{"op":"mcm","clk":"990232524","pt":1580495374383,"mc":[{"id":"1.168130661","rc":[{"batb":[[0,3.05,4.98],[1,2.94,1.34],[2,2.9,20.18]],"ltp":3.45,"tv":171.31,"id":26314798}]}]}
{"op":"mcm","clk":"990233417","pt":1580495385705,"mc":[{"id":"1.168130661","rc":[{"trd":[[2.7,4]],"batb":[[0,2.7,2.07]],"ltp":2.7,"tv":59.13,"id":25238892},{"batb":[[0,3.1,3],[1,3.05,1.98],[2,2.94,1.34]],"ltp":3.45,"tv":171.31,"id":26314798}],"tv":244.44}]}
{"op":"mcm","clk":"990233902","pt":1580495392600,"mc":[{"id":"1.168130661","rc":[{"batl":[[0,2.74,2],[1,2.82,2],[2,2.84,2]],"ltp":2.7,"tv":59.13,"id":25238892}]}]}
{"op":"mcm","clk":"990234038","pt":1580495394439,"mc":[{"id":"1.168130661","rc":[{"batb":[[0,3.05,1.98],[1,2.96,3]],"ltp":3.45,"tv":171.31,"id":26314798}]}]}
{"op":"mcm","clk":"990235014","pt":1580495405417,"mc":[{"id":"1.168130661","rc":[{"batb":[[1,2.98,3]],"ltp":3.45,"tv":171.31,"id":26314798}]}]}
{"op":"mcm","clk":"990235364","pt":1580495408641,"mc":[{"id":"1.168130661","rc":[{"batb":[[0,2.7,9.48]],"batl":[[2,2.9,5]],"ltp":2.7,"tv":59.13,"id":25238892},{"batb":[[1,3,6.67],[2,2.98,3]],"batl":[[0,3.4,3],[2,3.5,1]],"ltp":3.45,"tv":171.31,"id":26314798}]}]}
{"op":"mcm","clk":"990236358","pt":1580495418973,"mc":[{"id":"1.168130661","rc":[{"batb":[[0,3.05,4.98],[2,2.94,1.34]],"ltp":3.45,"tv":171.31,"id":26314798}]}]}
{"op":"mcm","clk":"990236812","pt":1580495424570,"mc":[{"id":"1.168130661","rc":[{"batl":[[1,3.5,1],[2,3.6,1]],"ltp":3.45,"tv":171.31,"id":26314798}]}]}
{"op":"mcm","clk":"990236834","pt":1580495424881,"mc":[{"id":"1.168130661","rc":[{"batl":[[0,3.35,4.23],[1,3.4,3],[2,3.5,1]],"ltp":3.45,"tv":171.31,"id":26314798}]}]}
{"op":"mcm","clk":"990237452","pt":1580495432179,"mc":[{"id":"1.168130661","rc":[{"batb":[[0,3.1,3],[1,3.05,1.98],[2,3,6.67]],"ltp":3.45,"tv":171.31,"id":26314798}]}]}
{"op":"mcm","clk":"990238323","pt":1580495443307,"mc":[{"id":"1.168130661","rc":[{"batb":[[0,3.05,4.98],[1,3,6.67],[2,2.94,1.34]],"ltp":3.45,"tv":171.31,"id":26314798}]}]}
{"op":"mcm","clk":"990239219","pt":1580495454830,"mc":[{"id":"1.168130661","rc":[{"batb":[[0,3.1,3],[1,3.05,1.98],[2,3,6.67]],"ltp":3.45,"tv":171.31,"id":26314798}]}]}
{"op":"mcm","clk":"990240371","pt":1580495470482,"mc":[{"id":"1.168130661","rc":[{"batl":[[0,2.82,2],[1,2.9,5],[2,2.92,24]],"ltp":2.7,"tv":59.13,"id":25238892},{"batb":[[2,2.94,1.34]],"batl":[[1,3.4,1]],"ltp":3.45,"tv":171.31,"id":26314798}]}]}
{"op":"mcm","clk":"990240449","pt":1580495471580,"mc":[{"id":"1.168130661","rc":[{"batb":[[0,3.05,1.98],[1,2.96,3]],"ltp":3.45,"tv":171.31,"id":26314798}]}]}
{"op":"mcm","clk":"990241380","pt":1580495483389,"mc":[{"id":"1.168130661","rc":[{"batb":[[1,2.98,3]],"ltp":3.45,"tv":171.31,"id":26314798}]}]}
{"op":"mcm","clk":"990241458","pt":1580495484492,"mc":[{"id":"1.168130661","rc":[{"batl":[[0,3.4,1],[1,3.5,1],[2,3.6,1]],"ltp":3.45,"tv":171.31,"id":26314798}]}]}
{"op":"mcm","clk":"990241501","pt":1580495485192,"mc":[{"id":"1.168130661","rc":[{"batl":[[2,3.55,3.99]],"ltp":3.45,"tv":171.31,"id":26314798}]}]}
{"op":"mcm","clk":"990242333","pt":1580495497313,"mc":[{"id":"1.168130661","rc":[{"batb":[[0,3,1.98]],"ltp":3.45,"tv":171.31,"id":26314798}]}]}
{"op":"mcm","clk":"990242406","pt":1580495498520,"mc":[{"id":"1.168130661","rc":[{"batb":[[0,3,4.98],[1,2.94,1.34],[2,2.9,20.18]],"ltp":3.45,"tv":171.31,"id":26314798}]}]}
{"op":"mcm","clk":"990243156","pt":1580495509114,"mc":[{"id":"1.168130661","rc":[{"batb":[[0,3.05,3],[1,3,1.98],[2,2.94,1.34]],"ltp":3.45,"tv":171.31,"id":26314798}]}]}
{"op":"mcm","clk":"990244168","pt":1580495522232,"mc":[{"id":"1.168130661","rc":[{"batb":[[0,3,1.98],[1,2.96,3]],"ltp":3.45,"tv":171.31,"id":26314798}]}]}
{"op":"mcm","clk":"990245596","pt":1580495538478,"mc":[{"id":"1.168130661","rc":[{"batb":[[1,2.98,3]],"ltp":3.45,"tv":171.31,"id":26314798}]}]}
{"op":"mcm","clk":"990246707","pt":1580495550716,"mc":[{"id":"1.168130661","rc":[{"batb":[[1,2.94,1.34],[2,2.9,20.18]],"ltp":3.45,"tv":171.31,"id":26314798}]}]}
{"op":"mcm","clk":"990246714","pt":1580495550815,"mc":[{"id":"1.168130661","rc":[{"batb":[[0,3,4.98]],"ltp":3.45,"tv":171.31,"id":26314798}]}]}
{"op":"mcm","clk":"990247574","pt":1580495561391,"mc":[{"id":"1.168130661","rc":[{"batb":[[0,3.05,3],[1,3,1.98],[2,2.94,1.34]],"ltp":3.45,"tv":171.31,"id":26314798}]}]}
{"op":"mcm","clk":"990248593","pt":1580495571642,"mc":[{"id":"1.168130661","rc":[{"batb":[[0,3,1.98],[1,2.96,3]],"ltp":3.45,"tv":171.31,"id":26314798}]}]}
{"op":"mcm","clk":"990249706","pt":1580495582140,"mc":[{"id":"1.168130661","rc":[{"batb":[[1,2.98,3]],"ltp":3.45,"tv":171.31,"id":26314798}]}]}
{"op":"mcm","clk":"990251020","pt":1580495593697,"mc":[{"id":"1.168130661","rc":[{"batl":[[1,3.5,3]],"ltp":3.45,"tv":171.31,"id":26314798}]}]}
{"op":"mcm","clk":"990251157","pt":1580495595165,"mc":[{"id":"1.168130661","rc":[{"batb":[[0,3,4.98],[1,2.94,1.34],[2,2.9,20.18]],"ltp":3.45,"tv":171.31,"id":26314798}]}]}
{"op":"mcm","clk":"990252032","pt":1580495603600,"mc":[{"id":"1.168130661","rc":[{"batl":[[2,3.6,1]],"ltp":3.45,"tv":171.31,"id":26314798}]}]}
{"op":"mcm","clk":"990252100","pt":1580495604202,"mc":[{"id":"1.168130661","rc":[{"batl":[[1,3.45,4.11],[2,3.5,3]],"ltp":3.45,"tv":171.31,"id":26314798}]}]}
{"op":"mcm","clk":"990252700","pt":1580495610193,"mc":[{"id":"1.168130661","rc":[{"batb":[[0,3.05,3],[1,3,1.98],[2,2.94,1.34]],"ltp":3.45,"tv":171.31,"id":26314798}]}]}
{"op":"mcm","clk":"990253813","pt":1580495621435,"mc":[{"id":"1.168130661","rc":[{"batb":[[0,3,1.98],[1,2.96,3]],"ltp":3.45,"tv":171.31,"id":26314798}]}]}
{"op":"mcm","clk":"990254971","pt":1580495634655,"mc":[{"id":"1.168130661","rc":[{"batb":[[1,2.98,3]],"ltp":3.45,"tv":171.31,"id":26314798}]}]}
{"op":"mcm","clk":"990256337","pt":1580495649179,"mc":[{"id":"1.168130661","rc":[{"batb":[[0,3,4.98],[1,2.94,1.34],[2,2.9,20.18]],"ltp":3.45,"tv":171.31,"id":26314798}]}]}
{"op":"mcm","clk":"990256792","pt":1580495653662,"mc":[{"id":"1.168130661","rc":[{"batl":[[0,3.4,3],[2,3.5,1]],"ltp":3.45,"tv":171.31,"id":26314798}]}]}
{"op":"mcm","clk":"990257583","pt":1580495661607,"mc":[{"id":"1.168130661","rc":[{"batb":[[0,3.05,3],[1,3,1.98],[2,2.94,1.34]],"ltp":3.45,"tv":171.31,"id":26314798}]}]}
{"op":"mcm","clk":"990257872","pt":1580495664284,"mc":[{"id":"1.168130661","rc":[{"batl":[[0,3.35,4.23],[1,3.4,3]],"ltp":3.45,"tv":171.31,"id":26314798}]}]}
{"op":"mcm","clk":"990258579","pt":1580495671608,"mc":[{"id":"1.168130661","rc":[{"batb":[[0,3,1.98],[1,2.96,3]],"ltp":3.45,"tv":171.31,"id":26314798}]}]}
{"op":"mcm","clk":"990259051","pt":1580495676822,"mc":[{"id":"1.168130661","rc":[{"trd":[[2.82,4],[2.9,23.6]],"batl":[[0,2.9,1.79],[1,2.92,24],[2,3,1]],"ltp":2.9,"tv":69.55,"id":25238892}],"tv":254.86}]}
{"op":"mcm","clk":"990259745","pt":1580495683536,"mc":[{"id":"1.168130661","rc":[{"batl":[[1,3,1],[2,3.4,50]],"ltp":2.9,"tv":69.55,"id":25238892}]}]}
{"op":"mcm","clk":"990259800","pt":1580495684025,"mc":[{"id":"1.168130661","rc":[{"batb":[[1,2.98,3]],"ltp":3.45,"tv":171.31,"id":26314798}]}]}
{"op":"mcm","clk":"990259894","pt":1580495684921,"mc":[{"id":"1.168130661","rc":[{"batb":[[0,2.72,1],[1,2.7,9.48],[2,2.68,2.71]],"ltp":2.9,"tv":69.55,"id":25238892}]}]}
{"op":"mcm","clk":"990261000","pt":1580495695043,"mc":[{"id":"1.168130661","rc":[{"batb":[[0,3,4.98],[1,2.94,1.34],[2,2.9,20.18]],"ltp":3.45,"tv":171.31,"id":26314798}]}]}
{"op":"mcm","clk":"990262452","pt":1580495707580,"mc":[{"id":"1.168130661","rc":[{"batl":[[1,3.4,50],[2,3.6,8]],"ltp":2.9,"tv":69.55,"id":25238892}]}]}
{"op":"mcm","clk":"990262570","pt":1580495708573,"mc":[{"id":"1.168130661","rc":[{"batl":[[1,3.35,3.3],[2,3.4,50]],"ltp":2.9,"tv":69.55,"id":25238892}]}]}
{"op":"mcm","clk":"990262637","pt":1580495709094,"mc":[{"id":"1.168130661","rc":[{"batb":[[0,3.05,3],[1,3,1.98],[2,2.94,1.34]],"ltp":3.45,"tv":171.31,"id":26314798}]}]}
{"op":"mcm","clk":"990262790","pt":1580495710265,"mc":[{"id":"1.168130661","rc":[{"batl":[[1,3,3],[2,3.35,3.3]],"ltp":2.9,"tv":69.55,"id":25238892}]}]}
{"op":"mcm","clk":"990263183","pt":1580495713903,"mc":[{"id":"1.168130661","rc":[{"batl":[[0,2.88,2],[1,2.9,1.79],[2,3,3]],"ltp":2.9,"tv":69.55,"id":25238892},{"batl":[[1,3.4,1]],"ltp":3.45,"tv":171.31,"id":26314798}]}]}
{"op":"mcm","clk":"990263825","pt":1580495719502,"mc":[{"id":"1.168130661","rc":[{"batb":[[0,3,1.98],[1,2.96,3]],"ltp":3.45,"tv":171.31,"id":26314798}]}]}
{"op":"mcm","clk":"990264148","pt":1580495722493,"mc":[{"id":"1.168130661","rc":[{"batl":[[0,3.4,1],[1,3.5,1],[2,3.55,3.99]],"ltp":3.45,"tv":171.31,"id":26314798}]}]}
{"op":"mcm","clk":"990264991","pt":1580495730601,"mc":[{"id":"1.168130661","rc":[{"batb":[[1,2.98,3]],"ltp":3.45,"tv":171.31,"id":26314798}]}]}
{"op":"mcm","clk":"990266159","pt":1580495741833,"mc":[{"id":"1.168130661","rc":[{"batb":[[0,3,4.98],[1,2.94,1.34],[2,2.9,20.18]],"ltp":3.45,"tv":171.31,"id":26314798}]}]}
{"op":"mcm","clk":"990267525","pt":1580495753266,"mc":[{"id":"1.168130661","rc":[{"batb":[[0,3.05,3],[1,3,1.98],[2,2.94,1.34]],"ltp":3.45,"tv":171.31,"id":26314798}]}]}
{"op":"mcm","clk":"990268711","pt":1580495764358,"mc":[{"id":"1.168130661","rc":[{"batb":[[0,3,1.98],[1,2.96,3]],"ltp":3.45,"tv":171.31,"id":26314798}]}]}
{"op":"mcm","clk":"990270325","pt":1580495778312,"mc":[{"id":"1.168130661","rc":[{"batb":[[1,2.98,3]],"ltp":3.45,"tv":171.31,"id":26314798}]}]}
{"op":"mcm","clk":"990271461","pt":1580495788921,"mc":[{"id":"1.168130661","rc":[{"batb":[[0,3,4.98],[1,2.94,1.34],[2,2.9,20.18]],"ltp":3.45,"tv":171.31,"id":26314798}]}]}
{"op":"mcm","clk":"990272420","pt":1580495798635,"mc":[{"id":"1.168130661","rc":[{"batb":[[0,3.05,3],[1,3,1.98],[2,2.94,1.34]],"ltp":3.45,"tv":171.31,"id":26314798}]}]}
{"op":"mcm","clk":"990273524","pt":1580495809544,"mc":[{"id":"1.168130661","rc":[{"batb":[[0,3,1.98],[1,2.96,3]],"ltp":3.45,"tv":171.31,"id":26314798}]}]}
{"op":"mcm","clk":"990274429","pt":1580495818472,"mc":[{"id":"1.168130661","rc":[{"batb":[[1,2.98,3]],"ltp":3.45,"tv":171.31,"id":26314798}]}]}
{"op":"mcm","clk":"990275282","pt":1580495825951,"mc":[{"id":"1.168130661","rc":[{"batb":[[0,3,4.98],[1,2.94,1.34],[2,2.9,20.18]],"ltp":3.45,"tv":171.31,"id":26314798}]}]}
{"op":"mcm","clk":"990275564","pt":1580495828970,"mc":[{"id":"1.168130661","rc":[{"batb":[[2,2.68,25.71]],"ltp":2.9,"tv":69.55,"id":25238892}]}]}
{"op":"mcm","clk":"990276178","pt":1580495835108,"mc":[{"id":"1.168130661","rc":[{"batb":[[0,3.05,3],[1,3,1.98],[2,2.94,1.34]],"ltp":3.45,"tv":171.31,"id":26314798}]}]}
{"op":"mcm","clk":"990276281","pt":1580495836368,"mc":[{"id":"1.168130661","rc":[{"batl":[[1,3.5,3]],"ltp":3.45,"tv":171.31,"id":26314798}]}]}
{"op":"mcm","clk":"990276593","pt":1580495839101,"mc":[{"id":"1.168130661","rc":[{"batl":[[1,3.45,4.11],[2,3.5,3]],"ltp":3.45,"tv":171.31,"id":26314798}]}]}
{"op":"mcm","clk":"990277075","pt":1580495844196,"mc":[{"id":"1.168130661","rc":[{"batb":[[0,3,1.98],[1,2.96,3]],"ltp":3.45,"tv":171.31,"id":26314798}]}]}
{"op":"mcm","clk":"990287625","pt":1580495852706,"mc":[{"id":"1.168130661","rc":[{"batb":[[1,2.94,1.34],[2,2.9,20.18]],"ltp":3.45,"tv":171.31,"id":26314798}]}]}
{"op":"mcm","clk":"990287636","pt":1580495852820,"mc":[{"id":"1.168130661","rc":[{"batb":[[1,2.98,3],[2,2.94,1.34]],"ltp":3.45,"tv":171.31,"id":26314798}]}]}
{"op":"mcm","clk":"990288683","pt":1580495862947,"mc":[{"id":"1.168130661","rc":[{"batb":[[0,3,4.98],[1,2.94,1.34],[2,2.9,20.18]],"ltp":3.45,"tv":171.31,"id":26314798}]}]}
{"op":"mcm","clk":"990289475","pt":1580495871164,"mc":[{"id":"1.168130661","rc":[{"batb":[[0,3.05,3],[1,3,1.98],[2,2.94,1.34]],"ltp":3.45,"tv":171.31,"id":26314798}]}]}
{"op":"mcm","clk":"990290253","pt":1580495878253,"mc":[{"id":"1.168130661","rc":[{"batb":[[0,3,1.98],[1,2.96,3]],"ltp":3.45,"tv":171.31,"id":26314798}]}]}
{"op":"mcm","clk":"990291334","pt":1580495887263,"mc":[{"id":"1.168130661","rc":[{"batb":[[1,2.98,3]],"ltp":3.45,"tv":171.31,"id":26314798}]}]}
{"op":"mcm","clk":"990292574","pt":1580495897383,"mc":[{"id":"1.168130661","rc":[{"batl":[[0,3.4,3],[2,3.5,1]],"ltp":3.45,"tv":171.31,"id":26314798}]}]}
{"op":"mcm","clk":"990292855","pt":1580495899872,"mc":[{"id":"1.168130661","rc":[{"batb":[[0,2.72,10.05]],"ltp":2.9,"tv":69.55,"id":25238892}]}]}
{"op":"mcm","clk":"990293047","pt":1580495901607,"mc":[{"id":"1.168130661","rc":[{"batb":[[0,2.74,1],[1,2.72,9.05],[2,2.7,9.48]],"ltp":2.9,"tv":69.55,"id":25238892},{"batb":[[0,3,4.98],[1,2.94,1.34],[2,2.9,20.18]],"ltp":3.45,"tv":171.31,"id":26314798}]}]}
{"op":"mcm","clk":"990294140","pt":1580495910785,"mc":[{"id":"1.168130661","rc":[{"batb":[[0,3.05,3],[1,3,1.98],[2,2.94,1.34]],"ltp":3.45,"tv":171.31,"id":26314798}]}]}
{"op":"mcm","clk":"990294810","pt":1580495916629,"mc":[{"id":"1.168130661","rc":[{"batl":[[1,3.5,1],[2,3.6,1]],"ltp":3.45,"tv":171.31,"id":26314798}]}]}
{"op":"mcm","clk":"990294852","pt":1580495916905,"mc":[{"id":"1.168130661","rc":[{"batl":[[0,3.35,4.23],[1,3.4,3],[2,3.5,1]],"ltp":3.45,"tv":171.31,"id":26314798}]}]}
{"op":"mcm","clk":"990295459","pt":1580495921497,"mc":[{"id":"1.168130661","rc":[{"batb":[[0,3,1.98],[1,2.96,3]],"ltp":3.45,"tv":171.31,"id":26314798}]}]}
{"op":"mcm","clk":"990296678","pt":1580495931632,"mc":[{"id":"1.168130661","rc":[{"batb":[[1,2.94,1.34],[2,2.9,20.18]],"ltp":3.45,"tv":171.31,"id":26314798}]}]}
{"op":"mcm","clk":"990296693","pt":1580495931731,"mc":[{"id":"1.168130661","rc":[{"batb":[[1,2.98,3],[2,2.94,1.34]],"ltp":3.45,"tv":171.31,"id":26314798}]}]}
{"op":"mcm","clk":"990297738","pt":1580495940231,"mc":[{"id":"1.168130661","rc":[{"batb":[[0,3,4.98],[1,2.94,1.34],[2,2.9,20.18]],"ltp":3.45,"tv":171.31,"id":26314798}]}]}
{"op":"mcm","clk":"990298976","pt":1580495951387,"mc":[{"id":"1.168130661","rc":[{"batb":[[0,3.05,3],[1,3,1.98],[2,2.94,1.34]],"ltp":3.45,"tv":171.31,"id":26314798}]}]}
{"op":"mcm","clk":"990299704","pt":1580495958183,"mc":[{"id":"1.168130661","rc":[{"batb":[[0,2.74,8.3],[2,2.7,2.07]],"ltp":2.9,"tv":69.55,"id":25238892},{"batb":[[0,8.2,4.42]],"ltp":8.0,"tv":13.99,"id":24420205},{"batb":[[0,3.05,9.56]],"batl":[[1,3.4,1]],"ltp":3.45,"tv":171.31,"id":26314798}]}]}
{"op":"mcm","clk":"990300219","pt":1580495963593,"mc":[{"id":"1.168130661","rc":[{"batb":[[0,2.76,4.33],[1,2.74,8.3]],"ltp":2.9,"tv":69.55,"id":25238892},{"batb":[[0,3.1,3],[1,3.05,6.56],[2,3,1.98]],"ltp":3.45,"tv":171.31,"id":26314798}]}]}
{"op":"mcm","clk":"990301352","pt":1580495974493,"mc":[{"id":"1.168130661","rc":[{"batl":[[0,3.4,1],[1,3.5,1],[2,3.6,1]],"ltp":3.45,"tv":171.31,"id":26314798}]}]}
{"op":"mcm","clk":"990301480","pt":1580495975596,"mc":[{"id":"1.168130661","rc":[{"batl":[[2,3.55,3.99]],"ltp":3.45,"tv":171.31,"id":26314798}]}]}
{"op":"mcm","clk":"990311724","pt":1580496077566,"mc":[{"id":"1.168130661","rc":[{"batl":[[1,3.5,3]],"ltp":3.45,"tv":171.31,"id":26314798}]}]}
{"op":"mcm","clk":"990313139","pt":1580496090261,"mc":[{"id":"1.168130661","rc":[{"batl":[[1,3.45,4.11],[2,3.5,3]],"ltp":3.45,"tv":171.31,"id":26314798}]}]}
{"op":"mcm","clk":"990318526","pt":1580496138364,"mc":[{"id":"1.168130661","rc":[{"batl":[[0,3.4,3],[2,3.5,1]],"ltp":3.45,"tv":171.31,"id":26314798}]}]}
{"op":"mcm","clk":"990319418","pt":1580496146637,"mc":[{"id":"1.168130661","rc":[{"batl":[[0,3.35,4.23],[1,3.4,3]],"ltp":3.45,"tv":171.31,"id":26314798}]}]}
{"op":"mcm","clk":"990325083","pt":1580496197639,"mc":[{"id":"1.168130661","rc":[{"batl":[[1,3.4,1]],"ltp":3.45,"tv":171.31,"id":26314798}]}]}
{"op":"mcm","clk":"990325639","pt":1580496202605,"mc":[{"id":"1.168130661","rc":[{"batl":[[0,3.4,1],[1,3.5,1],[2,3.6,1]],"ltp":3.45,"tv":171.31,"id":26314798}]}]}
{"op":"mcm","clk":"990325658","pt":1580496202814,"mc":[{"id":"1.168130661","rc":[{"batl":[[2,3.55,3.99]],"ltp":3.45,"tv":171.31,"id":26314798}]}]}
{"op":"mcm","clk":"990336653","pt":1580496320119,"mc":[{"id":"1.168130661","rc":[{"batl":[[1,3.5,3]],"ltp":3.45,"tv":171.31,"id":26314798}]}]}
{"op":"mcm","clk":"990337914","pt":1580496334813,"mc":[{"id":"1.168130661","rc":[{"batl":[[2,3.6,1]],"ltp":3.45,"tv":171.31,"id":26314798}]}]}
{"op":"mcm","clk":"990339663","pt":1580496353679,"mc":[{"id":"1.168130661","rc":[{"batl":[[1,3.45,4.11],[2,3.5,3]],"ltp":3.45,"tv":171.31,"id":26314798}]}]}
{"op":"mcm","clk":"990342365","pt":1580496382681,"mc":[{"id":"1.168130661","rc":[{"batl":[[0,3.4,3],[2,3.5,1]],"ltp":3.45,"tv":171.31,"id":26314798}]}]}
{"op":"mcm","clk":"990343216","pt":1580496391689,"mc":[{"id":"1.168130661","rc":[{"batl":[[0,3.35,4.23],[1,3.4,3]],"ltp":3.45,"tv":171.31,"id":26314798}]}]}
{"op":"mcm","clk":"990347535","pt":1580496442255,"mc":[{"id":"1.168130661","rc":[{"batl":[[1,3.4,1]],"ltp":3.45,"tv":171.31,"id":26314798}]}]}
{"op":"mcm","clk":"990348383","pt":1580496451704,"mc":[{"id":"1.168130661","rc":[{"batl":[[0,3.4,1],[1,3.5,1],[2,3.55,3.99]],"ltp":3.45,"tv":171.31,"id":26314798}]}]}
{"op":"mcm","clk":"990357847","pt":1580496561962,"mc":[{"id":"1.168130661","rc":[{"batl":[[1,3.5,3]],"ltp":3.45,"tv":171.31,"id":26314798}]}]}
{"op":"mcm","clk":"990358425","pt":1580496568456,"mc":[{"id":"1.168130661","rc":[{"batl":[[2,3.6,1]],"ltp":3.45,"tv":171.31,"id":26314798}]}]}
{"op":"mcm","clk":"990358451","pt":1580496568768,"mc":[{"id":"1.168130661","rc":[{"batl":[[1,3.45,4.11],[2,3.5,3]],"ltp":3.45,"tv":171.31,"id":26314798}]}]}
{"op":"mcm","clk":"990363044","pt":1580496622465,"mc":[{"id":"1.168130661","rc":[{"batl":[[0,3.4,3],[2,3.5,1]],"ltp":3.45,"tv":171.31,"id":26314798}]}]}
{"op":"mcm","clk":"990363635","pt":1580496628468,"mc":[{"id":"1.168130661","rc":[{"batl":[[1,3.5,1],[2,3.6,1]],"ltp":3.45,"tv":171.31,"id":26314798}]}]}
{"op":"mcm","clk":"990363774","pt":1580496629870,"mc":[{"id":"1.168130661","rc":[{"batl":[[0,3.35,4.23],[1,3.4,3],[2,3.5,1]],"ltp":3.45,"tv":171.31,"id":26314798}]}]}
{"op":"mcm","clk":"990369237","pt":1580496683121,"mc":[{"id":"1.168130661","rc":[{"batl":[[1,3.4,1]],"ltp":3.45,"tv":171.31,"id":26314798}]}]}
{"op":"mcm","clk":"990369690","pt":1580496687471,"mc":[{"id":"1.168130661","rc":[{"batl":[[0,3.4,1],[1,3.5,1],[2,3.6,1]],"ltp":3.45,"tv":171.31,"id":26314798}]}]}
{"op":"mcm","clk":"990369723","pt":1580496687727,"mc":[{"id":"1.168130661","rc":[{"batl":[[2,3.55,3.99]],"ltp":3.45,"tv":171.31,"id":26314798}]}]}
{"op":"mcm","clk":"990392578","pt":1580496804353,"mc":[{"id":"1.168130661","rc":[{"batl":[[1,3.5,3]],"ltp":3.45,"tv":171.31,"id":26314798}]}]}
{"op":"mcm","clk":"990394621","pt":1580496823097,"mc":[{"id":"1.168130661","rc":[{"batl":[[1,3.45,4.11],[2,3.5,3]],"ltp":3.45,"tv":171.31,"id":26314798}]}]}
{"op":"mcm","clk":"990399107","pt":1580496865598,"mc":[{"id":"1.168130661","rc":[{"batl":[[0,3.4,3],[2,3.5,1]],"ltp":3.45,"tv":171.31,"id":26314798}]}]}
{"op":"mcm","clk":"990401182","pt":1580496884508,"mc":[{"id":"1.168130661","rc":[{"batl":[[1,3.5,1],[2,3.6,1]],"ltp":3.45,"tv":171.31,"id":26314798}]}]}
{"op":"mcm","clk":"990401221","pt":1580496884819,"mc":[{"id":"1.168130661","rc":[{"batl":[[0,3.35,4.23],[1,3.4,3],[2,3.5,1]],"ltp":3.45,"tv":171.31,"id":26314798}]}]}
{"op":"mcm","clk":"990406537","pt":1580496926584,"mc":[{"id":"1.168130661","rc":[{"batl":[[1,3.4,1]],"ltp":3.45,"tv":171.31,"id":26314798}]}]}
{"op":"mcm","clk":"990406621","pt":1580496927370,"mc":[{"id":"1.168130661","rc":[{"batl":[[0,3.4,1],[1,3.5,1],[2,3.55,3.99]],"ltp":3.45,"tv":171.31,"id":26314798}]}]}
{"op":"mcm","clk":"990425693","pt":1580497113575,"mc":[{"id":"1.168130661","rc":[{"trd":[[3.1,41.86]],"batb":[[0,3.05,6.56],[1,3,1.98],[2,2.94,1.34]],"batl":[[0,3.1,96],[1,3.4,1],[2,3.5,1]],"ltp":3.1,"tv":177.31,"id":26314798}],"tv":260.86}]}
{"op":"mcm","clk":"990425940","pt":1580497116143,"mc":[{"id":"1.168130661","rc":[{"batb":[[0,3,1.98],[1,2.96,6.76]],"ltp":3.1,"tv":177.31,"id":26314798}]}]}
{"op":"mcm","clk":"990435357","pt":1580497205992,"mc":[{"id":"1.168130661","rc":[{"batb":[[0,2.76,6.4],[2,2.68,25.71]],"ltp":2.9,"tv":69.55,"id":25238892},{"batb":[[0,2.98,1.98]],"ltp":3.1,"tv":177.31,"id":26314798}]}]}
{"op":"mcm","clk":"990510857","pt":1580497688137,"mc":[{"id":"1.168130661","rc":[{"batl":[[2,2.96,2]],"ltp":2.9,"tv":69.55,"id":25238892}]}]}
{"op":"mcm","clk":"990542493","pt":1580497901536,"mc":[{"id":"1.168130661","rc":[{"trd":[[8.2,7.96]],"batb":[[0,8.2,2.42]],"ltp":8.2,"tv":17.99,"id":24420205}],"tv":264.87}]}
{"op":"mcm","clk":"990551086","pt":1580497957287,"mc":[{"id":"1.168130661","rc":[{"batb":[[0,8,1.78],[1,7,3.76],[2,5.8,3]],"ltp":8.2,"tv":17.99,"id":24420205}]}]}
{"op":"mcm","clk":"990552418","pt":1580497965617,"mc":[{"id":"1.168130661","rc":[{"batb":[[0,7.2,1.78]],"ltp":8.2,"tv":17.99,"id":24420205}]}]}
{"op":"mcm","clk":"990590599","pt":1580498212695,"mc":[{"id":"1.168130661","rc":[{"trd":[[2.96,17.48],[2.98,3.96]],"batb":[[0,2.94,1.34],[1,2.9,20.18],[2,2.78,3.9]],"batl":[[0,2.96,87.26]],"ltp":2.96,"tv":194.79,"id":26314798}],"tv":282.35}]}
{"op":"mcm","clk":"990590630","pt":1580498212904,"mc":[{"id":"1.168130661","rc":[{"trd":[[2.96,22.62]],"batl":[[0,2.96,84.69]],"ltp":2.96,"tv":199.93,"id":26314798}],"tv":287.49}]}
{"op":"mcm","clk":"990591777","pt":1580498220795,"mc":[{"id":"1.168130661","rc":[{"batb":[[0,7.4,1.68],[1,7.2,1.78],[2,7,3.76]],"ltp":8.2,"tv":17.99,"id":24420205},{"batb":[[1,2.9,21.86]],"ltp":2.96,"tv":199.93,"id":26314798}]}]}
{"op":"mcm","clk":"990592184","pt":1580498223515,"mc":[{"id":"1.168130661","rc":[{"batb":[[0,7.6,1.68],[1,7.4,1.68]],"ltp":8.2,"tv":17.99,"id":24420205}]}]}
{"op":"mcm","clk":"990593566","pt":1580498233141,"mc":[{"id":"1.168130661","rc":[{"batb":[[1,7,3.76],[2,5.8,3]],"ltp":8.2,"tv":17.99,"id":24420205}]}]}
{"op":"mcm","clk":"990597004","pt":1580498256484,"mc":[{"id":"1.168130661","rc":[{"batb":[[0,7.2,1.68]],"ltp":8.2,"tv":17.99,"id":24420205},{"trd":[[2.9,43.74],[2.94,4.68]],"batb":[[0,2.78,3.9],[1,2.26,3.32],[2,2.06,90]],"batl":[[0,2.9,61.47]],"ltp":2.9,"tv":246.36,"id":26314798}],"tv":333.91}]}
{"op":"mcm","clk":"990597206","pt":1580498257964,"mc":[{"id":"1.168130661","rc":[{"batb":[[0,7.4,1.76],[1,7.2,1.68],[2,7,3.76]],"ltp":8.2,"tv":17.99,"id":24420205}]}]}
{"op":"mcm","clk":"990599015","pt":1580498270925,"mc":[{"id":"1.168130661","rc":[{"batb":[[0,7.2,3.44],[1,7,3.76],[2,5.8,3]],"ltp":8.2,"tv":17.99,"id":24420205}]}]}
{"op":"mcm","clk":"990609566","pt":1580498347397,"mc":[{"id":"1.168130661","rc":[{"batb":[[1,2.42,18.95],[2,2.26,3.32]],"ltp":2.9,"tv":246.36,"id":26314798}]}]}
{"op":"mcm","clk":"990609863","pt":1580498349703,"mc":[{"id":"1.168130661","rc":[{"batb":[[2,2.28,18.95]],"ltp":2.9,"tv":246.36,"id":26314798}]}]}
{"op":"mcm","clk":"990616977","pt":1580498406776,"mc":[{"id":"1.168130661","rc":[{"batb":[[0,7.4,2.7],[1,7.2,3.44],[2,7,3.76]],"ltp":8.2,"tv":17.99,"id":24420205}]}]}
{"op":"mcm","clk":"990617982","pt":1580498414674,"mc":[{"id":"1.168130661","rc":[{"batb":[[1,7.2,1.76]],"ltp":8.2,"tv":17.99,"id":24420205}]}]}
{"op":"mcm","clk":"990617998","pt":1580498414764,"mc":[{"id":"1.168130661","rc":[{"batb":[[0,7.6,1.68],[1,7.4,2.7],[2,7.2,1.76]],"ltp":8.2,"tv":17.99,"id":24420205}]}]}
{"op":"mcm","clk":"990623239","pt":1580498453388,"mc":[{"id":"1.168130661","rc":[{"batb":[[0,7.8,1.76],[1,7.6,1.68],[2,7.4,2.7]],"ltp":8.2,"tv":17.99,"id":24420205}]}]}
{"op":"mcm","clk":"990624446","pt":1580498461708,"mc":[{"id":"1.168130661","rc":[{"batb":[[2,7,3.76]],"ltp":8.2,"tv":17.99,"id":24420205}]}]}
{"op":"mcm","clk":"990626813","pt":1580498479138,"mc":[{"id":"1.168130661","rc":[{"batb":[[0,8,1.68],[1,7.8,1.76]],"ltp":8.2,"tv":17.99,"id":24420205}]}]}
{"op":"mcm","clk":"990629621","pt":1580498500675,"mc":[{"id":"1.168130661","rc":[{"batb":[[1,7,3.76],[2,5.8,3]],"ltp":8.2,"tv":17.99,"id":24420205}]}]}
{"op":"mcm","clk":"990631234","pt":1580498512452,"mc":[{"id":"1.168130661","rc":[{"batb":[[0,7.2,1.68]],"ltp":8.2,"tv":17.99,"id":24420205}]}]}
{"op":"mcm","clk":"990636159","pt":1580498545849,"mc":[{"id":"1.168130661","rc":[{"batb":[[0,7.4,1.76],[1,7.2,1.68],[2,7,3.76]],"ltp":8.2,"tv":17.99,"id":24420205}]}]}
{"op":"mcm","clk":"990650338","pt":1580498576477,"mc":[{"id":"1.168130661","rc":[{"batb":[[0,7.6,1.68],[1,7.4,1.76]],"ltp":8.2,"tv":17.99,"id":24420205}]}]}
{"op":"mcm","clk":"990652123","pt":1580498588096,"mc":[{"id":"1.168130661","rc":[{"batl":[[0,500,2],[1,720,1.88],[2,730,9]],"ltp":0.0,"tv":0.0,"id":24707172}]}]}
{"op":"mcm","clk":"990652497","pt":1580498590716,"mc":[{"id":"1.168130661","rc":[{"batl":[[0,500,2.2],[1,720,1.68]],"ltp":0.0,"tv":0.0,"id":24707172}]}]}
{"op":"mcm","clk":"990652854","pt":1580498593217,"mc":[{"id":"1.168130661","rc":[{"batb":[[0,7.8,1.76],[1,7.6,1.68]],"ltp":8.2,"tv":17.99,"id":24420205}]}]}
{"op":"mcm","clk":"990654576","pt":1580498604522,"mc":[{"id":"1.168130661","rc":[{"batl":[[0,480,9],[1,500,2.2],[2,720,1.68]],"ltp":0.0,"tv":0.0,"id":24707172}]}]}
{"op":"mcm","clk":"990655346","pt":1580498609716,"mc":[{"id":"1.168130661","rc":[{"batl":[[0,470,1.68],[1,480,9],[2,500,2.2]],"ltp":0.0,"tv":0.0,"id":24707172},{"batb":[[0,8,1.68],[1,7.8,1.76]],"ltp":8.2,"tv":17.99,"id":24420205}]}]}
{"op":"mcm","clk":"990655616","pt":1580498611516,"mc":[{"id":"1.168130661","rc":[{"batl":[[2,500,2]],"ltp":0.0,"tv":0.0,"id":24707172}]}]}
{"op":"mcm","clk":"990655653","pt":1580498611730,"mc":[{"id":"1.168130661","rc":[{"batl":[[0,470,1.88]],"ltp":0.0,"tv":0.0,"id":24707172}]}]}
{"op":"mcm","clk":"990658630","pt":1580498631954,"mc":[{"id":"1.168130661","rc":[{"trd":[[2.78,7.8]],"batb":[[0,2.42,18.95],[1,2.28,18.95],[2,2.26,3.32]],"batl":[[0,2.78,1.1],[1,2.9,61.47],[2,3.4,1]],"ltp":2.78,"tv":254.16,"id":26314798}],"tv":341.71}]}
{"op":"mcm","clk":"990660084","pt":1580498641917,"mc":[{"id":"1.168130661","rc":[{"batb":[[1,7,3.76],[2,5.8,3]],"ltp":8.2,"tv":17.99,"id":24420205}]}]}
{"op":"mcm","clk":"990660232","pt":1580498642947,"mc":[{"id":"1.168130661","rc":[{"batb":[[0,7.2,1.68]],"ltp":8.2,"tv":17.99,"id":24420205}]}]}
{"op":"mcm","clk":"990661166","pt":1580498649163,"mc":[{"id":"1.168130661","rc":[{"batl":[[0,2.74,1.1]],"ltp":2.78,"tv":254.16,"id":26314798}]}]}
{"op":"mcm","clk":"990662170","pt":1580498655673,"mc":[{"id":"1.168130661","rc":[{"batl":[[0,2.6,1.1]],"ltp":2.78,"tv":254.16,"id":26314798}]}]}
{"op":"mcm","clk":"990662186","pt":1580498655781,"mc":[{"id":"1.168130661","rc":[{"trd":[[2.6,2.2]],"batl":[[0,2.9,61.47],[1,3.4,1],[2,3.5,1]],"ltp":2.6,"tv":256.36,"id":26314798}],"tv":343.91}]}
{"op":"mcm","clk":"990662631","pt":1580498658872,"mc":[{"id":"1.168130661","rc":[{"batb":[[0,2.44,4.73],[1,2.42,18.95],[2,2.28,18.95]],"ltp":2.6,"tv":256.36,"id":26314798}]}]}
{"op":"mcm","clk":"990666341","pt":1580498683688,"mc":[{"id":"1.168130661","rc":[{"batl":[[0,2.88,2],[1,2.9,61.47],[2,3.4,1]],"ltp":2.6,"tv":256.36,"id":26314798}]}]}
{"op":"mcm","clk":"990667356","pt":1580498690502,"mc":[{"id":"1.168130661","rc":[{"batb":[[0,7.4,1.68],[1,7.2,1.68],[2,7,3.76]],"ltp":8.2,"tv":17.99,"id":24420205},{"batb":[[0,2.46,1.98],[1,2.44,4.73],[2,2.42,18.95]],"ltp":2.6,"tv":256.36,"id":26314798}]}]}
{"op":"mcm","clk":"990670753","pt":1580498712552,"mc":[{"id":"1.168130661","rc":[{"batb":[[1,7,3.76],[2,5.8,3]],"ltp":8.2,"tv":17.99,"id":24420205}]}]}
{"op":"mcm","clk":"990670784","pt":1580498712762,"mc":[{"id":"1.168130661","rc":[{"batb":[[0,7.6,1.68],[1,7.4,1.68],[2,7,3.76]],"ltp":8.2,"tv":17.99,"id":24420205}]}]}
{"op":"mcm","clk":"990682366","pt":1580498785549,"mc":[{"id":"1.168130661","rc":[{"batb":[[0,7.8,1.68],[1,7.6,1.68]],"ltp":8.2,"tv":17.99,"id":24420205}]}]}
{"op":"mcm","clk":"990685912","pt":1580498809156,"mc":[{"id":"1.168130661","rc":[{"batb":[[0,8,1.68],[1,7.8,1.68]],"ltp":8.2,"tv":17.99,"id":24420205}]}]}
{"op":"mcm","clk":"990687040","pt":1580498816896,"mc":[{"id":"1.168130661","rc":[{"trd":[[2.76,27.95]],"batb":[[0,2.76,1.4]],"ltp":2.76,"tv":79.55,"id":25238892}],"tv":353.91}]}
{"op":"mcm","clk":"990687377","pt":1580498819280,"mc":[{"id":"1.168130661","rc":[{"batb":[[1,2.74,7.3]],"ltp":2.76,"tv":79.55,"id":25238892}]}]}
{"op":"mcm","clk":"990693289","pt":1580498857231,"mc":[{"id":"1.168130661","rc":[{"batb":[[1,2.68,25.71],[2,2.62,1]],"ltp":2.76,"tv":79.55,"id":25238892}]}]}
{"op":"mcm","clk":"990696154","pt":1580498875043,"mc":[{"id":"1.168130661","rc":[{"batb":[[1,2.7,7.77],[2,2.68,25.71]],"ltp":2.76,"tv":79.55,"id":25238892}]}]}
{"op":"mcm","clk":"990696601","pt":1580498878263,"mc":[{"id":"1.168130661","rc":[{"batb":[[0,2.72,1.4]],"ltp":2.76,"tv":79.55,"id":25238892},{"batb":[[0,8.2,1.68],[1,8,1.68]],"ltp":8.2,"tv":17.99,"id":24420205}]}]}
{"op":"mcm","clk":"990702975","pt":1580498920135,"mc":[{"id":"1.168130661","rc":[{"batl":[[0,2.88,2.18]],"ltp":2.6,"tv":256.36,"id":26314798}]}]}
{"op":"mcm","clk":"990731193","pt":1580499106958,"mc":[{"id":"1.168130661","rc":[{"batl":[[0,2.88,4]],"ltp":2.76,"tv":79.55,"id":25238892}]}]}
{"op":"mcm","clk":"990734386","pt":1580499127690,"mc":[{"id":"1.168130661","rc":[{"batl":[[1,2.9,4.79]],"ltp":2.76,"tv":79.55,"id":25238892}]}]}
{"op":"mcm","clk":"990746100","pt":1580499202295,"mc":[{"id":"1.168130661","rc":[{"batl":[[1,730,13]],"ltp":0.0,"tv":0.0,"id":25545675}]}]}
{"op":"mcm","clk":"990746692","pt":1580499206580,"mc":[{"id":"1.168130661","rc":[{"batl":[[1,480,13]],"ltp":0.0,"tv":0.0,"id":24707172}]}]}
{"op":"mcm","clk":"990801962","pt":1580499525397,"mc":[{"id":"1.168130661","rc":[{"batb":[[2,2.42,20.46]],"ltp":2.6,"tv":256.36,"id":26314798}]}]}
{"op":"mcm","clk":"990838903","pt":1580499764220,"mc":[{"id":"1.168130661","rc":[{"batl":[[0,2.88,4.38]],"ltp":2.76,"tv":79.55,"id":25238892}]}]}
{"op":"mcm","clk":"990843382","pt":1580499792462,"mc":[{"id":"1.168130661","rc":[{"trd":[[2.72,0.76]],"batb":[[0,2.72,1.02]],"batl":[[0,2.88,4]],"ltp":2.72,"tv":80.3,"id":25238892}],"tv":354.66}]}
{"op":"mcm","clk":"990875113","pt":1580500003142,"mc":[{"id":"1.168130661","rc":[{"trd":[[2.88,10]],"batl":[[0,2.88,2]],"ltp":2.88,"tv":84.3,"id":25238892}],"tv":358.66}]}
{"op":"mcm","clk":"990876072","pt":1580500009829,"mc":[{"id":"1.168130661","rc":[{"batb":[[0,2.72,2.02]],"ltp":2.88,"tv":84.3,"id":25238892}]}]}
{"op":"mcm","clk":"990877150","pt":1580500017243,"mc":[{"id":"1.168130661","rc":[{"batb":[[0,2.74,1],[1,2.72,1.02],[2,2.7,7.77]],"ltp":2.88,"tv":84.3,"id":25238892}]}]}
{"op":"mcm","clk":"990879160","pt":1580500031167,"mc":[{"id":"1.168130661","rc":[{"batb":[[0,2.74,3.45],[2,2.68,25.71]],"ltp":2.88,"tv":84.3,"id":25238892}]}]}
{"op":"mcm","clk":"990883406","pt":1580500063885,"mc":[{"id":"1.168130661","rc":[{"batb":[[0,2.74,1],[2,2.7,2.45]],"ltp":2.88,"tv":84.3,"id":25238892}]}]}
{"op":"mcm","clk":"990887652","pt":1580500097549,"mc":[{"id":"1.168130661","rc":[{"batb":[[0,2.74,2.68],[2,2.68,25.71]],"ltp":2.88,"tv":84.3,"id":25238892}]}]}
{"op":"mcm","clk":"990889403","pt":1580500110883,"mc":[{"id":"1.168130661","rc":[{"batb":[[0,2.74,3.7],[1,2.68,25.71],[2,2.42,20.46]],"ltp":2.88,"tv":84.3,"id":25238892}]}]}
{"op":"mcm","clk":"990891541","pt":1580500128983,"mc":[{"id":"1.168130661","rc":[{"batb":[[0,2.74,7.69]],"ltp":2.88,"tv":84.3,"id":25238892}]}]}
{"op":"mcm","clk":"990895887","pt":1580500161220,"mc":[{"id":"1.168130661","rc":[{"batb":[[0,2.74,2.02],[1,2.7,5.67],[2,2.68,25.71]],"ltp":2.88,"tv":84.3,"id":25238892}]}]}
{"op":"mcm","clk":"990899454","pt":1580500193971,"mc":[{"id":"1.168130661","rc":[{"batb":[[0,2.76,1.92],[1,2.74,2.02]],"ltp":2.88,"tv":84.3,"id":25238892}]}]}
{"op":"mcm","clk":"990901177","pt":1580500207580,"mc":[{"id":"1.168130661","rc":[{"batb":[[0,2.76,2.95],[1,2.74,1]],"ltp":2.88,"tv":84.3,"id":25238892}]}]}
{"op":"mcm","clk":"990903455","pt":1580500226135,"mc":[{"id":"1.168130661","rc":[{"batb":[[0,2.76,1.02],[2,2.7,1.92]],"ltp":2.88,"tv":84.3,"id":25238892}]}]}
{"op":"mcm","clk":"990904278","pt":1580500233712,"mc":[{"id":"1.168130661","rc":[{"batb":[[0,2.76,3.11]],"ltp":2.88,"tv":84.3,"id":25238892}]}]}
{"op":"mcm","clk":"990927700","pt":1580500361196,"mc":[{"id":"1.168130661","rc":[{"trd":[[2.88,22.99]],"batl":[[0,2.88,4.49]],"ltp":2.88,"tv":97.3,"id":25238892}],"tv":371.66}]}
{"op":"mcm","clk":"990975920","pt":1580500818719,"mc":[{"id":"1.168130661","rc":[{"trd":[[2.76,27.95],[2.88,22.99]],"batl":[[0,2.88,4.49]],"ltp":2.88,"tv":97.3,"id":25238892},{"batl":[[1,11.5,3.23]],"ltp":8.2,"tv":17.99,"id":24420205},{"trd":[[2.9,43.73],[2.94,4.68],[3.1,41.84],[3.45,88.1]],"batb":[[0,2.58,2],[1,2.46,1.98],[2,2.44,4.73]],"ltp":2.6,"tv":256.32,"id":26314798}],"tv":371.62}]}
{"op":"mcm","clk":"990995372","pt":1580500966995,"mc":[{"id":"1.168130661","rc":[{"batb":[[0,2.58,3.98],[1,2.44,4.73],[2,2.42,20.45]],"ltp":2.6,"tv":256.32,"id":26314798}]}]}
{"op":"mcm","clk":"991004298","pt":1580501026593,"mc":[{"id":"1.168130661","rc":[{"batb":[[2,7.2,11]],"ltp":8.2,"tv":17.99,"id":24420205}]}]}
{"op":"mcm","clk":"991006123","pt":1580501040086,"mc":[{"id":"1.168130661","rc":[{"batb":[[0,2.58,1.98]],"ltp":2.6,"tv":256.32,"id":26314798}]}]}
{"op":"mcm","clk":"991011931","pt":1580501078628,"mc":[{"id":"1.168130661","rc":[{"batb":[[0,2.76,10.36]],"ltp":2.88,"tv":97.3,"id":25238892}]}]}
{"op":"mcm","clk":"991016632","pt":1580501108574,"mc":[{"id":"1.168130661","rc":[{"batb":[[0,2.46,1.98]],"ltp":2.6,"tv":256.32,"id":26314798}]}]}
{"op":"mcm","clk":"991017212","pt":1580501111982,"mc":[{"id":"1.168130661","rc":[{"batl":[[0,2.88,6.49]],"ltp":2.88,"tv":97.3,"id":25238892}]}]}
{"op":"mcm","clk":"991028507","pt":1580501187003,"mc":[{"id":"1.168130661","rc":[{"batb":[[0,2.46,11.98]],"ltp":2.6,"tv":256.32,"id":26314798}]}]}
{"op":"mcm","clk":"991028979","pt":1580501190488,"mc":[{"id":"1.168130661","rc":[{"trd":[[2.76,31.96]],"batb":[[0,2.76,8.36]],"ltp":2.76,"tv":101.3,"id":25238892}],"tv":375.63}]}
{"op":"mcm","clk":"991029428","pt":1580501193403,"mc":[{"id":"1.168130661","rc":[{"batb":[[1,2.7,1.92],[2,2.68,2.7]],"ltp":2.76,"tv":101.3,"id":25238892}]}]}
{"op":"mcm","clk":"991030522","pt":1580501200508,"mc":[{"id":"1.168130661","rc":[{"batl":[[0,2.86,2],[1,2.88,6.49],[2,2.9,4.79]],"ltp":2.76,"tv":101.3,"id":25238892}]}]}
{"op":"mcm","clk":"991036655","pt":1580501240379,"mc":[{"id":"1.168130661","rc":[{"trd":[[2.76,34.18]],"batb":[[0,2.7,1.92],[1,2.68,2.7],[2,2.62,1]],"ltp":2.76,"tv":103.52,"id":25238892}],"tv":377.85}]}
{"op":"mcm","clk":"991038263","pt":1580501250590,"mc":[{"id":"1.168130661","rc":[{"batb":[[0,2.7,10.86]],"ltp":2.76,"tv":103.52,"id":25238892}]}]}
{"op":"mcm","clk":"991048674","pt":1580501255100,"mc":[{"id":"1.168130661","rc":[{"batl":[[2,2.9,15.79]],"ltp":2.76,"tv":103.52,"id":25238892}]}]}
{"op":"mcm","clk":"991064924","pt":1580501364573,"mc":[{"id":"1.168130661","rc":[{"batl":[[0,9.4,5],[1,10.5,1.88],[2,11,4]],"ltp":0.0,"tv":0.0,"id":420}]}]}
{"op":"mcm","clk":"991065674","pt":1580501369472,"mc":[{"id":"1.168130661","rc":[{"batl":[[0,8.6,5]],"ltp":0.0,"tv":0.0,"id":420}]}]}
{"op":"mcm","clk":"991066302","pt":1580501373665,"mc":[{"id":"1.168130661","rc":[{"batl":[[0,10.5,1.88],[1,11,4],[2,21,9]],"ltp":0.0,"tv":0.0,"id":420}]}]}
{"op":"mcm","clk":"991066345","pt":1580501373991,"mc":[{"id":"1.168130661","rc":[{"trd":[[7.8,10]],"ltp":7.8,"tv":10.0,"id":420}],"tv":387.85}]}
{"op":"mcm","clk":"991067029","pt":1580501378615,"mc":[{"id":"1.168130661","rc":[{"batb":[[1,7,4.7]],"ltp":7.8,"tv":10.0,"id":420}]}]}
{"op":"mcm","clk":"991070630","pt":1580501400724,"mc":[{"id":"1.168130661","rc":[{"batl":[[0,2.84,2],[1,2.86,2],[2,2.88,6.49]],"ltp":2.76,"tv":103.52,"id":25238892}]}]}
{"op":"mcm","clk":"991091946","pt":1580501533206,"mc":[{"id":"1.168130661","rc":[{"batb":[[0,2.72,1.68],[1,2.46,11.98],[2,2.44,4.73]],"ltp":2.6,"tv":256.32,"id":26314798}]}]}
{"op":"mcm","clk":"991092238","pt":1580501534819,"mc":[{"id":"1.168130661","rc":[{"batb":[[0,2.46,11.98],[1,2.44,4.73],[2,2.42,20.45]],"ltp":2.6,"tv":256.32,"id":26314798}]}]}
{"op":"mcm","clk":"991092919","pt":1580501539100,"mc":[{"id":"1.168130661","rc":[{"batb":[[0,2.46,12.4]],"ltp":2.6,"tv":256.32,"id":26314798}]}]}
{"op":"mcm","clk":"991093312","pt":1580501541435,"mc":[{"id":"1.168130661","rc":[{"batb":[[0,2.46,11.98]],"ltp":2.6,"tv":256.32,"id":26314798}]}]}
{"op":"mcm","clk":"991093462","pt":1580501542309,"mc":[{"id":"1.168130661","rc":[{"batb":[[0,2.46,12.4]],"ltp":2.6,"tv":256.32,"id":26314798}]}]}
{"op":"mcm","clk":"991093718","pt":1580501543833,"mc":[{"id":"1.168130661","rc":[{"batb":[[0,2.46,11.98]],"ltp":2.6,"tv":256.32,"id":26314798}]}]}
{"op":"mcm","clk":"991094023","pt":1580501545726,"mc":[{"id":"1.168130661","rc":[{"batb":[[0,2.46,12.4]],"ltp":2.6,"tv":256.32,"id":26314798}]}]}
{"op":"mcm","clk":"991094287","pt":1580501547334,"mc":[{"id":"1.168130661","rc":[{"batb":[[0,2.46,11.98]],"ltp":2.6,"tv":256.32,"id":26314798}]}]}
{"op":"mcm","clk":"991094673","pt":1580501549447,"mc":[{"id":"1.168130661","rc":[{"batb":[[0,2.46,12.4]],"ltp":2.6,"tv":256.32,"id":26314798}]}]}
{"op":"mcm","clk":"991094890","pt":1580501550625,"mc":[{"id":"1.168130661","rc":[{"batb":[[0,2.46,11.98]],"ltp":2.6,"tv":256.32,"id":26314798}]}]}
{"op":"mcm","clk":"991095213","pt":1580501552526,"mc":[{"id":"1.168130661","rc":[{"batb":[[0,2.46,12.4]],"ltp":2.6,"tv":256.32,"id":26314798}]}]}
{"op":"mcm","clk":"991095589","pt":1580501554635,"mc":[{"id":"1.168130661","rc":[{"batb":[[0,2.46,11.98]],"ltp":2.6,"tv":256.32,"id":26314798}]}]}
{"op":"mcm","clk":"991095843","pt":1580501556237,"mc":[{"id":"1.168130661","rc":[{"batb":[[0,2.46,12.4]],"ltp":2.6,"tv":256.32,"id":26314798}]}]}
{"op":"mcm","clk":"991096046","pt":1580501557532,"mc":[{"id":"1.168130661","rc":[{"batb":[[0,2.46,11.98]],"ltp":2.6,"tv":256.32,"id":26314798}]}]}
{"op":"mcm","clk":"991096558","pt":1580501560618,"mc":[{"id":"1.168130661","rc":[{"batb":[[0,2.46,12.4]],"ltp":2.6,"tv":256.32,"id":26314798}]}]}
{"op":"mcm","clk":"991096802","pt":1580501562020,"mc":[{"id":"1.168130661","rc":[{"batb":[[0,2.46,11.98]],"ltp":2.6,"tv":256.32,"id":26314798}]}]}
{"op":"mcm","clk":"991097128","pt":1580501564028,"mc":[{"id":"1.168130661","rc":[{"batb":[[0,2.46,12.4]],"ltp":2.6,"tv":256.32,"id":26314798}]}]}
{"op":"mcm","clk":"991097316","pt":1580501565221,"mc":[{"id":"1.168130661","rc":[{"batb":[[0,2.46,11.98]],"ltp":2.6,"tv":256.32,"id":26314798}]}]}
{"op":"mcm","clk":"991097725","pt":1580501567720,"mc":[{"id":"1.168130661","rc":[{"batb":[[0,2.46,12.4]],"ltp":2.6,"tv":256.32,"id":26314798}]}]}
{"op":"mcm","clk":"991097896","pt":1580501568845,"mc":[{"id":"1.168130661","rc":[{"batb":[[0,2.46,11.98]],"ltp":2.6,"tv":256.32,"id":26314798}]}]}
{"op":"mcm","clk":"991206753","pt":1580502199241,"mc":[{"id":"1.168130661","rc":[{"batb":[[0,2.46,14.98]],"ltp":2.6,"tv":256.32,"id":26314798}]}]}
{"op":"mcm","clk":"991211733","pt":1580502232575,"mc":[{"id":"1.168130661","rc":[{"trd":[[2.82,28.36]],"batb":[[0,2.82,14.82],[1,2.7,10.86],[2,2.68,2.7]],"ltp":2.82,"tv":127.88,"id":25238892}],"tv":412.21}]}
{"op":"mcm","clk":"991211913","pt":1580502233687,"mc":[{"id":"1.168130661","rc":[{"batb":[[1,2.7,6.84]],"ltp":2.82,"tv":127.88,"id":25238892}]}]}
{"op":"mcm","clk":"991213951","pt":1580502247310,"mc":[{"id":"1.168130661","rc":[{"batl":[[0,2.84,4]],"ltp":2.82,"tv":127.88,"id":25238892}]}]}
{"op":"mcm","clk":"991214662","pt":1580502252118,"mc":[{"id":"1.168130661","rc":[{"batl":[[0,2.84,2]],"ltp":2.82,"tv":127.88,"id":25238892}]}]}
{"op":"mcm","clk":"991215781","pt":1580502260116,"mc":[{"id":"1.168130661","rc":[{"batl":[[0,2.84,4]],"ltp":2.82,"tv":127.88,"id":25238892}]}]}
{"op":"mcm","clk":"991221157","pt":1580502298973,"mc":[{"id":"1.168130661","rc":[{"batb":[[0,2.46,15.4]],"ltp":2.6,"tv":256.32,"id":26314798}]}]}
{"op":"mcm","clk":"991221371","pt":1580502300479,"mc":[{"id":"1.168130661","rc":[{"batb":[[0,2.46,14.98]],"ltp":2.6,"tv":256.32,"id":26314798}]}]}
{"op":"mcm","clk":"991221824","pt":1580502303366,"mc":[{"id":"1.168130661","rc":[{"batb":[[0,2.46,15.4]],"ltp":2.6,"tv":256.32,"id":26314798}]}]}
{"op":"mcm","clk":"991222134","pt":1580502305590,"mc":[{"id":"1.168130661","rc":[{"batb":[[0,2.46,14.98]],"ltp":2.6,"tv":256.32,"id":26314798}]}]}
{"op":"mcm","clk":"991222211","pt":1580502306177,"mc":[{"id":"1.168130661","rc":[{"batb":[[0,2.46,15.4]],"ltp":2.6,"tv":256.32,"id":26314798}]}]}
{"op":"mcm","clk":"991222389","pt":1580502307378,"mc":[{"id":"1.168130661","rc":[{"batb":[[0,2.46,14.98]],"ltp":2.6,"tv":256.32,"id":26314798}]}]}
{"op":"mcm","clk":"991222666","pt":1580502309366,"mc":[{"id":"1.168130661","rc":[{"batb":[[0,2.46,15.4]],"ltp":2.6,"tv":256.32,"id":26314798}]}]}
{"op":"mcm","clk":"991222853","pt":1580502310588,"mc":[{"id":"1.168130661","rc":[{"batb":[[0,2.46,14.98]],"batl":[[0,2.88,2]],"ltp":2.6,"tv":256.32,"id":26314798}]}]}
{"op":"mcm","clk":"991223835","pt":1580502317717,"mc":[{"id":"1.168130661","rc":[{"batl":[[0,2.88,2.19]],"ltp":2.6,"tv":256.32,"id":26314798}]}]}
{"op":"mcm","clk":"991225019","pt":1580502326015,"mc":[{"id":"1.168130661","rc":[{"batl":[[0,2.84,2]],"ltp":2.82,"tv":127.88,"id":25238892}]}]}
{"op":"mcm","clk":"991225367","pt":1580502328403,"mc":[{"id":"1.168130661","rc":[{"batl":[[1,2.88,6.49],[2,2.9,15.79]],"ltp":2.82,"tv":127.88,"id":25238892}]}]}
{"op":"mcm","clk":"991227407","pt":1580502342839,"mc":[{"id":"1.168130661","rc":[{"batb":[[0,2.82,21.66],[1,2.68,2.7],[2,2.62,1]],"ltp":2.82,"tv":127.88,"id":25238892}]}]}
{"op":"mcm","clk":"991230792","pt":1580502366149,"mc":[{"id":"1.168130661","rc":[{"batl":[[2,2.9,4.79]],"ltp":2.82,"tv":127.88,"id":25238892}]}]}
{"op":"mcm","clk":"991236938","pt":1580502408805,"mc":[{"id":"1.168130661","rc":[{"batb":[[0,2.46,15.4]],"ltp":2.6,"tv":256.32,"id":26314798}]}]}
{"op":"mcm","clk":"991237101","pt":1580502409885,"mc":[{"id":"1.168130661","rc":[{"batb":[[0,2.46,14.98]],"ltp":2.6,"tv":256.32,"id":26314798}]}]}
{"op":"mcm","clk":"991237499","pt":1580502412503,"mc":[{"id":"1.168130661","rc":[{"batb":[[0,2.46,15.4]],"ltp":2.6,"tv":256.32,"id":26314798}]}]}
{"op":"mcm","clk":"991237673","pt":1580502413592,"mc":[{"id":"1.168130661","rc":[{"batb":[[0,2.46,14.98]],"ltp":2.6,"tv":256.32,"id":26314798}]}]}
{"op":"mcm","clk":"991237995","pt":1580502415893,"mc":[{"id":"1.168130661","rc":[{"batb":[[0,2.46,15.4]],"ltp":2.6,"tv":256.32,"id":26314798}]}]}
{"op":"mcm","clk":"991238215","pt":1580502417432,"mc":[{"id":"1.168130661","rc":[{"batb":[[0,2.46,14.98]],"ltp":2.6,"tv":256.32,"id":26314798}]}]}
{"op":"mcm","clk":"991238493","pt":1580502419362,"mc":[{"id":"1.168130661","rc":[{"batb":[[0,2.46,15.4]],"ltp":2.6,"tv":256.32,"id":26314798}]}]}
{"op":"mcm","clk":"991238606","pt":1580502420017,"mc":[{"id":"1.168130661","rc":[{"batb":[[0,2.46,14.98]],"ltp":2.6,"tv":256.32,"id":26314798}]}]}
{"op":"mcm","clk":"991240878","pt":1580502435532,"mc":[{"id":"1.168130661","rc":[{"batb":[[0,2.46,15.4]],"batl":[[0,2.88,2]],"ltp":2.6,"tv":256.32,"id":26314798}]}]}
{"op":"mcm","clk":"991240927","pt":1580502435843,"mc":[{"id":"1.168130661","rc":[{"batb":[[0,2.46,14.98]],"ltp":2.6,"tv":256.32,"id":26314798}]}]}
{"op":"mcm","clk":"991241110","pt":1580502437144,"mc":[{"id":"1.168130661","rc":[{"batb":[[0,2.74,25.2],[1,2.46,14.98],[2,2.44,4.73]],"ltp":2.6,"tv":256.32,"id":26314798}]}]}
{"op":"mcm","clk":"991241463","pt":1580502439553,"mc":[{"id":"1.168130661","rc":[{"batb":[[0,2.74,27.18],[1,2.46,13]],"ltp":2.6,"tv":256.32,"id":26314798}]}]}
{"op":"mcm","clk":"991241739","pt":1580502441442,"mc":[{"id":"1.168130661","rc":[{"trd":[[2.74,3.96]],"batb":[[0,2.46,13],[1,2.44,4.73],[2,2.42,20.45]],"ltp":2.74,"tv":260.28,"id":26314798}],"tv":416.17}]}
{"op":"mcm","clk":"991241904","pt":1580502442553,"mc":[{"id":"1.168130661","rc":[{"trd":[[2.88,4.36]],"batb":[[0,2.88,6.32],[1,2.46,13],[2,2.44,4.73]],"batl":[[0,2.9,61.47],[1,3.4,1],[2,3.5,1]],"ltp":2.88,"tv":264.64,"id":26314798}],"tv":420.53}]}
{"op":"mcm","clk":"991242067","pt":1580502443653,"mc":[{"id":"1.168130661","rc":[{"batb":[[1,2.74,25.2],[2,2.46,13]],"ltp":2.88,"tv":264.64,"id":26314798}]}]}
{"op":"mcm","clk":"991243095","pt":1580502450249,"mc":[{"id":"1.168130661","rc":[{"batb":[[1,2.46,13],[2,2.44,4.73]],"ltp":2.88,"tv":264.64,"id":26314798}]}]}
{"op":"mcm","clk":"991243442","pt":1580502452534,"mc":[{"id":"1.168130661","rc":[{"batb":[[1,2.46,13.42]],"ltp":2.88,"tv":264.64,"id":26314798}]}]}
{"op":"mcm","clk":"991244034","pt":1580502456554,"mc":[{"id":"1.168130661","rc":[{"batb":[[1,2.46,13.84]],"ltp":2.88,"tv":264.64,"id":26314798}]}]}
{"op":"mcm","clk":"991245063","pt":1580502463582,"mc":[{"id":"1.168130661","rc":[{"batb":[[1,2.46,13]],"ltp":2.88,"tv":264.64,"id":26314798}]}]}
{"op":"mcm","clk":"991245470","pt":1580502466187,"mc":[{"id":"1.168130661","rc":[{"trd":[[2.9,56.37]],"batb":[[0,2.46,13],[1,2.44,4.73],[2,2.42,20.45]],"batl":[[0,2.9,55.15]],"ltp":2.9,"tv":277.28,"id":26314798}],"tv":433.17}]}
{"op":"mcm","clk":"991245873","pt":1580502468962,"mc":[{"id":"1.168130661","rc":[{"trd":[[2.9,103.97]],"batb":[[0,2.48,5.76],[1,2.46,13],[2,2.44,4.73]],"batl":[[0,2.9,31.35]],"ltp":2.9,"tv":324.89,"id":26314798}],"tv":480.77}]}
{"op":"mcm","clk":"991246050","pt":1580502470085,"mc":[{"id":"1.168130661","rc":[{"batl":[[0,2.9,31.55]],"ltp":2.9,"tv":324.89,"id":26314798}]}]}
{"op":"mcm","clk":"991246441","pt":1580502472498,"mc":[{"id":"1.168130661","rc":[{"batb":[[0,2.5,9.19],[1,2.48,5.76],[2,2.46,13]],"ltp":2.9,"tv":324.89,"id":26314798}]}]}
{"op":"mcm","clk":"991251301","pt":1580502506013,"mc":[{"id":"1.168130661","rc":[{"batl":[[1,2.88,4.49]],"ltp":2.82,"tv":127.88,"id":25238892}]}]}
{"op":"mcm","clk":"991252361","pt":1580502512948,"mc":[{"id":"1.168130661","rc":[{"batl":[[2,2.9,1.79]],"ltp":2.82,"tv":127.88,"id":25238892}]}]}
{"op":"mcm","clk":"991255388","pt":1580502534685,"mc":[{"id":"1.168130661","rc":[{"batb":[[0,2.52,1.98],[1,2.5,9.19],[2,2.48,5.76]],"ltp":2.9,"tv":324.89,"id":26314798}]}]}
{"op":"mcm","clk":"991256487","pt":1580502542884,"mc":[{"id":"1.168130661","rc":[{"batl":[[1,2.86,3],[2,2.88,4.49]],"ltp":2.82,"tv":127.88,"id":25238892}]}]}
{"op":"mcm","clk":"991265582","pt":1580502612377,"mc":[{"id":"1.168130661","rc":[{"batb":[[0,7.4,3],[1,7.2,4.76],[2,7,4.7]],"ltp":7.8,"tv":10.0,"id":420}]}]}
{"op":"mcm","clk":"991266968","pt":1580502621985,"mc":[{"id":"1.168130661","rc":[{"batb":[[1,7.2,1.98]],"ltp":7.8,"tv":10.0,"id":420}]}]}
{"op":"mcm","clk":"991267962","pt":1580502628914,"mc":[{"id":"1.168130661","rc":[{"batb":[[0,7.6,1.98],[1,7.4,3]],"ltp":7.8,"tv":10.0,"id":420}]}]}
{"op":"mcm","clk":"991274466","pt":1580502675057,"mc":[{"id":"1.168130661","rc":[{"batb":[[0,2.52,4.27]],"ltp":2.9,"tv":324.89,"id":26314798}]}]}
{"op":"mcm","clk":"991275862","pt":1580502684796,"mc":[{"id":"1.168130661","rc":[{"batb":[[1,2.48,5.76],[2,2.46,13]],"ltp":2.9,"tv":324.89,"id":26314798}]}]}
{"op":"mcm","clk":"991281956","pt":1580502728648,"mc":[{"id":"1.168130661","rc":[{"batb":[[0,2.52,1.98],[1,2.5,2.3]],"batl":[[0,2.88,5.54],[1,2.9,31.35],[2,3.4,1]],"ltp":2.9,"tv":324.89,"id":26314798}]}]}
{"op":"mcm","clk":"991284277","pt":1580502744614,"mc":[{"id":"1.168130661","rc":[{"batl":[[0,2.86,5.15],[1,2.88,5.34],[2,2.9,31.35]],"ltp":2.9,"tv":324.89,"id":26314798}]}]}
{"op":"mcm","clk":"991289513","pt":1580502781669,"mc":[{"id":"1.168130661","rc":[{"batb":[[1,2.46,13],[2,2.44,4.73]],"ltp":2.9,"tv":324.89,"id":26314798}]}]}
{"op":"mcm","clk":"991289593","pt":1580502782270,"mc":[{"id":"1.168130661","rc":[{"batb":[[1,2.5,9.19],[2,2.48,2.32]],"ltp":2.9,"tv":324.89,"id":26314798}]}]}
{"op":"mcm","clk":"991293412","pt":1580502811400,"mc":[{"id":"1.168130661","rc":[{"trd":[[2.82,32.36]],"batb":[[0,2.82,19.66]],"ltp":2.82,"tv":131.88,"id":25238892}],"tv":484.77}]}
{"op":"mcm","clk":"991296562","pt":1580502834628,"mc":[{"id":"1.168130661","rc":[{"batb":[[0,2.52,4.27],[2,2.46,13]],"ltp":2.9,"tv":324.89,"id":26314798}]}]}
{"op":"mcm","clk":"991297283","pt":1580502840125,"mc":[{"id":"1.168130661","rc":[{"batb":[[1,2.46,13],[2,2.44,4.73]],"ltp":2.9,"tv":324.89,"id":26314798}]}]}
{"op":"mcm","clk":"991303683","pt":1580502887668,"mc":[{"id":"1.168130661","rc":[{"batb":[[0,2.52,1.98]],"ltp":2.9,"tv":324.89,"id":26314798}]}]}
{"op":"mcm","clk":"991305027","pt":1580502897182,"mc":[{"id":"1.168130661","rc":[{"batb":[[1,2.48,9.25],[2,2.46,13]],"ltp":2.9,"tv":324.89,"id":26314798}]}]}
{"op":"mcm","clk":"991306043","pt":1580502903704,"mc":[{"id":"1.168130661","rc":[{"trd":[[2.82,50.36]],"batb":[[0,2.82,10.66]],"ltp":2.82,"tv":149.88,"id":25238892},{"trd":[[2.48,2.04],[2.52,3.96]],"batb":[[0,2.5,5.74],[1,2.48,8.23]],"batl":[[1,2.9,31.35],[2,3.4,1]],"ltp":2.48,"tv":330.89,"id":26314798}],"tv":508.78}]}
{"op":"mcm","clk":"991307594","pt":1580502914503,"mc":[{"id":"1.168130661","rc":[{"batb":[[0,2.52,1.98],[1,2.5,5.74],[2,2.48,8.23]],"ltp":2.48,"tv":330.89,"id":26314798}]}]}
{"op":"mcm","clk":"991307861","pt":1580502916505,"mc":[{"id":"1.168130661","rc":[{"batb":[[2,2.46,13]],"ltp":2.48,"tv":330.89,"id":26314798}]}]}
{"op":"mcm","clk":"991312910","pt":1580502951552,"mc":[{"id":"1.168130661","rc":[{"batb":[[0,26,7.72]],"ltp":0.0,"tv":0.0,"id":25545675},{"batb":[[1,15.5,7.62]],"ltp":0.0,"tv":0.0,"id":24707172},{"trd":[[9.8,6.78]],"batb":[[0,9.8,5.91],[1,8.2,1.68],[2,8,1.68]],"ltp":9.8,"tv":24.77,"id":24420205}],"tv":515.56}]}
{"op":"mcm","clk":"991313886","pt":1580502958249,"mc":[{"id":"1.168130661","rc":[{"batb":[[1,8.4,3],[2,8.2,1.68]],"ltp":9.8,"tv":24.77,"id":24420205}]}]}
{"op":"mcm","clk":"991314394","pt":1580502961547,"mc":[{"id":"1.168130661","rc":[{"batb":[[0,9.8,9.3]],"ltp":9.8,"tv":24.77,"id":24420205}]}]}
{"op":"mcm","clk":"991314614","pt":1580502963149,"mc":[{"id":"1.168130661","rc":[{"batl":[[0,11.5,3.23],[1,12.5,10],[2,14,2.52]],"ltp":9.8,"tv":24.77,"id":24420205}]}]}
{"op":"mcm","clk":"991321749","pt":1580503012506,"mc":[{"id":"1.168130661","rc":[{"batb":[[0,10,1.68],[1,9.8,9.3],[2,8.4,3]],"ltp":9.8,"tv":24.77,"id":24420205}]}]}
{"op":"mcm","clk":"991323284","pt":1580503023394,"mc":[{"id":"1.168130661","rc":[{"batl":[[1,2.88,4.49],[2,2.9,1.79]],"ltp":2.82,"tv":149.88,"id":25238892}]}]}
{"op":"mcm","clk":"991325474","pt":1580503038689,"mc":[{"id":"1.168130661","rc":[{"batb":[[0,2.82,6.84]],"ltp":2.82,"tv":149.88,"id":25238892}]}]}
{"op":"mcm","clk":"991344814","pt":1580503108179,"mc":[{"id":"1.168130661","rc":[{"batb":[[0,2.7,6.84]],"ltp":2.82,"tv":149.88,"id":25238892}]}]}
{"op":"mcm","clk":"991346720","pt":1580503121099,"mc":[{"id":"1.168130661","rc":[{"batb":[[0,2.72,2.39],[1,2.7,6.84],[2,2.68,2.7]],"ltp":2.82,"tv":149.88,"id":25238892}]}]}
{"op":"mcm","clk":"991353738","pt":1580503169327,"mc":[{"id":"1.168130661","rc":[{"batl":[[0,2.88,4.49],[1,2.9,1.79],[2,3,10]],"ltp":2.82,"tv":149.88,"id":25238892}]}]}
{"op":"mcm","clk":"991358161","pt":1580503201874,"mc":[{"id":"1.168130661","rc":[{"batb":[[0,2.72,9.22],[1,2.68,2.7],[2,2.62,1]],"ltp":2.82,"tv":149.88,"id":25238892}]}]}
{"op":"mcm","clk":"991363670","pt":1580503247410,"mc":[{"id":"1.168130661","rc":[{"batb":[[0,2.8,2],[1,2.72,9.22],[2,2.68,2.7]],"ltp":2.82,"tv":149.88,"id":25238892}]}]}
{"op":"mcm","clk":"991364528","pt":1580503254422,"mc":[{"id":"1.168130661","rc":[{"batb":[[1,2.78,2],[2,2.72,9.22]],"ltp":2.82,"tv":149.88,"id":25238892}]}]}
{"op":"mcm","clk":"991369377","pt":1580503294548,"mc":[{"id":"1.168130661","rc":[{"batb":[[0,2.8,8.84],[2,2.72,2.39]],"ltp":2.82,"tv":149.88,"id":25238892}]}]}
{"op":"mcm","clk":"991383467","pt":1580503411996,"mc":[{"id":"1.168130661","rc":[{"batb":[[0,2.52,12.16]],"ltp":2.48,"tv":330.89,"id":26314798}]}]}
{"op":"mcm","clk":"991390116","pt":1580503463763,"mc":[{"id":"1.168130661","rc":[{"batb":[[0,2.54,2.27],[1,2.52,12.16],[2,2.5,5.74]],"ltp":2.48,"tv":330.89,"id":26314798}]}]}
{"op":"mcm","clk":"991391592","pt":1580503475559,"mc":[{"id":"1.168130661","rc":[{"trd":[[10,3.36]],"batb":[[0,9.8,9.3],[1,8.4,3],[2,7.2,11]],"batl":[[0,10,19.32],[1,11.5,3.23],[2,12.5,10]],"ltp":10.0,"tv":28.13,"id":24420205}],"tv":518.92}]}
{"op":"mcm","clk":"991391764","pt":1580503476974,"mc":[{"id":"1.168130661","rc":[{"batl":[[1,12.5,10],[2,14,2.52]],"ltp":10.0,"tv":28.13,"id":24420205}]}]}
{"op":"mcm","clk":"991392712","pt":1580503484880,"mc":[{"id":"1.168130661","rc":[{"batb":[[0,2.56,1.98],[1,2.54,2.27],[2,2.52,10.18]],"ltp":2.48,"tv":330.89,"id":26314798}]}]}
{"op":"mcm","clk":"991407359","pt":1580503605652,"mc":[{"id":"1.168130661","rc":[{"batb":[[2,2.5,5.74]],"ltp":2.48,"tv":330.89,"id":26314798}]}]}
{"op":"mcm","clk":"991409329","pt":1580503622134,"mc":[{"id":"1.168130661","rc":[{"batb":[[1,2.52,2.29]],"ltp":2.48,"tv":330.89,"id":26314798}]}]}
{"op":"mcm","clk":"991412739","pt":1580503651397,"mc":[{"id":"1.168130661","rc":[{"batb":[[0,2.54,1.98]],"ltp":2.48,"tv":330.89,"id":26314798}]}]}
{"op":"mcm","clk":"991417107","pt":1580503691262,"mc":[{"id":"1.168130661","rc":[{"batb":[[0,2.84,1.68],[1,2.8,8.84],[2,2.78,2]],"ltp":2.82,"tv":149.88,"id":25238892}]}]}
{"op":"mcm","clk":"991417215","pt":1580503692249,"mc":[{"id":"1.168130661","rc":[{"batb":[[0,2.8,8.84],[1,2.78,2],[2,2.72,2.39]],"ltp":2.82,"tv":149.88,"id":25238892}]}]}
{"op":"mcm","clk":"991419285","pt":1580503711512,"mc":[{"id":"1.168130661","rc":[{"trd":[[2.54,3.96]],"batb":[[0,2.52,2.29],[1,2.5,5.74],[2,2.46,13]],"batl":[[0,2.54,8.06],[1,2.86,5.15],[2,2.9,31.35]],"ltp":2.54,"tv":334.85,"id":26314798}],"tv":522.88}]}
{"op":"mcm","clk":"991419458","pt":1580503713096,"mc":[{"id":"1.168130661","rc":[{"batl":[[1,2.86,4.95]],"ltp":2.54,"tv":334.85,"id":26314798}]}]}
{"op":"mcm","clk":"991420114","pt":1580503719538,"mc":[{"id":"1.168130661","rc":[{"batl":[[1,2.9,31.35],[2,3.4,1]],"ltp":2.54,"tv":334.85,"id":26314798}]}]}
{"op":"mcm","clk":"991421520","pt":1580503733520,"mc":[{"id":"1.168130661","rc":[{"batb":[[1,2.46,13],[2,2.44,4.73]],"batl":[[0,2.88,5.34]],"ltp":2.54,"tv":334.85,"id":26314798}]}]}
{"op":"mcm","clk":"991422128","pt":1580503739109,"mc":[{"id":"1.168130661","rc":[{"batl":[[0,2.86,12.97],[1,2.88,5.34],[2,2.9,31.35]],"ltp":2.54,"tv":334.85,"id":26314798}]}]}
{"op":"mcm","clk":"991422355","pt":1580503741247,"mc":[{"id":"1.168130661","rc":[{"trd":[[2.86,3.5]],"batl":[[0,2.86,11.41]],"ltp":2.86,"tv":338.35,"id":26314798}],"tv":526.38}]}
{"op":"mcm","clk":"991425705","pt":1580503771478,"mc":[{"id":"1.168130661","rc":[{"batb":[[0,2.54,1.98],[1,2.52,2.29],[2,2.46,13]],"ltp":2.86,"tv":338.35,"id":26314798}]}]}
{"op":"mcm","clk":"991426262","pt":1580503777086,"mc":[{"id":"1.168130661","rc":[{"batb":[[0,2.54,11.88]],"ltp":2.86,"tv":338.35,"id":26314798}]}]}
{"op":"mcm","clk":"991426707","pt":1580503781303,"mc":[{"id":"1.168130661","rc":[{"batb":[[1,2.46,13],[2,2.44,4.73]],"ltp":2.86,"tv":338.35,"id":26314798}]}]}
{"op":"mcm","clk":"991432299","pt":1580503834370,"mc":[{"id":"1.168130661","rc":[{"batb":[[0,2.56,2.25],[1,2.54,11.88],[2,2.46,13]],"ltp":2.86,"tv":338.35,"id":26314798}]}]}
{"op":"mcm","clk":"991434613","pt":1580503857914,"mc":[{"id":"1.168130661","rc":[{"batb":[[0,2.58,1.98],[1,2.56,2.25],[2,2.54,9.9]],"ltp":2.86,"tv":338.35,"id":26314798}]}]}
{"op":"mcm","clk":"991435985","pt":1580503870236,"mc":[{"id":"1.168130661","rc":[{"trd":[[7.4,6],[7.6,3.96]],"batb":[[0,7,4.7],[1,6.8,18.6],[2,6,16.37]],"batl":[[0,7.4,6.31],[1,10.5,1.88],[2,11,4]],"ltp":7.4,"tv":19.96,"id":420}],"tv":536.34}]}
{"op":"mcm","clk":"991436101","pt":1580503871644,"mc":[{"id":"1.168130661","rc":[{"batl":[[1,10.5,1.68]],"ltp":7.4,"tv":19.96,"id":420}]}]}
{"op":"mcm","clk":"991437269","pt":1580503882331,"mc":[{"id":"1.168130661","rc":[{"batb":[[0,7,1.7],[2,6.4,3]],"ltp":7.4,"tv":19.96,"id":420}]}]}
{"op":"mcm","clk":"991438308","pt":1580503892358,"mc":[{"id":"1.168130661","rc":[{"batl":[[1,11,4],[2,21,9]],"ltp":7.4,"tv":19.96,"id":420}]}]}
{"op":"mcm","clk":"991454726","pt":1580503956113,"mc":[{"id":"1.168130661","rc":[{"batb":[[0,7,5.86]],"ltp":7.4,"tv":19.96,"id":420}]}]}
{"op":"mcm","clk":"991460835","pt":1580504019125,"mc":[{"id":"1.168130661","rc":[{"batb":[[0,2.68,5.53],[1,2.66,123],[2,2.58,1.98]],"batl":[[1,2.9,31.35],[2,3.4,1]],"ltp":2.86,"tv":338.35,"id":26314798}]}]}
{"op":"mcm","clk":"991463468","pt":1580504050688,"mc":[{"id":"1.168130661","rc":[{"batb":[[2,2.56,2.25]],"ltp":2.86,"tv":338.35,"id":26314798}]}]}
{"op":"mcm","clk":"991463478","pt":1580504050751,"mc":[{"id":"1.168130661","rc":[{"batb":[[0,2.68,7.51]],"ltp":2.86,"tv":338.35,"id":26314798}]}]}
{"op":"mcm","clk":"991464960","pt":1580504067091,"mc":[{"id":"1.168130661","rc":[{"batb":[[0,2.7,2.13],[1,2.68,7.51],[2,2.66,123]],"ltp":2.86,"tv":338.35,"id":26314798}]}]}
{"op":"mcm","clk":"991465169","pt":1580504069799,"mc":[{"id":"1.168130661","rc":[{"batl":[[0,2.86,11.22]],"ltp":2.86,"tv":338.35,"id":26314798}]}]}
{"op":"mcm","clk":"991466661","pt":1580504092137,"mc":[{"id":"1.168130661","rc":[{"trd":[[2.8,17.68]],"batb":[[0,2.78,2],[1,2.72,2.39],[2,2.68,2.7]],"batl":[[0,2.8,7.16],[1,2.88,4.49],[2,2.9,1.79]],"ltp":2.8,"tv":167.56,"id":25238892}],"tv":554.02}]}
{"op":"mcm","clk":"991467061","pt":1580504099748,"mc":[{"id":"1.168130661","rc":[{"trd":[[2.7,4.26]],"batb":[[0,2.68,7.51],[1,2.66,123],[2,2.54,9.9]],"batl":[[0,2.7,13.87],[1,2.86,11.22],[2,2.9,31.35]],"ltp":2.7,"tv":342.61,"id":26314798}],"tv":558.28}]}
{"op":"mcm","clk":"991467856","pt":1580504115448,"mc":[{"id":"1.168130661","rc":[{"batl":[[1,2.9,31.35],[2,3.4,1]],"ltp":2.7,"tv":342.61,"id":26314798}]}]}
{"op":"mcm","clk":"991467994","pt":1580504117475,"mc":[{"id":"1.168130661","rc":[{"batb":[[1,2.68,2.7],[2,2.62,1]],"ltp":2.8,"tv":167.56,"id":25238892}]}]}
{"op":"mcm","clk":"991468629","pt":1580504129100,"mc":[{"id":"1.168130661","rc":[{"trd":[[2.7,10.26]],"batl":[[0,2.7,10.87]],"ltp":2.7,"tv":348.61,"id":26314798}],"tv":564.28}]}
{"op":"mcm","clk":"991468854","pt":1580504133521,"mc":[{"id":"1.168130661","rc":[{"trd":[[2.78,4]],"batb":[[0,2.68,2.7],[1,2.62,1],[2,2.42,20.45]],"batl":[[0,2.78,6],[1,2.8,7.16],[2,2.88,4.49]],"ltp":2.78,"tv":171.56,"id":25238892}],"tv":568.28}]}
{"op":"mcm","clk":"991468923","pt":1580504134505,"mc":[{"id":"1.168130661","rc":[{"trd":[[2.68,8.72]],"batb":[[0,2.68,3.15]],"ltp":2.68,"tv":357.34,"id":26314798}],"tv":577.0}]}
{"op":"mcm","clk":"991469514","pt":1580504145531,"mc":[{"id":"1.168130661","rc":[{"batb":[[0,2.68,8.02]],"ltp":2.78,"tv":171.56,"id":25238892}]}]}
{"op":"mcm","clk":"991469755","pt":1580504149544,"mc":[{"id":"1.168130661","rc":[{"batl":[[0,2.76,3.29],[1,2.78,6],[2,2.8,7.16]],"ltp":2.78,"tv":171.56,"id":25238892}]}]}
{"op":"mcm","clk":"991477907","pt":1580504273194,"mc":[{"id":"1.168130661","rc":[{"trd":[[2.76,40.76]],"batl":[[0,2.78,6],[1,2.8,7.16],[2,2.88,4.49]],"ltp":2.76,"tv":178.14,"id":25238892},{"trd":[[2.7,14.26]],"batl":[[0,2.7,8.87]],"ltp":2.7,"tv":361.34,"id":26314798}],"tv":587.58}]}
{"op":"mcm","clk":"991477996","pt":1580504274386,"mc":[{"id":"1.168130661","rc":[{"batl":[[0,2.76,5.05],[1,2.78,6],[2,2.8,7.16]],"ltp":2.76,"tv":178.14,"id":25238892}]}]}
{"op":"mcm","clk":"991486426","pt":1580504394655,"mc":[{"id":"1.168130661","rc":[{"trd":[[2.68,15.02]],"batb":[[0,2.66,123],[1,2.54,9.9],[2,2.46,10]],"batl":[[0,2.68,6.85],[1,2.7,8.87],[2,2.9,31.35]],"ltp":2.68,"tv":367.64,"id":26314798}],"tv":593.89}]}
{"op":"mcm","clk":"991487439","pt":1580504404699,"mc":[{"id":"1.168130661","rc":[{"batl":[[0,2.7,8.87],[1,2.9,31.35],[2,3.4,1]],"ltp":2.68,"tv":367.64,"id":26314798}]}]}
{"op":"mcm","clk":"991487465","pt":1580504404816,"mc":[{"id":"1.168130661","rc":[{"batl":[[0,2.7,15.72]],"ltp":2.68,"tv":367.64,"id":26314798}]}]}
{"op":"mcm","clk":"991491557","pt":1580504454689,"mc":[{"id":"1.168130661","rc":[{"batb":[[1,2.46,10],[2,2.44,4.73]],"ltp":2.68,"tv":367.64,"id":26314798}]}]}
{"op":"mcm","clk":"991493880","pt":1580504482731,"mc":[{"id":"1.168130661","rc":[{"trd":[[2.7,35.72]],"batl":[[0,2.7,4.99]],"ltp":2.7,"tv":389.1,"id":26314798}],"tv":615.35}]}
{"op":"mcm","clk":"991495441","pt":1580504502147,"mc":[{"id":"1.168130661","rc":[{"batb":[[0,2.68,3],[1,2.66,123],[2,2.46,10]],"ltp":2.7,"tv":389.1,"id":26314798}]}]}
{"op":"mcm","clk":"991501871","pt":1580504591496,"mc":[{"id":"1.168130661","rc":[{"batl":[[0,2.7,14.99]],"ltp":2.7,"tv":389.1,"id":26314798}]}]}
{"op":"mcm","clk":"991502315","pt":1580504597431,"mc":[{"id":"1.168130661","rc":[{"batb":[[0,2.66,123],[1,2.46,10],[2,2.44,4.73]],"ltp":2.7,"tv":389.1,"id":26314798}]}]}
{"op":"mcm","clk":"991502684","pt":1580504602125,"mc":[{"id":"1.168130661","rc":[{"batl":[[1,2.74,10],[2,2.9,31.35]],"ltp":2.7,"tv":389.1,"id":26314798}]}]}
{"op":"mcm","clk":"991503392","pt":1580504610544,"mc":[{"id":"1.168130661","rc":[{"batl":[[0,2.68,10],[1,2.7,4.99],[2,2.74,10]],"ltp":2.7,"tv":389.1,"id":26314798}]}]}
{"op":"mcm","clk":"991507385","pt":1580504658703,"mc":[{"id":"1.168130661","rc":[{"batb":[[0,27,1.38],[1,26,6.98],[2,25,4.49]],"ltp":0.0,"tv":0.0,"id":25545675},{"batb":[[0,2.7,6.37],[1,2.68,8.02],[2,2.62,1]],"ltp":2.76,"tv":178.14,"id":25238892},{"batb":[[0,16,2.33]],"ltp":0.0,"tv":0.0,"id":24707172},{"batb":[[0,7.2,2.39],[1,7,5.86],[2,6.8,18.6]],"ltp":7.4,"tv":19.96,"id":420}]}]}
{"op":"mcm","clk":"991511355","pt":1580504706617,"mc":[{"id":"1.168130661","rc":[{"batb":[[1,2.68,2.7]],"ltp":2.76,"tv":178.14,"id":25238892},{"batb":[[1,15.5,5.64]],"ltp":0.0,"tv":0.0,"id":24707172},{"batb":[[1,7,1.7]],"ltp":7.4,"tv":19.96,"id":420}]}]}
{"op":"mcm","clk":"991511365","pt":1580504706724,"mc":[{"id":"1.168130661","rc":[{"batb":[[0,2.7,11.69]],"ltp":2.76,"tv":178.14,"id":25238892},{"batb":[[0,16.5,1.98],[1,16,2.33],[2,15.5,5.64]],"ltp":0.0,"tv":0.0,"id":24707172},{"batb":[[0,7.2,6.55]],"ltp":7.4,"tv":19.96,"id":420}]}]}
{"op":"mcm","clk":"991511591","pt":1580504709594,"mc":[{"id":"1.168130661","rc":[{"batb":[[1,16,1.08]],"ltp":0.0,"tv":0.0,"id":24707172}]}]}
{"op":"mcm","clk":"991517405","pt":1580504782192,"mc":[{"id":"1.168130661","rc":[{"batl":[[0,2.74,25.36],[1,2.76,5.05],[2,2.78,6]],"ltp":2.76,"tv":178.14,"id":25238892}]}]}
{"op":"mcm","clk":"991517888","pt":1580504788426,"mc":[{"id":"1.168130661","rc":[{"batl":[[0,2.76,5.05],[1,2.78,6],[2,2.8,7.16]],"ltp":2.76,"tv":178.14,"id":25238892}]}]}
{"op":"mcm","clk":"991518899","pt":1580504800243,"mc":[{"id":"1.168130661","rc":[{"batb":[[0,16,3.06],[1,15.5,5.64],[2,15,7.7]],"ltp":0.0,"tv":0.0,"id":24707172}]}]}
{"op":"mcm","clk":"991534728","pt":1580504873662,"mc":[{"id":"1.168130661","rc":[{"trd":[[16,6]],"batb":[[0,15.5,5.7],[1,15,7.7],[2,12,1.89]],"ltp":16.0,"tv":5.99,"id":24707172}],"tv":621.34}]}
{"op":"mcm","clk":"991535919","pt":1580504889265,"mc":[{"id":"1.168130661","rc":[{"batl":[[0,720,1.68]],"ltp":0.0,"tv":0.0,"id":25545675},{"batl":[[0,470,1.68]],"ltp":16.0,"tv":5.99,"id":24707172}]}]}
{"op":"mcm","clk":"991545254","pt":1580505001660,"mc":[{"id":"1.168130661","rc":[{"batb":[[0,2.46,10],[1,2.44,4.73],[2,2.42,20.45]],"ltp":2.7,"tv":389.1,"id":26314798}]}]}
{"op":"mcm","clk":"991545468","pt":1580505004549,"mc":[{"id":"1.168130661","rc":[{"batb":[[0,2.72,2.12],[1,2.7,11.69],[2,2.68,2.7]],"ltp":2.76,"tv":178.14,"id":25238892},{"batb":[[0,2.48,2.33],[1,2.46,10],[2,2.44,4.73]],"ltp":2.7,"tv":389.1,"id":26314798},{"trd":[[7.4,7.56]],"batl":[[0,7.4,5.53]],"ltp":7.4,"tv":21.52,"id":420}],"tv":622.9}]}
{"op":"mcm","clk":"991545749","pt":1580505008277,"mc":[{"id":"1.168130661","rc":[{"batl":[[0,720,1.88]],"ltp":0.0,"tv":0.0,"id":25545675},{"batl":[[0,470,1.88]],"ltp":16.0,"tv":5.99,"id":24707172}]}]}
{"op":"mcm","clk":"991547359","pt":1580505031701,"mc":[{"id":"1.168130661","rc":[{"batl":[[0,2.66,2],[1,2.68,10],[2,2.7,4.99]],"ltp":2.7,"tv":389.1,"id":26314798}]}]}
{"op":"mcm","clk":"991551348","pt":1580505083425,"mc":[{"id":"1.168130661","rc":[{"batl":[[1,2.7,4.99],[2,2.9,31.35]],"ltp":2.7,"tv":389.1,"id":26314798}]}]}
{"op":"mcm","clk":"991551523","pt":1580505085694,"mc":[{"id":"1.168130661","rc":[{"batl":[[0,2.68,2]],"ltp":2.7,"tv":389.1,"id":26314798}]}]}
{"op":"mcm","clk":"991551773","pt":1580505089512,"mc":[{"id":"1.168130661","rc":[{"batb":[[1,2.44,4.73],[2,2.42,20.45]],"ltp":2.7,"tv":389.1,"id":26314798}]}]}
{"op":"mcm","clk":"991553269","pt":1580505111469,"mc":[{"id":"1.168130661","rc":[{"batb":[[0,17,2],[1,15.5,5.7],[2,15,7.7]],"ltp":16.0,"tv":5.99,"id":24707172}]}]}
{"op":"mcm","clk":"991553843","pt":1580505119692,"mc":[{"id":"1.168130661","rc":[{"batb":[[0,29,2],[1,27,1.38],[2,26,6.98]],"ltp":0.0,"tv":0.0,"id":25545675}]}]}
{"op":"mcm","clk":"991555287","pt":1580505140088,"mc":[{"id":"1.168130661","rc":[{"batb":[[1,26,7.62],[2,25,4.49]],"ltp":0.0,"tv":0.0,"id":25545675}]}]}
{"op":"mcm","clk":"991556373","pt":1580505153600,"mc":[{"id":"1.168130661","rc":[{"batb":[[1,2.46,7],[2,2.44,4.73]],"ltp":2.7,"tv":389.1,"id":26314798}]}]}
{"op":"mcm","clk":"991558027","pt":1580505175138,"mc":[{"id":"1.168130661","rc":[{"batb":[[0,30,1.98],[1,29,2],[2,26,5.64]],"ltp":0.0,"tv":0.0,"id":25545675},{"batb":[[0,2.74,6.28],[1,2.72,7.44]],"ltp":2.76,"tv":178.14,"id":25238892},{"batb":[[0,17,2.06],[1,15.5,5.64]],"ltp":16.0,"tv":5.99,"id":24707172}]}]}
{"op":"mcm","clk":"991566393","pt":1580505285632,"mc":[{"id":"1.168130661","rc":[{"trd":[[7.2,4]],"batb":[[0,7.2,4.55]],"ltp":7.2,"tv":25.52,"id":420}],"tv":626.9}]}
{"op":"mcm","clk":"991568267","pt":1580505311434,"mc":[{"id":"1.168130661","rc":[{"batb":[[0,2.74,11.6],[1,2.72,2.12]],"ltp":2.76,"tv":178.14,"id":25238892},{"batb":[[0,2.5,6.89],[1,2.48,4.01]],"ltp":2.7,"tv":389.1,"id":26314798}]}]}
{"op":"mcm","clk":"991570084","pt":1580505337700,"mc":[{"id":"1.168130661","rc":[{"batl":[[0,2.78,6],[1,2.8,7.16],[2,2.88,4.49]],"ltp":2.76,"tv":178.14,"id":25238892}]}]}
{"op":"mcm","clk":"991578233","pt":1580505453013,"mc":[{"id":"1.168130661","rc":[{"batb":[[0,2.5,8.57],[1,2.48,2.33]],"ltp":2.7,"tv":389.1,"id":26314798}]}]}
{"op":"mcm","clk":"991583758","pt":1580505517706,"mc":[{"id":"1.168130661","rc":[{"trd":[[2.74,24]],"batb":[[0,2.74,1.6]],"ltp":2.74,"tv":198.14,"id":25238892}],"tv":646.91}]}
{"op":"mcm","clk":"991584528","pt":1580505527535,"mc":[{"id":"1.168130661","rc":[{"batl":[[0,2.76,3.29],[1,2.78,6],[2,2.8,7.16]],"ltp":2.74,"tv":198.14,"id":25238892}]}]}
{"op":"mcm","clk":"991600783","pt":1580505722674,"mc":[{"id":"1.168130661","rc":[{"trd":[[2.5,4]],"batb":[[0,2.5,6.57]],"ltp":2.5,"tv":393.1,"id":26314798}],"tv":650.91}]}
{"op":"mcm","clk":"991624136","pt":1580505886322,"mc":[{"id":"1.168130661","rc":[{"batb":[[0,2.52,25],[1,2.5,6.57],[2,2.48,2.33]],"ltp":2.5,"tv":393.1,"id":26314798}]}]}
{"op":"mcm","clk":"991625451","pt":1580505902960,"mc":[{"id":"1.168130661","rc":[{"trd":[[2.68,19.02]],"batl":[[0,2.7,4.99],[1,2.9,31.35],[2,3.4,1]],"ltp":2.68,"tv":397.1,"id":26314798}],"tv":654.91}]}
{"op":"mcm","clk":"991625698","pt":1580505906157,"mc":[{"id":"1.168130661","rc":[{"trd":[[2.76,47.34],[2.78,16],[2.8,27.58]],"batl":[[0,2.8,2.21],[1,2.88,4.49],[2,2.9,1.79]],"ltp":2.8,"tv":226.63,"id":25238892},{"trd":[[10,11.3]],"batl":[[0,10,15.35]],"ltp":10.0,"tv":36.08,"id":24420205},{"trd":[[2.46,32.22],[2.48,6.69],[2.5,17.14]],"batb":[[0,2.44,4.73],[1,2.42,20.45],[2,2.28,20.45]],"ltp":2.46,"tv":447.1,"id":26314798},{"trd":[[7.4,18.62]],"batl":[[0,11,4],[1,21,9],[2,21,0]],"ltp":7.4,"tv":36.58,"id":420}],"tv":752.4}]}
{"op":"mcm","clk":"991625794","pt":1580505907562,"mc":[{"id":"1.168130661","rc":[{"batl":[[2,1000,0.2]],"ltp":7.4,"tv":36.58,"id":420}]}]}
{"op":"mcm","clk":"991625863","pt":1580505908581,"mc":[{"id":"1.168130661","rc":[{"batl":[[0,11,4.2],[2,1000,0]],"ltp":7.4,"tv":36.58,"id":420}]}]}
{"op":"mcm","clk":"991626023","pt":1580505910648,"mc":[{"id":"1.168130661","rc":[{"batl":[[1,2.86,1.7],[2,2.88,4.49]],"ltp":2.8,"tv":226.63,"id":25238892},{"batb":[[2,6.8,20.66]],"batl":[[0,10.5,1.88],[1,11,4],[2,21,9]],"ltp":7.4,"tv":36.58,"id":420}]}]}
{"op":"mcm","clk":"991627424","pt":1580505931379,"mc":[{"id":"1.168130661","rc":[{"batb":[[0,2.44,44.73]],"ltp":2.46,"tv":447.1,"id":26314798}]}]}
{"op":"mcm","clk":"991627647","pt":1580505935014,"mc":[{"id":"1.168130661","rc":[{"trd":[[10,15.3]],"batl":[[0,10,13.35]],"ltp":10.0,"tv":40.08,"id":24420205}],"tv":756.39}]}
{"op":"mcm","clk":"991627807","pt":1580505937685,"mc":[{"id":"1.168130661","rc":[{"batb":[[0,2.46,3],[1,2.44,44.73],[2,2.42,20.45]],"ltp":2.46,"tv":447.1,"id":26314798}]}]}
{"op":"mcm","clk":"991628112","pt":1580505942814,"mc":[{"id":"1.168130661","rc":[{"batb":[[0,2.48,2.16],[1,2.46,3],[2,2.44,44.73]],"ltp":2.46,"tv":447.1,"id":26314798}]}]}
{"op":"mcm","clk":"991633096","pt":1580506018470,"mc":[{"id":"1.168130661","rc":[{"batb":[[0,2.52,25],[1,2.48,2.16],[2,2.46,3]],"ltp":2.46,"tv":447.1,"id":26314798}]}]}
{"op":"mcm","clk":"991633342","pt":1580506022463,"mc":[{"id":"1.168130661","rc":[{"batb":[[0,2.54,3],[1,2.52,25],[2,2.48,2.16]],"ltp":2.46,"tv":447.1,"id":26314798}]}]}
{"op":"mcm","clk":"991634823","pt":1580506049615,"mc":[{"id":"1.168130661","rc":[{"batb":[[2,2.44,44.73]],"ltp":2.46,"tv":447.1,"id":26314798}]}]}
{"op":"mcm","clk":"991634829","pt":1580506049728,"mc":[{"id":"1.168130661","rc":[{"batb":[[0,2.56,2.09],[1,2.54,3],[2,2.52,25]],"ltp":2.46,"tv":447.1,"id":26314798}]}]}
{"op":"mcm","clk":"991640276","pt":1580506145451,"mc":[{"id":"1.168130661","rc":[{"batb":[[1,2.54,153]],"ltp":2.46,"tv":447.1,"id":26314798}]}]}
{"op":"mcm","clk":"991645870","pt":1580506238720,"mc":[{"id":"1.168130661","rc":[{"trd":[[15.5,9.88],[17,4],[17.5,0.12]],"batb":[[0,15,8.4],[1,12,1.89],[2,9,9]],"ltp":15.5,"tv":19.99,"id":24707172}],"tv":770.39}]}
{"op":"mcm","clk":"991646302","pt":1580506245588,"mc":[{"id":"1.168130661","rc":[{"batb":[[0,15,7.7],[2,11.5,7.79]],"ltp":15.5,"tv":19.99,"id":24707172}]}]}
{"op":"mcm","clk":"991647006","pt":1580506256126,"mc":[{"id":"1.168130661","rc":[{"batl":[[0,21,13.8],[1,470,1.88],[2,480,13]],"ltp":15.5,"tv":19.99,"id":24707172}]}]}
{"op":"mcm","clk":"991647192","pt":1580506259044,"mc":[{"id":"1.168130661","rc":[{"batb":[[0,15.5,1.98],[1,15,7.7],[2,12,1.89]],"ltp":15.5,"tv":19.99,"id":24707172}]}]}
{"op":"mcm","clk":"991647405","pt":1580506261327,"mc":[{"id":"1.168130661","rc":[{"batl":[[0,21,14],[1,470,1.68]],"ltp":15.5,"tv":19.99,"id":24707172}]}]}
{"op":"mcm","clk":"991648041","pt":1580506270437,"mc":[{"id":"1.168130661","rc":[{"trd":[[15,15.4],[15.5,13.84]],"batb":[[0,12,1.89],[1,11.5,7.79],[2,9,9]],"batl":[[0,21,14.32]],"ltp":15.0,"tv":39.35,"id":24707172}],"tv":789.76}]}
{"op":"mcm","clk":"991648169","pt":1580506272645,"mc":[{"id":"1.168130661","rc":[{"batl":[[0,21,14.12]],"ltp":15.0,"tv":39.35,"id":24707172}]}]}
{"op":"mcm","clk":"991648210","pt":1580506273262,"mc":[{"id":"1.168130661","rc":[{"batl":[[0,20,2],[1,21,13.8]],"ltp":15.0,"tv":39.35,"id":24707172}]}]}
{"op":"mcm","clk":"991649245","pt":1580506289707,"mc":[{"id":"1.168130661","rc":[{"batl":[[0,20,1.68]],"ltp":15.0,"tv":39.35,"id":24707172}]}]}
{"op":"mcm","clk":"991649252","pt":1580506289809,"mc":[{"id":"1.168130661","rc":[{"batl":[[1,21,14.12]],"ltp":15.0,"tv":39.35,"id":24707172}]}]}
{"op":"mcm","clk":"991649415","pt":1580506292236,"mc":[{"id":"1.168130661","rc":[{"batl":[[0,20,1.86]],"ltp":15.0,"tv":39.35,"id":24707172}]}]}
{"op":"mcm","clk":"991650383","pt":1580506307536,"mc":[{"id":"1.168130661","rc":[{"trd":[[2.8,32]],"batl":[[0,2.86,1.7],[1,2.88,4.49],[2,2.9,1.79]],"ltp":2.8,"tv":231.05,"id":25238892}],"tv":794.18}]}
{"op":"mcm","clk":"991653453","pt":1580506348287,"mc":[{"id":"1.168130661","rc":[{"batb":[[0,12.5,2],[1,12,1.89],[2,11.5,7.79]],"ltp":15.0,"tv":39.35,"id":24707172}]}]}
{"op":"mcm","clk":"991653864","pt":1580506354204,"mc":[{"id":"1.168130661","rc":[{"batb":[[0,13,1.98],[1,12.5,2],[2,12,1.89]],"ltp":15.0,"tv":39.35,"id":24707172}]}]}
{"op":"mcm","clk":"991654298","pt":1580506359982,"mc":[{"id":"1.168130661","rc":[{"batb":[[0,2.74,11.6]],"ltp":2.8,"tv":231.05,"id":25238892}]}]}
{"op":"mcm","clk":"991656027","pt":1580506385648,"mc":[{"id":"1.168130661","rc":[{"batb":[[0,9.8,18.38]],"ltp":10.0,"tv":40.08,"id":24420205}]}]}
{"op":"mcm","clk":"991656096","pt":1580506386636,"mc":[{"id":"1.168130661","rc":[{"batl":[[2,480,4]],"ltp":15.0,"tv":39.35,"id":24707172},{"batb":[[0,9.8,9.08]],"ltp":10.0,"tv":40.08,"id":24420205}]}]}
{"op":"mcm","clk":"991656105","pt":1580506386740,"mc":[{"id":"1.168130661","rc":[{"batl":[[2,60,9]],"ltp":15.0,"tv":39.35,"id":24707172}]}]}
{"op":"mcm","clk":"991656628","pt":1580506394649,"mc":[{"id":"1.168130661","rc":[{"trd":[[2.74,34]],"batb":[[0,2.74,6.6]],"ltp":2.74,"tv":241.04,"id":25238892}],"tv":804.17}]}
{"op":"mcm","clk":"991659921","pt":1580506449346,"mc":[{"id":"1.168130661","rc":[{"batb":[[0,2.74,10.8]],"ltp":2.74,"tv":241.04,"id":25238892},{"batb":[[0,2.56,6.21]],"ltp":2.46,"tv":447.1,"id":26314798}]}]}
{"op":"mcm","clk":"991660534","pt":1580506458978,"mc":[{"id":"1.168130661","rc":[{"batb":[[0,2.58,3],[1,2.56,6.21],[2,2.54,150]],"ltp":2.46,"tv":447.1,"id":26314798}]}]}
{"op":"mcm","clk":"991662040","pt":1580506482686,"mc":[{"id":"1.168130661","rc":[{"trd":[[2.7,45.7]],"batb":[[0,2.6,2.74],[1,2.58,3],[2,2.56,4.12]],"batl":[[0,2.88,5.14]],"ltp":2.7,"tv":457.08,"id":26314798}],"tv":814.15}]}
{"op":"mcm","clk":"991662334","pt":1580506487498,"mc":[{"id":"1.168130661","rc":[{"batb":[[1,2.56,7.12],[2,2.54,150]],"ltp":2.7,"tv":457.08,"id":26314798}]}]}
{"op":"mcm","clk":"991662692","pt":1580506492108,"mc":[{"id":"1.168130661","rc":[{"batb":[[0,7.4,5],[1,7.2,4.55],[2,7,1.7]],"ltp":7.4,"tv":36.58,"id":420}]}]}
{"op":"mcm","clk":"991665612","pt":1580506536633,"mc":[{"id":"1.168130661","rc":[{"batb":[[0,2.56,7.8],[1,2.54,150],[2,2.52,25]],"ltp":2.7,"tv":457.08,"id":26314798}]}]}
{"op":"mcm","clk":"991665614","pt":1580506536736,"mc":[{"id":"1.168130661","rc":[{"batb":[[0,2.58,2.76],[1,2.56,7.12],[2,2.54,150]],"ltp":2.7,"tv":457.08,"id":26314798}]}]}
{"op":"mcm","clk":"991666075","pt":1580506543644,"mc":[{"id":"1.168130661","rc":[{"batb":[[0,2.6,4.8],[1,2.58,2.08],[2,2.56,3]],"ltp":2.7,"tv":457.08,"id":26314798},{"batb":[[0,7.6,4.16],[1,7.4,5],[2,7,2.1]],"ltp":7.4,"tv":36.58,"id":420}]}]}
{"op":"mcm","clk":"991669311","pt":1580506590347,"mc":[{"id":"1.168130661","rc":[{"batb":[[0,2.62,2.73],[1,2.6,4.12]],"ltp":2.7,"tv":457.08,"id":26314798}]}]}
{"op":"mcm","clk":"991672538","pt":1580506638700,"mc":[{"id":"1.168130661","rc":[{"batb":[[0,2.64,4.8],[1,2.62,2.05]],"ltp":2.7,"tv":457.08,"id":26314798}]}]}
{"op":"mcm","clk":"991685052","pt":1580506683966,"mc":[{"id":"1.168130661","rc":[{"batb":[[0,7.8,2.21],[1,7.6,4.16],[2,7.4,5]],"ltp":7.4,"tv":36.58,"id":420}]}]}
{"op":"mcm","clk":"991688130","pt":1580506731621,"mc":[{"id":"1.168130661","rc":[{"batb":[[0,8,4.16],[1,7.8,2.21]],"ltp":7.4,"tv":36.58,"id":420}]}]}
{"op":"mcm","clk":"991702652","pt":1580506948634,"mc":[{"id":"1.168130661","rc":[{"batb":[[0,13.5,2.27],[1,13,1.98],[2,12.5,2]],"ltp":15.0,"tv":39.35,"id":24707172}]}]}
{"op":"mcm","clk":"991703027","pt":1580506954663,"mc":[{"id":"1.168130661","rc":[{"batb":[[0,30,2.91]],"ltp":0.0,"tv":0.0,"id":25545675}]}]}
{"op":"mcm","clk":"991706234","pt":1580507011344,"mc":[{"id":"1.168130661","rc":[{"batb":[[0,8.2,2.1],[1,8,4.16]],"ltp":7.4,"tv":36.58,"id":420}]}]}
{"op":"mcm","clk":"991706456","pt":1580507015220,"mc":[{"id":"1.168130661","rc":[{"batb":[[0,14,1.98],[1,13.5,2.27]],"ltp":15.0,"tv":39.35,"id":24707172},{"batb":[[0,8.4,4.16],[1,8.2,2.1]],"ltp":7.4,"tv":36.58,"id":420}]}]}
{"op":"mcm","clk":"991706672","pt":1580507019448,"mc":[{"id":"1.168130661","rc":[{"batb":[[0,14.5,2.27],[1,14,1.98]],"ltp":15.0,"tv":39.35,"id":24707172}]}]}
{"op":"mcm","clk":"991707366","pt":1580507031946,"mc":[{"id":"1.168130661","rc":[{"trd":[[2.64,4.64],[2.7,47.06]],"batb":[[0,2.64,1.81]],"ltp":2.64,"tv":463.08,"id":26314798}],"tv":820.15}]}
{"op":"mcm","clk":"991707635","pt":1580507037585,"mc":[{"id":"1.168130661","rc":[{"batl":[[0,2.88,5.33]],"ltp":2.64,"tv":463.08,"id":26314798}]}]}
{"op":"mcm","clk":"991709063","pt":1580507064136,"mc":[{"id":"1.168130661","rc":[{"batb":[[0,15,1.98],[1,14.5,2.27]],"ltp":15.0,"tv":39.35,"id":24707172}]}]}
{"op":"mcm","clk":"991709422","pt":1580507071424,"mc":[{"id":"1.168130661","rc":[{"batb":[[1,2.58,2.08]],"ltp":2.64,"tv":463.08,"id":26314798}]}]}
{"op":"mcm","clk":"991711596","pt":1580507109364,"mc":[{"id":"1.168130661","rc":[{"batb":[[0,2.6,1.81]],"ltp":2.64,"tv":463.08,"id":26314798}]}]}
{"op":"mcm","clk":"991714833","pt":1580507161649,"mc":[{"id":"1.168130661","rc":[{"batb":[[0,8.6,2],[1,8.4,4.16]],"ltp":7.4,"tv":36.58,"id":420}]}]}
{"op":"mcm","clk":"991715319","pt":1580507169568,"mc":[{"id":"1.168130661","rc":[{"batb":[[0,8.8,4.16],[1,8.6,2]],"ltp":7.4,"tv":36.58,"id":420}]}]}
{"op":"mcm","clk":"991715685","pt":1580507174964,"mc":[{"id":"1.168130661","rc":[{"batl":[[0,10.5,1.68]],"ltp":7.4,"tv":36.58,"id":420}]}]}
{"op":"mcm","clk":"991723832","pt":1580507311694,"mc":[{"id":"1.168130661","rc":[{"batb":[[0,9,1.92],[1,8.8,4.16]],"ltp":7.4,"tv":36.58,"id":420}]}]}
{"op":"mcm","clk":"991724436","pt":1580507322681,"mc":[{"id":"1.168130661","rc":[{"batb":[[1,7.4,5],[2,7,1.47]],"ltp":7.4,"tv":36.58,"id":420}]}]}
{"op":"mcm","clk":"991724461","pt":1580507323107,"mc":[{"id":"1.168130661","rc":[{"batb":[[0,9.2,4.16],[1,9,1.92],[2,7.4,5]],"ltp":7.4,"tv":36.58,"id":420}]}]}
{"op":"mcm","clk":"991727213","pt":1580507370672,"mc":[{"id":"1.168130661","rc":[{"trd":[[15,18.78]],"batb":[[0,14.5,2.56],[1,12.5,2],[2,12,1.89]],"ltp":15.0,"tv":42.73,"id":24707172}],"tv":823.53}]}
{"op":"mcm","clk":"991728698","pt":1580507392488,"mc":[{"id":"1.168130661","rc":[{"batb":[[0,15,1.62],[1,14.5,2.27],[2,12.5,2]],"batl":[[0,19.5,2.18],[1,20,1.68],[2,21,14.12]],"ltp":15.0,"tv":42.73,"id":24707172}]}]}
{"op":"mcm","clk":"991730441","pt":1580507419717,"mc":[{"id":"1.168130661","rc":[{"batl":[[2,21,0]],"ltp":7.4,"tv":36.58,"id":420}]}]}
{"op":"mcm","clk":"991730448","pt":1580507419822,"mc":[{"id":"1.168130661","rc":[{"batl":[[2,32,9]],"ltp":7.4,"tv":36.58,"id":420}]}]}
{"op":"mcm","clk":"991730653","pt":1580507422663,"mc":[{"id":"1.168130661","rc":[{"trd":[[9.8,10.48]],"batb":[[0,9.8,7.23]],"ltp":9.8,"tv":43.77,"id":24420205}],"tv":827.22}]}
{"op":"mcm","clk":"991730931","pt":1580507427335,"mc":[{"id":"1.168130661","rc":[{"batb":[[0,9.8,9.08]],"ltp":9.8,"tv":43.77,"id":24420205}]}]}
{"op":"mcm","clk":"991733010","pt":1580507462232,"mc":[{"id":"1.168130661","rc":[{"batb":[[0,9.4,1.83],[1,9.2,4.16]],"ltp":7.4,"tv":36.58,"id":420}]}]}
{"op":"mcm","clk":"991733604","pt":1580507471329,"mc":[{"id":"1.168130661","rc":[{"batb":[[0,34,3.03],[1,30,2.91],[2,29,2]],"ltp":0.0,"tv":0.0,"id":25545675}]}]}
{"op":"mcm","clk":"991733660","pt":1580507472413,"mc":[{"id":"1.168130661","rc":[{"batb":[[0,30,2.91],[1,29,2],[2,26,5.64]],"ltp":0.0,"tv":0.0,"id":25545675}]}]}
{"op":"mcm","clk":"991748537","pt":1580507555635,"mc":[{"id":"1.168130661","rc":[{"batb":[[0,9.6,4.16],[1,9.4,1.83]],"ltp":7.4,"tv":36.58,"id":420}]}]}
{"op":"mcm","clk":"991748977","pt":1580507563154,"mc":[{"id":"1.168130661","rc":[{"batb":[[0,2.6,76.81]],"ltp":2.64,"tv":463.08,"id":26314798}]}]}
{"op":"mcm","clk":"991750383","pt":1580507585657,"mc":[{"id":"1.168130661","rc":[{"batl":[[0,19,3.03],[1,19.5,2.18],[2,20,1.68]],"ltp":15.0,"tv":42.73,"id":24707172}]}]}
{"op":"mcm","clk":"991750847","pt":1580507593695,"mc":[{"id":"1.168130661","rc":[{"batl":[[0,19.5,2.18],[1,20,1.68],[2,21,14.12]],"ltp":15.0,"tv":42.73,"id":24707172}]}]}
{"op":"mcm","clk":"991751532","pt":1580507603299,"mc":[{"id":"1.168130661","rc":[{"trd":[[10,32.38]],"batl":[[0,10,4.8]],"ltp":10.0,"tv":60.86,"id":24420205}],"tv":844.31}]}
{"op":"mcm","clk":"991751701","pt":1580507605892,"mc":[{"id":"1.168130661","rc":[{"batb":[[0,2.62,2.05],[1,2.6,76.81]],"ltp":2.64,"tv":463.08,"id":26314798}]}]}
{"op":"mcm","clk":"991751831","pt":1580507608009,"mc":[{"id":"1.168130661","rc":[{"batb":[[0,2.62,5.05],[2,2.54,150]],"ltp":2.64,"tv":463.08,"id":26314798}]}]}
{"op":"mcm","clk":"991751981","pt":1580507610491,"mc":[{"id":"1.168130661","rc":[{"batb":[[2,2.56,6]],"ltp":2.64,"tv":463.08,"id":26314798}]}]}
{"op":"mcm","clk":"991757631","pt":1580507702546,"mc":[{"id":"1.168130661","rc":[{"batb":[[0,9.8,1.76],[1,9.6,4.16]],"ltp":7.4,"tv":36.58,"id":420}]}]}
{"op":"mcm","clk":"991759348","pt":1580507731208,"mc":[{"id":"1.168130661","rc":[{"batl":[[0,11,4],[1,32,9],[2,32,0]],"ltp":7.4,"tv":36.58,"id":420}]}]}
{"op":"mcm","clk":"991768221","pt":1580507905517,"mc":[{"id":"1.168130661","rc":[{"batb":[[0,2.76,7.25],[1,2.74,10.8],[2,2.72,2.12]],"ltp":2.74,"tv":241.04,"id":25238892}]}]}
{"op":"mcm","clk":"991770113","pt":1580507945383,"mc":[{"id":"1.168130661","rc":[{"trd":[[2.62,8]],"batb":[[0,2.62,1.05]],"ltp":2.62,"tv":471.08,"id":26314798}],"tv":852.31}]}
{"op":"mcm","clk":"991773872","pt":1580508024916,"mc":[{"id":"1.168130661","rc":[{"trd":[[2.74,34],[2.76,47.35],[2.8,32]],"batb":[[1,2.74,10.8],[2,2.72,2.12]],"batl":[[0,2.86,61.7]],"ltp":2.74,"tv":241.05,"id":25238892},{"trd":[[15,18.78],[16,6]],"ltp":15.0,"tv":42.73,"id":24707172},{"trd":[[8.2,7.97],[10,32.39]],"batl":[[0,10,4.81]],"ltp":10.0,"tv":60.86,"id":24420205},{"trd":[[2.48,6.68],[2.5,17.14],[2.7,47.06],[2.9,103.98],[2.96,22.63],[3.1,41.84],[3.45,88.1],[3.55,14.28],[3.6,23.52]],"ltp":2.62,"tv":471.09,"id":26314798},{"trd":[[7.4,18.62]],"batb":[[0,9.8,61.76],[1,9.6,4.16]],"ltp":7.4,"tv":36.58,"id":420}],"tv":852.34}]}
{"op":"mcm","clk":"991774139","pt":1580508029589,"mc":[{"id":"1.168130661","rc":[{"batl":[[0,2.84,4],[1,2.86,61.7],[2,2.88,4.49]],"ltp":2.74,"tv":241.05,"id":25238892}]}]}
{"op":"mcm","clk":"991774321","pt":1580508033585,"mc":[{"id":"1.168130661","rc":[{"batl":[[0,2.82,1.72],[1,2.84,4],[2,2.86,60]],"ltp":2.74,"tv":241.05,"id":25238892},{"batl":[[0,19,1.68],[1,19.5,2.18]],"ltp":15.0,"tv":42.73,"id":24707172}]}]}
{"op":"mcm","clk":"991776950","pt":1580508079551,"mc":[{"id":"1.168130661","rc":[{"batl":[[1,21,14.3],[2,60,9]],"ltp":15.0,"tv":42.73,"id":24707172}]}]}
{"op":"mcm","clk":"991783037","pt":1580508178929,"mc":[{"id":"1.168130661","rc":[{"trd":[[9.8,15.34]],"batb":[[0,9.8,6.65]],"ltp":9.8,"tv":65.72,"id":24420205}],"tv":857.2}]}
{"op":"mcm","clk":"991783574","pt":1580508188420,"mc":[{"id":"1.168130661","rc":[{"batb":[[0,9.8,9.08]],"ltp":9.8,"tv":65.72,"id":24420205}]}]}
{"op":"mcm","clk":"991783985","pt":1580508195466,"mc":[{"id":"1.168130661","rc":[{"batl":[[0,20,1.86],[1,21,14.12]],"ltp":15.0,"tv":42.73,"id":24707172}]}]}
{"op":"mcm","clk":"991784021","pt":1580508196188,"mc":[{"id":"1.168130661","rc":[{"batl":[[0,10.5,2.5],[1,11,4],[2,32,9]],"ltp":7.4,"tv":36.58,"id":420}]}]}
{"op":"mcm","clk":"991786024","pt":1580508230501,"mc":[{"id":"1.168130661","rc":[{"batl":[[0,18,3],[1,20,1.86],[2,21,14.12]],"ltp":15.0,"tv":42.73,"id":24707172}]}]}
{"op":"mcm","clk":"991786056","pt":1580508231084,"mc":[{"id":"1.168130661","rc":[{"batl":[[1,20,1.68]],"ltp":15.0,"tv":42.73,"id":24707172}]}]}
{"op":"mcm","clk":"991787421","pt":1580508253410,"mc":[{"id":"1.168130661","rc":[{"batl":[[0,60,2],[1,720,1.88],[2,730,13]],"ltp":0.0,"tv":0.0,"id":25545675}]}]}
{"op":"mcm","clk":"991787531","pt":1580508255312,"mc":[{"id":"1.168130661","rc":[{"batl":[[0,60,2.2],[1,720,1.68]],"ltp":0.0,"tv":0.0,"id":25545675}]}]}
{"op":"mcm","clk":"991788935","pt":1580508279346,"mc":[{"id":"1.168130661","rc":[{"batl":[[0,11,4],[1,32,9],[2,32,0]],"ltp":7.4,"tv":36.58,"id":420}]}]}
{"op":"mcm","clk":"991789400","pt":1580508286183,"mc":[{"id":"1.168130661","rc":[{"batl":[[0,55,1.88],[1,60,2]],"ltp":0.0,"tv":0.0,"id":25545675}]}]}
{"op":"mcm","clk":"991789687","pt":1580508290365,"mc":[{"id":"1.168130661","rc":[{"batl":[[0,17.5,2],[1,18,3],[2,20,1.68]],"ltp":15.0,"tv":42.73,"id":24707172}]}]}
{"op":"mcm","clk":"991790467","pt":1580508301108,"mc":[{"id":"1.168130661","rc":[{"trd":[[2.76,61.85]],"batb":[[0,2.74,10.8],[1,2.72,2.12],[2,2.68,2.7]],"batl":[[0,2.76,2.75],[1,2.82,1.72],[2,2.84,4]],"ltp":2.76,"tv":255.55,"id":25238892}],"tv":871.7}]}
{"op":"mcm","clk":"991790941","pt":1580508308609,"mc":[{"id":"1.168130661","rc":[{"trd":[[2.74,39.5]],"batb":[[0,2.74,8.05]],"batl":[[0,2.82,1.72],[1,2.84,4],[2,2.86,60]],"ltp":2.74,"tv":261.05,"id":25238892}],"tv":877.2}]}
{"op":"mcm","clk":"991791528","pt":1580508318006,"mc":[{"id":"1.168130661","rc":[{"batl":[[2,230,9]],"ltp":0.0,"tv":0.0,"id":25545675}]}]}
{"op":"mcm","clk":"991791592","pt":1580508319144,"mc":[{"id":"1.168130661","rc":[{"batl":[[0,2.74,6],[1,2.88,5.33],[2,2.9,31.35]],"ltp":2.62,"tv":471.09,"id":26314798}]}]}
{"op":"mcm","clk":"991791972","pt":1580508325749,"mc":[{"id":"1.168130661","rc":[{"batl":[[1,2.88,5.14]],"ltp":2.62,"tv":471.09,"id":26314798}]}]}
{"op":"mcm","clk":"991793129","pt":1580508343660,"mc":[{"id":"1.168130661","rc":[{"batl":[[0,2.72,2],[1,2.74,6],[2,2.88,5.14]],"ltp":2.62,"tv":471.09,"id":26314798}]}]}
{"op":"mcm","clk":"991794458","pt":1580508367595,"mc":[{"id":"1.168130661","rc":[{"batl":[[0,17,1.68],[1,17.5,2],[2,18,3]],"ltp":15.0,"tv":42.73,"id":24707172}]}]}
{"op":"mcm","clk":"991796264","pt":1580508397545,"mc":[{"id":"1.168130661","rc":[{"batl":[[0,16.5,2],[1,17,1.68]],"ltp":15.0,"tv":42.73,"id":24707172}]}]}
{"op":"mcm","clk":"991811365","pt":1580508484994,"mc":[{"id":"1.168130661","rc":[{"trd":[[2.72,4]],"batb":[[0,2.72,18],[1,2.62,1.05],[2,2.6,76.81]],"batl":[[0,2.74,6],[1,2.88,5.14],[2,2.9,31.35]],"ltp":2.72,"tv":475.09,"id":26314798}],"tv":881.2}]}
{"op":"mcm","clk":"991811977","pt":1580508494527,"mc":[{"id":"1.168130661","rc":[{"trd":[[2.82,53.8],[2.84,36.56]],"batl":[[0,2.86,60],[1,2.88,4.49],[2,2.9,1.79]],"ltp":2.84,"tv":301.06,"id":25238892},{"trd":[[2.74,15.96]],"batl":[[0,2.88,10.49],[1,2.9,31.35],[2,3.4,1]],"ltp":2.74,"tv":487.09,"id":26314798}],"tv":933.2}]}
{"op":"mcm","clk":"991812046","pt":1580508495624,"mc":[{"id":"1.168130661","rc":[{"batb":[[0,2.74,9.05]],"ltp":2.84,"tv":301.06,"id":25238892}]}]}
{"op":"mcm","clk":"991812258","pt":1580508498718,"mc":[{"id":"1.168130661","rc":[{"batb":[[0,2.76,4.12],[1,2.74,9.05],[2,2.72,2.12]],"ltp":2.84,"tv":301.06,"id":25238892},{"batb":[[1,2.6,76.81],[2,2.56,6]],"ltp":2.74,"tv":487.09,"id":26314798}]}]}
{"op":"mcm","clk":"991812442","pt":1580508501607,"mc":[{"id":"1.168130661","rc":[{"batb":[[1,2.62,6],[2,2.6,76.81]],"ltp":2.74,"tv":487.09,"id":26314798}]}]}
{"op":"mcm","clk":"991814449","pt":1580508533449,"mc":[{"id":"1.168130661","rc":[{"batb":[[0,2.62,6],[1,2.6,76.81],[2,2.56,6]],"batl":[[0,2.9,31.35],[1,3.4,1],[2,3.5,1]],"ltp":2.74,"tv":487.09,"id":26314798}]}]}
{"op":"mcm","clk":"991814644","pt":1580508536694,"mc":[{"id":"1.168130661","rc":[{"batl":[[0,2.9,31.53]],"ltp":2.74,"tv":487.09,"id":26314798}]}]}
{"op":"mcm","clk":"991814921","pt":1580508540670,"mc":[{"id":"1.168130661","rc":[{"trd":[[2.88,4.72]],"batb":[[0,2.88,17.82],[1,2.62,6],[2,2.6,76.81]],"batl":[[0,2.9,31.35]],"ltp":2.88,"tv":487.45,"id":26314798}],"tv":933.56}]}
{"op":"mcm","clk":"991815127","pt":1580508543698,"mc":[{"id":"1.168130661","rc":[{"batb":[[1,2.6,76.81],[2,2.54,150]],"ltp":2.88,"tv":487.45,"id":26314798}]}]}
{"op":"mcm","clk":"991815447","pt":1580508548701,"mc":[{"id":"1.168130661","rc":[{"batb":[[0,2.88,60.34]],"ltp":2.88,"tv":487.45,"id":26314798}]}]}
{"op":"mcm","clk":"991817588","pt":1580508582368,"mc":[{"id":"1.168130661","rc":[{"trd":[[2.76,65.85]],"batb":[[0,2.76,2.12]],"ltp":2.76,"tv":305.06,"id":25238892}],"tv":937.56}]}
{"op":"mcm","clk":"991817704","pt":1580508584271,"mc":[{"id":"1.168130661","rc":[{"batb":[[1,2.74,8.05]],"ltp":2.76,"tv":305.06,"id":25238892}]}]}
{"op":"mcm","clk":"991818352","pt":1580508594676,"mc":[{"id":"1.168130661","rc":[{"batb":[[0,15.5,3],[1,15,1.62],[2,14.5,2.27]],"ltp":15.0,"tv":42.73,"id":24707172}]}]}
{"op":"mcm","clk":"991818395","pt":1580508595192,"mc":[{"id":"1.168130661","rc":[{"batb":[[0,2.88,42.52]],"ltp":2.88,"tv":487.45,"id":26314798}]}]}
{"op":"mcm","clk":"991819041","pt":1580508604703,"mc":[{"id":"1.168130661","rc":[{"trd":[[2.9,139.98]],"batl":[[0,2.9,13.35]],"ltp":2.9,"tv":523.45,"id":26314798}],"tv":973.56}]}
{"op":"mcm","clk":"991819215","pt":1580508607181,"mc":[{"id":"1.168130661","rc":[{"batl":[[1,18,3],[2,21,14.12]],"ltp":15.0,"tv":42.73,"id":24707172}]}]}
{"op":"mcm","clk":"991819507","pt":1580508610599,"mc":[{"id":"1.168130661","rc":[{"batb":[[1,14.5,2.56],[2,12.5,2]],"ltp":15.0,"tv":42.73,"id":24707172}]}]}
{"op":"mcm","clk":"991819556","pt":1580508611324,"mc":[{"id":"1.168130661","rc":[{"batl":[[0,17.5,2]],"ltp":15.0,"tv":42.73,"id":24707172}]}]}
{"op":"mcm","clk":"991822743","pt":1580508662369,"mc":[{"id":"1.168130661","rc":[{"trd":[[2.88,13.12]],"batb":[[0,2.88,38.32]],"ltp":2.88,"tv":531.85,"id":26314798}],"tv":981.96}]}
{"op":"mcm","clk":"991823139","pt":1580508668978,"mc":[{"id":"1.168130661","rc":[{"batb":[[0,2.88,42.52]],"ltp":2.88,"tv":531.85,"id":26314798}]}]}
{"op":"mcm","clk":"991823845","pt":1580508681689,"mc":[{"id":"1.168130661","rc":[{"trd":[[2.76,70.09]],"batb":[[0,2.74,8.05],[1,2.72,2.12],[2,2.68,2.7]],"batl":[[0,2.76,15.27],[1,2.84,16.8],[2,2.86,60]],"ltp":2.76,"tv":309.3,"id":25238892}],"tv":986.2}]}
{"op":"mcm","clk":"991824401","pt":1580508689706,"mc":[{"id":"1.168130661","rc":[{"batl":[[1,2.86,60],[2,2.88,4.49]],"ltp":2.76,"tv":309.3,"id":25238892}]}]}
{"op":"mcm","clk":"991824854","pt":1580508696586,"mc":[{"id":"1.168130661","rc":[{"batl":[[1,2.84,16.8],[2,2.86,60]],"ltp":2.76,"tv":309.3,"id":25238892}]}]}
{"op":"mcm","clk":"991824985","pt":1580508699012,"mc":[{"id":"1.168130661","rc":[{"batl":[[1,2.86,60],[2,2.88,4.49]],"ltp":2.76,"tv":309.3,"id":25238892}]}]}
{"op":"mcm","clk":"991825057","pt":1580508700250,"mc":[{"id":"1.168130661","rc":[{"batl":[[1,2.84,16.8],[2,2.86,60]],"ltp":2.76,"tv":309.3,"id":25238892}]}]}
{"op":"mcm","clk":"991825203","pt":1580508702320,"mc":[{"id":"1.168130661","rc":[{"batl":[[1,2.86,60],[2,2.88,4.49]],"ltp":2.76,"tv":309.3,"id":25238892}]}]}
{"op":"mcm","clk":"991825266","pt":1580508703245,"mc":[{"id":"1.168130661","rc":[{"batl":[[1,2.84,16.8],[2,2.86,60]],"ltp":2.76,"tv":309.3,"id":25238892}]}]}
{"op":"mcm","clk":"991825532","pt":1580508706670,"mc":[{"id":"1.168130661","rc":[{"batl":[[1,2.86,60],[2,2.88,4.49]],"ltp":2.76,"tv":309.3,"id":25238892}]}]}
{"op":"mcm","clk":"991825753","pt":1580508709211,"mc":[{"id":"1.168130661","rc":[{"batl":[[1,2.84,16.8],[2,2.86,60]],"ltp":2.76,"tv":309.3,"id":25238892}]}]}
{"op":"mcm","clk":"991825872","pt":1580508710616,"mc":[{"id":"1.168130661","rc":[{"batl":[[1,2.86,60],[2,2.88,4.49]],"ltp":2.76,"tv":309.3,"id":25238892}]}]}
{"op":"mcm","clk":"991826528","pt":1580508719664,"mc":[{"id":"1.168130661","rc":[{"batl":[[1,2.84,16.8],[2,2.86,60]],"ltp":2.76,"tv":309.3,"id":25238892}]}]}
{"op":"mcm","clk":"991826913","pt":1580508725046,"mc":[{"id":"1.168130661","rc":[{"batl":[[1,2.86,60],[2,2.88,4.49]],"ltp":2.76,"tv":309.3,"id":25238892}]}]}
{"op":"mcm","clk":"991826975","pt":1580508726228,"mc":[{"id":"1.168130661","rc":[{"batl":[[1,2.84,16.8],[2,2.86,60]],"ltp":2.76,"tv":309.3,"id":25238892}]}]}
{"op":"mcm","clk":"991827072","pt":1580508727675,"mc":[{"id":"1.168130661","rc":[{"batl":[[1,2.86,60],[2,2.88,4.49]],"ltp":2.76,"tv":309.3,"id":25238892}]}]}
{"op":"mcm","clk":"991827212","pt":1580508729642,"mc":[{"id":"1.168130661","rc":[{"batl":[[1,2.84,16.8],[2,2.86,60]],"ltp":2.76,"tv":309.3,"id":25238892}]}]}
{"op":"mcm","clk":"991827319","pt":1580508731554,"mc":[{"id":"1.168130661","rc":[{"batl":[[1,2.86,60],[2,2.88,4.49]],"ltp":2.76,"tv":309.3,"id":25238892}]}]}
{"op":"mcm","clk":"991837754","pt":1580508922034,"mc":[{"id":"1.168130661","rc":[{"batl":[[0,16.5,3],[1,17.5,2]],"ltp":15.0,"tv":42.73,"id":24707172}]}]}
{"op":"mcm","clk":"991838171","pt":1580508930881,"mc":[{"id":"1.168130661","rc":[{"batl":[[1,21,14.12],[2,60,9]],"ltp":15.0,"tv":42.73,"id":24707172}]}]}
{"op":"mcm","clk":"991839024","pt":1580508948250,"mc":[{"id":"1.168130661","rc":[{"batb":[[2,25,5.13]],"ltp":0.0,"tv":0.0,"id":25545675},{"batb":[[0,8.4,3],[1,7.2,11],[2,5.7,1.64]],"ltp":9.8,"tv":65.72,"id":24420205},{"batb":[[0,2.6,76.81],[1,2.54,150],[2,2.52,25]],"ltp":2.88,"tv":531.85,"id":26314798}]}]}
{"op":"mcm","clk":"991839095","pt":1580508949682,"mc":[{"id":"1.168130661","rc":[{"batb":[[0,15.5,3.29],[1,14.5,2.27]],"ltp":15.0,"tv":42.73,"id":24707172},{"batb":[[0,8.6,1.98],[1,8.4,3],[2,7.2,11]],"ltp":9.8,"tv":65.72,"id":24420205},{"batb":[[0,10,4.16],[1,9.8,61.76]],"ltp":7.4,"tv":36.58,"id":420}]}]}
{"op":"mcm","clk":"991839157","pt":1580508950716,"mc":[{"id":"1.168130661","rc":[{"batb":[[2,25,5.32]],"ltp":0.0,"tv":0.0,"id":25545675}]}]}
{"op":"mcm","clk":"991839225","pt":1580508951610,"mc":[{"id":"1.168130661","rc":[{"batl":[[0,2.9,13.54]],"ltp":2.88,"tv":531.85,"id":26314798}]}]}
{"op":"mcm","clk":"991839535","pt":1580508957596,"mc":[{"id":"1.168130661","rc":[{"batb":[[1,2.56,6],[2,2.54,150]],"ltp":2.88,"tv":531.85,"id":26314798}]}]}
{"op":"mcm","clk":"991840819","pt":1580508983541,"mc":[{"id":"1.168130661","rc":[{"batb":[[0,8.8,2.06],[1,8.6,1.98],[2,8.4,3]],"batl":[[1,12,1.68],[2,12.5,10]],"ltp":9.8,"tv":65.72,"id":24420205}]}]}
{"op":"mcm","clk":"991840933","pt":1580508985615,"mc":[{"id":"1.168130661","rc":[{"batl":[[0,9.8,2],[1,10,4.81],[2,12,1.68]],"ltp":9.8,"tv":65.72,"id":24420205},{"batb":[[0,2.62,2.08],[1,2.6,76.81],[2,2.56,6]],"ltp":2.88,"tv":531.85,"id":26314798}]}]}
{"op":"mcm","clk":"991841251","pt":1580508991609,"mc":[{"id":"1.168130661","rc":[{"batb":[[0,9,1.98],[1,8.8,2.06]],"ltp":9.8,"tv":65.72,"id":24420205},{"batb":[[0,2.64,1.81],[1,2.62,2.08],[2,2.6,75]],"ltp":2.88,"tv":531.85,"id":26314798}]}]}
{"op":"mcm","clk":"991841714","pt":1580508998429,"mc":[{"id":"1.168130661","rc":[{"batb":[[2,13,5.54]],"ltp":0.0,"tv":0.0,"id":25545675}]}]}
{"op":"mcm","clk":"991842681","pt":1580509016721,"mc":[{"id":"1.168130661","rc":[{"trd":[[9.8,19.34],[10,42.01]],"batb":[[0,10,43.19],[1,9,1.98],[2,8.8,2.06]],"batl":[[0,12,1.68],[1,12.5,10],[2,14,2.52]],"ltp":10.0,"tv":79.34,"id":24420205}],"tv":999.81}]}
{"op":"mcm","clk":"991842689","pt":1580509016927,"mc":[{"id":"1.168130661","rc":[{"batl":[[2,13.5,2.31]],"ltp":10.0,"tv":79.34,"id":24420205}]}]}
{"op":"mcm","clk":"991843447","pt":1580509030636,"mc":[{"id":"1.168130661","rc":[{"batb":[[0,9,1.98],[1,8.8,2.06],[2,8.4,3]],"batl":[[2,14,2.52]],"ltp":10.0,"tv":79.34,"id":24420205}]}]}
{"op":"mcm","clk":"991843918","pt":1580509039519,"mc":[{"id":"1.168130661","rc":[{"batb":[[0,9,4.16]],"ltp":10.0,"tv":79.34,"id":24420205}]}]}
{"op":"mcm","clk":"991844132","pt":1580509043578,"mc":[{"id":"1.168130661","rc":[{"batl":[[0,2.76,20.27]],"ltp":2.76,"tv":309.3,"id":25238892}]}]}
{"op":"mcm","clk":"991844609","pt":1580509052474,"mc":[{"id":"1.168130661","rc":[{"batb":[[0,2.74,13.05]],"ltp":2.76,"tv":309.3,"id":25238892}]}]}
{"op":"mcm","clk":"991844906","pt":1580509058566,"mc":[{"id":"1.168130661","rc":[{"trd":[[8.4,3.28],[8.8,8.08],[9,8.32]],"batb":[[0,8.4,1.56],[1,7.2,11],[2,5.7,1.64]],"ltp":8.4,"tv":94.66,"id":24420205}],"tv":1015.14}]}
{"op":"mcm","clk":"991844959","pt":1580509059558,"mc":[{"id":"1.168130661","rc":[{"batb":[[0,7.4,1.56]],"ltp":8.4,"tv":94.66,"id":24420205}]}]}
{"op":"mcm","clk":"991845003","pt":1580509060475,"mc":[{"id":"1.168130661","rc":[{"batb":[[0,30,5.03]],"ltp":0.0,"tv":0.0,"id":25545675},{"batb":[[1,2.62,26.25]],"ltp":2.88,"tv":531.85,"id":26314798}]}]}
{"op":"mcm","clk":"991845095","pt":1580509062682,"mc":[{"id":"1.168130661","rc":[{"batb":[[0,7.4,2.34]],"ltp":8.4,"tv":94.66,"id":24420205}]}]}
{"op":"mcm","clk":"991845569","pt":1580509074692,"mc":[{"id":"1.168130661","rc":[{"batb":[[0,7.6,3.34],[1,7.4,2.34],[2,7.2,11]],"batl":[[0,12,3.47]],"ltp":8.4,"tv":94.66,"id":24420205}]}]}
{"op":"mcm","clk":"991845659","pt":1580509076291,"mc":[{"id":"1.168130661","rc":[{"batb":[[0,7.8,1.98],[1,7.6,3.34],[2,7.4,2.34]],"ltp":8.4,"tv":94.66,"id":24420205}]}]}
{"op":"mcm","clk":"991845977","pt":1580509082722,"mc":[{"id":"1.168130661","rc":[{"batb":[[0,10.5,1.64],[1,10,4.16],[2,9.8,60]],"ltp":7.4,"tv":36.58,"id":420}]}]}
{"op":"mcm","clk":"991846181","pt":1580509088317,"mc":[{"id":"1.168130661","rc":[{"batb":[[0,7.8,10.1]],"ltp":8.4,"tv":94.66,"id":24420205}]}]}
{"op":"mcm","clk":"991846344","pt":1580509091810,"mc":[{"id":"1.168130661","rc":[{"batl":[[0,11.5,3.23],[1,12,3.47],[2,12.5,10]],"ltp":8.4,"tv":94.66,"id":24420205}]}]}
{"op":"mcm","clk":"991848907","pt":1580509147009,"mc":[{"id":"1.168130661","rc":[{"batl":[[0,11,2],[1,11.5,3.23],[2,12,3.47]],"ltp":8.4,"tv":94.66,"id":24420205}]}]}
{"op":"mcm","clk":"991849146","pt":1580509152168,"mc":[{"id":"1.168130661","rc":[{"batb":[[0,8,3.17],[1,7.8,10.1]],"batl":[[0,10.5,1.68],[1,11,2],[2,11.5,3.23]],"ltp":8.4,"tv":94.66,"id":24420205}]}]}
{"op":"mcm","clk":"991849317","pt":1580509156598,"mc":[{"id":"1.168130661","rc":[{"batb":[[0,16,3],[1,14.5,2.56]],"ltp":15.0,"tv":42.73,"id":24707172},{"batb":[[0,8,11.08],[1,7.8,1.98]],"ltp":8.4,"tv":94.66,"id":24420205}]}]}
{"op":"mcm","clk":"991849396","pt":1580509157686,"mc":[{"id":"1.168130661","rc":[{"trd":[[16.5,6]],"batb":[[0,14.5,2.56],[1,12.5,2],[2,9,9.54]],"batl":[[0,21,14.12],[1,60,9],[2,480,4]],"ltp":16.5,"tv":48.73,"id":24707172}],"tv":1021.14}]}
{"op":"mcm","clk":"991849499","pt":1580509159386,"mc":[{"id":"1.168130661","rc":[{"batl":[[0,21,14.31]],"ltp":16.5,"tv":48.73,"id":24707172}]}]}
{"op":"mcm","clk":"991849657","pt":1580509162377,"mc":[{"id":"1.168130661","rc":[{"batb":[[0,8.2,1.98],[1,8,11.08]],"ltp":8.4,"tv":94.66,"id":24420205}]}]}
{"op":"mcm","clk":"991850045","pt":1580509170717,"mc":[{"id":"1.168130661","rc":[{"batl":[[2,12.5,10]],"ltp":8.4,"tv":94.66,"id":24420205}]}]}
{"op":"mcm","clk":"991850424","pt":1580509177510,"mc":[{"id":"1.168130661","rc":[{"batb":[[0,8.2,9.7],[1,8,3.17]],"ltp":8.4,"tv":94.66,"id":24420205}]}]}
{"op":"mcm","clk":"991850616","pt":1580509181818,"mc":[{"id":"1.168130661","rc":[{"trd":[[2.62,8.38],[2.64,8.26]],"batb":[[0,2.62,26.06],[1,2.6,75],[2,2.56,6]],"ltp":2.62,"tv":535.85,"id":26314798}],"tv":1025.13}]}
{"op":"mcm","clk":"991851473","pt":1580509200833,"mc":[{"id":"1.168130661","rc":[{"batl":[[0,20,2.19],[1,21,14.12],[2,60,9]],"ltp":16.5,"tv":48.73,"id":24707172},{"batl":[[0,10,2],[1,10.5,1.68]],"ltp":8.4,"tv":94.66,"id":24420205}]}]}
{"op":"mcm","clk":"991851755","pt":1580509206640,"mc":[{"id":"1.168130661","rc":[{"batb":[[0,2.64,3],[1,2.62,26.06],[2,2.6,75]],"ltp":2.62,"tv":535.85,"id":26314798}]}]}
{"op":"mcm","clk":"991851958","pt":1580509210650,"mc":[{"id":"1.168130661","rc":[{"batb":[[2,9.2,2.6]],"batl":[[2,44,1.68]],"ltp":16.5,"tv":48.73,"id":24707172},{"batb":[[0,8.4,3.02],[1,8.2,9.7]],"ltp":8.4,"tv":94.66,"id":24420205}]}]}
{"op":"mcm","clk":"991852232","pt":1580509216439,"mc":[{"id":"1.168130661","rc":[{"trd":[[10,0.72],[10.5,3.28]],"batb":[[0,10,3.8],[1,9.8,60],[2,7.4,5]],"ltp":10.0,"tv":40.58,"id":420}],"tv":1029.13}]}
{"op":"mcm","clk":"991852450","pt":1580509221033,"mc":[{"id":"1.168130661","rc":[{"batb":[[2,8.4,3]],"ltp":10.0,"tv":40.58,"id":420}]}]}
{"op":"mcm","clk":"991852620","pt":1580509224538,"mc":[{"id":"1.168130661","rc":[{"batb":[[0,8.4,10.55],[1,8.2,1.98]],"ltp":8.4,"tv":94.66,"id":24420205}]}]}
{"op":"mcm","clk":"991852668","pt":1580509225562,"mc":[{"id":"1.168130661","rc":[{"batb":[[2,7.4,1.56]],"ltp":8.4,"tv":94.66,"id":24420205}]}]}
{"op":"mcm","clk":"991853179","pt":1580509237703,"mc":[{"id":"1.168130661","rc":[{"batb":[[1,9.8,62]],"ltp":10.0,"tv":40.58,"id":420}]}]}
{"op":"mcm","clk":"991853368","pt":1580509241246,"mc":[{"id":"1.168130661","rc":[{"batb":[[1,26,2.83],[2,13,4.71]],"ltp":0.0,"tv":0.0,"id":25545675}]}]}
{"op":"mcm","clk":"991854737","pt":1580509269267,"mc":[{"id":"1.168130661","rc":[{"batl":[[0,19.5,1.87],[1,20,2],[2,21,14.12]],"ltp":16.5,"tv":48.73,"id":24707172}]}]}
{"op":"mcm","clk":"991855765","pt":1580509290957,"mc":[{"id":"1.168130661","rc":[{"trd":[[2.88,13.5],[2.9,143.24]],"batl":[[0,2.9,11.72]],"ltp":2.9,"tv":539.49,"id":26314798}],"tv":1032.77}]}
{"op":"mcm","clk":"991855848","pt":1580509292450,"mc":[{"id":"1.168130661","rc":[{"batb":[[0,32,1.47],[1,30,4.1],[2,26,2.19]],"ltp":0.0,"tv":0.0,"id":25545675}]}]}
{"op":"mcm","clk":"991855939","pt":1580509293938,"mc":[{"id":"1.168130661","rc":[{"batl":[[0,2.9,11.9]],"ltp":2.9,"tv":539.49,"id":26314798}]}]}
{"op":"mcm","clk":"991856056","pt":1580509296464,"mc":[{"id":"1.168130661","rc":[{"batb":[[1,30,1.98]],"ltp":0.0,"tv":0.0,"id":25545675}]}]}
{"op":"mcm","clk":"991856616","pt":1580509307585,"mc":[{"id":"1.168130661","rc":[{"batl":[[0,19,2],[1,19.5,1.87]],"ltp":16.5,"tv":48.73,"id":24707172},{"batl":[[0,2.88,2.18],[1,2.9,11.72],[2,3.4,1]],"ltp":2.9,"tv":539.49,"id":26314798}]}]}
{"op":"mcm","clk":"991858200","pt":1580509340616,"mc":[{"id":"1.168130661","rc":[{"batb":[[0,2.64,9.53]],"ltp":2.9,"tv":539.49,"id":26314798}]}]}
{"op":"mcm","clk":"991858220","pt":1580509341085,"mc":[{"id":"1.168130661","rc":[{"batb":[[0,8.6,2],[1,8.4,10.55],[2,8.2,1.98]],"ltp":8.4,"tv":94.66,"id":24420205}]}]}
{"op":"mcm","clk":"991858529","pt":1580509347492,"mc":[{"id":"1.168130661","rc":[{"batb":[[1,27,1.98]],"ltp":0.0,"tv":0.0,"id":25545675},{"batb":[[0,8.8,1.98],[1,8.6,2],[2,8.4,10.55]],"ltp":8.4,"tv":94.66,"id":24420205},{"batb":[[0,2.66,1.98],[1,2.64,9.53],[2,2.62,26.06]],"ltp":2.9,"tv":539.49,"id":26314798}]}]}
{"op":"mcm","clk":"991868430","pt":1580509353441,"mc":[{"id":"1.168130661","rc":[{"batb":[[1,8.6,9.36],[2,8.4,3.02]],"ltp":8.4,"tv":94.66,"id":24420205},{"batb":[[0,2.66,25.78],[2,2.62,1.89]],"batl":[[0,2.86,10.72],[1,2.88,2],[2,2.9,11.72]],"ltp":2.9,"tv":539.49,"id":26314798}]}]}
{"op":"mcm","clk":"991868550","pt":1580509355702,"mc":[{"id":"1.168130661","rc":[{"batl":[[0,18.5,1.68],[1,19,2],[2,21,14.31]],"ltp":16.5,"tv":48.73,"id":24707172},{"batb":[[0,9,2.81],[1,8.8,1.98],[2,8.6,9.36]],"ltp":8.4,"tv":94.66,"id":24420205}]}]}
{"op":"mcm","clk":"991868697","pt":1580509358938,"mc":[{"id":"1.168130661","rc":[{"batb":[[1,2.64,6.53]],"ltp":2.9,"tv":539.49,"id":26314798}]}]}
{"op":"mcm","clk":"991868790","pt":1580509360945,"mc":[{"id":"1.168130661","rc":[{"batl":[[0,18,2],[1,18.5,1.68]],"ltp":16.5,"tv":48.73,"id":24707172},{"batl":[[0,2.84,2.18],[1,2.86,10.54]],"ltp":2.9,"tv":539.49,"id":26314798}]}]}
{"op":"mcm","clk":"991868892","pt":1580509363216,"mc":[{"id":"1.168130661","rc":[{"batl":[[2,21,14.12]],"ltp":16.5,"tv":48.73,"id":24707172}]}]}
{"op":"mcm","clk":"991869104","pt":1580509368716,"mc":[{"id":"1.168130661","rc":[{"batb":[[2,8.6,2]],"ltp":8.4,"tv":94.66,"id":24420205},{"batb":[[0,2.66,1.98],[1,2.64,30.51]],"ltp":2.9,"tv":539.49,"id":26314798}]}]}
{"op":"mcm","clk":"991869660","pt":1580509382461,"mc":[{"id":"1.168130661","rc":[{"batb":[[1,2.64,6.53],[2,2.62,26.06]],"ltp":2.9,"tv":539.49,"id":26314798}]}]}
{"op":"mcm","clk":"991870407","pt":1580509396662,"mc":[{"id":"1.168130661","rc":[{"batl":[[0,17.5,1.68],[1,18,2]],"ltp":16.5,"tv":48.73,"id":24707172},{"batb":[[1,2.64,30.51],[2,2.62,1.89]],"ltp":2.9,"tv":539.49,"id":26314798}]}]}
{"op":"mcm","clk":"991871030","pt":1580509408057,"mc":[{"id":"1.168130661","rc":[{"batl":[[0,2.84,12.18]],"ltp":2.9,"tv":539.49,"id":26314798}]}]}
{"op":"mcm","clk":"991871218","pt":1580509412169,"mc":[{"id":"1.168130661","rc":[{"batb":[[1,2.64,6.53],[2,2.62,26.06]],"ltp":2.9,"tv":539.49,"id":26314798}]}]}
{"op":"mcm","clk":"991871310","pt":1580509414685,"mc":[{"id":"1.168130661","rc":[{"batl":[[0,17,2],[1,17.5,1.68]],"ltp":16.5,"tv":48.73,"id":24707172}]}]}
{"op":"mcm","clk":"991871671","pt":1580509422493,"mc":[{"id":"1.168130661","rc":[{"batl":[[0,2.76,31.54]],"ltp":2.76,"tv":309.3,"id":25238892}]}]}
{"op":"mcm","clk":"991871926","pt":1580509427483,"mc":[{"id":"1.168130661","rc":[{"batb":[[1,2.64,30.51],[2,2.62,1.89]],"ltp":2.9,"tv":539.49,"id":26314798}]}]}
{"op":"mcm","clk":"991872122","pt":1580509431708,"mc":[{"id":"1.168130661","rc":[{"trd":[[2.74,65.6]],"batb":[[0,2.72,2.12],[1,2.68,2.7],[2,2.62,1]],"batl":[[0,2.74,6.95],[1,2.76,31.54],[2,2.86,60]],"ltp":2.74,"tv":335.4,"id":25238892}],"tv":1058.87}]}
{"op":"mcm","clk":"991872399","pt":1580509436612,"mc":[{"id":"1.168130661","rc":[{"batl":[[1,21,14.12],[2,60,9]],"ltp":16.5,"tv":48.73,"id":24707172}]}]}
{"op":"mcm","clk":"991872405","pt":1580509436812,"mc":[{"id":"1.168130661","rc":[{"batl":[[0,16.5,1.68],[1,17,2],[2,21,14.12]],"ltp":16.5,"tv":48.73,"id":24707172}]}]}
{"op":"mcm","clk":"991872627","pt":1580509441507,"mc":[{"id":"1.168130661","rc":[{"batb":[[1,2.64,6.53],[2,2.62,26.06]],"ltp":2.9,"tv":539.49,"id":26314798}]}]}
{"op":"mcm","clk":"991873305","pt":1580509455501,"mc":[{"id":"1.168130661","rc":[{"batb":[[1,2.64,30.51],[2,2.62,1.89]],"ltp":2.9,"tv":539.49,"id":26314798}]}]}
{"op":"mcm","clk":"991873946","pt":1580509468065,"mc":[{"id":"1.168130661","rc":[{"batl":[[1,21,14.12],[2,60,9]],"ltp":16.5,"tv":48.73,"id":24707172}]}]}
{"op":"mcm","clk":"991874110","pt":1580509470642,"mc":[{"id":"1.168130661","rc":[{"batb":[[1,2.64,6.53],[2,2.62,26.06]],"ltp":2.9,"tv":539.49,"id":26314798}]}]}
{"op":"mcm","clk":"991874824","pt":1580509484434,"mc":[{"id":"1.168130661","rc":[{"batb":[[1,2.64,30.51],[2,2.62,1.89]],"ltp":2.9,"tv":539.49,"id":26314798}]}]}
{"op":"mcm","clk":"991875191","pt":1580509491037,"mc":[{"id":"1.168130661","rc":[{"batl":[[0,20,1.68]],"ltp":16.5,"tv":48.73,"id":24707172}]}]}
{"op":"mcm","clk":"991875337","pt":1580509493564,"mc":[{"id":"1.168130661","rc":[{"batl":[[0,20,1.86]],"ltp":16.5,"tv":48.73,"id":24707172}]}]}
{"op":"mcm","clk":"991875578","pt":1580509498466,"mc":[{"id":"1.168130661","rc":[{"batb":[[1,2.64,6.53],[2,2.62,26.06]],"ltp":2.9,"tv":539.49,"id":26314798}]}]}
{"op":"mcm","clk":"991876439","pt":1580509513546,"mc":[{"id":"1.168130661","rc":[{"batb":[[1,2.64,30.51],[2,2.62,1.89]],"ltp":2.9,"tv":539.49,"id":26314798}]}]}
{"op":"mcm","clk":"991876653","pt":1580509517368,"mc":[{"id":"1.168130661","rc":[{"trd":[[2.72,4.99]],"batb":[[0,2.68,2.7],[1,2.62,1],[2,2.6,20]],"batl":[[0,2.72,4.83]],"ltp":2.72,"tv":339.63,"id":25238892}],"tv":1063.11}]}
{"op":"mcm","clk":"991876790","pt":1580509519687,"mc":[{"id":"1.168130661","rc":[{"trd":[[2.72,8.09]],"batl":[[0,2.72,3.28]],"ltp":2.72,"tv":342.73,"id":25238892}],"tv":1066.21}]}
{"op":"mcm","clk":"991876918","pt":1580509521504,"mc":[{"id":"1.168130661","rc":[{"trd":[[2.72,11.19]],"batl":[[0,2.72,1.73]],"ltp":2.72,"tv":345.83,"id":25238892}],"tv":1069.31}]}
{"op":"mcm","clk":"991877220","pt":1580509527500,"mc":[{"id":"1.168130661","rc":[{"batb":[[1,2.64,6.53],[2,2.62,26.06]],"ltp":2.9,"tv":539.49,"id":26314798}]}]}
{"op":"mcm","clk":"991877865","pt":1580509540219,"mc":[{"id":"1.168130661","rc":[{"trd":[[2.72,12.55]],"batl":[[0,2.72,1.05]],"ltp":2.72,"tv":347.19,"id":25238892}],"tv":1070.67}]}
{"op":"mcm","clk":"991877920","pt":1580509541506,"mc":[{"id":"1.168130661","rc":[{"batb":[[1,2.64,30.51],[2,2.62,1.89]],"ltp":2.9,"tv":539.49,"id":26314798}]}]}
{"op":"mcm","clk":"991878684","pt":1580509556408,"mc":[{"id":"1.168130661","rc":[{"batb":[[1,2.64,6.53],[2,2.62,26.06]],"ltp":2.9,"tv":539.49,"id":26314798}]}]}
{"op":"mcm","clk":"991879298","pt":1580509570542,"mc":[{"id":"1.168130661","rc":[{"batb":[[1,2.64,30.51],[2,2.62,1.89]],"ltp":2.9,"tv":539.49,"id":26314798}]}]}
{"op":"mcm","clk":"991879449","pt":1580509574441,"mc":[{"id":"1.168130661","rc":[{"batl":[[0,19.5,2.18],[1,20,1.68],[2,21,14.12]],"ltp":16.5,"tv":48.73,"id":24707172}]}]}
{"op":"mcm","clk":"991879728","pt":1580509582542,"mc":[{"id":"1.168130661","rc":[{"batb":[[0,2.68,7.34]],"ltp":2.72,"tv":347.19,"id":25238892}]}]}
{"op":"mcm","clk":"991879769","pt":1580509583465,"mc":[{"id":"1.168130661","rc":[{"batb":[[0,9.2,1.98],[1,9,2.81]],"ltp":8.4,"tv":94.66,"id":24420205}]}]}
{"op":"mcm","clk":"991879812","pt":1580509584450,"mc":[{"id":"1.168130661","rc":[{"batb":[[1,2.64,6.53],[2,2.62,26.06]],"ltp":2.9,"tv":539.49,"id":26314798}]}]}
{"op":"mcm","clk":"991880261","pt":1580509594283,"mc":[{"id":"1.168130661","rc":[{"batl":[[0,19,1.68],[1,19.5,2.18]],"ltp":16.5,"tv":48.73,"id":24707172}]}]}
{"op":"mcm","clk":"991880465","pt":1580509599573,"mc":[{"id":"1.168130661","rc":[{"batb":[[1,2.64,30.51],[2,2.62,1.89]],"ltp":2.9,"tv":539.49,"id":26314798}]}]}
{"op":"mcm","clk":"991881023","pt":1580509613386,"mc":[{"id":"1.168130661","rc":[{"batb":[[1,2.64,6.53],[2,2.62,26.06]],"ltp":2.9,"tv":539.49,"id":26314798}]}]}
{"op":"mcm","clk":"991881621","pt":1580509627532,"mc":[{"id":"1.168130661","rc":[{"batb":[[1,2.64,30.51],[2,2.62,1.89]],"ltp":2.9,"tv":539.49,"id":26314798}]}]}
{"op":"mcm","clk":"991881671","pt":1580509628620,"mc":[{"id":"1.168130661","rc":[{"batl":[[0,18.5,2],[1,19,1.68],[2,21,14.3]],"ltp":16.5,"tv":48.73,"id":24707172}]}]}
{"op":"mcm","clk":"991882259","pt":1580509642627,"mc":[{"id":"1.168130661","rc":[{"batb":[[1,2.64,6.53],[2,2.62,26.06]],"ltp":2.9,"tv":539.49,"id":26314798}]}]}
{"op":"mcm","clk":"991882706","pt":1580509653148,"mc":[{"id":"1.168130661","rc":[{"batb":[[0,2.7,6.38],[1,2.68,7.34],[2,2.62,1]],"ltp":2.72,"tv":347.19,"id":25238892}]}]}
{"op":"mcm","clk":"991882855","pt":1580509656451,"mc":[{"id":"1.168130661","rc":[{"batb":[[1,2.64,30.51],[2,2.62,1.89]],"ltp":2.9,"tv":539.49,"id":26314798}]}]}
{"op":"mcm","clk":"991883049","pt":1580509661052,"mc":[{"id":"1.168130661","rc":[{"batl":[[0,18,1.68],[1,18.5,2]],"ltp":16.5,"tv":48.73,"id":24707172}]}]}
{"op":"mcm","clk":"991883128","pt":1580509662963,"mc":[{"id":"1.168130661","rc":[{"batl":[[2,21,14.12]],"ltp":16.5,"tv":48.73,"id":24707172}]}]}
{"op":"mcm","clk":"991883467","pt":1580509670596,"mc":[{"id":"1.168130661","rc":[{"batb":[[1,2.64,6.53],[2,2.62,26.06]],"ltp":2.9,"tv":539.49,"id":26314798}]}]}
{"op":"mcm","clk":"991883908","pt":1580509682105,"mc":[{"id":"1.168130661","rc":[{"batl":[[0,17.5,2],[1,18,1.68]],"ltp":16.5,"tv":48.73,"id":24707172}]}]}
{"op":"mcm","clk":"991884046","pt":1580509685499,"mc":[{"id":"1.168130661","rc":[{"batb":[[1,2.64,30.51],[2,2.62,1.89]],"ltp":2.9,"tv":539.49,"id":26314798}]}]}
{"op":"mcm","clk":"991884524","pt":1580509695099,"mc":[{"id":"1.168130661","rc":[{"batl":[[0,17,1.68],[1,17.5,2]],"ltp":16.5,"tv":48.73,"id":24707172}]}]}
{"op":"mcm","clk":"991884725","pt":1580509699534,"mc":[{"id":"1.168130661","rc":[{"batb":[[1,2.64,6.53],[2,2.62,26.06]],"ltp":2.9,"tv":539.49,"id":26314798}]}]}
{"op":"mcm","clk":"991885354","pt":1580509713446,"mc":[{"id":"1.168130661","rc":[{"batb":[[1,2.64,30.51],[2,2.62,1.89]],"ltp":2.9,"tv":539.49,"id":26314798}]}]}
{"op":"mcm","clk":"991886085","pt":1580509728580,"mc":[{"id":"1.168130661","rc":[{"batb":[[1,2.64,6.53],[2,2.62,26.06]],"ltp":2.9,"tv":539.49,"id":26314798}]}]}
{"op":"mcm","clk":"991886451","pt":1580509735644,"mc":[{"id":"1.168130661","rc":[{"batl":[[0,16.5,2],[1,17,1.68]],"ltp":16.5,"tv":48.73,"id":24707172}]}]}
{"op":"mcm","clk":"991886596","pt":1580509738264,"mc":[{"id":"1.168130661","rc":[{"trd":[[2.64,8.29],[2.66,3.96]],"batb":[[0,2.64,6.51],[1,2.62,26.06],[2,2.6,75]],"ltp":2.64,"tv":543.49,"id":26314798}],"tv":1074.67}]}
{"op":"mcm","clk":"991887511","pt":1580509755593,"mc":[{"id":"1.168130661","rc":[{"batb":[[0,2.66,3],[1,2.64,6.51],[2,2.62,26.06]],"ltp":2.64,"tv":543.49,"id":26314798}]}]}
{"op":"mcm","clk":"991887649","pt":1580509758415,"mc":[{"id":"1.168130661","rc":[{"batb":[[1,2.64,30.49],[2,2.62,1.89]],"ltp":2.64,"tv":543.49,"id":26314798}]}]}
{"op":"mcm","clk":"991891883","pt":1580509849720,"mc":[{"id":"1.168130661","rc":[{"trd":[[2.7,16.76]],"batb":[[0,2.68,7.34],[1,2.62,1],[2,2.6,20]],"batl":[[0,2.7,75.4],[1,2.72,1.05],[2,2.76,31.54]],"ltp":2.7,"tv":359.95,"id":25238892}],"tv":1087.43}]}
{"op":"mcm","clk":"991892013","pt":1580509853221,"mc":[{"id":"1.168130661","rc":[{"trd":[[2.7,17.74]],"batl":[[0,2.7,74.91]],"ltp":2.7,"tv":360.93,"id":25238892}],"tv":1088.41}]}
{"op":"mcm","clk":"991892086","pt":1580509855123,"mc":[{"id":"1.168130661","rc":[{"trd":[[2.7,18.72]],"batl":[[0,2.7,74.42]],"ltp":2.7,"tv":361.91,"id":25238892}],"tv":1089.39}]}
{"op":"mcm","clk":"991892294","pt":1580509860573,"mc":[{"id":"1.168130661","rc":[{"trd":[[2.68,14.68]],"batb":[[0,2.62,1],[1,2.6,20],[2,2.42,20.45]],"batl":[[0,2.68,67.08]],"ltp":2.68,"tv":376.59,"id":25238892}],"tv":1104.07}]}
{"op":"mcm","clk":"991892362","pt":1580509862441,"mc":[{"id":"1.168130661","rc":[{"trd":[[2.68,15.12]],"batl":[[0,2.68,66.86]],"ltp":2.68,"tv":377.03,"id":25238892}],"tv":1104.51}]}
{"op":"mcm","clk":"991892440","pt":1580509864655,"mc":[{"id":"1.168130661","rc":[{"trd":[[2.68,15.56]],"batb":[[0,2.6,21.68],[1,2.5,1]],"batl":[[0,2.68,66.64]],"ltp":2.68,"tv":377.47,"id":25238892},{"batb":[[0,2.66,8.35]],"ltp":2.64,"tv":543.49,"id":26314798}],"tv":1104.95}]}
{"op":"mcm","clk":"991892470","pt":1580509865633,"mc":[{"id":"1.168130661","rc":[{"batb":[[0,2.62,8.29],[1,2.6,21.68],[2,2.5,1]],"ltp":2.68,"tv":377.47,"id":25238892},{"batb":[[0,2.68,8.11],[1,2.66,8.35],[2,2.64,30.49]],"ltp":2.64,"tv":543.49,"id":26314798}]}]}
{"op":"mcm","clk":"991892511","pt":1580509866667,"mc":[{"id":"1.168130661","rc":[{"batb":[[1,28,1.04],[2,27,1.98]],"ltp":0.0,"tv":0.0,"id":25545675},{"trd":[[2.68,15.76]],"batl":[[0,2.68,66.54]],"ltp":2.68,"tv":377.67,"id":25238892},{"batb":[[0,15,2.24],[1,14.5,2.27],[2,12.5,2]],"ltp":16.5,"tv":48.73,"id":24707172},{"batb":[[0,9.4,1.83],[1,9.2,4.97],[2,9,2.81]],"ltp":8.4,"tv":94.66,"id":24420205},{"batb":[[1,2.66,5.35]],"ltp":2.64,"tv":543.49,"id":26314798},{"batb":[[0,10,6.14]],"ltp":10.0,"tv":40.58,"id":420}],"tv":1105.15}]}
{"op":"mcm","clk":"991892593","pt":1580509868374,"mc":[{"id":"1.168130661","rc":[{"trd":[[2.68,15.96]],"batl":[[0,2.68,66.44]],"ltp":2.68,"tv":377.87,"id":25238892}],"tv":1105.35}]}
{"op":"mcm","clk":"991892726","pt":1580509871672,"mc":[{"id":"1.168130661","rc":[{"batl":[[0,2.72,1.05],[1,2.76,31.54],[2,2.84,6]],"ltp":2.68,"tv":377.87,"id":25238892}]}]}
{"op":"mcm","clk":"991892810","pt":1580509873473,"mc":[{"id":"1.168130661","rc":[{"trd":[[2.72,12.75]],"batl":[[0,2.76,32.49],[1,2.84,6],[2,2.86,60]],"ltp":2.72,"tv":378.07,"id":25238892}],"tv":1105.55}]}
{"op":"mcm","clk":"991892856","pt":1580509874551,"mc":[{"id":"1.168130661","rc":[{"batb":[[0,2.64,5.58],[1,2.62,32.46],[2,2.6,21.68]],"ltp":2.72,"tv":378.07,"id":25238892},{"batb":[[0,9.4,8.57]],"ltp":8.4,"tv":94.66,"id":24420205},{"batb":[[0,2.68,31.73],[2,2.64,6.51]],"ltp":2.64,"tv":543.49,"id":26314798}]}]}
{"op":"mcm","clk":"991893051","pt":1580509879179,"mc":[{"id":"1.168130661","rc":[{"batb":[[1,2.62,33.46]],"ltp":2.72,"tv":378.07,"id":25238892}]}]}
{"op":"mcm","clk":"991893489","pt":1580509888644,"mc":[{"id":"1.168130661","rc":[{"batb":[[0,2.64,29.56],[1,2.62,9.29]],"ltp":2.72,"tv":378.07,"id":25238892}]}]}
{"op":"mcm","clk":"991893633","pt":1580509891679,"mc":[{"id":"1.168130661","rc":[{"batb":[[2,7.4,1.56]],"ltp":8.4,"tv":94.66,"id":24420205}]}]}
{"op":"mcm","clk":"991893681","pt":1580509892614,"mc":[{"id":"1.168130661","rc":[{"batl":[[1,21,14.12],[2,60,9]],"ltp":16.5,"tv":48.73,"id":24707172},{"batl":[[1,10.5,1.74]],"ltp":8.4,"tv":94.66,"id":24420205}]}]}
{"op":"mcm","clk":"991893726","pt":1580509893384,"mc":[{"id":"1.168130661","rc":[{"trd":[[2.64,59.12]],"batb":[[0,2.62,9.29],[1,2.6,21.68],[2,2.42,20.45]],"batl":[[0,2.64,36.44],[1,2.76,32.49],[2,2.84,6]],"ltp":2.64,"tv":437.2,"id":25238892}],"tv":1164.67}]}
{"op":"mcm","clk":"991893961","pt":1580509897674,"mc":[{"id":"1.168130661","rc":[{"trd":[[2.64,66.7]],"batl":[[0,2.64,32.65]],"ltp":2.64,"tv":444.78,"id":25238892},{"trd":[[16.5,8.78]],"batl":[[0,21,14.12],[1,60,9],[2,480,4]],"ltp":16.5,"tv":51.51,"id":24707172},{"trd":[[10,44.01]],"batl":[[0,10.5,1.74],[1,12.5,10],[2,14,2.52]],"ltp":10.0,"tv":96.66,"id":24420205},{"trd":[[2.82,0.36],[2.84,2.68]],"batl":[[0,2.84,8.66]],"ltp":2.84,"tv":546.53,"id":26314798},{"batb":[[0,10,7.09]],"ltp":10.0,"tv":40.58,"id":420}],"tv":1180.07}]}
{"op":"mcm","clk":"991893986","pt":1580509898192,"mc":[{"id":"1.168130661","rc":[{"batb":[[0,32,1.76]],"ltp":0.0,"tv":0.0,"id":25545675},{"batb":[[0,15.5,2.13],[1,15,2.24],[2,14.5,2.27]],"batl":[[0,21,14.31]],"ltp":16.5,"tv":51.51,"id":24707172},{"batb":[[0,9.6,2.08],[1,9.4,8.57],[2,9.2,4.97]],"ltp":10.0,"tv":96.66,"id":24420205},{"batb":[[0,2.7,2.1],[1,2.68,31.73],[2,2.66,5.35]],"ltp":2.84,"tv":546.53,"id":26314798}]}]}
{"op":"mcm","clk":"991894098","pt":1580509901491,"mc":[{"id":"1.168130661","rc":[{"batb":[[0,2.62,8.29],[2,2.5,1]],"ltp":2.64,"tv":444.78,"id":25238892}]}]}
{"op":"mcm","clk":"991894227","pt":1580509903607,"mc":[{"id":"1.168130661","rc":[{"batb":[[1,28,3.3]],"ltp":0.0,"tv":0.0,"id":25545675},{"batb":[[1,15,6.46]],"ltp":16.5,"tv":51.51,"id":24707172},{"batb":[[0,2.7,25.55],[1,2.68,8.11]],"ltp":2.84,"tv":546.53,"id":26314798}]}]}
{"op":"mcm","clk":"991895119","pt":1580509924709,"mc":[{"id":"1.168130661","rc":[{"batl":[[0,12.5,10],[1,14,2.52],[2,38,9]],"ltp":10.0,"tv":96.66,"id":24420205}]}]}
{"op":"mcm","clk":"991895146","pt":1580509925333,"mc":[{"id":"1.168130661","rc":[{"batb":[[1,15,8.61]],"batl":[[1,48,1.68],[2,60,9]],"ltp":16.5,"tv":51.51,"id":24707172},{"batl":[[0,12,1.52],[1,12.5,10],[2,14,2.52]],"ltp":10.0,"tv":96.66,"id":24420205}]}]}
{"op":"mcm","clk":"991895201","pt":1580509926517,"mc":[{"id":"1.168130661","rc":[{"trd":[[2.62,16.58]],"batb":[[0,2.6,21.68],[1,2.5,1],[2,2.42,20.45]],"batl":[[0,2.62,24.36]],"ltp":2.62,"tv":461.36,"id":25238892}],"tv":1196.66}]}
{"op":"mcm","clk":"991895385","pt":1580509931440,"mc":[{"id":"1.168130661","rc":[{"batb":[[0,15.5,6.21],[1,15,4.39]],"ltp":16.5,"tv":51.51,"id":24707172}]}]}
{"op":"mcm","clk":"991895419","pt":1580509932424,"mc":[{"id":"1.168130661","rc":[{"batl":[[2,2.86,60]],"ltp":2.62,"tv":461.36,"id":25238892}]}]}
{"op":"mcm","clk":"991895678","pt":1580509938309,"mc":[{"id":"1.168130661","rc":[{"batl":[[0,2.74,11.8],[1,2.76,31.54]],"ltp":2.62,"tv":461.36,"id":25238892}]}]}
{"op":"mcm","clk":"991895762","pt":1580509940427,"mc":[{"id":"1.168130661","rc":[{"batl":[[2,2.84,6]],"ltp":2.62,"tv":461.36,"id":25238892}]}]}
{"op":"mcm","clk":"991896194","pt":1580509951717,"mc":[{"id":"1.168130661","rc":[{"batl":[[0,2.72,2.95],[1,2.74,10.85],[2,2.76,31.54]],"ltp":2.62,"tv":461.36,"id":25238892}]}]}
{"op":"mcm","clk":"991896439","pt":1580509957663,"mc":[{"id":"1.168130661","rc":[{"batl":[[0,2.7,9.26],[1,2.72,2.95],[2,2.74,10.85]],"ltp":2.62,"tv":461.36,"id":25238892},{"batl":[[0,12.5,10],[1,14,2.52],[2,38,9]],"ltp":10.0,"tv":96.66,"id":24420205}]}]}
{"op":"mcm","clk":"991896495","pt":1580509958645,"mc":[{"id":"1.168130661","rc":[{"batl":[[0,20,1.87],[1,21,14.12]],"ltp":16.5,"tv":51.51,"id":24707172},{"batb":[[0,9.8,2.66],[1,9.6,2.08],[2,9.4,8.57]],"batl":[[1,13.5,3.12],[2,14,2.52]],"ltp":10.0,"tv":96.66,"id":24420205}]}]}
{"op":"mcm","clk":"991896551","pt":1580509960445,"mc":[{"id":"1.168130661","rc":[{"batb":[[0,9.8,9.13],[2,9.4,1.83]],"ltp":10.0,"tv":96.66,"id":24420205}]}]}
{"op":"mcm","clk":"991898034","pt":1580509991589,"mc":[{"id":"1.168130661","rc":[{"trd":[[2.6,42]],"batb":[[0,2.5,1.68],[1,2.42,20.45],[2,2.32,10.78]],"ltp":2.6,"tv":503.36,"id":25238892}],"tv":1238.66}]}
{"op":"mcm","clk":"991898166","pt":1580509993996,"mc":[{"id":"1.168130661","rc":[{"batb":[[0,2.44,1.68]],"ltp":2.6,"tv":503.36,"id":25238892}]}]}
{"op":"mcm","clk":"991898669","pt":1580510003697,"mc":[{"id":"1.168130661","rc":[{"batb":[[0,2.46,6.21],[1,2.44,1],[2,2.42,20.45]],"batl":[[0,2.72,2.95],[1,2.74,10.85],[2,2.76,34.59]],"ltp":2.6,"tv":503.36,"id":25238892}]}]}
{"op":"mcm","clk":"991898953","pt":1580510009508,"mc":[{"id":"1.168130661","rc":[{"batb":[[0,2.48,1.68],[1,2.46,5.53]],"ltp":2.6,"tv":503.36,"id":25238892}]}]}
{"op":"mcm","clk":"991899101","pt":1580510013512,"mc":[{"id":"1.168130661","rc":[{"batb":[[2,2.44,3]],"ltp":2.6,"tv":503.36,"id":25238892}]}]}
{"op":"mcm","clk":"991899855","pt":1580510032509,"mc":[{"id":"1.168130661","rc":[{"batb":[[0,16,1.08],[1,15.5,6.21],[2,15,4.39]],"ltp":16.5,"tv":51.51,"id":24707172},{"batb":[[0,2.72,6.34],[1,2.7,2.1],[2,2.68,8.11]],"ltp":2.84,"tv":546.53,"id":26314798}]}]}
{"op":"mcm","clk":"991900043","pt":1580510036522,"mc":[{"id":"1.168130661","rc":[{"batb":[[0,2.5,2.48],[1,2.48,1]],"ltp":2.6,"tv":503.36,"id":25238892}]}]}
{"op":"mcm","clk":"991900090","pt":1580510037710,"mc":[{"id":"1.168130661","rc":[{"batb":[[0,2.5,3.48],[1,2.44,3],[2,2.42,20.45]],"ltp":2.6,"tv":503.36,"id":25238892}]}]}
{"op":"mcm","clk":"991900830","pt":1580510054720,"mc":[{"id":"1.168130661","rc":[{"batb":[[0,34,2.27],[1,32,1.47],[2,28,3.3]],"ltp":0.0,"tv":0.0,"id":25545675},{"batb":[[0,16,1.37],[2,15,4.09]],"ltp":16.5,"tv":51.51,"id":24707172},{"batb":[[0,10,1.98],[1,9.8,9.13],[2,9.6,2.08]],"ltp":10.0,"tv":96.66,"id":24420205},{"batb":[[0,2.72,11.69]],"ltp":2.84,"tv":546.53,"id":26314798}]}]}
{"op":"mcm","clk":"991900953","pt":1580510057546,"mc":[{"id":"1.168130661","rc":[{"batl":[[0,2.72,3.15]],"ltp":2.6,"tv":503.36,"id":25238892}]}]}
{"op":"mcm","clk":"991900997","pt":1580510058573,"mc":[{"id":"1.168130661","rc":[{"batb":[[0,2.74,2.07],[1,2.72,11.69]],"ltp":2.84,"tv":546.53,"id":26314798}]}]}
{"op":"mcm","clk":"991901100","pt":1580510060544,"mc":[{"id":"1.168130661","rc":[{"batb":[[1,32,3.45],[2,28,1.04]],"ltp":0.0,"tv":0.0,"id":25545675},{"batb":[[0,10,8.31],[1,9.8,2.66]],"ltp":10.0,"tv":96.66,"id":24420205}]}]}
{"op":"mcm","clk":"991901766","pt":1580510075273,"mc":[{"id":"1.168130661","rc":[{"batb":[[1,32,1.47]],"ltp":0.0,"tv":0.0,"id":25545675}]}]}
{"op":"mcm","clk":"991905303","pt":1580510149613,"mc":[{"id":"1.168130661","rc":[{"batl":[[1,2.74,14.64]],"ltp":2.6,"tv":503.36,"id":25238892}]}]}
{"op":"mcm","clk":"991905357","pt":1580510150644,"mc":[{"id":"1.168130661","rc":[{"batb":[[0,2.74,7.42],[1,2.72,6.34]],"ltp":2.84,"tv":546.53,"id":26314798}]}]}
{"op":"mcm","clk":"991905497","pt":1580510154950,"mc":[{"id":"1.168130661","rc":[{"batl":[[2,2.9,15.51]],"ltp":2.84,"tv":546.53,"id":26314798}]}]}
{"op":"mcm","clk":"991905810","pt":1580510162935,"mc":[{"id":"1.168130661","rc":[{"batb":[[0,2.5,5.48]],"ltp":2.6,"tv":503.36,"id":25238892}]}]}
{"op":"mcm","clk":"991906966","pt":1580510194673,"mc":[{"id":"1.168130661","rc":[{"batb":[[0,10.5,1.64],[1,10,8.31],[2,9.8,2.66]],"ltp":10.0,"tv":96.66,"id":24420205}]}]}
{"op":"mcm","clk":"991907318","pt":1580510204404,"mc":[{"id":"1.168130661","rc":[{"batb":[[1,10,1.98]],"ltp":10.0,"tv":96.66,"id":24420205}]}]}
{"op":"mcm","clk":"991919277","pt":1580510266432,"mc":[{"id":"1.168130661","rc":[{"trd":[[2.7,19.12],[2.72,18.65],[2.74,79.74]],"batl":[[0,2.74,7.57],[1,2.76,34.59],[2,2.84,6]],"ltp":2.74,"tv":523.8,"id":25238892}],"tv":1259.1}]}
{"op":"mcm","clk":"991919416","pt":1580510269465,"mc":[{"id":"1.168130661","rc":[{"batb":[[0,2.52,1.68],[1,2.5,3.8],[2,2.44,3]],"ltp":2.74,"tv":523.8,"id":25238892}]}]}
{"op":"mcm","clk":"991919556","pt":1580510272654,"mc":[{"id":"1.168130661","rc":[{"batl":[[0,2.74,7.77]],"ltp":2.74,"tv":523.8,"id":25238892}]}]}
{"op":"mcm","clk":"991919718","pt":1580510276875,"mc":[{"id":"1.168130661","rc":[{"batb":[[0,2.52,3.84]],"ltp":2.74,"tv":523.8,"id":25238892}]}]}
{"op":"mcm","clk":"991919754","pt":1580510277856,"mc":[{"id":"1.168130661","rc":[{"batb":[[0,2.54,1],[1,2.52,2.84],[2,2.5,3.8]],"ltp":2.74,"tv":523.8,"id":25238892}]}]}
{"op":"mcm","clk":"991920634","pt":1580510298184,"mc":[{"id":"1.168130661","rc":[{"batl":[[0,40,1],[1,55,1.88],[2,60,2]],"ltp":0.0,"tv":0.0,"id":25545675}]}]}
{"op":"mcm","clk":"991920753","pt":1580510301477,"mc":[{"id":"1.168130661","rc":[{"batl":[[1,55,1.68]],"ltp":0.0,"tv":0.0,"id":25545675}]}]}
{"op":"mcm","clk":"991920939","pt":1580510306703,"mc":[{"id":"1.168130661","rc":[{"batb":[[0,2.54,2.77],[2,2.5,2]],"ltp":2.74,"tv":523.8,"id":25238892}]}]}
{"op":"mcm","clk":"991921069","pt":1580510310010,"mc":[{"id":"1.168130661","rc":[{"trd":[[34,2]],"batb":[[0,34,1.27]],"batl":[[0,55,1.68],[1,60,2],[2,230,9]],"ltp":34.0,"tv":2.0,"id":25545675}],"tv":1261.1}]}
{"op":"mcm","clk":"991921111","pt":1580510311090,"mc":[{"id":"1.168130661","rc":[{"batb":[[0,2.56,1],[1,2.54,1.77],[2,2.52,2.84]],"ltp":2.74,"tv":523.8,"id":25238892}]}]}
{"op":"mcm","clk":"991921420","pt":1580510318404,"mc":[{"id":"1.168130661","rc":[{"batb":[[1,15.5,2.13]],"ltp":16.5,"tv":51.51,"id":24707172}]}]}
{"op":"mcm","clk":"991921895","pt":1580510330831,"mc":[{"id":"1.168130661","rc":[{"batb":[[0,2.56,3.13],[2,2.5,2.68]],"ltp":2.74,"tv":523.8,"id":25238892}]}]}
{"op":"mcm","clk":"991922138","pt":1580510335406,"mc":[{"id":"1.168130661","rc":[{"batb":[[0,2.58,1],[1,2.56,2.13],[2,2.54,1.77]],"ltp":2.74,"tv":523.8,"id":25238892},{"batb":[[0,2.76,6.24],[1,2.74,7.42]],"ltp":2.84,"tv":546.53,"id":26314798}]}]}
{"op":"mcm","clk":"991922323","pt":1580510339629,"mc":[{"id":"1.168130661","rc":[{"batb":[[0,32,1.47],[1,28,1.04],[2,26,2.19]],"ltp":34.0,"tv":2.0,"id":25545675},{"batb":[[0,2.58,2.68],[2,2.5,2.68]],"ltp":2.74,"tv":523.8,"id":25238892}]}]}
{"op":"mcm","clk":"991922333","pt":1580510339833,"mc":[{"id":"1.168130661","rc":[{"batb":[[1,29,1.27],[2,28,1.04]],"ltp":34.0,"tv":2.0,"id":25545675}]}]}
{"op":"mcm","clk":"991922430","pt":1580510342037,"mc":[{"id":"1.168130661","rc":[{"batl":[[0,55,1.88]],"ltp":34.0,"tv":2.0,"id":25545675}]}]}
{"op":"mcm","clk":"991922501","pt":1580510343625,"mc":[{"id":"1.168130661","rc":[{"batb":[[0,2.6,1],[1,2.58,1.68],[2,2.56,2.13]],"ltp":2.74,"tv":523.8,"id":25238892}]}]}
{"op":"mcm","clk":"991922606","pt":1580510346138,"mc":[{"id":"1.168130661","rc":[{"batl":[[2,24,2]],"ltp":16.5,"tv":51.51,"id":24707172}]}]}
{"op":"mcm","clk":"991922694","pt":1580510348295,"mc":[{"id":"1.168130661","rc":[{"batl":[[0,2.74,7.57]],"ltp":2.74,"tv":523.8,"id":25238892}]}]}
{"op":"mcm","clk":"991922907","pt":1580510352667,"mc":[{"id":"1.168130661","rc":[{"trd":[[10,13],[10.5,5.18]],"batb":[[0,9.8,62],[1,8.4,3],[2,7.4,5]],"batl":[[0,10,2.91],[1,11,4],[2,32,9]],"ltp":10.0,"tv":54.75,"id":420}],"tv":1275.28}]}
{"op":"mcm","clk":"991922914","pt":1580510352925,"mc":[{"id":"1.168130661","rc":[{"trd":[[10,18.82]],"batl":[[0,11,4],[1,32,9],[2,32,0]],"ltp":10.0,"tv":60.58,"id":420}],"tv":1281.1}]}
{"op":"mcm","clk":"991924245","pt":1580510385561,"mc":[{"id":"1.168130661","rc":[{"batb":[[0,2.6,3.09],[2,2.5,2.68]],"ltp":2.74,"tv":523.8,"id":25238892},{"batb":[[0,2.78,2.04],[1,2.76,6.24],[2,2.74,5.35]],"ltp":2.84,"tv":546.53,"id":26314798}]}]}
{"op":"mcm","clk":"991924337","pt":1580510388689,"mc":[{"id":"1.168130661","rc":[{"batb":[[0,2.62,1],[1,2.6,2.09],[2,2.58,1.68]],"ltp":2.74,"tv":523.8,"id":25238892}]}]}
{"op":"mcm","clk":"991924382","pt":1580510390701,"mc":[{"id":"1.168130661","rc":[{"batl":[[1,24,2],[2,32,9]],"ltp":10.0,"tv":60.58,"id":420}]}]}
{"op":"mcm","clk":"991924992","pt":1580510407709,"mc":[{"id":"1.168130661","rc":[{"batb":[[0,2.62,2.68],[2,2.5,2.68]],"ltp":2.74,"tv":523.8,"id":25238892}]}]}
{"op":"mcm","clk":"991925262","pt":1580510413450,"mc":[{"id":"1.168130661","rc":[{"trd":[[2.74,94.88]],"batl":[[0,2.76,34.59],[1,2.84,6],[2,2.86,60]],"ltp":2.74,"tv":538.94,"id":25238892},{"trd":[[15.5,18.11],[16,8.74]],"batb":[[0,15,4.09],[1,14.5,2.27],[2,12.5,2]],"ltp":15.5,"tv":58.52,"id":24707172},{"trd":[[10,47.97],[10.5,3.28]],"batb":[[0,9.8,2.66],[1,9.6,2.08],[2,9.2,2.99]],"ltp":10.0,"tv":103.9,"id":24420205}],"tv":1310.48}]}
{"op":"mcm","clk":"991926293","pt":1580510439544,"mc":[{"id":"1.168130661","rc":[{"batb":[[1,2.5,2.68],[2,2.42,20.45]],"ltp":2.74,"tv":538.94,"id":25238892}]}]}
{"op":"mcm","clk":"991926345","pt":1580510440723,"mc":[{"id":"1.168130661","rc":[{"batb":[[0,2.64,2.06],[1,2.62,1],[2,2.5,2.68]],"batl":[[0,2.74,4],[1,2.76,34.59],[2,2.84,6]],"ltp":2.74,"tv":538.94,"id":25238892}]}]}
{"op":"mcm","clk":"991926349","pt":1580510440824,"mc":[{"id":"1.168130661","rc":[{"batb":[[0,2.66,1.68],[1,2.64,2.06],[2,2.62,1]],"ltp":2.74,"tv":538.94,"id":25238892}]}]}
{"op":"mcm","clk":"991928524","pt":1580510493406,"mc":[{"id":"1.168130661","rc":[{"batl":[[0,19.5,2.19],[1,20,1.68],[2,21,14.12]],"ltp":15.5,"tv":58.52,"id":24707172}]}]}
{"op":"mcm","clk":"991929122","pt":1580510508333,"mc":[{"id":"1.168130661","rc":[{"batl":[[0,19,1.68],[1,19.5,2.19]],"ltp":15.5,"tv":58.52,"id":24707172}]}]}
{"op":"mcm","clk":"991929966","pt":1580510529644,"mc":[{"id":"1.168130661","rc":[{"trd":[[2.42,5.16],[2.5,4],[2.52,1.36],[2.62,18.58],[2.64,70.82],[2.66,3.36]],"batb":[[0,2.42,17.86],[1,2.3,24.6],[2,2.2,115]],"ltp":2.42,"tv":558.94,"id":25238892}],"tv":1330.48}]}
{"op":"mcm","clk":"991929973","pt":1580510529736,"mc":[{"id":"1.168130661","rc":[{"batl":[[0,2.74,4.18]],"ltp":2.42,"tv":558.94,"id":25238892}]}]}
{"op":"mcm","clk":"991930033","pt":1580510531246,"mc":[{"id":"1.168130661","rc":[{"batb":[[2,2.22,6]],"ltp":2.42,"tv":558.94,"id":25238892}]}]}
{"op":"mcm","clk":"991930288","pt":1580510536442,"mc":[{"id":"1.168130661","rc":[{"batb":[[1,29,3.45]],"ltp":34.0,"tv":2.0,"id":25545675},{"batb":[[0,9.8,9.13]],"ltp":10.0,"tv":103.9,"id":24420205}]}]}
{"op":"mcm","clk":"991930449","pt":1580510540549,"mc":[{"id":"1.168130661","rc":[{"batb":[[0,2.42,22.66]],"ltp":2.42,"tv":558.94,"id":25238892}]}]}
{"op":"mcm","clk":"991930616","pt":1580510544670,"mc":[{"id":"1.168130661","rc":[{"batl":[[1,2.76,31.54]],"ltp":2.42,"tv":558.94,"id":25238892}]}]}
{"op":"mcm","clk":"991930623","pt":1580510544927,"mc":[{"id":"1.168130661","rc":[{"batl":[[0,2.72,1.82],[1,2.74,4],[2,2.76,31.54]],"ltp":2.42,"tv":558.94,"id":25238892}]}]}
{"op":"mcm","clk":"991930765","pt":1580510547654,"mc":[{"id":"1.168130661","rc":[{"batb":[[0,2.44,6.14],[1,2.42,22.66],[2,2.3,24.6]],"batl":[[0,2.72,15.46]],"ltp":2.42,"tv":558.94,"id":25238892},{"batl":[[1,21,14.31],[2,24,2]],"ltp":15.5,"tv":58.52,"id":24707172}]}]}
{"op":"mcm","clk":"991930775","pt":1580510547860,"mc":[{"id":"1.168130661","rc":[{"batl":[[0,18.5,2],[1,19,1.68],[2,21,14.31]],"ltp":15.5,"tv":58.52,"id":24707172}]}]}
{"op":"mcm","clk":"991931250","pt":1580510559179,"mc":[{"id":"1.168130661","rc":[{"batb":[[2,2.3,20.45]],"ltp":2.42,"tv":558.94,"id":25238892}]}]}
{"op":"mcm","clk":"991931439","pt":1580510563673,"mc":[{"id":"1.168130661","rc":[{"batb":[[0,2.46,1.98],[1,2.44,6.14],[2,2.42,22.66]],"ltp":2.42,"tv":558.94,"id":25238892},{"batb":[[0,15.5,1.98],[1,15,4.09],[2,14.5,2.27]],"ltp":15.5,"tv":58.52,"id":24707172},{"batb":[[0,10,1.7],[1,9.8,9.13],[2,9.6,2.08]],"ltp":10.0,"tv":103.9,"id":24420205},{"batb":[[0,10,1.98],[1,9.8,62],[2,8.4,3]],"ltp":10.0,"tv":60.58,"id":420}]}]}
{"op":"mcm","clk":"991931463","pt":1580510564287,"mc":[{"id":"1.168130661","rc":[{"batl":[[1,2.76,31.54],[2,2.84,6]],"ltp":2.42,"tv":558.94,"id":25238892},{"batl":[[2,21,14.12]],"ltp":15.5,"tv":58.52,"id":24707172},{"batb":[[0,2.8,6.15],[1,2.78,7.39],[2,2.68,8.11]],"ltp":2.84,"tv":546.53,"id":26314798}]}]}
{"op":"mcm","clk":"991932121","pt":1580510580674,"mc":[{"id":"1.168130661","rc":[{"batl":[[0,2.72,13.82]],"ltp":2.42,"tv":558.94,"id":25238892}]}]}
{"op":"mcm","clk":"991932146","pt":1580510581186,"mc":[{"id":"1.168130661","rc":[{"batl":[[1,2.76,33.16]],"ltp":2.42,"tv":558.94,"id":25238892},{"batl":[[0,18,1.68],[1,18.5,2]],"ltp":15.5,"tv":58.52,"id":24707172}]}]}
{"op":"mcm","clk":"991932190","pt":1580510582582,"mc":[{"id":"1.168130661","rc":[{"batb":[[2,2.62,1.89]],"ltp":2.84,"tv":546.53,"id":26314798}]}]}
{"op":"mcm","clk":"991932667","pt":1580510594812,"mc":[{"id":"1.168130661","rc":[{"batb":[[0,2.8,13.91]],"ltp":2.84,"tv":546.53,"id":26314798}]}]}
{"op":"mcm","clk":"991932935","pt":1580510601501,"mc":[{"id":"1.168130661","rc":[{"batl":[[0,2.7,2.18],[1,2.72,13.64],[2,2.76,33.16]],"ltp":2.42,"tv":558.94,"id":25238892},{"batl":[[0,17.5,2],[1,18,1.68]],"ltp":15.5,"tv":58.52,"id":24707172},{"batb":[[0,2.82,2.01],[1,2.8,13.91],[2,2.78,5.35]],"ltp":2.84,"tv":546.53,"id":26314798}]}]}
{"op":"mcm","clk":"991933180","pt":1580510607501,"mc":[{"id":"1.168130661","rc":[{"batb":[[0,2.82,7.36],[2,2.62,1.89]],"ltp":2.84,"tv":546.53,"id":26314798}]}]}
{"op":"mcm","clk":"991938954","pt":1580510731953,"mc":[{"id":"1.168130661","rc":[{"batb":[[0,10,3.42]],"ltp":10.0,"tv":103.9,"id":24420205}]}]}
{"op":"mcm","clk":"991939171","pt":1580510737458,"mc":[{"id":"1.168130661","rc":[{"batb":[[1,9.8,2.66]],"ltp":10.0,"tv":103.9,"id":24420205}]}]}
{"op":"mcm","clk":"991941031","pt":1580510778499,"mc":[{"id":"1.168130661","rc":[{"batb":[[0,2.5,1.51],[1,2.46,1.98],[2,2.44,6.14]],"ltp":2.42,"tv":558.94,"id":25238892}]}]}
{"op":"mcm","clk":"991941201","pt":1580510781610,"mc":[{"id":"1.168130661","rc":[{"batb":[[0,2.46,1.98],[1,2.44,6.14],[2,2.42,4.8]],"ltp":2.42,"tv":558.94,"id":25238892}]}]}
{"op":"mcm","clk":"991941646","pt":1580510793312,"mc":[{"id":"1.168130661","rc":[{"batb":[[0,2.5,16.66],[1,2.46,1.98],[2,2.44,6.14]],"ltp":2.42,"tv":558.94,"id":25238892}]}]}
{"op":"mcm","clk":"991943915","pt":1580510846074,"mc":[{"id":"1.168130661","rc":[{"batl":[[2,2.9,11.72]],"ltp":2.84,"tv":546.53,"id":26314798}]}]}
{"op":"mcm","clk":"991950296","pt":1580510965699,"mc":[{"id":"1.168130661","rc":[{"batl":[[0,2.6,2],[1,2.7,2.18],[2,2.72,13.64]],"ltp":2.42,"tv":558.94,"id":25238892}]}]}
{"op":"mcm","clk":"991950395","pt":1580510967707,"mc":[{"id":"1.168130661","rc":[{"batl":[[1,2.7,2]],"ltp":2.42,"tv":558.94,"id":25238892}]}]}
{"op":"mcm","clk":"991950746","pt":1580510975518,"mc":[{"id":"1.168130661","rc":[{"batl":[[1,2.76,33.16],[2,2.86,60]],"ltp":2.42,"tv":558.94,"id":25238892}]}]}
{"op":"mcm","clk":"991950878","pt":1580510978714,"mc":[{"id":"1.168130661","rc":[{"trd":[[2.6,46]],"batb":[[0,2.6,14.66]],"batl":[[0,2.76,33.16],[1,2.86,60],[2,2.88,4.49]],"ltp":2.6,"tv":562.94,"id":25238892}],"tv":1334.48}]}
{"op":"mcm","clk":"991950918","pt":1580510979532,"mc":[{"id":"1.168130661","rc":[{"batb":[[1,29,1.27]],"ltp":34.0,"tv":2.0,"id":25545675},{"batb":[[2,2.42,21.46]],"batl":[[1,2.86,63.88]],"ltp":2.6,"tv":562.94,"id":25238892}]}]}
{"op":"mcm","clk":"991951050","pt":1580510981714,"mc":[{"id":"1.168130661","rc":[{"batb":[[0,2.46,1.98],[1,2.42,21.46],[2,2.2,115]],"ltp":2.6,"tv":562.94,"id":25238892}]}]}
{"op":"mcm","clk":"991951063","pt":1580510982011,"mc":[{"id":"1.168130661","rc":[{"batb":[[0,2.48,11.81],[1,2.46,16.64],[2,2.42,21.46]],"ltp":2.6,"tv":562.94,"id":25238892}]}]}
{"op":"mcm","clk":"991951146","pt":1580510983704,"mc":[{"id":"1.168130661","rc":[{"batb":[[1,2.46,1.98]],"ltp":2.6,"tv":562.94,"id":25238892}]}]}
{"op":"mcm","clk":"991951177","pt":1580510984326,"mc":[{"id":"1.168130661","rc":[{"batb":[[0,2.5,14.66]],"ltp":2.6,"tv":562.94,"id":25238892}]}]}
{"op":"mcm","clk":"991951266","pt":1580510986328,"mc":[{"id":"1.168130661","rc":[{"batl":[[0,2.76,33.35]],"ltp":2.6,"tv":562.94,"id":25238892}]}]}
{"op":"mcm","clk":"991951546","pt":1580510992929,"mc":[{"id":"1.168130661","rc":[{"batl":[[0,2.74,4.19],[1,2.76,33.16],[2,2.86,63.88]],"ltp":2.6,"tv":562.94,"id":25238892}]}]}
{"op":"mcm","clk":"991951898","pt":1580511001252,"mc":[{"id":"1.168130661","rc":[{"batb":[[1,29,3.45]],"ltp":34.0,"tv":2.0,"id":25545675}]}]}
{"op":"mcm","clk":"991951979","pt":1580511002643,"mc":[{"id":"1.168130661","rc":[{"batl":[[1,2.76,31.54]],"ltp":2.6,"tv":562.94,"id":25238892}]}]}
{"op":"mcm","clk":"991952010","pt":1580511003316,"mc":[{"id":"1.168130661","rc":[{"batl":[[0,2.72,1.83],[1,2.74,4],[2,2.76,31.54]],"ltp":2.6,"tv":562.94,"id":25238892}]}]}
{"op":"mcm","clk":"991952302","pt":1580511009326,"mc":[{"id":"1.168130661","rc":[{"batb":[[0,2.52,11.66],[1,2.5,14.66],[2,2.46,1.98]],"ltp":2.6,"tv":562.94,"id":25238892}]}]}
{"op":"mcm","clk":"991952564","pt":1580511015645,"mc":[{"id":"1.168130661","rc":[{"batb":[[1,29,1.27]],"ltp":34.0,"tv":2.0,"id":25545675}]}]}
{"op":"mcm","clk":"991953346","pt":1580511036697,"mc":[{"id":"1.168130661","rc":[{"batl":[[0,2.74,4.19],[1,2.76,31.54],[2,2.86,63.88]],"ltp":2.6,"tv":562.94,"id":25238892}]}]}
{"op":"mcm","clk":"991953358","pt":1580511037064,"mc":[{"id":"1.168130661","rc":[{"batl":[[1,2.76,33.01]],"ltp":2.6,"tv":562.94,"id":25238892}]}]}
{"op":"mcm","clk":"991953499","pt":1580511041592,"mc":[{"id":"1.168130661","rc":[{"trd":[[2.84,6.42]],"batl":[[0,2.84,6.79]],"ltp":2.84,"tv":550.27,"id":26314798}],"tv":1338.22}]}
{"op":"mcm","clk":"991953514","pt":1580511042059,"mc":[{"id":"1.168130661","rc":[{"batl":[[2,2.84,6]],"ltp":2.6,"tv":562.94,"id":25238892}]}]}
{"op":"mcm","clk":"991954542","pt":1580511071704,"mc":[{"id":"1.168130661","rc":[{"batl":[[0,2.72,1.83],[1,2.74,4],[2,2.76,31.54]],"ltp":2.6,"tv":562.94,"id":25238892}]}]}
{"op":"mcm","clk":"991954958","pt":1580511083229,"mc":[{"id":"1.168130661","rc":[{"batl":[[0,2.7,2.19],[1,2.72,1.64],[2,2.74,4]],"ltp":2.6,"tv":562.94,"id":25238892}]}]}
{"op":"mcm","clk":"991955107","pt":1580511087339,"mc":[{"id":"1.168130661","rc":[{"batb":[[1,29,3.45]],"ltp":34.0,"tv":2.0,"id":25545675}]}]}
{"op":"mcm","clk":"991955861","pt":1580511105451,"mc":[{"id":"1.168130661","rc":[{"batl":[[1,2.74,4],[2,2.76,33.16]],"ltp":2.6,"tv":562.94,"id":25238892}]}]}
{"op":"mcm","clk":"991956393","pt":1580511116463,"mc":[{"id":"1.168130661","rc":[{"batb":[[1,29,1.27]],"ltp":34.0,"tv":2.0,"id":25545675}]}]}
{"op":"mcm","clk":"991957519","pt":1580511138519,"mc":[{"id":"1.168130661","rc":[{"batl":[[0,2.72,2.19]],"ltp":2.6,"tv":562.94,"id":25238892}]}]}
{"op":"mcm","clk":"991968330","pt":1580511162540,"mc":[{"id":"1.168130661","rc":[{"trd":[[2.82,15.08]],"batb":[[0,2.8,13.91],[1,2.62,1.89],[2,2.6,75]],"batl":[[0,2.82,92.64],[1,2.84,6.79],[2,2.86,10.54]],"ltp":2.82,"tv":564.99,"id":26314798}],"tv":1352.95}]}
{"op":"mcm","clk":"991968814","pt":1580511173234,"mc":[{"id":"1.168130661","rc":[{"batb":[[1,29,3.45]],"ltp":34.0,"tv":2.0,"id":25545675}]}]}
{"op":"mcm","clk":"991970189","pt":1580511205454,"mc":[{"id":"1.168130661","rc":[{"batb":[[0,2.54,14.66],[1,2.52,11.66]],"ltp":2.6,"tv":562.94,"id":25238892},{"trd":[[2.8,12.12]],"batb":[[0,2.8,7.84]],"ltp":2.8,"tv":577.11,"id":26314798}],"tv":1365.07}]}
{"op":"mcm","clk":"991970206","pt":1580511205760,"mc":[{"id":"1.168130661","rc":[{"trd":[[2.8,18.18]],"batb":[[0,2.8,4.82]],"ltp":2.8,"tv":583.17,"id":26314798}],"tv":1371.13}]}
{"op":"mcm","clk":"991970288","pt":1580511207702,"mc":[{"id":"1.168130661","rc":[{"trd":[[2.8,24.24]],"batb":[[0,2.8,1.79]],"ltp":2.8,"tv":589.23,"id":26314798}],"tv":1377.19}]}
{"op":"mcm","clk":"991970293","pt":1580511207861,"mc":[{"id":"1.168130661","rc":[{"batb":[[1,2.62,4.89]],"ltp":2.8,"tv":589.23,"id":26314798}]}]}
{"op":"mcm","clk":"991970362","pt":1580511209397,"mc":[{"id":"1.168130661","rc":[{"trd":[[2.8,27.81]],"batb":[[0,2.62,4.89],[1,2.6,75],[2,2.56,6]],"batl":[[0,2.8,1.24],[1,2.82,92.64],[2,2.84,6.79]],"ltp":2.8,"tv":592.8,"id":26314798},{"batb":[[0,10,3.71]],"ltp":10.0,"tv":60.58,"id":420}],"tv":1380.76}]}
{"op":"mcm","clk":"991970404","pt":1580511210065,"mc":[{"id":"1.168130661","rc":[{"trd":[[2.82,42.69]],"batl":[[0,2.82,78.84],[1,2.84,6.79],[2,2.86,10.54]],"ltp":2.82,"tv":620.41,"id":26314798}],"tv":1408.36}]}
{"op":"mcm","clk":"991970529","pt":1580511213812,"mc":[{"id":"1.168130661","rc":[{"batl":[[0,2.8,3.03],[1,2.82,78.84],[2,2.84,6.79]],"ltp":2.82,"tv":620.41,"id":26314798}]}]}
{"op":"mcm","clk":"991970652","pt":1580511216491,"mc":[{"id":"1.168130661","rc":[{"batb":[[0,2.62,29.06]],"ltp":2.82,"tv":620.41,"id":26314798}]}]}
{"op":"mcm","clk":"991970773","pt":1580511218692,"mc":[{"id":"1.168130661","rc":[{"batb":[[0,2.68,3.03],[1,2.62,29.06],[2,2.6,75]],"batl":[[0,2.8,13.74]],"ltp":2.82,"tv":620.41,"id":26314798}]}]}
{"op":"mcm","clk":"991971028","pt":1580511224612,"mc":[{"id":"1.168130661","rc":[{"batl":[[0,2.7,3.22],[1,2.72,2],[2,2.74,4]],"ltp":2.6,"tv":562.94,"id":25238892}]}]}
{"op":"mcm","clk":"991971379","pt":1580511234013,"mc":[{"id":"1.168130661","rc":[{"batl":[[0,2.78,3.03],[1,2.8,13.74],[2,2.82,78.84]],"ltp":2.82,"tv":620.41,"id":26314798}]}]}
{"op":"mcm","clk":"991971887","pt":1580511245336,"mc":[{"id":"1.168130661","rc":[{"batb":[[0,10,9.75]],"ltp":10.0,"tv":103.9,"id":24420205}]}]}
{"op":"mcm","clk":"991971984","pt":1580511247641,"mc":[{"id":"1.168130661","rc":[{"batl":[[1,2.74,4],[2,2.76,33.16]],"ltp":2.6,"tv":562.94,"id":25238892},{"batb":[[0,16,1.25],[1,15.5,1.98],[2,15,4.09]],"ltp":15.5,"tv":58.52,"id":24707172},{"batb":[[0,10.5,1.9],[1,10,9.75],[2,9.8,2.66]],"ltp":10.0,"tv":103.9,"id":24420205}]}]}
{"op":"mcm","clk":"991971989","pt":1580511247741,"mc":[{"id":"1.168130661","rc":[{"batl":[[0,2.68,2],[1,2.7,3.22],[2,2.74,4]],"ltp":2.6,"tv":562.94,"id":25238892}]}]}
{"op":"mcm","clk":"991972467","pt":1580511259436,"mc":[{"id":"1.168130661","rc":[{"batb":[[1,15.5,6.07]],"ltp":15.5,"tv":58.52,"id":24707172},{"batb":[[0,10.5,7.93],[1,10,3.42]],"ltp":10.0,"tv":103.9,"id":24420205}]}]}
{"op":"mcm","clk":"991973904","pt":1580511298074,"mc":[{"id":"1.168130661","rc":[{"batb":[[0,11,2.5],[1,10.5,7.93],[2,10,3.42]],"ltp":10.0,"tv":103.9,"id":24420205}]}]}
{"op":"mcm","clk":"991974110","pt":1580511302699,"mc":[{"id":"1.168130661","rc":[{"batb":[[1,15.5,1.98]],"ltp":15.5,"tv":58.52,"id":24707172},{"batb":[[1,10,3.42],[2,9.8,2.66]],"ltp":10.0,"tv":103.9,"id":24420205}]}]}
{"op":"mcm","clk":"991974731","pt":1580511316415,"mc":[{"id":"1.168130661","rc":[{"batb":[[1,15.5,6.07]],"ltp":15.5,"tv":58.52,"id":24707172},{"batb":[[1,10.5,6.03],[2,10,3.42]],"ltp":10.0,"tv":103.9,"id":24420205}]}]}
{"op":"mcm","clk":"991975263","pt":1580511329603,"mc":[{"id":"1.168130661","rc":[{"batl":[[1,14,2.52],[2,24,2]],"ltp":10.0,"tv":103.9,"id":24420205}]}]}
{"op":"mcm","clk":"991975287","pt":1580511330630,"mc":[{"id":"1.168130661","rc":[{"batl":[[1,13.5,1.35],[2,14,2.52]],"ltp":10.0,"tv":103.9,"id":24420205}]}]}
{"op":"mcm","clk":"991975312","pt":1580511331348,"mc":[{"id":"1.168130661","rc":[{"batb":[[1,15.5,1.98]],"ltp":15.5,"tv":58.52,"id":24707172},{"batb":[[1,10,3.42],[2,9.6,2.08]],"ltp":10.0,"tv":103.9,"id":24420205}]}]}
{"op":"mcm","clk":"991975802","pt":1580511345250,"mc":[{"id":"1.168130661","rc":[{"batb":[[1,15.5,6.07]],"ltp":15.5,"tv":58.52,"id":24707172}]}]}
{"op":"mcm","clk":"991976290","pt":1580511358652,"mc":[{"id":"1.168130661","rc":[{"batl":[[0,2.66,3.79],[1,2.68,2],[2,2.7,3.22]],"ltp":2.6,"tv":562.94,"id":25238892}]}]}
{"op":"mcm","clk":"991976525","pt":1580511364150,"mc":[{"id":"1.168130661","rc":[{"batl":[[2,2.7,3.03]],"ltp":2.6,"tv":562.94,"id":25238892}]}]}
{"op":"mcm","clk":"991976893","pt":1580511374309,"mc":[{"id":"1.168130661","rc":[{"trd":[[2.66,10.94]],"batl":[[0,2.68,2],[1,2.7,3.03],[2,2.74,4]],"ltp":2.66,"tv":570.51,"id":25238892},{"trd":[[15.5,30.24],[16,11.24]],"batb":[[0,15,4.09],[1,14.5,2.27],[2,12.5,2]],"ltp":15.5,"tv":73.15,"id":24707172},{"trd":[[11,5]],"batb":[[0,10,3.42],[1,9.6,2.08],[2,8.4,1.56]],"batl":[[0,12.5,10.02]],"ltp":11.0,"tv":108.91,"id":24420205}],"tv":1435.58}]}
{"op":"mcm","clk":"991977379","pt":1580511386701,"mc":[{"id":"1.168130661","rc":[{"batb":[[2,7.2,11]],"ltp":11.0,"tv":108.91,"id":24420205}]}]}
{"op":"mcm","clk":"991977535","pt":1580511390400,"mc":[{"id":"1.168130661","rc":[{"trd":[[10,26.24]],"batb":[[0,9.8,62],[1,8.4,3],[2,8,10]],"ltp":10.0,"tv":67.99,"id":420}],"tv":1442.99}]}
{"op":"mcm","clk":"991977675","pt":1580511393581,"mc":[{"id":"1.168130661","rc":[{"batb":[[0,2.56,6.73],[1,2.54,14.66],[2,2.52,11.66]],"ltp":2.66,"tv":570.51,"id":25238892}]}]}
{"op":"mcm","clk":"991977838","pt":1580511396512,"mc":[{"id":"1.168130661","rc":[{"batl":[[0,17,1.68],[1,17.5,2]],"ltp":15.5,"tv":73.15,"id":24707172},{"batb":[[2,7.4,1.68]],"batl":[[1,13.5,2.28]],"ltp":11.0,"tv":108.91,"id":24420205}]}]}
{"op":"mcm","clk":"991978886","pt":1580511419356,"mc":[{"id":"1.168130661","rc":[{"trd":[[2.78,13.86],[2.8,33.75]],"batl":[[0,2.8,10.77],[1,2.82,78.84],[2,2.84,6.79]],"ltp":2.8,"tv":632.4,"id":26314798}],"tv":1454.99}]}
{"op":"mcm","clk":"991979536","pt":1580511431663,"mc":[{"id":"1.168130661","rc":[{"batb":[[0,15,1.94]],"batl":[[0,17.5,2],[1,21,14.12],[2,24,2]],"ltp":15.5,"tv":73.15,"id":24707172}]}]}
{"op":"mcm","clk":"991980159","pt":1580511447684,"mc":[{"id":"1.168130661","rc":[{"batb":[[0,2.56,8.71]],"ltp":2.66,"tv":570.51,"id":25238892},{"batb":[[0,2.68,10.13]],"ltp":2.8,"tv":632.4,"id":26314798},{"batb":[[0,10,1.98],[1,9.8,62],[2,8.4,3]],"ltp":10.0,"tv":67.99,"id":420}]}]}
{"op":"mcm","clk":"991980307","pt":1580511451177,"mc":[{"id":"1.168130661","rc":[{"batl":[[0,20,2]],"ltp":15.5,"tv":73.15,"id":24707172}]}]}
{"op":"mcm","clk":"991980518","pt":1580511457307,"mc":[{"id":"1.168130661","rc":[{"batl":[[0,20,2.18]],"ltp":15.5,"tv":73.15,"id":24707172}]}]}
{"op":"mcm","clk":"991980575","pt":1580511458587,"mc":[{"id":"1.168130661","rc":[{"batb":[[0,2.7,3],[1,2.68,10.13],[2,2.62,26.06]],"ltp":2.8,"tv":632.4,"id":26314798}]}]}
{"op":"mcm","clk":"991980649","pt":1580511460419,"mc":[{"id":"1.168130661","rc":[{"batb":[[2,2.62,1.89]],"ltp":2.8,"tv":632.4,"id":26314798}]}]}
{"op":"mcm","clk":"991980838","pt":1580511464765,"mc":[{"id":"1.168130661","rc":[{"batb":[[0,15,4]],"ltp":15.5,"tv":73.15,"id":24707172}]}]}
{"op":"mcm","clk":"991981450","pt":1580511480417,"mc":[{"id":"1.168130661","rc":[{"batb":[[0,2.68,10.13],[1,2.62,1.89],[2,2.6,75]],"batl":[[0,2.78,4],[1,2.8,10.77],[2,2.82,78.84]],"ltp":2.8,"tv":632.4,"id":26314798}]}]}
{"op":"mcm","clk":"991981479","pt":1580511481192,"mc":[{"id":"1.168130661","rc":[{"batl":[[0,2.68,18.8]],"ltp":2.66,"tv":570.51,"id":25238892}]}]}
{"op":"mcm","clk":"991982115","pt":1580511498628,"mc":[{"id":"1.168130661","rc":[{"batl":[[0,19.5,1.86],[1,20,2],[2,21,14.12]],"ltp":15.5,"tv":73.15,"id":24707172}]}]}
{"op":"mcm","clk":"991982340","pt":1580511504536,"mc":[{"id":"1.168130661","rc":[{"batl":[[0,19.5,3.76]],"ltp":15.5,"tv":73.15,"id":24707172}]}]}
{"op":"mcm","clk":"991982681","pt":1580511513262,"mc":[{"id":"1.168130661","rc":[{"batb":[[0,15.5,1.11],[1,15,4],[2,14.5,2.27]],"ltp":15.5,"tv":73.15,"id":24707172}]}]}
{"op":"mcm","clk":"991982886","pt":1580511518335,"mc":[{"id":"1.168130661","rc":[{"batl":[[0,2.68,16.8]],"ltp":2.66,"tv":570.51,"id":25238892},{"batl":[[1,21,14.12],[2,24,2]],"ltp":15.5,"tv":73.15,"id":24707172}]}]}
{"op":"mcm","clk":"991983495","pt":1580511532657,"mc":[{"id":"1.168130661","rc":[{"batl":[[0,19.5,2.08],[1,20,1.68],[2,21,14.12]],"ltp":15.5,"tv":73.15,"id":24707172}]}]}
{"op":"mcm","clk":"991983660","pt":1580511536257,"mc":[{"id":"1.168130661","rc":[{"trd":[[2.68,49.57],[2.7,23.37]],"batl":[[0,2.74,4.9],[1,2.76,33.16],[2,2.84,6]],"ltp":2.7,"tv":608.38,"id":25238892}],"tv":1492.85}]}
{"op":"mcm","clk":"991984976","pt":1580511566597,"mc":[{"id":"1.168130661","rc":[{"batl":[[0,2.72,2.54],[1,2.74,4],[2,2.76,31.54]],"ltp":2.7,"tv":608.38,"id":25238892},{"batl":[[0,19,1.68],[1,19.5,2.08]],"ltp":15.5,"tv":73.15,"id":24707172}]}]}
{"op":"mcm","clk":"991986559","pt":1580511599640,"mc":[{"id":"1.168130661","rc":[{"batl":[[0,2.74,4.9],[1,2.76,31.54],[2,2.84,6]],"ltp":2.7,"tv":608.38,"id":25238892}]}]}
{"op":"mcm","clk":"991986614","pt":1580511600663,"mc":[{"id":"1.168130661","rc":[{"batl":[[1,2.76,33.16]],"ltp":2.7,"tv":608.38,"id":25238892}]}]}
{"op":"mcm","clk":"991986829","pt":1580511603552,"mc":[{"id":"1.168130661","rc":[{"batb":[[0,2.7,6.38],[1,2.68,10.13],[2,2.62,1.89]],"ltp":2.8,"tv":632.4,"id":26314798}]}]}
{"op":"mcm","clk":"991988615","pt":1580511636278,"mc":[{"id":"1.168130661","rc":[{"batb":[[0,2.7,13.48],[1,2.68,3.03]],"ltp":2.8,"tv":632.4,"id":26314798}]}]}
{"op":"mcm","clk":"991995646","pt":1580511799658,"mc":[{"id":"1.168130661","rc":[{"batl":[[1,2.76,31.54]],"ltp":2.7,"tv":608.38,"id":25238892}]}]}
{"op":"mcm","clk":"991995711","pt":1580511800641,"mc":[{"id":"1.168130661","rc":[{"batl":[[0,2.72,2.54],[1,2.74,4],[2,2.76,31.54]],"ltp":2.7,"tv":608.38,"id":25238892}]}]}
{"op":"mcm","clk":"992003516","pt":1580511967970,"mc":[{"id":"1.168130661","rc":[{"batl":[[0,2.7,2.9],[1,2.72,1.64],[2,2.74,4]],"ltp":2.7,"tv":608.38,"id":25238892},{"batl":[[0,18.5,2],[1,19,1.68],[2,19.5,2.08]],"ltp":15.5,"tv":73.15,"id":24707172}]}]}
{"op":"mcm","clk":"992003666","pt":1580511971291,"mc":[{"id":"1.168130661","rc":[{"batl":[[2,19.5,1.9]],"ltp":15.5,"tv":73.15,"id":24707172}]}]}
{"op":"mcm","clk":"992004224","pt":1580511983860,"mc":[{"id":"1.168130661","rc":[{"batl":[[2,21,14.12]],"ltp":15.5,"tv":73.15,"id":24707172}]}]}
{"op":"mcm","clk":"992018953","pt":1580512094621,"mc":[{"id":"1.168130661","rc":[{"batl":[[0,12.5,10]],"ltp":11.0,"tv":108.91,"id":24420205}]}]}
{"op":"mcm","clk":"992021190","pt":1580512148573,"mc":[{"id":"1.168130661","rc":[{"batl":[[0,2.78,7.03],[1,2.8,10.71]],"ltp":2.8,"tv":632.4,"id":26314798}]}]}
{"op":"mcm","clk":"992021240","pt":1580512149944,"mc":[{"id":"1.168130661","rc":[{"batl":[[0,2.78,3.03]],"ltp":2.8,"tv":632.4,"id":26314798}]}]}
{"op":"mcm","clk":"992021499","pt":1580512158288,"mc":[{"id":"1.168130661","rc":[{"batl":[[0,2.7,2]],"ltp":2.7,"tv":608.38,"id":25238892}]}]}
{"op":"mcm","clk":"992021552","pt":1580512159570,"mc":[{"id":"1.168130661","rc":[{"trd":[[2.7,27.37],[2.72,18.89]],"batl":[[0,2.72,1.52],[1,2.74,4],[2,2.76,31.54]],"ltp":2.72,"tv":612.61,"id":25238892}],"tv":1497.08}]}
{"op":"mcm","clk":"992021660","pt":1580512162295,"mc":[{"id":"1.168130661","rc":[{"batl":[[0,2.7,3.03],[1,2.72,1.52],[2,2.74,4]],"ltp":2.72,"tv":612.61,"id":25238892}]}]}
{"op":"mcm","clk":"992022405","pt":1580512184497,"mc":[{"id":"1.168130661","rc":[{"batb":[[0,2.58,2.09],[1,2.56,8.71],[2,2.54,14.66]],"ltp":2.72,"tv":612.61,"id":25238892}]}]}
{"op":"mcm","clk":"992024224","pt":1580512229153,"mc":[{"id":"1.168130661","rc":[{"batb":[[2,2.62,151.89]],"ltp":2.8,"tv":632.4,"id":26314798}]}]}
{"op":"mcm","clk":"992024574","pt":1580512236989,"mc":[{"id":"1.168130661","rc":[{"batb":[[2,2.64,6]],"ltp":2.8,"tv":632.4,"id":26314798}]}]}
{"op":"mcm","clk":"992027034","pt":1580512293959,"mc":[{"id":"1.168130661","rc":[{"batl":[[0,2.7,6.82]],"ltp":2.72,"tv":612.61,"id":25238892}]}]}
{"op":"mcm","clk":"992028814","pt":1580512334694,"mc":[{"id":"1.168130661","rc":[{"trd":[[2.7,40.99]],"batl":[[0,2.72,1.53],[1,2.74,4],[2,2.76,31.54]],"ltp":2.7,"tv":626.23,"id":25238892},{"trd":[[15,26.78],[15.5,32.46]],"batb":[[0,14.5,2.27],[1,12.5,2],[2,9,9.54]],"ltp":15.0,"tv":83.37,"id":24707172},{"trd":[[10,54.81]],"batb":[[0,9.6,2.08],[1,7.4,1.68],[2,7.2,11]],"ltp":10.0,"tv":115.75,"id":24420205}],"tv":1527.76}]}
{"op":"mcm","clk":"992028849","pt":1580512335519,"mc":[{"id":"1.168130661","rc":[{"trd":[[32,2.94]],"batb":[[0,29,3.45],[1,28,1.04],[2,26,2.19]],"batl":[[0,55,2.41]],"ltp":32.0,"tv":4.94,"id":25545675},{"trd":[[2.7,41.01]],"batl":[[0,2.72,1.52]],"ltp":2.7,"tv":626.25,"id":25238892},{"batl":[[0,16.5,2],[1,18.5,2],[2,19,1.68]],"ltp":15.0,"tv":83.37,"id":24707172},{"batl":[[0,2.74,3],[1,2.78,3.03]],"ltp":2.8,"tv":632.4,"id":26314798},{"batl":[[0,10.5,2.5],[1,11,4],[2,24,2]],"ltp":10.0,"tv":67.99,"id":420}],"tv":1530.72}]}
{"op":"mcm","clk":"992028905","pt":1580512336602,"mc":[{"id":"1.168130661","rc":[{"batb":[[0,29,4.27]],"ltp":32.0,"tv":4.94,"id":25545675},{"trd":[[2.72,21.93],[2.74,102.88],[2.76,133.17]],"batb":[[0,2.6,7.42],[1,2.58,11.66],[2,2.56,1.98]],"batl":[[0,2.84,6],[1,2.86,60],[2,2.88,4.49]],"ltp":2.76,"tv":700.37,"id":25238892},{"batb":[[1,13,1.9],[2,12.5,2]],"ltp":15.0,"tv":83.37,"id":24707172},{"batb":[[1,7.6,3.25],[2,7.4,1.68]],"ltp":10.0,"tv":115.75,"id":24420205},{"batb":[[0,2.72,9.08],[1,2.7,13.48],[2,2.68,3.03]],"ltp":2.8,"tv":632.4,"id":26314798},{"batb":[[0,10,4.45]],"ltp":10.0,"tv":67.99,"id":420}],"tv":1604.84}]}
{"op":"mcm","clk":"992028942","pt":1580512337479,"mc":[{"id":"1.168130661","rc":[{"batb":[[0,2.62,5.57],[1,2.6,6.62],[2,2.58,11.66]],"batl":[[0,2.82,4.44],[1,2.84,6],[2,2.86,60]],"ltp":2.76,"tv":700.37,"id":25238892},{"batl":[[1,18,1],[2,18.5,2]],"ltp":15.0,"tv":83.37,"id":24707172}]}]}
{"op":"mcm","clk":"992028968","pt":1580512338097,"mc":[{"id":"1.168130661","rc":[{"batl":[[0,55,2.21]],"ltp":32.0,"tv":4.94,"id":25545675},{"batb":[[0,13.5,2.27]],"ltp":15.0,"tv":83.37,"id":24707172}]}]}
{"op":"mcm","clk":"992029026","pt":1580512339279,"mc":[{"id":"1.168130661","rc":[{"batb":[[0,2.62,4.77]],"ltp":2.76,"tv":700.37,"id":25238892}]}]}
{"op":"mcm","clk":"992029239","pt":1580512344580,"mc":[{"id":"1.168130661","rc":[{"batb":[[0,2.64,11.26],[1,2.62,4.77],[2,2.6,6.62]],"batl":[[0,2.82,4.63]],"ltp":2.76,"tv":700.37,"id":25238892}]}]}
{"op":"mcm","clk":"992029269","pt":1580512345196,"mc":[{"id":"1.168130661","rc":[{"batb":[[1,8.4,1.56],[2,7.6,3.25]],"ltp":10.0,"tv":115.75,"id":24420205}]}]}
{"op":"mcm","clk":"992029340","pt":1580512346585,"mc":[{"id":"1.168130661","rc":[{"batb":[[0,2.66,2.03],[1,2.64,11.26],[2,2.62,4.77]],"ltp":2.76,"tv":700.37,"id":25238892},{"batl":[[0,16,2],[1,16.5,2],[2,18,1]],"ltp":15.0,"tv":83.37,"id":24707172},{"batb":[[0,8.4,9.1],[1,7.8,2.56]],"ltp":10.0,"tv":115.75,"id":24420205}]}]}
{"op":"mcm","clk":"992029922","pt":1580512361694,"mc":[{"id":"1.168130661","rc":[{"batb":[[0,2.66,6.15]],"ltp":2.76,"tv":700.37,"id":25238892},{"batb":[[0,8.4,1.56],[1,7.8,10.68]],"ltp":10.0,"tv":115.75,"id":24420205}]}]}
{"op":"mcm","clk":"992030039","pt":1580512364505,"mc":[{"id":"1.168130661","rc":[{"batb":[[0,8,1.56]],"ltp":10.0,"tv":115.75,"id":24420205}]}]}
{"op":"mcm","clk":"992030180","pt":1580512368323,"mc":[{"id":"1.168130661","rc":[{"batb":[[0,8,6.19]],"ltp":10.0,"tv":115.75,"id":24420205}]}]}
{"op":"mcm","clk":"992030366","pt":1580512372704,"mc":[{"id":"1.168130661","rc":[{"batb":[[0,8.2,1.56],[1,8,4.63],[2,7.8,10.68]],"ltp":10.0,"tv":115.75,"id":24420205}]}]}
{"op":"mcm","clk":"992030468","pt":1580512375427,"mc":[{"id":"1.168130661","rc":[{"batb":[[0,8.2,9.28],[2,7.8,2.56]],"ltp":10.0,"tv":115.75,"id":24420205}]}]}
{"op":"mcm","clk":"992030478","pt":1580512375734,"mc":[{"id":"1.168130661","rc":[{"trd":[[2.8,32.38],[2.82,62.68],[2.84,48.56],[2.86,26.62]],"batl":[[0,2.86,51.69],[1,2.88,4.49],[2,2.9,1.79]],"ltp":2.86,"tv":738.24,"id":25238892}],"tv":1642.71}]}
{"op":"mcm","clk":"992030585","pt":1580512378721,"mc":[{"id":"1.168130661","rc":[{"trd":[[2.86,102.34]],"batl":[[0,2.86,13.83]],"ltp":2.86,"tv":813.96,"id":25238892}],"tv":1718.43}]}
{"op":"mcm","clk":"992030614","pt":1580512379437,"mc":[{"id":"1.168130661","rc":[{"batl":[[0,2.86,14.03]],"ltp":2.86,"tv":813.96,"id":25238892}]}]}
{"op":"mcm","clk":"992030674","pt":1580512380522,"mc":[{"id":"1.168130661","rc":[{"batb":[[0,8.4,1.56],[1,8.2,7.72],[2,8,4.63]],"ltp":10.0,"tv":115.75,"id":24420205}]}]}
{"op":"mcm","clk":"992030887","pt":1580512385145,"mc":[{"id":"1.168130661","rc":[{"batb":[[0,2.68,6],[1,2.66,6.15],[2,2.64,11.26]],"ltp":2.86,"tv":813.96,"id":25238892}]}]}
{"op":"mcm","clk":"992031157","pt":1580512390656,"mc":[{"id":"1.168130661","rc":[{"batb":[[2,7.8,2.56]],"ltp":10.0,"tv":115.75,"id":24420205}]}]}
{"op":"mcm","clk":"992031343","pt":1580512395162,"mc":[{"id":"1.168130661","rc":[{"batb":[[0,2.7,7.1],[1,2.68,6],[2,2.66,2.03]],"ltp":2.86,"tv":813.96,"id":25238892},{"batb":[[0,8.4,3.24]],"ltp":10.0,"tv":115.75,"id":24420205}]}]}
{"op":"mcm","clk":"992031513","pt":1580512398671,"mc":[{"id":"1.168130661","rc":[{"batb":[[0,2.7,9.08]],"ltp":2.86,"tv":813.96,"id":25238892},{"batb":[[0,2.72,16.18],[1,2.7,6.38]],"ltp":2.8,"tv":632.4,"id":26314798}]}]}
{"op":"mcm","clk":"992031608","pt":1580512400936,"mc":[{"id":"1.168130661","rc":[{"batb":[[0,8.6,2.33],[1,8.4,3.24],[2,8.2,7.72]],"ltp":10.0,"tv":115.75,"id":24420205}]}]}
{"op":"mcm","clk":"992031757","pt":1580512404464,"mc":[{"id":"1.168130661","rc":[{"batb":[[0,8.6,9.69],[2,7.6,3.25]],"ltp":10.0,"tv":115.75,"id":24420205}]}]}
{"op":"mcm","clk":"992031828","pt":1580512406034,"mc":[{"id":"1.168130661","rc":[{"batl":[[0,55,2.55]],"ltp":32.0,"tv":4.94,"id":25545675},{"batb":[[0,2.72,6],[1,2.7,9.08]],"ltp":2.86,"tv":813.96,"id":25238892}]}]}
{"op":"mcm","clk":"992031957","pt":1580512408448,"mc":[{"id":"1.168130661","rc":[{"batl":[[0,2.86,13.83]],"ltp":2.86,"tv":813.96,"id":25238892}]}]}
{"op":"mcm","clk":"992033001","pt":1580512436681,"mc":[{"id":"1.168130661","rc":[{"batb":[[0,2.74,3],[1,2.72,6],[2,2.7,6.04]],"ltp":2.86,"tv":813.96,"id":25238892}]}]}
{"op":"mcm","clk":"992033029","pt":1580512437399,"mc":[{"id":"1.168130661","rc":[{"batb":[[0,2.74,4.52]],"ltp":2.86,"tv":813.96,"id":25238892},{"batb":[[0,8.8,1.68],[1,8.6,9.69],[2,8.4,1.56]],"ltp":10.0,"tv":115.75,"id":24420205}]}]}
{"op":"mcm","clk":"992033234","pt":1580512442585,"mc":[{"id":"1.168130661","rc":[{"batb":[[0,2.76,6],[1,2.74,4.52]],"ltp":2.86,"tv":813.96,"id":25238892}]}]}
{"op":"mcm","clk":"992033272","pt":1580512443460,"mc":[{"id":"1.168130661","rc":[{"batl":[[1,2.82,78.84],[2,2.84,6.79]],"ltp":2.8,"tv":632.4,"id":26314798}]}]}
{"op":"mcm","clk":"992033402","pt":1580512447701,"mc":[{"id":"1.168130661","rc":[{"batb":[[1,8.6,2.33]],"ltp":10.0,"tv":115.75,"id":24420205}]}]}
{"op":"mcm","clk":"992033480","pt":1580512449508,"mc":[{"id":"1.168130661","rc":[{"batl":[[0,2.74,6.03]],"ltp":2.8,"tv":632.4,"id":26314798}]}]}
{"op":"mcm","clk":"992034795","pt":1580512483427,"mc":[{"id":"1.168130661","rc":[{"trd":[[2.76,145.17]],"batb":[[0,2.74,4.52],[1,2.7,6.04],[2,2.66,2.03]],"batl":[[0,2.76,6.6],[1,2.86,13.83],[2,2.88,4.49]],"ltp":2.76,"tv":825.96,"id":25238892},{"batl":[[0,2.74,6.73]],"ltp":2.8,"tv":632.4,"id":26314798}],"tv":1730.43}]}
{"op":"mcm","clk":"992034969","pt":1580512487638,"mc":[{"id":"1.168130661","rc":[{"batl":[[0,2.74,6.03]],"ltp":2.8,"tv":632.4,"id":26314798}]}]}
{"op":"mcm","clk":"992035063","pt":1580512490329,"mc":[{"id":"1.168130661","rc":[{"batb":[[1,8.6,9.69]],"ltp":10.0,"tv":115.75,"id":24420205}]}]}
{"op":"mcm","clk":"992035541","pt":1580512502668,"mc":[{"id":"1.168130661","rc":[{"batb":[[0,2.72,4.52]],"ltp":2.76,"tv":825.96,"id":25238892},{"batb":[[0,8.8,3.71]],"ltp":10.0,"tv":115.75,"id":24420205}]}]}
{"op":"mcm","clk":"992035563","pt":1580512503343,"mc":[{"id":"1.168130661","rc":[{"trd":[[2.76,158.38]],"batb":[[0,2.72,5.49]],"batl":[[0,2.86,13.83],[1,2.88,4.49],[2,2.9,1.79]],"ltp":2.76,"tv":839.16,"id":25238892},{"batl":[[1,13.5,3.77]],"ltp":10.0,"tv":115.75,"id":24420205}],"tv":1743.63}]}
{"op":"mcm","clk":"992035617","pt":1580512504530,"mc":[{"id":"1.168130661","rc":[{"batb":[[0,2.72,4.52]],"ltp":2.76,"tv":839.16,"id":25238892},{"batb":[[0,8.8,10.91],[1,8.6,2.33]],"ltp":10.0,"tv":115.75,"id":24420205}]}]}
{"op":"mcm","clk":"992035818","pt":1580512508667,"mc":[{"id":"1.168130661","rc":[{"batb":[[0,9,2.22],[1,8.8,10.91]],"ltp":10.0,"tv":115.75,"id":24420205}]}]}
{"op":"mcm","clk":"992036244","pt":1580512518585,"mc":[{"id":"1.168130661","rc":[{"batb":[[1,8.8,3.71]],"ltp":10.0,"tv":115.75,"id":24420205}]}]}
{"op":"mcm","clk":"992036459","pt":1580512522564,"mc":[{"id":"1.168130661","rc":[{"batl":[[0,14.5,1.68],[1,16,2],[2,16.5,2]],"ltp":15.0,"tv":83.37,"id":24707172}]}]}
{"op":"mcm","clk":"992039260","pt":1580512590477,"mc":[{"id":"1.168130661","rc":[{"batl":[[0,2.74,3.03]],"ltp":2.8,"tv":632.4,"id":26314798}]}]}
{"op":"mcm","clk":"992041903","pt":1580512652636,"mc":[{"id":"1.168130661","rc":[{"batb":[[0,2.74,6.28],[1,2.72,4.52],[2,2.7,6.04]],"ltp":2.76,"tv":839.16,"id":25238892},{"batb":[[0,9,4.14]],"ltp":10.0,"tv":115.75,"id":24420205}]}]}
{"op":"mcm","clk":"992042324","pt":1580512662248,"mc":[{"id":"1.168130661","rc":[{"batb":[[0,9,11.17]],"ltp":10.0,"tv":115.75,"id":24420205}]}]}
{"op":"mcm","clk":"992042423","pt":1580512664362,"mc":[{"id":"1.168130661","rc":[{"batb":[[0,2.76,2.71],[1,2.74,6.28]],"ltp":2.76,"tv":839.16,"id":25238892}]}]}
{"op":"mcm","clk":"992043818","pt":1580512696206,"mc":[{"id":"1.168130661","rc":[{"batb":[[0,2.76,4.53]],"ltp":2.76,"tv":839.16,"id":25238892}]}]}
{"op":"mcm","clk":"992048028","pt":1580512802606,"mc":[{"id":"1.168130661","rc":[{"batb":[[0,2.78,6.19],[1,2.76,4.53]],"ltp":2.76,"tv":839.16,"id":25238892}]}]}
{"op":"mcm","clk":"992049503","pt":1580512836445,"mc":[{"id":"1.168130661","rc":[{"batl":[[0,50,2.87],[1,55,1.68]],"ltp":32.0,"tv":4.94,"id":25545675}]}]}
{"op":"mcm","clk":"992049514","pt":1580512836751,"mc":[{"id":"1.168130661","rc":[{"batb":[[0,30,1.39],[1,29,3.45],[2,28,1.04]],"ltp":32.0,"tv":4.94,"id":25545675}]}]}
{"op":"mcm","clk":"992050156","pt":1580512854401,"mc":[{"id":"1.168130661","rc":[{"batl":[[0,48,2.55],[1,50,2]],"ltp":32.0,"tv":4.94,"id":25545675}]}]}
{"op":"mcm","clk":"992051519","pt":1580512892013,"mc":[{"id":"1.168130661","rc":[{"batb":[[2,2.64,6]],"ltp":2.8,"tv":632.4,"id":26314798}]}]}
{"op":"mcm","clk":"992051573","pt":1580512893432,"mc":[{"id":"1.168130661","rc":[{"batb":[[0,2.74,6.28],[1,2.72,16.18]],"batl":[[0,2.82,78.84],[1,2.84,6.79],[2,2.9,11.72]],"ltp":2.8,"tv":632.4,"id":26314798}]}]}
{"op":"mcm","clk":"992051709","pt":1580512896537,"mc":[{"id":"1.168130661","rc":[{"batl":[[0,2.8,3.03],[1,2.82,78.84],[2,2.84,6.79]],"ltp":2.8,"tv":632.4,"id":26314798}]}]}
{"op":"mcm","clk":"992051729","pt":1580512897313,"mc":[{"id":"1.168130661","rc":[{"batb":[[1,29,1.27]],"ltp":32.0,"tv":4.94,"id":25545675},{"batb":[[0,9,4.14]],"ltp":10.0,"tv":115.75,"id":24420205}]}]}
{"op":"mcm","clk":"992052110","pt":1580512906223,"mc":[{"id":"1.168130661","rc":[{"trd":[[2.86,108.4]],"batl":[[0,2.86,10.8]],"ltp":2.86,"tv":845.22,"id":25238892}],"tv":1749.69}]}
{"op":"mcm","clk":"992052302","pt":1580512912543,"mc":[{"id":"1.168130661","rc":[{"batl":[[0,2.84,3.03],[1,2.86,10.8],[2,2.88,4.49]],"ltp":2.86,"tv":845.22,"id":25238892}]}]}
{"op":"mcm","clk":"992052824","pt":1580512926358,"mc":[{"id":"1.168130661","rc":[{"batb":[[0,9,11.17]],"ltp":10.0,"tv":115.75,"id":24420205}]}]}
{"op":"mcm","clk":"992053888","pt":1580512950259,"mc":[{"id":"1.168130661","rc":[{"trd":[[2.8,39.81]],"batl":[[0,2.82,78.84],[1,2.84,6.79],[2,2.9,11.72]],"ltp":2.8,"tv":638.46,"id":26314798}],"tv":1755.75}]}
{"op":"mcm","clk":"992063689","pt":1580512954381,"mc":[{"id":"1.168130661","rc":[{"batb":[[0,9,4.14]],"ltp":10.0,"tv":115.75,"id":24420205}]}]}
{"op":"mcm","clk":"992070863","pt":1580513135868,"mc":[{"id":"1.168130661","rc":[{"batl":[[1,15.5,10],[2,16,2]],"ltp":15.0,"tv":83.37,"id":24707172}]}]}
{"op":"mcm","clk":"992070985","pt":1580513139421,"mc":[{"id":"1.168130661","rc":[{"trd":[[10,35.14]],"batb":[[0,9.8,62],[1,8.4,3],[2,8,10]],"batl":[[0,10,7.55],[1,10.5,2.5],[2,11,4]],"ltp":10.0,"tv":76.89,"id":420}],"tv":1764.65}]}
{"op":"mcm","clk":"992071038","pt":1580513141382,"mc":[{"id":"1.168130661","rc":[{"batb":[[1,29,3.45]],"ltp":32.0,"tv":4.94,"id":25545675},{"batb":[[0,9,11.17]],"ltp":10.0,"tv":115.75,"id":24420205}]}]}
{"op":"mcm","clk":"992071146","pt":1580513144681,"mc":[{"id":"1.168130661","rc":[{"batb":[[0,2.82,10.71],[1,2.8,8.82],[2,2.78,6.19]],"ltp":2.86,"tv":845.22,"id":25238892},{"batb":[[0,9.2,2.68],[1,9,11.17],[2,8.8,3.71]],"ltp":10.0,"tv":115.75,"id":24420205}]}]}
{"op":"mcm","clk":"992071162","pt":1580513145197,"mc":[{"id":"1.168130661","rc":[{"trd":[[9.8,15.1]],"batb":[[0,9.8,54.45]],"batl":[[0,10.5,2.5],[1,11,4],[2,24,2]],"ltp":9.8,"tv":91.99,"id":420}],"tv":1779.75}]}
{"op":"mcm","clk":"992071512","pt":1580513155334,"mc":[{"id":"1.168130661","rc":[{"batb":[[1,29,1.27]],"ltp":32.0,"tv":4.94,"id":25545675},{"batb":[[1,9,4.14]],"ltp":10.0,"tv":115.75,"id":24420205}]}]}
{"op":"mcm","clk":"992071623","pt":1580513158438,"mc":[{"id":"1.168130661","rc":[{"batb":[[0,9.4,2.13],[1,9.2,2.68],[2,9,1.92]],"ltp":10.0,"tv":115.75,"id":24420205}]}]}
{"op":"mcm","clk":"992072081","pt":1580513170421,"mc":[{"id":"1.168130661","rc":[{"trd":[[2.84,54.62]],"batb":[[0,2.84,1.37],[1,2.82,10.71],[2,2.8,8.82]],"batl":[[0,2.86,10.8],[1,2.88,4.49],[2,2.9,1.79]],"ltp":2.84,"tv":851.29,"id":25238892}],"tv":1785.82}]}
{"op":"mcm","clk":"992072205","pt":1580513173825,"mc":[{"id":"1.168130661","rc":[{"trd":[[2.86,130],[2.88,24.11]],"batl":[[0,2.88,3.93],[1,2.9,1.79],[2,3,10]],"ltp":2.88,"tv":874.0,"id":25238892}],"tv":1808.54}]}
{"op":"mcm","clk":"992072334","pt":1580513178044,"mc":[{"id":"1.168130661","rc":[{"trd":[[2.88,31.97],[2.9,27.18]],"batb":[[0,2.84,1.71],[1,2.8,8.82],[2,2.78,6.19]],"batl":[[0,3,10],[1,3.1,20],[2,3.15,18.93]],"ltp":2.9,"tv":885.44,"id":25238892}],"tv":1819.97}]}
{"op":"mcm","clk":"992072567","pt":1580513184327,"mc":[{"id":"1.168130661","rc":[{"batl":[[0,2.98,21.25],[1,3,10],[2,3.1,20]],"ltp":2.9,"tv":885.44,"id":25238892}]}]}
{"op":"mcm","clk":"992072666","pt":1580513187165,"mc":[{"id":"1.168130661","rc":[{"batl":[[0,2.96,3.03],[1,2.98,21.25],[2,3,10]],"ltp":2.9,"tv":885.44,"id":25238892}]}]}
{"op":"mcm","clk":"992073071","pt":1580513198568,"mc":[{"id":"1.168130661","rc":[{"batl":[[0,2.96,24.42],[1,3,10],[2,3.1,20]],"ltp":2.9,"tv":885.44,"id":25238892}]}]}
{"op":"mcm","clk":"992073180","pt":1580513201669,"mc":[{"id":"1.168130661","rc":[{"batb":[[0,2.8,9.16],[1,2.78,6.19],[2,2.7,6.04]],"ltp":2.9,"tv":885.44,"id":25238892}]}]}
{"op":"mcm","clk":"992073189","pt":1580513201981,"mc":[{"id":"1.168130661","rc":[{"batb":[[0,2.82,1.71],[1,2.8,8.82],[2,2.78,6.19]],"ltp":2.9,"tv":885.44,"id":25238892}]}]}
{"op":"mcm","clk":"992073550","pt":1580513212556,"mc":[{"id":"1.168130661","rc":[{"batl":[[0,2.96,3.03],[1,2.98,21.25],[2,3,10]],"ltp":2.9,"tv":885.44,"id":25238892}]}]}
{"op":"mcm","clk":"992074214","pt":1580513227468,"mc":[{"id":"1.168130661","rc":[{"batl":[[0,2.96,24.42],[1,3,10],[2,3.1,20]],"ltp":2.9,"tv":885.44,"id":25238892}]}]}
{"op":"mcm","clk":"992074758","pt":1580513241511,"mc":[{"id":"1.168130661","rc":[{"batl":[[0,2.96,3.03],[1,2.98,21.25],[2,3,10]],"ltp":2.9,"tv":885.44,"id":25238892}]}]}
{"op":"mcm","clk":"992075290","pt":1580513255519,"mc":[{"id":"1.168130661","rc":[{"batl":[[0,2.96,24.42],[1,3,10],[2,3.1,20]],"ltp":2.9,"tv":885.44,"id":25238892}]}]}
{"op":"mcm","clk":"992075942","pt":1580513270664,"mc":[{"id":"1.168130661","rc":[{"batl":[[0,2.96,3.03]],"ltp":2.9,"tv":885.44,"id":25238892}]}]}
{"op":"mcm","clk":"992075944","pt":1580513270769,"mc":[{"id":"1.168130661","rc":[{"batl":[[1,2.98,21.25],[2,3,10]],"ltp":2.9,"tv":885.44,"id":25238892}]}]}
{"op":"mcm","clk":"992076473","pt":1580513284449,"mc":[{"id":"1.168130661","rc":[{"batl":[[0,2.96,24.42],[1,3,10],[2,3.1,20]],"ltp":2.9,"tv":885.44,"id":25238892}]}]}
{"op":"mcm","clk":"992076832","pt":1580513291365,"mc":[{"id":"1.168130661","rc":[{"batl":[[0,2.96,21.39]],"ltp":2.9,"tv":885.44,"id":25238892}]}]}
{"op":"mcm","clk":"992076875","pt":1580513292188,"mc":[{"id":"1.168130661","rc":[{"trd":[[2.96,37.84]],"batl":[[0,2.96,2.48]],"ltp":2.96,"tv":923.28,"id":25238892}],"tv":1857.82}]}
{"op":"mcm","clk":"992077048","pt":1580513295688,"mc":[{"id":"1.168130661","rc":[{"trd":[[2.96,42.8]],"batb":[[0,2.82,2.26]],"batl":[[0,3,10],[1,3.1,20],[2,3.15,18.93]],"ltp":2.96,"tv":928.24,"id":25238892}],"tv":1862.77}]}
{"op":"mcm","clk":"992077068","pt":1580513295944,"mc":[{"id":"1.168130661","rc":[{"batl":[[0,3,13.03]],"ltp":2.96,"tv":928.24,"id":25238892}]}]}
{"op":"mcm","clk":"992077184","pt":1580513298691,"mc":[{"id":"1.168130661","rc":[{"batl":[[0,2.98,21.25],[1,3,13.03],[2,3.1,20]],"ltp":2.96,"tv":928.24,"id":25238892},{"batl":[[0,12,5.28],[1,12.5,10],[2,13.5,3.77]],"ltp":10.0,"tv":115.75,"id":24420205}]}]}
{"op":"mcm","clk":"992077327","pt":1580513302551,"mc":[{"id":"1.168130661","rc":[{"batb":[[0,2.82,1.71]],"batl":[[0,2.96,2.48],[1,2.98,21.25],[2,3,10]],"ltp":2.96,"tv":928.24,"id":25238892}]}]}
{"op":"mcm","clk":"992078396","pt":1580513328692,"mc":[{"id":"1.168130661","rc":[{"batl":[[0,11.5,3.82],[1,12,5.28],[2,12.5,10]],"ltp":10.0,"tv":115.75,"id":24420205}]}]}
{"op":"mcm","clk":"992078960","pt":1580513341305,"mc":[{"id":"1.168130661","rc":[{"batl":[[1,3,10],[2,3.1,20]],"ltp":2.96,"tv":928.24,"id":25238892},{"batl":[[1,12.5,10],[2,14,2.52]],"ltp":10.0,"tv":115.75,"id":24420205}]}]}
{"op":"mcm","clk":"992079810","pt":1580513360324,"mc":[{"id":"1.168130661","rc":[{"batl":[[0,12,3.45]],"ltp":10.0,"tv":115.75,"id":24420205}]}]}
{"op":"mcm","clk":"992080294","pt":1580513372190,"mc":[{"id":"1.168130661","rc":[{"batl":[[0,3,10],[1,3.1,20],[2,3.15,18.93]],"ltp":2.96,"tv":928.24,"id":25238892}]}]}
{"op":"mcm","clk":"992080343","pt":1580513373888,"mc":[{"id":"1.168130661","rc":[{"batl":[[0,2.96,3.03],[1,3,10],[2,3.1,20]],"ltp":2.96,"tv":928.24,"id":25238892}]}]}
{"op":"mcm","clk":"992084271","pt":1580513464374,"mc":[{"id":"1.168130661","rc":[{"batb":[[0,2.82,7.82],[2,2.7,6.04]],"batl":[[0,2.94,3.03]],"ltp":2.96,"tv":928.24,"id":25238892}]}]}
{"op":"mcm","clk":"992087029","pt":1580513535625,"mc":[{"id":"1.168130661","rc":[{"trd":[[9.4,4.26]],"batb":[[0,9.2,2.68],[1,9,1.92],[2,8.8,3.71]],"batl":[[0,12,3.84]],"ltp":9.4,"tv":120.01,"id":24420205}],"tv":1867.03}]}
{"op":"mcm","clk":"992087596","pt":1580513548437,"mc":[{"id":"1.168130661","rc":[{"batl":[[0,11.5,3.61],[1,12,3.45],[2,12.5,10]],"ltp":9.4,"tv":120.01,"id":24420205}]}]}
{"op":"mcm","clk":"992089154","pt":1580513580285,"mc":[{"id":"1.168130661","rc":[{"batl":[[0,11,2.15],[1,11.5,3.23]],"ltp":9.4,"tv":120.01,"id":24420205}]}]}
{"op":"mcm","clk":"992090817","pt":1580513618629,"mc":[{"id":"1.168130661","rc":[{"batb":[[0,2.82,7.48]],"batl":[[0,2.9,2.69],[1,2.94,3.03],[2,3,10]],"ltp":2.96,"tv":928.24,"id":25238892}]}]}
{"op":"mcm","clk":"992090823","pt":1580513618730,"mc":[{"id":"1.168130661","rc":[{"batb":[[0,2.84,10.66],[1,2.82,7.48],[2,2.8,8.82]],"ltp":2.96,"tv":928.24,"id":25238892}]}]}
{"op":"mcm","clk":"992091895","pt":1580513642646,"mc":[{"id":"1.168130661","rc":[{"batl":[[0,10.5,2.39],[1,11,1.76],[2,11.5,3.23]],"ltp":9.4,"tv":120.01,"id":24420205}]}]}
{"op":"mcm","clk":"992091941","pt":1580513643569,"mc":[{"id":"1.168130661","rc":[{"batb":[[0,2.86,1.68],[1,2.84,10.66],[2,2.82,6.11]],"ltp":2.96,"tv":928.24,"id":25238892}]}]}
{"op":"mcm","clk":"992092011","pt":1580513644861,"mc":[{"id":"1.168130661","rc":[{"batl":[[2,12.5,10]],"ltp":9.4,"tv":120.01,"id":24420205}]}]}
{"op":"mcm","clk":"992093252","pt":1580513673704,"mc":[{"id":"1.168130661","rc":[{"trd":[[9.8,20.1]],"batb":[[0,9.8,51.95]],"batl":[[0,11,4],[1,24,2],[2,32,9]],"ltp":9.8,"tv":96.99,"id":420}],"tv":1872.03}]}
{"op":"mcm","clk":"992093306","pt":1580513675103,"mc":[{"id":"1.168130661","rc":[{"batb":[[0,2.86,1.36]],"ltp":2.96,"tv":928.24,"id":25238892}]}]}
{"op":"mcm","clk":"992098570","pt":1580513791663,"mc":[{"id":"1.168130661","rc":[{"batb":[[0,2.86,7.39],[2,2.8,8.82]],"ltp":2.96,"tv":928.24,"id":25238892}]}]}
{"op":"mcm","clk":"992111096","pt":1580513853008,"mc":[{"id":"1.168130661","rc":[{"trd":[[2.86,136.05]],"batb":[[0,2.86,4.36]],"ltp":2.86,"tv":934.29,"id":25238892}],"tv":1878.09}]}
{"op":"mcm","clk":"992111145","pt":1580513854603,"mc":[{"id":"1.168130661","rc":[{"trd":[[2.86,142.11]],"batb":[[0,2.86,1.33]],"ltp":2.86,"tv":940.35,"id":25238892}],"tv":1884.15}]}
{"op":"mcm","clk":"992111176","pt":1580513855421,"mc":[{"id":"1.168130661","rc":[{"batl":[[0,2.94,3.03],[1,3,10],[2,3.1,20]],"ltp":2.86,"tv":940.35,"id":25238892}]}]}
{"op":"mcm","clk":"992111208","pt":1580513856041,"mc":[{"id":"1.168130661","rc":[{"trd":[[2.88,38.03]],"ltp":2.88,"tv":946.41,"id":25238892}],"tv":1890.21}]}
{"op":"mcm","clk":"992111275","pt":1580513857535,"mc":[{"id":"1.168130661","rc":[{"trd":[[2.88,44.09]],"ltp":2.88,"tv":952.47,"id":25238892}],"tv":1896.27}]}
{"op":"mcm","clk":"992111341","pt":1580513859239,"mc":[{"id":"1.168130661","rc":[{"trd":[[2.88,50.15]],"ltp":2.88,"tv":958.53,"id":25238892}],"tv":1902.33}]}
{"op":"mcm","clk":"992111525","pt":1580513864639,"mc":[{"id":"1.168130661","rc":[{"batb":[[1,2.8,8.82],[2,2.7,6.04]],"batl":[[0,3,10],[1,3.1,20],[2,3.15,18.93]],"ltp":2.88,"tv":958.53,"id":25238892}]}]}
{"op":"mcm","clk":"992111591","pt":1580513866132,"mc":[{"id":"1.168130661","rc":[{"batl":[[0,2.98,3.03],[1,3,10],[2,3.05,3.56]],"ltp":2.88,"tv":958.53,"id":25238892}]}]}
{"op":"mcm","clk":"992111660","pt":1580513868241,"mc":[{"id":"1.168130661","rc":[{"batl":[[0,2.88,3.03],[1,2.98,3.03],[2,3,10]],"ltp":2.88,"tv":958.53,"id":25238892}]}]}
{"op":"mcm","clk":"992111711","pt":1580513869323,"mc":[{"id":"1.168130661","rc":[{"batl":[[0,2.98,3.03],[1,3,10],[2,3.05,3.56]],"ltp":2.88,"tv":958.53,"id":25238892}]}]}
{"op":"mcm","clk":"992111863","pt":1580513872662,"mc":[{"id":"1.168130661","rc":[{"batl":[[0,2.88,3.03],[1,2.98,3.03],[2,3,10]],"ltp":2.88,"tv":958.53,"id":25238892}]}]}
{"op":"mcm","clk":"992111943","pt":1580513874525,"mc":[{"id":"1.168130661","rc":[{"batl":[[1,24,2.6]],"ltp":9.8,"tv":96.99,"id":420}]}]}
{"op":"mcm","clk":"992112626","pt":1580513886265,"mc":[{"id":"1.168130661","rc":[{"trd":[[29,1.22],[30,2.78]],"batb":[[0,28,1.7],[1,26,2.19],[2,13,4.71]],"ltp":29.0,"tv":8.94,"id":25545675}],"tv":1906.33}]}
{"op":"mcm","clk":"992113706","pt":1580513911696,"mc":[{"id":"1.168130661","rc":[{"batb":[[0,28,1.04]],"ltp":29.0,"tv":8.94,"id":25545675}]}]}
{"op":"mcm","clk":"992113713","pt":1580513911748,"mc":[{"id":"1.168130661","rc":[{"batb":[[1,26,2.85]],"ltp":29.0,"tv":8.94,"id":25545675}]}]}
{"op":"mcm","clk":"992113993","pt":1580513918086,"mc":[{"id":"1.168130661","rc":[{"batb":[[0,28,1.2]],"ltp":29.0,"tv":8.94,"id":25545675}]}]}
{"op":"mcm","clk":"992114660","pt":1580513937582,"mc":[{"id":"1.168130661","rc":[{"trd":[[2.86,144.77]],"batb":[[0,2.82,10.71]],"batl":[[0,2.88,3.7]],"ltp":2.86,"tv":961.19,"id":25238892}],"tv":1908.99}]}
{"op":"mcm","clk":"992117167","pt":1580514007487,"mc":[{"id":"1.168130661","rc":[{"trd":[[2.72,25.87],[2.74,28.52]],"batb":[[0,2.72,5.24],[1,2.64,6],[2,2.62,151.89]],"batl":[[0,2.74,93.72],[1,2.82,78.84],[2,2.84,6.79]],"ltp":2.72,"tv":672.9,"id":26314798}],"tv":1943.43}]}
{"op":"mcm","clk":"992117276","pt":1580514009905,"mc":[{"id":"1.168130661","rc":[{"batb":[[0,10,1.72],[1,9.8,51.95],[2,8.4,3]],"ltp":9.8,"tv":96.99,"id":420}]}]}
{"op":"mcm","clk":"992117421","pt":1580514013605,"mc":[{"id":"1.168130661","rc":[{"batb":[[1,2.66,3],[2,2.64,6]],"ltp":2.72,"tv":672.9,"id":26314798}]}]}
{"op":"mcm","clk":"992117963","pt":1580514026318,"mc":[{"id":"1.168130661","rc":[{"batb":[[0,2.84,1.77],[1,2.82,10.71],[2,2.8,8.82]],"ltp":2.86,"tv":961.19,"id":25238892}]}]}
{"op":"mcm","clk":"992117983","pt":1580514026882,"mc":[{"id":"1.168130661","rc":[{"batb":[[0,2.82,10.71],[1,2.8,8.82],[2,2.7,6.04]],"ltp":2.86,"tv":961.19,"id":25238892}]}]}
{"op":"mcm","clk":"992118160","pt":1580514031309,"mc":[{"id":"1.168130661","rc":[{"trd":[[2.54,10.8],[2.66,15],[2.7,53.09],[2.8,50.02],[2.82,84.1]],"batb":[[0,2.54,9.26],[1,2.42,21.46],[2,2.2,115]],"ltp":2.54,"tv":1027.19,"id":25238892}],"tv":2009.43}]}
{"op":"mcm","clk":"992118190","pt":1580514032199,"mc":[{"id":"1.168130661","rc":[{"batl":[[0,2.88,3.89]],"ltp":2.54,"tv":1027.19,"id":25238892}]}]}
{"op":"mcm","clk":"992118329","pt":1580514035297,"mc":[{"id":"1.168130661","rc":[{"batb":[[0,2.54,34.19]],"ltp":2.54,"tv":1027.19,"id":25238892},{"batb":[[0,9.2,9.57]],"ltp":9.4,"tv":120.01,"id":24420205}]}]}
{"op":"mcm","clk":"992118807","pt":1580514046630,"mc":[{"id":"1.168130661","rc":[{"trd":[[2.62,45.9],[2.64,20.29],[2.66,9.96],[2.72,36.36]],"batb":[[0,2.64,11.23],[1,2.62,133.13],[2,2.6,77.18]],"ltp":2.62,"tv":738.9,"id":26314798}],"tv":2075.43}]}
{"op":"mcm","clk":"992118913","pt":1580514048533,"mc":[{"id":"1.168130661","rc":[{"batb":[[0,2.56,3],[1,2.54,34.19],[2,2.42,21.46]],"ltp":2.54,"tv":1027.19,"id":25238892},{"batl":[[0,2.7,6],[1,2.72,2.93],[2,2.74,93.72]],"ltp":2.62,"tv":738.9,"id":26314798}]}]}
{"op":"mcm","clk":"992119010","pt":1580514050640,"mc":[{"id":"1.168130661","rc":[{"batb":[[0,2.58,1.98],[1,2.56,10.57],[2,2.54,34.19]],"ltp":2.54,"tv":1027.19,"id":25238892},{"trd":[[9.4,5.04]],"batb":[[0,9.4,1.6],[1,9.2,9.57],[2,9,1.92]],"batl":[[0,10.5,2]],"ltp":9.4,"tv":120.78,"id":24420205},{"batb":[[0,2.64,14.88]],"ltp":2.62,"tv":738.9,"id":26314798},{"batb":[[0,10,3.4]],"ltp":9.8,"tv":96.99,"id":420}],"tv":2076.21}]}
{"op":"mcm","clk":"992119037","pt":1580514051523,"mc":[{"id":"1.168130661","rc":[{"batb":[[0,2.58,26.52],[2,2.54,9.26]],"ltp":2.54,"tv":1027.19,"id":25238892}]}]}
{"op":"mcm","clk":"992119205","pt":1580514055545,"mc":[{"id":"1.168130661","rc":[{"batb":[[0,2.6,7.57],[1,2.58,26.52],[2,2.56,3]],"ltp":2.54,"tv":1027.19,"id":25238892}]}]}
{"op":"mcm","clk":"992119305","pt":1580514057808,"mc":[{"id":"1.168130661","rc":[{"batb":[[0,2.62,8.53],[1,2.6,7.57],[2,2.58,26.52]],"batl":[[1,2.96,7.54],[2,2.98,3.03]],"ltp":2.54,"tv":1027.19,"id":25238892}]}]}
{"op":"mcm","clk":"992119366","pt":1580514059813,"mc":[{"id":"1.168130661","rc":[{"batb":[[0,2.62,25.19]],"ltp":2.54,"tv":1027.19,"id":25238892}]}]}
{"op":"mcm","clk":"992119541","pt":1580514065157,"mc":[{"id":"1.168130661","rc":[{"batb":[[0,28,1.57]],"ltp":29.0,"tv":8.94,"id":25545675},{"trd":[[2.84,55],[2.86,146.11]],"batb":[[0,2.86,3.05],[1,2.64,3],[2,2.62,25.19]],"batl":[[0,2.88,3.03]],"ltp":2.86,"tv":1028.91,"id":25238892},{"trd":[[14.5,1.54]],"batl":[[0,15.5,10.91],[1,16,2],[2,16.5,2]],"ltp":14.5,"tv":84.91,"id":24707172},{"trd":[[10.5,7.28]],"batl":[[0,11,1.76],[1,12.5,10],[2,14,2.52]],"ltp":10.5,"tv":124.78,"id":24420205},{"trd":[[2.7,59.06],[2.72,36.64]],"batb":[[2,2.6,75]],"batl":[[0,2.72,2.79],[1,2.74,93.72],[2,2.82,78.84]],"ltp":2.72,"tv":751.18,"id":26314798},{"batb":[[0,10.5,1.06],[1,10,3.4],[2,9.8,51.95]],"ltp":9.8,"tv":96.99,"id":420}],"tv":2095.75}]}
{"op":"mcm","clk":"992119586","pt":1580514066650,"mc":[{"id":"1.168130661","rc":[{"batb":[[0,28,1.41]],"ltp":29.0,"tv":8.94,"id":25545675}]}]}
{"op":"mcm","clk":"992119621","pt":1580514067423,"mc":[{"id":"1.168130661","rc":[{"trd":[[32,3.26]],"batl":[[0,48,2.39]],"ltp":32.0,"tv":9.26,"id":25545675},{"batb":[[1,2.64,26.98]],"ltp":2.86,"tv":1028.91,"id":25238892}],"tv":2096.07}]}
{"op":"mcm","clk":"992119697","pt":1580514069427,"mc":[{"id":"1.168130661","rc":[{"trd":[[2.64,32.29]],"batb":[[0,2.64,8.88]],"ltp":2.64,"tv":763.18,"id":26314798}],"tv":2108.07}]}
{"op":"mcm","clk":"992119838","pt":1580514073527,"mc":[{"id":"1.168130661","rc":[{"batb":[[0,9.4,3.83]],"ltp":10.5,"tv":124.78,"id":24420205}]}]}
{"op":"mcm","clk":"992120124","pt":1580514083458,"mc":[{"id":"1.168130661","rc":[{"batb":[[0,9.4,10.56],[1,9.2,2.68]],"ltp":10.5,"tv":124.78,"id":24420205}]}]}
{"op":"mcm","clk":"992120320","pt":1580514090553,"mc":[{"id":"1.168130661","rc":[{"batb":[[2,2.62,16.66]],"batl":[[1,2.98,3.03],[2,3,10]],"ltp":2.86,"tv":1028.91,"id":25238892},{"batl":[[0,15,2.97],[1,15.5,10],[2,16,2]],"ltp":14.5,"tv":84.91,"id":24707172},{"batl":[[0,12,2.94]],"ltp":10.5,"tv":124.78,"id":24420205}]}]}
{"op":"mcm","clk":"992120568","pt":1580514099366,"mc":[{"id":"1.168130661","rc":[{"batb":[[1,2.64,23.98]],"ltp":2.86,"tv":1028.91,"id":25238892},{"batb":[[0,2.64,32.87]],"ltp":2.64,"tv":763.18,"id":26314798}]}]}
{"op":"mcm","clk":"992120762","pt":1580514106261,"mc":[{"id":"1.168130661","rc":[{"batl":[[0,2.96,10.41]],"ltp":2.86,"tv":1028.91,"id":25238892}]}]}
{"op":"mcm","clk":"992120823","pt":1580514108678,"mc":[{"id":"1.168130661","rc":[{"batl":[[1,3,10],[2,3.1,20]],"ltp":2.86,"tv":1028.91,"id":25238892}]}]}
{"op":"mcm","clk":"992120953","pt":1580514112283,"mc":[{"id":"1.168130661","rc":[{"batl":[[0,2.96,13.44]],"ltp":2.86,"tv":1028.91,"id":25238892}]}]}
{"op":"mcm","clk":"992121042","pt":1580514115402,"mc":[{"id":"1.168130661","rc":[{"batb":[[0,2.64,8.88]],"ltp":2.64,"tv":763.18,"id":26314798}]}]}
{"op":"mcm","clk":"992121244","pt":1580514122611,"mc":[{"id":"1.168130661","rc":[{"batb":[[1,2.66,6.76],[2,2.64,23.98]],"batl":[[1,2.98,6.04],[2,3,10]],"ltp":2.86,"tv":1028.91,"id":25238892}]}]}
{"op":"mcm","clk":"992121415","pt":1580514127501,"mc":[{"id":"1.168130661","rc":[{"batl":[[2,16.5,2]],"ltp":14.5,"tv":84.91,"id":24707172}]}]}
{"op":"mcm","clk":"992121560","pt":1580514131533,"mc":[{"id":"1.168130661","rc":[{"batb":[[1,2.68,23.62],[2,2.66,6.76]],"ltp":2.86,"tv":1028.91,"id":25238892}]}]}
{"op":"mcm","clk":"992122278","pt":1580514154047,"mc":[{"id":"1.168130661","rc":[{"batl":[[0,2.94,4.87],[1,2.96,13.44]],"ltp":2.86,"tv":1028.91,"id":25238892}]}]}
{"op":"mcm","clk":"992123282","pt":1580514182657,"mc":[{"id":"1.168130661","rc":[{"batb":[[0,9.6,1.8],[1,9.4,10.56],[2,9.2,2.68]],"ltp":10.5,"tv":124.78,"id":24420205}]}]}
{"op":"mcm","clk":"992123542","pt":1580514189542,"mc":[{"id":"1.168130661","rc":[{"trd":[[13.5,4]],"batb":[[0,13,2.17],[1,12.5,2],[2,9,9.54]],"batl":[[2,21,14.12]],"ltp":13.5,"tv":88.91,"id":24707172}],"tv":2112.07}]}
{"op":"mcm","clk":"992123684","pt":1580514193081,"mc":[{"id":"1.168130661","rc":[{"batl":[[0,2.72,4.79]],"ltp":2.64,"tv":763.18,"id":26314798}]}]}
{"op":"mcm","clk":"992123775","pt":1580514195499,"mc":[{"id":"1.168130661","rc":[{"batb":[[0,9.6,8.39],[1,9.4,3.83]],"ltp":10.5,"tv":124.78,"id":24420205}]}]}
{"op":"mcm","clk":"992124032","pt":1580514200901,"mc":[{"id":"1.168130661","rc":[{"batl":[[0,2.94,7.9]],"ltp":2.86,"tv":1028.91,"id":25238892}]}]}
{"op":"mcm","clk":"992124441","pt":1580514210580,"mc":[{"id":"1.168130661","rc":[{"trd":[[2.64,36.29]],"batb":[[0,2.64,6.88]],"batl":[[0,2.72,2.79]],"ltp":2.64,"tv":767.18,"id":26314798}],"tv":2116.07}]}
{"op":"mcm","clk":"992125269","pt":1580514234533,"mc":[{"id":"1.168130661","rc":[{"batb":[[0,9.8,2.14],[1,9.6,8.39],[2,9.4,1.6]],"ltp":10.5,"tv":124.78,"id":24420205}]}]}
{"op":"mcm","clk":"992126381","pt":1580514268549,"mc":[{"id":"1.168130661","rc":[{"trd":[[2.86,152.17]],"batb":[[0,2.68,23.64],[1,2.66,6.76],[2,2.62,16.66]],"ltp":2.86,"tv":1034.97,"id":25238892}],"tv":2122.13}]}
{"op":"mcm","clk":"992126556","pt":1580514274400,"mc":[{"id":"1.168130661","rc":[{"batb":[[0,2.66,6.78],[1,2.62,16.66],[2,2.6,7.57]],"ltp":2.86,"tv":1034.97,"id":25238892}]}]}
{"op":"mcm","clk":"992126848","pt":1580514281599,"mc":[{"id":"1.168130661","rc":[{"batb":[[0,2.64,6.78]],"ltp":2.86,"tv":1034.97,"id":25238892}]}]}
{"op":"mcm","clk":"992127047","pt":1580514288579,"mc":[{"id":"1.168130661","rc":[{"batl":[[0,2.92,2],[1,2.94,7.9],[2,2.96,13.44]],"ltp":2.86,"tv":1034.97,"id":25238892}]}]}
{"op":"mcm","clk":"992127082","pt":1580514290322,"mc":[{"id":"1.168130661","rc":[{"batb":[[0,2.64,30.77]],"ltp":2.86,"tv":1034.97,"id":25238892}]}]}
{"op":"mcm","clk":"992127453","pt":1580514300189,"mc":[{"id":"1.168130661","rc":[{"batb":[[0,2.66,3.02],[1,2.64,30.75],[2,2.62,16.66]],"ltp":2.86,"tv":1034.97,"id":25238892}]}]}
{"op":"mcm","clk":"992127654","pt":1580514306401,"mc":[{"id":"1.168130661","rc":[{"batb":[[0,2.66,26.82],[1,2.64,6.76]],"ltp":2.86,"tv":1034.97,"id":25238892}]}]}
{"op":"mcm","clk":"992127930","pt":1580514314105,"mc":[{"id":"1.168130661","rc":[{"batb":[[0,2.68,6.68],[1,2.66,26.8]],"batl":[[0,2.9,2.48],[1,2.92,2],[2,2.94,3.03]],"ltp":2.86,"tv":1034.97,"id":25238892}]}]}
{"op":"mcm","clk":"992128172","pt":1580514322640,"mc":[{"id":"1.168130661","rc":[{"trd":[[2.86,152.21]],"batb":[[0,2.68,30.29],[1,2.66,3]],"batl":[[0,2.86,3.76],[1,2.9,2.48],[2,2.92,2]],"ltp":2.86,"tv":1035.01,"id":25238892}],"tv":2122.17}]}
{"op":"mcm","clk":"992128233","pt":1580514325922,"mc":[{"id":"1.168130661","rc":[{"batl":[[0,2.9,2.48],[1,2.92,2],[2,2.94,3.03]],"ltp":2.86,"tv":1035.01,"id":25238892}]}]}
{"op":"mcm","clk":"992128372","pt":1580514329827,"mc":[{"id":"1.168130661","rc":[{"batl":[[0,2.9,2.68]],"ltp":2.86,"tv":1035.01,"id":25238892}]}]}
{"op":"mcm","clk":"992128401","pt":1580514331163,"mc":[{"id":"1.168130661","rc":[{"batl":[[0,2.82,26.5],[1,2.9,2.68],[2,2.92,2]],"ltp":2.86,"tv":1035.01,"id":25238892}]}]}
{"op":"mcm","clk":"992128520","pt":1580514334658,"mc":[{"id":"1.168130661","rc":[{"batb":[[1,27,2],[2,26,2.19]],"ltp":32.0,"tv":9.26,"id":25545675},{"batb":[[0,2.7,13.47],[1,2.68,30.29],[2,2.66,3]],"ltp":2.86,"tv":1035.01,"id":25238892},{"batb":[[0,13,4.97]],"ltp":13.5,"tv":88.91,"id":24707172},{"batb":[[0,9.8,5.85]],"ltp":10.5,"tv":124.78,"id":24420205},{"batb":[[0,2.66,13.68],[1,2.64,6.88],[2,2.62,133.13]],"ltp":2.64,"tv":767.18,"id":26314798},{"batb":[[0,10.5,4.52]],"ltp":9.8,"tv":96.99,"id":420}]}]}
{"op":"mcm","clk":"992128534","pt":1580514335123,"mc":[{"id":"1.168130661","rc":[{"batl":[[1,2.9,2.48]],"ltp":2.86,"tv":1035.01,"id":25238892}]}]}
{"op":"mcm","clk":"992128633","pt":1580514338473,"mc":[{"id":"1.168130661","rc":[{"batb":[[0,2.72,23.28],[1,2.7,13.47],[2,2.68,6.66]],"batl":[[0,2.8,10.84],[1,2.82,26.5],[2,2.9,2.48]],"ltp":2.86,"tv":1035.01,"id":25238892},{"batb":[[0,10,6.33],[1,9.8,5.85],[2,9.6,1.8]],"ltp":10.5,"tv":124.78,"id":24420205},{"batb":[[0,10.5,10.55]],"ltp":9.8,"tv":96.99,"id":420}]}]}
{"op":"mcm","clk":"992128750","pt":1580514344138,"mc":[{"id":"1.168130661","rc":[{"batb":[[0,10,8.43],[1,9.8,3.71]],"ltp":10.5,"tv":124.78,"id":24420205}]}]}
{"op":"mcm","clk":"992128810","pt":1580514345688,"mc":[{"id":"1.168130661","rc":[{"batl":[[0,12.5,10],[1,14,2.52],[2,24,2]],"ltp":10.5,"tv":124.78,"id":24420205}]}]}
{"op":"mcm","clk":"992128835","pt":1580514346247,"mc":[{"id":"1.168130661","rc":[{"batl":[[1,13.5,3.23],[2,14,2.52]],"ltp":10.5,"tv":124.78,"id":24420205}]}]}
{"op":"mcm","clk":"992129514","pt":1580514367575,"mc":[{"id":"1.168130661","rc":[{"batl":[[0,2.8,33.56]],"ltp":2.86,"tv":1035.01,"id":25238892}]}]}
{"op":"mcm","clk":"992129580","pt":1580514369477,"mc":[{"id":"1.168130661","rc":[{"batl":[[1,2.9,2.48],[2,2.92,2]],"ltp":2.86,"tv":1035.01,"id":25238892}]}]}
{"op":"mcm","clk":"992129621","pt":1580514370608,"mc":[{"id":"1.168130661","rc":[{"batl":[[0,2.9,2.48],[1,2.92,2],[2,2.94,3.03]],"ltp":2.86,"tv":1035.01,"id":25238892}]}]}
{"op":"mcm","clk":"992129813","pt":1580514376627,"mc":[{"id":"1.168130661","rc":[{"batl":[[0,2.82,37.86],[1,2.9,2.48],[2,2.92,2]],"ltp":2.86,"tv":1035.01,"id":25238892}]}]}
{"op":"mcm","clk":"992129832","pt":1580514377301,"mc":[{"id":"1.168130661","rc":[{"batb":[[0,2.74,6.52],[1,2.72,23.28],[2,2.7,13.47]],"batl":[[0,2.8,10.84],[1,2.82,37.86],[2,2.9,2.48]],"ltp":2.86,"tv":1035.01,"id":25238892}]}]}
{"op":"mcm","clk":"992129912","pt":1580514379311,"mc":[{"id":"1.168130661","rc":[{"batl":[[0,2.8,48.7]],"ltp":2.86,"tv":1035.01,"id":25238892}]}]}
{"op":"mcm","clk":"992129956","pt":1580514380598,"mc":[{"id":"1.168130661","rc":[{"batl":[[1,2.9,2.48],[2,2.92,2]],"ltp":2.86,"tv":1035.01,"id":25238892}]}]}
{"op":"mcm","clk":"992130528","pt":1580514398211,"mc":[{"id":"1.168130661","rc":[{"batl":[[2,2.94,3.03]],"ltp":2.86,"tv":1035.01,"id":25238892}]}]}
{"op":"mcm","clk":"992130871","pt":1580514408670,"mc":[{"id":"1.168130661","rc":[{"batb":[[0,2.72,23.28],[1,2.7,13.47],[2,2.6,7.57]],"batl":[[1,2.94,3.03],[2,2.96,3.03]],"ltp":2.86,"tv":1035.01,"id":25238892}]}]}
{"op":"mcm","clk":"992131221","pt":1580514418557,"mc":[{"id":"1.168130661","rc":[{"batb":[[0,2.7,13.47],[1,2.6,7.57],[2,2.58,1.98]],"ltp":2.86,"tv":1035.01,"id":25238892}]}]}
{"op":"mcm","clk":"992131383","pt":1580514423144,"mc":[{"id":"1.168130661","rc":[{"batl":[[0,2.78,4],[1,2.8,48.7],[2,2.94,3.03]],"ltp":2.86,"tv":1035.01,"id":25238892}]}]}
{"op":"mcm","clk":"992132022","pt":1580514444684,"mc":[{"id":"1.168130661","rc":[{"batl":[[0,2.78,41.86]],"ltp":2.86,"tv":1035.01,"id":25238892}]}]}
{"op":"mcm","clk":"992132087","pt":1580514446285,"mc":[{"id":"1.168130661","rc":[{"batl":[[1,2.8,10.84]],"ltp":2.86,"tv":1035.01,"id":25238892}]}]}
{"op":"mcm","clk":"992132436","pt":1580514457607,"mc":[{"id":"1.168130661","rc":[{"batl":[[0,2.78,37.86]],"ltp":2.86,"tv":1035.01,"id":25238892}]}]}
{"op":"mcm","clk":"992132846","pt":1580514473031,"mc":[{"id":"1.168130661","rc":[{"batl":[[0,2.8,10.84],[1,2.94,3.03],[2,2.96,3.03]],"ltp":2.86,"tv":1035.01,"id":25238892}]}]}
{"op":"mcm","clk":"992132901","pt":1580514475033,"mc":[{"id":"1.168130661","rc":[{"batl":[[0,2.8,48.7]],"ltp":2.86,"tv":1035.01,"id":25238892}]}]}
{"op":"mcm","clk":"992133091","pt":1580514483012,"mc":[{"id":"1.168130661","rc":[{"batb":[[0,10.5,1.64],[1,10,8.43],[2,9.8,3.71]],"ltp":10.5,"tv":124.78,"id":24420205}]}]}
{"op":"mcm","clk":"992133270","pt":1580514490719,"mc":[{"id":"1.168130661","rc":[{"batl":[[0,2.78,4],[1,2.8,48.7],[2,2.94,3.03]],"ltp":2.86,"tv":1035.01,"id":25238892}]}]}
{"op":"mcm","clk":"992133347","pt":1580514494072,"mc":[{"id":"1.168130661","rc":[{"batl":[[0,2.78,41.86]],"ltp":2.86,"tv":1035.01,"id":25238892}]}]}
{"op":"mcm","clk":"992133389","pt":1580514495565,"mc":[{"id":"1.168130661","rc":[{"trd":[[2.78,99.72]],"batl":[[0,2.8,48.7],[1,2.94,3.03],[2,2.96,3.03]],"ltp":2.78,"tv":1118.73,"id":25238892},{"trd":[[10,71.68],[10.5,10.55]],"batb":[[0,9.8,3.71],[1,9.4,1.6],[2,9.2,2.68]],"ltp":10.0,"tv":144.93,"id":24420205},{"trd":[[10.5,26.28]],"batb":[[0,10,3.4],[1,9.8,51.95],[2,8.4,3]],"ltp":10.5,"tv":118.1,"id":420}],"tv":2247.14}]}
{"op":"mcm","clk":"992133447","pt":1580514497626,"mc":[{"id":"1.168130661","rc":[{"batb":[[0,13.5,1.55],[1,13,4.7],[2,12.5,2]],"ltp":13.5,"tv":88.91,"id":24707172},{"batb":[[0,2.68,6.43],[1,2.66,13.68],[2,2.64,3.65]],"batl":[[0,2.72,10.56]],"ltp":2.64,"tv":767.18,"id":26314798},{"batb":[[2,8,10]],"ltp":10.5,"tv":118.1,"id":420}]}]}
{"op":"mcm","clk":"992133637","pt":1580514503549,"mc":[{"id":"1.168130661","rc":[{"batb":[[1,2.62,5.26],[2,2.6,7.57]],"batl":[[1,2.92,4.72],[2,2.94,3.03]],"ltp":2.78,"tv":1118.73,"id":25238892}]}]}
{"op":"mcm","clk":"992134588","pt":1580514536386,"mc":[{"id":"1.168130661","rc":[{"batb":[[0,2.72,4.68],[1,2.7,13.47]],"ltp":2.78,"tv":1118.73,"id":25238892}]}]}
{"op":"mcm","clk":"992134780","pt":1580514542291,"mc":[{"id":"1.168130661","rc":[{"batb":[[0,2.74,4.06],[1,2.72,4.68],[2,2.7,13.47]],"ltp":2.78,"tv":1118.73,"id":25238892}]}]}
{"op":"mcm","clk":"992135336","pt":1580514560601,"mc":[{"id":"1.168130661","rc":[{"batl":[[0,12,2],[1,12.5,10],[2,13.5,3.23]],"ltp":10.0,"tv":144.93,"id":24420205}]}]}
{"op":"mcm","clk":"992135543","pt":1580514568625,"mc":[{"id":"1.168130661","rc":[{"batb":[[1,2.7,13.47],[2,2.6,7.57]],"batl":[[1,2.94,3.03],[2,2.96,3.03]],"ltp":2.78,"tv":1118.73,"id":25238892},{"batl":[[2,14,2.52]],"ltp":10.0,"tv":144.93,"id":24420205}]}]}
{"op":"mcm","clk":"992135546","pt":1580514568729,"mc":[{"id":"1.168130661","rc":[{"batl":[[0,11.5,3],[1,12,2],[2,12.5,10]],"ltp":10.0,"tv":144.93,"id":24420205}]}]}
{"op":"mcm","clk":"992135712","pt":1580514575438,"mc":[{"id":"1.168130661","rc":[{"trd":[[32,4]],"batl":[[0,48,2.02]],"ltp":32.0,"tv":10.0,"id":25545675},{"trd":[[2.8,58.48]],"batl":[[0,2.8,44.47]],"ltp":2.8,"tv":1127.19,"id":25238892},{"trd":[[14.5,3.19]],"batl":[[0,15,2.14]],"ltp":14.5,"tv":90.56,"id":24707172},{"trd":[[11.5,6]],"batl":[[0,12,2],[1,12.5,10],[2,14,2.52]],"ltp":11.5,"tv":150.93,"id":24420205},{"trd":[[2.72,39.76]],"batl":[[0,2.72,6.21]],"ltp":2.72,"tv":770.3,"id":26314798},{"batb":[[0,10.5,1.13],[1,10,3.4],[2,9.8,51.95]],"ltp":10.5,"tv":118.1,"id":420}],"tv":2267.1}]}
{"op":"mcm","clk":"992137719","pt":1580514663146,"mc":[{"id":"1.168130661","rc":[{"batb":[[0,2.76,6.24],[1,2.74,4.06],[2,2.7,13.47]],"ltp":2.8,"tv":1127.19,"id":25238892}]}]}
{"op":"mcm","clk":"992139029","pt":1580514722821,"mc":[{"id":"1.168130661","rc":[{"trd":[[44,0.68],[48,3.32]],"batl":[[0,50,2.02],[1,230,9],[2,730,4]],"ltp":48.0,"tv":14.01,"id":25545675}],"tv":2271.11}]}
{"op":"mcm","clk":"992139136","pt":1580514727502,"mc":[{"id":"1.168130661","rc":[{"batl":[[0,50,2.2]],"ltp":48.0,"tv":14.01,"id":25545675}]}]}
{"op":"mcm","clk":"992151093","pt":1580514813437,"mc":[{"id":"1.168130661","rc":[{"batb":[[0,10,1.72],[1,9.8,3.71],[2,9.4,1.6]],"ltp":11.5,"tv":150.93,"id":24420205}]}]}
{"op":"mcm","clk":"992152033","pt":1580514860588,"mc":[{"id":"1.168130661","rc":[{"batl":[[1,55,2],[2,230,9]],"ltp":48.0,"tv":14.01,"id":25545675}]}]}
{"op":"mcm","clk":"992152514","pt":1580514876319,"mc":[{"id":"1.168130661","rc":[{"batl":[[1,230,9],[2,730,4]],"ltp":48.0,"tv":14.01,"id":25545675}]}]}
{"op":"mcm","clk":"992153067","pt":1580514899527,"mc":[{"id":"1.168130661","rc":[{"batl":[[1,100,2],[2,230,9]],"ltp":48.0,"tv":14.01,"id":25545675}]}]}
{"op":"mcm","clk":"992155512","pt":1580514992752,"mc":[{"id":"1.168130661","rc":[{"batl":[[1,230,9],[2,730,4]],"ltp":48.0,"tv":14.01,"id":25545675}]}]}
{"op":"mcm","clk":"992155892","pt":1580515013771,"mc":[{"id":"1.168130661","rc":[{"batl":[[1,100,2],[2,230,9]],"ltp":48.0,"tv":14.01,"id":25545675}]}]}
{"op":"mcm","clk":"992155935","pt":1580515015983,"mc":[{"id":"1.168130661","rc":[{"batl":[[1,230,9],[2,730,4]],"ltp":48.0,"tv":14.01,"id":25545675}]}]}
{"op":"mcm","clk":"992155968","pt":1580515017373,"mc":[{"id":"1.168130661","rc":[{"batl":[[1,230,9.95]],"ltp":48.0,"tv":14.01,"id":25545675}]}]}
{"op":"mcm","clk":"992159095","pt":1580515157076,"mc":[{"id":"1.168130661","rc":[{"batl":[[0,2.7,1.77],[1,2.72,6.21],[2,2.74,93.72]],"ltp":2.72,"tv":770.3,"id":26314798}]}]}
{"op":"mcm","clk":"992159117","pt":1580515157954,"mc":[{"id":"1.168130661","rc":[{"batl":[[0,2.72,6.21],[1,2.74,93.72],[2,2.82,78.84]],"ltp":2.72,"tv":770.3,"id":26314798}]}]}
{"op":"mcm","clk":"992161075","pt":1580515227125,"mc":[{"id":"1.168130661","rc":[{"trd":[[10.5,26.7]],"batb":[[0,10,4.32],[1,9.8,51.95],[2,8,10]],"ltp":10.5,"tv":118.52,"id":420}],"tv":2271.53}]}
{"op":"mcm","clk":"992161311","pt":1580515234548,"mc":[{"id":"1.168130661","rc":[{"trd":[[2.76,161.08]],"batb":[[0,2.76,4.89]],"ltp":2.76,"tv":1129.89,"id":25238892}],"tv":2274.23}]}
{"op":"mcm","clk":"992161565","pt":1580515241283,"mc":[{"id":"1.168130661","rc":[{"trd":[[10.5,26.96]],"batb":[[0,10,4.19]],"ltp":10.5,"tv":118.77,"id":420}],"tv":2274.49}]}
{"op":"mcm","clk":"992163259","pt":1580515292610,"mc":[{"id":"1.168130661","rc":[{"batl":[[0,2.8,6.61]],"ltp":2.76,"tv":1129.89,"id":25238892}]}]}
{"op":"mcm","clk":"992163287","pt":1580515294252,"mc":[{"id":"1.168130661","rc":[{"trd":[[2.76,167.14]],"batb":[[0,2.76,1.86]],"ltp":2.76,"tv":1135.95,"id":25238892}],"tv":2280.55}]}
{"op":"mcm","clk":"992163328","pt":1580515295551,"mc":[{"id":"1.168130661","rc":[{"batl":[[0,2.8,42.5]],"ltp":2.76,"tv":1135.95,"id":25238892}]}]}
{"op":"mcm","clk":"992163383","pt":1580515297619,"mc":[{"id":"1.168130661","rc":[{"trd":[[2.76,170.85]],"batb":[[0,2.74,4.06],[1,2.7,13.47],[2,2.6,7.57]],"batl":[[0,2.76,1.17],[1,2.8,42.5],[2,2.94,3.03]],"ltp":2.76,"tv":1139.67,"id":25238892}],"tv":2284.26}]}
{"op":"mcm","clk":"992163428","pt":1580515299455,"mc":[{"id":"1.168130661","rc":[{"batl":[[0,2.8,42.5],[1,2.94,3.03],[2,2.96,3.03]],"ltp":2.76,"tv":1139.67,"id":25238892}]}]}
{"op":"mcm","clk":"992163456","pt":1580515300230,"mc":[{"id":"1.168130661","rc":[{"batb":[[0,2.76,4.24],[1,2.74,4.06],[2,2.7,13.47]],"batl":[[0,2.94,3.03],[1,2.96,3.03],[2,3,10]],"ltp":2.76,"tv":1139.67,"id":25238892}]}]}
{"op":"mcm","clk":"992163490","pt":1580515301358,"mc":[{"id":"1.168130661","rc":[{"batb":[[0,2.74,4.06],[1,2.7,13.47],[2,2.6,7.57]],"batl":[[0,2.78,6.64],[1,2.8,34.06],[2,2.94,3.03]],"ltp":2.76,"tv":1139.67,"id":25238892}]}]}
{"op":"mcm","clk":"992163533","pt":1580515302654,"mc":[{"id":"1.168130661","rc":[{"batl":[[0,2.78,1.15],[1,2.94,3.03],[2,2.96,3.03]],"ltp":2.76,"tv":1139.67,"id":25238892}]}]}
{"op":"mcm","clk":"992163544","pt":1580515303208,"mc":[{"id":"1.168130661","rc":[{"trd":[[2.78,102.02]],"batl":[[0,2.94,3.08],[1,2.96,3.03],[2,3,10]],"ltp":2.78,"tv":1141.97,"id":25238892}],"tv":2286.56}]}
{"op":"mcm","clk":"992163697","pt":1580515309633,"mc":[{"id":"1.168130661","rc":[{"batl":[[0,2.76,3.03],[1,2.94,3.08],[2,2.96,3.03]],"ltp":2.78,"tv":1141.97,"id":25238892}]}]}
{"op":"mcm","clk":"992163706","pt":1580515309841,"mc":[{"id":"1.168130661","rc":[{"batl":[[0,2.94,3.08],[1,2.96,3.03],[2,3,10]],"ltp":2.78,"tv":1141.97,"id":25238892}]}]}
{"op":"mcm","clk":"992163765","pt":1580515311429,"mc":[{"id":"1.168130661","rc":[{"batl":[[0,2.78,3.03],[1,2.94,3.08],[2,2.96,3.03]],"ltp":2.78,"tv":1141.97,"id":25238892}]}]}
{"op":"mcm","clk":"992163788","pt":1580515312472,"mc":[{"id":"1.168130661","rc":[{"batl":[[0,2.94,3.08],[1,2.96,3.03],[2,3,10]],"ltp":2.78,"tv":1141.97,"id":25238892}]}]}
{"op":"mcm","clk":"992163821","pt":1580515313551,"mc":[{"id":"1.168130661","rc":[{"batl":[[0,2.78,5.49],[1,2.8,34.06],[2,2.94,3.03]],"ltp":2.78,"tv":1141.97,"id":25238892}]}]}
{"op":"mcm","clk":"992163873","pt":1580515315057,"mc":[{"id":"1.168130661","rc":[{"batb":[[0,2.76,5.39],[1,2.74,4.06],[2,2.7,13.47]],"batl":[[0,2.94,3.03],[1,2.96,3.03],[2,3,10]],"ltp":2.78,"tv":1141.97,"id":25238892}]}]}
{"op":"mcm","clk":"992163913","pt":1580515316633,"mc":[{"id":"1.168130661","rc":[{"trd":[[2.76,176.91]],"batb":[[0,2.76,2.36]],"ltp":2.76,"tv":1148.03,"id":25238892}],"tv":2292.62}]}
{"op":"mcm","clk":"992163974","pt":1580515318230,"mc":[{"id":"1.168130661","rc":[{"batb":[[0,2.74,4.06],[1,2.7,13.47],[2,2.6,7.57]],"batl":[[0,2.8,31.08],[1,2.92,8.22],[2,2.94,40.89]],"ltp":2.76,"tv":1148.03,"id":25238892}]}]}
{"op":"mcm","clk":"992164391","pt":1580515329981,"mc":[{"id":"1.168130661","rc":[{"batb":[[2,2.58,1.98]],"ltp":2.76,"tv":1148.03,"id":25238892}]}]}
{"op":"mcm","clk":"992164560","pt":1580515334676,"mc":[{"id":"1.168130661","rc":[{"batl":[[0,2.8,68.94]],"ltp":2.76,"tv":1148.03,"id":25238892}]}]}
{"op":"mcm","clk":"992165496","pt":1580515364321,"mc":[{"id":"1.168130661","rc":[{"batl":[[0,2.78,7.44],[1,2.8,68.94],[2,2.92,8.22]],"ltp":2.76,"tv":1148.03,"id":25238892}]}]}
{"op":"mcm","clk":"992165989","pt":1580515380653,"mc":[{"id":"1.168130661","rc":[{"batl":[[1,2.8,37.86]],"ltp":2.76,"tv":1148.03,"id":25238892}]}]}
{"op":"mcm","clk":"992166256","pt":1580515388962,"mc":[{"id":"1.168130661","rc":[{"batl":[[0,2.78,30.16]],"ltp":2.76,"tv":1148.03,"id":25238892}]}]}
{"op":"mcm","clk":"992167627","pt":1580515426690,"mc":[{"id":"1.168130661","rc":[{"batl":[[0,2.78,68.02],[1,2.92,8.22],[2,2.94,40.89]],"ltp":2.76,"tv":1148.03,"id":25238892}]}]}
{"op":"mcm","clk":"992168475","pt":1580515456424,"mc":[{"id":"1.168130661","rc":[{"trd":[[2.78,238.06]],"batl":[[0,2.92,8.22],[1,2.94,40.89],[2,2.96,3.03]],"ltp":2.78,"tv":1284.07,"id":25238892},{"trd":[[10,75.12]],"batb":[[0,9.8,3.71],[1,9.4,1.6],[2,9.2,2.68]],"batl":[[0,12,2.8]],"ltp":10.0,"tv":154.37,"id":24420205}],"tv":2432.1}]}
{"op":"mcm","clk":"992168492","pt":1580515457347,"mc":[{"id":"1.168130661","rc":[{"batb":[[0,2.74,27.17]],"ltp":2.78,"tv":1284.07,"id":25238892}]}]}
{"op":"mcm","clk":"992168730","pt":1580515463509,"mc":[{"id":"1.168130661","rc":[{"batb":[[0,2.76,2.36],[1,2.74,27.17],[2,2.7,13.47]],"batl":[[0,2.94,3.03],[1,2.96,3.03],[2,3,10]],"ltp":2.78,"tv":1284.07,"id":25238892}]}]}
{"op":"mcm","clk":"992168760","pt":1580515464124,"mc":[{"id":"1.168130661","rc":[{"batl":[[0,2.92,20.68],[1,2.94,3.03],[2,2.96,3.03]],"ltp":2.78,"tv":1284.07,"id":25238892}]}]}
{"op":"mcm","clk":"992168925","pt":1580515470357,"mc":[{"id":"1.168130661","rc":[{"trd":[[2.74,142.21],[2.76,181.63]],"batb":[[0,2.74,7.51],[1,2.7,13.47],[2,2.58,1.98]],"ltp":2.74,"tv":1328.12,"id":25238892}],"tv":2476.16}]}
{"op":"mcm","clk":"992168997","pt":1580515472424,"mc":[{"id":"1.168130661","rc":[{"batl":[[0,2.94,3.03],[1,2.96,3.03],[2,3,10]],"ltp":2.74,"tv":1328.12,"id":25238892}]}]}
{"op":"mcm","clk":"992169016","pt":1580515473556,"mc":[{"id":"1.168130661","rc":[{"batb":[[0,2.7,13.47],[1,2.58,1.98],[2,2.54,9.26]],"ltp":2.74,"tv":1328.12,"id":25238892}]}]}
{"op":"mcm","clk":"992169059","pt":1580515475358,"mc":[{"id":"1.168130661","rc":[{"trd":[[2.94,0.03]],"batl":[[0,2.94,3.01]],"ltp":2.94,"tv":1328.15,"id":25238892}],"tv":2476.19}]}
{"op":"mcm","clk":"992169085","pt":1580515476337,"mc":[{"id":"1.168130661","rc":[{"batl":[[0,2.94,3.19]],"ltp":2.94,"tv":1328.15,"id":25238892}]}]}
{"op":"mcm","clk":"992169118","pt":1580515477160,"mc":[{"id":"1.168130661","rc":[{"batb":[[2,2.42,42.66]],"ltp":2.94,"tv":1328.15,"id":25238892}]}]}
{"op":"mcm","clk":"992169351","pt":1580515485360,"mc":[{"id":"1.168130661","rc":[{"batb":[[2,2.44,3.86]],"batl":[[0,2.92,3.41],[1,2.94,3.01],[2,2.96,3.03]],"ltp":2.94,"tv":1328.15,"id":25238892}]}]}
{"op":"mcm","clk":"992170521","pt":1580515523397,"mc":[{"id":"1.168130661","rc":[{"batb":[[0,29,1.06],[1,28,1.04],[2,27,2]],"ltp":48.0,"tv":14.01,"id":25545675},{"trd":[[10,76.72]],"batb":[[0,10,1.2],[1,9.8,3.71],[2,9.4,1.6]],"batl":[[0,12,2]],"ltp":10.0,"tv":155.97,"id":24420205}],"tv":2477.79}]}
{"op":"mcm","clk":"992170755","pt":1580515529978,"mc":[{"id":"1.168130661","rc":[{"batb":[[0,2.72,3.47],[1,2.7,13.47],[2,2.58,1.98]],"ltp":2.94,"tv":1328.15,"id":25238892}]}]}
{"op":"mcm","clk":"992170962","pt":1580515537611,"mc":[{"id":"1.168130661","rc":[{"batb":[[0,2.72,11.03]],"ltp":2.94,"tv":1328.15,"id":25238892}]}]}
{"op":"mcm","clk":"992171332","pt":1580515550598,"mc":[{"id":"1.168130661","rc":[{"trd":[[10,41.94],[10.5,28.54]],"batb":[[0,9.8,51.95],[1,8,10],[2,7.4,5]],"batl":[[0,10,4.81],[1,11,4],[2,24,2.6]],"ltp":10.0,"tv":127.16,"id":420}],"tv":2486.17}]}
{"op":"mcm","clk":"992171367","pt":1580515553399,"mc":[{"id":"1.168130661","rc":[{"batb":[[0,2.72,3.47]],"ltp":2.94,"tv":1328.15,"id":25238892},{"batb":[[1,8.4,3],[2,8,10]],"ltp":10.0,"tv":127.16,"id":420}]}]}
{"op":"mcm","clk":"992171825","pt":1580515569452,"mc":[{"id":"1.168130661","rc":[{"batb":[[0,2.72,11.03]],"ltp":2.94,"tv":1328.15,"id":25238892}]}]}
{"op":"mcm","clk":"992172060","pt":1580515578244,"mc":[{"id":"1.168130661","rc":[{"batl":[[0,2.9,2.18],[1,2.92,3.23],[2,2.94,3.01]],"ltp":2.94,"tv":1328.15,"id":25238892}]}]}
{"op":"mcm","clk":"992172271","pt":1580515584377,"mc":[{"id":"1.168130661","rc":[{"batb":[[0,2.72,3.47]],"ltp":2.94,"tv":1328.15,"id":25238892}]}]}
{"op":"mcm","clk":"992172732","pt":1580515597699,"mc":[{"id":"1.168130661","rc":[{"batl":[[1,2.94,3.01],[2,2.96,3.03]],"ltp":2.94,"tv":1328.15,"id":25238892}]}]}
{"op":"mcm","clk":"992172735","pt":1580515597802,"mc":[{"id":"1.168130661","rc":[{"batl":[[0,2.88,1.68],[1,2.9,2.18],[2,2.94,3.01]],"ltp":2.94,"tv":1328.15,"id":25238892}]}]}
{"op":"mcm","clk":"992172808","pt":1580515600268,"mc":[{"id":"1.168130661","rc":[{"batb":[[0,2.72,11.03]],"ltp":2.94,"tv":1328.15,"id":25238892}]}]}
{"op":"mcm","clk":"992173342","pt":1580515616389,"mc":[{"id":"1.168130661","rc":[{"batb":[[0,2.72,3.47]],"ltp":2.94,"tv":1328.15,"id":25238892}]}]}
{"op":"mcm","clk":"992174077","pt":1580515632332,"mc":[{"id":"1.168130661","rc":[{"batb":[[0,2.72,11.03]],"batl":[[0,2.86,2],[1,2.88,1.68],[2,2.94,3.19]],"ltp":2.94,"tv":1328.15,"id":25238892}]}]}
{"op":"mcm","clk":"992174924","pt":1580515648411,"mc":[{"id":"1.168130661","rc":[{"batb":[[0,2.72,3.47]],"ltp":2.94,"tv":1328.15,"id":25238892}]}]}
{"op":"mcm","clk":"992185207","pt":1580515664544,"mc":[{"id":"1.168130661","rc":[{"batb":[[0,2.72,11.03]],"ltp":2.94,"tv":1328.15,"id":25238892}]}]}
{"op":"mcm","clk":"992185289","pt":1580515667264,"mc":[{"id":"1.168130661","rc":[{"batl":[[2,3,10.18]],"ltp":2.94,"tv":1328.15,"id":25238892}]}]}
{"op":"mcm","clk":"992185711","pt":1580515680479,"mc":[{"id":"1.168130661","rc":[{"batb":[[0,2.72,3.47]],"ltp":2.94,"tv":1328.15,"id":25238892}]}]}
{"op":"mcm","clk":"992186290","pt":1580515696374,"mc":[{"id":"1.168130661","rc":[{"batb":[[0,2.72,11.03]],"ltp":2.94,"tv":1328.15,"id":25238892}]}]}
{"op":"mcm","clk":"992186868","pt":1580515712387,"mc":[{"id":"1.168130661","rc":[{"batb":[[0,2.72,3.47]],"ltp":2.94,"tv":1328.15,"id":25238892}]}]}
{"op":"mcm","clk":"992187194","pt":1580515728465,"mc":[{"id":"1.168130661","rc":[{"batb":[[0,2.72,11.03]],"ltp":2.94,"tv":1328.15,"id":25238892}]}]}
{"op":"mcm","clk":"992187513","pt":1580515744367,"mc":[{"id":"1.168130661","rc":[{"batb":[[0,2.72,3.47]],"ltp":2.94,"tv":1328.15,"id":25238892}]}]}
