{"op":"mcm","clk":"993348674","pt":1580540993437,"mc":[{"id":"1.168133543","rc":[{"batl":[[1,510,9.15]],"ltp":60.0,"tv":31.75,"id":7226819},{"batl":[[0,2.38,6],[1,2.4,2],[2,2.42,5.5]],"ltp":2.22,"tv":3022.85,"id":10107355}]}]}
{"op":"mcm","clk":"993348737","pt":1580540994519,"mc":[{"id":"1.168133543","rc":[{"batb":[[1,85,6.04],[2,75,16.64]],"ltp":190.0,"tv":20.7,"id":22308007},{"batb":[[1,55,7.4],[2,50,2.03]],"ltp":60.0,"tv":31.75,"id":7226819},{"batb":[[1,7.8,32.66],[2,7.6,3.31]],"ltp":9.8,"tv":427.59,"id":22121325},{"batb":[[0,95,3.64],[1,90,5.59],[2,80,2.37]],"ltp":95.0,"tv":13.25,"id":26548208}]}]}
{"op":"mcm","clk":"993348870","pt":1580540997552,"mc":[{"id":"1.168133543","rc":[{"batb":[[0,3.05,10.56],[1,3,5.74],[2,2.96,6]],"ltp":2.98,"tv":1565.7,"id":12636}]}]}
{"op":"mcm","clk":"993349057","pt":1580541001366,"mc":[{"id":"1.168133543","rc":[{"batb":[[2,7.6,1.98]],"ltp":9.8,"tv":427.59,"id":22121325}]}]}
{"op":"mcm","clk":"993349106","pt":1580541002553,"mc":[{"id":"1.168133543","rc":[{"trd":[[95,6.47],[100,2.6]],"batb":[[0,95,1.37],[2,80,1.87]],"ltp":95.0,"tv":17.79,"id":26548208},{"batb":[[2,110,13.66]],"ltp":580.0,"tv":6.13,"id":27606066},{"batl":[[1,440,2],[2,450,5]],"ltp":280.0,"tv":1.54,"id":24270700}],"tv":5533.44}]}
{"op":"mcm","clk":"993349123","pt":1580541002856,"mc":[{"id":"1.168133543","rc":[{"batb":[[0,95,1.79]],"ltp":95.0,"tv":17.79,"id":26548208}]}]}
{"op":"mcm","clk":"993349384","pt":1580541008685,"mc":[{"id":"1.168133543","rc":[{"batb":[[0,3.1,97.26],[1,3.05,10.56],[2,3,5.74]],"ltp":2.98,"tv":1565.7,"id":12636},{"batb":[[0,90,6.04],[1,80,1.54],[2,75,16]],"ltp":190.0,"tv":20.7,"id":22308007},{"batb":[[1,7.6,35.49],[2,7.4,21.52]],"ltp":9.8,"tv":427.59,"id":22121325}]}]}
{"op":"mcm","clk":"993349536","pt":1580541011479,"mc":[{"id":"1.168133543","rc":[{"batb":[[2,80,17.87]],"ltp":95.0,"tv":17.79,"id":26548208}]}]}
{"op":"mcm","clk":"993349649","pt":1580541013387,"mc":[{"id":"1.168133543","rc":[{"batb":[[1,80,1.04]],"ltp":190.0,"tv":20.7,"id":22308007}]}]}
{"op":"mcm","clk":"993349707","pt":1580541014569,"mc":[{"id":"1.168133543","rc":[{"batl":[[0,3.4,9.55],[1,3.5,2],[2,3.55,3.3]],"ltp":2.98,"tv":1565.7,"id":12636}]}]}
{"op":"mcm","clk":"993349752","pt":1580541015495,"mc":[{"id":"1.168133543","rc":[{"batl":[[0,160,3.03],[1,170,5],[2,200,1.72]],"ltp":190.0,"tv":20.7,"id":22308007}]}]}
{"op":"mcm","clk":"993349910","pt":1580541019502,"mc":[{"id":"1.168133543","rc":[{"batb":[[1,160,13.72],[2,150,1.32]],"ltp":580.0,"tv":6.13,"id":27606066}]}]}
{"op":"mcm","clk":"993350090","pt":1580541023468,"mc":[{"id":"1.168133543","rc":[{"batb":[[0,90,1.19]],"ltp":190.0,"tv":20.7,"id":22308007}]}]}
{"op":"mcm","clk":"993350261","pt":1580541027286,"mc":[{"id":"1.168133543","rc":[{"batb":[[2,80,18.08]],"ltp":95.0,"tv":17.79,"id":26548208}]}]}
{"op":"mcm","clk":"993350513","pt":1580541033323,"mc":[{"id":"1.168133543","rc":[{"batb":[[1,80,1.54]],"ltp":190.0,"tv":20.7,"id":22308007}]}]}
{"op":"mcm","clk":"993350672","pt":1580541037484,"mc":[{"id":"1.168133543","rc":[{"batb":[[1,85,6.04],[2,75,16.64]],"ltp":190.0,"tv":20.7,"id":22308007}]}]}
{"op":"mcm","clk":"993350705","pt":1580541038099,"mc":[{"id":"1.168133543","rc":[{"batb":[[1,160,13.82]],"ltp":580.0,"tv":6.13,"id":27606066}]}]}
{"op":"mcm","clk":"993351011","pt":1580541044231,"mc":[{"id":"1.168133543","rc":[{"batl":[[0,2.38,8],[1,2.42,5.5],[2,2.46,21]],"ltp":2.22,"tv":3022.85,"id":10107355}]}]}
{"op":"mcm","clk":"993351348","pt":1580541051540,"mc":[{"id":"1.168133543","rc":[{"batb":[[1,80,1.54],[2,75,16]],"ltp":190.0,"tv":20.7,"id":22308007}]}]}
{"op":"mcm","clk":"993351394","pt":1580541052426,"mc":[{"id":"1.168133543","rc":[{"batb":[[1,3.05,4]],"ltp":2.98,"tv":1565.7,"id":12636},{"batb":[[0,90,6.04]],"ltp":190.0,"tv":20.7,"id":22308007}]}]}
{"op":"mcm","clk":"993351442","pt":1580541053453,"mc":[{"id":"1.168133543","rc":[{"batb":[[1,80,1.04]],"ltp":190.0,"tv":20.7,"id":22308007},{"batl":[[0,2.38,6],[1,2.4,2],[2,2.42,5.5]],"ltp":2.22,"tv":3022.85,"id":10107355}]}]}
{"op":"mcm","clk":"993352048","pt":1580541066460,"mc":[{"id":"1.168133543","rc":[{"batl":[[0,3.35,3.71],[1,3.4,9.55],[2,3.5,2]],"ltp":2.98,"tv":1565.7,"id":12636}]}]}
{"op":"mcm","clk":"993352180","pt":1580541069459,"mc":[{"id":"1.168133543","rc":[{"batb":[[0,3.05,4],[1,3,5.74],[2,2.96,6]],"ltp":2.98,"tv":1565.7,"id":12636},{"batb":[[0,90,1.19]],"ltp":190.0,"tv":20.7,"id":22308007}]}]}
{"op":"mcm","clk":"993352213","pt":1580541070445,"mc":[{"id":"1.168133543","rc":[{"batl":[[0,2.38,8],[1,2.42,5.5],[2,2.46,21]],"ltp":2.22,"tv":3022.85,"id":10107355}]}]}
{"op":"mcm","clk":"993352325","pt":1580541073539,"mc":[{"id":"1.168133543","rc":[{"batb":[[1,80,1.54]],"ltp":190.0,"tv":20.7,"id":22308007}]}]}
{"op":"mcm","clk":"993352493","pt":1580541078069,"mc":[{"id":"1.168133543","rc":[{"batl":[[0,2.38,6],[1,2.4,2],[2,2.42,5.5]],"ltp":2.22,"tv":3022.85,"id":10107355}]}]}
{"op":"mcm","clk":"993352518","pt":1580541078683,"mc":[{"id":"1.168133543","rc":[{"batl":[[0,9.6,4],[1,9.8,6.85]],"ltp":9.8,"tv":427.59,"id":22121325}]}]}
{"op":"mcm","clk":"993352732","pt":1580541083461,"mc":[{"id":"1.168133543","rc":[{"batb":[[0,3.05,102.86]],"ltp":2.98,"tv":1565.7,"id":12636},{"batb":[[1,85,6.04],[2,75,16.64]],"ltp":190.0,"tv":20.7,"id":22308007},{"trd":[[2.24,285.67]],"batb":[[0,2.2,104],[1,2,46.19],[2,1.98,9.11]],"batl":[[0,2.24,1.05],[1,2.38,6],[2,2.4,2]],"ltp":2.24,"tv":3027.47,"id":10107355}],"tv":5538.06}]}
{"op":"mcm","clk":"993352815","pt":1580541085470,"mc":[{"id":"1.168133543","rc":[{"trd":[[2.22,198.72]],"batl":[[0,2.22,4],[1,2.24,1.05]],"ltp":2.22,"tv":3031.47,"id":10107355}],"tv":5542.06}]}
{"op":"mcm","clk":"993352849","pt":1580541086092,"mc":[{"id":"1.168133543","rc":[{"trd":[[2.22,206.72],[2.24,287.77]],"batb":[[0,2.2,104.95]],"batl":[[0,2.4,2],[1,2.42,5.5],[2,2.46,21]],"ltp":2.24,"tv":3041.57,"id":10107355}],"tv":5552.16}]}
{"op":"mcm","clk":"993352910","pt":1580541087382,"mc":[{"id":"1.168133543","rc":[{"batl":[[0,2.38,2]],"ltp":2.24,"tv":3041.57,"id":10107355}]}]}
{"op":"mcm","clk":"993353288","pt":1580541096272,"mc":[{"id":"1.168133543","rc":[{"batl":[[0,2.4,2]],"ltp":2.24,"tv":3041.57,"id":10107355}]}]}
{"op":"mcm","clk":"993353381","pt":1580541098496,"mc":[{"id":"1.168133543","rc":[{"batb":[[1,80,1.54],[2,75,16]],"ltp":190.0,"tv":20.7,"id":22308007}]}]}
{"op":"mcm","clk":"993353414","pt":1580541099394,"mc":[{"id":"1.168133543","rc":[{"batb":[[0,90,6.04]],"ltp":190.0,"tv":20.7,"id":22308007}]}]}
{"op":"mcm","clk":"993353716","pt":1580541106474,"mc":[{"id":"1.168133543","rc":[{"batl":[[0,2.38,2],[1,2.4,2],[2,2.42,5.5]],"ltp":2.24,"tv":3041.57,"id":10107355}]}]}
{"op":"mcm","clk":"993353954","pt":1580541112516,"mc":[{"id":"1.168133543","rc":[{"batb":[[0,90,1.19]],"ltp":190.0,"tv":20.7,"id":22308007}]}]}
{"op":"mcm","clk":"993353995","pt":1580541113494,"mc":[{"id":"1.168133543","rc":[{"batl":[[0,2.38,4],[1,2.42,5.5],[2,2.46,21]],"ltp":2.24,"tv":3041.57,"id":10107355}]}]}
{"op":"mcm","clk":"993354380","pt":1580541121521,"mc":[{"id":"1.168133543","rc":[{"batl":[[0,2.38,2],[1,2.4,2],[2,2.42,5.5]],"ltp":2.24,"tv":3041.57,"id":10107355}]}]}
{"op":"mcm","clk":"993354586","pt":1580541126462,"mc":[{"id":"1.168133543","rc":[{"batb":[[1,85,6.04],[2,75,16.64]],"ltp":190.0,"tv":20.7,"id":22308007}]}]}
{"op":"mcm","clk":"993354729","pt":1580541129344,"mc":[{"id":"1.168133543","rc":[{"batl":[[0,2.38,4],[1,2.42,5.5],[2,2.46,21]],"ltp":2.24,"tv":3041.57,"id":10107355}]}]}
{"op":"mcm","clk":"993355255","pt":1580541141547,"mc":[{"id":"1.168133543","rc":[{"batb":[[1,80,1.54],[2,75,16]],"ltp":190.0,"tv":20.7,"id":22308007}]}]}
{"op":"mcm","clk":"993355287","pt":1580541142469,"mc":[{"id":"1.168133543","rc":[{"batb":[[0,90,6.04]],"ltp":190.0,"tv":20.7,"id":22308007},{"batb":[[0,7.6,35.63],[1,7.4,21.52],[2,7,2.27]],"ltp":9.8,"tv":427.59,"id":22121325}]}]}
{"op":"mcm","clk":"993355831","pt":1580541152982,"mc":[{"id":"1.168133543","rc":[{"batb":[[1,80,1.04]],"ltp":190.0,"tv":20.7,"id":22308007},{"batb":[[0,7.8,5.82],[1,7.6,35.3],[2,7.4,21.52]],"ltp":9.8,"tv":427.59,"id":22121325}]}]}
{"op":"mcm","clk":"993355971","pt":1580541155503,"mc":[{"id":"1.168133543","rc":[{"batl":[[0,2.38,2],[1,2.4,2],[2,2.42,5.5]],"ltp":2.24,"tv":3041.57,"id":10107355}]}]}
{"op":"mcm","clk":"993356025","pt":1580541156485,"mc":[{"id":"1.168133543","rc":[{"batb":[[0,90,1.19]],"ltp":190.0,"tv":20.7,"id":22308007},{"batb":[[0,8,31.79],[1,7.8,5.69],[2,7.6,1.98]],"ltp":9.8,"tv":427.59,"id":22121325}]}]}
{"op":"mcm","clk":"993356053","pt":1580541157404,"mc":[{"id":"1.168133543","rc":[{"batl":[[0,3.35,5.71]],"ltp":2.98,"tv":1565.7,"id":12636}]}]}
{"op":"mcm","clk":"993356552","pt":1580541169516,"mc":[{"id":"1.168133543","rc":[{"batb":[[1,80,6.5]],"ltp":190.0,"tv":20.7,"id":22308007}]}]}
{"op":"mcm","clk":"993356729","pt":1580541173223,"mc":[{"id":"1.168133543","rc":[{"batb":[[1,80,7]],"ltp":190.0,"tv":20.7,"id":22308007},{"batb":[[1,7.6,2.18],[2,7.4,21.52]],"ltp":9.8,"tv":427.59,"id":22121325}]}]}
{"op":"mcm","clk":"993357145","pt":1580541181331,"mc":[{"id":"1.168133543","rc":[{"batl":[[0,2.38,4],[1,2.42,5.5],[2,2.46,21]],"ltp":2.24,"tv":3041.57,"id":10107355}]}]}
{"op":"mcm","clk":"993357257","pt":1580541183510,"mc":[{"id":"1.168133543","rc":[{"batb":[[1,85,6.04],[2,75,16.64]],"ltp":190.0,"tv":20.7,"id":22308007},{"batb":[[0,7.6,35.63],[1,7.4,21.52],[2,7,2.27]],"ltp":9.8,"tv":427.59,"id":22121325}]}]}
{"op":"mcm","clk":"993357555","pt":1580541190310,"mc":[{"id":"1.168133543","rc":[{"batl":[[0,2.38,2],[1,2.4,2],[2,2.42,5.5]],"ltp":2.24,"tv":3041.57,"id":10107355}]}]}
{"op":"mcm","clk":"993357652","pt":1580541192524,"mc":[{"id":"1.168133543","rc":[{"batb":[[0,7.8,5.82],[1,7.6,35.3],[2,7.4,21.52]],"ltp":9.8,"tv":427.59,"id":22121325}]}]}
{"op":"mcm","clk":"993357917","pt":1580541198546,"mc":[{"id":"1.168133543","rc":[{"batb":[[0,3.1,5.55],[1,3.05,102.86]],"ltp":2.98,"tv":1565.7,"id":12636},{"batb":[[0,90,6.04],[1,80,1.54],[2,75,16]],"ltp":190.0,"tv":20.7,"id":22308007},{"batb":[[0,8,31.79],[1,7.8,5.69],[2,7.6,1.98]],"ltp":9.8,"tv":427.59,"id":22121325}]}]}
{"op":"mcm","clk":"993358041","pt":1580541201529,"mc":[{"id":"1.168133543","rc":[{"batb":[[1,2,36.46]],"ltp":2.24,"tv":3041.57,"id":10107355}]}]}
{"op":"mcm","clk":"993358537","pt":1580541212531,"mc":[{"id":"1.168133543","rc":[{"batb":[[0,3.1,102.81],[1,3.05,4]],"ltp":2.98,"tv":1565.7,"id":12636},{"batb":[[0,90,1.19]],"ltp":190.0,"tv":20.7,"id":22308007}]}]}
{"op":"mcm","clk":"993358566","pt":1580541213349,"mc":[{"id":"1.168133543","rc":[{"batb":[[1,7.6,2.18],[2,7.4,21.52]],"ltp":9.8,"tv":427.59,"id":22121325}]}]}
{"op":"mcm","clk":"993359088","pt":1580541226570,"mc":[{"id":"1.168133543","rc":[{"batb":[[1,85,6.04],[2,75,16.64]],"ltp":190.0,"tv":20.7,"id":22308007},{"batb":[[0,7.6,35.63],[1,7.4,21.52],[2,7,2.27]],"ltp":9.8,"tv":427.59,"id":22121325}]}]}
{"op":"mcm","clk":"993359363","pt":1580541232347,"mc":[{"id":"1.168133543","rc":[{"batl":[[0,2.38,4],[1,2.42,5.5],[2,2.46,21]],"ltp":2.24,"tv":3041.57,"id":10107355}]}]}
{"op":"mcm","clk":"993359404","pt":1580541233271,"mc":[{"id":"1.168133543","rc":[{"batb":[[0,7.8,5.82],[1,7.6,35.3],[2,7.4,21.52]],"ltp":9.8,"tv":427.59,"id":22121325}]}]}
{"op":"mcm","clk":"993359759","pt":1580541241484,"mc":[{"id":"1.168133543","rc":[{"batb":[[1,80,1.54],[2,75,16]],"ltp":190.0,"tv":20.7,"id":22308007},{"batl":[[0,2.38,2],[1,2.4,2],[2,2.42,5.5]],"ltp":2.24,"tv":3041.57,"id":10107355},{"batb":[[1,7.6,1.98]],"ltp":9.8,"tv":427.59,"id":22121325},{"batb":[[2,130,2]],"ltp":160.0,"tv":19.01,"id":13306150}]}]}
{"op":"mcm","clk":"993359802","pt":1580541242468,"mc":[{"id":"1.168133543","rc":[{"batb":[[0,90,6.04]],"ltp":190.0,"tv":20.7,"id":22308007},{"batb":[[0,8,31.79],[1,7.8,5.69],[2,7.6,1.98]],"ltp":9.8,"tv":427.59,"id":22121325}]}]}
{"op":"mcm","clk":"993360332","pt":1580541252483,"mc":[{"id":"1.168133543","rc":[{"batb":[[1,80,1.04]],"ltp":190.0,"tv":20.7,"id":22308007},{"batb":[[1,7.6,2.18],[2,7.4,21.52]],"ltp":9.8,"tv":427.59,"id":22121325}]}]}
{"op":"mcm","clk":"993360479","pt":1580541255488,"mc":[{"id":"1.168133543","rc":[{"batb":[[0,90,1.19]],"ltp":190.0,"tv":20.7,"id":22308007},{"batb":[[0,7.6,2.31],[1,7.4,21.52],[2,7,2.27]],"ltp":9.8,"tv":427.59,"id":22121325}]}]}
{"op":"mcm","clk":"993360529","pt":1580541256573,"mc":[{"id":"1.168133543","rc":[{"batb":[[0,7.6,35.63]],"ltp":9.8,"tv":427.59,"id":22121325}]}]}
{"op":"mcm","clk":"993360624","pt":1580541258223,"mc":[{"id":"1.168133543","rc":[{"batl":[[0,2.38,4],[1,2.42,5.5],[2,2.46,21]],"ltp":2.24,"tv":3041.57,"id":10107355}]}]}
{"op":"mcm","clk":"993361068","pt":1580541266510,"mc":[{"id":"1.168133543","rc":[{"batl":[[0,2.38,2],[1,2.4,2],[2,2.42,5.5]],"ltp":2.24,"tv":3041.57,"id":10107355}]}]}
{"op":"mcm","clk":"993361183","pt":1580541269403,"mc":[{"id":"1.168133543","rc":[{"batb":[[1,80,6.5]],"ltp":190.0,"tv":20.7,"id":22308007}]}]}
{"op":"mcm","clk":"993361379","pt":1580541273520,"mc":[{"id":"1.168133543","rc":[{"batb":[[1,80,7]],"ltp":190.0,"tv":20.7,"id":22308007},{"batb":[[0,7.8,5.82],[1,7.6,35.3],[2,7.4,21.52]],"ltp":9.8,"tv":427.59,"id":22121325}]}]}
{"op":"mcm","clk":"993361456","pt":1580541274918,"mc":[{"id":"1.168133543","rc":[{"batb":[[0,3.1,106.81],[1,2.96,6],[2,2.9,1.98]],"ltp":2.98,"tv":1565.7,"id":12636}]}]}
{"op":"mcm","clk":"993361777","pt":1580541281012,"mc":[{"id":"1.168133543","rc":[{"batl":[[0,3.35,3.71]],"ltp":2.98,"tv":1565.7,"id":12636}]}]}
{"op":"mcm","clk":"993361954","pt":1580541284514,"mc":[{"id":"1.168133543","rc":[{"batb":[[0,3.1,9.55]],"ltp":2.98,"tv":1565.7,"id":12636},{"batb":[[1,80,1.54]],"ltp":190.0,"tv":20.7,"id":22308007},{"batb":[[1,7.6,1.98]],"ltp":9.8,"tv":427.59,"id":22121325}]}]}
{"op":"mcm","clk":"993361961","pt":1580541284615,"mc":[{"id":"1.168133543","rc":[{"batb":[[1,85,6.04],[2,75,16.64]],"ltp":190.0,"tv":20.7,"id":22308007},{"batb":[[0,8,31.79],[1,7.8,5.69],[2,7.6,1.98]],"ltp":9.8,"tv":427.59,"id":22121325}]}]}
{"op":"mcm","clk":"993362037","pt":1580541286111,"mc":[{"id":"1.168133543","rc":[{"batl":[[1,10,14.16],[2,10.5,12.74]],"ltp":9.8,"tv":427.59,"id":22121325}]}]}
{"op":"mcm","clk":"993362389","pt":1580541293012,"mc":[{"id":"1.168133543","rc":[{"batb":[[1,7.6,2.18],[2,7.4,21.52]],"ltp":9.8,"tv":427.59,"id":22121325}]}]}
{"op":"mcm","clk":"993362630","pt":1580541298525,"mc":[{"id":"1.168133543","rc":[{"batb":[[1,80,1.54],[2,75,16]],"ltp":190.0,"tv":20.7,"id":22308007},{"batb":[[0,7.6,2.31],[1,7.4,21.52],[2,7,2.27]],"ltp":9.8,"tv":427.59,"id":22121325}]}]}
{"op":"mcm","clk":"993362652","pt":1580541299044,"mc":[{"id":"1.168133543","rc":[{"batb":[[0,90,6.04]],"ltp":190.0,"tv":20.7,"id":22308007},{"batb":[[0,7.6,35.63]],"ltp":9.8,"tv":427.59,"id":22121325}]}]}
{"op":"mcm","clk":"993363376","pt":1580541312478,"mc":[{"id":"1.168133543","rc":[{"batb":[[0,90,1.19],[1,80,1.04]],"ltp":190.0,"tv":20.7,"id":22308007}]}]}
{"op":"mcm","clk":"993363427","pt":1580541313563,"mc":[{"id":"1.168133543","rc":[{"batb":[[0,7.8,5.82],[1,7.6,35.3],[2,7.4,21.52]],"ltp":9.8,"tv":427.59,"id":22121325}]}]}
{"op":"mcm","clk":"993363948","pt":1580541324448,"mc":[{"id":"1.168133543","rc":[{"batl":[[0,2.38,4],[1,2.42,5.5],[2,2.46,21]],"ltp":2.24,"tv":3041.57,"id":10107355}]}]}
{"op":"mcm","clk":"993363986","pt":1580541325270,"mc":[{"id":"1.168133543","rc":[{"batb":[[0,3.1,5.55],[1,2.98,4],[2,2.96,6]],"ltp":2.98,"tv":1565.7,"id":12636},{"batl":[[0,9.6,2],[1,9.8,2],[2,10,14.16]],"ltp":9.8,"tv":427.59,"id":22121325}]}]}
{"op":"mcm","clk":"993364027","pt":1580541325891,"mc":[{"id":"1.168133543","rc":[{"batb":[[1,55,21.4]],"ltp":60.0,"tv":31.75,"id":7226819}]}]}
{"op":"mcm","clk":"993364126","pt":1580541327488,"mc":[{"id":"1.168133543","rc":[{"batb":[[1,55,14.09]],"ltp":60.0,"tv":31.75,"id":7226819},{"batb":[[1,7.6,1.98]],"ltp":9.8,"tv":427.59,"id":22121325}]}]}
{"op":"mcm","clk":"993364191","pt":1580541328570,"mc":[{"id":"1.168133543","rc":[{"batb":[[1,80,6.5]],"ltp":190.0,"tv":20.7,"id":22308007},{"batb":[[0,60,8.08],[2,50,1.68]],"ltp":60.0,"tv":31.75,"id":7226819},{"trd":[[8,13.43],[9,8.08]],"batb":[[0,8.2,6.94],[1,8,24.95],[2,7.8,5.69]],"ltp":8.0,"tv":441.28,"id":22121325}],"tv":5565.86}]}
{"op":"mcm","clk":"993364341","pt":1580541331457,"mc":[{"id":"1.168133543","rc":[{"batb":[[0,8.2,7.13],[2,7.8,5.49]],"batl":[[0,9.6,2.13]],"ltp":8.0,"tv":441.28,"id":22121325}]}]}
{"op":"mcm","clk":"993364430","pt":1580541333261,"mc":[{"id":"1.168133543","rc":[{"batb":[[1,80,7]],"ltp":190.0,"tv":20.7,"id":22308007},{"batb":[[2,7.6,1.98]],"ltp":8.0,"tv":441.28,"id":22121325}]}]}
{"op":"mcm","clk":"993364494","pt":1580541334503,"mc":[{"id":"1.168133543","rc":[{"batl":[[0,2.38,2]],"ltp":2.24,"tv":3041.57,"id":10107355}]}]}
{"op":"mcm","clk":"993364500","pt":1580541334605,"mc":[{"id":"1.168133543","rc":[{"batl":[[1,2.4,2],[2,2.42,5.5]],"ltp":2.24,"tv":3041.57,"id":10107355}]}]}
{"op":"mcm","clk":"993364555","pt":1580541335799,"mc":[{"id":"1.168133543","rc":[{"batb":[[0,60,8.37]],"ltp":60.0,"tv":31.75,"id":7226819}]}]}
{"op":"mcm","clk":"993364839","pt":1580541341474,"mc":[{"id":"1.168133543","rc":[{"batb":[[1,80,1.54]],"ltp":190.0,"tv":20.7,"id":22308007},{"batb":[[0,60,1.68]],"ltp":60.0,"tv":31.75,"id":7226819},{"batb":[[1,7.6,1.98],[2,7.4,21.52]],"ltp":8.0,"tv":441.28,"id":22121325},{"batb":[[0,90,6.01],[1,80,18.08],[2,70,1.1]],"ltp":95.0,"tv":17.79,"id":26548208}]}]}
{"op":"mcm","clk":"993364909","pt":1580541342972,"mc":[{"id":"1.168133543","rc":[{"batl":[[0,2.38,4],[1,2.42,5.5],[2,2.46,21]],"ltp":2.24,"tv":3041.57,"id":10107355}]}]}
{"op":"mcm","clk":"993365274","pt":1580541351207,"mc":[{"id":"1.168133543","rc":[{"batl":[[0,2.38,2],[1,2.4,2],[2,2.42,5.5]],"ltp":2.24,"tv":3041.57,"id":10107355}]}]}
{"op":"mcm","clk":"993366648","pt":1580541375237,"mc":[{"id":"1.168133543","rc":[{"batb":[[1,3,6.67],[2,2.98,4]],"ltp":2.98,"tv":1565.7,"id":12636}]}]}
{"op":"mcm","clk":"993366753","pt":1580541377144,"mc":[{"id":"1.168133543","rc":[{"batl":[[0,2.38,4],[1,2.42,5.5],[2,2.46,21]],"ltp":2.24,"tv":3041.57,"id":10107355}]}]}
{"op":"mcm","clk":"993367139","pt":1580541385516,"mc":[{"id":"1.168133543","rc":[{"batb":[[2,2.96,6]],"ltp":2.98,"tv":1565.7,"id":12636}]}]}
{"op":"mcm","clk":"993367159","pt":1580541385931,"mc":[{"id":"1.168133543","rc":[{"batb":[[1,3.05,4],[2,3,6.67]],"ltp":2.98,"tv":1565.7,"id":12636}]}]}
{"op":"mcm","clk":"993367726","pt":1580541392153,"mc":[{"id":"1.168133543","rc":[{"batl":[[0,3.4,9.55],[1,3.5,2],[2,3.55,3.32]],"ltp":2.98,"tv":1565.7,"id":12636}]}]}
{"op":"mcm","clk":"993368782","pt":1580541410686,"mc":[{"id":"1.168133543","rc":[{"batl":[[0,2.38,2],[1,2.4,2],[2,2.42,5.5]],"ltp":2.24,"tv":3041.57,"id":10107355}]}]}
{"op":"mcm","clk":"993369647","pt":1580541423876,"mc":[{"id":"1.168133543","rc":[{"batl":[[0,3.35,3.72],[1,3.4,9.55],[2,3.5,2]],"ltp":2.98,"tv":1565.7,"id":12636}]}]}
{"op":"mcm","clk":"993369945","pt":1580541429197,"mc":[{"id":"1.168133543","rc":[{"batb":[[0,3.1,12],[2,2.96,6]],"ltp":2.98,"tv":1565.7,"id":12636}]}]}
{"op":"mcm","clk":"993371000","pt":1580541452436,"mc":[{"id":"1.168133543","rc":[{"batl":[[0,2.38,4],[1,2.42,5.5],[2,2.46,21]],"ltp":2.24,"tv":3041.57,"id":10107355}]}]}
{"op":"mcm","clk":"993371190","pt":1580541456539,"mc":[{"id":"1.168133543","rc":[{"batl":[[0,3.4,9.55],[1,3.5,2],[2,3.55,3.32]],"ltp":2.98,"tv":1565.7,"id":12636}]}]}
{"op":"mcm","clk":"993371437","pt":1580541461754,"mc":[{"id":"1.168133543","rc":[{"batb":[[1,50,1.77],[2,48,1.4]],"ltp":60.0,"tv":31.75,"id":7226819}]}]}
{"op":"mcm","clk":"993371787","pt":1580541469452,"mc":[{"id":"1.168133543","rc":[{"batb":[[0,60,1.38]],"ltp":60.0,"tv":31.75,"id":7226819}]}]}
{"op":"mcm","clk":"993372196","pt":1580541478451,"mc":[{"id":"1.168133543","rc":[{"batl":[[0,9.6,4.13],[1,10,14.16],[2,10.5,12.74]],"ltp":8.0,"tv":441.28,"id":22121325}]}]}
{"op":"mcm","clk":"993372343","pt":1580541481498,"mc":[{"id":"1.168133543","rc":[{"batb":[[0,50,2.49],[1,48,1.4],[2,46,1.08]],"ltp":60.0,"tv":31.75,"id":7226819}]}]}
{"op":"mcm","clk":"993372373","pt":1580541482043,"mc":[{"id":"1.168133543","rc":[{"batb":[[2,46,1.95]],"ltp":60.0,"tv":31.75,"id":7226819}]}]}
{"op":"mcm","clk":"993372444","pt":1580541483342,"mc":[{"id":"1.168133543","rc":[{"batb":[[0,8.4,2.24],[1,8.2,6.94],[2,7.6,1.98]],"ltp":8.0,"tv":441.28,"id":22121325}]}]}
{"op":"mcm","clk":"993372616","pt":1580541487262,"mc":[{"id":"1.168133543","rc":[{"batl":[[0,2.38,2],[1,2.4,2],[2,2.42,5.5]],"ltp":2.24,"tv":3041.57,"id":10107355}]}]}
{"op":"mcm","clk":"993372663","pt":1580541488554,"mc":[{"id":"1.168133543","rc":[{"batl":[[0,3.35,3.72],[1,3.4,9.55],[2,3.5,2]],"ltp":2.98,"tv":1565.7,"id":12636}]}]}
{"op":"mcm","clk":"993373015","pt":1580541496499,"mc":[{"id":"1.168133543","rc":[{"batl":[[0,9.6,2.13]],"ltp":8.0,"tv":441.28,"id":22121325}]}]}
{"op":"mcm","clk":"993373385","pt":1580541504380,"mc":[{"id":"1.168133543","rc":[{"batl":[[0,2.38,4],[1,2.42,5.5],[2,2.46,21]],"ltp":2.24,"tv":3041.57,"id":10107355},{"batl":[[0,9.8,2.13]],"ltp":8.0,"tv":441.28,"id":22121325}]}]}
{"op":"mcm","clk":"993373634","pt":1580541509398,"mc":[{"id":"1.168133543","rc":[{"batl":[[0,9.6,2.13],[1,9.8,2],[2,10,14.16]],"ltp":8.0,"tv":441.28,"id":22121325}]}]}
{"op":"mcm","clk":"993373776","pt":1580541512192,"mc":[{"id":"1.168133543","rc":[{"batl":[[0,2.38,2],[1,2.4,2],[2,2.42,5.5]],"ltp":2.24,"tv":3041.57,"id":10107355}]}]}
{"op":"mcm","clk":"993373803","pt":1580541512809,"mc":[{"id":"1.168133543","rc":[{"batb":[[0,3.1,16],[1,2.96,6],[2,2.9,1.98]],"ltp":2.98,"tv":1565.7,"id":12636}]}]}
{"op":"mcm","clk":"993374172","pt":1580541520526,"mc":[{"id":"1.168133543","rc":[{"batl":[[0,3.4,9.55],[1,3.5,2],[2,3.55,3.32]],"ltp":2.98,"tv":1565.7,"id":12636}]}]}
{"op":"mcm","clk":"993374661","pt":1580541530129,"mc":[{"id":"1.168133543","rc":[{"batl":[[0,2.38,4],[1,2.42,5.5],[2,2.46,21]],"ltp":2.24,"tv":3041.57,"id":10107355}]}]}
{"op":"mcm","clk":"993375485","pt":1580541547072,"mc":[{"id":"1.168133543","rc":[{"batl":[[0,2.38,2],[1,2.4,2],[2,2.42,5.5]],"ltp":2.24,"tv":3041.57,"id":10107355}]}]}
{"op":"mcm","clk":"993375762","pt":1580541552254,"mc":[{"id":"1.168133543","rc":[{"batl":[[0,3.35,3.72],[1,3.4,9.55],[2,3.5,2]],"ltp":2.98,"tv":1565.7,"id":12636}]}]}
{"op":"mcm","clk":"993375883","pt":1580541555256,"mc":[{"id":"1.168133543","rc":[{"batl":[[0,2.38,4],[1,2.42,5.5],[2,2.46,21]],"ltp":2.24,"tv":3041.57,"id":10107355}]}]}
{"op":"mcm","clk":"993376071","pt":1580541558469,"mc":[{"id":"1.168133543","rc":[{"batb":[[1,85,6.04],[2,75,16.64]],"ltp":190.0,"tv":20.7,"id":22308007}]}]}
{"op":"mcm","clk":"993376346","pt":1580541564565,"mc":[{"id":"1.168133543","rc":[{"trd":[[7.4,37.68],[7.6,4.54],[8.2,13.88],[8.4,20.65]],"batb":[[0,7,2.63],[1,6.6,47.6],[2,6.4,7.34]],"ltp":7.4,"tv":501.29,"id":22121325}],"tv":5625.86}]}
{"op":"mcm","clk":"993376388","pt":1580541565395,"mc":[{"id":"1.168133543","rc":[{"batl":[[0,9.6,2.32]],"ltp":7.4,"tv":501.29,"id":22121325}]}]}
{"op":"mcm","clk":"993376496","pt":1580541567573,"mc":[{"id":"1.168133543","rc":[{"batl":[[0,9.6,2.58]],"ltp":7.4,"tv":501.29,"id":22121325}]}]}
{"op":"mcm","clk":"993376498","pt":1580541567675,"mc":[{"id":"1.168133543","rc":[{"batl":[[0,9.6,2.75]],"ltp":7.4,"tv":501.29,"id":22121325}]}]}
{"op":"mcm","clk":"993376626","pt":1580541570395,"mc":[{"id":"1.168133543","rc":[{"batl":[[0,9.4,5.18],[1,9.6,2.13],[2,9.8,2]],"ltp":7.4,"tv":501.29,"id":22121325}]}]}
{"op":"mcm","clk":"993376663","pt":1580541571198,"mc":[{"id":"1.168133543","rc":[{"batb":[[0,7,2.27]],"ltp":7.4,"tv":501.29,"id":22121325}]}]}
{"op":"mcm","clk":"993376719","pt":1580541572502,"mc":[{"id":"1.168133543","rc":[{"batb":[[1,80,1.54],[2,75,16]],"ltp":190.0,"tv":20.7,"id":22308007},{"batb":[[1,6.6,9.6]],"ltp":7.4,"tv":501.29,"id":22121325}]}]}
{"op":"mcm","clk":"993376736","pt":1580541572812,"mc":[{"id":"1.168133543","rc":[{"batb":[[0,90,6.04]],"ltp":190.0,"tv":20.7,"id":22308007},{"batb":[[0,50,10.53]],"ltp":60.0,"tv":31.75,"id":7226819},{"batl":[[0,2.38,2],[1,2.4,2],[2,2.42,5.5]],"ltp":2.24,"tv":3041.57,"id":10107355},{"batb":[[1,6.8,29.77],[2,6.6,9.18]],"ltp":7.4,"tv":501.29,"id":22121325},{"batb":[[0,95,1.79],[1,90,5.59],[2,80,18.08]],"ltp":95.0,"tv":17.79,"id":26548208}]}]}
{"op":"mcm","clk":"993376769","pt":1580541573591,"mc":[{"id":"1.168133543","rc":[{"batb":[[0,7.2,2.21],[1,7,2.27],[2,6.8,29.77]],"batl":[[0,9.2,1.92],[1,9.4,4.99],[2,9.6,2.13]],"ltp":7.4,"tv":501.29,"id":22121325}]}]}
{"op":"mcm","clk":"993376997","pt":1580541578412,"mc":[{"id":"1.168133543","rc":[{"batl":[[0,9.2,2.18],[1,9.4,4.73]],"ltp":7.4,"tv":501.29,"id":22121325}]}]}
{"op":"mcm","clk":"993377279","pt":1580541584003,"mc":[{"id":"1.168133543","rc":[{"batl":[[0,3.4,9.55],[1,3.5,2],[2,3.55,3.32]],"ltp":2.98,"tv":1565.7,"id":12636},{"batb":[[0,50,10.88]],"ltp":60.0,"tv":31.75,"id":7226819}]}]}
{"op":"mcm","clk":"993377404","pt":1580541586497,"mc":[{"id":"1.168133543","rc":[{"batb":[[0,90,1.19]],"ltp":190.0,"tv":20.7,"id":22308007},{"batb":[[2,6.6,9.6]],"ltp":7.4,"tv":501.29,"id":22121325}]}]}
{"op":"mcm","clk":"993377460","pt":1580541587523,"mc":[{"id":"1.168133543","rc":[{"batb":[[0,3.15,95.71],[1,3.1,16],[2,2.96,6]],"batl":[[0,3.5,2],[1,3.55,3.32],[2,3.6,2]],"ltp":2.98,"tv":1565.7,"id":12636},{"batb":[[1,7,30.78]],"ltp":7.4,"tv":501.29,"id":22121325}]}]}
{"op":"mcm","clk":"993377557","pt":1580541589291,"mc":[{"id":"1.168133543","rc":[{"batl":[[0,2.38,4],[1,2.42,5.5],[2,2.46,21]],"ltp":2.24,"tv":3041.57,"id":10107355}]}]}
{"op":"mcm","clk":"993377608","pt":1580541590114,"mc":[{"id":"1.168133543","rc":[{"batb":[[0,3.2,6.25],[1,3.15,95.71],[2,3.1,9.55]],"batl":[[0,3.45,2],[1,3.5,2],[2,3.55,3.32]],"ltp":2.98,"tv":1565.7,"id":12636},{"batl":[[1,9.6,2.3],[2,9.8,2]],"ltp":7.4,"tv":501.29,"id":22121325}]}]}
{"op":"mcm","clk":"993377674","pt":1580541591522,"mc":[{"id":"1.168133543","rc":[{"batb":[[0,3.2,10.25]],"ltp":2.98,"tv":1565.7,"id":12636},{"trd":[[50,9.91],[55,6.28],[65,2.09],[75,0.4]],"batb":[[0,50,7.88]],"ltp":50.0,"tv":37.75,"id":7226819}],"tv":5631.86}]}
{"op":"mcm","clk":"993377711","pt":1580541592292,"mc":[{"id":"1.168133543","rc":[{"batb":[[0,3.2,12.25]],"ltp":2.98,"tv":1565.7,"id":12636},{"batb":[[0,50,7.53]],"ltp":50.0,"tv":37.75,"id":7226819}]}]}
{"op":"mcm","clk":"993377963","pt":1580541597896,"mc":[{"id":"1.168133543","rc":[{"batl":[[0,2.38,2],[1,2.4,2],[2,2.42,5.5]],"ltp":2.24,"tv":3041.57,"id":10107355}]}]}
{"op":"mcm","clk":"993378011","pt":1580541598925,"mc":[{"id":"1.168133543","rc":[{"batb":[[2,46,2.33]],"ltp":50.0,"tv":37.75,"id":7226819}]}]}
{"op":"mcm","clk":"993378209","pt":1580541602531,"mc":[{"id":"1.168133543","rc":[{"batb":[[1,3.1,9.55],[2,3,8.63]],"ltp":2.98,"tv":1565.7,"id":12636},{"batb":[[0,48,2.12],[1,46,1.47],[2,42,1.86]],"ltp":50.0,"tv":37.75,"id":7226819},{"batb":[[1,7,2.27]],"ltp":7.4,"tv":501.29,"id":22121325},{"batb":[[0,90,6.01],[1,80,18.08],[2,70,1.1]],"ltp":95.0,"tv":17.79,"id":26548208}]}]}
{"op":"mcm","clk":"993378524","pt":1580541608247,"mc":[{"id":"1.168133543","rc":[{"batb":[[1,46,1.08]],"ltp":50.0,"tv":37.75,"id":7226819}]}]}
{"op":"mcm","clk":"993378853","pt":1580541614547,"mc":[{"id":"1.168133543","rc":[{"batl":[[0,2.38,4],[1,2.42,5.5],[2,2.46,21]],"ltp":2.24,"tv":3041.57,"id":10107355}]}]}
{"op":"mcm","clk":"993378896","pt":1580541615567,"mc":[{"id":"1.168133543","rc":[{"batb":[[0,3.25,92.77],[1,3.2,12.25],[2,3.1,9.55]],"ltp":2.98,"tv":1565.7,"id":12636},{"batb":[[1,85,6.04],[2,75,16.64]],"ltp":190.0,"tv":20.7,"id":22308007},{"batb":[[1,7,30.78]],"ltp":7.4,"tv":501.29,"id":22121325},{"batb":[[0,95,1.79],[1,90,5.59],[2,80,18.08]],"ltp":95.0,"tv":17.79,"id":26548208}]}]}
{"op":"mcm","clk":"993378952","pt":1580541616567,"mc":[{"id":"1.168133543","rc":[{"trd":[[3.25,4]],"batb":[[0,3.25,90.78]],"batl":[[0,3.45,5.03],[2,3.6,2]],"ltp":3.25,"tv":1569.7,"id":12636},{"batb":[[2,42,2.28]],"ltp":50.0,"tv":37.75,"id":7226819}],"tv":5635.86}]}
{"op":"mcm","clk":"993379059","pt":1580541618470,"mc":[{"id":"1.168133543","rc":[{"batl":[[0,95,5.35]],"ltp":50.0,"tv":37.75,"id":7226819}]}]}
{"op":"mcm","clk":"993379668","pt":1580541630479,"mc":[{"id":"1.168133543","rc":[{"batb":[[0,3.2,12.25],[1,3.1,9.55],[2,3,8.63]],"ltp":3.25,"tv":1569.7,"id":12636},{"batb":[[0,90,6.04],[1,80,1.04],[2,75,16]],"ltp":190.0,"tv":20.7,"id":22308007}]}]}
{"op":"mcm","clk":"993379776","pt":1580541632391,"mc":[{"id":"1.168133543","rc":[{"batl":[[0,2.38,2],[1,2.4,2],[2,2.42,5.5]],"ltp":2.24,"tv":3041.57,"id":10107355}]}]}
{"op":"mcm","clk":"993380131","pt":1580541640322,"mc":[{"id":"1.168133543","rc":[{"batl":[[0,2.38,4],[1,2.42,5.5],[2,2.46,21]],"ltp":2.24,"tv":3041.57,"id":10107355}]}]}
{"op":"mcm","clk":"993380339","pt":1580541644398,"mc":[{"id":"1.168133543","rc":[{"batb":[[0,3.2,6],[1,3.15,6.35],[2,3.1,9.55]],"batl":[[0,3.45,3.03]],"ltp":3.25,"tv":1569.7,"id":12636}]}]}
{"op":"mcm","clk":"993380372","pt":1580541645110,"mc":[{"id":"1.168133543","rc":[{"batb":[[0,90,1.19]],"ltp":190.0,"tv":20.7,"id":22308007}]}]}
{"op":"mcm","clk":"993380500","pt":1580541647995,"mc":[{"id":"1.168133543","rc":[{"batl":[[0,3.5,2],[1,3.55,3.03]],"ltp":3.25,"tv":1569.7,"id":12636}]}]}
{"op":"mcm","clk":"993380643","pt":1580541650415,"mc":[{"id":"1.168133543","rc":[{"batb":[[1,80,1.54]],"ltp":190.0,"tv":20.7,"id":22308007}]}]}
{"op":"mcm","clk":"993380978","pt":1580541657731,"mc":[{"id":"1.168133543","rc":[{"batl":[[0,2.38,2],[1,2.4,2],[2,2.42,5.5]],"ltp":2.24,"tv":3041.57,"id":10107355}]}]}
{"op":"mcm","clk":"993381012","pt":1580541658611,"mc":[{"id":"1.168133543","rc":[{"batb":[[1,7,2.27]],"ltp":7.4,"tv":501.29,"id":22121325},{"batb":[[0,90,6.01],[1,80,18.08],[2,70,1.1]],"ltp":95.0,"tv":17.79,"id":26548208}]}]}
{"op":"mcm","clk":"993381175","pt":1580541662521,"mc":[{"id":"1.168133543","rc":[{"batb":[[0,48,1.4]],"ltp":50.0,"tv":37.75,"id":7226819}]}]}
{"op":"mcm","clk":"993381223","pt":1580541663501,"mc":[{"id":"1.168133543","rc":[{"batb":[[2,42,3.22]],"ltp":50.0,"tv":37.75,"id":7226819}]}]}
{"op":"mcm","clk":"993381317","pt":1580541665920,"mc":[{"id":"1.168133543","rc":[{"batl":[[0,2.38,4],[1,2.42,5.5],[2,2.46,21]],"ltp":2.24,"tv":3041.57,"id":10107355}]}]}
{"op":"mcm","clk":"993381593","pt":1580541672545,"mc":[{"id":"1.168133543","rc":[{"batb":[[2,44,9.22]],"ltp":50.0,"tv":37.75,"id":7226819}]}]}
{"op":"mcm","clk":"993381884","pt":1580541679965,"mc":[{"id":"1.168133543","rc":[{"batl":[[1,3.6,2],[2,3.75,3.26]],"ltp":3.25,"tv":1569.7,"id":12636}]}]}
{"op":"mcm","clk":"993382024","pt":1580541683258,"mc":[{"id":"1.168133543","rc":[{"batl":[[0,2.38,2],[1,2.4,2],[2,2.42,5.5]],"ltp":2.24,"tv":3041.57,"id":10107355}]}]}
{"op":"mcm","clk":"993382221","pt":1580541687532,"mc":[{"id":"1.168133543","rc":[{"batb":[[2,42,2.8]],"ltp":50.0,"tv":37.75,"id":7226819}]}]}
{"op":"mcm","clk":"993382511","pt":1580541693274,"mc":[{"id":"1.168133543","rc":[{"batl":[[2,3.7,4]],"ltp":3.25,"tv":1569.7,"id":12636}]}]}
{"op":"mcm","clk":"993382601","pt":1580541695333,"mc":[{"id":"1.168133543","rc":[{"batb":[[2,42,3.22]],"ltp":50.0,"tv":37.75,"id":7226819}]}]}
{"op":"mcm","clk":"993382833","pt":1580541700177,"mc":[{"id":"1.168133543","rc":[{"batl":[[0,2.38,4],[1,2.42,5.5],[2,2.46,21]],"ltp":2.24,"tv":3041.57,"id":10107355}]}]}
{"op":"mcm","clk":"993383446","pt":1580541712496,"mc":[{"id":"1.168133543","rc":[{"batl":[[1,3.55,3.03],[2,3.6,2]],"ltp":3.25,"tv":1569.7,"id":12636}]}]}
{"op":"mcm","clk":"993383615","pt":1580541715457,"mc":[{"id":"1.168133543","rc":[{"batb":[[2,44,9.22]],"ltp":50.0,"tv":37.75,"id":7226819}]}]}
{"op":"mcm","clk":"993384048","pt":1580541722496,"mc":[{"id":"1.168133543","rc":[{"batb":[[1,46,1.95]],"ltp":50.0,"tv":37.75,"id":7226819}]}]}
{"op":"mcm","clk":"993384364","pt":1580541727517,"mc":[{"id":"1.168133543","rc":[{"batb":[[1,46,2.33]],"ltp":50.0,"tv":37.75,"id":7226819}]}]}
{"op":"mcm","clk":"993384472","pt":1580541729282,"mc":[{"id":"1.168133543","rc":[{"batl":[[2,14,1]],"ltp":9.8,"tv":408.58,"id":10163711}]}]}
{"op":"mcm","clk":"993384550","pt":1580541730681,"mc":[{"id":"1.168133543","rc":[{"batb":[[0,48,9.24],[2,42,1.86]],"ltp":50.0,"tv":37.75,"id":7226819}]}]}
{"op":"mcm","clk":"993385140","pt":1580541742336,"mc":[{"id":"1.168133543","rc":[{"batl":[[0,2.38,2],[1,2.4,2],[2,2.42,5.5]],"ltp":2.24,"tv":3041.57,"id":10107355}]}]}
{"op":"mcm","clk":"993385225","pt":1580541744512,"mc":[{"id":"1.168133543","rc":[{"batb":[[0,48,1.4]],"ltp":50.0,"tv":37.75,"id":7226819}]}]}
{"op":"mcm","clk":"993385271","pt":1580541745541,"mc":[{"id":"1.168133543","rc":[{"batl":[[1,3.6,2],[2,3.65,3.03]],"ltp":3.25,"tv":1569.7,"id":12636}]}]}
{"op":"mcm","clk":"993385397","pt":1580541747843,"mc":[{"id":"1.168133543","rc":[{"batl":[[1,3.6,6]],"ltp":3.25,"tv":1569.7,"id":12636}]}]}
{"op":"mcm","clk":"993385525","pt":1580541750323,"mc":[{"id":"1.168133543","rc":[{"batb":[[1,46,1.95]],"ltp":50.0,"tv":37.75,"id":7226819}]}]}
{"op":"mcm","clk":"993395610","pt":1580541756566,"mc":[{"id":"1.168133543","rc":[{"batb":[[0,3.25,5.3],[1,3.2,6],[2,3.15,6.35]],"ltp":3.25,"tv":1569.7,"id":12636}]}]}
{"op":"mcm","clk":"993395675","pt":1580541757751,"mc":[{"id":"1.168133543","rc":[{"batb":[[2,42,2.28]],"ltp":50.0,"tv":37.75,"id":7226819}]}]}
{"op":"mcm","clk":"993395782","pt":1580541759552,"mc":[{"id":"1.168133543","rc":[{"batl":[[0,2.38,4],[1,2.42,5.5],[2,2.46,21]],"ltp":2.24,"tv":3041.57,"id":10107355}]}]}
{"op":"mcm","clk":"993396175","pt":1580541767844,"mc":[{"id":"1.168133543","rc":[{"batb":[[0,3.25,9.3]],"ltp":3.25,"tv":1569.7,"id":12636}]}]}
{"op":"mcm","clk":"993396797","pt":1580541779489,"mc":[{"id":"1.168133543","rc":[{"batl":[[1,3.55,3.03],[2,3.6,6]],"ltp":3.25,"tv":1569.7,"id":12636}]}]}
{"op":"mcm","clk":"993396948","pt":1580541782490,"mc":[{"id":"1.168133543","rc":[{"batb":[[1,46,1.08],[2,42,3.22]],"ltp":50.0,"tv":37.75,"id":7226819}]}]}
{"op":"mcm","clk":"993397143","pt":1580541785485,"mc":[{"id":"1.168133543","rc":[{"batl":[[0,2.38,2],[1,2.4,2],[2,2.42,5.5]],"ltp":2.24,"tv":3041.57,"id":10107355}]}]}
{"op":"mcm","clk":"993397562","pt":1580541793485,"mc":[{"id":"1.168133543","rc":[{"batl":[[0,2.38,4],[1,2.42,5.5],[2,2.46,21]],"ltp":2.24,"tv":3041.57,"id":10107355}]}]}
{"op":"mcm","clk":"993398025","pt":1580541802285,"mc":[{"id":"1.168133543","rc":[{"batl":[[0,2.38,2],[1,2.4,2],[2,2.42,5.5]],"ltp":2.24,"tv":3041.57,"id":10107355}]}]}
{"op":"mcm","clk":"993398308","pt":1580541806506,"mc":[{"id":"1.168133543","rc":[{"batb":[[0,3.3,6.06],[1,3.25,9.3],[2,3.2,6]],"ltp":3.25,"tv":1569.7,"id":12636}]}]}
{"op":"mcm","clk":"993398575","pt":1580541811503,"mc":[{"id":"1.168133543","rc":[{"batl":[[0,2.38,4],[1,2.42,5.5],[2,2.46,21]],"ltp":2.24,"tv":3041.57,"id":10107355},{"batl":[[0,9.2,4.18],[2,10,14.16]],"ltp":7.4,"tv":501.29,"id":22121325}]}]}
{"op":"mcm","clk":"993398620","pt":1580541812530,"mc":[{"id":"1.168133543","rc":[{"batb":[[0,7,2.27],[1,6.8,5.96],[2,6.6,9.18]],"batl":[[0,9.2,2.45]],"ltp":7.4,"tv":501.29,"id":22121325}]}]}
{"op":"mcm","clk":"993399218","pt":1580541823520,"mc":[{"id":"1.168133543","rc":[{"batl":[[2,3.6,2]],"ltp":3.25,"tv":1569.7,"id":12636}]}]}
{"op":"mcm","clk":"993399520","pt":1580541829222,"mc":[{"id":"1.168133543","rc":[{"batl":[[0,2.38,2],[1,2.4,2],[2,2.42,5.5]],"ltp":2.24,"tv":3041.57,"id":10107355}]}]}
{"op":"mcm","clk":"993400011","pt":1580541838566,"mc":[{"id":"1.168133543","rc":[{"trd":[[2.2,4.1],[2.24,289.67]],"batb":[[0,2.2,101.95]],"ltp":2.2,"tv":3047.57,"id":10107355}],"tv":5641.86}]}
{"op":"mcm","clk":"993400485","pt":1580541845567,"mc":[{"id":"1.168133543","rc":[{"batl":[[1,3.6,2],[2,3.75,3.26]],"ltp":3.25,"tv":1569.7,"id":12636}]}]}
{"op":"mcm","clk":"993400549","pt":1580541846445,"mc":[{"id":"1.168133543","rc":[{"batl":[[0,2.38,4],[1,2.42,5.5],[2,2.46,21]],"ltp":2.2,"tv":3047.57,"id":10107355},{"batb":[[1,6.8,8.07]],"ltp":7.4,"tv":501.29,"id":22121325}]}]}
{"op":"mcm","clk":"993401033","pt":1580541855397,"mc":[{"id":"1.168133543","rc":[{"batb":[[2,44,13.67]],"ltp":50.0,"tv":37.75,"id":7226819},{"batl":[[0,2.38,2],[1,2.4,2],[2,2.42,5.5]],"ltp":2.2,"tv":3047.57,"id":10107355}]}]}
{"op":"mcm","clk":"993401510","pt":1580541864384,"mc":[{"id":"1.168133543","rc":[{"batl":[[0,2.38,4],[1,2.42,5.5],[2,2.46,21]],"ltp":2.2,"tv":3047.57,"id":10107355}]}]}
{"op":"mcm","clk":"993401710","pt":1580541868284,"mc":[{"id":"1.168133543","rc":[{"batb":[[1,46,1.47]],"ltp":50.0,"tv":37.75,"id":7226819}]}]}
{"op":"mcm","clk":"993401923","pt":1580541872396,"mc":[{"id":"1.168133543","rc":[{"batl":[[0,2.38,2],[1,2.4,2],[2,2.42,5.5]],"ltp":2.2,"tv":3047.57,"id":10107355}]}]}
{"op":"mcm","clk":"993402029","pt":1580541874297,"mc":[{"id":"1.168133543","rc":[{"batl":[[0,9,8.05],[1,9.2,2],[2,9.6,2.3]],"ltp":7.4,"tv":501.29,"id":22121325}]}]}
{"op":"mcm","clk":"993402238","pt":1580541878020,"mc":[{"id":"1.168133543","rc":[{"batl":[[1,3.55,3.03],[2,3.6,2]],"ltp":3.25,"tv":1569.7,"id":12636}]}]}
{"op":"mcm","clk":"993402961","pt":1580541890403,"mc":[{"id":"1.168133543","rc":[{"batl":[[0,2.38,4],[1,2.42,5.5],[2,2.46,21]],"ltp":2.2,"tv":3047.57,"id":10107355}]}]}
{"op":"mcm","clk":"993403012","pt":1580541891330,"mc":[{"id":"1.168133543","rc":[{"batl":[[0,8.8,5.13],[1,9,7.79],[2,9.2,2]],"ltp":7.4,"tv":501.29,"id":22121325}]}]}
{"op":"mcm","clk":"993403082","pt":1580541892513,"mc":[{"id":"1.168133543","rc":[{"batb":[[1,85,6.04],[2,75,16.64]],"ltp":190.0,"tv":20.7,"id":22308007},{"batb":[[1,46,9.65]],"ltp":50.0,"tv":37.75,"id":7226819},{"batb":[[0,7,30.78]],"ltp":7.4,"tv":501.29,"id":22121325}]}]}
{"op":"mcm","clk":"993403105","pt":1580541892822,"mc":[{"id":"1.168133543","rc":[{"batb":[[0,95,1.79],[1,90,5.59],[2,80,18.08]],"ltp":95.0,"tv":17.79,"id":26548208}]}]}
{"op":"mcm","clk":"993403508","pt":1580541899223,"mc":[{"id":"1.168133543","rc":[{"batl":[[0,8.8,7.13],[2,9.6,2.3]],"ltp":7.4,"tv":501.29,"id":22121325}]}]}
{"op":"mcm","clk":"993403783","pt":1580541903035,"mc":[{"id":"1.168133543","rc":[{"batb":[[0,48,2.23]],"ltp":50.0,"tv":37.75,"id":7226819}]}]}
{"op":"mcm","clk":"993403979","pt":1580541906530,"mc":[{"id":"1.168133543","rc":[{"batb":[[1,80,1.54],[2,75,16]],"ltp":190.0,"tv":20.7,"id":22308007},{"batb":[[1,46,1.47]],"ltp":50.0,"tv":37.75,"id":7226819},{"batb":[[0,90,6.01],[1,80,18.08],[2,70,1.1]],"ltp":95.0,"tv":17.79,"id":26548208}]}]}
{"op":"mcm","clk":"993404022","pt":1580541907350,"mc":[{"id":"1.168133543","rc":[{"batb":[[0,48,10.07]],"ltp":50.0,"tv":37.75,"id":7226819}]}]}
{"op":"mcm","clk":"993404312","pt":1580541911537,"mc":[{"id":"1.168133543","rc":[{"batl":[[1,3.6,2],[2,3.8,3.57]],"ltp":3.25,"tv":1569.7,"id":12636}]}]}
{"op":"mcm","clk":"993404361","pt":1580541912354,"mc":[{"id":"1.168133543","rc":[{"batb":[[0,7.2,6.52],[1,7,30.78],[2,6.8,1.16]],"ltp":7.4,"tv":501.29,"id":22121325}]}]}
{"op":"mcm","clk":"993404615","pt":1580541916549,"mc":[{"id":"1.168133543","rc":[{"batl":[[0,2.38,2],[1,2.4,2],[2,2.42,5.5]],"ltp":2.2,"tv":3047.57,"id":10107355}]}]}
{"op":"mcm","clk":"993404985","pt":1580541922564,"mc":[{"id":"1.168133543","rc":[{"batb":[[0,48,2.23]],"ltp":50.0,"tv":37.75,"id":7226819},{"batb":[[1,7,2.27]],"ltp":7.4,"tv":501.29,"id":22121325}]}]}
{"op":"mcm","clk":"993405150","pt":1580541925470,"mc":[{"id":"1.168133543","rc":[{"batl":[[0,2.38,4],[1,2.42,5.5],[2,2.46,21]],"ltp":2.2,"tv":3047.57,"id":10107355}]}]}
{"op":"mcm","clk":"993405806","pt":1580541934275,"mc":[{"id":"1.168133543","rc":[{"batb":[[0,3.35,5.14],[1,3.3,6.06],[2,3.25,9.3]],"ltp":3.25,"tv":1569.7,"id":12636}]}]}
{"op":"mcm","clk":"993405830","pt":1580541934583,"mc":[{"id":"1.168133543","rc":[{"batb":[[2,3.25,4]],"ltp":3.25,"tv":1569.7,"id":12636}]}]}
{"op":"mcm","clk":"993406325","pt":1580541942389,"mc":[{"id":"1.168133543","rc":[{"batl":[[0,2.38,2],[1,2.4,2],[2,2.42,5.5]],"ltp":2.2,"tv":3047.57,"id":10107355}]}]}
{"op":"mcm","clk":"993406499","pt":1580541944512,"mc":[{"id":"1.168133543","rc":[{"batl":[[1,3.55,3.03],[2,3.6,2]],"ltp":3.25,"tv":1569.7,"id":12636}]}]}
{"op":"mcm","clk":"993406560","pt":1580541945396,"mc":[{"id":"1.168133543","rc":[{"batb":[[0,7,2.27],[1,6.8,8.07],[2,6.6,9.18]],"ltp":7.4,"tv":501.29,"id":22121325}]}]}
{"op":"mcm","clk":"993407449","pt":1580541959513,"mc":[{"id":"1.168133543","rc":[{"batl":[[0,2.38,4],[1,2.42,5.5],[2,2.46,21]],"ltp":2.2,"tv":3047.57,"id":10107355}]}]}
{"op":"mcm","clk":"993407634","pt":1580541962414,"mc":[{"id":"1.168133543","rc":[{"batb":[[0,48,1.4]],"ltp":50.0,"tv":37.75,"id":7226819}]}]}
{"op":"mcm","clk":"993407678","pt":1580541963034,"mc":[{"id":"1.168133543","rc":[{"batb":[[1,46,2.33]],"ltp":50.0,"tv":37.75,"id":7226819}]}]}
{"op":"mcm","clk":"993407788","pt":1580541964534,"mc":[{"id":"1.168133543","rc":[{"batb":[[0,48,9.24]],"ltp":50.0,"tv":37.75,"id":7226819}]}]}
{"op":"mcm","clk":"993408645","pt":1580541976837,"mc":[{"id":"1.168133543","rc":[{"batl":[[0,2.38,2],[1,2.4,2],[2,2.42,5.5]],"ltp":2.2,"tv":3047.57,"id":10107355}]}]}
{"op":"mcm","clk":"993408775","pt":1580541978541,"mc":[{"id":"1.168133543","rc":[{"batb":[[0,48,1.4]],"ltp":50.0,"tv":37.75,"id":7226819}]}]}
{"op":"mcm","clk":"993408828","pt":1580541979216,"mc":[{"id":"1.168133543","rc":[{"batl":[[1,3.6,2],[2,3.75,3.26]],"ltp":3.25,"tv":1569.7,"id":12636}]}]}
{"op":"mcm","clk":"993409356","pt":1580541986541,"mc":[{"id":"1.168133543","rc":[{"batb":[[0,3.35,9.14],[2,3.2,6]],"ltp":3.25,"tv":1569.7,"id":12636}]}]}
{"op":"mcm","clk":"993409894","pt":1580541994535,"mc":[{"id":"1.168133543","rc":[{"batl":[[0,2.38,4],[1,2.42,5.5],[2,2.46,21]],"ltp":2.2,"tv":3047.57,"id":10107355}]}]}
{"op":"mcm","clk":"993410556","pt":1580542002969,"mc":[{"id":"1.168133543","rc":[{"batl":[[0,2.38,2],[1,2.4,2],[2,2.42,5.5]],"ltp":2.2,"tv":3047.57,"id":10107355}]}]}
{"op":"mcm","clk":"993410986","pt":1580542009382,"mc":[{"id":"1.168133543","rc":[{"batl":[[2,3.7,4]],"ltp":3.25,"tv":1569.7,"id":12636}]}]}
{"op":"mcm","clk":"993411156","pt":1580542012061,"mc":[{"id":"1.168133543","rc":[{"batl":[[1,3.55,3.03],[2,3.6,2]],"ltp":3.25,"tv":1569.7,"id":12636}]}]}
{"op":"mcm","clk":"993411612","pt":1580542019566,"mc":[{"id":"1.168133543","rc":[{"batl":[[1,2.42,5.5],[2,2.46,21]],"ltp":2.2,"tv":3047.57,"id":10107355}]}]}
{"op":"mcm","clk":"993411619","pt":1580542019671,"mc":[{"id":"1.168133543","rc":[{"batl":[[0,2.38,4]],"ltp":2.2,"tv":3047.57,"id":10107355}]}]}
{"op":"mcm","clk":"993411821","pt":1580542022564,"mc":[{"id":"1.168133543","rc":[{"batb":[[1,3.2,6],[2,3,8.63]],"ltp":3.25,"tv":1569.7,"id":12636}]}]}
{"op":"mcm","clk":"993412105","pt":1580542026489,"mc":[{"id":"1.168133543","rc":[{"batb":[[0,48,9.24]],"ltp":50.0,"tv":37.75,"id":7226819}]}]}
{"op":"mcm","clk":"993412251","pt":1580542028806,"mc":[{"id":"1.168133543","rc":[{"batl":[[0,2.38,2],[1,2.4,2],[2,2.42,5.5]],"ltp":2.2,"tv":3047.57,"id":10107355}]}]}
{"op":"mcm","clk":"993412841","pt":1580542037501,"mc":[{"id":"1.168133543","rc":[{"batl":[[0,2.38,4],[1,2.42,5.5],[2,2.46,21]],"ltp":2.2,"tv":3047.57,"id":10107355}]}]}
{"op":"mcm","clk":"993413098","pt":1580542041431,"mc":[{"id":"1.168133543","rc":[{"batb":[[0,48,1.4]],"ltp":50.0,"tv":37.75,"id":7226819}]}]}
{"op":"mcm","clk":"993413331","pt":1580542044498,"mc":[{"id":"1.168133543","rc":[{"batl":[[1,3.6,2],[2,3.65,3.03]],"ltp":3.25,"tv":1569.7,"id":12636}]}]}
{"op":"mcm","clk":"993413444","pt":1580542046402,"mc":[{"id":"1.168133543","rc":[{"batb":[[0,48,14.4],[2,42,1.86]],"ltp":50.0,"tv":37.75,"id":7226819}]}]}
{"op":"mcm","clk":"993413974","pt":1580542054136,"mc":[{"id":"1.168133543","rc":[{"batb":[[1,46,1.95]],"ltp":50.0,"tv":37.75,"id":7226819}]}]}
{"op":"mcm","clk":"993414053","pt":1580542055219,"mc":[{"id":"1.168133543","rc":[{"batl":[[0,2.38,2],[1,2.4,2],[2,2.42,5.5]],"ltp":2.2,"tv":3047.57,"id":10107355}]}]}
{"op":"mcm","clk":"993414484","pt":1580542061530,"mc":[{"id":"1.168133543","rc":[{"batb":[[0,48,14.75]],"ltp":50.0,"tv":37.75,"id":7226819}]}]}
{"op":"mcm","clk":"993414499","pt":1580542061731,"mc":[{"id":"1.168133543","rc":[{"batl":[[1,3.6,6]],"ltp":3.25,"tv":1569.7,"id":12636}]}]}
{"op":"mcm","clk":"993414614","pt":1580542063432,"mc":[{"id":"1.168133543","rc":[{"batb":[[0,48,1.75]],"ltp":50.0,"tv":37.75,"id":7226819}]}]}
{"op":"mcm","clk":"993414800","pt":1580542066533,"mc":[{"id":"1.168133543","rc":[{"batl":[[2,10,14.46]],"ltp":7.4,"tv":501.29,"id":22121325}]}]}
{"op":"mcm","clk":"993415016","pt":1580542069939,"mc":[{"id":"1.168133543","rc":[{"batb":[[0,48,1.4]],"ltp":50.0,"tv":37.75,"id":7226819}]}]}
{"op":"mcm","clk":"993415222","pt":1580542073540,"mc":[{"id":"1.168133543","rc":[{"batb":[[2,42,16.86]],"ltp":50.0,"tv":37.75,"id":7226819}]}]}
{"op":"mcm","clk":"993415347","pt":1580542075550,"mc":[{"id":"1.168133543","rc":[{"batl":[[2,3.9,64]],"ltp":3.25,"tv":1569.7,"id":12636}]}]}
{"op":"mcm","clk":"993415402","pt":1580542076538,"mc":[{"id":"1.168133543","rc":[{"batl":[[0,3.45,4.53],[1,3.5,2],[2,3.55,3.03]],"ltp":3.25,"tv":1569.7,"id":12636}]}]}
{"op":"mcm","clk":"993415456","pt":1580542077355,"mc":[{"id":"1.168133543","rc":[{"batb":[[2,44,1.07]],"ltp":50.0,"tv":37.75,"id":7226819}]}]}
{"op":"mcm","clk":"993415717","pt":1580542081551,"mc":[{"id":"1.168133543","rc":[{"batb":[[1,46,1.08]],"ltp":50.0,"tv":37.75,"id":7226819},{"batl":[[0,2.38,4],[1,2.42,5.5],[2,2.46,21]],"ltp":2.2,"tv":3047.57,"id":10107355}]}]}
{"op":"mcm","clk":"993415758","pt":1580542082171,"mc":[{"id":"1.168133543","rc":[{"batb":[[2,44,1.98]],"ltp":50.0,"tv":37.75,"id":7226819}]}]}
{"op":"mcm","clk":"993415852","pt":1580542083565,"mc":[{"id":"1.168133543","rc":[{"batb":[[1,85,6.04],[2,75,16.64]],"ltp":190.0,"tv":20.7,"id":22308007},{"batb":[[1,46,9.26]],"ltp":50.0,"tv":37.75,"id":7226819},{"batb":[[0,7,30.78]],"ltp":7.4,"tv":501.29,"id":22121325}]}]}
{"op":"mcm","clk":"993415890","pt":1580542084188,"mc":[{"id":"1.168133543","rc":[{"batb":[[0,95,1.79],[1,90,5.59],[2,80,18.08]],"ltp":95.0,"tv":17.79,"id":26548208}]}]}
{"op":"mcm","clk":"993416244","pt":1580542089754,"mc":[{"id":"1.168133543","rc":[{"batl":[[0,2.38,2],[1,2.4,2],[2,2.42,5.5]],"ltp":2.2,"tv":3047.57,"id":10107355}]}]}
{"op":"mcm","clk":"993416803","pt":1580542098477,"mc":[{"id":"1.168133543","rc":[{"batb":[[0,90,6.04],[1,80,1.54],[2,75,16]],"ltp":190.0,"tv":20.7,"id":22308007}]}]}
{"op":"mcm","clk":"993416845","pt":1580542099199,"mc":[{"id":"1.168133543","rc":[{"batl":[[1,10,14.65],[2,10.5,12.74]],"ltp":7.4,"tv":501.29,"id":22121325}]}]}
{"op":"mcm","clk":"993417395","pt":1580542108389,"mc":[{"id":"1.168133543","rc":[{"batb":[[0,3.35,5.14],[1,3.25,4],[2,3.2,6]],"batl":[[2,3.6,2]],"ltp":3.25,"tv":1569.7,"id":12636},{"batb":[[0,7.2,6.52],[1,7,30.78],[2,6.8,1.16]],"ltp":7.4,"tv":501.29,"id":22121325}]}]}
{"op":"mcm","clk":"993417523","pt":1580542110506,"mc":[{"id":"1.168133543","rc":[{"batb":[[1,80,1.04]],"ltp":190.0,"tv":20.7,"id":22308007}]}]}
{"op":"mcm","clk":"993417698","pt":1580542113298,"mc":[{"id":"1.168133543","rc":[{"batb":[[0,90,1.19]],"ltp":190.0,"tv":20.7,"id":22308007},{"batb":[[1,46,1.08]],"ltp":50.0,"tv":37.75,"id":7226819},{"batb":[[1,7,2.27]],"ltp":7.4,"tv":501.29,"id":22121325},{"batb":[[0,90,6.01],[1,80,18.08],[2,70,1.1]],"ltp":95.0,"tv":17.79,"id":26548208}]}]}
{"op":"mcm","clk":"993417904","pt":1580542116810,"mc":[{"id":"1.168133543","rc":[{"batb":[[1,3.3,20],[2,3.25,4]],"ltp":3.25,"tv":1569.7,"id":12636}]}]}
{"op":"mcm","clk":"993418285","pt":1580542123625,"mc":[{"id":"1.168133543","rc":[{"batb":[[0,3.35,15.14]],"ltp":3.25,"tv":1569.7,"id":12636}]}]}
{"op":"mcm","clk":"993418377","pt":1580542125328,"mc":[{"id":"1.168133543","rc":[{"batl":[[0,2.38,4],[1,2.42,5.5],[2,2.46,21]],"ltp":2.2,"tv":3047.57,"id":10107355}]}]}
{"op":"mcm","clk":"993418455","pt":1580542126515,"mc":[{"id":"1.168133543","rc":[{"batb":[[1,46,9.26]],"ltp":50.0,"tv":37.75,"id":7226819}]}]}
{"op":"mcm","clk":"993418805","pt":1580542132335,"mc":[{"id":"1.168133543","rc":[{"batb":[[1,80,1.54]],"ltp":190.0,"tv":20.7,"id":22308007}]}]}
{"op":"mcm","clk":"993419310","pt":1580542140557,"mc":[{"id":"1.168133543","rc":[{"batb":[[1,46,1.08]],"ltp":50.0,"tv":37.75,"id":7226819},{"batb":[[0,7,2.27],[1,6.8,7.68],[2,6.6,9.18]],"ltp":7.4,"tv":501.29,"id":22121325}]}]}
{"op":"mcm","clk":"993419381","pt":1580542141539,"mc":[{"id":"1.168133543","rc":[{"batb":[[1,6.8,8.07]],"ltp":7.4,"tv":501.29,"id":22121325}]}]}
{"op":"mcm","clk":"993419510","pt":1580542143555,"mc":[{"id":"1.168133543","rc":[{"batl":[[0,2.38,2],[1,2.4,2],[2,2.42,5.5]],"ltp":2.2,"tv":3047.57,"id":10107355}]}]}
{"op":"mcm","clk":"993420013","pt":1580542151552,"mc":[{"id":"1.168133543","rc":[{"batl":[[0,2.38,4],[1,2.42,5.5],[2,2.46,21]],"ltp":2.2,"tv":3047.57,"id":10107355}]}]}
{"op":"mcm","clk":"993420251","pt":1580542155489,"mc":[{"id":"1.168133543","rc":[{"batb":[[1,85,6.04],[2,75,16.64]],"ltp":190.0,"tv":20.7,"id":22308007},{"batb":[[1,46,9.26]],"ltp":50.0,"tv":37.75,"id":7226819},{"batb":[[0,7,30.78]],"ltp":7.4,"tv":501.29,"id":22121325},{"trd":[[330,10.38]],"batb":[[0,260,1],[1,250,5.11],[2,230,1.32]],"batl":[[0,440,2],[1,450,5],[2,700,2]],"ltp":330.0,"tv":11.92,"id":24270700}],"tv":5652.24}]}
{"op":"mcm","clk":"993420286","pt":1580542156056,"mc":[{"id":"1.168133543","rc":[{"batb":[[0,95,1.79],[1,90,5.59],[2,80,18.08]],"ltp":95.0,"tv":17.79,"id":26548208}]}]}
{"op":"mcm","clk":"993420525","pt":1580542160394,"mc":[{"id":"1.168133543","rc":[{"batl":[[0,8.8,5.13],[1,9.8,2.49],[2,10,14.16]],"ltp":7.4,"tv":501.29,"id":22121325},{"batl":[[0,440,2.2]],"ltp":330.0,"tv":11.92,"id":24270700}]}]}
{"op":"mcm","clk":"993421082","pt":1580542168987,"mc":[{"id":"1.168133543","rc":[{"batl":[[0,2.38,2],[1,2.4,2],[2,2.42,5.5]],"ltp":2.2,"tv":3047.57,"id":10107355}]}]}
{"op":"mcm","clk":"993421119","pt":1580542169603,"mc":[{"id":"1.168133543","rc":[{"batb":[[1,80,1.54],[2,75,16]],"ltp":190.0,"tv":20.7,"id":22308007},{"batb":[[1,46,1.08]],"ltp":50.0,"tv":37.75,"id":7226819},{"batb":[[0,90,6.01],[1,80,18.08],[2,70,1.1]],"ltp":95.0,"tv":17.79,"id":26548208}]}]}
{"op":"mcm","clk":"993421271","pt":1580542172408,"mc":[{"id":"1.168133543","rc":[{"batl":[[0,9.8,2.75],[1,10,14.16],[2,10.5,12.74]],"ltp":7.4,"tv":501.29,"id":22121325}]}]}
{"op":"mcm","clk":"993421341","pt":1580542173392,"mc":[{"id":"1.168133543","rc":[{"batb":[[0,7,31.47],[1,6.8,7.33]],"batl":[[0,9.6,5.21],[1,9.8,2],[2,10,14.16]],"ltp":7.4,"tv":501.29,"id":22121325},{"batl":[[0,440,2.3],[2,950,2]],"ltp":330.0,"tv":11.92,"id":24270700}]}]}
{"op":"mcm","clk":"993421583","pt":1580542177294,"mc":[{"id":"1.168133543","rc":[{"batl":[[0,2.38,4],[1,2.42,5.5],[2,2.46,21]],"ltp":2.2,"tv":3047.57,"id":10107355}]}]}
{"op":"mcm","clk":"993422009","pt":1580542183520,"mc":[{"id":"1.168133543","rc":[{"batb":[[1,46,9.26]],"ltp":50.0,"tv":37.75,"id":7226819}]}]}
{"op":"mcm","clk":"993422147","pt":1580542185918,"mc":[{"id":"1.168133543","rc":[{"batl":[[0,2.38,2],[1,2.4,2],[2,2.42,5.5]],"ltp":2.2,"tv":3047.57,"id":10107355}]}]}
{"op":"mcm","clk":"993422968","pt":1580542199214,"mc":[{"id":"1.168133543","rc":[{"batb":[[1,46,1.08]],"ltp":50.0,"tv":37.75,"id":7226819},{"batb":[[0,7,2.96]],"ltp":7.4,"tv":501.29,"id":22121325}]}]}
{"op":"mcm","clk":"993423222","pt":1580542202561,"mc":[{"id":"1.168133543","rc":[{"trd":[[3.45,9.06]],"batl":[[0,3.5,2],[1,3.6,2],[2,3.8,6]],"ltp":3.45,"tv":1578.76,"id":12636}],"tv":5661.3}]}
{"op":"mcm","clk":"993423293","pt":1580542203552,"mc":[{"id":"1.168133543","rc":[{"batl":[[2,1000,2]],"ltp":330.0,"tv":11.92,"id":24270700}]}]}
{"op":"mcm","clk":"993423584","pt":1580542207564,"mc":[{"id":"1.168133543","rc":[{"batl":[[1,3.55,6.83],[2,3.6,2]],"ltp":3.45,"tv":1578.76,"id":12636}]}]}
{"op":"mcm","clk":"993423892","pt":1580542212536,"mc":[{"id":"1.168133543","rc":[{"batl":[[2,3.6,4.11]],"ltp":3.45,"tv":1578.76,"id":12636},{"batl":[[0,2.38,108.41]],"ltp":2.2,"tv":3047.57,"id":10107355}]}]}
{"op":"mcm","clk":"993423898","pt":1580542212639,"mc":[{"id":"1.168133543","rc":[{"batl":[[0,160,3.54]],"ltp":190.0,"tv":20.7,"id":22308007},{"batl":[[0,2.36,11.68],[1,2.38,108.41],[2,2.4,2]],"ltp":2.2,"tv":3047.57,"id":10107355}]}]}
{"op":"mcm","clk":"993424025","pt":1580542214467,"mc":[{"id":"1.168133543","rc":[{"batl":[[0,2.36,23.25]],"ltp":2.2,"tv":3047.57,"id":10107355}]}]}
{"op":"mcm","clk":"993424321","pt":1580542218356,"mc":[{"id":"1.168133543","rc":[{"batl":[[0,2.36,43.25]],"ltp":2.2,"tv":3047.57,"id":10107355}]}]}
{"op":"mcm","clk":"993424915","pt":1580542226568,"mc":[{"id":"1.168133543","rc":[{"batl":[[0,160,3.03]],"ltp":190.0,"tv":20.7,"id":22308007},{"batl":[[1,2.38,2]],"ltp":2.2,"tv":3047.57,"id":10107355}]}]}
{"op":"mcm","clk":"993425052","pt":1580542228483,"mc":[{"id":"1.168133543","rc":[{"batl":[[0,2.36,31.68]],"ltp":2.2,"tv":3047.57,"id":10107355}]}]}
{"op":"mcm","clk":"993425261","pt":1580542231497,"mc":[{"id":"1.168133543","rc":[{"batl":[[0,2.34,2],[1,2.36,31.68],[2,2.38,2]],"ltp":2.2,"tv":3047.57,"id":10107355}]}]}
{"op":"mcm","clk":"993425408","pt":1580542233516,"mc":[{"id":"1.168133543","rc":[{"batl":[[1,2.36,11.68]],"ltp":2.2,"tv":3047.57,"id":10107355}]}]}
{"op":"mcm","clk":"993425817","pt":1580542238476,"mc":[{"id":"1.168133543","rc":[{"batb":[[0,3.35,19.14],[2,3.2,6]],"ltp":3.45,"tv":1578.76,"id":12636},{"batl":[[2,2.4,2]],"ltp":2.2,"tv":3047.57,"id":10107355},{"batl":[[0,9.4,8.22],[1,9.6,4.59],[2,9.8,2]],"ltp":7.4,"tv":501.29,"id":22121325}]}]}
{"op":"mcm","clk":"993426731","pt":1580542251518,"mc":[{"id":"1.168133543","rc":[{"batl":[[1,9.8,2.13],[2,10,14.16]],"ltp":7.4,"tv":501.29,"id":22121325}]}]}
{"op":"mcm","clk":"993428371","pt":1580542272840,"mc":[{"id":"1.168133543","rc":[{"batl":[[0,2.32,2],[1,2.34,2],[2,2.36,11.68]],"ltp":2.2,"tv":3047.57,"id":10107355}]}]}
{"op":"mcm","clk":"993430503","pt":1580542298497,"mc":[{"id":"1.168133543","rc":[{"batl":[[0,2.3,2]],"ltp":2.2,"tv":3047.57,"id":10107355}]}]}
{"op":"mcm","clk":"993430561","pt":1580542299380,"mc":[{"id":"1.168133543","rc":[{"batl":[[2,2.42,5.5]],"ltp":2.2,"tv":3047.57,"id":10107355},{"batl":[[1,9.6,2.13]],"ltp":7.4,"tv":501.29,"id":22121325}]}]}
{"op":"mcm","clk":"993431054","pt":1580542304010,"mc":[{"id":"1.168133543","rc":[{"batl":[[0,2.28,3.36],[1,2.3,2],[2,2.34,2]],"ltp":2.2,"tv":3047.57,"id":10107355}]}]}
{"op":"mcm","clk":"993431143","pt":1580542305294,"mc":[{"id":"1.168133543","rc":[{"batl":[[0,2.3,2],[1,2.34,2],[2,2.42,5.5]],"ltp":2.2,"tv":3047.57,"id":10107355}]}]}
{"op":"mcm","clk":"993431491","pt":1580542310498,"mc":[{"id":"1.168133543","rc":[{"batl":[[0,9.2,5.11],[1,9.4,7.77],[2,9.6,2.13]],"ltp":7.4,"tv":501.29,"id":22121325}]}]}
{"op":"mcm","clk":"993437960","pt":1580542405568,"mc":[{"id":"1.168133543","rc":[{"trd":[[330,0.3],[450,10],[590,4]],"batb":[[0,600,1.85],[1,250,5.75],[2,160,13.82]],"batl":[[0,1000,0.2],[1,590,0]],"ltp":590.0,"tv":20.43,"id":27606066}],"tv":5675.6}]}
{"op":"mcm","clk":"993438015","pt":1580542406351,"mc":[{"id":"1.168133543","rc":[{"batb":[[0,250,5.75],[1,160,13.82],[2,150,1.32]],"ltp":590.0,"tv":20.43,"id":27606066}]}]}
{"op":"mcm","clk":"993438440","pt":1580542412366,"mc":[{"id":"1.168133543","rc":[{"batb":[[0,230,1.08],[1,160,13.49]],"ltp":590.0,"tv":20.43,"id":27606066}]}]}
{"op":"mcm","clk":"993440665","pt":1580542444507,"mc":[{"id":"1.168133543","rc":[{"batl":[[1,3.55,8.83]],"ltp":3.45,"tv":1578.76,"id":12636},{"trd":[[2.3,614.71]],"batl":[[0,2.34,2],[1,2.42,5.5],[2,2.46,21]],"ltp":2.3,"tv":3113.57,"id":10107355}],"tv":5741.6}]}
{"op":"mcm","clk":"993441427","pt":1580542455517,"mc":[{"id":"1.168133543","rc":[{"batl":[[0,160,3.54]],"ltp":190.0,"tv":20.7,"id":22308007}]}]}
{"op":"mcm","clk":"993441471","pt":1580542456438,"mc":[{"id":"1.168133543","rc":[{"batl":[[1,2.4,2],[2,2.42,5.5]],"ltp":2.3,"tv":3113.57,"id":10107355}]}]}
{"op":"mcm","clk":"993441985","pt":1580542464055,"mc":[{"id":"1.168133543","rc":[{"batl":[[1,9.6,2.3],[2,10,14.16]],"ltp":7.4,"tv":501.29,"id":22121325}]}]}
{"op":"mcm","clk":"993442071","pt":1580542465448,"mc":[{"id":"1.168133543","rc":[{"batl":[[1,2.38,2]],"ltp":2.3,"tv":3113.57,"id":10107355}]}]}
{"op":"mcm","clk":"993442306","pt":1580542468552,"mc":[{"id":"1.168133543","rc":[{"trd":[[2.34,404.1]],"batb":[[0,2.34,6],[1,2.2,101.95],[2,2,36.46]],"batl":[[0,2.36,11.68]],"ltp":2.34,"tv":3117.57,"id":10107355}],"tv":5745.6}]}
{"op":"mcm","clk":"993442353","pt":1580542469223,"mc":[{"id":"1.168133543","rc":[{"trd":[[2.34,416.1]],"batb":[[0,2.2,101.95],[1,2,36.46],[2,1.98,9.11]],"batl":[[0,2.38,2],[1,2.42,5.5],[2,2.46,21]],"ltp":2.34,"tv":3129.57,"id":10107355}],"tv":5757.6}]}
{"op":"mcm","clk":"993442493","pt":1580542471346,"mc":[{"id":"1.168133543","rc":[{"batb":[[0,2.22,2],[1,2.2,101.95],[2,2,36.46]],"ltp":2.34,"tv":3129.57,"id":10107355}]}]}
{"op":"mcm","clk":"993442692","pt":1580542474246,"mc":[{"id":"1.168133543","rc":[{"batl":[[0,2.4,2]],"ltp":2.34,"tv":3129.57,"id":10107355}]}]}
{"op":"mcm","clk":"993443122","pt":1580542480484,"mc":[{"id":"1.168133543","rc":[{"batl":[[0,9,8.05],[1,9.2,4.65],[2,9.6,2.3]],"ltp":7.4,"tv":501.29,"id":22121325}]}]}
{"op":"mcm","clk":"993443162","pt":1580542481157,"mc":[{"id":"1.168133543","rc":[{"trd":[[320,0.4],[330,0.3],[450,9.3]],"batl":[[0,1000,1.65],[1,1000,0]],"ltp":450.0,"tv":29.01,"id":13306150}],"tv":5767.6}]}
{"op":"mcm","clk":"993443243","pt":1580542482487,"mc":[{"id":"1.168133543","rc":[{"batb":[[0,150,1.95],[1,130,2],[2,120,1.92]],"batl":[[0,1000,1.5]],"ltp":450.0,"tv":29.01,"id":13306150}]}]}
{"op":"mcm","clk":"993443355","pt":1580542484490,"mc":[{"id":"1.168133543","rc":[{"batl":[[0,160,3.03]],"ltp":190.0,"tv":20.7,"id":22308007},{"trd":[[420,0.4],[430,0.2],[440,4],[450,10]],"batb":[[0,330,1.51],[1,250,5.3]],"batl":[[0,1000,2],[1,450,0],[2,1000,0]],"ltp":450.0,"tv":26.52,"id":24270700}],"tv":5782.2}]}
{"op":"mcm","clk":"993443585","pt":1580542487895,"mc":[{"id":"1.168133543","rc":[{"batl":[[0,1000,2.2]],"ltp":450.0,"tv":26.52,"id":24270700}]}]}
{"op":"mcm","clk":"993443644","pt":1580542488771,"mc":[{"id":"1.168133543","rc":[{"batb":[[2,120,1.77]],"ltp":450.0,"tv":29.01,"id":13306150}]}]}
{"op":"mcm","clk":"993443891","pt":1580542492480,"mc":[{"id":"1.168133543","rc":[{"batb":[[1,230,1.62],[2,180,1.13]],"ltp":450.0,"tv":26.52,"id":24270700},{"batb":[[1,120,1.77],[2,95,1.26]],"ltp":450.0,"tv":29.01,"id":13306150}]}]}
{"op":"mcm","clk":"993444191","pt":1580542496506,"mc":[{"id":"1.168133543","rc":[{"batl":[[1,9.6,2.3],[2,10,14.16]],"ltp":7.4,"tv":501.29,"id":22121325},{"batb":[[1,230,1.78],[2,180,1.03]],"ltp":450.0,"tv":26.52,"id":24270700}]}]}
{"op":"mcm","clk":"993444632","pt":1580542503423,"mc":[{"id":"1.168133543","rc":[{"batl":[[0,2.38,2],[1,2.4,2],[2,2.42,5.5]],"ltp":2.34,"tv":3129.57,"id":10107355},{"batb":[[2,95,1.68]],"ltp":450.0,"tv":29.01,"id":13306150}]}]}
{"op":"mcm","clk":"993444941","pt":1580542507402,"mc":[{"id":"1.168133543","rc":[{"batl":[[0,2.36,2],[1,2.38,2],[2,2.4,2]],"ltp":2.34,"tv":3129.57,"id":10107355}]}]}
{"op":"mcm","clk":"993445286","pt":1580542512307,"mc":[{"id":"1.168133543","rc":[{"batb":[[0,3.4,12],[1,3.35,19.14],[2,3.3,20]],"ltp":3.45,"tv":1578.76,"id":12636}]}]}
{"op":"mcm","clk":"993445574","pt":1580542516527,"mc":[{"id":"1.168133543","rc":[{"batb":[[1,230,1.62]],"ltp":450.0,"tv":26.52,"id":24270700}]}]}
{"op":"mcm","clk":"993445581","pt":1580542516631,"mc":[{"id":"1.168133543","rc":[{"batb":[[1,230,1.78]],"ltp":450.0,"tv":26.52,"id":24270700}]}]}
{"op":"mcm","clk":"993445703","pt":1580542518442,"mc":[{"id":"1.168133543","rc":[{"batl":[[0,2.34,2],[1,2.36,2],[2,2.38,2]],"ltp":2.34,"tv":3129.57,"id":10107355}]}]}
{"op":"mcm","clk":"993446800","pt":1580542533473,"mc":[{"id":"1.168133543","rc":[{"batb":[[0,1000,391.04]],"ltp":1000.0,"tv":11.76,"id":13819977}]}]}
{"op":"mcm","clk":"993447088","pt":1580542537245,"mc":[{"id":"1.168133543","rc":[{"batb":[[1,230,1.62]],"ltp":450.0,"tv":26.52,"id":24270700}]}]}
{"op":"mcm","clk":"993447142","pt":1580542537968,"mc":[{"id":"1.168133543","rc":[{"batb":[[1,230,1.78]],"ltp":450.0,"tv":26.52,"id":24270700}]}]}
{"op":"mcm","clk":"993447327","pt":1580542540239,"mc":[{"id":"1.168133543","rc":[{"batl":[[1,3.55,2]],"ltp":3.45,"tv":1578.76,"id":12636}]}]}
{"op":"mcm","clk":"993448389","pt":1580542554565,"mc":[{"id":"1.168133543","rc":[{"batl":[[0,2.32,2]],"ltp":2.34,"tv":3129.57,"id":10107355}]}]}
{"op":"mcm","clk":"993451221","pt":1580542596455,"mc":[{"id":"1.168133543","rc":[{"batb":[[0,1000,381.92]],"ltp":1000.0,"tv":11.76,"id":13819977}]}]}
{"op":"mcm","clk":"993451404","pt":1580542599254,"mc":[{"id":"1.168133543","rc":[{"batl":[[1,9.2,2],[2,10,14.46]],"ltp":7.4,"tv":501.29,"id":22121325}]}]}
{"op":"mcm","clk":"993451987","pt":1580542607259,"mc":[{"id":"1.168133543","rc":[{"trd":[[2.2,5.1],[2.22,210.72]],"batb":[[0,2.2,101.45],[1,2,36.46],[2,1.98,9.11]],"ltp":2.2,"tv":3134.57,"id":10107355}],"tv":5787.2}]}
{"op":"mcm","clk":"993452674","pt":1580542617478,"mc":[{"id":"1.168133543","rc":[{"trd":[[3.5,4]],"batl":[[0,3.55,2],[1,3.6,4.11],[2,3.8,6]],"ltp":3.5,"tv":1582.76,"id":12636},{"batb":[[2,95,5.68]],"ltp":450.0,"tv":29.01,"id":13306150}],"tv":5791.2}]}
{"op":"mcm","clk":"993452728","pt":1580542618402,"mc":[{"id":"1.168133543","rc":[{"batl":[[0,8.8,5.13],[1,9,7.79],[2,9.2,2]],"ltp":7.4,"tv":501.29,"id":22121325},{"batb":[[2,100,1.01]],"ltp":450.0,"tv":29.01,"id":13306150}]}]}
{"op":"mcm","clk":"993453718","pt":1580542632104,"mc":[{"id":"1.168133543","rc":[{"batl":[[2,4,6]],"ltp":3.5,"tv":1582.76,"id":12636}]}]}
{"op":"mcm","clk":"993453929","pt":1580542634998,"mc":[{"id":"1.168133543","rc":[{"batb":[[1,150,1.82],[2,110,13.5]],"ltp":590.0,"tv":20.43,"id":27606066}]}]}
{"op":"mcm","clk":"993454169","pt":1580542638216,"mc":[{"id":"1.168133543","rc":[{"batb":[[1,150,1.71]],"ltp":590.0,"tv":20.43,"id":27606066}]}]}
{"op":"mcm","clk":"993454784","pt":1580542645855,"mc":[{"id":"1.168133543","rc":[{"batb":[[2,110,13.65]],"ltp":590.0,"tv":20.43,"id":27606066}]}]}
{"op":"mcm","clk":"993465306","pt":1580542655940,"mc":[{"id":"1.168133543","rc":[{"batb":[[0,3.45,4.99],[1,3.4,12],[2,3.35,14]],"ltp":3.5,"tv":1582.76,"id":12636}]}]}
{"op":"mcm","clk":"993465549","pt":1580542659464,"mc":[{"id":"1.168133543","rc":[{"batb":[[1,230,1.62]],"ltp":450.0,"tv":26.52,"id":24270700}]}]}
{"op":"mcm","clk":"993465621","pt":1580542660471,"mc":[{"id":"1.168133543","rc":[{"batb":[[1,230,1.78]],"ltp":450.0,"tv":26.52,"id":24270700}]}]}
{"op":"mcm","clk":"993465685","pt":1580542661253,"mc":[{"id":"1.168133543","rc":[{"batl":[[2,4.5,56]],"ltp":3.5,"tv":1582.76,"id":12636}]}]}
{"op":"mcm","clk":"993467012","pt":1580542681995,"mc":[{"id":"1.168133543","rc":[{"batb":[[2,110,13.98]],"ltp":590.0,"tv":20.43,"id":27606066}]}]}
{"op":"mcm","clk":"993467152","pt":1580542684206,"mc":[{"id":"1.168133543","rc":[{"batl":[[2,5,50]],"ltp":3.5,"tv":1582.76,"id":12636}]}]}
{"op":"mcm","clk":"993467802","pt":1580542695495,"mc":[{"id":"1.168133543","rc":[{"trd":[[9.8,56.22]],"batb":[[0,9.6,12.34],[1,9.2,5.64],[2,8.4,9.24]],"batl":[[0,9.8,98.24],[1,10,51.32],[2,12,11]],"ltp":9.8,"tv":412.1,"id":10163711}],"tv":5794.72}]}
{"op":"mcm","clk":"993467808","pt":1580542695596,"mc":[{"id":"1.168133543","rc":[{"batb":[[1,240,77.68],[2,230,1.1]],"ltp":450.0,"tv":26.52,"id":24270700}]}]}
{"op":"mcm","clk":"993468094","pt":1580542700296,"mc":[{"id":"1.168133543","rc":[{"batb":[[1,150,89.71]],"ltp":590.0,"tv":20.43,"id":27606066}]}]}
{"op":"mcm","clk":"993468216","pt":1580542702714,"mc":[{"id":"1.168133543","rc":[{"batl":[[0,2.32,4]],"ltp":2.2,"tv":3134.57,"id":10107355}]}]}
{"op":"mcm","clk":"993468276","pt":1580542703902,"mc":[{"id":"1.168133543","rc":[{"batb":[[1,120,78.77]],"ltp":450.0,"tv":29.01,"id":13306150}]}]}
{"op":"mcm","clk":"993468386","pt":1580542706117,"mc":[{"id":"1.168133543","rc":[{"batl":[[1,9.2,2.19],[2,10,14.46]],"ltp":7.4,"tv":501.29,"id":22121325},{"batb":[[2,110,13.83]],"ltp":590.0,"tv":20.43,"id":27606066},{"batb":[[1,240,77.75]],"ltp":450.0,"tv":26.52,"id":24270700}]}]}
{"op":"mcm","clk":"993468828","pt":1580542714223,"mc":[{"id":"1.168133543","rc":[{"batl":[[2,5.5,51.67]],"ltp":3.5,"tv":1582.76,"id":12636},{"batb":[[1,150,89.82]],"ltp":590.0,"tv":20.43,"id":27606066},{"batb":[[1,120,78.91]],"ltp":450.0,"tv":29.01,"id":13306150}]}]}
{"op":"mcm","clk":"993468916","pt":1580542716030,"mc":[{"id":"1.168133543","rc":[{"batb":[[0,3.45,8.99],[2,3.35,10]],"ltp":3.5,"tv":1582.76,"id":12636}]}]}
{"op":"mcm","clk":"993470483","pt":1580542742484,"mc":[{"id":"1.168133543","rc":[{"batb":[[0,2.26,16],[1,2.2,101.45],[2,2,36.46]],"ltp":2.2,"tv":3134.57,"id":10107355},{"batb":[[2,110,13.5]],"ltp":590.0,"tv":20.43,"id":27606066},{"batb":[[1,120,79.21]],"ltp":450.0,"tv":29.01,"id":13306150}]}]}
{"op":"mcm","clk":"993470612","pt":1580542744297,"mc":[{"id":"1.168133543","rc":[{"batl":[[2,5.5,6.67]],"ltp":3.5,"tv":1582.76,"id":12636}]}]}
{"op":"mcm","clk":"993470859","pt":1580542748497,"mc":[{"id":"1.168133543","rc":[{"trd":[[2.32,213.37]],"batb":[[0,2.28,2],[1,2.26,16],[2,2.2,101.45]],"batl":[[0,2.36,2],[1,2.38,2],[2,2.42,5.5]],"ltp":2.32,"tv":3153.94,"id":10107355}],"tv":5814.09}]}
{"op":"mcm","clk":"993471169","pt":1580542754221,"mc":[{"id":"1.168133543","rc":[{"batb":[[2,2.22,6]],"ltp":2.32,"tv":3153.94,"id":10107355}]}]}
{"op":"mcm","clk":"993471308","pt":1580542756506,"mc":[{"id":"1.168133543","rc":[{"batl":[[0,2.36,109.31]],"ltp":2.32,"tv":3153.94,"id":10107355}]}]}
{"op":"mcm","clk":"993471322","pt":1580542756810,"mc":[{"id":"1.168133543","rc":[{"batl":[[0,160,3.54]],"ltp":190.0,"tv":20.7,"id":22308007},{"batl":[[0,2.34,11.76],[1,2.36,109.31],[2,2.38,2]],"ltp":2.32,"tv":3153.94,"id":10107355}]}]}
{"op":"mcm","clk":"993471400","pt":1580542758510,"mc":[{"id":"1.168133543","rc":[{"batl":[[0,2.34,23.46]],"ltp":2.32,"tv":3153.94,"id":10107355}]}]}
{"op":"mcm","clk":"993471448","pt":1580542759493,"mc":[{"id":"1.168133543","rc":[{"trd":[[3.55,4]],"batl":[[0,3.6,4.11],[1,5.5,6.67],[2,6,42]],"ltp":3.55,"tv":1586.76,"id":12636}],"tv":5818.09}]}
{"op":"mcm","clk":"993471457","pt":1580542759694,"mc":[{"id":"1.168133543","rc":[{"batl":[[0,2.34,25.46]],"ltp":2.32,"tv":3153.94,"id":10107355}]}]}
{"op":"mcm","clk":"993471554","pt":1580542761195,"mc":[{"id":"1.168133543","rc":[{"trd":[[8.2,183.48],[8.4,30.47],[9,63.94],[9.2,69.85],[9.6,47.05]],"batb":[[0,8.2,21.67],[1,8,23.54],[2,7.8,10.23]],"ltp":8.2,"tv":612.1,"id":10163711},{"batl":[[0,2.34,45.46]],"ltp":2.32,"tv":3153.94,"id":10107355}],"tv":6018.1}]}
{"op":"mcm","clk":"993471710","pt":1580542764333,"mc":[{"id":"1.168133543","rc":[{"batl":[[0,9.6,7.66],[1,9.8,98.24],[2,10,51.32]],"ltp":8.2,"tv":612.1,"id":10163711},{"batb":[[1,240,77.59]],"ltp":450.0,"tv":26.52,"id":24270700}]}]}
{"op":"mcm","clk":"993471771","pt":1580542765322,"mc":[{"id":"1.168133543","rc":[{"batl":[[0,9.6,7.89]],"ltp":8.2,"tv":612.1,"id":10163711},{"batb":[[1,240,77.75]],"ltp":450.0,"tv":26.52,"id":24270700}]}]}
{"op":"mcm","clk":"993471882","pt":1580542767133,"mc":[{"id":"1.168133543","rc":[{"batl":[[0,9.4,4],[1,9.6,7.89],[2,9.8,98.24]],"ltp":8.2,"tv":612.1,"id":10163711}]}]}
{"op":"mcm","clk":"993471946","pt":1580542768321,"mc":[{"id":"1.168133543","rc":[{"batl":[[0,2.32,2],[1,2.34,43.46],[2,2.36,109.31]],"ltp":2.32,"tv":3153.94,"id":10107355}]}]}
{"op":"mcm","clk":"993472148","pt":1580542771539,"mc":[{"id":"1.168133543","rc":[{"batb":[[1,85,6.04],[2,75,16.64]],"batl":[[0,160,3.03]],"ltp":190.0,"tv":20.7,"id":22308007},{"batb":[[1,46,9.26]],"ltp":50.0,"tv":37.75,"id":7226819},{"batl":[[2,2.36,2]],"ltp":2.32,"tv":3153.94,"id":10107355},{"batb":[[0,7,31.47]],"ltp":7.4,"tv":501.29,"id":22121325}]}]}
{"op":"mcm","clk":"993472295","pt":1580542773548,"mc":[{"id":"1.168133543","rc":[{"batl":[[1,2.34,31.76]],"ltp":2.32,"tv":3153.94,"id":10107355}]}]}
{"op":"mcm","clk":"993472350","pt":1580542774438,"mc":[{"id":"1.168133543","rc":[{"batl":[[2,7,36]],"ltp":3.55,"tv":1586.76,"id":12636},{"batb":[[0,8.4,7.36],[1,8.2,21.67],[2,8,23.54]],"batl":[[0,9.4,4.13],[1,9.6,7.75]],"ltp":8.2,"tv":612.1,"id":10163711}]}]}
{"op":"mcm","clk":"993472416","pt":1580542775543,"mc":[{"id":"1.168133543","rc":[{"batl":[[1,3.65,2],[2,5.5,6.67]],"ltp":3.55,"tv":1586.76,"id":12636}]}]}
{"op":"mcm","clk":"993472465","pt":1580542776250,"mc":[{"id":"1.168133543","rc":[{"batl":[[0,9,6],[1,9.4,4.13],[2,9.6,1.75]],"ltp":8.2,"tv":612.1,"id":10163711}]}]}
{"op":"mcm","clk":"993472532","pt":1580542777242,"mc":[{"id":"1.168133543","rc":[{"batl":[[0,2.3,2],[2,2.38,2]],"ltp":2.32,"tv":3153.94,"id":10107355}]}]}
{"op":"mcm","clk":"993472996","pt":1580542785476,"mc":[{"id":"1.168133543","rc":[{"batb":[[1,80,1.54],[2,75,16]],"ltp":190.0,"tv":20.7,"id":22308007},{"batb":[[1,240,77.59]],"ltp":450.0,"tv":26.52,"id":24270700}]}]}
{"op":"mcm","clk":"993473058","pt":1580542786460,"mc":[{"id":"1.168133543","rc":[{"batb":[[0,90,6.04]],"ltp":190.0,"tv":20.7,"id":22308007},{"batl":[[0,8.8,7.13],[1,10,14.65],[2,10.5,12.74]],"ltp":7.4,"tv":501.29,"id":22121325},{"batb":[[0,95,1.79],[1,90,5.59],[2,80,18.08]],"ltp":95.0,"tv":17.79,"id":26548208},{"batb":[[1,240,77.75]],"ltp":450.0,"tv":26.52,"id":24270700}]}]}
{"op":"mcm","clk":"993473236","pt":1580542789974,"mc":[{"id":"1.168133543","rc":[{"batl":[[1,9.6,1.89],[2,9.8,98.24]],"ltp":8.2,"tv":612.1,"id":10163711}]}]}
{"op":"mcm","clk":"993473528","pt":1580542795459,"mc":[{"id":"1.168133543","rc":[{"batl":[[0,8.8,5.13],[1,9.8,2.49],[2,10,14.16]],"ltp":7.4,"tv":501.29,"id":22121325}]}]}
{"op":"mcm","clk":"993473780","pt":1580542800178,"mc":[{"id":"1.168133543","rc":[{"batb":[[0,90,1.19]],"ltp":190.0,"tv":20.7,"id":22308007}]}]}
{"op":"mcm","clk":"993473922","pt":1580542802390,"mc":[{"id":"1.168133543","rc":[{"batb":[[2,44,1.07]],"ltp":50.0,"tv":37.75,"id":7226819}]}]}
{"op":"mcm","clk":"993473967","pt":1580542803115,"mc":[{"id":"1.168133543","rc":[{"batb":[[0,48,2.23],[2,42,16.86]],"ltp":50.0,"tv":37.75,"id":7226819}]}]}
{"op":"mcm","clk":"993474105","pt":1580542805291,"mc":[{"id":"1.168133543","rc":[{"batb":[[0,8.6,3.47],[1,8.4,7.36],[2,8.2,21.67]],"ltp":8.2,"tv":612.1,"id":10163711},{"batb":[[0,7.2,7.21],[1,7,30.78],[2,6.6,9.6]],"ltp":7.4,"tv":501.29,"id":22121325}]}]}
{"op":"mcm","clk":"993474156","pt":1580542806175,"mc":[{"id":"1.168133543","rc":[{"batb":[[2,80,20.18]],"ltp":95.0,"tv":17.79,"id":26548208},{"batb":[[1,130,2.54],[2,120,78.77]],"ltp":450.0,"tv":29.01,"id":13306150}]}]}
{"op":"mcm","clk":"993474273","pt":1580542808186,"mc":[{"id":"1.168133543","rc":[{"batl":[[0,9.6,5.21],[1,9.8,2]],"ltp":7.4,"tv":501.29,"id":22121325}]}]}
{"op":"mcm","clk":"993474433","pt":1580542811006,"mc":[{"id":"1.168133543","rc":[{"batb":[[0,48,2.6]],"ltp":50.0,"tv":37.75,"id":7226819}]}]}
{"op":"mcm","clk":"993474580","pt":1580542813502,"mc":[{"id":"1.168133543","rc":[{"batl":[[0,9.6,7.21],[1,10,14.16],[2,10.5,12.74]],"ltp":7.4,"tv":501.29,"id":22121325}]}]}
{"op":"mcm","clk":"993474643","pt":1580542814487,"mc":[{"id":"1.168133543","rc":[{"batb":[[1,46,1.08]],"ltp":50.0,"tv":37.75,"id":7226819},{"batb":[[1,7,2.27]],"ltp":7.4,"tv":501.29,"id":22121325},{"batb":[[0,90,6.01],[1,80,20.18],[2,70,1.1]],"ltp":95.0,"tv":17.79,"id":26548208}]}]}
{"op":"mcm","clk":"993474816","pt":1580542817330,"mc":[{"id":"1.168133543","rc":[{"trd":[[3.6,8.22],[3.65,3.78]],"batl":[[0,5.5,6.78],[1,6,42],[2,9.2,9]],"ltp":3.65,"tv":1598.76,"id":12636}],"tv":6030.1}]}
{"op":"mcm","clk":"993474936","pt":1580542819035,"mc":[{"id":"1.168133543","rc":[{"batl":[[0,5.4,4.11],[1,5.5,6.67],[2,6,42]],"ltp":3.65,"tv":1598.76,"id":12636}]}]}
{"op":"mcm","clk":"993475015","pt":1580542820330,"mc":[{"id":"1.168133543","rc":[{"batb":[[0,48,2.23]],"ltp":50.0,"tv":37.75,"id":7226819}]}]}
{"op":"mcm","clk":"993475124","pt":1580542822414,"mc":[{"id":"1.168133543","rc":[{"batb":[[0,3.55,10],[1,3.45,8.99],[2,3.4,12]],"ltp":3.65,"tv":1598.76,"id":12636},{"batl":[[0,9.6,5.21],[1,9.8,2],[2,10,14.16]],"ltp":7.4,"tv":501.29,"id":22121325}]}]}
{"op":"mcm","clk":"993475195","pt":1580542823547,"mc":[{"id":"1.168133543","rc":[{"trd":[[3.55,12]],"batb":[[0,3.55,6]],"ltp":3.55,"tv":1606.76,"id":12636}],"tv":6038.1}]}
{"op":"mcm","clk":"993475429","pt":1580542827438,"mc":[{"id":"1.168133543","rc":[{"batb":[[0,3.6,5],[1,3.55,6],[2,3.45,8.99]],"ltp":3.55,"tv":1606.76,"id":12636},{"batb":[[2,44,1.07]],"ltp":50.0,"tv":37.75,"id":7226819}]}]}
{"op":"mcm","clk":"993475557","pt":1580542829549,"mc":[{"id":"1.168133543","rc":[{"batb":[[1,240,77.59]],"ltp":450.0,"tv":26.52,"id":24270700}]}]}
{"op":"mcm","clk":"993475628","pt":1580542830537,"mc":[{"id":"1.168133543","rc":[{"batl":[[0,5.3,8.19],[1,5.4,4],[2,5.5,6.67]],"ltp":3.55,"tv":1606.76,"id":12636},{"batb":[[1,240,77.75]],"ltp":450.0,"tv":26.52,"id":24270700}]}]}
{"op":"mcm","clk":"993475687","pt":1580542831460,"mc":[{"id":"1.168133543","rc":[{"batl":[[0,5.2,2.11],[1,5.3,8.08],[2,5.4,4]],"ltp":3.55,"tv":1606.76,"id":12636}]}]}
{"op":"mcm","clk":"993475849","pt":1580542834460,"mc":[{"id":"1.168133543","rc":[{"trd":[[2.28,269.51]],"batb":[[0,2.26,16],[1,2.22,6],[2,2.2,101.45]],"ltp":2.28,"tv":3157.94,"id":10107355}],"tv":6042.1}]}
{"op":"mcm","clk":"993475914","pt":1580542835554,"mc":[{"id":"1.168133543","rc":[{"batb":[[1,2.22,12.42]],"ltp":2.28,"tv":3157.94,"id":10107355}]}]}
{"op":"mcm","clk":"993476106","pt":1580542838559,"mc":[{"id":"1.168133543","rc":[{"batl":[[0,5.2,5.14]],"ltp":3.55,"tv":1606.76,"id":12636}]}]}
{"op":"mcm","clk":"993476236","pt":1580542840572,"mc":[{"id":"1.168133543","rc":[{"batb":[[0,3.6,9],[2,3.45,4.99]],"ltp":3.55,"tv":1606.76,"id":12636}]}]}
{"op":"mcm","clk":"993476934","pt":1580542851557,"mc":[{"id":"1.168133543","rc":[{"batl":[[1,5.4,4],[2,5.5,6.67]],"ltp":3.55,"tv":1606.76,"id":12636}]}]}
{"op":"mcm","clk":"993477359","pt":1580542859506,"mc":[{"id":"1.168133543","rc":[{"batl":[[0,9.6,7.21],[1,10,14.16],[2,10.5,12.74]],"ltp":7.4,"tv":501.29,"id":22121325}]}]}
{"op":"mcm","clk":"993477523","pt":1580542862500,"mc":[{"id":"1.168133543","rc":[{"batb":[[0,48,1.4]],"ltp":50.0,"tv":37.75,"id":7226819}]}]}
{"op":"mcm","clk":"993477589","pt":1580542863488,"mc":[{"id":"1.168133543","rc":[{"batb":[[2,44,1.98]],"ltp":50.0,"tv":37.75,"id":7226819}]}]}
{"op":"mcm","clk":"993478068","pt":1580542872226,"mc":[{"id":"1.168133543","rc":[{"batl":[[0,9.4,8.22],[1,9.6,6.59],[2,10,14.16]],"ltp":7.4,"tv":501.29,"id":22121325}]}]}
{"op":"mcm","clk":"993478310","pt":1580542877428,"mc":[{"id":"1.168133543","rc":[{"batl":[[0,9.2,2.45],[1,9.4,7.77],[2,9.6,4.59]],"ltp":7.4,"tv":501.29,"id":22121325}]}]}
{"op":"mcm","clk":"993478511","pt":1580542881435,"mc":[{"id":"1.168133543","rc":[{"batl":[[0,5.1,7.71],[1,5.2,5.03],[2,5.4,4]],"ltp":3.55,"tv":1606.76,"id":12636}]}]}
{"op":"mcm","clk":"993478690","pt":1580542885547,"mc":[{"id":"1.168133543","rc":[{"batl":[[0,5,2.11],[1,5.1,7.6],[2,5.2,3.03]],"ltp":3.55,"tv":1606.76,"id":12636}]}]}
{"op":"mcm","clk":"993479061","pt":1580542893472,"mc":[{"id":"1.168133543","rc":[{"batl":[[0,4.9,8.86],[1,5,2],[2,5.1,7.6]],"ltp":3.55,"tv":1606.76,"id":12636},{"batl":[[0,9,5.21],[1,9.2,2],[2,9.4,7.77]],"ltp":7.4,"tv":501.29,"id":22121325}]}]}
{"op":"mcm","clk":"993479492","pt":1580542901254,"mc":[{"id":"1.168133543","rc":[{"batb":[[1,260,1.45],[2,240,77.4]],"ltp":450.0,"tv":26.52,"id":24270700}]}]}
{"op":"mcm","clk":"993479789","pt":1580542906052,"mc":[{"id":"1.168133543","rc":[{"batl":[[0,4.8,3.14],[1,4.9,8.75],[2,5,2]],"ltp":3.55,"tv":1606.76,"id":12636}]}]}
{"op":"mcm","clk":"993480297","pt":1580542915507,"mc":[{"id":"1.168133543","rc":[{"batl":[[1,5,2],[2,5.1,7.6]],"ltp":3.55,"tv":1606.76,"id":12636},{"batb":[[1,260,1.29]],"ltp":450.0,"tv":26.52,"id":24270700}]}]}
{"op":"mcm","clk":"993480315","pt":1580542915814,"mc":[{"id":"1.168133543","rc":[{"batb":[[1,260,1.45]],"ltp":450.0,"tv":26.52,"id":24270700}]}]}
{"op":"mcm","clk":"993480391","pt":1580542917198,"mc":[{"id":"1.168133543","rc":[{"batb":[[1,240,77.75],[2,180,1.03]],"ltp":450.0,"tv":26.52,"id":24270700}]}]}
{"op":"mcm","clk":"993480710","pt":1580542922097,"mc":[{"id":"1.168133543","rc":[{"batl":[[0,8.8,2.26],[1,9,4.95]],"ltp":7.4,"tv":501.29,"id":22121325}]}]}
{"op":"mcm","clk":"993481068","pt":1580542927348,"mc":[{"id":"1.168133543","rc":[{"batb":[[1,260,1.35],[2,240,77.4]],"ltp":450.0,"tv":26.52,"id":24270700}]}]}
{"op":"mcm","clk":"993481545","pt":1580542935370,"mc":[{"id":"1.168133543","rc":[{"batl":[[1,9.4,7.96],[2,10,14.29]],"ltp":7.4,"tv":501.29,"id":22121325},{"batb":[[1,260,1.19]],"ltp":450.0,"tv":26.52,"id":24270700}]}]}
{"op":"mcm","clk":"993481565","pt":1580542935627,"mc":[{"id":"1.168133543","rc":[{"batb":[[1,260,1.35]],"ltp":450.0,"tv":26.52,"id":24270700}]}]}
{"op":"mcm","clk":"993481815","pt":1580542939372,"mc":[{"id":"1.168133543","rc":[{"trd":[[3.65,4]],"batb":[[0,3.65,5.37],[1,3.6,9],[2,3.55,6]],"batl":[[0,4.7,2],[1,4.8,3.03]],"ltp":3.65,"tv":1606.98,"id":12636}],"tv":6042.32}]}
{"op":"mcm","clk":"993481905","pt":1580542940564,"mc":[{"id":"1.168133543","rc":[{"batl":[[0,4.7,2.2]],"ltp":3.65,"tv":1606.98,"id":12636}]}]}
{"op":"mcm","clk":"993481946","pt":1580542941377,"mc":[{"id":"1.168133543","rc":[{"batl":[[0,4.7,5.58]],"ltp":3.65,"tv":1606.98,"id":12636}]}]}
{"op":"mcm","clk":"993482034","pt":1580542942567,"mc":[{"id":"1.168133543","rc":[{"batb":[[2,3.55,8]],"ltp":3.65,"tv":1606.98,"id":12636}]}]}
{"op":"mcm","clk":"993482907","pt":1580542956884,"mc":[{"id":"1.168133543","rc":[{"batl":[[0,4.6,9.52],[1,4.7,5.38],[2,4.8,3.03]],"ltp":3.65,"tv":1606.98,"id":12636}]}]}
{"op":"mcm","clk":"993483890","pt":1580542971914,"mc":[{"id":"1.168133543","rc":[{"batl":[[0,4.5,3.23],[1,4.6,9.32],[2,4.7,5.38]],"ltp":3.65,"tv":1606.98,"id":12636}]}]}
{"op":"mcm","clk":"993484077","pt":1580542974499,"mc":[{"id":"1.168133543","rc":[{"batl":[[0,4.5,3.03]],"ltp":3.65,"tv":1606.98,"id":12636}]}]}
{"op":"mcm","clk":"993484115","pt":1580542975018,"mc":[{"id":"1.168133543","rc":[{"batl":[[0,4.5,3.23]],"ltp":3.65,"tv":1606.98,"id":12636},{"trd":[[2.26,223.18]],"batb":[[0,2.26,14]],"ltp":2.26,"tv":3161.94,"id":10107355}],"tv":6046.32}]}
{"op":"mcm","clk":"993484228","pt":1580542977022,"mc":[{"id":"1.168133543","rc":[{"batl":[[1,4.7,5.38],[2,5.1,7.6]],"ltp":3.65,"tv":1606.98,"id":12636}]}]}
{"op":"mcm","clk":"993484380","pt":1580542979455,"mc":[{"id":"1.168133543","rc":[{"trd":[[2.3,618.63]],"batl":[[0,2.34,31.8],[1,2.38,2],[2,2.42,5.5]],"ltp":2.3,"tv":3165.86,"id":10107355}],"tv":6050.24}]}
{"op":"mcm","clk":"993484710","pt":1580542983538,"mc":[{"id":"1.168133543","rc":[{"batl":[[0,2.38,2.04],[1,2.42,5.5],[2,2.46,21]],"ltp":2.3,"tv":3165.86,"id":10107355}]}]}
{"op":"mcm","clk":"993484796","pt":1580542984523,"mc":[{"id":"1.168133543","rc":[{"batl":[[1,9.8,98.47],[2,10,51.32]],"ltp":8.2,"tv":612.1,"id":10163711}]}]}
{"op":"mcm","clk":"993484881","pt":1580542985556,"mc":[{"id":"1.168133543","rc":[{"batl":[[0,2.38,2],[2,2.46,35.91]],"ltp":2.3,"tv":3165.86,"id":10107355}]}]}
{"op":"mcm","clk":"993484942","pt":1580542986430,"mc":[{"id":"1.168133543","rc":[{"batl":[[0,2.38,2.04],[2,2.46,33.2]],"ltp":2.3,"tv":3165.86,"id":10107355}]}]}
{"op":"mcm","clk":"993485327","pt":1580542993546,"mc":[{"id":"1.168133543","rc":[{"batl":[[0,4.4,2.2],[1,4.5,3.03],[2,4.7,3.38]],"ltp":3.65,"tv":1606.98,"id":12636}]}]}
{"op":"mcm","clk":"993485495","pt":1580542996448,"mc":[{"id":"1.168133543","rc":[{"batb":[[1,260,1.19]],"ltp":450.0,"tv":26.52,"id":24270700}]}]}
{"op":"mcm","clk":"993485560","pt":1580542997477,"mc":[{"id":"1.168133543","rc":[{"batl":[[0,4.3,10.16],[1,4.4,2],[2,4.5,3.03]],"ltp":3.65,"tv":1606.98,"id":12636},{"batb":[[1,260,1.35]],"ltp":450.0,"tv":26.52,"id":24270700}]}]}
{"op":"mcm","clk":"993485936","pt":1580543003877,"mc":[{"id":"1.168133543","rc":[{"batl":[[0,2.38,2],[1,2.42,5.54]],"ltp":2.3,"tv":3165.86,"id":10107355}]}]}
{"op":"mcm","clk":"993486028","pt":1580543005479,"mc":[{"id":"1.168133543","rc":[{"batl":[[2,4.7,3.38]],"ltp":3.65,"tv":1606.98,"id":12636}]}]}
{"op":"mcm","clk":"993486062","pt":1580543006096,"mc":[{"id":"1.168133543","rc":[{"batl":[[0,4.2,3.23],[1,4.3,9.96],[2,4.4,2]],"ltp":3.65,"tv":1606.98,"id":12636}]}]}
{"op":"mcm","clk":"993486400","pt":1580543012968,"mc":[{"id":"1.168133543","rc":[{"batl":[[0,9.2,2.45],[1,9.4,7.77]],"ltp":7.4,"tv":501.29,"id":22121325}]}]}
{"op":"mcm","clk":"993486469","pt":1580543014566,"mc":[{"id":"1.168133543","rc":[{"batl":[[0,4.1,51.58],[1,4.2,3.23],[2,4.3,9.96]],"ltp":3.65,"tv":1606.98,"id":12636},{"batl":[[0,160,3.54]],"ltp":190.0,"tv":20.7,"id":22308007},{"batl":[[0,2.38,13.61],[1,2.4,105.57],[2,2.42,5.5]],"ltp":2.3,"tv":3165.86,"id":10107355}]}]}
{"op":"mcm","clk":"993486524","pt":1580543015499,"mc":[{"id":"1.168133543","rc":[{"batl":[[0,4,4],[1,4.1,51.58],[2,4.2,3.23]],"ltp":3.65,"tv":1606.98,"id":12636},{"batl":[[0,2.38,24.95]],"ltp":2.3,"tv":3165.86,"id":10107355}]}]}
{"op":"mcm","clk":"993486616","pt":1580543017307,"mc":[{"id":"1.168133543","rc":[{"batl":[[0,2.36,2],[1,2.38,24.95],[2,2.4,105.57]],"ltp":2.3,"tv":3165.86,"id":10107355},{"batb":[[1,260,1.19]],"ltp":450.0,"tv":26.52,"id":24270700}]}]}
{"op":"mcm","clk":"993486685","pt":1580543018387,"mc":[{"id":"1.168133543","rc":[{"batl":[[0,9,5.21],[1,9.2,2],[2,9.4,7.77]],"ltp":7.4,"tv":501.29,"id":22121325},{"batb":[[1,260,1.35]],"ltp":450.0,"tv":26.52,"id":24270700}]}]}
{"op":"mcm","clk":"993486757","pt":1580543019481,"mc":[{"id":"1.168133543","rc":[{"batl":[[0,4,18]],"ltp":3.65,"tv":1606.98,"id":12636},{"batl":[[1,2.38,44.95]],"ltp":2.3,"tv":3165.86,"id":10107355}]}]}
{"op":"mcm","clk":"993486843","pt":1580543020978,"mc":[{"id":"1.168133543","rc":[{"batl":[[0,2.36,2.04],[2,2.4,105.53]],"ltp":2.3,"tv":3165.86,"id":10107355}]}]}
{"op":"mcm","clk":"993487064","pt":1580543024498,"mc":[{"id":"1.168133543","rc":[{"batl":[[0,2.34,2.04],[1,2.36,2],[2,2.38,44.95]],"ltp":2.3,"tv":3165.86,"id":10107355}]}]}
{"op":"mcm","clk":"993487340","pt":1580543029519,"mc":[{"id":"1.168133543","rc":[{"batl":[[1,4.2,3.23],[2,4.4,2]],"ltp":3.65,"tv":1606.98,"id":12636}]}]}
{"op":"mcm","clk":"993487372","pt":1580543030141,"mc":[{"id":"1.168133543","rc":[{"batl":[[0,3.95,53.54],[1,4,18],[2,4.2,3.23]],"ltp":3.65,"tv":1606.98,"id":12636},{"batl":[[1,2.36,109.31]],"ltp":2.3,"tv":3165.86,"id":10107355},{"batl":[[0,8.6,6.86],[1,8.8,35.14],[2,9,4.95]],"ltp":7.4,"tv":501.29,"id":22121325}]}]}
{"op":"mcm","clk":"993487411","pt":1580543030914,"mc":[{"id":"1.168133543","rc":[{"batl":[[0,2.34,13.9],[2,2.38,33.61]],"ltp":2.3,"tv":3165.86,"id":10107355}]}]}
{"op":"mcm","clk":"993487484","pt":1580543032300,"mc":[{"id":"1.168133543","rc":[{"batl":[[2,4.2,3.03]],"ltp":3.65,"tv":1606.98,"id":12636}]}]}
{"op":"mcm","clk":"993487607","pt":1580543034415,"mc":[{"id":"1.168133543","rc":[{"batl":[[1,9.6,3.71],[2,9.8,102.38]],"ltp":8.2,"tv":612.1,"id":10163711}]}]}
{"op":"mcm","clk":"993487739","pt":1580543036535,"mc":[{"id":"1.168133543","rc":[{"batl":[[0,8.6,7.12],[1,8.8,34.88]],"ltp":7.4,"tv":501.29,"id":22121325}]}]}
{"op":"mcm","clk":"993487862","pt":1580543038547,"mc":[{"id":"1.168133543","rc":[{"batl":[[0,3.9,4],[1,3.95,53.54],[2,4,14]],"ltp":3.65,"tv":1606.98,"id":12636},{"batl":[[2,9.2,2]],"ltp":7.4,"tv":501.29,"id":22121325}]}]}
{"op":"mcm","clk":"993487898","pt":1580543039111,"mc":[{"id":"1.168133543","rc":[{"batl":[[0,3.85,3.03],[1,3.9,4],[2,3.95,53.54]],"ltp":3.65,"tv":1606.98,"id":12636}]}]}
{"op":"mcm","clk":"993487991","pt":1580543040506,"mc":[{"id":"1.168133543","rc":[{"batl":[[0,8.6,9.12],[2,9.4,7.77]],"ltp":7.4,"tv":501.29,"id":22121325}]}]}
{"op":"mcm","clk":"993488117","pt":1580543042415,"mc":[{"id":"1.168133543","rc":[{"batl":[[2,2.38,13.61]],"ltp":2.3,"tv":3165.86,"id":10107355}]}]}
{"op":"mcm","clk":"993488189","pt":1580543043548,"mc":[{"id":"1.168133543","rc":[{"batl":[[2,4.4,2]],"ltp":3.65,"tv":1606.98,"id":12636},{"batl":[[1,2.36,2]],"ltp":2.3,"tv":3165.86,"id":10107355},{"batl":[[0,8.4,36.81],[1,8.6,8.86]],"ltp":7.4,"tv":501.29,"id":22121325}]}]}
{"op":"mcm","clk":"993488235","pt":1580543044320,"mc":[{"id":"1.168133543","rc":[{"batl":[[0,2.34,2.04]],"ltp":2.3,"tv":3165.86,"id":10107355}]}]}
{"op":"mcm","clk":"993488351","pt":1580543046744,"mc":[{"id":"1.168133543","rc":[{"batl":[[2,4.7,3.38]],"ltp":3.65,"tv":1606.98,"id":12636}]}]}
{"op":"mcm","clk":"993488555","pt":1580543050519,"mc":[{"id":"1.168133543","rc":[{"batl":[[2,4.9,51]],"ltp":3.65,"tv":1606.98,"id":12636}]}]}
{"op":"mcm","clk":"993488795","pt":1580543055000,"mc":[{"id":"1.168133543","rc":[{"batl":[[2,2.38,11.61]],"ltp":2.3,"tv":3165.86,"id":10107355}]}]}
{"op":"mcm","clk":"993488997","pt":1580543058499,"mc":[{"id":"1.168133543","rc":[{"batl":[[0,8.2,2],[1,8.4,36.81],[2,8.6,6.86]],"ltp":7.4,"tv":501.29,"id":22121325},{"batb":[[1,260,1.19]],"ltp":450.0,"tv":26.52,"id":24270700}]}]}
{"op":"mcm","clk":"993489055","pt":1580543059483,"mc":[{"id":"1.168133543","rc":[{"batb":[[1,260,1.35]],"ltp":450.0,"tv":26.52,"id":24270700}]}]}
{"op":"mcm","clk":"993489102","pt":1580543060503,"mc":[{"id":"1.168133543","rc":[{"batl":[[0,8.2,2.26],[1,8.4,36.54]],"ltp":7.4,"tv":501.29,"id":22121325}]}]}
{"op":"mcm","clk":"993489145","pt":1580543061528,"mc":[{"id":"1.168133543","rc":[{"batb":[[0,3.7,4.75],[1,3.65,5.37],[2,3.6,9]],"batl":[[1,4.9,51],[2,5.1,7.6]],"ltp":3.65,"tv":1606.98,"id":12636}]}]}
{"op":"mcm","clk":"993489884","pt":1580543073544,"mc":[{"id":"1.168133543","rc":[{"batl":[[0,4.9,51],[1,5.1,7.6],[2,5.5,6.67]],"ltp":3.65,"tv":1606.98,"id":12636}]}]}
{"op":"mcm","clk":"993490007","pt":1580543075495,"mc":[{"id":"1.168133543","rc":[{"batl":[[0,5.1,7.6],[1,5.5,27.21],[2,6,42]],"ltp":3.65,"tv":1606.98,"id":12636}]}]}
{"op":"mcm","clk":"993490147","pt":1580543077549,"mc":[{"id":"1.168133543","rc":[{"batb":[[0,3.7,8.75],[2,3.6,5]],"ltp":3.65,"tv":1606.98,"id":12636}]}]}
{"op":"mcm","clk":"993490334","pt":1580543080331,"mc":[{"id":"1.168133543","rc":[{"batl":[[0,5.1,7.78]],"ltp":3.65,"tv":1606.98,"id":12636}]}]}
{"op":"mcm","clk":"993490768","pt":1580543086542,"mc":[{"id":"1.168133543","rc":[{"batl":[[0,160,3.03]],"ltp":190.0,"tv":20.7,"id":22308007},{"batl":[[1,8.6,6.86],[2,9.4,7.77]],"ltp":7.4,"tv":501.29,"id":22121325}]}]}
{"op":"mcm","clk":"993491415","pt":1580543097539,"mc":[{"id":"1.168133543","rc":[{"batl":[[2,9.6,26.3]],"ltp":7.4,"tv":501.29,"id":22121325}]}]}
{"op":"mcm","clk":"993491605","pt":1580543099965,"mc":[{"id":"1.168133543","rc":[{"batb":[[0,3.75,1.65],[1,3.7,8.75],[2,3.65,5.37]],"ltp":3.65,"tv":1606.98,"id":12636}]}]}
{"op":"mcm","clk":"993491672","pt":1580543100780,"mc":[{"id":"1.168133543","rc":[{"batb":[[2,3.6,5]],"ltp":3.65,"tv":1606.98,"id":12636}]}]}
{"op":"mcm","clk":"993491918","pt":1580543104542,"mc":[{"id":"1.168133543","rc":[{"batb":[[1,130,6.54]],"ltp":450.0,"tv":29.01,"id":13306150}]}]}
{"op":"mcm","clk":"993491988","pt":1580543105572,"mc":[{"id":"1.168133543","rc":[{"batl":[[1,5.5,6.67],[2,7,36]],"ltp":3.65,"tv":1606.98,"id":12636},{"batl":[[2,10,14.46]],"ltp":7.4,"tv":501.29,"id":22121325}]}]}
{"op":"mcm","clk":"993492114","pt":1580543107474,"mc":[{"id":"1.168133543","rc":[{"batl":[[0,5,3.21]],"ltp":3.65,"tv":1606.98,"id":12636}]}]}
{"op":"mcm","clk":"993493200","pt":1580543123493,"mc":[{"id":"1.168133543","rc":[{"batb":[[1,3.7,4.75],[2,3.65,4]],"ltp":3.65,"tv":1606.98,"id":12636}]}]}
{"op":"mcm","clk":"993493874","pt":1580543133489,"mc":[{"id":"1.168133543","rc":[{"batb":[[1,3.7,8.75],[2,3.6,5]],"ltp":3.65,"tv":1606.98,"id":12636}]}]}
{"op":"mcm","clk":"993493992","pt":1580543135088,"mc":[{"id":"1.168133543","rc":[{"batl":[[2,8,31]],"ltp":3.65,"tv":1606.98,"id":12636}]}]}
{"op":"mcm","clk":"993494133","pt":1580543137406,"mc":[{"id":"1.168133543","rc":[{"batl":[[0,4.9,7.78],[1,5,3.03],[2,5.5,6.67]],"ltp":3.65,"tv":1606.98,"id":12636}]}]}
{"op":"mcm","clk":"993494424","pt":1580543141515,"mc":[{"id":"1.168133543","rc":[{"batl":[[0,4.8,8.92],[1,4.9,7.78],[2,5,3.03]],"ltp":3.65,"tv":1606.98,"id":12636}]}]}
{"op":"mcm","clk":"993494491","pt":1580543142491,"mc":[{"id":"1.168133543","rc":[{"trd":[[3.7,9.5],[3.75,3.3]],"batb":[[0,3.65,4],[1,3.6,5],[2,3.55,8]],"batl":[[0,3.7,4.01],[1,4.8,8.92],[2,4.9,7.78]],"ltp":3.7,"tv":1619.78,"id":12636}],"tv":6063.03}]}
{"op":"mcm","clk":"993494551","pt":1580543143513,"mc":[{"id":"1.168133543","rc":[{"trd":[[3.7,17.51]],"batl":[[0,4.6,8.18],[1,4.7,3.03],[2,4.8,8.92]],"ltp":3.7,"tv":1627.79,"id":12636},{"batl":[[0,2.34,110.27]],"ltp":2.3,"tv":3165.86,"id":10107355},{"batl":[[1,8.4,36.54],[2,8.6,6.86]],"ltp":7.4,"tv":501.29,"id":22121325}],"tv":6071.05}]}
{"op":"mcm","clk":"993494608","pt":1580543144492,"mc":[{"id":"1.168133543","rc":[{"batl":[[0,160,3.54]],"ltp":190.0,"tv":20.7,"id":22308007},{"batl":[[0,2.32,11.84],[1,2.34,110.23],[2,2.36,2]],"ltp":2.3,"tv":3165.86,"id":10107355}]}]}
{"op":"mcm","clk":"993494883","pt":1580543149726,"mc":[{"id":"1.168133543","rc":[{"batl":[[0,4.6,8.38]],"ltp":3.7,"tv":1627.79,"id":12636}]}]}
{"op":"mcm","clk":"993494954","pt":1580543151326,"mc":[{"id":"1.168133543","rc":[{"batl":[[0,4.7,3.23],[1,4.8,8.92],[2,4.9,7.6]],"ltp":3.7,"tv":1627.79,"id":12636},{"batl":[[0,2.32,31.84]],"ltp":2.3,"tv":3165.86,"id":10107355}]}]}
{"op":"mcm","clk":"993495149","pt":1580543154517,"mc":[{"id":"1.168133543","rc":[{"batl":[[0,4.6,2.2],[1,4.7,3.03],[2,4.8,8.92]],"ltp":3.7,"tv":1627.79,"id":12636}]}]}
{"op":"mcm","clk":"993495389","pt":1580543158547,"mc":[{"id":"1.168133543","rc":[{"batl":[[1,2.34,2]],"ltp":2.3,"tv":3165.86,"id":10107355}]}]}
{"op":"mcm","clk":"993495502","pt":1580543160341,"mc":[{"id":"1.168133543","rc":[{"batl":[[0,2.32,20.04]],"ltp":2.3,"tv":3165.86,"id":10107355}]}]}
{"op":"mcm","clk":"993495647","pt":1580543162548,"mc":[{"id":"1.168133543","rc":[{"batl":[[0,4.5,9.72],[1,4.6,2],[2,4.7,3.03]],"ltp":3.7,"tv":1627.79,"id":12636}]}]}
{"op":"mcm","clk":"993495848","pt":1580543165534,"mc":[{"id":"1.168133543","rc":[{"trd":[[7.2,10.42]],"batb":[[0,7.2,4.21]],"ltp":7.2,"tv":507.29,"id":22121325}],"tv":6077.05}]}
{"op":"mcm","clk":"993496680","pt":1580543178466,"mc":[{"id":"1.168133543","rc":[{"batl":[[0,2.34,2.04],[1,2.36,2],[2,2.38,20.32]],"ltp":2.3,"tv":3165.86,"id":10107355}]}]}
{"op":"mcm","clk":"993496764","pt":1580543179555,"mc":[{"id":"1.168133543","rc":[{"batb":[[0,7,2.27],[1,6.8,7.35],[2,6.6,9.18]],"ltp":7.2,"tv":507.29,"id":22121325}]}]}
{"op":"mcm","clk":"993496865","pt":1580543181142,"mc":[{"id":"1.168133543","rc":[{"batl":[[2,2.38,11.61]],"ltp":2.3,"tv":3165.86,"id":10107355},{"batb":[[1,6.8,4.88]],"ltp":7.2,"tv":507.29,"id":22121325}]}]}
{"op":"mcm","clk":"993496945","pt":1580543182517,"mc":[{"id":"1.168133543","rc":[{"batl":[[0,8.2,4.2]],"ltp":7.2,"tv":507.29,"id":22121325}]}]}
{"op":"mcm","clk":"993497185","pt":1580543186536,"mc":[{"id":"1.168133543","rc":[{"batl":[[1,8.6,6.86],[2,9.6,26.3]],"ltp":7.2,"tv":507.29,"id":22121325}]}]}
{"op":"mcm","clk":"993497188","pt":1580543186642,"mc":[{"id":"1.168133543","rc":[{"batl":[[0,2.34,110.27]],"ltp":2.3,"tv":3165.86,"id":10107355},{"batl":[[0,8,38.63],[1,8.2,3.94],[2,8.6,6.86]],"ltp":7.2,"tv":507.29,"id":22121325}]}]}
{"op":"mcm","clk":"993498446","pt":1580543201498,"mc":[{"id":"1.168133543","rc":[{"batl":[[0,2.34,2.04]],"ltp":2.3,"tv":3165.86,"id":10107355}]}]}
{"op":"mcm","clk":"993498510","pt":1580543202483,"mc":[{"id":"1.168133543","rc":[{"batl":[[0,2.34,13.9],[1,2.36,109.31]],"ltp":2.3,"tv":3165.86,"id":10107355}]}]}
{"op":"mcm","clk":"993498909","pt":1580543205375,"mc":[{"id":"1.168133543","rc":[{"batl":[[0,2.34,33.9]],"ltp":2.3,"tv":3165.86,"id":10107355}]}]}
{"op":"mcm","clk":"993498947","pt":1580543206087,"mc":[{"id":"1.168133543","rc":[{"batl":[[0,3.95,9.09],[1,4,40],[2,4.5,9.72]],"ltp":3.7,"tv":1627.79,"id":12636}]}]}
{"op":"mcm","clk":"993499084","pt":1580543208301,"mc":[{"id":"1.168133543","rc":[{"batb":[[0,3.65,9.48]],"batl":[[0,3.9,2],[1,3.95,9.09],[2,4,40]],"ltp":3.7,"tv":1627.79,"id":12636},{"batl":[[0,7.8,2],[1,8,38.63],[2,8.2,1.94]],"ltp":7.2,"tv":507.29,"id":22121325}]}]}
{"op":"mcm","clk":"993499538","pt":1580543215487,"mc":[{"id":"1.168133543","rc":[{"batl":[[1,2.36,2]],"ltp":2.3,"tv":3165.86,"id":10107355},{"batl":[[1,8.2,2.2],[2,8.6,14.93]],"ltp":7.2,"tv":507.29,"id":22121325}]}]}
{"op":"mcm","clk":"993499651","pt":1580543216571,"mc":[{"id":"1.168133543","rc":[{"batl":[[0,3.9,56.23]],"ltp":3.7,"tv":1627.79,"id":12636},{"batl":[[0,2.34,22.04]],"ltp":2.3,"tv":3165.86,"id":10107355},{"batl":[[2,8.4,36.54]],"ltp":7.2,"tv":507.29,"id":22121325}]}]}
{"op":"mcm","clk":"993499818","pt":1580543218192,"mc":[{"id":"1.168133543","rc":[{"batl":[[0,3.85,3.03],[1,3.9,56.23],[2,3.95,9.09]],"ltp":3.7,"tv":1627.79,"id":12636}]}]}
{"op":"mcm","clk":"993500059","pt":1580543221487,"mc":[{"id":"1.168133543","rc":[{"batl":[[0,2.34,2.04]],"ltp":2.3,"tv":3165.86,"id":10107355}]}]}
{"op":"mcm","clk":"993500197","pt":1580543223499,"mc":[{"id":"1.168133543","rc":[{"batb":[[1,260,1.19]],"ltp":450.0,"tv":26.52,"id":24270700}]}]}
{"op":"mcm","clk":"993500225","pt":1580543223909,"mc":[{"id":"1.168133543","rc":[{"batb":[[1,260,1.35]],"ltp":450.0,"tv":26.52,"id":24270700}]}]}
{"op":"mcm","clk":"993500562","pt":1580543228288,"mc":[{"id":"1.168133543","rc":[{"batl":[[0,3.85,17.03]],"ltp":3.7,"tv":1627.79,"id":12636}]}]}
{"op":"mcm","clk":"993500667","pt":1580543229528,"mc":[{"id":"1.168133543","rc":[{"batl":[[1,3.9,2]],"ltp":3.7,"tv":1627.79,"id":12636},{"batl":[[2,8.6,6.86]],"ltp":7.2,"tv":507.29,"id":22121325}]}]}
{"op":"mcm","clk":"993500675","pt":1580543229630,"mc":[{"id":"1.168133543","rc":[{"batl":[[1,8,38.63],[2,8.2,1.94]],"ltp":7.2,"tv":507.29,"id":22121325}]}]}
{"op":"mcm","clk":"993501046","pt":1580543236131,"mc":[{"id":"1.168133543","rc":[{"batl":[[0,3.85,3.03]],"ltp":3.7,"tv":1627.79,"id":12636}]}]}
{"op":"mcm","clk":"993501615","pt":1580543244535,"mc":[{"id":"1.168133543","rc":[{"batl":[[1,8.2,2.2],[2,8.6,6.86]],"ltp":7.2,"tv":507.29,"id":22121325}]}]}
{"op":"mcm","clk":"993501666","pt":1580543245354,"mc":[{"id":"1.168133543","rc":[{"batl":[[2,8.4,36.54]],"ltp":7.2,"tv":507.29,"id":22121325}]}]}
{"op":"mcm","clk":"993502046","pt":1580543251434,"mc":[{"id":"1.168133543","rc":[{"batl":[[0,3.9,5.03],[1,3.95,9.09],[2,4,40]],"ltp":3.7,"tv":1627.79,"id":12636}]}]}
{"op":"mcm","clk":"993502105","pt":1580543252453,"mc":[{"id":"1.168133543","rc":[{"batl":[[0,3.85,40],[1,3.9,5.03],[2,3.95,9.09]],"ltp":3.7,"tv":1627.79,"id":12636}]}]}
{"op":"mcm","clk":"993502677","pt":1580543258550,"mc":[{"id":"1.168133543","rc":[{"batl":[[2,8.6,6.86]],"ltp":7.2,"tv":507.29,"id":22121325}]}]}
{"op":"mcm","clk":"993502697","pt":1580543258758,"mc":[{"id":"1.168133543","rc":[{"batl":[[1,8,38.63],[2,8.2,1.94]],"ltp":7.2,"tv":507.29,"id":22121325}]}]}
{"op":"mcm","clk":"993502965","pt":1580543262172,"mc":[{"id":"1.168133543","rc":[{"batl":[[1,3.9,3.03]],"ltp":3.7,"tv":1627.79,"id":12636}]}]}
{"op":"mcm","clk":"993503055","pt":1580543263566,"mc":[{"id":"1.168133543","rc":[{"batb":[[1,260,1.19]],"ltp":450.0,"tv":26.52,"id":24270700}]}]}
{"op":"mcm","clk":"993503118","pt":1580543264546,"mc":[{"id":"1.168133543","rc":[{"batb":[[1,260,1.35]],"ltp":450.0,"tv":26.52,"id":24270700}]}]}
{"op":"mcm","clk":"993503307","pt":1580543267544,"mc":[{"id":"1.168133543","rc":[{"batl":[[0,3.9,43.03],[1,4.3,6],[2,4.4,57]],"ltp":3.7,"tv":1627.79,"id":12636}]}]}
{"op":"mcm","clk":"993503403","pt":1580543269076,"mc":[{"id":"1.168133543","rc":[{"batl":[[1,4.2,4.71],[2,4.3,6]],"ltp":3.7,"tv":1627.79,"id":12636}]}]}
{"op":"mcm","clk":"993503711","pt":1580543273053,"mc":[{"id":"1.168133543","rc":[{"batl":[[1,8.2,2.2],[2,8.4,36.54]],"ltp":7.2,"tv":507.29,"id":22121325}]}]}
{"op":"mcm","clk":"993503875","pt":1580543275474,"mc":[{"id":"1.168133543","rc":[{"batb":[[0,3.7,10],[1,3.65,9.48],[2,3.6,5]],"ltp":3.7,"tv":1627.79,"id":12636}]}]}
{"op":"mcm","clk":"993504339","pt":1580543281876,"mc":[{"id":"1.168133543","rc":[{"batb":[[0,3.7,14],[1,3.65,5.48]],"ltp":3.7,"tv":1627.79,"id":12636}]}]}
{"op":"mcm","clk":"993504427","pt":1580543283486,"mc":[{"id":"1.168133543","rc":[{"trd":[[3.9,93.62]],"batb":[[0,3.75,2],[1,3.7,14],[2,3.65,5.48]],"batl":[[0,4.3,6],[1,4.4,57],[2,4.9,7.6]],"ltp":3.9,"tv":1713.85,"id":12636}],"tv":6163.1}]}
{"op":"mcm","clk":"993504500","pt":1580543284466,"mc":[{"id":"1.168133543","rc":[{"batb":[[0,3.75,6]],"ltp":3.9,"tv":1713.85,"id":12636}]}]}
{"op":"mcm","clk":"993504584","pt":1580543285500,"mc":[{"id":"1.168133543","rc":[{"batl":[[1,4.9,7.6],[2,5.4,46]],"ltp":3.9,"tv":1713.85,"id":12636},{"batb":[[1,260,1.19]],"ltp":450.0,"tv":26.52,"id":24270700}]}]}
{"op":"mcm","clk":"993504671","pt":1580543286572,"mc":[{"id":"1.168133543","rc":[{"batl":[[2,8.6,6.86]],"ltp":7.2,"tv":507.29,"id":22121325},{"batb":[[1,260,1.35]],"ltp":450.0,"tv":26.52,"id":24270700}]}]}
{"op":"mcm","clk":"993504699","pt":1580543286879,"mc":[{"id":"1.168133543","rc":[{"batl":[[0,4.2,50.36],[1,4.3,6],[2,4.9,7.6]],"ltp":3.9,"tv":1713.85,"id":12636},{"batl":[[0,2.34,110.27]],"ltp":2.3,"tv":3165.86,"id":10107355},{"batl":[[1,8,38.63],[2,8.2,1.94]],"ltp":7.2,"tv":507.29,"id":22121325}]}]}
{"op":"mcm","clk":"993504818","pt":1580543288484,"mc":[{"id":"1.168133543","rc":[{"batl":[[0,2.32,11.84],[1,2.34,110.23],[2,2.36,2]],"ltp":2.3,"tv":3165.86,"id":10107355}]}]}
{"op":"mcm","clk":"993505073","pt":1580543291491,"mc":[{"id":"1.168133543","rc":[{"batb":[[0,3.8,2],[1,3.75,6],[2,3.7,14]],"ltp":3.9,"tv":1713.85,"id":12636}]}]}
{"op":"mcm","clk":"993505136","pt":1580543292371,"mc":[{"id":"1.168133543","rc":[{"trd":[[3.8,4]],"batb":[[0,3.75,6],[1,3.7,14],[2,3.65,5.48]],"batl":[[0,3.8,4],[1,4.2,50.36],[2,4.3,6]],"ltp":3.8,"tv":1717.85,"id":12636}],"tv":6167.1}]}
{"op":"mcm","clk":"993505221","pt":1580543293404,"mc":[{"id":"1.168133543","rc":[{"trd":[[2.26,223.48]],"batb":[[0,2.26,13.85]],"batl":[[0,2.32,31.84]],"ltp":2.26,"tv":3166.17,"id":10107355}],"tv":6167.41}]}
{"op":"mcm","clk":"993505372","pt":1580543295518,"mc":[{"id":"1.168133543","rc":[{"batl":[[2,4.9,7.6]],"ltp":3.8,"tv":1717.85,"id":12636}]}]}
{"op":"mcm","clk":"993505434","pt":1580543296496,"mc":[{"id":"1.168133543","rc":[{"trd":[[2.26,223.79]],"batb":[[0,2.26,13.7]],"ltp":2.26,"tv":3166.47,"id":10107355}],"tv":6167.71}]}
{"op":"mcm","clk":"993505657","pt":1580543300316,"mc":[{"id":"1.168133543","rc":[{"trd":[[3.8,12]],"batl":[[0,4.2,50.36],[1,4.8,9.5],[2,4.9,9.98]],"ltp":3.8,"tv":1725.85,"id":12636}],"tv":6175.71}]}
{"op":"mcm","clk":"993505729","pt":1580543301504,"mc":[{"id":"1.168133543","rc":[{"batl":[[0,4.8,9.5],[1,4.9,9.98],[2,5.4,46]],"ltp":3.8,"tv":1725.85,"id":12636},{"batl":[[1,2.34,2]],"ltp":2.26,"tv":3166.47,"id":10107355},{"batl":[[1,8.2,2.2],[2,8.6,11.37]],"ltp":7.2,"tv":507.29,"id":22121325}]}]}
{"op":"mcm","clk":"993505792","pt":1580543302532,"mc":[{"id":"1.168133543","rc":[{"batl":[[2,8.4,36.54]],"ltp":7.2,"tv":507.29,"id":22121325}]}]}
{"op":"mcm","clk":"993505851","pt":1580543303513,"mc":[{"id":"1.168133543","rc":[{"batl":[[0,2.32,20.04]],"ltp":2.26,"tv":3166.47,"id":10107355}]}]}
{"op":"mcm","clk":"993505909","pt":1580543304393,"mc":[{"id":"1.168133543","rc":[{"batl":[[0,4.9,9.98],[1,5.4,46],[2,5.5,6.67]],"ltp":3.8,"tv":1725.85,"id":12636}]}]}
{"op":"mcm","clk":"993505963","pt":1580543305320,"mc":[{"id":"1.168133543","rc":[{"batl":[[0,4.9,7.6],[1,5.4,52.15]],"ltp":3.8,"tv":1725.85,"id":12636},{"batb":[[1,260,1.19]],"ltp":450.0,"tv":26.52,"id":24270700}]}]}
{"op":"mcm","clk":"993506013","pt":1580543306307,"mc":[{"id":"1.168133543","rc":[{"batl":[[1,5.3,2.56],[2,5.4,46]],"ltp":3.8,"tv":1725.85,"id":12636},{"batb":[[2,8,23.54]],"ltp":8.2,"tv":612.1,"id":10163711},{"batb":[[1,260,1.35]],"ltp":450.0,"tv":26.52,"id":24270700}]}]}
{"op":"mcm","clk":"993506136","pt":1580543308524,"mc":[{"id":"1.168133543","rc":[{"batl":[[0,4.9,7.8]],"ltp":3.8,"tv":1725.85,"id":12636}]}]}
{"op":"mcm","clk":"993506507","pt":1580543314198,"mc":[{"id":"1.168133543","rc":[{"batl":[[1,5.4,46],[2,5.5,6.67]],"ltp":3.8,"tv":1725.85,"id":12636},{"batl":[[0,2.34,2.04],[1,2.36,2],[2,2.38,25.25]],"ltp":2.26,"tv":3166.47,"id":10107355}]}]}
{"op":"mcm","clk":"993506581","pt":1580543315532,"mc":[{"id":"1.168133543","rc":[{"batl":[[0,4.8,3.52],[1,4.9,7.6],[2,5.4,46]],"ltp":3.8,"tv":1725.85,"id":12636},{"batl":[[0,160,3.03]],"ltp":190.0,"tv":20.7,"id":22308007},{"batl":[[2,8.6,6.86]],"ltp":7.2,"tv":507.29,"id":22121325}]}]}
{"op":"mcm","clk":"993506653","pt":1580543316513,"mc":[{"id":"1.168133543","rc":[{"batb":[[2,3.6,5]],"batl":[[2,5.5,6.67]],"ltp":3.8,"tv":1725.85,"id":12636}]}]}
{"op":"mcm","clk":"993507322","pt":1580543326525,"mc":[{"id":"1.168133543","rc":[{"batb":[[1,260,1.19]],"ltp":450.0,"tv":26.52,"id":24270700}]}]}
{"op":"mcm","clk":"993507376","pt":1580543327243,"mc":[{"id":"1.168133543","rc":[{"batl":[[0,4.6,8.18],[1,4.7,9.32],[2,4.8,3.32]],"ltp":3.8,"tv":1725.85,"id":12636},{"batb":[[1,260,1.35]],"ltp":450.0,"tv":26.52,"id":24270700}]}]}
{"op":"mcm","clk":"993507536","pt":1580543329565,"mc":[{"id":"1.168133543","rc":[{"batl":[[0,160,3.54]],"ltp":190.0,"tv":20.7,"id":22308007},{"batl":[[0,2.34,110.27],[2,2.38,11.61]],"ltp":2.26,"tv":3166.47,"id":10107355},{"batl":[[1,8,38.63],[2,8.2,1.94]],"ltp":7.2,"tv":507.29,"id":22121325}]}]}
{"op":"mcm","clk":"993507646","pt":1580543331460,"mc":[{"id":"1.168133543","rc":[{"batl":[[0,4.6,8.38],[1,4.7,9.12]],"ltp":3.8,"tv":1725.85,"id":12636}]}]}
{"op":"mcm","clk":"993507953","pt":1580543336457,"mc":[{"id":"1.168133543","rc":[{"trd":[[2.22,223.32],[2.26,251.19]],"batb":[[0,2.22,6.12],[1,2.2,101.45],[2,2.12,6]],"ltp":2.22,"tv":3206.47,"id":10107355}],"tv":6215.71}]}
{"op":"mcm","clk":"993508003","pt":1580543337334,"mc":[{"id":"1.168133543","rc":[{"batb":[[0,2.2,101.45],[1,2.12,6],[2,2.1,119]],"ltp":2.22,"tv":3206.47,"id":10107355}]}]}
{"op":"mcm","clk":"993508081","pt":1580543338561,"mc":[{"id":"1.168133543","rc":[{"batb":[[1,2.14,3.24],[2,2.12,11.27]],"ltp":2.22,"tv":3206.47,"id":10107355}]}]}
{"op":"mcm","clk":"993508135","pt":1580543339334,"mc":[{"id":"1.168133543","rc":[{"batb":[[1,2.14,22.05]],"batl":[[0,2.3,6],[1,2.34,110.27],[2,2.36,2]],"ltp":2.22,"tv":3206.47,"id":10107355}]}]}
{"op":"mcm","clk":"993508446","pt":1580543344565,"mc":[{"id":"1.168133543","rc":[{"batl":[[0,160,3.03]],"ltp":190.0,"tv":20.7,"id":22308007},{"batl":[[1,2.34,2.04]],"ltp":2.22,"tv":3206.47,"id":10107355},{"batl":[[1,8.2,2.2],[2,8.6,11.37]],"ltp":7.2,"tv":507.29,"id":22121325}]}]}
{"op":"mcm","clk":"993508658","pt":1580543347549,"mc":[{"id":"1.168133543","rc":[{"batl":[[1,4.8,3.32],[2,4.9,7.6]],"ltp":3.8,"tv":1725.85,"id":12636},{"batl":[[0,2.3,6.04],[1,2.34,2]],"ltp":2.22,"tv":3206.47,"id":10107355},{"batb":[[1,260,1.19]],"ltp":450.0,"tv":26.52,"id":24270700}]}]}
{"op":"mcm","clk":"993508737","pt":1580543348573,"mc":[{"id":"1.168133543","rc":[{"batb":[[1,260,1.35]],"ltp":450.0,"tv":26.52,"id":24270700}]}]}
{"op":"mcm","clk":"993508893","pt":1580543350374,"mc":[{"id":"1.168133543","rc":[{"batl":[[0,8.8,2],[1,9,6],[2,9.6,3.71]],"ltp":8.2,"tv":612.1,"id":10163711}]}]}
{"op":"mcm","clk":"993509000","pt":1580543351558,"mc":[{"id":"1.168133543","rc":[{"batb":[[2,2.12,5.27]],"ltp":2.22,"tv":3206.47,"id":10107355}]}]}
{"op":"mcm","clk":"993509076","pt":1580543352482,"mc":[{"id":"1.168133543","rc":[{"batl":[[0,8.8,8],[1,9.6,6.07],[2,9.8,102.38]],"ltp":8.2,"tv":612.1,"id":10163711},{"batl":[[2,8.6,6.86]],"ltp":7.2,"tv":507.29,"id":22121325}]}]}
{"op":"mcm","clk":"993509477","pt":1580543358549,"mc":[{"id":"1.168133543","rc":[{"batl":[[0,160,3.54]],"ltp":190.0,"tv":20.7,"id":22308007},{"batl":[[1,8,38.63],[2,8.2,1.94]],"ltp":7.2,"tv":507.29,"id":22121325}]}]}
{"op":"mcm","clk":"993509785","pt":1580543363378,"mc":[{"id":"1.168133543","rc":[{"batl":[[2,5.3,47]],"ltp":3.8,"tv":1725.85,"id":12636}]}]}
{"op":"mcm","clk":"993510133","pt":1580543370084,"mc":[{"id":"1.168133543","rc":[{"batl":[[0,3.9,2],[1,4.8,3.52]],"ltp":3.8,"tv":1725.85,"id":12636},{"batl":[[1,9.6,12.01]],"ltp":8.2,"tv":612.1,"id":10163711}]}]}
{"op":"mcm","clk":"993510220","pt":1580543371573,"mc":[{"id":"1.168133543","rc":[{"batl":[[1,4.8,3.32]],"ltp":3.8,"tv":1725.85,"id":12636}]}]}
{"op":"mcm","clk":"993510309","pt":1580543373060,"mc":[{"id":"1.168133543","rc":[{"batl":[[0,160,3.03]],"ltp":190.0,"tv":20.7,"id":22308007},{"batl":[[1,8.2,2.2],[2,8.6,6.86]],"ltp":7.2,"tv":507.29,"id":22121325}]}]}
{"op":"mcm","clk":"993510377","pt":1580543374187,"mc":[{"id":"1.168133543","rc":[{"batl":[[2,5.2,4.22]],"ltp":3.8,"tv":1725.85,"id":12636},{"batl":[[1,9.6,18.81]],"ltp":8.2,"tv":612.1,"id":10163711},{"batl":[[2,8.6,10.54]],"ltp":7.2,"tv":507.29,"id":22121325}]}]}
{"op":"mcm","clk":"993510646","pt":1580543378499,"mc":[{"id":"1.168133543","rc":[{"batl":[[1,3.95,16],[2,4.8,3.52]],"ltp":3.8,"tv":1725.85,"id":12636}]}]}
{"op":"mcm","clk":"993510711","pt":1580543379478,"mc":[{"id":"1.168133543","rc":[{"batl":[[2,8.6,6.86]],"ltp":7.2,"tv":507.29,"id":22121325}]}]}
{"op":"mcm","clk":"993510959","pt":1580543383284,"mc":[{"id":"1.168133543","rc":[{"batl":[[2,4.8,3.32]],"ltp":3.8,"tv":1725.85,"id":12636}]}]}
{"op":"mcm","clk":"993511271","pt":1580543388571,"mc":[{"id":"1.168133543","rc":[{"batl":[[0,3.9,11.17],[2,4,100]],"ltp":3.8,"tv":1725.85,"id":12636}]}]}
{"op":"mcm","clk":"993511624","pt":1580543393479,"mc":[{"id":"1.168133543","rc":[{"batl":[[0,3.9,9.17]],"ltp":3.8,"tv":1725.85,"id":12636}]}]}
{"op":"mcm","clk":"993511668","pt":1580543394199,"mc":[{"id":"1.168133543","rc":[{"trd":[[3.7,28.51],[3.75,15.3]],"batb":[[0,3.7,8.5],[1,3.6,7.8],[2,3.55,6]],"ltp":3.7,"tv":1748.85,"id":12636}],"tv":6238.71}]}
{"op":"mcm","clk":"993511769","pt":1580543395995,"mc":[{"id":"1.168133543","rc":[{"trd":[[3.9,100.96]],"batl":[[0,3.9,5.5]],"ltp":3.9,"tv":1756.19,"id":12636}],"tv":6246.05}]}
{"op":"mcm","clk":"993511907","pt":1580543398001,"mc":[{"id":"1.168133543","rc":[{"batl":[[1,4.8,3.32],[2,5.2,4.22]],"ltp":3.9,"tv":1756.19,"id":12636}]}]}
{"op":"mcm","clk":"993512295","pt":1580543403303,"mc":[{"id":"1.168133543","rc":[{"batb":[[0,3.7,4.5],[1,3.65,4],[2,3.6,7.8]],"ltp":3.9,"tv":1756.19,"id":12636}]}]}
{"op":"mcm","clk":"993512439","pt":1580543405416,"mc":[{"id":"1.168133543","rc":[{"batb":[[2,3.6,5]],"ltp":3.9,"tv":1756.19,"id":12636},{"batl":[[1,8.6,7.12],[2,9.6,26.3]],"ltp":7.2,"tv":507.29,"id":22121325}]}]}
{"op":"mcm","clk":"993512453","pt":1580543405622,"mc":[{"id":"1.168133543","rc":[{"batl":[[2,10,14.46]],"ltp":7.2,"tv":507.29,"id":22121325}]}]}
{"op":"mcm","clk":"993512587","pt":1580543407492,"mc":[{"id":"1.168133543","rc":[{"batl":[[2,9.8,4.37]],"ltp":7.2,"tv":507.29,"id":22121325}]}]}
{"op":"mcm","clk":"993513127","pt":1580543415034,"mc":[{"id":"1.168133543","rc":[{"batl":[[0,95,5.37]],"ltp":50.0,"tv":37.75,"id":7226819}]}]}
{"op":"mcm","clk":"993513480","pt":1580543420357,"mc":[{"id":"1.168133543","rc":[{"batl":[[0,60,2.02],[1,95,5.35],[2,510,9.15]],"ltp":50.0,"tv":37.75,"id":7226819}]}]}
{"op":"mcm","clk":"993513602","pt":1580543421958,"mc":[{"id":"1.168133543","rc":[{"batb":[[0,3.7,8.5],[1,3.6,5],[2,3.55,6]],"ltp":3.9,"tv":1756.19,"id":12636}]}]}
{"op":"mcm","clk":"993513827","pt":1580543425328,"mc":[{"id":"1.168133543","rc":[{"batl":[[1,65,4],[2,95,5.35]],"ltp":50.0,"tv":37.75,"id":7226819}]}]}
{"op":"mcm","clk":"993514103","pt":1580543429472,"mc":[{"id":"1.168133543","rc":[{"batb":[[2,44,5]],"batl":[[0,60,2.47],[2,95,5.08]],"ltp":50.0,"tv":37.75,"id":7226819},{"trd":[[2.2,55.1]],"batb":[[0,2.2,76.45]],"ltp":2.2,"tv":3256.47,"id":10107355}],"tv":6296.05}]}
{"op":"mcm","clk":"993514162","pt":1580543430454,"mc":[{"id":"1.168133543","rc":[{"batb":[[1,85,6.04],[2,75,16.64]],"ltp":190.0,"tv":20.7,"id":22308007},{"batb":[[1,46,9.26]],"batl":[[0,60,2.45]],"ltp":50.0,"tv":37.75,"id":7226819},{"batl":[[0,7.8,9]],"ltp":7.2,"tv":507.29,"id":22121325},{"batb":[[1,140,3.04],[2,130,6.54]],"ltp":450.0,"tv":29.01,"id":13306150}]}]}
{"op":"mcm","clk":"993514205","pt":1580543431130,"mc":[{"id":"1.168133543","rc":[{"batb":[[0,95,1.79],[1,90,5.59],[2,80,20.18]],"ltp":95.0,"tv":17.79,"id":26548208},{"batb":[[1,270,2.09],[2,260,1.13]],"ltp":450.0,"tv":26.52,"id":24270700}]}]}
{"op":"mcm","clk":"993514272","pt":1580543432261,"mc":[{"id":"1.168133543","rc":[{"batl":[[1,8.4,5.71],[2,8.6,12.6]],"ltp":7.2,"tv":507.29,"id":22121325}]}]}
{"op":"mcm","clk":"993514849","pt":1580543441752,"mc":[{"id":"1.168133543","rc":[{"trd":[[55,7.18]],"batl":[[0,60,2]],"ltp":55.0,"tv":38.65,"id":7226819}],"tv":6296.95}]}
{"op":"mcm","clk":"993515065","pt":1580543444544,"mc":[{"id":"1.168133543","rc":[{"batb":[[1,80,1.54],[2,75,16]],"ltp":190.0,"tv":20.7,"id":22308007},{"batb":[[1,46,1.08]],"ltp":55.0,"tv":38.65,"id":7226819},{"batb":[[1,260,1.35],[2,240,77.4]],"ltp":450.0,"tv":26.52,"id":24270700},{"batb":[[1,130,6.54],[2,120,78.77]],"ltp":450.0,"tv":29.01,"id":13306150}]}]}
{"op":"mcm","clk":"993515120","pt":1580543445367,"mc":[{"id":"1.168133543","rc":[{"batb":[[0,90,6.04]],"ltp":190.0,"tv":20.7,"id":22308007},{"batb":[[0,150,4.79]],"ltp":450.0,"tv":29.01,"id":13306150}]}]}
{"op":"mcm","clk":"993515378","pt":1580543449460,"mc":[{"id":"1.168133543","rc":[{"batb":[[1,80,1.04]],"ltp":190.0,"tv":20.7,"id":22308007},{"batb":[[1,260,1.19]],"ltp":450.0,"tv":26.52,"id":24270700}]}]}
{"op":"mcm","clk":"993515458","pt":1580543450550,"mc":[{"id":"1.168133543","rc":[{"batb":[[1,260,1.35]],"ltp":450.0,"tv":26.52,"id":24270700}]}]}
{"op":"mcm","clk":"993515737","pt":1580543454282,"mc":[{"id":"1.168133543","rc":[{"batl":[[2,70,16]],"ltp":55.0,"tv":38.65,"id":7226819}]}]}
{"op":"mcm","clk":"993515827","pt":1580543455567,"mc":[{"id":"1.168133543","rc":[{"trd":[[3.9,111.96]],"batl":[[0,4.8,3.32],[1,5.2,4.22],[2,5.5,6.67]],"ltp":3.9,"tv":1767.19,"id":12636},{"batl":[[1,8.4,12.85]],"ltp":7.2,"tv":507.29,"id":22121325}],"tv":6307.95}]}
{"op":"mcm","clk":"993516032","pt":1580543458563,"mc":[{"id":"1.168133543","rc":[{"batl":[[1,5.5,6.67],[2,5.7,44]],"ltp":3.9,"tv":1767.19,"id":12636},{"batb":[[0,90,1.19]],"ltp":190.0,"tv":20.7,"id":22308007},{"batl":[[0,60,4.17]],"ltp":55.0,"tv":38.65,"id":7226819},{"batb":[[0,90,6.01],[1,80,20.18],[2,70,1.1]],"ltp":95.0,"tv":17.79,"id":26548208},{"batb":[[0,150,1.95]],"ltp":450.0,"tv":29.01,"id":13306150}]}]}
{"op":"mcm","clk":"993516058","pt":1580543458870,"mc":[{"id":"1.168133543","rc":[{"batl":[[0,4.8,3.52]],"ltp":3.9,"tv":1767.19,"id":12636}]}]}
{"op":"mcm","clk":"993516426","pt":1580543463477,"mc":[{"id":"1.168133543","rc":[{"batb":[[2,44,1.98]],"ltp":55.0,"tv":38.65,"id":7226819}]}]}
{"op":"mcm","clk":"993516477","pt":1580543463991,"mc":[{"id":"1.168133543","rc":[{"batl":[[0,60,2.17],[1,65,6]],"ltp":55.0,"tv":38.65,"id":7226819}]}]}
{"op":"mcm","clk":"993516666","pt":1580543466470,"mc":[{"id":"1.168133543","rc":[{"batl":[[2,6.4,39]],"ltp":3.9,"tv":1767.19,"id":12636}]}]}
{"op":"mcm","clk":"993516726","pt":1580543467292,"mc":[{"id":"1.168133543","rc":[{"trd":[[60,21.42]],"batl":[[0,65,6.26],[1,70,16],[2,95,5.08]],"ltp":60.0,"tv":42.47,"id":7226819}],"tv":6311.77}]}
{"op":"mcm","clk":"993516951","pt":1580543470389,"mc":[{"id":"1.168133543","rc":[{"batl":[[0,65,4.26]],"ltp":60.0,"tv":42.47,"id":7226819}]}]}
{"op":"mcm","clk":"993517026","pt":1580543471478,"mc":[{"id":"1.168133543","rc":[{"batl":[[0,95,5.34],[1,140,2],[2,510,9.15]],"ltp":60.0,"tv":42.47,"id":7226819}]}]}
{"op":"mcm","clk":"993517094","pt":1580543472511,"mc":[{"id":"1.168133543","rc":[{"batb":[[1,80,1.54]],"ltp":190.0,"tv":20.7,"id":22308007},{"batb":[[0,48,1.73]],"ltp":60.0,"tv":42.47,"id":7226819}]}]}
{"op":"mcm","clk":"993517218","pt":1580543474315,"mc":[{"id":"1.168133543","rc":[{"batl":[[0,160,3.54]],"ltp":190.0,"tv":20.7,"id":22308007},{"batl":[[0,95,5.08]],"ltp":60.0,"tv":42.47,"id":7226819}]}]}
{"op":"mcm","clk":"993517441","pt":1580543477695,"mc":[{"id":"1.168133543","rc":[{"batl":[[0,4.7,2.2],[1,4.8,3.32],[2,5.5,6.67]],"ltp":3.9,"tv":1767.19,"id":12636}]}]}
{"op":"mcm","clk":"993518113","pt":1580543488118,"mc":[{"id":"1.168133543","rc":[{"batb":[[0,3.7,4.5],[1,3.65,4],[2,3.6,5]],"ltp":3.9,"tv":1767.19,"id":12636}]}]}
{"op":"mcm","clk":"993518474","pt":1580543493516,"mc":[{"id":"1.168133543","rc":[{"batb":[[1,260,1.19]],"ltp":450.0,"tv":26.52,"id":24270700}]}]}
{"op":"mcm","clk":"993518482","pt":1580543493616,"mc":[{"id":"1.168133543","rc":[{"batl":[[0,4.6,9.52],[1,4.7,2],[2,4.8,3.32]],"ltp":3.9,"tv":1767.19,"id":12636},{"batb":[[1,260,1.35]],"ltp":450.0,"tv":26.52,"id":24270700}]}]}
{"op":"mcm","clk":"993518618","pt":1580543495824,"mc":[{"id":"1.168133543","rc":[{"batl":[[1,510,9.15],[2,550,2]],"ltp":60.0,"tv":42.47,"id":7226819}]}]}
{"op":"mcm","clk":"993518768","pt":1580543498317,"mc":[{"id":"1.168133543","rc":[{"batl":[[0,7.8,7],[1,8.2,2.26],[2,8.4,12.59]],"ltp":7.2,"tv":507.29,"id":22121325}]}]}
{"op":"mcm","clk":"993519088","pt":1580543503248,"mc":[{"id":"1.168133543","rc":[{"trd":[[2.28,273.51]],"ltp":2.28,"tv":3260.47,"id":10107355},{"batl":[[2,8.4,5.45]],"ltp":7.2,"tv":507.29,"id":22121325}],"tv":6315.77}]}
{"op":"mcm","clk":"993519209","pt":1580543505050,"mc":[{"id":"1.168133543","rc":[{"batb":[[0,3.7,6.61]],"ltp":3.9,"tv":1767.19,"id":12636}]}]}
{"op":"mcm","clk":"993519340","pt":1580543507114,"mc":[{"id":"1.168133543","rc":[{"batl":[[0,1000,1.52]],"ltp":450.0,"tv":29.01,"id":13306150}]}]}
{"op":"mcm","clk":"993519666","pt":1580543511556,"mc":[{"id":"1.168133543","rc":[{"batl":[[0,1000,1.32]],"ltp":450.0,"tv":29.01,"id":13306150}]}]}
{"op":"mcm","clk":"993519802","pt":1580543513165,"mc":[{"id":"1.168133543","rc":[{"batl":[[0,210,2.02],[1,1000,1.3]],"ltp":450.0,"tv":29.01,"id":13306150}]}]}
{"op":"mcm","clk":"993519885","pt":1580543514452,"mc":[{"id":"1.168133543","rc":[{"batb":[[1,260,1.19]],"ltp":450.0,"tv":26.52,"id":24270700}]}]}
{"op":"mcm","clk":"993519947","pt":1580543515335,"mc":[{"id":"1.168133543","rc":[{"batb":[[1,260,1.35]],"ltp":450.0,"tv":26.52,"id":24270700}]}]}
{"op":"mcm","clk":"993520088","pt":1580543517447,"mc":[{"id":"1.168133543","rc":[{"batl":[[2,5.3,47]],"ltp":3.9,"tv":1767.19,"id":12636},{"batl":[[1,1000,1.5]],"ltp":450.0,"tv":29.01,"id":13306150}]}]}
{"op":"mcm","clk":"993520213","pt":1580543519448,"mc":[{"id":"1.168133543","rc":[{"batl":[[0,4.5,7.8],[1,4.6,9.32],[2,4.7,2]],"ltp":3.9,"tv":1767.19,"id":12636}]}]}
{"op":"mcm","clk":"993520232","pt":1580543519756,"mc":[{"id":"1.168133543","rc":[{"batl":[[1,220,4],[2,1000,1.5]],"ltp":450.0,"tv":29.01,"id":13306150}]}]}
{"op":"mcm","clk":"993520447","pt":1580543522842,"mc":[{"id":"1.168133543","rc":[{"batl":[[2,1000,1.3]],"ltp":450.0,"tv":29.01,"id":13306150}]}]}
{"op":"mcm","clk":"993520635","pt":1580543525569,"mc":[{"id":"1.168133543","rc":[{"batb":[[0,3.75,4.6],[1,3.7,6.61],[2,3.65,4]],"ltp":3.9,"tv":1767.19,"id":12636}]}]}
{"op":"mcm","clk":"993520700","pt":1580543526552,"mc":[{"id":"1.168133543","rc":[{"batl":[[0,7.8,9],[1,8.4,5.71],[2,8.6,6.86]],"ltp":7.2,"tv":507.29,"id":22121325}]}]}
{"op":"mcm","clk":"993520762","pt":1580543527478,"mc":[{"id":"1.168133543","rc":[{"batl":[[1,8.4,11.75]],"ltp":7.2,"tv":507.29,"id":22121325}]}]}
{"op":"mcm","clk":"993520838","pt":1580543528460,"mc":[{"id":"1.168133543","rc":[{"trd":[[190,0.16]],"batb":[[0,150,1.87]],"batl":[[2,1000,1.5]],"ltp":190.0,"tv":29.17,"id":13306150}],"tv":6315.93}]}
{"op":"mcm","clk":"993521020","pt":1580543530475,"mc":[{"id":"1.168133543","rc":[{"batl":[[0,4.4,48.27],[1,4.5,7.6],[2,4.6,9.32]],"ltp":3.9,"tv":1767.19,"id":12636}]}]}
{"op":"mcm","clk":"993521153","pt":1580543532175,"mc":[{"id":"1.168133543","rc":[{"batl":[[0,4.3,2],[1,4.4,48.27],[2,4.5,7.6]],"ltp":3.9,"tv":1767.19,"id":12636}]}]}
{"op":"mcm","clk":"993521261","pt":1580543533571,"mc":[{"id":"1.168133543","rc":[{"batl":[[0,210,2]],"ltp":190.0,"tv":29.17,"id":13306150}]}]}
{"op":"mcm","clk":"993521392","pt":1580543535475,"mc":[{"id":"1.168133543","rc":[{"batl":[[2,1000,1.3]],"ltp":190.0,"tv":29.17,"id":13306150}]}]}
{"op":"mcm","clk":"993521455","pt":1580543536458,"mc":[{"id":"1.168133543","rc":[{"batb":[[0,3.75,8.6],[2,3.6,5]],"ltp":3.9,"tv":1767.19,"id":12636},{"batb":[[1,260,1.19]],"ltp":450.0,"tv":26.52,"id":24270700}]}]}
{"op":"mcm","clk":"993521506","pt":1580543537279,"mc":[{"id":"1.168133543","rc":[{"batl":[[0,4.3,16]],"ltp":3.9,"tv":1767.19,"id":12636},{"batb":[[1,260,1.35]],"ltp":450.0,"tv":26.52,"id":24270700}]}]}
{"op":"mcm","clk":"993521737","pt":1580543540472,"mc":[{"id":"1.168133543","rc":[{"batl":[[2,1000,1.5]],"ltp":190.0,"tv":29.17,"id":13306150}]}]}
{"op":"mcm","clk":"993522040","pt":1580543545397,"mc":[{"id":"1.168133543","rc":[{"batl":[[0,4.1,4],[1,4.2,50.36],[2,4.3,16]],"ltp":3.9,"tv":1767.19,"id":12636}]}]}
{"op":"mcm","clk":"993522102","pt":1580543546474,"mc":[{"id":"1.168133543","rc":[{"batl":[[2,1000,1.3]],"ltp":190.0,"tv":29.17,"id":13306150}]}]}
{"op":"mcm","clk":"993522464","pt":1580543551378,"mc":[{"id":"1.168133543","rc":[{"batl":[[2,230,16]],"ltp":190.0,"tv":29.17,"id":13306150}]}]}
{"op":"mcm","clk":"993532691","pt":1580543556368,"mc":[{"id":"1.168133543","rc":[{"batb":[[1,260,1.19]],"ltp":450.0,"tv":26.52,"id":24270700},{"batl":[[2,1000,1.5]],"ltp":190.0,"tv":29.17,"id":13306150}]}]}
{"op":"mcm","clk":"993532769","pt":1580543557499,"mc":[{"id":"1.168133543","rc":[{"batb":[[1,260,1.35]],"ltp":450.0,"tv":26.52,"id":24270700}]}]}
{"op":"mcm","clk":"993532847","pt":1580543558474,"mc":[{"id":"1.168133543","rc":[{"batl":[[2,1000,1.3]],"ltp":190.0,"tv":29.17,"id":13306150}]}]}
{"op":"mcm","clk":"993532919","pt":1580543559500,"mc":[{"id":"1.168133543","rc":[{"batl":[[1,4.3,16],[2,4.5,7.6]],"ltp":3.9,"tv":1767.19,"id":12636}]}]}
{"op":"mcm","clk":"993532979","pt":1580543560320,"mc":[{"id":"1.168133543","rc":[{"batl":[[0,4.1,55.58]],"ltp":3.9,"tv":1767.19,"id":12636}]}]}
{"op":"mcm","clk":"993533232","pt":1580543563509,"mc":[{"id":"1.168133543","rc":[{"batl":[[1,1000,1.5],[2,1000,0]],"ltp":190.0,"tv":29.17,"id":13306150}]}]}
{"op":"mcm","clk":"993533304","pt":1580543564498,"mc":[{"id":"1.168133543","rc":[{"batl":[[0,1000,1.5],[1,1000,0]],"ltp":190.0,"tv":29.17,"id":13306150}]}]}
{"op":"mcm","clk":"993533954","pt":1580543573520,"mc":[{"id":"1.168133543","rc":[{"batl":[[0,4.1,4]],"ltp":3.9,"tv":1767.19,"id":12636},{"batl":[[2,2.4,15.45]],"ltp":2.28,"tv":3260.47,"id":10107355}]}]}
{"op":"mcm","clk":"993534018","pt":1580543574497,"mc":[{"id":"1.168133543","rc":[{"batl":[[1,4.2,50.36],[2,4.3,16]],"ltp":3.9,"tv":1767.19,"id":12636}]}]}
{"op":"mcm","clk":"993534226","pt":1580543577388,"mc":[{"id":"1.168133543","rc":[{"batl":[[2,4.3,2]],"ltp":3.9,"tv":1767.19,"id":12636}]}]}
{"op":"mcm","clk":"993534647","pt":1580543583425,"mc":[{"id":"1.168133543","rc":[{"batl":[[2,2.42,9.52]],"ltp":2.28,"tv":3260.47,"id":10107355}]}]}
{"op":"mcm","clk":"993534721","pt":1580543584502,"mc":[{"id":"1.168133543","rc":[{"batl":[[1,2.42,9.52],[2,2.44,12.7]],"ltp":2.28,"tv":3260.47,"id":10107355}]}]}
{"op":"mcm","clk":"993534794","pt":1580543585531,"mc":[{"id":"1.168133543","rc":[{"batl":[[0,4,2],[1,4.1,18],[2,4.2,50.36]],"ltp":3.9,"tv":1767.19,"id":12636}]}]}
{"op":"mcm","clk":"993534858","pt":1580543586514,"mc":[{"id":"1.168133543","rc":[{"batl":[[0,1000,1.52]],"ltp":190.0,"tv":29.17,"id":13306150}]}]}
{"op":"mcm","clk":"993534922","pt":1580543587497,"mc":[{"id":"1.168133543","rc":[{"batl":[[2,2.46,23.72]],"ltp":2.28,"tv":3260.47,"id":10107355}]}]}
{"op":"mcm","clk":"993534997","pt":1580543588531,"mc":[{"id":"1.168133543","rc":[{"batl":[[0,4,54.87],[2,4.5,7.6]],"ltp":3.9,"tv":1767.19,"id":12636}]}]}
{"op":"mcm","clk":"993535261","pt":1580543592512,"mc":[{"id":"1.168133543","rc":[{"batl":[[0,1000,1.32]],"ltp":190.0,"tv":29.17,"id":13306150}]}]}
{"op":"mcm","clk":"993535396","pt":1580543594421,"mc":[{"id":"1.168133543","rc":[{"batl":[[0,2.3,6],[1,2.42,9.56]],"ltp":2.28,"tv":3260.47,"id":10107355}]}]}
{"op":"mcm","clk":"993535504","pt":1580543596530,"mc":[{"id":"1.168133543","rc":[{"batl":[[1,2.42,5.54]],"ltp":2.28,"tv":3260.47,"id":10107355}]}]}
{"op":"mcm","clk":"993535580","pt":1580543597508,"mc":[{"id":"1.168133543","rc":[{"batl":[[0,2.38,6]],"ltp":2.28,"tv":3260.47,"id":10107355}]}]}
{"op":"mcm","clk":"993535667","pt":1580543598535,"mc":[{"id":"1.168133543","rc":[{"batl":[[0,1000,1.52]],"ltp":190.0,"tv":29.17,"id":13306150}]}]}
{"op":"mcm","clk":"993535941","pt":1580543602552,"mc":[{"id":"1.168133543","rc":[{"batl":[[0,2.36,107.31],[1,2.38,6],[2,2.42,5.54]],"ltp":2.28,"tv":3260.47,"id":10107355}]}]}
{"op":"mcm","clk":"993536000","pt":1580543603321,"mc":[{"id":"1.168133543","rc":[{"batl":[[0,2.34,23.31],[1,2.36,107.31],[2,2.38,6]],"ltp":2.28,"tv":3260.47,"id":10107355}]}]}
{"op":"mcm","clk":"993536132","pt":1580543605328,"mc":[{"id":"1.168133543","rc":[{"batl":[[0,1000,1.32]],"ltp":190.0,"tv":29.17,"id":13306150}]}]}
{"op":"mcm","clk":"993536294","pt":1580543607541,"mc":[{"id":"1.168133543","rc":[{"batb":[[0,2.2,76.53]],"ltp":2.28,"tv":3260.47,"id":10107355}]}]}
{"op":"mcm","clk":"993536373","pt":1580543608565,"mc":[{"id":"1.168133543","rc":[{"batb":[[0,6.8,4.88],[1,6.6,9.18],[2,6,32.83]],"ltp":7.2,"tv":507.29,"id":22121325}]}]}
{"op":"mcm","clk":"993536447","pt":1580543609441,"mc":[{"id":"1.168133543","rc":[{"batl":[[0,2.32,6],[1,2.34,23.31],[2,2.36,107.31]],"ltp":2.28,"tv":3260.47,"id":10107355},{"batb":[[1,6.6,12.14]],"ltp":7.2,"tv":507.29,"id":22121325}]}]}
{"op":"mcm","clk":"993536532","pt":1580543610526,"mc":[{"id":"1.168133543","rc":[{"batl":[[0,1000,1.52]],"ltp":190.0,"tv":29.17,"id":13306150}]}]}
{"op":"mcm","clk":"993536593","pt":1580543611451,"mc":[{"id":"1.168133543","rc":[{"batl":[[1,2.34,43.31]],"ltp":2.28,"tv":3260.47,"id":10107355}]}]}
{"op":"mcm","clk":"993536867","pt":1580543615535,"mc":[{"id":"1.168133543","rc":[{"batl":[[0,3.95,4],[1,4,54.87],[2,4.1,14]],"ltp":3.9,"tv":1767.19,"id":12636},{"batl":[[0,2.3,6],[1,2.32,6],[2,2.34,43.31]],"ltp":2.28,"tv":3260.47,"id":10107355},{"batb":[[1,6.6,9.18]],"ltp":7.2,"tv":507.29,"id":22121325}]}]}
{"op":"mcm","clk":"993536933","pt":1580543616564,"mc":[{"id":"1.168133543","rc":[{"batl":[[1,4,2]],"ltp":3.9,"tv":1767.19,"id":12636},{"batl":[[0,160,3.03]],"ltp":190.0,"tv":20.7,"id":22308007},{"batl":[[0,1000,1.32]],"ltp":190.0,"tv":29.17,"id":13306150}]}]}
{"op":"mcm","clk":"993537065","pt":1580543618440,"mc":[{"id":"1.168133543","rc":[{"batl":[[2,2.34,31.76]],"ltp":2.28,"tv":3260.47,"id":10107355}]}]}
{"op":"mcm","clk":"993537123","pt":1580543619468,"mc":[{"id":"1.168133543","rc":[{"batb":[[0,180,2.4],[1,150,1.68],[2,130,6.54]],"ltp":190.0,"tv":29.17,"id":13306150}]}]}
{"op":"mcm","clk":"993537257","pt":1580543621474,"mc":[{"id":"1.168133543","rc":[{"batl":[[1,2.34,31.76],[2,2.42,5.54]],"ltp":2.28,"tv":3260.47,"id":10107355},{"batb":[[1,260,1.19]],"ltp":450.0,"tv":26.52,"id":24270700}]}]}
{"op":"mcm","clk":"993537331","pt":1580543622559,"mc":[{"id":"1.168133543","rc":[{"batl":[[0,2.28,6],[1,2.3,6],[2,2.34,31.76]],"ltp":2.28,"tv":3260.47,"id":10107355},{"batb":[[1,260,1.35]],"ltp":450.0,"tv":26.52,"id":24270700},{"batl":[[0,1000,1.52]],"ltp":190.0,"tv":29.17,"id":13306150}]}]}
{"op":"mcm","clk":"993537405","pt":1580543623553,"mc":[{"id":"1.168133543","rc":[{"batb":[[0,3.8,9.48],[1,3.75,8.6],[2,3.7,6.61]],"batl":[[2,4.5,7.6]],"ltp":3.9,"tv":1767.19,"id":12636},{"batl":[[0,2.28,6.04]],"ltp":2.28,"tv":3260.47,"id":10107355}]}]}
{"op":"mcm","clk":"993537488","pt":1580543624484,"mc":[{"id":"1.168133543","rc":[{"batl":[[2,4.5,10.94]],"ltp":3.9,"tv":1767.19,"id":12636}]}]}
{"op":"mcm","clk":"993537659","pt":1580543626548,"mc":[{"id":"1.168133543","rc":[{"batb":[[0,7,8],[1,6.8,4.88],[2,6.6,9.18]],"ltp":7.2,"tv":507.29,"id":22121325}]}]}
{"op":"mcm","clk":"993537703","pt":1580543627170,"mc":[{"id":"1.168133543","rc":[{"batl":[[2,2.34,11.76]],"ltp":2.28,"tv":3260.47,"id":10107355}]}]}
{"op":"mcm","clk":"993537799","pt":1580543628459,"mc":[{"id":"1.168133543","rc":[{"batl":[[0,1000,1.32]],"ltp":190.0,"tv":29.17,"id":13306150}]}]}
{"op":"mcm","clk":"993538078","pt":1580543631561,"mc":[{"id":"1.168133543","rc":[{"batb":[[0,7.2,3.22],[1,7,8],[2,6.6,9.6]],"ltp":7.2,"tv":507.29,"id":22121325}]}]}
{"op":"mcm","clk":"993538383","pt":1580543635270,"mc":[{"id":"1.168133543","rc":[{"batb":[[0,7.4,1.47],[1,7.2,3.22],[2,7,8]],"ltp":7.2,"tv":507.29,"id":22121325}]}]}
{"op":"mcm","clk":"993538473","pt":1580543636460,"mc":[{"id":"1.168133543","rc":[{"trd":[[3.95,8],[4,5.68]],"batl":[[0,4.5,10.94],[1,4.6,54],[2,5.5,6.67]],"ltp":4.0,"tv":1779.19,"id":12636}],"tv":6327.93}]}
{"op":"mcm","clk":"993538618","pt":1580543638570,"mc":[{"id":"1.168133543","rc":[{"batl":[[0,4.5,7.6]],"ltp":4.0,"tv":1779.19,"id":12636}]}]}
{"op":"mcm","clk":"993538712","pt":1580543639557,"mc":[{"id":"1.168133543","rc":[{"batb":[[0,3.85,2.08],[1,3.8,9.48],[2,3.75,8.6]],"ltp":4.0,"tv":1779.19,"id":12636}]}]}
{"op":"mcm","clk":"993538956","pt":1580543642395,"mc":[{"id":"1.168133543","rc":[{"batb":[[0,3.85,12.08]],"ltp":4.0,"tv":1779.19,"id":12636}]}]}
{"op":"mcm","clk":"993539073","pt":1580543643486,"mc":[{"id":"1.168133543","rc":[{"batl":[[0,7.8,7],[1,8.2,2.26],[2,8.4,11.49]],"ltp":7.2,"tv":507.29,"id":22121325}]}]}
{"op":"mcm","clk":"993539300","pt":1580543646364,"mc":[{"id":"1.168133543","rc":[{"batl":[[1,5.5,6.67],[2,6,42]],"ltp":4.0,"tv":1779.19,"id":12636}]}]}
{"op":"mcm","clk":"993539536","pt":1580543649570,"mc":[{"id":"1.168133543","rc":[{"batl":[[0,160,3.54]],"ltp":190.0,"tv":20.7,"id":22308007},{"batl":[[0,2.26,112.06],[1,2.28,6.04],[2,2.3,6]],"ltp":2.28,"tv":3260.47,"id":10107355}]}]}
{"op":"mcm","clk":"993539679","pt":1580543651568,"mc":[{"id":"1.168133543","rc":[{"batl":[[1,5.4,13.15],[2,5.5,6.67]],"ltp":4.0,"tv":1779.19,"id":12636},{"batl":[[0,2.24,12.06],[1,2.26,112.06],[2,2.28,6.04]],"ltp":2.28,"tv":3260.47,"id":10107355}]}]}
{"op":"mcm","clk":"993539737","pt":1580543652495,"mc":[{"id":"1.168133543","rc":[{"batl":[[0,4.4,3.61],[1,4.5,7.6],[2,5.4,13.15]],"ltp":4.0,"tv":1779.19,"id":12636},{"batl":[[1,2.26,112.1],[2,2.28,6]],"ltp":2.28,"tv":3260.47,"id":10107355}]}]}
{"op":"mcm","clk":"993539979","pt":1580543655489,"mc":[{"id":"1.168133543","rc":[{"batb":[[0,3.9,4.05],[1,3.85,12.08],[2,3.8,9.48]],"ltp":4.0,"tv":1779.19,"id":12636}]}]}
{"op":"mcm","clk":"993540059","pt":1580543656472,"mc":[{"id":"1.168133543","rc":[{"batl":[[0,2.24,32.06]],"ltp":2.28,"tv":3260.47,"id":10107355}]}]}
{"op":"mcm","clk":"993540126","pt":1580543657503,"mc":[{"id":"1.168133543","rc":[{"batb":[[0,7.4,1.56]],"ltp":7.2,"tv":507.29,"id":22121325}]}]}
{"op":"mcm","clk":"993540209","pt":1580543658491,"mc":[{"id":"1.168133543","rc":[{"trd":[[2.22,227.49]],"batb":[[0,2.2,76.45]],"batl":[[0,2.22,3.92],[1,2.24,32.06],[2,2.26,112.1]],"ltp":2.22,"tv":3264.63,"id":10107355}],"tv":6332.1}]}
{"op":"mcm","clk":"993540272","pt":1580543659372,"mc":[{"id":"1.168133543","rc":[{"trd":[[2.22,235.33]],"batl":[[0,2.24,32.06],[1,2.26,112.1],[2,2.3,2]],"ltp":2.22,"tv":3272.47,"id":10107355}],"tv":6339.94}]}
{"op":"mcm","clk":"993540640","pt":1580543664495,"mc":[{"id":"1.168133543","rc":[{"batl":[[1,2.3,2.04],[2,2.34,11.76]],"ltp":2.22,"tv":3272.47,"id":10107355}]}]}
{"op":"mcm","clk":"993540710","pt":1580543665421,"mc":[{"id":"1.168133543","rc":[{"batl":[[0,4.3,49.18],[1,4.4,3.61],[2,4.5,7.6]],"ltp":4.0,"tv":1779.19,"id":12636},{"batl":[[1,2.3,16.05]],"ltp":2.22,"tv":3272.47,"id":10107355},{"batb":[[1,7.2,4.22]],"ltp":7.2,"tv":507.29,"id":22121325}]}]}
{"op":"mcm","clk":"993540793","pt":1580543666509,"mc":[{"id":"1.168133543","rc":[{"batl":[[0,2.24,20]],"ltp":2.22,"tv":3272.47,"id":10107355}]}]}
{"op":"mcm","clk":"993540862","pt":1580543667492,"mc":[{"id":"1.168133543","rc":[{"batl":[[1,2.3,2.04],[2,2.32,32.62]],"ltp":2.22,"tv":3272.47,"id":10107355}]}]}
{"op":"mcm","clk":"993540931","pt":1580543668419,"mc":[{"id":"1.168133543","rc":[{"batl":[[1,2.3,10.92]],"ltp":2.22,"tv":3272.47,"id":10107355}]}]}
{"op":"mcm","clk":"993541700","pt":1580543678495,"mc":[{"id":"1.168133543","rc":[{"batl":[[0,4.4,3.61],[1,4.5,7.6],[2,5,50]],"ltp":4.0,"tv":1779.19,"id":12636}]}]}
{"op":"mcm","clk":"993542256","pt":1580543685526,"mc":[{"id":"1.168133543","rc":[{"batl":[[0,2.3,10.92],[1,2.32,32.62],[2,2.42,108.5]],"ltp":2.22,"tv":3272.47,"id":10107355}]}]}
{"op":"mcm","clk":"993542352","pt":1580543686520,"mc":[{"id":"1.168133543","rc":[{"batl":[[0,2.3,2.04],[1,2.42,108.5],[2,2.46,21]],"ltp":2.22,"tv":3272.47,"id":10107355}]}]}
{"op":"mcm","clk":"993542451","pt":1580543687504,"mc":[{"id":"1.168133543","rc":[{"batb":[[0,7.4,4.55]],"ltp":7.2,"tv":507.29,"id":22121325}]}]}
{"op":"mcm","clk":"993542529","pt":1580543688535,"mc":[{"id":"1.168133543","rc":[{"batl":[[1,2.4,11.73],[2,2.42,108.5]],"ltp":2.22,"tv":3272.47,"id":10107355}]}]}
{"op":"mcm","clk":"993542858","pt":1580543692525,"mc":[{"id":"1.168133543","rc":[{"batl":[[0,4.3,49.18],[1,4.4,3.61],[2,4.5,7.6]],"ltp":4.0,"tv":1779.19,"id":12636},{"batl":[[1,2.38,106.41],[2,2.4,11.73]],"ltp":2.22,"tv":3272.47,"id":10107355}]}]}
{"op":"mcm","clk":"993543043","pt":1580543694549,"mc":[{"id":"1.168133543","rc":[{"batl":[[1,2.36,11.62],[2,2.38,106.41]],"ltp":2.22,"tv":3272.47,"id":10107355}]}]}
{"op":"mcm","clk":"993543203","pt":1580543696514,"mc":[{"id":"1.168133543","rc":[{"batb":[[0,48,1.4]],"ltp":60.0,"tv":42.47,"id":7226819},{"batl":[[1,2.34,4],[2,2.36,11.62]],"ltp":2.22,"tv":3272.47,"id":10107355}]}]}
{"op":"mcm","clk":"993543518","pt":1580543700442,"mc":[{"id":"1.168133543","rc":[{"batl":[[0,2.3,2],[1,2.34,4.04]],"ltp":2.22,"tv":3272.47,"id":10107355}]}]}
{"op":"mcm","clk":"993543687","pt":1580543702517,"mc":[{"id":"1.168133543","rc":[{"batb":[[0,3.95,2.03],[1,3.9,4.05],[2,3.85,10]],"ltp":4.0,"tv":1779.19,"id":12636}]}]}
{"op":"mcm","clk":"993544020","pt":1580543706467,"mc":[{"id":"1.168133543","rc":[{"batb":[[1,260,1.19]],"ltp":450.0,"tv":26.52,"id":24270700}]}]}
{"op":"mcm","clk":"993544125","pt":1580543707558,"mc":[{"id":"1.168133543","rc":[{"batl":[[0,4.4,3.61],[1,4.5,7.6],[2,5,50]],"ltp":4.0,"tv":1779.19,"id":12636},{"batb":[[1,260,1.35]],"ltp":450.0,"tv":26.52,"id":24270700}]}]}
{"op":"mcm","clk":"993544197","pt":1580543708537,"mc":[{"id":"1.168133543","rc":[{"batl":[[1,2.34,112.27]],"ltp":2.22,"tv":3272.47,"id":10107355}]}]}
{"op":"mcm","clk":"993544259","pt":1580543709364,"mc":[{"id":"1.168133543","rc":[{"batl":[[0,2.3,2.04],[1,2.32,11.86],[2,2.34,112.23]],"ltp":2.22,"tv":3272.47,"id":10107355}]}]}
{"op":"mcm","clk":"993544562","pt":1580543713452,"mc":[{"id":"1.168133543","rc":[{"batl":[[0,2.3,6.04],[2,2.34,108.23]],"ltp":2.22,"tv":3272.47,"id":10107355}]}]}
{"op":"mcm","clk":"993545205","pt":1580543721568,"mc":[{"id":"1.168133543","rc":[{"batl":[[2,2.42,5.5]],"ltp":2.22,"tv":3272.47,"id":10107355}]}]}
{"op":"mcm","clk":"993545270","pt":1580543722345,"mc":[{"id":"1.168133543","rc":[{"batl":[[0,4.3,49.18],[1,4.4,3.61],[2,4.5,7.6]],"ltp":4.0,"tv":1779.19,"id":12636},{"batl":[[0,2.3,116.15]],"ltp":2.22,"tv":3272.47,"id":10107355}]}]}
{"op":"mcm","clk":"993545352","pt":1580543723486,"mc":[{"id":"1.168133543","rc":[{"batl":[[1,2.42,5.5],[2,2.44,6]],"ltp":2.22,"tv":3272.47,"id":10107355}]}]}
{"op":"mcm","clk":"993545601","pt":1580543726482,"mc":[{"id":"1.168133543","rc":[{"batl":[[1,2.4,32.26],[2,2.42,21.62]],"ltp":2.22,"tv":3272.47,"id":10107355}]}]}
{"op":"mcm","clk":"993545741","pt":1580543728492,"mc":[{"id":"1.168133543","rc":[{"batl":[[0,2.28,11.74],[1,2.3,116.11],[2,2.4,32.26]],"ltp":2.22,"tv":3272.47,"id":10107355}]}]}
{"op":"mcm","clk":"993546380","pt":1580543736471,"mc":[{"id":"1.168133543","rc":[{"batl":[[0,4.4,3.61],[1,4.5,7.6],[2,5.4,13.15]],"ltp":4.0,"tv":1779.19,"id":12636},{"batl":[[0,2.26,112.06],[1,2.28,11.74],[2,2.3,2]],"ltp":2.22,"tv":3272.47,"id":10107355}]}]}
{"op":"mcm","clk":"993546462","pt":1580543737503,"mc":[{"id":"1.168133543","rc":[{"batl":[[1,2.3,2.04],[2,2.4,136.26]],"ltp":2.22,"tv":3272.47,"id":10107355}]}]}
{"op":"mcm","clk":"993546562","pt":1580543738490,"mc":[{"id":"1.168133543","rc":[{"batl":[[0,2.26,112.1],[1,2.3,2]],"ltp":2.22,"tv":3272.47,"id":10107355},{"trd":[[7.8,14]],"batl":[[0,8.2,2.26],[1,8.4,11.49],[2,9.4,27.18]],"ltp":7.8,"tv":521.29,"id":22121325}],"tv":6353.94}]}
{"op":"mcm","clk":"993546668","pt":1580543739569,"mc":[{"id":"1.168133543","rc":[{"batl":[[1,9.4,27.18],[2,9.8,4.19]],"ltp":7.8,"tv":521.29,"id":22121325}]}]}
{"op":"mcm","clk":"993546823","pt":1580543741474,"mc":[{"id":"1.168133543","rc":[{"batl":[[1,9.2,4.26],[2,9.4,27.18]],"ltp":7.8,"tv":521.29,"id":22121325}]}]}
{"op":"mcm","clk":"993547132","pt":1580543745483,"mc":[{"id":"1.168133543","rc":[{"batl":[[1,5.4,13.15],[2,5.5,51.67]],"ltp":4.0,"tv":1779.19,"id":12636}]}]}
{"op":"mcm","clk":"993547207","pt":1580543746514,"mc":[{"id":"1.168133543","rc":[{"trd":[[2.24,293.67]],"batl":[[0,2.24,9.6],[1,2.26,112.1],[2,2.3,2]],"ltp":2.24,"tv":3276.47,"id":10107355}],"tv":6357.94}]}
{"op":"mcm","clk":"993547283","pt":1580543747493,"mc":[{"id":"1.168133543","rc":[{"trd":[[2.24,305.67]],"batl":[[0,2.24,3.6]],"ltp":2.24,"tv":3288.47,"id":10107355}],"tv":6369.94}]}
{"op":"mcm","clk":"993547372","pt":1580543748519,"mc":[{"id":"1.168133543","rc":[{"batb":[[1,260,1.19]],"ltp":450.0,"tv":26.52,"id":24270700}]}]}
{"op":"mcm","clk":"993547442","pt":1580543749396,"mc":[{"id":"1.168133543","rc":[{"batb":[[1,260,1.35]],"ltp":450.0,"tv":26.52,"id":24270700}]}]}
{"op":"mcm","clk":"993547533","pt":1580543750482,"mc":[{"id":"1.168133543","rc":[{"batl":[[1,2.3,2.04],[2,2.38,6]],"ltp":2.24,"tv":3288.47,"id":10107355}]}]}
{"op":"mcm","clk":"993547600","pt":1580543751411,"mc":[{"id":"1.168133543","rc":[{"batl":[[0,4.3,49.18],[1,4.4,3.61],[2,5.4,2.13]],"ltp":4.0,"tv":1779.19,"id":12636},{"batl":[[0,2.3,2.04],[1,2.38,6],[2,2.4,120.13]],"ltp":2.24,"tv":3288.47,"id":10107355},{"trd":[[8,13.95],[8.2,16.8]],"batl":[[0,9,34.65]],"ltp":8.2,"tv":524.73,"id":22121325}],"tv":6373.38}]}
{"op":"mcm","clk":"993547760","pt":1580543753423,"mc":[{"id":"1.168133543","rc":[{"batb":[[1,2.16,5.2],[2,2.14,22.05]],"batl":[[2,2.4,104]],"ltp":2.24,"tv":3288.47,"id":10107355},{"batl":[[1,9.4,27.18],[2,9.8,4.19]],"ltp":8.2,"tv":524.73,"id":22121325}]}]}
{"op":"mcm","clk":"993547841","pt":1580543754401,"mc":[{"id":"1.168133543","rc":[{"batb":[[0,7.4,4.84]],"batl":[[0,8.8,4.54],[1,9,34.11],[2,9.4,27.18]],"ltp":8.2,"tv":524.73,"id":22121325}]}]}
{"op":"mcm","clk":"993548077","pt":1580543757395,"mc":[{"id":"1.168133543","rc":[{"batl":[[0,2.3,2],[1,2.38,6.04]],"ltp":2.24,"tv":3288.47,"id":10107355}]}]}
{"op":"mcm","clk":"993548224","pt":1580543759440,"mc":[{"id":"1.168133543","rc":[{"batl":[[0,8.6,2.54],[1,8.8,4],[2,9,34.11]],"ltp":8.2,"tv":524.73,"id":22121325}]}]}
{"op":"mcm","clk":"993548636","pt":1580543764442,"mc":[{"id":"1.168133543","rc":[{"batl":[[0,4.4,3.61],[1,5.4,2.13],[2,5.5,51.67]],"ltp":4.0,"tv":1779.19,"id":12636},{"batl":[[0,160,3.03]],"ltp":190.0,"tv":20.7,"id":22308007},{"batl":[[2,9.4,27.18]],"ltp":8.2,"tv":524.73,"id":22121325}]}]}
{"op":"mcm","clk":"993548813","pt":1580543766506,"mc":[{"id":"1.168133543","rc":[{"batl":[[2,5.5,6.67]],"ltp":4.0,"tv":1779.19,"id":12636},{"batl":[[2,2.42,5.5]],"ltp":2.24,"tv":3288.47,"id":10107355},{"batl":[[2,9.8,4.37]],"ltp":8.2,"tv":524.73,"id":22121325}]}]}
{"op":"mcm","clk":"993548988","pt":1580543768513,"mc":[{"id":"1.168133543","rc":[{"batb":[[1,260,1.19]],"ltp":450.0,"tv":26.52,"id":24270700}]}]}
{"op":"mcm","clk":"993549069","pt":1580543769540,"mc":[{"id":"1.168133543","rc":[{"batb":[[1,260,1.35]],"ltp":450.0,"tv":26.52,"id":24270700}]}]}
{"op":"mcm","clk":"993549228","pt":1580543771532,"mc":[{"id":"1.168133543","rc":[{"batl":[[1,9.8,4.37],[2,10,14.16]],"ltp":8.2,"tv":524.73,"id":22121325}]}]}
{"op":"mcm","clk":"993549394","pt":1580543773545,"mc":[{"id":"1.168133543","rc":[{"batl":[[1,2.42,5.54],[2,2.46,21]],"ltp":2.24,"tv":3288.47,"id":10107355}]}]}
{"op":"mcm","clk":"993549697","pt":1580543777448,"mc":[{"id":"1.168133543","rc":[{"batb":[[0,4,9.14],[1,3.95,6.03],[2,3.9,4.05]],"ltp":4.0,"tv":1779.19,"id":12636}]}]}
{"op":"mcm","clk":"993549780","pt":1580543778533,"mc":[{"id":"1.168133543","rc":[{"trd":[[8.6,96.2]],"batb":[[0,8.4,7.36],[1,8,23.54],[2,7.8,6.41]],"batl":[[0,8.6,25.98],[1,8.8,8],[2,9.6,18.81]],"ltp":8.6,"tv":619.03,"id":10163711},{"batl":[[0,8.4,37.08],[1,8.6,2],[2,9.8,4.37]],"ltp":8.2,"tv":524.73,"id":22121325}],"tv":6380.31}]}
{"op":"mcm","clk":"993549871","pt":1580543779511,"mc":[{"id":"1.168133543","rc":[{"batl":[[0,160,3.54]],"ltp":190.0,"tv":20.7,"id":22308007},{"batb":[[1,8,26.88]],"ltp":8.6,"tv":619.03,"id":10163711},{"batl":[[2,2.46,23.16]],"ltp":2.24,"tv":3288.47,"id":10107355},{"batl":[[0,8.2,7.62],[1,8.4,36.54],[2,8.6,2]],"ltp":8.2,"tv":524.73,"id":22121325}]}]}
{"op":"mcm","clk":"993549935","pt":1580543780334,"mc":[{"id":"1.168133543","rc":[{"batl":[[2,9.6,15.33]],"ltp":8.6,"tv":619.03,"id":10163711},{"batl":[[2,2.46,21]],"ltp":2.24,"tv":3288.47,"id":10107355}]}]}
{"op":"mcm","clk":"993550258","pt":1580543784531,"mc":[{"id":"1.168133543","rc":[{"batl":[[1,8.8,2]],"ltp":8.6,"tv":619.03,"id":10163711}]}]}
{"op":"mcm","clk":"993550332","pt":1580543785507,"mc":[{"id":"1.168133543","rc":[{"trd":[[8.4,45.19]],"batb":[[0,8,23.54],[1,7.8,6.41],[2,7.2,6.21]],"batl":[[2,9.6,22.96]],"ltp":8.4,"tv":633.75,"id":10163711}],"tv":6395.03}]}
{"op":"mcm","clk":"993550406","pt":1580543786534,"mc":[{"id":"1.168133543","rc":[{"batl":[[1,2.42,5.5]],"ltp":2.24,"tv":3288.47,"id":10107355}]}]}
{"op":"mcm","clk":"993550486","pt":1580543787410,"mc":[{"id":"1.168133543","rc":[{"batl":[[1,2.42,5.54]],"ltp":2.24,"tv":3288.47,"id":10107355}]}]}
{"op":"mcm","clk":"993550990","pt":1580543793529,"mc":[{"id":"1.168133543","rc":[{"batl":[[0,8.8,2],[1,9.6,22.96],[2,9.8,98.24]],"ltp":8.4,"tv":633.75,"id":10163711},{"batl":[[1,8.6,2],[2,9.8,4.37]],"ltp":8.2,"tv":524.73,"id":22121325}]}]}
{"op":"mcm","clk":"993551062","pt":1580543794559,"mc":[{"id":"1.168133543","rc":[{"batl":[[1,9.4,23.91],[2,9.6,30.36]],"ltp":8.4,"tv":633.75,"id":10163711},{"batl":[[0,8,38.37],[1,8.2,7.62],[2,8.6,2]],"ltp":8.2,"tv":524.73,"id":22121325}]}]}
{"op":"mcm","clk":"993551133","pt":1580543795535,"mc":[{"id":"1.168133543","rc":[{"batl":[[2,9.6,2.45]],"ltp":8.4,"tv":633.75,"id":10163711}]}]}
{"op":"mcm","clk":"993551289","pt":1580543797440,"mc":[{"id":"1.168133543","rc":[{"batb":[[2,7,35.21]],"ltp":8.4,"tv":633.75,"id":10163711}]}]}
{"op":"mcm","clk":"993551597","pt":1580543801441,"mc":[{"id":"1.168133543","rc":[{"batb":[[1,7.8,10.66]],"ltp":8.4,"tv":633.75,"id":10163711}]}]}
{"op":"mcm","clk":"993552123","pt":1580543808356,"mc":[{"id":"1.168133543","rc":[{"batl":[[1,9.2,1.86],[2,9.4,23.78]],"ltp":8.4,"tv":633.75,"id":10163711}]}]}
{"op":"mcm","clk":"993552243","pt":1580543809540,"mc":[{"id":"1.168133543","rc":[{"batl":[[1,9,24.83],[2,9.2,1.86]],"ltp":8.4,"tv":633.75,"id":10163711},{"batl":[[0,8.2,7.62],[1,8.6,2],[2,9.6,26.3]],"ltp":8.2,"tv":524.73,"id":22121325}]}]}
{"op":"mcm","clk":"993552329","pt":1580543810559,"mc":[{"id":"1.168133543","rc":[{"batl":[[2,9.4,8.02]],"ltp":8.2,"tv":524.73,"id":22121325}]}]}
{"op":"mcm","clk":"993552579","pt":1580543813443,"mc":[{"id":"1.168133543","rc":[{"batl":[[0,8.6,2],[1,8.8,2],[2,9,24.83]],"ltp":8.4,"tv":633.75,"id":10163711}]}]}
{"op":"mcm","clk":"993553668","pt":1580543826473,"mc":[{"id":"1.168133543","rc":[{"batl":[[2,9.2,1.86]],"ltp":8.4,"tv":633.75,"id":10163711}]}]}
{"op":"mcm","clk":"993553734","pt":1580543827291,"mc":[{"id":"1.168133543","rc":[{"batl":[[0,8.6,27.98]],"ltp":8.4,"tv":633.75,"id":10163711}]}]}
{"op":"mcm","clk":"993554370","pt":1580543835474,"mc":[{"id":"1.168133543","rc":[{"batb":[[1,7.8,6.41]],"ltp":8.4,"tv":633.75,"id":10163711}]}]}
{"op":"mcm","clk":"993554819","pt":1580543841506,"mc":[{"id":"1.168133543","rc":[{"batl":[[0,8.6,2]],"ltp":8.4,"tv":633.75,"id":10163711}]}]}
{"op":"mcm","clk":"993554906","pt":1580543842473,"mc":[{"id":"1.168133543","rc":[{"batl":[[2,9,24.83]],"ltp":8.4,"tv":633.75,"id":10163711}]}]}
{"op":"mcm","clk":"993555882","pt":1580543855523,"mc":[{"id":"1.168133543","rc":[{"batl":[[2,9.2,1.86]],"ltp":8.4,"tv":633.75,"id":10163711}]}]}
{"op":"mcm","clk":"993555957","pt":1580543856499,"mc":[{"id":"1.168133543","rc":[{"batl":[[0,8.6,27.98]],"ltp":8.4,"tv":633.75,"id":10163711}]}]}
{"op":"mcm","clk":"993556859","pt":1580543868334,"mc":[{"id":"1.168133543","rc":[{"trd":[[2.2,115.1]],"batb":[[0,2.2,46.45]],"ltp":2.2,"tv":3348.47,"id":10107355}],"tv":6455.03}]}
{"op":"mcm","clk":"993556964","pt":1580543869502,"mc":[{"id":"1.168133543","rc":[{"batl":[[0,8.6,2],[2,9,24.83]],"ltp":8.4,"tv":633.75,"id":10163711},{"batb":[[1,2.14,22.05],[2,2.12,5.27]],"ltp":2.2,"tv":3348.47,"id":10107355}]}]}
{"op":"mcm","clk":"993557280","pt":1580543873517,"mc":[{"id":"1.168133543","rc":[{"batb":[[1,260,1.19]],"ltp":450.0,"tv":26.52,"id":24270700}]}]}
{"op":"mcm","clk":"993557358","pt":1580543874542,"mc":[{"id":"1.168133543","rc":[{"batb":[[1,260,1.35]],"ltp":450.0,"tv":26.52,"id":24270700}]}]}
{"op":"mcm","clk":"993557522","pt":1580543876552,"mc":[{"id":"1.168133543","rc":[{"batl":[[0,5.4,2.13],[1,5.5,6.67],[2,6,42]],"ltp":4.0,"tv":1779.19,"id":12636}]}]}
{"op":"mcm","clk":"993557605","pt":1580543877536,"mc":[{"id":"1.168133543","rc":[{"batl":[[1,2.4,6.67],[2,2.42,5.5]],"ltp":2.2,"tv":3348.47,"id":10107355}]}]}
{"op":"mcm","clk":"993557691","pt":1580543878515,"mc":[{"id":"1.168133543","rc":[{"batl":[[0,5.5,10.84],[1,6,42],[2,9.2,9]],"ltp":4.0,"tv":1779.19,"id":12636}]}]}
{"op":"mcm","clk":"993557757","pt":1580543879443,"mc":[{"id":"1.168133543","rc":[{"batl":[[0,5.5,6.87]],"ltp":4.0,"tv":1779.19,"id":12636}]}]}
{"op":"mcm","clk":"993558131","pt":1580543883520,"mc":[{"id":"1.168133543","rc":[{"batl":[[0,160,3.03]],"ltp":190.0,"tv":20.7,"id":22308007},{"trd":[[8,4]],"batb":[[0,8,21.54]],"batl":[[2,9.2,1.86]],"ltp":8.0,"tv":637.75,"id":10163711}],"tv":6459.03}]}
{"op":"mcm","clk":"993558408","pt":1580543886453,"mc":[{"id":"1.168133543","rc":[{"batl":[[1,9.2,9],[2,10.5,24]],"ltp":4.0,"tv":1779.19,"id":12636}]}]}
{"op":"mcm","clk":"993559482","pt":1580543898524,"mc":[{"id":"1.168133543","rc":[{"batl":[[2,9,4]],"ltp":8.0,"tv":637.75,"id":10163711}]}]}
{"op":"mcm","clk":"993560999","pt":1580543915459,"mc":[{"id":"1.168133543","rc":[{"batl":[[2,9.2,1.86]],"ltp":8.0,"tv":637.75,"id":10163711}]}]}
{"op":"mcm","clk":"993561100","pt":1580543916488,"mc":[{"id":"1.168133543","rc":[{"batl":[[2,13,19]],"ltp":4.0,"tv":1779.19,"id":12636}]}]}
{"op":"mcm","clk":"993561195","pt":1580543917468,"mc":[{"id":"1.168133543","rc":[{"trd":[[4.1,13.44]],"batl":[[0,4.1,3.8],[1,5.5,6.87],[2,9.2,9]],"ltp":4.1,"tv":1787.59,"id":12636}],"tv":6467.43}]}
{"op":"mcm","clk":"993561341","pt":1580543919370,"mc":[{"id":"1.168133543","rc":[{"batl":[[1,5.5,6.67]],"ltp":4.1,"tv":1787.59,"id":12636}]}]}
{"op":"mcm","clk":"993561651","pt":1580543922469,"mc":[{"id":"1.168133543","rc":[{"batb":[[0,2.22,7.75],[1,2.2,46.45],[2,2.14,22.05]],"ltp":2.2,"tv":3348.47,"id":10107355}]}]}
{"op":"mcm","clk":"993561719","pt":1580543923393,"mc":[{"id":"1.168133543","rc":[{"batb":[[2,2.14,5.51]],"ltp":2.2,"tv":3348.47,"id":10107355}]}]}
{"op":"mcm","clk":"993561982","pt":1580543926496,"mc":[{"id":"1.168133543","rc":[{"batl":[[0,160,3.54]],"ltp":190.0,"tv":20.7,"id":22308007},{"batl":[[1,2.38,106.45],[2,2.4,6.63]],"ltp":2.2,"tv":3348.47,"id":10107355}]}]}
{"op":"mcm","clk":"993562557","pt":1580543932473,"mc":[{"id":"1.168133543","rc":[{"batl":[[1,2.36,4],[2,2.38,106.45]],"ltp":2.2,"tv":3348.47,"id":10107355}]}]}
{"op":"mcm","clk":"993563233","pt":1580543939497,"mc":[{"id":"1.168133543","rc":[{"batl":[[1,2.36,4.04],[2,2.38,106.41]],"ltp":2.2,"tv":3348.47,"id":10107355}]}]}
{"op":"mcm","clk":"993563457","pt":1580543941520,"mc":[{"id":"1.168133543","rc":[{"batl":[[2,2.4,6.63]],"ltp":2.2,"tv":3348.47,"id":10107355}]}]}
{"op":"mcm","clk":"993563562","pt":1580543942501,"mc":[{"id":"1.168133543","rc":[{"batl":[[1,2.36,111.35]],"ltp":2.2,"tv":3348.47,"id":10107355}]}]}
{"op":"mcm","clk":"993564811","pt":1580543955435,"mc":[{"id":"1.168133543","rc":[{"batl":[[2,9,4]],"ltp":8.0,"tv":637.75,"id":10163711}]}]}
{"op":"mcm","clk":"993564919","pt":1580543956516,"mc":[{"id":"1.168133543","rc":[{"batl":[[0,8.4,7.02],[1,8.6,27.98],[2,8.8,2]],"ltp":8.0,"tv":637.75,"id":10163711},{"batl":[[1,2.36,4.04],[2,2.38,106.41]],"ltp":2.2,"tv":3348.47,"id":10107355}]}]}
{"op":"mcm","clk":"993566181","pt":1580543970440,"mc":[{"id":"1.168133543","rc":[{"batl":[[1,8.6,2]],"ltp":8.0,"tv":637.75,"id":10163711},{"batl":[[1,2.36,111.35],[2,2.4,6.63]],"ltp":2.2,"tv":3348.47,"id":10107355}]}]}
{"op":"mcm","clk":"993567315","pt":1580543985433,"mc":[{"id":"1.168133543","rc":[{"batl":[[1,2.36,4.04],[2,2.38,106.41]],"ltp":2.2,"tv":3348.47,"id":10107355}]}]}
{"op":"mcm","clk":"993568393","pt":1580543998538,"mc":[{"id":"1.168133543","rc":[{"batl":[[2,2.4,6.63]],"ltp":2.2,"tv":3348.47,"id":10107355}]}]}
{"op":"mcm","clk":"993568469","pt":1580543999567,"mc":[{"id":"1.168133543","rc":[{"batl":[[1,2.36,111.35]],"ltp":2.2,"tv":3348.47,"id":10107355}]}]}
{"op":"mcm","clk":"993568564","pt":1580544000557,"mc":[{"id":"1.168133543","rc":[{"trd":[[4.1,21.04]],"batb":[[0,4.1,1.08],[1,4,9.14],[2,3.95,6.03]],"batl":[[0,5.5,6.67],[1,9.2,9],[2,10.5,24]],"ltp":4.1,"tv":1795.19,"id":12636}],"tv":6475.03}]}
{"op":"mcm","clk":"993568655","pt":1580544001486,"mc":[{"id":"1.168133543","rc":[{"batl":[[0,5.4,4.51],[1,5.5,8.92],[2,9.2,9]],"ltp":4.1,"tv":1795.19,"id":12636}]}]}
{"op":"mcm","clk":"993568893","pt":1580544003364,"mc":[{"id":"1.168133543","rc":[{"batl":[[0,5.5,6.67],[1,9.2,9],[2,10.5,24]],"ltp":4.1,"tv":1795.19,"id":12636}]}]}
{"op":"mcm","clk":"993569188","pt":1580544006477,"mc":[{"id":"1.168133543","rc":[{"trd":[[8,8]],"batb":[[0,8,19.54]],"ltp":8.0,"tv":641.75,"id":10163711}],"tv":6479.03}]}
{"op":"mcm","clk":"993569242","pt":1580544007092,"mc":[{"id":"1.168133543","rc":[{"batl":[[2,13,19]],"ltp":4.1,"tv":1795.19,"id":12636}]}]}
{"op":"mcm","clk":"993569457","pt":1580544009565,"mc":[{"id":"1.168133543","rc":[{"batl":[[0,5.4,2.95],[1,5.5,6.67],[2,9.2,9]],"ltp":4.1,"tv":1795.19,"id":12636}]}]}
{"op":"mcm","clk":"993569717","pt":1580544013269,"mc":[{"id":"1.168133543","rc":[{"batl":[[0,160,3.03]],"ltp":190.0,"tv":20.7,"id":22308007},{"batl":[[1,2.36,4.04]],"ltp":2.2,"tv":3348.47,"id":10107355}]}]}
{"op":"mcm","clk":"993569852","pt":1580544015377,"mc":[{"id":"1.168133543","rc":[{"trd":[[4,23.52],[4.1,23.2]],"batb":[[0,3.95,6.25],[1,3.9,4.05],[2,3.85,10]],"batl":[[0,4.1,2],[1,5.4,2.95],[2,5.5,6.67]],"ltp":4.0,"tv":1815.19,"id":12636}],"tv":6499.03}]}
{"op":"mcm","clk":"993570103","pt":1580544018390,"mc":[{"id":"1.168133543","rc":[{"trd":[[4.1,27.2]],"batl":[[0,5.4,2.95],[1,5.5,6.67],[2,9.2,9]],"ltp":4.1,"tv":1819.19,"id":12636}],"tv":6503.03}]}
{"op":"mcm","clk":"993570345","pt":1580544021574,"mc":[{"id":"1.168133543","rc":[{"batb":[[1,260,1.19]],"ltp":450.0,"tv":26.52,"id":24270700}]}]}
{"op":"mcm","clk":"993570423","pt":1580544022493,"mc":[{"id":"1.168133543","rc":[{"batb":[[0,3.95,6.03]],"batl":[[0,5.2,7.52],[1,5.3,8.08],[2,5.4,2.95]],"ltp":4.1,"tv":1819.19,"id":12636},{"batb":[[1,260,1.35]],"ltp":450.0,"tv":26.52,"id":24270700}]}]}
{"op":"mcm","clk":"993570769","pt":1580544027478,"mc":[{"id":"1.168133543","rc":[{"batl":[[1,2.34,108.27],[2,2.36,4]],"ltp":2.2,"tv":3348.47,"id":10107355},{"batl":[[0,8,38.37],[1,8.2,7.62],[2,8.6,2]],"ltp":8.2,"tv":524.73,"id":22121325}]}]}
{"op":"mcm","clk":"993570846","pt":1580544028503,"mc":[{"id":"1.168133543","rc":[{"batl":[[0,160,3.54]],"ltp":190.0,"tv":20.7,"id":22308007},{"batl":[[1,2.32,11.87],[2,2.34,108.23]],"ltp":2.2,"tv":3348.47,"id":10107355}]}]}
{"op":"mcm","clk":"993570990","pt":1580544030503,"mc":[{"id":"1.168133543","rc":[{"batb":[[0,4,3],[1,3.95,6.03],[2,3.9,4.05]],"ltp":4.1,"tv":1819.19,"id":12636}]}]}
{"op":"mcm","clk":"993571437","pt":1580544036479,"mc":[{"id":"1.168133543","rc":[{"batl":[[0,2.3,2.04],[1,2.32,11.83]],"ltp":2.2,"tv":3348.47,"id":10107355}]}]}
{"op":"mcm","clk":"993571809","pt":1580544041523,"mc":[{"id":"1.168133543","rc":[{"batl":[[2,2.4,6.63]],"ltp":2.2,"tv":3348.47,"id":10107355}]}]}
{"op":"mcm","clk":"993571889","pt":1580544042514,"mc":[{"id":"1.168133543","rc":[{"batl":[[0,2.3,112.15]],"ltp":2.2,"tv":3348.47,"id":10107355}]}]}
{"op":"mcm","clk":"993572116","pt":1580544045509,"mc":[{"id":"1.168133543","rc":[{"batl":[[1,5.4,2.95],[2,5.5,6.67]],"ltp":4.1,"tv":1819.19,"id":12636},{"batl":[[0,8,38.91],[1,8.2,7.08]],"ltp":8.2,"tv":524.73,"id":22121325}]}]}
{"op":"mcm","clk":"993572427","pt":1580544048528,"mc":[{"id":"1.168133543","rc":[{"batb":[[0,3.95,6.03],[1,3.9,4.05],[2,3.85,10]],"ltp":4.1,"tv":1819.19,"id":12636}]}]}
{"op":"mcm","clk":"993572643","pt":1580544051523,"mc":[{"id":"1.168133543","rc":[{"batb":[[2,190,1.15]],"ltp":450.0,"tv":26.52,"id":24270700}]}]}
{"op":"mcm","clk":"993572734","pt":1580544052210,"mc":[{"id":"1.168133543","rc":[{"batb":[[2,200,78]],"ltp":450.0,"tv":26.52,"id":24270700}]}]}
{"op":"mcm","clk":"993573215","pt":1580544057529,"mc":[{"id":"1.168133543","rc":[{"batb":[[2,200,77.93]],"ltp":450.0,"tv":26.52,"id":24270700}]}]}
{"op":"mcm","clk":"993573467","pt":1580544060543,"mc":[{"id":"1.168133543","rc":[{"trd":[[7.4,43.08]],"batb":[[0,7.4,2.26]],"ltp":7.4,"tv":530.13,"id":22121325}],"tv":6508.43}]}
{"op":"mcm","clk":"993574015","pt":1580544064550,"mc":[{"id":"1.168133543","rc":[{"batl":[[0,5.1,7.6],[1,5.2,7.52],[2,5.4,2.95]],"ltp":4.1,"tv":1819.19,"id":12636}]}]}
{"op":"mcm","clk":"993574144","pt":1580544065542,"mc":[{"id":"1.168133543","rc":[{"batb":[[2,200,78.01]],"ltp":450.0,"tv":26.52,"id":24270700}]}]}
{"op":"mcm","clk":"993574233","pt":1580544066523,"mc":[{"id":"1.168133543","rc":[{"batl":[[0,5,8.57],[1,5.1,7.6],[2,5.2,7.52]],"ltp":4.1,"tv":1819.19,"id":12636}]}]}
{"op":"mcm","clk":"993574556","pt":1580544070511,"mc":[{"id":"1.168133543","rc":[{"batl":[[0,8.2,7.62],[1,8.6,2],[2,9.4,8.02]],"ltp":7.4,"tv":530.13,"id":22121325}]}]}
{"op":"mcm","clk":"993574626","pt":1580544071448,"mc":[{"id":"1.168133543","rc":[{"batl":[[2,9.4,15.85]],"ltp":7.4,"tv":530.13,"id":22121325}]}]}
{"op":"mcm","clk":"993575577","pt":1580544080116,"mc":[{"id":"1.168133543","rc":[{"batb":[[0,7.6,1.52],[1,7.4,2.26],[2,7.2,4.22]],"ltp":7.4,"tv":530.13,"id":22121325}]}]}
{"op":"mcm","clk":"993576129","pt":1580544088360,"mc":[{"id":"1.168133543","rc":[{"batl":[[1,8.6,9]],"ltp":8.0,"tv":641.75,"id":10163711}]}]}
{"op":"mcm","clk":"993577147","pt":1580544101471,"mc":[{"id":"1.168133543","rc":[{"batl":[[2,2.42,5.5]],"ltp":2.2,"tv":3348.47,"id":10107355}]}]}
{"op":"mcm","clk":"993580713","pt":1580544141127,"mc":[{"id":"1.168133543","rc":[{"batb":[[0,7.4,2.26],[1,7.2,4.22],[2,7,8]],"ltp":7.4,"tv":530.13,"id":22121325}]}]}
{"op":"mcm","clk":"993581632","pt":1580544149574,"mc":[{"id":"1.168133543","rc":[{"batb":[[1,260,1.19]],"ltp":450.0,"tv":26.52,"id":24270700}]}]}
{"op":"mcm","clk":"993581645","pt":1580544149680,"mc":[{"id":"1.168133543","rc":[{"batb":[[1,260,1.35]],"ltp":450.0,"tv":26.52,"id":24270700}]}]}
{"op":"mcm","clk":"993582391","pt":1580544156562,"mc":[{"id":"1.168133543","rc":[{"batl":[[0,2.3,2.04]],"ltp":2.2,"tv":3348.47,"id":10107355}]}]}
{"op":"mcm","clk":"993583631","pt":1580544170496,"mc":[{"id":"1.168133543","rc":[{"batl":[[0,2.32,11.87],[1,2.42,5.5],[2,2.46,21]],"ltp":2.2,"tv":3348.47,"id":10107355},{"batb":[[1,260,1.19]],"ltp":450.0,"tv":26.52,"id":24270700}]}]}
{"op":"mcm","clk":"993583655","pt":1580544170759,"mc":[{"id":"1.168133543","rc":[{"batl":[[1,2.4,2.29],[2,2.42,5.5]],"ltp":2.2,"tv":3348.47,"id":10107355},{"batb":[[1,260,1.35]],"ltp":450.0,"tv":26.52,"id":24270700}]}]}
{"op":"mcm","clk":"993584122","pt":1580544176370,"mc":[{"id":"1.168133543","rc":[{"batb":[[2,75,21]],"batl":[[1,200,1.72],[2,320,2]],"ltp":190.0,"tv":20.7,"id":22308007},{"batl":[[0,500,4.44],[1,510,9]],"ltp":60.0,"tv":42.47,"id":7226819},{"batb":[[0,8,2.25]],"ltp":8.0,"tv":641.75,"id":10163711},{"batl":[[1,2.4,8.18]],"ltp":2.2,"tv":3348.47,"id":10107355},{"batb":[[0,7.8,1.9],[1,7.6,18.33],[2,7.2,4.5]],"ltp":7.4,"tv":530.13,"id":22121325},{"batb":[[0,100,5],[1,90,1.01],[2,80,20.18]],"batl":[[1,980,9.15],[2,980,0]],"ltp":95.0,"tv":17.79,"id":26548208}]}]}
{"op":"mcm","clk":"993584198","pt":1580544177340,"mc":[{"id":"1.168133543","rc":[{"batl":[[0,510,9.23],[1,550,2],[2,800,2]],"ltp":60.0,"tv":42.47,"id":7226819}]}]}
{"op":"mcm","clk":"993584259","pt":1580544178179,"mc":[{"id":"1.168133543","rc":[{"batb":[[2,7.2,8.02]],"ltp":7.4,"tv":530.13,"id":22121325},{"batb":[[2,85,2.31]],"ltp":95.0,"tv":17.79,"id":26548208}]}]}
{"op":"mcm","clk":"993584812","pt":1580544185420,"mc":[{"id":"1.168133543","rc":[{"batl":[[0,2.3,110.15],[1,2.32,11.83],[2,2.4,8.18]],"ltp":2.2,"tv":3348.47,"id":10107355},{"trd":[[100,8.52]],"batb":[[0,100,2.04]],"ltp":100.0,"tv":23.71,"id":26548208}],"tv":6514.35}]}
{"op":"mcm","clk":"993584892","pt":1580544186509,"mc":[{"id":"1.168133543","rc":[{"batl":[[1,190,5],[2,200,1.72]],"ltp":190.0,"tv":20.7,"id":22308007},{"batl":[[0,100,5.08],[1,510,9.15],[2,550,2]],"ltp":60.0,"tv":42.47,"id":7226819},{"batb":[[0,90,1.01],[1,85,2.31],[2,80,17.87]],"ltp":100.0,"tv":23.71,"id":26548208}]}]}
{"op":"mcm","clk":"993584948","pt":1580544187386,"mc":[{"id":"1.168133543","rc":[{"batb":[[1,80,18.08],[2,70,1.1]],"ltp":100.0,"tv":23.71,"id":26548208}]}]}
{"op":"mcm","clk":"993585132","pt":1580544190499,"mc":[{"id":"1.168133543","rc":[{"batb":[[1,80,18.27]],"ltp":100.0,"tv":23.71,"id":26548208}]}]}
{"op":"mcm","clk":"993585804","pt":1580544200521,"mc":[{"id":"1.168133543","rc":[{"batb":[[1,80,2.27]],"ltp":100.0,"tv":23.71,"id":26548208}]}]}
{"op":"mcm","clk":"993585927","pt":1580544202326,"mc":[{"id":"1.168133543","rc":[{"batb":[[1,80,2.06]],"ltp":100.0,"tv":23.71,"id":26548208}]}]}
{"op":"mcm","clk":"993586410","pt":1580544209508,"mc":[{"id":"1.168133543","rc":[{"batb":[[2,70,1.35]],"ltp":100.0,"tv":23.71,"id":26548208}]}]}
{"op":"mcm","clk":"993587049","pt":1580544218334,"mc":[{"id":"1.168133543","rc":[{"batb":[[2,70,3.45]],"ltp":100.0,"tv":23.71,"id":26548208}]}]}
{"op":"mcm","clk":"993588607","pt":1580544241571,"mc":[{"id":"1.168133543","rc":[{"batb":[[0,80,2.65],[1,70,3.45],[2,65,16.77]],"ltp":100.0,"tv":23.71,"id":26548208}]}]}
{"op":"mcm","clk":"993588642","pt":1580544242082,"mc":[{"id":"1.168133543","rc":[{"batb":[[1,70,3.98]],"ltp":100.0,"tv":23.71,"id":26548208}]}]}
{"op":"mcm","clk":"993589674","pt":1580544258289,"mc":[{"id":"1.168133543","rc":[{"batb":[[1,75,16.91],[2,70,3.07]],"ltp":100.0,"tv":23.71,"id":26548208}]}]}
{"op":"mcm","clk":"993589967","pt":1580544262309,"mc":[{"id":"1.168133543","rc":[{"batb":[[2,70,2.82]],"ltp":100.0,"tv":23.71,"id":26548208}]}]}
{"op":"mcm","clk":"993590447","pt":1580544269512,"mc":[{"id":"1.168133543","rc":[{"batb":[[0,80,2.87]],"ltp":100.0,"tv":23.71,"id":26548208}]}]}
{"op":"mcm","clk":"993591852","pt":1580544290011,"mc":[{"id":"1.168133543","rc":[{"batl":[[1,5.2,7.52],[2,5.5,6.67]],"ltp":4.1,"tv":1819.19,"id":12636}]}]}
{"op":"mcm","clk":"993592373","pt":1580544298310,"mc":[{"id":"1.168133543","rc":[{"trd":[[8.2,31.92]],"batb":[[0,7.8,9.22]],"batl":[[0,8.6,2.06],[1,9.4,15.85],[2,9.8,11.64]],"ltp":8.2,"tv":545.25,"id":22121325}],"tv":6529.48}]}
{"op":"mcm","clk":"993592454","pt":1580544299543,"mc":[{"id":"1.168133543","rc":[{"batb":[[0,8,1.91],[1,7.8,7.32],[2,7.6,18.33]],"batl":[[1,9.2,33.36],[2,9.4,15.85]],"ltp":8.2,"tv":545.25,"id":22121325}]}]}
{"op":"mcm","clk":"993592482","pt":1580544300056,"mc":[{"id":"1.168133543","rc":[{"batl":[[2,9.8,3.97]],"ltp":8.2,"tv":545.25,"id":22121325}]}]}
{"op":"mcm","clk":"993592816","pt":1580544305426,"mc":[{"id":"1.168133543","rc":[{"batl":[[0,4.9,7.6],[1,5,8.57],[2,5.2,7.52]],"ltp":4.1,"tv":1819.19,"id":12636}]}]}
{"op":"mcm","clk":"993593381","pt":1580544313481,"mc":[{"id":"1.168133543","rc":[{"batl":[[1,5.2,7.52],[2,5.5,6.67]],"ltp":4.1,"tv":1819.19,"id":12636},{"batl":[[0,160,3.03]],"ltp":190.0,"tv":20.7,"id":22308007},{"batl":[[0,2.32,11.87],[1,2.4,8.18],[2,2.42,5.5]],"ltp":2.2,"tv":3348.47,"id":10107355},{"batl":[[1,9.8,3.97],[2,10,14.16]],"ltp":8.2,"tv":545.25,"id":22121325},{"batb":[[1,260,1.19]],"ltp":450.0,"tv":26.52,"id":24270700}]}]}
{"op":"mcm","clk":"993593468","pt":1580544314465,"mc":[{"id":"1.168133543","rc":[{"batl":[[1,2.4,40.28]],"ltp":2.2,"tv":3348.47,"id":10107355},{"batl":[[1,9.8,8.14]],"ltp":8.2,"tv":545.25,"id":22121325},{"batb":[[1,260,1.35]],"ltp":450.0,"tv":26.52,"id":24270700}]}]}
{"op":"mcm","clk":"993593505","pt":1580544315037,"mc":[{"id":"1.168133543","rc":[{"batl":[[0,9.8,8.2],[1,10,14.16],[2,11,12.1]],"ltp":8.2,"tv":545.25,"id":22121325}]}]}
{"op":"mcm","clk":"993593627","pt":1580544316533,"mc":[{"id":"1.168133543","rc":[{"batl":[[1,2.4,8.18]],"ltp":2.2,"tv":3348.47,"id":10107355},{"batl":[[0,10,14.52],[1,11,12.1],[2,11.5,5.08]],"ltp":8.2,"tv":545.25,"id":22121325}]}]}
{"op":"mcm","clk":"993594395","pt":1580544325565,"mc":[{"id":"1.168133543","rc":[{"batl":[[0,8.2,2],[1,8.4,7.02],[2,8.6,9]],"ltp":8.0,"tv":641.75,"id":10163711},{"batb":[[0,8,4.41]],"ltp":8.2,"tv":545.25,"id":22121325},{"batb":[[1,260,1.42]],"ltp":450.0,"tv":26.52,"id":24270700}]}]}
{"op":"mcm","clk":"993594464","pt":1580544326283,"mc":[{"id":"1.168133543","rc":[{"trd":[[8,12.5]],"batb":[[0,7.8,6.41],[1,7,35.21],[2,6.8,21.64]],"batl":[[0,8,12.55],[1,8.2,2],[2,8.4,7.02]],"ltp":8.0,"tv":646.25,"id":10163711},{"batb":[[0,8.2,1.92],[1,8,2.5],[2,7.8,7.32]],"ltp":8.2,"tv":545.25,"id":22121325}],"tv":6533.97}]}
{"op":"mcm","clk":"993594543","pt":1580544327360,"mc":[{"id":"1.168133543","rc":[{"batb":[[1,7.2,4.44],[2,7,40.78]],"ltp":8.0,"tv":646.25,"id":10163711},{"batl":[[0,2.32,11.83],[1,2.4,8.22]],"ltp":2.2,"tv":3348.47,"id":10107355}]}]}
{"op":"mcm","clk":"993594619","pt":1580544328488,"mc":[{"id":"1.168133543","rc":[{"batl":[[0,4.8,44.06],[1,4.9,7.6],[2,5.2,7.52]],"ltp":4.1,"tv":1819.19,"id":12636},{"trd":[[7.8,12.81]],"batb":[[0,7.2,4.44],[1,7,40.78],[2,6.8,21.64]],"batl":[[0,7.8,22.25],[1,8,12.55],[2,8.2,2]],"ltp":7.8,"tv":659.06,"id":10163711},{"batl":[[0,2.3,110.11],[1,2.32,11.83],[2,2.4,8.22]],"ltp":2.2,"tv":3348.47,"id":10107355},{"batl":[[0,9.8,31.68],[1,10,14.16],[2,11,12.1]],"ltp":8.2,"tv":545.25,"id":22121325}],"tv":6546.79}]}
{"op":"mcm","clk":"993594667","pt":1580544329160,"mc":[{"id":"1.168133543","rc":[{"batl":[[0,4.7,8.04],[1,4.8,44.06],[2,4.9,7.6]],"ltp":4.1,"tv":1819.19,"id":12636},{"batl":[[0,160,3.54]],"ltp":190.0,"tv":20.7,"id":22308007},{"batb":[[2,6.8,23.37]],"ltp":7.8,"tv":659.06,"id":10163711}]}]}
{"op":"mcm","clk":"993594769","pt":1580544330550,"mc":[{"id":"1.168133543","rc":[{"batb":[[0,7,35.21],[1,6.8,25.96],[2,6.4,1.4]],"ltp":7.8,"tv":659.06,"id":10163711}]}]}
{"op":"mcm","clk":"993595069","pt":1580544334570,"mc":[{"id":"1.168133543","rc":[{"batl":[[0,4.7,22.04]],"ltp":4.1,"tv":1819.19,"id":12636}]}]}
{"op":"mcm","clk":"993595143","pt":1580544335493,"mc":[{"id":"1.168133543","rc":[{"batl":[[0,9.6,2.36],[1,9.8,31.32],[2,10,14.16]],"ltp":8.2,"tv":545.25,"id":22121325}]}]}
{"op":"mcm","clk":"993595469","pt":1580544339562,"mc":[{"id":"1.168133543","rc":[{"batb":[[0,4,20],[1,3.95,6.03],[2,3.9,4.05]],"ltp":4.1,"tv":1819.19,"id":12636}]}]}
{"op":"mcm","clk":"993595527","pt":1580544340278,"mc":[{"id":"1.168133543","rc":[{"batb":[[2,6.2,6]],"ltp":7.8,"tv":659.06,"id":10163711}]}]}
{"op":"mcm","clk":"993595680","pt":1580544342492,"mc":[{"id":"1.168133543","rc":[{"batl":[[1,4.9,7.6],[2,5.4,46]],"ltp":4.1,"tv":1819.19,"id":12636},{"batb":[[2,6,10.43]],"ltp":7.8,"tv":659.06,"id":10163711}]}]}
{"op":"mcm","clk":"993595760","pt":1580544343471,"mc":[{"id":"1.168133543","rc":[{"batl":[[0,4.6,45.98],[1,4.7,22.04],[2,4.9,7.6]],"ltp":4.1,"tv":1819.19,"id":12636}]}]}
{"op":"mcm","clk":"993596257","pt":1580544350183,"mc":[{"id":"1.168133543","rc":[{"batb":[[0,7.2,2.42],[1,7,36.67],[2,6.8,25.96]],"ltp":7.8,"tv":659.06,"id":10163711}]}]}
{"op":"mcm","clk":"993596726","pt":1580544356511,"mc":[{"id":"1.168133543","rc":[{"trd":[[7.2,3.58],[7.6,4.42]],"batb":[[0,7,35.42],[1,6.8,25.96],[2,6,10.43]],"ltp":7.2,"tv":663.06,"id":10163711},{"batb":[[1,260,1.26]],"ltp":450.0,"tv":26.52,"id":24270700}],"tv":6550.78}]}
{"op":"mcm","clk":"993596788","pt":1580544357488,"mc":[{"id":"1.168133543","rc":[{"batb":[[1,260,1.42]],"ltp":450.0,"tv":26.52,"id":24270700}]}]}
{"op":"mcm","clk":"993596844","pt":1580544358517,"mc":[{"id":"1.168133543","rc":[{"batl":[[2,8.2,2.19]],"ltp":7.2,"tv":663.06,"id":10163711}]}]}
{"op":"mcm","clk":"993596970","pt":1580544360402,"mc":[{"id":"1.168133543","rc":[{"batb":[[1,6.8,23.37]],"ltp":7.2,"tv":663.06,"id":10163711}]}]}
{"op":"mcm","clk":"993597290","pt":1580544364480,"mc":[{"id":"1.168133543","rc":[{"batb":[[1,6.8,23.68]],"ltp":7.2,"tv":663.06,"id":10163711}]}]}
{"op":"mcm","clk":"993598221","pt":1580544379514,"mc":[{"id":"1.168133543","rc":[{"batb":[[1,260,1.26]],"ltp":450.0,"tv":26.52,"id":24270700}]}]}
{"op":"mcm","clk":"993598299","pt":1580544380545,"mc":[{"id":"1.168133543","rc":[{"batl":[[2,8.4,7.21]],"ltp":7.2,"tv":663.06,"id":10163711},{"batb":[[1,260,1.42]],"ltp":450.0,"tv":26.52,"id":24270700}]}]}
{"op":"mcm","clk":"993598719","pt":1580544386443,"mc":[{"id":"1.168133543","rc":[{"batb":[[1,6.8,21.95],[2,6.6,1.79]],"ltp":7.2,"tv":663.06,"id":10163711}]}]}
{"op":"mcm","clk":"993600309","pt":1580544409565,"mc":[{"id":"1.168133543","rc":[{"batb":[[1,80,4.57]],"ltp":190.0,"tv":20.7,"id":22308007}]}]}
{"op":"mcm","clk":"993600366","pt":1580544410546,"mc":[{"id":"1.168133543","rc":[{"batl":[[0,180,3.54]],"ltp":190.0,"tv":20.7,"id":22308007}]}]}
{"op":"mcm","clk":"993600588","pt":1580544414543,"mc":[{"id":"1.168133543","rc":[{"batl":[[0,180,3.03]],"ltp":190.0,"tv":20.7,"id":22308007}]}]}
{"op":"mcm","clk":"993600786","pt":1580544418160,"mc":[{"id":"1.168133543","rc":[{"batb":[[0,80,2.68]],"ltp":100.0,"tv":23.71,"id":26548208}]}]}
{"op":"mcm","clk":"993602285","pt":1580544441910,"mc":[{"id":"1.168133543","rc":[{"batl":[[0,2.3,110.15],[2,2.4,8.18]],"ltp":2.2,"tv":3348.47,"id":10107355}]}]}
{"op":"mcm","clk":"993602941","pt":1580544451445,"mc":[{"id":"1.168133543","rc":[{"batb":[[2,6.4,1.86]],"ltp":7.2,"tv":663.06,"id":10163711},{"batb":[[2,7.6,18.33]],"ltp":8.2,"tv":545.25,"id":22121325}]}]}
{"op":"mcm","clk":"993612936","pt":1580544452325,"mc":[{"id":"1.168133543","rc":[{"batb":[[2,7.6,20.58]],"ltp":8.2,"tv":545.25,"id":22121325}]}]}
{"op":"mcm","clk":"993614142","pt":1580544469551,"mc":[{"id":"1.168133543","rc":[{"trd":[[4,63.52]],"batb":[[0,3.95,6.03],[1,3.9,4.05],[2,3.85,10]],"ltp":4.0,"tv":1859.19,"id":12636}],"tv":6590.78}]}
{"op":"mcm","clk":"993614350","pt":1580544472550,"mc":[{"id":"1.168133543","rc":[{"trd":[[3.75,75.14],[3.85,20],[3.9,120.06],[3.95,20.06]],"batb":[[0,3.7,6.61],[1,3.65,68],[2,3.6,5]],"batl":[[1,4.7,14]],"ltp":3.75,"tv":1959.19,"id":12636},{"batb":[[0,7.2,2.04],[1,7,35],[2,6.8,21.95]],"ltp":7.2,"tv":663.06,"id":10163711},{"batb":[[0,2.24,2],[1,2.22,7.75],[2,2.2,46.45]],"ltp":2.2,"tv":3348.47,"id":10107355}],"tv":6690.78}]}
{"op":"mcm","clk":"993614390","pt":1580544473270,"mc":[{"id":"1.168133543","rc":[{"trd":[[7.2,4.42]],"batb":[[0,7,35],[1,6.8,21.95],[2,6.4,1.86]],"ltp":7.2,"tv":663.9,"id":10163711},{"batb":[[0,2.22,7.75],[1,2.2,46.45],[2,2.14,5.51]],"ltp":2.2,"tv":3348.47,"id":10107355},{"batb":[[2,7.6,21.22]],"ltp":8.2,"tv":545.25,"id":22121325}],"tv":6691.63}]}
{"op":"mcm","clk":"993615080","pt":1580544483568,"mc":[{"id":"1.168133543","rc":[{"batl":[[0,900,2],[1,1000,0.2]],"ltp":590.0,"tv":20.43,"id":27606066}]}]}
{"op":"mcm","clk":"993615137","pt":1580544484287,"mc":[{"id":"1.168133543","rc":[{"batl":[[0,900,2.2],[1,1000,0]],"ltp":590.0,"tv":20.43,"id":27606066}]}]}
{"op":"mcm","clk":"993615206","pt":1580544485473,"mc":[{"id":"1.168133543","rc":[{"batl":[[0,4.7,14],[1,4.9,7.6],[2,5.4,46]],"ltp":3.75,"tv":1959.19,"id":12636},{"batb":[[0,7.2,2.21],[1,7,35],[2,6.8,21.95]],"batl":[[0,8,12.55],[1,8.4,7.21],[2,8.6,7]],"ltp":7.2,"tv":663.9,"id":10163711},{"batl":[[0,2.32,11.87],[1,2.4,8.18],[2,2.42,5.5]],"ltp":2.2,"tv":3348.47,"id":10107355},{"batl":[[1,10,14.16],[2,11,12.1]],"ltp":8.2,"tv":545.25,"id":22121325}]}]}
{"op":"mcm","clk":"993615270","pt":1580544486396,"mc":[{"id":"1.168133543","rc":[{"batl":[[1,8.4,13.01],[2,8.6,14.96]],"ltp":7.2,"tv":663.9,"id":10163711},{"batl":[[1,2.4,40.28]],"ltp":2.2,"tv":3348.47,"id":10107355}]}]}
{"op":"mcm","clk":"993615333","pt":1580544487479,"mc":[{"id":"1.168133543","rc":[{"trd":[[3.6,18.22],[3.7,41.73]],"batb":[[0,3.55,6],[1,3.4,12],[2,3.35,79.1]],"batl":[[0,3.6,13.39],[1,4.7,14],[2,4.9,7.6]],"ltp":3.6,"tv":1982.41,"id":12636}],"tv":6714.85}]}
{"op":"mcm","clk":"993615412","pt":1580544488567,"mc":[{"id":"1.168133543","rc":[{"trd":[[3.55,31.56],[3.6,45]],"batb":[[0,3.5,3.44],[1,3.45,8.06],[2,3.4,16.39]],"batl":[[0,4.9,7.6],[1,5.5,6.67],[2,5.9,42]],"ltp":3.6,"tv":2028.75,"id":12636},{"trd":[[8,19]],"batl":[[0,8,9.3],[1,8.6,15.15],[2,8.8,2]],"ltp":8.0,"tv":670.4,"id":10163711},{"batl":[[1,2.4,8.18]],"ltp":2.2,"tv":3348.47,"id":10107355}],"tv":6767.69}]}
{"op":"mcm","clk":"993615468","pt":1580544489491,"mc":[{"id":"1.168133543","rc":[{"batb":[[0,3.45,8.06],[1,3.4,16.39],[2,3.35,79.1]],"ltp":3.6,"tv":2028.75,"id":12636}]}]}
{"op":"mcm","clk":"993615519","pt":1580544490368,"mc":[{"id":"1.168133543","rc":[{"batb":[[1,3.4,12]],"batl":[[1,5.4,10.5],[2,5.5,16.91]],"ltp":3.6,"tv":2028.75,"id":12636}]}]}
{"op":"mcm","clk":"993616299","pt":1580544500878,"mc":[{"id":"1.168133543","rc":[{"batl":[[0,9.6,2.3],[1,10,14.22]],"ltp":8.2,"tv":545.25,"id":22121325},{"batl":[[0,990,2.02],[1,1000,1.3]],"ltp":190.0,"tv":29.17,"id":13306150}]}]}
{"op":"mcm","clk":"993617521","pt":1580544516489,"mc":[{"id":"1.168133543","rc":[{"batb":[[1,260,1.26]],"ltp":450.0,"tv":26.52,"id":24270700}]}]}
{"op":"mcm","clk":"993617586","pt":1580544517518,"mc":[{"id":"1.168133543","rc":[{"batb":[[2,3.35,4.1]],"batl":[[1,5.5,16.91],[2,6.8,37]],"ltp":3.6,"tv":2028.75,"id":12636},{"batb":[[1,260,1.42]],"ltp":450.0,"tv":26.52,"id":24270700}]}]}
{"op":"mcm","clk":"993617657","pt":1580544518500,"mc":[{"id":"1.168133543","rc":[{"batl":[[1,5.4,2.31],[2,5.5,16.91]],"ltp":3.6,"tv":2028.75,"id":12636}]}]}
{"op":"mcm","clk":"993618509","pt":1580544531425,"mc":[{"id":"1.168133543","rc":[{"batl":[[0,5.4,2.31],[1,5.5,16.91],[2,6.8,37]],"ltp":3.6,"tv":2028.75,"id":12636}]}]}
{"op":"mcm","clk":"993618569","pt":1580544532450,"mc":[{"id":"1.168133543","rc":[{"batl":[[0,5.5,10.18],[1,6.8,37],[2,9.2,9]],"ltp":3.6,"tv":2028.75,"id":12636}]}]}
{"op":"mcm","clk":"993618648","pt":1580544533534,"mc":[{"id":"1.168133543","rc":[{"batl":[[0,5.5,6.67],[1,6.6,9.84],[2,6.8,45.81]],"ltp":3.6,"tv":2028.75,"id":12636}]}]}
{"op":"mcm","clk":"993618882","pt":1580544537145,"mc":[{"id":"1.168133543","rc":[{"trd":[[3.4,23.88],[3.45,25.18]],"batb":[[0,3.35,4.16],[1,3.3,23.77],[2,3.1,81]],"batl":[[1,6.6,14.89]],"ltp":3.4,"tv":2068.75,"id":12636}],"tv":6807.69}]}
{"op":"mcm","clk":"993619116","pt":1580544540346,"mc":[{"id":"1.168133543","rc":[{"batl":[[0,4,10],[1,5.5,6.67],[2,6.6,14.89]],"ltp":3.4,"tv":2068.75,"id":12636}]}]}
{"op":"mcm","clk":"993619205","pt":1580544541549,"mc":[{"id":"1.168133543","rc":[{"trd":[[3.35,3.88],[3.4,24]],"batb":[[0,3.35,2.16]],"ltp":3.35,"tv":2072.75,"id":12636},{"trd":[[7.6,44.42],[7.8,15.28],[8,18.95],[8.2,35.76]],"batb":[[0,7.2,5.14],[1,7,8],[2,6.6,47.6]],"ltp":7.6,"tv":595.26,"id":22121325}],"tv":6861.69}]}
{"op":"mcm","clk":"993619265","pt":1580544542535,"mc":[{"id":"1.168133543","rc":[{"batb":[[0,7.2,4.5]],"ltp":7.6,"tv":595.26,"id":22121325}]}]}
{"op":"mcm","clk":"993619336","pt":1580544543517,"mc":[{"id":"1.168133543","rc":[{"batb":[[0,3.35,90.22]],"batl":[[0,3.95,2],[1,4,10],[2,5.5,6.67]],"ltp":3.35,"tv":2072.75,"id":12636},{"batb":[[1,85,6.04],[2,80,3.67]],"ltp":190.0,"tv":20.7,"id":22308007},{"batb":[[1,46,11.75]],"ltp":60.0,"tv":42.47,"id":7226819},{"batb":[[0,7.2,32.22]],"ltp":7.6,"tv":595.26,"id":22121325},{"batb":[[1,160,3.66],[2,150,89.32]],"ltp":590.0,"tv":20.43,"id":27606066}]}]}
{"op":"mcm","clk":"993619418","pt":1580544544550,"mc":[{"id":"1.168133543","rc":[{"trd":[[3.35,43.86]],"batb":[[0,3.35,70.24]],"ltp":3.35,"tv":2112.73,"id":12636},{"batb":[[0,7.4,7.87],[1,7.2,31.93],[2,7,8]],"ltp":7.6,"tv":595.26,"id":22121325},{"batb":[[0,85,2.12],[1,80,2.09],[2,75,16.91]],"ltp":100.0,"tv":23.71,"id":26548208},{"batb":[[0,180,4.77]],"ltp":190.0,"tv":29.17,"id":13306150}],"tv":6901.67}]}
{"op":"mcm","clk":"993619463","pt":1580544545219,"mc":[{"id":"1.168133543","rc":[{"batb":[[2,44,1.57]],"ltp":60.0,"tv":42.47,"id":7226819}]}]}
{"op":"mcm","clk":"993619639","pt":1580544547544,"mc":[{"id":"1.168133543","rc":[{"batl":[[0,3.9,7.6],[1,3.95,2],[2,4,10]],"ltp":3.35,"tv":2112.73,"id":12636},{"batb":[[0,90,4.22],[2,75,21.64]],"ltp":190.0,"tv":20.7,"id":22308007}]}]}
{"op":"mcm","clk":"993619715","pt":1580544548530,"mc":[{"id":"1.168133543","rc":[{"trd":[[3.35,163.8]],"batb":[[0,3.35,10.3],[2,2.94,85]],"ltp":3.35,"tv":2232.67,"id":12636},{"batb":[[0,48,1.5]],"ltp":60.0,"tv":42.47,"id":7226819},{"trd":[[2.22,266.84]],"batb":[[0,2.2,46.45],[1,2.14,13.87],[2,2.12,5.27]],"batl":[[0,2.22,1.05],[1,2.32,11.87],[2,2.4,8.18]],"ltp":2.22,"tv":3379.98,"id":10107355},{"batl":[[0,9.6,2.48]],"ltp":7.6,"tv":595.26,"id":22121325}],"tv":7053.12}]}
{"op":"mcm","clk":"993619798","pt":1580544549564,"mc":[{"id":"1.168133543","rc":[{"trd":[[2.22,268.94]],"batb":[[0,2.24,3.05],[1,2.2,46.45],[2,2.14,3.24]],"batl":[[0,2.4,8.22],[1,2.42,21.24],[2,2.46,21]],"ltp":2.22,"tv":3382.08,"id":10107355}],"tv":7055.22}]}
{"op":"mcm","clk":"993619842","pt":1580544550355,"mc":[{"id":"1.168133543","rc":[{"batb":[[0,3.4,1.98],[1,3.35,10.3],[2,3.3,23.77]],"ltp":3.35,"tv":2232.67,"id":12636},{"batb":[[0,7.4,1.98],[1,7.2,2.21],[2,7,35]],"ltp":8.0,"tv":670.4,"id":10163711},{"batb":[[0,2.24,7.76]],"batl":[[0,2.42,21.28],[1,2.46,21],[2,2.48,50]],"ltp":2.22,"tv":3382.08,"id":10107355},{"batb":[[0,7.6,1.98],[1,7.4,7.87],[2,7.2,31.93]],"ltp":7.6,"tv":595.26,"id":22121325}]}]}
{"op":"mcm","clk":"993619921","pt":1580544551328,"mc":[{"id":"1.168133543","rc":[{"batl":[[0,2.42,5.54]],"ltp":2.22,"tv":3382.08,"id":10107355}]}]}
{"op":"mcm","clk":"993620072","pt":1580544553544,"mc":[{"id":"1.168133543","rc":[{"trd":[[3.35,179.83],[3.4,27.96]],"batb":[[0,3.35,2.29],[1,3.3,23.77],[2,2.96,6]],"ltp":3.35,"tv":2252.67,"id":12636},{"batb":[[0,48,1.87]],"ltp":60.0,"tv":42.47,"id":7226819}],"tv":7075.21}]}
{"op":"mcm","clk":"993620143","pt":1580544554371,"mc":[{"id":"1.168133543","rc":[{"batl":[[0,9.4,2.05],[1,9.6,2.13],[2,10,14.22]],"ltp":7.6,"tv":595.26,"id":22121325}]}]}
{"op":"mcm","clk":"993620242","pt":1580544555553,"mc":[{"id":"1.168133543","rc":[{"batb":[[2,3,8.63]],"ltp":3.35,"tv":2252.67,"id":12636},{"trd":[[2.24,309.67]],"batb":[[0,2.24,5.76]],"ltp":2.24,"tv":3386.08,"id":10107355}],"tv":7079.21}]}
{"op":"mcm","clk":"993620390","pt":1580544557565,"mc":[{"id":"1.168133543","rc":[{"batb":[[0,3.3,23.77],[1,3,8.63],[2,2.96,6]],"batl":[[0,3.9,11.12]],"ltp":3.35,"tv":2252.67,"id":12636},{"batb":[[1,80,1.54],[2,75,21]],"ltp":190.0,"tv":20.7,"id":22308007},{"batb":[[1,46,1.08]],"ltp":60.0,"tv":42.47,"id":7226819},{"batb":[[2,7.2,4.22]],"ltp":7.6,"tv":595.26,"id":22121325},{"batb":[[0,80,2.68],[1,75,16.91],[2,65,1.49]],"ltp":100.0,"tv":23.71,"id":26548208},{"batb":[[1,150,89.82],[2,110,13.5]],"ltp":590.0,"tv":20.43,"id":27606066},{"batb":[[0,180,2.4]],"ltp":190.0,"tv":29.17,"id":13306150}]}]}
{"op":"mcm","clk":"993620462","pt":1580544558545,"mc":[{"id":"1.168133543","rc":[{"batb":[[1,80,1.04]],"ltp":190.0,"tv":20.7,"id":22308007},{"batb":[[1,260,1.26]],"ltp":450.0,"tv":26.52,"id":24270700}]}]}
{"op":"mcm","clk":"993620539","pt":1580544559571,"mc":[{"id":"1.168133543","rc":[{"batl":[[0,3.8,7.5],[1,3.85,11.13],[2,3.9,11.12]],"ltp":3.35,"tv":2252.67,"id":12636},{"batl":[[0,9.2,4.83],[1,9.4,1.69],[2,9.6,2.13]],"ltp":7.6,"tv":595.26,"id":22121325},{"batb":[[1,260,1.42]],"ltp":450.0,"tv":26.52,"id":24270700}]}]}
{"op":"mcm","clk":"993620605","pt":1580544560553,"mc":[{"id":"1.168133543","rc":[{"batb":[[0,48,1.5]],"ltp":60.0,"tv":42.47,"id":7226819}]}]}
{"op":"mcm","clk":"993620663","pt":1580544561375,"mc":[{"id":"1.168133543","rc":[{"batb":[[1,3.05,13.14],[2,3,5.8]],"ltp":3.35,"tv":2252.67,"id":12636}]}]}
{"op":"mcm","clk":"993620715","pt":1580544562457,"mc":[{"id":"1.168133543","rc":[{"batb":[[1,3.05,26.28]],"ltp":3.35,"tv":2252.67,"id":12636}]}]}
{"op":"mcm","clk":"993621023","pt":1580544567448,"mc":[{"id":"1.168133543","rc":[{"batb":[[0,3.35,1.98],[1,3.3,23.77],[2,3.05,26.28]],"ltp":3.35,"tv":2252.67,"id":12636},{"trd":[[2.24,311.77]],"batb":[[0,2.22,4.71]],"ltp":2.24,"tv":3388.18,"id":10107355}],"tv":7081.31}]}
{"op":"mcm","clk":"993621039","pt":1580544567656,"mc":[{"id":"1.168133543","rc":[{"batb":[[2,44,1.98]],"ltp":60.0,"tv":42.47,"id":7226819}]}]}
{"op":"mcm","clk":"993621243","pt":1580544570560,"mc":[{"id":"1.168133543","rc":[{"batb":[[2,3,5.8]],"ltp":3.35,"tv":2252.67,"id":12636}]}]}
{"op":"mcm","clk":"993621304","pt":1580544571488,"mc":[{"id":"1.168133543","rc":[{"batb":[[0,95,4.59],[1,90,4.22],[2,80,1.04]],"ltp":190.0,"tv":20.7,"id":22308007},{"batb":[[1,46,11.75]],"ltp":60.0,"tv":42.47,"id":7226819},{"batb":[[0,2.22,118.78]],"ltp":2.24,"tv":3388.18,"id":10107355},{"batb":[[0,7.6,28.24]],"ltp":7.6,"tv":595.26,"id":22121325}]}]}
{"op":"mcm","clk":"993621370","pt":1580544572367,"mc":[{"id":"1.168133543","rc":[{"batb":[[0,2.24,14.65],[1,2.22,118.78],[2,2.2,46.45]],"ltp":2.24,"tv":3388.18,"id":10107355},{"batb":[[0,85,2.12],[1,80,2.09],[2,75,16.91]],"ltp":100.0,"tv":23.71,"id":26548208}]}]}
{"op":"mcm","clk":"993621565","pt":1580544575101,"mc":[{"id":"1.168133543","rc":[{"batb":[[2,44,1.57]],"ltp":60.0,"tv":42.47,"id":7226819}]}]}
{"op":"mcm","clk":"993621646","pt":1580544576492,"mc":[{"id":"1.168133543","rc":[{"batb":[[2,3,14.43]],"ltp":3.35,"tv":2252.67,"id":12636}]}]}
{"op":"mcm","clk":"993621846","pt":1580544579391,"mc":[{"id":"1.168133543","rc":[{"batb":[[0,95,20.59]],"ltp":190.0,"tv":20.7,"id":22308007}]}]}
{"op":"mcm","clk":"993621922","pt":1580544580481,"mc":[{"id":"1.168133543","rc":[{"batl":[[1,3.9,11.12],[2,3.95,2]],"ltp":3.35,"tv":2252.67,"id":12636},{"batb":[[0,100,3.42],[1,95,20.59],[2,90,1.19]],"ltp":190.0,"tv":20.7,"id":22308007},{"batb":[[0,7.8,3.89],[1,7.6,28.24],[2,7.4,7.87]],"ltp":7.6,"tv":595.26,"id":22121325}]}]}
{"op":"mcm","clk":"993622158","pt":1580544583395,"mc":[{"id":"1.168133543","rc":[{"batb":[[0,48,1.87]],"ltp":60.0,"tv":42.47,"id":7226819}]}]}
{"op":"mcm","clk":"993622346","pt":1580544586500,"mc":[{"id":"1.168133543","rc":[{"batb":[[1,95,16]],"ltp":190.0,"tv":20.7,"id":22308007},{"batb":[[1,46,1.08]],"ltp":60.0,"tv":42.47,"id":7226819},{"batb":[[1,2.22,4.71]],"ltp":2.24,"tv":3388.18,"id":10107355},{"batb":[[1,7.6,1.98]],"ltp":7.6,"tv":595.26,"id":22121325},{"batb":[[0,80,2.68],[1,75,16.91],[2,65,1.49]],"ltp":100.0,"tv":23.71,"id":26548208}]}]}
{"op":"mcm","clk":"993622566","pt":1580544589507,"mc":[{"id":"1.168133543","rc":[{"batb":[[0,2.22,4.71],[1,2.2,46.45],[2,2.14,3.24]],"ltp":2.24,"tv":3388.18,"id":10107355}]}]}
{"op":"mcm","clk":"993622635","pt":1580544590547,"mc":[{"id":"1.168133543","rc":[{"batb":[[0,100,3.59]],"ltp":190.0,"tv":20.7,"id":22308007}]}]}
{"op":"mcm","clk":"993622664","pt":1580544590816,"mc":[{"id":"1.168133543","rc":[{"batb":[[0,48,1.5]],"ltp":60.0,"tv":42.47,"id":7226819}]}]}
{"op":"mcm","clk":"993622804","pt":1580544592532,"mc":[{"id":"1.168133543","rc":[{"batb":[[2,7.4,10.55]],"ltp":7.6,"tv":595.26,"id":22121325}]}]}
{"op":"mcm","clk":"993623062","pt":1580544596521,"mc":[{"id":"1.168133543","rc":[{"batl":[[0,2.4,2.04],[1,2.42,5.5],[2,2.46,21]],"ltp":2.24,"tv":3388.18,"id":10107355}]}]}
{"op":"mcm","clk":"993623196","pt":1580544598543,"mc":[{"id":"1.168133543","rc":[{"batb":[[2,44,1.98]],"ltp":60.0,"tv":42.47,"id":7226819}]}]}
{"op":"mcm","clk":"993623353","pt":1580544600525,"mc":[{"id":"1.168133543","rc":[{"batb":[[0,85,2.12],[1,80,2.09],[2,75,16.91]],"ltp":100.0,"tv":23.71,"id":26548208}]}]}
{"op":"mcm","clk":"993624255","pt":1580544612573,"mc":[{"id":"1.168133543","rc":[{"batb":[[0,7.6,5.88],[1,7.4,10.55],[2,7,8]],"ltp":7.6,"tv":595.26,"id":22121325}]}]}
{"op":"mcm","clk":"993624398","pt":1580544614539,"mc":[{"id":"1.168133543","rc":[{"batb":[[1,46,11.75]],"ltp":60.0,"tv":42.47,"id":7226819},{"batb":[[0,2.22,118.78]],"ltp":2.24,"tv":3388.18,"id":10107355},{"batb":[[0,7.8,25.58],[1,7.6,5.88],[2,7.4,10.55]],"ltp":7.6,"tv":595.26,"id":22121325}]}]}
{"op":"mcm","clk":"993624912","pt":1580544621556,"mc":[{"id":"1.168133543","rc":[{"batb":[[2,44,1.57]],"ltp":60.0,"tv":42.47,"id":7226819}]}]}
{"op":"mcm","clk":"993625415","pt":1580544629490,"mc":[{"id":"1.168133543","rc":[{"batb":[[0,48,1.87]],"ltp":60.0,"tv":42.47,"id":7226819}]}]}
{"op":"mcm","clk":"993626415","pt":1580544642398,"mc":[{"id":"1.168133543","rc":[{"trd":[[46,0.26],[48,3.74]],"batb":[[0,46,11.62],[1,44,1.57],[2,42,24.07]],"batl":[[0,100,5.28]],"ltp":46.0,"tv":46.47,"id":7226819}],"tv":7085.31}]}
{"op":"mcm","clk":"993626514","pt":1580544643567,"mc":[{"id":"1.168133543","rc":[{"batb":[[0,44,2.52],[1,42,27.02],[2,40,1.25]],"ltp":46.0,"tv":46.47,"id":7226819}]}]}
{"op":"mcm","clk":"993626719","pt":1580544646501,"mc":[{"id":"1.168133543","rc":[{"batb":[[1,42,21.19]],"ltp":46.0,"tv":46.47,"id":7226819}]}]}
{"op":"mcm","clk":"993626757","pt":1580544647011,"mc":[{"id":"1.168133543","rc":[{"batb":[[0,8,3.7],[1,7.8,25.58],[2,7.6,1.98]],"ltp":7.6,"tv":595.26,"id":22121325}]}]}
{"op":"mcm","clk":"993626998","pt":1580544650415,"mc":[{"id":"1.168133543","rc":[{"batb":[[1,3.3,20]],"ltp":3.35,"tv":2252.67,"id":12636}]}]}
{"op":"mcm","clk":"993627513","pt":1580544657498,"mc":[{"id":"1.168133543","rc":[{"batb":[[0,2.22,4.71]],"ltp":2.24,"tv":3388.18,"id":10107355},{"batb":[[1,7.6,1.98],[2,7.4,10.55]],"ltp":7.6,"tv":595.26,"id":22121325}]}]}
{"op":"mcm","clk":"993627569","pt":1580544658218,"mc":[{"id":"1.168133543","rc":[{"batb":[[1,7.6,4.51],[2,7.4,2.97]],"ltp":7.6,"tv":595.26,"id":22121325}]}]}
{"op":"mcm","clk":"993628221","pt":1580544667527,"mc":[{"id":"1.168133543","rc":[{"batb":[[1,7.6,1.98]],"ltp":7.6,"tv":595.26,"id":22121325}]}]}
{"op":"mcm","clk":"993628785","pt":1580544675354,"mc":[{"id":"1.168133543","rc":[{"batb":[[2,3.05,7]],"ltp":3.35,"tv":2252.67,"id":12636},{"batb":[[2,7.2,6.83]],"ltp":7.6,"tv":595.26,"id":22121325}]}]}
{"op":"mcm","clk":"993629086","pt":1580544679536,"mc":[{"id":"1.168133543","rc":[{"trd":[[9,8.44],[9.2,11.97]],"batb":[[0,7.6,1.98],[1,7.2,6.83],[2,7,8]],"batl":[[0,9.2,1.83]],"ltp":9.2,"tv":601.26,"id":22121325}],"tv":7091.31}]}
{"op":"mcm","clk":"993629140","pt":1580544680255,"mc":[{"id":"1.168133543","rc":[{"batb":[[2,3.1,5.84]],"ltp":3.35,"tv":2252.67,"id":12636},{"batb":[[1,7.4,4.39],[2,7.2,6.55]],"ltp":9.2,"tv":601.26,"id":22121325}]}]}
{"op":"mcm","clk":"993629215","pt":1580544681439,"mc":[{"id":"1.168133543","rc":[{"batb":[[2,7,8]],"ltp":9.2,"tv":601.26,"id":22121325}]}]}
{"op":"mcm","clk":"993629407","pt":1580544683964,"mc":[{"id":"1.168133543","rc":[{"batb":[[0,7.6,2.18]],"ltp":9.2,"tv":601.26,"id":22121325}]}]}
{"op":"mcm","clk":"993629493","pt":1580544685562,"mc":[{"id":"1.168133543","rc":[{"batb":[[0,7.8,5.69],[1,7.6,1.98],[2,7.4,4.39]],"ltp":9.2,"tv":601.26,"id":22121325}]}]}
{"op":"mcm","clk":"993630365","pt":1580544696467,"mc":[{"id":"1.168133543","rc":[{"batb":[[0,3.35,7.12]],"ltp":3.35,"tv":2252.67,"id":12636},{"batb":[[1,7.2,4.61]],"ltp":8.0,"tv":670.4,"id":10163711}]}]}
{"op":"mcm","clk":"993630695","pt":1580544701485,"mc":[{"id":"1.168133543","rc":[{"batb":[[0,80,2.68],[1,75,16.91],[2,65,1.49]],"ltp":100.0,"tv":23.71,"id":26548208}]}]}
{"op":"mcm","clk":"993630830","pt":1580544703493,"mc":[{"id":"1.168133543","rc":[{"batl":[[0,3.75,2],[1,3.8,7.5],[2,3.9,11.12]],"ltp":3.35,"tv":2252.67,"id":12636}]}]}
{"op":"mcm","clk":"993630892","pt":1580544704171,"mc":[{"id":"1.168133543","rc":[{"batb":[[2,7.4,7.46]],"ltp":9.2,"tv":601.26,"id":22121325}]}]}
{"op":"mcm","clk":"993630983","pt":1580544705573,"mc":[{"id":"1.168133543","rc":[{"batl":[[1,2.42,7.5]],"ltp":2.24,"tv":3388.18,"id":10107355}]}]}
{"op":"mcm","clk":"993632909","pt":1580544731927,"mc":[{"id":"1.168133543","rc":[{"batb":[[0,44,2.63]],"ltp":46.0,"tv":46.47,"id":7226819}]}]}
{"op":"mcm","clk":"993633199","pt":1580544736107,"mc":[{"id":"1.168133543","rc":[{"batb":[[1,7.2,2.39]],"ltp":8.0,"tv":670.4,"id":10163711}]}]}
{"op":"mcm","clk":"993636392","pt":1580544773543,"mc":[{"id":"1.168133543","rc":[{"batl":[[2,3.9,3.52]],"ltp":3.35,"tv":2252.67,"id":12636},{"batl":[[0,9.2,1.89]],"ltp":9.2,"tv":601.26,"id":22121325}]}]}
{"op":"mcm","clk":"993637089","pt":1580544782558,"mc":[{"id":"1.168133543","rc":[{"batb":[[0,3.35,14.12]],"ltp":3.35,"tv":2252.67,"id":12636}]}]}
{"op":"mcm","clk":"993637161","pt":1580544783541,"mc":[{"id":"1.168133543","rc":[{"batb":[[0,3.4,8.53],[1,3.35,14.12],[2,3.3,20]],"ltp":3.35,"tv":2252.67,"id":12636}]}]}
{"op":"mcm","clk":"993637242","pt":1580544784476,"mc":[{"id":"1.168133543","rc":[{"batl":[[0,3.75,6.24]],"ltp":3.35,"tv":2252.67,"id":12636},{"batb":[[0,8,1.98],[1,7.8,5.69],[2,7.6,1.98]],"batl":[[1,9.6,2.13],[2,10,14.16]],"ltp":9.2,"tv":601.26,"id":22121325}]}]}
{"op":"mcm","clk":"993637320","pt":1580544785563,"mc":[{"id":"1.168133543","rc":[{"batb":[[1,7.8,5.49]],"batl":[[2,10,17.17]],"ltp":9.2,"tv":601.26,"id":22121325}]}]}
{"op":"mcm","clk":"993637385","pt":1580544786453,"mc":[{"id":"1.168133543","rc":[{"batb":[[0,8,2.18]],"ltp":9.2,"tv":601.26,"id":22121325}]}]}
{"op":"mcm","clk":"993637616","pt":1580544789481,"mc":[{"id":"1.168133543","rc":[{"batb":[[0,8.2,3.36],[1,8,1.98]],"ltp":9.2,"tv":601.26,"id":22121325}]}]}
{"op":"mcm","clk":"993637773","pt":1580544791465,"mc":[{"id":"1.168133543","rc":[{"batb":[[2,7.6,5.38]],"ltp":9.2,"tv":601.26,"id":22121325}]}]}
{"op":"mcm","clk":"993637855","pt":1580544792558,"mc":[{"id":"1.168133543","rc":[{"batl":[[0,9.2,1.83],[2,10,17.23]],"ltp":9.2,"tv":601.26,"id":22121325}]}]}
{"op":"mcm","clk":"993638455","pt":1580544799480,"mc":[{"id":"1.168133543","rc":[{"batl":[[0,990,2.22]],"ltp":190.0,"tv":29.17,"id":13306150}]}]}
{"op":"mcm","clk":"993638970","pt":1580544805512,"mc":[{"id":"1.168133543","rc":[{"batl":[[0,990,2.02]],"ltp":190.0,"tv":29.17,"id":13306150}]}]}
{"op":"mcm","clk":"993639118","pt":1580544807481,"mc":[{"id":"1.168133543","rc":[{"batl":[[0,3.75,2]],"ltp":3.35,"tv":2252.67,"id":12636},{"batb":[[0,8.4,1.89],[1,8.2,3.36]],"ltp":9.2,"tv":601.26,"id":22121325}]}]}
{"op":"mcm","clk":"993639388","pt":1580544810514,"mc":[{"id":"1.168133543","rc":[{"batb":[[0,8.6,3.02],[1,8.4,1.89],[2,7.6,5.57]],"ltp":9.2,"tv":601.26,"id":22121325}]}]}
{"op":"mcm","clk":"993639478","pt":1580544811504,"mc":[{"id":"1.168133543","rc":[{"batl":[[0,990,2.22]],"ltp":190.0,"tv":29.17,"id":13306150}]}]}
{"op":"mcm","clk":"993639908","pt":1580544816530,"mc":[{"id":"1.168133543","rc":[{"batb":[[0,3.4,14.83]],"batl":[[0,3.75,135.02]],"ltp":3.35,"tv":2252.67,"id":12636},{"batl":[[0,2.38,11.61],[1,2.4,107.57],[2,2.42,7.5]],"ltp":2.24,"tv":3388.18,"id":10107355}]}]}
{"op":"mcm","clk":"993639980","pt":1580544817423,"mc":[{"id":"1.168133543","rc":[{"batl":[[0,3.7,9.17],[1,3.75,135.02],[2,3.8,7.5]],"ltp":3.35,"tv":2252.67,"id":12636},{"batb":[[2,7.8,4.09]],"ltp":9.2,"tv":601.26,"id":22121325},{"batl":[[0,990,2.02]],"ltp":190.0,"tv":29.17,"id":13306150}]}]}
{"op":"mcm","clk":"993640082","pt":1580544818528,"mc":[{"id":"1.168133543","rc":[{"batb":[[2,8,3.11]],"ltp":9.2,"tv":601.26,"id":22121325}]}]}
{"op":"mcm","clk":"993640435","pt":1580544822317,"mc":[{"id":"1.168133543","rc":[{"batl":[[0,990,2.22]],"ltp":190.0,"tv":29.17,"id":13306150}]}]}
{"op":"mcm","clk":"993640609","pt":1580544824279,"mc":[{"id":"1.168133543","rc":[{"batl":[[0,3.7,29.17]],"ltp":3.35,"tv":2252.67,"id":12636},{"batl":[[0,2.38,31.61]],"ltp":2.24,"tv":3388.18,"id":10107355}]}]}
{"op":"mcm","clk":"993640862","pt":1580544827496,"mc":[{"id":"1.168133543","rc":[{"trd":[[2.22,288.93]],"batb":[[0,2.22,2]],"batl":[[0,2.38,20]],"ltp":2.22,"tv":3408.17,"id":10107355}],"tv":7111.31}]}
{"op":"mcm","clk":"993640960","pt":1580544828532,"mc":[{"id":"1.168133543","rc":[{"batb":[[0,3.45,4],[1,3.4,14.83],[2,3.35,14.12]],"ltp":3.35,"tv":2252.67,"id":12636},{"batb":[[0,2.2,46.45],[1,2.14,3.24],[2,2.12,5.27]],"ltp":2.22,"tv":3408.17,"id":10107355}]}]}
{"op":"mcm","clk":"993641048","pt":1580544829512,"mc":[{"id":"1.168133543","rc":[{"batl":[[1,3.75,2]],"ltp":3.35,"tv":2252.67,"id":12636},{"trd":[[180,1.82]],"batl":[[0,180,2.12]],"ltp":180.0,"tv":22.52,"id":22308007},{"batb":[[1,2.12,5.27],[2,2.06,6]],"batl":[[1,2.4,2.04]],"ltp":2.22,"tv":3408.17,"id":10107355},{"batl":[[0,990,2.02]],"ltp":190.0,"tv":29.17,"id":13306150}],"tv":7113.13}]}
{"op":"mcm","clk":"993641121","pt":1580544830492,"mc":[{"id":"1.168133543","rc":[{"batb":[[1,2.08,33.08],[2,2.06,22.54]],"batl":[[2,2.42,5.5]],"ltp":2.22,"tv":3408.17,"id":10107355}]}]}
{"op":"mcm","clk":"993641189","pt":1580544831429,"mc":[{"id":"1.168133543","rc":[{"batl":[[0,3.7,20]],"ltp":3.35,"tv":2252.67,"id":12636},{"batl":[[0,2.36,2],[1,2.38,20],[2,2.4,2.04]],"ltp":2.22,"tv":3408.17,"id":10107355},{"batb":[[1,260,1.26]],"ltp":450.0,"tv":26.52,"id":24270700}]}]}
{"op":"mcm","clk":"993641283","pt":1580544832518,"mc":[{"id":"1.168133543","rc":[{"batb":[[1,260,1.42]],"ltp":450.0,"tv":26.52,"id":24270700}]}]}
{"op":"mcm","clk":"993641450","pt":1580544834433,"mc":[{"id":"1.168133543","rc":[{"batb":[[2,75,5.98]],"ltp":180.0,"tv":22.52,"id":22308007},{"batl":[[0,990,2.22]],"ltp":190.0,"tv":29.17,"id":13306150}]}]}
{"op":"mcm","clk":"993641594","pt":1580544836305,"mc":[{"id":"1.168133543","rc":[{"batb":[[0,3.5,10],[1,3.45,4],[2,3.4,14.83]],"ltp":3.35,"tv":2252.67,"id":12636}]}]}
{"op":"mcm","clk":"993641794","pt":1580544838435,"mc":[{"id":"1.168133543","rc":[{"trd":[[9.2,12.52]],"batl":[[0,9.2,1.55]],"ltp":9.2,"tv":601.81,"id":22121325}],"tv":7113.68}]}
{"op":"mcm","clk":"993641953","pt":1580544840345,"mc":[{"id":"1.168133543","rc":[{"batl":[[0,2.36,2.04],[2,2.4,2]],"ltp":2.22,"tv":3408.17,"id":10107355},{"batl":[[0,990,2.02]],"ltp":190.0,"tv":29.17,"id":13306150}]}]}
{"op":"mcm","clk":"993642028","pt":1580544841126,"mc":[{"id":"1.168133543","rc":[{"batb":[[0,3.55,6],[1,3.5,10],[2,3.45,4]],"ltp":3.35,"tv":2252.67,"id":12636}]}]}
{"op":"mcm","clk":"993642242","pt":1580544843508,"mc":[{"id":"1.168133543","rc":[{"batl":[[0,2.36,109.35]],"ltp":2.22,"tv":3408.17,"id":10107355}]}]}
{"op":"mcm","clk":"993642346","pt":1580544844439,"mc":[{"id":"1.168133543","rc":[{"batb":[[1,2.08,49.61]],"ltp":2.22,"tv":3408.17,"id":10107355},{"batl":[[2,10,14.22]],"ltp":9.2,"tv":601.81,"id":22121325}]}]}
{"op":"mcm","clk":"993642546","pt":1580544846516,"mc":[{"id":"1.168133543","rc":[{"batl":[[0,990,2.22]],"ltp":190.0,"tv":29.17,"id":13306150}]}]}
{"op":"mcm","clk":"993642629","pt":1580544847544,"mc":[{"id":"1.168133543","rc":[{"batl":[[0,3.75,2],[1,3.8,7.5],[2,3.9,3.52]],"ltp":3.35,"tv":2252.67,"id":12636}]}]}
{"op":"mcm","clk":"993642832","pt":1580544849564,"mc":[{"id":"1.168133543","rc":[{"batb":[[2,8.2,3.9]],"ltp":9.2,"tv":601.81,"id":22121325}]}]}
{"op":"mcm","clk":"993642936","pt":1580544850542,"mc":[{"id":"1.168133543","rc":[{"batb":[[0,3.55,13]],"ltp":3.35,"tv":2252.67,"id":12636}]}]}
{"op":"mcm","clk":"993643015","pt":1580544851530,"mc":[{"id":"1.168133543","rc":[{"batb":[[0,300,1.03],[1,230,1.03],[2,150,89.82]],"ltp":590.0,"tv":20.43,"id":27606066},{"batl":[[0,990,2.02]],"ltp":190.0,"tv":29.17,"id":13306150}]}]}
{"op":"mcm","clk":"993643190","pt":1580544853543,"mc":[{"id":"1.168133543","rc":[{"batb":[[2,2.06,16.54]],"ltp":2.22,"tv":3408.17,"id":10107355}]}]}
{"op":"mcm","clk":"993643499","pt":1580544857160,"mc":[{"id":"1.168133543","rc":[{"batl":[[0,990,2.22]],"ltp":190.0,"tv":29.17,"id":13306150}]}]}
{"op":"mcm","clk":"993643989","pt":1580544863569,"mc":[{"id":"1.168133543","rc":[{"batl":[[0,3.8,7.5],[1,3.9,3.52],[2,4,10]],"ltp":3.35,"tv":2252.67,"id":12636}]}]}
{"op":"mcm","clk":"993644064","pt":1580544864449,"mc":[{"id":"1.168133543","rc":[{"batl":[[0,990,2.02]],"ltp":190.0,"tv":29.17,"id":13306150}]}]}
{"op":"mcm","clk":"993644468","pt":1580544869464,"mc":[{"id":"1.168133543","rc":[{"batl":[[0,990,2.22]],"ltp":190.0,"tv":29.17,"id":13306150}]}]}
{"op":"mcm","clk":"993644838","pt":1580544873444,"mc":[{"id":"1.168133543","rc":[{"batb":[[1,260,1.26]],"ltp":450.0,"tv":26.52,"id":24270700}]}]}
{"op":"mcm","clk":"993644917","pt":1580544874375,"mc":[{"id":"1.168133543","rc":[{"batb":[[1,260,1.42]],"ltp":450.0,"tv":26.52,"id":24270700}]}]}
{"op":"mcm","clk":"993645007","pt":1580544875499,"mc":[{"id":"1.168133543","rc":[{"batl":[[0,990,2.02]],"ltp":190.0,"tv":29.17,"id":13306150}]}]}
{"op":"mcm","clk":"993645310","pt":1580544878477,"mc":[{"id":"1.168133543","rc":[{"batl":[[0,3.8,11.11],[1,4,10],[2,4.2,6]],"ltp":3.35,"tv":2252.67,"id":12636}]}]}
{"op":"mcm","clk":"993645409","pt":1580544879561,"mc":[{"id":"1.168133543","rc":[{"batl":[[2,4.6,6]],"ltp":3.35,"tv":2252.67,"id":12636}]}]}
{"op":"mcm","clk":"993645586","pt":1580544881486,"mc":[{"id":"1.168133543","rc":[{"batl":[[0,990,2.22]],"ltp":190.0,"tv":29.17,"id":13306150}]}]}
{"op":"mcm","clk":"993646049","pt":1580544886369,"mc":[{"id":"1.168133543","rc":[{"batl":[[0,990,2.02]],"ltp":190.0,"tv":29.17,"id":13306150}]}]}
{"op":"mcm","clk":"993646130","pt":1580544887399,"mc":[{"id":"1.168133543","rc":[{"trd":[[2.2,123.9]],"batb":[[0,2.2,42.05]],"ltp":2.2,"tv":3416.97,"id":10107355}],"tv":7122.48}]}
{"op":"mcm","clk":"993646592","pt":1580544892080,"mc":[{"id":"1.168133543","rc":[{"batb":[[0,80,2.83]],"ltp":100.0,"tv":23.71,"id":26548208},{"batl":[[0,990,2.22]],"ltp":190.0,"tv":29.17,"id":13306150}]}]}
{"op":"mcm","clk":"993646691","pt":1580544893315,"mc":[{"id":"1.168133543","rc":[{"batl":[[1,10,14.35],[2,11,12.1]],"ltp":9.2,"tv":601.81,"id":22121325}]}]}
{"op":"mcm","clk":"993646793","pt":1580544894510,"mc":[{"id":"1.168133543","rc":[{"batb":[[1,260,1.26]],"ltp":450.0,"tv":26.52,"id":24270700}]}]}
{"op":"mcm","clk":"993646821","pt":1580544894975,"mc":[{"id":"1.168133543","rc":[{"batl":[[2,11,15.11]],"ltp":9.2,"tv":601.81,"id":22121325},{"batb":[[1,260,1.42]],"ltp":450.0,"tv":26.52,"id":24270700}]}]}
{"op":"mcm","clk":"993647188","pt":1580544898922,"mc":[{"id":"1.168133543","rc":[{"batl":[[1,10,14.29],[2,11,15.17]],"ltp":9.2,"tv":601.81,"id":22121325},{"batl":[[0,990,2.02]],"ltp":190.0,"tv":29.17,"id":13306150}]}]}
{"op":"mcm","clk":"993647722","pt":1580544904418,"mc":[{"id":"1.168133543","rc":[{"batl":[[0,990,2.22]],"ltp":190.0,"tv":29.17,"id":13306150}]}]}
{"op":"mcm","clk":"993648245","pt":1580544910207,"mc":[{"id":"1.168133543","rc":[{"batl":[[0,990,2.02]],"ltp":190.0,"tv":29.17,"id":13306150}]}]}
{"op":"mcm","clk":"993648892","pt":1580544917513,"mc":[{"id":"1.168133543","rc":[{"batl":[[2,5.1,49]],"ltp":3.35,"tv":2252.67,"id":12636},{"batl":[[0,2.34,2.04],[1,2.36,109.31],[2,2.38,20]],"ltp":2.2,"tv":3416.97,"id":10107355}]}]}
{"op":"mcm","clk":"993648979","pt":1580544918441,"mc":[{"id":"1.168133543","rc":[{"batb":[[1,2.14,2.06],[2,2.08,49.61]],"batl":[[0,2.34,13.8]],"ltp":2.2,"tv":3416.97,"id":10107355}]}]}
{"op":"mcm","clk":"993649327","pt":1580544922118,"mc":[{"id":"1.168133543","rc":[{"batl":[[2,2.42,5.5]],"ltp":2.2,"tv":3416.97,"id":10107355}]}]}
{"op":"mcm","clk":"993649533","pt":1580544924552,"mc":[{"id":"1.168133543","rc":[{"batb":[[1,8.2,3.9],[2,8,2.92]],"ltp":9.2,"tv":601.81,"id":22121325}]}]}
{"op":"mcm","clk":"993649693","pt":1580544926329,"mc":[{"id":"1.168133543","rc":[{"batb":[[1,2.14,20.86]],"ltp":2.2,"tv":3416.97,"id":10107355}]}]}
{"op":"mcm","clk":"993649824","pt":1580544927733,"mc":[{"id":"1.168133543","rc":[{"batb":[[2,160,13.5]],"ltp":590.0,"tv":20.43,"id":27606066}]}]}
{"op":"mcm","clk":"993649991","pt":1580544929545,"mc":[{"id":"1.168133543","rc":[{"batl":[[1,2.36,2]],"ltp":2.2,"tv":3416.97,"id":10107355}]}]}
{"op":"mcm","clk":"993650079","pt":1580544930470,"mc":[{"id":"1.168133543","rc":[{"batb":[[1,2.16,2.02],[2,2.14,20.86]],"batl":[[0,2.32,109.16],[1,2.34,2.04],[2,2.36,2]],"ltp":2.2,"tv":3416.97,"id":10107355}]}]}
{"op":"mcm","clk":"993650284","pt":1580544932545,"mc":[{"id":"1.168133543","rc":[{"batb":[[2,2.14,2.06]],"ltp":2.2,"tv":3416.97,"id":10107355}]}]}
{"op":"mcm","clk":"993650464","pt":1580544934360,"mc":[{"id":"1.168133543","rc":[{"batb":[[2,2.14,20.86]],"ltp":2.2,"tv":3416.97,"id":10107355}]}]}
{"op":"mcm","clk":"993650580","pt":1580544935455,"mc":[{"id":"1.168133543","rc":[{"batb":[[2,2.14,2.06]],"ltp":2.2,"tv":3416.97,"id":10107355}]}]}
{"op":"mcm","clk":"993650904","pt":1580544938572,"mc":[{"id":"1.168133543","rc":[{"batl":[[2,5.5,6.67]],"ltp":3.35,"tv":2252.67,"id":12636}]}]}
{"op":"mcm","clk":"993651005","pt":1580544939552,"mc":[{"id":"1.168133543","rc":[{"batb":[[2,2.14,20.86]],"ltp":2.2,"tv":3416.97,"id":10107355}]}]}
{"op":"mcm","clk":"993651208","pt":1580544941480,"mc":[{"id":"1.168133543","rc":[{"batl":[[2,320,2]],"ltp":180.0,"tv":22.52,"id":22308007},{"batb":[[2,2.14,2.06]],"ltp":2.2,"tv":3416.97,"id":10107355}]}]}
{"op":"mcm","clk":"993651399","pt":1580544943353,"mc":[{"id":"1.168133543","rc":[{"batb":[[2,2.14,20.86]],"ltp":2.2,"tv":3416.97,"id":10107355}]}]}
{"op":"mcm","clk":"993651506","pt":1580544944484,"mc":[{"id":"1.168133543","rc":[{"batb":[[2,2.14,2.06]],"batl":[[0,2.34,2.04],[1,2.36,2],[2,2.42,5.5]],"ltp":2.2,"tv":3416.97,"id":10107355}]}]}
{"op":"mcm","clk":"993651567","pt":1580544945162,"mc":[{"id":"1.168133543","rc":[{"batb":[[1,2.14,2.06],[2,2.08,49.61]],"ltp":2.2,"tv":3416.97,"id":10107355}]}]}
{"op":"mcm","clk":"993651674","pt":1580544946498,"mc":[{"id":"1.168133543","rc":[{"batb":[[1,2.14,20.86]],"batl":[[2,2.4,29.86]],"ltp":2.2,"tv":3416.97,"id":10107355}]}]}
{"op":"mcm","clk":"993652561","pt":1580544955563,"mc":[{"id":"1.168133543","rc":[{"batb":[[1,2.14,2.06]],"batl":[[2,2.42,5.5]],"ltp":2.2,"tv":3416.97,"id":10107355}]}]}
{"op":"mcm","clk":"993652645","pt":1580544956506,"mc":[{"id":"1.168133543","rc":[{"batb":[[1,260,1.26]],"ltp":450.0,"tv":26.52,"id":24270700}]}]}
{"op":"mcm","clk":"993652734","pt":1580544957482,"mc":[{"id":"1.168133543","rc":[{"batb":[[1,260,1.42]],"ltp":450.0,"tv":26.52,"id":24270700}]}]}
{"op":"mcm","clk":"993652849","pt":1580544958464,"mc":[{"id":"1.168133543","rc":[{"batl":[[0,2.34,110.27]],"ltp":2.2,"tv":3416.97,"id":10107355}]}]}
{"op":"mcm","clk":"993653787","pt":1580544967499,"mc":[{"id":"1.168133543","rc":[{"batb":[[0,3.6,4.78],[1,3.55,13],[2,3.5,10]],"ltp":3.35,"tv":2252.67,"id":12636}]}]}
{"op":"mcm","clk":"993653856","pt":1580544968304,"mc":[{"id":"1.168133543","rc":[{"batl":[[2,570,2.15]],"ltp":180.0,"tv":22.52,"id":22308007}]}]}
{"op":"mcm","clk":"993654148","pt":1580544971501,"mc":[{"id":"1.168133543","rc":[{"batl":[[0,2.34,108.27]],"ltp":2.2,"tv":3416.97,"id":10107355}]}]}
{"op":"mcm","clk":"993654231","pt":1580544972489,"mc":[{"id":"1.168133543","rc":[{"batl":[[0,2.36,2.04],[1,2.42,5.5],[2,2.44,6]],"ltp":2.2,"tv":3416.97,"id":10107355}]}]}
{"op":"mcm","clk":"993654302","pt":1580544973313,"mc":[{"id":"1.168133543","rc":[{"batb":[[1,2.08,49.61],[2,2.06,16.54]],"ltp":2.2,"tv":3416.97,"id":10107355}]}]}
{"op":"mcm","clk":"993654640","pt":1580544976488,"mc":[{"id":"1.168133543","rc":[{"batl":[[2,300,2]],"ltp":180.0,"tv":22.52,"id":22308007},{"batl":[[2,2.46,21]],"ltp":2.2,"tv":3416.97,"id":10107355},{"batb":[[1,260,1.26]],"ltp":450.0,"tv":26.52,"id":24270700}]}]}
{"op":"mcm","clk":"993654714","pt":1580544977414,"mc":[{"id":"1.168133543","rc":[{"batb":[[1,260,1.42]],"ltp":450.0,"tv":26.52,"id":24270700}]}]}
{"op":"mcm","clk":"993655568","pt":1580544984944,"mc":[{"id":"1.168133543","rc":[{"batl":[[0,2.36,2],[1,2.42,5.54]],"ltp":2.2,"tv":3416.97,"id":10107355}]}]}
{"op":"mcm","clk":"993656122","pt":1580544991538,"mc":[{"id":"1.168133543","rc":[{"trd":[[3.55,57.56],[3.6,54.56]],"batb":[[0,3.5,10],[1,3.45,4],[2,3.4,14.83]],"batl":[[0,3.55,1.22],[1,3.8,11.11],[2,4,10]],"ltp":3.55,"tv":2288.23,"id":12636},{"trd":[[2.2,185.9]],"batb":[[0,2.2,11.05]],"ltp":2.2,"tv":3478.97,"id":10107355}],"tv":7220.04}]}
{"op":"mcm","clk":"993656202","pt":1580544992418,"mc":[{"id":"1.168133543","rc":[{"trd":[[3.5,10.06],[3.55,60]],"batb":[[0,3.5,6.97]],"batl":[[0,3.8,3.61],[1,4,10],[2,5.5,6.67]],"ltp":3.5,"tv":2296.73,"id":12636}],"tv":7228.54}]}
{"op":"mcm","clk":"993656302","pt":1580544993309,"mc":[{"id":"1.168133543","rc":[{"batb":[[1,2.08,33.08]],"ltp":2.2,"tv":3478.97,"id":10107355}]}]}
{"op":"mcm","clk":"993656889","pt":1580544996553,"mc":[{"id":"1.168133543","rc":[{"batl":[[2,300,2.72]],"ltp":180.0,"tv":22.52,"id":22308007},{"batb":[[1,8.4,2.05],[2,8.2,3.9]],"ltp":9.2,"tv":601.81,"id":22121325}]}]}
{"op":"mcm","clk":"993656974","pt":1580544997334,"mc":[{"id":"1.168133543","rc":[{"batb":[[1,260,1.26]],"ltp":450.0,"tv":26.52,"id":24270700}]}]}
{"op":"mcm","clk":"993657105","pt":1580544998421,"mc":[{"id":"1.168133543","rc":[{"batb":[[1,260,1.42]],"ltp":450.0,"tv":26.52,"id":24270700}]}]}
{"op":"mcm","clk":"993657382","pt":1580545001418,"mc":[{"id":"1.168133543","rc":[{"batl":[[0,3.75,133.02],[1,3.8,3.61],[2,4,10]],"ltp":3.5,"tv":2296.73,"id":12636}]}]}
{"op":"mcm","clk":"993657470","pt":1580545002354,"mc":[{"id":"1.168133543","rc":[{"batl":[[0,3.7,8.77],[1,3.75,133.02],[2,3.8,3.61]],"ltp":3.5,"tv":2296.73,"id":12636}]}]}
{"op":"mcm","clk":"993657744","pt":1580545004944,"mc":[{"id":"1.168133543","rc":[{"batl":[[0,3.7,28.77]],"ltp":3.5,"tv":2296.73,"id":12636}]}]}
{"op":"mcm","clk":"993658224","pt":1580545007541,"mc":[{"id":"1.168133543","rc":[{"batl":[[2,300,2]],"ltp":180.0,"tv":22.52,"id":22308007}]}]}
{"op":"mcm","clk":"993658693","pt":1580545012558,"mc":[{"id":"1.168133543","rc":[{"trd":[[3.5,24]],"batb":[[0,3.45,6],[1,3.4,14.83],[2,3.35,1.98]],"batl":[[0,3.5,193.03],[1,3.7,28.77],[2,3.75,133.02]],"ltp":3.5,"tv":2310.67,"id":12636},{"batb":[[0,2.2,13.05]],"ltp":2.2,"tv":3478.97,"id":10107355}],"tv":7242.48}]}
{"op":"mcm","clk":"993658883","pt":1580545014431,"mc":[{"id":"1.168133543","rc":[{"batl":[[1,3.7,20]],"ltp":3.5,"tv":2310.67,"id":12636}]}]}
{"op":"mcm","clk":"993658965","pt":1580545015366,"mc":[{"id":"1.168133543","rc":[{"batb":[[1,2.08,49.61]],"batl":[[1,2.4,6.67],[2,2.42,5.5]],"ltp":2.2,"tv":3478.97,"id":10107355}]}]}
{"op":"mcm","clk":"993659071","pt":1580545016457,"mc":[{"id":"1.168133543","rc":[{"batl":[[2,3.8,3.61]],"ltp":3.5,"tv":2310.67,"id":12636}]}]}
{"op":"mcm","clk":"993660213","pt":1580545027255,"mc":[{"id":"1.168133543","rc":[{"batb":[[0,44,3.03]],"ltp":46.0,"tv":46.47,"id":7226819}]}]}
{"op":"mcm","clk":"993660497","pt":1580545030574,"mc":[{"id":"1.168133543","rc":[{"trd":[[3.45,37.18]],"batb":[[0,3.4,16.83],[1,3.35,1.98],[2,3.3,23.14]],"batl":[[0,3.45,4.5],[1,3.5,193.03],[2,3.7,20]],"ltp":3.45,"tv":2322.67,"id":12636},{"batl":[[2,300,2.78]],"ltp":180.0,"tv":22.52,"id":22308007},{"batb":[[0,44,14.19]],"ltp":46.0,"tv":46.47,"id":7226819},{"batb":[[0,85,2.27],[1,80,2.09],[2,75,16.91]],"ltp":100.0,"tv":23.71,"id":26548208},{"batb":[[2,170,3.24]],"ltp":590.0,"tv":20.43,"id":27606066}],"tv":7254.48}]}
{"op":"mcm","clk":"993660984","pt":1580545036574,"mc":[{"id":"1.168133543","rc":[{"batl":[[2,3.8,3.61]],"ltp":3.45,"tv":2322.67,"id":12636},{"batb":[[1,2.18,2],[2,2.08,49.61]],"ltp":2.2,"tv":3478.97,"id":10107355}]}]}
{"op":"mcm","clk":"993661043","pt":1580545037247,"mc":[{"id":"1.168133543","rc":[{"batb":[[0,2.2,11.05],[1,2.08,49.61],[2,2.06,16.54]],"ltp":2.2,"tv":3478.97,"id":10107355}]}]}
{"op":"mcm","clk":"993661147","pt":1580545038482,"mc":[{"id":"1.168133543","rc":[{"batb":[[1,2.08,33.08]],"ltp":2.2,"tv":3478.97,"id":10107355}]}]}
{"op":"mcm","clk":"993661340","pt":1580545040462,"mc":[{"id":"1.168133543","rc":[{"batb":[[1,260,1.26]],"ltp":450.0,"tv":26.52,"id":24270700}]}]}
{"op":"mcm","clk":"993661511","pt":1580545042485,"mc":[{"id":"1.168133543","rc":[{"batb":[[1,3.35,7.98]],"ltp":3.45,"tv":2322.67,"id":12636}]}]}
{"op":"mcm","clk":"993661614","pt":1580545043555,"mc":[{"id":"1.168133543","rc":[{"batl":[[2,420,2.93]],"ltp":180.0,"tv":22.52,"id":22308007}]}]}
{"op":"mcm","clk":"993661717","pt":1580545044795,"mc":[{"id":"1.168133543","rc":[{"batb":[[2,180,3.08]],"ltp":590.0,"tv":20.43,"id":27606066}]}]}
{"op":"mcm","clk":"993663071","pt":1580545058493,"mc":[{"id":"1.168133543","rc":[{"batl":[[2,670,2.93]],"ltp":180.0,"tv":22.52,"id":22308007},{"batb":[[2,160,13.5]],"ltp":590.0,"tv":20.43,"id":27606066}]}]}
{"op":"mcm","clk":"993663085","pt":1580545058597,"mc":[{"id":"1.168133543","rc":[{"batb":[[2,190,2.92]],"ltp":590.0,"tv":20.43,"id":27606066}]}]}
{"op":"mcm","clk":"993663395","pt":1580545061466,"mc":[{"id":"1.168133543","rc":[{"batb":[[1,260,1.42]],"ltp":450.0,"tv":26.52,"id":24270700}]}]}
{"op":"mcm","clk":"993664581","pt":1580545073413,"mc":[{"id":"1.168133543","rc":[{"batb":[[2,160,13.5]],"ltp":590.0,"tv":20.43,"id":27606066}]}]}
{"op":"mcm","clk":"993664616","pt":1580545073673,"mc":[{"id":"1.168133543","rc":[{"trd":[[2.2,189.9]],"batb":[[0,2.2,9.05]],"ltp":2.2,"tv":3482.97,"id":10107355}],"tv":7258.48}]}
{"op":"mcm","clk":"993664728","pt":1580545075022,"mc":[{"id":"1.168133543","rc":[{"trd":[[3.4,61.62]],"batb":[[0,3.35,7.98],[1,3.3,23.14],[2,3.1,5.84]],"batl":[[0,3.4,33.17],[1,3.45,4.5],[2,3.5,193.03]],"ltp":3.4,"tv":2356.32,"id":12636},{"batb":[[1,2.08,16.54],[2,2,36.46]],"ltp":2.2,"tv":3482.97,"id":10107355}],"tv":7292.14}]}
{"op":"mcm","clk":"993664856","pt":1580545076482,"mc":[{"id":"1.168133543","rc":[{"batb":[[1,3.3,20]],"ltp":3.4,"tv":2356.32,"id":12636}]}]}
{"op":"mcm","clk":"993665042","pt":1580545078191,"mc":[{"id":"1.168133543","rc":[{"batl":[[0,2.34,2],[1,2.36,2],[2,2.4,6.67]],"ltp":2.2,"tv":3482.97,"id":10107355}]}]}
{"op":"mcm","clk":"993665341","pt":1580545081417,"mc":[{"id":"1.168133543","rc":[{"batb":[[1,260,1.26]],"ltp":450.0,"tv":26.52,"id":24270700}]}]}
{"op":"mcm","clk":"993665450","pt":1580545082516,"mc":[{"id":"1.168133543","rc":[{"batb":[[1,260,1.42]],"ltp":450.0,"tv":26.52,"id":24270700}]}]}
{"op":"mcm","clk":"993666036","pt":1580545087510,"mc":[{"id":"1.168133543","rc":[{"batb":[[2,170,3.24]],"ltp":590.0,"tv":20.43,"id":27606066},{"batb":[[0,180,4.77]],"ltp":190.0,"tv":29.17,"id":13306150}]}]}
{"op":"mcm","clk":"993666140","pt":1580545088494,"mc":[{"id":"1.168133543","rc":[{"batl":[[2,920,2.93]],"ltp":180.0,"tv":22.52,"id":22308007}]}]}
{"op":"mcm","clk":"993666348","pt":1580545090419,"mc":[{"id":"1.168133543","rc":[{"batl":[[0,2.34,2.04],[2,2.4,6.63]],"ltp":2.2,"tv":3482.97,"id":10107355}]}]}
{"op":"mcm","clk":"993667302","pt":1580545101450,"mc":[{"id":"1.168133543","rc":[{"batb":[[1,260,1.26]],"ltp":450.0,"tv":26.52,"id":24270700}]}]}
