{"op":"mcm","clk":"993022665","pt":1580535166505,"mc":[{"id":"1.168133543","rc":[{"batb":[[0,230,1.32]],"ltp":280.0,"tv":1.54,"id":24270700}]}]}
{"op":"mcm","clk":"993022666","pt":1580535166607,"mc":[{"id":"1.168133543","rc":[{"batb":[[1,220,1.26],[2,170,4.13]],"ltp":280.0,"tv":1.54,"id":24270700}]}]}
{"op":"mcm","clk":"993023557","pt":1580535182740,"mc":[{"id":"1.168133543","rc":[{"batb":[[0,230,2.42],[1,180,1.03],[2,170,3.21]],"ltp":280.0,"tv":1.54,"id":24270700}]}]}
{"op":"mcm","clk":"993024422","pt":1580535199817,"mc":[{"id":"1.168133543","rc":[{"batb":[[0,230,1.32],[1,220,1.26],[2,170,4.13]],"ltp":280.0,"tv":1.54,"id":24270700}]}]}
{"op":"mcm","clk":"993025176","pt":1580535216464,"mc":[{"id":"1.168133543","rc":[{"batb":[[0,230,2.42],[1,180,1.03],[2,170,3.21]],"ltp":280.0,"tv":1.54,"id":24270700}]}]}
{"op":"mcm","clk":"993025779","pt":1580535231817,"mc":[{"id":"1.168133543","rc":[{"batb":[[0,230,1.32],[1,220,1.26],[2,170,4.13]],"ltp":280.0,"tv":1.54,"id":24270700}]}]}
{"op":"mcm","clk":"993026502","pt":1580535247705,"mc":[{"id":"1.168133543","rc":[{"batb":[[0,230,2.42],[1,180,1.03],[2,170,3.21]],"ltp":280.0,"tv":1.54,"id":24270700}]}]}
{"op":"mcm","clk":"993027240","pt":1580535263723,"mc":[{"id":"1.168133543","rc":[{"batb":[[0,230,1.32],[1,220,1.26],[2,170,4.13]],"ltp":280.0,"tv":1.54,"id":24270700}]}]}
{"op":"mcm","clk":"993027836","pt":1580535277758,"mc":[{"id":"1.168133543","rc":[{"batb":[[0,230,2.42],[1,180,1.03],[2,170,3.21]],"ltp":280.0,"tv":1.54,"id":24270700}]}]}
{"op":"mcm","clk":"993028524","pt":1580535292892,"mc":[{"id":"1.168133543","rc":[{"batb":[[0,230,1.32],[1,220,1.26],[2,170,4.13]],"ltp":280.0,"tv":1.54,"id":24270700}]}]}
{"op":"mcm","clk":"993029186","pt":1580535306517,"mc":[{"id":"1.168133543","rc":[{"batb":[[0,230,2.42],[1,180,1.03],[2,170,3.21]],"ltp":280.0,"tv":1.54,"id":24270700}]}]}
{"op":"mcm","clk":"993029826","pt":1580535320834,"mc":[{"id":"1.168133543","rc":[{"batb":[[0,230,1.32],[1,220,1.26],[2,170,4.13]],"ltp":280.0,"tv":1.54,"id":24270700}]}]}
{"op":"mcm","clk":"993030486","pt":1580535335691,"mc":[{"id":"1.168133543","rc":[{"batb":[[0,230,2.42],[1,180,1.03],[2,170,3.21]],"ltp":280.0,"tv":1.54,"id":24270700}]}]}
{"op":"mcm","clk":"993031019","pt":1580535349690,"mc":[{"id":"1.168133543","rc":[{"batb":[[0,230,1.32],[1,220,1.26],[2,170,4.13]],"ltp":280.0,"tv":1.54,"id":24270700}]}]}
{"op":"mcm","clk":"993031613","pt":1580535363519,"mc":[{"id":"1.168133543","rc":[{"batb":[[1,180,1.03],[2,170,3.21]],"ltp":280.0,"tv":1.54,"id":24270700}]}]}
{"op":"mcm","clk":"993031619","pt":1580535363620,"mc":[{"id":"1.168133543","rc":[{"batb":[[0,230,2.42]],"ltp":280.0,"tv":1.54,"id":24270700}]}]}
{"op":"mcm","clk":"993032189","pt":1580535378550,"mc":[{"id":"1.168133543","rc":[{"batb":[[0,230,1.32]],"ltp":280.0,"tv":1.54,"id":24270700}]}]}
{"op":"mcm","clk":"993032199","pt":1580535378655,"mc":[{"id":"1.168133543","rc":[{"batb":[[1,220,1.26],[2,170,4.13]],"ltp":280.0,"tv":1.54,"id":24270700}]}]}
{"op":"mcm","clk":"993032813","pt":1580535392774,"mc":[{"id":"1.168133543","rc":[{"batb":[[0,230,2.42],[1,180,1.03],[2,170,3.21]],"ltp":280.0,"tv":1.54,"id":24270700}]}]}
{"op":"mcm","clk":"993033339","pt":1580535406797,"mc":[{"id":"1.168133543","rc":[{"batb":[[0,230,1.32],[1,220,1.26],[2,170,4.13]],"ltp":280.0,"tv":1.54,"id":24270700}]}]}
{"op":"mcm","clk":"993033927","pt":1580535421739,"mc":[{"id":"1.168133543","rc":[{"batb":[[0,230,2.42],[1,180,1.03],[2,170,3.21]],"ltp":280.0,"tv":1.54,"id":24270700}]}]}
{"op":"mcm","clk":"993034532","pt":1580535435548,"mc":[{"id":"1.168133543","rc":[{"batb":[[0,230,1.32]],"ltp":280.0,"tv":1.54,"id":24270700}]}]}
{"op":"mcm","clk":"993034541","pt":1580535435652,"mc":[{"id":"1.168133543","rc":[{"batb":[[1,220,1.26],[2,170,4.13]],"ltp":280.0,"tv":1.54,"id":24270700}]}]}
{"op":"mcm","clk":"993035351","pt":1580535449544,"mc":[{"id":"1.168133543","rc":[{"batb":[[0,230,2.42],[1,180,1.03],[2,170,3.21]],"ltp":280.0,"tv":1.54,"id":24270700}]}]}
{"op":"mcm","clk":"993046182","pt":1580535464684,"mc":[{"id":"1.168133543","rc":[{"batb":[[0,230,1.32],[1,220,1.26],[2,170,4.13]],"ltp":280.0,"tv":1.54,"id":24270700}]}]}
{"op":"mcm","clk":"993046867","pt":1580535478514,"mc":[{"id":"1.168133543","rc":[{"batb":[[1,180,1.03],[2,170,3.21]],"ltp":280.0,"tv":1.54,"id":24270700}]}]}
{"op":"mcm","clk":"993046873","pt":1580535478620,"mc":[{"id":"1.168133543","rc":[{"batb":[[0,230,2.42]],"ltp":280.0,"tv":1.54,"id":24270700}]}]}
{"op":"mcm","clk":"993047400","pt":1580535492547,"mc":[{"id":"1.168133543","rc":[{"batb":[[0,230,1.32]],"ltp":280.0,"tv":1.54,"id":24270700}]}]}
{"op":"mcm","clk":"993047412","pt":1580535492753,"mc":[{"id":"1.168133543","rc":[{"batb":[[1,220,1.26],[2,170,4.13]],"ltp":280.0,"tv":1.54,"id":24270700}]}]}
{"op":"mcm","clk":"993048079","pt":1580535506560,"mc":[{"id":"1.168133543","rc":[{"batb":[[1,180,1.03],[2,170,3.21]],"ltp":280.0,"tv":1.54,"id":24270700}]}]}
{"op":"mcm","clk":"993048085","pt":1580535506664,"mc":[{"id":"1.168133543","rc":[{"batb":[[0,230,2.42]],"ltp":280.0,"tv":1.54,"id":24270700}]}]}
{"op":"mcm","clk":"993048746","pt":1580535521513,"mc":[{"id":"1.168133543","rc":[{"batb":[[0,230,1.32]],"ltp":280.0,"tv":1.54,"id":24270700}]}]}
{"op":"mcm","clk":"993048752","pt":1580535521617,"mc":[{"id":"1.168133543","rc":[{"batb":[[1,220,1.26],[2,170,4.13]],"ltp":280.0,"tv":1.54,"id":24270700}]}]}
{"op":"mcm","clk":"993049254","pt":1580535535506,"mc":[{"id":"1.168133543","rc":[{"batb":[[1,180,1.03],[2,170,3.21]],"ltp":280.0,"tv":1.54,"id":24270700}]}]}
{"op":"mcm","clk":"993049258","pt":1580535535610,"mc":[{"id":"1.168133543","rc":[{"batb":[[0,230,2.42]],"ltp":280.0,"tv":1.54,"id":24270700}]}]}
{"op":"mcm","clk":"993049763","pt":1580535549529,"mc":[{"id":"1.168133543","rc":[{"batb":[[0,230,1.32],[1,220,1.26],[2,170,4.13]],"ltp":280.0,"tv":1.54,"id":24270700}]}]}
{"op":"mcm","clk":"993050271","pt":1580535564479,"mc":[{"id":"1.168133543","rc":[{"batb":[[1,180,1.03],[2,170,3.21]],"ltp":280.0,"tv":1.54,"id":24270700}]}]}
{"op":"mcm","clk":"993050308","pt":1580535565250,"mc":[{"id":"1.168133543","rc":[{"batb":[[0,230,2.42]],"ltp":280.0,"tv":1.54,"id":24270700}]}]}
{"op":"mcm","clk":"993050910","pt":1580535578698,"mc":[{"id":"1.168133543","rc":[{"batb":[[0,230,1.32],[1,220,1.26],[2,170,4.13]],"ltp":280.0,"tv":1.54,"id":24270700}]}]}
{"op":"mcm","clk":"993051596","pt":1580535592486,"mc":[{"id":"1.168133543","rc":[{"batb":[[1,180,1.03],[2,170,3.21]],"ltp":280.0,"tv":1.54,"id":24270700}]}]}
{"op":"mcm","clk":"993051602","pt":1580535592590,"mc":[{"id":"1.168133543","rc":[{"batb":[[0,230,2.42]],"ltp":280.0,"tv":1.54,"id":24270700}]}]}
{"op":"mcm","clk":"993052340","pt":1580535607524,"mc":[{"id":"1.168133543","rc":[{"batb":[[0,230,1.32]],"ltp":280.0,"tv":1.54,"id":24270700}]}]}
{"op":"mcm","clk":"993052348","pt":1580535607626,"mc":[{"id":"1.168133543","rc":[{"batb":[[1,220,1.26],[2,170,4.13]],"ltp":280.0,"tv":1.54,"id":24270700}]}]}
{"op":"mcm","clk":"993053049","pt":1580535621541,"mc":[{"id":"1.168133543","rc":[{"batb":[[1,180,1.03],[2,170,3.21]],"ltp":280.0,"tv":1.54,"id":24270700}]}]}
{"op":"mcm","clk":"993053056","pt":1580535621645,"mc":[{"id":"1.168133543","rc":[{"batb":[[0,230,2.42]],"ltp":280.0,"tv":1.54,"id":24270700}]}]}
{"op":"mcm","clk":"993053690","pt":1580535635653,"mc":[{"id":"1.168133543","rc":[{"batb":[[0,230,1.32],[1,220,1.26],[2,170,4.13]],"ltp":280.0,"tv":1.54,"id":24270700}]}]}
{"op":"mcm","clk":"993054366","pt":1580535650712,"mc":[{"id":"1.168133543","rc":[{"batb":[[0,230,2.42],[1,180,1.03],[2,170,3.21]],"ltp":280.0,"tv":1.54,"id":24270700}]}]}
{"op":"mcm","clk":"993055016","pt":1580535664724,"mc":[{"id":"1.168133543","rc":[{"batb":[[0,230,1.32],[1,220,1.26],[2,170,4.13]],"ltp":280.0,"tv":1.54,"id":24270700}]}]}
{"op":"mcm","clk":"993055713","pt":1580535679122,"mc":[{"id":"1.168133543","rc":[{"batb":[[0,230,2.42],[1,180,1.03],[2,170,3.21]],"ltp":280.0,"tv":1.54,"id":24270700}]}]}
{"op":"mcm","clk":"993056453","pt":1580535693743,"mc":[{"id":"1.168133543","rc":[{"batb":[[0,230,1.32],[1,220,1.26],[2,170,4.13]],"ltp":280.0,"tv":1.54,"id":24270700}]}]}
{"op":"mcm","clk":"993057119","pt":1580535707680,"mc":[{"id":"1.168133543","rc":[{"batb":[[0,230,2.42],[1,180,1.03],[2,170,3.21]],"ltp":280.0,"tv":1.54,"id":24270700}]}]}
{"op":"mcm","clk":"993057796","pt":1580535721509,"mc":[{"id":"1.168133543","rc":[{"batb":[[0,230,1.32]],"ltp":280.0,"tv":1.54,"id":24270700}]}]}
{"op":"mcm","clk":"993057800","pt":1580535721612,"mc":[{"id":"1.168133543","rc":[{"batb":[[1,220,1.26],[2,170,4.13]],"ltp":280.0,"tv":1.54,"id":24270700}]}]}
{"op":"mcm","clk":"993058433","pt":1580535736537,"mc":[{"id":"1.168133543","rc":[{"batb":[[0,230,2.42],[1,180,1.03],[2,170,3.21]],"ltp":280.0,"tv":1.54,"id":24270700}]}]}
{"op":"mcm","clk":"993059040","pt":1580535750528,"mc":[{"id":"1.168133543","rc":[{"batb":[[0,230,1.32]],"ltp":280.0,"tv":1.54,"id":24270700}]}]}
{"op":"mcm","clk":"993059045","pt":1580535750629,"mc":[{"id":"1.168133543","rc":[{"batb":[[1,220,1.26],[2,170,4.13]],"ltp":280.0,"tv":1.54,"id":24270700}]}]}
{"op":"mcm","clk":"993059682","pt":1580535764558,"mc":[{"id":"1.168133543","rc":[{"batb":[[1,180,1.03],[2,170,3.21]],"ltp":280.0,"tv":1.54,"id":24270700}]}]}
{"op":"mcm","clk":"993059692","pt":1580535764765,"mc":[{"id":"1.168133543","rc":[{"batb":[[0,230,2.42]],"ltp":280.0,"tv":1.54,"id":24270700}]}]}
{"op":"mcm","clk":"993060270","pt":1580535779515,"mc":[{"id":"1.168133543","rc":[{"batb":[[0,230,1.32]],"ltp":280.0,"tv":1.54,"id":24270700}]}]}
{"op":"mcm","clk":"993060273","pt":1580535779616,"mc":[{"id":"1.168133543","rc":[{"batb":[[1,220,1.26],[2,170,4.13]],"ltp":280.0,"tv":1.54,"id":24270700}]}]}
{"op":"mcm","clk":"993060829","pt":1580535793509,"mc":[{"id":"1.168133543","rc":[{"batb":[[1,180,1.03],[2,170,3.21]],"ltp":280.0,"tv":1.54,"id":24270700}]}]}
{"op":"mcm","clk":"993060835","pt":1580535793613,"mc":[{"id":"1.168133543","rc":[{"batb":[[0,230,2.42]],"ltp":280.0,"tv":1.54,"id":24270700}]}]}
{"op":"mcm","clk":"993061405","pt":1580535807540,"mc":[{"id":"1.168133543","rc":[{"batb":[[0,230,1.32]],"ltp":280.0,"tv":1.54,"id":24270700}]}]}
{"op":"mcm","clk":"993061409","pt":1580535807642,"mc":[{"id":"1.168133543","rc":[{"batb":[[1,220,1.26],[2,170,4.13]],"ltp":280.0,"tv":1.54,"id":24270700}]}]}
{"op":"mcm","clk":"993062068","pt":1580535822474,"mc":[{"id":"1.168133543","rc":[{"batb":[[1,180,1.03],[2,170,3.21]],"ltp":280.0,"tv":1.54,"id":24270700}]}]}
{"op":"mcm","clk":"993062090","pt":1580535822938,"mc":[{"id":"1.168133543","rc":[{"batb":[[0,230,2.42]],"ltp":280.0,"tv":1.54,"id":24270700}]}]}
{"op":"mcm","clk":"993062865","pt":1580535836782,"mc":[{"id":"1.168133543","rc":[{"batb":[[0,230,1.32],[1,220,1.26],[2,170,4.13]],"ltp":280.0,"tv":1.54,"id":24270700}]}]}
{"op":"mcm","clk":"993063583","pt":1580535850789,"mc":[{"id":"1.168133543","rc":[{"batb":[[0,230,2.42],[1,180,1.03],[2,170,3.21]],"ltp":280.0,"tv":1.54,"id":24270700}]}]}
{"op":"mcm","clk":"993064345","pt":1580535865473,"mc":[{"id":"1.168133543","rc":[{"batb":[[0,230,1.32],[1,220,1.26],[2,170,4.13]],"ltp":280.0,"tv":1.54,"id":24270700}]}]}
{"op":"mcm","clk":"993065049","pt":1580535879524,"mc":[{"id":"1.168133543","rc":[{"batb":[[1,180,1.03],[2,170,3.21]],"ltp":280.0,"tv":1.54,"id":24270700}]}]}
{"op":"mcm","clk":"993065056","pt":1580535879629,"mc":[{"id":"1.168133543","rc":[{"batb":[[0,230,2.42]],"ltp":280.0,"tv":1.54,"id":24270700}]}]}
{"op":"mcm","clk":"993065678","pt":1580535893512,"mc":[{"id":"1.168133543","rc":[{"batb":[[0,230,1.32]],"ltp":280.0,"tv":1.54,"id":24270700}]}]}
{"op":"mcm","clk":"993065684","pt":1580535893614,"mc":[{"id":"1.168133543","rc":[{"batb":[[1,220,1.26],[2,170,4.13]],"ltp":280.0,"tv":1.54,"id":24270700}]}]}
{"op":"mcm","clk":"993066424","pt":1580535908527,"mc":[{"id":"1.168133543","rc":[{"batb":[[1,180,1.03],[2,170,3.21]],"ltp":280.0,"tv":1.54,"id":24270700}]}]}
{"op":"mcm","clk":"993066430","pt":1580535908632,"mc":[{"id":"1.168133543","rc":[{"batb":[[0,230,2.42]],"ltp":280.0,"tv":1.54,"id":24270700}]}]}
{"op":"mcm","clk":"993067081","pt":1580535922745,"mc":[{"id":"1.168133543","rc":[{"batb":[[0,230,1.32],[1,220,1.26],[2,170,4.13]],"ltp":280.0,"tv":1.54,"id":24270700}]}]}
{"op":"mcm","clk":"993067787","pt":1580535936683,"mc":[{"id":"1.168133543","rc":[{"batb":[[0,230,2.42],[1,180,1.03],[2,170,3.21]],"ltp":280.0,"tv":1.54,"id":24270700}]}]}
{"op":"mcm","clk":"993068080","pt":1580535941539,"mc":[{"id":"1.168133543","rc":[{"trd":[[65,2.4],[70,0.02],[80,2.22],[90,3.28],[95,1.48]],"batb":[[0,65,1.85],[1,60,1.33],[2,55,1.07]],"batl":[[2,1000,3.05]],"ltp":65.0,"tv":17.48,"id":22308007}],"tv":4314.51}]}
{"op":"mcm","clk":"993068088","pt":1580535941748,"mc":[{"id":"1.168133543","rc":[{"trd":[[65,5.6]],"batb":[[0,60,1.58],[1,55,1.07],[2,16,3.03]],"batl":[[2,1000,1.45]],"ltp":65.0,"tv":20.68,"id":22308007}],"tv":4317.71}]}
{"op":"mcm","clk":"993068180","pt":1580535943450,"mc":[{"id":"1.168133543","rc":[{"batb":[[0,60,2]],"ltp":65.0,"tv":20.68,"id":22308007}]}]}
{"op":"mcm","clk":"993068242","pt":1580535944481,"mc":[{"id":"1.168133543","rc":[{"batl":[[2,1000,1.46]],"ltp":65.0,"tv":20.68,"id":22308007}]}]}
{"op":"mcm","clk":"993068283","pt":1580535944943,"mc":[{"id":"1.168133543","rc":[{"batl":[[0,200,1.73],[2,1000,1.45]],"ltp":65.0,"tv":20.68,"id":22308007}]}]}
{"op":"mcm","clk":"993068637","pt":1580535951555,"mc":[{"id":"1.168133543","rc":[{"batb":[[0,230,1.32]],"ltp":280.0,"tv":1.54,"id":24270700}]}]}
{"op":"mcm","clk":"993068645","pt":1580535951658,"mc":[{"id":"1.168133543","rc":[{"batb":[[1,220,1.26],[2,170,4.13]],"ltp":280.0,"tv":1.54,"id":24270700}]}]}
{"op":"mcm","clk":"993069342","pt":1580535965498,"mc":[{"id":"1.168133543","rc":[{"batb":[[1,180,1.03],[2,170,3.21]],"ltp":280.0,"tv":1.54,"id":24270700}]}]}
{"op":"mcm","clk":"993069354","pt":1580535965605,"mc":[{"id":"1.168133543","rc":[{"batb":[[0,230,2.42]],"ltp":280.0,"tv":1.54,"id":24270700}]}]}
{"op":"mcm","clk":"993070125","pt":1580535979493,"mc":[{"id":"1.168133543","rc":[{"batb":[[0,230,1.32],[1,220,1.26],[2,170,4.13]],"ltp":280.0,"tv":1.54,"id":24270700}]}]}
{"op":"mcm","clk":"993071141","pt":1580535994701,"mc":[{"id":"1.168133543","rc":[{"batb":[[0,230,2.42],[1,180,1.03],[2,170,3.21]],"ltp":280.0,"tv":1.54,"id":24270700}]}]}
{"op":"mcm","clk":"993071817","pt":1580536008543,"mc":[{"id":"1.168133543","rc":[{"batb":[[0,230,1.32]],"ltp":280.0,"tv":1.54,"id":24270700}]}]}
{"op":"mcm","clk":"993071826","pt":1580536008645,"mc":[{"id":"1.168133543","rc":[{"batb":[[1,220,1.26],[2,170,4.13]],"ltp":280.0,"tv":1.54,"id":24270700}]}]}
{"op":"mcm","clk":"993072474","pt":1580536022735,"mc":[{"id":"1.168133543","rc":[{"batb":[[0,230,2.42],[1,180,1.03],[2,170,3.21]],"ltp":280.0,"tv":1.54,"id":24270700}]}]}
{"op":"mcm","clk":"993073150","pt":1580536037681,"mc":[{"id":"1.168133543","rc":[{"batb":[[0,230,1.32],[1,220,1.26],[2,170,4.13]],"ltp":280.0,"tv":1.54,"id":24270700}]}]}
{"op":"mcm","clk":"993073745","pt":1580536051497,"mc":[{"id":"1.168133543","rc":[{"batb":[[1,180,1.03],[2,170,3.21]],"ltp":280.0,"tv":1.54,"id":24270700}]}]}
{"op":"mcm","clk":"993073750","pt":1580536051596,"mc":[{"id":"1.168133543","rc":[{"batb":[[0,230,2.42]],"ltp":280.0,"tv":1.54,"id":24270700}]}]}
{"op":"mcm","clk":"993074354","pt":1580536065509,"mc":[{"id":"1.168133543","rc":[{"batb":[[0,230,1.32],[1,220,1.26],[2,170,4.13]],"ltp":280.0,"tv":1.54,"id":24270700}]}]}
{"op":"mcm","clk":"993074947","pt":1580536080514,"mc":[{"id":"1.168133543","rc":[{"batb":[[1,180,1.03],[2,170,3.21]],"ltp":280.0,"tv":1.54,"id":24270700}]}]}
{"op":"mcm","clk":"993074961","pt":1580536080826,"mc":[{"id":"1.168133543","rc":[{"batb":[[0,230,2.42]],"ltp":280.0,"tv":1.54,"id":24270700}]}]}
{"op":"mcm","clk":"993075472","pt":1580536094519,"mc":[{"id":"1.168133543","rc":[{"batb":[[0,230,1.32],[1,220,1.26],[2,170,4.13]],"ltp":280.0,"tv":1.54,"id":24270700}]}]}
{"op":"mcm","clk":"993076015","pt":1580536108535,"mc":[{"id":"1.168133543","rc":[{"batb":[[1,180,1.03],[2,170,3.21]],"ltp":280.0,"tv":1.54,"id":24270700}]}]}
{"op":"mcm","clk":"993076027","pt":1580536108842,"mc":[{"id":"1.168133543","rc":[{"batb":[[0,230,2.42]],"ltp":280.0,"tv":1.54,"id":24270700}]}]}
{"op":"mcm","clk":"993076563","pt":1580536123569,"mc":[{"id":"1.168133543","rc":[{"batb":[[0,230,1.32],[1,220,1.26],[2,170,4.13]],"ltp":280.0,"tv":1.54,"id":24270700}]}]}
{"op":"mcm","clk":"993077102","pt":1580536137472,"mc":[{"id":"1.168133543","rc":[{"batb":[[1,180,1.03],[2,170,3.21]],"ltp":280.0,"tv":1.54,"id":24270700}]}]}
{"op":"mcm","clk":"993077106","pt":1580536137579,"mc":[{"id":"1.168133543","rc":[{"batb":[[0,230,2.42]],"ltp":280.0,"tv":1.54,"id":24270700}]}]}
{"op":"mcm","clk":"993077283","pt":1580536142456,"mc":[{"id":"1.168133543","rc":[{"batl":[[0,2.38,2.01],[1,2.42,5.5],[2,2.46,21]],"ltp":2.38,"tv":2458.89,"id":10107355}]}]}
{"op":"mcm","clk":"993077625","pt":1580536151700,"mc":[{"id":"1.168133543","rc":[{"batb":[[0,230,1.32],[1,220,1.26],[2,170,4.13]],"ltp":280.0,"tv":1.54,"id":24270700}]}]}
{"op":"mcm","clk":"993078147","pt":1580536166494,"mc":[{"id":"1.168133543","rc":[{"batb":[[1,180,1.03],[2,170,3.21]],"ltp":280.0,"tv":1.54,"id":24270700}]}]}
{"op":"mcm","clk":"993078151","pt":1580536166597,"mc":[{"id":"1.168133543","rc":[{"batb":[[0,230,2.42]],"ltp":280.0,"tv":1.54,"id":24270700}]}]}
{"op":"mcm","clk":"993078645","pt":1580536180521,"mc":[{"id":"1.168133543","rc":[{"batb":[[0,230,1.32]],"ltp":280.0,"tv":1.54,"id":24270700}]}]}
{"op":"mcm","clk":"993078648","pt":1580536180578,"mc":[{"id":"1.168133543","rc":[{"batb":[[1,220,1.26],[2,170,4.13]],"ltp":280.0,"tv":1.54,"id":24270700}]}]}
{"op":"mcm","clk":"993079107","pt":1580536194525,"mc":[{"id":"1.168133543","rc":[{"batb":[[1,180,1.03],[2,170,3.21]],"ltp":280.0,"tv":1.54,"id":24270700}]}]}
{"op":"mcm","clk":"993079111","pt":1580536194629,"mc":[{"id":"1.168133543","rc":[{"batb":[[0,230,2.42]],"ltp":280.0,"tv":1.54,"id":24270700}]}]}
{"op":"mcm","clk":"993079777","pt":1580536209517,"mc":[{"id":"1.168133543","rc":[{"batb":[[0,230,1.32],[1,220,1.26],[2,170,4.13]],"ltp":280.0,"tv":1.54,"id":24270700}]}]}
{"op":"mcm","clk":"993080369","pt":1580536223511,"mc":[{"id":"1.168133543","rc":[{"batb":[[1,180,1.03],[2,170,3.21]],"ltp":280.0,"tv":1.54,"id":24270700}]}]}
{"op":"mcm","clk":"993080372","pt":1580536223614,"mc":[{"id":"1.168133543","rc":[{"batb":[[0,230,2.42]],"ltp":280.0,"tv":1.54,"id":24270700}]}]}
{"op":"mcm","clk":"993080846","pt":1580536237535,"mc":[{"id":"1.168133543","rc":[{"batb":[[0,230,1.32],[1,220,1.26],[2,170,4.13]],"ltp":280.0,"tv":1.54,"id":24270700}]}]}
{"op":"mcm","clk":"993081309","pt":1580536252558,"mc":[{"id":"1.168133543","rc":[{"batb":[[1,180,1.03],[2,170,3.21]],"ltp":280.0,"tv":1.54,"id":24270700}]}]}
{"op":"mcm","clk":"993081314","pt":1580536252656,"mc":[{"id":"1.168133543","rc":[{"batb":[[0,230,2.42]],"ltp":280.0,"tv":1.54,"id":24270700}]}]}
{"op":"mcm","clk":"993081802","pt":1580536266545,"mc":[{"id":"1.168133543","rc":[{"batb":[[0,230,1.32],[1,220,1.26],[2,170,4.13]],"ltp":280.0,"tv":1.54,"id":24270700}]}]}
{"op":"mcm","clk":"993082421","pt":1580536280569,"mc":[{"id":"1.168133543","rc":[{"batb":[[0,230,2.42],[1,180,1.03],[2,170,3.21]],"ltp":280.0,"tv":1.54,"id":24270700}]}]}
{"op":"mcm","clk":"993083122","pt":1580536295517,"mc":[{"id":"1.168133543","rc":[{"batb":[[0,230,1.32]],"ltp":280.0,"tv":1.54,"id":24270700}]}]}
{"op":"mcm","clk":"993083129","pt":1580536295618,"mc":[{"id":"1.168133543","rc":[{"batb":[[1,220,1.26],[2,170,4.13]],"ltp":280.0,"tv":1.54,"id":24270700}]}]}
{"op":"mcm","clk":"993083645","pt":1580536309494,"mc":[{"id":"1.168133543","rc":[{"batb":[[1,180,1.03],[2,170,3.21]],"ltp":280.0,"tv":1.54,"id":24270700}]}]}
{"op":"mcm","clk":"993083648","pt":1580536309598,"mc":[{"id":"1.168133543","rc":[{"batb":[[0,230,2.42]],"ltp":280.0,"tv":1.54,"id":24270700}]}]}
{"op":"mcm","clk":"993084171","pt":1580536323507,"mc":[{"id":"1.168133543","rc":[{"batb":[[0,230,1.32],[1,220,1.26],[2,170,4.13]],"ltp":280.0,"tv":1.54,"id":24270700}]}]}
{"op":"mcm","clk":"993084620","pt":1580536337545,"mc":[{"id":"1.168133543","rc":[{"batb":[[0,230,2.42],[1,180,1.03],[2,170,3.21]],"ltp":280.0,"tv":1.54,"id":24270700}]}]}
{"op":"mcm","clk":"993095019","pt":1580536352527,"mc":[{"id":"1.168133543","rc":[{"batb":[[0,230,1.32],[1,220,1.26],[2,170,4.13]],"ltp":280.0,"tv":1.54,"id":24270700}]}]}
{"op":"mcm","clk":"993095528","pt":1580536366551,"mc":[{"id":"1.168133543","rc":[{"batb":[[0,230,2.42],[1,180,1.03],[2,170,3.21]],"ltp":280.0,"tv":1.54,"id":24270700}]}]}
{"op":"mcm","clk":"993096072","pt":1580536380479,"mc":[{"id":"1.168133543","rc":[{"batb":[[0,230,1.32],[1,220,1.26],[2,170,4.13]],"ltp":280.0,"tv":1.54,"id":24270700}]}]}
{"op":"mcm","clk":"993096538","pt":1580536395479,"mc":[{"id":"1.168133543","rc":[{"batb":[[1,180,1.03],[2,170,3.21]],"ltp":280.0,"tv":1.54,"id":24270700}]}]}
{"op":"mcm","clk":"993096545","pt":1580536395684,"mc":[{"id":"1.168133543","rc":[{"batb":[[0,230,2.42]],"ltp":280.0,"tv":1.54,"id":24270700}]}]}
{"op":"mcm","clk":"993097210","pt":1580536409526,"mc":[{"id":"1.168133543","rc":[{"batb":[[0,230,1.32]],"ltp":280.0,"tv":1.54,"id":24270700}]}]}
{"op":"mcm","clk":"993097216","pt":1580536409625,"mc":[{"id":"1.168133543","rc":[{"batb":[[1,220,1.26],[2,170,4.13]],"ltp":280.0,"tv":1.54,"id":24270700}]}]}
{"op":"mcm","clk":"993097784","pt":1580536423559,"mc":[{"id":"1.168133543","rc":[{"batb":[[0,230,2.42],[1,180,1.03],[2,170,3.21]],"ltp":280.0,"tv":1.54,"id":24270700}]}]}
{"op":"mcm","clk":"993098523","pt":1580536443557,"mc":[{"id":"1.168133543","rc":[{"batb":[[0,230,1.32],[1,220,1.26],[2,170,4.13]],"ltp":280.0,"tv":1.54,"id":24270700}]}]}
{"op":"mcm","clk":"993099390","pt":1580536457536,"mc":[{"id":"1.168133543","rc":[{"batb":[[0,230,2.42],[1,180,1.03],[2,170,3.21]],"ltp":280.0,"tv":1.54,"id":24270700}]}]}
{"op":"mcm","clk":"993099993","pt":1580536471556,"mc":[{"id":"1.168133543","rc":[{"batb":[[0,230,1.32],[1,220,1.26],[2,170,4.13]],"ltp":280.0,"tv":1.54,"id":24270700}]}]}
{"op":"mcm","clk":"993100601","pt":1580536486485,"mc":[{"id":"1.168133543","rc":[{"batb":[[1,180,1.03],[2,170,3.21]],"ltp":280.0,"tv":1.54,"id":24270700}]}]}
{"op":"mcm","clk":"993100607","pt":1580536486590,"mc":[{"id":"1.168133543","rc":[{"batb":[[0,230,2.42]],"ltp":280.0,"tv":1.54,"id":24270700}]}]}
{"op":"mcm","clk":"993101190","pt":1580536500468,"mc":[{"id":"1.168133543","rc":[{"batb":[[0,230,1.32]],"ltp":280.0,"tv":1.54,"id":24270700}]}]}
{"op":"mcm","clk":"993101196","pt":1580536500621,"mc":[{"id":"1.168133543","rc":[{"batb":[[1,220,1.26],[2,170,4.13]],"ltp":280.0,"tv":1.54,"id":24270700}]}]}
{"op":"mcm","clk":"993101843","pt":1580536514517,"mc":[{"id":"1.168133543","rc":[{"batb":[[1,180,1.03],[2,170,3.21]],"ltp":280.0,"tv":1.54,"id":24270700}]}]}
{"op":"mcm","clk":"993101855","pt":1580536514721,"mc":[{"id":"1.168133543","rc":[{"batb":[[0,230,2.42]],"ltp":280.0,"tv":1.54,"id":24270700}]}]}
{"op":"mcm","clk":"993102586","pt":1580536529496,"mc":[{"id":"1.168133543","rc":[{"batb":[[0,230,1.32]],"ltp":280.0,"tv":1.54,"id":24270700}]}]}
{"op":"mcm","clk":"993102593","pt":1580536529598,"mc":[{"id":"1.168133543","rc":[{"batb":[[1,220,1.26],[2,170,4.13]],"ltp":280.0,"tv":1.54,"id":24270700}]}]}
{"op":"mcm","clk":"993103320","pt":1580536543550,"mc":[{"id":"1.168133543","rc":[{"batb":[[0,230,2.42],[1,180,1.03],[2,170,3.21]],"ltp":280.0,"tv":1.54,"id":24270700}]}]}
{"op":"mcm","clk":"993103935","pt":1580536557564,"mc":[{"id":"1.168133543","rc":[{"batb":[[0,230,1.32],[1,220,1.26],[2,170,4.13]],"ltp":280.0,"tv":1.54,"id":24270700}]}]}
{"op":"mcm","clk":"993104632","pt":1580536572574,"mc":[{"id":"1.168133543","rc":[{"batb":[[0,230,2.42],[1,180,1.03],[2,170,3.21]],"ltp":280.0,"tv":1.54,"id":24270700}]}]}
{"op":"mcm","clk":"993105234","pt":1580536587487,"mc":[{"id":"1.168133543","rc":[{"batb":[[0,230,1.32],[1,220,1.26],[2,170,4.13]],"ltp":280.0,"tv":1.54,"id":24270700}]}]}
{"op":"mcm","clk":"993105685","pt":1580536600522,"mc":[{"id":"1.168133543","rc":[{"batb":[[1,180,1.03],[2,170,3.21]],"ltp":280.0,"tv":1.54,"id":24270700}]}]}
{"op":"mcm","clk":"993105693","pt":1580536600625,"mc":[{"id":"1.168133543","rc":[{"batb":[[0,230,2.42]],"ltp":280.0,"tv":1.54,"id":24270700}]}]}
{"op":"mcm","clk":"993106420","pt":1580536619544,"mc":[{"id":"1.168133543","rc":[{"batb":[[0,230,1.32]],"ltp":280.0,"tv":1.54,"id":24270700}]}]}
{"op":"mcm","clk":"993106480","pt":1580536620528,"mc":[{"id":"1.168133543","rc":[{"batb":[[1,220,1.26],[2,170,4.13]],"ltp":280.0,"tv":1.54,"id":24270700}]}]}
{"op":"mcm","clk":"993107061","pt":1580536634517,"mc":[{"id":"1.168133543","rc":[{"batb":[[0,230,2.42],[1,180,1.03],[2,170,3.21]],"ltp":280.0,"tv":1.54,"id":24270700}]}]}
{"op":"mcm","clk":"993108451","pt":1580536648563,"mc":[{"id":"1.168133543","rc":[{"batb":[[0,230,1.32]],"ltp":280.0,"tv":1.54,"id":24270700}]}]}
{"op":"mcm","clk":"993108477","pt":1580536648677,"mc":[{"id":"1.168133543","rc":[{"batb":[[1,220,1.26],[2,170,4.13]],"ltp":280.0,"tv":1.54,"id":24270700}]}]}
{"op":"mcm","clk":"993109974","pt":1580536662480,"mc":[{"id":"1.168133543","rc":[{"batb":[[1,180,1.03],[2,170,3.21]],"ltp":280.0,"tv":1.54,"id":24270700}]}]}
{"op":"mcm","clk":"993109980","pt":1580536662635,"mc":[{"id":"1.168133543","rc":[{"batb":[[0,230,2.42]],"ltp":280.0,"tv":1.54,"id":24270700}]}]}
{"op":"mcm","clk":"993110457","pt":1580536672237,"mc":[{"id":"1.168133543","rc":[{"trd":[[9.4,29.47]],"batb":[[0,9.2,5.64]],"ltp":9.4,"tv":357.31,"id":10163711}],"tv":4325.71}]}
{"op":"mcm","clk":"993110666","pt":1580536677502,"mc":[{"id":"1.168133543","rc":[{"batb":[[0,230,1.32],[1,220,1.26],[2,170,4.13]],"ltp":280.0,"tv":1.54,"id":24270700}]}]}
{"op":"mcm","clk":"993111179","pt":1580536691514,"mc":[{"id":"1.168133543","rc":[{"batb":[[1,180,1.03],[2,170,3.21]],"ltp":280.0,"tv":1.54,"id":24270700}]}]}
{"op":"mcm","clk":"993111192","pt":1580536691818,"mc":[{"id":"1.168133543","rc":[{"batb":[[0,230,2.42]],"ltp":280.0,"tv":1.54,"id":24270700}]}]}
{"op":"mcm","clk":"993111746","pt":1580536705532,"mc":[{"id":"1.168133543","rc":[{"batb":[[0,230,1.32]],"ltp":280.0,"tv":1.54,"id":24270700}]}]}
{"op":"mcm","clk":"993111749","pt":1580536705633,"mc":[{"id":"1.168133543","rc":[{"batb":[[1,220,1.26],[2,170,4.13]],"ltp":280.0,"tv":1.54,"id":24270700}]}]}
{"op":"mcm","clk":"993112289","pt":1580536720537,"mc":[{"id":"1.168133543","rc":[{"batb":[[1,180,1.03],[2,170,3.21]],"ltp":280.0,"tv":1.54,"id":24270700}]}]}
{"op":"mcm","clk":"993112296","pt":1580536720742,"mc":[{"id":"1.168133543","rc":[{"batb":[[0,230,2.42]],"ltp":280.0,"tv":1.54,"id":24270700}]}]}
{"op":"mcm","clk":"993112713","pt":1580536734492,"mc":[{"id":"1.168133543","rc":[{"batb":[[0,230,1.32]],"ltp":280.0,"tv":1.54,"id":24270700}]}]}
{"op":"mcm","clk":"993112717","pt":1580536734594,"mc":[{"id":"1.168133543","rc":[{"batb":[[1,220,1.26],[2,170,4.13]],"ltp":280.0,"tv":1.54,"id":24270700}]}]}
{"op":"mcm","clk":"993113210","pt":1580536748565,"mc":[{"id":"1.168133543","rc":[{"batb":[[0,230,2.42],[1,180,1.03],[2,170,3.21]],"ltp":280.0,"tv":1.54,"id":24270700}]}]}
{"op":"mcm","clk":"993113756","pt":1580536763523,"mc":[{"id":"1.168133543","rc":[{"batb":[[0,230,1.32]],"ltp":280.0,"tv":1.54,"id":24270700}]}]}
{"op":"mcm","clk":"993113761","pt":1580536763620,"mc":[{"id":"1.168133543","rc":[{"batb":[[1,220,1.26],[2,170,4.13]],"ltp":280.0,"tv":1.54,"id":24270700}]}]}
{"op":"mcm","clk":"993114284","pt":1580536777521,"mc":[{"id":"1.168133543","rc":[{"batb":[[1,180,1.03],[2,170,3.21]],"ltp":280.0,"tv":1.54,"id":24270700}]}]}
{"op":"mcm","clk":"993114286","pt":1580536777623,"mc":[{"id":"1.168133543","rc":[{"batb":[[0,230,2.42]],"ltp":280.0,"tv":1.54,"id":24270700}]}]}
{"op":"mcm","clk":"993114789","pt":1580536791821,"mc":[{"id":"1.168133543","rc":[{"batb":[[0,230,1.32],[1,220,1.26],[2,170,4.13]],"ltp":280.0,"tv":1.54,"id":24270700}]}]}
{"op":"mcm","clk":"993115429","pt":1580536806528,"mc":[{"id":"1.168133543","rc":[{"batb":[[1,180,1.03],[2,170,3.21]],"ltp":280.0,"tv":1.54,"id":24270700}]}]}
{"op":"mcm","clk":"993115434","pt":1580536806708,"mc":[{"id":"1.168133543","rc":[{"batb":[[0,230,2.42]],"ltp":280.0,"tv":1.54,"id":24270700}]}]}
{"op":"mcm","clk":"993116107","pt":1580536820475,"mc":[{"id":"1.168133543","rc":[{"batb":[[0,230,1.32],[1,220,1.26],[2,170,4.13]],"ltp":280.0,"tv":1.54,"id":24270700}]}]}
{"op":"mcm","clk":"993116726","pt":1580536834678,"mc":[{"id":"1.168133543","rc":[{"batb":[[0,230,2.42],[1,180,1.03],[2,170,3.21]],"ltp":280.0,"tv":1.54,"id":24270700}]}]}
{"op":"mcm","clk":"993117323","pt":1580536849706,"mc":[{"id":"1.168133543","rc":[{"batb":[[0,230,1.32],[1,220,1.26],[2,170,4.13]],"ltp":280.0,"tv":1.54,"id":24270700}]}]}
{"op":"mcm","clk":"993117409","pt":1580536852026,"mc":[{"id":"1.168133543","rc":[{"batb":[[2,2.82,4]],"ltp":2.88,"tv":1073.56,"id":12636}]}]}
{"op":"mcm","clk":"993117644","pt":1580536857329,"mc":[{"id":"1.168133543","rc":[{"batl":[[0,2.9,5]],"ltp":2.88,"tv":1073.56,"id":12636}]}]}
{"op":"mcm","clk":"993117941","pt":1580536863532,"mc":[{"id":"1.168133543","rc":[{"batb":[[1,180,1.03],[2,170,3.21]],"ltp":280.0,"tv":1.54,"id":24270700}]}]}
{"op":"mcm","clk":"993118005","pt":1580536864512,"mc":[{"id":"1.168133543","rc":[{"batb":[[0,230,2.42]],"ltp":280.0,"tv":1.54,"id":24270700}]}]}
{"op":"mcm","clk":"993118133","pt":1580536868221,"mc":[{"id":"1.168133543","rc":[{"batb":[[1,2.84,5.44],[2,2.8,2.2]],"ltp":2.88,"tv":1073.56,"id":12636},{"batl":[[1,2.4,2],[2,2.42,5.5]],"ltp":2.38,"tv":2458.89,"id":10107355}]}]}
{"op":"mcm","clk":"993118620","pt":1580536877558,"mc":[{"id":"1.168133543","rc":[{"batb":[[0,230,1.32]],"ltp":280.0,"tv":1.54,"id":24270700}]}]}
{"op":"mcm","clk":"993118624","pt":1580536877658,"mc":[{"id":"1.168133543","rc":[{"batb":[[1,220,1.26],[2,170,4.13]],"ltp":280.0,"tv":1.54,"id":24270700}]}]}
{"op":"mcm","clk":"993119088","pt":1580536889243,"mc":[{"id":"1.168133543","rc":[{"trd":[[2.36,246.3]],"ltp":2.36,"tv":2462.89,"id":10107355}],"tv":4329.71}]}
{"op":"mcm","clk":"993119217","pt":1580536892542,"mc":[{"id":"1.168133543","rc":[{"batl":[[1,11,2],[2,11.5,3.08]],"ltp":8.4,"tv":339.13,"id":22121325},{"batb":[[1,180,1.03],[2,170,3.21]],"ltp":280.0,"tv":1.54,"id":24270700}]}]}
{"op":"mcm","clk":"993119282","pt":1580536893477,"mc":[{"id":"1.168133543","rc":[{"batb":[[0,8.4,4.08],[1,7.4,3]],"ltp":8.4,"tv":339.13,"id":22121325},{"batb":[[0,230,2.42]],"ltp":280.0,"tv":1.54,"id":24270700}]}]}
{"op":"mcm","clk":"993119790","pt":1580536900476,"mc":[{"id":"1.168133543","rc":[{"batb":[[1,2.32,2],[2,2.28,20.92]],"ltp":2.36,"tv":2462.89,"id":10107355}]}]}
{"op":"mcm","clk":"993120009","pt":1580536905452,"mc":[{"id":"1.168133543","rc":[{"batb":[[2,2.28,12.15]],"ltp":2.36,"tv":2462.89,"id":10107355}]}]}
{"op":"mcm","clk":"993120059","pt":1580536906478,"mc":[{"id":"1.168133543","rc":[{"batb":[[0,230,1.32]],"ltp":280.0,"tv":1.54,"id":24270700}]}]}
{"op":"mcm","clk":"993120064","pt":1580536906580,"mc":[{"id":"1.168133543","rc":[{"batb":[[1,220,1.26],[2,170,4.13]],"ltp":280.0,"tv":1.54,"id":24270700}]}]}
{"op":"mcm","clk":"993120128","pt":1580536908170,"mc":[{"id":"1.168133543","rc":[{"batl":[[0,2.38,4.01],[1,2.42,5.5],[2,2.46,21]],"ltp":2.36,"tv":2462.89,"id":10107355}]}]}
{"op":"mcm","clk":"993120489","pt":1580536916278,"mc":[{"id":"1.168133543","rc":[{"batl":[[0,2.38,2.01],[1,2.4,2],[2,2.42,5.5]],"ltp":2.36,"tv":2462.89,"id":10107355}]}]}
{"op":"mcm","clk":"993120668","pt":1580536920489,"mc":[{"id":"1.168133543","rc":[{"batb":[[1,180,1.03],[2,170,3.21]],"ltp":280.0,"tv":1.54,"id":24270700}]}]}
{"op":"mcm","clk":"993120671","pt":1580536920592,"mc":[{"id":"1.168133543","rc":[{"batb":[[0,230,2.42]],"ltp":280.0,"tv":1.54,"id":24270700}]}]}
{"op":"mcm","clk":"993120787","pt":1580536923267,"mc":[{"id":"1.168133543","rc":[{"batl":[[0,2.38,4.01],[1,2.42,5.5],[2,2.46,21]],"ltp":2.36,"tv":2462.89,"id":10107355}]}]}
{"op":"mcm","clk":"993120825","pt":1580536924191,"mc":[{"id":"1.168133543","rc":[{"batb":[[1,2.86,4],[2,2.84,1.44]],"ltp":2.88,"tv":1073.56,"id":12636}]}]}
{"op":"mcm","clk":"993121307","pt":1580536932475,"mc":[{"id":"1.168133543","rc":[{"batb":[[1,80,17.88]],"ltp":160.0,"tv":7.22,"id":26548208}]}]}
{"op":"mcm","clk":"993121403","pt":1580536934475,"mc":[{"id":"1.168133543","rc":[{"batb":[[0,230,1.32]],"ltp":280.0,"tv":1.54,"id":24270700}]}]}
{"op":"mcm","clk":"993121445","pt":1580536935394,"mc":[{"id":"1.168133543","rc":[{"batb":[[0,2.88,75.01]],"ltp":2.88,"tv":1073.56,"id":12636},{"batb":[[1,220,1.26],[2,170,4.13]],"ltp":280.0,"tv":1.54,"id":24270700}]}]}
{"op":"mcm","clk":"993121718","pt":1580536942515,"mc":[{"id":"1.168133543","rc":[{"batb":[[0,85,2.62]],"ltp":160.0,"tv":7.22,"id":26548208}]}]}
{"op":"mcm","clk":"993121997","pt":1580536949484,"mc":[{"id":"1.168133543","rc":[{"batb":[[0,2.88,5.55]],"ltp":2.88,"tv":1073.56,"id":12636},{"batb":[[1,180,1.03],[2,170,3.21]],"ltp":280.0,"tv":1.54,"id":24270700}]}]}
{"op":"mcm","clk":"993122030","pt":1580536950407,"mc":[{"id":"1.168133543","rc":[{"batb":[[0,9.4,2.77],[1,9.2,5.64],[2,8.8,2.37]],"ltp":9.4,"tv":357.31,"id":10163711},{"batb":[[0,230,2.42]],"ltp":280.0,"tv":1.54,"id":24270700}]}]}
{"op":"mcm","clk":"993122614","pt":1580536963524,"mc":[{"id":"1.168133543","rc":[{"batb":[[0,9.2,5.64],[1,8.8,2.37],[2,8.6,7.91]],"ltp":9.4,"tv":357.31,"id":10163711},{"batb":[[0,230,1.32]],"ltp":280.0,"tv":1.54,"id":24270700}]}]}
{"op":"mcm","clk":"993122655","pt":1580536964550,"mc":[{"id":"1.168133543","rc":[{"batb":[[0,2.88,75.01]],"ltp":2.88,"tv":1073.56,"id":12636},{"batb":[[1,220,1.26],[2,170,4.13]],"ltp":280.0,"tv":1.54,"id":24270700}]}]}
{"op":"mcm","clk":"993123104","pt":1580536977542,"mc":[{"id":"1.168133543","rc":[{"batb":[[0,2.88,5.55]],"ltp":2.88,"tv":1073.56,"id":12636},{"batb":[[0,9.4,2.77],[1,9.2,5.64],[2,8.8,2.37]],"ltp":9.4,"tv":357.31,"id":10163711},{"batb":[[1,180,1.03],[2,170,3.21]],"ltp":280.0,"tv":1.54,"id":24270700}]}]}
{"op":"mcm","clk":"993123118","pt":1580536977852,"mc":[{"id":"1.168133543","rc":[{"batb":[[0,230,2.42]],"ltp":280.0,"tv":1.54,"id":24270700}]}]}
{"op":"mcm","clk":"993123168","pt":1580536979335,"mc":[{"id":"1.168133543","rc":[{"batb":[[0,2.88,9.55],[1,2.84,1.44],[2,2.8,2.2]],"ltp":2.88,"tv":1073.56,"id":12636},{"batl":[[0,2.38,2.01],[1,2.4,2],[2,2.42,5.5]],"ltp":2.36,"tv":2462.89,"id":10107355}]}]}
{"op":"mcm","clk":"993123297","pt":1580536982417,"mc":[{"id":"1.168133543","rc":[{"trd":[[2.9,145.72]],"batb":[[1,2.8,2.2],[2,2.76,2.13]],"batl":[[0,2.9,3.6]],"ltp":2.9,"tv":1076.36,"id":12636},{"batb":[[2,16,3.37]],"ltp":65.0,"tv":20.68,"id":22308007},{"batb":[[0,85,3.08],[2,70,1.1]],"ltp":160.0,"tv":7.22,"id":26548208},{"batb":[[2,100,1.55]],"ltp":160.0,"tv":19.01,"id":13306150}],"tv":4332.51}]}
{"op":"mcm","clk":"993123337","pt":1580536983443,"mc":[{"id":"1.168133543","rc":[{"batb":[[2,16.5,1.39]],"ltp":65.0,"tv":20.68,"id":22308007}]}]}
{"op":"mcm","clk":"993123346","pt":1580536983749,"mc":[{"id":"1.168133543","rc":[{"batb":[[2,16.5,1.69]],"ltp":65.0,"tv":20.68,"id":22308007}]}]}
{"op":"mcm","clk":"993123459","pt":1580536987351,"mc":[{"id":"1.168133543","rc":[{"batl":[[0,2.38,4.01],[1,2.42,5.5],[2,2.46,21]],"ltp":2.36,"tv":2462.89,"id":10107355}]}]}
{"op":"mcm","clk":"993123633","pt":1580536992535,"mc":[{"id":"1.168133543","rc":[{"batb":[[0,9.2,5.64],[1,8.8,2.37],[2,8.6,7.91]],"ltp":9.4,"tv":357.31,"id":10163711},{"batb":[[0,230,1.32]],"ltp":280.0,"tv":1.54,"id":24270700}]}]}
{"op":"mcm","clk":"993123647","pt":1580536993149,"mc":[{"id":"1.168133543","rc":[{"batb":[[1,220,1.26],[2,170,4.13]],"ltp":280.0,"tv":1.54,"id":24270700}]}]}
{"op":"mcm","clk":"993124180","pt":1580537006474,"mc":[{"id":"1.168133543","rc":[{"batb":[[0,230,2.42],[1,180,1.03],[2,170,3.21]],"ltp":280.0,"tv":1.54,"id":24270700}]}]}
{"op":"mcm","clk":"993124738","pt":1580537018797,"mc":[{"id":"1.168133543","rc":[{"batl":[[0,2.38,2.01],[1,2.4,2],[2,2.42,5.5]],"ltp":2.36,"tv":2462.89,"id":10107355}]}]}
{"op":"mcm","clk":"993124800","pt":1580537020489,"mc":[{"id":"1.168133543","rc":[{"batb":[[0,230,1.32]],"ltp":280.0,"tv":1.54,"id":24270700}]}]}
{"op":"mcm","clk":"993124804","pt":1580537020590,"mc":[{"id":"1.168133543","rc":[{"batb":[[1,220,1.26],[2,170,4.13]],"ltp":280.0,"tv":1.54,"id":24270700}]}]}
{"op":"mcm","clk":"993125012","pt":1580537026985,"mc":[{"id":"1.168133543","rc":[{"batl":[[0,2.38,4.01],[1,2.42,5.5],[2,2.46,21]],"ltp":2.36,"tv":2462.89,"id":10107355}]}]}
{"op":"mcm","clk":"993125294","pt":1580537034420,"mc":[{"id":"1.168133543","rc":[{"batb":[[0,50,18.18]],"ltp":60.0,"tv":30.43,"id":7226819},{"batl":[[0,2.38,2.01],[1,2.4,2],[2,2.42,5.5]],"ltp":2.36,"tv":2462.89,"id":10107355}]}]}
{"op":"mcm","clk":"993125328","pt":1580537035498,"mc":[{"id":"1.168133543","rc":[{"batb":[[0,50,15.21]],"ltp":60.0,"tv":30.43,"id":7226819},{"batb":[[1,180,1.03],[2,170,3.21]],"ltp":280.0,"tv":1.54,"id":24270700}]}]}
{"op":"mcm","clk":"993125361","pt":1580537036420,"mc":[{"id":"1.168133543","rc":[{"batb":[[0,55,3.11],[1,50,14.8],[2,48,3.08]],"ltp":60.0,"tv":30.43,"id":7226819},{"batb":[[0,230,2.42]],"ltp":280.0,"tv":1.54,"id":24270700}]}]}
{"op":"mcm","clk":"993125859","pt":1580537049493,"mc":[{"id":"1.168133543","rc":[{"batb":[[0,230,1.32]],"ltp":280.0,"tv":1.54,"id":24270700}]}]}
{"op":"mcm","clk":"993125887","pt":1580537050210,"mc":[{"id":"1.168133543","rc":[{"batl":[[0,2.38,4.01],[1,2.42,5.5],[2,2.46,21]],"ltp":2.36,"tv":2462.89,"id":10107355},{"batb":[[1,220,1.26],[2,170,4.13]],"ltp":280.0,"tv":1.54,"id":24270700}]}]}
{"op":"mcm","clk":"993126324","pt":1580537063515,"mc":[{"id":"1.168133543","rc":[{"batb":[[1,180,1.03],[2,170,3.21]],"ltp":280.0,"tv":1.54,"id":24270700}]}]}
{"op":"mcm","clk":"993126328","pt":1580537063616,"mc":[{"id":"1.168133543","rc":[{"batb":[[0,230,2.42]],"ltp":280.0,"tv":1.54,"id":24270700}]}]}
{"op":"mcm","clk":"993126584","pt":1580537071514,"mc":[{"id":"1.168133543","rc":[{"batb":[[0,55,3.43]],"ltp":60.0,"tv":30.43,"id":7226819}]}]}
{"op":"mcm","clk":"993126718","pt":1580537073826,"mc":[{"id":"1.168133543","rc":[{"batl":[[0,2.38,2.01],[1,2.4,2],[2,2.42,5.5]],"ltp":2.36,"tv":2462.89,"id":10107355}]}]}
{"op":"mcm","clk":"993126852","pt":1580537078562,"mc":[{"id":"1.168133543","rc":[{"batb":[[0,230,1.32]],"ltp":280.0,"tv":1.54,"id":24270700}]}]}
{"op":"mcm","clk":"993126890","pt":1580537079544,"mc":[{"id":"1.168133543","rc":[{"batb":[[1,220,1.26],[2,170,4.13]],"ltp":280.0,"tv":1.54,"id":24270700}]}]}
{"op":"mcm","clk":"993127391","pt":1580537092556,"mc":[{"id":"1.168133543","rc":[{"batb":[[0,230,2.42],[1,180,1.03],[2,170,3.21]],"ltp":280.0,"tv":1.54,"id":24270700}]}]}
{"op":"mcm","clk":"993127979","pt":1580537106489,"mc":[{"id":"1.168133543","rc":[{"batl":[[0,2.38,4.01],[1,2.42,5.5],[2,2.46,21]],"ltp":2.36,"tv":2462.89,"id":10107355},{"batb":[[0,230,1.32]],"ltp":280.0,"tv":1.54,"id":24270700}]}]}
{"op":"mcm","clk":"993127982","pt":1580537106590,"mc":[{"id":"1.168133543","rc":[{"batb":[[1,220,1.26],[2,170,4.13]],"ltp":280.0,"tv":1.54,"id":24270700}]}]}
{"op":"mcm","clk":"993128380","pt":1580537114559,"mc":[{"id":"1.168133543","rc":[{"batl":[[0,2.38,2.01],[1,2.4,2],[2,2.42,5.5]],"ltp":2.36,"tv":2462.89,"id":10107355}]}]}
{"op":"mcm","clk":"993128641","pt":1580537120175,"mc":[{"id":"1.168133543","rc":[{"batb":[[1,2.32,10.62]],"ltp":2.36,"tv":2462.89,"id":10107355}]}]}
{"op":"mcm","clk":"993128699","pt":1580537121457,"mc":[{"id":"1.168133543","rc":[{"batb":[[1,180,1.03],[2,170,3.21]],"ltp":280.0,"tv":1.54,"id":24270700}]}]}
{"op":"mcm","clk":"993128752","pt":1580537122383,"mc":[{"id":"1.168133543","rc":[{"batl":[[0,2.38,4.01],[1,2.42,5.5],[2,2.46,21]],"ltp":2.36,"tv":2462.89,"id":10107355},{"batb":[[0,230,2.42]],"ltp":280.0,"tv":1.54,"id":24270700}]}]}
{"op":"mcm","clk":"993129118","pt":1580537130371,"mc":[{"id":"1.168133543","rc":[{"batl":[[0,2.38,2.01],[1,2.4,2],[2,2.42,5.5]],"ltp":2.36,"tv":2462.89,"id":10107355}]}]}
{"op":"mcm","clk":"993129401","pt":1580537135696,"mc":[{"id":"1.168133543","rc":[{"batb":[[0,230,1.32],[1,220,1.26],[2,170,4.13]],"ltp":280.0,"tv":1.54,"id":24270700}]}]}
{"op":"mcm","clk":"993129552","pt":1580537138321,"mc":[{"id":"1.168133543","rc":[{"batl":[[0,2.38,4.01],[1,2.42,5.5],[2,2.46,21]],"ltp":2.36,"tv":2462.89,"id":10107355}]}]}
{"op":"mcm","clk":"993129885","pt":1580537146105,"mc":[{"id":"1.168133543","rc":[{"batl":[[0,2.38,2.01],[1,2.4,2],[2,2.42,5.5]],"ltp":2.36,"tv":2462.89,"id":10107355}]}]}
{"op":"mcm","clk":"993130045","pt":1580537149504,"mc":[{"id":"1.168133543","rc":[{"batb":[[1,180,1.03],[2,170,3.21]],"ltp":280.0,"tv":1.54,"id":24270700}]}]}
{"op":"mcm","clk":"993130050","pt":1580537149604,"mc":[{"id":"1.168133543","rc":[{"batb":[[0,230,2.42]],"ltp":280.0,"tv":1.54,"id":24270700}]}]}
{"op":"mcm","clk":"993130710","pt":1580537164565,"mc":[{"id":"1.168133543","rc":[{"batb":[[0,230,1.32]],"ltp":280.0,"tv":1.54,"id":24270700}]}]}
{"op":"mcm","clk":"993130726","pt":1580537164873,"mc":[{"id":"1.168133543","rc":[{"batb":[[1,220,1.26],[2,170,4.13]],"ltp":280.0,"tv":1.54,"id":24270700}]}]}
{"op":"mcm","clk":"993131339","pt":1580537177547,"mc":[{"id":"1.168133543","rc":[{"batl":[[1,2.42,5.5],[2,2.46,21]],"ltp":2.36,"tv":2462.89,"id":10107355}]}]}
{"op":"mcm","clk":"993131380","pt":1580537178474,"mc":[{"id":"1.168133543","rc":[{"batl":[[0,2.38,4.01]],"ltp":2.36,"tv":2462.89,"id":10107355},{"batb":[[1,180,1.03],[2,170,3.21]],"ltp":280.0,"tv":1.54,"id":24270700}]}]}
{"op":"mcm","clk":"993131385","pt":1580537178576,"mc":[{"id":"1.168133543","rc":[{"batb":[[0,230,2.42]],"ltp":280.0,"tv":1.54,"id":24270700}]}]}
{"op":"mcm","clk":"993132049","pt":1580537192574,"mc":[{"id":"1.168133543","rc":[{"batb":[[0,230,1.32]],"ltp":280.0,"tv":1.54,"id":24270700}]}]}
{"op":"mcm","clk":"993132082","pt":1580537193294,"mc":[{"id":"1.168133543","rc":[{"batl":[[0,2.38,2.01],[1,2.4,2],[2,2.42,5.5]],"ltp":2.36,"tv":2462.89,"id":10107355},{"batb":[[1,220,1.26],[2,170,4.13]],"ltp":280.0,"tv":1.54,"id":24270700}]}]}
{"op":"mcm","clk":"993132393","pt":1580537201375,"mc":[{"id":"1.168133543","rc":[{"batl":[[0,2.38,4.01],[1,2.42,5.5],[2,2.46,21]],"ltp":2.36,"tv":2462.89,"id":10107355}]}]}
{"op":"mcm","clk":"993132643","pt":1580537207505,"mc":[{"id":"1.168133543","rc":[{"batb":[[1,180,1.03],[2,170,3.21]],"ltp":280.0,"tv":1.54,"id":24270700}]}]}
{"op":"mcm","clk":"993132649","pt":1580537207608,"mc":[{"id":"1.168133543","rc":[{"batb":[[0,230,2.42]],"ltp":280.0,"tv":1.54,"id":24270700}]}]}
{"op":"mcm","clk":"993132727","pt":1580537209419,"mc":[{"id":"1.168133543","rc":[{"batl":[[0,2.38,2.01],[1,2.4,2],[2,2.42,5.5]],"ltp":2.36,"tv":2462.89,"id":10107355}]}]}
{"op":"mcm","clk":"993133218","pt":1580537221507,"mc":[{"id":"1.168133543","rc":[{"batb":[[0,230,1.32]],"ltp":280.0,"tv":1.54,"id":24270700}]}]}
{"op":"mcm","clk":"993133255","pt":1580537222432,"mc":[{"id":"1.168133543","rc":[{"batb":[[1,220,1.26],[2,170,4.13]],"ltp":280.0,"tv":1.54,"id":24270700}]}]}
{"op":"mcm","clk":"993133703","pt":1580537233354,"mc":[{"id":"1.168133543","rc":[{"batl":[[0,2.38,4.01],[1,2.42,5.5],[2,2.46,21]],"ltp":2.36,"tv":2462.89,"id":10107355}]}]}
{"op":"mcm","clk":"993133788","pt":1580537235529,"mc":[{"id":"1.168133543","rc":[{"batb":[[1,180,1.03],[2,170,3.21]],"ltp":280.0,"tv":1.54,"id":24270700}]}]}
{"op":"mcm","clk":"993133793","pt":1580537235632,"mc":[{"id":"1.168133543","rc":[{"batb":[[0,230,2.42]],"ltp":280.0,"tv":1.54,"id":24270700}]}]}
{"op":"mcm","clk":"993134328","pt":1580537249527,"mc":[{"id":"1.168133543","rc":[{"batl":[[0,2.38,2.01]],"ltp":2.36,"tv":2462.89,"id":10107355}]}]}
{"op":"mcm","clk":"993134363","pt":1580537250556,"mc":[{"id":"1.168133543","rc":[{"batl":[[1,2.4,2],[2,2.42,5.5]],"ltp":2.36,"tv":2462.89,"id":10107355},{"batb":[[0,230,1.32],[1,220,1.26],[2,170,4.13]],"ltp":280.0,"tv":1.54,"id":24270700}]}]}
{"op":"mcm","clk":"993144389","pt":1580537257343,"mc":[{"id":"1.168133543","rc":[{"batb":[[2,110,14.02]],"ltp":580.0,"tv":6.13,"id":27606066}]}]}
{"op":"mcm","clk":"993144668","pt":1580537264548,"mc":[{"id":"1.168133543","rc":[{"batb":[[1,180,1.03],[2,170,3.21]],"ltp":280.0,"tv":1.54,"id":24270700}]}]}
{"op":"mcm","clk":"993144670","pt":1580537264648,"mc":[{"id":"1.168133543","rc":[{"batb":[[0,230,2.42]],"ltp":280.0,"tv":1.54,"id":24270700}]}]}
{"op":"mcm","clk":"993145121","pt":1580537276537,"mc":[{"id":"1.168133543","rc":[{"batb":[[1,120,2.62]],"ltp":580.0,"tv":6.13,"id":27606066}]}]}
{"op":"mcm","clk":"993145188","pt":1580537278552,"mc":[{"id":"1.168133543","rc":[{"batb":[[1,110,14.53],[2,100,16.8]],"ltp":580.0,"tv":6.13,"id":27606066},{"batb":[[0,230,1.32]],"ltp":280.0,"tv":1.54,"id":24270700}]}]}
{"op":"mcm","clk":"993145193","pt":1580537278655,"mc":[{"id":"1.168133543","rc":[{"batb":[[1,130,2.46],[2,110,14.02]],"ltp":580.0,"tv":6.13,"id":27606066},{"batb":[[1,220,1.26],[2,170,4.13]],"ltp":280.0,"tv":1.54,"id":24270700}]}]}
{"op":"mcm","clk":"993145617","pt":1580537289063,"mc":[{"id":"1.168133543","rc":[{"batl":[[0,2.38,4.01],[1,2.42,5.5],[2,2.46,21]],"ltp":2.36,"tv":2462.89,"id":10107355}]}]}
{"op":"mcm","clk":"993145802","pt":1580537293565,"mc":[{"id":"1.168133543","rc":[{"batb":[[1,140,1.84],[2,110,14.5]],"ltp":580.0,"tv":6.13,"id":27606066},{"batb":[[0,230,2.42],[1,180,1.03],[2,170,3.21]],"ltp":280.0,"tv":1.54,"id":24270700}]}]}
{"op":"mcm","clk":"993145893","pt":1580537295965,"mc":[{"id":"1.168133543","rc":[{"batb":[[2,110,14.17]],"ltp":580.0,"tv":6.13,"id":27606066}]}]}
{"op":"mcm","clk":"993146342","pt":1580537307549,"mc":[{"id":"1.168133543","rc":[{"batb":[[0,230,1.32]],"ltp":280.0,"tv":1.54,"id":24270700}]}]}
{"op":"mcm","clk":"993146346","pt":1580537307653,"mc":[{"id":"1.168133543","rc":[{"batb":[[1,220,1.26],[2,170,4.13]],"ltp":280.0,"tv":1.54,"id":24270700}]}]}
{"op":"mcm","clk":"993146530","pt":1580537313266,"mc":[{"id":"1.168133543","rc":[{"batl":[[0,2.38,2.01],[1,2.4,2],[2,2.42,5.5]],"ltp":2.36,"tv":2462.89,"id":10107355}]}]}
{"op":"mcm","clk":"993146868","pt":1580537321553,"mc":[{"id":"1.168133543","rc":[{"batb":[[1,180,1.03],[2,170,3.21]],"ltp":280.0,"tv":1.54,"id":24270700}]}]}
{"op":"mcm","clk":"993146873","pt":1580537321656,"mc":[{"id":"1.168133543","rc":[{"batb":[[0,230,2.42]],"ltp":280.0,"tv":1.54,"id":24270700}]}]}
{"op":"mcm","clk":"993147478","pt":1580537336477,"mc":[{"id":"1.168133543","rc":[{"batb":[[1,140,1.97],[2,110,14.02]],"ltp":580.0,"tv":6.13,"id":27606066},{"batb":[[0,230,1.32],[1,220,1.26],[2,170,4.13]],"ltp":280.0,"tv":1.54,"id":24270700}]}]}
{"op":"mcm","clk":"993148019","pt":1580537350570,"mc":[{"id":"1.168133543","rc":[{"batb":[[1,110,14.18],[2,100,16.8]],"ltp":580.0,"tv":6.13,"id":27606066},{"batb":[[1,180,1.03],[2,170,3.21]],"ltp":280.0,"tv":1.54,"id":24270700}]}]}
{"op":"mcm","clk":"993148033","pt":1580537350980,"mc":[{"id":"1.168133543","rc":[{"batb":[[1,150,1.85],[2,110,14.02]],"ltp":580.0,"tv":6.13,"id":27606066},{"batb":[[0,230,2.42]],"ltp":280.0,"tv":1.54,"id":24270700}]}]}
{"op":"mcm","clk":"993148455","pt":1580537361015,"mc":[{"id":"1.168133543","rc":[{"batl":[[0,2.38,4.01],[1,2.42,5.5],[2,2.46,21]],"ltp":2.36,"tv":2462.89,"id":10107355}]}]}
{"op":"mcm","clk":"993148614","pt":1580537364679,"mc":[{"id":"1.168133543","rc":[{"batb":[[1,160,1.61],[2,110,14.15]],"ltp":580.0,"tv":6.13,"id":27606066},{"batb":[[0,230,1.32],[1,220,1.26],[2,170,4.13]],"ltp":280.0,"tv":1.54,"id":24270700}]}]}
{"op":"mcm","clk":"993148774","pt":1580537368910,"mc":[{"id":"1.168133543","rc":[{"batl":[[0,2.38,2.01],[1,2.4,2],[2,2.42,5.5]],"ltp":2.36,"tv":2462.89,"id":10107355}]}]}
{"op":"mcm","clk":"993149216","pt":1580537379532,"mc":[{"id":"1.168133543","rc":[{"batb":[[1,110,14.18],[2,100,16.8]],"ltp":580.0,"tv":6.13,"id":27606066},{"batb":[[1,180,1.03],[2,170,3.21]],"ltp":280.0,"tv":1.54,"id":24270700}]}]}
{"op":"mcm","clk":"993149221","pt":1580537379635,"mc":[{"id":"1.168133543","rc":[{"batb":[[1,170,1.52],[2,110,14.15]],"ltp":580.0,"tv":6.13,"id":27606066},{"batb":[[0,230,2.42]],"ltp":280.0,"tv":1.54,"id":24270700}]}]}
{"op":"mcm","clk":"993149430","pt":1580537384538,"mc":[{"id":"1.168133543","rc":[{"batl":[[1,2.42,5.5],[2,2.46,21]],"ltp":2.36,"tv":2462.89,"id":10107355}]}]}
{"op":"mcm","clk":"993149450","pt":1580537385005,"mc":[{"id":"1.168133543","rc":[{"batl":[[0,2.38,4.01]],"ltp":2.36,"tv":2462.89,"id":10107355}]}]}
{"op":"mcm","clk":"993149683","pt":1580537390510,"mc":[{"id":"1.168133543","rc":[{"batb":[[1,170,1.63],[2,110,14.02]],"ltp":580.0,"tv":6.13,"id":27606066}]}]}
{"op":"mcm","clk":"993149797","pt":1580537393519,"mc":[{"id":"1.168133543","rc":[{"batl":[[0,2.38,2.01],[1,2.4,2],[2,2.42,5.5]],"ltp":2.36,"tv":2462.89,"id":10107355},{"batb":[[1,110,14.16],[2,100,16.8]],"ltp":580.0,"tv":6.13,"id":27606066},{"batb":[[0,230,1.32]],"ltp":280.0,"tv":1.54,"id":24270700}]}]}
{"op":"mcm","clk":"993149807","pt":1580537393725,"mc":[{"id":"1.168133543","rc":[{"batb":[[0,2.34,37]],"ltp":2.36,"tv":2462.89,"id":10107355},{"batb":[[1,180,1.55],[2,110,14.02]],"ltp":580.0,"tv":6.13,"id":27606066},{"batb":[[1,220,1.26],[2,170,4.13]],"ltp":280.0,"tv":1.54,"id":24270700}]}]}
{"op":"mcm","clk":"993150122","pt":1580537401536,"mc":[{"id":"1.168133543","rc":[{"batl":[[0,2.38,4.01],[1,2.42,5.5],[2,2.46,21]],"ltp":2.36,"tv":2462.89,"id":10107355}]}]}
{"op":"mcm","clk":"993150332","pt":1580537407570,"mc":[{"id":"1.168133543","rc":[{"batb":[[0,2.34,7.36]],"ltp":2.36,"tv":2462.89,"id":10107355},{"batb":[[1,110,14.16],[2,100,16.8]],"ltp":580.0,"tv":6.13,"id":27606066},{"batb":[[1,180,1.03],[2,170,3.21]],"ltp":280.0,"tv":1.54,"id":24270700}]}]}
{"op":"mcm","clk":"993150336","pt":1580537407623,"mc":[{"id":"1.168133543","rc":[{"batb":[[1,190,1.36],[2,110,14.13]],"ltp":580.0,"tv":6.13,"id":27606066},{"batb":[[0,230,2.42]],"ltp":280.0,"tv":1.54,"id":24270700}]}]}
{"op":"mcm","clk":"993150401","pt":1580537409273,"mc":[{"id":"1.168133543","rc":[{"batl":[[0,2.38,2.01],[1,2.4,2],[2,2.42,5.5]],"ltp":2.36,"tv":2462.89,"id":10107355}]}]}
{"op":"mcm","clk":"993150723","pt":1580537417461,"mc":[{"id":"1.168133543","rc":[{"batl":[[0,2.38,4.01],[1,2.42,5.5],[2,2.46,21]],"ltp":2.36,"tv":2462.89,"id":10107355}]}]}
{"op":"mcm","clk":"993150923","pt":1580537422559,"mc":[{"id":"1.168133543","rc":[{"batb":[[1,110,14.16],[2,100,16.8]],"ltp":580.0,"tv":6.13,"id":27606066},{"batb":[[0,230,1.32]],"ltp":280.0,"tv":1.54,"id":24270700}]}]}
{"op":"mcm","clk":"993150945","pt":1580537422970,"mc":[{"id":"1.168133543","rc":[{"batb":[[0,9.4,2.77],[1,9.2,5.64],[2,8.8,2.37]],"ltp":9.4,"tv":357.31,"id":10163711},{"batb":[[1,120,2.25],[2,110,14.02]],"ltp":580.0,"tv":6.13,"id":27606066},{"batb":[[1,220,1.26],[2,170,4.13]],"ltp":280.0,"tv":1.54,"id":24270700}]}]}
{"op":"mcm","clk":"993151480","pt":1580537435412,"mc":[{"id":"1.168133543","rc":[{"batb":[[1,120,2.58]],"ltp":580.0,"tv":6.13,"id":27606066}]}]}
{"op":"mcm","clk":"993151528","pt":1580537436501,"mc":[{"id":"1.168133543","rc":[{"batb":[[0,9.2,5.64],[1,8.8,2.37],[2,8.6,7.91]],"ltp":9.4,"tv":357.31,"id":10163711},{"batb":[[1,110,14.49],[2,100,16.8]],"ltp":580.0,"tv":6.13,"id":27606066},{"batb":[[1,180,1.03],[2,170,3.21]],"ltp":280.0,"tv":1.54,"id":24270700}]}]}
{"op":"mcm","clk":"993151547","pt":1580537436911,"mc":[{"id":"1.168133543","rc":[{"batb":[[1,130,2.42],[2,110,14.02]],"ltp":580.0,"tv":6.13,"id":27606066},{"batb":[[0,230,2.42]],"ltp":280.0,"tv":1.54,"id":24270700}]}]}
{"op":"mcm","clk":"993151741","pt":1580537442424,"mc":[{"id":"1.168133543","rc":[{"batl":[[0,2.38,2.01],[1,2.4,2],[2,2.42,5.5]],"ltp":2.36,"tv":2462.89,"id":10107355}]}]}
{"op":"mcm","clk":"993151837","pt":1580537444385,"mc":[{"id":"1.168133543","rc":[{"batb":[[1,130,2.45]],"ltp":580.0,"tv":6.13,"id":27606066}]}]}
{"op":"mcm","clk":"993152043","pt":1580537449024,"mc":[{"id":"1.168133543","rc":[{"batl":[[0,2.38,4.01],[1,2.42,5.5],[2,2.46,21]],"ltp":2.36,"tv":2462.89,"id":10107355}]}]}
{"op":"mcm","clk":"993152115","pt":1580537450727,"mc":[{"id":"1.168133543","rc":[{"batb":[[1,140,1.98],[2,110,14.35]],"ltp":580.0,"tv":6.13,"id":27606066},{"batb":[[0,230,1.32],[1,220,1.26],[2,170,4.13]],"ltp":280.0,"tv":1.54,"id":24270700}]}]}
{"op":"mcm","clk":"993152307","pt":1580537455824,"mc":[{"id":"1.168133543","rc":[{"batb":[[2,110,14.02]],"ltp":580.0,"tv":6.13,"id":27606066}]}]}
{"op":"mcm","clk":"993152672","pt":1580537464541,"mc":[{"id":"1.168133543","rc":[{"batb":[[0,2.88,5.55],[1,2.82,4],[2,2.8,2.2]],"ltp":2.9,"tv":1076.36,"id":12636},{"batl":[[0,2.38,2.01],[1,2.4,2],[2,2.42,5.5]],"ltp":2.36,"tv":2462.89,"id":10107355}]}]}
{"op":"mcm","clk":"993152707","pt":1580537465524,"mc":[{"id":"1.168133543","rc":[{"batb":[[1,110,14.19],[2,100,16.8]],"ltp":580.0,"tv":6.13,"id":27606066},{"batb":[[1,180,1.03],[2,170,3.21]],"ltp":280.0,"tv":1.54,"id":24270700}]}]}
{"op":"mcm","clk":"993152746","pt":1580537466343,"mc":[{"id":"1.168133543","rc":[{"batb":[[1,150,1.72],[2,110,14.16]],"ltp":580.0,"tv":6.13,"id":27606066},{"batb":[[0,230,2.42]],"ltp":280.0,"tv":1.54,"id":24270700}]}]}
{"op":"mcm","clk":"993153351","pt":1580537479558,"mc":[{"id":"1.168133543","rc":[{"batb":[[0,2.34,37]],"batl":[[0,2.38,4.01],[1,2.42,5.5],[2,2.46,21]],"ltp":2.36,"tv":2462.89,"id":10107355},{"batb":[[1,110,14.19],[2,100,16.8]],"ltp":580.0,"tv":6.13,"id":27606066},{"batb":[[0,230,1.32]],"ltp":280.0,"tv":1.54,"id":24270700}]}]}
{"op":"mcm","clk":"993153359","pt":1580537479664,"mc":[{"id":"1.168133543","rc":[{"batb":[[1,160,1.61],[2,110,14.16]],"ltp":580.0,"tv":6.13,"id":27606066},{"batb":[[1,220,1.26],[2,170,4.13]],"ltp":280.0,"tv":1.54,"id":24270700}]}]}
{"op":"mcm","clk":"993153675","pt":1580537486374,"mc":[{"id":"1.168133543","rc":[{"batl":[[0,2.38,2.01],[1,2.4,2],[2,2.42,5.5]],"ltp":2.36,"tv":2462.89,"id":10107355}]}]}
{"op":"mcm","clk":"993153968","pt":1580537493557,"mc":[{"id":"1.168133543","rc":[{"batb":[[1,110,14.19],[2,100,16.8]],"ltp":580.0,"tv":6.13,"id":27606066},{"batb":[[1,180,1.03],[2,170,3.21]],"ltp":280.0,"tv":1.54,"id":24270700}]}]}
{"op":"mcm","clk":"993153974","pt":1580537493664,"mc":[{"id":"1.168133543","rc":[{"batb":[[1,170,1.52],[2,110,14.16]],"ltp":580.0,"tv":6.13,"id":27606066},{"batb":[[0,230,2.42]],"ltp":280.0,"tv":1.54,"id":24270700}]}]}
{"op":"mcm","clk":"993154157","pt":1580537498362,"mc":[{"id":"1.168133543","rc":[{"batb":[[1,2.32,2]],"ltp":2.36,"tv":2462.89,"id":10107355},{"batb":[[1,170,1.63],[2,110,14.02]],"ltp":580.0,"tv":6.13,"id":27606066}]}]}
{"op":"mcm","clk":"993154299","pt":1580537501468,"mc":[{"id":"1.168133543","rc":[{"batl":[[0,2.38,4.01],[1,2.42,5.5],[2,2.46,21]],"ltp":2.36,"tv":2462.89,"id":10107355}]}]}
{"op":"mcm","clk":"993154627","pt":1580537508498,"mc":[{"id":"1.168133543","rc":[{"batb":[[0,2.34,7.36]],"ltp":2.36,"tv":2462.89,"id":10107355},{"batb":[[1,110,14.16],[2,100,16.8]],"ltp":580.0,"tv":6.13,"id":27606066},{"batb":[[0,230,1.32]],"ltp":280.0,"tv":1.54,"id":24270700}]}]}
{"op":"mcm","clk":"993154644","pt":1580537508802,"mc":[{"id":"1.168133543","rc":[{"batb":[[0,9.4,2.77],[1,9.2,5.64],[2,8.8,2.37]],"ltp":9.4,"tv":357.31,"id":10163711},{"batb":[[2,2.3,30.15]],"ltp":2.36,"tv":2462.89,"id":10107355},{"batb":[[1,180,1.55],[2,110,14.02]],"ltp":580.0,"tv":6.13,"id":27606066},{"batb":[[1,220,1.26],[2,170,4.13]],"ltp":280.0,"tv":1.54,"id":24270700}]}]}
{"op":"mcm","clk":"993154974","pt":1580537516498,"mc":[{"id":"1.168133543","rc":[{"batl":[[0,2.38,2.01],[1,2.4,2],[2,2.42,5.5]],"ltp":2.36,"tv":2462.89,"id":10107355}]}]}
{"op":"mcm","clk":"993155219","pt":1580537522499,"mc":[{"id":"1.168133543","rc":[{"batl":[[1,2.42,5.5],[2,2.46,21]],"ltp":2.36,"tv":2462.89,"id":10107355}]}]}
{"op":"mcm","clk":"993155254","pt":1580537523116,"mc":[{"id":"1.168133543","rc":[{"batb":[[1,2.84,4]],"ltp":2.9,"tv":1076.36,"id":12636},{"batb":[[0,9.2,5.64],[1,8.8,2.37],[2,8.6,7.91]],"ltp":9.4,"tv":357.31,"id":10163711},{"batl":[[0,2.38,4.01]],"ltp":2.36,"tv":2462.89,"id":10107355},{"batb":[[1,190,1.36],[2,110,14.13]],"ltp":580.0,"tv":6.13,"id":27606066},{"batb":[[0,230,2.42],[1,180,1.03],[2,170,3.21]],"ltp":280.0,"tv":1.54,"id":24270700}]}]}
{"op":"mcm","clk":"993155580","pt":1580537531489,"mc":[{"id":"1.168133543","rc":[{"batl":[[0,2.38,2.01]],"ltp":2.36,"tv":2462.89,"id":10107355}]}]}
{"op":"mcm","clk":"993155585","pt":1580537531592,"mc":[{"id":"1.168133543","rc":[{"batl":[[1,2.4,2],[2,2.42,5.5]],"ltp":2.36,"tv":2462.89,"id":10107355}]}]}
{"op":"mcm","clk":"993155790","pt":1580537536528,"mc":[{"id":"1.168133543","rc":[{"batb":[[1,110,14.16],[2,100,16.8]],"ltp":580.0,"tv":6.13,"id":27606066},{"batb":[[0,230,1.32]],"ltp":280.0,"tv":1.54,"id":24270700}]}]}
{"op":"mcm","clk":"993155799","pt":1580537536686,"mc":[{"id":"1.168133543","rc":[{"batb":[[0,2.88,75.01]],"ltp":2.9,"tv":1076.36,"id":12636},{"batb":[[0,9.4,2.77],[1,9.2,5.64],[2,8.8,2.37]],"ltp":9.4,"tv":357.31,"id":10163711},{"batb":[[1,120,2.25],[2,110,14.02]],"ltp":580.0,"tv":6.13,"id":27606066},{"batb":[[1,220,1.26],[2,170,4.13]],"ltp":280.0,"tv":1.54,"id":24270700}]}]}
{"op":"mcm","clk":"993155896","pt":1580537538800,"mc":[{"id":"1.168133543","rc":[{"batl":[[0,2.38,4.01],[1,2.42,5.5],[2,2.46,21]],"ltp":2.36,"tv":2462.89,"id":10107355}]}]}
{"op":"mcm","clk":"993156496","pt":1580537551513,"mc":[{"id":"1.168133543","rc":[{"batb":[[0,2.88,5.55]],"ltp":2.9,"tv":1076.36,"id":12636},{"batb":[[0,230,2.42],[1,180,1.03],[2,170,3.21]],"ltp":280.0,"tv":1.54,"id":24270700}]}]}
{"op":"mcm","clk":"993156545","pt":1580537552500,"mc":[{"id":"1.168133543","rc":[{"batb":[[1,120,2.14]],"ltp":580.0,"tv":6.13,"id":27606066}]}]}
{"op":"mcm","clk":"993156575","pt":1580537553017,"mc":[{"id":"1.168133543","rc":[{"batb":[[1,120,2.29]],"ltp":580.0,"tv":6.13,"id":27606066}]}]}
{"op":"mcm","clk":"993156670","pt":1580537555229,"mc":[{"id":"1.168133543","rc":[{"batb":[[1,120,2.62]],"ltp":580.0,"tv":6.13,"id":27606066}]}]}
{"op":"mcm","clk":"993157101","pt":1580537565521,"mc":[{"id":"1.168133543","rc":[{"batb":[[1,110,14.53],[2,100,16.8]],"ltp":580.0,"tv":6.13,"id":27606066},{"batb":[[0,230,1.32]],"ltp":280.0,"tv":1.54,"id":24270700}]}]}
{"op":"mcm","clk":"993157113","pt":1580537565829,"mc":[{"id":"1.168133543","rc":[{"batb":[[0,2.88,75.01]],"ltp":2.9,"tv":1076.36,"id":12636},{"batb":[[1,130,2.46],[2,110,14.02]],"ltp":580.0,"tv":6.13,"id":27606066},{"batb":[[1,220,1.26],[2,170,4.13]],"ltp":280.0,"tv":1.54,"id":24270700}]}]}
{"op":"mcm","clk":"993157200","pt":1580537568256,"mc":[{"id":"1.168133543","rc":[{"batl":[[0,2.38,2.01],[1,2.4,2],[2,2.42,5.5]],"ltp":2.36,"tv":2462.89,"id":10107355}]}]}
{"op":"mcm","clk":"993157415","pt":1580537573168,"mc":[{"id":"1.168133543","rc":[{"batl":[[0,2.36,2],[1,2.38,2.01],[2,2.4,2]],"ltp":2.36,"tv":2462.89,"id":10107355}]}]}
{"op":"mcm","clk":"993157682","pt":1580537579553,"mc":[{"id":"1.168133543","rc":[{"batb":[[0,2.88,5.55]],"ltp":2.9,"tv":1076.36,"id":12636},{"batb":[[1,110,14.53],[2,100,16.8]],"ltp":580.0,"tv":6.13,"id":27606066},{"batb":[[1,180,1.03],[2,170,3.21]],"ltp":280.0,"tv":1.54,"id":24270700}]}]}
{"op":"mcm","clk":"993157697","pt":1580537579865,"mc":[{"id":"1.168133543","rc":[{"batb":[[1,140,1.84],[2,110,14.5]],"ltp":580.0,"tv":6.13,"id":27606066},{"batb":[[0,230,2.42]],"ltp":280.0,"tv":1.54,"id":24270700}]}]}
{"op":"mcm","clk":"993157914","pt":1580537583757,"mc":[{"id":"1.168133543","rc":[{"trd":[[2.34,321.42]],"batb":[[0,2.34,5.36]],"batl":[[2,2.42,5.5]],"ltp":2.34,"tv":2466.89,"id":10107355}],"tv":4336.51}]}
{"op":"mcm","clk":"993158413","pt":1580537594556,"mc":[{"id":"1.168133543","rc":[{"batb":[[0,230,1.32]],"ltp":280.0,"tv":1.54,"id":24270700}]}]}
{"op":"mcm","clk":"993158433","pt":1580537594864,"mc":[{"id":"1.168133543","rc":[{"batb":[[0,2.88,75.01]],"ltp":2.9,"tv":1076.36,"id":12636},{"batb":[[1,220,1.26],[2,170,4.13]],"ltp":280.0,"tv":1.54,"id":24270700}]}]}
{"op":"mcm","clk":"993158494","pt":1580537596150,"mc":[{"id":"1.168133543","rc":[{"batb":[[2,110,14.17]],"ltp":580.0,"tv":6.13,"id":27606066}]}]}
{"op":"mcm","clk":"993158600","pt":1580537598567,"mc":[{"id":"1.168133543","rc":[{"trd":[[2.34,325.42]],"batb":[[0,2.34,3.36]],"ltp":2.34,"tv":2470.89,"id":10107355}],"tv":4340.51}]}
{"op":"mcm","clk":"993158623","pt":1580537599086,"mc":[{"id":"1.168133543","rc":[{"batb":[[1,2.86,4]],"ltp":2.9,"tv":1076.36,"id":12636}]}]}
{"op":"mcm","clk":"993158929","pt":1580537604478,"mc":[{"id":"1.168133543","rc":[{"trd":[[2.9,151.78]],"batl":[[0,2.92,41.64],[1,2.94,58.02],[2,2.96,50]],"ltp":2.9,"tv":1082.42,"id":12636}],"tv":4346.57}]}
{"op":"mcm","clk":"993159002","pt":1580537605975,"mc":[{"id":"1.168133543","rc":[{"batb":[[1,140,1.97],[2,110,14.02]],"ltp":580.0,"tv":6.13,"id":27606066}]}]}
{"op":"mcm","clk":"993159137","pt":1580537608805,"mc":[{"id":"1.168133543","rc":[{"batb":[[0,2.88,5.55]],"ltp":2.9,"tv":1082.42,"id":12636},{"batb":[[1,150,1.85]],"ltp":580.0,"tv":6.13,"id":27606066},{"batb":[[0,230,2.42],[1,180,1.03],[2,170,3.21]],"ltp":280.0,"tv":1.54,"id":24270700}]}]}
{"op":"mcm","clk":"993159402","pt":1580537614485,"mc":[{"id":"1.168133543","rc":[{"trd":[[2.34,329.42]],"batb":[[0,2.34,1.36]],"ltp":2.34,"tv":2474.89,"id":10107355},{"batb":[[0,8.6,2.58],[1,8.4,3.5],[2,7.4,3]],"ltp":8.4,"tv":339.13,"id":22121325}],"tv":4350.57}]}
{"op":"mcm","clk":"993159711","pt":1580537621398,"mc":[{"id":"1.168133543","rc":[{"batl":[[0,2.9,2.57],[1,2.92,41.07],[2,2.94,58.02]],"ltp":2.9,"tv":1082.42,"id":12636}]}]}
{"op":"mcm","clk":"993159754","pt":1580537622482,"mc":[{"id":"1.168133543","rc":[{"batb":[[1,110,14.18],[2,100,16.8]],"ltp":580.0,"tv":6.13,"id":27606066},{"batb":[[0,230,1.32]],"ltp":280.0,"tv":1.54,"id":24270700}]}]}
{"op":"mcm","clk":"993159765","pt":1580537622685,"mc":[{"id":"1.168133543","rc":[{"batb":[[0,2.88,75.01]],"ltp":2.9,"tv":1082.42,"id":12636},{"batb":[[1,160,1.61],[2,110,14.15]],"ltp":580.0,"tv":6.13,"id":27606066},{"batb":[[1,220,1.26],[2,170,4.13]],"ltp":280.0,"tv":1.54,"id":24270700}]}]}
{"op":"mcm","clk":"993160037","pt":1580537629392,"mc":[{"id":"1.168133543","rc":[{"trd":[[2.34,332.14]],"batb":[[0,2.32,2],[1,2.3,30.15],[2,2.28,12.15]],"batl":[[0,2.36,2.64]],"ltp":2.34,"tv":2477.61,"id":10107355}],"tv":4353.29}]}
{"op":"mcm","clk":"993160333","pt":1580537636705,"mc":[{"id":"1.168133543","rc":[{"batl":[[0,2.9,3.58]],"ltp":2.9,"tv":1082.42,"id":12636}]}]}
{"op":"mcm","clk":"993160383","pt":1580537637942,"mc":[{"id":"1.168133543","rc":[{"batb":[[0,2.88,5.55]],"ltp":2.9,"tv":1082.42,"id":12636},{"batb":[[1,170,1.52]],"ltp":580.0,"tv":6.13,"id":27606066},{"batb":[[0,230,2.42],[1,180,1.03],[2,170,3.21]],"ltp":280.0,"tv":1.54,"id":24270700}]}]}
{"op":"mcm","clk":"993160613","pt":1580537644337,"mc":[{"id":"1.168133543","rc":[{"batb":[[0,2.88,9.55],[1,2.8,2.2],[2,2.66,15]],"ltp":2.9,"tv":1082.42,"id":12636}]}]}
{"op":"mcm","clk":"993160954","pt":1580537651544,"mc":[{"id":"1.168133543","rc":[{"batb":[[1,110,14.18],[2,100,16.8]],"ltp":580.0,"tv":6.13,"id":27606066},{"batb":[[0,230,1.32]],"ltp":280.0,"tv":1.54,"id":24270700}]}]}
{"op":"mcm","clk":"993160963","pt":1580537651703,"mc":[{"id":"1.168133543","rc":[{"batb":[[1,180,1.44],[2,110,14.15]],"ltp":580.0,"tv":6.13,"id":27606066},{"batb":[[1,220,1.26],[2,170,4.13]],"ltp":280.0,"tv":1.54,"id":24270700}]}]}
{"op":"mcm","clk":"993161136","pt":1580537656029,"mc":[{"id":"1.168133543","rc":[{"batl":[[0,2.9,8.58]],"ltp":2.9,"tv":1082.42,"id":12636}]}]}
{"op":"mcm","clk":"993161287","pt":1580537659327,"mc":[{"id":"1.168133543","rc":[{"batb":[[0,2.88,5.55],[1,2.82,4],[2,2.8,2.2]],"ltp":2.9,"tv":1082.42,"id":12636}]}]}
{"op":"mcm","clk":"993161321","pt":1580537660249,"mc":[{"id":"1.168133543","rc":[{"batb":[[2,16.5,17.69]],"ltp":65.0,"tv":20.68,"id":22308007},{"batb":[[2,110,14.02]],"ltp":580.0,"tv":6.13,"id":27606066}]}]}
{"op":"mcm","clk":"993161517","pt":1580537665551,"mc":[{"id":"1.168133543","rc":[{"batb":[[1,110,14.05],[2,100,16.8]],"ltp":580.0,"tv":6.13,"id":27606066},{"batb":[[1,180,1.03],[2,170,3.21]],"ltp":280.0,"tv":1.54,"id":24270700}]}]}
{"op":"mcm","clk":"993161526","pt":1580537665757,"mc":[{"id":"1.168133543","rc":[{"batb":[[0,2.88,75.01]],"ltp":2.9,"tv":1082.42,"id":12636},{"batb":[[1,120,2.14],[2,110,14.02]],"ltp":580.0,"tv":6.13,"id":27606066},{"batb":[[0,230,2.42]],"ltp":280.0,"tv":1.54,"id":24270700}]}]}
{"op":"mcm","clk":"993161662","pt":1580537669453,"mc":[{"id":"1.168133543","rc":[{"batl":[[0,2.9,7.57]],"ltp":2.9,"tv":1082.42,"id":12636}]}]}
{"op":"mcm","clk":"993161875","pt":1580537674541,"mc":[{"id":"1.168133543","rc":[{"batb":[[2,17,1.04]],"ltp":65.0,"tv":20.68,"id":22308007},{"batb":[[0,9.4,4.6]],"ltp":9.4,"tv":357.31,"id":10163711}]}]}
{"op":"mcm","clk":"993162039","pt":1580537679577,"mc":[{"id":"1.168133543","rc":[{"batb":[[1,120,2.47]],"ltp":580.0,"tv":6.13,"id":27606066}]}]}
{"op":"mcm","clk":"993162089","pt":1580537681063,"mc":[{"id":"1.168133543","rc":[{"batb":[[0,2.88,5.55]],"ltp":2.9,"tv":1082.42,"id":12636},{"batb":[[1,130,2.31]],"ltp":580.0,"tv":6.13,"id":27606066},{"batb":[[0,230,1.32],[1,220,1.26],[2,170,4.13]],"ltp":280.0,"tv":1.54,"id":24270700}]}]}
{"op":"mcm","clk":"993162609","pt":1580537694865,"mc":[{"id":"1.168133543","rc":[{"batb":[[0,2.88,75.01]],"ltp":2.9,"tv":1082.42,"id":12636},{"batb":[[1,140,1.84],[2,110,14.35]],"ltp":580.0,"tv":6.13,"id":27606066},{"batb":[[0,230,2.42],[1,180,1.03],[2,170,3.21]],"ltp":280.0,"tv":1.54,"id":24270700}]}]}
{"op":"mcm","clk":"993162640","pt":1580537695689,"mc":[{"id":"1.168133543","rc":[{"batb":[[2,8.6,8.01]],"ltp":9.4,"tv":357.31,"id":10163711}]}]}
{"op":"mcm","clk":"993162912","pt":1580537702570,"mc":[{"id":"1.168133543","rc":[{"batb":[[2,110,14.02]],"ltp":580.0,"tv":6.13,"id":27606066}]}]}
{"op":"mcm","clk":"993163134","pt":1580537708480,"mc":[{"id":"1.168133543","rc":[{"batb":[[0,2.88,5.55]],"ltp":2.9,"tv":1082.42,"id":12636},{"batb":[[0,230,1.32]],"ltp":280.0,"tv":1.54,"id":24270700}]}]}
{"op":"mcm","clk":"993163137","pt":1580537708583,"mc":[{"id":"1.168133543","rc":[{"batb":[[1,220,1.26],[2,170,4.13]],"ltp":280.0,"tv":1.54,"id":24270700}]}]}
{"op":"mcm","clk":"993163293","pt":1580537713179,"mc":[{"id":"1.168133543","rc":[{"batb":[[1,2.84,4]],"ltp":2.9,"tv":1082.42,"id":12636}]}]}
{"op":"mcm","clk":"993163662","pt":1580537723504,"mc":[{"id":"1.168133543","rc":[{"batb":[[1,180,1.03],[2,170,3.21]],"ltp":280.0,"tv":1.54,"id":24270700}]}]}
{"op":"mcm","clk":"993163694","pt":1580537724175,"mc":[{"id":"1.168133543","rc":[{"batb":[[0,2.88,75.01]],"ltp":2.9,"tv":1082.42,"id":12636},{"batb":[[0,230,2.42]],"ltp":280.0,"tv":1.54,"id":24270700}]}]}
{"op":"mcm","clk":"993163829","pt":1580537728211,"mc":[{"id":"1.168133543","rc":[{"batb":[[1,2.86,4]],"ltp":2.9,"tv":1082.42,"id":12636}]}]}
{"op":"mcm","clk":"993164237","pt":1580537737710,"mc":[{"id":"1.168133543","rc":[{"batb":[[0,2.88,5.55]],"ltp":2.9,"tv":1082.42,"id":12636},{"batb":[[0,230,1.32],[1,220,1.26],[2,170,4.13]],"ltp":280.0,"tv":1.54,"id":24270700}]}]}
{"op":"mcm","clk":"993164448","pt":1580537742406,"mc":[{"id":"1.168133543","rc":[{"batb":[[0,2.88,9.55],[1,2.8,2.2],[2,2.66,15]],"ltp":2.9,"tv":1082.42,"id":12636}]}]}
{"op":"mcm","clk":"993164791","pt":1580537750505,"mc":[{"id":"1.168133543","rc":[{"batb":[[0,2.88,5.55]],"ltp":2.9,"tv":1082.42,"id":12636}]}]}
{"op":"mcm","clk":"993164795","pt":1580537750606,"mc":[{"id":"1.168133543","rc":[{"batb":[[1,2.82,4],[2,2.8,2.2]],"ltp":2.9,"tv":1082.42,"id":12636}]}]}
{"op":"mcm","clk":"993164859","pt":1580537751841,"mc":[{"id":"1.168133543","rc":[{"batb":[[0,2.88,75.01]],"ltp":2.9,"tv":1082.42,"id":12636},{"batb":[[0,230,2.42],[1,180,1.03],[2,170,3.21]],"ltp":280.0,"tv":1.54,"id":24270700}]}]}
{"op":"mcm","clk":"993165483","pt":1580537765442,"mc":[{"id":"1.168133543","rc":[{"batb":[[1,2.84,4]],"ltp":2.9,"tv":1082.42,"id":12636}]}]}
{"op":"mcm","clk":"993165545","pt":1580537766735,"mc":[{"id":"1.168133543","rc":[{"batb":[[0,2.88,5.55]],"ltp":2.9,"tv":1082.42,"id":12636},{"batb":[[0,230,1.32],[1,220,1.26],[2,170,4.13]],"ltp":280.0,"tv":1.54,"id":24270700}]}]}
{"op":"mcm","clk":"993165815","pt":1580537771345,"mc":[{"id":"1.168133543","rc":[{"trd":[[2.88,156.68]],"batb":[[0,2.88,4.54]],"ltp":2.88,"tv":1084.45,"id":12636}],"tv":4355.31}]}
{"op":"mcm","clk":"993166225","pt":1580537778330,"mc":[{"id":"1.168133543","rc":[{"trd":[[2.88,165.76]],"batb":[[0,2.84,4],[1,2.8,2.2],[2,2.66,15]],"batl":[[0,2.88,1.03],[1,2.9,2],[2,2.92,41.07]],"ltp":2.88,"tv":1093.53,"id":12636}],"tv":4364.39}]}
{"op":"mcm","clk":"993166323","pt":1580537780549,"mc":[{"id":"1.168133543","rc":[{"trd":[[2.86,68.76]],"batb":[[0,2.8,2.2],[1,2.66,15],[2,2.58,1.98]],"ltp":2.86,"tv":1101.53,"id":12636},{"batb":[[1,180,1.03],[2,170,3.21]],"ltp":280.0,"tv":1.54,"id":24270700}],"tv":4372.39}]}
{"op":"mcm","clk":"993166360","pt":1580537781431,"mc":[{"id":"1.168133543","rc":[{"batl":[[0,2.9,3.03],[1,2.92,41.07],[2,2.94,58.02]],"ltp":2.86,"tv":1101.53,"id":12636},{"batb":[[0,230,2.42]],"ltp":280.0,"tv":1.54,"id":24270700}]}]}
{"op":"mcm","clk":"993166430","pt":1580537783276,"mc":[{"id":"1.168133543","rc":[{"batb":[[0,2.8,4.18],[2,2.56,2.92]],"ltp":2.86,"tv":1101.53,"id":12636},{"batb":[[2,48,1.4]],"ltp":60.0,"tv":30.43,"id":7226819},{"batb":[[0,9.4,7.03]],"ltp":9.4,"tv":357.31,"id":10163711},{"batb":[[0,2.32,10.89]],"ltp":2.34,"tv":2477.61,"id":10107355},{"batb":[[0,8.8,1.98],[1,8.6,2.58],[2,8.4,3.5]],"ltp":8.4,"tv":339.13,"id":22121325}]}]}
{"op":"mcm","clk":"993166485","pt":1580537784364,"mc":[{"id":"1.168133543","rc":[{"batl":[[0,2.88,2],[1,2.9,3.03],[2,2.92,41.07]],"ltp":2.86,"tv":1101.53,"id":12636}]}]}
{"op":"mcm","clk":"993166700","pt":1580537789941,"mc":[{"id":"1.168133543","rc":[{"batb":[[1,2.68,15]],"ltp":2.86,"tv":1101.53,"id":12636}]}]}
{"op":"mcm","clk":"993166778","pt":1580537791861,"mc":[{"id":"1.168133543","rc":[{"batb":[[1,2.68,20]],"ltp":2.86,"tv":1101.53,"id":12636}]}]}
{"op":"mcm","clk":"993166924","pt":1580537794559,"mc":[{"id":"1.168133543","rc":[{"batb":[[0,9.4,4.27]],"ltp":9.4,"tv":357.31,"id":10163711},{"batb":[[1,2.28,12.15],[2,2.26,23.83]],"ltp":2.34,"tv":2477.61,"id":10107355},{"batb":[[0,230,1.32]],"ltp":280.0,"tv":1.54,"id":24270700}]}]}
{"op":"mcm","clk":"993166937","pt":1580537794663,"mc":[{"id":"1.168133543","rc":[{"batb":[[1,220,1.26],[2,170,4.13]],"ltp":280.0,"tv":1.54,"id":24270700}]}]}
{"op":"mcm","clk":"993167281","pt":1580537798970,"mc":[{"id":"1.168133543","rc":[{"batb":[[2,2.6,5]],"ltp":2.86,"tv":1101.53,"id":12636}]}]}
{"op":"mcm","clk":"993167498","pt":1580537803160,"mc":[{"id":"1.168133543","rc":[{"batb":[[2,2.62,6.04]],"batl":[[0,2.88,7.5]],"ltp":2.86,"tv":1101.53,"id":12636}]}]}
{"op":"mcm","clk":"993167915","pt":1580537808499,"mc":[{"id":"1.168133543","rc":[{"batb":[[1,180,1.03],[2,170,3.21]],"ltp":280.0,"tv":1.54,"id":24270700}]}]}
{"op":"mcm","clk":"993167918","pt":1580537808600,"mc":[{"id":"1.168133543","rc":[{"batb":[[0,230,2.42]],"ltp":280.0,"tv":1.54,"id":24270700}]}]}
{"op":"mcm","clk":"993168569","pt":1580537823737,"mc":[{"id":"1.168133543","rc":[{"batb":[[0,230,1.32],[1,220,1.26],[2,170,4.13]],"ltp":280.0,"tv":1.54,"id":24270700}]}]}
{"op":"mcm","clk":"993168701","pt":1580537826432,"mc":[{"id":"1.168133543","rc":[{"batb":[[1,2.7,4],[2,2.68,20]],"ltp":2.86,"tv":1101.53,"id":12636}]}]}
{"op":"mcm","clk":"993169272","pt":1580537837553,"mc":[{"id":"1.168133543","rc":[{"batb":[[0,230,2.42],[1,180,1.03],[2,170,3.21]],"ltp":280.0,"tv":1.54,"id":24270700}]}]}
{"op":"mcm","clk":"993169478","pt":1580537841933,"mc":[{"id":"1.168133543","rc":[{"batb":[[1,2.72,4]],"ltp":2.86,"tv":1101.53,"id":12636}]}]}
{"op":"mcm","clk":"993169889","pt":1580537851561,"mc":[{"id":"1.168133543","rc":[{"batb":[[0,230,1.32]],"ltp":280.0,"tv":1.54,"id":24270700}]}]}
{"op":"mcm","clk":"993169897","pt":1580537851767,"mc":[{"id":"1.168133543","rc":[{"batb":[[0,2.82,10.85],[1,2.8,75.63],[2,2.72,4]],"ltp":2.86,"tv":1101.53,"id":12636},{"batb":[[1,220,1.26],[2,170,4.13]],"ltp":280.0,"tv":1.54,"id":24270700}]}]}
{"op":"mcm","clk":"993170486","pt":1580537865085,"mc":[{"id":"1.168133543","rc":[{"batb":[[0,2.82,14.85],[2,2.68,20]],"ltp":2.86,"tv":1101.53,"id":12636}]}]}
{"op":"mcm","clk":"993170570","pt":1580537866482,"mc":[{"id":"1.168133543","rc":[{"batb":[[1,2.8,4.18]],"ltp":2.86,"tv":1101.53,"id":12636},{"batb":[[1,180,1.03],[2,170,3.21]],"ltp":280.0,"tv":1.54,"id":24270700}]}]}
{"op":"mcm","clk":"993170605","pt":1580537867360,"mc":[{"id":"1.168133543","rc":[{"batl":[[0,2.88,2]],"ltp":2.86,"tv":1101.53,"id":12636},{"batb":[[0,230,2.42]],"ltp":280.0,"tv":1.54,"id":24270700}]}]}
{"op":"mcm","clk":"993171062","pt":1580537877290,"mc":[{"id":"1.168133543","rc":[{"batb":[[1,140,1.97]],"ltp":580.0,"tv":6.13,"id":27606066}]}]}
{"op":"mcm","clk":"993171220","pt":1580537880857,"mc":[{"id":"1.168133543","rc":[{"batb":[[0,2.84,70.44],[1,2.82,14.85],[2,2.8,4.18]],"ltp":2.86,"tv":1101.53,"id":12636},{"batb":[[1,150,1.85]],"ltp":580.0,"tv":6.13,"id":27606066},{"batb":[[0,230,1.32],[1,220,1.26],[2,170,4.13]],"ltp":280.0,"tv":1.54,"id":24270700}]}]}
{"op":"mcm","clk":"993171573","pt":1580537888496,"mc":[{"id":"1.168133543","rc":[{"batb":[[0,2.84,74.44],[1,2.82,10.85]],"ltp":2.86,"tv":1101.53,"id":12636}]}]}
{"op":"mcm","clk":"993171877","pt":1580537894790,"mc":[{"id":"1.168133543","rc":[{"batb":[[1,160,1.61],[2,110,14.15]],"ltp":580.0,"tv":6.13,"id":27606066},{"batb":[[0,230,2.42],[1,180,1.03],[2,170,3.21]],"ltp":280.0,"tv":1.54,"id":24270700}]}]}
{"op":"mcm","clk":"993172457","pt":1580537909710,"mc":[{"id":"1.168133543","rc":[{"batb":[[1,170,1.52]],"ltp":580.0,"tv":6.13,"id":27606066},{"batb":[[0,230,1.32],[1,220,1.26],[2,170,4.13]],"ltp":280.0,"tv":1.54,"id":24270700}]}]}
{"op":"mcm","clk":"993173086","pt":1580537923520,"mc":[{"id":"1.168133543","rc":[{"batb":[[1,110,14.18],[2,100,16.8]],"ltp":580.0,"tv":6.13,"id":27606066},{"batb":[[1,180,1.03],[2,170,3.21]],"ltp":280.0,"tv":1.54,"id":24270700}]}]}
{"op":"mcm","clk":"993173131","pt":1580537924344,"mc":[{"id":"1.168133543","rc":[{"batb":[[1,180,1.44],[2,110,14.15]],"ltp":580.0,"tv":6.13,"id":27606066},{"batb":[[0,230,2.42]],"ltp":280.0,"tv":1.54,"id":24270700}]}]}
{"op":"mcm","clk":"993173495","pt":1580537931464,"mc":[{"id":"1.168133543","rc":[{"batb":[[1,180,1.55],[2,110,14.02]],"ltp":580.0,"tv":6.13,"id":27606066}]}]}
{"op":"mcm","clk":"993173797","pt":1580537937446,"mc":[{"id":"1.168133543","rc":[{"batb":[[1,110,14.16],[2,100,16.8]],"ltp":580.0,"tv":6.13,"id":27606066},{"batb":[[0,230,1.32]],"ltp":280.0,"tv":1.54,"id":24270700}]}]}
{"op":"mcm","clk":"993173804","pt":1580537937652,"mc":[{"id":"1.168133543","rc":[{"batb":[[1,190,1.47],[2,110,14.02]],"ltp":580.0,"tv":6.13,"id":27606066},{"batb":[[1,220,1.26],[2,170,4.13]],"ltp":280.0,"tv":1.54,"id":24270700}]}]}
{"op":"mcm","clk":"993174497","pt":1580537952569,"mc":[{"id":"1.168133543","rc":[{"batb":[[1,110,14.16],[2,100,16.8]],"ltp":580.0,"tv":6.13,"id":27606066},{"batb":[[1,180,1.03],[2,170,3.21]],"ltp":280.0,"tv":1.54,"id":24270700}]}]}
{"op":"mcm","clk":"993174520","pt":1580537952980,"mc":[{"id":"1.168133543","rc":[{"batb":[[1,120,2.25],[2,110,14.02]],"ltp":580.0,"tv":6.13,"id":27606066},{"batb":[[0,230,2.42]],"ltp":280.0,"tv":1.54,"id":24270700}]}]}
{"op":"mcm","clk":"993175154","pt":1580537966697,"mc":[{"id":"1.168133543","rc":[{"batb":[[1,120,2.58]],"ltp":580.0,"tv":6.13,"id":27606066},{"batb":[[0,230,1.32],[1,220,1.26],[2,170,4.13]],"ltp":280.0,"tv":1.54,"id":24270700}]}]}
{"op":"mcm","clk":"993175763","pt":1580537980492,"mc":[{"id":"1.168133543","rc":[{"batb":[[1,110,14.49],[2,100,16.8]],"ltp":580.0,"tv":6.13,"id":27606066},{"batb":[[1,180,1.03],[2,170,3.21]],"ltp":280.0,"tv":1.54,"id":24270700}]}]}
{"op":"mcm","clk":"993175768","pt":1580537980594,"mc":[{"id":"1.168133543","rc":[{"batb":[[1,130,2.42],[2,110,14.02]],"ltp":580.0,"tv":6.13,"id":27606066},{"batb":[[0,230,2.42]],"ltp":280.0,"tv":1.54,"id":24270700}]}]}
{"op":"mcm","clk":"993175917","pt":1580537984406,"mc":[{"id":"1.168133543","rc":[{"batb":[[1,130,2.45]],"ltp":580.0,"tv":6.13,"id":27606066}]}]}
{"op":"mcm","clk":"993176407","pt":1580537995498,"mc":[{"id":"1.168133543","rc":[{"batb":[[1,110,14.52],[2,100,16.8]],"ltp":580.0,"tv":6.13,"id":27606066},{"batb":[[0,230,1.32]],"ltp":280.0,"tv":1.54,"id":24270700}]}]}
{"op":"mcm","clk":"993176415","pt":1580537995602,"mc":[{"id":"1.168133543","rc":[{"batb":[[1,140,1.98],[2,110,14.35]],"ltp":580.0,"tv":6.13,"id":27606066},{"batb":[[1,220,1.26],[2,170,4.13]],"ltp":280.0,"tv":1.54,"id":24270700}]}]}
{"op":"mcm","clk":"993176838","pt":1580538005205,"mc":[{"id":"1.168133543","rc":[{"batb":[[0,2.86,6.02],[1,2.84,74.44],[2,2.82,10.85]],"ltp":2.86,"tv":1101.53,"id":12636}]}]}
{"op":"mcm","clk":"993176885","pt":1580538006441,"mc":[{"id":"1.168133543","rc":[{"batb":[[2,110,14.02]],"ltp":580.0,"tv":6.13,"id":27606066}]}]}
{"op":"mcm","clk":"993177045","pt":1580538009737,"mc":[{"id":"1.168133543","rc":[{"batb":[[1,2.84,4]],"ltp":2.86,"tv":1101.53,"id":12636},{"batb":[[1,150,1.72],[2,110,14.16]],"ltp":580.0,"tv":6.13,"id":27606066},{"batb":[[0,230,2.42],[1,180,1.03],[2,170,3.21]],"ltp":280.0,"tv":1.54,"id":24270700}]}]}
{"op":"mcm","clk":"993177506","pt":1580538020362,"mc":[{"id":"1.168133543","rc":[{"batb":[[0,2.86,10.02],[1,2.82,10.85],[2,2.8,4.18]],"ltp":2.86,"tv":1101.53,"id":12636}]}]}
{"op":"mcm","clk":"993177642","pt":1580538023556,"mc":[{"id":"1.168133543","rc":[{"batb":[[1,110,14.19],[2,100,16.8]],"ltp":580.0,"tv":6.13,"id":27606066},{"batb":[[0,230,1.32]],"ltp":280.0,"tv":1.54,"id":24270700}]}]}
{"op":"mcm","clk":"993177647","pt":1580538023658,"mc":[{"id":"1.168133543","rc":[{"batb":[[1,160,1.61],[2,110,14.16]],"ltp":580.0,"tv":6.13,"id":27606066},{"batb":[[1,220,1.26],[2,170,4.13]],"ltp":280.0,"tv":1.54,"id":24270700}]}]}
{"op":"mcm","clk":"993177860","pt":1580538028364,"mc":[{"id":"1.168133543","rc":[{"batb":[[0,2.86,6.02],[1,2.84,4],[2,2.82,10.85]],"ltp":2.86,"tv":1101.53,"id":12636}]}]}
{"op":"mcm","clk":"993178337","pt":1580538038385,"mc":[{"id":"1.168133543","rc":[{"batb":[[2,110,14.02]],"ltp":580.0,"tv":6.13,"id":27606066}]}]}
{"op":"mcm","clk":"993178346","pt":1580538038694,"mc":[{"id":"1.168133543","rc":[{"batb":[[1,170,1.52]],"ltp":580.0,"tv":6.13,"id":27606066},{"batb":[[0,230,2.42],[1,180,1.03],[2,170,3.21]],"ltp":280.0,"tv":1.54,"id":24270700}]}]}
{"op":"mcm","clk":"993178914","pt":1580538052806,"mc":[{"id":"1.168133543","rc":[{"batb":[[0,2.86,10.02],[1,2.82,10.85],[2,2.8,4.18]],"ltp":2.86,"tv":1101.53,"id":12636},{"batb":[[1,180,1.44]],"ltp":580.0,"tv":6.13,"id":27606066},{"batb":[[0,230,1.32],[1,220,1.26],[2,170,4.13]],"ltp":280.0,"tv":1.54,"id":24270700}]}]}
{"op":"mcm","clk":"993179436","pt":1580538066482,"mc":[{"id":"1.168133543","rc":[{"batb":[[1,110,14.05],[2,100,16.8]],"ltp":580.0,"tv":6.13,"id":27606066},{"batb":[[1,180,1.03],[2,170,3.21]],"ltp":280.0,"tv":1.54,"id":24270700}]}]}
{"op":"mcm","clk":"993179452","pt":1580538066892,"mc":[{"id":"1.168133543","rc":[{"batb":[[1,120,2.14],[2,110,14.02]],"ltp":580.0,"tv":6.13,"id":27606066},{"batb":[[0,230,2.42]],"ltp":280.0,"tv":1.54,"id":24270700}]}]}
{"op":"mcm","clk":"993179610","pt":1580538070500,"mc":[{"id":"1.168133543","rc":[{"batb":[[1,120,2.47]],"ltp":580.0,"tv":6.13,"id":27606066}]}]}
{"op":"mcm","clk":"993179839","pt":1580538076485,"mc":[{"id":"1.168133543","rc":[{"batb":[[0,2.86,6.02],[1,2.84,4],[2,2.82,10.85]],"ltp":2.86,"tv":1101.53,"id":12636}]}]}
{"op":"mcm","clk":"993180012","pt":1580538081497,"mc":[{"id":"1.168133543","rc":[{"batb":[[1,110,14.38],[2,100,16.8]],"ltp":580.0,"tv":6.13,"id":27606066},{"batb":[[0,230,1.32]],"ltp":280.0,"tv":1.54,"id":24270700}]}]}
{"op":"mcm","clk":"993180016","pt":1580538081596,"mc":[{"id":"1.168133543","rc":[{"batb":[[1,130,2.31],[2,110,14.02]],"ltp":580.0,"tv":6.13,"id":27606066},{"batb":[[1,220,1.26],[2,170,4.13]],"ltp":280.0,"tv":1.54,"id":24270700}]}]}
{"op":"mcm","clk":"993180600","pt":1580538095548,"mc":[{"id":"1.168133543","rc":[{"batb":[[1,110,14.38],[2,100,16.8]],"ltp":580.0,"tv":6.13,"id":27606066},{"batb":[[1,180,1.03],[2,170,3.21]],"ltp":280.0,"tv":1.54,"id":24270700}]}]}
{"op":"mcm","clk":"993180628","pt":1580538096016,"mc":[{"id":"1.168133543","rc":[{"batb":[[1,140,1.84],[2,110,14.35]],"ltp":580.0,"tv":6.13,"id":27606066},{"batb":[[0,230,2.42]],"ltp":280.0,"tv":1.54,"id":24270700}]}]}
{"op":"mcm","clk":"993181125","pt":1580538107953,"mc":[{"id":"1.168133543","rc":[{"batb":[[0,2.86,10.02],[1,2.82,10.85],[2,2.8,4.18]],"ltp":2.86,"tv":1101.53,"id":12636}]}]}
{"op":"mcm","clk":"993181189","pt":1580538109560,"mc":[{"id":"1.168133543","rc":[{"batb":[[0,230,1.32],[1,220,1.26],[2,170,4.13]],"ltp":280.0,"tv":1.54,"id":24270700}]}]}
{"op":"mcm","clk":"993181279","pt":1580538111775,"mc":[{"id":"1.168133543","rc":[{"batb":[[2,110,14.02]],"ltp":580.0,"tv":6.13,"id":27606066}]}]}
{"op":"mcm","clk":"993181784","pt":1580538123197,"mc":[{"id":"1.168133543","rc":[{"batb":[[0,2.86,6.02],[1,2.84,4],[2,2.82,10.85]],"ltp":2.86,"tv":1101.53,"id":12636}]}]}
{"op":"mcm","clk":"993181843","pt":1580538124486,"mc":[{"id":"1.168133543","rc":[{"batb":[[1,180,1.03],[2,170,3.21]],"ltp":280.0,"tv":1.54,"id":24270700}]}]}
{"op":"mcm","clk":"993181847","pt":1580538124587,"mc":[{"id":"1.168133543","rc":[{"batb":[[0,230,2.42]],"ltp":280.0,"tv":1.54,"id":24270700}]}]}
{"op":"mcm","clk":"993182322","pt":1580538135598,"mc":[{"id":"1.168133543","rc":[{"batl":[[0,2.38,2.65],[1,2.42,5.5],[2,2.46,21]],"ltp":2.34,"tv":2477.61,"id":10107355}]}]}
{"op":"mcm","clk":"993182406","pt":1580538138478,"mc":[{"id":"1.168133543","rc":[{"batb":[[0,230,1.32]],"ltp":280.0,"tv":1.54,"id":24270700}]}]}
{"op":"mcm","clk":"993182410","pt":1580538138580,"mc":[{"id":"1.168133543","rc":[{"batb":[[1,220,1.26],[2,170,4.13]],"ltp":280.0,"tv":1.54,"id":24270700}]}]}
{"op":"mcm","clk":"993182626","pt":1580538144604,"mc":[{"id":"1.168133543","rc":[{"batb":[[1,140,1.97]],"ltp":580.0,"tv":6.13,"id":27606066}]}]}
{"op":"mcm","clk":"993192745","pt":1580538152521,"mc":[{"id":"1.168133543","rc":[{"batb":[[1,110,14.18],[2,100,16.8]],"ltp":580.0,"tv":6.13,"id":27606066},{"batb":[[1,180,1.03],[2,170,3.21]],"ltp":280.0,"tv":1.54,"id":24270700}]}]}
{"op":"mcm","clk":"993192761","pt":1580538152882,"mc":[{"id":"1.168133543","rc":[{"batl":[[1,2.4,4],[2,2.42,5.5]],"ltp":2.34,"tv":2477.61,"id":10107355},{"batb":[[1,150,1.85],[2,110,14.02]],"ltp":580.0,"tv":6.13,"id":27606066},{"batb":[[0,230,2.42]],"ltp":280.0,"tv":1.54,"id":24270700}]}]}
{"op":"mcm","clk":"993192819","pt":1580538154998,"mc":[{"id":"1.168133543","rc":[{"batl":[[0,2.38,2.01],[1,2.4,4.64]],"ltp":2.34,"tv":2477.61,"id":10107355}]}]}
{"op":"mcm","clk":"993193135","pt":1580538163320,"mc":[{"id":"1.168133543","rc":[{"batl":[[0,2.38,2.65],[1,2.4,4]],"ltp":2.34,"tv":2477.61,"id":10107355}]}]}
{"op":"mcm","clk":"993193330","pt":1580538167528,"mc":[{"id":"1.168133543","rc":[{"batb":[[1,160,1.61],[2,110,14.15]],"ltp":580.0,"tv":6.13,"id":27606066},{"batb":[[0,230,1.32],[1,220,1.26],[2,170,4.13]],"ltp":280.0,"tv":1.54,"id":24270700}]}]}
{"op":"mcm","clk":"993194023","pt":1580538181547,"mc":[{"id":"1.168133543","rc":[{"batl":[[1,2.9,1.03]],"ltp":2.86,"tv":1101.53,"id":12636},{"batb":[[1,110,14.18],[2,100,16.8]],"ltp":580.0,"tv":6.13,"id":27606066},{"batb":[[1,180,1.03],[2,170,3.21]],"ltp":280.0,"tv":1.54,"id":24270700}]}]}
{"op":"mcm","clk":"993194031","pt":1580538181649,"mc":[{"id":"1.168133543","rc":[{"batb":[[1,170,1.52],[2,110,14.15]],"ltp":580.0,"tv":6.13,"id":27606066},{"batb":[[0,230,2.42]],"ltp":280.0,"tv":1.54,"id":24270700}]}]}
{"op":"mcm","clk":"993194580","pt":1580538195527,"mc":[{"id":"1.168133543","rc":[{"batb":[[1,2.82,10.85],[2,2.8,4.18]],"ltp":2.86,"tv":1101.53,"id":12636},{"batb":[[1,110,14.18],[2,100,16.8]],"ltp":580.0,"tv":6.13,"id":27606066},{"batb":[[0,230,1.32]],"ltp":280.0,"tv":1.54,"id":24270700}]}]}
{"op":"mcm","clk":"993194584","pt":1580538195632,"mc":[{"id":"1.168133543","rc":[{"batb":[[0,2.86,10.02]],"ltp":2.86,"tv":1101.53,"id":12636},{"batb":[[1,180,1.44],[2,110,14.15]],"ltp":580.0,"tv":6.13,"id":27606066},{"batb":[[1,220,1.26],[2,170,4.13]],"ltp":280.0,"tv":1.54,"id":24270700}]}]}
{"op":"mcm","clk":"993194667","pt":1580538197940,"mc":[{"id":"1.168133543","rc":[{"batb":[[2,110,14.02]],"ltp":580.0,"tv":6.13,"id":27606066}]}]}
{"op":"mcm","clk":"993195135","pt":1580538209276,"mc":[{"id":"1.168133543","rc":[{"batl":[[0,2.88,4]],"ltp":2.86,"tv":1101.53,"id":12636},{"batl":[[0,2.34,2],[1,2.38,2.65],[2,2.4,4]],"ltp":2.34,"tv":2477.61,"id":10107355}]}]}
{"op":"mcm","clk":"993195187","pt":1580538210568,"mc":[{"id":"1.168133543","rc":[{"trd":[[2.88,173.76]],"batb":[[0,2.88,65.47],[1,2.86,10.02],[2,2.82,10.85]],"batl":[[0,2.9,1.03],[1,2.92,41.07],[2,2.94,58.02]],"ltp":2.88,"tv":1109.52,"id":12636},{"batb":[[1,110,14.05],[2,100,16.8]],"ltp":580.0,"tv":6.13,"id":27606066},{"batb":[[1,180,1.03],[2,170,3.21]],"ltp":280.0,"tv":1.54,"id":24270700}],"tv":4380.38}]}
{"op":"mcm","clk":"993195221","pt":1580538211382,"mc":[{"id":"1.168133543","rc":[{"batb":[[1,120,2.14],[2,110,14.02]],"ltp":580.0,"tv":6.13,"id":27606066},{"batb":[[0,230,2.42]],"ltp":280.0,"tv":1.54,"id":24270700}]}]}
{"op":"mcm","clk":"993195374","pt":1580538214369,"mc":[{"id":"1.168133543","rc":[{"batb":[[2,2.82,12.85]],"ltp":2.88,"tv":1109.52,"id":12636},{"batb":[[1,120,2.47]],"ltp":580.0,"tv":6.13,"id":27606066}]}]}
{"op":"mcm","clk":"993195634","pt":1580538221464,"mc":[{"id":"1.168133543","rc":[{"batl":[[2,2.42,5.5]],"ltp":2.34,"tv":2477.61,"id":10107355}]}]}
{"op":"mcm","clk":"993195735","pt":1580538224079,"mc":[{"id":"1.168133543","rc":[{"batl":[[0,2.9,3.03]],"ltp":2.88,"tv":1109.52,"id":12636}]}]}
{"op":"mcm","clk":"993195781","pt":1580538225002,"mc":[{"id":"1.168133543","rc":[{"batb":[[0,2.86,10.02],[1,2.82,12.85],[2,2.8,4.18]],"ltp":2.88,"tv":1109.52,"id":12636},{"batb":[[1,130,2.31]],"ltp":580.0,"tv":6.13,"id":27606066},{"batb":[[0,230,1.32],[1,220,1.26],[2,170,4.13]],"ltp":280.0,"tv":1.54,"id":24270700}]}]}
{"op":"mcm","clk":"993195900","pt":1580538227383,"mc":[{"id":"1.168133543","rc":[{"batl":[[0,2.9,17.03]],"ltp":2.88,"tv":1109.52,"id":12636}]}]}
{"op":"mcm","clk":"993195944","pt":1580538228302,"mc":[{"id":"1.168133543","rc":[{"batl":[[0,2.34,2.64],[1,2.38,2.01]],"ltp":2.34,"tv":2477.61,"id":10107355}]}]}
{"op":"mcm","clk":"993196280","pt":1580538236107,"mc":[{"id":"1.168133543","rc":[{"batb":[[0,2.86,6.02],[1,2.84,4],[2,2.82,12.85]],"ltp":2.88,"tv":1109.52,"id":12636}]}]}
{"op":"mcm","clk":"993196590","pt":1580538244322,"mc":[{"id":"1.168133543","rc":[{"batb":[[0,2.32,40.78]],"ltp":2.34,"tv":2477.61,"id":10107355},{"batb":[[1,140,1.84],[2,110,14.35]],"ltp":580.0,"tv":6.13,"id":27606066},{"batb":[[0,230,2.42],[1,180,1.03],[2,170,3.21]],"ltp":280.0,"tv":1.54,"id":24270700}]}]}
{"op":"mcm","clk":"993196913","pt":1580538253902,"mc":[{"id":"1.168133543","rc":[{"batb":[[2,110,14.02]],"ltp":580.0,"tv":6.13,"id":27606066}]}]}
{"op":"mcm","clk":"993197050","pt":1580538257539,"mc":[{"id":"1.168133543","rc":[{"batb":[[0,2.32,10.89]],"ltp":2.34,"tv":2477.61,"id":10107355},{"batb":[[0,230,1.32]],"ltp":280.0,"tv":1.54,"id":24270700}]}]}
{"op":"mcm","clk":"993197066","pt":1580538257800,"mc":[{"id":"1.168133543","rc":[{"batb":[[1,220,1.26],[2,170,4.13]],"ltp":280.0,"tv":1.54,"id":24270700}]}]}
{"op":"mcm","clk":"993197627","pt":1580538272533,"mc":[{"id":"1.168133543","rc":[{"batl":[[0,2.88,2],[1,2.9,17.03],[2,2.92,41.07]],"ltp":2.88,"tv":1109.52,"id":12636},{"batb":[[0,2.32,40.78]],"ltp":2.34,"tv":2477.61,"id":10107355},{"batb":[[1,180,1.03],[2,170,3.21]],"ltp":280.0,"tv":1.54,"id":24270700}]}]}
{"op":"mcm","clk":"993197634","pt":1580538272633,"mc":[{"id":"1.168133543","rc":[{"batb":[[0,230,2.42]],"ltp":280.0,"tv":1.54,"id":24270700}]}]}
{"op":"mcm","clk":"993197763","pt":1580538275814,"mc":[{"id":"1.168133543","rc":[{"batb":[[0,2.86,10.02],[1,2.82,12.85],[2,2.8,4.18]],"ltp":2.88,"tv":1109.52,"id":12636}]}]}
{"op":"mcm","clk":"993198148","pt":1580538286566,"mc":[{"id":"1.168133543","rc":[{"batb":[[0,2.32,10.89]],"ltp":2.34,"tv":2477.61,"id":10107355},{"batb":[[0,230,1.32]],"ltp":280.0,"tv":1.54,"id":24270700}]}]}
{"op":"mcm","clk":"993198178","pt":1580538287342,"mc":[{"id":"1.168133543","rc":[{"batb":[[1,220,1.26],[2,170,4.13]],"ltp":280.0,"tv":1.54,"id":24270700}]}]}
{"op":"mcm","clk":"993198354","pt":1580538291149,"mc":[{"id":"1.168133543","rc":[{"batl":[[2,2.4,4]],"ltp":2.34,"tv":2477.61,"id":10107355}]}]}
{"op":"mcm","clk":"993198791","pt":1580538300569,"mc":[{"id":"1.168133543","rc":[{"batb":[[1,180,1.03],[2,170,3.21]],"ltp":280.0,"tv":1.54,"id":24270700}]}]}
{"op":"mcm","clk":"993198841","pt":1580538301548,"mc":[{"id":"1.168133543","rc":[{"batb":[[0,2.32,40.78]],"ltp":2.34,"tv":2477.61,"id":10107355},{"batb":[[0,230,2.42]],"ltp":280.0,"tv":1.54,"id":24270700}]}]}
{"op":"mcm","clk":"993198980","pt":1580538304941,"mc":[{"id":"1.168133543","rc":[{"batb":[[1,140,1.97]],"ltp":580.0,"tv":6.13,"id":27606066}]}]}
{"op":"mcm","clk":"993199168","pt":1580538309263,"mc":[{"id":"1.168133543","rc":[{"batl":[[2,2.42,5.5]],"ltp":2.34,"tv":2477.61,"id":10107355}]}]}
{"op":"mcm","clk":"993199429","pt":1580538315478,"mc":[{"id":"1.168133543","rc":[{"batb":[[0,2.32,10.89]],"ltp":2.34,"tv":2477.61,"id":10107355},{"batb":[[1,110,14.18],[2,100,16.8]],"ltp":580.0,"tv":6.13,"id":27606066},{"batb":[[0,230,1.32]],"ltp":280.0,"tv":1.54,"id":24270700}]}]}
{"op":"mcm","clk":"993199442","pt":1580538315785,"mc":[{"id":"1.168133543","rc":[{"batb":[[1,150,1.85],[2,110,14.02]],"ltp":580.0,"tv":6.13,"id":27606066},{"batb":[[1,220,1.26],[2,170,4.13]],"ltp":280.0,"tv":1.54,"id":24270700}]}]}
{"op":"mcm","clk":"993199494","pt":1580538317280,"mc":[{"id":"1.168133543","rc":[{"batb":[[0,2.86,6.02],[1,2.84,4],[2,2.82,12.85]],"ltp":2.88,"tv":1109.52,"id":12636}]}]}
{"op":"mcm","clk":"993200053","pt":1580538329516,"mc":[{"id":"1.168133543","rc":[{"batb":[[1,110,14.18],[2,100,16.8]],"ltp":580.0,"tv":6.13,"id":27606066},{"batb":[[1,180,1.03],[2,170,3.21]],"ltp":280.0,"tv":1.54,"id":24270700}]}]}
{"op":"mcm","clk":"993200061","pt":1580538329721,"mc":[{"id":"1.168133543","rc":[{"batb":[[0,2.32,40.78]],"ltp":2.34,"tv":2477.61,"id":10107355},{"batb":[[1,160,1.61],[2,110,14.15]],"ltp":580.0,"tv":6.13,"id":27606066},{"batb":[[0,230,2.42]],"ltp":280.0,"tv":1.54,"id":24270700}]}]}
{"op":"mcm","clk":"993200718","pt":1580538343506,"mc":[{"id":"1.168133543","rc":[{"batb":[[0,2.32,10.89]],"ltp":2.34,"tv":2477.61,"id":10107355},{"batb":[[1,110,14.18],[2,100,16.8]],"ltp":580.0,"tv":6.13,"id":27606066},{"batb":[[0,230,1.32]],"ltp":280.0,"tv":1.54,"id":24270700}]}]}
{"op":"mcm","clk":"993200721","pt":1580538343606,"mc":[{"id":"1.168133543","rc":[{"batb":[[1,170,1.52],[2,110,14.15]],"ltp":580.0,"tv":6.13,"id":27606066},{"batb":[[1,220,1.26],[2,170,4.13]],"ltp":280.0,"tv":1.54,"id":24270700}]}]}
{"op":"mcm","clk":"993200934","pt":1580538348404,"mc":[{"id":"1.168133543","rc":[{"trd":[[2.88,179.82]],"batl":[[0,2.9,16],[1,2.92,41.07],[2,2.94,58.02]],"ltp":2.88,"tv":1115.58,"id":12636}],"tv":4386.44}]}
{"op":"mcm","clk":"993200990","pt":1580538349428,"mc":[{"id":"1.168133543","rc":[{"trd":[[2.9,153.34]],"batb":[[2,2.82,14.85]],"batl":[[0,2.88,5],[1,2.9,15.22],[2,2.92,41.07]],"ltp":2.9,"tv":1117.14,"id":12636},{"trd":[[60,16.64]],"batl":[[0,510,9.7]],"ltp":60.0,"tv":30.79,"id":7226819},{"trd":[[10,26.36]],"batl":[[0,10,53.14]],"ltp":10.0,"tv":359.51,"id":10163711},{"trd":[[2.34,337.42],[2.38,140.47]],"batb":[[1,2.26,23.83],[2,2.24,5.28]],"batl":[[0,2.42,5.5],[1,2.46,21],[2,2.48,50]],"ltp":2.38,"tv":2486.91,"id":10107355},{"trd":[[9.8,10.2],[10,74.88]],"batl":[[0,10,20.37]],"ltp":10.0,"tv":341.33,"id":22121325},{"trd":[[160,1.98]],"batl":[[0,160,3.01]],"ltp":160.0,"tv":7.34,"id":26548208}],"tv":4402.18}]}
{"op":"mcm","clk":"993201242","pt":1580538354230,"mc":[{"id":"1.168133543","rc":[{"trd":[[2.32,62.82]],"batb":[[0,2.26,23.83],[1,2.24,5.28],[2,2.22,6]],"batl":[[0,2.32,51.77],[1,2.42,5.5],[2,2.46,21]],"ltp":2.32,"tv":2508.69,"id":10107355}],"tv":4423.96}]}
{"op":"mcm","clk":"993201302","pt":1580538355519,"mc":[{"id":"1.168133543","rc":[{"trd":[[2.88,189.82]],"batb":[[0,2.88,5],[1,2.86,6.02],[2,2.84,4]],"batl":[[0,2.9,15.22],[1,2.92,41.07],[2,2.94,58.02]],"ltp":2.88,"tv":1127.14,"id":12636},{"batb":[[0,65,1.03],[1,60,1.33],[2,55,1.07]],"ltp":65.0,"tv":20.68,"id":22308007},{"trd":[[60,17.6]],"batl":[[0,510,9.22]],"ltp":60.0,"tv":31.75,"id":7226819},{"batb":[[0,9.6,3],[1,9.4,4.27],[2,9.2,5.64]],"ltp":10.0,"tv":359.51,"id":10163711},{"trd":[[2.32,87.64]],"batl":[[0,2.32,39.36]],"ltp":2.32,"tv":2533.51,"id":10107355},{"trd":[[10,80.64]],"batl":[[0,10,17.49]],"ltp":10.0,"tv":347.09,"id":22121325},{"batb":[[0,85,3.38]],"ltp":160.0,"tv":7.34,"id":26548208},{"batb":[[0,220,1.15]],"ltp":580.0,"tv":6.13,"id":27606066},{"batb":[[0,230,1.43]],"ltp":280.0,"tv":1.54,"id":24270700},{"batb":[[0,160,1.56]],"ltp":160.0,"tv":19.01,"id":13306150}],"tv":4465.5}]}
{"op":"mcm","clk":"993201335","pt":1580538356235,"mc":[{"id":"1.168133543","rc":[{"trd":[[2.9,155.98]],"batl":[[0,2.9,13.9]],"ltp":2.9,"tv":1129.78,"id":12636},{"trd":[[10,30]],"batl":[[0,10,51.32]],"ltp":10.0,"tv":363.15,"id":10163711},{"trd":[[2.32,103.34]],"batb":[[0,2.28,12.15],[1,2.26,23.83],[2,2.24,5.28]],"batl":[[0,2.32,31.51]],"ltp":2.32,"tv":2549.21,"id":10107355},{"trd":[[10,84.28]],"batb":[[0,8.8,2.12],[2,8.4,6.5]],"batl":[[0,10,15.67]],"ltp":10.0,"tv":350.73,"id":22121325},{"trd":[[160,2.18]],"batl":[[0,160,2.91]],"ltp":160.0,"tv":7.54,"id":26548208}],"tv":4491.32}]}
{"op":"mcm","clk":"993201433","pt":1580538358537,"mc":[{"id":"1.168133543","rc":[{"batb":[[0,2.88,70.47]],"ltp":2.9,"tv":1129.78,"id":12636},{"batb":[[1,110,14.05],[2,100,16.8]],"ltp":580.0,"tv":6.13,"id":27606066},{"batb":[[1,180,1.03],[2,170,3.21]],"ltp":280.0,"tv":1.54,"id":24270700}]}]}
{"op":"mcm","clk":"993201466","pt":1580538359311,"mc":[{"id":"1.168133543","rc":[{"batl":[[0,510,9.42]],"ltp":60.0,"tv":31.75,"id":7226819},{"batb":[[1,180,1.44],[2,110,14.02]],"ltp":580.0,"tv":6.13,"id":27606066},{"batb":[[0,230,2.53]],"ltp":280.0,"tv":1.54,"id":24270700}]}]}
{"op":"mcm","clk":"993201499","pt":1580538360238,"mc":[{"id":"1.168133543","rc":[{"batb":[[2,2.84,6]],"ltp":2.9,"tv":1129.78,"id":12636}]}]}
{"op":"mcm","clk":"993201599","pt":1580538362452,"mc":[{"id":"1.168133543","rc":[{"trd":[[2.26,142.04],[2.28,265.51]],"batb":[[0,2.26,4.46],[1,2.24,5.28],[2,2.22,6]],"batl":[[0,2.42,5.5],[1,2.46,21],[2,2.48,50]],"ltp":2.26,"tv":2612.23,"id":10107355}],"tv":4554.34}]}
{"op":"mcm","clk":"993201635","pt":1580538363336,"mc":[{"id":"1.168133543","rc":[{"batb":[[2,2.22,14.77]],"ltp":2.26,"tv":2612.23,"id":10107355}]}]}
{"op":"mcm","clk":"993201705","pt":1580538364832,"mc":[{"id":"1.168133543","rc":[{"batb":[[2,2.22,6]],"ltp":2.26,"tv":2612.23,"id":10107355}]}]}
{"op":"mcm","clk":"993202023","pt":1580538372556,"mc":[{"id":"1.168133543","rc":[{"batb":[[0,2.88,5]],"ltp":2.9,"tv":1129.78,"id":12636},{"batb":[[1,110,14.05],[2,100,16.8]],"ltp":580.0,"tv":6.13,"id":27606066}]}]}
{"op":"mcm","clk":"993202033","pt":1580538372762,"mc":[{"id":"1.168133543","rc":[{"batb":[[0,2.26,35.15]],"ltp":2.26,"tv":2612.23,"id":10107355},{"batb":[[1,190,1.36],[2,110,14.02]],"ltp":580.0,"tv":6.13,"id":27606066}]}]}
{"op":"mcm","clk":"993202169","pt":1580538376055,"mc":[{"id":"1.168133543","rc":[{"batb":[[0,8.8,3.93]],"ltp":10.0,"tv":350.73,"id":22121325}]}]}
{"op":"mcm","clk":"993202276","pt":1580538378966,"mc":[{"id":"1.168133543","rc":[{"batl":[[0,2.4,4],[1,2.42,5.5],[2,2.46,21]],"ltp":2.26,"tv":2612.23,"id":10107355}]}]}
{"op":"mcm","clk":"993202365","pt":1580538381388,"mc":[{"id":"1.168133543","rc":[{"batl":[[0,2.38,2],[1,2.4,4],[2,2.42,5.5]],"ltp":2.26,"tv":2612.23,"id":10107355}]}]}
{"op":"mcm","clk":"993202461","pt":1580538383861,"mc":[{"id":"1.168133543","rc":[{"batb":[[0,9.6,6.96]],"ltp":10.0,"tv":363.15,"id":10163711}]}]}
{"op":"mcm","clk":"993202572","pt":1580538386489,"mc":[{"id":"1.168133543","rc":[{"batb":[[0,2.26,4.46]],"ltp":2.26,"tv":2612.23,"id":10107355},{"batb":[[1,110,14.05],[2,100,16.8]],"ltp":580.0,"tv":6.13,"id":27606066}]}]}
{"op":"mcm","clk":"993202582","pt":1580538386697,"mc":[{"id":"1.168133543","rc":[{"batb":[[1,2.24,36.24]],"ltp":2.26,"tv":2612.23,"id":10107355},{"batb":[[1,120,2.14],[2,110,14.02]],"ltp":580.0,"tv":6.13,"id":27606066}]}]}
{"op":"mcm","clk":"993202693","pt":1580538389498,"mc":[{"id":"1.168133543","rc":[{"batl":[[0,2.38,4]],"ltp":2.26,"tv":2612.23,"id":10107355}]}]}
{"op":"mcm","clk":"993202713","pt":1580538389964,"mc":[{"id":"1.168133543","rc":[{"batb":[[0,2.88,9],[2,2.84,2]],"ltp":2.9,"tv":1129.78,"id":12636}]}]}
{"op":"mcm","clk":"993203002","pt":1580538397874,"mc":[{"id":"1.168133543","rc":[{"batb":[[1,120,2.47]],"ltp":580.0,"tv":6.13,"id":27606066}]}]}
{"op":"mcm","clk":"993203147","pt":1580538401497,"mc":[{"id":"1.168133543","rc":[{"batb":[[1,110,14.38],[2,100,16.8]],"ltp":580.0,"tv":6.13,"id":27606066}]}]}
{"op":"mcm","clk":"993203185","pt":1580538402482,"mc":[{"id":"1.168133543","rc":[{"batb":[[1,130,2.31],[2,110,14.02]],"ltp":580.0,"tv":6.13,"id":27606066}]}]}
{"op":"mcm","clk":"993203551","pt":1580538410985,"mc":[{"id":"1.168133543","rc":[{"batb":[[0,2.26,13.31]],"ltp":2.26,"tv":2612.23,"id":10107355}]}]}
{"op":"mcm","clk":"993203995","pt":1580538421018,"mc":[{"id":"1.168133543","rc":[{"batb":[[0,2.28,30.42],[1,2.26,13.31],[2,2.24,5.28]],"ltp":2.26,"tv":2612.23,"id":10107355},{"batb":[[1,140,1.84],[2,110,14.35]],"ltp":580.0,"tv":6.13,"id":27606066}]}]}
{"op":"mcm","clk":"993204555","pt":1580538434515,"mc":[{"id":"1.168133543","rc":[{"batb":[[1,150,1.72]],"ltp":580.0,"tv":6.13,"id":27606066}]}]}
{"op":"mcm","clk":"993204735","pt":1580538439039,"mc":[{"id":"1.168133543","rc":[{"batb":[[2,110,14.02]],"ltp":580.0,"tv":6.13,"id":27606066}]}]}
{"op":"mcm","clk":"993205161","pt":1580538448536,"mc":[{"id":"1.168133543","rc":[{"batb":[[1,160,1.61]],"ltp":580.0,"tv":6.13,"id":27606066}]}]}
{"op":"mcm","clk":"993205345","pt":1580538453426,"mc":[{"id":"1.168133543","rc":[{"batl":[[1,2.42,5.5],[2,2.46,21]],"ltp":2.26,"tv":2612.23,"id":10107355}]}]}
{"op":"mcm","clk":"993205758","pt":1580538463557,"mc":[{"id":"1.168133543","rc":[{"batl":[[0,2.38,2],[1,2.4,2],[2,2.42,5.5]],"ltp":2.26,"tv":2612.23,"id":10107355},{"batb":[[1,110,14.05],[2,100,16.8]],"ltp":580.0,"tv":6.13,"id":27606066}]}]}
{"op":"mcm","clk":"993205767","pt":1580538463658,"mc":[{"id":"1.168133543","rc":[{"batb":[[1,170,1.52],[2,110,14.02]],"ltp":580.0,"tv":6.13,"id":27606066}]}]}
{"op":"mcm","clk":"993205845","pt":1580538465359,"mc":[{"id":"1.168133543","rc":[{"batb":[[0,2.28,39.19],[1,2.26,4.46]],"ltp":2.26,"tv":2612.23,"id":10107355},{"batb":[[1,170,1.63]],"ltp":580.0,"tv":6.13,"id":27606066}]}]}
{"op":"mcm","clk":"993206096","pt":1580538471473,"mc":[{"id":"1.168133543","rc":[{"batl":[[0,2.38,4],[1,2.42,5.5],[2,2.46,21]],"ltp":2.26,"tv":2612.23,"id":10107355}]}]}
{"op":"mcm","clk":"993206283","pt":1580538477547,"mc":[{"id":"1.168133543","rc":[{"trd":[[2.9,183.76]],"batb":[[0,2.9,51.13],[1,2.88,9],[2,2.86,6.02]],"batl":[[0,2.92,41.07],[1,2.94,58.02],[2,2.96,50]],"ltp":2.9,"tv":1157.56,"id":12636},{"batb":[[1,110,14.16],[2,100,16.8]],"ltp":580.0,"tv":6.13,"id":27606066}],"tv":4582.13}]}
{"op":"mcm","clk":"993206297","pt":1580538477961,"mc":[{"id":"1.168133543","rc":[{"batb":[[1,2.88,23.1]],"ltp":2.9,"tv":1157.56,"id":12636},{"batb":[[1,180,1.55],[2,110,14.02]],"ltp":580.0,"tv":6.13,"id":27606066}]}]}
{"op":"mcm","clk":"993206343","pt":1580538479294,"mc":[{"id":"1.168133543","rc":[{"batl":[[0,2.38,2],[1,2.4,2],[2,2.42,5.5]],"ltp":2.26,"tv":2612.23,"id":10107355}]}]}
{"op":"mcm","clk":"993206613","pt":1580538486488,"mc":[{"id":"1.168133543","rc":[{"trd":[[9.6,22.37],[9.8,17.53]],"batb":[[0,9.6,3.59],[1,9.4,2.44]],"batl":[[0,9.8,17.59],[1,10,51.32],[2,17,1.88]],"ltp":9.6,"tv":373.41,"id":10163711}],"tv":4592.38}]}
{"op":"mcm","clk":"993206777","pt":1580538491490,"mc":[{"id":"1.168133543","rc":[{"batb":[[0,2.88,23.1],[1,2.86,6.02],[2,2.84,2]],"ltp":2.9,"tv":1157.56,"id":12636},{"batb":[[1,110,14.16],[2,100,16.8]],"ltp":580.0,"tv":6.13,"id":27606066}]}]}
{"op":"mcm","clk":"993206793","pt":1580538491907,"mc":[{"id":"1.168133543","rc":[{"batb":[[1,190,1.36],[2,110,14.13]],"ltp":580.0,"tv":6.13,"id":27606066}]}]}
{"op":"mcm","clk":"993206899","pt":1580538495000,"mc":[{"id":"1.168133543","rc":[{"batl":[[0,2.38,4],[1,2.42,5.5],[2,2.46,21]],"ltp":2.26,"tv":2612.23,"id":10107355}]}]}
{"op":"mcm","clk":"993207772","pt":1580538519501,"mc":[{"id":"1.168133543","rc":[{"batb":[[1,190,1.46],[2,110,14.02]],"ltp":580.0,"tv":6.13,"id":27606066}]}]}
{"op":"mcm","clk":"993207813","pt":1580538520531,"mc":[{"id":"1.168133543","rc":[{"batb":[[1,110,14.15],[2,100,16.8]],"ltp":580.0,"tv":6.13,"id":27606066}]}]}
{"op":"mcm","clk":"993207823","pt":1580538520737,"mc":[{"id":"1.168133543","rc":[{"batb":[[1,200,1.4],[2,110,14.02]],"ltp":580.0,"tv":6.13,"id":27606066}]}]}
{"op":"mcm","clk":"993208338","pt":1580538534541,"mc":[{"id":"1.168133543","rc":[{"batb":[[1,210,1.24],[2,110,14.12]],"ltp":580.0,"tv":6.13,"id":27606066}]}]}
{"op":"mcm","clk":"993208367","pt":1580538535362,"mc":[{"id":"1.168133543","rc":[{"batl":[[0,2.38,2],[1,2.4,2],[2,2.42,5.5]],"ltp":2.26,"tv":2612.23,"id":10107355}]}]}
{"op":"mcm","clk":"993208637","pt":1580538543381,"mc":[{"id":"1.168133543","rc":[{"batl":[[0,2.38,4],[1,2.42,5.5],[2,2.46,21]],"ltp":2.26,"tv":2612.23,"id":10107355}]}]}
{"op":"mcm","clk":"993208731","pt":1580538546080,"mc":[{"id":"1.168133543","rc":[{"batb":[[0,9,2.05],[1,8.8,3.79],[2,8.4,7.08]],"ltp":10.0,"tv":350.73,"id":22121325}]}]}
{"op":"mcm","clk":"993208884","pt":1580538550570,"mc":[{"id":"1.168133543","rc":[{"batb":[[1,120,2.24],[2,110,14.02]],"ltp":580.0,"tv":6.13,"id":27606066}]}]}
{"op":"mcm","clk":"993209191","pt":1580538559256,"mc":[{"id":"1.168133543","rc":[{"batl":[[0,2.38,2],[1,2.4,2],[2,2.42,5.5]],"ltp":2.26,"tv":2612.23,"id":10107355}]}]}
{"op":"mcm","clk":"993209278","pt":1580538561299,"mc":[{"id":"1.168133543","rc":[{"batb":[[1,120,2.57]],"ltp":580.0,"tv":6.13,"id":27606066}]}]}
{"op":"mcm","clk":"993209363","pt":1580538563491,"mc":[{"id":"1.168133543","rc":[{"batb":[[1,110,14.48],[2,100,16.8]],"ltp":580.0,"tv":6.13,"id":27606066}]}]}
{"op":"mcm","clk":"993209367","pt":1580538563592,"mc":[{"id":"1.168133543","rc":[{"batb":[[1,130,2.41],[2,110,14.02]],"ltp":580.0,"tv":6.13,"id":27606066}]}]}
{"op":"mcm","clk":"993209752","pt":1580538572931,"mc":[{"id":"1.168133543","rc":[{"batb":[[1,130,2.31]],"ltp":580.0,"tv":6.13,"id":27606066}]}]}
{"op":"mcm","clk":"993209844","pt":1580538575504,"mc":[{"id":"1.168133543","rc":[{"batl":[[1,2.42,5.5],[2,2.46,21]],"ltp":2.26,"tv":2612.23,"id":10107355}]}]}
{"op":"mcm","clk":"993209848","pt":1580538575606,"mc":[{"id":"1.168133543","rc":[{"batl":[[0,2.38,4]],"ltp":2.26,"tv":2612.23,"id":10107355}]}]}
{"op":"mcm","clk":"993209922","pt":1580538577512,"mc":[{"id":"1.168133543","rc":[{"batb":[[1,110,14.38],[2,100,16.8]],"ltp":580.0,"tv":6.13,"id":27606066}]}]}
{"op":"mcm","clk":"993209927","pt":1580538577613,"mc":[{"id":"1.168133543","rc":[{"batb":[[1,140,1.84],[2,110,14.35]],"ltp":580.0,"tv":6.13,"id":27606066}]}]}
{"op":"mcm","clk":"993210070","pt":1580538581623,"mc":[{"id":"1.168133543","rc":[{"batb":[[2,110,14.02]],"ltp":580.0,"tv":6.13,"id":27606066}]}]}
{"op":"mcm","clk":"993210170","pt":1580538584408,"mc":[{"id":"1.168133543","rc":[{"batl":[[0,2.38,2],[1,2.4,2],[2,2.42,5.5]],"ltp":2.26,"tv":2612.23,"id":10107355}]}]}
{"op":"mcm","clk":"993210475","pt":1580538592555,"mc":[{"id":"1.168133543","rc":[{"batl":[[0,2.38,4],[1,2.42,5.5],[2,2.46,21]],"ltp":2.26,"tv":2612.23,"id":10107355},{"batb":[[1,110,14.05],[2,100,16.8]],"ltp":580.0,"tv":6.13,"id":27606066}]}]}
{"op":"mcm","clk":"993210480","pt":1580538592608,"mc":[{"id":"1.168133543","rc":[{"batb":[[1,150,1.72],[2,110,14.02]],"ltp":580.0,"tv":6.13,"id":27606066}]}]}
{"op":"mcm","clk":"993210739","pt":1580538600044,"mc":[{"id":"1.168133543","rc":[{"batl":[[0,2.38,2],[1,2.4,2],[2,2.42,5.5]],"ltp":2.26,"tv":2612.23,"id":10107355}]}]}
{"op":"mcm","clk":"993211085","pt":1580538606525,"mc":[{"id":"1.168133543","rc":[{"batb":[[1,110,14.05],[2,100,16.8]],"ltp":580.0,"tv":6.13,"id":27606066}]}]}
{"op":"mcm","clk":"993211088","pt":1580538606632,"mc":[{"id":"1.168133543","rc":[{"batb":[[1,160,1.61],[2,110,14.02]],"ltp":580.0,"tv":6.13,"id":27606066}]}]}
{"op":"mcm","clk":"993211151","pt":1580538608069,"mc":[{"id":"1.168133543","rc":[{"batl":[[0,2.38,4],[1,2.42,5.5],[2,2.46,21]],"ltp":2.26,"tv":2612.23,"id":10107355}]}]}
{"op":"mcm","clk":"993211273","pt":1580538610451,"mc":[{"id":"1.168133543","rc":[{"batb":[[1,8.8,1.98]],"ltp":10.0,"tv":350.73,"id":22121325}]}]}
{"op":"mcm","clk":"993211486","pt":1580538616034,"mc":[{"id":"1.168133543","rc":[{"batl":[[0,2.38,2],[1,2.4,2],[2,2.42,5.5]],"ltp":2.26,"tv":2612.23,"id":10107355}]}]}
{"op":"mcm","clk":"993211657","pt":1580538620535,"mc":[{"id":"1.168133543","rc":[{"batb":[[1,110,14.05],[2,100,16.8]],"ltp":580.0,"tv":6.13,"id":27606066}]}]}
{"op":"mcm","clk":"993211663","pt":1580538620636,"mc":[{"id":"1.168133543","rc":[{"batb":[[1,170,1.52],[2,110,14.02]],"ltp":580.0,"tv":6.13,"id":27606066}]}]}
{"op":"mcm","clk":"993211957","pt":1580538624527,"mc":[{"id":"1.168133543","rc":[{"batl":[[0,2.38,4],[1,2.42,5.5],[2,2.46,21]],"ltp":2.26,"tv":2612.23,"id":10107355}]}]}
{"op":"mcm","clk":"993212422","pt":1580538633027,"mc":[{"id":"1.168133543","rc":[{"batb":[[0,2.9,5.94],[1,2.88,23.1]],"ltp":2.9,"tv":1157.56,"id":12636}]}]}
{"op":"mcm","clk":"993212520","pt":1580538635520,"mc":[{"id":"1.168133543","rc":[{"batb":[[1,110,14.05],[2,100,16.8]],"ltp":580.0,"tv":6.13,"id":27606066}]}]}
{"op":"mcm","clk":"993212540","pt":1580538636040,"mc":[{"id":"1.168133543","rc":[{"batb":[[1,180,1.44],[2,110,14.02]],"ltp":580.0,"tv":6.13,"id":27606066}]}]}
{"op":"mcm","clk":"993213107","pt":1580538648366,"mc":[{"id":"1.168133543","rc":[{"batl":[[0,2.38,2],[1,2.4,2],[2,2.42,5.5]],"ltp":2.26,"tv":2612.23,"id":10107355}]}]}
{"op":"mcm","clk":"993213149","pt":1580538649548,"mc":[{"id":"1.168133543","rc":[{"batb":[[1,190,1.36]],"ltp":580.0,"tv":6.13,"id":27606066}]}]}
{"op":"mcm","clk":"993213845","pt":1580538663478,"mc":[{"id":"1.168133543","rc":[{"batl":[[1,2.42,5.5],[2,2.46,21]],"ltp":2.26,"tv":2612.23,"id":10107355},{"batb":[[1,110,14.05],[2,100,16.8]],"ltp":580.0,"tv":6.13,"id":27606066}]}]}
{"op":"mcm","clk":"993213876","pt":1580538663991,"mc":[{"id":"1.168133543","rc":[{"batb":[[0,2.9,9.94],[1,2.88,19.1]],"ltp":2.9,"tv":1157.56,"id":12636},{"batl":[[0,2.38,4]],"ltp":2.26,"tv":2612.23,"id":10107355},{"batb":[[1,120,2.14],[2,110,14.02]],"ltp":580.0,"tv":6.13,"id":27606066}]}]}
{"op":"mcm","clk":"993213948","pt":1580538665179,"mc":[{"id":"1.168133543","rc":[{"batb":[[1,120,2.47]],"ltp":580.0,"tv":6.13,"id":27606066}]}]}
{"op":"mcm","clk":"993214700","pt":1580538678473,"mc":[{"id":"1.168133543","rc":[{"batb":[[1,110,14.38],[2,100,16.8]],"ltp":580.0,"tv":6.13,"id":27606066}]}]}
{"op":"mcm","clk":"993214705","pt":1580538678575,"mc":[{"id":"1.168133543","rc":[{"batb":[[1,130,2.31],[2,110,14.02]],"ltp":580.0,"tv":6.13,"id":27606066}]}]}
{"op":"mcm","clk":"993214774","pt":1580538680477,"mc":[{"id":"1.168133543","rc":[{"batl":[[0,2.38,2]],"ltp":2.26,"tv":2612.23,"id":10107355}]}]}
{"op":"mcm","clk":"993214778","pt":1580538680581,"mc":[{"id":"1.168133543","rc":[{"batl":[[1,2.4,2],[2,2.42,5.5]],"ltp":2.26,"tv":2612.23,"id":10107355},{"batb":[[1,130,2.45]],"ltp":580.0,"tv":6.13,"id":27606066}]}]}
{"op":"mcm","clk":"993215139","pt":1580538688496,"mc":[{"id":"1.168133543","rc":[{"batl":[[0,2.38,4],[1,2.42,5.5],[2,2.46,21]],"ltp":2.26,"tv":2612.23,"id":10107355}]}]}
{"op":"mcm","clk":"993215364","pt":1580538692516,"mc":[{"id":"1.168133543","rc":[{"batb":[[1,110,14.52],[2,100,16.8]],"ltp":580.0,"tv":6.13,"id":27606066}]}]}
{"op":"mcm","clk":"993215387","pt":1580538692724,"mc":[{"id":"1.168133543","rc":[{"batb":[[1,140,1.98],[2,110,14.35]],"ltp":580.0,"tv":6.13,"id":27606066}]}]}
{"op":"mcm","clk":"993215937","pt":1580538706511,"mc":[{"id":"1.168133543","rc":[{"batb":[[1,150,1.72],[2,110,14.16]],"ltp":580.0,"tv":6.13,"id":27606066}]}]}
{"op":"mcm","clk":"993216427","pt":1580538721521,"mc":[{"id":"1.168133543","rc":[{"batb":[[1,110,14.19],[2,100,16.8]],"ltp":580.0,"tv":6.13,"id":27606066}]}]}
{"op":"mcm","clk":"993216454","pt":1580538721935,"mc":[{"id":"1.168133543","rc":[{"batb":[[1,160,1.61],[2,110,14.16]],"ltp":580.0,"tv":6.13,"id":27606066}]}]}
{"op":"mcm","clk":"993216748","pt":1580538729123,"mc":[{"id":"1.168133543","rc":[{"batl":[[0,2.38,2],[1,2.4,2],[2,2.42,5.5]],"ltp":2.26,"tv":2612.23,"id":10107355}]}]}
{"op":"mcm","clk":"993216944","pt":1580538734559,"mc":[{"id":"1.168133543","rc":[{"batb":[[2,110,14.02]],"ltp":580.0,"tv":6.13,"id":27606066}]}]}
{"op":"mcm","clk":"993216976","pt":1580538735538,"mc":[{"id":"1.168133543","rc":[{"batb":[[1,110,14.17],[2,100,16.8]],"ltp":580.0,"tv":6.13,"id":27606066}]}]}
{"op":"mcm","clk":"993216980","pt":1580538735640,"mc":[{"id":"1.168133543","rc":[{"batb":[[1,170,1.64],[2,110,14.02]],"ltp":580.0,"tv":6.13,"id":27606066}]}]}
{"op":"mcm","clk":"993217513","pt":1580538749560,"mc":[{"id":"1.168133543","rc":[{"batb":[[1,180,1.44],[2,110,14.14]],"ltp":580.0,"tv":6.13,"id":27606066}]}]}
{"op":"mcm","clk":"993218030","pt":1580538761865,"mc":[{"id":"1.168133543","rc":[{"batl":[[0,2.38,4],[1,2.42,5.5],[2,2.46,21]],"ltp":2.26,"tv":2612.23,"id":10107355}]}]}
{"op":"mcm","clk":"993218150","pt":1580538764689,"mc":[{"id":"1.168133543","rc":[{"batb":[[1,190,1.36]],"ltp":580.0,"tv":6.13,"id":27606066}]}]}
{"op":"mcm","clk":"993218753","pt":1580538778562,"mc":[{"id":"1.168133543","rc":[{"batb":[[1,180,1.44]],"ltp":580.0,"tv":6.13,"id":27606066}]}]}
{"op":"mcm","clk":"993219258","pt":1580538788033,"mc":[{"id":"1.168133543","rc":[{"trd":[[2.9,193.76]],"batb":[[0,2.9,4.94]],"ltp":2.9,"tv":1167.56,"id":12636},{"batb":[[1,180,1.55],[2,110,14.02]],"ltp":580.0,"tv":6.13,"id":27606066}],"tv":4602.38}]}
{"op":"mcm","clk":"993219410","pt":1580538791123,"mc":[{"id":"1.168133543","rc":[{"batb":[[0,2.3,7.49],[1,2.28,39.19],[2,2.26,4.46]],"ltp":2.26,"tv":2612.23,"id":10107355}]}]}
{"op":"mcm","clk":"993219465","pt":1580538792513,"mc":[{"id":"1.168133543","rc":[{"batb":[[0,2.9,56.07]],"ltp":2.9,"tv":1167.56,"id":12636},{"batb":[[0,2.3,37.64],[1,2.28,8.77]],"ltp":2.26,"tv":2612.23,"id":10107355},{"batb":[[1,110,14.16],[2,100,16.8]],"ltp":580.0,"tv":6.13,"id":27606066}]}]}
{"op":"mcm","clk":"993219498","pt":1580538793231,"mc":[{"id":"1.168133543","rc":[{"batb":[[1,190,1.47],[2,110,14.02]],"ltp":580.0,"tv":6.13,"id":27606066}]}]}
{"op":"mcm","clk":"993219943","pt":1580538802119,"mc":[{"id":"1.168133543","rc":[{"batl":[[0,2.38,2],[1,2.4,2],[2,2.42,5.5]],"ltp":2.26,"tv":2612.23,"id":10107355}]}]}
{"op":"mcm","clk":"993220217","pt":1580538807553,"mc":[{"id":"1.168133543","rc":[{"batb":[[0,2.9,4.94]],"ltp":2.9,"tv":1167.56,"id":12636},{"batb":[[1,200,1.3],[2,110,14.13]],"ltp":580.0,"tv":6.13,"id":27606066}]}]}
{"op":"mcm","clk":"993221261","pt":1580538835997,"mc":[{"id":"1.168133543","rc":[{"batl":[[0,2.38,4],[1,2.42,5.5],[2,2.46,21]],"ltp":2.26,"tv":2612.23,"id":10107355}]}]}
{"op":"mcm","clk":"993221512","pt":1580538842197,"mc":[{"id":"1.168133543","rc":[{"batb":[[0,2.3,46.34],[1,2.26,4.46],[2,2.24,5.28]],"ltp":2.26,"tv":2612.23,"id":10107355},{"batb":[[1,200,1.4],[2,110,14.02]],"ltp":580.0,"tv":6.13,"id":27606066}]}]}
{"op":"mcm","clk":"993221885","pt":1580538851479,"mc":[{"id":"1.168133543","rc":[{"batb":[[0,2.9,56.07]],"ltp":2.9,"tv":1167.56,"id":12636},{"batb":[[0,2.32,29.89],[1,2.3,16.19],[2,2.26,4.46]],"ltp":2.26,"tv":2612.23,"id":10107355},{"batb":[[1,110,14.15],[2,100,16.8]],"ltp":580.0,"tv":6.13,"id":27606066}]}]}
{"op":"mcm","clk":"993221932","pt":1580538852813,"mc":[{"id":"1.168133543","rc":[{"batb":[[1,110,14.5]],"ltp":580.0,"tv":6.13,"id":27606066}]}]}
{"op":"mcm","clk":"993222210","pt":1580538860326,"mc":[{"id":"1.168133543","rc":[{"batl":[[0,2.38,2],[1,2.4,2],[2,2.42,5.5]],"ltp":2.26,"tv":2612.23,"id":10107355}]}]}
{"op":"mcm","clk":"993222445","pt":1580538864702,"mc":[{"id":"1.168133543","rc":[{"batb":[[0,2.9,4.94]],"ltp":2.9,"tv":1167.56,"id":12636},{"batb":[[0,2.3,16.19],[1,2.26,4.46],[2,2.24,5.28]],"ltp":2.26,"tv":2612.23,"id":10107355},{"batb":[[1,120,2.6],[2,110,14.02]],"ltp":580.0,"tv":6.13,"id":27606066}]}]}
{"op":"mcm","clk":"993222595","pt":1580538868306,"mc":[{"id":"1.168133543","rc":[{"batl":[[0,2.38,4],[1,2.42,5.5],[2,2.46,21]],"ltp":2.26,"tv":2612.23,"id":10107355}]}]}
{"op":"mcm","clk":"993222995","pt":1580538877325,"mc":[{"id":"1.168133543","rc":[{"batl":[[0,2.38,2],[1,2.4,2],[2,2.42,5.5]],"ltp":2.26,"tv":2612.23,"id":10107355}]}]}
{"op":"mcm","clk":"993223051","pt":1580538878506,"mc":[{"id":"1.168133543","rc":[{"batb":[[1,110,14.5],[2,100,16.8]],"ltp":580.0,"tv":6.13,"id":27606066}]}]}
{"op":"mcm","clk":"993223057","pt":1580538878611,"mc":[{"id":"1.168133543","rc":[{"batb":[[1,130,2.08],[2,110,14.37]],"ltp":580.0,"tv":6.13,"id":27606066}]}]}
{"op":"mcm","clk":"993223650","pt":1580538893539,"mc":[{"id":"1.168133543","rc":[{"batl":[[0,2.38,4],[1,2.42,5.5],[2,2.46,21]],"ltp":2.26,"tv":2612.23,"id":10107355},{"batb":[[1,140,1.94]],"ltp":580.0,"tv":6.13,"id":27606066}]}]}
{"op":"mcm","clk":"993223715","pt":1580538895131,"mc":[{"id":"1.168133543","rc":[{"batb":[[0,2.3,7.49]],"ltp":2.26,"tv":2612.23,"id":10107355},{"batb":[[1,140,1.84],[2,110,14.02]],"ltp":580.0,"tv":6.13,"id":27606066}]}]}
{"op":"mcm","clk":"993223989","pt":1580538901367,"mc":[{"id":"1.168133543","rc":[{"batl":[[0,2.38,2],[1,2.4,2],[2,2.42,5.5]],"ltp":2.26,"tv":2612.23,"id":10107355}]}]}
{"op":"mcm","clk":"993224272","pt":1580538907477,"mc":[{"id":"1.168133543","rc":[{"batb":[[1,110,14.05],[2,100,16.8]],"ltp":580.0,"tv":6.13,"id":27606066}]}]}
{"op":"mcm","clk":"993224303","pt":1580538907940,"mc":[{"id":"1.168133543","rc":[{"batb":[[1,150,1.72],[2,110,14.02]],"ltp":580.0,"tv":6.13,"id":27606066}]}]}
{"op":"mcm","clk":"993224654","pt":1580538917990,"mc":[{"id":"1.168133543","rc":[{"batl":[[0,2.38,4],[1,2.42,5.5],[2,2.46,21]],"ltp":2.26,"tv":2612.23,"id":10107355}]}]}
{"op":"mcm","clk":"993224817","pt":1580538921503,"mc":[{"id":"1.168133543","rc":[{"batb":[[1,110,14.05],[2,100,16.8]],"ltp":580.0,"tv":6.13,"id":27606066}]}]}
{"op":"mcm","clk":"993224840","pt":1580538921910,"mc":[{"id":"1.168133543","rc":[{"batb":[[0,2.9,56.07]],"ltp":2.9,"tv":1167.56,"id":12636},{"batb":[[0,2.3,37.64]],"ltp":2.26,"tv":2612.23,"id":10107355},{"batb":[[1,160,1.61],[2,110,14.02]],"ltp":580.0,"tv":6.13,"id":27606066}]}]}
{"op":"mcm","clk":"993225268","pt":1580538934219,"mc":[{"id":"1.168133543","rc":[{"batl":[[0,2.38,2],[1,2.4,2],[2,2.42,5.5]],"ltp":2.26,"tv":2612.23,"id":10107355}]}]}
{"op":"mcm","clk":"993225322","pt":1580538936483,"mc":[{"id":"1.168133543","rc":[{"batb":[[0,2.9,4.94]],"ltp":2.9,"tv":1167.56,"id":12636},{"batb":[[0,2.3,7.49],[1,2.28,30.42],[2,2.26,4.46]],"ltp":2.26,"tv":2612.23,"id":10107355},{"batb":[[1,110,14.05],[2,100,16.8]],"ltp":580.0,"tv":6.13,"id":27606066}]}]}
{"op":"mcm","clk":"993225330","pt":1580538936688,"mc":[{"id":"1.168133543","rc":[{"batb":[[1,170,1.52],[2,110,14.02]],"ltp":580.0,"tv":6.13,"id":27606066}]}]}
{"op":"mcm","clk":"993225470","pt":1580538940503,"mc":[{"id":"1.168133543","rc":[{"batl":[[0,2.4,2],[1,2.42,5.5],[2,2.46,21]],"ltp":2.26,"tv":2612.23,"id":10107355}]}]}
{"op":"mcm","clk":"993225546","pt":1580538942305,"mc":[{"id":"1.168133543","rc":[{"batl":[[0,2.38,2]],"ltp":2.26,"tv":2612.23,"id":10107355}]}]}
{"op":"mcm","clk":"993225811","pt":1580538950922,"mc":[{"id":"1.168133543","rc":[{"batl":[[0,2.4,2]],"ltp":2.26,"tv":2612.23,"id":10107355},{"batb":[[1,180,1.44]],"ltp":580.0,"tv":6.13,"id":27606066}]}]}
{"op":"mcm","clk":"993226333","pt":1580538964532,"mc":[{"id":"1.168133543","rc":[{"batb":[[1,110,14.05],[2,100,16.8]],"ltp":580.0,"tv":6.13,"id":27606066}]}]}
{"op":"mcm","clk":"993226336","pt":1580538964634,"mc":[{"id":"1.168133543","rc":[{"batb":[[1,190,1.36],[2,110,14.02]],"ltp":580.0,"tv":6.13,"id":27606066}]}]}
{"op":"mcm","clk":"993226933","pt":1580538979479,"mc":[{"id":"1.168133543","rc":[{"batb":[[1,110,14.05],[2,100,16.8]],"ltp":580.0,"tv":6.13,"id":27606066}]}]}
{"op":"mcm","clk":"993226937","pt":1580538979582,"mc":[{"id":"1.168133543","rc":[{"batb":[[1,120,2.14],[2,110,14.02]],"ltp":580.0,"tv":6.13,"id":27606066}]}]}
{"op":"mcm","clk":"993227501","pt":1580538994160,"mc":[{"id":"1.168133543","rc":[{"trd":[[2.92,147.14]],"batl":[[0,2.92,38.94]],"ltp":2.92,"tv":1171.82,"id":12636}],"tv":4606.64}]}
{"op":"mcm","clk":"993227582","pt":1580538996374,"mc":[{"id":"1.168133543","rc":[{"batb":[[1,120,2.47]],"ltp":580.0,"tv":6.13,"id":27606066}]}]}
{"op":"mcm","clk":"993227991","pt":1580539007514,"mc":[{"id":"1.168133543","rc":[{"batb":[[1,110,14.38],[2,100,16.8]],"ltp":580.0,"tv":6.13,"id":27606066}]}]}
{"op":"mcm","clk":"993227997","pt":1580539007618,"mc":[{"id":"1.168133543","rc":[{"batb":[[1,130,2.31],[2,110,14.02]],"ltp":580.0,"tv":6.13,"id":27606066}]}]}
{"op":"mcm","clk":"993228367","pt":1580539016826,"mc":[{"id":"1.168133543","rc":[{"batl":[[0,2.38,2],[1,2.4,2],[2,2.42,5.5]],"ltp":2.26,"tv":2612.23,"id":10107355}]}]}
{"op":"mcm","clk":"993228647","pt":1580539022514,"mc":[{"id":"1.168133543","rc":[{"batb":[[1,110,14.38],[2,100,16.8]],"ltp":580.0,"tv":6.13,"id":27606066}]}]}
{"op":"mcm","clk":"993228662","pt":1580539022722,"mc":[{"id":"1.168133543","rc":[{"batb":[[1,140,1.84],[2,110,14.35]],"ltp":580.0,"tv":6.13,"id":27606066}]}]}
{"op":"mcm","clk":"993229325","pt":1580539036539,"mc":[{"id":"1.168133543","rc":[{"batb":[[1,110,14.05],[2,100,16.8]],"ltp":580.0,"tv":6.13,"id":27606066}]}]}
{"op":"mcm","clk":"993229329","pt":1580539036642,"mc":[{"id":"1.168133543","rc":[{"batb":[[1,150,1.72],[2,110,14.02]],"ltp":580.0,"tv":6.13,"id":27606066}]}]}
{"op":"mcm","clk":"993229819","pt":1580539049543,"mc":[{"id":"1.168133543","rc":[{"batl":[[0,2.38,4],[1,2.42,5.5],[2,2.46,21]],"ltp":2.26,"tv":2612.23,"id":10107355}]}]}
{"op":"mcm","clk":"993229861","pt":1580539050471,"mc":[{"id":"1.168133543","rc":[{"batb":[[1,110,14.05],[2,100,16.8]],"ltp":580.0,"tv":6.13,"id":27606066}]}]}
{"op":"mcm","clk":"993229874","pt":1580539050678,"mc":[{"id":"1.168133543","rc":[{"batb":[[0,2.9,56.07]],"ltp":2.92,"tv":1171.82,"id":12636},{"batb":[[1,160,1.61],[2,110,14.02]],"ltp":580.0,"tv":6.13,"id":27606066}]}]}
{"op":"mcm","clk":"993240252","pt":1580539065568,"mc":[{"id":"1.168133543","rc":[{"batb":[[0,2.9,4.94]],"ltp":2.92,"tv":1171.82,"id":12636},{"batb":[[1,170,1.52]],"ltp":580.0,"tv":6.13,"id":27606066}]}]}
{"op":"mcm","clk":"993240656","pt":1580539079511,"mc":[{"id":"1.168133543","rc":[{"batb":[[1,110,14.05],[2,100,16.8]],"ltp":580.0,"tv":6.13,"id":27606066}]}]}
{"op":"mcm","clk":"993240673","pt":1580539079976,"mc":[{"id":"1.168133543","rc":[{"batb":[[0,2.9,56.07]],"ltp":2.92,"tv":1171.82,"id":12636},{"batb":[[1,180,1.44],[2,110,14.02]],"ltp":580.0,"tv":6.13,"id":27606066}]}]}
{"op":"mcm","clk":"993240807","pt":1580539083293,"mc":[{"id":"1.168133543","rc":[{"batl":[[0,2.38,2],[1,2.4,2],[2,2.42,5.5]],"ltp":2.26,"tv":2612.23,"id":10107355}]}]}
{"op":"mcm","clk":"993241155","pt":1580539093525,"mc":[{"id":"1.168133543","rc":[{"batb":[[0,2.9,4.94]],"ltp":2.92,"tv":1171.82,"id":12636},{"batb":[[1,110,14.05],[2,100,16.8]],"ltp":580.0,"tv":6.13,"id":27606066}]}]}
{"op":"mcm","clk":"993241170","pt":1580539093796,"mc":[{"id":"1.168133543","rc":[{"batb":[[1,190,1.36],[2,110,14.02]],"ltp":580.0,"tv":6.13,"id":27606066}]}]}
{"op":"mcm","clk":"993241377","pt":1580539098486,"mc":[{"id":"1.168133543","rc":[{"batb":[[0,95,1.01],[1,85,3.08],[2,80,17.88]],"ltp":160.0,"tv":7.54,"id":26548208}]}]}
{"op":"mcm","clk":"993241445","pt":1580539100097,"mc":[{"id":"1.168133543","rc":[{"batl":[[0,2.38,4],[1,2.42,5.5],[2,2.46,21]],"ltp":2.26,"tv":2612.23,"id":10107355}]}]}
{"op":"mcm","clk":"993241808","pt":1580539108545,"mc":[{"id":"1.168133543","rc":[{"batb":[[0,2.9,56.07]],"ltp":2.92,"tv":1171.82,"id":12636},{"batb":[[1,85,1.25]],"ltp":160.0,"tv":7.54,"id":26548208},{"batb":[[1,110,14.05],[2,100,16.8]],"ltp":580.0,"tv":6.13,"id":27606066}]}]}
{"op":"mcm","clk":"993241847","pt":1580539109419,"mc":[{"id":"1.168133543","rc":[{"batb":[[1,2.28,39.19]],"ltp":2.26,"tv":2612.23,"id":10107355},{"batb":[[1,90,2.31],[2,80,18.55]],"ltp":160.0,"tv":7.54,"id":26548208},{"batb":[[1,120,2.29],[2,110,14.02]],"ltp":580.0,"tv":6.13,"id":27606066}]}]}
{"op":"mcm","clk":"993241884","pt":1580539110506,"mc":[{"id":"1.168133543","rc":[{"batb":[[2,80,18.54]],"ltp":160.0,"tv":7.54,"id":26548208}]}]}
{"op":"mcm","clk":"993241950","pt":1580539112214,"mc":[{"id":"1.168133543","rc":[{"batb":[[2,80,18.55]],"ltp":160.0,"tv":7.54,"id":26548208}]}]}
{"op":"mcm","clk":"993242071","pt":1580539116539,"mc":[{"id":"1.168133543","rc":[{"batl":[[0,2.38,2]],"ltp":2.26,"tv":2612.23,"id":10107355}]}]}
{"op":"mcm","clk":"993242078","pt":1580539116949,"mc":[{"id":"1.168133543","rc":[{"batl":[[1,2.4,2],[2,2.42,5.5]],"ltp":2.26,"tv":2612.23,"id":10107355},{"batb":[[1,120,2.62]],"ltp":580.0,"tv":6.13,"id":27606066}]}]}
{"op":"mcm","clk":"993242283","pt":1580539122510,"mc":[{"id":"1.168133543","rc":[{"batb":[[0,2.9,4.94]],"ltp":2.92,"tv":1171.82,"id":12636},{"batb":[[1,2.28,8.77]],"ltp":2.26,"tv":2612.23,"id":10107355},{"batb":[[1,85,1.26],[2,80,17.87]],"ltp":160.0,"tv":7.54,"id":26548208},{"batb":[[1,110,14.53],[2,100,16.8]],"ltp":580.0,"tv":6.13,"id":27606066}]}]}
{"op":"mcm","clk":"993242319","pt":1580539123539,"mc":[{"id":"1.168133543","rc":[{"batb":[[0,2.3,37.64]],"ltp":2.26,"tv":2612.23,"id":10107355},{"batb":[[1,130,2.46],[2,110,14.02]],"ltp":580.0,"tv":6.13,"id":27606066}]}]}
{"op":"mcm","clk":"993242742","pt":1580539136552,"mc":[{"id":"1.168133543","rc":[{"batb":[[1,110,14.53],[2,100,16.8]],"ltp":580.0,"tv":6.13,"id":27606066}]}]}
{"op":"mcm","clk":"993242774","pt":1580539137222,"mc":[{"id":"1.168133543","rc":[{"batb":[[1,85,3.09]],"ltp":160.0,"tv":7.54,"id":26548208},{"batb":[[1,140,1.84],[2,110,14.5]],"ltp":580.0,"tv":6.13,"id":27606066}]}]}
{"op":"mcm","clk":"993242809","pt":1580539138146,"mc":[{"id":"1.168133543","rc":[{"batb":[[2,110,14.17]],"ltp":580.0,"tv":6.13,"id":27606066}]}]}
{"op":"mcm","clk":"993243391","pt":1580539151574,"mc":[{"id":"1.168133543","rc":[{"batb":[[1,85,1.26]],"ltp":160.0,"tv":7.54,"id":26548208},{"batb":[[1,110,14.2],[2,100,16.8]],"ltp":580.0,"tv":6.13,"id":27606066}]}]}
{"op":"mcm","clk":"993243397","pt":1580539151678,"mc":[{"id":"1.168133543","rc":[{"batb":[[1,90,2.31],[2,80,18.55]],"ltp":160.0,"tv":7.54,"id":26548208},{"batb":[[1,150,1.72],[2,110,14.17]],"ltp":580.0,"tv":6.13,"id":27606066}]}]}
{"op":"mcm","clk":"993243639","pt":1580539158547,"mc":[{"id":"1.168133543","rc":[{"batl":[[1,2.42,5.5],[2,2.46,21]],"ltp":2.26,"tv":2612.23,"id":10107355}]}]}
{"op":"mcm","clk":"993243645","pt":1580539158651,"mc":[{"id":"1.168133543","rc":[{"batl":[[0,2.38,4]],"ltp":2.26,"tv":2612.23,"id":10107355}]}]}
{"op":"mcm","clk":"993243827","pt":1580539163378,"mc":[{"id":"1.168133543","rc":[{"batb":[[1,2.26,4.46],[2,2.24,5.28]],"ltp":2.26,"tv":2612.23,"id":10107355},{"batb":[[2,110,14.02]],"ltp":580.0,"tv":6.13,"id":27606066}]}]}
{"op":"mcm","clk":"993243901","pt":1580539165489,"mc":[{"id":"1.168133543","rc":[{"batb":[[0,2.3,7.49]],"ltp":2.26,"tv":2612.23,"id":10107355},{"batb":[[1,85,1.26],[2,80,17.87]],"ltp":160.0,"tv":7.54,"id":26548208},{"batb":[[1,110,14.05],[2,100,16.8]],"ltp":580.0,"tv":6.13,"id":27606066}]}]}
{"op":"mcm","clk":"993243917","pt":1580539165799,"mc":[{"id":"1.168133543","rc":[{"batb":[[1,2.28,30.42],[2,2.26,4.46]],"ltp":2.26,"tv":2612.23,"id":10107355},{"batb":[[1,160,1.61],[2,110,14.02]],"ltp":580.0,"tv":6.13,"id":27606066}]}]}
{"op":"mcm","clk":"993244456","pt":1580539179870,"mc":[{"id":"1.168133543","rc":[{"batb":[[0,2.9,56.07]],"ltp":2.92,"tv":1171.82,"id":12636},{"batb":[[1,85,3.09]],"ltp":160.0,"tv":7.54,"id":26548208},{"batb":[[1,170,1.52]],"ltp":580.0,"tv":6.13,"id":27606066}]}]}
{"op":"mcm","clk":"993245057","pt":1580539195503,"mc":[{"id":"1.168133543","rc":[{"batb":[[0,2.9,4.94]],"ltp":2.92,"tv":1171.82,"id":12636},{"batb":[[1,90,2.31],[2,80,18.55]],"ltp":160.0,"tv":7.54,"id":26548208},{"batb":[[1,180,1.44]],"ltp":580.0,"tv":6.13,"id":27606066}]}]}
{"op":"mcm","clk":"993245612","pt":1580539208505,"mc":[{"id":"1.168133543","rc":[{"batb":[[1,110,14.05],[2,100,16.8]],"ltp":580.0,"tv":6.13,"id":27606066}]}]}
{"op":"mcm","clk":"993245623","pt":1580539208737,"mc":[{"id":"1.168133543","rc":[{"batb":[[0,2.9,56.07]],"ltp":2.92,"tv":1171.82,"id":12636},{"batb":[[1,190,1.36],[2,110,14.02]],"ltp":580.0,"tv":6.13,"id":27606066}]}]}
{"op":"mcm","clk":"993246226","pt":1580539222503,"mc":[{"id":"1.168133543","rc":[{"batb":[[0,2.9,4.94]],"ltp":2.92,"tv":1171.82,"id":12636},{"batb":[[1,120,2.14]],"ltp":580.0,"tv":6.13,"id":27606066}]}]}
{"op":"mcm","clk":"993246548","pt":1580539230697,"mc":[{"id":"1.168133543","rc":[{"batl":[[0,2.38,2],[1,2.4,2],[2,2.42,5.5]],"ltp":2.26,"tv":2612.23,"id":10107355}]}]}
{"op":"mcm","clk":"993246783","pt":1580539236632,"mc":[{"id":"1.168133543","rc":[{"batb":[[1,85,1.26],[2,80,17.87]],"ltp":160.0,"tv":7.54,"id":26548208}]}]}
{"op":"mcm","clk":"993246911","pt":1580539239529,"mc":[{"id":"1.168133543","rc":[{"batb":[[1,120,2.47]],"ltp":580.0,"tv":6.13,"id":27606066}]}]}
{"op":"mcm","clk":"993247439","pt":1580539251950,"mc":[{"id":"1.168133543","rc":[{"batb":[[1,85,3.09]],"ltp":160.0,"tv":7.54,"id":26548208},{"batb":[[1,130,2.31]],"ltp":580.0,"tv":6.13,"id":27606066}]}]}
{"op":"mcm","clk":"993247612","pt":1580539256443,"mc":[{"id":"1.168133543","rc":[{"batl":[[0,2.38,4],[1,2.42,5.5],[2,2.46,21]],"ltp":2.26,"tv":2612.23,"id":10107355}]}]}
{"op":"mcm","clk":"993248048","pt":1580539265554,"mc":[{"id":"1.168133543","rc":[{"batl":[[0,2.38,2],[1,2.4,2],[2,2.42,5.5]],"ltp":2.26,"tv":2612.23,"id":10107355},{"batb":[[1,85,1.26]],"ltp":160.0,"tv":7.54,"id":26548208},{"batb":[[1,110,14.38],[2,100,16.8]],"ltp":580.0,"tv":6.13,"id":27606066}]}]}
{"op":"mcm","clk":"993248054","pt":1580539265657,"mc":[{"id":"1.168133543","rc":[{"batb":[[1,90,2.31],[2,80,18.55]],"ltp":160.0,"tv":7.54,"id":26548208},{"batb":[[1,140,1.84],[2,110,14.35]],"ltp":580.0,"tv":6.13,"id":27606066}]}]}
{"op":"mcm","clk":"993248629","pt":1580539278390,"mc":[{"id":"1.168133543","rc":[{"trd":[[8.4,16.16],[8.6,1.16],[8.8,119.98],[9,7.46]],"batb":[[0,6.4,14.17],[1,5.1,90],[2,3.5,86.16]],"ltp":8.4,"tv":372.73,"id":22121325}],"tv":4628.64}]}
{"op":"mcm","clk":"993248674","pt":1580539279468,"mc":[{"id":"1.168133543","rc":[{"batb":[[1,2.88,40.13]],"ltp":2.92,"tv":1171.82,"id":12636},{"batb":[[0,9.6,9.9]],"ltp":9.6,"tv":373.41,"id":10163711},{"batb":[[0,2.32,26.11],[1,2.3,7.49],[2,2.28,30.42]],"ltp":2.26,"tv":2612.23,"id":10107355},{"batb":[[0,6.6,12.29],[1,6.4,14.06],[2,5.1,90]],"ltp":8.4,"tv":372.73,"id":22121325},{"batb":[[1,150,1.35],[2,140,1.81]],"ltp":580.0,"tv":6.13,"id":27606066}]}]}
{"op":"mcm","clk":"993248732","pt":1580539280554,"mc":[{"id":"1.168133543","rc":[{"batb":[[0,2.9,56.07]],"ltp":2.92,"tv":1171.82,"id":12636},{"batb":[[0,2.34,29.64],[1,2.32,26.11],[2,2.3,7.49]],"ltp":2.26,"tv":2612.23,"id":10107355},{"batl":[[0,10,15.85]],"ltp":8.4,"tv":372.73,"id":22121325},{"batb":[[1,150,3.04],[2,110,14.02]],"ltp":580.0,"tv":6.13,"id":27606066}]}]}
{"op":"mcm","clk":"993248761","pt":1580539281173,"mc":[{"id":"1.168133543","rc":[{"batb":[[0,6.8,6.69],[1,6.6,12.18],[2,6.4,14.06]],"batl":[[0,10,15.97]],"ltp":8.4,"tv":372.73,"id":22121325}]}]}
{"op":"mcm","clk":"993248810","pt":1580539282098,"mc":[{"id":"1.168133543","rc":[{"batl":[[0,2.38,4],[1,2.42,5.5],[2,2.46,21]],"ltp":2.26,"tv":2612.23,"id":10107355}]}]}
{"op":"mcm","clk":"993248958","pt":1580539284962,"mc":[{"id":"1.168133543","rc":[{"batb":[[0,7,2.67],[1,6.8,6.29],[2,6.6,12.18]],"batl":[[0,10,16.17]],"ltp":8.4,"tv":372.73,"id":22121325}]}]}
{"op":"mcm","clk":"993249082","pt":1580539287489,"mc":[{"id":"1.168133543","rc":[{"trd":[[6.6,1.66],[6.8,12.58],[7,4.76],[7.2,4.42],[7.6,0.58]],"batb":[[0,6.6,11.35],[1,6.4,14.06],[2,5.1,90]],"batl":[[0,9.8,2.12],[1,10,15.67],[2,11,2]],"ltp":6.6,"tv":396.74,"id":22121325}],"tv":4652.65}]}
{"op":"mcm","clk":"993249089","pt":1580539287596,"mc":[{"id":"1.168133543","rc":[{"batb":[[0,6.8,3.77],[1,6.6,11.35],[2,6.4,14.06]],"ltp":6.6,"tv":396.74,"id":22121325}]}]}
{"op":"mcm","clk":"993249183","pt":1580539289469,"mc":[{"id":"1.168133543","rc":[{"batb":[[0,60,1.68],[1,55,3.43],[2,50,14.8]],"ltp":60.0,"tv":31.75,"id":7226819},{"batb":[[0,2.34,31.32]],"ltp":2.26,"tv":2612.23,"id":10107355},{"batb":[[0,7,1.98],[1,6.8,3.77],[2,6.6,11.35]],"ltp":6.6,"tv":396.74,"id":22121325}]}]}
{"op":"mcm","clk":"993249201","pt":1580539289782,"mc":[{"id":"1.168133543","rc":[{"batb":[[0,2.9,58.05]],"ltp":2.92,"tv":1171.82,"id":12636},{"batb":[[0,9.6,12.34],[1,9.2,5.64],[2,8.6,2.43]],"ltp":9.6,"tv":373.41,"id":10163711},{"batl":[[0,2.38,2],[1,2.4,2],[2,2.42,5.5]],"ltp":2.26,"tv":2612.23,"id":10107355}]}]}
{"op":"mcm","clk":"993249351","pt":1580539293184,"mc":[{"id":"1.168133543","rc":[{"batb":[[1,6.8,4.19]],"batl":[[0,9.8,2.39]],"ltp":6.6,"tv":396.74,"id":22121325}]}]}
{"op":"mcm","clk":"993249400","pt":1580539294481,"mc":[{"id":"1.168133543","rc":[{"batb":[[0,2.9,6.92]],"ltp":2.92,"tv":1171.82,"id":12636},{"batb":[[1,160,1.61],[2,150,1.32]],"ltp":580.0,"tv":6.13,"id":27606066}]}]}
{"op":"mcm","clk":"993249474","pt":1580539296126,"mc":[{"id":"1.168133543","rc":[{"batb":[[2,8.4,9.24]],"ltp":9.6,"tv":373.41,"id":10163711},{"batb":[[2,6.6,9.18]],"ltp":6.6,"tv":396.74,"id":22121325}]}]}
{"op":"mcm","clk":"993249566","pt":1580539298084,"mc":[{"id":"1.168133543","rc":[{"batl":[[0,2.38,4],[1,2.42,5.5],[2,2.46,21]],"ltp":2.26,"tv":2612.23,"id":10107355}]}]}
{"op":"mcm","clk":"993249711","pt":1580539301375,"mc":[{"id":"1.168133543","rc":[{"batb":[[1,55,3.11]],"ltp":60.0,"tv":31.75,"id":7226819},{"batb":[[0,7,4.25]],"batl":[[0,9.6,5.11],[1,9.8,1.75],[2,10,15.67]],"ltp":6.6,"tv":396.74,"id":22121325}]}]}
{"op":"mcm","clk":"993249792","pt":1580539304100,"mc":[{"id":"1.168133543","rc":[{"trd":[[2.34,337.92]],"batb":[[0,2.34,31.07]],"ltp":2.34,"tv":2612.73,"id":10107355}],"tv":4653.14}]}
{"op":"mcm","clk":"993249873","pt":1580539306414,"mc":[{"id":"1.168133543","rc":[{"batl":[[0,2.38,2],[1,2.4,2],[2,2.42,5.5]],"ltp":2.34,"tv":2612.73,"id":10107355}]}]}
{"op":"mcm","clk":"993249957","pt":1580539308520,"mc":[{"id":"1.168133543","rc":[{"batb":[[1,150,1.35],[2,110,14.02]],"ltp":580.0,"tv":6.13,"id":27606066}]}]}
{"op":"mcm","clk":"993249982","pt":1580539309192,"mc":[{"id":"1.168133543","rc":[{"batb":[[0,2.9,58.05]],"ltp":2.92,"tv":1171.82,"id":12636},{"batb":[[0,7.2,2.21],[1,7,4.25],[2,6.8,4.19]],"ltp":6.6,"tv":396.74,"id":22121325},{"batb":[[1,170,1.52],[2,150,1.32]],"ltp":580.0,"tv":6.13,"id":27606066}]}]}
{"op":"mcm","clk":"993250105","pt":1580539311905,"mc":[{"id":"1.168133543","rc":[{"trd":[[2.34,338.31]],"batb":[[0,2.34,30.88]],"ltp":2.34,"tv":2613.13,"id":10107355}],"tv":4653.54}]}
{"op":"mcm","clk":"993250207","pt":1580539314518,"mc":[{"id":"1.168133543","rc":[{"trd":[[2.34,338.54]],"batb":[[0,2.34,30.76]],"batl":[[1,2.42,5.5],[2,2.46,21]],"ltp":2.34,"tv":2613.35,"id":10107355}],"tv":4653.76}]}
{"op":"mcm","clk":"993250210","pt":1580539314619,"mc":[{"id":"1.168133543","rc":[{"batl":[[0,2.38,4]],"ltp":2.34,"tv":2613.35,"id":10107355}]}]}
{"op":"mcm","clk":"993250551","pt":1580539322540,"mc":[{"id":"1.168133543","rc":[{"batb":[[0,2.9,6.92]],"ltp":2.92,"tv":1171.82,"id":12636},{"batl":[[0,2.38,2],[1,2.4,2],[2,2.42,5.5]],"ltp":2.34,"tv":2613.35,"id":10107355},{"batl":[[1,9.8,3.75]],"ltp":6.6,"tv":396.74,"id":22121325},{"batb":[[1,180,1.44]],"ltp":580.0,"tv":6.13,"id":27606066}]}]}
{"op":"mcm","clk":"993250730","pt":1580539326506,"mc":[{"id":"1.168133543","rc":[{"batb":[[0,7.4,1.98],[1,7.2,2.21],[2,7,2.27]],"ltp":6.6,"tv":396.74,"id":22121325}]}]}
{"op":"mcm","clk":"993251235","pt":1580539337521,"mc":[{"id":"1.168133543","rc":[{"batb":[[1,150,1.35],[2,110,14.02]],"ltp":580.0,"tv":6.13,"id":27606066}]}]}
{"op":"mcm","clk":"993251260","pt":1580539337927,"mc":[{"id":"1.168133543","rc":[{"batb":[[0,2.9,58.05]],"ltp":2.92,"tv":1171.82,"id":12636},{"batb":[[1,190,1.36],[2,150,1.32]],"ltp":580.0,"tv":6.13,"id":27606066}]}]}
{"op":"mcm","clk":"993251346","pt":1580539339525,"mc":[{"id":"1.168133543","rc":[{"batl":[[0,2.38,4],[1,2.42,5.5],[2,2.46,21]],"ltp":2.34,"tv":2613.35,"id":10107355}]}]}
{"op":"mcm","clk":"993251490","pt":1580539342357,"mc":[{"id":"1.168133543","rc":[{"batl":[[0,9.2,4.06],[1,9.4,7.6],[2,9.6,4.46]],"ltp":6.6,"tv":396.74,"id":22121325}]}]}
{"op":"mcm","clk":"993251638","pt":1580539345563,"mc":[{"id":"1.168133543","rc":[{"trd":[[2.34,358.52]],"batb":[[0,2.34,20.78]],"ltp":2.34,"tv":2633.34,"id":10107355}],"tv":4673.75}]}
{"op":"mcm","clk":"993251737","pt":1580539347565,"mc":[{"id":"1.168133543","rc":[{"batl":[[0,2.38,2],[1,2.4,2],[2,2.42,5.5]],"ltp":2.34,"tv":2633.34,"id":10107355},{"batl":[[0,9.2,6.06]],"ltp":6.6,"tv":396.74,"id":22121325}]}]}
{"op":"mcm","clk":"993251928","pt":1580539351529,"mc":[{"id":"1.168133543","rc":[{"batb":[[0,2.9,6.92]],"ltp":2.92,"tv":1171.82,"id":12636},{"batb":[[1,160,1.61]],"ltp":580.0,"tv":6.13,"id":27606066}]}]}
{"op":"mcm","clk":"993252394","pt":1580539361287,"mc":[{"id":"1.168133543","rc":[{"batl":[[0,9,5.21],[1,9.2,5.61],[2,9.4,7.6]],"ltp":6.6,"tv":396.74,"id":22121325}]}]}
{"op":"mcm","clk":"993252574","pt":1580539365545,"mc":[{"id":"1.168133543","rc":[{"batb":[[0,2.9,58.05]],"ltp":2.92,"tv":1171.82,"id":12636},{"trd":[[9.8,22.85]],"batl":[[0,9.8,14.93]],"ltp":9.8,"tv":378.72,"id":10163711},{"batb":[[1,150,1.35],[2,110,14.02]],"ltp":580.0,"tv":6.13,"id":27606066}],"tv":4679.06}]}
{"op":"mcm","clk":"993252603","pt":1580539366472,"mc":[{"id":"1.168133543","rc":[{"batb":[[1,170,1.52],[2,150,1.32]],"ltp":580.0,"tv":6.13,"id":27606066}]}]}
{"op":"mcm","clk":"993252876","pt":1580539372273,"mc":[{"id":"1.168133543","rc":[{"batl":[[0,2.38,4],[1,2.42,5.5],[2,2.46,21]],"ltp":2.34,"tv":2633.34,"id":10107355}]}]}
{"op":"mcm","clk":"993252925","pt":1580539373539,"mc":[{"id":"1.168133543","rc":[{"batl":[[0,8.8,2],[1,9,5.21],[2,9.2,3.61]],"ltp":6.6,"tv":396.74,"id":22121325}]}]}
{"op":"mcm","clk":"993253049","pt":1580539376671,"mc":[{"id":"1.168133543","rc":[{"batl":[[0,8.8,2.27],[1,9,4.94]],"ltp":6.6,"tv":396.74,"id":22121325}]}]}
{"op":"mcm","clk":"993253133","pt":1580539378570,"mc":[{"id":"1.168133543","rc":[{"batl":[[2,9.2,3.41]],"ltp":6.6,"tv":396.74,"id":22121325},{"batb":[[1,170,1.63]],"ltp":580.0,"tv":6.13,"id":27606066}]}]}
{"op":"mcm","clk":"993253215","pt":1580539380480,"mc":[{"id":"1.168133543","rc":[{"batb":[[0,2.9,6.92]],"ltp":2.92,"tv":1171.82,"id":12636},{"batb":[[0,2.34,1.68]],"ltp":2.34,"tv":2633.34,"id":10107355},{"batb":[[1,150,1.46],[2,110,14.02]],"ltp":580.0,"tv":6.13,"id":27606066}]}]}
{"op":"mcm","clk":"993253258","pt":1580539381461,"mc":[{"id":"1.168133543","rc":[{"trd":[[2.34,361.88]],"batb":[[0,2.32,26.11],[1,2.3,7.49],[2,2.26,4.46]],"batl":[[0,2.38,2],[1,2.4,2],[2,2.42,5.5]],"ltp":2.34,"tv":2636.7,"id":10107355},{"batl":[[1,9.2,3.59],[2,9.4,7.6]],"ltp":6.6,"tv":396.74,"id":22121325},{"batb":[[1,180,1.55],[2,150,1.32]],"ltp":580.0,"tv":6.13,"id":27606066}],"tv":4682.42}]}
{"op":"mcm","clk":"993253306","pt":1580539382184,"mc":[{"id":"1.168133543","rc":[{"batl":[[0,8.6,5.25],[1,8.8,2],[2,9.2,3.59]],"ltp":6.6,"tv":396.74,"id":22121325}]}]}
{"op":"mcm","clk":"993253901","pt":1580539395272,"mc":[{"id":"1.168133543","rc":[{"batb":[[0,2.9,58.05]],"ltp":2.92,"tv":1171.82,"id":12636},{"batb":[[0,2.34,19.1],[1,2.32,26.11],[2,2.3,7.49]],"ltp":2.34,"tv":2636.7,"id":10107355},{"batb":[[1,190,1.36],[2,150,1.43]],"ltp":580.0,"tv":6.13,"id":27606066}]}]}
{"op":"mcm","clk":"993254023","pt":1580539398506,"mc":[{"id":"1.168133543","rc":[{"batl":[[0,2.38,4],[1,2.42,5.5],[2,2.46,21]],"ltp":2.34,"tv":2636.7,"id":10107355}]}]}
{"op":"mcm","clk":"993254312","pt":1580539406112,"mc":[{"id":"1.168133543","rc":[{"batl":[[0,2.38,2],[1,2.4,2],[2,2.42,5.5]],"ltp":2.34,"tv":2636.7,"id":10107355}]}]}
{"op":"mcm","clk":"993254386","pt":1580539408427,"mc":[{"id":"1.168133543","rc":[{"batb":[[0,2.9,6.92]],"ltp":2.92,"tv":1171.82,"id":12636}]}]}
{"op":"mcm","clk":"993254636","pt":1580539414915,"mc":[{"id":"1.168133543","rc":[{"batl":[[0,8.6,7.25],[1,9.2,3.59],[2,9.4,7.6]],"ltp":6.6,"tv":396.74,"id":22121325}]}]}
{"op":"mcm","clk":"993255000","pt":1580539423560,"mc":[{"id":"1.168133543","rc":[{"batb":[[0,2.32,26.11],[1,2.3,7.49],[2,2.26,4.46]],"batl":[[0,2.38,4],[1,2.42,5.5],[2,2.46,21]],"ltp":2.34,"tv":2636.7,"id":10107355}]}]}
{"op":"mcm","clk":"993255015","pt":1580539423819,"mc":[{"id":"1.168133543","rc":[{"batb":[[0,2.9,58.05]],"ltp":2.92,"tv":1171.82,"id":12636}]}]}
{"op":"mcm","clk":"993255363","pt":1580539431258,"mc":[{"id":"1.168133543","rc":[{"batb":[[0,2.32,34.73]],"batl":[[0,2.38,2],[1,2.4,2],[2,2.42,5.5]],"ltp":2.34,"tv":2636.7,"id":10107355},{"batb":[[1,190,1.46],[2,150,1.32]],"ltp":580.0,"tv":6.13,"id":27606066}]}]}
{"op":"mcm","clk":"993255647","pt":1580539437541,"mc":[{"id":"1.168133543","rc":[{"batb":[[0,2.9,6.92]],"ltp":2.92,"tv":1171.82,"id":12636},{"batb":[[1,150,1.45],[2,110,14.02]],"ltp":580.0,"tv":6.13,"id":27606066}]}]}
{"op":"mcm","clk":"993255654","pt":1580539437752,"mc":[{"id":"1.168133543","rc":[{"batb":[[0,2.34,19.1],[1,2.32,34.73],[2,2.3,7.49]],"ltp":2.34,"tv":2636.7,"id":10107355},{"batb":[[1,200,1.4],[2,150,1.32]],"ltp":580.0,"tv":6.13,"id":27606066}]}]}
{"op":"mcm","clk":"993255721","pt":1580539439187,"mc":[{"id":"1.168133543","rc":[{"batl":[[0,2.38,4],[1,2.42,5.5],[2,2.46,21]],"ltp":2.34,"tv":2636.7,"id":10107355}]}]}
{"op":"mcm","clk":"993256346","pt":1580539451551,"mc":[{"id":"1.168133543","rc":[{"batb":[[0,2.32,34.73],[1,2.3,7.49],[2,2.26,4.46]],"ltp":2.34,"tv":2636.7,"id":10107355},{"batb":[[1,150,1.45],[2,110,14.02]],"ltp":580.0,"tv":6.13,"id":27606066}]}]}
{"op":"mcm","clk":"993256362","pt":1580539451758,"mc":[{"id":"1.168133543","rc":[{"batb":[[0,2.9,58.05]],"ltp":2.92,"tv":1171.82,"id":12636},{"batb":[[1,210,1.24],[2,150,1.42]],"ltp":580.0,"tv":6.13,"id":27606066}]}]}
{"op":"mcm","clk":"993256914","pt":1580539463487,"mc":[{"id":"1.168133543","rc":[{"batl":[[0,2.38,2]],"ltp":2.34,"tv":2636.7,"id":10107355}]}]}
{"op":"mcm","clk":"993256937","pt":1580539464001,"mc":[{"id":"1.168133543","rc":[{"batl":[[1,2.4,2],[2,2.42,5.5]],"ltp":2.34,"tv":2636.7,"id":10107355}]}]}
{"op":"mcm","clk":"993257032","pt":1580539466477,"mc":[{"id":"1.168133543","rc":[{"batb":[[0,2.9,6.92]],"ltp":2.92,"tv":1171.82,"id":12636},{"batb":[[1,150,1.45],[2,110,14.02]],"ltp":580.0,"tv":6.13,"id":27606066}]}]}
{"op":"mcm","clk":"993257079","pt":1580539467504,"mc":[{"id":"1.168133543","rc":[{"batb":[[0,2.34,19.1],[1,2.32,34.73],[2,2.3,7.49]],"ltp":2.34,"tv":2636.7,"id":10107355},{"batb":[[1,160,1.71],[2,150,1.32]],"ltp":580.0,"tv":6.13,"id":27606066}]}]}
{"op":"mcm","clk":"993257294","pt":1580539472492,"mc":[{"id":"1.168133543","rc":[{"batl":[[1,2.42,5.5],[2,2.46,21]],"ltp":2.34,"tv":2636.7,"id":10107355}]}]}
{"op":"mcm","clk":"993257299","pt":1580539472593,"mc":[{"id":"1.168133543","rc":[{"batl":[[0,2.38,4]],"ltp":2.34,"tv":2636.7,"id":10107355}]}]}
{"op":"mcm","clk":"993257664","pt":1580539480810,"mc":[{"id":"1.168133543","rc":[{"batb":[[0,2.9,58.05]],"ltp":2.92,"tv":1171.82,"id":12636},{"batb":[[0,2.32,34.73],[1,2.3,7.49],[2,2.26,4.46]],"ltp":2.34,"tv":2636.7,"id":10107355},{"batb":[[1,170,1.62]],"ltp":580.0,"tv":6.13,"id":27606066}]}]}
{"op":"mcm","clk":"993257805","pt":1580539484423,"mc":[{"id":"1.168133543","rc":[{"batb":[[1,170,1.52]],"ltp":580.0,"tv":6.13,"id":27606066}]}]}
{"op":"mcm","clk":"993257826","pt":1580539484983,"mc":[{"id":"1.168133543","rc":[{"batb":[[1,170,1.63]],"ltp":580.0,"tv":6.13,"id":27606066}]}]}
{"op":"mcm","clk":"993257972","pt":1580539489416,"mc":[{"id":"1.168133543","rc":[{"batl":[[0,2.38,2],[1,2.4,2],[2,2.42,5.5]],"ltp":2.34,"tv":2636.7,"id":10107355}]}]}
{"op":"mcm","clk":"993258155","pt":1580539494524,"mc":[{"id":"1.168133543","rc":[{"batb":[[0,2.9,6.92]],"ltp":2.92,"tv":1171.82,"id":12636},{"batb":[[1,150,1.46],[2,110,14.02]],"ltp":580.0,"tv":6.13,"id":27606066}]}]}
{"op":"mcm","clk":"993258165","pt":1580539494734,"mc":[{"id":"1.168133543","rc":[{"batb":[[0,2.34,19.1],[1,2.32,34.73],[2,2.3,7.49]],"ltp":2.34,"tv":2636.7,"id":10107355},{"batb":[[1,180,1.55],[2,150,1.32]],"ltp":580.0,"tv":6.13,"id":27606066}]}]}
{"op":"mcm","clk":"993258306","pt":1580539497835,"mc":[{"id":"1.168133543","rc":[{"batl":[[0,2.38,4],[1,2.42,5.5],[2,2.46,21]],"ltp":2.34,"tv":2636.7,"id":10107355}]}]}
{"op":"mcm","clk":"993258949","pt":1580539509553,"mc":[{"id":"1.168133543","rc":[{"batb":[[0,2.32,34.73],[1,2.3,7.49],[2,2.26,4.46]],"ltp":2.34,"tv":2636.7,"id":10107355},{"batb":[[1,150,1.46],[2,110,14.02]],"ltp":580.0,"tv":6.13,"id":27606066}]}]}
{"op":"mcm","clk":"993258988","pt":1580539510429,"mc":[{"id":"1.168133543","rc":[{"batb":[[0,2.9,58.05]],"ltp":2.92,"tv":1171.82,"id":12636},{"batb":[[1,190,1.36],[2,150,1.43]],"ltp":580.0,"tv":6.13,"id":27606066}]}]}
{"op":"mcm","clk":"993259168","pt":1580539514341,"mc":[{"id":"1.168133543","rc":[{"batl":[[0,2.38,2],[1,2.4,2],[2,2.42,5.5]],"ltp":2.34,"tv":2636.7,"id":10107355}]}]}
{"op":"mcm","clk":"993259413","pt":1580539521150,"mc":[{"id":"1.168133543","rc":[{"batb":[[1,7,2.27],[2,6.6,9.6]],"ltp":6.6,"tv":396.74,"id":22121325}]}]}
{"op":"mcm","clk":"993259474","pt":1580539522543,"mc":[{"id":"1.168133543","rc":[{"batl":[[1,2.42,5.5],[2,2.46,21]],"ltp":2.34,"tv":2636.7,"id":10107355}]}]}
{"op":"mcm","clk":"993259515","pt":1580539523466,"mc":[{"id":"1.168133543","rc":[{"batb":[[0,2.9,6.92]],"ltp":2.92,"tv":1171.82,"id":12636},{"batl":[[0,2.38,4]],"ltp":2.34,"tv":2636.7,"id":10107355}]}]}
{"op":"mcm","clk":"993259929","pt":1580539532859,"mc":[{"id":"1.168133543","rc":[{"batb":[[0,7.2,1.98]],"ltp":6.6,"tv":396.74,"id":22121325}]}]}
{"op":"mcm","clk":"993260112","pt":1580539537444,"mc":[{"id":"1.168133543","rc":[{"batb":[[0,2.9,58.05]],"ltp":2.92,"tv":1171.82,"id":12636}]}]}
{"op":"mcm","clk":"993260146","pt":1580539538473,"mc":[{"id":"1.168133543","rc":[{"batb":[[2,150,1.32]],"ltp":580.0,"tv":6.13,"id":27606066}]}]}
{"op":"mcm","clk":"993260725","pt":1580539552487,"mc":[{"id":"1.168133543","rc":[{"batb":[[0,2.9,6.92]],"ltp":2.92,"tv":1171.82,"id":12636},{"batb":[[1,150,1.35],[2,110,14.02]],"ltp":580.0,"tv":6.13,"id":27606066}]}]}
{"op":"mcm","clk":"993260776","pt":1580539553372,"mc":[{"id":"1.168133543","rc":[{"batb":[[0,65,1.11],[1,60,4.38]],"ltp":65.0,"tv":20.68,"id":22308007},{"batb":[[1,160,1.61],[2,150,1.32]],"ltp":580.0,"tv":6.13,"id":27606066}]}]}
{"op":"mcm","clk":"993260907","pt":1580539556357,"mc":[{"id":"1.168133543","rc":[{"batl":[[0,2.38,2],[1,2.4,2],[2,2.42,5.5]],"ltp":2.34,"tv":2636.7,"id":10107355}]}]}
{"op":"mcm","clk":"993261325","pt":1580539567381,"mc":[{"id":"1.168133543","rc":[{"batb":[[0,2.9,58.05]],"ltp":2.92,"tv":1171.82,"id":12636},{"batb":[[1,60,1.33]],"ltp":65.0,"tv":20.68,"id":22308007},{"batb":[[0,2.34,19.1],[1,2.32,34.73],[2,2.3,7.49]],"ltp":2.34,"tv":2636.7,"id":10107355},{"batb":[[1,170,1.52]],"ltp":580.0,"tv":6.13,"id":27606066}]}]}
{"op":"mcm","clk":"993261370","pt":1580539568372,"mc":[{"id":"1.168133543","rc":[{"batl":[[0,2.4,2],[1,2.42,5.5],[2,2.46,21]],"ltp":2.34,"tv":2636.7,"id":10107355},{"batl":[[2,10,15.8]],"ltp":6.6,"tv":396.74,"id":22121325}]}]}
{"op":"mcm","clk":"993261956","pt":1580539580491,"mc":[{"id":"1.168133543","rc":[{"batb":[[0,2.9,6.92]],"ltp":2.92,"tv":1171.82,"id":12636},{"batb":[[1,150,1.35],[2,110,14.02]],"ltp":580.0,"tv":6.13,"id":27606066}]}]}
{"op":"mcm","clk":"993262013","pt":1580539581516,"mc":[{"id":"1.168133543","rc":[{"batl":[[0,8.6,5.25],[1,8.8,2],[2,9.2,3.59]],"ltp":6.6,"tv":396.74,"id":22121325},{"batb":[[1,180,1.44],[2,150,1.32]],"ltp":580.0,"tv":6.13,"id":27606066}]}]}
{"op":"mcm","clk":"993262551","pt":1580539588710,"mc":[{"id":"1.168133543","rc":[{"batl":[[0,8.6,7.25],[1,9.2,3.59],[2,10,15.8]],"ltp":6.6,"tv":396.74,"id":22121325}]}]}
{"op":"mcm","clk":"993262779","pt":1580539591916,"mc":[{"id":"1.168133543","rc":[{"batb":[[1,2.32,26.11]],"batl":[[1,2.42,7.5]],"ltp":2.34,"tv":2636.7,"id":10107355}]}]}
{"op":"mcm","clk":"993262904","pt":1580539595513,"mc":[{"id":"1.168133543","rc":[{"batb":[[1,150,1.35],[2,110,14.02]],"ltp":580.0,"tv":6.13,"id":27606066}]}]}
{"op":"mcm","clk":"993262947","pt":1580539596388,"mc":[{"id":"1.168133543","rc":[{"batb":[[0,2.9,58.05]],"ltp":2.92,"tv":1171.82,"id":12636},{"batb":[[1,190,1.36],[2,150,1.32]],"ltp":580.0,"tv":6.13,"id":27606066}]}]}
{"op":"mcm","clk":"993263792","pt":1580539609520,"mc":[{"id":"1.168133543","rc":[{"batb":[[0,2.9,6.92]],"ltp":2.92,"tv":1171.82,"id":12636},{"batb":[[1,150,1.35],[2,110,14.02]],"ltp":580.0,"tv":6.13,"id":27606066}]}]}
{"op":"mcm","clk":"993263833","pt":1580539610242,"mc":[{"id":"1.168133543","rc":[{"batb":[[1,60,4.38]],"ltp":65.0,"tv":20.68,"id":22308007},{"batb":[[1,160,1.61],[2,150,1.32]],"ltp":580.0,"tv":6.13,"id":27606066}]}]}
{"op":"mcm","clk":"993264656","pt":1580539623545,"mc":[{"id":"1.168133543","rc":[{"batb":[[1,60,1.33]],"ltp":65.0,"tv":20.68,"id":22308007},{"batb":[[1,150,1.35],[2,110,14.02]],"ltp":580.0,"tv":6.13,"id":27606066}]}]}
{"op":"mcm","clk":"993264675","pt":1580539623852,"mc":[{"id":"1.168133543","rc":[{"batb":[[0,2.9,58.05]],"ltp":2.92,"tv":1171.82,"id":12636},{"batb":[[1,170,1.52],[2,150,1.32]],"ltp":580.0,"tv":6.13,"id":27606066}]}]}
{"op":"mcm","clk":"993265455","pt":1580539638557,"mc":[{"id":"1.168133543","rc":[{"batb":[[0,2.9,6.92]],"ltp":2.92,"tv":1171.82,"id":12636},{"batb":[[1,60,4.38]],"ltp":65.0,"tv":20.68,"id":22308007},{"batb":[[1,150,1.35],[2,110,14.02]],"ltp":580.0,"tv":6.13,"id":27606066}]}]}
{"op":"mcm","clk":"993265464","pt":1580539638609,"mc":[{"id":"1.168133543","rc":[{"batb":[[1,180,1.44],[2,150,1.32]],"ltp":580.0,"tv":6.13,"id":27606066}]}]}
{"op":"mcm","clk":"993266071","pt":1580539652568,"mc":[{"id":"1.168133543","rc":[{"batb":[[1,60,1.33]],"ltp":65.0,"tv":20.68,"id":22308007},{"batb":[[1,150,1.35],[2,110,14.02]],"ltp":580.0,"tv":6.13,"id":27606066}]}]}
{"op":"mcm","clk":"993266102","pt":1580539653034,"mc":[{"id":"1.168133543","rc":[{"batb":[[0,2.9,58.05]],"ltp":2.92,"tv":1171.82,"id":12636},{"batb":[[1,190,1.36],[2,150,1.32]],"ltp":580.0,"tv":6.13,"id":27606066}]}]}
{"op":"mcm","clk":"993266809","pt":1580539666533,"mc":[{"id":"1.168133543","rc":[{"batb":[[0,2.9,6.92]],"ltp":2.92,"tv":1171.82,"id":12636},{"batb":[[1,60,4.38]],"ltp":65.0,"tv":20.68,"id":22308007},{"batb":[[1,150,1.35],[2,110,14.02]],"ltp":580.0,"tv":6.13,"id":27606066}]}]}
{"op":"mcm","clk":"993266815","pt":1580539666637,"mc":[{"id":"1.168133543","rc":[{"batb":[[1,160,1.61],[2,150,1.32]],"ltp":580.0,"tv":6.13,"id":27606066}]}]}
{"op":"mcm","clk":"993267607","pt":1580539681559,"mc":[{"id":"1.168133543","rc":[{"batb":[[0,2.9,58.05]],"ltp":2.92,"tv":1171.82,"id":12636},{"batb":[[1,60,1.33]],"ltp":65.0,"tv":20.68,"id":22308007},{"batb":[[1,150,1.35],[2,110,14.02]],"ltp":580.0,"tv":6.13,"id":27606066}]}]}
{"op":"mcm","clk":"993267650","pt":1580539682488,"mc":[{"id":"1.168133543","rc":[{"batb":[[1,170,1.52],[2,150,1.32]],"ltp":580.0,"tv":6.13,"id":27606066}]}]}
{"op":"mcm","clk":"993268307","pt":1580539695510,"mc":[{"id":"1.168133543","rc":[{"batb":[[0,2.9,6.92]],"ltp":2.92,"tv":1171.82,"id":12636},{"batb":[[1,150,1.35],[2,110,14.02]],"ltp":580.0,"tv":6.13,"id":27606066}]}]}
{"op":"mcm","clk":"993268315","pt":1580539695714,"mc":[{"id":"1.168133543","rc":[{"batb":[[1,60,4.38]],"ltp":65.0,"tv":20.68,"id":22308007},{"batb":[[1,180,1.44],[2,150,1.32]],"ltp":580.0,"tv":6.13,"id":27606066}]}]}
{"op":"mcm","clk":"993268982","pt":1580539709789,"mc":[{"id":"1.168133543","rc":[{"batb":[[0,2.9,58.05]],"ltp":2.92,"tv":1171.82,"id":12636},{"batb":[[1,190,1.36]],"ltp":580.0,"tv":6.13,"id":27606066}]}]}
{"op":"mcm","clk":"993269313","pt":1580539716326,"mc":[{"id":"1.168133543","rc":[{"batb":[[0,2.36,7.3],[1,2.34,19.1],[2,2.32,26.11]],"ltp":2.34,"tv":2636.7,"id":10107355}]}]}
{"op":"mcm","clk":"993269375","pt":1580539717510,"mc":[{"id":"1.168133543","rc":[{"batl":[[1,2.42,5.5]],"ltp":2.34,"tv":2636.7,"id":10107355}]}]}
{"op":"mcm","clk":"993269661","pt":1580539724526,"mc":[{"id":"1.168133543","rc":[{"batb":[[0,2.9,6.92]],"ltp":2.92,"tv":1171.82,"id":12636},{"batb":[[1,150,1.35],[2,110,14.02]],"ltp":580.0,"tv":6.13,"id":27606066}]}]}
{"op":"mcm","clk":"993269664","pt":1580539724627,"mc":[{"id":"1.168133543","rc":[{"batb":[[1,160,1.61],[2,150,1.32]],"ltp":580.0,"tv":6.13,"id":27606066}]}]}
{"op":"mcm","clk":"993270181","pt":1580539738492,"mc":[{"id":"1.168133543","rc":[{"batb":[[1,150,1.35],[2,110,14.02]],"ltp":580.0,"tv":6.13,"id":27606066}]}]}
{"op":"mcm","clk":"993270196","pt":1580539738801,"mc":[{"id":"1.168133543","rc":[{"batb":[[0,2.9,58.05]],"ltp":2.92,"tv":1171.82,"id":12636},{"batb":[[1,170,1.52],[2,150,1.32]],"ltp":580.0,"tv":6.13,"id":27606066}]}]}
{"op":"mcm","clk":"993270774","pt":1580539751326,"mc":[{"id":"1.168133543","rc":[{"batb":[[1,170,1.63]],"ltp":580.0,"tv":6.13,"id":27606066}]}]}
{"op":"mcm","clk":"993270823","pt":1580539752510,"mc":[{"id":"1.168133543","rc":[{"batb":[[0,2.9,6.92]],"ltp":2.92,"tv":1171.82,"id":12636},{"batb":[[1,180,1.55]],"ltp":580.0,"tv":6.13,"id":27606066}]}]}
{"op":"mcm","clk":"993270964","pt":1580539755434,"mc":[{"id":"1.168133543","rc":[{"batl":[[0,8.6,5.25],[1,8.8,2],[2,9.2,3.59]],"ltp":6.6,"tv":396.74,"id":22121325}]}]}
{"op":"mcm","clk":"993271622","pt":1580539767830,"mc":[{"id":"1.168133543","rc":[{"batb":[[0,2.9,58.05]],"ltp":2.92,"tv":1171.82,"id":12636},{"batb":[[1,60,1.33]],"ltp":65.0,"tv":20.68,"id":22308007},{"batb":[[1,190,1.36],[2,150,1.43]],"ltp":580.0,"tv":6.13,"id":27606066}]}]}
{"op":"mcm","clk":"993272210","pt":1580539781479,"mc":[{"id":"1.168133543","rc":[{"batb":[[0,2.9,6.92]],"ltp":2.92,"tv":1171.82,"id":12636}]}]}
{"op":"mcm","clk":"993272218","pt":1580539781639,"mc":[{"id":"1.168133543","rc":[{"batb":[[1,60,4.38]],"ltp":65.0,"tv":20.68,"id":22308007}]}]}
{"op":"mcm","clk":"993272880","pt":1580539795553,"mc":[{"id":"1.168133543","rc":[{"batb":[[1,60,1.33]],"ltp":65.0,"tv":20.68,"id":22308007}]}]}
{"op":"mcm","clk":"993272885","pt":1580539795653,"mc":[{"id":"1.168133543","rc":[{"batb":[[0,2.9,58.05]],"ltp":2.92,"tv":1171.82,"id":12636}]}]}
{"op":"mcm","clk":"993273355","pt":1580539805271,"mc":[{"id":"1.168133543","rc":[{"batb":[[1,190,1.46],[2,150,1.32]],"ltp":580.0,"tv":6.13,"id":27606066}]}]}
{"op":"mcm","clk":"993273577","pt":1580539810478,"mc":[{"id":"1.168133543","rc":[{"batb":[[0,2.9,6.92]],"ltp":2.92,"tv":1171.82,"id":12636},{"batb":[[1,150,1.45],[2,110,14.02]],"ltp":580.0,"tv":6.13,"id":27606066}]}]}
{"op":"mcm","clk":"993273639","pt":1580539811505,"mc":[{"id":"1.168133543","rc":[{"batb":[[1,60,4.38]],"ltp":65.0,"tv":20.68,"id":22308007},{"batb":[[1,200,1.4],[2,150,1.32]],"ltp":580.0,"tv":6.13,"id":27606066}]}]}
{"op":"mcm","clk":"993274153","pt":1580539824501,"mc":[{"id":"1.168133543","rc":[{"batb":[[1,60,1.33]],"ltp":65.0,"tv":20.68,"id":22308007},{"batb":[[1,150,1.45],[2,110,14.02]],"ltp":580.0,"tv":6.13,"id":27606066}]}]}
{"op":"mcm","clk":"993274164","pt":1580539824707,"mc":[{"id":"1.168133543","rc":[{"batb":[[0,2.9,58.05]],"ltp":2.92,"tv":1171.82,"id":12636},{"batb":[[1,210,1.24],[2,150,1.42]],"ltp":580.0,"tv":6.13,"id":27606066}]}]}
{"op":"mcm","clk":"993274788","pt":1580539839230,"mc":[{"id":"1.168133543","rc":[{"batb":[[0,2.9,6.92]],"ltp":2.92,"tv":1171.82,"id":12636},{"batb":[[1,60,4.38]],"ltp":65.0,"tv":20.68,"id":22308007},{"batb":[[1,160,1.71],[2,150,1.32]],"ltp":580.0,"tv":6.13,"id":27606066}]}]}
{"op":"mcm","clk":"993274930","pt":1580539841918,"mc":[{"id":"1.168133543","rc":[{"batl":[[0,330,5.39],[1,1000,2]],"ltp":280.0,"tv":1.54,"id":24270700}]}]}
{"op":"mcm","clk":"993275093","pt":1580539845517,"mc":[{"id":"1.168133543","rc":[{"batl":[[1,9.2,3.59],[2,10,15.8]],"ltp":6.6,"tv":396.74,"id":22121325}]}]}
{"op":"mcm","clk":"993275095","pt":1580539845617,"mc":[{"id":"1.168133543","rc":[{"batl":[[0,8.6,7.25]],"ltp":6.6,"tv":396.74,"id":22121325}]}]}
{"op":"mcm","clk":"993275462","pt":1580539853549,"mc":[{"id":"1.168133543","rc":[{"batb":[[1,150,1.45],[2,110,14.02]],"ltp":580.0,"tv":6.13,"id":27606066}]}]}
{"op":"mcm","clk":"993275471","pt":1580539853704,"mc":[{"id":"1.168133543","rc":[{"batb":[[0,2.9,58.05]],"ltp":2.92,"tv":1171.82,"id":12636},{"batb":[[1,170,1.62],[2,150,1.32]],"ltp":580.0,"tv":6.13,"id":27606066}]}]}
{"op":"mcm","clk":"993275680","pt":1580539859310,"mc":[{"id":"1.168133543","rc":[{"batb":[[1,170,1.63]],"ltp":580.0,"tv":6.13,"id":27606066}]}]}
{"op":"mcm","clk":"993276050","pt":1580539867553,"mc":[{"id":"1.168133543","rc":[{"batb":[[0,2.9,6.92]],"ltp":2.92,"tv":1171.82,"id":12636},{"batb":[[1,180,1.55]],"ltp":580.0,"tv":6.13,"id":27606066}]}]}
{"op":"mcm","clk":"993276598","pt":1580539881571,"mc":[{"id":"1.168133543","rc":[{"batb":[[1,150,1.46],[2,110,14.02]],"ltp":580.0,"tv":6.13,"id":27606066}]}]}
{"op":"mcm","clk":"993276606","pt":1580539881777,"mc":[{"id":"1.168133543","rc":[{"batb":[[0,2.9,58.05]],"ltp":2.92,"tv":1171.82,"id":12636},{"batb":[[1,190,1.36],[2,150,1.43]],"ltp":580.0,"tv":6.13,"id":27606066}]}]}
{"op":"mcm","clk":"993277229","pt":1580539896587,"mc":[{"id":"1.168133543","rc":[{"batb":[[0,2.9,6.92]],"ltp":2.92,"tv":1171.82,"id":12636}]}]}
{"op":"mcm","clk":"993277867","pt":1580539910613,"mc":[{"id":"1.168133543","rc":[{"batb":[[0,2.9,58.05]],"ltp":2.92,"tv":1171.82,"id":12636}]}]}
{"op":"mcm","clk":"993277934","pt":1580539912002,"mc":[{"id":"1.168133543","rc":[{"batb":[[1,190,1.46],[2,150,1.32]],"ltp":580.0,"tv":6.13,"id":27606066}]}]}
{"op":"mcm","clk":"993278514","pt":1580539924626,"mc":[{"id":"1.168133543","rc":[{"batb":[[0,2.9,6.92]],"ltp":2.92,"tv":1171.82,"id":12636},{"batb":[[1,200,1.4]],"ltp":580.0,"tv":6.13,"id":27606066}]}]}
{"op":"mcm","clk":"993278647","pt":1580539927356,"mc":[{"id":"1.168133543","rc":[{"batl":[[0,8.6,5.25],[1,8.8,2],[2,9.2,3.59]],"ltp":6.6,"tv":396.74,"id":22121325}]}]}
{"op":"mcm","clk":"993279243","pt":1580539939787,"mc":[{"id":"1.168133543","rc":[{"batb":[[0,2.9,58.05]],"ltp":2.92,"tv":1171.82,"id":12636},{"batb":[[1,210,1.24],[2,150,1.42]],"ltp":580.0,"tv":6.13,"id":27606066}]}]}
{"op":"mcm","clk":"993279389","pt":1580539943390,"mc":[{"id":"1.168133543","rc":[{"batl":[[0,8.6,7.25],[1,9.2,3.59],[2,10,15.8]],"ltp":6.6,"tv":396.74,"id":22121325}]}]}
{"op":"mcm","clk":"993289681","pt":1580539953369,"mc":[{"id":"1.168133543","rc":[{"batb":[[0,2.9,6.92]],"ltp":2.92,"tv":1171.82,"id":12636},{"batb":[[1,150,1.45],[2,110,14.02]],"ltp":580.0,"tv":6.13,"id":27606066}]}]}
{"op":"mcm","clk":"993289688","pt":1580539953577,"mc":[{"id":"1.168133543","rc":[{"batb":[[1,160,1.71],[2,150,1.32]],"ltp":580.0,"tv":6.13,"id":27606066}]}]}
{"op":"mcm","clk":"993289940","pt":1580539959503,"mc":[{"id":"1.168133543","rc":[{"batl":[[0,8.6,5.25],[1,8.8,2],[2,9.2,3.59]],"ltp":6.6,"tv":396.74,"id":22121325}]}]}
{"op":"mcm","clk":"993290161","pt":1580539965539,"mc":[{"id":"1.168133543","rc":[{"batb":[[1,160,1.61]],"ltp":580.0,"tv":6.13,"id":27606066}]}]}
{"op":"mcm","clk":"993290166","pt":1580539965643,"mc":[{"id":"1.168133543","rc":[{"batb":[[1,160,1.73]],"ltp":580.0,"tv":6.13,"id":27606066}]}]}
{"op":"mcm","clk":"993290240","pt":1580539967548,"mc":[{"id":"1.168133543","rc":[{"batb":[[1,150,1.47],[2,110,14.02]],"ltp":580.0,"tv":6.13,"id":27606066}]}]}
{"op":"mcm","clk":"993290252","pt":1580539967710,"mc":[{"id":"1.168133543","rc":[{"batb":[[0,2.9,58.05]],"ltp":2.92,"tv":1171.82,"id":12636},{"batb":[[1,170,1.64],[2,150,1.32]],"ltp":580.0,"tv":6.13,"id":27606066}]}]}
{"op":"mcm","clk":"993290833","pt":1580539978047,"mc":[{"id":"1.168133543","rc":[{"batl":[[0,8.6,7.25],[1,9.2,3.59],[2,10,15.8]],"ltp":6.6,"tv":396.74,"id":22121325}]}]}
{"op":"mcm","clk":"993291077","pt":1580539982532,"mc":[{"id":"1.168133543","rc":[{"batb":[[0,2.9,6.92]],"ltp":2.92,"tv":1171.82,"id":12636},{"batb":[[1,180,1.44],[2,150,1.44]],"ltp":580.0,"tv":6.13,"id":27606066}]}]}
{"op":"mcm","clk":"993291280","pt":1580539986084,"mc":[{"id":"1.168133543","rc":[{"batl":[[0,8.6,5.25],[1,8.8,2],[2,9.2,3.59]],"ltp":6.6,"tv":396.74,"id":22121325}]}]}
{"op":"mcm","clk":"993291842","pt":1580539996861,"mc":[{"id":"1.168133543","rc":[{"batb":[[0,2.9,58.05]],"ltp":2.92,"tv":1171.82,"id":12636},{"batb":[[1,190,1.36]],"ltp":580.0,"tv":6.13,"id":27606066}]}]}
{"op":"mcm","clk":"993292179","pt":1580540002883,"mc":[{"id":"1.168133543","rc":[{"batl":[[0,8.6,7.25],[1,9.2,3.59],[2,10,15.8]],"ltp":6.6,"tv":396.74,"id":22121325}]}]}
{"op":"mcm","clk":"993292628","pt":1580540010479,"mc":[{"id":"1.168133543","rc":[{"batb":[[0,2.9,6.92]],"ltp":2.92,"tv":1171.82,"id":12636},{"batb":[[1,150,1.47],[2,110,14.02]],"ltp":580.0,"tv":6.13,"id":27606066}]}]}
{"op":"mcm","clk":"993292636","pt":1580540010583,"mc":[{"id":"1.168133543","rc":[{"batb":[[1,180,1.44],[2,150,1.44]],"ltp":580.0,"tv":6.13,"id":27606066}]}]}
{"op":"mcm","clk":"993293063","pt":1580540019494,"mc":[{"id":"1.168133543","rc":[{"batl":[[0,8.6,5.25]],"ltp":6.6,"tv":396.74,"id":22121325}]}]}
{"op":"mcm","clk":"993293081","pt":1580540019800,"mc":[{"id":"1.168133543","rc":[{"batl":[[1,8.8,2],[2,9.2,3.59]],"ltp":6.6,"tv":396.74,"id":22121325},{"batb":[[2,150,1.32]],"ltp":580.0,"tv":6.13,"id":27606066}]}]}
{"op":"mcm","clk":"993293365","pt":1580540025527,"mc":[{"id":"1.168133543","rc":[{"batb":[[0,2.9,58.05]],"ltp":2.92,"tv":1171.82,"id":12636},{"batb":[[1,150,1.35],[2,110,14.02]],"ltp":580.0,"tv":6.13,"id":27606066}]}]}
{"op":"mcm","clk":"993293367","pt":1580540025626,"mc":[{"id":"1.168133543","rc":[{"batb":[[1,190,1.36],[2,150,1.32]],"ltp":580.0,"tv":6.13,"id":27606066}]}]}
{"op":"mcm","clk":"993293921","pt":1580540036476,"mc":[{"id":"1.168133543","rc":[{"batl":[[0,8.6,7.25],[1,9.2,3.59],[2,10,15.8]],"ltp":6.6,"tv":396.74,"id":22121325}]}]}
{"op":"mcm","clk":"993294305","pt":1580540044518,"mc":[{"id":"1.168133543","rc":[{"batb":[[0,2.9,6.92]],"ltp":2.92,"tv":1171.82,"id":12636},{"batb":[[1,150,1.35],[2,110,14.02]],"ltp":580.0,"tv":6.13,"id":27606066}]}]}
{"op":"mcm","clk":"993294315","pt":1580540044722,"mc":[{"id":"1.168133543","rc":[{"batl":[[0,8.6,5.25],[1,8.8,2],[2,9.2,3.59]],"ltp":6.6,"tv":396.74,"id":22121325},{"batb":[[1,160,1.61],[2,150,1.32]],"ltp":580.0,"tv":6.13,"id":27606066}]}]}
{"op":"mcm","clk":"993295018","pt":1580540058503,"mc":[{"id":"1.168133543","rc":[{"batb":[[1,150,1.35],[2,110,14.02]],"ltp":580.0,"tv":6.13,"id":27606066}]}]}
{"op":"mcm","clk":"993295028","pt":1580540058711,"mc":[{"id":"1.168133543","rc":[{"batb":[[0,2.9,58.05]],"ltp":2.92,"tv":1171.82,"id":12636},{"batb":[[1,170,1.52],[2,150,1.32]],"ltp":580.0,"tv":6.13,"id":27606066}]}]}
{"op":"mcm","clk":"993295599","pt":1580540070437,"mc":[{"id":"1.168133543","rc":[{"batl":[[0,8.6,7.25],[1,9.2,3.59],[2,10,15.8]],"ltp":6.6,"tv":396.74,"id":22121325}]}]}
{"op":"mcm","clk":"993295706","pt":1580540072553,"mc":[{"id":"1.168133543","rc":[{"batb":[[0,2.9,6.92]],"ltp":2.92,"tv":1171.82,"id":12636},{"batb":[[1,180,1.44]],"ltp":580.0,"tv":6.13,"id":27606066}]}]}
{"op":"mcm","clk":"993296370","pt":1580540087489,"mc":[{"id":"1.168133543","rc":[{"batl":[[0,8.6,5.25],[1,8.8,2],[2,9.2,3.59]],"ltp":6.6,"tv":396.74,"id":22121325},{"batb":[[1,150,1.35],[2,110,14.02]],"ltp":580.0,"tv":6.13,"id":27606066}]}]}
{"op":"mcm","clk":"993296419","pt":1580540088319,"mc":[{"id":"1.168133543","rc":[{"batb":[[0,2.9,58.05]],"ltp":2.92,"tv":1171.82,"id":12636},{"batb":[[1,190,1.36],[2,150,1.32]],"ltp":580.0,"tv":6.13,"id":27606066}]}]}
{"op":"mcm","clk":"993296745","pt":1580540095112,"mc":[{"id":"1.168133543","rc":[{"batl":[[0,8.6,7.25],[1,9.2,3.59],[2,10,15.8]],"ltp":6.6,"tv":396.74,"id":22121325}]}]}
{"op":"mcm","clk":"993297092","pt":1580540101518,"mc":[{"id":"1.168133543","rc":[{"batb":[[0,2.9,6.92]],"ltp":2.92,"tv":1171.82,"id":12636},{"batb":[[1,150,1.35],[2,110,14.02]],"ltp":580.0,"tv":6.13,"id":27606066}]}]}
{"op":"mcm","clk":"993297097","pt":1580540101623,"mc":[{"id":"1.168133543","rc":[{"batb":[[1,160,1.61],[2,150,1.32]],"ltp":580.0,"tv":6.13,"id":27606066}]}]}
{"op":"mcm","clk":"993297794","pt":1580540115835,"mc":[{"id":"1.168133543","rc":[{"batb":[[0,2.9,58.05]],"ltp":2.92,"tv":1171.82,"id":12636},{"batb":[[1,170,1.52]],"ltp":580.0,"tv":6.13,"id":27606066}]}]}
{"op":"mcm","clk":"993298433","pt":1580540127674,"mc":[{"id":"1.168133543","rc":[{"batb":[[1,170,1.63]],"ltp":580.0,"tv":6.13,"id":27606066}]}]}
{"op":"mcm","clk":"993298600","pt":1580540130555,"mc":[{"id":"1.168133543","rc":[{"batb":[[0,2.9,6.92]],"ltp":2.92,"tv":1171.82,"id":12636},{"batb":[[1,150,1.46],[2,110,14.02]],"ltp":580.0,"tv":6.13,"id":27606066}]}]}
{"op":"mcm","clk":"993298606","pt":1580540130660,"mc":[{"id":"1.168133543","rc":[{"batb":[[1,180,1.55],[2,150,1.32]],"ltp":580.0,"tv":6.13,"id":27606066}]}]}
{"op":"mcm","clk":"993299374","pt":1580540144822,"mc":[{"id":"1.168133543","rc":[{"batb":[[0,2.9,58.05]],"ltp":2.92,"tv":1171.82,"id":12636},{"batb":[[1,190,1.36],[2,150,1.43]],"ltp":580.0,"tv":6.13,"id":27606066}]}]}
{"op":"mcm","clk":"993300073","pt":1580540158636,"mc":[{"id":"1.168133543","rc":[{"batb":[[0,2.9,6.92]],"ltp":2.92,"tv":1171.82,"id":12636}]}]}
{"op":"mcm","clk":"993300802","pt":1580540173456,"mc":[{"id":"1.168133543","rc":[{"batb":[[0,2.9,58.05]],"ltp":2.92,"tv":1171.82,"id":12636}]}]}
{"op":"mcm","clk":"993301155","pt":1580540179465,"mc":[{"id":"1.168133543","rc":[{"batl":[[0,8.6,5.25],[1,8.8,2],[2,9.2,3.59]],"ltp":6.6,"tv":396.74,"id":22121325}]}]}
{"op":"mcm","clk":"993301599","pt":1580540187576,"mc":[{"id":"1.168133543","rc":[{"batb":[[0,2.9,6.92]],"ltp":2.92,"tv":1171.82,"id":12636}]}]}
{"op":"mcm","clk":"993302243","pt":1580540199555,"mc":[{"id":"1.168133543","rc":[{"batb":[[2,150,1.32]],"ltp":580.0,"tv":6.13,"id":27606066}]}]}
{"op":"mcm","clk":"993302344","pt":1580540201565,"mc":[{"id":"1.168133543","rc":[{"batb":[[0,2.9,58.05]],"ltp":2.92,"tv":1171.82,"id":12636},{"batb":[[1,150,1.35],[2,110,14.02]],"ltp":580.0,"tv":6.13,"id":27606066}]}]}
{"op":"mcm","clk":"993302351","pt":1580540201671,"mc":[{"id":"1.168133543","rc":[{"batb":[[1,160,1.61],[2,150,1.32]],"ltp":580.0,"tv":6.13,"id":27606066}]}]}
{"op":"mcm","clk":"993302918","pt":1580540213078,"mc":[{"id":"1.168133543","rc":[{"batl":[[0,8.6,7.25],[1,9.2,3.59],[2,10,15.8]],"ltp":6.6,"tv":396.74,"id":22121325}]}]}
{"op":"mcm","clk":"993303346","pt":1580540220574,"mc":[{"id":"1.168133543","rc":[{"batb":[[0,2.9,6.92]],"ltp":2.92,"tv":1171.82,"id":12636},{"batb":[[1,150,1.35],[2,110,14.02]],"ltp":580.0,"tv":6.13,"id":27606066}]}]}
{"op":"mcm","clk":"993303354","pt":1580540220678,"mc":[{"id":"1.168133543","rc":[{"batb":[[1,170,1.52],[2,150,1.32]],"ltp":580.0,"tv":6.13,"id":27606066}]}]}
{"op":"mcm","clk":"993304213","pt":1580540235510,"mc":[{"id":"1.168133543","rc":[{"batb":[[0,2.9,58.05]],"ltp":2.92,"tv":1171.82,"id":12636},{"batb":[[1,150,1.35],[2,110,14.02]],"ltp":580.0,"tv":6.13,"id":27606066}]}]}
{"op":"mcm","clk":"993304219","pt":1580540235612,"mc":[{"id":"1.168133543","rc":[{"batb":[[1,180,1.44],[2,150,1.32]],"ltp":580.0,"tv":6.13,"id":27606066}]}]}
{"op":"mcm","clk":"993304360","pt":1580540238141,"mc":[{"id":"1.168133543","rc":[{"batl":[[0,8.6,5.25],[1,8.8,2],[2,9.2,3.59]],"ltp":6.6,"tv":396.74,"id":22121325}]}]}
{"op":"mcm","clk":"993304945","pt":1580540249558,"mc":[{"id":"1.168133543","rc":[{"batb":[[0,2.9,6.92]],"ltp":2.92,"tv":1171.82,"id":12636},{"batb":[[1,190,1.36]],"ltp":580.0,"tv":6.13,"id":27606066}]}]}
{"op":"mcm","clk":"993305567","pt":1580540263558,"mc":[{"id":"1.168133543","rc":[{"batb":[[0,2.9,58.05]],"ltp":2.92,"tv":1171.82,"id":12636},{"batl":[[0,8.6,7.25],[1,9.2,3.59],[2,10,15.8]],"ltp":6.6,"tv":396.74,"id":22121325},{"batb":[[1,150,1.35],[2,110,14.02]],"ltp":580.0,"tv":6.13,"id":27606066}]}]}
{"op":"mcm","clk":"993305572","pt":1580540263660,"mc":[{"id":"1.168133543","rc":[{"batb":[[1,160,1.61],[2,150,1.32]],"ltp":580.0,"tv":6.13,"id":27606066}]}]}
{"op":"mcm","clk":"993305670","pt":1580540265976,"mc":[{"id":"1.168133543","rc":[{"trd":[[2.36,260.9]],"batb":[[0,2.34,19.1],[1,2.32,26.11],[2,2.26,4.46]],"ltp":2.36,"tv":2651.3,"id":10107355}],"tv":4697.03}]}
{"op":"mcm","clk":"993306104","pt":1580540275191,"mc":[{"id":"1.168133543","rc":[{"trd":[[2.34,399.86]],"batb":[[0,2.32,26.23],[1,2.26,4.46],[2,2.24,5.28]],"ltp":2.34,"tv":2689.28,"id":10107355}],"tv":4735.0}]}
{"op":"mcm","clk":"993306248","pt":1580540278490,"mc":[{"id":"1.168133543","rc":[{"batb":[[0,2.9,6.92]],"ltp":2.92,"tv":1171.82,"id":12636},{"batb":[[2,6.8,2.95]],"ltp":6.6,"tv":396.74,"id":22121325},{"batb":[[1,150,1.35],[2,110,14.02]],"ltp":580.0,"tv":6.13,"id":27606066}]}]}
{"op":"mcm","clk":"993306272","pt":1580540279002,"mc":[{"id":"1.168133543","rc":[{"batb":[[1,170,1.52],[2,150,1.32]],"ltp":580.0,"tv":6.13,"id":27606066}]}]}
{"op":"mcm","clk":"993306328","pt":1580540280285,"mc":[{"id":"1.168133543","rc":[{"batl":[[0,8.6,5.25],[1,8.8,2],[2,9.2,3.59]],"ltp":6.6,"tv":396.74,"id":22121325}]}]}
{"op":"mcm","clk":"993306604","pt":1580540286498,"mc":[{"id":"1.168133543","rc":[{"trd":[[2.92,159.86]],"batl":[[0,2.92,32.58]],"ltp":2.92,"tv":1184.54,"id":12636},{"trd":[[2.32,143.1],[2.34,400.1],[2.38,152.01],[2.4,33.69]],"batb":[[0,2.32,6.23]],"batl":[[0,2.42,5.5],[1,2.46,21],[2,2.48,50]],"ltp":2.4,"tv":2744.82,"id":10107355},{"trd":[[8.6,5.44]],"batl":[[0,8.6,3.11]],"ltp":8.6,"tv":401.02,"id":22121325}],"tv":4807.55}]}
{"op":"mcm","clk":"993306614","pt":1580540286909,"mc":[{"id":"1.168133543","rc":[{"trd":[[190,0.48]],"batl":[[0,200,1.72]],"ltp":190.0,"tv":20.7,"id":22308007},{"trd":[[9.8,26.63]],"batl":[[0,9.8,13.04]],"ltp":9.8,"tv":382.5,"id":10163711},{"trd":[[160,2.42]],"batl":[[0,160,2.79]],"ltp":160.0,"tv":7.78,"id":26548208}],"tv":4811.59}]}
{"op":"mcm","clk":"993306666","pt":1580540288297,"mc":[{"id":"1.168133543","rc":[{"batl":[[0,2.4,2],[1,2.42,5.5],[2,2.46,21]],"ltp":2.4,"tv":2744.82,"id":10107355},{"batb":[[0,7.2,2.27]],"ltp":8.6,"tv":401.02,"id":22121325}]}]}
{"op":"mcm","clk":"993306777","pt":1580540291545,"mc":[{"id":"1.168133543","rc":[{"batb":[[0,7.2,4.48]],"ltp":8.6,"tv":401.02,"id":22121325}]}]}
{"op":"mcm","clk":"993306817","pt":1580540292524,"mc":[{"id":"1.168133543","rc":[{"batb":[[0,2.9,58.05]],"ltp":2.92,"tv":1184.54,"id":12636},{"batb":[[0,65,1.12]],"ltp":190.0,"tv":20.7,"id":22308007},{"batb":[[0,7.4,2.61],[1,7.2,4.19],[2,7,2.27]],"ltp":8.6,"tv":401.02,"id":22121325},{"batb":[[1,150,1.35],[2,110,14.02]],"ltp":580.0,"tv":6.13,"id":27606066}]}]}
{"op":"mcm","clk":"993306832","pt":1580540292934,"mc":[{"id":"1.168133543","rc":[{"batb":[[1,180,1.44],[2,150,1.32]],"ltp":580.0,"tv":6.13,"id":27606066}]}]}
{"op":"mcm","clk":"993307392","pt":1580540306539,"mc":[{"id":"1.168133543","rc":[{"batb":[[0,2.9,6.92]],"ltp":2.92,"tv":1184.54,"id":12636},{"batb":[[1,150,1.35],[2,110,14.02]],"ltp":580.0,"tv":6.13,"id":27606066}]}]}
{"op":"mcm","clk":"993307422","pt":1580540307060,"mc":[{"id":"1.168133543","rc":[{"batb":[[1,190,1.36],[2,150,1.32]],"ltp":580.0,"tv":6.13,"id":27606066}]}]}
{"op":"mcm","clk":"993307542","pt":1580540310241,"mc":[{"id":"1.168133543","rc":[{"trd":[[2.32,151.1]],"batb":[[0,2.32,2.22]],"ltp":2.32,"tv":2752.82,"id":10107355}],"tv":4819.59}]}
{"op":"mcm","clk":"993307609","pt":1580540311472,"mc":[{"id":"1.168133543","rc":[{"batb":[[0,7.6,1.98],[1,7.4,2.61],[2,7.2,2.21]],"ltp":8.6,"tv":401.02,"id":22121325}]}]}
{"op":"mcm","clk":"993307687","pt":1580540313378,"mc":[{"id":"1.168133543","rc":[{"batb":[[0,7.6,4.07],[2,7,2.27]],"ltp":8.6,"tv":401.02,"id":22121325}]}]}
{"op":"mcm","clk":"993308035","pt":1580540321553,"mc":[{"id":"1.168133543","rc":[{"batb":[[0,2.9,58.05]],"ltp":2.92,"tv":1184.54,"id":12636},{"batb":[[1,150,1.35],[2,110,14.02]],"ltp":580.0,"tv":6.13,"id":27606066}]}]}
{"op":"mcm","clk":"993308038","pt":1580540321655,"mc":[{"id":"1.168133543","rc":[{"batb":[[1,160,1.61],[2,150,1.32]],"ltp":580.0,"tv":6.13,"id":27606066}]}]}
{"op":"mcm","clk":"993308442","pt":1580540332468,"mc":[{"id":"1.168133543","rc":[{"trd":[[2.92,190.52]],"batl":[[0,2.92,17.25]],"ltp":2.92,"tv":1215.2,"id":12636},{"trd":[[9.8,35.73]],"batl":[[0,9.8,8.49]],"ltp":9.8,"tv":391.6,"id":10163711},{"trd":[[2.32,193.99]],"batb":[[0,2.26,4.46],[1,2.24,5.28],[2,2.22,6]],"batl":[[0,2.32,23.56],[1,2.4,2],[2,2.42,5.5]],"ltp":2.32,"tv":2795.71,"id":10107355},{"trd":[[8.6,11.66],[8.8,123.98]],"batl":[[0,9.2,3.59],[1,10,15.8],[2,11.5,3.08]],"ltp":8.8,"tv":411.24,"id":22121325},{"trd":[[160,2.98]],"batl":[[0,160,2.51]],"ltp":160.0,"tv":8.34,"id":26548208}],"tv":4913.02}]}
{"op":"mcm","clk":"993308494","pt":1580540333800,"mc":[{"id":"1.168133543","rc":[{"batb":[[0,60,5.08],[1,55,1.07],[2,29,16.6]],"ltp":190.0,"tv":20.7,"id":22308007}]}]}
{"op":"mcm","clk":"993308562","pt":1580540335494,"mc":[{"id":"1.168133543","rc":[{"batb":[[0,2.9,6.92]],"ltp":2.92,"tv":1215.2,"id":12636},{"batb":[[1,170,1.52]],"ltp":580.0,"tv":6.13,"id":27606066}]}]}
{"op":"mcm","clk":"993308707","pt":1580540338477,"mc":[{"id":"1.168133543","rc":[{"trd":[[2.92,218.32]],"batl":[[0,2.92,3.35]],"ltp":2.92,"tv":1243.0,"id":12636}],"tv":4940.82}]}
{"op":"mcm","clk":"993308750","pt":1580540339501,"mc":[{"id":"1.168133543","rc":[{"batb":[[1,2.88,26.03]],"ltp":2.92,"tv":1243.0,"id":12636},{"batb":[[0,80,1.39],[1,60,4.72],[2,55,1.07]],"ltp":190.0,"tv":20.7,"id":22308007}]}]}
{"op":"mcm","clk":"993308759","pt":1580540339810,"mc":[{"id":"1.168133543","rc":[{"batb":[[1,170,1.63]],"ltp":580.0,"tv":6.13,"id":27606066}]}]}
{"op":"mcm","clk":"993308995","pt":1580540344527,"mc":[{"id":"1.168133543","rc":[{"trd":[[2.26,163]],"batb":[[0,2.24,5.28],[1,2.22,6],[2,2.2,104]],"batl":[[0,2.26,13.08]],"ltp":2.26,"tv":2816.67,"id":10107355}],"tv":4961.78}]}
{"op":"mcm","clk":"993309027","pt":1580540345092,"mc":[{"id":"1.168133543","rc":[{"trd":[[2.92,225.02],[2.94,197.35]],"batl":[[0,2.94,51.33],[1,2.96,50],[2,2.98,50]],"ltp":2.94,"tv":1263.08,"id":12636},{"trd":[[9.8,41.75]],"batl":[[0,9.8,5.47]],"ltp":9.8,"tv":397.63,"id":10163711},{"trd":[[2.26,189.16]],"batl":[[0,2.4,2],[1,2.42,5.5],[2,2.46,21]],"ltp":2.26,"tv":2842.83,"id":10107355},{"trd":[[9,7.82],[9.2,6.32]],"batb":[[0,7.8,7.17],[1,7.6,4.07],[2,7.4,2.61]],"batl":[[0,10,15.8],[1,11.5,3.08],[2,12,3]],"ltp":9.2,"tv":417.65,"id":22121325},{"trd":[[160,3.36]],"batl":[[0,160,2.32]],"ltp":160.0,"tv":8.72,"id":26548208}],"tv":5020.84}]}
{"op":"mcm","clk":"993309102","pt":1580540346426,"mc":[{"id":"1.168133543","rc":[{"batl":[[0,2.38,4]],"ltp":2.26,"tv":2842.83,"id":10107355},{"batl":[[0,10,15.98]],"ltp":9.2,"tv":417.65,"id":22121325}]}]}
{"op":"mcm","clk":"993309110","pt":1580540346628,"mc":[{"id":"1.168133543","rc":[{"batb":[[0,7.6,4.07],[1,7.4,2.61],[2,7,2.27]],"ltp":9.2,"tv":417.65,"id":22121325}]}]}
{"op":"mcm","clk":"993309200","pt":1580540348525,"mc":[{"id":"1.168133543","rc":[{"batl":[[0,2.26,15],[1,2.38,4],[2,2.42,5.5]],"ltp":2.26,"tv":2842.83,"id":10107355}]}]}
{"op":"mcm","clk":"993309255","pt":1580540349502,"mc":[{"id":"1.168133543","rc":[{"batb":[[1,60,1.66]],"ltp":190.0,"tv":20.7,"id":22308007},{"batb":[[0,7.6,4.27]],"ltp":9.2,"tv":417.65,"id":22121325},{"batb":[[1,150,1.46],[2,110,14.02]],"ltp":580.0,"tv":6.13,"id":27606066}]}]}
{"op":"mcm","clk":"993309266","pt":1580540349708,"mc":[{"id":"1.168133543","rc":[{"batb":[[1,65,3.16],[2,60,1.33]],"ltp":190.0,"tv":20.7,"id":22308007},{"batb":[[1,180,1.55],[2,150,1.32]],"ltp":580.0,"tv":6.13,"id":27606066}]}]}
{"op":"mcm","clk":"993309390","pt":1580540352727,"mc":[{"id":"1.168133543","rc":[{"batl":[[1,2.34,12],[2,2.38,4]],"ltp":2.26,"tv":2842.83,"id":10107355}]}]}
{"op":"mcm","clk":"993309515","pt":1580540355555,"mc":[{"id":"1.168133543","rc":[{"trd":[[2.94,220.41]],"batl":[[0,2.94,39.8]],"ltp":2.94,"tv":1286.14,"id":12636},{"batb":[[0,80,1.79]],"ltp":190.0,"tv":20.7,"id":22308007},{"batb":[[0,60,2.2]],"ltp":60.0,"tv":31.75,"id":7226819},{"trd":[[9.8,48.67]],"batl":[[0,9.8,2.01]],"ltp":9.8,"tv":404.55,"id":10163711},{"trd":[[2.26,219.16]],"batb":[[0,2.24,5.29]],"batl":[[0,2.34,14],[1,2.38,2],[2,2.42,5.5]],"ltp":2.26,"tv":2872.83,"id":10107355},{"trd":[[9.6,0.36],[9.8,10.46]],"batb":[[0,9.8,3.15],[1,7.6,4.27],[2,7.4,2.61]],"batl":[[0,10,15.67]],"ltp":9.8,"tv":418.27,"id":22121325},{"batb":[[0,95,1.35]],"ltp":160.0,"tv":8.72,"id":26548208},{"batb":[[0,230,1.03],[1,180,1.78]],"ltp":580.0,"tv":6.13,"id":27606066},{"batb":[[0,230,2.66]],"ltp":280.0,"tv":1.54,"id":24270700},{"batb":[[0,160,1.75]],"ltp":160.0,"tv":19.01,"id":13306150}],"tv":5081.43}]}
{"op":"mcm","clk":"993309584","pt":1580540356542,"mc":[{"id":"1.168133543","rc":[{"trd":[[2.26,219.18]],"batb":[[0,2.24,5.28]],"batl":[[0,2.32,11.83],[1,2.34,14],[2,2.38,2]],"ltp":2.26,"tv":2872.85,"id":10107355},{"batb":[[1,7.6,2.18]],"ltp":9.8,"tv":418.27,"id":22121325}],"tv":5081.45}]}
{"op":"mcm","clk":"993309637","pt":1580540357417,"mc":[{"id":"1.168133543","rc":[{"batl":[[0,330,5.19]],"ltp":280.0,"tv":1.54,"id":24270700}]}]}
{"op":"mcm","clk":"993309683","pt":1580540358340,"mc":[{"id":"1.168133543","rc":[{"batb":[[0,85,1.43],[1,65,3.52]],"ltp":190.0,"tv":20.7,"id":22308007},{"batb":[[1,7.6,2.31]],"ltp":9.8,"tv":418.27,"id":22121325},{"batb":[[0,100,1.05],[1,90,2.61]],"ltp":160.0,"tv":8.72,"id":26548208}]}]}
{"op":"mcm","clk":"993309956","pt":1580540363228,"mc":[{"id":"1.168133543","rc":[{"batb":[[0,60,16.2],[2,48,2.2]],"ltp":60.0,"tv":31.75,"id":7226819},{"batl":[[0,2.3,2],[1,2.32,11.83],[2,2.34,14]],"ltp":2.26,"tv":2872.85,"id":10107355}]}]}
{"op":"mcm","clk":"993309993","pt":1580540364560,"mc":[{"id":"1.168133543","rc":[{"batb":[[1,60,2.02],[2,55,1.07]],"ltp":190.0,"tv":20.7,"id":22308007},{"batb":[[1,50,1.21],[2,48,1.4]],"ltp":60.0,"tv":31.75,"id":7226819},{"batb":[[1,85,1.56],[2,80,17.87]],"ltp":160.0,"tv":8.72,"id":26548208},{"batb":[[1,150,1.69],[2,110,14.02]],"ltp":580.0,"tv":6.13,"id":27606066},{"batb":[[0,230,1.56]],"ltp":280.0,"tv":1.54,"id":24270700}]}]}
{"op":"mcm","clk":"993310001","pt":1580540364662,"mc":[{"id":"1.168133543","rc":[{"batb":[[0,65,2.81],[1,60,15.68],[2,50,1.21]],"ltp":60.0,"tv":31.75,"id":7226819},{"batb":[[1,95,1.94],[2,85,1.26]],"ltp":160.0,"tv":8.72,"id":26548208},{"batb":[[1,190,1.59],[2,150,1.43]],"ltp":580.0,"tv":6.13,"id":27606066}]}]}
{"op":"mcm","clk":"993310115","pt":1580540367533,"mc":[{"id":"1.168133543","rc":[{"batl":[[0,2.28,2],[1,2.3,2],[2,2.32,11.83]],"ltp":2.26,"tv":2872.85,"id":10107355},{"batb":[[2,85,1.25]],"ltp":160.0,"tv":8.72,"id":26548208}]}]}
{"op":"mcm","clk":"993310141","pt":1580540368151,"mc":[{"id":"1.168133543","rc":[{"batb":[[2,85,1.26]],"ltp":160.0,"tv":8.72,"id":26548208}]}]}
{"op":"mcm","clk":"993310191","pt":1580540369178,"mc":[{"id":"1.168133543","rc":[{"batb":[[2,48,2.29]],"ltp":60.0,"tv":31.75,"id":7226819}]}]}
{"op":"mcm","clk":"993310364","pt":1580540372371,"mc":[{"id":"1.168133543","rc":[{"batb":[[1,60,18.02]],"ltp":190.0,"tv":20.7,"id":22308007}]}]}
{"op":"mcm","clk":"993310593","pt":1580540377354,"mc":[{"id":"1.168133543","rc":[{"batb":[[0,65,3.08]],"ltp":60.0,"tv":31.75,"id":7226819}]}]}
{"op":"mcm","clk":"993310652","pt":1580540378538,"mc":[{"id":"1.168133543","rc":[{"batb":[[0,65,6.97]],"ltp":60.0,"tv":31.75,"id":7226819},{"batb":[[1,7.6,3.78]],"ltp":9.8,"tv":418.27,"id":22121325},{"batb":[[1,95,4.61]],"ltp":160.0,"tv":8.72,"id":26548208},{"batb":[[1,200,2.79]],"ltp":580.0,"tv":6.13,"id":27606066},{"batb":[[1,190,3.41],[2,170,3.49]],"ltp":280.0,"tv":1.54,"id":24270700}]}]}
{"op":"mcm","clk":"993310657","pt":1580540378641,"mc":[{"id":"1.168133543","rc":[{"batb":[[0,160,3.34]],"ltp":160.0,"tv":19.01,"id":13306150}]}]}
{"op":"mcm","clk":"993310997","pt":1580540385494,"mc":[{"id":"1.168133543","rc":[{"batb":[[1,60,18.29]],"ltp":190.0,"tv":20.7,"id":22308007}]}]}
{"op":"mcm","clk":"993311137","pt":1580540389079,"mc":[{"id":"1.168133543","rc":[{"batl":[[0,2.26,2],[1,2.28,2],[2,2.3,2]],"ltp":2.26,"tv":2872.85,"id":10107355},{"trd":[[95,2.44],[100,2.1]],"batb":[[0,95,3.39],[1,85,1.26],[2,80,17.87]],"ltp":95.0,"tv":13.25,"id":26548208}],"tv":5085.99}]}
{"op":"mcm","clk":"993311253","pt":1580540392567,"mc":[{"id":"1.168133543","rc":[{"batb":[[0,2.92,5],[1,2.9,6.92],[2,2.88,26.03]],"ltp":2.94,"tv":1286.14,"id":12636},{"batb":[[0,85,1.36],[1,80,17.87],[2,70,1.1]],"ltp":95.0,"tv":13.25,"id":26548208},{"batb":[[1,150,1.69],[2,110,14.02]],"ltp":580.0,"tv":6.13,"id":27606066},{"batb":[[1,180,1.03],[2,170,3.21]],"ltp":280.0,"tv":1.54,"id":24270700},{"batb":[[0,150,1.87],[1,100,1.55],[2,95,2.3]],"ltp":160.0,"tv":19.01,"id":13306150}]}]}
{"op":"mcm","clk":"993311298","pt":1580540393493,"mc":[{"id":"1.168133543","rc":[{"trd":[[2.94,247.61]],"batl":[[0,2.94,26.2]],"ltp":2.94,"tv":1313.34,"id":12636},{"batb":[[0,85,5.14]],"ltp":95.0,"tv":13.25,"id":26548208},{"batb":[[1,210,2.67],[2,150,1.43]],"ltp":580.0,"tv":6.13,"id":27606066},{"batb":[[1,200,3.13],[2,170,3.64]],"ltp":280.0,"tv":1.54,"id":24270700},{"batb":[[1,110,4.52],[2,95,3.2]],"ltp":160.0,"tv":19.01,"id":13306150}],"tv":5113.19}]}
{"op":"mcm","clk":"993311427","pt":1580540396474,"mc":[{"id":"1.168133543","rc":[{"batb":[[1,200,3.33]],"ltp":280.0,"tv":1.54,"id":24270700}]}]}
{"op":"mcm","clk":"993311447","pt":1580540397092,"mc":[{"id":"1.168133543","rc":[{"trd":[[2.94,257.61]],"batl":[[0,2.94,21.2]],"ltp":2.94,"tv":1323.34,"id":12636},{"batl":[[1,11,2],[2,11.5,3.08]],"ltp":9.8,"tv":418.27,"id":22121325},{"batb":[[1,120,1.77],[2,110,4.32]],"ltp":160.0,"tv":19.01,"id":13306150}],"tv":5123.19}]}
{"op":"mcm","clk":"993311494","pt":1580540398499,"mc":[{"id":"1.168133543","rc":[{"trd":[[2.94,287.61]],"batl":[[0,2.94,6.2]],"ltp":2.94,"tv":1353.34,"id":12636}],"tv":5153.19}]}
{"op":"mcm","clk":"993311801","pt":1580540401411,"mc":[{"id":"1.168133543","rc":[{"trd":[[2.94,300.01]],"batl":[[0,2.96,50],[1,2.98,50],[2,3.5,2]],"ltp":2.94,"tv":1365.74,"id":12636}],"tv":5165.59}]}
{"op":"mcm","clk":"993311939","pt":1580540402512,"mc":[{"id":"1.168133543","rc":[{"batb":[[2,48,1.49]],"ltp":60.0,"tv":31.75,"id":7226819}]}]}
{"op":"mcm","clk":"993312017","pt":1580540403095,"mc":[{"id":"1.168133543","rc":[{"batb":[[0,65,7.54]],"ltp":60.0,"tv":31.75,"id":7226819},{"batb":[[1,210,2.76],[2,150,1.32]],"ltp":580.0,"tv":6.13,"id":27606066},{"batb":[[1,120,2.1]],"ltp":160.0,"tv":19.01,"id":13306150}]}]}
{"op":"mcm","clk":"993312450","pt":1580540405481,"mc":[{"id":"1.168133543","rc":[{"trd":[[2.24,261.61]],"batb":[[0,2.22,6],[1,2.2,104],[2,2.08,9.11]],"batl":[[0,2.24,6.72],[1,2.26,2],[2,2.28,2]],"ltp":2.24,"tv":2883.41,"id":10107355}],"tv":5176.15}]}
{"op":"mcm","clk":"993312628","pt":1580540407494,"mc":[{"id":"1.168133543","rc":[{"trd":[[2.96,110.2]],"batb":[[0,2.92,10]],"batl":[[0,2.96,44.91]],"ltp":2.96,"tv":1375.92,"id":12636},{"batb":[[0,85,1.59]],"ltp":190.0,"tv":20.7,"id":22308007},{"batb":[[0,65,7.74]],"ltp":60.0,"tv":31.75,"id":7226819},{"trd":[[9.8,52.71]],"batl":[[0,10,51.32],[1,17,1.88],[2,29,9.24]],"ltp":9.8,"tv":408.58,"id":10163711},{"trd":[[2.24,275.05]],"batb":[[0,2.22,128.91]],"batl":[[0,2.26,2],[1,2.28,2],[2,2.3,2]],"ltp":2.24,"tv":2896.85,"id":10107355},{"trd":[[10,87.3]],"batl":[[0,10,14.16]],"ltp":10.0,"tv":421.29,"id":22121325},{"batb":[[0,85,5.29]],"ltp":95.0,"tv":13.25,"id":26548208},{"batb":[[0,230,1.08],[1,150,1.67],[2,110,14.02]],"ltp":580.0,"tv":6.13,"id":27606066},{"batb":[[0,230,1.62],[1,180,1.22],[2,170,3.21]],"ltp":280.0,"tv":1.54,"id":24270700},{"batb":[[0,150,1.95],[1,130,3.27],[2,120,2.1]],"ltp":160.0,"tv":19.01,"id":13306150}],"tv":5206.82}]}
{"op":"mcm","clk":"993312709","pt":1580540408526,"mc":[{"id":"1.168133543","rc":[{"batb":[[0,9.8,1.76],[1,9.6,12.34],[2,9.2,5.64]],"ltp":9.8,"tv":408.58,"id":10163711},{"batb":[[1,220,2.62],[2,150,1.35]],"ltp":580.0,"tv":6.13,"id":27606066},{"batb":[[1,210,2.95],[2,170,3.89]],"ltp":280.0,"tv":1.54,"id":24270700}]}]}
{"op":"mcm","clk":"993312820","pt":1580540409513,"mc":[{"id":"1.168133543","rc":[{"batb":[[0,90,1.19],[1,65,1.37],[2,60,17.33]],"ltp":190.0,"tv":20.7,"id":22308007}]}]}
{"op":"mcm","clk":"993313082","pt":1580540413538,"mc":[{"id":"1.168133543","rc":[{"trd":[[2.96,122.64]],"batb":[[0,2.94,5],[1,2.92,10],[2,2.9,6.92]],"batl":[[0,2.96,38.69]],"ltp":2.96,"tv":1388.36,"id":12636}],"tv":5219.26}]}
{"op":"mcm","clk":"993313141","pt":1580540414514,"mc":[{"id":"1.168133543","rc":[{"batb":[[0,2.94,10],[1,2.92,14],[2,2.9,2.92]],"ltp":2.96,"tv":1388.36,"id":12636}]}]}
{"op":"mcm","clk":"993313152","pt":1580540414720,"mc":[{"id":"1.168133543","rc":[{"trd":[[2.96,135.07]],"batl":[[0,2.96,32.47]],"ltp":2.96,"tv":1400.8,"id":12636}],"tv":5231.7}]}
{"op":"mcm","clk":"993313267","pt":1580540416419,"mc":[{"id":"1.168133543","rc":[{"trd":[[2.96,145.07]],"batl":[[0,2.96,27.47]],"ltp":2.96,"tv":1410.8,"id":12636}],"tv":5241.7}]}
{"op":"mcm","clk":"993313296","pt":1580540417035,"mc":[{"id":"1.168133543","rc":[{"trd":[[2.96,155.07]],"batl":[[0,2.96,22.47]],"ltp":2.96,"tv":1420.8,"id":12636}],"tv":5251.7}]}
{"op":"mcm","clk":"993313515","pt":1580540421550,"mc":[{"id":"1.168133543","rc":[{"trd":[[2.96,200.01]],"batb":[[0,2.96,6.02],[1,2.92,4]],"batl":[[0,2.98,50],[1,3.5,2],[2,3.6,2]],"ltp":2.96,"tv":1465.74,"id":12636},{"batb":[[0,2.22,14.83]],"ltp":2.24,"tv":2896.85,"id":10107355},{"batb":[[1,150,1.67],[2,110,14.02]],"ltp":580.0,"tv":6.13,"id":27606066},{"batb":[[1,180,1.22],[2,170,3.21]],"ltp":280.0,"tv":1.54,"id":24270700},{"batb":[[1,120,2.1],[2,95,3.44]],"ltp":160.0,"tv":19.01,"id":13306150}],"tv":5296.64}]}
{"op":"mcm","clk":"993313556","pt":1580540422326,"mc":[{"id":"1.168133543","rc":[{"trd":[[2.98,32.8]],"batb":[[0,2.96,141.67],[1,2.94,4]],"batl":[[0,2.98,33.6]],"ltp":2.98,"tv":1498.54,"id":12636},{"batb":[[1,70,7],[2,60,17.92]],"ltp":190.0,"tv":20.7,"id":22308007},{"batb":[[1,220,2.61],[2,170,4.13]],"ltp":280.0,"tv":1.54,"id":24270700},{"batb":[[1,140,3.04],[2,120,2.1]],"ltp":160.0,"tv":19.01,"id":13306150}],"tv":5329.44}]}
{"op":"mcm","clk":"993313621","pt":1580540423518,"mc":[{"id":"1.168133543","rc":[{"batb":[[0,2.22,6]],"ltp":2.24,"tv":2896.85,"id":10107355}]}]}
{"op":"mcm","clk":"993313679","pt":1580540424551,"mc":[{"id":"1.168133543","rc":[{"batb":[[0,2.96,135.65]],"ltp":2.98,"tv":1498.54,"id":12636}]}]}
{"op":"mcm","clk":"993313953","pt":1580540429747,"mc":[{"id":"1.168133543","rc":[{"batb":[[2,60,17.67]],"ltp":190.0,"tv":20.7,"id":22308007}]}]}
{"op":"mcm","clk":"993314168","pt":1580540433423,"mc":[{"id":"1.168133543","rc":[{"batb":[[0,2.96,137.65]],"ltp":2.98,"tv":1498.54,"id":12636}]}]}
{"op":"mcm","clk":"993314232","pt":1580540434559,"mc":[{"id":"1.168133543","rc":[{"batb":[[0,2.96,141.65]],"ltp":2.98,"tv":1498.54,"id":12636}]}]}
{"op":"mcm","clk":"993314315","pt":1580540436049,"mc":[{"id":"1.168133543","rc":[{"batb":[[0,2.96,6]],"ltp":2.98,"tv":1498.54,"id":12636},{"batb":[[1,160,3.52],[2,150,1.32]],"ltp":580.0,"tv":6.13,"id":27606066},{"batb":[[0,230,3.82],[1,180,1.22],[2,170,3.21]],"ltp":280.0,"tv":1.54,"id":24270700},{"batb":[[0,150,4.79],[1,120,2.1],[2,95,3.44]],"ltp":160.0,"tv":19.01,"id":13306150}]}]}
{"op":"mcm","clk":"993314505","pt":1580540439574,"mc":[{"id":"1.168133543","rc":[{"batb":[[1,2.9,2.92],[2,2.88,26.03]],"ltp":2.98,"tv":1498.54,"id":12636}]}]}
{"op":"mcm","clk":"993314560","pt":1580540440453,"mc":[{"id":"1.168133543","rc":[{"batb":[[0,2.96,10]],"ltp":2.98,"tv":1498.54,"id":12636}]}]}
{"op":"mcm","clk":"993314615","pt":1580540441234,"mc":[{"id":"1.168133543","rc":[{"batl":[[0,2.24,3],[1,2.26,2],[2,2.28,2]],"ltp":2.24,"tv":2896.85,"id":10107355}]}]}
{"op":"mcm","clk":"993315173","pt":1580540450485,"mc":[{"id":"1.168133543","rc":[{"batb":[[1,150,1.67],[2,110,14.02]],"ltp":580.0,"tv":6.13,"id":27606066},{"batb":[[0,230,1.62]],"ltp":280.0,"tv":1.54,"id":24270700},{"batb":[[0,150,1.95]],"ltp":160.0,"tv":19.01,"id":13306150}]}]}
{"op":"mcm","clk":"993315177","pt":1580540450586,"mc":[{"id":"1.168133543","rc":[{"trd":[[2.98,99.97]],"batb":[[0,2.98,101.18],[1,2.96,10],[2,2.9,2.92]],"batl":[[0,3.5,2],[1,3.6,2],[2,5.5,6.67]],"ltp":2.98,"tv":1565.7,"id":12636},{"batb":[[0,2.22,120.08]],"ltp":2.24,"tv":2896.85,"id":10107355},{"batb":[[1,170,3.33],[2,150,1.32]],"ltp":580.0,"tv":6.13,"id":27606066},{"batb":[[0,160,3.42],[1,150,1.19],[2,120,2.1]],"ltp":160.0,"tv":19.01,"id":13306150}],"tv":5396.6}]}
{"op":"mcm","clk":"993315292","pt":1580540452388,"mc":[{"id":"1.168133543","rc":[{"batl":[[0,3.5,2.19]],"ltp":2.98,"tv":1565.7,"id":12636},{"trd":[[2.24,281.05]],"batb":[[0,2.24,6.65],[1,2.22,120.08],[2,2.2,104]],"batl":[[0,2.26,2],[1,2.28,2],[2,2.3,2]],"ltp":2.24,"tv":2902.84,"id":10107355}],"tv":5402.6}]}
{"op":"mcm","clk":"993315687","pt":1580540459292,"mc":[{"id":"1.168133543","rc":[{"batb":[[0,3,3],[1,2.98,101.18],[2,2.96,10]],"ltp":2.98,"tv":1565.7,"id":12636}]}]}
{"op":"mcm","clk":"993315752","pt":1580540460525,"mc":[{"id":"1.168133543","rc":[{"batb":[[0,3,9.67]],"ltp":2.98,"tv":1565.7,"id":12636},{"batb":[[1,170,3.35]],"ltp":580.0,"tv":6.13,"id":27606066}]}]}
{"op":"mcm","clk":"993315924","pt":1580540464542,"mc":[{"id":"1.168133543","rc":[{"batb":[[1,2.96,10],[2,2.9,2.92]],"ltp":2.98,"tv":1565.7,"id":12636},{"batb":[[1,65,1.12],[2,60,17.33]],"ltp":190.0,"tv":20.7,"id":22308007},{"batb":[[0,65,1.55]],"ltp":60.0,"tv":31.75,"id":7226819},{"batb":[[1,2.22,6]],"ltp":2.24,"tv":2902.84,"id":10107355},{"batb":[[0,85,1.51]],"ltp":95.0,"tv":13.25,"id":26548208},{"batb":[[1,150,1.69],[2,110,14.02]],"ltp":580.0,"tv":6.13,"id":27606066},{"batb":[[0,150,1.95],[1,120,2.1],[2,95,3.44]],"ltp":160.0,"tv":19.01,"id":13306150}]}]}
{"op":"mcm","clk":"993315976","pt":1580540465520,"mc":[{"id":"1.168133543","rc":[{"batb":[[0,2.22,6],[1,2.2,104],[2,2.08,9.11]],"ltp":2.24,"tv":2902.84,"id":10107355}]}]}
{"op":"mcm","clk":"993316015","pt":1580540466346,"mc":[{"id":"1.168133543","rc":[{"batb":[[2,95,3.26]],"ltp":160.0,"tv":19.01,"id":13306150}]}]}
{"op":"mcm","clk":"993316190","pt":1580540470304,"mc":[{"id":"1.168133543","rc":[{"batl":[[1,3.55,3.82],[2,3.6,2]],"ltp":2.98,"tv":1565.7,"id":12636}]}]}
{"op":"mcm","clk":"993316348","pt":1580540473037,"mc":[{"id":"1.168133543","rc":[{"batb":[[1,2.98,4],[2,2.96,6]],"ltp":2.98,"tv":1565.7,"id":12636}]}]}
{"op":"mcm","clk":"993316499","pt":1580540475052,"mc":[{"id":"1.168133543","rc":[{"batl":[[0,3.45,12.61],[1,3.5,2],[2,3.55,3.82]],"ltp":2.98,"tv":1565.7,"id":12636}]}]}
{"op":"mcm","clk":"993316873","pt":1580540483254,"mc":[{"id":"1.168133543","rc":[{"batb":[[0,3,6.67]],"batl":[[0,3.4,9.55],[1,3.45,12.61],[2,3.5,2]],"ltp":2.98,"tv":1565.7,"id":12636}]}]}
{"op":"mcm","clk":"993317118","pt":1580540488463,"mc":[{"id":"1.168133543","rc":[{"batb":[[1,70,2.79],[2,60,17.67]],"ltp":190.0,"tv":20.7,"id":22308007}]}]}
{"op":"mcm","clk":"993317661","pt":1580540495072,"mc":[{"id":"1.168133543","rc":[{"batl":[[1,3.5,2.19],[2,3.55,3.82]],"ltp":2.98,"tv":1565.7,"id":12636}]}]}
{"op":"mcm","clk":"993317711","pt":1580540496460,"mc":[{"id":"1.168133543","rc":[{"batb":[[2,2,46.19]],"ltp":2.24,"tv":2902.84,"id":10107355}]}]}
{"op":"mcm","clk":"993317893","pt":1580540500278,"mc":[{"id":"1.168133543","rc":[{"batb":[[1,7.6,5.1]],"ltp":10.0,"tv":421.29,"id":22121325}]}]}
{"op":"mcm","clk":"993317984","pt":1580540502456,"mc":[{"id":"1.168133543","rc":[{"batl":[[0,3.35,3.89],[1,3.4,9.55],[2,3.5,2.19]],"ltp":2.98,"tv":1565.7,"id":12636}]}]}
{"op":"mcm","clk":"993318639","pt":1580540513688,"mc":[{"id":"1.168133543","rc":[{"batb":[[0,2.98,4],[1,2.96,6],[2,2.9,2.92]],"ltp":2.98,"tv":1565.7,"id":12636},{"batb":[[1,150,1.58]],"ltp":580.0,"tv":6.13,"id":27606066}]}]}
{"op":"mcm","clk":"993318995","pt":1580540521403,"mc":[{"id":"1.168133543","rc":[{"batb":[[0,60,16.67],[1,48,1.49],[2,46,1.08]],"ltp":60.0,"tv":31.75,"id":7226819},{"batb":[[1,120,1.77]],"ltp":160.0,"tv":19.01,"id":13306150}]}]}
{"op":"mcm","clk":"993319019","pt":1580540521921,"mc":[{"id":"1.168133543","rc":[{"batb":[[0,65,1.6],[1,60,15.68],[2,48,1.49]],"ltp":60.0,"tv":31.75,"id":7226819},{"batb":[[2,100,1.35]],"ltp":160.0,"tv":19.01,"id":13306150}]}]}
{"op":"mcm","clk":"993320579","pt":1580540558061,"mc":[{"id":"1.168133543","rc":[{"batl":[[1,1000,4]],"ltp":280.0,"tv":1.54,"id":24270700}]}]}
{"op":"mcm","clk":"993322072","pt":1580540592140,"mc":[{"id":"1.168133543","rc":[{"batb":[[1,60,1.68],[2,48,15.49]],"ltp":60.0,"tv":31.75,"id":7226819}]}]}
{"op":"mcm","clk":"993322198","pt":1580540595226,"mc":[{"id":"1.168133543","rc":[{"batb":[[0,65,1.33]],"ltp":60.0,"tv":31.75,"id":7226819}]}]}
{"op":"mcm","clk":"993322417","pt":1580540600273,"mc":[{"id":"1.168133543","rc":[{"batb":[[1,50,1.77],[2,48,15.4]],"ltp":60.0,"tv":31.75,"id":7226819}]}]}
{"op":"mcm","clk":"993322581","pt":1580540604447,"mc":[{"id":"1.168133543","rc":[{"batb":[[1,50,2.12]],"ltp":60.0,"tv":31.75,"id":7226819}]}]}
{"op":"mcm","clk":"993322695","pt":1580540607482,"mc":[{"id":"1.168133543","rc":[{"batb":[[1,55,7.4],[2,50,2.03]],"ltp":60.0,"tv":31.75,"id":7226819}]}]}
{"op":"mcm","clk":"993323224","pt":1580540622492,"mc":[{"id":"1.168133543","rc":[{"batb":[[1,50,2.12],[2,48,15.4]],"ltp":60.0,"tv":31.75,"id":7226819}]}]}
{"op":"mcm","clk":"993323791","pt":1580540636514,"mc":[{"id":"1.168133543","rc":[{"batb":[[1,55,7.4],[2,50,2.03]],"ltp":60.0,"tv":31.75,"id":7226819}]}]}
{"op":"mcm","clk":"993323883","pt":1580540638526,"mc":[{"id":"1.168133543","rc":[{"batl":[[0,3.3,4.82],[1,3.35,3.89],[2,3.4,9.55]],"ltp":2.98,"tv":1565.7,"id":12636}]}]}
{"op":"mcm","clk":"993324055","pt":1580540642500,"mc":[{"id":"1.168133543","rc":[{"batb":[[0,60,1.38]],"ltp":60.0,"tv":31.75,"id":7226819}]}]}
{"op":"mcm","clk":"993324186","pt":1580540645326,"mc":[{"id":"1.168133543","rc":[{"batb":[[0,3,5.74],[1,2.98,4],[2,2.96,6]],"ltp":2.98,"tv":1565.7,"id":12636}]}]}
{"op":"mcm","clk":"993324385","pt":1580540650531,"mc":[{"id":"1.168133543","rc":[{"batb":[[1,50,2.12],[2,48,15.4]],"ltp":60.0,"tv":31.75,"id":7226819}]}]}
{"op":"mcm","clk":"993324848","pt":1580540661255,"mc":[{"id":"1.168133543","rc":[{"batl":[[0,3.25,3.03],[1,3.3,4.82]],"ltp":2.98,"tv":1565.7,"id":12636}]}]}
{"op":"mcm","clk":"993325033","pt":1580540665566,"mc":[{"id":"1.168133543","rc":[{"batb":[[1,75,6.58],[2,70,2.03]],"ltp":190.0,"tv":20.7,"id":22308007},{"batb":[[1,55,7.4],[2,50,2.03]],"ltp":60.0,"tv":31.75,"id":7226819},{"batb":[[1,200,3.33],[2,170,3.64]],"ltp":280.0,"tv":1.54,"id":24270700}]}]}
{"op":"mcm","clk":"993325080","pt":1580540666444,"mc":[{"id":"1.168133543","rc":[{"batb":[[1,75,6.64]],"ltp":190.0,"tv":20.7,"id":22308007}]}]}
{"op":"mcm","clk":"993325419","pt":1580540675681,"mc":[{"id":"1.168133543","rc":[{"batb":[[1,80,1.32],[2,75,5.82]],"ltp":190.0,"tv":20.7,"id":22308007}]}]}
{"op":"mcm","clk":"993325577","pt":1580540679489,"mc":[{"id":"1.168133543","rc":[{"batb":[[2,70,2.03]],"ltp":190.0,"tv":20.7,"id":22308007},{"batb":[[1,180,1.22],[2,170,3.21]],"ltp":280.0,"tv":1.54,"id":24270700}]}]}
{"op":"mcm","clk":"993325703","pt":1580540683481,"mc":[{"id":"1.168133543","rc":[{"batl":[[1,3.4,9.55],[2,3.5,2]],"ltp":2.98,"tv":1565.7,"id":12636}]}]}
{"op":"mcm","clk":"993325795","pt":1580540685489,"mc":[{"id":"1.168133543","rc":[{"batb":[[1,80,1.87]],"ltp":95.0,"tv":13.25,"id":26548208}]}]}
{"op":"mcm","clk":"993325821","pt":1580540686159,"mc":[{"id":"1.168133543","rc":[{"batb":[[0,85,1.3]],"ltp":95.0,"tv":13.25,"id":26548208}]}]}
{"op":"mcm","clk":"993326047","pt":1580540692471,"mc":[{"id":"1.168133543","rc":[{"batl":[[0,3.35,3.14]],"ltp":2.98,"tv":1565.7,"id":12636}]}]}
{"op":"mcm","clk":"993326093","pt":1580540693497,"mc":[{"id":"1.168133543","rc":[{"batb":[[1,50,2.12],[2,48,15.4]],"ltp":60.0,"tv":31.75,"id":7226819}]}]}
{"op":"mcm","clk":"993326146","pt":1580540694310,"mc":[{"id":"1.168133543","rc":[{"batb":[[2,75,16]],"ltp":190.0,"tv":20.7,"id":22308007},{"batb":[[2,70,1.35]],"ltp":95.0,"tv":13.25,"id":26548208}]}]}
{"op":"mcm","clk":"993326553","pt":1580540702282,"mc":[{"id":"1.168133543","rc":[{"batb":[[0,50,3.64],[1,48,15.4],[2,46,1.08]],"ltp":60.0,"tv":31.75,"id":7226819},{"batb":[[0,80,2.71],[1,70,1.91],[2,65,16.77]],"ltp":95.0,"tv":13.25,"id":26548208}]}]}
{"op":"mcm","clk":"993326567","pt":1580540702588,"mc":[{"id":"1.168133543","rc":[{"batb":[[1,80,1.54]],"ltp":190.0,"tv":20.7,"id":22308007}]}]}
{"op":"mcm","clk":"993327593","pt":1580540725547,"mc":[{"id":"1.168133543","rc":[{"batb":[[0,3,12.41]],"ltp":2.98,"tv":1565.7,"id":12636},{"batb":[[1,150,1.71]],"ltp":580.0,"tv":6.13,"id":27606066}]}]}
{"op":"mcm","clk":"993327632","pt":1580540726319,"mc":[{"id":"1.168133543","rc":[{"batl":[[0,3.3,2],[1,3.35,3.14],[2,3.4,9.55]],"ltp":2.98,"tv":1565.7,"id":12636}]}]}
{"op":"mcm","clk":"993343220","pt":1580540870481,"mc":[{"id":"1.168133543","rc":[{"batb":[[0,3.05,1],[1,3,12.41],[2,2.98,4]],"ltp":2.98,"tv":1565.7,"id":12636}]}]}
{"op":"mcm","clk":"993343255","pt":1580540871566,"mc":[{"id":"1.168133543","rc":[{"batb":[[0,3,12.41],[1,2.98,4],[2,2.96,6]],"ltp":2.98,"tv":1565.7,"id":12636}]}]}
{"op":"mcm","clk":"993345320","pt":1580540915506,"mc":[{"id":"1.168133543","rc":[{"trd":[[9.8,16.76]],"batb":[[0,7.6,5.1],[1,7.4,2.61],[2,7,2.27]],"batl":[[0,9.8,6.85],[1,10,14.16],[2,11,2]],"ltp":9.8,"tv":427.59,"id":22121325}],"tv":5408.9}]}
{"op":"mcm","clk":"993345527","pt":1580540920438,"mc":[{"id":"1.168133543","rc":[{"batl":[[1,2.38,11.7],[2,2.4,104]],"ltp":2.24,"tv":2902.84,"id":10107355}]}]}
{"op":"mcm","clk":"993345608","pt":1580540922548,"mc":[{"id":"1.168133543","rc":[{"batb":[[0,3.05,98.86],[1,3,12.41],[2,2.98,4]],"ltp":2.98,"tv":1565.7,"id":12636},{"batb":[[1,85,6.04],[2,75,16.64]],"ltp":190.0,"tv":20.7,"id":22308007},{"batb":[[0,55,8.12],[1,50,2.83],[2,48,15.4]],"ltp":60.0,"tv":31.75,"id":7226819},{"batb":[[0,2.22,120.08]],"batl":[[1,2.38,2.81]],"ltp":2.24,"tv":2902.84,"id":10107355},{"batb":[[0,7.8,32.79],[1,7.6,4.78],[2,7.4,2.61]],"ltp":9.8,"tv":427.59,"id":22121325},{"batb":[[0,85,4.62],[1,80,1.87],[2,70,1.91]],"ltp":95.0,"tv":13.25,"id":26548208},{"batb":[[1,200,3.33],[2,170,3.64]],"ltp":280.0,"tv":1.54,"id":24270700},{"batb":[[1,130,3.27],[2,120,1.77]],"ltp":160.0,"tv":19.01,"id":13306150}]}]}
{"op":"mcm","clk":"993345650","pt":1580540923526,"mc":[{"id":"1.168133543","rc":[{"batl":[[2,3.5,2]],"ltp":2.98,"tv":1565.7,"id":12636}]}]}
{"op":"mcm","clk":"993345693","pt":1580540924551,"mc":[{"id":"1.168133543","rc":[{"batb":[[0,7.8,34.83]],"batl":[[0,9.8,8.85],[2,11.5,3.08]],"ltp":9.8,"tv":427.59,"id":22121325}]}]}
{"op":"mcm","clk":"993345806","pt":1580540927126,"mc":[{"id":"1.168133543","rc":[{"batb":[[1,7.6,3.31]],"ltp":9.8,"tv":427.59,"id":22121325}]}]}
{"op":"mcm","clk":"993346044","pt":1580540932252,"mc":[{"id":"1.168133543","rc":[{"batb":[[0,8,5.49],[1,7.8,34.7],[2,7.6,3.31]],"ltp":9.8,"tv":427.59,"id":22121325}]}]}
{"op":"mcm","clk":"993346293","pt":1580540937550,"mc":[{"id":"1.168133543","rc":[{"batb":[[0,90,6.04],[1,80,1.54],[2,75,16]],"ltp":190.0,"tv":20.7,"id":22308007},{"batb":[[0,2.22,6]],"ltp":2.24,"tv":2902.84,"id":10107355},{"batb":[[0,8.2,31.02],[1,8,5.36],[2,7.8,2.23]],"ltp":9.8,"tv":427.59,"id":22121325},{"batb":[[0,80,2.71],[1,75,4.67],[2,70,1.53]],"ltp":95.0,"tv":13.25,"id":26548208},{"batb":[[1,180,1.22],[2,170,3.21]],"ltp":280.0,"tv":1.54,"id":24270700},{"batb":[[1,120,1.77],[2,100,1.35]],"ltp":160.0,"tv":19.01,"id":13306150}]}]}
{"op":"mcm","clk":"993346412","pt":1580540940268,"mc":[{"id":"1.168133543","rc":[{"batl":[[0,9.6,2],[1,9.8,8.85],[2,10,14.16]],"ltp":9.8,"tv":427.59,"id":22121325}]}]}
{"op":"mcm","clk":"993346461","pt":1580540941146,"mc":[{"id":"1.168133543","rc":[{"batl":[[2,2.42,5.5]],"ltp":2.24,"tv":2902.84,"id":10107355}]}]}
{"op":"mcm","clk":"993346527","pt":1580540942479,"mc":[{"id":"1.168133543","rc":[{"batb":[[1,50,2.03]],"ltp":60.0,"tv":31.75,"id":7226819},{"batl":[[0,2.34,2],[1,2.42,5.5],[2,2.46,21]],"ltp":2.24,"tv":2902.84,"id":10107355},{"batb":[[2,65,17.74]],"ltp":95.0,"tv":13.25,"id":26548208}]}]}
{"op":"mcm","clk":"993346569","pt":1580540943357,"mc":[{"id":"1.168133543","rc":[{"batb":[[0,3.1,6.45],[1,3.05,102.86],[2,3,5.74]],"batl":[[0,3.35,3.14],[1,3.5,2],[2,3.6,2]],"ltp":2.98,"tv":1565.7,"id":12636},{"batb":[[0,60,1.38],[1,55,7.4],[2,50,2.03]],"ltp":60.0,"tv":31.75,"id":7226819},{"batb":[[0,2.22,15.01]],"ltp":2.24,"tv":2902.84,"id":10107355},{"batb":[[0,80,3.21]],"ltp":95.0,"tv":13.25,"id":26548208}]}]}
{"op":"mcm","clk":"993346672","pt":1580540945463,"mc":[{"id":"1.168133543","rc":[{"batb":[[2,7.6,3.5]],"ltp":9.8,"tv":427.59,"id":22121325}]}]}
{"op":"mcm","clk":"993346716","pt":1580540946489,"mc":[{"id":"1.168133543","rc":[{"batb":[[0,8.4,2.03],[1,8.2,30.88],[2,8,5.36]],"ltp":9.8,"tv":427.59,"id":22121325}]}]}
{"op":"mcm","clk":"993346752","pt":1580540947570,"mc":[{"id":"1.168133543","rc":[{"batl":[[0,3.5,2],[1,3.55,3.03]],"ltp":2.98,"tv":1565.7,"id":12636}]}]}
{"op":"mcm","clk":"993346891","pt":1580540951476,"mc":[{"id":"1.168133543","rc":[{"batb":[[1,3.05,4]],"ltp":2.98,"tv":1565.7,"id":12636},{"batb":[[0,90,1.19]],"ltp":190.0,"tv":20.7,"id":22308007},{"batb":[[1,50,2.12],[2,48,15.4]],"ltp":60.0,"tv":31.75,"id":7226819},{"batb":[[1,8,5.36],[2,7.6,3.5]],"ltp":9.8,"tv":427.59,"id":22121325},{"batb":[[1,70,1.35],[2,65,16.77]],"ltp":95.0,"tv":13.25,"id":26548208}]}]}
{"op":"mcm","clk":"993346927","pt":1580540952394,"mc":[{"id":"1.168133543","rc":[{"batl":[[0,3.4,9.55],[1,3.45,12.42],[2,3.5,2]],"ltp":2.98,"tv":1565.7,"id":12636},{"batb":[[1,7.6,3.5],[2,7.4,2.61]],"ltp":9.8,"tv":427.59,"id":22121325}]}]}
{"op":"mcm","clk":"993347089","pt":1580540955375,"mc":[{"id":"1.168133543","rc":[{"trd":[[2.22,180.34]],"batb":[[0,2.2,104],[1,2,46.19],[2,1.98,9.11]],"batl":[[0,2.22,7.19],[1,2.34,2],[2,2.42,5.5]],"ltp":2.22,"tv":3008.47,"id":10107355}],"tv":5514.53}]}
{"op":"mcm","clk":"993347153","pt":1580540956559,"mc":[{"id":"1.168133543","rc":[{"trd":[[2.22,194.72]],"batb":[[0,2.24,2.31],[1,2.2,104],[2,2,46.19]],"batl":[[0,2.34,2],[1,2.42,5.5],[2,2.46,21]],"ltp":2.22,"tv":3022.85,"id":10107355}],"tv":5528.91}]}
{"op":"mcm","clk":"993347190","pt":1580540957277,"mc":[{"id":"1.168133543","rc":[{"batl":[[0,2.32,6],[1,2.34,2],[2,2.42,5.5]],"ltp":2.22,"tv":3022.85,"id":10107355}]}]}
{"op":"mcm","clk":"993347280","pt":1580540959897,"mc":[{"id":"1.168133543","rc":[{"batl":[[0,2.3,2],[1,2.32,6]],"ltp":2.22,"tv":3022.85,"id":10107355}]}]}
{"op":"mcm","clk":"993347475","pt":1580540965494,"mc":[{"id":"1.168133543","rc":[{"batb":[[0,3.1,103.71]],"ltp":2.98,"tv":1565.7,"id":12636},{"batb":[[1,85,6.04],[2,75,16.64]],"ltp":190.0,"tv":20.7,"id":22308007},{"batb":[[1,55,7.4],[2,50,2.03]],"ltp":60.0,"tv":31.75,"id":7226819},{"batb":[[1,7.8,32.66],[2,7.6,3.31]],"ltp":9.8,"tv":427.59,"id":22121325},{"batb":[[0,85,4.62],[1,80,2.37],[2,70,1.35]],"ltp":95.0,"tv":13.25,"id":26548208},{"batb":[[1,200,3.33],[2,170,3.64]],"ltp":280.0,"tv":1.54,"id":24270700},{"batb":[[1,130,3.27],[2,120,1.77]],"ltp":160.0,"tv":19.01,"id":13306150}]}]}
{"op":"mcm","clk":"993347539","pt":1580540967391,"mc":[{"id":"1.168133543","rc":[{"batl":[[0,2.28,6],[1,2.3,2]],"ltp":2.22,"tv":3022.85,"id":10107355}]}]}
{"op":"mcm","clk":"993347564","pt":1580540968105,"mc":[{"id":"1.168133543","rc":[{"batl":[[0,2.28,8],[1,2.42,5.5],[2,2.46,21]],"ltp":2.22,"tv":3022.85,"id":10107355}]}]}
{"op":"mcm","clk":"993347737","pt":1580540972519,"mc":[{"id":"1.168133543","rc":[{"batl":[[1,3.5,2],[2,3.55,3.03]],"ltp":2.98,"tv":1565.7,"id":12636}]}]}
{"op":"mcm","clk":"993347897","pt":1580540976534,"mc":[{"id":"1.168133543","rc":[{"batl":[[0,2.28,6]],"ltp":2.22,"tv":3022.85,"id":10107355}]}]}
{"op":"mcm","clk":"993347902","pt":1580540976635,"mc":[{"id":"1.168133543","rc":[{"batl":[[1,2.4,2],[2,2.42,5.5]],"ltp":2.22,"tv":3022.85,"id":10107355}]}]}
{"op":"mcm","clk":"993347970","pt":1580540978535,"mc":[{"id":"1.168133543","rc":[{"batl":[[0,2.38,6]],"ltp":2.22,"tv":3022.85,"id":10107355}]}]}
{"op":"mcm","clk":"993348011","pt":1580540979523,"mc":[{"id":"1.168133543","rc":[{"batl":[[2,3.6,2]],"ltp":2.98,"tv":1565.7,"id":12636},{"batb":[[0,90,5.84],[1,85,3.78],[2,80,2.37]],"ltp":95.0,"tv":13.25,"id":26548208},{"batb":[[0,250,5.75],[1,150,2.04]],"ltp":580.0,"tv":6.13,"id":27606066},{"batb":[[0,250,5.3],[1,230,1.32],[2,200,3.33]],"ltp":280.0,"tv":1.54,"id":24270700},{"batb":[[0,250,5],[1,150,1.95],[2,130,3.27]],"ltp":160.0,"tv":19.01,"id":13306150}]}]}
{"op":"mcm","clk":"993348060","pt":1580540980501,"mc":[{"id":"1.168133543","rc":[{"batb":[[0,3.1,6.45]],"batl":[[0,3.35,3.64],[1,3.4,9.55],[2,3.5,2]],"ltp":2.98,"tv":1565.7,"id":12636},{"batb":[[1,80,1.54],[2,75,16]],"ltp":190.0,"tv":20.7,"id":22308007},{"batb":[[1,50,2.12],[2,48,15.4]],"ltp":60.0,"tv":31.75,"id":7226819},{"batb":[[1,7.6,3.5],[2,7.4,21.52]],"ltp":9.8,"tv":427.59,"id":22121325},{"batb":[[1,80,2.37],[2,70,1.1]],"ltp":95.0,"tv":13.25,"id":26548208},{"batb":[[2,180,1.22]],"ltp":280.0,"tv":1.54,"id":24270700},{"batb":[[2,120,1.77]],"ltp":160.0,"tv":19.01,"id":13306150}]}]}
{"op":"mcm","clk":"993348268","pt":1580540985522,"mc":[{"id":"1.168133543","rc":[{"batl":[[0,2.38,8],[1,2.42,5.5],[2,2.46,21]],"ltp":2.22,"tv":3022.85,"id":10107355}]}]}
{"op":"mcm","clk":"993348489","pt":1580540989541,"mc":[{"id":"1.168133543","rc":[{"batl":[[0,170,5],[1,200,1.72],[2,210,2.87]],"ltp":190.0,"tv":20.7,"id":22308007},{"batl":[[0,95,5],[1,510,9.42],[2,550,2]],"ltp":60.0,"tv":31.75,"id":7226819},{"batl":[[1,12,11],[2,17,1.88]],"ltp":9.8,"tv":408.58,"id":10163711},{"batb":[[2,70,1.35]],"batl":[[1,220,5],[2,980,9.15]],"ltp":95.0,"tv":13.25,"id":26548208},{"batl":[[0,450,5.15],[1,590,2]],"ltp":580.0,"tv":6.13,"id":27606066},{"batb":[[2,180,1.32]],"batl":[[1,450,5],[2,1000,4]],"ltp":280.0,"tv":1.54,"id":24270700},{"batl":[[0,450,5.35],[1,1000,1.3]],"ltp":160.0,"tv":19.01,"id":13306150}]}]}
{"op":"mcm","clk":"993348586","pt":1580540991528,"mc":[{"id":"1.168133543","rc":[{"batl":[[0,95,5.02],[1,510,9.4]],"ltp":60.0,"tv":31.75,"id":7226819}]}]}
{"op":"mcm","clk":"993348618","pt":1580540992243,"mc":[{"id":"1.168133543","rc":[{"batl":[[0,95,5.29],[1,510,9.35]],"ltp":60.0,"tv":31.75,"id":7226819},{"batb":[[2,180,1.13]],"ltp":280.0,"tv":1.54,"id":24270700}]}]}
