{"op":"mcm","clk":"992017153","pt":1580512059478,"mc":[{"id":"1.168133543","rc":[{"batl":[[0,15.5,2.76],[1,16,3.03],[2,16.5,1.94]],"ltp":12.0,"tv":201.57,"id":22121325}]}]}
{"op":"mcm","clk":"992017201","pt":1580512060401,"mc":[{"id":"1.168133543","rc":[{"batb":[[0,180,1.96]],"ltp":280.0,"tv":1.54,"id":24270700}]}]}
{"op":"mcm","clk":"992017695","pt":1580512069496,"mc":[{"id":"1.168133543","rc":[{"trd":[[2.28,212.59],[2.3,488.15]],"batl":[[0,2.3,1.54],[1,2.32,4],[2,2.36,3.79]],"ltp":2.3,"tv":1905.62,"id":10107355}],"tv":3035.84}]}
{"op":"mcm","clk":"992017967","pt":1580512074503,"mc":[{"id":"1.168133543","rc":[{"batb":[[0,180,1.26]],"ltp":280.0,"tv":1.54,"id":24270700}]}]}
{"op":"mcm","clk":"992018131","pt":1580512077401,"mc":[{"id":"1.168133543","rc":[{"batl":[[0,9.8,3.38],[1,10,66],[2,29,9.24]],"ltp":9.8,"tv":145.43,"id":10163711},{"batl":[[1,2.36,3.79],[2,2.38,38.4]],"ltp":2.3,"tv":1905.62,"id":10107355}]}]}
{"op":"mcm","clk":"992021335","pt":1580512152524,"mc":[{"id":"1.168133543","rc":[{"batl":[[0,15,2],[1,15.5,2.76],[2,16,3.03]],"ltp":12.0,"tv":201.57,"id":22121325}]}]}
{"op":"mcm","clk":"992021466","pt":1580512157464,"mc":[{"id":"1.168133543","rc":[{"trd":[[2.84,78.79],[2.86,26.06]],"batb":[[0,2.82,8.69],[1,2.8,2],[2,2.78,2.52]],"ltp":2.84,"tv":770.52,"id":12636}],"tv":3085.84}]}
{"op":"mcm","clk":"992021547","pt":1580512159569,"mc":[{"id":"1.168133543","rc":[{"batl":[[0,14.5,1.92],[1,15,2]],"ltp":12.0,"tv":201.57,"id":22121325}]}]}
{"op":"mcm","clk":"992022102","pt":1580512176478,"mc":[{"id":"1.168133543","rc":[{"batl":[[2,16.5,1.94]],"ltp":12.0,"tv":201.57,"id":22121325}]}]}
{"op":"mcm","clk":"992022127","pt":1580512177355,"mc":[{"id":"1.168133543","rc":[{"batl":[[0,14.5,4.94]],"ltp":12.0,"tv":201.57,"id":22121325}]}]}
{"op":"mcm","clk":"992023139","pt":1580512205037,"mc":[{"id":"1.168133543","rc":[{"batl":[[0,2.9,60.54]],"ltp":2.84,"tv":770.52,"id":12636}]}]}
{"op":"mcm","clk":"992023207","pt":1580512206430,"mc":[{"id":"1.168133543","rc":[{"batl":[[0,14,2],[1,14.5,4.94]],"ltp":12.0,"tv":201.57,"id":22121325}]}]}
{"op":"mcm","clk":"992023809","pt":1580512219570,"mc":[{"id":"1.168133543","rc":[{"batl":[[0,13.5,2.06],[1,14,2],[2,14.5,3.03]],"ltp":12.0,"tv":201.57,"id":22121325}]}]}
{"op":"mcm","clk":"992024243","pt":1580512229564,"mc":[{"id":"1.168133543","rc":[{"trd":[[2.82,86.89],[2.84,80.05]],"batb":[[0,2.82,2.69]],"ltp":2.82,"tv":782.52,"id":12636}],"tv":3097.84}]}
{"op":"mcm","clk":"992024351","pt":1580512232493,"mc":[{"id":"1.168133543","rc":[{"batb":[[1,11,2.52]],"ltp":12.0,"tv":201.57,"id":22121325}]}]}
{"op":"mcm","clk":"992024498","pt":1580512235482,"mc":[{"id":"1.168133543","rc":[{"batl":[[0,2.88,2],[1,2.9,60.54],[2,2.92,50]],"ltp":2.82,"tv":782.52,"id":12636}]}]}
{"op":"mcm","clk":"992024681","pt":1580512240178,"mc":[{"id":"1.168133543","rc":[{"batl":[[0,2.88,7.93]],"ltp":2.82,"tv":782.52,"id":12636},{"batl":[[0,13.5,5.09],[2,16.5,1.94]],"ltp":12.0,"tv":201.57,"id":22121325}]}]}
{"op":"mcm","clk":"992024907","pt":1580512245079,"mc":[{"id":"1.168133543","rc":[{"batl":[[0,2.3,4.57]],"ltp":2.3,"tv":1905.62,"id":10107355}]}]}
{"op":"mcm","clk":"992025007","pt":1580512246892,"mc":[{"id":"1.168133543","rc":[{"batb":[[1,9.2,13.86],[2,9,15.68]],"ltp":9.8,"tv":145.43,"id":10163711},{"batb":[[1,11,13.71]],"ltp":12.0,"tv":201.57,"id":22121325},{"batb":[[0,180,1.96]],"ltp":280.0,"tv":1.54,"id":24270700}]}]}
{"op":"mcm","clk":"992025614","pt":1580512260218,"mc":[{"id":"1.168133543","rc":[{"batl":[[1,16.5,1.94],[2,65,9.08]],"ltp":12.0,"tv":201.57,"id":22121325}]}]}
{"op":"mcm","clk":"992026114","pt":1580512272522,"mc":[{"id":"1.168133543","rc":[{"batl":[[0,10,66],[1,29,9.24],[2,1000,1.45]],"ltp":9.8,"tv":145.43,"id":10163711},{"batl":[[0,13.5,2.06],[2,60,3.11]],"ltp":12.0,"tv":201.57,"id":22121325}]}]}
{"op":"mcm","clk":"992026280","pt":1580512276450,"mc":[{"id":"1.168133543","rc":[{"batb":[[1,9,15.79],[2,8.8,4.18]],"ltp":9.8,"tv":145.43,"id":10163711}]}]}
{"op":"mcm","clk":"992026294","pt":1580512276756,"mc":[{"id":"1.168133543","rc":[{"batl":[[0,2.86,2],[1,2.88,7.93],[2,2.9,60.54]],"ltp":2.82,"tv":782.52,"id":12636}]}]}
{"op":"mcm","clk":"992026467","pt":1580512280552,"mc":[{"id":"1.168133543","rc":[{"batl":[[0,16,1.73]],"ltp":12.0,"tv":201.57,"id":22121325}]}]}
{"op":"mcm","clk":"992026488","pt":1580512281062,"mc":[{"id":"1.168133543","rc":[{"batl":[[0,16,1.91]],"ltp":12.0,"tv":201.57,"id":22121325}]}]}
{"op":"mcm","clk":"992027240","pt":1580512298491,"mc":[{"id":"1.168133543","rc":[{"batl":[[0,2.86,5.03]],"ltp":2.82,"tv":782.52,"id":12636}]}]}
{"op":"mcm","clk":"992027266","pt":1580512299164,"mc":[{"id":"1.168133543","rc":[{"batl":[[2,2.9,57.51]],"ltp":2.82,"tv":782.52,"id":12636}]}]}
{"op":"mcm","clk":"992027438","pt":1580512303488,"mc":[{"id":"1.168133543","rc":[{"batl":[[0,9.8,3.38],[1,10,66],[2,29,9.24]],"ltp":9.8,"tv":145.43,"id":10163711}]}]}
{"op":"mcm","clk":"992027473","pt":1580512304503,"mc":[{"id":"1.168133543","rc":[{"batl":[[0,16,4.94],[2,65,9.08]],"ltp":12.0,"tv":201.57,"id":22121325}]}]}
{"op":"mcm","clk":"992030190","pt":1580512368490,"mc":[{"id":"1.168133543","rc":[{"batl":[[0,15.5,2],[1,16,4.94],[2,16.5,1.94]],"ltp":12.0,"tv":201.57,"id":22121325}]}]}
{"op":"mcm","clk":"992030670","pt":1580512380521,"mc":[{"id":"1.168133543","rc":[{"batl":[[0,15,2.86],[1,15.5,2],[2,16,3.21]],"ltp":12.0,"tv":201.57,"id":22121325}]}]}
{"op":"mcm","clk":"992038486","pt":1580512570466,"mc":[{"id":"1.168133543","rc":[{"batl":[[1,2.38,38.4],[2,2.4,2.23]],"ltp":2.3,"tv":1905.62,"id":10107355}]}]}
{"op":"mcm","clk":"992040138","pt":1580512610087,"mc":[{"id":"1.168133543","rc":[{"trd":[[11,21.22],[11.5,23.96]],"batb":[[0,11,7.7],[1,9.8,5.06],[2,8.4,5.13]],"ltp":11.0,"tv":217.57,"id":22121325}],"tv":3113.84}]}
{"op":"mcm","clk":"992040199","pt":1580512611537,"mc":[{"id":"1.168133543","rc":[{"batb":[[0,9.8,5.06],[1,8.4,5.13],[2,7.8,3.67]],"ltp":11.0,"tv":217.57,"id":22121325}]}]}
{"op":"mcm","clk":"992040208","pt":1580512611693,"mc":[{"id":"1.168133543","rc":[{"batb":[[1,9.2,13.86],[2,9,15.68]],"ltp":9.8,"tv":145.43,"id":10163711},{"batb":[[0,10,8.56],[1,9.8,4.97],[2,8.4,5.13]],"ltp":11.0,"tv":217.57,"id":22121325}]}]}
{"op":"mcm","clk":"992040271","pt":1580512613198,"mc":[{"id":"1.168133543","rc":[{"batl":[[0,15,3.04],[2,16,3.03]],"ltp":11.0,"tv":217.57,"id":22121325}]}]}
{"op":"mcm","clk":"992040506","pt":1580512618530,"mc":[{"id":"1.168133543","rc":[{"batl":[[0,10,66],[1,29,9.24],[2,1000,1.45]],"ltp":9.8,"tv":145.43,"id":10163711},{"batl":[[2,16.5,1.94]],"ltp":11.0,"tv":217.57,"id":22121325}]}]}
{"op":"mcm","clk":"992040509","pt":1580512618630,"mc":[{"id":"1.168133543","rc":[{"batl":[[0,14.5,3.21],[1,15,2.86],[2,15.5,2]],"ltp":11.0,"tv":217.57,"id":22121325}]}]}
{"op":"mcm","clk":"992040591","pt":1580512620444,"mc":[{"id":"1.168133543","rc":[{"batl":[[0,14,1.98],[1,14.5,3.21]],"ltp":11.0,"tv":217.57,"id":22121325}]}]}
{"op":"mcm","clk":"992041330","pt":1580512638535,"mc":[{"id":"1.168133543","rc":[{"batl":[[0,13.5,2],[1,14,1.98],[2,14.5,3.21]],"ltp":11.0,"tv":217.57,"id":22121325}]}]}
{"op":"mcm","clk":"992041393","pt":1580512640544,"mc":[{"id":"1.168133543","rc":[{"batl":[[1,14.5,3.21],[2,16.5,1.94]],"ltp":11.0,"tv":217.57,"id":22121325}]}]}
{"op":"mcm","clk":"992041402","pt":1580512640752,"mc":[{"id":"1.168133543","rc":[{"batl":[[0,13,2.13],[1,13.5,2],[2,14.5,3.21]],"ltp":11.0,"tv":217.57,"id":22121325}]}]}
{"op":"mcm","clk":"992041468","pt":1580512642555,"mc":[{"id":"1.168133543","rc":[{"batb":[[0,9.4,1.91],[2,9,15.61]],"ltp":9.8,"tv":145.43,"id":10163711},{"batb":[[0,2.24,23.06]],"ltp":2.3,"tv":1905.62,"id":10107355},{"batb":[[0,10.5,1.98],[1,10,8.56],[2,9.8,4.97]],"ltp":11.0,"tv":217.57,"id":22121325}]}]}
{"op":"mcm","clk":"992041507","pt":1580512643580,"mc":[{"id":"1.168133543","rc":[{"batl":[[2,14.5,3.03]],"ltp":11.0,"tv":217.57,"id":22121325}]}]}
{"op":"mcm","clk":"992041795","pt":1580512650469,"mc":[{"id":"1.168133543","rc":[{"batl":[[0,13,5.16],[2,16.5,1.94]],"ltp":11.0,"tv":217.57,"id":22121325}]}]}
{"op":"mcm","clk":"992042171","pt":1580512658390,"mc":[{"id":"1.168133543","rc":[{"batb":[[1,110,2.36]],"ltp":580.0,"tv":6.13,"id":27606066}]}]}
{"op":"mcm","clk":"992042873","pt":1580512674554,"mc":[{"id":"1.168133543","rc":[{"batb":[[1,110,1.21]],"ltp":580.0,"tv":6.13,"id":27606066}]}]}
{"op":"mcm","clk":"992042877","pt":1580512674663,"mc":[{"id":"1.168133543","rc":[{"batb":[[1,120,1.41],[2,100,17.67]],"ltp":580.0,"tv":6.13,"id":27606066}]}]}
{"op":"mcm","clk":"992043238","pt":1580512682561,"mc":[{"id":"1.168133543","rc":[{"batl":[[0,13,2.13]],"ltp":11.0,"tv":217.57,"id":22121325}]}]}
{"op":"mcm","clk":"992043243","pt":1580512682666,"mc":[{"id":"1.168133543","rc":[{"batl":[[2,16,3.03]],"ltp":11.0,"tv":217.57,"id":22121325}]}]}
{"op":"mcm","clk":"992043685","pt":1580512692488,"mc":[{"id":"1.168133543","rc":[{"batl":[[1,15.5,2]],"ltp":11.0,"tv":217.57,"id":22121325}]}]}
{"op":"mcm","clk":"992044074","pt":1580512701500,"mc":[{"id":"1.168133543","rc":[{"batl":[[0,15,2.86]],"ltp":11.0,"tv":217.57,"id":22121325}]}]}
{"op":"mcm","clk":"992047294","pt":1580512787186,"mc":[{"id":"1.168133543","rc":[{"batl":[[1,2.88,5.93]],"ltp":2.82,"tv":782.52,"id":12636}]}]}
{"op":"mcm","clk":"992049335","pt":1580512831667,"mc":[{"id":"1.168133543","rc":[{"batl":[[0,2.86,3.03]],"ltp":2.82,"tv":782.52,"id":12636}]}]}
{"op":"mcm","clk":"992052234","pt":1580512910512,"mc":[{"id":"1.168133543","rc":[{"trd":[[85,3.48],[90,0.52]],"batb":[[0,80,2.22],[1,70,1.1],[2,60,1.23]],"ltp":85.0,"tv":5.36,"id":26548208}],"tv":3117.84}]}
{"op":"mcm","clk":"992052829","pt":1580512926564,"mc":[{"id":"1.168133543","rc":[{"batb":[[0,80,2.39]],"ltp":85.0,"tv":5.36,"id":26548208}]}]}
{"op":"mcm","clk":"992052967","pt":1580512929985,"mc":[{"id":"1.168133543","rc":[{"batl":[[0,160,4.2]],"ltp":85.0,"tv":5.36,"id":26548208}]}]}
{"op":"mcm","clk":"992053653","pt":1580512945072,"mc":[{"id":"1.168133543","rc":[{"trd":[[9,31.78],[9.2,35.74],[9.4,13.81]],"batb":[[0,9,1.4],[1,8.8,4.18],[2,8.6,2.52]],"ltp":9.0,"tv":205.41,"id":10163711}],"tv":3177.82}]}
{"op":"mcm","clk":"992053699","pt":1580512945903,"mc":[{"id":"1.168133543","rc":[{"batl":[[1,17,1.88],[2,29,9.24]],"ltp":9.0,"tv":205.41,"id":10163711}]}]}
{"op":"mcm","clk":"992053798","pt":1580512948300,"mc":[{"id":"1.168133543","rc":[{"batb":[[2,8.6,4.85]],"ltp":9.0,"tv":205.41,"id":10163711}]}]}
{"op":"mcm","clk":"992053842","pt":1580512949076,"mc":[{"id":"1.168133543","rc":[{"batl":[[0,10,66.09]],"ltp":9.0,"tv":205.41,"id":10163711},{"batb":[[0,2.26,7.62],[1,2.24,23.06],[2,2.22,31.09]],"ltp":2.3,"tv":1905.62,"id":10107355},{"batb":[[0,10.5,3.62]],"ltp":11.0,"tv":217.57,"id":22121325}]}]}
{"op":"mcm","clk":"992063854","pt":1580512958505,"mc":[{"id":"1.168133543","rc":[{"batb":[[1,9.8,5.06],[2,8.4,5.13]],"ltp":11.0,"tv":217.57,"id":22121325}]}]}
{"op":"mcm","clk":"992063858","pt":1580512958605,"mc":[{"id":"1.168133543","rc":[{"batb":[[0,10.5,11.68]],"ltp":11.0,"tv":217.57,"id":22121325}]}]}
{"op":"mcm","clk":"992064068","pt":1580512963921,"mc":[{"id":"1.168133543","rc":[{"batl":[[0,9.8,2.09],[1,10,66],[2,17,1.88]],"ltp":9.0,"tv":205.41,"id":10163711}]}]}
{"op":"mcm","clk":"992064400","pt":1580512973558,"mc":[{"id":"1.168133543","rc":[{"batl":[[0,9.8,5.12]],"ltp":9.0,"tv":205.41,"id":10163711}]}]}
{"op":"mcm","clk":"992066475","pt":1580513020535,"mc":[{"id":"1.168133543","rc":[{"batb":[[0,9,3.38]],"ltp":9.0,"tv":205.41,"id":10163711},{"batb":[[1,2.24,20]],"ltp":2.3,"tv":1905.62,"id":10107355}]}]}
{"op":"mcm","clk":"992066481","pt":1580513020638,"mc":[{"id":"1.168133543","rc":[{"batb":[[0,2.26,10.68]],"ltp":2.3,"tv":1905.62,"id":10107355}]}]}
{"op":"mcm","clk":"992067232","pt":1580513039158,"mc":[{"id":"1.168133543","rc":[{"trd":[[2.26,103.32]],"batb":[[0,2.26,7.65]],"ltp":2.26,"tv":1911.68,"id":10107355}],"tv":3183.88}]}
{"op":"mcm","clk":"992068635","pt":1580513073183,"mc":[{"id":"1.168133543","rc":[{"batl":[[0,9.8,3.12]],"ltp":9.0,"tv":205.41,"id":10163711}]}]}
{"op":"mcm","clk":"992071900","pt":1580513165861,"mc":[{"id":"1.168133543","rc":[{"trd":[[2.86,32.12]],"batb":[[0,2.86,14.32],[1,2.82,2.69],[2,2.8,2]],"batl":[[0,2.88,5.93],[1,2.9,57.51],[2,2.92,50]],"ltp":2.86,"tv":788.58,"id":12636}],"tv":3189.94}]}
{"op":"mcm","clk":"992071975","pt":1580513167358,"mc":[{"id":"1.168133543","rc":[{"batl":[[0,2.9,57.51],[1,2.92,50],[2,2.94,58.02]],"ltp":2.86,"tv":788.58,"id":12636}]}]}
{"op":"mcm","clk":"992072721","pt":1580513188392,"mc":[{"id":"1.168133543","rc":[{"trd":[[2.3,492.15]],"batl":[[0,2.3,2.57]],"ltp":2.3,"tv":1915.68,"id":10107355}],"tv":3193.94}]}
{"op":"mcm","clk":"992073468","pt":1580513209715,"mc":[{"id":"1.168133543","rc":[{"batl":[[1,2.36,4],[2,2.38,38.4]],"ltp":2.3,"tv":1915.68,"id":10107355}]}]}
{"op":"mcm","clk":"992077778","pt":1580513314131,"mc":[{"id":"1.168133543","rc":[{"batb":[[0,2.88,5.98],[1,2.86,14.32],[2,2.82,2.69]],"ltp":2.86,"tv":788.58,"id":12636}]}]}
{"op":"mcm","clk":"992090808","pt":1580513618535,"mc":[{"id":"1.168133543","rc":[{"trd":[[2.3,497.29]],"batb":[[0,2.3,8.01],[1,2.26,7.65],[2,2.24,20]],"batl":[[0,2.36,4],[1,2.38,38.4],[2,2.4,2.23]],"ltp":2.3,"tv":1920.82,"id":10107355}],"tv":3199.08}]}
{"op":"mcm","clk":"992090839","pt":1580513619207,"mc":[{"id":"1.168133543","rc":[{"trd":[[2.3,513.31]],"batb":[[0,2.26,7.65],[1,2.24,20],[2,2.22,18.69]],"batl":[[0,2.3,16.02],[1,2.36,4],[2,2.38,38.4]],"ltp":2.3,"tv":1936.84,"id":10107355}],"tv":3215.1}]}
{"op":"mcm","clk":"992091497","pt":1580513633542,"mc":[{"id":"1.168133543","rc":[{"batl":[[1,2.38,38.4],[2,2.4,2.23]],"ltp":2.3,"tv":1936.84,"id":10107355}]}]}
{"op":"mcm","clk":"992092418","pt":1580513654553,"mc":[{"id":"1.168133543","rc":[{"trd":[[2.3,545.31]],"batb":[[0,2.28,12.15],[1,2.26,7.65],[2,2.24,20]],"batl":[[0,2.38,38.42],[1,2.4,2.23],[2,2.48,50]],"ltp":2.3,"tv":1968.84,"id":10107355}],"tv":3247.1}]}
{"op":"mcm","clk":"992092672","pt":1580513660485,"mc":[{"id":"1.168133543","rc":[{"batb":[[0,180,1.26]],"ltp":280.0,"tv":1.54,"id":24270700}]}]}
{"op":"mcm","clk":"992093044","pt":1580513668474,"mc":[{"id":"1.168133543","rc":[{"trd":[[2.3,545.35],[2.38,111.16]],"batl":[[0,2.4,2.65],[1,2.48,50],[2,2.5,50]],"ltp":2.38,"tv":2044.84,"id":10107355}],"tv":3323.1}]}
{"op":"mcm","clk":"992093200","pt":1580513672569,"mc":[{"id":"1.168133543","rc":[{"batl":[[1,2.46,4],[2,2.48,50]],"ltp":2.38,"tv":2044.84,"id":10107355}]}]}
{"op":"mcm","clk":"992093351","pt":1580513676491,"mc":[{"id":"1.168133543","rc":[{"batb":[[0,48,1.4]],"ltp":50.0,"tv":15.25,"id":7226819},{"trd":[[2.38,112],[2.4,22.7]],"batl":[[0,2.46,4.65],[1,2.48,50],[2,2.5,50]],"ltp":2.4,"tv":2048.84,"id":10107355},{"batb":[[0,80,1.88]],"ltp":85.0,"tv":5.36,"id":26548208},{"batb":[[1,100,1.15],[2,90,1.36]],"ltp":160.0,"tv":19.01,"id":13306150}],"tv":3327.1}]}
{"op":"mcm","clk":"992094001","pt":1580513692414,"mc":[{"id":"1.168133543","rc":[{"batb":[[1,70,1.61]],"ltp":85.0,"tv":5.36,"id":26548208}]}]}
{"op":"mcm","clk":"992094674","pt":1580513707407,"mc":[{"id":"1.168133543","rc":[{"batb":[[1,70,1.1]],"ltp":85.0,"tv":5.36,"id":26548208}]}]}
{"op":"mcm","clk":"992095163","pt":1580513717639,"mc":[{"id":"1.168133543","rc":[{"batl":[[0,2.44,2.65],[1,2.46,4],[2,2.48,50]],"ltp":2.4,"tv":2048.84,"id":10107355}]}]}
{"op":"mcm","clk":"992095472","pt":1580513723463,"mc":[{"id":"1.168133543","rc":[{"batb":[[1,70,1.61]],"ltp":85.0,"tv":5.36,"id":26548208}]}]}
{"op":"mcm","clk":"992096166","pt":1580513739441,"mc":[{"id":"1.168133543","rc":[{"batb":[[1,70,1.1]],"ltp":85.0,"tv":5.36,"id":26548208}]}]}
{"op":"mcm","clk":"992096952","pt":1580513755408,"mc":[{"id":"1.168133543","rc":[{"batb":[[1,70,1.61]],"ltp":85.0,"tv":5.36,"id":26548208}]}]}
{"op":"mcm","clk":"992097661","pt":1580513771492,"mc":[{"id":"1.168133543","rc":[{"batb":[[1,70,1.1]],"ltp":85.0,"tv":5.36,"id":26548208}]}]}
{"op":"mcm","clk":"992098366","pt":1580513787434,"mc":[{"id":"1.168133543","rc":[{"batb":[[1,70,1.61]],"ltp":85.0,"tv":5.36,"id":26548208}]}]}
{"op":"mcm","clk":"992098709","pt":1580513795238,"mc":[{"id":"1.168133543","rc":[{"batl":[[0,2.4,3.68],[1,2.44,2],[2,2.46,4]],"ltp":2.4,"tv":2048.84,"id":10107355}]}]}
{"op":"mcm","clk":"992098918","pt":1580513801445,"mc":[{"id":"1.168133543","rc":[{"batl":[[0,2.38,4],[1,2.4,3.68],[2,2.44,2]],"ltp":2.4,"tv":2048.84,"id":10107355}]}]}
{"op":"mcm","clk":"992099021","pt":1580513803555,"mc":[{"id":"1.168133543","rc":[{"batb":[[2,44,3.32]],"ltp":50.0,"tv":15.25,"id":7226819},{"batb":[[0,80,2.39],[1,70,1.1]],"ltp":85.0,"tv":5.36,"id":26548208},{"batb":[[1,100,1.66]],"ltp":160.0,"tv":19.01,"id":13306150}]}]}
{"op":"mcm","clk":"992099050","pt":1580513804431,"mc":[{"id":"1.168133543","rc":[{"batb":[[1,46,1.19]],"ltp":50.0,"tv":15.25,"id":7226819}]}]}
{"op":"mcm","clk":"992099425","pt":1580513814949,"mc":[{"id":"1.168133543","rc":[{"batl":[[0,2.38,7.03]],"ltp":2.4,"tv":2048.84,"id":10107355}]}]}
{"op":"mcm","clk":"992099625","pt":1580513819472,"mc":[{"id":"1.168133543","rc":[{"batb":[[2,42,1.86]],"ltp":50.0,"tv":15.25,"id":7226819},{"batb":[[1,100,1.15]],"ltp":160.0,"tv":19.01,"id":13306150}]}]}
{"op":"mcm","clk":"992099648","pt":1580513819883,"mc":[{"id":"1.168133543","rc":[{"batb":[[1,46,3.73]],"ltp":50.0,"tv":15.25,"id":7226819},{"batb":[[1,110,1.16],[2,90,1.86]],"ltp":160.0,"tv":19.01,"id":13306150}]}]}
{"op":"mcm","clk":"992099813","pt":1580513823571,"mc":[{"id":"1.168133543","rc":[{"batl":[[0,2.38,3.03]],"ltp":2.4,"tv":2048.84,"id":10107355}]}]}
{"op":"mcm","clk":"992099912","pt":1580513825681,"mc":[{"id":"1.168133543","rc":[{"batl":[[2,2.48,50]],"ltp":2.4,"tv":2048.84,"id":10107355}]}]}
{"op":"mcm","clk":"992118592","pt":1580514041339,"mc":[{"id":"1.168133543","rc":[{"batb":[[0,2.28,20.92]],"ltp":2.4,"tv":2048.84,"id":10107355}]}]}
{"op":"mcm","clk":"992128015","pt":1580514316527,"mc":[{"id":"1.168133543","rc":[{"trd":[[2.9,32.86]],"batl":[[0,2.9,52.51]],"ltp":2.9,"tv":798.58,"id":12636}],"tv":3337.1}]}
{"op":"mcm","clk":"992130106","pt":1580514386525,"mc":[{"id":"1.168133543","rc":[{"trd":[[2.38,118.06]],"batb":[[0,2.38,3.07],[1,2.28,20.92],[2,2.26,7.65]],"batl":[[0,2.4,3.68],[1,2.48,50],[2,2.5,50]],"ltp":2.38,"tv":2054.9,"id":10107355}],"tv":3343.16}]}
{"op":"mcm","clk":"992130126","pt":1580514387142,"mc":[{"id":"1.168133543","rc":[{"trd":[[2.38,124.2],[2.4,29.69]],"batb":[[0,2.28,8.77],[1,2.26,7.65],[2,2.24,20]],"batl":[[0,2.38,6.13],[1,2.48,50.18]],"ltp":2.4,"tv":2068.03,"id":10107355}],"tv":3356.29}]}
{"op":"mcm","clk":"992131268","pt":1580514420202,"mc":[{"id":"1.168133543","rc":[{"batb":[[0,2.28,12.15]],"ltp":2.4,"tv":2068.03,"id":10107355}]}]}
{"op":"mcm","clk":"992133273","pt":1580514490980,"mc":[{"id":"1.168133543","rc":[{"trd":[[2.88,57.59]],"batb":[[0,2.86,14.32],[1,2.82,2.69],[2,2.8,2]],"batl":[[0,2.88,4.02],[1,2.9,52.51],[2,2.92,50]],"ltp":2.88,"tv":810.55,"id":12636}],"tv":3368.25}]}
{"op":"mcm","clk":"992133504","pt":1580514499387,"mc":[{"id":"1.168133543","rc":[{"trd":[[2.86,56.12]],"batb":[[0,2.86,2.32]],"ltp":2.86,"tv":834.55,"id":12636}],"tv":3392.25}]}
{"op":"mcm","clk":"992133634","pt":1580514503395,"mc":[{"id":"1.168133543","rc":[{"batb":[[0,180,1.96]],"ltp":280.0,"tv":1.54,"id":24270700}]}]}
{"op":"mcm","clk":"992134535","pt":1580514534331,"mc":[{"id":"1.168133543","rc":[{"batl":[[1,2.48,50]],"ltp":2.4,"tv":2068.03,"id":10107355}]}]}
{"op":"mcm","clk":"992134676","pt":1580514538950,"mc":[{"id":"1.168133543","rc":[{"trd":[[2.38,130]],"batl":[[0,2.38,3.23]],"ltp":2.38,"tv":2073.83,"id":10107355}],"tv":3398.05}]}
{"op":"mcm","clk":"992134760","pt":1580514541468,"mc":[{"id":"1.168133543","rc":[{"batl":[[0,2.36,2],[1,2.38,4.75],[2,2.48,50]],"ltp":2.38,"tv":2073.83,"id":10107355}]}]}
{"op":"mcm","clk":"992134784","pt":1580514542398,"mc":[{"id":"1.168133543","rc":[{"batl":[[0,2.38,4.75],[1,2.48,50],[2,2.5,50]],"ltp":2.38,"tv":2073.83,"id":10107355}]}]}
{"op":"mcm","clk":"992134806","pt":1580514543015,"mc":[{"id":"1.168133543","rc":[{"batb":[[0,2.3,7.49],[1,2.28,12.15],[2,2.26,3.06]],"ltp":2.38,"tv":2073.83,"id":10107355}]}]}
{"op":"mcm","clk":"992135032","pt":1580514551448,"mc":[{"id":"1.168133543","rc":[{"batb":[[0,180,1.26]],"ltp":280.0,"tv":1.54,"id":24270700}]}]}
{"op":"mcm","clk":"992149555","pt":1580514760000,"mc":[{"id":"1.168133543","rc":[{"trd":[[2.86,60.76]],"batb":[[0,2.82,2.69],[1,2.8,2],[2,2.78,2.52]],"ltp":2.86,"tv":839.19,"id":12636}],"tv":3402.69}]}
{"op":"mcm","clk":"992149684","pt":1580514765819,"mc":[{"id":"1.168133543","rc":[{"trd":[[2.82,92.27]],"batb":[[0,2.8,2],[1,2.78,2.52],[2,2.1,25]],"ltp":2.82,"tv":844.57,"id":12636}],"tv":3408.07}]}
{"op":"mcm","clk":"992149833","pt":1580514771437,"mc":[{"id":"1.168133543","rc":[{"batb":[[0,180,1.96]],"ltp":280.0,"tv":1.54,"id":24270700}]}]}
{"op":"mcm","clk":"992149916","pt":1580514774517,"mc":[{"id":"1.168133543","rc":[{"batl":[[0,2.86,5.22],[1,2.88,4.02],[2,2.9,52.51]],"ltp":2.82,"tv":844.57,"id":12636}]}]}
{"op":"mcm","clk":"992149995","pt":1580514777244,"mc":[{"id":"1.168133543","rc":[{"trd":[[2.8,50.88]],"batb":[[0,2.78,2.52],[1,2.1,25],[2,2.02,7.38]],"ltp":2.8,"tv":848.57,"id":12636}],"tv":3412.07}]}
{"op":"mcm","clk":"992150132","pt":1580514781531,"mc":[{"id":"1.168133543","rc":[{"batb":[[0,2.12,2.52]],"ltp":2.8,"tv":848.57,"id":12636},{"batb":[[1,16.5,2.52],[2,16,3.03]],"ltp":80.0,"tv":11.61,"id":22308007},{"batb":[[2,44,3.19]],"ltp":50.0,"tv":15.25,"id":7226819},{"batb":[[0,9,5.9]],"ltp":9.0,"tv":205.41,"id":10163711},{"batb":[[0,2.32,2.52],[1,2.3,7.49],[2,2.28,12.15]],"ltp":2.38,"tv":2073.83,"id":10107355},{"batb":[[0,11,2.52],[1,10.5,11.68],[2,9.8,5.06]],"ltp":11.0,"tv":217.57,"id":22121325}]}]}
{"op":"mcm","clk":"992150152","pt":1580514782048,"mc":[{"id":"1.168133543","rc":[{"batb":[[2,160,1.36]],"ltp":280.0,"tv":1.54,"id":24270700}]}]}
{"op":"mcm","clk":"992150228","pt":1580514784262,"mc":[{"id":"1.168133543","rc":[{"batb":[[0,2.12,9.78]],"batl":[[0,2.78,2.52],[1,2.86,5.22],[2,2.88,4.02]],"ltp":2.8,"tv":848.57,"id":12636}]}]}
{"op":"mcm","clk":"992150294","pt":1580514786071,"mc":[{"id":"1.168133543","rc":[{"batl":[[0,2.78,2.7]],"ltp":2.8,"tv":848.57,"id":12636}]}]}
{"op":"mcm","clk":"992150488","pt":1580514792374,"mc":[{"id":"1.168133543","rc":[{"batl":[[0,2.86,5.4],[1,2.88,4.02],[2,2.9,52.51]],"ltp":2.8,"tv":848.57,"id":12636}]}]}
{"op":"mcm","clk":"992150586","pt":1580514796092,"mc":[{"id":"1.168133543","rc":[{"batb":[[0,2.14,20.02],[1,2.12,9.78],[2,2.1,25]],"ltp":2.8,"tv":848.57,"id":12636}]}]}
{"op":"mcm","clk":"992150817","pt":1580514803467,"mc":[{"id":"1.168133543","rc":[{"batb":[[0,2.16,3.91],[1,2.14,20.02],[2,2.12,9.78]],"ltp":2.8,"tv":848.57,"id":12636},{"batb":[[0,55,3.93]],"ltp":80.0,"tv":11.61,"id":22308007},{"batb":[[2,8.6,2.52]],"ltp":9.0,"tv":205.41,"id":10163711}]}]}
{"op":"mcm","clk":"992150847","pt":1580514804496,"mc":[{"id":"1.168133543","rc":[{"batb":[[1,10.5,3.62]],"ltp":11.0,"tv":217.57,"id":22121325}]}]}
{"op":"mcm","clk":"992150867","pt":1580514805168,"mc":[{"id":"1.168133543","rc":[{"batb":[[0,2.16,37.9]],"ltp":2.8,"tv":848.57,"id":12636},{"batb":[[0,11,10.22]],"ltp":11.0,"tv":217.57,"id":22121325}]}]}
{"op":"mcm","clk":"992150994","pt":1580514808367,"mc":[{"id":"1.168133543","rc":[{"batb":[[0,2.18,6.84],[1,2.16,37.9],[2,2.14,20.02]],"ltp":2.8,"tv":848.57,"id":12636}]}]}
{"op":"mcm","clk":"992151114","pt":1580514814569,"mc":[{"id":"1.168133543","rc":[{"batb":[[0,2.34,17.73],[1,2.32,2.52],[2,2.3,7.49]],"ltp":2.38,"tv":2073.83,"id":10107355}]}]}
{"op":"mcm","clk":"992151154","pt":1580514816475,"mc":[{"id":"1.168133543","rc":[{"batb":[[2,2.12,9.78]],"ltp":2.8,"tv":848.57,"id":12636}]}]}
{"op":"mcm","clk":"992151163","pt":1580514816786,"mc":[{"id":"1.168133543","rc":[{"batb":[[0,2.2,19.48],[1,2.18,6.84],[2,2.16,37.9]],"ltp":2.8,"tv":848.57,"id":12636}]}]}
{"op":"mcm","clk":"992151244","pt":1580514820502,"mc":[{"id":"1.168133543","rc":[{"batb":[[2,2.16,3.91]],"ltp":2.8,"tv":848.57,"id":12636}]}]}
{"op":"mcm","clk":"992151247","pt":1580514820603,"mc":[{"id":"1.168133543","rc":[{"batb":[[0,2.22,33.06],[1,2.2,19.48],[2,2.18,6.84]],"ltp":2.8,"tv":848.57,"id":12636}]}]}
{"op":"mcm","clk":"992151289","pt":1580514822316,"mc":[{"id":"1.168133543","rc":[{"batb":[[0,2.24,1.98],[1,2.22,33.06],[2,2.2,19.48]],"ltp":2.8,"tv":848.57,"id":12636},{"batb":[[0,48,3.08]],"ltp":50.0,"tv":15.25,"id":7226819},{"batb":[[0,2.34,20.79]],"ltp":2.38,"tv":2073.83,"id":10107355},{"batb":[[0,11.5,1.98],[1,11,10.22],[2,10.5,1.64]],"ltp":11.0,"tv":217.57,"id":22121325}]}]}
{"op":"mcm","clk":"992151503","pt":1580514833521,"mc":[{"id":"1.168133543","rc":[{"batb":[[0,2.24,5.65]],"ltp":2.8,"tv":848.57,"id":12636}]}]}
{"op":"mcm","clk":"992151554","pt":1580514836516,"mc":[{"id":"1.168133543","rc":[{"batb":[[0,48,5.52],[1,46,1.19]],"ltp":50.0,"tv":15.25,"id":7226819}]}]}
{"op":"mcm","clk":"992151582","pt":1580514838524,"mc":[{"id":"1.168133543","rc":[{"batb":[[2,2.18,6.84]],"ltp":2.8,"tv":848.57,"id":12636}]}]}
{"op":"mcm","clk":"992151591","pt":1580514838935,"mc":[{"id":"1.168133543","rc":[{"batb":[[0,2.26,18.96],[1,2.24,5.65],[2,2.22,33.06]],"ltp":2.8,"tv":848.57,"id":12636}]}]}
{"op":"mcm","clk":"992151636","pt":1580514841354,"mc":[{"id":"1.168133543","rc":[{"batb":[[0,2.28,6.15],[1,2.26,18.96],[2,2.24,5.65]],"ltp":2.8,"tv":848.57,"id":12636}]}]}
{"op":"mcm","clk":"992151716","pt":1580514845673,"mc":[{"id":"1.168133543","rc":[{"trd":[[11.5,25.96]],"batb":[[0,11,11.2],[1,10.5,1.64],[2,9.8,5.06]],"ltp":11.5,"tv":219.57,"id":22121325}],"tv":3414.07}]}
{"op":"mcm","clk":"992151870","pt":1580514852535,"mc":[{"id":"1.168133543","rc":[{"batb":[[0,2.28,38.35]],"ltp":2.8,"tv":848.57,"id":12636}]}]}
{"op":"mcm","clk":"992152009","pt":1580514859239,"mc":[{"id":"1.168133543","rc":[{"batb":[[1,2.24,5.65],[2,2.12,9.78]],"ltp":2.8,"tv":848.57,"id":12636}]}]}
{"op":"mcm","clk":"992152094","pt":1580514863469,"mc":[{"id":"1.168133543","rc":[{"batb":[[0,2.3,3.5],[1,2.28,38.35],[2,2.24,1.98]],"ltp":2.8,"tv":848.57,"id":12636}]}]}
{"op":"mcm","clk":"992152450","pt":1580514874361,"mc":[{"id":"1.168133543","rc":[{"batb":[[0,2.32,6.04],[1,2.3,3.5],[2,2.28,32.2]],"ltp":2.8,"tv":848.57,"id":12636}]}]}
{"op":"mcm","clk":"992152649","pt":1580514881500,"mc":[{"id":"1.168133543","rc":[{"batb":[[0,2.34,18.31],[1,2.32,6.04],[2,2.3,3.5]],"ltp":2.8,"tv":848.57,"id":12636}]}]}
{"op":"mcm","clk":"992152728","pt":1580514884469,"mc":[{"id":"1.168133543","rc":[{"batb":[[0,2.36,31.1],[1,2.34,18.31],[2,2.32,6.04]],"ltp":2.8,"tv":848.57,"id":12636}]}]}
{"op":"mcm","clk":"992152911","pt":1580514893416,"mc":[{"id":"1.168133543","rc":[{"batb":[[0,2.38,3.29],[1,2.36,31.1],[2,2.34,18.31]],"ltp":2.8,"tv":848.57,"id":12636}]}]}
{"op":"mcm","clk":"992153185","pt":1580514903197,"mc":[{"id":"1.168133543","rc":[{"batb":[[0,2.4,17.85],[1,2.38,3.29],[2,2.36,31.1]],"ltp":2.8,"tv":848.57,"id":12636}]}]}
{"op":"mcm","clk":"992153226","pt":1580514904487,"mc":[{"id":"1.168133543","rc":[{"batb":[[0,2.42,1.99],[1,2.4,17.85],[2,2.38,3.29]],"ltp":2.8,"tv":848.57,"id":12636}]}]}
{"op":"mcm","clk":"992153311","pt":1580514907427,"mc":[{"id":"1.168133543","rc":[{"batb":[[0,2.42,7.78]],"ltp":2.8,"tv":848.57,"id":12636}]}]}
{"op":"mcm","clk":"992153573","pt":1580514916580,"mc":[{"id":"1.168133543","rc":[{"batb":[[0,2.42,38.11]],"ltp":2.8,"tv":848.57,"id":12636}]}]}
{"op":"mcm","clk":"992153606","pt":1580514918222,"mc":[{"id":"1.168133543","rc":[{"batb":[[0,2.44,1.98],[1,2.42,38.11],[2,2.4,17.85]],"ltp":2.8,"tv":848.57,"id":12636}]}]}
{"op":"mcm","clk":"992153746","pt":1580514923434,"mc":[{"id":"1.168133543","rc":[{"batb":[[0,2.44,5.14]],"ltp":2.8,"tv":848.57,"id":12636}]}]}
{"op":"mcm","clk":"992153782","pt":1580514924516,"mc":[{"id":"1.168133543","rc":[{"batb":[[0,2.46,17.42],[1,2.44,5.14],[2,2.42,38.11]],"ltp":2.8,"tv":848.57,"id":12636}]}]}
{"op":"mcm","clk":"992154049","pt":1580514932521,"mc":[{"id":"1.168133543","rc":[{"batb":[[0,2.48,29.6],[1,2.46,17.42],[2,2.44,5.14]],"ltp":2.8,"tv":848.57,"id":12636}]}]}
{"op":"mcm","clk":"992154255","pt":1580514940256,"mc":[{"id":"1.168133543","rc":[{"batb":[[0,2.5,5.6],[1,2.48,29.6],[2,2.46,17.42]],"ltp":2.8,"tv":848.57,"id":12636}]}]}
{"op":"mcm","clk":"992154428","pt":1580514947347,"mc":[{"id":"1.168133543","rc":[{"batb":[[2,2.44,5.14]],"ltp":2.8,"tv":848.57,"id":12636}]}]}
{"op":"mcm","clk":"992154562","pt":1580514953460,"mc":[{"id":"1.168133543","rc":[{"batb":[[2,2.44,1.98]],"ltp":2.8,"tv":848.57,"id":12636}]}]}
{"op":"mcm","clk":"992154608","pt":1580514955564,"mc":[{"id":"1.168133543","rc":[{"batb":[[0,2.52,2.99],[1,2.5,5.6],[2,2.48,29.6]],"ltp":2.8,"tv":848.57,"id":12636}]}]}
{"op":"mcm","clk":"992154852","pt":1580514964485,"mc":[{"id":"1.168133543","rc":[{"batb":[[1,2.5,34.97],[2,2.44,1.98]],"ltp":2.8,"tv":848.57,"id":12636},{"batb":[[0,2.36,7.3],[1,2.34,20.79],[2,2.32,2.52]],"ltp":2.38,"tv":2073.83,"id":10107355}]}]}
{"op":"mcm","clk":"992155864","pt":1580515012536,"mc":[{"id":"1.168133543","rc":[{"batb":[[2,2.42,1.99]],"ltp":2.8,"tv":848.57,"id":12636},{"batb":[[1,2.34,17.73]],"ltp":2.38,"tv":2073.83,"id":10107355}]}]}
{"op":"mcm","clk":"992155869","pt":1580515012640,"mc":[{"id":"1.168133543","rc":[{"batb":[[0,2.54,1.98],[1,2.52,2.99],[2,2.5,34.97]],"ltp":2.8,"tv":848.57,"id":12636},{"batb":[[0,2.36,10.36]],"ltp":2.38,"tv":2073.83,"id":10107355}]}]}
{"op":"mcm","clk":"992156147","pt":1580515023926,"mc":[{"id":"1.168133543","rc":[{"batb":[[0,11.5,2.48],[1,11,10.22]],"ltp":11.5,"tv":219.57,"id":22121325}]}]}
{"op":"mcm","clk":"992156235","pt":1580515027529,"mc":[{"id":"1.168133543","rc":[{"batb":[[2,2.5,5.6]],"ltp":2.8,"tv":848.57,"id":12636},{"batb":[[0,11.5,9.84],[1,11,2.52]],"ltp":11.5,"tv":219.57,"id":22121325}]}]}
{"op":"mcm","clk":"992156280","pt":1580515029428,"mc":[{"id":"1.168133543","rc":[{"batb":[[0,2.54,9.85]],"ltp":2.8,"tv":848.57,"id":12636}]}]}
{"op":"mcm","clk":"992156480","pt":1580515040507,"mc":[{"id":"1.168133543","rc":[{"batb":[[2,2.12,2.52]],"ltp":2.8,"tv":848.57,"id":12636}]}]}
{"op":"mcm","clk":"992156496","pt":1580515041022,"mc":[{"id":"1.168133543","rc":[{"batb":[[0,2.56,4.61],[1,2.54,9.85],[2,2.52,2.99]],"ltp":2.8,"tv":848.57,"id":12636}]}]}
{"op":"mcm","clk":"992156557","pt":1580515043489,"mc":[{"id":"1.168133543","rc":[{"batb":[[0,2.56,33.28]],"ltp":2.8,"tv":848.57,"id":12636}]}]}
{"op":"mcm","clk":"992157634","pt":1580515093265,"mc":[{"id":"1.168133543","rc":[{"batb":[[1,2.54,1.98]],"ltp":2.8,"tv":848.57,"id":12636}]}]}
{"op":"mcm","clk":"992157886","pt":1580515104273,"mc":[{"id":"1.168133543","rc":[{"batb":[[0,2.58,1.98],[1,2.56,33.28]],"ltp":2.8,"tv":848.57,"id":12636}]}]}
{"op":"mcm","clk":"992157963","pt":1580515107497,"mc":[{"id":"1.168133543","rc":[{"batb":[[1,2.56,4.61]],"ltp":2.8,"tv":848.57,"id":12636}]}]}
{"op":"mcm","clk":"992158222","pt":1580515123390,"mc":[{"id":"1.168133543","rc":[{"batb":[[1,2.56,33.28]],"ltp":2.8,"tv":848.57,"id":12636}]}]}
{"op":"mcm","clk":"992158609","pt":1580515139438,"mc":[{"id":"1.168133543","rc":[{"batb":[[1,2.56,4.61]],"ltp":2.8,"tv":848.57,"id":12636}]}]}
{"op":"mcm","clk":"992158664","pt":1580515141447,"mc":[{"id":"1.168133543","rc":[{"batb":[[1,2.52,2.99],[2,2.14,4.61]],"ltp":2.8,"tv":848.57,"id":12636}]}]}
{"op":"mcm","clk":"992158942","pt":1580515151939,"mc":[{"id":"1.168133543","rc":[{"batb":[[0,2.54,1.98]],"ltp":2.8,"tv":848.57,"id":12636}]}]}
{"op":"mcm","clk":"992159640","pt":1580515175514,"mc":[{"id":"1.168133543","rc":[{"batb":[[0,2.54,5.01],[2,2.12,2.52]],"ltp":2.8,"tv":848.57,"id":12636}]}]}
{"op":"mcm","clk":"992159942","pt":1580515186415,"mc":[{"id":"1.168133543","rc":[{"batb":[[0,2.54,33.91]],"ltp":2.8,"tv":848.57,"id":12636}]}]}
{"op":"mcm","clk":"992160144","pt":1580515193510,"mc":[{"id":"1.168133543","rc":[{"batb":[[1,2.12,2.52],[2,2.1,25]],"ltp":2.8,"tv":848.57,"id":12636}]}]}
{"op":"mcm","clk":"992160171","pt":1580515194535,"mc":[{"id":"1.168133543","rc":[{"batb":[[0,2.56,2.92],[1,2.54,33.91],[2,2.12,2.52]],"ltp":2.8,"tv":848.57,"id":12636}]}]}
{"op":"mcm","clk":"992160278","pt":1580515199121,"mc":[{"id":"1.168133543","rc":[{"batb":[[0,2.58,1.98],[1,2.56,2.92],[2,2.54,31.93]],"ltp":2.8,"tv":848.57,"id":12636}]}]}
{"op":"mcm","clk":"992160395","pt":1580515202444,"mc":[{"id":"1.168133543","rc":[{"batb":[[2,2.54,3.03]],"ltp":2.8,"tv":848.57,"id":12636}]}]}
{"op":"mcm","clk":"992160638","pt":1580515210127,"mc":[{"id":"1.168133543","rc":[{"batb":[[0,2.58,5.01],[2,2.12,2.52]],"ltp":2.8,"tv":848.57,"id":12636}]}]}
{"op":"mcm","clk":"992160879","pt":1580515219843,"mc":[{"id":"1.168133543","rc":[{"batb":[[0,2.58,33.46]],"ltp":2.8,"tv":848.57,"id":12636}]}]}
{"op":"mcm","clk":"992161307","pt":1580515234448,"mc":[{"id":"1.168133543","rc":[{"batb":[[0,2.58,5.01]],"ltp":2.8,"tv":848.57,"id":12636}]}]}
{"op":"mcm","clk":"992161859","pt":1580515250459,"mc":[{"id":"1.168133543","rc":[{"batb":[[0,2.58,33.46]],"ltp":2.8,"tv":848.57,"id":12636}]}]}
{"op":"mcm","clk":"992162452","pt":1580515266504,"mc":[{"id":"1.168133543","rc":[{"batb":[[0,2.58,5.01]],"ltp":2.8,"tv":848.57,"id":12636}]}]}
{"op":"mcm","clk":"992162880","pt":1580515277912,"mc":[{"id":"1.168133543","rc":[{"trd":[[1000,11.76]],"batb":[[0,1000,325.02]],"ltp":1000.0,"tv":11.76,"id":13819977}],"tv":3418.07}]}
{"op":"mcm","clk":"992163015","pt":1580515282437,"mc":[{"id":"1.168133543","rc":[{"batb":[[0,2.58,33.46]],"ltp":2.8,"tv":848.57,"id":12636}]}]}
{"op":"mcm","clk":"992163405","pt":1580515298535,"mc":[{"id":"1.168133543","rc":[{"batb":[[0,2.62,4],[1,2.58,5.01],[2,2.56,2.92]],"ltp":2.8,"tv":848.57,"id":12636}]}]}
{"op":"mcm","clk":"992163419","pt":1580515299148,"mc":[{"id":"1.168133543","rc":[{"batb":[[1,2.6,4],[2,2.58,5.01]],"ltp":2.8,"tv":848.57,"id":12636}]}]}
{"op":"mcm","clk":"992163851","pt":1580515314464,"mc":[{"id":"1.168133543","rc":[{"batb":[[0,2.64,11.41],[1,2.62,32.02],[2,2.6,4]],"ltp":2.8,"tv":848.57,"id":12636}]}]}
{"op":"mcm","clk":"992164406","pt":1580515330543,"mc":[{"id":"1.168133543","rc":[{"batb":[[0,2.66,27.59],[1,2.64,11.41],[2,2.62,4]],"ltp":2.8,"tv":848.57,"id":12636}]}]}
{"op":"mcm","clk":"992165061","pt":1580515350485,"mc":[{"id":"1.168133543","rc":[{"trd":[[11.5,35.96]],"batb":[[0,11.5,4.85]],"ltp":11.5,"tv":229.56,"id":22121325}],"tv":3428.07}]}
{"op":"mcm","clk":"992165446","pt":1580515362520,"mc":[{"id":"1.168133543","rc":[{"batb":[[0,11,2.52],[1,9.8,5.06],[2,8.4,5.13]],"ltp":11.5,"tv":229.56,"id":22121325}]}]}
{"op":"mcm","clk":"992165450","pt":1580515362623,"mc":[{"id":"1.168133543","rc":[{"batb":[[1,10,5.66],[2,9.8,4.97]],"ltp":11.5,"tv":229.56,"id":22121325}]}]}
{"op":"mcm","clk":"992165837","pt":1580515376739,"mc":[{"id":"1.168133543","rc":[{"batb":[[0,2.68,1.77],[1,2.66,27.59],[2,2.64,11.41]],"ltp":2.8,"tv":848.57,"id":12636}]}]}
{"op":"mcm","clk":"992165913","pt":1580515378742,"mc":[{"id":"1.168133543","rc":[{"batb":[[0,2.66,27.59],[1,2.64,11.41],[2,2.62,4]],"ltp":2.8,"tv":848.57,"id":12636}]}]}
{"op":"mcm","clk":"992166575","pt":1580515397572,"mc":[{"id":"1.168133543","rc":[{"batb":[[0,2.68,3.03],[1,2.66,27.59],[2,2.64,11.41]],"ltp":2.8,"tv":848.57,"id":12636}]}]}
{"op":"mcm","clk":"992166610","pt":1580515398349,"mc":[{"id":"1.168133543","rc":[{"batb":[[0,48,5.62],[1,46,1.08]],"ltp":50.0,"tv":15.25,"id":7226819},{"batl":[[1,15.5,2.32]],"ltp":11.5,"tv":229.56,"id":22121325}]}]}
{"op":"mcm","clk":"992167049","pt":1580515409689,"mc":[{"id":"1.168133543","rc":[{"batb":[[0,50,2.44],[1,48,3.08],[2,46,1.08]],"ltp":50.0,"tv":15.25,"id":7226819}]}]}
{"op":"mcm","clk":"992168038","pt":1580515442534,"mc":[{"id":"1.168133543","rc":[{"batl":[[1,16,3.35],[2,16.5,1.94]],"ltp":11.5,"tv":229.56,"id":22121325}]}]}
{"op":"mcm","clk":"992169732","pt":1580515496088,"mc":[{"id":"1.168133543","rc":[{"batb":[[0,2.68,10.49]],"ltp":2.8,"tv":848.57,"id":12636}]}]}
{"op":"mcm","clk":"992169993","pt":1580515505477,"mc":[{"id":"1.168133543","rc":[{"batb":[[0,2.7,27.19],[1,2.68,10.49]],"ltp":2.8,"tv":848.57,"id":12636}]}]}
{"op":"mcm","clk":"992170679","pt":1580515527517,"mc":[{"id":"1.168133543","rc":[{"batb":[[1,2.68,7.46]],"ltp":2.8,"tv":848.57,"id":12636}]}]}
{"op":"mcm","clk":"992170681","pt":1580515527628,"mc":[{"id":"1.168133543","rc":[{"batb":[[0,2.72,3.03],[1,2.7,27.19],[2,2.68,7.46]],"ltp":2.8,"tv":848.57,"id":12636}]}]}
{"op":"mcm","clk":"992170761","pt":1580515530134,"mc":[{"id":"1.168133543","rc":[{"batl":[[0,2.86,5.22]],"ltp":2.8,"tv":848.57,"id":12636}]}]}
{"op":"mcm","clk":"992170956","pt":1580515537353,"mc":[{"id":"1.168133543","rc":[{"batl":[[1,2.42,5.5],[2,2.48,50]],"ltp":2.38,"tv":2073.83,"id":10107355}]}]}
{"op":"mcm","clk":"992171338","pt":1580515550856,"mc":[{"id":"1.168133543","rc":[{"batb":[[2,2.58,1.98]],"ltp":2.8,"tv":848.57,"id":12636},{"batl":[[0,14.5,2],[1,15,2.86],[2,16,3.35]],"ltp":11.5,"tv":229.56,"id":22121325}]}]}
{"op":"mcm","clk":"992171532","pt":1580515559475,"mc":[{"id":"1.168133543","rc":[{"batl":[[0,14,1.98],[1,14.5,2]],"ltp":11.5,"tv":229.56,"id":22121325}]}]}
{"op":"mcm","clk":"992171626","pt":1580515562470,"mc":[{"id":"1.168133543","rc":[{"batl":[[0,14,5.01],[2,16.5,2.26]],"ltp":11.5,"tv":229.56,"id":22121325}]}]}
{"op":"mcm","clk":"992172674","pt":1580515595700,"mc":[{"id":"1.168133543","rc":[{"batl":[[0,14,1.98]],"ltp":11.5,"tv":229.56,"id":22121325}]}]}
{"op":"mcm","clk":"992172916","pt":1580515605343,"mc":[{"id":"1.168133543","rc":[{"batl":[[1,16,2.32],[2,16.5,1.94]],"ltp":11.5,"tv":229.56,"id":22121325}]}]}
{"op":"mcm","clk":"992173610","pt":1580515623432,"mc":[{"id":"1.168133543","rc":[{"batl":[[0,15.5,3.08],[1,16,2]],"ltp":11.5,"tv":229.56,"id":22121325}]}]}
{"op":"mcm","clk":"992173962","pt":1580515630539,"mc":[{"id":"1.168133543","rc":[{"batl":[[0,15,3.03],[1,15.5,3.08],[2,16,2]],"ltp":11.5,"tv":229.56,"id":22121325}]}]}
{"op":"mcm","clk":"992174236","pt":1580515635561,"mc":[{"id":"1.168133543","rc":[{"batl":[[0,2.38,3.23]],"ltp":2.38,"tv":2073.83,"id":10107355}]}]}
{"op":"mcm","clk":"992174705","pt":1580515644359,"mc":[{"id":"1.168133543","rc":[{"batl":[[1,16,2.32],[2,16.5,1.94]],"ltp":11.5,"tv":229.56,"id":22121325}]}]}
{"op":"mcm","clk":"992174734","pt":1580515644679,"mc":[{"id":"1.168133543","rc":[{"batl":[[0,14.5,1.92],[1,15,3.03],[2,16,2.32]],"ltp":11.5,"tv":229.56,"id":22121325}]}]}
{"op":"mcm","clk":"992185018","pt":1580515658888,"mc":[{"id":"1.168133543","rc":[{"batl":[[0,14,2],[1,14.5,1.92],[2,15,3.03]],"ltp":11.5,"tv":229.56,"id":22121325}]}]}
{"op":"mcm","clk":"992185171","pt":1580515663516,"mc":[{"id":"1.168133543","rc":[{"batl":[[0,14,5.03],[2,16.5,2.26]],"ltp":11.5,"tv":229.56,"id":22121325}]}]}
{"op":"mcm","clk":"992185228","pt":1580515665516,"mc":[{"id":"1.168133543","rc":[{"batl":[[0,13.5,2.06],[1,14,5.03]],"ltp":11.5,"tv":229.56,"id":22121325}]}]}
{"op":"mcm","clk":"992186825","pt":1580515711460,"mc":[{"id":"1.168133543","rc":[{"batl":[[1,14,3.03]],"ltp":11.5,"tv":229.56,"id":22121325}]}]}
{"op":"mcm","clk":"992186841","pt":1580515711768,"mc":[{"id":"1.168133543","rc":[{"batl":[[0,13,2],[1,13.5,2.06],[2,14,3.03]],"ltp":11.5,"tv":229.56,"id":22121325}]}]}
{"op":"mcm","clk":"992187188","pt":1580515728157,"mc":[{"id":"1.168133543","rc":[{"batl":[[0,12.5,2.22],[1,13,2]],"ltp":11.5,"tv":229.56,"id":22121325}]}]}
{"op":"mcm","clk":"992187272","pt":1580515731774,"mc":[{"id":"1.168133543","rc":[{"batl":[[0,12.5,5.25],[2,16.5,2.26]],"ltp":11.5,"tv":229.56,"id":22121325}]}]}
{"op":"mcm","clk":"992187926","pt":1580515764460,"mc":[{"id":"1.168133543","rc":[{"batl":[[1,16.5,2.26],[2,65,9]],"ltp":11.5,"tv":229.56,"id":22121325}]}]}
{"op":"mcm","clk":"992188006","pt":1580515766937,"mc":[{"id":"1.168133543","rc":[{"batl":[[0,12.5,2.22],[2,60,3.03]],"ltp":11.5,"tv":229.56,"id":22121325}]}]}
{"op":"mcm","clk":"992188060","pt":1580515770242,"mc":[{"id":"1.168133543","rc":[{"batl":[[0,16.5,2.26],[1,60,3.03],[2,65,9]],"ltp":11.5,"tv":229.56,"id":22121325}]}]}
{"op":"mcm","clk":"992188070","pt":1580515770654,"mc":[{"id":"1.168133543","rc":[{"batl":[[0,16,2.05],[1,16.5,1.94],[2,60,3.03]],"ltp":11.5,"tv":229.56,"id":22121325}]}]}
{"op":"mcm","clk":"992188333","pt":1580515785474,"mc":[{"id":"1.168133543","rc":[{"trd":[[2.36,123.02]],"batb":[[0,2.34,17.73],[1,2.32,2.52],[2,2.24,20]],"batl":[[0,2.36,59.64],[1,2.38,3.23],[2,2.42,5.5]],"ltp":2.36,"tv":2094.55,"id":10107355}],"tv":3448.79}]}
{"op":"mcm","clk":"992188350","pt":1580515786394,"mc":[{"id":"1.168133543","rc":[{"batb":[[0,2.72,9.36]],"ltp":2.8,"tv":848.57,"id":12636},{"batb":[[0,9.2,1.87],[1,9,5.9],[2,8.8,4.18]],"ltp":9.0,"tv":205.41,"id":10163711},{"batb":[[1,10.5,1.64],[2,10,5.66]],"ltp":11.5,"tv":229.56,"id":22121325}]}]}
{"op":"mcm","clk":"992188466","pt":1580515791494,"mc":[{"id":"1.168133543","rc":[{"batb":[[1,2.58,1.98],[2,2.56,2.92]],"ltp":2.8,"tv":848.57,"id":12636},{"batb":[[2,9.8,5.06]],"ltp":11.5,"tv":229.56,"id":22121325}]}]}
{"op":"mcm","clk":"992188478","pt":1580515792065,"mc":[{"id":"1.168133543","rc":[{"batb":[[1,10.5,6.95]],"ltp":11.5,"tv":229.56,"id":22121325}]}]}
{"op":"mcm","clk":"992188739","pt":1580515803484,"mc":[{"id":"1.168133543","rc":[{"batl":[[0,16,15.08],[2,65,9]],"ltp":11.5,"tv":229.56,"id":22121325}]}]}
{"op":"mcm","clk":"992191715","pt":1580515906823,"mc":[{"id":"1.168133543","rc":[{"batb":[[0,80,3.04]],"ltp":85.0,"tv":5.36,"id":26548208}]}]}
{"op":"mcm","clk":"992191916","pt":1580515919525,"mc":[{"id":"1.168133543","rc":[{"batb":[[0,85,1.16],[1,80,1.88],[2,70,1.1]],"ltp":85.0,"tv":5.36,"id":26548208}]}]}
{"op":"mcm","clk":"992192048","pt":1580515923858,"mc":[{"id":"1.168133543","rc":[{"batb":[[0,55,4.23]],"ltp":80.0,"tv":11.61,"id":22308007}]}]}
{"op":"mcm","clk":"992192617","pt":1580515949193,"mc":[{"id":"1.168133543","rc":[{"trd":[[2.34,160.87]],"batb":[[0,2.34,10.29]],"ltp":2.34,"tv":2109.43,"id":10107355}],"tv":3463.67}]}
{"op":"mcm","clk":"992192752","pt":1580515954298,"mc":[{"id":"1.168133543","rc":[{"trd":[[2.34,170.87]],"batb":[[0,2.34,5.28]],"ltp":2.34,"tv":2119.43,"id":10107355}],"tv":3473.67}]}
{"op":"mcm","clk":"992193307","pt":1580515978111,"mc":[{"id":"1.168133543","rc":[{"batl":[[0,15.5,2.32],[1,16,14.76],[2,16.5,1.94]],"ltp":11.5,"tv":229.56,"id":22121325}]}]}
{"op":"mcm","clk":"992193897","pt":1580515999415,"mc":[{"id":"1.168133543","rc":[{"batl":[[1,16,13.03]],"ltp":11.5,"tv":229.56,"id":22121325}]}]}
{"op":"mcm","clk":"992193907","pt":1580515999776,"mc":[{"id":"1.168133543","rc":[{"batl":[[0,15,2.86],[1,15.5,2.32],[2,16,13.03]],"ltp":11.5,"tv":229.56,"id":22121325}]}]}
{"op":"mcm","clk":"992194125","pt":1580516007512,"mc":[{"id":"1.168133543","rc":[{"batl":[[0,15,5.89],[2,16,10]],"ltp":11.5,"tv":229.56,"id":22121325}]}]}
{"op":"mcm","clk":"992194759","pt":1580516031530,"mc":[{"id":"1.168133543","rc":[{"batl":[[0,14.5,2],[1,15,5.89],[2,16,10.32]],"ltp":11.5,"tv":229.56,"id":22121325}]}]}
{"op":"mcm","clk":"992194995","pt":1580516042439,"mc":[{"id":"1.168133543","rc":[{"batl":[[0,14,1.98],[1,14.5,2],[2,15,3.03]],"ltp":11.5,"tv":229.56,"id":22121325}]}]}
{"op":"mcm","clk":"992195460","pt":1580516071287,"mc":[{"id":"1.168133543","rc":[{"batl":[[0,14,5.01],[2,16,10.32]],"ltp":11.5,"tv":229.56,"id":22121325}]}]}
{"op":"mcm","clk":"992195658","pt":1580516085200,"mc":[{"id":"1.168133543","rc":[{"batl":[[1,16,10.32],[2,16.5,1.94]],"ltp":11.5,"tv":229.56,"id":22121325}]}]}
{"op":"mcm","clk":"992196005","pt":1580516103440,"mc":[{"id":"1.168133543","rc":[{"batl":[[0,14,1.98],[1,15.5,3.35],[2,16,10]],"ltp":11.5,"tv":229.56,"id":22121325}]}]}
{"op":"mcm","clk":"992196408","pt":1580516122338,"mc":[{"id":"1.168133543","rc":[{"batl":[[0,15.5,3.35],[1,16,10],[2,16.5,1.94]],"ltp":11.5,"tv":229.56,"id":22121325}]}]}
{"op":"mcm","clk":"992196416","pt":1580516122646,"mc":[{"id":"1.168133543","rc":[{"batl":[[0,15,2.86],[1,15.5,3.35],[2,16,10]],"ltp":11.5,"tv":229.56,"id":22121325}]}]}
{"op":"mcm","clk":"992200813","pt":1580516299514,"mc":[{"id":"1.168133543","rc":[{"batl":[[0,14.5,2],[1,15,2.86],[2,15.5,3.35]],"ltp":11.5,"tv":229.56,"id":22121325}]}]}
{"op":"mcm","clk":"992200875","pt":1580516302302,"mc":[{"id":"1.168133543","rc":[{"batl":[[1,15.5,3.35],[2,16,10]],"ltp":11.5,"tv":229.56,"id":22121325}]}]}
{"op":"mcm","clk":"992200883","pt":1580516302611,"mc":[{"id":"1.168133543","rc":[{"batl":[[0,14,1.98],[1,14.5,2],[2,15.5,3.35]],"ltp":11.5,"tv":229.56,"id":22121325}]}]}
{"op":"mcm","clk":"992201151","pt":1580516315445,"mc":[{"id":"1.168133543","rc":[{"batl":[[0,14,5.01],[2,16,10.32]],"ltp":11.5,"tv":229.56,"id":22121325}]}]}
{"op":"mcm","clk":"992201914","pt":1580516352980,"mc":[{"id":"1.168133543","rc":[{"batl":[[1,15.5,2.32],[2,16,10]],"ltp":11.5,"tv":229.56,"id":22121325}]}]}
{"op":"mcm","clk":"992202038","pt":1580516357379,"mc":[{"id":"1.168133543","rc":[{"batl":[[0,14,1.98],[1,15.5,5.35]],"ltp":11.5,"tv":229.56,"id":22121325}]}]}
{"op":"mcm","clk":"992202063","pt":1580516358360,"mc":[{"id":"1.168133543","rc":[{"trd":[[50,5.52]],"batb":[[0,48,3.52],[1,46,1.08],[2,44,3.19]],"ltp":50.0,"tv":19.25,"id":7226819}],"tv":3477.67}]}
{"op":"mcm","clk":"992202161","pt":1580516362994,"mc":[{"id":"1.168133543","rc":[{"batl":[[0,15,2.86]],"ltp":11.5,"tv":229.56,"id":22121325}]}]}
{"op":"mcm","clk":"992202231","pt":1580516365492,"mc":[{"id":"1.168133543","rc":[{"batb":[[0,50,2.97],[1,48,3.08],[2,46,1.08]],"ltp":50.0,"tv":19.25,"id":7226819},{"batb":[[1,10.5,19.01]],"ltp":11.5,"tv":229.56,"id":22121325}]}]}
{"op":"mcm","clk":"992202235","pt":1580516365584,"mc":[{"id":"1.168133543","rc":[{"batb":[[0,85,2.48]],"ltp":85.0,"tv":5.36,"id":26548208},{"batb":[[1,120,2.47]],"ltp":580.0,"tv":6.13,"id":27606066},{"batb":[[0,180,2.66]],"ltp":280.0,"tv":1.54,"id":24270700},{"batb":[[1,110,2.22]],"ltp":160.0,"tv":19.01,"id":13306150}]}]}
{"op":"mcm","clk":"992202328","pt":1580516369573,"mc":[{"id":"1.168133543","rc":[{"batb":[[0,50,3.07]],"ltp":50.0,"tv":19.25,"id":7226819},{"batb":[[2,90,1.87]],"ltp":160.0,"tv":19.01,"id":13306150}]}]}
{"op":"mcm","clk":"992202499","pt":1580516380538,"mc":[{"id":"1.168133543","rc":[{"batb":[[1,110,1.21],[2,100,16.8]],"ltp":580.0,"tv":6.13,"id":27606066},{"batb":[[0,180,1.26]],"ltp":280.0,"tv":1.54,"id":24270700},{"batb":[[1,100,1.16],[2,90,1.36]],"ltp":160.0,"tv":19.01,"id":13306150}]}]}
{"op":"mcm","clk":"992202500","pt":1580516380642,"mc":[{"id":"1.168133543","rc":[{"batb":[[0,130,2.98]],"ltp":580.0,"tv":6.13,"id":27606066},{"batb":[[0,190,2.31],[1,170,3.49]],"ltp":280.0,"tv":1.54,"id":24270700},{"batb":[[1,120,1.63],[2,95,1.26]],"ltp":160.0,"tv":19.01,"id":13306150}]}]}
{"op":"mcm","clk":"992202557","pt":1580516383322,"mc":[{"id":"1.168133543","rc":[{"batb":[[1,100,17.67],[2,44,1]],"ltp":580.0,"tv":6.13,"id":27606066}]}]}
{"op":"mcm","clk":"992202778","pt":1580516396533,"mc":[{"id":"1.168133543","rc":[{"batb":[[1,100,1.16],[2,90,1.36]],"ltp":160.0,"tv":19.01,"id":13306150}]}]}
{"op":"mcm","clk":"992202779","pt":1580516396634,"mc":[{"id":"1.168133543","rc":[{"batb":[[1,130,1.33],[2,100,1.16]],"ltp":160.0,"tv":19.01,"id":13306150}]}]}
{"op":"mcm","clk":"992202846","pt":1580516402473,"mc":[{"id":"1.168133543","rc":[{"batb":[[0,2.74,2.52],[1,2.72,9.36],[2,2.58,1.98]],"ltp":2.8,"tv":848.57,"id":12636},{"batb":[[1,16,3.03],[2,7.2,2.39]],"ltp":80.0,"tv":11.61,"id":22308007},{"batb":[[0,50,3.87]],"ltp":50.0,"tv":19.25,"id":7226819},{"batb":[[1,2.24,20],[2,2.22,6]],"ltp":2.34,"tv":2119.43,"id":10107355},{"batb":[[0,10.5,19.01],[1,9.8,5.06],[2,8.4,5.13]],"ltp":11.5,"tv":229.56,"id":22121325},{"batb":[[2,70,1.66]],"ltp":85.0,"tv":5.36,"id":26548208},{"batb":[[2,120,1.81]],"ltp":280.0,"tv":1.54,"id":24270700}]}]}
{"op":"mcm","clk":"992202920","pt":1580516407163,"mc":[{"id":"1.168133543","rc":[{"batl":[[0,14.5,2],[1,15,2.86],[2,15.5,3.35]],"ltp":11.5,"tv":229.56,"id":22121325}]}]}
{"op":"mcm","clk":"992202992","pt":1580516412490,"mc":[{"id":"1.168133543","rc":[{"batb":[[0,10.5,1.64]],"ltp":11.5,"tv":229.56,"id":22121325}]}]}
{"op":"mcm","clk":"992202996","pt":1580516412751,"mc":[{"id":"1.168133543","rc":[{"batb":[[1,10,18.33],[2,9.8,4.97]],"ltp":11.5,"tv":229.56,"id":22121325}]}]}
{"op":"mcm","clk":"992203163","pt":1580516422565,"mc":[{"id":"1.168133543","rc":[{"batl":[[0,14.5,5.03],[2,16,10.32]],"ltp":11.5,"tv":229.56,"id":22121325}]}]}
{"op":"mcm","clk":"992203212","pt":1580516425464,"mc":[{"id":"1.168133543","rc":[{"batl":[[0,14,1.98],[1,14.5,5.03]],"ltp":11.5,"tv":229.56,"id":22121325}]}]}
{"op":"mcm","clk":"992203516","pt":1580516437488,"mc":[{"id":"1.168133543","rc":[{"batb":[[2,2.22,14.65]],"ltp":2.34,"tv":2119.43,"id":10107355}]}]}
{"op":"mcm","clk":"992203581","pt":1580516440722,"mc":[{"id":"1.168133543","rc":[{"batb":[[2,2.22,6]],"ltp":2.34,"tv":2119.43,"id":10107355}]}]}
{"op":"mcm","clk":"992204123","pt":1580516460458,"mc":[{"id":"1.168133543","rc":[{"batl":[[0,13.5,2],[1,14,1.98],[2,14.5,3.03]],"ltp":11.5,"tv":229.56,"id":22121325}]}]}
{"op":"mcm","clk":"992204253","pt":1580516465341,"mc":[{"id":"1.168133543","rc":[{"batl":[[1,14.5,3.03],[2,16,10.32]],"ltp":11.5,"tv":229.56,"id":22121325}]}]}
{"op":"mcm","clk":"992204265","pt":1580516465752,"mc":[{"id":"1.168133543","rc":[{"batl":[[0,13,2.13],[1,13.5,2],[2,14.5,3.03]],"ltp":11.5,"tv":229.56,"id":22121325}]}]}
{"op":"mcm","clk":"992204510","pt":1580516477039,"mc":[{"id":"1.168133543","rc":[{"trd":[[8.2,37.92],[8.4,12.18],[8.8,8.36],[9,43.58],[9.2,39.48]],"batb":[[0,8.2,94.45],[1,8,11.76],[2,7.8,9.01]],"ltp":8.2,"tv":255.42,"id":10163711}],"tv":3527.68}]}
{"op":"mcm","clk":"992204675","pt":1580516483569,"mc":[{"id":"1.168133543","rc":[{"batb":[[1,8,8.76]],"batl":[[0,9.8,3.26]],"ltp":8.2,"tv":255.42,"id":10163711}]}]}
{"op":"mcm","clk":"992204753","pt":1580516486049,"mc":[{"id":"1.168133543","rc":[{"batb":[[0,8.4,2.38],[1,8.2,94.45],[2,8,8.76]],"ltp":8.2,"tv":255.42,"id":10163711}]}]}
{"op":"mcm","clk":"992204797","pt":1580516488178,"mc":[{"id":"1.168133543","rc":[{"batl":[[0,13,5.16],[2,16,10.32]],"ltp":11.5,"tv":229.56,"id":22121325}]}]}
{"op":"mcm","clk":"992205149","pt":1580516506573,"mc":[{"id":"1.168133543","rc":[{"batb":[[2,8,6.25]],"ltp":8.2,"tv":255.42,"id":10163711}]}]}
{"op":"mcm","clk":"992205314","pt":1580516513714,"mc":[{"id":"1.168133543","rc":[{"batl":[[1,16,10.32],[2,16.5,1.94]],"ltp":11.5,"tv":229.56,"id":22121325}]}]}
{"op":"mcm","clk":"992205378","pt":1580516517425,"mc":[{"id":"1.168133543","rc":[{"batb":[[2,2.22,14.68]],"ltp":2.34,"tv":2119.43,"id":10107355}]}]}
{"op":"mcm","clk":"992205457","pt":1580516521512,"mc":[{"id":"1.168133543","rc":[{"batb":[[2,2.22,6]],"ltp":2.34,"tv":2119.43,"id":10107355},{"batl":[[0,13,2.13],[1,15.5,3.35],[2,16,10]],"ltp":11.5,"tv":229.56,"id":22121325}]}]}
{"op":"mcm","clk":"992205576","pt":1580516526896,"mc":[{"id":"1.168133543","rc":[{"batl":[[0,15,2.86]],"ltp":11.5,"tv":229.56,"id":22121325}]}]}
{"op":"mcm","clk":"992216293","pt":1580516563562,"mc":[{"id":"1.168133543","rc":[{"trd":[[2.24,251.05],[2.34,181.43]],"batb":[[0,2.24,5.28],[1,2.22,18.4],[2,2.2,104]],"ltp":2.24,"tv":2159.44,"id":10107355}],"tv":3567.68}]}
{"op":"mcm","clk":"992216459","pt":1580516570352,"mc":[{"id":"1.168133543","rc":[{"batb":[[0,8.4,17.46]],"ltp":8.2,"tv":255.42,"id":10163711},{"batb":[[0,2.24,61.81]],"ltp":2.24,"tv":2159.44,"id":10107355}]}]}
{"op":"mcm","clk":"992217667","pt":1580516619998,"mc":[{"id":"1.168133543","rc":[{"batl":[[0,9.6,2.13],[1,9.8,3.12],[2,10,66]],"ltp":8.2,"tv":255.42,"id":10163711},{"batl":[[0,14.5,2],[1,15,2.86],[2,15.5,3.35]],"ltp":11.5,"tv":229.56,"id":22121325}]}]}
{"op":"mcm","clk":"992217829","pt":1580516624185,"mc":[{"id":"1.168133543","rc":[{"batl":[[0,14.5,5.03],[2,16,10.32]],"ltp":11.5,"tv":229.56,"id":22121325}]}]}
{"op":"mcm","clk":"992217906","pt":1580516627488,"mc":[{"id":"1.168133543","rc":[{"batl":[[0,14,1.98],[1,14.5,5.03]],"ltp":11.5,"tv":229.56,"id":22121325}]}]}
{"op":"mcm","clk":"992219172","pt":1580516673446,"mc":[{"id":"1.168133543","rc":[{"batl":[[0,13.5,2],[1,14,1.98],[2,14.5,3.03]],"ltp":11.5,"tv":229.56,"id":22121325}]}]}
{"op":"mcm","clk":"992219564","pt":1580516688474,"mc":[{"id":"1.168133543","rc":[{"batl":[[0,13.5,5.03],[1,16,10.32],[2,16.5,1.94]],"ltp":11.5,"tv":229.56,"id":22121325}]}]}
{"op":"mcm","clk":"992219589","pt":1580516689452,"mc":[{"id":"1.168133543","rc":[{"batl":[[0,13,2.13],[1,13.5,5.03],[2,16,10.32]],"ltp":11.5,"tv":229.56,"id":22121325}]}]}
{"op":"mcm","clk":"992220545","pt":1580516726505,"mc":[{"id":"1.168133543","rc":[{"batl":[[1,13.5,3.03]],"ltp":11.5,"tv":229.56,"id":22121325}]}]}
{"op":"mcm","clk":"992220554","pt":1580516726713,"mc":[{"id":"1.168133543","rc":[{"batl":[[0,12.5,2],[1,13,2.13],[2,13.5,3.03]],"ltp":11.5,"tv":229.56,"id":22121325}]}]}
{"op":"mcm","clk":"992220603","pt":1580516729353,"mc":[{"id":"1.168133543","rc":[{"batl":[[0,12,2.31],[1,12.5,2]],"ltp":11.5,"tv":229.56,"id":22121325}]}]}
{"op":"mcm","clk":"992220639","pt":1580516731509,"mc":[{"id":"1.168133543","rc":[{"batb":[[0,2.26,16.83],[1,2.24,61.81],[2,2.22,18.4]],"ltp":2.24,"tv":2159.44,"id":10107355}]}]}
{"op":"mcm","clk":"992220647","pt":1580516732025,"mc":[{"id":"1.168133543","rc":[{"batb":[[0,2.76,13.78],[1,2.74,2.52],[2,2.72,9.36]],"ltp":2.8,"tv":848.57,"id":12636},{"batb":[[0,60,1.68],[1,55,3.87],[2,16,3.03]],"ltp":80.0,"tv":11.61,"id":22308007},{"batb":[[0,55,1.45],[1,50,3.87],[2,48,3.08]],"ltp":50.0,"tv":19.25,"id":7226819},{"batb":[[0,8.6,4.42],[1,8.4,17.46],[2,8.2,94.45]],"ltp":8.2,"tv":255.42,"id":10163711},{"batb":[[0,10.5,5.26]],"ltp":11.5,"tv":229.56,"id":22121325}]}]}
{"op":"mcm","clk":"992220911","pt":1580516741019,"mc":[{"id":"1.168133543","rc":[{"batb":[[0,8.8,2.27],[1,8.6,4.42],[2,8.4,15.08]],"ltp":8.2,"tv":255.42,"id":10163711}]}]}
{"op":"mcm","clk":"992221205","pt":1580516747568,"mc":[{"id":"1.168133543","rc":[{"batb":[[0,2.78,26.4],[1,2.76,13.78],[2,2.74,2.52]],"ltp":2.8,"tv":848.57,"id":12636},{"batb":[[2,8.2,94.45]],"ltp":8.2,"tv":255.42,"id":10163711},{"batb":[[1,2.24,5.28]],"ltp":2.24,"tv":2159.44,"id":10107355},{"batb":[[0,11,5.07],[1,10.5,5.26],[2,9.8,5.06]],"ltp":11.5,"tv":229.56,"id":22121325}]}]}
{"op":"mcm","clk":"992221301","pt":1580516751442,"mc":[{"id":"1.168133543","rc":[{"batb":[[1,55,3.09]],"ltp":80.0,"tv":11.61,"id":22308007}]}]}
{"op":"mcm","clk":"992221350","pt":1580516753666,"mc":[{"id":"1.168133543","rc":[{"batb":[[2,8.4,6]],"ltp":8.2,"tv":255.42,"id":10163711}]}]}
{"op":"mcm","clk":"992221552","pt":1580516762570,"mc":[{"id":"1.168133543","rc":[{"batb":[[2,2.72,9.36]],"ltp":2.8,"tv":848.57,"id":12636}]}]}
{"op":"mcm","clk":"992221567","pt":1580516763192,"mc":[{"id":"1.168133543","rc":[{"batb":[[0,2.8,2.52],[1,2.78,26.4],[2,2.76,13.78]],"ltp":2.8,"tv":848.57,"id":12636},{"batb":[[2,16,3.37]],"ltp":80.0,"tv":11.61,"id":22308007},{"batb":[[0,8.8,4.23]],"ltp":8.2,"tv":255.42,"id":10163711},{"batb":[[0,11,6.17]],"ltp":11.5,"tv":229.56,"id":22121325}]}]}
{"op":"mcm","clk":"992221599","pt":1580516764279,"mc":[{"id":"1.168133543","rc":[{"batb":[[0,8.8,1.96]],"ltp":8.2,"tv":255.42,"id":10163711}]}]}
{"op":"mcm","clk":"992221947","pt":1580516780821,"mc":[{"id":"1.168133543","rc":[{"batl":[[1,13.5,3.03],[2,16,10.32]],"ltp":11.5,"tv":229.56,"id":22121325}]}]}
{"op":"mcm","clk":"992222062","pt":1580516785788,"mc":[{"id":"1.168133543","rc":[{"batl":[[1,15.5,3.35],[2,16,10]],"ltp":11.5,"tv":229.56,"id":22121325}]}]}
{"op":"mcm","clk":"992222202","pt":1580516792109,"mc":[{"id":"1.168133543","rc":[{"batl":[[0,15,2.86]],"ltp":11.5,"tv":229.56,"id":22121325}]}]}
{"op":"mcm","clk":"992222246","pt":1580516794533,"mc":[{"id":"1.168133543","rc":[{"batb":[[1,2.76,13.78],[2,2.72,9.36]],"ltp":2.8,"tv":848.57,"id":12636},{"batb":[[0,11,17.69]],"ltp":11.5,"tv":229.56,"id":22121325}]}]}
{"op":"mcm","clk":"992222855","pt":1580516822446,"mc":[{"id":"1.168133543","rc":[{"batb":[[0,2.78,2.52]],"ltp":2.8,"tv":848.57,"id":12636}]}]}
{"op":"mcm","clk":"992224399","pt":1580516884355,"mc":[{"id":"1.168133543","rc":[{"batb":[[0,11.5,1.5],[1,11,17.69],[2,10.5,3.62]],"ltp":11.5,"tv":229.56,"id":22121325}]}]}
{"op":"mcm","clk":"992224497","pt":1580516888543,"mc":[{"id":"1.168133543","rc":[{"batl":[[0,14.5,2],[1,15,2.86],[2,15.5,3.35]],"ltp":11.5,"tv":229.56,"id":22121325}]}]}
{"op":"mcm","clk":"992224664","pt":1580516894467,"mc":[{"id":"1.168133543","rc":[{"batl":[[2,16,10.32]],"ltp":11.5,"tv":229.56,"id":22121325}]}]}
{"op":"mcm","clk":"992224690","pt":1580516895445,"mc":[{"id":"1.168133543","rc":[{"batl":[[0,14.5,5.03],[1,16,10.32],[2,16.5,1.94]],"ltp":11.5,"tv":229.56,"id":22121325}]}]}
{"op":"mcm","clk":"992224712","pt":1580516896319,"mc":[{"id":"1.168133543","rc":[{"batl":[[0,14,1.98],[1,14.5,5.03],[2,16,10.32]],"ltp":11.5,"tv":229.56,"id":22121325}]}]}
{"op":"mcm","clk":"992225794","pt":1580516943019,"mc":[{"id":"1.168133543","rc":[{"batl":[[0,13.5,2],[1,14,1.98],[2,14.5,3.03]],"ltp":11.5,"tv":229.56,"id":22121325}]}]}
{"op":"mcm","clk":"992225826","pt":1580516944515,"mc":[{"id":"1.168133543","rc":[{"batb":[[0,2.78,8.71],[2,2.72,3.03]],"ltp":2.8,"tv":848.57,"id":12636}]}]}
{"op":"mcm","clk":"992226043","pt":1580516954533,"mc":[{"id":"1.168133543","rc":[{"batb":[[0,2.8,10.91],[1,2.78,80.67],[2,2.76,13.78]],"ltp":2.8,"tv":848.57,"id":12636},{"batb":[[0,8.8,16.35]],"ltp":8.2,"tv":255.42,"id":10163711},{"batb":[[0,2.28,55.54],[1,2.26,16.83],[2,2.24,5.28]],"ltp":2.24,"tv":2159.44,"id":10107355}]}]}
{"op":"mcm","clk":"992226102","pt":1580516957138,"mc":[{"id":"1.168133543","rc":[{"batl":[[0,13,2.13],[1,13.5,2]],"ltp":11.5,"tv":229.56,"id":22121325}]}]}
{"op":"mcm","clk":"992226150","pt":1580516959150,"mc":[{"id":"1.168133543","rc":[{"batl":[[0,2.88,4.02],[1,2.9,52.51],[2,2.92,50]],"ltp":2.8,"tv":848.57,"id":12636},{"batl":[[0,13,5.16],[2,16,10.32]],"ltp":11.5,"tv":229.56,"id":22121325}]}]}
{"op":"mcm","clk":"992226369","pt":1580516967170,"mc":[{"id":"1.168133543","rc":[{"batl":[[0,9.6,6.13]],"ltp":8.2,"tv":255.42,"id":10163711}]}]}
{"op":"mcm","clk":"992226429","pt":1580516969550,"mc":[{"id":"1.168133543","rc":[{"batb":[[0,2.82,70.94],[1,2.8,10.91],[2,2.78,8.71]],"ltp":2.8,"tv":848.57,"id":12636}]}]}
{"op":"mcm","clk":"992226442","pt":1580516969961,"mc":[{"id":"1.168133543","rc":[{"trd":[[2.88,65.62]],"batb":[[0,2.88,2.03],[1,2.82,70.94]],"batl":[[0,2.9,52.51],[1,2.92,50],[2,2.94,58.02]],"ltp":2.88,"tv":856.6,"id":12636}],"tv":3575.72}]}
{"op":"mcm","clk":"992226909","pt":1580516985479,"mc":[{"id":"1.168133543","rc":[{"batb":[[1,2.78,8.71],[2,2.76,13.78]],"ltp":2.88,"tv":856.6,"id":12636}]}]}
{"op":"mcm","clk":"992226912","pt":1580516985583,"mc":[{"id":"1.168133543","rc":[{"batb":[[1,2.8,71.44],[2,2.78,8.71]],"ltp":2.88,"tv":856.6,"id":12636}]}]}
{"op":"mcm","clk":"992227112","pt":1580516992308,"mc":[{"id":"1.168133543","rc":[{"trd":[[2.88,69.69]],"batb":[[0,2.8,71.44],[1,2.78,8.71],[2,2.76,29.88]],"batl":[[0,2.88,13.4],[1,2.9,52.51],[2,2.92,50]],"ltp":2.88,"tv":860.67,"id":12636},{"batl":[[0,13,2.13],[2,15.5,3.35]],"ltp":11.5,"tv":229.56,"id":22121325}],"tv":3579.79}]}
{"op":"mcm","clk":"992227246","pt":1580516997427,"mc":[{"id":"1.168133543","rc":[{"trd":[[9.6,4.03]],"batl":[[0,9.6,2.12]],"ltp":9.6,"tv":259.45,"id":10163711},{"batl":[[1,15,2]],"ltp":11.5,"tv":229.56,"id":22121325}],"tv":3583.82}]}
{"op":"mcm","clk":"992227308","pt":1580516999502,"mc":[{"id":"1.168133543","rc":[{"batl":[[0,14.5,2.96]],"ltp":11.5,"tv":229.56,"id":22121325}]}]}
{"op":"mcm","clk":"992227382","pt":1580517001427,"mc":[{"id":"1.168133543","rc":[{"batb":[[0,2.78,8.71],[1,2.76,29.88],[2,2.58,1.98]],"ltp":2.88,"tv":860.67,"id":12636},{"batb":[[0,8.8,1.96]],"ltp":9.6,"tv":259.45,"id":10163711},{"batb":[[0,2.26,16.83],[1,2.24,5.28],[2,2.22,18.4]],"ltp":2.24,"tv":2159.44,"id":10107355}]}]}
{"op":"mcm","clk":"992227403","pt":1580517001839,"mc":[{"id":"1.168133543","rc":[{"trd":[[9.6,8.27]],"batl":[[0,9.8,3.12],[1,10,66],[2,17,1.88]],"ltp":9.6,"tv":263.69,"id":10163711}],"tv":3588.06}]}
{"op":"mcm","clk":"992227518","pt":1580517004642,"mc":[{"id":"1.168133543","rc":[{"batb":[[2,8.4,6.14]],"ltp":9.6,"tv":263.69,"id":10163711}]}]}
{"op":"mcm","clk":"992227702","pt":1580517010532,"mc":[{"id":"1.168133543","rc":[{"batb":[[2,8.4,9.14]],"ltp":9.6,"tv":263.69,"id":10163711}]}]}
{"op":"mcm","clk":"992228119","pt":1580517018933,"mc":[{"id":"1.168133543","rc":[{"batb":[[0,8.8,6.32]],"ltp":9.6,"tv":263.69,"id":10163711}]}]}
{"op":"mcm","clk":"992230812","pt":1580517105491,"mc":[{"id":"1.168133543","rc":[{"batl":[[0,9.6,2],[1,9.8,3.12],[2,10,66]],"ltp":9.6,"tv":263.69,"id":10163711}]}]}
{"op":"mcm","clk":"992232868","pt":1580517162954,"mc":[{"id":"1.168133543","rc":[{"batl":[[0,2.34,3.03],[1,2.36,59.64],[2,2.38,3.23]],"ltp":2.24,"tv":2159.44,"id":10107355}]}]}
{"op":"mcm","clk":"992232881","pt":1580517163675,"mc":[{"id":"1.168133543","rc":[{"batl":[[0,2.36,59.64],[1,2.38,3.23],[2,2.42,5.5]],"ltp":2.24,"tv":2159.44,"id":10107355}]}]}
{"op":"mcm","clk":"992233033","pt":1580517168997,"mc":[{"id":"1.168133543","rc":[{"batb":[[0,2.78,10.39]],"ltp":2.88,"tv":860.67,"id":12636},{"batb":[[0,1000,325.04]],"ltp":1000.0,"tv":11.76,"id":13819977},{"batb":[[1,8.6,6.47]],"ltp":9.6,"tv":263.69,"id":10163711},{"batb":[[0,2.28,1.68],[1,2.26,16.83],[2,2.24,5.28]],"ltp":2.24,"tv":2159.44,"id":10107355},{"batb":[[0,11.5,3.03]],"ltp":11.5,"tv":229.56,"id":22121325},{"batb":[[1,110,1.02],[2,100,16.8]],"ltp":580.0,"tv":6.13,"id":27606066}]}]}
{"op":"mcm","clk":"992233263","pt":1580517176498,"mc":[{"id":"1.168133543","rc":[{"batb":[[1,11,1.11]],"ltp":11.5,"tv":229.56,"id":22121325}]}]}
{"op":"mcm","clk":"992233299","pt":1580517178826,"mc":[{"id":"1.168133543","rc":[{"batb":[[0,11.5,1.5]],"ltp":11.5,"tv":229.56,"id":22121325}]}]}
{"op":"mcm","clk":"992233440","pt":1580517183291,"mc":[{"id":"1.168133543","rc":[{"trd":[[11.5,38.95]],"batb":[[0,11,1.11],[1,10.5,3.62],[2,9.8,5.06]],"batl":[[0,11.5,1.5],[1,14.5,2.96],[2,15,2]],"ltp":11.5,"tv":232.56,"id":22121325}],"tv":3591.05}]}
{"op":"mcm","clk":"992233695","pt":1580517192436,"mc":[{"id":"1.168133543","rc":[{"batb":[[0,11,17.69]],"ltp":11.5,"tv":232.56,"id":22121325}]}]}
{"op":"mcm","clk":"992233954","pt":1580517201283,"mc":[{"id":"1.168133543","rc":[{"trd":[[11.5,41.96]],"batb":[[0,11,17.72]],"batl":[[0,14.5,2.96],[1,15,2],[2,15.5,3.35]],"ltp":11.5,"tv":235.56,"id":22121325}],"tv":3594.06}]}
{"op":"mcm","clk":"992236250","pt":1580517282016,"mc":[{"id":"1.168133543","rc":[{"trd":[[11.5,42.02]],"batb":[[0,11,17.69]],"batl":[[0,11.5,3.97],[1,14.5,2.96],[2,15,2]],"ltp":11.5,"tv":235.62,"id":22121325}],"tv":3594.12}]}
{"op":"mcm","clk":"992236373","pt":1580517287388,"mc":[{"id":"1.168133543","rc":[{"trd":[[11,26.26]],"batb":[[0,11,15.17]],"batl":[[1,15,2],[2,15.5,3.35]],"ltp":11.0,"tv":240.66,"id":22121325}],"tv":3599.16}]}
{"op":"mcm","clk":"992236394","pt":1580517288422,"mc":[{"id":"1.168133543","rc":[{"batb":[[0,10.5,3.62],[1,9.8,5.06],[2,8.4,5.13]],"ltp":11.0,"tv":240.66,"id":22121325}]}]}
{"op":"mcm","clk":"992236416","pt":1580517289417,"mc":[{"id":"1.168133543","rc":[{"batb":[[0,2.8,71.44],[1,2.78,10.39],[2,2.76,29.88]],"ltp":2.88,"tv":860.67,"id":12636},{"batb":[[0,9,14.07],[1,8.8,6.32],[2,8.6,6.47]],"ltp":9.6,"tv":263.69,"id":10163711},{"batb":[[0,2.28,57.22]],"ltp":2.24,"tv":2159.44,"id":10107355}]}]}
{"op":"mcm","clk":"992236439","pt":1580517290547,"mc":[{"id":"1.168133543","rc":[{"batb":[[1,2.78,8.71]],"ltp":2.88,"tv":860.67,"id":12636},{"batb":[[2,8.6,4.42]],"ltp":9.6,"tv":263.69,"id":10163711}]}]}
{"op":"mcm","clk":"992236556","pt":1580517295506,"mc":[{"id":"1.168133543","rc":[{"batb":[[0,2.82,1.68],[1,2.8,71.44],[2,2.78,8.71]],"ltp":2.88,"tv":860.67,"id":12636},{"batb":[[0,9.2,1.92],[1,9,14.07],[2,8.8,6.32]],"ltp":9.6,"tv":263.69,"id":10163711}]}]}
{"op":"mcm","clk":"992236578","pt":1580517296548,"mc":[{"id":"1.168133543","rc":[{"batb":[[0,9.2,6.09],[2,8.8,1.96]],"ltp":9.6,"tv":263.69,"id":10163711}]}]}
{"op":"mcm","clk":"992236757","pt":1580517302543,"mc":[{"id":"1.168133543","rc":[{"batb":[[0,2.82,4.2],[2,2.78,6.19]],"ltp":2.88,"tv":860.67,"id":12636},{"batb":[[0,9.4,1.83],[1,9.2,6.09],[2,9,14.07]],"ltp":9.6,"tv":263.69,"id":10163711}]}]}
{"op":"mcm","clk":"992236811","pt":1580517304411,"mc":[{"id":"1.168133543","rc":[{"batb":[[2,8.6,4.42]],"ltp":9.6,"tv":263.69,"id":10163711}]}]}
{"op":"mcm","clk":"992236873","pt":1580517306315,"mc":[{"id":"1.168133543","rc":[{"batb":[[1,9.2,4.17]],"ltp":9.6,"tv":263.69,"id":10163711}]}]}
{"op":"mcm","clk":"992237013","pt":1580517311320,"mc":[{"id":"1.168133543","rc":[{"batb":[[2,8.6,6.47]],"ltp":9.6,"tv":263.69,"id":10163711}]}]}
{"op":"mcm","clk":"992237341","pt":1580517319565,"mc":[{"id":"1.168133543","rc":[{"batl":[[0,2.9,52.51],[1,2.92,50],[2,2.94,58.02]],"ltp":2.88,"tv":860.67,"id":12636},{"trd":[[9.8,6.36]],"batl":[[0,10,66],[1,17,1.88],[2,29,9.24]],"ltp":9.8,"tv":263.87,"id":10163711},{"batl":[[2,15.5,1.61]],"ltp":11.0,"tv":240.66,"id":22121325}],"tv":3599.34}]}
{"op":"mcm","clk":"992237374","pt":1580517320551,"mc":[{"id":"1.168133543","rc":[{"batb":[[1,9,14.07],[2,8.8,6.63]],"ltp":9.8,"tv":263.87,"id":10163711}]}]}
{"op":"mcm","clk":"992237400","pt":1580517321377,"mc":[{"id":"1.168133543","rc":[{"batb":[[1,9,14.17]],"ltp":9.8,"tv":263.87,"id":10163711}]}]}
{"op":"mcm","clk":"992237597","pt":1580517327876,"mc":[{"id":"1.168133543","rc":[{"batb":[[1,9.2,2.02],[2,9,14.07]],"ltp":9.8,"tv":263.87,"id":10163711}]}]}
{"op":"mcm","clk":"992237838","pt":1580517336502,"mc":[{"id":"1.168133543","rc":[{"batb":[[1,9.2,15.78],[2,8.8,6.63]],"ltp":9.8,"tv":263.87,"id":10163711}]}]}
{"op":"mcm","clk":"992238055","pt":1580517343011,"mc":[{"id":"1.168133543","rc":[{"batb":[[2,8.8,4.36]],"ltp":9.8,"tv":263.87,"id":10163711}]}]}
{"op":"mcm","clk":"992238835","pt":1580517371538,"mc":[{"id":"1.168133543","rc":[{"batl":[[0,11,1.82],[1,11.5,3.97],[2,15,2]],"ltp":11.0,"tv":240.66,"id":22121325}]}]}
{"op":"mcm","clk":"992238881","pt":1580517373135,"mc":[{"id":"1.168133543","rc":[{"batl":[[2,15.5,2.32]],"ltp":11.0,"tv":240.66,"id":22121325}]}]}
{"op":"mcm","clk":"992240432","pt":1580517422503,"mc":[{"id":"1.168133543","rc":[{"batb":[[0,2.84,6.07],[1,2.82,4.2],[2,2.8,71.44]],"ltp":2.88,"tv":860.67,"id":12636}]}]}
{"op":"mcm","clk":"992240544","pt":1580517427131,"mc":[{"id":"1.168133543","rc":[{"batl":[[2,16,10.32]],"ltp":11.0,"tv":240.66,"id":22121325}]}]}
{"op":"mcm","clk":"992240637","pt":1580517431519,"mc":[{"id":"1.168133543","rc":[{"batb":[[2,2.76,15.91]],"ltp":2.88,"tv":860.67,"id":12636}]}]}
{"op":"mcm","clk":"992240639","pt":1580517431618,"mc":[{"id":"1.168133543","rc":[{"batb":[[0,2.84,76.5]],"ltp":2.88,"tv":860.67,"id":12636}]}]}
{"op":"mcm","clk":"992240803","pt":1580517437347,"mc":[{"id":"1.168133543","rc":[{"batb":[[1,2.82,2.52]],"ltp":2.88,"tv":860.67,"id":12636}]}]}
{"op":"mcm","clk":"992240927","pt":1580517442137,"mc":[{"id":"1.168133543","rc":[{"batb":[[0,2.86,1.68],[1,2.84,76.5],[2,2.82,2.52]],"ltp":2.88,"tv":860.67,"id":12636}]}]}
{"op":"mcm","clk":"992241053","pt":1580517447350,"mc":[{"id":"1.168133543","rc":[{"batb":[[1,2.84,6.07]],"ltp":2.88,"tv":860.67,"id":12636}]}]}
{"op":"mcm","clk":"992241061","pt":1580517447761,"mc":[{"id":"1.168133543","rc":[{"batb":[[0,2.84,6.07],[1,2.82,2.52],[2,2.76,15.91]],"ltp":2.88,"tv":860.67,"id":12636}]}]}
{"op":"mcm","clk":"992251008","pt":1580517453445,"mc":[{"id":"1.168133543","rc":[{"batb":[[2,2.78,1.68]],"ltp":2.88,"tv":860.67,"id":12636}]}]}
{"op":"mcm","clk":"992251445","pt":1580517482507,"mc":[{"id":"1.168133543","rc":[{"batb":[[0,2.86,2.52],[1,2.84,6.07]],"ltp":2.88,"tv":860.67,"id":12636}]}]}
{"op":"mcm","clk":"992253887","pt":1580517609757,"mc":[{"id":"1.168133543","rc":[{"trd":[[10.5,16]],"batb":[[0,9.8,5.68],[1,8.4,5.13],[2,6.2,11.64]],"ltp":10.5,"tv":246.66,"id":22121325}],"tv":3605.34}]}
{"op":"mcm","clk":"992256365","pt":1580517725496,"mc":[{"id":"1.168133543","rc":[{"batb":[[0,200,1.7],[1,190,1.71],[2,170,3.49]],"ltp":280.0,"tv":1.54,"id":24270700}]}]}
{"op":"mcm","clk":"992256526","pt":1580517734522,"mc":[{"id":"1.168133543","rc":[{"batb":[[1,170,3.87],[2,120,1.81]],"ltp":280.0,"tv":1.54,"id":24270700}]}]}
{"op":"mcm","clk":"992256529","pt":1580517734626,"mc":[{"id":"1.168133543","rc":[{"batb":[[0,200,2.97]],"ltp":280.0,"tv":1.54,"id":24270700}]}]}
{"op":"mcm","clk":"992256630","pt":1580517739020,"mc":[{"id":"1.168133543","rc":[{"batb":[[1,170,3.64]],"ltp":280.0,"tv":1.54,"id":24270700}]}]}
{"op":"mcm","clk":"992256836","pt":1580517750434,"mc":[{"id":"1.168133543","rc":[{"batb":[[0,200,1.7]],"ltp":280.0,"tv":1.54,"id":24270700}]}]}
{"op":"mcm","clk":"992256844","pt":1580517750588,"mc":[{"id":"1.168133543","rc":[{"batb":[[0,210,1.56],[1,200,1.35],[2,170,3.64]],"ltp":280.0,"tv":1.54,"id":24270700}]}]}
{"op":"mcm","clk":"992257145","pt":1580517765316,"mc":[{"id":"1.168133543","rc":[{"batb":[[0,210,2.66],[1,170,3.89],[2,120,1.81]],"ltp":280.0,"tv":1.54,"id":24270700}]}]}
{"op":"mcm","clk":"992257581","pt":1580517781559,"mc":[{"id":"1.168133543","rc":[{"batb":[[0,220,1.26],[1,210,1.34],[2,170,3.89]],"ltp":280.0,"tv":1.54,"id":24270700}]}]}
{"op":"mcm","clk":"992257616","pt":1580517782854,"mc":[{"id":"1.168133543","rc":[{"batb":[[0,220,2.36],[1,170,4.13],[2,120,1.81]],"ltp":280.0,"tv":1.54,"id":24270700}]}]}
{"op":"mcm","clk":"992258022","pt":1580517799689,"mc":[{"id":"1.168133543","rc":[{"batb":[[0,230,1.1],[1,220,1.26],[2,170,4.13]],"ltp":280.0,"tv":1.54,"id":24270700}]}]}
{"op":"mcm","clk":"992260951","pt":1580517932399,"mc":[{"id":"1.168133543","rc":[{"trd":[[9.2,54.03],[9.4,17.48]],"batb":[[0,9.2,8.51],[1,8.8,4.36],[2,8.6,4.42]],"ltp":9.2,"tv":282.08,"id":10163711}],"tv":3623.55}]}
{"op":"mcm","clk":"992261037","pt":1580517937361,"mc":[{"id":"1.168133543","rc":[{"batl":[[0,10,66.09]],"ltp":9.2,"tv":282.08,"id":10163711}]}]}
{"op":"mcm","clk":"992261129","pt":1580517941704,"mc":[{"id":"1.168133543","rc":[{"batb":[[0,8.8,13.26],[1,8.6,4.42],[2,8.4,6.14]],"ltp":9.2,"tv":282.08,"id":10163711}]}]}
{"op":"mcm","clk":"992261405","pt":1580517958687,"mc":[{"id":"1.168133543","rc":[{"batl":[[0,9.8,2.09],[1,10,66],[2,17,1.88]],"ltp":9.2,"tv":282.08,"id":10163711}]}]}
{"op":"mcm","clk":"992261534","pt":1580517962536,"mc":[{"id":"1.168133543","rc":[{"batb":[[0,2.86,7.52],[1,2.78,1.68],[2,2.76,2.13]],"ltp":2.88,"tv":860.67,"id":12636},{"batb":[[0,2.3,7],[1,2.28,57.22],[2,2.26,16.83]],"ltp":2.24,"tv":2159.44,"id":10107355}]}]}
{"op":"mcm","clk":"992261555","pt":1580517963299,"mc":[{"id":"1.168133543","rc":[{"batb":[[0,2.88,5.98],[1,2.86,7.52]],"ltp":2.88,"tv":860.67,"id":12636}]}]}
{"op":"mcm","clk":"992261678","pt":1580517968308,"mc":[{"id":"1.168133543","rc":[{"batb":[[0,2.88,7.66]],"ltp":2.88,"tv":860.67,"id":12636},{"batl":[[0,9.8,5.47]],"ltp":9.2,"tv":282.08,"id":10163711}]}]}
{"op":"mcm","clk":"992262001","pt":1580517980543,"mc":[{"id":"1.168133543","rc":[{"trd":[[10,1.06],[10.5,17.24]],"batb":[[0,9.8,4.97]],"batl":[[0,10,2.29],[1,11,1.82],[2,11.5,3.97]],"ltp":10.0,"tv":248.09,"id":22121325}],"tv":3624.98}]}
{"op":"mcm","clk":"992262105","pt":1580517985138,"mc":[{"id":"1.168133543","rc":[{"batb":[[1,8.4,8.13]],"ltp":10.0,"tv":248.09,"id":22121325}]}]}
{"op":"mcm","clk":"992262167","pt":1580517987357,"mc":[{"id":"1.168133543","rc":[{"batl":[[2,11.5,4.05]],"ltp":10.0,"tv":248.09,"id":22121325}]}]}
{"op":"mcm","clk":"992262940","pt":1580518015491,"mc":[{"id":"1.168133543","rc":[{"trd":[[2.9,48.62]],"batl":[[0,2.9,44.63]],"ltp":2.9,"tv":876.43,"id":12636},{"batl":[[0,200,2.3]],"ltp":80.0,"tv":11.61,"id":22308007},{"trd":[[85,0.43],[90,0.71],[95,0.34]],"batl":[[0,95,2.86]],"ltp":95.0,"tv":19.74,"id":7226819},{"trd":[[9.6,11.45],[9.8,7.93]],"batl":[[0,9.8,4.69]],"ltp":9.8,"tv":286.82,"id":10163711},{"trd":[[2.36,142.4]],"batl":[[0,2.36,49.95]],"ltp":2.36,"tv":2178.82,"id":10107355},{"trd":[[10,5.64]],"batl":[[0,11,1.82],[1,11.5,4.05],[2,12,3]],"ltp":10.0,"tv":252.67,"id":22121325},{"batl":[[0,160,4.05]],"ltp":85.0,"tv":5.36,"id":26548208}],"tv":3669.93}]}
{"op":"mcm","clk":"992263018","pt":1580518018476,"mc":[{"id":"1.168133543","rc":[{"batb":[[0,55,1.46]],"ltp":95.0,"tv":19.74,"id":7226819},{"batb":[[0,8.8,13.36]],"ltp":9.8,"tv":286.82,"id":10163711}]}]}
{"op":"mcm","clk":"992263028","pt":1580518018889,"mc":[{"id":"1.168133543","rc":[{"batb":[[2,8.4,9.14]],"ltp":9.8,"tv":286.82,"id":10163711}]}]}
{"op":"mcm","clk":"992263045","pt":1580518020508,"mc":[{"id":"1.168133543","rc":[{"batb":[[0,2.88,77.12]],"ltp":2.9,"tv":876.43,"id":12636}]}]}
{"op":"mcm","clk":"992263161","pt":1580518024394,"mc":[{"id":"1.168133543","rc":[{"batb":[[0,55,2.24]],"ltp":95.0,"tv":19.74,"id":7226819}]}]}
{"op":"mcm","clk":"992263433","pt":1580518036723,"mc":[{"id":"1.168133543","rc":[{"batb":[[0,2.88,7.66]],"ltp":2.9,"tv":876.43,"id":12636},{"batb":[[0,55,4.95],[1,48,3.98],[2,46,1.08]],"ltp":95.0,"tv":19.74,"id":7226819}]}]}
{"op":"mcm","clk":"992263464","pt":1580518038517,"mc":[{"id":"1.168133543","rc":[{"batl":[[0,500,3.18],[1,510,9]],"ltp":95.0,"tv":19.74,"id":7226819}]}]}
{"op":"mcm","clk":"992263525","pt":1580518041335,"mc":[{"id":"1.168133543","rc":[{"batl":[[0,500,3.38]],"ltp":95.0,"tv":19.74,"id":7226819}]}]}
{"op":"mcm","clk":"992263630","pt":1580518046008,"mc":[{"id":"1.168133543","rc":[{"batl":[[0,500,3.46]],"ltp":95.0,"tv":19.74,"id":7226819}]}]}
{"op":"mcm","clk":"992265107","pt":1580518114272,"mc":[{"id":"1.168133543","rc":[{"batb":[[0,55,5.03],[1,48,3.88]],"ltp":95.0,"tv":19.74,"id":7226819}]}]}
{"op":"mcm","clk":"992282108","pt":1580518441566,"mc":[{"id":"1.168133543","rc":[{"batb":[[1,2.86,2.52]],"ltp":2.9,"tv":876.43,"id":12636},{"batb":[[0,2.28,57.22],[1,2.26,16.83],[2,2.24,5.28]],"ltp":2.36,"tv":2178.82,"id":10107355}]}]}
{"op":"mcm","clk":"992282125","pt":1580518442542,"mc":[{"id":"1.168133543","rc":[{"batb":[[0,2.88,12.66]],"ltp":2.9,"tv":876.43,"id":12636},{"batb":[[0,2.34,7],[1,2.28,57.22],[2,2.26,16.83]],"ltp":2.36,"tv":2178.82,"id":10107355}]}]}
{"op":"mcm","clk":"992282164","pt":1580518444245,"mc":[{"id":"1.168133543","rc":[{"batb":[[1,2.3,6],[2,2.28,57.22]],"ltp":2.36,"tv":2178.82,"id":10107355}]}]}
{"op":"mcm","clk":"992282174","pt":1580518444863,"mc":[{"id":"1.168133543","rc":[{"batb":[[2,2.28,55.54]],"ltp":2.36,"tv":2178.82,"id":10107355}]}]}
{"op":"mcm","clk":"992282233","pt":1580518448486,"mc":[{"id":"1.168133543","rc":[{"batb":[[0,8.8,4.46]],"ltp":9.8,"tv":286.82,"id":10163711},{"batb":[[2,2.26,16.83]],"ltp":2.36,"tv":2178.82,"id":10107355}]}]}
{"op":"mcm","clk":"992282268","pt":1580518450712,"mc":[{"id":"1.168133543","rc":[{"batb":[[1,2.32,1.68],[2,2.3,6]],"ltp":2.36,"tv":2178.82,"id":10107355}]}]}
{"op":"mcm","clk":"992282387","pt":1580518457406,"mc":[{"id":"1.168133543","rc":[{"batb":[[1,2.26,16.83],[2,2.24,5.28]],"ltp":2.36,"tv":2178.82,"id":10107355}]}]}
{"op":"mcm","clk":"992282508","pt":1580518463687,"mc":[{"id":"1.168133543","rc":[{"batb":[[1,2.28,1.68],[2,2.26,16.83]],"ltp":2.36,"tv":2178.82,"id":10107355}]}]}
{"op":"mcm","clk":"992282637","pt":1580518469489,"mc":[{"id":"1.168133543","rc":[{"batb":[[0,2.28,1.68],[1,2.26,16.83],[2,2.24,5.28]],"ltp":2.36,"tv":2178.82,"id":10107355}]}]}
{"op":"mcm","clk":"992282642","pt":1580518469694,"mc":[{"id":"1.168133543","rc":[{"batb":[[0,2.3,7],[1,2.28,1.68],[2,2.26,16.83]],"ltp":2.36,"tv":2178.82,"id":10107355}]}]}
{"op":"mcm","clk":"992282675","pt":1580518471292,"mc":[{"id":"1.168133543","rc":[{"batb":[[0,8.8,6.73]],"ltp":9.8,"tv":286.82,"id":10163711}]}]}
{"op":"mcm","clk":"992283314","pt":1580518501422,"mc":[{"id":"1.168133543","rc":[{"batb":[[1,2.76,2.13],[2,2.58,1.98]],"ltp":2.9,"tv":876.43,"id":12636}]}]}
{"op":"mcm","clk":"992283326","pt":1580518501630,"mc":[{"id":"1.168133543","rc":[{"batb":[[2,2.6,2.52]],"ltp":2.9,"tv":876.43,"id":12636}]}]}
{"op":"mcm","clk":"992290296","pt":1580518773680,"mc":[{"id":"1.168133543","rc":[{"batb":[[0,9,2.32],[1,8.8,6.63],[2,8.6,4.42]],"ltp":9.8,"tv":286.82,"id":10163711}]}]}
{"op":"mcm","clk":"992296307","pt":1580518947264,"mc":[{"id":"1.168133543","rc":[{"batb":[[2,2.6,23.82]],"ltp":2.9,"tv":876.43,"id":12636}]}]}
{"op":"mcm","clk":"992296363","pt":1580518949272,"mc":[{"id":"1.168133543","rc":[{"batb":[[2,8.2,4.73]],"ltp":10.0,"tv":252.67,"id":22121325}]}]}
{"op":"mcm","clk":"992297298","pt":1580518984254,"mc":[{"id":"1.168133543","rc":[{"batb":[[2,2.6,47.48]],"ltp":2.9,"tv":876.43,"id":12636}]}]}
{"op":"mcm","clk":"992297339","pt":1580518986363,"mc":[{"id":"1.168133543","rc":[{"batb":[[2,8.2,9.99]],"ltp":10.0,"tv":252.67,"id":22121325}]}]}
{"op":"mcm","clk":"992298378","pt":1580519031059,"mc":[{"id":"1.168133543","rc":[{"trd":[[2.9,58.62]],"batb":[[0,2.88,7.66]],"batl":[[0,2.9,39.63]],"ltp":2.9,"tv":886.43,"id":12636}],"tv":3679.93}]}
{"op":"mcm","clk":"992299725","pt":1580519084819,"mc":[{"id":"1.168133543","rc":[{"batb":[[0,2.88,5.98]],"ltp":2.9,"tv":886.43,"id":12636}]}]}
{"op":"mcm","clk":"992299968","pt":1580519093961,"mc":[{"id":"1.168133543","rc":[{"batb":[[2,2.62,1.68]],"ltp":2.9,"tv":886.43,"id":12636}]}]}
{"op":"mcm","clk":"992316074","pt":1580519355431,"mc":[{"id":"1.168133543","rc":[{"trd":[[55,6.1],[60,9.6]],"batb":[[0,55,3.02]],"ltp":55.0,"tv":23.75,"id":7226819}],"tv":3683.94}]}
{"op":"mcm","clk":"992316120","pt":1580519357494,"mc":[{"id":"1.168133543","rc":[{"batb":[[0,50,4.09],[1,48,3.08]],"ltp":55.0,"tv":23.75,"id":7226819}]}]}
{"op":"mcm","clk":"992316183","pt":1580519359299,"mc":[{"id":"1.168133543","rc":[{"batl":[[0,500,3.48]],"ltp":55.0,"tv":23.75,"id":7226819}]}]}
{"op":"mcm","clk":"992316200","pt":1580519360225,"mc":[{"id":"1.168133543","rc":[{"trd":[[2.9,62.62]],"batb":[[0,2.88,19.19]],"batl":[[0,2.9,37.63]],"ltp":2.9,"tv":890.43,"id":12636}],"tv":3687.94}]}
{"op":"mcm","clk":"992316259","pt":1580519362344,"mc":[{"id":"1.168133543","rc":[{"batb":[[2,2.6,47.48]],"ltp":2.9,"tv":890.43,"id":12636}]}]}
{"op":"mcm","clk":"992316462","pt":1580519368841,"mc":[{"id":"1.168133543","rc":[{"trd":[[2.9,65.98]],"batl":[[0,2.9,35.95]],"ltp":2.9,"tv":893.79,"id":12636}],"tv":3691.3}]}
{"op":"mcm","clk":"992316656","pt":1580519375538,"mc":[{"id":"1.168133543","rc":[{"trd":[[2.9,69.34]],"batl":[[0,2.9,34.27]],"ltp":2.9,"tv":897.15,"id":12636},{"batl":[[0,500,3.28]],"ltp":55.0,"tv":23.75,"id":7226819}],"tv":3694.66}]}
{"op":"mcm","clk":"992316659","pt":1580519375641,"mc":[{"id":"1.168133543","rc":[{"batl":[[0,500,3.48]],"ltp":55.0,"tv":23.75,"id":7226819}]}]}
{"op":"mcm","clk":"992316839","pt":1580519382128,"mc":[{"id":"1.168133543","rc":[{"trd":[[2.9,74.78]],"batl":[[0,2.9,31.55]],"ltp":2.9,"tv":902.59,"id":12636}],"tv":3700.1}]}
{"op":"mcm","clk":"992319065","pt":1580519463439,"mc":[{"id":"1.168133543","rc":[{"batb":[[0,50,4.18]],"ltp":55.0,"tv":23.75,"id":7226819}]}]}
{"op":"mcm","clk":"992332539","pt":1580520021566,"mc":[{"id":"1.168133543","rc":[{"batl":[[0,2.34,1.51],[1,2.36,49.95],[2,2.38,3.23]],"ltp":2.36,"tv":2178.82,"id":10107355}]}]}
{"op":"mcm","clk":"992332553","pt":1580520022031,"mc":[{"id":"1.168133543","rc":[{"batl":[[0,2.36,49.95],[1,2.38,3.23],[2,2.42,5.5]],"ltp":2.36,"tv":2178.82,"id":10107355}]}]}
{"op":"mcm","clk":"992352247","pt":1580520415929,"mc":[{"id":"1.168133543","rc":[{"batb":[[0,2.88,25.07]],"ltp":2.9,"tv":902.59,"id":12636}]}]}
{"op":"mcm","clk":"992360407","pt":1580520703922,"mc":[{"id":"1.168133543","rc":[{"batb":[[0,2.88,19.19]],"ltp":2.9,"tv":902.59,"id":12636}]}]}
{"op":"mcm","clk":"992363716","pt":1580520828778,"mc":[{"id":"1.168133543","rc":[{"batb":[[0,2.88,21.39]],"ltp":2.9,"tv":902.59,"id":12636}]}]}
{"op":"mcm","clk":"992379189","pt":1580521076528,"mc":[{"id":"1.168133543","rc":[{"batb":[[0,2.28,1.68],[1,2.26,23.83],[2,2.24,5.28]],"ltp":2.36,"tv":2178.82,"id":10107355}]}]}
{"op":"mcm","clk":"992379321","pt":1580521082540,"mc":[{"id":"1.168133543","rc":[{"batb":[[0,9,11.02]],"ltp":9.8,"tv":286.82,"id":10163711},{"batb":[[0,2.3,12.07],[1,2.28,57.22],[2,2.26,23.83]],"ltp":2.36,"tv":2178.82,"id":10107355}]}]}
{"op":"mcm","clk":"992379497","pt":1580521089530,"mc":[{"id":"1.168133543","rc":[{"batb":[[1,2.28,55.54]],"ltp":2.36,"tv":2178.82,"id":10107355}]}]}
{"op":"mcm","clk":"992379689","pt":1580521097542,"mc":[{"id":"1.168133543","rc":[{"batb":[[0,9,2.32]],"ltp":9.8,"tv":286.82,"id":10163711},{"batb":[[1,2.26,23.83],[2,2.24,5.28]],"ltp":2.36,"tv":2178.82,"id":10107355}]}]}
{"op":"mcm","clk":"992379695","pt":1580521098159,"mc":[{"id":"1.168133543","rc":[{"batb":[[0,2.32,1.68],[1,2.3,12.07],[2,2.26,23.83]],"ltp":2.36,"tv":2178.82,"id":10107355}]}]}
{"op":"mcm","clk":"992384585","pt":1580521344026,"mc":[{"id":"1.168133543","rc":[{"batb":[[0,60,1.92]],"ltp":80.0,"tv":11.61,"id":22308007}]}]}
{"op":"mcm","clk":"992386935","pt":1580521452522,"mc":[{"id":"1.168133543","rc":[{"batb":[[1,2.26,23.83],[2,2.24,5.28]],"batl":[[0,2.34,30],[1,2.36,49.95],[2,2.38,3.23]],"ltp":2.36,"tv":2178.82,"id":10107355}]}]}
{"op":"mcm","clk":"992386985","pt":1580521454487,"mc":[{"id":"1.168133543","rc":[{"batb":[[1,2.26,32.68]],"ltp":2.36,"tv":2178.82,"id":10107355}]}]}
{"op":"mcm","clk":"992387071","pt":1580521457524,"mc":[{"id":"1.168133543","rc":[{"batb":[[0,9,11.02]],"ltp":9.8,"tv":286.82,"id":10163711},{"batb":[[1,2.28,55.54],[2,2.26,32.68]],"ltp":2.36,"tv":2178.82,"id":10107355}]}]}
{"op":"mcm","clk":"992387119","pt":1580521459388,"mc":[{"id":"1.168133543","rc":[{"batb":[[0,2.28,55.54],[1,2.26,32.68],[2,2.24,5.28]],"ltp":2.36,"tv":2178.82,"id":10107355}]}]}
{"op":"mcm","clk":"992387341","pt":1580521468615,"mc":[{"id":"1.168133543","rc":[{"batb":[[0,2.3,1.68],[1,2.28,55.54],[2,2.26,32.68]],"ltp":2.36,"tv":2178.82,"id":10107355}]}]}
{"op":"mcm","clk":"992387415","pt":1580521471518,"mc":[{"id":"1.168133543","rc":[{"batb":[[1,8.8,2.27]],"ltp":9.8,"tv":286.82,"id":10163711}]}]}
{"op":"mcm","clk":"992387427","pt":1580521471923,"mc":[{"id":"1.168133543","rc":[{"batb":[[0,9.2,4.17],[1,9,11.02]],"ltp":9.8,"tv":286.82,"id":10163711}]}]}
{"op":"mcm","clk":"992387454","pt":1580521473531,"mc":[{"id":"1.168133543","rc":[{"batb":[[1,9,2.32]],"ltp":9.8,"tv":286.82,"id":10163711}]}]}
{"op":"mcm","clk":"992387782","pt":1580521489262,"mc":[{"id":"1.168133543","rc":[{"batb":[[0,9,2.32],[1,8.8,4.36]],"ltp":9.8,"tv":286.82,"id":10163711}]}]}
{"op":"mcm","clk":"992387825","pt":1580521491425,"mc":[{"id":"1.168133543","rc":[{"batb":[[0,9,11.02]],"ltp":9.8,"tv":286.82,"id":10163711}]}]}
{"op":"mcm","clk":"992388171","pt":1580521506277,"mc":[{"id":"1.168133543","rc":[{"batb":[[0,9.2,4.17],[1,9,11.02]],"ltp":9.8,"tv":286.82,"id":10163711}]}]}
{"op":"mcm","clk":"992388209","pt":1580521507468,"mc":[{"id":"1.168133543","rc":[{"batb":[[1,9,2.32]],"ltp":9.8,"tv":286.82,"id":10163711}]}]}
{"op":"mcm","clk":"992388257","pt":1580521509846,"mc":[{"id":"1.168133543","rc":[{"batb":[[1,8.6,4.52],[2,8.4,9.14]],"batl":[[0,9.8,3.38]],"ltp":9.8,"tv":286.82,"id":10163711},{"batb":[[2,2.26,23.83]],"ltp":2.36,"tv":2178.82,"id":10107355}]}]}
{"op":"mcm","clk":"992388524","pt":1580521523948,"mc":[{"id":"1.168133543","rc":[{"batb":[[0,8.8,6.73],[1,8.6,4.42]],"ltp":9.8,"tv":286.82,"id":10163711}]}]}
{"op":"mcm","clk":"992388580","pt":1580521527470,"mc":[{"id":"1.168133543","rc":[{"batb":[[0,9,8.8],[1,8.8,6.63],[2,8.6,4.42]],"ltp":9.8,"tv":286.82,"id":10163711}]}]}
{"op":"mcm","clk":"992388938","pt":1580521541356,"mc":[{"id":"1.168133543","rc":[{"batb":[[0,9.2,4.17],[1,9,8.8]],"ltp":9.8,"tv":286.82,"id":10163711}]}]}
{"op":"mcm","clk":"992388990","pt":1580521543480,"mc":[{"id":"1.168133543","rc":[{"batb":[[1,8.6,4.52],[2,8.4,9.14]],"ltp":9.8,"tv":286.82,"id":10163711}]}]}
{"op":"mcm","clk":"992389237","pt":1580521558478,"mc":[{"id":"1.168133543","rc":[{"batb":[[0,8.6,4.52],[1,8.4,9.14],[2,8.2,94.45]],"ltp":9.8,"tv":286.82,"id":10163711}]}]}
{"op":"mcm","clk":"992389262","pt":1580521559507,"mc":[{"id":"1.168133543","rc":[{"batb":[[0,8.8,13.36],[1,8.6,4.42],[2,8.4,9.14]],"ltp":9.8,"tv":286.82,"id":10163711}]}]}
{"op":"mcm","clk":"992389378","pt":1580521564310,"mc":[{"id":"1.168133543","rc":[{"batl":[[0,9.6,2],[1,9.8,3.38],[2,10,66]],"ltp":9.8,"tv":286.82,"id":10163711}]}]}
{"op":"mcm","clk":"992391022","pt":1580521617785,"mc":[{"id":"1.168133543","rc":[{"batb":[[0,9,2.32],[1,8.8,13.26],[2,8.6,4.42]],"ltp":9.8,"tv":286.82,"id":10163711}]}]}
{"op":"mcm","clk":"992391093","pt":1580521620470,"mc":[{"id":"1.168133543","rc":[{"batb":[[1,8.8,4.36]],"ltp":9.8,"tv":286.82,"id":10163711}]}]}
{"op":"mcm","clk":"992391097","pt":1580521620575,"mc":[{"id":"1.168133543","rc":[{"batb":[[0,9,11.02]],"ltp":9.8,"tv":286.82,"id":10163711}]}]}
{"op":"mcm","clk":"992391411","pt":1580521633371,"mc":[{"id":"1.168133543","rc":[{"batb":[[0,9.2,4.17],[1,9,11.02]],"ltp":9.8,"tv":286.82,"id":10163711}]}]}
{"op":"mcm","clk":"992391474","pt":1580521636410,"mc":[{"id":"1.168133543","rc":[{"batb":[[1,9,2.32]],"ltp":9.8,"tv":286.82,"id":10163711}]}]}
{"op":"mcm","clk":"992391850","pt":1580521650516,"mc":[{"id":"1.168133543","rc":[{"batb":[[0,9,2.32],[1,8.6,4.42],[2,8.4,9.14]],"ltp":9.8,"tv":286.82,"id":10163711}]}]}
{"op":"mcm","clk":"992391875","pt":1580521651399,"mc":[{"id":"1.168133543","rc":[{"batb":[[0,9,11.02],[1,8.8,6.63],[2,8.6,4.42]],"ltp":9.8,"tv":286.82,"id":10163711}]}]}
{"op":"mcm","clk":"992392317","pt":1580521668044,"mc":[{"id":"1.168133543","rc":[{"batb":[[0,9.2,4.17],[1,9,11.02]],"ltp":9.8,"tv":286.82,"id":10163711}]}]}
{"op":"mcm","clk":"992392376","pt":1580521671020,"mc":[{"id":"1.168133543","rc":[{"batb":[[1,9,8.8]],"batl":[[0,9.8,3.38],[1,10,66],[2,17,1.88]],"ltp":9.8,"tv":286.82,"id":10163711}]}]}
{"op":"mcm","clk":"992392983","pt":1580521699997,"mc":[{"id":"1.168133543","rc":[{"batl":[[0,10,66],[1,17,1.88],[2,29,9.24]],"ltp":9.8,"tv":286.82,"id":10163711}]}]}
{"op":"mcm","clk":"992393474","pt":1580521722969,"mc":[{"id":"1.168133543","rc":[{"batb":[[0,2.88,19.19],[1,2.8,2.2],[2,2.76,2.13]],"ltp":2.9,"tv":902.59,"id":12636}]}]}
{"op":"mcm","clk":"992394245","pt":1580521761210,"mc":[{"id":"1.168133543","rc":[{"batb":[[2,8.2,9.2]],"ltp":10.0,"tv":252.67,"id":22121325}]}]}
{"op":"mcm","clk":"992396753","pt":1580521874103,"mc":[{"id":"1.168133543","rc":[{"batb":[[2,8.2,3.95]],"ltp":10.0,"tv":252.67,"id":22121325}]}]}
{"op":"mcm","clk":"992396771","pt":1580521874923,"mc":[{"id":"1.168133543","rc":[{"batb":[[2,8.2,8.33]],"ltp":10.0,"tv":252.67,"id":22121325}]}]}
{"op":"mcm","clk":"992397522","pt":1580521906479,"mc":[{"id":"1.168133543","rc":[{"batb":[[1,8.6,4.52],[2,8.4,9.14]],"ltp":9.8,"tv":286.82,"id":10163711}]}]}
{"op":"mcm","clk":"992397527","pt":1580521906583,"mc":[{"id":"1.168133543","rc":[{"batb":[[0,9.2,12.68]],"ltp":9.8,"tv":286.82,"id":10163711}]}]}
{"op":"mcm","clk":"992398395","pt":1580521933516,"mc":[{"id":"1.168133543","rc":[{"batb":[[0,9.2,4.17]],"ltp":9.8,"tv":286.82,"id":10163711}]}]}
{"op":"mcm","clk":"992398421","pt":1580521934495,"mc":[{"id":"1.168133543","rc":[{"batb":[[0,8.6,4.52],[1,8.4,9.14],[2,8.2,94.45]],"ltp":9.8,"tv":286.82,"id":10163711}]}]}
{"op":"mcm","clk":"992398448","pt":1580521935523,"mc":[{"id":"1.168133543","rc":[{"batb":[[0,8.8,6.73],[1,8.6,4.42],[2,8.4,9.14]],"ltp":9.8,"tv":286.82,"id":10163711}]}]}
{"op":"mcm","clk":"992398522","pt":1580521939389,"mc":[{"id":"1.168133543","rc":[{"batb":[[0,9,2.32],[1,8.8,6.63],[2,8.6,4.42]],"batl":[[0,9.8,2],[1,10,66],[2,17,1.88]],"ltp":9.8,"tv":286.82,"id":10163711}]}]}
{"op":"mcm","clk":"992398764","pt":1580521949491,"mc":[{"id":"1.168133543","rc":[{"batb":[[0,9,11.02]],"ltp":9.8,"tv":286.82,"id":10163711}]}]}
{"op":"mcm","clk":"992408818","pt":1580521958306,"mc":[{"id":"1.168133543","rc":[{"batb":[[1,8.8,2.27]],"ltp":9.8,"tv":286.82,"id":10163711}]}]}
{"op":"mcm","clk":"992408833","pt":1580521958823,"mc":[{"id":"1.168133543","rc":[{"batb":[[0,9.2,4.17],[1,9,11.02]],"ltp":9.8,"tv":286.82,"id":10163711}]}]}
{"op":"mcm","clk":"992409030","pt":1580521965527,"mc":[{"id":"1.168133543","rc":[{"batb":[[0,9.2,12.68],[1,9,2.32]],"ltp":9.8,"tv":286.82,"id":10163711}]}]}
{"op":"mcm","clk":"992409865","pt":1580521993569,"mc":[{"id":"1.168133543","rc":[{"batb":[[1,8.6,4.52],[2,8.4,9.14]],"batl":[[0,10,66],[1,17,1.88],[2,29,9.24]],"ltp":9.8,"tv":286.82,"id":10163711}]}]}
{"op":"mcm","clk":"992410036","pt":1580521999488,"mc":[{"id":"1.168133543","rc":[{"batb":[[0,9.2,4.17]],"ltp":9.8,"tv":286.82,"id":10163711}]}]}
{"op":"mcm","clk":"992410174","pt":1580522004485,"mc":[{"id":"1.168133543","rc":[{"batb":[[0,8.6,4.52],[1,8.4,9.14],[2,8.2,94.45]],"ltp":9.8,"tv":286.82,"id":10163711}]}]}
{"op":"mcm","clk":"992410187","pt":1580522004848,"mc":[{"id":"1.168133543","rc":[{"batb":[[0,8.8,4.46],[1,8.6,4.42],[2,8.4,9.14]],"ltp":9.8,"tv":286.82,"id":10163711}]}]}
{"op":"mcm","clk":"992410457","pt":1580522014500,"mc":[{"id":"1.168133543","rc":[{"batb":[[0,8.8,13.36]],"ltp":9.8,"tv":286.82,"id":10163711}]}]}
{"op":"mcm","clk":"992410857","pt":1580522027398,"mc":[{"id":"1.168133543","rc":[{"batl":[[0,9.8,3.38],[1,10,66],[2,17,1.88]],"ltp":9.8,"tv":286.82,"id":10163711}]}]}
{"op":"mcm","clk":"992412790","pt":1580522100357,"mc":[{"id":"1.168133543","rc":[{"batb":[[0,9,2.32],[1,8.8,13.26],[2,8.6,4.42]],"batl":[[0,9.6,2],[1,9.8,3.38],[2,10,66]],"ltp":9.8,"tv":286.82,"id":10163711}]}]}
{"op":"mcm","clk":"992413039","pt":1580522110477,"mc":[{"id":"1.168133543","rc":[{"batb":[[1,8.8,4.36]],"ltp":9.8,"tv":286.82,"id":10163711}]}]}
{"op":"mcm","clk":"992413042","pt":1580522110580,"mc":[{"id":"1.168133543","rc":[{"batb":[[0,9,11.02]],"ltp":9.8,"tv":286.82,"id":10163711}]}]}
{"op":"mcm","clk":"992413258","pt":1580522119198,"mc":[{"id":"1.168133543","rc":[{"batb":[[0,9.2,4.17],[1,9,11.02]],"ltp":9.8,"tv":286.82,"id":10163711}]}]}
{"op":"mcm","clk":"992413415","pt":1580522125396,"mc":[{"id":"1.168133543","rc":[{"batl":[[1,10,66],[2,17,1.88]],"ltp":9.8,"tv":286.82,"id":10163711}]}]}
{"op":"mcm","clk":"992413443","pt":1580522126538,"mc":[{"id":"1.168133543","rc":[{"batb":[[1,9,2.32]],"ltp":9.8,"tv":286.82,"id":10163711}]}]}
{"op":"mcm","clk":"992413444","pt":1580522126638,"mc":[{"id":"1.168133543","rc":[{"batb":[[0,9.2,12.68]],"ltp":9.8,"tv":286.82,"id":10163711}]}]}
{"op":"mcm","clk":"992413835","pt":1580522142557,"mc":[{"id":"1.168133543","rc":[{"batb":[[0,9.2,4.17]],"ltp":9.8,"tv":286.82,"id":10163711}]}]}
{"op":"mcm","clk":"992414117","pt":1580522153526,"mc":[{"id":"1.168133543","rc":[{"batb":[[1,8.6,4.52],[2,8.4,9.14]],"batl":[[0,10,66],[1,17,1.88],[2,29,9.24]],"ltp":9.8,"tv":286.82,"id":10163711}]}]}
{"op":"mcm","clk":"992414126","pt":1580522154043,"mc":[{"id":"1.168133543","rc":[{"batb":[[0,8.8,6.73],[1,8.6,4.42]],"ltp":9.8,"tv":286.82,"id":10163711}]}]}
{"op":"mcm","clk":"992414240","pt":1580522158539,"mc":[{"id":"1.168133543","rc":[{"batb":[[0,9,8.8],[1,8.8,6.63],[2,8.6,4.42]],"batl":[[0,9.8,3.03],[1,10,66],[2,17,1.88]],"ltp":9.8,"tv":286.82,"id":10163711}]}]}
{"op":"mcm","clk":"992414579","pt":1580522171373,"mc":[{"id":"1.168133543","rc":[{"batb":[[0,9.2,4.17],[1,9,8.8]],"ltp":9.8,"tv":286.82,"id":10163711}]}]}
{"op":"mcm","clk":"992414658","pt":1580522174479,"mc":[{"id":"1.168133543","rc":[{"batb":[[1,8.6,4.52],[2,8.4,9.14]],"ltp":9.8,"tv":286.82,"id":10163711}]}]}
{"op":"mcm","clk":"992415009","pt":1580522188572,"mc":[{"id":"1.168133543","rc":[{"batb":[[0,8.8,4.46],[1,8.6,4.42]],"ltp":9.8,"tv":286.82,"id":10163711}]}]}
{"op":"mcm","clk":"992415036","pt":1580522190484,"mc":[{"id":"1.168133543","rc":[{"batb":[[0,8.8,13.36]],"ltp":9.8,"tv":286.82,"id":10163711}]}]}
{"op":"mcm","clk":"992416773","pt":1580522260454,"mc":[{"id":"1.168133543","rc":[{"batb":[[0,9,2.32],[1,8.8,13.26],[2,8.6,4.42]],"batl":[[0,9.6,2],[1,9.8,3.03],[2,10,66]],"ltp":9.8,"tv":286.82,"id":10163711}]}]}
{"op":"mcm","clk":"992416970","pt":1580522269567,"mc":[{"id":"1.168133543","rc":[{"batb":[[0,9,11.02],[1,8.8,4.36]],"ltp":9.8,"tv":286.82,"id":10163711}]}]}
{"op":"mcm","clk":"992417225","pt":1580522280385,"mc":[{"id":"1.168133543","rc":[{"batb":[[0,9.2,4.17],[1,9,11.02]],"ltp":9.8,"tv":286.82,"id":10163711}]}]}
{"op":"mcm","clk":"992417348","pt":1580522285377,"mc":[{"id":"1.168133543","rc":[{"batb":[[1,9,2.32]],"ltp":9.8,"tv":286.82,"id":10163711}]}]}
{"op":"mcm","clk":"992417419","pt":1580522287899,"mc":[{"id":"1.168133543","rc":[{"batl":[[1,10,66],[2,17,1.88]],"ltp":9.8,"tv":286.82,"id":10163711}]}]}
{"op":"mcm","clk":"992417674","pt":1580522297404,"mc":[{"id":"1.168133543","rc":[{"batb":[[0,9,2.32],[1,8.8,4.36]],"ltp":9.8,"tv":286.82,"id":10163711}]}]}
{"op":"mcm","clk":"992417678","pt":1580522297609,"mc":[{"id":"1.168133543","rc":[{"batb":[[1,8.8,6.63]],"ltp":9.8,"tv":286.82,"id":10163711}]}]}
{"op":"mcm","clk":"992417798","pt":1580522301524,"mc":[{"id":"1.168133543","rc":[{"batb":[[0,9,11.02]],"ltp":9.8,"tv":286.82,"id":10163711}]}]}
{"op":"mcm","clk":"992418123","pt":1580522314054,"mc":[{"id":"1.168133543","rc":[{"batl":[[0,9.8,2]],"ltp":9.8,"tv":286.82,"id":10163711}]}]}
{"op":"mcm","clk":"992418160","pt":1580522315346,"mc":[{"id":"1.168133543","rc":[{"batb":[[0,9.2,4.17],[1,9,11.02]],"ltp":9.8,"tv":286.82,"id":10163711}]}]}
{"op":"mcm","clk":"992418222","pt":1580522317555,"mc":[{"id":"1.168133543","rc":[{"batb":[[1,9,2.32]],"ltp":9.8,"tv":286.82,"id":10163711}]}]}
{"op":"mcm","clk":"992418226","pt":1580522317658,"mc":[{"id":"1.168133543","rc":[{"batb":[[0,9.2,12.68]],"ltp":9.8,"tv":286.82,"id":10163711}]}]}
{"op":"mcm","clk":"992418579","pt":1580522333358,"mc":[{"id":"1.168133543","rc":[{"batb":[[0,9.2,4.17]],"ltp":9.8,"tv":286.82,"id":10163711}]}]}
{"op":"mcm","clk":"992418945","pt":1580522349525,"mc":[{"id":"1.168133543","rc":[{"batb":[[0,9,2.32],[1,8.8,4.36]],"ltp":9.8,"tv":286.82,"id":10163711}]}]}
{"op":"mcm","clk":"992418954","pt":1580522349681,"mc":[{"id":"1.168133543","rc":[{"batb":[[1,8.8,6.63]],"ltp":9.8,"tv":286.82,"id":10163711}]}]}
{"op":"mcm","clk":"992419014","pt":1580522353230,"mc":[{"id":"1.168133543","rc":[{"batl":[[0,9.8,5.03]],"ltp":9.8,"tv":286.82,"id":10163711}]}]}
{"op":"mcm","clk":"992419276","pt":1580522365476,"mc":[{"id":"1.168133543","rc":[{"batb":[[0,9,11.02]],"ltp":9.8,"tv":286.82,"id":10163711}]}]}
{"op":"mcm","clk":"992419320","pt":1580522367463,"mc":[{"id":"1.168133543","rc":[{"batb":[[0,9.2,4.17],[1,9,8.8]],"batl":[[0,9.8,3.03]],"ltp":9.8,"tv":286.82,"id":10163711}]}]}
{"op":"mcm","clk":"992419731","pt":1580522381557,"mc":[{"id":"1.168133543","rc":[{"batb":[[1,8.6,4.52],[2,8.4,9.14]],"ltp":9.8,"tv":286.82,"id":10163711}]}]}
{"op":"mcm","clk":"992419811","pt":1580522384279,"mc":[{"id":"1.168133543","rc":[{"batb":[[0,8.8,4.46],[1,8.6,4.42]],"ltp":9.8,"tv":286.82,"id":10163711}]}]}
{"op":"mcm","clk":"992420142","pt":1580522393350,"mc":[{"id":"1.168133543","rc":[{"batl":[[0,2.32,3.03],[1,2.34,30],[2,2.36,49.95]],"ltp":2.36,"tv":2178.82,"id":10107355}]}]}
{"op":"mcm","clk":"992420179","pt":1580522394183,"mc":[{"id":"1.168133543","rc":[{"trd":[[2.32,41.04]],"batb":[[0,2.32,2.87],[1,2.3,1.68],[2,2.28,55.54]],"batl":[[0,2.34,30],[1,2.36,49.95],[2,2.38,3.23]],"ltp":2.32,"tv":2184.56,"id":10107355}],"tv":3705.84}]}
{"op":"mcm","clk":"992420244","pt":1580522396254,"mc":[{"id":"1.168133543","rc":[{"batb":[[0,2.3,1.68],[1,2.28,55.54],[2,2.26,23.83]],"ltp":2.32,"tv":2184.56,"id":10107355}]}]}
{"op":"mcm","clk":"992420286","pt":1580522397396,"mc":[{"id":"1.168133543","rc":[{"batb":[[0,8.8,13.36]],"ltp":9.8,"tv":286.82,"id":10163711}]}]}
{"op":"mcm","clk":"992420325","pt":1580522398174,"mc":[{"id":"1.168133543","rc":[{"trd":[[2.34,187.13]],"batl":[[0,2.34,27.15]],"ltp":2.34,"tv":2190.26,"id":10107355}],"tv":3711.54}]}
{"op":"mcm","clk":"992423309","pt":1580522473797,"mc":[{"id":"1.168133543","rc":[{"batb":[[0,9,2.32],[1,8.8,13.26],[2,8.6,4.42]],"batl":[[0,9.6,2],[1,9.8,3.03],[2,10,66]],"ltp":9.8,"tv":286.82,"id":10163711}]}]}
{"op":"mcm","clk":"992423394","pt":1580522476529,"mc":[{"id":"1.168133543","rc":[{"batb":[[0,9,11.02],[1,8.8,4.36]],"ltp":9.8,"tv":286.82,"id":10163711}]}]}
{"op":"mcm","clk":"992423721","pt":1580522487413,"mc":[{"id":"1.168133543","rc":[{"batb":[[0,9.2,4.17],[1,9,11.02]],"ltp":9.8,"tv":286.82,"id":10163711}]}]}
{"op":"mcm","clk":"992423836","pt":1580522492548,"mc":[{"id":"1.168133543","rc":[{"batb":[[1,9,2.32]],"ltp":9.8,"tv":286.82,"id":10163711}]}]}
{"op":"mcm","clk":"992424278","pt":1580522510898,"mc":[{"id":"1.168133543","rc":[{"batb":[[0,9,2.32],[1,8.8,6.63]],"ltp":9.8,"tv":286.82,"id":10163711}]}]}
{"op":"mcm","clk":"992424744","pt":1580522524412,"mc":[{"id":"1.168133543","rc":[{"batb":[[0,9,11.02]],"ltp":9.8,"tv":286.82,"id":10163711}]}]}
{"op":"mcm","clk":"992424818","pt":1580522527298,"mc":[{"id":"1.168133543","rc":[{"batb":[[0,9,8.8]],"batl":[[0,9.8,3.03],[1,10,66],[2,17,1.88]],"ltp":9.8,"tv":286.82,"id":10163711}]}]}
{"op":"mcm","clk":"992424847","pt":1580522528178,"mc":[{"id":"1.168133543","rc":[{"batb":[[0,9.2,4.17],[1,9,8.8]],"ltp":9.8,"tv":286.82,"id":10163711}]}]}
{"op":"mcm","clk":"992425255","pt":1580522540594,"mc":[{"id":"1.168133543","rc":[{"batb":[[1,8.6,4.52],[2,8.4,9.14]],"ltp":9.8,"tv":286.82,"id":10163711}]}]}
{"op":"mcm","clk":"992425423","pt":1580522547029,"mc":[{"id":"1.168133543","rc":[{"batl":[[0,10,66],[1,17,1.88],[2,29,9.24]],"ltp":9.8,"tv":286.82,"id":10163711}]}]}
{"op":"mcm","clk":"992425534","pt":1580522550927,"mc":[{"id":"1.168133543","rc":[{"batb":[[0,8.8,4.46],[1,8.6,4.42]],"ltp":9.8,"tv":286.82,"id":10163711}]}]}
{"op":"mcm","clk":"992425699","pt":1580522556452,"mc":[{"id":"1.168133543","rc":[{"batb":[[0,8.8,13.36]],"ltp":9.8,"tv":286.82,"id":10163711}]}]}
{"op":"mcm","clk":"992426223","pt":1580522578972,"mc":[{"id":"1.168133543","rc":[{"batl":[[0,9.8,3.38],[1,10,66],[2,17,1.88]],"ltp":9.8,"tv":286.82,"id":10163711}]}]}
{"op":"mcm","clk":"992429597","pt":1580522698520,"mc":[{"id":"1.168133543","rc":[{"batb":[[2,8.2,3.95]],"ltp":10.0,"tv":252.67,"id":22121325}]}]}
{"op":"mcm","clk":"992429607","pt":1580522699085,"mc":[{"id":"1.168133543","rc":[{"batb":[[2,8.2,7.7]],"ltp":10.0,"tv":252.67,"id":22121325}]}]}
{"op":"mcm","clk":"992430693","pt":1580522738550,"mc":[{"id":"1.168133543","rc":[{"batb":[[0,9,2.32],[1,8.8,13.26],[2,8.6,4.42]],"batl":[[0,9.6,2],[1,9.8,3.38],[2,10,66]],"ltp":9.8,"tv":286.82,"id":10163711}]}]}
{"op":"mcm","clk":"992430853","pt":1580522745394,"mc":[{"id":"1.168133543","rc":[{"batb":[[2,8.2,3.76]],"ltp":10.0,"tv":252.67,"id":22121325}]}]}
{"op":"mcm","clk":"992430867","pt":1580522746010,"mc":[{"id":"1.168133543","rc":[{"batb":[[2,8.2,7.13]],"ltp":10.0,"tv":252.67,"id":22121325}]}]}
{"op":"mcm","clk":"992430909","pt":1580522747507,"mc":[{"id":"1.168133543","rc":[{"batb":[[1,8.8,4.36]],"ltp":9.8,"tv":286.82,"id":10163711}]}]}
{"op":"mcm","clk":"992430911","pt":1580522747607,"mc":[{"id":"1.168133543","rc":[{"batb":[[0,9,11.02]],"ltp":9.8,"tv":286.82,"id":10163711}]}]}
{"op":"mcm","clk":"992431169","pt":1580522756131,"mc":[{"id":"1.168133543","rc":[{"batb":[[0,9.2,4.17],[1,9,11.02]],"ltp":9.8,"tv":286.82,"id":10163711}]}]}
{"op":"mcm","clk":"992431404","pt":1580522763415,"mc":[{"id":"1.168133543","rc":[{"batb":[[1,9,2.32]],"ltp":9.8,"tv":286.82,"id":10163711}]}]}
{"op":"mcm","clk":"992432009","pt":1580522779221,"mc":[{"id":"1.168133543","rc":[{"batb":[[0,9,2.32],[1,8.8,4.36]],"ltp":9.8,"tv":286.82,"id":10163711}]}]}
{"op":"mcm","clk":"992432523","pt":1580522795441,"mc":[{"id":"1.168133543","rc":[{"batb":[[0,9,11.02]],"ltp":9.8,"tv":286.82,"id":10163711}]}]}
{"op":"mcm","clk":"992432569","pt":1580522797141,"mc":[{"id":"1.168133543","rc":[{"batb":[[0,9.2,4.17],[1,9,11.02]],"ltp":9.8,"tv":286.82,"id":10163711}]}]}
{"op":"mcm","clk":"992432862","pt":1580522810574,"mc":[{"id":"1.168133543","rc":[{"batb":[[1,9,2.32]],"ltp":9.8,"tv":286.82,"id":10163711}]}]}
{"op":"mcm","clk":"992432948","pt":1580522814066,"mc":[{"id":"1.168133543","rc":[{"batl":[[1,10,66],[2,17,1.88]],"ltp":9.8,"tv":286.82,"id":10163711}]}]}
{"op":"mcm","clk":"992433084","pt":1580522819984,"mc":[{"id":"1.168133543","rc":[{"batb":[[0,9,2.32],[1,8.8,4.36]],"ltp":9.8,"tv":286.82,"id":10163711}]}]}
{"op":"mcm","clk":"992433264","pt":1580522828427,"mc":[{"id":"1.168133543","rc":[{"batb":[[0,9,11.02]],"ltp":9.8,"tv":286.82,"id":10163711}]}]}
{"op":"mcm","clk":"992433477","pt":1580522837219,"mc":[{"id":"1.168133543","rc":[{"batb":[[0,9.2,4.17],[1,9,11.02]],"ltp":9.8,"tv":286.82,"id":10163711}]}]}
{"op":"mcm","clk":"992433634","pt":1580522844522,"mc":[{"id":"1.168133543","rc":[{"batb":[[0,9.2,12.68],[1,9,2.32]],"ltp":9.8,"tv":286.82,"id":10163711}]}]}
{"op":"mcm","clk":"992433672","pt":1580522846221,"mc":[{"id":"1.168133543","rc":[{"batb":[[1,8.6,4.52],[2,8.4,9.14]],"batl":[[0,10,66],[1,17,1.88],[2,29,9.24]],"ltp":9.8,"tv":286.82,"id":10163711}]}]}
{"op":"mcm","clk":"992443755","pt":1580522860476,"mc":[{"id":"1.168133543","rc":[{"batb":[[0,9.2,4.17]],"ltp":9.8,"tv":286.82,"id":10163711}]}]}
{"op":"mcm","clk":"992444004","pt":1580522871394,"mc":[{"id":"1.168133543","rc":[{"batb":[[0,8.6,4.52],[1,8.4,9.14],[2,8.2,94.45]],"ltp":9.8,"tv":286.82,"id":10163711}]}]}
{"op":"mcm","clk":"992444009","pt":1580522871600,"mc":[{"id":"1.168133543","rc":[{"batb":[[0,8.8,4.46],[1,8.6,4.42],[2,8.4,9.14]],"ltp":9.8,"tv":286.82,"id":10163711}]}]}
{"op":"mcm","clk":"992444123","pt":1580522876387,"mc":[{"id":"1.168133543","rc":[{"batb":[[0,8.8,13.36]],"ltp":9.8,"tv":286.82,"id":10163711}]}]}
{"op":"mcm","clk":"992444171","pt":1580522879310,"mc":[{"id":"1.168133543","rc":[{"batl":[[0,9.8,3.38],[1,10,66],[2,17,1.88]],"ltp":9.8,"tv":286.82,"id":10163711}]}]}
{"op":"mcm","clk":"992445763","pt":1580522953105,"mc":[{"id":"1.168133543","rc":[{"batb":[[0,9,2.32],[1,8.8,13.26],[2,8.6,4.42]],"batl":[[0,9.6,2],[1,9.8,3.38],[2,10,66]],"ltp":9.8,"tv":286.82,"id":10163711}]}]}
{"op":"mcm","clk":"992445892","pt":1580522957697,"mc":[{"id":"1.168133543","rc":[{"batb":[[0,9,11.02],[1,8.8,4.36]],"ltp":9.8,"tv":286.82,"id":10163711}]}]}
{"op":"mcm","clk":"992446125","pt":1580522968750,"mc":[{"id":"1.168133543","rc":[{"batb":[[0,9.2,4.17],[1,9,11.02]],"ltp":9.8,"tv":286.82,"id":10163711}]}]}
{"op":"mcm","clk":"992446181","pt":1580522973528,"mc":[{"id":"1.168133543","rc":[{"batb":[[1,9,2.32]],"ltp":9.8,"tv":286.82,"id":10163711}]}]}
{"op":"mcm","clk":"992446293","pt":1580522979245,"mc":[{"id":"1.168133543","rc":[{"batl":[[1,10,66],[2,17,1.88]],"ltp":9.8,"tv":286.82,"id":10163711}]}]}
{"op":"mcm","clk":"992446425","pt":1580522985939,"mc":[{"id":"1.168133543","rc":[{"batb":[[0,9,2.32],[1,8.8,4.36]],"ltp":9.8,"tv":286.82,"id":10163711}]}]}
{"op":"mcm","clk":"992446476","pt":1580522989437,"mc":[{"id":"1.168133543","rc":[{"batb":[[0,9,11.02]],"ltp":9.8,"tv":286.82,"id":10163711}]}]}
{"op":"mcm","clk":"992446721","pt":1580523003186,"mc":[{"id":"1.168133543","rc":[{"batb":[[0,9.2,4.17],[1,9,11.02]],"ltp":9.8,"tv":286.82,"id":10163711}]}]}
{"op":"mcm","clk":"992446784","pt":1580523005507,"mc":[{"id":"1.168133543","rc":[{"batb":[[1,9,2.32]],"ltp":9.8,"tv":286.82,"id":10163711}]}]}
{"op":"mcm","clk":"992446788","pt":1580523005622,"mc":[{"id":"1.168133543","rc":[{"batb":[[0,9.2,12.68]],"ltp":9.8,"tv":286.82,"id":10163711}]}]}
{"op":"mcm","clk":"992446922","pt":1580523008295,"mc":[{"id":"1.168133543","rc":[{"batb":[[1,8.6,4.52],[2,8.4,9.14]],"batl":[[0,10,66],[1,17,1.88],[2,29,9.24]],"ltp":9.8,"tv":286.82,"id":10163711}]}]}
{"op":"mcm","clk":"992447192","pt":1580523021422,"mc":[{"id":"1.168133543","rc":[{"batb":[[0,9.2,4.17]],"ltp":9.8,"tv":286.82,"id":10163711}]}]}
{"op":"mcm","clk":"992447529","pt":1580523037348,"mc":[{"id":"1.168133543","rc":[{"batb":[[0,8.8,4.46],[1,8.6,4.42]],"ltp":9.8,"tv":286.82,"id":10163711}]}]}
{"op":"mcm","clk":"992447700","pt":1580523044394,"mc":[{"id":"1.168133543","rc":[{"batl":[[0,9.8,3.03],[1,10,66],[2,17,1.88]],"ltp":9.8,"tv":286.82,"id":10163711}]}]}
{"op":"mcm","clk":"992448014","pt":1580523052527,"mc":[{"id":"1.168133543","rc":[{"batb":[[0,8.8,13.36]],"ltp":9.8,"tv":286.82,"id":10163711}]}]}
{"op":"mcm","clk":"992449477","pt":1580523115403,"mc":[{"id":"1.168133543","rc":[{"batb":[[0,9,2.32],[1,8.8,13.26],[2,8.6,4.42]],"batl":[[0,9.6,2],[1,9.8,3.03],[2,10,66]],"ltp":9.8,"tv":286.82,"id":10163711}]}]}
{"op":"mcm","clk":"992449514","pt":1580523116529,"mc":[{"id":"1.168133543","rc":[{"batb":[[1,8.8,4.36]],"ltp":9.8,"tv":286.82,"id":10163711}]}]}
{"op":"mcm","clk":"992449517","pt":1580523116633,"mc":[{"id":"1.168133543","rc":[{"batb":[[0,9,11.02]],"ltp":9.8,"tv":286.82,"id":10163711}]}]}
{"op":"mcm","clk":"992449789","pt":1580523128435,"mc":[{"id":"1.168133543","rc":[{"batb":[[1,8.6,4.42],[2,8.4,9.14]],"ltp":9.8,"tv":286.82,"id":10163711}]}]}
{"op":"mcm","clk":"992449796","pt":1580523128640,"mc":[{"id":"1.168133543","rc":[{"batb":[[0,9.2,4.17],[1,9,11.02],[2,8.6,4.42]],"ltp":9.8,"tv":286.82,"id":10163711}]}]}
{"op":"mcm","clk":"992449879","pt":1580523132548,"mc":[{"id":"1.168133543","rc":[{"batb":[[1,9,2.32]],"ltp":9.8,"tv":286.82,"id":10163711}]}]}
{"op":"mcm","clk":"992450129","pt":1580523142968,"mc":[{"id":"1.168133543","rc":[{"batl":[[1,10,66],[2,17,1.88]],"ltp":9.8,"tv":286.82,"id":10163711}]}]}
{"op":"mcm","clk":"992450194","pt":1580523145993,"mc":[{"id":"1.168133543","rc":[{"batb":[[0,9,2.32],[1,8.8,4.36]],"ltp":9.8,"tv":286.82,"id":10163711}]}]}
{"op":"mcm","clk":"992450248","pt":1580523148452,"mc":[{"id":"1.168133543","rc":[{"batb":[[0,9,11.02]],"ltp":9.8,"tv":286.82,"id":10163711}]}]}
{"op":"mcm","clk":"992450591","pt":1580523163184,"mc":[{"id":"1.168133543","rc":[{"batb":[[0,9.2,4.17],[1,9,11.02]],"ltp":9.8,"tv":286.82,"id":10163711}]}]}
{"op":"mcm","clk":"992450629","pt":1580523164514,"mc":[{"id":"1.168133543","rc":[{"batb":[[1,9,2.32]],"ltp":9.8,"tv":286.82,"id":10163711}]}]}
{"op":"mcm","clk":"992450631","pt":1580523164615,"mc":[{"id":"1.168133543","rc":[{"batb":[[0,9.2,12.68]],"ltp":9.8,"tv":286.82,"id":10163711}]}]}
{"op":"mcm","clk":"992450737","pt":1580523169501,"mc":[{"id":"1.168133543","rc":[{"batb":[[1,8.6,4.52],[2,8.4,9.14]],"batl":[[0,10,66],[1,17,1.88],[2,29,9.24]],"ltp":9.8,"tv":286.82,"id":10163711}]}]}
{"op":"mcm","clk":"992451027","pt":1580523181529,"mc":[{"id":"1.168133543","rc":[{"batb":[[0,9.2,4.17]],"ltp":9.8,"tv":286.82,"id":10163711}]}]}
{"op":"mcm","clk":"992451175","pt":1580523186425,"mc":[{"id":"1.168133543","rc":[{"batb":[[0,8.8,4.46],[1,8.6,4.42]],"ltp":9.8,"tv":286.82,"id":10163711}]}]}
{"op":"mcm","clk":"992451531","pt":1580523197448,"mc":[{"id":"1.168133543","rc":[{"batb":[[0,8.8,13.36]],"ltp":9.8,"tv":286.82,"id":10163711}]}]}
{"op":"mcm","clk":"992451833","pt":1580523208466,"mc":[{"id":"1.168133543","rc":[{"batl":[[0,9.8,3.38],[1,10,66],[2,17,1.88]],"ltp":9.8,"tv":286.82,"id":10163711}]}]}
{"op":"mcm","clk":"992453706","pt":1580523275480,"mc":[{"id":"1.168133543","rc":[{"batb":[[0,9,2.32],[1,8.8,13.26],[2,8.6,4.42]],"batl":[[0,9.6,2],[1,9.8,3.38],[2,10,66]],"ltp":9.8,"tv":286.82,"id":10163711}]}]}
{"op":"mcm","clk":"992453959","pt":1580523288517,"mc":[{"id":"1.168133543","rc":[{"batb":[[1,8.8,4.36]],"ltp":9.8,"tv":286.82,"id":10163711}]}]}
{"op":"mcm","clk":"992453964","pt":1580523288577,"mc":[{"id":"1.168133543","rc":[{"batb":[[0,9,11.02]],"ltp":9.8,"tv":286.82,"id":10163711}]}]}
{"op":"mcm","clk":"992454445","pt":1580523305524,"mc":[{"id":"1.168133543","rc":[{"batb":[[1,8.6,4.42],[2,8.4,9.14]],"ltp":9.8,"tv":286.82,"id":10163711}]}]}
{"op":"mcm","clk":"992454448","pt":1580523305729,"mc":[{"id":"1.168133543","rc":[{"batb":[[0,9.2,4.17],[1,9,11.02],[2,8.6,4.42]],"ltp":9.8,"tv":286.82,"id":10163711}]}]}
{"op":"mcm","clk":"992454631","pt":1580523314535,"mc":[{"id":"1.168133543","rc":[{"batb":[[1,9,2.32]],"batl":[[1,10,66],[2,17,1.88]],"ltp":9.8,"tv":286.82,"id":10163711}]}]}
{"op":"mcm","clk":"992454635","pt":1580523314640,"mc":[{"id":"1.168133543","rc":[{"batb":[[0,9.2,12.68]],"ltp":9.8,"tv":286.82,"id":10163711}]}]}
{"op":"mcm","clk":"992454896","pt":1580523323461,"mc":[{"id":"1.168133543","rc":[{"batb":[[0,9.2,4.17]],"ltp":9.8,"tv":286.82,"id":10163711}]}]}
{"op":"mcm","clk":"992455042","pt":1580523328561,"mc":[{"id":"1.168133543","rc":[{"batb":[[1,8.6,4.52],[2,8.4,9.14]],"ltp":9.8,"tv":286.82,"id":10163711}]}]}
{"op":"mcm","clk":"992455062","pt":1580523329545,"mc":[{"id":"1.168133543","rc":[{"batl":[[0,10,66],[1,17,1.88],[2,29,9.24]],"ltp":9.8,"tv":286.82,"id":10163711}]}]}
{"op":"mcm","clk":"992455088","pt":1580523330471,"mc":[{"id":"1.168133543","rc":[{"batl":[[0,60,4],[1,500,3.48],[2,510,9]],"ltp":55.0,"tv":23.75,"id":7226819}]}]}
{"op":"mcm","clk":"992455138","pt":1580523332168,"mc":[{"id":"1.168133543","rc":[{"batl":[[1,500,3.28]],"ltp":55.0,"tv":23.75,"id":7226819},{"batl":[[0,160,4]],"ltp":85.0,"tv":5.36,"id":26548208}]}]}
{"op":"mcm","clk":"992455331","pt":1580523339548,"mc":[{"id":"1.168133543","rc":[{"batb":[[0,50,1.21]],"ltp":55.0,"tv":23.75,"id":7226819},{"batb":[[0,9.2,12.68]],"ltp":9.8,"tv":286.82,"id":10163711}]}]}
{"op":"mcm","clk":"992455571","pt":1580523346379,"mc":[{"id":"1.168133543","rc":[{"batl":[[1,510,9.25],[2,550,2]],"ltp":55.0,"tv":23.75,"id":7226819}]}]}
{"op":"mcm","clk":"992455705","pt":1580523349982,"mc":[{"id":"1.168133543","rc":[{"batl":[[1,510,9.17]],"ltp":55.0,"tv":23.75,"id":7226819}]}]}
{"op":"mcm","clk":"992456099","pt":1580523362207,"mc":[{"id":"1.168133543","rc":[{"batb":[[0,48,3.49],[1,46,1.95],[2,42,1.86]],"ltp":55.0,"tv":23.75,"id":7226819}]}]}
{"op":"mcm","clk":"992481297","pt":1580523870313,"mc":[{"id":"1.168133543","rc":[{"trd":[[9.2,58.57]],"batb":[[0,9.2,10.41]],"ltp":9.2,"tv":291.36,"id":10163711}],"tv":3716.08}]}
{"op":"mcm","clk":"992481439","pt":1580523877194,"mc":[{"id":"1.168133543","rc":[{"batb":[[2,8.4,6.14]],"ltp":9.2,"tv":291.36,"id":10163711}]}]}
{"op":"mcm","clk":"992483169","pt":1580523943431,"mc":[{"id":"1.168133543","rc":[{"batb":[[2,8.2,3.76]],"ltp":10.0,"tv":252.67,"id":22121325}]}]}
{"op":"mcm","clk":"992483606","pt":1580523956154,"mc":[{"id":"1.168133543","rc":[{"batb":[[2,8,2.86]],"ltp":10.0,"tv":252.67,"id":22121325}]}]}
{"op":"mcm","clk":"992483635","pt":1580523956920,"mc":[{"id":"1.168133543","rc":[{"batb":[[2,8,6.04]],"ltp":10.0,"tv":252.67,"id":22121325}]}]}
{"op":"mcm","clk":"992485224","pt":1580524009521,"mc":[{"id":"1.168133543","rc":[{"batb":[[0,9.2,1.9],[1,8.8,9],[2,8.6,4.42]],"ltp":9.2,"tv":291.36,"id":10163711}]}]}
{"op":"mcm","clk":"992485364","pt":1580524014552,"mc":[{"id":"1.168133543","rc":[{"batb":[[0,9,2.04],[1,8.8,8.9]],"ltp":9.2,"tv":291.36,"id":10163711}]}]}
{"op":"mcm","clk":"992485503","pt":1580524016928,"mc":[{"id":"1.168133543","rc":[{"batb":[[0,9,4.26]],"batl":[[0,9.8,2],[1,10,66],[2,17,1.88]],"ltp":9.2,"tv":291.36,"id":10163711}]}]}
{"op":"mcm","clk":"992485899","pt":1580524030475,"mc":[{"id":"1.168133543","rc":[{"batb":[[1,8.6,4.42],[2,8.4,6.14]],"ltp":9.2,"tv":291.36,"id":10163711}]}]}
{"op":"mcm","clk":"992485905","pt":1580524030680,"mc":[{"id":"1.168133543","rc":[{"batb":[[0,9,12.96]],"ltp":9.2,"tv":291.36,"id":10163711}]}]}
{"op":"mcm","clk":"992486008","pt":1580524034073,"mc":[{"id":"1.168133543","rc":[{"batl":[[0,9.8,5.38]],"ltp":9.2,"tv":291.36,"id":10163711}]}]}
{"op":"mcm","clk":"992487173","pt":1580524069919,"mc":[{"id":"1.168133543","rc":[{"batb":[[0,9,10.74]],"batl":[[0,9.8,3.38]],"ltp":9.2,"tv":291.36,"id":10163711}]}]}
{"op":"mcm","clk":"992487491","pt":1580524078560,"mc":[{"id":"1.168133543","rc":[{"batb":[[0,9,2.04],[1,8.8,8.9],[2,8.6,4.42]],"ltp":9.2,"tv":291.36,"id":10163711}]}]}
{"op":"mcm","clk":"992490999","pt":1580524175514,"mc":[{"id":"1.168133543","rc":[{"batb":[[0,9,4.26]],"ltp":9.2,"tv":291.36,"id":10163711}]}]}
{"op":"mcm","clk":"992491468","pt":1580524189549,"mc":[{"id":"1.168133543","rc":[{"batb":[[1,8.6,4.42],[2,8.4,6.14]],"ltp":9.2,"tv":291.36,"id":10163711}]}]}
{"op":"mcm","clk":"992491473","pt":1580524189653,"mc":[{"id":"1.168133543","rc":[{"batb":[[0,9,12.96]],"ltp":9.2,"tv":291.36,"id":10163711}]}]}
{"op":"mcm","clk":"992492616","pt":1580524229338,"mc":[{"id":"1.168133543","rc":[{"batb":[[0,9,10.74]],"ltp":9.2,"tv":291.36,"id":10163711}]}]}
{"op":"mcm","clk":"992492847","pt":1580524237565,"mc":[{"id":"1.168133543","rc":[{"batb":[[0,9,2.04]],"ltp":9.2,"tv":291.36,"id":10163711}]}]}
{"op":"mcm","clk":"992492852","pt":1580524237623,"mc":[{"id":"1.168133543","rc":[{"batb":[[1,8.8,8.9],[2,8.6,4.42]],"ltp":9.2,"tv":291.36,"id":10163711}]}]}
{"op":"mcm","clk":"992495493","pt":1580524303431,"mc":[{"id":"1.168133543","rc":[{"trd":[[2.28,241.21],[2.3,548.71]],"batb":[[0,2.28,41.23],[1,2.26,23.83],[2,2.24,5.28]],"ltp":2.28,"tv":2222.24,"id":10107355}],"tv":3748.07}]}
{"op":"mcm","clk":"992495922","pt":1580524310776,"mc":[{"id":"1.168133543","rc":[{"batb":[[0,2.3,1.68],[1,2.28,41.23],[2,2.26,23.83]],"ltp":2.28,"tv":2222.24,"id":10107355}]}]}
{"op":"mcm","clk":"992497093","pt":1580524335395,"mc":[{"id":"1.168133543","rc":[{"batb":[[0,9,4.26]],"ltp":9.2,"tv":291.36,"id":10163711}]}]}
{"op":"mcm","clk":"992497505","pt":1580524348715,"mc":[{"id":"1.168133543","rc":[{"batb":[[0,9,12.96],[1,8.6,4.42],[2,8.4,6.14]],"ltp":9.2,"tv":291.36,"id":10163711}]}]}
{"op":"mcm","clk":"992498867","pt":1580524388236,"mc":[{"id":"1.168133543","rc":[{"batb":[[0,9,10.74]],"ltp":9.2,"tv":291.36,"id":10163711}]}]}
{"op":"mcm","clk":"992499217","pt":1580524396573,"mc":[{"id":"1.168133543","rc":[{"batb":[[0,9,2.04]],"ltp":9.2,"tv":291.36,"id":10163711}]}]}
{"op":"mcm","clk":"992499267","pt":1580524397551,"mc":[{"id":"1.168133543","rc":[{"batb":[[1,8.8,8.9],[2,8.6,4.42]],"ltp":9.2,"tv":291.36,"id":10163711}]}]}
{"op":"mcm","clk":"992502881","pt":1580524493901,"mc":[{"id":"1.168133543","rc":[{"batb":[[0,9,4.26]],"ltp":9.2,"tv":291.36,"id":10163711}]}]}
{"op":"mcm","clk":"992503353","pt":1580524507530,"mc":[{"id":"1.168133543","rc":[{"batb":[[1,8.6,4.42],[2,8.4,6.14]],"ltp":9.2,"tv":291.36,"id":10163711}]}]}
{"op":"mcm","clk":"992503355","pt":1580524507629,"mc":[{"id":"1.168133543","rc":[{"batb":[[0,9,12.96]],"ltp":9.2,"tv":291.36,"id":10163711}]}]}
{"op":"mcm","clk":"992504714","pt":1580524547117,"mc":[{"id":"1.168133543","rc":[{"batb":[[0,9,10.74]],"ltp":9.2,"tv":291.36,"id":10163711}]}]}
{"op":"mcm","clk":"992505047","pt":1580524556047,"mc":[{"id":"1.168133543","rc":[{"batb":[[0,9,2.04],[1,8.8,8.9],[2,8.6,4.42]],"ltp":9.2,"tv":291.36,"id":10163711}]}]}
{"op":"mcm","clk":"992518403","pt":1580524653614,"mc":[{"id":"1.168133543","rc":[{"batb":[[0,9,4.26]],"ltp":9.2,"tv":291.36,"id":10163711}]}]}
{"op":"mcm","clk":"992518900","pt":1580524667536,"mc":[{"id":"1.168133543","rc":[{"batb":[[1,8.6,4.42],[2,8.4,6.14]],"ltp":9.2,"tv":291.36,"id":10163711}]}]}
{"op":"mcm","clk":"992518904","pt":1580524667642,"mc":[{"id":"1.168133543","rc":[{"batb":[[0,9,12.96]],"ltp":9.2,"tv":291.36,"id":10163711}]}]}
{"op":"mcm","clk":"992520174","pt":1580524707068,"mc":[{"id":"1.168133543","rc":[{"batb":[[0,9,10.74]],"ltp":9.2,"tv":291.36,"id":10163711}]}]}
{"op":"mcm","clk":"992520545","pt":1580524719520,"mc":[{"id":"1.168133543","rc":[{"batb":[[0,9,2.04]],"ltp":9.2,"tv":291.36,"id":10163711}]}]}
{"op":"mcm","clk":"992520577","pt":1580524720293,"mc":[{"id":"1.168133543","rc":[{"batb":[[1,8.8,8.9],[2,8.6,4.42]],"ltp":9.2,"tv":291.36,"id":10163711}]}]}
{"op":"mcm","clk":"992523730","pt":1580524813280,"mc":[{"id":"1.168133543","rc":[{"batb":[[0,9,4.26]],"ltp":9.2,"tv":291.36,"id":10163711}]}]}
{"op":"mcm","clk":"992523850","pt":1580524815697,"mc":[{"id":"1.168133543","rc":[{"batb":[[0,9,12.96],[1,8.6,4.42],[2,8.4,6.14]],"ltp":9.2,"tv":291.36,"id":10163711}]}]}
{"op":"mcm","clk":"992525725","pt":1580524866346,"mc":[{"id":"1.168133543","rc":[{"batb":[[0,9,10.74]],"ltp":9.2,"tv":291.36,"id":10163711}]}]}
{"op":"mcm","clk":"992526187","pt":1580524878573,"mc":[{"id":"1.168133543","rc":[{"batb":[[0,9,2.04],[1,8.8,8.9],[2,8.6,4.42]],"ltp":9.2,"tv":291.36,"id":10163711}]}]}
{"op":"mcm","clk":"992529906","pt":1580524972939,"mc":[{"id":"1.168133543","rc":[{"batb":[[0,9,4.26]],"ltp":9.2,"tv":291.36,"id":10163711}]}]}
{"op":"mcm","clk":"992529976","pt":1580524974533,"mc":[{"id":"1.168133543","rc":[{"batb":[[0,9,12.96],[1,8.6,4.42],[2,8.4,6.14]],"ltp":9.2,"tv":291.36,"id":10163711}]}]}
{"op":"mcm","clk":"992532045","pt":1580525026499,"mc":[{"id":"1.168133543","rc":[{"batb":[[0,9,10.74]],"ltp":9.2,"tv":291.36,"id":10163711}]}]}
{"op":"mcm","clk":"992532510","pt":1580525038751,"mc":[{"id":"1.168133543","rc":[{"batb":[[0,9,2.04],[1,8.8,8.9],[2,8.6,4.42]],"ltp":9.2,"tv":291.36,"id":10163711}]}]}
{"op":"mcm","clk":"992533584","pt":1580525067494,"mc":[{"id":"1.168133543","rc":[{"batb":[[2,8,2.86]],"ltp":10.0,"tv":252.67,"id":22121325}]}]}
{"op":"mcm","clk":"992533620","pt":1580525068576,"mc":[{"id":"1.168133543","rc":[{"batb":[[2,8,5.57]],"ltp":10.0,"tv":252.67,"id":22121325}]}]}
{"op":"mcm","clk":"992535785","pt":1580525132360,"mc":[{"id":"1.168133543","rc":[{"batb":[[0,9,4.26]],"ltp":9.2,"tv":291.36,"id":10163711}]}]}
{"op":"mcm","clk":"992535887","pt":1580525135551,"mc":[{"id":"1.168133543","rc":[{"batb":[[1,8.6,4.42],[2,8.4,6.14]],"ltp":9.2,"tv":291.36,"id":10163711}]}]}
{"op":"mcm","clk":"992535923","pt":1580525136541,"mc":[{"id":"1.168133543","rc":[{"batb":[[0,9,12.96]],"ltp":9.2,"tv":291.36,"id":10163711}]}]}
{"op":"mcm","clk":"992537504","pt":1580525185331,"mc":[{"id":"1.168133543","rc":[{"batb":[[0,9,10.74]],"ltp":9.2,"tv":291.36,"id":10163711}]}]}
{"op":"mcm","clk":"992537704","pt":1580525190459,"mc":[{"id":"1.168133543","rc":[{"batb":[[2,8,2.7]],"ltp":10.0,"tv":252.67,"id":22121325}]}]}
{"op":"mcm","clk":"992537755","pt":1580525191540,"mc":[{"id":"1.168133543","rc":[{"batb":[[2,8,5.13]],"ltp":10.0,"tv":252.67,"id":22121325}]}]}
{"op":"mcm","clk":"992538005","pt":1580525198436,"mc":[{"id":"1.168133543","rc":[{"batb":[[0,9,2.04]],"ltp":9.2,"tv":291.36,"id":10163711}]}]}
{"op":"mcm","clk":"992538011","pt":1580525198640,"mc":[{"id":"1.168133543","rc":[{"batb":[[1,8.8,8.9],[2,8.6,4.42]],"ltp":9.2,"tv":291.36,"id":10163711}]}]}
{"op":"mcm","clk":"992540712","pt":1580525291923,"mc":[{"id":"1.168133543","rc":[{"batb":[[0,9,4.26]],"ltp":9.2,"tv":291.36,"id":10163711}]}]}
{"op":"mcm","clk":"992540785","pt":1580525294433,"mc":[{"id":"1.168133543","rc":[{"batb":[[1,8.6,4.42],[2,8.4,6.14]],"ltp":9.2,"tv":291.36,"id":10163711}]}]}
{"op":"mcm","clk":"992540795","pt":1580525294638,"mc":[{"id":"1.168133543","rc":[{"batb":[[0,9,12.96]],"ltp":9.2,"tv":291.36,"id":10163711}]}]}
{"op":"mcm","clk":"992542755","pt":1580525344995,"mc":[{"id":"1.168133543","rc":[{"batb":[[0,9,10.74]],"ltp":9.2,"tv":291.36,"id":10163711}]}]}
{"op":"mcm","clk":"992543301","pt":1580525359522,"mc":[{"id":"1.168133543","rc":[{"batb":[[0,9,2.04]],"ltp":9.2,"tv":291.36,"id":10163711}]}]}
{"op":"mcm","clk":"992543308","pt":1580525359610,"mc":[{"id":"1.168133543","rc":[{"batb":[[1,8.8,8.9],[2,8.6,4.42]],"ltp":9.2,"tv":291.36,"id":10163711}]}]}
{"op":"mcm","clk":"992546760","pt":1580525450801,"mc":[{"id":"1.168133543","rc":[{"batb":[[0,9,4.26]],"ltp":9.2,"tv":291.36,"id":10163711}]}]}
{"op":"mcm","clk":"992547154","pt":1580525461495,"mc":[{"id":"1.168133543","rc":[{"batb":[[1,8.6,4.42],[2,8.4,6.14]],"ltp":9.2,"tv":291.36,"id":10163711}]}]}
{"op":"mcm","clk":"992547157","pt":1580525461598,"mc":[{"id":"1.168133543","rc":[{"batb":[[0,9,12.96]],"ltp":9.2,"tv":291.36,"id":10163711}]}]}
{"op":"mcm","clk":"992548372","pt":1580525503657,"mc":[{"id":"1.168133543","rc":[{"batb":[[0,9,10.74]],"ltp":9.2,"tv":291.36,"id":10163711}]}]}
{"op":"mcm","clk":"992548650","pt":1580525512560,"mc":[{"id":"1.168133543","rc":[{"batb":[[0,9,2.04],[1,8.8,8.9],[2,8.6,4.42]],"ltp":9.2,"tv":291.36,"id":10163711}]}]}
{"op":"mcm","clk":"992561230","pt":1580525611261,"mc":[{"id":"1.168133543","rc":[{"batb":[[0,9,4.26]],"ltp":9.2,"tv":291.36,"id":10163711}]}]}
{"op":"mcm","clk":"992561549","pt":1580525623555,"mc":[{"id":"1.168133543","rc":[{"batb":[[0,9,12.96],[1,8.6,4.42],[2,8.4,6.14]],"ltp":9.2,"tv":291.36,"id":10163711}]}]}
{"op":"mcm","clk":"992562878","pt":1580525665559,"mc":[{"id":"1.168133543","rc":[{"batb":[[0,9,2.04]],"ltp":9.2,"tv":291.36,"id":10163711}]}]}
{"op":"mcm","clk":"992562882","pt":1580525665665,"mc":[{"id":"1.168133543","rc":[{"batb":[[1,8.8,8.9],[2,8.6,4.42]],"ltp":9.2,"tv":291.36,"id":10163711}]}]}
{"op":"mcm","clk":"992566420","pt":1580525770222,"mc":[{"id":"1.168133543","rc":[{"batb":[[0,9,4.26]],"ltp":9.2,"tv":291.36,"id":10163711}]}]}
{"op":"mcm","clk":"992566582","pt":1580525776520,"mc":[{"id":"1.168133543","rc":[{"batb":[[1,8.6,4.42],[2,8.4,6.14]],"ltp":9.2,"tv":291.36,"id":10163711}]}]}
{"op":"mcm","clk":"992566583","pt":1580525776622,"mc":[{"id":"1.168133543","rc":[{"batb":[[0,9,12.96]],"ltp":9.2,"tv":291.36,"id":10163711}]}]}
{"op":"mcm","clk":"992567922","pt":1580525823545,"mc":[{"id":"1.168133543","rc":[{"batb":[[0,9,10.74]],"ltp":9.2,"tv":291.36,"id":10163711}]}]}
{"op":"mcm","clk":"992567997","pt":1580525827547,"mc":[{"id":"1.168133543","rc":[{"batb":[[0,9,2.04],[1,8.8,8.9],[2,8.6,4.42]],"ltp":9.2,"tv":291.36,"id":10163711}]}]}
{"op":"mcm","clk":"992570417","pt":1580525929018,"mc":[{"id":"1.168133543","rc":[{"batb":[[0,9,4.26]],"ltp":9.2,"tv":291.36,"id":10163711}]}]}
{"op":"mcm","clk":"992577915","pt":1580526136546,"mc":[{"id":"1.168133543","rc":[{"batb":[[1,8.6,4.42],[2,8.4,6.14]],"ltp":9.2,"tv":291.36,"id":10163711}]}]}
{"op":"mcm","clk":"992577917","pt":1580526136645,"mc":[{"id":"1.168133543","rc":[{"batb":[[0,9,12.96]],"ltp":9.2,"tv":291.36,"id":10163711}]}]}
{"op":"mcm","clk":"992578002","pt":1580526140034,"mc":[{"id":"1.168133543","rc":[{"batb":[[0,9,10.74]],"ltp":9.2,"tv":291.36,"id":10163711}]}]}
{"op":"mcm","clk":"992578448","pt":1580526152679,"mc":[{"id":"1.168133543","rc":[{"batb":[[0,9,2.04],[1,8.8,8.9],[2,8.6,4.42]],"ltp":9.2,"tv":291.36,"id":10163711}]}]}
{"op":"mcm","clk":"992585064","pt":1580526350285,"mc":[{"id":"1.168133543","rc":[{"batb":[[0,9,4.26]],"ltp":9.2,"tv":291.36,"id":10163711}]}]}
{"op":"mcm","clk":"992585356","pt":1580526359505,"mc":[{"id":"1.168133543","rc":[{"batb":[[0,2.88,25.07]],"ltp":2.9,"tv":902.59,"id":12636},{"batb":[[0,9,8.46],[1,8.6,4.42],[2,8.4,6.14]],"ltp":9.2,"tv":291.36,"id":10163711},{"batb":[[0,2.3,15.96],[1,2.26,23.83],[2,2.24,5.28]],"ltp":2.28,"tv":2222.24,"id":10107355}]}]}
{"op":"mcm","clk":"992585359","pt":1580526359609,"mc":[{"id":"1.168133543","rc":[{"batb":[[0,9.2,8.51],[1,9,8.46],[2,8.6,4.42]],"ltp":9.2,"tv":291.36,"id":10163711}]}]}
{"op":"mcm","clk":"992585518","pt":1580526364554,"mc":[{"id":"1.168133543","rc":[{"batb":[[0,9.4,1.86],[1,9.2,8.51],[2,9,6.52]],"ltp":9.2,"tv":291.36,"id":10163711}]}]}
{"op":"mcm","clk":"992585793","pt":1580526372339,"mc":[{"id":"1.168133543","rc":[{"batl":[[0,10,66],[1,17,1.88],[2,29,9.24]],"ltp":9.2,"tv":291.36,"id":10163711}]}]}
{"op":"mcm","clk":"992586501","pt":1580526392470,"mc":[{"id":"1.168133543","rc":[{"batb":[[0,2.3,1.68]],"ltp":2.28,"tv":2222.24,"id":10107355}]}]}
{"op":"mcm","clk":"992586535","pt":1580526393299,"mc":[{"id":"1.168133543","rc":[{"batb":[[0,2.26,23.83],[1,2.24,5.28],[2,2.22,6]],"ltp":2.28,"tv":2222.24,"id":10107355}]}]}
{"op":"mcm","clk":"992586775","pt":1580526400622,"mc":[{"id":"1.168133543","rc":[{"batb":[[0,2.28,1.68],[1,2.26,23.83],[2,2.24,5.28]],"ltp":2.28,"tv":2222.24,"id":10107355}]}]}
{"op":"mcm","clk":"992586828","pt":1580526403512,"mc":[{"id":"1.168133543","rc":[{"batb":[[2,9,4.3]],"ltp":9.2,"tv":291.36,"id":10163711},{"batb":[[1,2.26,32.68]],"ltp":2.28,"tv":2222.24,"id":10107355}]}]}
{"op":"mcm","clk":"992586934","pt":1580526407484,"mc":[{"id":"1.168133543","rc":[{"batb":[[0,2.28,42.92]],"ltp":2.28,"tv":2222.24,"id":10107355}]}]}
{"op":"mcm","clk":"992598556","pt":1580526456807,"mc":[{"id":"1.168133543","rc":[{"batb":[[1,2.26,23.83]],"ltp":2.28,"tv":2222.24,"id":10107355}]}]}
{"op":"mcm","clk":"992602513","pt":1580526558945,"mc":[{"id":"1.168133543","rc":[{"trd":[[2.34,195.13]],"batl":[[0,2.34,23.15]],"ltp":2.34,"tv":2230.24,"id":10107355}],"tv":3756.07}]}
{"op":"mcm","clk":"992610829","pt":1580526790553,"mc":[{"id":"1.168133543","rc":[{"batb":[[0,9.4,5.22],[2,8.6,4.52]],"ltp":9.2,"tv":291.36,"id":10163711},{"trd":[[2.34,220.33]],"batb":[[0,2.32,11.99],[1,2.3,14.28],[2,2.28,42.92]],"batl":[[0,2.34,10.55]],"ltp":2.34,"tv":2255.44,"id":10107355}],"tv":3781.27}]}
{"op":"mcm","clk":"992610858","pt":1580526791479,"mc":[{"id":"1.168133543","rc":[{"batb":[[2,2.28,41.23]],"ltp":2.34,"tv":2255.44,"id":10107355}]}]}
{"op":"mcm","clk":"992610991","pt":1580526795565,"mc":[{"id":"1.168133543","rc":[{"batb":[[1,8.6,4.52],[2,8.4,6.14]],"ltp":9.2,"tv":291.36,"id":10163711},{"batb":[[2,2.26,23.83]],"ltp":2.34,"tv":2255.44,"id":10107355}]}]}
{"op":"mcm","clk":"992611017","pt":1580526796075,"mc":[{"id":"1.168133543","rc":[{"trd":[[2.34,241.42]],"batb":[[0,2.34,29.64],[1,2.32,11.99],[2,2.3,14.28]],"batl":[[0,2.36,49.95],[1,2.38,3.23],[2,2.42,5.5]],"ltp":2.34,"tv":2276.53,"id":10107355}],"tv":3802.36}]}
{"op":"mcm","clk":"992611123","pt":1580526799180,"mc":[{"id":"1.168133543","rc":[{"trd":[[2.36,145.76]],"batl":[[0,2.36,48.27]],"ltp":2.36,"tv":2279.9,"id":10107355}],"tv":3805.72}]}
{"op":"mcm","clk":"992611438","pt":1580526807385,"mc":[{"id":"1.168133543","rc":[{"trd":[[2.36,149.12]],"batl":[[0,2.36,46.59]],"ltp":2.36,"tv":2283.26,"id":10107355}],"tv":3809.08}]}
{"op":"mcm","clk":"992611551","pt":1580526811977,"mc":[{"id":"1.168133543","rc":[{"batb":[[0,2.32,11.99],[1,2.3,14.28],[2,2.26,23.83]],"ltp":2.36,"tv":2283.26,"id":10107355}]}]}
{"op":"mcm","clk":"992611652","pt":1580526815287,"mc":[{"id":"1.168133543","rc":[{"batb":[[0,2.34,2.5],[1,2.32,11.99],[2,2.3,14.28]],"ltp":2.36,"tv":2283.26,"id":10107355}]}]}
{"op":"mcm","clk":"992612640","pt":1580526844425,"mc":[{"id":"1.168133543","rc":[{"batb":[[0,9.4,1.86]],"ltp":9.2,"tv":291.36,"id":10163711},{"batb":[[2,2.26,23.83]],"ltp":2.36,"tv":2283.26,"id":10107355}]}]}
{"op":"mcm","clk":"992612678","pt":1580526845558,"mc":[{"id":"1.168133543","rc":[{"batb":[[1,8.8,9],[2,8.6,4.42]],"ltp":9.2,"tv":291.36,"id":10163711}]}]}
{"op":"mcm","clk":"992612732","pt":1580526847672,"mc":[{"id":"1.168133543","rc":[{"batl":[[0,9.8,3.04],[1,10,66],[2,17,1.88]],"ltp":9.2,"tv":291.36,"id":10163711}]}]}
{"op":"mcm","clk":"992612908","pt":1580526852982,"mc":[{"id":"1.168133543","rc":[{"batb":[[0,9,2.04],[1,8.8,8.9]],"ltp":9.2,"tv":291.36,"id":10163711}]}]}
{"op":"mcm","clk":"992613378","pt":1580526868193,"mc":[{"id":"1.168133543","rc":[{"batb":[[2,8,2.7]],"ltp":10.0,"tv":252.67,"id":22121325}]}]}
{"op":"mcm","clk":"992613413","pt":1580526869177,"mc":[{"id":"1.168133543","rc":[{"batb":[[2,8,4.73]],"ltp":10.0,"tv":252.67,"id":22121325}]}]}
{"op":"mcm","clk":"992613960","pt":1580526887519,"mc":[{"id":"1.168133543","rc":[{"batb":[[0,9,4.26]],"ltp":9.2,"tv":291.36,"id":10163711}]}]}
{"op":"mcm","clk":"992614084","pt":1580526892511,"mc":[{"id":"1.168133543","rc":[{"batb":[[1,8.6,4.42],[2,8.4,6.14]],"ltp":9.2,"tv":291.36,"id":10163711}]}]}
{"op":"mcm","clk":"992614106","pt":1580526893232,"mc":[{"id":"1.168133543","rc":[{"batb":[[0,9,12.96]],"ltp":9.2,"tv":291.36,"id":10163711}]}]}
{"op":"mcm","clk":"992615543","pt":1580526941076,"mc":[{"id":"1.168133543","rc":[{"batb":[[0,9,10.74]],"ltp":9.2,"tv":291.36,"id":10163711}]}]}
{"op":"mcm","clk":"992616147","pt":1580526956482,"mc":[{"id":"1.168133543","rc":[{"batb":[[0,9,2.04]],"ltp":9.2,"tv":291.36,"id":10163711}]}]}
{"op":"mcm","clk":"992616153","pt":1580526956587,"mc":[{"id":"1.168133543","rc":[{"batb":[[1,8.8,8.9],[2,8.6,4.42]],"ltp":9.2,"tv":291.36,"id":10163711}]}]}
{"op":"mcm","clk":"992620436","pt":1580527048486,"mc":[{"id":"1.168133543","rc":[{"batb":[[0,9,4.26]],"ltp":9.2,"tv":291.36,"id":10163711}]}]}
{"op":"mcm","clk":"992620549","pt":1580527051524,"mc":[{"id":"1.168133543","rc":[{"batb":[[1,8.6,4.42],[2,8.4,6.14]],"ltp":9.2,"tv":291.36,"id":10163711}]}]}
{"op":"mcm","clk":"992620553","pt":1580527051630,"mc":[{"id":"1.168133543","rc":[{"batb":[[0,9,12.96]],"ltp":9.2,"tv":291.36,"id":10163711}]}]}
{"op":"mcm","clk":"992620891","pt":1580527060130,"mc":[{"id":"1.168133543","rc":[{"batb":[[2,8,2.03]],"ltp":10.0,"tv":252.67,"id":22121325}]}]}
{"op":"mcm","clk":"992620959","pt":1580527061820,"mc":[{"id":"1.168133543","rc":[{"batb":[[2,8,4.29]],"ltp":10.0,"tv":252.67,"id":22121325}]}]}
{"op":"mcm","clk":"992622560","pt":1580527101379,"mc":[{"id":"1.168133543","rc":[{"batb":[[0,9,10.74]],"ltp":9.2,"tv":291.36,"id":10163711}]}]}
{"op":"mcm","clk":"992623124","pt":1580527116508,"mc":[{"id":"1.168133543","rc":[{"batb":[[0,9,2.04],[1,8.8,8.9],[2,8.6,4.42]],"ltp":9.2,"tv":291.36,"id":10163711}]}]}
{"op":"mcm","clk":"992625921","pt":1580527207482,"mc":[{"id":"1.168133543","rc":[{"batb":[[0,9,4.26]],"ltp":9.2,"tv":291.36,"id":10163711}]}]}
{"op":"mcm","clk":"992626117","pt":1580527212493,"mc":[{"id":"1.168133543","rc":[{"batb":[[1,8.6,4.42],[2,8.4,6.14]],"ltp":9.2,"tv":291.36,"id":10163711}]}]}
{"op":"mcm","clk":"992626123","pt":1580527212594,"mc":[{"id":"1.168133543","rc":[{"batb":[[0,9,12.96]],"ltp":9.2,"tv":291.36,"id":10163711}]}]}
{"op":"mcm","clk":"992627386","pt":1580527260734,"mc":[{"id":"1.168133543","rc":[{"batb":[[0,9,10.74]],"ltp":9.2,"tv":291.36,"id":10163711}]}]}
{"op":"mcm","clk":"992627798","pt":1580527276563,"mc":[{"id":"1.168133543","rc":[{"batb":[[0,9,2.04],[1,8.8,8.9],[2,8.6,4.42]],"ltp":9.2,"tv":291.36,"id":10163711}]}]}
{"op":"mcm","clk":"992640353","pt":1580527367084,"mc":[{"id":"1.168133543","rc":[{"batb":[[0,9,4.26]],"ltp":9.2,"tv":291.36,"id":10163711}]}]}
{"op":"mcm","clk":"992640579","pt":1580527376484,"mc":[{"id":"1.168133543","rc":[{"batb":[[1,8.6,4.42],[2,8.4,6.14]],"ltp":9.2,"tv":291.36,"id":10163711}]}]}
{"op":"mcm","clk":"992640582","pt":1580527376587,"mc":[{"id":"1.168133543","rc":[{"batb":[[0,9,12.96]],"ltp":9.2,"tv":291.36,"id":10163711}]}]}
{"op":"mcm","clk":"992641957","pt":1580527420829,"mc":[{"id":"1.168133543","rc":[{"batb":[[0,9,10.74]],"ltp":9.2,"tv":291.36,"id":10163711}]}]}
{"op":"mcm","clk":"992641992","pt":1580527422526,"mc":[{"id":"1.168133543","rc":[{"batb":[[0,9,2.04]],"ltp":9.2,"tv":291.36,"id":10163711}]}]}
{"op":"mcm","clk":"992642004","pt":1580527422732,"mc":[{"id":"1.168133543","rc":[{"batb":[[1,8.8,8.9],[2,8.6,4.42]],"ltp":9.2,"tv":291.36,"id":10163711}]}]}
{"op":"mcm","clk":"992645263","pt":1580527526963,"mc":[{"id":"1.168133543","rc":[{"batb":[[0,9,4.26]],"ltp":9.2,"tv":291.36,"id":10163711}]}]}
{"op":"mcm","clk":"992645406","pt":1580527532572,"mc":[{"id":"1.168133543","rc":[{"batb":[[1,8.6,4.42],[2,8.4,6.14]],"ltp":9.2,"tv":291.36,"id":10163711}]}]}
{"op":"mcm","clk":"992645425","pt":1580527533496,"mc":[{"id":"1.168133543","rc":[{"batb":[[0,9,12.96]],"ltp":9.2,"tv":291.36,"id":10163711}]}]}
{"op":"mcm","clk":"992646640","pt":1580527580329,"mc":[{"id":"1.168133543","rc":[{"batb":[[0,9,10.74]],"ltp":9.2,"tv":291.36,"id":10163711}]}]}
{"op":"mcm","clk":"992646816","pt":1580527586557,"mc":[{"id":"1.168133543","rc":[{"batb":[[0,9,2.04]],"ltp":9.2,"tv":291.36,"id":10163711}]}]}
{"op":"mcm","clk":"992646838","pt":1580527587022,"mc":[{"id":"1.168133543","rc":[{"batb":[[1,8.8,8.9],[2,8.6,4.42]],"ltp":9.2,"tv":291.36,"id":10163711}]}]}
{"op":"mcm","clk":"992649332","pt":1580527687322,"mc":[{"id":"1.168133543","rc":[{"batb":[[0,9,4.26]],"ltp":9.2,"tv":291.36,"id":10163711}]}]}
{"op":"mcm","clk":"992649366","pt":1580527688509,"mc":[{"id":"1.168133543","rc":[{"batb":[[1,8.6,4.42],[2,8.4,6.14]],"ltp":9.2,"tv":291.36,"id":10163711}]}]}
{"op":"mcm","clk":"992649369","pt":1580527688613,"mc":[{"id":"1.168133543","rc":[{"batb":[[0,9,12.96]],"ltp":9.2,"tv":291.36,"id":10163711}]}]}
{"op":"mcm","clk":"992650215","pt":1580527717256,"mc":[{"id":"1.168133543","rc":[{"batl":[[0,9.6,3.03],[1,9.8,3.04],[2,10,66]],"ltp":9.2,"tv":291.36,"id":10163711}]}]}
{"op":"mcm","clk":"992650234","pt":1580527717767,"mc":[{"id":"1.168133543","rc":[{"batl":[[0,9.8,3.04],[1,10,66],[2,17,1.88]],"ltp":9.2,"tv":291.36,"id":10163711}]}]}
{"op":"mcm","clk":"992651002","pt":1580527741194,"mc":[{"id":"1.168133543","rc":[{"batb":[[0,9,10.74]],"ltp":9.2,"tv":291.36,"id":10163711}]}]}
{"op":"mcm","clk":"992651233","pt":1580527749485,"mc":[{"id":"1.168133543","rc":[{"batb":[[0,9,2.04]],"ltp":9.2,"tv":291.36,"id":10163711}]}]}
{"op":"mcm","clk":"992651241","pt":1580527749690,"mc":[{"id":"1.168133543","rc":[{"batb":[[1,8.8,8.9],[2,8.6,4.42]],"ltp":9.2,"tv":291.36,"id":10163711}]}]}
{"op":"mcm","clk":"992654321","pt":1580527847953,"mc":[{"id":"1.168133543","rc":[{"batb":[[0,9,4.26]],"ltp":9.2,"tv":291.36,"id":10163711}]}]}
{"op":"mcm","clk":"992654855","pt":1580527865472,"mc":[{"id":"1.168133543","rc":[{"batb":[[1,8.6,4.42],[2,8.4,6.14]],"ltp":9.2,"tv":291.36,"id":10163711}]}]}
{"op":"mcm","clk":"992654860","pt":1580527865575,"mc":[{"id":"1.168133543","rc":[{"batb":[[0,9,12.96]],"ltp":9.2,"tv":291.36,"id":10163711}]}]}
{"op":"mcm","clk":"992655815","pt":1580527902542,"mc":[{"id":"1.168133543","rc":[{"batb":[[0,9,10.74]],"ltp":9.2,"tv":291.36,"id":10163711}]}]}
{"op":"mcm","clk":"992655991","pt":1580527911556,"mc":[{"id":"1.168133543","rc":[{"batb":[[0,9,2.04]],"ltp":9.2,"tv":291.36,"id":10163711}]}]}
{"op":"mcm","clk":"992655993","pt":1580527911660,"mc":[{"id":"1.168133543","rc":[{"batb":[[1,8.8,8.9],[2,8.6,4.42]],"ltp":9.2,"tv":291.36,"id":10163711}]}]}
{"op":"mcm","clk":"992658545","pt":1580528009398,"mc":[{"id":"1.168133543","rc":[{"batb":[[0,9,4.26]],"ltp":9.2,"tv":291.36,"id":10163711}]}]}
{"op":"mcm","clk":"992658824","pt":1580528019737,"mc":[{"id":"1.168133543","rc":[{"batb":[[0,9,12.96],[1,8.6,4.42],[2,8.4,6.14]],"ltp":9.2,"tv":291.36,"id":10163711}]}]}
{"op":"mcm","clk":"992659925","pt":1580528062986,"mc":[{"id":"1.168133543","rc":[{"batb":[[0,9,10.74]],"ltp":9.2,"tv":291.36,"id":10163711}]}]}
{"op":"mcm","clk":"992660224","pt":1580528077573,"mc":[{"id":"1.168133543","rc":[{"batb":[[0,9,2.04]],"ltp":9.2,"tv":291.36,"id":10163711}]}]}
{"op":"mcm","clk":"992660244","pt":1580528078393,"mc":[{"id":"1.168133543","rc":[{"batb":[[1,8.8,8.9],[2,8.6,4.42]],"ltp":9.2,"tv":291.36,"id":10163711}]}]}
{"op":"mcm","clk":"992662517","pt":1580528169163,"mc":[{"id":"1.168133543","rc":[{"batb":[[0,9,4.26]],"ltp":9.2,"tv":291.36,"id":10163711}]}]}
{"op":"mcm","clk":"992662925","pt":1580528182507,"mc":[{"id":"1.168133543","rc":[{"batb":[[1,8.6,4.42],[2,8.4,6.14]],"ltp":9.2,"tv":291.36,"id":10163711}]}]}
{"op":"mcm","clk":"992662928","pt":1580528182609,"mc":[{"id":"1.168133543","rc":[{"batb":[[0,9,12.96]],"ltp":9.2,"tv":291.36,"id":10163711}]}]}
{"op":"mcm","clk":"992664083","pt":1580528223131,"mc":[{"id":"1.168133543","rc":[{"batb":[[0,9,10.74]],"ltp":9.2,"tv":291.36,"id":10163711}]}]}
{"op":"mcm","clk":"992664355","pt":1580528230471,"mc":[{"id":"1.168133543","rc":[{"batb":[[0,9,2.04]],"ltp":9.2,"tv":291.36,"id":10163711}]}]}
{"op":"mcm","clk":"992664358","pt":1580528230575,"mc":[{"id":"1.168133543","rc":[{"batb":[[1,8.8,8.9],[2,8.6,4.42]],"ltp":9.2,"tv":291.36,"id":10163711}]}]}
{"op":"mcm","clk":"992677026","pt":1580528330478,"mc":[{"id":"1.168133543","rc":[{"batb":[[0,9,4.26],[1,8.6,4.42],[2,8.4,6.14]],"ltp":9.2,"tv":291.36,"id":10163711}]}]}
{"op":"mcm","clk":"992677030","pt":1580528330579,"mc":[{"id":"1.168133543","rc":[{"batb":[[0,9,12.96]],"ltp":9.2,"tv":291.36,"id":10163711}]}]}
{"op":"mcm","clk":"992678298","pt":1580528383189,"mc":[{"id":"1.168133543","rc":[{"batb":[[0,9,10.74]],"ltp":9.2,"tv":291.36,"id":10163711}]}]}
{"op":"mcm","clk":"992678651","pt":1580528394571,"mc":[{"id":"1.168133543","rc":[{"batb":[[0,9,2.04]],"ltp":9.2,"tv":291.36,"id":10163711}]}]}
{"op":"mcm","clk":"992678670","pt":1580528394980,"mc":[{"id":"1.168133543","rc":[{"batb":[[1,8.8,8.9],[2,8.6,4.42]],"ltp":9.2,"tv":291.36,"id":10163711}]}]}
{"op":"mcm","clk":"992681869","pt":1580528489835,"mc":[{"id":"1.168133543","rc":[{"batb":[[0,9,4.26]],"ltp":9.2,"tv":291.36,"id":10163711}]}]}
{"op":"mcm","clk":"992682428","pt":1580528505537,"mc":[{"id":"1.168133543","rc":[{"batb":[[1,8.6,4.42],[2,8.4,6.14]],"ltp":9.2,"tv":291.36,"id":10163711}]}]}
{"op":"mcm","clk":"992682434","pt":1580528505639,"mc":[{"id":"1.168133543","rc":[{"batb":[[0,9,12.96]],"ltp":9.2,"tv":291.36,"id":10163711}]}]}
{"op":"mcm","clk":"992683760","pt":1580528543288,"mc":[{"id":"1.168133543","rc":[{"batb":[[0,9,10.74]],"ltp":9.2,"tv":291.36,"id":10163711}]}]}
{"op":"mcm","clk":"992684108","pt":1580528553902,"mc":[{"id":"1.168133543","rc":[{"batb":[[0,9,2.04],[1,8.8,8.9],[2,8.6,4.42]],"ltp":9.2,"tv":291.36,"id":10163711}]}]}
{"op":"mcm","clk":"992687407","pt":1580528649315,"mc":[{"id":"1.168133543","rc":[{"batb":[[0,9,4.26]],"ltp":9.2,"tv":291.36,"id":10163711}]}]}
{"op":"mcm","clk":"992688003","pt":1580528664703,"mc":[{"id":"1.168133543","rc":[{"batb":[[0,9,12.96],[1,8.6,4.42],[2,8.4,6.14]],"ltp":9.2,"tv":291.36,"id":10163711}]}]}
{"op":"mcm","clk":"992689463","pt":1580528703165,"mc":[{"id":"1.168133543","rc":[{"batb":[[0,9,10.74]],"ltp":9.2,"tv":291.36,"id":10163711}]}]}
{"op":"mcm","clk":"992689839","pt":1580528712568,"mc":[{"id":"1.168133543","rc":[{"batb":[[0,9,2.04],[1,8.8,8.9],[2,8.6,4.42]],"ltp":9.2,"tv":291.36,"id":10163711}]}]}
{"op":"mcm","clk":"992694161","pt":1580528810099,"mc":[{"id":"1.168133543","rc":[{"batb":[[0,9,4.26]],"ltp":9.2,"tv":291.36,"id":10163711}]}]}
{"op":"mcm","clk":"992695124","pt":1580528823525,"mc":[{"id":"1.168133543","rc":[{"batb":[[1,8.6,4.42],[2,8.4,6.14]],"ltp":9.2,"tv":291.36,"id":10163711}]}]}
{"op":"mcm","clk":"992695135","pt":1580528823629,"mc":[{"id":"1.168133543","rc":[{"batb":[[0,9,12.96]],"ltp":9.2,"tv":291.36,"id":10163711}]}]}
{"op":"mcm","clk":"992696661","pt":1580528863406,"mc":[{"id":"1.168133543","rc":[{"batb":[[0,9,10.74]],"ltp":9.2,"tv":291.36,"id":10163711}]}]}
{"op":"mcm","clk":"992696978","pt":1580528871874,"mc":[{"id":"1.168133543","rc":[{"batb":[[0,9,2.04],[1,8.8,8.9],[2,8.6,4.42]],"ltp":9.2,"tv":291.36,"id":10163711}]}]}
{"op":"mcm","clk":"992699104","pt":1580528930198,"mc":[{"id":"1.168133543","rc":[{"batb":[[0,2.88,19.19]],"ltp":2.9,"tv":902.59,"id":12636}]}]}
{"op":"mcm","clk":"992700775","pt":1580528970516,"mc":[{"id":"1.168133543","rc":[{"batb":[[0,9,4.26]],"ltp":9.2,"tv":291.36,"id":10163711}]}]}
{"op":"mcm","clk":"992701368","pt":1580528983553,"mc":[{"id":"1.168133543","rc":[{"batb":[[1,8.6,4.42],[2,8.4,6.14]],"ltp":9.2,"tv":291.36,"id":10163711}]}]}
{"op":"mcm","clk":"992701374","pt":1580528983657,"mc":[{"id":"1.168133543","rc":[{"batb":[[0,9,12.96]],"ltp":9.2,"tv":291.36,"id":10163711}]}]}
{"op":"mcm","clk":"992703370","pt":1580529023426,"mc":[{"id":"1.168133543","rc":[{"batb":[[0,9,10.74]],"ltp":9.2,"tv":291.36,"id":10163711}]}]}
{"op":"mcm","clk":"992703700","pt":1580529030495,"mc":[{"id":"1.168133543","rc":[{"batb":[[0,9,2.04]],"ltp":9.2,"tv":291.36,"id":10163711}]}]}
{"op":"mcm","clk":"992703704","pt":1580529030597,"mc":[{"id":"1.168133543","rc":[{"batb":[[1,8.8,8.9],[2,8.6,4.42]],"ltp":9.2,"tv":291.36,"id":10163711}]}]}
{"op":"mcm","clk":"992707764","pt":1580529131564,"mc":[{"id":"1.168133543","rc":[{"batb":[[0,9,4.26],[1,8.6,4.42],[2,8.4,6.14]],"ltp":9.2,"tv":291.36,"id":10163711}]}]}
{"op":"mcm","clk":"992707776","pt":1580529132026,"mc":[{"id":"1.168133543","rc":[{"batb":[[0,9,12.96]],"ltp":9.2,"tv":291.36,"id":10163711}]}]}
{"op":"mcm","clk":"992719120","pt":1580529178408,"mc":[{"id":"1.168133543","rc":[{"batb":[[2,8,2.03]],"ltp":10.0,"tv":252.67,"id":22121325}]}]}
{"op":"mcm","clk":"992719288","pt":1580529184430,"mc":[{"id":"1.168133543","rc":[{"batb":[[0,9,10.74]],"ltp":9.2,"tv":291.36,"id":10163711}]}]}
{"op":"mcm","clk":"992719423","pt":1580529188539,"mc":[{"id":"1.168133543","rc":[{"batb":[[0,9,2.04]],"ltp":9.2,"tv":291.36,"id":10163711}]}]}
{"op":"mcm","clk":"992719428","pt":1580529188642,"mc":[{"id":"1.168133543","rc":[{"batb":[[1,8.8,8.9],[2,8.6,4.42]],"ltp":9.2,"tv":291.36,"id":10163711}]}]}
{"op":"mcm","clk":"992720217","pt":1580529216441,"mc":[{"id":"1.168133543","rc":[{"batb":[[2,7.8,2.56]],"ltp":10.0,"tv":252.67,"id":22121325}]}]}
{"op":"mcm","clk":"992720271","pt":1580529218036,"mc":[{"id":"1.168133543","rc":[{"batb":[[2,7.8,4.29]],"ltp":10.0,"tv":252.67,"id":22121325}]}]}
{"op":"mcm","clk":"992722713","pt":1580529291621,"mc":[{"id":"1.168133543","rc":[{"batb":[[0,9,4.26]],"ltp":9.2,"tv":291.36,"id":10163711}]}]}
{"op":"mcm","clk":"992722955","pt":1580529301552,"mc":[{"id":"1.168133543","rc":[{"batb":[[0,9,12.96],[1,8.6,4.42],[2,8.4,6.14]],"ltp":9.2,"tv":291.36,"id":10163711}]}]}
{"op":"mcm","clk":"992724291","pt":1580529345224,"mc":[{"id":"1.168133543","rc":[{"batb":[[0,9,10.74]],"ltp":9.2,"tv":291.36,"id":10163711}]}]}
{"op":"mcm","clk":"992724557","pt":1580529349498,"mc":[{"id":"1.168133543","rc":[{"batb":[[0,9,2.04]],"ltp":9.2,"tv":291.36,"id":10163711}]}]}
{"op":"mcm","clk":"992724584","pt":1580529350314,"mc":[{"id":"1.168133543","rc":[{"batb":[[0,8.8,13.26]],"ltp":9.2,"tv":291.36,"id":10163711}]}]}
{"op":"mcm","clk":"992725139","pt":1580529367319,"mc":[{"id":"1.168133543","rc":[{"batb":[[0,8.8,10.99]],"ltp":9.2,"tv":291.36,"id":10163711}]}]}
{"op":"mcm","clk":"992726171","pt":1580529398477,"mc":[{"id":"1.168133543","rc":[{"batl":[[0,9.6,2],[1,9.8,3.04],[2,10,66]],"ltp":9.2,"tv":291.36,"id":10163711}]}]}
{"op":"mcm","clk":"992727829","pt":1580529451552,"mc":[{"id":"1.168133543","rc":[{"batb":[[0,9,2.32],[1,8.8,10.89],[2,8.6,4.42]],"ltp":9.2,"tv":291.36,"id":10163711}]}]}
{"op":"mcm","clk":"992727908","pt":1580529454368,"mc":[{"id":"1.168133543","rc":[{"batb":[[0,9.2,1.9],[1,9,2.32],[2,8.8,8.9]],"ltp":9.2,"tv":291.36,"id":10163711}]}]}
{"op":"mcm","clk":"992728241","pt":1580529465571,"mc":[{"id":"1.168133543","rc":[{"batb":[[1,9,11.02],[2,8.6,4.42]],"ltp":9.2,"tv":291.36,"id":10163711}]}]}
{"op":"mcm","clk":"992729578","pt":1580529505254,"mc":[{"id":"1.168133543","rc":[{"batb":[[1,9,8.8]],"batl":[[0,9.8,3.04],[1,10,66],[2,17,1.88]],"ltp":9.2,"tv":291.36,"id":10163711}]}]}
{"op":"mcm","clk":"992729860","pt":1580529513478,"mc":[{"id":"1.168133543","rc":[{"batb":[[1,8.6,4.52],[2,8.4,6.14]],"ltp":9.2,"tv":291.36,"id":10163711}]}]}
{"op":"mcm","clk":"992729866","pt":1580529513581,"mc":[{"id":"1.168133543","rc":[{"batb":[[1,8.8,9],[2,8.6,4.42]],"ltp":9.2,"tv":291.36,"id":10163711}]}]}
{"op":"mcm","clk":"992730639","pt":1580529534243,"mc":[{"id":"1.168133543","rc":[{"batb":[[0,9,2.04],[1,8.8,8.9]],"ltp":9.2,"tv":291.36,"id":10163711}]}]}
{"op":"mcm","clk":"992733900","pt":1580529611368,"mc":[{"id":"1.168133543","rc":[{"batb":[[0,9,4.26]],"ltp":9.2,"tv":291.36,"id":10163711}]}]}
{"op":"mcm","clk":"992733996","pt":1580529613478,"mc":[{"id":"1.168133543","rc":[{"batb":[[1,8.6,4.42],[2,8.4,6.14]],"ltp":9.2,"tv":291.36,"id":10163711}]}]}
{"op":"mcm","clk":"992734013","pt":1580529613784,"mc":[{"id":"1.168133543","rc":[{"batb":[[0,9,12.96]],"ltp":9.2,"tv":291.36,"id":10163711}]}]}
{"op":"mcm","clk":"992736283","pt":1580529664500,"mc":[{"id":"1.168133543","rc":[{"batb":[[0,9,10.74]],"ltp":9.2,"tv":291.36,"id":10163711}]}]}
{"op":"mcm","clk":"992736809","pt":1580529673485,"mc":[{"id":"1.168133543","rc":[{"batb":[[0,9,2.04]],"ltp":9.2,"tv":291.36,"id":10163711}]}]}
{"op":"mcm","clk":"992736815","pt":1580529673588,"mc":[{"id":"1.168133543","rc":[{"batb":[[1,8.8,8.9],[2,8.6,4.42]],"ltp":9.2,"tv":291.36,"id":10163711}]}]}
{"op":"mcm","clk":"992749199","pt":1580529980341,"mc":[{"id":"1.168133543","rc":[{"batb":[[0,9,4.26]],"ltp":9.2,"tv":291.36,"id":10163711}]}]}
{"op":"mcm","clk":"992749289","pt":1580529982710,"mc":[{"id":"1.168133543","rc":[{"batb":[[0,9,12.96],[1,8.6,4.42],[2,8.4,6.14]],"ltp":9.2,"tv":291.36,"id":10163711}]}]}
{"op":"mcm","clk":"992751015","pt":1580530034219,"mc":[{"id":"1.168133543","rc":[{"trd":[[2.88,89.7]],"batb":[[0,2.88,9.18]],"ltp":2.88,"tv":922.6,"id":12636},{"batb":[[0,9,10.74]],"ltp":9.2,"tv":291.36,"id":10163711}],"tv":3829.08}]}
{"op":"mcm","clk":"992751041","pt":1580530035146,"mc":[{"id":"1.168133543","rc":[{"trd":[[2.88,99.7]],"batb":[[0,2.88,4.18]],"ltp":2.88,"tv":932.6,"id":12636}],"tv":3839.08}]}
{"op":"mcm","clk":"992751087","pt":1580530036530,"mc":[{"id":"1.168133543","rc":[{"trd":[[2.88,108.06]],"batb":[[0,2.8,2.2],[1,2.76,2.13],[2,2.6,2.52]],"batl":[[0,2.9,32.37]],"ltp":2.88,"tv":940.96,"id":12636},{"batb":[[0,9,2.04],[1,8.8,8.9],[2,8.6,4.42]],"ltp":9.2,"tv":291.36,"id":10163711}],"tv":3847.45}]}
{"op":"mcm","clk":"992751164","pt":1580530038542,"mc":[{"id":"1.168133543","rc":[{"batl":[[0,2.88,5.82],[1,2.9,31.55],[2,2.92,50]],"ltp":2.88,"tv":940.96,"id":12636}]}]}
{"op":"mcm","clk":"992751298","pt":1580530042965,"mc":[{"id":"1.168133543","rc":[{"batl":[[0,2.88,10.82]],"ltp":2.88,"tv":940.96,"id":12636}]}]}
{"op":"mcm","clk":"992763122","pt":1580530086761,"mc":[{"id":"1.168133543","rc":[{"batb":[[1,2.78,7.19],[2,2.76,2.13]],"ltp":2.88,"tv":940.96,"id":12636}]}]}
{"op":"mcm","clk":"992766617","pt":1580530139502,"mc":[{"id":"1.168133543","rc":[{"batb":[[0,9,4.26]],"ltp":9.2,"tv":291.36,"id":10163711}]}]}
{"op":"mcm","clk":"992766843","pt":1580530143518,"mc":[{"id":"1.168133543","rc":[{"batb":[[0,9,12.96],[1,8.6,4.42],[2,8.4,6.14]],"ltp":9.2,"tv":291.36,"id":10163711}]}]}
{"op":"mcm","clk":"992769631","pt":1580530192592,"mc":[{"id":"1.168133543","rc":[{"batb":[[0,9,10.74]],"ltp":9.2,"tv":291.36,"id":10163711}]}]}
{"op":"mcm","clk":"992770117","pt":1580530202025,"mc":[{"id":"1.168133543","rc":[{"batb":[[0,2.8,4.72]],"ltp":2.88,"tv":940.96,"id":12636}]}]}
{"op":"mcm","clk":"992770274","pt":1580530204998,"mc":[{"id":"1.168133543","rc":[{"batl":[[1,2.38,5.23]],"ltp":2.36,"tv":2283.26,"id":10107355}]}]}
{"op":"mcm","clk":"992774424","pt":1580530294483,"mc":[{"id":"1.168133543","rc":[{"batb":[[0,2.8,76.16]],"ltp":2.88,"tv":940.96,"id":12636},{"batb":[[0,9,2.04],[1,8.8,8.9],[2,8.6,4.42]],"ltp":9.2,"tv":291.36,"id":10163711}]}]}
{"op":"mcm","clk":"992774642","pt":1580530298547,"mc":[{"id":"1.168133543","rc":[{"batb":[[1,2.76,2.13],[2,2.58,1.98]],"ltp":2.88,"tv":940.96,"id":12636},{"batb":[[0,9,4.26]],"ltp":9.2,"tv":291.36,"id":10163711}]}]}
{"op":"mcm","clk":"992775239","pt":1580530310552,"mc":[{"id":"1.168133543","rc":[{"batb":[[0,2.8,4.72],[2,2.58,79.51]],"ltp":2.88,"tv":940.96,"id":12636},{"batb":[[0,9,12.96],[1,8.6,4.42],[2,8.4,6.14]],"ltp":9.2,"tv":291.36,"id":10163711},{"batb":[[0,10,16.69],[1,9.8,4.97],[2,8.4,8.13]],"ltp":10.0,"tv":252.67,"id":22121325}]}]}
{"op":"mcm","clk":"992775358","pt":1580530313447,"mc":[{"id":"1.168133543","rc":[{"trd":[[9,63.74]],"batb":[[0,9,2.89]],"ltp":9.0,"tv":311.52,"id":10163711}],"tv":3867.6}]}
{"op":"mcm","clk":"992775652","pt":1580530319250,"mc":[{"id":"1.168133543","rc":[{"batl":[[0,9.8,3.14]],"ltp":9.0,"tv":311.52,"id":10163711}]}]}
{"op":"mcm","clk":"992775850","pt":1580530322053,"mc":[{"id":"1.168133543","rc":[{"batb":[[0,2.8,2.2],[1,2.78,2.52],[2,2.76,2.13]],"ltp":2.88,"tv":940.96,"id":12636}]}]}
{"op":"mcm","clk":"992776057","pt":1580530326490,"mc":[{"id":"1.168133543","rc":[{"batb":[[0,8.6,10.94],[1,8.4,6.14],[2,8.2,94.45]],"ltp":9.0,"tv":311.52,"id":10163711}]}]}
{"op":"mcm","clk":"992776227","pt":1580530330060,"mc":[{"id":"1.168133543","rc":[{"batl":[[1,2.38,3.23]],"ltp":2.36,"tv":2283.26,"id":10107355}]}]}
{"op":"mcm","clk":"992776717","pt":1580530342525,"mc":[{"id":"1.168133543","rc":[{"batb":[[0,8.6,7.91]],"ltp":9.0,"tv":311.52,"id":10163711}]}]}
{"op":"mcm","clk":"992776730","pt":1580530342684,"mc":[{"id":"1.168133543","rc":[{"batb":[[0,8.8,2.95],[1,8.6,7.91],[2,8.4,6.14]],"ltp":9.0,"tv":311.52,"id":10163711}]}]}
{"op":"mcm","clk":"992777048","pt":1580530351508,"mc":[{"id":"1.168133543","rc":[{"batl":[[0,9.6,2.09],[1,9.8,3.04],[2,10,66]],"ltp":9.0,"tv":311.52,"id":10163711}]}]}
{"op":"mcm","clk":"992859422","pt":1580531905835,"mc":[{"id":"1.168133543","rc":[{"trd":[[2.36,149.16]],"batl":[[0,2.36,46.57]],"ltp":2.36,"tv":2283.3,"id":10107355}],"tv":3867.65}]}
{"op":"mcm","clk":"992872683","pt":1580532288558,"mc":[{"id":"1.168133543","rc":[{"trd":[[2.88,129.7]],"batl":[[0,2.9,31.55],[1,2.92,50],[2,2.94,58.02]],"ltp":2.88,"tv":962.6,"id":12636},{"trd":[[190,0.2]],"batl":[[0,200,2.13]],"ltp":190.0,"tv":11.81,"id":22308007},{"trd":[[60,10.62]],"batl":[[0,60,3.49]],"ltp":60.0,"tv":24.77,"id":7226819},{"trd":[[9.6,15.63],[9.8,14.02]],"batl":[[0,10,66],[1,17,1.88],[2,29,9.24]],"ltp":9.8,"tv":321.8,"id":10163711},{"trd":[[2.34,273.04]],"batb":[[0,2.26,23.83],[1,2.24,5.28],[2,2.22,6]],"batl":[[0,2.34,22.19],[1,2.36,46.57],[2,2.38,3.23]],"ltp":2.34,"tv":2314.91,"id":10107355},{"trd":[[11,29.9],[11.5,43.96]],"batl":[[0,11.5,3.08],[1,12,3],[2,16.5,2.26]],"ltp":11.5,"tv":258.24,"id":22121325},{"trd":[[160,0.4]],"batl":[[0,160,3.8]],"ltp":160.0,"tv":5.76,"id":26548208}],"tv":3938.38}]}
{"op":"mcm","clk":"992872716","pt":1580532289438,"mc":[{"id":"1.168133543","rc":[{"batb":[[2,8.4,9.14]],"ltp":9.8,"tv":321.8,"id":10163711},{"batb":[[2,8.4,5.13]],"ltp":11.5,"tv":258.24,"id":22121325}]}]}
{"op":"mcm","clk":"992872877","pt":1580532294487,"mc":[{"id":"1.168133543","rc":[{"batb":[[0,65,1.25],[1,60,1.33],[2,55,3.09]],"batl":[[0,200,2.33]],"ltp":190.0,"tv":11.81,"id":22308007},{"batb":[[0,8.8,3.05]],"ltp":9.8,"tv":321.8,"id":10163711}]}]}
{"op":"mcm","clk":"992873072","pt":1580532300372,"mc":[{"id":"1.168133543","rc":[{"batl":[[0,2.88,4],[1,2.9,31.55],[2,2.92,50]],"ltp":2.88,"tv":962.6,"id":12636}]}]}
{"op":"mcm","clk":"992873285","pt":1580532305189,"mc":[{"id":"1.168133543","rc":[{"batl":[[0,2.88,9]],"ltp":2.88,"tv":962.6,"id":12636}]}]}
{"op":"mcm","clk":"992873335","pt":1580532306692,"mc":[{"id":"1.168133543","rc":[{"batl":[[0,2.88,14]],"ltp":2.88,"tv":962.6,"id":12636}]}]}
{"op":"mcm","clk":"992873743","pt":1580532317501,"mc":[{"id":"1.168133543","rc":[{"batl":[[0,2.88,10]],"ltp":2.88,"tv":962.6,"id":12636},{"batb":[[2,55,1.07]],"ltp":190.0,"tv":11.81,"id":22308007}]}]}
{"op":"mcm","clk":"992873755","pt":1580532317807,"mc":[{"id":"1.168133543","rc":[{"batb":[[0,9,2.23],[1,8.8,2.95],[2,8.6,7.91]],"ltp":9.8,"tv":321.8,"id":10163711},{"batb":[[0,2.26,32.68]],"ltp":2.34,"tv":2314.91,"id":10107355}]}]}
{"op":"mcm","clk":"992876127","pt":1580532376450,"mc":[{"id":"1.168133543","rc":[{"batb":[[0,65,3.27]],"ltp":190.0,"tv":11.81,"id":22308007}]}]}
{"op":"mcm","clk":"992877203","pt":1580532395031,"mc":[{"id":"1.168133543","rc":[{"trd":[[10,39.04]],"batb":[[0,9.8,4.97],[1,8.4,5.13],[2,8,3.11]],"batl":[[0,10,38.29],[1,11.5,3.08],[2,12,3]],"ltp":10.0,"tv":291.64,"id":22121325}],"tv":3971.78}]}
{"op":"mcm","clk":"992877250","pt":1580532396423,"mc":[{"id":"1.168133543","rc":[{"batb":[[1,8.4,8.13]],"ltp":10.0,"tv":291.64,"id":22121325}]}]}
{"op":"mcm","clk":"992877327","pt":1580532399199,"mc":[{"id":"1.168133543","rc":[{"trd":[[9.8,9.59]],"batb":[[0,8.4,8.31],[1,8,3.11],[2,6.2,11.64]],"ltp":9.8,"tv":301.23,"id":22121325}],"tv":3981.36}]}
{"op":"mcm","clk":"992877813","pt":1580532410518,"mc":[{"id":"1.168133543","rc":[{"trd":[[2.88,149.7],[2.9,137.88],[2.92,142.88]],"batb":[[0,2.88,8.03],[1,2.8,2.2],[2,2.78,2.52]],"batl":[[0,2.92,41.07],[1,2.94,58.02],[2,2.96,50]],"ltp":2.92,"tv":1063.56,"id":12636},{"batb":[[0,85,1.12],[1,65,2.73],[2,60,1.33]],"ltp":190.0,"tv":11.81,"id":22308007},{"trd":[[60,12.36]],"batl":[[0,60,2.62]],"ltp":60.0,"tv":26.51,"id":7226819},{"trd":[[10,24.16]],"batb":[[0,9.2,5.64],[1,9,2.23],[2,8.8,2.95]],"batl":[[0,10,54.24]],"ltp":10.0,"tv":345.32,"id":10163711},{"trd":[[2.34,317.42],[2.36,242.3],[2.38,136.45]],"batb":[[0,2.28,12.15],[1,2.26,32.68],[2,2.24,5.28]],"batl":[[0,2.42,5.51],[1,2.46,21],[2,2.48,50]],"ltp":2.38,"tv":2458.89,"id":10107355},{"trd":[[10,72.94]],"batl":[[0,10,21.34]],"ltp":10.0,"tv":335.13,"id":22121325},{"batb":[[0,85,3.06]],"ltp":160.0,"tv":5.76,"id":26548208},{"batb":[[0,220,1.04],[1,130,2.13],[2,110,1.02]],"ltp":580.0,"tv":6.13,"id":27606066},{"batb":[[0,230,1.32]],"ltp":280.0,"tv":1.54,"id":24270700},{"batb":[[0,150,1.51]],"ltp":160.0,"tv":19.01,"id":13306150}],"tv":4285.46}]}
{"op":"mcm","clk":"992877834","pt":1580532410826,"mc":[{"id":"1.168133543","rc":[{"trd":[[190,0.46],[200,0.96]],"batl":[[0,200,1.72]],"ltp":200.0,"tv":12.63,"id":22308007},{"trd":[[60,16.28]],"batl":[[0,510,9.83],[1,550,2],[2,550,0]],"ltp":60.0,"tv":30.43,"id":7226819},{"trd":[[160,1.86]],"batl":[[0,160,3.07]],"ltp":160.0,"tv":7.22,"id":26548208}],"tv":4291.66}]}
{"op":"mcm","clk":"992877952","pt":1580532412432,"mc":[{"id":"1.168133543","rc":[{"batl":[[0,510,9.88]],"ltp":60.0,"tv":30.43,"id":7226819}]}]}
{"op":"mcm","clk":"992878150","pt":1580532416043,"mc":[{"id":"1.168133543","rc":[{"batb":[[0,65,3.55],[1,60,1.33],[2,55,1.07]],"ltp":200.0,"tv":12.63,"id":22308007},{"batb":[[0,85,2.41]],"ltp":160.0,"tv":7.22,"id":26548208}]}]}
{"op":"mcm","clk":"992878411","pt":1580532422348,"mc":[{"id":"1.168133543","rc":[{"batb":[[0,2.9,2.52],[1,2.88,8.03],[2,2.8,2.2]],"ltp":2.92,"tv":1063.56,"id":12636},{"batb":[[0,90,1.33],[1,65,2.97],[2,60,1.33]],"ltp":200.0,"tv":12.63,"id":22308007}]}]}
{"op":"mcm","clk":"992878485","pt":1580532424466,"mc":[{"id":"1.168133543","rc":[{"batb":[[0,90,1.54],[1,65,2.73]],"ltp":200.0,"tv":12.63,"id":22308007},{"batb":[[0,2.28,20.92],[1,2.26,23.83]],"ltp":2.38,"tv":2458.89,"id":10107355}]}]}
{"op":"mcm","clk":"992878496","pt":1580532424725,"mc":[{"id":"1.168133543","rc":[{"batb":[[0,9.4,2.04],[1,9.2,5.64],[2,8.8,3.05]],"ltp":10.0,"tv":345.32,"id":10163711}]}]}
{"op":"mcm","clk":"992878547","pt":1580532426528,"mc":[{"id":"1.168133543","rc":[{"trd":[[2.9,142.92]],"batb":[[0,2.88,8.03],[1,2.8,2.2],[2,2.76,2.13]],"batl":[[0,2.9,2.48],[1,2.92,41.07],[2,2.94,58.02]],"ltp":2.9,"tv":1068.6,"id":12636}],"tv":4296.7}]}
{"op":"mcm","clk":"992878725","pt":1580532431161,"mc":[{"id":"1.168133543","rc":[{"batb":[[2,6.4,11.01]],"ltp":10.0,"tv":335.13,"id":22121325}]}]}
{"op":"mcm","clk":"992878777","pt":1580532432961,"mc":[{"id":"1.168133543","rc":[{"batl":[[0,2.9,6.48]],"ltp":2.9,"tv":1068.6,"id":12636},{"batl":[[0,9.8,4],[1,10,54.24],[2,17,1.88]],"ltp":10.0,"tv":345.32,"id":10163711},{"batl":[[0,2.4,4.01],[1,2.42,5.5],[2,2.46,21]],"ltp":2.38,"tv":2458.89,"id":10107355}]}]}
{"op":"mcm","clk":"992879013","pt":1580532439551,"mc":[{"id":"1.168133543","rc":[{"batl":[[0,2.9,4]],"ltp":2.9,"tv":1068.6,"id":12636}]}]}
{"op":"mcm","clk":"992879016","pt":1580532439654,"mc":[{"id":"1.168133543","rc":[{"trd":[[2.88,154.66]],"batb":[[0,2.88,5.55]],"ltp":2.88,"tv":1073.56,"id":12636}],"tv":4301.66}]}
{"op":"mcm","clk":"992880402","pt":1580532478088,"mc":[{"id":"1.168133543","rc":[{"batb":[[1,2.82,7.09],[2,2.8,2.2]],"ltp":2.88,"tv":1073.56,"id":12636}]}]}
{"op":"mcm","clk":"992880576","pt":1580532482213,"mc":[{"id":"1.168133543","rc":[{"batb":[[1,2.84,1.44],[2,2.82,7.09]],"ltp":2.88,"tv":1073.56,"id":12636}]}]}
{"op":"mcm","clk":"992882863","pt":1580532532751,"mc":[{"id":"1.168133543","rc":[{"batb":[[2,2.8,2.2]],"ltp":2.88,"tv":1073.56,"id":12636}]}]}
{"op":"mcm","clk":"992883362","pt":1580532543820,"mc":[{"id":"1.168133543","rc":[{"batb":[[0,2.3,7.49],[1,2.28,20.92],[2,2.26,23.83]],"ltp":2.38,"tv":2458.89,"id":10107355}]}]}
{"op":"mcm","clk":"992885333","pt":1580532588035,"mc":[{"id":"1.168133543","rc":[{"batb":[[1,8,1.64]],"ltp":10.0,"tv":335.13,"id":22121325}]}]}
{"op":"mcm","clk":"992885421","pt":1580532589947,"mc":[{"id":"1.168133543","rc":[{"batb":[[2,6.4,12.76]],"ltp":10.0,"tv":335.13,"id":22121325}]}]}
{"op":"mcm","clk":"992887288","pt":1580532643329,"mc":[{"id":"1.168133543","rc":[{"trd":[[8.4,3.38],[9.2,0.26],[9.8,9.94]],"batb":[[0,8.4,6.31]],"ltp":8.4,"tv":339.13,"id":22121325}],"tv":4305.66}]}
{"op":"mcm","clk":"992887311","pt":1580532643905,"mc":[{"id":"1.168133543","rc":[{"batb":[[0,8.4,3.31],[2,7.4,3.64]],"ltp":8.4,"tv":339.13,"id":22121325}]}]}
{"op":"mcm","clk":"992887617","pt":1580532651013,"mc":[{"id":"1.168133543","rc":[{"batb":[[0,8.4,3.5]],"batl":[[0,10,21.47]],"ltp":8.4,"tv":339.13,"id":22121325}]}]}
{"op":"mcm","clk":"992887842","pt":1580532655450,"mc":[{"id":"1.168133543","rc":[{"batb":[[1,7.4,3.64],[2,6.4,12.12]],"ltp":8.4,"tv":339.13,"id":22121325}]}]}
{"op":"mcm","clk":"992887925","pt":1580532656749,"mc":[{"id":"1.168133543","rc":[{"batb":[[2,6.4,14.06]],"ltp":8.4,"tv":339.13,"id":22121325}]}]}
{"op":"mcm","clk":"992888216","pt":1580532662837,"mc":[{"id":"1.168133543","rc":[{"batb":[[2,6.6,3]],"ltp":8.4,"tv":339.13,"id":22121325}]}]}
{"op":"mcm","clk":"992904802","pt":1580532832789,"mc":[{"id":"1.168133543","rc":[{"batb":[[0,50,3.38],[1,48,3.08],[2,46,1.95]],"ltp":60.0,"tv":30.43,"id":7226819},{"batb":[[2,8.6,8.01]],"ltp":10.0,"tv":345.32,"id":10163711},{"batb":[[0,2.3,37.64]],"ltp":2.38,"tv":2458.89,"id":10107355},{"batb":[[1,140,1.84],[2,110,1.17]],"ltp":580.0,"tv":6.13,"id":27606066},{"batb":[[0,230,2.42],[1,180,1.03],[2,170,3.21]],"ltp":280.0,"tv":1.54,"id":24270700},{"batb":[[1,140,1.23]],"ltp":160.0,"tv":19.01,"id":13306150}]}]}
{"op":"mcm","clk":"992904880","pt":1580532835206,"mc":[{"id":"1.168133543","rc":[{"batb":[[2,8.8,2.37]],"batl":[[0,10,54.24],[1,17,1.88],[2,29,9.24]],"ltp":10.0,"tv":345.32,"id":10163711},{"batl":[[0,2.42,5.51],[1,2.46,21],[2,2.48,50]],"ltp":2.38,"tv":2458.89,"id":10107355}]}]}
{"op":"mcm","clk":"992905145","pt":1580532842525,"mc":[{"id":"1.168133543","rc":[{"batb":[[2,46,1.08]],"ltp":60.0,"tv":30.43,"id":7226819}]}]}
{"op":"mcm","clk":"992905162","pt":1580532842937,"mc":[{"id":"1.168133543","rc":[{"batb":[[0,50,4.18]],"ltp":60.0,"tv":30.43,"id":7226819}]}]}
{"op":"mcm","clk":"992905461","pt":1580532851046,"mc":[{"id":"1.168133543","rc":[{"batb":[[0,2.3,46.34],[1,2.28,12.15]],"ltp":2.38,"tv":2458.89,"id":10107355},{"batb":[[1,140,1.97],[2,110,1.02]],"ltp":580.0,"tv":6.13,"id":27606066}]}]}
{"op":"mcm","clk":"992905565","pt":1580532853846,"mc":[{"id":"1.168133543","rc":[{"batb":[[0,2.32,29.89],[1,2.3,16.19],[2,2.28,12.15]],"ltp":2.38,"tv":2458.89,"id":10107355},{"batb":[[1,150,1.85]],"ltp":580.0,"tv":6.13,"id":27606066},{"batb":[[0,230,1.32],[1,220,1.26],[2,170,4.13]],"ltp":280.0,"tv":1.54,"id":24270700},{"batb":[[0,150,2.66],[1,100,1.16],[2,90,1.36]],"ltp":160.0,"tv":19.01,"id":13306150}]}]}
{"op":"mcm","clk":"992906124","pt":1580532869748,"mc":[{"id":"1.168133543","rc":[{"batb":[[1,160,1.61],[2,110,1.15]],"ltp":580.0,"tv":6.13,"id":27606066},{"batb":[[0,230,2.42],[1,180,1.03],[2,170,3.21]],"ltp":280.0,"tv":1.54,"id":24270700},{"batb":[[0,160,1.39],[1,150,1.19],[2,100,1.16]],"ltp":160.0,"tv":19.01,"id":13306150}]}]}
{"op":"mcm","clk":"992906315","pt":1580532875438,"mc":[{"id":"1.168133543","rc":[{"batl":[[0,2.4,4.01],[1,2.42,5.5],[2,2.46,21]],"ltp":2.38,"tv":2458.89,"id":10107355}]}]}
{"op":"mcm","clk":"992906651","pt":1580532884454,"mc":[{"id":"1.168133543","rc":[{"batb":[[1,170,1.52]],"ltp":580.0,"tv":6.13,"id":27606066},{"batb":[[0,230,1.32],[1,220,1.26],[2,170,4.13]],"ltp":280.0,"tv":1.54,"id":24270700}]}]}
{"op":"mcm","clk":"992907300","pt":1580532900572,"mc":[{"id":"1.168133543","rc":[{"batb":[[1,110,1.18],[2,100,16.8]],"ltp":580.0,"tv":6.13,"id":27606066},{"batb":[[1,180,1.03],[2,170,3.21]],"ltp":280.0,"tv":1.54,"id":24270700}]}]}
{"op":"mcm","clk":"992907308","pt":1580532900678,"mc":[{"id":"1.168133543","rc":[{"batb":[[1,180,1.44],[2,110,1.15]],"ltp":580.0,"tv":6.13,"id":27606066},{"batb":[[0,230,2.42]],"ltp":280.0,"tv":1.54,"id":24270700}]}]}
{"op":"mcm","clk":"992907457","pt":1580532904509,"mc":[{"id":"1.168133543","rc":[{"batb":[[0,2.32,38.51],[1,2.3,7.49]],"ltp":2.38,"tv":2458.89,"id":10107355},{"batb":[[1,180,1.55],[2,110,1.02]],"ltp":580.0,"tv":6.13,"id":27606066}]}]}
{"op":"mcm","clk":"992908030","pt":1580532916685,"mc":[{"id":"1.168133543","rc":[{"batb":[[1,190,1.47]],"ltp":580.0,"tv":6.13,"id":27606066},{"batb":[[0,230,1.32],[1,220,1.26],[2,170,4.13]],"ltp":280.0,"tv":1.54,"id":24270700}]}]}
{"op":"mcm","clk":"992908678","pt":1580532932531,"mc":[{"id":"1.168133543","rc":[{"batb":[[1,110,1.16],[2,100,16.8]],"ltp":580.0,"tv":6.13,"id":27606066},{"batb":[[1,180,1.03],[2,170,3.21]],"ltp":280.0,"tv":1.54,"id":24270700}]}]}
{"op":"mcm","clk":"992908702","pt":1580532932995,"mc":[{"id":"1.168133543","rc":[{"batb":[[1,120,2.25],[2,110,2.28]],"ltp":580.0,"tv":6.13,"id":27606066},{"batb":[[0,230,2.42]],"ltp":280.0,"tv":1.54,"id":24270700}]}]}
{"op":"mcm","clk":"992909178","pt":1580532942964,"mc":[{"id":"1.168133543","rc":[{"batb":[[1,120,2.58]],"ltp":580.0,"tv":6.13,"id":27606066}]}]}
{"op":"mcm","clk":"992909470","pt":1580532948740,"mc":[{"id":"1.168133543","rc":[{"batb":[[1,130,2.42]],"ltp":580.0,"tv":6.13,"id":27606066},{"batb":[[0,230,1.32],[1,220,1.26],[2,170,4.13]],"ltp":280.0,"tv":1.54,"id":24270700}]}]}
{"op":"mcm","clk":"992909809","pt":1580532956982,"mc":[{"id":"1.168133543","rc":[{"batb":[[1,130,2.45]],"ltp":580.0,"tv":6.13,"id":27606066}]}]}
{"op":"mcm","clk":"992910149","pt":1580532964570,"mc":[{"id":"1.168133543","rc":[{"batb":[[1,110,2.77],[2,100,16.8]],"ltp":580.0,"tv":6.13,"id":27606066},{"batb":[[1,180,1.03],[2,170,3.21]],"ltp":280.0,"tv":1.54,"id":24270700}]}]}
{"op":"mcm","clk":"992910153","pt":1580532964671,"mc":[{"id":"1.168133543","rc":[{"batb":[[1,140,1.98],[2,110,2.6]],"ltp":580.0,"tv":6.13,"id":27606066},{"batb":[[0,230,2.42]],"ltp":280.0,"tv":1.54,"id":24270700}]}]}
{"op":"mcm","clk":"992910858","pt":1580532981282,"mc":[{"id":"1.168133543","rc":[{"batb":[[1,150,1.72],[2,110,2.42]],"ltp":580.0,"tv":6.13,"id":27606066},{"batb":[[0,230,1.32],[1,220,1.26],[2,170,4.13]],"ltp":280.0,"tv":1.54,"id":24270700}]}]}
{"op":"mcm","clk":"992911388","pt":1580532994704,"mc":[{"id":"1.168133543","rc":[{"batb":[[0,2.34,7.36],[1,2.32,38.51]],"ltp":2.38,"tv":2458.89,"id":10107355}]}]}
{"op":"mcm","clk":"992911462","pt":1580532996502,"mc":[{"id":"1.168133543","rc":[{"batb":[[0,2.34,37],[1,2.32,8.62]],"batl":[[0,2.42,5.51],[1,2.46,21],[2,2.48,50]],"ltp":2.38,"tv":2458.89,"id":10107355},{"batb":[[1,110,2.45],[2,100,16.8]],"ltp":580.0,"tv":6.13,"id":27606066},{"batb":[[1,180,1.03],[2,170,3.21]],"ltp":280.0,"tv":1.54,"id":24270700}]}]}
{"op":"mcm","clk":"992911471","pt":1580532996603,"mc":[{"id":"1.168133543","rc":[{"batb":[[1,160,1.61],[2,110,2.42]],"ltp":580.0,"tv":6.13,"id":27606066},{"batb":[[0,230,2.42]],"ltp":280.0,"tv":1.54,"id":24270700}]}]}
{"op":"mcm","clk":"992912041","pt":1580533010539,"mc":[{"id":"1.168133543","rc":[{"batb":[[1,2.28,12.15],[2,2.26,23.83]],"ltp":2.38,"tv":2458.89,"id":10107355},{"batb":[[1,160,1.73],[2,110,2.28]],"ltp":580.0,"tv":6.13,"id":27606066}]}]}
{"op":"mcm","clk":"992912145","pt":1580533013144,"mc":[{"id":"1.168133543","rc":[{"batb":[[2,110,1.02]],"ltp":580.0,"tv":6.13,"id":27606066}]}]}
{"op":"mcm","clk":"992912310","pt":1580533017556,"mc":[{"id":"1.168133543","rc":[{"batb":[[0,2.34,7.36]],"ltp":2.38,"tv":2458.89,"id":10107355},{"batb":[[1,110,1.17],[2,100,16.8]],"ltp":580.0,"tv":6.13,"id":27606066},{"batb":[[0,230,1.32]],"ltp":280.0,"tv":1.54,"id":24270700}]}]}
{"op":"mcm","clk":"992912321","pt":1580533017763,"mc":[{"id":"1.168133543","rc":[{"batb":[[1,2.3,30.15],[2,2.28,12.15]],"ltp":2.38,"tv":2458.89,"id":10107355},{"batb":[[1,170,1.64],[2,110,1.02]],"ltp":580.0,"tv":6.13,"id":27606066},{"batb":[[1,220,1.26],[2,170,4.13]],"ltp":280.0,"tv":1.54,"id":24270700}]}]}
{"op":"mcm","clk":"992913066","pt":1580533033555,"mc":[{"id":"1.168133543","rc":[{"batb":[[1,180,1.44],[2,110,1.14]],"ltp":580.0,"tv":6.13,"id":27606066},{"batb":[[0,230,2.42],[1,180,1.03],[2,170,3.21]],"ltp":280.0,"tv":1.54,"id":24270700}]}]}
{"op":"mcm","clk":"992913713","pt":1580533048561,"mc":[{"id":"1.168133543","rc":[{"batb":[[0,230,1.32]],"ltp":280.0,"tv":1.54,"id":24270700}]}]}
{"op":"mcm","clk":"992913718","pt":1580533048664,"mc":[{"id":"1.168133543","rc":[{"batb":[[1,220,1.26],[2,170,4.13]],"ltp":280.0,"tv":1.54,"id":24270700}]}]}
{"op":"mcm","clk":"992914349","pt":1580533063512,"mc":[{"id":"1.168133543","rc":[{"batb":[[2,110,1.02]],"ltp":580.0,"tv":6.13,"id":27606066}]}]}
{"op":"mcm","clk":"992914392","pt":1580533064496,"mc":[{"id":"1.168133543","rc":[{"batb":[[1,110,1.16],[2,100,16.8]],"ltp":580.0,"tv":6.13,"id":27606066},{"batb":[[1,180,1.03],[2,170,3.21]],"ltp":280.0,"tv":1.54,"id":24270700}]}]}
{"op":"mcm","clk":"992914395","pt":1580533064600,"mc":[{"id":"1.168133543","rc":[{"batb":[[1,190,1.47],[2,110,1.02]],"ltp":580.0,"tv":6.13,"id":27606066},{"batb":[[0,230,2.42]],"ltp":280.0,"tv":1.54,"id":24270700}]}]}
{"op":"mcm","clk":"992915107","pt":1580533080537,"mc":[{"id":"1.168133543","rc":[{"batb":[[1,120,2.25]],"ltp":580.0,"tv":6.13,"id":27606066},{"batb":[[0,230,1.32],[1,220,1.26],[2,170,4.13]],"ltp":280.0,"tv":1.54,"id":24270700}]}]}
{"op":"mcm","clk":"992915729","pt":1580533096557,"mc":[{"id":"1.168133543","rc":[{"batb":[[1,180,1.03],[2,170,3.21]],"ltp":280.0,"tv":1.54,"id":24270700}]}]}
{"op":"mcm","clk":"992915735","pt":1580533096659,"mc":[{"id":"1.168133543","rc":[{"batb":[[0,230,2.42]],"ltp":280.0,"tv":1.54,"id":24270700}]}]}
{"op":"mcm","clk":"992916403","pt":1580533112642,"mc":[{"id":"1.168133543","rc":[{"batb":[[0,230,1.32],[1,220,1.26],[2,170,4.13]],"ltp":280.0,"tv":1.54,"id":24270700}]}]}
{"op":"mcm","clk":"992916601","pt":1580533116989,"mc":[{"id":"1.168133543","rc":[{"batb":[[1,2.3,38.85]],"ltp":2.38,"tv":2458.89,"id":10107355},{"batb":[[1,120,2.29]],"ltp":580.0,"tv":6.13,"id":27606066}]}]}
{"op":"mcm","clk":"992917108","pt":1580533128899,"mc":[{"id":"1.168133543","rc":[{"batb":[[1,2.32,29.89],[2,2.3,8.7]],"ltp":2.38,"tv":2458.89,"id":10107355},{"batb":[[0,230,2.42],[1,180,1.03],[2,170,3.21]],"ltp":280.0,"tv":1.54,"id":24270700}]}]}
{"op":"mcm","clk":"992917942","pt":1580533144496,"mc":[{"id":"1.168133543","rc":[{"batb":[[0,230,1.32],[1,220,1.26],[2,170,4.13]],"ltp":280.0,"tv":1.54,"id":24270700}]}]}
{"op":"mcm","clk":"992918707","pt":1580533160517,"mc":[{"id":"1.168133543","rc":[{"batb":[[1,180,1.03],[2,170,3.21]],"ltp":280.0,"tv":1.54,"id":24270700}]}]}
{"op":"mcm","clk":"992918735","pt":1580533161242,"mc":[{"id":"1.168133543","rc":[{"batb":[[0,230,2.42]],"ltp":280.0,"tv":1.54,"id":24270700}]}]}
{"op":"mcm","clk":"992919254","pt":1580533171020,"mc":[{"id":"1.168133543","rc":[{"batb":[[1,2.32,38.51],[2,2.28,12.15]],"ltp":2.38,"tv":2458.89,"id":10107355}]}]}
{"op":"mcm","clk":"992919528","pt":1580533176546,"mc":[{"id":"1.168133543","rc":[{"batb":[[1,2.32,8.62]],"ltp":2.38,"tv":2458.89,"id":10107355},{"batb":[[0,230,1.32]],"ltp":280.0,"tv":1.54,"id":24270700}]}]}
{"op":"mcm","clk":"992919534","pt":1580533176646,"mc":[{"id":"1.168133543","rc":[{"batb":[[1,220,1.26],[2,170,4.13]],"ltp":280.0,"tv":1.54,"id":24270700}]}]}
{"op":"mcm","clk":"992920189","pt":1580533192762,"mc":[{"id":"1.168133543","rc":[{"batb":[[0,2.34,37]],"ltp":2.38,"tv":2458.89,"id":10107355},{"batb":[[0,230,2.42],[1,180,1.03],[2,170,3.21]],"ltp":280.0,"tv":1.54,"id":24270700}]}]}
{"op":"mcm","clk":"992920883","pt":1580533208511,"mc":[{"id":"1.168133543","rc":[{"batb":[[0,2.34,7.36]],"ltp":2.38,"tv":2458.89,"id":10107355},{"batb":[[0,230,1.32]],"ltp":280.0,"tv":1.54,"id":24270700}]}]}
{"op":"mcm","clk":"992920908","pt":1580533209025,"mc":[{"id":"1.168133543","rc":[{"batb":[[1,220,1.26],[2,170,4.13]],"ltp":280.0,"tv":1.54,"id":24270700}]}]}
{"op":"mcm","clk":"992921515","pt":1580533224513,"mc":[{"id":"1.168133543","rc":[{"batb":[[0,2.34,37],[1,2.28,20.92],[2,2.26,23.83]],"ltp":2.38,"tv":2458.89,"id":10107355},{"batb":[[1,180,1.03],[2,170,3.21]],"ltp":280.0,"tv":1.54,"id":24270700}]}]}
{"op":"mcm","clk":"992921518","pt":1580533224615,"mc":[{"id":"1.168133543","rc":[{"batb":[[0,230,2.42]],"ltp":280.0,"tv":1.54,"id":24270700}]}]}
{"op":"mcm","clk":"992922132","pt":1580533240572,"mc":[{"id":"1.168133543","rc":[{"batb":[[0,2.34,7.36]],"ltp":2.38,"tv":2458.89,"id":10107355},{"batb":[[0,230,1.32]],"ltp":280.0,"tv":1.54,"id":24270700}]}]}
{"op":"mcm","clk":"992922171","pt":1580533241245,"mc":[{"id":"1.168133543","rc":[{"batb":[[1,2.3,30.15],[2,2.28,20.92]],"ltp":2.38,"tv":2458.89,"id":10107355},{"batb":[[1,220,1.26],[2,170,4.13]],"ltp":280.0,"tv":1.54,"id":24270700}]}]}
{"op":"mcm","clk":"992922864","pt":1580533255553,"mc":[{"id":"1.168133543","rc":[{"batb":[[1,180,1.03],[2,170,3.21]],"ltp":280.0,"tv":1.54,"id":24270700}]}]}
{"op":"mcm","clk":"992922868","pt":1580533255656,"mc":[{"id":"1.168133543","rc":[{"batb":[[0,230,2.42]],"ltp":280.0,"tv":1.54,"id":24270700}]}]}
{"op":"mcm","clk":"992923547","pt":1580533271569,"mc":[{"id":"1.168133543","rc":[{"batb":[[0,230,1.32],[1,220,1.26],[2,170,4.13]],"ltp":280.0,"tv":1.54,"id":24270700}]}]}
{"op":"mcm","clk":"992923847","pt":1580533277884,"mc":[{"id":"1.168133543","rc":[{"batb":[[2,2.28,12.15]],"ltp":2.38,"tv":2458.89,"id":10107355}]}]}
{"op":"mcm","clk":"992924226","pt":1580533287500,"mc":[{"id":"1.168133543","rc":[{"batb":[[1,180,1.03],[2,170,3.21]],"ltp":280.0,"tv":1.54,"id":24270700}]}]}
{"op":"mcm","clk":"992924236","pt":1580533287603,"mc":[{"id":"1.168133543","rc":[{"batb":[[0,230,2.42]],"ltp":280.0,"tv":1.54,"id":24270700}]}]}
{"op":"mcm","clk":"992925017","pt":1580533303716,"mc":[{"id":"1.168133543","rc":[{"batb":[[0,230,1.32],[1,220,1.26],[2,170,4.13]],"ltp":280.0,"tv":1.54,"id":24270700}]}]}
{"op":"mcm","clk":"992925670","pt":1580533320533,"mc":[{"id":"1.168133543","rc":[{"batb":[[0,230,2.42],[1,180,1.03],[2,170,3.21]],"ltp":280.0,"tv":1.54,"id":24270700}]}]}
{"op":"mcm","clk":"992926295","pt":1580533335537,"mc":[{"id":"1.168133543","rc":[{"batb":[[0,230,1.32],[1,220,1.26],[2,170,4.13]],"ltp":280.0,"tv":1.54,"id":24270700}]}]}
{"op":"mcm","clk":"992926995","pt":1580533352323,"mc":[{"id":"1.168133543","rc":[{"batb":[[0,230,2.42],[1,180,1.03],[2,170,3.21]],"ltp":280.0,"tv":1.54,"id":24270700}]}]}
{"op":"mcm","clk":"992927668","pt":1580533368123,"mc":[{"id":"1.168133543","rc":[{"batb":[[0,230,1.32],[1,220,1.26],[2,170,4.13]],"ltp":280.0,"tv":1.54,"id":24270700}]}]}
{"op":"mcm","clk":"992928333","pt":1580533383517,"mc":[{"id":"1.168133543","rc":[{"batb":[[1,180,1.03],[2,170,3.21]],"ltp":280.0,"tv":1.54,"id":24270700}]}]}
{"op":"mcm","clk":"992928349","pt":1580533383726,"mc":[{"id":"1.168133543","rc":[{"batb":[[0,230,2.42]],"ltp":280.0,"tv":1.54,"id":24270700}]}]}
{"op":"mcm","clk":"992929022","pt":1580533399566,"mc":[{"id":"1.168133543","rc":[{"batb":[[0,230,1.32]],"ltp":280.0,"tv":1.54,"id":24270700}]}]}
{"op":"mcm","clk":"992929029","pt":1580533399669,"mc":[{"id":"1.168133543","rc":[{"batb":[[1,220,1.26],[2,170,4.13]],"ltp":280.0,"tv":1.54,"id":24270700}]}]}
{"op":"mcm","clk":"992929741","pt":1580533415491,"mc":[{"id":"1.168133543","rc":[{"batb":[[1,180,1.03],[2,170,3.21]],"ltp":280.0,"tv":1.54,"id":24270700}]}]}
{"op":"mcm","clk":"992929751","pt":1580533415593,"mc":[{"id":"1.168133543","rc":[{"batb":[[0,230,2.42]],"ltp":280.0,"tv":1.54,"id":24270700}]}]}
{"op":"mcm","clk":"992930421","pt":1580533431534,"mc":[{"id":"1.168133543","rc":[{"batb":[[0,230,1.32]],"ltp":280.0,"tv":1.54,"id":24270700}]}]}
{"op":"mcm","clk":"992930432","pt":1580533431692,"mc":[{"id":"1.168133543","rc":[{"batb":[[1,220,1.26],[2,170,4.13]],"ltp":280.0,"tv":1.54,"id":24270700}]}]}
{"op":"mcm","clk":"992931022","pt":1580533446522,"mc":[{"id":"1.168133543","rc":[{"batb":[[1,180,1.03],[2,170,3.21]],"ltp":280.0,"tv":1.54,"id":24270700}]}]}
{"op":"mcm","clk":"992931025","pt":1580533446623,"mc":[{"id":"1.168133543","rc":[{"batb":[[0,230,2.42]],"ltp":280.0,"tv":1.54,"id":24270700}]}]}
{"op":"mcm","clk":"992931682","pt":1580533462532,"mc":[{"id":"1.168133543","rc":[{"batb":[[0,230,1.32],[1,220,1.26],[2,170,4.13]],"ltp":280.0,"tv":1.54,"id":24270700}]}]}
{"op":"mcm","clk":"992932554","pt":1580533478695,"mc":[{"id":"1.168133543","rc":[{"batb":[[0,230,2.42],[1,180,1.03],[2,170,3.21]],"ltp":280.0,"tv":1.54,"id":24270700}]}]}
{"op":"mcm","clk":"992933131","pt":1580533488272,"mc":[{"id":"1.168133543","rc":[{"batb":[[1,2.3,38.85]],"ltp":2.38,"tv":2458.89,"id":10107355}]}]}
{"op":"mcm","clk":"992933503","pt":1580533494910,"mc":[{"id":"1.168133543","rc":[{"batb":[[1,2.32,29.89],[2,2.3,8.7]],"ltp":2.38,"tv":2458.89,"id":10107355},{"batb":[[0,230,1.32],[1,220,1.26],[2,170,4.13]],"ltp":280.0,"tv":1.54,"id":24270700}]}]}
{"op":"mcm","clk":"992934329","pt":1580533510538,"mc":[{"id":"1.168133543","rc":[{"batb":[[1,180,1.03],[2,170,3.21]],"ltp":280.0,"tv":1.54,"id":24270700}]}]}
{"op":"mcm","clk":"992934367","pt":1580533511561,"mc":[{"id":"1.168133543","rc":[{"batb":[[0,230,2.42]],"ltp":280.0,"tv":1.54,"id":24270700}]}]}
{"op":"mcm","clk":"992935137","pt":1580533526570,"mc":[{"id":"1.168133543","rc":[{"batb":[[0,230,1.32]],"ltp":280.0,"tv":1.54,"id":24270700}]}]}
{"op":"mcm","clk":"992935141","pt":1580533526679,"mc":[{"id":"1.168133543","rc":[{"batb":[[1,220,1.26],[2,170,4.13]],"ltp":280.0,"tv":1.54,"id":24270700}]}]}
{"op":"mcm","clk":"992935813","pt":1580533540560,"mc":[{"id":"1.168133543","rc":[{"batb":[[1,2.32,38.51],[2,2.28,12.15]],"ltp":2.38,"tv":2458.89,"id":10107355}]}]}
{"op":"mcm","clk":"992935907","pt":1580533542566,"mc":[{"id":"1.168133543","rc":[{"batb":[[1,2.32,8.62]],"ltp":2.38,"tv":2458.89,"id":10107355},{"batb":[[0,230,2.42],[1,180,1.03],[2,170,3.21]],"ltp":280.0,"tv":1.54,"id":24270700}]}]}
{"op":"mcm","clk":"992936541","pt":1580533558527,"mc":[{"id":"1.168133543","rc":[{"batb":[[0,230,1.32]],"ltp":280.0,"tv":1.54,"id":24270700}]}]}
{"op":"mcm","clk":"992936549","pt":1580533558686,"mc":[{"id":"1.168133543","rc":[{"batb":[[0,2.34,37]],"ltp":2.38,"tv":2458.89,"id":10107355},{"batb":[[1,220,1.26],[2,170,4.13]],"ltp":280.0,"tv":1.54,"id":24270700}]}]}
{"op":"mcm","clk":"992937328","pt":1580533574523,"mc":[{"id":"1.168133543","rc":[{"batb":[[0,2.34,7.36]],"ltp":2.38,"tv":2458.89,"id":10107355},{"batb":[[1,180,1.03],[2,170,3.21]],"ltp":280.0,"tv":1.54,"id":24270700}]}]}
{"op":"mcm","clk":"992937344","pt":1580533574830,"mc":[{"id":"1.168133543","rc":[{"batb":[[0,230,2.42]],"ltp":280.0,"tv":1.54,"id":24270700}]}]}
{"op":"mcm","clk":"992938082","pt":1580533590472,"mc":[{"id":"1.168133543","rc":[{"batb":[[0,230,1.32]],"ltp":280.0,"tv":1.54,"id":24270700}]}]}
{"op":"mcm","clk":"992938095","pt":1580533590680,"mc":[{"id":"1.168133543","rc":[{"batb":[[0,2.34,37]],"ltp":2.38,"tv":2458.89,"id":10107355},{"batb":[[1,220,1.26],[2,170,4.13]],"ltp":280.0,"tv":1.54,"id":24270700}]}]}
{"op":"mcm","clk":"992938230","pt":1580533593473,"mc":[{"id":"1.168133543","rc":[{"batb":[[1,2.28,12.15],[2,2.26,23.83]],"ltp":2.38,"tv":2458.89,"id":10107355}]}]}
{"op":"mcm","clk":"992938774","pt":1580533606884,"mc":[{"id":"1.168133543","rc":[{"batb":[[0,2.34,7.36],[1,2.3,30.15],[2,2.28,12.15]],"ltp":2.38,"tv":2458.89,"id":10107355},{"batb":[[0,230,2.42],[1,180,1.03],[2,170,3.21]],"ltp":280.0,"tv":1.54,"id":24270700}]}]}
{"op":"mcm","clk":"992939486","pt":1580533622533,"mc":[{"id":"1.168133543","rc":[{"batb":[[0,230,1.32]],"ltp":280.0,"tv":1.54,"id":24270700}]}]}
{"op":"mcm","clk":"992939492","pt":1580533622588,"mc":[{"id":"1.168133543","rc":[{"batb":[[1,220,1.26],[2,170,4.13]],"ltp":280.0,"tv":1.54,"id":24270700}]}]}
{"op":"mcm","clk":"992940186","pt":1580533637519,"mc":[{"id":"1.168133543","rc":[{"batb":[[0,230,2.42],[1,180,1.03],[2,170,3.21]],"ltp":280.0,"tv":1.54,"id":24270700}]}]}
{"op":"mcm","clk":"992950693","pt":1580533653556,"mc":[{"id":"1.168133543","rc":[{"batb":[[0,230,1.32],[1,220,1.26],[2,170,4.13]],"ltp":280.0,"tv":1.54,"id":24270700}]}]}
{"op":"mcm","clk":"992951378","pt":1580533669501,"mc":[{"id":"1.168133543","rc":[{"batb":[[0,230,2.42],[1,180,1.03],[2,170,3.21]],"ltp":280.0,"tv":1.54,"id":24270700}]}]}
{"op":"mcm","clk":"992952067","pt":1580533685557,"mc":[{"id":"1.168133543","rc":[{"batb":[[0,230,1.32]],"ltp":280.0,"tv":1.54,"id":24270700}]}]}
{"op":"mcm","clk":"992952070","pt":1580533685611,"mc":[{"id":"1.168133543","rc":[{"batb":[[1,220,1.26],[2,170,4.13]],"ltp":280.0,"tv":1.54,"id":24270700}]}]}
{"op":"mcm","clk":"992952550","pt":1580533700157,"mc":[{"id":"1.168133543","rc":[{"batb":[[1,2.3,38.85]],"ltp":2.38,"tv":2458.89,"id":10107355}]}]}
{"op":"mcm","clk":"992952599","pt":1580533701546,"mc":[{"id":"1.168133543","rc":[{"batb":[[1,2.3,8.7]],"ltp":2.38,"tv":2458.89,"id":10107355},{"batb":[[1,180,1.03],[2,170,3.21]],"ltp":280.0,"tv":1.54,"id":24270700}]}]}
{"op":"mcm","clk":"992952606","pt":1580533701770,"mc":[{"id":"1.168133543","rc":[{"batb":[[1,2.32,29.89],[2,2.3,8.7]],"ltp":2.38,"tv":2458.89,"id":10107355},{"batb":[[0,230,2.42]],"ltp":280.0,"tv":1.54,"id":24270700}]}]}
{"op":"mcm","clk":"992953185","pt":1580533717498,"mc":[{"id":"1.168133543","rc":[{"batb":[[0,230,1.32],[1,220,1.26],[2,170,4.13]],"ltp":280.0,"tv":1.54,"id":24270700}]}]}
{"op":"mcm","clk":"992953820","pt":1580533733511,"mc":[{"id":"1.168133543","rc":[{"batb":[[1,180,1.03],[2,170,3.21]],"ltp":280.0,"tv":1.54,"id":24270700}]}]}
{"op":"mcm","clk":"992953826","pt":1580533733611,"mc":[{"id":"1.168133543","rc":[{"batb":[[0,230,2.42]],"ltp":280.0,"tv":1.54,"id":24270700}]}]}
{"op":"mcm","clk":"992954507","pt":1580533751523,"mc":[{"id":"1.168133543","rc":[{"batb":[[0,230,1.32],[1,220,1.26],[2,170,4.13]],"ltp":280.0,"tv":1.54,"id":24270700}]}]}
{"op":"mcm","clk":"992954557","pt":1580533753012,"mc":[{"id":"1.168133543","rc":[{"batb":[[1,2.32,38.51],[2,2.28,12.15]],"ltp":2.38,"tv":2458.89,"id":10107355}]}]}
{"op":"mcm","clk":"992955139","pt":1580533766544,"mc":[{"id":"1.168133543","rc":[{"batb":[[1,2.32,8.62]],"ltp":2.38,"tv":2458.89,"id":10107355},{"batb":[[0,230,2.42],[1,180,1.03],[2,170,3.21]],"ltp":280.0,"tv":1.54,"id":24270700}]}]}
{"op":"mcm","clk":"992955892","pt":1580533782491,"mc":[{"id":"1.168133543","rc":[{"batb":[[0,2.34,37]],"ltp":2.38,"tv":2458.89,"id":10107355},{"batb":[[0,230,1.32]],"ltp":280.0,"tv":1.54,"id":24270700}]}]}
{"op":"mcm","clk":"992955897","pt":1580533782592,"mc":[{"id":"1.168133543","rc":[{"batb":[[1,220,1.26],[2,170,4.13]],"ltp":280.0,"tv":1.54,"id":24270700}]}]}
{"op":"mcm","clk":"992956623","pt":1580533798516,"mc":[{"id":"1.168133543","rc":[{"batb":[[0,2.34,7.36]],"ltp":2.38,"tv":2458.89,"id":10107355},{"batb":[[1,180,1.03],[2,170,3.21]],"ltp":280.0,"tv":1.54,"id":24270700}]}]}
{"op":"mcm","clk":"992956635","pt":1580533798774,"mc":[{"id":"1.168133543","rc":[{"batb":[[0,230,2.42]],"ltp":280.0,"tv":1.54,"id":24270700}]}]}
{"op":"mcm","clk":"992956982","pt":1580533806421,"mc":[{"id":"1.168133543","rc":[{"batb":[[1,2.28,20.92],[2,2.26,23.83]],"ltp":2.38,"tv":2458.89,"id":10107355}]}]}
{"op":"mcm","clk":"992957370","pt":1580533814517,"mc":[{"id":"1.168133543","rc":[{"batb":[[0,230,1.32],[1,220,1.26],[2,170,4.13]],"ltp":280.0,"tv":1.54,"id":24270700}]}]}
{"op":"mcm","clk":"992958060","pt":1580533830557,"mc":[{"id":"1.168133543","rc":[{"batb":[[1,180,1.03],[2,170,3.21]],"ltp":280.0,"tv":1.54,"id":24270700}]}]}
{"op":"mcm","clk":"992958083","pt":1580533831218,"mc":[{"id":"1.168133543","rc":[{"batb":[[0,230,2.42]],"ltp":280.0,"tv":1.54,"id":24270700}]}]}
{"op":"mcm","clk":"992958774","pt":1580533846489,"mc":[{"id":"1.168133543","rc":[{"batb":[[0,230,1.32],[1,220,1.26],[2,170,4.13]],"ltp":280.0,"tv":1.54,"id":24270700}]}]}
{"op":"mcm","clk":"992959664","pt":1580533862486,"mc":[{"id":"1.168133543","rc":[{"batb":[[1,180,1.03],[2,170,3.21]],"ltp":280.0,"tv":1.54,"id":24270700}]}]}
{"op":"mcm","clk":"992959667","pt":1580533862586,"mc":[{"id":"1.168133543","rc":[{"batb":[[0,230,2.42]],"ltp":280.0,"tv":1.54,"id":24270700}]}]}
{"op":"mcm","clk":"992960490","pt":1580533878700,"mc":[{"id":"1.168133543","rc":[{"batb":[[0,230,1.32],[1,220,1.26],[2,170,4.13]],"ltp":280.0,"tv":1.54,"id":24270700}]}]}
{"op":"mcm","clk":"992961270","pt":1580533894559,"mc":[{"id":"1.168133543","rc":[{"batb":[[1,180,1.03],[2,170,3.21]],"ltp":280.0,"tv":1.54,"id":24270700}]}]}
{"op":"mcm","clk":"992961292","pt":1580533895229,"mc":[{"id":"1.168133543","rc":[{"batb":[[0,230,2.42]],"ltp":280.0,"tv":1.54,"id":24270700}]}]}
{"op":"mcm","clk":"992961948","pt":1580533910479,"mc":[{"id":"1.168133543","rc":[{"batb":[[0,230,1.32]],"ltp":280.0,"tv":1.54,"id":24270700}]}]}
{"op":"mcm","clk":"992961954","pt":1580533910583,"mc":[{"id":"1.168133543","rc":[{"batb":[[1,220,1.26],[2,170,4.13]],"ltp":280.0,"tv":1.54,"id":24270700}]}]}
{"op":"mcm","clk":"992962644","pt":1580533926477,"mc":[{"id":"1.168133543","rc":[{"batb":[[0,230,2.42],[1,180,1.03],[2,170,3.21]],"ltp":280.0,"tv":1.54,"id":24270700}]}]}
{"op":"mcm","clk":"992963387","pt":1580533942514,"mc":[{"id":"1.168133543","rc":[{"batb":[[0,230,1.32]],"ltp":280.0,"tv":1.54,"id":24270700}]}]}
{"op":"mcm","clk":"992963392","pt":1580533942616,"mc":[{"id":"1.168133543","rc":[{"batb":[[1,220,1.26],[2,170,4.13]],"ltp":280.0,"tv":1.54,"id":24270700}]}]}
{"op":"mcm","clk":"992963990","pt":1580533957539,"mc":[{"id":"1.168133543","rc":[{"batb":[[0,230,2.42],[1,180,1.03],[2,170,3.21]],"ltp":280.0,"tv":1.54,"id":24270700}]}]}
{"op":"mcm","clk":"992964510","pt":1580533973547,"mc":[{"id":"1.168133543","rc":[{"batb":[[0,230,1.32]],"ltp":280.0,"tv":1.54,"id":24270700}]}]}
{"op":"mcm","clk":"992964516","pt":1580533973649,"mc":[{"id":"1.168133543","rc":[{"batb":[[1,220,1.26],[2,170,4.13]],"ltp":280.0,"tv":1.54,"id":24270700}]}]}
{"op":"mcm","clk":"992965083","pt":1580533989551,"mc":[{"id":"1.168133543","rc":[{"batb":[[0,230,2.42],[1,180,1.03],[2,170,3.21]],"ltp":280.0,"tv":1.54,"id":24270700}]}]}
{"op":"mcm","clk":"992965756","pt":1580534005502,"mc":[{"id":"1.168133543","rc":[{"batb":[[0,230,1.32]],"ltp":280.0,"tv":1.54,"id":24270700}]}]}
{"op":"mcm","clk":"992965758","pt":1580534005604,"mc":[{"id":"1.168133543","rc":[{"batb":[[1,220,1.26],[2,170,4.13]],"ltp":280.0,"tv":1.54,"id":24270700}]}]}
{"op":"mcm","clk":"992966408","pt":1580534021540,"mc":[{"id":"1.168133543","rc":[{"batb":[[1,180,1.03],[2,170,3.21]],"ltp":280.0,"tv":1.54,"id":24270700}]}]}
{"op":"mcm","clk":"992966411","pt":1580534021640,"mc":[{"id":"1.168133543","rc":[{"batb":[[0,230,2.42]],"ltp":280.0,"tv":1.54,"id":24270700}]}]}
{"op":"mcm","clk":"992967017","pt":1580534037543,"mc":[{"id":"1.168133543","rc":[{"batb":[[0,230,1.32],[1,220,1.26],[2,170,4.13]],"ltp":280.0,"tv":1.54,"id":24270700}]}]}
{"op":"mcm","clk":"992967212","pt":1580534042534,"mc":[{"id":"1.168133543","rc":[{"batb":[[0,230,2.42],[1,180,1.03],[2,170,3.21]],"ltp":280.0,"tv":1.54,"id":24270700}]}]}
{"op":"mcm","clk":"992967944","pt":1580534058551,"mc":[{"id":"1.168133543","rc":[{"batb":[[0,230,1.32],[1,220,1.26],[2,170,4.13]],"ltp":280.0,"tv":1.54,"id":24270700}]}]}
{"op":"mcm","clk":"992968287","pt":1580534067488,"mc":[{"id":"1.168133543","rc":[{"batb":[[1,180,1.03],[2,170,3.21]],"ltp":280.0,"tv":1.54,"id":24270700}]}]}
{"op":"mcm","clk":"992968289","pt":1580534067594,"mc":[{"id":"1.168133543","rc":[{"batb":[[0,230,2.42]],"ltp":280.0,"tv":1.54,"id":24270700}]}]}
{"op":"mcm","clk":"992968846","pt":1580534083526,"mc":[{"id":"1.168133543","rc":[{"batb":[[0,230,1.32]],"ltp":280.0,"tv":1.54,"id":24270700}]}]}
{"op":"mcm","clk":"992968852","pt":1580534083629,"mc":[{"id":"1.168133543","rc":[{"batb":[[1,220,1.26],[2,170,4.13]],"ltp":280.0,"tv":1.54,"id":24270700}]}]}
{"op":"mcm","clk":"992969193","pt":1580534093537,"mc":[{"id":"1.168133543","rc":[{"batb":[[0,230,2.42],[1,180,1.03],[2,170,3.21]],"ltp":280.0,"tv":1.54,"id":24270700}]}]}
{"op":"mcm","clk":"992969871","pt":1580534110564,"mc":[{"id":"1.168133543","rc":[{"batb":[[0,230,1.32],[1,220,1.26],[2,170,4.13]],"ltp":280.0,"tv":1.54,"id":24270700}]}]}
{"op":"mcm","clk":"992970158","pt":1580534118452,"mc":[{"id":"1.168133543","rc":[{"batb":[[1,180,1.03],[2,170,3.21]],"ltp":280.0,"tv":1.54,"id":24270700}]}]}
{"op":"mcm","clk":"992970164","pt":1580534118582,"mc":[{"id":"1.168133543","rc":[{"batb":[[0,230,2.42]],"ltp":280.0,"tv":1.54,"id":24270700}]}]}
{"op":"mcm","clk":"992970818","pt":1580534134686,"mc":[{"id":"1.168133543","rc":[{"batb":[[0,230,1.32],[1,220,1.26],[2,170,4.13]],"ltp":280.0,"tv":1.54,"id":24270700}]}]}
{"op":"mcm","clk":"992971256","pt":1580534144477,"mc":[{"id":"1.168133543","rc":[{"batb":[[1,180,1.03],[2,170,3.21]],"ltp":280.0,"tv":1.54,"id":24270700}]}]}
{"op":"mcm","clk":"992971263","pt":1580534144681,"mc":[{"id":"1.168133543","rc":[{"batb":[[0,230,2.42]],"ltp":280.0,"tv":1.54,"id":24270700}]}]}
{"op":"mcm","clk":"992972069","pt":1580534160511,"mc":[{"id":"1.168133543","rc":[{"batb":[[0,230,1.32]],"ltp":280.0,"tv":1.54,"id":24270700}]}]}
{"op":"mcm","clk":"992972076","pt":1580534160716,"mc":[{"id":"1.168133543","rc":[{"batb":[[1,220,1.26],[2,170,4.13]],"ltp":280.0,"tv":1.54,"id":24270700}]}]}
{"op":"mcm","clk":"992972517","pt":1580534169546,"mc":[{"id":"1.168133543","rc":[{"batb":[[1,180,1.03],[2,170,3.21]],"ltp":280.0,"tv":1.54,"id":24270700}]}]}
{"op":"mcm","clk":"992972523","pt":1580534169628,"mc":[{"id":"1.168133543","rc":[{"batb":[[0,230,2.42]],"ltp":280.0,"tv":1.54,"id":24270700}]}]}
{"op":"mcm","clk":"992973247","pt":1580534185799,"mc":[{"id":"1.168133543","rc":[{"batb":[[0,230,1.32],[1,220,1.26],[2,170,4.13]],"ltp":280.0,"tv":1.54,"id":24270700}]}]}
{"op":"mcm","clk":"992973678","pt":1580534195688,"mc":[{"id":"1.168133543","rc":[{"batb":[[0,230,2.42],[1,180,1.03],[2,170,3.21]],"ltp":280.0,"tv":1.54,"id":24270700}]}]}
{"op":"mcm","clk":"992974340","pt":1580534211521,"mc":[{"id":"1.168133543","rc":[{"batb":[[0,230,1.32]],"ltp":280.0,"tv":1.54,"id":24270700}]}]}
{"op":"mcm","clk":"992974346","pt":1580534211727,"mc":[{"id":"1.168133543","rc":[{"batb":[[1,220,1.26],[2,170,4.13]],"ltp":280.0,"tv":1.54,"id":24270700}]}]}
{"op":"mcm","clk":"992974760","pt":1580534220412,"mc":[{"id":"1.168133543","rc":[{"batb":[[1,180,1.03],[2,170,3.21]],"ltp":280.0,"tv":1.54,"id":24270700}]}]}
{"op":"mcm","clk":"992974768","pt":1580534220617,"mc":[{"id":"1.168133543","rc":[{"batb":[[0,230,2.42]],"ltp":280.0,"tv":1.54,"id":24270700}]}]}
{"op":"mcm","clk":"992975489","pt":1580534236541,"mc":[{"id":"1.168133543","rc":[{"batb":[[0,230,1.32]],"ltp":280.0,"tv":1.54,"id":24270700}]}]}
{"op":"mcm","clk":"992975495","pt":1580534236642,"mc":[{"id":"1.168133543","rc":[{"batb":[[1,220,1.26],[2,170,4.13]],"ltp":280.0,"tv":1.54,"id":24270700}]}]}
{"op":"mcm","clk":"992975907","pt":1580534246555,"mc":[{"id":"1.168133543","rc":[{"batb":[[0,230,2.42],[1,180,1.03],[2,170,3.21]],"ltp":280.0,"tv":1.54,"id":24270700}]}]}
{"op":"mcm","clk":"992976555","pt":1580534262692,"mc":[{"id":"1.168133543","rc":[{"batb":[[0,230,1.32],[1,220,1.26],[2,170,4.13]],"ltp":280.0,"tv":1.54,"id":24270700}]}]}
{"op":"mcm","clk":"992976905","pt":1580534271490,"mc":[{"id":"1.168133543","rc":[{"batb":[[1,180,1.03],[2,170,3.21]],"ltp":280.0,"tv":1.54,"id":24270700}]}]}
{"op":"mcm","clk":"992976909","pt":1580534271595,"mc":[{"id":"1.168133543","rc":[{"batb":[[0,230,2.42]],"ltp":280.0,"tv":1.54,"id":24270700}]}]}
{"op":"mcm","clk":"992977376","pt":1580534287551,"mc":[{"id":"1.168133543","rc":[{"batb":[[0,230,1.32]],"ltp":280.0,"tv":1.54,"id":24270700}]}]}
{"op":"mcm","clk":"992977378","pt":1580534287652,"mc":[{"id":"1.168133543","rc":[{"batb":[[1,220,1.26],[2,170,4.13]],"ltp":280.0,"tv":1.54,"id":24270700}]}]}
{"op":"mcm","clk":"992977773","pt":1580534297561,"mc":[{"id":"1.168133543","rc":[{"batb":[[1,180,1.03],[2,170,3.21]],"ltp":280.0,"tv":1.54,"id":24270700}]}]}
{"op":"mcm","clk":"992977780","pt":1580534297661,"mc":[{"id":"1.168133543","rc":[{"batb":[[0,230,2.42]],"ltp":280.0,"tv":1.54,"id":24270700}]}]}
{"op":"mcm","clk":"992978374","pt":1580534312681,"mc":[{"id":"1.168133543","rc":[{"batb":[[0,230,1.32],[1,220,1.26],[2,170,4.13]],"ltp":280.0,"tv":1.54,"id":24270700}]}]}
{"op":"mcm","clk":"992978733","pt":1580534322479,"mc":[{"id":"1.168133543","rc":[{"batb":[[1,180,1.03],[2,170,3.21]],"ltp":280.0,"tv":1.54,"id":24270700}]}]}
{"op":"mcm","clk":"992978771","pt":1580534323196,"mc":[{"id":"1.168133543","rc":[{"batb":[[0,230,2.42]],"ltp":280.0,"tv":1.54,"id":24270700}]}]}
{"op":"mcm","clk":"992979403","pt":1580534338475,"mc":[{"id":"1.168133543","rc":[{"batb":[[0,230,1.32]],"ltp":280.0,"tv":1.54,"id":24270700}]}]}
{"op":"mcm","clk":"992979416","pt":1580534338682,"mc":[{"id":"1.168133543","rc":[{"batb":[[1,220,1.26],[2,170,4.13]],"ltp":280.0,"tv":1.54,"id":24270700}]}]}
{"op":"mcm","clk":"992979877","pt":1580534348496,"mc":[{"id":"1.168133543","rc":[{"batb":[[1,180,1.03],[2,170,3.21]],"ltp":280.0,"tv":1.54,"id":24270700}]}]}
{"op":"mcm","clk":"992979908","pt":1580534349318,"mc":[{"id":"1.168133543","rc":[{"batb":[[0,230,2.42]],"ltp":280.0,"tv":1.54,"id":24270700}]}]}
{"op":"mcm","clk":"992980360","pt":1580534363738,"mc":[{"id":"1.168133543","rc":[{"batb":[[0,230,1.32],[1,220,1.26],[2,170,4.13]],"ltp":280.0,"tv":1.54,"id":24270700}]}]}
{"op":"mcm","clk":"992980754","pt":1580534373744,"mc":[{"id":"1.168133543","rc":[{"batb":[[0,230,2.42],[1,180,1.03],[2,170,3.21]],"ltp":280.0,"tv":1.54,"id":24270700}]}]}
{"op":"mcm","clk":"992981443","pt":1580534388071,"mc":[{"id":"1.168133543","rc":[{"batb":[[0,8.6,2.02],[1,8.4,3.5],[2,7.4,3.64]],"ltp":8.4,"tv":339.13,"id":22121325}]}]}
{"op":"mcm","clk":"992981546","pt":1580534389562,"mc":[{"id":"1.168133543","rc":[{"batb":[[0,8.4,3.5],[1,7.4,3.64],[2,6.6,3]],"ltp":8.4,"tv":339.13,"id":22121325},{"batb":[[0,230,1.32]],"ltp":280.0,"tv":1.54,"id":24270700}]}]}
{"op":"mcm","clk":"992981600","pt":1580534390441,"mc":[{"id":"1.168133543","rc":[{"batb":[[1,220,1.26],[2,170,4.13]],"ltp":280.0,"tv":1.54,"id":24270700}]}]}
{"op":"mcm","clk":"992981988","pt":1580534398556,"mc":[{"id":"1.168133543","rc":[{"batb":[[1,180,1.03],[2,170,3.21]],"ltp":280.0,"tv":1.54,"id":24270700}]}]}
{"op":"mcm","clk":"992981996","pt":1580534398658,"mc":[{"id":"1.168133543","rc":[{"batb":[[0,230,2.42]],"ltp":280.0,"tv":1.54,"id":24270700}]}]}
{"op":"mcm","clk":"992982729","pt":1580534414473,"mc":[{"id":"1.168133543","rc":[{"batb":[[0,230,1.32]],"ltp":280.0,"tv":1.54,"id":24270700}]}]}
{"op":"mcm","clk":"992982758","pt":1580534415189,"mc":[{"id":"1.168133543","rc":[{"batb":[[1,220,1.26],[2,170,4.13]],"ltp":280.0,"tv":1.54,"id":24270700}]}]}
{"op":"mcm","clk":"992983197","pt":1580534424568,"mc":[{"id":"1.168133543","rc":[{"batb":[[1,180,1.03],[2,170,3.21]],"ltp":280.0,"tv":1.54,"id":24270700}]}]}
{"op":"mcm","clk":"992983201","pt":1580534424669,"mc":[{"id":"1.168133543","rc":[{"batb":[[0,230,2.42]],"ltp":280.0,"tv":1.54,"id":24270700}]}]}
{"op":"mcm","clk":"992983825","pt":1580534440716,"mc":[{"id":"1.168133543","rc":[{"batb":[[0,230,1.32],[1,220,1.26],[2,170,4.13]],"ltp":280.0,"tv":1.54,"id":24270700}]}]}
{"op":"mcm","clk":"992983953","pt":1580534444219,"mc":[{"id":"1.168133543","rc":[{"batb":[[0,230,2.42],[1,180,1.03],[2,170,3.21]],"ltp":280.0,"tv":1.54,"id":24270700}]}]}
{"op":"mcm","clk":"992984638","pt":1580534459520,"mc":[{"id":"1.168133543","rc":[{"batb":[[0,230,1.32],[1,220,1.26],[2,170,4.13]],"ltp":280.0,"tv":1.54,"id":24270700}]}]}
{"op":"mcm","clk":"992984924","pt":1580534464547,"mc":[{"id":"1.168133543","rc":[{"batb":[[1,180,1.03],[2,170,3.21]],"ltp":280.0,"tv":1.54,"id":24270700}]}]}
{"op":"mcm","clk":"992984928","pt":1580534464650,"mc":[{"id":"1.168133543","rc":[{"batb":[[0,230,2.42]],"ltp":280.0,"tv":1.54,"id":24270700}]}]}
{"op":"mcm","clk":"992985557","pt":1580534481763,"mc":[{"id":"1.168133543","rc":[{"batb":[[0,230,1.32],[1,220,1.26],[2,170,4.13]],"ltp":280.0,"tv":1.54,"id":24270700}]}]}
{"op":"mcm","clk":"992986103","pt":1580534497559,"mc":[{"id":"1.168133543","rc":[{"batb":[[1,180,1.03],[2,170,3.21]],"ltp":280.0,"tv":1.54,"id":24270700}]}]}
{"op":"mcm","clk":"992986121","pt":1580534497865,"mc":[{"id":"1.168133543","rc":[{"batb":[[0,230,2.42]],"ltp":280.0,"tv":1.54,"id":24270700}]}]}
{"op":"mcm","clk":"992986245","pt":1580534500498,"mc":[{"id":"1.168133543","rc":[{"batb":[[0,230,1.32]],"ltp":280.0,"tv":1.54,"id":24270700}]}]}
{"op":"mcm","clk":"992986248","pt":1580534500602,"mc":[{"id":"1.168133543","rc":[{"batb":[[1,220,1.26],[2,170,4.13]],"ltp":280.0,"tv":1.54,"id":24270700}]}]}
{"op":"mcm","clk":"992986844","pt":1580534516505,"mc":[{"id":"1.168133543","rc":[{"batb":[[1,180,1.03],[2,170,3.21]],"ltp":280.0,"tv":1.54,"id":24270700}]}]}
{"op":"mcm","clk":"992986852","pt":1580534516609,"mc":[{"id":"1.168133543","rc":[{"batb":[[0,230,2.42]],"ltp":280.0,"tv":1.54,"id":24270700}]}]}
{"op":"mcm","clk":"992986983","pt":1580534519696,"mc":[{"id":"1.168133543","rc":[{"batb":[[0,230,1.32],[1,220,1.26],[2,170,4.13]],"ltp":280.0,"tv":1.54,"id":24270700}]}]}
{"op":"mcm","clk":"992987728","pt":1580534535521,"mc":[{"id":"1.168133543","rc":[{"batb":[[1,180,1.03],[2,170,3.21]],"ltp":280.0,"tv":1.54,"id":24270700}]}]}
{"op":"mcm","clk":"992987734","pt":1580534535623,"mc":[{"id":"1.168133543","rc":[{"batb":[[0,230,2.42]],"ltp":280.0,"tv":1.54,"id":24270700}]}]}
{"op":"mcm","clk":"992987943","pt":1580534539545,"mc":[{"id":"1.168133543","rc":[{"batb":[[0,230,1.32]],"ltp":280.0,"tv":1.54,"id":24270700}]}]}
{"op":"mcm","clk":"992987949","pt":1580534539596,"mc":[{"id":"1.168133543","rc":[{"batb":[[1,220,1.26],[2,170,4.13]],"ltp":280.0,"tv":1.54,"id":24270700}]}]}
{"op":"mcm","clk":"992998446","pt":1580534554551,"mc":[{"id":"1.168133543","rc":[{"batb":[[0,230,2.42],[1,180,1.03],[2,170,3.21]],"ltp":280.0,"tv":1.54,"id":24270700}]}]}
{"op":"mcm","clk":"992998662","pt":1580534558558,"mc":[{"id":"1.168133543","rc":[{"batb":[[0,230,1.32]],"ltp":280.0,"tv":1.54,"id":24270700}]}]}
{"op":"mcm","clk":"992998666","pt":1580534558665,"mc":[{"id":"1.168133543","rc":[{"batb":[[1,220,1.26],[2,170,4.13]],"ltp":280.0,"tv":1.54,"id":24270700}]}]}
{"op":"mcm","clk":"992999266","pt":1580534574560,"mc":[{"id":"1.168133543","rc":[{"batb":[[1,180,1.03],[2,170,3.21]],"ltp":280.0,"tv":1.54,"id":24270700}]}]}
{"op":"mcm","clk":"992999281","pt":1580534575074,"mc":[{"id":"1.168133543","rc":[{"batb":[[0,230,2.42]],"ltp":280.0,"tv":1.54,"id":24270700}]}]}
{"op":"mcm","clk":"992999383","pt":1580534577753,"mc":[{"id":"1.168133543","rc":[{"batb":[[0,230,1.32],[1,220,1.26],[2,170,4.13]],"ltp":280.0,"tv":1.54,"id":24270700}]}]}
{"op":"mcm","clk":"992999915","pt":1580534593491,"mc":[{"id":"1.168133543","rc":[{"batb":[[1,180,1.03],[2,170,3.21]],"ltp":280.0,"tv":1.54,"id":24270700}]}]}
{"op":"mcm","clk":"992999919","pt":1580534593592,"mc":[{"id":"1.168133543","rc":[{"batb":[[0,230,2.42]],"ltp":280.0,"tv":1.54,"id":24270700}]}]}
{"op":"mcm","clk":"993000022","pt":1580534596664,"mc":[{"id":"1.168133543","rc":[{"batb":[[0,230,1.32],[1,220,1.26],[2,170,4.13]],"ltp":280.0,"tv":1.54,"id":24270700}]}]}
{"op":"mcm","clk":"993000544","pt":1580534612681,"mc":[{"id":"1.168133543","rc":[{"batb":[[0,230,2.42],[1,180,1.03],[2,170,3.21]],"ltp":280.0,"tv":1.54,"id":24270700}]}]}
{"op":"mcm","clk":"993000646","pt":1580534615809,"mc":[{"id":"1.168133543","rc":[{"batb":[[0,230,1.32],[1,220,1.26],[2,170,4.13]],"ltp":280.0,"tv":1.54,"id":24270700}]}]}
{"op":"mcm","clk":"993001175","pt":1580534631719,"mc":[{"id":"1.168133543","rc":[{"batb":[[0,230,2.42],[1,180,1.03],[2,170,3.21]],"ltp":280.0,"tv":1.54,"id":24270700}]}]}
{"op":"mcm","clk":"993001290","pt":1580534634544,"mc":[{"id":"1.168133543","rc":[{"batb":[[0,230,1.32],[1,220,1.26],[2,170,4.13]],"ltp":280.0,"tv":1.54,"id":24270700}]}]}
{"op":"mcm","clk":"993002003","pt":1580534656558,"mc":[{"id":"1.168133543","rc":[{"batb":[[1,180,1.03],[2,170,3.21]],"ltp":280.0,"tv":1.54,"id":24270700}]}]}
{"op":"mcm","clk":"993002004","pt":1580534656660,"mc":[{"id":"1.168133543","rc":[{"batb":[[0,230,2.42]],"ltp":280.0,"tv":1.54,"id":24270700}]}]}
{"op":"mcm","clk":"993002644","pt":1580534672515,"mc":[{"id":"1.168133543","rc":[{"batb":[[0,230,1.32]],"ltp":280.0,"tv":1.54,"id":24270700}]}]}
{"op":"mcm","clk":"993002652","pt":1580534672721,"mc":[{"id":"1.168133543","rc":[{"batb":[[1,220,1.26],[2,170,4.13]],"ltp":280.0,"tv":1.54,"id":24270700}]}]}
{"op":"mcm","clk":"993002749","pt":1580534676109,"mc":[{"id":"1.168133543","rc":[{"batb":[[0,230,2.42],[1,180,1.03],[2,170,3.21]],"ltp":280.0,"tv":1.54,"id":24270700}]}]}
{"op":"mcm","clk":"993002922","pt":1580534681519,"mc":[{"id":"1.168133543","rc":[{"batb":[[0,230,1.32],[1,220,1.26],[2,170,4.13]],"ltp":280.0,"tv":1.54,"id":24270700}]}]}
{"op":"mcm","clk":"993003139","pt":1580534687497,"mc":[{"id":"1.168133543","rc":[{"batb":[[1,180,1.03],[2,170,3.21]],"ltp":280.0,"tv":1.54,"id":24270700}]}]}
{"op":"mcm","clk":"993003148","pt":1580534687599,"mc":[{"id":"1.168133543","rc":[{"batb":[[0,230,2.42]],"ltp":280.0,"tv":1.54,"id":24270700}]}]}
{"op":"mcm","clk":"993003280","pt":1580534691508,"mc":[{"id":"1.168133543","rc":[{"batb":[[0,230,1.32],[1,220,1.26],[2,170,4.13]],"ltp":280.0,"tv":1.54,"id":24270700}]}]}
{"op":"mcm","clk":"993005923","pt":1580534756316,"mc":[{"id":"1.168133543","rc":[{"batl":[[0,1000,2.35]],"ltp":280.0,"tv":1.54,"id":24270700}]}]}
{"op":"mcm","clk":"993006219","pt":1580534763505,"mc":[{"id":"1.168133543","rc":[{"batb":[[0,230,2.42],[1,180,1.03],[2,170,3.21]],"ltp":280.0,"tv":1.54,"id":24270700}]}]}
{"op":"mcm","clk":"993006925","pt":1580534779509,"mc":[{"id":"1.168133543","rc":[{"batb":[[0,230,1.32]],"ltp":280.0,"tv":1.54,"id":24270700}]}]}
{"op":"mcm","clk":"993006932","pt":1580534779612,"mc":[{"id":"1.168133543","rc":[{"batb":[[1,220,1.26],[2,170,4.13]],"ltp":280.0,"tv":1.54,"id":24270700}]}]}
{"op":"mcm","clk":"993007553","pt":1580534795554,"mc":[{"id":"1.168133543","rc":[{"batb":[[1,180,1.03],[2,170,3.21]],"ltp":280.0,"tv":1.54,"id":24270700}]}]}
{"op":"mcm","clk":"993007558","pt":1580534795657,"mc":[{"id":"1.168133543","rc":[{"batb":[[0,230,2.42]],"ltp":280.0,"tv":1.54,"id":24270700}]}]}
{"op":"mcm","clk":"993008207","pt":1580534814569,"mc":[{"id":"1.168133543","rc":[{"batb":[[0,230,1.32],[1,220,1.26],[2,170,4.13]],"ltp":280.0,"tv":1.54,"id":24270700}]}]}
{"op":"mcm","clk":"993008823","pt":1580534831702,"mc":[{"id":"1.168133543","rc":[{"batb":[[0,230,2.42],[1,180,1.03],[2,170,3.21]],"ltp":280.0,"tv":1.54,"id":24270700}]}]}
{"op":"mcm","clk":"993009349","pt":1580534847499,"mc":[{"id":"1.168133543","rc":[{"batb":[[0,230,1.32],[1,220,1.26],[2,170,4.13]],"ltp":280.0,"tv":1.54,"id":24270700}]}]}
{"op":"mcm","clk":"993010091","pt":1580534863554,"mc":[{"id":"1.168133543","rc":[{"batb":[[0,230,2.42],[1,180,1.03],[2,170,3.21]],"ltp":280.0,"tv":1.54,"id":24270700}]}]}
{"op":"mcm","clk":"993010759","pt":1580534879571,"mc":[{"id":"1.168133543","rc":[{"batb":[[0,230,1.32]],"ltp":280.0,"tv":1.54,"id":24270700}]}]}
{"op":"mcm","clk":"993010765","pt":1580534879676,"mc":[{"id":"1.168133543","rc":[{"batb":[[1,220,1.26],[2,170,4.13]],"ltp":280.0,"tv":1.54,"id":24270700}]}]}
{"op":"mcm","clk":"993010898","pt":1580534883268,"mc":[{"id":"1.168133543","rc":[{"trd":[[9.4,21.48]],"batb":[[0,9.2,5.68],[1,8.8,2.37],[2,8.6,7.91]],"ltp":9.4,"tv":349.32,"id":10163711}],"tv":4309.66}]}
{"op":"mcm","clk":"993011333","pt":1580534895551,"mc":[{"id":"1.168133543","rc":[{"batb":[[0,230,2.42],[1,180,1.03],[2,170,3.21]],"ltp":280.0,"tv":1.54,"id":24270700}]}]}
{"op":"mcm","clk":"993011819","pt":1580534911490,"mc":[{"id":"1.168133543","rc":[{"batb":[[0,230,1.32]],"ltp":280.0,"tv":1.54,"id":24270700}]}]}
{"op":"mcm","clk":"993011823","pt":1580534911592,"mc":[{"id":"1.168133543","rc":[{"batb":[[1,220,1.26],[2,170,4.13]],"ltp":280.0,"tv":1.54,"id":24270700}]}]}
{"op":"mcm","clk":"993012405","pt":1580534927521,"mc":[{"id":"1.168133543","rc":[{"batb":[[1,180,1.03],[2,170,3.21]],"ltp":280.0,"tv":1.54,"id":24270700}]}]}
{"op":"mcm","clk":"993012411","pt":1580534927624,"mc":[{"id":"1.168133543","rc":[{"batb":[[0,230,2.42]],"ltp":280.0,"tv":1.54,"id":24270700}]}]}
{"op":"mcm","clk":"993013002","pt":1580534943515,"mc":[{"id":"1.168133543","rc":[{"batb":[[0,230,1.32]],"ltp":280.0,"tv":1.54,"id":24270700}]}]}
{"op":"mcm","clk":"993013008","pt":1580534943620,"mc":[{"id":"1.168133543","rc":[{"batb":[[1,220,1.26],[2,170,4.13]],"ltp":280.0,"tv":1.54,"id":24270700}]}]}
{"op":"mcm","clk":"993013542","pt":1580534959562,"mc":[{"id":"1.168133543","rc":[{"batb":[[0,230,2.42],[1,180,1.03],[2,170,3.21]],"ltp":280.0,"tv":1.54,"id":24270700}]}]}
{"op":"mcm","clk":"993014033","pt":1580534975568,"mc":[{"id":"1.168133543","rc":[{"batb":[[0,230,1.32],[1,220,1.26],[2,170,4.13]],"ltp":280.0,"tv":1.54,"id":24270700}]}]}
{"op":"mcm","clk":"993014539","pt":1580534991507,"mc":[{"id":"1.168133543","rc":[{"batb":[[1,180,1.03],[2,170,3.21]],"ltp":280.0,"tv":1.54,"id":24270700}]}]}
{"op":"mcm","clk":"993014544","pt":1580534991615,"mc":[{"id":"1.168133543","rc":[{"batb":[[0,230,2.42]],"ltp":280.0,"tv":1.54,"id":24270700}]}]}
{"op":"mcm","clk":"993015162","pt":1580535007520,"mc":[{"id":"1.168133543","rc":[{"batb":[[0,230,1.32]],"ltp":280.0,"tv":1.54,"id":24270700}]}]}
{"op":"mcm","clk":"993015168","pt":1580535007621,"mc":[{"id":"1.168133543","rc":[{"batb":[[1,220,1.26],[2,170,4.13]],"ltp":280.0,"tv":1.54,"id":24270700}]}]}
{"op":"mcm","clk":"993015757","pt":1580535023573,"mc":[{"id":"1.168133543","rc":[{"batb":[[0,230,2.42],[1,180,1.03],[2,170,3.21]],"ltp":280.0,"tv":1.54,"id":24270700}]}]}
{"op":"mcm","clk":"993016269","pt":1580535038484,"mc":[{"id":"1.168133543","rc":[{"batb":[[0,230,1.32]],"ltp":280.0,"tv":1.54,"id":24270700}]}]}
{"op":"mcm","clk":"993016272","pt":1580535038585,"mc":[{"id":"1.168133543","rc":[{"batb":[[1,220,1.26],[2,170,4.13]],"ltp":280.0,"tv":1.54,"id":24270700}]}]}
{"op":"mcm","clk":"993016642","pt":1580535049070,"mc":[{"id":"1.168133543","rc":[{"batl":[[0,2.9,9]],"ltp":2.88,"tv":1073.56,"id":12636}]}]}
{"op":"mcm","clk":"993016871","pt":1580535055406,"mc":[{"id":"1.168133543","rc":[{"batb":[[0,230,2.42],[1,180,1.03],[2,170,3.21]],"ltp":280.0,"tv":1.54,"id":24270700}]}]}
{"op":"mcm","clk":"993017469","pt":1580535070721,"mc":[{"id":"1.168133543","rc":[{"batb":[[0,230,1.32],[1,220,1.26],[2,170,4.13]],"ltp":280.0,"tv":1.54,"id":24270700}]}]}
{"op":"mcm","clk":"993018367","pt":1580535087243,"mc":[{"id":"1.168133543","rc":[{"batb":[[0,230,2.42],[1,180,1.03],[2,170,3.21]],"ltp":280.0,"tv":1.54,"id":24270700}]}]}
{"op":"mcm","clk":"993019164","pt":1580535102679,"mc":[{"id":"1.168133543","rc":[{"batb":[[0,230,1.32],[1,220,1.26],[2,170,4.13]],"ltp":280.0,"tv":1.54,"id":24270700}]}]}
{"op":"mcm","clk":"993020050","pt":1580535118706,"mc":[{"id":"1.168133543","rc":[{"batb":[[0,230,2.42],[1,180,1.03],[2,170,3.21]],"ltp":280.0,"tv":1.54,"id":24270700}]}]}
{"op":"mcm","clk":"993020792","pt":1580535134508,"mc":[{"id":"1.168133543","rc":[{"batb":[[0,230,1.32]],"ltp":280.0,"tv":1.54,"id":24270700}]}]}
{"op":"mcm","clk":"993020800","pt":1580535134626,"mc":[{"id":"1.168133543","rc":[{"batb":[[1,220,1.26],[2,170,4.13]],"ltp":280.0,"tv":1.54,"id":24270700}]}]}
{"op":"mcm","clk":"993021781","pt":1580535150542,"mc":[{"id":"1.168133543","rc":[{"batb":[[1,180,1.03],[2,170,3.21]],"ltp":280.0,"tv":1.54,"id":24270700}]}]}
{"op":"mcm","clk":"993021783","pt":1580535150644,"mc":[{"id":"1.168133543","rc":[{"batb":[[0,230,2.42]],"ltp":280.0,"tv":1.54,"id":24270700}]}]}
