{"op":"mcm","clk":"992187540","pt":1580515745857,"mc":[{"id":"1.168130661","rc":[{"batl":[[1,170,2.95],[2,230,9]],"ltp":48.0,"tv":14.01,"id":25545675}]}]}
{"op":"mcm","clk":"992187823","pt":1580515760287,"mc":[{"id":"1.168130661","rc":[{"batb":[[0,2.72,11.03]],"ltp":2.94,"tv":1328.15,"id":25238892}]}]}
{"op":"mcm","clk":"992188136","pt":1580515775397,"mc":[{"id":"1.168130661","rc":[{"batb":[[0,2.72,3.47]],"ltp":2.94,"tv":1328.15,"id":25238892}]}]}
{"op":"mcm","clk":"992188267","pt":1580515781721,"mc":[{"id":"1.168130661","rc":[{"batl":[[1,170,3.28]],"ltp":48.0,"tv":14.01,"id":25545675}]}]}
{"op":"mcm","clk":"992188522","pt":1580515795362,"mc":[{"id":"1.168130661","rc":[{"batb":[[0,2.72,11.03]],"ltp":2.94,"tv":1328.15,"id":25238892}]}]}
{"op":"mcm","clk":"992188602","pt":1580515798712,"mc":[{"id":"1.168130661","rc":[{"batl":[[1,170,1.28]],"ltp":48.0,"tv":14.01,"id":25545675}]}]}
{"op":"mcm","clk":"992189063","pt":1580515812439,"mc":[{"id":"1.168130661","rc":[{"batb":[[0,2.72,3.47]],"ltp":2.94,"tv":1328.15,"id":25238892}]}]}
{"op":"mcm","clk":"992189629","pt":1580515828476,"mc":[{"id":"1.168130661","rc":[{"batb":[[0,2.72,11.03]],"ltp":2.94,"tv":1328.15,"id":25238892}]}]}
{"op":"mcm","clk":"992190028","pt":1580515844276,"mc":[{"id":"1.168130661","rc":[{"batb":[[0,2.72,3.47]],"ltp":2.94,"tv":1328.15,"id":25238892}]}]}
{"op":"mcm","clk":"992190299","pt":1580515852701,"mc":[{"id":"1.168130661","rc":[{"trd":[[2.72,51.93]],"batb":[[0,2.7,13.47],[1,2.58,1.98],[2,2.52,37.86]],"ltp":2.72,"tv":1358.15,"id":25238892},{"trd":[[14.5,3.35],[15,30.8]],"batl":[[0,15.5,10.05],[1,21,14.12],[2,24,2]],"ltp":15.0,"tv":94.74,"id":24707172},{"trd":[[12,4]],"batl":[[0,12.5,10],[1,14,2.52],[2,22,1.43]],"ltp":12.0,"tv":159.97,"id":24420205},{"trd":[[2.68,69.02]],"batb":[[0,2.66,13.68],[1,2.64,3.65],[2,2.62,133.13]],"ltp":2.68,"tv":820.3,"id":26314798},{"trd":[[10,51.56]],"batl":[[0,11,4],[1,24,2.6],[2,32,9]],"ltp":10.0,"tv":136.78,"id":420}],"tv":2583.97}]}
{"op":"mcm","clk":"992190301","pt":1580515852803,"mc":[{"id":"1.168130661","rc":[{"trd":[[48,3.36],[50,0.86]],"batl":[[0,50,1.57]],"ltp":50.0,"tv":14.91,"id":25545675},{"trd":[[12.5,1.18]],"batl":[[0,12.5,9.41]],"ltp":12.5,"tv":161.15,"id":24420205}],"tv":2586.05}]}
{"op":"mcm","clk":"992190369","pt":1580515854715,"mc":[{"id":"1.168130661","rc":[{"batb":[[0,29,1.32]],"batl":[[0,50,1.75]],"ltp":50.0,"tv":14.91,"id":25545675}]}]}
{"op":"mcm","clk":"992190384","pt":1580515855285,"mc":[{"id":"1.168130661","rc":[{"batb":[[0,10,2.92]],"ltp":12.5,"tv":161.15,"id":24420205},{"batb":[[0,10,1.72],[1,9.8,51.95],[2,8.4,3]],"ltp":10.0,"tv":136.78,"id":420}]}]}
{"op":"mcm","clk":"992191193","pt":1580515881715,"mc":[{"id":"1.168130661","rc":[{"batl":[[0,15.5,10]],"ltp":15.0,"tv":94.74,"id":24707172}]}]}
{"op":"mcm","clk":"992191227","pt":1580515882644,"mc":[{"id":"1.168130661","rc":[{"batb":[[0,13.5,1.28]],"batl":[[1,21,14.15]],"ltp":15.0,"tv":94.74,"id":24707172}]}]}
{"op":"mcm","clk":"992191249","pt":1580515883530,"mc":[{"id":"1.168130661","rc":[{"batl":[[0,50,2]],"ltp":50.0,"tv":14.91,"id":25545675}]}]}
{"op":"mcm","clk":"992191365","pt":1580515890432,"mc":[{"id":"1.168130661","rc":[{"batb":[[0,13.5,1.91]],"ltp":15.0,"tv":94.74,"id":24707172}]}]}
{"op":"mcm","clk":"992191524","pt":1580515898563,"mc":[{"id":"1.168130661","rc":[{"batl":[[0,11,7.5]],"ltp":10.0,"tv":136.78,"id":420}]}]}
{"op":"mcm","clk":"992191544","pt":1580515899442,"mc":[{"id":"1.168130661","rc":[{"batl":[[0,10.5,3.5],[1,11,4],[2,24,2.6]],"ltp":10.0,"tv":136.78,"id":420}]}]}
{"op":"mcm","clk":"992191583","pt":1580515900931,"mc":[{"id":"1.168130661","rc":[{"trd":[[10,55]],"batb":[[0,9.8,51.95],[1,8.4,3],[2,8,10]],"batl":[[0,10,1.78]],"ltp":10.0,"tv":140.22,"id":420}],"tv":2589.49}]}
{"op":"mcm","clk":"992192674","pt":1580515951202,"mc":[{"id":"1.168130661","rc":[{"batb":[[0,10,5.32]],"ltp":12.5,"tv":161.15,"id":24420205}]}]}
{"op":"mcm","clk":"992193438","pt":1580515982541,"mc":[{"id":"1.168130661","rc":[{"batb":[[0,2.72,6.34],[1,2.7,13.47],[2,2.58,1.98]],"ltp":2.72,"tv":1358.15,"id":25238892}]}]}
{"op":"mcm","clk":"992193598","pt":1580515987752,"mc":[{"id":"1.168130661","rc":[{"batb":[[0,2.72,37.17]],"ltp":2.72,"tv":1358.15,"id":25238892}]}]}
{"op":"mcm","clk":"992194002","pt":1580516003342,"mc":[{"id":"1.168130661","rc":[{"batb":[[0,2.72,6.34]],"ltp":2.72,"tv":1358.15,"id":25238892}]}]}
{"op":"mcm","clk":"992194054","pt":1580516004984,"mc":[{"id":"1.168130661","rc":[{"batl":[[0,15,2],[1,15.5,10],[2,21,14.15]],"ltp":15.0,"tv":94.74,"id":24707172}]}]}
{"op":"mcm","clk":"992194202","pt":1580516010370,"mc":[{"id":"1.168130661","rc":[{"batl":[[0,15,2.05],[2,21,14.12]],"ltp":15.0,"tv":94.74,"id":24707172}]}]}
{"op":"mcm","clk":"992194425","pt":1580516019378,"mc":[{"id":"1.168130661","rc":[{"batb":[[0,2.72,37.17]],"ltp":2.72,"tv":1358.15,"id":25238892}]}]}
{"op":"mcm","clk":"992194849","pt":1580516035596,"mc":[{"id":"1.168130661","rc":[{"batb":[[0,2.72,6.34]],"ltp":2.72,"tv":1358.15,"id":25238892}]}]}
{"op":"mcm","clk":"992195116","pt":1580516051508,"mc":[{"id":"1.168130661","rc":[{"batb":[[0,2.72,37.17]],"ltp":2.72,"tv":1358.15,"id":25238892}]}]}
{"op":"mcm","clk":"992195375","pt":1580516067587,"mc":[{"id":"1.168130661","rc":[{"batb":[[0,2.72,6.34]],"ltp":2.72,"tv":1358.15,"id":25238892}]}]}
{"op":"mcm","clk":"992195628","pt":1580516083342,"mc":[{"id":"1.168130661","rc":[{"batb":[[0,2.72,37.17]],"ltp":2.72,"tv":1358.15,"id":25238892}]}]}
{"op":"mcm","clk":"992195930","pt":1580516099565,"mc":[{"id":"1.168130661","rc":[{"batb":[[0,2.72,6.34]],"ltp":2.72,"tv":1358.15,"id":25238892}]}]}
{"op":"mcm","clk":"992196168","pt":1580516110627,"mc":[{"id":"1.168130661","rc":[{"batb":[[0,2.7,5.4],[1,2.66,13.68],[2,2.64,3.65]],"ltp":2.68,"tv":820.3,"id":26314798}]}]}
{"op":"mcm","clk":"992196282","pt":1580516115374,"mc":[{"id":"1.168130661","rc":[{"batb":[[0,2.72,37.17]],"ltp":2.72,"tv":1358.15,"id":25238892}]}]}
{"op":"mcm","clk":"992196610","pt":1580516130536,"mc":[{"id":"1.168130661","rc":[{"batb":[[0,2.72,6.34]],"ltp":2.72,"tv":1358.15,"id":25238892}]}]}
{"op":"mcm","clk":"992197019","pt":1580516146387,"mc":[{"id":"1.168130661","rc":[{"batb":[[0,2.72,37.17]],"ltp":2.72,"tv":1358.15,"id":25238892}]}]}
{"op":"mcm","clk":"992197428","pt":1580516162404,"mc":[{"id":"1.168130661","rc":[{"batb":[[0,2.72,6.34]],"ltp":2.72,"tv":1358.15,"id":25238892}]}]}
{"op":"mcm","clk":"992197905","pt":1580516178706,"mc":[{"id":"1.168130661","rc":[{"batb":[[0,2.72,37.17]],"ltp":2.72,"tv":1358.15,"id":25238892}]}]}
{"op":"mcm","clk":"992198305","pt":1580516194456,"mc":[{"id":"1.168130661","rc":[{"batb":[[0,2.72,6.34]],"ltp":2.72,"tv":1358.15,"id":25238892}]}]}
{"op":"mcm","clk":"992198679","pt":1580516206540,"mc":[{"id":"1.168130661","rc":[{"trd":[[14.5,3.45]],"batl":[[0,15,2]],"ltp":14.5,"tv":94.84,"id":24707172}],"tv":2589.59}]}
{"op":"mcm","clk":"992198740","pt":1580516210355,"mc":[{"id":"1.168130661","rc":[{"batb":[[0,2.72,37.17]],"ltp":2.72,"tv":1358.15,"id":25238892}]}]}
{"op":"mcm","clk":"992198880","pt":1580516215465,"mc":[{"id":"1.168130661","rc":[{"trd":[[15,34.8]],"batl":[[0,15.5,10],[1,21,14.12],[2,24,2]],"ltp":15.0,"tv":98.84,"id":24707172}],"tv":2593.59}]}
{"op":"mcm","clk":"992198985","pt":1580516218663,"mc":[{"id":"1.168130661","rc":[{"batb":[[0,13.5,1.28]],"ltp":15.0,"tv":98.84,"id":24707172}]}]}
{"op":"mcm","clk":"992199108","pt":1580516224290,"mc":[{"id":"1.168130661","rc":[{"batb":[[0,2.8,5.21],[1,2.72,37.17],[2,2.7,13.47]],"ltp":2.72,"tv":1358.15,"id":25238892}]}]}
{"op":"mcm","clk":"992199164","pt":1580516226460,"mc":[{"id":"1.168130661","rc":[{"batb":[[1,2.74,30.61],[2,2.72,6.34]],"ltp":2.72,"tv":1358.15,"id":25238892}]}]}
{"op":"mcm","clk":"992199241","pt":1580516229916,"mc":[{"id":"1.168130661","rc":[{"batl":[[2,3,10]],"ltp":2.72,"tv":1358.15,"id":25238892}]}]}
{"op":"mcm","clk":"992199540","pt":1580516242320,"mc":[{"id":"1.168130661","rc":[{"batb":[[1,2.72,6.34],[2,2.7,13.47]],"ltp":2.72,"tv":1358.15,"id":25238892}]}]}
{"op":"mcm","clk":"992200151","pt":1580516272669,"mc":[{"id":"1.168130661","rc":[{"batl":[[0,2.88,1.68],[1,3,10],[2,3.1,20]],"ltp":2.72,"tv":1358.15,"id":25238892},{"batb":[[0,13.5,3.5]],"ltp":15.0,"tv":98.84,"id":24707172}]}]}
{"op":"mcm","clk":"992200321","pt":1580516279646,"mc":[{"id":"1.168130661","rc":[{"trd":[[2.7,69.86]],"batb":[[0,2.66,13.68],[1,2.64,3.65],[2,2.62,133.13]],"batl":[[0,2.7,94.6],[1,2.72,6.21],[2,2.74,93.72]],"ltp":2.7,"tv":831.1,"id":26314798}],"tv":2604.39}]}
{"op":"mcm","clk":"992200365","pt":1580516281358,"mc":[{"id":"1.168130661","rc":[{"batl":[[1,2.98,100],[2,3,10]],"ltp":2.72,"tv":1358.15,"id":25238892}]}]}
{"op":"mcm","clk":"992200625","pt":1580516292692,"mc":[{"id":"1.168130661","rc":[{"batl":[[0,2.96,13.53]],"ltp":2.72,"tv":1358.15,"id":25238892}]}]}
{"op":"mcm","clk":"992200921","pt":1580516304878,"mc":[{"id":"1.168130661","rc":[{"batl":[[0,2.84,8.38],[1,2.96,13.53],[2,2.98,100]],"ltp":2.72,"tv":1358.15,"id":25238892}]}]}
{"op":"mcm","clk":"992202391","pt":1580516373334,"mc":[{"id":"1.168130661","rc":[{"batb":[[0,2.82,6.11],[1,2.8,5.21]],"batl":[[1,2.96,3.18]],"ltp":2.72,"tv":1358.15,"id":25238892}]}]}
{"op":"mcm","clk":"992202617","pt":1580516386671,"mc":[{"id":"1.168130661","rc":[{"batl":[[1,2.98,100],[2,3,10]],"ltp":2.72,"tv":1358.15,"id":25238892}]}]}
{"op":"mcm","clk":"992202636","pt":1580516387863,"mc":[{"id":"1.168130661","rc":[{"batl":[[1,2.96,8.4],[2,2.98,100]],"ltp":2.72,"tv":1358.15,"id":25238892}]}]}
{"op":"mcm","clk":"992202784","pt":1580516397152,"mc":[{"id":"1.168130661","rc":[{"trd":[[2.66,29.97]],"batb":[[0,2.66,3.67]],"ltp":2.66,"tv":851.1,"id":26314798}],"tv":2624.39}]}
{"op":"mcm","clk":"992202853","pt":1580516403296,"mc":[{"id":"1.168130661","rc":[{"batb":[[0,2.68,6.43],[1,2.66,3.67],[2,2.64,3.65]],"ltp":2.66,"tv":851.1,"id":26314798}]}]}
{"op":"mcm","clk":"992203042","pt":1580516416379,"mc":[{"id":"1.168130661","rc":[{"trd":[[10,87.35]],"batb":[[0,9.8,3.72],[1,9.4,1.6],[2,9.2,2.68]],"ltp":10.0,"tv":171.78,"id":24420205}],"tv":2635.02}]}
{"op":"mcm","clk":"992204222","pt":1580516464354,"mc":[{"id":"1.168130661","rc":[{"trd":[[2.82,96.32]],"batb":[[0,2.8,5.21],[1,2.7,13.47],[2,2.58,1.98]],"batl":[[0,2.82,2.33]],"ltp":2.82,"tv":1370.37,"id":25238892}],"tv":2647.24}]}
{"op":"mcm","clk":"992204326","pt":1580516468351,"mc":[{"id":"1.168130661","rc":[{"batl":[[1,2.94,4],[2,2.96,8.4]],"ltp":2.82,"tv":1370.37,"id":25238892}]}]}
{"op":"mcm","clk":"992204758","pt":1580516486507,"mc":[{"id":"1.168130661","rc":[{"batl":[[0,12,2],[1,12.5,9.41],[2,14,2.52]],"ltp":10.0,"tv":171.78,"id":24420205}]}]}
{"op":"mcm","clk":"992216947","pt":1580516589625,"mc":[{"id":"1.168130661","rc":[{"trd":[[2.8,63.17]],"batb":[[0,2.8,2.86]],"batl":[[0,2.94,14.4],[1,2.96,8.4],[2,2.98,100]],"ltp":2.8,"tv":1375.07,"id":25238892}],"tv":2651.94}]}
{"op":"mcm","clk":"992216953","pt":1580516589833,"mc":[{"id":"1.168130661","rc":[{"batl":[[1,2.98,100],[2,3,10]],"ltp":2.8,"tv":1375.07,"id":25238892}]}]}
{"op":"mcm","clk":"992217018","pt":1580516592832,"mc":[{"id":"1.168130661","rc":[{"batl":[[0,2.92,2],[1,2.94,14.4],[2,2.98,100]],"ltp":2.8,"tv":1375.07,"id":25238892}]}]}
{"op":"mcm","clk":"992217066","pt":1580516595252,"mc":[{"id":"1.168130661","rc":[{"trd":[[2.7,88.4]],"batl":[[0,2.7,85.33]],"ltp":2.7,"tv":869.64,"id":26314798}],"tv":2670.48}]}
{"op":"mcm","clk":"992217299","pt":1580516606034,"mc":[{"id":"1.168130661","rc":[{"batl":[[0,2.9,3.25],[1,2.92,2],[2,2.94,14.4]],"ltp":2.8,"tv":1375.07,"id":25238892}]}]}
{"op":"mcm","clk":"992217502","pt":1580516614359,"mc":[{"id":"1.168130661","rc":[{"batb":[[0,14,4.62],[1,13.5,3.5],[2,13,4.7]],"ltp":15.0,"tv":98.84,"id":24707172}]}]}
{"op":"mcm","clk":"992217811","pt":1580516623563,"mc":[{"id":"1.168130661","rc":[{"batl":[[2,2.94,10.4]],"ltp":2.8,"tv":1375.07,"id":25238892},{"batb":[[0,14.5,4.62]],"ltp":15.0,"tv":98.84,"id":24707172}]}]}
{"op":"mcm","clk":"992218439","pt":1580516646334,"mc":[{"id":"1.168130661","rc":[{"batl":[[1,2.94,10.4],[2,2.96,6]],"ltp":2.8,"tv":1375.07,"id":25238892}]}]}
{"op":"mcm","clk":"992218747","pt":1580516656713,"mc":[{"id":"1.168130661","rc":[{"trd":[[14.5,12.69]],"batb":[[0,13.5,3.5],[1,13,4.7],[2,12.5,2]],"ltp":14.5,"tv":108.08,"id":24707172}],"tv":2679.72}]}
{"op":"mcm","clk":"992219098","pt":1580516669404,"mc":[{"id":"1.168130661","rc":[{"batl":[[0,2.92,3.23]],"ltp":2.8,"tv":1375.07,"id":25238892}]}]}
{"op":"mcm","clk":"992219247","pt":1580516676134,"mc":[{"id":"1.168130661","rc":[{"trd":[[2.7,259.06]],"batl":[[0,2.72,6.21],[1,2.74,93.72],[2,2.8,6]],"ltp":2.7,"tv":1040.3,"id":26314798}],"tv":2850.38}]}
{"op":"mcm","clk":"992220033","pt":1580516707455,"mc":[{"id":"1.168130661","rc":[{"batl":[[2,60,9.45]],"ltp":14.5,"tv":108.08,"id":24707172},{"batl":[[2,32,9.6]],"ltp":10.0,"tv":140.22,"id":420}]}]}
{"op":"mcm","clk":"992225963","pt":1580516950707,"mc":[{"id":"1.168130661","rc":[{"trd":[[9.8,24.1]],"batb":[[0,9.8,49.95]],"ltp":9.8,"tv":144.22,"id":420}],"tv":2854.38}]}
{"op":"mcm","clk":"992227390","pt":1580517001686,"mc":[{"id":"1.168130661","rc":[{"batl":[[0,15,10],[1,15.5,10],[2,21,14.12]],"ltp":14.5,"tv":108.08,"id":24707172}]}]}
{"op":"mcm","clk":"992232916","pt":1580517164600,"mc":[{"id":"1.168130661","rc":[{"batb":[[1,2.72,1.68],[2,2.7,13.47]],"ltp":2.8,"tv":1375.07,"id":25238892},{"batb":[[1,2.66,5.35]],"ltp":2.7,"tv":1040.3,"id":26314798},{"trd":[[10,58.53]],"batl":[[0,11,4.02],[1,32,9.6],[2,170,0.33]],"ltp":10.0,"tv":147.74,"id":420}],"tv":2857.91}]}
{"op":"mcm","clk":"992236700","pt":1580517300891,"mc":[{"id":"1.168130661","rc":[{"trd":[[2.8,63.48]],"batb":[[0,2.8,2.71]],"ltp":2.8,"tv":1375.37,"id":25238892}],"tv":2858.21}]}
{"op":"mcm","clk":"992236795","pt":1580517303885,"mc":[{"id":"1.168130661","rc":[{"trd":[[2.8,63.78]],"batb":[[0,2.8,2.56]],"ltp":2.8,"tv":1375.67,"id":25238892}],"tv":2858.51}]}
{"op":"mcm","clk":"992238995","pt":1580517377568,"mc":[{"id":"1.168130661","rc":[{"trd":[[9.8,26.76],[10,87.37]],"batb":[[0,9.4,1.6],[1,9.2,2.68],[2,9,1.96]],"ltp":9.8,"tv":179.22,"id":24420205}],"tv":2865.95}]}
{"op":"mcm","clk":"992239042","pt":1580517379583,"mc":[{"id":"1.168130661","rc":[{"batb":[[2,8.8,3.71]],"ltp":9.8,"tv":179.22,"id":24420205}]}]}
{"op":"mcm","clk":"992239737","pt":1580517405998,"mc":[{"id":"1.168130661","rc":[{"trd":[[2.72,43.76]],"batl":[[0,2.72,4.21]],"ltp":2.72,"tv":1044.3,"id":26314798}],"tv":2869.95}]}
{"op":"mcm","clk":"992240994","pt":1580517444564,"mc":[{"id":"1.168130661","rc":[{"batb":[[0,13.5,25.5]],"ltp":14.5,"tv":108.08,"id":24707172}]}]}
{"op":"mcm","clk":"992241134","pt":1580517451582,"mc":[{"id":"1.168130661","rc":[{"batb":[[0,14,1.26],[1,13.5,25.5],[2,13,4.7]],"ltp":14.5,"tv":108.08,"id":24707172}]}]}
{"op":"mcm","clk":"992251276","pt":1580517472636,"mc":[{"id":"1.168130661","rc":[{"batb":[[0,29,10.32]],"ltp":50.0,"tv":14.91,"id":25545675}]}]}
{"op":"mcm","clk":"992251296","pt":1580517473356,"mc":[{"id":"1.168130661","rc":[{"batb":[[0,29,10.49]],"ltp":50.0,"tv":14.91,"id":25545675}]}]}
{"op":"mcm","clk":"992251430","pt":1580517482041,"mc":[{"id":"1.168130661","rc":[{"batb":[[0,29,11.09]],"ltp":50.0,"tv":14.91,"id":25545675}]}]}
{"op":"mcm","clk":"992251707","pt":1580517501101,"mc":[{"id":"1.168130661","rc":[{"trd":[[2.68,73.06]],"batb":[[0,2.68,4.41]],"ltp":2.68,"tv":1048.34,"id":26314798}],"tv":2873.99}]}
{"op":"mcm","clk":"992251781","pt":1580517506503,"mc":[{"id":"1.168130661","rc":[{"batb":[[0,29,10.4]],"ltp":50.0,"tv":14.91,"id":25545675}]}]}
{"op":"mcm","clk":"992251999","pt":1580517512388,"mc":[{"id":"1.168130661","rc":[{"batb":[[2,2.64,6.65]],"ltp":2.68,"tv":1048.34,"id":26314798}]}]}
{"op":"mcm","clk":"992255205","pt":1580517663700,"mc":[{"id":"1.168130661","rc":[{"batb":[[0,30,1.37],[1,29,9.6],[2,28,1.04]],"ltp":50.0,"tv":14.91,"id":25545675}]}]}
{"op":"mcm","clk":"992261311","pt":1580517952703,"mc":[{"id":"1.168130661","rc":[{"trd":[[9.8,28.1]],"batb":[[0,9.8,47.95]],"ltp":9.8,"tv":151.74,"id":420}],"tv":2877.99}]}
{"op":"mcm","clk":"992261336","pt":1580517954148,"mc":[{"id":"1.168130661","rc":[{"batl":[[1,18.5,2.31],[2,32,9]],"ltp":9.8,"tv":151.74,"id":420}]}]}
{"op":"mcm","clk":"992261362","pt":1580517955547,"mc":[{"id":"1.168130661","rc":[{"trd":[[2.92,6.47]],"batl":[[0,2.94,10.4],[1,2.96,6],[2,2.98,100]],"ltp":2.92,"tv":1382.15,"id":25238892}],"tv":2884.46}]}
{"op":"mcm","clk":"992261455","pt":1580517960553,"mc":[{"id":"1.168130661","rc":[{"batb":[[1,2.74,2.06],[2,2.72,1.68]],"batl":[[0,2.92,1.93],[1,2.94,10.4],[2,2.96,6]],"ltp":2.92,"tv":1382.15,"id":25238892}]}]}
{"op":"mcm","clk":"992263070","pt":1580518021384,"mc":[{"id":"1.168130661","rc":[{"batb":[[2,8.2,4.73]],"ltp":9.8,"tv":151.74,"id":420}]}]}
{"op":"mcm","clk":"992263725","pt":1580518050023,"mc":[{"id":"1.168130661","rc":[{"batb":[[2,8.2,9.99]],"ltp":9.8,"tv":151.74,"id":420}]}]}
{"op":"mcm","clk":"992264253","pt":1580518074456,"mc":[{"id":"1.168130661","rc":[{"batl":[[0,10,7],[1,12,2],[2,12.5,9.41]],"ltp":9.8,"tv":179.22,"id":24420205}]}]}
{"op":"mcm","clk":"992264303","pt":1580518076831,"mc":[{"id":"1.168130661","rc":[{"batl":[[0,9.8,7]],"ltp":9.8,"tv":179.22,"id":24420205}]}]}
{"op":"mcm","clk":"992264355","pt":1580518079661,"mc":[{"id":"1.168130661","rc":[{"batl":[[0,9.6,7]],"ltp":9.8,"tv":179.22,"id":24420205}]}]}
{"op":"mcm","clk":"992264358","pt":1580518079766,"mc":[{"id":"1.168130661","rc":[{"trd":[[9.6,6.54]],"batl":[[0,9.6,3.73]],"ltp":9.6,"tv":185.76,"id":24420205}],"tv":2891.0}]}
{"op":"mcm","clk":"992264413","pt":1580518082561,"mc":[{"id":"1.168130661","rc":[{"batl":[[0,9.8,3.73]],"ltp":9.6,"tv":185.76,"id":24420205}]}]}
{"op":"mcm","clk":"992264486","pt":1580518085645,"mc":[{"id":"1.168130661","rc":[{"trd":[[9.6,14]],"batl":[[0,12,2],[1,12.5,9.41],[2,14,2.52]],"ltp":9.6,"tv":193.22,"id":24420205}],"tv":2898.46}]}
{"op":"mcm","clk":"992269635","pt":1580518299887,"mc":[{"id":"1.168130661","rc":[{"batl":[[0,2.92,3.93]],"ltp":2.92,"tv":1382.15,"id":25238892}]}]}
{"op":"mcm","clk":"992289439","pt":1580518735573,"mc":[{"id":"1.168130661","rc":[{"batb":[[0,30,2]],"ltp":50.0,"tv":14.91,"id":25545675}]}]}
{"op":"mcm","clk":"992289729","pt":1580518748501,"mc":[{"id":"1.168130661","rc":[{"batb":[[0,32,3.41],[1,30,1.11],[2,29,9.6]],"ltp":50.0,"tv":14.91,"id":25545675}]}]}
{"op":"mcm","clk":"992291104","pt":1580518802683,"mc":[{"id":"1.168130661","rc":[{"batb":[[0,32,2.78]],"ltp":50.0,"tv":14.91,"id":25545675}]}]}
{"op":"mcm","clk":"992291448","pt":1580518811691,"mc":[{"id":"1.168130661","rc":[{"batb":[[0,30,1.37],[1,29,9.6],[2,28,1.04]],"ltp":50.0,"tv":14.91,"id":25545675}]}]}
{"op":"mcm","clk":"992291452","pt":1580518811788,"mc":[{"id":"1.168130661","rc":[{"batb":[[0,30,3.89]],"ltp":50.0,"tv":14.91,"id":25545675}]}]}
{"op":"mcm","clk":"992291526","pt":1580518814473,"mc":[{"id":"1.168130661","rc":[{"batb":[[0,32,1.42],[1,30,3.63],[2,29,9.6]],"ltp":50.0,"tv":14.91,"id":25545675}]}]}
{"op":"mcm","clk":"992291722","pt":1580518819292,"mc":[{"id":"1.168130661","rc":[{"batb":[[0,32,5.37]],"ltp":50.0,"tv":14.91,"id":25545675}]}]}
{"op":"mcm","clk":"992292261","pt":1580518835389,"mc":[{"id":"1.168130661","rc":[{"batb":[[0,32,1.42]],"ltp":50.0,"tv":14.91,"id":25545675}]}]}
{"op":"mcm","clk":"992292750","pt":1580518851331,"mc":[{"id":"1.168130661","rc":[{"batb":[[0,32,5.37]],"ltp":50.0,"tv":14.91,"id":25545675}]}]}
{"op":"mcm","clk":"992293250","pt":1580518867443,"mc":[{"id":"1.168130661","rc":[{"batb":[[0,32,1.42]],"ltp":50.0,"tv":14.91,"id":25545675}]}]}
{"op":"mcm","clk":"992293750","pt":1580518875855,"mc":[{"id":"1.168130661","rc":[{"trd":[[2.72,47.76]],"batl":[[0,2.72,2.21]],"ltp":2.72,"tv":1052.34,"id":26314798}],"tv":2902.46}]}
{"op":"mcm","clk":"992294180","pt":1580518885966,"mc":[{"id":"1.168130661","rc":[{"trd":[[2.68,77.12]],"batb":[[0,2.68,2.38]],"ltp":2.68,"tv":1056.4,"id":26314798}],"tv":2906.53}]}
{"op":"mcm","clk":"992294948","pt":1580518899704,"mc":[{"id":"1.168130661","rc":[{"batb":[[0,32,5.37]],"ltp":50.0,"tv":14.91,"id":25545675}]}]}
{"op":"mcm","clk":"992295425","pt":1580518913533,"mc":[{"id":"1.168130661","rc":[{"batb":[[0,34,2.23],[1,32,5.37],[2,30,1.11]],"ltp":50.0,"tv":14.91,"id":25545675}]}]}
{"op":"mcm","clk":"992295465","pt":1580518915400,"mc":[{"id":"1.168130661","rc":[{"batb":[[1,32,1.42]],"ltp":50.0,"tv":14.91,"id":25545675}]}]}
{"op":"mcm","clk":"992296273","pt":1580518945661,"mc":[{"id":"1.168130661","rc":[{"batb":[[0,32,3.94],[1,30,1.11],[2,29,9.6]],"ltp":50.0,"tv":14.91,"id":25545675}]}]}
{"op":"mcm","clk":"992297033","pt":1580518972396,"mc":[{"id":"1.168130661","rc":[{"batl":[[2,2.78,11.72]],"ltp":2.68,"tv":1056.4,"id":26314798}]}]}
{"op":"mcm","clk":"992297508","pt":1580518994747,"mc":[{"id":"1.168130661","rc":[{"batl":[[2,2.78,110.72]],"ltp":2.68,"tv":1056.4,"id":26314798}]}]}
{"op":"mcm","clk":"992299367","pt":1580519073057,"mc":[{"id":"1.168130661","rc":[{"batb":[[0,32,4.44],[1,29,10.14],[2,28,1.04]],"ltp":50.0,"tv":14.91,"id":25545675}]}]}
{"op":"mcm","clk":"992299538","pt":1580519078161,"mc":[{"id":"1.168130661","rc":[{"batl":[[2,2.76,199]],"ltp":2.68,"tv":1056.4,"id":26314798}]}]}
{"op":"mcm","clk":"992299826","pt":1580519088380,"mc":[{"id":"1.168130661","rc":[{"batb":[[2,2.64,3.65]],"ltp":2.68,"tv":1056.4,"id":26314798}]}]}
{"op":"mcm","clk":"992315202","pt":1580519318642,"mc":[{"id":"1.168130661","rc":[{"batl":[[0,2.92,1.93]],"ltp":2.92,"tv":1382.15,"id":25238892}]}]}
{"op":"mcm","clk":"992315203","pt":1580519318744,"mc":[{"id":"1.168130661","rc":[{"trd":[[2.92,10.34],[2.94,0.17]],"batl":[[0,2.94,10.33],[1,2.96,6],[2,2.98,100]],"ltp":2.94,"tv":1386.15,"id":25238892}],"tv":2910.53}]}
{"op":"mcm","clk":"992319173","pt":1580519468031,"mc":[{"id":"1.168130661","rc":[{"trd":[[15,38.88]],"batl":[[0,15,7.96]],"ltp":15.0,"tv":112.16,"id":24707172}],"tv":2914.61}]}
{"op":"mcm","clk":"992325586","pt":1580519741417,"mc":[{"id":"1.168130661","rc":[{"batl":[[1,15,2],[2,18.5,2.31]],"ltp":9.8,"tv":151.74,"id":420}]}]}
{"op":"mcm","clk":"992325704","pt":1580519746438,"mc":[{"id":"1.168130661","rc":[{"batl":[[1,18.5,2.31],[2,32,9]],"ltp":9.8,"tv":151.74,"id":420}]}]}
{"op":"mcm","clk":"992331040","pt":1580519962704,"mc":[{"id":"1.168130661","rc":[{"batl":[[0,2.9,1.51],[1,2.94,10.33],[2,2.96,6]],"ltp":2.94,"tv":1386.15,"id":25238892}]}]}
{"op":"mcm","clk":"992331053","pt":1580519963073,"mc":[{"id":"1.168130661","rc":[{"batl":[[0,2.94,10.33],[1,2.96,6],[2,2.98,100]],"ltp":2.94,"tv":1386.15,"id":25238892}]}]}
{"op":"mcm","clk":"992331654","pt":1580519987107,"mc":[{"id":"1.168130661","rc":[{"trd":[[2.68,77.78]],"batb":[[0,2.68,2.05]],"ltp":2.68,"tv":1057.06,"id":26314798}],"tv":2915.27}]}
{"op":"mcm","clk":"992332624","pt":1580520025958,"mc":[{"id":"1.168130661","rc":[{"batl":[[0,2.92,4],[1,2.94,10.33],[2,2.96,6]],"ltp":2.94,"tv":1386.15,"id":25238892}]}]}
{"op":"mcm","clk":"992352437","pt":1580520425241,"mc":[{"id":"1.168130661","rc":[{"batb":[[0,2.7,29],[1,2.68,2.05],[2,2.66,5.35]],"ltp":2.68,"tv":1057.06,"id":26314798}]}]}
{"op":"mcm","clk":"992352575","pt":1580520431333,"mc":[{"id":"1.168130661","rc":[{"batb":[[2,2.66,3.67]],"ltp":2.68,"tv":1057.06,"id":26314798}]}]}
{"op":"mcm","clk":"992352759","pt":1580520438978,"mc":[{"id":"1.168130661","rc":[{"trd":[[2.72,51.12]],"batl":[[0,2.74,94.25],[1,2.76,199],[2,2.78,110.72]],"ltp":2.72,"tv":1060.42,"id":26314798}],"tv":2918.63}]}
{"op":"mcm","clk":"992352984","pt":1580520447206,"mc":[{"id":"1.168130661","rc":[{"trd":[[2.72,52.18]],"batb":[[0,2.72,1.15],[1,2.7,29],[2,2.68,2.05]],"batl":[[0,2.74,93.72]],"ltp":2.72,"tv":1061.48,"id":26314798}],"tv":2919.69}]}
{"op":"mcm","clk":"992355407","pt":1580520533906,"mc":[{"id":"1.168130661","rc":[{"trd":[[9.2,0.8],[9.4,8.23]],"batb":[[0,9.2,2.28],[1,8.8,3.71],[2,8.4,3.66]],"ltp":9.2,"tv":197.22,"id":24420205}],"tv":2923.68}]}
{"op":"mcm","clk":"992355477","pt":1580520536284,"mc":[{"id":"1.168130661","rc":[{"batb":[[2,8.4,2.1]],"ltp":9.2,"tv":197.22,"id":24420205}]}]}
{"op":"mcm","clk":"992367201","pt":1580520978264,"mc":[{"id":"1.168130661","rc":[{"trd":[[13.5,25.49],[14,2.52]],"batb":[[0,13.5,14.75],[1,13,4.7],[2,12.5,2]],"ltp":13.5,"tv":136.17,"id":24707172}],"tv":2947.7}]}
{"op":"mcm","clk":"992367249","pt":1580520980751,"mc":[{"id":"1.168130661","rc":[{"batl":[[0,2.92,6]],"ltp":2.94,"tv":1386.15,"id":25238892}]}]}
{"op":"mcm","clk":"992367973","pt":1580521014110,"mc":[{"id":"1.168130661","rc":[{"batl":[[0,2.92,2]],"ltp":2.94,"tv":1386.15,"id":25238892}]}]}
{"op":"mcm","clk":"992368860","pt":1580521047718,"mc":[{"id":"1.168130661","rc":[{"trd":[[2.8,68.9]],"batb":[[0,2.74,2.06],[1,2.72,1.68],[2,2.7,13.47]],"batl":[[0,2.92,2.44],[1,2.96,6],[2,2.98,100]],"ltp":2.8,"tv":1391.27,"id":25238892}],"tv":2952.82}]}
{"op":"mcm","clk":"992368869","pt":1580521048595,"mc":[{"id":"1.168130661","rc":[{"batb":[[1,2.72,32.52]],"ltp":2.8,"tv":1391.27,"id":25238892}]}]}
{"op":"mcm","clk":"992378822","pt":1580521056530,"mc":[{"id":"1.168130661","rc":[{"batb":[[0,32,8.4]],"ltp":50.0,"tv":14.91,"id":25545675},{"batb":[[1,2.72,1.68]],"ltp":2.8,"tv":1391.27,"id":25238892}]}]}
{"op":"mcm","clk":"992378880","pt":1580521060453,"mc":[{"id":"1.168130661","rc":[{"batl":[[1,2.94,3.36],[2,2.96,6]],"ltp":2.8,"tv":1391.27,"id":25238892}]}]}
{"op":"mcm","clk":"992378902","pt":1580521061426,"mc":[{"id":"1.168130661","rc":[{"batl":[[1,2.94,5.04]],"ltp":2.8,"tv":1391.27,"id":25238892}]}]}
{"op":"mcm","clk":"992378913","pt":1580521062452,"mc":[{"id":"1.168130661","rc":[{"batl":[[0,2.86,2.12],[1,2.88,3.36],[2,2.9,1.68]],"ltp":2.8,"tv":1391.27,"id":25238892}]}]}
{"op":"mcm","clk":"992378947","pt":1580521064556,"mc":[{"id":"1.168130661","rc":[{"batl":[[0,2.86,3.8],[1,2.88,5.04],[2,2.9,3.36]],"ltp":2.8,"tv":1391.27,"id":25238892}]}]}
{"op":"mcm","clk":"992378996","pt":1580521066619,"mc":[{"id":"1.168130661","rc":[{"batl":[[0,2.86,5.48]],"ltp":2.8,"tv":1391.27,"id":25238892}]}]}
{"op":"mcm","clk":"992379006","pt":1580521067235,"mc":[{"id":"1.168130661","rc":[{"batl":[[1,2.88,6.72]],"ltp":2.8,"tv":1391.27,"id":25238892}]}]}
{"op":"mcm","clk":"992379163","pt":1580521075351,"mc":[{"id":"1.168130661","rc":[{"batb":[[1,9,7.04],[2,8.8,3.71]],"ltp":9.2,"tv":197.22,"id":24420205}]}]}
{"op":"mcm","clk":"992379456","pt":1580521088193,"mc":[{"id":"1.168130661","rc":[{"batb":[[1,9,8.99]],"ltp":9.2,"tv":197.22,"id":24420205}]}]}
{"op":"mcm","clk":"992380369","pt":1580521141542,"mc":[{"id":"1.168130661","rc":[{"batb":[[0,2.74,18.72]],"ltp":2.8,"tv":1391.27,"id":25238892}]}]}
{"op":"mcm","clk":"992380404","pt":1580521144368,"mc":[{"id":"1.168130661","rc":[{"batb":[[1,2.7,13.47],[2,2.6,16.66]],"ltp":2.8,"tv":1391.27,"id":25238892}]}]}
{"op":"mcm","clk":"992380469","pt":1580521149468,"mc":[{"id":"1.168130661","rc":[{"batb":[[0,2.74,2.06],[1,2.72,16.66],[2,2.7,13.47]],"ltp":2.8,"tv":1391.27,"id":25238892}]}]}
{"op":"mcm","clk":"992380512","pt":1580521152145,"mc":[{"id":"1.168130661","rc":[{"batb":[[0,2.74,3.74]],"ltp":2.8,"tv":1391.27,"id":25238892}]}]}
{"op":"mcm","clk":"992380555","pt":1580521154461,"mc":[{"id":"1.168130661","rc":[{"batb":[[0,2.74,20.4],[1,2.7,13.47],[2,2.6,16.66]],"ltp":2.8,"tv":1391.27,"id":25238892}]}]}
{"op":"mcm","clk":"992380620","pt":1580521158677,"mc":[{"id":"1.168130661","rc":[{"batb":[[0,2.76,3],[1,2.74,20.4],[2,2.7,13.47]],"ltp":2.8,"tv":1391.27,"id":25238892}]}]}
{"op":"mcm","clk":"992381134","pt":1580521186604,"mc":[{"id":"1.168130661","rc":[{"batb":[[0,2.78,2.02],[1,2.76,3],[2,2.74,18.34]],"ltp":2.8,"tv":1391.27,"id":25238892}]}]}
{"op":"mcm","clk":"992381670","pt":1580521199572,"mc":[{"id":"1.168130661","rc":[{"batb":[[1,2.74,18.34],[2,2.7,13.47]],"ltp":2.8,"tv":1391.27,"id":25238892}]}]}
{"op":"mcm","clk":"992382035","pt":1580521218521,"mc":[{"id":"1.168130661","rc":[{"batb":[[0,2.76,2.02]],"ltp":2.8,"tv":1391.27,"id":25238892}]}]}
{"op":"mcm","clk":"992383613","pt":1580521293230,"mc":[{"id":"1.168130661","rc":[{"batb":[[0,14,1.23],[1,13.5,14.75],[2,13,4.7]],"ltp":13.5,"tv":136.17,"id":24707172}]}]}
{"op":"mcm","clk":"992393915","pt":1580521746486,"mc":[{"id":"1.168130661","rc":[{"batb":[[2,8.2,5.26]],"ltp":9.8,"tv":151.74,"id":420}]}]}
{"op":"mcm","clk":"992393934","pt":1580521747465,"mc":[{"id":"1.168130661","rc":[{"batb":[[2,8.2,9.2]],"ltp":9.8,"tv":151.74,"id":420}]}]}
{"op":"mcm","clk":"992396397","pt":1580521854127,"mc":[{"id":"1.168130661","rc":[{"batb":[[2,8.2,3.95]],"ltp":9.8,"tv":151.74,"id":420}]}]}
{"op":"mcm","clk":"992396415","pt":1580521854802,"mc":[{"id":"1.168130661","rc":[{"batb":[[2,8.2,8.33]],"ltp":9.8,"tv":151.74,"id":420}]}]}
{"op":"mcm","clk":"992418531","pt":1580522331707,"mc":[{"id":"1.168130661","rc":[{"trd":[[2.7,260.76],[2.72,54.48]],"batb":[[0,2.7,28.15],[1,2.68,2.05],[2,2.66,3.67]],"ltp":2.7,"tv":1065.48,"id":26314798}],"tv":2956.82}]}
{"op":"mcm","clk":"992418564","pt":1580522332590,"mc":[{"id":"1.168130661","rc":[{"batb":[[0,2.72,3.13],[1,2.7,28.15],[2,2.68,2.05]],"ltp":2.7,"tv":1065.48,"id":26314798}]}]}
{"op":"mcm","clk":"992418698","pt":1580522338630,"mc":[{"id":"1.168130661","rc":[{"trd":[[2.78,243.8]],"batl":[[0,2.86,5.64]],"ltp":2.78,"tv":1397.01,"id":25238892}],"tv":2962.56}]}
{"op":"mcm","clk":"992418721","pt":1580522339608,"mc":[{"id":"1.168130661","rc":[{"trd":[[2.76,185.63],[2.78,244.12]],"batb":[[0,2.74,18.36],[1,2.7,13.47],[2,2.6,16.66]],"batl":[[0,2.86,5.48]],"ltp":2.76,"tv":1401.33,"id":25238892}],"tv":2966.88}]}
{"op":"mcm","clk":"992418787","pt":1580522342236,"mc":[{"id":"1.168130661","rc":[{"trd":[[2.8,69.78]],"batb":[[0,2.8,2.57],[1,2.74,18.36],[2,2.7,13.47]],"batl":[[0,2.84,10.6],[1,2.86,5.04],[2,2.88,6.72]],"ltp":2.8,"tv":1402.21,"id":25238892}],"tv":2967.76}]}
{"op":"mcm","clk":"992419034","pt":1580522354417,"mc":[{"id":"1.168130661","rc":[{"batb":[[0,32,4.44]],"ltp":50.0,"tv":14.91,"id":25545675},{"batb":[[1,9,1.96]],"ltp":9.2,"tv":197.22,"id":24420205},{"trd":[[2.74,46.12]],"batl":[[0,2.74,84.92]],"ltp":2.74,"tv":1083.08,"id":26314798}],"tv":2985.36}]}
{"op":"mcm","clk":"992419185","pt":1580522361345,"mc":[{"id":"1.168130661","rc":[{"batb":[[1,8.8,3.71],[2,8.2,5.26]],"ltp":9.2,"tv":197.22,"id":24420205}]}]}
{"op":"mcm","clk":"992419306","pt":1580522366750,"mc":[{"id":"1.168130661","rc":[{"batb":[[2,8.4,2.38]],"ltp":9.2,"tv":197.22,"id":24420205}]}]}
{"op":"mcm","clk":"992419400","pt":1580522370174,"mc":[{"id":"1.168130661","rc":[{"batb":[[2,8.4,4.48]],"ltp":9.2,"tv":197.22,"id":24420205}]}]}
{"op":"mcm","clk":"992419432","pt":1580522371466,"mc":[{"id":"1.168130661","rc":[{"batb":[[0,32,8.4]],"ltp":50.0,"tv":14.91,"id":25545675},{"batb":[[1,9,7.04],[2,8.8,3.71]],"ltp":9.2,"tv":197.22,"id":24420205}]}]}
{"op":"mcm","clk":"992419991","pt":1580522389462,"mc":[{"id":"1.168130661","rc":[{"batb":[[0,32,4.44]],"ltp":50.0,"tv":14.91,"id":25545675},{"batb":[[1,9,1.96]],"ltp":9.2,"tv":197.22,"id":24420205}]}]}
{"op":"mcm","clk":"992420327","pt":1580522398181,"mc":[{"id":"1.168130661","rc":[{"batb":[[1,8.8,3.71],[2,8.4,2.38]],"ltp":9.2,"tv":197.22,"id":24420205}]}]}
{"op":"mcm","clk":"992420714","pt":1580522406507,"mc":[{"id":"1.168130661","rc":[{"batb":[[0,32,8.4]],"ltp":50.0,"tv":14.91,"id":25545675}]}]}
{"op":"mcm","clk":"992420803","pt":1580522409303,"mc":[{"id":"1.168130661","rc":[{"batb":[[2,8.4,4.48]],"ltp":9.2,"tv":197.22,"id":24420205}]}]}
{"op":"mcm","clk":"992421255","pt":1580522424436,"mc":[{"id":"1.168130661","rc":[{"batb":[[1,9,7.04],[2,8.8,3.71]],"ltp":9.2,"tv":197.22,"id":24420205}]}]}
{"op":"mcm","clk":"992421645","pt":1580522437156,"mc":[{"id":"1.168130661","rc":[{"batb":[[1,9,8.99]],"ltp":9.2,"tv":197.22,"id":24420205}]}]}
{"op":"mcm","clk":"992421775","pt":1580522441470,"mc":[{"id":"1.168130661","rc":[{"batb":[[0,32,4.44]],"ltp":50.0,"tv":14.91,"id":25545675},{"batb":[[1,9,1.96]],"ltp":9.2,"tv":197.22,"id":24420205}]}]}
{"op":"mcm","clk":"992421981","pt":1580522446544,"mc":[{"id":"1.168130661","rc":[{"batb":[[1,8.8,3.71],[2,8.2,5.26]],"ltp":9.2,"tv":197.22,"id":24420205}]}]}
{"op":"mcm","clk":"992422322","pt":1580522455278,"mc":[{"id":"1.168130661","rc":[{"batb":[[2,8.4,2.1]],"ltp":9.2,"tv":197.22,"id":24420205}]}]}
{"op":"mcm","clk":"992422602","pt":1580522459360,"mc":[{"id":"1.168130661","rc":[{"batb":[[0,32,8.4]],"ltp":50.0,"tv":14.91,"id":25545675}]}]}
{"op":"mcm","clk":"992422790","pt":1580522461389,"mc":[{"id":"1.168130661","rc":[{"batb":[[0,2.82,2.55],[1,2.8,2.57],[2,2.74,18.36]],"ltp":2.8,"tv":1402.21,"id":25238892}]}]}
{"op":"mcm","clk":"992422848","pt":1580522462581,"mc":[{"id":"1.168130661","rc":[{"batb":[[1,2.74,18.36],[2,2.7,13.47]],"ltp":2.8,"tv":1402.21,"id":25238892}]}]}
{"op":"mcm","clk":"992423389","pt":1580522476378,"mc":[{"id":"1.168130661","rc":[{"batb":[[0,32,4.44]],"ltp":50.0,"tv":14.91,"id":25545675}]}]}
{"op":"mcm","clk":"992423594","pt":1580522482200,"mc":[{"id":"1.168130661","rc":[{"batb":[[2,8,41.56]],"ltp":9.2,"tv":197.22,"id":24420205}]}]}
{"op":"mcm","clk":"992423819","pt":1580522491623,"mc":[{"id":"1.168130661","rc":[{"batb":[[2,8.2,2.15]],"ltp":9.2,"tv":197.22,"id":24420205}]}]}
{"op":"mcm","clk":"992424266","pt":1580522510329,"mc":[{"id":"1.168130661","rc":[{"batb":[[2,8.2,4.59]],"ltp":9.2,"tv":197.22,"id":24420205}]}]}
{"op":"mcm","clk":"992426075","pt":1580522572610,"mc":[{"id":"1.168130661","rc":[{"batb":[[0,32,8.4]],"ltp":50.0,"tv":14.91,"id":25545675},{"trd":[[2.72,60.72]],"batb":[[0,2.7,28.15],[1,2.68,2.05],[2,2.66,3.67]],"ltp":2.72,"tv":1089.32,"id":26314798}],"tv":2991.6}]}
{"op":"mcm","clk":"992429290","pt":1580522686642,"mc":[{"id":"1.168130661","rc":[{"batb":[[2,8.2,7.7]],"ltp":9.8,"tv":151.74,"id":420}]}]}
{"op":"mcm","clk":"992429719","pt":1580522702652,"mc":[{"id":"1.168130661","rc":[{"batb":[[0,2.72,6.34],[1,2.7,28.15]],"ltp":2.72,"tv":1089.32,"id":26314798}]}]}
{"op":"mcm","clk":"992429841","pt":1580522707347,"mc":[{"id":"1.168130661","rc":[{"batb":[[0,32,4.44]],"ltp":50.0,"tv":14.91,"id":25545675}]}]}
{"op":"mcm","clk":"992430645","pt":1580522736286,"mc":[{"id":"1.168130661","rc":[{"batb":[[2,8.2,7.13]],"ltp":9.8,"tv":151.74,"id":420}]}]}
{"op":"mcm","clk":"992431592","pt":1580522768448,"mc":[{"id":"1.168130661","rc":[{"trd":[[2.82,100.31]],"batb":[[0,2.74,18.92],[1,2.7,13.47],[2,2.6,16.66]],"ltp":2.82,"tv":1406.21,"id":25238892}],"tv":2995.6}]}
{"op":"mcm","clk":"992431987","pt":1580522778451,"mc":[{"id":"1.168130661","rc":[{"batl":[[0,2.84,12.6]],"ltp":2.82,"tv":1406.21,"id":25238892}]}]}
{"op":"mcm","clk":"992432140","pt":1580522783654,"mc":[{"id":"1.168130661","rc":[{"batb":[[0,32,8.4]],"ltp":50.0,"tv":14.91,"id":25545675},{"batb":[[1,9,7.04],[2,8.8,3.71]],"ltp":9.2,"tv":197.22,"id":24420205}]}]}
{"op":"mcm","clk":"992432288","pt":1580522788533,"mc":[{"id":"1.168130661","rc":[{"batl":[[1,2.86,7.04]],"ltp":2.82,"tv":1406.21,"id":25238892}]}]}
{"op":"mcm","clk":"992432447","pt":1580522792973,"mc":[{"id":"1.168130661","rc":[{"batb":[[1,9,8.99]],"ltp":9.2,"tv":197.22,"id":24420205}]}]}
{"op":"mcm","clk":"992433194","pt":1580522824719,"mc":[{"id":"1.168130661","rc":[{"batl":[[2,2.88,8.72]],"ltp":2.82,"tv":1406.21,"id":25238892}]}]}
{"op":"mcm","clk":"992447129","pt":1580523017209,"mc":[{"id":"1.168130661","rc":[{"trd":[[2.74,145.05],[2.76,185.69],[2.82,101.42]],"batb":[[0,2.74,16.92]],"ltp":2.74,"tv":1410.21,"id":25238892}],"tv":2999.6}]}
{"op":"mcm","clk":"992447602","pt":1580523040587,"mc":[{"id":"1.168130661","rc":[{"batl":[[0,2.82,1.68],[1,2.84,2],[2,2.86,7.04]],"ltp":2.74,"tv":1410.21,"id":25238892}]}]}
{"op":"mcm","clk":"992447627","pt":1580523041458,"mc":[{"id":"1.168130661","rc":[{"batl":[[0,2.8,1.68],[1,2.82,1.68],[2,2.84,2]],"ltp":2.74,"tv":1410.21,"id":25238892}]}]}
{"op":"mcm","clk":"992447643","pt":1580523042294,"mc":[{"id":"1.168130661","rc":[{"batl":[[0,2.78,1.68],[1,2.8,1.68],[2,2.82,1.68]],"ltp":2.74,"tv":1410.21,"id":25238892}]}]}
{"op":"mcm","clk":"992447877","pt":1580523049074,"mc":[{"id":"1.168130661","rc":[{"batl":[[0,2.8,1.68],[1,2.82,1.68],[2,2.84,2]],"ltp":2.74,"tv":1410.21,"id":25238892}]}]}
{"op":"mcm","clk":"992447890","pt":1580523049789,"mc":[{"id":"1.168130661","rc":[{"batl":[[0,2.82,1.68],[1,2.84,2],[2,2.86,7.04]],"ltp":2.74,"tv":1410.21,"id":25238892}]}]}
{"op":"mcm","clk":"992447949","pt":1580523050771,"mc":[{"id":"1.168130661","rc":[{"batl":[[0,2.84,2],[1,2.86,7.04],[2,2.88,8.72]],"ltp":2.74,"tv":1410.21,"id":25238892}]}]}
{"op":"mcm","clk":"992448058","pt":1580523054593,"mc":[{"id":"1.168130661","rc":[{"trd":[[2.74,178.5]],"batb":[[0,2.7,13.66],[1,2.62,2.43]],"batl":[[0,2.82,10.66],[1,2.84,2],[2,2.86,7.04]],"ltp":2.74,"tv":1443.65,"id":25238892}],"tv":3033.05}]}
{"op":"mcm","clk":"992448080","pt":1580523055363,"mc":[{"id":"1.168130661","rc":[{"batb":[[0,2.72,1.87],[1,2.7,13.47],[2,2.62,2.43]],"ltp":2.74,"tv":1443.65,"id":25238892}]}]}
{"op":"mcm","clk":"992448190","pt":1580523060695,"mc":[{"id":"1.168130661","rc":[{"trd":[[2.72,73.38]],"batb":[[0,2.7,28.15],[1,2.66,3.67],[2,2.64,3.65]],"ltp":2.72,"tv":1101.99,"id":26314798}],"tv":3045.71}]}
{"op":"mcm","clk":"992448194","pt":1580523060800,"mc":[{"id":"1.168130661","rc":[{"batb":[[2,2.6,16.66]],"ltp":2.74,"tv":1443.65,"id":25238892}]}]}
{"op":"mcm","clk":"992448242","pt":1580523063213,"mc":[{"id":"1.168130661","rc":[{"batb":[[0,9.2,4.16]],"ltp":9.2,"tv":197.22,"id":24420205}]}]}
{"op":"mcm","clk":"992448321","pt":1580523065684,"mc":[{"id":"1.168130661","rc":[{"trd":[[2.7,289.14]],"batb":[[0,2.7,13.95]],"ltp":2.7,"tv":1130.37,"id":26314798}],"tv":3074.09}]}
{"op":"mcm","clk":"992448535","pt":1580523075387,"mc":[{"id":"1.168130661","rc":[{"trd":[[2.7,56.46],[2.72,55.29],[2.74,178.87]],"batb":[[0,2.7,11.79],[1,2.6,16.66],[2,2.58,1.98]],"ltp":2.7,"tv":1450.75,"id":25238892},{"batb":[[0,9.2,11.04],[1,9,1.96]],"ltp":9.2,"tv":197.22,"id":24420205}],"tv":3081.19}]}
{"op":"mcm","clk":"992448665","pt":1580523080525,"mc":[{"id":"1.168130661","rc":[{"batb":[[0,2.72,3.12],[1,2.7,11.79],[2,2.6,16.66]],"ltp":2.7,"tv":1450.75,"id":25238892}]}]}
{"op":"mcm","clk":"992448669","pt":1580523080833,"mc":[{"id":"1.168130661","rc":[{"batb":[[1,8.8,3.71],[2,8,41.56]],"ltp":9.2,"tv":197.22,"id":24420205}]}]}
{"op":"mcm","clk":"992448855","pt":1580523089122,"mc":[{"id":"1.168130661","rc":[{"batb":[[0,9.4,1.87],[1,9.2,11.04],[2,8.8,3.71]],"ltp":9.2,"tv":197.22,"id":24420205}]}]}
{"op":"mcm","clk":"992448983","pt":1580523094403,"mc":[{"id":"1.168130661","rc":[{"batb":[[0,9.4,8.61],[1,9.2,4.16]],"ltp":9.2,"tv":197.22,"id":24420205}]}]}
{"op":"mcm","clk":"992450015","pt":1580523138972,"mc":[{"id":"1.168130661","rc":[{"trd":[[9.4,25.46]],"batb":[[0,9.2,4.16],[1,8.8,3.71],[2,8,45.16]],"ltp":9.4,"tv":214.45,"id":24420205}],"tv":3098.42}]}
{"op":"mcm","clk":"992451538","pt":1580523197601,"mc":[{"id":"1.168130661","rc":[{"trd":[[2.72,61.28]],"batb":[[0,2.7,11.91],[1,2.6,16.66],[2,2.58,1.98]],"ltp":2.72,"tv":1456.75,"id":25238892}],"tv":3104.42}]}
{"op":"mcm","clk":"992451728","pt":1580523204655,"mc":[{"id":"1.168130661","rc":[{"trd":[[2.72,61.52]],"batb":[[0,2.7,11.79]],"batl":[[0,2.72,2.88],[1,2.82,10.66],[2,2.84,2]],"ltp":2.72,"tv":1456.99,"id":25238892}],"tv":3104.66}]}
{"op":"mcm","clk":"992452142","pt":1580523219060,"mc":[{"id":"1.168130661","rc":[{"batl":[[0,2.82,10.66],[1,2.84,2],[2,2.86,7.04]],"ltp":2.72,"tv":1456.99,"id":25238892}]}]}
{"op":"mcm","clk":"992452290","pt":1580523224670,"mc":[{"id":"1.168130661","rc":[{"trd":[[2.7,62.46]],"batb":[[0,2.7,8.79]],"ltp":2.7,"tv":1462.99,"id":25238892}],"tv":3110.66}]}
{"op":"mcm","clk":"992452822","pt":1580523245346,"mc":[{"id":"1.168130661","rc":[{"trd":[[2.7,301.14]],"batb":[[0,2.7,7.95]],"ltp":2.7,"tv":1142.37,"id":26314798}],"tv":3122.66}]}
{"op":"mcm","clk":"992455184","pt":1580523333657,"mc":[{"id":"1.168130661","rc":[{"batb":[[0,2.72,6.34],[1,2.7,8.79],[2,2.6,16.66]],"ltp":2.7,"tv":1462.99,"id":25238892}]}]}
{"op":"mcm","clk":"992464783","pt":1580523646804,"mc":[{"id":"1.168130661","rc":[{"batb":[[0,9.4,2.13],[1,9.2,4.16],[2,8.8,3.71]],"ltp":9.4,"tv":214.45,"id":24420205}]}]}
{"op":"mcm","clk":"992482857","pt":1580523934230,"mc":[{"id":"1.168130661","rc":[{"batb":[[2,8.2,3.76]],"ltp":9.8,"tv":151.74,"id":420}]}]}
{"op":"mcm","clk":"992483206","pt":1580523944570,"mc":[{"id":"1.168130661","rc":[{"batb":[[2,8,12.86]],"ltp":9.8,"tv":151.74,"id":420}]}]}
{"op":"mcm","clk":"992483247","pt":1580523945556,"mc":[{"id":"1.168130661","rc":[{"batb":[[2,8,16.04]],"ltp":9.8,"tv":151.74,"id":420}]}]}
{"op":"mcm","clk":"992488260","pt":1580524099372,"mc":[{"id":"1.168130661","rc":[{"trd":[[9.4,29.73]],"batb":[[0,9.2,4.16],[1,8.8,3.71],[2,8,45.16]],"batl":[[0,12,2.39]],"ltp":9.4,"tv":218.72,"id":24420205}],"tv":3126.92}]}
{"op":"mcm","clk":"992488556","pt":1580524108687,"mc":[{"id":"1.168130661","rc":[{"batl":[[0,11.5,3.61],[1,12,2],[2,12.5,9.41]],"ltp":9.4,"tv":218.72,"id":24420205}]}]}
{"op":"mcm","clk":"992488686","pt":1580524112391,"mc":[{"id":"1.168130661","rc":[{"batl":[[0,11,2.21],[1,11.5,3.23],[2,12,2]],"ltp":9.4,"tv":218.72,"id":24420205}]}]}
{"op":"mcm","clk":"992523708","pt":1580524812655,"mc":[{"id":"1.168130661","rc":[{"batb":[[2,8,41.56]],"ltp":9.4,"tv":218.72,"id":24420205}]}]}
{"op":"mcm","clk":"992524039","pt":1580524820085,"mc":[{"id":"1.168130661","rc":[{"batl":[[0,11,1.82]],"ltp":9.4,"tv":218.72,"id":24420205}]}]}
{"op":"mcm","clk":"992525955","pt":1580524872120,"mc":[{"id":"1.168130661","rc":[{"batl":[[0,10.5,2],[1,11,1.82],[2,11.5,3.23]],"ltp":9.4,"tv":218.72,"id":24420205}]}]}
{"op":"mcm","clk":"992526179","pt":1580524878316,"mc":[{"id":"1.168130661","rc":[{"batl":[[2,12.5,9.41]],"ltp":9.4,"tv":218.72,"id":24420205}]}]}
{"op":"mcm","clk":"992526352","pt":1580524882497,"mc":[{"id":"1.168130661","rc":[{"batb":[[0,2.72,37.17]],"batl":[[0,2.84,2],[1,2.86,7.04],[2,2.88,8.72]],"ltp":2.7,"tv":1462.99,"id":25238892}]}]}
{"op":"mcm","clk":"992527118","pt":1580524902728,"mc":[{"id":"1.168130661","rc":[{"batb":[[0,2.74,3],[1,2.72,37.17],[2,2.7,8.79]],"ltp":2.7,"tv":1462.99,"id":25238892}]}]}
{"op":"mcm","clk":"992527896","pt":1580524923380,"mc":[{"id":"1.168130661","rc":[{"batb":[[1,2.72,6.34]],"ltp":2.7,"tv":1462.99,"id":25238892}]}]}
{"op":"mcm","clk":"992528251","pt":1580524931403,"mc":[{"id":"1.168130661","rc":[{"batb":[[0,2.72,6.34],[1,2.7,8.79],[2,2.6,16.66]],"ltp":2.7,"tv":1462.99,"id":25238892}]}]}
{"op":"mcm","clk":"992533186","pt":1580525056367,"mc":[{"id":"1.168130661","rc":[{"batb":[[2,8,12.86]],"ltp":9.8,"tv":151.74,"id":420}]}]}
{"op":"mcm","clk":"992533248","pt":1580525058169,"mc":[{"id":"1.168130661","rc":[{"batb":[[2,8,15.57]],"ltp":9.8,"tv":151.74,"id":420}]}]}
{"op":"mcm","clk":"992533315","pt":1580525060087,"mc":[{"id":"1.168130661","rc":[{"trd":[[9.2,9.12]],"batb":[[0,8.8,3.71],[1,8,41.56],[2,7.6,5.74]],"ltp":9.2,"tv":227.03,"id":24420205}],"tv":3135.24}]}
{"op":"mcm","clk":"992533619","pt":1580525068575,"mc":[{"id":"1.168130661","rc":[{"trd":[[14,4.98]],"batb":[[0,13.5,14.75],[1,13,4.7],[2,12.5,2]],"batl":[[0,14,1.77],[1,15,7.96],[2,15.5,10]],"ltp":14.0,"tv":138.63,"id":24707172}],"tv":3137.69}]}
{"op":"mcm","clk":"992533658","pt":1580525069706,"mc":[{"id":"1.168130661","rc":[{"trd":[[14,8.34]],"batl":[[0,15,8.05],[1,15.5,10],[2,21,14.12]],"ltp":14.0,"tv":141.99,"id":24707172}],"tv":3141.06}]}
{"op":"mcm","clk":"992533933","pt":1580525078671,"mc":[{"id":"1.168130661","rc":[{"trd":[[13.5,25.67]],"batb":[[0,13.5,14.66]],"batl":[[0,15,7.96]],"ltp":13.5,"tv":142.17,"id":24707172}],"tv":3141.24}]}
{"op":"mcm","clk":"992537379","pt":1580525181540,"mc":[{"id":"1.168130661","rc":[{"batb":[[2,8,12.7]],"ltp":9.8,"tv":151.74,"id":420}]}]}
{"op":"mcm","clk":"992537449","pt":1580525183332,"mc":[{"id":"1.168130661","rc":[{"batb":[[2,7.6,3.02]],"ltp":9.2,"tv":227.03,"id":24420205},{"batb":[[2,8,15.13]],"ltp":9.8,"tv":151.74,"id":420}]}]}
{"op":"mcm","clk":"992541377","pt":1580525309851,"mc":[{"id":"1.168130661","rc":[{"batb":[[2,7.2,13.03]],"ltp":9.2,"tv":227.03,"id":24420205}]}]}
{"op":"mcm","clk":"992543546","pt":1580525364611,"mc":[{"id":"1.168130661","rc":[{"trd":[[2.7,317.04]],"batb":[[0,2.66,3.67],[1,2.64,14.89],[2,2.62,133.13]],"batl":[[0,2.7,27.41],[1,2.74,84.92],[2,2.76,199]],"ltp":2.7,"tv":1158.26,"id":26314798}],"tv":3157.13}]}
{"op":"mcm","clk":"992543959","pt":1580525374023,"mc":[{"id":"1.168130661","rc":[{"batb":[[0,14,1.23],[1,13.5,14.66],[2,13,4.7]],"ltp":13.5,"tv":142.17,"id":24707172}]}]}
{"op":"mcm","clk":"992548321","pt":1580525501705,"mc":[{"id":"1.168130661","rc":[{"trd":[[2.66,37.31]],"batb":[[0,2.64,14.89],[1,2.62,133.13],[2,2.6,75]],"batl":[[0,2.66,23.74]],"ltp":2.66,"tv":1165.61,"id":26314798}],"tv":3164.48}]}
{"op":"mcm","clk":"992548768","pt":1580525516619,"mc":[{"id":"1.168130661","rc":[{"batb":[[0,34,1.16],[1,32,7.89],[2,29,10.14]],"ltp":50.0,"tv":14.91,"id":25545675},{"batb":[[0,2.72,8.32]],"ltp":2.7,"tv":1462.99,"id":25238892},{"batb":[[0,14,2.92]],"ltp":13.5,"tv":142.17,"id":24707172},{"trd":[[10,58.56]],"batb":[[0,10,1.97],[1,9.8,47.95],[2,8.4,3]],"batl":[[0,11,4]],"ltp":10.0,"tv":151.78,"id":420}],"tv":3164.51}]}
{"op":"mcm","clk":"992549465","pt":1580525540668,"mc":[{"id":"1.168130661","rc":[{"trd":[[14,14.19]],"batb":[[0,13.5,14.66],[1,13,4.7],[2,12.5,2]],"ltp":14.0,"tv":148.02,"id":24707172}],"tv":3170.36}]}
{"op":"mcm","clk":"992560041","pt":1580525564683,"mc":[{"id":"1.168130661","rc":[{"trd":[[2.64,66.07]],"batb":[[0,2.62,133.13],[1,2.6,75],[2,2.52,25]],"batl":[[0,2.64,8.86]],"ltp":2.64,"tv":1195.39,"id":26314798}],"tv":3200.14}]}
{"op":"mcm","clk":"992560044","pt":1580525564779,"mc":[{"id":"1.168130661","rc":[{"batl":[[2,2.76,201.21]],"ltp":2.64,"tv":1195.39,"id":26314798}]}]}
{"op":"mcm","clk":"992560153","pt":1580525569204,"mc":[{"id":"1.168130661","rc":[{"batl":[[0,2.64,18.86],[2,2.76,199]],"ltp":2.64,"tv":1195.39,"id":26314798}]}]}
{"op":"mcm","clk":"992560234","pt":1580525572498,"mc":[{"id":"1.168130661","rc":[{"batb":[[0,34,1.75]],"ltp":50.0,"tv":14.91,"id":25545675},{"trd":[[2.84,69.82]],"batl":[[0,2.84,16]],"ltp":2.84,"tv":1477.81,"id":25238892},{"trd":[[15,41.68]],"batl":[[0,15,6.56]],"ltp":15.0,"tv":150.82,"id":24707172},{"trd":[[10.5,14.55]],"batb":[[0,8.8,3.72]],"batl":[[0,11,1.82],[1,12.5,9.41],[2,14,2.52]],"ltp":10.5,"tv":231.03,"id":24420205},{"trd":[[2.64,82.03]],"batl":[[0,2.64,10.88]],"ltp":2.64,"tv":1211.35,"id":26314798},{"batb":[[0,10.5,2.01],[1,10,1.97],[2,9.8,47.95]],"ltp":10.0,"tv":151.78,"id":420}],"tv":3237.72}]}
{"op":"mcm","clk":"992560249","pt":1580525573109,"mc":[{"id":"1.168130661","rc":[{"batl":[[0,50,1.82]],"ltp":50.0,"tv":14.91,"id":25545675}]}]}
{"op":"mcm","clk":"992560404","pt":1580525579429,"mc":[{"id":"1.168130661","rc":[{"batb":[[1,8,40]],"ltp":10.5,"tv":231.03,"id":24420205}]}]}
{"op":"mcm","clk":"992560719","pt":1580525589523,"mc":[{"id":"1.168130661","rc":[{"batl":[[0,12,1.67]],"ltp":10.5,"tv":231.03,"id":24420205}]}]}
{"op":"mcm","clk":"992561379","pt":1580525616958,"mc":[{"id":"1.168130661","rc":[{"batb":[[0,9,2.34],[1,8.8,3.71],[2,8,40]],"ltp":10.5,"tv":231.03,"id":24420205}]}]}
{"op":"mcm","clk":"992561814","pt":1580525635422,"mc":[{"id":"1.168130661","rc":[{"trd":[[2.62,47.66]],"batb":[[0,2.62,132.25]],"batl":[[0,2.64,10]],"ltp":2.62,"tv":1213.11,"id":26314798}],"tv":3239.48}]}
{"op":"mcm","clk":"992565258","pt":1580525734659,"mc":[{"id":"1.168130661","rc":[{"batb":[[1,32,5.37]],"ltp":50.0,"tv":14.91,"id":25545675}]}]}
{"op":"mcm","clk":"992565273","pt":1580525735124,"mc":[{"id":"1.168130661","rc":[{"batb":[[0,36,2.83],[1,34,1.16],[2,32,5.37]],"ltp":50.0,"tv":14.91,"id":25545675}]}]}
{"op":"mcm","clk":"992565298","pt":1580525736368,"mc":[{"id":"1.168130661","rc":[{"batb":[[2,32,4.22]],"ltp":50.0,"tv":14.91,"id":25545675}]}]}
{"op":"mcm","clk":"992566340","pt":1580525767485,"mc":[{"id":"1.168130661","rc":[{"batb":[[0,34,3.99],[1,32,4.22],[2,29,10.14]],"ltp":50.0,"tv":14.91,"id":25545675}]}]}
{"op":"mcm","clk":"992566550","pt":1580525774815,"mc":[{"id":"1.168130661","rc":[{"batb":[[0,36,1.62],[1,34,3.4],[2,32,4.22]],"ltp":50.0,"tv":14.91,"id":25545675}]}]}
{"op":"mcm","clk":"992566669","pt":1580525780708,"mc":[{"id":"1.168130661","rc":[{"trd":[[10.5,32.56]],"batb":[[0,10,1.97],[1,9.8,47.95],[2,8.4,3]],"batl":[[0,11,4.51]],"ltp":10.5,"tv":155.8,"id":420}],"tv":3243.5}]}
{"op":"mcm","clk":"992566746","pt":1580525784823,"mc":[{"id":"1.168130661","rc":[{"batb":[[2,8,15.13]],"ltp":10.5,"tv":155.8,"id":420}]}]}
{"op":"mcm","clk":"992568436","pt":1580525845215,"mc":[{"id":"1.168130661","rc":[{"batb":[[0,2.78,4],[1,2.72,8.32],[2,2.7,8.79]],"ltp":2.84,"tv":1477.81,"id":25238892}]}]}
{"op":"mcm","clk":"992570208","pt":1580525919315,"mc":[{"id":"1.168130661","rc":[{"batb":[[0,2.72,8.32],[1,2.7,8.79],[2,2.6,16.66]],"ltp":2.84,"tv":1477.81,"id":25238892}]}]}
{"op":"mcm","clk":"992570366","pt":1580525926805,"mc":[{"id":"1.168130661","rc":[{"batl":[[1,2.86,5.04],[2,2.88,6.72]],"ltp":2.84,"tv":1477.81,"id":25238892}]}]}
{"op":"mcm","clk":"992578528","pt":1580526154683,"mc":[{"id":"1.168130661","rc":[{"batb":[[0,36,5.14],[2,29,10.4]],"ltp":50.0,"tv":14.91,"id":25545675},{"batb":[[0,2.74,5.67],[1,2.72,39.15],[2,2.7,8.79]],"batl":[[0,2.84,10.81]],"ltp":2.84,"tv":1477.81,"id":25238892},{"trd":[[2.64,102.02]],"batb":[[0,2.64,37.98],[1,2.62,132.25],[2,2.6,75]],"batl":[[0,2.74,84.92],[1,2.76,199],[2,2.78,110.72]],"ltp":2.64,"tv":1233.1,"id":26314798}],"tv":3263.49}]}
{"op":"mcm","clk":"992578546","pt":1580526155199,"mc":[{"id":"1.168130661","rc":[{"batb":[[0,36,5.59],[1,34,2.9]],"ltp":50.0,"tv":14.91,"id":25545675}]}]}
{"op":"mcm","clk":"992579408","pt":1580526179704,"mc":[{"id":"1.168130661","rc":[{"batb":[[1,30,1.46],[2,29,9.6]],"ltp":50.0,"tv":14.91,"id":25545675}]}]}
{"op":"mcm","clk":"992579412","pt":1580526179808,"mc":[{"id":"1.168130661","rc":[{"batb":[[0,38,2.46],[1,36,5.14],[2,30,1.46]],"ltp":50.0,"tv":14.91,"id":25545675}]}]}
{"op":"mcm","clk":"992579976","pt":1580526196473,"mc":[{"id":"1.168130661","rc":[{"batb":[[0,38,3.39],[1,36,4.11]],"ltp":50.0,"tv":14.91,"id":25545675}]}]}
{"op":"mcm","clk":"992580012","pt":1580526197657,"mc":[{"id":"1.168130661","rc":[{"batb":[[0,38,6.73],[1,34,1.25],[2,29,10.4]],"ltp":50.0,"tv":14.91,"id":25545675},{"batb":[[1,2.72,8.32]],"ltp":2.84,"tv":1477.81,"id":25238892},{"batb":[[0,2.62,132.25],[1,2.6,75],[2,2.52,25]],"batl":[[0,2.72,10.91],[1,2.74,84.92],[2,2.76,199]],"ltp":2.64,"tv":1233.1,"id":26314798}]}]}
{"op":"mcm","clk":"992584464","pt":1580526332665,"mc":[{"id":"1.168130661","rc":[{"batb":[[0,2.76,6.24],[1,2.74,5.67],[2,2.72,1.98]],"ltp":2.84,"tv":1477.81,"id":25238892}]}]}
{"op":"mcm","clk":"992600211","pt":1580526501357,"mc":[{"id":"1.168130661","rc":[{"batb":[[0,10,3.69]],"batl":[[0,11,4]],"ltp":10.5,"tv":155.8,"id":420}]}]}
{"op":"mcm","clk":"992603412","pt":1580526582702,"mc":[{"id":"1.168130661","rc":[{"batb":[[2,8,12.43]],"ltp":10.5,"tv":155.8,"id":420}]}]}
{"op":"mcm","clk":"992603492","pt":1580526585165,"mc":[{"id":"1.168130661","rc":[{"batb":[[2,8.2,2.29]],"ltp":10.5,"tv":155.8,"id":420}]}]}
{"op":"mcm","clk":"992604678","pt":1580526617709,"mc":[{"id":"1.168130661","rc":[{"batb":[[2,8.2,4.35]],"ltp":10.5,"tv":155.8,"id":420}]}]}
{"op":"mcm","clk":"992621101","pt":1580527065638,"mc":[{"id":"1.168130661","rc":[{"batb":[[0,2.64,10.08],[1,2.62,132.25],[2,2.6,75]],"ltp":2.64,"tv":1233.1,"id":26314798}]}]}
{"op":"mcm","clk":"992622409","pt":1580527097382,"mc":[{"id":"1.168130661","rc":[{"trd":[[38,11.57],[40,1.86]],"batb":[[0,34,1.26],[1,29,10.4],[2,28,1.04]],"ltp":38.0,"tv":28.34,"id":25545675}],"tv":3276.92}]}
{"op":"mcm","clk":"992622501","pt":1580527099482,"mc":[{"id":"1.168130661","rc":[{"batl":[[0,48,1.07],[1,50,1.82],[2,170,1.28]],"ltp":38.0,"tv":28.34,"id":25545675}]}]}
{"op":"mcm","clk":"992622667","pt":1580527104410,"mc":[{"id":"1.168130661","rc":[{"batl":[[0,48,1.85]],"ltp":38.0,"tv":28.34,"id":25545675}]}]}
{"op":"mcm","clk":"992623830","pt":1580527138657,"mc":[{"id":"1.168130661","rc":[{"trd":[[9.8,37.52],[10,65.94]],"batb":[[0,9.8,43.24],[1,8.2,4.35],[2,8,10]],"ltp":9.8,"tv":172.6,"id":420}],"tv":3293.72}]}
{"op":"mcm","clk":"992624028","pt":1580527143561,"mc":[{"id":"1.168130661","rc":[{"batb":[[1,8.4,3],[2,8.2,4.35]],"ltp":9.8,"tv":172.6,"id":420}]}]}
{"op":"mcm","clk":"992624804","pt":1580527166578,"mc":[{"id":"1.168130661","rc":[{"trd":[[2.74,186.55],[2.76,198.18]],"batb":[[0,2.74,1.83],[1,2.72,1.98],[2,2.7,8.79]],"ltp":2.74,"tv":1497.97,"id":25238892}],"tv":3313.89}]}
{"op":"mcm","clk":"992624867","pt":1580527169772,"mc":[{"id":"1.168130661","rc":[{"batb":[[0,14,1.23],[1,13.5,14.66],[2,13,4.7]],"ltp":15.0,"tv":150.82,"id":24707172},{"batb":[[0,9,4.26]],"ltp":10.5,"tv":231.03,"id":24420205}]}]}
{"op":"mcm","clk":"992625803","pt":1580527204332,"mc":[{"id":"1.168130661","rc":[{"batb":[[0,2.66,6.48],[1,2.64,10.08],[2,2.62,132.25]],"ltp":2.64,"tv":1233.1,"id":26314798}]}]}
{"op":"mcm","clk":"992642598","pt":1580527443319,"mc":[{"id":"1.168130661","rc":[{"batb":[[0,34,1.25]],"ltp":38.0,"tv":28.34,"id":25545675},{"batb":[[1,2.72,32.82]],"ltp":2.74,"tv":1497.97,"id":25238892},{"batb":[[0,10,1.72],[1,9.8,43.24],[2,8.4,3]],"ltp":9.8,"tv":172.6,"id":420}]}]}
{"op":"mcm","clk":"992642954","pt":1580527452190,"mc":[{"id":"1.168130661","rc":[{"batb":[[1,2.72,1.98]],"ltp":2.74,"tv":1497.97,"id":25238892}]}]}
{"op":"mcm","clk":"992643258","pt":1580527460499,"mc":[{"id":"1.168130661","rc":[{"batb":[[1,2.72,32.82]],"ltp":2.74,"tv":1497.97,"id":25238892}]}]}
{"op":"mcm","clk":"992643542","pt":1580527468428,"mc":[{"id":"1.168130661","rc":[{"batb":[[1,2.72,8.32]],"ltp":2.74,"tv":1497.97,"id":25238892}]}]}
{"op":"mcm","clk":"992643767","pt":1580527476408,"mc":[{"id":"1.168130661","rc":[{"batb":[[0,2.76,6.24],[1,2.74,32.44],[2,2.72,1.98]],"ltp":2.74,"tv":1497.97,"id":25238892}]}]}
{"op":"mcm","clk":"992644008","pt":1580527484135,"mc":[{"id":"1.168130661","rc":[{"batb":[[1,2.74,1.83]],"ltp":2.74,"tv":1497.97,"id":25238892}]}]}
{"op":"mcm","clk":"992649264","pt":1580527685670,"mc":[{"id":"1.168130661","rc":[{"batl":[[0,2.7,3.03],[1,2.72,10.91],[2,2.74,84.92]],"ltp":2.64,"tv":1233.1,"id":26314798}]}]}
{"op":"mcm","clk":"992649314","pt":1580527686699,"mc":[{"id":"1.168130661","rc":[{"batl":[[0,2.72,10.91],[1,2.74,84.92],[2,2.76,199]],"ltp":2.64,"tv":1233.1,"id":26314798}]}]}
{"op":"mcm","clk":"992662790","pt":1580528177718,"mc":[{"id":"1.168130661","rc":[{"trd":[[2.72,93.55]],"batb":[[1,2.62,132.25],[2,2.6,75]],"batl":[[0,2.74,85.75],[1,2.76,199],[2,2.78,110.72]],"ltp":2.72,"tv":1253.26,"id":26314798}],"tv":3334.05}]}
{"op":"mcm","clk":"992662795","pt":1580528177822,"mc":[{"id":"1.168130661","rc":[{"trd":[[2.72,95.21]],"batl":[[0,2.74,84.92]],"ltp":2.72,"tv":1254.92,"id":26314798}],"tv":3335.71}]}
{"op":"mcm","clk":"992664196","pt":1580528226158,"mc":[{"id":"1.168130661","rc":[{"trd":[[2.76,208.26]],"batb":[[0,2.76,1.2]],"ltp":2.76,"tv":1508.06,"id":25238892}],"tv":3345.79}]}
{"op":"mcm","clk":"992683747","pt":1580528542568,"mc":[{"id":"1.168130661","rc":[{"batb":[[0,14,6.27]],"ltp":15.0,"tv":150.82,"id":24707172},{"batb":[[0,10,10.96]],"ltp":9.8,"tv":172.6,"id":420}]}]}
{"op":"mcm","clk":"992687019","pt":1580528637683,"mc":[{"id":"1.168130661","rc":[{"batl":[[0,2.72,10],[1,2.74,84.92],[2,2.76,199]],"ltp":2.72,"tv":1254.92,"id":26314798}]}]}
{"op":"mcm","clk":"992687041","pt":1580528638252,"mc":[{"id":"1.168130661","rc":[{"batl":[[0,2.72,15]],"ltp":2.72,"tv":1254.92,"id":26314798}]}]}
{"op":"mcm","clk":"992687085","pt":1580528639229,"mc":[{"id":"1.168130661","rc":[{"batl":[[0,2.72,20]],"ltp":2.72,"tv":1254.92,"id":26314798}]}]}
{"op":"mcm","clk":"992687105","pt":1580528640153,"mc":[{"id":"1.168130661","rc":[{"batl":[[0,2.74,84.92],[1,2.76,199],[2,2.78,110.72]],"ltp":2.72,"tv":1254.92,"id":26314798}]}]}
{"op":"mcm","clk":"992687118","pt":1580528641080,"mc":[{"id":"1.168130661","rc":[{"batl":[[0,2.72,5],[1,2.74,84.92],[2,2.76,199]],"ltp":2.72,"tv":1254.92,"id":26314798}]}]}
{"op":"mcm","clk":"992687171","pt":1580528642575,"mc":[{"id":"1.168130661","rc":[{"batl":[[0,2.72,15]],"ltp":2.72,"tv":1254.92,"id":26314798}]}]}
{"op":"mcm","clk":"992687886","pt":1580528661972,"mc":[{"id":"1.168130661","rc":[{"trd":[[14,24.91]],"batb":[[0,13.5,15.57],[1,13,4.7],[2,12.5,2]],"ltp":14.0,"tv":161.54,"id":24707172}],"tv":3356.51}]}
{"op":"mcm","clk":"992692547","pt":1580528777518,"mc":[{"id":"1.168130661","rc":[{"batl":[[0,2.7,10],[1,2.72,15],[2,2.74,84.92]],"ltp":2.72,"tv":1254.92,"id":26314798}]}]}
{"op":"mcm","clk":"992692569","pt":1580528778237,"mc":[{"id":"1.168130661","rc":[{"batl":[[0,2.7,15]],"ltp":2.72,"tv":1254.92,"id":26314798}]}]}
{"op":"mcm","clk":"992692596","pt":1580528779320,"mc":[{"id":"1.168130661","rc":[{"batb":[[1,2.74,32.44]],"ltp":2.76,"tv":1508.06,"id":25238892}]}]}
{"op":"mcm","clk":"992692752","pt":1580528784936,"mc":[{"id":"1.168130661","rc":[{"batb":[[0,2.76,12.12]],"ltp":2.76,"tv":1508.06,"id":25238892}]}]}
{"op":"mcm","clk":"992693386","pt":1580528796420,"mc":[{"id":"1.168130661","rc":[{"batb":[[0,2.78,30.17],[1,2.76,12.12],[2,2.74,1.83]],"ltp":2.76,"tv":1508.06,"id":25238892}]}]}
{"op":"mcm","clk":"992694508","pt":1580528815359,"mc":[{"id":"1.168130661","rc":[{"batb":[[0,2.76,12.12],[1,2.74,1.83],[2,2.72,1.98]],"ltp":2.76,"tv":1508.06,"id":25238892}]}]}
{"op":"mcm","clk":"992695623","pt":1580528834697,"mc":[{"id":"1.168130661","rc":[{"batb":[[0,2.76,1.2]],"ltp":2.76,"tv":1508.06,"id":25238892}]}]}
{"op":"mcm","clk":"992696200","pt":1580528850424,"mc":[{"id":"1.168130661","rc":[{"batb":[[1,2.74,32.44]],"ltp":2.76,"tv":1508.06,"id":25238892}]}]}
{"op":"mcm","clk":"992696804","pt":1580528868350,"mc":[{"id":"1.168130661","rc":[{"batb":[[1,2.74,1.83]],"ltp":2.76,"tv":1508.06,"id":25238892}]}]}
{"op":"mcm","clk":"992697479","pt":1580528885645,"mc":[{"id":"1.168130661","rc":[{"batb":[[1,2.74,32.44]],"ltp":2.76,"tv":1508.06,"id":25238892}]}]}
{"op":"mcm","clk":"992698107","pt":1580528903692,"mc":[{"id":"1.168130661","rc":[{"batb":[[1,2.74,1.83]],"ltp":2.76,"tv":1508.06,"id":25238892}]}]}
{"op":"mcm","clk":"992698400","pt":1580528911583,"mc":[{"id":"1.168130661","rc":[{"trd":[[2.7,347.04]],"batb":[[0,2.7,25],[1,2.66,6.48],[2,2.62,132.25]],"batl":[[0,2.72,15],[1,2.74,84.92],[2,2.76,199]],"ltp":2.7,"tv":1284.92,"id":26314798}],"tv":3386.51}]}
{"op":"mcm","clk":"992698545","pt":1580528916178,"mc":[{"id":"1.168130661","rc":[{"batb":[[0,2.7,32.56]],"ltp":2.7,"tv":1284.92,"id":26314798}]}]}
{"op":"mcm","clk":"992698922","pt":1580528925629,"mc":[{"id":"1.168130661","rc":[{"trd":[[2.7,357.04]],"batb":[[0,2.7,27.56]],"ltp":2.7,"tv":1294.92,"id":26314798}],"tv":3396.51}]}
{"op":"mcm","clk":"992698993","pt":1580528927429,"mc":[{"id":"1.168130661","rc":[{"trd":[[2.7,367.04]],"batb":[[0,2.7,22.56]],"ltp":2.7,"tv":1304.92,"id":26314798}],"tv":3406.51}]}
{"op":"mcm","clk":"992699039","pt":1580528928608,"mc":[{"id":"1.168130661","rc":[{"trd":[[2.7,377.04]],"batb":[[0,2.7,17.56]],"ltp":2.7,"tv":1314.92,"id":26314798}],"tv":3416.51}]}
{"op":"mcm","clk":"992699649","pt":1580528945324,"mc":[{"id":"1.168130661","rc":[{"batb":[[0,2.7,10]],"ltp":2.7,"tv":1314.92,"id":26314798}]}]}
{"op":"mcm","clk":"992700031","pt":1580528954280,"mc":[{"id":"1.168130661","rc":[{"trd":[[2.7,387.04]],"batb":[[0,2.7,5]],"ltp":2.7,"tv":1324.92,"id":26314798}],"tv":3426.51}]}
{"op":"mcm","clk":"992700074","pt":1580528955170,"mc":[{"id":"1.168130661","rc":[{"trd":[[2.7,397.04]],"batb":[[0,2.66,6.48],[1,2.62,132.25],[2,2.6,75]],"ltp":2.7,"tv":1334.92,"id":26314798}],"tv":3436.51}]}
{"op":"mcm","clk":"992700185","pt":1580528957683,"mc":[{"id":"1.168130661","rc":[{"batl":[[0,2.72,5]],"ltp":2.7,"tv":1334.92,"id":26314798}]}]}
{"op":"mcm","clk":"992700223","pt":1580528958402,"mc":[{"id":"1.168130661","rc":[{"batl":[[0,2.72,10]],"ltp":2.7,"tv":1334.92,"id":26314798}]}]}
{"op":"mcm","clk":"992708096","pt":1580529142917,"mc":[{"id":"1.168130661","rc":[{"batb":[[0,30,2.05],[1,29,9.6]],"ltp":38.0,"tv":28.34,"id":25545675}]}]}
{"op":"mcm","clk":"992724621","pt":1580529351590,"mc":[{"id":"1.168130661","rc":[{"trd":[[2.72,95.35]],"batl":[[0,2.72,9.93]],"ltp":2.72,"tv":1335.06,"id":26314798}],"tv":3436.65}]}
{"op":"mcm","clk":"992724972","pt":1580529362553,"mc":[{"id":"1.168130661","rc":[{"batb":[[1,2.72,1.98],[2,2.7,8.79]],"batl":[[0,2.78,9.03],[1,2.8,16.3],[2,2.84,10.81]],"ltp":2.76,"tv":1508.06,"id":25238892}]}]}
{"op":"mcm","clk":"992725034","pt":1580529364139,"mc":[{"id":"1.168130661","rc":[{"batl":[[1,2.84,10.81],[2,2.86,5.04]],"ltp":2.76,"tv":1508.06,"id":25238892}]}]}
{"op":"mcm","clk":"992725151","pt":1580529367627,"mc":[{"id":"1.168130661","rc":[{"batl":[[0,2.78,25.45]],"ltp":2.76,"tv":1508.06,"id":25238892}]}]}
{"op":"mcm","clk":"992725271","pt":1580529371520,"mc":[{"id":"1.168130661","rc":[{"batl":[[0,2.78,9.03]],"ltp":2.76,"tv":1508.06,"id":25238892}]}]}
{"op":"mcm","clk":"992725298","pt":1580529372342,"mc":[{"id":"1.168130661","rc":[{"batl":[[0,2.78,13.57]],"ltp":2.76,"tv":1508.06,"id":25238892}]}]}
{"op":"mcm","clk":"992725750","pt":1580529384190,"mc":[{"id":"1.168130661","rc":[{"batb":[[1,2.72,5.34]],"ltp":2.76,"tv":1508.06,"id":25238892}]}]}
{"op":"mcm","clk":"992727194","pt":1580529432523,"mc":[{"id":"1.168130661","rc":[{"trd":[[2.76,210.66]],"batb":[[0,2.72,5.34],[1,2.7,8.79],[2,2.6,16.66]],"batl":[[0,2.76,8.51],[1,2.78,13.57],[2,2.84,10.81]],"ltp":2.76,"tv":1510.46,"id":25238892}],"tv":3439.06}]}
{"op":"mcm","clk":"992745517","pt":1580529885610,"mc":[{"id":"1.168130661","rc":[{"batl":[[0,11.5,40],[1,12,1.67],[2,12.5,9.41]],"ltp":10.5,"tv":231.03,"id":24420205}]}]}
{"op":"mcm","clk":"992762496","pt":1580530078662,"mc":[{"id":"1.168130661","rc":[{"batb":[[0,2.72,1.98]],"ltp":2.76,"tv":1510.46,"id":25238892},{"batb":[[0,13.5,14.66]],"ltp":14.0,"tv":161.54,"id":24707172},{"batb":[[0,10,1.72]],"ltp":9.8,"tv":172.6,"id":420}]}]}
{"op":"mcm","clk":"992764558","pt":1580530102570,"mc":[{"id":"1.168130661","rc":[{"trd":[[2.76,227.69]],"batl":[[0,2.78,13.57],[1,2.84,10.81],[2,2.86,5.04]],"ltp":2.76,"tv":1527.48,"id":25238892}],"tv":3456.08}]}
{"op":"mcm","clk":"992765703","pt":1580530123211,"mc":[{"id":"1.168130661","rc":[{"trd":[[9.8,39.96],[10,69.38]],"batb":[[0,9.8,42.02],[1,8.4,3],[2,8,13.67]],"ltp":9.8,"tv":178.48,"id":420}],"tv":3461.96}]}
{"op":"mcm","clk":"992772487","pt":1580530244818,"mc":[{"id":"1.168130661","rc":[{"batl":[[2,75,2]],"ltp":38.0,"tv":28.34,"id":25545675}]}]}
{"op":"mcm","clk":"992774645","pt":1580530298600,"mc":[{"id":"1.168130661","rc":[{"batb":[[0,2.72,32.82]],"batl":[[0,2.78,4.54]],"ltp":2.76,"tv":1527.48,"id":25238892}]}]}
{"op":"mcm","clk":"992777065","pt":1580530352207,"mc":[{"id":"1.168130661","rc":[{"batb":[[0,2.74,3],[1,2.72,32.82],[2,2.7,8.79]],"ltp":2.76,"tv":1527.48,"id":25238892}]}]}
{"op":"mcm","clk":"992777268","pt":1580530356372,"mc":[{"id":"1.168130661","rc":[{"batb":[[1,2.72,1.98]],"ltp":2.76,"tv":1527.48,"id":25238892}]}]}
{"op":"mcm","clk":"992777918","pt":1580530369380,"mc":[{"id":"1.168130661","rc":[{"batb":[[0,2.72,1.98],[1,2.7,8.79],[2,2.6,16.66]],"ltp":2.76,"tv":1527.48,"id":25238892}]}]}
{"op":"mcm","clk":"992778395","pt":1580530374402,"mc":[{"id":"1.168130661","rc":[{"batb":[[0,2.72,32.82]],"ltp":2.76,"tv":1527.48,"id":25238892}]}]}
{"op":"mcm","clk":"992780164","pt":1580530403197,"mc":[{"id":"1.168130661","rc":[{"batb":[[0,2.74,3],[1,2.72,32.82],[2,2.7,8.79]],"ltp":2.76,"tv":1527.48,"id":25238892}]}]}
{"op":"mcm","clk":"992780519","pt":1580530409437,"mc":[{"id":"1.168130661","rc":[{"batb":[[1,2.72,1.98]],"ltp":2.76,"tv":1527.48,"id":25238892}]}]}
{"op":"mcm","clk":"992781126","pt":1580530420642,"mc":[{"id":"1.168130661","rc":[{"batb":[[0,2.72,1.98],[1,2.7,8.79],[2,2.6,16.66]],"ltp":2.76,"tv":1527.48,"id":25238892}]}]}
{"op":"mcm","clk":"992781335","pt":1580530424760,"mc":[{"id":"1.168130661","rc":[{"trd":[[2.78,246.02]],"batl":[[0,2.78,3.6]],"ltp":2.78,"tv":1529.38,"id":25238892}],"tv":3463.86}]}
{"op":"mcm","clk":"992781459","pt":1580530426451,"mc":[{"id":"1.168130661","rc":[{"batb":[[0,2.72,32.82]],"ltp":2.78,"tv":1529.38,"id":25238892}]}]}
{"op":"mcm","clk":"992781556","pt":1580530428420,"mc":[{"id":"1.168130661","rc":[{"batl":[[1,2.74,86.92]],"ltp":2.72,"tv":1335.06,"id":26314798}]}]}
{"op":"mcm","clk":"992782686","pt":1580530454799,"mc":[{"id":"1.168130661","rc":[{"batb":[[0,2.74,3],[1,2.72,32.82],[2,2.7,8.79]],"ltp":2.78,"tv":1529.38,"id":25238892}]}]}
{"op":"mcm","clk":"992782972","pt":1580530461397,"mc":[{"id":"1.168130661","rc":[{"batb":[[1,2.72,1.98]],"ltp":2.78,"tv":1529.38,"id":25238892}]}]}
{"op":"mcm","clk":"992783370","pt":1580530472019,"mc":[{"id":"1.168130661","rc":[{"batb":[[0,2.72,1.98],[1,2.7,8.79],[2,2.6,16.66]],"ltp":2.78,"tv":1529.38,"id":25238892}]}]}
{"op":"mcm","clk":"992783682","pt":1580530479293,"mc":[{"id":"1.168130661","rc":[{"batb":[[0,2.72,32.82]],"ltp":2.78,"tv":1529.38,"id":25238892}]}]}
{"op":"mcm","clk":"992784737","pt":1580530506346,"mc":[{"id":"1.168130661","rc":[{"batb":[[0,2.74,3],[1,2.72,32.82],[2,2.7,8.79]],"ltp":2.78,"tv":1529.38,"id":25238892}]}]}
{"op":"mcm","clk":"992785097","pt":1580530514454,"mc":[{"id":"1.168130661","rc":[{"batb":[[1,2.72,1.98]],"ltp":2.78,"tv":1529.38,"id":25238892}]}]}
{"op":"mcm","clk":"992785697","pt":1580530529382,"mc":[{"id":"1.168130661","rc":[{"batb":[[0,2.72,1.98],[1,2.7,8.79],[2,2.6,16.66]],"ltp":2.78,"tv":1529.38,"id":25238892}]}]}
{"op":"mcm","clk":"992785816","pt":1580530532473,"mc":[{"id":"1.168130661","rc":[{"batb":[[0,2.72,32.82]],"ltp":2.78,"tv":1529.38,"id":25238892}]}]}
{"op":"mcm","clk":"992786626","pt":1580530553596,"mc":[{"id":"1.168130661","rc":[{"batl":[[1,2.74,84.92]],"ltp":2.72,"tv":1335.06,"id":26314798}]}]}
{"op":"mcm","clk":"992787040","pt":1580530563207,"mc":[{"id":"1.168130661","rc":[{"batb":[[0,2.74,3],[1,2.72,32.82],[2,2.7,8.79]],"ltp":2.78,"tv":1529.38,"id":25238892}]}]}
{"op":"mcm","clk":"992787195","pt":1580530567373,"mc":[{"id":"1.168130661","rc":[{"batb":[[1,2.72,1.98]],"ltp":2.78,"tv":1529.38,"id":25238892}]}]}
{"op":"mcm","clk":"992788002","pt":1580530586535,"mc":[{"id":"1.168130661","rc":[{"batb":[[0,2.72,1.98],[1,2.7,8.79],[2,2.6,16.66]],"ltp":2.78,"tv":1529.38,"id":25238892}]}]}
{"op":"mcm","clk":"992789164","pt":1580530602617,"mc":[{"id":"1.168130661","rc":[{"batb":[[0,2.72,32.82]],"ltp":2.78,"tv":1529.38,"id":25238892}]}]}
{"op":"mcm","clk":"992790058","pt":1580530620464,"mc":[{"id":"1.168130661","rc":[{"batb":[[0,2.74,3],[1,2.72,32.82],[2,2.7,8.79]],"ltp":2.78,"tv":1529.38,"id":25238892}]}]}
{"op":"mcm","clk":"992790865","pt":1580530637447,"mc":[{"id":"1.168130661","rc":[{"batb":[[1,2.72,1.98]],"ltp":2.78,"tv":1529.38,"id":25238892}]}]}
{"op":"mcm","clk":"992790883","pt":1580530637857,"mc":[{"id":"1.168130661","rc":[{"batb":[[0,2.72,1.98],[1,2.7,8.79],[2,2.6,16.66]],"ltp":2.78,"tv":1529.38,"id":25238892}]}]}
{"op":"mcm","clk":"992791596","pt":1580530654254,"mc":[{"id":"1.168130661","rc":[{"batb":[[0,2.72,32.82]],"ltp":2.78,"tv":1529.38,"id":25238892}]}]}
{"op":"mcm","clk":"992792326","pt":1580530671996,"mc":[{"id":"1.168130661","rc":[{"batb":[[0,2.74,3],[1,2.72,32.82],[2,2.7,8.79]],"ltp":2.78,"tv":1529.38,"id":25238892}]}]}
{"op":"mcm","clk":"992792991","pt":1580530689398,"mc":[{"id":"1.168130661","rc":[{"batb":[[1,2.72,1.98]],"ltp":2.78,"tv":1529.38,"id":25238892}]}]}
{"op":"mcm","clk":"992793956","pt":1580530712428,"mc":[{"id":"1.168130661","rc":[{"batb":[[0,2.72,1.98],[1,2.7,8.79],[2,2.6,16.66]],"ltp":2.78,"tv":1529.38,"id":25238892}]}]}
{"op":"mcm","clk":"992794499","pt":1580530724679,"mc":[{"id":"1.168130661","rc":[{"batb":[[0,2.72,32.82]],"ltp":2.78,"tv":1529.38,"id":25238892}]}]}
{"op":"mcm","clk":"992795444","pt":1580530746475,"mc":[{"id":"1.168130661","rc":[{"batb":[[0,2.74,3],[1,2.72,32.82],[2,2.7,8.79]],"ltp":2.78,"tv":1529.38,"id":25238892}]}]}
{"op":"mcm","clk":"992795918","pt":1580530759383,"mc":[{"id":"1.168130661","rc":[{"batb":[[1,2.72,1.98]],"ltp":2.78,"tv":1529.38,"id":25238892}]}]}
{"op":"mcm","clk":"992796060","pt":1580530763273,"mc":[{"id":"1.168130661","rc":[{"batb":[[0,2.72,1.98],[1,2.7,8.79],[2,2.6,16.66]],"ltp":2.78,"tv":1529.38,"id":25238892}]}]}
{"op":"mcm","clk":"992796561","pt":1580530777586,"mc":[{"id":"1.168130661","rc":[{"batb":[[0,2.72,32.82]],"ltp":2.78,"tv":1529.38,"id":25238892}]}]}
{"op":"mcm","clk":"992798158","pt":1580530820646,"mc":[{"id":"1.168130661","rc":[{"batb":[[0,2.74,3],[1,2.72,32.82],[2,2.7,8.79]],"ltp":2.78,"tv":1529.38,"id":25238892}]}]}
{"op":"mcm","clk":"992798527","pt":1580530829336,"mc":[{"id":"1.168130661","rc":[{"batb":[[1,2.72,1.98]],"ltp":2.78,"tv":1529.38,"id":25238892}]}]}
{"op":"mcm","clk":"992798799","pt":1580530837536,"mc":[{"id":"1.168130661","rc":[{"batb":[[0,2.72,1.98],[1,2.7,8.79],[2,2.6,16.66]],"ltp":2.78,"tv":1529.38,"id":25238892}]}]}
{"op":"mcm","clk":"992799049","pt":1580530845176,"mc":[{"id":"1.168130661","rc":[{"trd":[[30,5.09],[32,4.52],[36,1.18]],"batb":[[0,29,9.65],[1,28,1.04],[2,27,1.35]],"ltp":30.0,"tv":32.35,"id":25545675},{"trd":[[13.5,29.67]],"batb":[[0,13.5,12.66]],"ltp":13.5,"tv":165.54,"id":24707172}],"tv":3471.86}]}
{"op":"mcm","clk":"992799093","pt":1580530846462,"mc":[{"id":"1.168130661","rc":[{"batb":[[0,29,9.04]],"ltp":30.0,"tv":32.35,"id":25545675}]}]}
{"op":"mcm","clk":"992799124","pt":1580530847392,"mc":[{"id":"1.168130661","rc":[{"batb":[[0,2.72,32.82]],"ltp":2.78,"tv":1529.38,"id":25238892}]}]}
{"op":"mcm","clk":"992799373","pt":1580530854392,"mc":[{"id":"1.168130661","rc":[{"batb":[[1,28,1.67]],"ltp":30.0,"tv":32.35,"id":25545675}]}]}
{"op":"mcm","clk":"992799531","pt":1580530858881,"mc":[{"id":"1.168130661","rc":[{"trd":[[9,12.3],[10.5,14.57]],"batb":[[0,9,2.26]],"ltp":9.0,"tv":235.03,"id":24420205}],"tv":3475.86}]}
{"op":"mcm","clk":"992799701","pt":1580530862617,"mc":[{"id":"1.168130661","rc":[{"batb":[[2,8,41.56]],"ltp":9.0,"tv":235.03,"id":24420205}]}]}
{"op":"mcm","clk":"992800087","pt":1580530872424,"mc":[{"id":"1.168130661","rc":[{"batl":[[0,11,5.82],[1,11.5,40]],"ltp":9.0,"tv":235.03,"id":24420205}]}]}
{"op":"mcm","clk":"992800626","pt":1580530888555,"mc":[{"id":"1.168130661","rc":[{"batb":[[0,29,9.71]],"ltp":30.0,"tv":32.35,"id":25545675}]}]}
{"op":"mcm","clk":"992801059","pt":1580530901067,"mc":[{"id":"1.168130661","rc":[{"batb":[[0,2.74,3],[1,2.72,32.82],[2,2.7,8.79]],"ltp":2.78,"tv":1529.38,"id":25238892}]}]}
{"op":"mcm","clk":"992801558","pt":1580530913789,"mc":[{"id":"1.168130661","rc":[{"batb":[[0,29,9.88]],"ltp":30.0,"tv":32.35,"id":25545675}]}]}
{"op":"mcm","clk":"992801764","pt":1580530918275,"mc":[{"id":"1.168130661","rc":[{"batb":[[1,2.72,1.98]],"ltp":2.78,"tv":1529.38,"id":25238892}]}]}
{"op":"mcm","clk":"992802433","pt":1580530935208,"mc":[{"id":"1.168130661","rc":[{"batb":[[0,2.72,1.98],[1,2.7,8.79],[2,2.6,16.66]],"ltp":2.78,"tv":1529.38,"id":25238892}]}]}
{"op":"mcm","clk":"992802512","pt":1580530937411,"mc":[{"id":"1.168130661","rc":[{"batb":[[0,2.72,32.82]],"ltp":2.78,"tv":1529.38,"id":25238892}]}]}
{"op":"mcm","clk":"992802731","pt":1580530942887,"mc":[{"id":"1.168130661","rc":[{"batb":[[2,2.5,6.75]],"batl":[[0,2.84,10.81],[1,2.86,5.04],[2,2.88,6.72]],"ltp":2.78,"tv":1529.38,"id":25238892}]}]}
{"op":"mcm","clk":"992802816","pt":1580530944588,"mc":[{"id":"1.168130661","rc":[{"batl":[[0,2.8,15.36],[1,2.84,10.81],[2,2.86,5.04]],"ltp":2.78,"tv":1529.38,"id":25238892}]}]}
{"op":"mcm","clk":"992802898","pt":1580530946599,"mc":[{"id":"1.168130661","rc":[{"batl":[[0,2.78,15.47],[1,2.8,18.39],[2,2.84,10.81]],"ltp":2.78,"tv":1529.38,"id":25238892}]}]}
{"op":"mcm","clk":"992802976","pt":1580530947838,"mc":[{"id":"1.168130661","rc":[{"batl":[[1,2.84,10.81],[2,2.86,5.04]],"ltp":2.78,"tv":1529.38,"id":25238892}]}]}
{"op":"mcm","clk":"992813084","pt":1580530955655,"mc":[{"id":"1.168130661","rc":[{"batb":[[0,2.72,1.98]],"batl":[[0,2.76,9.07],[1,2.78,15.47],[2,2.84,10.81]],"ltp":2.78,"tv":1529.38,"id":25238892}]}]}
{"op":"mcm","clk":"992813257","pt":1580530958648,"mc":[{"id":"1.168130661","rc":[{"batl":[[1,2.84,10.81],[2,2.86,5.04]],"ltp":2.78,"tv":1529.38,"id":25238892}]}]}
{"op":"mcm","clk":"992813277","pt":1580530958913,"mc":[{"id":"1.168130661","rc":[{"batl":[[0,2.76,24.65]],"ltp":2.78,"tv":1529.38,"id":25238892}]}]}
{"op":"mcm","clk":"992813529","pt":1580530963761,"mc":[{"id":"1.168130661","rc":[{"trd":[[2.72,64.55]],"batb":[[0,2.7,9.26],[1,2.5,6.75],[2,2.48,111]],"ltp":2.72,"tv":1532.41,"id":25238892}],"tv":3478.89}]}
{"op":"mcm","clk":"992813588","pt":1580530964853,"mc":[{"id":"1.168130661","rc":[{"batl":[[0,2.76,9.07]],"ltp":2.72,"tv":1532.41,"id":25238892}]}]}
{"op":"mcm","clk":"992813632","pt":1580530965733,"mc":[{"id":"1.168130661","rc":[{"batl":[[0,2.76,23.16]],"ltp":2.72,"tv":1532.41,"id":25238892}]}]}
{"op":"mcm","clk":"992816911","pt":1580531044419,"mc":[{"id":"1.168130661","rc":[{"batl":[[0,11,1.82]],"ltp":9.0,"tv":235.03,"id":24420205}]}]}
{"op":"mcm","clk":"992817607","pt":1580531063255,"mc":[{"id":"1.168130661","rc":[{"trd":[[2.76,274.01]],"batl":[[0,2.84,10.81],[1,2.86,5.04],[2,2.88,6.72]],"ltp":2.76,"tv":1578.73,"id":25238892},{"trd":[[9,16.76]],"batb":[[0,8.8,3.74],[1,8,41.56],[2,7.2,13.03]],"ltp":9.0,"tv":239.49,"id":24420205}],"tv":3529.67}]}
{"op":"mcm","clk":"992817630","pt":1580531064025,"mc":[{"id":"1.168130661","rc":[{"batb":[[0,30,1.45],[1,29,9],[2,28,1.67]],"ltp":30.0,"tv":32.35,"id":25545675}]}]}
{"op":"mcm","clk":"992818406","pt":1580531084658,"mc":[{"id":"1.168130661","rc":[{"batb":[[1,2.52,4],[2,2.5,6.75]],"batl":[[0,2.82,3.57],[1,2.84,10.81],[2,2.86,5.04]],"ltp":2.76,"tv":1578.73,"id":25238892}]}]}
{"op":"mcm","clk":"992818419","pt":1580531085068,"mc":[{"id":"1.168130661","rc":[{"batb":[[0,8.2,3.74]],"ltp":9.0,"tv":239.49,"id":24420205}]}]}
{"op":"mcm","clk":"992819745","pt":1580531117607,"mc":[{"id":"1.168130661","rc":[{"batb":[[0,2.72,3.78],[1,2.7,8.79]],"ltp":2.76,"tv":1578.73,"id":25238892}]}]}
{"op":"mcm","clk":"992820384","pt":1580531130335,"mc":[{"id":"1.168130661","rc":[{"batb":[[0,2.72,34.62]],"ltp":2.76,"tv":1578.73,"id":25238892}]}]}
{"op":"mcm","clk":"992821062","pt":1580531146574,"mc":[{"id":"1.168130661","rc":[{"batb":[[0,2.74,13.96],[1,2.72,34.62],[2,2.7,8.79]],"ltp":2.76,"tv":1578.73,"id":25238892}]}]}
{"op":"mcm","clk":"992821141","pt":1580531148585,"mc":[{"id":"1.168130661","rc":[{"batb":[[0,2.76,30.39],[1,2.74,13.96],[2,2.72,3.78]],"ltp":2.76,"tv":1578.73,"id":25238892}]}]}
{"op":"mcm","clk":"992821397","pt":1580531154061,"mc":[{"id":"1.168130661","rc":[{"batl":[[0,10.5,2],[1,11,1.82],[2,11.5,40]],"ltp":9.0,"tv":239.49,"id":24420205}]}]}
{"op":"mcm","clk":"992821816","pt":1580531163591,"mc":[{"id":"1.168130661","rc":[{"batb":[[1,2.74,10.96]],"ltp":2.76,"tv":1578.73,"id":25238892}]}]}
{"op":"mcm","clk":"992822510","pt":1580531180412,"mc":[{"id":"1.168130661","rc":[{"batb":[[2,8,11.74]],"ltp":9.8,"tv":178.48,"id":420}]}]}
{"op":"mcm","clk":"992822558","pt":1580531181499,"mc":[{"id":"1.168130661","rc":[{"batb":[[2,2.7,9.26]],"batl":[[0,2.84,10.81],[1,2.86,5.04],[2,2.88,6.72]],"ltp":2.76,"tv":1578.73,"id":25238892}]}]}
{"op":"mcm","clk":"992824805","pt":1580531237262,"mc":[{"id":"1.168130661","rc":[{"batb":[[2,8,10]],"ltp":9.8,"tv":178.48,"id":420}]}]}
{"op":"mcm","clk":"992828542","pt":1580531349701,"mc":[{"id":"1.168130661","rc":[{"batb":[[0,2.76,30.86],[2,2.7,8.79]],"ltp":2.76,"tv":1578.73,"id":25238892},{"batb":[[0,8.4,2.01],[1,8.2,3.71],[2,8,41.56]],"ltp":9.0,"tv":239.49,"id":24420205},{"batb":[[0,2.66,10.91]],"ltp":2.72,"tv":1335.06,"id":26314798},{"batb":[[0,10,1.98],[1,9.8,42.02],[2,8.4,3]],"ltp":9.8,"tv":178.48,"id":420}]}]}
{"op":"mcm","clk":"992829371","pt":1580531374227,"mc":[{"id":"1.168130661","rc":[{"batb":[[0,8.6,1.71],[1,8.4,1.98]],"ltp":9.0,"tv":239.49,"id":24420205}]}]}
{"op":"mcm","clk":"992830189","pt":1580531406689,"mc":[{"id":"1.168130661","rc":[{"batb":[[0,8.6,1.92]],"ltp":9.0,"tv":239.49,"id":24420205}]}]}
{"op":"mcm","clk":"992842762","pt":1580531708225,"mc":[{"id":"1.168130661","rc":[{"batb":[[0,8.8,1.45],[1,8.6,1.89],[2,8.4,1.98]],"ltp":9.0,"tv":239.49,"id":24420205}]}]}
{"op":"mcm","clk":"992842923","pt":1580531712238,"mc":[{"id":"1.168130661","rc":[{"batl":[[1,11,5.82]],"ltp":9.0,"tv":239.49,"id":24420205}]}]}
{"op":"mcm","clk":"992866150","pt":1580532109789,"mc":[{"id":"1.168130661","rc":[{"trd":[[9.8,48],[10,73.35]],"batb":[[0,9.8,38],[1,8.4,3],[2,8,10]],"ltp":9.8,"tv":190.48,"id":420}],"tv":3541.68}]}
{"op":"mcm","clk":"992922052","pt":1580533238560,"mc":[{"id":"1.168130661","rc":[{"batl":[[0,2.82,2],[1,2.84,10.81],[2,2.86,5.04]],"ltp":2.76,"tv":1578.73,"id":25238892}]}]}
{"op":"mcm","clk":"992940411","pt":1580533642316,"mc":[{"id":"1.168130661","rc":[{"batl":[[0,2.84,10.81],[1,2.86,5.04],[2,2.88,6.72]],"ltp":2.76,"tv":1578.73,"id":25238892}]}]}
{"op":"mcm","clk":"992940594","pt":1580533646820,"mc":[{"id":"1.168130661","rc":[{"batl":[[0,2.82,2],[1,2.84,10.81],[2,2.86,5.04]],"ltp":2.76,"tv":1578.73,"id":25238892}]}]}
{"op":"mcm","clk":"992960678","pt":1580533881739,"mc":[{"id":"1.168130661","rc":[{"batb":[[0,2.7,2],[1,2.66,10.91],[2,2.62,132.25]],"ltp":2.72,"tv":1335.06,"id":26314798}]}]}
{"op":"mcm","clk":"992960790","pt":1580533884052,"mc":[{"id":"1.168130661","rc":[{"batl":[[0,2.72,11.93]],"ltp":2.72,"tv":1335.06,"id":26314798}]}]}
{"op":"mcm","clk":"992960904","pt":1580533886562,"mc":[{"id":"1.168130661","rc":[{"batl":[[0,2.72,13.93]],"ltp":2.72,"tv":1335.06,"id":26314798}]}]}
{"op":"mcm","clk":"992961085","pt":1580533890664,"mc":[{"id":"1.168130661","rc":[{"batl":[[0,2.72,15.93]],"ltp":2.72,"tv":1335.06,"id":26314798}]}]}
{"op":"mcm","clk":"992961397","pt":1580533897695,"mc":[{"id":"1.168130661","rc":[{"batb":[[0,2.78,2],[1,2.76,30.86],[2,2.74,10.96]],"ltp":2.76,"tv":1578.73,"id":25238892}]}]}
{"op":"mcm","clk":"992967578","pt":1580534051527,"mc":[{"id":"1.168130661","rc":[{"batl":[[0,2.84,10.81],[1,2.86,5.04],[2,2.88,6.72]],"ltp":2.76,"tv":1578.73,"id":25238892}]}]}
{"op":"mcm","clk":"992967753","pt":1580534055240,"mc":[{"id":"1.168130661","rc":[{"batl":[[0,2.82,2],[1,2.84,10.81],[2,2.86,5.04]],"ltp":2.76,"tv":1578.73,"id":25238892}]}]}
{"op":"mcm","clk":"992967827","pt":1580534056534,"mc":[{"id":"1.168130661","rc":[{"batl":[[0,2.82,4]],"ltp":2.76,"tv":1578.73,"id":25238892}]}]}
{"op":"mcm","clk":"992969035","pt":1580534089722,"mc":[{"id":"1.168130661","rc":[{"trd":[[15,54.8]],"batl":[[0,15.5,10],[1,21,14.12],[2,29,2.45]],"ltp":15.0,"tv":178.66,"id":24707172}],"tv":3554.8}]}
{"op":"mcm","clk":"992969182","pt":1580534093327,"mc":[{"id":"1.168130661","rc":[{"batb":[[0,14,4.52],[1,13.5,12.66],[2,13,4.7]],"ltp":15.0,"tv":178.66,"id":24707172}]}]}
{"op":"mcm","clk":"992969427","pt":1580534099629,"mc":[{"id":"1.168130661","rc":[{"trd":[[2.82,109.42]],"batl":[[0,2.84,10.81],[1,2.86,5.04],[2,2.88,6.72]],"ltp":2.82,"tv":1586.73,"id":25238892}],"tv":3562.8}]}
{"op":"mcm","clk":"992969528","pt":1580534102029,"mc":[{"id":"1.168130661","rc":[{"batb":[[0,2.78,6]],"ltp":2.82,"tv":1586.73,"id":25238892}]}]}
{"op":"mcm","clk":"992975567","pt":1580534238189,"mc":[{"id":"1.168130661","rc":[{"trd":[[2.72,101.42]],"batl":[[0,2.72,12.89]],"ltp":2.72,"tv":1341.14,"id":26314798}],"tv":3568.87}]}
{"op":"mcm","clk":"992975701","pt":1580534241127,"mc":[{"id":"1.168130661","rc":[{"batl":[[0,2.84,12.81]],"ltp":2.82,"tv":1586.73,"id":25238892}]}]}
{"op":"mcm","clk":"992977322","pt":1580534285648,"mc":[{"id":"1.168130661","rc":[{"trd":[[2.62,103.22],[2.66,59.13],[2.7,401.04]],"batb":[[0,2.64,11.24],[1,2.62,104.47],[2,2.6,75]],"batl":[[0,2.66,3.59],[1,2.72,12.89],[2,2.74,84.92]],"ltp":2.62,"tv":1422.51,"id":26314798}],"tv":3650.25}]}
{"op":"mcm","clk":"992977417","pt":1580534288679,"mc":[{"id":"1.168130661","rc":[{"batb":[[0,2.8,6.15],[1,2.78,6],[2,2.76,30.86]],"ltp":2.82,"tv":1586.73,"id":25238892}]}]}
{"op":"mcm","clk":"992977441","pt":1580534289247,"mc":[{"id":"1.168130661","rc":[{"batb":[[0,14.5,1.18],[1,14,4.52],[2,13.5,12.66]],"ltp":15.0,"tv":178.66,"id":24707172},{"batb":[[0,10,1.72],[1,9.8,38],[2,8.4,3]],"ltp":9.8,"tv":190.48,"id":420}]}]}
{"op":"mcm","clk":"992977489","pt":1580534290643,"mc":[{"id":"1.168130661","rc":[{"batb":[[2,2.7,9.26]],"ltp":2.82,"tv":1586.73,"id":25238892},{"trd":[[2.62,166.12],[2.64,124.5]],"batb":[[0,2.62,73.02],[1,2.6,75],[2,2.52,25]],"ltp":2.62,"tv":1507.89,"id":26314798}],"tv":3735.63}]}
{"op":"mcm","clk":"992977525","pt":1580534291471,"mc":[{"id":"1.168130661","rc":[{"batb":[[0,30,2.99]],"ltp":30.0,"tv":32.35,"id":25545675},{"batb":[[0,2.8,22.61]],"ltp":2.82,"tv":1586.73,"id":25238892},{"batb":[[0,14.5,4.36]],"ltp":15.0,"tv":178.66,"id":24707172},{"batb":[[0,8.8,6.69]],"ltp":9.0,"tv":239.49,"id":24420205},{"batb":[[0,2.64,17.46],[1,2.62,73.02],[2,2.6,75]],"ltp":2.62,"tv":1507.89,"id":26314798},{"batb":[[0,10,6.33]],"ltp":9.8,"tv":190.48,"id":420}]}]}
{"op":"mcm","clk":"992977614","pt":1580534293580,"mc":[{"id":"1.168130661","rc":[{"batb":[[2,28,1.04]],"ltp":30.0,"tv":32.35,"id":25545675}]}]}
{"op":"mcm","clk":"992977671","pt":1580534295080,"mc":[{"id":"1.168130661","rc":[{"trd":[[2.62,216.06],[2.64,159.41]],"batb":[[0,2.62,48.05],[1,2.6,75],[2,2.52,25]],"ltp":2.62,"tv":1592.74,"id":26314798}],"tv":3820.48}]}
{"op":"mcm","clk":"992977768","pt":1580534297460,"mc":[{"id":"1.168130661","rc":[{"batb":[[1,13.5,12.66],[2,13,4.7]],"ltp":15.0,"tv":178.66,"id":24707172}]}]}
{"op":"mcm","clk":"992977947","pt":1580534301677,"mc":[{"id":"1.168130661","rc":[{"batb":[[0,30,3.58]],"ltp":30.0,"tv":32.35,"id":25545675},{"trd":[[2.62,283.4]],"batb":[[0,2.62,14.38]],"ltp":2.62,"tv":1660.08,"id":26314798}],"tv":3887.82}]}
{"op":"mcm","clk":"992977975","pt":1580534302395,"mc":[{"id":"1.168130661","rc":[{"trd":[[2.62,301.16]],"batb":[[0,2.62,5.5]],"ltp":2.62,"tv":1677.84,"id":26314798}],"tv":3905.58}]}
{"op":"mcm","clk":"992978280","pt":1580534310577,"mc":[{"id":"1.168130661","rc":[{"batb":[[0,9,1.83],[1,8.8,6.67]],"ltp":9.0,"tv":239.49,"id":24420205}]}]}
{"op":"mcm","clk":"992978701","pt":1580534321602,"mc":[{"id":"1.168130661","rc":[{"batb":[[0,9.2,1.37],[1,9,1.83],[2,8.8,5.24]],"ltp":9.0,"tv":239.49,"id":24420205}]}]}
{"op":"mcm","clk":"992980444","pt":1580534366571,"mc":[{"id":"1.168130661","rc":[{"batl":[[0,2.84,10.81]],"ltp":2.82,"tv":1586.73,"id":25238892}]}]}
{"op":"mcm","clk":"992983761","pt":1580534439478,"mc":[{"id":"1.168130661","rc":[{"trd":[[2.62,306.74]],"batb":[[0,2.62,2.71]],"batl":[[1,2.72,10.89]],"ltp":2.62,"tv":1683.42,"id":26314798}],"tv":3911.16}]}
{"op":"mcm","clk":"992983846","pt":1580534441488,"mc":[{"id":"1.168130661","rc":[{"batl":[[1,2.72,8.89]],"ltp":2.62,"tv":1683.42,"id":26314798}]}]}
{"op":"mcm","clk":"992984012","pt":1580534445881,"mc":[{"id":"1.168130661","rc":[{"batl":[[1,2.72,6.89]],"ltp":2.62,"tv":1683.42,"id":26314798}]}]}
{"op":"mcm","clk":"992999494","pt":1580534580588,"mc":[{"id":"1.168130661","rc":[{"batb":[[0,2.64,2],[1,2.62,2.71],[2,2.6,75]],"ltp":2.62,"tv":1683.42,"id":26314798}]}]}
{"op":"mcm","clk":"992999704","pt":1580534587480,"mc":[{"id":"1.168130661","rc":[{"trd":[[2.66,66.31]],"batl":[[0,2.72,17.8],[1,2.74,84.92],[2,2.76,199]],"ltp":2.66,"tv":1690.6,"id":26314798}],"tv":3918.34}]}
{"op":"mcm","clk":"992999971","pt":1580534594878,"mc":[{"id":"1.168130661","rc":[{"batl":[[0,2.7,4],[1,2.72,17.8],[2,2.74,84.92]],"ltp":2.66,"tv":1690.6,"id":26314798}]}]}
{"op":"mcm","clk":"993000072","pt":1580534598008,"mc":[{"id":"1.168130661","rc":[{"batb":[[0,2.66,2],[1,2.64,2],[2,2.62,2.71]],"ltp":2.66,"tv":1690.6,"id":26314798}]}]}
{"op":"mcm","clk":"993000340","pt":1580534606937,"mc":[{"id":"1.168130661","rc":[{"batl":[[0,2.7,9]],"ltp":2.66,"tv":1690.6,"id":26314798}]}]}
{"op":"mcm","clk":"993000472","pt":1580534610531,"mc":[{"id":"1.168130661","rc":[{"trd":[[2.82,113.42],[2.84,90.36]],"batb":[[1,2.78,4]],"batl":[[0,2.86,5.59],[1,2.88,6.72],[2,2.9,3.36]],"ltp":2.82,"tv":1611.27,"id":25238892}],"tv":3942.87}]}
{"op":"mcm","clk":"993000524","pt":1580534612019,"mc":[{"id":"1.168130661","rc":[{"batl":[[0,2.7,5]],"ltp":2.66,"tv":1690.6,"id":26314798}]}]}
{"op":"mcm","clk":"993005973","pt":1580534757602,"mc":[{"id":"1.168130661","rc":[{"batb":[[0,2.82,2],[1,2.8,22.61],[2,2.78,4]],"ltp":2.82,"tv":1611.27,"id":25238892}]}]}
{"op":"mcm","clk":"993010137","pt":1580534864387,"mc":[{"id":"1.168130661","rc":[{"batl":[[0,2.68,4],[1,2.7,5],[2,2.72,17.8]],"ltp":2.66,"tv":1690.6,"id":26314798}]}]}
{"op":"mcm","clk":"993026416","pt":1580535245648,"mc":[{"id":"1.168130661","rc":[{"batl":[[0,10,2.53],[1,10.5,2],[2,11,5.82]],"ltp":9.0,"tv":239.49,"id":24420205}]}]}
{"op":"mcm","clk":"993026974","pt":1580535257960,"mc":[{"id":"1.168130661","rc":[{"trd":[[30,10.15]],"batb":[[0,30,1.04]],"ltp":30.0,"tv":37.41,"id":25545675}],"tv":3947.94}]}
{"op":"mcm","clk":"993027283","pt":1580535264552,"mc":[{"id":"1.168130661","rc":[{"batb":[[0,29,9.46],[1,28,1.04],[2,27,1.35]],"ltp":30.0,"tv":37.41,"id":25545675}]}]}
{"op":"mcm","clk":"993027497","pt":1580535269652,"mc":[{"id":"1.168130661","rc":[{"batl":[[0,2.7,5],[1,2.72,17.8],[2,2.74,84.92]],"ltp":2.66,"tv":1690.6,"id":26314798}]}]}
{"op":"mcm","clk":"993027593","pt":1580535271670,"mc":[{"id":"1.168130661","rc":[{"batb":[[1,28,1.67]],"ltp":30.0,"tv":37.41,"id":25545675}]}]}
{"op":"mcm","clk":"993027615","pt":1580535272184,"mc":[{"id":"1.168130661","rc":[{"batl":[[0,48,2.18]],"ltp":30.0,"tv":37.41,"id":25545675}]}]}
{"op":"mcm","clk":"993032470","pt":1580535384477,"mc":[{"id":"1.168130661","rc":[{"trd":[[9,20.42],[9.2,11.85]],"batb":[[0,8.8,5.24],[1,8.4,1.98],[2,8,42.17]],"ltp":9.0,"tv":245.89,"id":24420205}],"tv":3954.34}]}
{"op":"mcm","clk":"993033028","pt":1580535397368,"mc":[{"id":"1.168130661","rc":[{"batb":[[0,29,9.63]],"ltp":30.0,"tv":37.41,"id":25545675},{"batl":[[0,9.8,1.62],[1,10,2.53],[2,10.5,2]],"ltp":9.0,"tv":245.89,"id":24420205}]}]}
{"op":"mcm","clk":"993033165","pt":1580535401392,"mc":[{"id":"1.168130661","rc":[{"batb":[[2,8.2,2.67]],"batl":[[0,9.8,3.34]],"ltp":9.0,"tv":245.89,"id":24420205}]}]}
{"op":"mcm","clk":"993033674","pt":1580535415541,"mc":[{"id":"1.168130661","rc":[{"batl":[[0,9.6,2],[1,9.8,3.34],[2,10,2.53]],"ltp":9.0,"tv":245.89,"id":24420205}]}]}
{"op":"mcm","clk":"993033769","pt":1580535418222,"mc":[{"id":"1.168130661","rc":[{"batl":[[1,2.88,8.72]],"ltp":2.82,"tv":1611.27,"id":25238892}]}]}
{"op":"mcm","clk":"993034007","pt":1580535423346,"mc":[{"id":"1.168130661","rc":[{"batl":[[0,9.6,4.09]],"ltp":9.0,"tv":245.89,"id":24420205}]}]}
{"op":"mcm","clk":"993046448","pt":1580535468415,"mc":[{"id":"1.168130661","rc":[{"batl":[[0,9.6,2.09]],"ltp":9.0,"tv":245.89,"id":24420205}]}]}
{"op":"mcm","clk":"993047754","pt":1580535500295,"mc":[{"id":"1.168130661","rc":[{"batl":[[0,48,1.85]],"ltp":30.0,"tv":37.41,"id":25545675}]}]}
{"op":"mcm","clk":"993049459","pt":1580535542550,"mc":[{"id":"1.168130661","rc":[{"batl":[[1,2.88,6.72]],"ltp":2.82,"tv":1611.27,"id":25238892}]}]}
{"op":"mcm","clk":"993050662","pt":1580535573294,"mc":[{"id":"1.168130661","rc":[{"batb":[[0,30,1.2],[1,29,9],[2,28,1.67]],"ltp":30.0,"tv":37.41,"id":25545675}]}]}
{"op":"mcm","clk":"993053168","pt":1580535624498,"mc":[{"id":"1.168130661","rc":[{"batl":[[1,9.8,1.72]],"ltp":9.0,"tv":245.89,"id":24420205}]}]}
{"op":"mcm","clk":"993053688","pt":1580535635650,"mc":[{"id":"1.168130661","rc":[{"batl":[[0,9.8,1.72],[1,10,2.53],[2,11,4]],"ltp":9.0,"tv":245.89,"id":24420205}]}]}
{"op":"mcm","clk":"993053692","pt":1580535635752,"mc":[{"id":"1.168130661","rc":[{"batl":[[0,9.8,3.76]],"ltp":9.0,"tv":245.89,"id":24420205}]}]}
{"op":"mcm","clk":"993054818","pt":1580535660954,"mc":[{"id":"1.168130661","rc":[{"batb":[[0,9,1.81],[1,8.8,5.24],[2,8.4,1.98]],"ltp":9.0,"tv":245.89,"id":24420205}]}]}
{"op":"mcm","clk":"993056488","pt":1580535694410,"mc":[{"id":"1.168130661","rc":[{"batb":[[0,8.8,5.24],[1,8.4,1.98],[2,8,42.17]],"batl":[[0,9.8,2.04]],"ltp":9.0,"tv":245.89,"id":24420205}]}]}
{"op":"mcm","clk":"993058076","pt":1580535727662,"mc":[{"id":"1.168130661","rc":[{"batb":[[2,8.2,2.67]],"batl":[[0,9.6,1.76],[1,9.8,2.04],[2,10,2.53]],"ltp":9.0,"tv":245.89,"id":24420205}]}]}
{"op":"mcm","clk":"993058564","pt":1580535739381,"mc":[{"id":"1.168130661","rc":[{"batl":[[1,9.8,6.04]],"ltp":9.0,"tv":245.89,"id":24420205}]}]}
{"op":"mcm","clk":"993063249","pt":1580535843690,"mc":[{"id":"1.168130661","rc":[{"batb":[[0,9,1.92],[1,8.8,5.24],[2,8.4,1.98]],"ltp":9.0,"tv":245.89,"id":24420205}]}]}
{"op":"mcm","clk":"993063889","pt":1580535856914,"mc":[{"id":"1.168130661","rc":[{"batl":[[0,9.8,6.04],[1,10,2.53],[2,11.5,40]],"ltp":9.0,"tv":245.89,"id":24420205}]}]}
{"op":"mcm","clk":"993064079","pt":1580535860004,"mc":[{"id":"1.168130661","rc":[{"batl":[[0,9.8,2.04],[2,11,4]],"ltp":9.0,"tv":245.89,"id":24420205}]}]}
{"op":"mcm","clk":"993074811","pt":1580536077017,"mc":[{"id":"1.168130661","rc":[{"batl":[[0,2.68,2],[1,2.7,5],[2,2.72,17.8]],"ltp":2.66,"tv":1690.6,"id":26314798}]}]}
{"op":"mcm","clk":"993080251","pt":1580536220001,"mc":[{"id":"1.168130661","rc":[{"batl":[[0,2.68,4]],"ltp":2.66,"tv":1690.6,"id":26314798}]}]}
{"op":"mcm","clk":"993080340","pt":1580536222684,"mc":[{"id":"1.168130661","rc":[{"batl":[[0,2.68,6]],"ltp":2.66,"tv":1690.6,"id":26314798}]}]}
{"op":"mcm","clk":"993080475","pt":1580536227230,"mc":[{"id":"1.168130661","rc":[{"batl":[[0,2.68,8]],"ltp":2.66,"tv":1690.6,"id":26314798}]}]}
{"op":"mcm","clk":"993080640","pt":1580536231618,"mc":[{"id":"1.168130661","rc":[{"batb":[[0,30,1.7]],"ltp":30.0,"tv":37.41,"id":25545675},{"trd":[[2.84,91.45],[2.86,162.29]],"batl":[[0,2.88,6.72],[1,2.9,3.36],[2,2.92,3.36]],"ltp":2.86,"tv":1622.45,"id":25238892},{"trd":[[15.5,34.52]],"batl":[[0,15.5,8.97]],"ltp":15.5,"tv":180.72,"id":24707172},{"trd":[[9.8,27.58]],"batl":[[0,10,2.53],[1,11,4],[2,11.5,40]],"ltp":9.8,"tv":246.71,"id":24420205},{"trd":[[2.68,89.7]],"batl":[[0,2.68,2.04]],"ltp":2.68,"tv":1702.52,"id":26314798},{"batb":[[0,10.5,1.52],[1,10,6.33],[2,9.8,38]],"ltp":9.8,"tv":190.48,"id":420}],"tv":3980.32}]}
{"op":"mcm","clk":"993080678","pt":1580536232388,"mc":[{"id":"1.168130661","rc":[{"batb":[[1,2.64,4],[2,2.62,4.71]],"batl":[[0,2.68,2]],"ltp":2.68,"tv":1702.52,"id":26314798}]}]}
{"op":"mcm","clk":"993080725","pt":1580536233421,"mc":[{"id":"1.168130661","rc":[{"batb":[[1,2.64,6]],"ltp":2.68,"tv":1702.52,"id":26314798}]}]}
{"op":"mcm","clk":"993080911","pt":1580536239649,"mc":[{"id":"1.168130661","rc":[{"batb":[[0,2.84,16.74],[1,2.82,31.75],[2,2.8,16.46]],"ltp":2.86,"tv":1622.45,"id":25238892},{"batb":[[2,8.4,3.54]],"ltp":9.8,"tv":246.71,"id":24420205}]}]}
{"op":"mcm","clk":"993081427","pt":1580536255347,"mc":[{"id":"1.168130661","rc":[{"batb":[[1,2.82,2]],"ltp":2.86,"tv":1622.45,"id":25238892}]}]}
{"op":"mcm","clk":"993081878","pt":1580536269165,"mc":[{"id":"1.168130661","rc":[{"batl":[[0,9.8,2],[1,10,2.53],[2,11,4]],"ltp":9.8,"tv":246.71,"id":24420205}]}]}
{"op":"mcm","clk":"993084926","pt":1580536345654,"mc":[{"id":"1.168130661","rc":[{"trd":[[9,24.25]],"batb":[[0,8.8,5.24],[1,8.4,3.54],[2,8,40.61]],"batl":[[0,9.8,2.6],[2,11.5,40]],"ltp":9.0,"tv":250.54,"id":24420205}],"tv":3984.15}]}
{"op":"mcm","clk":"993085058","pt":1580536348274,"mc":[{"id":"1.168130661","rc":[{"batb":[[1,8.4,1.98],[2,8,42.17]],"ltp":9.0,"tv":250.54,"id":24420205}]}]}
{"op":"mcm","clk":"993095496","pt":1580536365676,"mc":[{"id":"1.168130661","rc":[{"batb":[[2,8.2,2.67]],"batl":[[0,9.6,2.36],[1,9.8,2],[2,10,2.53]],"ltp":9.0,"tv":250.54,"id":24420205}]}]}
{"op":"mcm","clk":"993095887","pt":1580536375695,"mc":[{"id":"1.168130661","rc":[{"batl":[[1,10,2.53],[2,11.5,40]],"ltp":9.0,"tv":250.54,"id":24420205}]}]}
{"op":"mcm","clk":"993096071","pt":1580536380479,"mc":[{"id":"1.168130661","rc":[{"batl":[[1,9.8,4],[2,10,2.53]],"ltp":9.0,"tv":250.54,"id":24420205}]}]}
{"op":"mcm","clk":"993096446","pt":1580536392242,"mc":[{"id":"1.168130661","rc":[{"batb":[[0,2.86,2],[1,2.84,16.74]],"ltp":2.86,"tv":1622.45,"id":25238892}]}]}
{"op":"mcm","clk":"993096621","pt":1580536397853,"mc":[{"id":"1.168130661","rc":[{"batl":[[1,10,2.53],[2,11.5,40]],"ltp":9.0,"tv":250.54,"id":24420205}]}]}
{"op":"mcm","clk":"993097987","pt":1580536429073,"mc":[{"id":"1.168130661","rc":[{"batl":[[0,9.8,2.29]],"ltp":9.0,"tv":250.54,"id":24420205}]}]}
{"op":"mcm","clk":"993099536","pt":1580536460424,"mc":[{"id":"1.168130661","rc":[{"trd":[[9,25.46]],"batb":[[0,9,1.2],[1,8.8,5.24],[2,8.4,1.98]],"batl":[[0,9.8,1.68]],"ltp":9.0,"tv":251.75,"id":24420205}],"tv":3985.36}]}
{"op":"mcm","clk":"993100013","pt":1580536472122,"mc":[{"id":"1.168130661","rc":[{"batl":[[2,11,4]],"ltp":9.0,"tv":251.75,"id":24420205}]}]}
{"op":"mcm","clk":"993100130","pt":1580536475313,"mc":[{"id":"1.168130661","rc":[{"batl":[[0,9.8,3.3]],"ltp":9.0,"tv":251.75,"id":24420205}]}]}
{"op":"mcm","clk":"993100435","pt":1580536482624,"mc":[{"id":"1.168130661","rc":[{"batl":[[0,9.6,2],[1,9.8,3.3],[2,10,2.53]],"ltp":9.0,"tv":251.75,"id":24420205}]}]}
{"op":"mcm","clk":"993100858","pt":1580536492327,"mc":[{"id":"1.168130661","rc":[{"batb":[[0,8.8,5.24],[1,8.4,1.98],[2,8,42.17]],"batl":[[1,9.8,2.18]],"ltp":9.0,"tv":251.75,"id":24420205}]}]}
{"op":"mcm","clk":"993102283","pt":1580536523877,"mc":[{"id":"1.168130661","rc":[{"batl":[[0,9.2,15],[1,9.6,2],[2,9.8,2.18]],"ltp":9.0,"tv":251.75,"id":24420205}]}]}
{"op":"mcm","clk":"993102978","pt":1580536536709,"mc":[{"id":"1.168130661","rc":[{"batb":[[0,32,1.06],[1,30,1.2],[2,29,9]],"ltp":30.0,"tv":37.41,"id":25545675},{"trd":[[2.88,63.25]],"batl":[[0,2.9,3.53],[1,2.92,3.36],[2,2.94,8.4]],"ltp":2.88,"tv":1635.55,"id":25238892},{"trd":[[15.5,36.94]],"batl":[[0,15.5,7.76]],"ltp":15.5,"tv":183.14,"id":24707172},{"trd":[[9.2,15.95]],"batl":[[0,9.2,12.95]],"ltp":9.2,"tv":255.85,"id":24420205},{"trd":[[2.68,93.7]],"batb":[[0,2.68,5.04],[1,2.66,2],[2,2.64,6]],"batl":[[0,2.7,5],[1,2.72,17.8],[2,2.74,84.92]],"ltp":2.68,"tv":1706.52,"id":26314798},{"trd":[[11,3.44]],"batl":[[0,11,2.28]],"ltp":11.0,"tv":193.92,"id":420}],"tv":4012.42}]}
{"op":"mcm","clk":"993103009","pt":1580536537320,"mc":[{"id":"1.168130661","rc":[{"trd":[[2.88,63.59]],"batl":[[0,2.9,3.36]],"ltp":2.88,"tv":1635.89,"id":25238892},{"batl":[[1,9.8,2.18],[2,10,2.53]],"ltp":9.2,"tv":255.85,"id":24420205},{"batl":[[2,32,9.17]],"ltp":11.0,"tv":193.92,"id":420}],"tv":4012.76}]}
{"op":"mcm","clk":"993103282","pt":1580536542520,"mc":[{"id":"1.168130661","rc":[{"trd":[[2.68,96.7]],"batb":[[0,2.68,3.54]],"ltp":2.68,"tv":1709.52,"id":26314798}],"tv":4015.76}]}
{"op":"mcm","clk":"993103327","pt":1580536543705,"mc":[{"id":"1.168130661","rc":[{"batb":[[2,2.64,8]],"ltp":2.68,"tv":1709.52,"id":26314798}]}]}
{"op":"mcm","clk":"993103463","pt":1580536547630,"mc":[{"id":"1.168130661","rc":[{"trd":[[2.68,103.78]],"batb":[[0,2.66,2],[1,2.64,8],[2,2.62,4.71]],"batl":[[0,2.68,1.46]],"ltp":2.68,"tv":1716.6,"id":26314798}],"tv":4022.84}]}
{"op":"mcm","clk":"993103663","pt":1580536551544,"mc":[{"id":"1.168130661","rc":[{"batb":[[1,30,1.79]],"ltp":30.0,"tv":37.41,"id":25545675},{"batl":[[0,2.7,1.46]],"ltp":2.68,"tv":1716.6,"id":26314798}]}]}
{"op":"mcm","clk":"993104019","pt":1580536559160,"mc":[{"id":"1.168130661","rc":[{"batb":[[0,10.5,3.42]],"ltp":11.0,"tv":193.92,"id":420}]}]}
{"op":"mcm","clk":"993104215","pt":1580536563832,"mc":[{"id":"1.168130661","rc":[{"batl":[[0,2.7,8.35],[1,2.72,10.91]],"ltp":2.68,"tv":1716.6,"id":26314798}]}]}
{"op":"mcm","clk":"993104921","pt":1580536579351,"mc":[{"id":"1.168130661","rc":[{"batl":[[1,10,3.09],[2,11.5,40]],"ltp":9.2,"tv":255.85,"id":24420205}]}]}
{"op":"mcm","clk":"993105046","pt":1580536582651,"mc":[{"id":"1.168130661","rc":[{"batb":[[0,2.88,2],[1,2.86,2],[2,2.84,16.74]],"ltp":2.88,"tv":1635.89,"id":25238892}]}]}
{"op":"mcm","clk":"993110935","pt":1580536685297,"mc":[{"id":"1.168130661","rc":[{"batb":[[0,2.66,8.48]],"ltp":2.68,"tv":1716.6,"id":26314798}]}]}
{"op":"mcm","clk":"993111639","pt":1580536702605,"mc":[{"id":"1.168130661","rc":[{"batb":[[0,2.68,2],[1,2.66,8.48],[2,2.64,6]],"ltp":2.68,"tv":1716.6,"id":26314798}]}]}
{"op":"mcm","clk":"993116571","pt":1580536831025,"mc":[{"id":"1.168130661","rc":[{"batb":[[0,10.5,6.42]],"ltp":11.0,"tv":193.92,"id":420}]}]}
{"op":"mcm","clk":"993116684","pt":1580536833543,"mc":[{"id":"1.168130661","rc":[{"batb":[[0,10.5,4.52]],"ltp":11.0,"tv":193.92,"id":420}]}]}
{"op":"mcm","clk":"993116815","pt":1580536836636,"mc":[{"id":"1.168130661","rc":[{"batl":[[1,9.8,6.55],[2,10,2.53]],"ltp":9.2,"tv":255.85,"id":24420205}]}]}
{"op":"mcm","clk":"993118107","pt":1580536867709,"mc":[{"id":"1.168130661","rc":[{"batl":[[1,9.6,6],[2,10,3.09]],"ltp":9.2,"tv":255.85,"id":24420205}]}]}
{"op":"mcm","clk":"993118877","pt":1580536883690,"mc":[{"id":"1.168130661","rc":[{"batl":[[1,10,3.09],[2,11.5,40]],"ltp":9.2,"tv":255.85,"id":24420205}]}]}
{"op":"mcm","clk":"993118881","pt":1580536883794,"mc":[{"id":"1.168130661","rc":[{"batl":[[0,9.2,18.95]],"ltp":9.2,"tv":255.85,"id":24420205}]}]}
{"op":"mcm","clk":"993120113","pt":1580536907712,"mc":[{"id":"1.168130661","rc":[{"batl":[[0,9.2,12.95]],"ltp":9.2,"tv":255.85,"id":24420205}]}]}
{"op":"mcm","clk":"993120115","pt":1580536907813,"mc":[{"id":"1.168130661","rc":[{"batl":[[1,9.8,6.55],[2,10,2.53]],"ltp":9.2,"tv":255.85,"id":24420205}]}]}
{"op":"mcm","clk":"993120769","pt":1580536922709,"mc":[{"id":"1.168130661","rc":[{"batl":[[1,9.6,6],[2,10,3.09]],"ltp":9.2,"tv":255.85,"id":24420205}]}]}
{"op":"mcm","clk":"993121241","pt":1580536931348,"mc":[{"id":"1.168130661","rc":[{"batl":[[0,9.2,18.95],[1,10,3.09],[2,11.5,40]],"ltp":9.2,"tv":255.85,"id":24420205}]}]}
{"op":"mcm","clk":"993121563","pt":1580536938364,"mc":[{"id":"1.168130661","rc":[{"batl":[[0,9.2,12.95],[1,9.8,6.55],[2,10,2.53]],"ltp":9.2,"tv":255.85,"id":24420205}]}]}
{"op":"mcm","clk":"993121918","pt":1580536947644,"mc":[{"id":"1.168130661","rc":[{"batl":[[1,9.6,6],[2,10,3.09]],"ltp":9.2,"tv":255.85,"id":24420205}]}]}
{"op":"mcm","clk":"993122557","pt":1580536962091,"mc":[{"id":"1.168130661","rc":[{"trd":[[2.86,166.29],[2.88,67.59]],"batb":[[0,2.84,16.74],[1,2.8,16.46],[2,2.78,4]],"ltp":2.86,"tv":1643.89,"id":25238892}],"tv":4030.84}]}
{"op":"mcm","clk":"993123073","pt":1580536976571,"mc":[{"id":"1.168130661","rc":[{"trd":[[2.84,95.87]],"batb":[[0,2.84,14.53]],"batl":[[0,2.86,2.07],[1,2.88,3.86],[2,2.9,9.02]],"ltp":2.84,"tv":1648.31,"id":25238892}],"tv":4035.26}]}
{"op":"mcm","clk":"993123085","pt":1580536976875,"mc":[{"id":"1.168130661","rc":[{"batl":[[0,2.9,3.36],[1,2.92,3.36],[2,2.94,8.4]],"ltp":2.84,"tv":1648.31,"id":25238892}]}]}
{"op":"mcm","clk":"993123134","pt":1580536978315,"mc":[{"id":"1.168130661","rc":[{"batl":[[0,9.2,18.95],[1,10,3.09],[2,11.5,40]],"ltp":9.2,"tv":255.85,"id":24420205}]}]}
{"op":"mcm","clk":"993123684","pt":1580536994380,"mc":[{"id":"1.168130661","rc":[{"batl":[[0,9.2,12.95],[1,9.8,6.55],[2,10,2.53]],"ltp":9.2,"tv":255.85,"id":24420205}]}]}
{"op":"mcm","clk":"993123740","pt":1580536996583,"mc":[{"id":"1.168130661","rc":[{"trd":[[10.5,41.6]],"batb":[[0,10,6.33],[1,9.8,38],[2,8,10]],"batl":[[0,10.5,5.48],[1,11,2.28],[2,18.5,2.31]],"ltp":10.5,"tv":202.96,"id":420}],"tv":4044.3}]}
{"op":"mcm","clk":"993123773","pt":1580536997604,"mc":[{"id":"1.168130661","rc":[{"trd":[[10.5,52.55]],"batb":[[0,10,6.89]],"batl":[[0,11,2.28],[1,18.5,2.31],[2,32,9.17]],"ltp":10.5,"tv":213.92,"id":420}],"tv":4055.26}]}
{"op":"mcm","clk":"993124728","pt":1580537018548,"mc":[{"id":"1.168130661","rc":[{"batb":[[0,10,11.89]],"ltp":10.5,"tv":213.92,"id":420}]}]}
{"op":"mcm","clk":"993124984","pt":1580537026324,"mc":[{"id":"1.168130661","rc":[{"batl":[[1,9.6,6],[2,10,3.09]],"ltp":9.2,"tv":255.85,"id":24420205}]}]}
{"op":"mcm","clk":"993125264","pt":1580537033652,"mc":[{"id":"1.168130661","rc":[{"batl":[[0,9.2,18.95],[1,10,3.09],[2,11.5,40]],"ltp":9.2,"tv":255.85,"id":24420205}]}]}
{"op":"mcm","clk":"993126542","pt":1580537070488,"mc":[{"id":"1.168130661","rc":[{"trd":[[2.84,115.87]],"batb":[[0,2.84,4.53]],"ltp":2.84,"tv":1668.3,"id":25238892}],"tv":4075.25}]}
{"op":"mcm","clk":"993126912","pt":1580537080418,"mc":[{"id":"1.168130661","rc":[{"batl":[[0,9.2,12.95],[1,9.8,6.55],[2,10,2.53]],"ltp":9.2,"tv":255.85,"id":24420205}]}]}
{"op":"mcm","clk":"993128342","pt":1580537113879,"mc":[{"id":"1.168130661","rc":[{"batl":[[1,9.6,6],[2,10,3.09]],"ltp":9.2,"tv":255.85,"id":24420205}]}]}
{"op":"mcm","clk":"993129078","pt":1580537129653,"mc":[{"id":"1.168130661","rc":[{"batl":[[1,10,3.09],[2,11.5,40]],"ltp":9.2,"tv":255.85,"id":24420205}]}]}
{"op":"mcm","clk":"993129084","pt":1580537129753,"mc":[{"id":"1.168130661","rc":[{"batl":[[0,9.2,18.95]],"ltp":9.2,"tv":255.85,"id":24420205}]}]}
{"op":"mcm","clk":"993129514","pt":1580537137593,"mc":[{"id":"1.168130661","rc":[{"batl":[[0,9.2,12.95],[1,9.8,6.55],[2,10,2.53]],"ltp":9.2,"tv":255.85,"id":24420205}]}]}
{"op":"mcm","clk":"993130568","pt":1580537161414,"mc":[{"id":"1.168130661","rc":[{"batl":[[1,9.6,6],[2,10,3.09]],"ltp":9.2,"tv":255.85,"id":24420205}]}]}
{"op":"mcm","clk":"993131324","pt":1580537177191,"mc":[{"id":"1.168130661","rc":[{"batl":[[0,9.2,18.95],[1,10,3.09],[2,11.5,40]],"ltp":9.2,"tv":255.85,"id":24420205}]}]}
{"op":"mcm","clk":"993132054","pt":1580537192626,"mc":[{"id":"1.168130661","rc":[{"batl":[[0,9.2,12.95]],"ltp":9.2,"tv":255.85,"id":24420205}]}]}
{"op":"mcm","clk":"993132098","pt":1580537193709,"mc":[{"id":"1.168130661","rc":[{"batl":[[1,9.8,6.55],[2,10,2.53]],"ltp":9.2,"tv":255.85,"id":24420205}]}]}
{"op":"mcm","clk":"993132705","pt":1580537208847,"mc":[{"id":"1.168130661","rc":[{"batl":[[1,9.6,6],[2,10,3.09]],"ltp":9.2,"tv":255.85,"id":24420205}]}]}
{"op":"mcm","clk":"993133365","pt":1580537225038,"mc":[{"id":"1.168130661","rc":[{"batl":[[0,9.2,18.95],[1,10,3.09],[2,11.5,40]],"ltp":9.2,"tv":255.85,"id":24420205}]}]}
{"op":"mcm","clk":"993133678","pt":1580537232683,"mc":[{"id":"1.168130661","rc":[{"batl":[[0,9.2,12.95]],"ltp":9.2,"tv":255.85,"id":24420205}]}]}
{"op":"mcm","clk":"993133682","pt":1580537232788,"mc":[{"id":"1.168130661","rc":[{"batl":[[1,9.8,6.55],[2,10,2.53]],"ltp":9.2,"tv":255.85,"id":24420205}]}]}
{"op":"mcm","clk":"993134019","pt":1580537241189,"mc":[{"id":"1.168130661","rc":[{"batl":[[1,9.6,6],[2,10,3.09]],"ltp":9.2,"tv":255.85,"id":24420205}]}]}
{"op":"mcm","clk":"993134292","pt":1580537248654,"mc":[{"id":"1.168130661","rc":[{"batl":[[1,10,3.09],[2,11.5,40]],"ltp":9.2,"tv":255.85,"id":24420205}]}]}
{"op":"mcm","clk":"993134300","pt":1580537248861,"mc":[{"id":"1.168130661","rc":[{"batl":[[0,9.2,18.95]],"ltp":9.2,"tv":255.85,"id":24420205}]}]}
{"op":"mcm","clk":"993145258","pt":1580537280406,"mc":[{"id":"1.168130661","rc":[{"batl":[[0,9.2,12.95],[1,9.8,6.55],[2,10,2.53]],"ltp":9.2,"tv":255.85,"id":24420205}]}]}
{"op":"mcm","clk":"993145582","pt":1580537288216,"mc":[{"id":"1.168130661","rc":[{"batl":[[1,9.6,6],[2,10,3.09]],"ltp":9.2,"tv":255.85,"id":24420205}]}]}
{"op":"mcm","clk":"993146258","pt":1580537305442,"mc":[{"id":"1.168130661","rc":[{"trd":[[8.8,18.55]],"batb":[[0,8.4,1.98],[1,8,42.17],[2,7.4,3.23]],"ltp":8.8,"tv":266.32,"id":24420205}],"tv":4085.73}]}
{"op":"mcm","clk":"993146579","pt":1580537314249,"mc":[{"id":"1.168130661","rc":[{"batb":[[1,8,40.61],[2,7.4,4.79]],"ltp":8.8,"tv":266.32,"id":24420205}]}]}
{"op":"mcm","clk":"993146661","pt":1580537316257,"mc":[{"id":"1.168130661","rc":[{"batb":[[0,8.4,3.88]],"ltp":8.8,"tv":266.32,"id":24420205}]}]}
{"op":"mcm","clk":"993147448","pt":1580537335606,"mc":[{"id":"1.168130661","rc":[{"batb":[[2,7.4,1.56]],"batl":[[0,9.2,18.95],[1,10,3.09],[2,11.5,40]],"ltp":8.8,"tv":266.32,"id":24420205}]}]}
{"op":"mcm","clk":"993147784","pt":1580537344364,"mc":[{"id":"1.168130661","rc":[{"batl":[[0,9.2,12.95],[1,9.8,6.55],[2,10,2.53]],"ltp":8.8,"tv":266.32,"id":24420205}]}]}
{"op":"mcm","clk":"993148428","pt":1580537360393,"mc":[{"id":"1.168130661","rc":[{"batl":[[1,9.6,6],[2,10,3.09]],"ltp":8.8,"tv":266.32,"id":24420205}]}]}
{"op":"mcm","clk":"993149397","pt":1580537383712,"mc":[{"id":"1.168130661","rc":[{"batl":[[0,9.2,18.95],[1,10,3.09],[2,11.5,40]],"ltp":8.8,"tv":266.32,"id":24420205}]}]}
{"op":"mcm","clk":"993150415","pt":1580537409479,"mc":[{"id":"1.168130661","rc":[{"batl":[[0,9.2,12.95],[1,9.8,6.55],[2,10,2.53]],"ltp":8.8,"tv":266.32,"id":24420205}]}]}
{"op":"mcm","clk":"993150975","pt":1580537423585,"mc":[{"id":"1.168130661","rc":[{"batl":[[1,9.6,6],[2,10,3.09]],"ltp":8.8,"tv":266.32,"id":24420205}]}]}
{"op":"mcm","clk":"993151418","pt":1580537433966,"mc":[{"id":"1.168130661","rc":[{"batl":[[0,9.2,18.95],[1,10,3.09],[2,11.5,40]],"ltp":8.8,"tv":266.32,"id":24420205}]}]}
{"op":"mcm","clk":"993152289","pt":1580537455414,"mc":[{"id":"1.168130661","rc":[{"batl":[[0,9.2,12.95],[1,9.8,6.55],[2,10,2.53]],"ltp":8.8,"tv":266.32,"id":24420205}]}]}
{"op":"mcm","clk":"993152982","pt":1580537471518,"mc":[{"id":"1.168130661","rc":[{"batl":[[1,9.6,6],[2,10,3.09]],"ltp":8.8,"tv":266.32,"id":24420205}]}]}
{"op":"mcm","clk":"993153691","pt":1580537486688,"mc":[{"id":"1.168130661","rc":[{"batl":[[0,9.2,18.95],[1,10,3.09],[2,11.5,40]],"ltp":8.8,"tv":266.32,"id":24420205}]}]}
{"op":"mcm","clk":"993154256","pt":1580537500485,"mc":[{"id":"1.168130661","rc":[{"batl":[[0,9.2,12.95],[1,9.8,6.55],[2,10,2.53]],"ltp":8.8,"tv":266.32,"id":24420205}]}]}
{"op":"mcm","clk":"993154377","pt":1580537503288,"mc":[{"id":"1.168130661","rc":[{"batb":[[0,2.68,5.36]],"ltp":2.68,"tv":1716.6,"id":26314798},{"batb":[[0,10.5,3.92],[1,10,11.33],[2,9.8,38]],"ltp":10.5,"tv":213.92,"id":420}]}]}
{"op":"mcm","clk":"993154596","pt":1580537507672,"mc":[{"id":"1.168130661","rc":[{"batl":[[1,9.6,6],[2,10,3.09]],"ltp":8.8,"tv":266.32,"id":24420205}]}]}
{"op":"mcm","clk":"993154688","pt":1580537509686,"mc":[{"id":"1.168130661","rc":[{"batb":[[0,10.5,3.36]],"ltp":10.5,"tv":213.92,"id":420}]}]}
{"op":"mcm","clk":"993154935","pt":1580537515577,"mc":[{"id":"1.168130661","rc":[{"batl":[[0,9.2,18.95],[1,10,3.09],[2,11.5,40]],"ltp":8.8,"tv":266.32,"id":24420205}]}]}
{"op":"mcm","clk":"993155184","pt":1580537521821,"mc":[{"id":"1.168130661","rc":[{"batl":[[0,9.2,12.95],[1,9.8,6.55],[2,10,2.53]],"ltp":8.8,"tv":266.32,"id":24420205}]}]}
{"op":"mcm","clk":"993155569","pt":1580537531228,"mc":[{"id":"1.168130661","rc":[{"batl":[[1,9.6,6],[2,10,3.09]],"ltp":8.8,"tv":266.32,"id":24420205}]}]}
{"op":"mcm","clk":"993155865","pt":1580537538233,"mc":[{"id":"1.168130661","rc":[{"batl":[[0,9.2,18.95],[1,10,3.09],[2,11.5,40]],"ltp":8.8,"tv":266.32,"id":24420205}]}]}
{"op":"mcm","clk":"993157518","pt":1580537575577,"mc":[{"id":"1.168130661","rc":[{"batl":[[0,9.2,12.95],[1,9.8,6.55],[2,10,2.53]],"ltp":8.8,"tv":266.32,"id":24420205}]}]}
{"op":"mcm","clk":"993157876","pt":1580537583085,"mc":[{"id":"1.168130661","rc":[{"batl":[[1,9.6,6],[2,10,3.09]],"ltp":8.8,"tv":266.32,"id":24420205}]}]}
{"op":"mcm","clk":"993158219","pt":1580537590324,"mc":[{"id":"1.168130661","rc":[{"batl":[[0,9.2,18.95],[1,10,3.09],[2,11.5,40]],"ltp":8.8,"tv":266.32,"id":24420205}]}]}
{"op":"mcm","clk":"993158587","pt":1580537598310,"mc":[{"id":"1.168130661","rc":[{"batl":[[0,9.2,12.95],[1,9.8,6.55],[2,10,2.53]],"ltp":8.8,"tv":266.32,"id":24420205}]}]}
{"op":"mcm","clk":"993158796","pt":1580537602300,"mc":[{"id":"1.168130661","rc":[{"batb":[[0,2.86,4],[1,2.84,4.53],[2,2.8,16.46]],"batl":[[0,2.88,10.64],[1,2.9,3.36],[2,2.92,3.36]],"ltp":2.84,"tv":1668.3,"id":25238892}]}]}
{"op":"mcm","clk":"993158922","pt":1580537604324,"mc":[{"id":"1.168130661","rc":[{"batl":[[1,9.6,6],[2,10,3.09]],"ltp":8.8,"tv":266.32,"id":24420205}]}]}
{"op":"mcm","clk":"993159305","pt":1580537612534,"mc":[{"id":"1.168130661","rc":[{"batb":[[0,34,1.19],[1,30,2.29]],"ltp":30.0,"tv":37.41,"id":25545675},{"trd":[[2.88,83.25]],"batl":[[0,2.88,2.81]],"ltp":2.88,"tv":1683.96,"id":25238892},{"trd":[[15.5,39.86]],"batl":[[0,15.5,6.3]],"ltp":15.5,"tv":186.06,"id":24707172},{"trd":[[9.2,20.85]],"batl":[[0,9.2,10.5]],"ltp":9.2,"tv":271.22,"id":24420205},{"trd":[[2.7,417.74]],"batb":[[0,2.7,6.38],[1,2.68,5.36],[2,2.66,2]],"batl":[[0,2.72,10.91],[1,2.74,84.92],[2,2.76,199]],"ltp":2.7,"tv":1733.3,"id":26314798},{"trd":[[11,8]],"batb":[[0,11,1.56],[1,10.5,3.36],[2,10,9.61]],"batl":[[0,18.5,2.31],[1,32,9.17],[2,170,0.33]],"ltp":11.0,"tv":218.48,"id":420}],"tv":4130.47}]}
{"op":"mcm","clk":"993159513","pt":1580537616652,"mc":[{"id":"1.168130661","rc":[{"batl":[[2,1000,0.51]],"ltp":11.0,"tv":218.48,"id":420}]}]}
{"op":"mcm","clk":"993159534","pt":1580537617271,"mc":[{"id":"1.168130661","rc":[{"batb":[[1,8,42.17],[2,7.2,13.03]],"ltp":9.2,"tv":271.22,"id":24420205},{"batl":[[0,18.5,2.49],[2,170,0.33]],"ltp":11.0,"tv":218.48,"id":420}]}]}
{"op":"mcm","clk":"993159713","pt":1580537621451,"mc":[{"id":"1.168130661","rc":[{"batl":[[0,9.2,16.5],[1,10,3.09],[2,11.5,40]],"ltp":9.2,"tv":271.22,"id":24420205}]}]}
{"op":"mcm","clk":"993159771","pt":1580537622842,"mc":[{"id":"1.168130661","rc":[{"batl":[[0,18,1.07],[1,18.5,2.31],[2,32,9.17]],"ltp":11.0,"tv":218.48,"id":420}]}]}
{"op":"mcm","clk":"993159873","pt":1580537625569,"mc":[{"id":"1.168130661","rc":[{"trd":[[2.7,430.49]],"batb":[[0,2.68,5.36],[1,2.66,2],[2,2.64,6]],"ltp":2.7,"tv":1746.06,"id":26314798}],"tv":4143.22}]}
{"op":"mcm","clk":"993159996","pt":1580537628671,"mc":[{"id":"1.168130661","rc":[{"batl":[[0,9.2,10.5]],"ltp":9.2,"tv":271.22,"id":24420205}]}]}
{"op":"mcm","clk":"993160036","pt":1580537629392,"mc":[{"id":"1.168130661","rc":[{"batl":[[1,9.8,6.55],[2,10,2.53]],"ltp":9.2,"tv":271.22,"id":24420205}]}]}
{"op":"mcm","clk":"993160150","pt":1580537632280,"mc":[{"id":"1.168130661","rc":[{"batb":[[0,2.68,2]],"ltp":2.7,"tv":1746.06,"id":26314798}]}]}
{"op":"mcm","clk":"993160412","pt":1580537638666,"mc":[{"id":"1.168130661","rc":[{"batl":[[0,18,2.75]],"ltp":11.0,"tv":218.48,"id":420}]}]}
{"op":"mcm","clk":"993160737","pt":1580537647382,"mc":[{"id":"1.168130661","rc":[{"batl":[[0,17.5,2.3],[1,18,2.57],[2,18.5,2.31]],"ltp":11.0,"tv":218.48,"id":420}]}]}
{"op":"mcm","clk":"993160952","pt":1580537651494,"mc":[{"id":"1.168130661","rc":[{"batl":[[1,9.6,6],[2,10,3.09]],"ltp":9.2,"tv":271.22,"id":24420205}]}]}
{"op":"mcm","clk":"993161252","pt":1580537658502,"mc":[{"id":"1.168130661","rc":[{"batl":[[0,9.2,16.5],[1,10,3.09],[2,11.5,40]],"ltp":9.2,"tv":271.22,"id":24420205}]}]}
{"op":"mcm","clk":"993161555","pt":1580537666480,"mc":[{"id":"1.168130661","rc":[{"batl":[[0,17,2.18],[1,17.5,2.12],[2,18,2.57]],"ltp":11.0,"tv":218.48,"id":420}]}]}
{"op":"mcm","clk":"993161673","pt":1580537669711,"mc":[{"id":"1.168130661","rc":[{"batl":[[0,16.5,1.86],[1,17,2],[2,17.5,2.12]],"ltp":11.0,"tv":218.48,"id":420}]}]}
{"op":"mcm","clk":"993161835","pt":1580537673720,"mc":[{"id":"1.168130661","rc":[{"batl":[[0,9.2,10.5],[1,9.8,6.55],[2,10,2.53]],"ltp":9.2,"tv":271.22,"id":24420205}]}]}
{"op":"mcm","clk":"993161846","pt":1580537673925,"mc":[{"id":"1.168130661","rc":[{"batl":[[0,2.7,2],[1,2.72,10.91],[2,2.74,84.92]],"ltp":2.7,"tv":1746.06,"id":26314798}]}]}
{"op":"mcm","clk":"993162240","pt":1580537685132,"mc":[{"id":"1.168130661","rc":[{"batl":[[2,18,1.17]],"ltp":11.0,"tv":218.48,"id":420}]}]}
{"op":"mcm","clk":"993162294","pt":1580537686622,"mc":[{"id":"1.168130661","rc":[{"trd":[[2.66,70.3],[2.68,107.77]],"batb":[[0,2.64,6],[1,2.62,4.71],[2,2.6,75]],"batl":[[0,2.66,8.67],[1,2.7,2]],"ltp":2.66,"tv":1754.05,"id":26314798}],"tv":4151.21}]}
{"op":"mcm","clk":"993162406","pt":1580537689912,"mc":[{"id":"1.168130661","rc":[{"batl":[[1,9.6,6],[2,10,3.09]],"ltp":9.2,"tv":271.22,"id":24420205}]}]}
{"op":"mcm","clk":"993163541","pt":1580537720667,"mc":[{"id":"1.168130661","rc":[{"batl":[[1,18,1.17],[2,18.5,2.31]],"ltp":11.0,"tv":218.48,"id":420}]}]}
{"op":"mcm","clk":"993163573","pt":1580537721381,"mc":[{"id":"1.168130661","rc":[{"batl":[[0,16,2.18],[1,16.5,1.68],[2,18,1.17]],"ltp":11.0,"tv":218.48,"id":420}]}]}
{"op":"mcm","clk":"993163813","pt":1580537727646,"mc":[{"id":"1.168130661","rc":[{"batl":[[0,9.2,16.5],[1,10,3.09],[2,11.5,40]],"ltp":9.2,"tv":271.22,"id":24420205}]}]}
{"op":"mcm","clk":"993163980","pt":1580537731994,"mc":[{"id":"1.168130661","rc":[{"batl":[[0,15.5,1.86],[1,16,2]],"ltp":11.0,"tv":218.48,"id":420}]}]}
{"op":"mcm","clk":"993164139","pt":1580537735652,"mc":[{"id":"1.168130661","rc":[{"batb":[[0,2.64,9.36]],"ltp":2.66,"tv":1754.05,"id":26314798}]}]}
{"op":"mcm","clk":"993164413","pt":1580537741684,"mc":[{"id":"1.168130661","rc":[{"batl":[[0,9.2,10.5]],"ltp":9.2,"tv":271.22,"id":24420205}]}]}
{"op":"mcm","clk":"993164452","pt":1580537742454,"mc":[{"id":"1.168130661","rc":[{"batl":[[1,9.8,6.55],[2,10,2.53]],"ltp":9.2,"tv":271.22,"id":24420205}]}]}
{"op":"mcm","clk":"993164779","pt":1580537750092,"mc":[{"id":"1.168130661","rc":[{"batl":[[1,9.6,6],[2,10,3.09]],"ltp":9.2,"tv":271.22,"id":24420205}]}]}
{"op":"mcm","clk":"993165048","pt":1580537756589,"mc":[{"id":"1.168130661","rc":[{"batl":[[0,9.2,16.5],[1,10,3.09],[2,11.5,40]],"ltp":9.2,"tv":271.22,"id":24420205}]}]}
{"op":"mcm","clk":"993165443","pt":1580537764685,"mc":[{"id":"1.168130661","rc":[{"batl":[[0,9.2,10.5],[1,9.8,6.55],[2,10,2.53]],"ltp":9.2,"tv":271.22,"id":24420205}]}]}
{"op":"mcm","clk":"993165856","pt":1580537772020,"mc":[{"id":"1.168130661","rc":[{"trd":[[9.2,41.85]],"batl":[[0,9.8,6.55],[1,10,2.53],[2,11.5,40]],"ltp":9.2,"tv":292.22,"id":24420205}],"tv":4172.21}]}
{"op":"mcm","clk":"993166008","pt":1580537775016,"mc":[{"id":"1.168130661","rc":[{"batl":[[0,9.6,2],[1,9.8,6.55],[2,10,2.53]],"ltp":9.2,"tv":292.22,"id":24420205},{"batl":[[0,15,2],[1,15.5,1.86]],"ltp":11.0,"tv":218.48,"id":420}]}]}
{"op":"mcm","clk":"993166281","pt":1580537779521,"mc":[{"id":"1.168130661","rc":[{"batl":[[0,9.6,8],[1,10,3.09],[2,11.5,40]],"ltp":9.2,"tv":292.22,"id":24420205}]}]}
{"op":"mcm","clk":"993166950","pt":1580537794717,"mc":[{"id":"1.168130661","rc":[{"batl":[[0,9.6,2],[1,9.8,6.55],[2,10,2.53]],"ltp":9.2,"tv":292.22,"id":24420205},{"batl":[[1,18,1.35],[2,18.5,2.31]],"ltp":11.0,"tv":218.48,"id":420}]}]}
{"op":"mcm","clk":"993167012","pt":1580537795441,"mc":[{"id":"1.168130661","rc":[{"batl":[[0,9.6,2.58],[1,9.8,6]],"ltp":9.2,"tv":292.22,"id":24420205},{"batl":[[0,14.5,1.68],[1,15,2],[2,18,1.35]],"ltp":11.0,"tv":218.48,"id":420}]}]}
{"op":"mcm","clk":"993168673","pt":1580537825885,"mc":[{"id":"1.168130661","rc":[{"batl":[[0,9.6,8.58],[1,10,2.53],[2,11.5,40]],"ltp":9.2,"tv":292.22,"id":24420205}]}]}
{"op":"mcm","clk":"993168886","pt":1580537829379,"mc":[{"id":"1.168130661","rc":[{"batl":[[0,14,2],[1,14.5,1.68]],"ltp":11.0,"tv":218.48,"id":420}]}]}
{"op":"mcm","clk":"993169010","pt":1580537831744,"mc":[{"id":"1.168130661","rc":[{"batl":[[2,18,1.17]],"ltp":11.0,"tv":218.48,"id":420}]}]}
{"op":"mcm","clk":"993169455","pt":1580537841470,"mc":[{"id":"1.168130661","rc":[{"batl":[[0,9.6,2.58],[1,9.8,6],[2,10,2.53]],"ltp":9.2,"tv":292.22,"id":24420205}]}]}
{"op":"mcm","clk":"993169800","pt":1580537849562,"mc":[{"id":"1.168130661","rc":[{"batl":[[0,9.6,8.58],[1,10,2.53],[2,11.5,40]],"ltp":9.2,"tv":292.22,"id":24420205}]}]}
{"op":"mcm","clk":"993169918","pt":1580537852425,"mc":[{"id":"1.168130661","rc":[{"batl":[[2,18.5,2.59]],"ltp":11.0,"tv":218.48,"id":420}]}]}
{"op":"mcm","clk":"993170207","pt":1580537858590,"mc":[{"id":"1.168130661","rc":[{"batl":[[0,13.5,1.68],[1,14,2]],"ltp":11.0,"tv":218.48,"id":420}]}]}
{"op":"mcm","clk":"993170298","pt":1580537860703,"mc":[{"id":"1.168130661","rc":[{"batb":[[1,8.2,3.05],[2,8,41.56]],"ltp":9.2,"tv":292.22,"id":24420205}]}]}
{"op":"mcm","clk":"993170432","pt":1580537863699,"mc":[{"id":"1.168130661","rc":[{"batl":[[0,9.6,2.58]],"ltp":9.2,"tv":292.22,"id":24420205}]}]}
{"op":"mcm","clk":"993170435","pt":1580537863801,"mc":[{"id":"1.168130661","rc":[{"batl":[[1,9.8,6],[2,10,2.53]],"ltp":9.2,"tv":292.22,"id":24420205}]}]}
{"op":"mcm","clk":"993170850","pt":1580537872687,"mc":[{"id":"1.168130661","rc":[{"batl":[[1,10,2.53],[2,11.5,40]],"ltp":9.2,"tv":292.22,"id":24420205}]}]}
{"op":"mcm","clk":"993170856","pt":1580537872813,"mc":[{"id":"1.168130661","rc":[{"batl":[[0,9.6,8.58]],"ltp":9.2,"tv":292.22,"id":24420205}]}]}
{"op":"mcm","clk":"993171119","pt":1580537878585,"mc":[{"id":"1.168130661","rc":[{"batl":[[0,9.6,2.58],[1,9.8,6],[2,10,2.53]],"ltp":9.2,"tv":292.22,"id":24420205}]}]}
{"op":"mcm","clk":"993171300","pt":1580537882722,"mc":[{"id":"1.168130661","rc":[{"batl":[[1,18.5,2.59],[2,32,9]],"ltp":11.0,"tv":218.48,"id":420}]}]}
{"op":"mcm","clk":"993171342","pt":1580537883700,"mc":[{"id":"1.168130661","rc":[{"batl":[[0,13,2],[1,13.5,1.68],[2,18.5,2.59]],"ltp":11.0,"tv":218.48,"id":420}]}]}
{"op":"mcm","clk":"993171352","pt":1580537883902,"mc":[{"id":"1.168130661","rc":[{"batb":[[1,8,42.17],[2,7.2,2.03]],"ltp":9.2,"tv":292.22,"id":24420205}]}]}
{"op":"mcm","clk":"993171570","pt":1580537888410,"mc":[{"id":"1.168130661","rc":[{"batb":[[0,2.64,47.34]],"ltp":2.66,"tv":1754.05,"id":26314798}]}]}
{"op":"mcm","clk":"993171635","pt":1580537889632,"mc":[{"id":"1.168130661","rc":[{"batl":[[0,12.5,1.68],[1,13,2]],"ltp":11.0,"tv":218.48,"id":420}]}]}
{"op":"mcm","clk":"993171912","pt":1580537895717,"mc":[{"id":"1.168130661","rc":[{"batl":[[0,9.6,8.58],[1,10,2.53],[2,11.5,40]],"ltp":9.2,"tv":292.22,"id":24420205}]}]}
{"op":"mcm","clk":"993172333","pt":1580537906661,"mc":[{"id":"1.168130661","rc":[{"batb":[[0,2.88,7.87],[1,2.86,33.33],[2,2.84,4.53]],"batl":[[0,2.9,3.36],[1,2.92,3.36],[2,2.94,8.4]],"ltp":2.88,"tv":1683.96,"id":25238892},{"batb":[[0,2.64,9.36]],"ltp":2.66,"tv":1754.05,"id":26314798}]}]}
{"op":"mcm","clk":"993172653","pt":1580537914260,"mc":[{"id":"1.168130661","rc":[{"batb":[[0,2.88,21.31]],"ltp":2.88,"tv":1683.96,"id":25238892}]}]}
{"op":"mcm","clk":"993172837","pt":1580537918643,"mc":[{"id":"1.168130661","rc":[{"batl":[[0,9.6,2.58]],"ltp":9.2,"tv":292.22,"id":24420205}]}]}
{"op":"mcm","clk":"993172878","pt":1580537919464,"mc":[{"id":"1.168130661","rc":[{"batl":[[1,9.8,6],[2,10,2.53]],"ltp":9.2,"tv":292.22,"id":24420205}]}]}
{"op":"mcm","clk":"993172950","pt":1580537920953,"mc":[{"id":"1.168130661","rc":[{"batl":[[0,13,2],[1,18,1.96],[2,18.5,2.31]],"ltp":11.0,"tv":218.48,"id":420}]}]}
{"op":"mcm","clk":"993173076","pt":1580537923369,"mc":[{"id":"1.168130661","rc":[{"batb":[[1,2.86,4]],"ltp":2.88,"tv":1683.96,"id":25238892}]}]}
{"op":"mcm","clk":"993173242","pt":1580537926462,"mc":[{"id":"1.168130661","rc":[{"batl":[[0,9.6,8.58],[1,10,2.53],[2,11.5,40]],"ltp":9.2,"tv":292.22,"id":24420205}]}]}
{"op":"mcm","clk":"993173411","pt":1580537930073,"mc":[{"id":"1.168130661","rc":[{"batb":[[0,2.88,7.87]],"ltp":2.88,"tv":1683.96,"id":25238892},{"batb":[[1,10.5,5.26]],"ltp":11.0,"tv":218.48,"id":420}]}]}
{"op":"mcm","clk":"993173761","pt":1580537936673,"mc":[{"id":"1.168130661","rc":[{"batl":[[0,17.5,4.12]],"ltp":11.0,"tv":218.48,"id":420}]}]}
{"op":"mcm","clk":"993173771","pt":1580537936881,"mc":[{"id":"1.168130661","rc":[{"batl":[[0,17.5,4.31]],"ltp":11.0,"tv":218.48,"id":420}]}]}
{"op":"mcm","clk":"993174499","pt":1580537952574,"mc":[{"id":"1.168130661","rc":[{"batl":[[0,17,1.87],[1,17.5,4.12],[2,18.5,2.59]],"ltp":11.0,"tv":218.48,"id":420}]}]}
{"op":"mcm","clk":"993174541","pt":1580537953397,"mc":[{"id":"1.168130661","rc":[{"batl":[[0,17,2.16],[2,18.5,2.31]],"ltp":11.0,"tv":218.48,"id":420}]}]}
{"op":"mcm","clk":"993175107","pt":1580537965516,"mc":[{"id":"1.168130661","rc":[{"batl":[[0,9.6,2.58],[1,9.8,6],[2,10,2.53]],"ltp":9.2,"tv":292.22,"id":24420205}]}]}
{"op":"mcm","clk":"993175447","pt":1580537973230,"mc":[{"id":"1.168130661","rc":[{"batl":[[0,9.6,8.58],[1,10,2.53],[2,11.5,40]],"ltp":9.2,"tv":292.22,"id":24420205}]}]}
{"op":"mcm","clk":"993176177","pt":1580537990657,"mc":[{"id":"1.168130661","rc":[{"batl":[[0,16.5,2.19],[1,17,1.97],[2,17.5,2.12]],"ltp":11.0,"tv":218.48,"id":420}]}]}
{"op":"mcm","clk":"993176353","pt":1580537994569,"mc":[{"id":"1.168130661","rc":[{"batl":[[2,18.5,2.31]],"ltp":11.0,"tv":218.48,"id":420}]}]}
{"op":"mcm","clk":"993177302","pt":1580538016186,"mc":[{"id":"1.168130661","rc":[{"batl":[[0,16,1.87],[1,16.5,2],[2,18.5,2.6]],"ltp":11.0,"tv":218.48,"id":420}]}]}
{"op":"mcm","clk":"993177448","pt":1580538019278,"mc":[{"id":"1.168130661","rc":[{"batl":[[0,9.6,2.58],[1,9.8,6],[2,10,2.53]],"ltp":9.2,"tv":292.22,"id":24420205}]}]}
{"op":"mcm","clk":"993177567","pt":1580538021754,"mc":[{"id":"1.168130661","rc":[{"batb":[[0,2.64,14.36]],"ltp":2.66,"tv":1754.05,"id":26314798}]}]}
{"op":"mcm","clk":"993178465","pt":1580538041273,"mc":[{"id":"1.168130661","rc":[{"batb":[[0,2.88,11.23]],"ltp":2.88,"tv":1683.96,"id":25238892}]}]}
{"op":"mcm","clk":"993178592","pt":1580538044311,"mc":[{"id":"1.168130661","rc":[{"batl":[[0,15.5,2.19],[1,16,1.68]],"ltp":11.0,"tv":218.48,"id":420}]}]}
{"op":"mcm","clk":"993178719","pt":1580538047712,"mc":[{"id":"1.168130661","rc":[{"batl":[[0,15,1.68],[1,15.5,2.19]],"ltp":11.0,"tv":218.48,"id":420}]}]}
{"op":"mcm","clk":"993179195","pt":1580538060592,"mc":[{"id":"1.168130661","rc":[{"batl":[[0,9.6,8.58],[1,10,2.53],[2,11.5,40]],"ltp":9.2,"tv":292.22,"id":24420205}]}]}
{"op":"mcm","clk":"993179474","pt":1580538067310,"mc":[{"id":"1.168130661","rc":[{"batl":[[0,9.6,2.58],[1,9.8,6],[2,10,2.53]],"ltp":9.2,"tv":292.22,"id":24420205}]}]}
{"op":"mcm","clk":"993179796","pt":1580538074941,"mc":[{"id":"1.168130661","rc":[{"batl":[[0,9.6,8.58],[1,10,2.53],[2,11.5,40]],"ltp":9.2,"tv":292.22,"id":24420205}]}]}
{"op":"mcm","clk":"993179819","pt":1580538075822,"mc":[{"id":"1.168130661","rc":[{"batl":[[1,2.74,84.92],[2,2.76,199]],"ltp":2.66,"tv":1754.05,"id":26314798}]}]}
{"op":"mcm","clk":"993180680","pt":1580538097249,"mc":[{"id":"1.168130661","rc":[{"batb":[[0,11,3.38]],"batl":[[0,14.5,2],[1,15,1.68],[2,18.5,2.79]],"ltp":11.0,"tv":218.48,"id":420}]}]}
{"op":"mcm","clk":"993181101","pt":1580538107281,"mc":[{"id":"1.168130661","rc":[{"batl":[[0,9.6,2.58],[1,9.8,6],[2,10,2.53]],"ltp":9.2,"tv":292.22,"id":24420205},{"batb":[[0,11,8.38],[2,10,4.61]],"ltp":11.0,"tv":218.48,"id":420}]}]}
{"op":"mcm","clk":"993181206","pt":1580538110066,"mc":[{"id":"1.168130661","rc":[{"batl":[[0,14,1.68],[1,14.5,2]],"ltp":11.0,"tv":218.48,"id":420}]}]}
{"op":"mcm","clk":"993181303","pt":1580538112502,"mc":[{"id":"1.168130661","rc":[{"batb":[[1,10.5,3.36]],"ltp":11.0,"tv":218.48,"id":420}]}]}
{"op":"mcm","clk":"993181360","pt":1580538113742,"mc":[{"id":"1.168130661","rc":[{"batl":[[2,18.5,2.6]],"ltp":11.0,"tv":218.48,"id":420}]}]}
{"op":"mcm","clk":"993181703","pt":1580538121652,"mc":[{"id":"1.168130661","rc":[{"batl":[[1,10,2.53],[2,11.5,40]],"ltp":9.2,"tv":292.22,"id":24420205}]}]}
{"op":"mcm","clk":"993181755","pt":1580538122684,"mc":[{"id":"1.168130661","rc":[{"batl":[[0,9.6,8.58]],"ltp":9.2,"tv":292.22,"id":24420205}]}]}
{"op":"mcm","clk":"993182712","pt":1580538146673,"mc":[{"id":"1.168130661","rc":[{"batl":[[0,9.6,2.58],[1,9.8,6],[2,10,2.53]],"ltp":9.2,"tv":292.22,"id":24420205}]}]}
{"op":"mcm","clk":"993182836","pt":1580538150280,"mc":[{"id":"1.168130661","rc":[{"batl":[[0,13.5,2],[1,14,1.68]],"ltp":11.0,"tv":218.48,"id":420}]}]}
{"op":"mcm","clk":"993192749","pt":1580538152623,"mc":[{"id":"1.168130661","rc":[{"trd":[[2.88,105.25]],"batb":[[0,2.86,4.23],[1,2.84,4.53],[2,2.8,16.46]],"ltp":2.88,"tv":1705.97,"id":25238892}],"tv":4194.22}]}
{"op":"mcm","clk":"993192799","pt":1580538154122,"mc":[{"id":"1.168130661","rc":[{"batl":[[0,9.6,8.58],[1,10,2.53],[2,11.5,40]],"ltp":9.2,"tv":292.22,"id":24420205}]}]}
{"op":"mcm","clk":"993193473","pt":1580538170113,"mc":[{"id":"1.168130661","rc":[{"batl":[[0,9.6,2.58],[1,9.8,6],[2,10,2.53]],"ltp":9.2,"tv":292.22,"id":24420205}]}]}
{"op":"mcm","clk":"993193591","pt":1580538172419,"mc":[{"id":"1.168130661","rc":[{"batl":[[0,13,1.68],[1,13.5,2]],"ltp":11.0,"tv":218.48,"id":420}]}]}
{"op":"mcm","clk":"993194247","pt":1580538186641,"mc":[{"id":"1.168130661","rc":[{"batl":[[0,9.6,8.58],[1,10,2.53],[2,11.5,40]],"ltp":9.2,"tv":292.22,"id":24420205}]}]}
{"op":"mcm","clk":"993194547","pt":1580538194444,"mc":[{"id":"1.168130661","rc":[{"batl":[[0,9.6,2.58],[1,9.8,6],[2,10,2.53]],"ltp":9.2,"tv":292.22,"id":24420205}]}]}
{"op":"mcm","clk":"993194905","pt":1580538203631,"mc":[{"id":"1.168130661","rc":[{"batl":[[0,9.6,8.58],[1,10,2.53],[2,11.5,40]],"ltp":9.2,"tv":292.22,"id":24420205},{"batb":[[0,11,6.56]],"batl":[[1,18.5,2.6],[2,32,9]],"ltp":11.0,"tv":218.48,"id":420}]}]}
{"op":"mcm","clk":"993194927","pt":1580538204145,"mc":[{"id":"1.168130661","rc":[{"batl":[[0,18,1.97],[1,18.5,2.31]],"ltp":11.0,"tv":218.48,"id":420}]}]}
{"op":"mcm","clk":"993195072","pt":1580538207644,"mc":[{"id":"1.168130661","rc":[{"batl":[[0,18,2.15]],"ltp":11.0,"tv":218.48,"id":420}]}]}
{"op":"mcm","clk":"993195564","pt":1580538219452,"mc":[{"id":"1.168130661","rc":[{"batl":[[0,9.6,2.58],[1,9.8,6],[2,10,2.53]],"ltp":9.2,"tv":292.22,"id":24420205}]}]}
{"op":"mcm","clk":"993195905","pt":1580538227486,"mc":[{"id":"1.168130661","rc":[{"batl":[[0,9.6,8.58],[1,10,2.53],[2,11.5,40]],"ltp":9.2,"tv":292.22,"id":24420205}]}]}
{"op":"mcm","clk":"993196217","pt":1580538234675,"mc":[{"id":"1.168130661","rc":[{"batl":[[0,9.6,2.58]],"ltp":9.2,"tv":292.22,"id":24420205}]}]}
{"op":"mcm","clk":"993196244","pt":1580538235188,"mc":[{"id":"1.168130661","rc":[{"batl":[[1,9.8,6],[2,10,2.53]],"ltp":9.2,"tv":292.22,"id":24420205}]}]}
{"op":"mcm","clk":"993196568","pt":1580538243708,"mc":[{"id":"1.168130661","rc":[{"batl":[[0,9.6,8.58],[1,10,2.53],[2,11.5,40]],"ltp":9.2,"tv":292.22,"id":24420205},{"trd":[[2.66,75.2]],"batl":[[0,2.66,6.22]],"ltp":2.66,"tv":1758.95,"id":26314798}],"tv":4199.12}]}
{"op":"mcm","clk":"993197427","pt":1580538267541,"mc":[{"id":"1.168130661","rc":[{"batl":[[0,9.6,2.58],[1,9.8,6],[2,10,2.53]],"ltp":9.2,"tv":292.22,"id":24420205}]}]}
{"op":"mcm","clk":"993197432","pt":1580538267744,"mc":[{"id":"1.168130661","rc":[{"batl":[[0,17.5,8.07],[1,18,1.68],[2,18.5,2.31]],"ltp":11.0,"tv":218.48,"id":420}]}]}
{"op":"mcm","clk":"993197708","pt":1580538274532,"mc":[{"id":"1.168130661","rc":[{"batl":[[0,9.6,8.58],[1,10,2.53],[2,11.5,40]],"ltp":9.2,"tv":292.22,"id":24420205}]}]}
{"op":"mcm","clk":"993198703","pt":1580538298557,"mc":[{"id":"1.168130661","rc":[{"batl":[[0,17,2.15],[1,17.5,7.6]],"ltp":11.0,"tv":218.48,"id":420}]}]}
{"op":"mcm","clk":"993198769","pt":1580538300155,"mc":[{"id":"1.168130661","rc":[{"batl":[[0,9.6,2.58],[1,9.8,6],[2,10,2.53]],"ltp":9.2,"tv":292.22,"id":24420205}]}]}
{"op":"mcm","clk":"993199202","pt":1580538310550,"mc":[{"id":"1.168130661","rc":[{"batb":[[0,11.5,1.74],[1,11,6.56],[2,10.5,3.36]],"ltp":11.0,"tv":218.48,"id":420}]}]}
{"op":"mcm","clk":"993199230","pt":1580538311164,"mc":[{"id":"1.168130661","rc":[{"batl":[[0,16.5,2.18],[1,17,1.97],[2,17.5,7.6]],"ltp":11.0,"tv":218.48,"id":420}]}]}
{"op":"mcm","clk":"993199814","pt":1580538324680,"mc":[{"id":"1.168130661","rc":[{"batl":[[1,10,2.53],[2,11.5,40]],"ltp":9.2,"tv":292.22,"id":24420205},{"batl":[[0,16.5,4.43]],"ltp":11.0,"tv":218.48,"id":420}]}]}
{"op":"mcm","clk":"993199841","pt":1580538325185,"mc":[{"id":"1.168130661","rc":[{"batl":[[0,9.6,8.58]],"ltp":9.2,"tv":292.22,"id":24420205}]}]}
{"op":"mcm","clk":"993200075","pt":1580538329986,"mc":[{"id":"1.168130661","rc":[{"batl":[[0,16,1.86],[1,16.5,4.25],[2,17.5,7.89]],"ltp":11.0,"tv":218.48,"id":420}]}]}
{"op":"mcm","clk":"993200938","pt":1580538348511,"mc":[{"id":"1.168130661","rc":[{"batl":[[0,9.6,2.58],[1,9.8,6],[2,10,2.53]],"ltp":9.2,"tv":292.22,"id":24420205}]}]}
{"op":"mcm","clk":"993201379","pt":1580538357315,"mc":[{"id":"1.168130661","rc":[{"batl":[[0,9.6,8.58],[1,10,2.53],[2,11.5,40]],"ltp":9.2,"tv":292.22,"id":24420205}]}]}
{"op":"mcm","clk":"993201684","pt":1580538364415,"mc":[{"id":"1.168130661","rc":[{"batl":[[0,15.5,2],[1,16,1.86],[2,16.5,2.25]],"ltp":11.0,"tv":218.48,"id":420}]}]}
{"op":"mcm","clk":"993202339","pt":1580538380721,"mc":[{"id":"1.168130661","rc":[{"batl":[[0,9.6,2.58]],"ltp":9.2,"tv":292.22,"id":24420205}]}]}
{"op":"mcm","clk":"993202351","pt":1580538381032,"mc":[{"id":"1.168130661","rc":[{"batl":[[1,9.8,6],[2,10,2.53]],"ltp":9.2,"tv":292.22,"id":24420205}]}]}
{"op":"mcm","clk":"993202448","pt":1580538383556,"mc":[{"id":"1.168130661","rc":[{"batl":[[2,17.5,7.89]],"ltp":11.0,"tv":218.48,"id":420}]}]}
{"op":"mcm","clk":"993202665","pt":1580538388623,"mc":[{"id":"1.168130661","rc":[{"batl":[[0,9.6,8.58],[1,10,2.53],[2,11.5,40]],"ltp":9.2,"tv":292.22,"id":24420205}]}]}
{"op":"mcm","clk":"993202825","pt":1580538393325,"mc":[{"id":"1.168130661","rc":[{"batl":[[0,15,1.68],[1,15.5,2],[2,17.5,8.07]],"ltp":11.0,"tv":218.48,"id":420}]}]}
{"op":"mcm","clk":"993202977","pt":1580538397255,"mc":[{"id":"1.168130661","rc":[{"batl":[[0,9.6,2.58],[1,9.8,6],[2,10,2.53]],"ltp":9.2,"tv":292.22,"id":24420205}]}]}
{"op":"mcm","clk":"993203806","pt":1580538417267,"mc":[{"id":"1.168130661","rc":[{"batl":[[0,14.5,2],[1,15,1.68]],"ltp":11.0,"tv":218.48,"id":420}]}]}
{"op":"mcm","clk":"993204046","pt":1580538422463,"mc":[{"id":"1.168130661","rc":[{"batl":[[2,17.5,7.89]],"ltp":11.0,"tv":218.48,"id":420}]}]}
{"op":"mcm","clk":"993204156","pt":1580538425446,"mc":[{"id":"1.168130661","rc":[{"batl":[[0,14,1.68],[1,14.5,2]],"ltp":11.0,"tv":218.48,"id":420}]}]}
{"op":"mcm","clk":"993204334","pt":1580538429258,"mc":[{"id":"1.168130661","rc":[{"batl":[[0,9.6,8.58],[1,10,2.53],[2,11.5,40]],"ltp":9.2,"tv":292.22,"id":24420205}]}]}
{"op":"mcm","clk":"993204692","pt":1580538438071,"mc":[{"id":"1.168130661","rc":[{"batl":[[0,9.6,2.58],[1,9.8,6],[2,10,2.53]],"ltp":9.2,"tv":292.22,"id":24420205}]}]}
{"op":"mcm","clk":"993205473","pt":1580538456717,"mc":[{"id":"1.168130661","rc":[{"batl":[[0,14.5,2],[1,17.5,7.89],[2,18.5,2.31]],"ltp":11.0,"tv":218.48,"id":420}]}]}
{"op":"mcm","clk":"993205477","pt":1580538456821,"mc":[{"id":"1.168130661","rc":[{"batl":[[1,17,1.97],[2,17.5,7.6]],"ltp":11.0,"tv":218.48,"id":420}]}]}
{"op":"mcm","clk":"993205678","pt":1580538461708,"mc":[{"id":"1.168130661","rc":[{"batl":[[1,16.5,2.25],[2,17,1.97]],"ltp":11.0,"tv":218.48,"id":420}]}]}
{"op":"mcm","clk":"993206019","pt":1580538469320,"mc":[{"id":"1.168130661","rc":[{"batl":[[0,9.6,8.58],[1,10,2.53],[2,11.5,40]],"ltp":9.2,"tv":292.22,"id":24420205}]}]}
{"op":"mcm","clk":"993206098","pt":1580538471523,"mc":[{"id":"1.168130661","rc":[{"batl":[[0,16,2]],"ltp":11.0,"tv":218.48,"id":420}]}]}
{"op":"mcm","clk":"993206667","pt":1580538488251,"mc":[{"id":"1.168130661","rc":[{"batl":[[0,15.5,1.68],[1,16,2],[2,16.5,2.25]],"ltp":11.0,"tv":218.48,"id":420}]}]}
{"op":"mcm","clk":"993207140","pt":1580538501252,"mc":[{"id":"1.168130661","rc":[{"batl":[[2,18.5,2.6]],"ltp":11.0,"tv":218.48,"id":420}]}]}
{"op":"mcm","clk":"993207423","pt":1580538509554,"mc":[{"id":"1.168130661","rc":[{"batl":[[0,9.6,2.58],[1,9.8,6],[2,10,2.53]],"ltp":9.2,"tv":292.22,"id":24420205}]}]}
{"op":"mcm","clk":"993207698","pt":1580538517857,"mc":[{"id":"1.168130661","rc":[{"batl":[[0,9.6,8.58],[1,10,2.53],[2,11.5,40]],"ltp":9.2,"tv":292.22,"id":24420205}]}]}
{"op":"mcm","clk":"993207979","pt":1580538525166,"mc":[{"id":"1.168130661","rc":[{"batl":[[0,15,2],[1,15.5,1.68]],"ltp":11.0,"tv":218.48,"id":420}]}]}
{"op":"mcm","clk":"993208170","pt":1580538529656,"mc":[{"id":"1.168130661","rc":[{"trd":[[2.6,4.62],[2.62,316.16],[2.64,188.13]],"batb":[[0,2.6,73.79],[1,2.52,45],[2,2.5,6.75]],"ltp":2.6,"tv":1799.5,"id":26314798}],"tv":4239.67}]}
{"op":"mcm","clk":"993208228","pt":1580538531462,"mc":[{"id":"1.168130661","rc":[{"batb":[[1,2.52,49.24]],"ltp":2.6,"tv":1799.5,"id":26314798}]}]}
{"op":"mcm","clk":"993208449","pt":1580538537475,"mc":[{"id":"1.168130661","rc":[{"trd":[[2.6,28.12]],"batb":[[0,2.6,62.04],[1,2.52,45]],"ltp":2.6,"tv":1823.0,"id":26314798}],"tv":4263.17}]}
{"op":"mcm","clk":"993208498","pt":1580538538966,"mc":[{"id":"1.168130661","rc":[{"batb":[[1,2.52,49.24]],"batl":[[1,2.74,88.49]],"ltp":2.6,"tv":1823.0,"id":26314798}]}]}
{"op":"mcm","clk":"993208670","pt":1580538544364,"mc":[{"id":"1.168130661","rc":[{"trd":[[2.6,118.24]],"batb":[[0,2.6,16.98],[1,2.52,45]],"batl":[[1,2.74,84.92]],"ltp":2.6,"tv":1913.12,"id":26314798}],"tv":4353.29}]}
{"op":"mcm","clk":"993208726","pt":1580538545879,"mc":[{"id":"1.168130661","rc":[{"batl":[[1,2.74,89]],"ltp":2.6,"tv":1913.12,"id":26314798}]}]}
{"op":"mcm","clk":"993208855","pt":1580538549698,"mc":[{"id":"1.168130661","rc":[{"batl":[[0,9.6,2.58]],"ltp":9.2,"tv":292.22,"id":24420205}]}]}
{"op":"mcm","clk":"993208891","pt":1580538550678,"mc":[{"id":"1.168130661","rc":[{"batl":[[1,9.8,6],[2,10,2.53]],"ltp":9.2,"tv":292.22,"id":24420205},{"batl":[[1,18.5,2.6],[2,32,9]],"ltp":11.0,"tv":218.48,"id":420}]}]}
{"op":"mcm","clk":"993208899","pt":1580538550781,"mc":[{"id":"1.168130661","rc":[{"batl":[[0,14.5,1.68],[1,15,2],[2,18.5,2.6]],"ltp":11.0,"tv":218.48,"id":420}]}]}
{"op":"mcm","clk":"993208976","pt":1580538552585,"mc":[{"id":"1.168130661","rc":[{"trd":[[2.52,67.13],[2.6,152.2]],"batb":[[0,2.52,13.42],[1,2.5,6.75],[2,2.46,10]],"ltp":2.52,"tv":2010.25,"id":26314798}],"tv":4450.42}]}
{"op":"mcm","clk":"993209010","pt":1580538553557,"mc":[{"id":"1.168130661","rc":[{"trd":[[2.52,85.93]],"batb":[[0,2.52,4.02]],"batl":[[0,2.64,14.31],[1,2.66,6.22],[2,2.72,2.95]],"ltp":2.52,"tv":2029.05,"id":26314798}],"tv":4469.22}]}
{"op":"mcm","clk":"993209135","pt":1580538557667,"mc":[{"id":"1.168130661","rc":[{"batl":[[1,10,2.53],[2,11.5,40]],"ltp":9.2,"tv":292.22,"id":24420205}]}]}
{"op":"mcm","clk":"993209146","pt":1580538557977,"mc":[{"id":"1.168130661","rc":[{"batl":[[0,9.6,8.58]],"ltp":9.2,"tv":292.22,"id":24420205}]}]}
{"op":"mcm","clk":"993209518","pt":1580538567195,"mc":[{"id":"1.168130661","rc":[{"trd":[[2.52,96.25]],"batb":[[0,2.52,3.86]],"ltp":2.52,"tv":2039.37,"id":26314798}],"tv":4479.54}]}
{"op":"mcm","clk":"993209608","pt":1580538569618,"mc":[{"id":"1.168130661","rc":[{"trd":[[2.54,19.12]],"batb":[[0,2.54,3.86],[1,2.52,43.65],[2,2.5,6.75]],"ltp":2.54,"tv":2054.53,"id":26314798}],"tv":4494.7}]}
{"op":"mcm","clk":"993209657","pt":1580538570603,"mc":[{"id":"1.168130661","rc":[{"trd":[[2.52,136.47],[2.54,26.84]],"batb":[[0,2.52,23.54],[1,2.5,6.75],[2,2.46,10]],"ltp":2.52,"tv":2102.47,"id":26314798}],"tv":4542.64}]}
{"op":"mcm","clk":"993209706","pt":1580538571694,"mc":[{"id":"1.168130661","rc":[{"trd":[[2.52,148.72]],"batb":[[0,2.52,17.42]],"ltp":2.52,"tv":2114.72,"id":26314798}],"tv":4554.89}]}
{"op":"mcm","clk":"993209954","pt":1580538578435,"mc":[{"id":"1.168130661","rc":[{"batb":[[2,2.46,15]],"ltp":2.52,"tv":2114.72,"id":26314798}]}]}
{"op":"mcm","clk":"993209978","pt":1580538579108,"mc":[{"id":"1.168130661","rc":[{"batl":[[0,14,2],[1,14.5,1.68]],"ltp":11.0,"tv":218.48,"id":420}]}]}
{"op":"mcm","clk":"993210102","pt":1580538582396,"mc":[{"id":"1.168130661","rc":[{"batl":[[0,13.5,1.68],[1,14,2]],"ltp":11.0,"tv":218.48,"id":420}]}]}
{"op":"mcm","clk":"993210123","pt":1580538583116,"mc":[{"id":"1.168130661","rc":[{"batl":[[0,2.66,6.22],[1,2.74,84.92],[2,2.76,199]],"ltp":2.52,"tv":2114.72,"id":26314798}]}]}
{"op":"mcm","clk":"993210364","pt":1580538589614,"mc":[{"id":"1.168130661","rc":[{"batb":[[0,2.5,6.75],[1,2.46,15],[2,2.44,44.73]],"ltp":2.52,"tv":2114.72,"id":26314798}]}]}
{"op":"mcm","clk":"993210419","pt":1580538590959,"mc":[{"id":"1.168130661","rc":[{"batl":[[0,9.6,2.58],[1,9.8,6],[2,10,2.53]],"ltp":9.2,"tv":292.22,"id":24420205}]}]}
{"op":"mcm","clk":"993210456","pt":1580538591940,"mc":[{"id":"1.168130661","rc":[{"batl":[[0,2.64,4],[1,2.66,6.22],[2,2.74,84.92]],"ltp":2.52,"tv":2114.72,"id":26314798}]}]}
{"op":"mcm","clk":"993210709","pt":1580538599217,"mc":[{"id":"1.168130661","rc":[{"batl":[[0,9.6,8.58],[1,10,2.53],[2,11.5,40]],"ltp":9.2,"tv":292.22,"id":24420205}]}]}
{"op":"mcm","clk":"993211166","pt":1580538608329,"mc":[{"id":"1.168130661","rc":[{"batb":[[0,2.5,24.31]],"ltp":2.52,"tv":2114.72,"id":26314798}]}]}
{"op":"mcm","clk":"993211436","pt":1580538614531,"mc":[{"id":"1.168130661","rc":[{"batl":[[0,14,2],[1,18,1.97],[2,18.5,2.31]],"ltp":11.0,"tv":218.48,"id":420}]}]}
{"op":"mcm","clk":"993212136","pt":1580538627660,"mc":[{"id":"1.168130661","rc":[{"batb":[[0,2.5,6.75],[1,2.48,17.7],[2,2.46,15]],"ltp":2.52,"tv":2114.72,"id":26314798}]}]}
{"op":"mcm","clk":"993212316","pt":1580538630650,"mc":[{"id":"1.168130661","rc":[{"batl":[[0,9.6,2.58]],"ltp":9.2,"tv":292.22,"id":24420205}]}]}
{"op":"mcm","clk":"993212319","pt":1580538630754,"mc":[{"id":"1.168130661","rc":[{"batl":[[1,9.8,6],[2,10,2.53]],"ltp":9.2,"tv":292.22,"id":24420205}]}]}
{"op":"mcm","clk":"993212445","pt":1580538633544,"mc":[{"id":"1.168130661","rc":[{"trd":[[2.5,30.64]],"batb":[[0,2.48,17.7],[1,2.46,15],[2,2.44,44.73]],"batl":[[0,2.5,1.25],[1,2.62,2],[2,2.64,4]],"ltp":2.5,"tv":2128.22,"id":26314798},{"batl":[[0,17.5,2.29],[1,18,1.68]],"ltp":11.0,"tv":218.48,"id":420}],"tv":4568.39}]}
{"op":"mcm","clk":"993212632","pt":1580538638360,"mc":[{"id":"1.168130661","rc":[{"batl":[[0,17.5,2.47]],"ltp":11.0,"tv":218.48,"id":420}]}]}
{"op":"mcm","clk":"993212805","pt":1580538642680,"mc":[{"id":"1.168130661","rc":[{"batb":[[1,32,2.48],[2,30,1.79]],"ltp":30.0,"tv":37.41,"id":25545675},{"batb":[[0,2.86,4.7]],"ltp":2.88,"tv":1705.97,"id":25238892},{"trd":[[2.5,33.14]],"batb":[[0,2.5,3.75],[1,2.48,20.51],[2,2.46,15]],"batl":[[0,2.62,2],[1,2.64,4],[2,2.66,6.22]],"ltp":2.5,"tv":2130.72,"id":26314798}],"tv":4570.89}]}
{"op":"mcm","clk":"993212984","pt":1580538645477,"mc":[{"id":"1.168130661","rc":[{"batl":[[0,17,2.15],[1,17.5,2]],"ltp":11.0,"tv":218.48,"id":420}]}]}
{"op":"mcm","clk":"993213028","pt":1580538646465,"mc":[{"id":"1.168130661","rc":[{"batb":[[0,2.52,17.42],[1,2.5,11.31],[2,2.48,2.81]],"ltp":2.5,"tv":2130.72,"id":26314798}]}]}
{"op":"mcm","clk":"993213364","pt":1580538655565,"mc":[{"id":"1.168130661","rc":[{"batl":[[0,9.6,8.58],[1,10,2.53],[2,11.5,40]],"ltp":9.2,"tv":292.22,"id":24420205}]}]}
{"op":"mcm","clk":"993213787","pt":1580538662696,"mc":[{"id":"1.168130661","rc":[{"batl":[[0,9.6,2.58]],"ltp":9.2,"tv":292.22,"id":24420205}]}]}
{"op":"mcm","clk":"993213846","pt":1580538663481,"mc":[{"id":"1.168130661","rc":[{"batl":[[1,9.8,6],[2,10,2.53]],"ltp":9.2,"tv":292.22,"id":24420205}]}]}
{"op":"mcm","clk":"993215068","pt":1580538686598,"mc":[{"id":"1.168130661","rc":[{"batl":[[0,2.64,4],[1,2.66,6.22],[2,2.72,6]],"ltp":2.5,"tv":2130.72,"id":26314798},{"batl":[[1,18,2]],"ltp":11.0,"tv":218.48,"id":420}]}]}
{"op":"mcm","clk":"993215320","pt":1580538692106,"mc":[{"id":"1.168130661","rc":[{"batl":[[1,17.5,2.12],[2,18,2]],"ltp":11.0,"tv":218.48,"id":420}]}]}
{"op":"mcm","clk":"993215576","pt":1580538696439,"mc":[{"id":"1.168130661","rc":[{"batl":[[0,16.5,7.78],[1,17,1.97],[2,17.5,2.12]],"ltp":11.0,"tv":218.48,"id":420}]}]}
{"op":"mcm","clk":"993215828","pt":1580538703022,"mc":[{"id":"1.168130661","rc":[{"batl":[[0,9.6,8.58],[1,10,2.53],[2,11.5,40]],"ltp":9.2,"tv":292.22,"id":24420205}]}]}
{"op":"mcm","clk":"993216018","pt":1580538709133,"mc":[{"id":"1.168130661","rc":[{"batl":[[0,16,1.95],[1,16.5,7.6],[2,17.5,2.41]],"ltp":11.0,"tv":218.48,"id":420}]}]}
{"op":"mcm","clk":"993216083","pt":1580538711144,"mc":[{"id":"1.168130661","rc":[{"batl":[[2,18,2.29]],"ltp":11.0,"tv":218.48,"id":420}]}]}
{"op":"mcm","clk":"993217157","pt":1580538740676,"mc":[{"id":"1.168130661","rc":[{"batl":[[0,15.5,2],[1,16.5,7.78],[2,18.5,2.6]],"ltp":11.0,"tv":218.48,"id":420}]}]}
{"op":"mcm","clk":"993217165","pt":1580538740781,"mc":[{"id":"1.168130661","rc":[{"batl":[[0,15,1.68],[1,15.5,2],[2,16.5,7.78]],"ltp":11.0,"tv":218.48,"id":420}]}]}
{"op":"mcm","clk":"993217304","pt":1580538743866,"mc":[{"id":"1.168130661","rc":[{"batl":[[0,9.6,2.58],[1,9.8,6],[2,10,2.53]],"ltp":9.2,"tv":292.22,"id":24420205}]}]}
{"op":"mcm","clk":"993217888","pt":1580538759122,"mc":[{"id":"1.168130661","rc":[{"batb":[[0,2.54,5.04],[1,2.52,17.42],[2,2.5,3.75]],"ltp":2.5,"tv":2130.72,"id":26314798}]}]}
{"op":"mcm","clk":"993218013","pt":1580538761506,"mc":[{"id":"1.168130661","rc":[{"batl":[[0,9.6,8.58],[1,10,2.53],[2,11.5,40]],"ltp":9.2,"tv":292.22,"id":24420205}]}]}
{"op":"mcm","clk":"993218262","pt":1580538767614,"mc":[{"id":"1.168130661","rc":[{"batl":[[2,2.7,5]],"ltp":2.5,"tv":2130.72,"id":26314798}]}]}
{"op":"mcm","clk":"993218328","pt":1580538769101,"mc":[{"id":"1.168130661","rc":[{"batl":[[0,9.6,2.58],[1,9.8,6],[2,10,2.53]],"ltp":9.2,"tv":292.22,"id":24420205}]}]}
{"op":"mcm","clk":"993218747","pt":1580538778411,"mc":[{"id":"1.168130661","rc":[{"batl":[[0,2.66,6.22],[1,2.7,5],[2,2.72,6]],"ltp":2.5,"tv":2130.72,"id":26314798}]}]}
{"op":"mcm","clk":"993219573","pt":1580538794631,"mc":[{"id":"1.168130661","rc":[{"batl":[[0,9.6,8.58],[1,10,2.53],[2,11.5,40]],"ltp":9.2,"tv":292.22,"id":24420205},{"batl":[[0,14.5,2],[1,15,1.68]],"ltp":11.0,"tv":218.48,"id":420}]}]}
{"op":"mcm","clk":"993219638","pt":1580538795559,"mc":[{"id":"1.168130661","rc":[{"batl":[[2,16.5,7.6]],"ltp":11.0,"tv":218.48,"id":420}]}]}
{"op":"mcm","clk":"993219926","pt":1580538801706,"mc":[{"id":"1.168130661","rc":[{"batl":[[0,9.6,2.58],[1,9.8,6],[2,10,2.53]],"ltp":9.2,"tv":292.22,"id":24420205}]}]}
{"op":"mcm","clk":"993220083","pt":1580538804652,"mc":[{"id":"1.168130661","rc":[{"batl":[[0,14,1.68],[1,14.5,2]],"ltp":11.0,"tv":218.48,"id":420}]}]}
{"op":"mcm","clk":"993220330","pt":1580538810657,"mc":[{"id":"1.168130661","rc":[{"batl":[[0,9.6,8.58],[1,10,2.53],[2,11.5,40]],"ltp":9.2,"tv":292.22,"id":24420205}]}]}
{"op":"mcm","clk":"993221094","pt":1580538831593,"mc":[{"id":"1.168130661","rc":[{"trd":[[2.9,33.18]],"batl":[[0,2.92,3.72],[1,2.94,8.4],[2,2.96,6.72]],"ltp":2.9,"tv":1711.97,"id":25238892}],"tv":4576.89}]}
{"op":"mcm","clk":"993221137","pt":1580538832583,"mc":[{"id":"1.168130661","rc":[{"batb":[[0,2.88,6.21],[1,2.86,4.47]],"ltp":2.9,"tv":1711.97,"id":25238892}]}]}
{"op":"mcm","clk":"993221270","pt":1580538836255,"mc":[{"id":"1.168130661","rc":[{"batl":[[0,14.5,2],[1,16,1.68]],"ltp":11.0,"tv":218.48,"id":420}]}]}
{"op":"mcm","clk":"993221660","pt":1580538845494,"mc":[{"id":"1.168130661","rc":[{"batl":[[1,15.5,2.39],[2,16,1.68]],"ltp":11.0,"tv":218.48,"id":420}]}]}
{"op":"mcm","clk":"993221728","pt":1580538847510,"mc":[{"id":"1.168130661","rc":[{"trd":[[2.9,33.9],[2.92,15.62]],"batl":[[0,2.94,9.12],[1,2.96,6.72],[2,2.98,100]],"ltp":2.92,"tv":1717.97,"id":25238892},{"batl":[[0,15,2]],"ltp":11.0,"tv":218.48,"id":420}],"tv":4582.89}]}
{"op":"mcm","clk":"993221891","pt":1580538851677,"mc":[{"id":"1.168130661","rc":[{"batl":[[0,9.6,2.58]],"ltp":9.2,"tv":292.22,"id":24420205}]}]}
{"op":"mcm","clk":"993221895","pt":1580538851781,"mc":[{"id":"1.168130661","rc":[{"batl":[[1,9.8,6],[2,10,2.53]],"ltp":9.2,"tv":292.22,"id":24420205}]}]}
{"op":"mcm","clk":"993222119","pt":1580538858015,"mc":[{"id":"1.168130661","rc":[{"batb":[[1,2.82,4.47]],"batl":[[0,2.92,11.29],[1,2.94,8.4],[2,2.96,6.72]],"ltp":2.92,"tv":1717.97,"id":25238892}]}]}
{"op":"mcm","clk":"993222192","pt":1580538859714,"mc":[{"id":"1.168130661","rc":[{"batl":[[0,9.6,8.58],[1,10,2.53],[2,11.5,40]],"ltp":9.2,"tv":292.22,"id":24420205}]}]}
{"op":"mcm","clk":"993222558","pt":1580538867636,"mc":[{"id":"1.168130661","rc":[{"batl":[[0,9.6,2.58]],"ltp":9.2,"tv":292.22,"id":24420205}]}]}
{"op":"mcm","clk":"993222582","pt":1580538867994,"mc":[{"id":"1.168130661","rc":[{"batl":[[1,9.8,6],[2,10,2.53]],"ltp":9.2,"tv":292.22,"id":24420205},{"batl":[[0,14.5,1.68],[1,15,2],[2,15.5,2.39]],"ltp":11.0,"tv":218.48,"id":420}]}]}
{"op":"mcm","clk":"993222973","pt":1580538876709,"mc":[{"id":"1.168130661","rc":[{"batl":[[0,9.6,8.58],[1,10,2.53],[2,11.5,40]],"ltp":9.2,"tv":292.22,"id":24420205}]}]}
{"op":"mcm","clk":"993223273","pt":1580538883642,"mc":[{"id":"1.168130661","rc":[{"batl":[[2,16.5,7.6]],"ltp":11.0,"tv":218.48,"id":420}]}]}
{"op":"mcm","clk":"993223997","pt":1580538901475,"mc":[{"id":"1.168130661","rc":[{"batl":[[0,14,2],[1,14.5,1.68]],"ltp":11.0,"tv":218.48,"id":420}]}]}
{"op":"mcm","clk":"993224583","pt":1580538916375,"mc":[{"id":"1.168130661","rc":[{"batl":[[0,9.6,2.58],[1,9.8,6],[2,10,2.53]],"ltp":9.2,"tv":292.22,"id":24420205}]}]}
{"op":"mcm","clk":"993224823","pt":1580538921604,"mc":[{"id":"1.168130661","rc":[{"batl":[[2,18.5,2.6]],"ltp":11.0,"tv":218.48,"id":420}]}]}
{"op":"mcm","clk":"993224967","pt":1580538925575,"mc":[{"id":"1.168130661","rc":[{"batl":[[0,9.6,8.58],[1,10,2.53],[2,11.5,40]],"ltp":9.2,"tv":292.22,"id":24420205}]}]}
{"op":"mcm","clk":"993225168","pt":1580538931593,"mc":[{"id":"1.168130661","rc":[{"batl":[[0,13.5,1.68],[1,14,2]],"ltp":11.0,"tv":218.48,"id":420}]}]}
{"op":"mcm","clk":"993225516","pt":1580538941688,"mc":[{"id":"1.168130661","rc":[{"batl":[[0,9.6,2.58],[1,9.8,6],[2,10,2.53]],"ltp":9.2,"tv":292.22,"id":24420205}]}]}
{"op":"mcm","clk":"993225794","pt":1580538950296,"mc":[{"id":"1.168130661","rc":[{"batl":[[0,9.6,8.58],[1,10,2.53],[2,11.5,40]],"ltp":9.2,"tv":292.22,"id":24420205}]}]}
{"op":"mcm","clk":"993225989","pt":1580538954643,"mc":[{"id":"1.168130661","rc":[{"batl":[[1,18,2.29],[2,18.5,2.31]],"ltp":11.0,"tv":218.48,"id":420}]}]}
{"op":"mcm","clk":"993226201","pt":1580538960615,"mc":[{"id":"1.168130661","rc":[{"batl":[[1,17.5,2.41],[2,18,2]],"ltp":11.0,"tv":218.48,"id":420}]}]}
{"op":"mcm","clk":"993226297","pt":1580538963547,"mc":[{"id":"1.168130661","rc":[{"batl":[[0,17,1.97],[1,17.5,2.12]],"ltp":11.0,"tv":218.48,"id":420}]}]}
{"op":"mcm","clk":"993226547","pt":1580538970513,"mc":[{"id":"1.168130661","rc":[{"batl":[[0,17,2.17]],"ltp":11.0,"tv":218.48,"id":420}]}]}
{"op":"mcm","clk":"993227040","pt":1580538982261,"mc":[{"id":"1.168130661","rc":[{"batl":[[0,9.6,2.58],[1,9.8,6],[2,10,2.53]],"ltp":9.2,"tv":292.22,"id":24420205}]}]}
{"op":"mcm","clk":"993227341","pt":1580538990653,"mc":[{"id":"1.168130661","rc":[{"batl":[[0,9.6,8.58],[1,10,2.53],[2,11.5,40]],"ltp":9.2,"tv":292.22,"id":24420205}]}]}
{"op":"mcm","clk":"993228021","pt":1580539008089,"mc":[{"id":"1.168130661","rc":[{"batl":[[0,16.5,2.2],[1,17,1.97],[2,17.5,2.12]],"ltp":11.0,"tv":218.48,"id":420}]}]}
{"op":"mcm","clk":"993228522","pt":1580539019627,"mc":[{"id":"1.168130661","rc":[{"batl":[[2,18.5,2.31]],"ltp":11.0,"tv":218.48,"id":420}]}]}
{"op":"mcm","clk":"993228711","pt":1580539023710,"mc":[{"id":"1.168130661","rc":[{"batl":[[0,9.6,2.58],[1,9.8,6],[2,10,2.53]],"ltp":9.2,"tv":292.22,"id":24420205}]}]}
{"op":"mcm","clk":"993228887","pt":1580539027233,"mc":[{"id":"1.168130661","rc":[{"batl":[[0,16,1.88],[1,16.5,2],[2,18.5,2.6]],"ltp":11.0,"tv":218.48,"id":420}]}]}
{"op":"mcm","clk":"993229100","pt":1580539031700,"mc":[{"id":"1.168130661","rc":[{"batl":[[0,9.6,8.58],[1,10,2.53],[2,11.5,40]],"ltp":9.2,"tv":292.22,"id":24420205}]}]}
{"op":"mcm","clk":"993229765","pt":1580539048358,"mc":[{"id":"1.168130661","rc":[{"batl":[[0,9.6,2.58],[1,9.8,6],[2,10,2.53]],"ltp":9.2,"tv":292.22,"id":24420205}]}]}
{"op":"mcm","clk":"993239930","pt":1580539056722,"mc":[{"id":"1.168130661","rc":[{"batl":[[0,9.6,8.58],[1,10,2.53],[2,11.5,40]],"ltp":9.2,"tv":292.22,"id":24420205}]}]}
{"op":"mcm","clk":"993240111","pt":1580539061637,"mc":[{"id":"1.168130661","rc":[{"batl":[[1,18,2.29],[2,18.5,2.31]],"ltp":11.0,"tv":218.48,"id":420}]}]}
{"op":"mcm","clk":"993240522","pt":1580539074044,"mc":[{"id":"1.168130661","rc":[{"batl":[[0,9.6,2.58],[1,9.8,6],[2,10,2.53]],"ltp":9.2,"tv":292.22,"id":24420205}]}]}
{"op":"mcm","clk":"993240584","pt":1580539076622,"mc":[{"id":"1.168130661","rc":[{"batl":[[1,17.5,2.41],[2,18,2]],"ltp":11.0,"tv":218.48,"id":420}]}]}
{"op":"mcm","clk":"993240600","pt":1580539077445,"mc":[{"id":"1.168130661","rc":[{"batl":[[0,2.92,13.29]],"ltp":2.92,"tv":1717.97,"id":25238892}]}]}
{"op":"mcm","clk":"993240771","pt":1580539082465,"mc":[{"id":"1.168130661","rc":[{"batl":[[0,9.6,8.58],[1,10,2.53],[2,11.5,40]],"ltp":9.2,"tv":292.22,"id":24420205}]}]}
{"op":"mcm","clk":"993241057","pt":1580539090683,"mc":[{"id":"1.168130661","rc":[{"batl":[[0,17,2.17],[1,17.5,2.12]],"ltp":11.0,"tv":218.48,"id":420}]}]}
{"op":"mcm","clk":"993241430","pt":1580539099677,"mc":[{"id":"1.168130661","rc":[{"batl":[[0,9.6,2.58]],"ltp":9.2,"tv":292.22,"id":24420205}]}]}
{"op":"mcm","clk":"993241438","pt":1580539099936,"mc":[{"id":"1.168130661","rc":[{"batl":[[1,9.8,6],[2,10,2.53]],"ltp":9.2,"tv":292.22,"id":24420205}]}]}
{"op":"mcm","clk":"993242017","pt":1580539114269,"mc":[{"id":"1.168130661","rc":[{"batl":[[0,9.6,8.58],[1,10,2.53],[2,11.5,40]],"ltp":9.2,"tv":292.22,"id":24420205}]}]}
{"op":"mcm","clk":"993242052","pt":1580539115712,"mc":[{"id":"1.168130661","rc":[{"batl":[[0,16.5,2.2],[1,17,1.97],[2,18.5,2.31]],"ltp":11.0,"tv":218.48,"id":420}]}]}
{"op":"mcm","clk":"993242286","pt":1580539122608,"mc":[{"id":"1.168130661","rc":[{"batl":[[0,16,1.88],[1,16.5,2],[2,18.5,2.6]],"ltp":11.0,"tv":218.48,"id":420}]}]}
{"op":"mcm","clk":"993242906","pt":1580539140619,"mc":[{"id":"1.168130661","rc":[{"batl":[[0,9.6,2.58],[1,9.8,6],[2,10,2.53]],"ltp":9.2,"tv":292.22,"id":24420205}]}]}
{"op":"mcm","clk":"993243939","pt":1580539166261,"mc":[{"id":"1.168130661","rc":[{"batl":[[0,9.6,8.58],[1,10,2.53],[2,11.5,40]],"ltp":9.2,"tv":292.22,"id":24420205}]}]}
{"op":"mcm","clk":"993244045","pt":1580539168972,"mc":[{"id":"1.168130661","rc":[{"batl":[[1,18,2.29],[2,18.5,2.31]],"ltp":11.0,"tv":218.48,"id":420}]}]}
{"op":"mcm","clk":"993244242","pt":1580539173371,"mc":[{"id":"1.168130661","rc":[{"batl":[[0,9.6,2.58],[1,9.8,6],[2,10,2.53]],"ltp":9.2,"tv":292.22,"id":24420205},{"batl":[[1,17.5,2.41],[2,18,2]],"ltp":11.0,"tv":218.48,"id":420}]}]}
{"op":"mcm","clk":"993244498","pt":1580539181155,"mc":[{"id":"1.168130661","rc":[{"batl":[[0,9.6,8.58],[1,10,2.53],[2,11.5,40]],"ltp":9.2,"tv":292.22,"id":24420205}]}]}
{"op":"mcm","clk":"993244625","pt":1580539185273,"mc":[{"id":"1.168130661","rc":[{"batl":[[0,2.9,2],[1,2.92,13.29],[2,2.94,8.4]],"ltp":2.92,"tv":1717.97,"id":25238892}]}]}
{"op":"mcm","clk":"993244652","pt":1580539186193,"mc":[{"id":"1.168130661","rc":[{"batl":[[0,17,2.17],[1,17.5,2.12]],"ltp":11.0,"tv":218.48,"id":420}]}]}
{"op":"mcm","clk":"993245011","pt":1580539194579,"mc":[{"id":"1.168130661","rc":[{"trd":[[2.88,117.67]],"batb":[[0,2.82,4.47],[1,2.8,16.46],[2,2.78,4]],"batl":[[0,2.88,3.79],[1,2.9,2],[2,2.92,13.29]],"ltp":2.88,"tv":1730.39,"id":25238892}],"tv":4595.31}]}
{"op":"mcm","clk":"993245143","pt":1580539197674,"mc":[{"id":"1.168130661","rc":[{"batb":[[0,2.56,6.73],[1,2.54,5.04],[2,2.52,17.42]],"ltp":2.5,"tv":2130.72,"id":26314798}]}]}
{"op":"mcm","clk":"993245270","pt":1580539200512,"mc":[{"id":"1.168130661","rc":[{"batb":[[2,2.5,3.75]],"ltp":2.5,"tv":2130.72,"id":26314798}]}]}
{"op":"mcm","clk":"993245340","pt":1580539202208,"mc":[{"id":"1.168130661","rc":[{"batl":[[2,2.92,11.29]],"ltp":2.88,"tv":1730.39,"id":25238892}]}]}
{"op":"mcm","clk":"993245442","pt":1580539204594,"mc":[{"id":"1.168130661","rc":[{"trd":[[2.86,167.23]],"batb":[[0,2.82,4]],"batl":[[0,2.86,3.32]],"ltp":2.86,"tv":1731.33,"id":25238892}],"tv":4596.25}]}
{"op":"mcm","clk":"993245674","pt":1580539209709,"mc":[{"id":"1.168130661","rc":[{"trd":[[2.82,121.42]],"batb":[[0,2.8,16.46],[1,2.78,4],[2,2.7,8.79]],"batl":[[0,2.82,16],[1,2.84,3.32],[2,2.9,2]],"ltp":2.82,"tv":1739.33,"id":25238892}],"tv":4604.25}]}
{"op":"mcm","clk":"993245689","pt":1580539210009,"mc":[{"id":"1.168130661","rc":[{"batb":[[0,11.5,2.17]],"ltp":11.0,"tv":218.48,"id":420}]}]}
{"op":"mcm","clk":"993245849","pt":1580539213623,"mc":[{"id":"1.168130661","rc":[{"batl":[[0,2.82,19.32],[1,2.9,2],[2,2.92,11.29]],"ltp":2.82,"tv":1739.33,"id":25238892}]}]}
{"op":"mcm","clk":"993245897","pt":1580539214610,"mc":[{"id":"1.168130661","rc":[{"batl":[[0,9.6,2.58],[1,9.8,6],[2,10,2.53]],"ltp":9.2,"tv":292.22,"id":24420205},{"batb":[[1,2.5,3.75],[2,2.48,2.81]],"batl":[[0,2.64,11.05],[1,2.66,6.22],[2,2.7,5]],"ltp":2.5,"tv":2130.72,"id":26314798}]}]}
{"op":"mcm","clk":"993246007","pt":1580539217600,"mc":[{"id":"1.168130661","rc":[{"trd":[[2.8,101.78]],"batb":[[0,2.78,4.46],[1,2.7,8.79],[2,2.68,93]],"batl":[[0,2.82,3.32]],"ltp":2.8,"tv":1771.33,"id":25238892}],"tv":4636.25}]}
{"op":"mcm","clk":"993246090","pt":1580539219101,"mc":[{"id":"1.168130661","rc":[{"trd":[[2.8,102.7]],"batb":[[0,2.78,4]],"batl":[[0,2.8,2.86]],"ltp":2.8,"tv":1772.25,"id":25238892}],"tv":4637.17}]}
{"op":"mcm","clk":"993246236","pt":1580539222710,"mc":[{"id":"1.168130661","rc":[{"batl":[[0,9.6,8.58],[1,10,2.53],[2,11.5,40]],"ltp":9.2,"tv":292.22,"id":24420205},{"batl":[[0,16.5,2.2],[1,17,1.97],[2,17.5,2.12]],"ltp":11.0,"tv":218.48,"id":420}]}]}
{"op":"mcm","clk":"993246537","pt":1580539230442,"mc":[{"id":"1.168130661","rc":[{"batl":[[0,9.6,2.58],[1,9.8,6],[2,10,2.53]],"ltp":9.2,"tv":292.22,"id":24420205},{"batl":[[2,18.5,2.31]],"ltp":11.0,"tv":218.48,"id":420}]}]}
{"op":"mcm","clk":"993246556","pt":1580539230909,"mc":[{"id":"1.168130661","rc":[{"batb":[[2,2.58,97]],"ltp":2.8,"tv":1772.25,"id":25238892}]}]}
{"op":"mcm","clk":"993246678","pt":1580539234236,"mc":[{"id":"1.168130661","rc":[{"batb":[[2,2.6,6]],"ltp":2.8,"tv":1772.25,"id":25238892}]}]}
{"op":"mcm","clk":"993246825","pt":1580539237619,"mc":[{"id":"1.168130661","rc":[{"trd":[[2.8,108.42]],"batl":[[0,2.9,2],[1,2.94,9.12],[2,2.96,6.72]],"ltp":2.8,"tv":1777.97,"id":25238892}],"tv":4642.89}]}
{"op":"mcm","clk":"993247238","pt":1580539247560,"mc":[{"id":"1.168130661","rc":[{"trd":[[14.5,21.42]],"batb":[[0,13.5,12.66],[1,13,4.7],[2,12.5,2]],"batl":[[0,15.5,6.94]],"ltp":14.5,"tv":194.78,"id":24707172}],"tv":4651.61}]}
{"op":"mcm","clk":"993247424","pt":1580539251641,"mc":[{"id":"1.168130661","rc":[{"batb":[[2,2.62,3.19]],"batl":[[0,2.88,10.68],[1,2.9,2],[2,2.92,3.59]],"ltp":2.8,"tv":1777.97,"id":25238892},{"batb":[[0,8.6,2],[1,8.4,3.88],[2,8,42.17]],"ltp":9.2,"tv":292.22,"id":24420205},{"batl":[[0,16,1.88],[1,16.5,2],[2,18.5,2.6]],"ltp":11.0,"tv":218.48,"id":420}]}]}
{"op":"mcm","clk":"993247576","pt":1580539255671,"mc":[{"id":"1.168130661","rc":[{"batb":[[1,8.4,6.88]],"ltp":9.2,"tv":292.22,"id":24420205}]}]}
{"op":"mcm","clk":"993247592","pt":1580539256032,"mc":[{"id":"1.168130661","rc":[{"trd":[[13.5,30.95]],"batb":[[0,13.5,12.02]],"batl":[[0,15.5,6.3]],"ltp":13.5,"tv":196.06,"id":24707172},{"batl":[[0,9.6,8.58],[1,10,2.53],[2,11.5,40]],"ltp":9.2,"tv":292.22,"id":24420205}],"tv":4652.89}]}
{"op":"mcm","clk":"993247655","pt":1580539257373,"mc":[{"id":"1.168130661","rc":[{"batb":[[0,14,4.52],[1,13.5,12.02],[2,13,4.7]],"ltp":13.5,"tv":196.06,"id":24707172}]}]}
{"op":"mcm","clk":"993248387","pt":1580539273155,"mc":[{"id":"1.168130661","rc":[{"batb":[[1,2.72,3],[2,2.7,8.79]],"ltp":2.8,"tv":1777.97,"id":25238892}]}]}
{"op":"mcm","clk":"993248559","pt":1580539276997,"mc":[{"id":"1.168130661","rc":[{"batl":[[1,18,2.29],[2,18.5,2.31]],"ltp":11.0,"tv":218.48,"id":420}]}]}
{"op":"mcm","clk":"993248926","pt":1580539284487,"mc":[{"id":"1.168130661","rc":[{"batl":[[0,17.5,2.17],[1,18,2]],"ltp":11.0,"tv":218.48,"id":420}]}]}
{"op":"mcm","clk":"993249134","pt":1580539288587,"mc":[{"id":"1.168130661","rc":[{"batl":[[0,9.6,2.58],[1,9.8,6],[2,10,2.53]],"ltp":9.2,"tv":292.22,"id":24420205}]}]}
{"op":"mcm","clk":"993249187","pt":1580539289570,"mc":[{"id":"1.168130661","rc":[{"batl":[[0,17.5,4.29]],"ltp":11.0,"tv":218.48,"id":420}]}]}
{"op":"mcm","clk":"993249452","pt":1580539295559,"mc":[{"id":"1.168130661","rc":[{"batb":[[0,13.5,12.02],[1,13,4.7],[2,12.5,2]],"ltp":13.5,"tv":196.06,"id":24707172}]}]}
{"op":"mcm","clk":"993249501","pt":1580539296696,"mc":[{"id":"1.168130661","rc":[{"batl":[[0,9.6,8.58],[1,10,2.53],[2,11.5,40]],"ltp":9.2,"tv":292.22,"id":24420205}]}]}
{"op":"mcm","clk":"993249539","pt":1580539297516,"mc":[{"id":"1.168130661","rc":[{"batb":[[0,2.78,18.12]],"ltp":2.8,"tv":1777.97,"id":25238892},{"batb":[[0,8.8,1.98],[1,8.6,2],[2,8.4,4.89]],"ltp":9.2,"tv":292.22,"id":24420205},{"batb":[[0,2.56,9.54],[2,2.46,10]],"ltp":2.5,"tv":2130.72,"id":26314798}]}]}
{"op":"mcm","clk":"993249716","pt":1580539301580,"mc":[{"id":"1.168130661","rc":[{"batb":[[0,8.8,3.79],[2,8.4,3]],"ltp":9.2,"tv":292.22,"id":24420205}]}]}
{"op":"mcm","clk":"993249746","pt":1580539302406,"mc":[{"id":"1.168130661","rc":[{"batb":[[1,2.7,8.79],[2,2.62,3.19]],"ltp":2.8,"tv":1777.97,"id":25238892}]}]}
{"op":"mcm","clk":"993250182","pt":1580539313903,"mc":[{"id":"1.168130661","rc":[{"batl":[[0,9.6,2.58],[1,9.8,6],[2,10,2.53]],"ltp":9.2,"tv":292.22,"id":24420205}]}]}
{"op":"mcm","clk":"993250340","pt":1580539318213,"mc":[{"id":"1.168130661","rc":[{"batb":[[0,2.8,5.88],[1,2.78,18.12],[2,2.7,8.79]],"batl":[[0,2.9,2],[1,2.92,3.59],[2,2.94,8.4]],"ltp":2.8,"tv":1777.97,"id":25238892}]}]}
{"op":"mcm","clk":"993250501","pt":1580539321509,"mc":[{"id":"1.168130661","rc":[{"batl":[[0,9.6,8.58],[1,10,2.53],[2,11.5,40]],"ltp":9.2,"tv":292.22,"id":24420205}]}]}
{"op":"mcm","clk":"993250903","pt":1580539330723,"mc":[{"id":"1.168130661","rc":[{"batl":[[0,9.8,6.58]],"ltp":9.2,"tv":292.22,"id":24420205},{"batl":[[0,17,2.49],[1,17.5,3.8]],"ltp":11.0,"tv":218.48,"id":420}]}]}
{"op":"mcm","clk":"993251637","pt":1580539345511,"mc":[{"id":"1.168130661","rc":[{"batl":[[0,16.5,7.8],[1,17,2.29],[2,17.5,3.8]],"ltp":11.0,"tv":218.48,"id":420}]}]}
{"op":"mcm","clk":"993251678","pt":1580539346335,"mc":[{"id":"1.168130661","rc":[{"batl":[[0,16,2.52],[1,16.5,7.6],[2,17,2.29]],"ltp":11.0,"tv":218.48,"id":420}]}]}
{"op":"mcm","clk":"993251796","pt":1580539348644,"mc":[{"id":"1.168130661","rc":[{"batl":[[0,2.88,1.68],[1,2.9,2],[2,2.94,9.12]],"ltp":2.8,"tv":1777.97,"id":25238892}]}]}
{"op":"mcm","clk":"993251838","pt":1580539349417,"mc":[{"id":"1.168130661","rc":[{"batl":[[0,9.8,6.57]],"ltp":9.2,"tv":292.22,"id":24420205},{"batl":[[0,15.5,1.82],[1,16,2.52],[2,16.5,7.6]],"ltp":11.0,"tv":218.48,"id":420}]}]}
{"op":"mcm","clk":"993253276","pt":1580539381675,"mc":[{"id":"1.168130661","rc":[{"batl":[[0,2.9,2],[1,2.94,9.12],[2,2.96,6.72]],"ltp":2.8,"tv":1777.97,"id":25238892}]}]}
{"op":"mcm","clk":"993253326","pt":1580539382495,"mc":[{"id":"1.168130661","rc":[{"batl":[[1,2.92,2.4],[2,2.94,8.4]],"ltp":2.8,"tv":1777.97,"id":25238892}]}]}
{"op":"mcm","clk":"993253390","pt":1580539383781,"mc":[{"id":"1.168130661","rc":[{"batl":[[0,15,2],[1,15.5,1.82],[2,16,2.52]],"ltp":11.0,"tv":218.48,"id":420}]}]}
{"op":"mcm","clk":"993253475","pt":1580539385687,"mc":[{"id":"1.168130661","rc":[{"batl":[[2,16.5,7.8]],"ltp":11.0,"tv":218.48,"id":420}]}]}
{"op":"mcm","clk":"993254581","pt":1580539413631,"mc":[{"id":"1.168130661","rc":[{"batl":[[0,2.88,1.68],[1,2.9,2],[2,2.94,9.12]],"ltp":2.8,"tv":1777.97,"id":25238892},{"batl":[[0,14.5,1.68],[1,15,2]],"ltp":11.0,"tv":218.48,"id":420}]}]}
{"op":"mcm","clk":"993254764","pt":1580539418715,"mc":[{"id":"1.168130661","rc":[{"batb":[[0,12,1.44],[1,11.5,4.17],[2,11,5]],"batl":[[2,16.5,7.6]],"ltp":11.0,"tv":218.48,"id":420}]}]}
{"op":"mcm","clk":"993255093","pt":1580539425614,"mc":[{"id":"1.168130661","rc":[{"batb":[[0,8.8,6.79],[2,8,42.17]],"ltp":9.2,"tv":292.22,"id":24420205}]}]}
{"op":"mcm","clk":"993255392","pt":1580539431720,"mc":[{"id":"1.168130661","rc":[{"batb":[[1,11.5,6.17]],"ltp":11.0,"tv":218.48,"id":420}]}]}
{"op":"mcm","clk":"993255560","pt":1580539435631,"mc":[{"id":"1.168130661","rc":[{"batb":[[1,11.5,9.53]],"ltp":11.0,"tv":218.48,"id":420}]}]}
{"op":"mcm","clk":"993255605","pt":1580539436714,"mc":[{"id":"1.168130661","rc":[{"batl":[[1,16.5,7.6],[2,18.5,2.6]],"ltp":11.0,"tv":218.48,"id":420}]}]}
{"op":"mcm","clk":"993255611","pt":1580539436817,"mc":[{"id":"1.168130661","rc":[{"batl":[[0,9.6,2.57],[1,9.8,6],[2,10,2.53]],"ltp":9.2,"tv":292.22,"id":24420205},{"batl":[[0,14,2],[1,14.5,1.68],[2,16.5,7.6]],"ltp":11.0,"tv":218.48,"id":420}]}]}
{"op":"mcm","clk":"993256039","pt":1580539445629,"mc":[{"id":"1.168130661","rc":[{"batl":[[0,2.9,2],[1,2.92,2.4],[2,2.94,8.4]],"ltp":2.8,"tv":1777.97,"id":25238892},{"batb":[[0,9,1.92],[1,8.8,6.79]],"ltp":9.2,"tv":292.22,"id":24420205},{"batl":[[1,16.5,7.6],[2,18.5,2.6]],"ltp":11.0,"tv":218.48,"id":420}]}]}
{"op":"mcm","clk":"993256044","pt":1580539445731,"mc":[{"id":"1.168130661","rc":[{"batl":[[0,13.5,1.68],[1,14,2],[2,16.5,7.6]],"ltp":11.0,"tv":218.48,"id":420}]}]}
{"op":"mcm","clk":"993256175","pt":1580539448458,"mc":[{"id":"1.168130661","rc":[{"batb":[[0,2.8,35.84]],"ltp":2.8,"tv":1777.97,"id":25238892},{"batb":[[0,14,4.52],[1,13.5,12.02],[2,13,4.7]],"ltp":13.5,"tv":196.06,"id":24707172}]}]}
{"op":"mcm","clk":"993257035","pt":1580539466579,"mc":[{"id":"1.168130661","rc":[{"trd":[[9,29.3]],"batb":[[0,8.8,6.79],[1,8,42.17],[2,7.2,2.03]],"batl":[[0,9.6,3.18]],"ltp":9.0,"tv":296.06,"id":24420205}],"tv":4656.72}]}
{"op":"mcm","clk":"993257072","pt":1580539467355,"mc":[{"id":"1.168130661","rc":[{"batb":[[0,2.8,5.88]],"ltp":2.8,"tv":1777.97,"id":25238892}]}]}
{"op":"mcm","clk":"993257272","pt":1580539472183,"mc":[{"id":"1.168130661","rc":[{"batl":[[0,9.6,9.18],[1,10,2.53],[2,11.5,40]],"ltp":9.0,"tv":296.06,"id":24420205}]}]}
{"op":"mcm","clk":"993257541","pt":1580539477679,"mc":[{"id":"1.168130661","rc":[{"batl":[[0,2.88,1.68],[1,2.9,2],[2,2.94,9.12]],"ltp":2.8,"tv":1777.97,"id":25238892},{"batl":[[0,14,2],[1,16,1.68]],"ltp":11.0,"tv":218.48,"id":420}]}]}
{"op":"mcm","clk":"993257657","pt":1580539480654,"mc":[{"id":"1.168130661","rc":[{"batl":[[1,15.5,2.39],[2,16,1.68]],"ltp":11.0,"tv":218.48,"id":420}]}]}
{"op":"mcm","clk":"993257879","pt":1580539486684,"mc":[{"id":"1.168130661","rc":[{"batb":[[0,13.5,12.02],[1,13,4.7],[2,12.5,2]],"ltp":13.5,"tv":196.06,"id":24707172}]}]}
{"op":"mcm","clk":"993257956","pt":1580539489006,"mc":[{"id":"1.168130661","rc":[{"batl":[[0,9.6,3.18],[1,9.8,6],[2,10,2.53]],"ltp":9.0,"tv":296.06,"id":24420205}]}]}
{"op":"mcm","clk":"993258016","pt":1580539490502,"mc":[{"id":"1.168130661","rc":[{"batl":[[0,15,2]],"ltp":11.0,"tv":218.48,"id":420}]}]}
{"op":"mcm","clk":"993258945","pt":1580539509400,"mc":[{"id":"1.168130661","rc":[{"batl":[[0,2.9,2],[1,2.92,2.4],[2,2.94,8.4]],"ltp":2.8,"tv":1777.97,"id":25238892},{"batl":[[0,14.5,1.68],[1,15,2],[2,15.5,2.39]],"ltp":11.0,"tv":218.48,"id":420}]}]}
{"op":"mcm","clk":"993259304","pt":1580539518313,"mc":[{"id":"1.168130661","rc":[{"batl":[[2,16.5,7.6]],"ltp":11.0,"tv":218.48,"id":420}]}]}
{"op":"mcm","clk":"993260227","pt":1580539540633,"mc":[{"id":"1.168130661","rc":[{"batl":[[1,2.94,9.12],[2,2.96,6.72]],"ltp":2.8,"tv":1777.97,"id":25238892}]}]}
{"op":"mcm","clk":"993260272","pt":1580539541519,"mc":[{"id":"1.168130661","rc":[{"batl":[[0,2.88,1.68],[1,2.9,2],[2,2.94,9.12]],"ltp":2.8,"tv":1777.97,"id":25238892}]}]}
{"op":"mcm","clk":"993260372","pt":1580539544150,"mc":[{"id":"1.168130661","rc":[{"batl":[[0,14,2],[1,14.5,1.68]],"ltp":11.0,"tv":218.48,"id":420}]}]}
{"op":"mcm","clk":"993261168","pt":1580539563466,"mc":[{"id":"1.168130661","rc":[{"batb":[[0,2.8,35.84]],"ltp":2.8,"tv":1777.97,"id":25238892},{"batb":[[0,14,4.52],[1,13.5,12.02],[2,13,4.7]],"ltp":13.5,"tv":196.06,"id":24707172}]}]}
{"op":"mcm","clk":"993261500","pt":1580539571602,"mc":[{"id":"1.168130661","rc":[{"trd":[[32,9.48],[34,3.12],[36,2.44]],"batb":[[0,30,1.79],[1,29,9],[2,28,1.04]],"batl":[[0,32,1.33],[1,48,1.85],[2,50,1.82]],"ltp":32.0,"tv":44.75,"id":25545675},{"batl":[[2,18.5,2.6]],"ltp":11.0,"tv":218.48,"id":420}],"tv":4664.07}]}
{"op":"mcm","clk":"993261615","pt":1580539572534,"mc":[{"id":"1.168130661","rc":[{"batl":[[0,2.9,2],[1,2.92,2.4],[2,2.94,8.4]],"ltp":2.8,"tv":1777.97,"id":25238892},{"batl":[[0,13.5,1.68],[1,14,2]],"ltp":11.0,"tv":218.48,"id":420}]}]}
{"op":"mcm","clk":"993261668","pt":1580539573666,"mc":[{"id":"1.168130661","rc":[{"batb":[[0,30,1.2]],"ltp":32.0,"tv":44.75,"id":25545675}]}]}
{"op":"mcm","clk":"993261790","pt":1580539576353,"mc":[{"id":"1.168130661","rc":[{"trd":[[30,12.55]],"batb":[[0,29,9],[1,28,1.04],[2,27,1.35]],"batl":[[0,48,1.98],[1,50,1.82],[2,75,2]],"ltp":30.0,"tv":47.15,"id":25545675}],"tv":4666.46}]}
{"op":"mcm","clk":"993262022","pt":1580539581670,"mc":[{"id":"1.168130661","rc":[{"batb":[[1,28,1.67]],"ltp":30.0,"tv":47.15,"id":25545675}]}]}
{"op":"mcm","clk":"993262062","pt":1580539582338,"mc":[{"id":"1.168130661","rc":[{"trd":[[29,1.48]],"batb":[[0,29,8.87]],"batl":[[0,48,1.85]],"ltp":29.0,"tv":47.41,"id":25545675},{"batb":[[0,2.8,5.88]],"ltp":2.8,"tv":1777.97,"id":25238892}],"tv":4666.72}]}
{"op":"mcm","clk":"993262381","pt":1580539587665,"mc":[{"id":"1.168130661","rc":[{"batl":[[0,48,2.03]],"ltp":29.0,"tv":47.41,"id":25545675},{"batl":[[1,10,2.53],[2,11.5,40]],"ltp":9.0,"tv":296.06,"id":24420205}]}]}
{"op":"mcm","clk":"993262511","pt":1580539588505,"mc":[{"id":"1.168130661","rc":[{"batl":[[0,2.92,2.4],[1,2.94,8.4],[2,2.96,6.72]],"ltp":2.8,"tv":1777.97,"id":25238892},{"batl":[[0,9.6,9.18]],"ltp":9.0,"tv":296.06,"id":24420205}]}]}
{"op":"mcm","clk":"993262960","pt":1580539596697,"mc":[{"id":"1.168130661","rc":[{"batl":[[0,9.6,3.18],[1,9.8,6],[2,10,2.53]],"ltp":9.0,"tv":296.06,"id":24420205}]}]}
{"op":"mcm","clk":"993262987","pt":1580539597264,"mc":[{"id":"1.168130661","rc":[{"batl":[[1,18,2.29],[2,18.5,2.31]],"ltp":11.0,"tv":218.48,"id":420}]}]}
{"op":"mcm","clk":"993263414","pt":1580539601697,"mc":[{"id":"1.168130661","rc":[{"batb":[[0,13.5,12.02],[1,13,4.7],[2,12.5,2]],"ltp":13.5,"tv":196.06,"id":24707172}]}]}
{"op":"mcm","clk":"993263552","pt":1580539604700,"mc":[{"id":"1.168130661","rc":[{"batl":[[0,17.5,1.97],[1,18,2]],"ltp":11.0,"tv":218.48,"id":420}]}]}
{"op":"mcm","clk":"993263906","pt":1580539611591,"mc":[{"id":"1.168130661","rc":[{"batl":[[0,17.5,2.15]],"ltp":11.0,"tv":218.48,"id":420}]}]}
{"op":"mcm","clk":"993264052","pt":1580539613604,"mc":[{"id":"1.168130661","rc":[{"batl":[[0,17.5,4.27]],"ltp":11.0,"tv":218.48,"id":420}]}]}
{"op":"mcm","clk":"993264575","pt":1580539621895,"mc":[{"id":"1.168130661","rc":[{"batl":[[0,9.6,9.18],[1,10,2.53],[2,11.5,40]],"ltp":9.0,"tv":296.06,"id":24420205}]}]}
{"op":"mcm","clk":"993264666","pt":1580539623698,"mc":[{"id":"1.168130661","rc":[{"batl":[[0,9.4,4.6],[1,9.6,8.57],[2,10,2.53]],"ltp":9.0,"tv":296.06,"id":24420205}]}]}
{"op":"mcm","clk":"993265035","pt":1580539630522,"mc":[{"id":"1.168130661","rc":[{"batl":[[0,9.2,6.6],[1,9.4,4],[2,9.6,2.57]],"ltp":9.0,"tv":296.06,"id":24420205}]}]}
{"op":"mcm","clk":"993265999","pt":1580539650658,"mc":[{"id":"1.168130661","rc":[{"batl":[[2,10,3.1]],"ltp":9.0,"tv":296.06,"id":24420205},{"batl":[[0,17,2.47],[1,17.5,3.8]],"ltp":11.0,"tv":218.48,"id":420}]}]}
{"op":"mcm","clk":"993266057","pt":1580539652388,"mc":[{"id":"1.168130661","rc":[{"batl":[[1,10,3.1],[2,11.5,40]],"ltp":9.0,"tv":296.06,"id":24420205}]}]}
{"op":"mcm","clk":"993266140","pt":1580539653657,"mc":[{"id":"1.168130661","rc":[{"trd":[[9,30.5],[9.2,53.85]],"batb":[[0,9.2,3.4],[1,8.8,6.79],[2,8,42.17]],"batl":[[0,10,3.1],[1,11.5,40],[2,12.5,29.41]],"ltp":9.2,"tv":309.26,"id":24420205},{"batl":[[1,17.5,1.68]],"ltp":11.0,"tv":218.48,"id":420}],"tv":4679.93}]}
{"op":"mcm","clk":"993266529","pt":1580539661076,"mc":[{"id":"1.168130661","rc":[{"batb":[[0,8.8,6.79],[1,8,42.17],[2,7.2,2.03]],"ltp":9.2,"tv":309.26,"id":24420205}]}]}
{"op":"mcm","clk":"993266702","pt":1580539664678,"mc":[{"id":"1.168130661","rc":[{"batl":[[0,16.5,3.18],[1,17,2.29],[2,17.5,1.68]],"ltp":11.0,"tv":218.48,"id":420}]}]}
{"op":"mcm","clk":"993266879","pt":1580539667675,"mc":[{"id":"1.168130661","rc":[{"batl":[[0,10,2.53]],"ltp":9.2,"tv":309.26,"id":24420205},{"batl":[[0,16,1.68],[1,16.5,3.18],[2,17,2.29]],"ltp":11.0,"tv":218.48,"id":420}]}]}
{"op":"mcm","clk":"993266926","pt":1580539668599,"mc":[{"id":"1.168130661","rc":[{"batb":[[2,7.4,7.75]],"batl":[[1,11,5.64],[2,11.5,40]],"ltp":9.2,"tv":309.26,"id":24420205}]}]}
{"op":"mcm","clk":"993267097","pt":1580539671880,"mc":[{"id":"1.168130661","rc":[{"batl":[[0,16,4]],"ltp":11.0,"tv":218.48,"id":420}]}]}
{"op":"mcm","clk":"993267933","pt":1580539688005,"mc":[{"id":"1.168130661","rc":[{"batl":[[1,10.5,6],[2,11,5.64]],"ltp":9.2,"tv":309.26,"id":24420205}]}]}
{"op":"mcm","clk":"993267998","pt":1580539689188,"mc":[{"id":"1.168130661","rc":[{"trd":[[29,19.23]],"batb":[[0,28,1.67],[1,27,1.35],[2,25,2]],"batl":[[0,29,1.21],[1,48,2.03],[2,50,1.82]],"ltp":29.0,"tv":65.16,"id":25545675}],"tv":4697.67}]}
{"op":"mcm","clk":"993268116","pt":1580539691703,"mc":[{"id":"1.168130661","rc":[{"batb":[[0,28,1.04]],"batl":[[1,48,2.2]],"ltp":29.0,"tv":65.16,"id":25545675}]}]}
{"op":"mcm","clk":"993268365","pt":1580539696696,"mc":[{"id":"1.168130661","rc":[{"trd":[[27,0.34],[28,2.08]],"batb":[[0,27,1.18],[1,25,2],[2,19,3.14]],"batl":[[0,48,2.2],[1,50,1.82],[2,75,2]],"ltp":27.0,"tv":67.57,"id":25545675}],"tv":4700.09}]}
{"op":"mcm","clk":"993268413","pt":1580539697719,"mc":[{"id":"1.168130661","rc":[{"batl":[[0,48,2.39]],"ltp":27.0,"tv":67.57,"id":25545675}]}]}
{"op":"mcm","clk":"993268531","pt":1580539700296,"mc":[{"id":"1.168130661","rc":[{"batb":[[2,19,4.07]],"ltp":27.0,"tv":67.57,"id":25545675},{"batb":[[0,9,6.37],[1,8.8,6.79],[2,8,42.17]],"ltp":9.2,"tv":309.26,"id":24420205}]}]}
{"op":"mcm","clk":"993268753","pt":1580539704423,"mc":[{"id":"1.168130661","rc":[{"batl":[[0,15.5,2],[1,16,4],[2,16.5,3.18]],"ltp":11.0,"tv":218.48,"id":420}]}]}
{"op":"mcm","clk":"993269105","pt":1580539712017,"mc":[{"id":"1.168130661","rc":[{"batb":[[0,9,10.57]],"ltp":9.2,"tv":309.26,"id":24420205}]}]}
{"op":"mcm","clk":"993269184","pt":1580539713628,"mc":[{"id":"1.168130661","rc":[{"batb":[[1,25,2.61]],"ltp":27.0,"tv":67.57,"id":25545675},{"batb":[[1,8.8,4.98]],"ltp":9.2,"tv":309.26,"id":24420205}]}]}
{"op":"mcm","clk":"993269225","pt":1580539714308,"mc":[{"id":"1.168130661","rc":[{"batb":[[0,9.2,1.73],[1,9,10.57],[2,8.8,4.98]],"ltp":9.2,"tv":309.26,"id":24420205}]}]}
{"op":"mcm","clk":"993269343","pt":1580539717153,"mc":[{"id":"1.168130661","rc":[{"batb":[[2,19,3.14]],"ltp":27.0,"tv":67.57,"id":25545675}]}]}
{"op":"mcm","clk":"993269936","pt":1580539731365,"mc":[{"id":"1.168130661","rc":[{"batl":[[0,15,1.68],[1,15.5,2],[2,16,2.32]],"ltp":11.0,"tv":218.48,"id":420}]}]}
{"op":"mcm","clk":"993270515","pt":1580539745463,"mc":[{"id":"1.168130661","rc":[{"batb":[[0,14,1.23],[1,13.5,12.02],[2,13,4.7]],"ltp":13.5,"tv":196.06,"id":24707172}]}]}
{"op":"mcm","clk":"993270619","pt":1580539747674,"mc":[{"id":"1.168130661","rc":[{"batl":[[2,16.5,3]],"ltp":11.0,"tv":218.48,"id":420}]}]}
{"op":"mcm","clk":"993271057","pt":1580539757489,"mc":[{"id":"1.168130661","rc":[{"batl":[[1,16,2]],"ltp":11.0,"tv":218.48,"id":420}]}]}
{"op":"mcm","clk":"993271258","pt":1580539761508,"mc":[{"id":"1.168130661","rc":[{"batl":[[0,46,8.14],[1,48,1.85],[2,50,1.82]],"ltp":27.0,"tv":67.57,"id":25545675}]}]}
{"op":"mcm","clk":"993271354","pt":1580539763702,"mc":[{"id":"1.168130661","rc":[{"batl":[[0,15.5,1.68]],"ltp":11.0,"tv":218.48,"id":420}]}]}
{"op":"mcm","clk":"993271388","pt":1580539764525,"mc":[{"id":"1.168130661","rc":[{"batl":[[0,44,1.87],[1,46,7.95],[2,50,2.6]],"ltp":27.0,"tv":67.57,"id":25545675}]}]}
{"op":"mcm","clk":"993271548","pt":1580539766492,"mc":[{"id":"1.168130661","rc":[{"batl":[[0,44,2.72],[2,50,1.82]],"ltp":27.0,"tv":67.57,"id":25545675},{"batl":[[0,15.5,4.07]],"ltp":11.0,"tv":218.48,"id":420}]}]}
{"op":"mcm","clk":"993272429","pt":1580539786601,"mc":[{"id":"1.168130661","rc":[{"batl":[[0,44,2.83]],"ltp":27.0,"tv":67.57,"id":25545675}]}]}
{"op":"mcm","clk":"993273631","pt":1580539811351,"mc":[{"id":"1.168130661","rc":[{"batl":[[0,15,2],[1,15.5,4.07]],"ltp":11.0,"tv":218.48,"id":420}]}]}
{"op":"mcm","clk":"993274340","pt":1580539828672,"mc":[{"id":"1.168130661","rc":[{"batl":[[0,14.5,1.68],[1,15,2],[2,15.5,2.39]],"ltp":11.0,"tv":218.48,"id":420}]}]}
{"op":"mcm","clk":"993274950","pt":1580539842324,"mc":[{"id":"1.168130661","rc":[{"batl":[[2,16.5,3]],"ltp":11.0,"tv":218.48,"id":420}]}]}
{"op":"mcm","clk":"993275353","pt":1580539851027,"mc":[{"id":"1.168130661","rc":[{"batb":[[0,2.78,18.12],[1,2.7,8.79],[2,2.62,3.19]],"ltp":2.8,"tv":1777.97,"id":25238892},{"batb":[[1,9,6.37]],"ltp":9.2,"tv":309.26,"id":24420205},{"batb":[[1,11.5,6.17]],"ltp":11.0,"tv":218.48,"id":420}]}]}
{"op":"mcm","clk":"993275917","pt":1580539864722,"mc":[{"id":"1.168130661","rc":[{"batl":[[0,2.9,2],[1,2.92,2.4],[2,2.94,8.4]],"ltp":2.8,"tv":1777.97,"id":25238892},{"batl":[[0,14,2],[1,14.5,1.68]],"ltp":11.0,"tv":218.48,"id":420}]}]}
{"op":"mcm","clk":"993276117","pt":1580539869360,"mc":[{"id":"1.168130661","rc":[{"batb":[[0,14,5.75]],"ltp":13.5,"tv":196.06,"id":24707172}]}]}
{"op":"mcm","clk":"993277003","pt":1580539891696,"mc":[{"id":"1.168130661","rc":[{"batl":[[0,2.88,1.68],[1,2.9,2],[2,2.94,9.12]],"ltp":2.8,"tv":1777.97,"id":25238892},{"batl":[[0,13.5,1.68],[1,14,2]],"ltp":11.0,"tv":218.48,"id":420}]}]}
{"op":"mcm","clk":"993277392","pt":1580539900605,"mc":[{"id":"1.168130661","rc":[{"batl":[[0,2.88,6.68]],"ltp":2.8,"tv":1777.97,"id":25238892}]}]}
{"op":"mcm","clk":"993277702","pt":1580539907453,"mc":[{"id":"1.168130661","rc":[{"batb":[[0,2.56,26.69]],"ltp":2.5,"tv":2130.72,"id":26314798}]}]}
{"op":"mcm","clk":"993277810","pt":1580539909215,"mc":[{"id":"1.168130661","rc":[{"trd":[[2.84,119.87]],"batl":[[0,2.84,3],[1,2.88,1.68],[2,2.9,2]],"ltp":2.84,"tv":1781.97,"id":25238892}],"tv":4704.09}]}
{"op":"mcm","clk":"993277875","pt":1580539910711,"mc":[{"id":"1.168130661","rc":[{"batb":[[1,26,2.7],[2,25,2]],"ltp":27.0,"tv":67.57,"id":25545675},{"batb":[[0,2.8,19.4],[1,2.78,18.12],[2,2.7,8.79]],"ltp":2.84,"tv":1781.97,"id":25238892},{"batb":[[0,14.5,3.75],[1,14,5.75],[2,13.5,12.02]],"ltp":13.5,"tv":196.06,"id":24707172},{"batb":[[0,9.2,7.63]],"ltp":9.2,"tv":309.26,"id":24420205},{"batb":[[0,2.58,21.06],[1,2.56,26.69],[2,2.5,3.75]],"ltp":2.5,"tv":2130.72,"id":26314798},{"batb":[[0,12,5.96]],"ltp":11.0,"tv":218.48,"id":420}]}]}
{"op":"mcm","clk":"993278182","pt":1580539918156,"mc":[{"id":"1.168130661","rc":[{"batl":[[2,2.94,9.12]],"ltp":2.84,"tv":1781.97,"id":25238892},{"batb":[[0,12,10.96],[1,11.5,4.43],[2,10,13.23]],"batl":[[1,16.5,3],[2,18.5,2.6]],"ltp":11.0,"tv":218.48,"id":420}]}]}
{"op":"mcm","clk":"993278464","pt":1580539923650,"mc":[{"id":"1.168130661","rc":[{"batl":[[0,2.88,3],[1,2.94,9.12],[2,2.96,6.72]],"ltp":2.84,"tv":1781.97,"id":25238892},{"batl":[[0,16.5,3],[1,18.5,2.6],[2,22,11]],"ltp":11.0,"tv":218.48,"id":420}]}]}
{"op":"mcm","clk":"993278595","pt":1580539926331,"mc":[{"id":"1.168130661","rc":[{"batb":[[1,14,1.23]],"ltp":13.5,"tv":196.06,"id":24707172},{"batb":[[1,2.56,9.54]],"ltp":2.5,"tv":2130.72,"id":26314798}]}]}
{"op":"mcm","clk":"993278627","pt":1580539926948,"mc":[{"id":"1.168130661","rc":[{"batb":[[1,26,2.09]],"batl":[[1,46,7.6]],"ltp":27.0,"tv":67.57,"id":25545675}]}]}
{"op":"mcm","clk":"993279427","pt":1580539944370,"mc":[{"id":"1.168130661","rc":[{"trd":[[2.58,42.01]],"batb":[[0,2.56,9.59],[1,2.5,3.75],[2,2.46,10]],"ltp":2.58,"tv":2172.72,"id":26314798}],"tv":4746.1}]}
{"op":"mcm","clk":"993279659","pt":1580539949669,"mc":[{"id":"1.168130661","rc":[{"trd":[[2.56,17.9],[2.58,42.11]],"batb":[[0,2.5,4.34],[1,2.46,10],[2,2.44,44.73]],"ltp":2.56,"tv":2190.72,"id":26314798}],"tv":4764.09}]}
{"op":"mcm","clk":"993289636","pt":1580539952313,"mc":[{"id":"1.168130661","rc":[{"batl":[[2,32,9]],"ltp":11.0,"tv":218.48,"id":420}]}]}
{"op":"mcm","clk":"993289747","pt":1580539955326,"mc":[{"id":"1.168130661","rc":[{"batl":[[0,16,1.87],[1,16.5,3],[2,18.5,2.6]],"ltp":11.0,"tv":218.48,"id":420}]}]}
{"op":"mcm","clk":"993290119","pt":1580539964406,"mc":[{"id":"1.168130661","rc":[{"batb":[[0,2.5,21.9]],"ltp":2.56,"tv":2190.72,"id":26314798}]}]}
{"op":"mcm","clk":"993290160","pt":1580539965535,"mc":[{"id":"1.168130661","rc":[{"batb":[[2,10,4.61]],"ltp":11.0,"tv":218.48,"id":420}]}]}
{"op":"mcm","clk":"993290458","pt":1580539971427,"mc":[{"id":"1.168130661","rc":[{"batl":[[0,2.62,2],[1,2.64,11.05],[2,2.66,6.22]],"ltp":2.56,"tv":2190.72,"id":26314798}]}]}
{"op":"mcm","clk":"993291129","pt":1580539983661,"mc":[{"id":"1.168130661","rc":[{"batb":[[0,2.5,4.34],[1,2.48,17.7],[2,2.46,10]],"ltp":2.56,"tv":2190.72,"id":26314798}]}]}
{"op":"mcm","clk":"993291338","pt":1580539987064,"mc":[{"id":"1.168130661","rc":[{"batl":[[1,50,1.82],[2,75,2]],"ltp":27.0,"tv":67.57,"id":25545675}]}]}
{"op":"mcm","clk":"993292269","pt":1580540004576,"mc":[{"id":"1.168130661","rc":[{"trd":[[2.8,147.22]],"batb":[[0,2.78,18.12],[1,2.7,8.79],[2,2.62,6]],"batl":[[0,2.8,10.6],[1,2.88,3],[2,2.94,9.12]],"ltp":2.8,"tv":1820.77,"id":25238892}],"tv":4802.89}]}
{"op":"mcm","clk":"993292634","pt":1580540010579,"mc":[{"id":"1.168130661","rc":[{"batb":[[0,9.4,1.98],[1,9.2,7.63],[2,9,6.37]],"ltp":9.2,"tv":309.26,"id":24420205}]}]}
{"op":"mcm","clk":"993293069","pt":1580540019596,"mc":[{"id":"1.168130661","rc":[{"batb":[[2,8.8,3]],"batl":[[2,11.5,40.5]],"ltp":9.2,"tv":309.26,"id":24420205}]}]}
{"op":"mcm","clk":"993293107","pt":1580540020317,"mc":[{"id":"1.168130661","rc":[{"batb":[[2,2.52,99]],"ltp":2.8,"tv":1820.77,"id":25238892}]}]}
{"op":"mcm","clk":"993293361","pt":1580540025424,"mc":[{"id":"1.168130661","rc":[{"batl":[[0,15.5,2],[1,16,1.87],[2,16.5,3]],"ltp":11.0,"tv":218.48,"id":420}]}]}
{"op":"mcm","clk":"993293738","pt":1580540033047,"mc":[{"id":"1.168130661","rc":[{"batl":[[0,15.5,4.39]],"ltp":11.0,"tv":218.48,"id":420}]}]}
{"op":"mcm","clk":"993294201","pt":1580540042457,"mc":[{"id":"1.168130661","rc":[{"batb":[[2,2.5,6.75]],"ltp":2.8,"tv":1820.77,"id":25238892}]}]}
{"op":"mcm","clk":"993294405","pt":1580540046580,"mc":[{"id":"1.168130661","rc":[{"batb":[[0,15,1.15],[1,14.5,3.75]],"ltp":13.5,"tv":196.06,"id":24707172}]}]}
{"op":"mcm","clk":"993294675","pt":1580540051693,"mc":[{"id":"1.168130661","rc":[{"batl":[[1,16.5,3],[2,18.5,2.6]],"ltp":11.0,"tv":218.48,"id":420}]}]}
{"op":"mcm","clk":"993294686","pt":1580540051898,"mc":[{"id":"1.168130661","rc":[{"batl":[[0,15,1.68],[1,15.5,4.39],[2,16.5,3]],"ltp":11.0,"tv":218.48,"id":420}]}]}
{"op":"mcm","clk":"993295999","pt":1580540079610,"mc":[{"id":"1.168130661","rc":[{"batl":[[0,14.5,2],[1,15,1.68],[2,15.5,2.39]],"ltp":11.0,"tv":218.48,"id":420}]}]}
{"op":"mcm","clk":"993296190","pt":1580540083627,"mc":[{"id":"1.168130661","rc":[{"batl":[[0,14,1.68],[1,14.5,2]],"ltp":11.0,"tv":218.48,"id":420}]}]}
{"op":"mcm","clk":"993296477","pt":1580540089455,"mc":[{"id":"1.168130661","rc":[{"batl":[[2,16.5,3]],"ltp":11.0,"tv":218.48,"id":420}]}]}
{"op":"mcm","clk":"993296945","pt":1580540098685,"mc":[{"id":"1.168130661","rc":[{"trd":[[2.8,168.41]],"batb":[[0,2.8,19.37],[1,2.78,18.12],[2,2.7,8.79]],"batl":[[0,2.88,3],[1,2.94,9.12],[2,2.96,6.72]],"ltp":2.8,"tv":1841.96,"id":25238892}],"tv":4824.09}]}
{"op":"mcm","clk":"993297173","pt":1580540103176,"mc":[{"id":"1.168130661","rc":[{"batb":[[2,10,13.23]],"ltp":11.0,"tv":218.48,"id":420}]}]}
{"op":"mcm","clk":"993297836","pt":1580540116622,"mc":[{"id":"1.168130661","rc":[{"batl":[[0,14.5,2],[1,16,1.68]],"ltp":11.0,"tv":218.48,"id":420}]}]}
{"op":"mcm","clk":"993297882","pt":1580540117400,"mc":[{"id":"1.168130661","rc":[{"batb":[[0,2.78,18.12],[1,2.7,8.79],[2,2.62,6]],"ltp":2.8,"tv":1841.96,"id":25238892}]}]}
{"op":"mcm","clk":"993298157","pt":1580540122511,"mc":[{"id":"1.168130661","rc":[{"batb":[[2,10,4.61]],"ltp":11.0,"tv":218.48,"id":420}]}]}
{"op":"mcm","clk":"993298456","pt":1580540128140,"mc":[{"id":"1.168130661","rc":[{"batl":[[1,15.5,2.39],[2,16,1.68]],"ltp":11.0,"tv":218.48,"id":420}]}]}
{"op":"mcm","clk":"993298861","pt":1580540135039,"mc":[{"id":"1.168130661","rc":[{"batb":[[2,2.52,99]],"ltp":2.8,"tv":1841.96,"id":25238892}]}]}
{"op":"mcm","clk":"993299231","pt":1580540142248,"mc":[{"id":"1.168130661","rc":[{"batb":[[0,2.8,3],[1,2.78,18.12],[2,2.7,8.79]],"ltp":2.8,"tv":1841.96,"id":25238892}]}]}
{"op":"mcm","clk":"993299437","pt":1580540146163,"mc":[{"id":"1.168130661","rc":[{"batb":[[2,10,13.23]],"ltp":11.0,"tv":218.48,"id":420}]}]}
{"op":"mcm","clk":"993299565","pt":1580540148476,"mc":[{"id":"1.168130661","rc":[{"trd":[[2.78,280.02],[2.8,174.41]],"batb":[[0,2.78,1.12],[1,2.7,8.79],[2,2.54,5.39]],"batl":[[0,2.86,10.73],[1,2.88,3],[2,2.94,9.12]],"ltp":2.78,"tv":1881.96,"id":25238892},{"batb":[[0,12.5,1.6],[1,12,10.96],[2,11.5,4.43]],"batl":[[0,14,1.68],[1,14.5,2],[2,15.5,2.39]],"ltp":11.0,"tv":218.48,"id":420}],"tv":4864.08}]}
{"op":"mcm","clk":"993299675","pt":1580540150584,"mc":[{"id":"1.168130661","rc":[{"batb":[[2,2.52,99]],"ltp":2.78,"tv":1881.96,"id":25238892}]}]}
{"op":"mcm","clk":"993299867","pt":1580540154299,"mc":[{"id":"1.168130661","rc":[{"batb":[[0,2.72,1.12]],"ltp":2.78,"tv":1881.96,"id":25238892}]}]}
{"op":"mcm","clk":"993299919","pt":1580540155384,"mc":[{"id":"1.168130661","rc":[{"batb":[[0,2.72,21.05]],"ltp":2.78,"tv":1881.96,"id":25238892},{"batl":[[1,15,2]],"ltp":11.0,"tv":218.48,"id":420}]}]}
{"op":"mcm","clk":"993299945","pt":1580540155902,"mc":[{"id":"1.168130661","rc":[{"batb":[[2,2.54,6]],"ltp":2.78,"tv":1881.96,"id":25238892}]}]}
{"op":"mcm","clk":"993300454","pt":1580540166175,"mc":[{"id":"1.168130661","rc":[{"batl":[[2,16.5,3]],"ltp":11.0,"tv":218.48,"id":420}]}]}
{"op":"mcm","clk":"993300544","pt":1580540168186,"mc":[{"id":"1.168130661","rc":[{"batb":[[2,2.5,6.75]],"ltp":2.78,"tv":1881.96,"id":25238892}]}]}
{"op":"mcm","clk":"993300692","pt":1580540171339,"mc":[{"id":"1.168130661","rc":[{"batl":[[0,2.84,2.96],[1,2.86,10.73],[2,2.88,3]],"ltp":2.78,"tv":1881.96,"id":25238892}]}]}
{"op":"mcm","clk":"993300981","pt":1580540176614,"mc":[{"id":"1.168130661","rc":[{"batb":[[0,27,3.16]],"ltp":27.0,"tv":67.57,"id":25545675},{"batb":[[0,12.5,3.58]],"ltp":11.0,"tv":218.48,"id":420}]}]}
{"op":"mcm","clk":"993301028","pt":1580540177440,"mc":[{"id":"1.168130661","rc":[{"batb":[[0,2.72,1.12]],"ltp":2.78,"tv":1881.96,"id":25238892}]}]}
{"op":"mcm","clk":"993301183","pt":1580540180037,"mc":[{"id":"1.168130661","rc":[{"batb":[[2,2.52,4.17]],"batl":[[0,2.82,3.72],[1,2.84,2.96],[2,2.86,10.73]],"ltp":2.78,"tv":1881.96,"id":25238892},{"batl":[[0,15,2],[1,16.5,3],[2,18,14.29]],"ltp":11.0,"tv":218.48,"id":420}]}]}
{"op":"mcm","clk":"993301579","pt":1580540187371,"mc":[{"id":"1.168130661","rc":[{"trd":[[12.5,7.16]],"batb":[[0,12,10.96],[1,11.5,4.43],[2,10,4.61]],"ltp":12.5,"tv":225.64,"id":420}],"tv":4871.25}]}
{"op":"mcm","clk":"993301952","pt":1580540193666,"mc":[{"id":"1.168130661","rc":[{"batl":[[2,18.5,2.6]],"ltp":12.5,"tv":225.64,"id":420}]}]}
{"op":"mcm","clk":"993302839","pt":1580540211685,"mc":[{"id":"1.168130661","rc":[{"batb":[[0,2.72,4.64],[2,2.5,6.75]],"ltp":2.78,"tv":1881.96,"id":25238892},{"batl":[[0,14.5,2.07],[1,15,2],[2,16.5,3]],"ltp":12.5,"tv":225.64,"id":420}]}]}
{"op":"mcm","clk":"993304041","pt":1580540232422,"mc":[{"id":"1.168130661","rc":[{"batl":[[0,14,2],[1,14.5,2.07]],"ltp":12.5,"tv":225.64,"id":420}]}]}
{"op":"mcm","clk":"993304085","pt":1580540233347,"mc":[{"id":"1.168130661","rc":[{"batb":[[0,2.72,24.57]],"ltp":2.78,"tv":1881.96,"id":25238892}]}]}
{"op":"mcm","clk":"993305168","pt":1580540254557,"mc":[{"id":"1.168130661","rc":[{"batb":[[0,2.72,4.64]],"ltp":2.78,"tv":1881.96,"id":25238892}]}]}
{"op":"mcm","clk":"993306029","pt":1580540273392,"mc":[{"id":"1.168130661","rc":[{"batb":[[0,2.72,24.57]],"ltp":2.78,"tv":1881.96,"id":25238892}]}]}
{"op":"mcm","clk":"993306326","pt":1580540280236,"mc":[{"id":"1.168130661","rc":[{"batb":[[0,2.74,6.28],[1,2.72,24.57],[2,2.7,8.79]],"batl":[[2,2.88,3]],"ltp":2.78,"tv":1881.96,"id":25238892}]}]}
{"op":"mcm","clk":"993306769","pt":1580540291241,"mc":[{"id":"1.168130661","rc":[{"batb":[[0,2.74,7.4],[1,2.72,23.46]],"ltp":2.78,"tv":1881.96,"id":25238892}]}]}
{"op":"mcm","clk":"993306813","pt":1580540292428,"mc":[{"id":"1.168130661","rc":[{"batb":[[0,2.74,27.19],[1,2.72,3.52]],"ltp":2.78,"tv":1881.96,"id":25238892}]}]}
{"op":"mcm","clk":"993307397","pt":1580540306642,"mc":[{"id":"1.168130661","rc":[{"batl":[[0,2.84,2.96],[1,2.86,1.68]],"ltp":2.78,"tv":1881.96,"id":25238892}]}]}
{"op":"mcm","clk":"993307747","pt":1580540314662,"mc":[{"id":"1.168130661","rc":[{"batl":[[0,2.86,4.62],[1,2.88,3],[2,2.94,9.12]],"ltp":2.78,"tv":1881.96,"id":25238892}]}]}
{"op":"mcm","clk":"993308674","pt":1580540337709,"mc":[{"id":"1.168130661","rc":[{"batb":[[1,2.7,8.79],[2,2.62,6]],"ltp":2.78,"tv":1881.96,"id":25238892}]}]}
{"op":"mcm","clk":"993308680","pt":1580540337915,"mc":[{"id":"1.168130661","rc":[{"batb":[[0,2.76,3.47],[1,2.74,27.19],[2,2.7,8.79]],"ltp":2.78,"tv":1881.96,"id":25238892}]}]}
{"op":"mcm","clk":"993309253","pt":1580540349452,"mc":[{"id":"1.168130661","rc":[{"batb":[[0,2.76,23.12],[1,2.74,7.4]],"ltp":2.78,"tv":1881.96,"id":25238892}]}]}
{"op":"mcm","clk":"993311046","pt":1580540386683,"mc":[{"id":"1.168130661","rc":[{"batl":[[0,10,7.53]],"ltp":9.2,"tv":309.26,"id":24420205}]}]}
{"op":"mcm","clk":"993311837","pt":1580540401633,"mc":[{"id":"1.168130661","rc":[{"batl":[[2,11.5,40]],"ltp":9.2,"tv":309.26,"id":24420205}]}]}
{"op":"mcm","clk":"993311934","pt":1580540402414,"mc":[{"id":"1.168130661","rc":[{"batl":[[0,10,8.09]],"ltp":9.2,"tv":309.26,"id":24420205}]}]}
{"op":"mcm","clk":"993313823","pt":1580540427480,"mc":[{"id":"1.168130661","rc":[{"trd":[[9.4,34.77]],"batb":[[0,9.4,2.85]],"ltp":9.4,"tv":314.3,"id":24420205}],"tv":4876.29}]}
{"op":"mcm","clk":"993315913","pt":1580540464340,"mc":[{"id":"1.168130661","rc":[{"batb":[[0,2.78,6.19],[1,2.76,23.12],[2,2.74,1.12]],"ltp":2.78,"tv":1881.96,"id":25238892}]}]}
{"op":"mcm","clk":"993316882","pt":1580540483463,"mc":[{"id":"1.168130661","rc":[{"batb":[[0,2.78,25.7],[1,2.76,3.47]],"ltp":2.78,"tv":1881.96,"id":25238892}]}]}
{"op":"mcm","clk":"993323421","pt":1580540627392,"mc":[{"id":"1.168130661","rc":[{"trd":[[2.78,331.44]],"batb":[[0,2.76,3.47],[1,2.74,1.12],[2,2.7,8.79]],"batl":[[0,2.78,9.28],[1,2.86,4.62],[2,2.88,3]],"ltp":2.78,"tv":1933.38,"id":25238892}],"tv":4927.71}]}
{"op":"mcm","clk":"993323470","pt":1580540628473,"mc":[{"id":"1.168130661","rc":[{"batb":[[0,2.52,7.42],[1,2.5,3.75],[2,2.48,17.7]],"ltp":2.56,"tv":2190.72,"id":26314798}]}]}
{"op":"mcm","clk":"993323688","pt":1580540634505,"mc":[{"id":"1.168130661","rc":[{"trd":[[15,57.1]],"batb":[[0,14.5,3.75],[1,13.5,12.02],[2,13,4.7]],"batl":[[0,15.5,6.91]],"ltp":15.0,"tv":198.37,"id":24707172},{"batl":[[0,2.64,11.05],[1,2.66,6.22],[2,2.7,5]],"ltp":2.56,"tv":2190.72,"id":26314798}],"tv":4930.01}]}
{"op":"mcm","clk":"993323794","pt":1580540636621,"mc":[{"id":"1.168130661","rc":[{"batb":[[0,27,7.87]],"ltp":27.0,"tv":67.57,"id":25545675},{"batb":[[0,2.76,49.35]],"ltp":2.78,"tv":1933.38,"id":25238892},{"batb":[[0,2.52,75.09],[2,2.46,10]],"batl":[[0,2.66,6.22],[1,2.7,5],[2,2.72,6]],"ltp":2.56,"tv":2190.72,"id":26314798},{"batb":[[0,12.5,10.6],[1,12,10.96],[2,11.5,4.43]],"ltp":12.5,"tv":225.64,"id":420}]}]}
{"op":"mcm","clk":"993323844","pt":1580540637706,"mc":[{"id":"1.168130661","rc":[{"batb":[[0,27,8.48]],"ltp":27.0,"tv":67.57,"id":25545675},{"batb":[[0,9.4,4.68]],"ltp":9.4,"tv":314.3,"id":24420205}]}]}
{"op":"mcm","clk":"993324138","pt":1580540644505,"mc":[{"id":"1.168130661","rc":[{"batl":[[0,2.86,4.62],[1,2.88,3],[2,2.94,9.12]],"ltp":2.78,"tv":1933.38,"id":25238892}]}]}
{"op":"mcm","clk":"993324417","pt":1580540651400,"mc":[{"id":"1.168130661","rc":[{"batb":[[1,26,2.77]],"ltp":27.0,"tv":67.57,"id":25545675}]}]}
{"op":"mcm","clk":"993324583","pt":1580540655721,"mc":[{"id":"1.168130661","rc":[{"batb":[[0,2.76,3.47],[2,2.72,46.55]],"ltp":2.78,"tv":1933.38,"id":25238892},{"batl":[[1,16.5,3],[2,18.5,2.6]],"ltp":12.5,"tv":225.64,"id":420}]}]}
{"op":"mcm","clk":"993324594","pt":1580540655928,"mc":[{"id":"1.168130661","rc":[{"batl":[[1,18,1.76],[2,21,14.12]],"ltp":15.0,"tv":198.37,"id":24707172}]}]}
{"op":"mcm","clk":"993325038","pt":1580540665620,"mc":[{"id":"1.168130661","rc":[{"trd":[[2.76,280.95]],"batb":[[0,2.74,1.12],[1,2.72,46.55],[2,2.7,8.79]],"batl":[[0,2.76,5.81],[1,2.86,4.62],[2,2.88,3]],"ltp":2.76,"tv":1940.32,"id":25238892}],"tv":4936.95}]}
{"op":"mcm","clk":"993325381","pt":1580540674355,"mc":[{"id":"1.168130661","rc":[{"batb":[[1,2.7,8.79],[2,2.62,6]],"ltp":2.76,"tv":1940.32,"id":25238892}]}]}
{"op":"mcm","clk":"993325880","pt":1580540687655,"mc":[{"id":"1.168130661","rc":[{"batl":[[0,16.5,3],[1,18.5,2.6],[2,22,11]],"ltp":12.5,"tv":225.64,"id":420}]}]}
{"op":"mcm","clk":"993325890","pt":1580540687860,"mc":[{"id":"1.168130661","rc":[{"batl":[[0,16,2],[1,16.5,3],[2,18.5,2.6]],"ltp":12.5,"tv":225.64,"id":420}]}]}
{"op":"mcm","clk":"993325970","pt":1580540690471,"mc":[{"id":"1.168130661","rc":[{"batb":[[0,2.72,1.12]],"ltp":2.76,"tv":1940.32,"id":25238892}]}]}
{"op":"mcm","clk":"993326467","pt":1580540700675,"mc":[{"id":"1.168130661","rc":[{"batl":[[0,2.86,4.62],[1,2.88,3],[2,2.94,9.12]],"ltp":2.76,"tv":1940.32,"id":25238892}]}]}
{"op":"mcm","clk":"993326809","pt":1580540707467,"mc":[{"id":"1.168130661","rc":[{"batb":[[0,2.56,3.75],[1,2.52,75.09]],"ltp":2.56,"tv":2190.72,"id":26314798}]}]}
{"op":"mcm","clk":"993326861","pt":1580540708597,"mc":[{"id":"1.168130661","rc":[{"batb":[[2,2.52,99]],"ltp":2.76,"tv":1940.32,"id":25238892},{"batb":[[1,2.54,6],[2,2.52,75.09]],"ltp":2.56,"tv":2190.72,"id":26314798}]}]}
{"op":"mcm","clk":"993326901","pt":1580540709316,"mc":[{"id":"1.168130661","rc":[{"batb":[[2,2.54,6]],"ltp":2.76,"tv":1940.32,"id":25238892}]}]}
{"op":"mcm","clk":"993327055","pt":1580540712492,"mc":[{"id":"1.168130661","rc":[{"batb":[[2,2.52,7.42]],"ltp":2.56,"tv":2190.72,"id":26314798}]}]}
{"op":"mcm","clk":"993327371","pt":1580540719895,"mc":[{"id":"1.168130661","rc":[{"batb":[[1,2.52,7.42],[2,2.46,10]],"ltp":2.56,"tv":2190.72,"id":26314798}]}]}
{"op":"mcm","clk":"993327847","pt":1580540732422,"mc":[{"id":"1.168130661","rc":[{"batl":[[0,15.5,2.71],[1,16,2],[2,16.5,3]],"ltp":12.5,"tv":225.64,"id":420}]}]}
{"op":"mcm","clk":"993328212","pt":1580540742432,"mc":[{"id":"1.168130661","rc":[{"batb":[[2,2.5,6.75]],"batl":[[0,2.84,2],[1,2.86,4.62],[2,2.88,3]],"ltp":2.76,"tv":1940.32,"id":25238892},{"batl":[[0,15,2],[1,15.5,2.71]],"ltp":12.5,"tv":225.64,"id":420}]}]}
{"op":"mcm","clk":"993328545","pt":1580540750429,"mc":[{"id":"1.168130661","rc":[{"batl":[[0,2.8,1.18],[1,2.84,2],[2,2.86,4.62]],"ltp":2.76,"tv":1940.32,"id":25238892}]}]}
{"op":"mcm","clk":"993328752","pt":1580540755658,"mc":[{"id":"1.168130661","rc":[{"batl":[[0,2.76,1.18]],"ltp":2.76,"tv":1940.32,"id":25238892}]}]}
{"op":"mcm","clk":"993328877","pt":1580540758226,"mc":[{"id":"1.168130661","rc":[{"batl":[[0,2.74,1.18]],"ltp":2.76,"tv":1940.32,"id":25238892}]}]}
{"op":"mcm","clk":"993329104","pt":1580540762362,"mc":[{"id":"1.168130661","rc":[{"batl":[[2,2.86,1.68]],"ltp":2.76,"tv":1940.32,"id":25238892}]}]}
{"op":"mcm","clk":"993329292","pt":1580540766273,"mc":[{"id":"1.168130661","rc":[{"batl":[[0,2.76,1.18]],"ltp":2.76,"tv":1940.32,"id":25238892},{"batb":[[2,2.48,30]],"ltp":2.56,"tv":2190.72,"id":26314798}]}]}
{"op":"mcm","clk":"993330569","pt":1580540795195,"mc":[{"id":"1.168130661","rc":[{"batb":[[0,13,1.33],[1,12.5,10.6],[2,12,9.53]],"ltp":12.5,"tv":225.64,"id":420}]}]}
{"op":"mcm","clk":"993332373","pt":1580540841694,"mc":[{"id":"1.168130661","rc":[{"trd":[[2.7,80.04],[2.72,66.79]],"batb":[[0,2.5,6.75],[1,2.48,114.63],[2,2.44,7.73]],"batl":[[0,2.7,60.09],[1,2.76,1.18],[2,2.84,2]],"ltp":2.7,"tv":1960.13,"id":25238892}],"tv":4956.77}]}
{"op":"mcm","clk":"993332413","pt":1580540842717,"mc":[{"id":"1.168130661","rc":[{"batb":[[0,27,8.66]],"ltp":27.0,"tv":67.57,"id":25545675},{"batb":[[0,2.5,15.33]],"ltp":2.7,"tv":1960.13,"id":25238892}]}]}
{"op":"mcm","clk":"993332425","pt":1580540843127,"mc":[{"id":"1.168130661","rc":[{"batb":[[1,2.48,111]],"ltp":2.7,"tv":1960.13,"id":25238892}]}]}
{"op":"mcm","clk":"993332545","pt":1580540846306,"mc":[{"id":"1.168130661","rc":[{"batb":[[0,2.52,50.25],[1,2.5,15.33],[2,2.48,111]],"ltp":2.7,"tv":1960.13,"id":25238892},{"batb":[[0,2.56,70.37]],"ltp":2.56,"tv":2190.72,"id":26314798}]}]}
{"op":"mcm","clk":"993332628","pt":1580540848411,"mc":[{"id":"1.168130661","rc":[{"trd":[[9.8,28.69],[10,96.26]],"batl":[[0,10,3.09]],"ltp":10.0,"tv":324.3,"id":24420205}],"tv":4966.76}]}
{"op":"mcm","clk":"993332713","pt":1580540850623,"mc":[{"id":"1.168130661","rc":[{"batl":[[2,2.86,1.68]],"ltp":2.7,"tv":1960.13,"id":25238892}]}]}
{"op":"mcm","clk":"993332724","pt":1580540850930,"mc":[{"id":"1.168130661","rc":[{"batl":[[0,2.68,2],[1,2.7,60.09],[2,2.76,1.18]],"ltp":2.7,"tv":1960.13,"id":25238892}]}]}
{"op":"mcm","clk":"993342683","pt":1580540854944,"mc":[{"id":"1.168130661","rc":[{"batb":[[0,2.58,6.68],[1,2.56,70.37],[2,2.48,30.59]],"ltp":2.56,"tv":2190.72,"id":26314798}]}]}
{"op":"mcm","clk":"993343051","pt":1580540865653,"mc":[{"id":"1.168130661","rc":[{"batb":[[0,2.54,49.86],[1,2.52,14.17],[2,2.5,15.33]],"ltp":2.7,"tv":1960.13,"id":25238892},{"batb":[[0,2.58,73.37],[1,2.56,3.75],[2,2.48,30]],"ltp":2.56,"tv":2190.72,"id":26314798}]}]}
{"op":"mcm","clk":"993344419","pt":1580540895600,"mc":[{"id":"1.168130661","rc":[{"batb":[[0,2.54,64.02],[1,2.5,15.33],[2,2.48,111]],"ltp":2.7,"tv":1960.13,"id":25238892}]}]}
{"op":"mcm","clk":"993344697","pt":1580540902696,"mc":[{"id":"1.168130661","rc":[{"trd":[[2.54,130.93]],"batb":[[0,2.54,3.98]],"batl":[[1,2.76,1.18],[2,2.86,88.68]],"ltp":2.54,"tv":2080.26,"id":25238892}],"tv":5086.89}]}
{"op":"mcm","clk":"993344796","pt":1580540904700,"mc":[{"id":"1.168130661","rc":[{"batl":[[0,2.76,1.18],[1,2.84,2]],"ltp":2.54,"tv":2080.26,"id":25238892}]}]}
{"op":"mcm","clk":"993344845","pt":1580540905623,"mc":[{"id":"1.168130661","rc":[{"batb":[[0,27,10.54]],"ltp":27.0,"tv":67.57,"id":25545675},{"batb":[[0,2.54,23.92]],"ltp":2.54,"tv":2080.26,"id":25238892},{"batb":[[0,14.5,7.24]],"ltp":15.0,"tv":198.37,"id":24707172},{"batb":[[0,9.4,10.07]],"ltp":10.0,"tv":324.3,"id":24420205},{"batb":[[0,2.58,93]],"ltp":2.56,"tv":2190.72,"id":26314798},{"batb":[[0,13,5.22]],"ltp":12.5,"tv":225.64,"id":420}]}]}
{"op":"mcm","clk":"993344888","pt":1580540906496,"mc":[{"id":"1.168130661","rc":[{"batl":[[0,2.76,1.38]],"ltp":2.54,"tv":2080.26,"id":25238892}]}]}
{"op":"mcm","clk":"993345266","pt":1580540914419,"mc":[{"id":"1.168130661","rc":[{"batl":[[2,2.86,1.68]],"ltp":2.54,"tv":2080.26,"id":25238892}]}]}
{"op":"mcm","clk":"993345362","pt":1580540916681,"mc":[{"id":"1.168130661","rc":[{"batb":[[0,13,10.22],[2,12,4.53]],"ltp":12.5,"tv":225.64,"id":420}]}]}
{"op":"mcm","clk":"993345614","pt":1580540922699,"mc":[{"id":"1.168130661","rc":[{"batb":[[0,28,5.33],[1,27,5.04],[2,26,2.09]],"ltp":27.0,"tv":67.57,"id":25545675},{"batb":[[0,2.6,65.59],[1,2.58,26.9],[2,2.56,3.75]],"ltp":2.56,"tv":2190.72,"id":26314798},{"batb":[[0,13.5,9.81],[1,13,10.22]],"ltp":12.5,"tv":225.64,"id":420}]}]}
{"op":"mcm","clk":"993345641","pt":1580540923319,"mc":[{"id":"1.168130661","rc":[{"batl":[[1,2.82,5.64],[2,2.84,2]],"ltp":2.54,"tv":2080.26,"id":25238892}]}]}
{"op":"mcm","clk":"993345697","pt":1580540924602,"mc":[{"id":"1.168130661","rc":[{"batb":[[0,29,1.98],[1,28,5.33],[2,27,3.05]],"ltp":27.0,"tv":67.57,"id":25545675},{"batb":[[0,2.6,66.18],[1,2.58,26.31]],"ltp":2.56,"tv":2190.72,"id":26314798}]}]}
{"op":"mcm","clk":"993345998","pt":1580540931021,"mc":[{"id":"1.168130661","rc":[{"batb":[[2,27,3.71]],"ltp":27.0,"tv":67.57,"id":25545675}]}]}
{"op":"mcm","clk":"993347232","pt":1580540958658,"mc":[{"id":"1.168130661","rc":[{"batl":[[1,2.8,2],[2,2.82,5.64]],"ltp":2.54,"tv":2080.26,"id":25238892},{"batl":[[0,15.5,2.71],[1,16.5,3],[2,18.5,2.6]],"ltp":12.5,"tv":225.64,"id":420}]}]}
{"op":"mcm","clk":"993347633","pt":1580540969697,"mc":[{"id":"1.168130661","rc":[{"batl":[[0,2.74,7.6],[1,2.76,1.18],[2,2.8,2]],"ltp":2.54,"tv":2080.26,"id":25238892}]}]}
{"op":"mcm","clk":"993347638","pt":1580540969801,"mc":[{"id":"1.168130661","rc":[{"batl":[[0,2.74,7.8]],"ltp":2.54,"tv":2080.26,"id":25238892}]}]}
{"op":"mcm","clk":"993347849","pt":1580540975400,"mc":[{"id":"1.168130661","rc":[{"trd":[[2.54,136.93]],"batb":[[0,2.54,20.92]],"ltp":2.54,"tv":2086.26,"id":25238892}],"tv":5092.89}]}
{"op":"mcm","clk":"993347899","pt":1580540976583,"mc":[{"id":"1.168130661","rc":[{"batb":[[0,2.54,47.37]],"ltp":2.54,"tv":2086.26,"id":25238892},{"batb":[[0,2.6,92.01]],"ltp":2.56,"tv":2190.72,"id":26314798}]}]}
{"op":"mcm","clk":"993347917","pt":1580540977097,"mc":[{"id":"1.168130661","rc":[{"batb":[[0,29,4.3]],"ltp":27.0,"tv":67.57,"id":25545675},{"trd":[[15,58.31]],"batb":[[0,15,3.87],[1,14.5,7.24],[2,13.5,12.02]],"batl":[[0,15.5,6.3]],"ltp":15.0,"tv":199.58,"id":24707172},{"batb":[[0,9.6,7],[1,9.4,10.07],[2,9.2,7.63]],"ltp":10.0,"tv":324.3,"id":24420205},{"batb":[[0,14,4.8],[1,13.5,9.81],[2,13,10.22]],"ltp":12.5,"tv":225.64,"id":420}],"tv":5094.1}]}
{"op":"mcm","clk":"993348017","pt":1580540979722,"mc":[{"id":"1.168130661","rc":[{"batb":[[2,27,8.71]],"ltp":27.0,"tv":67.57,"id":25545675}]}]}
{"op":"mcm","clk":"993348059","pt":1580540980501,"mc":[{"id":"1.168130661","rc":[{"batb":[[0,29,8.68],[1,27,9.5],[2,26,2.09]],"ltp":27.0,"tv":67.57,"id":25545675},{"batb":[[0,15,16.53]],"ltp":15.0,"tv":199.58,"id":24707172},{"batb":[[0,2.6,26.42]],"ltp":2.56,"tv":2190.72,"id":26314798},{"batb":[[1,13,10.22],[2,12,4.53]],"ltp":12.5,"tv":225.64,"id":420}]}]}
{"op":"mcm","clk":"993348589","pt":1580540991625,"mc":[{"id":"1.168130661","rc":[{"batb":[[0,2.62,3.75],[1,2.6,26.42],[2,2.58,26.31]],"ltp":2.56,"tv":2190.72,"id":26314798}]}]}
{"op":"mcm","clk":"993348919","pt":1580540998633,"mc":[{"id":"1.168130661","rc":[{"trd":[[2.66,87.65]],"batl":[[0,2.7,15.87],[1,2.72,6],[2,2.74,84.92]],"ltp":2.66,"tv":2203.18,"id":26314798}],"tv":5106.56}]}
{"op":"mcm","clk":"993348972","pt":1580540999616,"mc":[{"id":"1.168130661","rc":[{"batb":[[0,2.62,68.84]],"ltp":2.66,"tv":2203.18,"id":26314798}]}]}
{"op":"mcm","clk":"993349302","pt":1580541006413,"mc":[{"id":"1.168130661","rc":[{"batb":[[0,2.64,3.75],[1,2.62,65.09],[2,2.6,26.42]],"batl":[[0,2.68,5],[1,2.7,10.87],[2,2.72,6]],"ltp":2.66,"tv":2203.18,"id":26314798}]}]}
{"op":"mcm","clk":"993349665","pt":1580541013642,"mc":[{"id":"1.168130661","rc":[{"batl":[[2,2.82,5.64]],"ltp":2.54,"tv":2086.26,"id":25238892}]}]}
{"op":"mcm","clk":"993349714","pt":1580541014720,"mc":[{"id":"1.168130661","rc":[{"batl":[[0,2.72,2.2],[1,2.74,7.6],[2,2.76,1.18]],"ltp":2.54,"tv":2086.26,"id":25238892}]}]}
{"op":"mcm","clk":"993349827","pt":1580541017652,"mc":[{"id":"1.168130661","rc":[{"batb":[[0,2.6,2],[1,2.54,47.37],[2,2.5,15.33]],"ltp":2.54,"tv":2086.26,"id":25238892}]}]}
{"op":"mcm","clk":"993349871","pt":1580541018628,"mc":[{"id":"1.168130661","rc":[{"batl":[[0,2.7,11.21],[1,2.72,2.2],[2,2.74,7.6]],"ltp":2.54,"tv":2086.26,"id":25238892},{"batb":[[1,2.6,26.42],[2,2.58,26.31]],"ltp":2.66,"tv":2203.18,"id":26314798}]}]}
{"op":"mcm","clk":"993350014","pt":1580541021662,"mc":[{"id":"1.168130661","rc":[{"batl":[[1,2.72,2]],"ltp":2.54,"tv":2086.26,"id":25238892}]}]}
{"op":"mcm","clk":"993351555","pt":1580541055618,"mc":[{"id":"1.168130661","rc":[{"trd":[[2.64,195.63]],"batb":[[0,2.6,26.42],[1,2.58,26.31],[2,2.5,6]],"ltp":2.64,"tv":2210.68,"id":26314798}],"tv":5114.06}]}
{"op":"mcm","clk":"993351598","pt":1580541056391,"mc":[{"id":"1.168130661","rc":[{"batb":[[0,2.62,65.09],[1,2.6,26.42],[2,2.58,26.31]],"ltp":2.64,"tv":2210.68,"id":26314798}]}]}
{"op":"mcm","clk":"993352009","pt":1580541065631,"mc":[{"id":"1.168130661","rc":[{"batb":[[1,27,8.89]],"ltp":27.0,"tv":67.57,"id":25545675}]}]}
{"op":"mcm","clk":"993352029","pt":1580541066046,"mc":[{"id":"1.168130661","rc":[{"batb":[[0,29,9.25]],"ltp":27.0,"tv":67.57,"id":25545675}]}]}
{"op":"mcm","clk":"993352156","pt":1580541068837,"mc":[{"id":"1.168130661","rc":[{"batl":[[0,44,2.64]],"ltp":27.0,"tv":67.57,"id":25545675}]}]}
{"op":"mcm","clk":"993352397","pt":1580541075438,"mc":[{"id":"1.168130661","rc":[{"batb":[[0,30,4.81],[1,29,4.3],[2,27,8.89]],"ltp":27.0,"tv":67.57,"id":25545675}]}]}
{"op":"mcm","clk":"993352613","pt":1580541080632,"mc":[{"id":"1.168130661","rc":[{"batb":[[0,2.62,12],[1,2.6,2],[2,2.54,47.37]],"ltp":2.54,"tv":2086.26,"id":25238892},{"batb":[[0,2.62,77.09]],"ltp":2.64,"tv":2210.68,"id":26314798}]}]}
{"op":"mcm","clk":"993353228","pt":1580541094663,"mc":[{"id":"1.168130661","rc":[{"batb":[[0,2.62,12]],"ltp":2.64,"tv":2210.68,"id":26314798}]}]}
{"op":"mcm","clk":"993354415","pt":1580541122318,"mc":[{"id":"1.168130661","rc":[{"batl":[[1,2.74,7.6],[2,2.76,1.18]],"ltp":2.54,"tv":2086.26,"id":25238892}]}]}
{"op":"mcm","clk":"993354598","pt":1580541126717,"mc":[{"id":"1.168130661","rc":[{"batb":[[0,9.8,1.76],[1,9.6,7],[2,9.4,8.24]],"ltp":10.0,"tv":324.3,"id":24420205},{"batb":[[0,14.5,1.18],[1,14,4.8],[2,13,8.9]],"ltp":12.5,"tv":225.64,"id":420}]}]}
{"op":"mcm","clk":"993355540","pt":1580541147670,"mc":[{"id":"1.168130661","rc":[{"trd":[[15,65]],"batb":[[0,15,13.19]],"ltp":15.0,"tv":206.27,"id":24707172},{"trd":[[14,9.59],[14.5,2.37]],"batb":[[0,13,8.9],[1,12,4.53],[2,11.5,4.43]],"ltp":14.0,"tv":237.61,"id":420}],"tv":5132.71}]}
{"op":"mcm","clk":"993355809","pt":1580541152569,"mc":[{"id":"1.168130661","rc":[{"batb":[[0,14.5,7.77],[1,13.5,12.02],[2,13,4.7]],"ltp":15.0,"tv":206.27,"id":24707172},{"batb":[[0,13.5,9.81],[1,13,8.9],[2,12,4.53]],"ltp":14.0,"tv":237.61,"id":420}]}]}
{"op":"mcm","clk":"993355987","pt":1580541155661,"mc":[{"id":"1.168130661","rc":[{"batb":[[1,13,3.9]],"ltp":14.0,"tv":237.61,"id":420}]}]}
{"op":"mcm","clk":"993356258","pt":1580541162696,"mc":[{"id":"1.168130661","rc":[{"batb":[[0,13.5,14.81]],"ltp":14.0,"tv":237.61,"id":420}]}]}
{"op":"mcm","clk":"993356435","pt":1580541166672,"mc":[{"id":"1.168130661","rc":[{"trd":[[2.62,339.47]],"batb":[[0,2.6,26.76],[1,2.58,26.31],[2,2.5,6]],"ltp":2.62,"tv":2233.99,"id":26314798}],"tv":5156.02}]}
{"op":"mcm","clk":"993356647","pt":1580541171474,"mc":[{"id":"1.168130661","rc":[{"batb":[[0,2.62,65.43],[1,2.6,26.42],[2,2.58,26.31]],"ltp":2.62,"tv":2233.99,"id":26314798},{"batb":[[0,14,9.46],[1,13.5,5],[2,13,3.9]],"ltp":14.0,"tv":237.61,"id":420}]}]}
{"op":"mcm","clk":"993357477","pt":1580541188711,"mc":[{"id":"1.168130661","rc":[{"batb":[[1,2.54,47.37],[2,2.5,6.75]],"ltp":2.54,"tv":2086.26,"id":25238892}]}]}
{"op":"mcm","clk":"993357498","pt":1580541189224,"mc":[{"id":"1.168130661","rc":[{"batb":[[0,2.64,2],[1,2.62,12],[2,2.54,47.37]],"ltp":2.54,"tv":2086.26,"id":25238892}]}]}
{"op":"mcm","clk":"993357737","pt":1580541194425,"mc":[{"id":"1.168130661","rc":[{"batl":[[1,2.76,1.18],[2,2.82,5.64]],"ltp":2.54,"tv":2086.26,"id":25238892}]}]}
{"op":"mcm","clk":"993357869","pt":1580541197613,"mc":[{"id":"1.168130661","rc":[{"batb":[[0,2.64,2],[1,2.62,65.43],[2,2.6,26.42]],"ltp":2.62,"tv":2233.99,"id":26314798}]}]}
{"op":"mcm","clk":"993358898","pt":1580541221534,"mc":[{"id":"1.168130661","rc":[{"batb":[[0,2.66,3],[1,2.64,2],[2,2.62,12]],"ltp":2.54,"tv":2086.26,"id":25238892}]}]}
