{"op":"mcm","clk":"989823568","pt":1580491659636,"mc":[{"id":"1.168133553","rc":[{"batb":[[0,1.9,90],[1,1.89,1.98],[2,1.88,1.99]],"ltp":0.0,"tv":0.0,"id":27227336},{"batb":[[0,1.9,90],[1,1.89,1.98],[2,1.88,1.99]],"ltp":0.0,"tv":0.0,"id":21641292}]}]}
{"op":"mcm","clk":"989824211","pt":1580491666557,"mc":[{"id":"1.168133553","rc":[{"batb":[[0,1.26,35]],"ltp":1.59,"tv":23.62,"id":16325787}]}]}
{"op":"mcm","clk":"989824315","pt":1580491667390,"mc":[{"id":"1.168133553","rc":[{"batb":[[0,1.27,3],[1,1.26,35],[2,1.25,10]],"ltp":1.59,"tv":23.62,"id":16325787}]}]}
{"op":"mcm","clk":"989825562","pt":1580491678574,"mc":[{"id":"1.168133553","rc":[{"batb":[[0,1.91,19.76],[1,1.9,90],[2,1.89,1.98]],"batl":[[0,910,3.23],[1,920,9]],"ltp":0.0,"tv":0.0,"id":27227336},{"batb":[[0,1.27,6.34]],"ltp":1.59,"tv":23.62,"id":16325787}]}]}
{"op":"mcm","clk":"989825688","pt":1580491679559,"mc":[{"id":"1.168133553","rc":[{"batb":[[0,1.91,20.16],[1,1.9,90],[2,1.89,1.98]],"batl":[[0,910,3.23],[1,920,9]],"ltp":0.0,"tv":0.0,"id":21641292}]}]}
{"op":"mcm","clk":"989826346","pt":1580491684490,"mc":[{"id":"1.168133553","rc":[{"batl":[[0,910,3.03]],"ltp":0.0,"tv":0.0,"id":27227336},{"batl":[[0,910,3.03]],"ltp":0.0,"tv":0.0,"id":21641292}]}]}
{"op":"mcm","clk":"989826471","pt":1580491685479,"mc":[{"id":"1.168133553","rc":[{"batl":[[0,910,3.23]],"ltp":0.0,"tv":0.0,"id":27227336},{"batl":[[0,910,3.23]],"ltp":0.0,"tv":0.0,"id":21641292}]}]}
{"op":"mcm","clk":"989827076","pt":1580491690809,"mc":[{"id":"1.168133553","rc":[{"batb":[[0,1.92,3],[1,1.91,19.76],[2,1.9,90]],"ltp":0.0,"tv":0.0,"id":27227336},{"batb":[[0,1.92,3],[1,1.91,20.16],[2,1.9,90]],"ltp":0.0,"tv":0.0,"id":21641292}]}]}
{"op":"mcm","clk":"989827340","pt":1580491693382,"mc":[{"id":"1.168133553","rc":[{"batb":[[0,1.28,3],[1,1.27,3.34],[2,1.26,35]],"ltp":1.59,"tv":23.62,"id":16325787}]}]}
{"op":"mcm","clk":"989827779","pt":1580491697516,"mc":[{"id":"1.168133553","rc":[{"batb":[[0,1.94,90],[1,1.92,3],[2,1.91,19.76]],"batl":[[0,890,9],[1,910,3.23]],"ltp":0.0,"tv":0.0,"id":27227336},{"batb":[[0,1.94,90],[1,1.92,3],[2,1.91,20.16]],"batl":[[0,890,9],[1,910,3.23]],"ltp":0.0,"tv":0.0,"id":21641292}]}]}
{"op":"mcm","clk":"989827887","pt":1580491698512,"mc":[{"id":"1.168133553","rc":[{"batl":[[1,910,3.03]],"ltp":0.0,"tv":0.0,"id":27227336},{"batl":[[1,910,3.03]],"ltp":0.0,"tv":0.0,"id":21641292}]}]}
{"op":"mcm","clk":"989827918","pt":1580491698722,"mc":[{"id":"1.168133553","rc":[{"batl":[[0,890,9.2]],"ltp":0.0,"tv":0.0,"id":27227336},{"batl":[[0,890,9.2]],"ltp":0.0,"tv":0.0,"id":21641292}]}]}
{"op":"mcm","clk":"989829177","pt":1580491712170,"mc":[{"id":"1.168133553","rc":[{"batl":[[0,1.47,18.97],[1,1.48,45],[2,1.5,3.03]],"ltp":1.59,"tv":23.62,"id":16325787}]}]}
{"op":"mcm","clk":"989832472","pt":1580491745520,"mc":[{"id":"1.168133553","rc":[{"batl":[[0,1.46,3.03],[1,1.47,18.97],[2,1.48,45]],"ltp":1.59,"tv":23.62,"id":16325787}]}]}
{"op":"mcm","clk":"989832573","pt":1580491746491,"mc":[{"id":"1.168133553","rc":[{"batb":[[0,1.95,19.36],[1,1.94,90],[2,1.92,3]],"batl":[[0,880,3.23],[1,890,9]],"ltp":0.0,"tv":0.0,"id":27227336},{"batb":[[2,1.89,1.98]],"ltp":0.0,"tv":0.0,"id":21641292}]}]}
{"op":"mcm","clk":"989832669","pt":1580491747320,"mc":[{"id":"1.168133553","rc":[{"batb":[[0,1.96,1.98],[1,1.95,19.36],[2,1.94,90]],"ltp":0.0,"tv":0.0,"id":27227336},{"batb":[[0,1.96,1.98],[1,1.95,19.74],[2,1.94,90]],"batl":[[0,880,3.23],[1,890,9]],"ltp":0.0,"tv":0.0,"id":21641292},{"batb":[[0,1.28,38],[2,1.24,1.33]],"ltp":1.59,"tv":23.62,"id":16325787}]}]}
{"op":"mcm","clk":"989833678","pt":1580491756537,"mc":[{"id":"1.168133553","rc":[{"batl":[[0,880,3.03]],"ltp":0.0,"tv":0.0,"id":27227336},{"batl":[[0,880,3.03]],"ltp":0.0,"tv":0.0,"id":21641292}]}]}
{"op":"mcm","clk":"989833715","pt":1580491756894,"mc":[{"id":"1.168133553","rc":[{"batl":[[0,880,3.23]],"ltp":0.0,"tv":0.0,"id":27227336},{"batl":[[0,880,3.23]],"ltp":0.0,"tv":0.0,"id":21641292},{"batb":[[0,1.29,3],[1,1.28,35],[2,1.27,3.34]],"ltp":1.59,"tv":23.62,"id":16325787}]}]}
{"op":"mcm","clk":"989834357","pt":1580491763407,"mc":[{"id":"1.168133553","rc":[{"batb":[[0,1.97,1.99],[1,1.96,1.98],[2,1.95,19.36]],"ltp":0.0,"tv":0.0,"id":27227336},{"batb":[[0,1.97,1.99],[1,1.96,1.98],[2,1.95,19.74]],"ltp":0.0,"tv":0.0,"id":21641292}]}]}
{"op":"mcm","clk":"989834867","pt":1580491768443,"mc":[{"id":"1.168133553","rc":[{"batb":[[0,1.98,90],[1,1.97,1.99],[2,1.96,1.98]],"ltp":0.0,"tv":0.0,"id":27227336},{"batb":[[0,1.98,90],[1,1.97,1.99],[2,1.96,1.98]],"ltp":0.0,"tv":0.0,"id":21641292}]}]}
{"op":"mcm","clk":"989834963","pt":1580491769338,"mc":[{"id":"1.168133553","rc":[{"batl":[[0,860,9],[1,880,3.23]],"ltp":0.0,"tv":0.0,"id":27227336},{"batl":[[0,860,9],[1,880,3.23]],"ltp":0.0,"tv":0.0,"id":21641292}]}]}
{"op":"mcm","clk":"989837421","pt":1580491792568,"mc":[{"id":"1.168133553","rc":[{"batb":[[0,1.98,90.83]],"ltp":0.0,"tv":0.0,"id":27227336},{"batb":[[0,1.3,1.27],[1,1.29,3],[2,1.28,35]],"ltp":1.59,"tv":23.62,"id":16325787}]}]}
{"op":"mcm","clk":"989837528","pt":1580491793463,"mc":[{"id":"1.168133553","rc":[{"batb":[[0,1.98,90.83]],"ltp":0.0,"tv":0.0,"id":21641292}]}]}
{"op":"mcm","clk":"989838491","pt":1580491802478,"mc":[{"id":"1.168133553","rc":[{"batb":[[0,1.3,4.27],[1,1.28,35],[2,1.27,3.34]],"ltp":1.59,"tv":23.62,"id":16325787}]}]}
{"op":"mcm","clk":"989839966","pt":1580491815095,"mc":[{"id":"1.168133553","rc":[{"batb":[[0,1.31,3],[1,1.3,1.27],[2,1.28,35]],"ltp":1.59,"tv":23.62,"id":16325787}]}]}
{"op":"mcm","clk":"989840840","pt":1580491820504,"mc":[{"id":"1.168133553","rc":[{"batb":[[0,1.99,5.43],[1,1.98,90],[2,1.97,1.99]],"ltp":0.0,"tv":0.0,"id":27227336},{"batb":[[0,1.99,5.43],[1,1.98,90],[2,1.97,1.99]],"ltp":0.0,"tv":0.0,"id":21641292}]}]}
{"op":"mcm","clk":"989841534","pt":1580491825791,"mc":[{"id":"1.168133553","rc":[{"batb":[[0,1.3,1.27],[1,1.29,3]],"ltp":1.59,"tv":23.62,"id":16325787}]}]}
{"op":"mcm","clk":"989842612","pt":1580491833409,"mc":[{"id":"1.168133553","rc":[{"batb":[[0,2.02,90],[1,2,12.32],[2,1.99,5.43]],"ltp":0.0,"tv":0.0,"id":27227336},{"batb":[[0,2.02,90],[1,1.99,5.43]],"ltp":0.0,"tv":0.0,"id":21641292}]}]}
{"op":"mcm","clk":"989843288","pt":1580491838416,"mc":[{"id":"1.168133553","rc":[{"batb":[[0,1.3,4.27],[1,1.28,35],[2,1.27,3.34]],"ltp":1.59,"tv":23.62,"id":16325787}]}]}
{"op":"mcm","clk":"989844174","pt":1580491845337,"mc":[{"id":"1.168133553","rc":[{"batb":[[0,2.04,1.98],[1,2.02,90],[2,2,12.32]],"ltp":0.0,"tv":0.0,"id":27227336},{"batb":[[0,2.04,1.98],[1,2.02,90],[2,1.99,5.43]],"ltp":0.0,"tv":0.0,"id":21641292},{"batb":[[0,1.3,39.26],[1,1.27,3.34],[2,1.21,6]],"ltp":1.59,"tv":23.62,"id":16325787}]}]}
{"op":"mcm","clk":"989844598","pt":1580491848956,"mc":[{"id":"1.168133553","rc":[{"batb":[[0,2.04,6.36]],"ltp":0.0,"tv":0.0,"id":27227336},{"batb":[[0,2.04,6.36],[2,1.97,2.82]],"ltp":0.0,"tv":0.0,"id":21641292}]}]}
{"op":"mcm","clk":"989844853","pt":1580491851237,"mc":[{"id":"1.168133553","rc":[{"batb":[[0,1.31,3],[1,1.3,36.26],[2,1.27,3.34]],"ltp":1.59,"tv":23.62,"id":16325787}]}]}
{"op":"mcm","clk":"989846351","pt":1580491862365,"mc":[{"id":"1.168133553","rc":[{"batb":[[0,2.06,1.99],[1,2.04,6.36],[2,2.02,90]],"ltp":0.0,"tv":0.0,"id":27227336},{"batb":[[0,2.06,1.99],[1,2.04,6.36],[2,2.02,90]],"ltp":0.0,"tv":0.0,"id":21641292}]}]}
{"op":"mcm","clk":"989846889","pt":1580491866130,"mc":[{"id":"1.168133553","rc":[{"batb":[[0,2.08,90],[1,2.06,1.99],[2,2.04,6.36]],"ltp":0.0,"tv":0.0,"id":27227336},{"batb":[[0,2.08,90],[1,2.06,1.99],[2,2.04,6.36]],"ltp":0.0,"tv":0.0,"id":21641292}]}]}
{"op":"mcm","clk":"989848833","pt":1580491878973,"mc":[{"id":"1.168133553","rc":[{"batb":[[0,2.1,4.14],[1,2.08,90],[2,2.06,1.99]],"ltp":0.0,"tv":0.0,"id":27227336},{"batb":[[0,2.1,4.14],[1,2.08,90],[2,2.06,1.99]],"ltp":0.0,"tv":0.0,"id":21641292}]}]}
{"op":"mcm","clk":"989851320","pt":1580491898556,"mc":[{"id":"1.168133553","rc":[{"batb":[[0,2.14,90],[1,2.1,4.14]],"ltp":0.0,"tv":0.0,"id":27227336},{"batb":[[0,2.1,94.14],[1,2.06,1.99],[2,2.04,1.98]],"ltp":0.0,"tv":0.0,"id":21641292}]}]}
{"op":"mcm","clk":"989852556","pt":1580491908973,"mc":[{"id":"1.168133553","rc":[{"batb":[[0,2.16,3.92],[1,2.14,90]],"ltp":0.0,"tv":0.0,"id":27227336}]}]}
{"op":"mcm","clk":"989854096","pt":1580491919489,"mc":[{"id":"1.168133553","rc":[{"batb":[[0,1.31,6.24],[2,1.21,6]],"ltp":1.59,"tv":23.62,"id":16325787}]}]}
{"op":"mcm","clk":"989854240","pt":1580491920491,"mc":[{"id":"1.168133553","rc":[{"batb":[[0,2.18,17.31],[1,2.16,3.92],[2,2.14,90]],"batl":[[0,850,3.03],[1,860,9],[2,870,0.2]],"ltp":0.0,"tv":0.0,"id":27227336},{"batb":[[0,2.12,18.16],[1,2.1,94.14],[2,2.06,1.99]],"ltp":0.0,"tv":0.0,"id":21641292}]}]}
{"op":"mcm","clk":"989854276","pt":1580491920766,"mc":[{"id":"1.168133553","rc":[{"batl":[[0,850,3.03],[1,860,9],[2,870,0.2]],"ltp":0.0,"tv":0.0,"id":21641292}]}]}
{"op":"mcm","clk":"989855059","pt":1580491926382,"mc":[{"id":"1.168133553","rc":[{"batb":[[0,1.32,3],[1,1.31,3.24],[2,1.3,36.26]],"ltp":1.59,"tv":23.62,"id":16325787}]}]}
{"op":"mcm","clk":"989855754","pt":1580491931567,"mc":[{"id":"1.168133553","rc":[{"batb":[[0,2.22,90],[1,2.18,17.31],[2,2.16,3.92]],"batl":[[1,870,0.2],[2,870,0]],"ltp":0.0,"tv":0.0,"id":27227336},{"batl":[[1,870,0.2],[2,870,0]],"ltp":0.0,"tv":0.0,"id":21641292}]}]}
{"op":"mcm","clk":"989855836","pt":1580491932195,"mc":[{"id":"1.168133553","rc":[{"batl":[[0,830,9],[1,850,3.03],[2,870,0.2]],"ltp":0.0,"tv":0.0,"id":27227336},{"batl":[[0,830,9],[1,850,3.03],[2,870,0.2]],"ltp":0.0,"tv":0.0,"id":21641292}]}]}
{"op":"mcm","clk":"989856992","pt":1580491939482,"mc":[{"id":"1.168133553","rc":[{"batb":[[0,2.24,1.98],[1,2.22,90],[2,2.18,17.31]],"ltp":0.0,"tv":0.0,"id":27227336},{"batb":[[0,2.14,1.98],[1,2.12,18.16],[2,2.1,94.14]],"ltp":0.0,"tv":0.0,"id":21641292},{"batb":[[0,1.32,38],[2,1.3,1.27]],"ltp":1.59,"tv":23.62,"id":16325787}]}]}
{"op":"mcm","clk":"989857087","pt":1580491940109,"mc":[{"id":"1.168133553","rc":[{"batb":[[0,2.24,5.66]],"ltp":0.0,"tv":0.0,"id":27227336},{"batb":[[0,2.14,5.98],[2,2.1,90]],"ltp":0.0,"tv":0.0,"id":21641292}]}]}
{"op":"mcm","clk":"989858069","pt":1580491947524,"mc":[{"id":"1.168133553","rc":[{"batb":[[0,2.26,1.99],[1,2.24,5.66],[2,2.22,90]],"ltp":0.0,"tv":0.0,"id":27227336}]}]}
{"op":"mcm","clk":"989858098","pt":1580491947730,"mc":[{"id":"1.168133553","rc":[{"batb":[[0,2.16,1.99],[1,2.14,5.98],[2,2.12,18.16]],"ltp":0.0,"tv":0.0,"id":21641292}]}]}
{"op":"mcm","clk":"989858419","pt":1580491950329,"mc":[{"id":"1.168133553","rc":[{"batb":[[0,1.33,3],[1,1.32,35],[2,1.31,3.24]],"ltp":1.59,"tv":23.62,"id":16325787}]}]}
{"op":"mcm","clk":"989860120","pt":1580491964433,"mc":[{"id":"1.168133553","rc":[{"batb":[[0,2.28,90],[1,2.26,1.99],[2,2.24,5.66]],"ltp":0.0,"tv":0.0,"id":27227336}]}]}
{"op":"mcm","clk":"989860662","pt":1580491969323,"mc":[{"id":"1.168133553","rc":[{"batb":[[0,2.3,3.51],[1,2.28,90],[2,2.26,1.99]],"ltp":0.0,"tv":0.0,"id":27227336}]}]}
{"op":"mcm","clk":"989863979","pt":1580491997386,"mc":[{"id":"1.168133553","rc":[{"batb":[[0,2.34,90],[1,2.3,3.51]],"ltp":0.0,"tv":0.0,"id":27227336}]}]}
{"op":"mcm","clk":"989864143","pt":1580491999095,"mc":[{"id":"1.168133553","rc":[{"batb":[[0,2.36,3],[1,2.34,90]],"ltp":0.0,"tv":0.0,"id":27227336}]}]}
{"op":"mcm","clk":"989868560","pt":1580492030321,"mc":[{"id":"1.168133553","rc":[{"batb":[[0,2.4,90],[1,2.36,3]],"ltp":0.0,"tv":0.0,"id":27227336}]}]}
{"op":"mcm","clk":"989868843","pt":1580492032538,"mc":[{"id":"1.168133553","rc":[{"batb":[[1,2.14,3.99]],"ltp":0.0,"tv":0.0,"id":21641292},{"batb":[[1,1.31,3.24],[2,1.3,1.27]],"ltp":1.59,"tv":23.62,"id":16325787}]}]}
{"op":"mcm","clk":"989868942","pt":1580492033187,"mc":[{"id":"1.168133553","rc":[{"batb":[[0,2.42,1.98],[1,2.4,90],[2,2.36,3]],"ltp":0.0,"tv":0.0,"id":27227336},{"batb":[[0,2.18,1.98],[1,2.16,1.99],[2,2.14,3.99]],"ltp":0.0,"tv":0.0,"id":21641292},{"batb":[[0,1.33,38]],"ltp":1.59,"tv":23.62,"id":16325787}]}]}
{"op":"mcm","clk":"989869434","pt":1580492036507,"mc":[{"id":"1.168133553","rc":[{"batb":[[0,1.33,35]],"ltp":1.59,"tv":23.62,"id":16325787}]}]}
{"op":"mcm","clk":"989869553","pt":1580492037404,"mc":[{"id":"1.168133553","rc":[{"batb":[[0,1.34,3],[1,1.33,35],[2,1.31,3.24]],"ltp":1.59,"tv":23.62,"id":16325787}]}]}
{"op":"mcm","clk":"989870667","pt":1580492045507,"mc":[{"id":"1.168133553","rc":[{"batb":[[0,2.44,1.99],[1,2.42,1.98],[2,2.4,90]],"ltp":0.0,"tv":0.0,"id":27227336}]}]}
{"op":"mcm","clk":"989870695","pt":1580492045720,"mc":[{"id":"1.168133553","rc":[{"batb":[[0,2.2,1.99],[1,2.18,1.98]],"ltp":0.0,"tv":0.0,"id":21641292}]}]}
{"op":"mcm","clk":"989872938","pt":1580492063542,"mc":[{"id":"1.168133553","rc":[{"batb":[[2,2.36,3]],"ltp":0.0,"tv":0.0,"id":27227336}]}]}
{"op":"mcm","clk":"989873030","pt":1580492064241,"mc":[{"id":"1.168133553","rc":[{"batb":[[0,2.46,90],[1,2.44,1.99],[2,2.42,1.98]],"ltp":0.0,"tv":0.0,"id":27227336}]}]}
{"op":"mcm","clk":"989877229","pt":1580492097460,"mc":[{"id":"1.168133553","rc":[{"batb":[[0,2.48,15.22],[1,2.46,90],[2,2.44,1.99]],"batl":[[0,820,3.03],[1,830,9]],"ltp":0.0,"tv":0.0,"id":27227336}]}]}
{"op":"mcm","clk":"989877297","pt":1580492097979,"mc":[{"id":"1.168133553","rc":[{"batb":[[0,2.2,5.02]],"batl":[[0,820,3.03],[1,830,9]],"ltp":0.0,"tv":0.0,"id":21641292}]}]}
{"op":"mcm","clk":"989880055","pt":1580492119543,"mc":[{"id":"1.168133553","rc":[{"batb":[[0,2.5,3.03],[1,2.48,15.22],[2,2.46,90]],"ltp":0.0,"tv":0.0,"id":27227336}]}]}
{"op":"mcm","clk":"989881260","pt":1580492129434,"mc":[{"id":"1.168133553","rc":[{"batb":[[0,2.54,90],[1,2.52,1.98],[2,2.5,3.03]],"ltp":0.0,"tv":0.0,"id":27227336},{"batb":[[0,2.22,1.98],[1,2.2,5.02]],"ltp":0.0,"tv":0.0,"id":21641292},{"batb":[[0,1.34,38],[1,1.31,3.24],[2,1.3,1.27]],"ltp":1.59,"tv":23.62,"id":16325787}]}]}
{"op":"mcm","clk":"989881345","pt":1580492130113,"mc":[{"id":"1.168133553","rc":[{"batl":[[0,800,9],[1,820,3.03]],"ltp":0.0,"tv":0.0,"id":27227336},{"batl":[[0,800,9],[1,820,3.03]],"ltp":0.0,"tv":0.0,"id":21641292}]}]}
{"op":"mcm","clk":"989882499","pt":1580492138469,"mc":[{"id":"1.168133553","rc":[{"batb":[[0,1.34,35]],"ltp":1.59,"tv":23.62,"id":16325787}]}]}
{"op":"mcm","clk":"989882554","pt":1580492138887,"mc":[{"id":"1.168133553","rc":[{"batb":[[0,1.35,3],[1,1.34,35],[2,1.31,3.24]],"ltp":1.59,"tv":23.62,"id":16325787}]}]}
{"op":"mcm","clk":"989883908","pt":1580492149498,"mc":[{"id":"1.168133553","rc":[{"batb":[[2,2.48,15.22]],"ltp":0.0,"tv":0.0,"id":27227336}]}]}
{"op":"mcm","clk":"989884035","pt":1580492150464,"mc":[{"id":"1.168133553","rc":[{"batb":[[0,2.56,1.99],[1,2.54,90],[2,2.52,1.98]],"ltp":0.0,"tv":0.0,"id":27227336},{"batb":[[0,2.24,1.99],[1,2.22,1.98],[2,2.2,3.03]],"ltp":0.0,"tv":0.0,"id":21641292}]}]}
{"op":"mcm","clk":"989884186","pt":1580492151465,"mc":[{"id":"1.168133553","rc":[{"batb":[[0,2.56,4.91]],"ltp":0.0,"tv":0.0,"id":27227336}]}]}
{"op":"mcm","clk":"989885798","pt":1580492163526,"mc":[{"id":"1.168133553","rc":[{"batb":[[1,2.52,1.98],[2,2.48,15.22]],"ltp":0.0,"tv":0.0,"id":27227336}]}]}
{"op":"mcm","clk":"989885930","pt":1580492164424,"mc":[{"id":"1.168133553","rc":[{"batb":[[0,2.6,90],[1,2.56,4.91],[2,2.52,1.98]],"ltp":0.0,"tv":0.0,"id":27227336}]}]}
{"op":"mcm","clk":"989886657","pt":1580492169534,"mc":[{"id":"1.168133553","rc":[{"batb":[[0,2.6,90.63]],"ltp":0.0,"tv":0.0,"id":27227336},{"batb":[[0,2.24,2.73]],"ltp":0.0,"tv":0.0,"id":21641292},{"batb":[[0,1.36,1.21],[1,1.35,3],[2,1.34,35]],"ltp":1.59,"tv":23.62,"id":16325787}]}]}
{"op":"mcm","clk":"989887168","pt":1580492173543,"mc":[{"id":"1.168133553","rc":[{"batb":[[1,1.34,35],[2,1.31,3.24]],"ltp":1.59,"tv":23.62,"id":16325787}]}]}
{"op":"mcm","clk":"989887182","pt":1580492173646,"mc":[{"id":"1.168133553","rc":[{"batb":[[0,1.36,4.21]],"ltp":1.59,"tv":23.62,"id":16325787}]}]}
{"op":"mcm","clk":"989887881","pt":1580492179258,"mc":[{"id":"1.168133553","rc":[{"batb":[[1,2.56,1.99]],"ltp":0.0,"tv":0.0,"id":27227336}]}]}
{"op":"mcm","clk":"989888145","pt":1580492181434,"mc":[{"id":"1.168133553","rc":[{"batb":[[0,2.62,3.44],[1,2.6,90],[2,2.56,1.99]],"ltp":0.0,"tv":0.0,"id":27227336}]}]}
{"op":"mcm","clk":"989889096","pt":1580492188064,"mc":[{"id":"1.168133553","rc":[{"batb":[[0,1.37,3],[1,1.36,1.21],[2,1.34,35]],"ltp":1.59,"tv":23.62,"id":16325787}]}]}
{"op":"mcm","clk":"989890621","pt":1580492199743,"mc":[{"id":"1.168133553","rc":[{"batb":[[0,2.66,90],[1,2.62,3.44]],"ltp":0.0,"tv":0.0,"id":27227336}]}]}
{"op":"mcm","clk":"989891166","pt":1580492204266,"mc":[{"id":"1.168133553","rc":[{"batb":[[0,1.36,1.21],[1,1.35,3]],"ltp":1.59,"tv":23.62,"id":16325787}]}]}
{"op":"mcm","clk":"989891718","pt":1580492208883,"mc":[{"id":"1.168133553","rc":[{"batb":[[1,2.56,2.62],[2,2.52,1.98]],"ltp":0.0,"tv":0.0,"id":27227336}]}]}
{"op":"mcm","clk":"989892016","pt":1580492211684,"mc":[{"id":"1.168133553","rc":[{"batb":[[0,2.68,2.71],[1,2.66,90],[2,2.56,2.62]],"ltp":0.0,"tv":0.0,"id":27227336}]}]}
{"op":"mcm","clk":"989892581","pt":1580492216220,"mc":[{"id":"1.168133553","rc":[{"batb":[[0,1.36,4.21],[1,1.34,35],[2,1.31,3.24]],"ltp":1.59,"tv":23.62,"id":16325787}]}]}
{"op":"mcm","clk":"989893169","pt":1580492221029,"mc":[{"id":"1.168133553","rc":[{"batb":[[0,2.7,1.98],[1,2.68,2.71],[2,2.66,90]],"ltp":0.0,"tv":0.0,"id":27227336},{"batb":[[0,2.26,1.98],[1,2.24,2.73]],"ltp":0.0,"tv":0.0,"id":21641292},{"batb":[[0,1.36,39.21],[1,1.31,3.24],[2,1.2,90]],"ltp":1.59,"tv":23.62,"id":16325787}]}]}
{"op":"mcm","clk":"989893947","pt":1580492227557,"mc":[{"id":"1.168133553","rc":[{"batb":[[0,1.36,36.21]],"ltp":1.59,"tv":23.62,"id":16325787}]}]}
{"op":"mcm","clk":"989893960","pt":1580492227664,"mc":[{"id":"1.168133553","rc":[{"batb":[[0,1.37,3],[1,1.36,36.21],[2,1.31,3.24]],"ltp":1.59,"tv":23.62,"id":16325787}]}]}
{"op":"mcm","clk":"989907984","pt":1580492265374,"mc":[{"id":"1.168133553","rc":[{"batb":[[0,2.72,1.99],[1,2.7,1.98],[2,2.68,2.71]],"ltp":0.0,"tv":0.0,"id":27227336},{"batb":[[0,2.28,1.99],[1,2.26,1.98],[2,2.2,3.77]],"ltp":0.0,"tv":0.0,"id":21641292}]}]}
{"op":"mcm","clk":"989913848","pt":1580492316462,"mc":[{"id":"1.168133553","rc":[{"batb":[[1,2.68,2.71],[2,2.66,90]],"ltp":0.0,"tv":0.0,"id":27227336},{"batb":[[1,2.2,3.77],[2,2.14,3.99]],"ltp":0.0,"tv":0.0,"id":21641292},{"batb":[[1,1.36,1.21]],"ltp":1.59,"tv":23.62,"id":16325787}]}]}
{"op":"mcm","clk":"989913873","pt":1580492316575,"mc":[{"id":"1.168133553","rc":[{"batb":[[0,2.74,1.98],[1,2.72,1.99],[2,2.68,2.71]],"ltp":0.0,"tv":0.0,"id":27227336},{"batb":[[0,2.3,1.98],[1,2.28,1.99],[2,2.2,3.77]],"ltp":0.0,"tv":0.0,"id":21641292},{"batb":[[0,1.37,38]],"ltp":1.59,"tv":23.62,"id":16325787}]}]}
{"op":"mcm","clk":"989914613","pt":1580492323294,"mc":[{"id":"1.168133553","rc":[{"batb":[[0,1.38,3],[1,1.37,35],[2,1.36,1.21]],"ltp":1.59,"tv":23.62,"id":16325787}]}]}
{"op":"mcm","clk":"989916751","pt":1580492342323,"mc":[{"id":"1.168133553","rc":[{"batb":[[0,2.74,9.28]],"ltp":0.0,"tv":0.0,"id":27227336},{"batb":[[1,2.28,10.76]],"ltp":0.0,"tv":0.0,"id":21641292},{"batb":[[0,1.38,13]],"ltp":1.59,"tv":23.62,"id":16325787}]}]}
{"op":"mcm","clk":"989917591","pt":1580492350417,"mc":[{"id":"1.168133553","rc":[{"batb":[[0,1.39,3],[1,1.38,10],[2,1.37,35]],"ltp":1.59,"tv":23.62,"id":16325787}]}]}
{"op":"mcm","clk":"989918448","pt":1580492358952,"mc":[{"id":"1.168133553","rc":[{"batb":[[2,2.66,90]],"ltp":0.0,"tv":0.0,"id":27227336}]}]}
{"op":"mcm","clk":"989919071","pt":1580492365544,"mc":[{"id":"1.168133553","rc":[{"batb":[[2,2.68,6]],"ltp":0.0,"tv":0.0,"id":27227336}]}]}
{"op":"mcm","clk":"989919882","pt":1580492374489,"mc":[{"id":"1.168133553","rc":[{"batb":[[0,2.76,1.99],[1,2.74,9.28]],"ltp":0.0,"tv":0.0,"id":27227336},{"batb":[[0,2.32,1.99],[1,2.3,1.98],[2,2.28,8.77]],"ltp":0.0,"tv":0.0,"id":21641292}]}]}
{"op":"mcm","clk":"989922958","pt":1580492405911,"mc":[{"id":"1.168133553","rc":[{"batb":[[1,2.3,10.68],[2,2.2,3.77]],"ltp":0.0,"tv":0.0,"id":21641292}]}]}
{"op":"mcm","clk":"989924338","pt":1580492419005,"mc":[{"id":"1.168133553","rc":[{"batb":[[0,2.32,5.44]],"ltp":0.0,"tv":0.0,"id":21641292}]}]}
{"op":"mcm","clk":"989924559","pt":1580492421324,"mc":[{"id":"1.168133553","rc":[{"batb":[[0,2.76,4.58]],"ltp":0.0,"tv":0.0,"id":27227336}]}]}
{"op":"mcm","clk":"989933482","pt":1580492508492,"mc":[{"id":"1.168133553","rc":[{"batb":[[0,2.78,3.47],[1,2.76,4.58],[2,2.74,9.28]],"batl":[[1,870,0.2],[2,870,0]],"ltp":0.0,"tv":0.0,"id":27227336}]}]}
{"op":"mcm","clk":"989933583","pt":1580492509284,"mc":[{"id":"1.168133553","rc":[{"batl":[[0,790,3.03],[1,800,9],[2,870,0.2]],"ltp":0.0,"tv":0.0,"id":27227336},{"batb":[[0,2.34,3.03],[1,2.32,5.44],[2,2.3,10.68]],"batl":[[0,790,3.03],[1,800,9]],"ltp":0.0,"tv":0.0,"id":21641292}]}]}
{"op":"mcm","clk":"989935088","pt":1580492524311,"mc":[{"id":"1.168133553","rc":[{"batl":[[0,770,9],[1,790,3.03]],"ltp":0.0,"tv":0.0,"id":27227336},{"batl":[[0,770,9],[1,790,3.03]],"ltp":0.0,"tv":0.0,"id":21641292},{"batl":[[0,1.46,23.03]],"ltp":1.59,"tv":23.62,"id":16325787}]}]}
{"op":"mcm","clk":"989936085","pt":1580492533975,"mc":[{"id":"1.168133553","rc":[{"batb":[[0,2.78,10.66],[2,2.74,1.98]],"ltp":0.0,"tv":0.0,"id":27227336},{"batb":[[1,2.32,14.06],[2,2.3,1.98]],"ltp":0.0,"tv":0.0,"id":21641292}]}]}
{"op":"mcm","clk":"989936681","pt":1580492540170,"mc":[{"id":"1.168133553","rc":[{"batb":[[1,2.76,1.99]],"ltp":0.0,"tv":0.0,"id":27227336},{"batb":[[0,2.34,6.43],[1,2.32,10.61]],"ltp":0.0,"tv":0.0,"id":21641292}]}]}
{"op":"mcm","clk":"989936927","pt":1580492542360,"mc":[{"id":"1.168133553","rc":[{"batb":[[0,2.8,2.53],[1,2.78,10.66],[2,2.76,1.99]],"ltp":0.0,"tv":0.0,"id":27227336}]}]}
{"op":"mcm","clk":"989937127","pt":1580492544271,"mc":[{"id":"1.168133553","rc":[{"batb":[[0,2.82,1.99],[1,2.8,2.53],[2,2.78,10.66]],"ltp":0.0,"tv":0.0,"id":27227336}]}]}
{"op":"mcm","clk":"989937248","pt":1580492545307,"mc":[{"id":"1.168133553","rc":[{"batb":[[0,2.36,1.99],[1,2.34,6.43],[2,2.32,8.62]],"ltp":0.0,"tv":0.0,"id":21641292}]}]}
{"op":"mcm","clk":"989937842","pt":1580492551806,"mc":[{"id":"1.168133553","rc":[{"batb":[[0,2.84,1.98],[1,2.82,1.99],[2,2.8,2.53]],"ltp":0.0,"tv":0.0,"id":27227336},{"batb":[[0,2.38,1.98],[1,2.36,1.99],[2,2.34,6.43]],"ltp":0.0,"tv":0.0,"id":21641292},{"batb":[[0,1.39,38],[2,1.36,1.21]],"ltp":1.59,"tv":23.62,"id":16325787}]}]}
{"op":"mcm","clk":"989937987","pt":1580492553301,"mc":[{"id":"1.168133553","rc":[{"batb":[[0,1.4,3],[1,1.39,35],[2,1.38,10]],"ltp":1.59,"tv":23.62,"id":16325787}]}]}
{"op":"mcm","clk":"989939486","pt":1580492568929,"mc":[{"id":"1.168133553","rc":[{"batb":[[2,2.34,3.03]],"ltp":0.0,"tv":0.0,"id":21641292}]}]}
{"op":"mcm","clk":"989942291","pt":1580492598456,"mc":[{"id":"1.168133553","rc":[{"batb":[[0,2.84,9.02]],"ltp":0.0,"tv":0.0,"id":27227336},{"batb":[[0,2.38,10.38]],"ltp":0.0,"tv":0.0,"id":21641292},{"batb":[[0,1.4,13],[2,1.36,1.21]],"ltp":1.59,"tv":23.62,"id":16325787}]}]}
{"op":"mcm","clk":"989942354","pt":1580492599141,"mc":[{"id":"1.168133553","rc":[{"batb":[[2,2.78,3.47]],"ltp":0.0,"tv":0.0,"id":27227336}]}]}
{"op":"mcm","clk":"989942765","pt":1580492603312,"mc":[{"id":"1.168133553","rc":[{"batb":[[0,1.41,3],[1,1.4,10],[2,1.39,35]],"ltp":1.59,"tv":23.62,"id":16325787}]}]}
{"op":"mcm","clk":"989945310","pt":1580492630124,"mc":[{"id":"1.168133553","rc":[{"batb":[[0,2.84,9.6]],"ltp":0.0,"tv":0.0,"id":27227336},{"batb":[[0,2.38,11.07]],"ltp":0.0,"tv":0.0,"id":21641292},{"batb":[[0,1.42,1.16],[1,1.41,3],[2,1.4,10]],"ltp":1.59,"tv":23.62,"id":16325787}]}]}
{"op":"mcm","clk":"989945757","pt":1580492634109,"mc":[{"id":"1.168133553","rc":[{"batb":[[0,1.42,4.16],[1,1.4,10],[2,1.39,35]],"ltp":1.59,"tv":23.62,"id":16325787}]}]}
{"op":"mcm","clk":"989947377","pt":1580492649534,"mc":[{"id":"1.168133553","rc":[{"batb":[[0,2.88,1.99],[1,2.84,9.6]],"ltp":0.0,"tv":0.0,"id":27227336}]}]}
{"op":"mcm","clk":"989947465","pt":1580492650430,"mc":[{"id":"1.168133553","rc":[{"batb":[[0,2.42,1.99],[1,2.38,11.07]],"ltp":0.0,"tv":0.0,"id":21641292},{"trd":[[1.43,6]],"batb":[[0,1.42,1.16]],"ltp":1.43,"tv":29.62,"id":16325787}],"tv":29.62}]}
{"op":"mcm","clk":"989948611","pt":1580492662000,"mc":[{"id":"1.168133553","rc":[{"batb":[[1,2.84,2.56]],"ltp":0.0,"tv":0.0,"id":27227336},{"batb":[[1,2.38,2.67]],"ltp":0.0,"tv":0.0,"id":21641292}]}]}
{"op":"mcm","clk":"989956086","pt":1580492732449,"mc":[{"id":"1.168133553","rc":[{"batl":[[0,770,9.2],[2,870,0]],"ltp":0.0,"tv":0.0,"id":27227336},{"batb":[[2,2.36,3]],"batl":[[0,770,9.2],[2,870,0]],"ltp":0.0,"tv":0.0,"id":21641292}]}]}
{"op":"mcm","clk":"989956882","pt":1580492740350,"mc":[{"id":"1.168133553","rc":[{"batb":[[0,2.9,1.98],[1,2.88,1.99],[2,2.78,4.04]],"ltp":0.0,"tv":0.0,"id":27227336},{"batb":[[0,2.44,1.98],[1,2.42,1.99],[2,2.36,3.69]],"ltp":0.0,"tv":0.0,"id":21641292},{"batb":[[1,1.4,45],[2,1.31,3.24]],"ltp":1.43,"tv":29.62,"id":16325787}]}]}
{"op":"mcm","clk":"989957495","pt":1580492746395,"mc":[{"id":"1.168133553","rc":[{"batb":[[0,2.92,1.99],[1,2.9,1.98]],"ltp":0.0,"tv":0.0,"id":27227336},{"batb":[[0,2.46,1.99],[1,2.44,1.98]],"ltp":0.0,"tv":0.0,"id":21641292}]}]}
{"op":"mcm","clk":"989968788","pt":1580492848512,"mc":[{"id":"1.168133553","rc":[{"batb":[[2,2.8,3.58]],"ltp":0.0,"tv":0.0,"id":27227336},{"batb":[[1,1.41,3],[2,1.4,45]],"ltp":1.43,"tv":29.62,"id":16325787}]}]}
{"op":"mcm","clk":"989969395","pt":1580492854544,"mc":[{"id":"1.168133553","rc":[{"batb":[[2,1.4,35]],"ltp":1.43,"tv":29.62,"id":16325787}]}]}
{"op":"mcm","clk":"989971949","pt":1580492882527,"mc":[{"id":"1.168133553","rc":[{"batb":[[0,2.94,1.98],[1,2.92,1.99]],"ltp":0.0,"tv":0.0,"id":27227336},{"batb":[[0,2.48,1.98],[1,2.46,1.99]],"ltp":0.0,"tv":0.0,"id":21641292},{"batb":[[1,1.41,38],[2,1.31,3.24]],"ltp":1.43,"tv":29.62,"id":16325787}]}]}
{"op":"mcm","clk":"989972416","pt":1580492887324,"mc":[{"id":"1.168133553","rc":[{"batb":[[1,1.41,35]],"ltp":1.43,"tv":29.62,"id":16325787}]}]}
{"op":"mcm","clk":"989973180","pt":1580492895936,"mc":[{"id":"1.168133553","rc":[{"trd":[[1.41,69.96],[1.42,2.32]],"batb":[[0,1.31,3.24],[1,1.2,90],[2,1.12,1197.67]],"batl":[[0,1.41,3.88],[1,1.46,23.03],[2,1.47,18.97]],"ltp":1.41,"tv":101.9,"id":16325787}],"tv":101.9}]}
{"op":"mcm","clk":"989974859","pt":1580492914568,"mc":[{"id":"1.168133553","rc":[{"batb":[[0,2.94,5.02]],"ltp":0.0,"tv":0.0,"id":27227336},{"batb":[[0,1.21,3.24]],"ltp":1.41,"tv":101.9,"id":16325787}]}]}
{"op":"mcm","clk":"989974964","pt":1580492915567,"mc":[{"id":"1.168133553","rc":[{"batl":[[0,760,3.23],[1,770,9]],"ltp":0.0,"tv":0.0,"id":27227336},{"batb":[[0,2.48,5.02]],"batl":[[0,760,3.23],[1,770,9]],"ltp":0.0,"tv":0.0,"id":21641292}]}]}
{"op":"mcm","clk":"989975307","pt":1580492918451,"mc":[{"id":"1.168133553","rc":[{"batb":[[2,1.13,6]],"batl":[[0,1.4,2],[1,1.41,3.88],[2,1.46,23.03]],"ltp":1.41,"tv":101.9,"id":16325787}]}]}
{"op":"mcm","clk":"989975595","pt":1580492921475,"mc":[{"id":"1.168133553","rc":[{"batl":[[1,1.46,23.03],[2,1.47,18.97]],"ltp":1.41,"tv":101.9,"id":16325787}]}]}
{"op":"mcm","clk":"989975745","pt":1580492923365,"mc":[{"id":"1.168133553","rc":[{"batb":[[0,1.25,75.87],[1,1.21,3.24],[2,1.2,90]],"ltp":1.41,"tv":101.9,"id":16325787}]}]}
{"op":"mcm","clk":"989975827","pt":1580492924462,"mc":[{"id":"1.168133553","rc":[{"batb":[[1,1.21,41.18]],"ltp":1.41,"tv":101.9,"id":16325787}]}]}
{"op":"mcm","clk":"989975890","pt":1580492925184,"mc":[{"id":"1.168133553","rc":[{"batb":[[1,1.21,79.11]],"ltp":1.41,"tv":101.9,"id":16325787}]}]}
{"op":"mcm","clk":"989976011","pt":1580492926486,"mc":[{"id":"1.168133553","rc":[{"batb":[[1,1.21,154.98]],"ltp":1.41,"tv":101.9,"id":16325787}]}]}
{"op":"mcm","clk":"989976097","pt":1580492927471,"mc":[{"id":"1.168133553","rc":[{"batb":[[2,2.68,3.58]],"ltp":0.0,"tv":0.0,"id":27227336},{"batb":[[2,2.12,3.69]],"ltp":0.0,"tv":0.0,"id":21641292}]}]}
{"op":"mcm","clk":"989976349","pt":1580492930081,"mc":[{"id":"1.168133553","rc":[{"batb":[[1,1.22,6],[2,1.21,154.98]],"ltp":1.41,"tv":101.9,"id":16325787}]}]}
{"op":"mcm","clk":"989976553","pt":1580492932164,"mc":[{"id":"1.168133553","rc":[{"batb":[[0,2.96,2.32],[1,2.94,5.02],[2,2.92,1.99]],"ltp":0.0,"tv":0.0,"id":27227336}]}]}
{"op":"mcm","clk":"989977955","pt":1580492946093,"mc":[{"id":"1.168133553","rc":[{"batl":[[0,740,9],[1,760,3.23]],"ltp":0.0,"tv":0.0,"id":27227336},{"batl":[[0,740,9],[1,760,3.23]],"ltp":0.0,"tv":0.0,"id":21641292}]}]}
{"op":"mcm","clk":"989978379","pt":1580492950311,"mc":[{"id":"1.168133553","rc":[{"batb":[[0,2.98,1.99],[1,2.96,2.32],[2,2.94,5.02]],"ltp":0.0,"tv":0.0,"id":27227336},{"batb":[[0,2.5,1.99],[1,2.48,5.02]],"ltp":0.0,"tv":0.0,"id":21641292}]}]}
{"op":"mcm","clk":"989981667","pt":1580492982324,"mc":[{"id":"1.168133553","rc":[{"batb":[[0,2.98,2.54]],"ltp":0.0,"tv":0.0,"id":27227336},{"batb":[[0,1.26,10],[1,1.25,75.87],[2,1.22,6]],"batl":[[0,1.45,2]],"ltp":1.41,"tv":101.9,"id":16325787}]}]}
{"op":"mcm","clk":"989981962","pt":1580492985434,"mc":[{"id":"1.168133553","rc":[{"batb":[[0,1.27,33.77],[1,1.26,10],[2,1.25,75.87]],"ltp":1.41,"tv":101.9,"id":16325787}]}]}
{"op":"mcm","clk":"989983995","pt":1580493005898,"mc":[{"id":"1.168133553","rc":[{"batl":[[0,1.44,44],[1,1.45,2],[2,1.46,23.03]],"ltp":1.41,"tv":101.9,"id":16325787}]}]}
{"op":"mcm","clk":"989986135","pt":1580493027198,"mc":[{"id":"1.168133553","rc":[{"batb":[[0,3,1.98],[1,2.98,2.54],[2,2.96,2.32]],"ltp":0.0,"tv":0.0,"id":27227336},{"batb":[[0,2.52,1.98],[1,2.5,1.99],[2,2.48,3.03]],"ltp":0.0,"tv":0.0,"id":21641292}]}]}
{"op":"mcm","clk":"989988024","pt":1580493044199,"mc":[{"id":"1.168133553","rc":[{"batb":[[2,2.96,5.32]],"ltp":0.0,"tv":0.0,"id":27227336},{"batb":[[0,1.28,3],[1,1.27,33.77],[2,1.26,10]],"ltp":1.41,"tv":101.9,"id":16325787}]}]}
{"op":"mcm","clk":"989988191","pt":1580493045202,"mc":[{"id":"1.168133553","rc":[{"batb":[[1,1.26,10],[2,1.25,75.87]],"ltp":1.41,"tv":101.9,"id":16325787}]}]}
{"op":"mcm","clk":"989988361","pt":1580493046518,"mc":[{"id":"1.168133553","rc":[{"batb":[[0,3,8.65]],"ltp":0.0,"tv":0.0,"id":27227336},{"batb":[[0,2.52,9.92]],"ltp":0.0,"tv":0.0,"id":21641292},{"batl":[[0,1.43,2],[1,1.44,44]],"ltp":1.41,"tv":101.9,"id":16325787}]}]}
{"op":"mcm","clk":"989988692","pt":1580493048800,"mc":[{"id":"1.168133553","rc":[{"batb":[[2,2.96,3]],"ltp":0.0,"tv":0.0,"id":27227336}]}]}
{"op":"mcm","clk":"989988922","pt":1580493050998,"mc":[{"id":"1.168133553","rc":[{"batb":[[0,3.05,2.22],[1,3,8.65],[2,2.98,2.54]],"ltp":0.0,"tv":0.0,"id":27227336},{"batb":[[0,2.54,2.96],[1,2.52,9.92],[2,2.5,1.99]],"ltp":0.0,"tv":0.0,"id":21641292}]}]}
{"op":"mcm","clk":"989989549","pt":1580493056529,"mc":[{"id":"1.168133553","rc":[{"batb":[[2,2.96,3.55]],"ltp":0.0,"tv":0.0,"id":27227336}]}]}
{"op":"mcm","clk":"989989658","pt":1580493057431,"mc":[{"id":"1.168133553","rc":[{"batb":[[0,3.1,1.99],[1,3.05,2.22],[2,3,8.65]],"ltp":0.0,"tv":0.0,"id":27227336},{"batb":[[0,2.56,1.99],[1,2.54,2.96],[2,2.52,9.92]],"ltp":0.0,"tv":0.0,"id":21641292}]}]}
{"op":"mcm","clk":"989993086","pt":1580493088547,"mc":[{"id":"1.168133553","rc":[{"batb":[[0,1.27,3]],"ltp":1.41,"tv":101.9,"id":16325787}]}]}
{"op":"mcm","clk":"989993898","pt":1580493096560,"mc":[{"id":"1.168133553","rc":[{"batb":[[0,3.25,33],[1,2.56,1.99],[2,2.54,2.96]],"ltp":0.0,"tv":0.0,"id":21641292}]}]}
{"op":"mcm","clk":"989994687","pt":1580493104978,"mc":[{"id":"1.168133553","rc":[{"batb":[[0,1.28,33.5],[1,1.27,3],[2,1.26,10]],"ltp":1.41,"tv":101.9,"id":16325787}]}]}
{"op":"mcm","clk":"989995113","pt":1580493109166,"mc":[{"id":"1.168133553","rc":[{"batb":[[2,2.52,9.92]],"ltp":0.0,"tv":0.0,"id":21641292}]}]}
{"op":"mcm","clk":"989995333","pt":1580493111464,"mc":[{"id":"1.168133553","rc":[{"batb":[[2,3,1.98]],"ltp":0.0,"tv":0.0,"id":27227336},{"batb":[[0,3.3,1.98],[1,3.25,33],[2,2.56,1.99]],"ltp":0.0,"tv":0.0,"id":21641292},{"batb":[[2,1.25,75.87]],"ltp":1.41,"tv":101.9,"id":16325787}]}]}
{"op":"mcm","clk":"989995871","pt":1580493116546,"mc":[{"id":"1.168133553","rc":[{"batb":[[2,1.26,6]],"ltp":1.41,"tv":101.9,"id":16325787}]}]}
{"op":"mcm","clk":"989996410","pt":1580493122269,"mc":[{"id":"1.168133553","rc":[{"batb":[[0,1.29,3],[1,1.28,33.5]],"ltp":1.41,"tv":101.9,"id":16325787}]}]}
{"op":"mcm","clk":"989996530","pt":1580493123473,"mc":[{"id":"1.168133553","rc":[{"batb":[[0,4,34],[1,3.1,1.99],[2,3.05,2.22]],"ltp":0.0,"tv":0.0,"id":27227336}]}]}
{"op":"mcm","clk":"989996615","pt":1580493124368,"mc":[{"id":"1.168133553","rc":[{"batb":[[1,1.26,6],[2,1.25,75.87]],"ltp":1.41,"tv":101.9,"id":16325787}]}]}
{"op":"mcm","clk":"989997921","pt":1580493138787,"mc":[{"id":"1.168133553","rc":[{"batb":[[2,3,1.98]],"ltp":0.0,"tv":0.0,"id":27227336}]}]}
{"op":"mcm","clk":"989998109","pt":1580493140774,"mc":[{"id":"1.168133553","rc":[{"batb":[[0,4.1,1.47],[1,4,34],[2,3.1,1.99]],"ltp":0.0,"tv":0.0,"id":27227336}]}]}
{"op":"mcm","clk":"990009090","pt":1580493155509,"mc":[{"id":"1.168133553","rc":[{"batb":[[0,1.27,3]],"ltp":1.41,"tv":101.9,"id":16325787}]}]}
{"op":"mcm","clk":"990009962","pt":1580493164522,"mc":[{"id":"1.168133553","rc":[{"batb":[[0,1.28,33.5],[1,1.27,3],[2,1.26,6]],"ltp":1.41,"tv":101.9,"id":16325787}]}]}
{"op":"mcm","clk":"990010171","pt":1580493167424,"mc":[{"id":"1.168133553","rc":[{"batb":[[0,4.2,1.99],[1,4.1,1.47],[2,4,34]],"ltp":0.0,"tv":0.0,"id":27227336}]}]}
{"op":"mcm","clk":"990010205","pt":1580493167850,"mc":[{"id":"1.168133553","rc":[{"batb":[[0,3.35,1.99],[1,3.3,1.98],[2,3.25,33]],"ltp":0.0,"tv":0.0,"id":21641292}]}]}
{"op":"mcm","clk":"990010439","pt":1580493170716,"mc":[{"id":"1.168133553","rc":[{"batb":[[0,4.3,1.98],[1,4.2,1.99],[2,4.1,1.47]],"ltp":0.0,"tv":0.0,"id":27227336},{"batb":[[0,3.4,1.98],[1,3.35,1.99],[2,3.3,1.98]],"ltp":0.0,"tv":0.0,"id":21641292}]}]}
{"op":"mcm","clk":"990012090","pt":1580493189465,"mc":[{"id":"1.168133553","rc":[{"batb":[[0,1.29,3],[1,1.28,33.5]],"ltp":1.41,"tv":101.9,"id":16325787}]}]}
{"op":"mcm","clk":"990013449","pt":1580493203585,"mc":[{"id":"1.168133553","rc":[{"batb":[[1,1.26,6],[2,1.25,75.87]],"ltp":1.41,"tv":101.9,"id":16325787}]}]}
{"op":"mcm","clk":"990018359","pt":1580493254472,"mc":[{"id":"1.168133553","rc":[{"batb":[[0,1.26,6],[1,1.25,75.87],[2,1.22,6]],"ltp":1.41,"tv":101.9,"id":16325787}]}]}
{"op":"mcm","clk":"990018379","pt":1580493254678,"mc":[{"id":"1.168133553","rc":[{"batb":[[0,1.27,3],[1,1.26,6],[2,1.25,75.87]],"ltp":1.41,"tv":101.9,"id":16325787}]}]}
{"op":"mcm","clk":"990019087","pt":1580493263078,"mc":[{"id":"1.168133553","rc":[{"batb":[[0,1.28,33.5],[1,1.27,3],[2,1.26,6]],"ltp":1.41,"tv":101.9,"id":16325787}]}]}
{"op":"mcm","clk":"990019554","pt":1580493268507,"mc":[{"id":"1.168133553","rc":[{"batb":[[0,1.29,3.04],[1,1.28,33.5],[2,1.27,3]],"ltp":1.41,"tv":101.9,"id":16325787}]}]}
{"op":"mcm","clk":"990019636","pt":1580493269482,"mc":[{"id":"1.168133553","rc":[{"batb":[[0,4.3,5.02]],"batl":[[0,730,3.03],[1,740,9],[2,760,0.2]],"ltp":0.0,"tv":0.0,"id":27227336}]}]}
{"op":"mcm","clk":"990019679","pt":1580493270000,"mc":[{"id":"1.168133553","rc":[{"batb":[[0,3.4,5.02]],"batl":[[0,730,3.03],[1,740,9],[2,760,0.2]],"ltp":0.0,"tv":0.0,"id":21641292}]}]}
{"op":"mcm","clk":"990020168","pt":1580493275012,"mc":[{"id":"1.168133553","rc":[{"batl":[[0,710,9],[1,730,3.03]],"ltp":0.0,"tv":0.0,"id":27227336},{"batl":[[0,710,9],[1,730,3.03]],"ltp":0.0,"tv":0.0,"id":21641292}]}]}
{"op":"mcm","clk":"990020876","pt":1580493282979,"mc":[{"id":"1.168133553","rc":[{"batb":[[1,1.27,3],[2,1.26,6]],"ltp":1.41,"tv":101.9,"id":16325787}]}]}
{"op":"mcm","clk":"990021378","pt":1580493289098,"mc":[{"id":"1.168133553","rc":[{"batb":[[2,4,34]],"ltp":0.0,"tv":0.0,"id":27227336},{"batb":[[2,3.25,33]],"ltp":0.0,"tv":0.0,"id":21641292}]}]}
{"op":"mcm","clk":"990022419","pt":1580493301537,"mc":[{"id":"1.168133553","rc":[{"batb":[[1,4,34],[2,2.66,90.55]],"ltp":0.0,"tv":0.0,"id":27227336}]}]}
{"op":"mcm","clk":"990022533","pt":1580493302436,"mc":[{"id":"1.168133553","rc":[{"batb":[[0,4.4,1.99],[1,4.3,5.02],[2,4,34]],"ltp":0.0,"tv":0.0,"id":27227336},{"batb":[[0,3.45,1.99],[1,3.4,5.02]],"ltp":0.0,"tv":0.0,"id":21641292}]}]}
{"op":"mcm","clk":"990023550","pt":1580493313550,"mc":[{"id":"1.168133553","rc":[{"batb":[[0,4.5,1.98],[1,4.4,1.99],[2,4.3,3.03]],"ltp":0.0,"tv":0.0,"id":27227336},{"batb":[[0,3.5,1.98],[1,3.45,1.99],[2,3.4,3.03]],"ltp":0.0,"tv":0.0,"id":21641292}]}]}
{"op":"mcm","clk":"990024228","pt":1580493322102,"mc":[{"id":"1.168133553","rc":[{"batb":[[1,4.4,3.33]],"ltp":0.0,"tv":0.0,"id":27227336}]}]}
{"op":"mcm","clk":"990026636","pt":1580493348708,"mc":[{"id":"1.168133553","rc":[{"batb":[[1,4.4,1.99]],"ltp":0.0,"tv":0.0,"id":27227336}]}]}
{"op":"mcm","clk":"990026888","pt":1580493351394,"mc":[{"id":"1.168133553","rc":[{"batb":[[0,4.5,3.28]],"ltp":0.0,"tv":0.0,"id":27227336}]}]}
{"op":"mcm","clk":"990036060","pt":1580493465488,"mc":[{"id":"1.168133553","rc":[{"batb":[[1,4.3,3.03],[2,4.1,3]],"ltp":0.0,"tv":0.0,"id":27227336}]}]}
{"op":"mcm","clk":"990036132","pt":1580493466168,"mc":[{"id":"1.168133553","rc":[{"batb":[[0,4.6,1.99],[1,4.5,3.28],[2,4.3,3.03]],"ltp":0.0,"tv":0.0,"id":27227336},{"batb":[[0,3.55,1.99],[1,3.5,1.98]],"ltp":0.0,"tv":0.0,"id":21641292}]}]}
{"op":"mcm","clk":"990036350","pt":1580493468861,"mc":[{"id":"1.168133553","rc":[{"batb":[[1,4.5,1.98]],"ltp":0.0,"tv":0.0,"id":27227336}]}]}
{"op":"mcm","clk":"990036545","pt":1580493471153,"mc":[{"id":"1.168133553","rc":[{"batb":[[0,4.6,3.26]],"ltp":0.0,"tv":0.0,"id":27227336}]}]}
{"op":"mcm","clk":"990040593","pt":1580493522260,"mc":[{"id":"1.168133553","rc":[{"batb":[[0,5,34],[1,4.6,3.26],[2,4.5,1.98]],"ltp":0.0,"tv":0.0,"id":27227336},{"batb":[[0,3.75,33],[1,3.55,1.99],[2,3.5,1.98]],"ltp":0.0,"tv":0.0,"id":21641292}]}]}
{"op":"mcm","clk":"990040672","pt":1580493523047,"mc":[{"id":"1.168133553","rc":[{"batb":[[0,5.1,3.92],[1,5,34],[2,4.6,3.26]],"ltp":0.0,"tv":0.0,"id":27227336},{"batb":[[0,3.8,5.26],[1,3.75,33],[2,3.55,1.99]],"ltp":0.0,"tv":0.0,"id":21641292},{"batb":[[1,1.28,10],[2,1.27,3]],"ltp":1.41,"tv":101.9,"id":16325787}]}]}
{"op":"mcm","clk":"990041173","pt":1580493529445,"mc":[{"id":"1.168133553","rc":[{"batb":[[2,4.6,1.99]],"ltp":0.0,"tv":0.0,"id":27227336}]}]}
{"op":"mcm","clk":"990041375","pt":1580493532270,"mc":[{"id":"1.168133553","rc":[{"batb":[[2,1.26,6]],"ltp":1.41,"tv":101.9,"id":16325787}]}]}
{"op":"mcm","clk":"990041762","pt":1580493537577,"mc":[{"id":"1.168133553","rc":[{"batb":[[0,1.3,32.99],[1,1.29,3.04],[2,1.28,10]],"ltp":1.41,"tv":101.9,"id":16325787}]}]}
{"op":"mcm","clk":"990042241","pt":1580493544486,"mc":[{"id":"1.168133553","rc":[{"batb":[[0,5.2,3.03],[1,5.1,3.92],[2,5,34]],"batl":[[1,760,0.2],[2,760,0]],"ltp":0.0,"tv":0.0,"id":27227336},{"batb":[[0,1.31,3.03],[1,1.3,32.99]],"ltp":1.41,"tv":101.9,"id":16325787}]}]}
{"op":"mcm","clk":"990042317","pt":1580493545387,"mc":[{"id":"1.168133553","rc":[{"batl":[[0,700,3.03],[1,710,9],[2,760,0.2]],"ltp":0.0,"tv":0.0,"id":27227336},{"batb":[[0,3.85,3.03],[1,3.8,5.26],[2,3.75,33]],"batl":[[0,700,3.03],[1,710,9]],"ltp":0.0,"tv":0.0,"id":21641292}]}]}
{"op":"mcm","clk":"990043270","pt":1580493557308,"mc":[{"id":"1.168133553","rc":[{"batb":[[1,1.28,10],[2,1.26,6]],"ltp":1.41,"tv":101.9,"id":16325787}]}]}
{"op":"mcm","clk":"990044258","pt":1580493570493,"mc":[{"id":"1.168133553","rc":[{"batl":[[0,680,9],[1,700,3.03]],"ltp":0.0,"tv":0.0,"id":27227336},{"batl":[[0,680,9],[1,700,3.03]],"ltp":0.0,"tv":0.0,"id":21641292}]}]}
{"op":"mcm","clk":"990044453","pt":1580493573222,"mc":[{"id":"1.168133553","rc":[{"batb":[[0,5.5,34],[1,5.2,3.03],[2,5.1,3.92]],"ltp":0.0,"tv":0.0,"id":27227336}]}]}
{"op":"mcm","clk":"990045948","pt":1580493594937,"mc":[{"id":"1.168133553","rc":[{"batb":[[0,5.6,1.98],[1,5.5,34],[2,5.2,3.03]],"ltp":0.0,"tv":0.0,"id":27227336},{"batb":[[0,3.9,1.98],[1,3.85,3.03],[2,3.8,5.26]],"ltp":0.0,"tv":0.0,"id":21641292}]}]}
{"op":"mcm","clk":"990046311","pt":1580493599565,"mc":[{"id":"1.168133553","rc":[{"batb":[[2,3.75,33]],"ltp":0.0,"tv":0.0,"id":21641292},{"batb":[[1,1.26,6],[2,1.25,75.87]],"ltp":1.41,"tv":101.9,"id":16325787}]}]}
{"op":"mcm","clk":"990046459","pt":1580493601284,"mc":[{"id":"1.168133553","rc":[{"batb":[[0,4,33],[1,3.9,1.98],[2,3.85,3.03]],"ltp":0.0,"tv":0.0,"id":21641292}]}]}
{"op":"mcm","clk":"990048193","pt":1580493619187,"mc":[{"id":"1.168133553","rc":[{"batb":[[0,5.6,1.98],[2,5.2,3.03]],"batl":[[1,700,3.03]],"ltp":0.0,"tv":0.0,"id":27227336},{"batb":[[1,3.9,1.98],[2,3.85,3.03]],"batl":[[1,700,3.03]],"ltp":0.0,"tv":0.0,"id":21641292},{"trd":[[1.41,69.91],[1.51,12.72]],"batb":[[0,1.31,3.03],[2,1.25,75.78]],"batl":[[2,1.46,23.03]],"ltp":1.41,"tv":101.85,"id":16325787}],"tv":101.85}]}
{"op":"mcm","clk":"990048517","pt":1580493623204,"mc":[{"id":"1.168133553","rc":[{"batb":[[0,5.6,2.95]],"ltp":0.0,"tv":0.0,"id":27227336},{"batb":[[0,4.1,1.47],[1,4,33],[2,3.9,1.98]],"ltp":0.0,"tv":0.0,"id":21641292}]}]}
{"op":"mcm","clk":"990049916","pt":1580493640203,"mc":[{"id":"1.168133553","rc":[{"batb":[[0,5.8,1.99],[1,5.6,2.95],[2,5.5,34]],"ltp":0.0,"tv":0.0,"id":27227336},{"batb":[[0,4.2,1.99],[1,4.1,1.47],[2,4,33]],"ltp":0.0,"tv":0.0,"id":21641292}]}]}
{"op":"mcm","clk":"990050714","pt":1580493649005,"mc":[{"id":"1.168133553","rc":[{"batb":[[1,5.6,1.98]],"ltp":0.0,"tv":0.0,"id":27227336}]}]}
{"op":"mcm","clk":"990050906","pt":1580493650891,"mc":[{"id":"1.168133553","rc":[{"batb":[[0,5.8,2.91]],"ltp":0.0,"tv":0.0,"id":27227336}]}]}
{"op":"mcm","clk":"990053162","pt":1580493673530,"mc":[{"id":"1.168133553","rc":[{"batb":[[0,5.9,1.2],[1,5.8,1.99],[2,5.6,1.98]],"ltp":0.0,"tv":0.0,"id":27227336}]}]}
{"op":"mcm","clk":"990053247","pt":1580493674541,"mc":[{"id":"1.168133553","rc":[{"batb":[[0,4.2,2.38]],"ltp":0.0,"tv":0.0,"id":21641292}]}]}
{"op":"mcm","clk":"990053568","pt":1580493678527,"mc":[{"id":"1.168133553","rc":[{"batb":[[0,1.27,3.03]],"ltp":1.41,"tv":101.85,"id":16325787}]}]}
{"op":"mcm","clk":"990053640","pt":1580493679539,"mc":[{"id":"1.168133553","rc":[{"batb":[[0,5.9,4.23]],"batl":[[0,670,3.03],[1,680,9]],"ltp":0.0,"tv":0.0,"id":27227336},{"batb":[[1,4,33],[2,3.9,1.98]],"ltp":0.0,"tv":0.0,"id":21641292}]}]}
{"op":"mcm","clk":"990053689","pt":1580493680127,"mc":[{"id":"1.168133553","rc":[{"batb":[[1,4.1,3.03],[2,4,33]],"batl":[[0,670,3.03],[1,680,9]],"ltp":0.0,"tv":0.0,"id":21641292}]}]}
{"op":"mcm","clk":"990053808","pt":1580493681545,"mc":[{"id":"1.168133553","rc":[{"batb":[[0,4.3,1.38],[1,4.2,2.38],[2,4.1,3.03]],"ltp":0.0,"tv":0.0,"id":21641292}]}]}
{"op":"mcm","clk":"990053879","pt":1580493682248,"mc":[{"id":"1.168133553","rc":[{"batl":[[0,650,9],[1,670,3.03]],"ltp":0.0,"tv":0.0,"id":27227336},{"batl":[[0,650,9],[1,670,3.03]],"ltp":0.0,"tv":0.0,"id":21641292}]}]}
{"op":"mcm","clk":"990055200","pt":1580493695541,"mc":[{"id":"1.168133553","rc":[{"batb":[[0,1.28,33.46],[1,1.27,3.03],[2,1.26,6]],"ltp":1.41,"tv":101.85,"id":16325787}]}]}
{"op":"mcm","clk":"990060638","pt":1580493756734,"mc":[{"id":"1.168133553","rc":[{"batb":[[0,6,34],[1,5.9,4.23],[2,5.8,1.99]],"ltp":0.0,"tv":0.0,"id":27227336},{"batb":[[0,4.5,33],[1,4.3,1.38],[2,4.2,2.38]],"ltp":0.0,"tv":0.0,"id":21641292}]}]}
{"op":"mcm","clk":"990060788","pt":1580493758527,"mc":[{"id":"1.168133553","rc":[{"batb":[[0,1.29,3.19],[1,1.28,33.46],[2,1.27,3.03]],"ltp":1.41,"tv":101.85,"id":16325787}]}]}
{"op":"mcm","clk":"990060830","pt":1580493759007,"mc":[{"id":"1.168133553","rc":[{"batb":[[0,6,34.66]],"ltp":0.0,"tv":0.0,"id":27227336},{"batb":[[0,4.5,33.89]],"ltp":0.0,"tv":0.0,"id":21641292}]}]}
{"op":"mcm","clk":"990061846","pt":1580493769261,"mc":[{"id":"1.168133553","rc":[{"batb":[[1,5.9,3.31]],"ltp":0.0,"tv":0.0,"id":27227336},{"batb":[[1,4.2,2.38],[2,4.1,3.03]],"ltp":0.0,"tv":0.0,"id":21641292}]}]}
{"op":"mcm","clk":"990062729","pt":1580493776973,"mc":[{"id":"1.168133553","rc":[{"batb":[[1,1.27,3.03],[2,1.26,6]],"ltp":1.41,"tv":101.85,"id":16325787}]}]}
{"op":"mcm","clk":"990063450","pt":1580493783165,"mc":[{"id":"1.168133553","rc":[{"batb":[[0,6.2,2.65],[1,6,34],[2,5.9,3.31]],"ltp":0.0,"tv":0.0,"id":27227336},{"batb":[[0,4.6,2.88],[1,4.5,33],[2,4.2,2.38]],"ltp":0.0,"tv":0.0,"id":21641292}]}]}
{"op":"mcm","clk":"990070943","pt":1580493873350,"mc":[{"id":"1.168133553","rc":[{"batb":[[0,6.4,1.99],[1,6.2,2.65],[2,6,34]],"ltp":0.0,"tv":0.0,"id":27227336}]}]}
{"op":"mcm","clk":"990070994","pt":1580493873822,"mc":[{"id":"1.168133553","rc":[{"batb":[[0,4.7,1.99],[1,4.6,2.88],[2,4.5,33]],"ltp":0.0,"tv":0.0,"id":21641292}]}]}
{"op":"mcm","clk":"990074695","pt":1580493914390,"mc":[{"id":"1.168133553","rc":[{"batb":[[1,1.26,6],[2,1.25,75.78]],"ltp":1.41,"tv":101.85,"id":16325787}]}]}
{"op":"mcm","clk":"990074784","pt":1580493915492,"mc":[{"id":"1.168133553","rc":[{"batb":[[0,6.4,5.02]],"batl":[[0,640,3.03],[1,650,9]],"ltp":0.0,"tv":0.0,"id":27227336},{"batb":[[0,1.3,3.03],[1,1.29,3.19],[2,1.26,6]],"ltp":1.41,"tv":101.85,"id":16325787}]}]}
{"op":"mcm","clk":"990074824","pt":1580493916015,"mc":[{"id":"1.168133553","rc":[{"batb":[[0,4.7,5.02]],"batl":[[0,640,3.03],[1,650,9]],"ltp":0.0,"tv":0.0,"id":21641292}]}]}
{"op":"mcm","clk":"990075138","pt":1580493919442,"mc":[{"id":"1.168133553","rc":[{"batb":[[0,1.31,32.7],[1,1.3,3.03],[2,1.29,3.19]],"ltp":1.41,"tv":101.85,"id":16325787}]}]}
{"op":"mcm","clk":"990075392","pt":1580493922039,"mc":[{"id":"1.168133553","rc":[{"batb":[[0,6.4,5.83]],"ltp":0.0,"tv":0.0,"id":27227336},{"batb":[[0,4.8,1.2],[1,4.7,5.02],[2,4.6,2.88]],"ltp":0.0,"tv":0.0,"id":21641292}]}]}
{"op":"mcm","clk":"990077546","pt":1580493943959,"mc":[{"id":"1.168133553","rc":[{"batl":[[0,620,9],[1,640,3.03]],"ltp":0.0,"tv":0.0,"id":27227336},{"batl":[[0,620,9],[1,640,3.03]],"ltp":0.0,"tv":0.0,"id":21641292}]}]}
{"op":"mcm","clk":"990081163","pt":1580493981428,"mc":[{"id":"1.168133553","rc":[{"batb":[[0,6.4,15.83]],"ltp":0.0,"tv":0.0,"id":27227336}]}]}
{"op":"mcm","clk":"990085024","pt":1580494023262,"mc":[{"id":"1.168133553","rc":[{"batb":[[0,6.6,2.79],[1,6.4,15.02],[2,6,34.66]],"ltp":0.0,"tv":0.0,"id":27227336},{"batb":[[0,4.8,3.18],[2,4.5,33.89]],"ltp":0.0,"tv":0.0,"id":21641292}]}]}
{"op":"mcm","clk":"990086749","pt":1580494041557,"mc":[{"id":"1.168133553","rc":[{"batb":[[0,6.8,1.99],[1,6.6,2.79],[2,6.4,13.03]],"ltp":0.0,"tv":0.0,"id":27227336},{"batb":[[1,4.7,3.03]],"ltp":0.0,"tv":0.0,"id":21641292}]}]}
{"op":"mcm","clk":"990086757","pt":1580494041663,"mc":[{"id":"1.168133553","rc":[{"batb":[[0,4.9,1.99],[1,4.8,3.18],[2,4.7,3.03]],"ltp":0.0,"tv":0.0,"id":21641292}]}]}
{"op":"mcm","clk":"990098779","pt":1580494069300,"mc":[{"id":"1.168133553","rc":[{"batb":[[1,6.6,1.98]],"ltp":0.0,"tv":0.0,"id":27227336},{"batb":[[1,4.8,1.98]],"ltp":0.0,"tv":0.0,"id":21641292}]}]}
{"op":"mcm","clk":"990103992","pt":1580494124409,"mc":[{"id":"1.168133553","rc":[{"batb":[[1,1.29,3.19],[2,1.26,6]],"ltp":1.41,"tv":101.85,"id":16325787}]}]}
{"op":"mcm","clk":"990104093","pt":1580494125413,"mc":[{"id":"1.168133553","rc":[{"batb":[[0,6.8,5.02],[2,6.4,10]],"batl":[[0,610,3.03],[1,620,9]],"ltp":0.0,"tv":0.0,"id":27227336},{"batb":[[0,1.32,3.03],[1,1.31,32.7],[2,1.29,3.19]],"ltp":1.41,"tv":101.85,"id":16325787}]}]}
{"op":"mcm","clk":"990104162","pt":1580494126045,"mc":[{"id":"1.168133553","rc":[{"batb":[[0,4.9,5.02],[2,4.5,33.89]],"batl":[[0,610,3.03],[1,620,9]],"ltp":0.0,"tv":0.0,"id":21641292}]}]}
{"op":"mcm","clk":"990105414","pt":1580494137988,"mc":[{"id":"1.168133553","rc":[{"batb":[[1,1.29,3.19],[2,1.26,6]],"ltp":1.41,"tv":101.85,"id":16325787}]}]}
{"op":"mcm","clk":"990105633","pt":1580494140164,"mc":[{"id":"1.168133553","rc":[{"batl":[[0,590,9],[1,610,3.03]],"ltp":0.0,"tv":0.0,"id":27227336},{"batl":[[0,590,9],[1,610,3.03]],"ltp":0.0,"tv":0.0,"id":21641292}]}]}
{"op":"mcm","clk":"990106294","pt":1580494146514,"mc":[{"id":"1.168133553","rc":[{"batb":[[2,4.5,33]],"ltp":0.0,"tv":0.0,"id":21641292}]}]}
{"op":"mcm","clk":"990107402","pt":1580494159412,"mc":[{"id":"1.168133553","rc":[{"batb":[[0,4.9,5.35]],"ltp":0.0,"tv":0.0,"id":21641292}]}]}
{"op":"mcm","clk":"990110521","pt":1580494194560,"mc":[{"id":"1.168133553","rc":[{"batb":[[0,4.9,3.36]],"ltp":0.0,"tv":0.0,"id":21641292}]}]}
{"op":"mcm","clk":"990110556","pt":1580494194937,"mc":[{"id":"1.168133553","rc":[{"batb":[[0,5.1,1.99],[1,4.9,3.36],[2,4.8,1.98]],"ltp":0.0,"tv":0.0,"id":21641292}]}]}
{"op":"mcm","clk":"990112298","pt":1580494214804,"mc":[{"id":"1.168133553","rc":[{"batb":[[0,7,1.98],[1,6.8,5.02]],"ltp":0.0,"tv":0.0,"id":27227336},{"batb":[[0,5.2,1.98],[1,5.1,1.99],[2,4.9,3.36]],"ltp":0.0,"tv":0.0,"id":21641292}]}]}
{"op":"mcm","clk":"990112951","pt":1580494221502,"mc":[{"id":"1.168133553","rc":[{"batb":[[0,5.3,1.06],[1,5.2,1.98],[2,5.1,1.99]],"ltp":0.0,"tv":0.0,"id":21641292}]}]}
{"op":"mcm","clk":"990125199","pt":1580494357413,"mc":[{"id":"1.168133553","rc":[{"batb":[[0,1.29,3.19],[1,1.26,6],[2,1.25,75.78]],"ltp":1.41,"tv":101.85,"id":16325787}]}]}
{"op":"mcm","clk":"990125270","pt":1580494358193,"mc":[{"id":"1.168133553","rc":[{"batl":[[0,580,3.03],[1,590,9]],"ltp":0.0,"tv":0.0,"id":27227336},{"batl":[[0,580,3.03],[1,590,9]],"ltp":0.0,"tv":0.0,"id":21641292},{"batb":[[0,1.3,3.03],[1,1.29,3.19],[2,1.26,6]],"ltp":1.41,"tv":101.85,"id":16325787}]}]}
{"op":"mcm","clk":"990125590","pt":1580494361702,"mc":[{"id":"1.168133553","rc":[{"batb":[[0,1.31,32.7],[1,1.3,3.03],[2,1.29,3.19]],"ltp":1.41,"tv":101.85,"id":16325787}]}]}
{"op":"mcm","clk":"990125909","pt":1580494365443,"mc":[{"id":"1.168133553","rc":[{"batb":[[1,6.8,3.03]],"ltp":0.0,"tv":0.0,"id":27227336},{"batb":[[2,4.9,3.36]],"ltp":0.0,"tv":0.0,"id":21641292}]}]}
{"op":"mcm","clk":"990126322","pt":1580494370456,"mc":[{"id":"1.168133553","rc":[{"batl":[[0,560,9],[1,580,3.03]],"ltp":0.0,"tv":0.0,"id":27227336},{"batl":[[0,560,9],[1,580,3.03]],"ltp":0.0,"tv":0.0,"id":21641292}]}]}
{"op":"mcm","clk":"990128966","pt":1580494400903,"mc":[{"id":"1.168133553","rc":[{"batb":[[1,5,2.31],[2,4.9,3.03]],"ltp":0.0,"tv":0.0,"id":21641292}]}]}
{"op":"mcm","clk":"990140016","pt":1580494519449,"mc":[{"id":"1.168133553","rc":[{"batb":[[0,1.32,3.03],[1,1.31,32.7]],"ltp":1.41,"tv":101.85,"id":16325787}]}]}
{"op":"mcm","clk":"990140110","pt":1580494520569,"mc":[{"id":"1.168133553","rc":[{"batb":[[1,6.6,3.03]],"batl":[[0,550,3.03],[1,560,9]],"ltp":0.0,"tv":0.0,"id":27227336},{"batl":[[1,760,0.2],[2,760,0]],"ltp":0.0,"tv":0.0,"id":21641292}]}]}
{"op":"mcm","clk":"990140213","pt":1580494521497,"mc":[{"id":"1.168133553","rc":[{"batl":[[0,550,3.03],[1,560,9],[2,760,0.2]],"ltp":0.0,"tv":0.0,"id":21641292}]}]}
{"op":"mcm","clk":"990140641","pt":1580494526952,"mc":[{"id":"1.168133553","rc":[{"batb":[[1,1.29,3.19],[2,1.26,6]],"ltp":1.41,"tv":101.85,"id":16325787}]}]}
{"op":"mcm","clk":"990141290","pt":1580494534387,"mc":[{"id":"1.168133553","rc":[{"batl":[[0,530,9],[1,550,3.03]],"ltp":0.0,"tv":0.0,"id":27227336},{"batl":[[0,530,9],[1,550,3.03]],"ltp":0.0,"tv":0.0,"id":21641292}]}]}
{"op":"mcm","clk":"990155728","pt":1580494678532,"mc":[{"id":"1.168133553","rc":[{"batl":[[0,520,3.03],[1,530,9]],"ltp":0.0,"tv":0.0,"id":27227336},{"batl":[[1,760,0.2],[2,760,0]],"ltp":0.0,"tv":0.0,"id":21641292},{"batb":[[0,1.3,3.03]],"ltp":1.41,"tv":101.85,"id":16325787}]}]}
{"op":"mcm","clk":"990155787","pt":1580494679159,"mc":[{"id":"1.168133553","rc":[{"batl":[[0,520,3.03],[1,530,9],[2,760,0.2]],"ltp":0.0,"tv":0.0,"id":21641292}]}]}
{"op":"mcm","clk":"990156628","pt":1580494687544,"mc":[{"id":"1.168133553","rc":[{"batb":[[0,6.8,1.98]],"ltp":0.0,"tv":0.0,"id":27227336}]}]}
{"op":"mcm","clk":"990156808","pt":1580494689364,"mc":[{"id":"1.168133553","rc":[{"batb":[[0,7,1.99],[1,6.8,1.98],[2,6.6,3.03]],"ltp":0.0,"tv":0.0,"id":27227336},{"batb":[[0,5.4,1.99],[1,5.3,1.06],[2,5,2.31]],"ltp":0.0,"tv":0.0,"id":21641292}]}]}
{"op":"mcm","clk":"990157285","pt":1580494693573,"mc":[{"id":"1.168133553","rc":[{"batb":[[0,1.31,32.7],[1,1.3,3.03],[2,1.29,3.19]],"ltp":1.41,"tv":101.85,"id":16325787}]}]}
{"op":"mcm","clk":"990157543","pt":1580494696272,"mc":[{"id":"1.168133553","rc":[{"batl":[[0,500,9],[1,520,3.03]],"ltp":0.0,"tv":0.0,"id":27227336},{"batl":[[0,500,9],[1,520,3.03]],"ltp":0.0,"tv":0.0,"id":21641292}]}]}
{"op":"mcm","clk":"990157862","pt":1580494699177,"mc":[{"id":"1.168133553","rc":[{"batb":[[1,5,2.31],[2,4.9,3.03]],"ltp":0.0,"tv":0.0,"id":21641292}]}]}
{"op":"mcm","clk":"990164620","pt":1580494765529,"mc":[{"id":"1.168133553","rc":[{"batb":[[2,6.4,10]],"ltp":0.0,"tv":0.0,"id":27227336},{"batb":[[0,1.32,3.03],[1,1.31,32.7]],"ltp":1.41,"tv":101.85,"id":16325787}]}]}
{"op":"mcm","clk":"990164730","pt":1580494766521,"mc":[{"id":"1.168133553","rc":[{"batb":[[0,7,5.02]],"batl":[[0,490,3.03],[1,500,9]],"ltp":0.0,"tv":0.0,"id":27227336},{"batl":[[0,490,3.03],[1,500,9]],"ltp":0.0,"tv":0.0,"id":21641292}]}]}
{"op":"mcm","clk":"990165191","pt":1580494771404,"mc":[{"id":"1.168133553","rc":[{"batl":[[0,1.43,6]],"ltp":1.41,"tv":101.85,"id":16325787}]}]}
{"op":"mcm","clk":"990165737","pt":1580494777398,"mc":[{"id":"1.168133553","rc":[{"batb":[[1,1.29,3.19],[2,1.26,6]],"ltp":1.41,"tv":101.85,"id":16325787}]}]}
{"op":"mcm","clk":"990167442","pt":1580494794460,"mc":[{"id":"1.168133553","rc":[{"batl":[[0,470,9],[1,490,3.03]],"ltp":0.0,"tv":0.0,"id":27227336},{"batl":[[0,470,9],[1,490,3.03]],"ltp":0.0,"tv":0.0,"id":21641292}]}]}
{"op":"mcm","clk":"990167542","pt":1580494795465,"mc":[{"id":"1.168133553","rc":[{"batb":[[2,6.6,3]],"ltp":0.0,"tv":0.0,"id":27227336},{"batb":[[2,1.27,3]],"ltp":1.41,"tv":101.85,"id":16325787}]}]}
{"op":"mcm","clk":"990170418","pt":1580494821790,"mc":[{"id":"1.168133553","rc":[{"batb":[[0,5.5,1.01],[1,5.4,1.99],[2,5,2.31]],"ltp":0.0,"tv":0.0,"id":21641292}]}]}
{"op":"mcm","clk":"990171659","pt":1580494833404,"mc":[{"id":"1.168133553","rc":[{"batb":[[0,7,3.03]],"ltp":0.0,"tv":0.0,"id":27227336}]}]}
{"op":"mcm","clk":"990171694","pt":1580494833726,"mc":[{"id":"1.168133553","rc":[{"batb":[[1,5,2.31],[2,4.9,3.03]],"ltp":0.0,"tv":0.0,"id":21641292}]}]}
{"op":"mcm","clk":"990174621","pt":1580494861123,"mc":[{"id":"1.168133553","rc":[{"batl":[[0,470,9.2],[2,760,0]],"ltp":0.0,"tv":0.0,"id":27227336},{"batl":[[0,470,9.2],[2,760,0]],"ltp":0.0,"tv":0.0,"id":21641292}]}]}
{"op":"mcm","clk":"990176669","pt":1580494880537,"mc":[{"id":"1.168133553","rc":[{"batb":[[0,6.8,1.98],[1,6.6,3],[2,6.4,10]],"ltp":0.0,"tv":0.0,"id":27227336},{"batb":[[0,1.3,3.03]],"batl":[[0,1.42,3.03],[1,1.43,6],[2,1.44,44]],"ltp":1.41,"tv":101.85,"id":16325787}]}]}
{"op":"mcm","clk":"990176756","pt":1580494881467,"mc":[{"id":"1.168133553","rc":[{"batb":[[0,6.8,5.01]],"batl":[[0,460,3.23],[1,470,9]],"ltp":0.0,"tv":0.0,"id":27227336},{"batl":[[0,460,3.23],[1,470,9]],"ltp":0.0,"tv":0.0,"id":21641292}]}]}
{"op":"mcm","clk":"990176825","pt":1580494881969,"mc":[{"id":"1.168133553","rc":[{"batb":[[0,1.31,32.7],[1,1.3,3.03],[2,1.29,3.19]],"ltp":1.41,"tv":101.85,"id":16325787}]}]}
{"op":"mcm","clk":"990178199","pt":1580494894564,"mc":[{"id":"1.168133553","rc":[{"batl":[[0,440,9],[1,460,3.23]],"ltp":0.0,"tv":0.0,"id":27227336},{"batl":[[0,440,9],[1,460,3.23]],"ltp":0.0,"tv":0.0,"id":21641292}]}]}
{"op":"mcm","clk":"990178268","pt":1580494895152,"mc":[{"id":"1.168133553","rc":[{"batl":[[0,440,9.2],[1,460,3.03]],"ltp":0.0,"tv":0.0,"id":27227336},{"batl":[[0,440,9.2],[1,460,3.03]],"ltp":0.0,"tv":0.0,"id":21641292}]}]}
{"op":"mcm","clk":"990178885","pt":1580494901275,"mc":[{"id":"1.168133553","rc":[{"batl":[[1,1.43,2]],"ltp":1.41,"tv":101.85,"id":16325787}]}]}
{"op":"mcm","clk":"990179878","pt":1580494911548,"mc":[{"id":"1.168133553","rc":[{"batb":[[0,6.8,5.77]],"ltp":0.0,"tv":0.0,"id":27227336}]}]}
{"op":"mcm","clk":"990181310","pt":1580494925512,"mc":[{"id":"1.168133553","rc":[{"batl":[[1,1.44,44],[2,1.46,20]],"ltp":1.41,"tv":101.85,"id":16325787}]}]}
{"op":"mcm","clk":"990183896","pt":1580494948446,"mc":[{"id":"1.168133553","rc":[{"batl":[[0,1.41,4],[1,1.42,3.03],[2,1.44,44]],"ltp":1.41,"tv":101.85,"id":16325787}]}]}
{"op":"mcm","clk":"990200194","pt":1580495020507,"mc":[{"id":"1.168133553","rc":[{"batb":[[1,1.29,3.19],[2,1.26,6]],"ltp":1.41,"tv":101.85,"id":16325787}]}]}
{"op":"mcm","clk":"990200291","pt":1580495021500,"mc":[{"id":"1.168133553","rc":[{"batl":[[0,430,3.23],[1,440,9]],"ltp":0.0,"tv":0.0,"id":27227336},{"batl":[[1,460,0]],"ltp":0.0,"tv":0.0,"id":21641292},{"batb":[[0,1.32,3.03],[1,1.31,32.7],[2,1.29,3.19]],"batl":[[0,1.4,3.03],[1,1.41,4]],"ltp":1.41,"tv":101.85,"id":16325787}]}]}
{"op":"mcm","clk":"990200302","pt":1580495021607,"mc":[{"id":"1.168133553","rc":[{"batl":[[0,430,3.23],[1,440,9]],"ltp":0.0,"tv":0.0,"id":21641292}]}]}
{"op":"mcm","clk":"990200586","pt":1580495025016,"mc":[{"id":"1.168133553","rc":[{"batl":[[0,410,9],[1,430,3.23]],"ltp":0.0,"tv":0.0,"id":27227336},{"batl":[[0,410,9],[1,430,3.23]],"ltp":0.0,"tv":0.0,"id":21641292}]}]}
{"op":"mcm","clk":"990200716","pt":1580495026416,"mc":[{"id":"1.168133553","rc":[{"batb":[[1,1.29,3.19],[2,1.26,6]],"ltp":1.41,"tv":101.85,"id":16325787}]}]}
{"op":"mcm","clk":"990201192","pt":1580495031513,"mc":[{"id":"1.168133553","rc":[{"batl":[[0,410,9.2],[1,430,3.03]],"ltp":0.0,"tv":0.0,"id":27227336},{"batl":[[0,410,9.2],[1,430,3.03]],"ltp":0.0,"tv":0.0,"id":21641292},{"batl":[[1,1.44,44],[2,1.46,20]],"ltp":1.41,"tv":101.85,"id":16325787}]}]}
{"op":"mcm","clk":"990201297","pt":1580495032511,"mc":[{"id":"1.168133553","rc":[{"batb":[[2,1.27,3]],"batl":[[0,1.39,4],[1,1.4,3.03],[2,1.44,44]],"ltp":1.41,"tv":101.85,"id":16325787}]}]}
{"op":"mcm","clk":"990209721","pt":1580495117538,"mc":[{"id":"1.168133553","rc":[{"batl":[[1,430,0]],"ltp":0.0,"tv":0.0,"id":27227336},{"batb":[[0,1.3,3.03]],"ltp":1.41,"tv":101.85,"id":16325787}]}]}
{"op":"mcm","clk":"990209805","pt":1580495118536,"mc":[{"id":"1.168133553","rc":[{"batl":[[0,400,3.23],[1,410,9]],"ltp":0.0,"tv":0.0,"id":27227336},{"batl":[[0,400,3.23],[1,410,9]],"ltp":0.0,"tv":0.0,"id":21641292}]}]}
{"op":"mcm","clk":"990210119","pt":1580495122150,"mc":[{"id":"1.168133553","rc":[{"batl":[[0,380,9],[1,400,3.23]],"ltp":0.0,"tv":0.0,"id":27227336},{"batl":[[0,380,9],[1,400,3.23]],"ltp":0.0,"tv":0.0,"id":21641292}]}]}
{"op":"mcm","clk":"990210387","pt":1580495124879,"mc":[{"id":"1.168133553","rc":[{"batb":[[0,1.31,32.7],[1,1.3,3.03],[2,1.29,3.19]],"ltp":1.41,"tv":101.85,"id":16325787}]}]}
{"op":"mcm","clk":"990210633","pt":1580495127563,"mc":[{"id":"1.168133553","rc":[{"batl":[[1,400,3.03]],"ltp":0.0,"tv":0.0,"id":27227336},{"batl":[[1,400,3.03]],"ltp":0.0,"tv":0.0,"id":21641292}]}]}
{"op":"mcm","clk":"990210730","pt":1580495128558,"mc":[{"id":"1.168133553","rc":[{"batl":[[0,380,9.2]],"ltp":0.0,"tv":0.0,"id":27227336},{"batl":[[0,380,9.2]],"ltp":0.0,"tv":0.0,"id":21641292}]}]}
{"op":"mcm","clk":"990215303","pt":1580495175415,"mc":[{"id":"1.168133553","rc":[{"batl":[[1,400,0]],"ltp":0.0,"tv":0.0,"id":27227336},{"batb":[[0,1.32,3.03],[1,1.31,32.7]],"ltp":1.41,"tv":101.85,"id":16325787}]}]}
{"op":"mcm","clk":"990215402","pt":1580495176418,"mc":[{"id":"1.168133553","rc":[{"batl":[[0,370,3.23],[1,380,9]],"ltp":0.0,"tv":0.0,"id":27227336},{"batl":[[0,370,3.23],[1,380,9]],"ltp":0.0,"tv":0.0,"id":21641292}]}]}
{"op":"mcm","clk":"990216235","pt":1580495184520,"mc":[{"id":"1.168133553","rc":[{"batb":[[1,1.29,3.19],[2,1.26,6]],"ltp":1.41,"tv":101.85,"id":16325787}]}]}
{"op":"mcm","clk":"990216470","pt":1580495187155,"mc":[{"id":"1.168133553","rc":[{"batl":[[0,350,9],[1,370,3.23]],"ltp":0.0,"tv":0.0,"id":27227336},{"batl":[[0,350,9],[1,370,3.23]],"ltp":0.0,"tv":0.0,"id":21641292}]}]}
{"op":"mcm","clk":"990216588","pt":1580495188566,"mc":[{"id":"1.168133553","rc":[{"batl":[[1,370,3.03]],"ltp":0.0,"tv":0.0,"id":27227336},{"batl":[[1,370,3.03]],"ltp":0.0,"tv":0.0,"id":21641292}]}]}
{"op":"mcm","clk":"990216611","pt":1580495188875,"mc":[{"id":"1.168133553","rc":[{"batl":[[0,350,9.2]],"ltp":0.0,"tv":0.0,"id":27227336},{"batl":[[0,350,9.2]],"ltp":0.0,"tv":0.0,"id":21641292}]}]}
{"op":"mcm","clk":"990216835","pt":1580495191375,"mc":[{"id":"1.168133553","rc":[{"batb":[[2,1.27,3]],"ltp":1.41,"tv":101.85,"id":16325787}]}]}
{"op":"mcm","clk":"990223035","pt":1580495258550,"mc":[{"id":"1.168133553","rc":[{"batl":[[0,340,3.23],[1,350,9]],"ltp":0.0,"tv":0.0,"id":27227336},{"batl":[[1,370,0]],"ltp":0.0,"tv":0.0,"id":21641292},{"batb":[[0,1.3,3.03]],"ltp":1.41,"tv":101.85,"id":16325787}]}]}
{"op":"mcm","clk":"990223045","pt":1580495258656,"mc":[{"id":"1.168133553","rc":[{"batl":[[0,340,3.23],[1,350,9]],"ltp":0.0,"tv":0.0,"id":21641292}]}]}
{"op":"mcm","clk":"990223559","pt":1580495264570,"mc":[{"id":"1.168133553","rc":[{"batb":[[0,1.31,32.7],[1,1.3,3.03],[2,1.29,3.19]],"ltp":1.41,"tv":101.85,"id":16325787}]}]}
{"op":"mcm","clk":"990225314","pt":1580495285549,"mc":[{"id":"1.168133553","rc":[{"batl":[[0,320,9],[1,340,3.23]],"ltp":0.0,"tv":0.0,"id":27227336},{"batl":[[0,320,9],[1,340,3.23]],"ltp":0.0,"tv":0.0,"id":21641292}]}]}
{"op":"mcm","clk":"990225862","pt":1580495292010,"mc":[{"id":"1.168133553","rc":[{"batl":[[0,320,9.2],[1,340,3.03]],"ltp":0.0,"tv":0.0,"id":27227336},{"batl":[[0,320,9.2],[1,340,3.03]],"ltp":0.0,"tv":0.0,"id":21641292}]}]}
{"op":"mcm","clk":"990230788","pt":1580495353386,"mc":[{"id":"1.168133553","rc":[{"batl":[[0,310,3.23],[1,320,9]],"ltp":0.0,"tv":0.0,"id":27227336},{"batl":[[1,340,0]],"ltp":0.0,"tv":0.0,"id":21641292},{"batb":[[0,1.32,3.03],[1,1.31,32.7]],"ltp":1.41,"tv":101.85,"id":16325787}]}]}
{"op":"mcm","clk":"990230867","pt":1580495354291,"mc":[{"id":"1.168133553","rc":[{"batl":[[0,310,3.23],[1,320,9]],"ltp":0.0,"tv":0.0,"id":21641292}]}]}
{"op":"mcm","clk":"990231833","pt":1580495365591,"mc":[{"id":"1.168133553","rc":[{"batb":[[1,1.29,3.19],[2,1.26,6]],"ltp":1.41,"tv":101.85,"id":16325787}]}]}
{"op":"mcm","clk":"990231964","pt":1580495367327,"mc":[{"id":"1.168133553","rc":[{"batb":[[2,1.27,3]],"ltp":1.41,"tv":101.85,"id":16325787}]}]}
{"op":"mcm","clk":"990233325","pt":1580495384531,"mc":[{"id":"1.168133553","rc":[{"batl":[[0,290,9],[1,310,3.23]],"ltp":0.0,"tv":0.0,"id":27227336},{"batl":[[0,290,9],[1,310,3.23]],"ltp":0.0,"tv":0.0,"id":21641292}]}]}
{"op":"mcm","clk":"990233540","pt":1580495386918,"mc":[{"id":"1.168133553","rc":[{"batl":[[0,290,9.2],[1,310,3.03]],"ltp":0.0,"tv":0.0,"id":27227336},{"batl":[[0,290,9.2],[1,310,3.03]],"ltp":0.0,"tv":0.0,"id":21641292}]}]}
{"op":"mcm","clk":"990240778","pt":1580495476447,"mc":[{"id":"1.168133553","rc":[{"batl":[[0,280,3.23],[1,290,9]],"ltp":0.0,"tv":0.0,"id":27227336},{"batl":[[1,310,0]],"ltp":0.0,"tv":0.0,"id":21641292},{"batb":[[0,1.3,3.03]],"ltp":1.41,"tv":101.85,"id":16325787}]}]}
{"op":"mcm","clk":"990240855","pt":1580495477444,"mc":[{"id":"1.168133553","rc":[{"batl":[[0,280,3.23],[1,290,9]],"ltp":0.0,"tv":0.0,"id":21641292}]}]}
{"op":"mcm","clk":"990241231","pt":1580495481546,"mc":[{"id":"1.168133553","rc":[{"batl":[[0,260,9],[1,280,3.23]],"ltp":0.0,"tv":0.0,"id":27227336},{"batl":[[0,260,9],[1,280,3.23]],"ltp":0.0,"tv":0.0,"id":21641292}]}]}
{"op":"mcm","clk":"990241278","pt":1580495482230,"mc":[{"id":"1.168133553","rc":[{"batl":[[0,260,9.2],[1,280,3.03]],"ltp":0.0,"tv":0.0,"id":27227336},{"batl":[[0,260,9.2],[1,280,3.03]],"ltp":0.0,"tv":0.0,"id":21641292}]}]}
{"op":"mcm","clk":"990241546","pt":1580495485850,"mc":[{"id":"1.168133553","rc":[{"batb":[[0,1.31,32.7],[1,1.3,3.03],[2,1.29,3.19]],"ltp":1.41,"tv":101.85,"id":16325787}]}]}
{"op":"mcm","clk":"990249999","pt":1580495584569,"mc":[{"id":"1.168133553","rc":[{"batb":[[0,1.32,3.03],[1,1.31,32.7]],"ltp":1.41,"tv":101.85,"id":16325787}]}]}
{"op":"mcm","clk":"990250115","pt":1580495585563,"mc":[{"id":"1.168133553","rc":[{"batl":[[0,250,3.23],[1,260,9]],"ltp":0.0,"tv":0.0,"id":27227336},{"batl":[[0,250,3.23],[1,260,9]],"ltp":0.0,"tv":0.0,"id":21641292}]}]}
{"op":"mcm","clk":"990252003","pt":1580495603298,"mc":[{"id":"1.168133553","rc":[{"batb":[[1,1.29,3.19],[2,1.26,6]],"ltp":1.41,"tv":101.85,"id":16325787}]}]}
{"op":"mcm","clk":"990252739","pt":1580495610565,"mc":[{"id":"1.168133553","rc":[{"batl":[[1,260,0]],"ltp":0.0,"tv":0.0,"id":27227336},{"batl":[[1,260,0]],"ltp":0.0,"tv":0.0,"id":21641292}]}]}
{"op":"mcm","clk":"990252826","pt":1580495611473,"mc":[{"id":"1.168133553","rc":[{"batl":[[0,230,9],[1,250,3.23]],"ltp":0.0,"tv":0.0,"id":27227336},{"batl":[[0,230,9],[1,250,3.23]],"ltp":0.0,"tv":0.0,"id":21641292}]}]}
{"op":"mcm","clk":"990252957","pt":1580495612770,"mc":[{"id":"1.168133553","rc":[{"batl":[[0,230,9.2],[1,250,3.03]],"ltp":0.0,"tv":0.0,"id":27227336},{"batl":[[0,230,9.2],[1,250,3.03]],"ltp":0.0,"tv":0.0,"id":21641292}]}]}
{"op":"mcm","clk":"990258660","pt":1580495672563,"mc":[{"id":"1.168133553","rc":[{"batl":[[0,220,3.23],[1,230,9]],"ltp":0.0,"tv":0.0,"id":27227336},{"batl":[[0,220,3.23],[1,230,9]],"ltp":0.0,"tv":0.0,"id":21641292},{"batb":[[0,1.3,3.03]],"ltp":1.41,"tv":101.85,"id":16325787}]}]}
{"op":"mcm","clk":"990259221","pt":1580495678282,"mc":[{"id":"1.168133553","rc":[{"batl":[[0,200,9],[1,220,3.23]],"ltp":0.0,"tv":0.0,"id":27227336},{"batl":[[0,200,9],[1,220,3.23]],"ltp":0.0,"tv":0.0,"id":21641292}]}]}
{"op":"mcm","clk":"990259648","pt":1580495682499,"mc":[{"id":"1.168133553","rc":[{"batb":[[0,1.31,32.7],[1,1.3,3.03],[2,1.29,3.19]],"ltp":1.41,"tv":101.85,"id":16325787}]}]}
{"op":"mcm","clk":"990269511","pt":1580495771459,"mc":[{"id":"1.168133553","rc":[{"batb":[[0,1.32,3.03],[1,1.31,32.7]],"ltp":1.41,"tv":101.85,"id":16325787}]}]}
{"op":"mcm","clk":"990269601","pt":1580495772346,"mc":[{"id":"1.168133553","rc":[{"batl":[[0,190,3.03],[1,200,9],[2,220,0.2]],"ltp":0.0,"tv":0.0,"id":27227336},{"batl":[[0,190,3.03],[1,200,9],[2,220,0.2]],"ltp":0.0,"tv":0.0,"id":21641292}]}]}
{"op":"mcm","clk":"990269982","pt":1580495775470,"mc":[{"id":"1.168133553","rc":[{"batl":[[0,170,9],[1,190,3.03]],"ltp":0.0,"tv":0.0,"id":27227336},{"batl":[[0,170,9],[1,190,3.03]],"ltp":0.0,"tv":0.0,"id":21641292}]}]}
{"op":"mcm","clk":"990270901","pt":1580495783196,"mc":[{"id":"1.168133553","rc":[{"batb":[[1,1.29,3.19],[2,1.26,6]],"ltp":1.41,"tv":101.85,"id":16325787}]}]}
{"op":"mcm","clk":"990271025","pt":1580495784395,"mc":[{"id":"1.168133553","rc":[{"batl":[[0,1.39,804]],"ltp":1.41,"tv":101.85,"id":16325787}]}]}
{"op":"mcm","clk":"990291493","pt":1580495888485,"mc":[{"id":"1.168133553","rc":[{"batl":[[0,160,3.03],[1,170,9]],"ltp":0.0,"tv":0.0,"id":27227336},{"batl":[[1,220,0.2],[2,220,0]],"ltp":0.0,"tv":0.0,"id":21641292},{"batb":[[0,1.3,3.03]],"ltp":1.41,"tv":101.85,"id":16325787}]}]}
{"op":"mcm","clk":"990291517","pt":1580495888696,"mc":[{"id":"1.168133553","rc":[{"batl":[[0,160,3.03],[1,170,9],[2,220,0.2]],"ltp":0.0,"tv":0.0,"id":21641292}]}]}
{"op":"mcm","clk":"990293229","pt":1580495903201,"mc":[{"id":"1.168133553","rc":[{"batb":[[0,1.31,32.7],[1,1.3,3.03],[2,1.29,3.19]],"ltp":1.41,"tv":101.85,"id":16325787}]}]}
{"op":"mcm","clk":"990293398","pt":1580495904502,"mc":[{"id":"1.168133553","rc":[{"batl":[[1,220,0.2],[2,220,0]],"ltp":0.0,"tv":0.0,"id":27227336},{"batl":[[1,220,0.2],[2,220,0]],"ltp":0.0,"tv":0.0,"id":21641292}]}]}
{"op":"mcm","clk":"990293404","pt":1580495904599,"mc":[{"id":"1.168133553","rc":[{"batl":[[0,140,9],[1,160,3.03],[2,220,0.2]],"ltp":0.0,"tv":0.0,"id":27227336},{"batl":[[0,140,9],[1,160,3.03],[2,220,0.2]],"ltp":0.0,"tv":0.0,"id":21641292}]}]}
{"op":"mcm","clk":"990302203","pt":1580495983531,"mc":[{"id":"1.168133553","rc":[{"batl":[[0,130,3.03],[1,140,9]],"ltp":0.0,"tv":0.0,"id":27227336},{"batl":[[0,130,3.03],[1,140,9]],"ltp":0.0,"tv":0.0,"id":21641292},{"batb":[[0,1.32,3.03],[1,1.31,32.7]],"ltp":1.41,"tv":101.85,"id":16325787}]}]}
{"op":"mcm","clk":"990302370","pt":1580495985241,"mc":[{"id":"1.168133553","rc":[{"batb":[[1,1.29,3.19],[2,1.26,6]],"ltp":1.41,"tv":101.85,"id":16325787}]}]}
{"op":"mcm","clk":"990303986","pt":1580496002362,"mc":[{"id":"1.168133553","rc":[{"batl":[[0,110,9],[1,130,3.03]],"ltp":0.0,"tv":0.0,"id":27227336},{"batl":[[0,110,9],[1,130,3.03]],"ltp":0.0,"tv":0.0,"id":21641292}]}]}
{"op":"mcm","clk":"990304944","pt":1580496012474,"mc":[{"id":"1.168133553","rc":[{"batl":[[0,110,9.05]],"ltp":0.0,"tv":0.0,"id":27227336}]}]}
{"op":"mcm","clk":"990304950","pt":1580496012588,"mc":[{"id":"1.168133553","rc":[{"batl":[[0,110,9.05]],"ltp":0.0,"tv":0.0,"id":21641292}]}]}
{"op":"mcm","clk":"990305449","pt":1580496017919,"mc":[{"id":"1.168133553","rc":[{"batb":[[0,7,3.62],[1,6.8,5.01],[2,6.6,3]],"ltp":0.0,"tv":0.0,"id":27227336},{"batb":[[1,5.1,3.92],[2,5,2.31]],"ltp":0.0,"tv":0.0,"id":21641292},{"batb":[[1,1.3,10],[2,1.29,3.19]],"ltp":1.41,"tv":101.85,"id":16325787}]}]}
{"op":"mcm","clk":"990310301","pt":1580496064435,"mc":[{"id":"1.168133553","rc":[{"batb":[[0,1.3,10],[1,1.29,3.19],[2,1.26,6]],"ltp":1.41,"tv":101.85,"id":16325787}]}]}
{"op":"mcm","clk":"990310430","pt":1580496065542,"mc":[{"id":"1.168133553","rc":[{"batb":[[0,7.2,3.03],[1,7,3.62],[2,6.8,1.98]],"batl":[[0,100,3.08],[1,110,9]],"ltp":0.0,"tv":0.0,"id":27227336},{"batl":[[1,220,0.2],[2,220,0]],"ltp":0.0,"tv":0.0,"id":21641292},{"batb":[[0,1.31,3.03],[1,1.3,10],[2,1.29,3.19]],"ltp":1.41,"tv":101.85,"id":16325787}]}]}
{"op":"mcm","clk":"990310491","pt":1580496066133,"mc":[{"id":"1.168133553","rc":[{"batl":[[0,90,9],[1,100,3.08]],"ltp":0.0,"tv":0.0,"id":27227336},{"batl":[[0,100,3.08],[1,110,9],[2,220,0.2]],"ltp":0.0,"tv":0.0,"id":21641292}]}]}
{"op":"mcm","clk":"990311169","pt":1580496072527,"mc":[{"id":"1.168133553","rc":[{"batl":[[1,100,3.03]],"ltp":0.0,"tv":0.0,"id":27227336}]}]}
{"op":"mcm","clk":"990311183","pt":1580496072634,"mc":[{"id":"1.168133553","rc":[{"batl":[[0,90,9.06]],"ltp":0.0,"tv":0.0,"id":27227336}]}]}
{"op":"mcm","clk":"990311755","pt":1580496077830,"mc":[{"id":"1.168133553","rc":[{"batb":[[0,7.4,2.7],[1,7.2,3.03],[2,6.8,2.74]],"ltp":0.0,"tv":0.0,"id":27227336}]}]}
{"op":"mcm","clk":"990312404","pt":1580496083970,"mc":[{"id":"1.168133553","rc":[{"batb":[[0,1.32,32.45],[1,1.31,3.03],[2,1.3,10]],"ltp":1.41,"tv":101.85,"id":16325787}]}]}
{"op":"mcm","clk":"990314085","pt":1580496098808,"mc":[{"id":"1.168133553","rc":[{"batl":[[0,90,9],[1,100,3.08]],"ltp":0.0,"tv":0.0,"id":21641292}]}]}
{"op":"mcm","clk":"990314465","pt":1580496102441,"mc":[{"id":"1.168133553","rc":[{"batl":[[1,100,3.03],[2,1000,0.26]],"ltp":0.0,"tv":0.0,"id":21641292}]}]}
{"op":"mcm","clk":"990314508","pt":1580496102723,"mc":[{"id":"1.168133553","rc":[{"batl":[[0,90,9.06],[2,220,0.2]],"ltp":0.0,"tv":0.0,"id":21641292}]}]}
{"op":"mcm","clk":"990318477","pt":1580496137942,"mc":[{"id":"1.168133553","rc":[{"batb":[[0,1.33,10],[1,1.32,32.45],[2,1.31,3.03]],"ltp":1.41,"tv":101.85,"id":16325787}]}]}
{"op":"mcm","clk":"990318652","pt":1580496139527,"mc":[{"id":"1.168133553","rc":[{"batl":[[0,1.39,800]],"ltp":1.41,"tv":101.85,"id":16325787}]}]}
{"op":"mcm","clk":"990319283","pt":1580496145436,"mc":[{"id":"1.168133553","rc":[{"batb":[[1,1.31,3.03],[2,1.29,3.19]],"ltp":1.41,"tv":101.85,"id":16325787}]}]}
{"op":"mcm","clk":"990321222","pt":1580496162505,"mc":[{"id":"1.168133553","rc":[{"batl":[[0,85,3.09],[1,220,0.2],[2,220,0]],"ltp":0.0,"tv":0.0,"id":27227336},{"batl":[[0,85,3.09],[1,90,9]],"ltp":0.0,"tv":0.0,"id":21641292}]}]}
{"op":"mcm","clk":"990321237","pt":1580496162610,"mc":[{"id":"1.168133553","rc":[{"batl":[[0,75,9],[1,85,3.09],[2,220,0.2]],"ltp":0.0,"tv":0.0,"id":27227336}]}]}
{"op":"mcm","clk":"990324273","pt":1580496189551,"mc":[{"id":"1.168133553","rc":[{"batl":[[1,85,3.03],[2,1000,2.2]],"ltp":0.0,"tv":0.0,"id":27227336}]}]}
{"op":"mcm","clk":"990324397","pt":1580496190546,"mc":[{"id":"1.168133553","rc":[{"batl":[[0,75,9.07],[2,220,0.2]],"ltp":0.0,"tv":0.0,"id":27227336}]}]}
{"op":"mcm","clk":"990324900","pt":1580496195523,"mc":[{"id":"1.168133553","rc":[{"batl":[[0,75,9],[1,85,3.09]],"ltp":0.0,"tv":0.0,"id":21641292}]}]}
{"op":"mcm","clk":"990325149","pt":1580496198217,"mc":[{"id":"1.168133553","rc":[{"batb":[[0,1.31,3.03],[1,1.3,10]],"batl":[[0,1.38,4],[1,1.39,800],[2,1.4,3.03]],"ltp":1.41,"tv":101.85,"id":16325787}]}]}
{"op":"mcm","clk":"990325839","pt":1580496204559,"mc":[{"id":"1.168133553","rc":[{"batb":[[2,6.4,10.76]],"ltp":0.0,"tv":0.0,"id":27227336},{"batb":[[2,4.9,3.36]],"ltp":0.0,"tv":0.0,"id":21641292}]}]}
{"op":"mcm","clk":"990325849","pt":1580496204666,"mc":[{"id":"1.168133553","rc":[{"batb":[[0,7.6,1.98],[1,7.4,2.7],[2,7.2,3.03]],"ltp":0.0,"tv":0.0,"id":27227336},{"batb":[[1,5.2,1.98],[2,5.1,3.92]],"ltp":0.0,"tv":0.0,"id":21641292}]}]}
{"op":"mcm","clk":"990327431","pt":1580496220409,"mc":[{"id":"1.168133553","rc":[{"batl":[[1,85,3.03],[2,1000,2.2]],"ltp":0.0,"tv":0.0,"id":21641292}]}]}
{"op":"mcm","clk":"990327503","pt":1580496221198,"mc":[{"id":"1.168133553","rc":[{"batl":[[0,75,9.07],[2,220,0.2]],"ltp":0.0,"tv":0.0,"id":21641292}]}]}
{"op":"mcm","clk":"990327619","pt":1580496222308,"mc":[{"id":"1.168133553","rc":[{"batb":[[0,7.6,5.01],[2,6.4,10.76]],"batl":[[0,70,3.1],[1,75,9]],"ltp":0.0,"tv":0.0,"id":27227336},{"batl":[[0,70,3.1],[1,75,9]],"ltp":0.0,"tv":0.0,"id":21641292}]}]}
{"op":"mcm","clk":"990328202","pt":1580496228508,"mc":[{"id":"1.168133553","rc":[{"batl":[[0,60,9],[1,70,3.1]],"ltp":0.0,"tv":0.0,"id":27227336},{"batl":[[0,60,9],[1,70,3.1]],"ltp":0.0,"tv":0.0,"id":21641292}]}]}
{"op":"mcm","clk":"990330408","pt":1580496250564,"mc":[{"id":"1.168133553","rc":[{"batl":[[1,70,3.03]],"ltp":0.0,"tv":0.0,"id":27227336},{"batl":[[1,70,3.03]],"ltp":0.0,"tv":0.0,"id":21641292}]}]}
{"op":"mcm","clk":"990330487","pt":1580496251458,"mc":[{"id":"1.168133553","rc":[{"batl":[[0,60,9.09]],"ltp":0.0,"tv":0.0,"id":27227336},{"batl":[[0,60,9.09]],"ltp":0.0,"tv":0.0,"id":21641292}]}]}
{"op":"mcm","clk":"990331144","pt":1580496259086,"mc":[{"id":"1.168133553","rc":[{"batb":[[0,7.8,2.56],[1,7.6,5.01]],"ltp":0.0,"tv":0.0,"id":27227336},{"batb":[[1,5.3,3.77],[2,5.2,1.98]],"ltp":0.0,"tv":0.0,"id":21641292}]}]}
{"op":"mcm","clk":"990334574","pt":1580496298069,"mc":[{"id":"1.168133553","rc":[{"batl":[[0,55,3.12],[1,60,9]],"ltp":0.0,"tv":0.0,"id":27227336},{"batl":[[0,55,3.12],[1,60,9]],"ltp":0.0,"tv":0.0,"id":21641292}]}]}
{"op":"mcm","clk":"990337101","pt":1580496325298,"mc":[{"id":"1.168133553","rc":[{"batl":[[0,48,9],[1,55,3.12]],"ltp":0.0,"tv":0.0,"id":27227336},{"batl":[[0,48,9],[1,55,3.12]],"ltp":0.0,"tv":0.0,"id":21641292}]}]}
{"op":"mcm","clk":"990338438","pt":1580496340560,"mc":[{"id":"1.168133553","rc":[{"batl":[[1,55,3.03],[2,1000,2.2]],"ltp":0.0,"tv":0.0,"id":27227336},{"batl":[[1,55,3.03],[2,1000,2.2]],"ltp":0.0,"tv":0.0,"id":21641292}]}]}
{"op":"mcm","clk":"990338554","pt":1580496341559,"mc":[{"id":"1.168133553","rc":[{"batl":[[0,48,9.11],[2,220,0.2]],"ltp":0.0,"tv":0.0,"id":27227336},{"batl":[[0,48,9.11],[2,220,0.2]],"ltp":0.0,"tv":0.0,"id":21641292}]}]}
{"op":"mcm","clk":"990341006","pt":1580496368448,"mc":[{"id":"1.168133553","rc":[{"batl":[[0,46,3.14],[1,48,9]],"ltp":0.0,"tv":0.0,"id":27227336},{"batl":[[0,46,3.14],[1,48,9]],"ltp":0.0,"tv":0.0,"id":21641292}]}]}
{"op":"mcm","clk":"990342979","pt":1580496389154,"mc":[{"id":"1.168133553","rc":[{"batl":[[0,42,9],[1,46,3.14]],"ltp":0.0,"tv":0.0,"id":27227336},{"batl":[[0,42,9],[1,46,3.14]],"ltp":0.0,"tv":0.0,"id":21641292}]}]}
{"op":"mcm","clk":"990343279","pt":1580496392375,"mc":[{"id":"1.168133553","rc":[{"batb":[[0,8,1.98],[1,7.8,2.56],[2,7.6,3.03]],"ltp":0.0,"tv":0.0,"id":27227336},{"batb":[[1,5.4,1.98],[2,5.3,3.77]],"ltp":0.0,"tv":0.0,"id":21641292}]}]}
{"op":"mcm","clk":"990344028","pt":1580496401544,"mc":[{"id":"1.168133553","rc":[{"batl":[[2,1000,2.2]],"ltp":0.0,"tv":0.0,"id":27227336}]}]}
{"op":"mcm","clk":"990344112","pt":1580496402331,"mc":[{"id":"1.168133553","rc":[{"batl":[[0,42,9.12],[1,46,3.03],[2,220,0.2]],"ltp":0.0,"tv":0.0,"id":27227336},{"batl":[[0,42,9.12],[1,46,3.03]],"ltp":0.0,"tv":0.0,"id":21641292}]}]}
{"op":"mcm","clk":"990346486","pt":1580496430556,"mc":[{"id":"1.168133553","rc":[{"batb":[[0,8,5.01],[2,6.4,10.76]],"batl":[[0,40,3.15],[1,42,9]],"ltp":0.0,"tv":0.0,"id":27227336}]}]}
{"op":"mcm","clk":"990346508","pt":1580496430875,"mc":[{"id":"1.168133553","rc":[{"batl":[[0,40,3.15],[1,42,9]],"ltp":0.0,"tv":0.0,"id":21641292}]}]}
{"op":"mcm","clk":"990347447","pt":1580496441511,"mc":[{"id":"1.168133553","rc":[{"batl":[[2,220,0]],"ltp":0.0,"tv":0.0,"id":27227336},{"batl":[[2,220,0]],"ltp":0.0,"tv":0.0,"id":21641292}]}]}
{"op":"mcm","clk":"990347553","pt":1580496442422,"mc":[{"id":"1.168133553","rc":[{"batb":[[1,6.4,10.76],[2,6,34]],"batl":[[0,40,3.35]],"ltp":0.0,"tv":0.0,"id":27227336},{"batb":[[2,4.9,3.36]],"batl":[[0,40,3.35]],"ltp":0.0,"tv":0.0,"id":21641292}]}]}
{"op":"mcm","clk":"990348561","pt":1580496453510,"mc":[{"id":"1.168133553","rc":[{"batl":[[1,42,0]],"ltp":0.0,"tv":0.0,"id":27227336},{"batl":[[1,42,0]],"ltp":0.0,"tv":0.0,"id":21641292}]}]}
{"op":"mcm","clk":"990348576","pt":1580496453615,"mc":[{"id":"1.168133553","rc":[{"batl":[[0,36,9],[1,40,3.35]],"ltp":0.0,"tv":0.0,"id":27227336},{"batl":[[0,36,9],[1,40,3.35]],"ltp":0.0,"tv":0.0,"id":21641292}]}]}
{"op":"mcm","clk":"990349334","pt":1580496462505,"mc":[{"id":"1.168133553","rc":[{"batl":[[0,36,9.15],[1,40,3.23]],"ltp":0.0,"tv":0.0,"id":27227336},{"batl":[[1,40,3.23]],"ltp":0.0,"tv":0.0,"id":21641292}]}]}
{"op":"mcm","clk":"990349410","pt":1580496463442,"mc":[{"id":"1.168133553","rc":[{"batl":[[0,36,9.15]],"ltp":0.0,"tv":0.0,"id":21641292}]}]}
{"op":"mcm","clk":"990352351","pt":1580496497492,"mc":[{"id":"1.168133553","rc":[{"batb":[[0,8,1.98],[1,6.6,3.79],[2,6.4,10]],"ltp":0.0,"tv":0.0,"id":27227336}]}]}
{"op":"mcm","clk":"990352458","pt":1580496498496,"mc":[{"id":"1.168133553","rc":[{"batl":[[0,34,3.18],[1,36,9],[2,38,0.2]],"ltp":0.0,"tv":0.0,"id":27227336},{"batl":[[0,34,3.18],[1,36,9],[2,38,0.2]],"ltp":0.0,"tv":0.0,"id":21641292}]}]}
{"op":"mcm","clk":"990354163","pt":1580496519538,"mc":[{"id":"1.168133553","rc":[{"batl":[[0,30,9],[1,34,3.18]],"ltp":0.0,"tv":0.0,"id":27227336},{"batl":[[0,30,9],[1,34,3.18]],"ltp":0.0,"tv":0.0,"id":21641292}]}]}
{"op":"mcm","clk":"990354395","pt":1580496522446,"mc":[{"id":"1.168133553","rc":[{"batl":[[1,34,3.03],[2,1000,0.37]],"ltp":0.0,"tv":0.0,"id":27227336},{"batl":[[1,34,3.03],[2,1000,2.2]],"ltp":0.0,"tv":0.0,"id":21641292}]}]}
{"op":"mcm","clk":"990354439","pt":1580496523021,"mc":[{"id":"1.168133553","rc":[{"batl":[[0,30,9.17],[2,38,0.2]],"ltp":0.0,"tv":0.0,"id":27227336},{"batl":[[0,30,9.17],[2,38,0.2]],"ltp":0.0,"tv":0.0,"id":21641292}]}]}
{"op":"mcm","clk":"990357855","pt":1580496561977,"mc":[{"id":"1.168133553","rc":[{"batb":[[1,7.2,2.78],[2,6.6,3.79]],"ltp":0.0,"tv":0.0,"id":27227336},{"batb":[[0,5.5,4.65]],"ltp":0.0,"tv":0.0,"id":21641292}]}]}
{"op":"mcm","clk":"990359392","pt":1580496581019,"mc":[{"id":"1.168133553","rc":[{"batb":[[0,7.4,1.98]],"ltp":0.0,"tv":0.0,"id":27227336},{"batb":[[0,5.6,1.98],[1,5.5,4.65]],"ltp":0.0,"tv":0.0,"id":21641292}]}]}
{"op":"mcm","clk":"990359752","pt":1580496586025,"mc":[{"id":"1.168133553","rc":[{"batb":[[2,4.9,3.03]],"ltp":0.0,"tv":0.0,"id":21641292}]}]}
{"op":"mcm","clk":"990360156","pt":1580496590551,"mc":[{"id":"1.168133553","rc":[{"batb":[[0,7.4,5.01],[2,6.4,10.76]],"ltp":0.0,"tv":0.0,"id":27227336},{"batb":[[1,5.5,3.64]],"ltp":0.0,"tv":0.0,"id":21641292}]}]}
{"op":"mcm","clk":"990360234","pt":1580496591539,"mc":[{"id":"1.168133553","rc":[{"batl":[[0,29,3.2],[1,30,9]],"ltp":0.0,"tv":0.0,"id":27227336},{"batl":[[0,29,3.2],[1,30,9]],"ltp":0.0,"tv":0.0,"id":21641292}]}]}
{"op":"mcm","clk":"990360272","pt":1580496592004,"mc":[{"id":"1.168133553","rc":[{"batb":[[0,5.6,2.95]],"ltp":0.0,"tv":0.0,"id":21641292}]}]}
{"op":"mcm","clk":"990360839","pt":1580496598570,"mc":[{"id":"1.168133553","rc":[{"batb":[[0,5.7,1.26],[1,5.6,1.98],[2,5.5,3.64]],"ltp":0.0,"tv":0.0,"id":21641292}]}]}
{"op":"mcm","clk":"990361360","pt":1580496603977,"mc":[{"id":"1.168133553","rc":[{"batb":[[2,6.6,3.76]],"ltp":0.0,"tv":0.0,"id":27227336}]}]}
{"op":"mcm","clk":"990362388","pt":1580496615377,"mc":[{"id":"1.168133553","rc":[{"batl":[[0,29,12.2],[1,38,0.2],[2,38,0]],"ltp":0.0,"tv":0.0,"id":27227336},{"batl":[[0,27,9],[1,29,3.2]],"ltp":0.0,"tv":0.0,"id":21641292}]}]}
{"op":"mcm","clk":"990363040","pt":1580496622408,"mc":[{"id":"1.168133553","rc":[{"batb":[[1,6.6,3.76],[2,6.4,10]],"ltp":0.0,"tv":0.0,"id":27227336},{"batb":[[2,5,3]],"ltp":0.0,"tv":0.0,"id":21641292}]}]}
{"op":"mcm","clk":"990363541","pt":1580496627516,"mc":[{"id":"1.168133553","rc":[{"batb":[[2,4.9,3.03]],"ltp":0.0,"tv":0.0,"id":21641292}]}]}
{"op":"mcm","clk":"990365010","pt":1580496642445,"mc":[{"id":"1.168133553","rc":[{"batl":[[2,1000,2.2]],"ltp":0.0,"tv":0.0,"id":21641292}]}]}
{"op":"mcm","clk":"990365056","pt":1580496642922,"mc":[{"id":"1.168133553","rc":[{"batl":[[0,27,9.19],[1,29,3.03],[2,38,0.2]],"ltp":0.0,"tv":0.0,"id":21641292}]}]}
{"op":"mcm","clk":"990366852","pt":1580496661451,"mc":[{"id":"1.168133553","rc":[{"batb":[[0,7.4,1.98],[1,6.8,3.79],[2,6.6,3]],"ltp":0.0,"tv":0.0,"id":27227336},{"batl":[[0,26,3.22],[1,27,9]],"ltp":0.0,"tv":0.0,"id":21641292}]}]}
{"op":"mcm","clk":"990369070","pt":1580496681286,"mc":[{"id":"1.168133553","rc":[{"batl":[[0,24,9],[1,26,3.22]],"ltp":0.0,"tv":0.0,"id":21641292}]}]}
{"op":"mcm","clk":"990371179","pt":1580496700451,"mc":[{"id":"1.168133553","rc":[{"batl":[[0,24,9.22],[1,26,3.03]],"ltp":0.0,"tv":0.0,"id":21641292}]}]}
{"op":"mcm","clk":"990372136","pt":1580496708569,"mc":[{"id":"1.168133553","rc":[{"batb":[[0,7.8,15.87],[1,7.4,1.98],[2,6.8,3.79]],"ltp":0.0,"tv":0.0,"id":27227336},{"batb":[[0,5.9,22.02],[1,5.7,1.26],[2,5.6,1.98]],"ltp":0.0,"tv":0.0,"id":21641292},{"batb":[[0,1.34,317.43],[1,1.31,3.03],[2,1.3,10]],"ltp":1.41,"tv":101.85,"id":16325787}]}]}
{"op":"mcm","clk":"990372335","pt":1580496710443,"mc":[{"id":"1.168133553","rc":[{"batb":[[1,5.6,2.27],[2,5.2,19.71]],"ltp":0.0,"tv":0.0,"id":21641292},{"batb":[[2,1.3,286.03]],"ltp":1.41,"tv":101.85,"id":16325787}]}]}
{"op":"mcm","clk":"990372431","pt":1580496711424,"mc":[{"id":"1.168133553","rc":[{"batb":[[0,5.9,22.93]],"ltp":0.0,"tv":0.0,"id":21641292}]}]}
{"op":"mcm","clk":"990373422","pt":1580496720534,"mc":[{"id":"1.168133553","rc":[{"batl":[[0,10,9.2],[1,29,12.2],[2,38,0.2]],"ltp":0.0,"tv":0.0,"id":27227336},{"batl":[[0,8,11.83],[1,24,9.22],[2,26,3.03]],"ltp":0.0,"tv":0.0,"id":21641292},{"batl":[[0,1.39,800],[1,1.4,3.03],[2,1.44,44]],"ltp":1.41,"tv":101.85,"id":16325787}]}]}
{"op":"mcm","clk":"990375462","pt":1580496739483,"mc":[{"id":"1.168133553","rc":[{"batb":[[0,8,3.03],[1,7.8,15.87],[2,7.4,1.98]],"batl":[[0,9.8,3.03],[1,10,9.2],[2,29,9.17]],"ltp":0.0,"tv":0.0,"id":27227336},{"batl":[[2,38,0.2]],"ltp":0.0,"tv":0.0,"id":21641292}]}]}
{"op":"mcm","clk":"990375567","pt":1580496740419,"mc":[{"id":"1.168133553","rc":[{"batl":[[0,7.8,3.03],[1,8,11.83],[2,24,9.22]],"ltp":0.0,"tv":0.0,"id":21641292}]}]}
{"op":"mcm","clk":"990376022","pt":1580496744096,"mc":[{"id":"1.168133553","rc":[{"batb":[[0,8.2,2.44],[1,8,3.03],[2,7.8,15.87]],"ltp":0.0,"tv":0.0,"id":27227336},{"batb":[[0,6,4.24],[1,5.9,22.02],[2,5.6,2.27]],"ltp":0.0,"tv":0.0,"id":21641292},{"batb":[[2,1.3,276.03]],"ltp":1.41,"tv":101.85,"id":16325787}]}]}
{"op":"mcm","clk":"990376164","pt":1580496745413,"mc":[{"id":"1.168133553","rc":[{"batl":[[2,23,9.22]],"ltp":0.0,"tv":0.0,"id":21641292}]}]}
{"op":"mcm","clk":"990394721","pt":1580496824026,"mc":[{"id":"1.168133553","rc":[{"trd":[[1.34,400]],"batb":[[0,1.34,117.43]],"ltp":1.34,"tv":501.85,"id":16325787}],"tv":501.85}]}
{"op":"mcm","clk":"990395184","pt":1580496828057,"mc":[{"id":"1.168133553","rc":[{"batb":[[0,1.34,102.6]],"ltp":1.34,"tv":501.85,"id":16325787}]}]}
{"op":"mcm","clk":"990424629","pt":1580497101390,"mc":[{"id":"1.168133553","rc":[{"trd":[[6,4]],"batb":[[0,6,2.24]],"ltp":6.0,"tv":3.99,"id":21641292}],"tv":505.85}]}
{"op":"mcm","clk":"990432879","pt":1580497186031,"mc":[{"id":"1.168133553","rc":[{"batl":[[0,1.38,58],[1,1.39,800],[2,1.4,3.03]],"ltp":1.34,"tv":501.85,"id":16325787}]}]}
{"op":"mcm","clk":"990452124","pt":1580497333755,"mc":[{"id":"1.168133553","rc":[{"batl":[[0,1.37,100],[1,1.38,58],[2,1.39,800]],"ltp":1.34,"tv":501.85,"id":16325787}]}]}
{"op":"mcm","clk":"990453522","pt":1580497343554,"mc":[{"id":"1.168133553","rc":[{"batl":[[2,38,0.42]],"ltp":6.0,"tv":3.99,"id":21641292}]}]}
{"op":"mcm","clk":"990453648","pt":1580497344563,"mc":[{"id":"1.168133553","rc":[{"batl":[[2,25,9.22]],"ltp":6.0,"tv":3.99,"id":21641292},{"batl":[[0,1.36,2],[1,1.37,100],[2,1.38,58]],"ltp":1.34,"tv":501.85,"id":16325787}]}]}
{"op":"mcm","clk":"990453724","pt":1580497345149,"mc":[{"id":"1.168133553","rc":[{"batl":[[0,1.37,100],[1,1.38,58],[2,1.39,800]],"ltp":1.34,"tv":501.85,"id":16325787}]}]}
{"op":"mcm","clk":"990463796","pt":1580497420065,"mc":[{"id":"1.168133553","rc":[{"batb":[[0,1.34,104.6]],"ltp":1.34,"tv":501.85,"id":16325787}]}]}
{"op":"mcm","clk":"990466233","pt":1580497436785,"mc":[{"id":"1.168133553","rc":[{"batl":[[0,1.35,30],[1,1.37,100],[2,1.38,58]],"ltp":1.34,"tv":501.85,"id":16325787}]}]}
{"op":"mcm","clk":"990491479","pt":1580497619208,"mc":[{"id":"1.168133553","rc":[{"trd":[[1.34,460]],"batb":[[0,1.34,74.6]],"batl":[[0,1.37,100],[1,1.38,58],[2,1.39,800]],"ltp":1.34,"tv":561.85,"id":16325787}],"tv":565.85}]}
{"op":"mcm","clk":"990491653","pt":1580497620510,"mc":[{"id":"1.168133553","rc":[{"batb":[[0,1.34,71.89]],"ltp":1.34,"tv":561.85,"id":16325787}]}]}
{"op":"mcm","clk":"990546233","pt":1580497926227,"mc":[{"id":"1.168133553","rc":[{"trd":[[1.34,603.78]],"batb":[[0,1.31,11.69],[1,1.3,276.03],[2,1.28,200]],"batl":[[0,1.34,8.11],[1,1.37,100],[2,1.38,58]],"ltp":1.34,"tv":705.63,"id":16325787}],"tv":709.63}]}
{"op":"mcm","clk":"990546455","pt":1580497927520,"mc":[{"id":"1.168133553","rc":[{"batb":[[0,1.32,3.12],[1,1.31,11.69],[2,1.3,276.03]],"ltp":1.34,"tv":705.63,"id":16325787}]}]}
{"op":"mcm","clk":"990546594","pt":1580497928426,"mc":[{"id":"1.168133553","rc":[{"batb":[[0,8.2,3.14]],"ltp":0.0,"tv":0.0,"id":27227336},{"batb":[[0,6,2.93]],"ltp":6.0,"tv":3.99,"id":21641292}]}]}
{"op":"mcm","clk":"990551077","pt":1580497957241,"mc":[{"id":"1.168133553","rc":[{"batl":[[0,1.37,100],[1,1.38,58],[2,1.39,800]],"ltp":1.34,"tv":705.63,"id":16325787}]}]}
{"op":"mcm","clk":"990564863","pt":1580498048254,"mc":[{"id":"1.168133553","rc":[{"batb":[[0,8.4,1.98],[1,8.2,3.14],[2,8,3.03]],"ltp":0.0,"tv":0.0,"id":27227336},{"batb":[[0,6.2,1.98],[1,6,2.93],[2,5.9,22.02]],"ltp":6.0,"tv":3.99,"id":21641292}]}]}
{"op":"mcm","clk":"990587985","pt":1580498196218,"mc":[{"id":"1.168133553","rc":[{"batb":[[0,1.32,13.12]],"ltp":1.34,"tv":705.63,"id":16325787}]}]}
{"op":"mcm","clk":"990625971","pt":1580498472528,"mc":[{"id":"1.168133553","rc":[{"batb":[[0,1.32,3.12]],"ltp":1.34,"tv":705.63,"id":16325787}]}]}
{"op":"mcm","clk":"990632608","pt":1580498522551,"mc":[{"id":"1.168133553","rc":[{"batl":[[1,1.39,800],[2,1.4,3.03]],"ltp":1.34,"tv":705.63,"id":16325787}]}]}
{"op":"mcm","clk":"990632671","pt":1580498523080,"mc":[{"id":"1.168133553","rc":[{"batl":[[0,1.37,158]],"ltp":1.34,"tv":705.63,"id":16325787}]}]}
{"op":"mcm","clk":"990678093","pt":1580498759775,"mc":[{"id":"1.168133553","rc":[{"trd":[[6,9.86],[6.2,3.96]],"batb":[[0,5.9,22.02],[1,5.5,3.29],[2,5.2,19.71]],"batl":[[0,7.8,3.12]],"ltp":6.0,"tv":13.81,"id":21641292}],"tv":719.44}]}
{"op":"mcm","clk":"990678369","pt":1580498761600,"mc":[{"id":"1.168133553","rc":[{"batl":[[0,7.8,3.03]],"ltp":6.0,"tv":13.81,"id":21641292}]}]}
{"op":"mcm","clk":"990682043","pt":1580498783505,"mc":[{"id":"1.168133553","rc":[{"batb":[[0,6,1.98],[1,5.9,22.02],[2,5.5,3.29]],"ltp":6.0,"tv":13.81,"id":21641292}]}]}
{"op":"mcm","clk":"990688363","pt":1580498826186,"mc":[{"id":"1.168133553","rc":[{"batb":[[1,1.31,111.69]],"ltp":1.34,"tv":705.63,"id":16325787}]}]}
{"op":"mcm","clk":"990820593","pt":1580499647557,"mc":[{"id":"1.168133553","rc":[{"batl":[[0,1.35,1.68],[1,1.37,158],[2,1.39,800]],"ltp":1.34,"tv":705.63,"id":16325787}]}]}
{"op":"mcm","clk":"990820688","pt":1580499648154,"mc":[{"id":"1.168133553","rc":[{"batl":[[0,1.37,158],[1,1.39,800],[2,1.4,3.03]],"ltp":1.34,"tv":705.63,"id":16325787}]}]}
{"op":"mcm","clk":"990884533","pt":1580500073232,"mc":[{"id":"1.168133553","rc":[{"trd":[[9,2]],"batb":[[0,9,1],[1,8.4,1.98],[2,8.2,3.14]],"ltp":9.0,"tv":2.0,"id":27227336}],"tv":721.44}]}
{"op":"mcm","clk":"990891108","pt":1580500125432,"mc":[{"id":"1.168133553","rc":[{"batb":[[2,8,6.73]],"ltp":9.0,"tv":2.0,"id":27227336}]}]}
{"op":"mcm","clk":"990900952","pt":1580500205928,"mc":[{"id":"1.168133553","rc":[{"batb":[[1,8.2,2.69],[2,8,6.03]],"ltp":9.0,"tv":2.0,"id":27227336}]}]}
{"op":"mcm","clk":"990902772","pt":1580500220539,"mc":[{"id":"1.168133553","rc":[{"batb":[[0,1.33,3.03],[1,1.32,3.12],[2,1.31,108.66]],"ltp":1.34,"tv":705.63,"id":16325787}]}]}
{"op":"mcm","clk":"990902797","pt":1580500220753,"mc":[{"id":"1.168133553","rc":[{"batb":[[2,1.31,100]],"batl":[[0,1.36,8.41],[1,1.37,158],[2,1.39,800]],"ltp":1.34,"tv":705.63,"id":16325787}]}]}
{"op":"mcm","clk":"990908071","pt":1580500267559,"mc":[{"id":"1.168133553","rc":[{"batb":[[0,1.32,3.12],[1,1.31,100],[2,1.3,276.03]],"ltp":1.34,"tv":705.63,"id":16325787}]}]}
{"op":"mcm","clk":"990929360","pt":1580500376849,"mc":[{"id":"1.168133553","rc":[{"trd":[[1.36,16.82]],"batb":[[0,1.36,6.59],[1,1.32,3.12],[2,1.31,100]],"batl":[[0,1.37,158],[1,1.39,800],[2,1.44,44]],"ltp":1.36,"tv":722.45,"id":16325787}],"tv":738.26}]}
{"op":"mcm","clk":"990929659","pt":1580500379640,"mc":[{"id":"1.168133553","rc":[{"batb":[[0,1.32,3.12],[1,1.31,100],[2,1.3,276.03]],"ltp":1.36,"tv":722.45,"id":16325787}]}]}
{"op":"mcm","clk":"990930438","pt":1580500386194,"mc":[{"id":"1.168133553","rc":[{"trd":[[1.37,12]],"batl":[[0,1.37,152]],"ltp":1.37,"tv":734.45,"id":16325787}],"tv":750.26}]}
{"op":"mcm","clk":"990991688","pt":1580500940883,"mc":[{"id":"1.168133553","rc":[{"batb":[[1,8.2,2.69],[2,8,6.03]],"batl":[[0,9.8,3.03]],"ltp":9.0,"tv":2.0,"id":27227336},{"batl":[[0,7.8,3.03]],"ltp":6.0,"tv":13.81,"id":21641292},{"trd":[[1.41,69.92],[1.42,2.32]],"batb":[[0,1.32,3.12]],"ltp":1.37,"tv":734.45,"id":16325787}],"tv":750.27}]}
{"op":"mcm","clk":"990994186","pt":1580500959308,"mc":[{"id":"1.168133553","rc":[{"batb":[[0,1.32,20.39]],"batl":[[0,1.36,100],[1,1.37,152],[2,1.39,800]],"ltp":1.37,"tv":734.45,"id":16325787}]}]}
{"op":"mcm","clk":"991085640","pt":1580501495543,"mc":[{"id":"1.168133553","rc":[{"batl":[[0,1.35,50.72],[1,1.36,100],[2,1.37,152]],"ltp":1.37,"tv":734.45,"id":16325787}]}]}
{"op":"mcm","clk":"991099676","pt":1580501580775,"mc":[{"id":"1.168133553","rc":[{"batl":[[0,1.34,100],[1,1.35,50.72],[2,1.36,100]],"ltp":1.37,"tv":734.45,"id":16325787}]}]}
{"op":"mcm","clk":"991139545","pt":1580501824400,"mc":[{"id":"1.168133553","rc":[{"trd":[[1.32,40.78]],"batb":[[0,1.31,100],[1,1.3,276.03],[2,1.29,6]],"ltp":1.32,"tv":775.24,"id":16325787}],"tv":791.05}]}
{"op":"mcm","clk":"991140812","pt":1580501831720,"mc":[{"id":"1.168133553","rc":[{"batl":[[0,1.33,50],[1,1.34,100],[2,1.35,50.72]],"ltp":1.32,"tv":775.24,"id":16325787}]}]}
{"op":"mcm","clk":"991143705","pt":1580501848896,"mc":[{"id":"1.168133553","rc":[{"trd":[[1.31,200]],"batb":[[0,1.3,276.03],[1,1.29,22.21],[2,1.28,200]],"ltp":1.31,"tv":975.24,"id":16325787}],"tv":991.05}]}
{"op":"mcm","clk":"991148469","pt":1580501878799,"mc":[{"id":"1.168133553","rc":[{"batb":[[1,1.29,6]],"ltp":1.31,"tv":975.24,"id":16325787}]}]}
{"op":"mcm","clk":"991163110","pt":1580501971643,"mc":[{"id":"1.168133553","rc":[{"trd":[[1.3,400]],"batb":[[0,1.3,76.03]],"ltp":1.3,"tv":1375.24,"id":16325787}],"tv":1391.05}]}
{"op":"mcm","clk":"991164533","pt":1580501981234,"mc":[{"id":"1.168133553","rc":[{"trd":[[1.29,32.51]],"batb":[[0,1.28,200],[1,1.27,39.38],[2,1.26,45.38]],"ltp":1.29,"tv":1407.74,"id":16325787}],"tv":1423.56}]}
{"op":"mcm","clk":"991164725","pt":1580501982572,"mc":[{"id":"1.168133553","rc":[{"batb":[[0,1.29,2],[1,1.28,200],[2,1.27,39.38]],"ltp":1.29,"tv":1407.74,"id":16325787}]}]}
{"op":"mcm","clk":"991165583","pt":1580501988256,"mc":[{"id":"1.168133553","rc":[{"batl":[[0,1.32,6],[1,1.33,50],[2,1.34,100]],"ltp":1.29,"tv":1407.74,"id":16325787}]}]}
{"op":"mcm","clk":"991166114","pt":1580501991158,"mc":[{"id":"1.168133553","rc":[{"batb":[[1,8.4,2.16],[2,8.2,2.69]],"ltp":9.0,"tv":2.0,"id":27227336},{"batb":[[0,6,5.01]],"ltp":6.0,"tv":13.81,"id":21641292},{"batb":[[0,1.29,16.06]],"ltp":1.29,"tv":1407.74,"id":16325787}]}]}
{"op":"mcm","clk":"991175077","pt":1580502048555,"mc":[{"id":"1.168133553","rc":[{"batb":[[1,8.6,1.98],[2,8.4,2.16]],"ltp":9.0,"tv":2.0,"id":27227336}]}]}
{"op":"mcm","clk":"991186797","pt":1580502127609,"mc":[{"id":"1.168133553","rc":[{"batl":[[0,1.32,56]],"ltp":1.29,"tv":1407.74,"id":16325787}]}]}
{"op":"mcm","clk":"991231521","pt":1580502371102,"mc":[{"id":"1.168133553","rc":[{"batb":[[0,1.3,100],[1,1.29,16.06],[2,1.28,200]],"ltp":1.29,"tv":1407.74,"id":16325787}]}]}
{"op":"mcm","clk":"991240692","pt":1580502434100,"mc":[{"id":"1.168133553","rc":[{"trd":[[1.32,54.22]],"batl":[[0,1.32,49.28]],"ltp":1.32,"tv":1421.18,"id":16325787}],"tv":1437.0}]}
{"op":"mcm","clk":"991282768","pt":1580502734284,"mc":[{"id":"1.168133553","rc":[{"batb":[[2,8.4,2.28]],"ltp":9.0,"tv":2.0,"id":27227336},{"batb":[[1,5.9,22.19]],"ltp":6.0,"tv":13.81,"id":21641292}]}]}
{"op":"mcm","clk":"991395377","pt":1580503506234,"mc":[{"id":"1.168133553","marketDefinition":{"bspMarket":true,"turnInPlayEnabled":true,"persistenceEnabled":true,"marketBaseRate":5.0,"eventId":"29678760","eventTypeId":"7","numberOfWinners":1,"bettingType":"ODDS","marketType":"WIN","marketTime":"2020-02-01T14:12:00.000Z","suspendTime":"2020-02-01T14:12:00.000Z","bspReconciled":false,"complete":true,"inPlay":false,"crossMatching":false,"runnersVoidable":false,"numberOfActiveRunners":3,"betDelay":0,"status":"OPEN","runners":[{"adjustmentFactor":70.72,"status":"ACTIVE","sortPriority":1,"id":16325787,"name":"Kalooki"},{"adjustmentFactor":13.85,"status":"ACTIVE","sortPriority":2,"id":21641292,"name":"Lemon T"},{"adjustmentFactor":15.41,"status":"ACTIVE","sortPriority":3,"id":27227336,"name":"Islandray"}],"regulators":["MR_INT"],"venue":"Wetherby","countryCode":"GB","discountAllowed":true,"timezone":"Europe/London","openDate":"2020-02-01T13:03:00.000Z","version":3143869040,"name":"2m5f Nov Hrd","eventName":"Weth  1st Feb"}}]}
{"op":"mcm","clk":"991397581","pt":1580503525053,"mc":[{"id":"1.168133553","rc":[{"trd":[[1.32,152.78]],"batb":[[0,1.32,150.72],[1,1.3,100],[2,1.29,16.06]],"batl":[[0,1.33,50],[1,1.34,100],[2,1.35,50.72]],"ltp":1.32,"tv":1519.74,"id":16325787}],"tv":1535.56}]}
{"op":"mcm","clk":"991398507","pt":1580503532636,"mc":[{"id":"1.168133553","rc":[{"batb":[[1,1.31,6],[2,1.3,100]],"ltp":1.32,"tv":1519.74,"id":16325787}]}]}
{"op":"mcm","clk":"991398728","pt":1580503534273,"mc":[{"id":"1.168133553","rc":[{"trd":[[6,13.86]],"batb":[[0,6,3]],"ltp":6.0,"tv":17.81,"id":21641292}],"tv":1539.56}]}
{"op":"mcm","clk":"991406025","pt":1580503594345,"mc":[{"id":"1.168133553","rc":[{"trd":[[6,19.86]],"batb":[[0,5.9,22.19],[1,5.5,3.29],[2,5.2,19.71]],"batl":[[0,6,7],[1,7.8,3.03],[2,8,11.83]],"ltp":6.0,"tv":23.82,"id":21641292}],"tv":1545.57}]}
{"op":"mcm","clk":"991406058","pt":1580503594659,"mc":[{"id":"1.168133553","rc":[{"trd":[[6,33.87]],"batl":[[0,7.8,3.03],[1,8,11.83],[2,25,9.22]],"ltp":6.0,"tv":37.82,"id":21641292},{"trd":[[1.33,3.36]],"batl":[[0,1.33,48.32]],"ltp":1.33,"tv":1523.1,"id":16325787}],"tv":1562.93}]}
{"op":"mcm","clk":"991423888","pt":1580503754606,"mc":[{"id":"1.168133553","rc":[{"batb":[[2,8.4,12.28]],"ltp":9.0,"tv":2.0,"id":27227336}]}]}
{"op":"mcm","clk":"991425262","pt":1580503767357,"mc":[{"id":"1.168133553","rc":[{"batb":[[0,6.2,1.68],[1,5.9,22.19],[2,5.5,3.29]],"ltp":6.0,"tv":37.82,"id":21641292}]}]}
{"op":"mcm","clk":"991425368","pt":1580503768446,"mc":[{"id":"1.168133553","rc":[{"batb":[[0,5.9,22.19],[1,5.5,3.29],[2,5.2,19.71]],"ltp":6.0,"tv":37.82,"id":21641292}]}]}
{"op":"mcm","clk":"991465388","pt":1580504072577,"mc":[{"id":"1.168133553","rc":[{"batl":[[0,1.33,66.32]],"ltp":1.33,"tv":1523.1,"id":16325787}]}]}
{"op":"mcm","clk":"991474529","pt":1580504226800,"mc":[{"id":"1.168133553","rc":[{"trd":[[1.32,212.78]],"batb":[[0,1.32,120.72]],"ltp":1.32,"tv":1583.1,"id":16325787}],"tv":1622.93}]}
{"op":"mcm","clk":"991492907","pt":1580504470784,"mc":[{"id":"1.168133553","rc":[{"batb":[[1,8.8,2.27],[2,8.6,1.98]],"ltp":9.0,"tv":2.0,"id":27227336}]}]}
{"op":"mcm","clk":"991493366","pt":1580504476397,"mc":[{"id":"1.168133553","rc":[{"batb":[[2,8.6,2.09]],"ltp":9.0,"tv":2.0,"id":27227336}]}]}
{"op":"mcm","clk":"991493844","pt":1580504482479,"mc":[{"id":"1.168133553","rc":[{"trd":[[1.33,43.36]],"batl":[[0,1.33,46.32]],"ltp":1.33,"tv":1623.1,"id":16325787}],"tv":1662.93}]}
{"op":"mcm","clk":"991494395","pt":1580504488469,"mc":[{"id":"1.168133553","rc":[{"trd":[[1.33,83.36]],"batl":[[0,1.33,26.32]],"ltp":1.33,"tv":1663.1,"id":16325787}],"tv":1702.93}]}
{"op":"mcm","clk":"991495659","pt":1580504504491,"mc":[{"id":"1.168133553","rc":[{"trd":[[1.33,123.36]],"batl":[[0,1.33,6.32]],"ltp":1.33,"tv":1703.1,"id":16325787}],"tv":1742.93}]}
{"op":"mcm","clk":"991500779","pt":1580504575115,"mc":[{"id":"1.168133553","rc":[{"batl":[[0,1.33,56.32]],"ltp":1.33,"tv":1703.1,"id":16325787}]}]}
{"op":"mcm","clk":"991505837","pt":1580504641771,"mc":[{"id":"1.168133553","rc":[{"trd":[[1.32,454.22]],"batb":[[0,1.31,6],[1,1.3,100],[2,1.29,16.06]],"batl":[[0,1.32,17.49],[1,1.33,56.32],[2,1.34,100]],"ltp":1.32,"tv":1944.54,"id":16325787}],"tv":1984.37}]}
{"op":"mcm","clk":"991505981","pt":1580504643278,"mc":[{"id":"1.168133553","rc":[{"trd":[[1.32,466.22]],"batl":[[0,1.32,11.49]],"ltp":1.32,"tv":1956.54,"id":16325787}],"tv":1996.37}]}
{"op":"mcm","clk":"991506086","pt":1580504644476,"mc":[{"id":"1.168133553","rc":[{"trd":[[1.32,478.22]],"batl":[[0,1.32,5.49]],"ltp":1.32,"tv":1968.54,"id":16325787}],"tv":2008.37}]}
{"op":"mcm","clk":"991506176","pt":1580504645469,"mc":[{"id":"1.168133553","rc":[{"trd":[[1.32,486.22]],"batl":[[0,1.32,1.49]],"ltp":1.32,"tv":1976.54,"id":16325787}],"tv":2016.37}]}
{"op":"mcm","clk":"991506244","pt":1580504646298,"mc":[{"id":"1.168133553","rc":[{"trd":[[1.32,489.2]],"batl":[[0,1.33,56.32],[1,1.34,100],[2,1.35,50.72]],"ltp":1.32,"tv":1979.52,"id":16325787}],"tv":2019.35}]}
{"op":"mcm","clk":"991506285","pt":1580504646818,"mc":[{"id":"1.168133553","rc":[{"batl":[[0,1.33,406.32]],"ltp":1.32,"tv":1979.52,"id":16325787}]}]}
{"op":"mcm","clk":"991506350","pt":1580504647606,"mc":[{"id":"1.168133553","rc":[{"batl":[[2,1.35,400.72]],"ltp":1.32,"tv":1979.52,"id":16325787}]}]}
{"op":"mcm","clk":"991506522","pt":1580504649527,"mc":[{"id":"1.168133553","rc":[{"batl":[[0,1.33,56.32]],"ltp":1.32,"tv":1979.52,"id":16325787}]}]}
{"op":"mcm","clk":"991506582","pt":1580504650103,"mc":[{"id":"1.168133553","rc":[{"batl":[[2,1.35,50.72]],"ltp":1.32,"tv":1979.52,"id":16325787}]}]}
{"op":"mcm","clk":"991506875","pt":1580504653230,"mc":[{"id":"1.168133553","rc":[{"batb":[[0,6,2.87],[1,5.9,22.19],[2,5.5,3.29]],"ltp":6.0,"tv":37.82,"id":21641292}]}]}
{"op":"mcm","clk":"991507091","pt":1580504655532,"mc":[{"id":"1.168133553","rc":[{"batl":[[0,1.33,106.32]],"ltp":1.32,"tv":1979.52,"id":16325787}]}]}
{"op":"mcm","clk":"991507545","pt":1580504660527,"mc":[{"id":"1.168133553","rc":[{"batl":[[2,1.35,100.72]],"ltp":1.32,"tv":1979.52,"id":16325787}]}]}
{"op":"mcm","clk":"991510770","pt":1580504699888,"mc":[{"id":"1.168133553","rc":[{"batb":[[2,1.29,75.66]],"ltp":1.32,"tv":1979.52,"id":16325787}]}]}
{"op":"mcm","clk":"991545700","pt":1580505007547,"mc":[{"id":"1.168133553","rc":[{"batb":[[0,1.32,13.04],[1,1.31,6],[2,1.3,100]],"ltp":1.32,"tv":1979.52,"id":16325787}]}]}
{"op":"mcm","clk":"991560422","pt":1580505207200,"mc":[{"id":"1.168133553","rc":[{"trd":[[1.32,509.21]],"batb":[[0,1.32,3.04]],"ltp":1.32,"tv":1999.53,"id":16325787}],"tv":2039.35}]}
{"op":"mcm","clk":"991630146","pt":1580505969820,"mc":[{"id":"1.168133553","rc":[{"batl":[[2,1.35,155.72]],"ltp":1.32,"tv":1999.53,"id":16325787}]}]}
{"op":"mcm","clk":"991638355","pt":1580506115410,"mc":[{"id":"1.168133553","rc":[{"batl":[[1,1.34,110]],"ltp":1.32,"tv":1999.53,"id":16325787}]}]}
{"op":"mcm","clk":"991659818","pt":1580506447529,"mc":[{"id":"1.168133553","rc":[{"batl":[[2,1.35,180.92]],"ltp":1.32,"tv":1999.53,"id":16325787}]}]}
{"op":"mcm","clk":"991708066","pt":1580507045247,"mc":[{"id":"1.168133553","rc":[{"trd":[[6,37.86]],"batb":[[0,5.9,23.06],[1,5.5,3.29],[2,5.2,19.71]],"ltp":6.0,"tv":41.82,"id":21641292}],"tv":2043.35}]}
{"op":"mcm","clk":"991708334","pt":1580507050437,"mc":[{"id":"1.168133553","rc":[{"batl":[[0,7.6,2],[1,7.8,3.03],[2,8,11.83]],"ltp":6.0,"tv":41.82,"id":21641292}]}]}
{"op":"mcm","clk":"991723400","pt":1580507303233,"mc":[{"id":"1.168133553","rc":[{"trd":[[1.32,515.29]],"batb":[[0,1.31,6],[1,1.3,100],[2,1.29,135.66]],"ltp":1.32,"tv":2005.61,"id":16325787}],"tv":2049.43}]}
{"op":"mcm","clk":"991726750","pt":1580507363505,"mc":[{"id":"1.168133553","rc":[{"batl":[[0,1.32,4],[1,1.33,106.32],[2,1.34,110]],"ltp":1.32,"tv":2005.61,"id":16325787}]}]}
{"op":"mcm","clk":"991726810","pt":1580507364537,"mc":[{"id":"1.168133553","rc":[{"trd":[[1.32,519.29]],"batl":[[0,1.32,2]],"ltp":1.32,"tv":2009.61,"id":16325787}],"tv":2053.43}]}
{"op":"mcm","clk":"991726833","pt":1580507364844,"mc":[{"id":"1.168133553","rc":[{"trd":[[1.32,523.29]],"batl":[[0,1.33,106.32],[1,1.34,110],[2,1.35,180.92]],"ltp":1.32,"tv":2013.61,"id":16325787}],"tv":2057.43}]}
{"op":"mcm","clk":"991805268","pt":1580508452097,"mc":[{"id":"1.168133553","rc":[{"trd":[[6,37.86]],"ltp":6.0,"tv":41.82,"id":21641292},{"trd":[[1.29,32.52],[1.41,69.93],[1.42,2.32],[1.51,12.72]],"batb":[[2,1.29,135.64]],"batl":[[2,1.35,180.86]],"ltp":1.32,"tv":2013.63,"id":16325787}],"tv":2057.45}]}
{"op":"mcm","clk":"991823940","pt":1580508683346,"mc":[{"id":"1.168133553","rc":[{"batl":[[0,1.32,50],[1,1.33,106.32],[2,1.34,110]],"ltp":1.32,"tv":2013.63,"id":16325787}]}]}
{"op":"mcm","clk":"991824016","pt":1580508684335,"mc":[{"id":"1.168133553","rc":[{"trd":[[1.32,527.29]],"batl":[[0,1.32,48]],"ltp":1.32,"tv":2017.63,"id":16325787}],"tv":2061.45}]}
{"op":"mcm","clk":"991824082","pt":1580508685215,"mc":[{"id":"1.168133553","rc":[{"trd":[[1.32,539.29]],"batl":[[0,1.32,42]],"ltp":1.32,"tv":2029.63,"id":16325787}],"tv":2073.45}]}
{"op":"mcm","clk":"991824175","pt":1580508686559,"mc":[{"id":"1.168133553","rc":[{"trd":[[1.32,555.29]],"batl":[[0,1.32,34]],"ltp":1.32,"tv":2045.63,"id":16325787}],"tv":2089.45}]}
{"op":"mcm","clk":"991824251","pt":1580508687535,"mc":[{"id":"1.168133553","rc":[{"trd":[[1.32,567.29]],"batl":[[0,1.32,28]],"ltp":1.32,"tv":2057.63,"id":16325787}],"tv":2101.45}]}
{"op":"mcm","clk":"991824320","pt":1580508688418,"mc":[{"id":"1.168133553","rc":[{"trd":[[1.32,579.29]],"batl":[[0,1.32,22]],"ltp":1.32,"tv":2069.63,"id":16325787}],"tv":2113.45}]}
{"op":"mcm","clk":"991824380","pt":1580508689552,"mc":[{"id":"1.168133553","rc":[{"trd":[[1.32,591.29]],"batl":[[0,1.32,16]],"ltp":1.32,"tv":2081.63,"id":16325787}],"tv":2125.45}]}
{"op":"mcm","clk":"991824453","pt":1580508690432,"mc":[{"id":"1.168133553","rc":[{"trd":[[1.32,603.29]],"batl":[[0,1.32,10]],"ltp":1.32,"tv":2093.63,"id":16325787}],"tv":2137.45}]}
{"op":"mcm","clk":"991824517","pt":1580508691418,"mc":[{"id":"1.168133553","rc":[{"trd":[[1.32,615.29]],"batl":[[0,1.32,4]],"ltp":1.32,"tv":2105.63,"id":16325787}],"tv":2149.45}]}
{"op":"mcm","clk":"991824559","pt":1580508692037,"mc":[{"id":"1.168133553","rc":[{"trd":[[1.32,623.29]],"batl":[[0,1.33,106.32],[1,1.34,110],[2,1.35,180.86]],"ltp":1.32,"tv":2113.63,"id":16325787}],"tv":2157.45}]}
{"op":"mcm","clk":"991826813","pt":1580508723491,"mc":[{"id":"1.168133553","rc":[{"trd":[[5.9,16.26],[6,39.6]],"batb":[[0,5.9,14.06]],"ltp":5.9,"tv":59.82,"id":21641292},{"trd":[[1.31,212]],"batb":[[0,1.3,100],[1,1.29,135.64],[2,1.28,200]],"ltp":1.31,"tv":2125.63,"id":16325787}],"tv":2187.45}]}
{"op":"mcm","clk":"991826839","pt":1580508723901,"mc":[{"id":"1.168133553","rc":[{"batl":[[1,29,9.17],[2,50,2]],"ltp":9.0,"tv":2.0,"id":27227336},{"trd":[[5.9,28.26]],"batb":[[0,5.9,8.06],[2,5.3,23.11]],"batl":[[2,25,9.22]],"ltp":5.9,"tv":71.82,"id":21641292},{"trd":[[1.31,224]],"batb":[[0,1.31,331.89],[1,1.3,100],[2,1.29,135.64]],"ltp":1.31,"tv":2137.63,"id":16325787}],"tv":2211.45}]}
{"op":"mcm","clk":"991827023","pt":1580508727007,"mc":[{"id":"1.168133553","rc":[{"batl":[[0,1.32,6],[1,1.33,106.32],[2,1.34,110]],"ltp":1.31,"tv":2137.63,"id":16325787}]}]}
{"op":"mcm","clk":"991827132","pt":1580508728502,"mc":[{"id":"1.168133553","rc":[{"trd":[[1.32,635.29]],"batl":[[0,1.33,106.32],[1,1.34,110],[2,1.35,180.86]],"ltp":1.32,"tv":2149.63,"id":16325787}],"tv":2223.45}]}
{"op":"mcm","clk":"991827177","pt":1580508729220,"mc":[{"id":"1.168133553","rc":[{"batb":[[0,5.9,22.19]],"ltp":5.9,"tv":71.82,"id":21641292}]}]}
{"op":"mcm","clk":"991827485","pt":1580508734045,"mc":[{"id":"1.168133553","rc":[{"trd":[[9.8,4]],"batl":[[0,9.8,9.29],[1,28,3.03],[2,29,9.17]],"ltp":9.8,"tv":6.0,"id":27227336},{"batl":[[1,7.8,17.64]],"ltp":5.9,"tv":71.82,"id":21641292}],"tv":2227.45}]}
{"op":"mcm","clk":"991828133","pt":1580508744502,"mc":[{"id":"1.168133553","rc":[{"batl":[[0,9.8,11.29]],"ltp":9.8,"tv":6.0,"id":27227336}]}]}
{"op":"mcm","clk":"991839031","pt":1580508948349,"mc":[{"id":"1.168133553","rc":[{"batl":[[0,28,3.03],[1,29,9.17],[2,50,2]],"ltp":9.8,"tv":6.0,"id":27227336},{"batb":[[2,4.9,3.09]],"batl":[[1,7.8,3.03]],"ltp":5.9,"tv":71.82,"id":21641292},{"batb":[[0,1.31,11.33]],"ltp":1.32,"tv":2149.63,"id":16325787}]}]}
{"op":"mcm","clk":"991839144","pt":1580508950455,"mc":[{"id":"1.168133553","rc":[{"batl":[[0,28,3.22],[1,29,9]],"ltp":9.8,"tv":6.0,"id":27227336}]}]}
{"op":"mcm","clk":"991839339","pt":1580508953570,"mc":[{"id":"1.168133553","rc":[{"batl":[[0,28,3.4]],"ltp":9.8,"tv":6.0,"id":27227336}]}]}
{"op":"mcm","clk":"991839453","pt":1580508956048,"mc":[{"id":"1.168133553","rc":[{"batl":[[0,27,1.96],[1,28,3.03],[2,29,9]],"ltp":9.8,"tv":6.0,"id":27227336}]}]}
{"op":"mcm","clk":"991841729","pt":1580508998565,"mc":[{"id":"1.168133553","rc":[{"batb":[[0,5.5,3.46],[1,4.9,3.09],[2,4.5,33]],"ltp":5.9,"tv":71.82,"id":21641292}]}]}
{"op":"mcm","clk":"991841850","pt":1580509000428,"mc":[{"id":"1.168133553","rc":[{"batl":[[0,7.4,5.79],[1,7.6,2],[2,7.8,3.03]],"ltp":5.9,"tv":71.82,"id":21641292}]}]}
{"op":"mcm","clk":"991842699","pt":1580509017184,"mc":[{"id":"1.168133553","rc":[{"batl":[[0,7.2,2],[1,7.4,5.79]],"ltp":5.9,"tv":71.82,"id":21641292}]}]}
{"op":"mcm","clk":"991842774","pt":1580509018477,"mc":[{"id":"1.168133553","rc":[{"batb":[[0,9,2.98],[2,8.4,15.26]],"ltp":9.8,"tv":6.0,"id":27227336},{"batb":[[0,5.6,2.44],[1,5.5,3],[2,4.9,3.09]],"ltp":5.9,"tv":71.82,"id":21641292}]}]}
{"op":"mcm","clk":"991842784","pt":1580509018684,"mc":[{"id":"1.168133553","rc":[{"batb":[[2,8.6,2.11]],"ltp":9.8,"tv":6.0,"id":27227336}]}]}
{"op":"mcm","clk":"991842923","pt":1580509021377,"mc":[{"id":"1.168133553","rc":[{"batl":[[1,7.8,3.03],[2,25,9.22]],"ltp":5.9,"tv":71.82,"id":21641292}]}]}
{"op":"mcm","clk":"991845448","pt":1580509071359,"mc":[{"id":"1.168133553","rc":[{"batb":[[1,8.6,2.11],[2,8.4,15.16]],"ltp":9.8,"tv":6.0,"id":27227336},{"batl":[[0,7.6,2]],"ltp":5.9,"tv":71.82,"id":21641292}]}]}
{"op":"mcm","clk":"991846088","pt":1580509085590,"mc":[{"id":"1.168133553","rc":[{"batl":[[0,7.4,5.79],[1,7.6,2],[2,7.8,3.03]],"ltp":5.9,"tv":71.82,"id":21641292}]}]}
{"op":"mcm","clk":"991846492","pt":1580509094999,"mc":[{"id":"1.168133553","rc":[{"batb":[[1,8.6,5.14]],"ltp":9.8,"tv":6.0,"id":27227336}]}]}
{"op":"mcm","clk":"991846817","pt":1580509101431,"mc":[{"id":"1.168133553","rc":[{"batb":[[0,9,1],[1,8.8,1.98],[2,8.6,5.14]],"ltp":9.8,"tv":6.0,"id":27227336}]}]}
{"op":"mcm","clk":"991847985","pt":1580509125268,"mc":[{"id":"1.168133553","rc":[{"batl":[[0,7.2,2],[1,7.4,5.79]],"ltp":5.9,"tv":71.82,"id":21641292}]}]}
{"op":"mcm","clk":"991848146","pt":1580509128091,"mc":[{"id":"1.168133553","rc":[{"batl":[[1,7.8,3.03],[2,25,9.22]],"ltp":5.9,"tv":71.82,"id":21641292}]}]}
{"op":"mcm","clk":"991849113","pt":1580509151298,"mc":[{"id":"1.168133553","rc":[{"batb":[[0,1.3,100],[1,1.29,135.64],[2,1.28,200]],"batl":[[0,1.32,5.95],[1,1.33,126.32],[2,1.34,110]],"ltp":1.32,"tv":2149.63,"id":16325787}]}]}
{"op":"mcm","clk":"991850477","pt":1580509178541,"mc":[{"id":"1.168133553","rc":[{"batl":[[0,7.6,2]],"ltp":5.9,"tv":71.82,"id":21641292}]}]}
{"op":"mcm","clk":"991851048","pt":1580509191443,"mc":[{"id":"1.168133553","rc":[{"batl":[[0,7.4,5.79],[1,7.6,2],[2,7.8,3.03]],"ltp":5.9,"tv":71.82,"id":21641292}]}]}
{"op":"mcm","clk":"991851976","pt":1580509210966,"mc":[{"id":"1.168133553","rc":[{"trd":[[1.32,637.89]],"batl":[[0,1.32,4.65]],"ltp":1.32,"tv":2152.23,"id":16325787}],"tv":2230.05}]}
{"op":"mcm","clk":"991852972","pt":1580509232498,"mc":[{"id":"1.168133553","rc":[{"batl":[[1,7.8,3.03],[2,25,9.22]],"ltp":5.9,"tv":71.82,"id":21641292}]}]}
{"op":"mcm","clk":"991853001","pt":1580509233325,"mc":[{"id":"1.168133553","rc":[{"batl":[[0,7.2,2]],"ltp":5.9,"tv":71.82,"id":21641292}]}]}
{"op":"mcm","clk":"991855497","pt":1580509285511,"mc":[{"id":"1.168133553","rc":[{"batl":[[0,7.6,2]],"ltp":5.9,"tv":71.82,"id":21641292}]}]}
{"op":"mcm","clk":"991855819","pt":1580509292034,"mc":[{"id":"1.168133553","rc":[{"batl":[[0,7.4,5.79],[1,7.6,2],[2,7.8,3.03]],"ltp":5.9,"tv":71.82,"id":21641292}]}]}
{"op":"mcm","clk":"991858123","pt":1580509338816,"mc":[{"id":"1.168133553","rc":[{"batl":[[0,7.2,2],[1,7.4,5.79]],"ltp":5.9,"tv":71.82,"id":21641292}]}]}
{"op":"mcm","clk":"991868426","pt":1580509353341,"mc":[{"id":"1.168133553","rc":[{"batl":[[1,7.8,3.03],[2,25,9.22]],"ltp":5.9,"tv":71.82,"id":21641292}]}]}
{"op":"mcm","clk":"991870181","pt":1580509392434,"mc":[{"id":"1.168133553","rc":[{"batl":[[0,7.6,2]],"ltp":5.9,"tv":71.82,"id":21641292}]}]}
{"op":"mcm","clk":"991870323","pt":1580509395122,"mc":[{"id":"1.168133553","rc":[{"batl":[[0,7.4,5.79],[1,7.6,2],[2,7.8,3.03]],"ltp":5.9,"tv":71.82,"id":21641292}]}]}
{"op":"mcm","clk":"991872844","pt":1580509446002,"mc":[{"id":"1.168133553","rc":[{"batl":[[0,7.2,2],[1,7.4,5.79]],"ltp":5.9,"tv":71.82,"id":21641292}]}]}
{"op":"mcm","clk":"991873345","pt":1580509456325,"mc":[{"id":"1.168133553","rc":[{"batl":[[1,7.8,3.03],[2,25,9.22]],"ltp":5.9,"tv":71.82,"id":21641292}]}]}
{"op":"mcm","clk":"991875623","pt":1580509499295,"mc":[{"id":"1.168133553","rc":[{"batl":[[0,7.6,2]],"ltp":5.9,"tv":71.82,"id":21641292}]}]}
{"op":"mcm","clk":"991876763","pt":1580509519133,"mc":[{"id":"1.168133553","rc":[{"batl":[[0,7.4,5.79],[1,7.6,2],[2,7.8,3.03]],"ltp":5.9,"tv":71.82,"id":21641292}]}]}
{"op":"mcm","clk":"991878488","pt":1580509552482,"mc":[{"id":"1.168133553","rc":[{"batl":[[1,7.8,3.03],[2,25,9.22]],"ltp":5.9,"tv":71.82,"id":21641292}]}]}
{"op":"mcm","clk":"991878495","pt":1580509552586,"mc":[{"id":"1.168133553","rc":[{"batl":[[0,7.2,2],[1,7.4,5.79],[2,7.8,3.03]],"ltp":5.9,"tv":71.82,"id":21641292}]}]}
{"op":"mcm","clk":"991878924","pt":1580509561858,"mc":[{"id":"1.168133553","rc":[{"batl":[[1,7.8,3.03],[2,25,9.22]],"ltp":5.9,"tv":71.82,"id":21641292}]}]}
{"op":"mcm","clk":"991880729","pt":1580509605919,"mc":[{"id":"1.168133553","rc":[{"batl":[[0,7.6,2]],"ltp":5.9,"tv":71.82,"id":21641292}]}]}
{"op":"mcm","clk":"991881553","pt":1580509625473,"mc":[{"id":"1.168133553","rc":[{"batl":[[0,7.4,5.79],[1,7.6,2],[2,7.8,3.03]],"ltp":5.9,"tv":71.82,"id":21641292}]}]}
{"op":"mcm","clk":"991883007","pt":1580509659510,"mc":[{"id":"1.168133553","rc":[{"batl":[[1,7.8,3.03],[2,25,9.22]],"ltp":5.9,"tv":71.82,"id":21641292}]}]}
{"op":"mcm","clk":"991883013","pt":1580509659626,"mc":[{"id":"1.168133553","rc":[{"batl":[[0,7.2,2],[1,7.4,5.79],[2,7.8,3.03]],"ltp":5.9,"tv":71.82,"id":21641292}]}]}
{"op":"mcm","clk":"991883300","pt":1580509666724,"mc":[{"id":"1.168133553","rc":[{"batl":[[1,7.8,3.03],[2,25,9.22]],"ltp":5.9,"tv":71.82,"id":21641292}]}]}
{"op":"mcm","clk":"991883625","pt":1580509674724,"mc":[{"id":"1.168133553","rc":[{"batl":[[0,7,5.07],[1,7.2,2],[2,7.8,3.03]],"ltp":5.9,"tv":71.82,"id":21641292}]}]}
{"op":"mcm","clk":"991885368","pt":1580509713707,"mc":[{"id":"1.168133553","rc":[{"batl":[[0,6.8,2],[1,7,5.07]],"ltp":5.9,"tv":71.82,"id":21641292}]}]}
{"op":"mcm","clk":"991890651","pt":1580509820555,"mc":[{"id":"1.168133553","rc":[{"batb":[[0,9,3.22]],"ltp":9.8,"tv":6.0,"id":27227336}]}]}
{"op":"mcm","clk":"991893784","pt":1580509894426,"mc":[{"id":"1.168133553","rc":[{"batb":[[0,9.2,1.98],[1,9,3.22]],"ltp":9.8,"tv":6.0,"id":27227336}]}]}
{"op":"mcm","clk":"991893910","pt":1580509896335,"mc":[{"id":"1.168133553","rc":[{"batb":[[2,8.6,5.03]],"ltp":9.8,"tv":6.0,"id":27227336}]}]}
{"op":"mcm","clk":"991893940","pt":1580509897056,"mc":[{"id":"1.168133553","rc":[{"batb":[[1,9,3.32]],"ltp":9.8,"tv":6.0,"id":27227336}]}]}
{"op":"mcm","clk":"991900452","pt":1580510046596,"mc":[{"id":"1.168133553","rc":[{"batl":[[2,1.34,113.79]],"ltp":1.32,"tv":2152.23,"id":16325787}]}]}
{"op":"mcm","clk":"991902222","pt":1580510084484,"mc":[{"id":"1.168133553","rc":[{"batl":[[0,11,20],[1,27,1.96],[2,28,3.03]],"ltp":9.8,"tv":6.0,"id":27227336}]}]}
{"op":"mcm","clk":"991902355","pt":1580510087378,"mc":[{"id":"1.168133553","rc":[{"batl":[[1,27,1.78]],"ltp":9.8,"tv":6.0,"id":27227336}]}]}
{"op":"mcm","clk":"991902878","pt":1580510098510,"mc":[{"id":"1.168133553","rc":[{"batl":[[1,28,3.22],[2,29,9]],"ltp":9.8,"tv":6.0,"id":27227336}]}]}
{"op":"mcm","clk":"991903565","pt":1580510112106,"mc":[{"id":"1.168133553","rc":[{"batl":[[0,10.5,3.03],[1,11,20],[2,29,9.19]],"ltp":9.8,"tv":6.0,"id":27227336}]}]}
{"op":"mcm","clk":"991907511","pt":1580510209649,"mc":[{"id":"1.168133553","rc":[{"batl":[[2,1.34,138.79]],"ltp":1.32,"tv":2152.23,"id":16325787}]}]}
{"op":"mcm","clk":"991907767","pt":1580510215979,"mc":[{"id":"1.168133553","rc":[{"trd":[[1.32,647.19]],"batb":[[0,1.32,25.35],[1,1.3,100],[2,1.29,135.64]],"batl":[[0,1.33,126.32],[1,1.34,138.79],[2,1.35,184.64]],"ltp":1.32,"tv":2161.53,"id":16325787}],"tv":2239.35}]}
{"op":"mcm","clk":"991908169","pt":1580510226562,"mc":[{"id":"1.168133553","rc":[{"batb":[[0,1.32,50.35]],"ltp":1.32,"tv":2161.53,"id":16325787}]}]}
{"op":"mcm","clk":"991908557","pt":1580510237009,"mc":[{"id":"1.168133553","rc":[{"batb":[[0,1.32,25]],"ltp":1.32,"tv":2161.53,"id":16325787}]}]}
{"op":"mcm","clk":"991908670","pt":1580510240096,"mc":[{"id":"1.168133553","rc":[{"trd":[[1.32,655.59]],"batb":[[0,1.32,20.8]],"ltp":1.32,"tv":2169.93,"id":16325787}],"tv":2247.76}]}
{"op":"mcm","clk":"991909013","pt":1580510249349,"mc":[{"id":"1.168133553","rc":[{"trd":[[1.33,173.36]],"batl":[[0,1.33,101.32]],"ltp":1.33,"tv":2219.93,"id":16325787}],"tv":2297.76}]}
{"op":"mcm","clk":"991919212","pt":1580510265247,"mc":[{"id":"1.168133553","rc":[{"trd":[[1.32,663.99]],"batb":[[0,1.32,16.6]],"ltp":1.32,"tv":2228.33,"id":16325787}],"tv":2306.16}]}
{"op":"mcm","clk":"991922800","pt":1580510350506,"mc":[{"id":"1.168133553","rc":[{"batl":[[1,1.34,135]],"ltp":1.32,"tv":2228.33,"id":16325787}]}]}
{"op":"mcm","clk":"991922846","pt":1580510351190,"mc":[{"id":"1.168133553","rc":[{"batl":[[0,1.33,105.11]],"ltp":1.32,"tv":2228.33,"id":16325787}]}]}
{"op":"mcm","clk":"991936520","pt":1580510680454,"mc":[{"id":"1.168133553","rc":[{"batl":[[0,1.33,101.32],[2,1.35,180.86]],"ltp":1.32,"tv":2228.33,"id":16325787}]}]}
{"op":"mcm","clk":"991948978","pt":1580510935015,"mc":[{"id":"1.168133553","rc":[{"trd":[[1.32,669.99]],"batb":[[0,1.32,13.6]],"ltp":1.32,"tv":2234.33,"id":16325787}],"tv":2312.16}]}
{"op":"mcm","clk":"991970420","pt":1580511210575,"mc":[{"id":"1.168133553","rc":[{"trd":[[1.32,697.19]],"batb":[[0,1.3,100],[1,1.29,135.64],[2,1.28,200]],"batl":[[0,1.33,102.11]],"ltp":1.32,"tv":2261.53,"id":16325787}],"tv":2339.36}]}
{"op":"mcm","clk":"991983101","pt":1580511524283,"mc":[{"id":"1.168133553","rc":[{"batb":[[0,1.31,100],[1,1.3,100],[2,1.29,135.64]],"ltp":1.32,"tv":2261.53,"id":16325787}]}]}
{"op":"mcm","clk":"991983826","pt":1580511540625,"mc":[{"id":"1.168133553","rc":[{"batb":[[0,1.3,100],[1,1.29,135.64],[2,1.28,200]],"ltp":1.32,"tv":2261.53,"id":16325787}]}]}
{"op":"mcm","clk":"991984079","pt":1580511546134,"mc":[{"id":"1.168133553","rc":[{"batb":[[0,1.31,50],[1,1.3,100],[2,1.29,135.64]],"ltp":1.32,"tv":2261.53,"id":16325787}]}]}
{"op":"mcm","clk":"991984096","pt":1580511546598,"mc":[{"id":"1.168133553","rc":[{"batb":[[1,1.3,150]],"ltp":1.32,"tv":2261.53,"id":16325787}]}]}
{"op":"mcm","clk":"991984217","pt":1580511549533,"mc":[{"id":"1.168133553","rc":[{"batb":[[2,1.29,185.64]],"ltp":1.32,"tv":2261.53,"id":16325787}]}]}
{"op":"mcm","clk":"991986243","pt":1580511594317,"mc":[{"id":"1.168133553","rc":[{"trd":[[1.31,234]],"batb":[[0,1.31,45]],"ltp":1.31,"tv":2271.53,"id":16325787}],"tv":2349.36}]}
{"op":"mcm","clk":"991986288","pt":1580511594931,"mc":[{"id":"1.168133553","rc":[{"batl":[[0,1.32,5.75],[1,1.33,101.32],[2,1.34,135]],"ltp":1.31,"tv":2271.53,"id":16325787}]}]}
{"op":"mcm","clk":"991988435","pt":1580511631564,"mc":[{"id":"1.168133553","rc":[{"batl":[[0,1.32,15.75]],"ltp":1.31,"tv":2271.53,"id":16325787}]}]}
{"op":"mcm","clk":"991994145","pt":1580511768007,"mc":[{"id":"1.168133553","rc":[{"batb":[[0,1.31,17.32],[2,1.29,190.61]],"ltp":1.31,"tv":2271.53,"id":16325787}]}]}
{"op":"mcm","clk":"991994217","pt":1580511769507,"mc":[{"id":"1.168133553","rc":[{"batb":[[2,1.29,185.64]],"ltp":1.31,"tv":2271.53,"id":16325787}]}]}
{"op":"mcm","clk":"991994398","pt":1580511772325,"mc":[{"id":"1.168133553","rc":[{"batl":[[0,1.32,10.79]],"ltp":1.31,"tv":2271.53,"id":16325787}]}]}
{"op":"mcm","clk":"991994448","pt":1580511773378,"mc":[{"id":"1.168133553","rc":[{"trd":[[1.31,244]],"batb":[[0,1.31,12.32]],"ltp":1.31,"tv":2281.53,"id":16325787}],"tv":2359.36}]}
{"op":"mcm","clk":"992004794","pt":1580511997190,"mc":[{"id":"1.168133553","rc":[{"batl":[[0,1.32,13.82]],"ltp":1.31,"tv":2281.53,"id":16325787}]}]}
{"op":"mcm","clk":"992033224","pt":1580512442230,"mc":[{"id":"1.168133553","rc":[{"batb":[[1,1.3,100],[2,1.29,135.64]],"ltp":1.31,"tv":2281.53,"id":16325787}]}]}
{"op":"mcm","clk":"992068862","pt":1580513079479,"mc":[{"id":"1.168133553","rc":[{"trd":[[5.8,5.46],[5.9,28.6]],"batb":[[0,5.6,2.27]],"ltp":5.8,"tv":77.62,"id":21641292}],"tv":2365.15}]}
{"op":"mcm","clk":"992068884","pt":1580513079991,"mc":[{"id":"1.168133553","rc":[{"trd":[[10.5,6.06]],"batl":[[0,11,20],[1,29,9.19],[2,50,2]],"ltp":10.5,"tv":12.05,"id":27227336},{"trd":[[1.32,724.83]],"batl":[[0,1.33,101.32],[1,1.34,135],[2,1.35,180.86]],"ltp":1.32,"tv":2309.17,"id":16325787}],"tv":2398.85}]}
{"op":"mcm","clk":"992069091","pt":1580513085299,"mc":[{"id":"1.168133553","rc":[{"batb":[[1,5,3.3],[2,4.9,3.03]],"batl":[[0,6.8,2.15]],"ltp":5.8,"tv":77.62,"id":21641292}]}]}
{"op":"mcm","clk":"992069134","pt":1580513086895,"mc":[{"id":"1.168133553","rc":[{"trd":[[5.8,9.46]],"ltp":5.8,"tv":81.62,"id":21641292}],"tv":2402.85}]}
{"op":"mcm","clk":"992069236","pt":1580513090398,"mc":[{"id":"1.168133553","rc":[{"trd":[[5.8,13.46]],"ltp":5.8,"tv":85.62,"id":21641292}],"tv":2406.85}]}
{"op":"mcm","clk":"992069330","pt":1580513093437,"mc":[{"id":"1.168133553","rc":[{"trd":[[5.8,17.46]],"ltp":5.8,"tv":89.62,"id":21641292}],"tv":2410.85}]}
{"op":"mcm","clk":"992069491","pt":1580513098440,"mc":[{"id":"1.168133553","rc":[{"trd":[[11,2.1]],"batl":[[0,11,18.95]],"ltp":11.0,"tv":14.15,"id":27227336},{"trd":[[5.8,21.46]],"ltp":5.8,"tv":93.62,"id":21641292},{"trd":[[1.33,190.8]],"batl":[[0,1.33,92.6]],"ltp":1.33,"tv":2326.61,"id":16325787}],"tv":2434.39}]}
{"op":"mcm","clk":"992069588","pt":1580513101012,"mc":[{"id":"1.168133553","rc":[{"trd":[[5.8,27.46]],"ltp":5.8,"tv":99.62,"id":21641292}],"tv":2440.39}]}
{"op":"mcm","clk":"992069754","pt":1580513105346,"mc":[{"id":"1.168133553","rc":[{"batb":[[2,8.6,5.69]],"ltp":11.0,"tv":14.15,"id":27227336},{"batb":[[1,5.1,3.32],[2,5,3]],"ltp":5.8,"tv":99.62,"id":21641292}]}]}
{"op":"mcm","clk":"992070668","pt":1580513131193,"mc":[{"id":"1.168133553","rc":[{"batb":[[0,5.2,2.51],[1,5.1,3.09]],"ltp":5.8,"tv":99.62,"id":21641292}]}]}
{"op":"mcm","clk":"992073067","pt":1580513198515,"mc":[{"id":"1.168133553","rc":[{"batb":[[0,1.31,62.32]],"ltp":1.33,"tv":2326.61,"id":16325787}]}]}
{"op":"mcm","clk":"992073195","pt":1580513202083,"mc":[{"id":"1.168133553","rc":[{"trd":[[1.33,194.8]],"batb":[[1,1.3,150]],"batl":[[0,1.33,90.6]],"ltp":1.33,"tv":2330.61,"id":16325787}],"tv":2444.39}]}
{"op":"mcm","clk":"992074419","pt":1580513232159,"mc":[{"id":"1.168133553","rc":[{"batb":[[0,1.31,12.32],[1,1.3,100]],"ltp":1.33,"tv":2330.61,"id":16325787}]}]}
{"op":"mcm","clk":"992082437","pt":1580513420430,"mc":[{"id":"1.168133553","rc":[{"trd":[[1.3,453.36],[1.31,268.64]],"batb":[[0,1.3,73.32],[1,1.29,135.64],[2,1.28,200]],"ltp":1.3,"tv":2408.61,"id":16325787}],"tv":2522.39}]}
{"op":"mcm","clk":"992084217","pt":1580513462979,"mc":[{"id":"1.168133553","rc":[{"trd":[[1.3,457.36]],"batb":[[0,1.3,71.32]],"ltp":1.3,"tv":2412.61,"id":16325787}],"tv":2526.39}]}
{"op":"mcm","clk":"992119558","pt":1580514065570,"mc":[{"id":"1.168133553","rc":[{"trd":[[1.33,200.76]],"batl":[[0,1.33,87.62]],"ltp":1.33,"tv":2418.57,"id":16325787}],"tv":2532.36}]}
{"op":"mcm","clk":"992119606","pt":1580514067164,"mc":[{"id":"1.168133553","rc":[{"batl":[[0,1.33,89.13]],"ltp":1.33,"tv":2418.57,"id":16325787}]}]}
{"op":"mcm","clk":"992127261","pt":1580514294908,"mc":[{"id":"1.168133553","rc":[{"batl":[[0,11,39.95]],"ltp":11.0,"tv":14.15,"id":27227336}]}]}
{"op":"mcm","clk":"992135547","pt":1580514568786,"mc":[{"id":"1.168133553","rc":[{"batb":[[0,1.3,81.32]],"ltp":1.33,"tv":2418.57,"id":16325787}]}]}
{"op":"mcm","clk":"992135604","pt":1580514571569,"mc":[{"id":"1.168133553","rc":[{"batb":[[0,1.3,91.32]],"ltp":1.33,"tv":2418.57,"id":16325787}]}]}
{"op":"mcm","clk":"992135715","pt":1580514575591,"mc":[{"id":"1.168133553","rc":[{"batb":[[0,1.31,3],[1,1.3,91.32],[2,1.29,135.64]],"ltp":1.33,"tv":2418.57,"id":16325787}]}]}
{"op":"mcm","clk":"992135822","pt":1580514580276,"mc":[{"id":"1.168133553","rc":[{"batl":[[0,1.33,92.13]],"ltp":1.33,"tv":2418.57,"id":16325787}]}]}
{"op":"mcm","clk":"992135862","pt":1580514583410,"mc":[{"id":"1.168133553","rc":[{"batl":[[0,1.32,3],[1,1.33,92.13],[2,1.34,135]],"ltp":1.33,"tv":2418.57,"id":16325787}]}]}
{"op":"mcm","clk":"992135892","pt":1580514585976,"mc":[{"id":"1.168133553","rc":[{"batl":[[0,1.33,92.13],[1,1.34,135],[2,1.35,180.86]],"ltp":1.33,"tv":2418.57,"id":16325787}]}]}
{"op":"mcm","clk":"992136522","pt":1580514619214,"mc":[{"id":"1.168133553","rc":[{"batb":[[0,1.3,91.32],[1,1.29,135.64],[2,1.28,200]],"ltp":1.33,"tv":2418.57,"id":16325787}]}]}
{"op":"mcm","clk":"992136586","pt":1580514621421,"mc":[{"id":"1.168133553","rc":[{"batb":[[0,1.3,71.32]],"batl":[[0,1.33,89.13]],"ltp":1.33,"tv":2418.57,"id":16325787}]}]}
{"op":"mcm","clk":"992138931","pt":1580514717471,"mc":[{"id":"1.168133553","rc":[{"batl":[[0,1.32,2],[1,1.33,89.13],[2,1.34,135]],"ltp":1.33,"tv":2418.57,"id":16325787}]}]}
{"op":"mcm","clk":"992138940","pt":1580514718088,"mc":[{"id":"1.168133553","rc":[{"batl":[[0,1.33,89.13],[1,1.34,135],[2,1.35,180.86]],"ltp":1.33,"tv":2418.57,"id":16325787}]}]}
{"op":"mcm","clk":"992151842","pt":1580514851351,"mc":[{"id":"1.168133553","rc":[{"batl":[[0,1.32,58],[1,1.33,89.13],[2,1.34,135]],"ltp":1.33,"tv":2418.57,"id":16325787}]}]}
{"op":"mcm","clk":"992153808","pt":1580514925400,"mc":[{"id":"1.168133553","rc":[{"trd":[[1.3,599.25]],"batb":[[0,1.29,135.98],[1,1.28,200],[2,1.27,6]],"ltp":1.3,"tv":2560.46,"id":16325787}],"tv":2674.25}]}
{"op":"mcm","clk":"992153814","pt":1580514925605,"mc":[{"id":"1.168133553","rc":[{"batb":[[1,1.28,219.81]],"ltp":1.3,"tv":2560.46,"id":16325787}]}]}
{"op":"mcm","clk":"992154075","pt":1580514933604,"mc":[{"id":"1.168133553","rc":[{"batl":[[0,1.31,151.95],[1,1.32,58],[2,1.33,89.13]],"ltp":1.3,"tv":2560.46,"id":16325787}]}]}
{"op":"mcm","clk":"992154284","pt":1580514940823,"mc":[{"id":"1.168133553","rc":[{"batl":[[1,1.32,159.3]],"ltp":1.3,"tv":2560.46,"id":16325787}]}]}
{"op":"mcm","clk":"992154608","pt":1580514955564,"mc":[{"id":"1.168133553","rc":[{"batb":[[1,1.28,200]],"ltp":1.3,"tv":2560.46,"id":16325787}]}]}
{"op":"mcm","clk":"992160931","pt":1580515222253,"mc":[{"id":"1.168133553","rc":[{"batb":[[0,5.3,4.52],[1,5.2,1.98],[2,5.1,3.09]],"ltp":5.8,"tv":99.62,"id":21641292}]}]}
{"op":"mcm","clk":"992161140","pt":1580515230035,"mc":[{"id":"1.168133553","rc":[{"batb":[[0,5.4,3.55],[1,5.3,4],[2,5.2,1.98]],"ltp":5.8,"tv":99.62,"id":21641292}]}]}
{"op":"mcm","clk":"992161407","pt":1580515236868,"mc":[{"id":"1.168133553","rc":[{"batb":[[1,5.2,1.98],[2,5,3.06]],"ltp":5.8,"tv":99.62,"id":21641292}]}]}
{"op":"mcm","clk":"992162386","pt":1580515264391,"mc":[{"id":"1.168133553","rc":[{"batb":[[0,5.2,2.51],[1,5.1,3.09],[2,5,3]],"ltp":5.8,"tv":99.62,"id":21641292}]}]}
{"op":"mcm","clk":"992166339","pt":1580515391443,"mc":[{"id":"1.168133553","rc":[{"trd":[[1.31,572.55]],"batl":[[0,1.32,159.3],[1,1.33,89.13],[2,1.34,135]],"ltp":1.31,"tv":2864.37,"id":16325787}],"tv":2978.15}]}
{"op":"mcm","clk":"992167376","pt":1580515416452,"mc":[{"id":"1.168133553","rc":[{"batb":[[0,1.3,382.75],[1,1.29,135.64],[2,1.28,200]],"ltp":1.31,"tv":2864.37,"id":16325787}]}]}
{"op":"mcm","clk":"992168964","pt":1580515471543,"mc":[{"id":"1.168133553","rc":[{"trd":[[1.31,575.91]],"batl":[[0,1.32,159.39]],"ltp":1.31,"tv":2867.73,"id":16325787}],"tv":2981.51}]}
{"op":"mcm","clk":"992168989","pt":1580515472268,"mc":[{"id":"1.168133553","rc":[{"batb":[[0,1.31,1.68],[1,1.3,382.75],[2,1.29,135.64]],"batl":[[0,1.32,159.3]],"ltp":1.31,"tv":2867.73,"id":16325787}]}]}
{"op":"mcm","clk":"992169279","pt":1580515483346,"mc":[{"id":"1.168133553","rc":[{"batl":[[0,1.32,172.38]],"ltp":1.31,"tv":2867.73,"id":16325787}]}]}
{"op":"mcm","clk":"992172193","pt":1580515582210,"mc":[{"id":"1.168133553","rc":[{"batb":[[0,1.3,382.75],[1,1.29,135.64],[2,1.28,200]],"ltp":1.31,"tv":2867.73,"id":16325787}]}]}
{"op":"mcm","clk":"992173544","pt":1580515621327,"mc":[{"id":"1.168133553","rc":[{"batb":[[0,1.31,1.68],[1,1.3,382.75],[2,1.29,135.64]],"ltp":1.31,"tv":2867.73,"id":16325787}]}]}
{"op":"mcm","clk":"992173755","pt":1580515627349,"mc":[{"id":"1.168133553","rc":[{"batl":[[1,1.33,87.62]],"ltp":1.31,"tv":2867.73,"id":16325787}]}]}
{"op":"mcm","clk":"992173962","pt":1580515630539,"mc":[{"id":"1.168133553","rc":[{"trd":[[1.32,728.37]],"batl":[[0,1.32,170.61]],"ltp":1.32,"tv":2871.27,"id":16325787}],"tv":2985.05}]}
{"op":"mcm","clk":"992174134","pt":1580515633354,"mc":[{"id":"1.168133553","rc":[{"batb":[[0,1.3,382.75],[1,1.29,135.64],[2,1.28,200]],"batl":[[0,1.32,157.53]],"ltp":1.32,"tv":2871.27,"id":16325787}]}]}
{"op":"mcm","clk":"992174156","pt":1580515633867,"mc":[{"id":"1.168133553","rc":[{"batl":[[0,1.32,157.63]],"ltp":1.32,"tv":2871.27,"id":16325787}]}]}
{"op":"mcm","clk":"992174528","pt":1580515641163,"mc":[{"id":"1.168133553","rc":[{"trd":[[1.3,599.45]],"batb":[[0,1.3,382.65]],"batl":[[0,1.32,157.53]],"ltp":1.3,"tv":2871.47,"id":16325787}],"tv":2985.25}]}
{"op":"mcm","clk":"992187466","pt":1580515742095,"mc":[{"id":"1.168133553","rc":[{"batl":[[0,6.8,9.65]],"ltp":5.8,"tv":99.62,"id":21641292}]}]}
{"op":"mcm","clk":"992187496","pt":1580515743488,"mc":[{"id":"1.168133553","rc":[{"batl":[[0,6.6,7.65],[1,6.8,2],[2,7,5.07]],"ltp":5.8,"tv":99.62,"id":21641292}]}]}
{"op":"mcm","clk":"992187526","pt":1580515745085,"mc":[{"id":"1.168133553","rc":[{"trd":[[11,8.5]],"batl":[[0,11,36.75]],"ltp":11.0,"tv":20.55,"id":27227336},{"trd":[[6.4,15]],"batl":[[0,6.8,2.15],[1,7,5.07],[2,7.8,3.03]],"ltp":6.4,"tv":114.62,"id":21641292},{"trd":[[1.32,781.71]],"batl":[[0,1.32,130.86]],"ltp":1.32,"tv":2924.81,"id":16325787}],"tv":3059.99}]}
{"op":"mcm","clk":"992187576","pt":1580515747817,"mc":[{"id":"1.168133553","rc":[{"batb":[[0,5.3,3.52],[1,5.2,1.98],[2,5.1,3.09]],"ltp":6.4,"tv":114.62,"id":21641292}]}]}
{"op":"mcm","clk":"992187864","pt":1580515762132,"mc":[{"id":"1.168133553","rc":[{"batb":[[0,5.4,3.52]],"ltp":6.4,"tv":114.62,"id":21641292}]}]}
{"op":"mcm","clk":"992188153","pt":1580515776168,"mc":[{"id":"1.168133553","rc":[{"batb":[[0,5.5,3.52]],"ltp":6.4,"tv":114.62,"id":21641292}]}]}
{"op":"mcm","clk":"992201856","pt":1580516351380,"mc":[{"id":"1.168133553","rc":[{"batb":[[0,5.6,2.27],[1,5.5,3.24]],"ltp":6.4,"tv":114.62,"id":21641292}]}]}
{"op":"mcm","clk":"992203544","pt":1580516438899,"mc":[{"id":"1.168133553","rc":[{"batb":[[2,5.2,3]],"ltp":6.4,"tv":114.62,"id":21641292}]}]}
{"op":"mcm","clk":"992233413","pt":1580517182512,"mc":[{"id":"1.168133553","rc":[{"batb":[[2,8.8,2.01]],"ltp":11.0,"tv":20.55,"id":27227336},{"batb":[[2,5.2,4.68]],"ltp":6.4,"tv":114.62,"id":21641292},{"batb":[[0,1.31,1.68],[1,1.3,382.65],[2,1.29,135.64]],"ltp":1.32,"tv":2924.81,"id":16325787}]}]}
{"op":"mcm","clk":"992234006","pt":1580517203610,"mc":[{"id":"1.168133553","rc":[{"batb":[[2,5.2,1.68]],"ltp":6.4,"tv":114.62,"id":21641292}]}]}
{"op":"mcm","clk":"992234119","pt":1580517207493,"mc":[{"id":"1.168133553","rc":[{"batb":[[2,5.1,3.09]],"ltp":6.4,"tv":114.62,"id":21641292}]}]}
{"op":"mcm","clk":"992239338","pt":1580517389369,"mc":[{"id":"1.168133553","rc":[{"batb":[[1,1.3,410.65]],"ltp":1.32,"tv":2924.81,"id":16325787}]}]}
{"op":"mcm","clk":"992258615","pt":1580517823248,"mc":[{"id":"1.168133553","rc":[{"trd":[[1.31,590.79]],"batb":[[0,1.3,410.65],[1,1.29,135.64],[2,1.28,200]],"ltp":1.31,"tv":2939.69,"id":16325787}],"tv":3074.87}]}
{"op":"mcm","clk":"992258684","pt":1580517826038,"mc":[{"id":"1.168133553","rc":[{"batb":[[0,1.31,1.68],[1,1.3,410.65],[2,1.29,135.64]],"ltp":1.31,"tv":2939.69,"id":16325787}]}]}
{"op":"mcm","clk":"992283675","pt":1580518516954,"mc":[{"id":"1.168133553","rc":[{"batb":[[2,1.29,145.84]],"ltp":1.31,"tv":2939.69,"id":16325787}]}]}
{"op":"mcm","clk":"992285698","pt":1580518601388,"mc":[{"id":"1.168133553","rc":[{"trd":[[9,8.64],[9.2,3.96]],"batb":[[0,8.8,2.01],[1,8.6,5.69],[2,8.4,14.34]],"batl":[[0,11,37.35]],"ltp":9.0,"tv":31.16,"id":27227336}],"tv":3085.48}]}
{"op":"mcm","clk":"992285773","pt":1580518604215,"mc":[{"id":"1.168133553","rc":[{"batb":[[0,8.6,5.69],[1,8.4,14.34],[2,7,1.46]],"batl":[[0,11,37.45]],"ltp":9.0,"tv":31.16,"id":27227336}]}]}
{"op":"mcm","clk":"992285882","pt":1580518607516,"mc":[{"id":"1.168133553","rc":[{"batb":[[2,8,3.7]],"ltp":9.0,"tv":31.16,"id":27227336}]}]}
{"op":"mcm","clk":"992285884","pt":1580518607617,"mc":[{"id":"1.168133553","rc":[{"batb":[[2,8,3.85]],"ltp":9.0,"tv":31.16,"id":27227336}]}]}
{"op":"mcm","clk":"992285963","pt":1580518610095,"mc":[{"id":"1.168133553","rc":[{"batb":[[0,8.6,7.75]],"ltp":9.0,"tv":31.16,"id":27227336}]}]}
{"op":"mcm","clk":"992286135","pt":1580518615625,"mc":[{"id":"1.168133553","rc":[{"batb":[[0,1.31,23.68]],"ltp":1.31,"tv":2939.69,"id":16325787}]}]}
{"op":"mcm","clk":"992286598","pt":1580518630948,"mc":[{"id":"1.168133553","rc":[{"batb":[[1,8.4,12.16]],"ltp":9.0,"tv":31.16,"id":27227336}]}]}
{"op":"mcm","clk":"992287103","pt":1580518650560,"mc":[{"id":"1.168133553","rc":[{"batb":[[0,5.6,4.27]],"ltp":6.4,"tv":114.62,"id":21641292}]}]}
{"op":"mcm","clk":"992287297","pt":1580518658081,"mc":[{"id":"1.168133553","rc":[{"trd":[[1.32,825.71]],"batb":[[0,1.31,1.68]],"batl":[[0,1.32,108.86]],"ltp":1.32,"tv":2983.69,"id":16325787}],"tv":3129.48}]}
{"op":"mcm","clk":"992291257","pt":1580518805845,"mc":[{"id":"1.168133553","rc":[{"batb":[[0,8.8,1.98],[1,8.6,7.75],[2,8.4,12.16]],"ltp":9.0,"tv":31.16,"id":27227336}]}]}
{"op":"mcm","clk":"992335540","pt":1580520149471,"mc":[{"id":"1.168133553","rc":[{"trd":[[6.2,6.99]],"ltp":6.2,"tv":117.65,"id":21641292},{"trd":[[1.32,850.91]],"batl":[[0,1.32,96.27]],"ltp":1.32,"tv":3008.89,"id":16325787}],"tv":3157.7}]}
{"op":"mcm","clk":"992335555","pt":1580520149985,"mc":[{"id":"1.168133553","rc":[{"batb":[[0,6.2,1.51],[1,5.6,4.27],[2,5.5,3.24]],"ltp":6.2,"tv":117.65,"id":21641292}]}]}
{"op":"mcm","clk":"992345470","pt":1580520153507,"mc":[{"id":"1.168133553","rc":[{"batb":[[0,5.6,4.27],[1,5.5,3.24],[2,5.1,3.09]],"ltp":6.2,"tv":117.65,"id":21641292}]}]}
{"op":"mcm","clk":"992345489","pt":1580520154277,"mc":[{"id":"1.168133553","rc":[{"trd":[[6.6,0.3]],"batb":[[0,6.6,1.27],[1,5.6,4.27],[2,5.5,3.24]],"batl":[[0,6.8,2]],"ltp":6.6,"tv":117.95,"id":21641292}],"tv":3158.0}]}
{"op":"mcm","clk":"992345523","pt":1580520155101,"mc":[{"id":"1.168133553","rc":[{"batb":[[1,5.7,3.29],[2,5.6,3.98]],"ltp":6.6,"tv":117.95,"id":21641292}]}]}
{"op":"mcm","clk":"992345577","pt":1580520157472,"mc":[{"id":"1.168133553","rc":[{"batb":[[0,5.7,3.29],[1,5.6,3.98],[2,5.1,3.32]],"ltp":6.6,"tv":117.95,"id":21641292}]}]}
{"op":"mcm","clk":"992345595","pt":1580520158296,"mc":[{"id":"1.168133553","rc":[{"trd":[[6.8,4]],"batb":[[0,5.7,3.46]],"batl":[[0,7,5.07],[1,7.8,3.03],[2,25,9.22]],"ltp":6.8,"tv":121.95,"id":21641292}],"tv":3162.01}]}
{"op":"mcm","clk":"992345747","pt":1580520165511,"mc":[{"id":"1.168133553","rc":[{"batb":[[0,5.8,3.17],[1,5.6,4.27]],"ltp":6.8,"tv":121.95,"id":21641292}]}]}
{"op":"mcm","clk":"992345944","pt":1580520175830,"mc":[{"id":"1.168133553","rc":[{"batb":[[0,5.9,3.17]],"ltp":6.8,"tv":121.95,"id":21641292}]}]}
{"op":"mcm","clk":"992346236","pt":1580520186417,"mc":[{"id":"1.168133553","rc":[{"batb":[[0,6,3],[1,5.6,4.44]],"ltp":6.8,"tv":121.95,"id":21641292}]}]}
{"op":"mcm","clk":"992346514","pt":1580520196221,"mc":[{"id":"1.168133553","rc":[{"batb":[[0,5.8,7.55],[1,5.7,3.29],[2,5.6,3.98]],"ltp":6.8,"tv":121.95,"id":21641292}]}]}
{"op":"mcm","clk":"992346768","pt":1580520206464,"mc":[{"id":"1.168133553","rc":[{"batb":[[0,5.9,3.17],[1,5.8,7.39],[2,5.7,3.38]],"ltp":6.8,"tv":121.95,"id":21641292}]}]}
{"op":"mcm","clk":"992347050","pt":1580520216288,"mc":[{"id":"1.168133553","rc":[{"batb":[[0,6,3],[1,5.7,3.55],[2,5.6,3.98]],"ltp":6.8,"tv":121.95,"id":21641292}]}]}
{"op":"mcm","clk":"992347134","pt":1580520220998,"mc":[{"id":"1.168133553","rc":[{"batb":[[1,5.6,4.44],[2,5.1,3.32]],"ltp":6.8,"tv":121.95,"id":21641292}]}]}
{"op":"mcm","clk":"992347231","pt":1580520225810,"mc":[{"id":"1.168133553","rc":[{"batb":[[0,5.7,3.46],[1,5.6,3.98]],"ltp":6.8,"tv":121.95,"id":21641292}]}]}
{"op":"mcm","clk":"992347490","pt":1580520235395,"mc":[{"id":"1.168133553","rc":[{"batb":[[0,5.8,7.55],[1,5.7,3.29],[2,5.6,3.98]],"ltp":6.8,"tv":121.95,"id":21641292}]}]}
{"op":"mcm","clk":"992347513","pt":1580520236690,"mc":[{"id":"1.168133553","rc":[{"batb":[[0,5.9,3.17],[1,5.8,7.39],[2,5.6,4.27]],"ltp":6.8,"tv":121.95,"id":21641292}]}]}
{"op":"mcm","clk":"992347688","pt":1580520243813,"mc":[{"id":"1.168133553","rc":[{"batb":[[2,5.7,3.38]],"ltp":6.8,"tv":121.95,"id":21641292}]}]}
{"op":"mcm","clk":"992347784","pt":1580520246991,"mc":[{"id":"1.168133553","rc":[{"batb":[[0,6,3],[1,5.8,7.55]],"ltp":6.8,"tv":121.95,"id":21641292}]}]}
{"op":"mcm","clk":"992347951","pt":1580520255492,"mc":[{"id":"1.168133553","rc":[{"batb":[[0,5.7,3.55],[1,5.6,3.98],[2,5.1,3.32]],"ltp":6.8,"tv":121.95,"id":21641292}]}]}
{"op":"mcm","clk":"992347963","pt":1580520256215,"mc":[{"id":"1.168133553","rc":[{"trd":[[5.8,33.46],[5.9,28.93]],"batb":[[0,5.7,3.38]],"ltp":5.8,"tv":128.29,"id":21641292}],"tv":3168.34}]}
{"op":"mcm","clk":"992347981","pt":1580520256887,"mc":[{"id":"1.168133553","rc":[{"batb":[[2,5.2,3.24]],"ltp":5.8,"tv":128.29,"id":21641292}]}]}
{"op":"mcm","clk":"992348079","pt":1580520260098,"mc":[{"id":"1.168133553","rc":[{"batb":[[0,5.6,4.27],[1,5.2,3.24],[2,5.1,3.09]],"batl":[[0,7,5.22]],"ltp":5.8,"tv":128.29,"id":21641292}]}]}
{"op":"mcm","clk":"992348618","pt":1580520280156,"mc":[{"id":"1.168133553","rc":[{"batb":[[1,5.1,3.32],[2,4.6,1.68]],"ltp":5.8,"tv":128.29,"id":21641292}]}]}
{"op":"mcm","clk":"992350415","pt":1580520343068,"mc":[{"id":"1.168133553","rc":[{"trd":[[1.32,1043.38]],"batl":[[0,1.33,87.65],[1,1.34,157],[2,1.35,180.86]],"ltp":1.32,"tv":3201.36,"id":16325787}],"tv":3360.82}]}
{"op":"mcm","clk":"992351153","pt":1580520372588,"mc":[{"id":"1.168133553","rc":[{"batl":[[1,1.34,135]],"ltp":1.32,"tv":3201.36,"id":16325787}]}]}
{"op":"mcm","clk":"992351279","pt":1580520377818,"mc":[{"id":"1.168133553","rc":[{"trd":[[1.32,1043.44]],"batb":[[0,1.32,4.17],[1,1.31,1.68],[2,1.3,410.65]],"batl":[[0,1.33,87.62]],"ltp":1.32,"tv":3201.43,"id":16325787}],"tv":3360.88}]}
{"op":"mcm","clk":"992351312","pt":1580520378694,"mc":[{"id":"1.168133553","rc":[{"batb":[[0,1.31,1.68],[1,1.3,410.65],[2,1.29,145.84]],"batl":[[0,1.33,87.65]],"ltp":1.32,"tv":3201.43,"id":16325787}]}]}
{"op":"mcm","clk":"992351371","pt":1580520380484,"mc":[{"id":"1.168133553","rc":[{"batl":[[0,1.33,87.62]],"ltp":1.32,"tv":3201.43,"id":16325787}]}]}
{"op":"mcm","clk":"992351387","pt":1580520381410,"mc":[{"id":"1.168133553","rc":[{"trd":[[1.31,590.85]],"batb":[[0,1.31,1.65]],"ltp":1.31,"tv":3201.49,"id":16325787}],"tv":3360.95}]}
{"op":"mcm","clk":"992352021","pt":1580520405753,"mc":[{"id":"1.168133553","rc":[{"batb":[[1,1.3,314.42]],"ltp":1.31,"tv":3201.49,"id":16325787}]}]}
{"op":"mcm","clk":"992355352","pt":1580520531888,"mc":[{"id":"1.168133553","rc":[{"batl":[[0,6.4,2],[1,7,5.22],[2,7.8,3.03]],"ltp":5.8,"tv":128.29,"id":21641292}]}]}
{"op":"mcm","clk":"992355433","pt":1580520534887,"mc":[{"id":"1.168133553","rc":[{"batl":[[0,6.2,2]],"ltp":5.8,"tv":128.29,"id":21641292}]}]}
{"op":"mcm","clk":"992355552","pt":1580520538084,"mc":[{"id":"1.168133553","rc":[{"trd":[[9.6,0.18],[11,10.52]],"batb":[[0,8.8,2.85]],"batl":[[0,11,36.34]],"ltp":11.0,"tv":33.36,"id":27227336},{"trd":[[6,43.6]],"batl":[[0,7,5.22],[1,7.8,3.03],[2,25,9.22]],"ltp":6.0,"tv":132.29,"id":21641292},{"trd":[[1.33,218.84]],"batl":[[0,1.33,78.58]],"ltp":1.33,"tv":3219.57,"id":16325787}],"tv":3385.23}]}
{"op":"mcm","clk":"992355584","pt":1580520538860,"mc":[{"id":"1.168133553","rc":[{"batl":[[0,1.33,89.49]],"ltp":1.33,"tv":3219.57,"id":16325787}]}]}
{"op":"mcm","clk":"992355703","pt":1580520542993,"mc":[{"id":"1.168133553","rc":[{"batb":[[0,8.8,2.95]],"ltp":11.0,"tv":33.36,"id":27227336}]}]}
{"op":"mcm","clk":"992355733","pt":1580520544386,"mc":[{"id":"1.168133553","rc":[{"batb":[[0,9,5.73],[1,8.8,1.98],[2,8.6,7.75]],"ltp":11.0,"tv":33.36,"id":27227336}]}]}
{"op":"mcm","clk":"992358893","pt":1580520650454,"mc":[{"id":"1.168133553","rc":[{"batb":[[0,9.2,2.85],[1,9,4.86]],"ltp":11.0,"tv":33.36,"id":27227336}]}]}
{"op":"mcm","clk":"992359178","pt":1580520660651,"mc":[{"id":"1.168133553","rc":[{"batb":[[1,8.6,7.85],[2,8.4,12.16]],"ltp":11.0,"tv":33.36,"id":27227336}]}]}
{"op":"mcm","clk":"992359570","pt":1580520674683,"mc":[{"id":"1.168133553","rc":[{"batb":[[2,8.4,10]],"ltp":11.0,"tv":33.36,"id":27227336}]}]}
{"op":"mcm","clk":"992359934","pt":1580520686896,"mc":[{"id":"1.168133553","rc":[{"batb":[[0,9.4,3.23],[1,9.2,1.98],[2,8.6,7.85]],"ltp":11.0,"tv":33.36,"id":27227336}]}]}
{"op":"mcm","clk":"992367951","pt":1580521013441,"mc":[{"id":"1.168133553","rc":[{"batb":[[2,8.6,10.05]],"ltp":11.0,"tv":33.36,"id":27227336}]}]}
{"op":"mcm","clk":"992368142","pt":1580521019757,"mc":[{"id":"1.168133553","rc":[{"batb":[[2,8.8,2.3]],"ltp":11.0,"tv":33.36,"id":27227336}]}]}
{"op":"mcm","clk":"992380233","pt":1580521132300,"mc":[{"id":"1.168133553","rc":[{"batb":[[1,1.3,316.42]],"ltp":1.33,"tv":3219.57,"id":16325787}]}]}
{"op":"mcm","clk":"992382847","pt":1580521261558,"mc":[{"id":"1.168133553","rc":[{"batb":[[1,8.8,2.3],[2,8.6,7.75]],"ltp":11.0,"tv":33.36,"id":27227336}]}]}
{"op":"mcm","clk":"992382864","pt":1580521262435,"mc":[{"id":"1.168133553","rc":[{"batb":[[0,9.6,2.85],[1,9.4,2.36],[2,8.8,2.3]],"ltp":11.0,"tv":33.36,"id":27227336}]}]}
{"op":"mcm","clk":"992384490","pt":1580521338257,"mc":[{"id":"1.168133553","rc":[{"batb":[[0,5.7,2.68],[1,5.6,3.98],[2,5.1,3.32]],"ltp":6.0,"tv":132.29,"id":21641292}]}]}
{"op":"mcm","clk":"992398522","pt":1580521939389,"mc":[{"id":"1.168133553","rc":[{"batb":[[0,9.6,5.05],[2,8.6,7.85]],"ltp":11.0,"tv":33.36,"id":27227336}]}]}
{"op":"mcm","clk":"992398541","pt":1580521940110,"mc":[{"id":"1.168133553","rc":[{"batb":[[0,9.8,1.76],[1,9.6,5.05],[2,9.4,2.36]],"ltp":11.0,"tv":33.36,"id":27227336}]}]}
{"op":"mcm","clk":"992478417","pt":1580523762226,"mc":[{"id":"1.168133553","rc":[{"batl":[[0,1.32,122.58],[1,1.33,89.49],[2,1.34,135]],"ltp":1.33,"tv":3219.57,"id":16325787}]}]}
{"op":"mcm","clk":"992478482","pt":1580523763617,"mc":[{"id":"1.168133553","rc":[{"batl":[[1,1.33,78.58]],"ltp":1.33,"tv":3219.57,"id":16325787}]}]}
{"op":"mcm","clk":"992483397","pt":1580523949838,"mc":[{"id":"1.168133553","rc":[{"trd":[[1.32,1288.59]],"batl":[[0,1.33,78.58],[1,1.34,135],[2,1.35,180.86]],"ltp":1.32,"tv":3464.72,"id":16325787}],"tv":3630.38}]}
{"op":"mcm","clk":"992483460","pt":1580523951346,"mc":[{"id":"1.168133553","rc":[{"batl":[[0,1.33,89.55]],"ltp":1.32,"tv":3464.72,"id":16325787}]}]}
{"op":"mcm","clk":"992484154","pt":1580523974373,"mc":[{"id":"1.168133553","rc":[{"batb":[[1,1.3,193.84]],"batl":[[0,1.32,17.19],[1,1.33,89.55],[2,1.34,135]],"ltp":1.32,"tv":3464.72,"id":16325787}]}]}
{"op":"mcm","clk":"992484193","pt":1580523975403,"mc":[{"id":"1.168133553","rc":[{"batl":[[1,1.33,78.58]],"ltp":1.32,"tv":3464.72,"id":16325787}]}]}
{"op":"mcm","clk":"992484485","pt":1580523986104,"mc":[{"id":"1.168133553","rc":[{"trd":[[1.32,1322.04]],"batl":[[0,1.33,79.04],[1,1.34,135],[2,1.35,180.86]],"ltp":1.32,"tv":3498.17,"id":16325787}],"tv":3663.83}]}
{"op":"mcm","clk":"992485590","pt":1580524019552,"mc":[{"id":"1.168133553","rc":[{"batb":[[1,1.3,177.13]],"ltp":1.32,"tv":3498.17,"id":16325787}]}]}
{"op":"mcm","clk":"992485770","pt":1580524026042,"mc":[{"id":"1.168133553","rc":[{"batl":[[0,1.33,90.02]],"ltp":1.32,"tv":3498.17,"id":16325787}]}]}
{"op":"mcm","clk":"992542475","pt":1580525337593,"mc":[{"id":"1.168133553","rc":[{"trd":[[1.32,1322.96],[1.33,237.92]],"batl":[[0,1.33,80.02]],"ltp":1.33,"tv":3518.17,"id":16325787}],"tv":3683.83}]}
{"op":"mcm","clk":"992569711","pt":1580525899550,"mc":[{"id":"1.168133553","rc":[{"batb":[[1,1.3,30.24]],"ltp":1.33,"tv":3518.17,"id":16325787}]}]}
{"op":"mcm","clk":"992572786","pt":1580526012085,"mc":[{"id":"1.168133553","rc":[{"batb":[[0,1.31,148.53]],"ltp":1.33,"tv":3518.17,"id":16325787}]}]}
{"op":"mcm","clk":"992618309","pt":1580527000174,"mc":[{"id":"1.168133553","rc":[{"trd":[[1.31,600.85]],"batb":[[0,1.31,143.54]],"ltp":1.31,"tv":3528.16,"id":16325787}],"tv":3693.82}]}
{"op":"mcm","clk":"992618625","pt":1580527005935,"mc":[{"id":"1.168133553","rc":[{"batb":[[0,1.32,1.68],[1,1.31,143.54],[2,1.3,30.24]],"ltp":1.31,"tv":3528.16,"id":16325787}]}]}
{"op":"mcm","clk":"992733158","pt":1580529597253,"mc":[{"id":"1.168133553","rc":[{"batb":[[1,1.3,30.24],[2,1.29,145.84]],"ltp":1.31,"tv":3528.16,"id":16325787}]}]}
{"op":"mcm","clk":"992733269","pt":1580529600549,"mc":[{"id":"1.168133553","rc":[{"batb":[[0,1.3,30.24],[1,1.29,145.84],[2,1.28,200]],"ltp":1.31,"tv":3528.16,"id":16325787}]}]}
{"op":"mcm","clk":"992733724","pt":1580529608367,"mc":[{"id":"1.168133553","rc":[{"trd":[[1.33,397.05]],"batb":[[0,1.31,1.68],[1,1.3,30.24],[2,1.29,145.84]],"batl":[[0,1.34,135.42],[1,1.35,180.86],[2,1.36,100]],"ltp":1.33,"tv":3687.29,"id":16325787}],"tv":3852.94}]}
{"op":"mcm","clk":"992736227","pt":1580529663314,"mc":[{"id":"1.168133553","rc":[{"trd":[[1.33,397.89],[1.34,731.66]],"batl":[[0,1.34,71.03]],"ltp":1.34,"tv":3816.0,"id":16325787}],"tv":3981.66}]}
{"op":"mcm","clk":"992736283","pt":1580529664500,"mc":[{"id":"1.168133553","rc":[{"batb":[[1,1.3,41.47]],"ltp":1.34,"tv":3816.0,"id":16325787}]}]}
{"op":"mcm","clk":"992778130","pt":1580530371662,"mc":[{"id":"1.168133553","rc":[{"batb":[[0,1.31,2.44]],"ltp":1.34,"tv":3816.0,"id":16325787}]}]}
{"op":"mcm","clk":"992778870","pt":1580530380754,"mc":[{"id":"1.168133553","rc":[{"batl":[[2,8.4,1.74]],"ltp":6.0,"tv":132.29,"id":21641292}]}]}
{"op":"mcm","clk":"992815778","pt":1580531017369,"mc":[{"id":"1.168133553","rc":[{"batl":[[0,1.33,10],[1,1.34,71.03],[2,1.35,180.86]],"ltp":1.34,"tv":3816.0,"id":16325787}]}]}
{"op":"mcm","clk":"992815862","pt":1580531019067,"mc":[{"id":"1.168133553","rc":[{"batl":[[0,1.33,15]],"ltp":1.34,"tv":3816.0,"id":16325787}]}]}
{"op":"mcm","clk":"992816010","pt":1580531022519,"mc":[{"id":"1.168133553","rc":[{"trd":[[1.3,682.35],[1.31,604.2],[1.32,1324.47]],"batb":[[0,1.29,145.84],[1,1.28,200],[2,1.27,6]],"batl":[[0,1.3,6.79],[1,1.33,15],[2,1.34,71.03]],"ltp":1.3,"tv":3903.77,"id":16325787}],"tv":4069.43}]}
{"op":"mcm","clk":"992816051","pt":1580531023496,"mc":[{"id":"1.168133553","rc":[{"trd":[[1.3,695.95]],"batb":[[0,1.3,10.64],[1,1.29,145.84],[2,1.28,200]],"batl":[[0,1.33,15],[1,1.34,71.03],[2,1.35,180.86]],"ltp":1.3,"tv":3917.36,"id":16325787}],"tv":4083.02}]}
{"op":"mcm","clk":"992816162","pt":1580531026329,"mc":[{"id":"1.168133553","rc":[{"batl":[[0,1.32,10],[1,1.33,15],[2,1.34,71.03]],"ltp":1.3,"tv":3917.36,"id":16325787}]}]}
{"op":"mcm","clk":"992816205","pt":1580531027410,"mc":[{"id":"1.168133553","rc":[{"batl":[[0,1.31,5],[1,1.32,10],[2,1.33,15]],"ltp":1.3,"tv":3917.36,"id":16325787}]}]}
{"op":"mcm","clk":"992816225","pt":1580531028023,"mc":[{"id":"1.168133553","rc":[{"batl":[[0,1.31,10]],"ltp":1.3,"tv":3917.36,"id":16325787}]}]}
{"op":"mcm","clk":"992816360","pt":1580531030822,"mc":[{"id":"1.168133553","rc":[{"batb":[[0,1.3,12.32]],"ltp":1.3,"tv":3917.36,"id":16325787}]}]}
{"op":"mcm","clk":"992816416","pt":1580531032003,"mc":[{"id":"1.168133553","rc":[{"batl":[[0,1.31,15]],"ltp":1.3,"tv":3917.36,"id":16325787}]}]}
{"op":"mcm","clk":"992828573","pt":1580531350524,"mc":[{"id":"1.168133553","rc":[{"batb":[[0,10,1.98],[1,9.8,1.76],[2,9.6,3.07]],"ltp":11.0,"tv":33.36,"id":27227336},{"batb":[[0,5.8,1.98],[1,5.7,2.68],[2,5.6,2]],"ltp":6.0,"tv":132.29,"id":21641292}]}]}
{"op":"mcm","clk":"992863837","pt":1580532046142,"mc":[{"id":"1.168133553","rc":[{"trd":[[1.31,604.25]],"batl":[[0,1.31,14.98]],"ltp":1.31,"tv":3917.41,"id":16325787}],"tv":4083.06}]}
{"op":"mcm","clk":"992927404","pt":1580533360995,"mc":[{"id":"1.168133553","rc":[{"batl":[[0,7,10.22]],"ltp":6.0,"tv":132.29,"id":21641292}]}]}
{"op":"mcm","clk":"992928235","pt":1580533381343,"mc":[{"id":"1.168133553","rc":[{"batl":[[1,14,5],[2,29,9.19]],"ltp":11.0,"tv":33.36,"id":27227336}]}]}
{"op":"mcm","clk":"992931682","pt":1580533462532,"mc":[{"id":"1.168133553","rc":[{"batl":[[0,7,5.22]],"ltp":6.0,"tv":132.29,"id":21641292}]}]}
{"op":"mcm","clk":"992933994","pt":1580533504142,"mc":[{"id":"1.168133553","rc":[{"batl":[[0,7,15.22]],"ltp":6.0,"tv":132.29,"id":21641292}]}]}
{"op":"mcm","clk":"992936126","pt":1580533547471,"mc":[{"id":"1.168133553","rc":[{"batl":[[1,14,3]],"ltp":11.0,"tv":33.36,"id":27227336}]}]}
{"op":"mcm","clk":"992936613","pt":1580533560334,"mc":[{"id":"1.168133553","rc":[{"batl":[[0,7,17.22]],"ltp":6.0,"tv":132.29,"id":21641292}]}]}
{"op":"mcm","clk":"992938752","pt":1580533606268,"mc":[{"id":"1.168133553","rc":[{"batl":[[1,14,4]],"ltp":11.0,"tv":33.36,"id":27227336},{"batl":[[0,7,15.22]],"ltp":6.0,"tv":132.29,"id":21641292}]}]}
{"op":"mcm","clk":"992939616","pt":1580533625535,"mc":[{"id":"1.168133553","rc":[{"batl":[[1,14,3]],"ltp":11.0,"tv":33.36,"id":27227336}]}]}
{"op":"mcm","clk":"992958229","pt":1580533834258,"mc":[{"id":"1.168133553","rc":[{"trd":[[9.8,6.04],[10,3.96]],"batb":[[0,9.6,3.81],[1,9.4,2.36],[2,8.6,5.85]],"ltp":9.8,"tv":39.36,"id":27227336}],"tv":4089.06}]}
{"op":"mcm","clk":"992958914","pt":1580533849468,"mc":[{"id":"1.168133553","rc":[{"trd":[[5.7,4.04],[5.8,37.42]],"batb":[[0,5.6,2.66],[1,5.1,3.32],[2,4.6,1.68]],"ltp":5.7,"tv":140.29,"id":21641292}],"tv":4097.07}]}
{"op":"mcm","clk":"992975717","pt":1580534241440,"mc":[{"id":"1.168133553","rc":[{"batl":[[2,1.33,166.95]],"ltp":1.31,"tv":3917.41,"id":16325787}]}]}
{"op":"mcm","clk":"992983299","pt":1580534427203,"mc":[{"id":"1.168133553","rc":[{"trd":[[1.3,705.95]],"batb":[[0,1.3,7.32]],"ltp":1.3,"tv":3927.41,"id":16325787}],"tv":4107.07}]}
{"op":"mcm","clk":"992983396","pt":1580534429418,"mc":[{"id":"1.168133553","rc":[{"trd":[[1.3,715.95]],"batb":[[0,1.3,2.32]],"ltp":1.3,"tv":3937.41,"id":16325787}],"tv":4117.07}]}
{"op":"mcm","clk":"992983506","pt":1580534432511,"mc":[{"id":"1.168133553","rc":[{"trd":[[1.3,723.95]],"batb":[[0,1.29,145.84],[1,1.28,200],[2,1.27,7.51]],"batl":[[0,1.3,1],[1,1.31,14.98],[2,1.32,10]],"ltp":1.3,"tv":3945.41,"id":16325787}],"tv":4125.07}]}
{"op":"mcm","clk":"992983511","pt":1580534432615,"mc":[{"id":"1.168133553","rc":[{"trd":[[1.3,725.95]],"batl":[[0,1.31,14.98],[1,1.32,10],[2,1.33,166.95]],"ltp":1.3,"tv":3947.41,"id":16325787}],"tv":4127.07}]}
{"op":"mcm","clk":"992983609","pt":1580534435708,"mc":[{"id":"1.168133553","rc":[{"batb":[[0,1.3,1.68],[1,1.29,145.84],[2,1.28,200]],"batl":[[2,1.33,151.95]],"ltp":1.3,"tv":3947.41,"id":16325787}]}]}
{"op":"mcm","clk":"992983754","pt":1580534439217,"mc":[{"id":"1.168133553","rc":[{"trd":[[1.3,729.31]],"batb":[[0,1.29,145.84],[1,1.28,200],[2,1.27,7.51]],"batl":[[0,1.3,3.32],[1,1.31,14.98],[2,1.32,10]],"ltp":1.3,"tv":3950.77,"id":16325787}],"tv":4130.43}]}
{"op":"mcm","clk":"992983871","pt":1580534442311,"mc":[{"id":"1.168133553","rc":[{"batl":[[0,1.3,8.32]],"ltp":1.3,"tv":3950.77,"id":16325787}]}]}
{"op":"mcm","clk":"992983953","pt":1580534444219,"mc":[{"id":"1.168133553","rc":[{"trd":[[1.3,732.67]],"batl":[[0,1.3,6.64]],"ltp":1.3,"tv":3954.13,"id":16325787}],"tv":4133.79}]}
{"op":"mcm","clk":"992984252","pt":1580534451513,"mc":[{"id":"1.168133553","rc":[{"trd":[[1.3,736.03]],"batl":[[0,1.3,9.96]],"ltp":1.3,"tv":3957.49,"id":16325787}],"tv":4137.15}]}
{"op":"mcm","clk":"992984644","pt":1580534459621,"mc":[{"id":"1.168133553","rc":[{"trd":[[1.3,739.57]],"batl":[[0,1.3,8.19]],"ltp":1.3,"tv":3961.03,"id":16325787}],"tv":4140.69}]}
{"op":"mcm","clk":"992986443","pt":1580534505661,"mc":[{"id":"1.168133553","rc":[{"batb":[[0,5.8,2.02],[1,5.6,2.66],[2,5.1,3.32]],"ltp":5.7,"tv":140.29,"id":21641292}]}]}
{"op":"mcm","clk":"992986478","pt":1580534506689,"mc":[{"id":"1.168133553","rc":[{"batb":[[0,5.6,2.66],[1,5.1,3.32],[2,4.6,1.68]],"ltp":5.7,"tv":140.29,"id":21641292}]}]}
{"op":"mcm","clk":"993008509","pt":1580534823273,"mc":[{"id":"1.168133553","rc":[{"trd":[[1.3,755.95]],"batb":[[0,1.3,11.81],[1,1.29,145.84],[2,1.28,200]],"batl":[[0,1.31,14.98],[1,1.32,10],[2,1.33,151.95]],"ltp":1.3,"tv":3977.41,"id":16325787}],"tv":4157.07}]}
{"op":"mcm","clk":"993013610","pt":1580534962277,"mc":[{"id":"1.168133553","rc":[{"batb":[[0,9.8,2.72],[1,9.6,3.07],[2,9.4,2.36]],"ltp":9.8,"tv":39.36,"id":27227336},{"batb":[[0,5.7,2.64],[1,5.6,2],[2,5.1,3.32]],"ltp":5.7,"tv":140.29,"id":21641292},{"batb":[[0,1.3,25.04]],"ltp":1.3,"tv":3977.41,"id":16325787}]}]}
{"op":"mcm","clk":"993055416","pt":1580535673130,"mc":[{"id":"1.168133553","rc":[{"trd":[[6,47.6],[6.8,4.31]],"batl":[[0,7,15.07]],"ltp":6.8,"tv":144.59,"id":21641292},{"trd":[[1.31,607.61]],"batl":[[0,1.31,13.3]],"ltp":1.31,"tv":3980.77,"id":16325787}],"tv":4164.73}]}
{"op":"mcm","clk":"993055713","pt":1580535679122,"mc":[{"id":"1.168133553","rc":[{"batb":[[0,5.8,7.55],[1,5.7,2.64],[2,5.6,2]],"ltp":6.8,"tv":144.59,"id":21641292}]}]}
{"op":"mcm","clk":"993056191","pt":1580535689031,"mc":[{"id":"1.168133553","rc":[{"batb":[[1,5.7,5.73]],"ltp":6.8,"tv":144.59,"id":21641292}]}]}
{"op":"mcm","clk":"993056296","pt":1580535690737,"mc":[{"id":"1.168133553","rc":[{"batl":[[0,1.31,15.3]],"ltp":1.31,"tv":3980.77,"id":16325787}]}]}
{"op":"mcm","clk":"993060194","pt":1580535777667,"mc":[{"id":"1.168133553","rc":[{"batl":[[0,6.8,2],[1,7,15.07],[2,7.8,3.03]],"ltp":6.8,"tv":144.59,"id":21641292}]}]}
{"op":"mcm","clk":"993061661","pt":1580535813362,"mc":[{"id":"1.168133553","rc":[{"batb":[[0,5.9,2.92],[1,5.8,7.55],[2,5.7,5.73]],"ltp":6.8,"tv":144.59,"id":21641292},{"batl":[[0,1.31,13.3]],"ltp":1.31,"tv":3980.77,"id":16325787}]}]}
{"op":"mcm","clk":"993062068","pt":1580535822474,"mc":[{"id":"1.168133553","rc":[{"batb":[[1,5.7,5.9],[2,5.6,2]],"ltp":6.8,"tv":144.59,"id":21641292}]}]}
{"op":"mcm","clk":"993062359","pt":1580535828653,"mc":[{"id":"1.168133553","rc":[{"batb":[[1,5.7,2.81]],"ltp":6.8,"tv":144.59,"id":21641292}]}]}
{"op":"mcm","clk":"993064197","pt":1580535862417,"mc":[{"id":"1.168133553","rc":[{"trd":[[5.9,34.77]],"batb":[[0,5.7,2.81],[1,5.6,2],[2,5.2,1.92]],"ltp":5.9,"tv":150.42,"id":21641292}],"tv":4170.56}]}
{"op":"mcm","clk":"993064442","pt":1580535867473,"mc":[{"id":"1.168133553","rc":[{"batb":[[2,4.5,33.3]],"ltp":5.9,"tv":150.42,"id":21641292}]}]}
{"op":"mcm","clk":"993064488","pt":1580535868197,"mc":[{"id":"1.168133553","rc":[{"batb":[[2,5.3,3.26]],"ltp":5.9,"tv":150.42,"id":21641292}]}]}
{"op":"mcm","clk":"993202802","pt":1580538392698,"mc":[{"id":"1.168133553","rc":[{"batl":[[0,1.31,15.3]],"ltp":1.31,"tv":3980.77,"id":16325787}]}]}
{"op":"mcm","clk":"993207622","pt":1580538515433,"mc":[{"id":"1.168133553","rc":[{"trd":[[5.7,8.77],[5.8,37.76]],"batb":[[0,5.6,2.28],[1,5.3,3.26],[2,4.6,2.83]],"ltp":5.7,"tv":155.49,"id":21641292}],"tv":4175.63}]}
{"op":"mcm","clk":"993207772","pt":1580538519501,"mc":[{"id":"1.168133553","rc":[{"batl":[[0,6.8,2.16]],"ltp":5.7,"tv":155.49,"id":21641292}]}]}
{"op":"mcm","clk":"993207960","pt":1580538524650,"mc":[{"id":"1.168133553","rc":[{"batl":[[0,6.8,4.5]],"ltp":5.7,"tv":155.49,"id":21641292}]}]}
{"op":"mcm","clk":"993208080","pt":1580538527534,"mc":[{"id":"1.168133553","rc":[{"trd":[[11,14.16]],"batl":[[0,11,34.52]],"ltp":11.0,"tv":43.0,"id":27227336},{"trd":[[6.6,6.68]],"batl":[[0,6.8,4.34],[2,8.4,1.74]],"ltp":6.6,"tv":161.87,"id":21641292},{"trd":[[1.31,638.21]],"batb":[[0,1.31,13.15],[1,1.3,25.04],[2,1.29,145.84]],"batl":[[0,1.32,10],[1,1.33,151.95],[2,1.34,71.03]],"ltp":1.31,"tv":4011.37,"id":16325787}],"tv":4216.25}]}
{"op":"mcm","clk":"993208113","pt":1580538528361,"mc":[{"id":"1.168133553","rc":[{"batl":[[0,1.32,27.18]],"ltp":1.31,"tv":4011.37,"id":16325787}]}]}
{"op":"mcm","clk":"993208198","pt":1580538530529,"mc":[{"id":"1.168133553","rc":[{"batl":[[0,1.32,47.18]],"ltp":1.31,"tv":4011.37,"id":16325787}]}]}
{"op":"mcm","clk":"993208260","pt":1580538532334,"mc":[{"id":"1.168133553","rc":[{"trd":[[5.3,0.05],[5.5,0.47],[5.6,4],[5.7,9.33]],"batb":[[0,5.3,3.01],[1,4.6,2.83],[2,4.5,33]],"ltp":5.3,"tv":166.93,"id":21641292}],"tv":4221.32}]}
{"op":"mcm","clk":"993208338","pt":1580538534541,"mc":[{"id":"1.168133553","rc":[{"batl":[[0,6.8,4.57]],"ltp":5.3,"tv":166.93,"id":21641292}]}]}
{"op":"mcm","clk":"993208367","pt":1580538535362,"mc":[{"id":"1.168133553","rc":[{"batb":[[0,5.3,3.17]],"ltp":5.3,"tv":166.93,"id":21641292}]}]}
{"op":"mcm","clk":"993208468","pt":1580538537936,"mc":[{"id":"1.168133553","rc":[{"batb":[[0,5.4,2.15],[1,5.3,3.01],[2,4.6,2.83]],"ltp":5.3,"tv":166.93,"id":21641292},{"batb":[[0,1.31,26.38],[1,1.3,11.81]],"ltp":1.31,"tv":4011.37,"id":16325787}]}]}
{"op":"mcm","clk":"993208707","pt":1580538545351,"mc":[{"id":"1.168133553","rc":[{"trd":[[1.31,658.21]],"batb":[[0,1.31,16.38]],"batl":[[0,1.32,37.18]],"ltp":1.31,"tv":4031.37,"id":16325787}],"tv":4241.31}]}
{"op":"mcm","clk":"993208731","pt":1580538546080,"mc":[{"id":"1.168133553","rc":[{"batb":[[0,10,1.59],[1,9.8,2.72],[2,9.6,3.07]],"ltp":11.0,"tv":43.0,"id":27227336},{"batb":[[0,5.4,5.1]],"batl":[[0,6.8,2.23]],"ltp":5.3,"tv":166.93,"id":21641292}]}]}
{"op":"mcm","clk":"993209162","pt":1580538558487,"mc":[{"id":"1.168133553","rc":[{"batb":[[1,4.6,2.83],[2,4.5,33]],"ltp":5.3,"tv":166.93,"id":21641292}]}]}
{"op":"mcm","clk":"993209191","pt":1580538559256,"mc":[{"id":"1.168133553","rc":[{"batb":[[0,5.5,3.63],[1,5.4,5.1],[2,4.6,2.83]],"ltp":5.3,"tv":166.93,"id":21641292}]}]}
{"op":"mcm","clk":"993209435","pt":1580538565291,"mc":[{"id":"1.168133553","rc":[{"batb":[[0,5.5,3.8],[1,5.4,4.93]],"ltp":5.3,"tv":166.93,"id":21641292}]}]}
{"op":"mcm","clk":"993209531","pt":1580538567503,"mc":[{"id":"1.168133553","rc":[{"batb":[[1,5.4,1.98]],"ltp":5.3,"tv":166.93,"id":21641292}]}]}
{"op":"mcm","clk":"993209539","pt":1580538567708,"mc":[{"id":"1.168133553","rc":[{"batb":[[0,5.6,3.01],[1,5.5,3.63],[2,5.4,1.98]],"ltp":5.3,"tv":166.93,"id":21641292}]}]}
{"op":"mcm","clk":"993215217","pt":1580538690195,"mc":[{"id":"1.168133553","rc":[{"batb":[[0,5.6,5.01]],"ltp":5.3,"tv":166.93,"id":21641292}]}]}
{"op":"mcm","clk":"993217243","pt":1580538742523,"mc":[{"id":"1.168133553","rc":[{"trd":[[1.31,668.2]],"batb":[[0,1.31,11.38]],"ltp":1.31,"tv":4041.37,"id":16325787}],"tv":4251.31}]}
{"op":"mcm","clk":"993218764","pt":1580538778767,"mc":[{"id":"1.168133553","rc":[{"batb":[[0,9.8,2.72],[1,9.6,3.07],[2,9.4,2.36]],"ltp":11.0,"tv":43.0,"id":27227336},{"batb":[[0,5.6,2.17]],"ltp":5.3,"tv":166.93,"id":21641292}]}]}
{"op":"mcm","clk":"993220373","pt":1580538811538,"mc":[{"id":"1.168133553","rc":[{"batb":[[1,5.4,1.98],[2,4.7,4.29]],"ltp":5.3,"tv":166.93,"id":21641292}]}]}
{"op":"mcm","clk":"993220392","pt":1580538811951,"mc":[{"id":"1.168133553","rc":[{"batb":[[2,4.8,1.1]],"ltp":5.3,"tv":166.93,"id":21641292}]}]}
{"op":"mcm","clk":"993221017","pt":1580538828755,"mc":[{"id":"1.168133553","rc":[{"batb":[[0,5.4,2.15],[1,5.2,2]],"ltp":5.3,"tv":166.93,"id":21641292}]}]}
{"op":"mcm","clk":"993221162","pt":1580538833199,"mc":[{"id":"1.168133553","rc":[{"trd":[[1.31,690.97]],"batb":[[0,1.3,11.81],[1,1.29,145.84],[2,1.28,200]],"batl":[[0,1.31,3.63],[1,1.32,37.18],[2,1.33,151.95]],"ltp":1.31,"tv":4064.13,"id":16325787}],"tv":4274.08}]}
{"op":"mcm","clk":"993221512","pt":1580538842197,"mc":[{"id":"1.168133553","rc":[{"trd":[[1.3,763.21]],"batb":[[0,1.3,8.18]],"batl":[[0,1.32,37.18],[1,1.33,151.95],[2,1.34,71.03]],"ltp":1.3,"tv":4071.39,"id":16325787}],"tv":4281.34}]}
{"op":"mcm","clk":"993221575","pt":1580538843389,"mc":[{"id":"1.168133553","rc":[{"batb":[[0,5.3,5.18]],"ltp":5.3,"tv":166.93,"id":21641292},{"batb":[[0,1.3,14.33]],"ltp":1.3,"tv":4071.39,"id":16325787}]}]}
{"op":"mcm","clk":"993222900","pt":1580538875212,"mc":[{"id":"1.168133553","rc":[{"batb":[[0,5.3,5.9]],"ltp":5.3,"tv":166.93,"id":21641292}]}]}
{"op":"mcm","clk":"993239807","pt":1580539053352,"mc":[{"id":"1.168133553","rc":[{"batl":[[0,6.8,27.23]],"ltp":5.3,"tv":166.93,"id":21641292}]}]}
{"op":"mcm","clk":"993242561","pt":1580539130744,"mc":[{"id":"1.168133553","rc":[{"batl":[[0,1.32,17.18]],"ltp":1.3,"tv":4071.39,"id":16325787}]}]}
{"op":"mcm","clk":"993242853","pt":1580539139432,"mc":[{"id":"1.168133553","rc":[{"batl":[[0,1.32,37.18]],"ltp":1.3,"tv":4071.39,"id":16325787}]}]}
{"op":"mcm","clk":"993246641","pt":1580539233432,"mc":[{"id":"1.168133553","rc":[{"trd":[[11,34.42]],"batl":[[0,11,24.39]],"ltp":11.0,"tv":63.26,"id":27227336},{"trd":[[6.6,7.14],[6.8,36.61]],"batb":[[0,6.6,1.29],[1,5.3,5.9],[2,5.2,2]],"batl":[[0,6.8,10.85]],"ltp":6.8,"tv":199.69,"id":21641292},{"trd":[[1.3,963.21]],"batb":[[0,1.3,1.68],[2,1.28,203.09]],"ltp":1.3,"tv":4271.39,"id":16325787}],"tv":4534.35}]}
{"op":"mcm","clk":"993246668","pt":1580539234025,"mc":[{"id":"1.168133553","rc":[{"batb":[[0,6.6,1.06]],"ltp":6.8,"tv":199.69,"id":21641292},{"batb":[[0,1.29,145.84],[1,1.28,203.09],[2,1.27,7.51]],"ltp":1.3,"tv":4271.39,"id":16325787}]}]}
{"op":"mcm","clk":"993246726","pt":1580539235233,"mc":[{"id":"1.168133553","rc":[{"trd":[[6.8,58.31]],"batl":[[0,7,15.07],[1,8.4,1.74],[2,11,3]],"ltp":6.8,"tv":221.39,"id":21641292},{"batb":[[1,1.28,200]],"ltp":1.3,"tv":4271.39,"id":16325787}],"tv":4556.06}]}
{"op":"mcm","clk":"993246854","pt":1580539238231,"mc":[{"id":"1.168133553","rc":[{"batb":[[1,5.3,6.13]],"ltp":6.8,"tv":221.39,"id":21641292}]}]}
{"op":"mcm","clk":"993246911","pt":1580539239529,"mc":[{"id":"1.168133553","rc":[{"batb":[[1,5.4,8.33],[2,5.3,5.73]],"ltp":6.8,"tv":221.39,"id":21641292}]}]}
{"op":"mcm","clk":"993247094","pt":1580539243930,"mc":[{"id":"1.168133553","rc":[{"batb":[[0,10,1.59],[1,9.8,2.72],[2,9.6,3.07]],"ltp":11.0,"tv":63.26,"id":27227336},{"batb":[[1,5.5,3.3],[2,5.4,7.93]],"ltp":6.8,"tv":221.39,"id":21641292}]}]}
{"op":"mcm","clk":"993247131","pt":1580539244811,"mc":[{"id":"1.168133553","rc":[{"batb":[[1,6,8.62],[2,5.5,3.3]],"ltp":6.8,"tv":221.39,"id":21641292}]}]}
{"op":"mcm","clk":"993247510","pt":1580539253755,"mc":[{"id":"1.168133553","rc":[{"batb":[[2,5.6,3.32]],"ltp":6.8,"tv":221.39,"id":21641292}]}]}
{"op":"mcm","clk":"993248048","pt":1580539265554,"mc":[{"id":"1.168133553","rc":[{"batb":[[1,6.2,2.19],[2,6,8.62]],"ltp":6.8,"tv":221.39,"id":21641292}]}]}
{"op":"mcm","clk":"993248054","pt":1580539265657,"mc":[{"id":"1.168133553","rc":[{"batb":[[1,6.2,4.76]],"ltp":6.8,"tv":221.39,"id":21641292}]}]}
{"op":"mcm","clk":"993248469","pt":1580539275065,"mc":[{"id":"1.168133553","rc":[{"batb":[[1,6.2,6.76]],"ltp":6.8,"tv":221.39,"id":21641292}]}]}
{"op":"mcm","clk":"993248629","pt":1580539278390,"mc":[{"id":"1.168133553","rc":[{"batb":[[1,6.2,9.61]],"ltp":6.8,"tv":221.39,"id":21641292}]}]}
{"op":"mcm","clk":"993248896","pt":1580539283972,"mc":[{"id":"1.168133553","rc":[{"batb":[[1,6.4,3.1],[2,6.2,9.61]],"ltp":6.8,"tv":221.39,"id":21641292}]}]}
{"op":"mcm","clk":"993249630","pt":1580539299518,"mc":[{"id":"1.168133553","rc":[{"batb":[[2,6.2,7.61]],"ltp":6.8,"tv":221.39,"id":21641292}]}]}
{"op":"mcm","clk":"993249637","pt":1580539299621,"mc":[{"id":"1.168133553","rc":[{"batb":[[1,6.4,5.1]],"ltp":6.8,"tv":221.39,"id":21641292}]}]}
{"op":"mcm","clk":"993250371","pt":1580539318828,"mc":[{"id":"1.168133553","rc":[{"batb":[[0,6.6,3.12],[2,6.2,5.42]],"ltp":6.8,"tv":221.39,"id":21641292}]}]}
{"op":"mcm","clk":"993253768","pt":1580539392072,"mc":[{"id":"1.168133553","rc":[{"batb":[[0,1.3,2],[1,1.29,145.84],[2,1.28,200]],"ltp":1.3,"tv":4271.39,"id":16325787}]}]}
{"op":"mcm","clk":"993256937","pt":1580539464001,"mc":[{"id":"1.168133553","rc":[{"trd":[[6.6,13.38]],"batb":[[0,6.4,5.1],[1,6.2,5.42],[2,6,8.62]],"ltp":6.6,"tv":227.63,"id":21641292}],"tv":4562.29}]}
{"op":"mcm","clk":"993257566","pt":1580539478193,"mc":[{"id":"1.168133553","rc":[{"batb":[[0,9.8,2.72],[1,9.6,3.07],[2,9.4,2.36]],"ltp":11.0,"tv":63.26,"id":27227336},{"batb":[[1,6.2,2.85]],"ltp":6.6,"tv":227.63,"id":21641292}]}]}
{"op":"mcm","clk":"993270196","pt":1580539738801,"mc":[{"id":"1.168133553","rc":[{"batl":[[0,1.32,17.18]],"ltp":1.3,"tv":4271.39,"id":16325787}]}]}
{"op":"mcm","clk":"993270371","pt":1580539743029,"mc":[{"id":"1.168133553","rc":[{"batl":[[0,1.32,37.18]],"ltp":1.3,"tv":4271.39,"id":16325787}]}]}
{"op":"mcm","clk":"993292775","pt":1580540013321,"mc":[{"id":"1.168133553","rc":[{"trd":[[1.3,967.21]],"batb":[[0,1.29,145.84],[1,1.28,200],[2,1.27,7.51]],"ltp":1.3,"tv":4275.39,"id":16325787}],"tv":4566.29}]}
{"op":"mcm","clk":"993293587","pt":1580540029917,"mc":[{"id":"1.168133553","rc":[{"trd":[[1.29,68.48]],"batb":[[0,1.29,127.85]],"ltp":1.29,"tv":4311.36,"id":16325787}],"tv":4602.26}]}
{"op":"mcm","clk":"993308929","pt":1580540343193,"mc":[{"id":"1.168133553","rc":[{"batl":[[0,1.32,17.18]],"ltp":1.29,"tv":4311.36,"id":16325787}]}]}
{"op":"mcm","clk":"993309266","pt":1580540349708,"mc":[{"id":"1.168133553","rc":[{"batl":[[0,1.32,37.18]],"ltp":1.29,"tv":4311.36,"id":16325787}]}]}
{"op":"mcm","clk":"993309339","pt":1580540351297,"mc":[{"id":"1.168133553","rc":[{"batb":[[0,1.3,29.01],[1,1.29,127.85],[2,1.28,200]],"ltp":1.29,"tv":4311.36,"id":16325787}]}]}
{"op":"mcm","clk":"993313679","pt":1580540424551,"mc":[{"id":"1.168133553","rc":[{"trd":[[6.4,25.21]],"batb":[[0,6.2,2.85],[1,6,8.62],[2,5.3,2.39]],"ltp":6.4,"tv":237.84,"id":21641292}],"tv":4612.47}]}
{"op":"mcm","clk":"993314831","pt":1580540444747,"mc":[{"id":"1.168133553","rc":[{"trd":[[1.3,987.21]],"batb":[[0,1.3,19.01]],"ltp":1.3,"tv":4331.36,"id":16325787}],"tv":4632.47}]}
{"op":"mcm","clk":"993315114","pt":1580540449404,"mc":[{"id":"1.168133553","rc":[{"batb":[[2,5.4,3.86]],"batl":[[0,6.8,3.03],[1,7,15.07],[2,8.4,1.74]],"ltp":6.4,"tv":237.84,"id":21641292}]}]}
{"op":"mcm","clk":"993315418","pt":1580540454498,"mc":[{"id":"1.168133553","rc":[{"batb":[[0,10,4.71],[1,9.8,2.72],[2,9.6,3.07]],"ltp":11.0,"tv":63.26,"id":27227336},{"batb":[[0,6.4,7.1],[1,6.2,2.85],[2,6,8.62]],"ltp":6.4,"tv":237.84,"id":21641292},{"batb":[[0,1.3,53.96]],"ltp":1.3,"tv":4331.36,"id":16325787}]}]}
{"op":"mcm","clk":"993316094","pt":1580540468246,"mc":[{"id":"1.168133553","rc":[{"batb":[[2,9.6,4.91]],"ltp":11.0,"tv":63.26,"id":27227336}]}]}
{"op":"mcm","clk":"993316846","pt":1580540482433,"mc":[{"id":"1.168133553","rc":[{"batl":[[0,7,15.07],[1,8.4,1.74],[2,11,3]],"ltp":6.4,"tv":237.84,"id":21641292}]}]}
{"op":"mcm","clk":"993317233","pt":1580540491143,"mc":[{"id":"1.168133553","rc":[{"batb":[[0,6.4,9.1]],"ltp":6.4,"tv":237.84,"id":21641292}]}]}
{"op":"mcm","clk":"993319530","pt":1580540533108,"mc":[{"id":"1.168133553","rc":[{"batl":[[0,1.32,337.18]],"ltp":1.3,"tv":4331.36,"id":16325787}]}]}
{"op":"mcm","clk":"993321740","pt":1580540584393,"mc":[{"id":"1.168133553","rc":[{"batb":[[0,10.5,1.64],[1,10,4.71],[2,9.8,1.98]],"ltp":11.0,"tv":63.26,"id":27227336}]}]}
{"op":"mcm","clk":"993325954","pt":1580540689962,"mc":[{"id":"1.168133553","rc":[{"batl":[[0,1.32,837.18]],"ltp":1.3,"tv":4331.36,"id":16325787}]}]}
{"op":"mcm","clk":"993327980","pt":1580540736264,"mc":[{"id":"1.168133553","rc":[{"batl":[[0,1.32,1837.18]],"ltp":1.3,"tv":4331.36,"id":16325787}]}]}
{"op":"mcm","clk":"993329025","pt":1580540760691,"mc":[{"id":"1.168133553","rc":[{"batl":[[1,8.2,5],[2,8.4,1.74]],"ltp":6.4,"tv":237.84,"id":21641292}]}]}
{"op":"mcm","clk":"993344832","pt":1580540905319,"mc":[{"id":"1.168133553","rc":[{"batb":[[0,10.5,6.46]],"ltp":11.0,"tv":63.26,"id":27227336},{"batb":[[0,6.4,17.01]],"ltp":6.4,"tv":237.84,"id":21641292},{"batb":[[0,1.3,92.92]],"ltp":1.3,"tv":4331.36,"id":16325787}]}]}
{"op":"mcm","clk":"993345016","pt":1580540908403,"mc":[{"id":"1.168133553","rc":[{"batb":[[1,6,8.62],[2,5.3,2.39]],"ltp":6.4,"tv":237.84,"id":21641292}]}]}
{"op":"mcm","clk":"993345403","pt":1580540917454,"mc":[{"id":"1.168133553","rc":[{"batb":[[0,10.5,8.14]],"ltp":11.0,"tv":63.26,"id":27227336},{"batb":[[0,6.6,2.67],[1,6.4,17.01],[2,6,8.62]],"ltp":6.4,"tv":237.84,"id":21641292}]}]}
{"op":"mcm","clk":"993346855","pt":1580540950393,"mc":[{"id":"1.168133553","rc":[{"batl":[[0,1.32,1817.18]],"ltp":1.3,"tv":4331.36,"id":16325787}]}]}
{"op":"mcm","clk":"993347737","pt":1580540972519,"mc":[{"id":"1.168133553","rc":[{"batl":[[0,1.31,5],[1,1.32,1817.18],[2,1.33,151.95]],"ltp":1.3,"tv":4331.36,"id":16325787}]}]}
{"op":"mcm","clk":"993347847","pt":1580540975301,"mc":[{"id":"1.168133553","rc":[{"batl":[[0,1.31,10]],"ltp":1.3,"tv":4331.36,"id":16325787}]}]}
{"op":"mcm","clk":"993348429","pt":1580540988453,"mc":[{"id":"1.168133553","rc":[{"batl":[[0,6.8,2],[1,7,15.07],[2,8.2,5]],"ltp":6.4,"tv":237.84,"id":21641292}]}]}
{"op":"mcm","clk":"993355435","pt":1580541145463,"mc":[{"id":"1.168133553","rc":[{"trd":[[10.5,22.34]],"batb":[[0,10,4.71],[1,9.8,1.98],[2,9.6,3.07]],"ltp":10.5,"tv":79.54,"id":27227336}],"tv":4648.76}]}
{"op":"mcm","clk":"993355476","pt":1580541146489,"mc":[{"id":"1.168133553","rc":[{"batb":[[0,10,9.77]],"ltp":10.5,"tv":79.54,"id":27227336},{"batb":[[0,6.6,10.35]],"ltp":6.4,"tv":237.84,"id":21641292},{"batb":[[0,1.3,131.88]],"ltp":1.3,"tv":4331.36,"id":16325787}]}]}
{"op":"mcm","clk":"993362326","pt":1580541291724,"mc":[{"id":"1.168133553","rc":[{"batl":[[2,1.34,71.03]],"ltp":1.3,"tv":4331.36,"id":16325787}]}]}
{"op":"mcm","clk":"993367139","pt":1580541385516,"mc":[{"id":"1.168133553","rc":[{"trd":[[6.6,34.07]],"batb":[[0,6.4,17.01],[1,6,8.62],[2,5.3,2.39]],"ltp":6.6,"tv":258.54,"id":21641292}],"tv":4669.45}]}
{"op":"mcm","clk":"993367891","pt":1580541395547,"mc":[{"id":"1.168133553","rc":[{"batb":[[0,6.4,15.01],[1,6.2,2],[2,6,8.62]],"ltp":6.6,"tv":258.54,"id":21641292}]}]}
{"op":"mcm","clk":"993370717","pt":1580541445510,"mc":[{"id":"1.168133553","rc":[{"batb":[[1,6,8.62],[2,5.3,2.39]],"ltp":6.6,"tv":258.54,"id":21641292}]}]}
{"op":"mcm","clk":"993370730","pt":1580541445819,"mc":[{"id":"1.168133553","rc":[{"batb":[[0,10.5,1.64],[1,10,9.77],[2,9.8,1.98]],"ltp":10.5,"tv":79.54,"id":27227336},{"batb":[[0,6.4,17.01]],"ltp":6.6,"tv":258.54,"id":21641292}]}]}
{"op":"mcm","clk":"993371102","pt":1580541454726,"mc":[{"id":"1.168133553","rc":[{"batb":[[0,6.4,15.01],[1,6.2,2],[2,6,8.62]],"ltp":6.6,"tv":258.54,"id":21641292}]}]}
{"op":"mcm","clk":"993371510","pt":1580541463147,"mc":[{"id":"1.168133553","rc":[{"batb":[[0,6.4,17.01],[1,6,8.62],[2,5.3,2.39]],"ltp":6.6,"tv":258.54,"id":21641292}]}]}
{"op":"mcm","clk":"993372275","pt":1580541479866,"mc":[{"id":"1.168133553","rc":[{"batb":[[0,6.4,15.01],[1,6.2,2],[2,6,8.62]],"ltp":6.6,"tv":258.54,"id":21641292}]}]}
{"op":"mcm","clk":"993373050","pt":1580541497377,"mc":[{"id":"1.168133553","rc":[{"batb":[[0,6.4,17.01],[1,6,8.62],[2,5.3,2.39]],"ltp":6.6,"tv":258.54,"id":21641292}]}]}
{"op":"mcm","clk":"993373803","pt":1580541512809,"mc":[{"id":"1.168133553","rc":[{"batb":[[0,6.6,2.61],[1,6.4,17.01],[2,6,8.62]],"ltp":6.6,"tv":258.54,"id":21641292}]}]}
{"op":"mcm","clk":"993373883","pt":1580541514207,"mc":[{"id":"1.168133553","rc":[{"batb":[[1,6.4,15.01],[2,6.2,2]],"ltp":6.6,"tv":258.54,"id":21641292}]}]}
{"op":"mcm","clk":"993374324","pt":1580541523345,"mc":[{"id":"1.168133553","rc":[{"batb":[[0,6.6,4.61],[2,6,8.62]],"ltp":6.6,"tv":258.54,"id":21641292}]}]}
{"op":"mcm","clk":"993378260","pt":1580541603514,"mc":[{"id":"1.168133553","rc":[{"batl":[[0,1.31,15]],"ltp":1.3,"tv":4331.36,"id":16325787}]}]}
{"op":"mcm","clk":"993399368","pt":1580541826040,"mc":[{"id":"1.168133553","rc":[{"batl":[[2,20,8]],"ltp":10.5,"tv":79.54,"id":27227336}]}]}
{"op":"mcm","clk":"993405063","pt":1580541923855,"mc":[{"id":"1.168133553","rc":[{"trd":[[1.31,720.97]],"batb":[[0,1.31,85],[1,1.3,131.88],[2,1.29,127.85]],"batl":[[0,1.32,1817.18],[1,1.34,71.03],[2,1.35,180.86]],"ltp":1.31,"tv":4361.36,"id":16325787}],"tv":4699.45}]}
{"op":"mcm","clk":"993405204","pt":1580541926453,"mc":[{"id":"1.168133553","rc":[{"trd":[[1.32,1382.49]],"batb":[[1,1.3,112.87]],"batl":[[0,1.32,1788.17]],"ltp":1.32,"tv":4419.38,"id":16325787}],"tv":4757.47}]}
{"op":"mcm","clk":"993411244","pt":1580542013456,"mc":[{"id":"1.168133553","rc":[{"trd":[[6.6,43.29]],"batb":[[0,6.4,15.01],[1,6,8.62],[2,5.3,2.39]],"batl":[[0,6.6,20.39],[1,6.8,2],[2,7,15.07]],"ltp":6.6,"tv":267.76,"id":21641292}],"tv":4766.7}]}
{"op":"mcm","clk":"993411292","pt":1580542014175,"mc":[{"id":"1.168133553","rc":[{"trd":[[6.4,25.52]],"batb":[[0,6.4,14.86]],"ltp":6.4,"tv":268.06,"id":21641292}],"tv":4767.0}]}
{"op":"mcm","clk":"993411433","pt":1580542016771,"mc":[{"id":"1.168133553","rc":[{"trd":[[6.4,25.82]],"batb":[[0,6.4,14.71]],"ltp":6.4,"tv":268.37,"id":21641292}],"tv":4767.3}]}
{"op":"mcm","clk":"993411536","pt":1580542018484,"mc":[{"id":"1.168133553","rc":[{"trd":[[11,66.23]],"batl":[[0,11,8.49]],"ltp":11.0,"tv":111.35,"id":27227336},{"trd":[[6.4,66.6]],"batb":[[0,6,8.62],[1,5.3,2.39],[2,4.9,4.79]],"batl":[[0,6.8,2],[1,7,15.07],[2,8.2,5]],"ltp":6.4,"tv":309.15,"id":21641292},{"trd":[[1.32,1437.57]],"batl":[[0,1.32,1760.63]],"ltp":1.32,"tv":4474.46,"id":16325787}],"tv":4894.97}]}
{"op":"mcm","clk":"993411718","pt":1580542021165,"mc":[{"id":"1.168133553","rc":[{"batb":[[0,6.2,2],[1,6,8.62],[2,5.3,2.39]],"ltp":6.4,"tv":309.15,"id":21641292}]}]}
{"op":"mcm","clk":"993413176","pt":1580542042524,"mc":[{"id":"1.168133553","rc":[{"batl":[[2,8,3.03]],"ltp":6.4,"tv":309.15,"id":21641292}]}]}
{"op":"mcm","clk":"993423892","pt":1580542212536,"mc":[{"id":"1.168133553","rc":[{"trd":[[11,70.23]],"batl":[[0,11,6.49]],"ltp":11.0,"tv":115.35,"id":27227336}],"tv":4898.97}]}
{"op":"mcm","clk":"993425641","pt":1580542236413,"mc":[{"id":"1.168133553","rc":[{"trd":[[1.32,1495.59]],"batl":[[0,1.32,1731.62]],"ltp":1.32,"tv":4532.48,"id":16325787}],"tv":4956.99}]}
{"op":"mcm","clk":"993434106","pt":1580542345580,"mc":[{"id":"1.168133553","rc":[{"trd":[[6.2,10.99]],"batb":[[0,6,8.62],[1,5.3,2.39],[2,5,4.51]],"batl":[[0,6.8,2.52]],"ltp":6.2,"tv":313.14,"id":21641292}],"tv":4960.99}]}
{"op":"mcm","clk":"993434667","pt":1580542354284,"mc":[{"id":"1.168133553","rc":[{"batb":[[1,5.4,2.4],[2,5.3,1.98]],"ltp":6.2,"tv":313.14,"id":21641292}]}]}
{"op":"mcm","clk":"993447785","pt":1580542546597,"mc":[{"id":"1.168133553","rc":[{"trd":[[1.31,740.97]],"batb":[[0,1.31,75]],"ltp":1.31,"tv":4552.48,"id":16325787}],"tv":4980.99}]}
{"op":"mcm","clk":"993447946","pt":1580542548568,"mc":[{"id":"1.168133553","rc":[{"trd":[[1.32,1553.61]],"batl":[[0,1.32,1702.61]],"ltp":1.32,"tv":4610.5,"id":16325787}],"tv":5039.01}]}
{"op":"mcm","clk":"993450036","pt":1580542578453,"mc":[{"id":"1.168133553","rc":[{"trd":[[1.32,1558.49]],"batl":[[0,1.32,1700.17]],"ltp":1.32,"tv":4615.38,"id":16325787}],"tv":5043.89}]}
{"op":"mcm","clk":"993450076","pt":1580542578925,"mc":[{"id":"1.168133553","rc":[{"trd":[[11,70.81]],"batl":[[0,11,6.2]],"ltp":11.0,"tv":115.93,"id":27227336},{"trd":[[6.2,12.03]],"batl":[[0,6.8,2]],"ltp":6.2,"tv":314.19,"id":21641292}],"tv":5045.51}]}
{"op":"mcm","clk":"993451169","pt":1580542595572,"mc":[{"id":"1.168133553","rc":[{"batb":[[0,6,28.62]],"ltp":6.2,"tv":314.19,"id":21641292}]}]}
{"op":"mcm","clk":"993475054","pt":1580542821109,"mc":[{"id":"1.168133553","rc":[{"batb":[[1,5.4,19.9]],"ltp":6.2,"tv":314.19,"id":21641292}]}]}
{"op":"mcm","clk":"993475494","pt":1580542828525,"mc":[{"id":"1.168133553","rc":[{"batb":[[1,1.3,180.87]],"ltp":1.32,"tv":4615.38,"id":16325787}]}]}
{"op":"mcm","clk":"993476934","pt":1580542851557,"mc":[{"id":"1.168133553","rc":[{"batb":[[1,5.4,2.4]],"ltp":6.2,"tv":314.19,"id":21641292}]}]}
{"op":"mcm","clk":"993477359","pt":1580542859506,"mc":[{"id":"1.168133553","rc":[{"trd":[[1.32,1616.51]],"batl":[[0,1.32,1671.16]],"ltp":1.32,"tv":4673.4,"id":16325787}],"tv":5103.53}]}
{"op":"mcm","clk":"993478454","pt":1580542880307,"mc":[{"id":"1.168133553","rc":[{"batb":[[1,5.4,19.9]],"ltp":6.2,"tv":314.19,"id":21641292}]}]}
{"op":"mcm","clk":"993480009","pt":1580542910014,"mc":[{"id":"1.168133553","rc":[{"batb":[[1,5.4,2.4]],"ltp":6.2,"tv":314.19,"id":21641292}]}]}
{"op":"mcm","clk":"993481905","pt":1580542940564,"mc":[{"id":"1.168133553","rc":[{"batb":[[1,5.4,19.9]],"ltp":6.2,"tv":314.19,"id":21641292}]}]}
{"op":"mcm","clk":"993483717","pt":1580542969535,"mc":[{"id":"1.168133553","rc":[{"batb":[[1,5.4,2.4]],"ltp":6.2,"tv":314.19,"id":21641292}]}]}
{"op":"mcm","clk":"993485687","pt":1580542999389,"mc":[{"id":"1.168133553","rc":[{"batb":[[1,5.4,19.9]],"ltp":6.2,"tv":314.19,"id":21641292}]}]}
{"op":"mcm","clk":"993486346","pt":1580543011574,"mc":[{"id":"1.168133553","rc":[{"trd":[[1.31,744.97]],"batb":[[0,1.31,73]],"ltp":1.31,"tv":4677.4,"id":16325787}],"tv":5107.53}]}
{"op":"mcm","clk":"993486524","pt":1580543015499,"mc":[{"id":"1.168133553","rc":[{"trd":[[1.32,1620.47]],"batl":[[0,1.32,1669.18]],"ltp":1.32,"tv":4681.36,"id":16325787}],"tv":5111.49}]}
{"op":"mcm","clk":"993487340","pt":1580543029519,"mc":[{"id":"1.168133553","rc":[{"batb":[[1,5.4,2.4]],"ltp":6.2,"tv":314.19,"id":21641292}]}]}
{"op":"mcm","clk":"993487550","pt":1580543033431,"mc":[{"id":"1.168133553","rc":[{"trd":[[1.31,783.97]],"batb":[[0,1.31,53.5]],"ltp":1.31,"tv":4720.36,"id":16325787}],"tv":5150.49}]}
{"op":"mcm","clk":"993489055","pt":1580543059483,"mc":[{"id":"1.168133553","rc":[{"batb":[[1,5.4,19.9]],"batl":[[2,7.8,3.38]],"ltp":6.2,"tv":314.19,"id":21641292}]}]}
{"op":"mcm","clk":"993489373","pt":1580543065526,"mc":[{"id":"1.168133553","rc":[{"batl":[[2,7.6,3.03]],"ltp":6.2,"tv":314.19,"id":21641292}]}]}
{"op":"mcm","clk":"993490881","pt":1580543088439,"mc":[{"id":"1.168133553","rc":[{"batb":[[1,5.4,2.4]],"batl":[[2,7.6,5.22]],"ltp":6.2,"tv":314.19,"id":21641292}]}]}
{"op":"mcm","clk":"993492849","pt":1580543118271,"mc":[{"id":"1.168133553","rc":[{"batb":[[1,5.4,19.9]],"ltp":6.2,"tv":314.19,"id":21641292}]}]}
{"op":"mcm","clk":"993493677","pt":1580543130394,"mc":[{"id":"1.168133553","rc":[{"trd":[[6,61.6]],"batb":[[0,6,21.62]],"ltp":6.0,"tv":328.19,"id":21641292},{"trd":[[1.32,1648.47]],"batl":[[0,1.32,1655.18]],"ltp":1.32,"tv":4748.36,"id":16325787}],"tv":5192.49}]}
{"op":"mcm","clk":"993493874","pt":1580543133489,"mc":[{"id":"1.168133553","rc":[{"trd":[[11,78.95]],"batl":[[0,11,2.13]],"ltp":11.0,"tv":124.07,"id":27227336},{"trd":[[6.4,80.6]],"batb":[[1,5.4,2.4]],"ltp":6.4,"tv":342.19,"id":21641292},{"trd":[[1.32,1716.35]],"batl":[[0,1.32,1621.24]],"ltp":1.32,"tv":4816.24,"id":16325787}],"tv":5282.51}]}
{"op":"mcm","clk":"993493895","pt":1580543133797,"mc":[{"id":"1.168133553","rc":[{"trd":[[11,83.21]],"batb":[[0,11,1.94],[1,10.5,1.64],[2,10,9.77]],"batl":[[0,14,3],[1,20,8],[2,29,9.27]],"ltp":11.0,"tv":128.33,"id":27227336},{"batb":[[0,6.4,7],[1,6,21.62],[2,5.7,25.75]],"ltp":6.4,"tv":342.19,"id":21641292},{"trd":[[1.32,1784.24]],"batl":[[0,1.32,1587.3]],"ltp":1.32,"tv":4884.13,"id":16325787}],"tv":5354.66}]}
{"op":"mcm","clk":"993493992","pt":1580543135088,"mc":[{"id":"1.168133553","rc":[{"batb":[[1,6,25.75]],"ltp":6.4,"tv":342.19,"id":21641292}]}]}
{"op":"mcm","clk":"993494080","pt":1580543136525,"mc":[{"id":"1.168133553","rc":[{"batl":[[2,29,9.08]],"ltp":11.0,"tv":128.33,"id":27227336}]}]}
{"op":"mcm","clk":"993494133","pt":1580543137406,"mc":[{"id":"1.168133553","rc":[{"batl":[[0,13.5,1.55],[1,14,3],[2,20,8]],"ltp":11.0,"tv":128.33,"id":27227336},{"batl":[[0,6.8,4.34]],"ltp":6.4,"tv":342.19,"id":21641292}]}]}
{"op":"mcm","clk":"993494204","pt":1580543138329,"mc":[{"id":"1.168133553","rc":[{"trd":[[10.5,23.36],[11,87.09]],"batb":[[0,10.5,1.13],[1,10,9.77],[2,9.8,4.48]],"ltp":10.5,"tv":133.24,"id":27227336},{"trd":[[6.4,92.04]],"batb":[[0,6.4,1.28]],"ltp":6.4,"tv":353.63,"id":21641292},{"trd":[[1.32,1862.24]],"batl":[[0,1.32,1548.3]],"ltp":1.32,"tv":4962.13,"id":16325787}],"tv":5449.0}]}
{"op":"mcm","clk":"993494287","pt":1580543139511,"mc":[{"id":"1.168133553","rc":[{"batb":[[2,5.8,5.22]],"ltp":6.4,"tv":353.63,"id":21641292}]}]}
{"op":"mcm","clk":"993494424","pt":1580543141515,"mc":[{"id":"1.168133553","rc":[{"batb":[[2,9.8,1.98]],"ltp":10.5,"tv":133.24,"id":27227336},{"batb":[[1,6,21.62],[2,5.7,25.75]],"ltp":6.4,"tv":353.63,"id":21641292}]}]}
{"op":"mcm","clk":"993494491","pt":1580543142491,"mc":[{"id":"1.168133553","rc":[{"batb":[[2,5.8,3.55]],"ltp":6.4,"tv":353.63,"id":21641292}]}]}
{"op":"mcm","clk":"993494608","pt":1580543144492,"mc":[{"id":"1.168133553","rc":[{"batl":[[0,12,11],[1,13.5,1.55],[2,14,3]],"ltp":10.5,"tv":133.24,"id":27227336},{"batb":[[2,5.9,2]],"ltp":6.4,"tv":353.63,"id":21641292}]}]}
{"op":"mcm","clk":"993495459","pt":1580543159528,"mc":[{"id":"1.168133553","rc":[{"batl":[[0,6.8,2]],"ltp":6.4,"tv":353.63,"id":21641292}]}]}
{"op":"mcm","clk":"993495954","pt":1580543167538,"mc":[{"id":"1.168133553","rc":[{"trd":[[1.32,1976.42]],"batl":[[0,1.32,1491.21]],"ltp":1.32,"tv":5076.31,"id":16325787}],"tv":5563.18}]}
{"op":"mcm","clk":"993496945","pt":1580543182517,"mc":[{"id":"1.168133553","rc":[{"trd":[[10.5,44.86]],"batb":[[0,10,9.77],[1,9.8,1.98],[2,9.6,9.65]],"ltp":10.5,"tv":154.73,"id":27227336},{"trd":[[6.4,126.15]],"batb":[[0,6,21.62],[1,5.9,2],[2,5.8,3.55]],"batl":[[0,6.8,2.54]],"ltp":6.4,"tv":387.74,"id":21641292},{"trd":[[1.32,2152.48]],"batl":[[0,1.32,1403.18]],"ltp":1.32,"tv":5252.37,"id":16325787}],"tv":5794.85}]}
{"op":"mcm","clk":"993497002","pt":1580543183246,"mc":[{"id":"1.168133553","rc":[{"trd":[[6.4,127.23]],"batl":[[0,6.8,2]],"ltp":6.4,"tv":388.82,"id":21641292}],"tv":5795.93}]}
{"op":"mcm","clk":"993497046","pt":1580543183968,"mc":[{"id":"1.168133553","rc":[{"batl":[[1,7,18.87]],"ltp":6.4,"tv":388.82,"id":21641292}]}]}
{"op":"mcm","clk":"993499418","pt":1580543213577,"mc":[{"id":"1.168133553","rc":[{"batl":[[1,7,15.07]],"ltp":6.4,"tv":388.82,"id":21641292}]}]}
{"op":"mcm","clk":"993501490","pt":1580543242534,"mc":[{"id":"1.168133553","rc":[{"trd":[[6,83.6]],"batb":[[0,6,10.62]],"ltp":6.0,"tv":410.82,"id":21641292},{"trd":[[1.32,2196.48]],"batl":[[0,1.32,1381.18]],"ltp":1.32,"tv":5296.37,"id":16325787}],"tv":5861.93}]}
{"op":"mcm","clk":"993501666","pt":1580543245354,"mc":[{"id":"1.168133553","rc":[{"trd":[[6,99.96]],"batb":[[0,6,2.44]],"ltp":6.0,"tv":427.18,"id":21641292},{"trd":[[1.32,2230.48]],"batl":[[0,1.32,1364.18]],"ltp":1.32,"tv":5330.37,"id":16325787}],"tv":5912.29}]}
{"op":"mcm","clk":"993501732","pt":1580543246536,"mc":[{"id":"1.168133553","rc":[{"batb":[[2,5.7,29.53]],"batl":[[0,6.4,1.62],[1,6.8,2],[2,7,15.07]],"ltp":6.0,"tv":427.18,"id":21641292}]}]}
{"op":"mcm","clk":"993501779","pt":1580543247256,"mc":[{"id":"1.168133553","rc":[{"batb":[[2,5.7,25.75]],"ltp":6.0,"tv":427.18,"id":21641292}]}]}
{"op":"mcm","clk":"993502449","pt":1580543256171,"mc":[{"id":"1.168133553","rc":[{"batl":[[1,6.6,3.37],[2,6.8,2]],"ltp":6.0,"tv":427.18,"id":21641292}]}]}
{"op":"mcm","clk":"993504818","pt":1580543288484,"mc":[{"id":"1.168133553","rc":[{"batl":[[1,6.8,5.27],[2,7,15.07]],"ltp":6.0,"tv":427.18,"id":21641292}]}]}
{"op":"mcm","clk":"993506013","pt":1580543306307,"mc":[{"id":"1.168133553","rc":[{"trd":[[6,104.84]],"batb":[[0,5.9,2],[1,5.7,25.75],[2,5.3,2.39]],"batl":[[0,6.4,1.7]],"ltp":6.0,"tv":432.06,"id":21641292}],"tv":5917.17}]}
{"op":"mcm","clk":"993506653","pt":1580543316513,"mc":[{"id":"1.168133553","rc":[{"trd":[[12,14.48]],"batl":[[0,12,3.76]],"ltp":12.0,"tv":169.21,"id":27227336},{"trd":[[5.9,68.06]],"batb":[[0,5.8,2.74]],"ltp":5.9,"tv":465.35,"id":21641292},{"trd":[[1.32,2362.08]],"batl":[[0,1.32,1298.38]],"ltp":1.32,"tv":5461.97,"id":16325787}],"tv":6096.54}]}
{"op":"mcm","clk":"993506724","pt":1580543317540,"mc":[{"id":"1.168133553","rc":[{"trd":[[12,14.64]],"batl":[[0,12,3.68]],"ltp":12.0,"tv":169.37,"id":27227336},{"batb":[[0,5.8,2.91]],"ltp":5.9,"tv":465.35,"id":21641292},{"trd":[[1.32,2363.6]],"batl":[[0,1.32,1297.62]],"ltp":1.32,"tv":5463.49,"id":16325787}],"tv":6098.22}]}
{"op":"mcm","clk":"993506731","pt":1580543317642,"mc":[{"id":"1.168133553","rc":[{"batl":[[1,6.6,2.47],[2,6.8,5.27]],"ltp":5.9,"tv":465.35,"id":21641292}]}]}
{"op":"mcm","clk":"993506996","pt":1580543321440,"mc":[{"id":"1.168133553","rc":[{"batl":[[0,6.4,4.73],[2,6.8,2]],"ltp":5.9,"tv":465.35,"id":21641292}]}]}
{"op":"mcm","clk":"993507196","pt":1580543324416,"mc":[{"id":"1.168133553","rc":[{"batl":[[0,13.5,1.55],[1,14,3],[2,15.5,8.34]],"ltp":12.0,"tv":169.37,"id":27227336},{"batl":[[1,6.8,2],[2,7,15.07]],"ltp":5.9,"tv":465.35,"id":21641292},{"batb":[[0,1.32,13.05],[1,1.31,53.5],[2,1.3,180.87]],"batl":[[0,1.34,71.03],[1,1.35,224.67],[2,1.36,251.95]],"ltp":1.32,"tv":5463.49,"id":16325787}]}]}
{"op":"mcm","clk":"993507262","pt":1580543325545,"mc":[{"id":"1.168133553","rc":[{"batl":[[0,1.34,86.38]],"ltp":1.32,"tv":5463.49,"id":16325787}]}]}
{"op":"mcm","clk":"993507322","pt":1580543326525,"mc":[{"id":"1.168133553","rc":[{"batl":[[2,15.5,12.98]],"ltp":12.0,"tv":169.37,"id":27227336},{"batl":[[2,7,19.33]],"ltp":5.9,"tv":465.35,"id":21641292},{"trd":[[1.32,2365.28]],"batb":[[0,1.32,12.21]],"batl":[[1,1.35,180.86]],"ltp":1.32,"tv":5465.17,"id":16325787}],"tv":6099.9}]}
{"op":"mcm","clk":"993507415","pt":1580543327860,"mc":[{"id":"1.168133553","rc":[{"trd":[[1.32,2366.96]],"batb":[[0,1.32,11.37]],"ltp":1.32,"tv":5466.85,"id":16325787}],"tv":6101.58}]}
{"op":"mcm","clk":"993507536","pt":1580543329565,"mc":[{"id":"1.168133553","rc":[{"batb":[[0,5.8,4.91]],"ltp":5.9,"tv":465.35,"id":21641292}]}]}
{"op":"mcm","clk":"993508081","pt":1580543338561,"mc":[{"id":"1.168133553","rc":[{"batb":[[0,5.8,2.17]],"ltp":5.9,"tv":465.35,"id":21641292},{"trd":[[1.34,903.04]],"batl":[[0,1.34,2000.69]],"ltp":1.34,"tv":5638.24,"id":16325787}],"tv":6272.97}]}
{"op":"mcm","clk":"993508332","pt":1580543342565,"mc":[{"id":"1.168133553","rc":[{"trd":[[1.32,2368.22]],"batb":[[0,1.32,10.74]],"ltp":1.32,"tv":5639.5,"id":16325787}],"tv":6274.23}]}
{"op":"mcm","clk":"993508446","pt":1580543344565,"mc":[{"id":"1.168133553","rc":[{"trd":[[1.32,2369.3]],"batb":[[0,1.32,10.2]],"ltp":1.32,"tv":5640.58,"id":16325787}],"tv":6275.31}]}
{"op":"mcm","clk":"993508596","pt":1580543346574,"mc":[{"id":"1.168133553","rc":[{"trd":[[1.32,2370.38]],"batb":[[0,1.32,9.66]],"batl":[[0,1.33,3.36],[1,1.34,2000.69],[2,1.35,180.86]],"ltp":1.32,"tv":5641.65,"id":16325787}],"tv":6276.38}]}
{"op":"mcm","clk":"993508658","pt":1580543347549,"mc":[{"id":"1.168133553","rc":[{"batl":[[2,15.5,8.34]],"ltp":12.0,"tv":169.37,"id":27227336},{"batl":[[0,1.34,2000.69],[1,1.35,180.86],[2,1.36,251.95]],"ltp":1.32,"tv":5641.65,"id":16325787}]}]}
{"op":"mcm","clk":"993509178","pt":1580543353865,"mc":[{"id":"1.168133553","rc":[{"batl":[[0,6.4,1.7],[1,6.8,5.27]],"ltp":5.9,"tv":465.35,"id":21641292}]}]}
{"op":"mcm","clk":"993510646","pt":1580543378499,"mc":[{"id":"1.168133553","rc":[{"batl":[[2,7,15.07]],"ltp":5.9,"tv":465.35,"id":21641292}]}]}
{"op":"mcm","clk":"993510959","pt":1580543383284,"mc":[{"id":"1.168133553","rc":[{"trd":[[1.32,2371.18]],"batb":[[0,1.32,9.26]],"ltp":1.32,"tv":5642.46,"id":16325787}],"tv":6277.19}]}
{"op":"mcm","clk":"993511344","pt":1580543389507,"mc":[{"id":"1.168133553","rc":[{"trd":[[1.32,2371.98]],"batb":[[0,1.32,8.86]],"ltp":1.32,"tv":5643.26,"id":16325787}],"tv":6277.99}]}
{"op":"mcm","clk":"993514028","pt":1580543428330,"mc":[{"id":"1.168133553","rc":[{"batl":[[0,14,3.37],[1,15.5,8.34],[2,20,9.58]],"ltp":12.0,"tv":169.37,"id":27227336},{"batl":[[1,6.6,2.41],[2,6.8,5.27]],"ltp":5.9,"tv":465.35,"id":21641292}]}]}
{"op":"mcm","clk":"993515120","pt":1580543445367,"mc":[{"id":"1.168133553","rc":[{"trd":[[1.32,2372.58]],"batb":[[0,1.32,8.55]],"ltp":1.32,"tv":5643.86,"id":16325787}],"tv":6278.59}]}
{"op":"mcm","clk":"993515277","pt":1580543447961,"mc":[{"id":"1.168133553","rc":[{"trd":[[1.32,2373.19]],"batb":[[0,1.32,8.25]],"ltp":1.32,"tv":5644.47,"id":16325787}],"tv":6279.2}]}
{"op":"mcm","clk":"993515684","pt":1580543453562,"mc":[{"id":"1.168133553","rc":[{"batl":[[2,6.8,2]],"ltp":5.9,"tv":465.35,"id":21641292}]}]}
{"op":"mcm","clk":"993515737","pt":1580543454282,"mc":[{"id":"1.168133553","rc":[{"batl":[[0,6.4,4.73]],"ltp":5.9,"tv":465.35,"id":21641292}]}]}
{"op":"mcm","clk":"993518022","pt":1580543486522,"mc":[{"id":"1.168133553","rc":[{"batl":[[0,6.4,1.7]],"ltp":5.9,"tv":465.35,"id":21641292}]}]}
{"op":"mcm","clk":"993518034","pt":1580543486728,"mc":[{"id":"1.168133553","rc":[{"batl":[[2,6.8,5.27]],"ltp":5.9,"tv":465.35,"id":21641292}]}]}
{"op":"mcm","clk":"993520143","pt":1580543518471,"mc":[{"id":"1.168133553","rc":[{"batl":[[0,6.4,4.73],[2,6.8,2]],"ltp":5.9,"tv":465.35,"id":21641292}]}]}
{"op":"mcm","clk":"993522401","pt":1580543550498,"mc":[{"id":"1.168133553","rc":[{"batl":[[0,6.4,1.7],[2,6.8,5.27]],"ltp":5.9,"tv":465.35,"id":21641292}]}]}
{"op":"mcm","clk":"993533075","pt":1580543561503,"mc":[{"id":"1.168133553","rc":[{"trd":[[1.32,2373.63]],"batb":[[0,1.32,8.03]],"ltp":1.32,"tv":5644.9,"id":16325787}],"tv":6279.63}]}
{"op":"mcm","clk":"993533232","pt":1580543563509,"mc":[{"id":"1.168133553","rc":[{"batl":[[1,6.8,5.27],[2,7,15.07]],"ltp":5.9,"tv":465.35,"id":21641292},{"trd":[[1.32,2374.01]],"batb":[[0,1.32,7.84]],"ltp":1.32,"tv":5645.29,"id":16325787}],"tv":6280.02}]}
{"op":"mcm","clk":"993533368","pt":1580543565485,"mc":[{"id":"1.168133553","rc":[{"batb":[[0,10.5,1.64],[1,10,9.77],[2,9.8,1.98]],"ltp":12.0,"tv":169.37,"id":27227336},{"trd":[[1.32,2389.68]],"batb":[[0,1.31,53.5],[1,1.3,180.87],[2,1.29,127.85]],"batl":[[0,1.32,8.99],[1,1.34,2000.69],[2,1.35,180.86]],"ltp":1.32,"tv":5660.96,"id":16325787}],"tv":6295.69}]}
{"op":"mcm","clk":"993533428","pt":1580543566443,"mc":[{"id":"1.168133553","rc":[{"batl":[[1,1.34,2000]],"ltp":1.32,"tv":5660.96,"id":16325787}]}]}
{"op":"mcm","clk":"993533581","pt":1580543568526,"mc":[{"id":"1.168133553","rc":[{"batb":[[0,1.31,68.5]],"ltp":1.32,"tv":5660.96,"id":16325787}]}]}
{"op":"mcm","clk":"993549069","pt":1580543769540,"mc":[{"id":"1.168133553","rc":[{"trd":[[5.8,37.98],[5.9,68.4]],"batb":[[0,5.8,1.89]],"ltp":5.8,"tv":465.91,"id":21641292}],"tv":6296.25}]}
{"op":"mcm","clk":"993549471","pt":1580543774520,"mc":[{"id":"1.168133553","rc":[{"batb":[[2,5.3,8.7]],"ltp":5.8,"tv":465.91,"id":21641292}]}]}
{"op":"mcm","clk":"993550587","pt":1580543788542,"mc":[{"id":"1.168133553","rc":[{"batb":[[0,5.7,25.75],[1,5.4,2.29],[2,5.3,8.29]],"ltp":5.8,"tv":465.91,"id":21641292}]}]}
{"op":"mcm","clk":"993550737","pt":1580543790449,"mc":[{"id":"1.168133553","rc":[{"batb":[[0,5.7,25.92],[1,5.4,2.13]],"ltp":5.8,"tv":465.91,"id":21641292}]}]}
{"op":"mcm","clk":"993552992","pt":1580543818555,"mc":[{"id":"1.168133553","rc":[{"batb":[[1,5.4,15.59]],"ltp":5.8,"tv":465.91,"id":21641292}]}]}
{"op":"mcm","clk":"993555325","pt":1580543848476,"mc":[{"id":"1.168133553","rc":[{"batb":[[1,5.4,2.13]],"ltp":5.8,"tv":465.91,"id":21641292}]}]}
{"op":"mcm","clk":"993555882","pt":1580543855523,"mc":[{"id":"1.168133553","rc":[{"trd":[[5.7,16.99],[5.8,38.32]],"batb":[[0,5.7,23.75]],"ltp":5.7,"tv":473.91,"id":21641292},{"trd":[[1.31,787.97]],"batb":[[0,1.31,66.5]],"ltp":1.31,"tv":5664.96,"id":16325787}],"tv":6308.25}]}
{"op":"mcm","clk":"993556242","pt":1580543860509,"mc":[{"id":"1.168133553","rc":[{"batl":[[0,6.4,1.86]],"ltp":5.7,"tv":473.91,"id":21641292}]}]}
{"op":"mcm","clk":"993556621","pt":1580543865400,"mc":[{"id":"1.168133553","rc":[{"batb":[[0,5.7,25.75]],"ltp":5.7,"tv":473.91,"id":21641292}]}]}
{"op":"mcm","clk":"993557605","pt":1580543877536,"mc":[{"id":"1.168133553","rc":[{"batb":[[1,5.4,15.5]],"batl":[[1,6.6,2.41],[2,6.8,5.27]],"ltp":5.7,"tv":473.91,"id":21641292}]}]}
{"op":"mcm","clk":"993559731","pt":1580543901555,"mc":[{"id":"1.168133553","rc":[{"batl":[[0,6.4,4.89],[2,6.8,2]],"ltp":5.7,"tv":473.91,"id":21641292}]}]}
{"op":"mcm","clk":"993560246","pt":1580543907554,"mc":[{"id":"1.168133553","rc":[{"batb":[[1,5.4,2.13]],"ltp":5.7,"tv":473.91,"id":21641292}]}]}
{"op":"mcm","clk":"993562664","pt":1580543933510,"mc":[{"id":"1.168133553","rc":[{"batl":[[0,6.4,1.86],[2,6.8,5.27]],"ltp":5.7,"tv":473.91,"id":21641292}]}]}
{"op":"mcm","clk":"993563015","pt":1580543937281,"mc":[{"id":"1.168133553","rc":[{"batb":[[1,5.4,15.5]],"ltp":5.7,"tv":473.91,"id":21641292}]}]}
{"op":"mcm","clk":"993565820","pt":1580543966522,"mc":[{"id":"1.168133553","rc":[{"batl":[[2,6.8,2]],"ltp":5.7,"tv":473.91,"id":21641292}]}]}
{"op":"mcm","clk":"993565896","pt":1580543967349,"mc":[{"id":"1.168133553","rc":[{"batb":[[1,5.4,2.13]],"batl":[[0,6.4,4.89]],"ltp":5.7,"tv":473.91,"id":21641292}]}]}
{"op":"mcm","clk":"993568203","pt":1580543996264,"mc":[{"id":"1.168133553","rc":[{"batb":[[1,5.4,15.5]],"ltp":5.7,"tv":473.91,"id":21641292}]}]}
{"op":"mcm","clk":"993568275","pt":1580543997141,"mc":[{"id":"1.168133553","rc":[{"trd":[[5.7,36.99]],"batb":[[0,5.7,15.75]],"ltp":5.7,"tv":493.91,"id":21641292}],"tv":6328.25}]}
{"op":"mcm","clk":"993568469","pt":1580543999567,"mc":[{"id":"1.168133553","rc":[{"batl":[[0,6.4,1.86],[2,6.8,5.27]],"ltp":5.7,"tv":493.91,"id":21641292}]}]}
{"op":"mcm","clk":"993569188","pt":1580544006477,"mc":[{"id":"1.168133553","rc":[{"batb":[[0,5.8,2.97],[1,5.7,25.75],[2,5.4,15.5]],"ltp":5.7,"tv":493.91,"id":21641292}]}]}
{"op":"mcm","clk":"993570033","pt":1580544017571,"mc":[{"id":"1.168133553","rc":[{"batb":[[2,5.4,13.61]],"ltp":5.7,"tv":493.91,"id":21641292}]}]}
{"op":"mcm","clk":"993570103","pt":1580544018390,"mc":[{"id":"1.168133553","rc":[{"batb":[[0,5.8,4.86]],"ltp":5.7,"tv":493.91,"id":21641292}]}]}
{"op":"mcm","clk":"993570682","pt":1580544026397,"mc":[{"id":"1.168133553","rc":[{"batl":[[0,6.4,1.78]],"ltp":5.7,"tv":493.91,"id":21641292}]}]}
{"op":"mcm","clk":"993571067","pt":1580544031485,"mc":[{"id":"1.168133553","rc":[{"batl":[[0,6.4,4.81],[2,6.8,2]],"ltp":5.7,"tv":493.91,"id":21641292}]}]}
{"op":"mcm","clk":"993574015","pt":1580544064550,"mc":[{"id":"1.168133553","rc":[{"batl":[[0,6.4,1.78]],"ltp":5.7,"tv":493.91,"id":21641292}]}]}
{"op":"mcm","clk":"993574144","pt":1580544065542,"mc":[{"id":"1.168133553","rc":[{"batl":[[2,6.8,5.27]],"ltp":5.7,"tv":493.91,"id":21641292}]}]}
{"op":"mcm","clk":"993576721","pt":1580544096338,"mc":[{"id":"1.168133553","rc":[{"batl":[[0,6.4,4.81],[2,6.8,2]],"ltp":5.7,"tv":493.91,"id":21641292}]}]}
{"op":"mcm","clk":"993579453","pt":1580544128293,"mc":[{"id":"1.168133553","rc":[{"batl":[[0,6.4,1.78],[2,6.8,5.27]],"ltp":5.7,"tv":493.91,"id":21641292}]}]}
{"op":"mcm","clk":"993582853","pt":1580544161486,"mc":[{"id":"1.168133553","rc":[{"batl":[[2,6.8,2]],"ltp":5.7,"tv":493.91,"id":21641292}]}]}
{"op":"mcm","clk":"993582918","pt":1580544162159,"mc":[{"id":"1.168133553","rc":[{"batl":[[0,6.4,4.81]],"ltp":5.7,"tv":493.91,"id":21641292}]}]}
{"op":"mcm","clk":"993585420","pt":1580544194486,"mc":[{"id":"1.168133553","rc":[{"batl":[[0,6.4,1.78],[2,6.8,5.27]],"ltp":5.7,"tv":493.91,"id":21641292}]}]}
{"op":"mcm","clk":"993587596","pt":1580544226547,"mc":[{"id":"1.168133553","rc":[{"batl":[[0,6.4,4.81],[2,6.8,2]],"ltp":5.7,"tv":493.91,"id":21641292}]}]}
{"op":"mcm","clk":"993588221","pt":1580544236365,"mc":[{"id":"1.168133553","rc":[{"batl":[[1,6.8,2],[2,7,15.07]],"ltp":5.7,"tv":493.91,"id":21641292}]}]}
{"op":"mcm","clk":"993589674","pt":1580544258289,"mc":[{"id":"1.168133553","rc":[{"batl":[[0,6.4,1.78],[1,6.8,5.27]],"ltp":5.7,"tv":493.91,"id":21641292}]}]}
{"op":"mcm","clk":"993590297","pt":1580544267302,"mc":[{"id":"1.168133553","rc":[{"trd":[[5.8,48.03]],"batb":[[0,5.7,25.75],[1,5.3,2.22],[2,5.1,9.7]],"ltp":5.8,"tv":503.62,"id":21641292}],"tv":6337.96}]}
{"op":"mcm","clk":"993590519","pt":1580544270284,"mc":[{"id":"1.168133553","rc":[{"batb":[[0,5.8,2],[1,5.7,25.75],[2,5.3,2.22]],"ltp":5.8,"tv":503.62,"id":21641292}]}]}
{"op":"mcm","clk":"993591276","pt":1580544280914,"mc":[{"id":"1.168133553","rc":[{"batl":[[1,6.6,2.41],[2,6.8,5.27]],"ltp":5.8,"tv":503.62,"id":21641292}]}]}
{"op":"mcm","clk":"993591852","pt":1580544290011,"mc":[{"id":"1.168133553","rc":[{"batl":[[0,6.4,4.81],[2,6.8,2]],"ltp":5.8,"tv":503.62,"id":21641292}]}]}
{"op":"mcm","clk":"993594115","pt":1580544322472,"mc":[{"id":"1.168133553","rc":[{"batl":[[0,6.4,1.78],[2,6.8,5.27]],"ltp":5.8,"tv":503.62,"id":21641292}]}]}
{"op":"mcm","clk":"993596659","pt":1580544355484,"mc":[{"id":"1.168133553","rc":[{"batl":[[0,6.4,4.81],[2,6.8,2]],"ltp":5.8,"tv":503.62,"id":21641292}]}]}
{"op":"mcm","clk":"993598956","pt":1580544389528,"mc":[{"id":"1.168133553","rc":[{"batl":[[0,6.4,1.78],[2,6.8,5.27]],"ltp":5.8,"tv":503.62,"id":21641292}]}]}
{"op":"mcm","clk":"993600686","pt":1580544416557,"mc":[{"id":"1.168133553","rc":[{"trd":[[1.32,2407.66]],"batb":[[0,1.32,1.4],[1,1.31,66.5],[2,1.3,180.87]],"batl":[[0,1.34,2000],[1,1.35,180.86],[2,1.36,251.95]],"ltp":1.32,"tv":5682.94,"id":16325787}],"tv":6355.94}]}
{"op":"mcm","clk":"993601059","pt":1580544422568,"mc":[{"id":"1.168133553","rc":[{"batl":[[0,6.4,4.81],[2,6.8,2]],"ltp":5.8,"tv":503.62,"id":21641292}]}]}
{"op":"mcm","clk":"993613245","pt":1580544456565,"mc":[{"id":"1.168133553","rc":[{"batl":[[0,6.4,1.78],[2,6.8,5.27]],"ltp":5.8,"tv":503.62,"id":21641292}]}]}
{"op":"mcm","clk":"993615468","pt":1580544489491,"mc":[{"id":"1.168133553","rc":[{"batl":[[2,6.8,2]],"ltp":5.8,"tv":503.62,"id":21641292}]}]}
{"op":"mcm","clk":"993615519","pt":1580544490368,"mc":[{"id":"1.168133553","rc":[{"batl":[[0,6.4,4.81]],"ltp":5.8,"tv":503.62,"id":21641292}]}]}
{"op":"mcm","clk":"993616877","pt":1580544508511,"mc":[{"id":"1.168133553","rc":[{"batl":[[1,6.8,2],[2,7,15.07]],"ltp":5.8,"tv":503.62,"id":21641292}]}]}
{"op":"mcm","clk":"993616949","pt":1580544509286,"mc":[{"id":"1.168133553","rc":[{"trd":[[1.34,931.04]],"batl":[[0,1.34,1986]],"ltp":1.34,"tv":5710.94,"id":16325787}],"tv":6383.94}]}
{"op":"mcm","clk":"993618021","pt":1580544523495,"mc":[{"id":"1.168133553","rc":[{"batl":[[0,6.4,1.78],[1,6.8,5.27]],"ltp":5.8,"tv":503.62,"id":21641292}]}]}
{"op":"mcm","clk":"993619463","pt":1580544545219,"mc":[{"id":"1.168133553","rc":[{"batb":[[0,1.32,14.45]],"ltp":1.34,"tv":5710.94,"id":16325787}]}]}
{"op":"mcm","clk":"993626571","pt":1580544644388,"mc":[{"id":"1.168133553","rc":[{"trd":[[5.8,52.03]],"batb":[[0,5.7,25.75],[1,5.3,2.22],[2,5.1,9.7]],"batl":[[0,5.8,2],[1,6.4,1.78],[2,6.8,5.27]],"ltp":5.8,"tv":507.62,"id":21641292}],"tv":6387.94}]}
{"op":"mcm","clk":"993626659","pt":1580544645572,"mc":[{"id":"1.168133553","rc":[{"trd":[[5.7,75.13]],"batb":[[0,5.7,6.68]],"ltp":5.7,"tv":545.77,"id":21641292}],"tv":6426.09}]}
{"op":"mcm","clk":"993626719","pt":1580544646501,"mc":[{"id":"1.168133553","rc":[{"trd":[[5.6,8],[5.7,88.49]],"batb":[[0,5.3,9.56],[1,5.1,9.7],[2,5,4.45]],"batl":[[0,5.6,2.04],[1,5.7,9.05],[2,5.8,3.62]],"ltp":5.6,"tv":563.13,"id":21641292}],"tv":6443.45}]}
{"op":"mcm","clk":"993626757","pt":1580544647011,"mc":[{"id":"1.168133553","rc":[{"batb":[[2,5,34.7]],"ltp":5.6,"tv":563.13,"id":21641292}]}]}
{"op":"mcm","clk":"993626870","pt":1580544648510,"mc":[{"id":"1.168133553","rc":[{"batb":[[0,5.3,2.22],[1,5,44.8],[2,4.8,1.04]],"ltp":5.6,"tv":563.13,"id":21641292}]}]}
{"op":"mcm","clk":"993626922","pt":1580544649283,"mc":[{"id":"1.168133553","rc":[{"batb":[[1,5,34.76]],"ltp":5.6,"tv":563.13,"id":21641292}]}]}
{"op":"mcm","clk":"993627310","pt":1580544654400,"mc":[{"id":"1.168133553","rc":[{"batb":[[0,5.1,2.28],[1,5,34.7]],"ltp":5.6,"tv":563.13,"id":21641292}]}]}
{"op":"mcm","clk":"993627333","pt":1580544654708,"mc":[{"id":"1.168133553","rc":[{"batl":[[0,5.6,3.66],[2,5.8,2]],"ltp":5.6,"tv":563.13,"id":21641292}]}]}
{"op":"mcm","clk":"993627569","pt":1580544658218,"mc":[{"id":"1.168133553","rc":[{"batb":[[0,5.2,5.71],[1,5.1,2.04],[2,5,34.7]],"ltp":5.6,"tv":563.13,"id":21641292}]}]}
{"op":"mcm","clk":"993627999","pt":1580544664328,"mc":[{"id":"1.168133553","rc":[{"batb":[[1,5.1,1.98]],"ltp":5.6,"tv":563.13,"id":21641292}]}]}
{"op":"mcm","clk":"993628221","pt":1580544667527,"mc":[{"id":"1.168133553","rc":[{"batb":[[0,5.2,7.71]],"ltp":5.6,"tv":563.13,"id":21641292}]}]}
{"op":"mcm","clk":"993628464","pt":1580544670530,"mc":[{"id":"1.168133553","rc":[{"trd":[[5.5,0.94]],"batb":[[0,5.2,7.48]],"batl":[[0,5.5,9.76],[1,5.6,3.66],[2,5.7,9.05]],"ltp":5.5,"tv":563.6,"id":21641292}],"tv":6443.92}]}
{"op":"mcm","clk":"993628601","pt":1580544672529,"mc":[{"id":"1.168133553","rc":[{"trd":[[13.5,0.74]],"batl":[[0,14,3]],"ltp":13.5,"tv":170.11,"id":27227336},{"trd":[[5.5,2.76]],"batl":[[0,5.5,8.85]],"ltp":5.5,"tv":565.42,"id":21641292},{"trd":[[1.34,938.5]],"batl":[[0,1.34,1982.27]],"ltp":1.34,"tv":5718.4,"id":16325787}],"tv":6453.94}]}
{"op":"mcm","clk":"993628785","pt":1580544675354,"mc":[{"id":"1.168133553","rc":[{"batb":[[0,5.3,6.23],[1,5.2,7.48],[2,5.1,2.32]],"batl":[[0,5.5,10.47],[1,5.7,9.05],[2,5.8,2.23]],"ltp":5.5,"tv":565.42,"id":21641292}]}]}
{"op":"mcm","clk":"993629542","pt":1580544686235,"mc":[{"id":"1.168133553","rc":[{"batb":[[0,10.5,5.72]],"ltp":13.5,"tv":170.11,"id":27227336}]}]}
{"op":"mcm","clk":"993629614","pt":1580544687164,"mc":[{"id":"1.168133553","rc":[{"batl":[[1,20,9.58],[2,29,9.08]],"ltp":13.5,"tv":170.11,"id":27227336}]}]}
{"op":"mcm","clk":"993629958","pt":1580544691482,"mc":[{"id":"1.168133553","rc":[{"batb":[[0,5.4,2.34],[1,5.3,6.23],[2,5.2,5.06]],"ltp":5.5,"tv":565.42,"id":21641292}]}]}
{"op":"mcm","clk":"993630042","pt":1580544692480,"mc":[{"id":"1.168133553","rc":[{"batb":[[0,5.4,5.28],[2,5.2,2]],"ltp":5.5,"tv":565.42,"id":21641292}]}]}
{"op":"mcm","clk":"993630278","pt":1580544695278,"mc":[{"id":"1.168133553","rc":[{"trd":[[5.5,2.88]],"batl":[[0,5.5,10.41]],"ltp":5.5,"tv":565.54,"id":21641292}],"tv":6454.06}]}
{"op":"mcm","clk":"993630455","pt":1580544697553,"mc":[{"id":"1.168133553","rc":[{"batl":[[0,14,12.31]],"ltp":13.5,"tv":170.11,"id":27227336}]}]}
{"op":"mcm","clk":"993631729","pt":1580544716500,"mc":[{"id":"1.168133553","rc":[{"batb":[[0,5.4,7.28],[2,5.1,2.32]],"ltp":5.5,"tv":565.54,"id":21641292}]}]}
{"op":"mcm","clk":"993632329","pt":1580544724511,"mc":[{"id":"1.168133553","rc":[{"batb":[[0,5.4,4.95]],"ltp":5.5,"tv":565.54,"id":21641292}]}]}
{"op":"mcm","clk":"993635154","pt":1580544758524,"mc":[{"id":"1.168133553","rc":[{"batb":[[0,5.4,2]],"ltp":5.5,"tv":565.54,"id":21641292}]}]}
{"op":"mcm","clk":"993635252","pt":1580544759553,"mc":[{"id":"1.168133553","rc":[{"trd":[[5.5,23.7]],"batb":[[0,5.5,9.75],[1,5.4,2],[2,5.3,6.23]],"batl":[[0,5.7,9.05],[1,5.8,2.23],[2,6.6,38.16]],"ltp":5.5,"tv":586.36,"id":21641292}],"tv":6474.88}]}
{"op":"mcm","clk":"993635659","pt":1580544764558,"mc":[{"id":"1.168133553","rc":[{"batb":[[0,5.4,2],[1,5.3,6.23],[2,5.1,11.38]],"ltp":5.5,"tv":586.36,"id":21641292}]}]}
{"op":"mcm","clk":"993635880","pt":1580544767449,"mc":[{"id":"1.168133553","rc":[{"batb":[[0,5.5,26.89],[1,5.4,2],[2,5.3,6.23]],"ltp":5.5,"tv":586.36,"id":21641292}]}]}
{"op":"mcm","clk":"993636754","pt":1580544778546,"mc":[{"id":"1.168133553","rc":[{"trd":[[5.7,106.59]],"batb":[[0,5.7,10.95],[1,5.5,26.89],[2,5.4,2]],"batl":[[0,5.8,2.23],[1,6.4,8.1],[2,6.6,43.38]],"ltp":5.7,"tv":604.46,"id":21641292}],"tv":6492.98}]}
{"op":"mcm","clk":"993636802","pt":1580544779171,"mc":[{"id":"1.168133553","rc":[{"batl":[[0,14,12.68]],"ltp":13.5,"tv":170.11,"id":27227336}]}]}
{"op":"mcm","clk":"993636906","pt":1580544780567,"mc":[{"id":"1.168133553","rc":[{"batl":[[2,6.6,5.38]],"ltp":5.7,"tv":604.46,"id":21641292}]}]}
{"op":"mcm","clk":"993636997","pt":1580544781571,"mc":[{"id":"1.168133553","rc":[{"batl":[[1,6.8,2.16],[2,7,15.07]],"ltp":5.7,"tv":604.46,"id":21641292}]}]}
{"op":"mcm","clk":"993637242","pt":1580544784476,"mc":[{"id":"1.168133553","rc":[{"batb":[[1,5.6,2],[2,5.5,26.89]],"ltp":5.7,"tv":604.46,"id":21641292}]}]}
{"op":"mcm","clk":"993637320","pt":1580544785563,"mc":[{"id":"1.168133553","rc":[{"trd":[[5.8,56.48]],"batb":[[0,5.7,11.16]],"batl":[[0,6.8,4.51],[1,7,15.07],[2,7.4,5.35]],"ltp":5.8,"tv":608.91,"id":21641292}],"tv":6497.43}]}
{"op":"mcm","clk":"993637385","pt":1580544786453,"mc":[{"id":"1.168133553","rc":[{"batb":[[0,5.6,2.21],[1,5.5,27.13],[2,5.4,7.33]],"ltp":5.8,"tv":608.91,"id":21641292}]}]}
{"op":"mcm","clk":"993638244","pt":1580544797401,"mc":[{"id":"1.168133553","rc":[{"batl":[[0,6,2.07],[1,6.2,10.16],[2,6.8,2]],"ltp":5.8,"tv":608.91,"id":21641292}]}]}
{"op":"mcm","clk":"993638455","pt":1580544799480,"mc":[{"id":"1.168133553","rc":[{"batb":[[0,5.9,20],[1,5.6,2.21],[2,5.5,27.13]],"ltp":5.8,"tv":608.91,"id":21641292}]}]}
{"op":"mcm","clk":"993638625","pt":1580544801501,"mc":[{"id":"1.168133553","rc":[{"batb":[[1,5.6,11.66]],"ltp":5.8,"tv":608.91,"id":21641292}]}]}
{"op":"mcm","clk":"993638877","pt":1580544804475,"mc":[{"id":"1.168133553","rc":[{"batb":[[0,5.6,11.66],[1,5.5,35.46],[2,5.4,7.33]],"ltp":5.8,"tv":608.91,"id":21641292}]}]}
