{"op":"mcm","clk":"987631624","pt":1580469305563,"mc":[{"id":"1.168133553","marketDefinition":{"bspMarket":true,"turnInPlayEnabled":true,"persistenceEnabled":true,"marketBaseRate":5.0,"eventId":"29678760","eventTypeId":"7","numberOfWinners":1,"bettingType":"ODDS","marketType":"WIN","marketTime":"2020-02-01T14:12:00.000Z","suspendTime":"2020-02-01T14:12:00.000Z","bspReconciled":false,"complete":true,"inPlay":false,"crossMatching":false,"runnersVoidable":false,"numberOfActiveRunners":3,"betDelay":0,"status":"OPEN","runners":[{"adjustmentFactor":70.72,"status":"ACTIVE","sortPriority":1,"id":16325787,"name":"Kalooki"},{"adjustmentFactor":15.41,"status":"ACTIVE","sortPriority":2,"id":27227336,"name":"Islandray"},{"adjustmentFactor":13.85,"status":"ACTIVE","sortPriority":3,"id":21641292,"name":"Lemon T"}],"regulators":["MR_INT"],"venue":"Wetherby","countryCode":"GB","discountAllowed":false,"timezone":"Europe/London","openDate":"2020-02-01T13:03:00.000Z","version":3142859283,"name":"2m5f Nov Hrd","eventName":"Weth  1st Feb"},"rc":[{"batb":[[0,1.01,4237.2]],"ltp":0.0,"tv":0.0,"id":27227336},{"batb":[[0,1.01,4227.2]],"ltp":0.0,"tv":0.0,"id":21641292},{"batb":[[0,1.01,4237.2]],"ltp":0.0,"tv":0.0,"id":16325787}]}]}
{"op":"mcm","clk":"987631639","pt":1580469305769,"mc":[{"id":"1.168133553","rc":[{"batb":[[0,1.01,4237.2]],"ltp":0.0,"tv":0.0,"id":21641292}]}]}
{"op":"mcm","clk":"987631761","pt":1580469307284,"mc":[{"id":"1.168133553","marketDefinition":{"bspMarket":true,"turnInPlayEnabled":true,"persistenceEnabled":true,"marketBaseRate":5.0,"eventId":"29678760","eventTypeId":"7","numberOfWinners":1,"bettingType":"ODDS","marketType":"WIN","marketTime":"2020-02-01T14:12:00.000Z","suspendTime":"2020-02-01T14:12:00.000Z","bspReconciled":false,"complete":true,"inPlay":false,"crossMatching":false,"runnersVoidable":false,"numberOfActiveRunners":3,"betDelay":0,"status":"OPEN","runners":[{"adjustmentFactor":70.72,"status":"ACTIVE","sortPriority":1,"id":16325787,"name":"Kalooki"},{"adjustmentFactor":15.41,"status":"ACTIVE","sortPriority":2,"id":27227336,"name":"Islandray"},{"adjustmentFactor":13.85,"status":"ACTIVE","sortPriority":3,"id":21641292,"name":"Lemon T"}],"regulators":["MR_INT"],"venue":"Wetherby","countryCode":"GB","discountAllowed":true,"timezone":"Europe/London","openDate":"2020-02-01T13:03:00.000Z","version":3142859283,"name":"2m5f Nov Hrd","eventName":"Weth  1st Feb"},"rc":[{"batb":[[0,1.51,3.36],[1,1.01,4240.56]],"ltp":0.0,"tv":0.0,"id":27227336},{"batb":[[0,1.51,3.36],[1,1.01,4240.56]],"ltp":0.0,"tv":0.0,"id":21641292},{"batb":[[0,1.51,3.36],[1,1.01,4240.56]],"ltp":0.0,"tv":0.0,"id":16325787}]}]}
{"op":"mcm","clk":"987632887","pt":1580469322421,"mc":[{"id":"1.168133553","rc":[{"batb":[[1,1.03,5.18],[2,1.01,4240.56]],"ltp":0.0,"tv":0.0,"id":27227336},{"batb":[[1,1.03,5.18],[2,1.01,4240.56]],"ltp":0.0,"tv":0.0,"id":21641292},{"batb":[[1,1.03,5.18],[2,1.01,4240.56]],"ltp":0.0,"tv":0.0,"id":16325787}]}]}
{"op":"mcm","clk":"987633431","pt":1580469330036,"mc":[{"id":"1.168133553","rc":[{"batb":[[2,1.01,4242.56]],"ltp":0.0,"tv":0.0,"id":27227336},{"batb":[[2,1.01,4242.56]],"ltp":0.0,"tv":0.0,"id":21641292},{"batb":[[2,1.01,4242.56]],"ltp":0.0,"tv":0.0,"id":16325787}]}]}
{"op":"mcm","clk":"987636404","pt":1580469367366,"mc":[{"id":"1.168133553","rc":[{"batb":[[2,1.01,4101.96]],"ltp":0.0,"tv":0.0,"id":21641292}]}]}
{"op":"mcm","clk":"987636469","pt":1580469368253,"mc":[{"id":"1.168133553","rc":[{"batb":[[1,1.03,1630.23],[2,1.01,4101.96]],"ltp":0.0,"tv":0.0,"id":27227336},{"batb":[[1,1.03,1663.02]],"ltp":0.0,"tv":0.0,"id":21641292},{"batb":[[1,1.03,1627.71],[2,1.01,4101.96]],"ltp":0.0,"tv":0.0,"id":16325787}]}]}
{"op":"mcm","clk":"987641610","pt":1580469434515,"mc":[{"id":"1.168133553","rc":[{"batb":[[2,1.01,4103.64]],"ltp":0.0,"tv":0.0,"id":16325787}]}]}
{"op":"mcm","clk":"987641670","pt":1580469435091,"mc":[{"id":"1.168133553","rc":[{"batb":[[2,1.01,4103.64]],"ltp":0.0,"tv":0.0,"id":27227336},{"batb":[[2,1.01,4103.64]],"ltp":0.0,"tv":0.0,"id":21641292}]}]}
{"op":"mcm","clk":"987651979","pt":1580469568188,"mc":[{"id":"1.168133553","rc":[{"batb":[[2,1.02,1.99]],"ltp":0.0,"tv":0.0,"id":16325787}]}]}
{"op":"mcm","clk":"987652061","pt":1580469569399,"mc":[{"id":"1.168133553","rc":[{"batb":[[2,1.02,1.99]],"ltp":0.0,"tv":0.0,"id":27227336}]}]}
{"op":"mcm","clk":"987652150","pt":1580469570512,"mc":[{"id":"1.168133553","rc":[{"batb":[[2,1.02,1.99]],"ltp":0.0,"tv":0.0,"id":21641292}]}]}
{"op":"mcm","clk":"987658616","pt":1580469660339,"mc":[{"id":"1.168133553","rc":[{"batl":[[0,1.73,5]],"ltp":0.0,"tv":0.0,"id":16325787}]}]}
{"op":"mcm","clk":"987659756","pt":1580469676569,"mc":[{"id":"1.168133553","rc":[{"trd":[[1.51,6.72]],"batb":[[0,1.03,1627.71],[1,1.02,1.99],[2,1.01,4105.64]],"batl":[[0,1.73,5.64]],"ltp":1.51,"tv":6.72,"id":16325787}],"tv":6.72}]}
{"op":"mcm","clk":"987664889","pt":1580469739899,"mc":[{"id":"1.168133553","rc":[{"batl":[[0,1.6,8]],"ltp":1.51,"tv":6.72,"id":16325787}]}]}
{"op":"mcm","clk":"987665842","pt":1580469751345,"mc":[{"id":"1.168133553","rc":[{"batl":[[0,1.67,8]],"ltp":1.51,"tv":6.72,"id":16325787}]}]}
{"op":"mcm","clk":"987674362","pt":1580469758164,"mc":[{"id":"1.168133553","rc":[{"batb":[[0,1.04,1.99],[1,1.03,1627.71]],"ltp":1.51,"tv":6.72,"id":16325787}]}]}
{"op":"mcm","clk":"987674487","pt":1580469759740,"mc":[{"id":"1.168133553","rc":[{"batb":[[2,1.02,6]],"ltp":1.51,"tv":6.72,"id":16325787}]}]}
{"op":"mcm","clk":"987677854","pt":1580469802957,"mc":[{"id":"1.168133553","rc":[{"batb":[[1,1.04,3],[2,1.03,1630.23]],"ltp":0.0,"tv":0.0,"id":27227336},{"batb":[[1,1.04,3],[2,1.03,1663.02]],"ltp":0.0,"tv":0.0,"id":21641292},{"batb":[[0,1.04,4.99]],"ltp":1.51,"tv":6.72,"id":16325787}]}]}
{"op":"mcm","clk":"987679141","pt":1580469822146,"mc":[{"id":"1.168133553","rc":[{"batb":[[0,1.05,40.83],[1,1.04,4.99],[2,1.03,1627.71]],"ltp":1.51,"tv":6.72,"id":16325787}]}]}
{"op":"mcm","clk":"987683508","pt":1580469879464,"mc":[{"id":"1.168133553","rc":[{"batb":[[0,1.06,1.99],[1,1.05,40.83],[2,1.04,3]],"ltp":1.51,"tv":6.72,"id":16325787}]}]}
{"op":"mcm","clk":"987684532","pt":1580469892282,"mc":[{"id":"1.168133553","rc":[{"batb":[[1,1.04,3],[2,1.03,1627.71]],"ltp":1.51,"tv":6.72,"id":16325787}]}]}
{"op":"mcm","clk":"987689103","pt":1580469954283,"mc":[{"id":"1.168133553","rc":[{"batb":[[0,1.05,1.99]],"ltp":1.51,"tv":6.72,"id":16325787}]}]}
{"op":"mcm","clk":"987689832","pt":1580469964393,"mc":[{"id":"1.168133553","rc":[{"batb":[[0,1.06,40.45],[1,1.05,1.99],[2,1.04,3]],"ltp":1.51,"tv":6.72,"id":16325787}]}]}
{"op":"mcm","clk":"987691893","pt":1580469994791,"mc":[{"id":"1.168133553","rc":[{"batb":[[0,1.07,3],[1,1.06,40.45],[2,1.05,1.99]],"ltp":1.51,"tv":6.72,"id":16325787}]}]}
{"op":"mcm","clk":"987693023","pt":1580470012227,"mc":[{"id":"1.168133553","rc":[{"batb":[[1,1.05,1.99],[2,1.04,6]],"ltp":1.51,"tv":6.72,"id":16325787}]}]}
{"op":"mcm","clk":"987694204","pt":1580470030929,"mc":[{"id":"1.168133553","rc":[{"batb":[[0,1.08,1.99],[1,1.07,3]],"ltp":1.51,"tv":6.72,"id":16325787}]}]}
{"op":"mcm","clk":"987694592","pt":1580470036111,"mc":[{"id":"1.168133553","rc":[{"batb":[[0,1.09,39.34],[1,1.08,1.99],[2,1.07,3]],"ltp":1.51,"tv":6.72,"id":16325787}]}]}
{"op":"mcm","clk":"987696886","pt":1580470071985,"mc":[{"id":"1.168133553","rc":[{"batb":[[1,1.05,10],[2,1.04,3]],"ltp":0.0,"tv":0.0,"id":27227336},{"batb":[[1,1.05,10],[2,1.04,3]],"ltp":0.0,"tv":0.0,"id":21641292},{"batb":[[0,1.1,10],[1,1.09,39.34],[2,1.08,1.99]],"ltp":1.51,"tv":6.72,"id":16325787}]}]}
{"op":"mcm","clk":"987696953","pt":1580470073284,"mc":[{"id":"1.168133553","rc":[{"batb":[[1,1.06,3],[2,1.05,10]],"ltp":0.0,"tv":0.0,"id":27227336},{"batb":[[1,1.06,3],[2,1.05,10]],"ltp":0.0,"tv":0.0,"id":21641292},{"batb":[[0,1.11,3],[1,1.1,10],[2,1.09,39.34]],"ltp":1.51,"tv":6.72,"id":16325787}]}]}
{"op":"mcm","clk":"987697481","pt":1580470083293,"mc":[{"id":"1.168133553","rc":[{"batb":[[2,1.08,1.99]],"ltp":1.51,"tv":6.72,"id":16325787}]}]}
{"op":"mcm","clk":"987697497","pt":1580470083603,"mc":[{"id":"1.168133553","rc":[{"batb":[[0,1.12,38.28],[1,1.11,3],[2,1.1,10]],"ltp":1.51,"tv":6.72,"id":16325787}]}]}
{"op":"mcm","clk":"987699060","pt":1580470111332,"mc":[{"id":"1.168133553","rc":[{"batb":[[0,1.13,1.99],[1,1.12,38.28],[2,1.11,3]],"ltp":1.51,"tv":6.72,"id":16325787}]}]}
{"op":"mcm","clk":"987700184","pt":1580470130952,"mc":[{"id":"1.168133553","rc":[{"batb":[[1,1.07,10],[2,1.06,3]],"ltp":0.0,"tv":0.0,"id":27227336},{"batb":[[1,1.07,10],[2,1.06,3]],"ltp":0.0,"tv":0.0,"id":21641292},{"batb":[[0,1.13,11.99]],"ltp":1.51,"tv":6.72,"id":16325787}]}]}
{"op":"mcm","clk":"987700250","pt":1580470132141,"mc":[{"id":"1.168133553","rc":[{"batb":[[1,1.11,3],[2,1.04,6]],"ltp":1.51,"tv":6.72,"id":16325787}]}]}
{"op":"mcm","clk":"987703541","pt":1580470189496,"mc":[{"id":"1.168133553","rc":[{"batb":[[1,1.06,3],[2,1.04,10]],"ltp":0.0,"tv":0.0,"id":27227336},{"batb":[[1,1.06,3],[2,1.04,10]],"ltp":0.0,"tv":0.0,"id":21641292},{"batb":[[0,1.13,1.99],[1,1.12,10],[2,1.11,3]],"ltp":1.51,"tv":6.72,"id":16325787}]}]}
{"op":"mcm","clk":"987703607","pt":1580470191002,"mc":[{"id":"1.168133553","rc":[{"batb":[[1,1.05,3]],"ltp":0.0,"tv":0.0,"id":27227336},{"batb":[[1,1.05,3]],"ltp":0.0,"tv":0.0,"id":21641292},{"batb":[[2,1.04,6]],"ltp":1.51,"tv":6.72,"id":16325787}]}]}
{"op":"mcm","clk":"987704396","pt":1580470203430,"mc":[{"id":"1.168133553","rc":[{"batb":[[0,1.14,37.61],[1,1.13,1.99],[2,1.12,10]],"ltp":1.51,"tv":6.72,"id":16325787}]}]}
{"op":"mcm","clk":"987704856","pt":1580470209726,"mc":[{"id":"1.168133553","rc":[{"batb":[[0,1.15,1.99],[1,1.14,37.61]],"ltp":1.51,"tv":6.72,"id":16325787}]}]}
{"op":"mcm","clk":"987705850","pt":1580470227740,"mc":[{"id":"1.168133553","rc":[{"batb":[[1,1.12,10],[2,1.03,1627.71]],"ltp":1.51,"tv":6.72,"id":16325787}]}]}
{"op":"mcm","clk":"987707321","pt":1580470253285,"mc":[{"id":"1.168133553","rc":[{"batb":[[2,1.03,1630.23]],"ltp":0.0,"tv":0.0,"id":27227336},{"batb":[[2,1.03,1663.02]],"ltp":0.0,"tv":0.0,"id":21641292},{"batb":[[1,1.03,1627.71],[2,1.01,4105.64]],"ltp":1.51,"tv":6.72,"id":16325787}]}]}
{"op":"mcm","clk":"987709476","pt":1580470288927,"mc":[{"id":"1.168133553","rc":[{"batb":[[0,1.04,1.99]],"ltp":1.51,"tv":6.72,"id":16325787}]}]}
{"op":"mcm","clk":"987710174","pt":1580470296666,"mc":[{"id":"1.168133553","rc":[{"batb":[[2,1.02,6]],"ltp":1.51,"tv":6.72,"id":16325787}]}]}
{"op":"mcm","clk":"987710306","pt":1580470299279,"mc":[{"id":"1.168133553","rc":[{"batb":[[0,1.05,40.83],[1,1.04,1.99],[2,1.03,1627.71]],"ltp":1.51,"tv":6.72,"id":16325787}]}]}
{"op":"mcm","clk":"987712773","pt":1580470337348,"mc":[{"id":"1.168133553","rc":[{"batb":[[1,1.04,3]],"ltp":0.0,"tv":0.0,"id":27227336},{"batb":[[1,1.04,3]],"ltp":0.0,"tv":0.0,"id":21641292}]}]}
{"op":"mcm","clk":"987714621","pt":1580470364869,"mc":[{"id":"1.168133553","rc":[{"batb":[[0,1.06,1.99],[1,1.05,40.83]],"ltp":1.51,"tv":6.72,"id":16325787}]}]}
{"op":"mcm","clk":"987714894","pt":1580470368992,"mc":[{"id":"1.168133553","rc":[{"batb":[[1,1.03,1627.71],[2,1.02,6]],"ltp":1.51,"tv":6.72,"id":16325787}]}]}
{"op":"mcm","clk":"987715596","pt":1580470379171,"mc":[{"id":"1.168133553","rc":[{"batb":[[1,1.04,6],[2,1.03,1627.71]],"ltp":1.51,"tv":6.72,"id":16325787}]}]}
{"op":"mcm","clk":"987715690","pt":1580470381001,"mc":[{"id":"1.168133553","rc":[{"batb":[[1,1.05,10],[2,1.04,3]],"ltp":0.0,"tv":0.0,"id":27227336},{"batb":[[1,1.05,10],[2,1.04,3]],"ltp":0.0,"tv":0.0,"id":21641292},{"batb":[[1,1.05,10],[2,1.04,6]],"ltp":1.51,"tv":6.72,"id":16325787}]}]}
{"op":"mcm","clk":"987716497","pt":1580470393236,"mc":[{"id":"1.168133553","rc":[{"batb":[[0,1.07,40.07],[1,1.06,1.99],[2,1.05,10]],"ltp":1.51,"tv":6.72,"id":16325787}]}]}
{"op":"mcm","clk":"987717984","pt":1580470421383,"mc":[{"id":"1.168133553","rc":[{"batb":[[1,1.06,3],[2,1.05,10]],"ltp":0.0,"tv":0.0,"id":27227336},{"batb":[[1,1.06,3],[2,1.05,10]],"ltp":0.0,"tv":0.0,"id":21641292},{"batb":[[0,1.08,3],[1,1.07,40.07],[2,1.06,1.99]],"ltp":1.51,"tv":6.72,"id":16325787}]}]}
{"op":"mcm","clk":"987719210","pt":1580470442118,"mc":[{"id":"1.168133553","rc":[{"batb":[[1,1.06,1.99],[2,1.05,10]],"ltp":1.51,"tv":6.72,"id":16325787}]}]}
{"op":"mcm","clk":"987719377","pt":1580470444755,"mc":[{"id":"1.168133553","rc":[{"batb":[[2,1.03,1630.23]],"ltp":0.0,"tv":0.0,"id":27227336},{"batb":[[2,1.03,1663.02]],"ltp":0.0,"tv":0.0,"id":21641292},{"batb":[[2,1.04,6]],"ltp":1.51,"tv":6.72,"id":16325787}]}]}
{"op":"mcm","clk":"987719518","pt":1580470447124,"mc":[{"id":"1.168133553","rc":[{"batb":[[0,1.09,1.99],[1,1.08,3]],"ltp":1.51,"tv":6.72,"id":16325787}]}]}
{"op":"mcm","clk":"987719596","pt":1580470448530,"mc":[{"id":"1.168133553","rc":[{"batb":[[0,1.09,4.99]],"ltp":1.51,"tv":6.72,"id":16325787}]}]}
{"op":"mcm","clk":"987720108","pt":1580470458341,"mc":[{"id":"1.168133553","rc":[{"batb":[[0,1.1,3],[1,1.09,1.99],[2,1.08,3]],"ltp":1.51,"tv":6.72,"id":16325787}]}]}
{"op":"mcm","clk":"987720567","pt":1580470467476,"mc":[{"id":"1.168133553","rc":[{"batb":[[0,1.12,3],[1,1.11,38.63],[2,1.09,1.99]],"ltp":1.51,"tv":6.72,"id":16325787}]}]}
{"op":"mcm","clk":"987721813","pt":1580470488518,"mc":[{"id":"1.168133553","rc":[{"batb":[[1,1.03,1630.23],[2,1.02,1.99]],"ltp":0.0,"tv":0.0,"id":27227336},{"batb":[[1,1.03,1663.02],[2,1.02,1.99]],"ltp":0.0,"tv":0.0,"id":21641292}]}]}
{"op":"mcm","clk":"987721821","pt":1580470488622,"mc":[{"id":"1.168133553","rc":[{"batb":[[1,1.04,3],[2,1.03,1630.23]],"ltp":0.0,"tv":0.0,"id":27227336},{"batb":[[1,1.04,3],[2,1.03,1663.02]],"ltp":0.0,"tv":0.0,"id":21641292}]}]}
{"op":"mcm","clk":"987722009","pt":1580470491729,"mc":[{"id":"1.168133553","rc":[{"batb":[[1,1.09,1.99],[2,1.04,6]],"ltp":1.51,"tv":6.72,"id":16325787}]}]}
{"op":"mcm","clk":"987722453","pt":1580470499106,"mc":[{"id":"1.168133553","rc":[{"batb":[[0,1.09,1.99],[1,1.05,3]],"ltp":1.51,"tv":6.72,"id":16325787}]}]}
{"op":"mcm","clk":"987723217","pt":1580470511523,"mc":[{"id":"1.168133553","rc":[{"batb":[[1,1.06,3]],"ltp":1.51,"tv":6.72,"id":16325787}]}]}
{"op":"mcm","clk":"987724496","pt":1580470533884,"mc":[{"id":"1.168133553","rc":[{"batb":[[1,1.07,3]],"ltp":1.51,"tv":6.72,"id":16325787}]}]}
{"op":"mcm","clk":"987724802","pt":1580470539077,"mc":[{"id":"1.168133553","rc":[{"batb":[[0,1.08,1.99]],"ltp":1.51,"tv":6.72,"id":16325787}]}]}
{"op":"mcm","clk":"987724864","pt":1580470540256,"mc":[{"id":"1.168133553","rc":[{"batb":[[0,1.09,39.34],[1,1.08,1.99],[2,1.07,3]],"ltp":1.51,"tv":6.72,"id":16325787}]}]}
{"op":"mcm","clk":"987725294","pt":1580470548485,"mc":[{"id":"1.168133553","rc":[{"batb":[[0,1.1,3],[1,1.09,39.34],[2,1.08,1.99]],"ltp":1.51,"tv":6.72,"id":16325787}]}]}
{"op":"mcm","clk":"987726264","pt":1580470565122,"mc":[{"id":"1.168133553","rc":[{"batb":[[1,1.08,1.99],[2,1.04,6]],"ltp":1.51,"tv":6.72,"id":16325787}]}]}
{"op":"mcm","clk":"987726784","pt":1580470576113,"mc":[{"id":"1.168133553","rc":[{"batb":[[0,1.08,1.99],[1,1.05,3]],"ltp":1.51,"tv":6.72,"id":16325787}]}]}
{"op":"mcm","clk":"987726969","pt":1580470579042,"mc":[{"id":"1.168133553","rc":[{"batb":[[1,1.05,10],[2,1.04,3]],"ltp":0.0,"tv":0.0,"id":27227336},{"batb":[[1,1.05,10],[2,1.04,3]],"ltp":0.0,"tv":0.0,"id":21641292},{"batb":[[1,1.06,10],[2,1.05,3]],"ltp":1.51,"tv":6.72,"id":16325787}]}]}
{"op":"mcm","clk":"987727387","pt":1580470586748,"mc":[{"id":"1.168133553","rc":[{"batb":[[1,1.07,3],[2,1.06,10]],"ltp":1.51,"tv":6.72,"id":16325787}]}]}
{"op":"mcm","clk":"987727521","pt":1580470589244,"mc":[{"id":"1.168133553","rc":[{"batb":[[0,1.09,39.34],[1,1.08,1.99],[2,1.07,3]],"ltp":1.51,"tv":6.72,"id":16325787}]}]}
{"op":"mcm","clk":"987728029","pt":1580470599029,"mc":[{"id":"1.168133553","rc":[{"batb":[[0,1.1,3],[1,1.09,39.34],[2,1.08,1.99]],"ltp":1.51,"tv":6.72,"id":16325787}]}]}
{"op":"mcm","clk":"987728836","pt":1580470613293,"mc":[{"id":"1.168133553","rc":[{"batb":[[1,1.08,1.99],[2,1.06,10]],"ltp":1.51,"tv":6.72,"id":16325787}]}]}
{"op":"mcm","clk":"987729351","pt":1580470622493,"mc":[{"id":"1.168133553","rc":[{"batb":[[1,1.06,3],[2,1.05,10]],"ltp":0.0,"tv":0.0,"id":27227336},{"batb":[[1,1.06,3],[2,1.05,10]],"ltp":0.0,"tv":0.0,"id":21641292},{"batb":[[2,1.07,3]],"ltp":1.51,"tv":6.72,"id":16325787}]}]}
{"op":"mcm","clk":"987729388","pt":1580470623064,"mc":[{"id":"1.168133553","rc":[{"batb":[[0,1.11,1.99],[1,1.1,3]],"ltp":1.51,"tv":6.72,"id":16325787}]}]}
{"op":"mcm","clk":"987729430","pt":1580470623793,"mc":[{"id":"1.168133553","rc":[{"batb":[[0,1.11,4.99],[1,1.07,3],[2,1.06,10]],"ltp":1.51,"tv":6.72,"id":16325787}]}]}
{"op":"mcm","clk":"987730675","pt":1580470642760,"mc":[{"id":"1.168133553","rc":[{"batb":[[0,1.12,3],[1,1.11,1.99],[2,1.07,3]],"ltp":1.51,"tv":6.72,"id":16325787}]}]}
{"op":"mcm","clk":"987730975","pt":1580470648645,"mc":[{"id":"1.168133553","rc":[{"batb":[[2,1.03,1630.23]],"ltp":0.0,"tv":0.0,"id":27227336},{"batb":[[2,1.03,1663.02]],"ltp":0.0,"tv":0.0,"id":21641292}]}]}
{"op":"mcm","clk":"987739616","pt":1580470657248,"mc":[{"id":"1.168133553","rc":[{"batb":[[0,1.11,1.99],[1,1.08,3]],"ltp":1.51,"tv":6.72,"id":16325787}]}]}
{"op":"mcm","clk":"987740612","pt":1580470673869,"mc":[{"id":"1.168133553","rc":[{"batb":[[1,1.09,3]],"ltp":1.51,"tv":6.72,"id":16325787}]}]}
{"op":"mcm","clk":"987741125","pt":1580470683510,"mc":[{"id":"1.168133553","rc":[{"batb":[[1,1.04,3]],"ltp":0.0,"tv":0.0,"id":27227336},{"batb":[[1,1.04,3]],"ltp":0.0,"tv":0.0,"id":21641292},{"batb":[[2,1.05,3]],"ltp":1.51,"tv":6.72,"id":16325787}]}]}
{"op":"mcm","clk":"987741256","pt":1580470685383,"mc":[{"id":"1.168133553","rc":[{"batb":[[0,1.12,38.28],[1,1.11,1.99],[2,1.1,3]],"ltp":1.51,"tv":6.72,"id":16325787}]}]}
{"op":"mcm","clk":"987742163","pt":1580470700405,"mc":[{"id":"1.168133553","rc":[{"batb":[[0,1.13,3],[1,1.12,38.28],[2,1.11,1.99]],"ltp":1.51,"tv":6.72,"id":16325787}]}]}
{"op":"mcm","clk":"987742335","pt":1580470703317,"mc":[{"id":"1.168133553","rc":[{"batb":[[0,1.14,1.99],[1,1.13,3],[2,1.12,38.28]],"ltp":1.51,"tv":6.72,"id":16325787}]}]}
{"op":"mcm","clk":"987742864","pt":1580470712015,"mc":[{"id":"1.168133553","rc":[{"batb":[[0,1.15,37.28],[1,1.14,1.99],[2,1.13,3]],"ltp":1.51,"tv":6.72,"id":16325787}]}]}
{"op":"mcm","clk":"987743160","pt":1580470716543,"mc":[{"id":"1.168133553","rc":[{"batb":[[2,1.05,3]],"ltp":1.51,"tv":6.72,"id":16325787}]}]}
{"op":"mcm","clk":"987743171","pt":1580470716655,"mc":[{"id":"1.168133553","rc":[{"batb":[[0,1.16,3],[1,1.15,37.28],[2,1.14,1.99]],"ltp":1.51,"tv":6.72,"id":16325787}]}]}
{"op":"mcm","clk":"987744335","pt":1580470736493,"mc":[{"id":"1.168133553","rc":[{"batb":[[1,1.14,1.99],[2,1.05,3]],"ltp":1.51,"tv":6.72,"id":16325787}]}]}
{"op":"mcm","clk":"987744628","pt":1580470741268,"mc":[{"id":"1.168133553","rc":[{"batb":[[0,1.14,1.99],[1,1.06,3]],"ltp":1.51,"tv":6.72,"id":16325787}]}]}
{"op":"mcm","clk":"987745195","pt":1580470750817,"mc":[{"id":"1.168133553","rc":[{"batb":[[2,1.04,3]],"ltp":1.51,"tv":6.72,"id":16325787}]}]}
{"op":"mcm","clk":"987745376","pt":1580470753495,"mc":[{"id":"1.168133553","rc":[{"batb":[[1,1.04,3],[2,1.03,1627.71]],"ltp":1.51,"tv":6.72,"id":16325787}]}]}
{"op":"mcm","clk":"987745385","pt":1580470753598,"mc":[{"id":"1.168133553","rc":[{"batb":[[1,1.07,3],[2,1.04,3]],"ltp":1.51,"tv":6.72,"id":16325787}]}]}
{"op":"mcm","clk":"987745955","pt":1580470763893,"mc":[{"id":"1.168133553","rc":[{"batb":[[1,1.08,3]],"ltp":1.51,"tv":6.72,"id":16325787}]}]}
{"op":"mcm","clk":"987746446","pt":1580470772740,"mc":[{"id":"1.168133553","rc":[{"batb":[[1,1.09,3]],"ltp":1.51,"tv":6.72,"id":16325787}]}]}
{"op":"mcm","clk":"987747040","pt":1580470783136,"mc":[{"id":"1.168133553","rc":[{"batb":[[1,1.1,3]],"ltp":1.51,"tv":6.72,"id":16325787}]}]}
{"op":"mcm","clk":"987747198","pt":1580470785963,"mc":[{"id":"1.168133553","rc":[{"batb":[[0,1.11,1.99]],"ltp":1.51,"tv":6.72,"id":16325787}]}]}
{"op":"mcm","clk":"987747709","pt":1580470796039,"mc":[{"id":"1.168133553","rc":[{"batb":[[0,1.11,4.99],[1,1.04,3],[2,1.03,1627.71]],"ltp":1.51,"tv":6.72,"id":16325787}]}]}
{"op":"mcm","clk":"987748469","pt":1580470808481,"mc":[{"id":"1.168133553","rc":[{"batb":[[0,1.11,1.99]],"ltp":1.51,"tv":6.72,"id":16325787}]}]}
{"op":"mcm","clk":"987748516","pt":1580470809169,"mc":[{"id":"1.168133553","rc":[{"batb":[[0,1.13,37.94],[1,1.12,3],[2,1.11,1.99]],"ltp":1.51,"tv":6.72,"id":16325787}]}]}
{"op":"mcm","clk":"987749340","pt":1580470823008,"mc":[{"id":"1.168133553","rc":[{"batb":[[0,1.14,3],[1,1.13,37.94]],"ltp":1.51,"tv":6.72,"id":16325787}]}]}
{"op":"mcm","clk":"987750032","pt":1580470834427,"mc":[{"id":"1.168133553","rc":[{"batb":[[1,1.11,1.99],[2,1.04,3]],"ltp":1.51,"tv":6.72,"id":16325787}]}]}
{"op":"mcm","clk":"987750351","pt":1580470839056,"mc":[{"id":"1.168133553","rc":[{"batb":[[0,1.11,1.99],[1,1.05,3]],"ltp":1.51,"tv":6.72,"id":16325787}]}]}
{"op":"mcm","clk":"987751519","pt":1580470855959,"mc":[{"id":"1.168133553","rc":[{"batb":[[1,1.06,3]],"ltp":1.51,"tv":6.72,"id":16325787}]}]}
{"op":"mcm","clk":"987752308","pt":1580470870000,"mc":[{"id":"1.168133553","rc":[{"batb":[[1,1.07,3]],"ltp":1.51,"tv":6.72,"id":16325787}]}]}
{"op":"mcm","clk":"987753017","pt":1580470881504,"mc":[{"id":"1.168133553","rc":[{"batb":[[1,1.08,3]],"ltp":1.51,"tv":6.72,"id":16325787}]}]}
{"op":"mcm","clk":"987753741","pt":1580470893333,"mc":[{"id":"1.168133553","rc":[{"batb":[[1,1.09,3]],"ltp":1.51,"tv":6.72,"id":16325787}]}]}
{"op":"mcm","clk":"987754207","pt":1580470902276,"mc":[{"id":"1.168133553","rc":[{"batb":[[1,1.1,3]],"ltp":1.51,"tv":6.72,"id":16325787}]}]}
{"op":"mcm","clk":"987754415","pt":1580470905278,"mc":[{"id":"1.168133553","rc":[{"batb":[[0,1.12,38.28],[1,1.11,1.99],[2,1.1,3]],"ltp":1.51,"tv":6.72,"id":16325787}]}]}
{"op":"mcm","clk":"987754823","pt":1580470911547,"mc":[{"id":"1.168133553","rc":[{"batb":[[2,1.04,3]],"ltp":1.51,"tv":6.72,"id":16325787}]}]}
{"op":"mcm","clk":"987754831","pt":1580470911654,"mc":[{"id":"1.168133553","rc":[{"batb":[[0,1.13,3],[1,1.12,38.28],[2,1.11,1.99]],"ltp":1.51,"tv":6.72,"id":16325787}]}]}
{"op":"mcm","clk":"987755895","pt":1580470929015,"mc":[{"id":"1.168133553","rc":[{"batb":[[1,1.11,1.99],[2,1.04,3]],"ltp":1.51,"tv":6.72,"id":16325787}]}]}
{"op":"mcm","clk":"987756161","pt":1580470933000,"mc":[{"id":"1.168133553","rc":[{"batb":[[0,1.11,1.99],[1,1.05,3]],"ltp":1.51,"tv":6.72,"id":16325787}]}]}
{"op":"mcm","clk":"987756445","pt":1580470937315,"mc":[{"id":"1.168133553","rc":[{"batb":[[1,1.05,10],[2,1.04,3]],"ltp":0.0,"tv":0.0,"id":27227336},{"batb":[[1,1.05,10],[2,1.04,3]],"ltp":0.0,"tv":0.0,"id":21641292},{"batb":[[1,1.06,10],[2,1.05,3]],"ltp":1.51,"tv":6.72,"id":16325787}]}]}
{"op":"mcm","clk":"987756977","pt":1580470945124,"mc":[{"id":"1.168133553","rc":[{"batb":[[1,1.07,3],[2,1.06,10]],"ltp":1.51,"tv":6.72,"id":16325787}]}]}
{"op":"mcm","clk":"987757228","pt":1580470949026,"mc":[{"id":"1.168133553","rc":[{"batb":[[0,1.08,1.99]],"ltp":1.51,"tv":6.72,"id":16325787}]}]}
{"op":"mcm","clk":"987757529","pt":1580470953547,"mc":[{"id":"1.168133553","rc":[{"batb":[[0,1.09,39.34],[1,1.08,1.99],[2,1.07,3]],"ltp":1.51,"tv":6.72,"id":16325787}]}]}
{"op":"mcm","clk":"987757757","pt":1580470956863,"mc":[{"id":"1.168133553","rc":[{"batb":[[0,1.1,3],[1,1.09,39.34],[2,1.08,1.99]],"ltp":1.51,"tv":6.72,"id":16325787}]}]}
{"op":"mcm","clk":"987758519","pt":1580470968329,"mc":[{"id":"1.168133553","rc":[{"batb":[[1,1.06,3],[2,1.05,10]],"ltp":0.0,"tv":0.0,"id":27227336},{"batb":[[1,1.06,3],[2,1.05,10]],"ltp":0.0,"tv":0.0,"id":21641292}]}]}
{"op":"mcm","clk":"987759115","pt":1580470976690,"mc":[{"id":"1.168133553","rc":[{"batl":[[0,1000,0.2]],"ltp":0.0,"tv":0.0,"id":27227336},{"batl":[[0,1000,0.2]],"ltp":0.0,"tv":0.0,"id":21641292},{"batl":[[0,1000,0.2]],"ltp":1.51,"tv":6.72,"id":16325787}]}]}
{"op":"mcm","clk":"987759191","pt":1580470977776,"mc":[{"id":"1.168133553","rc":[{"batb":[[1,1.08,1.99],[2,1.07,3]],"ltp":1.51,"tv":6.72,"id":16325787}]}]}
{"op":"mcm","clk":"987759661","pt":1580470984203,"mc":[{"id":"1.168133553","rc":[{"batb":[[0,1.08,4.99],[1,1.07,3],[2,1.06,10]],"ltp":1.51,"tv":6.72,"id":16325787}]}]}
{"op":"mcm","clk":"987760512","pt":1580470996530,"mc":[{"id":"1.168133553","rc":[{"batb":[[0,1.09,3],[1,1.08,1.99],[2,1.07,3]],"ltp":1.51,"tv":6.72,"id":16325787}]}]}
{"op":"mcm","clk":"987760891","pt":1580471002447,"mc":[{"id":"1.168133553","rc":[{"batb":[[0,1.1,38.97],[1,1.09,3],[2,1.08,1.99]],"ltp":1.51,"tv":6.72,"id":16325787}]}]}
{"op":"mcm","clk":"987761130","pt":1580471005743,"mc":[{"id":"1.168133553","rc":[{"batb":[[0,1.11,3],[1,1.1,38.97]],"ltp":1.51,"tv":6.72,"id":16325787}]}]}
{"op":"mcm","clk":"987761514","pt":1580471012120,"mc":[{"id":"1.168133553","rc":[{"batb":[[1,1.07,10],[2,1.06,3]],"ltp":0.0,"tv":0.0,"id":27227336},{"batb":[[1,1.07,10],[2,1.06,3]],"ltp":0.0,"tv":0.0,"id":21641292},{"batb":[[0,1.11,13]],"ltp":1.51,"tv":6.72,"id":16325787}]}]}
{"op":"mcm","clk":"987761634","pt":1580471015139,"mc":[{"id":"1.168133553","rc":[{"batb":[[0,1.12,3],[1,1.11,10],[2,1.1,38.97]],"ltp":1.51,"tv":6.72,"id":16325787}]}]}
{"op":"mcm","clk":"987761767","pt":1580471018327,"mc":[{"id":"1.168133553","rc":[{"batb":[[1,1.08,3],[2,1.07,10]],"ltp":0.0,"tv":0.0,"id":27227336},{"batb":[[1,1.08,3],[2,1.07,10]],"ltp":0.0,"tv":0.0,"id":21641292},{"batb":[[0,1.12,6]],"ltp":1.51,"tv":6.72,"id":16325787}]}]}
{"op":"mcm","clk":"987762085","pt":1580471024574,"mc":[{"id":"1.168133553","rc":[{"batb":[[0,1.13,3],[1,1.12,3],[2,1.11,10]],"ltp":1.51,"tv":6.72,"id":16325787}]}]}
{"op":"mcm","clk":"987762219","pt":1580471026759,"mc":[{"id":"1.168133553","rc":[{"batb":[[0,1.14,37.61],[1,1.13,3],[2,1.12,3]],"ltp":1.51,"tv":6.72,"id":16325787}]}]}
{"op":"mcm","clk":"987762735","pt":1580471036769,"mc":[{"id":"1.168133553","rc":[{"batb":[[0,1.15,3],[1,1.14,37.61]],"ltp":1.51,"tv":6.72,"id":16325787}]}]}
{"op":"mcm","clk":"987763431","pt":1580471050180,"mc":[{"id":"1.168133553","rc":[{"batb":[[0,1.16,1.99],[1,1.15,3],[2,1.14,37.61]],"ltp":1.51,"tv":6.72,"id":16325787}]}]}
{"op":"mcm","clk":"987763541","pt":1580471052220,"mc":[{"id":"1.168133553","rc":[{"batb":[[2,1.12,3]],"ltp":1.51,"tv":6.72,"id":16325787}]}]}
{"op":"mcm","clk":"987763584","pt":1580471053007,"mc":[{"id":"1.168133553","rc":[{"batb":[[0,1.18,3],[1,1.17,36.65],[2,1.16,1.99]],"ltp":1.51,"tv":6.72,"id":16325787}]}]}
{"op":"mcm","clk":"987764895","pt":1580471077437,"mc":[{"id":"1.168133553","rc":[{"batb":[[1,1.16,1.99],[2,1.11,10]],"ltp":1.51,"tv":6.72,"id":16325787}]}]}
{"op":"mcm","clk":"987765150","pt":1580471082547,"mc":[{"id":"1.168133553","rc":[{"batb":[[0,1.16,1.99],[1,1.11,10],[2,1.03,1627.71]],"ltp":1.51,"tv":6.72,"id":16325787}]}]}
{"op":"mcm","clk":"987765152","pt":1580471082651,"mc":[{"id":"1.168133553","rc":[{"batb":[[1,1.12,3],[2,1.11,10]],"ltp":1.51,"tv":6.72,"id":16325787}]}]}
{"op":"mcm","clk":"987765409","pt":1580471087287,"mc":[{"id":"1.168133553","rc":[{"batb":[[2,1.03,1630.23]],"ltp":0.0,"tv":0.0,"id":27227336},{"batb":[[2,1.03,1663.02]],"ltp":0.0,"tv":0.0,"id":21641292},{"batb":[[2,1.03,1627.71]],"ltp":1.51,"tv":6.72,"id":16325787}]}]}
{"op":"mcm","clk":"987765886","pt":1580471095556,"mc":[{"id":"1.168133553","rc":[{"batb":[[1,1.13,3]],"ltp":1.51,"tv":6.72,"id":16325787}]}]}
{"op":"mcm","clk":"987766747","pt":1580471106487,"mc":[{"id":"1.168133553","rc":[{"batb":[[1,1.03,1627.71],[2,1.01,4105.64]],"ltp":1.51,"tv":6.72,"id":16325787}]}]}
{"op":"mcm","clk":"987766751","pt":1580471106586,"mc":[{"id":"1.168133553","rc":[{"batb":[[1,1.14,3],[2,1.03,1627.71]],"ltp":1.51,"tv":6.72,"id":16325787}]}]}
{"op":"mcm","clk":"987767382","pt":1580471116212,"mc":[{"id":"1.168133553","rc":[{"batb":[[1,1.15,3]],"ltp":1.51,"tv":6.72,"id":16325787}]}]}
{"op":"mcm","clk":"987768002","pt":1580471123918,"mc":[{"id":"1.168133553","rc":[{"batb":[[1,1.04,3]],"ltp":0.0,"tv":0.0,"id":27227336},{"batb":[[1,1.04,3]],"ltp":0.0,"tv":0.0,"id":21641292}]}]}
{"op":"mcm","clk":"987768059","pt":1580471124905,"mc":[{"id":"1.168133553","rc":[{"batb":[[0,1.16,4.99],[1,1.03,1627.71],[2,1.01,4105.64]],"ltp":1.51,"tv":6.72,"id":16325787}]}]}
{"op":"mcm","clk":"987768581","pt":1580471132706,"mc":[{"id":"1.168133553","rc":[{"batb":[[0,1.17,3],[1,1.16,1.99],[2,1.03,1627.71]],"ltp":1.51,"tv":6.72,"id":16325787}]}]}
{"op":"mcm","clk":"987769417","pt":1580471146400,"mc":[{"id":"1.168133553","rc":[{"batb":[[0,1.16,1.99],[1,1.04,3]],"ltp":1.51,"tv":6.72,"id":16325787}]}]}
{"op":"mcm","clk":"987770350","pt":1580471156515,"mc":[{"id":"1.168133553","rc":[{"batb":[[1,1.03,1627.71],[2,1.01,4105.64]],"ltp":1.51,"tv":6.72,"id":16325787}]}]}
{"op":"mcm","clk":"987770361","pt":1580471156618,"mc":[{"id":"1.168133553","rc":[{"batb":[[1,1.05,3],[2,1.03,1627.71]],"ltp":1.51,"tv":6.72,"id":16325787}]}]}
{"op":"mcm","clk":"987771253","pt":1580471167429,"mc":[{"id":"1.168133553","rc":[{"batb":[[0,1.06,1.99]],"ltp":1.51,"tv":6.72,"id":16325787}]}]}
{"op":"mcm","clk":"987771273","pt":1580471167736,"mc":[{"id":"1.168133553","rc":[{"batb":[[0,1.06,4.99],[1,1.03,1627.71],[2,1.01,4105.64]],"ltp":1.51,"tv":6.72,"id":16325787}]}]}
{"op":"mcm","clk":"987772063","pt":1580471177512,"mc":[{"id":"1.168133553","rc":[{"batb":[[0,1.06,1.99]],"ltp":1.51,"tv":6.72,"id":16325787}]}]}
{"op":"mcm","clk":"987772098","pt":1580471178035,"mc":[{"id":"1.168133553","rc":[{"batb":[[0,1.08,39.7],[1,1.07,3],[2,1.06,1.99]],"ltp":1.51,"tv":6.72,"id":16325787}]}]}
{"op":"mcm","clk":"987772569","pt":1580471184854,"mc":[{"id":"1.168133553","rc":[{"batb":[[0,1.09,3],[1,1.08,39.7]],"ltp":1.51,"tv":6.72,"id":16325787}]}]}
{"op":"mcm","clk":"987774056","pt":1580471203689,"mc":[{"id":"1.168133553","rc":[{"batb":[[1,1.06,1.99],[2,1.04,6]],"ltp":1.51,"tv":6.72,"id":16325787}]}]}
{"op":"mcm","clk":"987774203","pt":1580471205204,"mc":[{"id":"1.168133553","rc":[{"batb":[[0,1.06,1.99],[1,1.05,3]],"ltp":1.51,"tv":6.72,"id":16325787}]}]}
{"op":"mcm","clk":"987775078","pt":1580471215828,"mc":[{"id":"1.168133553","rc":[{"batb":[[0,1.06,4.99],[1,1.04,6],[2,1.03,1627.71]],"ltp":1.51,"tv":6.72,"id":16325787}]}]}
{"op":"mcm","clk":"987776101","pt":1580471226212,"mc":[{"id":"1.168133553","rc":[{"batb":[[0,1.07,3],[1,1.06,1.99],[2,1.04,6]],"ltp":1.51,"tv":6.72,"id":16325787}]}]}
{"op":"mcm","clk":"987776304","pt":1580471228918,"mc":[{"id":"1.168133553","rc":[{"batb":[[0,1.08,39.7],[1,1.07,3],[2,1.06,1.99]],"ltp":1.51,"tv":6.72,"id":16325787}]}]}
{"op":"mcm","clk":"987776724","pt":1580471234977,"mc":[{"id":"1.168133553","rc":[{"batb":[[0,1.09,3],[1,1.08,39.7]],"ltp":1.51,"tv":6.72,"id":16325787}]}]}
{"op":"mcm","clk":"987777722","pt":1580471254156,"mc":[{"id":"1.168133553","rc":[{"batb":[[1,1.06,1.99],[2,1.04,6]],"ltp":1.51,"tv":6.72,"id":16325787}]}]}
{"op":"mcm","clk":"987777876","pt":1580471257036,"mc":[{"id":"1.168133553","rc":[{"batb":[[1,1.05,10],[2,1.04,3]],"ltp":0.0,"tv":0.0,"id":27227336},{"batb":[[1,1.05,10],[2,1.04,3]],"ltp":0.0,"tv":0.0,"id":21641292},{"batb":[[1,1.07,10],[2,1.06,1.99]],"ltp":1.51,"tv":6.72,"id":16325787}]}]}
{"op":"mcm","clk":"987778145","pt":1580471262341,"mc":[{"id":"1.168133553","rc":[{"batb":[[0,1.09,1.99],[1,1.08,3],[2,1.07,10]],"ltp":1.51,"tv":6.72,"id":16325787}]}]}
{"op":"mcm","clk":"987778682","pt":1580471271261,"mc":[{"id":"1.168133553","rc":[{"batb":[[0,1.09,4.99],[1,1.07,10],[2,1.04,6]],"ltp":1.51,"tv":6.72,"id":16325787}]}]}
{"op":"mcm","clk":"987779215","pt":1580471280384,"mc":[{"id":"1.168133553","rc":[{"batb":[[0,1.1,3],[1,1.09,1.99],[2,1.07,10]],"ltp":1.51,"tv":6.72,"id":16325787}]}]}
{"op":"mcm","clk":"987779808","pt":1580471289554,"mc":[{"id":"1.168133553","rc":[{"batb":[[0,1.09,1.99],[1,1.08,3]],"ltp":1.51,"tv":6.72,"id":16325787}]}]}
{"op":"mcm","clk":"987780086","pt":1580471294055,"mc":[{"id":"1.168133553","rc":[{"batb":[[1,1.06,3],[2,1.05,10]],"ltp":0.0,"tv":0.0,"id":27227336},{"batb":[[1,1.06,3],[2,1.05,10]],"ltp":0.0,"tv":0.0,"id":21641292}]}]}
{"op":"mcm","clk":"987780683","pt":1580471302273,"mc":[{"id":"1.168133553","rc":[{"batb":[[0,1.09,4.99],[1,1.07,10],[2,1.04,6]],"ltp":1.51,"tv":6.72,"id":16325787}]}]}
{"op":"mcm","clk":"987781157","pt":1580471309055,"mc":[{"id":"1.168133553","rc":[{"batb":[[0,1.1,3],[1,1.09,1.99],[2,1.07,10]],"ltp":1.51,"tv":6.72,"id":16325787}]}]}
{"op":"mcm","clk":"987781912","pt":1580471319801,"mc":[{"id":"1.168133553","rc":[{"batb":[[0,1.09,1.99],[1,1.08,3]],"ltp":1.51,"tv":6.72,"id":16325787}]}]}
{"op":"mcm","clk":"987782629","pt":1580471329805,"mc":[{"id":"1.168133553","rc":[{"batb":[[0,1.1,38.97],[1,1.09,4.99]],"ltp":1.51,"tv":6.72,"id":16325787}]}]}
{"op":"mcm","clk":"987783436","pt":1580471341420,"mc":[{"id":"1.168133553","rc":[{"batb":[[0,1.11,3],[1,1.1,38.97],[2,1.09,1.99]],"ltp":1.51,"tv":6.72,"id":16325787}]}]}
{"op":"mcm","clk":"987783458","pt":1580471341683,"mc":[{"id":"1.168133553","rc":[{"batb":[[1,1.07,10],[2,1.06,3]],"ltp":0.0,"tv":0.0,"id":27227336},{"batb":[[1,1.07,10],[2,1.06,3]],"ltp":0.0,"tv":0.0,"id":21641292},{"batb":[[0,1.11,13]],"ltp":1.51,"tv":6.72,"id":16325787}]}]}
{"op":"mcm","clk":"987784061","pt":1580471349463,"mc":[{"id":"1.168133553","rc":[{"batb":[[1,1.08,3],[2,1.07,10]],"ltp":0.0,"tv":0.0,"id":27227336},{"batb":[[1,1.08,3],[2,1.07,10]],"ltp":0.0,"tv":0.0,"id":21641292},{"batb":[[0,1.12,3],[1,1.11,13],[2,1.1,38.97]],"ltp":1.51,"tv":6.72,"id":16325787}]}]}
{"op":"mcm","clk":"987784189","pt":1580471351136,"mc":[{"id":"1.168133553","rc":[{"batb":[[0,1.13,3],[1,1.12,3],[2,1.11,10]],"ltp":1.51,"tv":6.72,"id":16325787}]}]}
{"op":"mcm","clk":"987784535","pt":1580471355949,"mc":[{"id":"1.168133553","rc":[{"batb":[[0,1.14,37.61],[1,1.13,3],[2,1.12,3]],"ltp":1.51,"tv":6.72,"id":16325787}]}]}
{"op":"mcm","clk":"987784663","pt":1580471357964,"mc":[{"id":"1.168133553","rc":[{"batb":[[0,1.15,1.99],[1,1.14,37.61],[2,1.13,3]],"ltp":1.51,"tv":6.72,"id":16325787}]}]}
{"op":"mcm","clk":"987785031","pt":1580471362560,"mc":[{"id":"1.168133553","rc":[{"batb":[[2,1.12,3]],"ltp":1.51,"tv":6.72,"id":16325787}]}]}
{"op":"mcm","clk":"987785035","pt":1580471362663,"mc":[{"id":"1.168133553","rc":[{"batb":[[0,1.15,4.99]],"ltp":1.51,"tv":6.72,"id":16325787}]}]}
{"op":"mcm","clk":"987785930","pt":1580471373173,"mc":[{"id":"1.168133553","rc":[{"batb":[[0,1.16,3],[1,1.15,1.99],[2,1.14,37.61]],"ltp":1.51,"tv":6.72,"id":16325787}]}]}
{"op":"mcm","clk":"987786612","pt":1580471382278,"mc":[{"id":"1.168133553","rc":[{"batb":[[0,1.17,36.65],[1,1.16,3],[2,1.15,1.99]],"ltp":1.51,"tv":6.72,"id":16325787}]}]}
{"op":"mcm","clk":"987786906","pt":1580471386101,"mc":[{"id":"1.168133553","rc":[{"batb":[[0,1.18,3],[1,1.17,36.65]],"ltp":1.51,"tv":6.72,"id":16325787}]}]}
{"op":"mcm","clk":"987788604","pt":1580471406952,"mc":[{"id":"1.168133553","rc":[{"batb":[[1,1.15,1.99],[2,1.12,3]],"ltp":1.51,"tv":6.72,"id":16325787}]}]}
{"op":"mcm","clk":"987789379","pt":1580471416548,"mc":[{"id":"1.168133553","rc":[{"batb":[[0,1.15,1.99],[1,1.12,3],[2,1.11,10]],"ltp":1.51,"tv":6.72,"id":16325787}]}]}
{"op":"mcm","clk":"987789388","pt":1580471416654,"mc":[{"id":"1.168133553","rc":[{"batb":[[1,1.13,3],[2,1.12,3]],"ltp":1.51,"tv":6.72,"id":16325787}]}]}
{"op":"mcm","clk":"987790151","pt":1580471426862,"mc":[{"id":"1.168133553","rc":[{"batb":[[2,1.03,1630.23]],"ltp":0.0,"tv":0.0,"id":27227336},{"batb":[[2,1.03,1663.02]],"ltp":0.0,"tv":0.0,"id":21641292}]}]}
{"op":"mcm","clk":"987790260","pt":1580471428230,"mc":[{"id":"1.168133553","rc":[{"batb":[[1,1.14,3]],"ltp":1.51,"tv":6.72,"id":16325787}]}]}
{"op":"mcm","clk":"987790574","pt":1580471432974,"mc":[{"id":"1.168133553","rc":[{"batb":[[0,1.16,36.97],[1,1.15,1.99],[2,1.14,3]],"ltp":1.51,"tv":6.72,"id":16325787}]}]}
{"op":"mcm","clk":"987790990","pt":1580471439488,"mc":[{"id":"1.168133553","rc":[{"batb":[[2,1.12,3]],"ltp":1.51,"tv":6.72,"id":16325787}]}]}
{"op":"mcm","clk":"987790998","pt":1580471439603,"mc":[{"id":"1.168133553","rc":[{"batb":[[0,1.17,3],[1,1.16,36.97],[2,1.15,1.99]],"ltp":1.51,"tv":6.72,"id":16325787}]}]}
{"op":"mcm","clk":"987791768","pt":1580471452403,"mc":[{"id":"1.168133553","rc":[{"batb":[[0,1.18,1.99],[1,1.17,3],[2,1.16,36.97]],"ltp":1.51,"tv":6.72,"id":16325787}]}]}
{"op":"mcm","clk":"987792184","pt":1580471458293,"mc":[{"id":"1.168133553","rc":[{"batb":[[2,1.12,3]],"ltp":1.51,"tv":6.72,"id":16325787}]}]}
{"op":"mcm","clk":"987792206","pt":1580471458609,"mc":[{"id":"1.168133553","rc":[{"batb":[[0,1.19,36.03],[1,1.18,1.99],[2,1.17,3]],"ltp":1.51,"tv":6.72,"id":16325787}]}]}
{"op":"mcm","clk":"987792314","pt":1580471460430,"mc":[{"id":"1.168133553","rc":[{"batb":[[1,1.04,3]],"ltp":0.0,"tv":0.0,"id":27227336},{"batb":[[1,1.04,3]],"ltp":0.0,"tv":0.0,"id":21641292}]}]}
{"op":"mcm","clk":"987792860","pt":1580471469030,"mc":[{"id":"1.168133553","rc":[{"batb":[[0,1.2,3],[1,1.19,36.03],[2,1.18,1.99]],"ltp":1.51,"tv":6.72,"id":16325787}]}]}
{"op":"mcm","clk":"987793985","pt":1580471483639,"mc":[{"id":"1.168133553","rc":[{"batb":[[1,1.18,1.99],[2,1.03,1627.71]],"ltp":1.51,"tv":6.72,"id":16325787}]}]}
{"op":"mcm","clk":"987794117","pt":1580471485571,"mc":[{"id":"1.168133553","rc":[{"batb":[[0,1.18,1.99],[1,1.04,3]],"ltp":1.51,"tv":6.72,"id":16325787}]}]}
{"op":"mcm","clk":"987794969","pt":1580471497558,"mc":[{"id":"1.168133553","rc":[{"batb":[[1,1.05,3]],"ltp":1.51,"tv":6.72,"id":16325787}]}]}
{"op":"mcm","clk":"987795509","pt":1580471505199,"mc":[{"id":"1.168133553","rc":[{"batb":[[1,1.06,3]],"ltp":1.51,"tv":6.72,"id":16325787}]}]}
{"op":"mcm","clk":"987796331","pt":1580471517675,"mc":[{"id":"1.168133553","rc":[{"batb":[[1,1.07,3]],"ltp":1.51,"tv":6.72,"id":16325787}]}]}
{"op":"mcm","clk":"987797241","pt":1580471529736,"mc":[{"id":"1.168133553","rc":[{"batb":[[1,1.08,3]],"ltp":1.51,"tv":6.72,"id":16325787}]}]}
{"op":"mcm","clk":"987798077","pt":1580471541406,"mc":[{"id":"1.168133553","rc":[{"batb":[[1,1.09,3]],"ltp":1.51,"tv":6.72,"id":16325787}]}]}
{"op":"mcm","clk":"987798420","pt":1580471547175,"mc":[{"id":"1.168133553","rc":[{"batb":[[0,1.1,1.99]],"ltp":1.51,"tv":6.72,"id":16325787}]}]}
{"op":"mcm","clk":"987798548","pt":1580471549505,"mc":[{"id":"1.168133553","rc":[{"batb":[[2,1.04,6]],"ltp":1.51,"tv":6.72,"id":16325787}]}]}
{"op":"mcm","clk":"987798654","pt":1580471551493,"mc":[{"id":"1.168133553","rc":[{"batb":[[0,1.1,4.99],[1,1.04,6],[2,1.03,1627.71]],"ltp":1.51,"tv":6.72,"id":16325787}]}]}
{"op":"mcm","clk":"987807294","pt":1580471560137,"mc":[{"id":"1.168133553","rc":[{"batb":[[1,1.05,3],[2,1.04,6]],"ltp":1.51,"tv":6.72,"id":16325787}]}]}
{"op":"mcm","clk":"987807612","pt":1580471565409,"mc":[{"id":"1.168133553","rc":[{"batb":[[0,1.11,3],[1,1.1,1.99],[2,1.05,3]],"ltp":1.51,"tv":6.72,"id":16325787}]}]}
{"op":"mcm","clk":"987808311","pt":1580471577032,"mc":[{"id":"1.168133553","rc":[{"batb":[[0,1.1,1.99],[1,1.06,3]],"ltp":1.51,"tv":6.72,"id":16325787}]}]}
{"op":"mcm","clk":"987809035","pt":1580471589973,"mc":[{"id":"1.168133553","rc":[{"batb":[[1,1.07,3]],"ltp":1.51,"tv":6.72,"id":16325787}]}]}
{"op":"mcm","clk":"987809306","pt":1580471594863,"mc":[{"id":"1.168133553","rc":[{"batb":[[1,1.05,10],[2,1.04,3]],"ltp":0.0,"tv":0.0,"id":27227336},{"batb":[[1,1.05,10],[2,1.04,3]],"ltp":0.0,"tv":0.0,"id":21641292},{"batb":[[1,1.08,10],[2,1.07,3]],"ltp":1.51,"tv":6.72,"id":16325787}]}]}
{"op":"mcm","clk":"987809698","pt":1580471601781,"mc":[{"id":"1.168133553","rc":[{"batb":[[1,1.09,3],[2,1.08,10]],"ltp":1.51,"tv":6.72,"id":16325787}]}]}
{"op":"mcm","clk":"987809930","pt":1580471606300,"mc":[{"id":"1.168133553","rc":[{"batb":[[0,1.11,38.63],[1,1.1,1.99],[2,1.09,3]],"ltp":1.51,"tv":6.72,"id":16325787}]}]}
{"op":"mcm","clk":"987810249","pt":1580471612981,"mc":[{"id":"1.168133553","rc":[{"batb":[[0,1.12,3],[1,1.11,38.63],[2,1.1,1.99]],"ltp":1.51,"tv":6.72,"id":16325787}]}]}
{"op":"mcm","clk":"987811280","pt":1580471630698,"mc":[{"id":"1.168133553","rc":[{"batb":[[1,1.1,1.99],[2,1.08,10]],"ltp":1.51,"tv":6.72,"id":16325787}]}]}
{"op":"mcm","clk":"987811372","pt":1580471632422,"mc":[{"id":"1.168133553","rc":[{"batb":[[0,1.1,1.99],[1,1.09,3]],"ltp":1.51,"tv":6.72,"id":16325787}]}]}
{"op":"mcm","clk":"987811629","pt":1580471636890,"mc":[{"id":"1.168133553","rc":[{"batb":[[1,1.06,3],[2,1.05,10]],"ltp":0.0,"tv":0.0,"id":27227336},{"batb":[[1,1.06,3],[2,1.05,10]],"ltp":0.0,"tv":0.0,"id":21641292}]}]}
{"op":"mcm","clk":"987812067","pt":1580471644317,"mc":[{"id":"1.168133553","rc":[{"batb":[[0,1.1,4.99],[1,1.08,10],[2,1.04,6]],"ltp":1.51,"tv":6.72,"id":16325787}]}]}
{"op":"mcm","clk":"987812605","pt":1580471655517,"mc":[{"id":"1.168133553","rc":[{"batb":[[0,1.11,3],[1,1.1,1.99],[2,1.08,10]],"ltp":1.51,"tv":6.72,"id":16325787}]}]}
{"op":"mcm","clk":"987812628","pt":1580471656031,"mc":[{"id":"1.168133553","rc":[{"batb":[[0,1.12,38.28],[1,1.11,3],[2,1.1,1.99]],"ltp":1.51,"tv":6.72,"id":16325787}]}]}
{"op":"mcm","clk":"987813214","pt":1580471667263,"mc":[{"id":"1.168133553","rc":[{"batb":[[0,1.13,4.99],[1,1.12,38.28],[2,1.08,10]],"ltp":1.51,"tv":6.72,"id":16325787}]}]}
{"op":"mcm","clk":"987814097","pt":1580471681190,"mc":[{"id":"1.168133553","rc":[{"batb":[[2,1.03,1630.23]],"ltp":0.0,"tv":0.0,"id":27227336},{"batb":[[2,1.03,1663.02]],"ltp":0.0,"tv":0.0,"id":21641292},{"batb":[[1,1.04,6],[2,1.03,1627.71]],"ltp":1.51,"tv":6.72,"id":16325787}]}]}
{"op":"mcm","clk":"987814173","pt":1580471682181,"mc":[{"id":"1.168133553","rc":[{"batb":[[0,1.14,3],[1,1.13,1.99],[2,1.04,6]],"ltp":1.51,"tv":6.72,"id":16325787}]}]}
{"op":"mcm","clk":"987814820","pt":1580471693509,"mc":[{"id":"1.168133553","rc":[{"batb":[[0,1.13,1.99],[1,1.05,3]],"ltp":1.51,"tv":6.72,"id":16325787}]}]}
{"op":"mcm","clk":"987815697","pt":1580471707249,"mc":[{"id":"1.168133553","rc":[{"batb":[[1,1.06,3]],"ltp":1.51,"tv":6.72,"id":16325787}]}]}
{"op":"mcm","clk":"987816492","pt":1580471719300,"mc":[{"id":"1.168133553","rc":[{"batb":[[1,1.07,3]],"ltp":1.51,"tv":6.72,"id":16325787}]}]}
{"op":"mcm","clk":"987817010","pt":1580471728950,"mc":[{"id":"1.168133553","rc":[{"batb":[[1,1.08,3]],"ltp":1.51,"tv":6.72,"id":16325787}]}]}
{"op":"mcm","clk":"987817662","pt":1580471739733,"mc":[{"id":"1.168133553","rc":[{"batb":[[1,1.09,3]],"ltp":1.51,"tv":6.72,"id":16325787}]}]}
{"op":"mcm","clk":"987818184","pt":1580471748337,"mc":[{"id":"1.168133553","rc":[{"batb":[[1,1.04,3]],"ltp":0.0,"tv":0.0,"id":27227336},{"batb":[[1,1.04,3]],"ltp":0.0,"tv":0.0,"id":21641292}]}]}
{"op":"mcm","clk":"987818208","pt":1580471748762,"mc":[{"id":"1.168133553","rc":[{"batb":[[1,1.1,3]],"ltp":1.51,"tv":6.72,"id":16325787}]}]}
{"op":"mcm","clk":"987818793","pt":1580471757256,"mc":[{"id":"1.168133553","rc":[{"batb":[[1,1.11,3]],"ltp":1.51,"tv":6.72,"id":16325787}]}]}
{"op":"mcm","clk":"987819464","pt":1580471767051,"mc":[{"id":"1.168133553","rc":[{"batb":[[1,1.12,3]],"ltp":1.51,"tv":6.72,"id":16325787}]}]}
{"op":"mcm","clk":"987820161","pt":1580471777368,"mc":[{"id":"1.168133553","rc":[{"batb":[[0,1.13,4.99],[1,1.04,6],[2,1.03,1627.71]],"ltp":1.51,"tv":6.72,"id":16325787}]}]}
{"op":"mcm","clk":"987820798","pt":1580471786924,"mc":[{"id":"1.168133553","rc":[{"batb":[[0,1.14,3],[1,1.13,1.99],[2,1.04,6]],"ltp":1.51,"tv":6.72,"id":16325787}]}]}
{"op":"mcm","clk":"987821389","pt":1580471796548,"mc":[{"id":"1.168133553","rc":[{"batb":[[0,1.13,1.99],[1,1.05,3]],"ltp":1.51,"tv":6.72,"id":16325787}]}]}
{"op":"mcm","clk":"987821546","pt":1580471798948,"mc":[{"id":"1.168133553","rc":[{"batb":[[0,1.06,1.99]],"ltp":1.51,"tv":6.72,"id":16325787}]}]}
{"op":"mcm","clk":"987821990","pt":1580471806337,"mc":[{"id":"1.168133553","rc":[{"batb":[[0,1.07,40.07],[1,1.06,1.99],[2,1.05,3]],"ltp":1.51,"tv":6.72,"id":16325787}]}]}
{"op":"mcm","clk":"987822060","pt":1580471807434,"mc":[{"id":"1.168133553","rc":[{"batb":[[0,1.08,3],[1,1.07,40.07],[2,1.06,1.99]],"ltp":1.51,"tv":6.72,"id":16325787}]}]}
{"op":"mcm","clk":"987823829","pt":1580471831781,"mc":[{"id":"1.168133553","rc":[{"batb":[[1,1.06,1.99],[2,1.04,6]],"ltp":1.51,"tv":6.72,"id":16325787}]}]}
{"op":"mcm","clk":"987824029","pt":1580471834372,"mc":[{"id":"1.168133553","rc":[{"batb":[[0,1.06,1.99],[1,1.05,3]],"ltp":1.51,"tv":6.72,"id":16325787}]}]}
{"op":"mcm","clk":"987824493","pt":1580471841884,"mc":[{"id":"1.168133553","rc":[{"batb":[[0,1.06,4.99],[1,1.04,6],[2,1.03,1627.71]],"ltp":1.51,"tv":6.72,"id":16325787}]}]}
{"op":"mcm","clk":"987825160","pt":1580471852316,"mc":[{"id":"1.168133553","rc":[{"batb":[[0,1.07,3],[1,1.06,1.99],[2,1.04,6]],"ltp":1.51,"tv":6.72,"id":16325787}]}]}
{"op":"mcm","clk":"987825518","pt":1580471857620,"mc":[{"id":"1.168133553","rc":[{"batb":[[0,1.08,39.7],[1,1.07,3],[2,1.06,1.99]],"ltp":1.51,"tv":6.72,"id":16325787}]}]}
{"op":"mcm","clk":"987825897","pt":1580471862518,"mc":[{"id":"1.168133553","rc":[{"batb":[[0,1.09,3],[1,1.08,39.7]],"ltp":1.51,"tv":6.72,"id":16325787}]}]}
{"op":"mcm","clk":"987827392","pt":1580471883729,"mc":[{"id":"1.168133553","rc":[{"batb":[[1,1.06,1.99],[2,1.04,6]],"ltp":1.51,"tv":6.72,"id":16325787}]}]}
{"op":"mcm","clk":"987827857","pt":1580471890066,"mc":[{"id":"1.168133553","rc":[{"batb":[[0,1.06,1.99],[1,1.05,3]],"ltp":1.51,"tv":6.72,"id":16325787}]}]}
{"op":"mcm","clk":"987828646","pt":1580471899757,"mc":[{"id":"1.168133553","rc":[{"batb":[[0,1.06,4.99],[1,1.04,6],[2,1.03,1627.71]],"ltp":1.51,"tv":6.72,"id":16325787}]}]}
{"op":"mcm","clk":"987829647","pt":1580471912508,"mc":[{"id":"1.168133553","rc":[{"batb":[[0,1.06,1.99]],"ltp":1.51,"tv":6.72,"id":16325787}]}]}
{"op":"mcm","clk":"987829657","pt":1580471912610,"mc":[{"id":"1.168133553","rc":[{"batb":[[0,1.07,3],[1,1.06,1.99],[2,1.04,6]],"ltp":1.51,"tv":6.72,"id":16325787}]}]}
{"op":"mcm","clk":"987830543","pt":1580471924533,"mc":[{"id":"1.168133553","rc":[{"batb":[[0,1.06,1.99],[1,1.05,3]],"ltp":1.51,"tv":6.72,"id":16325787}]}]}
{"op":"mcm","clk":"987831231","pt":1580471934550,"mc":[{"id":"1.168133553","rc":[{"batb":[[0,1.06,4.99],[1,1.04,6],[2,1.03,1627.71]],"ltp":1.51,"tv":6.72,"id":16325787}]}]}
{"op":"mcm","clk":"987832065","pt":1580471946209,"mc":[{"id":"1.168133553","rc":[{"batb":[[0,1.07,3],[1,1.06,1.99],[2,1.04,6]],"ltp":1.51,"tv":6.72,"id":16325787}]}]}
{"op":"mcm","clk":"987832703","pt":1580471954975,"mc":[{"id":"1.168133553","rc":[{"batb":[[0,1.06,1.99],[1,1.05,3]],"ltp":1.51,"tv":6.72,"id":16325787}]}]}
{"op":"mcm","clk":"987833089","pt":1580471960360,"mc":[{"id":"1.168133553","rc":[{"batb":[[0,1.07,40.07],[1,1.06,1.99],[2,1.05,3]],"ltp":1.51,"tv":6.72,"id":16325787}]}]}
{"op":"mcm","clk":"987833414","pt":1580471965298,"mc":[{"id":"1.168133553","rc":[{"batb":[[0,1.08,3],[1,1.07,40.07],[2,1.06,1.99]],"ltp":1.51,"tv":6.72,"id":16325787}]}]}
{"op":"mcm","clk":"987834941","pt":1580471985297,"mc":[{"id":"1.168133553","rc":[{"batb":[[1,1.06,1.99],[2,1.04,6]],"ltp":1.51,"tv":6.72,"id":16325787}]}]}
{"op":"mcm","clk":"987835052","pt":1580471986705,"mc":[{"id":"1.168133553","rc":[{"batb":[[0,1.06,1.99],[1,1.05,3]],"ltp":1.51,"tv":6.72,"id":16325787}]}]}
{"op":"mcm","clk":"987835654","pt":1580471995942,"mc":[{"id":"1.168133553","rc":[{"batb":[[0,1.06,4.99],[1,1.04,6],[2,1.03,1627.71]],"ltp":1.51,"tv":6.72,"id":16325787}]}]}
{"op":"mcm","clk":"987836560","pt":1580472005561,"mc":[{"id":"1.168133553","rc":[{"batb":[[2,1.03,1630.64]],"ltp":0.0,"tv":0.0,"id":27227336},{"batb":[[2,1.03,1663.44]],"ltp":0.0,"tv":0.0,"id":21641292},{"batb":[[0,1.06,1.99],[2,1.03,1628.12]],"ltp":1.51,"tv":6.72,"id":16325787}]}]}
{"op":"mcm","clk":"987836573","pt":1580472005667,"mc":[{"id":"1.168133553","rc":[{"batb":[[0,1.07,3],[1,1.06,1.99],[2,1.04,6]],"ltp":1.51,"tv":6.72,"id":16325787}]}]}
{"op":"mcm","clk":"987837140","pt":1580472011651,"mc":[{"id":"1.168133553","rc":[{"batb":[[0,1.08,39.71],[1,1.07,3],[2,1.06,1.99]],"ltp":1.51,"tv":6.72,"id":16325787}]}]}
{"op":"mcm","clk":"987837506","pt":1580472016286,"mc":[{"id":"1.168133553","rc":[{"batb":[[0,1.09,3],[1,1.08,39.71]],"ltp":1.51,"tv":6.72,"id":16325787}]}]}
{"op":"mcm","clk":"987838924","pt":1580472036399,"mc":[{"id":"1.168133553","rc":[{"batb":[[1,1.06,1.99],[2,1.04,6]],"ltp":1.51,"tv":6.72,"id":16325787}]}]}
{"op":"mcm","clk":"987839567","pt":1580472045508,"mc":[{"id":"1.168133553","rc":[{"batb":[[0,1.06,1.99],[1,1.05,3]],"ltp":1.51,"tv":6.72,"id":16325787}]}]}
{"op":"mcm","clk":"987840316","pt":1580472055851,"mc":[{"id":"1.168133553","rc":[{"batb":[[0,1.06,4.99],[1,1.04,6],[2,1.03,1628.12]],"ltp":1.51,"tv":6.72,"id":16325787}]}]}
{"op":"mcm","clk":"987840423","pt":1580472057512,"mc":[{"id":"1.168133553","rc":[{"batb":[[1,1.05,10],[2,1.04,3]],"ltp":0.0,"tv":0.0,"id":27227336},{"batb":[[1,1.05,10],[2,1.04,3]],"ltp":0.0,"tv":0.0,"id":21641292},{"batb":[[1,1.05,10],[2,1.04,6]],"ltp":1.51,"tv":6.72,"id":16325787}]}]}
{"op":"mcm","clk":"987840716","pt":1580472061352,"mc":[{"id":"1.168133553","rc":[{"batb":[[0,1.07,40.08],[1,1.06,4.99],[2,1.05,10]],"ltp":1.51,"tv":6.72,"id":16325787}]}]}
{"op":"mcm","clk":"987841295","pt":1580472068362,"mc":[{"id":"1.168133553","rc":[{"batb":[[0,1.08,3],[1,1.07,40.08],[2,1.06,1.99]],"ltp":1.51,"tv":6.72,"id":16325787}]}]}
{"op":"mcm","clk":"987842272","pt":1580472082236,"mc":[{"id":"1.168133553","rc":[{"batb":[[0,1.09,1.99],[1,1.08,3],[2,1.07,40.08]],"ltp":1.51,"tv":6.72,"id":16325787}]}]}
{"op":"mcm","clk":"987842511","pt":1580472087279,"mc":[{"id":"1.168133553","rc":[{"batb":[[0,1.1,38.98],[1,1.09,1.99],[2,1.08,3]],"ltp":1.51,"tv":6.72,"id":16325787}]}]}
{"op":"mcm","clk":"987842868","pt":1580472093347,"mc":[{"id":"1.168133553","rc":[{"batb":[[0,1.11,3],[1,1.1,38.98],[2,1.09,1.99]],"ltp":1.51,"tv":6.72,"id":16325787}]}]}
{"op":"mcm","clk":"987844309","pt":1580472113288,"mc":[{"id":"1.168133553","rc":[{"batb":[[1,1.09,1.99],[2,1.05,10]],"ltp":1.51,"tv":6.72,"id":16325787}]}]}
{"op":"mcm","clk":"987844462","pt":1580472115098,"mc":[{"id":"1.168133553","rc":[{"batb":[[2,1.03,1630.64]],"ltp":0.0,"tv":0.0,"id":27227336},{"batb":[[2,1.03,1663.44]],"ltp":0.0,"tv":0.0,"id":21641292},{"batb":[[0,1.09,1.99],[1,1.06,3]],"ltp":1.51,"tv":6.72,"id":16325787}]}]}
{"op":"mcm","clk":"987845529","pt":1580472125496,"mc":[{"id":"1.168133553","rc":[{"batb":[[1,1.05,10],[2,1.04,6]],"ltp":1.51,"tv":6.72,"id":16325787}]}]}
{"op":"mcm","clk":"987845543","pt":1580472125605,"mc":[{"id":"1.168133553","rc":[{"batb":[[1,1.07,3],[2,1.05,10]],"ltp":1.51,"tv":6.72,"id":16325787}]}]}
{"op":"mcm","clk":"987846610","pt":1580472134737,"mc":[{"id":"1.168133553","rc":[{"batb":[[1,1.08,3]],"ltp":1.51,"tv":6.72,"id":16325787}]}]}
{"op":"mcm","clk":"987847101","pt":1580472138859,"mc":[{"id":"1.168133553","rc":[{"batb":[[0,1.1,38.98],[1,1.09,1.99],[2,1.08,3]],"ltp":1.51,"tv":6.72,"id":16325787}]}]}
{"op":"mcm","clk":"987847627","pt":1580472144158,"mc":[{"id":"1.168133553","rc":[{"batb":[[0,1.11,3],[1,1.1,38.98],[2,1.09,1.99]],"ltp":1.51,"tv":6.72,"id":16325787}]}]}
{"op":"mcm","clk":"987848088","pt":1580472149021,"mc":[{"id":"1.168133553","rc":[{"batb":[[1,1.03,1630.64],[2,1.02,1.99]],"ltp":0.0,"tv":0.0,"id":27227336},{"batb":[[1,1.03,1663.44],[2,1.02,1.99]],"ltp":0.0,"tv":0.0,"id":21641292}]}]}
{"op":"mcm","clk":"987849408","pt":1580472164592,"mc":[{"id":"1.168133553","rc":[{"batb":[[1,1.09,1.99],[2,1.04,6]],"ltp":1.51,"tv":6.72,"id":16325787}]}]}
{"op":"mcm","clk":"987849707","pt":1580472168490,"mc":[{"id":"1.168133553","rc":[{"batb":[[0,1.09,1.99],[1,1.05,3]],"ltp":1.51,"tv":6.72,"id":16325787}]}]}
{"op":"mcm","clk":"987850658","pt":1580472178924,"mc":[{"id":"1.168133553","rc":[{"batb":[[0,1.06,1.99]],"ltp":1.51,"tv":6.72,"id":16325787}]}]}
{"op":"mcm","clk":"987850906","pt":1580472181810,"mc":[{"id":"1.168133553","rc":[{"batb":[[0,1.06,4.99],[1,1.04,6],[2,1.03,1628.12]],"ltp":1.51,"tv":6.72,"id":16325787}]}]}
{"op":"mcm","clk":"987852043","pt":1580472193762,"mc":[{"id":"1.168133553","rc":[{"batb":[[0,1.07,3],[1,1.06,1.99],[2,1.04,6]],"ltp":1.51,"tv":6.72,"id":16325787}]}]}
{"op":"mcm","clk":"987853131","pt":1580472204570,"mc":[{"id":"1.168133553","rc":[{"batb":[[0,1.06,1.99],[1,1.05,3]],"ltp":1.51,"tv":6.72,"id":16325787}]}]}
{"op":"mcm","clk":"987854015","pt":1580472214612,"mc":[{"id":"1.168133553","rc":[{"batb":[[0,1.07,40.08],[1,1.06,1.99],[2,1.05,3]],"ltp":1.51,"tv":6.72,"id":16325787}]}]}
{"op":"mcm","clk":"987854236","pt":1580472216716,"mc":[{"id":"1.168133553","rc":[{"batb":[[0,1.08,3],[1,1.07,40.08],[2,1.06,1.99]],"ltp":1.51,"tv":6.72,"id":16325787}]}]}
{"op":"mcm","clk":"987856775","pt":1580472238811,"mc":[{"id":"1.168133553","rc":[{"batb":[[1,1.06,1.99],[2,1.04,6]],"ltp":1.51,"tv":6.72,"id":16325787}]}]}
{"op":"mcm","clk":"987857131","pt":1580472242699,"mc":[{"id":"1.168133553","rc":[{"batb":[[0,1.06,1.99],[1,1.05,3]],"ltp":1.51,"tv":6.72,"id":16325787}]}]}
{"op":"mcm","clk":"987858622","pt":1580472255111,"mc":[{"id":"1.168133553","rc":[{"batb":[[0,1.06,4.99],[1,1.04,6],[2,1.03,1628.12]],"ltp":1.51,"tv":6.72,"id":16325787}]}]}
{"op":"mcm","clk":"987860535","pt":1580472271773,"mc":[{"id":"1.168133553","rc":[{"batb":[[0,1.07,3],[1,1.06,1.99],[2,1.04,6]],"ltp":1.51,"tv":6.72,"id":16325787}]}]}
{"op":"mcm","clk":"987861808","pt":1580472284282,"mc":[{"id":"1.168133553","rc":[{"batb":[[0,1.06,1.99],[1,1.05,3]],"ltp":1.51,"tv":6.72,"id":16325787}]}]}
{"op":"mcm","clk":"987862421","pt":1580472289793,"mc":[{"id":"1.168133553","rc":[{"batb":[[0,1.07,40.08],[1,1.06,1.99],[2,1.05,3]],"ltp":1.51,"tv":6.72,"id":16325787}]}]}
{"op":"mcm","clk":"987863604","pt":1580472301288,"mc":[{"id":"1.168133553","rc":[{"batb":[[0,1.08,3],[1,1.07,40.08],[2,1.06,1.99]],"ltp":1.51,"tv":6.72,"id":16325787}]}]}
{"op":"mcm","clk":"987864895","pt":1580472314538,"mc":[{"id":"1.168133553","rc":[{"batb":[[1,1.06,1.99],[2,1.04,6]],"ltp":1.51,"tv":6.72,"id":16325787}]}]}
{"op":"mcm","clk":"987864990","pt":1580472315540,"mc":[{"id":"1.168133553","rc":[{"batb":[[0,1.06,1.99],[1,1.04,6],[2,1.03,1628.12]],"ltp":1.51,"tv":6.72,"id":16325787}]}]}
{"op":"mcm","clk":"987864995","pt":1580472315645,"mc":[{"id":"1.168133553","rc":[{"batb":[[1,1.05,3],[2,1.04,6]],"ltp":1.51,"tv":6.72,"id":16325787}]}]}
{"op":"mcm","clk":"987866647","pt":1580472330850,"mc":[{"id":"1.168133553","rc":[{"batb":[[0,1.06,4.99],[1,1.04,6],[2,1.03,1628.12]],"ltp":1.51,"tv":6.72,"id":16325787}]}]}
{"op":"mcm","clk":"987868441","pt":1580472348399,"mc":[{"id":"1.168133553","rc":[{"batb":[[0,1.07,3],[1,1.06,1.99],[2,1.04,6]],"ltp":1.51,"tv":6.72,"id":16325787}]}]}
{"op":"mcm","clk":"987869802","pt":1580472364514,"mc":[{"id":"1.168133553","rc":[{"batb":[[0,1.07,40.08],[2,1.05,3]],"ltp":1.51,"tv":6.72,"id":16325787}]}]}
{"op":"mcm","clk":"987871383","pt":1580472379140,"mc":[{"id":"1.168133553","rc":[{"batb":[[0,1.08,3],[1,1.07,40.08],[2,1.06,1.99]],"ltp":1.51,"tv":6.72,"id":16325787}]}]}
{"op":"mcm","clk":"987872278","pt":1580472389937,"mc":[{"id":"1.168133553","rc":[{"batb":[[1,1.06,1.99],[2,1.04,6]],"ltp":1.51,"tv":6.72,"id":16325787}]}]}
{"op":"mcm","clk":"987872555","pt":1580472393555,"mc":[{"id":"1.168133553","rc":[{"batb":[[0,1.06,1.99],[1,1.04,6],[2,1.03,1628.12]],"ltp":1.51,"tv":6.72,"id":16325787}]}]}
{"op":"mcm","clk":"987872567","pt":1580472393670,"mc":[{"id":"1.168133553","rc":[{"batb":[[1,1.05,3],[2,1.04,6]],"ltp":1.51,"tv":6.72,"id":16325787}]}]}
{"op":"mcm","clk":"987873722","pt":1580472407898,"mc":[{"id":"1.168133553","rc":[{"batb":[[0,1.06,4.99],[1,1.04,6],[2,1.03,1628.12]],"ltp":1.51,"tv":6.72,"id":16325787}]}]}
{"op":"mcm","clk":"987875929","pt":1580472427247,"mc":[{"id":"1.168133553","rc":[{"batb":[[0,1.07,3],[1,1.06,1.99],[2,1.04,6]],"ltp":1.51,"tv":6.72,"id":16325787}]}]}
{"op":"mcm","clk":"987877269","pt":1580472440060,"mc":[{"id":"1.168133553","rc":[{"batb":[[0,1.08,39.71],[1,1.07,3],[2,1.06,1.99]],"ltp":1.51,"tv":6.72,"id":16325787}]}]}
{"op":"mcm","clk":"987877609","pt":1580472443771,"mc":[{"id":"1.168133553","rc":[{"batb":[[0,1.09,3],[1,1.08,39.71]],"ltp":1.51,"tv":6.72,"id":16325787}]}]}
{"op":"mcm","clk":"987887919","pt":1580472465797,"mc":[{"id":"1.168133553","rc":[{"batb":[[1,1.06,1.99],[2,1.04,6]],"ltp":1.51,"tv":6.72,"id":16325787}]}]}
{"op":"mcm","clk":"987888321","pt":1580472469472,"mc":[{"id":"1.168133553","rc":[{"batb":[[0,1.06,1.99],[1,1.05,3]],"ltp":1.51,"tv":6.72,"id":16325787}]}]}
{"op":"mcm","clk":"987889977","pt":1580472485984,"mc":[{"id":"1.168133553","rc":[{"batb":[[0,1.06,4.99],[1,1.04,6],[2,1.03,1628.12]],"ltp":1.51,"tv":6.72,"id":16325787}]}]}
{"op":"mcm","clk":"987891514","pt":1580472500240,"mc":[{"id":"1.168133553","rc":[{"batb":[[0,1.07,3],[1,1.06,1.99],[2,1.04,6]],"ltp":1.51,"tv":6.72,"id":16325787}]}]}
{"op":"mcm","clk":"987892249","pt":1580472507456,"mc":[{"id":"1.168133553","rc":[{"batb":[[1,1.04,10],[2,1.03,1630.64]],"ltp":0.0,"tv":0.0,"id":27227336},{"batb":[[1,1.04,10],[2,1.03,1663.44]],"ltp":0.0,"tv":0.0,"id":21641292},{"batb":[[0,1.07,13]],"ltp":1.51,"tv":6.72,"id":16325787}]}]}
{"op":"mcm","clk":"987893060","pt":1580472515493,"mc":[{"id":"1.168133553","rc":[{"batb":[[0,1.08,3],[1,1.07,10]],"ltp":1.51,"tv":6.72,"id":16325787}]}]}
{"op":"mcm","clk":"987893068","pt":1580472515582,"mc":[{"id":"1.168133553","rc":[{"batb":[[0,1.09,1.99],[1,1.08,3],[2,1.07,10]],"ltp":1.51,"tv":6.72,"id":16325787}]}]}
{"op":"mcm","clk":"987893197","pt":1580472516804,"mc":[{"id":"1.168133553","rc":[{"batb":[[0,1.1,38.98],[1,1.09,1.99],[2,1.08,3]],"ltp":1.51,"tv":6.72,"id":16325787}]}]}
{"op":"mcm","clk":"987894574","pt":1580472530419,"mc":[{"id":"1.168133553","rc":[{"batb":[[0,1.11,3],[1,1.1,38.98],[2,1.09,1.99]],"ltp":1.51,"tv":6.72,"id":16325787}]}]}
{"op":"mcm","clk":"987895920","pt":1580472543201,"mc":[{"id":"1.168133553","rc":[{"batb":[[1,1.09,1.99],[2,1.07,10]],"ltp":1.51,"tv":6.72,"id":16325787}]}]}
{"op":"mcm","clk":"987896155","pt":1580472545304,"mc":[{"id":"1.168133553","rc":[{"batb":[[0,1.09,1.99],[1,1.08,3]],"ltp":1.51,"tv":6.72,"id":16325787}]}]}
{"op":"mcm","clk":"987897731","pt":1580472558738,"mc":[{"id":"1.168133553","rc":[{"batb":[[0,1.09,4.99],[1,1.07,10],[2,1.04,6]],"ltp":1.51,"tv":6.72,"id":16325787}]}]}
{"op":"mcm","clk":"987899080","pt":1580472573059,"mc":[{"id":"1.168133553","rc":[{"batb":[[0,1.1,3],[1,1.09,1.99],[2,1.07,10]],"ltp":1.51,"tv":6.72,"id":16325787}]}]}
{"op":"mcm","clk":"987900262","pt":1580472584866,"mc":[{"id":"1.168133553","rc":[{"batb":[[0,1.09,1.99],[1,1.08,3]],"ltp":1.51,"tv":6.72,"id":16325787}]}]}
{"op":"mcm","clk":"987901135","pt":1580472594684,"mc":[{"id":"1.168133553","rc":[{"batb":[[0,1.1,38.98],[1,1.09,1.99],[2,1.08,3]],"ltp":1.51,"tv":6.72,"id":16325787}]}]}
{"op":"mcm","clk":"987901498","pt":1580472598486,"mc":[{"id":"1.168133553","rc":[{"batb":[[0,1.11,13],[1,1.1,38.98],[2,1.09,1.99]],"ltp":1.51,"tv":6.72,"id":16325787}]}]}
{"op":"mcm","clk":"987901590","pt":1580472599287,"mc":[{"id":"1.168133553","rc":[{"batb":[[0,1.12,1.99],[1,1.11,13],[2,1.1,38.98]],"ltp":1.51,"tv":6.72,"id":16325787}]}]}
{"op":"mcm","clk":"987903512","pt":1580472617023,"mc":[{"id":"1.168133553","rc":[{"batb":[[0,1.12,4.99],[1,1.11,10]],"ltp":1.51,"tv":6.72,"id":16325787}]}]}
{"op":"mcm","clk":"987904056","pt":1580472622057,"mc":[{"id":"1.168133553","rc":[{"batb":[[0,1.13,37.95],[1,1.12,4.99],[2,1.11,10]],"ltp":1.51,"tv":6.72,"id":16325787}]}]}
{"op":"mcm","clk":"987904808","pt":1580472629080,"mc":[{"id":"1.168133553","rc":[{"batb":[[0,1.14,3],[1,1.13,37.95],[2,1.12,1.99]],"ltp":1.51,"tv":6.72,"id":16325787}]}]}
{"op":"mcm","clk":"987906917","pt":1580472649575,"mc":[{"id":"1.168133553","rc":[{"batb":[[1,1.12,1.99],[2,1.11,10]],"ltp":1.51,"tv":6.72,"id":16325787}]}]}
{"op":"mcm","clk":"987908011","pt":1580472660230,"mc":[{"id":"1.168133553","rc":[{"batb":[[0,1.12,4.99],[1,1.11,10],[2,1.04,6]],"ltp":1.51,"tv":6.72,"id":16325787}]}]}
{"op":"mcm","clk":"987909353","pt":1580472673053,"mc":[{"id":"1.168133553","rc":[{"batb":[[0,1.13,3],[1,1.12,1.99],[2,1.11,10]],"ltp":1.51,"tv":6.72,"id":16325787}]}]}
{"op":"mcm","clk":"987909711","pt":1580472676831,"mc":[{"id":"1.168133553","rc":[{"batb":[[0,1.14,37.62],[1,1.13,3],[2,1.12,1.99]],"ltp":1.51,"tv":6.72,"id":16325787}]}]}
{"op":"mcm","clk":"987910641","pt":1580472685568,"mc":[{"id":"1.168133553","rc":[{"batb":[[0,1.15,3],[1,1.14,37.62]],"ltp":1.51,"tv":6.72,"id":16325787}]}]}
{"op":"mcm","clk":"987911449","pt":1580472693338,"mc":[{"id":"1.168133553","rc":[{"batb":[[0,1.16,1.99],[1,1.15,3],[2,1.14,37.62]],"ltp":1.51,"tv":6.72,"id":16325787}]}]}
{"op":"mcm","clk":"987912388","pt":1580472701976,"mc":[{"id":"1.168133553","rc":[{"batb":[[0,1.16,4.99],[1,1.14,37.62],[2,1.03,1628.12]],"ltp":1.51,"tv":6.72,"id":16325787}]}]}
{"op":"mcm","clk":"987912507","pt":1580472703086,"mc":[{"id":"1.168133553","rc":[{"batb":[[1,1.03,1628.12],[2,1.01,4105.65]],"ltp":1.51,"tv":6.72,"id":16325787}]}]}
{"op":"mcm","clk":"987913923","pt":1580472715458,"mc":[{"id":"1.168133553","rc":[{"batb":[[0,1.17,3],[1,1.16,1.99],[2,1.03,1628.12]],"ltp":1.51,"tv":6.72,"id":16325787}]}]}
{"op":"mcm","clk":"987915277","pt":1580472728567,"mc":[{"id":"1.168133553","rc":[{"batb":[[0,1.18,36.34],[2,1.04,3]],"ltp":1.51,"tv":6.72,"id":16325787}]}]}
{"op":"mcm","clk":"987916934","pt":1580472744180,"mc":[{"id":"1.168133553","rc":[{"batb":[[0,1.19,3],[1,1.18,36.34],[2,1.16,1.99]],"ltp":1.51,"tv":6.72,"id":16325787}]}]}
{"op":"mcm","clk":"987917939","pt":1580472754016,"mc":[{"id":"1.168133553","rc":[{"batb":[[1,1.16,1.99],[2,1.03,1628.12]],"ltp":1.51,"tv":6.72,"id":16325787}]}]}
{"op":"mcm","clk":"987919030","pt":1580472764433,"mc":[{"id":"1.168133553","rc":[{"batb":[[0,1.16,1.99],[1,1.04,3]],"ltp":1.51,"tv":6.72,"id":16325787}]}]}
{"op":"mcm","clk":"987920484","pt":1580472777875,"mc":[{"id":"1.168133553","rc":[{"batb":[[1,1.05,3]],"ltp":1.51,"tv":6.72,"id":16325787}]}]}
{"op":"mcm","clk":"987920817","pt":1580472780909,"mc":[{"id":"1.168133553","rc":[{"batb":[[0,1.06,1.99]],"ltp":1.51,"tv":6.72,"id":16325787}]}]}
{"op":"mcm","clk":"987921018","pt":1580472782186,"mc":[{"id":"1.168133553","rc":[{"batb":[[2,1.04,6]],"ltp":1.51,"tv":6.72,"id":16325787}]}]}
{"op":"mcm","clk":"987922544","pt":1580472796531,"mc":[{"id":"1.168133553","rc":[{"batb":[[1,1.04,6],[2,1.03,1628.12]],"ltp":1.51,"tv":6.72,"id":16325787}]}]}
{"op":"mcm","clk":"987922560","pt":1580472796590,"mc":[{"id":"1.168133553","rc":[{"batb":[[0,1.06,4.99]],"ltp":1.51,"tv":6.72,"id":16325787}]}]}
{"op":"mcm","clk":"987924421","pt":1580472813504,"mc":[{"id":"1.168133553","rc":[{"batb":[[0,1.07,3],[1,1.06,1.99],[2,1.04,6]],"ltp":1.51,"tv":6.72,"id":16325787}]}]}
{"op":"mcm","clk":"987926146","pt":1580472830543,"mc":[{"id":"1.168133553","rc":[{"batb":[[0,1.06,1.99],[1,1.04,6],[2,1.03,1628.12]],"ltp":1.51,"tv":6.72,"id":16325787}]}]}
{"op":"mcm","clk":"987926222","pt":1580472831326,"mc":[{"id":"1.168133553","rc":[{"batb":[[0,1.07,40.08],[1,1.06,1.99],[2,1.05,3]],"ltp":1.51,"tv":6.72,"id":16325787}]}]}
{"op":"mcm","clk":"987927808","pt":1580472846767,"mc":[{"id":"1.168133553","rc":[{"batb":[[0,1.08,3],[1,1.07,40.08],[2,1.06,1.99]],"ltp":1.51,"tv":6.72,"id":16325787}]}]}
{"op":"mcm","clk":"987928847","pt":1580472857255,"mc":[{"id":"1.168133553","rc":[{"batb":[[1,1.06,1.99],[2,1.04,6]],"ltp":1.51,"tv":6.72,"id":16325787}]}]}
{"op":"mcm","clk":"987929209","pt":1580472861109,"mc":[{"id":"1.168133553","rc":[{"batb":[[0,1.09,1.99],[1,1.08,3]],"ltp":1.51,"tv":6.72,"id":16325787}]}]}
{"op":"mcm","clk":"987929407","pt":1580472862895,"mc":[{"id":"1.168133553","rc":[{"batb":[[0,1.09,4.99],[1,1.04,6],[2,1.03,1628.12]],"ltp":1.51,"tv":6.72,"id":16325787}]}]}
{"op":"mcm","clk":"987929973","pt":1580472868427,"mc":[{"id":"1.168133553","rc":[{"batb":[[1,1.05,10],[2,1.04,6]],"ltp":1.51,"tv":6.72,"id":16325787}]}]}
{"op":"mcm","clk":"987930975","pt":1580472878524,"mc":[{"id":"1.168133553","rc":[{"batb":[[0,1.1,3],[1,1.09,1.99],[2,1.05,10]],"ltp":1.51,"tv":6.72,"id":16325787}]}]}
{"op":"mcm","clk":"987931604","pt":1580472884329,"mc":[{"id":"1.168133553","rc":[{"batb":[[0,1.11,38.64],[1,1.1,3],[2,1.09,1.99]],"ltp":1.51,"tv":6.72,"id":16325787}]}]}
{"op":"mcm","clk":"987932388","pt":1580472892349,"mc":[{"id":"1.168133553","rc":[{"batb":[[0,1.12,3],[1,1.11,38.64]],"ltp":1.51,"tv":6.72,"id":16325787}]}]}
{"op":"mcm","clk":"987933989","pt":1580472909889,"mc":[{"id":"1.168133553","rc":[{"batb":[[1,1.09,1.99],[2,1.05,10]],"ltp":1.51,"tv":6.72,"id":16325787}]}]}
{"op":"mcm","clk":"987935280","pt":1580472923542,"mc":[{"id":"1.168133553","rc":[{"batb":[[0,1.09,1.99],[1,1.05,10],[2,1.04,6]],"ltp":1.51,"tv":6.72,"id":16325787}]}]}
{"op":"mcm","clk":"987935284","pt":1580472923640,"mc":[{"id":"1.168133553","rc":[{"batb":[[1,1.06,3],[2,1.05,10]],"ltp":1.51,"tv":6.72,"id":16325787}]}]}
{"op":"mcm","clk":"987936695","pt":1580472937521,"mc":[{"id":"1.168133553","rc":[{"batb":[[1,1.05,10],[2,1.04,6]],"ltp":1.51,"tv":6.72,"id":16325787}]}]}
{"op":"mcm","clk":"987936706","pt":1580472937626,"mc":[{"id":"1.168133553","rc":[{"batb":[[1,1.07,3],[2,1.05,10]],"ltp":1.51,"tv":6.72,"id":16325787}]}]}
{"op":"mcm","clk":"987938699","pt":1580472958482,"mc":[{"id":"1.168133553","rc":[{"batb":[[1,1.08,10],[2,1.07,3]],"ltp":1.51,"tv":6.72,"id":16325787}]}]}
{"op":"mcm","clk":"987938856","pt":1580472960097,"mc":[{"id":"1.168133553","rc":[{"batb":[[0,1.09,4.99],[2,1.04,6]],"ltp":1.51,"tv":6.72,"id":16325787}]}]}
{"op":"mcm","clk":"987939012","pt":1580472961571,"mc":[{"id":"1.168133553","rc":[{"batb":[[0,1.1,38.98],[1,1.09,4.99],[2,1.08,10]],"ltp":1.51,"tv":6.72,"id":16325787}]}]}
{"op":"mcm","clk":"987940054","pt":1580472972704,"mc":[{"id":"1.168133553","rc":[{"batb":[[0,1.11,3],[1,1.1,38.98],[2,1.09,1.99]],"ltp":1.51,"tv":6.72,"id":16325787}]}]}
{"op":"mcm","clk":"987941609","pt":1580472988209,"mc":[{"id":"1.168133553","rc":[{"batb":[[1,1.09,1.99],[2,1.08,10]],"ltp":1.51,"tv":6.72,"id":16325787}]}]}
{"op":"mcm","clk":"987942417","pt":1580472995697,"mc":[{"id":"1.168133553","rc":[{"batb":[[0,1.09,4.99],[1,1.08,10],[2,1.04,6]],"ltp":1.51,"tv":6.72,"id":16325787}]}]}
{"op":"mcm","clk":"987943723","pt":1580473008023,"mc":[{"id":"1.168133553","rc":[{"batb":[[0,1.1,3],[1,1.09,1.99],[2,1.08,10]],"ltp":1.51,"tv":6.72,"id":16325787}]}]}
{"op":"mcm","clk":"987944281","pt":1580473013128,"mc":[{"id":"1.168133553","rc":[{"batb":[[0,1.11,38.64],[1,1.1,3],[2,1.09,1.99]],"ltp":1.51,"tv":6.72,"id":16325787}]}]}
{"op":"mcm","clk":"987945288","pt":1580473022038,"mc":[{"id":"1.168133553","rc":[{"batb":[[0,1.12,3],[1,1.11,38.64]],"ltp":1.51,"tv":6.72,"id":16325787}]}]}
{"op":"mcm","clk":"987947254","pt":1580473040152,"mc":[{"id":"1.168133553","rc":[{"batb":[[1,1.09,1.99],[2,1.08,10]],"ltp":1.51,"tv":6.72,"id":16325787}]}]}
{"op":"mcm","clk":"987947410","pt":1580473041793,"mc":[{"id":"1.168133553","rc":[{"batb":[[0,1.13,1.99],[1,1.12,3]],"ltp":1.51,"tv":6.72,"id":16325787}]}]}
{"op":"mcm","clk":"987948270","pt":1580473049521,"mc":[{"id":"1.168133553","rc":[{"batb":[[0,1.14,3],[1,1.13,11.99],[2,1.04,6]],"ltp":1.51,"tv":6.72,"id":16325787}]}]}
{"op":"mcm","clk":"987950063","pt":1580473067541,"mc":[{"id":"1.168133553","rc":[{"batb":[[0,1.15,37.29],[1,1.14,3],[2,1.13,11.99]],"ltp":1.51,"tv":6.72,"id":16325787}]}]}
{"op":"mcm","clk":"987950964","pt":1580473076359,"mc":[{"id":"1.168133553","rc":[{"batb":[[0,1.16,3],[1,1.15,37.29]],"ltp":1.51,"tv":6.72,"id":16325787}]}]}
{"op":"mcm","clk":"987952998","pt":1580473094394,"mc":[{"id":"1.168133553","rc":[{"batb":[[1,1.13,11.99],[2,1.03,1628.12]],"ltp":1.51,"tv":6.72,"id":16325787}]}]}
{"op":"mcm","clk":"987954258","pt":1580473106412,"mc":[{"id":"1.168133553","rc":[{"batb":[[0,1.14,3]],"ltp":1.51,"tv":6.72,"id":16325787}]}]}
{"op":"mcm","clk":"987954494","pt":1580473108671,"mc":[{"id":"1.168133553","rc":[{"batb":[[2,1.04,6]],"ltp":1.51,"tv":6.72,"id":16325787}]}]}
{"op":"mcm","clk":"987955862","pt":1580473122091,"mc":[{"id":"1.168133553","rc":[{"batb":[[0,1.15,37.29],[1,1.14,3],[2,1.13,11.99]],"ltp":1.51,"tv":6.72,"id":16325787}]}]}
{"op":"mcm","clk":"987956087","pt":1580473124116,"mc":[{"id":"1.168133553","rc":[{"batb":[[0,1.16,1.99],[1,1.15,37.29],[2,1.14,3]],"ltp":1.51,"tv":6.72,"id":16325787}]}]}
{"op":"mcm","clk":"987957253","pt":1580473135929,"mc":[{"id":"1.168133553","rc":[{"batb":[[1,1.05,3],[2,1.04,10]],"ltp":0.0,"tv":0.0,"id":27227336},{"batb":[[1,1.05,3],[2,1.04,10]],"ltp":0.0,"tv":0.0,"id":21641292}]}]}
{"op":"mcm","clk":"987957401","pt":1580473137512,"mc":[{"id":"1.168133553","rc":[{"batb":[[0,1.16,4.99],[2,1.13,10]],"ltp":1.51,"tv":6.72,"id":16325787}]}]}
{"op":"mcm","clk":"987957530","pt":1580473139147,"mc":[{"id":"1.168133553","rc":[{"batb":[[1,1.06,10],[2,1.05,3]],"ltp":0.0,"tv":0.0,"id":27227336},{"batb":[[1,1.06,10],[2,1.05,3]],"ltp":0.0,"tv":0.0,"id":21641292},{"batb":[[2,1.04,10]],"ltp":1.51,"tv":6.72,"id":16325787}]}]}
{"op":"mcm","clk":"987958271","pt":1580473147512,"mc":[{"id":"1.168133553","rc":[{"batb":[[1,1.04,10],[2,1.03,1628.12]],"ltp":1.51,"tv":6.72,"id":16325787}]}]}
{"op":"mcm","clk":"987958900","pt":1580473154058,"mc":[{"id":"1.168133553","rc":[{"batb":[[0,1.17,3],[1,1.16,1.99],[2,1.04,10]],"ltp":1.51,"tv":6.72,"id":16325787}]}]}
{"op":"mcm","clk":"987960393","pt":1580473169572,"mc":[{"id":"1.168133553","rc":[{"batb":[[0,1.16,1.99],[1,1.05,3]],"ltp":1.51,"tv":6.72,"id":16325787}]}]}
{"op":"mcm","clk":"987961734","pt":1580473183150,"mc":[{"id":"1.168133553","rc":[{"batb":[[1,1.06,3]],"ltp":1.51,"tv":6.72,"id":16325787}]}]}
{"op":"mcm","clk":"987963313","pt":1580473199353,"mc":[{"id":"1.168133553","rc":[{"batb":[[0,1.08,1.99],[1,1.07,3]],"ltp":1.51,"tv":6.72,"id":16325787}]}]}
{"op":"mcm","clk":"987963456","pt":1580473200861,"mc":[{"id":"1.168133553","rc":[{"batb":[[0,1.09,39.35],[1,1.08,1.99],[2,1.07,3]],"ltp":1.51,"tv":6.72,"id":16325787}]}]}
{"op":"mcm","clk":"987964958","pt":1580473215478,"mc":[{"id":"1.168133553","rc":[{"batb":[[2,1.04,10]],"ltp":1.51,"tv":6.72,"id":16325787}]}]}
{"op":"mcm","clk":"987964966","pt":1580473215575,"mc":[{"id":"1.168133553","rc":[{"batb":[[0,1.1,3],[1,1.09,39.35],[2,1.08,1.99]],"ltp":1.51,"tv":6.72,"id":16325787}]}]}
{"op":"mcm","clk":"987966220","pt":1580473227503,"mc":[{"id":"1.168133553","rc":[{"batb":[[1,1.08,1.99],[2,1.04,10]],"ltp":1.51,"tv":6.72,"id":16325787}]}]}
{"op":"mcm","clk":"987966474","pt":1580473229516,"mc":[{"id":"1.168133553","rc":[{"batb":[[2,1.03,1628.12]],"ltp":1.51,"tv":6.72,"id":16325787}]}]}
{"op":"mcm","clk":"987966642","pt":1580473230950,"mc":[{"id":"1.168133553","rc":[{"batb":[[2,1.04,6]],"ltp":1.51,"tv":6.72,"id":16325787}]}]}
{"op":"mcm","clk":"987966785","pt":1580473232218,"mc":[{"id":"1.168133553","rc":[{"batb":[[0,1.08,1.99],[1,1.05,3]],"ltp":1.51,"tv":6.72,"id":16325787}]}]}
{"op":"mcm","clk":"987968423","pt":1580473247231,"mc":[{"id":"1.168133553","rc":[{"batb":[[1,1.06,3]],"ltp":1.51,"tv":6.72,"id":16325787}]}]}
{"op":"mcm","clk":"987970643","pt":1580473268907,"mc":[{"id":"1.168133553","rc":[{"batb":[[1,1.07,3]],"ltp":1.51,"tv":6.72,"id":16325787}]}]}
{"op":"mcm","clk":"987971791","pt":1580473278449,"mc":[{"id":"1.168133553","rc":[{"batb":[[2,1.03,1630.64]],"ltp":0.0,"tv":0.0,"id":27227336},{"batb":[[2,1.03,1663.44]],"ltp":0.0,"tv":0.0,"id":21641292}]}]}
{"op":"mcm","clk":"987971814","pt":1580473278614,"mc":[{"id":"1.168133553","rc":[{"batb":[[1,1.07,3],[2,1.06,10]],"ltp":0.0,"tv":0.0,"id":27227336},{"batb":[[1,1.07,3],[2,1.06,10]],"ltp":0.0,"tv":0.0,"id":21641292},{"batb":[[2,1.05,3]],"ltp":1.51,"tv":6.72,"id":16325787}]}]}
{"op":"mcm","clk":"987972140","pt":1580473281422,"mc":[{"id":"1.168133553","rc":[{"batb":[[0,1.09,39.35],[1,1.08,1.99],[2,1.07,3]],"ltp":1.51,"tv":6.72,"id":16325787}]}]}
{"op":"mcm","clk":"987972771","pt":1580473287143,"mc":[{"id":"1.168133553","rc":[{"batb":[[0,1.1,1.99],[1,1.09,39.35]],"ltp":1.51,"tv":6.72,"id":16325787}]}]}
{"op":"mcm","clk":"987973139","pt":1580473290258,"mc":[{"id":"1.168133553","rc":[{"batb":[[0,1.1,4.99],[2,1.05,3]],"ltp":1.51,"tv":6.72,"id":16325787}]}]}
{"op":"mcm","clk":"987974528","pt":1580473304298,"mc":[{"id":"1.168133553","rc":[{"batb":[[0,1.11,3],[1,1.1,1.99],[2,1.09,39.35]],"ltp":1.51,"tv":6.72,"id":16325787}]}]}
{"op":"mcm","clk":"987974779","pt":1580473307162,"mc":[{"id":"1.168133553","rc":[{"batb":[[0,1.12,38.29],[1,1.11,3],[2,1.1,1.99]],"ltp":1.51,"tv":6.72,"id":16325787}]}]}
{"op":"mcm","clk":"987976131","pt":1580473320227,"mc":[{"id":"1.168133553","rc":[{"batb":[[1,1.08,10],[2,1.07,3]],"ltp":0.0,"tv":0.0,"id":27227336},{"batb":[[1,1.08,10],[2,1.07,3]],"ltp":0.0,"tv":0.0,"id":21641292}]}]}
{"op":"mcm","clk":"987977015","pt":1580473329128,"mc":[{"id":"1.168133553","rc":[{"batb":[[0,1.13,3],[1,1.12,38.29]],"ltp":1.51,"tv":6.72,"id":16325787}]}]}
{"op":"mcm","clk":"987977414","pt":1580473332842,"mc":[{"id":"1.168133553","rc":[{"batb":[[1,1.1,1.99],[2,1.05,3]],"ltp":1.51,"tv":6.72,"id":16325787}]}]}
{"op":"mcm","clk":"987978839","pt":1580473346079,"mc":[{"id":"1.168133553","rc":[{"batb":[[0,1.1,1.99],[1,1.06,3]],"ltp":1.51,"tv":6.72,"id":16325787}]}]}
{"op":"mcm","clk":"987988482","pt":1580473360957,"mc":[{"id":"1.168133553","rc":[{"batb":[[1,1.07,3]],"ltp":1.51,"tv":6.72,"id":16325787}]}]}
{"op":"mcm","clk":"987989388","pt":1580473370787,"mc":[{"id":"1.168133553","rc":[{"batb":[[0,1.08,1.99]],"ltp":1.51,"tv":6.72,"id":16325787}]}]}
{"op":"mcm","clk":"987990023","pt":1580473377219,"mc":[{"id":"1.168133553","rc":[{"batb":[[0,1.08,4.99],[1,1.05,3],[2,1.04,6]],"ltp":1.51,"tv":6.72,"id":16325787}]}]}
{"op":"mcm","clk":"987991286","pt":1580473390099,"mc":[{"id":"1.168133553","rc":[{"batb":[[0,1.09,3],[1,1.08,1.99],[2,1.05,3]],"ltp":1.51,"tv":6.72,"id":16325787}]}]}
{"op":"mcm","clk":"987992635","pt":1580473402543,"mc":[{"id":"1.168133553","rc":[{"batb":[[0,1.08,1.99],[1,1.05,3],[2,1.04,6]],"ltp":1.51,"tv":6.72,"id":16325787}]}]}
{"op":"mcm","clk":"987992649","pt":1580473402646,"mc":[{"id":"1.168133553","rc":[{"batb":[[1,1.06,3],[2,1.05,3]],"ltp":1.51,"tv":6.72,"id":16325787}]}]}
{"op":"mcm","clk":"987993514","pt":1580473410945,"mc":[{"id":"1.168133553","rc":[{"batb":[[1,1.07,10],[2,1.06,3]],"ltp":1.51,"tv":6.72,"id":16325787}]}]}
{"op":"mcm","clk":"987993976","pt":1580473415381,"mc":[{"id":"1.168133553","rc":[{"batb":[[0,1.08,4.99],[2,1.05,3]],"ltp":1.51,"tv":6.72,"id":16325787}]}]}
{"op":"mcm","clk":"987995576","pt":1580473430958,"mc":[{"id":"1.168133553","rc":[{"batb":[[0,1.09,3],[1,1.08,1.99],[2,1.07,10]],"ltp":1.51,"tv":6.72,"id":16325787}]}]}
{"op":"mcm","clk":"987996027","pt":1580473435480,"mc":[{"id":"1.168133553","rc":[{"batb":[[0,1.1,38.98],[1,1.09,3],[2,1.08,1.99]],"ltp":1.51,"tv":6.72,"id":16325787}]}]}
{"op":"mcm","clk":"987996851","pt":1580473444523,"mc":[{"id":"1.168133553","rc":[{"batb":[[0,1.11,3],[1,1.1,38.98]],"ltp":1.51,"tv":6.72,"id":16325787}]}]}
{"op":"mcm","clk":"987998260","pt":1580473458423,"mc":[{"id":"1.168133553","rc":[{"batb":[[2,1.03,1630.64]],"ltp":0.0,"tv":0.0,"id":27227336},{"batb":[[2,1.03,1663.44]],"ltp":0.0,"tv":0.0,"id":21641292}]}]}
{"op":"mcm","clk":"987998462","pt":1580473460524,"mc":[{"id":"1.168133553","rc":[{"batb":[[1,1.08,1.99],[2,1.07,10]],"ltp":1.51,"tv":6.72,"id":16325787}]}]}
{"op":"mcm","clk":"987998745","pt":1580473463042,"mc":[{"id":"1.168133553","rc":[{"batb":[[0,1.12,1.99],[1,1.11,3]],"ltp":1.51,"tv":6.72,"id":16325787}]}]}
{"op":"mcm","clk":"987999638","pt":1580473473529,"mc":[{"id":"1.168133553","rc":[{"batb":[[1,1.07,10],[2,1.04,6]],"ltp":1.51,"tv":6.72,"id":16325787}]}]}
{"op":"mcm","clk":"987999652","pt":1580473473638,"mc":[{"id":"1.168133553","rc":[{"batb":[[0,1.12,4.99]],"ltp":1.51,"tv":6.72,"id":16325787}]}]}
{"op":"mcm","clk":"988001221","pt":1580473490446,"mc":[{"id":"1.168133553","rc":[{"batb":[[0,1.13,3],[1,1.12,1.99],[2,1.07,10]],"ltp":1.51,"tv":6.72,"id":16325787}]}]}
{"op":"mcm","clk":"988002377","pt":1580473502550,"mc":[{"id":"1.168133553","rc":[{"batb":[[1,1.03,1630.64],[2,1.02,1.99]],"ltp":0.0,"tv":0.0,"id":27227336},{"batb":[[1,1.03,1663.44],[2,1.02,1.99]],"ltp":0.0,"tv":0.0,"id":21641292},{"batb":[[2,1.04,6]],"ltp":1.51,"tv":6.72,"id":16325787}]}]}
{"op":"mcm","clk":"988002391","pt":1580473502657,"mc":[{"id":"1.168133553","rc":[{"batb":[[1,1.04,10],[2,1.03,1630.64]],"ltp":0.0,"tv":0.0,"id":27227336},{"batb":[[1,1.04,10],[2,1.03,1663.44]],"ltp":0.0,"tv":0.0,"id":21641292},{"batb":[[0,1.13,13]],"ltp":1.51,"tv":6.72,"id":16325787}]}]}
{"op":"mcm","clk":"988002513","pt":1580473504073,"mc":[{"id":"1.168133553","rc":[{"batb":[[0,1.14,3],[1,1.13,10],[2,1.12,1.99]],"ltp":1.51,"tv":6.72,"id":16325787}]}]}
{"op":"mcm","clk":"988003343","pt":1580473512789,"mc":[{"id":"1.168133553","rc":[{"batb":[[0,1.15,37.29],[1,1.14,3],[2,1.13,10]],"ltp":1.51,"tv":6.72,"id":16325787}]}]}
{"op":"mcm","clk":"988003816","pt":1580473518095,"mc":[{"id":"1.168133553","rc":[{"batb":[[0,1.16,3],[1,1.15,37.29]],"ltp":1.51,"tv":6.72,"id":16325787}]}]}
{"op":"mcm","clk":"988005535","pt":1580473537850,"mc":[{"id":"1.168133553","rc":[{"batb":[[1,1.13,10],[2,1.12,1.99]],"ltp":1.51,"tv":6.72,"id":16325787}]}]}
{"op":"mcm","clk":"988006298","pt":1580473546140,"mc":[{"id":"1.168133553","rc":[{"batb":[[0,1.14,3]],"ltp":1.51,"tv":6.72,"id":16325787}]}]}
{"op":"mcm","clk":"988006569","pt":1580473548837,"mc":[{"id":"1.168133553","rc":[{"batb":[[0,1.15,1.99],[1,1.14,3],[2,1.13,10]],"ltp":1.51,"tv":6.72,"id":16325787}]}]}
{"op":"mcm","clk":"988007953","pt":1580473563317,"mc":[{"id":"1.168133553","rc":[{"batb":[[0,1.15,4.99],[1,1.13,10],[2,1.03,1628.12]],"ltp":1.51,"tv":6.72,"id":16325787}]}]}
{"op":"mcm","clk":"988009044","pt":1580473574956,"mc":[{"id":"1.168133553","rc":[{"batb":[[0,1.16,3],[1,1.15,1.99],[2,1.13,10]],"ltp":1.51,"tv":6.72,"id":16325787}]}]}
{"op":"mcm","clk":"988010137","pt":1580473586234,"mc":[{"id":"1.168133553","rc":[{"batb":[[0,1.15,1.99],[1,1.14,3]],"ltp":1.51,"tv":6.72,"id":16325787}]}]}
{"op":"mcm","clk":"988010503","pt":1580473590057,"mc":[{"id":"1.168133553","rc":[{"batb":[[0,1.16,36.97],[1,1.15,1.99],[2,1.14,3]],"ltp":1.51,"tv":6.72,"id":16325787}]}]}
{"op":"mcm","clk":"988010844","pt":1580473592856,"mc":[{"id":"1.168133553","rc":[{"batb":[[0,1.16,46.97]],"ltp":1.51,"tv":6.72,"id":16325787}]}]}
{"op":"mcm","clk":"988011441","pt":1580473597897,"mc":[{"id":"1.168133553","rc":[{"batb":[[0,1.17,3],[1,1.16,46.97],[2,1.15,1.99]],"ltp":1.51,"tv":6.72,"id":16325787}]}]}
{"op":"mcm","clk":"988013566","pt":1580473617197,"mc":[{"id":"1.168133553","rc":[{"batb":[[0,1.18,36.34],[1,1.17,3],[2,1.16,10]],"ltp":1.51,"tv":6.72,"id":16325787}]}]}
{"op":"mcm","clk":"988014344","pt":1580473624218,"mc":[{"id":"1.168133553","rc":[{"batb":[[0,1.19,3],[1,1.18,36.34]],"ltp":1.51,"tv":6.72,"id":16325787}]}]}
{"op":"mcm","clk":"988014841","pt":1580473628417,"mc":[{"id":"1.168133553","rc":[{"batb":[[0,1.2,1.99],[1,1.19,3],[2,1.18,36.34]],"ltp":1.51,"tv":6.72,"id":16325787}]}]}
{"op":"mcm","clk":"988015871","pt":1580473637742,"mc":[{"id":"1.168133553","rc":[{"batb":[[0,1.2,4.99],[1,1.18,36.34],[2,1.16,10]],"ltp":1.51,"tv":6.72,"id":16325787}]}]}
{"op":"mcm","clk":"988016503","pt":1580473643701,"mc":[{"id":"1.168133553","rc":[{"batb":[[1,1.16,10],[2,1.03,1628.12]],"ltp":1.51,"tv":6.72,"id":16325787}]}]}
{"op":"mcm","clk":"988017548","pt":1580473654283,"mc":[{"id":"1.168133553","rc":[{"batb":[[0,1.21,3],[1,1.2,1.99],[2,1.16,10]],"ltp":1.51,"tv":6.72,"id":16325787}]}]}
{"op":"mcm","clk":"988018841","pt":1580473666510,"mc":[{"id":"1.168133553","rc":[{"batb":[[0,1.2,1.99],[1,1.17,3]],"ltp":1.51,"tv":6.72,"id":16325787}]}]}
{"op":"mcm","clk":"988020078","pt":1580473679229,"mc":[{"id":"1.168133553","rc":[{"batb":[[1,1.18,3]],"ltp":1.51,"tv":6.72,"id":16325787}]}]}
{"op":"mcm","clk":"988020511","pt":1580473683218,"mc":[{"id":"1.168133553","rc":[{"batb":[[2,1.04,10]],"ltp":1.51,"tv":6.72,"id":16325787}]}]}
{"op":"mcm","clk":"988021974","pt":1580473697283,"mc":[{"id":"1.168133553","rc":[{"batb":[[1,1.19,3]],"ltp":1.51,"tv":6.72,"id":16325787}]}]}
{"op":"mcm","clk":"988023293","pt":1580473710818,"mc":[{"id":"1.168133553","rc":[{"batb":[[0,1.19,3],[1,1.04,10],[2,1.03,1628.12]],"ltp":1.51,"tv":6.72,"id":16325787}]}]}
{"op":"mcm","clk":"988023371","pt":1580473711720,"mc":[{"id":"1.168133553","rc":[{"batb":[[0,1.05,3]],"ltp":1.51,"tv":6.72,"id":16325787}]}]}
{"op":"mcm","clk":"988024149","pt":1580473720305,"mc":[{"id":"1.168133553","rc":[{"batb":[[0,1.06,40.46],[1,1.05,3],[2,1.04,10]],"ltp":1.51,"tv":6.72,"id":16325787}]}]}
{"op":"mcm","clk":"988025076","pt":1580473728890,"mc":[{"id":"1.168133553","rc":[{"batb":[[0,1.07,3],[1,1.06,40.46]],"ltp":1.51,"tv":6.72,"id":16325787}]}]}
{"op":"mcm","clk":"988026770","pt":1580473745333,"mc":[{"id":"1.168133553","rc":[{"batb":[[1,1.04,10],[2,1.03,1628.12]],"ltp":1.51,"tv":6.72,"id":16325787}]}]}
{"op":"mcm","clk":"988026850","pt":1580473746017,"mc":[{"id":"1.168133553","rc":[{"batb":[[0,1.05,3]],"ltp":1.51,"tv":6.72,"id":16325787}]}]}
{"op":"mcm","clk":"988029281","pt":1580473771547,"mc":[{"id":"1.168133553","rc":[{"batb":[[0,1.06,40.46],[1,1.05,3],[2,1.04,10]],"ltp":1.51,"tv":6.72,"id":16325787}]}]}
{"op":"mcm","clk":"988029482","pt":1580473773554,"mc":[{"id":"1.168133553","rc":[{"batb":[[0,1.07,13],[1,1.06,40.46],[2,1.03,1628.12]],"ltp":1.51,"tv":6.72,"id":16325787}]}]}
{"op":"mcm","clk":"988030324","pt":1580473782645,"mc":[{"id":"1.168133553","rc":[{"batb":[[2,1.04,6]],"ltp":1.51,"tv":6.72,"id":16325787}]}]}
{"op":"mcm","clk":"988030859","pt":1580473787551,"mc":[{"id":"1.168133553","rc":[{"batb":[[0,1.07,10]],"ltp":1.51,"tv":6.72,"id":16325787}]}]}
{"op":"mcm","clk":"988030865","pt":1580473787656,"mc":[{"id":"1.168133553","rc":[{"batb":[[0,1.08,3],[1,1.07,10],[2,1.06,40.46]],"ltp":1.51,"tv":6.72,"id":16325787}]}]}
{"op":"mcm","clk":"988031726","pt":1580473796451,"mc":[{"id":"1.168133553","rc":[{"batb":[[2,1.04,6]],"ltp":1.51,"tv":6.72,"id":16325787}]}]}
{"op":"mcm","clk":"988031792","pt":1580473796869,"mc":[{"id":"1.168133553","rc":[{"batb":[[0,1.09,39.35],[1,1.08,3],[2,1.07,10]],"ltp":1.51,"tv":6.72,"id":16325787}]}]}
{"op":"mcm","clk":"988031870","pt":1580473797775,"mc":[{"id":"1.168133553","rc":[{"batb":[[0,1.1,1.99],[1,1.09,39.35],[2,1.08,3]],"ltp":1.51,"tv":6.72,"id":16325787}]}]}
{"op":"mcm","clk":"988032538","pt":1580473804356,"mc":[{"id":"1.168133553","rc":[{"batb":[[0,1.1,4.99],[2,1.07,10]],"ltp":1.51,"tv":6.72,"id":16325787}]}]}
{"op":"mcm","clk":"988033881","pt":1580473817884,"mc":[{"id":"1.168133553","rc":[{"batb":[[0,1.11,3],[1,1.1,1.99],[2,1.09,39.35]],"ltp":1.51,"tv":6.72,"id":16325787}]}]}
{"op":"mcm","clk":"988034355","pt":1580473822392,"mc":[{"id":"1.168133553","rc":[{"batb":[[2,1.07,10]],"ltp":1.51,"tv":6.72,"id":16325787}]}]}
{"op":"mcm","clk":"988034372","pt":1580473822709,"mc":[{"id":"1.168133553","rc":[{"batb":[[0,1.12,38.29],[1,1.11,3],[2,1.1,1.99]],"ltp":1.51,"tv":6.72,"id":16325787}]}]}
{"op":"mcm","clk":"988035350","pt":1580473832030,"mc":[{"id":"1.168133553","rc":[{"batb":[[0,1.13,3],[1,1.12,38.29]],"ltp":1.51,"tv":6.72,"id":16325787}]}]}
{"op":"mcm","clk":"988037127","pt":1580473849423,"mc":[{"id":"1.168133553","rc":[{"batb":[[0,1.14,37.62],[1,1.13,3]],"ltp":1.51,"tv":6.72,"id":16325787}]}]}
{"op":"mcm","clk":"988038677","pt":1580473863634,"mc":[{"id":"1.168133553","rc":[{"batb":[[2,1.11,10]],"ltp":1.51,"tv":6.72,"id":16325787}]}]}
{"op":"mcm","clk":"988039509","pt":1580473869823,"mc":[{"id":"1.168133553","rc":[{"batb":[[0,1.15,3],[1,1.14,37.62]],"ltp":1.51,"tv":6.72,"id":16325787}]}]}
{"op":"mcm","clk":"988040119","pt":1580473875831,"mc":[{"id":"1.168133553","rc":[{"batb":[[1,1.11,10],[2,1.1,1.99]],"ltp":1.51,"tv":6.72,"id":16325787}]}]}
{"op":"mcm","clk":"988041196","pt":1580473884406,"mc":[{"id":"1.168133553","rc":[{"batb":[[0,1.12,3]],"ltp":1.51,"tv":6.72,"id":16325787}]}]}
{"op":"mcm","clk":"988041950","pt":1580473892317,"mc":[{"id":"1.168133553","rc":[{"batb":[[0,1.13,1.99],[1,1.12,3],[2,1.11,10]],"ltp":1.51,"tv":6.72,"id":16325787}]}]}
{"op":"mcm","clk":"988042647","pt":1580473899509,"mc":[{"id":"1.168133553","rc":[{"batb":[[0,1.13,4.99],[1,1.11,10],[2,1.04,6]],"ltp":1.51,"tv":6.72,"id":16325787}]}]}
{"op":"mcm","clk":"988042778","pt":1580473900919,"mc":[{"id":"1.168133553","rc":[{"batb":[[1,1.05,3],[2,1.04,10]],"ltp":0.0,"tv":0.0,"id":27227336},{"batb":[[1,1.05,3],[2,1.04,10]],"ltp":0.0,"tv":0.0,"id":21641292},{"batb":[[1,1.12,3],[2,1.11,10]],"ltp":1.51,"tv":6.72,"id":16325787}]}]}
{"op":"mcm","clk":"988042884","pt":1580473901932,"mc":[{"id":"1.168133553","rc":[{"batb":[[0,1.14,37.62],[1,1.13,4.99],[2,1.12,3]],"ltp":1.51,"tv":6.72,"id":16325787}]}]}
{"op":"mcm","clk":"988043807","pt":1580473909457,"mc":[{"id":"1.168133553","rc":[{"batb":[[0,1.15,3],[1,1.14,37.62],[2,1.13,1.99]],"ltp":1.51,"tv":6.72,"id":16325787}]}]}
{"op":"mcm","clk":"988046145","pt":1580473927789,"mc":[{"id":"1.168133553","rc":[{"batb":[[1,1.13,1.99],[2,1.12,3]],"ltp":1.51,"tv":6.72,"id":16325787}]}]}
{"op":"mcm","clk":"988047202","pt":1580473936468,"mc":[{"id":"1.168133553","rc":[{"batb":[[0,1.13,1.99],[1,1.12,3],[2,1.11,10]],"ltp":1.51,"tv":6.72,"id":16325787}]}]}
{"op":"mcm","clk":"988047217","pt":1580473936576,"mc":[{"id":"1.168133553","rc":[{"batb":[[0,1.13,4.99]],"ltp":1.51,"tv":6.72,"id":16325787}]}]}
{"op":"mcm","clk":"988049305","pt":1580473953525,"mc":[{"id":"1.168133553","rc":[{"batb":[[0,1.14,37.62],[1,1.13,4.99],[2,1.12,3]],"ltp":1.51,"tv":6.72,"id":16325787}]}]}
{"op":"mcm","clk":"988049336","pt":1580473953732,"mc":[{"id":"1.168133553","rc":[{"batb":[[0,1.14,40.62],[1,1.13,1.99]],"ltp":1.51,"tv":6.72,"id":16325787}]}]}
{"op":"mcm","clk":"988049577","pt":1580473955605,"mc":[{"id":"1.168133553","rc":[{"batb":[[2,1.03,1630.64]],"ltp":0.0,"tv":0.0,"id":27227336},{"batb":[[2,1.03,1663.44]],"ltp":0.0,"tv":0.0,"id":21641292}]}]}
{"op":"mcm","clk":"988050971","pt":1580473968044,"mc":[{"id":"1.168133553","rc":[{"batb":[[0,1.15,3],[1,1.14,37.62],[2,1.13,1.99]],"ltp":1.51,"tv":6.72,"id":16325787}]}]}
{"op":"mcm","clk":"988051862","pt":1580473976830,"mc":[{"id":"1.168133553","rc":[{"batb":[[0,1.16,1.99],[1,1.15,3],[2,1.14,37.62]],"ltp":1.51,"tv":6.72,"id":16325787}]}]}
{"op":"mcm","clk":"988052049","pt":1580473978562,"mc":[{"id":"1.168133553","rc":[{"batb":[[0,1.17,36.65],[1,1.16,1.99],[2,1.15,3]],"ltp":1.51,"tv":6.72,"id":16325787}]}]}
{"op":"mcm","clk":"988052612","pt":1580473983548,"mc":[{"id":"1.168133553","rc":[{"batb":[[2,1.12,3]],"ltp":1.51,"tv":6.72,"id":16325787}]}]}
{"op":"mcm","clk":"988052621","pt":1580473983651,"mc":[{"id":"1.168133553","rc":[{"batb":[[0,1.18,3],[1,1.17,36.65],[2,1.16,1.99]],"ltp":1.51,"tv":6.72,"id":16325787}]}]}
{"op":"mcm","clk":"988054647","pt":1580474004204,"mc":[{"id":"1.168133553","rc":[{"batb":[[1,1.16,1.99],[2,1.12,3]],"ltp":1.51,"tv":6.72,"id":16325787}]}]}
{"op":"mcm","clk":"988055655","pt":1580474014215,"mc":[{"id":"1.168133553","rc":[{"batb":[[0,1.16,1.99],[1,1.13,3]],"ltp":1.51,"tv":6.72,"id":16325787}]}]}
{"op":"mcm","clk":"988056999","pt":1580474028331,"mc":[{"id":"1.168133553","rc":[{"batb":[[1,1.04,3]],"ltp":0.0,"tv":0.0,"id":27227336},{"batb":[[1,1.04,3]],"ltp":0.0,"tv":0.0,"id":21641292},{"batb":[[2,1.04,3]],"ltp":1.51,"tv":6.72,"id":16325787}]}]}
{"op":"mcm","clk":"988057427","pt":1580474032132,"mc":[{"id":"1.168133553","rc":[{"batb":[[1,1.14,3]],"ltp":1.51,"tv":6.72,"id":16325787}]}]}
{"op":"mcm","clk":"988059071","pt":1580474047157,"mc":[{"id":"1.168133553","rc":[{"batb":[[1,1.15,3]],"ltp":1.51,"tv":6.72,"id":16325787}]}]}
{"op":"mcm","clk":"988059931","pt":1580474054985,"mc":[{"id":"1.168133553","rc":[{"batb":[[0,1.17,36.65],[1,1.16,1.99],[2,1.15,3]],"ltp":1.51,"tv":6.72,"id":16325787}]}]}
{"op":"mcm","clk":"988060569","pt":1580474060092,"mc":[{"id":"1.168133553","rc":[{"batb":[[0,1.18,1.99],[1,1.17,36.65]],"ltp":1.51,"tv":6.72,"id":16325787}]}]}
{"op":"mcm","clk":"988061001","pt":1580474063791,"mc":[{"id":"1.168133553","rc":[{"batb":[[0,1.18,4.99],[2,1.04,3]],"ltp":1.51,"tv":6.72,"id":16325787}]}]}
{"op":"mcm","clk":"988062564","pt":1580474077727,"mc":[{"id":"1.168133553","rc":[{"batb":[[0,1.19,3],[1,1.18,1.99],[2,1.17,36.65]],"ltp":1.51,"tv":6.72,"id":16325787}]}]}
{"op":"mcm","clk":"988062846","pt":1580474080511,"mc":[{"id":"1.168133553","rc":[{"batb":[[0,1.2,35.74],[1,1.19,3],[2,1.18,1.99]],"ltp":1.51,"tv":6.72,"id":16325787}]}]}
{"op":"mcm","clk":"988063876","pt":1580474091324,"mc":[{"id":"1.168133553","rc":[{"batb":[[0,1.21,3],[1,1.2,35.74]],"ltp":1.51,"tv":6.72,"id":16325787}]}]}
{"op":"mcm","clk":"988065676","pt":1580474108037,"mc":[{"id":"1.168133553","rc":[{"batb":[[1,1.18,1.99],[2,1.04,3]],"ltp":1.51,"tv":6.72,"id":16325787}]}]}
{"op":"mcm","clk":"988067021","pt":1580474121166,"mc":[{"id":"1.168133553","rc":[{"batb":[[0,1.18,1.99],[1,1.05,3]],"ltp":1.51,"tv":6.72,"id":16325787}]}]}
{"op":"mcm","clk":"988068518","pt":1580474136263,"mc":[{"id":"1.168133553","rc":[{"batb":[[1,1.06,3]],"ltp":1.51,"tv":6.72,"id":16325787}]}]}
{"op":"mcm","clk":"988068801","pt":1580474139374,"mc":[{"id":"1.168133553","rc":[{"batb":[[1,1.05,10],[2,1.04,3]],"ltp":0.0,"tv":0.0,"id":27227336},{"batb":[[1,1.05,10],[2,1.04,3]],"ltp":0.0,"tv":0.0,"id":21641292},{"batb":[[1,1.07,10],[2,1.06,3]],"ltp":1.51,"tv":6.72,"id":16325787}]}]}
{"op":"mcm","clk":"988069257","pt":1580474143771,"mc":[{"id":"1.168133553","rc":[{"batb":[[0,1.08,1.99]],"ltp":1.51,"tv":6.72,"id":16325787}]}]}
{"op":"mcm","clk":"988069969","pt":1580474151084,"mc":[{"id":"1.168133553","rc":[{"batb":[[0,1.08,4.99],[2,1.04,3]],"ltp":1.51,"tv":6.72,"id":16325787}]}]}
{"op":"mcm","clk":"988070655","pt":1580474158630,"mc":[{"id":"1.168133553","rc":[{"batb":[[0,1.09,39.35],[1,1.08,4.99],[2,1.07,10]],"ltp":1.51,"tv":6.72,"id":16325787}]}]}
{"op":"mcm","clk":"988071177","pt":1580474164530,"mc":[{"id":"1.168133553","rc":[{"batb":[[1,1.08,1.99]],"ltp":1.51,"tv":6.72,"id":16325787}]}]}
{"op":"mcm","clk":"988071183","pt":1580474164636,"mc":[{"id":"1.168133553","rc":[{"batb":[[0,1.1,3],[1,1.09,39.35],[2,1.08,1.99]],"ltp":1.51,"tv":6.72,"id":16325787}]}]}
{"op":"mcm","clk":"988071941","pt":1580474172532,"mc":[{"id":"1.168133553","rc":[{"batb":[[2,1.03,1630.64]],"ltp":0.0,"tv":0.0,"id":27227336},{"batb":[[2,1.03,1663.44]],"ltp":0.0,"tv":0.0,"id":21641292}]}]}
{"op":"mcm","clk":"988071954","pt":1580474172630,"mc":[{"id":"1.168133553","rc":[{"batb":[[1,1.06,3],[2,1.05,10]],"ltp":0.0,"tv":0.0,"id":27227336},{"batb":[[1,1.06,3],[2,1.05,10]],"ltp":0.0,"tv":0.0,"id":21641292}]}]}
{"op":"mcm","clk":"988073394","pt":1580474185759,"mc":[{"id":"1.168133553","rc":[{"batb":[[1,1.08,1.99],[2,1.07,10]],"ltp":1.51,"tv":6.72,"id":16325787}]}]}
{"op":"mcm","clk":"988074302","pt":1580474193972,"mc":[{"id":"1.168133553","rc":[{"batb":[[0,1.08,4.99],[1,1.07,10],[2,1.04,6]],"ltp":1.51,"tv":6.72,"id":16325787}]}]}
{"op":"mcm","clk":"988075741","pt":1580474206991,"mc":[{"id":"1.168133553","rc":[{"batb":[[0,1.09,3],[1,1.08,1.99],[2,1.07,10]],"ltp":1.51,"tv":6.72,"id":16325787}]}]}
{"op":"mcm","clk":"988076243","pt":1580474211292,"mc":[{"id":"1.168133553","rc":[{"batb":[[0,1.1,38.98],[1,1.09,3],[2,1.08,1.99]],"ltp":1.51,"tv":6.72,"id":16325787}]}]}
{"op":"mcm","clk":"988077374","pt":1580474222718,"mc":[{"id":"1.168133553","rc":[{"batb":[[0,1.11,3],[1,1.1,38.98]],"ltp":1.51,"tv":6.72,"id":16325787}]}]}
{"op":"mcm","clk":"988077975","pt":1580474228933,"mc":[{"id":"1.168133553","rc":[{"batb":[[0,1.12,1.99],[1,1.11,3],[2,1.1,38.98]],"ltp":1.51,"tv":6.72,"id":16325787}]}]}
{"op":"mcm","clk":"988078071","pt":1580474230240,"mc":[{"id":"1.168133553","rc":[{"batb":[[1,1.07,10],[2,1.06,3]],"ltp":0.0,"tv":0.0,"id":27227336},{"batb":[[1,1.07,10],[2,1.06,3]],"ltp":0.0,"tv":0.0,"id":21641292},{"batb":[[0,1.12,11.99]],"ltp":1.51,"tv":6.72,"id":16325787}]}]}
{"op":"mcm","clk":"988078770","pt":1580474237210,"mc":[{"id":"1.168133553","rc":[{"batb":[[0,1.13,37.95],[1,1.12,11.99],[2,1.11,3]],"ltp":1.51,"tv":6.72,"id":16325787}]}]}
{"op":"mcm","clk":"988079021","pt":1580474239931,"mc":[{"id":"1.168133553","rc":[{"batb":[[0,1.14,3],[1,1.13,37.95],[2,1.12,11.99]],"ltp":1.51,"tv":6.72,"id":16325787}]}]}
{"op":"mcm","clk":"988089422","pt":1580474262323,"mc":[{"id":"1.168133553","rc":[{"batb":[[1,1.08,3],[2,1.07,10]],"ltp":0.0,"tv":0.0,"id":27227336},{"batb":[[1,1.08,3],[2,1.07,10]],"ltp":0.0,"tv":0.0,"id":21641292}]}]}
{"op":"mcm","clk":"988089463","pt":1580474262741,"mc":[{"id":"1.168133553","rc":[{"batb":[[1,1.12,11.99],[2,1.04,6]],"ltp":1.51,"tv":6.72,"id":16325787}]}]}
{"op":"mcm","clk":"988090102","pt":1580474268811,"mc":[{"id":"1.168133553","rc":[{"batb":[[0,1.13,3]],"ltp":1.51,"tv":6.72,"id":16325787}]}]}
{"op":"mcm","clk":"988092015","pt":1580474288055,"mc":[{"id":"1.168133553","rc":[{"batb":[[0,1.14,37.62],[1,1.13,3],[2,1.12,11.99]],"ltp":1.51,"tv":6.72,"id":16325787}]}]}
{"op":"mcm","clk":"988093150","pt":1580474300994,"mc":[{"id":"1.168133553","rc":[{"batb":[[0,1.15,3],[1,1.14,37.62]],"ltp":1.51,"tv":6.72,"id":16325787}]}]}
{"op":"mcm","clk":"988094290","pt":1580474313617,"mc":[{"id":"1.168133553","rc":[{"batb":[[1,1.12,11.99],[2,1.04,6]],"ltp":1.51,"tv":6.72,"id":16325787}]}]}
{"op":"mcm","clk":"988094548","pt":1580474316029,"mc":[{"id":"1.168133553","rc":[{"batb":[[0,1.16,1.99],[1,1.15,3],[2,1.12,10]],"ltp":1.51,"tv":6.72,"id":16325787}]}]}
{"op":"mcm","clk":"988095036","pt":1580474320536,"mc":[{"id":"1.168133553","rc":[{"batb":[[1,1.12,10],[2,1.04,6]],"ltp":1.51,"tv":6.72,"id":16325787}]}]}
{"op":"mcm","clk":"988095100","pt":1580474321224,"mc":[{"id":"1.168133553","rc":[{"batb":[[1,1.09,10],[2,1.08,3]],"ltp":0.0,"tv":0.0,"id":27227336},{"batb":[[1,1.09,10],[2,1.08,3]],"ltp":0.0,"tv":0.0,"id":21641292},{"batb":[[0,1.16,4.99],[1,1.05,10],[2,1.03,1628.12]],"ltp":1.51,"tv":6.72,"id":16325787}]}]}
{"op":"mcm","clk":"988096820","pt":1580474339129,"mc":[{"id":"1.168133553","rc":[{"batb":[[0,1.17,3],[1,1.16,1.99],[2,1.05,10]],"ltp":1.51,"tv":6.72,"id":16325787}]}]}
{"op":"mcm","clk":"988096878","pt":1580474339757,"mc":[{"id":"1.168133553","rc":[{"batb":[[0,1.18,36.34],[1,1.17,3],[2,1.16,1.99]],"ltp":1.51,"tv":6.72,"id":16325787}]}]}
{"op":"mcm","clk":"988098188","pt":1580474352741,"mc":[{"id":"1.168133553","rc":[{"batb":[[0,1.19,3],[1,1.18,36.34]],"ltp":1.51,"tv":6.72,"id":16325787}]}]}
{"op":"mcm","clk":"988098502","pt":1580474356302,"mc":[{"id":"1.168133553","rc":[{"batb":[[2,1.03,1630.64]],"ltp":0.0,"tv":0.0,"id":27227336},{"batb":[[2,1.03,1663.44]],"ltp":0.0,"tv":0.0,"id":21641292}]}]}
{"op":"mcm","clk":"988099642","pt":1580474367209,"mc":[{"id":"1.168133553","rc":[{"batb":[[1,1.16,1.99],[2,1.05,10]],"ltp":1.51,"tv":6.72,"id":16325787}]}]}
{"op":"mcm","clk":"988099956","pt":1580474370023,"mc":[{"id":"1.168133553","rc":[{"batb":[[0,1.16,1.99],[1,1.06,3]],"ltp":1.51,"tv":6.72,"id":16325787}]}]}
{"op":"mcm","clk":"988101652","pt":1580474387135,"mc":[{"id":"1.168133553","rc":[{"batb":[[1,1.07,3]],"ltp":1.51,"tv":6.72,"id":16325787}]}]}
{"op":"mcm","clk":"988102458","pt":1580474394775,"mc":[{"id":"1.168133553","rc":[{"batb":[[0,1.08,1.99]],"ltp":1.51,"tv":6.72,"id":16325787}]}]}
{"op":"mcm","clk":"988103435","pt":1580474403484,"mc":[{"id":"1.168133553","rc":[{"batb":[[1,1.05,10],[2,1.04,6]],"ltp":1.51,"tv":6.72,"id":16325787}]}]}
{"op":"mcm","clk":"988103447","pt":1580474403584,"mc":[{"id":"1.168133553","rc":[{"batb":[[0,1.08,4.99]],"ltp":1.51,"tv":6.72,"id":16325787}]}]}
{"op":"mcm","clk":"988104342","pt":1580474411463,"mc":[{"id":"1.168133553","rc":[{"batb":[[1,1.03,1630.64],[2,1.02,1.99]],"ltp":0.0,"tv":0.0,"id":27227336},{"batb":[[1,1.03,1663.44],[2,1.02,1.99]],"ltp":0.0,"tv":0.0,"id":21641292}]}]}
{"op":"mcm","clk":"988104624","pt":1580474414338,"mc":[{"id":"1.168133553","rc":[{"batb":[[0,1.09,3],[1,1.08,1.99],[2,1.05,10]],"ltp":1.51,"tv":6.72,"id":16325787}]}]}
{"op":"mcm","clk":"988105035","pt":1580474418234,"mc":[{"id":"1.168133553","rc":[{"batb":[[0,1.1,38.98],[1,1.09,3],[2,1.08,1.99]],"ltp":1.51,"tv":6.72,"id":16325787}]}]}
{"op":"mcm","clk":"988105724","pt":1580474425561,"mc":[{"id":"1.168133553","rc":[{"batb":[[0,1.11,3],[1,1.1,38.98]],"ltp":1.51,"tv":6.72,"id":16325787}]}]}
{"op":"mcm","clk":"988107625","pt":1580474444402,"mc":[{"id":"1.168133553","rc":[{"batb":[[1,1.08,1.99],[2,1.05,10]],"ltp":1.51,"tv":6.72,"id":16325787}]}]}
{"op":"mcm","clk":"988108319","pt":1580474451490,"mc":[{"id":"1.168133553","rc":[{"batb":[[0,1.08,1.99],[1,1.05,10],[2,1.04,6]],"ltp":1.51,"tv":6.72,"id":16325787}]}]}
{"op":"mcm","clk":"988108325","pt":1580474451603,"mc":[{"id":"1.168133553","rc":[{"batb":[[1,1.06,3],[2,1.05,10]],"ltp":1.51,"tv":6.72,"id":16325787}]}]}
{"op":"mcm","clk":"988110019","pt":1580474467531,"mc":[{"id":"1.168133553","rc":[{"batb":[[1,1.05,10],[2,1.04,6]],"ltp":1.51,"tv":6.72,"id":16325787}]}]}
{"op":"mcm","clk":"988110037","pt":1580474467633,"mc":[{"id":"1.168133553","rc":[{"batb":[[1,1.07,3],[2,1.05,10]],"ltp":1.51,"tv":6.72,"id":16325787}]}]}
{"op":"mcm","clk":"988110369","pt":1580474470458,"mc":[{"id":"1.168133553","rc":[{"batb":[[0,1.09,39.35],[1,1.08,1.99],[2,1.07,3]],"ltp":1.51,"tv":6.72,"id":16325787}]}]}
{"op":"mcm","clk":"988111455","pt":1580474480572,"mc":[{"id":"1.168133553","rc":[{"batb":[[0,1.1,3],[1,1.09,39.35],[2,1.08,1.99]],"ltp":1.51,"tv":6.72,"id":16325787}]}]}
{"op":"mcm","clk":"988112806","pt":1580474492883,"mc":[{"id":"1.168133553","rc":[{"batb":[[0,1.11,1.99],[1,1.1,3],[2,1.09,39.35]],"ltp":1.51,"tv":6.72,"id":16325787}]}]}
{"op":"mcm","clk":"988113304","pt":1580474497457,"mc":[{"id":"1.168133553","rc":[{"batb":[[2,1.05,10]],"ltp":1.51,"tv":6.72,"id":16325787}]}]}
{"op":"mcm","clk":"988113344","pt":1580474497985,"mc":[{"id":"1.168133553","rc":[{"batb":[[0,1.12,38.29],[1,1.11,4.99]],"ltp":1.51,"tv":6.72,"id":16325787}]}]}
{"op":"mcm","clk":"988113768","pt":1580474501889,"mc":[{"id":"1.168133553","rc":[{"batb":[[0,1.13,10],[1,1.12,38.29],[2,1.11,4.99]],"ltp":1.51,"tv":6.72,"id":16325787}]}]}
{"op":"mcm","clk":"988114910","pt":1580474512113,"mc":[{"id":"1.168133553","rc":[{"batb":[[0,1.14,3],[1,1.13,10],[2,1.12,38.29]],"ltp":1.51,"tv":6.72,"id":16325787}]}]}
{"op":"mcm","clk":"988116081","pt":1580474523152,"mc":[{"id":"1.168133553","rc":[{"batb":[[0,1.15,37.29],[1,1.14,3],[2,1.13,10]],"ltp":1.51,"tv":6.72,"id":16325787}]}]}
{"op":"mcm","clk":"988116419","pt":1580474526165,"mc":[{"id":"1.168133553","rc":[{"batb":[[0,1.16,3],[1,1.15,37.29]],"ltp":1.51,"tv":6.72,"id":16325787}]}]}
{"op":"mcm","clk":"988118871","pt":1580474548164,"mc":[{"id":"1.168133553","rc":[{"batb":[[1,1.13,10],[2,1.11,1.99]],"ltp":1.51,"tv":6.72,"id":16325787}]}]}
{"op":"mcm","clk":"988119532","pt":1580474554218,"mc":[{"id":"1.168133553","rc":[{"batb":[[0,1.14,3]],"ltp":1.51,"tv":6.72,"id":16325787}]}]}
{"op":"mcm","clk":"988121245","pt":1580474570220,"mc":[{"id":"1.168133553","rc":[{"batb":[[0,1.15,1.99],[1,1.14,3],[2,1.13,10]],"ltp":1.51,"tv":6.72,"id":16325787}]}]}
{"op":"mcm","clk":"988121707","pt":1580474574945,"mc":[{"id":"1.168133553","rc":[{"batb":[[0,1.16,36.97],[1,1.15,1.99],[2,1.14,3]],"ltp":1.51,"tv":6.72,"id":16325787}]}]}
{"op":"mcm","clk":"988122228","pt":1580474579744,"mc":[{"id":"1.168133553","rc":[{"batb":[[1,1.04,3],[2,1.03,1630.64]],"ltp":0.0,"tv":0.0,"id":27227336},{"batb":[[1,1.04,3],[2,1.03,1663.44]],"ltp":0.0,"tv":0.0,"id":21641292}]}]}
{"op":"mcm","clk":"988122690","pt":1580474583747,"mc":[{"id":"1.168133553","rc":[{"batb":[[0,1.17,3],[1,1.16,36.97],[2,1.15,1.99]],"ltp":1.51,"tv":6.72,"id":16325787}]}]}
{"op":"mcm","clk":"988123628","pt":1580474592161,"mc":[{"id":"1.168133553","rc":[{"batb":[[1,1.05,10],[2,1.04,3]],"ltp":0.0,"tv":0.0,"id":27227336},{"batb":[[1,1.05,10],[2,1.04,3]],"ltp":0.0,"tv":0.0,"id":21641292},{"batb":[[1,1.16,46.97]],"ltp":1.51,"tv":6.72,"id":16325787}]}]}
{"op":"mcm","clk":"988124708","pt":1580474601492,"mc":[{"id":"1.168133553","rc":[{"batb":[[0,1.18,36.34],[1,1.17,3],[2,1.16,10]],"ltp":1.51,"tv":6.72,"id":16325787}]}]}
{"op":"mcm","clk":"988126555","pt":1580474616352,"mc":[{"id":"1.168133553","rc":[{"batb":[[0,1.19,3],[1,1.18,36.34]],"ltp":1.51,"tv":6.72,"id":16325787}]}]}
{"op":"mcm","clk":"988127822","pt":1580474627583,"mc":[{"id":"1.168133553","rc":[{"batb":[[1,1.16,10],[2,1.15,1.99]],"ltp":1.51,"tv":6.72,"id":16325787}]}]}
{"op":"mcm","clk":"988128996","pt":1580474638429,"mc":[{"id":"1.168133553","rc":[{"batb":[[0,1.17,3]],"ltp":1.51,"tv":6.72,"id":16325787}]}]}
{"op":"mcm","clk":"988130319","pt":1580474650047,"mc":[{"id":"1.168133553","rc":[{"batb":[[0,1.18,1.99],[1,1.17,3],[2,1.16,10]],"ltp":1.51,"tv":6.72,"id":16325787}]}]}
{"op":"mcm","clk":"988130921","pt":1580474655045,"mc":[{"id":"1.168133553","rc":[{"batb":[[0,1.19,36.04],[1,1.18,1.99],[2,1.17,3]],"ltp":1.51,"tv":6.72,"id":16325787}]}]}
{"op":"mcm","clk":"988131189","pt":1580474657252,"mc":[{"id":"1.168133553","rc":[{"batb":[[0,1.2,3],[1,1.19,36.04],[2,1.18,1.99]],"ltp":1.51,"tv":6.72,"id":16325787}]}]}
{"op":"mcm","clk":"988132510","pt":1580474669038,"mc":[{"id":"1.168133553","rc":[{"batb":[[1,1.06,3],[2,1.05,10]],"ltp":0.0,"tv":0.0,"id":27227336},{"batb":[[1,1.06,3],[2,1.05,10]],"ltp":0.0,"tv":0.0,"id":21641292}]}]}
{"op":"mcm","clk":"988133947","pt":1580474682380,"mc":[{"id":"1.168133553","rc":[{"batb":[[2,1.03,1630.64]],"ltp":0.0,"tv":0.0,"id":27227336},{"batb":[[2,1.03,1663.44]],"ltp":0.0,"tv":0.0,"id":21641292},{"batb":[[1,1.18,1.99],[2,1.03,1628.12]],"ltp":1.51,"tv":6.72,"id":16325787}]}]}
{"op":"mcm","clk":"988134872","pt":1580474691404,"mc":[{"id":"1.168133553","rc":[{"batb":[[0,1.18,1.99],[1,1.04,3]],"ltp":1.51,"tv":6.72,"id":16325787}]}]}
{"op":"mcm","clk":"988136849","pt":1580474709145,"mc":[{"id":"1.168133553","rc":[{"batb":[[1,1.05,3]],"ltp":1.51,"tv":6.72,"id":16325787}]}]}
{"op":"mcm","clk":"988139106","pt":1580474729469,"mc":[{"id":"1.168133553","rc":[{"batb":[[0,1.06,1.99],[1,1.03,1628.12],[2,1.01,4105.65]],"ltp":1.51,"tv":6.72,"id":16325787}]}]}
{"op":"mcm","clk":"988139122","pt":1580474729581,"mc":[{"id":"1.168133553","rc":[{"batb":[[0,1.06,4.99]],"ltp":1.51,"tv":6.72,"id":16325787}]}]}
{"op":"mcm","clk":"988139879","pt":1580474737063,"mc":[{"id":"1.168133553","rc":[{"batb":[[1,1.04,6],[2,1.03,1628.12]],"ltp":1.51,"tv":6.72,"id":16325787}]}]}
{"op":"mcm","clk":"988141182","pt":1580474748904,"mc":[{"id":"1.168133553","rc":[{"batb":[[0,1.07,3],[1,1.06,1.99],[2,1.04,6]],"ltp":1.51,"tv":6.72,"id":16325787}]}]}
{"op":"mcm","clk":"988142651","pt":1580474762728,"mc":[{"id":"1.168133553","rc":[{"batb":[[0,1.08,39.71],[1,1.07,3],[2,1.06,1.99]],"ltp":1.51,"tv":6.72,"id":16325787}]}]}
{"op":"mcm","clk":"988142884","pt":1580474765108,"mc":[{"id":"1.168133553","rc":[{"batb":[[0,1.09,3],[1,1.08,39.71]],"ltp":1.51,"tv":6.72,"id":16325787}]}]}
{"op":"mcm","clk":"988145172","pt":1580474785941,"mc":[{"id":"1.168133553","rc":[{"batb":[[1,1.03,1630.64],[2,1.02,1.99]],"ltp":0.0,"tv":0.0,"id":27227336},{"batb":[[1,1.03,1663.44],[2,1.02,1.99]],"ltp":0.0,"tv":0.0,"id":21641292}]}]}
{"op":"mcm","clk":"988145352","pt":1580474788147,"mc":[{"id":"1.168133553","rc":[{"batb":[[1,1.06,1.99],[2,1.04,6]],"ltp":1.51,"tv":6.72,"id":16325787}]}]}
{"op":"mcm","clk":"988145628","pt":1580474791395,"mc":[{"id":"1.168133553","rc":[{"batb":[[0,1.06,1.99],[1,1.05,3]],"ltp":1.51,"tv":6.72,"id":16325787}]}]}
{"op":"mcm","clk":"988146878","pt":1580474805484,"mc":[{"id":"1.168133553","rc":[{"batb":[[1,1.04,6],[2,1.03,1628.12]],"ltp":1.51,"tv":6.72,"id":16325787}]}]}
{"op":"mcm","clk":"988146889","pt":1580474805590,"mc":[{"id":"1.168133553","rc":[{"batb":[[0,1.06,4.99]],"ltp":1.51,"tv":6.72,"id":16325787}]}]}
{"op":"mcm","clk":"988149084","pt":1580474822991,"mc":[{"id":"1.168133553","rc":[{"batb":[[0,1.07,3],[1,1.06,1.99],[2,1.04,6]],"ltp":1.51,"tv":6.72,"id":16325787}]}]}
{"op":"mcm","clk":"988150895","pt":1580474840330,"mc":[{"id":"1.168133553","rc":[{"batb":[[0,1.09,3],[1,1.08,39.71],[2,1.06,1.99]],"ltp":1.51,"tv":6.72,"id":16325787}]}]}
{"op":"mcm","clk":"988153221","pt":1580474865721,"mc":[{"id":"1.168133553","rc":[{"batb":[[1,1.06,1.99],[2,1.04,6]],"ltp":1.51,"tv":6.72,"id":16325787}]}]}
{"op":"mcm","clk":"988153796","pt":1580474871739,"mc":[{"id":"1.168133553","rc":[{"batb":[[0,1.06,1.99],[1,1.05,3]],"ltp":1.51,"tv":6.72,"id":16325787}]}]}
{"op":"mcm","clk":"988155010","pt":1580474885542,"mc":[{"id":"1.168133553","rc":[{"batb":[[0,1.06,4.99],[1,1.04,6],[2,1.03,1628.12]],"ltp":1.51,"tv":6.72,"id":16325787}]}]}
{"op":"mcm","clk":"988156436","pt":1580474900811,"mc":[{"id":"1.168133553","rc":[{"batb":[[0,1.07,3],[1,1.06,1.99],[2,1.04,6]],"ltp":1.51,"tv":6.72,"id":16325787}]}]}
{"op":"mcm","clk":"988157678","pt":1580474913388,"mc":[{"id":"1.168133553","rc":[{"batb":[[0,1.06,1.99],[1,1.05,3]],"ltp":1.51,"tv":6.72,"id":16325787}]}]}
{"op":"mcm","clk":"988158074","pt":1580474917498,"mc":[{"id":"1.168133553","rc":[{"batb":[[0,1.07,40.08],[1,1.06,1.99],[2,1.05,3]],"ltp":1.51,"tv":6.72,"id":16325787}]}]}
{"op":"mcm","clk":"988160706","pt":1580474927723,"mc":[{"id":"1.168133553","rc":[{"batb":[[0,1.08,3],[1,1.07,40.08],[2,1.06,1.99]],"ltp":1.51,"tv":6.72,"id":16325787}]}]}
{"op":"mcm","clk":"988163506","pt":1580474944115,"mc":[{"id":"1.168133553","rc":[{"batb":[[1,1.06,1.99],[2,1.04,6]],"ltp":1.51,"tv":6.72,"id":16325787}]}]}
{"op":"mcm","clk":"988165159","pt":1580474957914,"mc":[{"id":"1.168133553","rc":[{"batb":[[0,1.06,1.99],[1,1.05,3]],"ltp":1.51,"tv":6.72,"id":16325787}]}]}
{"op":"mcm","clk":"988166583","pt":1580474970154,"mc":[{"id":"1.168133553","rc":[{"batb":[[0,1.07,40.08],[1,1.06,1.99],[2,1.05,3]],"ltp":1.51,"tv":6.72,"id":16325787}]}]}
{"op":"mcm","clk":"988166986","pt":1580474973727,"mc":[{"id":"1.168133553","rc":[{"batb":[[0,1.08,3],[1,1.07,40.08],[2,1.06,1.99]],"ltp":1.51,"tv":6.72,"id":16325787}]}]}
{"op":"mcm","clk":"988167226","pt":1580474975960,"mc":[{"id":"1.168133553","rc":[{"batb":[[1,1.04,3],[2,1.03,1630.64]],"ltp":0.0,"tv":0.0,"id":27227336},{"batb":[[1,1.04,3],[2,1.03,1663.44]],"ltp":0.0,"tv":0.0,"id":21641292}]}]}
{"op":"mcm","clk":"988169384","pt":1580474996594,"mc":[{"id":"1.168133553","rc":[{"batb":[[1,1.06,1.99],[2,1.04,6]],"ltp":1.51,"tv":6.72,"id":16325787}]}]}
{"op":"mcm","clk":"988169954","pt":1580475001848,"mc":[{"id":"1.168133553","rc":[{"batb":[[0,1.06,1.99],[1,1.05,3]],"ltp":1.51,"tv":6.72,"id":16325787}]}]}
{"op":"mcm","clk":"988172035","pt":1580475020546,"mc":[{"id":"1.168133553","rc":[{"batb":[[0,1.06,4.99],[1,1.04,6],[2,1.03,1628.12]],"ltp":1.51,"tv":6.72,"id":16325787}]}]}
{"op":"mcm","clk":"988173676","pt":1580475039287,"mc":[{"id":"1.168133553","rc":[{"batb":[[0,1.07,3],[1,1.06,1.99],[2,1.04,6]],"ltp":1.51,"tv":6.72,"id":16325787}]}]}
{"op":"mcm","clk":"988174413","pt":1580475048177,"mc":[{"id":"1.168133553","rc":[{"batb":[[0,1.08,39.71],[1,1.07,3],[2,1.06,1.99]],"ltp":1.51,"tv":6.72,"id":16325787}]}]}
{"op":"mcm","clk":"988174646","pt":1580475050867,"mc":[{"id":"1.168133553","rc":[{"batb":[[0,1.09,1.99],[1,1.08,39.71],[2,1.07,3]],"ltp":1.51,"tv":6.72,"id":16325787}]}]}
{"op":"mcm","clk":"988175035","pt":1580475055799,"mc":[{"id":"1.168133553","rc":[{"batb":[[0,1.09,4.99],[2,1.04,6]],"ltp":1.51,"tv":6.72,"id":16325787}]}]}
{"op":"mcm","clk":"988176405","pt":1580475071425,"mc":[{"id":"1.168133553","rc":[{"batb":[[0,1.1,3],[1,1.09,1.99],[2,1.08,39.71]],"ltp":1.51,"tv":6.72,"id":16325787}]}]}
{"op":"mcm","clk":"988176702","pt":1580475075357,"mc":[{"id":"1.168133553","rc":[{"batb":[[0,1.11,38.64],[1,1.1,3],[2,1.09,1.99]],"ltp":1.51,"tv":6.72,"id":16325787}]}]}
{"op":"mcm","clk":"988177543","pt":1580475086350,"mc":[{"id":"1.168133553","rc":[{"batb":[[0,1.12,3],[1,1.11,38.64]],"ltp":1.51,"tv":6.72,"id":16325787}]}]}
{"op":"mcm","clk":"988178867","pt":1580475100940,"mc":[{"id":"1.168133553","rc":[{"batb":[[1,1.09,1.99],[2,1.04,6]],"ltp":1.51,"tv":6.72,"id":16325787}]}]}
{"op":"mcm","clk":"988179808","pt":1580475112452,"mc":[{"id":"1.168133553","rc":[{"batb":[[0,1.09,1.99],[1,1.05,3]],"ltp":1.51,"tv":6.72,"id":16325787}]}]}
{"op":"mcm","clk":"988181348","pt":1580475130378,"mc":[{"id":"1.168133553","rc":[{"batb":[[1,1.06,3]],"ltp":1.51,"tv":6.72,"id":16325787}]}]}
{"op":"mcm","clk":"988182236","pt":1580475140495,"mc":[{"id":"1.168133553","rc":[{"batb":[[0,1.06,3],[1,1.04,6],[2,1.03,1628.12]],"ltp":1.51,"tv":6.72,"id":16325787}]}]}
{"op":"mcm","clk":"988182243","pt":1580475140596,"mc":[{"id":"1.168133553","rc":[{"batb":[[0,1.07,1.99],[1,1.06,3],[2,1.04,6]],"ltp":1.51,"tv":6.72,"id":16325787}]}]}
{"op":"mcm","clk":"988182801","pt":1580475146058,"mc":[{"id":"1.168133553","rc":[{"batb":[[0,1.07,4.99],[1,1.04,6],[2,1.03,1628.12]],"ltp":1.51,"tv":6.72,"id":16325787}]}]}
{"op":"mcm","clk":"988192413","pt":1580475161334,"mc":[{"id":"1.168133553","rc":[{"batb":[[0,1.08,3],[1,1.07,1.99],[2,1.04,6]],"ltp":1.51,"tv":6.72,"id":16325787}]}]}
{"op":"mcm","clk":"988193693","pt":1580475176922,"mc":[{"id":"1.168133553","rc":[{"batb":[[0,1.09,39.35],[1,1.08,3],[2,1.07,1.99]],"ltp":1.51,"tv":6.72,"id":16325787}]}]}
{"op":"mcm","clk":"988194104","pt":1580475181839,"mc":[{"id":"1.168133553","rc":[{"batb":[[0,1.1,3],[1,1.09,39.35]],"ltp":1.51,"tv":6.72,"id":16325787}]}]}
{"op":"mcm","clk":"988195818","pt":1580475201418,"mc":[{"id":"1.168133553","rc":[{"batb":[[1,1.07,1.99],[2,1.04,6]],"ltp":1.51,"tv":6.72,"id":16325787}]}]}
{"op":"mcm","clk":"988195867","pt":1580475202148,"mc":[{"id":"1.168133553","rc":[{"batb":[[0,1.07,1.99],[1,1.05,3]],"ltp":1.51,"tv":6.72,"id":16325787}]}]}
{"op":"mcm","clk":"988197313","pt":1580475221892,"mc":[{"id":"1.168133553","rc":[{"batb":[[1,1.06,3]],"ltp":1.51,"tv":6.72,"id":16325787}]}]}
{"op":"mcm","clk":"988197652","pt":1580475226208,"mc":[{"id":"1.168133553","rc":[{"batb":[[1,1.05,10],[2,1.04,3]],"ltp":0.0,"tv":0.0,"id":27227336},{"batb":[[1,1.05,10],[2,1.04,3]],"ltp":0.0,"tv":0.0,"id":21641292},{"batb":[[0,1.07,11.99]],"ltp":1.51,"tv":6.72,"id":16325787}]}]}
{"op":"mcm","clk":"988197794","pt":1580475228004,"mc":[{"id":"1.168133553","rc":[{"batb":[[0,1.08,39.71],[1,1.07,11.99],[2,1.06,3]],"ltp":1.51,"tv":6.72,"id":16325787}]}]}
{"op":"mcm","clk":"988198093","pt":1580475231310,"mc":[{"id":"1.168133553","rc":[{"batb":[[0,1.09,1.99],[1,1.08,39.71],[2,1.07,10]],"ltp":1.51,"tv":6.72,"id":16325787}]}]}
{"op":"mcm","clk":"988198863","pt":1580475240620,"mc":[{"id":"1.168133553","rc":[{"batb":[[0,1.09,4.99]],"ltp":1.51,"tv":6.72,"id":16325787}]}]}
{"op":"mcm","clk":"988200321","pt":1580475256464,"mc":[{"id":"1.168133553","rc":[{"batb":[[0,1.1,3],[1,1.09,1.99]],"ltp":1.51,"tv":6.72,"id":16325787}]}]}
{"op":"mcm","clk":"988201757","pt":1580475273779,"mc":[{"id":"1.168133553","rc":[{"batb":[[0,1.09,1.99],[1,1.08,3]],"ltp":1.51,"tv":6.72,"id":16325787}]}]}
{"op":"mcm","clk":"988202390","pt":1580475281620,"mc":[{"id":"1.168133553","rc":[{"batb":[[0,1.1,38.98],[1,1.09,1.99],[2,1.08,3]],"ltp":1.51,"tv":6.72,"id":16325787}]}]}
{"op":"mcm","clk":"988203140","pt":1580475291326,"mc":[{"id":"1.168133553","rc":[{"batb":[[0,1.11,3],[1,1.1,38.98],[2,1.09,1.99]],"ltp":1.51,"tv":6.72,"id":16325787}]}]}
{"op":"mcm","clk":"988204491","pt":1580475307619,"mc":[{"id":"1.168133553","rc":[{"batb":[[1,1.09,1.99],[2,1.07,10]],"ltp":1.51,"tv":6.72,"id":16325787}]}]}
{"op":"mcm","clk":"988205351","pt":1580475316850,"mc":[{"id":"1.168133553","rc":[{"batb":[[1,1.1,10],[2,1.09,1.99]],"ltp":1.51,"tv":6.72,"id":16325787}]}]}
{"op":"mcm","clk":"988205872","pt":1580475322874,"mc":[{"id":"1.168133553","rc":[{"batb":[[0,1.12,1.99],[1,1.11,3],[2,1.1,10]],"ltp":1.51,"tv":6.72,"id":16325787}]}]}
{"op":"mcm","clk":"988206397","pt":1580475329090,"mc":[{"id":"1.168133553","rc":[{"batb":[[1,1.06,3],[2,1.05,10]],"ltp":0.0,"tv":0.0,"id":27227336},{"batb":[[1,1.06,3],[2,1.05,10]],"ltp":0.0,"tv":0.0,"id":21641292}]}]}
{"op":"mcm","clk":"988206877","pt":1580475334599,"mc":[{"id":"1.168133553","rc":[{"batb":[[0,1.13,37.95],[1,1.12,1.99],[2,1.11,3]],"ltp":1.51,"tv":6.72,"id":16325787}]}]}
{"op":"mcm","clk":"988207056","pt":1580475336685,"mc":[{"id":"1.168133553","rc":[{"batb":[[0,1.14,3],[1,1.13,37.95],[2,1.12,1.99]],"ltp":1.51,"tv":6.72,"id":16325787}]}]}
{"op":"mcm","clk":"988208961","pt":1580475360360,"mc":[{"id":"1.168133553","rc":[{"batb":[[1,1.12,1.99],[2,1.1,10]],"ltp":1.51,"tv":6.72,"id":16325787}]}]}
{"op":"mcm","clk":"988209209","pt":1580475363369,"mc":[{"id":"1.168133553","rc":[{"batb":[[0,1.12,1.99],[1,1.11,3]],"ltp":1.51,"tv":6.72,"id":16325787}]}]}
{"op":"mcm","clk":"988210752","pt":1580475380748,"mc":[{"id":"1.168133553","rc":[{"batb":[[0,1.12,4.99],[1,1.1,10],[2,1.04,6]],"ltp":1.51,"tv":6.72,"id":16325787}]}]}
{"op":"mcm","clk":"988212080","pt":1580475395934,"mc":[{"id":"1.168133553","rc":[{"batb":[[0,1.13,3],[1,1.12,1.99],[2,1.1,10]],"ltp":1.51,"tv":6.72,"id":16325787}]}]}
{"op":"mcm","clk":"988212564","pt":1580475401724,"mc":[{"id":"1.168133553","rc":[{"batb":[[0,1.14,1.99],[1,1.13,3]],"ltp":1.51,"tv":6.72,"id":16325787}]}]}
{"op":"mcm","clk":"988213354","pt":1580475410856,"mc":[{"id":"1.168133553","rc":[{"batb":[[0,1.15,37.29],[1,1.14,1.99],[2,1.13,3]],"ltp":1.51,"tv":6.72,"id":16325787}]}]}
{"op":"mcm","clk":"988214042","pt":1580475418872,"mc":[{"id":"1.168133553","rc":[{"batb":[[0,1.16,3],[1,1.15,37.29],[2,1.14,1.99]],"ltp":1.51,"tv":6.72,"id":16325787}]}]}
{"op":"mcm","clk":"988214353","pt":1580475422987,"mc":[{"id":"1.168133553","rc":[{"batb":[[2,1.03,1630.64]],"ltp":0.0,"tv":0.0,"id":27227336},{"batb":[[2,1.03,1663.44]],"ltp":0.0,"tv":0.0,"id":21641292}]}]}
{"op":"mcm","clk":"988214630","pt":1580475426759,"mc":[{"id":"1.168133553","rc":[{"batb":[[1,1.03,1630.64],[2,1.02,1.99]],"ltp":0.0,"tv":0.0,"id":27227336},{"batb":[[1,1.03,1663.44],[2,1.02,1.99]],"ltp":0.0,"tv":0.0,"id":21641292}]}]}
{"op":"mcm","clk":"988215399","pt":1580475436722,"mc":[{"id":"1.168133553","rc":[{"batb":[[1,1.14,1.99],[2,1.03,1628.12]],"ltp":1.51,"tv":6.72,"id":16325787}]}]}
{"op":"mcm","clk":"988215815","pt":1580475442408,"mc":[{"id":"1.168133553","rc":[{"batb":[[0,1.14,1.99],[1,1.04,3]],"ltp":1.51,"tv":6.72,"id":16325787}]}]}
{"op":"mcm","clk":"988217104","pt":1580475459017,"mc":[{"id":"1.168133553","rc":[{"batb":[[1,1.05,3]],"ltp":1.51,"tv":6.72,"id":16325787}]}]}
{"op":"mcm","clk":"988217559","pt":1580475464656,"mc":[{"id":"1.168133553","rc":[{"batb":[[2,1.04,6]],"ltp":1.51,"tv":6.72,"id":16325787}]}]}
{"op":"mcm","clk":"988218540","pt":1580475476911,"mc":[{"id":"1.168133553","rc":[{"batb":[[1,1.06,3]],"ltp":1.51,"tv":6.72,"id":16325787}]}]}
{"op":"mcm","clk":"988219077","pt":1580475483153,"mc":[{"id":"1.168133553","rc":[{"batb":[[0,1.07,1.99]],"ltp":1.51,"tv":6.72,"id":16325787}]}]}
{"op":"mcm","clk":"988219419","pt":1580475487556,"mc":[{"id":"1.168133553","rc":[{"batb":[[0,1.08,39.71],[1,1.07,1.99],[2,1.06,3]],"ltp":1.51,"tv":6.72,"id":16325787}]}]}
{"op":"mcm","clk":"988219973","pt":1580475494876,"mc":[{"id":"1.168133553","rc":[{"batb":[[0,1.09,3],[1,1.08,39.71],[2,1.07,1.99]],"ltp":1.51,"tv":6.72,"id":16325787}]}]}
{"op":"mcm","clk":"988221368","pt":1580475512713,"mc":[{"id":"1.168133553","rc":[{"batb":[[1,1.07,1.99],[2,1.04,6]],"ltp":1.51,"tv":6.72,"id":16325787}]}]}
{"op":"mcm","clk":"988221460","pt":1580475513844,"mc":[{"id":"1.168133553","rc":[{"batb":[[0,1.07,1.99],[1,1.05,3]],"ltp":1.51,"tv":6.72,"id":16325787}]}]}
{"op":"mcm","clk":"988222851","pt":1580475531390,"mc":[{"id":"1.168133553","rc":[{"batb":[[1,1.06,3]],"ltp":1.51,"tv":6.72,"id":16325787}]}]}
{"op":"mcm","clk":"988223386","pt":1580475538300,"mc":[{"id":"1.168133553","rc":[{"batb":[[0,1.08,39.71],[1,1.07,1.99],[2,1.06,3]],"ltp":1.51,"tv":6.72,"id":16325787}]}]}
{"op":"mcm","clk":"988223944","pt":1580475544397,"mc":[{"id":"1.168133553","rc":[{"batb":[[0,1.09,3],[1,1.08,39.71],[2,1.07,1.99]],"ltp":1.51,"tv":6.72,"id":16325787}]}]}
{"op":"mcm","clk":"988225546","pt":1580475564338,"mc":[{"id":"1.168133553","rc":[{"batb":[[1,1.07,1.99],[2,1.04,6]],"ltp":1.51,"tv":6.72,"id":16325787}]}]}
{"op":"mcm","clk":"988226413","pt":1580475575646,"mc":[{"id":"1.168133553","rc":[{"batb":[[0,1.07,1.99],[1,1.05,3]],"ltp":1.51,"tv":6.72,"id":16325787}]}]}
{"op":"mcm","clk":"988226946","pt":1580475582481,"mc":[{"id":"1.168133553","rc":[{"batb":[[0,1.06,1.99]],"ltp":1.51,"tv":6.72,"id":16325787}]}]}
{"op":"mcm","clk":"988227682","pt":1580475591421,"mc":[{"id":"1.168133553","rc":[{"batb":[[0,1.07,40.08],[1,1.06,4.99]],"ltp":1.51,"tv":6.72,"id":16325787}]}]}
{"op":"mcm","clk":"988228843","pt":1580475604917,"mc":[{"id":"1.168133553","rc":[{"batb":[[0,1.08,3],[1,1.07,40.08],[2,1.06,1.99]],"ltp":1.51,"tv":6.72,"id":16325787}]}]}
{"op":"mcm","clk":"988229147","pt":1580475608704,"mc":[{"id":"1.168133553","rc":[{"batb":[[1,1.04,10],[2,1.03,1630.64]],"ltp":0.0,"tv":0.0,"id":27227336},{"batb":[[1,1.04,10],[2,1.03,1663.44]],"ltp":0.0,"tv":0.0,"id":21641292},{"batb":[[0,1.08,13]],"ltp":1.51,"tv":6.72,"id":16325787}]}]}
{"op":"mcm","clk":"988229976","pt":1580475615516,"mc":[{"id":"1.168133553","rc":[{"batb":[[0,1.52,1.09],[1,1.51,3.36],[2,1.04,10]],"ltp":0.0,"tv":0.0,"id":27227336},{"batb":[[0,1.52,1.09],[1,1.51,3.36],[2,1.04,10]],"ltp":0.0,"tv":0.0,"id":21641292},{"batb":[[0,1.09,1.52],[1,1.08,13],[2,1.07,40.08]],"ltp":1.51,"tv":6.72,"id":16325787}]}]}
{"op":"mcm","clk":"988230138","pt":1580475617318,"mc":[{"id":"1.168133553","rc":[{"batb":[[0,1.09,4.52],[1,1.08,10],[2,1.06,1.99]],"ltp":1.51,"tv":6.72,"id":16325787}]}]}
{"op":"mcm","clk":"988231286","pt":1580475628426,"mc":[{"id":"1.168133553","rc":[{"batb":[[0,1.1,3],[1,1.09,1.52],[2,1.08,10]],"ltp":1.51,"tv":6.72,"id":16325787}]}]}
{"op":"mcm","clk":"988233030","pt":1580475646308,"mc":[{"id":"1.168133553","rc":[{"batb":[[0,1.09,4.52],[1,1.08,10],[2,1.06,1.99]],"ltp":1.51,"tv":6.72,"id":16325787}]}]}
{"op":"mcm","clk":"988234641","pt":1580475661253,"mc":[{"id":"1.168133553","rc":[{"batb":[[0,1.1,3],[1,1.09,1.52],[2,1.08,10]],"ltp":1.51,"tv":6.72,"id":16325787}]}]}
{"op":"mcm","clk":"988235287","pt":1580475667956,"mc":[{"id":"1.168133553","rc":[{"batb":[[0,1.11,1.99],[1,1.1,3],[2,1.09,1.52]],"ltp":1.51,"tv":6.72,"id":16325787}]}]}
{"op":"mcm","clk":"988235426","pt":1580475669338,"mc":[{"id":"1.168133553","rc":[{"batb":[[0,1.12,38.29],[1,1.11,1.99],[2,1.1,3]],"ltp":1.51,"tv":6.72,"id":16325787}]}]}
{"op":"mcm","clk":"988236680","pt":1580475680555,"mc":[{"id":"1.168133553","rc":[{"batb":[[2,1.09,1.52]],"ltp":1.51,"tv":6.72,"id":16325787}]}]}
{"op":"mcm","clk":"988236697","pt":1580475680659,"mc":[{"id":"1.168133553","rc":[{"batb":[[0,1.13,3],[1,1.12,38.29],[2,1.11,1.99]],"ltp":1.51,"tv":6.72,"id":16325787}]}]}
{"op":"mcm","clk":"988238204","pt":1580475695414,"mc":[{"id":"1.168133553","rc":[{"batb":[[1,1.11,1.99],[2,1.09,1.52]],"ltp":1.51,"tv":6.72,"id":16325787}]}]}
{"op":"mcm","clk":"988238435","pt":1580475698128,"mc":[{"id":"1.168133553","rc":[{"batb":[[0,1.11,1.99],[1,1.1,3]],"ltp":1.51,"tv":6.72,"id":16325787}]}]}
{"op":"mcm","clk":"988239115","pt":1580475705124,"mc":[{"id":"1.168133553","rc":[{"batb":[[2,1.03,1630.64]],"ltp":0.0,"tv":0.0,"id":27227336},{"batb":[[2,1.03,1663.44]],"ltp":0.0,"tv":0.0,"id":21641292}]}]}
{"op":"mcm","clk":"988240235","pt":1580475713348,"mc":[{"id":"1.168133553","rc":[{"batb":[[0,1.11,4.99],[1,1.09,1.52],[2,1.04,6]],"ltp":1.51,"tv":6.72,"id":16325787}]}]}
{"op":"mcm","clk":"988242197","pt":1580475728064,"mc":[{"id":"1.168133553","rc":[{"batb":[[0,1.12,3],[1,1.11,1.99],[2,1.09,1.52]],"ltp":1.51,"tv":6.72,"id":16325787}]}]}
{"op":"mcm","clk":"988244830","pt":1580475745382,"mc":[{"id":"1.168133553","rc":[{"batb":[[0,1.11,1.99],[1,1.1,3]],"ltp":1.51,"tv":6.72,"id":16325787}]}]}
{"op":"mcm","clk":"988244923","pt":1580475745869,"mc":[{"id":"1.168133553","rc":[{"batb":[[0,1.12,38.29],[1,1.11,1.99],[2,1.1,3]],"ltp":1.51,"tv":6.72,"id":16325787}]}]}
{"op":"mcm","clk":"988246153","pt":1580475754007,"mc":[{"id":"1.168133553","rc":[{"batb":[[0,1.13,1.99],[1,1.12,38.29]],"ltp":1.51,"tv":6.72,"id":16325787}]}]}
{"op":"mcm","clk":"988247435","pt":1580475763021,"mc":[{"id":"1.168133553","rc":[{"batb":[[0,1.13,4.99],[2,1.09,1.52]],"ltp":1.51,"tv":6.72,"id":16325787}]}]}
{"op":"mcm","clk":"988248910","pt":1580475771530,"mc":[{"id":"1.168133553","rc":[{"batb":[[1,1.09,1.52],[2,1.04,6]],"ltp":1.51,"tv":6.72,"id":16325787}]}]}
{"op":"mcm","clk":"988250133","pt":1580475779678,"mc":[{"id":"1.168133553","rc":[{"batb":[[0,1.14,3],[1,1.13,1.99],[2,1.09,1.52]],"ltp":1.51,"tv":6.72,"id":16325787}]}]}
{"op":"mcm","clk":"988252018","pt":1580475794514,"mc":[{"id":"1.168133553","rc":[{"batb":[[0,1.13,1.99],[1,1.1,3]],"ltp":1.51,"tv":6.72,"id":16325787}]}]}
{"op":"mcm","clk":"988253373","pt":1580475808404,"mc":[{"id":"1.168133553","rc":[{"batb":[[1,1.11,3]],"ltp":1.51,"tv":6.72,"id":16325787}]}]}
{"op":"mcm","clk":"988254826","pt":1580475821852,"mc":[{"id":"1.168133553","rc":[{"batb":[[1,1.12,3]],"ltp":1.51,"tv":6.72,"id":16325787}]}]}
{"op":"mcm","clk":"988256956","pt":1580475836888,"mc":[{"id":"1.168133553","rc":[{"batb":[[0,1.13,4.99],[1,1.09,1.52],[2,1.04,6]],"ltp":1.51,"tv":6.72,"id":16325787}]}]}
{"op":"mcm","clk":"988258732","pt":1580475851822,"mc":[{"id":"1.168133553","rc":[{"batb":[[0,1.14,3],[1,1.13,1.99],[2,1.09,1.52]],"ltp":1.51,"tv":6.72,"id":16325787}]}]}
{"op":"mcm","clk":"988260579","pt":1580475867436,"mc":[{"id":"1.168133553","rc":[{"batb":[[0,1.13,1.99],[1,1.1,3]],"ltp":1.51,"tv":6.72,"id":16325787}]}]}
{"op":"mcm","clk":"988261198","pt":1580475874246,"mc":[{"id":"1.168133553","rc":[{"batb":[[2,1.04,6]],"ltp":1.51,"tv":6.72,"id":16325787}]}]}
{"op":"mcm","clk":"988261942","pt":1580475880551,"mc":[{"id":"1.168133553","rc":[{"batb":[[1,1.04,6],[2,1.03,1628.12]],"ltp":1.51,"tv":6.72,"id":16325787}]}]}
{"op":"mcm","clk":"988261960","pt":1580475880656,"mc":[{"id":"1.168133553","rc":[{"batb":[[1,1.11,3],[2,1.04,6]],"ltp":1.51,"tv":6.72,"id":16325787}]}]}
{"op":"mcm","clk":"988262471","pt":1580475885481,"mc":[{"id":"1.168133553","rc":[{"batb":[[0,1.52,11.09]],"ltp":0.0,"tv":0.0,"id":27227336},{"batb":[[0,1.52,11.09]],"ltp":0.0,"tv":0.0,"id":21641292},{"batb":[[1,1.12,10],[2,1.11,3]],"ltp":1.51,"tv":6.72,"id":16325787}]}]}
{"op":"mcm","clk":"988263199","pt":1580475893269,"mc":[{"id":"1.168133553","rc":[{"batb":[[0,1.13,4.99],[2,1.04,6]],"ltp":1.51,"tv":6.72,"id":16325787}]}]}
{"op":"mcm","clk":"988263496","pt":1580475896464,"mc":[{"id":"1.168133553","rc":[{"batb":[[0,1.14,37.62],[1,1.13,4.99],[2,1.12,10]],"ltp":1.51,"tv":6.72,"id":16325787}]}]}
{"op":"mcm","clk":"988264313","pt":1580475904826,"mc":[{"id":"1.168133553","rc":[{"batb":[[0,1.15,1.99],[1,1.14,37.62],[2,1.13,3]],"ltp":1.51,"tv":6.72,"id":16325787}]}]}
{"op":"mcm","clk":"988264879","pt":1580475910966,"mc":[{"id":"1.168133553","rc":[{"batb":[[0,1.15,4.99],[2,1.12,10]],"ltp":1.51,"tv":6.72,"id":16325787}]}]}
{"op":"mcm","clk":"988266004","pt":1580475922149,"mc":[{"id":"1.168133553","rc":[{"batb":[[1,1.12,10],[2,1.03,1628.12]],"ltp":1.51,"tv":6.72,"id":16325787}]}]}
{"op":"mcm","clk":"988266560","pt":1580475927528,"mc":[{"id":"1.168133553","rc":[{"batb":[[0,1.15,1.99]],"ltp":1.51,"tv":6.72,"id":16325787}]}]}
{"op":"mcm","clk":"988266570","pt":1580475927634,"mc":[{"id":"1.168133553","rc":[{"batb":[[0,1.16,3],[1,1.15,1.99],[2,1.12,10]],"ltp":1.51,"tv":6.72,"id":16325787}]}]}
{"op":"mcm","clk":"988267964","pt":1580475941472,"mc":[{"id":"1.168133553","rc":[{"batb":[[0,1.15,1.99],[1,1.12,10],[2,1.03,1628.12]],"ltp":1.51,"tv":6.72,"id":16325787}]}]}
{"op":"mcm","clk":"988267970","pt":1580475941577,"mc":[{"id":"1.168133553","rc":[{"batb":[[1,1.13,3],[2,1.12,10]],"ltp":1.51,"tv":6.72,"id":16325787}]}]}
{"op":"mcm","clk":"988269193","pt":1580475954124,"mc":[{"id":"1.168133553","rc":[{"batb":[[1,1.14,3]],"ltp":1.51,"tv":6.72,"id":16325787}]}]}
{"op":"mcm","clk":"988270642","pt":1580475967810,"mc":[{"id":"1.168133553","rc":[{"batb":[[0,1.15,4.99],[1,1.12,10],[2,1.03,1628.12]],"ltp":1.51,"tv":6.72,"id":16325787}]}]}
{"op":"mcm","clk":"988271360","pt":1580475975516,"mc":[{"id":"1.168133553","rc":[{"batb":[[1,1.03,1628.12],[2,1.01,4105.65]],"ltp":1.51,"tv":6.72,"id":16325787}]}]}
{"op":"mcm","clk":"988271950","pt":1580475981253,"mc":[{"id":"1.168133553","rc":[{"batb":[[0,1.16,3],[1,1.15,1.99],[2,1.03,1628.12]],"ltp":1.51,"tv":6.72,"id":16325787}]}]}
{"op":"mcm","clk":"988274288","pt":1580475995573,"mc":[{"id":"1.168133553","rc":[{"batb":[[0,1.03,1628.12],[1,1.02,1.99],[2,1.01,4105.65]],"ltp":1.51,"tv":6.72,"id":16325787}]}]}
{"op":"mcm","clk":"988274302","pt":1580475995678,"mc":[{"id":"1.168133553","rc":[{"batb":[[0,1.04,3],[1,1.03,1628.12],[2,1.02,1.99]],"ltp":1.51,"tv":6.72,"id":16325787}]}]}
{"op":"mcm","clk":"988274460","pt":1580475997471,"mc":[{"id":"1.168133553","rc":[{"batb":[[0,1.05,40.84],[1,1.04,3],[2,1.03,1628.12]],"ltp":1.51,"tv":6.72,"id":16325787}]}]}
{"op":"mcm","clk":"988276005","pt":1580476011732,"mc":[{"id":"1.168133553","rc":[{"batb":[[0,1.06,3],[1,1.05,40.84]],"ltp":1.51,"tv":6.72,"id":16325787}]}]}
{"op":"mcm","clk":"988276420","pt":1580476015573,"mc":[{"id":"1.168133553","rc":[{"batb":[[2,1.04,6]],"ltp":1.51,"tv":6.72,"id":16325787}]}]}
{"op":"mcm","clk":"988277098","pt":1580476021659,"mc":[{"id":"1.168133553","rc":[{"batb":[[1,1.04,6],[2,1.03,1628.12]],"ltp":1.51,"tv":6.72,"id":16325787}]}]}
{"op":"mcm","clk":"988277414","pt":1580476024874,"mc":[{"id":"1.168133553","rc":[{"batb":[[0,1.05,3]],"ltp":1.51,"tv":6.72,"id":16325787}]}]}
{"op":"mcm","clk":"988280012","pt":1580476047114,"mc":[{"id":"1.168133553","rc":[{"batb":[[0,1.06,40.46],[1,1.05,3],[2,1.04,6]],"ltp":1.51,"tv":6.72,"id":16325787}]}]}
{"op":"mcm","clk":"988288869","pt":1580476052272,"mc":[{"id":"1.168133553","rc":[{"batb":[[0,1.07,3],[1,1.06,40.46]],"ltp":1.51,"tv":6.72,"id":16325787}]}]}
{"op":"mcm","clk":"988291054","pt":1580476071650,"mc":[{"id":"1.168133553","rc":[{"batb":[[1,1.04,6],[2,1.03,1628.12]],"ltp":1.51,"tv":6.72,"id":16325787}]}]}
{"op":"mcm","clk":"988292052","pt":1580476080638,"mc":[{"id":"1.168133553","rc":[{"batb":[[0,1.08,1.99],[1,1.07,3],[2,1.04,6]],"ltp":1.51,"tv":6.72,"id":16325787}]}]}
{"op":"mcm","clk":"988292879","pt":1580476087439,"mc":[{"id":"1.168133553","rc":[{"batb":[[0,1.08,4.99],[1,1.04,6],[2,1.03,1628.12]],"ltp":1.51,"tv":6.72,"id":16325787}]}]}
{"op":"mcm","clk":"988294789","pt":1580476103988,"mc":[{"id":"1.168133553","rc":[{"batb":[[0,1.09,3],[1,1.08,1.99],[2,1.04,6]],"ltp":1.51,"tv":6.72,"id":16325787}]}]}
{"op":"mcm","clk":"988296440","pt":1580476119699,"mc":[{"id":"1.168133553","rc":[{"batb":[[0,1.08,1.99],[1,1.05,3]],"ltp":1.51,"tv":6.72,"id":16325787}]}]}
{"op":"mcm","clk":"988298043","pt":1580476133543,"mc":[{"id":"1.168133553","rc":[{"batb":[[1,1.06,3]],"ltp":1.51,"tv":6.72,"id":16325787}]}]}
{"op":"mcm","clk":"988299712","pt":1580476149881,"mc":[{"id":"1.168133553","rc":[{"batb":[[1,1.07,3]],"ltp":1.51,"tv":6.72,"id":16325787}]}]}
{"op":"mcm","clk":"988300547","pt":1580476156915,"mc":[{"id":"1.168133553","rc":[{"batb":[[0,1.08,11.99]],"ltp":1.51,"tv":6.72,"id":16325787}]}]}
{"op":"mcm","clk":"988302054","pt":1580476169521,"mc":[{"id":"1.168133553","rc":[{"batb":[[0,1.09,39.35],[1,1.08,11.99],[2,1.07,3]],"ltp":1.51,"tv":6.72,"id":16325787}]}]}
{"op":"mcm","clk":"988302157","pt":1580476170319,"mc":[{"id":"1.168133553","rc":[{"batb":[[0,1.1,3],[1,1.09,39.35],[2,1.08,11.99]],"ltp":1.51,"tv":6.72,"id":16325787}]}]}
{"op":"mcm","clk":"988304486","pt":1580476189752,"mc":[{"id":"1.168133553","rc":[{"batb":[[0,1.51,3],[1,1.1,3],[2,1.09,39.35]],"ltp":1.51,"tv":6.72,"id":16325787}]}]}
{"op":"mcm","clk":"988305072","pt":1580476194245,"mc":[{"id":"1.168133553","rc":[{"batb":[[2,1.08,11.99]],"ltp":1.51,"tv":6.72,"id":16325787}]}]}
{"op":"mcm","clk":"988305296","pt":1580476196273,"mc":[{"id":"1.168133553","rc":[{"batb":[[1,1.44,3]],"ltp":1.51,"tv":6.72,"id":16325787}]}]}
{"op":"mcm","clk":"988310294","pt":1580476237021,"mc":[{"id":"1.168133553","rc":[{"batb":[[2,1.08,10]],"ltp":1.51,"tv":6.72,"id":16325787}]}]}
{"op":"mcm","clk":"988311470","pt":1580476247439,"mc":[{"id":"1.168133553","rc":[{"batb":[[1,1.45,10],[2,1.44,3]],"ltp":1.51,"tv":6.72,"id":16325787}]}]}
{"op":"mcm","clk":"988317939","pt":1580476301690,"mc":[{"id":"1.168133553","rc":[{"batb":[[0,1.45,10],[1,1.44,3],[2,1.03,1628.12]],"ltp":1.51,"tv":6.72,"id":16325787}]}]}
{"op":"mcm","clk":"988322043","pt":1580476337650,"mc":[{"id":"1.168133553","rc":[{"batb":[[0,1.44,3],[1,1.04,10]],"ltp":1.51,"tv":6.72,"id":16325787}]}]}
{"op":"mcm","clk":"988323475","pt":1580476349914,"mc":[{"id":"1.168133553","rc":[{"batb":[[0,1.05,3]],"ltp":1.51,"tv":6.72,"id":16325787}]}]}
{"op":"mcm","clk":"988325423","pt":1580476365986,"mc":[{"id":"1.168133553","rc":[{"batb":[[0,1.06,40.46],[1,1.05,3],[2,1.04,10]],"ltp":1.51,"tv":6.72,"id":16325787}]}]}
{"op":"mcm","clk":"988326363","pt":1580476374067,"mc":[{"id":"1.168133553","rc":[{"batb":[[0,1.07,3],[1,1.06,40.46]],"ltp":1.51,"tv":6.72,"id":16325787}]}]}
{"op":"mcm","clk":"988328220","pt":1580476390309,"mc":[{"id":"1.168133553","rc":[{"batb":[[1,1.04,10],[2,1.03,1628.12]],"ltp":1.51,"tv":6.72,"id":16325787}]}]}
{"op":"mcm","clk":"988329497","pt":1580476401453,"mc":[{"id":"1.168133553","rc":[{"batb":[[0,1.05,3]],"ltp":1.51,"tv":6.72,"id":16325787}]}]}
{"op":"mcm","clk":"988329629","pt":1580476402778,"mc":[{"id":"1.168133553","rc":[{"batb":[[0,1.06,1.99],[1,1.05,3],[2,1.04,10]],"ltp":1.51,"tv":6.72,"id":16325787}]}]}
{"op":"mcm","clk":"988331024","pt":1580476414954,"mc":[{"id":"1.168133553","rc":[{"batb":[[0,1.07,40.08],[1,1.06,1.99],[2,1.05,3]],"ltp":1.51,"tv":6.72,"id":16325787}]}]}
{"op":"mcm","clk":"988331477","pt":1580476419071,"mc":[{"id":"1.168133553","rc":[{"batb":[[0,1.08,3],[1,1.07,40.08],[2,1.06,1.99]],"ltp":1.51,"tv":6.72,"id":16325787}]}]}
{"op":"mcm","clk":"988333688","pt":1580476438752,"mc":[{"id":"1.168133553","rc":[{"batb":[[1,1.06,1.99],[2,1.04,6]],"ltp":1.51,"tv":6.72,"id":16325787}]}]}
{"op":"mcm","clk":"988334617","pt":1580476446366,"mc":[{"id":"1.168133553","rc":[{"batb":[[0,1.06,1.99],[1,1.05,3]],"ltp":1.51,"tv":6.72,"id":16325787}]}]}
{"op":"mcm","clk":"988336184","pt":1580476459081,"mc":[{"id":"1.168133553","rc":[{"batb":[[0,1.06,4.99],[1,1.04,6],[2,1.03,1628.12]],"ltp":1.51,"tv":6.72,"id":16325787}]}]}
{"op":"mcm","clk":"988337436","pt":1580476471029,"mc":[{"id":"1.168133553","rc":[{"batb":[[0,1.07,3],[1,1.06,1.99],[2,1.04,6]],"ltp":1.51,"tv":6.72,"id":16325787}]}]}
{"op":"mcm","clk":"988338823","pt":1580476483742,"mc":[{"id":"1.168133553","rc":[{"batb":[[0,1.06,1.99],[1,1.05,3]],"ltp":1.51,"tv":6.72,"id":16325787}]}]}
{"op":"mcm","clk":"988339143","pt":1580476486779,"mc":[{"id":"1.168133553","rc":[{"batb":[[0,1.07,40.08],[1,1.06,1.99],[2,1.05,3]],"ltp":1.51,"tv":6.72,"id":16325787}]}]}
{"op":"mcm","clk":"988339541","pt":1580476490289,"mc":[{"id":"1.168133553","rc":[{"batb":[[0,1.51,3],[1,1.08,1.99],[2,1.07,40.08]],"ltp":1.51,"tv":6.72,"id":16325787}]}]}
{"op":"mcm","clk":"988340560","pt":1580476499658,"mc":[{"id":"1.168133553","rc":[{"batb":[[1,1.44,3],[2,1.08,1.99]],"ltp":1.51,"tv":6.72,"id":16325787}]}]}
{"op":"mcm","clk":"988342563","pt":1580476517429,"mc":[{"id":"1.168133553","rc":[{"trd":[[1.51,12.72]],"batb":[[0,1.44,3],[1,1.08,1.99],[2,1.03,1628.12]],"ltp":1.51,"tv":12.72,"id":16325787}],"tv":12.72}]}
{"op":"mcm","clk":"988343405","pt":1580476525251,"mc":[{"id":"1.168133553","rc":[{"batb":[[0,1.08,1.99],[1,1.04,3]],"ltp":1.51,"tv":12.72,"id":16325787}]}]}
{"op":"mcm","clk":"988343545","pt":1580476526572,"mc":[{"id":"1.168133553","rc":[{"batl":[[0,1.44,4],[1,1000,0.2]],"ltp":1.51,"tv":12.72,"id":16325787}]}]}
{"op":"mcm","clk":"988343879","pt":1580476529654,"mc":[{"id":"1.168133553","rc":[{"batl":[[0,1000,0.2],[1,1000,0]],"ltp":1.51,"tv":12.72,"id":16325787}]}]}
{"op":"mcm","clk":"988344670","pt":1580476537470,"mc":[{"id":"1.168133553","rc":[{"batb":[[1,1.03,1628.12],[2,1.02,6]],"ltp":1.51,"tv":12.72,"id":16325787}]}]}
{"op":"mcm","clk":"988344699","pt":1580476537782,"mc":[{"id":"1.168133553","rc":[{"batb":[[1,1.05,3],[2,1.03,1628.12]],"ltp":1.51,"tv":12.72,"id":16325787}]}]}
{"op":"mcm","clk":"988346187","pt":1580476548980,"mc":[{"id":"1.168133553","rc":[{"batb":[[2,1.04,6]],"ltp":1.51,"tv":12.72,"id":16325787}]}]}
{"op":"mcm","clk":"988346481","pt":1580476551464,"mc":[{"id":"1.168133553","rc":[{"batb":[[1,1.04,6],[2,1.03,1628.12]],"ltp":1.51,"tv":12.72,"id":16325787}]}]}
{"op":"mcm","clk":"988346509","pt":1580476551669,"mc":[{"id":"1.168133553","rc":[{"batb":[[1,1.06,3],[2,1.04,6]],"ltp":1.51,"tv":12.72,"id":16325787}]}]}
{"op":"mcm","clk":"988348240","pt":1580476564472,"mc":[{"id":"1.168133553","rc":[{"batb":[[1,1.04,6],[2,1.03,1628.12]],"ltp":1.51,"tv":12.72,"id":16325787}]}]}
{"op":"mcm","clk":"988348252","pt":1580476564576,"mc":[{"id":"1.168133553","rc":[{"batb":[[1,1.07,3],[2,1.04,6]],"ltp":1.51,"tv":12.72,"id":16325787}]}]}
{"op":"mcm","clk":"988349967","pt":1580476578494,"mc":[{"id":"1.168133553","rc":[{"batb":[[1,1.04,6],[2,1.03,1628.12]],"ltp":1.51,"tv":12.72,"id":16325787}]}]}
{"op":"mcm","clk":"988349980","pt":1580476578615,"mc":[{"id":"1.168133553","rc":[{"batb":[[0,1.08,4.99]],"ltp":1.51,"tv":12.72,"id":16325787}]}]}
{"op":"mcm","clk":"988351459","pt":1580476590488,"mc":[{"id":"1.168133553","rc":[{"batb":[[0,1.08,1.99]],"ltp":1.51,"tv":12.72,"id":16325787}]}]}
{"op":"mcm","clk":"988351472","pt":1580476590597,"mc":[{"id":"1.168133553","rc":[{"batb":[[0,1.09,3],[1,1.08,1.99],[2,1.04,6]],"ltp":1.51,"tv":12.72,"id":16325787}]}]}
{"op":"mcm","clk":"988353278","pt":1580476605725,"mc":[{"id":"1.168133553","rc":[{"batb":[[0,1.1,38.98],[1,1.09,3],[2,1.08,1.99]],"ltp":1.51,"tv":12.72,"id":16325787}]}]}
{"op":"mcm","clk":"988353646","pt":1580476608808,"mc":[{"id":"1.168133553","rc":[{"batb":[[0,1.11,3],[1,1.1,38.98]],"ltp":1.51,"tv":12.72,"id":16325787}]}]}
{"op":"mcm","clk":"988354803","pt":1580476619528,"mc":[{"id":"1.168133553","rc":[{"batl":[[0,2.7,17],[1,1000,0.2]],"ltp":1.51,"tv":12.72,"id":16325787}]}]}
{"op":"mcm","clk":"988355819","pt":1580476629636,"mc":[{"id":"1.168133553","rc":[{"batb":[[1,1.08,1.99],[2,1.04,6]],"ltp":1.51,"tv":12.72,"id":16325787}]}]}
{"op":"mcm","clk":"988356548","pt":1580476636116,"mc":[{"id":"1.168133553","rc":[{"batb":[[0,1.08,1.99],[1,1.05,3]],"ltp":1.51,"tv":12.72,"id":16325787}]}]}
{"op":"mcm","clk":"988357790","pt":1580476648288,"mc":[{"id":"1.168133553","rc":[{"batb":[[1,1.06,3]],"ltp":1.51,"tv":12.72,"id":16325787}]}]}
{"op":"mcm","clk":"988358479","pt":1580476655254,"mc":[{"id":"1.168133553","rc":[{"batb":[[0,1.07,1.99]],"ltp":1.51,"tv":12.72,"id":16325787}]}]}
{"op":"mcm","clk":"988359067","pt":1580476661153,"mc":[{"id":"1.168133553","rc":[{"batb":[[0,1.07,4.99],[1,1.04,6],[2,1.03,1628.12]],"ltp":1.51,"tv":12.72,"id":16325787}]}]}
{"op":"mcm","clk":"988360541","pt":1580476675923,"mc":[{"id":"1.168133553","rc":[{"batb":[[0,1.08,3],[1,1.07,1.99],[2,1.04,6]],"ltp":1.51,"tv":12.72,"id":16325787}]}]}
{"op":"mcm","clk":"988360626","pt":1580476676999,"mc":[{"id":"1.168133553","rc":[{"batb":[[0,1.09,39.35],[1,1.08,3],[2,1.07,1.99]],"ltp":1.51,"tv":12.72,"id":16325787}]}]}
{"op":"mcm","clk":"988361896","pt":1580476689042,"mc":[{"id":"1.168133553","rc":[{"batb":[[0,1.1,3],[1,1.09,39.35]],"ltp":1.51,"tv":12.72,"id":16325787}]}]}
{"op":"mcm","clk":"988363105","pt":1580476700339,"mc":[{"id":"1.168133553","rc":[{"batb":[[1,1.07,1.99],[2,1.04,6]],"ltp":1.51,"tv":12.72,"id":16325787}]}]}
{"op":"mcm","clk":"988363336","pt":1580476702534,"mc":[{"id":"1.168133553","rc":[{"batb":[[0,1.07,1.99],[1,1.05,3]],"ltp":1.51,"tv":12.72,"id":16325787}]}]}
{"op":"mcm","clk":"988364853","pt":1580476716178,"mc":[{"id":"1.168133553","rc":[{"batb":[[1,1.06,3]],"ltp":1.51,"tv":12.72,"id":16325787}]}]}
{"op":"mcm","clk":"988365443","pt":1580476721732,"mc":[{"id":"1.168133553","rc":[{"batl":[[0,1000,0.2],[1,1000,0]],"ltp":1.51,"tv":12.72,"id":16325787}]}]}
{"op":"mcm","clk":"988365705","pt":1580476723905,"mc":[{"id":"1.168133553","rc":[{"batb":[[0,1.08,39.71],[1,1.07,1.99],[2,1.06,3]],"ltp":1.51,"tv":12.72,"id":16325787}]}]}
{"op":"mcm","clk":"988366095","pt":1580476727822,"mc":[{"id":"1.168133553","rc":[{"batb":[[0,1.09,1.99],[1,1.08,39.71]],"ltp":1.51,"tv":12.72,"id":16325787}]}]}
{"op":"mcm","clk":"988366343","pt":1580476730022,"mc":[{"id":"1.168133553","rc":[{"batb":[[0,1.09,4.99],[2,1.04,6]],"ltp":1.51,"tv":12.72,"id":16325787}]}]}
{"op":"mcm","clk":"988368388","pt":1580476747343,"mc":[{"id":"1.168133553","rc":[{"batb":[[1,1.04,6],[2,1.03,1628.12]],"ltp":1.51,"tv":12.72,"id":16325787}]}]}
{"op":"mcm","clk":"988368719","pt":1580476750334,"mc":[{"id":"1.168133553","rc":[{"batb":[[0,1.1,3],[1,1.09,1.99],[2,1.04,6]],"ltp":1.51,"tv":12.72,"id":16325787}]}]}
{"op":"mcm","clk":"988370553","pt":1580476766144,"mc":[{"id":"1.168133553","rc":[{"batb":[[0,1.09,1.99],[1,1.05,3]],"ltp":1.51,"tv":12.72,"id":16325787}]}]}
{"op":"mcm","clk":"988371226","pt":1580476771746,"mc":[{"id":"1.168133553","rc":[{"batb":[[0,1.53,3],[1,1.52,11.09],[2,1.51,3.36]],"ltp":0.0,"tv":0.0,"id":27227336},{"batb":[[0,1.53,3],[1,1.52,11.09],[2,1.51,3.36]],"ltp":0.0,"tv":0.0,"id":21641292}]}]}
{"op":"mcm","clk":"988371759","pt":1580476776478,"mc":[{"id":"1.168133553","rc":[{"batb":[[1,1.06,10],[2,1.05,3]],"ltp":1.51,"tv":12.72,"id":16325787}]}]}
{"op":"mcm","clk":"988372277","pt":1580476781041,"mc":[{"id":"1.168133553","rc":[{"batb":[[1,1.07,3],[2,1.06,10]],"ltp":1.51,"tv":12.72,"id":16325787}]}]}
{"op":"mcm","clk":"988373818","pt":1580476794093,"mc":[{"id":"1.168133553","rc":[{"batb":[[1,1.08,3]],"ltp":1.51,"tv":12.72,"id":16325787}]}]}
{"op":"mcm","clk":"988373930","pt":1580476795096,"mc":[{"id":"1.168133553","rc":[{"batb":[[0,1.1,38.98],[1,1.09,1.99],[2,1.08,3]],"ltp":1.51,"tv":12.72,"id":16325787}]}]}
{"op":"mcm","clk":"988374579","pt":1580476800541,"mc":[{"id":"1.168133553","rc":[{"batb":[[0,1.11,1.99],[1,1.1,38.98]],"ltp":1.51,"tv":12.72,"id":16325787}]}]}
{"op":"mcm","clk":"988374639","pt":1580476801036,"mc":[{"id":"1.168133553","rc":[{"batb":[[0,1.54,1.99],[1,1.53,3],[2,1.52,11.09]],"ltp":0.0,"tv":0.0,"id":27227336},{"batb":[[0,1.54,1.99],[1,1.53,3],[2,1.52,11.09]],"ltp":0.0,"tv":0.0,"id":21641292}]}]}
{"op":"mcm","clk":"988375996","pt":1580476811231,"mc":[{"id":"1.168133553","rc":[{"batb":[[0,1.11,4.99],[2,1.06,10]],"ltp":1.51,"tv":12.72,"id":16325787}]}]}
{"op":"mcm","clk":"988376868","pt":1580476818896,"mc":[{"id":"1.168133553","rc":[{"batb":[[1,1.06,10],[2,1.04,6]],"ltp":1.51,"tv":12.72,"id":16325787}]}]}
{"op":"mcm","clk":"988377137","pt":1580476821038,"mc":[{"id":"1.168133553","rc":[{"batb":[[0,1.12,3],[1,1.11,1.99],[2,1.06,10]],"ltp":1.51,"tv":12.72,"id":16325787}]}]}
{"op":"mcm","clk":"988378258","pt":1580476830744,"mc":[{"id":"1.168133553","rc":[{"batb":[[0,1.11,1.99],[1,1.07,3]],"ltp":1.51,"tv":12.72,"id":16325787}]}]}
{"op":"mcm","clk":"988379763","pt":1580476843403,"mc":[{"id":"1.168133553","rc":[{"batb":[[1,1.08,3]],"ltp":1.51,"tv":12.72,"id":16325787}]}]}
{"op":"mcm","clk":"988381333","pt":1580476856097,"mc":[{"id":"1.168133553","rc":[{"batb":[[1,1.09,3]],"ltp":1.51,"tv":12.72,"id":16325787}]}]}
{"op":"mcm","clk":"988382139","pt":1580476862827,"mc":[{"id":"1.168133553","rc":[{"batb":[[0,1.54,11.99],[2,1.52,1.09]],"ltp":0.0,"tv":0.0,"id":27227336},{"batb":[[0,1.54,11.99],[2,1.52,1.09]],"ltp":0.0,"tv":0.0,"id":21641292},{"batb":[[1,1.1,10],[2,1.09,3]],"ltp":1.51,"tv":12.72,"id":16325787}]}]}
{"op":"mcm","clk":"988382506","pt":1580476865804,"mc":[{"id":"1.168133553","rc":[{"batb":[[0,1.12,38.29],[1,1.11,1.99],[2,1.1,10]],"ltp":1.51,"tv":12.72,"id":16325787}]}]}
{"op":"mcm","clk":"988382808","pt":1580476868440,"mc":[{"id":"1.168133553","rc":[{"batl":[[0,2.5,4],[1,1000,0.2]],"ltp":1.51,"tv":12.72,"id":16325787}]}]}
{"op":"mcm","clk":"988383432","pt":1580476873352,"mc":[{"id":"1.168133553","rc":[{"batb":[[0,1.14,1.99],[1,1.13,3],[2,1.12,38.29]],"ltp":1.51,"tv":12.72,"id":16325787}]}]}
{"op":"mcm","clk":"988384788","pt":1580476884830,"mc":[{"id":"1.168133553","rc":[{"batb":[[0,1.14,4.99],[1,1.12,38.29],[2,1.1,10]],"ltp":1.51,"tv":12.72,"id":16325787}]}]}
{"op":"mcm","clk":"988385435","pt":1580476889817,"mc":[{"id":"1.168133553","rc":[{"batb":[[1,1.1,10],[2,1.04,6]],"ltp":1.51,"tv":12.72,"id":16325787}]}]}
{"op":"mcm","clk":"988386477","pt":1580476898273,"mc":[{"id":"1.168133553","rc":[{"batb":[[0,1.15,3],[1,1.14,1.99],[2,1.1,10]],"ltp":1.51,"tv":12.72,"id":16325787}]}]}
{"op":"mcm","clk":"988387426","pt":1580476906156,"mc":[{"id":"1.168133553","rc":[{"batl":[[0,1000,0.2],[1,1000,0]],"ltp":1.51,"tv":12.72,"id":16325787}]}]}
{"op":"mcm","clk":"988387804","pt":1580476909475,"mc":[{"id":"1.168133553","rc":[{"batb":[[0,1.14,1.99],[1,1.11,3]],"ltp":1.51,"tv":12.72,"id":16325787}]}]}
{"op":"mcm","clk":"988389082","pt":1580476921003,"mc":[{"id":"1.168133553","rc":[{"batb":[[1,1.12,3]],"ltp":1.51,"tv":12.72,"id":16325787}]}]}
{"op":"mcm","clk":"988389307","pt":1580476923110,"mc":[{"id":"1.168133553","rc":[{"batl":[[0,2.8,4],[1,1000,0.2]],"ltp":1.51,"tv":12.72,"id":16325787}]}]}
{"op":"mcm","clk":"988389913","pt":1580476928120,"mc":[{"id":"1.168133553","rc":[{"batb":[[1,1.52,1.09],[2,1.51,3.36]],"ltp":0.0,"tv":0.0,"id":27227336},{"batb":[[1,1.52,1.09],[2,1.51,3.36]],"ltp":0.0,"tv":0.0,"id":21641292},{"batb":[[2,1.11,3]],"ltp":1.51,"tv":12.72,"id":16325787}]}]}
{"op":"mcm","clk":"988390753","pt":1580476934992,"mc":[{"id":"1.168133553","rc":[{"batb":[[1,1.13,3]],"ltp":1.51,"tv":12.72,"id":16325787}]}]}
{"op":"mcm","clk":"988391014","pt":1580476937331,"mc":[{"id":"1.168133553","rc":[{"batb":[[0,1.15,37.29],[1,1.14,1.99],[2,1.13,3]],"ltp":1.51,"tv":12.72,"id":16325787}]}]}
{"op":"mcm","clk":"988391170","pt":1580476938598,"mc":[{"id":"1.168133553","rc":[{"batl":[[0,1000,0.2],[1,1000,0]],"ltp":1.51,"tv":12.72,"id":16325787}]}]}
{"op":"mcm","clk":"988391951","pt":1580476945323,"mc":[{"id":"1.168133553","rc":[{"batb":[[0,1.16,1.99],[1,1.15,37.29]],"ltp":1.51,"tv":12.72,"id":16325787}]}]}
{"op":"mcm","clk":"988392279","pt":1580476948119,"mc":[{"id":"1.168133553","rc":[{"batb":[[0,1.54,1.99],[1,1.53,10],[2,1.52,1.09]],"ltp":0.0,"tv":0.0,"id":27227336},{"batb":[[0,1.54,1.99],[1,1.53,10],[2,1.52,1.09]],"ltp":0.0,"tv":0.0,"id":21641292},{"batb":[[1,1.15,47.29]],"ltp":1.51,"tv":12.72,"id":16325787}]}]}
{"op":"mcm","clk":"988392683","pt":1580476951846,"mc":[{"id":"1.168133553","rc":[{"batb":[[0,1.16,4.99],[2,1.11,3]],"ltp":1.51,"tv":12.72,"id":16325787}]}]}
{"op":"mcm","clk":"988401600","pt":1580476957356,"mc":[{"id":"1.168133553","rc":[{"batl":[[0,3.1,4],[1,1000,0.2]],"ltp":1.51,"tv":12.72,"id":16325787}]}]}
{"op":"mcm","clk":"988402059","pt":1580476961464,"mc":[{"id":"1.168133553","rc":[{"batb":[[1,1.15,10]],"ltp":1.51,"tv":12.72,"id":16325787}]}]}
{"op":"mcm","clk":"988402113","pt":1580476961840,"mc":[{"id":"1.168133553","rc":[{"batb":[[0,1.17,36.65],[1,1.16,4.99],[2,1.15,10]],"ltp":1.51,"tv":12.72,"id":16325787}]}]}
{"op":"mcm","clk":"988402385","pt":1580476964446,"mc":[{"id":"1.168133553","rc":[{"batb":[[0,1.18,3],[1,1.17,36.65],[2,1.16,1.99]],"ltp":1.51,"tv":12.72,"id":16325787}]}]}
{"op":"mcm","clk":"988404749","pt":1580476985240,"mc":[{"id":"1.168133553","rc":[{"batb":[[1,1.16,1.99],[2,1.15,10]],"ltp":1.51,"tv":12.72,"id":16325787}]}]}
{"op":"mcm","clk":"988405217","pt":1580476988937,"mc":[{"id":"1.168133553","rc":[{"batb":[[0,1.16,4.99],[1,1.15,10],[2,1.11,3]],"ltp":1.51,"tv":12.72,"id":16325787}]}]}
{"op":"mcm","clk":"988407313","pt":1580477007089,"mc":[{"id":"1.168133553","rc":[{"batb":[[0,1.17,3],[1,1.16,1.99],[2,1.15,10]],"ltp":1.51,"tv":12.72,"id":16325787}]}]}
{"op":"mcm","clk":"988407489","pt":1580477008665,"mc":[{"id":"1.168133553","rc":[{"batb":[[0,1.18,36.34],[1,1.17,3],[2,1.16,1.99]],"ltp":1.51,"tv":12.72,"id":16325787}]}]}
{"op":"mcm","clk":"988409196","pt":1580477024330,"mc":[{"id":"1.168133553","rc":[{"batb":[[0,1.19,3],[1,1.18,36.34]],"ltp":1.51,"tv":12.72,"id":16325787}]}]}
{"op":"mcm","clk":"988409602","pt":1580477027930,"mc":[{"id":"1.168133553","rc":[{"batb":[[0,1.2,1.99],[1,1.19,3],[2,1.18,36.34]],"ltp":1.51,"tv":12.72,"id":16325787}]}]}
{"op":"mcm","clk":"988410143","pt":1580477032507,"mc":[{"id":"1.168133553","rc":[{"batb":[[2,1.15,10]],"ltp":1.51,"tv":12.72,"id":16325787}]}]}
{"op":"mcm","clk":"988410260","pt":1580477033503,"mc":[{"id":"1.168133553","rc":[{"batb":[[0,1.21,35.44],[1,1.2,1.99],[2,1.19,3]],"ltp":1.51,"tv":12.72,"id":16325787}]}]}
{"op":"mcm","clk":"988410324","pt":1580477034025,"mc":[{"id":"1.168133553","rc":[{"batb":[[0,1.22,10],[1,1.21,35.44],[2,1.2,1.99]],"ltp":1.51,"tv":12.72,"id":16325787}]}]}
{"op":"mcm","clk":"988411097","pt":1580477040459,"mc":[{"id":"1.168133553","rc":[{"batb":[[0,1.23,3],[1,1.22,10],[2,1.21,35.44]],"ltp":1.51,"tv":12.72,"id":16325787}]}]}
{"op":"mcm","clk":"988412957","pt":1580477056247,"mc":[{"id":"1.168133553","rc":[{"batb":[[2,1.2,1.99]],"ltp":1.51,"tv":12.72,"id":16325787}]}]}
{"op":"mcm","clk":"988413010","pt":1580477056664,"mc":[{"id":"1.168133553","rc":[{"batb":[[0,1.24,34.59],[1,1.23,3],[2,1.22,10]],"ltp":1.51,"tv":12.72,"id":16325787}]}]}
{"op":"mcm","clk":"988414182","pt":1580477066662,"mc":[{"id":"1.168133553","rc":[{"batb":[[0,1.25,3],[1,1.24,34.59]],"ltp":1.51,"tv":12.72,"id":16325787}]}]}
{"op":"mcm","clk":"988415833","pt":1580477080326,"mc":[{"id":"1.168133553","rc":[{"batb":[[1,1.22,10],[2,1.2,1.99]],"ltp":1.51,"tv":12.72,"id":16325787}]}]}
{"op":"mcm","clk":"988415942","pt":1580477081093,"mc":[{"id":"1.168133553","rc":[{"batb":[[0,1.23,3]],"ltp":1.51,"tv":12.72,"id":16325787}]}]}
{"op":"mcm","clk":"988418680","pt":1580477103844,"mc":[{"id":"1.168133553","rc":[{"batb":[[0,1.24,34.59],[1,1.23,3],[2,1.22,10]],"ltp":1.51,"tv":12.72,"id":16325787}]}]}
{"op":"mcm","clk":"988419524","pt":1580477110251,"mc":[{"id":"1.168133553","rc":[{"batb":[[0,1.25,3],[1,1.24,34.59]],"ltp":1.51,"tv":12.72,"id":16325787}]}]}
{"op":"mcm","clk":"988419674","pt":1580477111261,"mc":[{"id":"1.168133553","rc":[{"batb":[[0,1.26,1.99],[1,1.25,3],[2,1.24,34.59]],"ltp":1.51,"tv":12.72,"id":16325787}]}]}
{"op":"mcm","clk":"988420731","pt":1580477120198,"mc":[{"id":"1.168133553","rc":[{"batb":[[0,1.26,11.99]],"ltp":1.51,"tv":12.72,"id":16325787}]}]}
{"op":"mcm","clk":"988421555","pt":1580477127204,"mc":[{"id":"1.168133553","rc":[{"batb":[[0,1.27,3],[1,1.26,11.99],[2,1.11,3]],"ltp":1.51,"tv":12.72,"id":16325787}]}]}
{"op":"mcm","clk":"988421596","pt":1580477127612,"mc":[{"id":"1.168133553","rc":[{"batb":[[0,1.28,33.5],[1,1.27,3],[2,1.26,11.99]],"ltp":1.51,"tv":12.72,"id":16325787}]}]}
{"op":"mcm","clk":"988423022","pt":1580477139929,"mc":[{"id":"1.168133553","rc":[{"batb":[[0,1.29,3],[1,1.28,33.5]],"ltp":1.51,"tv":12.72,"id":16325787}]}]}
{"op":"mcm","clk":"988424422","pt":1580477151037,"mc":[{"id":"1.168133553","rc":[{"batb":[[1,1.26,11.99],[2,1.11,3]],"ltp":1.51,"tv":12.72,"id":16325787}]}]}
{"op":"mcm","clk":"988424593","pt":1580477152356,"mc":[{"id":"1.168133553","rc":[{"batb":[[0,1.27,3]],"ltp":1.51,"tv":12.72,"id":16325787}]}]}
{"op":"mcm","clk":"988427336","pt":1580477176312,"mc":[{"id":"1.168133553","rc":[{"batb":[[0,1.28,33.5],[1,1.27,3],[2,1.26,11.99]],"ltp":1.51,"tv":12.72,"id":16325787}]}]}
{"op":"mcm","clk":"988428014","pt":1580477182527,"mc":[{"id":"1.168133553","rc":[{"batb":[[1,1.26,11.99],[2,1.03,1628.12]],"ltp":1.51,"tv":12.72,"id":16325787}]}]}
{"op":"mcm","clk":"988428021","pt":1580477182629,"mc":[{"id":"1.168133553","rc":[{"batb":[[0,1.29,3],[1,1.28,33.5],[2,1.26,11.99]],"ltp":1.51,"tv":12.72,"id":16325787}]}]}
{"op":"mcm","clk":"988429769","pt":1580477198219,"mc":[{"id":"1.168133553","rc":[{"batb":[[0,1.3,1.99],[1,1.29,3],[2,1.28,33.5]],"ltp":1.51,"tv":12.72,"id":16325787}]}]}
{"op":"mcm","clk":"988430019","pt":1580477200476,"mc":[{"id":"1.168133553","rc":[{"batb":[[2,1.26,10]],"ltp":1.51,"tv":12.72,"id":16325787}]}]}
{"op":"mcm","clk":"988430069","pt":1580477200880,"mc":[{"id":"1.168133553","rc":[{"batb":[[0,1.31,32.74],[1,1.3,1.99],[2,1.29,3]],"ltp":1.51,"tv":12.72,"id":16325787}]}]}
{"op":"mcm","clk":"988430852","pt":1580477207500,"mc":[{"id":"1.168133553","rc":[{"batb":[[0,1.32,10],[1,1.31,32.74],[2,1.3,1.99]],"ltp":1.51,"tv":12.72,"id":16325787}]}]}
{"op":"mcm","clk":"988431313","pt":1580477210960,"mc":[{"id":"1.168133553","rc":[{"batb":[[0,1.33,3],[1,1.32,10],[2,1.31,32.74]],"ltp":1.51,"tv":12.72,"id":16325787}]}]}
{"op":"mcm","clk":"988433018","pt":1580477225339,"mc":[{"id":"1.168133553","rc":[{"batb":[[0,1.34,32],[1,1.33,3],[2,1.32,10]],"ltp":1.51,"tv":12.72,"id":16325787}]}]}
{"op":"mcm","clk":"988433097","pt":1580477226029,"mc":[{"id":"1.168133553","rc":[{"batb":[[0,1.35,3],[1,1.34,32]],"ltp":1.51,"tv":12.72,"id":16325787}]}]}
{"op":"mcm","clk":"988436196","pt":1580477251343,"mc":[{"id":"1.168133553","rc":[{"batb":[[0,1.33,3],[1,1.32,10],[2,1.3,1.99]],"ltp":1.51,"tv":12.72,"id":16325787}]}]}
{"op":"mcm","clk":"988439084","pt":1580477275490,"mc":[{"id":"1.168133553","rc":[{"batb":[[2,1.03,1628.12]],"ltp":1.51,"tv":12.72,"id":16325787}]}]}
{"op":"mcm","clk":"988439112","pt":1580477275704,"mc":[{"id":"1.168133553","rc":[{"batb":[[0,1.34,33.99],[1,1.33,3],[2,1.32,10]],"ltp":1.51,"tv":12.72,"id":16325787}]}]}
{"op":"mcm","clk":"988440489","pt":1580477286549,"mc":[{"id":"1.168133553","rc":[{"batb":[[1,1.32,10],[2,1.03,1628.12]],"ltp":1.51,"tv":12.72,"id":16325787}]}]}
{"op":"mcm","clk":"988440502","pt":1580477286625,"mc":[{"id":"1.168133553","rc":[{"batb":[[0,1.35,3],[1,1.34,33.99],[2,1.32,10]],"ltp":1.51,"tv":12.72,"id":16325787}]}]}
{"op":"mcm","clk":"988441169","pt":1580477293451,"mc":[{"id":"1.168133553","rc":[{"batb":[[0,1.35,13],[2,1.03,1628.12]],"ltp":1.51,"tv":12.72,"id":16325787}]}]}
{"op":"mcm","clk":"988441699","pt":1580477299056,"mc":[{"id":"1.168133553","rc":[{"batb":[[0,1.36,3],[1,1.35,10],[2,1.34,33.99]],"ltp":1.51,"tv":12.72,"id":16325787}]}]}
{"op":"mcm","clk":"988441813","pt":1580477300232,"mc":[{"id":"1.168133553","rc":[{"batb":[[2,1.34,1.99]],"ltp":1.51,"tv":12.72,"id":16325787}]}]}
{"op":"mcm","clk":"988441849","pt":1580477300656,"mc":[{"id":"1.168133553","rc":[{"batb":[[0,1.37,31.31],[1,1.36,3],[2,1.35,10]],"ltp":1.51,"tv":12.72,"id":16325787}]}]}
{"op":"mcm","clk":"988442878","pt":1580477311193,"mc":[{"id":"1.168133553","rc":[{"batb":[[0,1.38,3],[1,1.37,31.31]],"ltp":1.51,"tv":12.72,"id":16325787}]}]}
{"op":"mcm","clk":"988444525","pt":1580477325915,"mc":[{"id":"1.168133553","rc":[{"batb":[[1,1.35,10],[2,1.34,1.99]],"ltp":1.51,"tv":12.72,"id":16325787}]}]}
{"op":"mcm","clk":"988446019","pt":1580477339428,"mc":[{"id":"1.168133553","rc":[{"batb":[[0,1.36,3]],"ltp":1.51,"tv":12.72,"id":16325787}]}]}
{"op":"mcm","clk":"988447302","pt":1580477350878,"mc":[{"id":"1.168133553","rc":[{"batb":[[0,1.37,31.31],[1,1.36,3],[2,1.35,10]],"ltp":1.51,"tv":12.72,"id":16325787}]}]}
{"op":"mcm","clk":"988447608","pt":1580477353265,"mc":[{"id":"1.168133553","rc":[{"batb":[[0,1.38,1.99],[1,1.37,31.31],[2,1.36,3]],"ltp":1.51,"tv":12.72,"id":16325787}]}]}
{"op":"mcm","clk":"988448053","pt":1580477357391,"mc":[{"id":"1.168133553","rc":[{"batb":[[0,1.38,4.99],[2,1.35,10]],"ltp":1.51,"tv":12.72,"id":16325787}]}]}
{"op":"mcm","clk":"988449905","pt":1580477373382,"mc":[{"id":"1.168133553","rc":[{"batb":[[0,1.39,3],[1,1.38,1.99],[2,1.37,31.31]],"ltp":1.51,"tv":12.72,"id":16325787}]}]}
{"op":"mcm","clk":"988449975","pt":1580477374217,"mc":[{"id":"1.168133553","rc":[{"batb":[[2,1.35,10]],"ltp":1.51,"tv":12.72,"id":16325787}]}]}
{"op":"mcm","clk":"988450021","pt":1580477374596,"mc":[{"id":"1.168133553","rc":[{"batb":[[0,1.4,30.63],[1,1.39,3],[2,1.38,1.99]],"ltp":1.51,"tv":12.72,"id":16325787}]}]}
{"op":"mcm","clk":"988450439","pt":1580477379033,"mc":[{"id":"1.168133553","rc":[{"batb":[[0,1.41,10],[1,1.4,30.63],[2,1.39,3]],"ltp":1.51,"tv":12.72,"id":16325787}]}]}
{"op":"mcm","clk":"988450910","pt":1580477383527,"mc":[{"id":"1.168133553","rc":[{"batb":[[0,1.42,3],[1,1.41,10],[2,1.4,30.63]],"ltp":1.51,"tv":12.72,"id":16325787}]}]}
{"op":"mcm","clk":"988452531","pt":1580477398960,"mc":[{"id":"1.168133553","rc":[{"batb":[[2,1.38,1.99]],"ltp":1.51,"tv":12.72,"id":16325787}]}]}
{"op":"mcm","clk":"988456459","pt":1580477434114,"mc":[{"id":"1.168133553","rc":[{"batb":[[0,1.43,1.99],[1,1.42,3],[2,1.41,10]],"ltp":1.51,"tv":12.72,"id":16325787}]}]}
{"op":"mcm","clk":"988457427","pt":1580477443320,"mc":[{"id":"1.168133553","rc":[{"batb":[[0,1.43,4.99],[1,1.41,10],[2,1.03,1628.12]],"ltp":1.51,"tv":12.72,"id":16325787}]}]}
{"op":"mcm","clk":"988458638","pt":1580477454931,"mc":[{"id":"1.168133553","rc":[{"batb":[[0,1.44,3],[1,1.43,1.99],[2,1.41,10]],"ltp":1.51,"tv":12.72,"id":16325787}]}]}
{"op":"mcm","clk":"988459771","pt":1580477464886,"mc":[{"id":"1.168133553","rc":[{"batb":[[0,1.44,13],[2,1.03,1628.12]],"ltp":1.51,"tv":12.72,"id":16325787}]}]}
{"op":"mcm","clk":"988466369","pt":1580477519552,"mc":[{"id":"1.168133553","rc":[{"batb":[[1,1.03,1628.12],[2,1.01,4105.65]],"ltp":1.51,"tv":12.72,"id":16325787}]}]}
{"op":"mcm","clk":"988466381","pt":1580477519657,"mc":[{"id":"1.168133553","rc":[{"batb":[[2,1.02,1.99]],"ltp":1.51,"tv":12.72,"id":16325787}]}]}
{"op":"mcm","clk":"988470011","pt":1580477550311,"mc":[{"id":"1.168133553","rc":[{"batb":[[0,1.44,3],[1,1.04,10],[2,1.03,1628.12]],"ltp":1.51,"tv":12.72,"id":16325787}]}]}
{"op":"mcm","clk":"988471202","pt":1580477560530,"mc":[{"id":"1.168133553","rc":[{"batb":[[0,1.05,3]],"ltp":1.51,"tv":12.72,"id":16325787}]}]}
{"op":"mcm","clk":"988472139","pt":1580477569558,"mc":[{"id":"1.168133553","rc":[{"batb":[[0,1.06,40.46],[1,1.05,3],[2,1.04,10]],"ltp":1.51,"tv":12.72,"id":16325787}]}]}
{"op":"mcm","clk":"988472911","pt":1580477576540,"mc":[{"id":"1.168133553","rc":[{"batb":[[1,1.04,10],[2,1.03,1628.12]],"ltp":1.51,"tv":12.72,"id":16325787}]}]}
{"op":"mcm","clk":"988472919","pt":1580477576636,"mc":[{"id":"1.168133553","rc":[{"batb":[[0,1.07,3],[1,1.06,40.46],[2,1.04,10]],"ltp":1.51,"tv":12.72,"id":16325787}]}]}
{"op":"mcm","clk":"988474903","pt":1580477594403,"mc":[{"id":"1.168133553","rc":[{"batb":[[1,1.04,10],[2,1.03,1628.12]],"ltp":1.51,"tv":12.72,"id":16325787}]}]}
{"op":"mcm","clk":"988475343","pt":1580477598519,"mc":[{"id":"1.168133553","rc":[{"batb":[[0,1.08,1.99],[1,1.07,3],[2,1.04,10]],"ltp":1.51,"tv":12.72,"id":16325787}]}]}
{"op":"mcm","clk":"988476251","pt":1580477607340,"mc":[{"id":"1.168133553","rc":[{"batb":[[0,1.08,4.99],[1,1.04,10],[2,1.03,1628.12]],"ltp":1.51,"tv":12.72,"id":16325787}]}]}
{"op":"mcm","clk":"988477414","pt":1580477617831,"mc":[{"id":"1.168133553","rc":[{"batb":[[0,1.09,3],[1,1.08,1.99],[2,1.04,10]],"ltp":1.51,"tv":12.72,"id":16325787}]}]}
{"op":"mcm","clk":"988477559","pt":1580477619151,"mc":[{"id":"1.168133553","rc":[{"batb":[[0,1.1,38.98],[1,1.09,3],[2,1.08,1.99]],"ltp":1.51,"tv":12.72,"id":16325787}]}]}
{"op":"mcm","clk":"988478857","pt":1580477630460,"mc":[{"id":"1.168133553","rc":[{"batb":[[0,1.11,3],[1,1.1,38.98]],"ltp":1.51,"tv":12.72,"id":16325787}]}]}
{"op":"mcm","clk":"988479521","pt":1580477637366,"mc":[{"id":"1.168133553","rc":[{"batb":[[0,1.11,13]],"ltp":1.51,"tv":12.72,"id":16325787}]}]}
{"op":"mcm","clk":"988479568","pt":1580477637784,"mc":[{"id":"1.168133553","rc":[{"batb":[[0,1.12,3],[1,1.11,13],[2,1.1,38.98]],"ltp":1.51,"tv":12.72,"id":16325787}]}]}
{"op":"mcm","clk":"988480193","pt":1580477643346,"mc":[{"id":"1.168133553","rc":[{"batb":[[0,1.13,3],[1,1.12,3],[2,1.11,10]],"ltp":1.51,"tv":12.72,"id":16325787}]}]}
{"op":"mcm","clk":"988480273","pt":1580477644095,"mc":[{"id":"1.168133553","rc":[{"batb":[[0,1.14,37.62],[1,1.13,3],[2,1.12,3]],"ltp":1.51,"tv":12.72,"id":16325787}]}]}
{"op":"mcm","clk":"988481621","pt":1580477656472,"mc":[{"id":"1.168133553","rc":[{"batb":[[1,1.12,3],[2,1.11,10]],"ltp":1.51,"tv":12.72,"id":16325787}]}]}
{"op":"mcm","clk":"988481630","pt":1580477656575,"mc":[{"id":"1.168133553","rc":[{"batb":[[0,1.15,3],[1,1.14,37.62],[2,1.12,3]],"ltp":1.51,"tv":12.72,"id":16325787}]}]}
{"op":"mcm","clk":"988482933","pt":1580477668745,"mc":[{"id":"1.168133553","rc":[{"batb":[[1,1.12,3],[2,1.11,10]],"ltp":1.51,"tv":12.72,"id":16325787}]}]}
{"op":"mcm","clk":"988483049","pt":1580477670061,"mc":[{"id":"1.168133553","rc":[{"batb":[[0,1.13,3]],"ltp":1.51,"tv":12.72,"id":16325787}]}]}
{"op":"mcm","clk":"988483974","pt":1580477679333,"mc":[{"id":"1.168133553","rc":[{"batb":[[0,1.14,1.99],[1,1.13,3],[2,1.12,3]],"ltp":1.51,"tv":12.72,"id":16325787}]}]}
{"op":"mcm","clk":"988484307","pt":1580477682335,"mc":[{"id":"1.168133553","rc":[{"batb":[[0,1.14,4.99],[1,1.12,3],[2,1.11,10]],"ltp":1.51,"tv":12.72,"id":16325787}]}]}
{"op":"mcm","clk":"988485786","pt":1580477696309,"mc":[{"id":"1.168133553","rc":[{"batb":[[0,1.15,3],[1,1.14,1.99],[2,1.12,3]],"ltp":1.51,"tv":12.72,"id":16325787}]}]}
{"op":"mcm","clk":"988487404","pt":1580477711248,"mc":[{"id":"1.168133553","rc":[{"batb":[[0,1.14,1.99],[1,1.13,3]],"ltp":1.51,"tv":12.72,"id":16325787}]}]}
{"op":"mcm","clk":"988487954","pt":1580477716654,"mc":[{"id":"1.168133553","rc":[{"batb":[[0,1.15,37.29],[1,1.14,1.99],[2,1.13,3]],"ltp":1.51,"tv":12.72,"id":16325787}]}]}
{"op":"mcm","clk":"988488544","pt":1580477722569,"mc":[{"id":"1.168133553","rc":[{"batb":[[0,1.16,3],[1,1.15,37.29],[2,1.14,1.99]],"ltp":1.51,"tv":12.72,"id":16325787}]}]}
{"op":"mcm","clk":"988488662","pt":1580477723467,"mc":[{"id":"1.168133553","rc":[{"batb":[[1,1.15,47.29]],"ltp":1.51,"tv":12.72,"id":16325787}]}]}
{"op":"mcm","clk":"988489143","pt":1580477727373,"mc":[{"id":"1.168133553","rc":[{"batb":[[1,1.15,50.29]],"ltp":1.51,"tv":12.72,"id":16325787}]}]}
{"op":"mcm","clk":"988490461","pt":1580477740451,"mc":[{"id":"1.168133553","rc":[{"batb":[[0,1.17,36.65],[1,1.16,3],[2,1.15,13]],"ltp":1.51,"tv":12.72,"id":16325787}]}]}
{"op":"mcm","clk":"988491005","pt":1580477745476,"mc":[{"id":"1.168133553","rc":[{"batb":[[0,1.18,3],[1,1.17,36.65]],"ltp":1.51,"tv":12.72,"id":16325787}]}]}
{"op":"mcm","clk":"988491683","pt":1580477751717,"mc":[{"id":"1.168133553","rc":[{"batb":[[0,1.19,1.99],[1,1.18,3],[2,1.17,36.65]],"ltp":1.51,"tv":12.72,"id":16325787}]}]}
{"op":"mcm","clk":"988492616","pt":1580477760820,"mc":[{"id":"1.168133553","rc":[{"batb":[[0,1.19,4.99],[1,1.17,36.65],[2,1.15,13]],"ltp":1.51,"tv":12.72,"id":16325787}]}]}
{"op":"mcm","clk":"988493003","pt":1580477764613,"mc":[{"id":"1.168133553","rc":[{"batb":[[1,1.15,13],[2,1.03,1628.12]],"ltp":1.51,"tv":12.72,"id":16325787}]}]}
{"op":"mcm","clk":"988493945","pt":1580477774041,"mc":[{"id":"1.168133553","rc":[{"batb":[[0,1.2,3],[1,1.19,1.99],[2,1.15,13]],"ltp":1.51,"tv":12.72,"id":16325787}]}]}
{"op":"mcm","clk":"988495036","pt":1580477784050,"mc":[{"id":"1.168133553","rc":[{"batb":[[0,1.19,1.99],[1,1.16,3]],"ltp":1.51,"tv":12.72,"id":16325787}]}]}
{"op":"mcm","clk":"988496216","pt":1580477795201,"mc":[{"id":"1.168133553","rc":[{"batb":[[1,1.17,3]],"ltp":1.51,"tv":12.72,"id":16325787}]}]}
{"op":"mcm","clk":"988497634","pt":1580477808573,"mc":[{"id":"1.168133553","rc":[{"batb":[[1,1.15,13],[2,1.03,1628.12]],"ltp":1.51,"tv":12.72,"id":16325787}]}]}
{"op":"mcm","clk":"988497722","pt":1580477809476,"mc":[{"id":"1.168133553","rc":[{"batb":[[0,1.19,11.99],[1,1.18,3],[2,1.15,3]],"ltp":1.51,"tv":12.72,"id":16325787}]}]}
{"op":"mcm","clk":"988497880","pt":1580477811002,"mc":[{"id":"1.168133553","rc":[{"batb":[[0,1.2,3],[1,1.19,11.99],[2,1.18,3]],"ltp":1.51,"tv":12.72,"id":16325787}]}]}
{"op":"mcm","clk":"988498154","pt":1580477813892,"mc":[{"id":"1.168133553","rc":[{"batb":[[0,1.21,35.44],[1,1.2,3],[2,1.19,11.99]],"ltp":1.51,"tv":12.72,"id":16325787}]}]}
{"op":"mcm","clk":"988499156","pt":1580477823502,"mc":[{"id":"1.168133553","rc":[{"batb":[[0,1.22,1.99],[1,1.21,35.44],[2,1.2,3]],"ltp":1.51,"tv":12.72,"id":16325787}]}]}
{"op":"mcm","clk":"988499194","pt":1580477823919,"mc":[{"id":"1.168133553","rc":[{"batb":[[0,1.22,4.99]],"ltp":1.51,"tv":12.72,"id":16325787}]}]}
{"op":"mcm","clk":"988500780","pt":1580477837529,"mc":[{"id":"1.168133553","rc":[{"batb":[[1,1.2,3],[2,1.19,10]],"ltp":1.51,"tv":12.72,"id":16325787}]}]}
{"op":"mcm","clk":"988501422","pt":1580477843236,"mc":[{"id":"1.168133553","rc":[{"batb":[[0,1.23,3],[1,1.22,1.99],[2,1.2,3]],"ltp":1.51,"tv":12.72,"id":16325787}]}]}
{"op":"mcm","clk":"988511038","pt":1580477854444,"mc":[{"id":"1.168133553","rc":[{"batb":[[0,1.22,1.99],[1,1.21,3]],"ltp":1.51,"tv":12.72,"id":16325787}]}]}
{"op":"mcm","clk":"988511968","pt":1580477862637,"mc":[{"id":"1.168133553","rc":[{"batb":[[0,1.23,34.86],[1,1.22,1.99],[2,1.21,3]],"ltp":1.51,"tv":12.72,"id":16325787}]}]}
{"op":"mcm","clk":"988512351","pt":1580477865567,"mc":[{"id":"1.168133553","rc":[{"batb":[[0,1.24,3],[1,1.23,34.86],[2,1.22,1.99]],"ltp":1.51,"tv":12.72,"id":16325787}]}]}
{"op":"mcm","clk":"988514518","pt":1580477887227,"mc":[{"id":"1.168133553","rc":[{"batb":[[1,1.22,1.99],[2,1.2,3]],"ltp":1.51,"tv":12.72,"id":16325787}]}]}
{"op":"mcm","clk":"988514882","pt":1580477891325,"mc":[{"id":"1.168133553","rc":[{"batb":[[0,1.22,1.99],[1,1.21,3]],"ltp":1.51,"tv":12.72,"id":16325787}]}]}
{"op":"mcm","clk":"988515219","pt":1580477895433,"mc":[{"id":"1.168133553","rc":[{"batb":[[0,1.22,11.99]],"ltp":1.51,"tv":12.72,"id":16325787}]}]}
{"op":"mcm","clk":"988516158","pt":1580477904204,"mc":[{"id":"1.168133553","rc":[{"batb":[[0,1.23,3],[1,1.22,11.99]],"ltp":1.51,"tv":12.72,"id":16325787}]}]}
{"op":"mcm","clk":"988516760","pt":1580477910705,"mc":[{"id":"1.168133553","rc":[{"batb":[[0,1.24,34.59],[1,1.23,3],[2,1.22,11.99]],"ltp":1.51,"tv":12.72,"id":16325787}]}]}
{"op":"mcm","clk":"988517615","pt":1580477919541,"mc":[{"id":"1.168133553","rc":[{"batb":[[0,1.25,3],[1,1.24,34.59]],"ltp":1.51,"tv":12.72,"id":16325787}]}]}
{"op":"mcm","clk":"988519199","pt":1580477935251,"mc":[{"id":"1.168133553","rc":[{"batb":[[1,1.22,11.99],[2,1.2,3]],"ltp":1.51,"tv":12.72,"id":16325787}]}]}
{"op":"mcm","clk":"988520407","pt":1580477947573,"mc":[{"id":"1.168133553","rc":[{"batb":[[0,1.22,11.99],[1,1.2,3],[2,1.03,1628.12]],"ltp":1.51,"tv":12.72,"id":16325787}]}]}
{"op":"mcm","clk":"988520413","pt":1580477947679,"mc":[{"id":"1.168133553","rc":[{"batb":[[0,1.23,3],[1,1.22,11.99],[2,1.2,3]],"ltp":1.51,"tv":12.72,"id":16325787}]}]}
{"op":"mcm","clk":"988520570","pt":1580477949095,"mc":[{"id":"1.168133553","rc":[{"batb":[[0,1.23,6],[2,1.03,1628.12]],"ltp":1.51,"tv":12.72,"id":16325787}]}]}
{"op":"mcm","clk":"988521753","pt":1580477959469,"mc":[{"id":"1.168133553","rc":[{"batb":[[0,1.24,34.59],[1,1.23,6],[2,1.22,11.99]],"ltp":1.51,"tv":12.72,"id":16325787}]}]}
{"op":"mcm","clk":"988522448","pt":1580477965972,"mc":[{"id":"1.168133553","rc":[{"batb":[[0,1.25,3],[1,1.24,34.59],[2,1.23,3]],"ltp":1.51,"tv":12.72,"id":16325787}]}]}
{"op":"mcm","clk":"988522767","pt":1580477968878,"mc":[{"id":"1.168133553","rc":[{"batb":[[0,1.26,1.99],[1,1.25,3],[2,1.24,34.59]],"ltp":1.51,"tv":12.72,"id":16325787}]}]}
{"op":"mcm","clk":"988523896","pt":1580477980121,"mc":[{"id":"1.168133553","rc":[{"batb":[[0,1.26,4.99],[1,1.24,34.59],[2,1.23,3]],"ltp":1.51,"tv":12.72,"id":16325787}]}]}
{"op":"mcm","clk":"988523953","pt":1580477980703,"mc":[{"id":"1.168133553","rc":[{"batb":[[1,1.25,10],[2,1.24,34.59]],"ltp":1.51,"tv":12.72,"id":16325787}]}]}
{"op":"mcm","clk":"988524387","pt":1580477984994,"mc":[{"id":"1.168133553","rc":[{"batb":[[0,1.27,33.77],[1,1.26,4.99],[2,1.25,10]],"ltp":1.51,"tv":12.72,"id":16325787}]}]}
{"op":"mcm","clk":"988524934","pt":1580477990506,"mc":[{"id":"1.168133553","rc":[{"batb":[[1,1.26,1.99]],"ltp":1.51,"tv":12.72,"id":16325787}]}]}
{"op":"mcm","clk":"988524940","pt":1580477990614,"mc":[{"id":"1.168133553","rc":[{"batb":[[0,1.28,3],[1,1.27,33.77],[2,1.26,1.99]],"ltp":1.51,"tv":12.72,"id":16325787}]}]}
{"op":"mcm","clk":"988527034","pt":1580478009674,"mc":[{"id":"1.168133553","rc":[{"batb":[[1,1.26,1.99],[2,1.25,10]],"ltp":1.51,"tv":12.72,"id":16325787}]}]}
{"op":"mcm","clk":"988527845","pt":1580478016753,"mc":[{"id":"1.168133553","rc":[{"batb":[[0,1.26,4.99],[1,1.25,10],[2,1.23,3]],"ltp":1.51,"tv":12.72,"id":16325787}]}]}
{"op":"mcm","clk":"988528803","pt":1580478025868,"mc":[{"id":"1.168133553","rc":[{"batb":[[0,1.27,3],[1,1.26,1.99],[2,1.25,10]],"ltp":1.51,"tv":12.72,"id":16325787}]}]}
{"op":"mcm","clk":"988529521","pt":1580478033164,"mc":[{"id":"1.168133553","rc":[{"batb":[[0,1.28,33.5],[1,1.27,3],[2,1.26,1.99]],"ltp":1.51,"tv":12.72,"id":16325787}]}]}
{"op":"mcm","clk":"988529930","pt":1580478036985,"mc":[{"id":"1.168133553","rc":[{"batb":[[0,1.29,3],[1,1.28,33.5]],"ltp":1.51,"tv":12.72,"id":16325787}]}]}
{"op":"mcm","clk":"988530618","pt":1580478042492,"mc":[{"id":"1.168133553","rc":[{"batb":[[0,1.3,1.99],[1,1.29,3],[2,1.28,33.5]],"ltp":1.51,"tv":12.72,"id":16325787}]}]}
{"op":"mcm","clk":"988531597","pt":1580478051104,"mc":[{"id":"1.168133553","rc":[{"batb":[[0,1.3,4.99],[1,1.28,33.5],[2,1.25,10]],"ltp":1.51,"tv":12.72,"id":16325787}]}]}
{"op":"mcm","clk":"988532139","pt":1580478056612,"mc":[{"id":"1.168133553","rc":[{"batb":[[1,1.25,10],[2,1.03,1628.12]],"ltp":1.51,"tv":12.72,"id":16325787}]}]}
{"op":"mcm","clk":"988532553","pt":1580478060712,"mc":[{"id":"1.168133553","rc":[{"batb":[[0,1.31,3],[1,1.3,1.99],[2,1.25,10]],"ltp":1.51,"tv":12.72,"id":16325787}]}]}
{"op":"mcm","clk":"988533045","pt":1580478065929,"mc":[{"id":"1.168133553","rc":[{"batb":[[0,1.31,13],[2,1.03,1628.12]],"ltp":1.51,"tv":12.72,"id":16325787}]}]}
{"op":"mcm","clk":"988533398","pt":1580478069510,"mc":[{"id":"1.168133553","rc":[{"batb":[[0,1.32,3],[1,1.31,10],[2,1.3,1.99]],"ltp":1.51,"tv":12.72,"id":16325787}]}]}
{"op":"mcm","clk":"988534692","pt":1580478081336,"mc":[{"id":"1.168133553","rc":[{"batb":[[0,1.33,32.25],[1,1.32,3],[2,1.31,10]],"ltp":1.51,"tv":12.72,"id":16325787}]}]}
{"op":"mcm","clk":"988535638","pt":1580478090457,"mc":[{"id":"1.168133553","rc":[{"batb":[[0,1.34,3],[1,1.33,32.25]],"ltp":1.51,"tv":12.72,"id":16325787}]}]}
{"op":"mcm","clk":"988537276","pt":1580478106559,"mc":[{"id":"1.168133553","rc":[{"batb":[[1,1.31,10],[2,1.3,1.99]],"ltp":1.51,"tv":12.72,"id":16325787}]}]}
{"op":"mcm","clk":"988537794","pt":1580478111094,"mc":[{"id":"1.168133553","rc":[{"batb":[[0,1.32,3]],"ltp":1.51,"tv":12.72,"id":16325787}]}]}
{"op":"mcm","clk":"988538923","pt":1580478121390,"mc":[{"id":"1.168133553","rc":[{"batb":[[0,1.33,1.99],[1,1.32,3],[2,1.31,10]],"ltp":1.51,"tv":12.72,"id":16325787}]}]}
{"op":"mcm","clk":"988539269","pt":1580478124898,"mc":[{"id":"1.168133553","rc":[{"batb":[[0,1.33,4.99],[1,1.31,10],[2,1.03,1628.12]],"ltp":1.51,"tv":12.72,"id":16325787}]}]}
{"op":"mcm","clk":"988540594","pt":1580478139120,"mc":[{"id":"1.168133553","rc":[{"batb":[[0,1.34,3],[1,1.33,1.99],[2,1.31,10]],"ltp":1.51,"tv":12.72,"id":16325787}]}]}
{"op":"mcm","clk":"988541851","pt":1580478151238,"mc":[{"id":"1.168133553","rc":[{"batb":[[0,1.33,1.99],[1,1.32,3]],"ltp":1.51,"tv":12.72,"id":16325787}]}]}
{"op":"mcm","clk":"988541903","pt":1580478151816,"mc":[{"id":"1.168133553","rc":[{"batb":[[0,1.33,11.99],[2,1.03,1628.12]],"ltp":1.51,"tv":12.72,"id":16325787}]}]}
{"op":"mcm","clk":"988542304","pt":1580478155427,"mc":[{"id":"1.168133553","rc":[{"batb":[[0,1.34,32],[1,1.33,11.99],[2,1.32,3]],"ltp":1.51,"tv":12.72,"id":16325787}]}]}
{"op":"mcm","clk":"988543191","pt":1580478163954,"mc":[{"id":"1.168133553","rc":[{"batb":[[0,1.35,3],[1,1.34,32],[2,1.33,11.99]],"ltp":1.51,"tv":12.72,"id":16325787}]}]}
{"op":"mcm","clk":"988544726","pt":1580478179100,"mc":[{"id":"1.168133553","rc":[{"batb":[[1,1.33,11.99],[2,1.03,1628.12]],"ltp":1.51,"tv":12.72,"id":16325787}]}]}
{"op":"mcm","clk":"988544963","pt":1580478181309,"mc":[{"id":"1.168133553","rc":[{"batl":[[0,3.1,4.2],[1,1000,0]],"ltp":1.51,"tv":12.72,"id":16325787}]}]}
{"op":"mcm","clk":"988546507","pt":1580478195195,"mc":[{"id":"1.168133553","rc":[{"batb":[[0,1.34,3]],"ltp":1.51,"tv":12.72,"id":16325787}]}]}
{"op":"mcm","clk":"988546586","pt":1580478195916,"mc":[{"id":"1.168133553","rc":[{"batb":[[1,1.33,10]],"ltp":1.51,"tv":12.72,"id":16325787}]}]}
{"op":"mcm","clk":"988547441","pt":1580478203514,"mc":[{"id":"1.168133553","rc":[{"batb":[[0,1.35,31.77],[1,1.34,3],[2,1.33,10]],"ltp":1.51,"tv":12.72,"id":16325787}]}]}
{"op":"mcm","clk":"988548023","pt":1580478209219,"mc":[{"id":"1.168133553","rc":[{"batb":[[0,1.36,3],[1,1.35,31.77]],"ltp":1.51,"tv":12.72,"id":16325787}]}]}
{"op":"mcm","clk":"988550215","pt":1580478228876,"mc":[{"id":"1.168133553","rc":[{"batb":[[1,1.33,10],[2,1.03,1628.12]],"ltp":1.51,"tv":12.72,"id":16325787}]}]}
{"op":"mcm","clk":"988550540","pt":1580478232046,"mc":[{"id":"1.168133553","rc":[{"batb":[[0,1.34,3]],"ltp":1.51,"tv":12.72,"id":16325787}]}]}
{"op":"mcm","clk":"988551166","pt":1580478238170,"mc":[{"id":"1.168133553","rc":[{"batb":[[1,1.04,10]],"ltp":1.51,"tv":12.72,"id":16325787}]}]}
{"op":"mcm","clk":"988552063","pt":1580478246178,"mc":[{"id":"1.168133553","rc":[{"batb":[[0,1.05,3]],"ltp":1.51,"tv":12.72,"id":16325787}]}]}
{"op":"mcm","clk":"988552752","pt":1580478252710,"mc":[{"id":"1.168133553","rc":[{"batb":[[0,1.06,40.46],[1,1.05,3],[2,1.04,10]],"ltp":1.51,"tv":12.72,"id":16325787}]}]}
{"op":"mcm","clk":"988553522","pt":1580478259919,"mc":[{"id":"1.168133553","rc":[{"batb":[[0,1.07,3],[1,1.06,40.46]],"ltp":1.51,"tv":12.72,"id":16325787}]}]}
{"op":"mcm","clk":"988555319","pt":1580478276643,"mc":[{"id":"1.168133553","rc":[{"batb":[[1,1.04,10],[2,1.03,1628.12]],"ltp":1.51,"tv":12.72,"id":16325787}]}]}
{"op":"mcm","clk":"988555693","pt":1580478279637,"mc":[{"id":"1.168133553","rc":[{"batb":[[0,1.08,1.99],[1,1.07,3],[2,1.04,10]],"ltp":1.51,"tv":12.72,"id":16325787}]}]}
{"op":"mcm","clk":"988556569","pt":1580478286632,"mc":[{"id":"1.168133553","rc":[{"batb":[[0,1.08,4.99],[1,1.04,10],[2,1.03,1628.12]],"ltp":1.51,"tv":12.72,"id":16325787}]}]}
{"op":"mcm","clk":"988558053","pt":1580478301078,"mc":[{"id":"1.168133553","rc":[{"batb":[[0,1.09,3],[1,1.08,1.99],[2,1.04,10]],"ltp":1.51,"tv":12.72,"id":16325787}]}]}
{"op":"mcm","clk":"988559540","pt":1580478315874,"mc":[{"id":"1.168133553","rc":[{"batb":[[0,1.08,1.99],[1,1.05,3]],"ltp":1.51,"tv":12.72,"id":16325787}]}]}
{"op":"mcm","clk":"988560247","pt":1580478323520,"mc":[{"id":"1.168133553","rc":[{"batb":[[2,1.03,1628.12]],"ltp":1.51,"tv":12.72,"id":16325787}]}]}
{"op":"mcm","clk":"988560263","pt":1580478323689,"mc":[{"id":"1.168133553","rc":[{"batb":[[1,1.06,10],[2,1.05,3]],"ltp":1.51,"tv":12.72,"id":16325787}]}]}
{"op":"mcm","clk":"988560733","pt":1580478329174,"mc":[{"id":"1.168133553","rc":[{"batb":[[1,1.07,3],[2,1.06,10]],"ltp":1.51,"tv":12.72,"id":16325787}]}]}
{"op":"mcm","clk":"988561926","pt":1580478341173,"mc":[{"id":"1.168133553","rc":[{"batb":[[0,1.08,4.99],[1,1.06,10],[2,1.04,6]],"ltp":1.51,"tv":12.72,"id":16325787}]}]}
{"op":"mcm","clk":"988563437","pt":1580478355979,"mc":[{"id":"1.168133553","rc":[{"batb":[[0,1.09,3],[1,1.08,1.99],[2,1.06,10]],"ltp":1.51,"tv":12.72,"id":16325787}]}]}
{"op":"mcm","clk":"988564749","pt":1580478368786,"mc":[{"id":"1.168133553","rc":[{"batb":[[0,1.08,1.99],[1,1.07,3]],"ltp":1.51,"tv":12.72,"id":16325787}]}]}
{"op":"mcm","clk":"988565135","pt":1580478372814,"mc":[{"id":"1.168133553","rc":[{"batb":[[0,1.09,39.35],[1,1.08,1.99],[2,1.07,3]],"ltp":1.51,"tv":12.72,"id":16325787}]}]}
{"op":"mcm","clk":"988566029","pt":1580478381710,"mc":[{"id":"1.168133553","rc":[{"batb":[[0,1.1,3],[1,1.09,39.35],[2,1.08,1.99]],"ltp":1.51,"tv":12.72,"id":16325787}]}]}
{"op":"mcm","clk":"988567613","pt":1580478398203,"mc":[{"id":"1.168133553","rc":[{"batb":[[1,1.08,1.99],[2,1.06,10]],"ltp":1.51,"tv":12.72,"id":16325787}]}]}
{"op":"mcm","clk":"988568416","pt":1580478406095,"mc":[{"id":"1.168133553","rc":[{"batb":[[2,1.04,6]],"ltp":1.51,"tv":12.72,"id":16325787}]}]}
{"op":"mcm","clk":"988568543","pt":1580478407514,"mc":[{"id":"1.168133553","rc":[{"batb":[[0,1.08,1.99],[1,1.05,3]],"ltp":1.51,"tv":12.72,"id":16325787}]}]}
{"op":"mcm","clk":"988569549","pt":1580478416845,"mc":[{"id":"1.168133553","rc":[{"batb":[[1,1.06,3]],"ltp":1.51,"tv":12.72,"id":16325787}]}]}
{"op":"mcm","clk":"988570916","pt":1580478430862,"mc":[{"id":"1.168133553","rc":[{"batb":[[1,1.07,3]],"ltp":1.51,"tv":12.72,"id":16325787}]}]}
{"op":"mcm","clk":"988572424","pt":1580478446975,"mc":[{"id":"1.168133553","rc":[{"batb":[[0,1.08,4.99],[1,1.04,6],[2,1.03,1628.12]],"ltp":1.51,"tv":12.72,"id":16325787}]}]}
{"op":"mcm","clk":"988573854","pt":1580478460331,"mc":[{"id":"1.168133553","rc":[{"batb":[[0,1.09,3],[1,1.08,1.99],[2,1.04,6]],"ltp":1.51,"tv":12.72,"id":16325787}]}]}
{"op":"mcm","clk":"988575051","pt":1580478471510,"mc":[{"id":"1.168133553","rc":[{"batb":[[0,1.08,1.99],[1,1.05,3]],"ltp":1.51,"tv":12.72,"id":16325787}]}]}
{"op":"mcm","clk":"988575404","pt":1580478475146,"mc":[{"id":"1.168133553","rc":[{"batb":[[1,1.05,6]],"ltp":1.51,"tv":12.72,"id":16325787}]}]}
{"op":"mcm","clk":"988576190","pt":1580478482943,"mc":[{"id":"1.168133553","rc":[{"batb":[[1,1.06,3],[2,1.05,3]],"ltp":1.51,"tv":12.72,"id":16325787}]}]}
{"op":"mcm","clk":"988577494","pt":1580478496175,"mc":[{"id":"1.168133553","rc":[{"batb":[[1,1.07,3]],"ltp":1.51,"tv":12.72,"id":16325787}]}]}
{"op":"mcm","clk":"988577564","pt":1580478496924,"mc":[{"id":"1.168133553","rc":[{"batb":[[0,1.09,39.35],[1,1.08,1.99],[2,1.07,3]],"ltp":1.51,"tv":12.72,"id":16325787}]}]}
{"op":"mcm","clk":"988578952","pt":1580478511441,"mc":[{"id":"1.168133553","rc":[{"batb":[[0,1.1,3],[1,1.09,39.35],[2,1.08,1.99]],"ltp":1.51,"tv":12.72,"id":16325787}]}]}
{"op":"mcm","clk":"988579849","pt":1580478521119,"mc":[{"id":"1.168133553","rc":[{"batb":[[0,1.11,1.99],[1,1.1,3],[2,1.05,3]],"ltp":1.51,"tv":12.72,"id":16325787}]}]}
{"op":"mcm","clk":"988580396","pt":1580478527446,"mc":[{"id":"1.168133553","rc":[{"batb":[[0,1.11,4.99],[1,1.05,3],[2,1.04,6]],"ltp":1.51,"tv":12.72,"id":16325787}]}]}
{"op":"mcm","clk":"988581982","pt":1580478545351,"mc":[{"id":"1.168133553","rc":[{"batb":[[0,1.12,3],[1,1.11,1.99],[2,1.05,3]],"ltp":1.51,"tv":12.72,"id":16325787}]}]}
{"op":"mcm","clk":"988582055","pt":1580478546185,"mc":[{"id":"1.168133553","rc":[{"batb":[[0,1.13,37.95],[1,1.12,3],[2,1.11,1.99]],"ltp":1.51,"tv":12.72,"id":16325787}]}]}
{"op":"mcm","clk":"988583467","pt":1580478562473,"mc":[{"id":"1.168133553","rc":[{"batb":[[1,1.11,1.99],[2,1.04,6]],"ltp":1.51,"tv":12.72,"id":16325787}]}]}
{"op":"mcm","clk":"988583476","pt":1580478562577,"mc":[{"id":"1.168133553","rc":[{"batb":[[0,1.14,3],[1,1.13,37.95],[2,1.11,1.99]],"ltp":1.51,"tv":12.72,"id":16325787}]}]}
{"op":"mcm","clk":"988584217","pt":1580478570434,"mc":[{"id":"1.168133553","rc":[{"batb":[[1,1.11,1.99],[2,1.04,6]],"ltp":1.51,"tv":12.72,"id":16325787}]}]}
{"op":"mcm","clk":"988584628","pt":1580478575446,"mc":[{"id":"1.168133553","rc":[{"batb":[[0,1.11,1.99],[1,1.05,3]],"ltp":1.51,"tv":12.72,"id":16325787}]}]}
{"op":"mcm","clk":"988584804","pt":1580478577462,"mc":[{"id":"1.168133553","rc":[{"batb":[[1,1.06,10],[2,1.05,3]],"ltp":1.51,"tv":12.72,"id":16325787}]}]}
{"op":"mcm","clk":"988585790","pt":1580478590283,"mc":[{"id":"1.168133553","rc":[{"batb":[[1,1.07,3],[2,1.06,10]],"ltp":1.51,"tv":12.72,"id":16325787}]}]}
{"op":"mcm","clk":"988586336","pt":1580478596887,"mc":[{"id":"1.168133553","rc":[{"batb":[[0,1.08,1.99]],"ltp":1.51,"tv":12.72,"id":16325787}]}]}
{"op":"mcm","clk":"988587297","pt":1580478608122,"mc":[{"id":"1.168133553","rc":[{"batb":[[0,1.08,4.99],[1,1.06,10],[2,1.04,6]],"ltp":1.51,"tv":12.72,"id":16325787}]}]}
{"op":"mcm","clk":"988588242","pt":1580478618417,"mc":[{"id":"1.168133553","rc":[{"batb":[[0,1.09,3],[1,1.08,1.99],[2,1.06,10]],"ltp":1.51,"tv":12.72,"id":16325787}]}]}
{"op":"mcm","clk":"988588461","pt":1580478620900,"mc":[{"id":"1.168133553","rc":[{"batb":[[0,1.1,38.98],[1,1.09,3],[2,1.08,1.99]],"ltp":1.51,"tv":12.72,"id":16325787}]}]}
{"op":"mcm","clk":"988589168","pt":1580478629207,"mc":[{"id":"1.168133553","rc":[{"batb":[[0,1.11,3],[1,1.1,38.98]],"ltp":1.51,"tv":12.72,"id":16325787}]}]}
{"op":"mcm","clk":"988590482","pt":1580478644294,"mc":[{"id":"1.168133553","rc":[{"batb":[[1,1.08,1.99],[2,1.06,10]],"ltp":1.51,"tv":12.72,"id":16325787}]}]}
{"op":"mcm","clk":"988591376","pt":1580478654901,"mc":[{"id":"1.168133553","rc":[{"batb":[[0,1.08,1.99],[1,1.07,3]],"ltp":1.51,"tv":12.72,"id":16325787}]}]}
{"op":"mcm","clk":"988592091","pt":1580478663476,"mc":[{"id":"1.168133553","rc":[{"batb":[[0,1.08,11.99],[2,1.04,6]],"ltp":1.51,"tv":12.72,"id":16325787}]}]}
{"op":"mcm","clk":"988592390","pt":1580478667207,"mc":[{"id":"1.168133553","rc":[{"batb":[[0,1.09,3],[1,1.08,11.99]],"ltp":1.51,"tv":12.72,"id":16325787}]}]}
{"op":"mcm","clk":"988592547","pt":1580478669325,"mc":[{"id":"1.168133553","rc":[{"batb":[[0,1.1,38.98],[1,1.09,3],[2,1.08,11.99]],"ltp":1.51,"tv":12.72,"id":16325787}]}]}
{"op":"mcm","clk":"988592869","pt":1580478673896,"mc":[{"id":"1.168133553","rc":[{"batb":[[0,1.11,1.99],[1,1.1,38.98],[2,1.09,3]],"ltp":1.51,"tv":12.72,"id":16325787}]}]}
{"op":"mcm","clk":"988593365","pt":1580478680707,"mc":[{"id":"1.168133553","rc":[{"batb":[[0,1.11,4.99],[2,1.08,10]],"ltp":1.51,"tv":12.72,"id":16325787}]}]}
{"op":"mcm","clk":"988594211","pt":1580478691954,"mc":[{"id":"1.168133553","rc":[{"batb":[[0,1.11,7.99]],"ltp":1.51,"tv":12.72,"id":16325787}]}]}
{"op":"mcm","clk":"988594297","pt":1580478693148,"mc":[{"id":"1.168133553","rc":[{"batb":[[1,1.08,10],[2,1.04,6]],"ltp":1.51,"tv":12.72,"id":16325787}]}]}
{"op":"mcm","clk":"988594462","pt":1580478694958,"mc":[{"id":"1.168133553","rc":[{"batb":[[0,1.12,3],[1,1.11,4.99],[2,1.08,10]],"ltp":1.51,"tv":12.72,"id":16325787}]}]}
{"op":"mcm","clk":"988596277","pt":1580478717389,"mc":[{"id":"1.168133553","rc":[{"batb":[[0,1.13,37.95],[1,1.12,3],[2,1.11,4.99]],"ltp":1.51,"tv":12.72,"id":16325787}]}]}
{"op":"mcm","clk":"988596685","pt":1580478722701,"mc":[{"id":"1.168133553","rc":[{"batb":[[0,1.14,3],[1,1.13,37.95]],"ltp":1.51,"tv":12.72,"id":16325787}]}]}
{"op":"mcm","clk":"988598134","pt":1580478741445,"mc":[{"id":"1.168133553","rc":[{"batb":[[1,1.11,4.99],[2,1.08,10]],"ltp":1.51,"tv":12.72,"id":16325787}]}]}
{"op":"mcm","clk":"988598831","pt":1580478749524,"mc":[{"id":"1.168133553","rc":[{"batb":[[1,1.12,10],[2,1.11,3]],"ltp":1.51,"tv":12.72,"id":16325787}]}]}
{"op":"mcm","clk":"988598845","pt":1580478749630,"mc":[{"id":"1.168133553","rc":[{"batb":[[0,1.15,1.99],[1,1.14,3],[2,1.12,10]],"ltp":1.51,"tv":12.72,"id":16325787}]}]}
{"op":"mcm","clk":"988607461","pt":1580478753058,"mc":[{"id":"1.168133553","rc":[{"batb":[[0,1.15,4.99],[1,1.12,10],[2,1.11,3]],"ltp":1.51,"tv":12.72,"id":16325787}]}]}
{"op":"mcm","clk":"988608519","pt":1580478766240,"mc":[{"id":"1.168133553","rc":[{"batb":[[0,1.16,3],[1,1.15,1.99],[2,1.12,10]],"ltp":1.51,"tv":12.72,"id":16325787}]}]}
{"op":"mcm","clk":"988608555","pt":1580478766655,"mc":[{"id":"1.168133553","rc":[{"batb":[[0,1.17,36.65],[1,1.16,3],[2,1.15,1.99]],"ltp":1.51,"tv":12.72,"id":16325787}]}]}
{"op":"mcm","clk":"988609416","pt":1580478778563,"mc":[{"id":"1.168133553","rc":[{"batb":[[1,1.15,1.99],[2,1.12,10]],"ltp":1.51,"tv":12.72,"id":16325787}]}]}
{"op":"mcm","clk":"988609420","pt":1580478778668,"mc":[{"id":"1.168133553","rc":[{"batb":[[0,1.18,3],[1,1.17,36.65],[2,1.15,1.99]],"ltp":1.51,"tv":12.72,"id":16325787}]}]}
{"op":"mcm","clk":"988610254","pt":1580478790856,"mc":[{"id":"1.168133553","rc":[{"batb":[[1,1.15,1.99],[2,1.12,10]],"ltp":1.51,"tv":12.72,"id":16325787}]}]}
{"op":"mcm","clk":"988610396","pt":1580478793153,"mc":[{"id":"1.168133553","rc":[{"batb":[[0,1.15,1.99],[1,1.13,3]],"ltp":1.51,"tv":12.72,"id":16325787}]}]}
{"op":"mcm","clk":"988611419","pt":1580478807172,"mc":[{"id":"1.168133553","rc":[{"batb":[[1,1.14,3]],"ltp":1.51,"tv":12.72,"id":16325787}]}]}
{"op":"mcm","clk":"988612066","pt":1580478815296,"mc":[{"id":"1.168133553","rc":[{"batb":[[0,1.16,36.97],[1,1.15,1.99],[2,1.14,3]],"ltp":1.51,"tv":12.72,"id":16325787}]}]}
{"op":"mcm","clk":"988612697","pt":1580478822906,"mc":[{"id":"1.168133553","rc":[{"batb":[[0,1.17,3],[1,1.16,36.97],[2,1.15,1.99]],"ltp":1.51,"tv":12.72,"id":16325787}]}]}
{"op":"mcm","clk":"988612915","pt":1580478826313,"mc":[{"id":"1.168133553","rc":[{"batb":[[0,1.18,1.99],[1,1.17,3],[2,1.16,36.97]],"ltp":1.51,"tv":12.72,"id":16325787}]}]}
{"op":"mcm","clk":"988613362","pt":1580478832120,"mc":[{"id":"1.168133553","rc":[{"batb":[[2,1.16,39.97]],"ltp":1.51,"tv":12.72,"id":16325787}]}]}
{"op":"mcm","clk":"988613542","pt":1580478834103,"mc":[{"id":"1.168133553","rc":[{"batb":[[0,1.18,11.99]],"ltp":1.51,"tv":12.72,"id":16325787}]}]}
{"op":"mcm","clk":"988613741","pt":1580478836720,"mc":[{"id":"1.168133553","rc":[{"batb":[[0,1.19,3],[1,1.18,11.99]],"ltp":1.51,"tv":12.72,"id":16325787}]}]}
{"op":"mcm","clk":"988613941","pt":1580478839425,"mc":[{"id":"1.168133553","rc":[{"batb":[[0,1.2,35.74],[1,1.19,3],[2,1.18,11.99]],"ltp":1.51,"tv":12.72,"id":16325787}]}]}
{"op":"mcm","clk":"988614599","pt":1580478848508,"mc":[{"id":"1.168133553","rc":[{"batb":[[1,1.18,11.99],[2,1.16,3]],"ltp":1.51,"tv":12.72,"id":16325787}]}]}
{"op":"mcm","clk":"988614606","pt":1580478848612,"mc":[{"id":"1.168133553","rc":[{"batb":[[0,1.21,3],[1,1.2,35.74],[2,1.18,11.99]],"ltp":1.51,"tv":12.72,"id":16325787}]}]}
{"op":"mcm","clk":"988615594","pt":1580478863783,"mc":[{"id":"1.168133553","rc":[{"batb":[[1,1.18,11.99],[2,1.16,3]],"ltp":1.51,"tv":12.72,"id":16325787}]}]}
{"op":"mcm","clk":"988616016","pt":1580478869912,"mc":[{"id":"1.168133553","rc":[{"batb":[[0,1.19,3]],"ltp":1.51,"tv":12.72,"id":16325787}]}]}
{"op":"mcm","clk":"988617256","pt":1580478888849,"mc":[{"id":"1.168133553","rc":[{"batb":[[0,1.2,35.74],[1,1.19,3],[2,1.18,11.99]],"ltp":1.51,"tv":12.72,"id":16325787}]}]}
{"op":"mcm","clk":"988617482","pt":1580478892558,"mc":[{"id":"1.168133553","rc":[{"batb":[[0,1.21,3],[1,1.2,35.74]],"ltp":1.51,"tv":12.72,"id":16325787}]}]}
{"op":"mcm","clk":"988617855","pt":1580478898350,"mc":[{"id":"1.168133553","rc":[{"batb":[[0,1.22,1.99],[1,1.21,3],[2,1.2,35.74]],"ltp":1.51,"tv":12.72,"id":16325787}]}]}
{"op":"mcm","clk":"988618286","pt":1580478904967,"mc":[{"id":"1.168133553","rc":[{"batb":[[0,1.22,4.99],[1,1.2,35.74],[2,1.18,10]],"ltp":1.51,"tv":12.72,"id":16325787}]}]}
{"op":"mcm","clk":"988618859","pt":1580478913475,"mc":[{"id":"1.168133553","rc":[{"batb":[[1,1.18,10],[2,1.16,3]],"ltp":1.51,"tv":12.72,"id":16325787}]}]}
{"op":"mcm","clk":"988619239","pt":1580478919171,"mc":[{"id":"1.168133553","rc":[{"batb":[[1,1.16,13],[2,1.03,1628.12]],"ltp":1.51,"tv":12.72,"id":16325787}]}]}
{"op":"mcm","clk":"988619320","pt":1580478920169,"mc":[{"id":"1.168133553","rc":[{"batb":[[0,1.23,3],[1,1.22,1.99],[2,1.16,13]],"ltp":1.51,"tv":12.72,"id":16325787}]}]}
{"op":"mcm","clk":"988620381","pt":1580478934180,"mc":[{"id":"1.168133553","rc":[{"batb":[[0,1.22,1.99],[1,1.17,3]],"ltp":1.51,"tv":12.72,"id":16325787}]}]}
{"op":"mcm","clk":"988621326","pt":1580478948285,"mc":[{"id":"1.168133553","rc":[{"batb":[[1,1.18,3]],"ltp":1.51,"tv":12.72,"id":16325787}]}]}
{"op":"mcm","clk":"988622504","pt":1580478965801,"mc":[{"id":"1.168133553","rc":[{"batb":[[1,1.19,3]],"ltp":1.51,"tv":12.72,"id":16325787}]}]}
{"op":"mcm","clk":"988623598","pt":1580478981437,"mc":[{"id":"1.168133553","rc":[{"batb":[[0,1.2,1.99]],"ltp":1.51,"tv":12.72,"id":16325787}]}]}
{"op":"mcm","clk":"988623700","pt":1580478983019,"mc":[{"id":"1.168133553","rc":[{"batb":[[0,1.2,4.99],[1,1.16,13],[2,1.03,1628.12]],"ltp":1.51,"tv":12.72,"id":16325787}]}]}
{"op":"mcm","clk":"988624787","pt":1580478999569,"mc":[{"id":"1.168133553","rc":[{"batb":[[0,1.21,3],[1,1.2,1.99],[2,1.16,13]],"ltp":1.51,"tv":12.72,"id":16325787}]}]}
{"op":"mcm","clk":"988625080","pt":1580479004471,"mc":[{"id":"1.168133553","rc":[{"batb":[[0,1.21,13],[2,1.16,3]],"ltp":1.51,"tv":12.72,"id":16325787}]}]}
{"op":"mcm","clk":"988625486","pt":1580479010066,"mc":[{"id":"1.168133553","rc":[{"batb":[[0,1.22,3],[1,1.21,10],[2,1.2,1.99]],"ltp":1.51,"tv":12.72,"id":16325787}]}]}
{"op":"mcm","clk":"988625610","pt":1580479011864,"mc":[{"id":"1.168133553","rc":[{"batb":[[0,1.23,34.86],[1,1.22,3],[2,1.21,10]],"ltp":1.51,"tv":12.72,"id":16325787}]}]}
{"op":"mcm","clk":"988626246","pt":1580479022181,"mc":[{"id":"1.168133553","rc":[{"batb":[[0,1.24,3],[1,1.23,34.86]],"ltp":1.51,"tv":12.72,"id":16325787}]}]}
{"op":"mcm","clk":"988627146","pt":1580479035248,"mc":[{"id":"1.168133553","rc":[{"batb":[[1,1.21,10],[2,1.2,1.99]],"ltp":1.51,"tv":12.72,"id":16325787}]}]}
{"op":"mcm","clk":"988627841","pt":1580479045496,"mc":[{"id":"1.168133553","rc":[{"batb":[[0,1.22,3]],"ltp":1.51,"tv":12.72,"id":16325787}]}]}
{"op":"mcm","clk":"988628114","pt":1580479049200,"mc":[{"id":"1.168133553","rc":[{"batb":[[0,1.23,1.99],[1,1.22,3],[2,1.21,10]],"ltp":1.51,"tv":12.72,"id":16325787}]}]}
{"op":"mcm","clk":"988628613","pt":1580479056810,"mc":[{"id":"1.168133553","rc":[{"batb":[[0,1.23,4.99],[1,1.21,10],[2,1.03,1628.12]],"ltp":1.51,"tv":12.72,"id":16325787}]}]}
{"op":"mcm","clk":"988629291","pt":1580479067493,"mc":[{"id":"1.168133553","rc":[{"batb":[[0,1.24,3],[1,1.23,1.99],[2,1.21,10]],"ltp":1.51,"tv":12.72,"id":16325787}]}]}
{"op":"mcm","clk":"988630102","pt":1580479078441,"mc":[{"id":"1.168133553","rc":[{"batb":[[0,1.23,1.99],[1,1.22,3]],"ltp":1.51,"tv":12.72,"id":16325787}]}]}
{"op":"mcm","clk":"988630494","pt":1580479083527,"mc":[{"id":"1.168133553","rc":[{"batb":[[0,1.24,34.59],[1,1.23,1.99],[2,1.22,3]],"ltp":1.51,"tv":12.72,"id":16325787}]}]}
{"op":"mcm","clk":"988631226","pt":1580479093108,"mc":[{"id":"1.168133553","rc":[{"batb":[[0,1.25,3],[1,1.24,34.59],[2,1.23,1.99]],"ltp":1.51,"tv":12.72,"id":16325787}]}]}
{"op":"mcm","clk":"988631687","pt":1580479098509,"mc":[{"id":"1.168133553","rc":[{"batb":[[0,1.25,13]],"ltp":1.51,"tv":12.72,"id":16325787}]}]}
{"op":"mcm","clk":"988632453","pt":1580479107016,"mc":[{"id":"1.168133553","rc":[{"batb":[[1,1.23,1.99],[2,1.03,1628.12]],"ltp":1.51,"tv":12.72,"id":16325787}]}]}
{"op":"mcm","clk":"988632792","pt":1580479112437,"mc":[{"id":"1.168133553","rc":[{"batb":[[0,1.26,3],[1,1.25,10],[2,1.23,1.99]],"ltp":1.51,"tv":12.72,"id":16325787}]}]}
{"op":"mcm","clk":"988632852","pt":1580479113331,"mc":[{"id":"1.168133553","rc":[{"batb":[[0,1.27,1.99],[1,1.26,3],[2,1.25,10]],"ltp":1.51,"tv":12.72,"id":16325787}]}]}
{"op":"mcm","clk":"988633972","pt":1580479128219,"mc":[{"id":"1.168133553","rc":[{"batb":[[0,1.27,4.99],[1,1.25,10],[2,1.03,1628.12]],"ltp":1.51,"tv":12.72,"id":16325787}]}]}
{"op":"mcm","clk":"988634992","pt":1580479143464,"mc":[{"id":"1.168133553","rc":[{"batb":[[0,1.28,3],[1,1.27,1.99],[2,1.25,10]],"ltp":1.51,"tv":12.72,"id":16325787}]}]}
{"op":"mcm","clk":"988635203","pt":1580479146138,"mc":[{"id":"1.168133553","rc":[{"batb":[[2,1.26,3]],"ltp":1.51,"tv":12.72,"id":16325787}]}]}
{"op":"mcm","clk":"988635781","pt":1580479154752,"mc":[{"id":"1.168133553","rc":[{"batb":[[0,1.27,4.99],[1,1.26,3],[2,1.25,10]],"ltp":1.51,"tv":12.72,"id":16325787}]}]}
{"op":"mcm","clk":"988635919","pt":1580479156798,"mc":[{"id":"1.168133553","rc":[{"batb":[[0,1.28,33.5],[1,1.27,4.99],[2,1.26,3]],"ltp":1.51,"tv":12.72,"id":16325787}]}]}
{"op":"mcm","clk":"988636834","pt":1580479168882,"mc":[{"id":"1.168133553","rc":[{"batb":[[0,1.29,3],[1,1.28,33.5],[2,1.27,1.99]],"ltp":1.51,"tv":12.72,"id":16325787}]}]}
{"op":"mcm","clk":"988637589","pt":1580479179736,"mc":[{"id":"1.168133553","rc":[{"batb":[[0,1.3,1.99],[1,1.29,3],[2,1.28,33.5]],"ltp":1.51,"tv":12.72,"id":16325787}]}]}
{"op":"mcm","clk":"988637708","pt":1580479181419,"mc":[{"id":"1.168133553","rc":[{"batb":[[0,1.31,32.74],[1,1.3,1.99],[2,1.29,3]],"ltp":1.51,"tv":12.72,"id":16325787}]}]}
{"op":"mcm","clk":"988637800","pt":1580479183031,"mc":[{"id":"1.168133553","rc":[{"batb":[[0,1.32,3],[1,1.31,32.74],[2,1.3,1.99]],"ltp":1.51,"tv":12.72,"id":16325787}]}]}
{"op":"mcm","clk":"988638337","pt":1580479188844,"mc":[{"id":"1.168133553","rc":[{"batb":[[0,1.32,13]],"ltp":1.51,"tv":12.72,"id":16325787}]}]}
{"op":"mcm","clk":"988638931","pt":1580479196752,"mc":[{"id":"1.168133553","rc":[{"batb":[[0,2,1.68],[1,1.54,1.99],[2,1.53,10]],"ltp":0.0,"tv":0.0,"id":27227336},{"batb":[[0,1.33,3],[1,1.32,10],[2,1.31,32.74]],"ltp":1.51,"tv":12.72,"id":16325787}]}]}
{"op":"mcm","clk":"988639055","pt":1580479198331,"mc":[{"id":"1.168133553","rc":[{"batb":[[0,1.54,1.99],[1,1.53,10],[2,1.52,1.09]],"ltp":0.0,"tv":0.0,"id":27227336}]}]}
{"op":"mcm","clk":"988639701","pt":1580479205258,"mc":[{"id":"1.168133553","rc":[{"batb":[[2,1.52,1.09]],"ltp":0.0,"tv":0.0,"id":27227336},{"batb":[[2,1.52,1.09]],"ltp":0.0,"tv":0.0,"id":21641292},{"batb":[[0,1.34,32.01],[1,1.33,3],[2,1.32,10]],"ltp":1.51,"tv":12.72,"id":16325787}]}]}
{"op":"mcm","clk":"988640129","pt":1580479210399,"mc":[{"id":"1.168133553","rc":[{"batb":[[0,1.35,3],[1,1.34,32.01]],"ltp":1.51,"tv":12.72,"id":16325787}]}]}
{"op":"mcm","clk":"988641777","pt":1580479230228,"mc":[{"id":"1.168133553","rc":[{"batb":[[1,1.32,10],[2,1.3,1.99]],"ltp":1.51,"tv":12.72,"id":16325787}]}]}
{"op":"mcm","clk":"988642731","pt":1580479242498,"mc":[{"id":"1.168133553","rc":[{"batb":[[0,1.33,3]],"ltp":1.51,"tv":12.72,"id":16325787}]}]}
{"op":"mcm","clk":"988643793","pt":1580479253937,"mc":[{"id":"1.168133553","rc":[{"batb":[[0,1.34,34],[1,1.33,3],[2,1.32,10]],"ltp":1.51,"tv":12.72,"id":16325787}]}]}
{"op":"mcm","clk":"988643960","pt":1580479255820,"mc":[{"id":"1.168133553","rc":[{"batb":[[0,1.35,3],[1,1.34,34]],"ltp":1.51,"tv":12.72,"id":16325787}]}]}
{"op":"mcm","clk":"988646168","pt":1580479278473,"mc":[{"id":"1.168133553","rc":[{"batb":[[0,1.36,31.54],[1,1.35,3],[2,1.34,1.99]],"ltp":1.51,"tv":12.72,"id":16325787}]}]}
{"op":"mcm","clk":"988646315","pt":1580479280187,"mc":[{"id":"1.168133553","rc":[{"batb":[[1,1.52,1.09],[2,1.51,3.36]],"ltp":0.0,"tv":0.0,"id":27227336},{"batb":[[1,1.52,1.09],[2,1.51,3.36]],"ltp":0.0,"tv":0.0,"id":21641292}]}]}
{"op":"mcm","clk":"988647040","pt":1580479288110,"mc":[{"id":"1.168133553","rc":[{"batb":[[0,1.37,3],[1,1.36,31.54]],"ltp":1.51,"tv":12.72,"id":16325787}]}]}
{"op":"mcm","clk":"988648366","pt":1580479302980,"mc":[{"id":"1.168133553","rc":[{"batb":[[1,1.34,1.99],[2,1.03,1628.39]],"ltp":1.51,"tv":12.72,"id":16325787}]}]}
{"op":"mcm","clk":"988649446","pt":1580479311005,"mc":[{"id":"1.168133553","rc":[{"batb":[[0,1.34,1.99],[1,1.04,3]],"ltp":1.51,"tv":12.72,"id":16325787}]}]}
{"op":"mcm","clk":"988650970","pt":1580479325527,"mc":[{"id":"1.168133553","rc":[{"batb":[[1,1.03,1628.39],[2,1.01,4105.85]],"ltp":1.51,"tv":12.72,"id":16325787}]}]}
{"op":"mcm","clk":"988650983","pt":1580479325634,"mc":[{"id":"1.168133553","rc":[{"batb":[[1,1.05,3],[2,1.03,1628.39]],"ltp":1.51,"tv":12.72,"id":16325787}]}]}
{"op":"mcm","clk":"988651629","pt":1580479334143,"mc":[{"id":"1.168133553","rc":[{"batb":[[0,1.06,1.99]],"ltp":1.51,"tv":12.72,"id":16325787}]}]}
{"op":"mcm","clk":"988651695","pt":1580479335232,"mc":[{"id":"1.168133553","rc":[{"batb":[[0,1.53,1.99]],"ltp":0.0,"tv":0.0,"id":27227336},{"batb":[[0,1.53,1.99]],"ltp":0.0,"tv":0.0,"id":21641292}]}]}
{"op":"mcm","clk":"988652811","pt":1580479343053,"mc":[{"id":"1.168133553","rc":[{"batb":[[0,1.06,4.99],[1,1.03,1628.39],[2,1.01,4105.85]],"ltp":1.51,"tv":12.72,"id":16325787}]}]}
{"op":"mcm","clk":"988653204","pt":1580479345961,"mc":[{"id":"1.168133553","rc":[{"batb":[[1,1.04,6],[2,1.03,1628.39]],"ltp":1.51,"tv":12.72,"id":16325787}]}]}
{"op":"mcm","clk":"988653965","pt":1580479353263,"mc":[{"id":"1.168133553","rc":[{"batb":[[0,1.07,3],[1,1.06,1.99],[2,1.04,6]],"ltp":1.51,"tv":12.72,"id":16325787}]}]}
{"op":"mcm","clk":"988655062","pt":1580479364447,"mc":[{"id":"1.168133553","rc":[{"batb":[[0,1.06,1.99],[1,1.05,3]],"ltp":1.51,"tv":12.72,"id":16325787}]}]}
{"op":"mcm","clk":"988656204","pt":1580479374090,"mc":[{"id":"1.168133553","rc":[{"batb":[[0,1.07,40.08],[1,1.06,1.99],[2,1.05,3]],"ltp":1.51,"tv":12.72,"id":16325787}]}]}
{"op":"mcm","clk":"988656587","pt":1580479376548,"mc":[{"id":"1.168133553","rc":[{"batb":[[0,1.08,3],[1,1.07,40.08],[2,1.06,1.99]],"ltp":1.51,"tv":12.72,"id":16325787}]}]}
{"op":"mcm","clk":"988658618","pt":1580479397993,"mc":[{"id":"1.168133553","rc":[{"batb":[[1,1.06,1.99],[2,1.04,6]],"ltp":1.51,"tv":12.72,"id":16325787}]}]}
{"op":"mcm","clk":"988658940","pt":1580479401217,"mc":[{"id":"1.168133553","rc":[{"batb":[[0,1.06,1.99],[1,1.05,3]],"ltp":1.51,"tv":12.72,"id":16325787}]}]}
{"op":"mcm","clk":"988660208","pt":1580479412928,"mc":[{"id":"1.168133553","rc":[{"batb":[[0,1.06,4.99],[1,1.04,6],[2,1.03,1628.39]],"ltp":1.51,"tv":12.72,"id":16325787}]}]}
{"op":"mcm","clk":"988661635","pt":1580479424508,"mc":[{"id":"1.168133553","rc":[{"batb":[[0,1.06,1.99]],"ltp":1.51,"tv":12.72,"id":16325787}]}]}
{"op":"mcm","clk":"988661641","pt":1580479424609,"mc":[{"id":"1.168133553","rc":[{"batb":[[0,1.07,3],[1,1.06,1.99],[2,1.04,6]],"ltp":1.51,"tv":12.72,"id":16325787}]}]}
{"op":"mcm","clk":"988662643","pt":1580479437822,"mc":[{"id":"1.168133553","rc":[{"batb":[[0,1.06,1.99],[1,1.05,3]],"ltp":1.51,"tv":12.72,"id":16325787}]}]}
{"op":"mcm","clk":"988663433","pt":1580479447450,"mc":[{"id":"1.168133553","rc":[{"batb":[[0,1.07,40.08],[1,1.06,1.99],[2,1.05,3]],"ltp":1.51,"tv":12.72,"id":16325787}]}]}
{"op":"mcm","clk":"988663696","pt":1580479449949,"mc":[{"id":"1.168133553","rc":[{"batb":[[0,1.08,3],[1,1.07,40.08],[2,1.06,1.99]],"ltp":1.51,"tv":12.72,"id":16325787}]}]}
{"op":"mcm","clk":"988665668","pt":1580479471341,"mc":[{"id":"1.168133553","rc":[{"batb":[[0,1.09,1.99],[1,1.08,3],[2,1.04,6]],"ltp":1.51,"tv":12.72,"id":16325787}]}]}
{"op":"mcm","clk":"988665864","pt":1580479473443,"mc":[{"id":"1.168133553","rc":[{"batb":[[0,1.09,4.99],[1,1.04,6],[2,1.03,1628.39]],"ltp":1.51,"tv":12.72,"id":16325787}]}]}
{"op":"mcm","clk":"988667149","pt":1580479485442,"mc":[{"id":"1.168133553","rc":[{"batb":[[0,1.1,3],[1,1.09,1.99],[2,1.04,6]],"ltp":1.51,"tv":12.72,"id":16325787}]}]}
{"op":"mcm","clk":"988667931","pt":1580479494251,"mc":[{"id":"1.168133553","rc":[{"batb":[[0,1.11,38.65],[1,1.1,3],[2,1.09,1.99]],"ltp":1.51,"tv":12.72,"id":16325787}]}]}
{"op":"mcm","clk":"988668025","pt":1580479495353,"mc":[{"id":"1.168133553","rc":[{"batb":[[0,1.12,3],[1,1.11,38.65]],"ltp":1.51,"tv":12.72,"id":16325787}]}]}
{"op":"mcm","clk":"988670419","pt":1580479517899,"mc":[{"id":"1.168133553","rc":[{"batb":[[1,1.09,1.99],[2,1.04,6]],"ltp":1.51,"tv":12.72,"id":16325787}]}]}
{"op":"mcm","clk":"988670858","pt":1580479521474,"mc":[{"id":"1.168133553","rc":[{"batb":[[0,1.09,1.99],[1,1.04,6],[2,1.03,1628.39]],"ltp":1.51,"tv":12.72,"id":16325787}]}]}
{"op":"mcm","clk":"988670869","pt":1580479521587,"mc":[{"id":"1.168133553","rc":[{"batb":[[1,1.05,3],[2,1.04,6]],"ltp":1.51,"tv":12.72,"id":16325787}]}]}
{"op":"mcm","clk":"988672176","pt":1580479535431,"mc":[{"id":"1.168133553","rc":[{"batb":[[1,1.06,3]],"ltp":1.51,"tv":12.72,"id":16325787}]}]}
{"op":"mcm","clk":"988672520","pt":1580479538980,"mc":[{"id":"1.168133553","rc":[{"batb":[[0,1.07,1.99]],"ltp":1.51,"tv":12.72,"id":16325787}]}]}
{"op":"mcm","clk":"988672754","pt":1580479541797,"mc":[{"id":"1.168133553","rc":[{"batb":[[0,1.08,39.71],[1,1.07,1.99],[2,1.06,3]],"ltp":1.51,"tv":12.72,"id":16325787}]}]}
{"op":"mcm","clk":"988673137","pt":1580479546517,"mc":[{"id":"1.168133553","rc":[{"batb":[[0,1.09,3],[1,1.08,39.71],[2,1.07,1.99]],"ltp":1.51,"tv":12.72,"id":16325787}]}]}
{"op":"mcm","clk":"988674682","pt":1580479565801,"mc":[{"id":"1.168133553","rc":[{"batb":[[0,1.1,38.99],[1,1.09,3]],"ltp":1.51,"tv":12.72,"id":16325787}]}]}
{"op":"mcm","clk":"988674901","pt":1580479568537,"mc":[{"id":"1.168133553","rc":[{"batb":[[0,1.11,3],[1,1.1,38.99]],"ltp":1.51,"tv":12.72,"id":16325787}]}]}
{"op":"mcm","clk":"988676265","pt":1580479589486,"mc":[{"id":"1.168133553","rc":[{"batb":[[1,1.07,1.99],[2,1.04,6]],"ltp":1.51,"tv":12.72,"id":16325787}]}]}
{"op":"mcm","clk":"988676295","pt":1580479589853,"mc":[{"id":"1.168133553","rc":[{"batb":[[0,1.07,1.99],[1,1.05,3]],"ltp":1.51,"tv":12.72,"id":16325787}]}]}
{"op":"mcm","clk":"988677299","pt":1580479601110,"mc":[{"id":"1.168133553","rc":[{"batb":[[1,1.06,3]],"ltp":1.51,"tv":12.72,"id":16325787}]}]}
{"op":"mcm","clk":"988678361","pt":1580479614113,"mc":[{"id":"1.168133553","rc":[{"batb":[[0,1.08,39.71],[1,1.07,4.99]],"ltp":1.51,"tv":12.72,"id":16325787}]}]}
{"op":"mcm","clk":"988679523","pt":1580479627936,"mc":[{"id":"1.168133553","rc":[{"batb":[[0,1.09,3],[1,1.08,39.71],[2,1.07,1.99]],"ltp":1.51,"tv":12.72,"id":16325787}]}]}
{"op":"mcm","clk":"988680401","pt":1580479638024,"mc":[{"id":"1.168133553","rc":[{"batb":[[1,1.07,1.99],[2,1.04,6]],"ltp":1.51,"tv":12.72,"id":16325787}]}]}
{"op":"mcm","clk":"988680528","pt":1580479639429,"mc":[{"id":"1.168133553","rc":[{"batb":[[0,1.07,1.99],[1,1.05,3]],"ltp":1.51,"tv":12.72,"id":16325787}]}]}
{"op":"mcm","clk":"988690311","pt":1580479654947,"mc":[{"id":"1.168133553","rc":[{"batb":[[1,1.06,3]],"ltp":1.51,"tv":12.72,"id":16325787}]}]}
{"op":"mcm","clk":"988690866","pt":1580479661765,"mc":[{"id":"1.168133553","rc":[{"batb":[[0,1.08,39.71],[1,1.07,1.99],[2,1.06,3]],"ltp":1.51,"tv":12.72,"id":16325787}]}]}
{"op":"mcm","clk":"988691220","pt":1580479665854,"mc":[{"id":"1.168133553","rc":[{"batb":[[0,1.09,3],[1,1.08,39.71],[2,1.07,1.99]],"ltp":1.51,"tv":12.72,"id":16325787}]}]}
{"op":"mcm","clk":"988691879","pt":1580479674466,"mc":[{"id":"1.168133553","rc":[{"batb":[[0,1.1,1.99],[1,1.09,3],[2,1.08,39.71]],"ltp":1.51,"tv":12.72,"id":16325787}]}]}
{"op":"mcm","clk":"988692045","pt":1580479676462,"mc":[{"id":"1.168133553","rc":[{"batb":[[0,1.1,4.99],[1,1.08,39.71],[2,1.04,6]],"ltp":1.51,"tv":12.72,"id":16325787}]}]}
{"op":"mcm","clk":"988692814","pt":1580479685505,"mc":[{"id":"1.168133553","rc":[{"batb":[[1,1.04,6],[2,1.03,1628.39]],"ltp":1.51,"tv":12.72,"id":16325787}]}]}
{"op":"mcm","clk":"988693112","pt":1580479689711,"mc":[{"id":"1.168133553","rc":[{"batb":[[0,1.11,3],[1,1.1,1.99],[2,1.04,6]],"ltp":1.51,"tv":12.72,"id":16325787}]}]}
{"op":"mcm","clk":"988694064","pt":1580479702018,"mc":[{"id":"1.168133553","rc":[{"batb":[[0,1.1,1.99],[1,1.05,3]],"ltp":1.51,"tv":12.72,"id":16325787}]}]}
{"op":"mcm","clk":"988694928","pt":1580479714527,"mc":[{"id":"1.168133553","rc":[{"batb":[[1,1.04,6],[2,1.03,1628.39]],"ltp":1.51,"tv":12.72,"id":16325787}]}]}
{"op":"mcm","clk":"988694936","pt":1580479714632,"mc":[{"id":"1.168133553","rc":[{"batb":[[1,1.06,3],[2,1.04,6]],"ltp":1.51,"tv":12.72,"id":16325787}]}]}
{"op":"mcm","clk":"988696020","pt":1580479728440,"mc":[{"id":"1.168133553","rc":[{"batb":[[1,1.07,3]],"ltp":1.51,"tv":12.72,"id":16325787}]}]}
{"op":"mcm","clk":"988697031","pt":1580479741257,"mc":[{"id":"1.168133553","rc":[{"batb":[[1,1.08,3]],"ltp":1.51,"tv":12.72,"id":16325787}]}]}
{"op":"mcm","clk":"988697122","pt":1580479742470,"mc":[{"id":"1.168133553","rc":[{"batb":[[0,1.09,1.99]],"ltp":1.51,"tv":12.72,"id":16325787}]}]}
{"op":"mcm","clk":"988698262","pt":1580479758168,"mc":[{"id":"1.168133553","rc":[{"batb":[[0,1.1,38.99],[1,1.09,4.99]],"ltp":1.51,"tv":12.72,"id":16325787}]}]}
{"op":"mcm","clk":"988698887","pt":1580479766497,"mc":[{"id":"1.168133553","rc":[{"batb":[[0,1.11,3],[1,1.1,38.99],[2,1.09,1.99]],"ltp":1.51,"tv":12.72,"id":16325787}]}]}
{"op":"mcm","clk":"988699605","pt":1580479775703,"mc":[{"id":"1.168133553","rc":[{"batb":[[0,1.53,11.99]],"ltp":0.0,"tv":0.0,"id":27227336},{"batb":[[0,1.53,11.99]],"ltp":0.0,"tv":0.0,"id":21641292},{"batb":[[0,1.11,13]],"ltp":1.51,"tv":12.72,"id":16325787}]}]}
{"op":"mcm","clk":"988699746","pt":1580479777312,"mc":[{"id":"1.168133553","rc":[{"batb":[[0,1.12,3],[1,1.11,10],[2,1.1,38.99]],"ltp":1.51,"tv":12.72,"id":16325787}]}]}
{"op":"mcm","clk":"988700052","pt":1580479781272,"mc":[{"id":"1.168133553","rc":[{"batb":[[0,1.13,37.96],[1,1.12,3],[2,1.11,10]],"ltp":1.51,"tv":12.72,"id":16325787}]}]}
{"op":"mcm","clk":"988700685","pt":1580479789398,"mc":[{"id":"1.168133553","rc":[{"batb":[[0,1.14,3],[1,1.13,37.96]],"ltp":1.51,"tv":12.72,"id":16325787}]}]}
{"op":"mcm","clk":"988701879","pt":1580479804293,"mc":[{"id":"1.168133553","rc":[{"batb":[[1,1.11,10],[2,1.09,1.99]],"ltp":1.51,"tv":12.72,"id":16325787}]}]}
{"op":"mcm","clk":"988702264","pt":1580479808745,"mc":[{"id":"1.168133553","rc":[{"batb":[[0,1.15,1.99],[1,1.14,3],[2,1.11,10]],"ltp":1.51,"tv":12.72,"id":16325787}]}]}
{"op":"mcm","clk":"988702655","pt":1580479813525,"mc":[{"id":"1.168133553","rc":[{"batb":[[0,1.15,4.99],[1,1.11,10],[2,1.04,6]],"ltp":1.51,"tv":12.72,"id":16325787}]}]}
{"op":"mcm","clk":"988702905","pt":1580479816137,"mc":[{"id":"1.168133553","rc":[{"batb":[[2,1.03,1628.39]],"ltp":1.51,"tv":12.72,"id":16325787}]}]}
{"op":"mcm","clk":"988703663","pt":1580479825262,"mc":[{"id":"1.168133553","rc":[{"batb":[[0,1.16,3],[1,1.15,1.99],[2,1.11,10]],"ltp":1.51,"tv":12.72,"id":16325787}]}]}
{"op":"mcm","clk":"988703818","pt":1580479827366,"mc":[{"id":"1.168133553","rc":[{"batb":[[0,1.17,36.66],[1,1.16,3],[2,1.15,1.99]],"ltp":1.51,"tv":12.72,"id":16325787}]}]}
{"op":"mcm","clk":"988704392","pt":1580479834934,"mc":[{"id":"1.168133553","rc":[{"batb":[[0,1.18,3],[1,1.17,36.66]],"ltp":1.51,"tv":12.72,"id":16325787}]}]}
{"op":"mcm","clk":"988705694","pt":1580479851299,"mc":[{"id":"1.168133553","rc":[{"batb":[[1,1.15,1.99],[2,1.11,10]],"ltp":1.51,"tv":12.72,"id":16325787}]}]}
{"op":"mcm","clk":"988705989","pt":1580479854509,"mc":[{"id":"1.168133553","rc":[{"batb":[[0,1.15,1.99],[1,1.12,3]],"ltp":1.51,"tv":12.72,"id":16325787}]}]}
{"op":"mcm","clk":"988706238","pt":1580479857203,"mc":[{"id":"1.168133553","rc":[{"batb":[[1,1.13,10],[2,1.12,3]],"ltp":1.51,"tv":12.72,"id":16325787}]}]}
{"op":"mcm","clk":"988706900","pt":1580479864805,"mc":[{"id":"1.168133553","rc":[{"batb":[[1,1.14,3],[2,1.13,10]],"ltp":1.51,"tv":12.72,"id":16325787}]}]}
{"op":"mcm","clk":"988707701","pt":1580479874921,"mc":[{"id":"1.168133553","rc":[{"batb":[[0,1.16,36.98],[1,1.15,4.99]],"ltp":1.51,"tv":12.72,"id":16325787}]}]}
{"op":"mcm","clk":"988708417","pt":1580479885495,"mc":[{"id":"1.168133553","rc":[{"batb":[[0,1.17,4.99],[1,1.16,36.98]],"ltp":1.51,"tv":12.72,"id":16325787}]}]}
{"op":"mcm","clk":"988709280","pt":1580479898013,"mc":[{"id":"1.168133553","rc":[{"batb":[[1,1.13,10],[2,1.03,1628.39]],"ltp":1.51,"tv":12.72,"id":16325787}]}]}
{"op":"mcm","clk":"988709431","pt":1580479900054,"mc":[{"id":"1.168133553","rc":[{"batb":[[0,1.18,3],[1,1.17,1.99],[2,1.13,10]],"ltp":1.51,"tv":12.72,"id":16325787}]}]}
{"op":"mcm","clk":"988710265","pt":1580479910964,"mc":[{"id":"1.168133553","rc":[{"batb":[[0,1.17,1.99],[1,1.14,3]],"ltp":1.51,"tv":12.72,"id":16325787}]}]}
{"op":"mcm","clk":"988711261","pt":1580479922940,"mc":[{"id":"1.168133553","rc":[{"batb":[[1,1.15,3]],"ltp":1.51,"tv":12.72,"id":16325787}]}]}
{"op":"mcm","clk":"988712395","pt":1580479935960,"mc":[{"id":"1.168133553","rc":[{"batb":[[1,1.16,3]],"ltp":1.51,"tv":12.72,"id":16325787}]}]}
