{"op":"mcm","clk":"993639563","pt":1580544812500,"mc":[{"id":"1.168133553","rc":[{"trd":[[6,114.84]],"batb":[[0,5.6,2.21],[1,5.5,27.13]],"batl":[[0,6.2,10.16],[1,6.8,6.63],[2,7,18.7]],"ltp":6.0,"tv":618.91,"id":21641292}],"tv":6507.43}]}
{"op":"mcm","clk":"993639638","pt":1580544813500,"mc":[{"id":"1.168133553","rc":[{"batl":[[1,6.8,11.44]],"ltp":6.0,"tv":618.91,"id":21641292}]}]}
{"op":"mcm","clk":"993640082","pt":1580544818528,"mc":[{"id":"1.168133553","rc":[{"batl":[[1,6.6,5.4],[2,6.8,11.44]],"ltp":6.0,"tv":618.91,"id":21641292}]}]}
{"op":"mcm","clk":"993640786","pt":1580544826510,"mc":[{"id":"1.168133553","rc":[{"batl":[[0,6,2],[1,6.2,10.16],[2,6.6,5.4]],"ltp":6.0,"tv":618.91,"id":21641292}]}]}
{"op":"mcm","clk":"993641189","pt":1580544831429,"mc":[{"id":"1.168133553","rc":[{"batl":[[0,5.9,10],[1,6,2],[2,6.2,10.16]],"ltp":6.0,"tv":618.91,"id":21641292}]}]}
{"op":"mcm","clk":"993641450","pt":1580544834433,"mc":[{"id":"1.168133553","rc":[{"trd":[[1.32,2436.56]],"batb":[[0,1.31,66.5],[1,1.3,180.87],[2,1.29,127.85]],"batl":[[0,1.32,5.55],[1,1.34,1982.27],[2,1.35,180.86]],"ltp":1.32,"tv":5747.3,"id":16325787}],"tv":6536.33}]}
{"op":"mcm","clk":"993641689","pt":1580544837443,"mc":[{"id":"1.168133553","rc":[{"trd":[[5.9,78.4]],"batl":[[0,5.9,5]],"ltp":5.9,"tv":628.91,"id":21641292}],"tv":6546.33}]}
{"op":"mcm","clk":"993642434","pt":1580544845530,"mc":[{"id":"1.168133553","rc":[{"trd":[[10.5,48.86]],"batb":[[0,10.5,3.72]],"ltp":10.5,"tv":174.11,"id":27227336}],"tv":6550.33}]}
{"op":"mcm","clk":"993643283","pt":1580544854532,"mc":[{"id":"1.168133553","rc":[{"batl":[[0,14,12.96]],"ltp":10.5,"tv":174.11,"id":27227336}]}]}
{"op":"mcm","clk":"993643499","pt":1580544857160,"mc":[{"id":"1.168133553","rc":[{"batl":[[0,13.5,1.83],[1,14,12.31],[2,20,9.58]],"ltp":10.5,"tv":174.11,"id":27227336}]}]}
{"op":"mcm","clk":"993643610","pt":1580544858555,"mc":[{"id":"1.168133553","rc":[{"batb":[[1,5.5,40.13]],"ltp":5.9,"tv":628.91,"id":21641292}]}]}
{"op":"mcm","clk":"993645419","pt":1580544879666,"mc":[{"id":"1.168133553","rc":[{"batl":[[1,6.2,10.16],[2,6.6,5.4]],"ltp":5.9,"tv":628.91,"id":21641292}]}]}
{"op":"mcm","clk":"993646235","pt":1580544888492,"mc":[{"id":"1.168133553","rc":[{"trd":[[13.5,3.11]],"batl":[[0,14,12.95],[1,20,9.58],[2,25,10.08]],"ltp":13.5,"tv":176.48,"id":27227336},{"trd":[[1.32,2447.66],[1.34,951.78]],"batl":[[0,1.34,1975.63],[1,1.35,180.86],[2,1.36,251.95]],"ltp":1.34,"tv":5771.68,"id":16325787}],"tv":6577.09}]}
{"op":"mcm","clk":"993647354","pt":1580544900527,"mc":[{"id":"1.168133553","rc":[{"batl":[[2,29,9.08]],"ltp":13.5,"tv":176.48,"id":27227336}]}]}
{"op":"mcm","clk":"993653163","pt":1580544961280,"mc":[{"id":"1.168133553","rc":[{"batb":[[1,5.5,27.13]],"ltp":5.9,"tv":628.91,"id":21641292}]}]}
{"op":"mcm","clk":"993653787","pt":1580544967499,"mc":[{"id":"1.168133553","rc":[{"trd":[[5.9,88.4]],"batb":[[0,5.6,2.69]],"batl":[[0,6.2,10.16],[1,6.6,10.05],[2,6.8,6.63]],"ltp":5.9,"tv":638.91,"id":21641292}],"tv":6587.09}]}
{"op":"mcm","clk":"993653856","pt":1580544968304,"mc":[{"id":"1.168133553","rc":[{"batb":[[0,5.9,5.48],[1,5.6,2.21],[2,5.5,27.13]],"ltp":5.9,"tv":638.91,"id":21641292}]}]}
{"op":"mcm","clk":"993653932","pt":1580544969212,"mc":[{"id":"1.168133553","rc":[{"batl":[[1,6.6,5.4]],"ltp":5.9,"tv":638.91,"id":21641292}]}]}
{"op":"mcm","clk":"993654050","pt":1580544970406,"mc":[{"id":"1.168133553","rc":[{"batb":[[1,5.6,5.23]],"ltp":5.9,"tv":638.91,"id":21641292}]}]}
{"op":"mcm","clk":"993654714","pt":1580544977414,"mc":[{"id":"1.168133553","rc":[{"batb":[[1,5.7,2.21],[2,5.6,3.02]],"ltp":5.9,"tv":638.91,"id":21641292}]}]}
{"op":"mcm","clk":"993654800","pt":1580544978299,"mc":[{"id":"1.168133553","rc":[{"batb":[[0,5.7,2.69],[1,5.6,3.02],[2,5.5,27.13]],"ltp":5.9,"tv":638.91,"id":21641292}]}]}
{"op":"mcm","clk":"993655407","pt":1580544983237,"mc":[{"id":"1.168133553","rc":[{"trd":[[6.2,12.99]],"batb":[[0,5.7,2.21]],"batl":[[0,6.2,9.68]],"ltp":6.2,"tv":639.87,"id":21641292}],"tv":6588.05}]}
{"op":"mcm","clk":"993655511","pt":1580544984222,"mc":[{"id":"1.168133553","rc":[{"trd":[[6.2,16.99]],"batl":[[0,6.2,7.68]],"ltp":6.2,"tv":643.87,"id":21641292}],"tv":6592.05}]}
{"op":"mcm","clk":"993655677","pt":1580544986440,"mc":[{"id":"1.168133553","rc":[{"batb":[[0,5.7,2.38]],"ltp":6.2,"tv":643.87,"id":21641292}]}]}
{"op":"mcm","clk":"993656711","pt":1580544995558,"mc":[{"id":"1.168133553","rc":[{"batb":[[0,5.9,7.96],[1,5.8,10.38],[2,5.7,2]],"ltp":6.2,"tv":643.87,"id":21641292}]}]}
{"op":"mcm","clk":"993658965","pt":1580545015366,"mc":[{"id":"1.168133553","rc":[{"batb":[[0,5.9,9.96],[2,5.5,27.13]],"ltp":6.2,"tv":643.87,"id":21641292}]}]}
{"op":"mcm","clk":"993659252","pt":1580545018574,"mc":[{"id":"1.168133553","rc":[{"batl":[[1,6.8,6.63],[2,7,15.07]],"ltp":6.2,"tv":643.87,"id":21641292}]}]}
{"op":"mcm","clk":"993659857","pt":1580545024041,"mc":[{"id":"1.168133553","rc":[{"trd":[[10.5,54.85]],"batb":[[0,10,10.5],[1,9.8,1.98],[2,9.6,8.78]],"ltp":10.5,"tv":182.48,"id":27227336}],"tv":6598.05}]}
{"op":"mcm","clk":"993660114","pt":1580545026368,"mc":[{"id":"1.168133553","rc":[{"batl":[[1,6.8,9.43]],"ltp":6.2,"tv":643.87,"id":21641292}]}]}
{"op":"mcm","clk":"993660213","pt":1580545027255,"mc":[{"id":"1.168133553","rc":[{"trd":[[5.9,103.62]],"batb":[[0,5.9,2.35]],"ltp":5.9,"tv":659.09,"id":21641292},{"trd":[[1.34,971.78]],"batl":[[0,1.34,1965.63]],"ltp":1.34,"tv":5791.68,"id":16325787}],"tv":6633.27}]}
{"op":"mcm","clk":"993661254","pt":1580545039565,"mc":[{"id":"1.168133553","rc":[{"trd":[[6.2,32.35]],"batl":[[0,6.8,9.43],[1,7,22.43],[2,7.6,2.19]],"ltp":6.2,"tv":674.46,"id":21641292}],"tv":6648.63}]}
{"op":"mcm","clk":"993661340","pt":1580545040462,"mc":[{"id":"1.168133553","rc":[{"batl":[[0,13.5,1.01],[1,14,12.31],[2,20,9.58]],"ltp":10.5,"tv":182.48,"id":27227336}]}]}
{"op":"mcm","clk":"993661404","pt":1580545041289,"mc":[{"id":"1.168133553","rc":[{"batl":[[0,13.5,3.35]],"ltp":10.5,"tv":182.48,"id":27227336},{"batb":[[0,5.9,2]],"batl":[[0,6.6,9.03],[1,6.8,9.43],[2,7,22.43]],"ltp":6.2,"tv":674.46,"id":21641292}]}]}
{"op":"mcm","clk":"993662347","pt":1580545051481,"mc":[{"id":"1.168133553","rc":[{"trd":[[5.9,107.62]],"batb":[[0,5.8,10.38],[1,5.6,2.81]],"batl":[[0,5.9,11.33],[1,6.6,2],[2,6.8,2]],"ltp":5.9,"tv":678.46,"id":21641292}],"tv":6652.63}]}
{"op":"mcm","clk":"993662525","pt":1580545052988,"mc":[{"id":"1.168133553","rc":[{"batb":[[1,5.5,27.13],[2,5.1,2.32]],"batl":[[2,6.8,11.45]],"ltp":5.9,"tv":678.46,"id":21641292}]}]}
{"op":"mcm","clk":"993665341","pt":1580545081417,"mc":[{"id":"1.168133553","rc":[{"trd":[[5.8,77.24]],"batb":[[0,5.5,33.31],[1,5.1,16.47],[2,4.8,1.04]],"batl":[[0,5.8,2.66],[1,5.9,11.33],[2,6.6,2]],"ltp":5.8,"tv":699.21,"id":21641292},{"trd":[[1.34,1010.97]],"batl":[[0,1.34,1946.04]],"ltp":1.34,"tv":5830.86,"id":16325787}],"tv":6712.57}]}
{"op":"mcm","clk":"993665701","pt":1580545084495,"mc":[{"id":"1.168133553","rc":[{"batl":[[2,6.6,2.16]],"ltp":5.8,"tv":699.21,"id":21641292}]}]}
{"op":"mcm","clk":"993666733","pt":1580545094516,"mc":[{"id":"1.168133553","rc":[{"batl":[[2,6.8,11.61]],"ltp":5.8,"tv":699.21,"id":21641292}]}]}
{"op":"mcm","clk":"993668149","pt":1580545111549,"mc":[{"id":"1.168133553","rc":[{"batb":[[0,5.5,27.13],[1,5.1,2.32],[2,4.8,16.1]],"ltp":5.8,"tv":699.21,"id":21641292}]}]}
{"op":"mcm","clk":"993668958","pt":1580545121531,"mc":[{"id":"1.168133553","rc":[{"batb":[[1,5.2,2],[2,5.1,2.32]],"ltp":5.8,"tv":699.21,"id":21641292}]}]}
{"op":"mcm","clk":"993670421","pt":1580545140511,"mc":[{"id":"1.168133553","rc":[{"batb":[[2,5.1,15.43]],"ltp":5.8,"tv":699.21,"id":21641292}]}]}
{"op":"mcm","clk":"993670451","pt":1580545140870,"mc":[{"id":"1.168133553","rc":[{"batb":[[0,1.32,13.05],[1,1.31,66.5],[2,1.3,180.87]],"ltp":1.34,"tv":5830.86,"id":16325787}]}]}
{"op":"mcm","clk":"993672728","pt":1580545170573,"mc":[{"id":"1.168133553","rc":[{"batb":[[2,5.1,2.32]],"ltp":5.8,"tv":699.21,"id":21641292}]}]}
{"op":"mcm","clk":"993675062","pt":1580545200560,"mc":[{"id":"1.168133553","rc":[{"batb":[[2,5.1,15.43]],"ltp":5.8,"tv":699.21,"id":21641292}]}]}
{"op":"mcm","clk":"993675321","pt":1580545203562,"mc":[{"id":"1.168133553","rc":[{"batb":[[0,5.6,3.08],[1,5.5,27.13],[2,5.2,2]],"ltp":5.8,"tv":699.21,"id":21641292}]}]}
{"op":"mcm","clk":"993676469","pt":1580545218476,"mc":[{"id":"1.168133553","rc":[{"trd":[[5.6,13.1]],"batb":[[0,5.6,2.52],[2,5.1,15.43]],"ltp":5.6,"tv":704.32,"id":21641292}],"tv":6717.67}]}
{"op":"mcm","clk":"993677111","pt":1580545227193,"mc":[{"id":"1.168133553","rc":[{"trd":[[5.6,18.14]],"batb":[[0,5.5,27.13],[1,5.1,2.32],[2,4.8,9.38]],"ltp":5.6,"tv":709.36,"id":21641292}],"tv":6722.72}]}
{"op":"mcm","clk":"993678068","pt":1580545238497,"mc":[{"id":"1.168133553","rc":[{"batb":[[1,5.2,2],[2,5.1,2.32]],"ltp":5.6,"tv":709.36,"id":21641292}]}]}
{"op":"mcm","clk":"993679481","pt":1580545257356,"mc":[{"id":"1.168133553","rc":[{"batb":[[2,5.1,16.93]],"ltp":5.6,"tv":709.36,"id":21641292}]}]}
{"op":"mcm","clk":"993680582","pt":1580545272446,"mc":[{"id":"1.168133553","rc":[{"batl":[[0,13.5,2.71]],"ltp":10.5,"tv":182.48,"id":27227336}]}]}
{"op":"mcm","clk":"993681598","pt":1580545286473,"mc":[{"id":"1.168133553","rc":[{"batb":[[2,5.1,2.32]],"ltp":5.6,"tv":709.36,"id":21641292}]}]}
{"op":"mcm","clk":"993683979","pt":1580545316513,"mc":[{"id":"1.168133553","rc":[{"batb":[[2,5.1,16.93]],"ltp":5.6,"tv":709.36,"id":21641292}]}]}
{"op":"mcm","clk":"993684615","pt":1580545324515,"mc":[{"id":"1.168133553","rc":[{"batb":[[0,10.5,2.36],[1,10,9.77],[2,9.8,1.98]],"ltp":10.5,"tv":182.48,"id":27227336}]}]}
{"op":"mcm","clk":"993686621","pt":1580545346565,"mc":[{"id":"1.168133553","rc":[{"batb":[[2,5.1,2.32]],"ltp":5.6,"tv":709.36,"id":21641292}]}]}
{"op":"mcm","clk":"993699098","pt":1580545376214,"mc":[{"id":"1.168133553","rc":[{"batb":[[2,5.1,16.93]],"ltp":5.6,"tv":709.36,"id":21641292}]}]}
{"op":"mcm","clk":"993701463","pt":1580545405470,"mc":[{"id":"1.168133553","rc":[{"batb":[[2,5.1,2.32]],"ltp":5.6,"tv":709.36,"id":21641292}]}]}
{"op":"mcm","clk":"993701542","pt":1580545406457,"mc":[{"id":"1.168133553","rc":[{"trd":[[5.5,45.7]],"batb":[[0,5.5,16.13]],"ltp":5.5,"tv":731.36,"id":21641292}],"tv":6744.72}]}
{"op":"mcm","clk":"993701792","pt":1580545409460,"mc":[{"id":"1.168133553","rc":[{"batb":[[0,5.5,27.13]],"ltp":5.5,"tv":731.36,"id":21641292}]}]}
{"op":"mcm","clk":"993703861","pt":1580545434988,"mc":[{"id":"1.168133553","rc":[{"batb":[[2,5.1,16.93]],"ltp":5.5,"tv":731.36,"id":21641292}]}]}
{"op":"mcm","clk":"993706657","pt":1580545465532,"mc":[{"id":"1.168133553","rc":[{"batb":[[2,5.1,2.32]],"ltp":5.5,"tv":731.36,"id":21641292}]}]}
{"op":"mcm","clk":"993709282","pt":1580545494503,"mc":[{"id":"1.168133553","rc":[{"batb":[[2,5.1,16.93]],"ltp":5.5,"tv":731.36,"id":21641292}]}]}
{"op":"mcm","clk":"993711811","pt":1580545524543,"mc":[{"id":"1.168133553","rc":[{"batb":[[2,5.1,2.32]],"ltp":5.5,"tv":731.36,"id":21641292}]}]}
{"op":"mcm","clk":"993714454","pt":1580545554563,"mc":[{"id":"1.168133553","rc":[{"batb":[[2,5.1,16.93]],"ltp":5.5,"tv":731.36,"id":21641292}]}]}
{"op":"mcm","clk":"993716943","pt":1580545583390,"mc":[{"id":"1.168133553","rc":[{"batb":[[2,5.1,2.32]],"ltp":5.5,"tv":731.36,"id":21641292}]}]}
{"op":"mcm","clk":"993719490","pt":1580545613516,"mc":[{"id":"1.168133553","rc":[{"trd":[[5.5,55.7]],"batb":[[0,5.5,22.13],[2,5.1,16.93]],"ltp":5.5,"tv":741.36,"id":21641292}],"tv":6754.71}]}
{"op":"mcm","clk":"993719765","pt":1580545617042,"mc":[{"id":"1.168133553","rc":[{"batl":[[0,5.8,2.88]],"ltp":5.5,"tv":741.36,"id":21641292}]}]}
{"op":"mcm","clk":"993719981","pt":1580545619567,"mc":[{"id":"1.168133553","rc":[{"batb":[[0,5.5,26.89]],"ltp":5.5,"tv":741.36,"id":21641292}]}]}
{"op":"mcm","clk":"993722061","pt":1580545642550,"mc":[{"id":"1.168133553","rc":[{"batb":[[2,5.1,2.32]],"ltp":5.5,"tv":741.36,"id":21641292}]}]}
{"op":"mcm","clk":"993724334","pt":1580545672483,"mc":[{"id":"1.168133553","rc":[{"batb":[[2,5.1,16.8]],"ltp":5.5,"tv":741.36,"id":21641292}]}]}
{"op":"mcm","clk":"993725984","pt":1580545694369,"mc":[{"id":"1.168133553","rc":[{"trd":[[1.34,1021.27]],"batl":[[0,1.34,1940.89]],"ltp":1.34,"tv":5841.16,"id":16325787}],"tv":6765.01}]}
{"op":"mcm","clk":"993726556","pt":1580545701476,"mc":[{"id":"1.168133553","rc":[{"batb":[[2,5.1,2.32]],"ltp":5.5,"tv":741.36,"id":21641292}]}]}
{"op":"mcm","clk":"993728951","pt":1580545731322,"mc":[{"id":"1.168133553","rc":[{"batb":[[2,5.1,16.8]],"ltp":5.5,"tv":741.36,"id":21641292}]}]}
{"op":"mcm","clk":"993731277","pt":1580545761549,"mc":[{"id":"1.168133553","rc":[{"batb":[[2,5.1,2.32]],"ltp":5.5,"tv":741.36,"id":21641292}]}]}
{"op":"mcm","clk":"993732944","pt":1580545777317,"mc":[{"id":"1.168133553","rc":[{"trd":[[1.34,1030.35]],"batl":[[0,1.34,1936.35]],"ltp":1.34,"tv":5850.24,"id":16325787}],"tv":6774.09}]}
{"op":"mcm","clk":"993734083","pt":1580545790501,"mc":[{"id":"1.168133553","rc":[{"batb":[[2,5.1,17.38]],"ltp":5.5,"tv":741.36,"id":21641292}]}]}
{"op":"mcm","clk":"993736791","pt":1580545821550,"mc":[{"id":"1.168133553","rc":[{"batb":[[2,5.1,2.32]],"ltp":5.5,"tv":741.36,"id":21641292}]}]}
{"op":"mcm","clk":"993736879","pt":1580545822377,"mc":[{"id":"1.168133553","rc":[{"trd":[[1.34,1046.35]],"batl":[[0,1.34,1928.35]],"ltp":1.34,"tv":5866.24,"id":16325787}],"tv":6790.09}]}
{"op":"mcm","clk":"993739124","pt":1580545850107,"mc":[{"id":"1.168133553","rc":[{"batb":[[2,5.1,17.38]],"ltp":5.5,"tv":741.36,"id":21641292}]}]}
{"op":"mcm","clk":"993741327","pt":1580545879753,"mc":[{"id":"1.168133553","rc":[{"batb":[[2,5.1,2.32]],"ltp":5.5,"tv":741.36,"id":21641292}]}]}
{"op":"mcm","clk":"993743669","pt":1580545909296,"mc":[{"id":"1.168133553","rc":[{"batb":[[2,5.1,17.61]],"ltp":5.5,"tv":741.36,"id":21641292}]}]}
{"op":"mcm","clk":"993746163","pt":1580545939409,"mc":[{"id":"1.168133553","rc":[{"batb":[[2,5.1,2.32]],"ltp":5.5,"tv":741.36,"id":21641292}]}]}
{"op":"mcm","clk":"993748908","pt":1580545968481,"mc":[{"id":"1.168133553","rc":[{"batb":[[2,5.1,17.61]],"ltp":5.5,"tv":741.36,"id":21641292}]}]}
{"op":"mcm","clk":"993751528","pt":1580545997932,"mc":[{"id":"1.168133553","rc":[{"batb":[[2,5.1,2.32]],"ltp":5.5,"tv":741.36,"id":21641292}]}]}
{"op":"mcm","clk":"993752983","pt":1580546016942,"mc":[{"id":"1.168133553","rc":[{"trd":[[5.5,59.7]],"batb":[[0,5.5,24.89],[2,5.1,17.61]],"ltp":5.5,"tv":745.36,"id":21641292},{"trd":[[1.32,2473.76]],"batb":[[0,1.31,66.5],[1,1.3,185.83],[2,1.29,127.85]],"ltp":1.32,"tv":5892.34,"id":16325787}],"tv":6820.19}]}
{"op":"mcm","clk":"993753292","pt":1580546020528,"mc":[{"id":"1.168133553","rc":[{"batb":[[0,5.6,3.08],[1,5.5,26.89],[2,5.2,2]],"ltp":5.5,"tv":745.36,"id":21641292}]}]}
{"op":"mcm","clk":"993753345","pt":1580546021351,"mc":[{"id":"1.168133553","rc":[{"batb":[[1,1.3,180.87]],"ltp":1.32,"tv":5892.34,"id":16325787}]}]}
{"op":"mcm","clk":"993754211","pt":1580546032155,"mc":[{"id":"1.168133553","rc":[{"trd":[[5.8,83.02]],"batl":[[0,5.9,11.33],[1,6.8,11.61],[2,7,15.07]],"ltp":5.8,"tv":751.13,"id":21641292}],"tv":6825.96}]}
{"op":"mcm","clk":"993754381","pt":1580546034180,"mc":[{"id":"1.168133553","rc":[{"batb":[[1,5.5,27.13]],"ltp":5.8,"tv":751.13,"id":21641292}]}]}
{"op":"mcm","clk":"993755565","pt":1580546048355,"mc":[{"id":"1.168133553","rc":[{"batb":[[0,5.6,5.08],[2,5.1,12.16]],"ltp":5.8,"tv":751.13,"id":21641292}]}]}
{"op":"mcm","clk":"993756649","pt":1580546061677,"mc":[{"id":"1.168133553","rc":[{"batl":[[1,6.8,18.57]],"ltp":5.8,"tv":751.13,"id":21641292}]}]}
{"op":"mcm","clk":"993757473","pt":1580546070524,"mc":[{"id":"1.168133553","rc":[{"batb":[[0,1.32,300],[1,1.31,66.5],[2,1.3,180.87]],"ltp":1.32,"tv":5892.34,"id":16325787}]}]}
{"op":"mcm","clk":"993757622","pt":1580546072427,"mc":[{"id":"1.168133553","rc":[{"trd":[[1.33,403.8]],"batb":[[0,1.33,11.81],[1,1.32,300],[2,1.31,51.5]],"ltp":1.33,"tv":5898.26,"id":16325787}],"tv":6831.88}]}
{"op":"mcm","clk":"993757707","pt":1580546073563,"mc":[{"id":"1.168133553","rc":[{"trd":[[1.33,427.44]],"batb":[[0,1.32,300],[1,1.31,51.5],[2,1.3,180.87]],"ltp":1.33,"tv":5921.89,"id":16325787}],"tv":6855.52}]}
{"op":"mcm","clk":"993757781","pt":1580546074438,"mc":[{"id":"1.168133553","rc":[{"batl":[[0,1.33,2.49],[1,1.34,1928.35],[2,1.35,180.86]],"ltp":1.33,"tv":5921.89,"id":16325787}]}]}
{"op":"mcm","clk":"993759223","pt":1580546091353,"mc":[{"id":"1.168133553","rc":[{"batb":[[0,1.31,51.5],[1,1.3,190.25],[2,1.29,427.85]],"ltp":1.33,"tv":5921.89,"id":16325787}]}]}
{"op":"mcm","clk":"993759289","pt":1580546092434,"mc":[{"id":"1.168133553","rc":[{"batl":[[0,1.33,28.38]],"ltp":1.33,"tv":5921.89,"id":16325787}]}]}
{"op":"mcm","clk":"993759369","pt":1580546093571,"mc":[{"id":"1.168133553","rc":[{"batb":[[1,1.3,180.87]],"ltp":1.33,"tv":5921.89,"id":16325787}]}]}
{"op":"mcm","clk":"993759916","pt":1580546100261,"mc":[{"id":"1.168133553","rc":[{"batl":[[1,14,3]],"ltp":10.5,"tv":182.48,"id":27227336},{"batb":[[1,5.1,12.39],[2,4.8,1.04]],"batl":[[0,5.8,7.65],[1,5.9,11.33],[2,6.8,18.57]],"ltp":5.8,"tv":751.13,"id":21641292}]}]}
{"op":"mcm","clk":"993760598","pt":1580546108084,"mc":[{"id":"1.168133553","rc":[{"batb":[[0,5.6,3.08],[1,5.2,2.24],[2,5.1,12.16]],"ltp":5.8,"tv":751.13,"id":21641292}]}]}
{"op":"mcm","clk":"993761230","pt":1580546115488,"mc":[{"id":"1.168133553","rc":[{"trd":[[1.33,484.19],[1.34,1109.59]],"batl":[[0,1.34,1896.73],[1,1.35,180.86],[2,1.36,251.95]],"ltp":1.34,"tv":6041.89,"id":16325787}],"tv":6975.51}]}
{"op":"mcm","clk":"993761322","pt":1580546116471,"mc":[{"id":"1.168133553","rc":[{"batb":[[1,5.2,4.5],[2,5.1,2.32]],"ltp":5.8,"tv":751.13,"id":21641292},{"batb":[[0,1.31,77.78]],"ltp":1.34,"tv":6041.89,"id":16325787}]}]}
{"op":"mcm","clk":"993766080","pt":1580546172474,"mc":[{"id":"1.168133553","rc":[{"trd":[[5.8,98.32]],"batl":[[0,5.9,11.33],[1,6.8,23.24],[2,7,15.07]],"ltp":5.8,"tv":766.43,"id":21641292}],"tv":6990.81}]}
{"op":"mcm","clk":"993766696","pt":1580546180163,"mc":[{"id":"1.168133553","rc":[{"batb":[[1,5.5,27.13],[2,5.2,4.27]],"ltp":5.8,"tv":766.43,"id":21641292}]}]}
{"op":"mcm","clk":"993767277","pt":1580546187511,"mc":[{"id":"1.168133553","rc":[{"trd":[[5.6,28.29]],"batb":[[0,5.5,27.13],[1,5.2,2.27],[2,5.1,2.32]],"ltp":5.6,"tv":776.58,"id":21641292}],"tv":7000.96}]}
{"op":"mcm","clk":"993767509","pt":1580546190201,"mc":[{"id":"1.168133553","rc":[{"batl":[[1,14,12.31]],"ltp":10.5,"tv":182.48,"id":27227336}]}]}
{"op":"mcm","clk":"993769910","pt":1580546217548,"mc":[{"id":"1.168133553","rc":[{"batb":[[1,5.2,17.64]],"ltp":5.6,"tv":776.58,"id":21641292}]}]}
{"op":"mcm","clk":"993770000","pt":1580546218533,"mc":[{"id":"1.168133553","rc":[{"trd":[[5.5,65.69]],"batb":[[0,5.5,24.13]],"ltp":5.5,"tv":782.58,"id":21641292}],"tv":7006.96}]}
{"op":"mcm","clk":"993770145","pt":1580546220543,"mc":[{"id":"1.168133553","rc":[{"batb":[[0,5.6,8.16],[1,5.5,26.89],[2,5.2,17.64]],"ltp":5.5,"tv":782.58,"id":21641292}]}]}
{"op":"mcm","clk":"993770311","pt":1580546222523,"mc":[{"id":"1.168133553","rc":[{"batl":[[0,5.9,11.56]],"ltp":5.5,"tv":782.58,"id":21641292}]}]}
{"op":"mcm","clk":"993770618","pt":1580546226254,"mc":[{"id":"1.168133553","rc":[{"batb":[[0,5.6,10.16]],"ltp":5.5,"tv":782.58,"id":21641292}]}]}
{"op":"mcm","clk":"993790341","pt":1580546332489,"mc":[{"id":"1.168133553","rc":[{"trd":[[1.34,1809.59]],"batb":[[0,1.32,13.05],[1,1.31,77.78],[2,1.3,180.87]],"batl":[[0,1.34,1546.73]],"ltp":1.34,"tv":6741.89,"id":16325787}],"tv":7706.96}]}
{"op":"mcm","clk":"993791244","pt":1580546344501,"mc":[{"id":"1.168133553","rc":[{"batb":[[1,1.31,202.78]],"ltp":1.34,"tv":6741.89,"id":16325787}]}]}
{"op":"mcm","clk":"993793241","pt":1580546369460,"mc":[{"id":"1.168133553","rc":[{"batb":[[2,1.3,112.87]],"ltp":1.34,"tv":6741.89,"id":16325787}]}]}
{"op":"mcm","clk":"993794000","pt":1580546378544,"mc":[{"id":"1.168133553","rc":[{"trd":[[1.33,544.19]],"batb":[[0,1.33,30],[1,1.32,13.05],[2,1.31,202.78]],"ltp":1.33,"tv":6801.89,"id":16325787}],"tv":7766.96}]}
{"op":"mcm","clk":"993794048","pt":1580546379058,"mc":[{"id":"1.168133553","rc":[{"trd":[[1.33,604.19]],"batb":[[0,1.32,13.05],[1,1.31,202.78],[2,1.3,112.87]],"ltp":1.33,"tv":6861.89,"id":16325787}],"tv":7826.96}]}
{"op":"mcm","clk":"993797220","pt":1580546411538,"mc":[{"id":"1.168133553","rc":[{"batb":[[1,5.5,39.89]],"ltp":5.5,"tv":782.58,"id":21641292}]}]}
{"op":"mcm","clk":"993797273","pt":1580546412163,"mc":[{"id":"1.168133553","rc":[{"trd":[[5.6,40.29]],"batb":[[0,5.6,4.16]],"ltp":5.6,"tv":794.58,"id":21641292},{"trd":[[1.34,1841.59]],"batl":[[0,1.34,1530.73]],"ltp":1.34,"tv":6893.89,"id":16325787}],"tv":7870.96}]}
{"op":"mcm","clk":"993798487","pt":1580546427394,"mc":[{"id":"1.168133553","rc":[{"batb":[[1,10,15.77]],"ltp":10.5,"tv":182.48,"id":27227336}]}]}
{"op":"mcm","clk":"993800567","pt":1580546450276,"mc":[{"id":"1.168133553","rc":[{"batb":[[2,1.3,142.87]],"ltp":1.34,"tv":6893.89,"id":16325787}]}]}
{"op":"mcm","clk":"993816945","pt":1580546626543,"mc":[{"id":"1.168133553","rc":[{"batl":[[0,1.35,180.86],[1,1.36,273.76],[2,1.37,58.73]],"ltp":1.34,"tv":6893.89,"id":16325787}]}]}
{"op":"mcm","clk":"993818449","pt":1580546642386,"mc":[{"id":"1.168133553","rc":[{"batl":[[0,1.35,1680.86]],"ltp":1.34,"tv":6893.89,"id":16325787}]}]}
{"op":"mcm","clk":"993819814","pt":1580546656418,"mc":[{"id":"1.168133553","rc":[{"batl":[[1,1.36,251.95]],"ltp":1.34,"tv":6893.89,"id":16325787}]}]}
{"op":"mcm","clk":"993822477","pt":1580546686552,"mc":[{"id":"1.168133553","rc":[{"batl":[[1,1.36,254.25]],"ltp":1.34,"tv":6893.89,"id":16325787}]}]}
{"op":"mcm","clk":"993826205","pt":1580546731367,"mc":[{"id":"1.168133553","rc":[{"trd":[[5.6,44.29]],"batb":[[0,5.6,2.16]],"ltp":5.6,"tv":798.58,"id":21641292}],"tv":7874.96}]}
{"op":"mcm","clk":"993827319","pt":1580546744885,"mc":[{"id":"1.168133553","rc":[{"batb":[[2,5.2,15.38]],"ltp":5.6,"tv":798.58,"id":21641292}]}]}
{"op":"mcm","clk":"993827694","pt":1580546749494,"mc":[{"id":"1.168133553","rc":[{"trd":[[5.6,48.61]],"batb":[[0,5.5,39.89],[1,5.2,15.38],[2,5.1,2.32]],"batl":[[0,5.6,7.84],[1,5.9,11.56],[2,6.8,23.24]],"ltp":5.6,"tv":802.9,"id":21641292}],"tv":7879.28}]}
{"op":"mcm","clk":"993827830","pt":1580546751517,"mc":[{"id":"1.168133553","rc":[{"batl":[[1,14,3]],"ltp":10.5,"tv":182.48,"id":27227336},{"batb":[[0,5.5,13]],"ltp":5.6,"tv":802.9,"id":21641292}]}]}
{"op":"mcm","clk":"993827916","pt":1580546752200,"mc":[{"id":"1.168133553","rc":[{"batb":[[1,5.2,9.84]],"ltp":5.6,"tv":802.9,"id":21641292}]}]}
{"op":"mcm","clk":"993828265","pt":1580546756433,"mc":[{"id":"1.168133553","rc":[{"batb":[[1,5.3,2],[2,5.2,9.84]],"ltp":5.6,"tv":802.9,"id":21641292}]}]}
{"op":"mcm","clk":"993831784","pt":1580546795484,"mc":[{"id":"1.168133553","rc":[{"batb":[[1,5.4,2]],"ltp":5.6,"tv":802.9,"id":21641292}]}]}
{"op":"mcm","clk":"993833907","pt":1580546819522,"mc":[{"id":"1.168133553","rc":[{"trd":[[5.5,69.69]],"batb":[[0,5.5,11]],"ltp":5.5,"tv":806.9,"id":21641292}],"tv":7883.28}]}
{"op":"mcm","clk":"993838226","pt":1580546876495,"mc":[{"id":"1.168133553","rc":[{"trd":[[5.6,64.29]],"batb":[[0,5.6,7.28],[1,5.5,11],[2,5.4,2]],"batl":[[0,5.9,11.56],[1,6.8,23.24],[2,7,15.07]],"ltp":5.6,"tv":822.58,"id":21641292}],"tv":7898.96}]}
{"op":"mcm","clk":"993838601","pt":1580546881532,"mc":[{"id":"1.168133553","rc":[{"batb":[[0,5.5,37.89],[1,5.4,2],[2,5.2,9.84]],"ltp":5.6,"tv":822.58,"id":21641292}]}]}
{"op":"mcm","clk":"993839408","pt":1580546891546,"mc":[{"id":"1.168133553","rc":[{"batl":[[1,14,12.31]],"ltp":10.5,"tv":182.48,"id":27227336}]}]}
{"op":"mcm","clk":"993840957","pt":1580546911438,"mc":[{"id":"1.168133553","rc":[{"batb":[[2,5.2,19.68]],"ltp":5.6,"tv":822.58,"id":21641292}]}]}
{"op":"mcm","clk":"993841396","pt":1580546916562,"mc":[{"id":"1.168133553","rc":[{"batb":[[1,1.31,231.03]],"ltp":1.34,"tv":6893.89,"id":16325787}]}]}
{"op":"mcm","clk":"993843274","pt":1580546940876,"mc":[{"id":"1.168133553","rc":[{"batb":[[2,5.2,29.52]],"ltp":5.6,"tv":822.58,"id":21641292}]}]}
{"op":"mcm","clk":"993845776","pt":1580546973370,"mc":[{"id":"1.168133553","rc":[{"trd":[[5.8,98.77],[5.9,119.16]],"batl":[[0,5.9,5.56]],"ltp":5.9,"tv":834.58,"id":21641292}],"tv":7910.96}]}
{"op":"mcm","clk":"993845878","pt":1580546974566,"mc":[{"id":"1.168133553","rc":[{"trd":[[5.9,123.16]],"batl":[[0,5.9,3.56]],"ltp":5.9,"tv":838.58,"id":21641292}],"tv":7914.96}]}
{"op":"mcm","clk":"993846422","pt":1580546980494,"mc":[{"id":"1.168133553","rc":[{"batb":[[0,5.5,38.13]],"ltp":5.9,"tv":838.58,"id":21641292}]}]}
{"op":"mcm","clk":"993848118","pt":1580547000490,"mc":[{"id":"1.168133553","rc":[{"batl":[[1,6.8,11.61]],"ltp":5.9,"tv":838.58,"id":21641292}]}]}
{"op":"mcm","clk":"993849369","pt":1580547015737,"mc":[{"id":"1.168133553","rc":[{"batb":[[0,5.6,3],[1,5.5,38.13],[2,5.4,2]],"ltp":5.9,"tv":838.58,"id":21641292}]}]}
{"op":"mcm","clk":"993849550","pt":1580547018505,"mc":[{"id":"1.168133553","rc":[{"trd":[[1.32,2499.86]],"batb":[[0,1.31,231.03],[1,1.3,142.87],[2,1.29,427.85]],"batl":[[0,1.32,11.95],[1,1.35,1680.86],[2,1.36,254.25]],"ltp":1.32,"tv":6919.99,"id":16325787}],"tv":7941.05}]}
{"op":"mcm","clk":"993849568","pt":1580547018812,"mc":[{"id":"1.168133553","rc":[{"trd":[[1.32,2523.76]],"batb":[[0,1.32,5.26],[1,1.31,231.03],[2,1.3,142.87]],"batl":[[0,1.35,1680.86],[1,1.36,254.25],[2,1.37,58.73]],"ltp":1.32,"tv":6943.89,"id":16325787}],"tv":7964.95}]}
{"op":"mcm","clk":"993849657","pt":1580547020308,"mc":[{"id":"1.168133553","rc":[{"batl":[[1,1.36,256.52]],"ltp":1.32,"tv":6943.89,"id":16325787}]}]}
{"op":"mcm","clk":"993850080","pt":1580547026406,"mc":[{"id":"1.168133553","rc":[{"batl":[[0,1.34,4.85],[1,1.35,1680.86],[2,1.36,256.52]],"ltp":1.32,"tv":6943.89,"id":16325787}]}]}
{"op":"mcm","clk":"993850157","pt":1580547027242,"mc":[{"id":"1.168133553","rc":[{"batl":[[0,1.35,1680.86],[1,1.36,256.52],[2,1.37,58.73]],"ltp":1.32,"tv":6943.89,"id":16325787}]}]}
{"op":"mcm","clk":"993850270","pt":1580547028428,"mc":[{"id":"1.168133553","rc":[{"batb":[[0,5.6,5],[2,5.2,19.68]],"ltp":5.9,"tv":838.58,"id":21641292}]}]}
{"op":"mcm","clk":"993852416","pt":1580547053406,"mc":[{"id":"1.168133553","rc":[{"batl":[[0,1.35,1630.86]],"ltp":1.32,"tv":6943.89,"id":16325787}]}]}
{"op":"mcm","clk":"993860008","pt":1580547148523,"mc":[{"id":"1.168133553","rc":[{"trd":[[5.6,74.29]],"batb":[[0,5.5,38.13],[1,5.2,29.52],[2,5.1,2.32]],"ltp":5.6,"tv":848.57,"id":21641292}],"tv":7974.95}]}
{"op":"mcm","clk":"993860049","pt":1580547149036,"mc":[{"id":"1.168133553","rc":[{"trd":[[5.5,75.69]],"batb":[[0,5.5,35.13]],"ltp":5.5,"tv":854.57,"id":21641292},{"trd":[[1.35,15.99]],"batl":[[0,1.35,1622.86]],"ltp":1.35,"tv":6959.88,"id":16325787}],"tv":7996.95}]}
{"op":"mcm","clk":"993871620","pt":1580547169561,"mc":[{"id":"1.168133553","rc":[{"trd":[[5.5,79.69]],"batb":[[0,5.5,33.13]],"ltp":5.5,"tv":858.57,"id":21641292}],"tv":8000.95}]}
{"op":"mcm","clk":"993873762","pt":1580547194944,"mc":[{"id":"1.168133553","rc":[{"batl":[[0,5.8,2.9],[1,5.9,3.56],[2,6.8,11.61]],"ltp":5.5,"tv":858.57,"id":21641292}]}]}
{"op":"mcm","clk":"993874724","pt":1580547207353,"mc":[{"id":"1.168133553","rc":[{"batl":[[2,6.8,2.16]],"ltp":5.5,"tv":858.57,"id":21641292}]}]}
{"op":"mcm","clk":"993874832","pt":1580547208549,"mc":[{"id":"1.168133553","rc":[{"batb":[[0,1.32,227.26]],"ltp":1.35,"tv":6959.88,"id":16325787}]}]}
{"op":"mcm","clk":"993875016","pt":1580547210554,"mc":[{"id":"1.168133553","rc":[{"trd":[[1.33,655.96]],"batb":[[1,1.31,204.75]],"ltp":1.33,"tv":7011.65,"id":16325787}],"tv":8052.71}]}
{"op":"mcm","clk":"993875083","pt":1580547211276,"mc":[{"id":"1.168133553","rc":[{"batl":[[0,1.33,3.23],[1,1.35,1622.86],[2,1.36,254.25]],"ltp":1.33,"tv":7011.65,"id":16325787}]}]}
{"op":"mcm","clk":"993875219","pt":1580547212987,"mc":[{"id":"1.168133553","rc":[{"batb":[[1,5.3,2],[2,5.2,29.52]],"ltp":5.5,"tv":858.57,"id":21641292}]}]}
{"op":"mcm","clk":"993875585","pt":1580547217045,"mc":[{"id":"1.168133553","rc":[{"batl":[[1,1.34,32.46],[2,1.35,1622.86]],"ltp":1.33,"tv":7011.65,"id":16325787}]}]}
{"op":"mcm","clk":"993877750","pt":1580547242413,"mc":[{"id":"1.168133553","rc":[{"batb":[[1,5.4,2]],"ltp":5.5,"tv":858.57,"id":21641292}]}]}
{"op":"mcm","clk":"993891758","pt":1580547393462,"mc":[{"id":"1.168133553","rc":[{"trd":[[5.5,83.69]],"batb":[[0,5.5,31.13]],"ltp":5.5,"tv":862.57,"id":21641292},{"trd":[[1.33,662.42],[1.34,1875.13]],"batl":[[0,1.34,15.69],[1,1.35,1622.86],[2,1.36,251.95]],"ltp":1.34,"tv":7051.65,"id":16325787}],"tv":8096.71}]}
{"op":"mcm","clk":"993897329","pt":1580547454370,"mc":[{"id":"1.168133553","rc":[{"batl":[[0,1.34,90.69]],"ltp":1.34,"tv":7051.65,"id":16325787}]}]}
{"op":"mcm","clk":"993899835","pt":1580547486503,"mc":[{"id":"1.168133553","rc":[{"trd":[[1.34,1885.13]],"batl":[[0,1.34,85.69]],"ltp":1.34,"tv":7061.65,"id":16325787}],"tv":8106.71}]}
{"op":"mcm","clk":"993901143","pt":1580547504550,"mc":[{"id":"1.168133553","rc":[{"batl":[[0,1.34,10.69]],"ltp":1.34,"tv":7061.65,"id":16325787}]}]}
{"op":"mcm","clk":"993901383","pt":1580547507472,"mc":[{"id":"1.168133553","rc":[{"batb":[[0,1.32,222]],"batl":[[0,1.33,11.87],[1,1.34,1010.69],[2,1.35,1622.86]],"ltp":1.34,"tv":7061.65,"id":16325787}]}]}
{"op":"mcm","clk":"993901819","pt":1580547512842,"mc":[{"id":"1.168133553","rc":[{"batl":[[1,14,3]],"ltp":10.5,"tv":182.48,"id":27227336},{"batb":[[0,5.5,4.24]],"batl":[[0,5.7,7.97],[1,5.8,2.9],[2,5.9,3.56]],"ltp":5.5,"tv":862.57,"id":21641292}]}]}
{"op":"mcm","clk":"993901957","pt":1580547514492,"mc":[{"id":"1.168133553","rc":[{"batb":[[2,5.1,2.32]],"ltp":5.5,"tv":862.57,"id":21641292}]}]}
{"op":"mcm","clk":"993904350","pt":1580547544096,"mc":[{"id":"1.168133553","rc":[{"batb":[[2,5.1,5.9]],"ltp":5.5,"tv":862.57,"id":21641292}]}]}
{"op":"mcm","clk":"993907310","pt":1580547580498,"mc":[{"id":"1.168133553","rc":[{"trd":[[5.5,87.69],[5.7,122.53]],"batb":[[0,5.5,2.24]],"batl":[[0,5.8,2.9],[1,5.9,3.56],[2,6.8,39.16]],"ltp":5.5,"tv":882.52,"id":21641292}],"tv":8126.65}]}
{"op":"mcm","clk":"993909591","pt":1580547605537,"mc":[{"id":"1.168133553","rc":[{"batl":[[2,6.6,3.19]],"ltp":5.5,"tv":882.52,"id":21641292}]}]}
{"op":"mcm","clk":"993910147","pt":1580547610476,"mc":[{"id":"1.168133553","rc":[{"trd":[[5.5,89.69]],"batb":[[0,5.5,1.24]],"ltp":5.5,"tv":884.52,"id":21641292},{"trd":[[1.32,2526.76]],"batb":[[0,1.32,220.5]],"ltp":1.32,"tv":7064.65,"id":16325787}],"tv":8131.65}]}
{"op":"mcm","clk":"993910263","pt":1580547611574,"mc":[{"id":"1.168133553","rc":[{"trd":[[5.5,91.69]],"batb":[[0,5.4,2.24],[1,5.1,5.9],[2,4.8,1.04]],"ltp":5.5,"tv":886.52,"id":21641292},{"trd":[[1.32,2527.76]],"batb":[[0,1.32,220]],"ltp":1.32,"tv":7065.65,"id":16325787}],"tv":8134.65}]}
{"op":"mcm","clk":"993910349","pt":1580547612459,"mc":[{"id":"1.168133553","rc":[{"trd":[[5.4,0.52],[5.5,92.17]],"batb":[[0,5.4,1.74]],"ltp":5.4,"tv":887.51,"id":21641292}],"tv":8135.65}]}
{"op":"mcm","clk":"993910543","pt":1580547614443,"mc":[{"id":"1.168133553","rc":[{"batl":[[0,5.8,3.13]],"ltp":5.4,"tv":887.51,"id":21641292}]}]}
{"op":"mcm","clk":"993910987","pt":1580547619558,"mc":[{"id":"1.168133553","rc":[{"batb":[[0,5.1,2.32],[1,4.8,2.78],[2,4.7,2.53]],"ltp":5.4,"tv":887.51,"id":21641292}]}]}
{"op":"mcm","clk":"993911633","pt":1580547626396,"mc":[{"id":"1.168133553","rc":[{"batb":[[0,11,1.98],[1,10.5,2.36],[2,10,15.77]],"ltp":10.5,"tv":182.48,"id":27227336},{"batb":[[0,4.9,2.32]],"ltp":5.4,"tv":887.51,"id":21641292}]}]}
{"op":"mcm","clk":"993912493","pt":1580547636392,"mc":[{"id":"1.168133553","rc":[{"batb":[[0,5,3.52],[1,4.9,1.98],[2,4.8,2.78]],"ltp":5.4,"tv":887.51,"id":21641292}]}]}
{"op":"mcm","clk":"993912706","pt":1580547638514,"mc":[{"id":"1.168133553","rc":[{"batb":[[1,10.5,1.64]],"ltp":10.5,"tv":182.48,"id":27227336}]}]}
{"op":"mcm","clk":"993912789","pt":1580547639511,"mc":[{"id":"1.168133553","rc":[{"batb":[[1,4.9,3.72],[2,4.8,1.04]],"ltp":5.4,"tv":887.51,"id":21641292}]}]}
{"op":"mcm","clk":"993913048","pt":1580547642501,"mc":[{"id":"1.168133553","rc":[{"batb":[[0,5.1,3.46],[1,5,3.18],[2,4.9,3.72]],"ltp":5.4,"tv":887.51,"id":21641292}]}]}
{"op":"mcm","clk":"993913324","pt":1580547645730,"mc":[{"id":"1.168133553","rc":[{"batb":[[0,10.5,3.62],[1,10,15.77],[2,9.6,6.46]],"ltp":10.5,"tv":182.48,"id":27227336}]}]}
{"op":"mcm","clk":"993913745","pt":1580547650700,"mc":[{"id":"1.168133553","rc":[{"trd":[[1.32,2532.8]],"batb":[[0,1.32,217.48]],"ltp":1.32,"tv":7070.69,"id":16325787}],"tv":8140.69}]}
{"op":"mcm","clk":"993913917","pt":1580547652407,"mc":[{"id":"1.168133553","rc":[{"trd":[[1.32,2578.84]],"batb":[[0,1.32,194.46]],"batl":[[0,1.33,60.65]],"ltp":1.32,"tv":7116.73,"id":16325787}],"tv":8186.73}]}
{"op":"mcm","clk":"993914050","pt":1580547653308,"mc":[{"id":"1.168133553","rc":[{"trd":[[1.32,2583.4]],"batb":[[0,1.32,192.18]],"batl":[[0,1.33,11.87]],"ltp":1.32,"tv":7121.29,"id":16325787}],"tv":8191.29}]}
{"op":"mcm","clk":"993914176","pt":1580547654103,"mc":[{"id":"1.168133553","rc":[{"trd":[[1.32,2587.94]],"batb":[[0,1.32,189.91]],"ltp":1.32,"tv":7125.83,"id":16325787}],"tv":8195.83}]}
{"op":"mcm","clk":"993914702","pt":1580547659530,"mc":[{"id":"1.168133553","rc":[{"batb":[[0,5.1,5.2],[2,4.9,1.98]],"ltp":5.4,"tv":887.51,"id":21641292}]}]}
{"op":"mcm","clk":"993914860","pt":1580547661114,"mc":[{"id":"1.168133553","rc":[{"batb":[[0,5.2,3.06],[1,5.1,5.2]],"ltp":5.4,"tv":887.51,"id":21641292}]}]}
{"op":"mcm","clk":"993916788","pt":1580547678979,"mc":[{"id":"1.168133553","rc":[{"batb":[[0,5.2,4.8],[1,5.1,3.46]],"ltp":5.4,"tv":887.51,"id":21641292}]}]}
{"op":"mcm","clk":"993917331","pt":1580547684495,"mc":[{"id":"1.168133553","rc":[{"batb":[[1,1.31,176.5]],"ltp":1.32,"tv":7125.83,"id":16325787}]}]}
{"op":"mcm","clk":"993917346","pt":1580547684599,"mc":[{"id":"1.168133553","rc":[{"batb":[[2,1.3,171.12]],"ltp":1.32,"tv":7125.83,"id":16325787}]}]}
{"op":"mcm","clk":"993927051","pt":1580547770482,"mc":[{"id":"1.168133553","rc":[{"trd":[[1.32,2592.64]],"batb":[[0,1.32,187.56]],"ltp":1.32,"tv":7130.53,"id":16325787}],"tv":8200.53}]}
{"op":"mcm","clk":"993928182","pt":1580547781488,"mc":[{"id":"1.168133553","rc":[{"trd":[[5.8,105.03]],"batb":[[0,5.8,8.61],[1,5.2,4.8],[2,5.1,3.46]],"batl":[[0,5.9,3.56],[1,6.6,3.19],[2,6.8,2]],"ltp":5.8,"tv":893.77,"id":21641292}],"tv":8206.79}]}
{"op":"mcm","clk":"993928307","pt":1580547782522,"mc":[{"id":"1.168133553","rc":[{"batl":[[1,6.4,2.75],[2,6.6,3.03]],"ltp":5.8,"tv":893.77,"id":21641292}]}]}
{"op":"mcm","clk":"993928391","pt":1580547783413,"mc":[{"id":"1.168133553","rc":[{"batb":[[1,5.5,26.89],[2,5.2,4.8]],"ltp":5.8,"tv":893.77,"id":21641292}]}]}
{"op":"mcm","clk":"993928507","pt":1580547784495,"mc":[{"id":"1.168133553","rc":[{"batb":[[1,5.5,31.45]],"batl":[[1,6.6,3.19],[2,6.8,2]],"ltp":5.8,"tv":893.77,"id":21641292}]}]}
{"op":"mcm","clk":"993928722","pt":1580547786512,"mc":[{"id":"1.168133553","rc":[{"batb":[[1,5.5,31.69]],"ltp":5.8,"tv":893.77,"id":21641292}]}]}
{"op":"mcm","clk":"993928831","pt":1580547787503,"mc":[{"id":"1.168133553","rc":[{"batb":[[0,11,3.03],[1,10.5,3.62],[2,10,15.77]],"ltp":10.5,"tv":182.48,"id":27227336},{"batl":[[1,6.8,2.16],[2,7,15.07]],"ltp":5.8,"tv":893.77,"id":21641292}]}]}
{"op":"mcm","clk":"993929465","pt":1580547793536,"mc":[{"id":"1.168133553","rc":[{"batl":[[1,14,12.31]],"ltp":10.5,"tv":182.48,"id":27227336}]}]}
{"op":"mcm","clk":"993931403","pt":1580547813556,"mc":[{"id":"1.168133553","rc":[{"batl":[[1,6.8,7.39]],"ltp":5.8,"tv":893.77,"id":21641292}]}]}
{"op":"mcm","clk":"993932776","pt":1580547827489,"mc":[{"id":"1.168133553","rc":[{"batb":[[2,5.2,3.06]],"ltp":5.8,"tv":893.77,"id":21641292}]}]}
{"op":"mcm","clk":"993932883","pt":1580547828474,"mc":[{"id":"1.168133553","rc":[{"trd":[[5.9,130.28]],"batb":[[0,5.9,4.27],[1,5.8,8.61],[2,5.6,1.74]],"batl":[[0,6.8,7.39],[1,7,15.07],[2,7.6,2.19]],"ltp":5.9,"tv":900.89,"id":21641292}],"tv":8213.91}]}
{"op":"mcm","clk":"993932982","pt":1580547829513,"mc":[{"id":"1.168133553","rc":[{"batl":[[0,6.8,2.16]],"ltp":5.9,"tv":900.89,"id":21641292}]}]}
{"op":"mcm","clk":"993934807","pt":1580547847288,"mc":[{"id":"1.168133553","rc":[{"batb":[[0,5.9,6.01],[2,5.5,31.69]],"ltp":5.9,"tv":900.89,"id":21641292}]}]}
{"op":"mcm","clk":"993936905","pt":1580547866224,"mc":[{"id":"1.168133553","rc":[{"trd":[[1.32,2593.32]],"batb":[[0,1.32,187.22]],"ltp":1.32,"tv":7131.21,"id":16325787}],"tv":8214.59}]}
{"op":"mcm","clk":"993937698","pt":1580547874138,"mc":[{"id":"1.168133553","rc":[{"batb":[[0,11,2.89]],"ltp":10.5,"tv":182.48,"id":27227336},{"batb":[[2,5.5,35.34]],"batl":[[2,7.6,5.22]],"ltp":5.9,"tv":900.89,"id":21641292}]}]}
{"op":"mcm","clk":"993938675","pt":1580547884553,"mc":[{"id":"1.168133553","rc":[{"batl":[[1,14,3]],"ltp":10.5,"tv":182.48,"id":27227336},{"batb":[[2,5.7,25.75]],"ltp":5.9,"tv":900.89,"id":21641292}]}]}
{"op":"mcm","clk":"993939682","pt":1580547894486,"mc":[{"id":"1.168133553","rc":[{"batl":[[0,13.5,12.39]],"ltp":10.5,"tv":182.48,"id":27227336}]}]}
{"op":"mcm","clk":"993946288","pt":1580547959562,"mc":[{"id":"1.168133553","rc":[{"trd":[[5.9,134.28]],"batb":[[0,5.9,4.01]],"ltp":5.9,"tv":904.89,"id":21641292},{"trd":[[1.33,682.54]],"batl":[[0,1.33,1.81]],"ltp":1.33,"tv":7151.33,"id":16325787}],"tv":8238.71}]}
{"op":"mcm","clk":"993948164","pt":1580547978202,"mc":[{"id":"1.168133553","rc":[{"batl":[[0,6.6,2.16],[1,6.8,2],[2,7,15.07]],"ltp":5.9,"tv":904.89,"id":21641292}]}]}
{"op":"mcm","clk":"993950575","pt":1580548004419,"mc":[{"id":"1.168133553","rc":[{"batl":[[0,6.6,5.2]],"ltp":5.9,"tv":904.89,"id":21641292}]}]}
{"op":"mcm","clk":"993952466","pt":1580548026342,"mc":[{"id":"1.168133553","rc":[{"trd":[[5.9,140.42]],"batb":[[0,5.7,26.69],[1,5.6,4.49],[2,5.5,3.89]],"ltp":5.9,"tv":911.03,"id":21641292}],"tv":8244.85}]}
{"op":"mcm","clk":"993953545","pt":1580548039457,"mc":[{"id":"1.168133553","rc":[{"batl":[[0,6.6,2.16]],"ltp":5.9,"tv":911.03,"id":21641292}]}]}
{"op":"mcm","clk":"993953641","pt":1580548040555,"mc":[{"id":"1.168133553","rc":[{"batl":[[1,6.8,5.03]],"ltp":5.9,"tv":911.03,"id":21641292}]}]}
{"op":"mcm","clk":"993964844","pt":1580548055489,"mc":[{"id":"1.168133553","rc":[{"trd":[[5.7,148.27]],"batb":[[0,5.7,13.82]],"ltp":5.7,"tv":936.77,"id":21641292},{"trd":[[1.33,690.16]],"batb":[[0,1.33,7.95],[1,1.32,187.22],[2,1.31,176.5]],"batl":[[0,1.34,1010.69],[1,1.35,1622.86],[2,1.36,251.95]],"ltp":1.33,"tv":7158.94,"id":16325787}],"tv":8278.21}]}
{"op":"mcm","clk":"993964924","pt":1580548056369,"mc":[{"id":"1.168133553","rc":[{"batb":[[1,5.5,3.89],[2,5.1,3.46]],"ltp":5.7,"tv":936.77,"id":21641292},{"trd":[[1.33,706.06]],"batb":[[0,1.32,187.22],[1,1.31,176.5],[2,1.3,171.12]],"batl":[[0,1.33,3.95],[1,1.34,1010.69],[2,1.35,1622.86]],"ltp":1.33,"tv":7174.84,"id":16325787}],"tv":8294.11}]}
{"op":"mcm","clk":"993965036","pt":1580548057574,"mc":[{"id":"1.168133553","rc":[{"batb":[[1,5.5,6.86]],"ltp":5.7,"tv":936.77,"id":21641292}]}]}
{"op":"mcm","clk":"993965292","pt":1580548060491,"mc":[{"id":"1.168133553","rc":[{"batl":[[0,6.6,4.57]],"ltp":5.7,"tv":936.77,"id":21641292}]}]}
{"op":"mcm","clk":"993965618","pt":1580548064535,"mc":[{"id":"1.168133553","rc":[{"batb":[[0,5.7,26.69]],"ltp":5.7,"tv":936.77,"id":21641292}]}]}
{"op":"mcm","clk":"993966274","pt":1580548072521,"mc":[{"id":"1.168133553","rc":[{"batl":[[0,6.4,3.19],[1,6.6,4.41],[2,6.8,2]],"ltp":5.7,"tv":936.77,"id":21641292}]}]}
{"op":"mcm","clk":"993967543","pt":1580548086544,"mc":[{"id":"1.168133553","rc":[{"batb":[[0,5.7,25.75],[1,5.5,7.8]],"batl":[[0,6.2,2.16],[1,6.4,3.03],[2,6.6,2.41]],"ltp":5.7,"tv":936.77,"id":21641292}]}]}
{"op":"mcm","clk":"993969071","pt":1580548105449,"mc":[{"id":"1.168133553","rc":[{"batl":[[1,6.6,2.41],[2,6.8,5.03]],"ltp":5.7,"tv":936.77,"id":21641292}]}]}
{"op":"mcm","clk":"993969288","pt":1580548108430,"mc":[{"id":"1.168133553","rc":[{"trd":[[5.7,199.77]],"batb":[[0,5.5,7.8],[1,5.2,9.84],[2,5.1,11.99]],"ltp":5.7,"tv":988.27,"id":21641292}],"tv":8345.61}]}
{"op":"mcm","clk":"993971622","pt":1580548136085,"mc":[{"id":"1.168133553","rc":[{"batb":[[0,5.5,6.86],[1,5.2,10.78]],"ltp":5.7,"tv":988.27,"id":21641292}]}]}
{"op":"mcm","clk":"993971750","pt":1580548137490,"mc":[{"id":"1.168133553","rc":[{"trd":[[5.5,102.16]],"batb":[[0,5.1,12.93],[1,4.9,1.98],[2,4.8,1.04]],"batl":[[0,6,3.89],[1,6.2,2.16],[2,6.6,2.41]],"ltp":5.5,"tv":998.27,"id":21641292}],"tv":8355.6}]}
{"op":"mcm","clk":"993971839","pt":1580548138479,"mc":[{"id":"1.168133553","rc":[{"batb":[[0,5.1,4.4],[2,4.8,11.08]],"ltp":5.5,"tv":998.27,"id":21641292}]}]}
{"op":"mcm","clk":"993971954","pt":1580548139567,"mc":[{"id":"1.168133553","rc":[{"batb":[[2,4.8,15.13]],"batl":[[2,6.4,5.27]],"ltp":5.5,"tv":998.27,"id":21641292}]}]}
{"op":"mcm","clk":"993971987","pt":1580548139882,"mc":[{"id":"1.168133553","rc":[{"batl":[[0,6,4.12]],"ltp":5.5,"tv":998.27,"id":21641292}]}]}
{"op":"mcm","clk":"993972146","pt":1580548141500,"mc":[{"id":"1.168133553","rc":[{"batl":[[0,5.9,2.23],[1,6,3.89],[2,6.4,5.43]],"ltp":5.5,"tv":998.27,"id":21641292}]}]}
{"op":"mcm","clk":"993972475","pt":1580548145517,"mc":[{"id":"1.168133553","rc":[{"batb":[[0,5.1,3.46],[1,4.9,2.92]],"ltp":5.5,"tv":998.27,"id":21641292}]}]}
{"op":"mcm","clk":"993972557","pt":1580548146401,"mc":[{"id":"1.168133553","rc":[{"batb":[[2,4.8,9.68]],"ltp":5.5,"tv":998.27,"id":21641292}]}]}
{"op":"mcm","clk":"993975320","pt":1580548175222,"mc":[{"id":"1.168133553","rc":[{"batb":[[2,4.8,5.09]],"ltp":5.5,"tv":998.27,"id":21641292}]}]}
{"op":"mcm","clk":"993976160","pt":1580548184535,"mc":[{"id":"1.168133553","rc":[{"batb":[[0,5.2,3.03],[1,5.1,3.46],[2,4.9,2.92]],"ltp":5.5,"tv":998.27,"id":21641292}]}]}
{"op":"mcm","clk":"993977104","pt":1580548194476,"mc":[{"id":"1.168133553","rc":[{"batb":[[0,5.2,3.97],[2,4.9,1.98]],"ltp":5.5,"tv":998.27,"id":21641292}]}]}
{"op":"mcm","clk":"993984343","pt":1580548262483,"mc":[{"id":"1.168133553","rc":[{"trd":[[1.33,717.96]],"batb":[[0,1.33,4.05],[1,1.32,187.22],[2,1.31,176.5]],"batl":[[0,1.34,1010.69],[1,1.35,1622.86],[2,1.36,251.95]],"ltp":1.33,"tv":7186.74,"id":16325787}],"tv":8367.5}]}
{"op":"mcm","clk":"993984443","pt":1580548263367,"mc":[{"id":"1.168133553","rc":[{"trd":[[1.33,726.06]],"batb":[[0,1.32,187.22],[1,1.31,176.5],[2,1.3,171.12]],"batl":[[0,1.33,2.05],[1,1.34,1010.69],[2,1.35,1622.86]],"ltp":1.33,"tv":7194.84,"id":16325787}],"tv":8375.6}]}
{"op":"mcm","clk":"993985568","pt":1580548275185,"mc":[{"id":"1.168133553","rc":[{"batl":[[0,13.5,2.71]],"ltp":10.5,"tv":182.48,"id":27227336},{"batb":[[0,5.4,27.5],[1,5.2,3.97],[2,5.1,3.46]],"batl":[[0,5.8,4.02],[1,5.9,2.23]],"ltp":5.5,"tv":998.27,"id":21641292}]}]}
{"op":"mcm","clk":"993986319","pt":1580548283389,"mc":[{"id":"1.168133553","rc":[{"batb":[[1,5.3,2],[2,5.2,3.97]],"ltp":5.5,"tv":998.27,"id":21641292}]}]}
{"op":"mcm","clk":"993986485","pt":1580548284800,"mc":[{"id":"1.168133553","rc":[{"batl":[[2,14.5,8.96]],"ltp":10.5,"tv":182.48,"id":27227336}]}]}
{"op":"mcm","clk":"993988203","pt":1580548301521,"mc":[{"id":"1.168133553","rc":[{"batb":[[0,5.4,28.44],[2,5.2,3.03]],"ltp":5.5,"tv":998.27,"id":21641292}]}]}
{"op":"mcm","clk":"993988413","pt":1580548303613,"mc":[{"id":"1.168133553","rc":[{"batl":[[1,6.4,5.66],[2,6.6,2.41]],"ltp":5.5,"tv":998.27,"id":21641292}]}]}
{"op":"mcm","clk":"993988548","pt":1580548304878,"mc":[{"id":"1.168133553","rc":[{"batl":[[1,6.4,9.04]],"ltp":5.5,"tv":998.27,"id":21641292}]}]}
{"op":"mcm","clk":"993998077","pt":1580548392211,"mc":[{"id":"1.168133553","rc":[{"batl":[[2,6.8,2]],"ltp":5.5,"tv":998.27,"id":21641292}]}]}
{"op":"mcm","clk":"994002234","pt":1580548429417,"mc":[{"id":"1.168133553","rc":[{"trd":[[1.33,730.16]],"batl":[[0,1.34,1010.69],[1,1.35,1622.86],[2,1.36,251.95]],"ltp":1.33,"tv":7198.94,"id":16325787}],"tv":8379.7}]}
{"op":"mcm","clk":"994015641","pt":1580548548183,"mc":[{"id":"1.168133553","rc":[{"batl":[[1,1.35,1567.86],[2,1.36,151.95]],"ltp":1.33,"tv":7198.94,"id":16325787}]}]}
{"op":"mcm","clk":"994016884","pt":1580548559509,"mc":[{"id":"1.168133553","rc":[{"batl":[[0,1.33,100],[1,1.34,1010.69],[2,1.35,1567.86]],"ltp":1.33,"tv":7198.94,"id":16325787}]}]}
{"op":"mcm","clk":"994017166","pt":1580548562454,"mc":[{"id":"1.168133553","rc":[{"batl":[[1,1.34,1000]],"ltp":1.33,"tv":7198.94,"id":16325787}]}]}
{"op":"mcm","clk":"994017335","pt":1580548564230,"mc":[{"id":"1.168133553","rc":[{"batb":[[0,1.32,209.33]],"ltp":1.33,"tv":7198.94,"id":16325787}]}]}
{"op":"mcm","clk":"994018583","pt":1580548575379,"mc":[{"id":"1.168133553","rc":[{"batl":[[0,1.33,300]],"ltp":1.33,"tv":7198.94,"id":16325787}]}]}
{"op":"mcm","clk":"994021463","pt":1580548600499,"mc":[{"id":"1.168133553","rc":[{"trd":[[1.32,2594.32]],"batb":[[0,1.32,208.83]],"ltp":1.32,"tv":7199.94,"id":16325787}],"tv":8380.7}]}
{"op":"mcm","clk":"994025780","pt":1580548634395,"mc":[{"id":"1.168133553","rc":[{"trd":[[1.33,933.28]],"batl":[[0,1.33,198.44]],"ltp":1.33,"tv":7403.06,"id":16325787}],"tv":8583.82}]}
{"op":"mcm","clk":"994035525","pt":1580548722155,"mc":[{"id":"1.168133553","rc":[{"trd":[[1.32,2674.32]],"batb":[[0,1.32,168.83]],"ltp":1.32,"tv":7483.06,"id":16325787}],"tv":8663.82}]}
{"op":"mcm","clk":"994036428","pt":1580548730478,"mc":[{"id":"1.168133553","rc":[{"trd":[[1.32,2684.32]],"batb":[[0,1.32,163.83]],"ltp":1.32,"tv":7493.06,"id":16325787}],"tv":8673.82}]}
{"op":"mcm","clk":"994038829","pt":1580548753484,"mc":[{"id":"1.168133553","rc":[{"batl":[[0,1.34,1000],[1,1.35,1567.86],[2,1.36,151.95]],"ltp":1.32,"tv":7493.06,"id":16325787}]}]}
{"op":"mcm","clk":"994039578","pt":1580548761224,"mc":[{"id":"1.168133553","rc":[{"batl":[[0,1.34,33.3],[2,1.36,173.76]],"ltp":1.32,"tv":7493.06,"id":16325787}]}]}
{"op":"mcm","clk":"994040617","pt":1580548771128,"mc":[{"id":"1.168133553","rc":[{"batl":[[0,1.34,1533.3]],"ltp":1.32,"tv":7493.06,"id":16325787}]}]}
{"op":"mcm","clk":"994044803","pt":1580548812387,"mc":[{"id":"1.168133553","rc":[{"trd":[[13.5,8.53]],"batl":[[0,14,3],[1,14.5,8.96],[2,17,15]],"ltp":13.5,"tv":187.9,"id":27227336},{"trd":[[5.8,113.07]],"batl":[[0,6.4,9.04],[1,6.8,2],[2,7,15.07]],"ltp":5.8,"tv":1006.31,"id":21641292},{"trd":[[1.32,3047.3]],"batb":[[0,1.31,176.5],[1,1.3,215.51],[2,1.29,458.55]],"batl":[[0,1.32,44.51],[1,1.34,1533.3],[2,1.35,1567.86]],"ltp":1.32,"tv":7856.04,"id":16325787}],"tv":9050.26}]}
{"op":"mcm","clk":"994044905","pt":1580548813481,"mc":[{"id":"1.168133553","rc":[{"batb":[[2,5.2,10.62]],"batl":[[1,6.8,6.77]],"ltp":5.8,"tv":1006.31,"id":21641292},{"batb":[[1,1.3,171.12]],"ltp":1.32,"tv":7856.04,"id":16325787}]}]}
{"op":"mcm","clk":"994045086","pt":1580548815406,"mc":[{"id":"1.168133553","rc":[{"batl":[[0,6.4,5.66],[1,6.8,2]],"ltp":5.8,"tv":1006.31,"id":21641292}]}]}
{"op":"mcm","clk":"994045177","pt":1580548816494,"mc":[{"id":"1.168133553","rc":[{"batb":[[0,11.5,1.39],[1,11,2.89],[2,10.5,3.62]],"ltp":13.5,"tv":187.9,"id":27227336}]}]}
{"op":"mcm","clk":"994045856","pt":1580548823411,"mc":[{"id":"1.168133553","rc":[{"trd":[[1.32,3068.24]],"batl":[[0,1.32,34.04]],"ltp":1.32,"tv":7876.98,"id":16325787}],"tv":9071.2}]}
{"op":"mcm","clk":"994047258","pt":1580548837507,"mc":[{"id":"1.168133553","rc":[{"batl":[[2,19.5,13]],"ltp":13.5,"tv":187.9,"id":27227336},{"batb":[[2,5.2,7.59]],"ltp":5.8,"tv":1006.31,"id":21641292}]}]}
{"op":"mcm","clk":"994047355","pt":1580548838335,"mc":[{"id":"1.168133553","rc":[{"batb":[[0,5.5,3.03],[1,5.4,28.44],[2,5.3,2]],"batl":[[0,6.8,7.66],[1,7,19.43],[2,7.6,20.52]],"ltp":5.8,"tv":1006.31,"id":21641292}]}]}
{"op":"mcm","clk":"994047568","pt":1580548840422,"mc":[{"id":"1.168133553","rc":[{"batl":[[0,6.6,2.79],[1,6.8,7.28],[2,7,19.43]],"ltp":5.8,"tv":1006.31,"id":21641292}]}]}
{"op":"mcm","clk":"994047630","pt":1580548840999,"mc":[{"id":"1.168133553","rc":[{"batl":[[0,6.4,2.39],[1,6.6,2.41],[2,6.8,7.28]],"ltp":5.8,"tv":1006.31,"id":21641292}]}]}
{"op":"mcm","clk":"994047916","pt":1580548843497,"mc":[{"id":"1.168133553","rc":[{"trd":[[1.31,867.97]],"batb":[[0,1.31,136.5]],"ltp":1.31,"tv":7956.98,"id":16325787}],"tv":9151.2}]}
{"op":"mcm","clk":"994049615","pt":1580548859629,"mc":[{"id":"1.168133553","rc":[{"trd":[[1.31,871.33]],"batb":[[0,1.31,134.82]],"ltp":1.31,"tv":7960.34,"id":16325787}],"tv":9154.56}]}
{"op":"mcm","clk":"994050464","pt":1580548867548,"mc":[{"id":"1.168133553","rc":[{"batl":[[2,20,9.58]],"ltp":13.5,"tv":187.9,"id":27227336}]}]}
{"op":"mcm","clk":"994051223","pt":1580548875568,"mc":[{"id":"1.168133553","rc":[{"batl":[[1,1.33,100],[2,1.34,1533.3]],"ltp":1.31,"tv":7960.34,"id":16325787}]}]}
{"op":"mcm","clk":"994051311","pt":1580548876502,"mc":[{"id":"1.168133553","rc":[{"batl":[[0,6.4,5.42],[2,6.8,2]],"ltp":5.8,"tv":1006.31,"id":21641292}]}]}
{"op":"mcm","clk":"994051582","pt":1580548878489,"mc":[{"id":"1.168133553","rc":[{"batl":[[0,13.5,1.93],[1,14,3],[2,14.5,8.96]],"ltp":13.5,"tv":187.9,"id":27227336}]}]}
{"op":"mcm","clk":"994051801","pt":1580548880573,"mc":[{"id":"1.168133553","rc":[{"batl":[[0,14,3],[1,14.5,8.96],[2,20,9.58]],"ltp":13.5,"tv":187.9,"id":27227336}]}]}
{"op":"mcm","clk":"994053391","pt":1580548895307,"mc":[{"id":"1.168133553","rc":[{"trd":[[1.32,3078.76]],"batl":[[0,1.32,28.78]],"ltp":1.32,"tv":7970.86,"id":16325787}],"tv":9165.08}]}
{"op":"mcm","clk":"994054684","pt":1580548908510,"mc":[{"id":"1.168133553","rc":[{"batl":[[0,6.4,2.39]],"ltp":5.8,"tv":1006.31,"id":21641292}]}]}
{"op":"mcm","clk":"994054832","pt":1580548909556,"mc":[{"id":"1.168133553","rc":[{"batl":[[2,6.8,7.41]],"ltp":5.8,"tv":1006.31,"id":21641292}]}]}
{"op":"mcm","clk":"994055365","pt":1580548915439,"mc":[{"id":"1.168133553","rc":[{"trd":[[14,3.2]],"batl":[[0,14,1.4]],"ltp":14.0,"tv":191.1,"id":27227336},{"trd":[[5.5,116.35]],"batb":[[0,5.4,28.44],[1,5.3,2],[2,5.1,12.31]],"ltp":5.5,"tv":1020.5,"id":21641292},{"trd":[[1.32,3112.66]],"batl":[[0,1.32,11.83]],"ltp":1.32,"tv":8004.76,"id":16325787}],"tv":9216.37}]}
{"op":"mcm","clk":"994055416","pt":1580548915958,"mc":[{"id":"1.168133553","rc":[{"batl":[[0,14,1.76]],"ltp":14.0,"tv":191.1,"id":27227336}]}]}
{"op":"mcm","clk":"994055555","pt":1580548917320,"mc":[{"id":"1.168133553","rc":[{"batb":[[2,5.2,9.02]],"ltp":5.5,"tv":1020.5,"id":21641292}]}]}
{"op":"mcm","clk":"994058150","pt":1580548942457,"mc":[{"id":"1.168133553","rc":[{"batl":[[0,6.4,5.44],[2,6.8,2]],"ltp":5.5,"tv":1020.5,"id":21641292}]}]}
{"op":"mcm","clk":"994058527","pt":1580548946472,"mc":[{"id":"1.168133553","rc":[{"batb":[[2,5.2,18.03]],"ltp":5.5,"tv":1020.5,"id":21641292}]}]}
{"op":"mcm","clk":"994071714","pt":1580548976518,"mc":[{"id":"1.168133553","rc":[{"batl":[[0,6.4,2.39],[2,6.8,7.41]],"ltp":5.5,"tv":1020.5,"id":21641292}]}]}
{"op":"mcm","clk":"994074958","pt":1580549009171,"mc":[{"id":"1.168133553","rc":[{"batl":[[0,6.4,5.44],[2,6.8,2]],"ltp":5.5,"tv":1020.5,"id":21641292}]}]}
{"op":"mcm","clk":"994077568","pt":1580549033459,"mc":[{"id":"1.168133553","rc":[{"trd":[[11.5,0.54]],"batb":[[0,11.5,1.11]],"ltp":11.5,"tv":191.64,"id":27227336},{"trd":[[5.4,1.66]],"batb":[[0,5.4,27.87]],"ltp":5.4,"tv":1021.64,"id":21641292}],"tv":9218.05}]}
{"op":"mcm","clk":"994077646","pt":1580549034242,"mc":[{"id":"1.168133553","rc":[{"batb":[[0,11,2.89],[1,10.5,3.62],[2,10,24.4]],"ltp":11.5,"tv":191.64,"id":27227336}]}]}
{"op":"mcm","clk":"994077957","pt":1580549037365,"mc":[{"id":"1.168133553","rc":[{"batb":[[0,5.4,28.44]],"ltp":5.4,"tv":1021.64,"id":21641292}]}]}
{"op":"mcm","clk":"994078156","pt":1580549039342,"mc":[{"id":"1.168133553","rc":[{"trd":[[1.32,3122.9]],"batl":[[0,1.32,6.71]],"ltp":1.32,"tv":8015.0,"id":16325787}],"tv":9228.29}]}
{"op":"mcm","clk":"994078637","pt":1580549043553,"mc":[{"id":"1.168133553","rc":[{"batl":[[0,6.4,2.39],[2,6.8,7.41]],"ltp":5.4,"tv":1021.64,"id":21641292}]}]}
{"op":"mcm","clk":"994079970","pt":1580549057391,"mc":[{"id":"1.168133553","rc":[{"trd":[[1.31,891.33]],"batb":[[0,1.31,124.82]],"ltp":1.31,"tv":8035.0,"id":16325787}],"tv":9248.29}]}
{"op":"mcm","clk":"994081791","pt":1580549075528,"mc":[{"id":"1.168133553","rc":[{"batl":[[0,6.4,5.44],[2,6.8,2]],"ltp":5.4,"tv":1021.64,"id":21641292}]}]}
{"op":"mcm","clk":"994082833","pt":1580549085552,"mc":[{"id":"1.168133553","rc":[{"trd":[[1.32,3136.32],[1.33,951.04]],"batl":[[0,1.33,91.12],[1,1.34,1533.3],[2,1.35,1567.86]],"ltp":1.33,"tv":8066.18,"id":16325787}],"tv":9279.47}]}
{"op":"mcm","clk":"994085338","pt":1580549109519,"mc":[{"id":"1.168133553","rc":[{"batl":[[0,6.4,2.39],[2,6.8,7.41]],"ltp":5.4,"tv":1021.64,"id":21641292}]}]}
{"op":"mcm","clk":"994085542","pt":1580549111437,"mc":[{"id":"1.168133553","rc":[{"batl":[[0,1.34,1533.3],[1,1.35,1567.86],[2,1.36,151.95]],"ltp":1.33,"tv":8066.18,"id":16325787}]}]}
{"op":"mcm","clk":"994087371","pt":1580549129536,"mc":[{"id":"1.168133553","rc":[{"trd":[[1.33,961.2]],"ltp":1.33,"tv":8076.34,"id":16325787}],"tv":9289.63}]}
{"op":"mcm","clk":"994088247","pt":1580549137279,"mc":[{"id":"1.168133553","rc":[{"batl":[[0,1.33,80.76],[1,1.34,1533.3],[2,1.35,1567.86]],"ltp":1.33,"tv":8076.34,"id":16325787}]}]}
{"op":"mcm","clk":"994088769","pt":1580549142388,"mc":[{"id":"1.168133553","rc":[{"batl":[[0,6.4,5.44],[2,6.8,2]],"ltp":5.4,"tv":1021.64,"id":21641292}]}]}
{"op":"mcm","clk":"994090194","pt":1580549156504,"mc":[{"id":"1.168133553","rc":[{"batl":[[1,6.8,2],[2,7,15.07]],"ltp":5.4,"tv":1021.64,"id":21641292}]}]}
{"op":"mcm","clk":"994090567","pt":1580549160192,"mc":[{"id":"1.168133553","rc":[{"batl":[[2,7,19.3]],"ltp":5.4,"tv":1021.64,"id":21641292}]}]}
{"op":"mcm","clk":"994092163","pt":1580549175508,"mc":[{"id":"1.168133553","rc":[{"batl":[[0,6.4,2.39],[1,6.8,7.41]],"ltp":5.4,"tv":1021.64,"id":21641292}]}]}
{"op":"mcm","clk":"994093763","pt":1580549189967,"mc":[{"id":"1.168133553","rc":[{"batl":[[2,7,15.07]],"ltp":5.4,"tv":1021.64,"id":21641292}]}]}
{"op":"mcm","clk":"994102480","pt":1580549284540,"mc":[{"id":"1.168133553","rc":[{"trd":[[1.31,941.33]],"batb":[[0,1.31,99.82]],"ltp":1.31,"tv":8126.34,"id":16325787}],"tv":9339.63}]}
{"op":"mcm","clk":"994103949","pt":1580549298549,"mc":[{"id":"1.168133553","rc":[{"batb":[[0,1.31,124.82]],"ltp":1.31,"tv":8126.34,"id":16325787}]}]}
{"op":"mcm","clk":"994111450","pt":1580549373421,"mc":[{"id":"1.168133553","rc":[{"batb":[[0,5.5,20],[1,5.4,28.44],[2,5.3,2]],"ltp":5.4,"tv":1021.64,"id":21641292}]}]}
{"op":"mcm","clk":"994111703","pt":1580549375499,"mc":[{"id":"1.168133553","rc":[{"batl":[[1,6.6,2],[2,6.8,7.41]],"ltp":5.4,"tv":1021.64,"id":21641292}]}]}
{"op":"mcm","clk":"994111982","pt":1580549378525,"mc":[{"id":"1.168133553","rc":[{"batl":[[0,1.33,280.76]],"ltp":1.31,"tv":8126.34,"id":16325787}]}]}
{"op":"mcm","clk":"994114287","pt":1580549401559,"mc":[{"id":"1.168133553","rc":[{"batb":[[0,5.6,3],[1,5.5,20],[2,5.4,28.44]],"ltp":5.4,"tv":1021.64,"id":21641292}]}]}
{"op":"mcm","clk":"994115051","pt":1580549408365,"mc":[{"id":"1.168133553","rc":[{"batb":[[0,5.6,3.94],[2,5.4,27.5]],"ltp":5.4,"tv":1021.64,"id":21641292}]}]}
{"op":"mcm","clk":"994116543","pt":1580549422499,"mc":[{"id":"1.168133553","rc":[{"trd":[[1.31,945.33]],"batb":[[0,1.31,122.82]],"ltp":1.31,"tv":8130.34,"id":16325787}],"tv":9343.63}]}
{"op":"mcm","clk":"994116774","pt":1580549424583,"mc":[{"id":"1.168133553","rc":[{"trd":[[1.33,965.11]],"batl":[[0,1.33,278.8]],"ltp":1.33,"tv":8134.26,"id":16325787}],"tv":9347.55}]}
{"op":"mcm","clk":"994117373","pt":1580549430481,"mc":[{"id":"1.168133553","rc":[{"batb":[[0,5.5,20.94],[1,5.4,27.5],[2,5.3,2]],"ltp":5.4,"tv":1021.64,"id":21641292},{"trd":[[1.33,974.81]],"batl":[[0,1.33,273.95]],"ltp":1.33,"tv":8143.96,"id":16325787}],"tv":9357.25}]}
{"op":"mcm","clk":"994118123","pt":1580549437737,"mc":[{"id":"1.168133553","rc":[{"batb":[[0,5.5,20]],"ltp":5.4,"tv":1021.64,"id":21641292}]}]}
{"op":"mcm","clk":"994121295","pt":1580549468464,"mc":[{"id":"1.168133553","rc":[{"batb":[[0,5.5,22]],"ltp":5.4,"tv":1021.64,"id":21641292}]}]}
{"op":"mcm","clk":"994122244","pt":1580549477882,"mc":[{"id":"1.168133553","rc":[{"batb":[[0,5.6,3],[1,5.5,22],[2,5.4,27.5]],"ltp":5.4,"tv":1021.64,"id":21641292}]}]}
{"op":"mcm","clk":"994124502","pt":1580549498317,"mc":[{"id":"1.168133553","rc":[{"batl":[[1,6.8,7.41],[2,7,15.07]],"ltp":5.4,"tv":1021.64,"id":21641292}]}]}
{"op":"mcm","clk":"994125916","pt":1580549509437,"mc":[{"id":"1.168133553","rc":[{"batb":[[2,1.29,483.55]],"ltp":1.33,"tv":8143.96,"id":16325787}]}]}
{"op":"mcm","clk":"994126514","pt":1580549513457,"mc":[{"id":"1.168133553","rc":[{"batb":[[0,1.31,233.82]],"ltp":1.33,"tv":8143.96,"id":16325787}]}]}
{"op":"mcm","clk":"994129211","pt":1580549538574,"mc":[{"id":"1.168133553","rc":[{"batl":[[0,6.6,2.39]],"ltp":5.4,"tv":1021.64,"id":21641292}]}]}
{"op":"mcm","clk":"994134996","pt":1580549593194,"mc":[{"id":"1.168133553","rc":[{"trd":[[14,6.72],[14.5,15.44]],"batl":[[0,14.5,1.24],[1,20,9.58],[2,25,10.08]],"ltp":14.5,"tv":210.6,"id":27227336},{"trd":[[5.5,210.35],[5.6,80.29]],"batb":[[0,5.4,27.5],[1,5.3,2],[2,5.2,9.02]],"ltp":5.5,"tv":1121.64,"id":21641292},{"trd":[[1.33,1181.59]],"batl":[[0,1.33,170.56]],"ltp":1.33,"tv":8350.74,"id":16325787}],"tv":9682.99}]}
{"op":"mcm","clk":"994135113","pt":1580549594402,"mc":[{"id":"1.168133553","rc":[{"batb":[[0,1.32,81.36],[1,1.31,233.82],[2,1.3,171.12]],"ltp":1.33,"tv":8350.74,"id":16325787}]}]}
{"op":"mcm","clk":"994135152","pt":1580549594815,"mc":[{"id":"1.168133553","rc":[{"batl":[[1,19.5,3.48],[2,20,9.58]],"ltp":14.5,"tv":210.6,"id":27227336},{"batb":[[2,5.2,18.6]],"batl":[[1,6.8,10.79]],"ltp":5.5,"tv":1121.64,"id":21641292}]}]}
{"op":"mcm","clk":"994135307","pt":1580549596490,"mc":[{"id":"1.168133553","rc":[{"batl":[[1,20,9.58],[2,25,10.08]],"ltp":14.5,"tv":210.6,"id":27227336},{"batl":[[1,6.8,7.41]],"ltp":5.5,"tv":1121.64,"id":21641292}]}]}
{"op":"mcm","clk":"994135484","pt":1580549598216,"mc":[{"id":"1.168133553","rc":[{"batl":[[0,18,7.11]],"ltp":14.5,"tv":210.6,"id":27227336}]}]}
{"op":"mcm","clk":"994135905","pt":1580549602530,"mc":[{"id":"1.168133553","rc":[{"batb":[[0,11.5,5.11],[1,11,2.89],[2,10.5,3.62]],"batl":[[0,18,8.02]],"ltp":14.5,"tv":210.6,"id":27227336},{"batl":[[0,6.4,2.87],[1,6.6,2],[2,6.8,7.41]],"ltp":5.5,"tv":1121.64,"id":21641292}]}]}
{"op":"mcm","clk":"994136359","pt":1580549606339,"mc":[{"id":"1.168133553","rc":[{"batb":[[0,5.4,29.5]],"batl":[[0,6,3.03],[1,6.4,2.64],[2,6.6,2]],"ltp":5.5,"tv":1121.64,"id":21641292}]}]}
{"op":"mcm","clk":"994136700","pt":1580549609796,"mc":[{"id":"1.168133553","rc":[{"batb":[[0,1.32,106.36],[1,1.31,208.82]],"ltp":1.33,"tv":8350.74,"id":16325787}]}]}
{"op":"mcm","clk":"994137111","pt":1580549614287,"mc":[{"id":"1.168133553","rc":[{"batl":[[2,29,9.08]],"ltp":14.5,"tv":210.6,"id":27227336}]}]}
{"op":"mcm","clk":"994137894","pt":1580549623168,"mc":[{"id":"1.168133553","rc":[{"batl":[[0,17.5,1.2],[1,18,7.11],[2,20,9.58]],"ltp":14.5,"tv":210.6,"id":27227336}]}]}
{"op":"mcm","clk":"994139006","pt":1580549635573,"mc":[{"id":"1.168133553","rc":[{"batl":[[0,6.2,3.1],[1,6.4,2.48]],"ltp":5.5,"tv":1121.64,"id":21641292}]}]}
{"op":"mcm","clk":"994139473","pt":1580549640186,"mc":[{"id":"1.168133553","rc":[{"batb":[[0,12,5.78],[1,11.5,5.11],[2,11,2.89]],"ltp":14.5,"tv":210.6,"id":27227336}]}]}
{"op":"mcm","clk":"994139709","pt":1580549642566,"mc":[{"id":"1.168133553","rc":[{"batb":[[1,11.5,1.39]],"ltp":14.5,"tv":210.6,"id":27227336}]}]}
{"op":"mcm","clk":"994140302","pt":1580549649091,"mc":[{"id":"1.168133553","rc":[{"batb":[[0,12.5,1.27],[1,12,5.78]],"ltp":14.5,"tv":210.6,"id":27227336}]}]}
{"op":"mcm","clk":"994141707","pt":1580549664037,"mc":[{"id":"1.168133553","rc":[{"batb":[[2,1.3,302.44]],"ltp":1.33,"tv":8350.74,"id":16325787}]}]}
{"op":"mcm","clk":"994144511","pt":1580549692492,"mc":[{"id":"1.168133553","rc":[{"batl":[[0,17.5,1.39]],"ltp":14.5,"tv":210.6,"id":27227336}]}]}
{"op":"mcm","clk":"994154913","pt":1580549796436,"mc":[{"id":"1.168133553","rc":[{"batb":[[0,12.5,2.65]],"ltp":14.5,"tv":210.6,"id":27227336}]}]}
{"op":"mcm","clk":"994155026","pt":1580549797526,"mc":[{"id":"1.168133553","rc":[{"trd":[[5.4,5.66]],"batb":[[0,5.4,27.5]],"ltp":5.4,"tv":1125.64,"id":21641292}],"tv":9686.99}]}
{"op":"mcm","clk":"994155132","pt":1580549798514,"mc":[{"id":"1.168133553","rc":[{"batb":[[0,5.4,55]],"ltp":5.4,"tv":1125.64,"id":21641292}]}]}
{"op":"mcm","clk":"994155286","pt":1580549799445,"mc":[{"id":"1.168133553","rc":[{"batb":[[0,5.4,29.5]],"ltp":5.4,"tv":1125.64,"id":21641292}]}]}
{"op":"mcm","clk":"994156832","pt":1580549811486,"mc":[{"id":"1.168133553","rc":[{"batl":[[0,6,10.23],[1,6.2,2.87],[2,6.4,2.48]],"ltp":5.4,"tv":1125.64,"id":21641292}]}]}
{"op":"mcm","clk":"994158720","pt":1580549831563,"mc":[{"id":"1.168133553","rc":[{"batl":[[0,5.9,3.08],[1,6,10],[2,6.4,2.64]],"ltp":5.4,"tv":1125.64,"id":21641292}]}]}
{"op":"mcm","clk":"994159499","pt":1580549839551,"mc":[{"id":"1.168133553","rc":[{"batb":[[0,12.5,1.38]],"batl":[[0,18,7.59],[1,20,9.58],[2,25,10.08]],"ltp":14.5,"tv":210.6,"id":27227336}]}]}
{"op":"mcm","clk":"994171193","pt":1580549854179,"mc":[{"id":"1.168133553","rc":[{"batl":[[2,34,1.08]],"ltp":14.5,"tv":210.6,"id":27227336}]}]}
{"op":"mcm","clk":"994173420","pt":1580549877539,"mc":[{"id":"1.168133553","rc":[{"trd":[[1.31,955.87],[1.32,3349.06]],"batb":[[0,1.31,203.55],[1,1.3,302.44],[2,1.29,483.55]],"ltp":1.31,"tv":8574.02,"id":16325787}],"tv":9910.27}]}
{"op":"mcm","clk":"994175784","pt":1580549903455,"mc":[{"id":"1.168133553","rc":[{"batl":[[0,17.5,8.08],[1,18,7.11],[2,20,9.58]],"ltp":14.5,"tv":210.6,"id":27227336}]}]}
{"op":"mcm","clk":"994183984","pt":1580549989412,"mc":[{"id":"1.168133553","rc":[{"trd":[[5.4,9.66]],"batb":[[0,5.4,27.5]],"ltp":5.4,"tv":1129.64,"id":21641292},{"batl":[[0,1.33,322.51]],"ltp":1.31,"tv":8574.02,"id":16325787}],"tv":9914.27}]}
{"op":"mcm","clk":"994185172","pt":1580550001394,"mc":[{"id":"1.168133553","rc":[{"batb":[[0,5.4,29.5]],"ltp":5.4,"tv":1129.64,"id":21641292}]}]}
{"op":"mcm","clk":"994186078","pt":1580550009533,"mc":[{"id":"1.168133553","rc":[{"batl":[[0,1.32,42.66],[1,1.33,322.51],[2,1.34,1533.3]],"ltp":1.31,"tv":8574.02,"id":16325787}]}]}
{"op":"mcm","clk":"994188657","pt":1580550036435,"mc":[{"id":"1.168133553","rc":[{"batl":[[0,5.8,2],[1,5.9,3.08],[2,6,10]],"ltp":5.4,"tv":1129.64,"id":21641292}]}]}
{"op":"mcm","clk":"994188778","pt":1580550037523,"mc":[{"id":"1.168133553","rc":[{"batl":[[0,5.9,3.08],[1,6,10],[2,6.4,2.64]],"ltp":5.4,"tv":1129.64,"id":21641292}]}]}
{"op":"mcm","clk":"994197917","pt":1580550128987,"mc":[{"id":"1.168133553","rc":[{"batl":[[0,18,7.59],[1,20,9.58],[2,25,10.08]],"ltp":14.5,"tv":210.6,"id":27227336}]}]}
{"op":"mcm","clk":"994200661","pt":1580550155310,"mc":[{"id":"1.168133553","rc":[{"batl":[[2,34,1.08]],"ltp":14.5,"tv":210.6,"id":27227336}]}]}
{"op":"mcm","clk":"994200786","pt":1580550156511,"mc":[{"id":"1.168133553","rc":[{"trd":[[5.4,13.66]],"batb":[[0,5.4,27.5]],"ltp":5.4,"tv":1133.64,"id":21641292}],"tv":9918.27}]}
{"op":"mcm","clk":"994201165","pt":1580550160298,"mc":[{"id":"1.168133553","rc":[{"batb":[[0,5.4,29.5]],"ltp":5.4,"tv":1133.64,"id":21641292}]}]}
{"op":"mcm","clk":"994204081","pt":1580550188570,"mc":[{"id":"1.168133553","rc":[{"batb":[[2,5.2,28.54]],"ltp":5.4,"tv":1133.64,"id":21641292}]}]}
{"op":"mcm","clk":"994204448","pt":1580550191850,"mc":[{"id":"1.168133553","rc":[{"batl":[[0,17.5,8.08],[1,18,7.11],[2,20,9.58]],"ltp":14.5,"tv":210.6,"id":27227336}]}]}
{"op":"mcm","clk":"994206164","pt":1580550208514,"mc":[{"id":"1.168133553","rc":[{"batl":[[1,1.33,1775.99]],"ltp":1.31,"tv":8574.02,"id":16325787}]}]}
{"op":"mcm","clk":"994207262","pt":1580550218486,"mc":[{"id":"1.168133553","rc":[{"batb":[[2,5.2,18.6]],"ltp":5.4,"tv":1133.64,"id":21641292}]}]}
{"op":"mcm","clk":"994208956","pt":1580550234140,"mc":[{"id":"1.168133553","rc":[{"trd":[[5.4,17.66]],"batb":[[0,5.4,27.5]],"ltp":5.4,"tv":1137.64,"id":21641292}],"tv":9922.27}]}
{"op":"mcm","clk":"994210640","pt":1580550250447,"mc":[{"id":"1.168133553","rc":[{"batb":[[0,5.4,29.5]],"ltp":5.4,"tv":1137.64,"id":21641292}]}]}
{"op":"mcm","clk":"994217234","pt":1580550313559,"mc":[{"id":"1.168133553","rc":[{"trd":[[5.4,21.66]],"batb":[[0,5.4,27.5]],"ltp":5.4,"tv":1141.64,"id":21641292}],"tv":9926.27}]}
{"op":"mcm","clk":"994217986","pt":1580550320377,"mc":[{"id":"1.168133553","rc":[{"batb":[[0,5.4,29.5]],"ltp":5.4,"tv":1141.64,"id":21641292}]}]}
{"op":"mcm","clk":"994230295","pt":1580550418557,"mc":[{"id":"1.168133553","rc":[{"batl":[[0,18,7.59],[1,20,9.58],[2,25,10.08]],"ltp":14.5,"tv":210.6,"id":27227336}]}]}
{"op":"mcm","clk":"994231270","pt":1580550425365,"mc":[{"id":"1.168133553","rc":[{"batl":[[2,34,1.08]],"ltp":14.5,"tv":210.6,"id":27227336}]}]}
{"op":"mcm","clk":"994238195","pt":1580550478447,"mc":[{"id":"1.168133553","rc":[{"batl":[[0,17.5,8.08],[1,18,7.11],[2,20,9.58]],"ltp":14.5,"tv":210.6,"id":27227336}]}]}
{"op":"mcm","clk":"994238324","pt":1580550479541,"mc":[{"id":"1.168133553","rc":[{"trd":[[5.4,25.66]],"batb":[[0,5.4,27.5]],"ltp":5.4,"tv":1145.64,"id":21641292}],"tv":9930.27}]}
{"op":"mcm","clk":"994239104","pt":1580550486374,"mc":[{"id":"1.168133553","rc":[{"batb":[[0,5.4,29.5]],"ltp":5.4,"tv":1145.64,"id":21641292}]}]}
{"op":"mcm","clk":"994240862","pt":1580550501506,"mc":[{"id":"1.168133553","rc":[{"trd":[[1.31,989.57]],"batb":[[0,1.31,186.7]],"ltp":1.31,"tv":8607.72,"id":16325787}],"tv":9963.97}]}
{"op":"mcm","clk":"994256451","pt":1580550628507,"mc":[{"id":"1.168133553","rc":[{"trd":[[1.31,1021.57]],"batb":[[0,1.31,170.7]],"ltp":1.31,"tv":8639.72,"id":16325787}],"tv":9995.97}]}
{"op":"mcm","clk":"994260026","pt":1580550657500,"mc":[{"id":"1.168133553","rc":[{"trd":[[5.4,29.66]],"batb":[[0,5.4,27.5],[2,5.2,9.59]],"ltp":5.4,"tv":1149.64,"id":21641292},{"batl":[[2,1.34,1500]],"ltp":1.31,"tv":8639.72,"id":16325787}],"tv":9999.97}]}
{"op":"mcm","clk":"994260484","pt":1580550661542,"mc":[{"id":"1.168133553","rc":[{"batb":[[0,5.4,29.5]],"ltp":5.4,"tv":1149.64,"id":21641292}]}]}
{"op":"mcm","clk":"994261469","pt":1580550669315,"mc":[{"id":"1.168133553","rc":[{"batb":[[2,11,5.05]],"ltp":14.5,"tv":210.6,"id":27227336}]}]}
{"op":"mcm","clk":"994265643","pt":1580550704527,"mc":[{"id":"1.168133553","rc":[{"batl":[[0,18,7.59],[1,20,9.58],[2,25,10.08]],"ltp":14.5,"tv":210.6,"id":27227336}]}]}
{"op":"mcm","clk":"994266668","pt":1580550714326,"mc":[{"id":"1.168133553","rc":[{"trd":[[5.4,35.66]],"batb":[[0,5.4,26.5]],"ltp":5.4,"tv":1155.64,"id":21641292}],"tv":10005.97}]}
{"op":"mcm","clk":"994267432","pt":1580550721432,"mc":[{"id":"1.168133553","rc":[{"batb":[[0,5.4,27.5]],"ltp":5.4,"tv":1155.64,"id":21641292}]}]}
{"op":"mcm","clk":"994267939","pt":1580550725542,"mc":[{"id":"1.168133553","rc":[{"batb":[[0,5.4,29.5]],"ltp":5.4,"tv":1155.64,"id":21641292}]}]}
{"op":"mcm","clk":"994268045","pt":1580550726532,"mc":[{"id":"1.168133553","rc":[{"batl":[[2,34,1.08]],"ltp":14.5,"tv":210.6,"id":27227336}]}]}
{"op":"mcm","clk":"994282967","pt":1580550767500,"mc":[{"id":"1.168133553","rc":[{"batl":[[0,17.5,8.08],[1,18,7.11],[2,20,9.58]],"ltp":14.5,"tv":210.6,"id":27227336}]}]}
{"op":"mcm","clk":"994290803","pt":1580550837475,"mc":[{"id":"1.168133553","rc":[{"trd":[[1.31,1031.57]],"batb":[[0,1.31,165.7]],"ltp":1.31,"tv":8649.72,"id":16325787}],"tv":10015.97}]}
{"op":"mcm","clk":"994290924","pt":1580550838571,"mc":[{"id":"1.168133553","rc":[{"trd":[[5.4,39.66]],"batb":[[0,5.4,27.5]],"ltp":5.4,"tv":1159.64,"id":21641292}],"tv":10019.97}]}
{"op":"mcm","clk":"994291240","pt":1580550841344,"mc":[{"id":"1.168133553","rc":[{"batb":[[0,5.4,29.5]],"ltp":5.4,"tv":1159.64,"id":21641292}]}]}
{"op":"mcm","clk":"994297240","pt":1580550891540,"mc":[{"id":"1.168133553","rc":[{"trd":[[1.32,3367.54]],"batl":[[0,1.32,33.42]],"ltp":1.32,"tv":8668.2,"id":16325787}],"tv":10038.45}]}
{"op":"mcm","clk":"994297349","pt":1580550892419,"mc":[{"id":"1.168133553","rc":[{"trd":[[1.31,1064.59]],"batb":[[0,1.31,149.19]],"ltp":1.31,"tv":8701.22,"id":16325787}],"tv":10071.47}]}
{"op":"mcm","clk":"994297452","pt":1580550893452,"mc":[{"id":"1.168133553","rc":[{"trd":[[1.31,1074.59]],"batb":[[0,1.31,144.19]],"ltp":1.31,"tv":8711.22,"id":16325787}],"tv":10081.47}]}
{"op":"mcm","clk":"994309132","pt":1580550993365,"mc":[{"id":"1.168133553","rc":[{"batl":[[0,18,7.59],[1,20,9.58],[2,25,10.08]],"ltp":14.5,"tv":210.6,"id":27227336}]}]}
{"op":"mcm","clk":"994309461","pt":1580550996544,"mc":[{"id":"1.168133553","rc":[{"batl":[[2,34,1.08]],"ltp":14.5,"tv":210.6,"id":27227336}]}]}
{"op":"mcm","clk":"994315135","pt":1580551046454,"mc":[{"id":"1.168133553","rc":[{"batb":[[1,1.3,171.12]],"ltp":1.31,"tv":8711.22,"id":16325787}]}]}
{"op":"mcm","clk":"994316344","pt":1580551056564,"mc":[{"id":"1.168133553","rc":[{"batl":[[0,17.5,8.08],[1,18,7.11],[2,20,9.58]],"ltp":14.5,"tv":210.6,"id":27227336}]}]}
{"op":"mcm","clk":"994320219","pt":1580551087514,"mc":[{"id":"1.168133553","rc":[{"trd":[[1.32,3377.77]],"batl":[[0,1.32,28.31]],"ltp":1.32,"tv":8721.45,"id":16325787}],"tv":10091.7}]}
{"op":"mcm","clk":"994320912","pt":1580551093235,"mc":[{"id":"1.168133553","rc":[{"trd":[[1.32,3383.65]],"batl":[[0,1.32,25.37]],"ltp":1.32,"tv":8727.33,"id":16325787}],"tv":10097.58}]}
{"op":"mcm","clk":"994321040","pt":1580551094436,"mc":[{"id":"1.168133553","rc":[{"trd":[[1.32,3434.42]],"batb":[[0,1.32,5.92],[1,1.31,144.19],[2,1.3,171.12]],"batl":[[0,1.33,1775.99],[1,1.34,1500],[2,1.35,1525.21]],"ltp":1.32,"tv":8778.1,"id":16325787}],"tv":10148.35}]}
{"op":"mcm","clk":"994321509","pt":1580551098539,"mc":[{"id":"1.168133553","rc":[{"batl":[[2,6.6,2.16]],"ltp":5.4,"tv":1159.64,"id":21641292}]}]}
{"op":"mcm","clk":"994325217","pt":1580551129552,"mc":[{"id":"1.168133553","rc":[{"batl":[[2,6.8,7.57]],"ltp":5.4,"tv":1159.64,"id":21641292}]}]}
{"op":"mcm","clk":"994329942","pt":1580551173386,"mc":[{"id":"1.168133553","rc":[{"trd":[[5.4,43.66]],"batb":[[0,5.4,27.5]],"ltp":5.4,"tv":1163.64,"id":21641292},{"batb":[[2,1.3,271.12]],"ltp":1.32,"tv":8778.1,"id":16325787}],"tv":10152.35}]}
{"op":"mcm","clk":"994330405","pt":1580551177504,"mc":[{"id":"1.168133553","rc":[{"batb":[[0,5.4,29.5]],"ltp":5.4,"tv":1163.64,"id":21641292}]}]}
{"op":"mcm","clk":"994334542","pt":1580551209538,"mc":[{"id":"1.168133553","rc":[{"trd":[[1.33,1187.59]],"batl":[[0,1.33,1772.99]],"ltp":1.33,"tv":8784.1,"id":16325787}],"tv":10158.35}]}
{"op":"mcm","clk":"994343338","pt":1580551279499,"mc":[{"id":"1.168133553","rc":[{"batb":[[1,1.31,244.19],[2,1.3,171.12]],"ltp":1.33,"tv":8784.1,"id":16325787}]}]}
{"op":"mcm","clk":"994343699","pt":1580551282370,"mc":[{"id":"1.168133553","rc":[{"batl":[[0,18,7.59],[1,20,9.58],[2,23,10.08]],"ltp":14.5,"tv":210.6,"id":27227336}]}]}
{"op":"mcm","clk":"994351190","pt":1580551345908,"mc":[{"id":"1.168133553","rc":[{"batl":[[0,17.5,8.08],[1,18,7.11],[2,20,9.58]],"ltp":14.5,"tv":210.6,"id":27227336}]}]}
{"op":"mcm","clk":"994353889","pt":1580551370561,"mc":[{"id":"1.168133553","rc":[{"trd":[[1.32,3446.26]],"batb":[[0,1.31,244.19],[1,1.3,171.12],[2,1.29,483.55]],"batl":[[0,1.32,24.08],[1,1.33,1772.99],[2,1.34,1500]],"ltp":1.32,"tv":8795.94,"id":16325787}],"tv":10170.19}]}
{"op":"mcm","clk":"994354735","pt":1580551378286,"mc":[{"id":"1.168133553","rc":[{"trd":[[5.4,47.66]],"batb":[[0,5.4,27.5]],"ltp":5.4,"tv":1167.64,"id":21641292}],"tv":10174.19}]}
{"op":"mcm","clk":"994355439","pt":1580551383561,"mc":[{"id":"1.168133553","rc":[{"batb":[[0,5.4,29.5]],"ltp":5.4,"tv":1167.64,"id":21641292}]}]}
{"op":"mcm","clk":"994358169","pt":1580551401477,"mc":[{"id":"1.168133553","rc":[{"batl":[[0,1.32,29.08]],"ltp":1.32,"tv":8795.94,"id":16325787}]}]}
{"op":"mcm","clk":"994358218","pt":1580551401904,"mc":[{"id":"1.168133553","rc":[{"batb":[[2,1.29,488.55]],"ltp":1.32,"tv":8795.94,"id":16325787}]}]}
{"op":"mcm","clk":"994361103","pt":1580551423553,"mc":[{"id":"1.168133553","rc":[{"batl":[[1,20,9.58],[2,23,10.08]],"ltp":14.5,"tv":210.6,"id":27227336},{"batb":[[0,5.4,2]],"ltp":5.4,"tv":1167.64,"id":21641292}]}]}
{"op":"mcm","clk":"994362532","pt":1580551433410,"mc":[{"id":"1.168133553","rc":[{"batl":[[0,15,8.64],[1,17.5,8.08],[2,20,9.58]],"ltp":14.5,"tv":210.6,"id":27227336},{"batb":[[2,5.1,32.98]],"ltp":5.4,"tv":1167.64,"id":21641292}]}]}
{"op":"mcm","clk":"994362929","pt":1580551435509,"mc":[{"id":"1.168133553","rc":[{"batl":[[1,17.5,7.89]],"ltp":14.5,"tv":210.6,"id":27227336}]}]}
{"op":"mcm","clk":"994364195","pt":1580551444513,"mc":[{"id":"1.168133553","rc":[{"batl":[[0,15,8.98],[1,17.5,7.6]],"ltp":14.5,"tv":210.6,"id":27227336}]}]}
{"op":"mcm","clk":"994364334","pt":1580551445521,"mc":[{"id":"1.168133553","rc":[{"batl":[[0,5.8,3.27],[1,5.9,3.08],[2,6,10]],"ltp":5.4,"tv":1167.64,"id":21641292}]}]}
{"op":"mcm","clk":"994377779","pt":1580551533338,"mc":[{"id":"1.168133553","rc":[{"trd":[[1.31,1114.59]],"batb":[[0,1.31,224.19]],"ltp":1.31,"tv":8835.94,"id":16325787}],"tv":10214.19}]}
{"op":"mcm","clk":"994379637","pt":1580551545379,"mc":[{"id":"1.168133553","rc":[{"trd":[[14.5,16.12],[15,17.28]],"batb":[[0,15,1.45],[1,12.5,1.39],[2,12,5.78]],"batl":[[0,17.5,7.6],[1,20,9.58],[2,23,10.08]],"ltp":15.0,"tv":228.56,"id":27227336},{"trd":[[5.4,133.97]],"batb":[[0,5.3,2],[1,5.1,32.98],[2,4.9,1.98]],"batl":[[0,5.4,124.89],[1,5.8,3.27],[2,5.9,3.08]],"ltp":5.4,"tv":1253.95,"id":21641292},{"trd":[[1.32,3504.42],[1.33,1332.17]],"batb":[[0,1.32,16.48],[1,1.31,224.19],[2,1.3,171.12]],"batl":[[0,1.33,1700.7],[1,1.34,1500],[2,1.35,1525.21]],"ltp":1.33,"tv":9038.69,"id":16325787}],"tv":10521.21}]}
{"op":"mcm","clk":"994379802","pt":1580551546541,"mc":[{"id":"1.168133553","rc":[{"trd":[[5.4,314.23]],"batl":[[0,5.4,34.76]],"ltp":5.4,"tv":1434.21,"id":21641292}],"tv":10701.46}]}
{"op":"mcm","clk":"994379955","pt":1580551547509,"mc":[{"id":"1.168133553","rc":[{"batl":[[1,5.8,29.59]],"ltp":5.4,"tv":1434.21,"id":21641292}]}]}
{"op":"mcm","clk":"994380057","pt":1580551548253,"mc":[{"id":"1.168133553","rc":[{"batl":[[1,5.8,16.44]],"ltp":5.4,"tv":1434.21,"id":21641292}]}]}
{"op":"mcm","clk":"994380852","pt":1580551553535,"mc":[{"id":"1.168133553","rc":[{"batb":[[1,5.2,2],[2,5.1,3.46]],"ltp":5.4,"tv":1434.21,"id":21641292}]}]}
{"op":"mcm","clk":"994383622","pt":1580551571471,"mc":[{"id":"1.168133553","rc":[{"batl":[[0,20,9.58],[1,23,10.08],[2,34,1]],"ltp":15.0,"tv":228.56,"id":27227336}]}]}
{"op":"mcm","clk":"994383901","pt":1580551573395,"mc":[{"id":"1.168133553","rc":[{"batb":[[2,5.1,32.98]],"ltp":5.4,"tv":1434.21,"id":21641292}]}]}
{"op":"mcm","clk":"994384235","pt":1580551575478,"mc":[{"id":"1.168133553","rc":[{"batl":[[0,20,9.77]],"ltp":15.0,"tv":228.56,"id":27227336}]}]}
{"op":"mcm","clk":"994385471","pt":1580551583510,"mc":[{"id":"1.168133553","rc":[{"batl":[[0,18.5,6.91],[1,20,9.77],[2,23,10.08]],"ltp":15.0,"tv":228.56,"id":27227336}]}]}
{"op":"mcm","clk":"994385969","pt":1580551586516,"mc":[{"id":"1.168133553","rc":[{"batl":[[1,20,9.58]],"ltp":15.0,"tv":228.56,"id":27227336}]}]}
{"op":"mcm","clk":"994387519","pt":1580551593421,"mc":[{"id":"1.168133553","rc":[{"batl":[[0,20,9.58],[1,23,10.08],[2,34,1]],"ltp":15.0,"tv":228.56,"id":27227336},{"batb":[[2,5.1,3.46]],"ltp":5.4,"tv":1434.21,"id":21641292},{"batb":[[2,1.3,574.58]],"ltp":1.33,"tv":9038.69,"id":16325787}]}]}
{"op":"mcm","clk":"994388519","pt":1580551598917,"mc":[{"id":"1.168133553","rc":[{"batl":[[0,20,9.76]],"ltp":15.0,"tv":228.56,"id":27227336}]}]}
{"op":"mcm","clk":"994388930","pt":1580551601533,"mc":[{"id":"1.168133553","rc":[{"trd":[[1.33,1371.87]],"batl":[[0,1.33,1680.85]],"ltp":1.33,"tv":9078.39,"id":16325787}],"tv":10741.16}]}
{"op":"mcm","clk":"994389232","pt":1580551603509,"mc":[{"id":"1.168133553","rc":[{"batl":[[0,15.5,8.34],[1,20,9.76],[2,23,10.08]],"ltp":15.0,"tv":228.56,"id":27227336}]}]}
{"op":"mcm","clk":"994389439","pt":1580551604519,"mc":[{"id":"1.168133553","rc":[{"trd":[[15.5,16.68]],"batl":[[0,20,9.76],[1,23,10.08],[2,34,1]],"ltp":15.5,"tv":245.24,"id":27227336},{"trd":[[5.4,362.11]],"batl":[[0,5.4,10.82]],"ltp":5.4,"tv":1482.09,"id":21641292},{"trd":[[1.33,1566.25]],"batl":[[0,1.33,1583.67]],"ltp":1.33,"tv":9272.77,"id":16325787}],"tv":11000.1}]}
{"op":"mcm","clk":"994389599","pt":1580551605527,"mc":[{"id":"1.168133553","rc":[{"batl":[[1,5.8,3.27]],"ltp":5.4,"tv":1482.09,"id":21641292}]}]}
{"op":"mcm","clk":"994389927","pt":1580551607556,"mc":[{"id":"1.168133553","rc":[{"trd":[[5.3,4.05]],"batb":[[0,5.2,2],[1,5.1,3.46],[2,4.9,1.98]],"ltp":5.3,"tv":1486.09,"id":21641292}],"tv":11004.1}]}
{"op":"mcm","clk":"994390916","pt":1580551613517,"mc":[{"id":"1.168133553","rc":[{"batl":[[0,19,6.72],[1,20,9.76],[2,23,10.08]],"ltp":15.5,"tv":245.24,"id":27227336}]}]}
{"op":"mcm","clk":"994391470","pt":1580551617566,"mc":[{"id":"1.168133553","rc":[{"batb":[[1,13,3.3],[2,12.5,1.38]],"ltp":15.5,"tv":245.24,"id":27227336}]}]}
{"op":"mcm","clk":"994391769","pt":1580551619451,"mc":[{"id":"1.168133553","rc":[{"batl":[[0,5.3,5],[1,5.4,10.82],[2,5.8,3.27]],"ltp":5.3,"tv":1486.09,"id":21641292}]}]}
{"op":"mcm","clk":"994392345","pt":1580551623560,"mc":[{"id":"1.168133553","rc":[{"batl":[[0,20,9.76],[1,23,10.08],[2,34,1]],"ltp":15.5,"tv":245.24,"id":27227336},{"batb":[[2,1.3,171.12]],"ltp":1.33,"tv":9272.77,"id":16325787}]}]}
{"op":"mcm","clk":"994410323","pt":1580551670494,"mc":[{"id":"1.168133553","rc":[{"batb":[[0,1.32,116.48],[1,1.31,124.19]],"ltp":1.33,"tv":9272.77,"id":16325787}]}]}
{"op":"mcm","clk":"994413988","pt":1580551694436,"mc":[{"id":"1.168133553","rc":[{"batl":[[2,5.5,2]],"ltp":5.3,"tv":1486.09,"id":21641292}]}]}
{"op":"mcm","clk":"994429327","pt":1580551784450,"mc":[{"id":"1.168133553","rc":[{"batb":[[1,4.9,2.32],[2,4.8,3.04]],"ltp":5.3,"tv":1486.09,"id":21641292}]}]}
{"op":"mcm","clk":"994429780","pt":1580551787492,"mc":[{"id":"1.168133553","rc":[{"trd":[[5.2,4]],"batb":[[0,4.9,2.32],[1,4.8,3.04],[2,4.5,3.56]],"batl":[[0,5.2,1.84],[1,5.3,5],[2,5.4,10.82]],"ltp":5.2,"tv":1490.09,"id":21641292}],"tv":11008.1}]}
{"op":"mcm","clk":"994430567","pt":1580551792208,"mc":[{"id":"1.168133553","rc":[{"batb":[[0,4.9,4.32]],"ltp":5.2,"tv":1490.09,"id":21641292}]}]}
{"op":"mcm","clk":"994434785","pt":1580551817518,"mc":[{"id":"1.168133553","rc":[{"batl":[[0,5.2,4.29]],"ltp":5.2,"tv":1490.09,"id":21641292}]}]}
{"op":"mcm","clk":"994436171","pt":1580551825535,"mc":[{"id":"1.168133553","rc":[{"trd":[[5.1,0.67]],"batb":[[0,4.9,3.98]],"batl":[[0,5.1,1.99],[1,5.2,4.29],[2,5.3,5]],"ltp":5.1,"tv":1490.75,"id":21641292}],"tv":11008.77}]}
{"op":"mcm","clk":"994438546","pt":1580551839496,"mc":[{"id":"1.168133553","rc":[{"batl":[[1,5.2,24.29]],"ltp":5.1,"tv":1490.75,"id":21641292}]}]}
{"op":"mcm","clk":"994448463","pt":1580551897509,"mc":[{"id":"1.168133553","rc":[{"trd":[[4.5,4],[4.8,12.16],[4.9,7.96]],"batb":[[0,4.2,2.49],[1,4.1,4.54],[2,4,87.95]],"batl":[[0,5.2,24.29],[1,5.3,5],[2,5.4,11.14]],"ltp":4.8,"tv":1514.88,"id":21641292}],"tv":11032.89}]}
{"op":"mcm","clk":"994448565","pt":1580551898209,"mc":[{"id":"1.168133553","rc":[{"trd":[[20,4.42]],"batb":[[0,15,1.79]],"batl":[[0,20,7.37]],"ltp":20.0,"tv":249.66,"id":27227336},{"trd":[[4.8,22.24]],"batb":[[0,4.2,3.27],[1,4,25.95],[2,3.8,66]],"batl":[[0,5.1,4.19],[1,5.2,24.29],[2,5.3,5]],"ltp":4.8,"tv":1524.96,"id":21641292},{"trd":[[1.33,1643.36]],"batl":[[0,1.33,1545.14]],"ltp":1.33,"tv":9349.87,"id":16325787}],"tv":11124.5}]}
{"op":"mcm","clk":"994448787","pt":1580551899491,"mc":[{"id":"1.168133553","rc":[{"batb":[[0,15.5,5.63],[1,15,1.45],[2,13,3.3]],"ltp":20.0,"tv":249.66,"id":27227336},{"batb":[[0,4.3,19.85],[1,4.2,2.49],[2,4,29.03]],"ltp":4.8,"tv":1524.96,"id":21641292}]}]}
{"op":"mcm","clk":"994448953","pt":1580551900506,"mc":[{"id":"1.168133553","rc":[{"batb":[[2,13.5,4.92]],"ltp":20.0,"tv":249.66,"id":27227336}]}]}
{"op":"mcm","clk":"994449244","pt":1580551902514,"mc":[{"id":"1.168133553","rc":[{"batb":[[2,13.5,10.19]],"ltp":20.0,"tv":249.66,"id":27227336},{"batb":[[0,4.4,4.39],[1,4.3,19.07],[2,4.2,2.49]],"ltp":4.8,"tv":1524.96,"id":21641292}]}]}
{"op":"mcm","clk":"994449578","pt":1580551904527,"mc":[{"id":"1.168133553","rc":[{"trd":[[15.5,21.86],[19.5,0.68]],"batb":[[0,15.5,2.7]],"ltp":15.5,"tv":255.52,"id":27227336}],"tv":11130.36}]}
{"op":"mcm","clk":"994449754","pt":1580551905489,"mc":[{"id":"1.168133553","rc":[{"trd":[[17,4.72]],"batb":[[0,17,1.26],[1,15.5,2.7],[2,15,1.45]],"ltp":17.0,"tv":260.24,"id":27227336},{"trd":[[5.1,13.05],[5.2,11.04]],"batb":[[0,5.1,2.19],[1,4.4,4.39],[2,4.3,19.07]],"batl":[[0,5.2,20.77],[1,5.3,5],[2,5.4,11.14]],"ltp":5.1,"tv":1544.38,"id":21641292},{"trd":[[1.33,1735.71]],"batl":[[0,1.33,1498.99]],"ltp":1.33,"tv":9442.22,"id":16325787}],"tv":11246.85}]}
{"op":"mcm","clk":"994449906","pt":1580551906412,"mc":[{"id":"1.168133553","rc":[{"trd":[[5.1,17.43]],"batb":[[0,4.4,4.39],[1,4.3,19.07],[2,4.2,2.49]],"batl":[[0,5.1,2],[1,5.2,20.77],[2,5.3,5]],"ltp":5.1,"tv":1548.76,"id":21641292}],"tv":11251.23}]}
{"op":"mcm","clk":"994450098","pt":1580551907503,"mc":[{"id":"1.168133553","rc":[{"trd":[[4.5,8.48]],"batb":[[0,4.5,7.66],[1,4.4,3.61],[2,4.3,19.07]],"batl":[[0,5.2,20.77],[1,5.3,5],[2,5.4,11.14]],"ltp":4.5,"tv":1553.24,"id":21641292}],"tv":11255.71}]}
{"op":"mcm","clk":"994451629","pt":1580551916301,"mc":[{"id":"1.168133553","rc":[{"batb":[[0,4.6,2.74]],"ltp":4.5,"tv":1553.24,"id":21641292}]}]}
{"op":"mcm","clk":"994451998","pt":1580551918402,"mc":[{"id":"1.168133553","rc":[{"batl":[[2,5.4,10.82]],"ltp":4.5,"tv":1553.24,"id":21641292}]}]}
{"op":"mcm","clk":"994452643","pt":1580551921480,"mc":[{"id":"1.168133553","rc":[{"batl":[[0,20,8.19]],"ltp":17.0,"tv":260.24,"id":27227336}]}]}
{"op":"mcm","clk":"994453635","pt":1580551926523,"mc":[{"id":"1.168133553","marketDefinition":{"bspMarket":true,"turnInPlayEnabled":true,"persistenceEnabled":true,"marketBaseRate":5.0,"eventId":"29678760","eventTypeId":"7","numberOfWinners":1,"bettingType":"ODDS","marketType":"WIN","marketTime":"2020-02-01T14:12:00.000Z","suspendTime":"2020-02-01T14:12:00.000Z","bspReconciled":false,"complete":true,"inPlay":false,"crossMatching":true,"runnersVoidable":false,"numberOfActiveRunners":3,"betDelay":0,"status":"OPEN","runners":[{"adjustmentFactor":70.72,"status":"ACTIVE","sortPriority":1,"id":16325787,"name":"Kalooki"},{"adjustmentFactor":13.85,"status":"ACTIVE","sortPriority":2,"id":21641292,"name":"Lemon T"},{"adjustmentFactor":15.41,"status":"ACTIVE","sortPriority":3,"id":27227336,"name":"Islandray"}],"regulators":["MR_INT"],"venue":"Wetherby","countryCode":"GB","discountAllowed":true,"timezone":"Europe/London","openDate":"2020-02-01T13:03:00.000Z","version":3143869040,"name":"2m5f Nov Hrd","eventName":"Weth  1st Feb"}}]}
{"op":"mcm","clk":"994454767","pt":1580551932517,"mc":[{"id":"1.168133553","rc":[{"batb":[[0,18,3.85],[1,17,1.26],[2,15.5,2.7]],"ltp":17.0,"tv":260.24,"id":27227336}]}]}
{"op":"mcm","clk":"994455734","pt":1580551937406,"mc":[{"id":"1.168133553","rc":[{"trd":[[5.2,15.04]],"batl":[[0,5.2,18.77]],"ltp":5.2,"tv":1557.24,"id":21641292}],"tv":11259.71}]}
{"op":"mcm","clk":"994457865","pt":1580551949498,"mc":[{"id":"1.168133553","rc":[{"trd":[[18,7.7]],"batb":[[0,17,1.26],[1,15.5,2.7],[2,15,1.45]],"ltp":18.0,"tv":267.94,"id":27227336},{"trd":[[5.2,28.64]],"batl":[[0,5.2,11.97]],"ltp":5.2,"tv":1570.84,"id":21641292}],"tv":11281.01}]}
{"op":"mcm","clk":"994458088","pt":1580551950573,"mc":[{"id":"1.168133553","rc":[{"batl":[[0,5.2,12.67]],"ltp":5.2,"tv":1570.84,"id":21641292}]}]}
{"op":"mcm","clk":"994458265","pt":1580551951494,"mc":[{"id":"1.168133553","rc":[{"trd":[[19.5,1.5],[20,11.79]],"batl":[[0,23,10.08],[1,34,1],[2,48,9]],"ltp":20.0,"tv":276.12,"id":27227336},{"trd":[[5,32.67]],"batl":[[0,5,52.33],[1,5.2,24.67],[2,5.3,5]],"ltp":5.0,"tv":1603.51,"id":21641292},{"trd":[[1.33,1858.48]],"batl":[[0,1.33,1376.22]],"ltp":1.33,"tv":9564.99,"id":16325787}],"tv":11444.64}]}
{"op":"mcm","clk":"994458451","pt":1580551952498,"mc":[{"id":"1.168133553","rc":[{"batb":[[1,4.5,2],[2,4.4,3.61]],"ltp":5.0,"tv":1603.51,"id":21641292}]}]}
{"op":"mcm","clk":"994461151","pt":1580551967528,"mc":[{"id":"1.168133553","rc":[{"trd":[[20,13.37]],"ltp":20.0,"tv":277.7,"id":27227336},{"trd":[[5,38.99]],"batl":[[0,5,46.01]],"ltp":5.0,"tv":1609.83,"id":21641292},{"trd":[[1.33,1882.24]],"batl":[[0,1.33,1352.46]],"ltp":1.33,"tv":9588.75,"id":16325787}],"tv":11476.3}]}
{"op":"mcm","clk":"994461334","pt":1580551968545,"mc":[{"id":"1.168133553","rc":[{"batl":[[0,23,10.8]],"ltp":20.0,"tv":277.7,"id":27227336}]}]}
{"op":"mcm","clk":"994461539","pt":1580551969548,"mc":[{"id":"1.168133553","rc":[{"batl":[[1,5.2,27.51]],"ltp":5.0,"tv":1609.83,"id":21641292}]}]}
{"op":"mcm","clk":"994463594","pt":1580551980564,"mc":[{"id":"1.168133553","rc":[{"batl":[[1,5.2,26.82]],"ltp":5.0,"tv":1609.83,"id":21641292}]}]}
{"op":"mcm","clk":"994463769","pt":1580551981472,"mc":[{"id":"1.168133553","rc":[{"trd":[[22,0.16]],"batl":[[0,23,10.64]],"ltp":22.0,"tv":277.86,"id":27227336},{"trd":[[4.9,8.69]],"batl":[[0,5,48.01]],"ltp":4.9,"tv":1610.55,"id":21641292},{"trd":[[1.33,1884.9]],"batl":[[0,1.33,1349.8]],"ltp":1.33,"tv":9591.41,"id":16325787}],"tv":11479.84}]}
{"op":"mcm","clk":"994464532","pt":1580551985571,"mc":[{"id":"1.168133553","rc":[{"trd":[[20,16.31]],"ltp":20.0,"tv":280.8,"id":27227336},{"trd":[[5,50.75]],"batl":[[0,5,36.25]],"ltp":5.0,"tv":1622.31,"id":21641292},{"trd":[[1.33,1929.11]],"batl":[[0,1.33,1305.59]],"ltp":1.33,"tv":9635.62,"id":16325787}],"tv":11538.75}]}
{"op":"mcm","clk":"994465419","pt":1580551990483,"mc":[{"id":"1.168133553","rc":[{"trd":[[20,19.24]],"ltp":20.0,"tv":283.73,"id":27227336},{"trd":[[5,62.47]],"batl":[[0,5,24.53]],"ltp":5.0,"tv":1634.03,"id":21641292},{"trd":[[1.33,1973.17]],"batl":[[0,1.33,1261.53]],"ltp":1.33,"tv":9679.68,"id":16325787}],"tv":11597.46}]}
{"op":"mcm","clk":"994476752","pt":1580552055467,"mc":[{"id":"1.168133553","rc":[{"batb":[[0,4.5,2],[1,4.4,3.61],[2,4.3,19.07]],"ltp":5.0,"tv":1634.03,"id":21641292}]}]}
{"op":"mcm","clk":"994483144","pt":1580552091405,"mc":[{"id":"1.168133553","rc":[{"batb":[[2,1.3,216.12]],"ltp":1.33,"tv":9679.68,"id":16325787}]}]}
{"op":"mcm","clk":"994487601","pt":1580552116543,"mc":[{"id":"1.168133553","rc":[{"trd":[[20,22.18]],"ltp":20.0,"tv":286.67,"id":27227336},{"trd":[[5,74.23]],"batl":[[0,5,12.77]],"ltp":5.0,"tv":1645.79,"id":21641292},{"trd":[[1.33,2017.38]],"batl":[[0,1.33,1217.32]],"ltp":1.33,"tv":9723.89,"id":16325787}],"tv":11656.37}]}
{"op":"mcm","clk":"994487780","pt":1580552117539,"mc":[{"id":"1.168133553","rc":[{"batl":[[1,5.1,15.51],[2,5.2,26.82]],"ltp":5.0,"tv":1645.79,"id":21641292}]}]}
{"op":"mcm","clk":"994491623","pt":1580552138475,"mc":[{"id":"1.168133553","rc":[{"batb":[[2,15,18.45]],"ltp":20.0,"tv":286.67,"id":27227336}]}]}
{"op":"mcm","clk":"994491799","pt":1580552139484,"mc":[{"id":"1.168133553","rc":[{"trd":[[5,85.27]],"batl":[[0,5,7.25]],"ltp":5.0,"tv":1656.83,"id":21641292}],"tv":11667.41}]}
{"op":"mcm","clk":"994492988","pt":1580552146556,"mc":[{"id":"1.168133553","rc":[{"trd":[[1.33,2027.7]],"batl":[[0,1.33,1212.16]],"ltp":1.33,"tv":9734.21,"id":16325787}],"tv":11677.73}]}
{"op":"mcm","clk":"994493136","pt":1580552147509,"mc":[{"id":"1.168133553","rc":[{"batl":[[1,5.1,25.89]],"ltp":5.0,"tv":1656.83,"id":21641292}]}]}
{"op":"mcm","clk":"994493404","pt":1580552149210,"mc":[{"id":"1.168133553","rc":[{"batb":[[1,16,2.68],[2,15.5,2.7]],"ltp":20.0,"tv":286.67,"id":27227336}]}]}
{"op":"mcm","clk":"994496655","pt":1580552169410,"mc":[{"id":"1.168133553","rc":[{"trd":[[5,89.27]],"batl":[[0,5,5.25]],"ltp":5.0,"tv":1660.83,"id":21641292}],"tv":11681.73}]}
{"op":"mcm","clk":"994497872","pt":1580552176363,"mc":[{"id":"1.168133553","rc":[{"batl":[[1,5.1,36.28]],"ltp":5.0,"tv":1660.83,"id":21641292}]}]}
{"op":"mcm","clk":"994498775","pt":1580552181565,"mc":[{"id":"1.168133553","rc":[{"trd":[[5,95.27]],"batl":[[0,5,2.25]],"ltp":5.0,"tv":1666.83,"id":21641292}],"tv":11687.73}]}
{"op":"mcm","clk":"994503285","pt":1580552207495,"mc":[{"id":"1.168133553","rc":[{"trd":[[5,99.27]],"batl":[[0,5.1,36.53],[1,5.2,26.82],[2,5.3,5]],"ltp":5.0,"tv":1670.83,"id":21641292}],"tv":11691.73}]}
{"op":"mcm","clk":"994503457","pt":1580552208485,"mc":[{"id":"1.168133553","rc":[{"trd":[[5,99.77]],"batl":[[0,5.1,36.28]],"ltp":5.0,"tv":1671.33,"id":21641292}],"tv":11692.23}]}
{"op":"mcm","clk":"994506557","pt":1580552223045,"mc":[{"id":"1.168133553","rc":[{"batb":[[0,5,5],[1,4.5,2],[2,4.4,3.61]],"ltp":5.0,"tv":1671.33,"id":21641292}]}]}
{"op":"mcm","clk":"994507516","pt":1580552228448,"mc":[{"id":"1.168133553","rc":[{"trd":[[5.1,27.43]],"batb":[[0,4.5,2],[1,4.4,3.61],[2,4.3,19.07]],"batl":[[0,5.1,31.28]],"ltp":5.1,"tv":1681.33,"id":21641292}],"tv":11702.23}]}
{"op":"mcm","clk":"994510365","pt":1580552244563,"mc":[{"id":"1.168133553","rc":[{"batl":[[0,5,2],[1,5.1,31.28],[2,5.2,26.82]],"ltp":5.1,"tv":1681.33,"id":21641292}]}]}
{"op":"mcm","clk":"994510529","pt":1580552245532,"mc":[{"id":"1.168133553","rc":[{"batl":[[0,5.1,31.28],[1,5.2,23.98],[2,5.3,5]],"ltp":5.1,"tv":1681.33,"id":21641292}]}]}
{"op":"mcm","clk":"994522502","pt":1580552306570,"mc":[{"id":"1.168133553","rc":[{"batl":[[1,5.2,19.91]],"ltp":5.1,"tv":1681.33,"id":21641292}]}]}
{"op":"mcm","clk":"994527363","pt":1580552334062,"mc":[{"id":"1.168133553","rc":[{"batb":[[0,4.9,4],[1,4.5,2],[2,4.4,3.61]],"ltp":5.1,"tv":1681.33,"id":21641292}]}]}
{"op":"mcm","clk":"994531755","pt":1580552358093,"mc":[{"id":"1.168133553","rc":[{"batl":[[0,23,10]],"ltp":20.0,"tv":286.67,"id":27227336}]}]}
{"op":"mcm","clk":"994548699","pt":1580552448269,"mc":[{"id":"1.168133553","rc":[{"trd":[[5.1,49.2]],"batl":[[0,5.1,20.4]],"ltp":5.1,"tv":1703.1,"id":21641292}],"tv":11724.0}]}
{"op":"mcm","clk":"994549730","pt":1580552453465,"mc":[{"id":"1.168133553","rc":[{"batl":[[0,5.1,10.38],[1,5.2,11.97]],"ltp":5.1,"tv":1703.1,"id":21641292}]}]}
{"op":"mcm","clk":"994553013","pt":1580552470501,"mc":[{"id":"1.168133553","rc":[{"trd":[[5.1,60.02]],"batl":[[0,5.1,4.97],[1,5.2,19.72]],"ltp":5.1,"tv":1713.92,"id":21641292}],"tv":11734.82}]}
{"op":"mcm","clk":"994554140","pt":1580552476446,"mc":[{"id":"1.168133553","rc":[{"batb":[[1,4.8,7.35],[2,4.7,40.89]],"ltp":5.1,"tv":1713.92,"id":21641292},{"batb":[[1,1.31,612.24]],"ltp":1.33,"tv":9734.21,"id":16325787}]}]}
{"op":"mcm","clk":"994557370","pt":1580552494369,"mc":[{"id":"1.168133553","rc":[{"batb":[[0,4.9,6]],"ltp":5.1,"tv":1713.92,"id":21641292}]}]}
{"op":"mcm","clk":"994557467","pt":1580552494905,"mc":[{"id":"1.168133553","rc":[{"trd":[[4.9,18.29]],"batb":[[0,4.9,1.2]],"ltp":4.9,"tv":1723.52,"id":21641292}],"tv":11744.42}]}
{"op":"mcm","clk":"994558321","pt":1580552499570,"mc":[{"id":"1.168133553","rc":[{"batb":[[2,15,1.45]],"ltp":20.0,"tv":286.67,"id":27227336}]}]}
{"op":"mcm","clk":"994558463","pt":1580552500486,"mc":[{"id":"1.168133553","rc":[{"batl":[[0,5.1,2.24],[1,5.2,11.97]],"ltp":4.9,"tv":1723.52,"id":21641292}]}]}
{"op":"mcm","clk":"994558629","pt":1580552501490,"mc":[{"id":"1.168133553","rc":[{"batb":[[0,18,4.56],[1,17,1.26],[2,16,2.68]],"ltp":20.0,"tv":286.67,"id":27227336},{"batl":[[0,5.1,4.49]],"ltp":4.9,"tv":1723.52,"id":21641292}]}]}
{"op":"mcm","clk":"994562362","pt":1580552521524,"mc":[{"id":"1.168133553","rc":[{"batb":[[2,15,1.45]],"ltp":20.0,"tv":286.67,"id":27227336}]}]}
{"op":"mcm","clk":"994563023","pt":1580552525559,"mc":[{"id":"1.168133553","rc":[{"batb":[[0,4.8,8.55],[1,4.7,40.89],[2,4.4,3.61]],"ltp":4.9,"tv":1723.52,"id":21641292}]}]}
{"op":"mcm","clk":"994563646","pt":1580552529212,"mc":[{"id":"1.168133553","rc":[{"batb":[[2,15,18.45]],"ltp":20.0,"tv":286.67,"id":27227336}]}]}
{"op":"mcm","clk":"994582628","pt":1580552576530,"mc":[{"id":"1.168133553","rc":[{"trd":[[4.8,27.24]],"batb":[[0,4.8,6.05]],"ltp":4.8,"tv":1728.52,"id":21641292}],"tv":11749.42}]}
{"op":"mcm","clk":"994583897","pt":1580552583426,"mc":[{"id":"1.168133553","rc":[{"trd":[[5.1,64.02]],"batl":[[0,5.1,2.49]],"ltp":5.1,"tv":1732.52,"id":21641292}],"tv":11753.42}]}
{"op":"mcm","clk":"994584985","pt":1580552589436,"mc":[{"id":"1.168133553","rc":[{"batb":[[2,15,1.45]],"ltp":20.0,"tv":286.67,"id":27227336}]}]}
{"op":"mcm","clk":"994586495","pt":1580552597468,"mc":[{"id":"1.168133553","rc":[{"trd":[[5.1,74.51]],"batl":[[0,5.2,11.97],[1,5.3,5],[2,5.4,10.82]],"ltp":5.1,"tv":1743.01,"id":21641292}],"tv":11763.91}]}
{"op":"mcm","clk":"994588165","pt":1580552606267,"mc":[{"id":"1.168133553","rc":[{"batl":[[2,50,2]],"ltp":20.0,"tv":286.67,"id":27227336}]}]}
{"op":"mcm","clk":"994601071","pt":1580552678538,"mc":[{"id":"1.168133553","rc":[{"batb":[[0,5,16.8],[1,4.8,6.05],[2,4.7,40.89]],"ltp":5.1,"tv":1743.01,"id":21641292}]}]}
{"op":"mcm","clk":"994601244","pt":1580552679540,"mc":[{"id":"1.168133553","rc":[{"trd":[[5,121.77]],"batb":[[0,5,5.81]],"ltp":5.0,"tv":1765.01,"id":21641292}],"tv":11785.9}]}
{"op":"mcm","clk":"994601366","pt":1580552680215,"mc":[{"id":"1.168133553","rc":[{"batl":[[1,32,8.75],[2,34,5.37]],"ltp":20.0,"tv":286.67,"id":27227336},{"batb":[[1,4.8,8.51]],"ltp":5.0,"tv":1765.01,"id":21641292}]}]}
{"op":"mcm","clk":"994604919","pt":1580552700479,"mc":[{"id":"1.168133553","rc":[{"batb":[[0,5,21]],"ltp":5.0,"tv":1765.01,"id":21641292}]}]}
{"op":"mcm","clk":"994605587","pt":1580552704385,"mc":[{"id":"1.168133553","rc":[{"trd":[[5.2,40.26]],"batb":[[0,5,15.2]],"batl":[[0,5.2,6.16]],"ltp":5.2,"tv":1776.62,"id":21641292}],"tv":11797.52}]}
{"op":"mcm","clk":"994605974","pt":1580552706517,"mc":[{"id":"1.168133553","rc":[{"batb":[[1,4.9,1.2],[2,4.8,7.31]],"ltp":5.2,"tv":1776.62,"id":21641292}]}]}
{"op":"mcm","clk":"994606735","pt":1580552710526,"mc":[{"id":"1.168133553","rc":[{"batb":[[2,16,4.51]],"batl":[[2,34,1]],"ltp":20.0,"tv":286.67,"id":27227336}]}]}
{"op":"mcm","clk":"994607649","pt":1580552715427,"mc":[{"id":"1.168133553","rc":[{"trd":[[5.2,52.57],[5.3,22.13]],"batb":[[0,4.9,1.2],[1,4.8,2.46],[2,4.7,49.24]],"batl":[[0,5.3,17.16],[1,5.4,10.82],[2,5.5,18.68]],"ltp":5.3,"tv":1807.02,"id":21641292}],"tv":11827.92}]}
{"op":"mcm","clk":"994607917","pt":1580552716725,"mc":[{"id":"1.168133553","rc":[{"batb":[[2,16.5,4.44]],"ltp":20.0,"tv":286.67,"id":27227336},{"batb":[[2,4.7,40.89]],"ltp":5.3,"tv":1807.02,"id":21641292}]}]}
{"op":"mcm","clk":"994609086","pt":1580552723508,"mc":[{"id":"1.168133553","rc":[{"batl":[[0,5.3,57.16]],"ltp":5.3,"tv":1807.02,"id":21641292}]}]}
{"op":"mcm","clk":"994609410","pt":1580552725532,"mc":[{"id":"1.168133553","rc":[{"batb":[[0,4.8,2.46],[1,4.7,40.89],[2,4.4,3.61]],"ltp":5.3,"tv":1807.02,"id":21641292}]}]}
{"op":"mcm","clk":"994609456","pt":1580552725847,"mc":[{"id":"1.168133553","rc":[{"batb":[[0,4.8,1.2]],"ltp":5.3,"tv":1807.02,"id":21641292}]}]}
{"op":"mcm","clk":"994610172","pt":1580552730421,"mc":[{"id":"1.168133553","rc":[{"batb":[[0,4.9,16.73],[1,4.8,1.2],[2,4.7,40.89]],"ltp":5.3,"tv":1807.02,"id":21641292}]}]}
{"op":"mcm","clk":"994616323","pt":1580552765530,"mc":[{"id":"1.168133553","rc":[{"batb":[[0,18,5.49]],"ltp":20.0,"tv":286.67,"id":27227336}]}]}
{"op":"mcm","clk":"994625477","pt":1580552818514,"mc":[{"id":"1.168133553","rc":[{"trd":[[1.33,2039.9]],"batl":[[0,1.33,1206.06]],"ltp":1.33,"tv":9746.41,"id":16325787}],"tv":11840.12}]}
{"op":"mcm","clk":"994640997","pt":1580552907449,"mc":[{"id":"1.168133553","rc":[{"batl":[[0,5.3,58.04]],"ltp":5.3,"tv":1807.02,"id":21641292}]}]}
{"op":"mcm","clk":"994641148","pt":1580552908465,"mc":[{"id":"1.168133553","rc":[{"trd":[[4.9,40.29]],"batb":[[0,4.9,5.73]],"batl":[[0,5.2,11.04],[1,5.3,57.16],[2,5.4,10.82]],"ltp":4.9,"tv":1829.02,"id":21641292}],"tv":11862.12}]}
{"op":"mcm","clk":"994641279","pt":1580552909159,"mc":[{"id":"1.168133553","rc":[{"batl":[[0,5.2,10.37]],"ltp":4.9,"tv":1829.02,"id":21641292}]}]}
{"op":"mcm","clk":"994641490","pt":1580552910456,"mc":[{"id":"1.168133553","rc":[{"trd":[[18,16.82],[18.5,1.87]],"batb":[[0,17,1.26],[1,16.5,4.44],[2,16,4.51]],"batl":[[0,19.5,4.21],[1,23,10],[2,32,8.75]],"ltp":18.0,"tv":297.66,"id":27227336}],"tv":11873.11}]}
{"op":"mcm","clk":"994641534","pt":1580552910725,"mc":[{"id":"1.168133553","rc":[{"batb":[[1,15,1.45],[2,14,18.01]],"ltp":18.0,"tv":297.66,"id":27227336}]}]}
{"op":"mcm","clk":"994642240","pt":1580552914954,"mc":[{"id":"1.168133553","rc":[{"batl":[[0,5.2,24.37]],"ltp":4.9,"tv":1829.02,"id":21641292}]}]}
{"op":"mcm","clk":"994646332","pt":1580552939482,"mc":[{"id":"1.168133553","rc":[{"trd":[[19.5,2.78]],"batl":[[0,19.5,2.93]],"ltp":19.5,"tv":298.94,"id":27227336},{"trd":[[5,126.77]],"ltp":5.0,"tv":1834.02,"id":21641292},{"trd":[[1.33,2058.7]],"batl":[[0,1.33,1187.26]],"ltp":1.33,"tv":9765.21,"id":16325787}],"tv":11898.19}]}
{"op":"mcm","clk":"994648728","pt":1580552953211,"mc":[{"id":"1.168133553","rc":[{"trd":[[17.5,2]],"ltp":17.5,"tv":300.94,"id":27227336},{"trd":[[5.2,59.3]],"batl":[[0,5.2,17.64]],"ltp":5.2,"tv":1840.75,"id":21641292},{"trd":[[1.33,2085.02]],"batl":[[0,1.33,1160.94]],"ltp":1.33,"tv":9791.53,"id":16325787}],"tv":11933.24}]}
{"op":"mcm","clk":"994668771","pt":1580553069328,"mc":[{"id":"1.168133553","rc":[{"trd":[[19.5,5.71]],"batl":[[0,22,2.68]],"ltp":19.5,"tv":303.87,"id":27227336},{"trd":[[5.2,70.29]],"batb":[[0,5.1,7.49],[1,4.9,5.73],[2,4.8,1.2]],"batl":[[0,5.2,6.65]],"ltp":5.2,"tv":1851.74,"id":21641292},{"trd":[[1.31,1161.33],[1.32,3780.67]],"batb":[[0,1.31,588.87],[1,1.3,216.12],[2,1.29,488.55]],"ltp":1.31,"tv":10114.52,"id":16325787}],"tv":12270.14}]}
{"op":"mcm","clk":"994668937","pt":1580553070205,"mc":[{"id":"1.168133553","rc":[{"trd":[[5.1,82.51]],"batb":[[0,5.1,3.49]],"ltp":5.1,"tv":1859.74,"id":21641292}],"tv":12278.14}]}
{"op":"mcm","clk":"994669531","pt":1580553073532,"mc":[{"id":"1.168133553","rc":[{"batl":[[0,22,3.44]],"ltp":19.5,"tv":303.87,"id":27227336}]}]}
{"op":"mcm","clk":"994674020","pt":1580553098467,"mc":[{"id":"1.168133553","rc":[{"trd":[[1.31,1171.79]],"batb":[[0,1.31,583.64]],"ltp":1.31,"tv":10124.98,"id":16325787}],"tv":12288.6}]}
{"op":"mcm","clk":"994675312","pt":1580553106329,"mc":[{"id":"1.168133553","rc":[{"batb":[[1,1.3,221.12]],"batl":[[0,1.33,1165.94]],"ltp":1.31,"tv":10124.98,"id":16325787}]}]}
{"op":"mcm","clk":"994678084","pt":1580553121387,"mc":[{"id":"1.168133553","rc":[{"trd":[[5.1,87.31]],"batb":[[0,5.1,1.09]],"ltp":5.1,"tv":1864.54,"id":21641292}],"tv":12293.4}]}
{"op":"mcm","clk":"994678852","pt":1580553125509,"mc":[{"id":"1.168133553","rc":[{"batb":[[1,5,1.2],[2,4.9,5.73]],"ltp":5.1,"tv":1864.54,"id":21641292}]}]}
{"op":"mcm","clk":"994683715","pt":1580553153165,"mc":[{"id":"1.168133553","rc":[{"trd":[[1.33,2101.02]],"batl":[[0,1.33,1157.94]],"ltp":1.33,"tv":10140.98,"id":16325787}],"tv":12309.4}]}
{"op":"mcm","clk":"994687059","pt":1580553169574,"mc":[{"id":"1.168133553","rc":[{"batl":[[0,22,2.68]],"ltp":19.5,"tv":303.87,"id":27227336},{"batb":[[0,1.31,613.94]],"ltp":1.33,"tv":10140.98,"id":16325787}]}]}
{"op":"mcm","clk":"994687522","pt":1580553172506,"mc":[{"id":"1.168133553","rc":[{"trd":[[4.9,43.61],[5,129.17],[5.1,89.49]],"batb":[[0,4.9,4.07],[1,4.7,40.89],[2,4.4,60.61]],"ltp":4.9,"tv":1872.44,"id":21641292}],"tv":12317.3}]}
{"op":"mcm","clk":"994688584","pt":1580553178433,"mc":[{"id":"1.168133553","rc":[{"batl":[[0,18,20],[1,22,2.68],[2,23,10]],"ltp":19.5,"tv":303.87,"id":27227336}]}]}
{"op":"mcm","clk":"994688768","pt":1580553179542,"mc":[{"id":"1.168133553","rc":[{"batb":[[2,4.5,6]],"ltp":4.9,"tv":1872.44,"id":21641292}]}]}
{"op":"mcm","clk":"994689451","pt":1580553183563,"mc":[{"id":"1.168133553","rc":[{"trd":[[18,17.77]],"batl":[[0,18,19.05]],"ltp":18.0,"tv":304.82,"id":27227336},{"trd":[[5.2,73.59]],"batl":[[0,5.2,3.35]],"ltp":5.2,"tv":1875.74,"id":21641292},{"trd":[[1.32,3793.67]],"ltp":1.32,"tv":10153.98,"id":16325787}],"tv":12334.55}]}
{"op":"mcm","clk":"994689617","pt":1580553184559,"mc":[{"id":"1.168133553","rc":[{"batb":[[0,5.1,3.36],[1,4.9,4.07],[2,4.7,40.89]],"ltp":5.2,"tv":1875.74,"id":21641292}]}]}
{"op":"mcm","clk":"994690286","pt":1580553188567,"mc":[{"id":"1.168133553","rc":[{"trd":[[5.1,94.29]],"batb":[[0,4.9,5.03],[1,4.5,6],[2,4.4,60.61]],"ltp":5.1,"tv":1880.54,"id":21641292},{"batb":[[0,1.31,125.89]],"ltp":1.32,"tv":10153.98,"id":16325787}],"tv":12339.35}]}
{"op":"mcm","clk":"994690441","pt":1580553189536,"mc":[{"id":"1.168133553","rc":[{"trd":[[18,24.63]],"batl":[[0,18,12.19]],"ltp":18.0,"tv":311.68,"id":27227336},{"trd":[[5.2,76.94],[5.3,42.13]],"batb":[[0,5.1,4.38],[1,4.9,4.07],[2,4.5,6]],"batl":[[0,5.3,37.16],[1,5.4,10.82],[2,5.5,18.68]],"ltp":5.3,"tv":1903.89,"id":21641292},{"trd":[[1.32,3887.15]],"ltp":1.32,"tv":10247.46,"id":16325787}],"tv":12463.04}]}
{"op":"mcm","clk":"994690634","pt":1580553190760,"mc":[{"id":"1.168133553","rc":[{"batb":[[2,13.5,5.29]],"ltp":18.0,"tv":311.68,"id":27227336}]}]}
{"op":"mcm","clk":"994692279","pt":1580553200235,"mc":[{"id":"1.168133553","rc":[{"batb":[[2,4.4,3.61]],"ltp":5.3,"tv":1903.89,"id":21641292}]}]}
{"op":"mcm","clk":"994695638","pt":1580553219223,"mc":[{"id":"1.168133553","rc":[{"trd":[[18,26.83]],"batl":[[0,18,9.99]],"ltp":18.0,"tv":313.88,"id":27227336},{"trd":[[5.3,49.6]],"batl":[[0,5.3,29.69]],"ltp":5.3,"tv":1911.36,"id":21641292},{"trd":[[1.32,3917.15]],"ltp":1.32,"tv":10277.46,"id":16325787}],"tv":12502.71}]}
{"op":"mcm","clk":"994706791","pt":1580553285297,"mc":[{"id":"1.168133553","rc":[{"batb":[[1,5,2],[2,4.9,4.07]],"ltp":5.3,"tv":1911.36,"id":21641292}]}]}
{"op":"mcm","clk":"994714389","pt":1580553330562,"mc":[{"id":"1.168133553","rc":[{"batb":[[2,4.5,6]],"ltp":5.3,"tv":1911.36,"id":21641292}]}]}
{"op":"mcm","clk":"994714545","pt":1580553331468,"mc":[{"id":"1.168133553","rc":[{"trd":[[5.1,100.69]],"batb":[[0,5.1,1.18]],"batl":[[0,5.2,1.56],[1,5.3,29.69],[2,5.4,10.82]],"ltp":5.1,"tv":1917.76,"id":21641292}],"tv":12509.11}]}
{"op":"mcm","clk":"994720272","pt":1580553365358,"mc":[{"id":"1.168133553","rc":[{"batb":[[1,4.6,2]],"ltp":5.1,"tv":1917.76,"id":21641292}]}]}
{"op":"mcm","clk":"994721652","pt":1580553373567,"mc":[{"id":"1.168133553","rc":[{"batb":[[2,4.4,3.61]],"ltp":5.1,"tv":1917.76,"id":21641292}]}]}
{"op":"mcm","clk":"994724513","pt":1580553390518,"mc":[{"id":"1.168133553","rc":[{"batb":[[1,4.9,3.16],[2,4.6,2]],"ltp":5.1,"tv":1917.76,"id":21641292}]}]}
{"op":"mcm","clk":"994729349","pt":1580553420555,"mc":[{"id":"1.168133553","rc":[{"batb":[[1,4.6,2],[2,4.4,3.61]],"ltp":5.1,"tv":1917.76,"id":21641292}]}]}
{"op":"mcm","clk":"994746039","pt":1580553458485,"mc":[{"id":"1.168133553","rc":[{"batb":[[1,4.4,3.61],[2,4.3,58]],"ltp":5.1,"tv":1917.76,"id":21641292}]}]}
{"op":"mcm","clk":"994751208","pt":1580553489545,"mc":[{"id":"1.168133553","rc":[{"trd":[[18,26.9]],"batl":[[0,18,9.92]],"ltp":18.0,"tv":313.95,"id":27227336},{"trd":[[5.2,79.81],[5.3,50.98]],"batl":[[0,5.3,29],[1,5.4,10.82],[2,5.5,18.68]],"ltp":5.3,"tv":1922.01,"id":21641292},{"trd":[[1.32,3918.15]],"ltp":1.32,"tv":10278.46,"id":16325787}],"tv":12514.43}]}
{"op":"mcm","clk":"994751365","pt":1580553490513,"mc":[{"id":"1.168133553","rc":[{"batb":[[0,1.32,1],[1,1.31,125.89],[2,1.3,221.12]],"ltp":1.32,"tv":10278.46,"id":16325787}]}]}
{"op":"mcm","clk":"994752580","pt":1580553498121,"mc":[{"id":"1.168133553","rc":[{"batb":[[1,4.4,5.61]],"ltp":5.3,"tv":1922.01,"id":21641292}]}]}
{"op":"mcm","clk":"994754244","pt":1580553508545,"mc":[{"id":"1.168133553","rc":[{"trd":[[18,27.27]],"batl":[[0,18,9.55]],"ltp":18.0,"tv":314.32,"id":27227336},{"trd":[[5.3,52.23]],"batb":[[1,4.5,9.52],[2,4.4,5.61]],"batl":[[0,5.3,27.75]],"ltp":5.3,"tv":1923.26,"id":21641292},{"trd":[[1.32,3925.15]],"batb":[[0,1.31,125.89],[1,1.3,221.12],[2,1.29,488.55]],"ltp":1.32,"tv":10285.46,"id":16325787}],"tv":12523.05}]}
{"op":"mcm","clk":"994760577","pt":1580553546019,"mc":[{"id":"1.168133553","rc":[{"batl":[[2,5.5,23.68]],"ltp":5.3,"tv":1923.26,"id":21641292}]}]}
{"op":"mcm","clk":"994761870","pt":1580553553521,"mc":[{"id":"1.168133553","rc":[{"batl":[[2,1.35,1651.83]],"ltp":1.32,"tv":10285.46,"id":16325787}]}]}
{"op":"mcm","clk":"994783522","pt":1580553684924,"mc":[{"id":"1.168133553","rc":[{"trd":[[18,29.69]],"batl":[[0,18,7.13]],"ltp":18.0,"tv":316.74,"id":27227336},{"trd":[[5.3,60.45]],"batl":[[0,5.3,19.53]],"ltp":5.3,"tv":1931.48,"id":21641292},{"trd":[[1.32,3958.15]],"ltp":1.32,"tv":10318.46,"id":16325787}],"tv":12566.69}]}
{"op":"mcm","clk":"994785971","pt":1580553699534,"mc":[{"id":"1.168133553","rc":[{"trd":[[18,30.24]],"batl":[[0,18,6.58]],"ltp":18.0,"tv":317.29,"id":27227336},{"trd":[[5.3,62.32]],"batl":[[0,5.3,17.66]],"ltp":5.3,"tv":1933.35,"id":21641292},{"trd":[[1.32,3965.65]],"ltp":1.32,"tv":10325.96,"id":16325787}],"tv":12576.61}]}
{"op":"mcm","clk":"994788260","pt":1580553713488,"mc":[{"id":"1.168133553","rc":[{"batb":[[2,14,3.04]],"ltp":18.0,"tv":317.29,"id":27227336}]}]}
{"op":"mcm","clk":"994793801","pt":1580553746492,"mc":[{"id":"1.168133553","rc":[{"batb":[[2,13.5,5.29]],"ltp":18.0,"tv":317.29,"id":27227336}]}]}
{"op":"mcm","clk":"994805564","pt":1580553815521,"mc":[{"id":"1.168133553","rc":[{"batb":[[2,14,3.04]],"ltp":18.0,"tv":317.29,"id":27227336}]}]}
{"op":"mcm","clk":"994811047","pt":1580553848496,"mc":[{"id":"1.168133553","rc":[{"batb":[[2,13.5,5.29]],"ltp":18.0,"tv":317.29,"id":27227336}]}]}
{"op":"mcm","clk":"994819093","pt":1580553898538,"mc":[{"id":"1.168133553","rc":[{"trd":[[18,30.86]],"batl":[[0,18,5.96]],"ltp":18.0,"tv":317.91,"id":27227336},{"trd":[[5.3,64.41]],"batl":[[0,5.3,15.57]],"ltp":5.3,"tv":1935.44,"id":21641292},{"trd":[[1.32,3974.05]],"ltp":1.32,"tv":10334.36,"id":16325787}],"tv":12587.72}]}
{"op":"mcm","clk":"994820839","pt":1580553908353,"mc":[{"id":"1.168133553","rc":[{"trd":[[1.33,2141.02]],"batl":[[0,1.33,1137.94]],"ltp":1.33,"tv":10374.36,"id":16325787}],"tv":12627.72}]}
{"op":"mcm","clk":"994822071","pt":1580553915563,"mc":[{"id":"1.168133553","rc":[{"batb":[[2,14,3.04]],"ltp":18.0,"tv":317.91,"id":27227336}]}]}
{"op":"mcm","clk":"994827166","pt":1580553948417,"mc":[{"id":"1.168133553","rc":[{"batb":[[2,13.5,5.29]],"ltp":18.0,"tv":317.91,"id":27227336}]}]}
{"op":"mcm","clk":"994837590","pt":1580554014560,"mc":[{"id":"1.168133553","rc":[{"batb":[[2,14,3.04]],"ltp":18.0,"tv":317.91,"id":27227336}]}]}
{"op":"mcm","clk":"994838590","pt":1580554020547,"mc":[{"id":"1.168133553","rc":[{"batb":[[0,5.2,10.2],[1,5.1,1.18],[2,4.5,9.52]],"ltp":5.3,"tv":1935.44,"id":21641292}]}]}
{"op":"mcm","clk":"994839380","pt":1580554025555,"mc":[{"id":"1.168133553","rc":[{"batb":[[2,4.6,2]],"ltp":5.3,"tv":1935.44,"id":21641292}]}]}
{"op":"mcm","clk":"994839670","pt":1580554027569,"mc":[{"id":"1.168133553","rc":[{"batb":[[1,4.6,2],[2,4.5,9.52]],"ltp":5.3,"tv":1935.44,"id":21641292}]}]}
{"op":"mcm","clk":"994839766","pt":1580554028308,"mc":[{"id":"1.168133553","rc":[{"trd":[[5.3,66.69]],"batl":[[0,5.3,14.43]],"ltp":5.3,"tv":1937.72,"id":21641292}],"tv":12630.0}]}
{"op":"mcm","clk":"994839938","pt":1580554029368,"mc":[{"id":"1.168133553","rc":[{"batb":[[0,4.9,10.27]],"ltp":5.3,"tv":1937.72,"id":21641292}]}]}
{"op":"mcm","clk":"994840829","pt":1580554035488,"mc":[{"id":"1.168133553","rc":[{"trd":[[5.3,80.69]],"batb":[[1,4.5,9.52],[2,4.4,3.61]],"batl":[[0,5.3,7.43]],"ltp":5.3,"tv":1951.72,"id":21641292}],"tv":12644.0}]}
{"op":"mcm","clk":"994840975","pt":1580554036504,"mc":[{"id":"1.168133553","rc":[{"batb":[[1,4.7,2],[2,4.5,9.52]],"ltp":5.3,"tv":1951.72,"id":21641292}]}]}
{"op":"mcm","clk":"994841067","pt":1580554037093,"mc":[{"id":"1.168133553","rc":[{"batb":[[2,4.4,3.61]],"ltp":5.3,"tv":1951.72,"id":21641292}]}]}
{"op":"mcm","clk":"994842669","pt":1580554047416,"mc":[{"id":"1.168133553","rc":[{"batb":[[2,13.5,5.29]],"ltp":18.0,"tv":317.91,"id":27227336}]}]}
{"op":"mcm","clk":"994843486","pt":1580554052451,"mc":[{"id":"1.168133553","rc":[{"batb":[[0,5.2,3.2],[1,4.9,10.27],[2,4.7,2]],"ltp":5.3,"tv":1951.72,"id":21641292}]}]}
{"op":"mcm","clk":"994843727","pt":1580554053504,"mc":[{"id":"1.168133553","rc":[{"batb":[[1,4.7,2],[2,4.4,3.61]],"ltp":5.3,"tv":1951.72,"id":21641292}]}]}
{"op":"mcm","clk":"994845402","pt":1580554062035,"mc":[{"id":"1.168133553","rc":[{"batb":[[2,4.4,60.61]],"ltp":5.3,"tv":1951.72,"id":21641292}]}]}
{"op":"mcm","clk":"994845997","pt":1580554065529,"mc":[{"id":"1.168133553","rc":[{"batb":[[2,4.5,6]],"ltp":5.3,"tv":1951.72,"id":21641292}]}]}
{"op":"mcm","clk":"994846941","pt":1580554070546,"mc":[{"id":"1.168133553","rc":[{"trd":[[5.2,86.22]],"batb":[[0,4.7,2],[1,4.5,6],[2,4.4,60.61]],"batl":[[0,5.2,3.35],[1,5.3,7.43],[2,5.4,3222.82]],"ltp":5.2,"tv":1958.12,"id":21641292}],"tv":12650.4}]}
{"op":"mcm","clk":"994847092","pt":1580554071545,"mc":[{"id":"1.168133553","rc":[{"batb":[[0,1.32,1.19],[1,1.31,125.89],[2,1.3,221.12]],"ltp":1.33,"tv":10374.36,"id":16325787}]}]}
{"op":"mcm","clk":"994847276","pt":1580554072532,"mc":[{"id":"1.168133553","rc":[{"trd":[[5.2,86.82]],"batl":[[0,5.2,3.05]],"ltp":5.2,"tv":1958.73,"id":21641292}],"tv":12651.01}]}
{"op":"mcm","clk":"994847640","pt":1580554074423,"mc":[{"id":"1.168133553","rc":[{"trd":[[5.2,92.92]],"batl":[[0,5.3,7.43],[1,5.4,10.82],[2,5.5,23.68]],"ltp":5.2,"tv":1964.83,"id":21641292}],"tv":12657.11}]}
{"op":"mcm","clk":"994847835","pt":1580554075546,"mc":[{"id":"1.168133553","rc":[{"trd":[[5.3,84.69]],"batb":[[0,4.6,2],[1,4.5,15.24]],"batl":[[0,5.3,5.43]],"ltp":5.3,"tv":1968.83,"id":21641292}],"tv":12661.11}]}
{"op":"mcm","clk":"994850255","pt":1580554092381,"mc":[{"id":"1.168133553","rc":[{"batb":[[2,4.4,3.61]],"ltp":5.3,"tv":1968.83,"id":21641292}]}]}
{"op":"mcm","clk":"994851569","pt":1580554102503,"mc":[{"id":"1.168133553","rc":[{"batb":[[1,4.5,9.24]],"ltp":5.3,"tv":1968.83,"id":21641292}]}]}
{"op":"mcm","clk":"994853254","pt":1580554114479,"mc":[{"id":"1.168133553","rc":[{"batb":[[2,14,3.04]],"ltp":18.0,"tv":317.91,"id":27227336}]}]}
{"op":"mcm","clk":"994857955","pt":1580554148561,"mc":[{"id":"1.168133553","rc":[{"trd":[[18,32.46]],"batb":[[2,13.5,5.29]],"batl":[[0,18,4.36]],"ltp":18.0,"tv":319.51,"id":27227336},{"trd":[[5.3,90.12]],"batl":[[0,5.4,10.82],[1,5.5,23.68],[2,5.9,2.85]],"ltp":5.3,"tv":1974.26,"id":21641292},{"trd":[[1.32,3998.23]],"batb":[[0,1.31,125.89],[1,1.3,221.12],[2,1.29,488.55]],"batl":[[0,1.32,384.36],[1,1.33,1137.94],[2,1.34,1500]],"ltp":1.32,"tv":10398.54,"id":16325787}],"tv":12692.32}]}
{"op":"mcm","clk":"994858090","pt":1580554149564,"mc":[{"id":"1.168133553","rc":[{"batb":[[1,1.3,225.66]],"ltp":1.32,"tv":10398.54,"id":16325787}]}]}
{"op":"mcm","clk":"994858205","pt":1580554150478,"mc":[{"id":"1.168133553","rc":[{"batb":[[0,17,1.8]],"ltp":18.0,"tv":319.51,"id":27227336},{"batb":[[0,5.3,1.48],[1,4.7,40.89],[2,4.6,2]],"ltp":5.3,"tv":1974.26,"id":21641292},{"batb":[[0,1.31,613.94],[1,1.3,227.17]],"ltp":1.32,"tv":10398.54,"id":16325787}]}]}
{"op":"mcm","clk":"994859686","pt":1580554160454,"mc":[{"id":"1.168133553","rc":[{"batl":[[2,5.9,33.72]],"ltp":5.3,"tv":1974.26,"id":21641292}]}]}
{"op":"mcm","clk":"994861230","pt":1580554171370,"mc":[{"id":"1.168133553","rc":[{"batl":[[0,1.32,389.36]],"ltp":1.32,"tv":10398.54,"id":16325787}]}]}
{"op":"mcm","clk":"994861317","pt":1580554172064,"mc":[{"id":"1.168133553","rc":[{"batb":[[2,1.29,493.55]],"ltp":1.32,"tv":10398.54,"id":16325787}]}]}
{"op":"mcm","clk":"994863459","pt":1580554187571,"mc":[{"id":"1.168133553","rc":[{"trd":[[18,32.61]],"batl":[[0,18,4.21]],"ltp":18.0,"tv":319.66,"id":27227336},{"trd":[[5.3,93.6]],"batb":[[0,4.7,40.89],[1,4.6,2],[2,4.5,9.24]],"ltp":5.3,"tv":1977.74,"id":21641292},{"trd":[[1.32,4000.32]],"batl":[[0,1.32,387.27]],"ltp":1.32,"tv":10400.63,"id":16325787}],"tv":12698.04}]}
{"op":"mcm","clk":"994865715","pt":1580554204504,"mc":[{"id":"1.168133553","rc":[{"trd":[[1.32,4160.32]],"batb":[[1,1.3,271.56]],"batl":[[0,1.32,307.27]],"ltp":1.32,"tv":10560.63,"id":16325787}],"tv":12858.04}]}
{"op":"mcm","clk":"994867262","pt":1580554214506,"mc":[{"id":"1.168133553","rc":[{"batb":[[0,4.7,42.89],[1,4.5,9.24],[2,4.4,3.61]],"ltp":5.3,"tv":1977.74,"id":21641292}]}]}
{"op":"mcm","clk":"994869968","pt":1580554234451,"mc":[{"id":"1.168133553","rc":[{"batb":[[0,4.7,40.89],[1,4.6,2],[2,4.5,9.24]],"ltp":5.3,"tv":1977.74,"id":21641292},{"batb":[[1,1.3,227.17]],"ltp":1.32,"tv":10560.63,"id":16325787}]}]}
{"op":"mcm","clk":"994872709","pt":1580554254061,"mc":[{"id":"1.168133553","rc":[{"batb":[[0,4.7,42.89],[1,4.5,9.24],[2,4.4,3.61]],"ltp":5.3,"tv":1977.74,"id":21641292}]}]}
{"op":"mcm","clk":"994874139","pt":1580554264500,"mc":[{"id":"1.168133553","rc":[{"batb":[[0,4.7,40.89],[1,4.6,2],[2,4.5,9.24]],"ltp":5.3,"tv":1977.74,"id":21641292}]}]}
{"op":"mcm","clk":"994876687","pt":1580554283487,"mc":[{"id":"1.168133553","rc":[{"batb":[[0,4.7,42.89],[1,4.5,9.24],[2,4.4,3.61]],"ltp":5.3,"tv":1977.74,"id":21641292}]}]}
{"op":"mcm","clk":"994878196","pt":1580554294413,"mc":[{"id":"1.168133553","rc":[{"batb":[[0,4.7,40.89],[1,4.6,2],[2,4.5,9.24]],"ltp":5.3,"tv":1977.74,"id":21641292}]}]}
{"op":"mcm","clk":"994880051","pt":1580554309548,"mc":[{"id":"1.168133553","rc":[{"trd":[[18,34.56]],"batl":[[0,18,2.26]],"ltp":18.0,"tv":321.61,"id":27227336},{"trd":[[5.3,100.22]],"batl":[[1,5.5,17.3]],"ltp":5.3,"tv":1984.36,"id":21641292},{"trd":[[1.32,4186.89]],"batl":[[0,1.32,280.7]],"ltp":1.32,"tv":10587.2,"id":16325787}],"tv":12893.18}]}
{"op":"mcm","clk":"994881020","pt":1580554317556,"mc":[{"id":"1.168133553","rc":[{"trd":[[18,36.82]],"batl":[[0,22,2.68],[1,23,10],[2,32,8.75]],"ltp":18.0,"tv":323.87,"id":27227336},{"trd":[[5.3,107.88]],"batb":[[1,4.6,10.83]],"ltp":5.3,"tv":1992.02,"id":21641292},{"trd":[[1.32,4217.66]],"batl":[[0,1.32,249.93]],"ltp":1.32,"tv":10617.97,"id":16325787}],"tv":12933.88}]}
{"op":"mcm","clk":"994881670","pt":1580554322536,"mc":[{"id":"1.168133553","rc":[{"batl":[[0,22,3.44]],"ltp":18.0,"tv":323.87,"id":27227336}]}]}
{"op":"mcm","clk":"994881941","pt":1580554324547,"mc":[{"id":"1.168133553","rc":[{"batb":[[0,4.7,42.89],[1,4.6,8.83]],"ltp":5.3,"tv":1992.02,"id":21641292}]}]}
{"op":"mcm","clk":"994886011","pt":1580554351246,"mc":[{"id":"1.168133553","rc":[{"batb":[[0,4.8,8.46],[1,4.7,42.89]],"ltp":5.3,"tv":1992.02,"id":21641292}]}]}
{"op":"mcm","clk":"994897231","pt":1580554356430,"mc":[{"id":"1.168133553","rc":[{"trd":[[1.32,4227.82]],"batl":[[0,1.32,244.85]],"ltp":1.32,"tv":10628.13,"id":16325787}],"tv":12944.04}]}
{"op":"mcm","clk":"994899271","pt":1580554372049,"mc":[{"id":"1.168133553","rc":[{"trd":[[1.31,1175.79]],"batb":[[0,1.31,611.94]],"ltp":1.31,"tv":10632.13,"id":16325787}],"tv":12948.04}]}
{"op":"mcm","clk":"994899866","pt":1580554376494,"mc":[{"id":"1.168133553","rc":[{"trd":[[1.32,4231.78]],"batl":[[0,1.32,242.87]],"ltp":1.32,"tv":10636.09,"id":16325787}],"tv":12952.0}]}
{"op":"mcm","clk":"994905254","pt":1580554418508,"mc":[{"id":"1.168133553","rc":[{"trd":[[1.32,4242.18]],"batl":[[0,1.32,237.67]],"ltp":1.32,"tv":10646.49,"id":16325787}],"tv":12962.4}]}
{"op":"mcm","clk":"994911385","pt":1580554462394,"mc":[{"id":"1.168133553","rc":[{"trd":[[17,10.68],[17.5,3.08]],"batb":[[0,15,1.45],[1,13.5,5.29],[2,12.5,20]],"batl":[[0,17,4.76],[1,22,3.44],[2,23,10]],"ltp":17.0,"tv":330.91,"id":27227336},{"trd":[[5.4,372.93]],"batl":[[0,5.5,17.3],[1,5.9,33.72],[2,6,10]],"ltp":5.4,"tv":2002.84,"id":21641292},{"trd":[[1.32,4286.45]],"batl":[[0,1.32,193.4]],"ltp":1.32,"tv":10690.76,"id":16325787}],"tv":13024.52}]}
{"op":"mcm","clk":"994911552","pt":1580554463493,"mc":[{"id":"1.168133553","rc":[{"batb":[[1,13.5,10.56]],"ltp":17.0,"tv":330.91,"id":27227336}]}]}
{"op":"mcm","clk":"994914468","pt":1580554483358,"mc":[{"id":"1.168133553","rc":[{"batb":[[2,11.5,4.94]],"ltp":17.0,"tv":330.91,"id":27227336},{"batb":[[2,4.5,65.24]],"ltp":5.4,"tv":2002.84,"id":21641292}]}]}
{"op":"mcm","clk":"994915494","pt":1580554490378,"mc":[{"id":"1.168133553","rc":[{"batb":[[2,4.6,6]],"ltp":5.4,"tv":2002.84,"id":21641292}]}]}
{"op":"mcm","clk":"994915844","pt":1580554492491,"mc":[{"id":"1.168133553","rc":[{"batb":[[1,13.5,2.65]],"ltp":17.0,"tv":330.91,"id":27227336}]}]}
{"op":"mcm","clk":"994916011","pt":1580554493408,"mc":[{"id":"1.168133553","rc":[{"batb":[[1,11.5,4.95],[2,11,28.29]],"ltp":17.0,"tv":330.91,"id":27227336}]}]}
{"op":"mcm","clk":"994916448","pt":1580554496476,"mc":[{"id":"1.168133553","rc":[{"batb":[[1,12,3.58],[2,11.5,4.94]],"ltp":17.0,"tv":330.91,"id":27227336}]}]}
{"op":"mcm","clk":"994919675","pt":1580554516244,"mc":[{"id":"1.168133553","rc":[{"batb":[[1,12.5,3.04],[2,12,3.57]],"ltp":17.0,"tv":330.91,"id":27227336}]}]}
{"op":"mcm","clk":"994920165","pt":1580554519368,"mc":[{"id":"1.168133553","rc":[{"batb":[[2,11.5,4.94]],"ltp":17.0,"tv":330.91,"id":27227336}]}]}
{"op":"mcm","clk":"994925256","pt":1580554549390,"mc":[{"id":"1.168133553","rc":[{"batb":[[1,12.5,2.55]],"ltp":17.0,"tv":330.91,"id":27227336}]}]}
{"op":"mcm","clk":"994926512","pt":1580554556488,"mc":[{"id":"1.168133553","rc":[{"batb":[[2,1.29,193.55]],"ltp":1.32,"tv":10690.76,"id":16325787}]}]}
{"op":"mcm","clk":"994931001","pt":1580554582545,"mc":[{"id":"1.168133553","rc":[{"trd":[[1.32,4290.45]],"batl":[[0,1.32,191.4]],"ltp":1.32,"tv":10694.76,"id":16325787}],"tv":13028.52}]}
{"op":"mcm","clk":"994931861","pt":1580554587369,"mc":[{"id":"1.168133553","rc":[{"batl":[[0,1.32,193.4]],"ltp":1.32,"tv":10694.76,"id":16325787}]}]}
{"op":"mcm","clk":"994940331","pt":1580554636562,"mc":[{"id":"1.168133553","rc":[{"batb":[[2,11,23]],"ltp":17.0,"tv":330.91,"id":27227336}]}]}
{"op":"mcm","clk":"994954530","pt":1580554714554,"mc":[{"id":"1.168133553","rc":[{"trd":[[1.32,4294.45]],"batl":[[0,1.32,191.4]],"ltp":1.32,"tv":10698.76,"id":16325787}],"tv":13032.52}]}
{"op":"mcm","clk":"994955408","pt":1580554719970,"mc":[{"id":"1.168133553","rc":[{"batl":[[0,1.32,193.4]],"ltp":1.32,"tv":10698.76,"id":16325787}]}]}
{"op":"mcm","clk":"994956204","pt":1580554724485,"mc":[{"id":"1.168133553","rc":[{"batl":[[1,22,2.68]],"ltp":17.0,"tv":330.91,"id":27227336}]}]}
{"op":"mcm","clk":"994964215","pt":1580554767335,"mc":[{"id":"1.168133553","rc":[{"batb":[[2,4.5,9.24]],"ltp":5.4,"tv":2002.84,"id":21641292}]}]}
{"op":"mcm","clk":"994984873","pt":1580554866537,"mc":[{"id":"1.168133553","rc":[{"batl":[[0,1.32,195.4]],"ltp":1.32,"tv":10698.76,"id":16325787}]}]}
{"op":"mcm","clk":"995007686","pt":1580554971479,"mc":[{"id":"1.168133553","rc":[{"trd":[[17,12.27]],"batl":[[0,17,3.17]],"ltp":17.0,"tv":332.5,"id":27227336},{"trd":[[5.4,377.93]],"ltp":5.4,"tv":2007.84,"id":21641292},{"trd":[[1.32,4314.9]],"batl":[[0,1.32,174.95]],"ltp":1.32,"tv":10719.21,"id":16325787}],"tv":13059.56}]}
{"op":"mcm","clk":"995012856","pt":1580554995485,"mc":[{"id":"1.168133553","rc":[{"trd":[[17,13.22]],"batl":[[0,17,2.22]],"ltp":17.0,"tv":333.45,"id":27227336},{"trd":[[5.4,380.93]],"ltp":5.4,"tv":2010.84,"id":21641292},{"trd":[[1.32,4327.17]],"batl":[[0,1.32,162.68]],"ltp":1.32,"tv":10731.48,"id":16325787}],"tv":13075.78}]}
{"op":"mcm","clk":"995013079","pt":1580554996502,"mc":[{"id":"1.168133553","rc":[{"batl":[[1,22,2.91]],"ltp":17.0,"tv":333.45,"id":27227336}]}]}
{"op":"mcm","clk":"995015723","pt":1580555009536,"mc":[{"id":"1.168133553","rc":[{"batl":[[1,22,3.67]],"ltp":17.0,"tv":333.45,"id":27227336}]}]}
{"op":"mcm","clk":"995018630","pt":1580555024157,"mc":[{"id":"1.168133553","rc":[{"batb":[[2,4.5,65.24]],"ltp":5.4,"tv":2010.84,"id":21641292}]}]}
{"op":"mcm","clk":"995019917","pt":1580555030569,"mc":[{"id":"1.168133553","rc":[{"batb":[[2,4.6,6]],"ltp":5.4,"tv":2010.84,"id":21641292}]}]}
{"op":"mcm","clk":"995023408","pt":1580555047572,"mc":[{"id":"1.168133553","rc":[{"batl":[[0,1.32,11]],"ltp":1.32,"tv":10731.48,"id":16325787}]}]}
{"op":"mcm","clk":"995025022","pt":1580555054478,"mc":[{"id":"1.168133553","rc":[{"batb":[[2,10.5,1.98]],"ltp":17.0,"tv":333.45,"id":27227336}]}]}
{"op":"mcm","clk":"995027327","pt":1580555064528,"mc":[{"id":"1.168133553","rc":[{"batb":[[2,4.5,9.24]],"ltp":5.4,"tv":2010.84,"id":21641292}]}]}
{"op":"mcm","clk":"995031182","pt":1580555082540,"mc":[{"id":"1.168133553","rc":[{"batl":[[2,1.34,1525.33]],"ltp":1.32,"tv":10731.48,"id":16325787}]}]}
{"op":"mcm","clk":"995054580","pt":1580555191868,"mc":[{"id":"1.168133553","rc":[{"trd":[[1.31,2175.79]],"batb":[[0,1.31,111.94]],"ltp":1.31,"tv":11731.48,"id":16325787}],"tv":14075.78}]}
{"op":"mcm","clk":"995054893","pt":1580555193272,"mc":[{"id":"1.168133553","rc":[{"batb":[[0,1.3,227.17],[1,1.29,193.55],[2,1.28,200]],"ltp":1.31,"tv":11731.48,"id":16325787}]}]}
{"op":"mcm","clk":"995056155","pt":1580555199387,"mc":[{"id":"1.168133553","rc":[{"trd":[[17,17.22]],"batl":[[0,22,3.89],[1,23,10],[2,32,8.75]],"ltp":17.0,"tv":337.45,"id":27227336}],"tv":14079.78}]}
{"op":"mcm","clk":"995056252","pt":1580555199867,"mc":[{"id":"1.168133553","rc":[{"trd":[[17,17.66]],"batl":[[0,22,3.67]],"ltp":17.0,"tv":337.89,"id":27227336},{"batb":[[1,1.29,196.74]],"ltp":1.31,"tv":11731.48,"id":16325787}],"tv":14080.22}]}
{"op":"mcm","clk":"995056635","pt":1580555201488,"mc":[{"id":"1.168133553","rc":[{"batl":[[0,22,3.11]],"ltp":17.0,"tv":337.89,"id":27227336},{"trd":[[1.32,4338.07]],"batl":[[0,1.32,5.55]],"ltp":1.32,"tv":11742.38,"id":16325787}],"tv":14091.12}]}
{"op":"mcm","clk":"995056855","pt":1580555202570,"mc":[{"id":"1.168133553","rc":[{"batb":[[1,1.29,193.55]],"ltp":1.32,"tv":11742.38,"id":16325787}]}]}
{"op":"mcm","clk":"995057246","pt":1580555204516,"mc":[{"id":"1.168133553","rc":[{"trd":[[5.5,222.35]],"batl":[[0,5.5,11.3]],"ltp":5.5,"tv":2022.84,"id":21641292}],"tv":14103.12}]}
{"op":"mcm","clk":"995058044","pt":1580555208482,"mc":[{"id":"1.168133553","rc":[{"batl":[[0,21,2.24],[1,22,2.91],[2,23,10]],"ltp":17.0,"tv":337.89,"id":27227336}]}]}
{"op":"mcm","clk":"995061392","pt":1580555225519,"mc":[{"id":"1.168133553","rc":[{"batb":[[0,5,3.18],[1,4.8,8.46],[2,4.7,42.89]],"ltp":5.5,"tv":2022.84,"id":21641292}]}]}
{"op":"mcm","clk":"995063874","pt":1580555237334,"mc":[{"id":"1.168133553","rc":[{"batb":[[1,1.29,198.55]],"batl":[[0,1.32,10.55]],"ltp":1.32,"tv":11742.38,"id":16325787}]}]}
{"op":"mcm","clk":"995066469","pt":1580555249442,"mc":[{"id":"1.168133553","rc":[{"batb":[[0,5.1,3.92],[1,5,3.18],[2,4.8,8.46]],"ltp":5.5,"tv":2022.84,"id":21641292}]}]}
{"op":"mcm","clk":"995079956","pt":1580555262546,"mc":[{"id":"1.168133553","rc":[{"batl":[[0,20,7.8],[1,21,2.04],[2,22,2.68]],"ltp":17.0,"tv":337.89,"id":27227336}]}]}
{"op":"mcm","clk":"995080153","pt":1580555263525,"mc":[{"id":"1.168133553","rc":[{"batl":[[0,20,8.06]],"ltp":17.0,"tv":337.89,"id":27227336}]}]}
{"op":"mcm","clk":"995082443","pt":1580555274567,"mc":[{"id":"1.168133553","rc":[{"batb":[[0,5.1,5.92]],"ltp":5.5,"tv":2022.84,"id":21641292}]}]}
{"op":"mcm","clk":"995083578","pt":1580555279464,"mc":[{"id":"1.168133553","rc":[{"batl":[[1,22,2.68],[2,23,10]],"ltp":17.0,"tv":337.89,"id":27227336}]}]}
{"op":"mcm","clk":"995089266","pt":1580555308464,"mc":[{"id":"1.168133553","rc":[{"batb":[[0,5.1,2]],"ltp":5.5,"tv":2022.84,"id":21641292}]}]}
{"op":"mcm","clk":"995098972","pt":1580555359486,"mc":[{"id":"1.168133553","rc":[{"trd":[[1.3,1007.22]],"batb":[[0,1.3,217.17]],"ltp":1.3,"tv":11762.39,"id":16325787}],"tv":14123.13}]}
{"op":"mcm","clk":"995099092","pt":1580555360244,"mc":[{"id":"1.168133553","rc":[{"trd":[[1.32,4354.09]],"batl":[[0,1.32,2.54]],"ltp":1.32,"tv":11778.41,"id":16325787}],"tv":14139.15}]}
{"op":"mcm","clk":"995100730","pt":1580555368495,"mc":[{"id":"1.168133553","rc":[{"trd":[[5.5,226.35]],"batl":[[0,5.5,9.3]],"ltp":5.5,"tv":2026.84,"id":21641292}],"tv":14143.15}]}
{"op":"mcm","clk":"995105909","pt":1580555394546,"mc":[{"id":"1.168133553","rc":[{"trd":[[1.32,4359.17]],"batb":[[0,1.32,27.01],[1,1.3,217.17],[2,1.29,198.55]],"batl":[[0,1.33,1137.94],[1,1.34,1525.33],[2,1.35,1651.83]],"ltp":1.32,"tv":11783.49,"id":16325787}],"tv":14148.23}]}
{"op":"mcm","clk":"995106359","pt":1580555396557,"mc":[{"id":"1.168133553","rc":[{"batb":[[1,1.3,225.76]],"ltp":1.32,"tv":11783.49,"id":16325787}]}]}
{"op":"mcm","clk":"995115753","pt":1580555444428,"mc":[{"id":"1.168133553","rc":[{"trd":[[1.33,2156.7]],"batl":[[0,1.33,1130.1]],"ltp":1.33,"tv":11799.16,"id":16325787}],"tv":14163.91}]}
{"op":"mcm","clk":"995116333","pt":1580555447424,"mc":[{"id":"1.168133553","rc":[{"batb":[[1,1.31,100],[2,1.3,225.76]],"ltp":1.33,"tv":11799.16,"id":16325787}]}]}
{"op":"mcm","clk":"995124664","pt":1580555488257,"mc":[{"id":"1.168133553","rc":[{"batb":[[0,15.5,2.94],[1,15,1.45],[2,12.5,2.55]],"batl":[[0,23,10.46],[1,32,8.75],[2,34,1]],"ltp":17.0,"tv":337.89,"id":27227336},{"trd":[[1.33,2172.7]],"batl":[[0,1.33,1122.1]],"ltp":1.33,"tv":11815.16,"id":16325787}],"tv":14179.91}]}
{"op":"mcm","clk":"995129396","pt":1580555509421,"mc":[{"id":"1.168133553","rc":[{"trd":[[1.33,2181.56]],"batl":[[0,1.33,1117.67]],"ltp":1.33,"tv":11824.02,"id":16325787}],"tv":14188.77}]}
{"op":"mcm","clk":"995130286","pt":1580555513460,"mc":[{"id":"1.168133553","rc":[{"trd":[[5.1,104.69]],"batb":[[0,5,3.18],[1,4.8,8.46],[2,4.7,40.89]],"ltp":5.1,"tv":2030.84,"id":21641292}],"tv":14192.77}]}
{"op":"mcm","clk":"995133354","pt":1580555528368,"mc":[{"id":"1.168133553","rc":[{"batb":[[1,4.9,2],[2,4.8,8.46]],"ltp":5.1,"tv":2030.84,"id":21641292}]}]}
{"op":"mcm","clk":"995136865","pt":1580555544526,"mc":[{"id":"1.168133553","rc":[{"batb":[[0,5.1,3.92],[1,5,3.18],[2,4.9,2]],"ltp":5.1,"tv":2030.84,"id":21641292}]}]}
{"op":"mcm","clk":"995137311","pt":1580555546430,"mc":[{"id":"1.168133553","rc":[{"batl":[[1,32,13.22]],"ltp":17.0,"tv":337.89,"id":27227336}]}]}
{"op":"mcm","clk":"995138204","pt":1580555550551,"mc":[{"id":"1.168133553","rc":[{"batl":[[0,21,8.06],[1,23,10],[2,32,13.22]],"ltp":17.0,"tv":337.89,"id":27227336}]}]}
{"op":"mcm","clk":"995140134","pt":1580555559351,"mc":[{"id":"1.168133553","rc":[{"batb":[[0,5.1,5.92],[2,4.8,8.46]],"ltp":5.1,"tv":2030.84,"id":21641292}]}]}
{"op":"mcm","clk":"995141249","pt":1580555564554,"mc":[{"id":"1.168133553","rc":[{"trd":[[5.1,116.53]],"batb":[[0,5,3.18],[1,4.8,8.46],[2,4.7,40.89]],"batl":[[0,5.1,2.08],[1,5.5,9.3],[2,5.9,33.72]],"ltp":5.1,"tv":2042.68,"id":21641292}],"tv":14204.61}]}
{"op":"mcm","clk":"995146016","pt":1580555587514,"mc":[{"id":"1.168133553","rc":[{"batb":[[0,4.9,8.7]],"ltp":5.1,"tv":2042.68,"id":21641292}]}]}
{"op":"mcm","clk":"995148525","pt":1580555599538,"mc":[{"id":"1.168133553","rc":[{"batb":[[0,5,4.29],[1,4.9,8.7]],"ltp":5.1,"tv":2042.68,"id":21641292}]}]}
{"op":"mcm","clk":"995157810","pt":1580555645562,"mc":[{"id":"1.168133553","rc":[{"trd":[[19.5,6.23]],"ltp":19.5,"tv":338.41,"id":27227336},{"trd":[[5,135.57]],"batb":[[0,5,1.08]],"ltp":5.0,"tv":2049.09,"id":21641292}],"tv":14211.53}]}
{"op":"mcm","clk":"995158041","pt":1580555646548,"mc":[{"id":"1.168133553","rc":[{"batb":[[0,16,2.58],[1,15.5,2.94],[2,15,1.45]],"ltp":19.5,"tv":338.41,"id":27227336}]}]}
{"op":"mcm","clk":"995158269","pt":1580555647543,"mc":[{"id":"1.168133553","rc":[{"batb":[[0,19.5,1.74],[1,16,2.58]],"batl":[[0,20,2.95],[1,21,7.6],[2,23,10]],"ltp":19.5,"tv":338.41,"id":27227336}]}]}
{"op":"mcm","clk":"995158440","pt":1580555648561,"mc":[{"id":"1.168133553","rc":[{"batb":[[0,15,1.45],[1,12.5,2.55],[2,11,10.48]],"batl":[[0,20,3.21]],"ltp":19.5,"tv":338.41,"id":27227336}]}]}
{"op":"mcm","clk":"995158579","pt":1580555649365,"mc":[{"id":"1.168133553","rc":[{"batb":[[0,19.5,1.74],[1,15,1.45],[2,12.5,2.55]],"batl":[[0,20,2.95]],"ltp":19.5,"tv":338.41,"id":27227336}]}]}
{"op":"mcm","clk":"995158779","pt":1580555650571,"mc":[{"id":"1.168133553","rc":[{"batb":[[0,15,1.45],[1,12.5,2.55],[2,11,10.48]],"batl":[[0,20,3.21]],"ltp":19.5,"tv":338.41,"id":27227336}]}]}
{"op":"mcm","clk":"995158973","pt":1580555651550,"mc":[{"id":"1.168133553","rc":[{"batb":[[0,15.5,3.08],[1,15,1.45],[2,13,2.34]],"ltp":19.5,"tv":338.41,"id":27227336}]}]}
{"op":"mcm","clk":"995159173","pt":1580555652536,"mc":[{"id":"1.168133553","rc":[{"batb":[[0,15,1.45],[1,13,2.34],[2,12.5,2.54]],"ltp":19.5,"tv":338.41,"id":27227336},{"batb":[[0,5,4.92]],"ltp":5.0,"tv":2049.09,"id":21641292}]}]}
{"op":"mcm","clk":"995159584","pt":1580555654554,"mc":[{"id":"1.168133553","rc":[{"batb":[[1,12.5,2.55],[2,11,10.48]],"batl":[[0,20,2.95]],"ltp":19.5,"tv":338.41,"id":27227336}]}]}
{"op":"mcm","clk":"995159808","pt":1580555655542,"mc":[{"id":"1.168133553","rc":[{"trd":[[19,0.27]],"ltp":19.0,"tv":338.68,"id":27227336},{"trd":[[5.1,119.68]],"batl":[[0,5.5,9.3],[1,5.9,33.72],[2,6,10]],"ltp":5.1,"tv":2052.24,"id":21641292},{"trd":[[1.33,2185.42]],"batl":[[0,1.33,1113.81]],"ltp":1.33,"tv":11827.88,"id":16325787}],"tv":14218.81}]}
{"op":"mcm","clk":"995160237","pt":1580555657551,"mc":[{"id":"1.168133553","rc":[{"batl":[[0,20,2.75]],"ltp":19.0,"tv":338.68,"id":27227336}]}]}
{"op":"mcm","clk":"995160251","pt":1580555657661,"mc":[{"id":"1.168133553","rc":[{"batl":[[0,20,2.95]],"ltp":19.0,"tv":338.68,"id":27227336}]}]}
{"op":"mcm","clk":"995164488","pt":1580555678462,"mc":[{"id":"1.168133553","rc":[{"trd":[[5,141.97]],"batb":[[0,5,1.72]],"ltp":5.0,"tv":2058.64,"id":21641292},{"trd":[[1.33,2201.42]],"batl":[[0,1.33,1105.81]],"ltp":1.33,"tv":11843.88,"id":16325787}],"tv":14241.21}]}
{"op":"mcm","clk":"995165462","pt":1580555683462,"mc":[{"id":"1.168133553","rc":[{"batb":[[2,4.8,2]],"ltp":5.0,"tv":2058.64,"id":21641292}]}]}
{"op":"mcm","clk":"995170323","pt":1580555707523,"mc":[{"id":"1.168133553","rc":[{"trd":[[1.32,4379.17]],"batb":[[0,1.32,17.01]],"ltp":1.32,"tv":11863.88,"id":16325787}],"tv":14261.21}]}
{"op":"mcm","clk":"995170527","pt":1580555708492,"mc":[{"id":"1.168133553","rc":[{"batb":[[2,1.3,217.17]],"ltp":1.32,"tv":11863.88,"id":16325787}]}]}
{"op":"mcm","clk":"995171524","pt":1580555713519,"mc":[{"id":"1.168133553","rc":[{"batb":[[1,4.9,10.7],[2,4.7,40.89]],"ltp":5.0,"tv":2058.64,"id":21641292}]}]}
{"op":"mcm","clk":"995173370","pt":1580555723347,"mc":[{"id":"1.168133553","rc":[{"batb":[[1,4.9,8.7],[2,4.8,2]],"ltp":5.0,"tv":2058.64,"id":21641292}]}]}
{"op":"mcm","clk":"995174034","pt":1580555726553,"mc":[{"id":"1.168133553","rc":[{"trd":[[1.32,4381.17]],"batb":[[0,1.32,16.01],[1,1.31,101]],"ltp":1.32,"tv":11865.88,"id":16325787}],"tv":14263.21}]}
{"op":"mcm","clk":"995174417","pt":1580555728534,"mc":[{"id":"1.168133553","rc":[{"trd":[[1.32,4385.17]],"batb":[[0,1.32,14.01]],"ltp":1.32,"tv":11869.88,"id":16325787}],"tv":14267.21}]}
{"op":"mcm","clk":"995179545","pt":1580555753567,"mc":[{"id":"1.168133553","rc":[{"batb":[[1,4.9,10.7],[2,4.7,40.89]],"ltp":5.0,"tv":2058.64,"id":21641292}]}]}
{"op":"mcm","clk":"995184135","pt":1580555775491,"mc":[{"id":"1.168133553","rc":[{"batl":[[1,23,10],[2,32,13.22]],"ltp":19.0,"tv":338.68,"id":27227336}]}]}
{"op":"mcm","clk":"995188704","pt":1580555797563,"mc":[{"id":"1.168133553","rc":[{"batb":[[0,15.5,1.11],[1,15,1.45],[2,12.5,2.55]],"ltp":19.0,"tv":338.68,"id":27227336},{"trd":[[1.33,2217.42]],"batl":[[0,1.33,1097.81]],"ltp":1.33,"tv":11885.88,"id":16325787}],"tv":14283.21}]}
{"op":"mcm","clk":"995191545","pt":1580555810512,"mc":[{"id":"1.168133553","rc":[{"trd":[[19.5,6.3]],"batl":[[0,20,2.88]],"ltp":19.5,"tv":338.75,"id":27227336},{"trd":[[5,145.69]],"batb":[[0,4.9,10.7],[1,4.7,40.89],[2,4.4,3.61]],"ltp":5.0,"tv":2062.36,"id":21641292},{"trd":[[1.33,2218.47]],"batl":[[0,1.33,1096.76]],"ltp":1.33,"tv":11886.93,"id":16325787}],"tv":14288.05}]}
{"op":"mcm","clk":"995191763","pt":1580555811489,"mc":[{"id":"1.168133553","rc":[{"batl":[[0,5.4,12],[1,5.5,9.3],[2,5.9,33.72]],"ltp":5.0,"tv":2062.36,"id":21641292}]}]}
{"op":"mcm","clk":"995192913","pt":1580555815930,"mc":[{"id":"1.168133553","rc":[{"batb":[[2,4.5,9.03]],"batl":[[0,5.3,7.66],[1,5.4,12],[2,5.5,9.3]],"ltp":5.0,"tv":2062.36,"id":21641292}]}]}
{"op":"mcm","clk":"995196650","pt":1580555832468,"mc":[{"id":"1.168133553","rc":[{"batb":[[0,17.5,2.84],[1,17,4.82],[2,15.5,1.11]],"batl":[[0,23,10.13],[1,32,13.22],[2,34,1]],"ltp":19.5,"tv":338.75,"id":27227336},{"batb":[[0,4.9,8.7],[1,4.8,2],[2,4.7,40.89]],"ltp":5.0,"tv":2062.36,"id":21641292}]}]}
{"op":"mcm","clk":"995197641","pt":1580555837466,"mc":[{"id":"1.168133553","rc":[{"batl":[[0,23,10]],"ltp":19.5,"tv":338.75,"id":27227336}]}]}
{"op":"mcm","clk":"995198685","pt":1580555842279,"mc":[{"id":"1.168133553","rc":[{"batb":[[0,4.9,10.7],[1,4.7,40.89],[2,4.5,9.03]],"ltp":5.0,"tv":2062.36,"id":21641292}]}]}
{"op":"mcm","clk":"995199822","pt":1580555847468,"mc":[{"id":"1.168133553","rc":[{"batl":[[1,32,8.85]],"ltp":19.5,"tv":338.75,"id":27227336}]}]}
{"op":"mcm","clk":"995200986","pt":1580555852493,"mc":[{"id":"1.168133553","rc":[{"batb":[[0,4.9,8.7],[1,4.8,2],[2,4.7,40.89]],"ltp":5.0,"tv":2062.36,"id":21641292}]}]}
{"op":"mcm","clk":"995203484","pt":1580555862503,"mc":[{"id":"1.168133553","rc":[{"batb":[[0,4.9,10.7],[1,4.7,40.89],[2,4.5,9.03]],"ltp":5.0,"tv":2062.36,"id":21641292}]}]}
{"op":"mcm","clk":"995207912","pt":1580555882486,"mc":[{"id":"1.168133553","rc":[{"batb":[[0,4.9,8.7],[1,4.8,2],[2,4.7,40.89]],"ltp":5.0,"tv":2062.36,"id":21641292}]}]}
{"op":"mcm","clk":"995214745","pt":1580555912542,"mc":[{"id":"1.168133553","rc":[{"batb":[[0,4.9,10.7],[1,4.7,40.89],[2,4.5,9.03]],"ltp":5.0,"tv":2062.36,"id":21641292}]}]}
{"op":"mcm","clk":"995218911","pt":1580555932543,"mc":[{"id":"1.168133553","rc":[{"batb":[[0,4.9,8.7],[1,4.8,2],[2,4.7,40.89]],"ltp":5.0,"tv":2062.36,"id":21641292}]}]}
{"op":"mcm","clk":"995220918","pt":1580555942554,"mc":[{"id":"1.168133553","rc":[{"batb":[[1,4.7,40.89],[2,4.5,9.03]],"ltp":5.0,"tv":2062.36,"id":21641292}]}]}
{"op":"mcm","clk":"995221044","pt":1580555943197,"mc":[{"id":"1.168133553","rc":[{"batb":[[0,4.9,10.7]],"ltp":5.0,"tv":2062.36,"id":21641292}]}]}
{"op":"mcm","clk":"995222097","pt":1580555948478,"mc":[{"id":"1.168133553","rc":[{"trd":[[1.32,4389.17]],"batb":[[0,1.32,12.01]],"ltp":1.32,"tv":11890.93,"id":16325787}],"tv":14292.05}]}
{"op":"mcm","clk":"995223336","pt":1580555954510,"mc":[{"id":"1.168133553","rc":[{"batl":[[0,5,10],[1,5.3,7.66],[2,5.4,12]],"ltp":5.0,"tv":2062.36,"id":21641292}]}]}
{"op":"mcm","clk":"995223694","pt":1580555956405,"mc":[{"id":"1.168133553","rc":[{"batb":[[1,4.5,9.03],[2,4.4,3.61]],"ltp":5.0,"tv":2062.36,"id":21641292}]}]}
{"op":"mcm","clk":"995228820","pt":1580555982570,"mc":[{"id":"1.168133553","rc":[{"batb":[[1,4.4,3.61],[2,4.3,6]],"batl":[[1,5.4,12],[2,5.5,9.3]],"ltp":5.0,"tv":2062.36,"id":21641292}]}]}
{"op":"mcm","clk":"995228995","pt":1580555983497,"mc":[{"id":"1.168133553","rc":[{"trd":[[1.32,4389.31]],"batb":[[0,1.32,11.94]],"ltp":1.32,"tv":11891.07,"id":16325787}],"tv":14292.19}]}
{"op":"mcm","clk":"995229670","pt":1580555986464,"mc":[{"id":"1.168133553","rc":[{"trd":[[20,24.68]],"batl":[[0,23,10.63]],"ltp":20.0,"tv":341.25,"id":27227336},{"trd":[[5,155.69]],"batb":[[0,4.9,2]],"batl":[[0,5.4,12],[1,5.5,9.3],[2,5.9,2.85]],"ltp":5.0,"tv":2072.36,"id":21641292},{"trd":[[1.33,2256.06]],"batl":[[0,1.33,1059.17]],"ltp":1.33,"tv":11928.66,"id":16325787}],"tv":14342.28}]}
{"op":"mcm","clk":"995229766","pt":1580555986900,"mc":[{"id":"1.168133553","rc":[{"batl":[[1,5.5,12.17]],"ltp":5.0,"tv":2072.36,"id":21641292}]}]}
{"op":"mcm","clk":"995231732","pt":1580555996470,"mc":[{"id":"1.168133553","rc":[{"batb":[[1,4.7,40.89],[2,4.4,3.61]],"ltp":5.0,"tv":2072.36,"id":21641292}]}]}
{"op":"mcm","clk":"995232931","pt":1580556002371,"mc":[{"id":"1.168133553","rc":[{"batl":[[1,5.5,9.3]],"ltp":5.0,"tv":2072.36,"id":21641292}]}]}
{"op":"mcm","clk":"995233795","pt":1580556006529,"mc":[{"id":"1.168133553","rc":[{"batl":[[2,5.9,33.72]],"ltp":5.0,"tv":2072.36,"id":21641292}]}]}
{"op":"mcm","clk":"995235485","pt":1580556014435,"mc":[{"id":"1.168133553","rc":[{"batl":[[0,5.3,7.66],[1,5.4,12],[2,5.5,9.3]],"ltp":5.0,"tv":2072.36,"id":21641292}]}]}
{"op":"mcm","clk":"995236868","pt":1580556021016,"mc":[{"id":"1.168133553","rc":[{"batb":[[0,4.8,2]],"ltp":5.0,"tv":2072.36,"id":21641292}]}]}
{"op":"mcm","clk":"995239370","pt":1580556033550,"mc":[{"id":"1.168133553","rc":[{"batb":[[2,1.3,217.27]],"ltp":1.33,"tv":11928.66,"id":16325787}]}]}
{"op":"mcm","clk":"995240370","pt":1580556038376,"mc":[{"id":"1.168133553","rc":[{"batb":[[0,4.8,2.2]],"ltp":5.0,"tv":2072.36,"id":21641292}]}]}
{"op":"mcm","clk":"995241219","pt":1580556042405,"mc":[{"id":"1.168133553","rc":[{"batb":[[2,4.4,3.71]],"ltp":5.0,"tv":2072.36,"id":21641292}]}]}
{"op":"mcm","clk":"995242205","pt":1580556047415,"mc":[{"id":"1.168133553","rc":[{"batb":[[0,4.8,10.66]],"ltp":5.0,"tv":2072.36,"id":21641292}]}]}
{"op":"mcm","clk":"995247622","pt":1580556074244,"mc":[{"id":"1.168133553","rc":[{"trd":[[1.33,2276.06]],"batl":[[0,1.33,1049.17]],"ltp":1.33,"tv":11948.66,"id":16325787}],"tv":14362.28}]}
{"op":"mcm","clk":"995247913","pt":1580556075524,"mc":[{"id":"1.168133553","rc":[{"trd":[[20,25.31]],"batl":[[0,23,10]],"ltp":20.0,"tv":341.88,"id":27227336},{"trd":[[4.8,37.84],[4.9,43.81],[5,158.41]],"batb":[[0,4.8,5.16]],"ltp":4.8,"tv":2085.88,"id":21641292},{"trd":[[1.33,2285.53]],"batl":[[0,1.33,1039.7]],"ltp":1.33,"tv":11958.13,"id":16325787}],"tv":14385.9}]}
{"op":"mcm","clk":"995252556","pt":1580556099205,"mc":[{"id":"1.168133553","rc":[{"batb":[[0,4.8,7.16]],"ltp":4.8,"tv":2085.88,"id":21641292}]}]}
{"op":"mcm","clk":"995254273","pt":1580556108517,"mc":[{"id":"1.168133553","rc":[{"trd":[[4.8,49.06]],"batb":[[0,4.8,1.55]],"ltp":4.8,"tv":2097.1,"id":21641292}],"tv":14397.12}]}
{"op":"mcm","clk":"995258242","pt":1580556129429,"mc":[{"id":"1.168133553","rc":[{"batb":[[0,4.7,40.89],[1,4.5,1.65],[2,4.4,3.61]],"ltp":4.8,"tv":2097.1,"id":21641292}]}]}
{"op":"mcm","clk":"995274972","pt":1580556158459,"mc":[{"id":"1.168133553","rc":[{"batb":[[0,17.5,3.82],[2,15,1.45]],"ltp":20.0,"tv":341.88,"id":27227336}]}]}
{"op":"mcm","clk":"995278987","pt":1580556179527,"mc":[{"id":"1.168133553","rc":[{"trd":[[1.33,2292.49]],"batl":[[0,1.33,1036.22]],"ltp":1.33,"tv":11965.09,"id":16325787}],"tv":14404.08}]}
{"op":"mcm","clk":"995280422","pt":1580556186651,"mc":[{"id":"1.168133553","rc":[{"trd":[[23,1.06]],"batl":[[0,23,8.94]],"ltp":23.0,"tv":342.94,"id":27227336},{"trd":[[4.8,54.12]],"ltp":4.8,"tv":2102.16,"id":21641292},{"trd":[[1.33,2310.79]],"batl":[[0,1.33,1017.92]],"ltp":1.33,"tv":11983.39,"id":16325787}],"tv":14428.5}]}
{"op":"mcm","clk":"995281674","pt":1580556193484,"mc":[{"id":"1.168133553","rc":[{"batl":[[2,5.5,18.8]],"ltp":4.8,"tv":2102.16,"id":21641292}]}]}
{"op":"mcm","clk":"995282831","pt":1580556199481,"mc":[{"id":"1.168133553","rc":[{"batb":[[0,18,2.38],[1,17.5,3.82],[2,17,4.82]],"ltp":23.0,"tv":342.94,"id":27227336}]}]}
{"op":"mcm","clk":"995283606","pt":1580556203571,"mc":[{"id":"1.168133553","rc":[{"trd":[[1.33,2359.67]],"batl":[[0,1.33,993.48]],"ltp":1.33,"tv":12032.27,"id":16325787}],"tv":14477.38}]}
{"op":"mcm","clk":"995287166","pt":1580556221504,"mc":[{"id":"1.168133553","rc":[{"trd":[[18,40.82]],"batb":[[0,17.5,4.2],[1,17,4.82],[2,15,1.45]],"ltp":18.0,"tv":346.94,"id":27227336}],"tv":14481.38}]}
{"op":"mcm","clk":"995287756","pt":1580556224527,"mc":[{"id":"1.168133553","rc":[{"batl":[[0,22,1.64],[1,23,8.94],[2,32,8.85]],"ltp":18.0,"tv":346.94,"id":27227336}]}]}
{"op":"mcm","clk":"995290821","pt":1580556239530,"mc":[{"id":"1.168133553","rc":[{"batl":[[2,32,13.33]],"ltp":18.0,"tv":346.94,"id":27227336}]}]}
{"op":"mcm","clk":"995292174","pt":1580556246298,"mc":[{"id":"1.168133553","rc":[{"batl":[[0,22,2.36]],"ltp":18.0,"tv":346.94,"id":27227336}]}]}
{"op":"mcm","clk":"995293610","pt":1580556253123,"mc":[{"id":"1.168133553","rc":[{"batl":[[2,32,8.85]],"ltp":18.0,"tv":346.94,"id":27227336}]}]}
{"op":"mcm","clk":"995313746","pt":1580556351431,"mc":[{"id":"1.168133553","rc":[{"trd":[[1.32,4413.19]],"batb":[[0,1.31,101],[1,1.3,217.27],[2,1.29,198.65]],"batl":[[0,1.32,8.06],[1,1.33,993.48],[2,1.34,1525.33]],"ltp":1.32,"tv":12056.15,"id":16325787}],"tv":14505.26}]}
{"op":"mcm","clk":"995315103","pt":1580556358438,"mc":[{"id":"1.168133553","rc":[{"batl":[[1,5.5,18.8],[2,5.9,33.72]],"ltp":4.8,"tv":2102.16,"id":21641292}]}]}
{"op":"mcm","clk":"995315219","pt":1580556359137,"mc":[{"id":"1.168133553","rc":[{"batb":[[0,4.8,8.82],[1,4.7,40.89],[2,4.5,1.65]],"batl":[[0,5.2,12],[1,5.3,7.66],[2,5.5,18.8]],"ltp":4.8,"tv":2102.16,"id":21641292}]}]}
{"op":"mcm","clk":"995317084","pt":1580556368555,"mc":[{"id":"1.168133553","rc":[{"batb":[[1,4.5,1.65],[2,4.4,3.61]],"ltp":4.8,"tv":2102.16,"id":21641292}]}]}
{"op":"mcm","clk":"995320867","pt":1580556387382,"mc":[{"id":"1.168133553","rc":[{"batb":[[2,1.29,203.65]],"batl":[[0,1.32,13.06]],"ltp":1.32,"tv":12056.15,"id":16325787}]}]}
{"op":"mcm","clk":"995321098","pt":1580556388510,"mc":[{"id":"1.168133553","rc":[{"trd":[[1.31,2181.79],[1.32,4419.15]],"batb":[[0,1.31,98]],"batl":[[0,1.32,10.08]],"ltp":1.32,"tv":12068.11,"id":16325787}],"tv":14517.22}]}
{"op":"mcm","clk":"995321525","pt":1580556390510,"mc":[{"id":"1.168133553","rc":[{"batl":[[1,5.5,18.8],[2,5.9,2.85]],"ltp":4.8,"tv":2102.16,"id":21641292}]}]}
{"op":"mcm","clk":"995321634","pt":1580556391014,"mc":[{"id":"1.168133553","rc":[{"batl":[[0,5.1,4.91],[1,5.2,12],[2,5.5,18.8]],"ltp":4.8,"tv":2102.16,"id":21641292}]}]}
{"op":"mcm","clk":"995329886","pt":1580556432520,"mc":[{"id":"1.168133553","rc":[{"trd":[[21,0.63]],"batb":[[0,17.5,1.36],[1,15,1.45],[2,14.5,17.01]],"batl":[[0,21,2.08],[1,22,2.36],[2,23,8.94]],"ltp":21.0,"tv":347.57,"id":27227336},{"trd":[[5.1,122.29]],"batl":[[0,5.1,2.3]],"ltp":5.1,"tv":2104.78,"id":21641292},{"trd":[[1.32,4429.23]],"batl":[[0,1.33,993.48],[1,1.34,1525.33],[2,1.35,1651.83]],"ltp":1.32,"tv":12078.19,"id":16325787}],"tv":14530.55}]}
{"op":"mcm","clk":"995330012","pt":1580556433262,"mc":[{"id":"1.168133553","rc":[{"batb":[[1,15.5,5.02],[2,15,1.45]],"batl":[[0,21,12.08]],"ltp":21.0,"tv":347.57,"id":27227336}]}]}
{"op":"mcm","clk":"995334187","pt":1580556454463,"mc":[{"id":"1.168133553","rc":[{"batb":[[0,15.5,6.01],[1,15,1.45],[2,13,19.01]],"batl":[[0,20,1.8],[1,21,12.08],[2,23,9.66]],"ltp":21.0,"tv":347.57,"id":27227336}]}]}
{"op":"mcm","clk":"995334300","pt":1580556454958,"mc":[{"id":"1.168133553","rc":[{"batb":[[0,15,2.43],[1,13,19.01],[2,12.5,13.02]],"ltp":21.0,"tv":347.57,"id":27227336}]}]}
{"op":"mcm","clk":"995334830","pt":1580556457484,"mc":[{"id":"1.168133553","rc":[{"trd":[[20,25.84]],"batl":[[0,20,1.27]],"ltp":20.0,"tv":348.1,"id":27227336},{"trd":[[5.1,124.82]],"batl":[[0,5.2,12],[1,5.5,18.8],[2,5.9,2.85]],"ltp":5.1,"tv":2107.31,"id":21641292},{"trd":[[1.32,4437.23]],"ltp":1.32,"tv":12086.19,"id":16325787}],"tv":14541.61}]}
{"op":"mcm","clk":"995335581","pt":1580556461496,"mc":[{"id":"1.168133553","rc":[{"batl":[[2,23,8.94]],"ltp":20.0,"tv":348.1,"id":27227336}]}]}
{"op":"mcm","clk":"995335923","pt":1580556463216,"mc":[{"id":"1.168133553","rc":[{"batl":[[0,1.32,2],[1,1.33,993.48],[2,1.34,1525.33]],"ltp":1.32,"tv":12086.19,"id":16325787}]}]}
{"op":"mcm","clk":"995336544","pt":1580556466505,"mc":[{"id":"1.168133553","rc":[{"batb":[[1,12.5,13.03],[2,10.5,25.98]],"ltp":20.0,"tv":348.1,"id":27227336}]}]}
{"op":"mcm","clk":"995340324","pt":1580556485530,"mc":[{"id":"1.168133553","rc":[{"batb":[[1,12.5,7.84],[2,11,5.19]],"ltp":20.0,"tv":348.1,"id":27227336}]}]}
{"op":"mcm","clk":"995341584","pt":1580556491508,"mc":[{"id":"1.168133553","rc":[{"batb":[[1,12.5,2.55],[2,11,10.48]],"ltp":20.0,"tv":348.1,"id":27227336}]}]}
{"op":"mcm","clk":"995341806","pt":1580556492516,"mc":[{"id":"1.168133553","rc":[{"batl":[[1,5.4,2.88],[2,5.5,18.8]],"ltp":5.1,"tv":2107.31,"id":21641292}]}]}
{"op":"mcm","clk":"995342609","pt":1580556496512,"mc":[{"id":"1.168133553","rc":[{"batb":[[1,12.5,22.55]],"ltp":20.0,"tv":348.1,"id":27227336}]}]}
{"op":"mcm","clk":"995345958","pt":1580556512538,"mc":[{"id":"1.168133553","rc":[{"batl":[[0,5.2,52]],"ltp":5.1,"tv":2107.31,"id":21641292}]}]}
{"op":"mcm","clk":"995346205","pt":1580556513505,"mc":[{"id":"1.168133553","rc":[{"batb":[[0,4.5,1.65],[1,4.4,3.61],[2,4.3,58]],"ltp":5.1,"tv":2107.31,"id":21641292}]}]}
{"op":"mcm","clk":"995348052","pt":1580556522536,"mc":[{"id":"1.168133553","rc":[{"batl":[[1,5.4,17.47]],"ltp":5.1,"tv":2107.31,"id":21641292}]}]}
{"op":"mcm","clk":"995348992","pt":1580556526563,"mc":[{"id":"1.168133553","rc":[{"batb":[[0,4.5,7.22]],"batl":[[1,5.4,22.12]],"ltp":5.1,"tv":2107.31,"id":21641292}]}]}
{"op":"mcm","clk":"995352271","pt":1580556542574,"mc":[{"id":"1.168133553","rc":[{"trd":[[17.5,20.34],[19.5,6.44]],"batb":[[0,15,1.45]],"batl":[[0,17.5,27.58],[1,20,1.27],[2,21,12.08]],"ltp":17.5,"tv":365.5,"id":27227336},{"trd":[[5.2,144.92]],"batb":[[0,4.6,9.09],[1,4.5,7.22],[2,4.4,3.61]],"batl":[[0,5.4,7.53],[1,5.5,18.8],[2,5.9,2.85]],"ltp":5.2,"tv":2159.31,"id":21641292},{"trd":[[1.32,4439.23],[1.33,2560.98]],"batl":[[0,1.33,792.17],[1,1.34,1525.33],[2,1.35,1651.83]],"ltp":1.33,"tv":12289.5,"id":16325787}],"tv":14814.32}]}
{"op":"mcm","clk":"995353351","pt":1580556547503,"mc":[{"id":"1.168133553","rc":[{"batl":[[1,21,12.08],[2,23,8.94]],"ltp":17.5,"tv":365.5,"id":27227336}]}]}
{"op":"mcm","clk":"995355103","pt":1580556556514,"mc":[{"id":"1.168133553","rc":[{"batb":[[1,12.5,2.55]],"ltp":17.5,"tv":365.5,"id":27227336}]}]}
{"op":"mcm","clk":"995355872","pt":1580556560207,"mc":[{"id":"1.168133553","rc":[{"batb":[[0,4.7,4.07],[1,4.6,9.09],[2,4.5,1.65]],"ltp":5.2,"tv":2159.31,"id":21641292}]}]}
{"op":"mcm","clk":"995358567","pt":1580556572512,"mc":[{"id":"1.168133553","rc":[{"trd":[[1.31,2186.03]],"batb":[[0,1.31,95.88]],"ltp":1.31,"tv":12293.74,"id":16325787}],"tv":14818.56}]}
{"op":"mcm","clk":"995364170","pt":1580556598476,"mc":[{"id":"1.168133553","rc":[{"batb":[[0,4.7,5.62],[2,4.4,3.71]],"ltp":5.2,"tv":2159.31,"id":21641292}]}]}
{"op":"mcm","clk":"995367256","pt":1580556612483,"mc":[{"id":"1.168133553","rc":[{"trd":[[1.31,2198.03]],"batb":[[0,1.31,89.88]],"ltp":1.31,"tv":12305.74,"id":16325787}],"tv":14830.56}]}
{"op":"mcm","clk":"995367438","pt":1580556613414,"mc":[{"id":"1.168133553","rc":[{"batb":[[0,1.32,13.05],[1,1.31,89.88],[2,1.3,217.27]],"ltp":1.31,"tv":12305.74,"id":16325787}]}]}
{"op":"mcm","clk":"995406759","pt":1580556795474,"mc":[{"id":"1.168133553","rc":[{"batb":[[2,11,5.29]],"ltp":17.5,"tv":365.5,"id":27227336}]}]}
{"op":"mcm","clk":"995410647","pt":1580556813340,"mc":[{"id":"1.168133553","rc":[{"batb":[[2,10.5,1.98]],"ltp":17.5,"tv":365.5,"id":27227336}]}]}
{"op":"mcm","clk":"995418935","pt":1580556852540,"mc":[{"id":"1.168133553","rc":[{"trd":[[1.31,2204.87],[1.32,4465.33]],"batb":[[0,1.31,86.46],[1,1.3,217.27],[2,1.29,203.65]],"ltp":1.31,"tv":12338.68,"id":16325787}],"tv":14863.5}]}
{"op":"mcm","clk":"995419814","pt":1580556856557,"mc":[{"id":"1.168133553","rc":[{"batb":[[1,1.3,222.27]],"batl":[[0,1.33,797.17]],"ltp":1.31,"tv":12338.68,"id":16325787}]}]}
{"op":"mcm","clk":"995422238","pt":1580556868561,"mc":[{"id":"1.168133553","rc":[{"trd":[[1.31,2217.82]],"batb":[[0,1.31,79.99]],"batl":[[0,1.32,11.82],[1,1.33,797.17],[2,1.34,1525.33]],"ltp":1.31,"tv":12351.63,"id":16325787}],"tv":14876.44}]}
{"op":"mcm","clk":"995422439","pt":1580556869469,"mc":[{"id":"1.168133553","rc":[{"batl":[[0,1.33,797.17],[1,1.34,1525.33],[2,1.35,1651.83]],"ltp":1.31,"tv":12351.63,"id":16325787}]}]}
{"op":"mcm","clk":"995424054","pt":1580556877278,"mc":[{"id":"1.168133553","rc":[{"trd":[[17.5,23.31]],"batl":[[0,17.5,24.61]],"ltp":17.5,"tv":368.47,"id":27227336},{"trd":[[5.2,154.92]],"ltp":5.2,"tv":2169.31,"id":21641292},{"trd":[[1.33,2600.08]],"batl":[[0,1.33,758.07]],"ltp":1.33,"tv":12390.73,"id":16325787}],"tv":14928.51}]}
{"op":"mcm","clk":"995431108","pt":1580556910563,"mc":[{"id":"1.168133553","rc":[{"trd":[[17.5,28.3]],"batl":[[0,17.5,19.62]],"ltp":17.5,"tv":373.46,"id":27227336},{"trd":[[5.2,171.72]],"ltp":5.2,"tv":2186.11,"id":21641292},{"trd":[[1.33,2665.78]],"batl":[[0,1.33,692.37]],"ltp":1.33,"tv":12456.43,"id":16325787}],"tv":15016.01}]}
{"op":"mcm","clk":"995431580","pt":1580556912553,"mc":[{"id":"1.168133553","rc":[{"trd":[[1.33,2669.78]],"batl":[[0,1.33,690.37]],"ltp":1.33,"tv":12460.43,"id":16325787}],"tv":15020.01}]}
{"op":"mcm","clk":"995443624","pt":1580556968563,"mc":[{"id":"1.168133553","rc":[{"trd":[[1.33,2679.78]],"batl":[[0,1.33,685.37]],"ltp":1.33,"tv":12470.43,"id":16325787}],"tv":15030.01}]}
{"op":"mcm","clk":"995454419","pt":1580557019541,"mc":[{"id":"1.168133553","rc":[{"trd":[[1.31,2237.74]],"batb":[[0,1.31,70.03]],"ltp":1.31,"tv":12490.35,"id":16325787}],"tv":15049.93}]}
{"op":"mcm","clk":"995456534","pt":1580557029563,"mc":[{"id":"1.168133553","rc":[{"trd":[[1.31,2265.56]],"batb":[[0,1.31,56.12]],"ltp":1.31,"tv":12518.17,"id":16325787}],"tv":15077.75}]}
{"op":"mcm","clk":"995479184","pt":1580557087565,"mc":[{"id":"1.168133553","rc":[{"batb":[[0,15.5,1.11],[1,15,1.45],[2,12.5,2.55]],"ltp":17.5,"tv":373.46,"id":27227336},{"batb":[[0,5.3,3.25],[1,4.7,5.62],[2,4.6,9.09]],"ltp":5.2,"tv":2186.11,"id":21641292}]}]}
{"op":"mcm","clk":"995482265","pt":1580557102459,"mc":[{"id":"1.168133553","rc":[{"trd":[[1.33,2689.94]],"batl":[[0,1.33,680.29]],"ltp":1.33,"tv":12528.33,"id":16325787}],"tv":15087.91}]}
{"op":"mcm","clk":"995482480","pt":1580557103469,"mc":[{"id":"1.168133553","rc":[{"batb":[[1,4.7,1.55]],"batl":[[0,5.5,18.8],[1,5.9,2.85],[2,6.8,39]],"ltp":5.2,"tv":2186.11,"id":21641292}]}]}
{"op":"mcm","clk":"995482656","pt":1580557104377,"mc":[{"id":"1.168133553","rc":[{"batl":[[0,5.4,2.88],[1,5.5,18.8],[2,5.9,2.85]],"ltp":5.2,"tv":2186.11,"id":21641292}]}]}
{"op":"mcm","clk":"995489743","pt":1580557138493,"mc":[{"id":"1.168133553","rc":[{"batl":[[0,5.5,18.8],[1,5.9,2.85],[2,6.8,39]],"ltp":5.2,"tv":2186.11,"id":21641292}]}]}
{"op":"mcm","clk":"995489901","pt":1580557139292,"mc":[{"id":"1.168133553","rc":[{"batb":[[2,13,4.47]],"ltp":17.5,"tv":373.46,"id":27227336},{"trd":[[5.3,112.7]],"batb":[[0,4.7,2.39],[1,4.6,9.09],[2,4.4,60.71]],"batl":[[1,5.8,2.68],[2,5.9,5.35]],"ltp":5.3,"tv":2190.93,"id":21641292},{"trd":[[1.33,2707.94]],"batl":[[0,1.33,671.29]],"ltp":1.33,"tv":12546.33,"id":16325787}],"tv":15110.73}]}
{"op":"mcm","clk":"995490141","pt":1580557140525,"mc":[{"id":"1.168133553","rc":[{"batb":[[0,4.9,10.99],[1,4.7,1.55],[2,4.6,9.09]],"batl":[[2,5.9,2.85]],"ltp":5.3,"tv":2190.93,"id":21641292}]}]}
{"op":"mcm","clk":"995491559","pt":1580557147531,"mc":[{"id":"1.168133553","rc":[{"trd":[[17.5,28.64]],"batl":[[0,17.5,19.28]],"ltp":17.5,"tv":373.8,"id":27227336},{"trd":[[5.2,172.88],[5.3,114.38]],"batb":[[0,4.9,10.15]],"ltp":5.2,"tv":2193.77,"id":21641292},{"trd":[[1.31,2273.56],[1.33,2712.48]],"batb":[[0,1.31,52.12]],"batl":[[0,1.33,666.75]],"ltp":1.31,"tv":12558.87,"id":16325787}],"tv":15126.45}]}
{"op":"mcm","clk":"995491769","pt":1580557148542,"mc":[{"id":"1.168133553","rc":[{"trd":[[17.5,29.82]],"batl":[[0,17.5,18.1]],"ltp":17.5,"tv":374.98,"id":27227336},{"trd":[[5.2,176.88]],"ltp":5.2,"tv":2197.77,"id":21641292},{"trd":[[1.31,2281.56],[1.33,2728.12]],"batb":[[0,1.31,48.12]],"batl":[[0,1.33,651.11]],"ltp":1.33,"tv":12582.51,"id":16325787}],"tv":15155.27}]}
{"op":"mcm","clk":"995492824","pt":1580557153324,"mc":[{"id":"1.168133553","rc":[{"trd":[[17.5,35.73]],"batl":[[0,17.5,12.19]],"ltp":17.5,"tv":380.89,"id":27227336},{"trd":[[5.3,133.88]],"ltp":5.3,"tv":2217.27,"id":21641292},{"trd":[[1.32,4543.63]],"batl":[[0,1.32,2.2],[1,1.33,651.11],[2,1.34,1525.33]],"ltp":1.32,"tv":12660.81,"id":16325787}],"tv":15258.98}]}
{"op":"mcm","clk":"995496474","pt":1580557171385,"mc":[{"id":"1.168133553","rc":[{"batl":[[1,5.8,6.71]],"ltp":5.3,"tv":2217.27,"id":21641292}]}]}
{"op":"mcm","clk":"995497495","pt":1580557176391,"mc":[{"id":"1.168133553","rc":[{"trd":[[1.32,4548.03]],"batl":[[0,1.33,651.11],[1,1.34,1525.33],[2,1.35,1651.83]],"ltp":1.32,"tv":12665.21,"id":16325787}],"tv":15263.38}]}
{"op":"mcm","clk":"995503660","pt":1580557206569,"mc":[{"id":"1.168133553","rc":[{"batb":[[0,5,4.67],[1,4.9,10.15],[2,4.7,1.55]],"ltp":5.3,"tv":2217.27,"id":21641292}]}]}
{"op":"mcm","clk":"995505500","pt":1580557215541,"mc":[{"id":"1.168133553","rc":[{"batl":[[0,5.5,30.8]],"ltp":5.3,"tv":2217.27,"id":21641292}]}]}
{"op":"mcm","clk":"995506107","pt":1580557218488,"mc":[{"id":"1.168133553","rc":[{"batb":[[0,5,6.22],[2,4.6,9.09]],"ltp":5.3,"tv":2217.27,"id":21641292}]}]}
{"op":"mcm","clk":"995506481","pt":1580557220396,"mc":[{"id":"1.168133553","rc":[{"batl":[[1,5.7,7.32],[2,5.8,6.71]],"ltp":5.3,"tv":2217.27,"id":21641292}]}]}
{"op":"mcm","clk":"995507508","pt":1580557225378,"mc":[{"id":"1.168133553","rc":[{"batb":[[2,1.29,254.65]],"ltp":1.32,"tv":12665.21,"id":16325787}]}]}
{"op":"mcm","clk":"995509504","pt":1580557235534,"mc":[{"id":"1.168133553","rc":[{"batb":[[2,14,2.88]],"ltp":17.5,"tv":380.89,"id":27227336}]}]}
{"op":"mcm","clk":"995510509","pt":1580557240553,"mc":[{"id":"1.168133553","rc":[{"batb":[[2,4.4,60.71]],"batl":[[1,5.6,6.94],[2,5.7,7.32]],"ltp":5.3,"tv":2217.27,"id":21641292}]}]}
{"op":"mcm","clk":"995511430","pt":1580557245479,"mc":[{"id":"1.168133553","rc":[{"batb":[[0,1.32,75],[1,1.31,48.12],[2,1.3,222.27]],"ltp":1.32,"tv":12665.21,"id":16325787}]}]}
{"op":"mcm","clk":"995511635","pt":1580557246481,"mc":[{"id":"1.168133553","rc":[{"trd":[[17.5,37.17]],"batl":[[0,17.5,10.75]],"ltp":17.5,"tv":382.33,"id":27227336},{"trd":[[5.2,181.72]],"ltp":5.2,"tv":2222.11,"id":21641292},{"trd":[[1.32,4588.62],[1.33,2765.04]],"batb":[[0,1.32,54.71]],"batl":[[0,1.33,623.19]],"ltp":1.33,"tv":12742.71,"id":16325787}],"tv":15347.16}]}
{"op":"mcm","clk":"995545179","pt":1580557419513,"mc":[{"id":"1.168133553","rc":[{"trd":[[17.5,38.61]],"batl":[[0,17.5,9.31]],"ltp":17.5,"tv":383.77,"id":27227336},{"trd":[[5.2,186.56]],"ltp":5.2,"tv":2226.95,"id":21641292},{"trd":[[1.33,2801.96]],"batl":[[0,1.33,595.27]],"ltp":1.33,"tv":12779.63,"id":16325787}],"tv":15390.36}]}
{"op":"mcm","clk":"995547876","pt":1580557433480,"mc":[{"id":"1.168133553","rc":[{"trd":[[1.32,4698.04]],"batb":[[0,1.31,48.12],[1,1.3,222.27],[2,1.29,203.65]],"batl":[[0,1.32,44.29],[1,1.33,595.27],[2,1.34,1525.33]],"ltp":1.32,"tv":12889.05,"id":16325787}],"tv":15499.78}]}
{"op":"mcm","clk":"995548075","pt":1580557434500,"mc":[{"id":"1.168133553","rc":[{"batb":[[1,4.4,60.71],[2,4.2,17.32]],"ltp":5.2,"tv":2226.95,"id":21641292}]}]}
{"op":"mcm","clk":"995549081","pt":1580557439526,"mc":[{"id":"1.168133553","rc":[{"batb":[[0,5,4.67],[1,4.5,1.65],[2,4.4,60.61]],"ltp":5.2,"tv":2226.95,"id":21641292}]}]}
{"op":"mcm","clk":"995549634","pt":1580557442515,"mc":[{"id":"1.168133553","rc":[{"batb":[[0,4.5,1.65],[1,4.4,60.61],[2,4.2,17.32]],"ltp":5.2,"tv":2226.95,"id":21641292}]}]}
{"op":"mcm","clk":"995549846","pt":1580557443484,"mc":[{"id":"1.168133553","rc":[{"batb":[[0,4.5,10.89]],"ltp":5.2,"tv":2226.95,"id":21641292}]}]}
{"op":"mcm","clk":"995555964","pt":1580557476553,"mc":[{"id":"1.168133553","rc":[{"batb":[[0,4.6,5.45],[1,4.5,10.89],[2,4.4,60.61]],"ltp":5.2,"tv":2226.95,"id":21641292}]}]}
{"op":"mcm","clk":"995556146","pt":1580557477550,"mc":[{"id":"1.168133553","rc":[{"batl":[[1,5.6,7.25]],"ltp":5.2,"tv":2226.95,"id":21641292}]}]}
{"op":"mcm","clk":"995595189","pt":1580557683563,"mc":[{"id":"1.168133553","rc":[{"trd":[[1.32,4708.2]],"batl":[[0,1.32,39.21]],"ltp":1.32,"tv":12899.21,"id":16325787}],"tv":15509.94}]}
{"op":"mcm","clk":"995603371","pt":1580557729523,"mc":[{"id":"1.168133553","rc":[{"batl":[[0,5.4,2],[1,5.5,30.8],[2,5.6,7.25]],"ltp":5.2,"tv":2226.95,"id":21641292}]}]}
{"op":"mcm","clk":"995603860","pt":1580557732549,"mc":[{"id":"1.168133553","rc":[{"batl":[[0,5.5,30.8],[1,5.6,7.25],[2,5.9,2.85]],"ltp":5.2,"tv":2226.95,"id":21641292}]}]}
{"op":"mcm","clk":"995609097","pt":1580557763572,"mc":[{"id":"1.168133553","rc":[{"trd":[[1.31,2287.56]],"batb":[[0,1.31,45.12]],"ltp":1.31,"tv":12905.21,"id":16325787}],"tv":15515.94}]}
{"op":"mcm","clk":"995609286","pt":1580557764570,"mc":[{"id":"1.168133553","rc":[{"trd":[[1.32,4714.14]],"batl":[[0,1.32,36.24]],"ltp":1.32,"tv":12911.15,"id":16325787}],"tv":15521.88}]}
{"op":"mcm","clk":"995635971","pt":1580557934517,"mc":[{"id":"1.168133553","rc":[{"trd":[[1.32,4721.94]],"batl":[[0,1.32,32.34]],"ltp":1.32,"tv":12918.95,"id":16325787}],"tv":15529.68}]}
{"op":"mcm","clk":"995661655","pt":1580558034558,"mc":[{"id":"1.168133553","rc":[{"trd":[[16.5,1.77],[17.5,39.38]],"batl":[[0,17.5,9.3]],"ltp":16.5,"tv":386.31,"id":27227336},{"trd":[[5.3,136.42],[5.5,231.67]],"batl":[[0,5.5,25.48]],"ltp":5.5,"tv":2234.81,"id":21641292},{"trd":[[1.32,4754.28]],"batl":[[0,1.33,595.27],[1,1.34,1525.33],[2,1.35,1651.83]],"ltp":1.32,"tv":12951.29,"id":16325787}],"tv":15572.42}]}
{"op":"mcm","clk":"995663428","pt":1580558045567,"mc":[{"id":"1.168133553","rc":[{"batb":[[0,4.7,9.12],[1,4.6,5.45],[2,4.5,10.89]],"ltp":5.5,"tv":2234.81,"id":21641292}]}]}
{"op":"mcm","clk":"995664629","pt":1580558053399,"mc":[{"id":"1.168133553","rc":[{"batb":[[0,4.8,3.64],[1,4.7,9.12],[2,4.5,1.65]],"ltp":5.5,"tv":2234.81,"id":21641292}]}]}
{"op":"mcm","clk":"995665632","pt":1580558060395,"mc":[{"id":"1.168133553","rc":[{"batb":[[0,4.8,5.19],[2,4.4,60.71]],"ltp":5.5,"tv":2234.81,"id":21641292}]}]}
{"op":"mcm","clk":"995667016","pt":1580558069232,"mc":[{"id":"1.168133553","rc":[{"batb":[[1,4.4,60.71],[2,4,8.63]],"ltp":5.5,"tv":2234.81,"id":21641292}]}]}
{"op":"mcm","clk":"995668951","pt":1580558082257,"mc":[{"id":"1.168133553","rc":[{"batb":[[0,4.8,3.64],[1,4.5,1.65],[2,4.4,60.61]],"ltp":5.5,"tv":2234.81,"id":21641292}]}]}
{"op":"mcm","clk":"995669573","pt":1580558086448,"mc":[{"id":"1.168133553","rc":[{"trd":[[16.5,2.53]],"batl":[[0,17.5,8.54]],"ltp":16.5,"tv":387.07,"id":27227336},{"trd":[[5.5,233.95]],"batb":[[0,4.5,1.65],[1,4.4,60.61],[2,4,8.63]],"batl":[[0,5.5,23.2]],"ltp":5.5,"tv":2237.09,"id":21641292},{"trd":[[1.32,4763.78]],"batl":[[0,1.32,25.9],[1,1.33,595.27],[2,1.34,1525.33]],"ltp":1.32,"tv":12960.79,"id":16325787}],"tv":15584.96}]}
{"op":"mcm","clk":"995672019","pt":1580558102473,"mc":[{"id":"1.168133553","rc":[{"batb":[[0,4.4,60.71],[1,4.1,1.55]],"ltp":5.5,"tv":2237.09,"id":21641292}]}]}
{"op":"mcm","clk":"995672359","pt":1580558104493,"mc":[{"id":"1.168133553","rc":[{"batb":[[0,15.5,1.21]],"ltp":16.5,"tv":387.07,"id":27227336},{"batb":[[0,4.4,61.06]],"ltp":5.5,"tv":2237.09,"id":21641292},{"batb":[[0,1.31,46.32]],"ltp":1.32,"tv":12960.79,"id":16325787}]}]}
{"op":"mcm","clk":"995675151","pt":1580558122511,"mc":[{"id":"1.168133553","rc":[{"trd":[[1.32,4774.02]],"batl":[[0,1.32,20.78]],"ltp":1.32,"tv":12971.03,"id":16325787}],"tv":15595.2}]}
{"op":"mcm","clk":"995684395","pt":1580558182536,"mc":[{"id":"1.168133553","rc":[{"trd":[[1.32,4778.02]],"batl":[[0,1.32,18.78]],"ltp":1.32,"tv":12975.03,"id":16325787}],"tv":15599.2}]}
{"op":"mcm","clk":"995694127","pt":1580558249529,"mc":[{"id":"1.168133553","rc":[{"trd":[[17.5,39.99]],"batl":[[0,17.5,7.93]],"ltp":17.5,"tv":387.68,"id":27227336},{"trd":[[5.3,138.42]],"ltp":5.3,"tv":2239.09,"id":21641292},{"trd":[[1.31,2300.06],[1.32,4786.05]],"batb":[[0,1.31,40.07]],"batl":[[0,1.32,10.75]],"ltp":1.32,"tv":12995.56,"id":16325787}],"tv":15622.34}]}
{"op":"mcm","clk":"995696619","pt":1580558267367,"mc":[{"id":"1.168133553","rc":[{"trd":[[1.31,2340.06]],"batb":[[0,1.31,20.07]],"ltp":1.31,"tv":13035.56,"id":16325787}],"tv":15662.34}]}
{"op":"mcm","clk":"995702249","pt":1580558306330,"mc":[{"id":"1.168133553","rc":[{"trd":[[17.5,40.6]],"batl":[[0,17.5,7.32]],"ltp":17.5,"tv":388.29,"id":27227336},{"trd":[[5.3,140.42]],"ltp":5.3,"tv":2241.09,"id":21641292},{"trd":[[1.32,4794.08]],"batl":[[0,1.32,2.72]],"ltp":1.32,"tv":13043.59,"id":16325787}],"tv":15672.98}]}
{"op":"mcm","clk":"995703448","pt":1580558314366,"mc":[{"id":"1.168133553","rc":[{"trd":[[17.5,40.81]],"batl":[[0,17.5,7.11]],"ltp":17.5,"tv":388.5,"id":27227336},{"trd":[[5.3,141.1]],"batl":[[0,5.3,2.32],[1,5.5,23.2],[2,5.6,7.25]],"ltp":5.3,"tv":2241.77,"id":21641292},{"trd":[[1.32,4796.8]],"batl":[[0,1.33,595.27],[1,1.34,1525.33],[2,1.35,1651.83]],"ltp":1.32,"tv":13046.31,"id":16325787}],"tv":15676.59}]}
{"op":"mcm","clk":"995703872","pt":1580558317355,"mc":[{"id":"1.168133553","rc":[{"batl":[[0,5.5,23.2],[1,5.6,7.25],[2,5.9,2.85]],"ltp":5.3,"tv":2241.77,"id":21641292}]}]}
{"op":"mcm","clk":"995704312","pt":1580558320479,"mc":[{"id":"1.168133553","rc":[{"batb":[[0,4.5,2.2],[1,4.4,60.61],[2,4.1,1.55]],"ltp":5.3,"tv":2241.77,"id":21641292},{"batb":[[0,1.31,26.08]],"ltp":1.32,"tv":13046.31,"id":16325787}]}]}
{"op":"mcm","clk":"995704469","pt":1580558321567,"mc":[{"id":"1.168133553","rc":[{"batb":[[0,15.5,1.72]],"ltp":17.5,"tv":388.5,"id":27227336}]}]}
{"op":"mcm","clk":"995705523","pt":1580558333547,"mc":[{"id":"1.168133553","rc":[{"batb":[[1,4.4,3.61]],"ltp":5.3,"tv":2241.77,"id":21641292},{"batl":[[0,1.32,250],[1,1.33,595.27],[2,1.34,1525.33]],"ltp":1.32,"tv":13046.31,"id":16325787}]}]}
{"op":"mcm","clk":"995710846","pt":1580558360480,"mc":[{"id":"1.168133553","rc":[{"batb":[[1,4.4,60.61]],"ltp":5.3,"tv":2241.77,"id":21641292}]}]}
{"op":"mcm","clk":"995727052","pt":1580558462465,"mc":[{"id":"1.168133553","rc":[{"trd":[[17.5,44.47]],"batl":[[0,17.5,3.45]],"ltp":17.5,"tv":392.16,"id":27227336},{"trd":[[5.5,245.6]],"batb":[[0,4.5,11.44]],"batl":[[0,5.5,11.55]],"ltp":5.5,"tv":2253.42,"id":21641292},{"trd":[[1.31,2441.13]],"batb":[[0,1.3,222.27],[1,1.29,203.65],[2,1.28,245]],"ltp":1.31,"tv":13147.39,"id":16325787}],"tv":15792.98}]}
{"op":"mcm","clk":"995727390","pt":1580558464567,"mc":[{"id":"1.168133553","rc":[{"batb":[[0,5,37.82],[1,4.5,11.44],[2,4.4,60.61]],"ltp":5.5,"tv":2253.42,"id":21641292}]}]}
{"op":"mcm","clk":"995729161","pt":1580558475433,"mc":[{"id":"1.168133553","rc":[{"batl":[[0,17.5,12.61]],"ltp":17.5,"tv":392.16,"id":27227336}]}]}
{"op":"mcm","clk":"995729945","pt":1580558480539,"mc":[{"id":"1.168133553","rc":[{"batb":[[1,4.5,67.44],[2,4.4,3.61]],"ltp":5.5,"tv":2253.42,"id":21641292}]}]}
{"op":"mcm","clk":"995732402","pt":1580558495553,"mc":[{"id":"1.168133553","rc":[{"batb":[[1,4.6,6],[2,4.5,67.44]],"ltp":5.5,"tv":2253.42,"id":21641292}]}]}
{"op":"mcm","clk":"995734182","pt":1580558507485,"mc":[{"id":"1.168133553","rc":[{"trd":[[17.5,44.62]],"batl":[[0,17.5,12.46]],"ltp":17.5,"tv":392.31,"id":27227336},{"trd":[[5.5,246.08]],"batl":[[0,5.5,11.07]],"ltp":5.5,"tv":2253.9,"id":21641292},{"trd":[[1.31,2443.13]],"ltp":1.31,"tv":13149.39,"id":16325787}],"tv":15795.61}]}
{"op":"mcm","clk":"995738883","pt":1580558539493,"mc":[{"id":"1.168133553","rc":[{"batl":[[0,5.4,10],[1,5.5,11.07],[2,5.6,7.25]],"ltp":5.5,"tv":2253.9,"id":21641292}]}]}
{"op":"mcm","clk":"995739744","pt":1580558545480,"mc":[{"id":"1.168133553","rc":[{"batl":[[0,17.5,3.3]],"ltp":17.5,"tv":392.31,"id":27227336},{"batb":[[0,4.6,6],[1,4.5,67.44],[2,4.4,3.61]],"ltp":5.5,"tv":2253.9,"id":21641292}]}]}
{"op":"mcm","clk":"995740896","pt":1580558553387,"mc":[{"id":"1.168133553","rc":[{"batb":[[0,4.7,9.12],[1,4.6,6],[2,4.5,67.44]],"batl":[[2,5.6,17.25]],"ltp":5.5,"tv":2253.9,"id":21641292}]}]}
{"op":"mcm","clk":"995741523","pt":1580558557490,"mc":[{"id":"1.168133553","rc":[{"trd":[[17.5,48.19]],"batb":[[0,16,3.74],[1,15.5,1.72],[2,15,1.45]],"batl":[[0,21,10],[1,23,8.94],[2,34,1]],"ltp":17.5,"tv":395.88,"id":27227336},{"trd":[[5.3,151.1]],"ltp":5.3,"tv":2263.9,"id":21641292},{"trd":[[1.32,4836.95]],"batl":[[0,1.32,209.85]],"ltp":1.32,"tv":13189.54,"id":16325787}],"tv":15849.33}]}
{"op":"mcm","clk":"995741673","pt":1580558558515,"mc":[{"id":"1.168133553","rc":[{"batb":[[0,5.2,10],[1,4.7,9.12],[2,4.6,6]],"ltp":5.3,"tv":2263.9,"id":21641292},{"batb":[[1,1.29,211.19]],"ltp":1.32,"tv":13189.54,"id":16325787}]}]}
{"op":"mcm","clk":"995741965","pt":1580558560386,"mc":[{"id":"1.168133553","rc":[{"batb":[[1,1.29,208.65]],"batl":[[0,1.32,214.85]],"ltp":1.32,"tv":13189.54,"id":16325787}]}]}
{"op":"mcm","clk":"995742579","pt":1580558564468,"mc":[{"id":"1.168133553","rc":[{"batl":[[0,5.3,10],[1,5.4,10],[2,5.5,11.07]],"ltp":5.3,"tv":2263.9,"id":21641292}]}]}
{"op":"mcm","clk":"995742708","pt":1580558565484,"mc":[{"id":"1.168133553","rc":[{"trd":[[5.2,206.57]],"batb":[[0,4.7,9.12],[1,4.6,6],[2,4.5,58.2]],"batl":[[0,5.2,11.23],[1,5.3,10],[2,5.4,10]],"ltp":5.2,"tv":2283.9,"id":21641292}],"tv":15869.33}]}
{"op":"mcm","clk":"995742850","pt":1580558566469,"mc":[{"id":"1.168133553","rc":[{"batb":[[0,15.5,2.48],[1,15,1.45],[2,14,2.88]],"batl":[[0,20,2.09],[1,21,10],[2,23,8.94]],"ltp":17.5,"tv":395.88,"id":27227336},{"batb":[[0,4.8,2.62],[1,4.7,9.12],[2,4.6,6]],"ltp":5.2,"tv":2283.9,"id":21641292},{"batb":[[0,1.3,231.95]],"ltp":1.32,"tv":13189.54,"id":16325787}]}]}
{"op":"mcm","clk":"995743400","pt":1580558570471,"mc":[{"id":"1.168133553","rc":[{"batb":[[2,14.5,17.01]],"ltp":17.5,"tv":395.88,"id":27227336}]}]}
{"op":"mcm","clk":"995743563","pt":1580558571570,"mc":[{"id":"1.168133553","rc":[{"batl":[[0,20,2.89]],"ltp":17.5,"tv":395.88,"id":27227336}]}]}
{"op":"mcm","clk":"995743850","pt":1580558573569,"mc":[{"id":"1.168133553","rc":[{"batl":[[1,1.33,597.27]],"ltp":1.32,"tv":13189.54,"id":16325787}]}]}
{"op":"mcm","clk":"995744441","pt":1580558577563,"mc":[{"id":"1.168133553","rc":[{"trd":[[19.5,7.74]],"ltp":19.5,"tv":397.18,"id":27227336},{"trd":[[5.2,211.45]],"batb":[[1,4.6,6],[2,4.5,2.2]],"batl":[[0,5.2,6.35]],"ltp":5.2,"tv":2288.78,"id":21641292},{"trd":[[1.32,4856.19]],"batl":[[0,1.32,195.61]],"ltp":1.32,"tv":13208.78,"id":16325787}],"tv":15894.75}]}
{"op":"mcm","clk":"995745013","pt":1580558581489,"mc":[{"id":"1.168133553","rc":[{"batb":[[1,4.5,2.2],[2,4.4,3.61]],"ltp":5.2,"tv":2288.78,"id":21641292}]}]}
{"op":"mcm","clk":"995749197","pt":1580558610538,"mc":[{"id":"1.168133553","rc":[{"trd":[[1.32,5056.19]],"batl":[[0,1.32,95.61]],"ltp":1.32,"tv":13408.78,"id":16325787}],"tv":16094.75}]}
{"op":"mcm","clk":"995749346","pt":1580558611518,"mc":[{"id":"1.168133553","rc":[{"trd":[[20,28.46]],"batl":[[0,21,10.27],[1,23,8.94],[2,34,1]],"ltp":20.0,"tv":399.8,"id":27227336},{"trd":[[5.2,217.8],[5.3,154.76]],"batl":[[0,5.3,6.34],[1,5.4,10],[2,5.5,11.07]],"ltp":5.3,"tv":2298.79,"id":21641292},{"trd":[[1.31,2483.13]],"ltp":1.31,"tv":13448.78,"id":16325787}],"tv":16147.38}]}
{"op":"mcm","clk":"995752037","pt":1580558628504,"mc":[{"id":"1.168133553","rc":[{"batb":[[2,1.28,285]],"ltp":1.31,"tv":13448.78,"id":16325787}]}]}
{"op":"mcm","clk":"995752333","pt":1580558630513,"mc":[{"id":"1.168133553","rc":[{"batb":[[2,14,20.88]],"ltp":20.0,"tv":399.8,"id":27227336}]}]}
{"op":"mcm","clk":"995753407","pt":1580558637531,"mc":[{"id":"1.168133553","rc":[{"batl":[[0,5.2,2],[1,5.3,6.34],[2,5.4,10]],"ltp":5.3,"tv":2298.79,"id":21641292}]}]}
{"op":"mcm","clk":"995753558","pt":1580558638520,"mc":[{"id":"1.168133553","rc":[{"batl":[[0,5.3,6.34],[1,5.4,10],[2,5.5,11.07]],"ltp":5.3,"tv":2298.79,"id":21641292}]}]}
{"op":"mcm","clk":"995758147","pt":1580558667501,"mc":[{"id":"1.168133553","rc":[{"trd":[[1.32,5066.27]],"batl":[[0,1.32,90.57]],"ltp":1.32,"tv":13458.86,"id":16325787}],"tv":16157.46}]}
{"op":"mcm","clk":"995762063","pt":1580558691542,"mc":[{"id":"1.168133553","rc":[{"batl":[[0,21,10]],"ltp":20.0,"tv":399.8,"id":27227336}]}]}
{"op":"mcm","clk":"995762559","pt":1580558694459,"mc":[{"id":"1.168133553","rc":[{"batl":[[1,1.33,595.27]],"ltp":1.32,"tv":13458.86,"id":16325787}]}]}
{"op":"mcm","clk":"995768746","pt":1580558730487,"mc":[{"id":"1.168133553","rc":[{"batl":[[0,1.32,95.57]],"ltp":1.32,"tv":13458.86,"id":16325787}]}]}
{"op":"mcm","clk":"995768915","pt":1580558731471,"mc":[{"id":"1.168133553","rc":[{"batb":[[1,1.29,213.65]],"ltp":1.32,"tv":13458.86,"id":16325787}]}]}
{"op":"mcm","clk":"995775458","pt":1580558769552,"mc":[{"id":"1.168133553","rc":[{"trd":[[21,4.8]],"batl":[[0,21,5.83]],"ltp":21.0,"tv":403.97,"id":27227336},{"trd":[[5.3,161.1],[5.4,390.93]],"batl":[[0,5.5,11.07],[1,5.6,17.25],[2,5.7,10]],"ltp":5.4,"tv":2315.13,"id":21641292},{"trd":[[1.3,1539.76]],"batb":[[0,1.3,16.87]],"ltp":1.3,"tv":13991.4,"id":16325787}],"tv":16710.51}]}
{"op":"mcm","clk":"995775575","pt":1580558770374,"mc":[{"id":"1.168133553","rc":[{"batb":[[2,1.28,304.09]],"ltp":1.3,"tv":13991.4,"id":16325787}]}]}
{"op":"mcm","clk":"995776440","pt":1580558775559,"mc":[{"id":"1.168133553","rc":[{"batb":[[0,5,37.82],[1,4.8,2.62],[2,4.5,2.2]],"ltp":5.4,"tv":2315.13,"id":21641292}]}]}
{"op":"mcm","clk":"995777411","pt":1580558781538,"mc":[{"id":"1.168133553","rc":[{"batb":[[2,14,2.88]],"ltp":21.0,"tv":403.97,"id":27227336}]}]}
{"op":"mcm","clk":"995777900","pt":1580558784441,"mc":[{"id":"1.168133553","rc":[{"batb":[[2,1.28,285]],"ltp":1.3,"tv":13991.4,"id":16325787}]}]}
{"op":"mcm","clk":"995778079","pt":1580558785569,"mc":[{"id":"1.168133553","rc":[{"trd":[[21,12.09]],"batl":[[0,23,8.94],[1,34,1],[2,36,2]],"ltp":21.0,"tv":411.26,"id":27227336},{"trd":[[5.1,142.82]],"ltp":5.1,"tv":2333.13,"id":21641292},{"trd":[[1.32,5157.82]],"batl":[[0,1.32,15.02]],"ltp":1.32,"tv":14082.95,"id":16325787}],"tv":16827.35}]}
{"op":"mcm","clk":"995778239","pt":1580558786476,"mc":[{"id":"1.168133553","rc":[{"batl":[[0,17.5,9.16],[1,23,9.13],[2,34,1]],"ltp":21.0,"tv":411.26,"id":27227336},{"batb":[[1,4.9,2.41],[2,4.8,13.81]],"ltp":5.1,"tv":2333.13,"id":21641292}]}]}
{"op":"mcm","clk":"995778421","pt":1580558787571,"mc":[{"id":"1.168133553","rc":[{"batb":[[1,4.8,2.62],[2,4.5,2.2]],"ltp":5.1,"tv":2333.13,"id":21641292}]}]}
{"op":"mcm","clk":"995779315","pt":1580558792559,"mc":[{"id":"1.168133553","rc":[{"batl":[[1,23,8.94]],"ltp":21.0,"tv":411.26,"id":27227336}]}]}
{"op":"mcm","clk":"995782611","pt":1580558811472,"mc":[{"id":"1.168133553","rc":[{"batb":[[2,4.5,58.2]],"ltp":5.1,"tv":2333.13,"id":21641292}]}]}
{"op":"mcm","clk":"995782922","pt":1580558813418,"mc":[{"id":"1.168133553","rc":[{"batb":[[2,4.6,6]],"ltp":5.1,"tv":2333.13,"id":21641292}]}]}
{"op":"mcm","clk":"995785271","pt":1580558827142,"mc":[{"id":"1.168133553","rc":[{"trd":[[1.32,5178.3]],"batl":[[0,1.32,4.78]],"ltp":1.32,"tv":14103.43,"id":16325787}],"tv":16847.83}]}
{"op":"mcm","clk":"995785581","pt":1580558828512,"mc":[{"id":"1.168133553","rc":[{"batb":[[0,16,2.63],[1,15.5,1.72],[2,15,1.45]],"ltp":21.0,"tv":411.26,"id":27227336},{"batb":[[0,5.3,9],[1,5,37.82],[2,4.8,2.62]],"ltp":5.1,"tv":2333.13,"id":21641292},{"batb":[[0,1.31,36.4],[1,1.3,16.87],[2,1.29,213.65]],"ltp":1.32,"tv":14103.43,"id":16325787}]}]}
{"op":"mcm","clk":"995787421","pt":1580558838468,"mc":[{"id":"1.168133553","rc":[{"batb":[[0,16.5,6.98],[1,16,11.87],[2,15.5,1.72]],"ltp":21.0,"tv":411.26,"id":27227336}]}]}
{"op":"mcm","clk":"995803214","pt":1580558865460,"mc":[{"id":"1.168133553","rc":[{"batb":[[0,17,3.03],[1,16.5,6.98],[2,16,11.87]],"ltp":21.0,"tv":411.26,"id":27227336}]}]}
{"op":"mcm","clk":"995809700","pt":1580558899529,"mc":[{"id":"1.168133553","rc":[{"batb":[[0,17,1.87]],"ltp":21.0,"tv":411.26,"id":27227336}]}]}
{"op":"mcm","clk":"995809882","pt":1580558900539,"mc":[{"id":"1.168133553","rc":[{"trd":[[5.3,175.1]],"batb":[[0,5.3,1.99]],"ltp":5.3,"tv":2347.13,"id":21641292}],"tv":16861.84}]}
{"op":"mcm","clk":"995812260","pt":1580558913547,"mc":[{"id":"1.168133553","rc":[{"trd":[[17,21.4]],"batb":[[0,16.5,6.98],[1,16,11.87],[2,15.5,1.72]],"batl":[[0,17.5,9.81]],"ltp":17.0,"tv":415.01,"id":27227336}],"tv":16865.58}]}
{"op":"mcm","clk":"995816001","pt":1580558933545,"mc":[{"id":"1.168133553","rc":[{"trd":[[17,21.77]],"batl":[[0,17.5,9.44]],"ltp":17.0,"tv":415.38,"id":27227336},{"trd":[[5.3,178.76],[5.4,392.1]],"batb":[[0,5,37.98],[1,4.8,2.62],[2,4.7,53]],"ltp":5.3,"tv":2351.96,"id":21641292},{"trd":[[1.32,5183.08]],"batl":[[0,1.33,595.27],[1,1.34,1525.33],[2,1.35,1651.83]],"ltp":1.32,"tv":14108.21,"id":16325787}],"tv":16875.56}]}
{"op":"mcm","clk":"995816171","pt":1580558934408,"mc":[{"id":"1.168133553","rc":[{"batb":[[1,1.29,213.65],[2,1.28,285]],"ltp":1.32,"tv":14108.21,"id":16325787}]}]}
{"op":"mcm","clk":"995817509","pt":1580558941556,"mc":[{"id":"1.168133553","rc":[{"trd":[[17,22.05],[17.5,48.47]],"batl":[[0,17.5,8.88]],"ltp":17.5,"tv":415.94,"id":27227336},{"trd":[[5.2,219.64],[5.3,179.08]],"batb":[[0,5,37.82]],"ltp":5.2,"tv":2354.12,"id":21641292},{"trd":[[1.33,2809.14]],"batl":[[0,1.33,588.09]],"ltp":1.33,"tv":14115.39,"id":16325787}],"tv":16885.46}]}
{"op":"mcm","clk":"995817696","pt":1580558942534,"mc":[{"id":"1.168133553","rc":[{"batb":[[0,1.32,136.71],[1,1.31,36.4],[2,1.29,213.65]],"ltp":1.33,"tv":14115.39,"id":16325787}]}]}
{"op":"mcm","clk":"995818424","pt":1580558946330,"mc":[{"id":"1.168133553","rc":[{"batl":[[0,17.5,9.16]],"ltp":17.5,"tv":415.94,"id":27227336}]}]}
{"op":"mcm","clk":"995819840","pt":1580558953507,"mc":[{"id":"1.168133553","rc":[{"batb":[[0,1.32,136.75]],"ltp":1.33,"tv":14115.39,"id":16325787}]}]}
{"op":"mcm","clk":"995821368","pt":1580558961501,"mc":[{"id":"1.168133553","rc":[{"batb":[[2,4.5,2.2]],"ltp":5.2,"tv":2354.12,"id":21641292}]}]}
{"op":"mcm","clk":"995836322","pt":1580559038518,"mc":[{"id":"1.168133553","rc":[{"batb":[[0,17,1.02],[1,16.5,6.98],[2,16,11.87]],"ltp":17.5,"tv":415.94,"id":27227336}]}]}
{"op":"mcm","clk":"995836719","pt":1580559040429,"mc":[{"id":"1.168133553","rc":[{"trd":[[17.5,49.06]],"batl":[[0,17.5,8.57]],"ltp":17.5,"tv":416.53,"id":27227336},{"trd":[[5.2,221.64]],"ltp":5.2,"tv":2356.12,"id":21641292},{"trd":[[1.33,2816.96]],"batl":[[0,1.33,580.27]],"ltp":1.33,"tv":14123.21,"id":16325787}],"tv":16895.87}]}
{"op":"mcm","clk":"995837909","pt":1580559046445,"mc":[{"id":"1.168133553","rc":[{"batl":[[0,17.5,9.16]],"ltp":17.5,"tv":416.53,"id":27227336}]}]}
{"op":"mcm","clk":"995843811","pt":1580559078438,"mc":[{"id":"1.168133553","rc":[{"trd":[[1.33,2837.42]],"batl":[[0,1.33,570.04]],"ltp":1.33,"tv":14143.67,"id":16325787}],"tv":16916.33}]}
{"op":"mcm","clk":"995852092","pt":1580559125557,"mc":[{"id":"1.168133553","rc":[{"batl":[[0,1.33,570.42]],"ltp":1.33,"tv":14143.67,"id":16325787}]}]}
{"op":"mcm","clk":"995855588","pt":1580559144464,"mc":[{"id":"1.168133553","rc":[{"batl":[[0,5.5,11.16]],"ltp":5.2,"tv":2356.12,"id":21641292}]}]}
{"op":"mcm","clk":"995857977","pt":1580559156502,"mc":[{"id":"1.168133553","rc":[{"trd":[[17,24.09]],"batb":[[0,16.5,6.98],[1,16,11.87],[2,15,2.06]],"batl":[[0,17,3.98],[1,17.5,9.16],[2,23,8.94]],"ltp":17.0,"tv":418.56,"id":27227336}],"tv":16918.37}]}
{"op":"mcm","clk":"995858338","pt":1580559158404,"mc":[{"id":"1.168133553","rc":[{"batb":[[0,17,1.02],[1,16.5,6.98],[2,16,11.87]],"batl":[[0,17.5,9.16],[1,23,8.94],[2,34,1]],"ltp":17.0,"tv":418.56,"id":27227336}]}]}
{"op":"mcm","clk":"995859096","pt":1580559162512,"mc":[{"id":"1.168133553","rc":[{"trd":[[17.5,58.28]],"batb":[[0,17.5,9.12],[1,17,1.02],[2,16.5,6.98]],"batl":[[0,23,8.94],[1,34,1],[2,36,2]],"ltp":17.5,"tv":427.78,"id":27227336},{"trd":[[5,172.39],[5.2,252.43]],"batb":[[0,5,30.83]],"ltp":5.0,"tv":2400.89,"id":21641292},{"trd":[[1.33,2957.95]],"batl":[[0,1.33,449.89]],"ltp":1.33,"tv":14264.2,"id":16325787}],"tv":17092.89}]}
{"op":"mcm","clk":"995859273","pt":1580559163430,"mc":[{"id":"1.168133553","rc":[{"batb":[[2,16,12.63]],"batl":[[0,22,4.37],[1,23,13.12],[2,24,4.37]],"ltp":17.5,"tv":427.78,"id":27227336},{"batb":[[1,4.9,5.35],[2,4.8,13.01]],"ltp":5.0,"tv":2400.89,"id":21641292}]}]}
{"op":"mcm","clk":"995860012","pt":1580559167458,"mc":[{"id":"1.168133553","rc":[{"batl":[[0,21,7.56],[1,22,4.37],[2,23,13.12]],"ltp":17.5,"tv":427.78,"id":27227336},{"batb":[[0,5.1,8.46],[1,5,37.82],[2,4.9,5.35]],"ltp":5.0,"tv":2400.89,"id":21641292}]}]}
{"op":"mcm","clk":"995860599","pt":1580559170574,"mc":[{"id":"1.168133553","rc":[{"batb":[[2,16,20.48]],"batl":[[1,23,8.94],[2,34,1]],"ltp":17.5,"tv":427.78,"id":27227336},{"batb":[[2,4.8,2.62]],"ltp":5.0,"tv":2400.89,"id":21641292}]}]}
{"op":"mcm","clk":"995869459","pt":1580559215567,"mc":[{"id":"1.168133553","rc":[{"batl":[[1,22,3.03],[2,23,8.94]],"ltp":17.5,"tv":427.78,"id":27227336}]}]}
{"op":"mcm","clk":"995869646","pt":1580559216543,"mc":[{"id":"1.168133553","rc":[{"trd":[[5.1,150.82]],"batb":[[0,5.1,4.46]],"ltp":5.1,"tv":2408.89,"id":21641292}],"tv":17100.89}]}
{"op":"mcm","clk":"995875863","pt":1580559248480,"mc":[{"id":"1.168133553","rc":[{"batl":[[0,20,3.03],[1,21,7.56]],"ltp":17.5,"tv":427.78,"id":27227336}]}]}
{"op":"mcm","clk":"995882661","pt":1580559282379,"mc":[{"id":"1.168133553","rc":[{"batl":[[0,21,7.56],[1,22,3.03]],"ltp":17.5,"tv":427.78,"id":27227336}]}]}
{"op":"mcm","clk":"995887761","pt":1580559307536,"mc":[{"id":"1.168133553","rc":[{"batb":[[0,5.2,3.31],[1,5.1,4.46],[2,5,37.82]],"ltp":5.1,"tv":2408.89,"id":21641292}]}]}
{"op":"mcm","clk":"995891657","pt":1580559328488,"mc":[{"id":"1.168133553","rc":[{"batl":[[1,23,8.94],[2,34,1]],"ltp":17.5,"tv":427.78,"id":27227336}]}]}
{"op":"mcm","clk":"995891808","pt":1580559329469,"mc":[{"id":"1.168133553","rc":[{"batl":[[0,20,3.03],[1,21,7.56],[2,23,8.94]],"ltp":17.5,"tv":427.78,"id":27227336},{"batl":[[1,5.6,10]],"ltp":5.1,"tv":2408.89,"id":21641292}]}]}
{"op":"mcm","clk":"995891974","pt":1580559330491,"mc":[{"id":"1.168133553","rc":[{"batl":[[0,5.4,2.88],[1,5.5,11.16],[2,5.6,10]],"ltp":5.1,"tv":2408.89,"id":21641292}]}]}
{"op":"mcm","clk":"995894502","pt":1580559344236,"mc":[{"id":"1.168133553","rc":[{"batb":[[0,18,2.1],[1,17.5,9.12],[2,17,1.02]],"ltp":17.5,"tv":427.78,"id":27227336}]}]}
{"op":"mcm","clk":"995894751","pt":1580559345545,"mc":[{"id":"1.168133553","rc":[{"batb":[[0,17.5,9.12],[1,17,1.02],[2,16,17.73]],"ltp":17.5,"tv":427.78,"id":27227336},{"trd":[[1.33,2961.95]],"batl":[[0,1.33,447.89]],"ltp":1.33,"tv":14268.2,"id":16325787}],"tv":17104.89}]}
{"op":"mcm","clk":"995895053","pt":1580559347356,"mc":[{"id":"1.168133553","rc":[{"batb":[[2,16,21.42]],"ltp":17.5,"tv":427.78,"id":27227336}]}]}
{"op":"mcm","clk":"995898291","pt":1580559365543,"mc":[{"id":"1.168133553","rc":[{"batl":[[0,19.5,1.14],[1,20,3.03],[2,21,7.56]],"ltp":17.5,"tv":427.78,"id":27227336}]}]}
{"op":"mcm","clk":"995899008","pt":1580559369548,"mc":[{"id":"1.168133553","rc":[{"batl":[[0,20,3.03],[1,21,7.56],[2,23,8.94]],"ltp":17.5,"tv":427.78,"id":27227336}]}]}
{"op":"mcm","clk":"995899340","pt":1580559371566,"mc":[{"id":"1.168133553","rc":[{"batl":[[0,21,7.56],[1,23,8.94],[2,34,8]],"ltp":17.5,"tv":427.78,"id":27227336}]}]}
{"op":"mcm","clk":"995899500","pt":1580559372488,"mc":[{"id":"1.168133553","rc":[{"batl":[[1,22,3.03],[2,23,8.94]],"ltp":17.5,"tv":427.78,"id":27227336},{"batl":[[0,5.3,2],[1,5.4,2.88],[2,5.5,11.16]],"ltp":5.1,"tv":2408.89,"id":21641292},{"trd":[[1.32,5187.49]],"batb":[[0,1.32,134.54]],"ltp":1.32,"tv":14272.62,"id":16325787}],"tv":17109.31}]}
{"op":"mcm","clk":"995899683","pt":1580559373470,"mc":[{"id":"1.168133553","rc":[{"batl":[[0,5.3,4]],"ltp":5.1,"tv":2408.89,"id":21641292},{"batl":[[0,1.33,449.89]],"ltp":1.32,"tv":14272.62,"id":16325787}]}]}
{"op":"mcm","clk":"995900734","pt":1580559379274,"mc":[{"id":"1.168133553","rc":[{"batl":[[0,5.3,6]],"ltp":5.1,"tv":2408.89,"id":21641292},{"batl":[[0,1.33,451.89]],"ltp":1.32,"tv":14272.62,"id":16325787}]}]}
{"op":"mcm","clk":"995905264","pt":1580559405561,"mc":[{"id":"1.168133553","rc":[{"batl":[[0,20,3.03],[1,21,7.56]],"ltp":17.5,"tv":427.78,"id":27227336},{"batl":[[1,5.5,11.16],[2,5.6,10]],"ltp":5.1,"tv":2408.89,"id":21641292}]}]}
{"op":"mcm","clk":"995905412","pt":1580559406489,"mc":[{"id":"1.168133553","rc":[{"batl":[[2,5.6,12.78]],"ltp":5.1,"tv":2408.89,"id":21641292}]}]}
{"op":"mcm","clk":"995909673","pt":1580559431520,"mc":[{"id":"1.168133553","rc":[{"batl":[[0,19.5,2],[1,20,3.03],[2,21,7.56]],"ltp":17.5,"tv":427.78,"id":27227336}]}]}
{"op":"mcm","clk":"995909866","pt":1580559432537,"mc":[{"id":"1.168133553","rc":[{"batl":[[0,20,3.03],[1,21,7.56],[2,23,8.94]],"ltp":17.5,"tv":427.78,"id":27227336}]}]}
{"op":"mcm","clk":"995912738","pt":1580559447394,"mc":[{"id":"1.168133553","rc":[{"batl":[[0,21,7.56],[1,23,8.94],[2,34,8]],"ltp":17.5,"tv":427.78,"id":27227336}]}]}
{"op":"mcm","clk":"995912880","pt":1580559448205,"mc":[{"id":"1.168133553","rc":[{"batl":[[1,22,3.03],[2,23,8.94]],"ltp":17.5,"tv":427.78,"id":27227336}]}]}
{"op":"mcm","clk":"995915821","pt":1580559464551,"mc":[{"id":"1.168133553","rc":[{"batb":[[0,1.32,136.81]],"ltp":1.32,"tv":14272.62,"id":16325787}]}]}
{"op":"mcm","clk":"995916555","pt":1580559468564,"mc":[{"id":"1.168133553","rc":[{"trd":[[1.33,2966.49]],"batb":[[0,1.32,134.54]],"batl":[[0,1.33,449.62]],"ltp":1.33,"tv":14277.16,"id":16325787}],"tv":17113.85}]}
{"op":"mcm","clk":"995917084","pt":1580559471481,"mc":[{"id":"1.168133553","rc":[{"trd":[[1.32,5192.06]],"batb":[[0,1.32,132.25]],"ltp":1.32,"tv":14281.73,"id":16325787}],"tv":17118.42}]}
{"op":"mcm","clk":"995919551","pt":1580559485489,"mc":[{"id":"1.168133553","rc":[{"batl":[[0,20,3.03],[1,21,7.56]],"ltp":17.5,"tv":427.78,"id":27227336}]}]}
{"op":"mcm","clk":"995919902","pt":1580559487492,"mc":[{"id":"1.168133553","rc":[{"batb":[[0,18,6.84],[1,17.5,9.12],[2,17,1.02]],"ltp":17.5,"tv":427.78,"id":27227336}]}]}
{"op":"mcm","clk":"995920079","pt":1580559488462,"mc":[{"id":"1.168133553","rc":[{"batl":[[1,23,8.94],[2,34,1]],"ltp":17.5,"tv":427.78,"id":27227336},{"batb":[[2,4.8,2.62]],"ltp":5.1,"tv":2408.89,"id":21641292}]}]}
{"op":"mcm","clk":"995925586","pt":1580559521512,"mc":[{"id":"1.168133553","rc":[{"batl":[[0,22,3.03],[2,34,9.96]],"ltp":17.5,"tv":427.78,"id":27227336}]}]}
{"op":"mcm","clk":"995941314","pt":1580559610740,"mc":[{"id":"1.168133553","rc":[{"trd":[[1.32,5212.05]],"batb":[[0,1.32,122.27]],"ltp":1.32,"tv":14301.72,"id":16325787}],"tv":17138.41}]}
{"op":"mcm","clk":"995945950","pt":1580559636489,"mc":[{"id":"1.168133553","rc":[{"trd":[[5.2,252.53]],"batb":[[0,5.2,3.26]],"ltp":5.2,"tv":2408.99,"id":21641292}],"tv":17138.51}]}
{"op":"mcm","clk":"995946301","pt":1580559638512,"mc":[{"id":"1.168133553","rc":[{"batl":[[2,28,2]],"ltp":17.5,"tv":427.78,"id":27227336}]}]}
{"op":"mcm","clk":"995947581","pt":1580559645506,"mc":[{"id":"1.168133553","rc":[{"batl":[[2,28,2.53]],"ltp":17.5,"tv":427.78,"id":27227336}]}]}
{"op":"mcm","clk":"995948475","pt":1580559650429,"mc":[{"id":"1.168133553","rc":[{"batl":[[0,22,3.56],[2,28,2]],"ltp":17.5,"tv":427.78,"id":27227336}]}]}
{"op":"mcm","clk":"995949380","pt":1580559655460,"mc":[{"id":"1.168133553","rc":[{"batl":[[2,34,5.49]],"ltp":17.5,"tv":427.78,"id":27227336}]}]}
{"op":"mcm","clk":"995953811","pt":1580559679236,"mc":[{"id":"1.168133553","rc":[{"batl":[[0,5.3,2]],"ltp":5.2,"tv":2408.99,"id":21641292},{"batl":[[0,1.33,445.62]],"ltp":1.32,"tv":14301.72,"id":16325787}]}]}
{"op":"mcm","clk":"995954028","pt":1580559680565,"mc":[{"id":"1.168133553","rc":[{"batl":[[0,5.3,4]],"ltp":5.2,"tv":2408.99,"id":21641292},{"batl":[[0,1.33,447.62]],"ltp":1.32,"tv":14301.72,"id":16325787}]}]}
{"op":"mcm","clk":"995954994","pt":1580559686248,"mc":[{"id":"1.168133553","rc":[{"batl":[[0,5.3,6]],"ltp":5.2,"tv":2408.99,"id":21641292},{"batl":[[0,1.33,449.62]],"ltp":1.32,"tv":14301.72,"id":16325787}]}]}
{"op":"mcm","clk":"995958491","pt":1580559706465,"mc":[{"id":"1.168133553","rc":[{"trd":[[1.33,2970.49]],"batl":[[0,1.33,447.62]],"ltp":1.33,"tv":14305.72,"id":16325787}],"tv":17142.51}]}
{"op":"mcm","clk":"995981204","pt":1580559778523,"mc":[{"id":"1.168133553","rc":[{"trd":[[5.2,258.53]],"batb":[[0,5.1,4.72],[1,4.8,2.62],[2,4.6,6]],"ltp":5.2,"tv":2414.99,"id":21641292}],"tv":17148.51}]}
{"op":"mcm","clk":"995981387","pt":1580559779517,"mc":[{"id":"1.168133553","rc":[{"batb":[[1,5,37.82],[2,4.8,2.62]],"ltp":5.2,"tv":2414.99,"id":21641292}]}]}
{"op":"mcm","clk":"995983184","pt":1580559789541,"mc":[{"id":"1.168133553","rc":[{"batl":[[0,21,8.09],[1,22,3.03],[2,23,8.94]],"ltp":17.5,"tv":427.78,"id":27227336}]}]}
{"op":"mcm","clk":"995984856","pt":1580559799315,"mc":[{"id":"1.168133553","rc":[{"batl":[[0,20,3.56],[1,21,7.56]],"ltp":17.5,"tv":427.78,"id":27227336}]}]}
{"op":"mcm","clk":"995995320","pt":1580559859558,"mc":[{"id":"1.168133553","rc":[{"batb":[[2,4.4,60.71]],"ltp":5.2,"tv":2414.99,"id":21641292}]}]}
{"op":"mcm","clk":"995997872","pt":1580559873498,"mc":[{"id":"1.168133553","rc":[{"trd":[[18,50.36]],"batb":[[0,18,2.07]],"ltp":18.0,"tv":437.32,"id":27227336}],"tv":17158.05}]}
{"op":"mcm","clk":"995999103","pt":1580559880514,"mc":[{"id":"1.168133553","rc":[{"trd":[[1.33,3036.49]],"batl":[[0,1.33,414.62]],"ltp":1.33,"tv":14371.72,"id":16325787}],"tv":17224.05}]}
{"op":"mcm","clk":"996001947","pt":1580559897513,"mc":[{"id":"1.168133553","rc":[{"trd":[[1.32,5215.41],[1.33,3040.49]],"batb":[[0,1.32,120.59]],"batl":[[0,1.33,412.62]],"ltp":1.32,"tv":14379.08,"id":16325787}],"tv":17231.4}]}
{"op":"mcm","clk":"996002816","pt":1580559902478,"mc":[{"id":"1.168133553","rc":[{"batb":[[0,1.32,122.27]],"ltp":1.32,"tv":14379.08,"id":16325787}]}]}
{"op":"mcm","clk":"996002996","pt":1580559903511,"mc":[{"id":"1.168133553","rc":[{"batb":[[0,1.32,120.59]],"ltp":1.32,"tv":14379.08,"id":16325787}]}]}
{"op":"mcm","clk":"996003159","pt":1580559904493,"mc":[{"id":"1.168133553","rc":[{"trd":[[1.32,5235.4],[1.33,3043.82]],"batb":[[0,1.32,110.6]],"batl":[[0,1.33,410.96]],"ltp":1.32,"tv":14402.39,"id":16325787}],"tv":17254.72}]}
{"op":"mcm","clk":"996014611","pt":1580559969541,"mc":[{"id":"1.168133553","rc":[{"trd":[[5.1,154.3],[5.2,259.05]],"batb":[[0,5.1,2.72]],"ltp":5.1,"tv":2418.99,"id":21641292}],"tv":17258.72}]}
{"op":"mcm","clk":"996018072","pt":1580559989381,"mc":[{"id":"1.168133553","rc":[{"batl":[[0,5.3,2]],"ltp":5.1,"tv":2418.99,"id":21641292},{"batl":[[0,1.33,406.96]],"ltp":1.32,"tv":14402.39,"id":16325787}]}]}
{"op":"mcm","clk":"996023796","pt":1580560019509,"mc":[{"id":"1.168133553","rc":[{"batb":[[2,4.5,5.67]],"batl":[[2,5.6,17.25]],"ltp":5.1,"tv":2418.99,"id":21641292}]}]}
{"op":"mcm","clk":"996028571","pt":1580560045428,"mc":[{"id":"1.168133553","rc":[{"trd":[[1.33,3065.82]],"batl":[[0,1.33,395.96]],"ltp":1.33,"tv":14424.39,"id":16325787}],"tv":17280.72}]}
{"op":"mcm","clk":"996032455","pt":1580560067380,"mc":[{"id":"1.168133553","rc":[{"batl":[[0,5.3,12]],"ltp":5.1,"tv":2418.99,"id":21641292}]}]}
{"op":"mcm","clk":"996032668","pt":1580560068508,"mc":[{"id":"1.168133553","rc":[{"batl":[[1,5.5,21.16]],"ltp":5.1,"tv":2418.99,"id":21641292}]}]}
{"op":"mcm","clk":"996033378","pt":1580560072527,"mc":[{"id":"1.168133553","rc":[{"batb":[[2,4.4,60.71]],"batl":[[2,5.6,10]],"ltp":5.1,"tv":2418.99,"id":21641292}]}]}
{"op":"mcm","clk":"996033527","pt":1580560073419,"mc":[{"id":"1.168133553","rc":[{"batl":[[2,5.6,12.78]],"ltp":5.1,"tv":2418.99,"id":21641292}]}]}
{"op":"mcm","clk":"996033658","pt":1580560074201,"mc":[{"id":"1.168133553","rc":[{"batb":[[2,4.7,10]],"ltp":5.1,"tv":2418.99,"id":21641292}]}]}
{"op":"mcm","clk":"996036592","pt":1580560090541,"mc":[{"id":"1.168133553","rc":[{"trd":[[1.32,5239.39]],"batb":[[0,1.32,108.61]],"ltp":1.32,"tv":14428.39,"id":16325787}],"tv":17284.71}]}
{"op":"mcm","clk":"996037573","pt":1580560096570,"mc":[{"id":"1.168133553","rc":[{"batb":[[0,17.5,9.12],[1,17,1.02],[2,16,11.87]],"batl":[[0,18.5,3.54],[1,19,50],[2,20,3.56]],"ltp":18.0,"tv":437.32,"id":27227336}]}]}
{"op":"mcm","clk":"996038279","pt":1580560100469,"mc":[{"id":"1.168133553","rc":[{"batb":[[1,4.7,10],[2,4.6,10]],"ltp":5.1,"tv":2418.99,"id":21641292}]}]}
{"op":"mcm","clk":"996038672","pt":1580560102568,"mc":[{"id":"1.168133553","rc":[{"batl":[[0,18,50],[1,18.5,3.54],[2,19,50]],"ltp":18.0,"tv":437.32,"id":27227336}]}]}
{"op":"mcm","clk":"996045464","pt":1580560141555,"mc":[{"id":"1.168133553","rc":[{"trd":[[1.32,5243.39]],"batb":[[0,1.32,106.61]],"ltp":1.32,"tv":14432.38,"id":16325787}],"tv":17288.71}]}
{"op":"mcm","clk":"996045654","pt":1580560142569,"mc":[{"id":"1.168133553","rc":[{"trd":[[1.33,3069.82]],"batl":[[0,1.33,393.96]],"ltp":1.33,"tv":14436.38,"id":16325787}],"tv":17292.71}]}
{"op":"mcm","clk":"996049823","pt":1580560166073,"mc":[{"id":"1.168133553","rc":[{"batb":[[2,1.3,200]],"ltp":1.33,"tv":14436.38,"id":16325787}]}]}
{"op":"mcm","clk":"996055205","pt":1580560196405,"mc":[{"id":"1.168133553","rc":[{"batb":[[0,5.1,5.72]],"batl":[[0,5.3,15]],"ltp":5.1,"tv":2418.99,"id":21641292}]}]}
{"op":"mcm","clk":"996055913","pt":1580560200501,"mc":[{"id":"1.168133553","rc":[{"batl":[[0,5.3,12]],"ltp":5.1,"tv":2418.99,"id":21641292}]}]}
{"op":"mcm","clk":"996056113","pt":1580560201502,"mc":[{"id":"1.168133553","rc":[{"batb":[[0,5.1,2.72]],"ltp":5.1,"tv":2418.99,"id":21641292}]}]}
{"op":"mcm","clk":"996063150","pt":1580560240550,"mc":[{"id":"1.168133553","rc":[{"trd":[[18,50.58]],"batl":[[0,18,49.78]],"ltp":18.0,"tv":437.54,"id":27227336},{"trd":[[5.1,160.52]],"batb":[[0,4.7,10],[1,4.6,10],[2,4.4,60.71]],"ltp":5.1,"tv":2425.21,"id":21641292},{"trd":[[1.33,3072.81]],"batl":[[0,1.33,390.97]],"ltp":1.33,"tv":14439.37,"id":16325787}],"tv":17302.14}]}
{"op":"mcm","clk":"996063322","pt":1580560241574,"mc":[{"id":"1.168133553","rc":[{"batb":[[0,17.5,11.96]],"ltp":18.0,"tv":437.54,"id":27227336},{"batb":[[0,4.8,10.36],[1,4.7,10],[2,4.6,10]],"ltp":5.1,"tv":2425.21,"id":21641292},{"batb":[[1,1.31,57.54]],"ltp":1.33,"tv":14439.37,"id":16325787}]}]}
{"op":"mcm","clk":"996067073","pt":1580560263558,"mc":[{"id":"1.168133553","rc":[{"trd":[[1.33,3076.81]],"batl":[[0,1.33,388.97]],"ltp":1.33,"tv":14443.37,"id":16325787}],"tv":17306.14}]}
{"op":"mcm","clk":"996067387","pt":1580560265377,"mc":[{"id":"1.168133553","rc":[{"trd":[[1.32,5247.41]],"batb":[[0,1.32,104.6]],"ltp":1.32,"tv":14447.39,"id":16325787}],"tv":17310.15}]}
{"op":"mcm","clk":"996067950","pt":1580560268449,"mc":[{"id":"1.168133553","rc":[{"trd":[[1.32,5363.61]],"batb":[[0,1.32,46.53]],"ltp":1.32,"tv":14563.59,"id":16325787}],"tv":17426.36}]}
{"op":"mcm","clk":"996084131","pt":1580560354525,"mc":[{"id":"1.168133553","rc":[{"batb":[[0,17.5,14.5]],"ltp":18.0,"tv":437.54,"id":27227336}]}]}
{"op":"mcm","clk":"996086821","pt":1580560369272,"mc":[{"id":"1.168133553","rc":[{"trd":[[18,52]],"batl":[[0,18,48.36]],"ltp":18.0,"tv":438.96,"id":27227336},{"trd":[[5.1,165.52]],"ltp":5.1,"tv":2430.21,"id":21641292},{"trd":[[1.33,3095.98]],"batl":[[0,1.33,369.8]],"ltp":1.33,"tv":14582.76,"id":16325787}],"tv":17451.95}]}
{"op":"mcm","clk":"996088121","pt":1580560375431,"mc":[{"id":"1.168133553","rc":[{"trd":[[5.2,263.05]],"batb":[[0,4.9,2.01],[1,4.8,10.36],[2,4.7,10]],"ltp":5.2,"tv":2434.21,"id":21641292}],"tv":17455.95}]}
{"op":"mcm","clk":"996088667","pt":1580560378265,"mc":[{"id":"1.168133553","rc":[{"batl":[[0,5.2,2],[1,5.3,12],[2,5.5,21.16]],"ltp":5.2,"tv":2434.21,"id":21641292}]}]}
{"op":"mcm","clk":"996091018","pt":1580560390482,"mc":[{"id":"1.168133553","rc":[{"trd":[[5.2,267.05]],"batl":[[0,5.3,12],[1,5.5,21.16],[2,5.6,12.78]],"ltp":5.2,"tv":2438.21,"id":21641292}],"tv":17459.95}]}
{"op":"mcm","clk":"996091190","pt":1580560391485,"mc":[{"id":"1.168133553","rc":[{"batl":[[0,5.3,13.96]],"ltp":5.2,"tv":2438.21,"id":21641292}]}]}
{"op":"mcm","clk":"996092058","pt":1580560396519,"mc":[{"id":"1.168133553","rc":[{"trd":[[1.32,5366.77]],"batb":[[0,1.32,44.95]],"ltp":1.32,"tv":14585.92,"id":16325787}],"tv":17463.11}]}
{"op":"mcm","clk":"996093551","pt":1580560404528,"mc":[{"id":"1.168133553","rc":[{"trd":[[18,52.12]],"batl":[[0,18,48.24]],"ltp":18.0,"tv":439.08,"id":27227336},{"trd":[[5.1,165.94]],"ltp":5.1,"tv":2438.63,"id":21641292},{"trd":[[1.33,3097.59]],"batl":[[0,1.33,368.19]],"ltp":1.33,"tv":14587.53,"id":16325787}],"tv":17465.26}]}
{"op":"mcm","clk":"996098272","pt":1580560429566,"mc":[{"id":"1.168133553","rc":[{"trd":[[1.33,3113.59]],"batl":[[0,1.33,360.19]],"ltp":1.33,"tv":14603.53,"id":16325787}],"tv":17481.26}]}
{"op":"mcm","clk":"996098824","pt":1580560432461,"mc":[{"id":"1.168133553","rc":[{"batl":[[1,5.5,27.91]],"ltp":5.1,"tv":2438.63,"id":21641292},{"trd":[[1.32,5442.73]],"batb":[[0,1.32,6.99],[1,1.31,87.93]],"ltp":1.32,"tv":14679.49,"id":16325787}],"tv":17557.22}]}
{"op":"mcm","clk":"996100028","pt":1580560439254,"mc":[{"id":"1.168133553","rc":[{"trd":[[1.32,5446.93]],"batb":[[0,1.32,4.89]],"ltp":1.32,"tv":14683.69,"id":16325787}],"tv":17561.42}]}
{"op":"mcm","clk":"996106266","pt":1580560473516,"mc":[{"id":"1.168133553","rc":[{"batb":[[0,4.8,10.36],[1,4.7,10],[2,4.6,10]],"batl":[[0,5.2,6.25],[1,5.3,13.96],[2,5.5,27.91]],"ltp":5.1,"tv":2438.63,"id":21641292}]}]}
{"op":"mcm","clk":"996106360","pt":1580560474063,"mc":[{"id":"1.168133553","rc":[{"batb":[[0,4.9,2.01],[1,4.8,10.36],[2,4.7,10]],"batl":[[0,5.3,13.96],[1,5.5,27.91],[2,5.6,12.78]],"ltp":5.1,"tv":2438.63,"id":21641292}]}]}
{"op":"mcm","clk":"996155629","pt":1580560689385,"mc":[{"id":"1.168133553","rc":[{"trd":[[5.2,270.41]],"batb":[[0,4.9,3.8]],"ltp":5.2,"tv":2442.0,"id":21641292}],"tv":17564.78}]}
{"op":"mcm","clk":"996156821","pt":1580560696458,"mc":[{"id":"1.168133553","rc":[{"batl":[[0,5.2,1.68],[1,5.3,13.96],[2,5.5,27.91]],"ltp":5.2,"tv":2442.0,"id":21641292}]}]}
{"op":"mcm","clk":"996157047","pt":1580560697566,"mc":[{"id":"1.168133553","rc":[{"trd":[[1.33,3123.59]],"batl":[[0,1.33,355.19]],"ltp":1.33,"tv":14693.69,"id":16325787}],"tv":17574.78}]}
{"op":"mcm","clk":"996163819","pt":1580560735440,"mc":[{"id":"1.168133553","rc":[{"batl":[[0,1.33,405.19]],"ltp":1.33,"tv":14693.69,"id":16325787}]}]}
{"op":"mcm","clk":"996171332","pt":1580560778381,"mc":[{"id":"1.168133553","rc":[{"trd":[[1.33,3138.23]],"batl":[[0,1.33,397.87]],"ltp":1.33,"tv":14708.33,"id":16325787}],"tv":17589.42}]}
{"op":"mcm","clk":"996171544","pt":1580560779477,"mc":[{"id":"1.168133553","rc":[{"trd":[[18,52.97]],"batl":[[0,18,47.39]],"ltp":18.0,"tv":439.93,"id":27227336},{"trd":[[5.1,168.94]],"ltp":5.1,"tv":2445.0,"id":21641292},{"trd":[[1.33,3149.73]],"batl":[[0,1.33,386.37]],"ltp":1.33,"tv":14719.83,"id":16325787}],"tv":17604.77}]}
{"op":"mcm","clk":"996173656","pt":1580560791538,"mc":[{"id":"1.168133553","rc":[{"trd":[[18,58.62]],"batb":[[2,16,22.08]],"batl":[[0,18,41.74]],"ltp":18.0,"tv":445.58,"id":27227336},{"trd":[[5.2,272.09],[5.3,193.04],[5.5,249.53]],"batl":[[0,5.5,24.46],[1,5.6,17.75],[2,5.7,10]],"ltp":5.5,"tv":2464.09,"id":21641292},{"trd":[[1.31,2673.49],[1.32,5519.39]],"batb":[[0,1.3,213.29],[1,1.29,213.65],[2,1.28,85]],"ltp":1.31,"tv":14982.65,"id":16325787}],"tv":17892.33}]}
{"op":"mcm","clk":"996173834","pt":1580560792518,"mc":[{"id":"1.168133553","rc":[{"batb":[[0,5,37.82]],"batl":[[0,5.4,4.49],[1,5.5,24.46],[2,5.6,17.75]],"ltp":5.5,"tv":2464.09,"id":21641292}]}]}
{"op":"mcm","clk":"996174010","pt":1580560793514,"mc":[{"id":"1.168133553","rc":[{"batb":[[0,17.5,11.96],[2,16.5,2.53]],"ltp":18.0,"tv":445.58,"id":27227336},{"batb":[[0,5.1,7.41],[1,5,37.82],[2,4.8,10.36]],"batl":[[1,5.5,17.71]],"ltp":5.5,"tv":2464.09,"id":21641292},{"batl":[[0,1.33,416.3]],"ltp":1.31,"tv":14982.65,"id":16325787}]}]}
{"op":"mcm","clk":"996175081","pt":1580560799544,"mc":[{"id":"1.168133553","rc":[{"batb":[[0,5.2,3.73],[1,5.1,7.41],[2,5,37.82]],"batl":[[0,5.5,17.71],[1,5.6,12.78],[2,5.7,16.75]],"ltp":5.5,"tv":2464.09,"id":21641292},{"batb":[[0,1.3,200]],"ltp":1.31,"tv":14982.65,"id":16325787}]}]}
{"op":"mcm","clk":"996175233","pt":1580560800537,"mc":[{"id":"1.168133553","rc":[{"batb":[[0,1.3,205.86]],"ltp":1.31,"tv":14982.65,"id":16325787}]}]}
{"op":"mcm","clk":"996175600","pt":1580560802545,"mc":[{"id":"1.168133553","rc":[{"batl":[[2,5.7,10]],"ltp":5.5,"tv":2464.09,"id":21641292},{"batl":[[0,1.33,418.3]],"ltp":1.31,"tv":14982.65,"id":16325787}]}]}
{"op":"mcm","clk":"996178615","pt":1580560818549,"mc":[{"id":"1.168133553","rc":[{"batb":[[0,1.3,210.86]],"batl":[[0,1.33,423.3]],"ltp":1.31,"tv":14982.65,"id":16325787}]}]}
{"op":"mcm","clk":"996178836","pt":1580560819556,"mc":[{"id":"1.168133553","rc":[{"batb":[[0,17.5,14.5],[2,16,22.08]],"ltp":18.0,"tv":445.58,"id":27227336}]}]}
{"op":"mcm","clk":"996179028","pt":1580560820531,"mc":[{"id":"1.168133553","rc":[{"trd":[[1.33,3169.73]],"batb":[[0,1.3,241.25]],"batl":[[0,1.33,413.3]],"ltp":1.33,"tv":15002.65,"id":16325787}],"tv":17912.33}]}
{"op":"mcm","clk":"996179388","pt":1580560822519,"mc":[{"id":"1.168133553","rc":[{"batl":[[1,5.6,10]],"ltp":5.5,"tv":2464.09,"id":21641292}]}]}
{"op":"mcm","clk":"996179563","pt":1580560823558,"mc":[{"id":"1.168133553","rc":[{"batl":[[0,5.4,2.88],[1,5.5,17.71],[2,5.6,10]],"ltp":5.5,"tv":2464.09,"id":21641292}]}]}
{"op":"mcm","clk":"996181597","pt":1580560834449,"mc":[{"id":"1.168133553","rc":[{"trd":[[17.5,77.06]],"batb":[[0,17.5,2.58],[2,16.5,2.53]],"ltp":17.5,"tv":464.36,"id":27227336},{"batb":[[0,1.31,30.39],[1,1.3,210.86],[2,1.29,213.65]],"ltp":1.33,"tv":15002.65,"id":16325787}],"tv":17931.1}]}
{"op":"mcm","clk":"996198834","pt":1580560924526,"mc":[{"id":"1.168133553","rc":[{"batl":[[0,18,45.96]],"ltp":17.5,"tv":464.36,"id":27227336}]}]}
{"op":"mcm","clk":"996199020","pt":1580560925541,"mc":[{"id":"1.168133553","rc":[{"trd":[[5.2,277.33]],"batb":[[0,5.2,1.11]],"ltp":5.2,"tv":2469.33,"id":21641292}],"tv":17936.34}]}
{"op":"mcm","clk":"996205195","pt":1580560958492,"mc":[{"id":"1.168133553","rc":[{"batb":[[0,1.32,13.05],[1,1.31,30.39],[2,1.3,210.86]],"ltp":1.33,"tv":15002.65,"id":16325787}]}]}
{"op":"mcm","clk":"996206429","pt":1580560965557,"mc":[{"id":"1.168133553","rc":[{"batb":[[1,1.31,327.39]],"ltp":1.33,"tv":15002.65,"id":16325787}]}]}
{"op":"mcm","clk":"996206643","pt":1580560966538,"mc":[{"id":"1.168133553","rc":[{"batb":[[1,1.31,297]],"ltp":1.33,"tv":15002.65,"id":16325787}]}]}
{"op":"mcm","clk":"996212012","pt":1580560994534,"mc":[{"id":"1.168133553","rc":[{"batb":[[2,16,11.87]],"ltp":17.5,"tv":464.36,"id":27227336}]}]}
{"op":"mcm","clk":"996213626","pt":1580561002519,"mc":[{"id":"1.168133553","rc":[{"batb":[[2,16,14.59]],"ltp":17.5,"tv":464.36,"id":27227336}]}]}
{"op":"mcm","clk":"996217676","pt":1580561023475,"mc":[{"id":"1.168133553","rc":[{"batb":[[2,16.5,2.53]],"ltp":17.5,"tv":464.36,"id":27227336}]}]}
{"op":"mcm","clk":"996218315","pt":1580561026497,"mc":[{"id":"1.168133553","rc":[{"batb":[[2,1.3,230.86]],"ltp":1.33,"tv":15002.65,"id":16325787}]}]}
{"op":"mcm","clk":"996219918","pt":1580561034424,"mc":[{"id":"1.168133553","rc":[{"trd":[[1.33,3181.73]],"batl":[[0,1.33,407.3]],"ltp":1.33,"tv":15014.65,"id":16325787}],"tv":17948.34}]}
{"op":"mcm","clk":"996220697","pt":1580561038512,"mc":[{"id":"1.168133553","rc":[{"batl":[[0,5.3,2],[1,5.4,2.88],[2,5.5,17.71]],"ltp":5.2,"tv":2469.33,"id":21641292},{"batb":[[2,1.3,225]],"ltp":1.33,"tv":15014.65,"id":16325787}]}]}
{"op":"mcm","clk":"996220880","pt":1580561039552,"mc":[{"id":"1.168133553","rc":[{"batl":[[0,5.4,2.88],[1,5.5,17.71],[2,5.6,10]],"ltp":5.2,"tv":2469.33,"id":21641292}]}]}
{"op":"mcm","clk":"996227260","pt":1580561072556,"mc":[{"id":"1.168133553","rc":[{"batl":[[0,18,41.74]],"ltp":17.5,"tv":464.36,"id":27227336}]}]}
{"op":"mcm","clk":"996237079","pt":1580561122523,"mc":[{"id":"1.168133553","rc":[{"trd":[[1.31,2769.39],[1.32,5545.49]],"batb":[[0,1.31,249.05],[1,1.3,225],[2,1.29,213.65]],"ltp":1.31,"tv":15136.65,"id":16325787}],"tv":18070.34}]}
{"op":"mcm","clk":"996237258","pt":1580561123480,"mc":[{"id":"1.168133553","rc":[{"batb":[[1,1.3,227.42]],"ltp":1.31,"tv":15136.65,"id":16325787}]}]}
{"op":"mcm","clk":"996237663","pt":1580561125495,"mc":[{"id":"1.168133553","rc":[{"batb":[[0,5.2,4.42]],"ltp":5.2,"tv":2469.33,"id":21641292}]}]}
{"op":"mcm","clk":"996241138","pt":1580561144562,"mc":[{"id":"1.168133553","rc":[{"batl":[[0,5.3,2],[1,5.4,2.88],[2,5.5,17.71]],"ltp":5.2,"tv":2469.33,"id":21641292}]}]}
{"op":"mcm","clk":"996241484","pt":1580561146572,"mc":[{"id":"1.168133553","rc":[{"trd":[[18,58.99]],"batl":[[0,18,41.37]],"ltp":18.0,"tv":464.73,"id":27227336},{"trd":[[5.3,195.78]],"batl":[[0,5.4,2.88],[1,5.5,17.71],[2,5.6,10]],"ltp":5.3,"tv":2472.07,"id":21641292},{"trd":[[1.32,5550.53]],"ltp":1.32,"tv":15141.69,"id":16325787}],"tv":18078.49}]}
{"op":"mcm","clk":"996245725","pt":1580561169530,"mc":[{"id":"1.168133553","rc":[{"batb":[[1,1.3,225]],"ltp":1.32,"tv":15141.69,"id":16325787}]}]}
{"op":"mcm","clk":"996245942","pt":1580561170561,"mc":[{"id":"1.168133553","rc":[{"trd":[[5.2,283.33]],"batb":[[0,5.2,1.42]],"ltp":5.2,"tv":2478.07,"id":21641292}],"tv":18084.49}]}
{"op":"mcm","clk":"996252334","pt":1580561201504,"mc":[{"id":"1.168133553","rc":[{"batl":[[0,1.32,31.41],[1,1.33,407.3],[2,1.34,1525.33]],"ltp":1.32,"tv":15141.69,"id":16325787}]}]}
{"op":"mcm","clk":"996252527","pt":1580561202498,"mc":[{"id":"1.168133553","rc":[{"batb":[[0,17.5,5.17]],"ltp":18.0,"tv":464.73,"id":27227336},{"batb":[[0,5.3,8.55],[1,5.2,1.42],[2,5.1,7.41]],"ltp":5.2,"tv":2478.07,"id":21641292},{"trd":[[1.32,5613.35]],"batb":[[0,1.32,16.76],[1,1.31,249.05],[2,1.3,225]],"batl":[[0,1.33,407.3],[1,1.34,1525.33],[2,1.35,1651.83]],"ltp":1.32,"tv":15204.51,"id":16325787}],"tv":18147.31}]}
{"op":"mcm","clk":"996252789","pt":1580561203574,"mc":[{"id":"1.168133553","rc":[{"batb":[[0,17.5,7.23],[2,16,17.12]],"ltp":18.0,"tv":464.73,"id":27227336},{"batb":[[0,5.3,12],[1,5.2,8.83],[2,5,37.82]],"batl":[[0,5.4,10.97]],"ltp":5.2,"tv":2478.07,"id":21641292}]}]}
{"op":"mcm","clk":"996252961","pt":1580561204500,"mc":[{"id":"1.168133553","rc":[{"batb":[[2,4.8,10.36]],"ltp":5.2,"tv":2478.07,"id":21641292}]}]}
{"op":"mcm","clk":"996253177","pt":1580561205489,"mc":[{"id":"1.168133553","rc":[{"batb":[[2,16,20.96]],"ltp":18.0,"tv":464.73,"id":27227336}]}]}
{"op":"mcm","clk":"996253615","pt":1580561207514,"mc":[{"id":"1.168133553","rc":[{"trd":[[17.5,81.06]],"batb":[[0,17.5,5.23]],"ltp":17.5,"tv":468.73,"id":27227336},{"trd":[[5.3,205.04]],"batb":[[0,5.3,7.37]],"ltp":5.3,"tv":2487.33,"id":21641292}],"tv":18160.58}]}
{"op":"mcm","clk":"996253833","pt":1580561208500,"mc":[{"id":"1.168133553","rc":[{"batb":[[2,5,2.49]],"ltp":5.3,"tv":2487.33,"id":21641292}]}]}
{"op":"mcm","clk":"996254577","pt":1580561212527,"mc":[{"id":"1.168133553","rc":[{"batb":[[1,5.2,1.42]],"ltp":5.3,"tv":2487.33,"id":21641292}]}]}
{"op":"mcm","clk":"996254763","pt":1580561213505,"mc":[{"id":"1.168133553","rc":[{"batb":[[2,5.1,7.41]],"ltp":5.3,"tv":2487.33,"id":21641292}]}]}
{"op":"mcm","clk":"996256524","pt":1580561222314,"mc":[{"id":"1.168133553","rc":[{"trd":[[1.32,5617.39]],"batb":[[0,1.32,14.74]],"ltp":1.32,"tv":15208.55,"id":16325787}],"tv":18164.61}]}
{"op":"mcm","clk":"996257815","pt":1580561228517,"mc":[{"id":"1.168133553","rc":[{"batb":[[2,16.5,2.53]],"ltp":17.5,"tv":468.73,"id":27227336}]}]}
{"op":"mcm","clk":"996263124","pt":1580561255513,"mc":[{"id":"1.168133553","rc":[{"batb":[[0,17.5,4.65]],"ltp":17.5,"tv":468.73,"id":27227336}]}]}
{"op":"mcm","clk":"996263941","pt":1580561259513,"mc":[{"id":"1.168133553","rc":[{"batb":[[0,1.32,111.54]],"ltp":1.32,"tv":15208.55,"id":16325787}]}]}
{"op":"mcm","clk":"996264166","pt":1580561260518,"mc":[{"id":"1.168133553","rc":[{"batb":[[1,1.31,279.44]],"ltp":1.32,"tv":15208.55,"id":16325787}]}]}
{"op":"mcm","clk":"996266136","pt":1580561269479,"mc":[{"id":"1.168133553","rc":[{"batb":[[1,1.31,249.05]],"ltp":1.32,"tv":15208.55,"id":16325787}]}]}
{"op":"mcm","clk":"996276326","pt":1580561322476,"mc":[{"id":"1.168133553","rc":[{"trd":[[1.32,5621.39],[1.33,3185.73]],"batb":[[0,1.32,109.54]],"batl":[[0,1.33,405.3]],"ltp":1.33,"tv":15216.55,"id":16325787}],"tv":18172.62}]}
