{"op":"mcm","clk":"994932756","pt":1580554592557,"mc":[{"id":"1.168133548","rc":[{"trd":[[6.6,48.78]],"batb":[[0,6.4,8.39],[1,6.2,17.6],[2,6,26.55]],"ltp":6.6,"tv":552.11,"id":8231803},{"batb":[[2,27,4.22]],"ltp":29.0,"tv":75.32,"id":9193530}],"tv":6429.72}]}
{"op":"mcm","clk":"994932866","pt":1580554593254,"mc":[{"id":"1.168133548","rc":[{"batb":[[1,6.2,14.44]],"batl":[[2,7.4,9.5]],"ltp":6.6,"tv":552.11,"id":8231803}]}]}
{"op":"mcm","clk":"994933049","pt":1580554594369,"mc":[{"id":"1.168133548","rc":[{"batb":[[1,6.2,16.85]],"batl":[[2,7.4,2.15]],"ltp":6.6,"tv":552.11,"id":8231803}]}]}
{"op":"mcm","clk":"994933418","pt":1580554596565,"mc":[{"id":"1.168133548","rc":[{"batl":[[1,9.6,5.59]],"ltp":8.4,"tv":1267.74,"id":10616006}]}]}
{"op":"mcm","clk":"994933734","pt":1580554598446,"mc":[{"id":"1.168133548","rc":[{"batb":[[2,6,29.55]],"ltp":6.6,"tv":552.11,"id":8231803},{"batb":[[1,8.4,23.25],[2,8.2,5.03]],"ltp":8.4,"tv":1267.74,"id":10616006},{"trd":[[7.8,78.88]],"batb":[[0,7.8,19.86],[1,7.6,5],[2,7.4,15.4]],"batl":[[0,8,31.23],[1,8.2,22.85],[2,8.4,2.85]],"ltp":7.8,"tv":1147.99,"id":10170404},{"trd":[[8.8,46.01]],"batb":[[0,8.8,25.68],[1,8.6,7.25],[2,8.4,4.28]],"batl":[[0,9,5.96],[1,9.2,2],[2,9.6,1.66]],"ltp":8.8,"tv":521.55,"id":15608820},{"batb":[[1,29,9.49]],"ltp":29.0,"tv":75.32,"id":9193530},{"batb":[[1,23,9.27]],"ltp":26.0,"tv":127.09,"id":9001159}],"tv":6451.9}]}
{"op":"mcm","clk":"994933893","pt":1580554599463,"mc":[{"id":"1.168133548","rc":[{"batl":[[2,7.4,9.5]],"ltp":6.6,"tv":552.11,"id":8231803},{"batl":[[0,9.6,5.59],[1,9.8,1.62],[2,10.5,7.2]],"ltp":8.4,"tv":1267.74,"id":10616006},{"trd":[[7.8,93.13]],"batb":[[0,7.8,12.74]],"batl":[[1,8.2,30.81]],"ltp":7.8,"tv":1162.24,"id":10170404}],"tv":6466.16}]}
{"op":"mcm","clk":"994934026","pt":1580554600432,"mc":[{"id":"1.168133548","rc":[{"batl":[[2,7.4,2.15]],"ltp":6.6,"tv":552.11,"id":8231803},{"batb":[[1,7.6,7]],"batl":[[1,8.2,38.76]],"ltp":7.8,"tv":1162.24,"id":10170404},{"batb":[[1,8.6,16.9]],"ltp":8.8,"tv":521.55,"id":15608820}]}]}
{"op":"mcm","clk":"994934361","pt":1580554602457,"mc":[{"id":"1.168133548","rc":[{"batl":[[2,7.4,9.5]],"ltp":6.6,"tv":552.11,"id":8231803}]}]}
{"op":"mcm","clk":"994934559","pt":1580554603535,"mc":[{"id":"1.168133548","rc":[{"batl":[[2,7.4,2.15]],"ltp":6.6,"tv":552.11,"id":8231803},{"batb":[[0,30,3.33],[1,29,8.11]],"ltp":29.0,"tv":75.32,"id":9193530}]}]}
{"op":"mcm","clk":"994934954","pt":1580554605553,"mc":[{"id":"1.168133548","rc":[{"batl":[[2,7.4,9.5]],"ltp":6.6,"tv":552.11,"id":8231803}]}]}
{"op":"mcm","clk":"994935145","pt":1580554606562,"mc":[{"id":"1.168133548","rc":[{"batl":[[2,7.4,2.15]],"ltp":6.6,"tv":552.11,"id":8231803}]}]}
{"op":"mcm","clk":"994935485","pt":1580554608537,"mc":[{"id":"1.168133548","rc":[{"trd":[[8.8,56.01]],"batb":[[0,8.8,20.69]],"ltp":8.8,"tv":531.54,"id":15608820}],"tv":6476.15}]}
{"op":"mcm","clk":"994936150","pt":1580554612546,"mc":[{"id":"1.168133548","rc":[{"batl":[[2,7.4,9.5]],"ltp":6.6,"tv":552.11,"id":8231803},{"batl":[[0,8,28.38],[1,8.2,35.91],[2,8.6,7.96]],"ltp":7.8,"tv":1162.24,"id":10170404}]}]}
{"op":"mcm","clk":"994936322","pt":1580554613438,"mc":[{"id":"1.168133548","rc":[{"batb":[[0,30,3.92]],"ltp":29.0,"tv":75.32,"id":9193530}]}]}
{"op":"mcm","clk":"994936455","pt":1580554614249,"mc":[{"id":"1.168133548","rc":[{"batl":[[2,7.4,2.15]],"ltp":6.6,"tv":552.11,"id":8231803}]}]}
{"op":"mcm","clk":"994937147","pt":1580554618564,"mc":[{"id":"1.168133548","rc":[{"trd":[[8.8,60]],"batb":[[0,8.8,18.69]],"ltp":8.8,"tv":535.54,"id":15608820}],"tv":6480.15}]}
{"op":"mcm","clk":"994937459","pt":1580554620556,"mc":[{"id":"1.168133548","rc":[{"batb":[[0,7.6,7],[1,7.4,15.4],[2,7.2,21]],"ltp":7.8,"tv":1162.24,"id":10170404},{"batb":[[0,8.6,16.9],[1,8.4,4.28],[2,8.2,9.19]],"ltp":8.8,"tv":535.54,"id":15608820},{"batb":[[0,30,11.76],[1,27,4.22],[2,26,1.67]],"ltp":29.0,"tv":75.32,"id":9193530}]}]}
{"op":"mcm","clk":"994937593","pt":1580554621363,"mc":[{"id":"1.168133548","rc":[{"batl":[[2,7.4,9.5]],"ltp":6.6,"tv":552.11,"id":8231803},{"batb":[[1,7.4,18.02]],"ltp":7.8,"tv":1162.24,"id":10170404},{"batb":[[1,8.4,8.08]],"ltp":8.8,"tv":535.54,"id":15608820},{"batb":[[1,27,1.84]],"ltp":29.0,"tv":75.32,"id":9193530}]}]}
{"op":"mcm","clk":"994937743","pt":1580554622262,"mc":[{"id":"1.168133548","rc":[{"batl":[[2,7.4,2.15]],"ltp":6.6,"tv":552.11,"id":8231803},{"batb":[[1,7.4,15.4]],"ltp":7.8,"tv":1162.24,"id":10170404},{"batb":[[0,8.6,7.25]],"ltp":8.8,"tv":535.54,"id":15608820}]}]}
{"op":"mcm","clk":"994938922","pt":1580554628473,"mc":[{"id":"1.168133548","rc":[{"batl":[[2,7.4,9.5]],"ltp":6.6,"tv":552.11,"id":8231803},{"batb":[[1,8.4,4.28]],"batl":[[0,8.8,3],[1,9,5.96],[2,9.2,2]],"ltp":8.8,"tv":535.54,"id":15608820}]}]}
{"op":"mcm","clk":"994939254","pt":1580554630354,"mc":[{"id":"1.168133548","rc":[{"batl":[[2,7.4,2.15]],"ltp":6.6,"tv":552.11,"id":8231803}]}]}
{"op":"mcm","clk":"994940127","pt":1580554635392,"mc":[{"id":"1.168133548","rc":[{"batl":[[1,6,84.29],[2,6.2,44.16]],"ltp":5.6,"tv":1420.09,"id":9417341},{"batb":[[0,8.6,5.32],[2,8.2,2]],"ltp":8.4,"tv":1267.74,"id":10616006}]}]}
{"op":"mcm","clk":"994940839","pt":1580554639507,"mc":[{"id":"1.168133548","rc":[{"batb":[[0,8.8,21.59],[1,8.6,5.32],[2,8.2,2.63]],"ltp":8.4,"tv":1267.74,"id":10616006}]}]}
{"op":"mcm","clk":"994941738","pt":1580554644504,"mc":[{"id":"1.168133548","rc":[{"batl":[[2,7.4,9.5]],"ltp":6.6,"tv":552.11,"id":8231803}]}]}
{"op":"mcm","clk":"994942435","pt":1580554648394,"mc":[{"id":"1.168133548","rc":[{"batl":[[1,8.2,38.62],[2,8.4,2.71]],"ltp":7.8,"tv":1162.24,"id":10170404}]}]}
{"op":"mcm","clk":"994942973","pt":1580554651522,"mc":[{"id":"1.168133548","rc":[{"batl":[[2,7.4,2.15]],"ltp":6.6,"tv":552.11,"id":8231803}]}]}
{"op":"mcm","clk":"994944262","pt":1580554658495,"mc":[{"id":"1.168133548","rc":[{"trd":[[12,137.64]],"batb":[[0,11.5,3.48],[1,11,8.31],[2,10.5,1.98]],"batl":[[0,12,12.08],[1,12.5,50.29],[2,13.5,26.9]],"ltp":12.0,"tv":588.79,"id":8429550},{"batb":[[0,8.6,5.32],[1,8.2,2.63],[2,8,12.31]],"ltp":8.4,"tv":1267.74,"id":10616006}],"tv":6490.49}]}
{"op":"mcm","clk":"994944420","pt":1580554659502,"mc":[{"id":"1.168133548","rc":[{"batl":[[2,7.4,9.5]],"ltp":6.6,"tv":552.11,"id":8231803},{"batb":[[1,8.2,17.91]],"ltp":8.4,"tv":1267.74,"id":10616006}]}]}
{"op":"mcm","clk":"994944579","pt":1580554660399,"mc":[{"id":"1.168133548","rc":[{"batl":[[2,7.4,2.15]],"ltp":6.6,"tv":552.11,"id":8231803},{"batb":[[1,8.2,2.63]],"ltp":8.4,"tv":1267.74,"id":10616006},{"batb":[[1,27,5.6]],"ltp":29.0,"tv":75.32,"id":9193530}]}]}
{"op":"mcm","clk":"994944832","pt":1580554661724,"mc":[{"id":"1.168133548","rc":[{"batl":[[2,7.4,9.5]],"ltp":6.6,"tv":552.11,"id":8231803}]}]}
{"op":"mcm","clk":"994945343","pt":1580554664444,"mc":[{"id":"1.168133548","rc":[{"batl":[[2,7.4,2.15]],"ltp":6.6,"tv":552.11,"id":8231803}]}]}
{"op":"mcm","clk":"994945728","pt":1580554666410,"mc":[{"id":"1.168133548","rc":[{"batl":[[2,7.4,9.5]],"ltp":6.6,"tv":552.11,"id":8231803},{"batb":[[0,7.8,5],[1,7.6,7],[2,7.4,15.4]],"ltp":7.8,"tv":1162.24,"id":10170404}]}]}
{"op":"mcm","clk":"994945936","pt":1580554667526,"mc":[{"id":"1.168133548","rc":[{"trd":[[12,141.64]],"batl":[[0,12,10.08]],"ltp":12.0,"tv":592.79,"id":8429550}],"tv":6494.49}]}
{"op":"mcm","clk":"994946118","pt":1580554668503,"mc":[{"id":"1.168133548","rc":[{"batl":[[2,7.4,2.15]],"ltp":6.6,"tv":552.11,"id":8231803}]}]}
{"op":"mcm","clk":"994946473","pt":1580554670508,"mc":[{"id":"1.168133548","rc":[{"batl":[[2,7.4,9.5]],"ltp":6.6,"tv":552.11,"id":8231803}]}]}
{"op":"mcm","clk":"994947087","pt":1580554673516,"mc":[{"id":"1.168133548","rc":[{"batl":[[0,8,30.38]],"ltp":7.8,"tv":1162.24,"id":10170404}]}]}
{"op":"mcm","clk":"994948217","pt":1580554679207,"mc":[{"id":"1.168133548","rc":[{"batl":[[2,7.2,1.77]],"ltp":6.6,"tv":552.11,"id":8231803}]}]}
{"op":"mcm","clk":"994950284","pt":1580554690452,"mc":[{"id":"1.168133548","rc":[{"batb":[[0,6.6,2],[1,6.4,8.39],[2,6.2,16.85]],"ltp":6.6,"tv":552.11,"id":8231803}]}]}
{"op":"mcm","clk":"994950662","pt":1580554692449,"mc":[{"id":"1.168133548","rc":[{"trd":[[7.8,103.13]],"batb":[[0,7.6,7],[1,7.4,15.4],[2,7.2,21]],"batl":[[0,7.8,15],[1,8,30.38],[2,8.2,38.62]],"ltp":7.8,"tv":1172.24,"id":10170404}],"tv":6504.49}]}
{"op":"mcm","clk":"994950838","pt":1580554693458,"mc":[{"id":"1.168133548","rc":[{"batl":[[1,8,34.43]],"ltp":7.8,"tv":1172.24,"id":10170404}]}]}
{"op":"mcm","clk":"994951044","pt":1580554694458,"mc":[{"id":"1.168133548","rc":[{"batb":[[0,6.4,8.39],[1,6.2,16.85],[2,6,29.55]],"ltp":6.6,"tv":552.11,"id":8231803}]}]}
{"op":"mcm","clk":"994951365","pt":1580554696444,"mc":[{"id":"1.168133548","rc":[{"batb":[[0,11.5,14.49]],"ltp":12.0,"tv":592.79,"id":8429550},{"batb":[[0,8.8,21.59],[1,8.6,5.32],[2,8.2,2.63]],"ltp":8.4,"tv":1267.74,"id":10616006},{"trd":[[7.8,128.62]],"batl":[[0,7.8,2.25]],"ltp":7.8,"tv":1197.73,"id":10170404},{"trd":[[8.8,66]],"batb":[[0,8.8,15.69],[1,8.6,7.25],[2,8.4,4.28]],"batl":[[0,9,5.96],[1,9.2,2],[2,9.6,1.66]],"ltp":8.8,"tv":541.53,"id":15608820}],"tv":6535.98}]}
{"op":"mcm","clk":"994951524","pt":1580554697359,"mc":[{"id":"1.168133548","rc":[{"batl":[[1,8,30.38]],"ltp":7.8,"tv":1197.73,"id":10170404}]}]}
{"op":"mcm","clk":"994951724","pt":1580554698461,"mc":[{"id":"1.168133548","rc":[{"batb":[[1,8.6,12.42]],"ltp":8.8,"tv":541.53,"id":15608820}]}]}
{"op":"mcm","clk":"994953391","pt":1580554707441,"mc":[{"id":"1.168133548","rc":[{"trd":[[8.8,74]],"batb":[[0,8.8,11.7]],"ltp":8.8,"tv":549.53,"id":15608820}],"tv":6543.97}]}
{"op":"mcm","clk":"994954686","pt":1580554715549,"mc":[{"id":"1.168133548","rc":[{"batb":[[0,11.5,3.48]],"ltp":12.0,"tv":592.79,"id":8429550},{"batb":[[0,8.6,12.42],[1,8.4,4.28],[2,8.2,9.19]],"ltp":8.8,"tv":549.53,"id":15608820}]}]}
{"op":"mcm","clk":"994954862","pt":1580554716556,"mc":[{"id":"1.168133548","rc":[{"batl":[[0,5.8,11.25]],"ltp":5.6,"tv":1420.09,"id":9417341}]}]}
{"op":"mcm","clk":"994956204","pt":1580554724485,"mc":[{"id":"1.168133548","rc":[{"batb":[[0,8.6,7.25],[1,8.4,9.13]],"ltp":8.8,"tv":549.53,"id":15608820}]}]}
{"op":"mcm","clk":"994956842","pt":1580554727566,"mc":[{"id":"1.168133548","rc":[{"batl":[[0,8.8,2],[1,9,5.96],[2,9.2,2]],"ltp":8.8,"tv":549.53,"id":15608820},{"batb":[[1,28,3.94],[2,27,5.42]],"ltp":29.0,"tv":75.32,"id":9193530}]}]}
{"op":"mcm","clk":"994957048","pt":1580554728564,"mc":[{"id":"1.168133548","rc":[{"batb":[[1,8.4,4.85]],"ltp":8.8,"tv":549.53,"id":15608820},{"batb":[[2,27,1.66]],"ltp":29.0,"tv":75.32,"id":9193530}]}]}
{"op":"mcm","clk":"994957182","pt":1580554729361,"mc":[{"id":"1.168133548","rc":[{"batb":[[1,27,1.84],[2,26,1.67]],"ltp":29.0,"tv":75.32,"id":9193530}]}]}
{"op":"mcm","clk":"994958066","pt":1580554734490,"mc":[{"id":"1.168133548","rc":[{"batb":[[0,8.6,5.32],[1,8.2,2.63],[2,8,12.31]],"ltp":8.4,"tv":1267.74,"id":10616006}]}]}
{"op":"mcm","clk":"994962368","pt":1580554757518,"mc":[{"id":"1.168133548","rc":[{"batl":[[0,9.4,2],[1,9.6,5.59],[2,9.8,1.62]],"ltp":8.4,"tv":1267.74,"id":10616006}]}]}
{"op":"mcm","clk":"994962556","pt":1580554758513,"mc":[{"id":"1.168133548","rc":[{"batb":[[0,11.5,7.89]],"ltp":12.0,"tv":592.79,"id":8429550},{"batb":[[0,5.6,14.94]],"ltp":5.6,"tv":1420.09,"id":9417341},{"batb":[[0,6.4,16.3]],"ltp":6.6,"tv":552.11,"id":8231803},{"batb":[[0,8.6,11.21]],"ltp":8.4,"tv":1267.74,"id":10616006},{"batb":[[0,7.6,13.67]],"ltp":7.8,"tv":1197.73,"id":10170404},{"batb":[[0,8.6,13.14]],"ltp":8.8,"tv":549.53,"id":15608820},{"batb":[[0,30,13.45]],"ltp":29.0,"tv":75.32,"id":9193530},{"batb":[[0,26,3.16]],"ltp":26.0,"tv":127.09,"id":9001159},{"batb":[[0,5.3,13.12]],"ltp":5.3,"tv":761.54,"id":17352128}]}]}
{"op":"mcm","clk":"994964404","pt":1580554768324,"mc":[{"id":"1.168133548","rc":[{"batb":[[1,6.2,19.99]],"ltp":6.6,"tv":552.11,"id":8231803},{"batb":[[1,8.4,9.96]],"ltp":8.8,"tv":549.53,"id":15608820},{"batb":[[1,24,2.99],[2,23,8.49]],"ltp":26.0,"tv":127.09,"id":9001159}]}]}
{"op":"mcm","clk":"994964811","pt":1580554770539,"mc":[{"id":"1.168133548","rc":[{"trd":[[7.6,204.97]],"batb":[[0,7.6,11.59]],"ltp":7.6,"tv":1201.89,"id":10170404}],"tv":6548.14}]}
{"op":"mcm","clk":"994965225","pt":1580554772544,"mc":[{"id":"1.168133548","rc":[{"batl":[[2,10.5,10.4]],"ltp":8.4,"tv":1267.74,"id":10616006}]}]}
{"op":"mcm","clk":"994965443","pt":1580554773514,"mc":[{"id":"1.168133548","rc":[{"batb":[[0,32,7.35],[1,30,5.6],[2,27,1.84]],"ltp":29.0,"tv":75.32,"id":9193530},{"batb":[[2,23,1.73]],"ltp":26.0,"tv":127.09,"id":9001159}]}]}
{"op":"mcm","clk":"994965619","pt":1580554774323,"mc":[{"id":"1.168133548","rc":[{"batb":[[1,23,2.52],[2,22,5.38]],"ltp":26.0,"tv":127.09,"id":9001159}]}]}
{"op":"mcm","clk":"994966070","pt":1580554776520,"mc":[{"id":"1.168133548","rc":[{"batb":[[1,24,2.99],[2,23,1.73]],"ltp":26.0,"tv":127.09,"id":9001159}]}]}
{"op":"mcm","clk":"994967726","pt":1580554785560,"mc":[{"id":"1.168133548","rc":[{"batb":[[1,23,2.52],[2,22,5.38]],"ltp":26.0,"tv":127.09,"id":9001159}]}]}
{"op":"mcm","clk":"994968068","pt":1580554787474,"mc":[{"id":"1.168133548","rc":[{"batl":[[0,42,5.64],[1,44,4.87],[2,46,1.78]],"ltp":29.0,"tv":75.32,"id":9193530},{"batb":[[1,24,2.99],[2,23,1.73]],"ltp":26.0,"tv":127.09,"id":9001159}]}]}
{"op":"mcm","clk":"994969022","pt":1580554792457,"mc":[{"id":"1.168133548","rc":[{"batb":[[0,30,5.6],[1,27,1.84],[2,26,1.67]],"ltp":29.0,"tv":75.32,"id":9193530}]}]}
{"op":"mcm","clk":"994970106","pt":1580554798344,"mc":[{"id":"1.168133548","rc":[{"trd":[[6.4,72.18]],"batb":[[0,6.4,14.3]],"ltp":6.4,"tv":556.11,"id":8231803},{"batl":[[1,8,28.38]],"ltp":7.6,"tv":1201.89,"id":10170404},{"batb":[[0,30,5.02]],"ltp":29.0,"tv":75.32,"id":9193530}],"tv":6552.14}]}
{"op":"mcm","clk":"994970803","pt":1580554801567,"mc":[{"id":"1.168133548","rc":[{"batl":[[1,44,4.03]],"ltp":29.0,"tv":75.32,"id":9193530}]}]}
{"op":"mcm","clk":"994971344","pt":1580554803405,"mc":[{"id":"1.168133548","rc":[{"batb":[[2,6,26.55]],"ltp":6.4,"tv":556.11,"id":8231803}]}]}
{"op":"mcm","clk":"994972563","pt":1580554807451,"mc":[{"id":"1.168133548","rc":[{"batb":[[1,25,3],[2,24,2.99]],"ltp":26.0,"tv":127.09,"id":9001159}]}]}
{"op":"mcm","clk":"994973299","pt":1580554810480,"mc":[{"id":"1.168133548","rc":[{"batl":[[0,38,5.01],[1,40,3.03],[2,44,1.12]],"ltp":29.0,"tv":75.32,"id":9193530}]}]}
{"op":"mcm","clk":"994973518","pt":1580554811490,"mc":[{"id":"1.168133548","rc":[{"trd":[[12,161.79]],"batb":[[0,11.5,12.77]],"batl":[[0,12.5,50.29],[1,13.5,26.9],[2,16,16]],"ltp":12.0,"tv":612.93,"id":8429550},{"batb":[[0,5.6,23.98]],"ltp":5.6,"tv":1420.09,"id":9417341},{"trd":[[6.4,92.18]],"batb":[[0,6.4,12.22]],"ltp":6.4,"tv":576.1,"id":8231803},{"batb":[[0,8.8,21.59],[1,8.6,17.1],[2,8.2,2.63]],"ltp":8.4,"tv":1267.74,"id":10616006},{"batb":[[0,7.6,18.25],[1,7.4,20.56]],"ltp":7.6,"tv":1201.89,"id":10170404},{"batb":[[0,8.6,19.03]],"ltp":8.8,"tv":549.53,"id":15608820},{"batb":[[0,30,6.7]],"ltp":29.0,"tv":75.32,"id":9193530},{"batb":[[0,26,5.11]],"ltp":26.0,"tv":127.09,"id":9001159},{"batb":[[0,5.4,3.98],[1,5.3,22.68],[2,5.2,9.67]],"batl":[[1,5.7,9.64],[2,5.8,45.42]],"ltp":5.3,"tv":761.54,"id":17352128}],"tv":6592.28}]}
{"op":"mcm","clk":"994973710","pt":1580554812491,"mc":[{"id":"1.168133548","rc":[{"batb":[[0,26,5.75]],"ltp":26.0,"tv":127.09,"id":9001159}]}]}
{"op":"mcm","clk":"994974932","pt":1580554818500,"mc":[{"id":"1.168133548","rc":[{"batl":[[0,9.6,5.59],[1,10.5,10.4],[2,11,19.58]],"ltp":8.4,"tv":1267.74,"id":10616006}]}]}
{"op":"mcm","clk":"994975093","pt":1580554819312,"mc":[{"id":"1.168133548","rc":[{"batl":[[0,36,4.73]],"ltp":29.0,"tv":75.32,"id":9193530}]}]}
{"op":"mcm","clk":"994975577","pt":1580554821496,"mc":[{"id":"1.168133548","rc":[{"batl":[[1,44,1.12],[2,46,1.78]],"ltp":29.0,"tv":75.32,"id":9193530}]}]}
{"op":"mcm","clk":"994975779","pt":1580554822397,"mc":[{"id":"1.168133548","rc":[{"trd":[[11,75.44],[11.5,91.26],[12,162.75]],"batb":[[0,10.5,1.98],[1,10,10.65],[2,9.8,6.81]],"batl":[[0,11,76.2],[1,12.5,50.29],[2,13.5,26.9]],"ltp":11.0,"tv":658.93,"id":8429550},{"trd":[[5.8,364.6]],"batl":[[0,5.8,8.22]],"ltp":5.8,"tv":1423.12,"id":9417341},{"trd":[[6.8,2.58]],"batl":[[0,6.8,5.31]],"ltp":6.8,"tv":578.68,"id":8231803},{"trd":[[9.6,74.04]],"batl":[[0,9.6,3.76]],"ltp":9.6,"tv":1269.57,"id":10616006},{"trd":[[7.8,130.87]],"batb":[[0,7.8,2.21],[1,7.6,18.25],[2,7.4,20.56]],"batl":[[0,8,28.38],[1,8.2,38.62],[2,8.4,2.71]],"ltp":7.8,"tv":1204.14,"id":10170404},{"trd":[[8.8,76.01]],"batl":[[0,9,5.96],[1,9.2,2],[2,9.6,1.66]],"ltp":8.8,"tv":551.54,"id":15608820},{"trd":[[36,4.39]],"batl":[[0,36,4.24]],"ltp":36.0,"tv":75.81,"id":9193530},{"trd":[[29,15.4]],"batl":[[0,29,2.04]],"ltp":29.0,"tv":127.7,"id":9001159},{"trd":[[5.5,17.19]],"batl":[[0,5.5,6.57]],"ltp":5.5,"tv":764.73,"id":17352128}],"tv":6654.27}]}
{"op":"mcm","clk":"994976043","pt":1580554823505,"mc":[{"id":"1.168133548","rc":[{"batb":[[2,9.6,5.34]],"ltp":11.0,"tv":658.93,"id":8429550},{"batb":[[1,5.5,19.36]],"ltp":5.8,"tv":1423.12,"id":9417341},{"batl":[[1,10.5,7.2]],"ltp":9.6,"tv":1269.57,"id":10616006},{"batb":[[2,7.4,15.4]],"ltp":7.8,"tv":1204.14,"id":10170404},{"batl":[[1,32,1.16],[2,40,3.04]],"ltp":29.0,"tv":127.7,"id":9001159}]}]}
{"op":"mcm","clk":"994976453","pt":1580554825389,"mc":[{"id":"1.168133548","rc":[{"batb":[[0,10.5,9.92]],"ltp":11.0,"tv":658.93,"id":8429550},{"batl":[[2,42,2.46]],"ltp":29.0,"tv":127.7,"id":9001159}]}]}
{"op":"mcm","clk":"994976682","pt":1580554826506,"mc":[{"id":"1.168133548","rc":[{"batl":[[2,40,3.8]],"ltp":29.0,"tv":127.7,"id":9001159}]}]}
{"op":"mcm","clk":"994977561","pt":1580554830496,"mc":[{"id":"1.168133548","rc":[{"batb":[[0,8.6,17.1],[1,8.2,2.63],[2,8,12.31]],"ltp":9.6,"tv":1269.57,"id":10616006},{"batb":[[1,27,2.5]],"ltp":36.0,"tv":75.81,"id":9193530},{"batb":[[0,27,6.39],[1,26,5.11],[2,25,3]],"ltp":29.0,"tv":127.7,"id":9001159},{"batb":[[0,5.4,46.52]],"ltp":5.5,"tv":764.73,"id":17352128}]}]}
{"op":"mcm","clk":"994977757","pt":1580554831517,"mc":[{"id":"1.168133548","rc":[{"batb":[[2,9.6,4.17]],"ltp":11.0,"tv":658.93,"id":8429550},{"batb":[[2,6,29.55]],"ltp":6.8,"tv":578.68,"id":8231803},{"batb":[[1,8.4,3.63],[2,8.2,2]],"ltp":9.6,"tv":1269.57,"id":10616006},{"batl":[[2,42,2.46]],"ltp":29.0,"tv":127.7,"id":9001159}]}]}
{"op":"mcm","clk":"994977898","pt":1580554832360,"mc":[{"id":"1.168133548","rc":[{"trd":[[27,34.07]],"batb":[[0,26,5.11],[1,25,3],[2,24,2.99]],"ltp":27.0,"tv":140.49,"id":9001159}],"tv":6667.06}]}
{"op":"mcm","clk":"994978925","pt":1580554837536,"mc":[{"id":"1.168133548","rc":[{"batb":[[0,5.7,3.02],[1,5.6,23.98],[2,5.5,19.36]],"ltp":5.8,"tv":1423.12,"id":9417341},{"batb":[[0,6.6,2.61],[1,6.4,12.22],[2,6.2,19.99]],"ltp":6.8,"tv":578.68,"id":8231803},{"batl":[[0,8.8,2],[1,9,5.96],[2,9.2,2]],"ltp":8.8,"tv":551.54,"id":15608820}]}]}
{"op":"mcm","clk":"994979124","pt":1580554838531,"mc":[{"id":"1.168133548","rc":[{"batb":[[0,6.6,12.99]],"ltp":6.8,"tv":578.68,"id":8231803},{"batl":[[2,40,3.8]],"ltp":27.0,"tv":140.49,"id":9001159}]}]}
{"op":"mcm","clk":"994979428","pt":1580554839441,"mc":[{"id":"1.168133548","rc":[{"batb":[[1,6.4,17.65]],"ltp":6.8,"tv":578.68,"id":8231803},{"batl":[[2,42,2.46]],"ltp":27.0,"tv":140.49,"id":9001159}]}]}
{"op":"mcm","clk":"994979628","pt":1580554840352,"mc":[{"id":"1.168133548","rc":[{"trd":[[11,103.44]],"batl":[[0,11,62.2]],"ltp":11.0,"tv":686.93,"id":8429550}],"tv":6695.06}]}
{"op":"mcm","clk":"994979856","pt":1580554841564,"mc":[{"id":"1.168133548","rc":[{"batl":[[2,40,3.8]],"ltp":27.0,"tv":140.49,"id":9001159}]}]}
{"op":"mcm","clk":"994980149","pt":1580554843148,"mc":[{"id":"1.168133548","rc":[{"batl":[[1,32,1.69]],"ltp":27.0,"tv":140.49,"id":9001159}]}]}
{"op":"mcm","clk":"994980586","pt":1580554845439,"mc":[{"id":"1.168133548","rc":[{"batl":[[1,34,1.14],[2,42,1.85]],"ltp":27.0,"tv":140.49,"id":9001159}]}]}
{"op":"mcm","clk":"994981383","pt":1580554849568,"mc":[{"id":"1.168133548","rc":[{"batb":[[0,5.4,3.98]],"ltp":5.5,"tv":764.73,"id":17352128}]}]}
{"op":"mcm","clk":"994981475","pt":1580554850161,"mc":[{"id":"1.168133548","rc":[{"trd":[[10.5,82.94]],"batb":[[0,10.5,1.52]],"ltp":10.5,"tv":703.74,"id":8429550},{"trd":[[5.8,381.03]],"batb":[[0,5.8,35.46],[1,5.7,3.02],[2,5.6,23.98]],"batl":[[0,6,84.29],[1,6.2,44.16],[2,6.4,25]],"ltp":5.8,"tv":1439.55,"id":9417341},{"trd":[[6.8,13.19]],"batb":[[0,6.8,31.94],[1,6.6,12.99],[2,6.4,17.65]],"batl":[[0,7,2],[1,7.2,1.77],[2,7.4,14.5]],"ltp":6.8,"tv":589.3,"id":8231803},{"trd":[[5.5,30.32]],"batb":[[0,5.5,35.2],[1,5.4,3.98],[2,5.3,22.68]],"batl":[[0,5.7,9.64],[1,5.8,45.42],[2,6,13.37]],"ltp":5.5,"tv":777.86,"id":17352128}],"tv":6752.04}]}
{"op":"mcm","clk":"994982088","pt":1580554853574,"mc":[{"id":"1.168133548","rc":[{"batl":[[0,5.9,7.79],[1,6,84.29],[2,6.2,44.16]],"ltp":5.8,"tv":1439.55,"id":9417341},{"batb":[[0,8.8,9.32],[1,8.6,17.1],[2,8.4,3.63]],"ltp":9.6,"tv":1269.57,"id":10616006},{"batb":[[1,27,1.84]],"ltp":36.0,"tv":75.81,"id":9193530}]}]}
{"op":"mcm","clk":"994982308","pt":1580554854545,"mc":[{"id":"1.168133548","rc":[{"batl":[[2,6.2,46.09]],"ltp":5.8,"tv":1439.55,"id":9417341},{"batb":[[1,6.6,25.77]],"batl":[[2,7.4,9.31]],"ltp":6.8,"tv":589.3,"id":8231803},{"batl":[[0,34,2.86]],"ltp":36.0,"tv":75.81,"id":9193530}]}]}
{"op":"mcm","clk":"994982708","pt":1580554856350,"mc":[{"id":"1.168133548","rc":[{"batl":[[2,7.4,7.15]],"ltp":6.8,"tv":589.3,"id":8231803}]}]}
{"op":"mcm","clk":"994983369","pt":1580554859491,"mc":[{"id":"1.168133548","rc":[{"batl":[[0,9.8,3.76],[1,10,6.27],[2,10.5,7.2]],"ltp":9.6,"tv":1269.57,"id":10616006}]}]}
{"op":"mcm","clk":"994983758","pt":1580554861479,"mc":[{"id":"1.168133548","rc":[{"batl":[[2,6.2,66.09]],"ltp":5.8,"tv":1439.55,"id":9417341},{"batl":[[1,7.2,6.77]],"ltp":6.8,"tv":589.3,"id":8231803}]}]}
{"op":"mcm","clk":"994984630","pt":1580554865518,"mc":[{"id":"1.168133548","rc":[{"trd":[[7,4]],"batl":[[0,7.2,6.77],[1,7.4,7.15],[2,8,5.53]],"ltp":7.0,"tv":593.3,"id":8231803}],"tv":6756.04}]}
{"op":"mcm","clk":"994984873","pt":1580554866537,"mc":[{"id":"1.168133548","rc":[{"batl":[[0,5.9,27.79]],"ltp":5.8,"tv":1439.55,"id":9417341},{"trd":[[7.2,7.03]],"batl":[[0,7.2,5.26]],"ltp":7.2,"tv":596.32,"id":8231803}],"tv":6759.07}]}
{"op":"mcm","clk":"994985302","pt":1580554868537,"mc":[{"id":"1.168133548","rc":[{"batb":[[0,5.7,3.02],[1,5.6,23.98],[2,5.5,19.36]],"ltp":5.8,"tv":1439.55,"id":9417341},{"batb":[[0,6.6,25.77],[1,6.4,17.65],[2,6.2,12.08]],"ltp":7.2,"tv":596.32,"id":8231803},{"batb":[[0,5.4,3.98],[1,5.3,22.68],[2,5.2,9.67]],"ltp":5.5,"tv":777.86,"id":17352128}]}]}
{"op":"mcm","clk":"994985533","pt":1580554869561,"mc":[{"id":"1.168133548","rc":[{"batb":[[1,5.6,42.25]],"batl":[[2,6.2,64.16]],"ltp":5.8,"tv":1439.55,"id":9417341},{"batb":[[1,5.3,41.34]],"ltp":5.5,"tv":777.86,"id":17352128}]}]}
{"op":"mcm","clk":"994985773","pt":1580554870555,"mc":[{"id":"1.168133548","rc":[{"batb":[[1,6.4,20.65]],"ltp":7.2,"tv":596.32,"id":8231803}]}]}
{"op":"mcm","clk":"994986172","pt":1580554872528,"mc":[{"id":"1.168133548","rc":[{"batl":[[0,5.8,10],[1,5.9,27.79],[2,6,84.29]],"ltp":5.8,"tv":1439.55,"id":9417341}]}]}
{"op":"mcm","clk":"994986353","pt":1580554873440,"mc":[{"id":"1.168133548","rc":[{"trd":[[5.7,112.22]],"batb":[[0,5.6,23.98],[1,5.5,19.36],[2,5.4,7.41]],"batl":[[0,5.7,6.98],[1,5.8,10],[2,5.9,27.79]],"ltp":5.7,"tv":1445.6,"id":9417341},{"batb":[[0,6.6,12.99],[1,6.4,27.1]],"ltp":7.2,"tv":596.32,"id":8231803},{"batb":[[1,5.3,22.68]],"ltp":5.5,"tv":777.86,"id":17352128}],"tv":6765.11}]}
{"op":"mcm","clk":"994986679","pt":1580554875059,"mc":[{"id":"1.168133548","rc":[{"batl":[[0,5.7,16.98]],"ltp":5.7,"tv":1445.6,"id":9417341}]}]}
{"op":"mcm","clk":"994988580","pt":1580554884367,"mc":[{"id":"1.168133548","rc":[{"trd":[[5.6,110.75]],"batb":[[0,5.6,3.99]],"ltp":5.6,"tv":1485.59,"id":9417341}],"tv":6805.11}]}
{"op":"mcm","clk":"994988817","pt":1580554885475,"mc":[{"id":"1.168133548","rc":[{"trd":[[5.6,118.74]],"batb":[[0,5.5,19.36],[1,5.4,7.41],[2,5.3,3.2]],"batl":[[0,5.6,3.06],[1,5.7,16.98],[2,5.8,10]],"ltp":5.6,"tv":1493.58,"id":9417341},{"batl":[[0,32,2.27]],"ltp":36.0,"tv":75.81,"id":9193530}],"tv":6813.1}]}
{"op":"mcm","clk":"994989042","pt":1580554886536,"mc":[{"id":"1.168133548","rc":[{"trd":[[32,5.26]],"batl":[[0,44,1.39],[1,46,1.78],[2,90,15.11]],"ltp":32.0,"tv":79.81,"id":9193530}],"tv":6817.1}]}
{"op":"mcm","clk":"994989234","pt":1580554887446,"mc":[{"id":"1.168133548","rc":[{"trd":[[32,5.8]],"batb":[[0,32,7.08],[1,30,6.7],[2,27,1.84]],"batl":[[0,44,1.12]],"ltp":32.0,"tv":80.35,"id":9193530}],"tv":6817.64}]}
{"op":"mcm","clk":"994989641","pt":1580554889358,"mc":[{"id":"1.168133548","rc":[{"batl":[[2,90,12.08]],"ltp":32.0,"tv":80.35,"id":9193530}]}]}
{"op":"mcm","clk":"994990091","pt":1580554891543,"mc":[{"id":"1.168133548","rc":[{"batl":[[0,44,1.48]],"ltp":32.0,"tv":80.35,"id":9193530}]}]}
{"op":"mcm","clk":"994990224","pt":1580554892282,"mc":[{"id":"1.168133548","rc":[{"batl":[[2,90,15.11]],"ltp":32.0,"tv":80.35,"id":9193530}]}]}
{"op":"mcm","clk":"994990687","pt":1580554894468,"mc":[{"id":"1.168133548","rc":[{"batl":[[2,90,12.11]],"ltp":32.0,"tv":80.35,"id":9193530}]}]}
{"op":"mcm","clk":"994991715","pt":1580554899489,"mc":[{"id":"1.168133548","rc":[{"batb":[[0,32,7.64]],"ltp":32.0,"tv":80.35,"id":9193530}]}]}
{"op":"mcm","clk":"994998523","pt":1580554930462,"mc":[{"id":"1.168133548","rc":[{"trd":[[5.5,97.06]],"batb":[[0,5.4,7.41],[1,5.2,22],[2,5,25]],"batl":[[0,5.5,1.4],[1,5.6,3.06],[2,5.7,16.98]],"ltp":5.5,"tv":1532.29,"id":9417341}],"tv":6856.35}]}
{"op":"mcm","clk":"994998655","pt":1580554931159,"mc":[{"id":"1.168133548","rc":[{"batl":[[0,42,5.05],[1,44,1.36],[2,46,1.78]],"ltp":32.0,"tv":80.35,"id":9193530}]}]}
{"op":"mcm","clk":"994998930","pt":1580554932557,"mc":[{"id":"1.168133548","rc":[{"trd":[[10.5,85.98]],"batb":[[0,10,14.88],[1,9.6,4.17],[2,9.2,7.89]],"batl":[[0,10.5,2.48],[1,11,62.2],[2,12.5,50.29]],"ltp":10.5,"tv":706.78,"id":8429550},{"batb":[[1,5.2,26.25],[2,5.1,2]],"ltp":5.5,"tv":1532.29,"id":9417341}],"tv":6859.39}]}
{"op":"mcm","clk":"994999114","pt":1580554933367,"mc":[{"id":"1.168133548","rc":[{"trd":[[5.4,0.44]],"batb":[[0,5.4,7.19]],"ltp":5.4,"tv":1532.73,"id":9417341},{"trd":[[8.8,15.57]],"batb":[[0,8.8,9.19]],"ltp":8.8,"tv":1269.83,"id":10616006},{"trd":[[7.8,131.17]],"batb":[[0,7.8,2.06]],"ltp":7.8,"tv":1204.44,"id":10170404}],"tv":6860.39}]}
{"op":"mcm","clk":"994999357","pt":1580554934556,"mc":[{"id":"1.168133548","rc":[{"trd":[[10.5,90.94]],"batl":[[0,11,62.2],[1,12.5,50.29],[2,13.5,20.72]],"ltp":10.5,"tv":711.74,"id":8429550},{"batb":[[2,5,25]],"ltp":5.4,"tv":1532.73,"id":9417341}],"tv":6865.35}]}
{"op":"mcm","clk":"994999541","pt":1580554935469,"mc":[{"id":"1.168133548","rc":[{"batb":[[2,8.2,2.63]],"ltp":8.8,"tv":1269.83,"id":10616006}]}]}
{"op":"mcm","clk":"995002025","pt":1580554945495,"mc":[{"id":"1.168133548","rc":[{"batb":[[0,30,7.26],[1,27,1.84],[2,26,1.67]],"ltp":32.0,"tv":80.35,"id":9193530}]}]}
{"op":"mcm","clk":"995002308","pt":1580554946477,"mc":[{"id":"1.168133548","rc":[{"batb":[[0,9,21.11],[1,8.8,9.19],[2,8.6,17.1]],"ltp":8.8,"tv":1269.83,"id":10616006}]}]}
{"op":"mcm","clk":"995003890","pt":1580554953294,"mc":[{"id":"1.168133548","rc":[{"batb":[[0,30,6.7]],"ltp":32.0,"tv":80.35,"id":9193530}]}]}
{"op":"mcm","clk":"995006076","pt":1580554963502,"mc":[{"id":"1.168133548","rc":[{"batl":[[0,40,5.11],[1,44,1.48]],"ltp":32.0,"tv":80.35,"id":9193530}]}]}
{"op":"mcm","clk":"995008372","pt":1580554974542,"mc":[{"id":"1.168133548","rc":[{"trd":[[8.6,217.11]],"batb":[[0,8.6,14.03]],"ltp":8.6,"tv":561.54,"id":15608820}],"tv":6875.35}]}
{"op":"mcm","clk":"995012040","pt":1580554991385,"mc":[{"id":"1.168133548","rc":[{"trd":[[5.4,31.59]],"batb":[[0,5.3,22.68],[1,5.2,9.67],[2,5,5.07]],"batl":[[0,5.4,1.02],[1,5.7,9.64],[2,5.8,45.42]],"ltp":5.4,"tv":785.82,"id":17352128}],"tv":6883.31}]}
{"op":"mcm","clk":"995012174","pt":1580554991985,"mc":[{"id":"1.168133548","rc":[{"batb":[[2,5.1,2]],"ltp":5.4,"tv":1532.73,"id":9417341},{"batb":[[1,5.2,14.12]],"ltp":5.4,"tv":785.82,"id":17352128}]}]}
{"op":"mcm","clk":"995012437","pt":1580554993397,"mc":[{"id":"1.168133548","rc":[{"batl":[[0,38,4.12]],"ltp":32.0,"tv":80.35,"id":9193530},{"batb":[[1,5.2,11.67]],"ltp":5.4,"tv":785.82,"id":17352128}]}]}
{"op":"mcm","clk":"995013079","pt":1580554996502,"mc":[{"id":"1.168133548","rc":[{"batb":[[0,6.6,14.99]],"ltp":7.2,"tv":596.32,"id":8231803}]}]}
{"op":"mcm","clk":"995013717","pt":1580554999556,"mc":[{"id":"1.168133548","rc":[{"batb":[[2,5,25]],"ltp":5.4,"tv":1532.73,"id":9417341}]}]}
{"op":"mcm","clk":"995013897","pt":1580555000476,"mc":[{"id":"1.168133548","rc":[{"batb":[[0,10,6.23]],"ltp":10.5,"tv":711.74,"id":8429550}]}]}
{"op":"mcm","clk":"995014329","pt":1580555002548,"mc":[{"id":"1.168133548","rc":[{"trd":[[5.4,33.63]],"batb":[[0,5.4,34.84],[1,5.3,22.68],[2,5.2,11.67]],"batl":[[0,5.7,9.64],[1,5.8,45.42],[2,6,13.37]],"ltp":5.4,"tv":787.86,"id":17352128}],"tv":6885.35}]}
{"op":"mcm","clk":"995014504","pt":1580555003464,"mc":[{"id":"1.168133548","rc":[{"batb":[[2,5.2,9.67]],"ltp":5.4,"tv":787.86,"id":17352128}]}]}
{"op":"mcm","clk":"995018521","pt":1580555023571,"mc":[{"id":"1.168133548","rc":[{"batl":[[0,36,3.07]],"ltp":32.0,"tv":80.35,"id":9193530}]}]}
{"op":"mcm","clk":"995018910","pt":1580555025557,"mc":[{"id":"1.168133548","rc":[{"batl":[[2,8.4,4.07]],"ltp":7.8,"tv":1204.44,"id":10170404}]}]}
{"op":"mcm","clk":"995022278","pt":1580555042288,"mc":[{"id":"1.168133548","rc":[{"trd":[[5.5,99.86],[5.6,124.85]],"batb":[[0,5.6,15.54],[1,5.4,7.19],[2,5.2,26.25]],"batl":[[0,5.7,16.98],[1,5.8,10],[2,5.9,20]],"ltp":5.6,"tv":1541.65,"id":9417341}],"tv":6894.27}]}
{"op":"mcm","clk":"995022677","pt":1580555044308,"mc":[{"id":"1.168133548","rc":[{"batb":[[1,5.4,14.03]],"ltp":5.6,"tv":1541.65,"id":9417341}]}]}
{"op":"mcm","clk":"995023408","pt":1580555047572,"mc":[{"id":"1.168133548","rc":[{"trd":[[6.4,122.2],[6.6,78.75]],"batb":[[0,6.4,12.09],[1,6.2,14.82],[2,6,26.55]],"ltp":6.4,"tv":656.32,"id":8231803}],"tv":6954.26}]}
{"op":"mcm","clk":"995023850","pt":1580555049563,"mc":[{"id":"1.168133548","rc":[{"trd":[[26,10]],"batb":[[0,26,2.11]],"ltp":26.0,"tv":146.49,"id":9001159}],"tv":6960.26}]}
{"op":"mcm","clk":"995024011","pt":1580555050267,"mc":[{"id":"1.168133548","rc":[{"batl":[[0,8,29.81]],"ltp":7.8,"tv":1204.44,"id":10170404}]}]}
{"op":"mcm","clk":"995024394","pt":1580555051989,"mc":[{"id":"1.168133548","rc":[{"batb":[[0,6.4,9.09]],"ltp":6.4,"tv":656.32,"id":8231803}]}]}
{"op":"mcm","clk":"995024736","pt":1580555053469,"mc":[{"id":"1.168133548","rc":[{"batb":[[0,6.2,14.82],[1,6,26.55],[2,5.9,8.18]],"ltp":6.4,"tv":656.32,"id":8231803},{"batl":[[0,44,1.48],[1,46,1.78],[2,90,15.11]],"ltp":32.0,"tv":80.35,"id":9193530}]}]}
{"op":"mcm","clk":"995025022","pt":1580555054478,"mc":[{"id":"1.168133548","rc":[{"batb":[[1,6,17.9]],"ltp":6.4,"tv":656.32,"id":8231803},{"batl":[[0,34,2.19],[1,44,1.48],[2,46,1.78]],"ltp":32.0,"tv":80.35,"id":9193530}]}]}
{"op":"mcm","clk":"995025346","pt":1580555055504,"mc":[{"id":"1.168133548","rc":[{"batb":[[0,6.2,12.08]],"ltp":6.4,"tv":656.32,"id":8231803},{"batb":[[2,23,2.52]],"ltp":26.0,"tv":146.49,"id":9001159}]}]}
{"op":"mcm","clk":"995025881","pt":1580555057572,"mc":[{"id":"1.168133548","rc":[{"batl":[[1,7.4,5]],"ltp":6.4,"tv":656.32,"id":8231803}]}]}
{"op":"mcm","clk":"995026297","pt":1580555059487,"mc":[{"id":"1.168133548","rc":[{"batb":[[0,8.8,9.19],[1,8.6,17.1],[2,8.2,2.63]],"ltp":8.8,"tv":1269.83,"id":10616006},{"batb":[[0,32,7.08],[1,30,6.7],[2,27,1.84]],"ltp":32.0,"tv":80.35,"id":9193530},{"batb":[[0,5.3,22.68],[1,5.2,9.67],[2,5,5.07]],"ltp":5.4,"tv":787.86,"id":17352128}]}]}
{"op":"mcm","clk":"995026517","pt":1580555060512,"mc":[{"id":"1.168133548","rc":[{"batl":[[0,8,28.38],[1,8.2,40.01]],"ltp":7.8,"tv":1204.44,"id":10170404},{"batb":[[1,5.2,28.34]],"batl":[[0,5.6,7.98],[1,5.7,9.64],[2,5.8,45.42]],"ltp":5.4,"tv":787.86,"id":17352128}]}]}
{"op":"mcm","clk":"995026719","pt":1580555061492,"mc":[{"id":"1.168133548","rc":[{"batb":[[2,5.2,22]],"ltp":5.6,"tv":1541.65,"id":9417341}]}]}
{"op":"mcm","clk":"995027706","pt":1580555066410,"mc":[{"id":"1.168133548","rc":[{"batb":[[0,6.2,14.08]],"ltp":6.4,"tv":656.32,"id":8231803}]}]}
{"op":"mcm","clk":"995027855","pt":1580555067118,"mc":[{"id":"1.168133548","rc":[{"batl":[[0,10.5,2],[1,11,62.2],[2,12.5,50.29]],"ltp":10.5,"tv":711.74,"id":8429550},{"batb":[[1,5.2,9.67]],"ltp":5.4,"tv":787.86,"id":17352128}]}]}
{"op":"mcm","clk":"995029057","pt":1580555072513,"mc":[{"id":"1.168133548","rc":[{"trd":[[32,21.08]],"batb":[[0,30,6.7],[1,27,1.84],[2,26,1.67]],"ltp":32.0,"tv":95.63,"id":9193530}],"tv":6975.54}]}
{"op":"mcm","clk":"995033072","pt":1580555091361,"mc":[{"id":"1.168133548","rc":[{"batb":[[0,6.6,5],[1,6.2,14.08],[2,6,17.9]],"ltp":6.4,"tv":656.32,"id":8231803},{"batl":[[0,8,29.81]],"ltp":7.8,"tv":1204.44,"id":10170404},{"batl":[[0,44,1.48],[1,46,1.78],[2,90,12.08]],"ltp":32.0,"tv":95.63,"id":9193530}]}]}
{"op":"mcm","clk":"995033356","pt":1580555092549,"mc":[{"id":"1.168133548","rc":[{"batl":[[0,9,5],[1,9.8,3.76],[2,10,6.27]],"ltp":8.8,"tv":1269.83,"id":10616006}]}]}
{"op":"mcm","clk":"995033544","pt":1580555093357,"mc":[{"id":"1.168133548","rc":[{"trd":[[7.8,135.29]],"batb":[[0,7.6,18.25],[1,7.4,15.4],[2,7.2,21]],"batl":[[0,8,29.32],[1,8.2,42.2],[2,8.4,2.71]],"ltp":7.8,"tv":1208.56,"id":10170404},{"batl":[[2,90,15.11]],"ltp":32.0,"tv":95.63,"id":9193530}],"tv":6979.66}]}
{"op":"mcm","clk":"995033793","pt":1580555094570,"mc":[{"id":"1.168133548","rc":[{"trd":[[9,66.78]],"batl":[[0,9.8,3.76],[1,10,6.27],[2,10.5,7.2]],"ltp":9.0,"tv":1279.83,"id":10616006},{"batb":[[1,7.4,20.56]],"batl":[[0,8,28.38]],"ltp":7.8,"tv":1208.56,"id":10170404}],"tv":6989.66}]}
{"op":"mcm","clk":"995034189","pt":1580555096393,"mc":[{"id":"1.168133548","rc":[{"batb":[[1,6.4,4.7],[2,6.2,12.08]],"ltp":6.4,"tv":656.32,"id":8231803},{"batb":[[0,9,1],[1,8.8,9.19],[2,8.6,17.1]],"batl":[[0,9.8,6.09],[1,10,8.45]],"ltp":9.0,"tv":1279.83,"id":10616006}]}]}
{"op":"mcm","clk":"995036320","pt":1580555104488,"mc":[{"id":"1.168133548","rc":[{"trd":[[9,67.78]],"batb":[[0,8.8,9.69],[1,8.6,17.1],[2,8.2,2.63]],"ltp":9.0,"tv":1280.83,"id":10616006},{"batl":[[2,90,12.11]],"ltp":32.0,"tv":95.63,"id":9193530}],"tv":6990.66}]}
{"op":"mcm","clk":"995036811","pt":1580555106400,"mc":[{"id":"1.168133548","rc":[{"batl":[[0,7,2.27],[1,7.2,5.26],[2,7.4,5]],"ltp":6.4,"tv":656.32,"id":8231803},{"batl":[[0,9.8,3.76],[1,10,6.27]],"ltp":9.0,"tv":1280.83,"id":10616006},{"batb":[[1,5.2,11.67]],"batl":[[0,5.4,2.5],[1,5.6,7.98],[2,5.7,9.64]],"ltp":5.4,"tv":787.86,"id":17352128}]}]}
{"op":"mcm","clk":"995037095","pt":1580555107497,"mc":[{"id":"1.168133548","rc":[{"batb":[[0,7.6,20.36]],"ltp":7.8,"tv":1208.56,"id":10170404}]}]}
{"op":"mcm","clk":"995039584","pt":1580555119542,"mc":[{"id":"1.168133548","rc":[{"trd":[[9.8,81.43]],"batl":[[0,10,7.15],[1,10.5,7.2],[2,11,19.58]],"ltp":9.8,"tv":1286.59,"id":10616006}],"tv":6996.42}]}
{"op":"mcm","clk":"995039796","pt":1580555120531,"mc":[{"id":"1.168133548","rc":[{"trd":[[9.8,83.19]],"batl":[[0,10,6.27]],"ltp":9.8,"tv":1288.35,"id":10616006}],"tv":6998.18}]}
{"op":"mcm","clk":"995040015","pt":1580555121502,"mc":[{"id":"1.168133548","rc":[{"batb":[[2,8.4,3.63]],"ltp":9.8,"tv":1288.35,"id":10616006},{"batl":[[0,42,5.64],[1,44,1.36],[2,46,1.78]],"ltp":32.0,"tv":95.63,"id":9193530}]}]}
{"op":"mcm","clk":"995042215","pt":1580555132549,"mc":[{"id":"1.168133548","rc":[{"batl":[[0,9.8,1.62],[1,10,6.27],[2,10.5,7.2]],"ltp":9.8,"tv":1288.35,"id":10616006}]}]}
{"op":"mcm","clk":"995049428","pt":1580555166540,"mc":[{"id":"1.168133548","rc":[{"trd":[[5.6,132.23]],"batb":[[0,5.6,11.85]],"ltp":5.6,"tv":1549.03,"id":9417341},{"trd":[[8.6,221.91]],"batb":[[0,8.6,11.63]],"ltp":8.6,"tv":566.34,"id":15608820},{"trd":[[5.3,46.22]],"batb":[[0,5.3,18.78]],"ltp":5.3,"tv":795.66,"id":17352128}],"tv":7018.16}]}
{"op":"mcm","clk":"995049686","pt":1580555167565,"mc":[{"id":"1.168133548","rc":[{"batl":[[0,9.6,2],[1,9.8,1.62],[2,10,6.27]],"ltp":9.8,"tv":1288.35,"id":10616006}]}]}
{"op":"mcm","clk":"995049904","pt":1580555168548,"mc":[{"id":"1.168133548","rc":[{"trd":[[10.5,93.65]],"batb":[[0,10.5,1.64],[1,10,6.23],[2,9.6,4.17]],"batl":[[0,11,62.2],[1,12.5,50.29],[2,13.5,20.72]],"ltp":10.5,"tv":714.45,"id":8429550},{"trd":[[5.7,114.59]],"batl":[[0,5.7,14.61]],"ltp":5.7,"tv":1551.4,"id":9417341},{"trd":[[7,6.61]],"batl":[[0,7.2,5.26],[1,7.4,5],[2,8,5.53]],"ltp":7.0,"tv":658.93,"id":8231803},{"trd":[[9.6,76.63]],"batl":[[0,9.8,1.62],[1,10,6.27],[2,10.5,7.2]],"ltp":9.6,"tv":1290.94,"id":10616006},{"trd":[[8,246.49]],"batl":[[0,8,26.7],[2,8.4,4.07]],"ltp":8.0,"tv":1210.25,"id":10170404},{"trd":[[8.8,78.48]],"batl":[[0,9,5.96],[1,9.2,2],[2,10,5]],"ltp":8.8,"tv":568.81,"id":15608820},{"trd":[[40,4.38]],"batl":[[0,40,4.42],[1,44,1.48]],"ltp":40.0,"tv":95.97,"id":9193530},{"trd":[[29,15.87]],"batl":[[0,29,1.57]],"ltp":29.0,"tv":146.96,"id":9001159},{"trd":[[5.4,36.13]],"batb":[[1,5.2,9.67]],"batl":[[0,5.6,7.98],[1,5.7,9.64],[2,5.8,45.42]],"ltp":5.4,"tv":798.16,"id":17352128}],"tv":7035.91}]}
{"op":"mcm","clk":"995050099","pt":1580555169457,"mc":[{"id":"1.168133548","rc":[{"trd":[[10.5,95.65]],"batb":[[0,10,6.87],[1,9.6,4.17],[2,9.2,7.89]],"ltp":10.5,"tv":716.45,"id":8429550},{"batl":[[2,8.4,2.71]],"ltp":8.0,"tv":1210.25,"id":10170404},{"batb":[[1,8.4,4.85]],"batl":[[2,9.8,7.44]],"ltp":8.8,"tv":568.81,"id":15608820}],"tv":7037.91}]}
{"op":"mcm","clk":"995050713","pt":1580555172521,"mc":[{"id":"1.168133548","rc":[{"batl":[[0,11,71.24]],"ltp":10.5,"tv":716.45,"id":8429550},{"batb":[[0,8.8,1.96],[1,8.6,11.63],[2,8.4,4.85]],"ltp":8.8,"tv":568.81,"id":15608820},{"batl":[[1,32,1.69],[2,42,2.46]],"ltp":29.0,"tv":146.96,"id":9001159}]}]}
{"op":"mcm","clk":"995051149","pt":1580555174543,"mc":[{"id":"1.168133548","rc":[{"batb":[[2,8.2,9.19]],"ltp":8.8,"tv":568.81,"id":15608820},{"batl":[[2,40,2.87]],"ltp":29.0,"tv":146.96,"id":9001159}]}]}
{"op":"mcm","clk":"995051297","pt":1580555175256,"mc":[{"id":"1.168133548","rc":[{"batl":[[2,42,2.46]],"ltp":29.0,"tv":146.96,"id":9001159}]}]}
{"op":"mcm","clk":"995052694","pt":1580555182438,"mc":[{"id":"1.168133548","rc":[{"batl":[[2,40,3.88]],"ltp":29.0,"tv":146.96,"id":9001159}]}]}
{"op":"mcm","clk":"995052868","pt":1580555183450,"mc":[{"id":"1.168133548","rc":[{"batb":[[0,6.8,4.99],[1,6.6,5],[2,6.4,4.7]],"ltp":7.0,"tv":658.93,"id":8231803},{"batl":[[2,8.4,4.07]],"ltp":8.0,"tv":1210.25,"id":10170404},{"trd":[[8.8,82.4]],"batb":[[0,8.6,11.63],[1,8.2,9.19],[2,8,10]],"batl":[[0,9,6]],"ltp":8.8,"tv":572.73,"id":15608820}],"tv":7041.83}]}
{"op":"mcm","clk":"995053083","pt":1580555184568,"mc":[{"id":"1.168133548","rc":[{"batl":[[2,42,2.46]],"ltp":29.0,"tv":146.96,"id":9001159}]}]}
{"op":"mcm","clk":"995053290","pt":1580555185543,"mc":[{"id":"1.168133548","rc":[{"batb":[[1,6.6,7.28]],"ltp":7.0,"tv":658.93,"id":8231803},{"batb":[[1,8.4,4.56],[2,8.2,9.19]],"ltp":8.8,"tv":572.73,"id":15608820}]}]}
{"op":"mcm","clk":"995053592","pt":1580555187162,"mc":[{"id":"1.168133548","rc":[{"batb":[[0,5.4,3.19],[1,5.3,18.78],[2,5.2,9.67]],"ltp":5.4,"tv":798.16,"id":17352128}]}]}
{"op":"mcm","clk":"995054297","pt":1580555190554,"mc":[{"id":"1.168133548","rc":[{"batb":[[1,8.4,9.12]],"ltp":8.8,"tv":572.73,"id":15608820}]}]}
{"op":"mcm","clk":"995054893","pt":1580555193272,"mc":[{"id":"1.168133548","rc":[{"batb":[[0,6.8,6.99],[2,6.4,2.7]],"ltp":7.0,"tv":658.93,"id":8231803}]}]}
{"op":"mcm","clk":"995057015","pt":1580555203381,"mc":[{"id":"1.168133548","rc":[{"batl":[[0,7,2.48],[1,7.2,5.26],[2,7.4,5]],"ltp":7.0,"tv":658.93,"id":8231803},{"batl":[[0,38,3.86]],"ltp":40.0,"tv":95.97,"id":9193530}]}]}
{"op":"mcm","clk":"995061585","pt":1580555226500,"mc":[{"id":"1.168133548","rc":[{"batb":[[0,9,2.63],[1,8.8,9.19],[2,8.6,17.1]],"ltp":9.6,"tv":1290.94,"id":10616006}]}]}
{"op":"mcm","clk":"995063019","pt":1580555233537,"mc":[{"id":"1.168133548","rc":[{"batl":[[0,7.2,5.26],[1,7.4,5],[2,8,5.53]],"ltp":7.0,"tv":658.93,"id":8231803},{"batl":[[0,36,2.92]],"ltp":40.0,"tv":95.97,"id":9193530}]}]}
{"op":"mcm","clk":"995077982","pt":1580555253544,"mc":[{"id":"1.168133548","rc":[{"batl":[[1,8.2,39.49],[2,8.4,1.36]],"ltp":8.0,"tv":1210.25,"id":10170404}]}]}
{"op":"mcm","clk":"995078875","pt":1580555257448,"mc":[{"id":"1.168133548","rc":[{"batl":[[0,8,29.41],[1,8.2,42.2]],"ltp":8.0,"tv":1210.25,"id":10170404}]}]}
{"op":"mcm","clk":"995079083","pt":1580555258530,"mc":[{"id":"1.168133548","rc":[{"batl":[[2,8.4,4.07]],"ltp":8.0,"tv":1210.25,"id":10170404}]}]}
{"op":"mcm","clk":"995082443","pt":1580555274567,"mc":[{"id":"1.168133548","rc":[{"batl":[[1,32,1.16]],"ltp":29.0,"tv":146.96,"id":9001159}]}]}
{"op":"mcm","clk":"995082911","pt":1580555276560,"mc":[{"id":"1.168133548","rc":[{"batl":[[0,7,2.15],[1,7.2,5.26],[2,7.4,5]],"ltp":7.0,"tv":658.93,"id":8231803},{"batl":[[0,34,2.85]],"ltp":40.0,"tv":95.97,"id":9193530},{"batl":[[2,40,3]],"ltp":29.0,"tv":146.96,"id":9001159}]}]}
{"op":"mcm","clk":"995083380","pt":1580555278574,"mc":[{"id":"1.168133548","rc":[{"batl":[[2,42,2.46]],"ltp":29.0,"tv":146.96,"id":9001159}]}]}
{"op":"mcm","clk":"995084760","pt":1580555285203,"mc":[{"id":"1.168133548","rc":[{"trd":[[7,13.69]],"batl":[[0,7,1.83]],"ltp":7.0,"tv":666.01,"id":8231803}],"tv":7048.91}]}
{"op":"mcm","clk":"995087371","pt":1580555298551,"mc":[{"id":"1.168133548","rc":[{"batl":[[1,44,1.12]],"ltp":40.0,"tv":95.97,"id":9193530}]}]}
{"op":"mcm","clk":"995089997","pt":1580555312042,"mc":[{"id":"1.168133548","rc":[{"batb":[[1,8.4,4.56]],"ltp":8.8,"tv":572.73,"id":15608820}]}]}
{"op":"mcm","clk":"995090276","pt":1580555313548,"mc":[{"id":"1.168133548","rc":[{"batl":[[0,7.2,5.26],[1,7.4,5],[2,8,5.53]],"ltp":7.0,"tv":666.01,"id":8231803},{"batl":[[0,44,1.12],[1,46,1.78],[2,90,15.11]],"ltp":40.0,"tv":95.97,"id":9193530}]}]}
{"op":"mcm","clk":"995090443","pt":1580555314521,"mc":[{"id":"1.168133548","rc":[{"batb":[[1,8.4,9.12]],"ltp":8.8,"tv":572.73,"id":15608820},{"batl":[[2,90,12.11]],"ltp":40.0,"tv":95.97,"id":9193530}]}]}
{"op":"mcm","clk":"995090839","pt":1580555316514,"mc":[{"id":"1.168133548","rc":[{"batb":[[0,9,4.55]],"ltp":9.6,"tv":1290.94,"id":10616006},{"batb":[[0,30,7.24]],"batl":[[2,90,9.08]],"ltp":40.0,"tv":95.97,"id":9193530}]}]}
{"op":"mcm","clk":"995092090","pt":1580555323324,"mc":[{"id":"1.168133548","rc":[{"batl":[[0,10,6.27],[1,10.5,7.2],[2,11,19.58]],"ltp":9.6,"tv":1290.94,"id":10616006}]}]}
{"op":"mcm","clk":"995096403","pt":1580555346544,"mc":[{"id":"1.168133548","rc":[{"batl":[[0,7,2.77],[1,7.2,5.26],[2,7.4,5]],"ltp":7.0,"tv":666.01,"id":8231803},{"batl":[[0,42,3.79],[1,44,1],[2,46,1.78]],"ltp":40.0,"tv":95.97,"id":9193530}]}]}
{"op":"mcm","clk":"995097185","pt":1580555350526,"mc":[{"id":"1.168133548","rc":[{"trd":[[11,107.44]],"batl":[[0,11,69.24]],"ltp":11.0,"tv":720.45,"id":8429550}],"tv":7052.91}]}
{"op":"mcm","clk":"995097924","pt":1580555354150,"mc":[{"id":"1.168133548","rc":[{"batb":[[0,26,2.78],[1,25,4.59],[2,22,3.16]],"ltp":29.0,"tv":146.96,"id":9001159}]}]}
{"op":"mcm","clk":"995099853","pt":1580555364228,"mc":[{"id":"1.168133548","rc":[{"trd":[[11,116.12]],"batl":[[0,11,64.9]],"ltp":11.0,"tv":729.13,"id":8429550}],"tv":7061.59}]}
{"op":"mcm","clk":"995102307","pt":1580555376542,"mc":[{"id":"1.168133548","rc":[{"batl":[[0,7.2,5.26],[1,7.4,5],[2,8,5.53]],"ltp":7.0,"tv":666.01,"id":8231803},{"batl":[[0,40,2.7],[1,44,1.12]],"ltp":40.0,"tv":95.97,"id":9193530}]}]}
{"op":"mcm","clk":"995105513","pt":1580555392462,"mc":[{"id":"1.168133548","rc":[{"batb":[[0,10,8.89]],"ltp":11.0,"tv":729.13,"id":8429550}]}]}
{"op":"mcm","clk":"995108080","pt":1580555405474,"mc":[{"id":"1.168133548","rc":[{"batb":[[0,7.8,2.21],[1,7.6,20.36],[2,7.4,20.56]],"batl":[[0,8,30.84]],"ltp":8.0,"tv":1210.25,"id":10170404}]}]}
{"op":"mcm","clk":"995108278","pt":1580555406566,"mc":[{"id":"1.168133548","rc":[{"batl":[[0,7,2.42],[1,7.2,5.26],[2,7.4,5]],"ltp":7.0,"tv":666.01,"id":8231803},{"batb":[[2,7.4,15.4]],"ltp":8.0,"tv":1210.25,"id":10170404},{"batl":[[0,38,2.66]],"ltp":40.0,"tv":95.97,"id":9193530}]}]}
{"op":"mcm","clk":"995108669","pt":1580555408567,"mc":[{"id":"1.168133548","rc":[{"batl":[[1,7.2,17.26]],"ltp":7.0,"tv":666.01,"id":8231803},{"batl":[[0,9,18]],"ltp":8.8,"tv":572.73,"id":15608820}]}]}
{"op":"mcm","clk":"995108766","pt":1580555409047,"mc":[{"id":"1.168133548","rc":[{"batl":[[0,7,9.67]],"ltp":7.0,"tv":666.01,"id":8231803}]}]}
{"op":"mcm","clk":"995109090","pt":1580555410572,"mc":[{"id":"1.168133548","rc":[{"batl":[[2,9.8,14.87]],"ltp":8.8,"tv":572.73,"id":15608820}]}]}
{"op":"mcm","clk":"995109706","pt":1580555413549,"mc":[{"id":"1.168133548","rc":[{"batl":[[2,9.8,22.31]],"ltp":8.8,"tv":572.73,"id":15608820}]}]}
{"op":"mcm","clk":"995109885","pt":1580555414425,"mc":[{"id":"1.168133548","rc":[{"batb":[[1,9.8,4.08]],"ltp":11.0,"tv":729.13,"id":8429550}]}]}
{"op":"mcm","clk":"995110684","pt":1580555418463,"mc":[{"id":"1.168133548","rc":[{"batb":[[0,5.5,7.2],[1,5.4,3.19],[2,5.3,18.78]],"ltp":5.4,"tv":798.16,"id":17352128}]}]}
{"op":"mcm","clk":"995111040","pt":1580555420245,"mc":[{"id":"1.168133548","rc":[{"batl":[[1,12.5,56.93]],"ltp":11.0,"tv":729.13,"id":8429550}]}]}
{"op":"mcm","clk":"995114137","pt":1580555436497,"mc":[{"id":"1.168133548","rc":[{"batl":[[0,7,7.25]],"ltp":7.0,"tv":666.01,"id":8231803},{"batl":[[0,44,1.12],[1,46,1.78],[2,90,12.08]],"ltp":40.0,"tv":95.97,"id":9193530}]}]}
{"op":"mcm","clk":"995115581","pt":1580555443511,"mc":[{"id":"1.168133548","rc":[{"batl":[[0,7,19.25],[1,7.2,5.26]],"ltp":7.0,"tv":666.01,"id":8231803},{"batl":[[0,8.8,12.04],[1,9,5.96],[2,9.2,2]],"ltp":8.8,"tv":572.73,"id":15608820}]}]}
{"op":"mcm","clk":"995115753","pt":1580555444428,"mc":[{"id":"1.168133548","rc":[{"trd":[[11,136.72]],"batl":[[0,11,54.6]],"ltp":11.0,"tv":749.73,"id":8429550},{"batb":[[0,5.6,33.85]],"ltp":5.7,"tv":1551.4,"id":9417341},{"batb":[[2,6.4,22.7]],"batl":[[0,7,12]],"ltp":7.0,"tv":666.01,"id":8231803},{"batb":[[0,9.2,12.4],[1,9,4.55],[2,8.8,9.19]],"ltp":9.6,"tv":1290.94,"id":10616006},{"batb":[[2,7.4,31.09]],"ltp":8.0,"tv":1210.25,"id":10170404},{"trd":[[8.8,106.48]],"batb":[[0,8.6,12.49]],"batl":[[0,9,5.96],[1,9.2,2],[2,9.8,22.31]],"ltp":8.8,"tv":596.81,"id":15608820},{"batb":[[2,26,5.77]],"ltp":40.0,"tv":95.97,"id":9193530},{"batb":[[2,24,5.29]],"ltp":29.0,"tv":146.96,"id":9001159}],"tv":7106.27}]}
{"op":"mcm","clk":"995115937","pt":1580555445448,"mc":[{"id":"1.168133548","rc":[{"batb":[[1,5.4,29.3]],"ltp":5.7,"tv":1551.4,"id":9417341}]}]}
{"op":"mcm","clk":"995116099","pt":1580555446334,"mc":[{"id":"1.168133548","rc":[{"batl":[[2,9.8,7.44]],"ltp":8.8,"tv":596.81,"id":15608820}]}]}
{"op":"mcm","clk":"995116730","pt":1580555449519,"mc":[{"id":"1.168133548","rc":[{"batb":[[0,9.2,14.4]],"ltp":9.6,"tv":1290.94,"id":10616006}]}]}
{"op":"mcm","clk":"995117685","pt":1580555454544,"mc":[{"id":"1.168133548","rc":[{"batb":[[2,8.6,17.1]],"batl":[[0,10.5,7.32],[1,11,19.58],[2,11.5,10.44]],"ltp":9.6,"tv":1290.94,"id":10616006}]}]}
{"op":"mcm","clk":"995117904","pt":1580555455526,"mc":[{"id":"1.168133548","rc":[{"batl":[[1,11,21.74]],"ltp":9.6,"tv":1290.94,"id":10616006}]}]}
{"op":"mcm","clk":"995118084","pt":1580555456507,"mc":[{"id":"1.168133548","rc":[{"batl":[[1,11,19.58]],"ltp":9.6,"tv":1290.94,"id":10616006}]}]}
{"op":"mcm","clk":"995118302","pt":1580555457543,"mc":[{"id":"1.168133548","rc":[{"batl":[[0,11,59.6]],"ltp":11.0,"tv":749.73,"id":8429550}]}]}
{"op":"mcm","clk":"995119095","pt":1580555461538,"mc":[{"id":"1.168133548","rc":[{"trd":[[7.8,139.71]],"batb":[[0,7.6,20.36],[1,7.4,31.09],[2,7.2,21]],"batl":[[0,7.8,12.79],[1,8,29.41],[2,8.2,43.59]],"ltp":7.8,"tv":1214.67,"id":10170404}],"tv":7110.69}]}
{"op":"mcm","clk":"995119172","pt":1580555461916,"mc":[{"id":"1.168133548","rc":[{"batl":[[2,60,2]],"ltp":40.0,"tv":95.97,"id":9193530}]}]}
{"op":"mcm","clk":"995119485","pt":1580555463550,"mc":[{"id":"1.168133548","rc":[{"trd":[[9.4,22.1]],"batb":[[0,9.4,1.92],[1,9.2,14.4],[2,9,2.42]],"batl":[[0,10,6.27],[1,10.5,7.2],[2,11,19.58]],"ltp":9.4,"tv":1291.18,"id":10616006},{"batb":[[1,7.4,36.25]],"batl":[[2,8.2,40.01]],"ltp":7.8,"tv":1214.67,"id":10170404}],"tv":7110.93}]}
{"op":"mcm","clk":"995120179","pt":1580555466522,"mc":[{"id":"1.168133548","rc":[{"batl":[[0,42,4.25],[1,44,1],[2,46,1.78]],"ltp":40.0,"tv":95.97,"id":9193530}]}]}
{"op":"mcm","clk":"995126015","pt":1580555493419,"mc":[{"id":"1.168133548","rc":[{"trd":[[32,22.16]],"batb":[[0,30,6.7]],"batl":[[0,42,4.71]],"ltp":32.0,"tv":97.05,"id":9193530}],"tv":7112.01}]}
{"op":"mcm","clk":"995127083","pt":1580555498530,"mc":[{"id":"1.168133548","rc":[{"trd":[[30,2.23]],"batb":[[0,30,6.24]],"batl":[[0,42,4.25]],"ltp":30.0,"tv":97.97,"id":9193530}],"tv":7112.93}]}
{"op":"mcm","clk":"995127290","pt":1580555499556,"mc":[{"id":"1.168133548","rc":[{"batl":[[0,40,5.43],[1,44,1.12]],"ltp":30.0,"tv":97.97,"id":9193530}]}]}
{"op":"mcm","clk":"995131385","pt":1580555518436,"mc":[{"id":"1.168133548","rc":[{"trd":[[8.8,108.2]],"batb":[[0,8.6,11.63]],"batl":[[0,8.8,1.14],[1,9,5.96],[2,9.2,2]],"ltp":8.8,"tv":598.53,"id":15608820}],"tv":7114.65}]}
{"op":"mcm","clk":"995134034","pt":1580555531496,"mc":[{"id":"1.168133548","rc":[{"batl":[[0,44,1.12],[1,46,1.78],[2,55,9.41]],"ltp":30.0,"tv":97.97,"id":9193530}]}]}
{"op":"mcm","clk":"995134242","pt":1580555532490,"mc":[{"id":"1.168133548","rc":[{"batl":[[0,38,4.64],[1,44,1.12],[2,46,1.78]],"ltp":30.0,"tv":97.97,"id":9193530}]}]}
{"op":"mcm","clk":"995138873","pt":1580555553565,"mc":[{"id":"1.168133548","rc":[{"batb":[[1,9.8,6.91]],"ltp":11.0,"tv":749.73,"id":8429550},{"trd":[[5.7,124.31]],"batl":[[0,5.7,9.75]],"ltp":5.7,"tv":1561.12,"id":9417341},{"trd":[[6.8,27.17]],"batb":[[0,6.6,11.47],[1,6.4,22.7],[2,6.2,12.08]],"ltp":6.8,"tv":679.99,"id":8231803}],"tv":7138.35}]}
{"op":"mcm","clk":"995139082","pt":1580555554538,"mc":[{"id":"1.168133548","rc":[{"batb":[[1,9.8,13.89]],"ltp":11.0,"tv":749.73,"id":8429550},{"trd":[[5.7,148.1]],"batb":[[0,5.6,33.97]],"batl":[[0,5.8,17.88],[1,5.9,20],[2,6,84.29]],"ltp":5.7,"tv":1584.91,"id":9417341},{"batb":[[0,9.4,12.15]],"ltp":9.4,"tv":1291.18,"id":10616006},{"trd":[[7.8,168.25]],"batb":[[0,7.8,5.71],[1,7.6,20.36],[2,7.4,36.25]],"batl":[[0,8,29.41],[1,8.2,38.62],[2,8.4,2.71]],"ltp":7.8,"tv":1243.21,"id":10170404},{"trd":[[8.8,110.48]],"batb":[[0,8.8,9.79],[1,8.6,11.63],[2,8.4,9.12]],"batl":[[0,9,5.96],[1,9.2,2],[2,9.8,7.44]],"ltp":8.8,"tv":600.81,"id":15608820},{"batb":[[0,32,3.01],[1,30,6.24],[2,27,1.84]],"ltp":30.0,"tv":97.97,"id":9193530},{"batb":[[0,27,3.56],[1,26,2.78],[2,25,4.59]],"ltp":29.0,"tv":146.96,"id":9001159},{"batb":[[0,5.5,24.69]],"ltp":5.4,"tv":798.16,"id":17352128}],"tv":7192.96}]}
{"op":"mcm","clk":"995139276","pt":1580555555461,"mc":[{"id":"1.168133548","rc":[{"trd":[[5.7,148.34]],"batb":[[0,5.6,33.85]],"ltp":5.7,"tv":1585.15,"id":9417341},{"batb":[[0,6.6,9.2],[1,6.4,25.29]],"ltp":6.8,"tv":679.99,"id":8231803},{"batb":[[2,7.4,31.09]],"batl":[[1,8.2,41.86]],"ltp":7.8,"tv":1243.21,"id":10170404},{"batb":[[2,8.2,9.19]],"ltp":8.8,"tv":600.81,"id":15608820}],"tv":7193.2}]}
{"op":"mcm","clk":"995139478","pt":1580555556435,"mc":[{"id":"1.168133548","rc":[{"batb":[[1,6.4,27.46]],"ltp":6.8,"tv":679.99,"id":8231803},{"batb":[[1,8.6,15.49]],"batl":[[2,10,5]],"ltp":8.8,"tv":600.81,"id":15608820}]}]}
{"op":"mcm","clk":"995139914","pt":1580555558472,"mc":[{"id":"1.168133548","rc":[{"batb":[[1,6.4,29.63]],"ltp":6.8,"tv":679.99,"id":8231803},{"batb":[[1,7.6,25.62],[2,7.4,25.69]],"ltp":7.8,"tv":1243.21,"id":10170404},{"batl":[[2,9.8,7.44]],"ltp":8.8,"tv":600.81,"id":15608820}]}]}
{"op":"mcm","clk":"995141027","pt":1580555563467,"mc":[{"id":"1.168133548","rc":[{"batl":[[0,36,2.17]],"ltp":30.0,"tv":97.97,"id":9193530}]}]}
{"op":"mcm","clk":"995142306","pt":1580555569572,"mc":[{"id":"1.168133548","rc":[{"batl":[[2,42,10.13]],"ltp":29.0,"tv":146.96,"id":9001159}]}]}
{"op":"mcm","clk":"995144155","pt":1580555578367,"mc":[{"id":"1.168133548","rc":[{"trd":[[8.8,114.48]],"batb":[[0,8.8,7.79]],"ltp":8.8,"tv":604.81,"id":15608820}],"tv":7197.2}]}
{"op":"mcm","clk":"995145562","pt":1580555585498,"mc":[{"id":"1.168133548","rc":[{"batb":[[0,7.8,10.51]],"ltp":7.8,"tv":1243.21,"id":10170404}]}]}
{"op":"mcm","clk":"995145794","pt":1580555586526,"mc":[{"id":"1.168133548","rc":[{"batb":[[0,9.6,1.8],[1,9.4,12.15],[2,9.2,14.4]],"ltp":9.4,"tv":1291.18,"id":10616006}]}]}
{"op":"mcm","clk":"995146213","pt":1580555588504,"mc":[{"id":"1.168133548","rc":[{"batb":[[1,5.4,7.19]],"ltp":5.7,"tv":1585.15,"id":9417341},{"batb":[[2,25,1.59]],"ltp":29.0,"tv":146.96,"id":9001159}]}]}
{"op":"mcm","clk":"995146431","pt":1580555589516,"mc":[{"id":"1.168133548","rc":[{"batb":[[0,27,6.56]],"ltp":29.0,"tv":146.96,"id":9001159}]}]}
{"op":"mcm","clk":"995147055","pt":1580555592506,"mc":[{"id":"1.168133548","rc":[{"batb":[[1,5.4,26.67]],"ltp":5.7,"tv":1585.15,"id":9417341},{"trd":[[9.4,22.5],[9.6,80.23]],"batb":[[0,9.4,11.95],[1,9.2,14.4],[2,8.6,17.6]],"ltp":9.4,"tv":1295.18,"id":10616006}],"tv":7201.19}]}
{"op":"mcm","clk":"995147266","pt":1580555593529,"mc":[{"id":"1.168133548","rc":[{"batl":[[0,34,2.07]],"ltp":30.0,"tv":97.97,"id":9193530}]}]}
{"op":"mcm","clk":"995147462","pt":1580555594454,"mc":[{"id":"1.168133548","rc":[{"batb":[[1,5.4,31.06]],"ltp":5.7,"tv":1585.15,"id":9417341}]}]}
{"op":"mcm","clk":"995148852","pt":1580555601339,"mc":[{"id":"1.168133548","rc":[{"trd":[[6.6,86.75]],"batb":[[0,6.6,5.2]],"ltp":6.6,"tv":687.99,"id":8231803}],"tv":7209.19}]}
{"op":"mcm","clk":"995149739","pt":1580555605456,"mc":[{"id":"1.168133548","rc":[{"batb":[[1,6.4,24.76]],"ltp":6.6,"tv":687.99,"id":8231803}]}]}
{"op":"mcm","clk":"995152462","pt":1580555619273,"mc":[{"id":"1.168133548","rc":[{"batb":[[0,6.6,7.2]],"ltp":6.6,"tv":687.99,"id":8231803},{"trd":[[9.4,34.5]],"batb":[[0,9.4,5.95]],"ltp":9.4,"tv":1307.18,"id":10616006}],"tv":7221.19}]}
{"op":"mcm","clk":"995153249","pt":1580555623204,"mc":[{"id":"1.168133548","rc":[{"batl":[[0,44,1.12],[1,46,1.78],[2,80,2]],"ltp":30.0,"tv":97.97,"id":9193530}]}]}
{"op":"mcm","clk":"995154707","pt":1580555630432,"mc":[{"id":"1.168133548","rc":[{"trd":[[8.8,118.47]],"batb":[[0,8.8,5.79]],"ltp":8.8,"tv":608.8,"id":15608820}],"tv":7225.19}]}
{"op":"mcm","clk":"995161609","pt":1580555664496,"mc":[{"id":"1.168133548","rc":[{"batl":[[0,5.7,2],[1,5.8,10],[2,5.9,20]],"ltp":5.7,"tv":1585.15,"id":9417341}]}]}
{"op":"mcm","clk":"995161819","pt":1580555665569,"mc":[{"id":"1.168133548","rc":[{"batl":[[0,42,3.13],[1,44,1],[2,46,1.78]],"ltp":30.0,"tv":97.97,"id":9193530},{"batb":[[0,5.5,25.69]],"batl":[[0,5.6,8.98]],"ltp":5.4,"tv":798.16,"id":17352128}]}]}
{"op":"mcm","clk":"995163251","pt":1580555672509,"mc":[{"id":"1.168133548","rc":[{"trd":[[8.8,122.47]],"batb":[[0,8.8,3.79]],"ltp":8.8,"tv":612.8,"id":15608820}],"tv":7229.19}]}
{"op":"mcm","clk":"995163860","pt":1580555675419,"mc":[{"id":"1.168133548","rc":[{"trd":[[6.8,31.17]],"batl":[[0,6.8,10]],"ltp":6.8,"tv":691.99,"id":8231803},{"batb":[[1,8.6,11.63]],"ltp":8.8,"tv":612.8,"id":15608820}],"tv":7233.19}]}
{"op":"mcm","clk":"995164488","pt":1580555678462,"mc":[{"id":"1.168133548","rc":[{"batb":[[0,27,7.18],[1,26,2.11]],"ltp":29.0,"tv":146.96,"id":9001159}]}]}
{"op":"mcm","clk":"995164873","pt":1580555680494,"mc":[{"id":"1.168133548","rc":[{"batl":[[0,7,10]],"ltp":6.8,"tv":691.99,"id":8231803}]}]}
{"op":"mcm","clk":"995165054","pt":1580555681469,"mc":[{"id":"1.168133548","rc":[{"batl":[[2,7.4,13.44]],"ltp":6.8,"tv":691.99,"id":8231803}]}]}
{"op":"mcm","clk":"995165249","pt":1580555682485,"mc":[{"id":"1.168133548","rc":[{"batl":[[2,7.4,5]],"ltp":6.8,"tv":691.99,"id":8231803}]}]}
{"op":"mcm","clk":"995167210","pt":1580555692429,"mc":[{"id":"1.168133548","rc":[{"trd":[[8.8,130.06]],"batb":[[0,8.6,11.63],[1,8.2,9.19],[2,8,10]],"ltp":8.8,"tv":620.39,"id":15608820}],"tv":7240.77}]}
{"op":"mcm","clk":"995167476","pt":1580555693513,"mc":[{"id":"1.168133548","rc":[{"batb":[[1,8.2,14.73]],"ltp":8.8,"tv":620.39,"id":15608820}]}]}
{"op":"mcm","clk":"995168082","pt":1580555696414,"mc":[{"id":"1.168133548","rc":[{"batb":[[1,8.4,4.56],[2,8.2,14.73]],"ltp":8.8,"tv":620.39,"id":15608820}]}]}
{"op":"mcm","clk":"995168513","pt":1580555698510,"mc":[{"id":"1.168133548","rc":[{"batl":[[0,8.8,2.13],[1,9,5.96],[2,9.2,2]],"ltp":8.8,"tv":620.39,"id":15608820},{"batl":[[0,40,3.01],[1,44,1.12]],"ltp":30.0,"tv":97.97,"id":9193530}]}]}
{"op":"mcm","clk":"995170323","pt":1580555707523,"mc":[{"id":"1.168133548","rc":[{"trd":[[7.8,189.27]],"batb":[[0,7.6,25.62],[1,7.4,25.69],[2,7.2,21]],"batl":[[0,7.8,9.49],[1,8,29.41],[2,8.2,41.86]],"ltp":7.8,"tv":1264.23,"id":10170404}],"tv":7261.79}]}
{"op":"mcm","clk":"995170705","pt":1580555709393,"mc":[{"id":"1.168133548","rc":[{"batb":[[1,7.4,30.85]],"ltp":7.8,"tv":1264.23,"id":10170404}]}]}
{"op":"mcm","clk":"995171887","pt":1580555715452,"mc":[{"id":"1.168133548","rc":[{"trd":[[6.6,90.75]],"batb":[[0,6.6,5.2]],"ltp":6.6,"tv":695.99,"id":8231803},{"trd":[[5.5,34.32]],"batb":[[0,5.5,23.69]],"ltp":5.5,"tv":802.16,"id":17352128}],"tv":7269.79}]}
{"op":"mcm","clk":"995173207","pt":1580555722519,"mc":[{"id":"1.168133548","rc":[{"batl":[[0,8.8,4.13]],"ltp":8.8,"tv":620.39,"id":15608820}]}]}
{"op":"mcm","clk":"995176259","pt":1580555737570,"mc":[{"id":"1.168133548","rc":[{"batl":[[0,8.8,2]],"ltp":8.8,"tv":620.39,"id":15608820},{"batl":[[0,38,3.01]],"ltp":30.0,"tv":97.97,"id":9193530}]}]}
{"op":"mcm","clk":"995177925","pt":1580555745499,"mc":[{"id":"1.168133548","rc":[{"batb":[[2,6.2,18.53]],"ltp":6.6,"tv":695.99,"id":8231803}]}]}
{"op":"mcm","clk":"995179669","pt":1580555754160,"mc":[{"id":"1.168133548","rc":[{"trd":[[9.4,38.5]],"batb":[[0,9.4,3.95]],"ltp":9.4,"tv":1311.18,"id":10616006}],"tv":7273.79}]}
{"op":"mcm","clk":"995181212","pt":1580555761483,"mc":[{"id":"1.168133548","rc":[{"trd":[[27,42.84],[28,1.22]],"batb":[[0,27,2.18]],"ltp":27.0,"tv":156.95,"id":9001159}],"tv":7283.78}]}
{"op":"mcm","clk":"995182474","pt":1580555767501,"mc":[{"id":"1.168133548","rc":[{"trd":[[11,154.98]],"batl":[[0,11,50.47]],"ltp":11.0,"tv":767.99,"id":8429550}],"tv":7302.04}]}
{"op":"mcm","clk":"995182684","pt":1580555768468,"mc":[{"id":"1.168133548","rc":[{"batl":[[0,36,2.27]],"ltp":30.0,"tv":97.97,"id":9193530}]}]}
{"op":"mcm","clk":"995184135","pt":1580555775491,"mc":[{"id":"1.168133548","rc":[{"batl":[[1,7.2,5]],"ltp":6.6,"tv":695.99,"id":8231803}]}]}
{"op":"mcm","clk":"995184362","pt":1580555776555,"mc":[{"id":"1.168133548","rc":[{"batl":[[0,7,10.27]],"ltp":6.6,"tv":695.99,"id":8231803},{"batb":[[2,8.6,14.57]],"batl":[[1,10.5,5.05]],"ltp":9.4,"tv":1311.18,"id":10616006},{"batl":[[1,8,27.71]],"ltp":7.8,"tv":1264.23,"id":10170404}]}]}
{"op":"mcm","clk":"995184974","pt":1580555779553,"mc":[{"id":"1.168133548","rc":[{"batl":[[0,5.7,5]],"ltp":5.7,"tv":1585.15,"id":9417341},{"batl":[[1,32,1.69]],"ltp":27.0,"tv":156.95,"id":9001159}]}]}
{"op":"mcm","clk":"995185371","pt":1580555781445,"mc":[{"id":"1.168133548","rc":[{"batl":[[2,40,4.26]],"ltp":27.0,"tv":156.95,"id":9001159}]}]}
{"op":"mcm","clk":"995185592","pt":1580555782531,"mc":[{"id":"1.168133548","rc":[{"batl":[[2,42,2.46]],"ltp":27.0,"tv":156.95,"id":9001159}]}]}
{"op":"mcm","clk":"995187952","pt":1580555793538,"mc":[{"id":"1.168133548","rc":[{"trd":[[7.6,220.96]],"batb":[[0,7.6,17.63]],"ltp":7.6,"tv":1280.22,"id":10170404}],"tv":7318.04}]}
{"op":"mcm","clk":"995188704","pt":1580555797563,"mc":[{"id":"1.168133548","rc":[{"batb":[[0,32,3.54]],"ltp":30.0,"tv":97.97,"id":9193530}]}]}
{"op":"mcm","clk":"995189231","pt":1580555799547,"mc":[{"id":"1.168133548","rc":[{"batb":[[2,5.3,20]],"ltp":5.7,"tv":1585.15,"id":9417341}]}]}
{"op":"mcm","clk":"995192295","pt":1580555813487,"mc":[{"id":"1.168133548","rc":[{"batb":[[1,30,8.84]],"ltp":30.0,"tv":97.97,"id":9193530}]}]}
{"op":"mcm","clk":"995196650","pt":1580555832468,"mc":[{"id":"1.168133548","rc":[{"trd":[[11,155.15]],"batl":[[0,11,50.3]],"ltp":11.0,"tv":768.16,"id":8429550},{"trd":[[5.7,148.67]],"batl":[[0,5.7,4.67]],"ltp":5.7,"tv":1585.48,"id":9417341},{"trd":[[6.8,31.45]],"batl":[[0,7,10]],"ltp":6.8,"tv":696.26,"id":8231803},{"trd":[[9.4,42.12],[9.6,80.42]],"batb":[[0,9.4,2.14]],"ltp":9.4,"tv":1314.99,"id":10616006},{"trd":[[7.8,189.51]],"batl":[[0,7.8,9.25]],"ltp":7.8,"tv":1280.46,"id":10170404},{"trd":[[8.8,133.85]],"batl":[[0,9,5.96],[1,9.2,2],[2,9.8,3.38]],"ltp":8.8,"tv":624.18,"id":15608820},{"trd":[[36,4.44]],"batl":[[0,36,2.22]],"ltp":36.0,"tv":98.02,"id":9193530},{"trd":[[29,15.93]],"batl":[[0,29,1.51]],"ltp":29.0,"tv":157.01,"id":9001159},{"trd":[[5.6,20.65]],"batl":[[0,5.6,8.65]],"ltp":5.6,"tv":802.49,"id":17352128}],"tv":7327.09}]}
{"op":"mcm","clk":"995197850","pt":1580555838492,"mc":[{"id":"1.168133548","rc":[{"batl":[[2,9.8,10.81]],"ltp":8.8,"tv":624.18,"id":15608820}]}]}
{"op":"mcm","clk":"995200748","pt":1580555851509,"mc":[{"id":"1.168133548","rc":[{"batl":[[0,8.8,2],[1,9,5.96],[2,9.2,2]],"ltp":8.8,"tv":624.18,"id":15608820}]}]}
{"op":"mcm","clk":"995201969","pt":1580555856423,"mc":[{"id":"1.168133548","rc":[{"trd":[[32,29.25]],"batb":[[0,30,8.84],[1,27,1.84],[2,26,5.77]],"ltp":32.0,"tv":105.11,"id":9193530}],"tv":7334.19}]}
{"op":"mcm","clk":"995202285","pt":1580555857509,"mc":[{"id":"1.168133548","rc":[{"batb":[[0,30,6.24],[1,28,3.94],[2,27,1.66]],"ltp":32.0,"tv":105.11,"id":9193530}]}]}
{"op":"mcm","clk":"995205018","pt":1580555869554,"mc":[{"id":"1.168133548","rc":[{"batl":[[1,8,25],[2,8.2,39.15]],"ltp":7.8,"tv":1280.46,"id":10170404}]}]}
{"op":"mcm","clk":"995205419","pt":1580555871443,"mc":[{"id":"1.168133548","rc":[{"batb":[[1,28,7.69]],"batl":[[0,34,2.53]],"ltp":32.0,"tv":105.11,"id":9193530}]}]}
{"op":"mcm","clk":"995205867","pt":1580555873556,"mc":[{"id":"1.168133548","rc":[{"batl":[[0,7.8,11.96],[1,8,27.71],[2,8.2,41.86]],"ltp":7.8,"tv":1280.46,"id":10170404}]}]}
{"op":"mcm","clk":"995206387","pt":1580555875567,"mc":[{"id":"1.168133548","rc":[{"batl":[[0,9.8,2.83],[1,10,6.27],[2,10.5,2]],"ltp":9.4,"tv":1314.99,"id":10616006}]}]}
{"op":"mcm","clk":"995206830","pt":1580555877573,"mc":[{"id":"1.168133548","rc":[{"trd":[[9.4,46.12]],"batb":[[0,9.2,14.54],[1,8.6,14.57],[2,8,51.94]],"ltp":9.4,"tv":1318.99,"id":10616006}],"tv":7338.19}]}
{"op":"mcm","clk":"995206945","pt":1580555878063,"mc":[{"id":"1.168133548","rc":[{"batb":[[1,8.8,3.59],[2,8.6,14.07]],"ltp":9.4,"tv":1318.99,"id":10616006}]}]}
{"op":"mcm","clk":"995207709","pt":1580555881570,"mc":[{"id":"1.168133548","rc":[{"batb":[[0,9.6,2],[1,9.2,14.54],[2,8.8,3.59]],"ltp":9.4,"tv":1318.99,"id":10616006}]}]}
{"op":"mcm","clk":"995207912","pt":1580555882486,"mc":[{"id":"1.168133548","rc":[{"batb":[[2,8.6,14.57]],"ltp":9.4,"tv":1318.99,"id":10616006}]}]}
{"op":"mcm","clk":"995208144","pt":1580555883569,"mc":[{"id":"1.168133548","rc":[{"batb":[[2,8.8,7.64]],"ltp":9.4,"tv":1318.99,"id":10616006}]}]}
{"op":"mcm","clk":"995209062","pt":1580555887416,"mc":[{"id":"1.168133548","rc":[{"trd":[[5.7,158.01]],"batb":[[0,5.7,12.35],[1,5.6,33.85],[2,5.4,31.06]],"batl":[[0,5.8,10],[1,5.9,20],[2,6,84.29]],"ltp":5.7,"tv":1594.82,"id":9417341}],"tv":7347.53}]}
{"op":"mcm","clk":"995209281","pt":1580555888393,"mc":[{"id":"1.168133548","rc":[{"batb":[[2,5.4,7.19]],"ltp":5.7,"tv":1594.82,"id":9417341}]}]}
{"op":"mcm","clk":"995209553","pt":1580555889428,"mc":[{"id":"1.168133548","rc":[{"batb":[[2,5.5,2]],"ltp":5.7,"tv":1594.82,"id":9417341}]}]}
{"op":"mcm","clk":"995212566","pt":1580555902528,"mc":[{"id":"1.168133548","rc":[{"trd":[[9.6,84.42],[9.8,88.85]],"batb":[[0,9.2,14.54],[1,8.8,7.64],[2,8.6,14.07]],"batl":[[0,10.5,8.08],[1,11,19.58],[2,11.5,15.28]],"ltp":9.6,"tv":1328.65,"id":10616006}],"tv":7357.19}]}
{"op":"mcm","clk":"995213031","pt":1580555904542,"mc":[{"id":"1.168133548","rc":[{"batb":[[1,8.6,14.57],[2,8,51.94]],"batl":[[2,11.5,10.44]],"ltp":9.6,"tv":1328.65,"id":10616006}]}]}
{"op":"mcm","clk":"995213914","pt":1580555908428,"mc":[{"id":"1.168133548","rc":[{"batb":[[2,8.4,3.63]],"ltp":9.6,"tv":1328.65,"id":10616006}]}]}
{"op":"mcm","clk":"995214134","pt":1580555909554,"mc":[{"id":"1.168133548","rc":[{"trd":[[7.6,226]],"batb":[[0,7.6,15.11]],"ltp":7.6,"tv":1285.5,"id":10170404}],"tv":7362.23}]}
{"op":"mcm","clk":"995216069","pt":1580555918564,"mc":[{"id":"1.168133548","rc":[{"trd":[[9.2,135.5],[9.4,46.41]],"batb":[[0,9.2,11.18]],"ltp":9.2,"tv":1335.37,"id":10616006},{"batb":[[1,7.4,25.69]],"ltp":7.6,"tv":1285.5,"id":10170404}],"tv":7368.95}]}
{"op":"mcm","clk":"995216269","pt":1580555919470,"mc":[{"id":"1.168133548","rc":[{"batb":[[2,8,20.94]],"ltp":9.2,"tv":1335.37,"id":10616006}]}]}
{"op":"mcm","clk":"995218911","pt":1580555932543,"mc":[{"id":"1.168133548","rc":[{"batl":[[0,10.5,8.51]],"ltp":9.2,"tv":1335.37,"id":10616006}]}]}
{"op":"mcm","clk":"995219303","pt":1580555934478,"mc":[{"id":"1.168133548","rc":[{"trd":[[7.6,238.75]],"batb":[[0,7.6,8.73]],"ltp":7.6,"tv":1298.26,"id":10170404}],"tv":7381.71}]}
{"op":"mcm","clk":"995220713","pt":1580555941573,"mc":[{"id":"1.168133548","rc":[{"batl":[[0,10,2.43],[1,10.5,8.08],[2,11,19.58]],"ltp":9.2,"tv":1335.37,"id":10616006}]}]}
{"op":"mcm","clk":"995220918","pt":1580555942554,"mc":[{"id":"1.168133548","rc":[{"trd":[[11,155.69]],"batl":[[0,11,50.03]],"ltp":11.0,"tv":768.7,"id":8429550},{"trd":[[9.2,147.5]],"batb":[[0,9.2,5.18]],"ltp":9.2,"tv":1347.37,"id":10616006}],"tv":7394.25}]}
{"op":"mcm","clk":"995221044","pt":1580555943197,"mc":[{"id":"1.168133548","rc":[{"batb":[[0,10,13.95]],"ltp":11.0,"tv":768.7,"id":8429550},{"batb":[[0,5.7,21.23]],"ltp":5.7,"tv":1594.82,"id":9417341},{"batb":[[0,6.6,12.87]],"ltp":6.8,"tv":696.26,"id":8231803},{"batb":[[0,9.2,10.69]],"ltp":9.2,"tv":1347.37,"id":10616006},{"batb":[[0,7.6,15.4]],"ltp":7.6,"tv":1298.26,"id":10170404},{"batb":[[0,8.6,17.52]],"ltp":8.8,"tv":624.18,"id":15608820},{"batb":[[0,30,7.93]],"ltp":32.0,"tv":105.11,"id":9193530},{"batb":[[0,27,4.05]],"ltp":29.0,"tv":157.01,"id":9001159},{"batb":[[0,5.5,32.89]],"ltp":5.6,"tv":802.49,"id":17352128}]}]}
{"op":"mcm","clk":"995221254","pt":1580555944391,"mc":[{"id":"1.168133548","rc":[{"trd":[[6.6,94.75]],"batb":[[0,6.6,10.87]],"ltp":6.6,"tv":700.26,"id":8231803}],"tv":7398.25}]}
{"op":"mcm","clk":"995222097","pt":1580555948478,"mc":[{"id":"1.168133548","rc":[{"batb":[[1,6.4,30.29]],"ltp":6.6,"tv":700.26,"id":8231803},{"batb":[[1,7.4,30.85]],"ltp":7.6,"tv":1298.26,"id":10170404},{"batb":[[1,8.4,7.25]],"ltp":8.8,"tv":624.18,"id":15608820}]}]}
{"op":"mcm","clk":"995224877","pt":1580555962549,"mc":[{"id":"1.168133548","rc":[{"batl":[[0,11,52.03]],"ltp":11.0,"tv":768.7,"id":8429550},{"batb":[[1,8.4,9.94]],"ltp":8.8,"tv":624.18,"id":15608820}]}]}
{"op":"mcm","clk":"995225039","pt":1580555963314,"mc":[{"id":"1.168133548","rc":[{"batl":[[0,32,1.68]],"ltp":32.0,"tv":105.11,"id":9193530}]}]}
{"op":"mcm","clk":"995226442","pt":1580555970447,"mc":[{"id":"1.168133548","rc":[{"trd":[[30,5.59]],"batb":[[0,30,6.25]],"batl":[[0,44,1.12],[1,46,1.78],[2,80,2]],"ltp":30.0,"tv":108.47,"id":9193530},{"trd":[[5.5,44.46]],"batb":[[0,5.5,27.82]],"ltp":5.5,"tv":812.63,"id":17352128}],"tv":7411.74}]}
{"op":"mcm","clk":"995226635","pt":1580555971439,"mc":[{"id":"1.168133548","rc":[{"batb":[[1,8.6,21.92]],"ltp":9.2,"tv":1347.37,"id":10616006}]}]}
{"op":"mcm","clk":"995227611","pt":1580555976167,"mc":[{"id":"1.168133548","rc":[{"batl":[[0,44,1.48]],"ltp":30.0,"tv":108.47,"id":9193530}]}]}
{"op":"mcm","clk":"995228021","pt":1580555978541,"mc":[{"id":"1.168133548","rc":[{"trd":[[7.6,243.8]],"batb":[[0,7.6,12.88]],"ltp":7.6,"tv":1303.3,"id":10170404}],"tv":7416.79}]}
{"op":"mcm","clk":"995229430","pt":1580555985483,"mc":[{"id":"1.168133548","rc":[{"batb":[[1,7.4,25.69]],"ltp":7.6,"tv":1303.3,"id":10170404}]}]}
{"op":"mcm","clk":"995230716","pt":1580555991506,"mc":[{"id":"1.168133548","rc":[{"trd":[[11,168.83]],"batb":[[0,10.5,31.64],[1,10,13.32],[2,9.8,13.89]],"batl":[[0,11,45.46]],"ltp":11.0,"tv":781.84,"id":8429550},{"batb":[[1,8.6,14.57]],"ltp":9.2,"tv":1347.37,"id":10616006}],"tv":7429.93}]}
{"op":"mcm","clk":"995231132","pt":1580555993458,"mc":[{"id":"1.168133548","rc":[{"trd":[[9.2,159.5]],"batb":[[0,9.2,4.69]],"ltp":9.2,"tv":1359.38,"id":10616006}],"tv":7441.93}]}
{"op":"mcm","clk":"995232512","pt":1580556000412,"mc":[{"id":"1.168133548","rc":[{"trd":[[11,230.83]],"batb":[[0,10,13.95],[1,9.8,27.92],[2,9.2,7.89]],"batl":[[0,11,14.46]],"ltp":11.0,"tv":843.84,"id":8429550},{"batb":[[1,8.6,18.04]],"ltp":9.2,"tv":1359.38,"id":10616006},{"batl":[[1,32,1.16]],"ltp":29.0,"tv":157.01,"id":9001159}],"tv":7503.93}]}
{"op":"mcm","clk":"995232931","pt":1580556002371,"mc":[{"id":"1.168133548","rc":[{"batb":[[1,9.8,13.89]],"ltp":11.0,"tv":843.84,"id":8429550}]}]}
{"op":"mcm","clk":"995233492","pt":1580556005116,"mc":[{"id":"1.168133548","rc":[{"batl":[[2,42,10.13]],"ltp":29.0,"tv":157.01,"id":9001159}]}]}
{"op":"mcm","clk":"995235291","pt":1580556013543,"mc":[{"id":"1.168133548","rc":[{"batl":[[1,40,1.54],[2,42,9.52]],"ltp":29.0,"tv":157.01,"id":9001159}]}]}
{"op":"mcm","clk":"995237121","pt":1580556022249,"mc":[{"id":"1.168133548","rc":[{"batl":[[2,42,1.85]],"ltp":29.0,"tv":157.01,"id":9001159}]}]}
{"op":"mcm","clk":"995245769","pt":1580556065381,"mc":[{"id":"1.168133548","rc":[{"batb":[[0,10.5,3.17],[1,10,13.32],[2,9.8,13.89]],"ltp":11.0,"tv":843.84,"id":8429550},{"trd":[[7.8,202.69]],"batl":[[0,7.8,5.37]],"ltp":7.8,"tv":1316.48,"id":10170404},{"batl":[[0,36,5.52],[1,38,2.53],[2,44,1.48]],"ltp":30.0,"tv":108.47,"id":9193530},{"batl":[[1,34,3.14],[2,42,2.78]],"ltp":29.0,"tv":157.01,"id":9001159}],"tv":7517.1}]}
{"op":"mcm","clk":"995246128","pt":1580556067316,"mc":[{"id":"1.168133548","rc":[{"batb":[[1,8.6,14.57]],"ltp":9.2,"tv":1359.38,"id":10616006}]}]}
{"op":"mcm","clk":"995246828","pt":1580556070487,"mc":[{"id":"1.168133548","rc":[{"trd":[[10,30.94],[10.5,102]],"batb":[[0,9.8,13.89],[1,9.2,14.92],[2,9,4.44]],"batl":[[0,10,11.35],[1,10.5,4.03],[2,11,14.46]],"ltp":10.0,"tv":881.12,"id":8429550}],"tv":7554.39}]}
{"op":"mcm","clk":"995247040","pt":1580556071504,"mc":[{"id":"1.168133548","rc":[{"trd":[[5.8,381.57]],"batl":[[0,5.8,9.73]],"ltp":5.8,"tv":1595.36,"id":9417341},{"batb":[[0,6.6,11.1]],"ltp":6.6,"tv":700.26,"id":8231803},{"batl":[[0,34,2.17]],"ltp":30.0,"tv":108.47,"id":9193530}],"tv":7554.93}]}
{"op":"mcm","clk":"995247228","pt":1580556072405,"mc":[{"id":"1.168133548","rc":[{"batb":[[0,9.8,14.05],[1,9.2,7.89]],"ltp":10.0,"tv":881.12,"id":8429550},{"batb":[[0,6.8,2.76],[1,6.6,10.87],[2,6.4,30.29]],"ltp":6.6,"tv":700.26,"id":8231803},{"batb":[[0,9.4,2],[1,9.2,4.69],[2,8.6,14.57]],"ltp":9.2,"tv":1359.38,"id":10616006},{"trd":[[7.8,203.09]],"batl":[[0,7.8,5.17]],"ltp":7.8,"tv":1316.88,"id":10170404},{"trd":[[8.8,137.84]],"batl":[[0,9,5.96],[1,9.2,2],[2,9.8,3.38]],"ltp":8.8,"tv":628.17,"id":15608820},{"trd":[[5.6,21.21]],"batl":[[0,5.6,8.37]],"ltp":5.6,"tv":813.19,"id":17352128}],"tv":7559.89}]}
{"op":"mcm","clk":"995247622","pt":1580556074244,"mc":[{"id":"1.168133548","rc":[{"batb":[[2,6.4,27.7]],"ltp":6.6,"tv":700.26,"id":8231803}]}]}
{"op":"mcm","clk":"995247913","pt":1580556075524,"mc":[{"id":"1.168133548","rc":[{"batl":[[2,9.8,10.81]],"ltp":8.8,"tv":628.17,"id":15608820}]}]}
{"op":"mcm","clk":"995248675","pt":1580556079341,"mc":[{"id":"1.168133548","rc":[{"trd":[[7.6,264.07]],"batb":[[0,7.6,2.74]],"ltp":7.6,"tv":1337.15,"id":10170404}],"tv":7580.16}]}
{"op":"mcm","clk":"995248866","pt":1580556080210,"mc":[{"id":"1.168133548","rc":[{"batl":[[1,32,1.16],[2,34,3.14]],"ltp":29.0,"tv":157.01,"id":9001159}]}]}
{"op":"mcm","clk":"995250134","pt":1580556086521,"mc":[{"id":"1.168133548","rc":[{"trd":[[10,32.19]],"batl":[[0,10,10.72]],"ltp":10.0,"tv":882.38,"id":8429550},{"trd":[[5.8,383.74]],"batl":[[0,5.8,8.65]],"ltp":5.8,"tv":1597.53,"id":9417341},{"batb":[[0,6.8,3.69]],"ltp":6.6,"tv":700.26,"id":8231803},{"batb":[[0,9.4,2.65]],"ltp":9.2,"tv":1359.38,"id":10616006},{"batb":[[0,7.6,3.56]],"ltp":7.6,"tv":1337.15,"id":10170404},{"batb":[[0,8.6,18.24]],"ltp":8.8,"tv":628.17,"id":15608820},{"batb":[[0,30,6.5]],"ltp":30.0,"tv":108.47,"id":9193530},{"batb":[[0,27,4.33]],"ltp":29.0,"tv":157.01,"id":9001159},{"trd":[[5.6,23.45]],"batl":[[0,5.6,7.25]],"ltp":5.6,"tv":815.43,"id":17352128}],"tv":7585.83}]}
{"op":"mcm","clk":"995251161","pt":1580556091548,"mc":[{"id":"1.168133548","rc":[{"batb":[[1,6.6,12.99],[2,6.4,25.53]],"ltp":6.6,"tv":700.26,"id":8231803}]}]}
{"op":"mcm","clk":"995251287","pt":1580556092243,"mc":[{"id":"1.168133548","rc":[{"trd":[[7,29.69]],"batl":[[0,7,2]],"ltp":7.0,"tv":716.26,"id":8231803}],"tv":7601.83}]}
{"op":"mcm","clk":"995252436","pt":1580556098563,"mc":[{"id":"1.168133548","rc":[{"trd":[[8.8,139.28]],"batb":[[0,8.6,17.52]],"batl":[[0,8.8,1.28],[1,9,5.96],[2,9.2,2]],"ltp":8.8,"tv":629.61,"id":15608820}],"tv":7603.26}]}
{"op":"mcm","clk":"995252786","pt":1580556100484,"mc":[{"id":"1.168133548","rc":[{"batb":[[2,8.6,21.67]],"ltp":9.2,"tv":1359.38,"id":10616006}]}]}
{"op":"mcm","clk":"995255784","pt":1580556116495,"mc":[{"id":"1.168133548","rc":[{"trd":[[6.8,36.48]],"batb":[[0,6.8,1.17]],"ltp":6.8,"tv":721.3,"id":8231803}],"tv":7608.3}]}
{"op":"mcm","clk":"995256531","pt":1580556120403,"mc":[{"id":"1.168133548","rc":[{"trd":[[10,36.19]],"batl":[[0,10,8.72]],"ltp":10.0,"tv":886.38,"id":8429550}],"tv":7612.3}]}
{"op":"mcm","clk":"995256745","pt":1580556121547,"mc":[{"id":"1.168133548","rc":[{"batb":[[1,6.6,10.87],[2,6.4,33.61]],"ltp":6.8,"tv":721.3,"id":8231803},{"batl":[[0,10.5,8.51],[1,11,19.58],[2,11.5,10.44]],"ltp":9.2,"tv":1359.38,"id":10616006}]}]}
{"op":"mcm","clk":"995257047","pt":1580556123109,"mc":[{"id":"1.168133548","rc":[{"batb":[[2,6.4,28.08]],"ltp":6.8,"tv":721.3,"id":8231803}]}]}
{"op":"mcm","clk":"995258078","pt":1580556128524,"mc":[{"id":"1.168133548","rc":[{"batl":[[0,10,2.11],[1,10.5,8.08],[2,11,19.58]],"ltp":9.2,"tv":1359.38,"id":10616006}]}]}
{"op":"mcm","clk":"995258242","pt":1580556129429,"mc":[{"id":"1.168133548","rc":[{"batl":[[1,10.5,16.03]],"ltp":10.0,"tv":886.38,"id":8429550}]}]}
{"op":"mcm","clk":"995259424","pt":1580556135552,"mc":[{"id":"1.168133548","rc":[{"batl":[[1,10.5,28.03]],"ltp":10.0,"tv":886.38,"id":8429550}]}]}
{"op":"mcm","clk":"995259789","pt":1580556137476,"mc":[{"id":"1.168133548","rc":[{"trd":[[7.6,270.79]],"batb":[[0,7.4,25.89],[1,7.2,21],[2,7,23]],"ltp":7.6,"tv":1343.87,"id":10170404}],"tv":7619.02}]}
{"op":"mcm","clk":"995261196","pt":1580556143544,"mc":[{"id":"1.168133548","rc":[{"batl":[[1,10.5,40.03]],"ltp":10.0,"tv":886.38,"id":8429550},{"batb":[[2,5.5,9.06]],"ltp":5.8,"tv":1597.53,"id":9417341}]}]}
{"op":"mcm","clk":"995261997","pt":1580556147466,"mc":[{"id":"1.168133548","rc":[{"trd":[[10,37.35]],"batl":[[0,10,7.56]],"ltp":10.0,"tv":887.54,"id":8429550},{"trd":[[5.8,385.73]],"batl":[[0,5.8,6.66]],"ltp":5.8,"tv":1599.52,"id":9417341},{"trd":[[7,32.04]],"batl":[[0,7.2,5],[1,7.4,5],[2,8,5.53]],"ltp":7.0,"tv":723.65,"id":8231803},{"trd":[[9.6,86.09],[9.8,90]],"batb":[[0,9.4,1.83]],"ltp":9.6,"tv":1362.2,"id":10616006},{"trd":[[7.8,204.57]],"batb":[[1,7.2,26.36]],"batl":[[0,7.8,3.69]],"ltp":7.8,"tv":1345.35,"id":10170404},{"trd":[[8.8,140.56],[9,34.43]],"batl":[[0,9,5.93],[1,9.2,2],[2,9.8,10.81]],"ltp":9.0,"tv":630.92,"id":15608820},{"trd":[[34,3.22]],"batl":[[0,34,1.83]],"ltp":34.0,"tv":108.81,"id":9193530},{"trd":[[29,16.33]],"batl":[[0,29,1.11]],"ltp":29.0,"tv":157.41,"id":9001159},{"trd":[[5.6,25.51]],"batl":[[0,5.6,5.19]],"ltp":5.6,"tv":817.49,"id":17352128}],"tv":7632.93}]}
{"op":"mcm","clk":"995262206","pt":1580556148571,"mc":[{"id":"1.168133548","rc":[{"batl":[[1,10.5,52.03]],"ltp":10.0,"tv":887.54,"id":8429550},{"batl":[[0,10,3.7]],"ltp":9.6,"tv":1362.2,"id":10616006}]}]}
{"op":"mcm","clk":"995262364","pt":1580556149463,"mc":[{"id":"1.168133548","rc":[{"batb":[[2,8.6,17.62]],"ltp":9.6,"tv":1362.2,"id":10616006}]}]}
{"op":"mcm","clk":"995262584","pt":1580556150567,"mc":[{"id":"1.168133548","rc":[{"batl":[[0,10,14.44],[2,11,26.46]],"ltp":10.0,"tv":887.54,"id":8429550}]}]}
{"op":"mcm","clk":"995273953","pt":1580556153549,"mc":[{"id":"1.168133548","rc":[{"batl":[[2,11,38.46]],"ltp":10.0,"tv":887.54,"id":8429550}]}]}
{"op":"mcm","clk":"995275178","pt":1580556159476,"mc":[{"id":"1.168133548","rc":[{"batl":[[2,11,50.46]],"ltp":10.0,"tv":887.54,"id":8429550},{"batl":[[0,8.8,2],[1,9,5.93],[2,9.2,2]],"ltp":9.0,"tv":630.92,"id":15608820}]}]}
{"op":"mcm","clk":"995275987","pt":1580556163566,"mc":[{"id":"1.168133548","rc":[{"trd":[[7.4,62.15],[7.6,271.2]],"batb":[[0,7.4,23.38]],"ltp":7.4,"tv":1350.38,"id":10170404}],"tv":7637.97}]}
{"op":"mcm","clk":"995276177","pt":1580556164550,"mc":[{"id":"1.168133548","rc":[{"batl":[[0,38,2.53],[1,44,1.48],[2,46,1.78]],"ltp":34.0,"tv":108.81,"id":9193530}]}]}
{"op":"mcm","clk":"995276345","pt":1580556165460,"mc":[{"id":"1.168133548","rc":[{"batb":[[2,8.6,19.82]],"ltp":9.6,"tv":1362.2,"id":10616006},{"batl":[[0,5.6,14.44]],"ltp":5.6,"tv":817.49,"id":17352128}]}]}
{"op":"mcm","clk":"995276704","pt":1580556167463,"mc":[{"id":"1.168133548","rc":[{"trd":[[9.8,6]],"batb":[[0,9.8,11.05]],"batl":[[2,11,62.46]],"ltp":9.8,"tv":893.54,"id":8429550}],"tv":7643.97}]}
{"op":"mcm","clk":"995277673","pt":1580556172532,"mc":[{"id":"1.168133548","rc":[{"batl":[[2,11,74.46]],"ltp":9.8,"tv":893.54,"id":8429550},{"trd":[[8.6,227.9]],"batb":[[0,8.6,14.52]],"ltp":8.6,"tv":636.92,"id":15608820}],"tv":7649.96}]}
{"op":"mcm","clk":"995278600","pt":1580556177458,"mc":[{"id":"1.168133548","rc":[{"trd":[[8.6,238.03]],"batb":[[0,8.6,9.46]],"ltp":8.6,"tv":647.05,"id":15608820}],"tv":7660.09}]}
{"op":"mcm","clk":"995279405","pt":1580556181562,"mc":[{"id":"1.168133548","rc":[{"batb":[[1,8.4,7.25],[2,8.2,9.19]],"batl":[[0,8.8,7.93],[1,9.2,2],[2,9.8,3.38]],"ltp":8.6,"tv":647.05,"id":15608820}]}]}
{"op":"mcm","clk":"995279610","pt":1580556182535,"mc":[{"id":"1.168133548","rc":[{"batb":[[0,9.8,11.86]],"ltp":9.8,"tv":893.54,"id":8429550},{"trd":[[5.8,388.45]],"batl":[[0,5.8,5.3]],"ltp":5.8,"tv":1602.23,"id":9417341},{"batb":[[0,7,1.12],[1,6.8,1.17],[2,6.6,10.87]],"ltp":7.0,"tv":723.65,"id":8231803},{"batb":[[0,7.6,1.04],[1,7.4,23.38],[2,7.2,26.36]],"ltp":7.4,"tv":1350.38,"id":10170404},{"trd":[[5.6,28.32]],"batl":[[0,5.6,13.04]],"ltp":5.6,"tv":820.3,"id":17352128}],"tv":7665.62}]}
{"op":"mcm","clk":"995279686","pt":1580556183061,"mc":[{"id":"1.168133548","rc":[{"batb":[[0,9.4,2.67]],"ltp":9.6,"tv":1362.2,"id":10616006},{"batb":[[2,7.2,21]],"ltp":7.4,"tv":1350.38,"id":10170404},{"trd":[[8.8,142.34]],"batl":[[0,8.8,7.04],[2,9.8,18.01]],"ltp":8.8,"tv":648.83,"id":15608820}],"tv":7667.4}]}
{"op":"mcm","clk":"995281997","pt":1580556195082,"mc":[{"id":"1.168133548","rc":[{"batl":[[1,44,1.12]],"ltp":34.0,"tv":108.81,"id":9193530}]}]}
{"op":"mcm","clk":"995283205","pt":1580556201511,"mc":[{"id":"1.168133548","rc":[{"trd":[[5.6,48.32]],"batl":[[0,5.6,3.04]],"ltp":5.6,"tv":840.3,"id":17352128}],"tv":7687.4}]}
{"op":"mcm","clk":"995285388","pt":1580556212495,"mc":[{"id":"1.168133548","rc":[{"trd":[[9.8,29.72]],"batb":[[0,9.2,7.89],[1,9,4.44],[2,8.4,3]],"batl":[[0,9.8,3.14],[1,10,14.44],[2,10.5,52.03]],"ltp":9.8,"tv":917.26,"id":8429550},{"batl":[[0,44,1.12],[1,46,1.78],[2,80,2]],"ltp":34.0,"tv":108.81,"id":9193530},{"batl":[[2,42,2.46]],"ltp":29.0,"tv":157.41,"id":9001159}],"tv":7711.12}]}
{"op":"mcm","clk":"995285562","pt":1580556213518,"mc":[{"id":"1.168133548","rc":[{"trd":[[5.8,415.83]],"batb":[[0,5.8,21.77],[1,5.7,21.23],[2,5.6,33.85]],"batl":[[0,5.9,20],[1,6,91.99],[2,6.2,1066.09]],"ltp":5.8,"tv":1629.62,"id":9417341},{"trd":[[8.8,156.42]],"batb":[[0,8.8,4.66],[1,8.6,9.46],[2,8.4,7.25]],"batl":[[0,9.2,2],[1,9.8,18.01],[2,10,5]],"ltp":8.8,"tv":662.91,"id":15608820},{"trd":[[5.6,54.4]],"batb":[[0,5.6,30.55],[1,5.5,27.82],[2,5.4,3.19]],"batl":[[0,5.7,9.64],[1,5.8,45.42],[2,6,13.37]],"ltp":5.6,"tv":846.38,"id":17352128}],"tv":7758.66}]}
{"op":"mcm","clk":"995285755","pt":1580556214483,"mc":[{"id":"1.168133548","rc":[{"trd":[[7.2,17.03]],"batl":[[0,7.4,5],[1,8,5.53],[2,8.2,2.5]],"ltp":7.2,"tv":733.65,"id":8231803},{"batb":[[2,8.2,9.19]],"batl":[[2,10,11.5]],"ltp":8.8,"tv":662.91,"id":15608820}],"tv":7768.66}]}
{"op":"mcm","clk":"995285966","pt":1580556215503,"mc":[{"id":"1.168133548","rc":[{"batb":[[2,8.6,1.32]],"batl":[[0,9.4,2],[1,9.6,3.14],[2,10,7.56]],"ltp":9.8,"tv":917.26,"id":8429550},{"trd":[[7,34.29]],"batb":[[0,6.8,1.17],[1,6.6,10.87],[2,6.4,31.08]],"batl":[[0,7,6.13],[1,7.2,5],[2,7.4,5]],"ltp":7.0,"tv":735.9,"id":8231803}],"tv":7770.9}]}
{"op":"mcm","clk":"995286154","pt":1580556216510,"mc":[{"id":"1.168133548","rc":[{"batb":[[2,8.4,3]],"ltp":9.8,"tv":917.26,"id":8429550},{"batb":[[0,6.8,16.17]],"batl":[[0,7.2,5],[1,7.4,5],[2,7.6,5.66]],"ltp":7.0,"tv":735.9,"id":8231803}]}]}
{"op":"mcm","clk":"995286564","pt":1580556218490,"mc":[{"id":"1.168133548","rc":[{"batb":[[1,6.6,17.5]],"ltp":7.0,"tv":735.9,"id":8231803},{"batl":[[1,10,7.46],[2,12,5.68]],"ltp":8.8,"tv":662.91,"id":15608820}]}]}
{"op":"mcm","clk":"995286955","pt":1580556220523,"mc":[{"id":"1.168133548","rc":[{"batl":[[0,10,2.11]],"ltp":9.6,"tv":1362.2,"id":10616006},{"batl":[[1,9.6,1.66],[2,10,7.46]],"ltp":8.8,"tv":662.91,"id":15608820}]}]}
{"op":"mcm","clk":"995287374","pt":1580556222513,"mc":[{"id":"1.168133548","rc":[{"batb":[[0,5.7,21.23],[1,5.6,33.85],[2,5.5,9.06]],"ltp":5.8,"tv":1629.62,"id":9417341},{"batb":[[0,8.6,9.46],[1,8.2,9.19],[2,8,15]],"ltp":8.8,"tv":662.91,"id":15608820},{"batb":[[0,5.5,27.82],[1,5.4,3.19],[2,5.3,18.78]],"ltp":5.6,"tv":846.38,"id":17352128}]}]}
{"op":"mcm","clk":"995287550","pt":1580556223431,"mc":[{"id":"1.168133548","rc":[{"batb":[[1,5.6,53.12]],"batl":[[2,6.2,1064.16]],"ltp":5.8,"tv":1629.62,"id":9417341},{"batb":[[1,8.4,2.87],[2,8.2,13.56]],"ltp":8.8,"tv":662.91,"id":15608820},{"batb":[[1,5.4,19.34]],"ltp":5.6,"tv":846.38,"id":17352128}]}]}
{"op":"mcm","clk":"995287756","pt":1580556224527,"mc":[{"id":"1.168133548","rc":[{"trd":[[9.2,6.28]],"batb":[[0,9.2,4.75]],"batl":[[1,10,7.56],[2,10.5,52.03]],"ltp":9.2,"tv":923.54,"id":8429550},{"batb":[[1,5.6,33.85]],"ltp":5.8,"tv":1629.62,"id":9417341},{"batb":[[1,5.4,3.19]],"ltp":5.6,"tv":846.38,"id":17352128}],"tv":7777.18}]}
{"op":"mcm","clk":"995287872","pt":1580556225130,"mc":[{"id":"1.168133548","rc":[{"batl":[[0,10,7.56],[1,10.5,52.03],[2,11,74.46]],"ltp":9.2,"tv":923.54,"id":8429550}]}]}
{"op":"mcm","clk":"995288165","pt":1580556226402,"mc":[{"id":"1.168133548","rc":[{"batl":[[0,9,2.62],[1,9.2,2],[2,9.6,1.66]],"ltp":8.8,"tv":662.91,"id":15608820},{"batl":[[0,42,3.01],[1,44,1],[2,46,1.78]],"ltp":34.0,"tv":108.81,"id":9193530}]}]}
{"op":"mcm","clk":"995288385","pt":1580556227533,"mc":[{"id":"1.168133548","rc":[{"batb":[[2,8.2,4.88]],"ltp":9.2,"tv":923.54,"id":8429550},{"batl":[[0,5.8,2],[1,5.9,20],[2,6,91.99]],"ltp":5.8,"tv":1629.62,"id":9417341},{"batb":[[2,6.4,28.08]],"ltp":7.0,"tv":735.9,"id":8231803}]}]}
{"op":"mcm","clk":"995288588","pt":1580556228509,"mc":[{"id":"1.168133548","rc":[{"batl":[[0,9.8,2],[1,10,7.56],[2,10.5,52.03]],"ltp":9.2,"tv":923.54,"id":8429550}]}]}
{"op":"mcm","clk":"995289002","pt":1580556230516,"mc":[{"id":"1.168133548","rc":[{"batb":[[2,8.6,1.32]],"batl":[[0,9.4,2],[1,9.6,15],[2,9.8,2]],"ltp":9.2,"tv":923.54,"id":8429550}]}]}
{"op":"mcm","clk":"995291783","pt":1580556244313,"mc":[{"id":"1.168133548","rc":[{"trd":[[5.7,173.01]],"batb":[[0,5.7,13.73]],"ltp":5.7,"tv":1644.62,"id":9417341},{"trd":[[8.6,248.03]],"batb":[[0,8.6,4.46]],"ltp":8.6,"tv":672.9,"id":15608820},{"trd":[[5.5,59.46]],"batb":[[0,5.5,20.33]],"ltp":5.5,"tv":861.37,"id":17352128}],"tv":7817.17}]}
{"op":"mcm","clk":"995292174","pt":1580556246298,"mc":[{"id":"1.168133548","rc":[{"batb":[[2,8.2,4.88]],"ltp":9.2,"tv":923.54,"id":8429550},{"batb":[[2,8.2,9.19]],"ltp":8.6,"tv":672.9,"id":15608820}]}]}
{"op":"mcm","clk":"995292633","pt":1580556248502,"mc":[{"id":"1.168133548","rc":[{"trd":[[9.4,4],[9.6,6.48]],"batl":[[0,9.6,11.76],[1,9.8,2],[2,10,21.56]],"ltp":9.6,"tv":934.02,"id":8429550},{"batl":[[0,8.8,2],[1,9,2.62],[2,9.2,2]],"ltp":8.6,"tv":672.9,"id":15608820}],"tv":7827.65}]}
{"op":"mcm","clk":"995292828","pt":1580556249516,"mc":[{"id":"1.168133548","rc":[{"batl":[[1,9.2,2],[2,9.6,1.66]],"ltp":8.6,"tv":672.9,"id":15608820}]}]}
{"op":"mcm","clk":"995293610","pt":1580556253123,"mc":[{"id":"1.168133548","rc":[{"batb":[[2,8.4,3]],"ltp":9.6,"tv":934.02,"id":8429550}]}]}
{"op":"mcm","clk":"995294394","pt":1580556256538,"mc":[{"id":"1.168133548","rc":[{"trd":[[9.6,16.92]],"batl":[[0,9.6,6.54]],"ltp":9.6,"tv":944.46,"id":8429550},{"trd":[[7.8,211.95]],"batb":[[0,7.8,4.32],[1,7.6,1.04],[2,7.4,23.38]],"batl":[[0,8,27.71],[1,8.2,41.86],[2,8.4,2.71]],"ltp":7.8,"tv":1357.76,"id":10170404}],"tv":7845.47}]}
{"op":"mcm","clk":"995294593","pt":1580556257557,"mc":[{"id":"1.168133548","rc":[{"batl":[[0,7,2.69],[1,7.2,5],[2,7.4,5]],"ltp":7.0,"tv":735.9,"id":8231803},{"trd":[[7.8,220.59]],"batb":[[0,7.6,1.04],[1,7.4,23.38],[2,7.2,21]],"batl":[[0,7.8,2.87],[1,8,27.71],[2,8.2,41.86]],"ltp":7.8,"tv":1366.4,"id":10170404},{"batl":[[0,40,2.8],[1,44,1.12]],"ltp":34.0,"tv":108.81,"id":9193530}],"tv":7854.11}]}
{"op":"mcm","clk":"995294784","pt":1580556258530,"mc":[{"id":"1.168133548","rc":[{"trd":[[9.6,23.82]],"batl":[[0,9.6,3.09]],"ltp":9.6,"tv":951.36,"id":8429550},{"batl":[[0,7.8,4.61]],"ltp":7.8,"tv":1366.4,"id":10170404}],"tv":7861.02}]}
{"op":"mcm","clk":"995295384","pt":1580556261557,"mc":[{"id":"1.168133548","rc":[{"batl":[[1,8,25],[2,8.2,39.15]],"ltp":7.8,"tv":1366.4,"id":10170404}]}]}
{"op":"mcm","clk":"995296199","pt":1580556265448,"mc":[{"id":"1.168133548","rc":[{"batl":[[2,8.2,41.72]],"ltp":7.8,"tv":1366.4,"id":10170404}]}]}
{"op":"mcm","clk":"995296406","pt":1580556266570,"mc":[{"id":"1.168133548","rc":[{"trd":[[9.6,30],[9.8,33.72]],"batb":[[0,9.8,20.42],[1,9.2,4.75],[2,9,4.44]],"batl":[[0,10,7.56],[1,10.5,52.03],[2,11,74.46]],"ltp":9.8,"tv":961.54,"id":8429550}],"tv":7871.2}]}
{"op":"mcm","clk":"995297452","pt":1580556271487,"mc":[{"id":"1.168133548","rc":[{"trd":[[10,68.23]],"batb":[[0,10,4.98]],"batl":[[0,10.5,52.03],[1,11,74.46],[2,12,21]],"ltp":10.0,"tv":992.42,"id":8429550}],"tv":7902.08}]}
{"op":"mcm","clk":"995297862","pt":1580556273502,"mc":[{"id":"1.168133548","rc":[{"batb":[[1,9.4,2],[2,9.2,4.75]],"ltp":10.0,"tv":992.42,"id":8429550}]}]}
{"op":"mcm","clk":"995298038","pt":1580556274380,"mc":[{"id":"1.168133548","rc":[{"batb":[[2,9.2,11.76]],"ltp":10.0,"tv":992.42,"id":8429550}]}]}
{"op":"mcm","clk":"995298480","pt":1580556276515,"mc":[{"id":"1.168133548","rc":[{"batl":[[2,12.5,50.29]],"ltp":10.0,"tv":992.42,"id":8429550}]}]}
{"op":"mcm","clk":"995298689","pt":1580556277494,"mc":[{"id":"1.168133548","rc":[{"trd":[[10,78.19]],"batb":[[0,9.4,2],[1,9.2,11.76],[2,9,4.44]],"batl":[[0,10.5,52.05],[1,11,69.46]],"ltp":10.0,"tv":1002.38,"id":8429550}],"tv":7912.04}]}
{"op":"mcm","clk":"995298898","pt":1580556278512,"mc":[{"id":"1.168133548","rc":[{"batb":[[1,9.2,4.75],[2,9,11.7]],"ltp":10.0,"tv":1002.38,"id":8429550}]}]}
{"op":"mcm","clk":"995299120","pt":1580556279500,"mc":[{"id":"1.168133548","rc":[{"batb":[[2,9,4.44]],"ltp":10.0,"tv":1002.38,"id":8429550}]}]}
{"op":"mcm","clk":"995300573","pt":1580556286308,"mc":[{"id":"1.168133548","rc":[{"batl":[[0,10,3.34],[1,10.5,52.03],[2,11,69.46]],"ltp":10.0,"tv":1002.38,"id":8429550}]}]}
{"op":"mcm","clk":"995301249","pt":1580556289392,"mc":[{"id":"1.168133548","rc":[{"batl":[[0,10,17.34]],"ltp":10.0,"tv":1002.38,"id":8429550}]}]}
{"op":"mcm","clk":"995301483","pt":1580556290515,"mc":[{"id":"1.168133548","rc":[{"batl":[[0,7.2,5],[1,7.4,5],[2,7.6,5.66]],"ltp":7.0,"tv":735.9,"id":8231803},{"batl":[[0,38,2.71]],"ltp":34.0,"tv":108.81,"id":9193530},{"batb":[[0,5.6,2.21],[1,5.5,20.33],[2,5.4,3.19]],"ltp":5.5,"tv":861.37,"id":17352128}]}]}
{"op":"mcm","clk":"995302305","pt":1580556294409,"mc":[{"id":"1.168133548","rc":[{"batl":[[2,8.2,39.15]],"ltp":7.8,"tv":1366.4,"id":10170404}]}]}
{"op":"mcm","clk":"995302532","pt":1580556295435,"mc":[{"id":"1.168133548","rc":[{"trd":[[5.5,80.04],[5.6,58.82]],"batb":[[0,5.6,3.31],[1,5.5,10.04]],"ltp":5.5,"tv":886.37,"id":17352128}],"tv":7937.04}]}
{"op":"mcm","clk":"995303233","pt":1580556298521,"mc":[{"id":"1.168133548","rc":[{"batl":[[1,8,27.57],[2,8.2,41.72]],"ltp":7.8,"tv":1366.4,"id":10170404}]}]}
{"op":"mcm","clk":"995306646","pt":1580556313865,"mc":[{"id":"1.168133548","rc":[{"batl":[[2,11,62]],"ltp":10.0,"tv":1002.38,"id":8429550}]}]}
{"op":"mcm","clk":"995310944","pt":1580556336573,"mc":[{"id":"1.168133548","rc":[{"trd":[[10,112.87]],"batb":[[0,9.8,13.59],[1,9.4,2],[2,9.2,4.75]],"batl":[[0,10.5,52.03],[1,11,62],[2,12.5,50.29]],"ltp":10.0,"tv":1037.06,"id":8429550}],"tv":7971.71}]}
{"op":"mcm","clk":"995311119","pt":1580556337500,"mc":[{"id":"1.168133548","rc":[{"batb":[[0,9.8,14.28]],"batl":[[1,11,64.66]],"ltp":10.0,"tv":1037.06,"id":8429550}]}]}
{"op":"mcm","clk":"995311466","pt":1580556339285,"mc":[{"id":"1.168133548","rc":[{"batl":[[1,11,62]],"ltp":10.0,"tv":1037.06,"id":8429550}]}]}
{"op":"mcm","clk":"995312256","pt":1580556343380,"mc":[{"id":"1.168133548","rc":[{"trd":[[6.8,42.48]],"batb":[[0,6.8,13.17]],"ltp":6.8,"tv":741.89,"id":8231803}],"tv":7977.71}]}
{"op":"mcm","clk":"995312381","pt":1580556344034,"mc":[{"id":"1.168133548","rc":[{"trd":[[7.2,22.69]],"batl":[[0,7.2,2.17]],"ltp":7.2,"tv":747.55,"id":8231803}],"tv":7983.37}]}
{"op":"mcm","clk":"995312836","pt":1580556346520,"mc":[{"id":"1.168133548","rc":[{"batb":[[2,6.4,31.08]],"ltp":7.2,"tv":747.55,"id":8231803}]}]}
{"op":"mcm","clk":"995314353","pt":1580556354546,"mc":[{"id":"1.168133548","rc":[{"batb":[[0,7.6,6.04]],"ltp":7.8,"tv":1366.4,"id":10170404}]}]}
{"op":"mcm","clk":"995314938","pt":1580556357554,"mc":[{"id":"1.168133548","rc":[{"batb":[[0,7,2],[1,6.8,13.17],[2,6.6,17.5]],"ltp":7.2,"tv":747.55,"id":8231803},{"batb":[[1,8.2,9.19],[2,8,15]],"ltp":8.6,"tv":672.9,"id":15608820}]}]}
{"op":"mcm","clk":"995315103","pt":1580556358438,"mc":[{"id":"1.168133548","rc":[{"batb":[[2,6.6,15.5]],"ltp":7.2,"tv":747.55,"id":8231803}]}]}
{"op":"mcm","clk":"995315219","pt":1580556359137,"mc":[{"id":"1.168133548","rc":[{"batb":[[1,6.8,15.17],[2,6.6,8.87]],"ltp":7.2,"tv":747.55,"id":8231803},{"batb":[[1,8.2,11.57]],"ltp":8.6,"tv":672.9,"id":15608820}]}]}
{"op":"mcm","clk":"995315419","pt":1580556360472,"mc":[{"id":"1.168133548","rc":[{"batb":[[0,10,20.41],[1,9.8,14.28],[2,9.4,2]],"ltp":10.0,"tv":1037.06,"id":8429550},{"batb":[[2,8.6,14.57]],"ltp":9.6,"tv":1362.2,"id":10616006}]}]}
{"op":"mcm","clk":"995316265","pt":1580556364546,"mc":[{"id":"1.168133548","rc":[{"batb":[[0,10,22.94]],"ltp":10.0,"tv":1037.06,"id":8429550},{"batb":[[0,7.6,12.62]],"ltp":7.8,"tv":1366.4,"id":10170404},{"batl":[[1,30,2.53]],"ltp":29.0,"tv":157.41,"id":9001159}]}]}
{"op":"mcm","clk":"995317084","pt":1580556368555,"mc":[{"id":"1.168133548","rc":[{"batb":[[0,7,4],[1,6.8,13.17]],"ltp":7.2,"tv":747.55,"id":8231803}]}]}
{"op":"mcm","clk":"995317828","pt":1580556372363,"mc":[{"id":"1.168133548","rc":[{"trd":[[8.8,160.42]],"batl":[[0,9.2,2],[1,9.6,1.66],[2,10,5]],"ltp":8.8,"tv":676.9,"id":15608820}],"tv":7987.37}]}
{"op":"mcm","clk":"995319823","pt":1580556382512,"mc":[{"id":"1.168133548","rc":[{"trd":[[10.5,183.38]],"batb":[[0,10,27.17]],"batl":[[0,10.5,11.34]],"ltp":10.5,"tv":1118.44,"id":8429550}],"tv":8068.75}]}
{"op":"mcm","clk":"995320657","pt":1580556386396,"mc":[{"id":"1.168133548","rc":[{"trd":[[10.5,206.06]],"batb":[[0,10.5,1.99],[1,10,27.17]],"batl":[[0,11,62],[1,12.5,50.29],[2,13.5,20.72]],"ltp":10.5,"tv":1141.12,"id":8429550}],"tv":8091.43}]}
{"op":"mcm","clk":"995320867","pt":1580556387382,"mc":[{"id":"1.168133548","rc":[{"trd":[[11,274.67]],"batb":[[2,9.4,8.61]],"batl":[[0,11,40.08],[1,12,13.28],[2,12.5,56.93]],"ltp":11.0,"tv":1184.96,"id":8429550},{"batb":[[1,8.2,9.19]],"ltp":8.8,"tv":676.9,"id":15608820}],"tv":8135.27}]}
{"op":"mcm","clk":"995321301","pt":1580556389493,"mc":[{"id":"1.168133548","rc":[{"batl":[[1,12,19.92]],"ltp":11.0,"tv":1184.96,"id":8429550}]}]}
{"op":"mcm","clk":"995323123","pt":1580556398502,"mc":[{"id":"1.168133548","rc":[{"batb":[[1,8.2,11.57]],"batl":[[0,9,4.47],[1,9.2,2],[2,9.6,1.66]],"ltp":8.8,"tv":676.9,"id":15608820},{"batl":[[0,44,1.12],[1,46,1.78],[2,80,2]],"ltp":34.0,"tv":108.81,"id":9193530},{"batb":[[0,5.5,10.04],[1,5.4,3.19],[2,5.3,18.78]],"ltp":5.5,"tv":886.37,"id":17352128}]}]}
{"op":"mcm","clk":"995327106","pt":1580556418484,"mc":[{"id":"1.168133548","rc":[{"trd":[[8.8,164.42]],"batl":[[0,9.2,2],[1,9.6,1.66],[2,10,5]],"ltp":8.8,"tv":680.9,"id":15608820}],"tv":8139.27}]}
{"op":"mcm","clk":"995327281","pt":1580556419382,"mc":[{"id":"1.168133548","rc":[{"trd":[[9,38.43]],"batl":[[0,9,2.47],[1,9.2,2],[2,9.6,1.66]],"ltp":9.0,"tv":684.9,"id":15608820}],"tv":8143.27}]}
{"op":"mcm","clk":"995328637","pt":1580556426191,"mc":[{"id":"1.168133548","rc":[{"batb":[[2,8,18]],"ltp":9.0,"tv":684.9,"id":15608820}]}]}
{"op":"mcm","clk":"995328869","pt":1580556427282,"mc":[{"id":"1.168133548","rc":[{"trd":[[5.5,83.03]],"batb":[[0,5.5,8.54]],"ltp":5.5,"tv":889.37,"id":17352128}],"tv":8146.27}]}
{"op":"mcm","clk":"995329101","pt":1580556428413,"mc":[{"id":"1.168133548","rc":[{"batl":[[0,9.2,2],[1,9.6,1.66],[2,10,5]],"ltp":9.0,"tv":684.9,"id":15608820}]}]}
{"op":"mcm","clk":"995329240","pt":1580556429243,"mc":[{"id":"1.168133548","rc":[{"batl":[[0,42,3.88],[1,44,1],[2,46,1.78]],"ltp":34.0,"tv":108.81,"id":9193530}]}]}
{"op":"mcm","clk":"995330226","pt":1580556434359,"mc":[{"id":"1.168133548","rc":[{"trd":[[11,282.89]],"batl":[[0,11,35.97]],"ltp":11.0,"tv":1193.18,"id":8429550}],"tv":8154.49}]}
{"op":"mcm","clk":"995330668","pt":1580556436549,"mc":[{"id":"1.168133548","rc":[{"batl":[[1,10,5],[2,11.5,22]],"ltp":9.0,"tv":684.9,"id":15608820}]}]}
{"op":"mcm","clk":"995331598","pt":1580556441562,"mc":[{"id":"1.168133548","rc":[{"batl":[[2,11,3.72]],"ltp":9.0,"tv":684.9,"id":15608820}]}]}
{"op":"mcm","clk":"995333182","pt":1580556449548,"mc":[{"id":"1.168133548","rc":[{"trd":[[11,291.09]],"batl":[[0,11,31.87]],"ltp":11.0,"tv":1201.38,"id":8429550},{"batl":[[2,10.5,2.68]],"ltp":9.0,"tv":684.9,"id":15608820}],"tv":8162.69}]}
{"op":"mcm","clk":"995333783","pt":1580556452477,"mc":[{"id":"1.168133548","rc":[{"trd":[[11,362.83]],"batb":[[0,11,4.82],[1,10.5,1.99],[2,10,27.17]],"batl":[[0,12,19.92],[1,12.5,57.84],[2,13.5,20.72]],"ltp":11.0,"tv":1273.12,"id":8429550}],"tv":8234.43}]}
{"op":"mcm","clk":"995333985","pt":1580556453456,"mc":[{"id":"1.168133548","rc":[{"batl":[[0,12.5,63.25],[1,13.5,21.56],[2,15,17]],"ltp":11.0,"tv":1273.12,"id":8429550},{"batb":[[1,8.2,9.19]],"ltp":9.0,"tv":684.9,"id":15608820}]}]}
{"op":"mcm","clk":"995334187","pt":1580556454463,"mc":[{"id":"1.168133548","rc":[{"batl":[[0,12.5,50.29],[1,13.5,33.92]],"ltp":11.0,"tv":1273.12,"id":8429550}]}]}
{"op":"mcm","clk":"995334830","pt":1580556457484,"mc":[{"id":"1.168133548","rc":[{"batl":[[2,16,16]],"ltp":11.0,"tv":1273.12,"id":8429550}]}]}
{"op":"mcm","clk":"995335024","pt":1580556458485,"mc":[{"id":"1.168133548","rc":[{"batl":[[0,12,2.71],[1,12.5,51.2],[2,13.5,33.92]],"ltp":11.0,"tv":1273.12,"id":8429550},{"batl":[[0,10,8.44]],"ltp":9.6,"tv":1362.2,"id":10616006},{"trd":[[7.6,305.17]],"batb":[[0,7.4,23.38],[1,7.2,21],[2,7,23]],"batl":[[0,7.6,16.35],[1,7.8,1.74],[2,8,27.57]],"ltp":7.6,"tv":1400.37,"id":10170404},{"batl":[[1,9.4,6.32],[2,9.6,22.11]],"ltp":9.0,"tv":684.9,"id":15608820},{"batl":[[0,40,8.96],[1,44,1.12]],"ltp":34.0,"tv":108.81,"id":9193530}],"tv":8268.4}]}
{"op":"mcm","clk":"995335186","pt":1580556459392,"mc":[{"id":"1.168133548","rc":[{"batb":[[1,7.2,27.26]],"batl":[[1,7.8,5.93],[2,8,30.34]],"ltp":7.6,"tv":1400.37,"id":10170404},{"batb":[[1,8.2,11.57]],"ltp":9.0,"tv":684.9,"id":15608820},{"batl":[[0,5.7,23.64]],"ltp":5.5,"tv":889.37,"id":17352128}]}]}
{"op":"mcm","clk":"995335791","pt":1580556462523,"mc":[{"id":"1.168133548","rc":[{"trd":[[9.4,51.74]],"batb":[[0,9.2,4.69],[1,8.6,14.57],[2,8.4,3.63]],"ltp":9.4,"tv":1367.53,"id":10616006}],"tv":8273.74}]}
{"op":"mcm","clk":"995336544","pt":1580556466505,"mc":[{"id":"1.168133548","rc":[{"batb":[[2,8.2,5.51]],"batl":[[0,10,2.11]],"ltp":9.4,"tv":1367.53,"id":10616006},{"batl":[[0,7.8,5.93],[1,8,30.34],[2,8.2,22.57]],"ltp":7.6,"tv":1400.37,"id":10170404},{"batl":[[2,10,5]],"ltp":9.0,"tv":684.9,"id":15608820},{"batl":[[0,40,2.63]],"ltp":34.0,"tv":108.81,"id":9193530}]}]}
{"op":"mcm","clk":"995336725","pt":1580556467415,"mc":[{"id":"1.168133548","rc":[{"trd":[[11,366.83]],"batb":[[0,11,2.82]],"ltp":11.0,"tv":1277.12,"id":8429550},{"trd":[[7,38.29]],"batb":[[0,7,2]],"ltp":7.0,"tv":751.55,"id":8231803},{"trd":[[7.8,224.07]],"batl":[[0,8,30.34],[1,8.2,22.57],[2,8.4,2.57]],"ltp":7.8,"tv":1403.85,"id":10170404}],"tv":8285.22}]}
{"op":"mcm","clk":"995336923","pt":1580556468533,"mc":[{"id":"1.168133548","rc":[{"batl":[[0,8,27.57],[1,8.2,38.49]],"ltp":7.8,"tv":1403.85,"id":10170404}]}]}
{"op":"mcm","clk":"995338284","pt":1580556475509,"mc":[{"id":"1.168133548","rc":[{"trd":[[12,168.17]],"batb":[[0,10.5,2.1],[1,10,27.17],[2,9.4,2]],"batl":[[0,12.5,51.2],[1,13.5,33.92],[2,16,16]],"ltp":12.0,"tv":1282.54,"id":8429550}],"tv":8290.64}]}
{"op":"mcm","clk":"995338489","pt":1580556476523,"mc":[{"id":"1.168133548","rc":[{"trd":[[12,168.39]],"batb":[[0,10.5,1.99],[2,9.4,8.81]],"batl":[[0,12,3.96],[1,12.5,50.29],[2,13.5,33.08]],"ltp":12.0,"tv":1282.76,"id":8429550},{"batl":[[0,9.2,4]],"ltp":9.0,"tv":684.9,"id":15608820}],"tv":8290.86}]}
{"op":"mcm","clk":"995338709","pt":1580556477500,"mc":[{"id":"1.168133548","rc":[{"batb":[[2,9.4,11.03]],"ltp":12.0,"tv":1282.76,"id":8429550}]}]}
{"op":"mcm","clk":"995338915","pt":1580556478516,"mc":[{"id":"1.168133548","rc":[{"batl":[[0,11,2.79],[1,12,3.96],[2,12.5,50.29]],"ltp":12.0,"tv":1282.76,"id":8429550}]}]}
{"op":"mcm","clk":"995339071","pt":1580556479313,"mc":[{"id":"1.168133548","rc":[{"batb":[[0,10.5,8.43]],"batl":[[1,12.5,50.29],[2,13.5,20.72]],"ltp":12.0,"tv":1282.76,"id":8429550},{"trd":[[5.7,57.76]],"batl":[[0,5.7,14.64]],"ltp":5.7,"tv":907.37,"id":17352128}],"tv":8308.86}]}
{"op":"mcm","clk":"995340324","pt":1580556485530,"mc":[{"id":"1.168133548","rc":[{"trd":[[10.5,211.64]],"batb":[[0,10,27.17],[1,9.4,11.03],[2,9.2,4.75]],"batl":[[0,12,5.04],[2,13.5,31.02]],"ltp":10.5,"tv":1288.34,"id":8429550}],"tv":8314.44}]}
{"op":"mcm","clk":"995340774","pt":1580556487457,"mc":[{"id":"1.168133548","rc":[{"batb":[[1,9.4,2]],"ltp":10.5,"tv":1288.34,"id":8429550}]}]}
{"op":"mcm","clk":"995340974","pt":1580556488478,"mc":[{"id":"1.168133548","rc":[{"batb":[[2,9.2,18.77]],"batl":[[0,12,1.08]],"ltp":10.5,"tv":1288.34,"id":8429550},{"batl":[[0,9,3.86],[1,9.2,4],[2,9.4,6.32]],"ltp":9.0,"tv":684.9,"id":15608820},{"batl":[[0,38,2.35]],"ltp":34.0,"tv":108.81,"id":9193530}]}]}
{"op":"mcm","clk":"995341378","pt":1580556490514,"mc":[{"id":"1.168133548","rc":[{"batb":[[2,9.2,25.78]],"ltp":10.5,"tv":1288.34,"id":8429550}]}]}
{"op":"mcm","clk":"995343655","pt":1580556501520,"mc":[{"id":"1.168133548","rc":[{"batb":[[1,9.4,7.32]],"ltp":10.5,"tv":1288.34,"id":8429550}]}]}
{"op":"mcm","clk":"995343859","pt":1580556502502,"mc":[{"id":"1.168133548","rc":[{"batb":[[0,7.6,5],[1,7.4,23.38],[2,7.2,27.26]],"ltp":7.8,"tv":1403.85,"id":10170404}]}]}
{"op":"mcm","clk":"995344286","pt":1580556504435,"mc":[{"id":"1.168133548","rc":[{"batb":[[2,7.2,21]],"ltp":7.8,"tv":1403.85,"id":10170404}]}]}
{"op":"mcm","clk":"995344917","pt":1580556507531,"mc":[{"id":"1.168133548","rc":[{"trd":[[8.8,21.19],[9,68.78],[9.2,168.87]],"batb":[[0,8.8,3.66],[1,8.6,14.07]],"batl":[[0,10,8.38],[1,10.5,2]],"ltp":8.8,"tv":1383.53,"id":10616006}],"tv":8330.43}]}
{"op":"mcm","clk":"995345131","pt":1580556508503,"mc":[{"id":"1.168133548","rc":[{"batb":[[0,8.8,5.66]],"batl":[[0,9.8,3.89],[1,10,8.38],[2,10.5,2]],"ltp":8.8,"tv":1383.53,"id":10616006}]}]}
{"op":"mcm","clk":"995345323","pt":1580556509515,"mc":[{"id":"1.168133548","rc":[{"batl":[[1,10,2.11]],"ltp":8.8,"tv":1383.53,"id":10616006}]}]}
{"op":"mcm","clk":"995345738","pt":1580556511502,"mc":[{"id":"1.168133548","rc":[{"batb":[[0,10,24.64]],"ltp":10.5,"tv":1288.34,"id":8429550},{"batl":[[1,42,2.46],[2,75,11.49]],"ltp":29.0,"tv":157.41,"id":9001159}]}]}
{"op":"mcm","clk":"995345958","pt":1580556512538,"mc":[{"id":"1.168133548","rc":[{"batl":[[2,75,11.56]],"ltp":29.0,"tv":157.41,"id":9001159}]}]}
{"op":"mcm","clk":"995346205","pt":1580556513505,"mc":[{"id":"1.168133548","rc":[{"trd":[[7,42.29]],"batb":[[0,6.8,13.17],[1,6.6,8.87],[2,6.4,28.08]],"batl":[[0,7.2,2.69]],"ltp":7.0,"tv":755.55,"id":8231803},{"batl":[[0,10,2.11],[1,10.5,2],[2,11,19.58]],"ltp":8.8,"tv":1383.53,"id":10616006}],"tv":8334.43}]}
{"op":"mcm","clk":"995346389","pt":1580556514509,"mc":[{"id":"1.168133548","rc":[{"batl":[[2,11,22.18]],"ltp":8.8,"tv":1383.53,"id":10616006}]}]}
{"op":"mcm","clk":"995346980","pt":1580556517459,"mc":[{"id":"1.168133548","rc":[{"batl":[[2,13,3.84]],"ltp":10.5,"tv":1288.34,"id":8429550},{"trd":[[7,43.33]],"batb":[[0,7,1.48],[1,6.8,13.17],[2,6.6,8.87]],"batl":[[0,7.2,2.17]],"ltp":7.0,"tv":756.6,"id":8231803},{"batl":[[1,40,1.54],[2,42,1.85]],"ltp":29.0,"tv":157.41,"id":9001159}],"tv":8335.47}]}
{"op":"mcm","clk":"995347246","pt":1580556518538,"mc":[{"id":"1.168133548","rc":[{"trd":[[7,46.29]],"batb":[[0,6.8,13.17],[1,6.6,14.33],[2,6.4,28.08]],"batl":[[0,7,2.78],[1,7.2,2.17],[2,7.4,5]],"ltp":7.0,"tv":759.56,"id":8231803},{"batl":[[0,9.2,4],[1,9.4,6.32],[2,10,5]],"ltp":9.0,"tv":684.9,"id":15608820},{"batl":[[0,44,1.12],[1,46,1.78],[2,80,2]],"ltp":34.0,"tv":108.81,"id":9193530}],"tv":8338.43}]}
{"op":"mcm","clk":"995348306","pt":1580556523543,"mc":[{"id":"1.168133548","rc":[{"batl":[[0,12,15.08]],"ltp":10.5,"tv":1288.34,"id":8429550}]}]}
{"op":"mcm","clk":"995348577","pt":1580556524557,"mc":[{"id":"1.168133548","rc":[{"batb":[[0,5.6,3.08],[1,5.5,8.54]],"ltp":5.7,"tv":907.37,"id":17352128}]}]}
{"op":"mcm","clk":"995348748","pt":1580556525427,"mc":[{"id":"1.168133548","rc":[{"trd":[[8.6,254.03]],"batb":[[0,8.6,1.46],[2,8,22.18]],"ltp":8.6,"tv":690.9,"id":15608820},{"batb":[[1,28,3.94]],"ltp":34.0,"tv":108.81,"id":9193530}],"tv":8344.43}]}
{"op":"mcm","clk":"995349200","pt":1580556527551,"mc":[{"id":"1.168133548","rc":[{"batb":[[0,6.8,15.17]],"ltp":7.0,"tv":759.56,"id":8231803},{"batb":[[1,8.2,9.19]],"ltp":8.6,"tv":690.9,"id":15608820}]}]}
{"op":"mcm","clk":"995349974","pt":1580556531365,"mc":[{"id":"1.168133548","rc":[{"batb":[[2,8,19.18]],"ltp":8.6,"tv":690.9,"id":15608820}]}]}
{"op":"mcm","clk":"995350812","pt":1580556535574,"mc":[{"id":"1.168133548","rc":[{"trd":[[8.6,256.96]],"batb":[[0,8.2,9.19],[1,8,19.18],[2,7.8,5.54]],"batl":[[0,8.6,2.53],[1,9.2,4]],"ltp":8.6,"tv":693.83,"id":15608820}],"tv":8347.37}]}
{"op":"mcm","clk":"995351397","pt":1580556538471,"mc":[{"id":"1.168133548","rc":[{"batl":[[0,9.8,2],[1,10,2.11],[2,10.5,2]],"ltp":8.8,"tv":1383.53,"id":10616006},{"batb":[[0,8.2,11.24]],"ltp":8.6,"tv":693.83,"id":15608820}]}]}
{"op":"mcm","clk":"995351616","pt":1580556539474,"mc":[{"id":"1.168133548","rc":[{"batl":[[0,9.2,4],[1,10,5],[2,10.5,2.68]],"ltp":8.6,"tv":693.83,"id":15608820}]}]}
{"op":"mcm","clk":"995352271","pt":1580556542574,"mc":[{"id":"1.168133548","rc":[{"batl":[[1,10,1.68]],"ltp":8.8,"tv":1383.53,"id":10616006}]}]}
{"op":"mcm","clk":"995352474","pt":1580556543426,"mc":[{"id":"1.168133548","rc":[{"batl":[[2,10.5,2.41]],"ltp":8.8,"tv":1383.53,"id":10616006}]}]}
{"op":"mcm","clk":"995352924","pt":1580556545408,"mc":[{"id":"1.168133548","rc":[{"batl":[[1,9.8,2.44],[2,10,7.76]],"ltp":8.6,"tv":693.83,"id":15608820}]}]}
{"op":"mcm","clk":"995353549","pt":1580556548519,"mc":[{"id":"1.168133548","rc":[{"batl":[[0,7.2,2.17],[1,7.4,5],[2,7.6,5.66]],"ltp":7.0,"tv":759.56,"id":8231803}]}]}
{"op":"mcm","clk":"995353736","pt":1580556549526,"mc":[{"id":"1.168133548","rc":[{"batl":[[0,42,4.4],[1,44,1],[2,46,1.78]],"ltp":34.0,"tv":108.81,"id":9193530}]}]}
{"op":"mcm","clk":"995354861","pt":1580556555313,"mc":[{"id":"1.168133548","rc":[{"trd":[[8.2,47.24]],"batb":[[0,8.2,8.24]],"ltp":8.2,"tv":699.83,"id":15608820}],"tv":8353.37}]}
{"op":"mcm","clk":"995357524","pt":1580556567539,"mc":[{"id":"1.168133548","rc":[{"batb":[[0,27,5.8],[2,24,5.29]],"ltp":29.0,"tv":157.41,"id":9001159}]}]}
{"op":"mcm","clk":"995357722","pt":1580556568518,"mc":[{"id":"1.168133548","rc":[{"batl":[[0,9.2,2],[1,9.6,2],[2,9.8,2.44]],"ltp":8.2,"tv":699.83,"id":15608820}]}]}
{"op":"mcm","clk":"995359599","pt":1580556577499,"mc":[{"id":"1.168133548","rc":[{"batl":[[1,10,5],[2,10.5,2.68]],"ltp":8.2,"tv":699.83,"id":15608820},{"trd":[[5.7,75.76]],"batl":[[0,5.7,5.64]],"ltp":5.7,"tv":925.37,"id":17352128}],"tv":8371.37}]}
{"op":"mcm","clk":"995359801","pt":1580556578519,"mc":[{"id":"1.168133548","rc":[{"batl":[[0,9.2,4]],"ltp":8.2,"tv":699.83,"id":15608820},{"batb":[[1,28,7.69]],"batl":[[0,44,1.12],[1,46,1.78],[2,80,2]],"ltp":34.0,"tv":108.81,"id":9193530},{"batb":[[0,5.6,11.59]],"ltp":5.7,"tv":925.37,"id":17352128}]}]}
{"op":"mcm","clk":"995359953","pt":1580556579205,"mc":[{"id":"1.168133548","rc":[{"batl":[[0,7,2.54],[1,7.2,2.17],[2,7.4,5]],"ltp":7.0,"tv":759.56,"id":8231803},{"batl":[[0,40,2.89],[1,44,1.12],[2,46,1.78]],"ltp":34.0,"tv":108.81,"id":9193530}]}]}
{"op":"mcm","clk":"995360239","pt":1580556580511,"mc":[{"id":"1.168133548","rc":[{"batl":[[1,9.8,3.02],[2,10,5]],"ltp":8.2,"tv":699.83,"id":15608820}]}]}
{"op":"mcm","clk":"995360486","pt":1580556581499,"mc":[{"id":"1.168133548","rc":[{"batl":[[1,9.8,6.08]],"ltp":8.2,"tv":699.83,"id":15608820}]}]}
{"op":"mcm","clk":"995366145","pt":1580556607503,"mc":[{"id":"1.168133548","rc":[{"batb":[[0,10.5,1.64],[1,10,24.64],[2,9.4,7.32]],"ltp":10.5,"tv":1288.34,"id":8429550},{"batl":[[0,9.2,2]],"ltp":8.2,"tv":699.83,"id":15608820}]}]}
{"op":"mcm","clk":"995366399","pt":1580556608474,"mc":[{"id":"1.168133548","rc":[{"batl":[[1,9.6,2],[2,9.8,6.08]],"ltp":8.2,"tv":699.83,"id":15608820}]}]}
{"op":"mcm","clk":"995366588","pt":1580556609397,"mc":[{"id":"1.168133548","rc":[{"batl":[[0,7.2,2.17],[1,7.4,5],[2,7.6,5.66]],"ltp":7.0,"tv":759.56,"id":8231803},{"batl":[[2,10,7.4]],"ltp":8.2,"tv":699.83,"id":15608820},{"batl":[[0,38,2.44]],"ltp":34.0,"tv":108.81,"id":9193530}]}]}
{"op":"mcm","clk":"995370442","pt":1580556627569,"mc":[{"id":"1.168133548","rc":[{"batl":[[0,9.2,4],[1,10,7.4],[2,10.5,6.4]],"ltp":8.2,"tv":699.83,"id":15608820}]}]}
{"op":"mcm","clk":"995370645","pt":1580556628554,"mc":[{"id":"1.168133548","rc":[{"trd":[[5.7,176.37]],"batb":[[0,5.7,12.05]],"ltp":5.7,"tv":1647.98,"id":9417341},{"batl":[[1,9.8,21.66],[2,10,7.4]],"ltp":8.2,"tv":699.83,"id":15608820}],"tv":8374.73}]}
{"op":"mcm","clk":"995371688","pt":1580556633570,"mc":[{"id":"1.168133548","rc":[{"trd":[[5.7,196.36]],"batb":[[0,5.7,2.06]],"ltp":5.7,"tv":1667.97,"id":9417341},{"batl":[[1,9.8,24.09]],"ltp":8.2,"tv":699.83,"id":15608820}],"tv":8394.72}]}
{"op":"mcm","clk":"995371878","pt":1580556634484,"mc":[{"id":"1.168133548","rc":[{"trd":[[8.8,25.19]],"batb":[[0,8.8,3.66]],"ltp":8.8,"tv":1387.53,"id":10616006}],"tv":8398.72}]}
{"op":"mcm","clk":"995372287","pt":1580556636378,"mc":[{"id":"1.168133548","rc":[{"batl":[[1,9.8,2.44]],"ltp":8.2,"tv":699.83,"id":15608820}]}]}
{"op":"mcm","clk":"995372535","pt":1580556637496,"mc":[{"id":"1.168133548","rc":[{"batb":[[0,7.8,2.21],[1,7.6,5],[2,7.4,23.38]],"ltp":7.8,"tv":1403.85,"id":10170404}]}]}
{"op":"mcm","clk":"995372975","pt":1580556639571,"mc":[{"id":"1.168133548","rc":[{"batl":[[0,7,4.16],[1,7.2,2.17],[2,7.4,5]],"ltp":7.0,"tv":759.56,"id":8231803},{"batl":[[0,44,1.12],[1,46,1.78],[2,80,2]],"ltp":34.0,"tv":108.81,"id":9193530}]}]}
{"op":"mcm","clk":"995373120","pt":1580556640376,"mc":[{"id":"1.168133548","rc":[{"trd":[[5.7,200.49]],"batb":[[0,5.6,33.85],[1,5.5,9.06],[2,5.4,20]],"ltp":5.7,"tv":1672.1,"id":9417341}],"tv":8402.85}]}
{"op":"mcm","clk":"995374397","pt":1580556646505,"mc":[{"id":"1.168133548","rc":[{"batl":[[0,9.2,2],[1,9.6,2],[2,9.8,2.44]],"ltp":8.2,"tv":699.83,"id":15608820}]}]}
{"op":"mcm","clk":"995376420","pt":1580556654438,"mc":[{"id":"1.168133548","rc":[{"batl":[[1,9.4,1.69],[2,9.6,2]],"ltp":8.2,"tv":699.83,"id":15608820}]}]}
{"op":"mcm","clk":"995377071","pt":1580556657529,"mc":[{"id":"1.168133548","rc":[{"batl":[[0,5.7,1.14],[1,5.8,2],[2,5.9,20]],"ltp":5.7,"tv":1672.1,"id":9417341}]}]}
{"op":"mcm","clk":"995377472","pt":1580556659574,"mc":[{"id":"1.168133548","rc":[{"batl":[[0,5.8,2],[1,5.9,20],[2,6,84.29]],"ltp":5.7,"tv":1672.1,"id":9417341}]}]}
{"op":"mcm","clk":"995378709","pt":1580556665429,"mc":[{"id":"1.168133548","rc":[{"batb":[[0,10.5,4.17]],"ltp":10.5,"tv":1288.34,"id":8429550},{"batb":[[0,7.8,8.79]],"ltp":7.8,"tv":1403.85,"id":10170404},{"batl":[[1,34,3.14],[2,42,2.78]],"ltp":29.0,"tv":157.41,"id":9001159}]}]}
{"op":"mcm","clk":"995378946","pt":1580556666530,"mc":[{"id":"1.168133548","rc":[{"batl":[[0,9.2,4],[2,10,5]],"ltp":8.2,"tv":699.83,"id":15608820}]}]}
{"op":"mcm","clk":"995379311","pt":1580556668455,"mc":[{"id":"1.168133548","rc":[{"batl":[[2,10,8.08]],"ltp":8.2,"tv":699.83,"id":15608820}]}]}
{"op":"mcm","clk":"995379530","pt":1580556669548,"mc":[{"id":"1.168133548","rc":[{"batl":[[0,7.2,2.17],[1,7.4,5],[2,7.6,5.66]],"ltp":7.0,"tv":759.56,"id":8231803}]}]}
{"op":"mcm","clk":"995379710","pt":1580556670528,"mc":[{"id":"1.168133548","rc":[{"batl":[[2,10,5]],"ltp":8.2,"tv":699.83,"id":15608820},{"batl":[[0,42,4.54],[1,44,1],[2,46,1.78]],"ltp":34.0,"tv":108.81,"id":9193530},{"batl":[[2,42,1.85]],"ltp":29.0,"tv":157.41,"id":9001159}]}]}
{"op":"mcm","clk":"995380013","pt":1580556671566,"mc":[{"id":"1.168133548","rc":[{"batl":[[2,9.8,2.44]],"ltp":8.2,"tv":699.83,"id":15608820},{"batl":[[1,32,1.16],[2,34,3.14]],"ltp":29.0,"tv":157.41,"id":9001159}]}]}
{"op":"mcm","clk":"995381078","pt":1580556676557,"mc":[{"id":"1.168133548","rc":[{"batl":[[0,9.2,2],[2,9.6,2]],"ltp":8.2,"tv":699.83,"id":15608820}]}]}
{"op":"mcm","clk":"995381845","pt":1580556680464,"mc":[{"id":"1.168133548","rc":[{"trd":[[7.8,241.66]],"batb":[[0,7.6,5],[1,7.4,23.38],[2,7.2,21]],"batl":[[0,7.8,11.2],[1,8,27.57],[2,8.2,38.49]],"ltp":7.8,"tv":1421.45,"id":10170404}],"tv":8420.45}]}
{"op":"mcm","clk":"995385446","pt":1580556696491,"mc":[{"id":"1.168133548","rc":[{"batl":[[0,9.2,4],[2,10,5]],"ltp":8.2,"tv":699.83,"id":15608820}]}]}
{"op":"mcm","clk":"995385686","pt":1580556697373,"mc":[{"id":"1.168133548","rc":[{"batl":[[2,10,7.4]],"ltp":8.2,"tv":699.83,"id":15608820}]}]}
{"op":"mcm","clk":"995386335","pt":1580556700501,"mc":[{"id":"1.168133548","rc":[{"trd":[[9.8,94]],"batb":[[0,9.8,3],[1,8.8,3.66],[2,8.6,14.07]],"batl":[[0,10,1.68],[1,10.5,2.41],[2,11,19.58]],"ltp":9.8,"tv":1391.53,"id":10616006}],"tv":8424.45}]}
{"op":"mcm","clk":"995386497","pt":1580556701215,"mc":[{"id":"1.168133548","rc":[{"batl":[[1,5.9,22]],"ltp":5.7,"tv":1672.1,"id":9417341},{"batl":[[0,10,7.95]],"ltp":9.8,"tv":1391.53,"id":10616006},{"batb":[[1,8,15]],"batl":[[2,9.8,2.44]],"ltp":8.2,"tv":699.83,"id":15608820}]}]}
{"op":"mcm","clk":"995386825","pt":1580556702562,"mc":[{"id":"1.168133548","rc":[{"batl":[[0,7,2.54],[1,7.2,2.17],[2,7.4,5]],"ltp":7.0,"tv":759.56,"id":8231803},{"batb":[[1,8.8,8.62]],"ltp":9.8,"tv":1391.53,"id":10616006},{"batl":[[0,40,2.89],[1,44,1.12]],"ltp":34.0,"tv":108.81,"id":9193530}]}]}
{"op":"mcm","clk":"995387053","pt":1580556703536,"mc":[{"id":"1.168133548","rc":[{"batl":[[0,11.5,1.39],[1,12,15.08],[2,12.5,50.29]],"ltp":10.5,"tv":1288.34,"id":8429550}]}]}
{"op":"mcm","clk":"995388309","pt":1580556709473,"mc":[{"id":"1.168133548","rc":[{"batb":[[2,9.4,2]],"ltp":10.5,"tv":1288.34,"id":8429550}]}]}
{"op":"mcm","clk":"995388926","pt":1580556712358,"mc":[{"id":"1.168133548","rc":[{"trd":[[9.8,100]],"batb":[[0,8.8,8.62],[1,8.6,14.07],[2,8.4,3.63]],"batl":[[0,9.8,3],[1,10,7.95],[2,10.5,2.41]],"ltp":9.8,"tv":1397.53,"id":10616006}],"tv":8430.45}]}
{"op":"mcm","clk":"995389148","pt":1580556713479,"mc":[{"id":"1.168133548","rc":[{"batb":[[1,8,18.36]],"ltp":8.2,"tv":699.83,"id":15608820}]}]}
{"op":"mcm","clk":"995389371","pt":1580556714456,"mc":[{"id":"1.168133548","rc":[{"batb":[[0,8.8,3.66]],"ltp":9.8,"tv":1397.53,"id":10616006}]}]}
{"op":"mcm","clk":"995389805","pt":1580556716492,"mc":[{"id":"1.168133548","rc":[{"batl":[[0,9.2,2],[2,9.6,2]],"ltp":8.2,"tv":699.83,"id":15608820}]}]}
{"op":"mcm","clk":"995390002","pt":1580556717481,"mc":[{"id":"1.168133548","rc":[{"batb":[[0,9,9.11],[1,8.8,3.66],[2,8.6,14.07]],"ltp":9.8,"tv":1397.53,"id":10616006}]}]}
{"op":"mcm","clk":"995390221","pt":1580556718563,"mc":[{"id":"1.168133548","rc":[{"batl":[[1,10,1.68]],"ltp":9.8,"tv":1397.53,"id":10616006}]}]}
{"op":"mcm","clk":"995391015","pt":1580556722389,"mc":[{"id":"1.168133548","rc":[{"batb":[[0,9.2,2.13],[1,9,9.11],[2,8.8,3.66]],"ltp":9.8,"tv":1397.53,"id":10616006}]}]}
{"op":"mcm","clk":"995392115","pt":1580556727489,"mc":[{"id":"1.168133548","rc":[{"batl":[[0,9.2,4],[2,10,5]],"ltp":8.2,"tv":699.83,"id":15608820}]}]}
{"op":"mcm","clk":"995392311","pt":1580556728386,"mc":[{"id":"1.168133548","rc":[{"batl":[[0,12,15.08],[1,12.5,50.29],[2,13.5,20.72]],"ltp":10.5,"tv":1288.34,"id":8429550},{"batl":[[2,10,7.4]],"ltp":8.2,"tv":699.83,"id":15608820}]}]}
{"op":"mcm","clk":"995393355","pt":1580556733430,"mc":[{"id":"1.168133548","rc":[{"batl":[[0,7.2,2.17],[1,7.4,5],[2,7.6,5.66]],"ltp":7.0,"tv":759.56,"id":8231803},{"batl":[[0,38,2.47]],"ltp":34.0,"tv":108.81,"id":9193530}]}]}
{"op":"mcm","clk":"995393603","pt":1580556734516,"mc":[{"id":"1.168133548","rc":[{"batl":[[2,9.8,2.44]],"ltp":8.2,"tv":699.83,"id":15608820}]}]}
{"op":"mcm","clk":"995395822","pt":1580556745518,"mc":[{"id":"1.168133548","rc":[{"batb":[[1,9,12.84]],"batl":[[2,10.5,5.6]],"ltp":9.8,"tv":1397.53,"id":10616006}]}]}
{"op":"mcm","clk":"995400103","pt":1580556765549,"mc":[{"id":"1.168133548","rc":[{"batl":[[0,9.2,2],[2,9.6,2]],"ltp":8.2,"tv":699.83,"id":15608820}]}]}
{"op":"mcm","clk":"995400535","pt":1580556767452,"mc":[{"id":"1.168133548","rc":[{"batl":[[0,7,4.16],[1,7.2,2.17],[2,7.4,5]],"ltp":7.0,"tv":759.56,"id":8231803},{"batl":[[0,44,1.12],[1,46,1.78],[2,80,2]],"ltp":34.0,"tv":108.81,"id":9193530}]}]}
{"op":"mcm","clk":"995402915","pt":1580556778474,"mc":[{"id":"1.168133548","rc":[{"batl":[[1,9.6,2],[2,10,5]],"ltp":8.2,"tv":699.83,"id":15608820}]}]}
{"op":"mcm","clk":"995403550","pt":1580556781376,"mc":[{"id":"1.168133548","rc":[{"batl":[[0,8.8,4],[1,9.2,2],[2,9.6,2]],"ltp":8.2,"tv":699.83,"id":15608820}]}]}
{"op":"mcm","clk":"995403851","pt":1580556782571,"mc":[{"id":"1.168133548","rc":[{"batb":[[0,10.5,1.64]],"ltp":10.5,"tv":1288.34,"id":8429550},{"batl":[[2,42,2.46]],"ltp":29.0,"tv":157.41,"id":9001159}]}]}
{"op":"mcm","clk":"995404099","pt":1580556783557,"mc":[{"id":"1.168133548","rc":[{"batb":[[2,9.4,8.81]],"ltp":10.5,"tv":1288.34,"id":8429550},{"batl":[[2,42,5.46]],"ltp":29.0,"tv":157.41,"id":9001159}]}]}
{"op":"mcm","clk":"995404498","pt":1580556785367,"mc":[{"id":"1.168133548","rc":[{"batl":[[1,9.2,4],[2,10,5]],"ltp":8.2,"tv":699.83,"id":15608820}]}]}
{"op":"mcm","clk":"995404963","pt":1580556787464,"mc":[{"id":"1.168133548","rc":[{"batb":[[0,5.7,3.02],[1,5.6,33.85],[2,5.5,9.06]],"ltp":5.7,"tv":1672.1,"id":9417341}]}]}
{"op":"mcm","clk":"995405144","pt":1580556788278,"mc":[{"id":"1.168133548","rc":[{"batb":[[2,9.4,2]],"ltp":10.5,"tv":1288.34,"id":8429550},{"batl":[[2,42,2.46]],"ltp":29.0,"tv":157.41,"id":9001159}]}]}
{"op":"mcm","clk":"995405417","pt":1580556789459,"mc":[{"id":"1.168133548","rc":[{"batl":[[0,5.9,22],[1,6,91.99],[2,6.2,1064.16]],"ltp":5.7,"tv":1672.1,"id":9417341}]}]}
{"op":"mcm","clk":"995406582","pt":1580556794558,"mc":[{"id":"1.168133548","rc":[{"batl":[[0,5.8,2],[1,5.9,22],[2,6,91.99]],"ltp":5.7,"tv":1672.1,"id":9417341}]}]}
{"op":"mcm","clk":"995406759","pt":1580556795474,"mc":[{"id":"1.168133548","rc":[{"batl":[[0,8.8,6],[1,9.2,2]],"ltp":8.2,"tv":699.83,"id":15608820}]}]}
{"op":"mcm","clk":"995407383","pt":1580556798488,"mc":[{"id":"1.168133548","rc":[{"batl":[[0,7.2,2.17],[1,7.4,5],[2,7.6,5.66]],"ltp":7.0,"tv":759.56,"id":8231803},{"batl":[[2,9.8,7.54]],"ltp":8.2,"tv":699.83,"id":15608820},{"batl":[[0,42,4.4],[1,44,1],[2,46,1.78]],"ltp":34.0,"tv":108.81,"id":9193530}]}]}
{"op":"mcm","clk":"995412617","pt":1580556822571,"mc":[{"id":"1.168133548","rc":[{"trd":[[5.7,203.85]],"batb":[[0,5.7,1.34]],"batl":[[1,5.9,20]],"ltp":5.7,"tv":1675.47,"id":9417341}],"tv":8433.81}]}
{"op":"mcm","clk":"995412858","pt":1580556823551,"mc":[{"id":"1.168133548","rc":[{"trd":[[5.7,206.54]],"batb":[[0,5.6,33.85],[1,5.5,9.06],[2,5.4,20]],"ltp":5.7,"tv":1678.15,"id":9417341}],"tv":8436.49}]}
{"op":"mcm","clk":"995413721","pt":1580556827466,"mc":[{"id":"1.168133548","rc":[{"batb":[[0,8.4,2.05],[1,8.2,8.24],[2,8,18.36]],"ltp":8.2,"tv":699.83,"id":15608820}]}]}
{"op":"mcm","clk":"995413962","pt":1580556828556,"mc":[{"id":"1.168133548","rc":[{"batl":[[0,7,2.54],[1,7.2,2.17],[2,7.4,5]],"ltp":7.0,"tv":759.56,"id":8231803},{"batl":[[0,40,2.89],[1,44,1.12]],"ltp":34.0,"tv":108.81,"id":9193530}]}]}
{"op":"mcm","clk":"995414152","pt":1580556829503,"mc":[{"id":"1.168133548","rc":[{"batb":[[2,8,15]],"ltp":8.2,"tv":699.83,"id":15608820}]}]}
{"op":"mcm","clk":"995419576","pt":1580556855458,"mc":[{"id":"1.168133548","rc":[{"trd":[[7.6,314.55]],"batb":[[0,7.4,23.69],[1,7.2,21],[2,7,23]],"ltp":7.6,"tv":1430.83,"id":10170404}],"tv":8445.87}]}
{"op":"mcm","clk":"995419814","pt":1580556856557,"mc":[{"id":"1.168133548","rc":[{"batb":[[1,7.2,28.79]],"ltp":7.6,"tv":1430.83,"id":10170404}]}]}
{"op":"mcm","clk":"995420664","pt":1580556860574,"mc":[{"id":"1.168133548","rc":[{"batl":[[0,7.2,2.17],[1,7.4,5],[2,7.6,5.66]],"ltp":7.0,"tv":759.56,"id":8231803},{"batl":[[0,38,2.4]],"ltp":34.0,"tv":108.81,"id":9193530}]}]}
{"op":"mcm","clk":"995421619","pt":1580556865479,"mc":[{"id":"1.168133548","rc":[{"trd":[[7.4,65.53],[7.6,315.17]],"batb":[[0,7.4,21.69]],"ltp":7.4,"tv":1434.83,"id":10170404}],"tv":8449.87}]}
{"op":"mcm","clk":"995423686","pt":1580556875569,"mc":[{"id":"1.168133548","rc":[{"batb":[[0,7.6,10],[1,7.4,21.69],[2,7.2,28.79]],"ltp":7.4,"tv":1434.83,"id":10170404}]}]}
{"op":"mcm","clk":"995423910","pt":1580556876560,"mc":[{"id":"1.168133548","rc":[{"batb":[[2,7.2,21]],"ltp":7.4,"tv":1434.83,"id":10170404}]}]}
{"op":"mcm","clk":"995429163","pt":1580556901527,"mc":[{"id":"1.168133548","rc":[{"batl":[[1,8,25],[2,8.2,35.92]],"ltp":7.4,"tv":1434.83,"id":10170404}]}]}
{"op":"mcm","clk":"995429359","pt":1580556902533,"mc":[{"id":"1.168133548","rc":[{"batl":[[0,7,4.16],[1,7.2,2.17],[2,7.4,5]],"ltp":7.0,"tv":759.56,"id":8231803},{"batl":[[0,44,1.12],[1,46,1.78],[2,80,2]],"ltp":34.0,"tv":108.81,"id":9193530}]}]}
{"op":"mcm","clk":"995429999","pt":1580556905439,"mc":[{"id":"1.168133548","rc":[{"batl":[[0,7.8,13.77],[1,8,27.57],[2,8.2,38.49]],"ltp":7.4,"tv":1434.83,"id":10170404}]}]}
{"op":"mcm","clk":"995430684","pt":1580556908549,"mc":[{"id":"1.168133548","rc":[{"trd":[[27,48.28],[28,1.78]],"batb":[[0,27,2.8]],"ltp":27.0,"tv":163.42,"id":9001159}],"tv":8455.87}]}
{"op":"mcm","clk":"995432187","pt":1580556915466,"mc":[{"id":"1.168133548","rc":[{"batb":[[0,27,7.8]],"ltp":27.0,"tv":163.42,"id":9001159}]}]}
{"op":"mcm","clk":"995433902","pt":1580556923545,"mc":[{"id":"1.168133548","rc":[{"batl":[[1,32,1.66]],"ltp":27.0,"tv":163.42,"id":9001159}]}]}
{"op":"mcm","clk":"995438134","pt":1580556943564,"mc":[{"id":"1.168133548","rc":[{"batl":[[0,7.2,2.17],[1,7.4,5],[2,7.6,5.66]],"ltp":7.0,"tv":759.56,"id":8231803},{"batl":[[0,42,4.41],[1,44,1],[2,46,1.78]],"ltp":34.0,"tv":108.81,"id":9193530}]}]}
{"op":"mcm","clk":"995439446","pt":1580556949561,"mc":[{"id":"1.168133548","rc":[{"trd":[[30,9.09],[32,29.75]],"batb":[[0,30,4.5]],"ltp":30.0,"tv":112.81,"id":9193530}],"tv":8459.87}]}
{"op":"mcm","clk":"995441018","pt":1580556956502,"mc":[{"id":"1.168133548","rc":[{"batb":[[1,28,3.94]],"ltp":30.0,"tv":112.81,"id":9193530},{"batl":[[2,42,4.8]],"ltp":27.0,"tv":163.42,"id":9001159}]}]}
{"op":"mcm","clk":"995441405","pt":1580556958284,"mc":[{"id":"1.168133548","rc":[{"batl":[[2,42,2.46]],"ltp":27.0,"tv":163.42,"id":9001159}]}]}
{"op":"mcm","clk":"995443624","pt":1580556968563,"mc":[{"id":"1.168133548","rc":[{"batl":[[1,9,2],[2,9.2,2]],"ltp":8.2,"tv":699.83,"id":15608820}]}]}
{"op":"mcm","clk":"995444287","pt":1580556971462,"mc":[{"id":"1.168133548","rc":[{"batl":[[0,42,4.81]],"ltp":30.0,"tv":112.81,"id":9193530}]}]}
{"op":"mcm","clk":"995444734","pt":1580556973434,"mc":[{"id":"1.168133548","rc":[{"batl":[[0,40,4.91],[1,44,1.12]],"ltp":30.0,"tv":112.81,"id":9193530}]}]}
{"op":"mcm","clk":"995444982","pt":1580556974568,"mc":[{"id":"1.168133548","rc":[{"batb":[[1,5.5,19.06]],"ltp":5.7,"tv":1678.15,"id":9417341},{"batb":[[1,5.5,18.54]],"ltp":5.7,"tv":925.37,"id":17352128}]}]}
{"op":"mcm","clk":"995451791","pt":1580557007271,"mc":[{"id":"1.168133548","rc":[{"trd":[[7.6,331.17]],"batb":[[0,7.6,2]],"ltp":7.6,"tv":1450.83,"id":10170404}],"tv":8475.87}]}
{"op":"mcm","clk":"995452280","pt":1580557009564,"mc":[{"id":"1.168133548","rc":[{"batl":[[0,7,2.02],[1,7.2,2.17],[2,7.4,5]],"ltp":7.0,"tv":759.56,"id":8231803},{"batl":[[0,38,4.08],[1,44,1.52]],"ltp":30.0,"tv":112.81,"id":9193530}]}]}
{"op":"mcm","clk":"995472489","pt":1580557054388,"mc":[{"id":"1.168133548","rc":[{"batl":[[2,6,95.35]],"ltp":5.7,"tv":1678.15,"id":9417341},{"trd":[[7.6,335.17]],"batb":[[0,7.4,21.69],[1,7.2,21],[2,7,23]],"batl":[[0,7.6,14.98],[1,7.8,13.77],[2,8,27.57]],"ltp":7.6,"tv":1454.83,"id":10170404}],"tv":8479.87}]}
{"op":"mcm","clk":"995472691","pt":1580557055515,"mc":[{"id":"1.168133548","rc":[{"batl":[[0,7.2,2.17],[1,7.4,5],[2,7.6,5.66]],"ltp":7.0,"tv":759.56,"id":8231803},{"batb":[[1,7.2,25.47]],"ltp":7.6,"tv":1454.83,"id":10170404},{"batl":[[0,36,3.78]],"ltp":30.0,"tv":112.81,"id":9193530}]}]}
{"op":"mcm","clk":"995473301","pt":1580557058493,"mc":[{"id":"1.168133548","rc":[{"batb":[[0,27,8.42]],"ltp":27.0,"tv":163.42,"id":9001159}]}]}
{"op":"mcm","clk":"995473633","pt":1580557060422,"mc":[{"id":"1.168133548","rc":[{"batl":[[0,5.8,45.42],[1,6,13.37],[2,6.2,41.09]],"ltp":5.7,"tv":925.37,"id":17352128}]}]}
{"op":"mcm","clk":"995478200","pt":1580557082446,"mc":[{"id":"1.168133548","rc":[{"batl":[[0,7.2,2.24]],"ltp":7.0,"tv":759.56,"id":8231803}]}]}
{"op":"mcm","clk":"995479375","pt":1580557088566,"mc":[{"id":"1.168133548","rc":[{"batb":[[0,30,5.04]],"ltp":30.0,"tv":112.81,"id":9193530}]}]}
{"op":"mcm","clk":"995479572","pt":1580557089532,"mc":[{"id":"1.168133548","rc":[{"batl":[[0,7,3.04],[1,7.2,2.24],[2,7.4,5]],"ltp":7.0,"tv":759.56,"id":8231803},{"batb":[[1,28,7.69]],"batl":[[0,34,2.39]],"ltp":30.0,"tv":112.81,"id":9193530}]}]}
{"op":"mcm","clk":"995480190","pt":1580557092566,"mc":[{"id":"1.168133548","rc":[{"batl":[[0,5.8,2.09]],"ltp":5.7,"tv":1678.15,"id":9417341}]}]}
{"op":"mcm","clk":"995483977","pt":1580557110488,"mc":[{"id":"1.168133548","rc":[{"batl":[[0,7.6,15.05]],"ltp":7.6,"tv":1454.83,"id":10170404}]}]}
{"op":"mcm","clk":"995486681","pt":1580557123462,"mc":[{"id":"1.168133548","rc":[{"batl":[[0,12,1.08]],"ltp":10.5,"tv":1288.34,"id":8429550}]}]}
{"op":"mcm","clk":"995486894","pt":1580557124482,"mc":[{"id":"1.168133548","rc":[{"batl":[[2,13,11.77]],"ltp":10.5,"tv":1288.34,"id":8429550}]}]}
{"op":"mcm","clk":"995487026","pt":1580557125072,"mc":[{"id":"1.168133548","rc":[{"batl":[[2,13.5,27.04]],"ltp":10.5,"tv":1288.34,"id":8429550}]}]}
{"op":"mcm","clk":"995487915","pt":1580557129490,"mc":[{"id":"1.168133548","rc":[{"batl":[[0,5.8,45.51]],"ltp":5.7,"tv":925.37,"id":17352128}]}]}
{"op":"mcm","clk":"995488497","pt":1580557132507,"mc":[{"id":"1.168133548","rc":[{"batl":[[2,13.5,30.25]],"ltp":10.5,"tv":1288.34,"id":8429550}]}]}
{"op":"mcm","clk":"995489231","pt":1580557136087,"mc":[{"id":"1.168133548","rc":[{"batb":[[2,9.4,7]],"batl":[[2,13,3.61]],"ltp":10.5,"tv":1288.34,"id":8429550}]}]}
{"op":"mcm","clk":"995490141","pt":1580557140525,"mc":[{"id":"1.168133548","rc":[{"batl":[[1,32,1.16]],"ltp":27.0,"tv":163.42,"id":9001159}]}]}
{"op":"mcm","clk":"995491559","pt":1580557147531,"mc":[{"id":"1.168133548","rc":[{"batl":[[0,12,1.12]],"ltp":10.5,"tv":1288.34,"id":8429550}]}]}
{"op":"mcm","clk":"995495474","pt":1580557166374,"mc":[{"id":"1.168133548","rc":[{"batl":[[0,8.8,6.06]],"ltp":8.2,"tv":699.83,"id":15608820}]}]}
{"op":"mcm","clk":"995499181","pt":1580557184523,"mc":[{"id":"1.168133548","rc":[{"batl":[[0,34,2.4]],"ltp":30.0,"tv":112.81,"id":9193530}]}]}
{"op":"mcm","clk":"995500232","pt":1580557189525,"mc":[{"id":"1.168133548","rc":[{"batl":[[1,44,1.12]],"ltp":30.0,"tv":112.81,"id":9193530}]}]}
{"op":"mcm","clk":"995503088","pt":1580557203558,"mc":[{"id":"1.168133548","rc":[{"batl":[[0,9.8,3.05]],"ltp":9.8,"tv":1397.53,"id":10616006}]}]}
{"op":"mcm","clk":"995504031","pt":1580557208481,"mc":[{"id":"1.168133548","rc":[{"trd":[[9.2,172.87]],"batb":[[0,9,12.97],[1,8.8,3.66],[2,8.6,14.07]],"ltp":9.2,"tv":1401.53,"id":10616006},{"trd":[[7.4,69.53]],"batb":[[0,7.4,19.69]],"ltp":7.4,"tv":1458.83,"id":10170404}],"tv":8487.87}]}
{"op":"mcm","clk":"995505873","pt":1580557217473,"mc":[{"id":"1.168133548","rc":[{"batl":[[1,5.9,22]],"ltp":5.7,"tv":1678.15,"id":9417341},{"batb":[[1,8.2,13.12],[2,8,10]],"ltp":8.2,"tv":699.83,"id":15608820}]}]}
{"op":"mcm","clk":"995506704","pt":1580557221574,"mc":[{"id":"1.168133548","rc":[{"batl":[[0,29,1.13]],"ltp":27.0,"tv":163.42,"id":9001159}]}]}
{"op":"mcm","clk":"995510050","pt":1580557238566,"mc":[{"id":"1.168133548","rc":[{"trd":[[9,82.52],[9.2,173.13]],"batb":[[0,9,5.97]],"ltp":9.0,"tv":1415.53,"id":10616006},{"batl":[[1,40,1.54],[2,42,1.85]],"ltp":27.0,"tv":163.42,"id":9001159}],"tv":8501.87}]}
{"op":"mcm","clk":"995510268","pt":1580557239469,"mc":[{"id":"1.168133548","rc":[{"batl":[[0,9.6,6.44],[1,9.8,3.05],[2,10,1.68]],"ltp":9.0,"tv":1415.53,"id":10616006}]}]}
{"op":"mcm","clk":"995512959","pt":1580557253397,"mc":[{"id":"1.168133548","rc":[{"trd":[[5.8,420.02],[5.9,233.11]],"batl":[[0,5.9,17.37],[1,6,95.35],[2,6.2,1064.16]],"ltp":5.9,"tv":1691.59,"id":9417341}],"tv":8515.31}]}
{"op":"mcm","clk":"995513604","pt":1580557256568,"mc":[{"id":"1.168133548","rc":[{"batb":[[1,5.5,22.06]],"ltp":5.9,"tv":1691.59,"id":9417341}]}]}
{"op":"mcm","clk":"995514160","pt":1580557259492,"mc":[{"id":"1.168133548","rc":[{"batb":[[2,6.4,34.33]],"ltp":7.0,"tv":759.56,"id":8231803}]}]}
{"op":"mcm","clk":"995514327","pt":1580557260400,"mc":[{"id":"1.168133548","rc":[{"batl":[[0,5.8,2],[1,5.9,17.37],[2,6,95.35]],"ltp":5.9,"tv":1691.59,"id":9417341}]}]}
{"op":"mcm","clk":"995515288","pt":1580557265505,"mc":[{"id":"1.168133548","rc":[{"batb":[[0,5.6,35.85]],"ltp":5.9,"tv":1691.59,"id":9417341}]}]}
{"op":"mcm","clk":"995516925","pt":1580557273487,"mc":[{"id":"1.168133548","rc":[{"batb":[[0,9,2.24]],"ltp":9.0,"tv":1415.53,"id":10616006}]}]}
{"op":"mcm","clk":"995525715","pt":1580557318369,"mc":[{"id":"1.168133548","rc":[{"batb":[[0,8.8,3.66],[1,8.6,14.07],[2,8.2,5.51]],"ltp":9.0,"tv":1415.53,"id":10616006}]}]}
{"op":"mcm","clk":"995526298","pt":1580557321486,"mc":[{"id":"1.168133548","rc":[{"batl":[[2,8,37.57]],"ltp":7.4,"tv":1458.83,"id":10170404},{"trd":[[27,51.06],[28,3.01]],"batb":[[0,27,6.41]],"ltp":27.0,"tv":167.42,"id":9001159}],"tv":8519.31}]}
{"op":"mcm","clk":"995528732","pt":1580557334505,"mc":[{"id":"1.168133548","rc":[{"batl":[[1,38,1.03],[2,42,2.78]],"ltp":27.0,"tv":167.42,"id":9001159}]}]}
{"op":"mcm","clk":"995529556","pt":1580557338488,"mc":[{"id":"1.168133548","rc":[{"batb":[[2,8,20.5]],"ltp":8.2,"tv":699.83,"id":15608820}]}]}
{"op":"mcm","clk":"995530558","pt":1580557343469,"mc":[{"id":"1.168133548","rc":[{"batl":[[1,5.9,15.37]],"ltp":5.9,"tv":1691.59,"id":9417341}]}]}
{"op":"mcm","clk":"995531944","pt":1580557350510,"mc":[{"id":"1.168133548","rc":[{"trd":[[7,56.29]],"batl":[[0,7,2.59]],"ltp":7.0,"tv":769.56,"id":8231803}],"tv":8529.31}]}
{"op":"mcm","clk":"995532738","pt":1580557354528,"mc":[{"id":"1.168133548","rc":[{"trd":[[5.6,62.82]],"batb":[[0,5.6,9.59]],"ltp":5.6,"tv":929.37,"id":17352128}],"tv":8533.31}]}
{"op":"mcm","clk":"995533530","pt":1580557358556,"mc":[{"id":"1.168133548","rc":[{"batb":[[0,5.6,42.78],[1,5.5,15]],"ltp":5.9,"tv":1691.59,"id":9417341}]}]}
{"op":"mcm","clk":"995534100","pt":1580557361568,"mc":[{"id":"1.168133548","rc":[{"trd":[[7.6,365.27]],"batb":[[0,7.6,2.37],[1,7.4,19.69],[2,7.2,25.47]],"batl":[[0,7.8,13.77],[1,8,37.57],[2,8.2,22.57]],"ltp":7.6,"tv":1488.92,"id":10170404}],"tv":8563.41}]}
{"op":"mcm","clk":"995534475","pt":1580557363563,"mc":[{"id":"1.168133548","rc":[{"batb":[[2,7.2,21]],"ltp":7.6,"tv":1488.92,"id":10170404}]}]}
{"op":"mcm","clk":"995537180","pt":1580557377489,"mc":[{"id":"1.168133548","rc":[{"trd":[[6.8,62.48]],"batb":[[0,6.8,5.17]],"ltp":6.8,"tv":789.56,"id":8231803}],"tv":8583.41}]}
{"op":"mcm","clk":"995537530","pt":1580557379511,"mc":[{"id":"1.168133548","rc":[{"batb":[[1,6.6,8.87]],"ltp":6.8,"tv":789.56,"id":8231803},{"batb":[[2,8.4,5.39]],"ltp":9.0,"tv":1415.53,"id":10616006},{"batb":[[1,29,2],[2,28,7.69]],"ltp":30.0,"tv":112.81,"id":9193530}]}]}
{"op":"mcm","clk":"995537702","pt":1580557380379,"mc":[{"id":"1.168133548","rc":[{"batl":[[0,7,27.59]],"ltp":6.8,"tv":789.56,"id":8231803}]}]}
{"op":"mcm","clk":"995538880","pt":1580557386391,"mc":[{"id":"1.168133548","rc":[{"batb":[[1,6.6,11.78]],"ltp":6.8,"tv":789.56,"id":8231803}]}]}
{"op":"mcm","clk":"995539977","pt":1580557392569,"mc":[{"id":"1.168133548","rc":[{"trd":[[8.8,168.42]],"batl":[[0,8.8,4.06]],"ltp":8.8,"tv":703.83,"id":15608820}],"tv":8587.41}]}
{"op":"mcm","clk":"995540544","pt":1580557395569,"mc":[{"id":"1.168133548","rc":[{"trd":[[8.8,172.42]],"batl":[[0,8.8,2.06]],"ltp":8.8,"tv":707.83,"id":15608820}],"tv":8591.41}]}
{"op":"mcm","clk":"995540666","pt":1580557396264,"mc":[{"id":"1.168133548","rc":[{"batl":[[0,12,5.66]],"ltp":10.5,"tv":1288.34,"id":8429550},{"batb":[[1,5.5,35]],"batl":[[0,5.8,11.4]],"ltp":5.9,"tv":1691.59,"id":9417341},{"batl":[[0,7,35.38]],"ltp":6.8,"tv":789.56,"id":8231803},{"batl":[[0,9.6,12.12]],"ltp":9.0,"tv":1415.53,"id":10616006},{"batl":[[0,7.8,20.76]],"ltp":7.6,"tv":1488.92,"id":10170404},{"batl":[[0,8.8,8.26]],"ltp":8.8,"tv":707.83,"id":15608820},{"batl":[[0,5.8,54.91]],"ltp":5.6,"tv":929.37,"id":17352128}]}]}
{"op":"mcm","clk":"995540888","pt":1580557397477,"mc":[{"id":"1.168133548","rc":[{"batl":[[1,9.8,6.78]],"ltp":9.0,"tv":1415.53,"id":10616006},{"trd":[[7.6,370.01]],"batb":[[0,7.4,19.69],[1,7.2,21],[2,7,23]],"batl":[[0,7.6,4.88],[1,7.8,20.76],[2,8,43.66]],"ltp":7.6,"tv":1493.66,"id":10170404}],"tv":8596.15}]}
{"op":"mcm","clk":"995541112","pt":1580557398493,"mc":[{"id":"1.168133548","rc":[{"batl":[[2,8,37.57]],"ltp":7.6,"tv":1493.66,"id":10170404}]}]}
{"op":"mcm","clk":"995541477","pt":1580557400408,"mc":[{"id":"1.168133548","rc":[{"batb":[[1,7.2,26.36]],"ltp":7.6,"tv":1493.66,"id":10170404}]}]}
{"op":"mcm","clk":"995542641","pt":1580557406486,"mc":[{"id":"1.168133548","rc":[{"batl":[[0,9.6,12.57]],"ltp":9.0,"tv":1415.53,"id":10616006}]}]}
{"op":"mcm","clk":"995542820","pt":1580557407392,"mc":[{"id":"1.168133548","rc":[{"trd":[[7,74.29]],"batl":[[0,7,26.38]],"ltp":7.0,"tv":807.56,"id":8231803}],"tv":8614.15}]}
{"op":"mcm","clk":"995544783","pt":1580557417493,"mc":[{"id":"1.168133548","rc":[{"trd":[[8.8,32.51]],"batb":[[0,8.6,14.07],[1,8.4,5.39],[2,8,15.31]],"batl":[[0,8.8,16.34],[1,9.6,12.57],[2,9.8,6.78]],"ltp":8.8,"tv":1422.85,"id":10616006}],"tv":8621.47}]}
{"op":"mcm","clk":"995544986","pt":1580557418501,"mc":[{"id":"1.168133548","rc":[{"batl":[[2,9.8,3.05]],"ltp":8.8,"tv":1422.85,"id":10616006}]}]}
{"op":"mcm","clk":"995545179","pt":1580557419513,"mc":[{"id":"1.168133548","rc":[{"batb":[[2,8,12.31]],"batl":[[1,9.4,13.18],[2,9.6,19.66]],"ltp":8.8,"tv":1422.85,"id":10616006}]}]}
{"op":"mcm","clk":"995545577","pt":1580557421497,"mc":[{"id":"1.168133548","rc":[{"batl":[[1,9.4,20.72]],"ltp":8.8,"tv":1422.85,"id":10616006}]}]}
{"op":"mcm","clk":"995545955","pt":1580557423524,"mc":[{"id":"1.168133548","rc":[{"batb":[[0,5.7,38.3],[1,5.6,9.59],[2,5.5,18.54]],"ltp":5.6,"tv":929.37,"id":17352128}]}]}
{"op":"mcm","clk":"995547120","pt":1580557429793,"mc":[{"id":"1.168133548","rc":[{"trd":[[5.8,137.27]],"batl":[[0,5.8,30.03]],"ltp":5.8,"tv":979.13,"id":17352128}],"tv":8671.23}]}
{"op":"mcm","clk":"995548888","pt":1580557438504,"mc":[{"id":"1.168133548","rc":[{"trd":[[8.8,42.89]],"batl":[[0,8.8,11.15],[1,9.4,20.27]],"ltp":8.8,"tv":1433.23,"id":10616006}],"tv":8681.61}]}
{"op":"mcm","clk":"995549081","pt":1580557439526,"mc":[{"id":"1.168133548","rc":[{"batl":[[1,9.4,12.73]],"ltp":8.8,"tv":1433.23,"id":10616006}]}]}
{"op":"mcm","clk":"995549634","pt":1580557442515,"mc":[{"id":"1.168133548","rc":[{"batb":[[0,8.6,18.42],[1,8.4,2.05],[2,8.2,13.12]],"ltp":8.8,"tv":707.83,"id":15608820}]}]}
{"op":"mcm","clk":"995549846","pt":1580557443484,"mc":[{"id":"1.168133548","rc":[{"batb":[[1,8.4,9.09]],"ltp":8.8,"tv":707.83,"id":15608820}]}]}
{"op":"mcm","clk":"995551963","pt":1580557454520,"mc":[{"id":"1.168133548","rc":[{"trd":[[8.6,276.96]],"batb":[[0,8.6,8.42]],"ltp":8.6,"tv":727.83,"id":15608820}],"tv":8701.61}]}
{"op":"mcm","clk":"995552119","pt":1580557455424,"mc":[{"id":"1.168133548","rc":[{"trd":[[12,171.12]],"batl":[[0,12,2.93]],"ltp":12.0,"tv":1291.07,"id":8429550},{"trd":[[5.8,425.67]],"batl":[[0,5.8,5.75]],"ltp":5.8,"tv":1697.24,"id":9417341},{"trd":[[7,78.97]],"batl":[[0,7,21.7]],"ltp":7.0,"tv":812.24,"id":8231803},{"trd":[[8.8,46.61]],"batl":[[0,8.8,7.43]],"ltp":8.8,"tv":1436.95,"id":10616006},{"trd":[[7.2,94.3],[7.4,108.91]],"batb":[[0,7,23],[1,6.8,31.21],[2,6.6,18.18]],"batl":[[0,7.2,34.4],[1,7.6,4.88],[2,7.8,20.76]],"ltp":7.2,"tv":1590.31,"id":10170404},{"trd":[[8.8,176.14]],"batb":[[1,8.4,5.44]],"batl":[[0,8.8,4.54]],"ltp":8.8,"tv":731.55,"id":15608820},{"trd":[[34,4.18]],"batl":[[0,34,1.44]],"ltp":34.0,"tv":113.77,"id":9193530},{"trd":[[29,17.46]],"batl":[[0,38,1.03],[1,42,2.78],[2,55,7.76]],"ltp":29.0,"tv":168.55,"id":9001159},{"trd":[[5.8,142.92]],"batl":[[0,5.8,24.38]],"ltp":5.8,"tv":984.78,"id":17352128}],"tv":8826.49}]}
{"op":"mcm","clk":"995552316","pt":1580557456451,"mc":[{"id":"1.168133548","rc":[{"trd":[[7.2,102.28]],"batl":[[0,7.2,30.41],[1,7.8,20.76],[2,8,37.57]],"ltp":7.2,"tv":1598.29,"id":10170404}],"tv":8834.47}]}
{"op":"mcm","clk":"995552495","pt":1580557457423,"mc":[{"id":"1.168133548","rc":[{"batb":[[1,6.8,22.63]],"batl":[[1,7.6,5.65],[2,7.8,20.76]],"ltp":7.2,"tv":1598.29,"id":10170404}]}]}
{"op":"mcm","clk":"995552690","pt":1580557458536,"mc":[{"id":"1.168133548","rc":[{"batl":[[1,9.4,8.39]],"ltp":8.8,"tv":1436.95,"id":10616006},{"batl":[[1,7.6,12.4]],"ltp":7.2,"tv":1598.29,"id":10170404}]}]}
{"op":"mcm","clk":"995553909","pt":1580557465239,"mc":[{"id":"1.168133548","rc":[{"batb":[[1,5.5,32]],"ltp":5.8,"tv":1697.24,"id":9417341}]}]}
{"op":"mcm","clk":"995554125","pt":1580557466367,"mc":[{"id":"1.168133548","rc":[{"batb":[[0,5.6,44.78]],"ltp":5.8,"tv":1697.24,"id":9417341}]}]}
{"op":"mcm","clk":"995554532","pt":1580557468540,"mc":[{"id":"1.168133548","rc":[{"batl":[[0,8.8,6.54]],"ltp":8.8,"tv":731.55,"id":15608820}]}]}
{"op":"mcm","clk":"995555420","pt":1580557473464,"mc":[{"id":"1.168133548","rc":[{"batl":[[0,8.8,17.43]],"ltp":8.8,"tv":1436.95,"id":10616006}]}]}
{"op":"mcm","clk":"995555595","pt":1580557474475,"mc":[{"id":"1.168133548","rc":[{"trd":[[6.8,72.82]],"batb":[[0,6.6,11.78],[1,6.4,34.33],[2,6.2,19.87]],"ltp":6.8,"tv":822.57,"id":8231803}],"tv":8844.81}]}
{"op":"mcm","clk":"995556146","pt":1580557477550,"mc":[{"id":"1.168133548","rc":[{"batb":[[0,5.6,53.83]],"ltp":5.8,"tv":1697.24,"id":9417341},{"batb":[[0,6.8,7.45],[1,6.6,11.78],[2,6.4,34.33]],"ltp":6.8,"tv":822.57,"id":8231803},{"trd":[[8.6,30.63]],"batb":[[0,8.6,9.97]],"batl":[[0,8.8,7.43]],"ltp":8.6,"tv":1456.94,"id":10616006},{"batb":[[0,7,30.24]],"ltp":7.2,"tv":1598.29,"id":10170404},{"batb":[[0,8.6,14.31]],"ltp":8.8,"tv":731.55,"id":15608820},{"batb":[[0,30,6.73]],"ltp":34.0,"tv":113.77,"id":9193530},{"batb":[[0,29,1.75],[1,27,6.41],[2,26,2.11]],"batl":[[0,40,1.94],[1,42,1.85]],"ltp":29.0,"tv":168.55,"id":9001159},{"batb":[[0,5.7,47.18]],"ltp":5.8,"tv":984.78,"id":17352128}],"tv":8864.8}]}
{"op":"mcm","clk":"995556335","pt":1580557478460,"mc":[{"id":"1.168133548","rc":[{"batb":[[0,11,4.6],[1,10.5,1.64],[2,10,24.64]],"ltp":12.0,"tv":1291.07,"id":8429550},{"batl":[[1,9.4,15.92]],"ltp":8.6,"tv":1456.94,"id":10616006},{"batb":[[1,8.4,7.59]],"ltp":8.8,"tv":731.55,"id":15608820}]}]}
{"op":"mcm","clk":"995556555","pt":1580557479467,"mc":[{"id":"1.168133548","rc":[{"batl":[[1,9.4,8.39]],"ltp":8.6,"tv":1456.94,"id":10616006}]}]}
{"op":"mcm","clk":"995556756","pt":1580557480482,"mc":[{"id":"1.168133548","rc":[{"batb":[[0,5.7,2.65],[1,5.6,53.83],[2,5.5,32]],"ltp":5.8,"tv":1697.24,"id":9417341},{"batl":[[0,44,1.13],[1,46,1.78],[2,80,2]],"ltp":34.0,"tv":113.77,"id":9193530}]}]}
{"op":"mcm","clk":"995556980","pt":1580557481566,"mc":[{"id":"1.168133548","rc":[{"batb":[[2,26,4.25]],"ltp":29.0,"tv":168.55,"id":9001159}]}]}
{"op":"mcm","clk":"995557148","pt":1580557482473,"mc":[{"id":"1.168133548","rc":[{"batb":[[2,26,2.11]],"ltp":29.0,"tv":168.55,"id":9001159}]}]}
{"op":"mcm","clk":"995559529","pt":1580557494491,"mc":[{"id":"1.168133548","rc":[{"batl":[[2,7.8,18.19]],"ltp":7.2,"tv":1598.29,"id":10170404}]}]}
{"op":"mcm","clk":"995559710","pt":1580557495498,"mc":[{"id":"1.168133548","rc":[{"trd":[[7,96.97]],"batl":[[0,7,12.7]],"ltp":7.0,"tv":840.57,"id":8231803},{"trd":[[8.6,44.62]],"batb":[[0,8.6,2.98]],"ltp":8.6,"tv":1470.93,"id":10616006},{"trd":[[5.8,160.92]],"batl":[[0,5.8,15.38]],"ltp":5.8,"tv":1002.78,"id":17352128}],"tv":8914.79}]}
{"op":"mcm","clk":"995560255","pt":1580557498524,"mc":[{"id":"1.168133548","rc":[{"batl":[[1,7.6,14.97],[2,7.8,20.76]],"ltp":7.2,"tv":1598.29,"id":10170404}]}]}
{"op":"mcm","clk":"995560884","pt":1580557501450,"mc":[{"id":"1.168133548","rc":[{"trd":[[5.8,177.36]],"batb":[[1,5.6,1.08]],"batl":[[0,5.8,7.16]],"ltp":5.8,"tv":1019.22,"id":17352128}],"tv":8931.23}]}
{"op":"mcm","clk":"995561420","pt":1580557503537,"mc":[{"id":"1.168133548","rc":[{"batl":[[2,13.5,20.72]],"ltp":12.0,"tv":1291.07,"id":8429550},{"batb":[[2,5.5,37.82]],"ltp":5.8,"tv":1019.22,"id":17352128}]}]}
{"op":"mcm","clk":"995561652","pt":1580557504511,"mc":[{"id":"1.168133548","rc":[{"batb":[[2,5.5,47.46]],"ltp":5.8,"tv":1019.22,"id":17352128}]}]}
{"op":"mcm","clk":"995562053","pt":1580557506545,"mc":[{"id":"1.168133548","rc":[{"batb":[[0,5.7,5.65]],"ltp":5.8,"tv":1697.24,"id":9417341}]}]}
{"op":"mcm","clk":"995562759","pt":1580557510445,"mc":[{"id":"1.168133548","rc":[{"batb":[[0,5.7,3]],"ltp":5.8,"tv":1697.24,"id":9417341},{"batl":[[0,42,4.6],[1,44,1],[2,46,1.78]],"ltp":34.0,"tv":113.77,"id":9193530}]}]}
{"op":"mcm","clk":"995564654","pt":1580557520547,"mc":[{"id":"1.168133548","rc":[{"trd":[[7,177.75]],"batb":[[0,6.8,22.63],[1,6.6,35.63],[2,6.4,9.18]],"batl":[[0,7.6,2.73],[1,7.8,20.76],[2,8,37.57]],"ltp":7.0,"tv":1658.78,"id":10170404}],"tv":8991.72}]}
{"op":"mcm","clk":"995564835","pt":1580557521564,"mc":[{"id":"1.168133548","rc":[{"trd":[[11.5,91.29]],"batl":[[0,11.5,1.97],[1,12,2.93],[2,12.5,50.29]],"ltp":11.5,"tv":1291.1,"id":8429550},{"trd":[[5.8,425.73]],"batl":[[0,5.8,5.69]],"ltp":5.8,"tv":1697.3,"id":9417341},{"trd":[[7,97.02]],"batl":[[0,7,12.65]],"ltp":7.0,"tv":840.62,"id":8231803},{"trd":[[8.8,46.65]],"batl":[[0,8.8,7.39]],"ltp":8.8,"tv":1470.97,"id":10616006},{"trd":[[7,177.8]],"batl":[[0,7.6,2.68]],"ltp":7.0,"tv":1658.83,"id":10170404},{"trd":[[8.8,176.18]],"batl":[[0,8.8,6.5]],"ltp":8.8,"tv":731.59,"id":15608820},{"trd":[[34,4.19]],"batl":[[0,42,4.59]],"ltp":34.0,"tv":113.78,"id":9193530},{"trd":[[34,0.35]],"batl":[[0,40,1.93]],"ltp":34.0,"tv":168.56,"id":9001159},{"trd":[[5.8,177.42]],"batl":[[0,5.8,7.1]],"ltp":5.8,"tv":1019.28,"id":17352128}],"tv":8992.07}]}
{"op":"mcm","clk":"995566013","pt":1580557527516,"mc":[{"id":"1.168133548","rc":[{"batl":[[0,11.5,3.97]],"ltp":11.5,"tv":1291.1,"id":8429550}]}]}
{"op":"mcm","clk":"995568383","pt":1580557540423,"mc":[{"id":"1.168133548","rc":[{"batl":[[0,40,4.78],[1,44,1.12]],"ltp":34.0,"tv":113.78,"id":9193530}]}]}
{"op":"mcm","clk":"995568967","pt":1580557543517,"mc":[{"id":"1.168133548","rc":[{"trd":[[5.7,79.76]],"batb":[[0,5.7,45.18]],"ltp":5.7,"tv":1023.28,"id":17352128}],"tv":8996.07}]}
{"op":"mcm","clk":"995569654","pt":1580557547413,"mc":[{"id":"1.168133548","rc":[{"batb":[[0,5.6,53.83],[1,5.5,32],[2,5.4,20]],"ltp":5.8,"tv":1697.3,"id":9417341}]}]}
{"op":"mcm","clk":"995569974","pt":1580557549430,"mc":[{"id":"1.168133548","rc":[{"batl":[[0,8.8,9.39]],"ltp":8.8,"tv":1470.97,"id":10616006}]}]}
{"op":"mcm","clk":"995570115","pt":1580557550442,"mc":[{"id":"1.168133548","rc":[{"batl":[[0,40,1.53]],"ltp":34.0,"tv":168.56,"id":9001159}]}]}
{"op":"mcm","clk":"995570613","pt":1580557553356,"mc":[{"id":"1.168133548","rc":[{"trd":[[11.5,91.36]],"batl":[[0,11.5,3.9]],"ltp":11.5,"tv":1291.17,"id":8429550},{"trd":[[5.8,425.86]],"batl":[[0,5.8,5.56]],"ltp":5.8,"tv":1697.43,"id":9417341},{"trd":[[7,97.13]],"batl":[[0,7,12.54]],"ltp":7.0,"tv":840.73,"id":8231803},{"trd":[[8.6,50.69]],"batb":[[0,8.4,5.39],[1,8,12.31],[2,7.6,5.26]],"batl":[[0,8.6,3.83],[1,8.8,9.39],[2,9.4,8.39]],"ltp":8.6,"tv":1477.03,"id":10616006},{"trd":[[7,177.91]],"batl":[[0,7.6,2.57]],"ltp":7.0,"tv":1658.94,"id":10170404},{"trd":[[8.8,176.27]],"batl":[[0,8.8,6.41]],"ltp":8.8,"tv":731.68,"id":15608820},{"trd":[[40,4.4]],"batl":[[0,40,4.76]],"ltp":40.0,"tv":113.8,"id":9193530},{"trd":[[34,0.37]],"batl":[[0,40,1.51]],"ltp":34.0,"tv":168.58,"id":9001159},{"trd":[[5.8,177.55]],"batl":[[0,5.8,6.97]],"ltp":5.8,"tv":1023.41,"id":17352128}],"tv":9002.82}]}
{"op":"mcm","clk":"995570841","pt":1580557554520,"mc":[{"id":"1.168133548","rc":[{"batb":[[0,11,9.1]],"ltp":11.5,"tv":1291.17,"id":8429550},{"batb":[[0,5.7,8.67],[1,5.6,53.83],[2,5.5,32]],"ltp":5.8,"tv":1697.43,"id":9417341},{"batb":[[0,6.8,14.72]],"ltp":7.0,"tv":840.73,"id":8231803},{"batb":[[0,8.4,11.27]],"ltp":8.6,"tv":1477.03,"id":10616006},{"batb":[[0,7.2,6.86],[1,6.8,22.63],[2,6.6,35.63]],"batl":[[0,7.6,9.7]],"ltp":7.0,"tv":1658.94,"id":10170404},{"trd":[[8.8,189.09]],"batb":[[0,8.8,5.61],[1,8.6,14.31],[2,8.4,7.59]],"batl":[[0,9,2],[1,9.2,2],[2,9.8,3.12]],"ltp":8.8,"tv":744.5,"id":15608820},{"trd":[[5.8,191.49]],"batb":[[0,5.8,1.55],[1,5.7,45.18],[2,5.6,1.08]],"batl":[[0,5.9,7.88]],"ltp":5.8,"tv":1037.35,"id":17352128}],"tv":9029.58}]}
{"op":"mcm","clk":"995571004","pt":1580557555477,"mc":[{"id":"1.168133548","rc":[{"trd":[[5.7,223.88]],"batb":[[0,5.6,53.83],[1,5.5,32],[2,5.4,20]],"batl":[[0,5.7,11.33],[1,5.8,5.56],[2,5.9,15.37]],"ltp":5.7,"tv":1714.77,"id":9417341},{"batb":[[1,6.6,15.51]],"ltp":7.0,"tv":840.73,"id":8231803},{"batb":[[2,8.4,2.05]],"ltp":8.8,"tv":744.5,"id":15608820},{"batb":[[0,32,1.69],[1,30,6.19],[2,29,2]],"ltp":40.0,"tv":113.8,"id":9193530},{"batb":[[1,28,1.32],[2,27,6.41]],"ltp":34.0,"tv":168.58,"id":9001159}],"tv":9046.92}]}
{"op":"mcm","clk":"995571196","pt":1580557556475,"mc":[{"id":"1.168133548","rc":[{"batb":[[0,5.6,73.83]],"ltp":5.7,"tv":1714.77,"id":9417341},{"batl":[[2,10,8.58]],"ltp":8.8,"tv":744.5,"id":15608820}]}]}
{"op":"mcm","clk":"995571579","pt":1580557558489,"mc":[{"id":"1.168133548","rc":[{"batl":[[0,7.4,2],[1,7.6,9.7],[2,7.8,20.76]],"ltp":7.0,"tv":1658.94,"id":10170404},{"batl":[[2,9.8,3.01]],"ltp":8.8,"tv":744.5,"id":15608820}]}]}
{"op":"mcm","clk":"995571788","pt":1580557559506,"mc":[{"id":"1.168133548","rc":[{"trd":[[8.8,193.09]],"batb":[[0,8.8,3.61]],"ltp":8.8,"tv":748.5,"id":15608820}],"tv":9050.92}]}
{"op":"mcm","clk":"995572454","pt":1580557563191,"mc":[{"id":"1.168133548","rc":[{"trd":[[11,380.83],[11.5,99.16]],"batb":[[0,11,2.1]],"batl":[[0,12,2.93],[1,12.5,50.29],[2,13.5,20.72]],"ltp":11.0,"tv":1312.97,"id":8429550},{"trd":[[7,117.13]],"batl":[[0,7,2.54]],"ltp":7.0,"tv":860.73,"id":8231803},{"trd":[[8.4,117.74]],"batb":[[0,8.4,4.27]],"ltp":8.4,"tv":1491.03,"id":10616006},{"trd":[[7.4,112.91]],"batb":[[0,7.4,5.1],[1,7.2,6.86],[2,6.8,22.63]],"batl":[[0,7.6,9.7],[1,7.8,20.76],[2,8,37.57]],"ltp":7.4,"tv":1662.93,"id":10170404},{"batl":[[0,38,2.53]],"ltp":40.0,"tv":113.8,"id":9193530},{"batl":[[0,38,3.11],[1,42,2.78]],"ltp":34.0,"tv":168.58,"id":9001159}],"tv":9110.71}]}
{"op":"mcm","clk":"995572708","pt":1580557564503,"mc":[{"id":"1.168133548","rc":[{"batb":[[1,10.5,5.64]],"ltp":11.0,"tv":1312.97,"id":8429550},{"batl":[[0,7.6,11.7]],"ltp":7.4,"tv":1662.93,"id":10170404}]}]}
{"op":"mcm","clk":"995572901","pt":1580557565571,"mc":[{"id":"1.168133548","rc":[{"trd":[[5.7,246.54]],"batl":[[0,5.8,5.56],[1,5.9,15.37],[2,6,87.65]],"ltp":5.7,"tv":1737.43,"id":9417341}],"tv":9133.37}]}
{"op":"mcm","clk":"995573058","pt":1580557566385,"mc":[{"id":"1.168133548","rc":[{"batl":[[0,5.8,16.69]],"ltp":5.7,"tv":1737.43,"id":9417341}]}]}
{"op":"mcm","clk":"995573421","pt":1580557568509,"mc":[{"id":"1.168133548","rc":[{"batb":[[0,29,4.78]],"ltp":34.0,"tv":168.58,"id":9001159}]}]}
{"op":"mcm","clk":"995573620","pt":1580557569574,"mc":[{"id":"1.168133548","rc":[{"batl":[[0,5.9,9.88]],"ltp":5.8,"tv":1037.35,"id":17352128}]}]}
{"op":"mcm","clk":"995573787","pt":1580557570492,"mc":[{"id":"1.168133548","rc":[{"batl":[[0,7.6,13.7]],"ltp":7.4,"tv":1662.93,"id":10170404}]}]}
{"op":"mcm","clk":"995574336","pt":1580557573225,"mc":[{"id":"1.168133548","rc":[{"batb":[[2,7,2]],"ltp":7.4,"tv":1662.93,"id":10170404}]}]}
{"op":"mcm","clk":"995574567","pt":1580557574486,"mc":[{"id":"1.168133548","rc":[{"batb":[[2,27,9.31]],"ltp":34.0,"tv":168.58,"id":9001159}]}]}
{"op":"mcm","clk":"995575057","pt":1580557577487,"mc":[{"id":"1.168133548","rc":[{"batl":[[0,36,1.61],[1,38,2.53],[2,42,1.85]],"ltp":34.0,"tv":168.58,"id":9001159}]}]}
{"op":"mcm","clk":"995575570","pt":1580557580413,"mc":[{"id":"1.168133548","rc":[{"batl":[[0,12,6.93]],"ltp":11.0,"tv":1312.97,"id":8429550},{"trd":[[6.8,84.81],[7,122.21]],"batb":[[0,6.8,9.05]],"batl":[[0,7.2,2.24],[1,7.4,5],[2,7.6,5.66]],"ltp":7.0,"tv":877.8,"id":8231803},{"trd":[[8.8,200.31]],"batb":[[0,8.6,14.31],[1,8.4,2.05],[2,8.2,13.12]],"ltp":8.8,"tv":755.73,"id":15608820}],"tv":9157.67}]}
{"op":"mcm","clk":"995576135","pt":1580557583529,"mc":[{"id":"1.168133548","rc":[{"batb":[[1,6.6,11.78]],"ltp":7.0,"tv":877.8,"id":8231803}]}]}
{"op":"mcm","clk":"995579191","pt":1580557600534,"mc":[{"id":"1.168133548","rc":[{"trd":[[8.6,58.35]],"batb":[[0,8.6,14.59],[1,8.4,4.27],[2,8,12.31]],"batl":[[0,8.8,9.39],[1,9.4,8.39],[2,9.6,12.12]],"ltp":8.6,"tv":1498.69,"id":10616006}],"tv":9165.33}]}
{"op":"mcm","clk":"995579354","pt":1580557601551,"mc":[{"id":"1.168133548","rc":[{"batb":[[0,29,1.75]],"ltp":34.0,"tv":168.58,"id":9001159}]}]}
{"op":"mcm","clk":"995580880","pt":1580557609563,"mc":[{"id":"1.168133548","rc":[{"batl":[[0,8.8,2],[1,9,2],[2,9.2,2]],"ltp":8.8,"tv":755.73,"id":15608820},{"batb":[[2,27,6.41]],"ltp":34.0,"tv":168.58,"id":9001159}]}]}
{"op":"mcm","clk":"995582688","pt":1580557619394,"mc":[{"id":"1.168133548","rc":[{"batb":[[0,7.4,22.3]],"ltp":7.4,"tv":1662.93,"id":10170404}]}]}
{"op":"mcm","clk":"995583239","pt":1580557622521,"mc":[{"id":"1.168133548","rc":[{"batl":[[1,9.2,4],[2,9.4,8.39]],"ltp":8.6,"tv":1498.69,"id":10616006}]}]}
{"op":"mcm","clk":"995584096","pt":1580557627522,"mc":[{"id":"1.168133548","rc":[{"batb":[[1,7.2,12.22]],"ltp":7.4,"tv":1662.93,"id":10170404}]}]}
{"op":"mcm","clk":"995588706","pt":1580557651569,"mc":[{"id":"1.168133548","rc":[{"batb":[[0,7.4,17.2]],"ltp":7.4,"tv":1662.93,"id":10170404},{"batl":[[0,44,1.12],[1,46,1.78],[2,80,2]],"ltp":40.0,"tv":113.8,"id":9193530},{"batl":[[1,42,1.85],[2,55,11.15]],"ltp":34.0,"tv":168.58,"id":9001159}]}]}
{"op":"mcm","clk":"995588871","pt":1580557652493,"mc":[{"id":"1.168133548","rc":[{"trd":[[8.6,72.35]],"batb":[[0,8.6,7.59]],"ltp":8.6,"tv":1512.69,"id":10616006},{"trd":[[8.6,290.96]],"batb":[[0,8.6,7.31]],"ltp":8.6,"tv":769.73,"id":15608820}],"tv":9193.33}]}
{"op":"mcm","clk":"995589058","pt":1580557653552,"mc":[{"id":"1.168133548","rc":[{"batl":[[2,55,14.53]],"ltp":34.0,"tv":168.58,"id":9001159}]}]}
{"op":"mcm","clk":"995590585","pt":1580557660558,"mc":[{"id":"1.168133548","rc":[{"batl":[[2,55,11.15]],"ltp":34.0,"tv":168.58,"id":9001159}]}]}
{"op":"mcm","clk":"995591711","pt":1580557665499,"mc":[{"id":"1.168133548","rc":[{"batl":[[0,42,2.43],[1,55,11.15],[2,75,11.49]],"ltp":34.0,"tv":168.58,"id":9001159}]}]}
{"op":"mcm","clk":"995591938","pt":1580557666564,"mc":[{"id":"1.168133548","rc":[{"batl":[[0,40,1.51],[1,42,1.85],[2,55,11.15]],"ltp":34.0,"tv":168.58,"id":9001159}]}]}
{"op":"mcm","clk":"995595880","pt":1580557686553,"mc":[{"id":"1.168133548","rc":[{"trd":[[8.6,87.52]],"batb":[[0,8.4,4.27],[1,8,12.31],[2,7.6,5.26]],"batl":[[0,8.6,4.2],[1,8.8,9.39],[2,9.2,4]],"ltp":8.6,"tv":1527.86,"id":10616006},{"batb":[[0,7.4,30.89]],"ltp":7.4,"tv":1662.93,"id":10170404},{"batl":[[0,8.8,13.51]],"ltp":8.6,"tv":769.73,"id":15608820},{"batl":[[0,38,2.66],[1,44,1.12],[2,46,1.78]],"ltp":40.0,"tv":113.8,"id":9193530},{"batl":[[0,36,3.4],[1,42,2.78]],"ltp":34.0,"tv":168.58,"id":9001159}],"tv":9208.5}]}
{"op":"mcm","clk":"995596265","pt":1580557688548,"mc":[{"id":"1.168133548","rc":[{"batl":[[0,34,1.67],[1,36,2.82],[2,42,1.85]],"ltp":34.0,"tv":168.58,"id":9001159}]}]}
{"op":"mcm","clk":"995596605","pt":1580557690540,"mc":[{"id":"1.168133548","rc":[{"batl":[[0,5.9,7.88]],"ltp":5.8,"tv":1037.35,"id":17352128}]}]}
{"op":"mcm","clk":"995598057","pt":1580557698573,"mc":[{"id":"1.168133548","rc":[{"batl":[[0,5.8,18.69]],"ltp":5.7,"tv":1737.43,"id":9417341}]}]}
{"op":"mcm","clk":"995599063","pt":1580557704495,"mc":[{"id":"1.168133548","rc":[{"trd":[[5.7,82.66],[5.8,194.59]],"batb":[[0,5.7,43.73],[1,5.6,1.08],[2,5.5,47.46]],"ltp":5.7,"tv":1043.35,"id":17352128}],"tv":9214.5}]}
{"op":"mcm","clk":"995599416","pt":1580557706485,"mc":[{"id":"1.168133548","rc":[{"batb":[[1,8.4,5.03]],"ltp":8.6,"tv":769.73,"id":15608820},{"trd":[[5.9,76.58]],"batl":[[0,5.9,4.96]],"ltp":5.9,"tv":1049.19,"id":17352128}],"tv":9220.34}]}
{"op":"mcm","clk":"995601613","pt":1580557719538,"mc":[{"id":"1.168133548","rc":[{"batl":[[0,7.6,15.7]],"ltp":7.4,"tv":1662.93,"id":10170404}]}]}
{"op":"mcm","clk":"995601976","pt":1580557721515,"mc":[{"id":"1.168133548","rc":[{"batl":[[1,7.8,25.77]],"ltp":7.4,"tv":1662.93,"id":10170404}]}]}
{"op":"mcm","clk":"995602703","pt":1580557725565,"mc":[{"id":"1.168133548","rc":[{"trd":[[5.7,90.66]],"batb":[[0,5.7,39.73]],"ltp":5.7,"tv":1057.19,"id":17352128}],"tv":9228.34}]}
{"op":"mcm","clk":"995603371","pt":1580557729523,"mc":[{"id":"1.168133548","rc":[{"trd":[[8.6,95.92]],"batb":[[0,8.6,2.8],[1,8.4,4.27],[2,8,12.31]],"batl":[[0,8.8,9.39],[1,9.2,4],[2,9.4,8.39]],"ltp":8.6,"tv":1536.26,"id":10616006},{"batb":[[1,8.4,2.05]],"ltp":8.6,"tv":769.73,"id":15608820}],"tv":9236.74}]}
{"op":"mcm","clk":"995608914","pt":1580557762493,"mc":[{"id":"1.168133548","rc":[{"trd":[[8.6,305.59]],"batb":[[0,8.4,4.73],[1,8.2,13.12],[2,8,20.5]],"batl":[[0,8.6,6.68],[1,8.8,13.51],[2,9,2]],"ltp":8.6,"tv":784.36,"id":15608820}],"tv":9251.37}]}
{"op":"mcm","clk":"995609286","pt":1580557764570,"mc":[{"id":"1.168133548","rc":[{"batb":[[0,8.4,2.05]],"ltp":8.6,"tv":784.36,"id":15608820}]}]}
{"op":"mcm","clk":"995609607","pt":1580557766402,"mc":[{"id":"1.168133548","rc":[{"batl":[[0,5.8,46.69]],"ltp":5.7,"tv":1737.43,"id":9417341}]}]}
{"op":"mcm","clk":"995609976","pt":1580557768489,"mc":[{"id":"1.168133548","rc":[{"batb":[[0,5.8,9],[1,5.7,39.73],[2,5.6,1.08]],"ltp":5.7,"tv":1057.19,"id":17352128}]}]}
{"op":"mcm","clk":"995617611","pt":1580557815479,"mc":[{"id":"1.168133548","rc":[{"trd":[[8.6,101.52]],"batb":[[0,8.4,4.27],[1,8,12.31],[2,7.6,5.26]],"batl":[[0,8.6,12.2],[1,8.8,9.39],[2,9.2,4]],"ltp":8.6,"tv":1541.86,"id":10616006}],"tv":9256.97}]}
{"op":"mcm","clk":"995618966","pt":1580557823498,"mc":[{"id":"1.168133548","rc":[{"trd":[[5.8,200.59]],"batb":[[0,5.8,6]],"ltp":5.8,"tv":1063.19,"id":17352128}],"tv":9262.97}]}
{"op":"mcm","clk":"995619656","pt":1580557827496,"mc":[{"id":"1.168133548","rc":[{"trd":[[5.9,86.5]],"batb":[[0,5.8,6.04]],"batl":[[0,6,13.37],[1,6.2,41.09],[2,6.4,47.31]],"ltp":5.9,"tv":1073.11,"id":17352128}],"tv":9272.89}]}
{"op":"mcm","clk":"995620497","pt":1580557833416,"mc":[{"id":"1.168133548","rc":[{"batb":[[0,7.4,17.2]],"ltp":7.4,"tv":1662.93,"id":10170404},{"batl":[[1,8.8,2]],"ltp":8.6,"tv":784.36,"id":15608820},{"batl":[[0,44,1.12],[1,46,1.78],[2,80,2]],"ltp":40.0,"tv":113.8,"id":9193530},{"batl":[[1,42,1.85],[2,55,11.15]],"ltp":34.0,"tv":168.58,"id":9001159}]}]}
{"op":"mcm","clk":"995621369","pt":1580557839507,"mc":[{"id":"1.168133548","rc":[{"batl":[[0,42,2.43],[1,55,11.15],[2,75,11.49]],"ltp":34.0,"tv":168.58,"id":9001159}]}]}
{"op":"mcm","clk":"995621526","pt":1580557840537,"mc":[{"id":"1.168133548","rc":[{"batl":[[0,40,1.51],[1,42,1.85],[2,55,11.15]],"ltp":34.0,"tv":168.58,"id":9001159},{"trd":[[6,131.37]],"batl":[[0,6,5.37]],"ltp":6.0,"tv":1089.11,"id":17352128}],"tv":9288.89}]}
{"op":"mcm","clk":"995621674","pt":1580557841438,"mc":[{"id":"1.168133548","rc":[{"batl":[[2,55,7.32]],"ltp":34.0,"tv":168.58,"id":9001159}]}]}
{"op":"mcm","clk":"995622572","pt":1580557847540,"mc":[{"id":"1.168133548","rc":[{"batl":[[0,8.6,24.2]],"ltp":8.6,"tv":1541.86,"id":10616006},{"batl":[[0,6,19.37]],"ltp":6.0,"tv":1089.11,"id":17352128}]}]}
{"op":"mcm","clk":"995622721","pt":1580557848523,"mc":[{"id":"1.168133548","rc":[{"batl":[[1,8.8,13.67]],"ltp":8.6,"tv":1541.86,"id":10616006}]}]}
{"op":"mcm","clk":"995622871","pt":1580557849523,"mc":[{"id":"1.168133548","rc":[{"batl":[[1,8.8,11.67]],"ltp":8.6,"tv":1541.86,"id":10616006}]}]}
{"op":"mcm","clk":"995624097","pt":1580557857529,"mc":[{"id":"1.168133548","rc":[{"trd":[[8.4,126.3]],"batb":[[0,8,12.31],[1,7.6,5.26],[2,7.4,3]],"batl":[[0,8.6,36.2]],"ltp":8.4,"tv":1550.41,"id":10616006}],"tv":9297.44}]}
{"op":"mcm","clk":"995624265","pt":1580557858543,"mc":[{"id":"1.168133548","rc":[{"batl":[[1,8.8,15.63]],"ltp":8.4,"tv":1550.41,"id":10616006}]}]}
{"op":"mcm","clk":"995625334","pt":1580557865556,"mc":[{"id":"1.168133548","rc":[{"batl":[[1,8.8,27.63]],"ltp":8.4,"tv":1550.41,"id":10616006}]}]}
{"op":"mcm","clk":"995625789","pt":1580557868557,"mc":[{"id":"1.168133548","rc":[{"batl":[[0,8.4,5.94],[1,8.6,36.2],[2,8.8,27.63]],"ltp":8.4,"tv":1550.41,"id":10616006},{"batl":[[0,8.6,8.68],[1,9,2],[2,9.2,2]],"ltp":8.6,"tv":784.36,"id":15608820}]}]}
{"op":"mcm","clk":"995625927","pt":1580557869464,"mc":[{"id":"1.168133548","rc":[{"batl":[[2,8.8,19.39]],"ltp":8.4,"tv":1550.41,"id":10616006},{"batl":[[0,7.6,13.7]],"ltp":7.4,"tv":1662.93,"id":10170404}]}]}
{"op":"mcm","clk":"995626055","pt":1580557870273,"mc":[{"id":"1.168133548","rc":[{"batb":[[0,8.2,26.07],[1,8,12.31],[2,7.6,5.26]],"ltp":8.4,"tv":1550.41,"id":10616006},{"batl":[[1,7.8,20.76]],"ltp":7.4,"tv":1662.93,"id":10170404},{"batl":[[2,9.2,6.97]],"ltp":8.6,"tv":784.36,"id":15608820}]}]}
{"op":"mcm","clk":"995626754","pt":1580557874474,"mc":[{"id":"1.168133548","rc":[{"batl":[[2,8.8,31.39]],"ltp":8.4,"tv":1550.41,"id":10616006}]}]}
{"op":"mcm","clk":"995627384","pt":1580557878385,"mc":[{"id":"1.168133548","rc":[{"batl":[[2,8.8,43.39]],"ltp":8.4,"tv":1550.41,"id":10616006}]}]}
{"op":"mcm","clk":"995627521","pt":1580557879184,"mc":[{"id":"1.168133548","rc":[{"batl":[[0,7.6,11.7]],"ltp":7.4,"tv":1662.93,"id":10170404}]}]}
{"op":"mcm","clk":"995628771","pt":1580557887503,"mc":[{"id":"1.168133548","rc":[{"trd":[[8.4,138.18]],"batb":[[0,8.4,3.06],[1,8.2,26.07],[2,8,12.31]],"batl":[[0,8.6,36.2],[1,8.8,43.39],[2,9,24]],"ltp":8.4,"tv":1562.3,"id":10616006}],"tv":9309.33}]}
{"op":"mcm","clk":"995629094","pt":1580557889537,"mc":[{"id":"1.168133548","rc":[{"batl":[[1,8.8,51.03]],"ltp":8.4,"tv":1562.3,"id":10616006}]}]}
{"op":"mcm","clk":"995629568","pt":1580557892499,"mc":[{"id":"1.168133548","rc":[{"batb":[[2,10,20.41]],"ltp":11.0,"tv":1312.97,"id":8429550}]}]}
{"op":"mcm","clk":"995630172","pt":1580557896510,"mc":[{"id":"1.168133548","rc":[{"batl":[[2,9,29]],"ltp":8.4,"tv":1562.3,"id":10616006}]}]}
{"op":"mcm","clk":"995630332","pt":1580557897515,"mc":[{"id":"1.168133548","rc":[{"trd":[[8.4,144.3]],"batb":[[0,8.2,26.07],[1,8,12.31],[2,7.6,5.26]],"batl":[[0,8.4,16.94],[1,8.6,36.2],[2,8.8,51.03]],"ltp":8.4,"tv":1568.42,"id":10616006}],"tv":9315.45}]}
{"op":"mcm","clk":"995630461","pt":1580557898534,"mc":[{"id":"1.168133548","rc":[{"trd":[[7.2,27.17]],"batl":[[0,7.4,5],[1,7.6,5.66],[2,8,9.87]],"ltp":7.2,"tv":882.29,"id":8231803},{"batl":[[1,8.6,40.6],[2,8.8,43.39]],"ltp":8.4,"tv":1568.42,"id":10616006}],"tv":9319.93}]}
{"op":"mcm","clk":"995630611","pt":1580557899503,"mc":[{"id":"1.168133548","rc":[{"batl":[[1,7.6,17.7]],"ltp":7.2,"tv":882.29,"id":8231803},{"trd":[[5.9,86.58]],"batb":[[0,5.8,6]],"batl":[[0,5.9,6.31],[1,6,19.37],[2,6.2,35.05]],"ltp":5.9,"tv":1089.19,"id":17352128}],"tv":9320.01}]}
{"op":"mcm","clk":"995630742","pt":1580557900510,"mc":[{"id":"1.168133548","rc":[{"batl":[[0,7.2,6.03],[1,7.4,5],[2,7.6,17.7]],"ltp":7.2,"tv":882.29,"id":8231803}]}]}
{"op":"mcm","clk":"995631157","pt":1580557903432,"mc":[{"id":"1.168133548","rc":[{"batb":[[2,6.4,37.33]],"ltp":7.2,"tv":882.29,"id":8231803}]}]}
{"op":"mcm","clk":"995631962","pt":1580557908522,"mc":[{"id":"1.168133548","rc":[{"batl":[[0,8.6,6.68],[1,8.8,2],[2,9,2]],"ltp":8.6,"tv":784.36,"id":15608820}]}]}
{"op":"mcm","clk":"995632169","pt":1580557909537,"mc":[{"id":"1.168133548","rc":[{"batb":[[0,6.8,8.73]],"batl":[[0,7.2,8.5]],"ltp":7.2,"tv":882.29,"id":8231803}]}]}
{"op":"mcm","clk":"995649416","pt":1580557952469,"mc":[{"id":"1.168133548","rc":[{"trd":[[7.4,147.31]],"batb":[[0,7.2,12.22],[1,7,2],[2,6.8,22.63]],"batl":[[0,7.4,2.8],[1,7.6,11.7],[2,7.8,20.76]],"ltp":7.4,"tv":1697.33,"id":10170404}],"tv":9354.41}]}
{"op":"mcm","clk":"995649567","pt":1580557953480,"mc":[{"id":"1.168133548","rc":[{"batb":[[0,7.2,6.86],[2,6.8,39.53]],"batl":[[1,7.6,4.57]],"ltp":7.4,"tv":1697.33,"id":10170404}]}]}
{"op":"mcm","clk":"995649773","pt":1580557954563,"mc":[{"id":"1.168133548","rc":[{"batb":[[0,5.7,2.14],[1,5.6,73.83],[2,5.5,32]],"ltp":5.7,"tv":1737.43,"id":9417341},{"batb":[[2,6.8,47.97]],"ltp":7.4,"tv":1697.33,"id":10170404}]}]}
{"op":"mcm","clk":"995650423","pt":1580557958566,"mc":[{"id":"1.168133548","rc":[{"trd":[[7.2,116]],"batb":[[0,7,2],[1,6.8,47.97],[2,6.6,18.18]],"batl":[[0,7.2,3.14],[1,7.4,2.8],[2,7.6,4.57]],"ltp":7.2,"tv":1711.06,"id":10170404}],"tv":9368.13}]}
{"op":"mcm","clk":"995650586","pt":1580557959572,"mc":[{"id":"1.168133548","rc":[{"batb":[[0,11,4.39]],"ltp":11.0,"tv":1312.97,"id":8429550},{"batb":[[0,5.7,6.56]],"ltp":5.7,"tv":1737.43,"id":9417341},{"batb":[[0,7,3.6],[1,6.8,8.73],[2,6.6,11.78]],"ltp":7.2,"tv":882.29,"id":8231803},{"batb":[[0,8.2,29.14]],"ltp":8.4,"tv":1568.42,"id":10616006},{"batb":[[0,7,5.6],[2,6.6,35.35]],"ltp":7.2,"tv":1711.06,"id":10170404},{"batb":[[0,32,3.11]],"batl":[[0,42,3.23],[1,44,1],[2,46,1.78]],"ltp":40.0,"tv":113.8,"id":9193530},{"batb":[[0,29,3.32]],"ltp":34.0,"tv":168.58,"id":9001159},{"batb":[[0,5.8,10.34]],"ltp":5.9,"tv":1089.19,"id":17352128}]}]}
{"op":"mcm","clk":"995650700","pt":1580557960371,"mc":[{"id":"1.168133548","rc":[{"batb":[[1,10.5,4]],"ltp":11.0,"tv":1312.97,"id":8429550},{"batb":[[2,6.6,26.76]],"ltp":7.2,"tv":1711.06,"id":10170404},{"batb":[[0,8.4,5.05]],"ltp":8.6,"tv":784.36,"id":15608820}]}]}
{"op":"mcm","clk":"995650849","pt":1580557961483,"mc":[{"id":"1.168133548","rc":[{"trd":[[12,184.98],[12.5,57.94]],"batl":[[0,12.5,43.69],[1,13.5,20.72],[2,16,16]],"ltp":12.5,"tv":1340.01,"id":8429550},{"trd":[[5.7,259.64]],"batb":[[0,5.6,73.83],[1,5.5,32],[2,5.4,20]],"ltp":5.7,"tv":1750.54,"id":9417341},{"trd":[[7.2,44.16],[7.4,9.99],[7.6,21.61]],"batl":[[0,7.6,7.48],[1,8,9.87],[2,8.2,2.5]],"ltp":7.6,"tv":929.7,"id":8231803},{"trd":[[8.2,36.14]],"batb":[[0,8.2,13.35]],"ltp":8.2,"tv":1599.99,"id":10616006},{"trd":[[7.2,122.28],[7.4,152.9],[7.6,379.14]],"batb":[[0,7.2,8],[1,7,5.6],[2,6.8,47.97]],"batl":[[0,7.8,20.76],[1,8,37.57],[2,8.2,22.57]],"ltp":7.6,"tv":1732.06,"id":10170404},{"trd":[[8.2,57.73],[8.4,68.61]],"batb":[[0,8.2,7.87],[1,8,20.5],[2,7.8,5.54]],"ltp":8.2,"tv":804.94,"id":15608820},{"trd":[[42,5.8]],"batl":[[0,44,1.33],[1,46,1.78],[2,80,2]],"ltp":42.0,"tv":119.59,"id":9193530},{"trd":[[5.7,113.59],[5.8,221.26]],"batb":[[0,5.7,28.26],[1,5.6,1.08],[2,5.5,18.54]],"batl":[[0,5.8,10.33],[1,5.9,6.31],[2,6,19.37]],"ltp":5.7,"tv":1132.79,"id":17352128}],"tv":9578.24}]}
{"op":"mcm","clk":"995651041","pt":1580557962560,"mc":[{"id":"1.168133548","rc":[{"batb":[[0,5.7,3.21],[1,5.6,73.83],[2,5.5,32]],"ltp":5.7,"tv":1750.54,"id":9417341},{"trd":[[7.6,30.11]],"batl":[[0,7.6,3.23]],"ltp":7.6,"tv":938.2,"id":8231803},{"trd":[[8.4,149.38]],"batl":[[0,8.4,14.4]],"ltp":8.4,"tv":1605.07,"id":10616006},{"batb":[[0,7,5.6],[1,6.8,47.97],[2,6.6,26.76]],"ltp":7.6,"tv":1732.06,"id":10170404}],"tv":9591.82}]}
{"op":"mcm","clk":"995651182","pt":1580557963472,"mc":[{"id":"1.168133548","rc":[{"batl":[[1,13.5,33.08]],"ltp":12.5,"tv":1340.01,"id":8429550},{"batl":[[0,7.8,8.19],[2,8.2,10.69]],"ltp":7.6,"tv":938.2,"id":8231803},{"batl":[[1,8,47.95]],"ltp":7.6,"tv":1732.06,"id":10170404},{"batb":[[1,8,24.19]],"ltp":8.2,"tv":804.94,"id":15608820},{"batb":[[2,5.5,37.82]],"ltp":5.7,"tv":1132.79,"id":17352128}]}]}
{"op":"mcm","clk":"995651520","pt":1580557965491,"mc":[{"id":"1.168133548","rc":[{"batl":[[1,13.5,45.44]],"ltp":12.5,"tv":1340.01,"id":8429550},{"batl":[[0,7.8,16.38],[2,8.2,18.88]],"ltp":7.6,"tv":938.2,"id":8231803},{"batl":[[1,8,54.05]],"ltp":7.6,"tv":1732.06,"id":10170404},{"batb":[[1,8,27.41]],"ltp":8.2,"tv":804.94,"id":15608820},{"trd":[[5.8,237.27]],"batb":[[2,5.5,57.1]],"batl":[[0,5.8,2.32]],"ltp":5.8,"tv":1148.8,"id":17352128}],"tv":9607.84}]}
{"op":"mcm","clk":"995651701","pt":1580557966566,"mc":[{"id":"1.168133548","rc":[{"batl":[[1,8,17.94]],"ltp":7.6,"tv":938.2,"id":8231803},{"batl":[[1,8,45.98]],"ltp":7.6,"tv":1732.06,"id":10170404},{"batb":[[1,8,24.19]],"ltp":8.2,"tv":804.94,"id":15608820},{"batb":[[0,34,3.03],[1,32,3.11],[2,30,6.19]],"ltp":42.0,"tv":119.59,"id":9193530}]}]}
{"op":"mcm","clk":"995652156","pt":1580557969491,"mc":[{"id":"1.168133548","rc":[{"batl":[[0,8.6,8.68],[1,9,2],[2,9.2,2]],"ltp":8.2,"tv":804.94,"id":15608820}]}]}
{"op":"mcm","clk":"995652462","pt":1580557971520,"mc":[{"id":"1.168133548","rc":[{"batl":[[2,9.2,6.97]],"ltp":8.2,"tv":804.94,"id":15608820}]}]}
{"op":"mcm","clk":"995652760","pt":1580557973553,"mc":[{"id":"1.168133548","rc":[{"batl":[[2,6,5.37]],"ltp":5.8,"tv":1148.8,"id":17352128}]}]}
{"op":"mcm","clk":"995653476","pt":1580557978514,"mc":[{"id":"1.168133548","rc":[{"batl":[[0,7.8,22.76]],"ltp":7.6,"tv":1732.06,"id":10170404}]}]}
{"op":"mcm","clk":"995654767","pt":1580557987485,"mc":[{"id":"1.168133548","rc":[{"trd":[[8.2,54.68]],"batb":[[0,8.2,4.08]],"ltp":8.2,"tv":1623.6,"id":10616006},{"batb":[[0,7.2,10.55],[1,7,5.6],[2,6.8,47.97]],"batl":[[0,7.6,7.13],[1,7.8,22.76],[2,8,45.98]],"ltp":7.6,"tv":1732.06,"id":10170404},{"batl":[[0,8.4,9.05],[1,8.6,8.68],[2,9,2]],"ltp":8.2,"tv":804.94,"id":15608820},{"batl":[[0,38,3.03],[1,40,2.53],[2,44,1]],"ltp":42.0,"tv":119.59,"id":9193530},{"batb":[[2,27,6.8]],"batl":[[0,36,3.11],[1,42,6.17]],"ltp":34.0,"tv":168.58,"id":9001159}],"tv":9626.37}]}
{"op":"mcm","clk":"995654932","pt":1580557988504,"mc":[{"id":"1.168133548","rc":[{"batb":[[0,5.6,73.83],[1,5.5,32],[2,5.4,20]],"ltp":5.7,"tv":1750.54,"id":9417341},{"batl":[[0,7.6,3.6],[1,7.8,16.38],[2,8,17.94]],"ltp":7.6,"tv":938.2,"id":8231803},{"batl":[[0,38,2.31]],"ltp":42.0,"tv":119.59,"id":9193530}]}]}
{"op":"mcm","clk":"995655133","pt":1580557989504,"mc":[{"id":"1.168133548","rc":[{"batl":[[2,17,6.2]],"ltp":12.5,"tv":1340.01,"id":8429550},{"batl":[[0,7.6,11.79]],"ltp":7.6,"tv":938.2,"id":8231803},{"batl":[[2,8,39.89]],"ltp":7.6,"tv":1732.06,"id":10170404},{"batl":[[1,42,5.24]],"ltp":34.0,"tv":168.58,"id":9001159}]}]}
{"op":"mcm","clk":"995655297","pt":1580557990477,"mc":[{"id":"1.168133548","rc":[{"trd":[[11.5,103.16]],"batb":[[0,11.5,2.17],[1,11,4.39],[2,10.5,4]],"ltp":11.5,"tv":1344.01,"id":8429550},{"batb":[[0,29,3.67]],"batl":[[0,34,1.67],[1,36,2.53],[2,42,5.24]],"ltp":34.0,"tv":168.58,"id":9001159}],"tv":9630.37}]}
{"op":"mcm","clk":"995655457","pt":1580557991480,"mc":[{"id":"1.168133548","rc":[{"batl":[[0,7.6,8.19]],"ltp":7.6,"tv":938.2,"id":8231803},{"batl":[[0,40,2.53],[1,44,1],[2,46,1.78]],"ltp":42.0,"tv":119.59,"id":9193530},{"batl":[[2,42,1.85]],"ltp":34.0,"tv":168.58,"id":9001159}]}]}
{"op":"mcm","clk":"995655623","pt":1580557992504,"mc":[{"id":"1.168133548","rc":[{"batl":[[0,7.4,3.6],[1,7.6,10.41],[2,7.8,16.38]],"ltp":7.6,"tv":938.2,"id":8231803},{"batl":[[0,32,3.53],[1,34,1.67],[2,36,2.53]],"ltp":34.0,"tv":168.58,"id":9001159}]}]}
{"op":"mcm","clk":"995655776","pt":1580557993473,"mc":[{"id":"1.168133548","rc":[{"batl":[[1,7.6,14.26]],"ltp":7.6,"tv":938.2,"id":8231803}]}]}
{"op":"mcm","clk":"995656386","pt":1580557997522,"mc":[{"id":"1.168133548","rc":[{"batl":[[1,7.6,18.11]],"ltp":7.6,"tv":938.2,"id":8231803}]}]}
{"op":"mcm","clk":"995656529","pt":1580557998482,"mc":[{"id":"1.168133548","rc":[{"batl":[[1,7.8,20.19],[2,8,37.32]],"ltp":7.6,"tv":1732.06,"id":10170404}]}]}
{"op":"mcm","clk":"995656661","pt":1580557999489,"mc":[{"id":"1.168133548","rc":[{"batb":[[0,34,2.01]],"ltp":42.0,"tv":119.59,"id":9193530}]}]}
{"op":"mcm","clk":"995657187","pt":1580558003505,"mc":[{"id":"1.168133548","rc":[{"batl":[[1,7.8,22.63],[2,8,39.76]],"ltp":7.6,"tv":1732.06,"id":10170404}]}]}
{"op":"mcm","clk":"995657313","pt":1580558004503,"mc":[{"id":"1.168133548","rc":[{"batl":[[1,7.6,21.95]],"ltp":7.6,"tv":938.2,"id":8231803},{"trd":[[8.4,163.54]],"batb":[[0,8.2,106.08]],"batl":[[0,8.4,7.32]],"ltp":8.4,"tv":1637.76,"id":10616006}],"tv":9644.53}]}
{"op":"mcm","clk":"995657557","pt":1580558006324,"mc":[{"id":"1.168133548","rc":[{"batl":[[1,8.6,36.2]],"ltp":8.4,"tv":1637.76,"id":10616006}]}]}
{"op":"mcm","clk":"995658315","pt":1580558011537,"mc":[{"id":"1.168133548","rc":[{"trd":[[30,0.7]],"batb":[[0,29,3.32]],"batl":[[0,32,4.42],[1,36,3.11],[2,42,1.85]],"ltp":30.0,"tv":169.28,"id":9001159}],"tv":9645.23}]}
{"op":"mcm","clk":"995658443","pt":1580558012501,"mc":[{"id":"1.168133548","rc":[{"trd":[[30,2.47]],"batb":[[0,29,3.48]],"batl":[[0,32,3.53]],"ltp":30.0,"tv":171.06,"id":9001159}],"tv":9647.01}]}
{"op":"mcm","clk":"995658599","pt":1580558013509,"mc":[{"id":"1.168133548","rc":[{"batl":[[0,12,2.17],[1,12.5,43.69],[2,13.5,46.24]],"ltp":11.5,"tv":1344.01,"id":8429550},{"batl":[[0,7.2,3.51]],"ltp":7.6,"tv":938.2,"id":8231803},{"batb":[[0,29,3.32],[2,27,6.41]],"batl":[[0,36,3.11],[1,42,1.85],[2,55,10.82]],"ltp":30.0,"tv":171.06,"id":9001159}]}]}
{"op":"mcm","clk":"995658896","pt":1580558015419,"mc":[{"id":"1.168133548","rc":[{"batl":[[2,13.5,40.05]],"ltp":11.5,"tv":1344.01,"id":8429550}]}]}
{"op":"mcm","clk":"995659348","pt":1580558018522,"mc":[{"id":"1.168133548","rc":[{"batl":[[2,13.5,39.25]],"ltp":11.5,"tv":1344.01,"id":8429550},{"batl":[[1,7.6,28.94]],"ltp":7.6,"tv":938.2,"id":8231803}]}]}
{"op":"mcm","clk":"995659497","pt":1580558019527,"mc":[{"id":"1.168133548","rc":[{"batl":[[2,13.5,40.05]],"ltp":11.5,"tv":1344.01,"id":8429550}]}]}
{"op":"mcm","clk":"995660020","pt":1580558023523,"mc":[{"id":"1.168133548","rc":[{"batl":[[2,13.5,39.25]],"ltp":11.5,"tv":1344.01,"id":8429550}]}]}
{"op":"mcm","clk":"995660091","pt":1580558024251,"mc":[{"id":"1.168133548","rc":[{"batl":[[2,13.5,40.05]],"ltp":11.5,"tv":1344.01,"id":8429550}]}]}
{"op":"mcm","clk":"995660225","pt":1580558025156,"mc":[{"id":"1.168133548","rc":[{"trd":[[8.2,73.47]],"batb":[[0,8,24.19],[1,7.8,5.54],[2,7.6,6.25]],"batl":[[0,8.2,12.13],[1,8.4,9.05],[2,8.6,8.68]],"ltp":8.2,"tv":820.68,"id":15608820}],"tv":9662.75}]}
{"op":"mcm","clk":"995660436","pt":1580558026537,"mc":[{"id":"1.168133548","rc":[{"batb":[[0,8,20.5]],"ltp":8.2,"tv":820.68,"id":15608820}]}]}
{"op":"mcm","clk":"995660715","pt":1580558028554,"mc":[{"id":"1.168133548","rc":[{"batl":[[0,12.5,43.69],[1,13.5,40.05],[2,16,16]],"ltp":11.5,"tv":1344.01,"id":8429550},{"batl":[[0,7.6,28.94],[1,7.8,16.38],[2,8,9.87]],"ltp":7.6,"tv":938.2,"id":8231803},{"batb":[[1,7.8,13.48]],"ltp":8.2,"tv":820.68,"id":15608820}]}]}
{"op":"mcm","clk":"995660878","pt":1580558029572,"mc":[{"id":"1.168133548","rc":[{"batl":[[0,12,2.17],[1,12.5,43.69],[2,13.5,40.05]],"ltp":11.5,"tv":1344.01,"id":8429550},{"trd":[[7.2,51.18],[7.6,41.09]],"batl":[[0,7.4,5.26],[1,7.6,20.75],[2,7.8,16.38]],"ltp":7.6,"tv":956.2,"id":8231803}],"tv":9680.74}]}
{"op":"mcm","clk":"995662607","pt":1580558040571,"mc":[{"id":"1.168133548","rc":[{"batl":[[0,8.2,14.13],[2,8.6,6.68]],"ltp":8.2,"tv":820.68,"id":15608820}]}]}
{"op":"mcm","clk":"995663428","pt":1580558045567,"mc":[{"id":"1.168133548","rc":[{"batl":[[0,12.5,43.69],[1,13.5,39.25],[2,16,16]],"ltp":11.5,"tv":1344.01,"id":8429550},{"batl":[[0,7.2,3.6],[2,7.8,24.58]],"ltp":7.6,"tv":956.2,"id":8231803}]}]}
{"op":"mcm","clk":"995664055","pt":1580558049481,"mc":[{"id":"1.168133548","rc":[{"batl":[[2,17,6.2]],"ltp":11.5,"tv":1344.01,"id":8429550}]}]}
{"op":"mcm","clk":"995664212","pt":1580558050476,"mc":[{"id":"1.168133548","rc":[{"trd":[[8.4,178.17]],"batb":[[0,8.4,15.3],[1,8.2,106.08],[2,8,12.31]],"batl":[[0,8.6,36.2],[1,8.8,43.39],[2,9,29]],"ltp":8.4,"tv":1652.39,"id":10616006},{"trd":[[7.2,142.27]],"batb":[[0,7,6.16],[1,6.8,47.97],[2,6.6,18.18]],"ltp":7.2,"tv":1752.05,"id":10170404}],"tv":9715.36}]}
{"op":"mcm","clk":"995664478","pt":1580558052490,"mc":[{"id":"1.168133548","rc":[{"batl":[[1,8.8,51.03]],"ltp":8.4,"tv":1652.39,"id":10616006}]}]}
{"op":"mcm","clk":"995664752","pt":1580558054264,"mc":[{"id":"1.168133548","rc":[{"trd":[[8,24.26]],"batb":[[0,8,8.37]],"batl":[[0,8.2,2]],"ltp":8.0,"tv":844.94,"id":15608820}],"tv":9739.62}]}
{"op":"mcm","clk":"995665515","pt":1580558059487,"mc":[{"id":"1.168133548","rc":[{"batb":[[0,8.2,106.08],[1,8,12.31],[2,7.6,5.26]],"ltp":8.4,"tv":1652.39,"id":10616006}]}]}
{"op":"mcm","clk":"995665632","pt":1580558060395,"mc":[{"id":"1.168133548","rc":[{"batb":[[1,7.8,5.54]],"ltp":8.0,"tv":844.94,"id":15608820}]}]}
{"op":"mcm","clk":"995665801","pt":1580558061475,"mc":[{"id":"1.168133548","rc":[{"batb":[[0,8.2,4.08]],"batl":[[0,8.4,7.02],[1,8.6,36.2],[2,8.8,51.03]],"ltp":8.4,"tv":1652.39,"id":10616006}]}]}
{"op":"mcm","clk":"995666097","pt":1580558063530,"mc":[{"id":"1.168133548","rc":[{"batl":[[2,8.8,43.39]],"ltp":8.4,"tv":1652.39,"id":10616006}]}]}
{"op":"mcm","clk":"995666406","pt":1580558065545,"mc":[{"id":"1.168133548","rc":[{"trd":[[8.2,62.84]],"batb":[[0,8,12.31],[1,7.6,5.26],[2,7.4,3]],"batl":[[0,8.4,7.94]],"ltp":8.2,"tv":1660.55,"id":10616006}],"tv":9747.79}]}
{"op":"mcm","clk":"995666881","pt":1580558068328,"mc":[{"id":"1.168133548","rc":[{"batl":[[0,8.2,2.92],[1,8.4,7.02],[2,8.6,36.2]],"ltp":8.2,"tv":1660.55,"id":10616006}]}]}
{"op":"mcm","clk":"995667203","pt":1580558070511,"mc":[{"id":"1.168133548","rc":[{"trd":[[8,46.72]],"batb":[[0,7.8,5.54],[1,7.6,13.69],[2,7.4,6.98]],"batl":[[0,8.2,2.77]],"ltp":8.0,"tv":867.4,"id":15608820},{"trd":[[5.8,241.92]],"batb":[[0,5.8,4.67],[1,5.7,28.26],[2,5.6,1.08]],"batl":[[0,5.9,6.31],[1,6,5.37],[2,6.2,35.05]],"ltp":5.8,"tv":1153.46,"id":17352128}],"tv":9774.9}]}
{"op":"mcm","clk":"995667372","pt":1580558071529,"mc":[{"id":"1.168133548","rc":[{"trd":[[8,48.26],[8.2,77.47]],"batb":[[1,7.6,12.17],[2,7.4,5.41]],"batl":[[0,8.4,9.05],[1,8.6,6.68],[2,9,2]],"ltp":8.2,"tv":872.94,"id":15608820}],"tv":9780.44}]}
{"op":"mcm","clk":"995667534","pt":1580558072538,"mc":[{"id":"1.168133548","rc":[{"batb":[[0,7.6,8.64],[1,7.4,5.41],[2,7.2,9.56]],"ltp":8.2,"tv":872.94,"id":15608820},{"batb":[[2,27,8.55]],"ltp":30.0,"tv":171.06,"id":9001159}]}]}
{"op":"mcm","clk":"995667640","pt":1580558073326,"mc":[{"id":"1.168133548","rc":[{"batb":[[2,7,8.71]],"ltp":8.2,"tv":1660.55,"id":10616006},{"batb":[[0,7.6,6.25],[1,7.4,8.98]],"ltp":8.2,"tv":872.94,"id":15608820}]}]}
{"op":"mcm","clk":"995667790","pt":1580558074536,"mc":[{"id":"1.168133548","rc":[{"batl":[[1,8.6,11.68]],"ltp":8.2,"tv":872.94,"id":15608820}]}]}
{"op":"mcm","clk":"995667931","pt":1580558075551,"mc":[{"id":"1.168133548","rc":[{"batl":[[0,12,2.17],[1,12.5,43.69],[2,13.5,39.25]],"ltp":11.5,"tv":1344.01,"id":8429550},{"batl":[[0,7.6,20.75],[1,7.8,24.58],[2,8,9.87]],"ltp":7.6,"tv":956.2,"id":8231803}]}]}
{"op":"mcm","clk":"995668073","pt":1580558076551,"mc":[{"id":"1.168133548","rc":[{"batl":[[0,7.6,28.94]],"ltp":7.6,"tv":956.2,"id":8231803}]}]}
{"op":"mcm","clk":"995668211","pt":1580558077552,"mc":[{"id":"1.168133548","rc":[{"batl":[[2,13.5,33.08]],"ltp":11.5,"tv":1344.01,"id":8429550},{"batl":[[0,7.6,18.11]],"ltp":7.6,"tv":956.2,"id":8231803}]}]}
{"op":"mcm","clk":"995668550","pt":1580558079564,"mc":[{"id":"1.168133548","rc":[{"batl":[[1,8.6,21.98]],"ltp":8.2,"tv":872.94,"id":15608820}]}]}
{"op":"mcm","clk":"995668652","pt":1580558080356,"mc":[{"id":"1.168133548","rc":[{"batl":[[0,8.2,12],[1,8.4,9.05],[2,8.6,21.98]],"ltp":8.2,"tv":872.94,"id":15608820}]}]}
{"op":"mcm","clk":"995669301","pt":1580558084541,"mc":[{"id":"1.168133548","rc":[{"trd":[[8.2,68.68],[8.4,182.59]],"batl":[[0,8.4,4.81],[1,8.6,36.2],[2,8.8,43.39]],"ltp":8.4,"tv":1670.81,"id":10616006}],"tv":9790.7}]}
{"op":"mcm","clk":"995670084","pt":1580558089571,"mc":[{"id":"1.168133548","rc":[{"batb":[[1,7.8,2],[2,7.6,5.26]],"ltp":8.4,"tv":1670.81,"id":10616006}]}]}
{"op":"mcm","clk":"995670250","pt":1580558090572,"mc":[{"id":"1.168133548","rc":[{"batl":[[0,8.2,24]],"ltp":8.2,"tv":872.94,"id":15608820}]}]}
{"op":"mcm","clk":"995670388","pt":1580558091435,"mc":[{"id":"1.168133548","rc":[{"batl":[[0,8.2,26]],"ltp":8.2,"tv":872.94,"id":15608820}]}]}
{"op":"mcm","clk":"995670974","pt":1580558095558,"mc":[{"id":"1.168133548","rc":[{"batl":[[0,8,4.55],[1,8.2,26],[2,8.4,21.05]],"ltp":8.2,"tv":872.94,"id":15608820}]}]}
{"op":"mcm","clk":"995671072","pt":1580558096143,"mc":[{"id":"1.168133548","rc":[{"batb":[[1,7.4,10.55]],"ltp":8.2,"tv":872.94,"id":15608820}]}]}
{"op":"mcm","clk":"995671759","pt":1580558100554,"mc":[{"id":"1.168133548","rc":[{"batl":[[2,8.4,33.05]],"ltp":8.2,"tv":872.94,"id":15608820}]}]}
{"op":"mcm","clk":"995672182","pt":1580558103477,"mc":[{"id":"1.168133548","rc":[{"batl":[[2,8.4,45.05]],"ltp":8.2,"tv":872.94,"id":15608820}]}]}
{"op":"mcm","clk":"995672543","pt":1580558105562,"mc":[{"id":"1.168133548","rc":[{"batb":[[0,7.6,7.77]],"batl":[[0,7.8,2],[1,8,4.55],[2,8.2,26]],"ltp":8.2,"tv":872.94,"id":15608820}]}]}
{"op":"mcm","clk":"995672710","pt":1580558106470,"mc":[{"id":"1.168133548","rc":[{"trd":[[7.6,59.09]],"batl":[[0,7.6,9.11]],"ltp":7.6,"tv":974.2,"id":8231803}],"tv":9808.7}]}
{"op":"mcm","clk":"995672869","pt":1580558107491,"mc":[{"id":"1.168133548","rc":[{"batl":[[0,12.5,43.69],[1,13.5,33.08],[2,16,16]],"ltp":11.5,"tv":1344.01,"id":8429550},{"trd":[[5.7,263.74]],"batl":[[0,5.7,5.92],[1,5.8,46.69],[2,5.9,15.37]],"ltp":5.7,"tv":1754.64,"id":9417341},{"batb":[[0,7.2,7.39],[1,7,3.6],[2,6.8,8.73]],"batl":[[0,7.4,3.6],[1,8,9.87],[2,8.2,10.69]],"ltp":7.6,"tv":974.2,"id":8231803},{"batb":[[0,8.2,2.07],[1,8,12.31],[2,7.8,2]],"ltp":8.4,"tv":1670.81,"id":10616006}],"tv":9812.8}]}
{"op":"mcm","clk":"995672971","pt":1580558108180,"mc":[{"id":"1.168133548","rc":[{"trd":[[5.7,275.58]],"batb":[[0,5.7,16.23],[1,5.6,73.83],[2,5.5,32]],"batl":[[0,5.8,46.69],[1,5.9,15.37],[2,6,87.65]],"ltp":5.7,"tv":1766.47,"id":9417341}],"tv":9824.63}]}
{"op":"mcm","clk":"995673134","pt":1580558109497,"mc":[{"id":"1.168133548","rc":[{"batb":[[1,7,6.1]],"batl":[[1,8,17.78]],"ltp":7.6,"tv":974.2,"id":8231803}]}]}
{"op":"mcm","clk":"995673298","pt":1580558110521,"mc":[{"id":"1.168133548","rc":[{"batl":[[2,17,6.2]],"ltp":11.5,"tv":1344.01,"id":8429550}]}]}
{"op":"mcm","clk":"995673608","pt":1580558112501,"mc":[{"id":"1.168133548","rc":[{"trd":[[5.7,279.58]],"batb":[[0,5.7,14.24]],"batl":[[0,5.8,44.69]],"ltp":5.7,"tv":1770.47,"id":9417341}],"tv":9828.63}]}
{"op":"mcm","clk":"995674039","pt":1580558115477,"mc":[{"id":"1.168133548","rc":[{"trd":[[7.8,20]],"batb":[[0,7.8,3],[1,7.6,7.77],[2,7.4,6.98]],"batl":[[0,8,4.55],[1,8.2,26],[2,8.4,45.05]],"ltp":7.8,"tv":876.94,"id":15608820}],"tv":9832.63}]}
{"op":"mcm","clk":"995674520","pt":1580558118513,"mc":[{"id":"1.168133548","rc":[{"batb":[[0,5.6,73.83],[1,5.5,39.85],[2,5.4,20]],"ltp":5.7,"tv":1770.47,"id":9417341}]}]}
{"op":"mcm","clk":"995674827","pt":1580558120475,"mc":[{"id":"1.168133548","rc":[{"batb":[[1,5.5,32]],"ltp":5.7,"tv":1770.47,"id":9417341},{"batl":[[2,8,37.44]],"ltp":7.2,"tv":1752.05,"id":10170404}]}]}
{"op":"mcm","clk":"995675151","pt":1580558122511,"mc":[{"id":"1.168133548","rc":[{"trd":[[7.8,26]],"batb":[[0,7.6,6.25],[1,7.4,6.98],[2,7.2,9.56]],"batl":[[1,8.2,24]],"ltp":7.8,"tv":882.94,"id":15608820}],"tv":9838.63}]}
{"op":"mcm","clk":"995675301","pt":1580558123525,"mc":[{"id":"1.168133548","rc":[{"batb":[[1,7.4,8.98]],"ltp":7.8,"tv":882.94,"id":15608820}]}]}
{"op":"mcm","clk":"995675465","pt":1580558124527,"mc":[{"id":"1.168133548","rc":[{"batb":[[1,7.4,11.65]],"ltp":7.8,"tv":882.94,"id":15608820}]}]}
{"op":"mcm","clk":"995676067","pt":1580558128524,"mc":[{"id":"1.168133548","rc":[{"batl":[[0,8.2,24],[1,8.4,45.05],[2,8.6,45.98]],"ltp":7.8,"tv":882.94,"id":15608820}]}]}
{"op":"mcm","clk":"995676141","pt":1580558129005,"mc":[{"id":"1.168133548","rc":[{"batb":[[1,7.4,10.08]],"ltp":7.8,"tv":882.94,"id":15608820}]}]}
{"op":"mcm","clk":"995676360","pt":1580558130542,"mc":[{"id":"1.168133548","rc":[{"batl":[[2,8.6,57.98]],"ltp":7.8,"tv":882.94,"id":15608820}]}]}
{"op":"mcm","clk":"995676704","pt":1580558132500,"mc":[{"id":"1.168133548","rc":[{"trd":[[8.2,87.87]],"batl":[[0,8.2,18.8]],"ltp":8.2,"tv":893.34,"id":15608820}],"tv":9849.03}]}
{"op":"mcm","clk":"995676883","pt":1580558133519,"mc":[{"id":"1.168133548","rc":[{"batb":[[0,7,5.6]],"ltp":7.2,"tv":1752.05,"id":10170404},{"batl":[[1,8.4,36]],"ltp":8.2,"tv":893.34,"id":15608820},{"batl":[[0,44,1],[1,46,1.78],[2,80,2]],"ltp":42.0,"tv":119.59,"id":9193530},{"batl":[[0,42,2.43],[1,55,10.82],[2,75,11.49]],"ltp":30.0,"tv":171.06,"id":9001159}]}]}
{"op":"mcm","clk":"995677195","pt":1580558135545,"mc":[{"id":"1.168133548","rc":[{"batl":[[1,13,2],[2,13.5,33.08]],"ltp":11.5,"tv":1344.01,"id":8429550}]}]}
{"op":"mcm","clk":"995677641","pt":1580558138524,"mc":[{"id":"1.168133548","rc":[{"batl":[[0,12,2.17],[1,12.5,43.69],[2,13,2]],"ltp":11.5,"tv":1344.01,"id":8429550},{"batl":[[0,8,17.78],[1,8.2,10.69],[2,9,5]],"ltp":7.6,"tv":974.2,"id":8231803},{"batb":[[0,8,12.31],[1,7.8,2],[2,7.6,9.69]],"ltp":8.4,"tv":1670.81,"id":10616006},{"batl":[[0,42,2],[1,44,1],[2,46,1.78]],"ltp":42.0,"tv":119.59,"id":9193530}]}]}
{"op":"mcm","clk":"995677940","pt":1580558140539,"mc":[{"id":"1.168133548","rc":[{"batb":[[2,7.6,5.26]],"ltp":8.4,"tv":1670.81,"id":10616006}]}]}
{"op":"mcm","clk":"995678495","pt":1580558144426,"mc":[{"id":"1.168133548","rc":[{"batl":[[0,12,16.17]],"ltp":11.5,"tv":1344.01,"id":8429550}]}]}
{"op":"mcm","clk":"995680416","pt":1580558157525,"mc":[{"id":"1.168133548","rc":[{"batb":[[0,8,25.71],[1,7.6,6.25],[2,7.4,10.08]],"ltp":8.2,"tv":893.34,"id":15608820}]}]}
{"op":"mcm","clk":"995680573","pt":1580558158494,"mc":[{"id":"1.168133548","rc":[{"trd":[[8,70.18]],"batb":[[0,8,14.75]],"ltp":8.0,"tv":915.26,"id":15608820}],"tv":9870.95}]}
{"op":"mcm","clk":"995680720","pt":1580558159550,"mc":[{"id":"1.168133548","rc":[{"batb":[[1,7.8,5.81],[2,7.6,6.25]],"ltp":8.0,"tv":915.26,"id":15608820}]}]}
{"op":"mcm","clk":"995681388","pt":1580558163535,"mc":[{"id":"1.168133548","rc":[{"batb":[[0,11.5,4.7]],"ltp":11.5,"tv":1344.01,"id":8429550},{"batb":[[0,7.2,7.09],[1,7,5.6],[2,6.8,47.97]],"ltp":7.2,"tv":1752.05,"id":10170404},{"batl":[[0,38,2],[1,40,2.53],[2,44,1]],"ltp":42.0,"tv":119.59,"id":9193530},{"batl":[[0,42,4.96]],"ltp":30.0,"tv":171.06,"id":9001159}]}]}
{"op":"mcm","clk":"995681522","pt":1580558164444,"mc":[{"id":"1.168133548","rc":[{"batb":[[1,7.6,6.25],[2,7.4,7.41]],"ltp":8.0,"tv":915.26,"id":15608820}]}]}
{"op":"mcm","clk":"995681703","pt":1580558165506,"mc":[{"id":"1.168133548","rc":[{"batb":[[1,7.6,13.48]],"ltp":8.0,"tv":915.26,"id":15608820}]}]}
{"op":"mcm","clk":"995682612","pt":1580558171539,"mc":[{"id":"1.168133548","rc":[{"batl":[[0,12,14]],"ltp":11.5,"tv":1344.01,"id":8429550},{"batl":[[0,7.8,7.39],[1,8,17.78],[2,8.2,10.69]],"ltp":7.6,"tv":974.2,"id":8231803},{"batl":[[0,7.6,9.13],[1,7.8,20.63]],"ltp":7.2,"tv":1752.05,"id":10170404},{"batl":[[0,40,2.53],[1,44,1],[2,46,1.78]],"ltp":42.0,"tv":119.59,"id":9193530}]}]}
{"op":"mcm","clk":"995685151","pt":1580558187342,"mc":[{"id":"1.168133548","rc":[{"batb":[[2,6.8,11.78]],"ltp":7.6,"tv":974.2,"id":8231803}]}]}
{"op":"mcm","clk":"995686404","pt":1580558195501,"mc":[{"id":"1.168133548","rc":[{"batb":[[1,5.5,40]],"ltp":5.7,"tv":1770.47,"id":9417341}]}]}
{"op":"mcm","clk":"995686565","pt":1580558196509,"mc":[{"id":"1.168133548","rc":[{"batb":[[1,5.5,48]],"ltp":5.7,"tv":1770.47,"id":9417341}]}]}
{"op":"mcm","clk":"995686886","pt":1580558198520,"mc":[{"id":"1.168133548","rc":[{"batb":[[1,5.5,56]],"ltp":5.7,"tv":1770.47,"id":9417341}]}]}
{"op":"mcm","clk":"995687033","pt":1580558199483,"mc":[{"id":"1.168133548","rc":[{"batb":[[1,5.5,64]],"ltp":5.7,"tv":1770.47,"id":9417341}]}]}
{"op":"mcm","clk":"995687312","pt":1580558201501,"mc":[{"id":"1.168133548","rc":[{"batl":[[0,8,17.78],[1,8.2,10.69],[2,9,5]],"ltp":7.6,"tv":974.2,"id":8231803}]}]}
{"op":"mcm","clk":"995687479","pt":1580558202490,"mc":[{"id":"1.168133548","rc":[{"batl":[[0,7.6,7.39],[1,8,17.78],[2,8.2,10.69]],"ltp":7.6,"tv":974.2,"id":8231803}]}]}
{"op":"mcm","clk":"995688222","pt":1580558207506,"mc":[{"id":"1.168133548","rc":[{"trd":[[8.2,91.87]],"batl":[[0,8.2,16.8]],"ltp":8.2,"tv":919.26,"id":15608820}],"tv":9874.95}]}
{"op":"mcm","clk":"995691471","pt":1580558230509,"mc":[{"id":"1.168133548","rc":[{"batl":[[2,13,2.84]],"ltp":11.5,"tv":1344.01,"id":8429550}]}]}
{"op":"mcm","clk":"995691587","pt":1580558231429,"mc":[{"id":"1.168133548","rc":[{"batl":[[0,7.4,5.72]],"ltp":7.6,"tv":974.2,"id":8231803}]}]}
{"op":"mcm","clk":"995694536","pt":1580558252547,"mc":[{"id":"1.168133548","rc":[{"batb":[[0,11.5,2.17]],"ltp":11.5,"tv":1344.01,"id":8429550},{"batb":[[0,7,5.6],[1,6.8,47.97],[2,6.6,18.18]],"ltp":7.2,"tv":1752.05,"id":10170404},{"batb":[[1,7.8,5.81],[2,7.6,13.48]],"ltp":8.2,"tv":919.26,"id":15608820},{"batl":[[0,44,1],[1,46,1.78],[2,80,2]],"ltp":42.0,"tv":119.59,"id":9193530},{"batl":[[0,42,2.43]],"ltp":30.0,"tv":171.06,"id":9001159}]}]}
{"op":"mcm","clk":"995695516","pt":1580558259331,"mc":[{"id":"1.168133548","rc":[{"batl":[[2,13.5,22.36]],"ltp":11.5,"tv":1344.01,"id":8429550}]}]}
{"op":"mcm","clk":"995695844","pt":1580558261546,"mc":[{"id":"1.168133548","rc":[{"batl":[[0,7.8,8.31]],"ltp":7.6,"tv":974.2,"id":8231803},{"batb":[[0,8.2,2.69],[1,8,12.31],[2,7.8,2]],"ltp":8.4,"tv":1670.81,"id":10616006},{"batl":[[0,42,2],[1,44,1],[2,46,1.78]],"ltp":42.0,"tv":119.59,"id":9193530}]}]}
{"op":"mcm","clk":"995695945","pt":1580558262278,"mc":[{"id":"1.168133548","rc":[{"batb":[[1,7.6,13.48],[2,7.4,7.41]],"ltp":8.2,"tv":919.26,"id":15608820}]}]}
{"op":"mcm","clk":"995698528","pt":1580558280471,"mc":[{"id":"1.168133548","rc":[{"batl":[[0,5.7,10],[1,5.8,44.69],[2,5.9,15.37]],"ltp":5.7,"tv":1770.47,"id":9417341}]}]}
{"op":"mcm","clk":"995698666","pt":1580558281492,"mc":[{"id":"1.168133548","rc":[{"trd":[[5.7,299.58]],"batl":[[0,5.8,44.69],[1,5.9,15.37],[2,6,87.65]],"ltp":5.7,"tv":1790.47,"id":9417341},{"trd":[[8.2,102.41]],"batl":[[0,8.2,11.53]],"ltp":8.2,"tv":929.8,"id":15608820}],"tv":9905.49}]}
{"op":"mcm","clk":"995698981","pt":1580558283570,"mc":[{"id":"1.168133548","rc":[{"batb":[[0,7.2,4],[1,7,5.6],[2,6.8,47.97]],"ltp":7.2,"tv":1752.05,"id":10170404}]}]}
{"op":"mcm","clk":"995699369","pt":1580558286398,"mc":[{"id":"1.168133548","rc":[{"trd":[[8.2,74.06]],"batb":[[0,8,12.31],[1,7.8,2],[2,7.6,5.26]],"batl":[[0,8.2,6.57],[1,8.4,4.81],[2,8.6,36.2]],"ltp":8.2,"tv":1676.19,"id":10616006},{"batb":[[0,7.4,10.27],[1,7.2,4],[2,7,5.6]],"batl":[[2,8,38.87]],"ltp":7.2,"tv":1752.05,"id":10170404},{"trd":[[8,89.19]],"batb":[[0,8,5.24]],"ltp":8.0,"tv":948.81,"id":15608820},{"batl":[[0,36,2],[1,38,2.53],[2,44,1]],"ltp":42.0,"tv":119.59,"id":9193530},{"batl":[[0,42,4.96]],"ltp":30.0,"tv":171.06,"id":9001159}],"tv":9929.88}]}
{"op":"mcm","clk":"995699487","pt":1580558287510,"mc":[{"id":"1.168133548","rc":[{"batl":[[2,13.5,21.52]],"ltp":11.5,"tv":1344.01,"id":8429550}]}]}
{"op":"mcm","clk":"995699542","pt":1580558288007,"mc":[{"id":"1.168133548","rc":[{"batb":[[1,7.6,9.06]],"ltp":8.0,"tv":948.81,"id":15608820}]}]}
{"op":"mcm","clk":"995700002","pt":1580558291534,"mc":[{"id":"1.168133548","rc":[{"batl":[[0,38,2.53],[1,44,1],[2,46,1.78]],"ltp":42.0,"tv":119.59,"id":9193530}]}]}
{"op":"mcm","clk":"995700151","pt":1580558292504,"mc":[{"id":"1.168133548","rc":[{"batb":[[0,7,6.1],[1,6.8,11.78],[2,6.6,11.78]],"batl":[[0,7.6,15.58],[1,7.8,8.31],[2,8,17.78]],"ltp":7.6,"tv":974.2,"id":8231803},{"batl":[[1,8.4,24.81]],"ltp":8.2,"tv":1676.19,"id":10616006}]}]}
{"op":"mcm","clk":"995700255","pt":1580558293193,"mc":[{"id":"1.168133548","rc":[{"batl":[[2,8,37.44]],"ltp":7.2,"tv":1752.05,"id":10170404}]}]}
{"op":"mcm","clk":"995700399","pt":1580558294196,"mc":[{"id":"1.168133548","rc":[{"batb":[[0,7,3.6],[1,6.8,13.99]],"ltp":7.6,"tv":974.2,"id":8231803}]}]}
{"op":"mcm","clk":"995701367","pt":1580558300542,"mc":[{"id":"1.168133548","rc":[{"trd":[[8.2,113.45]],"batl":[[0,8.2,6.01]],"ltp":8.2,"tv":959.85,"id":15608820}],"tv":9940.92}]}
{"op":"mcm","clk":"995701464","pt":1580558301230,"mc":[{"id":"1.168133548","rc":[{"batb":[[1,11,7.43]],"ltp":11.5,"tv":1344.01,"id":8429550},{"batb":[[0,7,8.66]],"batl":[[1,7.8,12.78]],"ltp":7.6,"tv":974.2,"id":8231803},{"batb":[[0,34,4.55],[1,32,2.58]],"ltp":42.0,"tv":119.59,"id":9193530},{"batb":[[1,28,3.85]],"batl":[[2,75,12.01]],"ltp":30.0,"tv":171.06,"id":9001159}]}]}
{"op":"mcm","clk":"995702125","pt":1580558305528,"mc":[{"id":"1.168133548","rc":[{"batl":[[2,13.5,20.72]],"ltp":11.5,"tv":1344.01,"id":8429550},{"trd":[[8,99.67]],"batb":[[0,7.6,13.67],[1,7.4,11.41],[2,7.2,9.56]],"batl":[[0,8,14.76],[1,8.2,6.01],[2,8.4,36]],"ltp":8.0,"tv":970.33,"id":15608820}],"tv":9951.4}]}
{"op":"mcm","clk":"995702249","pt":1580558306330,"mc":[{"id":"1.168133548","rc":[{"batl":[[1,8.2,10.23]],"ltp":8.0,"tv":970.33,"id":15608820}]}]}
{"op":"mcm","clk":"995702416","pt":1580558307540,"mc":[{"id":"1.168133548","rc":[{"batb":[[0,7.6,10.85],[1,7.4,7.41]],"ltp":8.0,"tv":970.33,"id":15608820}]}]}
{"op":"mcm","clk":"995702561","pt":1580558308552,"mc":[{"id":"1.168133548","rc":[{"batb":[[1,7.4,11.82]],"ltp":8.0,"tv":970.33,"id":15608820}]}]}
{"op":"mcm","clk":"995702886","pt":1580558310534,"mc":[{"id":"1.168133548","rc":[{"batb":[[0,34,2.01],[1,32,5.11]],"ltp":42.0,"tv":119.59,"id":9193530}]}]}
{"op":"mcm","clk":"995703872","pt":1580558317355,"mc":[{"id":"1.168133548","rc":[{"batl":[[1,8.2,6.01]],"ltp":8.0,"tv":970.33,"id":15608820}]}]}
{"op":"mcm","clk":"995704600","pt":1580558322361,"mc":[{"id":"1.168133548","rc":[{"batl":[[0,7.4,3.77],[1,7.6,8.19],[2,7.8,12.78]],"ltp":7.6,"tv":974.2,"id":8231803}]}]}
{"op":"mcm","clk":"995704858","pt":1580558330558,"mc":[{"id":"1.168133548","rc":[{"batl":[[1,7.6,12.04]],"ltp":7.6,"tv":974.2,"id":8231803}]}]}
{"op":"mcm","clk":"995705050","pt":1580558330815,"mc":[{"id":"1.168133548","rc":[{"trd":[[8.2,87.21]],"batb":[[0,8.2,9.1],[1,8,12.31],[2,7.8,2]],"batl":[[0,8.4,24.81],[1,8.6,36.2],[2,8.8,43.39]],"ltp":8.2,"tv":1689.34,"id":10616006},{"trd":[[7.6,397.39]],"batb":[[0,7.6,7.86],[1,7.4,10.27],[2,7.2,4]],"batl":[[0,7.8,20.63],[1,8,37.44],[2,8.2,23.83]],"ltp":7.6,"tv":1770.3,"id":10170404},{"batb":[[0,30,3.03],[1,29,3.32],[2,28,3.85]],"ltp":30.0,"tv":171.06,"id":9001159},{"trd":[[5.9,99.19]],"batb":[[0,5.9,22.69],[1,5.8,4.67],[2,5.7,28.26]],"batl":[[0,6,5.37],[1,6.2,35.05],[2,6.4,47.31]],"ltp":5.9,"tv":1166.07,"id":17352128}],"tv":9995.41}]}
{"op":"mcm","clk":"995706183","pt":1580558334552,"mc":[{"id":"1.168133548","rc":[{"batl":[[2,13.5,21.52]],"ltp":11.5,"tv":1344.01,"id":8429550},{"batb":[[0,7,3.6]],"batl":[[0,7.6,19.74],[1,7.8,8.31],[2,8,14.34]],"ltp":7.6,"tv":974.2,"id":8231803},{"trd":[[8.2,105.42]],"batb":[[0,8,12.31],[1,7.8,2],[2,7.6,5.26]],"batl":[[1,8.6,40.6]],"ltp":8.2,"tv":1707.56,"id":10616006},{"batb":[[1,7.4,15.02]],"batl":[[0,7.8,22.11],[1,8,43.53]],"ltp":7.6,"tv":1770.3,"id":10170404},{"batb":[[0,7.6,6.25],[1,7.4,7.41]],"ltp":8.0,"tv":970.33,"id":15608820},{"batb":[[1,5.8,11]],"ltp":5.9,"tv":1166.07,"id":17352128}],"tv":10013.62}]}
{"op":"mcm","clk":"995706368","pt":1580558335539,"mc":[{"id":"1.168133548","rc":[{"batl":[[0,40,3.61],[1,42,4.38],[2,55,10.82]],"ltp":30.0,"tv":171.06,"id":9001159}]}]}
{"op":"mcm","clk":"995706533","pt":1580558336449,"mc":[{"id":"1.168133548","rc":[{"batl":[[1,7.8,16.5]],"ltp":7.6,"tv":974.2,"id":8231803},{"batb":[[0,30,5.56],[2,28,1.32]],"batl":[[2,55,11.34]],"ltp":30.0,"tv":171.06,"id":9001159}]}]}
{"op":"mcm","clk":"995706688","pt":1580558337470,"mc":[{"id":"1.168133548","rc":[{"batl":[[2,55,10.82]],"ltp":30.0,"tv":171.06,"id":9001159}]}]}
{"op":"mcm","clk":"995707405","pt":1580558341545,"mc":[{"id":"1.168133548","rc":[{"batb":[[0,30,2.53]],"ltp":30.0,"tv":171.06,"id":9001159}]}]}
{"op":"mcm","clk":"995707585","pt":1580558342458,"mc":[{"id":"1.168133548","rc":[{"batl":[[2,13.5,20.72]],"ltp":11.5,"tv":1344.01,"id":8429550},{"batb":[[0,7.4,15.02],[1,7.2,4],[2,7,5.6]],"batl":[[0,7.8,20.63],[2,8.2,22.44]],"ltp":7.6,"tv":1770.3,"id":10170404},{"batl":[[1,8.2,10.23]],"ltp":8.0,"tv":970.33,"id":15608820},{"batb":[[0,5.8,11],[1,5.7,28.26],[2,5.6,1.08]],"ltp":5.9,"tv":1166.07,"id":17352128}]}]}
{"op":"mcm","clk":"995707826","pt":1580558343473,"mc":[{"id":"1.168133548","rc":[{"batb":[[1,7.4,10.08]],"ltp":8.0,"tv":970.33,"id":15608820},{"batb":[[1,5.7,47.05]],"ltp":5.9,"tv":1166.07,"id":17352128}]}]}
{"op":"mcm","clk":"995708079","pt":1580558344542,"mc":[{"id":"1.168133548","rc":[{"batb":[[0,5.8,4.67]],"ltp":5.9,"tv":1166.07,"id":17352128}]}]}
{"op":"mcm","clk":"995708258","pt":1580558345568,"mc":[{"id":"1.168133548","rc":[{"batb":[[0,29,3.32],[1,28,1.32],[2,27,6.41]],"ltp":30.0,"tv":171.06,"id":9001159}]}]}
{"op":"mcm","clk":"995708430","pt":1580558346479,"mc":[{"id":"1.168133548","rc":[{"batb":[[1,28,3.85],[2,27,8.97]],"ltp":30.0,"tv":171.06,"id":9001159},{"batb":[[1,5.7,28.26]],"batl":[[0,6,13.15]],"ltp":5.9,"tv":1166.07,"id":17352128}]}]}
{"op":"mcm","clk":"995708598","pt":1580558347367,"mc":[{"id":"1.168133548","rc":[{"batl":[[0,7.4,3.6],[1,7.6,19.74],[2,7.8,16.5]],"ltp":7.6,"tv":974.2,"id":8231803},{"batb":[[0,8.2,2.38],[1,8,12.31],[2,7.8,2]],"ltp":8.2,"tv":1707.56,"id":10616006},{"batl":[[0,42,4.96],[1,55,10.82],[2,75,12.01]],"ltp":30.0,"tv":171.06,"id":9001159}]}]}
{"op":"mcm","clk":"995708774","pt":1580558348343,"mc":[{"id":"1.168133548","rc":[{"batl":[[2,13.5,21.52]],"ltp":11.5,"tv":1344.01,"id":8429550},{"batb":[[1,7.4,7.41]],"ltp":8.0,"tv":970.33,"id":15608820}]}]}
{"op":"mcm","clk":"995708915","pt":1580558349261,"mc":[{"id":"1.168133548","rc":[{"batl":[[1,7.6,23.58]],"ltp":7.6,"tv":974.2,"id":8231803}]}]}
{"op":"mcm","clk":"995709456","pt":1580558352474,"mc":[{"id":"1.168133548","rc":[{"batl":[[0,7.6,23.58],[1,7.8,16.5],[2,8,14.34]],"ltp":7.6,"tv":974.2,"id":8231803},{"batb":[[0,8,12.31],[1,7.8,2],[2,7.6,5.26]],"ltp":8.2,"tv":1707.56,"id":10616006}]}]}
{"op":"mcm","clk":"995709630","pt":1580558353561,"mc":[{"id":"1.168133548","rc":[{"batl":[[0,7.4,3.6],[1,7.6,23.58],[2,7.8,16.5]],"ltp":7.6,"tv":974.2,"id":8231803},{"batb":[[0,8.2,2.38],[1,8,12.31],[2,7.8,2]],"ltp":8.2,"tv":1707.56,"id":10616006}]}]}
{"op":"mcm","clk":"995709994","pt":1580558355564,"mc":[{"id":"1.168133548","rc":[{"batb":[[0,7,8.66]],"ltp":7.6,"tv":974.2,"id":8231803},{"batb":[[0,7.6,10.85]],"ltp":8.0,"tv":970.33,"id":15608820}]}]}
{"op":"mcm","clk":"995710619","pt":1580558359294,"mc":[{"id":"1.168133548","rc":[{"batl":[[1,7.6,28.05]],"ltp":7.6,"tv":974.2,"id":8231803}]}]}
{"op":"mcm","clk":"995714163","pt":1580558381433,"mc":[{"id":"1.168133548","rc":[{"batl":[[0,7.6,28.05],[1,7.8,16.5],[2,8,9.87]],"ltp":7.6,"tv":974.2,"id":8231803},{"batb":[[0,8,12.31],[1,7.8,2],[2,7.6,5.26]],"ltp":8.2,"tv":1707.56,"id":10616006}]}]}
{"op":"mcm","clk":"995714347","pt":1580558382526,"mc":[{"id":"1.168133548","rc":[{"batl":[[2,13.5,20.72]],"ltp":11.5,"tv":1344.01,"id":8429550},{"batl":[[0,7.2,3.66],[1,7.6,28.05],[2,7.8,16.5]],"ltp":7.6,"tv":974.2,"id":8231803},{"batb":[[2,7.6,10.62]],"ltp":8.2,"tv":1707.56,"id":10616006},{"batb":[[0,7.8,10.21],[1,7.6,10.85],[2,7.4,11.82]],"ltp":8.0,"tv":970.33,"id":15608820}]}]}
{"op":"mcm","clk":"995714501","pt":1580558383537,"mc":[{"id":"1.168133548","rc":[{"batl":[[2,13.5,21.52]],"ltp":11.5,"tv":1344.01,"id":8429550}]}]}
{"op":"mcm","clk":"995714667","pt":1580558384516,"mc":[{"id":"1.168133548","rc":[{"batb":[[2,7.6,5.26]],"ltp":8.2,"tv":1707.56,"id":10616006},{"batl":[[1,8.2,6.01]],"ltp":8.0,"tv":970.33,"id":15608820}]}]}
{"op":"mcm","clk":"995714927","pt":1580558386426,"mc":[{"id":"1.168133548","rc":[{"batb":[[1,7.6,6.25]],"ltp":8.0,"tv":970.33,"id":15608820}]}]}
{"op":"mcm","clk":"995715342","pt":1580558389539,"mc":[{"id":"1.168133548","rc":[{"batl":[[0,7.8,18.19]],"ltp":7.6,"tv":1770.3,"id":10170404}]}]}
{"op":"mcm","clk":"995715486","pt":1580558390525,"mc":[{"id":"1.168133548","rc":[{"batl":[[0,5.7,10],[1,5.8,44.69],[2,5.9,15.37]],"ltp":5.7,"tv":1790.47,"id":9417341},{"batb":[[2,6.6,13.57]],"ltp":7.6,"tv":974.2,"id":8231803},{"batl":[[1,8,41.09],[2,8.2,20]],"ltp":7.6,"tv":1770.3,"id":10170404}]}]}
{"op":"mcm","clk":"995715796","pt":1580558392426,"mc":[{"id":"1.168133548","rc":[{"trd":[[5.7,319.56]],"batb":[[0,5.7,4.25],[1,5.6,73.83],[2,5.5,64]],"batl":[[0,5.8,44.69],[1,5.9,15.37],[2,6,87.65]],"ltp":5.7,"tv":1810.46,"id":9417341},{"batb":[[2,6.6,11.78]],"ltp":7.6,"tv":974.2,"id":8231803}],"tv":10033.61}]}
{"op":"mcm","clk":"995717149","pt":1580558400480,"mc":[{"id":"1.168133548","rc":[{"trd":[[8,40.13]],"batb":[[0,7.8,2],[1,7.6,5.26],[2,7,8.71]],"batl":[[0,8,2.69],[1,8.4,24.81],[2,8.6,40.6]],"ltp":8.0,"tv":1732.18,"id":10616006}],"tv":10058.23}]}
{"op":"mcm","clk":"995717373","pt":1580558401476,"mc":[{"id":"1.168133548","rc":[{"batb":[[2,6.6,13.57]],"ltp":7.6,"tv":974.2,"id":8231803},{"batb":[[2,7.4,4.75]],"batl":[[1,8.4,28.92]],"ltp":8.0,"tv":1732.18,"id":10616006}]}]}
{"op":"mcm","clk":"995717595","pt":1580558402479,"mc":[{"id":"1.168133548","rc":[{"batl":[[2,8.6,36.2]],"ltp":8.0,"tv":1732.18,"id":10616006}]}]}
{"op":"mcm","clk":"995717747","pt":1580558403304,"mc":[{"id":"1.168133548","rc":[{"batb":[[0,5.6,73.83],[1,5.5,64],[2,5.4,20]],"ltp":5.7,"tv":1810.46,"id":9417341},{"trd":[[7.2,58.5]],"batb":[[0,7.2,26.51],[1,7,8.66],[2,6.8,13.99]],"batl":[[0,7.4,5.49],[1,7.6,23.58]],"ltp":7.2,"tv":981.51,"id":8231803}],"tv":10065.55}]}
{"op":"mcm","clk":"995718025","pt":1580558404573,"mc":[{"id":"1.168133548","rc":[{"trd":[[7.4,20.97]],"batb":[[0,7.4,1.77],[1,7.2,26.51],[2,7,17.11]],"batl":[[0,7.6,15.39],[1,7.8,16.5],[2,8,9.87]],"ltp":7.4,"tv":992.49,"id":8231803}],"tv":10076.53}]}
{"op":"mcm","clk":"995718203","pt":1580558405500,"mc":[{"id":"1.168133548","rc":[{"trd":[[7.6,77.08]],"batb":[[2,7,16.81]],"batl":[[0,7.6,6.39],[1,7.8,24.69]],"ltp":7.6,"tv":1010.49,"id":8231803},{"batb":[[0,34,2.52]],"ltp":42.0,"tv":119.59,"id":9193530},{"trd":[[6,149.37]],"batl":[[0,6,4.15]],"ltp":6.0,"tv":1184.07,"id":17352128}],"tv":10112.53}]}
{"op":"mcm","clk":"995718359","pt":1580558406369,"mc":[{"id":"1.168133548","rc":[{"batb":[[0,7.4,10.27]],"ltp":7.6,"tv":1770.3,"id":10170404}]}]}
{"op":"mcm","clk":"995718552","pt":1580558407418,"mc":[{"id":"1.168133548","rc":[{"batb":[[2,7,3.6]],"batl":[[0,8,9.87],[1,8.2,10.69],[2,8.8,28]],"ltp":7.6,"tv":1010.49,"id":8231803}]}]}
{"op":"mcm","clk":"995718732","pt":1580558408480,"mc":[{"id":"1.168133548","rc":[{"batl":[[0,8,15.84]],"ltp":7.6,"tv":1010.49,"id":8231803},{"trd":[[34,8.19]],"batb":[[0,32,5.63],[1,30,6.19],[2,29,2]],"ltp":34.0,"tv":123.59,"id":9193530}],"tv":10116.53}]}
{"op":"mcm","clk":"995719077","pt":1580558410480,"mc":[{"id":"1.168133548","rc":[{"batl":[[2,9,5]],"ltp":7.6,"tv":1010.49,"id":8231803}]}]}
{"op":"mcm","clk":"995719199","pt":1580558411394,"mc":[{"id":"1.168133548","rc":[{"batl":[[1,6.2,40.9]],"ltp":6.0,"tv":1184.07,"id":17352128}]}]}
{"op":"mcm","clk":"995719509","pt":1580558413506,"mc":[{"id":"1.168133548","rc":[{"trd":[[8,110.47]],"batb":[[1,7.6,11.52],[2,7.4,6.41]],"batl":[[0,8,9.36]],"ltp":8.0,"tv":981.13,"id":15608820}],"tv":10127.33}]}
{"op":"mcm","clk":"995719663","pt":1580558414518,"mc":[{"id":"1.168133548","rc":[{"batb":[[0,7,3.6],[1,6.8,13.99],[2,6.6,11.78]],"batl":[[0,7.6,3.6],[1,7.8,5.39],[2,8,15.84]],"ltp":7.6,"tv":1010.49,"id":8231803},{"batb":[[0,29,12.05]],"ltp":30.0,"tv":171.06,"id":9001159}]}]}
{"op":"mcm","clk":"995719771","pt":1580558415458,"mc":[{"id":"1.168133548","rc":[{"batl":[[0,6,18.15]],"ltp":6.0,"tv":1184.07,"id":17352128}]}]}
{"op":"mcm","clk":"995720339","pt":1580558418524,"mc":[{"id":"1.168133548","rc":[{"batb":[[0,7,8.66]],"ltp":7.6,"tv":1010.49,"id":8231803}]}]}
{"op":"mcm","clk":"995720521","pt":1580558419494,"mc":[{"id":"1.168133548","rc":[{"batl":[[2,13.5,22.36]],"ltp":11.5,"tv":1344.01,"id":8429550},{"trd":[[7.6,80.28]],"batl":[[0,7.6,2]],"ltp":7.6,"tv":1013.69,"id":8231803}],"tv":10130.52}]}
{"op":"mcm","clk":"995720683","pt":1580558420500,"mc":[{"id":"1.168133548","rc":[{"trd":[[11.5,107.5]],"batb":[[0,11,7.43],[1,10.5,4],[2,10,29.06]],"batl":[[0,11.5,7.83],[1,12,14],[2,12.5,43.69]],"ltp":11.5,"tv":1348.35,"id":8429550}],"tv":10134.86}]}
{"op":"mcm","clk":"995720814","pt":1580558421515,"mc":[{"id":"1.168133548","rc":[{"batb":[[0,11,4.39],[1,10.5,7.04]],"batl":[[1,12,16.76]],"ltp":11.5,"tv":1348.35,"id":8429550},{"batb":[[0,30,2.53],[1,29,12.05],[2,28,1.32]],"ltp":30.0,"tv":171.06,"id":9001159},{"batl":[[1,6.2,35.05]],"ltp":6.0,"tv":1184.07,"id":17352128}]}]}
{"op":"mcm","clk":"995721083","pt":1580558423437,"mc":[{"id":"1.168133548","rc":[{"batl":[[0,7.8,5.39],[1,8,15.84],[2,8.2,10.69]],"ltp":7.6,"tv":1013.69,"id":8231803},{"batl":[[1,8,43.53],[2,8.2,22.44]],"ltp":7.6,"tv":1770.3,"id":10170404},{"batb":[[1,29,3.32]],"batl":[[0,40,3.12],[1,42,4.38],[2,55,10.82]],"ltp":30.0,"tv":171.06,"id":9001159}]}]}
{"op":"mcm","clk":"995722094","pt":1580558430460,"mc":[{"id":"1.168133548","rc":[{"batb":[[0,7.4,15.02]],"ltp":7.6,"tv":1770.3,"id":10170404},{"batb":[[0,29,3.32],[1,28,3.85],[2,27,8.97]],"ltp":30.0,"tv":171.06,"id":9001159}]}]}
{"op":"mcm","clk":"995722442","pt":1580558432574,"mc":[{"id":"1.168133548","rc":[{"batb":[[0,5.7,2.29],[1,5.6,73.83],[2,5.5,64]],"ltp":5.7,"tv":1810.46,"id":9417341},{"batl":[[0,7.6,2.49],[1,7.8,5.39],[2,8,15.84]],"ltp":7.6,"tv":1013.69,"id":8231803},{"batl":[[0,42,4.96],[1,55,10.82],[2,75,12.01]],"ltp":30.0,"tv":171.06,"id":9001159}]}]}
{"op":"mcm","clk":"995722627","pt":1580558433540,"mc":[{"id":"1.168133548","rc":[{"batb":[[0,7.4,1.77],[1,7.2,61.68],[2,7,17.11]],"batl":[[1,8,15.84],[2,8.2,10.69]],"ltp":7.6,"tv":1013.69,"id":8231803},{"batb":[[0,7.4,4.75]],"ltp":7.6,"tv":1770.3,"id":10170404},{"trd":[[8,129.19]],"batb":[[0,7.6,11.52],[1,7.4,6.41],[2,7.2,9.56]],"batl":[[0,8.2,6.01],[1,8.4,36],[2,8.6,57.98]],"ltp":8.0,"tv":999.85,"id":15608820},{"batl":[[0,44,1],[1,46,1.78],[2,80,2.52]],"ltp":34.0,"tv":123.59,"id":9193530},{"batb":[[0,29,12.05]],"batl":[[0,42,2.43]],"ltp":30.0,"tv":171.06,"id":9001159}],"tv":10153.58}]}
{"op":"mcm","clk":"995722806","pt":1580558434550,"mc":[{"id":"1.168133548","rc":[{"trd":[[5.7,323.92]],"batb":[[0,5.6,73.94],[1,5.5,64],[2,5.4,20]],"ltp":5.7,"tv":1814.81,"id":9417341},{"trd":[[7.4,26.01],[7.6,81.98]],"batb":[[0,7.2,61.68],[1,7,17.11],[2,6.8,13.99]],"batl":[[0,7.6,1.64]],"ltp":7.6,"tv":1020.42,"id":8231803},{"batl":[[0,8,4.69]],"ltp":8.0,"tv":1732.18,"id":10616006},{"batb":[[0,8,10.21],[1,7.6,11.52],[2,7.4,6.41]],"ltp":8.0,"tv":999.85,"id":15608820}],"tv":10164.68}]}
{"op":"mcm","clk":"995722970","pt":1580558435563,"mc":[{"id":"1.168133548","rc":[{"batb":[[1,7,19.83]],"ltp":7.6,"tv":1020.42,"id":8231803},{"batl":[[0,7.8,22.66]],"ltp":7.6,"tv":1770.3,"id":10170404},{"batb":[[1,7.8,4.47],[2,7.6,11.52]],"ltp":8.0,"tv":999.85,"id":15608820},{"batl":[[2,75,3.54]],"ltp":34.0,"tv":123.59,"id":9193530}]}]}
{"op":"mcm","clk":"995723112","pt":1580558436380,"mc":[{"id":"1.168133548","rc":[{"batl":[[2,80,2.52]],"ltp":34.0,"tv":123.59,"id":9193530}]}]}
{"op":"mcm","clk":"995723305","pt":1580558437561,"mc":[{"id":"1.168133548","rc":[{"batb":[[0,5.7,2.29],[1,5.6,73.83],[2,5.5,64]],"ltp":5.7,"tv":1814.81,"id":9417341},{"batl":[[0,7.6,2.49]],"ltp":7.6,"tv":1020.42,"id":8231803},{"batl":[[0,6,4.15]],"ltp":6.0,"tv":1184.07,"id":17352128}]}]}
{"op":"mcm","clk":"995723940","pt":1580558441570,"mc":[{"id":"1.168133548","rc":[{"batb":[[0,7.2,4],[1,7,10.35],[2,6.8,53.85]],"ltp":7.6,"tv":1770.3,"id":10170404},{"trd":[[8.2,125.45]],"batl":[[0,8.4,36.01],[1,8.6,57.98],[2,9,6.05]],"ltp":8.2,"tv":1011.85,"id":15608820}],"tv":10176.68}]}
{"op":"mcm","clk":"995724200","pt":1580558443285,"mc":[{"id":"1.168133548","rc":[{"batb":[[0,7,19.83],[1,6.8,13.99],[2,6.6,11.78]],"ltp":7.6,"tv":1020.42,"id":8231803},{"batl":[[1,8.6,65.72]],"ltp":8.2,"tv":1011.85,"id":15608820}]}]}
{"op":"mcm","clk":"995724587","pt":1580558445517,"mc":[{"id":"1.168133548","rc":[{"batb":[[0,7,8.66],[1,6.8,22.57]],"ltp":7.6,"tv":1020.42,"id":8231803},{"batb":[[1,7.8,8.58]],"ltp":8.2,"tv":1011.85,"id":15608820}]}]}
{"op":"mcm","clk":"995724711","pt":1580558446383,"mc":[{"id":"1.168133548","rc":[{"trd":[[7.8,2]],"batb":[[0,7.8,1]],"ltp":7.8,"tv":1734.18,"id":10616006}],"tv":10178.68}]}
{"op":"mcm","clk":"995724867","pt":1580558447399,"mc":[{"id":"1.168133548","rc":[{"batb":[[1,6.8,13.99]],"ltp":7.6,"tv":1020.42,"id":8231803},{"trd":[[7.8,4]],"batb":[[0,7.6,5.26],[1,7.2,8.75],[2,7,8.71]],"batl":[[0,7.8,20],[1,8,4.69],[2,8.4,28.92]],"ltp":7.8,"tv":1736.18,"id":10616006}],"tv":10180.68}]}
