{"op":"mcm","clk":"990362571","pt":1580496617568,"mc":[{"id":"1.168133543","rc":[{"batb":[[0,48,2.29],[1,14.5,2.32],[2,14,3.03]],"ltp":0.0,"tv":0.0,"id":22308007},{"batb":[[0,30,3.72],[1,14,1.07],[2,13.5,12.13]],"ltp":0.0,"tv":0.0,"id":7226819},{"batb":[[1,5.9,22.02],[2,5.3,5.55]],"ltp":0.0,"tv":0.0,"id":10163711},{"batb":[[0,2.46,73.92],[1,2,1.27],[2,1.96,2.52]],"ltp":2.0,"tv":95.4,"id":10107355},{"batb":[[0,8.2,16.97]],"ltp":0.0,"tv":0.0,"id":22121325},{"batb":[[0,42,2.63],[1,22,5.15],[2,21,5]],"ltp":0.0,"tv":0.0,"id":26548208},{"batb":[[0,140,2],[1,23,4.82],[2,22,5]],"ltp":0.0,"tv":0.0,"id":27606066},{"batb":[[0,70,2],[1,23,4.82],[2,22,5]],"ltp":0.0,"tv":0.0,"id":24270700},{"batb":[[0,70,2],[1,22,3.37],[2,21,6]],"ltp":22.0,"tv":4.0,"id":13306150}]}]}
{"op":"mcm","clk":"990362811","pt":1580496620204,"mc":[{"id":"1.168133543","rc":[{"batb":[[0,2.74,48.55],[1,2.72,10.72],[2,2.68,2.52]],"ltp":2.94,"tv":115.93,"id":12636},{"batl":[[1,220,5],[2,1000,0.2]],"ltp":0.0,"tv":0.0,"id":22308007},{"batb":[[0,34,5],[1,30,3.72],[2,14,1.07]],"ltp":0.0,"tv":0.0,"id":7226819},{"batb":[[2,5.5,18.4]],"ltp":0.0,"tv":0.0,"id":10163711},{"batl":[[2,2.96,41.4]],"ltp":2.0,"tv":95.4,"id":10107355},{"batb":[[1,8,13.81]],"ltp":0.0,"tv":0.0,"id":22121325},{"batb":[[0,46,5],[1,42,2.63],[2,22,5.15]],"ltp":0.0,"tv":0.0,"id":26548208},{"batb":[[0,250,5],[1,140,2],[2,23,4.82]],"ltp":0.0,"tv":0.0,"id":27606066},{"batb":[[0,110,5],[1,70,2],[2,23,4.82]],"ltp":0.0,"tv":0.0,"id":24270700},{"batb":[[0,110,5],[1,70,2],[2,22,3.37]],"ltp":22.0,"tv":4.0,"id":13306150}]}]}
{"op":"mcm","clk":"990363234","pt":1580496624492,"mc":[{"id":"1.168133543","rc":[{"batl":[[2,1000,0]],"ltp":0.0,"tv":0.0,"id":22308007}]}]}
{"op":"mcm","clk":"990363614","pt":1580496628208,"mc":[{"id":"1.168133543","rc":[{"batl":[[0,2.54,2.58]],"ltp":2.0,"tv":95.4,"id":10107355}]}]}
{"op":"mcm","clk":"990363825","pt":1580496630393,"mc":[{"id":"1.168133543","rc":[{"batl":[[1,100,5],[2,110,9]],"ltp":0.0,"tv":0.0,"id":7226819},{"trd":[[8.6,12.46]],"batl":[[0,8.6,4.66],[1,620,9],[2,640,3.23]],"ltp":8.6,"tv":12.46,"id":10163711},{"batl":[[0,14,6.37],[1,620,9],[2,640,3.23]],"ltp":0.0,"tv":0.0,"id":22121325},{"batl":[[0,160,5],[1,980,9.2]],"ltp":0.0,"tv":0.0,"id":26548208},{"batl":[[0,590,5],[1,1000,0.2]],"ltp":0.0,"tv":0.0,"id":27606066},{"batl":[[0,290,5],[1,1000,0.2]],"ltp":0.0,"tv":0.0,"id":24270700},{"batl":[[0,290,5],[1,1000,0.2]],"ltp":22.0,"tv":4.0,"id":13306150}],"tv":231.56}]}
{"op":"mcm","clk":"990363933","pt":1580496631561,"mc":[{"id":"1.168133543","rc":[{"batb":[[0,7,3],[1,6.8,2.76],[2,5.9,22.02]],"ltp":8.6,"tv":12.46,"id":10163711}]}]}
{"op":"mcm","clk":"990364833","pt":1580496640420,"mc":[{"id":"1.168133543","rc":[{"batl":[[0,8.6,10.89]],"ltp":8.6,"tv":12.46,"id":10163711}]}]}
{"op":"mcm","clk":"990365010","pt":1580496642445,"mc":[{"id":"1.168133543","rc":[{"batl":[[2,310,9]],"ltp":0.0,"tv":0.0,"id":7226819},{"batl":[[1,29,9]],"ltp":8.6,"tv":12.46,"id":10163711},{"batl":[[1,65,9]],"ltp":0.0,"tv":0.0,"id":22121325}]}]}
{"op":"mcm","clk":"990365250","pt":1580496645214,"mc":[{"id":"1.168133543","rc":[{"batb":[[0,2.48,3],[1,2.46,73.92],[2,2,1.27]],"ltp":2.0,"tv":95.4,"id":10107355}]}]}
{"op":"mcm","clk":"990372822","pt":1580496715470,"mc":[{"id":"1.168133543","rc":[{"batb":[[0,2.74,56.14],[1,2.72,3.12]],"ltp":2.94,"tv":115.93,"id":12636},{"batb":[[1,14,3.37],[2,13.5,2.52]],"ltp":0.0,"tv":0.0,"id":22308007},{"batb":[[0,7.2,1.98],[1,7,3],[2,5.9,22.8]],"ltp":8.6,"tv":12.46,"id":10163711},{"batb":[[0,8.4,1.98],[1,8.2,16.97],[2,8,11.83]],"ltp":0.0,"tv":0.0,"id":22121325},{"batb":[[2,22,3.17]],"ltp":0.0,"tv":0.0,"id":26548208},{"batb":[[2,23,3.14]],"ltp":0.0,"tv":0.0,"id":27606066},{"batb":[[2,23,3.14]],"ltp":0.0,"tv":0.0,"id":24270700},{"batb":[[2,22,2.74]],"ltp":22.0,"tv":4.0,"id":13306150}]}]}
{"op":"mcm","clk":"990373098","pt":1580496718033,"mc":[{"id":"1.168133543","rc":[{"batb":[[0,7.2,4.98],[1,5.9,22.8],[2,5.5,18.4]],"ltp":8.6,"tv":12.46,"id":10163711}]}]}
{"op":"mcm","clk":"990373422","pt":1580496720534,"mc":[{"id":"1.168133543","rc":[{"batl":[[2,640,3.03]],"ltp":8.6,"tv":12.46,"id":10163711}]}]}
{"op":"mcm","clk":"990374361","pt":1580496728966,"mc":[{"id":"1.168133543","rc":[{"batb":[[0,7.4,3],[1,7.2,1.98],[2,5.9,22.8]],"ltp":8.6,"tv":12.46,"id":10163711}]}]}
{"op":"mcm","clk":"990374928","pt":1580496734392,"mc":[{"id":"1.168133543","rc":[{"batb":[[2,1.96,3.48]],"ltp":2.0,"tv":95.4,"id":10107355}]}]}
{"op":"mcm","clk":"990375053","pt":1580496735496,"mc":[{"id":"1.168133543","rc":[{"batb":[[1,8.2,14.98]],"ltp":0.0,"tv":0.0,"id":22121325}]}]}
{"op":"mcm","clk":"990375167","pt":1580496736490,"mc":[{"id":"1.168133543","rc":[{"batb":[[0,8.6,1.99],[1,8.4,1.98],[2,8.2,14.98]],"ltp":0.0,"tv":0.0,"id":22121325}]}]}
{"op":"mcm","clk":"990375462","pt":1580496739483,"mc":[{"id":"1.168133543","rc":[{"batb":[[0,7.2,1.98],[1,7,3]],"ltp":8.6,"tv":12.46,"id":10163711}]}]}
{"op":"mcm","clk":"990376710","pt":1580496750805,"mc":[{"id":"1.168133543","rc":[{"batb":[[0,7.2,4.98],[1,5.9,22.8],[2,5.5,18.4]],"ltp":8.6,"tv":12.46,"id":10163711}]}]}
{"op":"mcm","clk":"990386556","pt":1580496752490,"mc":[{"id":"1.168133543","rc":[{"batl":[[0,2.6,1.68],[1,2.96,41.4],[2,3,22]],"ltp":2.0,"tv":95.4,"id":10107355}]}]}
{"op":"mcm","clk":"990386656","pt":1580496753422,"mc":[{"id":"1.168133543","rc":[{"batl":[[0,8.4,3.03],[1,8.6,10.89],[2,29,9]],"ltp":8.6,"tv":12.46,"id":10163711},{"batl":[[1,2.94,2.23],[2,2.96,41.4]],"ltp":2.0,"tv":95.4,"id":10107355},{"batl":[[2,640,0.2]],"ltp":0.0,"tv":0.0,"id":22121325}]}]}
{"op":"mcm","clk":"990386762","pt":1580496754426,"mc":[{"id":"1.168133543","rc":[{"batl":[[0,13.5,3.03],[1,14,6.37],[2,65,9]],"ltp":0.0,"tv":0.0,"id":22121325}]}]}
{"op":"mcm","clk":"990387381","pt":1580496760212,"mc":[{"id":"1.168133543","rc":[{"batb":[[0,7.4,3],[1,7.2,1.98],[2,5.9,22.8]],"ltp":8.6,"tv":12.46,"id":10163711}]}]}
{"op":"mcm","clk":"990388745","pt":1580496771564,"mc":[{"id":"1.168133543","rc":[{"batb":[[0,7.2,1.98],[1,5.9,22.8],[2,5.5,18.4]],"ltp":8.6,"tv":12.46,"id":10163711}]}]}
{"op":"mcm","clk":"990388754","pt":1580496771663,"mc":[{"id":"1.168133543","rc":[{"batb":[[1,7,3],[2,5.9,22.8]],"ltp":8.6,"tv":12.46,"id":10163711}]}]}
{"op":"mcm","clk":"990389927","pt":1580496781448,"mc":[{"id":"1.168133543","rc":[{"batb":[[0,7.2,4.98],[1,5.9,22.8],[2,5.5,18.4]],"ltp":8.6,"tv":12.46,"id":10163711}]}]}
{"op":"mcm","clk":"990391454","pt":1580496794375,"mc":[{"id":"1.168133543","rc":[{"batb":[[0,7.4,3],[1,7.2,1.98],[2,5.9,22.8]],"ltp":8.6,"tv":12.46,"id":10163711}]}]}
{"op":"mcm","clk":"990392605","pt":1580496804610,"mc":[{"id":"1.168133543","rc":[{"batl":[[0,11.5,10],[1,13.5,3.03],[2,14,6.37]],"ltp":0.0,"tv":0.0,"id":22121325}]}]}
{"op":"mcm","clk":"990393047","pt":1580496808500,"mc":[{"id":"1.168133543","rc":[{"batb":[[0,7.2,1.98],[1,7,3]],"ltp":8.6,"tv":12.46,"id":10163711}]}]}
{"op":"mcm","clk":"990394479","pt":1580496821830,"mc":[{"id":"1.168133543","rc":[{"batb":[[0,7.2,4.98],[1,5.9,22.8],[2,5.5,18.4]],"ltp":8.6,"tv":12.46,"id":10163711}]}]}
{"op":"mcm","clk":"990395750","pt":1580496833150,"mc":[{"id":"1.168133543","rc":[{"batb":[[0,7.4,3],[1,7.2,1.98],[2,5.9,22.8]],"ltp":8.6,"tv":12.46,"id":10163711}]}]}
{"op":"mcm","clk":"990396990","pt":1580496845477,"mc":[{"id":"1.168133543","rc":[{"batb":[[0,7.2,1.98],[1,7,3]],"ltp":8.6,"tv":12.46,"id":10163711}]}]}
{"op":"mcm","clk":"990397944","pt":1580496855098,"mc":[{"id":"1.168133543","rc":[{"batb":[[0,7.2,4.98],[1,5.9,22.8],[2,5.5,18.4]],"ltp":8.6,"tv":12.46,"id":10163711}]}]}
{"op":"mcm","clk":"990399518","pt":1580496869330,"mc":[{"id":"1.168133543","rc":[{"batb":[[0,7.4,3],[1,7.2,1.98],[2,5.9,22.8]],"ltp":8.6,"tv":12.46,"id":10163711}]}]}
{"op":"mcm","clk":"990400790","pt":1580496881046,"mc":[{"id":"1.168133543","rc":[{"batb":[[0,7.2,1.98],[1,7,3]],"ltp":8.6,"tv":12.46,"id":10163711}]}]}
{"op":"mcm","clk":"990401784","pt":1580496889563,"mc":[{"id":"1.168133543","rc":[{"batb":[[2,170,1]],"ltp":1000.0,"tv":3.75,"id":13819977}]}]}
{"op":"mcm","clk":"990401952","pt":1580496891051,"mc":[{"id":"1.168133543","rc":[{"batb":[[0,7.2,4.98],[1,5.9,22.8],[2,5.5,18.4]],"ltp":8.6,"tv":12.46,"id":10163711}]}]}
{"op":"mcm","clk":"990403203","pt":1580496901570,"mc":[{"id":"1.168133543","rc":[{"batb":[[0,7.4,3],[1,7.2,1.98],[2,5.9,22.8]],"ltp":8.6,"tv":12.46,"id":10163711}]}]}
{"op":"mcm","clk":"990404855","pt":1580496912958,"mc":[{"id":"1.168133543","rc":[{"batb":[[0,7.2,1.98],[1,7,3]],"ltp":8.6,"tv":12.46,"id":10163711}]}]}
{"op":"mcm","clk":"990406431","pt":1580496925699,"mc":[{"id":"1.168133543","rc":[{"batb":[[0,7.2,4.98],[1,5.9,22.8],[2,5.5,18.4]],"ltp":8.6,"tv":12.46,"id":10163711}]}]}
{"op":"mcm","clk":"990407623","pt":1580496937019,"mc":[{"id":"1.168133543","rc":[{"batb":[[0,7.4,3],[1,7.2,1.98],[2,5.9,22.8]],"ltp":8.6,"tv":12.46,"id":10163711}]}]}
{"op":"mcm","clk":"990408564","pt":1580496945525,"mc":[{"id":"1.168133543","rc":[{"batb":[[0,7.2,1.98],[1,7,3]],"ltp":8.6,"tv":12.46,"id":10163711}]}]}
{"op":"mcm","clk":"990408786","pt":1580496947541,"mc":[{"id":"1.168133543","rc":[{"batb":[[0,8.8,1.98],[1,8.6,1.99]],"ltp":0.0,"tv":0.0,"id":22121325}]}]}
{"op":"mcm","clk":"990409729","pt":1580496956028,"mc":[{"id":"1.168133543","rc":[{"batb":[[0,7.2,4.98],[1,5.9,22.8],[2,5.5,18.4]],"ltp":8.6,"tv":12.46,"id":10163711}]}]}
{"op":"mcm","clk":"990410950","pt":1580496967977,"mc":[{"id":"1.168133543","rc":[{"batb":[[0,7.4,3],[1,7.2,1.98],[2,5.9,22.8]],"ltp":8.6,"tv":12.46,"id":10163711}]}]}
{"op":"mcm","clk":"990412080","pt":1580496979162,"mc":[{"id":"1.168133543","rc":[{"batb":[[0,7.2,1.98],[1,7,3]],"ltp":8.6,"tv":12.46,"id":10163711}]}]}
{"op":"mcm","clk":"990412895","pt":1580496987116,"mc":[{"id":"1.168133543","rc":[{"batb":[[0,7.2,4.98],[1,5.9,22.8],[2,5.5,18.4]],"ltp":8.6,"tv":12.46,"id":10163711}]}]}
{"op":"mcm","clk":"990414034","pt":1580496997953,"mc":[{"id":"1.168133543","rc":[{"batb":[[0,7.4,3],[1,7.2,1.98],[2,5.9,22.8]],"ltp":8.6,"tv":12.46,"id":10163711}]}]}
{"op":"mcm","clk":"990415055","pt":1580497008067,"mc":[{"id":"1.168133543","rc":[{"batb":[[0,7.2,1.98],[1,7,3]],"ltp":8.6,"tv":12.46,"id":10163711}]}]}
{"op":"mcm","clk":"990415426","pt":1580497011985,"mc":[{"id":"1.168133543","rc":[{"batb":[[1,8.2,14.98],[2,8,11.83]],"ltp":0.0,"tv":0.0,"id":22121325}]}]}
{"op":"mcm","clk":"990415911","pt":1580497017302,"mc":[{"id":"1.168133543","rc":[{"batb":[[0,7.2,4.98],[1,5.9,22.8],[2,5.5,18.4]],"ltp":8.6,"tv":12.46,"id":10163711}]}]}
{"op":"mcm","clk":"990416814","pt":1580497026425,"mc":[{"id":"1.168133543","rc":[{"batb":[[0,7.4,3],[1,7.2,1.98],[2,5.9,22.8]],"ltp":8.6,"tv":12.46,"id":10163711}]}]}
{"op":"mcm","clk":"990417871","pt":1580497036218,"mc":[{"id":"1.168133543","rc":[{"batb":[[0,7.2,1.98],[1,7,3]],"ltp":8.6,"tv":12.46,"id":10163711}]}]}
{"op":"mcm","clk":"990418998","pt":1580497046557,"mc":[{"id":"1.168133543","rc":[{"batb":[[0,7.2,4.98],[1,5.9,22.8],[2,5.5,18.4]],"ltp":8.6,"tv":12.46,"id":10163711}]}]}
{"op":"mcm","clk":"990419700","pt":1580497053572,"mc":[{"id":"1.168133543","rc":[{"batb":[[0,7.4,3],[1,7.2,1.98],[2,5.9,22.8]],"ltp":8.6,"tv":12.46,"id":10163711}]}]}
{"op":"mcm","clk":"990420900","pt":1580497064509,"mc":[{"id":"1.168133543","rc":[{"batb":[[0,7.2,1.98],[1,7,3]],"ltp":8.6,"tv":12.46,"id":10163711}]}]}
{"op":"mcm","clk":"990422231","pt":1580497077409,"mc":[{"id":"1.168133543","rc":[{"batb":[[0,7.2,4.98],[1,5.9,22.8],[2,5.5,18.4]],"ltp":8.6,"tv":12.46,"id":10163711}]}]}
{"op":"mcm","clk":"990422363","pt":1580497078919,"mc":[{"id":"1.168133543","rc":[{"batb":[[0,120,1],[1,110,5],[2,90,2]],"ltp":0.0,"tv":0.0,"id":24270700}]}]}
{"op":"mcm","clk":"990423384","pt":1580497088526,"mc":[{"id":"1.168133543","rc":[{"batb":[[0,7.4,3],[1,7.2,1.98],[2,5.9,22.8]],"ltp":8.6,"tv":12.46,"id":10163711}]}]}
{"op":"mcm","clk":"990424229","pt":1580497097367,"mc":[{"id":"1.168133543","rc":[{"batb":[[0,7.2,1.98],[1,7,3]],"ltp":8.6,"tv":12.46,"id":10163711}]}]}
{"op":"mcm","clk":"990425201","pt":1580497107900,"mc":[{"id":"1.168133543","rc":[{"batb":[[0,7.2,4.98],[1,5.9,22.8],[2,5.5,18.4]],"ltp":8.6,"tv":12.46,"id":10163711}]}]}
{"op":"mcm","clk":"990426384","pt":1580497121504,"mc":[{"id":"1.168133543","rc":[{"batb":[[0,7.4,3],[1,7.2,1.98],[2,5.9,22.8]],"ltp":8.6,"tv":12.46,"id":10163711}]}]}
{"op":"mcm","clk":"990427053","pt":1580497128743,"mc":[{"id":"1.168133543","rc":[{"batb":[[0,7.2,1.98],[1,7,3]],"ltp":8.6,"tv":12.46,"id":10163711}]}]}
{"op":"mcm","clk":"990427922","pt":1580497138141,"mc":[{"id":"1.168133543","rc":[{"batb":[[0,7.2,4.98],[1,5.9,22.8],[2,5.5,18.4]],"ltp":8.6,"tv":12.46,"id":10163711},{"batb":[[0,8.4,1.98]],"ltp":0.0,"tv":0.0,"id":22121325}]}]}
{"op":"mcm","clk":"990429167","pt":1580497150574,"mc":[{"id":"1.168133543","rc":[{"batb":[[0,7.4,3],[1,7.2,1.98],[2,5.9,22.8]],"ltp":8.6,"tv":12.46,"id":10163711}]}]}
{"op":"mcm","clk":"990430603","pt":1580497164688,"mc":[{"id":"1.168133543","rc":[{"batb":[[0,7.2,1.98],[1,7,3]],"ltp":8.6,"tv":12.46,"id":10163711}]}]}
{"op":"mcm","clk":"990431791","pt":1580497174941,"mc":[{"id":"1.168133543","rc":[{"batb":[[0,7.2,4.98],[1,5.9,22.8],[2,5.5,18.4]],"ltp":8.6,"tv":12.46,"id":10163711}]}]}
{"op":"mcm","clk":"990431920","pt":1580497176213,"mc":[{"id":"1.168133543","rc":[{"batb":[[0,8.6,1.99],[1,8.4,1.98],[2,8.2,14.98]],"ltp":0.0,"tv":0.0,"id":22121325}]}]}
{"op":"mcm","clk":"990432667","pt":1580497183916,"mc":[{"id":"1.168133543","rc":[{"batb":[[0,7.4,3],[1,7.2,1.98],[2,5.9,22.8]],"ltp":8.6,"tv":12.46,"id":10163711}]}]}
{"op":"mcm","clk":"990433581","pt":1580497192729,"mc":[{"id":"1.168133543","rc":[{"batb":[[0,7.2,1.98],[1,7,3]],"ltp":8.6,"tv":12.46,"id":10163711}]}]}
{"op":"mcm","clk":"990435325","pt":1580497205719,"mc":[{"id":"1.168133543","rc":[{"batb":[[0,7.2,4.98],[1,5.9,22.8],[2,5.5,18.4]],"ltp":8.6,"tv":12.46,"id":10163711}]}]}
{"op":"mcm","clk":"990437568","pt":1580497223381,"mc":[{"id":"1.168133543","rc":[{"batb":[[0,7.4,3],[1,7.2,1.98],[2,5.9,22.8]],"ltp":8.6,"tv":12.46,"id":10163711}]}]}
{"op":"mcm","clk":"990439309","pt":1580497236514,"mc":[{"id":"1.168133543","rc":[{"batb":[[0,7.2,1.98],[1,7,3]],"ltp":8.6,"tv":12.46,"id":10163711}]}]}
{"op":"mcm","clk":"990440511","pt":1580497245440,"mc":[{"id":"1.168133543","rc":[{"batb":[[0,7.2,4.98],[1,5.9,22.8],[2,5.5,18.4]],"ltp":8.6,"tv":12.46,"id":10163711}]}]}
{"op":"mcm","clk":"990441688","pt":1580497254452,"mc":[{"id":"1.168133543","rc":[{"batb":[[0,7.2,5.57]],"ltp":8.6,"tv":12.46,"id":10163711},{"batb":[[0,2.5,1.73],[1,2.48,3],[2,2.46,73.92]],"ltp":2.0,"tv":95.4,"id":10107355}]}]}
{"op":"mcm","clk":"990441928","pt":1580497256473,"mc":[{"id":"1.168133543","rc":[{"batb":[[0,7.4,3.58],[1,7.2,1.98],[2,5.9,22.8]],"ltp":8.6,"tv":12.46,"id":10163711}]}]}
{"op":"mcm","clk":"990442498","pt":1580497261326,"mc":[{"id":"1.168133543","rc":[{"batb":[[0,34,5.14],[2,13.5,10.86]],"ltp":0.0,"tv":0.0,"id":7226819}]}]}
{"op":"mcm","clk":"990442623","pt":1580497262385,"mc":[{"id":"1.168133543","rc":[{"batb":[[2,44,1]],"ltp":0.0,"tv":0.0,"id":27606066}]}]}
{"op":"mcm","clk":"990443283","pt":1580497266486,"mc":[{"id":"1.168133543","rc":[{"batb":[[2,13.5,10.15]],"ltp":0.0,"tv":0.0,"id":7226819},{"batb":[[0,7.2,1.98],[1,7,3]],"ltp":8.6,"tv":12.46,"id":10163711},{"batb":[[2,22,2.74]],"ltp":0.0,"tv":0.0,"id":26548208}]}]}
{"op":"mcm","clk":"990444307","pt":1580497274505,"mc":[{"id":"1.168133543","rc":[{"batb":[[0,8.8,1.98],[1,8.6,1.99]],"ltp":0.0,"tv":0.0,"id":22121325}]}]}
{"op":"mcm","clk":"990444465","pt":1580497275939,"mc":[{"id":"1.168133543","rc":[{"batb":[[0,7.2,4.98],[1,5.9,22.8],[2,5.5,18.4]],"ltp":8.6,"tv":12.46,"id":10163711}]}]}
{"op":"mcm","clk":"990444811","pt":1580497278706,"mc":[{"id":"1.168133543","rc":[{"batb":[[0,7.2,6.35]],"ltp":8.6,"tv":12.46,"id":10163711},{"batb":[[0,8.8,3.1]],"ltp":0.0,"tv":0.0,"id":22121325}]}]}
{"op":"mcm","clk":"990445723","pt":1580497285787,"mc":[{"id":"1.168133543","rc":[{"batb":[[0,7.4,3],[1,7.2,3.35],[2,5.9,22.8]],"ltp":8.6,"tv":12.46,"id":10163711}]}]}
{"op":"mcm","clk":"990449752","pt":1580497316509,"mc":[{"id":"1.168133543","rc":[{"batb":[[1,8.2,14.98],[2,8,11.83]],"ltp":0.0,"tv":0.0,"id":22121325}]}]}
{"op":"mcm","clk":"990463200","pt":1580497415272,"mc":[{"id":"1.168133543","rc":[{"batb":[[0,7.4,4.98],[1,7.2,1.37]],"ltp":8.6,"tv":12.46,"id":10163711},{"batb":[[0,8.8,1.12],[1,8.4,1.98],[2,8.2,14.98]],"ltp":0.0,"tv":0.0,"id":22121325}]}]}
{"op":"mcm","clk":"990472827","pt":1580497483955,"mc":[{"id":"1.168133543","rc":[{"batl":[[0,160,5.2],[1,980,9]],"ltp":0.0,"tv":0.0,"id":26548208},{"batl":[[0,590,5.2],[1,1000,0]],"ltp":0.0,"tv":0.0,"id":27606066},{"batl":[[0,290,5.2],[1,1000,0]],"ltp":0.0,"tv":0.0,"id":24270700},{"batl":[[0,290,5.2],[1,1000,0]],"ltp":22.0,"tv":4.0,"id":13306150}]}]}
{"op":"mcm","clk":"990486680","pt":1580497584799,"mc":[{"id":"1.168133543","rc":[{"batl":[[1,2.86,12],[2,2.94,2.23]],"ltp":2.0,"tv":95.4,"id":10107355}]}]}
{"op":"mcm","clk":"990512461","pt":1580497699398,"mc":[{"id":"1.168133543","rc":[{"batl":[[2,2.96,41.4]],"ltp":2.0,"tv":95.4,"id":10107355}]}]}
{"op":"mcm","clk":"990512622","pt":1580497700499,"mc":[{"id":"1.168133543","rc":[{"batl":[[1,2.84,2.3],[2,2.86,12]],"ltp":2.0,"tv":95.4,"id":10107355}]}]}
{"op":"mcm","clk":"990539381","pt":1580497881462,"mc":[{"id":"1.168133543","rc":[{"trd":[[2.5,3.44]],"batb":[[0,2.48,3.01],[1,2.46,73.92],[2,1.97,90.96]],"ltp":2.5,"tv":98.84,"id":10107355}],"tv":235.0}]}
{"op":"mcm","clk":"990539805","pt":1580497884556,"mc":[{"id":"1.168133543","rc":[{"trd":[[2.46,15.08],[2.48,6],[2.5,3.46]],"batb":[[0,2.46,66.38],[1,2.34,11.07]],"ltp":2.46,"tv":119.94,"id":10107355}],"tv":256.1}]}
{"op":"mcm","clk":"990540957","pt":1580497891459,"mc":[{"id":"1.168133543","rc":[{"batb":[[0,2.46,66.44]],"ltp":2.46,"tv":119.94,"id":10107355}]}]}
{"op":"mcm","clk":"990542567","pt":1580497901992,"mc":[{"id":"1.168133543","rc":[{"batb":[[1,8.4,6.98]],"ltp":0.0,"tv":0.0,"id":22121325}]}]}
{"op":"mcm","clk":"990544212","pt":1580497912773,"mc":[{"id":"1.168133543","rc":[{"batl":[[0,2.58,2],[1,2.6,1.68],[2,2.84,2.3]],"ltp":2.46,"tv":119.94,"id":10107355}]}]}
{"op":"mcm","clk":"990544725","pt":1580497916405,"mc":[{"id":"1.168133543","rc":[{"trd":[[2.46,16.06]],"batb":[[0,2.46,65.95]],"ltp":2.46,"tv":120.92,"id":10107355}],"tv":257.08}]}
{"op":"mcm","clk":"990545482","pt":1580497921525,"mc":[{"id":"1.168133543","rc":[{"batb":[[0,2.46,65.91]],"ltp":2.46,"tv":120.92,"id":10107355}]}]}
{"op":"mcm","clk":"990545776","pt":1580497923309,"mc":[{"id":"1.168133543","rc":[{"trd":[[2.46,16.58]],"batb":[[0,2.46,65.65]],"ltp":2.46,"tv":121.44,"id":10107355}],"tv":257.6}]}
{"op":"mcm","clk":"990546233","pt":1580497926227,"mc":[{"id":"1.168133543","rc":[{"trd":[[2.46,17.1]],"batb":[[0,2.46,65.39]],"ltp":2.46,"tv":121.96,"id":10107355}],"tv":258.12}]}
{"op":"mcm","clk":"990546594","pt":1580497928426,"mc":[{"id":"1.168133543","rc":[{"batl":[[0,2.58,4.54],[2,2.86,12]],"ltp":2.46,"tv":121.96,"id":10107355}]}]}
{"op":"mcm","clk":"990547039","pt":1580497931521,"mc":[{"id":"1.168133543","rc":[{"batb":[[0,2.46,130.73]],"ltp":2.46,"tv":121.96,"id":10107355}]}]}
{"op":"mcm","clk":"990547060","pt":1580497931627,"mc":[{"id":"1.168133543","rc":[{"batb":[[0,2.46,65.34]],"ltp":2.46,"tv":121.96,"id":10107355}]}]}
{"op":"mcm","clk":"990547332","pt":1580497933308,"mc":[{"id":"1.168133543","rc":[{"trd":[[2.46,17.3]],"batb":[[0,2.46,65.24]],"ltp":2.46,"tv":122.16,"id":10107355}],"tv":258.32}]}
{"op":"mcm","clk":"990547804","pt":1580497936243,"mc":[{"id":"1.168133543","rc":[{"trd":[[2.46,17.5]],"batb":[[0,2.46,65.14]],"ltp":2.46,"tv":122.36,"id":10107355}],"tv":258.52}]}
{"op":"mcm","clk":"990548651","pt":1580497941625,"mc":[{"id":"1.168133543","rc":[{"batb":[[0,2.46,65.13]],"ltp":2.46,"tv":122.36,"id":10107355}]}]}
{"op":"mcm","clk":"990553603","pt":1580497973207,"mc":[{"id":"1.168133543","rc":[{"batl":[[0,2.58,2.54]],"ltp":2.46,"tv":122.36,"id":10107355}]}]}
{"op":"mcm","clk":"990556662","pt":1580497993483,"mc":[{"id":"1.168133543","rc":[{"batl":[[0,2.6,1.68],[1,2.84,2.3]],"ltp":2.46,"tv":122.36,"id":10107355}]}]}
{"op":"mcm","clk":"990559687","pt":1580498013311,"mc":[{"id":"1.168133543","rc":[{"batl":[[0,8.2,10],[1,8.4,3.03],[2,8.6,10.89]],"ltp":8.6,"tv":12.46,"id":10163711}]}]}
{"op":"mcm","clk":"990570979","pt":1580498089181,"mc":[{"id":"1.168133543","rc":[{"batl":[[0,2.58,2],[1,2.6,1.68],[2,2.84,2.3]],"ltp":2.46,"tv":122.36,"id":10107355}]}]}
{"op":"mcm","clk":"990595020","pt":1580498242557,"mc":[{"id":"1.168133543","rc":[{"trd":[[2.58,4]],"batb":[[0,2.58,1],[1,2.46,65.13],[2,2.34,11.07]],"batl":[[0,2.6,1.68],[1,2.84,2.3],[2,2.86,12]],"ltp":2.58,"tv":126.36,"id":10107355}],"tv":262.52}]}
{"op":"mcm","clk":"990595062","pt":1580498242837,"mc":[{"id":"1.168133543","rc":[{"trd":[[2.58,6]],"batb":[[0,2.46,65.13],[1,2.34,11.07],[2,1.97,90.96]],"batl":[[0,2.58,8.59],[1,2.6,1.68],[2,2.84,2.3]],"ltp":2.58,"tv":128.36,"id":10107355}],"tv":264.52}]}
{"op":"mcm","clk":"990595563","pt":1580498246262,"mc":[{"id":"1.168133543","rc":[{"batl":[[0,2.58,27.78]],"ltp":2.58,"tv":128.36,"id":10107355}]}]}
{"op":"mcm","clk":"990595868","pt":1580498248462,"mc":[{"id":"1.168133543","rc":[{"batl":[[2,2.86,12]],"ltp":2.58,"tv":128.36,"id":10107355}]}]}
{"op":"mcm","clk":"990596016","pt":1580498249452,"mc":[{"id":"1.168133543","rc":[{"batl":[[0,2.56,2.56],[1,2.58,27.78],[2,2.6,1.68]],"ltp":2.58,"tv":128.36,"id":10107355}]}]}
{"op":"mcm","clk":"990597125","pt":1580498257358,"mc":[{"id":"1.168133543","rc":[{"batb":[[0,2.48,2.08],[1,2.46,65.13],[2,2.34,11.07]],"ltp":2.58,"tv":128.36,"id":10107355}]}]}
{"op":"mcm","clk":"990625812","pt":1580498471249,"mc":[{"id":"1.168133543","rc":[{"batb":[[0,2.48,102.08]],"ltp":2.58,"tv":128.36,"id":10107355}]}]}
{"op":"mcm","clk":"990659176","pt":1580498635847,"mc":[{"id":"1.168133543","rc":[{"trd":[[2.74,18.08],[2.78,5.92]],"batb":[[0,2.74,46.14]],"ltp":2.74,"tv":135.94,"id":12636}],"tv":284.52}]}
{"op":"mcm","clk":"990660450","pt":1580498644262,"mc":[{"id":"1.168133543","rc":[{"batb":[[0,2.74,55.18]],"ltp":2.74,"tv":135.94,"id":12636}]}]}
{"op":"mcm","clk":"990660922","pt":1580498647574,"mc":[{"id":"1.168133543","rc":[{"batb":[[0,2.76,6.2],[1,2.74,55.18],[2,2.72,3.12]],"ltp":2.74,"tv":135.94,"id":12636},{"batb":[[1,15,1.14],[2,14,3.37]],"ltp":0.0,"tv":0.0,"id":22308007},{"batb":[[0,34,5.89]],"ltp":0.0,"tv":0.0,"id":7226819},{"batb":[[0,7.6,2.25],[1,7.4,4.98],[2,7.2,1.37]],"ltp":8.6,"tv":12.46,"id":10163711},{"batb":[[0,2.5,6.85],[1,2.48,102.08],[2,2.46,65.13]],"ltp":2.58,"tv":128.36,"id":10107355},{"batb":[[1,8.6,1.99],[2,8.4,6.98]],"ltp":0.0,"tv":0.0,"id":22121325},{"batb":[[0,46,5.56]],"ltp":0.0,"tv":0.0,"id":26548208}]}]}
{"op":"mcm","clk":"990667209","pt":1580498689550,"mc":[{"id":"1.168133543","rc":[{"batb":[[1,2.74,47.59]],"ltp":2.74,"tv":135.94,"id":12636},{"batb":[[1,7.4,3]],"ltp":8.6,"tv":12.46,"id":10163711},{"batb":[[2,8.4,5]],"ltp":0.0,"tv":0.0,"id":22121325}]}]}
{"op":"mcm","clk":"990667224","pt":1580498689658,"mc":[{"id":"1.168133543","rc":[{"batb":[[0,2.76,13.8]],"ltp":2.74,"tv":135.94,"id":12636},{"batb":[[0,7.6,4.24]],"ltp":8.6,"tv":12.46,"id":10163711},{"batb":[[0,8.8,3.1]],"ltp":0.0,"tv":0.0,"id":22121325}]}]}
{"op":"mcm","clk":"990668851","pt":1580498700167,"mc":[{"id":"1.168133543","rc":[{"batb":[[0,2.52,2.05],[1,2.5,6.85],[2,2.48,100]],"ltp":2.58,"tv":128.36,"id":10107355}]}]}
{"op":"mcm","clk":"990673065","pt":1580498727438,"mc":[{"id":"1.168133543","rc":[{"batl":[[1,8.6,10.89],[2,29,9]],"ltp":8.6,"tv":12.46,"id":10163711}]}]}
{"op":"mcm","clk":"990690741","pt":1580498841536,"mc":[{"id":"1.168133543","rc":[{"trd":[[2.52,4]],"batb":[[0,2.5,6.9],[1,2.48,100],[2,2.46,65.13]],"ltp":2.52,"tv":132.36,"id":10107355}],"tv":288.52}]}
{"op":"mcm","clk":"990690839","pt":1580498842246,"mc":[{"id":"1.168133543","rc":[{"trd":[[2.5,17.15],[2.52,4.1]],"batb":[[0,2.48,100],[1,2.46,65.13],[2,2.34,11.07]],"batl":[[0,2.5,12.05],[1,2.56,21.51],[2,2.58,27.78]],"ltp":2.5,"tv":146.15,"id":10107355}],"tv":302.32}]}
{"op":"mcm","clk":"990691057","pt":1580498843615,"mc":[{"id":"1.168133543","rc":[{"batl":[[0,2.56,21.51],[1,2.58,27.78],[2,2.6,1.68]],"ltp":2.5,"tv":146.15,"id":10107355}]}]}
{"op":"mcm","clk":"990691472","pt":1580498846139,"mc":[{"id":"1.168133543","rc":[{"batl":[[0,2.5,6],[1,2.56,21.51],[2,2.58,27.78]],"ltp":2.5,"tv":146.15,"id":10107355}]}]}
{"op":"mcm","clk":"990692445","pt":1580498852256,"mc":[{"id":"1.168133543","rc":[{"trd":[[2.48,206]],"batb":[[0,2.46,65.13],[1,2.34,11.07],[2,1.97,90.96]],"ltp":2.48,"tv":346.15,"id":10107355}],"tv":502.32}]}
{"op":"mcm","clk":"990692687","pt":1580498853528,"mc":[{"id":"1.168133543","rc":[{"trd":[[2.46,55.41]],"batb":[[0,2.46,46.17]],"ltp":2.46,"tv":384.06,"id":10107355}],"tv":540.22}]}
{"op":"mcm","clk":"990692910","pt":1580498854941,"mc":[{"id":"1.168133543","rc":[{"batb":[[0,2.46,44.46]],"ltp":2.46,"tv":384.06,"id":10107355}]}]}
{"op":"mcm","clk":"990693817","pt":1580498860347,"mc":[{"id":"1.168133543","rc":[{"batb":[[2,2.22,28.76]],"ltp":2.46,"tv":384.06,"id":10107355}]}]}
{"op":"mcm","clk":"990694151","pt":1580498862337,"mc":[{"id":"1.168133543","rc":[{"trd":[[2.46,144.33]],"batb":[[0,2.34,11.07],[1,2.22,28.76],[2,1.97,90.96]],"batl":[[0,2.48,5.76],[1,2.5,6],[2,2.56,21.51]],"ltp":2.46,"tv":472.98,"id":10107355}],"tv":629.14}]}
{"op":"mcm","clk":"990694197","pt":1580498862657,"mc":[{"id":"1.168133543","rc":[{"batb":[[2,1.98,19.91]],"ltp":2.46,"tv":472.98,"id":10107355}]}]}
{"op":"mcm","clk":"990696840","pt":1580498879870,"mc":[{"id":"1.168133543","rc":[{"batl":[[2,2.56,2.56]],"ltp":2.46,"tv":472.98,"id":10107355}]}]}
{"op":"mcm","clk":"990698865","pt":1580498893477,"mc":[{"id":"1.168133543","rc":[{"batb":[[2,2,19.91]],"ltp":2.46,"tv":472.98,"id":10107355}]}]}
{"op":"mcm","clk":"990699578","pt":1580498898520,"mc":[{"id":"1.168133543","rc":[{"batl":[[2,2.58,27.78]],"ltp":2.46,"tv":472.98,"id":10107355}]}]}
{"op":"mcm","clk":"990699745","pt":1580498899513,"mc":[{"id":"1.168133543","rc":[{"batl":[[0,2.46,2.66],[1,2.48,5.76],[2,2.5,6]],"ltp":2.46,"tv":472.98,"id":10107355}]}]}
{"op":"mcm","clk":"990751170","pt":1580499237820,"mc":[{"id":"1.168133543","rc":[{"trd":[[250,4]],"batb":[[0,250,3]],"ltp":250.0,"tv":4.0,"id":27606066}],"tv":633.14}]}
{"op":"mcm","clk":"990752014","pt":1580499244216,"mc":[{"id":"1.168133543","rc":[{"batl":[[0,590,8.2]],"ltp":250.0,"tv":4.0,"id":27606066}]}]}
{"op":"mcm","clk":"990752168","pt":1580499245344,"mc":[{"id":"1.168133543","rc":[{"batb":[[0,140,2],[1,44,1],[2,40,2]],"batl":[[0,590,3.2]],"ltp":250.0,"tv":4.0,"id":27606066}]}]}
{"op":"mcm","clk":"990752307","pt":1580499246329,"mc":[{"id":"1.168133543","rc":[{"batl":[[0,590,2.2]],"ltp":250.0,"tv":4.0,"id":27606066}]}]}
{"op":"mcm","clk":"990752644","pt":1580499248844,"mc":[{"id":"1.168133543","rc":[{"batl":[[0,590,3.2]],"ltp":250.0,"tv":4.0,"id":27606066}]}]}
{"op":"mcm","clk":"990753132","pt":1580499252334,"mc":[{"id":"1.168133543","rc":[{"batl":[[0,200,1],[1,590,2.2]],"ltp":250.0,"tv":4.0,"id":27606066}]}]}
{"op":"mcm","clk":"990754055","pt":1580499259179,"mc":[{"id":"1.168133543","rc":[{"batl":[[1,590,2]],"ltp":250.0,"tv":4.0,"id":27606066}]}]}
{"op":"mcm","clk":"990756010","pt":1580499272482,"mc":[{"id":"1.168133543","rc":[{"batl":[[0,160,9.2]],"ltp":0.0,"tv":0.0,"id":26548208}]}]}
{"op":"mcm","clk":"990756816","pt":1580499277803,"mc":[{"id":"1.168133543","rc":[{"trd":[[110,10]],"batb":[[0,70,2],[1,22,2.74],[2,21,6]],"ltp":110.0,"tv":14.0,"id":13306150}],"tv":643.14}]}
{"op":"mcm","clk":"990757199","pt":1580499280683,"mc":[{"id":"1.168133543","rc":[{"batb":[[1,22,3.48]],"ltp":110.0,"tv":14.0,"id":13306150}]}]}
{"op":"mcm","clk":"990757848","pt":1580499285407,"mc":[{"id":"1.168133543","rc":[{"batl":[[0,280,0.2]],"ltp":110.0,"tv":14.0,"id":13306150}]}]}
{"op":"mcm","clk":"990758031","pt":1580499286887,"mc":[{"id":"1.168133543","rc":[{"batl":[[0,1000,0.2]],"ltp":110.0,"tv":14.0,"id":13306150}]}]}
{"op":"mcm","clk":"990760221","pt":1580499303337,"mc":[{"id":"1.168133543","rc":[{"batb":[[0,2.78,2.52],[1,2.76,13.8],[2,2.74,47.59]],"ltp":2.74,"tv":135.94,"id":12636},{"batb":[[2,14.5,2.86]],"ltp":0.0,"tv":0.0,"id":22308007},{"batb":[[0,36,3.41],[1,34,5],[2,30,3.72]],"ltp":0.0,"tv":0.0,"id":7226819},{"batb":[[0,7.6,6.75]],"ltp":8.6,"tv":12.46,"id":10163711},{"batb":[[0,2.36,2.52],[1,2.34,11.07],[2,2.22,28.76]],"ltp":2.46,"tv":472.98,"id":10107355},{"batb":[[1,8.6,4.51]],"ltp":0.0,"tv":0.0,"id":22121325},{"batb":[[1,44,2.52],[2,42,2.63]],"ltp":0.0,"tv":0.0,"id":26548208},{"batb":[[0,120,2.39]],"ltp":0.0,"tv":0.0,"id":24270700}]}]}
{"op":"mcm","clk":"990766334","pt":1580499344377,"mc":[{"id":"1.168133543","rc":[{"batb":[[1,15,4.17]],"ltp":0.0,"tv":0.0,"id":22308007}]}]}
{"op":"mcm","clk":"990767812","pt":1580499355127,"mc":[{"id":"1.168133543","rc":[{"batb":[[0,2.78,10.11],[1,2.76,6.2]],"ltp":2.74,"tv":135.94,"id":12636}]}]}
{"op":"mcm","clk":"990805871","pt":1580499551748,"mc":[{"id":"1.168133543","rc":[{"batl":[[0,11,3.03],[1,11.5,10]],"ltp":0.0,"tv":0.0,"id":22121325}]}]}
{"op":"mcm","clk":"990818767","pt":1580499636536,"mc":[{"id":"1.168133543","rc":[{"batl":[[0,2.4,1.68],[1,2.46,2.66],[2,2.48,5.76]],"ltp":2.46,"tv":472.98,"id":10107355}]}]}
{"op":"mcm","clk":"990818931","pt":1580499637518,"mc":[{"id":"1.168133543","rc":[{"batl":[[0,2.46,2.66],[1,2.5,6],[2,2.58,27.78]],"ltp":2.46,"tv":472.98,"id":10107355}]}]}
{"op":"mcm","clk":"990828456","pt":1580499697421,"mc":[{"id":"1.168133543","rc":[{"batl":[[0,2.5,6],[1,2.58,27.78],[2,2.6,1.68]],"ltp":2.46,"tv":472.98,"id":10107355}]}]}
{"op":"mcm","clk":"990828613","pt":1580499698435,"mc":[{"id":"1.168133543","rc":[{"batl":[[1,2.56,2.56],[2,2.58,27.78]],"ltp":2.46,"tv":472.98,"id":10107355}]}]}
{"op":"mcm","clk":"990840132","pt":1580499772020,"mc":[{"id":"1.168133543","rc":[{"trd":[[2.36,5.04]],"batb":[[0,2.34,11.07],[1,2.22,28.76],[2,2,19.91]],"batl":[[0,2.36,1.48],[1,2.5,6],[2,2.56,2.56]],"ltp":2.36,"tv":478.02,"id":10107355}],"tv":648.18}]}
{"op":"mcm","clk":"990848579","pt":1580499826481,"mc":[{"id":"1.168133543","rc":[{"batl":[[1,2.48,12],[2,2.5,6]],"ltp":2.36,"tv":478.02,"id":10107355}]}]}
{"op":"mcm","clk":"990848861","pt":1580499828523,"mc":[{"id":"1.168133543","rc":[{"trd":[[2.92,66.44]],"batl":[[0,2.92,9.81]],"ltp":2.92,"tv":156.31,"id":12636},{"trd":[[8.2,7.24]],"batl":[[0,8.2,6.38]],"ltp":8.2,"tv":19.69,"id":10163711},{"trd":[[2.36,8]],"batb":[[0,2.36,2.73],[1,2.34,11.07],[2,2.22,28.76]],"batl":[[0,2.46,5.78]],"ltp":2.36,"tv":480.98,"id":10107355},{"trd":[[11,6.07]],"batl":[[0,11.5,10],[1,14,6.37],[2,65,9]],"ltp":11.0,"tv":6.06,"id":22121325}],"tv":684.82}]}
{"op":"mcm","clk":"990849024","pt":1580499829467,"mc":[{"id":"1.168133543","rc":[{"trd":[[60,0.16],[65,0.74]],"batl":[[0,65,2.66]],"ltp":65.0,"tv":0.9,"id":22308007},{"trd":[[55,0.4],[60,0.16],[65,0.33]],"batl":[[0,65,2.86]],"ltp":65.0,"tv":0.9,"id":7226819},{"trd":[[150,0.36]],"batb":[[0,46,5.66]],"batl":[[0,160,9.02]],"ltp":150.0,"tv":0.36,"id":26548208},{"trd":[[200,0.28]],"batl":[[0,590,2.86],[1,590,0]],"ltp":200.0,"tv":4.28,"id":27606066},{"trd":[[280,0.2]],"batl":[[0,290,5.1]],"ltp":280.0,"tv":0.2,"id":24270700}],"tv":687.48}]}
{"op":"mcm","clk":"990849161","pt":1580499830294,"mc":[{"id":"1.168133543","rc":[{"batb":[[1,7.2,1.37],[2,7,3]],"ltp":8.2,"tv":19.69,"id":10163711}]}]}
{"op":"mcm","clk":"990849494","pt":1580499832481,"mc":[{"id":"1.168133543","rc":[{"batl":[[0,2.44,2.68],[1,2.46,5.78],[2,2.48,12]],"ltp":2.36,"tv":480.98,"id":10107355}]}]}
{"op":"mcm","clk":"990849635","pt":1580499833488,"mc":[{"id":"1.168133543","rc":[{"batl":[[0,210,3.03]],"ltp":65.0,"tv":0.9,"id":22308007},{"batl":[[0,95,3.03]],"ltp":65.0,"tv":0.9,"id":7226819}]}]}
{"op":"mcm","clk":"990849896","pt":1580499835218,"mc":[{"id":"1.168133543","rc":[{"batl":[[0,210,3.23]],"ltp":65.0,"tv":0.9,"id":22308007},{"batl":[[0,95,3.23]],"ltp":65.0,"tv":0.9,"id":7226819}]}]}
{"op":"mcm","clk":"990850002","pt":1580499835917,"mc":[{"id":"1.168133543","rc":[{"batb":[[0,38,1.13],[1,36,3.41],[2,34,5]],"batl":[[0,95,3.71]],"ltp":65.0,"tv":0.9,"id":7226819},{"batb":[[0,48,1.55],[1,46,5],[2,44,2.52]],"ltp":150.0,"tv":0.36,"id":26548208},{"batb":[[0,120,2.72]],"ltp":280.0,"tv":0.2,"id":24270700}]}]}
{"op":"mcm","clk":"990850119","pt":1580499836603,"mc":[{"id":"1.168133543","rc":[{"batb":[[0,70,5],[1,48,2.29],[2,15,4.17]],"ltp":65.0,"tv":0.9,"id":22308007}]}]}
{"op":"mcm","clk":"990852370","pt":1580499851729,"mc":[{"id":"1.168133543","rc":[{"batl":[[0,95,3.77]],"ltp":65.0,"tv":0.9,"id":7226819}]}]}
{"op":"mcm","clk":"990853413","pt":1580499858660,"mc":[{"id":"1.168133543","rc":[{"batb":[[2,15,3.03]],"ltp":65.0,"tv":0.9,"id":22308007}]}]}
{"op":"mcm","clk":"990881890","pt":1580500052323,"mc":[{"id":"1.168133543","rc":[{"batl":[[0,8,1],[1,8.2,6.38],[2,8.6,10.89]],"ltp":8.2,"tv":19.69,"id":10163711}]}]}
{"op":"mcm","clk":"990882022","pt":1580500053229,"mc":[{"id":"1.168133543","rc":[{"batl":[[0,8.2,6.38],[1,8.6,10.89],[2,29,9]],"ltp":8.2,"tv":19.69,"id":10163711}]}]}
{"op":"mcm","clk":"990889733","pt":1580500113749,"mc":[{"id":"1.168133543","rc":[{"batb":[[0,1000,287.12]],"ltp":1000.0,"tv":3.75,"id":13819977}]}]}
{"op":"mcm","clk":"990892991","pt":1580500140136,"mc":[{"id":"1.168133543","rc":[{"trd":[[8.8,6]],"batb":[[0,8.6,4.61],[1,8.4,5],[2,8.2,14.98]],"ltp":8.8,"tv":12.06,"id":22121325}],"tv":693.48}]}
{"op":"mcm","clk":"990930572","pt":1580500387371,"mc":[{"id":"1.168133543","rc":[{"trd":[[2.22,12.39],[2.34,22.14],[2.36,13.46]],"batb":[[0,2.24,6.08],[1,2.22,22.57],[2,2,19.91]],"batl":[[1,2.48,12],[2,2.5,6]],"ltp":2.22,"tv":520.97,"id":10107355}],"tv":733.47}]}
{"op":"mcm","clk":"990931828","pt":1580500399496,"mc":[{"id":"1.168133543","rc":[{"batb":[[0,2.24,15.03]],"ltp":2.22,"tv":520.97,"id":10107355}]}]}
{"op":"mcm","clk":"990932100","pt":1580500402396,"mc":[{"id":"1.168133543","rc":[{"batl":[[0,2.48,12],[1,2.5,6],[2,2.58,27.78]],"ltp":2.22,"tv":520.97,"id":10107355}]}]}
{"op":"mcm","clk":"990932233","pt":1580500403503,"mc":[{"id":"1.168133543","rc":[{"batl":[[0,2.46,2.66],[1,2.48,12],[2,2.5,6]],"ltp":2.22,"tv":520.97,"id":10107355}]}]}
{"op":"mcm","clk":"990932338","pt":1580500404507,"mc":[{"id":"1.168133543","rc":[{"batl":[[0,2.44,2],[1,2.46,2.66],[2,2.48,12]],"ltp":2.22,"tv":520.97,"id":10107355}]}]}
{"op":"mcm","clk":"990964669","pt":1580500710491,"mc":[{"id":"1.168133543","rc":[{"batl":[[0,2.44,2.76]],"ltp":2.22,"tv":520.97,"id":10107355},{"batl":[[0,160,9]],"ltp":150.0,"tv":0.36,"id":26548208}]}]}
{"op":"mcm","clk":"990969506","pt":1580500758545,"mc":[{"id":"1.168133543","rc":[{"batl":[[0,2.44,2]],"ltp":2.22,"tv":520.97,"id":10107355}]}]}
{"op":"mcm","clk":"990969532","pt":1580500758814,"mc":[{"id":"1.168133543","rc":[{"batl":[[0,2.44,2.76]],"ltp":2.22,"tv":520.97,"id":10107355}]}]}
{"op":"mcm","clk":"990976161","pt":1580500820558,"mc":[{"id":"1.168133543","rc":[{"trd":[[2.78,5.93]],"batb":[[1,2.76,6.22]],"ltp":2.92,"tv":156.32,"id":12636},{"batb":[[2,15,3.03]],"batl":[[0,210,3.23]],"ltp":65.0,"tv":0.9,"id":22308007},{"batb":[[1,36,3.41]],"batl":[[0,95,3.77]],"ltp":65.0,"tv":0.9,"id":7226819},{"batb":[[0,7.6,6.76],[1,7.2,1.37]],"ltp":8.2,"tv":19.7,"id":10163711},{"trd":[[2.1,5.3],[2.16,13.9],[2.18,23.22],[2.22,12.39],[2.46,144.31],[2.5,17.16],[3.7,24.36]],"batb":[[1,2.22,22.55],[2,2,19.89]],"batl":[[1,2.46,2.66]],"ltp":2.22,"tv":520.97,"id":10107355},{"trd":[[8.8,6.01],[11,6.06]],"batb":[[0,8.6,4.61]],"ltp":8.8,"tv":12.07,"id":22121325},{"batb":[[0,48,1.55]],"batl":[[0,160,9.2]],"ltp":150.0,"tv":0.36,"id":26548208},{"batb":[[1,22,3.49]],"ltp":110.0,"tv":14.0,"id":13306150}],"tv":733.48}]}
{"op":"mcm","clk":"990979203","pt":1580500848220,"mc":[{"id":"1.168133543","rc":[{"batl":[[0,2.4,12.76],[1,2.44,2],[2,2.46,2.66]],"ltp":2.22,"tv":520.97,"id":10107355}]}]}
{"op":"mcm","clk":"990980049","pt":1580500854023,"mc":[{"id":"1.168133543","rc":[{"batb":[[0,2.24,8.95]],"batl":[[0,2.28,6.03],[1,2.3,200.76],[2,2.4,12]],"ltp":2.22,"tv":520.97,"id":10107355}]}]}
{"op":"mcm","clk":"990980571","pt":1580500858535,"mc":[{"id":"1.168133543","rc":[{"batb":[[2,2.72,3.13]],"ltp":2.92,"tv":156.32,"id":12636},{"batb":[[0,48,2.29],[1,15,3.03],[2,14.5,2.86]],"batl":[[1,220,0]],"ltp":65.0,"tv":0.9,"id":22308007},{"batb":[[2,30,3.72]],"batl":[[1,310,9],[2,310,0]],"ltp":65.0,"tv":0.9,"id":7226819},{"batl":[[1,29,9],[2,29,0]],"ltp":8.2,"tv":19.7,"id":10163711},{"batl":[[1,65,9],[2,640,0.2]],"ltp":8.8,"tv":12.07,"id":22121325},{"batb":[[1,44,2.52],[2,42,2.63]],"batl":[[0,160,4.2]],"ltp":150.0,"tv":0.36,"id":26548208},{"batb":[[1,90,2],[2,70,4]],"batl":[[0,280,0.1]],"ltp":280.0,"tv":0.2,"id":24270700}]}]}
{"op":"mcm","clk":"990980899","pt":1580500861046,"mc":[{"id":"1.168133543","rc":[{"batl":[[0,1000,0.1]],"ltp":280.0,"tv":0.2,"id":24270700}]}]}
{"op":"mcm","clk":"990981137","pt":1580500862528,"mc":[{"id":"1.168133543","rc":[{"batb":[[1,15.5,1.74],[2,15,3.03]],"ltp":65.0,"tv":0.9,"id":22308007},{"batb":[[1,32,3.41]],"ltp":65.0,"tv":0.9,"id":7226819},{"batb":[[0,2.26,2.52],[1,2.24,8.95],[2,2.22,22.55]],"ltp":2.22,"tv":520.97,"id":10107355},{"batb":[[0,120,1.33],[2,75,2.23]],"ltp":280.0,"tv":0.2,"id":24270700}]}]}
{"op":"mcm","clk":"990982944","pt":1580500874859,"mc":[{"id":"1.168133543","rc":[{"batb":[[0,120,1]],"ltp":280.0,"tv":0.2,"id":24270700}]}]}
{"op":"mcm","clk":"990988194","pt":1580500912907,"mc":[{"id":"1.168133543","rc":[{"trd":[[2.24,0.48],[2.26,5.04]],"batb":[[0,2.24,8.71],[1,2.22,22.55],[2,2,19.89]],"batl":[[1,2.3,200]],"ltp":2.24,"tv":526.49,"id":10107355}],"tv":739.0}]}
{"op":"mcm","clk":"990989442","pt":1580500922116,"mc":[{"id":"1.168133543","rc":[{"batb":[[1,15.5,4.26]],"ltp":65.0,"tv":0.9,"id":22308007},{"batb":[[0,2.26,2.52],[1,2.24,8.71],[2,2.22,22.55]],"ltp":2.24,"tv":526.49,"id":10107355}]}]}
{"op":"mcm","clk":"990992569","pt":1580500947455,"mc":[{"id":"1.168133543","rc":[{"batb":[[1,16,3.03],[2,15.5,4.26]],"ltp":65.0,"tv":0.9,"id":22308007}]}]}
{"op":"mcm","clk":"990995558","pt":1580500968286,"mc":[{"id":"1.168133543","rc":[{"batb":[[0,1000,289.42]],"ltp":1000.0,"tv":3.75,"id":13819977},{"trd":[[7.6,4]],"batb":[[0,7.6,4.76]],"ltp":7.6,"tv":23.69,"id":10163711}],"tv":743.0}]}
{"op":"mcm","clk":"990996217","pt":1580500972527,"mc":[{"id":"1.168133543","rc":[{"trd":[[85,0.06]],"batl":[[0,95,3.74]],"ltp":85.0,"tv":0.95,"id":7226819},{"batb":[[0,2.26,11.23],[1,2.22,22.55],[2,2,19.89]],"ltp":2.24,"tv":526.49,"id":10107355},{"trd":[[150,0.38]],"batl":[[0,160,4.19]],"ltp":150.0,"tv":0.38,"id":26548208}],"tv":743.07}]}
{"op":"mcm","clk":"990996995","pt":1580500977544,"mc":[{"id":"1.168133543","rc":[{"batb":[[2,6.4,3.78]],"ltp":7.6,"tv":23.69,"id":10163711}]}]}
{"op":"mcm","clk":"990997606","pt":1580500981932,"mc":[{"id":"1.168133543","rc":[{"batb":[[0,7.6,2.24],[1,7.4,2.52],[2,7.2,1.37]],"ltp":7.6,"tv":23.69,"id":10163711},{"batb":[[0,2.26,8.71],[1,2.24,2.52],[2,2.22,22.55]],"ltp":2.24,"tv":526.49,"id":10107355}]}]}
{"op":"mcm","clk":"991006156","pt":1580501040305,"mc":[{"id":"1.168133543","rc":[{"trd":[[2.28,2.04]],"batl":[[0,2.28,5.01]],"ltp":2.28,"tv":528.53,"id":10107355}],"tv":745.11}]}
{"op":"mcm","clk":"991006452","pt":1580501042087,"mc":[{"id":"1.168133543","rc":[{"trd":[[2.28,7.08]],"batl":[[0,2.28,2.49]],"ltp":2.28,"tv":533.57,"id":10107355}],"tv":750.15}]}
{"op":"mcm","clk":"991013541","pt":1580501088508,"mc":[{"id":"1.168133543","rc":[{"batl":[[2,2.38,2.75]],"ltp":2.28,"tv":533.57,"id":10107355}]}]}
{"op":"mcm","clk":"991015568","pt":1580501101317,"mc":[{"id":"1.168133543","rc":[{"trd":[[2.28,12.06]],"batb":[[0,2.26,8.74]],"batl":[[0,2.3,200],[1,2.38,2.75],[2,2.4,12]],"ltp":2.28,"tv":538.54,"id":10107355}],"tv":755.13}]}
{"op":"mcm","clk":"991017236","pt":1580501112142,"mc":[{"id":"1.168133543","rc":[{"trd":[[2.28,12.12]],"batb":[[0,2.26,8.48]],"ltp":2.28,"tv":538.61,"id":10107355}],"tv":755.2}]}
{"op":"mcm","clk":"991019747","pt":1580501128294,"mc":[{"id":"1.168133543","rc":[{"trd":[[2.92,86.06]],"batb":[[0,2.92,7.31],[1,2.78,10.11],[2,2.76,6.22]],"batl":[[0,2.94,40.64],[1,2.96,52.12],[2,3.5,2]],"ltp":2.92,"tv":175.94,"id":12636},{"batb":[[0,48,2.91]],"ltp":65.0,"tv":0.9,"id":22308007},{"batb":[[0,40,1.25],[1,38,1.13],[2,32,3.41]],"ltp":85.0,"tv":0.95,"id":7226819},{"batb":[[0,7.8,6.41],[1,7.6,2.24],[2,7.4,2.52]],"ltp":7.6,"tv":23.69,"id":10163711},{"trd":[[2.3,43.48]],"batl":[[0,2.3,178.26]],"ltp":2.3,"tv":582.09,"id":10107355},{"trd":[[11.5,8.7]],"batl":[[0,11.5,5.65]],"ltp":11.5,"tv":20.77,"id":22121325},{"batb":[[0,50,1],[1,48,1.55],[2,44,2.52]],"ltp":150.0,"tv":0.38,"id":26548208},{"trd":[[200,0.78]],"batl":[[0,590,2.61]],"ltp":200.0,"tv":4.78,"id":27606066},{"batb":[[0,120,1.31]],"ltp":280.0,"tv":0.2,"id":24270700},{"batb":[[0,70,2.67]],"ltp":110.0,"tv":14.0,"id":13306150}],"tv":827.5}]}
{"op":"mcm","clk":"991021846","pt":1580501142430,"mc":[{"id":"1.168133543","rc":[{"trd":[[70,2.66],[75,1.34]],"batb":[[0,23,1.64],[1,22,2.52]],"ltp":70.0,"tv":18.0,"id":13306150}],"tv":831.5}]}
{"op":"mcm","clk":"991021935","pt":1580501143023,"mc":[{"id":"1.168133543","rc":[{"batb":[[2,2.72,2.52]],"batl":[[1,2.96,50]],"ltp":2.92,"tv":175.94,"id":12636},{"batb":[[2,15.5,2.52]],"ltp":65.0,"tv":0.9,"id":22308007},{"batb":[[0,70,2],[1,22,2.74]],"ltp":70.0,"tv":18.0,"id":13306150}]}]}
{"op":"mcm","clk":"991022607","pt":1580501147513,"mc":[{"id":"1.168133543","rc":[{"batb":[[1,32,3.41],[2,30,3.72]],"ltp":85.0,"tv":0.95,"id":7226819}]}]}
{"op":"mcm","clk":"991023741","pt":1580501155532,"mc":[{"id":"1.168133543","rc":[{"batb":[[1,2.9,6.48],[2,2.78,10.11]],"ltp":2.92,"tv":175.94,"id":12636},{"batb":[[1,22,3.49]],"ltp":70.0,"tv":18.0,"id":13306150}]}]}
{"op":"mcm","clk":"991027659","pt":1580501181436,"mc":[{"id":"1.168133543","rc":[{"trd":[[2.94,77.94]],"batl":[[0,2.94,11.03]],"ltp":2.94,"tv":235.16,"id":12636},{"batb":[[0,80,1.21],[1,48,2.29],[2,16,3.03]],"ltp":65.0,"tv":0.9,"id":22308007},{"batb":[[0,42,1.19],[1,40,1.25],[2,32,3.41]],"ltp":85.0,"tv":0.95,"id":7226819},{"trd":[[8.2,19.36]],"batb":[[0,8,6.25],[1,7.8,6.41],[2,7.6,2.24]],"batl":[[0,29,9.32],[1,29,0]],"ltp":8.2,"tv":35.81,"id":10163711},{"trd":[[2.3,86.96]],"batl":[[0,2.3,156.52]],"ltp":2.3,"tv":625.57,"id":10107355},{"trd":[[11.5,17.4]],"batl":[[0,11.5,1.3]],"ltp":11.5,"tv":29.47,"id":22121325},{"batb":[[0,50,1.91]],"ltp":150.0,"tv":0.38,"id":26548208},{"trd":[[200,1.28]],"batl":[[0,590,2.36]],"ltp":200.0,"tv":5.28,"id":27606066},{"batb":[[0,120,1.61]],"ltp":280.0,"tv":0.2,"id":24270700},{"batb":[[0,70,2.66]],"ltp":70.0,"tv":18.0,"id":13306150}],"tv":955.51}]}
{"op":"mcm","clk":"991027770","pt":1580501182088,"mc":[{"id":"1.168133543","rc":[{"trd":[[8.2,20]],"batl":[[0,29,9]],"ltp":8.2,"tv":36.45,"id":10163711},{"trd":[[11.5,20]],"batl":[[0,65,9.08],[1,640,0.2],[2,640,0]],"ltp":11.5,"tv":32.07,"id":22121325}],"tv":958.75}]}
{"op":"mcm","clk":"991028269","pt":1580501185406,"mc":[{"id":"1.168133543","rc":[{"batl":[[0,29,9.19]],"ltp":8.2,"tv":36.45,"id":10163711},{"batl":[[0,65,9.28],[1,640,0]],"ltp":11.5,"tv":32.07,"id":22121325}]}]}
{"op":"mcm","clk":"991028570","pt":1580501187431,"mc":[{"id":"1.168133543","rc":[{"batb":[[1,44,3.18],[2,42,2.63]],"ltp":150.0,"tv":0.38,"id":26548208}]}]}
{"op":"mcm","clk":"991028670","pt":1580501188227,"mc":[{"id":"1.168133543","rc":[{"batb":[[0,8.8,4.97],[1,8.6,4.51],[2,8.4,5]],"ltp":11.5,"tv":32.07,"id":22121325}]}]}
{"op":"mcm","clk":"991028787","pt":1580501189103,"mc":[{"id":"1.168133543","rc":[{"batb":[[1,70,5],[2,48,2.29]],"ltp":65.0,"tv":0.9,"id":22308007},{"batb":[[2,34,5.89]],"ltp":85.0,"tv":0.95,"id":7226819},{"batb":[[1,46,5.66],[2,44,2.52]],"ltp":150.0,"tv":0.38,"id":26548208},{"batb":[[1,110,5],[2,90,2]],"ltp":280.0,"tv":0.2,"id":24270700}]}]}
{"op":"mcm","clk":"991030322","pt":1580501199228,"mc":[{"id":"1.168133543","rc":[{"batl":[[2,3.25,36.8]],"ltp":2.94,"tv":235.16,"id":12636},{"batl":[[1,220,5]],"ltp":65.0,"tv":0.9,"id":22308007},{"batl":[[1,100,5],[2,310,9]],"ltp":85.0,"tv":0.95,"id":7226819},{"batl":[[0,8.6,10.89],[1,29,9.19]],"ltp":8.2,"tv":36.45,"id":10163711},{"batl":[[0,14,6.37],[1,65,9.28]],"ltp":11.5,"tv":32.07,"id":22121325},{"batl":[[0,160,9.19]],"ltp":150.0,"tv":0.38,"id":26548208},{"batl":[[0,290,5],[1,1000,0.1]],"ltp":280.0,"tv":0.2,"id":24270700}]}]}
{"op":"mcm","clk":"991031092","pt":1580501204441,"mc":[{"id":"1.168133543","rc":[{"batb":[[1,22,2.74]],"ltp":70.0,"tv":18.0,"id":13306150}]}]}
{"op":"mcm","clk":"991031324","pt":1580501206044,"mc":[{"id":"1.168133543","rc":[{"batl":[[1,29,9]],"ltp":8.2,"tv":36.45,"id":10163711},{"batl":[[0,290,5.1],[1,1000,0]],"ltp":280.0,"tv":0.2,"id":24270700}]}]}
{"op":"mcm","clk":"991032522","pt":1580501213571,"mc":[{"id":"1.168133543","rc":[{"trd":[[2.92,96.06]],"batb":[[0,2.92,2.31]],"ltp":2.92,"tv":245.16,"id":12636}],"tv":968.75}]}
{"op":"mcm","clk":"991048731","pt":1580501255477,"mc":[{"id":"1.168133543","rc":[{"batb":[[2,2.78,2.52]],"ltp":2.92,"tv":245.16,"id":12636},{"batb":[[2,7.4,2.78]],"ltp":8.2,"tv":36.45,"id":10163711}]}]}
{"op":"mcm","clk":"991048750","pt":1580501255577,"mc":[{"id":"1.168133543","rc":[{"batb":[[0,2.92,9.9]],"ltp":2.92,"tv":245.16,"id":12636},{"batb":[[0,8,8.23]],"ltp":8.2,"tv":36.45,"id":10163711}]}]}
{"op":"mcm","clk":"991051435","pt":1580501273224,"mc":[{"id":"1.168133543","rc":[{"batb":[[0,22,3.4],[1,21,6],[2,6.6,90]],"ltp":70.0,"tv":18.0,"id":13306150}]}]}
{"op":"mcm","clk":"991051607","pt":1580501274568,"mc":[{"id":"1.168133543","rc":[{"batb":[[0,23,1.63],[1,22,2.52],[2,21,6]],"ltp":70.0,"tv":18.0,"id":13306150}]}]}
{"op":"mcm","clk":"991053412","pt":1580501286675,"mc":[{"id":"1.168133543","rc":[{"batb":[[0,23,3.49]],"ltp":70.0,"tv":18.0,"id":13306150}]}]}
{"op":"mcm","clk":"991069595","pt":1580501394214,"mc":[{"id":"1.168133543","rc":[{"batb":[[0,24,2.42],[1,23,2.83],[2,22,2.52]],"ltp":70.0,"tv":18.0,"id":13306150}]}]}
{"op":"mcm","clk":"991070676","pt":1580501401049,"mc":[{"id":"1.168133543","rc":[{"batb":[[1,22,3.49],[2,21,6]],"ltp":70.0,"tv":18.0,"id":13306150}]}]}
{"op":"mcm","clk":"991093519","pt":1580501542668,"mc":[{"id":"1.168133543","rc":[{"trd":[[2.26,22]],"batb":[[0,2.24,2.52],[1,2.22,22.55],[2,2,19.89]],"batl":[[0,2.26,1.52],[1,2.3,156.52],[2,2.38,2.75]],"ltp":2.26,"tv":642.53,"id":10107355}],"tv":985.71}]}
{"op":"mcm","clk":"991094316","pt":1580501547497,"mc":[{"id":"1.168133543","rc":[{"trd":[[2.24,3.52]],"batb":[[0,2.24,1]],"batl":[[0,2.3,156.52],[1,2.38,2.75],[2,2.4,12]],"ltp":2.24,"tv":645.57,"id":10107355}],"tv":988.75}]}
{"op":"mcm","clk":"991099420","pt":1580501579097,"mc":[{"id":"1.168133543","rc":[{"trd":[[2.3,159.72]],"batl":[[0,2.3,120.14]],"ltp":2.3,"tv":718.33,"id":10107355}],"tv":1061.51}]}
{"op":"mcm","clk":"991100462","pt":1580501585794,"mc":[{"id":"1.168133543","rc":[{"batb":[[0,23,3.38],[1,22,2.52]],"ltp":70.0,"tv":18.0,"id":13306150}]}]}
{"op":"mcm","clk":"991101138","pt":1580501590301,"mc":[{"id":"1.168133543","rc":[{"batb":[[0,24,2.44],[1,23,2.72],[2,22,2.52]],"ltp":70.0,"tv":18.0,"id":13306150}]}]}
{"op":"mcm","clk":"991110306","pt":1580501645528,"mc":[{"id":"1.168133543","rc":[{"batb":[[0,2.28,4.5],[1,2.24,1],[2,2.22,22.55]],"ltp":2.3,"tv":718.33,"id":10107355}]}]}
{"op":"mcm","clk":"991110881","pt":1580501649021,"mc":[{"id":"1.168133543","rc":[{"trd":[[2.3,168.72]],"batb":[[0,2.24,1],[1,2.22,22.55],[2,2,19.89]],"batl":[[0,2.3,115.64]],"ltp":2.3,"tv":727.33,"id":10107355}],"tv":1070.51}]}
{"op":"mcm","clk":"991116127","pt":1580501680519,"mc":[{"id":"1.168133543","rc":[{"batb":[[2,7.4,102.78]],"ltp":8.2,"tv":36.45,"id":10163711}]}]}
{"op":"mcm","clk":"991123889","pt":1580501728395,"mc":[{"id":"1.168133543","rc":[{"batb":[[0,25,2.42],[1,24,1.78],[2,22,3.49]],"ltp":70.0,"tv":18.0,"id":13306150}]}]}
{"op":"mcm","clk":"991126539","pt":1580501744760,"mc":[{"id":"1.168133543","rc":[{"batb":[[1,22,3.49],[2,21,6]],"ltp":70.0,"tv":18.0,"id":13306150}]}]}
{"op":"mcm","clk":"991129287","pt":1580501760892,"mc":[{"id":"1.168133543","rc":[{"batb":[[2,6.6,90]],"ltp":70.0,"tv":18.0,"id":13306150}]}]}
{"op":"mcm","clk":"991139545","pt":1580501824400,"mc":[{"id":"1.168133543","rc":[{"batb":[[0,23,3.38],[1,22,2.52]],"ltp":70.0,"tv":18.0,"id":13306150}]}]}
{"op":"mcm","clk":"991139887","pt":1580501826402,"mc":[{"id":"1.168133543","rc":[{"batl":[[0,2.28,8.4],[1,2.3,115.64],[2,2.38,2.75]],"ltp":2.3,"tv":727.33,"id":10107355}]}]}
{"op":"mcm","clk":"991140179","pt":1580501828235,"mc":[{"id":"1.168133543","rc":[{"batl":[[0,2.26,2.89],[1,2.28,8.4],[2,2.3,115.64]],"ltp":2.3,"tv":727.33,"id":10107355}]}]}
{"op":"mcm","clk":"991140558","pt":1580501830375,"mc":[{"id":"1.168133543","rc":[{"batl":[[0,9.4,2.99],[1,14,6.37],[2,65,9.28]],"ltp":11.5,"tv":32.07,"id":22121325}]}]}
{"op":"mcm","clk":"991140611","pt":1580501830798,"mc":[{"id":"1.168133543","rc":[{"trd":[[2.26,27.78]],"batl":[[0,2.28,8.4],[1,2.3,115.64],[2,2.4,12]],"ltp":2.26,"tv":733.11,"id":10107355},{"trd":[[9.4,5.98]],"batl":[[0,14,6.37],[1,65,9.28],[2,65,0]],"ltp":9.4,"tv":38.05,"id":22121325}],"tv":1082.27}]}
{"op":"mcm","clk":"991141714","pt":1580501836902,"mc":[{"id":"1.168133543","rc":[{"batl":[[0,2.28,27.93]],"ltp":2.26,"tv":733.11,"id":10107355}]}]}
{"op":"mcm","clk":"991142536","pt":1580501841732,"mc":[{"id":"1.168133543","rc":[{"batb":[[0,24,2.44],[1,23,2.72],[2,22,2.52]],"ltp":70.0,"tv":18.0,"id":13306150}]}]}
{"op":"mcm","clk":"991144774","pt":1580501855516,"mc":[{"id":"1.168133543","rc":[{"batl":[[0,12,2.99],[1,14,6.37],[2,65,9.28]],"ltp":9.4,"tv":38.05,"id":22121325}]}]}
{"op":"mcm","clk":"991148222","pt":1580501877305,"mc":[{"id":"1.168133543","rc":[{"trd":[[2.94,100]],"batl":[[0,2.96,50],[1,3.2,2.75]],"ltp":2.94,"tv":267.22,"id":12636},{"batb":[[0,80,1.52]],"ltp":65.0,"tv":0.9,"id":22308007},{"batb":[[0,42,1.83]],"ltp":85.0,"tv":0.95,"id":7226819},{"batb":[[0,8.2,3.41],[1,8,8.23],[2,7.8,6.41]],"ltp":8.2,"tv":36.45,"id":10163711},{"trd":[[2.28,36.64]],"batl":[[0,2.28,15.67]],"ltp":2.28,"tv":757.63,"id":10107355},{"trd":[[12,5.98]],"batl":[[0,14,6.37],[1,65,9.28],[2,65,0]],"ltp":12.0,"tv":44.03,"id":22121325},{"batb":[[0,55,1.37],[1,50,1],[2,46,5.66]],"ltp":150.0,"tv":0.38,"id":26548208},{"trd":[[200,1.56]],"batl":[[0,590,2.22]],"ltp":200.0,"tv":5.56,"id":27606066},{"batb":[[0,120,1.76]],"ltp":280.0,"tv":0.2,"id":24270700},{"batb":[[0,75,1.01],[1,24,1.78],[2,23,2.72]],"ltp":70.0,"tv":18.0,"id":13306150}],"tv":1135.11}]}
{"op":"mcm","clk":"991148469","pt":1580501878799,"mc":[{"id":"1.168133543","rc":[{"batl":[[1,3.25,36.8],[2,3.5,2]],"ltp":2.94,"tv":267.22,"id":12636}]}]}
{"op":"mcm","clk":"991148727","pt":1580501880532,"mc":[{"id":"1.168133543","rc":[{"batb":[[0,130,1.09],[1,120,1],[2,110,5]],"ltp":280.0,"tv":0.2,"id":24270700}]}]}
{"op":"mcm","clk":"991152685","pt":1580501907046,"mc":[{"id":"1.168133543","rc":[{"batb":[[0,8.2,4.85]],"ltp":8.2,"tv":36.45,"id":10163711}]}]}
{"op":"mcm","clk":"991154115","pt":1580501915947,"mc":[{"id":"1.168133543","rc":[{"batb":[[0,8.2,6.84],[1,8,6.25]],"ltp":8.2,"tv":36.45,"id":10163711}]}]}
{"op":"mcm","clk":"991168890","pt":1580502009385,"mc":[{"id":"1.168133543","rc":[{"batb":[[2,2.2,100]],"ltp":2.28,"tv":757.63,"id":10107355}]}]}
{"op":"mcm","clk":"991169248","pt":1580502011489,"mc":[{"id":"1.168133543","rc":[{"batb":[[0,2.24,7.13],[1,2.22,31.18]],"ltp":2.28,"tv":757.63,"id":10107355}]}]}
{"op":"mcm","clk":"991183710","pt":1580502104443,"mc":[{"id":"1.168133543","rc":[{"trd":[[8.2,24]],"batb":[[0,8.2,4.84]],"ltp":8.2,"tv":40.45,"id":10163711}],"tv":1139.11}]}
{"op":"mcm","clk":"991187818","pt":1580502134940,"mc":[{"id":"1.168133543","rc":[{"batb":[[1,8,6.37]],"ltp":8.2,"tv":40.45,"id":10163711},{"batb":[[1,8.6,4.62]],"ltp":12.0,"tv":44.03,"id":22121325}]}]}
{"op":"mcm","clk":"991214663","pt":1580502252118,"mc":[{"id":"1.168133543","rc":[{"batl":[[0,13.5,2],[1,14,6.37],[2,65,9.28]],"ltp":12.0,"tv":44.03,"id":22121325}]}]}
{"op":"mcm","clk":"991227658","pt":1580502344549,"mc":[{"id":"1.168133543","rc":[{"trd":[[2.28,88.64]],"batl":[[0,2.28,10.33]],"ltp":2.28,"tv":809.63,"id":10107355}],"tv":1191.11}]}
{"op":"mcm","clk":"991227737","pt":1580502344972,"mc":[{"id":"1.168133543","rc":[{"batl":[[0,2.28,20.66]],"ltp":2.28,"tv":809.63,"id":10107355}]}]}
{"op":"mcm","clk":"991228749","pt":1580502351763,"mc":[{"id":"1.168133543","rc":[{"batb":[[0,2.26,20],[1,2.24,7.13],[2,2.22,31.18]],"ltp":2.28,"tv":809.63,"id":10107355}]}]}
{"op":"mcm","clk":"991231241","pt":1580502369394,"mc":[{"id":"1.168133543","rc":[{"trd":[[8.8,41.15]],"batb":[[0,8.6,4.62],[1,8.4,5],[2,8.2,14.98]],"batl":[[0,8.8,37.43],[1,13.5,2],[2,14,6.37]],"ltp":8.8,"tv":79.17,"id":22121325}],"tv":1226.25}]}
{"op":"mcm","clk":"991237330","pt":1580502411337,"mc":[{"id":"1.168133543","rc":[{"trd":[[2.96,33.78]],"batl":[[0,2.96,33.11]],"ltp":2.96,"tv":301.0,"id":12636},{"batb":[[0,85,1.43],[1,70,5.62]],"ltp":65.0,"tv":0.9,"id":22308007},{"batb":[[0,46,1.08],[1,42,1.83],[2,40,1.25]],"ltp":85.0,"tv":0.95,"id":7226819},{"batb":[[0,8.4,5.95],[1,8.2,4.84],[2,8,6.37]],"ltp":8.2,"tv":40.45,"id":10163711},{"trd":[[2.28,129.96]],"batb":[[0,2.28,1.27],[1,2.26,20],[2,2.24,7.13]],"batl":[[0,2.3,115.64],[1,2.4,12],[2,2.46,12]],"ltp":2.28,"tv":850.95,"id":10107355},{"trd":[[8.8,52.51]],"batl":[[0,8.8,31.75],[1,14,6.37],[2,65,9.08]],"ltp":8.8,"tv":90.53,"id":22121325},{"batb":[[0,60,1.23],[1,50,1.91]],"ltp":150.0,"tv":0.38,"id":26548208},{"trd":[[200,2]],"batb":[[0,140,2.03]],"batl":[[0,590,2]],"ltp":200.0,"tv":6.0,"id":27606066},{"batb":[[0,160,1.02],[1,120,1.33]],"ltp":280.0,"tv":0.2,"id":24270700},{"batb":[[0,75,1.6]],"ltp":70.0,"tv":18.0,"id":13306150}],"tv":1313.15}]}
{"op":"mcm","clk":"991237921","pt":1580502415439,"mc":[{"id":"1.168133543","rc":[{"batl":[[0,590,2.2]],"ltp":200.0,"tv":6.0,"id":27606066}]}]}
{"op":"mcm","clk":"991238653","pt":1580502420390,"mc":[{"id":"1.168133543","rc":[{"trd":[[190,0.52]],"batb":[[0,130,1.09],[1,120,1]],"batl":[[0,190,2.26],[1,290,5.1]],"ltp":190.0,"tv":0.72,"id":24270700}],"tv":1313.67}]}
{"op":"mcm","clk":"991238928","pt":1580502422365,"mc":[{"id":"1.168133543","rc":[{"batl":[[1,290,5]],"ltp":190.0,"tv":0.72,"id":24270700}]}]}
{"op":"mcm","clk":"991239092","pt":1580502423484,"mc":[{"id":"1.168133543","rc":[{"batl":[[0,290,5],[1,290,0]],"ltp":190.0,"tv":0.72,"id":24270700}]}]}
{"op":"mcm","clk":"991240096","pt":1580502430260,"mc":[{"id":"1.168133543","rc":[{"trd":[[180,0.3]],"batb":[[0,120,1.94],[1,110,5],[2,90,2]],"batl":[[0,180,2.37],[1,290,5.2]],"ltp":180.0,"tv":1.02,"id":24270700}],"tv":1313.97}]}
{"op":"mcm","clk":"991240379","pt":1580502432089,"mc":[{"id":"1.168133543","rc":[{"batl":[[0,290,5.2],[1,290,0]],"ltp":180.0,"tv":1.02,"id":24270700}]}]}
{"op":"mcm","clk":"991241019","pt":1580502436483,"mc":[{"id":"1.168133543","rc":[{"trd":[[2.96,47.04]],"batl":[[0,2.96,26.48]],"ltp":2.96,"tv":314.26,"id":12636},{"trd":[[8.6,17.02]],"batl":[[0,8.6,8.61]],"ltp":8.6,"tv":45.02,"id":10163711}],"tv":1331.79}]}
{"op":"mcm","clk":"991241135","pt":1580502437397,"mc":[{"id":"1.168133543","rc":[{"trd":[[200,0.18]],"batl":[[0,210,3.14]],"ltp":200.0,"tv":1.08,"id":22308007},{"trd":[[85,0.39],[90,0.08]],"batl":[[0,95,3.53]],"ltp":90.0,"tv":1.37,"id":7226819},{"batb":[[0,8.4,7.93],[1,8.2,2.85]],"ltp":8.6,"tv":45.02,"id":10163711},{"batb":[[1,2.26,29.41]],"ltp":2.28,"tv":850.95,"id":10107355},{"trd":[[8.8,52.99]],"batb":[[0,8.6,6.3]],"batl":[[0,8.8,31.51]],"ltp":8.8,"tv":91.01,"id":22121325},{"trd":[[150,0.64]],"batl":[[0,160,9.06]],"ltp":150.0,"tv":0.63,"id":26548208},{"trd":[[580,0.06]],"batl":[[0,590,2.17]],"ltp":580.0,"tv":6.06,"id":27606066},{"trd":[[280,0.34]],"batl":[[0,290,5.13]],"ltp":280.0,"tv":1.15,"id":24270700}],"tv":1333.34}]}
{"op":"mcm","clk":"991241750","pt":1580502441475,"mc":[{"id":"1.168133543","rc":[{"batl":[[0,8.6,10.89]],"ltp":8.6,"tv":45.02,"id":10163711}]}]}
{"op":"mcm","clk":"991242011","pt":1580502443298,"mc":[{"id":"1.168133543","rc":[{"batl":[[0,95,3.73]],"ltp":90.0,"tv":1.37,"id":7226819},{"batl":[[0,160,9]],"ltp":150.0,"tv":0.63,"id":26548208}]}]}
{"op":"mcm","clk":"991243126","pt":1580502450529,"mc":[{"id":"1.168133543","rc":[{"batb":[[0,46,1.16]],"ltp":90.0,"tv":1.37,"id":7226819},{"batl":[[0,160,9.2]],"ltp":150.0,"tv":0.63,"id":26548208}]}]}
{"op":"mcm","clk":"991245157","pt":1580502464236,"mc":[{"id":"1.168133543","rc":[{"trd":[[2.96,80.82]],"batl":[[0,2.96,9.59]],"ltp":2.96,"tv":348.04,"id":12636},{"batb":[[0,95,1.03],[1,80,1.52],[2,70,5]],"ltp":200.0,"tv":1.08,"id":22308007},{"batb":[[0,48,1.04],[1,46,1.16],[2,42,1.83]],"ltp":90.0,"tv":1.37,"id":7226819},{"trd":[[8.6,38.81]],"batl":[[0,29,9],[1,29,0]],"ltp":8.6,"tv":66.8,"id":10163711},{"trd":[[2.3,212.2]],"batl":[[0,2.3,93.9]],"ltp":2.3,"tv":894.43,"id":10107355},{"trd":[[8.8,64.35]],"batl":[[0,8.8,25.83]],"ltp":8.8,"tv":102.37,"id":22121325},{"batb":[[0,65,1.49],[1,55,1.37],[2,50,1]],"ltp":150.0,"tv":0.63,"id":26548208},{"batb":[[0,140,2.26]],"ltp":580.0,"tv":6.06,"id":27606066},{"batb":[[0,130,1.22],[1,120,1],[2,110,5]],"ltp":280.0,"tv":1.15,"id":24270700},{"batb":[[0,85,1.15],[1,75,1.01],[2,24,1.78]],"ltp":70.0,"tv":18.0,"id":13306150}],"tv":1443.74}]}
{"op":"mcm","clk":"991245944","pt":1580502469435,"mc":[{"id":"1.168133543","rc":[{"batb":[[2,23,2.72]],"ltp":70.0,"tv":18.0,"id":13306150}]}]}
{"op":"mcm","clk":"991246293","pt":1580502471536,"mc":[{"id":"1.168133543","rc":[{"batl":[[0,8.6,10.89],[1,29,9.2]],"ltp":8.6,"tv":66.8,"id":10163711}]}]}
{"op":"mcm","clk":"991247129","pt":1580502477478,"mc":[{"id":"1.168133543","rc":[{"batl":[[1,29,9]],"ltp":8.6,"tv":66.8,"id":10163711}]}]}
{"op":"mcm","clk":"991252932","pt":1580502516710,"mc":[{"id":"1.168133543","rc":[{"trd":[[2.96,100]],"batb":[[0,2.92,9.91]],"batl":[[0,3.25,36.8],[1,3.5,2],[2,5.5,6.67]],"ltp":2.96,"tv":367.22,"id":12636},{"batb":[[0,95,1.29]],"ltp":200.0,"tv":1.08,"id":22308007},{"batb":[[0,48,1.61]],"ltp":90.0,"tv":1.37,"id":7226819},{"trd":[[8.6,45.41]],"batl":[[0,8.6,7.59]],"ltp":8.6,"tv":73.4,"id":10163711},{"trd":[[2.3,236.88]],"batl":[[0,2.3,81.56]],"ltp":2.3,"tv":919.11,"id":10107355},{"trd":[[8.8,70.79]],"batl":[[0,8.8,22.61]],"ltp":8.8,"tv":108.81,"id":22121325},{"batb":[[0,70,1.1],[1,60,1.23],[2,50,1.91]],"ltp":150.0,"tv":0.63,"id":26548208},{"batb":[[0,140,2.38]],"ltp":580.0,"tv":6.06,"id":27606066},{"batb":[[0,160,1.04],[1,120,1.33]],"ltp":280.0,"tv":1.15,"id":24270700},{"batb":[[0,85,1.45]],"ltp":70.0,"tv":18.0,"id":13306150}],"tv":1500.64}]}
{"op":"mcm","clk":"991253167","pt":1580502518509,"mc":[{"id":"1.168133543","rc":[{"batl":[[0,95,3.53]],"ltp":90.0,"tv":1.37,"id":7226819}]}]}
{"op":"mcm","clk":"991253601","pt":1580502521591,"mc":[{"id":"1.168133543","rc":[{"batl":[[0,8.6,10.89]],"ltp":8.6,"tv":73.4,"id":10163711}]}]}
{"op":"mcm","clk":"991254909","pt":1580502531219,"mc":[{"id":"1.168133543","rc":[{"batb":[[2,22,3.49]],"ltp":70.0,"tv":18.0,"id":13306150}]}]}
{"op":"mcm","clk":"991274505","pt":1580502675317,"mc":[{"id":"1.168133543","rc":[{"batl":[[0,3.2,7.08],[1,3.25,36.8],[2,3.5,2]],"ltp":2.96,"tv":367.22,"id":12636}]}]}
{"op":"mcm","clk":"991277709","pt":1580502698676,"mc":[{"id":"1.168133543","rc":[{"trd":[[2.3,245.74]],"batl":[[0,2.3,77.13]],"ltp":2.3,"tv":927.97,"id":10107355}],"tv":1509.5}]}
{"op":"mcm","clk":"991287729","pt":1580502768267,"mc":[{"id":"1.168133543","rc":[{"trd":[[2.3,266.8]],"batl":[[0,2.3,66.6]],"ltp":2.3,"tv":949.03,"id":10107355}],"tv":1530.56}]}
{"op":"mcm","clk":"991290449","pt":1580502789070,"mc":[{"id":"1.168133543","rc":[{"trd":[[2.92,121.04],[2.96,100.02]],"batb":[[0,2.9,6.48],[1,2.78,2.52],[2,2.74,47.59]],"ltp":2.92,"tv":392.22,"id":12636},{"trd":[[2.3,292]],"batl":[[0,2.3,54]],"ltp":2.3,"tv":974.23,"id":10107355}],"tv":1580.76}]}
{"op":"mcm","clk":"991293398","pt":1580502811305,"mc":[{"id":"1.168133543","rc":[{"batb":[[0,2.92,1.98],[1,2.9,6.48],[2,2.78,2.52]],"ltp":2.92,"tv":392.22,"id":12636}]}]}
{"op":"mcm","clk":"991293538","pt":1580502812235,"mc":[{"id":"1.168133543","rc":[{"trd":[[2.28,132.5]],"batb":[[0,2.26,29.41],[1,2.24,7.13],[2,2.22,31.18]],"batl":[[0,2.3,54.73],[1,2.4,15.08]],"ltp":2.28,"tv":976.77,"id":10107355}],"tv":1583.3}]}
{"op":"mcm","clk":"991301621","pt":1580502873173,"mc":[{"id":"1.168133543","rc":[{"batl":[[1,2.4,27.08],[2,2.58,27.76]],"ltp":2.28,"tv":976.77,"id":10107355}]}]}
{"op":"mcm","clk":"991303079","pt":1580502883285,"mc":[{"id":"1.168133543","rc":[{"batl":[[0,2.94,50],[1,3.2,7.08],[2,3.25,36.8]],"ltp":2.92,"tv":392.22,"id":12636}]}]}
{"op":"mcm","clk":"991303348","pt":1580502885292,"mc":[{"id":"1.168133543","rc":[{"batl":[[1,2.4,24]],"ltp":2.28,"tv":976.77,"id":10107355}]}]}
{"op":"mcm","clk":"991303631","pt":1580502887251,"mc":[{"id":"1.168133543","rc":[{"trd":[[2.94,134]],"batl":[[0,2.94,33]],"ltp":2.94,"tv":426.22,"id":12636},{"batb":[[0,100,1.17],[1,85,1.43],[2,70,5.62]],"ltp":200.0,"tv":1.08,"id":22308007},{"batb":[[0,50,1.48],[1,48,1.04],[2,46,1.16]],"ltp":90.0,"tv":1.37,"id":7226819},{"trd":[[8.6,57.03]],"batl":[[0,8.6,5.08]],"ltp":8.6,"tv":85.02,"id":10163711},{"trd":[[2.28,133.96],[2.3,334.02]],"batl":[[0,2.3,32.99]],"ltp":2.3,"tv":1020.25,"id":10107355},{"trd":[[8.8,82.17]],"batl":[[0,8.8,16.92]],"ltp":8.8,"tv":120.19,"id":22121325},{"batb":[[0,75,1],[1,65,1.49],[2,55,1.37]],"ltp":150.0,"tv":0.63,"id":26548208},{"batb":[[0,140,2.59]],"ltp":580.0,"tv":6.06,"id":27606066},{"batb":[[0,160,1.29]],"ltp":280.0,"tv":1.15,"id":24270700},{"batb":[[0,90,1.36],[1,75,1.6]],"ltp":70.0,"tv":18.0,"id":13306150}],"tv":1683.78}]}
{"op":"mcm","clk":"991303698","pt":1580502887777,"mc":[{"id":"1.168133543","rc":[{"batl":[[1,3.2,5.08]],"ltp":2.94,"tv":426.22,"id":12636}]}]}
{"op":"mcm","clk":"991303882","pt":1580502889211,"mc":[{"id":"1.168133543","rc":[{"trd":[[8.8,88.23]],"batl":[[0,8.8,13.89]],"ltp":8.8,"tv":126.25,"id":22121325}],"tv":1689.84}]}
{"op":"mcm","clk":"991304354","pt":1580502892829,"mc":[{"id":"1.168133543","rc":[{"batl":[[0,8.6,10.89]],"ltp":8.6,"tv":85.02,"id":10163711}]}]}
{"op":"mcm","clk":"991305985","pt":1580502903331,"mc":[{"id":"1.168133543","rc":[{"batb":[[2,46,1.08]],"ltp":90.0,"tv":1.37,"id":7226819}]}]}
{"op":"mcm","clk":"991306129","pt":1580502904334,"mc":[{"id":"1.168133543","rc":[{"batb":[[0,50,1.56]],"ltp":90.0,"tv":1.37,"id":7226819}]}]}
{"op":"mcm","clk":"991306314","pt":1580502905443,"mc":[{"id":"1.168133543","rc":[{"trd":[[8.6,62.19]],"batl":[[0,8.6,8.31]],"ltp":8.6,"tv":90.18,"id":10163711},{"trd":[[2.3,353.27]],"batl":[[0,2.3,23.36]],"ltp":2.3,"tv":1039.5,"id":10107355},{"trd":[[8.8,93.27]],"batl":[[0,8.8,11.37]],"ltp":8.8,"tv":131.29,"id":22121325}],"tv":1719.3}]}
{"op":"mcm","clk":"991306404","pt":1580502905823,"mc":[{"id":"1.168133543","rc":[{"trd":[[200,0.4]],"batl":[[0,210,3.03]],"ltp":200.0,"tv":1.3,"id":22308007},{"trd":[[90,0.59]],"batl":[[0,95,3.27]],"ltp":90.0,"tv":1.88,"id":7226819},{"trd":[[150,0.92]],"batl":[[0,160,9.06]],"ltp":150.0,"tv":0.92,"id":26548208},{"trd":[[580,0.13]],"batl":[[0,590,2.14]],"ltp":580.0,"tv":6.12,"id":27606066},{"trd":[[280,0.5]],"batl":[[0,290,5.05]],"ltp":280.0,"tv":1.32,"id":24270700}],"tv":1720.53}]}
{"op":"mcm","clk":"991307314","pt":1580502912534,"mc":[{"id":"1.168133543","rc":[{"batl":[[0,160,9]],"ltp":150.0,"tv":0.92,"id":26548208},{"batl":[[0,290,5]],"ltp":280.0,"tv":1.32,"id":24270700}]}]}
{"op":"mcm","clk":"991307354","pt":1580502912843,"mc":[{"id":"1.168133543","rc":[{"batl":[[0,8.6,9.22]],"ltp":8.6,"tv":90.18,"id":10163711},{"batb":[[2,22,2.74]],"ltp":70.0,"tv":18.0,"id":13306150}]}]}
{"op":"mcm","clk":"991308183","pt":1580502918873,"mc":[{"id":"1.168133543","rc":[{"batl":[[0,160,9.2]],"ltp":150.0,"tv":0.92,"id":26548208}]}]}
{"op":"mcm","clk":"991311284","pt":1580502940529,"mc":[{"id":"1.168133543","rc":[{"trd":[[2.94,168.02]],"batl":[[0,2.94,15.99]],"ltp":2.94,"tv":460.24,"id":12636},{"batb":[[0,110,1.06],[1,95,1.03],[2,80,1.52]],"ltp":200.0,"tv":1.3,"id":22308007},{"batb":[[0,55,1.74],[1,48,1.69]],"ltp":90.0,"tv":1.88,"id":7226819},{"trd":[[8.6,73.83]],"batl":[[0,8.6,3.4]],"ltp":8.6,"tv":101.82,"id":10163711},{"trd":[[2.3,399.99]],"batl":[[0,2.4,24],[1,2.58,27.76],[2,2.8,18.93]],"ltp":2.3,"tv":1086.22,"id":10107355},{"trd":[[8.8,104.63]],"batl":[[0,8.8,5.69]],"ltp":8.8,"tv":142.65,"id":22121325},{"batb":[[0,80,1.21],[1,70,1.1],[2,60,1.23]],"ltp":150.0,"tv":0.92,"id":26548208},{"batb":[[0,140,2.79]],"ltp":580.0,"tv":6.12,"id":27606066},{"batb":[[0,170,1.22],[1,120,1.64]],"ltp":280.0,"tv":1.32,"id":24270700},{"batb":[[0,95,1.25],[1,85,1.15],[2,75,1.01]],"ltp":70.0,"tv":18.0,"id":13306150}],"tv":1824.27}]}
{"op":"mcm","clk":"991311298","pt":1580502940638,"mc":[{"id":"1.168133543","rc":[{"batl":[[1,2.56,3],[2,2.58,27.76]],"ltp":2.3,"tv":1086.22,"id":10107355}]}]}
{"op":"mcm","clk":"991311529","pt":1580502942223,"mc":[{"id":"1.168133543","rc":[{"batl":[[1,2.58,27.76],[2,2.8,18.93]],"ltp":2.3,"tv":1086.22,"id":10107355}]}]}
{"op":"mcm","clk":"991311673","pt":1580502943230,"mc":[{"id":"1.168133543","rc":[{"batb":[[1,48,1.61]],"ltp":90.0,"tv":1.88,"id":7226819},{"batl":[[0,8.6,5]],"ltp":8.6,"tv":101.82,"id":10163711}]}]}
{"op":"mcm","clk":"991311854","pt":1580502944446,"mc":[{"id":"1.168133543","rc":[{"batb":[[0,60,1.27],[1,50,1.48],[2,48,1.04]],"ltp":90.0,"tv":1.88,"id":7226819}]}]}
{"op":"mcm","clk":"991313547","pt":1580502955867,"mc":[{"id":"1.168133543","rc":[{"batl":[[2,510,9]],"ltp":90.0,"tv":1.88,"id":7226819}]}]}
{"op":"mcm","clk":"991314962","pt":1580502965482,"mc":[{"id":"1.168133543","rc":[{"batb":[[0,2.26,38.54]],"batl":[[1,2.56,8.07],[2,2.58,27.76]],"ltp":2.3,"tv":1086.22,"id":10107355}]}]}
{"op":"mcm","clk":"991315072","pt":1580502966188,"mc":[{"id":"1.168133543","rc":[{"trd":[[8.8,110.69]],"batl":[[0,8.8,2.66]],"ltp":8.8,"tv":148.71,"id":22121325}],"tv":1830.33}]}
{"op":"mcm","clk":"991317749","pt":1580502984498,"mc":[{"id":"1.168133543","rc":[{"trd":[[2.9,12.04],[2.92,125]],"batb":[[0,2.78,2.98],[1,2.74,47.59],[2,2.72,2.52]],"ltp":2.9,"tv":476.24,"id":12636}],"tv":1846.33}]}
{"op":"mcm","clk":"991319034","pt":1580502993539,"mc":[{"id":"1.168133543","rc":[{"trd":[[2.94,183.96]],"batl":[[0,2.94,8.02]],"ltp":2.94,"tv":492.18,"id":12636},{"batb":[[0,110,1.23]],"ltp":200.0,"tv":1.3,"id":22308007},{"batb":[[0,60,1.63]],"ltp":90.0,"tv":1.88,"id":7226819},{"trd":[[8.6,79.27]],"batl":[[0,8.6,2.28]],"ltp":8.6,"tv":107.26,"id":10163711},{"trd":[[2.4,19.54]],"batl":[[0,2.4,14.23]],"ltp":2.4,"tv":1105.76,"id":10107355},{"trd":[[8.8,116.01]],"batl":[[0,14,6.37],[1,16.5,1.94]],"ltp":8.8,"tv":154.03,"id":22121325},{"batb":[[0,80,1.47]],"ltp":150.0,"tv":0.92,"id":26548208},{"batb":[[0,140,2.88]],"ltp":580.0,"tv":6.12,"id":27606066},{"batb":[[0,180,1.03],[1,120,1.94]],"ltp":280.0,"tv":1.32,"id":24270700},{"batb":[[0,100,1.15],[1,85,1.45]],"ltp":70.0,"tv":18.0,"id":13306150}],"tv":1892.57}]}
{"op":"mcm","clk":"991319054","pt":1580502993644,"mc":[{"id":"1.168133543","rc":[{"batl":[[1,29,9.18]],"ltp":8.6,"tv":107.26,"id":10163711}]}]}
{"op":"mcm","clk":"991319301","pt":1580502995352,"mc":[{"id":"1.168133543","rc":[{"batl":[[0,160,9]],"ltp":150.0,"tv":0.92,"id":26548208}]}]}
{"op":"mcm","clk":"991320120","pt":1580503001125,"mc":[{"id":"1.168133543","rc":[{"batl":[[1,2.96,50],[2,3.2,5.08]],"ltp":2.94,"tv":492.18,"id":12636}]}]}
{"op":"mcm","clk":"991320281","pt":1580503002348,"mc":[{"id":"1.168133543","rc":[{"batb":[[0,2.78,7.93]],"ltp":2.94,"tv":492.18,"id":12636},{"batl":[[0,13.5,3.17],[1,14,6.37],[2,16.5,1.94]],"ltp":8.8,"tv":154.03,"id":22121325}]}]}
{"op":"mcm","clk":"991320380","pt":1580503003046,"mc":[{"id":"1.168133543","rc":[{"batl":[[0,8.6,5]],"ltp":8.6,"tv":107.26,"id":10163711}]}]}
{"op":"mcm","clk":"991322705","pt":1580503019556,"mc":[{"id":"1.168133543","rc":[{"batl":[[0,13,3.36],[1,13.5,3.17],[2,14,6.37]],"ltp":8.8,"tv":154.03,"id":22121325}]}]}
{"op":"mcm","clk":"991322802","pt":1580503020158,"mc":[{"id":"1.168133543","rc":[{"batl":[[0,13,4.89]],"ltp":8.8,"tv":154.03,"id":22121325}]}]}
{"op":"mcm","clk":"991322994","pt":1580503021459,"mc":[{"id":"1.168133543","rc":[{"batl":[[1,14,6.37],[2,16.5,1.94]],"ltp":8.8,"tv":154.03,"id":22121325}]}]}
{"op":"mcm","clk":"991323040","pt":1580503021722,"mc":[{"id":"1.168133543","rc":[{"batl":[[0,12.5,3.43],[1,13,4.89],[2,14,6.37]],"ltp":8.8,"tv":154.03,"id":22121325}]}]}
{"op":"mcm","clk":"991324867","pt":1580503034280,"mc":[{"id":"1.168133543","rc":[{"batb":[[0,2.8,11.77],[1,2.78,7.47],[2,2.74,47.59]],"ltp":2.94,"tv":492.18,"id":12636},{"batb":[[0,60,2.61]],"ltp":90.0,"tv":1.88,"id":7226819},{"trd":[[8.6,89.27]],"batl":[[0,29,9.18],[1,29,0]],"ltp":8.6,"tv":117.26,"id":10163711},{"batb":[[0,2.28,13.89],[1,2.26,38.54],[2,2.24,7.13]],"ltp":2.4,"tv":1105.76,"id":10107355},{"batb":[[0,8.8,3.6],[1,8.6,6.3],[2,8.4,5]],"ltp":8.8,"tv":154.03,"id":22121325}],"tv":1902.57}]}
{"op":"mcm","clk":"991325158","pt":1580503036494,"mc":[{"id":"1.168133543","rc":[{"batl":[[1,1000,0.19]],"ltp":8.6,"tv":117.26,"id":10163711}]}]}
{"op":"mcm","clk":"991325206","pt":1580503036763,"mc":[{"id":"1.168133543","rc":[{"batl":[[0,29,9.37],[1,1000,0]],"ltp":8.6,"tv":117.26,"id":10163711}]}]}
{"op":"mcm","clk":"991325606","pt":1580503039578,"mc":[{"id":"1.168133543","rc":[{"batb":[[1,50,1.5]],"ltp":90.0,"tv":1.88,"id":7226819}]}]}
{"op":"mcm","clk":"991338700","pt":1580503065116,"mc":[{"id":"1.168133543","rc":[{"batl":[[0,2.94,58.02]],"ltp":2.94,"tv":492.18,"id":12636}]}]}
{"op":"mcm","clk":"991339954","pt":1580503074284,"mc":[{"id":"1.168133543","rc":[{"batl":[[0,28,3.4],[1,29,9]],"ltp":8.6,"tv":117.26,"id":10163711},{"batl":[[0,12,3.03],[1,12.5,3.43]],"ltp":8.8,"tv":154.03,"id":22121325}]}]}
{"op":"mcm","clk":"991340665","pt":1580503079473,"mc":[{"id":"1.168133543","rc":[{"batl":[[1,14,6.37],[2,16.5,1.94]],"ltp":8.8,"tv":154.03,"id":22121325}]}]}
{"op":"mcm","clk":"991340735","pt":1580503079901,"mc":[{"id":"1.168133543","rc":[{"batl":[[0,11.5,3.73],[1,12,3.03],[2,14,6.37]],"ltp":8.8,"tv":154.03,"id":22121325}]}]}
{"op":"mcm","clk":"991343088","pt":1580503095700,"mc":[{"id":"1.168133543","rc":[{"batl":[[2,2.98,50]],"ltp":2.94,"tv":492.18,"id":12636}]}]}
{"op":"mcm","clk":"991343571","pt":1580503099098,"mc":[{"id":"1.168133543","rc":[{"batb":[[0,2.8,16.72],[1,2.78,2.52]],"ltp":2.94,"tv":492.18,"id":12636},{"batb":[[0,2.28,23.3],[1,2.26,29.13]],"ltp":2.4,"tv":1105.76,"id":10107355},{"batb":[[0,9,1.68],[1,8.8,3.6],[2,8.6,4.62]],"ltp":8.8,"tv":154.03,"id":22121325}]}]}
{"op":"mcm","clk":"991344432","pt":1580503105345,"mc":[{"id":"1.168133543","rc":[{"batb":[[1,8.8,3.71],[2,8.6,4.51]],"ltp":8.8,"tv":154.03,"id":22121325}]}]}
{"op":"mcm","clk":"991347922","pt":1580503129466,"mc":[{"id":"1.168133543","rc":[{"batl":[[0,11,3.03],[1,11.5,3.73]],"ltp":8.8,"tv":154.03,"id":22121325}]}]}
{"op":"mcm","clk":"991349164","pt":1580503138212,"mc":[{"id":"1.168133543","rc":[{"batl":[[0,10.5,4.08],[1,11,3.03]],"ltp":8.8,"tv":154.03,"id":22121325}]}]}
{"op":"mcm","clk":"991353841","pt":1580503170057,"mc":[{"id":"1.168133543","rc":[{"batl":[[0,10,3.03],[1,10.5,4.08]],"ltp":8.8,"tv":154.03,"id":22121325}]}]}
{"op":"mcm","clk":"991354771","pt":1580503177180,"mc":[{"id":"1.168133543","rc":[{"batl":[[1,14,6.37],[2,16.5,1.94]],"ltp":8.8,"tv":154.03,"id":22121325}]}]}
{"op":"mcm","clk":"991354833","pt":1580503177603,"mc":[{"id":"1.168133543","rc":[{"batl":[[0,9.8,4.38],[1,10,3.03],[2,14,6.37]],"ltp":8.8,"tv":154.03,"id":22121325}]}]}
{"op":"mcm","clk":"991359753","pt":1580503214437,"mc":[{"id":"1.168133543","rc":[{"batl":[[0,9.6,3.03],[1,9.8,4.38]],"ltp":8.8,"tv":154.03,"id":22121325}]}]}
{"op":"mcm","clk":"991360059","pt":1580503216519,"mc":[{"id":"1.168133543","rc":[{"batl":[[0,9.4,4.56],[1,9.6,3.03]],"ltp":8.8,"tv":154.03,"id":22121325}]}]}
{"op":"mcm","clk":"991362520","pt":1580503237849,"mc":[{"id":"1.168133543","rc":[{"trd":[[2.28,137.32]],"batb":[[0,2.28,21.62]],"ltp":2.28,"tv":1109.12,"id":10107355}],"tv":1905.93}]}
{"op":"mcm","clk":"991364470","pt":1580503253989,"mc":[{"id":"1.168133543","rc":[{"batl":[[1,9.6,2.08]],"ltp":8.8,"tv":154.03,"id":22121325}]}]}
{"op":"mcm","clk":"991368684","pt":1580503288518,"mc":[{"id":"1.168133543","rc":[{"batl":[[1,14,6.37],[2,16.5,1.94]],"ltp":8.8,"tv":154.03,"id":22121325}]}]}
{"op":"mcm","clk":"991368792","pt":1580503289491,"mc":[{"id":"1.168133543","rc":[{"batl":[[0,9.2,2.17],[1,9.4,4.56],[2,14,6.37]],"ltp":8.8,"tv":154.03,"id":22121325}]}]}
{"op":"mcm","clk":"991369319","pt":1580503294011,"mc":[{"id":"1.168133543","rc":[{"trd":[[9,3.36]],"batb":[[0,8.8,3.71],[1,8.6,4.51],[2,8.4,5]],"batl":[[0,9,3.08],[1,9.2,2.17]],"ltp":9.0,"tv":157.39,"id":22121325}],"tv":1909.29}]}
{"op":"mcm","clk":"991369697","pt":1580503297423,"mc":[{"id":"1.168133543","rc":[{"batl":[[1,14,6.37],[2,16.5,1.94]],"ltp":9.0,"tv":157.39,"id":22121325}]}]}
{"op":"mcm","clk":"991369732","pt":1580503297691,"mc":[{"id":"1.168133543","rc":[{"batl":[[1,10,2],[2,14,6.37]],"ltp":9.0,"tv":157.39,"id":22121325}]}]}
{"op":"mcm","clk":"991371737","pt":1580503314479,"mc":[{"id":"1.168133543","rc":[{"batl":[[0,9.8,2.83]],"ltp":9.0,"tv":157.39,"id":22121325}]}]}
{"op":"mcm","clk":"991373040","pt":1580503325564,"mc":[{"id":"1.168133543","rc":[{"batl":[[1,14,6.37],[2,16.5,1.94]],"ltp":9.0,"tv":157.39,"id":22121325}]}]}
{"op":"mcm","clk":"991373167","pt":1580503326475,"mc":[{"id":"1.168133543","rc":[{"batl":[[1,13.5,1.48],[2,14,6.37]],"ltp":9.0,"tv":157.39,"id":22121325}]}]}
{"op":"mcm","clk":"991373181","pt":1580503326575,"mc":[{"id":"1.168133543","rc":[{"batl":[[1,13.5,2.72]],"ltp":9.0,"tv":157.39,"id":22121325}]}]}
{"op":"mcm","clk":"991373941","pt":1580503333308,"mc":[{"id":"1.168133543","rc":[{"batl":[[0,13,3.29]],"ltp":9.0,"tv":157.39,"id":22121325}]}]}
{"op":"mcm","clk":"991377860","pt":1580503364571,"mc":[{"id":"1.168133543","rc":[{"batl":[[0,12.5,3.1],[1,13,3.29]],"ltp":9.0,"tv":157.39,"id":22121325}]}]}
{"op":"mcm","clk":"991378813","pt":1580503372571,"mc":[{"id":"1.168133543","rc":[{"batl":[[0,12,2.31],[1,12.5,3.1]],"ltp":9.0,"tv":157.39,"id":22121325}]}]}
{"op":"mcm","clk":"991380062","pt":1580503383609,"mc":[{"id":"1.168133543","rc":[{"batb":[[0,9,1.98],[1,8.8,3.71],[2,8.6,4.51]],"ltp":9.0,"tv":157.39,"id":22121325}]}]}
{"op":"mcm","clk":"991384082","pt":1580503417140,"mc":[{"id":"1.168133543","rc":[{"batl":[[1,13.5,3.03]],"ltp":9.0,"tv":157.39,"id":22121325}]}]}
{"op":"mcm","clk":"991385857","pt":1580503431352,"mc":[{"id":"1.168133543","rc":[{"batl":[[0,13.5,3.03],[1,14,6.37],[2,16.5,1.94]],"ltp":9.0,"tv":157.39,"id":22121325}]}]}
{"op":"mcm","clk":"991385899","pt":1580503431632,"mc":[{"id":"1.168133543","rc":[{"batl":[[0,13,3.29],[1,13.5,3.03],[2,14,6.37]],"ltp":9.0,"tv":157.39,"id":22121325}]}]}
{"op":"mcm","clk":"991389275","pt":1580503457481,"mc":[{"id":"1.168133543","rc":[{"batl":[[0,12.5,3.03],[1,13,3.29]],"ltp":9.0,"tv":157.39,"id":22121325}]}]}
{"op":"mcm","clk":"991390124","pt":1580503463816,"mc":[{"id":"1.168133543","rc":[{"batl":[[0,27,2.19],[1,28,3.21],[2,29,9]],"ltp":8.6,"tv":117.26,"id":10163711},{"batl":[[0,12,2],[1,12.5,3.03],[2,13,3.29]],"ltp":9.0,"tv":157.39,"id":22121325}]}]}
{"op":"mcm","clk":"991391083","pt":1580503471234,"mc":[{"id":"1.168133543","rc":[{"batl":[[0,26,1.84],[1,27,2],[2,28,3.21]],"ltp":8.6,"tv":117.26,"id":10163711},{"batl":[[0,11.5,3.72],[1,12,2],[2,12.5,3.03]],"ltp":9.0,"tv":157.39,"id":22121325}]}]}
{"op":"mcm","clk":"991394847","pt":1580503502537,"mc":[{"id":"1.168133543","rc":[{"batl":[[0,26,4.87],[2,29,9.18]],"ltp":8.6,"tv":117.26,"id":10163711},{"batl":[[0,11,3.03],[1,11.5,3.72],[2,12,2]],"ltp":9.0,"tv":157.39,"id":22121325}]}]}
{"op":"mcm","clk":"991395530","pt":1580503507388,"mc":[{"id":"1.168133543","rc":[{"batl":[[0,26,5.07],[2,29,9]],"ltp":8.6,"tv":117.26,"id":10163711}]}]}
{"op":"mcm","clk":"991395736","pt":1580503509426,"mc":[{"id":"1.168133543","rc":[{"batl":[[1,12,2],[2,14,6.37]],"ltp":9.0,"tv":157.39,"id":22121325}]}]}
{"op":"mcm","clk":"991395778","pt":1580503509798,"mc":[{"id":"1.168133543","rc":[{"batl":[[0,10.5,2.65],[1,11,3.03],[2,12,2]],"ltp":9.0,"tv":157.39,"id":22121325}]}]}
{"op":"mcm","clk":"991396553","pt":1580503516305,"mc":[{"id":"1.168133543","rc":[{"batl":[[0,25,2.39],[1,26,4.68]],"ltp":8.6,"tv":117.26,"id":10163711},{"batl":[[2,14,6.37]],"ltp":9.0,"tv":157.39,"id":22121325}]}]}
{"op":"mcm","clk":"991398137","pt":1580503529557,"mc":[{"id":"1.168133543","rc":[{"batl":[[0,24,1.97],[1,25,2.2],[2,26,3.03]],"ltp":8.6,"tv":117.26,"id":10163711}]}]}
{"op":"mcm","clk":"991402297","pt":1580503562451,"mc":[{"id":"1.168133543","rc":[{"batl":[[0,24,5],[2,29,9]],"ltp":8.6,"tv":117.26,"id":10163711},{"batl":[[1,13.5,3.03]],"ltp":9.0,"tv":157.39,"id":22121325}]}]}
{"op":"mcm","clk":"991402945","pt":1580503567457,"mc":[{"id":"1.168133543","rc":[{"batl":[[0,24,5.22],[1,25,2]],"ltp":8.6,"tv":117.26,"id":10163711}]}]}
{"op":"mcm","clk":"991403192","pt":1580503569494,"mc":[{"id":"1.168133543","rc":[{"batl":[[1,29,9],[2,29,0]],"ltp":8.6,"tv":117.26,"id":10163711},{"batl":[[0,13.5,3.03],[1,14,6.37],[2,16.5,1.94]],"ltp":9.0,"tv":157.39,"id":22121325}]}]}
{"op":"mcm","clk":"991403283","pt":1580503570276,"mc":[{"id":"1.168133543","rc":[{"batl":[[0,13,3.29],[1,13.5,3.03],[2,14,6.37]],"ltp":9.0,"tv":157.39,"id":22121325}]}]}
{"op":"mcm","clk":"991403873","pt":1580503575290,"mc":[{"id":"1.168133543","rc":[{"batb":[[2,8,6.25]],"ltp":8.6,"tv":117.26,"id":10163711}]}]}
{"op":"mcm","clk":"991403923","pt":1580503575707,"mc":[{"id":"1.168133543","rc":[{"batb":[[1,8.2,2.97]],"ltp":8.6,"tv":117.26,"id":10163711}]}]}
{"op":"mcm","clk":"991406331","pt":1580503597059,"mc":[{"id":"1.168133543","rc":[{"batb":[[0,2.8,19.72]],"ltp":2.94,"tv":492.18,"id":12636}]}]}
{"op":"mcm","clk":"991408888","pt":1580503618500,"mc":[{"id":"1.168133543","rc":[{"batl":[[0,12.5,3.03],[1,13,3.29]],"ltp":9.0,"tv":157.39,"id":22121325}]}]}
{"op":"mcm","clk":"991409312","pt":1580503622026,"mc":[{"id":"1.168133543","rc":[{"batl":[[0,12,2],[1,12.5,3.03],[2,13,3.29]],"ltp":9.0,"tv":157.39,"id":22121325}]}]}
{"op":"mcm","clk":"991410225","pt":1580503629208,"mc":[{"id":"1.168133543","rc":[{"batl":[[0,11.5,3.72],[1,12,2],[2,12.5,3.03]],"ltp":9.0,"tv":157.39,"id":22121325}]}]}
{"op":"mcm","clk":"991414403","pt":1580503666458,"mc":[{"id":"1.168133543","rc":[{"batl":[[0,11,3.03],[1,11.5,3.72],[2,12,2]],"ltp":9.0,"tv":157.39,"id":22121325}]}]}
{"op":"mcm","clk":"991414695","pt":1580503669296,"mc":[{"id":"1.168133543","rc":[{"batl":[[0,10.5,2.65],[1,11,3.03]],"ltp":9.0,"tv":157.39,"id":22121325}]}]}
{"op":"mcm","clk":"991415301","pt":1580503675080,"mc":[{"id":"1.168133543","rc":[{"batl":[[0,23,2.41],[1,24,4.81],[2,29,9]],"ltp":8.6,"tv":117.26,"id":10163711},{"batl":[[2,14,6.37]],"ltp":9.0,"tv":157.39,"id":22121325}]}]}
{"op":"mcm","clk":"991416998","pt":1580503690350,"mc":[{"id":"1.168133543","rc":[{"batl":[[1,24,3.03]],"ltp":8.6,"tv":117.26,"id":10163711}]}]}
{"op":"mcm","clk":"991417040","pt":1580503690729,"mc":[{"id":"1.168133543","rc":[{"batl":[[0,22,2.14],[1,23,2.22],[2,24,3.03]],"ltp":8.6,"tv":117.26,"id":10163711}]}]}
{"op":"mcm","clk":"991419159","pt":1580503710570,"mc":[{"id":"1.168133543","rc":[{"batb":[[0,2.86,2.14],[1,2.8,19.26],[2,2.78,2.52]],"ltp":2.94,"tv":492.18,"id":12636}]}]}
{"op":"mcm","clk":"991419278","pt":1580503711461,"mc":[{"id":"1.168133543","rc":[{"trd":[[2.9,12.97]],"batb":[[0,2.8,19.72],[1,2.78,2.52],[2,2.74,47.59]],"ltp":2.9,"tv":493.11,"id":12636}],"tv":1910.22}]}
{"op":"mcm","clk":"991419400","pt":1580503712565,"mc":[{"id":"1.168133543","rc":[{"batb":[[0,2.8,19.26]],"ltp":2.9,"tv":493.11,"id":12636},{"batl":[[2,29,9]],"ltp":8.6,"tv":117.26,"id":10163711}]}]}
{"op":"mcm","clk":"991419514","pt":1580503713554,"mc":[{"id":"1.168133543","rc":[{"batb":[[0,2.8,19.72]],"ltp":2.9,"tv":493.11,"id":12636},{"batl":[[0,22,5.17]],"ltp":8.6,"tv":117.26,"id":10163711},{"batl":[[1,13.5,3.03]],"ltp":9.0,"tv":157.39,"id":22121325}]}]}
{"op":"mcm","clk":"991420477","pt":1580503723494,"mc":[{"id":"1.168133543","rc":[{"batl":[[1,23,2]],"ltp":8.6,"tv":117.26,"id":10163711}]}]}
{"op":"mcm","clk":"991420512","pt":1580503723903,"mc":[{"id":"1.168133543","rc":[{"batl":[[0,22,5.41]],"ltp":8.6,"tv":117.26,"id":10163711}]}]}
{"op":"mcm","clk":"991421006","pt":1580503728510,"mc":[{"id":"1.168133543","rc":[{"batl":[[1,29,9],[2,29,0]],"ltp":8.6,"tv":117.26,"id":10163711}]}]}
{"op":"mcm","clk":"991421212","pt":1580503730502,"mc":[{"id":"1.168133543","rc":[{"batl":[[0,13.5,3.03],[1,14,6.37],[2,16.5,1.94]],"ltp":9.0,"tv":157.39,"id":22121325}]}]}
{"op":"mcm","clk":"991421303","pt":1580503731292,"mc":[{"id":"1.168133543","rc":[{"batl":[[0,13,3.29],[1,13.5,3.03],[2,14,6.37]],"ltp":9.0,"tv":157.39,"id":22121325}]}]}
{"op":"mcm","clk":"991423322","pt":1580503749536,"mc":[{"id":"1.168133543","rc":[{"batl":[[0,12.5,3.03],[1,13,3.29]],"ltp":9.0,"tv":157.39,"id":22121325}]}]}
{"op":"mcm","clk":"991423512","pt":1580503751223,"mc":[{"id":"1.168133543","rc":[{"batl":[[0,12,2.31],[1,12.5,3.03]],"ltp":9.0,"tv":157.39,"id":22121325}]}]}
{"op":"mcm","clk":"991426692","pt":1580503781157,"mc":[{"id":"1.168133543","rc":[{"batl":[[0,11.5,2],[1,12,2.31],[2,12.5,3.03]],"ltp":9.0,"tv":157.39,"id":22121325}]}]}
{"op":"mcm","clk":"991427493","pt":1580503789386,"mc":[{"id":"1.168133543","rc":[{"batl":[[0,11.5,5.03],[2,14,6.37]],"ltp":9.0,"tv":157.39,"id":22121325}]}]}
{"op":"mcm","clk":"991427845","pt":1580503792468,"mc":[{"id":"1.168133543","rc":[{"batl":[[0,11,2.52],[1,11.5,5.03]],"ltp":9.0,"tv":157.39,"id":22121325}]}]}
{"op":"mcm","clk":"991430601","pt":1580503816823,"mc":[{"id":"1.168133543","rc":[{"batl":[[0,2.34,8],[1,2.4,14.23],[2,2.56,8.07]],"ltp":2.28,"tv":1109.12,"id":10107355}]}]}
{"op":"mcm","clk":"991432316","pt":1580503834567,"mc":[{"id":"1.168133543","rc":[{"batl":[[0,21,2.43],[1,22,4.98],[2,29,9]],"ltp":8.6,"tv":117.26,"id":10163711},{"batl":[[1,11.5,3.03]],"ltp":9.0,"tv":157.39,"id":22121325}]}]}
{"op":"mcm","clk":"991432973","pt":1580503841451,"mc":[{"id":"1.168133543","rc":[{"batb":[[1,2.26,20]],"batl":[[2,2.58,27.76]],"ltp":2.28,"tv":1109.12,"id":10107355},{"batl":[[1,13.5,3.03]],"ltp":9.0,"tv":157.39,"id":22121325}]}]}
{"op":"mcm","clk":"991434069","pt":1580503852495,"mc":[{"id":"1.168133543","rc":[{"batl":[[1,22,3.03]],"ltp":8.6,"tv":117.26,"id":10163711},{"batl":[[0,13.5,3.03],[1,14,6.37],[2,16.5,1.94]],"ltp":9.0,"tv":157.39,"id":22121325}]}]}
{"op":"mcm","clk":"991434108","pt":1580503852902,"mc":[{"id":"1.168133543","rc":[{"batl":[[0,20,2.33],[1,21,2.24],[2,22,3.03]],"ltp":8.6,"tv":117.26,"id":10163711},{"batl":[[0,13,3.29],[1,13.5,3.03],[2,14,6.37]],"ltp":9.0,"tv":157.39,"id":22121325}]}]}
{"op":"mcm","clk":"991434347","pt":1580503855304,"mc":[{"id":"1.168133543","rc":[{"batb":[[0,65,1.33],[1,60,2.25],[2,50,1.5]],"ltp":90.0,"tv":1.88,"id":7226819},{"batb":[[0,8.6,7.37],[1,8.4,7.93],[2,8.2,2.97]],"ltp":8.6,"tv":117.26,"id":10163711},{"batb":[[0,9,9.03]],"ltp":9.0,"tv":157.39,"id":22121325},{"batb":[[1,130,1.44],[2,120,1]],"ltp":280.0,"tv":1.32,"id":24270700}]}]}
{"op":"mcm","clk":"991434668","pt":1580503858378,"mc":[{"id":"1.168133543","rc":[{"batb":[[2,8.2,2.85]],"ltp":8.6,"tv":117.26,"id":10163711}]}]}
{"op":"mcm","clk":"991434725","pt":1580503859001,"mc":[{"id":"1.168133543","rc":[{"batb":[[1,8.4,8.05]],"ltp":8.6,"tv":117.26,"id":10163711}]}]}
{"op":"mcm","clk":"991437122","pt":1580503881029,"mc":[{"id":"1.168133543","rc":[{"trd":[[2.28,155.32]],"batb":[[0,2.28,12.62]],"ltp":2.28,"tv":1127.12,"id":10107355}],"tv":1928.22}]}
{"op":"mcm","clk":"991437861","pt":1580503887791,"mc":[{"id":"1.168133543","rc":[{"batl":[[0,19.5,2.19],[1,20,2.14],[2,22,3.27]],"ltp":8.6,"tv":117.26,"id":10163711}]}]}
{"op":"mcm","clk":"991438389","pt":1580503893294,"mc":[{"id":"1.168133543","rc":[{"batl":[[1,22,3.27],[2,29,9]],"ltp":8.6,"tv":117.26,"id":10163711}]}]}
{"op":"mcm","clk":"991438581","pt":1580503895181,"mc":[{"id":"1.168133543","rc":[{"batl":[[0,12.5,3.03],[1,13,3.29]],"ltp":9.0,"tv":157.39,"id":22121325}]}]}
{"op":"mcm","clk":"991440489","pt":1580503913028,"mc":[{"id":"1.168133543","rc":[{"batl":[[0,12,2.31],[1,12.5,3.03]],"ltp":9.0,"tv":157.39,"id":22121325}]}]}
{"op":"mcm","clk":"991441079","pt":1580503918853,"mc":[{"id":"1.168133543","rc":[{"trd":[[2.28,180.55]],"batb":[[0,2.26,20],[1,2.24,7.13],[2,2.22,31.18]],"ltp":2.28,"tv":1152.35,"id":10107355}],"tv":1953.44}]}
{"op":"mcm","clk":"991441551","pt":1580503923540,"mc":[{"id":"1.168133543","rc":[{"batb":[[1,95,1.7]],"ltp":200.0,"tv":1.3,"id":22308007},{"batb":[[1,75,1.23],[2,65,1.49]],"ltp":150.0,"tv":0.92,"id":26548208}]}]}
{"op":"mcm","clk":"991442720","pt":1580503934386,"mc":[{"id":"1.168133543","rc":[{"batb":[[1,95,1.03]],"ltp":200.0,"tv":1.3,"id":22308007},{"batb":[[1,70,1.1],[2,60,1.23]],"ltp":150.0,"tv":0.92,"id":26548208}]}]}
{"op":"mcm","clk":"991443345","pt":1580503940490,"mc":[{"id":"1.168133543","rc":[{"trd":[[2.26,67.78]],"batb":[[0,2.24,7.13],[1,2.22,31.18],[2,2.2,100]],"ltp":2.26,"tv":1192.35,"id":10107355}],"tv":1993.44}]}
{"op":"mcm","clk":"991443544","pt":1580503942484,"mc":[{"id":"1.168133543","rc":[{"batl":[[0,22,3.46],[1,29,9],[2,29,0]],"ltp":8.6,"tv":117.26,"id":10163711}]}]}
{"op":"mcm","clk":"991443835","pt":1580503945400,"mc":[{"id":"1.168133543","rc":[{"batb":[[1,95,1.7]],"ltp":200.0,"tv":1.3,"id":22308007},{"batb":[[1,75,1.23],[2,65,1.49]],"ltp":150.0,"tv":0.92,"id":26548208}]}]}
{"op":"mcm","clk":"991444016","pt":1580503947178,"mc":[{"id":"1.168133543","rc":[{"batb":[[0,8.8,1.98],[1,8.6,7.37],[2,8.4,6.07]],"ltp":8.6,"tv":117.26,"id":10163711},{"batb":[[0,2.24,10.57]],"ltp":2.26,"tv":1192.35,"id":10107355}]}]}
{"op":"mcm","clk":"991444149","pt":1580503948508,"mc":[{"id":"1.168133543","rc":[{"batb":[[2,8.4,5.95]],"ltp":8.6,"tv":117.26,"id":10163711}]}]}
{"op":"mcm","clk":"991444230","pt":1580503949213,"mc":[{"id":"1.168133543","rc":[{"batb":[[1,8.6,7.48]],"ltp":8.6,"tv":117.26,"id":10163711}]}]}
{"op":"mcm","clk":"991454887","pt":1580503957526,"mc":[{"id":"1.168133543","rc":[{"batb":[[1,95,1.03]],"ltp":200.0,"tv":1.3,"id":22308007}]}]}
{"op":"mcm","clk":"991455601","pt":1580503963536,"mc":[{"id":"1.168133543","rc":[{"batl":[[1,13.5,3.03]],"ltp":9.0,"tv":157.39,"id":22121325}]}]}
{"op":"mcm","clk":"991456150","pt":1580503968461,"mc":[{"id":"1.168133543","rc":[{"batb":[[1,70,1.1],[2,60,1.23]],"ltp":150.0,"tv":0.92,"id":26548208}]}]}
{"op":"mcm","clk":"991456674","pt":1580503973254,"mc":[{"id":"1.168133543","rc":[{"batl":[[0,13.5,3.03],[1,14,6.37],[2,16.5,1.94]],"ltp":9.0,"tv":157.39,"id":22121325}]}]}
{"op":"mcm","clk":"991456726","pt":1580503973632,"mc":[{"id":"1.168133543","rc":[{"batl":[[0,13,3.29],[1,13.5,3.03],[2,14,6.37]],"ltp":9.0,"tv":157.39,"id":22121325}]}]}
{"op":"mcm","clk":"991457273","pt":1580503979348,"mc":[{"id":"1.168133543","rc":[{"batb":[[1,95,1.7]],"ltp":200.0,"tv":1.3,"id":22308007},{"batb":[[1,75,1.23],[2,65,1.49]],"ltp":150.0,"tv":0.92,"id":26548208}]}]}
{"op":"mcm","clk":"991458347","pt":1580503990445,"mc":[{"id":"1.168133543","rc":[{"batb":[[1,95,1.03]],"ltp":200.0,"tv":1.3,"id":22308007},{"batb":[[1,70,1.1],[2,60,1.23]],"ltp":150.0,"tv":0.92,"id":26548208}]}]}
{"op":"mcm","clk":"991459385","pt":1580504001388,"mc":[{"id":"1.168133543","rc":[{"batb":[[1,95,1.7]],"ltp":200.0,"tv":1.3,"id":22308007},{"batb":[[1,75,1.23],[2,65,1.49]],"ltp":150.0,"tv":0.92,"id":26548208}]}]}
{"op":"mcm","clk":"991459842","pt":1580504006894,"mc":[{"id":"1.168133543","rc":[{"batl":[[1,2.38,12],[2,2.4,2.23]],"ltp":2.26,"tv":1192.35,"id":10107355}]}]}
{"op":"mcm","clk":"991460288","pt":1580504012483,"mc":[{"id":"1.168133543","rc":[{"batb":[[1,95,1.03]],"ltp":200.0,"tv":1.3,"id":22308007},{"batb":[[1,70,1.1],[2,60,1.23]],"ltp":150.0,"tv":0.92,"id":26548208}]}]}
{"op":"mcm","clk":"991460861","pt":1580504019390,"mc":[{"id":"1.168133543","rc":[{"batl":[[0,12.5,3.03],[1,13,3.29]],"ltp":9.0,"tv":157.39,"id":22121325}]}]}
{"op":"mcm","clk":"991461195","pt":1580504023397,"mc":[{"id":"1.168133543","rc":[{"batb":[[1,95,1.7]],"ltp":200.0,"tv":1.3,"id":22308007},{"batb":[[1,75,1.23],[2,65,1.49]],"ltp":150.0,"tv":0.92,"id":26548208}]}]}
{"op":"mcm","clk":"991462056","pt":1580504034220,"mc":[{"id":"1.168133543","rc":[{"batl":[[1,14,6.37],[2,16.5,1.94]],"ltp":9.0,"tv":157.39,"id":22121325}]}]}
{"op":"mcm","clk":"991462159","pt":1580504035446,"mc":[{"id":"1.168133543","rc":[{"batb":[[1,95,1.03]],"ltp":200.0,"tv":1.3,"id":22308007},{"batl":[[0,12,2.31],[1,12.5,3.03],[2,14,6.37]],"ltp":9.0,"tv":157.39,"id":22121325}]}]}
{"op":"mcm","clk":"991463084","pt":1580504046326,"mc":[{"id":"1.168133543","rc":[{"batb":[[1,95,1.7]],"ltp":200.0,"tv":1.3,"id":22308007}]}]}
{"op":"mcm","clk":"991463647","pt":1580504052427,"mc":[{"id":"1.168133543","rc":[{"batl":[[1,14,6.37],[2,16.5,1.94]],"ltp":9.0,"tv":157.39,"id":22121325}]}]}
{"op":"mcm","clk":"991463771","pt":1580504053534,"mc":[{"id":"1.168133543","rc":[{"batl":[[1,13.5,3.03],[2,14,6.37]],"ltp":9.0,"tv":157.39,"id":22121325}]}]}
{"op":"mcm","clk":"991463921","pt":1580504055156,"mc":[{"id":"1.168133543","rc":[{"batl":[[0,13,3.29]],"ltp":9.0,"tv":157.39,"id":22121325}]}]}
{"op":"mcm","clk":"991464157","pt":1580504057536,"mc":[{"id":"1.168133543","rc":[{"batb":[[1,95,1.03]],"ltp":200.0,"tv":1.3,"id":22308007},{"batb":[[1,70,1.1],[2,60,1.23]],"ltp":150.0,"tv":0.92,"id":26548208}]}]}
{"op":"mcm","clk":"991465072","pt":1580504068459,"mc":[{"id":"1.168133543","rc":[{"batb":[[1,95,1.7]],"ltp":200.0,"tv":1.3,"id":22308007},{"batb":[[1,75,1.23],[2,65,1.49]],"ltp":150.0,"tv":0.92,"id":26548208}]}]}
{"op":"mcm","clk":"991465922","pt":1580504079527,"mc":[{"id":"1.168133543","rc":[{"batb":[[1,95,1.03]],"ltp":200.0,"tv":1.3,"id":22308007},{"batb":[[1,70,1.1],[2,60,1.23]],"ltp":150.0,"tv":0.92,"id":26548208}]}]}
{"op":"mcm","clk":"991466212","pt":1580504084494,"mc":[{"id":"1.168133543","rc":[{"batl":[[0,21,2.43],[1,22,3.03],[2,29,9]],"ltp":8.6,"tv":117.26,"id":10163711},{"batl":[[0,12.5,2],[1,13,3.29],[2,13.5,3.03]],"ltp":9.0,"tv":157.39,"id":22121325}]}]}
{"op":"mcm","clk":"991466264","pt":1580504085491,"mc":[{"id":"1.168133543","rc":[{"batl":[[0,12.5,5.03],[2,14,6.37]],"ltp":9.0,"tv":157.39,"id":22121325}]}]}
{"op":"mcm","clk":"991466548","pt":1580504090366,"mc":[{"id":"1.168133543","rc":[{"batb":[[1,95,1.7]],"ltp":200.0,"tv":1.3,"id":22308007},{"batb":[[1,75,1.23],[2,65,1.49]],"ltp":150.0,"tv":0.92,"id":26548208}]}]}
{"op":"mcm","clk":"991466851","pt":1580504095988,"mc":[{"id":"1.168133543","rc":[{"batl":[[0,20,2.33],[1,21,2.24],[2,22,3.03]],"ltp":8.6,"tv":117.26,"id":10163711},{"batl":[[0,12,2.31],[1,12.5,5.03]],"ltp":9.0,"tv":157.39,"id":22121325}]}]}
{"op":"mcm","clk":"991467137","pt":1580504101522,"mc":[{"id":"1.168133543","rc":[{"batb":[[1,95,1.03]],"ltp":200.0,"tv":1.3,"id":22308007}]}]}
{"op":"mcm","clk":"991467747","pt":1580504113416,"mc":[{"id":"1.168133543","rc":[{"batb":[[1,95,1.7]],"ltp":200.0,"tv":1.3,"id":22308007}]}]}
{"op":"mcm","clk":"991468392","pt":1580504124511,"mc":[{"id":"1.168133543","rc":[{"batb":[[1,95,1.03]],"ltp":200.0,"tv":1.3,"id":22308007}]}]}
{"op":"mcm","clk":"991468971","pt":1580504135338,"mc":[{"id":"1.168133543","rc":[{"batb":[[1,95,1.7]],"ltp":200.0,"tv":1.3,"id":22308007}]}]}
{"op":"mcm","clk":"991469570","pt":1580504146533,"mc":[{"id":"1.168133543","rc":[{"batb":[[1,95,1.03]],"ltp":200.0,"tv":1.3,"id":22308007}]}]}
{"op":"mcm","clk":"991470274","pt":1580504157353,"mc":[{"id":"1.168133543","rc":[{"batb":[[1,95,1.7]],"ltp":200.0,"tv":1.3,"id":22308007}]}]}
{"op":"mcm","clk":"991470749","pt":1580504166135,"mc":[{"id":"1.168133543","rc":[{"batl":[[1,22,3.27],[2,29,9]],"ltp":8.6,"tv":117.26,"id":10163711},{"batl":[[1,12.5,3.03]],"ltp":9.0,"tv":157.39,"id":22121325}]}]}
{"op":"mcm","clk":"991470890","pt":1580504168758,"mc":[{"id":"1.168133543","rc":[{"batb":[[1,95,1.03]],"ltp":200.0,"tv":1.3,"id":22308007}]}]}
{"op":"mcm","clk":"991471481","pt":1580504179492,"mc":[{"id":"1.168133543","rc":[{"batb":[[1,95,1.7]],"ltp":200.0,"tv":1.3,"id":22308007}]}]}
{"op":"mcm","clk":"991471739","pt":1580504183469,"mc":[{"id":"1.168133543","rc":[{"batl":[[1,13.5,3.03]],"ltp":9.0,"tv":157.39,"id":22121325}]}]}
{"op":"mcm","clk":"991472218","pt":1580504191485,"mc":[{"id":"1.168133543","rc":[{"batb":[[1,95,1.03]],"ltp":200.0,"tv":1.3,"id":22308007},{"batb":[[1,70,1.1],[2,60,1.23]],"ltp":150.0,"tv":0.92,"id":26548208}]}]}
{"op":"mcm","clk":"991472431","pt":1580504195482,"mc":[{"id":"1.168133543","rc":[{"batl":[[0,13.5,3.03],[1,14,6.37],[2,16.5,1.94]],"ltp":9.0,"tv":157.39,"id":22121325}]}]}
{"op":"mcm","clk":"991472846","pt":1580504202518,"mc":[{"id":"1.168133543","rc":[{"batb":[[1,95,1.7]],"ltp":200.0,"tv":1.3,"id":22308007},{"batb":[[1,75,1.23],[2,65,1.49]],"ltp":150.0,"tv":0.92,"id":26548208}]}]}
{"op":"mcm","clk":"991473510","pt":1580504213540,"mc":[{"id":"1.168133543","rc":[{"batb":[[1,95,1.03]],"ltp":200.0,"tv":1.3,"id":22308007},{"batb":[[1,70,1.1],[2,60,1.23]],"ltp":150.0,"tv":0.92,"id":26548208}]}]}
{"op":"mcm","clk":"991473600","pt":1580504214583,"mc":[{"id":"1.168133543","rc":[{"batl":[[0,13,3.29],[1,13.5,3.03],[2,14,6.37]],"ltp":9.0,"tv":157.39,"id":22121325}]}]}
{"op":"mcm","clk":"991473703","pt":1580504216210,"mc":[{"id":"1.168133543","rc":[{"batl":[[0,12.5,3.03],[1,13,3.29]],"ltp":9.0,"tv":157.39,"id":22121325}]}]}
{"op":"mcm","clk":"991474337","pt":1580504224313,"mc":[{"id":"1.168133543","rc":[{"batb":[[1,95,1.7]],"ltp":200.0,"tv":1.3,"id":22308007},{"batb":[[1,75,1.23],[2,65,1.49]],"ltp":150.0,"tv":0.92,"id":26548208}]}]}
{"op":"mcm","clk":"991475104","pt":1580504234530,"mc":[{"id":"1.168133543","rc":[{"batl":[[0,12,2.31],[1,12.5,3.03]],"ltp":9.0,"tv":157.39,"id":22121325}]}]}
{"op":"mcm","clk":"991475183","pt":1580504235435,"mc":[{"id":"1.168133543","rc":[{"batb":[[1,95,1.03]],"ltp":200.0,"tv":1.3,"id":22308007}]}]}
{"op":"mcm","clk":"991475907","pt":1580504246324,"mc":[{"id":"1.168133543","rc":[{"batb":[[1,95,1.7]],"ltp":200.0,"tv":1.3,"id":22308007}]}]}
{"op":"mcm","clk":"991476067","pt":1580504248459,"mc":[{"id":"1.168133543","rc":[{"batl":[[1,13.5,3.03]],"ltp":9.0,"tv":157.39,"id":22121325}]}]}
{"op":"mcm","clk":"991476587","pt":1580504255063,"mc":[{"id":"1.168133543","rc":[{"batl":[[0,13,3.29]],"ltp":9.0,"tv":157.39,"id":22121325}]}]}
{"op":"mcm","clk":"991476765","pt":1580504257438,"mc":[{"id":"1.168133543","rc":[{"batb":[[1,95,1.03]],"ltp":200.0,"tv":1.3,"id":22308007}]}]}
{"op":"mcm","clk":"991477647","pt":1580504269386,"mc":[{"id":"1.168133543","rc":[{"batb":[[1,95,1.7]],"ltp":200.0,"tv":1.3,"id":22308007}]}]}
{"op":"mcm","clk":"991478377","pt":1580504280497,"mc":[{"id":"1.168133543","rc":[{"batb":[[1,95,1.03]],"ltp":200.0,"tv":1.3,"id":22308007}]}]}
{"op":"mcm","clk":"991478447","pt":1580504281489,"mc":[{"id":"1.168133543","rc":[{"batl":[[0,12.5,3.03],[1,13,3.29]],"ltp":9.0,"tv":157.39,"id":22121325}]}]}
{"op":"mcm","clk":"991479161","pt":1580504291384,"mc":[{"id":"1.168133543","rc":[{"batb":[[1,95,1.7]],"ltp":200.0,"tv":1.3,"id":22308007}]}]}
{"op":"mcm","clk":"991479371","pt":1580504294993,"mc":[{"id":"1.168133543","rc":[{"batl":[[0,12,2.31],[1,12.5,3.03]],"ltp":9.0,"tv":157.39,"id":22121325}]}]}
{"op":"mcm","clk":"991479897","pt":1580504302517,"mc":[{"id":"1.168133543","rc":[{"batb":[[1,95,1.03]],"ltp":200.0,"tv":1.3,"id":22308007}]}]}
{"op":"mcm","clk":"991480640","pt":1580504313537,"mc":[{"id":"1.168133543","rc":[{"batb":[[1,95,1.7]],"ltp":200.0,"tv":1.3,"id":22308007},{"batl":[[1,14,6.37],[2,16.5,1.94]],"ltp":9.0,"tv":157.39,"id":22121325}]}]}
{"op":"mcm","clk":"991480673","pt":1580504313909,"mc":[{"id":"1.168133543","rc":[{"batl":[[1,13.5,3.03],[2,14,6.37]],"ltp":9.0,"tv":157.39,"id":22121325}]}]}
{"op":"mcm","clk":"991480780","pt":1580504315209,"mc":[{"id":"1.168133543","rc":[{"batl":[[0,13,3.29]],"ltp":9.0,"tv":157.39,"id":22121325}]}]}
{"op":"mcm","clk":"991481440","pt":1580504324444,"mc":[{"id":"1.168133543","rc":[{"batb":[[1,95,1.03]],"ltp":200.0,"tv":1.3,"id":22308007}]}]}
{"op":"mcm","clk":"991481657","pt":1580504327125,"mc":[{"id":"1.168133543","rc":[{"batl":[[0,11,2],[1,20,2.33],[2,22,3.27]],"ltp":8.6,"tv":117.26,"id":10163711}]}]}
{"op":"mcm","clk":"991482229","pt":1580504335341,"mc":[{"id":"1.168133543","rc":[{"batb":[[1,95,1.7]],"ltp":200.0,"tv":1.3,"id":22308007},{"batl":[[1,22,3.46],[2,29,9]],"ltp":8.6,"tv":117.26,"id":10163711}]}]}
{"op":"mcm","clk":"991482999","pt":1580504346542,"mc":[{"id":"1.168133543","rc":[{"batl":[[0,12.5,3.03],[1,13,3.29]],"ltp":9.0,"tv":157.39,"id":22121325}]}]}
{"op":"mcm","clk":"991483062","pt":1580504347427,"mc":[{"id":"1.168133543","rc":[{"batb":[[1,95,1.03]],"ltp":200.0,"tv":1.3,"id":22308007}]}]}
{"op":"mcm","clk":"991483568","pt":1580504354572,"mc":[{"id":"1.168133543","rc":[{"batl":[[1,14,6.37],[2,16.5,1.94]],"ltp":9.0,"tv":157.39,"id":22121325}]}]}
{"op":"mcm","clk":"991483581","pt":1580504354834,"mc":[{"id":"1.168133543","rc":[{"batl":[[0,12,2.31],[1,12.5,3.03],[2,14,6.37]],"ltp":9.0,"tv":157.39,"id":22121325}]}]}
{"op":"mcm","clk":"991483836","pt":1580504358375,"mc":[{"id":"1.168133543","rc":[{"batb":[[1,95,1.7]],"ltp":200.0,"tv":1.3,"id":22308007}]}]}
{"op":"mcm","clk":"991484625","pt":1580504368459,"mc":[{"id":"1.168133543","rc":[{"trd":[[2.34,42.66]],"batb":[[0,2.24,4.44]],"batl":[[0,2.34,20.36]],"ltp":2.34,"tv":1212.87,"id":10107355}],"tv":2013.96}]}
{"op":"mcm","clk":"991484692","pt":1580504369443,"mc":[{"id":"1.168133543","rc":[{"batb":[[1,95,1.03]],"ltp":200.0,"tv":1.3,"id":22308007},{"batl":[[0,2.34,31.66]],"ltp":2.34,"tv":1212.87,"id":10107355}]}]}
{"op":"mcm","clk":"991485415","pt":1580504379533,"mc":[{"id":"1.168133543","rc":[{"batl":[[1,14,6.37],[2,16.5,1.94]],"ltp":9.0,"tv":157.39,"id":22121325}]}]}
{"op":"mcm","clk":"991485491","pt":1580504380563,"mc":[{"id":"1.168133543","rc":[{"batb":[[0,60,2.61],[1,50,1.5],[2,48,1.04]],"ltp":90.0,"tv":1.88,"id":7226819},{"batb":[[0,8.8,11.45],[1,8.4,6.06],[2,8.2,2.85]],"ltp":8.6,"tv":117.26,"id":10163711},{"batb":[[0,9.2,2.17],[1,9,9.03],[2,8.8,3.71]],"batl":[[1,13.5,3.03],[2,14,6.37]],"ltp":9.0,"tv":157.39,"id":22121325},{"batb":[[1,70,1.1],[2,60,1.23]],"ltp":150.0,"tv":0.92,"id":26548208}]}]}
{"op":"mcm","clk":"991485792","pt":1580504385375,"mc":[{"id":"1.168133543","rc":[{"batb":[[2,8.8,3.6]],"ltp":9.0,"tv":157.39,"id":22121325}]}]}
{"op":"mcm","clk":"991485848","pt":1580504386051,"mc":[{"id":"1.168133543","rc":[{"batb":[[1,9,9.13]],"ltp":9.0,"tv":157.39,"id":22121325}]}]}
{"op":"mcm","clk":"991486419","pt":1580504394552,"mc":[{"id":"1.168133543","rc":[{"batl":[[0,13.5,3.03],[1,14,6.37],[2,16.5,1.94]],"ltp":9.0,"tv":157.39,"id":22121325}]}]}
{"op":"mcm","clk":"991486441","pt":1580504394967,"mc":[{"id":"1.168133543","rc":[{"batl":[[0,13,3.29],[1,13.5,3.03],[2,14,6.37]],"ltp":9.0,"tv":157.39,"id":22121325}]}]}
{"op":"mcm","clk":"991488273","pt":1580504413300,"mc":[{"id":"1.168133543","rc":[{"batl":[[0,12.5,3.03],[1,13,3.29]],"ltp":9.0,"tv":157.39,"id":22121325}]}]}
{"op":"mcm","clk":"991488369","pt":1580504414392,"mc":[{"id":"1.168133543","rc":[{"batb":[[0,65,1.33],[1,60,2.25],[2,50,1.5]],"ltp":90.0,"tv":1.88,"id":7226819}]}]}
{"op":"mcm","clk":"991488430","pt":1580504415062,"mc":[{"id":"1.168133543","rc":[{"batb":[[0,9.4,1.98],[1,9.2,2.17],[2,9,7.15]],"batl":[[0,12,2.31],[1,12.5,3.03]],"ltp":9.0,"tv":157.39,"id":22121325}]}]}
{"op":"mcm","clk":"991488552","pt":1580504416526,"mc":[{"id":"1.168133543","rc":[{"batb":[[1,9.2,2.27],[2,9,7.05]],"ltp":9.0,"tv":157.39,"id":22121325}]}]}
{"op":"mcm","clk":"991489292","pt":1580504425494,"mc":[{"id":"1.168133543","rc":[{"batb":[[0,60,2.61],[1,50,1.5],[2,48,1.04]],"ltp":90.0,"tv":1.88,"id":7226819},{"batb":[[1,9.2,9.16],[2,8.8,3.6]],"ltp":9.0,"tv":157.39,"id":22121325}]}]}
{"op":"mcm","clk":"991492560","pt":1580504466258,"mc":[{"id":"1.168133543","rc":[{"batl":[[2,330,2]],"ltp":200.0,"tv":1.3,"id":22308007},{"batl":[[2,330,2]],"ltp":90.0,"tv":1.88,"id":7226819},{"batl":[[1,330,2],[2,980,9]],"ltp":150.0,"tv":0.92,"id":26548208},{"batl":[[0,330,2],[1,590,2.14]],"ltp":580.0,"tv":6.12,"id":27606066},{"batl":[[1,330,2]],"ltp":280.0,"tv":1.32,"id":24270700},{"batl":[[0,330,2],[1,1000,0.2]],"ltp":70.0,"tv":18.0,"id":13306150}]}]}
{"op":"mcm","clk":"991492724","pt":1580504468542,"mc":[{"id":"1.168133543","rc":[{"batl":[[1,590,2]],"ltp":580.0,"tv":6.12,"id":27606066},{"batl":[[0,330,2.2],[1,1000,0]],"ltp":70.0,"tv":18.0,"id":13306150}]}]}
{"op":"mcm","clk":"991493588","pt":1580504479357,"mc":[{"id":"1.168133543","rc":[{"batb":[[0,65,1.33],[1,60,2.25],[2,50,1.5]],"ltp":90.0,"tv":1.88,"id":7226819}]}]}
{"op":"mcm","clk":"991495659","pt":1580504504491,"mc":[{"id":"1.168133543","rc":[{"batl":[[2,330,2.15]],"ltp":200.0,"tv":1.3,"id":22308007},{"batl":[[2,330,2.15]],"ltp":90.0,"tv":1.88,"id":7226819},{"batl":[[1,330,2.15]],"ltp":150.0,"tv":0.92,"id":26548208},{"batl":[[0,330,2.15]],"ltp":580.0,"tv":6.12,"id":27606066},{"batl":[[1,330,2.15]],"ltp":280.0,"tv":1.32,"id":24270700},{"batl":[[0,330,2.35]],"ltp":70.0,"tv":18.0,"id":13306150}]}]}
{"op":"mcm","clk":"991495990","pt":1580504508515,"mc":[{"id":"1.168133543","rc":[{"batl":[[0,2.92,4],[1,2.94,58.02],[2,2.96,50]],"ltp":2.9,"tv":493.11,"id":12636}]}]}
{"op":"mcm","clk":"991498267","pt":1580504540379,"mc":[{"id":"1.168133543","rc":[{"batl":[[2,330,0.15]],"ltp":200.0,"tv":1.3,"id":22308007},{"batl":[[2,510,9.15]],"ltp":90.0,"tv":1.88,"id":7226819},{"batl":[[1,980,9.15],[2,980,0]],"ltp":150.0,"tv":0.92,"id":26548208},{"batl":[[0,590,2.15],[1,590,0]],"ltp":580.0,"tv":6.12,"id":27606066},{"batl":[[1,330,0.15]],"ltp":280.0,"tv":1.32,"id":24270700},{"batl":[[0,330,0.35]],"ltp":70.0,"tv":18.0,"id":13306150}]}]}
{"op":"mcm","clk":"991501458","pt":1580504585436,"mc":[{"id":"1.168133543","rc":[{"trd":[[2.22,33.5],[2.24,12.41]],"batb":[[0,2.22,20.62],[1,2.2,100],[2,2,53.51]],"ltp":2.22,"tv":1242.87,"id":10107355}],"tv":2043.96}]}
{"op":"mcm","clk":"991501526","pt":1580504586425,"mc":[{"id":"1.168133543","rc":[{"trd":[[2.8,11.08],[2.9,13.89]],"batb":[[0,2.8,16.71],[2,2.76,56.46]],"ltp":2.8,"tv":499.11,"id":12636},{"batl":[[1,330,0.15],[2,330,0]],"ltp":200.0,"tv":1.3,"id":22308007},{"batl":[[1,510,9.15],[2,550,2]],"ltp":90.0,"tv":1.88,"id":7226819},{"trd":[[2.22,45.5]],"batb":[[0,2.22,14.62],[2,2.02,6]],"ltp":2.22,"tv":1254.86,"id":10107355},{"batl":[[2,16.5,1.94]],"ltp":9.0,"tv":157.39,"id":22121325},{"batl":[[0,160,4]],"ltp":150.0,"tv":0.92,"id":26548208},{"batb":[[2,120,6]],"batl":[[0,330,0.15],[1,330,0]],"ltp":280.0,"tv":1.32,"id":24270700}],"tv":2061.97}]}
{"op":"mcm","clk":"991501596","pt":1580504587524,"mc":[{"id":"1.168133543","rc":[{"batl":[[0,330,0.35]],"ltp":280.0,"tv":1.32,"id":24270700}]}]}
{"op":"mcm","clk":"991502024","pt":1580504593544,"mc":[{"id":"1.168133543","rc":[{"batb":[[0,2.24,28.3],[1,2.22,14.62],[2,2.2,100]],"ltp":2.22,"tv":1254.86,"id":10107355},{"batb":[[1,120,6.94],[2,90,2]],"ltp":280.0,"tv":1.32,"id":24270700}]}]}
{"op":"mcm","clk":"991502034","pt":1580504593644,"mc":[{"id":"1.168133543","rc":[{"batb":[[1,95,1.7]],"ltp":200.0,"tv":1.3,"id":22308007}]}]}
{"op":"mcm","clk":"991502253","pt":1580504596552,"mc":[{"id":"1.168133543","rc":[{"batl":[[0,210,8.03]],"ltp":200.0,"tv":1.3,"id":22308007},{"batl":[[0,95,8.27]],"ltp":90.0,"tv":1.88,"id":7226819},{"batl":[[2,13.5,7.94]],"ltp":9.0,"tv":157.39,"id":22121325},{"batl":[[0,150,5],[1,160,4],[2,980,9.15]],"ltp":150.0,"tv":0.92,"id":26548208},{"batl":[[0,280,5],[1,330,0.35]],"ltp":280.0,"tv":1.32,"id":24270700}]}]}
{"op":"mcm","clk":"991502573","pt":1580504600468,"mc":[{"id":"1.168133543","rc":[{"batl":[[1,330,0.15]],"ltp":280.0,"tv":1.32,"id":24270700}]}]}
{"op":"mcm","clk":"991502796","pt":1580504603536,"mc":[{"id":"1.168133543","rc":[{"batb":[[1,100,1.13],[2,85,1.43]],"ltp":200.0,"tv":1.3,"id":22308007},{"batb":[[1,75,1.23],[2,65,1.49]],"ltp":150.0,"tv":0.92,"id":26548208}]}]}
{"op":"mcm","clk":"991503536","pt":1580504612473,"mc":[{"id":"1.168133543","rc":[{"batb":[[1,95,1.03],[2,80,1.52]],"ltp":200.0,"tv":1.3,"id":22308007},{"batb":[[1,70,1.1],[2,60,1.23]],"ltp":150.0,"tv":0.92,"id":26548208}]}]}
{"op":"mcm","clk":"991504245","pt":1580504622374,"mc":[{"id":"1.168133543","rc":[{"batb":[[1,95,1.7]],"ltp":200.0,"tv":1.3,"id":22308007},{"batb":[[1,75,1.23],[2,65,1.49]],"ltp":150.0,"tv":0.92,"id":26548208}]}]}
{"op":"mcm","clk":"991505092","pt":1580504632480,"mc":[{"id":"1.168133543","rc":[{"batb":[[1,95,1.03]],"ltp":200.0,"tv":1.3,"id":22308007},{"batb":[[1,70,1.1],[2,60,1.23]],"ltp":150.0,"tv":0.92,"id":26548208}]}]}
{"op":"mcm","clk":"991505796","pt":1580504641354,"mc":[{"id":"1.168133543","rc":[{"batb":[[1,95,1.7]],"ltp":200.0,"tv":1.3,"id":22308007},{"batb":[[1,75,1.23],[2,65,1.49]],"ltp":150.0,"tv":0.92,"id":26548208}]}]}
{"op":"mcm","clk":"991506721","pt":1580504651511,"mc":[{"id":"1.168133543","rc":[{"batb":[[1,95,1.03]],"ltp":200.0,"tv":1.3,"id":22308007},{"batb":[[1,70,1.1],[2,60,1.23]],"ltp":150.0,"tv":0.92,"id":26548208}]}]}
{"op":"mcm","clk":"991507328","pt":1580504658028,"mc":[{"id":"1.168133543","rc":[{"batb":[[0,9,1.92],[1,8.8,11.45],[2,8.4,6.06]],"ltp":8.6,"tv":117.26,"id":10163711},{"batb":[[0,9.4,3.81]],"ltp":9.0,"tv":157.39,"id":22121325}]}]}
{"op":"mcm","clk":"991507545","pt":1580504660527,"mc":[{"id":"1.168133543","rc":[{"batb":[[1,95,1.7]],"ltp":200.0,"tv":1.3,"id":22308007},{"batb":[[0,9,8.96],[1,8.8,4.25],[2,8.4,5.95]],"ltp":8.6,"tv":117.26,"id":10163711},{"batb":[[0,9.4,10.56],[1,9.2,2.27]],"ltp":9.0,"tv":157.39,"id":22121325}]}]}
{"op":"mcm","clk":"991507607","pt":1580504661348,"mc":[{"id":"1.168133543","rc":[{"batb":[[1,8.8,4.36]],"ltp":8.6,"tv":117.26,"id":10163711}]}]}
{"op":"mcm","clk":"991507700","pt":1580504662553,"mc":[{"id":"1.168133543","rc":[{"batl":[[1,22,3.27]],"ltp":8.6,"tv":117.26,"id":10163711}]}]}
{"op":"mcm","clk":"991508220","pt":1580504669333,"mc":[{"id":"1.168133543","rc":[{"trd":[[2.24,52.42]],"batb":[[0,2.24,8.29]],"ltp":2.24,"tv":1294.87,"id":10107355}],"tv":2101.98}]}
{"op":"mcm","clk":"991508327","pt":1580504670433,"mc":[{"id":"1.168133543","rc":[{"batb":[[1,95,1.03]],"ltp":200.0,"tv":1.3,"id":22308007},{"batb":[[1,8.8,2.09]],"ltp":8.6,"tv":117.26,"id":10163711},{"batb":[[1,8.8,3.7],[2,8.6,4.51]],"ltp":9.0,"tv":157.39,"id":22121325}]}]}
{"op":"mcm","clk":"991508949","pt":1580504678535,"mc":[{"id":"1.168133543","rc":[{"batb":[[0,2.26,4],[1,2.24,8.29],[2,2.22,14.62]],"ltp":2.24,"tv":1294.87,"id":10107355}]}]}
{"op":"mcm","clk":"991509018","pt":1580504679432,"mc":[{"id":"1.168133543","rc":[{"batb":[[0,9,1.92]],"ltp":8.6,"tv":117.26,"id":10163711},{"batb":[[1,2.22,14.62],[2,2.2,100]],"ltp":2.24,"tv":1294.87,"id":10107355}]}]}
{"op":"mcm","clk":"991509049","pt":1580504679741,"mc":[{"id":"1.168133543","rc":[{"batb":[[1,95,1.7]],"ltp":200.0,"tv":1.3,"id":22308007},{"batb":[[2,8.6,7.37]],"ltp":8.6,"tv":117.26,"id":10163711}]}]}
{"op":"mcm","clk":"991509712","pt":1580504687351,"mc":[{"id":"1.168133543","rc":[{"batb":[[0,2.28,5],[1,2.26,4],[2,2.22,14.62]],"ltp":2.24,"tv":1294.87,"id":10107355}]}]}
{"op":"mcm","clk":"991509895","pt":1580504689482,"mc":[{"id":"1.168133543","rc":[{"batb":[[1,95,1.03]],"ltp":200.0,"tv":1.3,"id":22308007},{"batb":[[0,60,2.61],[1,50,1.5],[2,48,1.04]],"ltp":90.0,"tv":1.88,"id":7226819},{"batb":[[2,8.4,5.95]],"ltp":8.6,"tv":117.26,"id":10163711},{"batb":[[0,9.4,3.81]],"ltp":9.0,"tv":157.39,"id":22121325}]}]}
{"op":"mcm","clk":"991509983","pt":1580504690476,"mc":[{"id":"1.168133543","rc":[{"batb":[[1,8.8,9.29]],"ltp":8.6,"tv":117.26,"id":10163711},{"batl":[[1,13.5,7.94],[2,16.5,1.94]],"ltp":9.0,"tv":157.39,"id":22121325}]}]}
{"op":"mcm","clk":"991510002","pt":1580504690681,"mc":[{"id":"1.168133543","rc":[{"batl":[[1,13,3.32],[2,13.5,7.94]],"ltp":9.0,"tv":157.39,"id":22121325}]}]}
{"op":"mcm","clk":"991510633","pt":1580504698388,"mc":[{"id":"1.168133543","rc":[{"batb":[[1,8.8,2.09]],"ltp":8.6,"tv":117.26,"id":10163711}]}]}
{"op":"mcm","clk":"991510904","pt":1580504701147,"mc":[{"id":"1.168133543","rc":[{"batb":[[0,9.2,1.98],[1,9,1.92],[2,8.4,6.06]],"ltp":8.6,"tv":117.26,"id":10163711}]}]}
{"op":"mcm","clk":"991511349","pt":1580504706569,"mc":[{"id":"1.168133543","rc":[{"batb":[[2,8.4,5.95]],"ltp":8.6,"tv":117.26,"id":10163711}]}]}
{"op":"mcm","clk":"991511435","pt":1580504707562,"mc":[{"id":"1.168133543","rc":[{"batb":[[1,9,2.02]],"ltp":8.6,"tv":117.26,"id":10163711}]}]}
{"op":"mcm","clk":"991512806","pt":1580504724903,"mc":[{"id":"1.168133543","rc":[{"batl":[[0,10.5,2],[1,11,2],[2,22,3.27]],"ltp":8.6,"tv":117.26,"id":10163711},{"batl":[[0,11.5,2],[1,12,2.31],[2,13,3.32]],"ltp":9.0,"tv":157.39,"id":22121325}]}]}
{"op":"mcm","clk":"991513005","pt":1580504727513,"mc":[{"id":"1.168133543","rc":[{"batb":[[1,95,1.7]],"ltp":200.0,"tv":1.3,"id":22308007},{"batb":[[0,65,1.33],[1,60,2.25],[2,50,1.5]],"ltp":90.0,"tv":1.88,"id":7226819},{"batb":[[1,9,9.06]],"ltp":8.6,"tv":117.26,"id":10163711},{"batb":[[0,9.4,10.56]],"ltp":9.0,"tv":157.39,"id":22121325},{"batb":[[1,75,1.23],[2,65,1.49]],"ltp":150.0,"tv":0.92,"id":26548208},{"batb":[[1,130,1.44],[2,120,6]],"ltp":280.0,"tv":1.32,"id":24270700}]}]}
{"op":"mcm","clk":"991513266","pt":1580504730528,"mc":[{"id":"1.168133543","rc":[{"batl":[[0,11,2.52],[1,11.5,2]],"ltp":9.0,"tv":157.39,"id":22121325}]}]}
{"op":"mcm","clk":"991513850","pt":1580504737520,"mc":[{"id":"1.168133543","rc":[{"batb":[[1,95,1.03]],"ltp":200.0,"tv":1.3,"id":22308007},{"batb":[[0,9.4,3.81]],"ltp":9.0,"tv":157.39,"id":22121325}]}]}
{"op":"mcm","clk":"991513875","pt":1580504737732,"mc":[{"id":"1.168133543","rc":[{"batb":[[0,2.82,22.49],[1,2.8,16.71],[2,2.78,2.52]],"ltp":2.8,"tv":499.11,"id":12636},{"batb":[[1,100,1.13],[2,85,1.43]],"ltp":200.0,"tv":1.3,"id":22308007}]}]}
{"op":"mcm","clk":"991517030","pt":1580504777440,"mc":[{"id":"1.168133543","rc":[{"batb":[[0,1000,306.42]],"ltp":1000.0,"tv":3.75,"id":13819977}]}]}
{"op":"mcm","clk":"991517185","pt":1580504779547,"mc":[{"id":"1.168133543","rc":[{"batl":[[1,13,3.32],[2,13.5,7.94]],"ltp":9.0,"tv":157.39,"id":22121325}]}]}
{"op":"mcm","clk":"991517195","pt":1580504779640,"mc":[{"id":"1.168133543","rc":[{"batl":[[1,12.5,2],[2,13,3.32]],"ltp":9.0,"tv":157.39,"id":22121325}]}]}
{"op":"mcm","clk":"991517588","pt":1580504784544,"mc":[{"id":"1.168133543","rc":[{"batb":[[0,2.8,16.71],[1,2.78,2.52],[2,2.76,56.46]],"ltp":2.8,"tv":499.11,"id":12636},{"batb":[[0,9.4,10.56]],"ltp":9.0,"tv":157.39,"id":22121325}]}]}
{"op":"mcm","clk":"991518058","pt":1580504790475,"mc":[{"id":"1.168133543","rc":[{"batl":[[0,12.5,2],[1,13,3.32],[2,13.5,7.94]],"ltp":9.0,"tv":157.39,"id":22121325}]}]}
{"op":"mcm","clk":"991518079","pt":1580504790680,"mc":[{"id":"1.168133543","rc":[{"batl":[[0,12,3.57],[1,12.5,2],[2,13,3.32]],"ltp":9.0,"tv":157.39,"id":22121325}]}]}
{"op":"mcm","clk":"991518311","pt":1580504793555,"mc":[{"id":"1.168133543","rc":[{"batb":[[0,1000,307.02]],"ltp":1000.0,"tv":3.75,"id":13819977}]}]}
{"op":"mcm","clk":"991535920","pt":1580504889265,"mc":[{"id":"1.168133543","rc":[{"batl":[[0,330,0.15]],"ltp":70.0,"tv":18.0,"id":13306150}]}]}
{"op":"mcm","clk":"991542387","pt":1580504962724,"mc":[{"id":"1.168133543","rc":[{"trd":[[2.28,184.55]],"batb":[[0,2.28,3]],"ltp":2.28,"tv":1298.87,"id":10107355}],"tv":2105.98}]}
{"op":"mcm","clk":"991545800","pt":1580505009118,"mc":[{"id":"1.168133543","rc":[{"batb":[[0,2.82,6.11],[1,2.8,16.71],[2,2.78,2.52]],"ltp":2.8,"tv":499.11,"id":12636},{"batb":[[0,2.28,10.55]],"ltp":2.28,"tv":1298.87,"id":10107355},{"batl":[[0,330,0.35]],"ltp":70.0,"tv":18.0,"id":13306150}]}]}
{"op":"mcm","clk":"991549593","pt":1580505061550,"mc":[{"id":"1.168133543","rc":[{"batb":[[2,8.6,1.99]],"ltp":9.0,"tv":157.39,"id":22121325}]}]}
{"op":"mcm","clk":"991549672","pt":1580505062556,"mc":[{"id":"1.168133543","rc":[{"batb":[[0,2.84,2.52],[1,2.82,6.11],[2,2.8,16.71]],"ltp":2.8,"tv":499.11,"id":12636},{"batb":[[2,50,2.18]],"ltp":90.0,"tv":1.88,"id":7226819},{"batb":[[0,9.4,1.83],[1,9.2,4.5],[2,9,7.15]],"ltp":8.6,"tv":117.26,"id":10163711},{"batb":[[0,9.6,2.52],[1,9.4,10.56],[2,8.8,3.7]],"ltp":9.0,"tv":157.39,"id":22121325},{"batb":[[2,40,2.81]],"ltp":580.0,"tv":6.12,"id":27606066},{"batb":[[1,130,1.71]],"ltp":280.0,"tv":1.32,"id":24270700}]}]}
{"op":"mcm","clk":"991549983","pt":1580505066549,"mc":[{"id":"1.168133543","rc":[{"batb":[[2,9,7.05]],"ltp":8.6,"tv":117.26,"id":10163711},{"batb":[[2,8.8,3.6]],"ltp":9.0,"tv":157.39,"id":22121325}]}]}
{"op":"mcm","clk":"991550005","pt":1580505066861,"mc":[{"id":"1.168133543","rc":[{"batb":[[1,9.2,4.6]],"ltp":8.6,"tv":117.26,"id":10163711},{"batb":[[1,9.4,10.66]],"ltp":9.0,"tv":157.39,"id":22121325}]}]}
{"op":"mcm","clk":"991550258","pt":1580505069686,"mc":[{"id":"1.168133543","rc":[{"batl":[[0,10,2],[1,10.5,2]],"ltp":8.6,"tv":117.26,"id":10163711}]}]}
{"op":"mcm","clk":"991550688","pt":1580505074565,"mc":[{"id":"1.168133543","rc":[{"batb":[[2,8.4,5.95]],"ltp":8.6,"tv":117.26,"id":10163711},{"batb":[[1,9.4,3.91]],"ltp":9.0,"tv":157.39,"id":22121325},{"batb":[[1,130,1.2]],"ltp":280.0,"tv":1.32,"id":24270700}]}]}
{"op":"mcm","clk":"991550744","pt":1580505075189,"mc":[{"id":"1.168133543","rc":[{"batb":[[1,2.82,28.59]],"ltp":2.8,"tv":499.11,"id":12636},{"batb":[[0,9.4,8.58]],"ltp":8.6,"tv":117.26,"id":10163711},{"batb":[[0,9.6,9.12]],"ltp":9.0,"tv":157.39,"id":22121325},{"batb":[[1,140,1.12],[2,120,6.59]],"ltp":280.0,"tv":1.32,"id":24270700}]}]}
{"op":"mcm","clk":"991551244","pt":1580505081911,"mc":[{"id":"1.168133543","rc":[{"batb":[[2,8.4,5]],"ltp":9.0,"tv":157.39,"id":22121325}]}]}
{"op":"mcm","clk":"991551418","pt":1580505084482,"mc":[{"id":"1.168133543","rc":[{"batb":[[0,9.4,1.83]],"ltp":8.6,"tv":117.26,"id":10163711}]}]}
{"op":"mcm","clk":"991551795","pt":1580505089773,"mc":[{"id":"1.168133543","rc":[{"batb":[[2,120,6.26]],"ltp":280.0,"tv":1.32,"id":24270700}]}]}
{"op":"mcm","clk":"991552054","pt":1580505093481,"mc":[{"id":"1.168133543","rc":[{"batb":[[1,120,6.87],[2,90,2]],"ltp":280.0,"tv":1.32,"id":24270700}]}]}
{"op":"mcm","clk":"991552115","pt":1580505094519,"mc":[{"id":"1.168133543","rc":[{"batb":[[0,9.8,4.98],[1,9.6,9.12],[2,9.4,3.91]],"ltp":9.0,"tv":157.39,"id":22121325},{"batb":[[1,130,1.38],[2,120,6]],"ltp":280.0,"tv":1.32,"id":24270700}]}]}
{"op":"mcm","clk":"991552135","pt":1580505094890,"mc":[{"id":"1.168133543","rc":[{"batb":[[0,9.4,3.09]],"ltp":8.6,"tv":117.26,"id":10163711}]}]}
{"op":"mcm","clk":"991552264","pt":1580505096400,"mc":[{"id":"1.168133543","rc":[{"batb":[[2,9.4,3.81]],"ltp":9.0,"tv":157.39,"id":22121325}]}]}
{"op":"mcm","clk":"991552299","pt":1580505096813,"mc":[{"id":"1.168133543","rc":[{"batb":[[1,9.6,9.22]],"ltp":9.0,"tv":157.39,"id":22121325}]}]}
{"op":"mcm","clk":"991552591","pt":1580505101990,"mc":[{"id":"1.168133543","rc":[{"batl":[[1,22,3.27],[2,29,9]],"ltp":8.6,"tv":117.26,"id":10163711},{"batl":[[0,11.5,2],[1,12,3.57]],"ltp":9.0,"tv":157.39,"id":22121325}]}]}
{"op":"mcm","clk":"991552687","pt":1580505103408,"mc":[{"id":"1.168133543","rc":[{"batb":[[1,2.82,6.11]],"ltp":2.8,"tv":499.11,"id":12636},{"batb":[[1,95,1.03],[2,80,1.95]],"ltp":200.0,"tv":1.3,"id":22308007},{"batb":[[0,60,2.61],[1,50,2.18],[2,48,1.04]],"ltp":90.0,"tv":1.88,"id":7226819},{"batb":[[1,9.6,2.62]],"ltp":9.0,"tv":157.39,"id":22121325},{"batb":[[1,70,1.1],[2,60,1.23]],"ltp":150.0,"tv":0.92,"id":26548208},{"batb":[[1,120,6.87],[2,90,2]],"ltp":280.0,"tv":1.32,"id":24270700}]}]}
{"op":"mcm","clk":"991553262","pt":1580505111417,"mc":[{"id":"1.168133543","rc":[{"batl":[[0,11,2.52],[1,11.5,2]],"ltp":9.0,"tv":157.39,"id":22121325},{"batb":[[1,130,1.17],[2,120,6]],"ltp":280.0,"tv":1.32,"id":24270700}]}]}
{"op":"mcm","clk":"991556553","pt":1580505155809,"mc":[{"id":"1.168133543","rc":[{"batl":[[1,13,3.32],[2,13.5,7.94]],"ltp":9.0,"tv":157.39,"id":22121325}]}]}
{"op":"mcm","clk":"991557828","pt":1580505172400,"mc":[{"id":"1.168133543","rc":[{"batl":[[0,12.5,2.22]],"ltp":9.0,"tv":157.39,"id":22121325}]}]}
{"op":"mcm","clk":"991559050","pt":1580505188730,"mc":[{"id":"1.168133543","rc":[{"trd":[[2.84,4]],"batb":[[0,2.82,6.63],[1,2.8,16.71],[2,2.78,2.52]],"ltp":2.84,"tv":503.11,"id":12636}],"tv":2109.98}]}
{"op":"mcm","clk":"991559785","pt":1580505198107,"mc":[{"id":"1.168133543","rc":[{"trd":[[2.84,8]],"batb":[[0,2.84,3.9],[1,2.82,6.11],[2,2.8,16.71]],"ltp":2.84,"tv":507.11,"id":12636}],"tv":2113.98}]}
{"op":"mcm","clk":"991560465","pt":1580505207618,"mc":[{"id":"1.168133543","rc":[{"trd":[[2.84,15.8]],"batb":[[0,2.82,6.11],[1,2.8,16.71],[2,2.78,2.52]],"batl":[[0,2.84,1.1],[1,2.92,4],[2,2.94,58.02]],"ltp":2.84,"tv":514.91,"id":12636}],"tv":2121.78}]}
{"op":"mcm","clk":"991561127","pt":1580505215931,"mc":[{"id":"1.168133543","rc":[{"batl":[[0,2.92,14.54],[1,2.94,58.02],[2,2.96,50]],"ltp":2.84,"tv":514.91,"id":12636}]}]}
{"op":"mcm","clk":"991562433","pt":1580505233554,"mc":[{"id":"1.168133543","rc":[{"batl":[[0,2.92,64.54]],"ltp":2.84,"tv":514.91,"id":12636}]}]}
{"op":"mcm","clk":"991563219","pt":1580505244463,"mc":[{"id":"1.168133543","rc":[{"batb":[[0,10,1.72],[1,9.8,4.98],[2,9.6,2.62]],"ltp":9.0,"tv":157.39,"id":22121325}]}]}
{"op":"mcm","clk":"991563691","pt":1580505250478,"mc":[{"id":"1.168133543","rc":[{"batb":[[2,9.6,2.52]],"ltp":9.0,"tv":157.39,"id":22121325}]}]}
{"op":"mcm","clk":"991563749","pt":1580505251420,"mc":[{"id":"1.168133543","rc":[{"batb":[[1,9.8,5.07]],"ltp":9.0,"tv":157.39,"id":22121325}]}]}
{"op":"mcm","clk":"991564660","pt":1580505262529,"mc":[{"id":"1.168133543","rc":[{"batl":[[0,12,2],[1,12.5,2.22],[2,13,3.32]],"ltp":9.0,"tv":157.39,"id":22121325}]}]}
{"op":"mcm","clk":"991565589","pt":1580505275215,"mc":[{"id":"1.168133543","rc":[{"batl":[[1,13,3.32],[2,13.5,7.94]],"ltp":9.0,"tv":157.39,"id":22121325}]}]}
{"op":"mcm","clk":"991565662","pt":1580505276319,"mc":[{"id":"1.168133543","rc":[{"batl":[[0,11.5,2.41],[1,12,2],[2,13,3.32]],"ltp":9.0,"tv":157.39,"id":22121325}]}]}
{"op":"mcm","clk":"991566289","pt":1580505284115,"mc":[{"id":"1.168133543","rc":[{"batl":[[1,2.38,56]],"ltp":2.28,"tv":1298.87,"id":10107355}]}]}
{"op":"mcm","clk":"991568602","pt":1580505316470,"mc":[{"id":"1.168133543","rc":[{"batl":[[1,13,3.32],[2,13.5,7.94]],"ltp":9.0,"tv":157.39,"id":22121325}]}]}
{"op":"mcm","clk":"991568653","pt":1580505317359,"mc":[{"id":"1.168133543","rc":[{"batl":[[0,12.5,2.22]],"ltp":9.0,"tv":157.39,"id":22121325}]}]}
{"op":"mcm","clk":"991575976","pt":1580505423227,"mc":[{"id":"1.168133543","rc":[{"batl":[[0,12,2],[1,12.5,2.22],[2,13,3.32]],"ltp":9.0,"tv":157.39,"id":22121325}]}]}
{"op":"mcm","clk":"991577087","pt":1580505438541,"mc":[{"id":"1.168133543","rc":[{"batl":[[1,13,3.32],[2,13.5,7.94]],"ltp":9.0,"tv":157.39,"id":22121325}]}]}
{"op":"mcm","clk":"991577132","pt":1580505439009,"mc":[{"id":"1.168133543","rc":[{"batl":[[0,11.5,2.41],[1,12,2],[2,13,3.32]],"ltp":9.0,"tv":157.39,"id":22121325}]}]}
{"op":"mcm","clk":"991578787","pt":1580505459483,"mc":[{"id":"1.168133543","rc":[{"trd":[[60,4.66],[65,1.05]],"batb":[[0,50,2.18],[1,48,1.04],[2,46,1.08]],"batl":[[0,60,2.39],[1,95,8.09],[2,510,9.15]],"ltp":60.0,"tv":7.09,"id":7226819}],"tv":2126.99}]}
{"op":"mcm","clk":"991580274","pt":1580505476381,"mc":[{"id":"1.168133543","rc":[{"batl":[[1,13,3.32],[2,13.5,7.94]],"ltp":9.0,"tv":157.39,"id":22121325}]}]}
{"op":"mcm","clk":"991580563","pt":1580505479399,"mc":[{"id":"1.168133543","rc":[{"batl":[[0,12.5,2.22]],"ltp":9.0,"tv":157.39,"id":22121325}]}]}
{"op":"mcm","clk":"991588465","pt":1580505580440,"mc":[{"id":"1.168133543","rc":[{"batb":[[1,140,4.45],[2,120,6.26]],"ltp":280.0,"tv":1.32,"id":24270700}]}]}
{"op":"mcm","clk":"991588720","pt":1580505584540,"mc":[{"id":"1.168133543","rc":[{"batl":[[0,12,2],[1,12.5,2.22],[2,13,3.32]],"ltp":9.0,"tv":157.39,"id":22121325}]}]}
{"op":"mcm","clk":"991589719","pt":1580505599554,"mc":[{"id":"1.168133543","rc":[{"batl":[[0,11.5,2.41],[1,12,2]],"ltp":9.0,"tv":157.39,"id":22121325}]}]}
{"op":"mcm","clk":"991591467","pt":1580505618450,"mc":[{"id":"1.168133543","rc":[{"batl":[[0,10,68]],"ltp":8.6,"tv":117.26,"id":10163711}]}]}
{"op":"mcm","clk":"991591570","pt":1580505619437,"mc":[{"id":"1.168133543","rc":[{"batb":[[0,2.82,28.59]],"ltp":2.84,"tv":514.91,"id":12636},{"batb":[[1,95,1.7]],"ltp":200.0,"tv":1.3,"id":22308007},{"batb":[[0,50,3.45]],"ltp":60.0,"tv":7.09,"id":7226819},{"batb":[[0,10,8.06]],"ltp":9.0,"tv":157.39,"id":22121325},{"batb":[[1,75,1.23],[2,65,1.49]],"ltp":150.0,"tv":0.92,"id":26548208},{"batb":[[1,150,1.12],[2,140,3.84]],"ltp":280.0,"tv":1.32,"id":24270700}]}]}
{"op":"mcm","clk":"991592230","pt":1580505628527,"mc":[{"id":"1.168133543","rc":[{"batb":[[1,100,1.13],[2,85,1.43]],"ltp":200.0,"tv":1.3,"id":22308007}]}]}
{"op":"mcm","clk":"991592992","pt":1580505637468,"mc":[{"id":"1.168133543","rc":[{"batl":[[1,13,3.32],[2,13.5,7.94]],"ltp":9.0,"tv":157.39,"id":22121325}]}]}
{"op":"mcm","clk":"991593062","pt":1580505638461,"mc":[{"id":"1.168133543","rc":[{"batb":[[0,2.82,6.11]],"ltp":2.84,"tv":514.91,"id":12636}]}]}
{"op":"mcm","clk":"991593283","pt":1580505640980,"mc":[{"id":"1.168133543","rc":[{"batl":[[0,12.5,2.22]],"ltp":9.0,"tv":157.39,"id":22121325},{"batb":[[1,150,1.39],[2,140,3.54]],"ltp":280.0,"tv":1.32,"id":24270700}]}]}
{"op":"mcm","clk":"991594024","pt":1580505649071,"mc":[{"id":"1.168133543","rc":[{"batb":[[2,2.24,48]],"ltp":2.28,"tv":1298.87,"id":10107355}]}]}
{"op":"mcm","clk":"991594410","pt":1580505653083,"mc":[{"id":"1.168133543","rc":[{"batl":[[0,9.8,3],[1,10,68],[2,22,3.27]],"ltp":8.6,"tv":117.26,"id":10163711}]}]}
{"op":"mcm","clk":"991602734","pt":1580505744523,"mc":[{"id":"1.168133543","rc":[{"batl":[[0,12,2],[1,12.5,2.22],[2,13,3.32]],"ltp":9.0,"tv":157.39,"id":22121325}]}]}
{"op":"mcm","clk":"991603076","pt":1580505749323,"mc":[{"id":"1.168133543","rc":[{"batb":[[0,2.82,28.59]],"ltp":2.84,"tv":514.91,"id":12636}]}]}
{"op":"mcm","clk":"991613669","pt":1580505760449,"mc":[{"id":"1.168133543","rc":[{"batb":[[0,2.82,6.11]],"ltp":2.84,"tv":514.91,"id":12636}]}]}
{"op":"mcm","clk":"991613901","pt":1580505763164,"mc":[{"id":"1.168133543","rc":[{"batl":[[0,11.5,2.41],[1,12,2]],"ltp":9.0,"tv":157.39,"id":22121325}]}]}
{"op":"mcm","clk":"991614532","pt":1580505771353,"mc":[{"id":"1.168133543","rc":[{"batb":[[0,2.82,28.59]],"ltp":2.84,"tv":514.91,"id":12636}]}]}
{"op":"mcm","clk":"991616788","pt":1580505798547,"mc":[{"id":"1.168133543","rc":[{"batl":[[1,13,3.32],[2,13.5,7.94]],"ltp":9.0,"tv":157.39,"id":22121325}]}]}
{"op":"mcm","clk":"991617268","pt":1580505804533,"mc":[{"id":"1.168133543","rc":[{"batl":[[0,12.5,2.22]],"ltp":9.0,"tv":157.39,"id":22121325}]}]}
{"op":"mcm","clk":"991617352","pt":1580505805537,"mc":[{"id":"1.168133543","rc":[{"batb":[[0,2.82,6.11]],"ltp":2.84,"tv":514.91,"id":12636}]}]}
{"op":"mcm","clk":"991625635","pt":1580505905329,"mc":[{"id":"1.168133543","rc":[{"batl":[[0,12,2],[1,12.5,2.22],[2,13,3.32]],"ltp":9.0,"tv":157.39,"id":22121325}]}]}
{"op":"mcm","clk":"991625782","pt":1580505907403,"mc":[{"id":"1.168133543","rc":[{"batl":[[0,11.5,2.41],[1,12,2]],"ltp":9.0,"tv":157.39,"id":22121325}]}]}
{"op":"mcm","clk":"991626422","pt":1580505916410,"mc":[{"id":"1.168133543","rc":[{"batb":[[0,2.82,28.59]],"ltp":2.84,"tv":514.91,"id":12636}]}]}
{"op":"mcm","clk":"991626471","pt":1580505917336,"mc":[{"id":"1.168133543","rc":[{"trd":[[2.34,63.44]],"batl":[[0,2.34,21.27]],"ltp":2.34,"tv":1319.66,"id":10107355}],"tv":2147.77}]}
{"op":"mcm","clk":"991629364","pt":1580505959513,"mc":[{"id":"1.168133543","rc":[{"batl":[[1,13,3.32],[2,13.5,7.94]],"ltp":9.0,"tv":157.39,"id":22121325}]}]}
{"op":"mcm","clk":"991629533","pt":1580505961390,"mc":[{"id":"1.168133543","rc":[{"batb":[[0,2.82,6.11]],"ltp":2.84,"tv":514.91,"id":12636}]}]}
{"op":"mcm","clk":"991630113","pt":1580505969408,"mc":[{"id":"1.168133543","rc":[{"batl":[[0,12.5,2.22]],"ltp":9.0,"tv":157.39,"id":22121325}]}]}
{"op":"mcm","clk":"991630848","pt":1580505980331,"mc":[{"id":"1.168133543","rc":[{"trd":[[2.82,12.22]],"batb":[[0,2.8,16.71],[1,2.78,2.52],[2,2.76,56.46]],"batl":[[0,2.82,18.89],[1,2.92,54],[2,2.94,58.02]],"ltp":2.82,"tv":527.13,"id":12636}],"tv":2159.99}]}
{"op":"mcm","clk":"991630982","pt":1580505983342,"mc":[{"id":"1.168133543","rc":[{"trd":[[2.82,50.01]],"batb":[[0,2.82,3.59],[1,2.8,16.71],[2,2.78,2.52]],"batl":[[0,2.92,50],[1,2.94,58.02],[2,2.96,50]],"ltp":2.82,"tv":564.92,"id":12636}],"tv":2197.78}]}
{"op":"mcm","clk":"991631608","pt":1580505994459,"mc":[{"id":"1.168133543","rc":[{"batb":[[0,2.8,16.71],[1,2.78,2.52],[2,2.76,56.46]],"ltp":2.82,"tv":564.92,"id":12636}]}]}
{"op":"mcm","clk":"991632662","pt":1580506011466,"mc":[{"id":"1.168133543","rc":[{"batb":[[0,10.5,1.9],[1,10,8.06],[2,9.8,5.07]],"ltp":9.0,"tv":157.39,"id":22121325}]}]}
{"op":"mcm","clk":"991632962","pt":1580506016385,"mc":[{"id":"1.168133543","rc":[{"batl":[[0,2.9,4],[1,2.92,50],[2,2.94,58.02]],"ltp":2.82,"tv":564.92,"id":12636},{"batb":[[2,9.8,4.98]],"ltp":9.0,"tv":157.39,"id":22121325}]}]}
{"op":"mcm","clk":"991632985","pt":1580506016660,"mc":[{"id":"1.168133543","rc":[{"batb":[[1,10,8.15]],"ltp":9.0,"tv":157.39,"id":22121325}]}]}
{"op":"mcm","clk":"991635615","pt":1580506065393,"mc":[{"id":"1.168133543","rc":[{"batl":[[0,12,2],[1,12.5,2.22],[2,13,3.32]],"ltp":9.0,"tv":157.39,"id":22121325}]}]}
{"op":"mcm","clk":"991635898","pt":1580506071229,"mc":[{"id":"1.168133543","rc":[{"batl":[[1,13,3.32],[2,13.5,7.94]],"ltp":9.0,"tv":157.39,"id":22121325}]}]}
{"op":"mcm","clk":"991635968","pt":1580506072417,"mc":[{"id":"1.168133543","rc":[{"batb":[[0,2.82,3.59],[1,2.8,16.71],[2,2.78,2.52]],"ltp":2.82,"tv":564.92,"id":12636},{"batl":[[0,11.5,2.41],[1,12,2],[2,13,3.32]],"ltp":9.0,"tv":157.39,"id":22121325}]}]}
{"op":"mcm","clk":"991638598","pt":1580506119137,"mc":[{"id":"1.168133543","rc":[{"batl":[[1,12.5,2]],"ltp":9.0,"tv":157.39,"id":22121325}]}]}
{"op":"mcm","clk":"991641391","pt":1580506162132,"mc":[{"id":"1.168133543","rc":[{"batl":[[0,2.88,10.65],[1,2.9,54],[2,2.92,50]],"ltp":2.82,"tv":564.92,"id":12636}]}]}
{"op":"mcm","clk":"991641669","pt":1580506167376,"mc":[{"id":"1.168133543","rc":[{"batl":[[1,2.9,50]],"ltp":2.82,"tv":564.92,"id":12636}]}]}
{"op":"mcm","clk":"991660798","pt":1580506463276,"mc":[{"id":"1.168133543","rc":[{"trd":[[2.88,21.3]],"batl":[[0,2.9,50],[1,2.92,50],[2,2.94,58.02]],"ltp":2.88,"tv":586.22,"id":12636},{"trd":[[9.8,6]],"batl":[[0,10,68],[1,22,3.27],[2,29,9]],"ltp":9.8,"tv":123.26,"id":10163711},{"trd":[[2.34,91.25]],"batl":[[0,2.34,7.37]],"ltp":2.34,"tv":1347.47,"id":10107355},{"trd":[[10.5,10]],"batb":[[0,10,8.15],[1,9.8,4.98],[2,9.6,2.52]],"ltp":10.5,"tv":167.39,"id":22121325}],"tv":2262.89}]}
{"op":"mcm","clk":"991660869","pt":1580506464364,"mc":[{"id":"1.168133543","rc":[{"trd":[[2.9,15.19]],"batb":[[0,2.8,16.71],[1,2.78,2.52],[2,2.76,56.46]],"batl":[[0,2.9,49.35]],"ltp":2.9,"tv":587.52,"id":12636},{"trd":[[210,0.32]],"batl":[[0,210,7.87]],"ltp":210.0,"tv":1.62,"id":22308007},{"trd":[[60,9.44]],"batl":[[0,95,8.09],[1,510,9.15],[2,550,2]],"ltp":60.0,"tv":11.87,"id":7226819},{"trd":[[10,0.64]],"batl":[[0,10,67.68]],"ltp":10.0,"tv":123.9,"id":10163711},{"trd":[[150,1.36]],"batl":[[0,150,4.78]],"ltp":150.0,"tv":1.36,"id":26548208},{"trd":[[280,0.72]],"batl":[[0,280,4.89]],"ltp":280.0,"tv":1.54,"id":24270700}],"tv":2270.59}]}
{"op":"mcm","clk":"991661021","pt":1580506466952,"mc":[{"id":"1.168133543","rc":[{"batb":[[2,8.4,8.95]],"ltp":10.0,"tv":123.9,"id":10163711}]}]}
{"op":"mcm","clk":"991661162","pt":1580506469281,"mc":[{"id":"1.168133543","rc":[{"batl":[[0,150,5]],"ltp":150.0,"tv":1.36,"id":26548208},{"batl":[[0,280,5]],"ltp":280.0,"tv":1.54,"id":24270700}]}]}
{"op":"mcm","clk":"991661211","pt":1580506469950,"mc":[{"id":"1.168133543","rc":[{"batl":[[0,2.88,4],[1,2.9,49.35],[2,2.92,50]],"ltp":2.9,"tv":587.52,"id":12636}]}]}
{"op":"mcm","clk":"991661564","pt":1580506475388,"mc":[{"id":"1.168133543","rc":[{"batb":[[0,2.82,3.59],[1,2.8,16.71],[2,2.78,2.52]],"ltp":2.9,"tv":587.52,"id":12636}]}]}
{"op":"mcm","clk":"991662323","pt":1580506487293,"mc":[{"id":"1.168133543","rc":[{"batl":[[0,2.9,49.35],[1,2.92,50],[2,2.94,58.02]],"ltp":2.9,"tv":587.52,"id":12636}]}]}
{"op":"mcm","clk":"991663090","pt":1580506497427,"mc":[{"id":"1.168133543","rc":[{"batb":[[0,2.8,16.71],[1,2.78,2.52],[2,2.76,56.46]],"ltp":2.9,"tv":587.52,"id":12636}]}]}
{"op":"mcm","clk":"991663130","pt":1580506498096,"mc":[{"id":"1.168133543","rc":[{"batl":[[1,13,3.32],[2,13.5,7.94]],"ltp":10.5,"tv":167.39,"id":22121325}]}]}
{"op":"mcm","clk":"991664423","pt":1580506517512,"mc":[{"id":"1.168133543","rc":[{"batl":[[0,12.5,2.22]],"ltp":10.5,"tv":167.39,"id":22121325}]}]}
{"op":"mcm","clk":"991665024","pt":1580506526973,"mc":[{"id":"1.168133543","rc":[{"batl":[[0,2.88,4],[1,2.9,49.35],[2,2.92,50]],"ltp":2.9,"tv":587.52,"id":12636}]}]}
{"op":"mcm","clk":"991665281","pt":1580506531193,"mc":[{"id":"1.168133543","rc":[{"batb":[[0,2.82,5.04],[1,2.8,16.71],[2,2.78,2.52]],"ltp":2.9,"tv":587.52,"id":12636},{"batb":[[0,2.3,3.36],[1,2.28,10.55],[2,2.26,4]],"ltp":2.34,"tv":1347.47,"id":10107355},{"batb":[[0,10,11.51]],"ltp":10.5,"tv":167.39,"id":22121325}]}]}
{"op":"mcm","clk":"991666021","pt":1580506542565,"mc":[{"id":"1.168133543","rc":[{"batb":[[0,10.5,6.04],[1,10,5.17],[2,9.8,4.98]],"ltp":10.5,"tv":167.39,"id":22121325}]}]}
{"op":"mcm","clk":"991666073","pt":1580506543591,"mc":[{"id":"1.168133543","rc":[{"batl":[[0,2.9,49.35],[1,2.92,50],[2,2.94,58.02]],"ltp":2.9,"tv":587.52,"id":12636}]}]}
{"op":"mcm","clk":"991673279","pt":1580506651296,"mc":[{"id":"1.168133543","rc":[{"trd":[[100,1.54],[110,0.52],[120,0.82],[130,0.78],[140,0.34]],"batb":[[0,90,1.21],[1,80,1.64],[2,75,5]],"ltp":100.0,"tv":5.62,"id":22308007}],"tv":2274.59}]}
{"op":"mcm","clk":"991683109","pt":1580506653533,"mc":[{"id":"1.168133543","rc":[{"batb":[[0,85,1.94],[1,80,1.05]],"ltp":100.0,"tv":5.62,"id":22308007}]}]}
{"op":"mcm","clk":"991683172","pt":1580506654409,"mc":[{"id":"1.168133543","rc":[{"trd":[[2.34,105.99]],"batb":[[0,2.32,7.42],[1,2.3,3.36],[2,2.28,3]],"batl":[[0,2.38,56],[1,2.4,2.23],[2,2.58,27.76]],"ltp":2.34,"tv":1362.21,"id":10107355}],"tv":2289.33}]}
{"op":"mcm","clk":"991683278","pt":1580506655817,"mc":[{"id":"1.168133543","rc":[{"batl":[[0,210,8.07]],"ltp":100.0,"tv":5.62,"id":22308007}]}]}
{"op":"mcm","clk":"991685064","pt":1580506684073,"mc":[{"id":"1.168133543","rc":[{"batb":[[0,11,1.56],[1,10.5,6.04],[2,10,3.45]],"ltp":10.5,"tv":167.39,"id":22121325}]}]}
{"op":"mcm","clk":"991687430","pt":1580506722205,"mc":[{"id":"1.168133543","rc":[{"batb":[[0,2.8,16.71],[1,2.78,2.52],[2,2.76,56.46]],"ltp":2.9,"tv":587.52,"id":12636},{"batb":[[1,2.28,3],[2,2.26,4]],"ltp":2.34,"tv":1362.21,"id":10107355},{"batb":[[2,9.8,5.07]],"ltp":10.5,"tv":167.39,"id":22121325}]}]}
{"op":"mcm","clk":"991688113","pt":1580506731517,"mc":[{"id":"1.168133543","rc":[{"batb":[[1,10,6.43],[2,9.8,4.98]],"ltp":10.5,"tv":167.39,"id":22121325}]}]}
{"op":"mcm","clk":"991688170","pt":1580506732294,"mc":[{"id":"1.168133543","rc":[{"batl":[[0,2.88,4],[1,2.9,49.35],[2,2.92,50]],"ltp":2.9,"tv":587.52,"id":12636}]}]}
{"op":"mcm","clk":"991691167","pt":1580506771281,"mc":[{"id":"1.168133543","rc":[{"batl":[[0,200,2.2],[1,210,7.87],[2,330,0.15]],"ltp":100.0,"tv":5.62,"id":22308007}]}]}
{"op":"mcm","clk":"991701675","pt":1580506933304,"mc":[{"id":"1.168133543","rc":[{"trd":[[10,0.88],[11,9.19]],"batb":[[0,10,5.99],[1,9.8,4.98],[2,9.6,2.52]],"ltp":10.0,"tv":171.39,"id":22121325}],"tv":2293.33}]}
{"op":"mcm","clk":"991701823","pt":1580506935385,"mc":[{"id":"1.168133543","rc":[{"batl":[[0,12.5,2.3]],"ltp":10.0,"tv":171.39,"id":22121325}]}]}
{"op":"mcm","clk":"991704567","pt":1580506980376,"mc":[{"id":"1.168133543","rc":[{"batl":[[0,12,2.08],[1,12.5,2.22],[2,13,3.32]],"ltp":10.0,"tv":171.39,"id":22121325}]}]}
{"op":"mcm","clk":"991705581","pt":1580506998357,"mc":[{"id":"1.168133543","rc":[{"batl":[[1,29,9.24],[2,330,0.15]],"ltp":10.0,"tv":123.9,"id":10163711},{"batl":[[0,11.5,2.41],[1,12,2.08]],"ltp":10.0,"tv":171.39,"id":22121325}]}]}
{"op":"mcm","clk":"991705687","pt":1580507000571,"mc":[{"id":"1.168133543","rc":[{"batb":[[0,2.82,3.59],[1,2.8,16.71],[2,2.78,2.52]],"ltp":2.9,"tv":587.52,"id":12636},{"trd":[[80,2.1],[85,2.2],[90,0.62],[95,1.06]],"batb":[[0,75,5],[1,48,2.29],[2,16,3.03]],"batl":[[0,200,2.21]],"ltp":80.0,"tv":11.59,"id":22308007}],"tv":2299.31}]}
{"op":"mcm","clk":"991705831","pt":1580507003361,"mc":[{"id":"1.168133543","rc":[{"batl":[[0,200,2.01]],"ltp":80.0,"tv":11.59,"id":22308007}]}]}
{"op":"mcm","clk":"991706089","pt":1580507008699,"mc":[{"id":"1.168133543","rc":[{"batl":[[0,200,2.21]],"ltp":80.0,"tv":11.59,"id":22308007}]}]}
{"op":"mcm","clk":"991706404","pt":1580507014491,"mc":[{"id":"1.168133543","rc":[{"batl":[[0,200,2.01]],"ltp":80.0,"tv":11.59,"id":22308007}]}]}
{"op":"mcm","clk":"991706706","pt":1580507020118,"mc":[{"id":"1.168133543","rc":[{"batl":[[0,2.9,49.35],[1,2.92,50],[2,2.94,58.02]],"ltp":2.9,"tv":587.52,"id":12636},{"batl":[[0,200,2.21]],"ltp":80.0,"tv":11.59,"id":22308007}]}]}
{"op":"mcm","clk":"991706867","pt":1580507023527,"mc":[{"id":"1.168133543","rc":[{"batb":[[0,2.8,16.71],[1,2.78,2.52],[2,2.76,56.46]],"ltp":2.9,"tv":587.52,"id":12636},{"batb":[[0,9.8,4.98],[1,9.6,2.52],[2,9.4,1.98]],"ltp":10.0,"tv":171.39,"id":22121325}]}]}
{"op":"mcm","clk":"991707013","pt":1580507026017,"mc":[{"id":"1.168133543","rc":[{"batl":[[0,200,2.01]],"ltp":80.0,"tv":11.59,"id":22308007}]}]}
{"op":"mcm","clk":"991707332","pt":1580507031426,"mc":[{"id":"1.168133543","rc":[{"batl":[[0,200,2.21]],"ltp":80.0,"tv":11.59,"id":22308007}]}]}
{"op":"mcm","clk":"991707482","pt":1580507034335,"mc":[{"id":"1.168133543","rc":[{"batb":[[0,10,5.99],[1,9.8,4.98],[2,9.6,2.52]],"batl":[[1,13,3.4],[2,13.5,7.94]],"ltp":10.0,"tv":171.39,"id":22121325}]}]}
{"op":"mcm","clk":"991707679","pt":1580507038515,"mc":[{"id":"1.168133543","rc":[{"batl":[[0,200,2.01]],"ltp":80.0,"tv":11.59,"id":22308007},{"batl":[[0,13,3.4],[1,13.5,7.94],[2,16.5,1.94]],"ltp":10.0,"tv":171.39,"id":22121325}]}]}
{"op":"mcm","clk":"991707687","pt":1580507038619,"mc":[{"id":"1.168133543","rc":[{"batl":[[0,12.5,2.3],[1,13,3.32],[2,13.5,7.94]],"ltp":10.0,"tv":171.39,"id":22121325}]}]}
{"op":"mcm","clk":"991707982","pt":1580507043635,"mc":[{"id":"1.168133543","rc":[{"batl":[[0,200,2.21]],"ltp":80.0,"tv":11.59,"id":22308007}]}]}
{"op":"mcm","clk":"991708286","pt":1580507049347,"mc":[{"id":"1.168133543","rc":[{"batl":[[0,200,2.01]],"ltp":80.0,"tv":11.59,"id":22308007}]}]}
{"op":"mcm","clk":"991708497","pt":1580507054160,"mc":[{"id":"1.168133543","rc":[{"batl":[[0,2.88,4],[1,2.9,49.35],[2,2.92,50]],"ltp":2.9,"tv":587.52,"id":12636}]}]}
{"op":"mcm","clk":"991708546","pt":1580507055042,"mc":[{"id":"1.168133543","rc":[{"batl":[[0,200,2.21]],"ltp":80.0,"tv":11.59,"id":22308007}]}]}
{"op":"mcm","clk":"991708910","pt":1580507061535,"mc":[{"id":"1.168133543","rc":[{"batl":[[0,200,2.01]],"ltp":80.0,"tv":11.59,"id":22308007}]}]}
{"op":"mcm","clk":"991709183","pt":1580507066360,"mc":[{"id":"1.168133543","rc":[{"batl":[[0,200,2.21]],"ltp":80.0,"tv":11.59,"id":22308007}]}]}
{"op":"mcm","clk":"991709512","pt":1580507072975,"mc":[{"id":"1.168133543","rc":[{"batl":[[0,200,2.01]],"ltp":80.0,"tv":11.59,"id":22308007}]}]}
{"op":"mcm","clk":"991709621","pt":1580507075358,"mc":[{"id":"1.168133543","rc":[{"batb":[[0,1000,329.02]],"ltp":1000.0,"tv":3.75,"id":13819977}]}]}
{"op":"mcm","clk":"991709786","pt":1580507078553,"mc":[{"id":"1.168133543","rc":[{"batl":[[0,200,2.21]],"ltp":80.0,"tv":11.59,"id":22308007}]}]}
{"op":"mcm","clk":"991710083","pt":1580507084493,"mc":[{"id":"1.168133543","rc":[{"batl":[[0,200,2.01]],"ltp":80.0,"tv":11.59,"id":22308007}]}]}
{"op":"mcm","clk":"991710266","pt":1580507088112,"mc":[{"id":"1.168133543","rc":[{"trd":[[80,2.12]],"batb":[[0,75,5.05]],"batl":[[0,200,2]],"ltp":80.0,"tv":11.61,"id":22308007}],"tv":2299.33}]}
{"op":"mcm","clk":"991710407","pt":1580507090084,"mc":[{"id":"1.168133543","rc":[{"batl":[[0,200,2.2]],"ltp":80.0,"tv":11.61,"id":22308007}]}]}
{"op":"mcm","clk":"991710509","pt":1580507091900,"mc":[{"id":"1.168133543","rc":[{"batb":[[1,48,2.3]],"ltp":80.0,"tv":11.61,"id":22308007}]}]}
{"op":"mcm","clk":"991713531","pt":1580507140521,"mc":[{"id":"1.168133543","rc":[{"batl":[[0,12,2.08],[1,12.5,2.22],[2,13,3.32]],"ltp":10.0,"tv":171.39,"id":22121325}]}]}
{"op":"mcm","clk":"991714821","pt":1580507161440,"mc":[{"id":"1.168133543","rc":[{"batl":[[0,11.5,2.41],[1,12,2.08]],"ltp":10.0,"tv":171.39,"id":22121325}]}]}
{"op":"mcm","clk":"991715173","pt":1580507167559,"mc":[{"id":"1.168133543","rc":[{"batb":[[0,150,2.68],[1,100,1.15],[2,85,1.45]],"ltp":70.0,"tv":18.0,"id":13306150}]}]}
{"op":"mcm","clk":"991715244","pt":1580507168542,"mc":[{"id":"1.168133543","rc":[{"batb":[[0,9.8,4.98],[1,9.6,2.52],[2,9.4,1.98]],"ltp":10.0,"tv":171.39,"id":22121325},{"batb":[[0,150,3.19]],"ltp":70.0,"tv":18.0,"id":13306150}]}]}
{"op":"mcm","clk":"991715598","pt":1580507173571,"mc":[{"id":"1.168133543","rc":[{"trd":[[160,1.02]],"batb":[[0,150,1.19]],"ltp":160.0,"tv":19.01,"id":13306150}],"tv":2300.34}]}
{"op":"mcm","clk":"991716907","pt":1580507194269,"mc":[{"id":"1.168133543","rc":[{"batl":[[1,13,3.4],[2,13.5,7.94]],"ltp":10.0,"tv":171.39,"id":22121325}]}]}
{"op":"mcm","clk":"991717311","pt":1580507201504,"mc":[{"id":"1.168133543","rc":[{"batb":[[0,10,5.99],[1,9.8,4.98],[2,9.6,2.52]],"ltp":10.0,"tv":171.39,"id":22121325}]}]}
{"op":"mcm","clk":"991717370","pt":1580507202178,"mc":[{"id":"1.168133543","rc":[{"batl":[[0,13,3.4],[1,13.5,7.94],[2,16.5,1.94]],"ltp":10.0,"tv":171.39,"id":22121325}]}]}
{"op":"mcm","clk":"991717467","pt":1580507203525,"mc":[{"id":"1.168133543","rc":[{"batl":[[0,12.5,2.3],[1,13,3.32],[2,13.5,7.94]],"ltp":10.0,"tv":171.39,"id":22121325}]}]}
{"op":"mcm","clk":"991723277","pt":1580507301034,"mc":[{"id":"1.168133543","rc":[{"batl":[[0,12,2.08],[1,12.5,2.22],[2,13,3.32]],"ltp":10.0,"tv":171.39,"id":22121325}]}]}
{"op":"mcm","clk":"991723506","pt":1580507305452,"mc":[{"id":"1.168133543","rc":[{"batl":[[0,11.5,2.41],[1,12,2.08]],"ltp":10.0,"tv":171.39,"id":22121325}]}]}
{"op":"mcm","clk":"991723870","pt":1580507312483,"mc":[{"id":"1.168133543","rc":[{"batb":[[0,9.8,4.98],[1,9.6,2.52],[2,9.4,1.98]],"ltp":10.0,"tv":171.39,"id":22121325}]}]}
{"op":"mcm","clk":"991726196","pt":1580507354921,"mc":[{"id":"1.168133543","rc":[{"batl":[[1,13,3.4],[2,13.5,7.94]],"ltp":10.0,"tv":171.39,"id":22121325}]}]}
{"op":"mcm","clk":"991726364","pt":1580507357322,"mc":[{"id":"1.168133543","rc":[{"batb":[[0,10,5.99],[1,9.8,4.98],[2,9.6,2.52]],"ltp":10.0,"tv":171.39,"id":22121325}]}]}
{"op":"mcm","clk":"991726959","pt":1580507366549,"mc":[{"id":"1.168133543","rc":[{"batl":[[0,13,3.4],[1,13.5,7.94],[2,16.5,1.94]],"ltp":10.0,"tv":171.39,"id":22121325}]}]}
{"op":"mcm","clk":"991726996","pt":1580507367123,"mc":[{"id":"1.168133543","rc":[{"trd":[[2.32,14]],"batb":[[0,2.28,3.43],[1,2.26,4],[2,2.24,48]],"ltp":2.32,"tv":1376.2,"id":10107355},{"batl":[[0,12.5,2.3],[1,13,3.32],[2,13.5,7.94]],"ltp":10.0,"tv":171.39,"id":22121325}],"tv":2314.34}]}
{"op":"mcm","clk":"991727578","pt":1580507376421,"mc":[{"id":"1.168133543","rc":[{"trd":[[2.28,189.69],[2.32,14.85]],"batb":[[0,2.26,4.43],[1,2.24,48],[2,2.22,14.62]],"ltp":2.28,"tv":1382.2,"id":10107355}],"tv":2320.34}]}
{"op":"mcm","clk":"991727751","pt":1580507379464,"mc":[{"id":"1.168133543","rc":[{"batb":[[0,2.26,12.65]],"ltp":2.28,"tv":1382.2,"id":10107355}]}]}
{"op":"mcm","clk":"991727923","pt":1580507381969,"mc":[{"id":"1.168133543","rc":[{"trd":[[2.26,74.92],[2.28,190.55]],"batb":[[0,2.26,8.65]],"ltp":2.26,"tv":1390.2,"id":10107355}],"tv":2328.34}]}
{"op":"mcm","clk":"991728188","pt":1580507385853,"mc":[{"id":"1.168133543","rc":[{"batl":[[0,2.36,4],[1,2.38,56],[2,2.4,2.23]],"ltp":2.26,"tv":1390.2,"id":10107355}]}]}
{"op":"mcm","clk":"991728467","pt":1580507389378,"mc":[{"id":"1.168133543","rc":[{"trd":[[2.26,90.92]],"batb":[[0,2.24,48.65],[1,2.22,14.62],[2,2.2,100]],"ltp":2.26,"tv":1406.2,"id":10107355}],"tv":2344.34}]}
{"op":"mcm","clk":"991728909","pt":1580507396481,"mc":[{"id":"1.168133543","rc":[{"trd":[[2.24,147.12],[2.26,92.22]],"batb":[[0,2.24,12.87]],"ltp":2.24,"tv":1502.2,"id":10107355}],"tv":2440.34}]}
{"op":"mcm","clk":"991728970","pt":1580507397359,"mc":[{"id":"1.168133543","rc":[{"batb":[[2,2.2,103.33]],"ltp":2.24,"tv":1502.2,"id":10107355}]}]}
{"op":"mcm","clk":"991729325","pt":1580507402433,"mc":[{"id":"1.168133543","rc":[{"batb":[[0,50,2.76]],"ltp":60.0,"tv":11.87,"id":7226819}]}]}
{"op":"mcm","clk":"991729376","pt":1580507403160,"mc":[{"id":"1.168133543","rc":[{"batb":[[0,2.82,2.52],[1,2.8,16.71],[2,2.78,2.52]],"ltp":2.9,"tv":587.52,"id":12636},{"batb":[[1,50,2.53],[2,48,2.29]],"ltp":80.0,"tv":11.61,"id":22308007},{"batb":[[2,46,3.6]],"ltp":60.0,"tv":11.87,"id":7226819},{"batb":[[0,2.26,2.52],[1,2.24,12.87],[2,2.22,14.62]],"ltp":2.24,"tv":1502.2,"id":10107355},{"batb":[[0,10.5,2.52],[1,10,5.99],[2,9.8,4.98]],"ltp":10.0,"tv":171.39,"id":22121325},{"batb":[[1,150,2.5]],"ltp":280.0,"tv":1.54,"id":24270700}]}]}
{"op":"mcm","clk":"991729712","pt":1580507408137,"mc":[{"id":"1.168133543","rc":[{"batl":[[0,2.38,56],[1,2.4,2.23],[2,2.58,27.76]],"ltp":2.24,"tv":1502.2,"id":10107355}]}]}
{"op":"mcm","clk":"991730056","pt":1580507413444,"mc":[{"id":"1.168133543","rc":[{"batb":[[1,160,1.39],[2,150,1.12]],"ltp":280.0,"tv":1.54,"id":24270700}]}]}
{"op":"mcm","clk":"991730775","pt":1580507424476,"mc":[{"id":"1.168133543","rc":[{"batl":[[0,2.36,6.36],[1,2.38,56],[2,2.4,2.23]],"ltp":2.24,"tv":1502.2,"id":10107355}]}]}
{"op":"mcm","clk":"991733584","pt":1580507471021,"mc":[{"id":"1.168133543","rc":[{"trd":[[50,1.53],[55,2.25]],"batb":[[0,50,1.08]],"ltp":50.0,"tv":15.25,"id":7226819}],"tv":2443.72}]}
{"op":"mcm","clk":"991733778","pt":1580507474530,"mc":[{"id":"1.168133543","rc":[{"trd":[[2.26,96.22]],"batb":[[0,2.24,13.39],[1,2.22,14.62],[2,2.2,100]],"ltp":2.26,"tv":1506.2,"id":10107355}],"tv":2447.72}]}
{"op":"mcm","clk":"991733902","pt":1580507476954,"mc":[{"id":"1.168133543","rc":[{"batl":[[0,95,8.11]],"ltp":50.0,"tv":15.25,"id":7226819}]}]}
{"op":"mcm","clk":"991734096","pt":1580507480547,"mc":[{"id":"1.168133543","rc":[{"batb":[[0,48,2.16],[1,46,3.6],[2,42,1.86]],"ltp":50.0,"tv":15.25,"id":7226819}]}]}
{"op":"mcm","clk":"991734220","pt":1580507483079,"mc":[{"id":"1.168133543","rc":[{"trd":[[2.24,172.08],[2.26,97.26]],"batb":[[0,2.22,15.01],[1,2.2,100],[2,2,61.02]],"ltp":2.24,"tv":1532.2,"id":10107355}],"tv":2473.72}]}
{"op":"mcm","clk":"991734683","pt":1580507490168,"mc":[{"id":"1.168133543","rc":[{"trd":[[2.22,74.72],[2.24,172.86]],"batb":[[0,2.2,100.02],[1,2.02,6]],"ltp":2.22,"tv":1562.2,"id":10107355}],"tv":2503.72}]}
{"op":"mcm","clk":"991734751","pt":1580507491369,"mc":[{"id":"1.168133543","rc":[{"batb":[[0,2.2,100]],"ltp":2.22,"tv":1562.2,"id":10107355}]}]}
{"op":"mcm","clk":"991735106","pt":1580507497568,"mc":[{"id":"1.168133543","rc":[{"batb":[[2,2,52.4]],"ltp":2.22,"tv":1562.2,"id":10107355}]}]}
{"op":"mcm","clk":"991736209","pt":1580507515221,"mc":[{"id":"1.168133543","rc":[{"batl":[[0,2.34,2],[1,2.36,6.36],[2,2.38,56]],"ltp":2.22,"tv":1562.2,"id":10107355}]}]}
{"op":"mcm","clk":"991736687","pt":1580507522488,"mc":[{"id":"1.168133543","rc":[{"batb":[[0,2.22,2.52],[1,2.2,100],[2,2.02,6]],"ltp":2.22,"tv":1562.2,"id":10107355}]}]}
{"op":"mcm","clk":"991748369","pt":1580507553362,"mc":[{"id":"1.168133543","rc":[{"batb":[[0,2.82,7.47],[1,2.8,11.76]],"ltp":2.9,"tv":587.52,"id":12636},{"batb":[[0,9.4,5.07],[1,9.2,2.62]],"ltp":10.0,"tv":123.9,"id":10163711},{"batb":[[0,11,1.98],[1,10.5,2.52],[2,10,5.99]],"ltp":10.0,"tv":171.39,"id":22121325}]}]}
{"op":"mcm","clk":"991749254","pt":1580507567379,"mc":[{"id":"1.168133543","rc":[{"batb":[[2,9.8,4.98]],"ltp":10.0,"tv":171.39,"id":22121325}]}]}
{"op":"mcm","clk":"991749287","pt":1580507567850,"mc":[{"id":"1.168133543","rc":[{"batl":[[0,2.36,6.36],[1,2.38,56],[2,2.4,2.23]],"ltp":2.22,"tv":1562.2,"id":10107355}]}]}
{"op":"mcm","clk":"991749375","pt":1580507569449,"mc":[{"id":"1.168133543","rc":[{"batl":[[0,2.9,49.35],[1,2.92,50],[2,2.94,58.02]],"ltp":2.9,"tv":587.52,"id":12636}]}]}
{"op":"mcm","clk":"991750143","pt":1580507582552,"mc":[{"id":"1.168133543","rc":[{"batb":[[1,10,2.52]],"ltp":10.0,"tv":171.39,"id":22121325}]}]}
{"op":"mcm","clk":"991750828","pt":1580507593383,"mc":[{"id":"1.168133543","rc":[{"batb":[[1,10,8.51]],"ltp":10.0,"tv":171.39,"id":22121325}]}]}
{"op":"mcm","clk":"991752144","pt":1580507613520,"mc":[{"id":"1.168133543","rc":[{"batb":[[0,48,2.52]],"ltp":50.0,"tv":15.25,"id":7226819}]}]}
{"op":"mcm","clk":"991754315","pt":1580507649356,"mc":[{"id":"1.168133543","rc":[{"batb":[[0,10.5,1.98]],"ltp":10.0,"tv":171.39,"id":22121325}]}]}
{"op":"mcm","clk":"991755907","pt":1580507676870,"mc":[{"id":"1.168133543","rc":[{"trd":[[2.8,32.16],[2.82,64.94]],"batb":[[0,2.8,1.22],[1,2.78,2.52],[2,2.76,56.46]],"ltp":2.8,"tv":623.53,"id":12636}],"tv":2539.73}]}
{"op":"mcm","clk":"991756153","pt":1580507680478,"mc":[{"id":"1.168133543","rc":[{"batl":[[0,2.88,4],[1,2.9,49.35],[2,2.92,50]],"ltp":2.8,"tv":623.53,"id":12636}]}]}
{"op":"mcm","clk":"991757168","pt":1580507695439,"mc":[{"id":"1.168133543","rc":[{"batb":[[0,2.22,31.08]],"ltp":2.22,"tv":1562.2,"id":10107355},{"batb":[[1,10,14.85]],"ltp":10.0,"tv":171.39,"id":22121325}]}]}
{"op":"mcm","clk":"991757180","pt":1580507695591,"mc":[{"id":"1.168133543","rc":[{"batb":[[0,75,5.76]],"ltp":80.0,"tv":11.61,"id":22308007},{"batb":[[0,48,3.84]],"ltp":50.0,"tv":15.25,"id":7226819},{"batb":[[1,75,2.07]],"ltp":150.0,"tv":1.36,"id":26548208}]}]}
{"op":"mcm","clk":"991760019","pt":1580507742104,"mc":[{"id":"1.168133543","rc":[{"batb":[[1,2.78,10.57]],"ltp":2.8,"tv":623.53,"id":12636},{"batb":[[0,2.22,35.15]],"ltp":2.22,"tv":1562.2,"id":10107355}]}]}
{"op":"mcm","clk":"991769506","pt":1580507933171,"mc":[{"id":"1.168133543","rc":[{"batl":[[0,10,66],[1,11.5,1.68],[2,29,9.24]],"ltp":10.0,"tv":123.9,"id":10163711}]}]}
{"op":"mcm","clk":"991776222","pt":1580508068400,"mc":[{"id":"1.168133543","rc":[{"trd":[[2.78,5.92],[2.8,32.14],[2.82,64.92],[2.9,15.18],[2.92,125.02],[2.94,183.97],[2.96,100.02],[3.9,7.56],[4.3,8.4]],"batb":[[1,2.78,10.58]],"ltp":2.8,"tv":623.5,"id":12636},{"batb":[[1,400,4.2]],"ltp":1000.0,"tv":3.76,"id":13819977},{"batb":[[0,75,5.76]],"ltp":80.0,"tv":11.61,"id":22308007},{"trd":[[60,9.44]],"batb":[[0,48,3.84]],"ltp":50.0,"tv":15.25,"id":7226819},{"trd":[[7.6,4],[8.2,24],[8.6,89.26],[9.4,10]],"batb":[[0,9.2,2.7],[1,8.4,8.95],[2,8.2,1.41]],"ltp":9.4,"tv":133.89,"id":10163711},{"trd":[[2.1,5.3],[2.16,13.9],[2.18,23.22],[2.22,74.72],[2.24,172.83],[2.26,97.25],[2.28,190.53],[2.3,400.01],[2.32,14.86],[2.34,105.99],[2.36,13.46],[2.46,144.31],[2.5,17.15],[3.35,6],[3.45,7.96],[3.7,24.36]],"batb":[[0,2.22,35.11]],"ltp":2.22,"tv":1562.16,"id":10107355},{"trd":[[8.8,116.01],[9,3.36]],"batb":[[1,10,14.83],[2,9.8,4.97]],"ltp":10.0,"tv":171.4,"id":22121325},{"batb":[[1,75,2.07]],"ltp":150.0,"tv":1.36,"id":26548208}],"tv":2549.65}]}
{"op":"mcm","clk":"991776423","pt":1580508071497,"mc":[{"id":"1.168133543","rc":[{"batb":[[0,2.8,7.37]],"ltp":2.8,"tv":623.5,"id":12636},{"batb":[[1,8.4,5.95]],"ltp":9.4,"tv":133.89,"id":10163711},{"batb":[[0,2.24,7.69],[1,2.22,35.11],[2,2.2,100]],"ltp":2.22,"tv":1562.16,"id":10107355},{"batb":[[0,10.5,3.62]],"ltp":10.0,"tv":171.4,"id":22121325}]}]}
{"op":"mcm","clk":"991777027","pt":1580508080527,"mc":[{"id":"1.168133543","rc":[{"batb":[[1,2.22,6.59]],"ltp":2.22,"tv":1562.16,"id":10107355},{"batb":[[1,10,2.52]],"ltp":10.0,"tv":171.4,"id":22121325}]}]}
{"op":"mcm","clk":"991777033","pt":1580508080631,"mc":[{"id":"1.168133543","rc":[{"batb":[[0,2.8,33.59]],"ltp":2.8,"tv":623.5,"id":12636},{"batb":[[0,2.24,35.95]],"ltp":2.22,"tv":1562.16,"id":10107355},{"batb":[[0,10.5,15.35]],"ltp":10.0,"tv":171.4,"id":22121325}]}]}
{"op":"mcm","clk":"991777990","pt":1580508093554,"mc":[{"id":"1.168133543","rc":[{"batb":[[0,10.5,3.62]],"ltp":10.0,"tv":171.4,"id":22121325}]}]}
{"op":"mcm","clk":"991779085","pt":1580508108564,"mc":[{"id":"1.168133543","rc":[{"batb":[[0,2.82,3.13],[1,2.8,33.59],[2,2.78,10.58]],"ltp":2.8,"tv":623.5,"id":12636},{"batl":[[0,9.8,3.38],[1,10,66],[2,11.5,1.68]],"ltp":9.4,"tv":133.89,"id":10163711}]}]}
{"op":"mcm","clk":"991779267","pt":1580508111981,"mc":[{"id":"1.168133543","rc":[{"batl":[[0,2.9,49.35],[1,2.92,50],[2,2.94,58.02]],"ltp":2.8,"tv":623.5,"id":12636}]}]}
{"op":"mcm","clk":"991779633","pt":1580508118683,"mc":[{"id":"1.168133543","rc":[{"batb":[[0,2.82,29.16],[1,2.8,7.37]],"ltp":2.8,"tv":623.5,"id":12636}]}]}
{"op":"mcm","clk":"991779833","pt":1580508121561,"mc":[{"id":"1.168133543","rc":[{"batb":[[0,2.84,2.52],[1,2.82,29.16],[2,2.8,7.37]],"ltp":2.8,"tv":623.5,"id":12636},{"batb":[[0,8.6,2.7]],"ltp":9.4,"tv":133.89,"id":10163711},{"batb":[[0,2.26,2.52],[1,2.24,35.95],[2,2.22,6.59]],"ltp":2.22,"tv":1562.16,"id":10107355}]}]}
{"op":"mcm","clk":"991780398","pt":1580508131399,"mc":[{"id":"1.168133543","rc":[{"batb":[[0,8.6,17.42]],"ltp":9.4,"tv":133.89,"id":10163711},{"batb":[[0,10.5,15.35]],"ltp":10.0,"tv":171.4,"id":22121325}]}]}
{"op":"mcm","clk":"991781379","pt":1580508149317,"mc":[{"id":"1.168133543","rc":[{"batb":[[0,2.28,20],[1,2.26,2.52],[2,2.24,35.95]],"ltp":2.22,"tv":1562.16,"id":10107355}]}]}
{"op":"mcm","clk":"991781808","pt":1580508156515,"mc":[{"id":"1.168133543","rc":[{"batb":[[2,2.24,7.69]],"ltp":2.22,"tv":1562.16,"id":10107355}]}]}
{"op":"mcm","clk":"991781837","pt":1580508157001,"mc":[{"id":"1.168133543","rc":[{"batb":[[0,2.3,27.53],[1,2.28,20],[2,2.26,2.52]],"batl":[[0,2.36,18.05]],"ltp":2.22,"tv":1562.16,"id":10107355}]}]}
{"op":"mcm","clk":"991783086","pt":1580508180059,"mc":[{"id":"1.168133543","rc":[{"trd":[[2.3,440.01]],"batb":[[0,2.3,7.53]],"ltp":2.3,"tv":1602.16,"id":10107355}],"tv":2589.66}]}
{"op":"mcm","clk":"991783385","pt":1580508185477,"mc":[{"id":"1.168133543","rc":[{"batl":[[0,2.36,11.69]],"ltp":2.3,"tv":1602.16,"id":10107355}]}]}
{"op":"mcm","clk":"991786591","pt":1580508239164,"mc":[{"id":"1.168133543","rc":[{"trd":[[2.84,35.8]],"batb":[[0,2.84,3.32]],"ltp":2.84,"tv":643.5,"id":12636}],"tv":2609.66}]}
{"op":"mcm","clk":"991787604","pt":1580508256512,"mc":[{"id":"1.168133543","rc":[{"trd":[[2.84,42.44]],"batb":[[0,2.82,29.16],[1,2.8,7.37],[2,2.78,10.58]],"batl":[[0,2.84,1.68],[1,2.9,49.35],[2,2.92,50]],"ltp":2.84,"tv":650.14,"id":12636}],"tv":2616.3}]}
{"op":"mcm","clk":"991789696","pt":1580508290467,"mc":[{"id":"1.168133543","rc":[{"batb":[[0,9,2.32],[1,8.6,17.32],[2,8.4,5.95]],"ltp":9.4,"tv":133.89,"id":10163711}]}]}
{"op":"mcm","clk":"991790124","pt":1580508296473,"mc":[{"id":"1.168133543","rc":[{"batb":[[1,8.8,14.47],[2,8.6,2.52]],"ltp":9.4,"tv":133.89,"id":10163711}]}]}
{"op":"mcm","clk":"991790683","pt":1580508304563,"mc":[{"id":"1.168133543","rc":[{"batb":[[0,2.32,7.43],[1,2.3,7.53],[2,2.28,20]],"ltp":2.3,"tv":1602.16,"id":10107355}]}]}
{"op":"mcm","clk":"991790993","pt":1580508309481,"mc":[{"id":"1.168133543","rc":[{"batb":[[1,8.6,17.32],[2,8.4,5.95]],"ltp":9.4,"tv":133.89,"id":10163711},{"batb":[[1,2.28,20],[2,2.26,2.52]],"ltp":2.3,"tv":1602.16,"id":10107355}]}]}
{"op":"mcm","clk":"991791788","pt":1580508322505,"mc":[{"id":"1.168133543","rc":[{"batb":[[1,8.6,2.6]],"ltp":9.4,"tv":133.89,"id":10163711},{"batb":[[0,10.5,3.62]],"ltp":10.0,"tv":171.4,"id":22121325}]}]}
{"op":"mcm","clk":"991791794","pt":1580508322603,"mc":[{"id":"1.168133543","rc":[{"batb":[[1,8.8,14.47],[2,8.6,2.52]],"ltp":9.4,"tv":133.89,"id":10163711}]}]}
{"op":"mcm","clk":"991792634","pt":1580508335524,"mc":[{"id":"1.168133543","rc":[{"batb":[[1,8.6,2.6],[2,8.4,5.95]],"ltp":9.4,"tv":133.89,"id":10163711}]}]}
{"op":"mcm","clk":"991792656","pt":1580508335834,"mc":[{"id":"1.168133543","rc":[{"batb":[[1,8.6,17.32]],"ltp":9.4,"tv":133.89,"id":10163711},{"batb":[[0,10.5,15.35]],"ltp":10.0,"tv":171.4,"id":22121325}]}]}
{"op":"mcm","clk":"991793175","pt":1580508344323,"mc":[{"id":"1.168133543","rc":[{"batl":[[0,9.6,2],[1,9.8,3.38],[2,10,66]],"ltp":9.4,"tv":133.89,"id":10163711}]}]}
{"op":"mcm","clk":"991793356","pt":1580508347466,"mc":[{"id":"1.168133543","rc":[{"batb":[[1,8.8,14.47],[2,8.6,2.52]],"ltp":9.4,"tv":133.89,"id":10163711},{"batb":[[0,10.5,3.62]],"ltp":10.0,"tv":171.4,"id":22121325}]}]}
{"op":"mcm","clk":"991794027","pt":1580508360456,"mc":[{"id":"1.168133543","rc":[{"batb":[[1,8.6,17.32],[2,8.4,5.95]],"ltp":9.4,"tv":133.89,"id":10163711},{"batb":[[0,10.5,15.35]],"ltp":10.0,"tv":171.4,"id":22121325}]}]}
{"op":"mcm","clk":"991794779","pt":1580508373500,"mc":[{"id":"1.168133543","rc":[{"batb":[[1,8.6,2.6]],"ltp":9.4,"tv":133.89,"id":10163711},{"batb":[[0,10.5,3.62]],"ltp":10.0,"tv":171.4,"id":22121325}]}]}
{"op":"mcm","clk":"991794783","pt":1580508373609,"mc":[{"id":"1.168133543","rc":[{"batb":[[1,8.8,14.47],[2,8.6,2.52]],"ltp":9.4,"tv":133.89,"id":10163711}]}]}
{"op":"mcm","clk":"991795538","pt":1580508385483,"mc":[{"id":"1.168133543","rc":[{"batb":[[1,8.6,17.32],[2,8.4,5.95]],"ltp":9.4,"tv":133.89,"id":10163711},{"batb":[[0,10.5,15.35]],"ltp":10.0,"tv":171.4,"id":22121325}]}]}
{"op":"mcm","clk":"991796328","pt":1580508398523,"mc":[{"id":"1.168133543","rc":[{"batb":[[1,8.6,2.6]],"ltp":9.4,"tv":133.89,"id":10163711},{"batb":[[0,10.5,3.62]],"ltp":10.0,"tv":171.4,"id":22121325}]}]}
{"op":"mcm","clk":"991796339","pt":1580508398626,"mc":[{"id":"1.168133543","rc":[{"batb":[[1,8.8,14.47],[2,8.6,2.52]],"ltp":9.4,"tv":133.89,"id":10163711}]}]}
{"op":"mcm","clk":"991797063","pt":1580508411543,"mc":[{"id":"1.168133543","rc":[{"batb":[[1,8.6,2.6],[2,8.4,5.95]],"ltp":9.4,"tv":133.89,"id":10163711}]}]}
{"op":"mcm","clk":"991797076","pt":1580508411647,"mc":[{"id":"1.168133543","rc":[{"batb":[[1,8.6,17.32]],"ltp":9.4,"tv":133.89,"id":10163711},{"batb":[[0,10.5,15.35]],"ltp":10.0,"tv":171.4,"id":22121325}]}]}
{"op":"mcm","clk":"991797860","pt":1580508424459,"mc":[{"id":"1.168133543","rc":[{"batb":[[1,8.8,14.47],[2,8.6,2.52]],"ltp":9.4,"tv":133.89,"id":10163711},{"batb":[[0,10.5,3.62]],"ltp":10.0,"tv":171.4,"id":22121325}]}]}
{"op":"mcm","clk":"991798644","pt":1580508436478,"mc":[{"id":"1.168133543","rc":[{"batb":[[1,8.6,17.32],[2,8.4,5.95]],"ltp":9.4,"tv":133.89,"id":10163711},{"batb":[[0,10.5,15.35]],"ltp":10.0,"tv":171.4,"id":22121325}]}]}
{"op":"mcm","clk":"991799446","pt":1580508449493,"mc":[{"id":"1.168133543","rc":[{"batb":[[1,8.8,14.47],[2,8.6,2.52]],"ltp":9.4,"tv":133.89,"id":10163711},{"batb":[[0,10.5,3.62]],"ltp":10.0,"tv":171.4,"id":22121325}]}]}
{"op":"mcm","clk":"991809968","pt":1580508462500,"mc":[{"id":"1.168133543","rc":[{"batb":[[1,8.6,17.32],[2,8.4,5.95]],"ltp":9.4,"tv":133.89,"id":10163711},{"batb":[[0,10.5,15.35]],"ltp":10.0,"tv":171.4,"id":22121325}]}]}
{"op":"mcm","clk":"991810773","pt":1580508475554,"mc":[{"id":"1.168133543","rc":[{"batb":[[1,8.8,14.47],[2,8.6,2.52]],"ltp":9.4,"tv":133.89,"id":10163711},{"batb":[[0,10.5,3.62]],"ltp":10.0,"tv":171.4,"id":22121325}]}]}
{"op":"mcm","clk":"991811516","pt":1580508487566,"mc":[{"id":"1.168133543","rc":[{"batb":[[1,8.6,17.32],[2,8.4,5.95]],"ltp":9.4,"tv":133.89,"id":10163711},{"batb":[[0,10.5,15.35]],"ltp":10.0,"tv":171.4,"id":22121325}]}]}
{"op":"mcm","clk":"991812377","pt":1580508500474,"mc":[{"id":"1.168133543","rc":[{"batb":[[1,8.6,2.6]],"ltp":9.4,"tv":133.89,"id":10163711},{"batb":[[0,10.5,3.62]],"ltp":10.0,"tv":171.4,"id":22121325}]}]}
{"op":"mcm","clk":"991812382","pt":1580508500576,"mc":[{"id":"1.168133543","rc":[{"batb":[[1,8.8,14.47],[2,8.6,2.52]],"ltp":9.4,"tv":133.89,"id":10163711}]}]}
{"op":"mcm","clk":"991813174","pt":1580508513512,"mc":[{"id":"1.168133543","rc":[{"batb":[[1,8.6,17.32],[2,8.4,5.95]],"ltp":9.4,"tv":133.89,"id":10163711},{"batb":[[0,10.5,15.35]],"ltp":10.0,"tv":171.4,"id":22121325}]}]}
{"op":"mcm","clk":"991813991","pt":1580508526544,"mc":[{"id":"1.168133543","rc":[{"batb":[[1,8.6,2.6]],"ltp":9.4,"tv":133.89,"id":10163711},{"batb":[[0,10.5,3.62]],"ltp":10.0,"tv":171.4,"id":22121325}]}]}
{"op":"mcm","clk":"991814004","pt":1580508526598,"mc":[{"id":"1.168133543","rc":[{"batb":[[1,8.8,14.47],[2,8.6,2.52]],"ltp":9.4,"tv":133.89,"id":10163711}]}]}
{"op":"mcm","clk":"991814770","pt":1580508538495,"mc":[{"id":"1.168133543","rc":[{"batb":[[1,8.6,17.32],[2,8.4,5.95]],"ltp":9.4,"tv":133.89,"id":10163711},{"batb":[[0,10.5,15.35]],"ltp":10.0,"tv":171.4,"id":22121325}]}]}
{"op":"mcm","clk":"991815633","pt":1580508551504,"mc":[{"id":"1.168133543","rc":[{"batb":[[1,8.6,2.6]],"ltp":9.4,"tv":133.89,"id":10163711},{"batb":[[0,10.5,3.62]],"ltp":10.0,"tv":171.4,"id":22121325}]}]}
{"op":"mcm","clk":"991815686","pt":1580508552227,"mc":[{"id":"1.168133543","rc":[{"batb":[[1,8.8,14.47],[2,8.6,2.52]],"ltp":9.4,"tv":133.89,"id":10163711}]}]}
{"op":"mcm","clk":"991816494","pt":1580508564535,"mc":[{"id":"1.168133543","rc":[{"batb":[[1,8.6,17.32],[2,8.4,5.95]],"ltp":9.4,"tv":133.89,"id":10163711},{"batb":[[0,10.5,15.35]],"ltp":10.0,"tv":171.4,"id":22121325}]}]}
{"op":"mcm","clk":"991817304","pt":1580508577536,"mc":[{"id":"1.168133543","rc":[{"batb":[[1,8.8,14.47],[2,8.6,2.52]],"ltp":9.4,"tv":133.89,"id":10163711},{"batb":[[0,10.5,3.62]],"ltp":10.0,"tv":171.4,"id":22121325}]}]}
{"op":"mcm","clk":"991818006","pt":1580508589472,"mc":[{"id":"1.168133543","rc":[{"batb":[[1,8.6,17.32],[2,8.4,5.95]],"ltp":9.4,"tv":133.89,"id":10163711},{"batb":[[0,10.5,15.35]],"ltp":10.0,"tv":171.4,"id":22121325}]}]}
{"op":"mcm","clk":"991818864","pt":1580508602483,"mc":[{"id":"1.168133543","rc":[{"batb":[[1,8.6,2.6]],"ltp":9.4,"tv":133.89,"id":10163711},{"batb":[[0,10.5,3.62]],"ltp":10.0,"tv":171.4,"id":22121325}]}]}
{"op":"mcm","clk":"991818873","pt":1580508602585,"mc":[{"id":"1.168133543","rc":[{"batb":[[1,8.8,14.47],[2,8.6,2.52]],"ltp":9.4,"tv":133.89,"id":10163711}]}]}
{"op":"mcm","clk":"991819002","pt":1580508604185,"mc":[{"id":"1.168133543","rc":[{"batb":[[0,9,4.24]],"ltp":9.4,"tv":133.89,"id":10163711}]}]}
{"op":"mcm","clk":"991819545","pt":1580508611165,"mc":[{"id":"1.168133543","rc":[{"batb":[[0,9,2.02]],"batl":[[0,9.8,3.38],[1,10,66],[2,11.5,1.68]],"ltp":9.4,"tv":133.89,"id":10163711}]}]}
{"op":"mcm","clk":"991819827","pt":1580508615506,"mc":[{"id":"1.168133543","rc":[{"batb":[[1,8.6,2.6],[2,8.4,5.95]],"ltp":9.4,"tv":133.89,"id":10163711}]}]}
{"op":"mcm","clk":"991819836","pt":1580508615610,"mc":[{"id":"1.168133543","rc":[{"batb":[[1,8.6,17.32]],"ltp":9.4,"tv":133.89,"id":10163711},{"batb":[[0,10.5,15.35]],"ltp":10.0,"tv":171.4,"id":22121325}]}]}
{"op":"mcm","clk":"991820592","pt":1580508627531,"mc":[{"id":"1.168133543","rc":[{"batb":[[1,8.8,14.47],[2,8.6,2.52]],"ltp":9.4,"tv":133.89,"id":10163711},{"batb":[[0,10.5,3.62]],"ltp":10.0,"tv":171.4,"id":22121325}]}]}
{"op":"mcm","clk":"991821432","pt":1580508640569,"mc":[{"id":"1.168133543","rc":[{"batb":[[1,8.6,17.32],[2,8.4,5.95]],"ltp":9.4,"tv":133.89,"id":10163711},{"batb":[[0,10.5,15.35]],"ltp":10.0,"tv":171.4,"id":22121325}]}]}
{"op":"mcm","clk":"991822187","pt":1580508653480,"mc":[{"id":"1.168133543","rc":[{"batb":[[1,8.6,2.6]],"ltp":9.4,"tv":133.89,"id":10163711},{"batb":[[0,10.5,3.62]],"ltp":10.0,"tv":171.4,"id":22121325}]}]}
{"op":"mcm","clk":"991822208","pt":1580508653787,"mc":[{"id":"1.168133543","rc":[{"batb":[[1,8.8,14.47],[2,8.6,2.52]],"ltp":9.4,"tv":133.89,"id":10163711}]}]}
{"op":"mcm","clk":"991822961","pt":1580508666494,"mc":[{"id":"1.168133543","rc":[{"batb":[[1,8.6,2.6],[2,8.4,5.95]],"ltp":9.4,"tv":133.89,"id":10163711}]}]}
{"op":"mcm","clk":"991823028","pt":1580508667430,"mc":[{"id":"1.168133543","rc":[{"batb":[[1,8.6,17.32]],"ltp":9.4,"tv":133.89,"id":10163711},{"batb":[[0,10.5,15.35]],"ltp":10.0,"tv":171.4,"id":22121325}]}]}
{"op":"mcm","clk":"991823355","pt":1580508672286,"mc":[{"id":"1.168133543","rc":[{"batb":[[0,2.34,20],[1,2.32,7.43]],"ltp":2.3,"tv":1602.16,"id":10107355}]}]}
{"op":"mcm","clk":"991823889","pt":1580508682517,"mc":[{"id":"1.168133543","rc":[{"batb":[[1,8.6,2.6]],"ltp":9.4,"tv":133.89,"id":10163711},{"batb":[[0,10.5,3.62]],"ltp":10.0,"tv":171.4,"id":22121325}]}]}
{"op":"mcm","clk":"991823940","pt":1580508683346,"mc":[{"id":"1.168133543","rc":[{"batb":[[1,8.8,14.47],[2,8.6,2.52]],"ltp":9.4,"tv":133.89,"id":10163711}]}]}
{"op":"mcm","clk":"991824709","pt":1580508694469,"mc":[{"id":"1.168133543","rc":[{"batb":[[1,8.6,2.6],[2,8.4,5.95]],"ltp":9.4,"tv":133.89,"id":10163711}]}]}
{"op":"mcm","clk":"991825604","pt":1580508707446,"mc":[{"id":"1.168133543","rc":[{"batb":[[1,8.8,14.47],[2,8.6,2.52]],"ltp":9.4,"tv":133.89,"id":10163711}]}]}
{"op":"mcm","clk":"991826592","pt":1580508720389,"mc":[{"id":"1.168133543","rc":[{"batb":[[1,8.6,2.6],[2,8.4,5.95]],"ltp":9.4,"tv":133.89,"id":10163711}]}]}
{"op":"mcm","clk":"991827432","pt":1580508733320,"mc":[{"id":"1.168133543","rc":[{"batb":[[1,8.8,14.47],[2,8.6,2.52]],"ltp":9.4,"tv":133.89,"id":10163711}]}]}
{"op":"mcm","clk":"991828186","pt":1580508745488,"mc":[{"id":"1.168133543","rc":[{"batb":[[1,8.6,2.6],[2,8.4,5.95]],"ltp":9.4,"tv":133.89,"id":10163711}]}]}
{"op":"mcm","clk":"991828991","pt":1580508758414,"mc":[{"id":"1.168133543","rc":[{"batb":[[1,8.8,14.47],[2,8.6,2.52]],"ltp":9.4,"tv":133.89,"id":10163711}]}]}
{"op":"mcm","clk":"991829882","pt":1580508771369,"mc":[{"id":"1.168133543","rc":[{"batb":[[1,8.6,2.6],[2,8.4,5.95]],"ltp":9.4,"tv":133.89,"id":10163711}]}]}
{"op":"mcm","clk":"991830776","pt":1580508783452,"mc":[{"id":"1.168133543","rc":[{"batb":[[1,8.8,14.47],[2,8.6,2.52]],"ltp":9.4,"tv":133.89,"id":10163711}]}]}
{"op":"mcm","clk":"991831609","pt":1580508796498,"mc":[{"id":"1.168133543","rc":[{"batb":[[1,8.6,2.6],[2,8.4,5.95]],"ltp":9.4,"tv":133.89,"id":10163711}]}]}
{"op":"mcm","clk":"991832301","pt":1580508809400,"mc":[{"id":"1.168133543","rc":[{"batb":[[1,8.8,14.47],[2,8.6,2.52]],"ltp":9.4,"tv":133.89,"id":10163711}]}]}
{"op":"mcm","clk":"991832924","pt":1580508822423,"mc":[{"id":"1.168133543","rc":[{"batb":[[1,8.6,2.6],[2,8.4,5.95]],"ltp":9.4,"tv":133.89,"id":10163711}]}]}
{"op":"mcm","clk":"991833484","pt":1580508834343,"mc":[{"id":"1.168133543","rc":[{"batb":[[1,8.8,14.47],[2,8.6,2.52]],"ltp":9.4,"tv":133.89,"id":10163711}]}]}
{"op":"mcm","clk":"991833929","pt":1580508844872,"mc":[{"id":"1.168133543","rc":[{"batb":[[1,170,3.21],[2,160,1.09]],"ltp":280.0,"tv":1.54,"id":24270700}]}]}
{"op":"mcm","clk":"991834076","pt":1580508847495,"mc":[{"id":"1.168133543","rc":[{"batb":[[1,8.6,2.6],[2,8.4,5.95]],"ltp":9.4,"tv":133.89,"id":10163711},{"batb":[[2,150,1.7]],"ltp":280.0,"tv":1.54,"id":24270700}]}]}
{"op":"mcm","clk":"991834102","pt":1580508848162,"mc":[{"id":"1.168133543","rc":[{"batb":[[0,180,1.73]],"ltp":280.0,"tv":1.54,"id":24270700}]}]}
{"op":"mcm","clk":"991834349","pt":1580508852497,"mc":[{"id":"1.168133543","rc":[{"batb":[[2,150,1.43]],"ltp":280.0,"tv":1.54,"id":24270700}]}]}
{"op":"mcm","clk":"991834736","pt":1580508859136,"mc":[{"id":"1.168133543","rc":[{"trd":[[2.36,36.84]],"batb":[[0,2.36,9.96],[1,2.34,20],[2,2.32,7.43]],"batl":[[0,2.38,56],[1,2.4,2.23],[2,2.48,50]],"ltp":2.36,"tv":1625.54,"id":10107355}],"tv":2639.68}]}
{"op":"mcm","clk":"991834792","pt":1580508860434,"mc":[{"id":"1.168133543","rc":[{"batb":[[0,2.82,3.13]],"ltp":2.84,"tv":650.14,"id":12636}]}]}
{"op":"mcm","clk":"991839031","pt":1580508948349,"mc":[{"id":"1.168133543","rc":[{"batb":[[0,50,3.29],[1,48,2.29],[2,16,3.03]],"batl":[[1,210,2.87]],"ltp":80.0,"tv":11.61,"id":22308007},{"batl":[[0,95,3.11]],"ltp":50.0,"tv":15.25,"id":7226819},{"batl":[[2,16.5,1.94]],"ltp":10.0,"tv":171.4,"id":22121325},{"batl":[[0,160,4],[1,980,9.15],[2,980,0]],"ltp":150.0,"tv":1.36,"id":26548208},{"batl":[[0,330,0.15],[1,330,0]],"ltp":280.0,"tv":1.54,"id":24270700}]}]}
{"op":"mcm","clk":"991839083","pt":1580508949425,"mc":[{"id":"1.168133543","rc":[{"batb":[[0,50,2.58]],"ltp":80.0,"tv":11.61,"id":22308007},{"batb":[[0,180,1.03]],"ltp":280.0,"tv":1.54,"id":24270700}]}]}
{"op":"mcm","clk":"991839144","pt":1580508950455,"mc":[{"id":"1.168133543","rc":[{"batb":[[0,55,1.12],[1,50,2.52],[2,48,2.29]],"ltp":80.0,"tv":11.61,"id":22308007}]}]}
{"op":"mcm","clk":"991839205","pt":1580508951341,"mc":[{"id":"1.168133543","rc":[{"batl":[[0,330,0.35]],"ltp":280.0,"tv":1.54,"id":24270700}]}]}
{"op":"mcm","clk":"991839453","pt":1580508956048,"mc":[{"id":"1.168133543","rc":[{"batb":[[0,55,1.91]],"ltp":80.0,"tv":11.61,"id":22308007}]}]}
{"op":"mcm","clk":"991839650","pt":1580508959975,"mc":[{"id":"1.168133543","rc":[{"batl":[[1,16.5,1.94],[2,60,3.11]],"ltp":10.0,"tv":171.4,"id":22121325}]}]}
{"op":"mcm","clk":"991839775","pt":1580508962502,"mc":[{"id":"1.168133543","rc":[{"batb":[[1,70,1.1],[2,60,1.23]],"ltp":150.0,"tv":1.36,"id":26548208}]}]}
{"op":"mcm","clk":"991839829","pt":1580508963493,"mc":[{"id":"1.168133543","rc":[{"batb":[[0,10.5,15.35]],"ltp":10.0,"tv":171.4,"id":22121325}]}]}
{"op":"mcm","clk":"991840385","pt":1580508975674,"mc":[{"id":"1.168133543","rc":[{"batb":[[1,75,2.07],[2,65,1.49]],"ltp":150.0,"tv":1.36,"id":26548208}]}]}
{"op":"mcm","clk":"991840502","pt":1580508978033,"mc":[{"id":"1.168133543","rc":[{"batl":[[0,16,1.81]],"ltp":10.0,"tv":171.4,"id":22121325}]}]}
{"op":"mcm","clk":"991840934","pt":1580508985615,"mc":[{"id":"1.168133543","rc":[{"batl":[[0,15.5,2.08],[1,16,1.73],[2,16.5,1.94]],"ltp":10.0,"tv":171.4,"id":22121325}]}]}
{"op":"mcm","clk":"991841049","pt":1580508987422,"mc":[{"id":"1.168133543","rc":[{"batb":[[1,70,1.1],[2,60,1.23]],"ltp":150.0,"tv":1.36,"id":26548208}]}]}
{"op":"mcm","clk":"991841306","pt":1580508992535,"mc":[{"id":"1.168133543","rc":[{"batl":[[0,15.5,5.11]],"ltp":10.0,"tv":171.4,"id":22121325}]}]}
{"op":"mcm","clk":"991841347","pt":1580508993103,"mc":[{"id":"1.168133543","rc":[{"batb":[[0,55,3.93]],"ltp":80.0,"tv":11.61,"id":22308007}]}]}
{"op":"mcm","clk":"991841729","pt":1580508998565,"mc":[{"id":"1.168133543","rc":[{"batb":[[2,16,3.03]],"ltp":80.0,"tv":11.61,"id":22308007},{"batb":[[0,44,1.88],[1,40,2.81],[2,32,2]],"ltp":580.0,"tv":6.13,"id":27606066}]}]}
{"op":"mcm","clk":"991841789","pt":1580508999350,"mc":[{"id":"1.168133543","rc":[{"batl":[[1,16.5,1.94],[2,65,9.08]],"ltp":10.0,"tv":171.4,"id":22121325}]}]}
{"op":"mcm","clk":"991841850","pt":1580509000428,"mc":[{"id":"1.168133543","rc":[{"batl":[[0,15,1.93],[1,15.5,5.03],[2,16.5,1.94]],"ltp":10.0,"tv":171.4,"id":22121325},{"batb":[[1,42,3.83],[2,40,2]],"ltp":580.0,"tv":6.13,"id":27606066}]}]}
{"op":"mcm","clk":"991841860","pt":1580509000635,"mc":[{"id":"1.168133543","rc":[{"batb":[[1,75,2.07],[2,65,1.49]],"ltp":150.0,"tv":1.36,"id":26548208}]}]}
{"op":"mcm","clk":"991841966","pt":1580509002541,"mc":[{"id":"1.168133543","rc":[{"batb":[[0,44,3.21]],"ltp":580.0,"tv":6.13,"id":27606066}]}]}
{"op":"mcm","clk":"991842495","pt":1580509013547,"mc":[{"id":"1.168133543","rc":[{"batb":[[0,44,6.09],[1,40,2.81],[2,32,2]],"ltp":580.0,"tv":6.13,"id":27606066}]}]}
{"op":"mcm","clk":"991843932","pt":1580509039728,"mc":[{"id":"1.168133543","rc":[{"batl":[[0,14.5,2.08],[1,15,1.85],[2,15.5,3.03]],"ltp":10.0,"tv":171.4,"id":22121325}]}]}
{"op":"mcm","clk":"991844049","pt":1580509042015,"mc":[{"id":"1.168133543","rc":[{"batl":[[0,14,2.07],[1,14.5,2]],"ltp":10.0,"tv":171.4,"id":22121325}]}]}
{"op":"mcm","clk":"991844864","pt":1580509057740,"mc":[{"id":"1.168133543","rc":[{"batl":[[0,14,5.1],[2,16.5,1.94]],"ltp":10.0,"tv":171.4,"id":22121325}]}]}
{"op":"mcm","clk":"991846255","pt":1580509089912,"mc":[{"id":"1.168133543","rc":[{"batl":[[0,14,2.07],[2,16,3.03]],"ltp":10.0,"tv":171.4,"id":22121325}]}]}
{"op":"mcm","clk":"991846429","pt":1580509093411,"mc":[{"id":"1.168133543","rc":[{"batl":[[1,15.5,2]],"ltp":10.0,"tv":171.4,"id":22121325}]}]}
{"op":"mcm","clk":"991847158","pt":1580509107451,"mc":[{"id":"1.168133543","rc":[{"batl":[[0,15.5,2.08],[1,16,3.03],[2,16.5,1.94]],"ltp":10.0,"tv":171.4,"id":22121325}]}]}
{"op":"mcm","clk":"991847178","pt":1580509107754,"mc":[{"id":"1.168133543","rc":[{"batl":[[0,15,2.94],[1,15.5,2],[2,16,3.03]],"ltp":10.0,"tv":171.4,"id":22121325}]}]}
{"op":"mcm","clk":"991851242","pt":1580509195358,"mc":[{"id":"1.168133543","rc":[{"batl":[[0,9.6,4],[1,9.8,3.38],[2,10,66]],"ltp":9.4,"tv":133.89,"id":10163711}]}]}
{"op":"mcm","clk":"991852371","pt":1580509219180,"mc":[{"id":"1.168133543","rc":[{"batl":[[0,9.4,3.03],[1,9.6,4]],"ltp":9.4,"tv":133.89,"id":10163711}]}]}
{"op":"mcm","clk":"991852818","pt":1580509229311,"mc":[{"id":"1.168133543","rc":[{"batl":[[1,10,66],[2,11.5,1.68]],"ltp":9.4,"tv":133.89,"id":10163711}]}]}
{"op":"mcm","clk":"991853939","pt":1580509252137,"mc":[{"id":"1.168133543","rc":[{"batl":[[0,9.8,3.38]],"ltp":9.4,"tv":133.89,"id":10163711}]}]}
{"op":"mcm","clk":"991854742","pt":1580509269369,"mc":[{"id":"1.168133543","rc":[{"batl":[[0,9.6,4],[1,9.8,3.38],[2,10,66]],"ltp":9.4,"tv":133.89,"id":10163711}]}]}
{"op":"mcm","clk":"991855497","pt":1580509285511,"mc":[{"id":"1.168133543","rc":[{"batl":[[0,9.4,3.03],[1,9.6,4]],"ltp":9.4,"tv":133.89,"id":10163711}]}]}
{"op":"mcm","clk":"991855819","pt":1580509292034,"mc":[{"id":"1.168133543","rc":[{"batl":[[1,10,66],[2,11.5,1.68]],"ltp":9.4,"tv":133.89,"id":10163711}]}]}
{"op":"mcm","clk":"991857416","pt":1580509323210,"mc":[{"id":"1.168133543","rc":[{"batl":[[0,9.8,3.38]],"ltp":9.4,"tv":133.89,"id":10163711}]}]}
{"op":"mcm","clk":"991857536","pt":1580509325422,"mc":[{"id":"1.168133543","rc":[{"batl":[[0,9.6,4],[1,9.8,3.38],[2,10,66]],"ltp":9.4,"tv":133.89,"id":10163711}]}]}
{"op":"mcm","clk":"991868899","pt":1580509363472,"mc":[{"id":"1.168133543","rc":[{"batl":[[0,9.4,3.03],[1,9.6,4]],"ltp":9.4,"tv":133.89,"id":10163711}]}]}
{"op":"mcm","clk":"991869411","pt":1580509375612,"mc":[{"id":"1.168133543","rc":[{"batl":[[1,10,66],[2,11.5,1.68]],"ltp":9.4,"tv":133.89,"id":10163711}]}]}
{"op":"mcm","clk":"991870362","pt":1580509395940,"mc":[{"id":"1.168133543","rc":[{"batl":[[0,9.8,3.38]],"ltp":9.4,"tv":133.89,"id":10163711}]}]}
{"op":"mcm","clk":"991870587","pt":1580509400226,"mc":[{"id":"1.168133543","rc":[{"trd":[[2.38,20.16]],"batl":[[0,2.38,45.92]],"ltp":2.38,"tv":1645.7,"id":10107355}],"tv":2659.84}]}
{"op":"mcm","clk":"991871098","pt":1580509409438,"mc":[{"id":"1.168133543","rc":[{"batl":[[0,9.6,4],[1,9.8,3.38],[2,10,66]],"ltp":9.4,"tv":133.89,"id":10163711}]}]}
{"op":"mcm","clk":"991871714","pt":1580509423169,"mc":[{"id":"1.168133543","rc":[{"trd":[[2.82,71.19]],"batb":[[0,2.8,7.37],[1,2.78,10.58],[2,2.72,2.52]],"batl":[[0,2.82,6.87],[1,2.84,1.68],[2,2.9,49.35]],"ltp":2.82,"tv":656.41,"id":12636}],"tv":2666.1}]}
{"op":"mcm","clk":"991871949","pt":1580509427991,"mc":[{"id":"1.168133543","rc":[{"trd":[[2.8,46.88]],"batb":[[0,2.78,10.58],[1,2.72,2.52],[2,2.68,2.52]],"batl":[[0,2.84,1.68],[1,2.9,49.35],[2,2.92,50]],"ltp":2.8,"tv":671.15,"id":12636}],"tv":2680.84}]}
{"op":"mcm","clk":"991872022","pt":1580509429387,"mc":[{"id":"1.168133543","rc":[{"batb":[[2,2.7,3.91]],"batl":[[1,2.88,3.67],[2,2.9,49.35]],"ltp":2.8,"tv":671.15,"id":12636},{"batl":[[0,9.4,3.03],[1,9.6,4]],"ltp":9.4,"tv":133.89,"id":10163711}]}]}
{"op":"mcm","clk":"991872621","pt":1580509441402,"mc":[{"id":"1.168133543","rc":[{"batb":[[0,180,1.73]],"ltp":280.0,"tv":1.54,"id":24270700}]}]}
{"op":"mcm","clk":"991872659","pt":1580509442294,"mc":[{"id":"1.168133543","rc":[{"batl":[[1,10,66],[2,11.5,1.68]],"ltp":9.4,"tv":133.89,"id":10163711}]}]}
{"op":"mcm","clk":"991873255","pt":1580509454540,"mc":[{"id":"1.168133543","rc":[{"batb":[[0,100,17.68],[1,44,2.33],[2,40,2.81]],"ltp":580.0,"tv":6.13,"id":27606066},{"batb":[[0,180,1.03]],"ltp":280.0,"tv":1.54,"id":24270700}]}]}
{"op":"mcm","clk":"991873976","pt":1580509468440,"mc":[{"id":"1.168133543","rc":[{"batb":[[1,44,1]],"ltp":580.0,"tv":6.13,"id":27606066}]}]}
{"op":"mcm","clk":"991874424","pt":1580509476074,"mc":[{"id":"1.168133543","rc":[{"batl":[[0,9.8,3.38]],"ltp":9.4,"tv":133.89,"id":10163711}]}]}
{"op":"mcm","clk":"991874677","pt":1580509481282,"mc":[{"id":"1.168133543","rc":[{"batl":[[0,9.6,4],[1,9.8,3.38],[2,10,66]],"ltp":9.4,"tv":133.89,"id":10163711}]}]}
{"op":"mcm","clk":"991877496","pt":1580509532558,"mc":[{"id":"1.168133543","rc":[{"batl":[[1,10,66],[2,11.5,1.68]],"ltp":9.4,"tv":133.89,"id":10163711}]}]}
{"op":"mcm","clk":"991877502","pt":1580509532660,"mc":[{"id":"1.168133543","rc":[{"batl":[[0,9.4,3.03],[1,9.6,4],[2,10,66]],"ltp":9.4,"tv":133.89,"id":10163711}]}]}
{"op":"mcm","clk":"991878264","pt":1580509548463,"mc":[{"id":"1.168133543","rc":[{"batl":[[1,10,66],[2,11.5,1.68]],"ltp":9.4,"tv":133.89,"id":10163711}]}]}
{"op":"mcm","clk":"991879640","pt":1580509580114,"mc":[{"id":"1.168133543","rc":[{"batl":[[0,9.8,3.38]],"ltp":9.4,"tv":133.89,"id":10163711}]}]}
{"op":"mcm","clk":"991879702","pt":1580509581717,"mc":[{"id":"1.168133543","rc":[{"batl":[[0,9.6,4],[1,9.8,3.38],[2,10,66]],"ltp":9.4,"tv":133.89,"id":10163711}]}]}
{"op":"mcm","clk":"991880682","pt":1580509605049,"mc":[{"id":"1.168133543","rc":[{"batl":[[1,2.86,2],[2,2.88,3.67]],"ltp":2.8,"tv":671.15,"id":12636}]}]}
{"op":"mcm","clk":"991881001","pt":1580509612971,"mc":[{"id":"1.168133543","rc":[{"batl":[[0,9.4,3.03],[1,9.6,4]],"ltp":9.4,"tv":133.89,"id":10163711}]}]}
{"op":"mcm","clk":"991881355","pt":1580509621084,"mc":[{"id":"1.168133543","rc":[{"batl":[[1,10,66],[2,11.5,1.68]],"ltp":9.4,"tv":133.89,"id":10163711}]}]}
{"op":"mcm","clk":"991882392","pt":1580509646294,"mc":[{"id":"1.168133543","rc":[{"batl":[[0,9.8,3.38]],"ltp":9.4,"tv":133.89,"id":10163711}]}]}
{"op":"mcm","clk":"991882774","pt":1580509654496,"mc":[{"id":"1.168133543","rc":[{"batl":[[0,9.6,4],[1,9.8,3.38],[2,10,66]],"ltp":9.4,"tv":133.89,"id":10163711}]}]}
{"op":"mcm","clk":"991883764","pt":1580509678564,"mc":[{"id":"1.168133543","rc":[{"batl":[[1,10,66],[2,11.5,1.68]],"ltp":9.4,"tv":133.89,"id":10163711}]}]}
{"op":"mcm","clk":"991883771","pt":1580509678660,"mc":[{"id":"1.168133543","rc":[{"batl":[[0,9.4,3.03],[1,9.6,4],[2,10,66]],"ltp":9.4,"tv":133.89,"id":10163711}]}]}
{"op":"mcm","clk":"991884473","pt":1580509693760,"mc":[{"id":"1.168133543","rc":[{"batl":[[1,10,66],[2,11.5,1.68]],"ltp":9.4,"tv":133.89,"id":10163711}]}]}
{"op":"mcm","clk":"991885229","pt":1580509710768,"mc":[{"id":"1.168133543","rc":[{"batl":[[0,9.8,3.38]],"ltp":9.4,"tv":133.89,"id":10163711}]}]}
{"op":"mcm","clk":"991886299","pt":1580509732504,"mc":[{"id":"1.168133543","rc":[{"batl":[[0,9.6,4],[1,9.8,3.38],[2,10,66]],"ltp":9.4,"tv":133.89,"id":10163711}]}]}
{"op":"mcm","clk":"991886844","pt":1580509742547,"mc":[{"id":"1.168133543","rc":[{"batl":[[0,9.4,3.03],[1,9.6,4]],"ltp":9.4,"tv":133.89,"id":10163711}]}]}
{"op":"mcm","clk":"991887488","pt":1580509755136,"mc":[{"id":"1.168133543","rc":[{"batl":[[1,10,66],[2,11.5,1.68]],"ltp":9.4,"tv":133.89,"id":10163711}]}]}
{"op":"mcm","clk":"991888411","pt":1580509774554,"mc":[{"id":"1.168133543","rc":[{"batl":[[0,9.8,3.38]],"ltp":9.4,"tv":133.89,"id":10163711}]}]}
{"op":"mcm","clk":"991888532","pt":1580509777686,"mc":[{"id":"1.168133543","rc":[{"batl":[[1,2.4,4.23]],"ltp":2.38,"tv":1645.7,"id":10107355}]}]}
{"op":"mcm","clk":"991888996","pt":1580509788115,"mc":[{"id":"1.168133543","rc":[{"batl":[[0,9.6,4],[1,9.8,3.38],[2,10,66]],"ltp":9.4,"tv":133.89,"id":10163711}]}]}
{"op":"mcm","clk":"991889983","pt":1580509807100,"mc":[{"id":"1.168133543","rc":[{"batl":[[0,9.4,3.03],[1,9.6,4]],"ltp":9.4,"tv":133.89,"id":10163711}]}]}
{"op":"mcm","clk":"991890678","pt":1580509821226,"mc":[{"id":"1.168133543","rc":[{"batl":[[1,10,66],[2,11.5,1.68]],"ltp":9.4,"tv":133.89,"id":10163711}]}]}
{"op":"mcm","clk":"991891479","pt":1580509840036,"mc":[{"id":"1.168133543","rc":[{"batl":[[0,9.8,3.38]],"ltp":9.4,"tv":133.89,"id":10163711}]}]}
{"op":"mcm","clk":"991892069","pt":1580509854763,"mc":[{"id":"1.168133543","rc":[{"batl":[[0,9.6,4],[1,9.8,3.38],[2,10,66]],"ltp":9.4,"tv":133.89,"id":10163711}]}]}
{"op":"mcm","clk":"991892824","pt":1580509873786,"mc":[{"id":"1.168133543","rc":[{"batl":[[0,9.4,3.03],[1,9.6,4]],"ltp":9.4,"tv":133.89,"id":10163711}]}]}
{"op":"mcm","clk":"991893784","pt":1580509894426,"mc":[{"id":"1.168133543","rc":[{"batl":[[1,10,66],[2,11.5,1.68]],"ltp":9.4,"tv":133.89,"id":10163711}]}]}
{"op":"mcm","clk":"991894043","pt":1580509899855,"mc":[{"id":"1.168133543","rc":[{"batl":[[1,2.4,2.23]],"ltp":2.38,"tv":1645.7,"id":10107355}]}]}
{"op":"mcm","clk":"991894647","pt":1580509913841,"mc":[{"id":"1.168133543","rc":[{"batl":[[0,9.8,3.38]],"ltp":9.4,"tv":133.89,"id":10163711}]}]}
{"op":"mcm","clk":"991895274","pt":1580509928376,"mc":[{"id":"1.168133543","rc":[{"batl":[[0,9.6,4],[1,9.8,3.38],[2,10,66]],"ltp":9.4,"tv":133.89,"id":10163711}]}]}
{"op":"mcm","clk":"991896264","pt":1580509953429,"mc":[{"id":"1.168133543","rc":[{"batl":[[0,9.4,3.03],[1,9.6,4]],"ltp":9.4,"tv":133.89,"id":10163711}]}]}
{"op":"mcm","clk":"991896650","pt":1580509962245,"mc":[{"id":"1.168133543","rc":[{"batl":[[1,10,66],[2,11.5,1.68]],"ltp":9.4,"tv":133.89,"id":10163711}]}]}
{"op":"mcm","clk":"991897725","pt":1580509985540,"mc":[{"id":"1.168133543","rc":[{"batl":[[0,10,66],[1,11.5,1.68],[2,29,9.24]],"ltp":9.4,"tv":133.89,"id":10163711}]}]}
{"op":"mcm","clk":"991897732","pt":1580509985646,"mc":[{"id":"1.168133543","rc":[{"batl":[[0,9.8,3.38],[1,10,66],[2,11.5,1.68]],"ltp":9.4,"tv":133.89,"id":10163711}]}]}
{"op":"mcm","clk":"991897819","pt":1580509987457,"mc":[{"id":"1.168133543","rc":[{"trd":[[2.34,136.07],[2.36,56.76]],"batb":[[0,2.34,4.96],[1,2.32,7.43],[2,2.26,2.52]],"ltp":2.34,"tv":1695.7,"id":10107355}],"tv":2730.84}]}
{"op":"mcm","clk":"991898597","pt":1580510002549,"mc":[{"id":"1.168133543","rc":[{"batl":[[0,9.6,4],[1,9.8,3.38],[2,10,66]],"ltp":9.4,"tv":133.89,"id":10163711}]}]}
{"op":"mcm","clk":"991899314","pt":1580510018963,"mc":[{"id":"1.168133543","rc":[{"batl":[[0,9.4,3.03],[1,9.6,4]],"ltp":9.4,"tv":133.89,"id":10163711}]}]}
{"op":"mcm","clk":"991899678","pt":1580510028394,"mc":[{"id":"1.168133543","rc":[{"trd":[[2.32,35.29],[2.34,145.99]],"batb":[[0,2.26,2.52],[1,2.22,6.59],[2,2.2,100]],"batl":[[0,2.32,34.82],[1,2.38,45.92],[2,2.4,2.23]],"ltp":2.32,"tv":1726.06,"id":10107355}],"tv":2761.2}]}
{"op":"mcm","clk":"991899756","pt":1580510030397,"mc":[{"id":"1.168133543","rc":[{"batb":[[1,8.8,14.47],[2,8.6,2.52]],"ltp":9.4,"tv":133.89,"id":10163711},{"batb":[[1,2.22,14.38]],"ltp":2.32,"tv":1726.06,"id":10107355},{"batb":[[0,110,2.03],[1,100,16.8],[2,44,1]],"ltp":580.0,"tv":6.13,"id":27606066},{"batb":[[0,180,1.73]],"ltp":280.0,"tv":1.54,"id":24270700}]}]}
{"op":"mcm","clk":"991899886","pt":1580510033225,"mc":[{"id":"1.168133543","rc":[{"batl":[[0,2.38,45.92],[1,2.4,2.23],[2,2.48,50]],"ltp":2.32,"tv":1726.06,"id":10107355}]}]}
{"op":"mcm","clk":"991900033","pt":1580510036411,"mc":[{"id":"1.168133543","rc":[{"batl":[[1,10,66],[2,11.5,1.68]],"ltp":9.4,"tv":133.89,"id":10163711},{"batb":[[0,120,1.23],[1,110,1.15],[2,100,16.8]],"ltp":580.0,"tv":6.13,"id":27606066},{"batb":[[0,180,1.96]],"ltp":280.0,"tv":1.54,"id":24270700}]}]}
{"op":"mcm","clk":"991900324","pt":1580510043499,"mc":[{"id":"1.168133543","rc":[{"batb":[[1,8.6,2.6],[2,8.4,5.95]],"ltp":9.4,"tv":133.89,"id":10163711},{"batb":[[1,100,16.8],[2,44,1]],"ltp":580.0,"tv":6.13,"id":27606066}]}]}
{"op":"mcm","clk":"991900700","pt":1580510051336,"mc":[{"id":"1.168133543","rc":[{"batl":[[0,2.36,22.77],[1,2.38,45.92],[2,2.4,2.23]],"ltp":2.32,"tv":1726.06,"id":10107355}]}]}
{"op":"mcm","clk":"991900720","pt":1580510051745,"mc":[{"id":"1.168133543","rc":[{"batl":[[0,9.8,3.38]],"ltp":9.4,"tv":133.89,"id":10163711}]}]}
{"op":"mcm","clk":"991901794","pt":1580510076047,"mc":[{"id":"1.168133543","rc":[{"batl":[[0,9.6,4],[1,9.8,3.38],[2,10,66]],"ltp":9.4,"tv":133.89,"id":10163711}]}]}
{"op":"mcm","clk":"991902222","pt":1580510084484,"mc":[{"id":"1.168133543","rc":[{"batl":[[0,9.4,3.03],[1,9.6,4]],"ltp":9.4,"tv":133.89,"id":10163711}]}]}
{"op":"mcm","clk":"991902386","pt":1580510088405,"mc":[{"id":"1.168133543","rc":[{"batb":[[0,9,2.09],[1,8.6,2.52]],"ltp":9.4,"tv":133.89,"id":10163711},{"batb":[[0,2.26,6.59],[1,2.22,10.32]],"ltp":2.32,"tv":1726.06,"id":10107355}]}]}
{"op":"mcm","clk":"991902445","pt":1580510089803,"mc":[{"id":"1.168133543","rc":[{"batl":[[2,2.4,6.02]],"ltp":2.32,"tv":1726.06,"id":10107355}]}]}
{"op":"mcm","clk":"991902598","pt":1580510093476,"mc":[{"id":"1.168133543","rc":[{"trd":[[9.2,0.2]],"batb":[[0,9,1.99]],"batl":[[0,9.2,3.9],[1,9.4,3.03]],"ltp":9.2,"tv":134.09,"id":10163711}],"tv":2761.4}]}
{"op":"mcm","clk":"991902698","pt":1580510095584,"mc":[{"id":"1.168133543","rc":[{"batl":[[2,10,66.09]],"ltp":9.2,"tv":134.09,"id":10163711}]}]}
{"op":"mcm","clk":"991902935","pt":1580510099490,"mc":[{"id":"1.168133543","rc":[{"batl":[[2,2.88,5.18]],"ltp":2.8,"tv":671.15,"id":12636}]}]}
{"op":"mcm","clk":"991903809","pt":1580510116536,"mc":[{"id":"1.168133543","rc":[{"batl":[[1,10,66.09],[2,11.5,1.68]],"ltp":9.2,"tv":134.09,"id":10163711}]}]}
{"op":"mcm","clk":"991903859","pt":1580510117207,"mc":[{"id":"1.168133543","rc":[{"trd":[[9.2,8]],"batl":[[0,10,66.09],[1,11.5,1.68],[2,29,9.24]],"ltp":9.2,"tv":141.89,"id":10163711}],"tv":2769.19}]}
{"op":"mcm","clk":"991904127","pt":1580510123442,"mc":[{"id":"1.168133543","rc":[{"batb":[[2,8.4,6.09]],"ltp":9.2,"tv":141.89,"id":10163711}]}]}
{"op":"mcm","clk":"991904277","pt":1580510127549,"mc":[{"id":"1.168133543","rc":[{"batb":[[1,8.8,4.18],[2,8.6,2.52]],"ltp":9.2,"tv":141.89,"id":10163711}]}]}
{"op":"mcm","clk":"991905296","pt":1580510149559,"mc":[{"id":"1.168133543","rc":[{"batl":[[0,9.8,3.12],[1,10,66],[2,11.5,1.68]],"ltp":9.2,"tv":141.89,"id":10163711}]}]}
{"op":"mcm","clk":"991905554","pt":1580510156291,"mc":[{"id":"1.168133543","rc":[{"trd":[[2.84,45.8],[2.86,4]],"batb":[[0,2.86,16.32],[1,2.78,10.58],[2,2.72,2.52]],"batl":[[0,2.88,5.18],[1,2.9,50.86],[2,2.92,50]],"ltp":2.86,"tv":678.51,"id":12636}],"tv":2776.55}]}
{"op":"mcm","clk":"991905691","pt":1580510160307,"mc":[{"id":"1.168133543","rc":[{"batb":[[1,2.8,2],[2,2.78,10.58]],"ltp":2.86,"tv":678.51,"id":12636}]}]}
{"op":"mcm","clk":"991906007","pt":1580510167412,"mc":[{"id":"1.168133543","rc":[{"trd":[[2.36,96.76]],"batl":[[0,2.36,2.77]],"ltp":2.36,"tv":1766.06,"id":10107355}],"tv":2816.55}]}
{"op":"mcm","clk":"991906504","pt":1580510181435,"mc":[{"id":"1.168133543","rc":[{"batl":[[0,2.88,1.51]],"ltp":2.86,"tv":678.51,"id":12636}]}]}
{"op":"mcm","clk":"991908847","pt":1580510245804,"mc":[{"id":"1.168133543","rc":[{"trd":[[1000,7.76]],"batb":[[0,1000,327.02]],"ltp":1000.0,"tv":7.76,"id":13819977},{"batl":[[2,1000,2.15]],"ltp":80.0,"tv":11.61,"id":22308007},{"batl":[[0,1000,2.35]],"ltp":160.0,"tv":19.01,"id":13306150}],"tv":2820.55}]}
{"op":"mcm","clk":"991918875","pt":1580510256655,"mc":[{"id":"1.168133543","rc":[{"batl":[[2,1000,3.15]],"ltp":80.0,"tv":11.61,"id":22308007},{"batl":[[0,1000,3.35]],"ltp":160.0,"tv":19.01,"id":13306150}]}]}
{"op":"mcm","clk":"991919103","pt":1580510263037,"mc":[{"id":"1.168133543","rc":[{"batb":[[0,2.8,2],[1,2.78,10.58],[2,2.72,2.52]],"batl":[[0,2.88,12.16]],"ltp":2.86,"tv":678.51,"id":12636}]}]}
{"op":"mcm","clk":"991919212","pt":1580510265247,"mc":[{"id":"1.168133543","rc":[{"batl":[[0,200,2.43]],"ltp":80.0,"tv":11.61,"id":22308007}]}]}
{"op":"mcm","clk":"991919546","pt":1580510272555,"mc":[{"id":"1.168133543","rc":[{"trd":[[2.36,102.3],[2.38,35.2]],"batl":[[0,2.38,38.4],[1,2.4,6.02],[2,2.46,3.79]],"ltp":2.38,"tv":1786.64,"id":10107355}],"tv":2841.13}]}
{"op":"mcm","clk":"991919638","pt":1580510274555,"mc":[{"id":"1.168133543","rc":[{"trd":[[2.88,45.62],[2.9,22.86]],"batl":[[0,2.9,47.02],[1,2.92,50],[2,2.94,58.02]],"ltp":2.9,"tv":710.51,"id":12636}],"tv":2873.14}]}
{"op":"mcm","clk":"991919697","pt":1580510276360,"mc":[{"id":"1.168133543","rc":[{"batb":[[0,2.8,10.06],[1,2.78,2.52]],"ltp":2.9,"tv":710.51,"id":12636}]}]}
{"op":"mcm","clk":"991919747","pt":1580510277696,"mc":[{"id":"1.168133543","rc":[{"batb":[[2,2.74,3.77]],"batl":[[0,2.88,3.59],[1,2.9,47.02],[2,2.92,50]],"ltp":2.9,"tv":710.51,"id":12636}]}]}
{"op":"mcm","clk":"991919898","pt":1580510281561,"mc":[{"id":"1.168133543","rc":[{"batl":[[2,1000,4.45]],"ltp":80.0,"tv":11.61,"id":22308007},{"batl":[[0,1000,4.65]],"ltp":160.0,"tv":19.01,"id":13306150}]}]}
{"op":"mcm","clk":"991920996","pt":1580510308313,"mc":[{"id":"1.168133543","rc":[{"batl":[[2,1000,1.45]],"ltp":80.0,"tv":11.61,"id":22308007},{"batl":[[0,1000,3.65]],"ltp":160.0,"tv":19.01,"id":13306150}]}]}
{"op":"mcm","clk":"991921345","pt":1580510316552,"mc":[{"id":"1.168133543","rc":[{"batl":[[0,1000,1.65]],"ltp":160.0,"tv":19.01,"id":13306150}]}]}
{"op":"mcm","clk":"991923305","pt":1580510362317,"mc":[{"id":"1.168133543","rc":[{"batl":[[0,2.88,5.1],[1,2.9,45.51]],"ltp":2.9,"tv":710.51,"id":12636}]}]}
{"op":"mcm","clk":"991923386","pt":1580510364118,"mc":[{"id":"1.168133543","rc":[{"batl":[[0,2.36,3.79],[1,2.38,38.4],[2,2.4,2.23]],"ltp":2.38,"tv":1786.64,"id":10107355}]}]}
{"op":"mcm","clk":"991923510","pt":1580510366525,"mc":[{"id":"1.168133543","rc":[{"batl":[[0,2.86,1.51],[1,2.88,3.59],[2,2.9,45.51]],"ltp":2.9,"tv":710.51,"id":12636}]}]}
{"op":"mcm","clk":"991923609","pt":1580510368526,"mc":[{"id":"1.168133543","rc":[{"batl":[[0,2.86,3.03]],"ltp":2.9,"tv":710.51,"id":12636}]}]}
{"op":"mcm","clk":"991923818","pt":1580510373099,"mc":[{"id":"1.168133543","rc":[{"batb":[[2,2.72,2.52]],"batl":[[1,2.9,45.51],[2,2.92,50]],"ltp":2.9,"tv":710.51,"id":12636}]}]}
{"op":"mcm","clk":"991944556","pt":1580510863818,"mc":[{"id":"1.168133543","rc":[{"trd":[[9,3.36]],"batb":[[0,8.8,4.49],[1,8.6,2.52],[2,8.4,6.09]],"batl":[[2,29,9.24]],"ltp":9.0,"tv":145.25,"id":10163711}],"tv":2876.5}]}
{"op":"mcm","clk":"991944976","pt":1580510868244,"mc":[{"id":"1.168133543","rc":[{"batl":[[0,9.6,2],[1,9.8,3.12],[2,10,66]],"ltp":9.0,"tv":145.25,"id":10163711},{"batb":[[0,130,1.03],[1,100,17.16]],"ltp":580.0,"tv":6.13,"id":27606066}]}]}
{"op":"mcm","clk":"991945160","pt":1580510870104,"mc":[{"id":"1.168133543","rc":[{"batl":[[0,2.86,1.51]],"ltp":2.9,"tv":710.51,"id":12636}]}]}
{"op":"mcm","clk":"991945263","pt":1580510872427,"mc":[{"id":"1.168133543","rc":[{"batl":[[0,2.9,45.51],[1,2.92,50],[2,2.94,58.02]],"ltp":2.9,"tv":710.51,"id":12636}]}]}
{"op":"mcm","clk":"991945312","pt":1580510874352,"mc":[{"id":"1.168133543","rc":[{"batb":[[0,2.82,1.54],[1,2.8,10.06],[2,2.78,2.52]],"ltp":2.9,"tv":710.51,"id":12636}]}]}
{"op":"mcm","clk":"991946195","pt":1580510886558,"mc":[{"id":"1.168133543","rc":[{"batl":[[0,2.88,4],[1,2.9,45.51],[2,2.92,50]],"ltp":2.9,"tv":710.51,"id":12636}]}]}
{"op":"mcm","clk":"991954742","pt":1580511077801,"mc":[{"id":"1.168133543","rc":[{"batb":[[0,2.82,4.91]],"ltp":2.9,"tv":710.51,"id":12636},{"batb":[[0,11,5.04],[1,10.5,15.35],[2,10,2.52]],"ltp":10.0,"tv":171.4,"id":22121325}]}]}
{"op":"mcm","clk":"991954966","pt":1580511083490,"mc":[{"id":"1.168133543","rc":[{"batl":[[0,14.5,2.08],[1,15,2.86]],"ltp":10.0,"tv":171.4,"id":22121325}]}]}
{"op":"mcm","clk":"991955210","pt":1580511090513,"mc":[{"id":"1.168133543","rc":[{"batl":[[0,2.9,45.51],[1,2.92,50],[2,2.94,58.02]],"ltp":2.9,"tv":710.51,"id":12636},{"batb":[[0,11.5,10.71],[1,11,5.04],[2,10.5,3.62]],"ltp":10.0,"tv":171.4,"id":22121325}]}]}
{"op":"mcm","clk":"991955230","pt":1580511091386,"mc":[{"id":"1.168133543","rc":[{"batl":[[0,14.5,5.11],[2,16.5,1.94]],"ltp":10.0,"tv":171.4,"id":22121325}]}]}
{"op":"mcm","clk":"991955712","pt":1580511102115,"mc":[{"id":"1.168133543","rc":[{"batl":[[0,14,2.07],[1,14.5,5.03]],"ltp":10.0,"tv":171.4,"id":22121325}]}]}
{"op":"mcm","clk":"991957526","pt":1580511138678,"mc":[{"id":"1.168133543","rc":[{"batl":[[0,13.5,2.08],[1,14,1.98],[2,14.5,3.03]],"ltp":10.0,"tv":171.4,"id":22121325}]}]}
{"op":"mcm","clk":"991957664","pt":1580511141305,"mc":[{"id":"1.168133543","rc":[{"batl":[[0,13,2.22],[1,13.5,2]],"ltp":10.0,"tv":171.4,"id":22121325}]}]}
{"op":"mcm","clk":"991967852","pt":1580511152402,"mc":[{"id":"1.168133543","rc":[{"batb":[[0,11,5.04],[1,10.5,3.62],[2,10,2.52]],"ltp":10.0,"tv":171.4,"id":22121325}]}]}
{"op":"mcm","clk":"991967988","pt":1580511155486,"mc":[{"id":"1.168133543","rc":[{"batl":[[2,16.5,1.94]],"ltp":10.0,"tv":171.4,"id":22121325}]}]}
{"op":"mcm","clk":"991968048","pt":1580511156510,"mc":[{"id":"1.168133543","rc":[{"batl":[[0,13,5.25]],"ltp":10.0,"tv":171.4,"id":22121325}]}]}
{"op":"mcm","clk":"991968674","pt":1580511169540,"mc":[{"id":"1.168133543","rc":[{"batb":[[0,10.5,3.62],[1,10,2.52],[2,9.8,4.97]],"ltp":10.0,"tv":171.4,"id":22121325}]}]}
{"op":"mcm","clk":"991969408","pt":1580511187050,"mc":[{"id":"1.168133543","rc":[{"batl":[[0,13,2.22],[2,16,3.03]],"ltp":10.0,"tv":171.4,"id":22121325}]}]}
{"op":"mcm","clk":"991969503","pt":1580511189662,"mc":[{"id":"1.168133543","rc":[{"batb":[[1,100,17.66]],"ltp":580.0,"tv":6.13,"id":27606066},{"batb":[[2,150,1.93]],"ltp":280.0,"tv":1.54,"id":24270700},{"batb":[[2,90,1.36]],"ltp":160.0,"tv":19.01,"id":13306150}]}]}
{"op":"mcm","clk":"991969627","pt":1580511192548,"mc":[{"id":"1.168133543","rc":[{"batl":[[0,2.34,2],[1,2.36,3.79],[2,2.38,38.4]],"ltp":2.38,"tv":1786.64,"id":10107355}]}]}
{"op":"mcm","clk":"991969682","pt":1580511193369,"mc":[{"id":"1.168133543","rc":[{"batl":[[1,15.5,2]],"ltp":10.0,"tv":171.4,"id":22121325}]}]}
{"op":"mcm","clk":"991969942","pt":1580511199444,"mc":[{"id":"1.168133543","rc":[{"batb":[[0,10.5,15.35]],"ltp":10.0,"tv":171.4,"id":22121325},{"batb":[[1,100,1.66]],"ltp":160.0,"tv":19.01,"id":13306150}]}]}
{"op":"mcm","clk":"991970192","pt":1580511205554,"mc":[{"id":"1.168133543","rc":[{"batl":[[0,15,2.94]],"ltp":10.0,"tv":171.4,"id":22121325}]}]}
{"op":"mcm","clk":"991970511","pt":1580511213499,"mc":[{"id":"1.168133543","rc":[{"batb":[[1,110,1.16],[2,90,1.86]],"ltp":160.0,"tv":19.01,"id":13306150}]}]}
{"op":"mcm","clk":"991971281","pt":1580511231078,"mc":[{"id":"1.168133543","rc":[{"batb":[[0,2.82,12.96],[1,2.8,2]],"ltp":2.9,"tv":710.51,"id":12636}]}]}
{"op":"mcm","clk":"991971743","pt":1580511242307,"mc":[{"id":"1.168133543","rc":[{"batb":[[0,2.84,2.52],[1,2.82,12.96],[2,2.8,2]],"ltp":2.9,"tv":710.51,"id":12636},{"batb":[[1,16,3.03],[2,7,90]],"ltp":80.0,"tv":11.61,"id":22308007},{"batb":[[1,46,1.08]],"ltp":50.0,"tv":15.25,"id":7226819},{"batb":[[0,2.26,4.07],[1,2.22,7.8]],"ltp":2.38,"tv":1786.64,"id":10107355},{"batb":[[0,11,2.52],[1,10.5,15.35]],"ltp":10.0,"tv":171.4,"id":22121325},{"batb":[[2,120,1.81]],"ltp":280.0,"tv":1.54,"id":24270700}]}]}
{"op":"mcm","clk":"991971759","pt":1580511242715,"mc":[{"id":"1.168133543","rc":[{"batb":[[1,110,1.21],[2,100,16.8]],"ltp":580.0,"tv":6.13,"id":27606066}]}]}
{"op":"mcm","clk":"991971964","pt":1580511247237,"mc":[{"id":"1.168133543","rc":[{"batb":[[0,55,4.26]],"ltp":80.0,"tv":11.61,"id":22308007}]}]}
{"op":"mcm","clk":"991972353","pt":1580511256562,"mc":[{"id":"1.168133543","rc":[{"batb":[[0,11,13.71],[1,10.5,3.62]],"ltp":10.0,"tv":171.4,"id":22121325}]}]}
{"op":"mcm","clk":"991975089","pt":1580511325387,"mc":[{"id":"1.168133543","rc":[{"batb":[[0,2.24,4.07],[1,2.22,20.2]],"ltp":2.38,"tv":1786.64,"id":10107355}]}]}
{"op":"mcm","clk":"991975166","pt":1580511327497,"mc":[{"id":"1.168133543","rc":[{"batb":[[1,2.22,12.4]],"ltp":2.38,"tv":1786.64,"id":10107355}]}]}
{"op":"mcm","clk":"991975180","pt":1580511327699,"mc":[{"id":"1.168133543","rc":[{"batb":[[0,2.24,11.79]],"ltp":2.38,"tv":1786.64,"id":10107355}]}]}
{"op":"mcm","clk":"991976638","pt":1580511367394,"mc":[{"id":"1.168133543","rc":[{"batb":[[0,2.26,3.36],[1,2.24,11.79],[2,2.22,12.4]],"ltp":2.38,"tv":1786.64,"id":10107355}]}]}
{"op":"mcm","clk":"991976731","pt":1580511370481,"mc":[{"id":"1.168133543","rc":[{"batb":[[0,180,1.26]],"ltp":280.0,"tv":1.54,"id":24270700}]}]}
{"op":"mcm","clk":"991977666","pt":1580511393431,"mc":[{"id":"1.168133543","rc":[{"batb":[[0,11.5,1.5],[1,11,13.71],[2,10.5,1.98]],"ltp":10.0,"tv":171.4,"id":22121325}]}]}
{"op":"mcm","clk":"991978656","pt":1580511414572,"mc":[{"id":"1.168133543","rc":[{"trd":[[2.82,76.15],[2.84,50.84]],"batb":[[0,2.82,10.48],[1,2.8,2],[2,2.78,2.52]],"ltp":2.82,"tv":720.52,"id":12636}],"tv":2886.51}]}
{"op":"mcm","clk":"991978682","pt":1580511415081,"mc":[{"id":"1.168133543","rc":[{"batb":[[0,2.82,8.06]],"ltp":2.82,"tv":720.52,"id":12636},{"batb":[[0,2.24,11.79],[1,2.22,12.4],[2,2.2,100]],"ltp":2.38,"tv":1786.64,"id":10107355}]}]}
{"op":"mcm","clk":"991979098","pt":1580511423388,"mc":[{"id":"1.168133543","rc":[{"batb":[[0,11.5,3.48],[2,9.8,4.97]],"ltp":10.0,"tv":171.4,"id":22121325}]}]}
{"op":"mcm","clk":"991979396","pt":1580511428489,"mc":[{"id":"1.168133543","rc":[{"batb":[[1,11,2.52]],"ltp":10.0,"tv":171.4,"id":22121325}]}]}
{"op":"mcm","clk":"991979445","pt":1580511429473,"mc":[{"id":"1.168133543","rc":[{"batb":[[0,11.5,14.19]],"ltp":10.0,"tv":171.4,"id":22121325}]}]}
{"op":"mcm","clk":"991980945","pt":1580511467382,"mc":[{"id":"1.168133543","rc":[{"trd":[[2.24,221.61]],"batb":[[0,2.22,12.4],[1,2.2,100],[2,2,61.45]],"batl":[[0,2.24,25.61],[1,2.34,2],[2,2.36,3.79]],"ltp":2.24,"tv":1835.42,"id":10107355}],"tv":2935.29}]}
{"op":"mcm","clk":"991981100","pt":1580511471515,"mc":[{"id":"1.168133543","rc":[{"batb":[[0,2.82,34.09]],"ltp":2.82,"tv":720.52,"id":12636},{"batb":[[0,8.8,18.88]],"ltp":9.0,"tv":145.25,"id":10163711},{"batb":[[0,180,1.96]],"ltp":280.0,"tv":1.54,"id":24270700}]}]}
{"op":"mcm","clk":"991981141","pt":1580511472510,"mc":[{"id":"1.168133543","rc":[{"batb":[[0,2.84,14.61],[1,2.82,34.09],[2,2.8,2]],"ltp":2.82,"tv":720.52,"id":12636},{"batb":[[0,9,4.92],[1,8.8,18.57],[2,8.6,2.52]],"ltp":9.0,"tv":145.25,"id":10163711},{"batb":[[0,2.22,31.09]],"ltp":2.24,"tv":1835.42,"id":10107355},{"trd":[[12,6.15]],"batb":[[0,12,3.37],[1,11.5,14.19],[2,11,2.52]],"batl":[[0,15,2.86]],"ltp":12.0,"tv":171.57,"id":22121325}],"tv":2935.46}]}
{"op":"mcm","clk":"991981147","pt":1580511472616,"mc":[{"id":"1.168133543","rc":[{"batb":[[0,80,2.72]],"ltp":150.0,"tv":1.36,"id":26548208}]}]}
{"op":"mcm","clk":"991981242","pt":1580511475017,"mc":[{"id":"1.168133543","rc":[{"batb":[[2,2.02,6]],"ltp":2.24,"tv":1835.42,"id":10107355}]}]}
{"op":"mcm","clk":"991981302","pt":1580511476509,"mc":[{"id":"1.168133543","rc":[{"batl":[[0,2.28,25.61]],"ltp":2.24,"tv":1835.42,"id":10107355}]}]}
{"op":"mcm","clk":"991981357","pt":1580511477903,"mc":[{"id":"1.168133543","rc":[{"batb":[[1,75,2.08]],"ltp":150.0,"tv":1.36,"id":26548208}]}]}
{"op":"mcm","clk":"991981656","pt":1580511485519,"mc":[{"id":"1.168133543","rc":[{"batb":[[1,2.82,8.06]],"ltp":2.82,"tv":720.52,"id":12636},{"batb":[[0,9.2,13.76],[1,9,4.92],[2,8.8,4.18]],"ltp":9.0,"tv":145.25,"id":10163711},{"batl":[[0,2.3,25.61]],"ltp":2.24,"tv":1835.42,"id":10107355},{"batb":[[0,12,13.63],[1,11.5,3.48]],"ltp":12.0,"tv":171.57,"id":22121325},{"batb":[[1,70,1.11],[2,60,1.23]],"ltp":150.0,"tv":1.36,"id":26548208}]}]}
{"op":"mcm","clk":"991981679","pt":1580511486340,"mc":[{"id":"1.168133543","rc":[{"batb":[[0,85,2.34],[1,80,1.87],[2,70,1.11]],"ltp":150.0,"tv":1.36,"id":26548208}]}]}
{"op":"mcm","clk":"991981871","pt":1580511492410,"mc":[{"id":"1.168133543","rc":[{"batb":[[2,70,1.1]],"ltp":150.0,"tv":1.36,"id":26548208}]}]}
{"op":"mcm","clk":"991981910","pt":1580511493431,"mc":[{"id":"1.168133543","rc":[{"batl":[[0,9.8,3.12],[1,10,66],[2,29,9.24]],"ltp":9.0,"tv":145.25,"id":10163711},{"batb":[[1,80,1.88]],"ltp":150.0,"tv":1.36,"id":26548208}]}]}
{"op":"mcm","clk":"991982150","pt":1580511499348,"mc":[{"id":"1.168133543","rc":[{"batb":[[0,180,1.26]],"ltp":280.0,"tv":1.54,"id":24270700}]}]}
{"op":"mcm","clk":"991982343","pt":1580511504537,"mc":[{"id":"1.168133543","rc":[{"trd":[[9.8,6.18]],"batl":[[0,10,66],[1,29,9.24],[2,1000,1.45]],"ltp":9.8,"tv":145.43,"id":10163711}],"tv":2935.64}]}
{"op":"mcm","clk":"991982486","pt":1580511508351,"mc":[{"id":"1.168133543","rc":[{"batb":[[0,9.2,13.86]],"ltp":9.8,"tv":145.43,"id":10163711}]}]}
{"op":"mcm","clk":"991984217","pt":1580511549533,"mc":[{"id":"1.168133543","rc":[{"batb":[[1,9,15.92]],"ltp":9.8,"tv":145.43,"id":10163711}]}]}
{"op":"mcm","clk":"991984435","pt":1580511554935,"mc":[{"id":"1.168133543","rc":[{"trd":[[2.3,456.01]],"batl":[[0,2.3,17.61]],"ltp":2.3,"tv":1851.42,"id":10107355}],"tv":2951.64}]}
{"op":"mcm","clk":"991986824","pt":1580511603548,"mc":[{"id":"1.168133543","rc":[{"batb":[[1,11.5,1.98]],"ltp":12.0,"tv":171.57,"id":22121325}]}]}
{"op":"mcm","clk":"991986837","pt":1580511603757,"mc":[{"id":"1.168133543","rc":[{"batb":[[0,12.5,1.38],[1,12,13.63],[2,11.5,1.98]],"ltp":12.0,"tv":171.57,"id":22121325}]}]}
{"op":"mcm","clk":"991987370","pt":1580511612766,"mc":[{"id":"1.168133543","rc":[{"batb":[[1,2.2,104]],"ltp":2.3,"tv":1851.42,"id":10107355}]}]}
{"op":"mcm","clk":"991987453","pt":1580511614472,"mc":[{"id":"1.168133543","rc":[{"batb":[[1,12,3.37]],"ltp":12.0,"tv":171.57,"id":22121325}]}]}
{"op":"mcm","clk":"991987507","pt":1580511615553,"mc":[{"id":"1.168133543","rc":[{"batl":[[1,16,3.03],[2,16.5,1.94]],"ltp":12.0,"tv":171.57,"id":22121325}]}]}
{"op":"mcm","clk":"991987710","pt":1580511618560,"mc":[{"id":"1.168133543","rc":[{"trd":[[12,32.35],[12.5,2.76]],"batb":[[0,11.5,1.98],[1,11,2.52],[2,9.8,5.06]],"batl":[[0,15,3.38]],"ltp":12.0,"tv":200.53,"id":22121325}],"tv":2980.6}]}
{"op":"mcm","clk":"991987715","pt":1580511618657,"mc":[{"id":"1.168133543","rc":[{"trd":[[12,33.39]],"batl":[[0,15,2.86]],"ltp":12.0,"tv":201.57,"id":22121325}],"tv":2981.64}]}
{"op":"mcm","clk":"991987840","pt":1580511621181,"mc":[{"id":"1.168133543","rc":[{"batb":[[0,9.4,1.83],[1,9.2,13.86],[2,9,15.68]],"ltp":9.8,"tv":145.43,"id":10163711}]}]}
{"op":"mcm","clk":"991988297","pt":1580511628569,"mc":[{"id":"1.168133543","rc":[{"batb":[[1,9,15.79],[2,8.8,4.18]],"ltp":9.8,"tv":145.43,"id":10163711},{"batb":[[1,11,13.71]],"ltp":12.0,"tv":201.57,"id":22121325}]}]}
{"op":"mcm","clk":"991988300","pt":1580511628669,"mc":[{"id":"1.168133543","rc":[{"batb":[[0,180,1.96]],"ltp":280.0,"tv":1.54,"id":24270700}]}]}
{"op":"mcm","clk":"991989519","pt":1580511656127,"mc":[{"id":"1.168133543","rc":[{"batl":[[0,2.28,4],[1,2.3,17.61],[2,2.34,2]],"ltp":2.3,"tv":1851.42,"id":10107355}]}]}
{"op":"mcm","clk":"991990126","pt":1580511670415,"mc":[{"id":"1.168133543","rc":[{"batb":[[0,2.86,8],[1,2.84,14.61],[2,2.82,8.06]],"ltp":2.82,"tv":720.52,"id":12636}]}]}
{"op":"mcm","clk":"991990568","pt":1580511680447,"mc":[{"id":"1.168133543","rc":[{"batl":[[0,9.8,3.38],[1,10,66],[2,29,9.24]],"ltp":9.8,"tv":145.43,"id":10163711}]}]}
{"op":"mcm","clk":"991992175","pt":1580511720429,"mc":[{"id":"1.168133543","rc":[{"batl":[[0,2.28,8]],"ltp":2.3,"tv":1851.42,"id":10107355}]}]}
{"op":"mcm","clk":"991993244","pt":1580511746690,"mc":[{"id":"1.168133543","rc":[{"batl":[[2,2.36,3.79]],"ltp":2.3,"tv":1851.42,"id":10107355}]}]}
{"op":"mcm","clk":"991994570","pt":1580511776059,"mc":[{"id":"1.168133543","rc":[{"batb":[[0,2.24,20],[1,2.22,31.09],[2,2.2,104]],"ltp":2.3,"tv":1851.42,"id":10107355}]}]}
{"op":"mcm","clk":"991995171","pt":1580511789167,"mc":[{"id":"1.168133543","rc":[{"trd":[[2.28,199.43]],"batl":[[0,2.28,3.55]],"ltp":2.28,"tv":1860.32,"id":10107355}],"tv":2990.54}]}
{"op":"mcm","clk":"992000404","pt":1580511896189,"mc":[{"id":"1.168133543","rc":[{"trd":[[2.28,205.48]],"batl":[[0,2.3,18.13],[1,2.36,3.79],[2,2.38,38.4]],"ltp":2.28,"tv":1866.38,"id":10107355}],"tv":2996.6}]}
{"op":"mcm","clk":"992001791","pt":1580511931146,"mc":[{"id":"1.168133543","rc":[{"trd":[[2.28,206.53],[2.3,461.03]],"batl":[[0,2.3,15.1]],"ltp":2.3,"tv":1872.44,"id":10107355}],"tv":3002.66}]}
{"op":"mcm","clk":"992001974","pt":1580511935230,"mc":[{"id":"1.168133543","rc":[{"batl":[[0,14.5,2],[1,15,2.86],[2,16,3.03]],"ltp":12.0,"tv":201.57,"id":22121325}]}]}
{"op":"mcm","clk":"992002578","pt":1580511948165,"mc":[{"id":"1.168133543","rc":[{"batl":[[0,14.5,5.03],[2,16.5,1.94]],"ltp":12.0,"tv":201.57,"id":22121325}]}]}
{"op":"mcm","clk":"992002723","pt":1580511951515,"mc":[{"id":"1.168133543","rc":[{"batl":[[1,2.32,4],[2,2.36,3.79]],"ltp":2.3,"tv":1872.44,"id":10107355}]}]}
{"op":"mcm","clk":"992002907","pt":1580511955124,"mc":[{"id":"1.168133543","rc":[{"batl":[[0,14,1.98],[1,14.5,5.03]],"ltp":12.0,"tv":201.57,"id":22121325}]}]}
{"op":"mcm","clk":"992003271","pt":1580511962399,"mc":[{"id":"1.168133543","rc":[{"batl":[[0,2.9,48.54]],"ltp":2.82,"tv":720.52,"id":12636}]}]}
{"op":"mcm","clk":"992003305","pt":1580511963020,"mc":[{"id":"1.168133543","rc":[{"batb":[[0,2.86,11.03]],"ltp":2.82,"tv":720.52,"id":12636}]}]}
{"op":"mcm","clk":"992003484","pt":1580511967136,"mc":[{"id":"1.168133543","rc":[{"trd":[[2.3,467.09]],"batl":[[0,2.3,12.07]],"ltp":2.3,"tv":1878.5,"id":10107355}],"tv":3008.72}]}
{"op":"mcm","clk":"992003567","pt":1580511969212,"mc":[{"id":"1.168133543","rc":[{"trd":[[2.3,473.15]],"batl":[[0,2.3,9.04]],"ltp":2.3,"tv":1884.56,"id":10107355}],"tv":3014.78}]}
{"op":"mcm","clk":"992003773","pt":1580511974019,"mc":[{"id":"1.168133543","rc":[{"batl":[[0,2.28,3.03],[1,2.3,9.04],[2,2.32,4]],"ltp":2.3,"tv":1884.56,"id":10107355}]}]}
{"op":"mcm","clk":"992004474","pt":1580511989565,"mc":[{"id":"1.168133543","rc":[{"batl":[[1,14.5,3.03]],"ltp":12.0,"tv":201.57,"id":22121325}]}]}
{"op":"mcm","clk":"992004484","pt":1580511989773,"mc":[{"id":"1.168133543","rc":[{"batl":[[0,13.5,2],[1,14,1.98],[2,14.5,3.03]],"ltp":12.0,"tv":201.57,"id":22121325}]}]}
{"op":"mcm","clk":"992004753","pt":1580511996365,"mc":[{"id":"1.168133543","rc":[{"batl":[[1,14.5,3.03],[2,16.5,1.94]],"ltp":12.0,"tv":201.57,"id":22121325}]}]}
{"op":"mcm","clk":"992004794","pt":1580511997190,"mc":[{"id":"1.168133543","rc":[{"batl":[[0,13,2.13],[1,13.5,2],[2,14.5,3.03]],"ltp":12.0,"tv":201.57,"id":22121325}]}]}
{"op":"mcm","clk":"992004971","pt":1580512002495,"mc":[{"id":"1.168133543","rc":[{"batb":[[1,9.2,13.86],[2,9,15.68]],"ltp":9.8,"tv":145.43,"id":10163711}]}]}
{"op":"mcm","clk":"992005348","pt":1580512011516,"mc":[{"id":"1.168133543","rc":[{"batl":[[0,10,66],[1,29,9.24],[2,1000,1.45]],"ltp":9.8,"tv":145.43,"id":10163711},{"batl":[[0,13,5.16],[2,16.5,1.94]],"ltp":12.0,"tv":201.57,"id":22121325}]}]}
{"op":"mcm","clk":"992006829","pt":1580512044283,"mc":[{"id":"1.168133543","rc":[{"batl":[[0,13,2.13],[1,16,3.03]],"ltp":12.0,"tv":201.57,"id":22121325}]}]}
{"op":"mcm","clk":"992006877","pt":1580512045467,"mc":[{"id":"1.168133543","rc":[{"batb":[[1,9,15.79],[2,8.8,4.18]],"ltp":9.8,"tv":145.43,"id":10163711},{"batb":[[0,180,1.26]],"ltp":280.0,"tv":1.54,"id":24270700}]}]}
{"op":"mcm","clk":"992017088","pt":1580512058187,"mc":[{"id":"1.168133543","rc":[{"batl":[[0,16,3.03],[1,16.5,1.94],[2,65,9.08]],"ltp":12.0,"tv":201.57,"id":22121325}]}]}
