{"op":"mcm","clk":"987629431","pt":1580469284549,"mc":[{"id":"1.168133543","marketDefinition":{"bspMarket":true,"turnInPlayEnabled":true,"persistenceEnabled":true,"marketBaseRate":5.0,"eventId":"29678760","eventTypeId":"7","numberOfWinners":1,"bettingType":"ODDS","marketType":"WIN","marketTime":"2020-02-01T13:03:00.000Z","suspendTime":"2020-02-01T13:03:00.000Z","bspReconciled":false,"complete":true,"inPlay":false,"crossMatching":false,"runnersVoidable":false,"numberOfActiveRunners":11,"betDelay":0,"status":"OPEN","runners":[{"adjustmentFactor":38.12,"status":"ACTIVE","sortPriority":1,"id":10107355,"name":"Emmas Joy"},{"adjustmentFactor":22.46,"status":"ACTIVE","sortPriority":2,"id":12636,"name":"Full Of Surprises"},{"adjustmentFactor":19.57,"status":"ACTIVE","sortPriority":3,"id":10163711,"name":"Easter Gold"},{"adjustmentFactor":6.33,"status":"ACTIVE","sortPriority":4,"id":22121325,"name":"Who What When"},{"adjustmentFactor":5.03,"status":"ACTIVE","sortPriority":5,"id":7226819,"name":"Set In Stone"},{"adjustmentFactor":4.11,"status":"ACTIVE","sortPriority":6,"id":26548208,"name":"Lex Eleven"},{"adjustmentFactor":1.8,"status":"ACTIVE","sortPriority":7,"id":13306150,"name":"Elysee Star"},{"adjustmentFactor":1.17,"status":"ACTIVE","sortPriority":8,"id":22308007,"name":"Bravantina"},{"adjustmentFactor":0.59,"status":"ACTIVE","sortPriority":9,"id":27606066,"name":"Backoftheenvelope"},{"adjustmentFactor":0.59,"status":"ACTIVE","sortPriority":10,"id":24270700,"name":"Annebelle"},{"adjustmentFactor":0.17,"status":"ACTIVE","sortPriority":11,"id":13819977,"name":"Olivers Betty"}],"regulators":["MR_INT"],"venue":"Wetherby","countryCode":"GB","discountAllowed":false,"timezone":"Europe/London","openDate":"2020-02-01T13:03:00.000Z","version":3142859022,"name":"2m Nov Hrd","eventName":"Weth  1st Feb"},"rc":[{"batb":[[0,1.51,3.36],[1,1.01,4240.56]],"ltp":0.0,"tv":0.0,"id":12636},{"batb":[[0,1.51,3.36],[1,1.01,4230.56]],"ltp":0.0,"tv":0.0,"id":13819977},{"batb":[[0,1.51,3.36],[1,1.01,4230.56]],"ltp":0.0,"tv":0.0,"id":22308007},{"batb":[[0,1.51,3.36],[1,1.01,4240.56]],"ltp":0.0,"tv":0.0,"id":7226819},{"batb":[[0,1.51,3.36],[1,1.01,4240.56]],"ltp":0.0,"tv":0.0,"id":10163711},{"batb":[[0,1.51,3.36],[1,1.01,4240.56]],"ltp":0.0,"tv":0.0,"id":10107355},{"batb":[[0,1.51,3.36],[1,1.01,4240.56]],"ltp":0.0,"tv":0.0,"id":22121325},{"batb":[[0,1.51,3.36],[1,1.01,4230.56]],"ltp":0.0,"tv":0.0,"id":26548208},{"batb":[[0,1.51,3.36],[1,1.01,4230.56]],"ltp":0.0,"tv":0.0,"id":27606066},{"batb":[[0,1.51,3.36],[1,1.01,4230.56]],"ltp":0.0,"tv":0.0,"id":24270700},{"batb":[[0,1.51,3.36],[1,1.01,4230.56]],"ltp":0.0,"tv":0.0,"id":13306150}]}]}
{"op":"mcm","clk":"987629520","pt":1580469285566,"mc":[{"id":"1.168133543","marketDefinition":{"bspMarket":true,"turnInPlayEnabled":true,"persistenceEnabled":true,"marketBaseRate":5.0,"eventId":"29678760","eventTypeId":"7","numberOfWinners":1,"bettingType":"ODDS","marketType":"WIN","marketTime":"2020-02-01T13:03:00.000Z","suspendTime":"2020-02-01T13:03:00.000Z","bspReconciled":false,"complete":true,"inPlay":false,"crossMatching":false,"runnersVoidable":false,"numberOfActiveRunners":11,"betDelay":0,"status":"OPEN","runners":[{"adjustmentFactor":38.12,"status":"ACTIVE","sortPriority":1,"id":10107355,"name":"Emmas Joy"},{"adjustmentFactor":22.46,"status":"ACTIVE","sortPriority":2,"id":12636,"name":"Full Of Surprises"},{"adjustmentFactor":19.57,"status":"ACTIVE","sortPriority":3,"id":10163711,"name":"Easter Gold"},{"adjustmentFactor":6.33,"status":"ACTIVE","sortPriority":4,"id":22121325,"name":"Who What When"},{"adjustmentFactor":5.03,"status":"ACTIVE","sortPriority":5,"id":7226819,"name":"Set In Stone"},{"adjustmentFactor":4.11,"status":"ACTIVE","sortPriority":6,"id":26548208,"name":"Lex Eleven"},{"adjustmentFactor":1.8,"status":"ACTIVE","sortPriority":7,"id":13306150,"name":"Elysee Star"},{"adjustmentFactor":1.17,"status":"ACTIVE","sortPriority":8,"id":22308007,"name":"Bravantina"},{"adjustmentFactor":0.59,"status":"ACTIVE","sortPriority":9,"id":27606066,"name":"Backoftheenvelope"},{"adjustmentFactor":0.59,"status":"ACTIVE","sortPriority":10,"id":24270700,"name":"Annebelle"},{"adjustmentFactor":0.17,"status":"ACTIVE","sortPriority":11,"id":13819977,"name":"Olivers Betty"}],"regulators":["MR_INT"],"venue":"Wetherby","countryCode":"GB","discountAllowed":true,"timezone":"Europe/London","openDate":"2020-02-01T13:03:00.000Z","version":3142859022,"name":"2m Nov Hrd","eventName":"Weth  1st Feb"},"rc":[{"batb":[[1,1.01,4240.56]],"ltp":0.0,"tv":0.0,"id":22308007},{"batb":[[1,1.01,4240.56]],"ltp":0.0,"tv":0.0,"id":26548208},{"batb":[[1,1.01,4240.56]],"ltp":0.0,"tv":0.0,"id":27606066},{"batb":[[1,1.01,4240.56]],"ltp":0.0,"tv":0.0,"id":24270700},{"batb":[[1,1.01,4240.56]],"ltp":0.0,"tv":0.0,"id":13306150}]}]}
{"op":"mcm","clk":"987629528","pt":1580469285754,"mc":[{"id":"1.168133543","rc":[{"batb":[[1,1.01,4240.56]],"ltp":0.0,"tv":0.0,"id":13819977}]}]}
{"op":"mcm","clk":"987631761","pt":1580469307284,"mc":[{"id":"1.168133543","rc":[{"batb":[[1,1.01,4099.96]],"ltp":0.0,"tv":0.0,"id":22308007}]}]}
{"op":"mcm","clk":"987631905","pt":1580469309278,"mc":[{"id":"1.168133543","rc":[{"batb":[[1,1.01,4099.96]],"ltp":0.0,"tv":0.0,"id":22121325},{"batb":[[1,1.01,4099.96]],"ltp":0.0,"tv":0.0,"id":13306150}]}]}
{"op":"mcm","clk":"987631998","pt":1580469310475,"mc":[{"id":"1.168133543","rc":[{"batb":[[1,1.01,4099.96]],"ltp":0.0,"tv":0.0,"id":13819977},{"batb":[[1,1.01,4099.96]],"ltp":0.0,"tv":0.0,"id":10163711}]}]}
{"op":"mcm","clk":"987632060","pt":1580469311368,"mc":[{"id":"1.168133543","rc":[{"batb":[[1,1.01,4099.96]],"ltp":0.0,"tv":0.0,"id":10107355}]}]}
{"op":"mcm","clk":"987632124","pt":1580469312304,"mc":[{"id":"1.168133543","rc":[{"batb":[[1,1.01,4099.96]],"ltp":0.0,"tv":0.0,"id":12636}]}]}
{"op":"mcm","clk":"987632207","pt":1580469313506,"mc":[{"id":"1.168133543","rc":[{"batb":[[1,1.01,4099.96]],"ltp":0.0,"tv":0.0,"id":7226819},{"batb":[[1,1.01,4099.96]],"ltp":0.0,"tv":0.0,"id":24270700}]}]}
{"op":"mcm","clk":"987632321","pt":1580469314288,"mc":[{"id":"1.168133543","rc":[{"batb":[[1,1.01,4099.96]],"ltp":0.0,"tv":0.0,"id":26548208}]}]}
{"op":"mcm","clk":"987632404","pt":1580469315279,"mc":[{"id":"1.168133543","rc":[{"batb":[[1,1.01,4099.96]],"ltp":0.0,"tv":0.0,"id":27606066}]}]}
{"op":"mcm","clk":"987632887","pt":1580469322421,"mc":[{"id":"1.168133543","rc":[{"batb":[[1,1.03,5.18],[2,1.01,4099.96]],"ltp":0.0,"tv":0.0,"id":12636},{"batb":[[1,1.03,5.18],[2,1.01,4099.96]],"ltp":0.0,"tv":0.0,"id":13819977},{"batb":[[1,1.03,5.18],[2,1.01,4099.96]],"ltp":0.0,"tv":0.0,"id":22308007},{"batb":[[1,1.03,5.18],[2,1.01,4099.96]],"ltp":0.0,"tv":0.0,"id":7226819},{"batb":[[1,1.03,5.18],[2,1.01,4099.96]],"ltp":0.0,"tv":0.0,"id":10163711},{"batb":[[1,1.03,5.18],[2,1.01,4099.96]],"ltp":0.0,"tv":0.0,"id":10107355},{"batb":[[1,1.03,5.18],[2,1.01,4099.96]],"ltp":0.0,"tv":0.0,"id":22121325},{"batb":[[1,1.03,5.18],[2,1.01,4099.96]],"ltp":0.0,"tv":0.0,"id":26548208},{"batb":[[1,1.03,5.18],[2,1.01,4099.96]],"ltp":0.0,"tv":0.0,"id":27606066},{"batb":[[1,1.03,5.18],[2,1.01,4099.96]],"ltp":0.0,"tv":0.0,"id":24270700},{"batb":[[1,1.03,5.18],[2,1.01,4099.96]],"ltp":0.0,"tv":0.0,"id":13306150}]}]}
{"op":"mcm","clk":"987633177","pt":1580469325821,"mc":[{"id":"1.168133543","rc":[{"batb":[[2,1.01,4101.96]],"ltp":0.0,"tv":0.0,"id":12636},{"batb":[[2,1.01,4101.96]],"ltp":0.0,"tv":0.0,"id":13819977},{"batb":[[2,1.01,4101.96]],"ltp":0.0,"tv":0.0,"id":22308007},{"batb":[[2,1.01,4101.96]],"ltp":0.0,"tv":0.0,"id":7226819},{"batb":[[2,1.01,4101.96]],"ltp":0.0,"tv":0.0,"id":10163711},{"batb":[[2,1.01,4101.96]],"ltp":0.0,"tv":0.0,"id":10107355},{"batb":[[2,1.01,4101.96]],"ltp":0.0,"tv":0.0,"id":22121325},{"batb":[[2,1.01,4101.96]],"ltp":0.0,"tv":0.0,"id":26548208},{"batb":[[2,1.01,4101.96]],"ltp":0.0,"tv":0.0,"id":27606066},{"batb":[[2,1.01,4101.96]],"ltp":0.0,"tv":0.0,"id":24270700},{"batb":[[2,1.01,4101.96]],"ltp":0.0,"tv":0.0,"id":13306150}]}]}
{"op":"mcm","clk":"987633431","pt":1580469330036,"mc":[{"id":"1.168133543","rc":[{"batb":[[1,1.03,1719.34]],"ltp":0.0,"tv":0.0,"id":12636},{"batb":[[1,1.03,1579.79]],"ltp":0.0,"tv":0.0,"id":13819977},{"batb":[[1,1.03,1694.12]],"ltp":0.0,"tv":0.0,"id":22308007},{"batb":[[1,1.03,1605.85]],"ltp":0.0,"tv":0.0,"id":7226819},{"batb":[[1,1.03,1536.91]],"ltp":0.0,"tv":0.0,"id":10163711},{"batb":[[1,1.03,1564.66]],"ltp":0.0,"tv":0.0,"id":10107355},{"batb":[[1,1.03,1713.46]],"ltp":0.0,"tv":0.0,"id":22121325},{"batb":[[1,1.03,1705.89]],"ltp":0.0,"tv":0.0,"id":26548208},{"batb":[[1,1.03,1745.41]],"ltp":0.0,"tv":0.0,"id":27606066},{"batb":[[1,1.03,1726.07]],"ltp":0.0,"tv":0.0,"id":24270700},{"batb":[[1,1.03,1548.68]],"ltp":0.0,"tv":0.0,"id":13306150}]}]}
{"op":"mcm","clk":"987642172","pt":1580469441521,"mc":[{"id":"1.168133543","rc":[{"batb":[[2,1.01,4103.64]],"ltp":0.0,"tv":0.0,"id":12636},{"batb":[[2,1.01,4103.64]],"ltp":0.0,"tv":0.0,"id":10163711},{"batb":[[2,1.01,4103.64]],"ltp":0.0,"tv":0.0,"id":10107355}]}]}
{"op":"mcm","clk":"987642236","pt":1580469442421,"mc":[{"id":"1.168133543","rc":[{"batb":[[2,1.01,4103.64]],"ltp":0.0,"tv":0.0,"id":7226819},{"batb":[[2,1.01,4103.64]],"ltp":0.0,"tv":0.0,"id":22121325},{"batb":[[2,1.01,4103.64]],"ltp":0.0,"tv":0.0,"id":26548208}]}]}
{"op":"mcm","clk":"987642303","pt":1580469443414,"mc":[{"id":"1.168133543","rc":[{"batb":[[2,1.01,4103.64]],"ltp":0.0,"tv":0.0,"id":22308007},{"batb":[[2,1.01,4103.64]],"ltp":0.0,"tv":0.0,"id":27606066},{"batb":[[2,1.01,4103.64]],"ltp":0.0,"tv":0.0,"id":13306150}]}]}
{"op":"mcm","clk":"987642341","pt":1580469444000,"mc":[{"id":"1.168133543","rc":[{"batb":[[2,1.01,4103.64]],"ltp":0.0,"tv":0.0,"id":13819977},{"batb":[[2,1.01,4103.64]],"ltp":0.0,"tv":0.0,"id":24270700}]}]}
{"op":"mcm","clk":"987650056","pt":1580469544573,"mc":[{"id":"1.168133543","rc":[{"batb":[[2,1.01,4105.64]],"ltp":0.0,"tv":0.0,"id":10107355}]}]}
{"op":"mcm","clk":"987650095","pt":1580469545046,"mc":[{"id":"1.168133543","rc":[{"batb":[[2,1.02,1.99]],"ltp":0.0,"tv":0.0,"id":10107355}]}]}
{"op":"mcm","clk":"987650203","pt":1580469546356,"mc":[{"id":"1.168133543","rc":[{"batb":[[2,1.02,1.99]],"ltp":0.0,"tv":0.0,"id":12636}]}]}
{"op":"mcm","clk":"987650281","pt":1580469547390,"mc":[{"id":"1.168133543","rc":[{"batb":[[2,1.02,1.99]],"ltp":0.0,"tv":0.0,"id":10163711}]}]}
{"op":"mcm","clk":"987650363","pt":1580469548488,"mc":[{"id":"1.168133543","rc":[{"batb":[[2,1.01,4105.64]],"ltp":0.0,"tv":0.0,"id":22121325}]}]}
{"op":"mcm","clk":"987650424","pt":1580469549377,"mc":[{"id":"1.168133543","rc":[{"batb":[[2,1.01,4107.63]],"ltp":0.0,"tv":0.0,"id":7226819},{"batb":[[2,1.02,1.99]],"ltp":0.0,"tv":0.0,"id":22121325}]}]}
{"op":"mcm","clk":"987650515","pt":1580469550479,"mc":[{"id":"1.168133543","rc":[{"batb":[[2,1.02,1.99]],"ltp":0.0,"tv":0.0,"id":7226819},{"batb":[[2,1.02,1.99]],"ltp":0.0,"tv":0.0,"id":26548208}]}]}
{"op":"mcm","clk":"987650592","pt":1580469551573,"mc":[{"id":"1.168133543","rc":[{"batb":[[2,1.01,4105.64]],"ltp":0.0,"tv":0.0,"id":22308007},{"batb":[[2,1.02,1.99]],"ltp":0.0,"tv":0.0,"id":13306150}]}]}
{"op":"mcm","clk":"987650679","pt":1580469552501,"mc":[{"id":"1.168133543","rc":[{"batb":[[2,1.01,4107.63]],"ltp":0.0,"tv":0.0,"id":22308007}]}]}
{"op":"mcm","clk":"987650751","pt":1580469553489,"mc":[{"id":"1.168133543","rc":[{"batb":[[2,1.02,1.99]],"ltp":0.0,"tv":0.0,"id":22308007},{"batb":[[2,1.01,4107.63]],"ltp":0.0,"tv":0.0,"id":27606066}]}]}
{"op":"mcm","clk":"987650819","pt":1580469554482,"mc":[{"id":"1.168133543","rc":[{"batb":[[2,1.02,1.99]],"ltp":0.0,"tv":0.0,"id":27606066},{"batb":[[2,1.01,4105.64]],"ltp":0.0,"tv":0.0,"id":24270700}]}]}
{"op":"mcm","clk":"987650917","pt":1580469555418,"mc":[{"id":"1.168133543","rc":[{"batb":[[2,1.01,4105.64]],"ltp":0.0,"tv":0.0,"id":13819977},{"batb":[[2,1.02,1.99]],"ltp":0.0,"tv":0.0,"id":24270700}]}]}
{"op":"mcm","clk":"987651003","pt":1580469556204,"mc":[{"id":"1.168133543","rc":[{"batb":[[2,1.02,1.99]],"ltp":0.0,"tv":0.0,"id":13819977}]}]}
{"op":"mcm","clk":"987683625","pt":1580469881044,"mc":[{"id":"1.168133543","rc":[{"batb":[[1,1.04,3],[2,1.03,1719.34]],"ltp":0.0,"tv":0.0,"id":12636},{"batb":[[1,1.04,3],[2,1.03,1579.79]],"ltp":0.0,"tv":0.0,"id":13819977},{"batb":[[1,1.04,3],[2,1.03,1694.12]],"ltp":0.0,"tv":0.0,"id":22308007},{"batb":[[1,1.04,3],[2,1.03,1605.85]],"ltp":0.0,"tv":0.0,"id":7226819},{"batb":[[1,1.04,3],[2,1.03,1536.91]],"ltp":0.0,"tv":0.0,"id":10163711},{"batb":[[1,1.04,3],[2,1.03,1564.66]],"ltp":0.0,"tv":0.0,"id":10107355},{"batb":[[1,1.04,3],[2,1.03,1713.46]],"ltp":0.0,"tv":0.0,"id":22121325},{"batb":[[1,1.04,3],[2,1.03,1705.89]],"ltp":0.0,"tv":0.0,"id":26548208},{"batb":[[1,1.04,3],[2,1.03,1745.41]],"ltp":0.0,"tv":0.0,"id":27606066},{"batb":[[1,1.04,3],[2,1.03,1726.07]],"ltp":0.0,"tv":0.0,"id":24270700},{"batb":[[1,1.04,3],[2,1.03,1548.68]],"ltp":0.0,"tv":0.0,"id":13306150}]}]}
{"op":"mcm","clk":"987758990","pt":1580470974943,"mc":[{"id":"1.168133543","rc":[{"batl":[[0,1000,0.2]],"ltp":0.0,"tv":0.0,"id":12636},{"batl":[[0,1000,0.2]],"ltp":0.0,"tv":0.0,"id":13819977},{"batl":[[0,1000,0.2]],"ltp":0.0,"tv":0.0,"id":22308007},{"batl":[[0,1000,0.2]],"ltp":0.0,"tv":0.0,"id":7226819},{"batl":[[0,1000,0.2]],"ltp":0.0,"tv":0.0,"id":10163711},{"batl":[[0,1000,0.2]],"ltp":0.0,"tv":0.0,"id":10107355},{"batl":[[0,1000,0.2]],"ltp":0.0,"tv":0.0,"id":22121325},{"batl":[[0,1000,0.2]],"ltp":0.0,"tv":0.0,"id":26548208},{"batl":[[0,1000,0.2]],"ltp":0.0,"tv":0.0,"id":27606066},{"batl":[[0,1000,0.2]],"ltp":0.0,"tv":0.0,"id":24270700},{"batl":[[0,1000,0.2]],"ltp":0.0,"tv":0.0,"id":13306150}]}]}
{"op":"mcm","clk":"987883046","pt":1580472452127,"mc":[{"id":"1.168133543","rc":[{"batb":[[2,1.03,1719.78]],"ltp":0.0,"tv":0.0,"id":12636},{"batb":[[2,1.03,1580.19]],"ltp":0.0,"tv":0.0,"id":13819977},{"batb":[[2,1.03,1694.55]],"ltp":0.0,"tv":0.0,"id":22308007},{"batb":[[2,1.03,1606.26]],"ltp":0.0,"tv":0.0,"id":7226819},{"batb":[[2,1.03,1537.3]],"ltp":0.0,"tv":0.0,"id":10163711},{"batb":[[2,1.03,1565.05]],"ltp":0.0,"tv":0.0,"id":10107355},{"batb":[[2,1.03,1713.89]],"ltp":0.0,"tv":0.0,"id":22121325},{"batb":[[2,1.03,1706.32]],"ltp":0.0,"tv":0.0,"id":26548208},{"batb":[[2,1.03,1745.85]],"ltp":0.0,"tv":0.0,"id":27606066},{"batb":[[2,1.03,1726.51]],"ltp":0.0,"tv":0.0,"id":24270700},{"batb":[[2,1.03,1549.08]],"ltp":0.0,"tv":0.0,"id":13306150}]}]}
{"op":"mcm","clk":"988215071","pt":1580475432515,"mc":[{"id":"1.168133543","rc":[{"batb":[[0,1.52,1.09],[1,1.51,3.36],[2,1.04,3]],"ltp":0.0,"tv":0.0,"id":12636},{"batb":[[0,1.52,1.09],[1,1.51,3.36],[2,1.04,3]],"ltp":0.0,"tv":0.0,"id":10107355}]}]}
{"op":"mcm","clk":"988215168","pt":1580475433484,"mc":[{"id":"1.168133543","rc":[{"batb":[[0,1.52,1.09],[1,1.51,3.36],[2,1.04,3]],"ltp":0.0,"tv":0.0,"id":22308007},{"batb":[[0,1.52,1.09],[1,1.51,3.36],[2,1.04,3]],"ltp":0.0,"tv":0.0,"id":7226819},{"batb":[[0,1.52,1.09],[1,1.51,3.36],[2,1.04,3]],"ltp":0.0,"tv":0.0,"id":10163711},{"batb":[[0,1.52,1.09],[1,1.51,3.36],[2,1.04,3]],"ltp":0.0,"tv":0.0,"id":22121325},{"batb":[[0,1.52,1.09],[1,1.51,3.36],[2,1.04,3]],"ltp":0.0,"tv":0.0,"id":26548208},{"batb":[[0,1.52,1.09],[1,1.51,3.36],[2,1.04,3]],"ltp":0.0,"tv":0.0,"id":27606066},{"batb":[[0,1.52,1.09],[1,1.51,3.36],[2,1.04,3]],"ltp":0.0,"tv":0.0,"id":13306150}]}]}
{"op":"mcm","clk":"988215199","pt":1580475433794,"mc":[{"id":"1.168133543","rc":[{"batb":[[0,1.52,1.09],[1,1.51,3.36],[2,1.04,3]],"ltp":0.0,"tv":0.0,"id":13819977},{"batb":[[0,1.52,1.09],[1,1.51,3.36],[2,1.04,3]],"ltp":0.0,"tv":0.0,"id":24270700}]}]}
{"op":"mcm","clk":"988638135","pt":1580479186312,"mc":[{"id":"1.168133543","rc":[{"batb":[[0,2,1.68],[1,1.52,1.09],[2,1.51,3.36]],"ltp":0.0,"tv":0.0,"id":12636}]}]}
{"op":"mcm","clk":"988638205","pt":1580479187160,"mc":[{"id":"1.168133543","rc":[{"batb":[[0,1.52,1.09],[1,1.51,3.36],[2,1.04,3]],"ltp":0.0,"tv":0.0,"id":12636}]}]}
{"op":"mcm","clk":"988668727","pt":1580479503442,"mc":[{"id":"1.168133543","rc":[{"batb":[[0,1.52,11.09]],"ltp":0.0,"tv":0.0,"id":12636},{"batb":[[0,1.52,11.09]],"ltp":0.0,"tv":0.0,"id":13819977},{"batb":[[0,1.52,11.09]],"ltp":0.0,"tv":0.0,"id":22308007},{"batb":[[0,1.52,11.09]],"ltp":0.0,"tv":0.0,"id":7226819},{"batb":[[0,1.52,11.09]],"ltp":0.0,"tv":0.0,"id":10163711},{"batb":[[0,1.52,11.09]],"ltp":0.0,"tv":0.0,"id":10107355},{"batb":[[0,1.52,11.09]],"ltp":0.0,"tv":0.0,"id":22121325},{"batb":[[0,1.52,11.09]],"ltp":0.0,"tv":0.0,"id":26548208},{"batb":[[0,1.52,11.09]],"ltp":0.0,"tv":0.0,"id":27606066},{"batb":[[0,1.52,11.09]],"ltp":0.0,"tv":0.0,"id":24270700},{"batb":[[0,1.52,11.09]],"ltp":0.0,"tv":0.0,"id":13306150}]}]}
{"op":"mcm","clk":"988672874","pt":1580479543502,"mc":[{"id":"1.168133543","rc":[{"batb":[[2,1.03,1720.07]],"ltp":0.0,"tv":0.0,"id":12636},{"batb":[[2,1.03,1580.45]],"ltp":0.0,"tv":0.0,"id":13819977},{"batb":[[2,1.03,1694.84]],"ltp":0.0,"tv":0.0,"id":22308007},{"batb":[[2,1.03,1606.53]],"ltp":0.0,"tv":0.0,"id":7226819},{"batb":[[2,1.03,1537.56]],"ltp":0.0,"tv":0.0,"id":10163711},{"batb":[[2,1.03,1565.32]],"ltp":0.0,"tv":0.0,"id":10107355},{"batb":[[2,1.03,1714.18]],"ltp":0.0,"tv":0.0,"id":22121325},{"batb":[[2,1.03,1706.61]],"ltp":0.0,"tv":0.0,"id":26548208},{"batb":[[2,1.03,1746.14]],"ltp":0.0,"tv":0.0,"id":27606066},{"batb":[[2,1.03,1726.8]],"ltp":0.0,"tv":0.0,"id":24270700},{"batb":[[2,1.03,1549.34]],"ltp":0.0,"tv":0.0,"id":13306150}]}]}
{"op":"mcm","clk":"988674622","pt":1580479565018,"mc":[{"id":"1.168133543","rc":[{"trd":[[1000,0.4]],"batb":[[0,1000,174.8],[1,1.52,11.09],[2,1.51,3.36]],"ltp":1000.0,"tv":0.4,"id":13819977}],"tv":0.4}]}
{"op":"mcm","clk":"988675974","pt":1580479585062,"mc":[{"id":"1.168133543","rc":[{"batb":[[1,1.52,10]],"ltp":1000.0,"tv":0.4,"id":13819977}]}]}
{"op":"mcm","clk":"988676265","pt":1580479589486,"mc":[{"id":"1.168133543","rc":[{"batb":[[1,1.51,3.36],[2,1.03,1580.45]],"ltp":1000.0,"tv":0.4,"id":13819977}]}]}
{"op":"mcm","clk":"988759842","pt":1580480455943,"mc":[{"id":"1.168133543","rc":[{"batb":[[0,1.53,3],[1,1.52,11.09],[2,1.51,3.36]],"ltp":0.0,"tv":0.0,"id":12636},{"batb":[[0,1.53,3],[1,1.52,11.09],[2,1.51,3.36]],"ltp":0.0,"tv":0.0,"id":22308007},{"batb":[[0,1.53,3],[1,1.52,11.09],[2,1.51,3.36]],"ltp":0.0,"tv":0.0,"id":7226819},{"batb":[[0,1.53,3],[1,1.52,11.09],[2,1.51,3.36]],"ltp":0.0,"tv":0.0,"id":10163711},{"batb":[[0,1.53,3],[1,1.52,11.09],[2,1.51,3.36]],"ltp":0.0,"tv":0.0,"id":10107355},{"batb":[[0,1.53,3],[1,1.52,11.09],[2,1.51,3.36]],"ltp":0.0,"tv":0.0,"id":22121325},{"batb":[[0,1.53,3],[1,1.52,11.09],[2,1.51,3.36]],"ltp":0.0,"tv":0.0,"id":26548208},{"batb":[[0,1.53,3],[1,1.52,11.09],[2,1.51,3.36]],"ltp":0.0,"tv":0.0,"id":27606066},{"batb":[[0,1.53,3],[1,1.52,11.09],[2,1.51,3.36]],"ltp":0.0,"tv":0.0,"id":24270700},{"batb":[[0,1.53,3],[1,1.52,11.09],[2,1.51,3.36]],"ltp":0.0,"tv":0.0,"id":13306150}]}]}
{"op":"mcm","clk":"988764480","pt":1580480500370,"mc":[{"id":"1.168133543","rc":[{"batb":[[0,1.54,1.99],[1,1.53,3],[2,1.52,11.09]],"ltp":0.0,"tv":0.0,"id":12636},{"batb":[[0,1.54,1.99],[1,1.53,3],[2,1.52,11.09]],"ltp":0.0,"tv":0.0,"id":10107355}]}]}
{"op":"mcm","clk":"988764601","pt":1580480501569,"mc":[{"id":"1.168133543","rc":[{"batb":[[0,1.54,1.99],[1,1.53,3],[2,1.52,11.09]],"ltp":0.0,"tv":0.0,"id":10163711},{"batb":[[0,1.54,1.99],[1,1.53,3],[2,1.52,11.09]],"ltp":0.0,"tv":0.0,"id":22121325}]}]}
{"op":"mcm","clk":"988764698","pt":1580480502407,"mc":[{"id":"1.168133543","rc":[{"batb":[[0,1.54,1.99],[1,1.53,3],[2,1.52,11.09]],"ltp":0.0,"tv":0.0,"id":7226819},{"batb":[[0,1.54,1.99],[1,1.53,3],[2,1.52,11.09]],"ltp":0.0,"tv":0.0,"id":26548208},{"batb":[[0,1.54,1.99],[1,1.53,3],[2,1.52,11.09]],"ltp":0.0,"tv":0.0,"id":13306150}]}]}
{"op":"mcm","clk":"988764805","pt":1580480503510,"mc":[{"id":"1.168133543","rc":[{"batb":[[0,1.54,1.99],[1,1.53,3],[2,1.52,11.09]],"ltp":0.0,"tv":0.0,"id":22308007},{"batb":[[0,1.54,1.99],[1,1.53,3],[2,1.52,11.09]],"ltp":0.0,"tv":0.0,"id":27606066},{"batb":[[0,1.54,1.99],[1,1.53,3],[2,1.52,11.09]],"ltp":0.0,"tv":0.0,"id":24270700}]}]}
{"op":"mcm","clk":"988778523","pt":1580480558681,"mc":[{"id":"1.168133543","rc":[{"batb":[[2,1.52,1.09]],"ltp":0.0,"tv":0.0,"id":12636},{"batb":[[2,1.52,1.09]],"ltp":0.0,"tv":0.0,"id":22308007},{"batb":[[2,1.52,1.09]],"ltp":0.0,"tv":0.0,"id":7226819},{"batb":[[2,1.52,1.09]],"ltp":0.0,"tv":0.0,"id":10163711},{"batb":[[2,1.52,1.09]],"ltp":0.0,"tv":0.0,"id":10107355},{"batb":[[2,1.52,1.09]],"ltp":0.0,"tv":0.0,"id":22121325},{"batb":[[2,1.52,1.09]],"ltp":0.0,"tv":0.0,"id":26548208},{"batb":[[2,1.52,1.09]],"ltp":0.0,"tv":0.0,"id":27606066},{"batb":[[2,1.52,1.09]],"ltp":0.0,"tv":0.0,"id":24270700},{"batb":[[2,1.52,1.09]],"ltp":0.0,"tv":0.0,"id":13306150}]}]}
{"op":"mcm","clk":"988787031","pt":1580480656391,"mc":[{"id":"1.168133543","rc":[{"batb":[[1,1.52,1.09],[2,1.51,3.36]],"ltp":0.0,"tv":0.0,"id":12636},{"batb":[[1,1.52,1.09],[2,1.51,3.36]],"ltp":0.0,"tv":0.0,"id":22308007},{"batb":[[1,1.52,1.09],[2,1.51,3.36]],"ltp":0.0,"tv":0.0,"id":7226819},{"batb":[[1,1.52,1.09],[2,1.51,3.36]],"ltp":0.0,"tv":0.0,"id":10163711},{"batb":[[1,1.52,1.09],[2,1.51,3.36]],"ltp":0.0,"tv":0.0,"id":10107355},{"batb":[[1,1.52,1.09],[2,1.51,3.36]],"ltp":0.0,"tv":0.0,"id":22121325},{"batb":[[1,1.52,1.09],[2,1.51,3.36]],"ltp":0.0,"tv":0.0,"id":26548208},{"batb":[[1,1.52,1.09],[2,1.51,3.36]],"ltp":0.0,"tv":0.0,"id":27606066},{"batb":[[1,1.52,1.09],[2,1.51,3.36]],"ltp":0.0,"tv":0.0,"id":24270700},{"batb":[[1,1.52,1.09],[2,1.51,3.36]],"ltp":0.0,"tv":0.0,"id":13306150}]}]}
{"op":"mcm","clk":"988789219","pt":1580480682277,"mc":[{"id":"1.168133543","rc":[{"batb":[[0,1.53,1.99]],"ltp":0.0,"tv":0.0,"id":12636},{"batb":[[0,1.53,1.99]],"ltp":0.0,"tv":0.0,"id":10107355}]}]}
{"op":"mcm","clk":"988789331","pt":1580480683477,"mc":[{"id":"1.168133543","rc":[{"batb":[[0,1.53,1.99]],"ltp":0.0,"tv":0.0,"id":7226819},{"batb":[[0,1.53,1.99]],"ltp":0.0,"tv":0.0,"id":10163711},{"batb":[[0,1.53,1.99]],"ltp":0.0,"tv":0.0,"id":22121325}]}]}
{"op":"mcm","clk":"988789426","pt":1580480684470,"mc":[{"id":"1.168133543","rc":[{"batb":[[0,1.52,1.09],[1,1.51,3.36],[2,1.04,3]],"ltp":0.0,"tv":0.0,"id":22308007},{"batb":[[0,1.53,1.99]],"ltp":0.0,"tv":0.0,"id":26548208},{"batb":[[0,1.53,1.99]],"ltp":0.0,"tv":0.0,"id":13306150}]}]}
{"op":"mcm","clk":"988789491","pt":1580480685371,"mc":[{"id":"1.168133543","rc":[{"batb":[[0,1.53,1.99],[1,1.52,1.09],[2,1.51,3.36]],"ltp":0.0,"tv":0.0,"id":22308007},{"batb":[[0,1.53,1.99]],"ltp":0.0,"tv":0.0,"id":27606066},{"batb":[[0,1.53,1.99]],"ltp":0.0,"tv":0.0,"id":24270700}]}]}
{"op":"mcm","clk":"988999428","pt":1580483140013,"mc":[{"id":"1.168133543","rc":[{"batb":[[0,1.53,11.99]],"ltp":0.0,"tv":0.0,"id":12636},{"batb":[[0,1.53,11.99]],"ltp":0.0,"tv":0.0,"id":22308007},{"batb":[[0,1.53,11.99]],"ltp":0.0,"tv":0.0,"id":7226819},{"batb":[[0,1.53,11.99]],"ltp":0.0,"tv":0.0,"id":10163711},{"batb":[[0,1.53,11.99]],"ltp":0.0,"tv":0.0,"id":10107355},{"batb":[[0,1.53,11.99]],"ltp":0.0,"tv":0.0,"id":22121325},{"batb":[[0,1.53,11.99]],"ltp":0.0,"tv":0.0,"id":26548208},{"batb":[[0,1.53,11.99]],"ltp":0.0,"tv":0.0,"id":27606066},{"batb":[[0,1.53,11.99]],"ltp":0.0,"tv":0.0,"id":24270700},{"batb":[[0,1.53,11.99]],"ltp":0.0,"tv":0.0,"id":13306150}]}]}
{"op":"mcm","clk":"989315142","pt":1580486672439,"mc":[{"id":"1.168133543","rc":[{"batb":[[1,1.52,1.08]],"ltp":0.0,"tv":0.0,"id":12636},{"batb":[[2,1.03,1580.19]],"ltp":1000.0,"tv":0.4,"id":13819977},{"batb":[[1,1.52,1.08]],"ltp":0.0,"tv":0.0,"id":22308007},{"batb":[[1,1.52,1.08]],"ltp":0.0,"tv":0.0,"id":7226819},{"batb":[[1,1.52,1.08]],"ltp":0.0,"tv":0.0,"id":10163711},{"batb":[[0,1.54,1.68],[1,1.53,11.99],[2,1.52,1.08]],"ltp":0.0,"tv":0.0,"id":10107355},{"batb":[[1,1.52,1.08]],"ltp":0.0,"tv":0.0,"id":22121325},{"batb":[[1,1.52,1.08]],"ltp":0.0,"tv":0.0,"id":26548208},{"batb":[[1,1.52,1.08]],"ltp":0.0,"tv":0.0,"id":27606066},{"batb":[[1,1.52,1.08]],"ltp":0.0,"tv":0.0,"id":24270700},{"batb":[[1,1.52,1.08]],"ltp":0.0,"tv":0.0,"id":13306150}]}]}
{"op":"mcm","clk":"989315223","pt":1580486673130,"mc":[{"id":"1.168133543","rc":[{"batb":[[0,1000,224.8]],"ltp":1000.0,"tv":0.4,"id":13819977},{"batb":[[0,1.55,1.99],[1,1.54,1.68],[2,1.53,10]],"ltp":0.0,"tv":0.0,"id":10107355}]}]}
{"op":"mcm","clk":"989315293","pt":1580486673840,"mc":[{"id":"1.168133543","rc":[{"trd":[[1.55,3.36]],"batb":[[0,1.54,1.99],[1,1.53,10],[2,1.52,1.08]],"ltp":1.55,"tv":3.36,"id":10107355}],"tv":3.76}]}
{"op":"mcm","clk":"989317123","pt":1580486690859,"mc":[{"id":"1.168133543","rc":[{"batb":[[0,1.55,10.31],[1,1.54,1.68]],"ltp":1.55,"tv":3.36,"id":10107355}]}]}
{"op":"mcm","clk":"989318655","pt":1580486704773,"mc":[{"id":"1.168133543","rc":[{"batb":[[1,1.52,1.08],[2,1.51,3.36]],"ltp":1.55,"tv":3.36,"id":10107355}]}]}
{"op":"mcm","clk":"989324680","pt":1580486766499,"mc":[{"id":"1.168133543","rc":[{"batb":[[0,1.52,1.39],[1,1.51,3.36],[2,1.5,3]],"ltp":1.55,"tv":3.36,"id":10107355}]}]}
{"op":"mcm","clk":"989324692","pt":1580486766600,"mc":[{"id":"1.168133543","rc":[{"batb":[[0,1.53,10.31],[1,1.52,1.08],[2,1.51,3.36]],"ltp":1.55,"tv":3.36,"id":10107355}]}]}
{"op":"mcm","clk":"989332119","pt":1580486837697,"mc":[{"id":"1.168133543","rc":[{"batb":[[0,1.52,1.39],[1,1.51,3.36],[2,1.5,3]],"ltp":1.55,"tv":3.36,"id":10107355}]}]}
{"op":"mcm","clk":"989354514","pt":1580486982427,"mc":[{"id":"1.168133543","rc":[{"batb":[[0,1.53,10.31],[1,1.52,1.08],[2,1.51,3.36]],"ltp":1.55,"tv":3.36,"id":10107355}]}]}
{"op":"mcm","clk":"989361518","pt":1580487057557,"mc":[{"id":"1.168133543","rc":[{"batb":[[0,1.52,11.39],[1,1.51,3.36],[2,1.5,3]],"ltp":1.55,"tv":3.36,"id":10107355}]}]}
{"op":"mcm","clk":"989449533","pt":1580487922340,"mc":[{"id":"1.168133543","rc":[{"batb":[[0,1.54,10.31],[1,1.52,11.08],[2,1.51,3.36]],"ltp":1.55,"tv":3.36,"id":10107355}]}]}
{"op":"mcm","clk":"989452709","pt":1580487958993,"mc":[{"id":"1.168133543","rc":[{"batb":[[0,1.55,10.31],[1,1.54,10],[2,1.52,1.08]],"ltp":1.55,"tv":3.36,"id":10107355}]}]}
{"op":"mcm","clk":"989559560","pt":1580489079561,"mc":[{"id":"1.168133543","rc":[{"batl":[[0,1000,0.62]],"ltp":1.55,"tv":3.36,"id":10107355}]}]}
{"op":"mcm","clk":"989559703","pt":1580489081531,"mc":[{"id":"1.168133543","rc":[{"batl":[[0,1000,1.88]],"ltp":1.55,"tv":3.36,"id":10107355}]}]}
{"op":"mcm","clk":"989559750","pt":1580489082154,"mc":[{"id":"1.168133543","rc":[{"batl":[[0,1000,0.62]],"ltp":1.55,"tv":3.36,"id":10107355}]}]}
{"op":"mcm","clk":"989559863","pt":1580489083432,"mc":[{"id":"1.168133543","rc":[{"batl":[[0,1000,0.2]],"ltp":1.55,"tv":3.36,"id":10107355}]}]}
{"op":"mcm","clk":"989560011","pt":1580489085366,"mc":[{"id":"1.168133543","rc":[{"batl":[[0,1000,0.62]],"ltp":1.55,"tv":3.36,"id":10107355}]}]}
{"op":"mcm","clk":"989560152","pt":1580489087168,"mc":[{"id":"1.168133543","rc":[{"batl":[[0,1000,0.2]],"ltp":1.55,"tv":3.36,"id":10107355}]}]}
{"op":"mcm","clk":"989560361","pt":1580489089547,"mc":[{"id":"1.168133543","rc":[{"batl":[[0,1000,0.62]],"ltp":1.55,"tv":3.36,"id":10107355}]}]}
{"op":"mcm","clk":"989560548","pt":1580489091455,"mc":[{"id":"1.168133543","rc":[{"batl":[[0,1000,1.88]],"ltp":1.55,"tv":3.36,"id":10107355}]}]}
{"op":"mcm","clk":"989560624","pt":1580489092460,"mc":[{"id":"1.168133543","rc":[{"batl":[[0,1000,0.62]],"ltp":1.55,"tv":3.36,"id":10107355}]}]}
{"op":"mcm","clk":"989560782","pt":1580489094472,"mc":[{"id":"1.168133543","rc":[{"batl":[[0,1000,0.2]],"ltp":1.55,"tv":3.36,"id":10107355}]}]}
{"op":"mcm","clk":"989561069","pt":1580489098469,"mc":[{"id":"1.168133543","rc":[{"batl":[[0,1000,0.62]],"ltp":0.0,"tv":0.0,"id":12636}]}]}
{"op":"mcm","clk":"989561168","pt":1580489099974,"mc":[{"id":"1.168133543","rc":[{"batl":[[0,1000,0.2]],"ltp":0.0,"tv":0.0,"id":12636}]}]}
{"op":"mcm","clk":"989561273","pt":1580489101370,"mc":[{"id":"1.168133543","rc":[{"batl":[[0,1000,0.62]],"ltp":0.0,"tv":0.0,"id":12636}]}]}
{"op":"mcm","clk":"989561345","pt":1580489102271,"mc":[{"id":"1.168133543","rc":[{"batl":[[0,1000,0.2]],"ltp":0.0,"tv":0.0,"id":12636}]}]}
{"op":"mcm","clk":"989561436","pt":1580489103485,"mc":[{"id":"1.168133543","rc":[{"batl":[[0,1000,1.88]],"ltp":0.0,"tv":0.0,"id":12636}]}]}
{"op":"mcm","clk":"989561518","pt":1580489104484,"mc":[{"id":"1.168133543","rc":[{"batl":[[0,1000,0.62]],"ltp":0.0,"tv":0.0,"id":12636}]}]}
{"op":"mcm","clk":"989561591","pt":1580489105381,"mc":[{"id":"1.168133543","rc":[{"batl":[[0,1000,0.2]],"ltp":0.0,"tv":0.0,"id":12636}]}]}
{"op":"mcm","clk":"989607277","pt":1580489591505,"mc":[{"id":"1.168133543","rc":[{"batb":[[0,1.55,13.31]],"ltp":1.55,"tv":3.36,"id":10107355}]}]}
{"op":"mcm","clk":"989607733","pt":1580489595502,"mc":[{"id":"1.168133543","rc":[{"batb":[[0,1.65,3],[1,1.55,10.31],[2,1.54,10]],"ltp":1.55,"tv":3.36,"id":10107355}]}]}
{"op":"mcm","clk":"989607830","pt":1580489596493,"mc":[{"id":"1.168133543","rc":[{"batb":[[0,1.55,10.31],[1,1.54,10],[2,1.52,1.08]],"ltp":1.55,"tv":3.36,"id":10107355}]}]}
{"op":"mcm","clk":"989612556","pt":1580489655059,"mc":[{"id":"1.168133543","rc":[{"batb":[[0,1.56,5.08],[1,1.55,10.31],[2,1.54,10]],"batl":[[0,1000,3.23]],"ltp":1.55,"tv":3.36,"id":10107355}]}]}
{"op":"mcm","clk":"989617372","pt":1580489716574,"mc":[{"id":"1.168133543","rc":[{"batb":[[0,1.56,5.39],[1,1.55,10]],"ltp":1.55,"tv":3.36,"id":10107355}]}]}
{"op":"mcm","clk":"989619717","pt":1580489746881,"mc":[{"id":"1.168133543","rc":[{"batb":[[0,1.57,10.31],[1,1.56,5.08]],"ltp":1.55,"tv":3.36,"id":10107355}]}]}
{"op":"mcm","clk":"989622148","pt":1580489778528,"mc":[{"id":"1.168133543","rc":[{"batb":[[0,1.58,3.85],[1,1.57,10.31]],"ltp":1.55,"tv":3.36,"id":10107355}]}]}
{"op":"mcm","clk":"989623857","pt":1580489800948,"mc":[{"id":"1.168133543","rc":[{"batb":[[0,1.58,4.16],[1,1.57,10]],"ltp":1.55,"tv":3.36,"id":10107355}]}]}
{"op":"mcm","clk":"989625305","pt":1580489821778,"mc":[{"id":"1.168133543","rc":[{"batb":[[0,1.59,10.31],[1,1.58,3.85]],"ltp":1.55,"tv":3.36,"id":10107355}]}]}
{"op":"mcm","clk":"989627602","pt":1580489852374,"mc":[{"id":"1.168133543","rc":[{"batb":[[0,1.6,3.54],[1,1.59,10.31]],"ltp":1.55,"tv":3.36,"id":10107355}]}]}
{"op":"mcm","clk":"989630114","pt":1580489883914,"mc":[{"id":"1.168133543","rc":[{"batb":[[0,1.6,3.85],[1,1.59,10]],"ltp":1.55,"tv":3.36,"id":10107355}]}]}
{"op":"mcm","clk":"989632184","pt":1580489909752,"mc":[{"id":"1.168133543","rc":[{"batb":[[0,1.61,10.31],[1,1.6,3.54]],"ltp":1.55,"tv":3.36,"id":10107355}]}]}
{"op":"mcm","clk":"989633751","pt":1580489931356,"mc":[{"id":"1.168133543","rc":[{"batb":[[0,1.62,3.46],[1,1.61,10.31]],"ltp":1.55,"tv":3.36,"id":10107355}]}]}
{"op":"mcm","clk":"989637261","pt":1580489976217,"mc":[{"id":"1.168133543","rc":[{"batb":[[0,1.62,3.77],[1,1.61,10]],"ltp":1.55,"tv":3.36,"id":10107355}]}]}
{"op":"mcm","clk":"989638194","pt":1580489988318,"mc":[{"id":"1.168133543","rc":[{"batb":[[0,1.63,10.31],[1,1.62,3.46]],"ltp":1.55,"tv":3.36,"id":10107355}]}]}
{"op":"mcm","clk":"989638949","pt":1580489997032,"mc":[{"id":"1.168133543","rc":[{"batb":[[0,1.64,3.41],[1,1.63,10.31]],"ltp":1.55,"tv":3.36,"id":10107355}]}]}
{"op":"mcm","clk":"989645148","pt":1580490062012,"mc":[{"id":"1.168133543","rc":[{"batb":[[0,1.64,3.72],[1,1.63,10]],"ltp":1.55,"tv":3.36,"id":10107355}]}]}
{"op":"mcm","clk":"989650802","pt":1580490124001,"mc":[{"id":"1.168133543","rc":[{"batb":[[1,1.54,10],[2,1.51,3.36]],"ltp":1.55,"tv":3.36,"id":10107355}]}]}
{"op":"mcm","clk":"989654473","pt":1580490163731,"mc":[{"id":"1.168133543","rc":[{"batb":[[0,1.55,3.72]],"ltp":1.55,"tv":3.36,"id":10107355}]}]}
{"op":"mcm","clk":"989753688","pt":1580491072497,"mc":[{"id":"1.168133543","rc":[{"batl":[[0,1000,4.92]],"ltp":1.55,"tv":3.36,"id":10107355}]}]}
{"op":"mcm","clk":"989753762","pt":1580491073076,"mc":[{"id":"1.168133543","rc":[{"batl":[[0,1000,3.66]],"ltp":1.55,"tv":3.36,"id":10107355}]}]}
{"op":"mcm","clk":"989754036","pt":1580491075502,"mc":[{"id":"1.168133543","rc":[{"batl":[[0,1000,4.92]],"ltp":1.55,"tv":3.36,"id":10107355}]}]}
{"op":"mcm","clk":"989754136","pt":1580491076285,"mc":[{"id":"1.168133543","rc":[{"batl":[[0,1000,3.66]],"ltp":1.55,"tv":3.36,"id":10107355}]}]}
{"op":"mcm","clk":"989754254","pt":1580491077595,"mc":[{"id":"1.168133543","rc":[{"batl":[[0,1000,3.23]],"ltp":1.55,"tv":3.36,"id":10107355}]}]}
{"op":"mcm","clk":"989755403","pt":1580491088201,"mc":[{"id":"1.168133543","rc":[{"batl":[[0,1000,0.62]],"ltp":0.0,"tv":0.0,"id":12636}]}]}
{"op":"mcm","clk":"989755568","pt":1580491089913,"mc":[{"id":"1.168133543","rc":[{"batl":[[0,1000,0.2]],"ltp":0.0,"tv":0.0,"id":12636}]}]}
{"op":"mcm","clk":"989755712","pt":1580491091378,"mc":[{"id":"1.168133543","rc":[{"batl":[[0,990,0.62]],"ltp":0.0,"tv":0.0,"id":12636}]}]}
{"op":"mcm","clk":"989755823","pt":1580491092717,"mc":[{"id":"1.168133543","rc":[{"batl":[[0,990,0.2]],"ltp":0.0,"tv":0.0,"id":12636}]}]}
{"op":"mcm","clk":"989756322","pt":1580491097993,"mc":[{"id":"1.168133543","rc":[{"batb":[[0,1.56,1.15],[1,1.55,3.41],[2,1.54,10]],"ltp":1.55,"tv":3.36,"id":10107355}]}]}
{"op":"mcm","clk":"989757029","pt":1580491105307,"mc":[{"id":"1.168133543","rc":[{"batl":[[0,1000,0.2]],"ltp":0.0,"tv":0.0,"id":12636}]}]}
{"op":"mcm","clk":"989757296","pt":1580491108320,"mc":[{"id":"1.168133543","rc":[{"batl":[[0,1000,4.92]],"ltp":1.55,"tv":3.36,"id":10107355}]}]}
{"op":"mcm","clk":"989757390","pt":1580491109213,"mc":[{"id":"1.168133543","rc":[{"batl":[[0,1000,3.66]],"ltp":1.55,"tv":3.36,"id":10107355}]}]}
{"op":"mcm","clk":"989757606","pt":1580491111541,"mc":[{"id":"1.168133543","rc":[{"batl":[[0,1000,4.92]],"ltp":1.55,"tv":3.36,"id":10107355}]}]}
{"op":"mcm","clk":"989757669","pt":1580491112118,"mc":[{"id":"1.168133543","rc":[{"batl":[[0,1000,3.66]],"ltp":1.55,"tv":3.36,"id":10107355}]}]}
{"op":"mcm","clk":"989757903","pt":1580491114407,"mc":[{"id":"1.168133543","rc":[{"batl":[[0,1000,3.23]],"ltp":1.55,"tv":3.36,"id":10107355}]}]}
{"op":"mcm","clk":"989758107","pt":1580491116537,"mc":[{"id":"1.168133543","rc":[{"batl":[[0,1000,3.66]],"ltp":1.55,"tv":3.36,"id":10107355}]}]}
{"op":"mcm","clk":"989758235","pt":1580491117742,"mc":[{"id":"1.168133543","rc":[{"batl":[[0,1000,3.23]],"ltp":1.55,"tv":3.36,"id":10107355}]}]}
{"op":"mcm","clk":"989758357","pt":1580491119045,"mc":[{"id":"1.168133543","rc":[{"batb":[[0,1.55,3.72],[1,1.54,10],[2,1.51,3.36]],"ltp":1.55,"tv":3.36,"id":10107355}]}]}
{"op":"mcm","clk":"989758775","pt":1580491123051,"mc":[{"id":"1.168133543","rc":[{"batb":[[0,1.56,1.15],[1,1.55,3.41],[2,1.54,10]],"ltp":1.55,"tv":3.36,"id":10107355}]}]}
{"op":"mcm","clk":"989759493","pt":1580491130342,"mc":[{"id":"1.168133543","rc":[{"batb":[[0,1.53,12.83]],"ltp":0.0,"tv":0.0,"id":12636}]}]}
{"op":"mcm","clk":"989760384","pt":1580491138574,"mc":[{"id":"1.168133543","rc":[{"batl":[[0,1000,3.66]],"ltp":1.55,"tv":3.36,"id":10107355}]}]}
{"op":"mcm","clk":"989760581","pt":1580491140502,"mc":[{"id":"1.168133543","rc":[{"batl":[[0,1000,3.23]],"ltp":1.55,"tv":3.36,"id":10107355}]}]}
{"op":"mcm","clk":"989760677","pt":1580491141552,"mc":[{"id":"1.168133543","rc":[{"batb":[[0,1.55,4.26],[1,1.54,10],[2,1.51,3.36]],"batl":[[0,1000,4.92]],"ltp":1.55,"tv":3.36,"id":10107355}]}]}
{"op":"mcm","clk":"989760746","pt":1580491142275,"mc":[{"id":"1.168133543","rc":[{"batb":[[0,1.53,10.84]],"ltp":0.0,"tv":0.0,"id":12636},{"batb":[[1,4,60],[2,1.51,3.36]],"ltp":1000.0,"tv":0.4,"id":13819977},{"batl":[[0,1000,3.66]],"ltp":1.55,"tv":3.36,"id":10107355}]}]}
{"op":"mcm","clk":"989760885","pt":1580491143653,"mc":[{"id":"1.168133543","rc":[{"batl":[[0,1000,3.23]],"ltp":1.55,"tv":3.36,"id":10107355}]}]}
{"op":"mcm","clk":"989761018","pt":1580491145166,"mc":[{"id":"1.168133543","rc":[{"batl":[[0,1000,0.62]],"ltp":0.0,"tv":0.0,"id":12636}]}]}
{"op":"mcm","clk":"989761581","pt":1580491150571,"mc":[{"id":"1.168133543","rc":[{"batl":[[0,6,0.42]],"ltp":0.0,"tv":0.0,"id":12636}]}]}
{"op":"mcm","clk":"989761840","pt":1580491152984,"mc":[{"id":"1.168133543","rc":[{"batb":[[0,1.53,10]],"ltp":0.0,"tv":0.0,"id":12636}]}]}
{"op":"mcm","clk":"989762700","pt":1580491159990,"mc":[{"id":"1.168133543","rc":[{"batb":[[0,1.52,1.92],[1,1.51,3.36],[2,1.04,3]],"ltp":0.0,"tv":0.0,"id":12636}]}]}
{"op":"mcm","clk":"989762863","pt":1580491161220,"mc":[{"id":"1.168133543","rc":[{"batl":[[0,1000,0.2]],"ltp":0.0,"tv":0.0,"id":12636}]}]}
{"op":"mcm","clk":"989763059","pt":1580491162909,"mc":[{"id":"1.168133543","rc":[{"batb":[[0,1.55,3.41]],"ltp":1.55,"tv":3.36,"id":10107355}]}]}
{"op":"mcm","clk":"989763357","pt":1580491165431,"mc":[{"id":"1.168133543","rc":[{"batb":[[0,1.55,4.26]],"ltp":1.55,"tv":3.36,"id":10107355}]}]}
{"op":"mcm","clk":"989763585","pt":1580491167415,"mc":[{"id":"1.168133543","rc":[{"batb":[[0,3.5,1.68],[1,1.55,3.41],[2,1.54,10]],"ltp":1.55,"tv":3.36,"id":10107355}]}]}
{"op":"mcm","clk":"989764537","pt":1580491177327,"mc":[{"id":"1.168133543","rc":[{"batl":[[0,1000,3.46]],"ltp":1.55,"tv":3.36,"id":10107355}]}]}
{"op":"mcm","clk":"989765286","pt":1580491185522,"mc":[{"id":"1.168133543","rc":[{"batl":[[0,1000,1.88]],"ltp":0.0,"tv":0.0,"id":12636}]}]}
{"op":"mcm","clk":"989765374","pt":1580491186513,"mc":[{"id":"1.168133543","rc":[{"batl":[[0,1000,0.62]],"ltp":0.0,"tv":0.0,"id":12636}]}]}
{"op":"mcm","clk":"989765590","pt":1580491188447,"mc":[{"id":"1.168133543","rc":[{"batl":[[0,1000,0.2]],"ltp":0.0,"tv":0.0,"id":12636}]}]}
{"op":"mcm","clk":"989765708","pt":1580491189658,"mc":[{"id":"1.168133543","rc":[{"batl":[[0,1000,0.62]],"ltp":0.0,"tv":0.0,"id":12636}]}]}
{"op":"mcm","clk":"989765890","pt":1580491191236,"mc":[{"id":"1.168133543","rc":[{"batl":[[0,3.55,0.42]],"ltp":0.0,"tv":0.0,"id":12636}]}]}
{"op":"mcm","clk":"989765989","pt":1580491192184,"mc":[{"id":"1.168133543","rc":[{"batl":[[0,1000,3.03]],"ltp":1.55,"tv":3.36,"id":10107355}]}]}
{"op":"mcm","clk":"989766098","pt":1580491193274,"mc":[{"id":"1.168133543","rc":[{"batl":[[0,1000,4.72]],"ltp":1.55,"tv":3.36,"id":10107355}]}]}
{"op":"mcm","clk":"989766189","pt":1580491194174,"mc":[{"id":"1.168133543","rc":[{"batl":[[0,1000,3.46]],"ltp":1.55,"tv":3.36,"id":10107355}]}]}
{"op":"mcm","clk":"989766331","pt":1580491195629,"mc":[{"id":"1.168133543","rc":[{"batl":[[0,1000,3.03]],"ltp":1.55,"tv":3.36,"id":10107355}]}]}
{"op":"mcm","clk":"989766616","pt":1580491198564,"mc":[{"id":"1.168133543","rc":[{"batl":[[0,3.45,0.42]],"ltp":0.0,"tv":0.0,"id":12636}]}]}
{"op":"mcm","clk":"989766764","pt":1580491199984,"mc":[{"id":"1.168133543","rc":[{"batb":[[0,1.52,1.08]],"ltp":0.0,"tv":0.0,"id":12636}]}]}
{"op":"mcm","clk":"989766912","pt":1580491201357,"mc":[{"id":"1.168133543","rc":[{"batb":[[0,1.55,4.26],[1,1.54,10],[2,1.51,3.36]],"ltp":1.55,"tv":3.36,"id":10107355}]}]}
{"op":"mcm","clk":"989767057","pt":1580491202782,"mc":[{"id":"1.168133543","rc":[{"batb":[[0,1.55,3.41]],"ltp":1.55,"tv":3.36,"id":10107355}]}]}
{"op":"mcm","clk":"989767343","pt":1580491205189,"mc":[{"id":"1.168133543","rc":[{"batl":[[0,1000,3.23]],"ltp":1.55,"tv":3.36,"id":10107355}]}]}
{"op":"mcm","clk":"989767653","pt":1580491208283,"mc":[{"id":"1.168133543","rc":[{"batl":[[0,1000,1.68]],"ltp":0.0,"tv":0.0,"id":12636}]}]}
{"op":"mcm","clk":"989767750","pt":1580491209299,"mc":[{"id":"1.168133543","rc":[{"batl":[[0,3.8,0.42]],"ltp":0.0,"tv":0.0,"id":12636}]}]}
{"op":"mcm","clk":"989768061","pt":1580491212497,"mc":[{"id":"1.168133543","rc":[{"batl":[[0,1000,3.66]],"ltp":1.55,"tv":3.36,"id":10107355}]}]}
{"op":"mcm","clk":"989768070","pt":1580491212602,"mc":[{"id":"1.168133543","rc":[{"trd":[[3.4,0.84]],"batl":[[0,1000,3.23]],"ltp":3.4,"tv":4.2,"id":10107355}],"tv":4.6}]}
{"op":"mcm","clk":"989768504","pt":1580491216383,"mc":[{"id":"1.168133543","rc":[{"batl":[[0,1000,4.08]],"ltp":3.4,"tv":4.2,"id":10107355}]}]}
{"op":"mcm","clk":"989768575","pt":1580491217011,"mc":[{"id":"1.168133543","rc":[{"batl":[[0,990,1.04],[1,1000,3.03]],"ltp":3.4,"tv":4.2,"id":10107355}]}]}
{"op":"mcm","clk":"989768744","pt":1580491218404,"mc":[{"id":"1.168133543","rc":[{"batb":[[0,1.56,3],[1,1.55,3.41],[2,1.54,10]],"batl":[[0,1000,3.23],[1,1000,0]],"ltp":3.4,"tv":4.2,"id":10107355}]}]}
{"op":"mcm","clk":"989768846","pt":1580491219397,"mc":[{"id":"1.168133543","rc":[{"batb":[[0,1.53,90],[1,1.52,1.08],[2,1.51,3.36]],"batl":[[0,980,9],[1,1000,0.2]],"ltp":0.0,"tv":0.0,"id":12636},{"batb":[[1,6,90],[2,4,60]],"ltp":1000.0,"tv":0.4,"id":13819977},{"batb":[[0,1.55,90],[1,1.53,11.99],[2,1.52,1.08]],"ltp":0.0,"tv":0.0,"id":22308007},{"batb":[[0,1.55,90],[1,1.53,11.99],[2,1.52,1.08]],"batl":[[0,980,9],[1,1000,0.2]],"ltp":0.0,"tv":0.0,"id":7226819},{"batb":[[0,1.55,90],[1,1.53,11.99],[2,1.52,1.08]],"batl":[[0,980,9],[1,1000,0.2]],"ltp":0.0,"tv":0.0,"id":10163711},{"batb":[[0,1.58,90],[1,1.56,3],[2,1.55,3.41]],"batl":[[0,980,9],[1,1000,4.08]],"ltp":3.4,"tv":4.2,"id":10107355},{"batb":[[0,1.55,90],[1,1.53,11.99],[2,1.52,1.08]],"batl":[[0,980,9],[1,1000,0.2]],"ltp":0.0,"tv":0.0,"id":22121325},{"batb":[[0,1.55,90],[1,1.53,11.99],[2,1.52,1.08]],"batl":[[0,980,9],[1,1000,0.2]],"ltp":0.0,"tv":0.0,"id":26548208},{"batb":[[0,1.55,90],[1,1.53,11.99],[2,1.52,1.08]],"ltp":0.0,"tv":0.0,"id":27606066},{"batb":[[0,1.55,90],[1,1.53,11.99],[2,1.52,1.08]],"ltp":0.0,"tv":0.0,"id":24270700},{"batb":[[0,1.55,90],[1,1.53,11.99],[2,1.52,1.08]],"ltp":0.0,"tv":0.0,"id":13306150}]}]}
{"op":"mcm","clk":"989768940","pt":1580491220190,"mc":[{"id":"1.168133543","rc":[{"trd":[[3.4,2.52]],"batl":[[1,1000,3.23]],"ltp":3.4,"tv":5.88,"id":10107355}],"tv":6.28}]}
{"op":"mcm","clk":"989769093","pt":1580491221389,"mc":[{"id":"1.168133543","rc":[{"batl":[[1,1000,4.92]],"ltp":3.4,"tv":5.88,"id":10107355}]}]}
{"op":"mcm","clk":"989769200","pt":1580491222389,"mc":[{"id":"1.168133543","rc":[{"trd":[[3.4,4.2]],"batl":[[1,1000,3.23]],"ltp":3.4,"tv":7.56,"id":10107355}],"tv":7.96}]}
{"op":"mcm","clk":"989769398","pt":1580491224527,"mc":[{"id":"1.168133543","rc":[{"batb":[[1,1.53,1.99]],"ltp":0.0,"tv":0.0,"id":22308007},{"batb":[[1,1.53,1.99]],"ltp":0.0,"tv":0.0,"id":7226819},{"batb":[[1,1.53,1.99]],"ltp":0.0,"tv":0.0,"id":10163711},{"batl":[[1,1000,4.08]],"ltp":3.4,"tv":7.56,"id":10107355},{"batb":[[1,1.53,1.99]],"ltp":0.0,"tv":0.0,"id":22121325},{"batb":[[1,1.53,1.99]],"ltp":0.0,"tv":0.0,"id":26548208},{"batb":[[1,1.53,1.99]],"ltp":0.0,"tv":0.0,"id":27606066},{"batb":[[1,1.53,1.99]],"ltp":0.0,"tv":0.0,"id":24270700},{"batb":[[1,1.53,1.99]],"ltp":0.0,"tv":0.0,"id":13306150}]}]}
{"op":"mcm","clk":"989769468","pt":1580491225202,"mc":[{"id":"1.168133543","rc":[{"trd":[[3.45,1.68]],"batl":[[1,1000,3.23]],"ltp":3.45,"tv":9.24,"id":10107355}],"tv":9.64}]}
{"op":"mcm","clk":"989769600","pt":1580491226525,"mc":[{"id":"1.168133543","rc":[{"batl":[[1,1000,4.08]],"ltp":3.45,"tv":9.24,"id":10107355}]}]}
{"op":"mcm","clk":"989769640","pt":1580491226985,"mc":[{"id":"1.168133543","rc":[{"trd":[[3.45,3.36]],"batl":[[1,1000,3.23]],"ltp":3.45,"tv":10.92,"id":10107355}],"tv":11.32}]}
{"op":"mcm","clk":"989769734","pt":1580491228177,"mc":[{"id":"1.168133543","rc":[{"batl":[[1,1000,4.92]],"ltp":3.45,"tv":10.92,"id":10107355}]}]}
{"op":"mcm","clk":"989769835","pt":1580491229435,"mc":[{"id":"1.168133543","rc":[{"trd":[[3.45,5.04]],"batl":[[1,1000,3.23]],"ltp":3.45,"tv":12.6,"id":10107355}],"tv":13.0}]}
{"op":"mcm","clk":"989770026","pt":1580491231322,"mc":[{"id":"1.168133543","rc":[{"batb":[[0,1.59,3],[1,1.58,90]],"batl":[[1,1000,4.08]],"ltp":3.45,"tv":12.6,"id":10107355}]}]}
{"op":"mcm","clk":"989770077","pt":1580491231740,"mc":[{"id":"1.168133543","rc":[{"batl":[[0,980,9.84],[1,1000,3.23]],"ltp":3.45,"tv":12.6,"id":10107355}]}]}
{"op":"mcm","clk":"989770258","pt":1580491233524,"mc":[{"id":"1.168133543","rc":[{"batl":[[1,1000,0]],"ltp":0.0,"tv":0.0,"id":12636},{"batl":[[1,1000,0]],"ltp":0.0,"tv":0.0,"id":7226819},{"batl":[[1,1000,0]],"ltp":0.0,"tv":0.0,"id":10163711},{"batl":[[0,980,9],[1,1000,3.03]],"ltp":3.45,"tv":12.6,"id":10107355},{"batl":[[1,1000,0]],"ltp":0.0,"tv":0.0,"id":22121325},{"batl":[[1,1000,0]],"ltp":0.0,"tv":0.0,"id":26548208}]}]}
{"op":"mcm","clk":"989770370","pt":1580491234519,"mc":[{"id":"1.168133543","rc":[{"batb":[[0,1.54,1.99],[1,1.53,90],[2,1.52,1.08]],"batl":[[0,980,9.2]],"ltp":0.0,"tv":0.0,"id":12636},{"batl":[[0,980,9.2]],"ltp":0.0,"tv":0.0,"id":7226819},{"batl":[[0,980,9.2]],"ltp":0.0,"tv":0.0,"id":10163711},{"trd":[[3.45,5.44]],"batb":[[0,1.59,3.31]],"ltp":3.45,"tv":13.0,"id":10107355},{"batl":[[0,980,9.2]],"ltp":0.0,"tv":0.0,"id":22121325},{"batl":[[0,980,9.2]],"ltp":0.0,"tv":0.0,"id":26548208}],"tv":13.4}]}
{"op":"mcm","clk":"989770497","pt":1580491235534,"mc":[{"id":"1.168133543","rc":[{"batb":[[1,1.52,1.08],[2,1.51,3.36]],"ltp":0.0,"tv":0.0,"id":7226819},{"batb":[[0,1.56,1.99],[1,1.55,90]],"ltp":0.0,"tv":0.0,"id":10163711},{"batb":[[0,1.56,1.99],[1,1.55,90]],"ltp":0.0,"tv":0.0,"id":22121325}]}]}
{"op":"mcm","clk":"989770618","pt":1580491236528,"mc":[{"id":"1.168133543","rc":[{"batb":[[0,1.56,1.99],[1,1.55,90],[2,1.52,1.08]],"ltp":0.0,"tv":0.0,"id":7226819},{"batl":[[1,1000,3.46]],"ltp":3.45,"tv":13.0,"id":10107355},{"batb":[[0,1.56,1.99],[1,1.55,90]],"ltp":0.0,"tv":0.0,"id":26548208},{"batb":[[0,1.56,1.99],[1,1.55,90]],"ltp":0.0,"tv":0.0,"id":13306150}]}]}
{"op":"mcm","clk":"989770692","pt":1580491237311,"mc":[{"id":"1.168133543","rc":[{"batb":[[0,1.56,1.99],[1,1.55,90]],"ltp":0.0,"tv":0.0,"id":22308007},{"batl":[[0,980,9.42],[1,1000,3.03]],"ltp":3.45,"tv":13.0,"id":10107355},{"batb":[[0,1.56,1.99],[1,1.55,90]],"ltp":0.0,"tv":0.0,"id":27606066},{"batb":[[0,1.56,1.99],[1,1.55,90]],"ltp":0.0,"tv":0.0,"id":24270700}]}]}
{"op":"mcm","clk":"989770831","pt":1580491238937,"mc":[{"id":"1.168133543","rc":[{"batl":[[0,980,9]],"ltp":3.45,"tv":13.0,"id":10107355}]}]}
{"op":"mcm","clk":"989771011","pt":1580491240534,"mc":[{"id":"1.168133543","rc":[{"batl":[[0,980,9.42]],"ltp":3.45,"tv":13.0,"id":10107355}]}]}
{"op":"mcm","clk":"989771250","pt":1580491242526,"mc":[{"id":"1.168133543","rc":[{"batl":[[0,980,9]],"ltp":3.45,"tv":13.0,"id":10107355}]}]}
{"op":"mcm","clk":"989771803","pt":1580491247398,"mc":[{"id":"1.168133543","rc":[{"batl":[[0,970,3.23],[1,980,9]],"ltp":0.0,"tv":0.0,"id":12636},{"batl":[[0,970,3.23],[1,980,9]],"ltp":0.0,"tv":0.0,"id":10163711},{"batb":[[0,1.6,3.31],[1,1.59,3.33],[2,1.58,90]],"batl":[[0,980,9.2],[1,1000,4.72]],"ltp":3.45,"tv":13.0,"id":10107355},{"batl":[[0,970,3.23],[1,980,9]],"ltp":0.0,"tv":0.0,"id":22121325}]}]}
{"op":"mcm","clk":"989771940","pt":1580491248503,"mc":[{"id":"1.168133543","rc":[{"batl":[[0,65,3.03],[1,980,9.2]],"ltp":0.0,"tv":0.0,"id":7226819},{"batl":[[0,980,9.62],[1,1000,3.03]],"ltp":3.45,"tv":13.0,"id":10107355}]}]}
{"op":"mcm","clk":"989772106","pt":1580491249974,"mc":[{"id":"1.168133543","rc":[{"batb":[[0,1.61,26.64],[1,1.6,3.31],[2,1.59,3.33]],"batl":[[0,980,9.2]],"ltp":3.45,"tv":13.0,"id":10107355}]}]}
{"op":"mcm","clk":"989772247","pt":1580491251286,"mc":[{"id":"1.168133543","rc":[{"batl":[[0,980,9.62]],"ltp":3.45,"tv":13.0,"id":10107355}]}]}
{"op":"mcm","clk":"989772489","pt":1580491253395,"mc":[{"id":"1.168133543","rc":[{"batb":[[0,1.54,4.99]],"ltp":0.0,"tv":0.0,"id":12636},{"batb":[[0,1.56,4.99]],"ltp":0.0,"tv":0.0,"id":22308007},{"batb":[[0,1.56,4.99]],"ltp":0.0,"tv":0.0,"id":7226819},{"batb":[[0,1.56,4.99]],"ltp":0.0,"tv":0.0,"id":10163711},{"batl":[[0,980,9.2]],"ltp":3.45,"tv":13.0,"id":10107355},{"batb":[[0,1.56,4.99]],"ltp":0.0,"tv":0.0,"id":22121325},{"batb":[[0,1.56,4.99]],"ltp":0.0,"tv":0.0,"id":26548208},{"batb":[[0,1.56,4.99]],"ltp":0.0,"tv":0.0,"id":27606066},{"batb":[[0,1.56,4.99]],"ltp":0.0,"tv":0.0,"id":24270700},{"batb":[[0,1.56,4.99]],"ltp":0.0,"tv":0.0,"id":13306150}]}]}
{"op":"mcm","clk":"989772721","pt":1580491255503,"mc":[{"id":"1.168133543","rc":[{"batb":[[0,3,1.68],[1,1.61,26.64],[2,1.6,3.31]],"ltp":3.45,"tv":13.0,"id":10107355}]}]}
{"op":"mcm","clk":"989772992","pt":1580491257519,"mc":[{"id":"1.168133543","rc":[{"batb":[[1,1.62,3],[2,1.61,26.64]],"ltp":3.45,"tv":13.0,"id":10107355}]}]}
{"op":"mcm","clk":"989773315","pt":1580491260297,"mc":[{"id":"1.168133543","rc":[{"batb":[[0,3.65,1.68],[1,1.54,4.99],[2,1.53,90]],"ltp":0.0,"tv":0.0,"id":12636}]}]}
{"op":"mcm","clk":"989773612","pt":1580491263310,"mc":[{"id":"1.168133543","rc":[{"batl":[[0,65,3.23],[1,980,9]],"ltp":0.0,"tv":0.0,"id":7226819}]}]}
{"op":"mcm","clk":"989773702","pt":1580491264206,"mc":[{"id":"1.168133543","rc":[{"batl":[[1,1000,3.46]],"ltp":3.45,"tv":13.0,"id":10107355}]}]}
{"op":"mcm","clk":"989773762","pt":1580491264839,"mc":[{"id":"1.168133543","rc":[{"trd":[[3.5,0.84]],"batl":[[1,1000,3.03]],"ltp":3.5,"tv":13.84,"id":10107355}],"tv":14.24}]}
{"op":"mcm","clk":"989773963","pt":1580491266518,"mc":[{"id":"1.168133543","rc":[{"batl":[[1,1000,3.46]],"ltp":3.5,"tv":13.84,"id":10107355}]}]}
{"op":"mcm","clk":"989774016","pt":1580491266903,"mc":[{"id":"1.168133543","rc":[{"batl":[[0,980,9.62],[1,1000,3.03]],"ltp":3.5,"tv":13.84,"id":10107355}]}]}
{"op":"mcm","clk":"989774210","pt":1580491268521,"mc":[{"id":"1.168133543","rc":[{"batl":[[0,980,9.2]],"ltp":3.5,"tv":13.84,"id":10107355}]}]}
{"op":"mcm","clk":"989774311","pt":1580491269522,"mc":[{"id":"1.168133543","rc":[{"batb":[[1,1.63,3]],"batl":[[1,1000,3.46]],"ltp":3.5,"tv":13.84,"id":10107355}]}]}
{"op":"mcm","clk":"989774360","pt":1580491270003,"mc":[{"id":"1.168133543","rc":[{"batl":[[0,980,9.62],[1,1000,3.03]],"ltp":3.5,"tv":13.84,"id":10107355}]}]}
{"op":"mcm","clk":"989774527","pt":1580491271497,"mc":[{"id":"1.168133543","rc":[{"batb":[[2,1.59,3.64]],"batl":[[0,980,9.2]],"ltp":3.5,"tv":13.84,"id":10107355}]}]}
{"op":"mcm","clk":"989774729","pt":1580491273400,"mc":[{"id":"1.168133543","rc":[{"batl":[[2,1000,0.42]],"ltp":0.0,"tv":0.0,"id":12636}]}]}
{"op":"mcm","clk":"989774836","pt":1580491274392,"mc":[{"id":"1.168133543","rc":[{"trd":[[3.9,0.84]],"batl":[[2,1000,0]],"ltp":3.9,"tv":0.84,"id":12636},{"batl":[[0,55,3],[1,980,9.2],[2,1000,3.03]],"ltp":3.5,"tv":13.84,"id":10107355}],"tv":15.08}]}
{"op":"mcm","clk":"989775041","pt":1580491276344,"mc":[{"id":"1.168133543","rc":[{"batl":[[2,1000,1.68]],"ltp":3.9,"tv":0.84,"id":12636}]}]}
{"op":"mcm","clk":"989775177","pt":1580491277511,"mc":[{"id":"1.168133543","rc":[{"trd":[[3.9,2.52]],"batl":[[2,1000,0]],"ltp":3.9,"tv":2.52,"id":12636},{"batl":[[0,55,3.2],[1,980,9]],"ltp":3.5,"tv":13.84,"id":10107355}],"tv":16.76}]}
{"op":"mcm","clk":"989775272","pt":1580491278350,"mc":[{"id":"1.168133543","rc":[{"batl":[[2,1000,1.68]],"ltp":3.9,"tv":2.52,"id":12636}]}]}
{"op":"mcm","clk":"989775368","pt":1580491279244,"mc":[{"id":"1.168133543","rc":[{"trd":[[3.9,4.2]],"batl":[[2,1000,0]],"ltp":3.9,"tv":4.2,"id":12636}],"tv":18.44}]}
{"op":"mcm","clk":"989775490","pt":1580491280358,"mc":[{"id":"1.168133543","rc":[{"batl":[[2,1000,0.84]],"ltp":3.9,"tv":4.2,"id":12636}]}]}
{"op":"mcm","clk":"989775607","pt":1580491281321,"mc":[{"id":"1.168133543","rc":[{"trd":[[3.9,5.88]],"batl":[[2,1000,0]],"ltp":3.9,"tv":5.88,"id":12636}],"tv":20.13}]}
{"op":"mcm","clk":"989775822","pt":1580491283164,"mc":[{"id":"1.168133543","rc":[{"trd":[[3.9,7.56]],"batb":[[1,1.55,3],[2,1.54,4.99]],"ltp":3.9,"tv":7.56,"id":12636},{"batb":[[1,1.64,3]],"ltp":3.5,"tv":13.84,"id":10107355}],"tv":21.81}]}
{"op":"mcm","clk":"989776108","pt":1580491285543,"mc":[{"id":"1.168133543","rc":[{"batl":[[0,960,1.04],[1,970,3.03],[2,980,9]],"ltp":3.9,"tv":7.56,"id":12636}]}]}
{"op":"mcm","clk":"989776120","pt":1580491285648,"mc":[{"id":"1.168133543","rc":[{"trd":[[4.1,1.68]],"batl":[[0,970,3.23],[1,980,9],[2,980,0]],"ltp":4.1,"tv":9.24,"id":12636}],"tv":23.49}]}
{"op":"mcm","clk":"989776391","pt":1580491287548,"mc":[{"id":"1.168133543","rc":[{"batb":[[1,1.57,90],[2,1.55,3]],"batl":[[0,950,9],[1,970,3.23],[2,1000,1.68]],"ltp":4.1,"tv":9.24,"id":12636},{"batb":[[2,4,72.33]],"ltp":1000.0,"tv":0.4,"id":13819977},{"batb":[[0,1.58,90],[1,1.56,4.99]],"ltp":0.0,"tv":0.0,"id":22308007},{"batb":[[0,1.58,90],[1,1.56,4.99]],"batl":[[1,110,9]],"ltp":0.0,"tv":0.0,"id":7226819},{"batb":[[0,1.58,90],[1,1.56,4.99]],"batl":[[0,950,9],[1,970,3.23]],"ltp":0.0,"tv":0.0,"id":10163711},{"batb":[[1,1.66,90],[2,1.64,3]],"batl":[[0,48,9],[1,55,3.2]],"ltp":3.5,"tv":13.84,"id":10107355},{"batb":[[0,1.58,90],[1,1.56,4.99]],"batl":[[0,950,9],[1,970,3.23]],"ltp":0.0,"tv":0.0,"id":22121325},{"batb":[[0,1.58,90],[1,1.56,4.99]],"ltp":0.0,"tv":0.0,"id":26548208},{"batb":[[0,1.58,90],[1,1.56,4.99]],"ltp":0.0,"tv":0.0,"id":27606066},{"batb":[[0,1.58,90],[1,1.56,4.99]],"ltp":0.0,"tv":0.0,"id":24270700},{"batb":[[0,1.58,90],[1,1.56,4.99]],"ltp":0.0,"tv":0.0,"id":13306150}]}]}
{"op":"mcm","clk":"989776461","pt":1580491288128,"mc":[{"id":"1.168133543","rc":[{"batl":[[0,950,9.84],[2,1000,0]],"ltp":4.1,"tv":9.24,"id":12636}]}]}
{"op":"mcm","clk":"989776622","pt":1580491289755,"mc":[{"id":"1.168133543","rc":[{"batl":[[0,950,9]],"ltp":4.1,"tv":9.24,"id":12636}]}]}
{"op":"mcm","clk":"989776823","pt":1580491291321,"mc":[{"id":"1.168133543","rc":[{"batl":[[0,950,9.2],[1,970,3.03]],"ltp":4.1,"tv":9.24,"id":12636},{"batl":[[0,950,9.2],[1,970,3.03]],"ltp":0.0,"tv":0.0,"id":10163711},{"batl":[[0,48,9.2],[1,55,3]],"ltp":3.5,"tv":13.84,"id":10107355},{"batl":[[0,950,9.2],[1,970,3.03]],"ltp":0.0,"tv":0.0,"id":22121325}]}]}
{"op":"mcm","clk":"989776964","pt":1580491292539,"mc":[{"id":"1.168133543","rc":[{"trd":[[3.45,7.12]],"ltp":3.45,"tv":15.52,"id":10107355}],"tv":25.17}]}
{"op":"mcm","clk":"989777165","pt":1580491294333,"mc":[{"id":"1.168133543","rc":[{"batl":[[2,1000,4.72]],"ltp":3.45,"tv":15.52,"id":10107355}]}]}
{"op":"mcm","clk":"989777316","pt":1580491295550,"mc":[{"id":"1.168133543","rc":[{"batb":[[1,1.67,3],[2,1.66,90]],"batl":[[0,46,1.04],[1,48,9],[2,55,3]],"ltp":3.45,"tv":15.52,"id":10107355}]}]}
{"op":"mcm","clk":"989777361","pt":1580491295969,"mc":[{"id":"1.168133543","rc":[{"batb":[[1,1.58,3],[2,1.57,90]],"ltp":4.1,"tv":9.24,"id":12636}]}]}
{"op":"mcm","clk":"989777511","pt":1580491297241,"mc":[{"id":"1.168133543","rc":[{"batl":[[0,48,9.2],[1,55,3],[2,1000,3.03]],"ltp":3.45,"tv":15.52,"id":10107355}]}]}
{"op":"mcm","clk":"989777660","pt":1580491298442,"mc":[{"id":"1.168133543","rc":[{"batl":[[2,1000,1.68]],"ltp":4.1,"tv":9.24,"id":12636}]}]}
{"op":"mcm","clk":"989777747","pt":1580491299246,"mc":[{"id":"1.168133543","rc":[{"trd":[[4,1.68]],"batl":[[2,1000,0]],"ltp":4.0,"tv":10.92,"id":12636}],"tv":26.85}]}
{"op":"mcm","clk":"989777900","pt":1580491300546,"mc":[{"id":"1.168133543","rc":[{"batl":[[2,1000,1.68]],"ltp":4.0,"tv":10.92,"id":12636}]}]}
{"op":"mcm","clk":"989778019","pt":1580491301547,"mc":[{"id":"1.168133543","rc":[{"batl":[[0,940,1.04],[1,950,9],[2,970,3.03]],"ltp":4.0,"tv":10.92,"id":12636}]}]}
{"op":"mcm","clk":"989778027","pt":1580491301657,"mc":[{"id":"1.168133543","rc":[{"trd":[[4.1,3.36]],"batl":[[0,950,9.2],[1,970,3.03],[2,970,0]],"ltp":4.1,"tv":12.6,"id":12636}],"tv":28.53}]}
{"op":"mcm","clk":"989778222","pt":1580491303560,"mc":[{"id":"1.168133543","rc":[{"batl":[[0,940,1.04],[1,950,9],[2,970,3.03]],"ltp":4.1,"tv":12.6,"id":12636}]}]}
{"op":"mcm","clk":"989778328","pt":1580491304573,"mc":[{"id":"1.168133543","rc":[{"trd":[[4.1,5.04]],"batl":[[0,950,9.2],[1,970,3.03],[2,970,0]],"ltp":4.1,"tv":14.28,"id":12636},{"batb":[[1,1.56,1.99]],"ltp":0.0,"tv":0.0,"id":22308007},{"batb":[[1,1.56,1.99]],"ltp":0.0,"tv":0.0,"id":7226819},{"batb":[[1,1.56,1.99]],"ltp":0.0,"tv":0.0,"id":10163711},{"batb":[[1,1.56,1.99]],"ltp":0.0,"tv":0.0,"id":22121325},{"batb":[[1,1.56,1.99]],"ltp":0.0,"tv":0.0,"id":26548208},{"batb":[[1,1.56,1.99]],"ltp":0.0,"tv":0.0,"id":27606066},{"batb":[[1,1.56,1.99]],"ltp":0.0,"tv":0.0,"id":24270700},{"batb":[[1,1.56,1.99]],"ltp":0.0,"tv":0.0,"id":13306150}],"tv":30.21}]}
{"op":"mcm","clk":"989778439","pt":1580491305469,"mc":[{"id":"1.168133543","rc":[{"batl":[[2,1000,0.84]],"ltp":4.1,"tv":14.28,"id":12636}]}]}
{"op":"mcm","clk":"989778496","pt":1580491305995,"mc":[{"id":"1.168133543","rc":[{"trd":[[4.2,1.68]],"batl":[[2,1000,0]],"ltp":4.2,"tv":15.96,"id":12636}],"tv":31.89}]}
{"op":"mcm","clk":"989778639","pt":1580491307371,"mc":[{"id":"1.168133543","rc":[{"batl":[[2,1000,1.68]],"ltp":4.2,"tv":15.96,"id":12636},{"batb":[[2,1.51,3.36]],"ltp":0.0,"tv":0.0,"id":22308007},{"batb":[[2,1.51,3.36]],"ltp":0.0,"tv":0.0,"id":7226819},{"batb":[[2,1.51,3.36]],"ltp":0.0,"tv":0.0,"id":10163711},{"batb":[[2,1.51,3.36]],"ltp":0.0,"tv":0.0,"id":22121325},{"batb":[[2,1.51,3.36]],"ltp":0.0,"tv":0.0,"id":26548208},{"batb":[[2,1.51,3.36]],"ltp":0.0,"tv":0.0,"id":27606066},{"batb":[[2,1.51,3.36]],"ltp":0.0,"tv":0.0,"id":24270700},{"batb":[[2,1.51,3.36]],"ltp":0.0,"tv":0.0,"id":13306150}]}]}
{"op":"mcm","clk":"989778767","pt":1580491308569,"mc":[{"id":"1.168133543","rc":[{"batl":[[2,1000,0]],"ltp":4.2,"tv":15.96,"id":12636}]}]}
{"op":"mcm","clk":"989778860","pt":1580491309465,"mc":[{"id":"1.168133543","rc":[{"trd":[[4.3,1.68]],"batb":[[1,1.59,3]],"ltp":4.3,"tv":17.64,"id":12636},{"batb":[[1,1.68,3]],"ltp":3.45,"tv":15.52,"id":10107355}],"tv":33.57}]}
{"op":"mcm","clk":"989778953","pt":1580491310356,"mc":[{"id":"1.168133543","rc":[{"batl":[[2,1000,1.68]],"ltp":4.3,"tv":17.64,"id":12636}]}]}
{"op":"mcm","clk":"989779082","pt":1580491311462,"mc":[{"id":"1.168133543","rc":[{"trd":[[4.3,3.36]],"batl":[[2,1000,0]],"ltp":4.3,"tv":19.33,"id":12636}],"tv":35.25}]}
{"op":"mcm","clk":"989779301","pt":1580491313564,"mc":[{"id":"1.168133543","rc":[{"batl":[[2,1000,0.84]],"ltp":4.3,"tv":19.33,"id":12636}]}]}
{"op":"mcm","clk":"989779373","pt":1580491314294,"mc":[{"id":"1.168133543","rc":[{"trd":[[4.3,5.04]],"batl":[[2,1000,0]],"ltp":4.3,"tv":21.01,"id":12636}],"tv":36.93}]}
{"op":"mcm","clk":"989779596","pt":1580491316289,"mc":[{"id":"1.168133543","rc":[{"batb":[[0,3,2.52]],"ltp":3.45,"tv":15.52,"id":10107355}]}]}
{"op":"mcm","clk":"989779697","pt":1580491317189,"mc":[{"id":"1.168133543","rc":[{"batb":[[0,3,1.68]],"ltp":3.45,"tv":15.52,"id":10107355}]}]}
{"op":"mcm","clk":"989779788","pt":1580491318084,"mc":[{"id":"1.168133543","rc":[{"batl":[[2,1000,4.72]],"ltp":3.45,"tv":15.52,"id":10107355}]}]}
{"op":"mcm","clk":"989779894","pt":1580491319187,"mc":[{"id":"1.168133543","rc":[{"batl":[[0,46,1.04],[1,48,9],[2,55,3]],"ltp":3.45,"tv":15.52,"id":10107355}]}]}
{"op":"mcm","clk":"989780082","pt":1580491320570,"mc":[{"id":"1.168133543","rc":[{"batb":[[1,1.6,1.03]],"ltp":4.3,"tv":21.01,"id":12636},{"batb":[[0,1.59,1.04],[1,1.58,90],[2,1.56,1.99]],"ltp":0.0,"tv":0.0,"id":22308007},{"batb":[[0,1.59,1.04],[1,1.58,90],[2,1.56,1.99]],"ltp":0.0,"tv":0.0,"id":7226819},{"batb":[[0,1.59,1.04],[1,1.58,90],[2,1.56,1.99]],"ltp":0.0,"tv":0.0,"id":10163711},{"batb":[[1,1.69,3.97]],"batl":[[0,48,9.2],[1,55,3],[2,1000,3.03]],"ltp":3.45,"tv":15.52,"id":10107355},{"batb":[[0,1.59,1.04],[1,1.58,90],[2,1.56,1.99]],"ltp":0.0,"tv":0.0,"id":22121325},{"batb":[[0,1.59,1.04],[1,1.58,90],[2,1.56,1.99]],"ltp":0.0,"tv":0.0,"id":26548208},{"batb":[[0,1.59,1.04],[1,1.58,90],[2,1.56,1.99]],"ltp":0.0,"tv":0.0,"id":13306150}]}]}
{"op":"mcm","clk":"989780151","pt":1580491321198,"mc":[{"id":"1.168133543","rc":[{"batb":[[1,1.6,4.03]],"ltp":4.3,"tv":21.01,"id":12636},{"batl":[[2,1000,4.72]],"ltp":3.45,"tv":15.52,"id":10107355},{"batb":[[0,1.59,1.04],[1,1.58,90],[2,1.56,1.99]],"ltp":0.0,"tv":0.0,"id":27606066},{"batb":[[0,1.59,1.04],[1,1.58,90],[2,1.56,1.99]],"ltp":0.0,"tv":0.0,"id":24270700}]}]}
{"op":"mcm","clk":"989780279","pt":1580491322505,"mc":[{"id":"1.168133543","rc":[{"batl":[[0,46,1.04],[1,48,9],[2,55,3]],"ltp":3.45,"tv":15.52,"id":10107355}]}]}
{"op":"mcm","clk":"989780414","pt":1580491323866,"mc":[{"id":"1.168133543","rc":[{"batl":[[0,48,9.2],[1,55,3],[2,1000,3.03]],"ltp":3.45,"tv":15.52,"id":10107355}]}]}
{"op":"mcm","clk":"989780528","pt":1580491325287,"mc":[{"id":"1.168133543","rc":[{"batl":[[2,1000,3.88]],"ltp":3.45,"tv":15.52,"id":10107355}]}]}
{"op":"mcm","clk":"989780580","pt":1580491325904,"mc":[{"id":"1.168133543","rc":[{"batl":[[0,46,1.04],[1,48,9],[2,55,3]],"ltp":3.45,"tv":15.52,"id":10107355}]}]}
{"op":"mcm","clk":"989780716","pt":1580491327379,"mc":[{"id":"1.168133543","rc":[{"batl":[[0,48,9.2],[1,55,3],[2,1000,3.03]],"ltp":3.45,"tv":15.52,"id":10107355}]}]}
{"op":"mcm","clk":"989780937","pt":1580491329506,"mc":[{"id":"1.168133543","rc":[{"batb":[[1,1.62,90],[2,1.6,4.03]],"ltp":4.3,"tv":21.01,"id":12636},{"batb":[[1,1.71,90],[2,1.69,3.97]],"ltp":3.45,"tv":15.52,"id":10107355}]}]}
{"op":"mcm","clk":"989780993","pt":1580491329988,"mc":[{"id":"1.168133543","rc":[{"batl":[[0,48,9.62]],"ltp":3.45,"tv":15.52,"id":10107355}]}]}
{"op":"mcm","clk":"989781095","pt":1580491331196,"mc":[{"id":"1.168133543","rc":[{"batl":[[0,48,9.2]],"ltp":3.45,"tv":15.52,"id":10107355}]}]}
{"op":"mcm","clk":"989781216","pt":1580491332396,"mc":[{"id":"1.168133543","rc":[{"batb":[[1,1.72,3],[2,1.71,90]],"batl":[[2,1000,4.72]],"ltp":3.45,"tv":15.52,"id":10107355}]}]}
{"op":"mcm","clk":"989781339","pt":1580491333491,"mc":[{"id":"1.168133543","rc":[{"batb":[[1,1.63,3],[2,1.62,90]],"ltp":4.3,"tv":21.01,"id":12636},{"batl":[[2,1000,3.03]],"ltp":3.45,"tv":15.52,"id":10107355}]}]}
{"op":"mcm","clk":"989781373","pt":1580491333907,"mc":[{"id":"1.168133543","rc":[{"batl":[[0,48,9.62]],"ltp":3.45,"tv":15.52,"id":10107355}]}]}
{"op":"mcm","clk":"989781503","pt":1580491335417,"mc":[{"id":"1.168133543","rc":[{"batl":[[0,48,9.2]],"ltp":3.45,"tv":15.52,"id":10107355}]}]}
{"op":"mcm","clk":"989781868","pt":1580491338916,"mc":[{"id":"1.168133543","rc":[{"batl":[[2,1000,1.68]],"ltp":4.3,"tv":21.01,"id":12636}]}]}
{"op":"mcm","clk":"989781969","pt":1580491340111,"mc":[{"id":"1.168133543","rc":[{"batl":[[0,950,9.62],[2,1000,0]],"ltp":4.3,"tv":21.01,"id":12636}]}]}
{"op":"mcm","clk":"989782099","pt":1580491341723,"mc":[{"id":"1.168133543","rc":[{"batl":[[0,950,9.2]],"ltp":4.3,"tv":21.01,"id":12636}]}]}
{"op":"mcm","clk":"989782240","pt":1580491343497,"mc":[{"id":"1.168133543","rc":[{"batb":[[1,1.71,90],[2,1.6,1.28]],"ltp":3.45,"tv":15.52,"id":10107355}]}]}
{"op":"mcm","clk":"989782302","pt":1580491344082,"mc":[{"id":"1.168133543","rc":[{"batb":[[1,1.64,3]],"batl":[[0,950,9.62]],"ltp":4.3,"tv":21.01,"id":12636},{"batb":[[1,1.73,3],[2,1.71,90]],"ltp":3.45,"tv":15.52,"id":10107355}]}]}
{"op":"mcm","clk":"989782397","pt":1580491345231,"mc":[{"id":"1.168133543","rc":[{"batl":[[0,950,9.2]],"ltp":4.3,"tv":21.01,"id":12636}]}]}
{"op":"mcm","clk":"989782526","pt":1580491346491,"mc":[{"id":"1.168133543","rc":[{"batl":[[2,1000,0.42]],"ltp":4.3,"tv":21.01,"id":12636}]}]}
{"op":"mcm","clk":"989782589","pt":1580491347118,"mc":[{"id":"1.168133543","rc":[{"trd":[[4.3,5.88]],"batl":[[2,1000,0]],"ltp":4.3,"tv":21.85,"id":12636}],"tv":37.77}]}
{"op":"mcm","clk":"989782712","pt":1580491348421,"mc":[{"id":"1.168133543","rc":[{"batl":[[2,1000,0.42]],"ltp":4.3,"tv":21.85,"id":12636}]}]}
{"op":"mcm","clk":"989782795","pt":1580491349099,"mc":[{"id":"1.168133543","rc":[{"trd":[[4.3,6.72]],"batl":[[2,1000,0]],"ltp":4.3,"tv":22.69,"id":12636}],"tv":38.62}]}
{"op":"mcm","clk":"989782928","pt":1580491350398,"mc":[{"id":"1.168133543","rc":[{"batl":[[2,1000,0.42]],"ltp":4.3,"tv":22.69,"id":12636}]}]}
{"op":"mcm","clk":"989782992","pt":1580491351024,"mc":[{"id":"1.168133543","rc":[{"trd":[[4.3,7.56]],"batl":[[2,1000,0]],"ltp":4.3,"tv":23.53,"id":12636}],"tv":39.46}]}
{"op":"mcm","clk":"989792753","pt":1580491352337,"mc":[{"id":"1.168133543","rc":[{"batl":[[2,1000,0.42]],"ltp":4.3,"tv":23.53,"id":12636}]}]}
{"op":"mcm","clk":"989792900","pt":1580491353536,"mc":[{"id":"1.168133543","rc":[{"batl":[[0,950,9.62]],"ltp":4.3,"tv":23.53,"id":12636}]}]}
{"op":"mcm","clk":"989792967","pt":1580491354231,"mc":[{"id":"1.168133543","rc":[{"batl":[[0,940,1.04],[1,950,9],[2,970,3.03]],"ltp":4.3,"tv":23.53,"id":12636}]}]}
{"op":"mcm","clk":"989793154","pt":1580491356218,"mc":[{"id":"1.168133543","rc":[{"batl":[[0,950,9.2],[1,970,3.03],[2,970,0]],"ltp":4.3,"tv":23.53,"id":12636}]}]}
{"op":"mcm","clk":"989793257","pt":1580491357315,"mc":[{"id":"1.168133543","rc":[{"batl":[[0,950,9.62]],"ltp":4.3,"tv":23.53,"id":12636}]}]}
{"op":"mcm","clk":"989793319","pt":1580491358243,"mc":[{"id":"1.168133543","rc":[{"batb":[[1,1.74,3]],"ltp":3.45,"tv":15.52,"id":10107355}]}]}
{"op":"mcm","clk":"989793370","pt":1580491358722,"mc":[{"id":"1.168133543","rc":[{"batb":[[1,1.65,3]],"ltp":4.3,"tv":23.53,"id":12636}]}]}
{"op":"mcm","clk":"989793436","pt":1580491359645,"mc":[{"id":"1.168133543","rc":[{"batl":[[0,950,9.2]],"ltp":4.3,"tv":23.53,"id":12636}]}]}
{"op":"mcm","clk":"989793581","pt":1580491361428,"mc":[{"id":"1.168133543","rc":[{"batl":[[2,1000,0.42]],"ltp":4.3,"tv":23.53,"id":12636}]}]}
{"op":"mcm","clk":"989793618","pt":1580491361852,"mc":[{"id":"1.168133543","rc":[{"batl":[[0,950,9.62],[2,1000,0]],"ltp":4.3,"tv":23.53,"id":12636}]}]}
{"op":"mcm","clk":"989793698","pt":1580491362837,"mc":[{"id":"1.168133543","rc":[{"batl":[[0,950,9.2]],"ltp":4.3,"tv":23.53,"id":12636}]}]}
{"op":"mcm","clk":"989794068","pt":1580491367250,"mc":[{"id":"1.168133543","rc":[{"batb":[[1,1.67,90],[2,1.65,3]],"ltp":4.3,"tv":23.53,"id":12636},{"batb":[[1,1.76,90],[2,1.74,3]],"ltp":3.45,"tv":15.52,"id":10107355}]}]}
{"op":"mcm","clk":"989794324","pt":1580491370532,"mc":[{"id":"1.168133543","rc":[{"batb":[[0,1.6,1.99],[1,1.59,1.04],[2,1.58,90]],"ltp":0.0,"tv":0.0,"id":7226819},{"batb":[[0,1.6,1.99],[1,1.59,1.04],[2,1.58,90]],"ltp":0.0,"tv":0.0,"id":10163711},{"batb":[[0,1.6,1.99],[1,1.59,1.04],[2,1.58,90]],"ltp":0.0,"tv":0.0,"id":22121325}]}]}
{"op":"mcm","clk":"989794396","pt":1580491371152,"mc":[{"id":"1.168133543","rc":[{"batb":[[0,1.6,1.99],[1,1.59,1.04],[2,1.58,90]],"ltp":0.0,"tv":0.0,"id":26548208}]}]}
{"op":"mcm","clk":"989794479","pt":1580491372044,"mc":[{"id":"1.168133543","rc":[{"batb":[[0,1.6,1.99],[1,1.59,1.04],[2,1.58,90]],"ltp":0.0,"tv":0.0,"id":13306150}]}]}
{"op":"mcm","clk":"989794613","pt":1580491373490,"mc":[{"id":"1.168133543","rc":[{"batb":[[0,1.6,1.99],[1,1.59,1.04],[2,1.58,90]],"ltp":0.0,"tv":0.0,"id":22308007}]}]}
{"op":"mcm","clk":"989794672","pt":1580491374172,"mc":[{"id":"1.168133543","rc":[{"batb":[[0,1.6,1.99],[1,1.59,1.04],[2,1.58,90]],"ltp":0.0,"tv":0.0,"id":27606066},{"batb":[[0,1.6,1.99],[1,1.59,1.04],[2,1.58,90]],"ltp":0.0,"tv":0.0,"id":24270700}]}]}
{"op":"mcm","clk":"989794867","pt":1580491376291,"mc":[{"id":"1.168133543","rc":[{"batb":[[1,1.68,3],[2,1.67,90]],"ltp":4.3,"tv":23.53,"id":12636},{"batb":[[1,1.77,3],[2,1.76,90]],"ltp":3.45,"tv":15.52,"id":10107355}]}]}
{"op":"mcm","clk":"989795068","pt":1580491378375,"mc":[{"id":"1.168133543","rc":[{"batb":[[0,1.68,3],[1,1.67,90],[2,1.6,1.03]],"ltp":4.3,"tv":23.53,"id":12636}]}]}
{"op":"mcm","clk":"989795203","pt":1580491379821,"mc":[{"id":"1.168133543","rc":[{"batb":[[2,1.51,3.36]],"ltp":4.3,"tv":23.53,"id":12636}]}]}
{"op":"mcm","clk":"989795461","pt":1580491382493,"mc":[{"id":"1.168133543","rc":[{"batl":[[0,950,9.62]],"ltp":4.3,"tv":23.53,"id":12636}]}]}
{"op":"mcm","clk":"989795480","pt":1580491382697,"mc":[{"id":"1.168133543","rc":[{"trd":[[4.3,8.4]],"batl":[[0,950,9.2]],"ltp":4.3,"tv":24.37,"id":12636}],"tv":40.3}]}
{"op":"mcm","clk":"989795712","pt":1580491385199,"mc":[{"id":"1.168133543","rc":[{"batl":[[2,1000,0.42]],"ltp":4.3,"tv":24.37,"id":12636}]}]}
{"op":"mcm","clk":"989795767","pt":1580491385832,"mc":[{"id":"1.168133543","rc":[{"trd":[[4.5,0.84]],"batl":[[2,1000,0]],"ltp":4.5,"tv":25.21,"id":12636}],"tv":41.14}]}
{"op":"mcm","clk":"989795906","pt":1580491387497,"mc":[{"id":"1.168133543","rc":[{"batl":[[2,1000,0.42]],"ltp":4.5,"tv":25.21,"id":12636}]}]}
{"op":"mcm","clk":"989795953","pt":1580491388024,"mc":[{"id":"1.168133543","rc":[{"trd":[[4.9,0.84]],"batl":[[2,1000,0]],"ltp":4.9,"tv":26.05,"id":12636}],"tv":41.98}]}
{"op":"mcm","clk":"989796007","pt":1580491388700,"mc":[{"id":"1.168133543","rc":[{"batb":[[1,1.78,3]],"ltp":3.45,"tv":15.52,"id":10107355}]}]}
{"op":"mcm","clk":"989796144","pt":1580491390321,"mc":[{"id":"1.168133543","rc":[{"trd":[[5,5.04]],"ltp":5.0,"tv":31.09,"id":12636}],"tv":47.02}]}
{"op":"mcm","clk":"989796342","pt":1580491392514,"mc":[{"id":"1.168133543","rc":[{"trd":[[5.5,4.08]],"batl":[[0,950,9.68]],"ltp":5.5,"tv":35.18,"id":12636}],"tv":51.1}]}
{"op":"mcm","clk":"989796360","pt":1580491392719,"mc":[{"id":"1.168133543","rc":[{"trd":[[5.5,5.04]],"batl":[[0,950,9.2]],"ltp":5.5,"tv":36.13,"id":12636}],"tv":52.06}]}
{"op":"mcm","clk":"989796533","pt":1580491394545,"mc":[{"id":"1.168133543","rc":[{"batl":[[0,5.7,2.52],[1,950,9.2],[2,970,3.03]],"ltp":5.5,"tv":36.13,"id":12636}]}]}
{"op":"mcm","clk":"989796551","pt":1580491394754,"mc":[{"id":"1.168133543","rc":[{"trd":[[5.7,5.04]],"batl":[[0,950,9.2],[1,970,3.03],[2,970,0]],"ltp":5.7,"tv":41.18,"id":12636}],"tv":57.11}]}
{"op":"mcm","clk":"989796671","pt":1580491395918,"mc":[{"id":"1.168133543","rc":[{"batl":[[0,5.7,2.52],[1,950,9.2],[2,970,3.03]],"ltp":5.7,"tv":41.18,"id":12636}]}]}
{"op":"mcm","clk":"989796879","pt":1580491398111,"mc":[{"id":"1.168133543","rc":[{"batl":[[0,5.6,2.52]],"ltp":5.7,"tv":41.18,"id":12636}]}]}
{"op":"mcm","clk":"989796995","pt":1580491399510,"mc":[{"id":"1.168133543","rc":[{"batl":[[0,950,9.2],[1,970,3.03],[2,970,0]],"ltp":5.7,"tv":41.18,"id":12636},{"batb":[[1,1.76,90],[2,1.59,3.33]],"ltp":3.45,"tv":15.52,"id":10107355}]}]}
{"op":"mcm","clk":"989797005","pt":1580491399618,"mc":[{"id":"1.168133543","rc":[{"batb":[[1,1.79,3],[2,1.76,90]],"ltp":3.45,"tv":15.52,"id":10107355}]}]}
{"op":"mcm","clk":"989797163","pt":1580491401332,"mc":[{"id":"1.168133543","rc":[{"batl":[[2,1000,0.42]],"ltp":5.7,"tv":41.18,"id":12636}]}]}
{"op":"mcm","clk":"989797238","pt":1580491402015,"mc":[{"id":"1.168133543","rc":[{"batl":[[0,950,9.62],[2,1000,0]],"ltp":5.7,"tv":41.18,"id":12636}]}]}
{"op":"mcm","clk":"989797347","pt":1580491403118,"mc":[{"id":"1.168133543","rc":[{"batb":[[0,1.7,90],[1,1.68,3]],"batl":[[0,950,9.2]],"ltp":5.7,"tv":41.18,"id":12636},{"batb":[[0,1.61,90],[1,1.6,1.99],[2,1.59,1.04]],"ltp":0.0,"tv":0.0,"id":22308007},{"batb":[[0,1.61,90],[1,1.6,1.99],[2,1.59,1.04]],"ltp":0.0,"tv":0.0,"id":7226819},{"batb":[[0,1.61,90],[1,1.6,1.99],[2,1.59,1.04]],"ltp":0.0,"tv":0.0,"id":10163711},{"batb":[[1,1.81,90],[2,1.79,3]],"ltp":3.45,"tv":15.52,"id":10107355},{"batb":[[0,1.61,90],[1,1.6,1.99],[2,1.59,1.04]],"ltp":0.0,"tv":0.0,"id":22121325},{"batb":[[0,1.61,90],[1,1.6,1.99],[2,1.59,1.04]],"ltp":0.0,"tv":0.0,"id":26548208},{"batb":[[0,1.61,90],[1,1.6,1.99],[2,1.59,1.04]],"ltp":0.0,"tv":0.0,"id":27606066},{"batb":[[0,1.61,90],[1,1.6,1.99],[2,1.59,1.04]],"ltp":0.0,"tv":0.0,"id":24270700},{"batb":[[0,1.61,90],[1,1.6,1.99],[2,1.59,1.04]],"ltp":0.0,"tv":0.0,"id":13306150}]}]}
{"op":"mcm","clk":"989797449","pt":1580491404228,"mc":[{"id":"1.168133543","rc":[{"batl":[[2,1000,0.42]],"ltp":5.7,"tv":41.18,"id":12636}]}]}
{"op":"mcm","clk":"989797587","pt":1580491405532,"mc":[{"id":"1.168133543","rc":[{"batl":[[0,950,9.62],[2,1000,0]],"ltp":5.7,"tv":41.18,"id":12636}]}]}
{"op":"mcm","clk":"989797608","pt":1580491405743,"mc":[{"id":"1.168133543","rc":[{"batl":[[0,950,9.2]],"ltp":5.7,"tv":41.18,"id":12636}]}]}
{"op":"mcm","clk":"989797833","pt":1580491407618,"mc":[{"id":"1.168133543","rc":[{"batl":[[0,48,9.62]],"ltp":3.45,"tv":15.52,"id":10107355}]}]}
{"op":"mcm","clk":"989797992","pt":1580491409329,"mc":[{"id":"1.168133543","rc":[{"batl":[[0,48,9.2]],"ltp":3.45,"tv":15.52,"id":10107355}]}]}
{"op":"mcm","clk":"989798126","pt":1580491410543,"mc":[{"id":"1.168133543","rc":[{"batb":[[0,1.71,3],[1,1.7,90]],"batl":[[2,1000,1.68]],"ltp":5.7,"tv":41.18,"id":12636},{"batb":[[1,1.82,3],[2,1.81,90]],"ltp":3.45,"tv":15.52,"id":10107355}]}]}
{"op":"mcm","clk":"989798190","pt":1580491411054,"mc":[{"id":"1.168133543","rc":[{"batl":[[0,950,9.62],[2,1000,0]],"ltp":5.7,"tv":41.18,"id":12636}]}]}
{"op":"mcm","clk":"989798303","pt":1580491412165,"mc":[{"id":"1.168133543","rc":[{"batl":[[0,950,9.2]],"ltp":5.7,"tv":41.18,"id":12636}]}]}
{"op":"mcm","clk":"989798442","pt":1580491413328,"mc":[{"id":"1.168133543","rc":[{"batl":[[2,1000,1.68]],"ltp":5.7,"tv":41.18,"id":12636}]}]}
{"op":"mcm","clk":"989798546","pt":1580491414269,"mc":[{"id":"1.168133543","rc":[{"batl":[[0,950,9.62],[2,1000,0]],"ltp":5.7,"tv":41.18,"id":12636}]}]}
{"op":"mcm","clk":"989798686","pt":1580491415563,"mc":[{"id":"1.168133543","rc":[{"batl":[[0,950,9.2]],"ltp":5.7,"tv":41.18,"id":12636}]}]}
{"op":"mcm","clk":"989798760","pt":1580491416158,"mc":[{"id":"1.168133543","rc":[{"batl":[[2,1000,1.68]],"ltp":5.7,"tv":41.18,"id":12636}]}]}
{"op":"mcm","clk":"989798864","pt":1580491417047,"mc":[{"id":"1.168133543","rc":[{"batl":[[0,950,9.62],[2,1000,0]],"ltp":5.7,"tv":41.18,"id":12636}]}]}
{"op":"mcm","clk":"989799135","pt":1580491419543,"mc":[{"id":"1.168133543","rc":[{"batl":[[0,950,9.2],[2,1000,1.68]],"ltp":5.7,"tv":41.18,"id":12636}]}]}
{"op":"mcm","clk":"989799220","pt":1580491420334,"mc":[{"id":"1.168133543","rc":[{"batl":[[0,950,9.62],[2,1000,0]],"ltp":5.7,"tv":41.18,"id":12636}]}]}
{"op":"mcm","clk":"989799408","pt":1580491422257,"mc":[{"id":"1.168133543","rc":[{"batl":[[0,950,9.2]],"ltp":5.7,"tv":41.18,"id":12636}]}]}
{"op":"mcm","clk":"989799713","pt":1580491425338,"mc":[{"id":"1.168133543","rc":[{"batl":[[2,1000,1.68]],"ltp":5.7,"tv":41.18,"id":12636},{"batb":[[1,1.83,3]],"ltp":3.45,"tv":15.52,"id":10107355}]}]}
{"op":"mcm","clk":"989799828","pt":1580491426372,"mc":[{"id":"1.168133543","rc":[{"batl":[[0,950,9.62],[2,1000,0]],"ltp":5.7,"tv":41.18,"id":12636}]}]}
{"op":"mcm","clk":"989800051","pt":1580491428461,"mc":[{"id":"1.168133543","rc":[{"batl":[[0,950,9.2],[2,1000,1.68]],"ltp":5.7,"tv":41.18,"id":12636}]}]}
{"op":"mcm","clk":"989800135","pt":1580491429353,"mc":[{"id":"1.168133543","rc":[{"batl":[[0,950,9.62],[2,1000,0]],"ltp":5.7,"tv":41.18,"id":12636}]}]}
{"op":"mcm","clk":"989800172","pt":1580491429766,"mc":[{"id":"1.168133543","rc":[{"batb":[[0,1.72,24.93],[1,1.71,3],[2,1.7,90]],"ltp":5.7,"tv":41.18,"id":12636}]}]}
{"op":"mcm","clk":"989800250","pt":1580491430647,"mc":[{"id":"1.168133543","rc":[{"batl":[[0,950,9.2]],"ltp":5.7,"tv":41.18,"id":12636}]}]}
{"op":"mcm","clk":"989800400","pt":1580491432265,"mc":[{"id":"1.168133543","rc":[{"batl":[[2,1000,0.42]],"ltp":5.7,"tv":41.18,"id":12636}]}]}
{"op":"mcm","clk":"989800451","pt":1580491432790,"mc":[{"id":"1.168133543","rc":[{"batl":[[0,950,9.62],[2,1000,0]],"ltp":5.7,"tv":41.18,"id":12636}]}]}
{"op":"mcm","clk":"989800594","pt":1580491434265,"mc":[{"id":"1.168133543","rc":[{"batl":[[0,950,9.2]],"ltp":5.7,"tv":41.18,"id":12636}]}]}
{"op":"mcm","clk":"989800831","pt":1580491436384,"mc":[{"id":"1.168133543","rc":[{"batl":[[0,5,1.68],[1,950,9.2],[2,970,3.03]],"ltp":5.7,"tv":41.18,"id":12636},{"batb":[[1,1.84,3]],"ltp":3.45,"tv":15.52,"id":10107355}]}]}
{"op":"mcm","clk":"989800922","pt":1580491437372,"mc":[{"id":"1.168133543","rc":[{"batb":[[0,1.73,3],[1,1.72,24.93]],"batl":[[0,4.8,1.68],[1,5,1.68],[2,950,9.2]],"ltp":5.7,"tv":41.18,"id":12636}]}]}
{"op":"mcm","clk":"989801213","pt":1580491440373,"mc":[{"id":"1.168133543","rc":[{"batb":[[0,1.75,90],[1,1.73,3],[2,1.72,24.93]],"ltp":5.7,"tv":41.18,"id":12636}]}]}
{"op":"mcm","clk":"989801240","pt":1580491440783,"mc":[{"id":"1.168133543","rc":[{"batl":[[2,9.2,9]],"ltp":5.7,"tv":41.18,"id":12636}]}]}
{"op":"mcm","clk":"989801551","pt":1580491443979,"mc":[{"id":"1.168133543","rc":[{"batl":[[0,48,9.62]],"ltp":3.45,"tv":15.52,"id":10107355}]}]}
{"op":"mcm","clk":"989801655","pt":1580491444762,"mc":[{"id":"1.168133543","rc":[{"batl":[[0,48,9.2]],"ltp":3.45,"tv":15.52,"id":10107355}]}]}
{"op":"mcm","clk":"989801868","pt":1580491447176,"mc":[{"id":"1.168133543","rc":[{"batb":[[0,3.2,1.68],[1,3,1.68],[2,1.84,3]],"ltp":3.45,"tv":15.52,"id":10107355}]}]}
{"op":"mcm","clk":"989802177","pt":1580491450468,"mc":[{"id":"1.168133543","rc":[{"batb":[[0,1.76,3],[1,1.75,90],[2,1.51,3.36]],"ltp":5.7,"tv":41.18,"id":12636},{"batb":[[1,3.05,3],[2,3,1.68]],"ltp":3.45,"tv":15.52,"id":10107355}]}]}
{"op":"mcm","clk":"989803269","pt":1580491462518,"mc":[{"id":"1.168133543","rc":[{"batl":[[2,1000,4.72]],"ltp":3.45,"tv":15.52,"id":10107355}]}]}
{"op":"mcm","clk":"989803393","pt":1580491463506,"mc":[{"id":"1.168133543","rc":[{"batb":[[1,3.1,3]],"batl":[[0,48,9.62],[2,1000,3.03]],"ltp":3.45,"tv":15.52,"id":10107355}]}]}
{"op":"mcm","clk":"989803599","pt":1580491465390,"mc":[{"id":"1.168133543","rc":[{"batl":[[0,48,9.2]],"ltp":3.45,"tv":15.52,"id":10107355}]}]}
{"op":"mcm","clk":"989803805","pt":1580491467475,"mc":[{"id":"1.168133543","rc":[{"batl":[[2,1000,4.72]],"ltp":3.45,"tv":15.52,"id":10107355}]}]}
{"op":"mcm","clk":"989803888","pt":1580491468414,"mc":[{"id":"1.168133543","rc":[{"batl":[[0,48,9.62],[2,1000,3.03]],"ltp":3.45,"tv":15.52,"id":10107355}]}]}
{"op":"mcm","clk":"989803912","pt":1580491468624,"mc":[{"id":"1.168133543","rc":[{"trd":[[3.45,7.96]],"batl":[[0,48,9.2]],"ltp":3.45,"tv":16.36,"id":10107355}],"tv":57.95}]}
{"op":"mcm","clk":"989804120","pt":1580491470504,"mc":[{"id":"1.168133543","rc":[{"batl":[[2,1000,4.72]],"ltp":3.45,"tv":16.36,"id":10107355}]}]}
{"op":"mcm","clk":"989804195","pt":1580491471287,"mc":[{"id":"1.168133543","rc":[{"batb":[[0,1.77,24.23],[1,1.76,3],[2,1.75,90]],"ltp":5.7,"tv":41.18,"id":12636},{"trd":[[3.5,1.68]],"batl":[[2,1000,3.03]],"ltp":3.5,"tv":17.2,"id":10107355}],"tv":58.79}]}
{"op":"mcm","clk":"989804743","pt":1580491476497,"mc":[{"id":"1.168133543","rc":[{"batb":[[1,1.75,90],[2,1.51,3.36]],"ltp":5.7,"tv":41.18,"id":12636},{"batb":[[1,3.15,3]],"ltp":3.5,"tv":17.2,"id":10107355}]}]}
{"op":"mcm","clk":"989804767","pt":1580491476704,"mc":[{"id":"1.168133543","rc":[{"batb":[[0,1.78,3],[1,1.77,24.23],[2,1.75,90]],"ltp":5.7,"tv":41.18,"id":12636},{"trd":[[3.55,0.84]],"ltp":3.55,"tv":18.04,"id":10107355}],"tv":59.63}]}
{"op":"mcm","clk":"989804937","pt":1580491478507,"mc":[{"id":"1.168133543","rc":[{"batl":[[2,1000,3.46]],"ltp":3.55,"tv":18.04,"id":10107355}]}]}
{"op":"mcm","clk":"989805012","pt":1580491479234,"mc":[{"id":"1.168133543","rc":[{"trd":[[3.6,0.84]],"batl":[[2,1000,3.03]],"ltp":3.6,"tv":18.88,"id":10107355}],"tv":60.47}]}
{"op":"mcm","clk":"989805136","pt":1580491480401,"mc":[{"id":"1.168133543","rc":[{"batl":[[2,1000,4.72]],"ltp":3.6,"tv":18.88,"id":10107355}]}]}
{"op":"mcm","clk":"989805242","pt":1580491481333,"mc":[{"id":"1.168133543","rc":[{"trd":[[3.65,0.84]],"batl":[[2,1000,3.03]],"ltp":3.65,"tv":19.73,"id":10107355}],"tv":61.31}]}
{"op":"mcm","clk":"989805355","pt":1580491482431,"mc":[{"id":"1.168133543","rc":[{"batl":[[0,4.7,2],[1,4.8,1.68],[2,5,1.68]],"ltp":5.7,"tv":41.18,"id":12636}]}]}
{"op":"mcm","clk":"989805453","pt":1580491483430,"mc":[{"id":"1.168133543","rc":[{"batl":[[2,1000,3.46]],"ltp":3.65,"tv":19.73,"id":10107355}]}]}
{"op":"mcm","clk":"989805522","pt":1580491484117,"mc":[{"id":"1.168133543","rc":[{"batb":[[2,1.76,6]],"ltp":5.7,"tv":41.18,"id":12636},{"trd":[[3.7,0.84]],"batl":[[2,1000,3.03]],"ltp":3.7,"tv":20.57,"id":10107355}],"tv":62.15}]}
{"op":"mcm","clk":"989805711","pt":1580491486213,"mc":[{"id":"1.168133543","rc":[{"trd":[[3.7,4.2]],"ltp":3.7,"tv":23.93,"id":10107355}],"tv":65.51}]}
{"op":"mcm","clk":"989805808","pt":1580491487204,"mc":[{"id":"1.168133543","rc":[{"batb":[[0,3.2,4.68],[1,3,1.68],[2,1.81,90]],"ltp":3.7,"tv":23.93,"id":10107355}]}]}
{"op":"mcm","clk":"989805857","pt":1580491487724,"mc":[{"id":"1.168133543","rc":[{"trd":[[3.7,7.56]],"ltp":3.7,"tv":27.29,"id":10107355}],"tv":68.87}]}
{"op":"mcm","clk":"989805980","pt":1580491489136,"mc":[{"id":"1.168133543","rc":[{"trd":[[3.7,10.93]],"ltp":3.7,"tv":30.65,"id":10107355}],"tv":72.23}]}
{"op":"mcm","clk":"989806135","pt":1580491490515,"mc":[{"id":"1.168133543","rc":[{"batb":[[1,1.76,6],[2,1.75,90]],"ltp":5.7,"tv":41.18,"id":12636}]}]}
{"op":"mcm","clk":"989806155","pt":1580491490725,"mc":[{"id":"1.168133543","rc":[{"trd":[[3.7,14.29]],"ltp":3.7,"tv":34.01,"id":10107355}],"tv":75.6}]}
{"op":"mcm","clk":"989806306","pt":1580491492132,"mc":[{"id":"1.168133543","rc":[{"trd":[[3.7,17.65]],"ltp":3.7,"tv":37.37,"id":10107355}],"tv":78.96}]}
{"op":"mcm","clk":"989806453","pt":1580491493750,"mc":[{"id":"1.168133543","rc":[{"trd":[[3.7,21.01]],"ltp":3.7,"tv":40.74,"id":10107355}],"tv":82.32}]}
{"op":"mcm","clk":"989806585","pt":1580491495322,"mc":[{"id":"1.168133543","rc":[{"trd":[[3.7,24.37]],"ltp":3.7,"tv":44.1,"id":10107355}],"tv":85.68}]}
{"op":"mcm","clk":"989806664","pt":1580491496257,"mc":[{"id":"1.168133543","rc":[{"batl":[[0,3.7,1.68],[1,48,9.2],[2,55,3]],"ltp":3.7,"tv":44.1,"id":10107355}]}]}
{"op":"mcm","clk":"989806884","pt":1580491498571,"mc":[{"id":"1.168133543","rc":[{"batb":[[0,3.25,3],[1,3.2,1.68],[2,3,1.68]],"batl":[[0,48,9.2],[1,55,3],[2,1000,3.03]],"ltp":3.7,"tv":44.1,"id":10107355}]}]}
{"op":"mcm","clk":"989806963","pt":1580491499362,"mc":[{"id":"1.168133543","rc":[{"batb":[[0,1.77,3]],"ltp":5.7,"tv":41.18,"id":12636},{"batl":[[0,3.75,1.68],[1,48,9.2],[2,55,3]],"ltp":3.7,"tv":44.1,"id":10107355}]}]}
{"op":"mcm","clk":"989807173","pt":1580491501466,"mc":[{"id":"1.168133543","rc":[{"batl":[[0,3.7,1.68]],"ltp":3.7,"tv":44.1,"id":10107355}]}]}
{"op":"mcm","clk":"989807339","pt":1580491502848,"mc":[{"id":"1.168133543","rc":[{"batl":[[0,48,9.2],[1,55,3],[2,1000,3.03]],"ltp":3.7,"tv":44.1,"id":10107355}]}]}
{"op":"mcm","clk":"989807581","pt":1580491505066,"mc":[{"id":"1.168133543","rc":[{"batl":[[0,3.6,1.68],[1,48,9.2],[2,55,3]],"ltp":3.7,"tv":44.1,"id":10107355}]}]}
{"op":"mcm","clk":"989807724","pt":1580491506269,"mc":[{"id":"1.168133543","rc":[{"batb":[[0,1.78,1.99],[1,1.77,3],[2,1.76,6]],"ltp":5.7,"tv":41.18,"id":12636},{"batb":[[0,3.25,3.31]],"ltp":3.7,"tv":44.1,"id":10107355}]}]}
{"op":"mcm","clk":"989807869","pt":1580491507484,"mc":[{"id":"1.168133543","rc":[{"batb":[[1,1.59,1.04],[2,1.51,3.36]],"ltp":0.0,"tv":0.0,"id":7226819},{"batb":[[0,1.62,1.99],[1,1.61,90]],"ltp":0.0,"tv":0.0,"id":10163711},{"batl":[[0,48,9.2],[1,55,3],[2,1000,3.03]],"ltp":3.7,"tv":44.1,"id":10107355},{"batb":[[0,1.62,1.99],[1,1.61,90]],"ltp":0.0,"tv":0.0,"id":22121325}]}]}
{"op":"mcm","clk":"989807996","pt":1580491508542,"mc":[{"id":"1.168133543","rc":[{"batb":[[0,1.62,1.99],[1,1.61,90],[2,1.59,1.04]],"ltp":0.0,"tv":0.0,"id":7226819},{"batb":[[0,1.62,1.99],[1,1.61,90]],"ltp":0.0,"tv":0.0,"id":26548208},{"batb":[[0,1.62,1.99],[1,1.61,90]],"ltp":0.0,"tv":0.0,"id":13306150}]}]}
{"op":"mcm","clk":"989808062","pt":1580491509060,"mc":[{"id":"1.168133543","rc":[{"batb":[[0,1.62,1.99],[1,1.61,90]],"ltp":0.0,"tv":0.0,"id":22308007},{"batl":[[0,3.55,1.68],[1,48,9.2],[2,55,3]],"ltp":3.7,"tv":44.1,"id":10107355}]}]}
{"op":"mcm","clk":"989808209","pt":1580491510386,"mc":[{"id":"1.168133543","rc":[{"batl":[[0,48,9.2],[1,55,3],[2,1000,3.03]],"ltp":3.7,"tv":44.1,"id":10107355},{"batb":[[0,1.62,1.99],[1,1.61,90]],"ltp":0.0,"tv":0.0,"id":27606066},{"batb":[[0,1.62,1.99],[1,1.61,90]],"ltp":0.0,"tv":0.0,"id":24270700}]}]}
{"op":"mcm","clk":"989808270","pt":1580491510868,"mc":[{"id":"1.168133543","rc":[{"batb":[[0,1.79,23.96],[1,1.78,1.99],[2,1.77,3]],"ltp":5.7,"tv":41.18,"id":12636},{"batl":[[0,3.7,1.68],[1,48,9.2],[2,55,3]],"ltp":3.7,"tv":44.1,"id":10107355}]}]}
{"op":"mcm","clk":"989808422","pt":1580491512560,"mc":[{"id":"1.168133543","rc":[{"batb":[[0,3.2,1.99],[1,3,1.68],[2,1.81,90]],"batl":[[1,3.8,1.68],[2,48,9.2]],"ltp":3.7,"tv":44.1,"id":10107355}]}]}
{"op":"mcm","clk":"989808512","pt":1580491513557,"mc":[{"id":"1.168133543","rc":[{"batb":[[0,1.8,3],[1,1.79,23.96],[2,1.78,1.99]],"ltp":5.7,"tv":41.18,"id":12636},{"batb":[[0,3.3,3.31],[1,3.2,1.68],[2,3,1.68]],"batl":[[1,3.8,3.36],[2,5.7,9]],"ltp":3.7,"tv":44.1,"id":10107355}]}]}
{"op":"mcm","clk":"989809825","pt":1580491527132,"mc":[{"id":"1.168133543","rc":[{"batb":[[0,3.35,3],[1,3.2,1.99]],"ltp":3.7,"tv":44.1,"id":10107355}]}]}
{"op":"mcm","clk":"989810203","pt":1580491530937,"mc":[{"id":"1.168133543","rc":[{"batb":[[1,1.78,1.99],[2,1.76,6]],"ltp":5.7,"tv":41.18,"id":12636}]}]}
{"op":"mcm","clk":"989810642","pt":1580491535237,"mc":[{"id":"1.168133543","rc":[{"batb":[[2,1.81,90]],"ltp":3.7,"tv":44.1,"id":10107355}]}]}
{"op":"mcm","clk":"989810713","pt":1580491535961,"mc":[{"id":"1.168133543","rc":[{"batb":[[1,1.81,90.31],[2,1.59,3.33]],"ltp":3.7,"tv":44.1,"id":10107355}]}]}
{"op":"mcm","clk":"989810873","pt":1580491537585,"mc":[{"id":"1.168133543","rc":[{"trd":[[3.35,3.36]],"batb":[[0,3.35,1.32]],"ltp":3.35,"tv":47.46,"id":10107355}],"tv":89.04}]}
{"op":"mcm","clk":"989811061","pt":1580491539267,"mc":[{"id":"1.168133543","rc":[{"batb":[[0,1.78,1.99],[1,1.77,3]],"ltp":5.7,"tv":41.18,"id":12636},{"trd":[[3.35,6]],"batb":[[0,1.81,90.31],[1,1.59,3.33],[2,1.54,10]],"batl":[[0,3.7,2.04]],"ltp":3.35,"tv":50.1,"id":10107355}],"tv":91.68}]}
{"op":"mcm","clk":"989811168","pt":1580491540265,"mc":[{"id":"1.168133543","rc":[{"batl":[[0,3.7,1.68]],"ltp":3.35,"tv":50.1,"id":10107355}]}]}
{"op":"mcm","clk":"989812160","pt":1580491550483,"mc":[{"id":"1.168133543","rc":[{"batb":[[0,1.79,23.96],[1,1.78,1.99],[2,1.77,3]],"ltp":5.7,"tv":41.18,"id":12636}]}]}
{"op":"mcm","clk":"989812191","pt":1580491550757,"mc":[{"id":"1.168133543","rc":[{"batb":[[1,1.78,4.99],[2,1.76,6]],"ltp":5.7,"tv":41.18,"id":12636}]}]}
{"op":"mcm","clk":"989813542","pt":1580491563574,"mc":[{"id":"1.168133543","rc":[{"batb":[[1,1.78,1.99]],"ltp":5.7,"tv":41.18,"id":12636}]}]}
{"op":"mcm","clk":"989813559","pt":1580491563679,"mc":[{"id":"1.168133543","rc":[{"batb":[[0,1.8,3],[1,1.79,23.96],[2,1.78,1.99]],"ltp":5.7,"tv":41.18,"id":12636}]}]}
{"op":"mcm","clk":"989814252","pt":1580491570396,"mc":[{"id":"1.168133543","rc":[{"batb":[[1,1.78,1.99],[2,1.76,6]],"ltp":5.7,"tv":41.18,"id":12636}]}]}
{"op":"mcm","clk":"989815317","pt":1580491580510,"mc":[{"id":"1.168133543","rc":[{"batb":[[0,1.78,1.99],[1,1.76,6],[2,1.75,90]],"ltp":5.7,"tv":41.18,"id":12636}]}]}
{"op":"mcm","clk":"989815394","pt":1580491581240,"mc":[{"id":"1.168133543","rc":[{"batb":[[1,1.77,3],[2,1.76,6]],"ltp":5.7,"tv":41.18,"id":12636}]}]}
{"op":"mcm","clk":"989816274","pt":1580491589613,"mc":[{"id":"1.168133543","rc":[{"batb":[[0,1.79,23.96],[1,1.78,1.99],[2,1.77,3]],"ltp":5.7,"tv":41.18,"id":12636}]}]}
{"op":"mcm","clk":"989816549","pt":1580491592236,"mc":[{"id":"1.168133543","rc":[{"batb":[[0,1.8,3],[1,1.79,23.96],[2,1.78,1.99]],"ltp":5.7,"tv":41.18,"id":12636}]}]}
{"op":"mcm","clk":"989818276","pt":1580491609049,"mc":[{"id":"1.168133543","rc":[{"batb":[[1,1.78,1.99],[2,1.76,6]],"ltp":5.7,"tv":41.18,"id":12636}]}]}
{"op":"mcm","clk":"989818646","pt":1580491612249,"mc":[{"id":"1.168133543","rc":[{"batb":[[0,1.78,1.99],[1,1.77,3]],"ltp":5.7,"tv":41.18,"id":12636}]}]}
{"op":"mcm","clk":"989819772","pt":1580491622949,"mc":[{"id":"1.168133543","rc":[{"batb":[[0,1.78,4.99],[1,1.76,6],[2,1.75,90]],"ltp":5.7,"tv":41.18,"id":12636}]}]}
{"op":"mcm","clk":"989820998","pt":1580491634501,"mc":[{"id":"1.168133543","rc":[{"batb":[[0,1.78,1.99]],"ltp":5.7,"tv":41.18,"id":12636}]}]}
{"op":"mcm","clk":"989821010","pt":1580491634603,"mc":[{"id":"1.168133543","rc":[{"batb":[[0,1.79,3],[1,1.78,1.99],[2,1.76,6]],"ltp":5.7,"tv":41.18,"id":12636}]}]}
{"op":"mcm","clk":"989821440","pt":1580491638811,"mc":[{"id":"1.168133543","rc":[{"batl":[[0,3.7,1.86]],"ltp":3.35,"tv":50.1,"id":10107355}]}]}
{"op":"mcm","clk":"989822164","pt":1580491645848,"mc":[{"id":"1.168133543","rc":[{"batb":[[0,1.78,1.99],[1,1.77,3]],"ltp":5.7,"tv":41.18,"id":12636}]}]}
{"op":"mcm","clk":"989822412","pt":1580491648423,"mc":[{"id":"1.168133543","rc":[{"batb":[[0,1.79,23.96],[1,1.78,1.99],[2,1.77,3]],"ltp":5.7,"tv":41.18,"id":12636}]}]}
{"op":"mcm","clk":"989824003","pt":1580491664452,"mc":[{"id":"1.168133543","rc":[{"batb":[[0,1.8,3],[1,1.79,23.96],[2,1.78,1.99]],"ltp":5.7,"tv":41.18,"id":12636}]}]}
{"op":"mcm","clk":"989824413","pt":1580491668177,"mc":[{"id":"1.168133543","rc":[{"batb":[[1,1.78,1.99],[2,1.76,6]],"ltp":5.7,"tv":41.18,"id":12636}]}]}
{"op":"mcm","clk":"989825208","pt":1580491675463,"mc":[{"id":"1.168133543","rc":[{"batb":[[1,1.79,10],[2,1.78,1.99]],"ltp":5.7,"tv":41.18,"id":12636},{"batb":[[0,1.82,10.31],[1,1.81,90],[2,1.59,3.33]],"ltp":3.35,"tv":50.1,"id":10107355}]}]}
{"op":"mcm","clk":"989825442","pt":1580491677565,"mc":[{"id":"1.168133543","rc":[{"batb":[[0,1.83,3.03],[1,1.82,10.31],[2,1.81,90]],"batl":[[1,3.75,3.03],[2,3.8,3.36]],"ltp":3.35,"tv":50.1,"id":10107355}]}]}
{"op":"mcm","clk":"989825562","pt":1580491678574,"mc":[{"id":"1.168133543","rc":[{"batb":[[0,1.8,8.25]],"batl":[[0,4.7,5.59]],"ltp":5.7,"tv":41.18,"id":12636},{"batb":[[0,1.62,17.62]],"batl":[[0,940,3.23],[1,950,9]],"ltp":0.0,"tv":0.0,"id":10163711}]}]}
{"op":"mcm","clk":"989825688","pt":1580491679559,"mc":[{"id":"1.168133543","rc":[{"batb":[[0,1.62,17.62]],"ltp":0.0,"tv":0.0,"id":7226819},{"batb":[[0,1.62,17.62]],"batl":[[0,940,3.23],[1,950,9]],"ltp":0.0,"tv":0.0,"id":22121325}]}]}
{"op":"mcm","clk":"989825814","pt":1580491680475,"mc":[{"id":"1.168133543","rc":[{"batl":[[0,940,3.03]],"ltp":0.0,"tv":0.0,"id":10163711},{"batl":[[0,940,3.03]],"ltp":0.0,"tv":0.0,"id":22121325}]}]}
{"op":"mcm","clk":"989825957","pt":1580491681400,"mc":[{"id":"1.168133543","rc":[{"batl":[[0,940,3.23]],"ltp":0.0,"tv":0.0,"id":10163711},{"batl":[[0,940,3.23]],"ltp":0.0,"tv":0.0,"id":22121325}]}]}
{"op":"mcm","clk":"989826813","pt":1580491688487,"mc":[{"id":"1.168133543","rc":[{"batb":[[0,1.81,23.7],[1,1.8,8.25],[2,1.79,10]],"ltp":5.7,"tv":41.18,"id":12636},{"batb":[[0,1.64,90],[1,1.62,17.62]],"ltp":0.0,"tv":0.0,"id":7226819},{"batb":[[0,1.64,90],[1,1.62,17.62]],"ltp":0.0,"tv":0.0,"id":10163711},{"batb":[[0,1.84,23.31],[1,1.83,3.03],[2,1.82,10.31]],"ltp":3.35,"tv":50.1,"id":10107355},{"batb":[[0,1.64,90],[1,1.62,17.62]],"ltp":0.0,"tv":0.0,"id":22121325}]}]}
{"op":"mcm","clk":"989826886","pt":1580491689220,"mc":[{"id":"1.168133543","rc":[{"batb":[[0,1.82,3],[1,1.81,23.7],[2,1.8,5.25]],"ltp":5.7,"tv":41.18,"id":12636},{"batl":[[0,920,9],[1,940,3.23]],"ltp":0.0,"tv":0.0,"id":10163711},{"batl":[[0,920,9],[1,940,3.23]],"ltp":0.0,"tv":0.0,"id":22121325}]}]}
{"op":"mcm","clk":"989827779","pt":1580491697516,"mc":[{"id":"1.168133543","rc":[{"batl":[[0,920,9.2],[1,940,3.03]],"ltp":0.0,"tv":0.0,"id":10163711},{"batl":[[0,920,9.2],[1,940,3.03]],"ltp":0.0,"tv":0.0,"id":22121325}]}]}
{"op":"mcm","clk":"989828778","pt":1580491707536,"mc":[{"id":"1.168133543","rc":[{"batb":[[2,1.51,3.36]],"ltp":0.0,"tv":0.0,"id":7226819},{"batb":[[2,1.51,3.36]],"ltp":0.0,"tv":0.0,"id":10163711},{"batb":[[2,1.51,3.36]],"ltp":0.0,"tv":0.0,"id":22121325}]}]}
{"op":"mcm","clk":"989828794","pt":1580491707744,"mc":[{"id":"1.168133543","rc":[{"batb":[[1,1.8,5.25],[2,1.79,10]],"ltp":5.7,"tv":41.18,"id":12636}]}]}
{"op":"mcm","clk":"989829388","pt":1580491714538,"mc":[{"id":"1.168133543","rc":[{"batb":[[0,1.81,3]],"ltp":5.7,"tv":41.18,"id":12636}]}]}
{"op":"mcm","clk":"989830660","pt":1580491727970,"mc":[{"id":"1.168133543","rc":[{"batb":[[0,1.82,23.56],[1,1.81,3],[2,1.8,5.25]],"ltp":5.7,"tv":41.18,"id":12636}]}]}
{"op":"mcm","clk":"989831573","pt":1580491736478,"mc":[{"id":"1.168133543","rc":[{"batb":[[0,1.84,23.62],[2,1.82,10]],"ltp":3.35,"tv":50.1,"id":10107355}]}]}
{"op":"mcm","clk":"989831676","pt":1580491737408,"mc":[{"id":"1.168133543","rc":[{"batb":[[0,1.83,1.99],[1,1.82,23.56],[2,1.81,3]],"ltp":5.7,"tv":41.18,"id":12636},{"batb":[[0,1.65,1.99],[1,1.64,90],[2,1.62,15.63]],"ltp":0.0,"tv":0.0,"id":10163711},{"batb":[[0,1.65,1.99],[1,1.64,90],[2,1.62,15.63]],"ltp":0.0,"tv":0.0,"id":22121325}]}]}
{"op":"mcm","clk":"989831781","pt":1580491738302,"mc":[{"id":"1.168133543","rc":[{"batb":[[0,1.83,4.99],[2,1.8,5.25]],"ltp":5.7,"tv":41.18,"id":12636},{"batb":[[0,1.65,1.99],[1,1.64,90],[2,1.62,15.63]],"ltp":0.0,"tv":0.0,"id":7226819}]}]}
{"op":"mcm","clk":"989831874","pt":1580491739282,"mc":[{"id":"1.168133543","rc":[{"batb":[[2,1.81,90]],"ltp":3.35,"tv":50.1,"id":10107355}]}]}
{"op":"mcm","clk":"989832367","pt":1580491744518,"mc":[{"id":"1.168133543","rc":[{"batb":[[2,1.82,6]],"ltp":3.35,"tv":50.1,"id":10107355}]}]}
{"op":"mcm","clk":"989832669","pt":1580491747320,"mc":[{"id":"1.168133543","rc":[{"batb":[[1,1.8,5.25],[2,1.76,6]],"ltp":5.7,"tv":41.18,"id":12636}]}]}
{"op":"mcm","clk":"989833319","pt":1580491753306,"mc":[{"id":"1.168133543","rc":[{"batb":[[0,1.84,3],[1,1.83,1.99],[2,1.8,5.25]],"ltp":5.7,"tv":41.18,"id":12636}]}]}
{"op":"mcm","clk":"989834668","pt":1580491766544,"mc":[{"id":"1.168133543","rc":[{"batb":[[0,1.83,1.99],[1,1.81,3]],"ltp":5.7,"tv":41.18,"id":12636}]}]}
{"op":"mcm","clk":"989835832","pt":1580491777949,"mc":[{"id":"1.168133543","rc":[{"batb":[[1,1.82,3]],"ltp":5.7,"tv":41.18,"id":12636}]}]}
{"op":"mcm","clk":"989836232","pt":1580491781430,"mc":[{"id":"1.168133543","rc":[{"batl":[[0,3.55,5],[1,3.7,1.86],[2,3.75,3.03]],"ltp":3.35,"tv":50.1,"id":10107355}]}]}
{"op":"mcm","clk":"989836737","pt":1580491786252,"mc":[{"id":"1.168133543","rc":[{"batb":[[0,1.84,23.31],[1,1.83,1.99],[2,1.82,3]],"ltp":5.7,"tv":41.18,"id":12636}]}]}
{"op":"mcm","clk":"989836984","pt":1580491788533,"mc":[{"id":"1.168133543","rc":[{"batb":[[2,1.8,5.25]],"ltp":5.7,"tv":41.18,"id":12636}]}]}
{"op":"mcm","clk":"989837053","pt":1580491789154,"mc":[{"id":"1.168133543","rc":[{"batb":[[0,1.85,3],[1,1.84,23.31],[2,1.83,1.99]],"ltp":5.7,"tv":41.18,"id":12636}]}]}
{"op":"mcm","clk":"989838531","pt":1580491802778,"mc":[{"id":"1.168133543","rc":[{"batl":[[0,4.7,3.59]],"ltp":5.7,"tv":41.18,"id":12636},{"batl":[[0,3.5,2],[1,3.55,5],[2,3.7,1.86]],"ltp":3.35,"tv":50.1,"id":10107355}]}]}
{"op":"mcm","clk":"989838874","pt":1580491805569,"mc":[{"id":"1.168133543","rc":[{"batb":[[1,1.83,1.99],[2,1.8,5.25]],"ltp":5.7,"tv":41.18,"id":12636}]}]}
{"op":"mcm","clk":"989839660","pt":1580491812377,"mc":[{"id":"1.168133543","rc":[{"batb":[[0,1.83,1.99],[1,1.81,3]],"ltp":5.7,"tv":41.18,"id":12636}]}]}
{"op":"mcm","clk":"989840840","pt":1580491820504,"mc":[{"id":"1.168133543","rc":[{"batl":[[0,3.4,5],[1,3.5,2]],"ltp":3.35,"tv":50.1,"id":10107355}]}]}
{"op":"mcm","clk":"989841293","pt":1580491824215,"mc":[{"id":"1.168133543","rc":[{"batb":[[1,1.82,3]],"ltp":5.7,"tv":41.18,"id":12636}]}]}
{"op":"mcm","clk":"989841458","pt":1580491825304,"mc":[{"id":"1.168133543","rc":[{"batb":[[0,1.84,23.31],[1,1.83,1.99],[2,1.82,3]],"ltp":5.7,"tv":41.18,"id":12636}]}]}
{"op":"mcm","clk":"989842735","pt":1580491834204,"mc":[{"id":"1.168133543","rc":[{"batb":[[0,1.85,3],[1,1.84,23.31],[2,1.83,1.99]],"ltp":5.7,"tv":41.18,"id":12636}]}]}
{"op":"mcm","clk":"989843557","pt":1580491840451,"mc":[{"id":"1.168133543","rc":[{"batb":[[0,1.86,1.99],[1,1.85,3],[2,1.84,23.31]],"ltp":5.7,"tv":41.18,"id":12636}]}]}
{"op":"mcm","clk":"989844174","pt":1580491845337,"mc":[{"id":"1.168133543","rc":[{"batb":[[2,1.8,5.25]],"ltp":5.7,"tv":41.18,"id":12636}]}]}
{"op":"mcm","clk":"989844202","pt":1580491845643,"mc":[{"id":"1.168133543","rc":[{"batb":[[0,1.87,22.93],[1,1.86,1.99],[2,1.85,3]],"ltp":5.7,"tv":41.18,"id":12636}]}]}
{"op":"mcm","clk":"989844598","pt":1580491848956,"mc":[{"id":"1.168133543","rc":[{"batb":[[0,1.88,3],[1,1.87,22.93],[2,1.86,1.99]],"ltp":5.7,"tv":41.18,"id":12636}]}]}
{"op":"mcm","clk":"989846764","pt":1580491865342,"mc":[{"id":"1.168133543","rc":[{"batb":[[1,1.86,1.99],[2,1.8,5.25]],"ltp":5.7,"tv":41.18,"id":12636}]}]}
{"op":"mcm","clk":"989846889","pt":1580491866130,"mc":[{"id":"1.168133543","rc":[{"batb":[[0,1.89,22.69],[1,1.88,3],[2,1.86,1.99]],"ltp":5.7,"tv":41.18,"id":12636}]}]}
{"op":"mcm","clk":"989847347","pt":1580491868786,"mc":[{"id":"1.168133543","rc":[{"batl":[[0,3.35,2],[1,3.4,5]],"ltp":3.35,"tv":50.1,"id":10107355}]}]}
{"op":"mcm","clk":"989847611","pt":1580491870574,"mc":[{"id":"1.168133543","rc":[{"batb":[[0,1.9,3],[1,1.89,22.69]],"ltp":5.7,"tv":41.18,"id":12636}]}]}
{"op":"mcm","clk":"989849709","pt":1580491885482,"mc":[{"id":"1.168133543","rc":[{"batb":[[1,1.86,1.99],[2,1.8,5.25]],"ltp":5.7,"tv":41.18,"id":12636}]}]}
{"op":"mcm","clk":"989850248","pt":1580491889906,"mc":[{"id":"1.168133543","rc":[{"batb":[[0,1.86,1.99],[1,1.81,3]],"ltp":5.7,"tv":41.18,"id":12636}]}]}
{"op":"mcm","clk":"989851882","pt":1580491903451,"mc":[{"id":"1.168133543","rc":[{"batb":[[1,1.82,3]],"ltp":5.7,"tv":41.18,"id":12636}]}]}
{"op":"mcm","clk":"989853055","pt":1580491912874,"mc":[{"id":"1.168133543","rc":[{"batb":[[1,1.83,3]],"ltp":5.7,"tv":41.18,"id":12636}]}]}
{"op":"mcm","clk":"989854729","pt":1580491923992,"mc":[{"id":"1.168133543","rc":[{"batb":[[1,1.84,3]],"ltp":5.7,"tv":41.18,"id":12636}]}]}
{"op":"mcm","clk":"989855968","pt":1580491933195,"mc":[{"id":"1.168133543","rc":[{"batb":[[0,1.85,1.99]],"ltp":5.7,"tv":41.18,"id":12636}]}]}
{"op":"mcm","clk":"989856558","pt":1580491936507,"mc":[{"id":"1.168133543","rc":[{"batb":[[1,1.8,5.25],[2,1.76,6]],"ltp":5.7,"tv":41.18,"id":12636}]}]}
{"op":"mcm","clk":"989856674","pt":1580491937203,"mc":[{"id":"1.168133543","rc":[{"batb":[[0,1.85,4.99]],"ltp":5.7,"tv":41.18,"id":12636}]}]}
{"op":"mcm","clk":"989858069","pt":1580491947524,"mc":[{"id":"1.168133543","rc":[{"batb":[[0,1.86,3],[1,1.85,1.99],[2,1.8,5.25]],"ltp":5.7,"tv":41.18,"id":12636}]}]}
{"op":"mcm","clk":"989859645","pt":1580491960231,"mc":[{"id":"1.168133543","rc":[{"batb":[[0,1.85,1.99],[1,1.81,3]],"ltp":5.7,"tv":41.18,"id":12636}]}]}
{"op":"mcm","clk":"989860809","pt":1580491970565,"mc":[{"id":"1.168133543","rc":[{"batb":[[1,1.82,3]],"ltp":5.7,"tv":41.18,"id":12636}]}]}
{"op":"mcm","clk":"989862416","pt":1580491983559,"mc":[{"id":"1.168133543","rc":[{"batb":[[1,1.8,5.25],[2,1.76,6]],"ltp":5.7,"tv":41.18,"id":12636}]}]}
{"op":"mcm","clk":"989862503","pt":1580491984481,"mc":[{"id":"1.168133543","rc":[{"batb":[[1,1.83,3],[2,1.8,5.25]],"ltp":5.7,"tv":41.18,"id":12636}]}]}
{"op":"mcm","clk":"989863756","pt":1580491995482,"mc":[{"id":"1.168133543","rc":[{"batb":[[1,1.8,5.25],[2,1.76,6]],"ltp":5.7,"tv":41.18,"id":12636}]}]}
{"op":"mcm","clk":"989863873","pt":1580491996483,"mc":[{"id":"1.168133543","rc":[{"batb":[[1,1.84,3],[2,1.8,5.25]],"ltp":5.7,"tv":41.18,"id":12636}]}]}
{"op":"mcm","clk":"989864404","pt":1580492001569,"mc":[{"id":"1.168133543","rc":[{"batb":[[0,1.86,23.06],[1,1.85,1.99],[2,1.84,3]],"ltp":5.7,"tv":41.18,"id":12636}]}]}
{"op":"mcm","clk":"989865279","pt":1580492007375,"mc":[{"id":"1.168133543","rc":[{"batb":[[0,1.87,3],[1,1.86,23.06],[2,1.85,1.99]],"ltp":5.7,"tv":41.18,"id":12636}]}]}
{"op":"mcm","clk":"989866992","pt":1580492020813,"mc":[{"id":"1.168133543","rc":[{"batb":[[1,1.85,1.99],[2,1.8,5.25]],"ltp":5.7,"tv":41.18,"id":12636}]}]}
{"op":"mcm","clk":"989867513","pt":1580492024400,"mc":[{"id":"1.168133543","rc":[{"batb":[[0,1.85,1.99],[1,1.81,3]],"ltp":5.7,"tv":41.18,"id":12636}]}]}
{"op":"mcm","clk":"989868465","pt":1580492029522,"mc":[{"id":"1.168133543","rc":[{"batb":[[0,1.82,1.99]],"ltp":5.7,"tv":41.18,"id":12636}]}]}
{"op":"mcm","clk":"989869211","pt":1580492034812,"mc":[{"id":"1.168133543","rc":[{"batb":[[0,1.82,4.99],[1,1.8,5.25],[2,1.76,6]],"ltp":5.7,"tv":41.18,"id":12636}]}]}
{"op":"mcm","clk":"989870895","pt":1580492047519,"mc":[{"id":"1.168133543","rc":[{"batb":[[0,1.82,1.99]],"ltp":5.7,"tv":41.18,"id":12636}]}]}
{"op":"mcm","clk":"989870987","pt":1580492048213,"mc":[{"id":"1.168133543","rc":[{"batb":[[0,1.83,3],[1,1.82,1.99],[2,1.8,5.25]],"ltp":5.7,"tv":41.18,"id":12636}]}]}
{"op":"mcm","clk":"989872447","pt":1580492059521,"mc":[{"id":"1.168133543","rc":[{"batb":[[0,1.84,23.31],[2,1.81,3]],"ltp":5.7,"tv":41.18,"id":12636}]}]}
{"op":"mcm","clk":"989872507","pt":1580492060042,"mc":[{"id":"1.168133543","rc":[{"batl":[[0,4.6,2],[1,4.7,3.59],[2,4.8,1.68]],"ltp":5.7,"tv":41.18,"id":12636},{"batl":[[0,3.4,5],[1,3.7,1.86],[2,3.75,3.03]],"ltp":3.35,"tv":50.1,"id":10107355}]}]}
{"op":"mcm","clk":"989874234","pt":1580492073254,"mc":[{"id":"1.168133543","rc":[{"batb":[[0,1.85,3],[1,1.84,23.31],[2,1.82,1.99]],"ltp":5.7,"tv":41.18,"id":12636}]}]}
{"op":"mcm","clk":"989874986","pt":1580492078938,"mc":[{"id":"1.168133543","rc":[{"batb":[[1,1.82,1.99],[2,1.8,5.25]],"ltp":5.7,"tv":41.18,"id":12636}]}]}
{"op":"mcm","clk":"989875635","pt":1580492084451,"mc":[{"id":"1.168133543","rc":[{"batb":[[0,1.82,1.99],[1,1.81,3]],"ltp":5.7,"tv":41.18,"id":12636}]}]}
{"op":"mcm","clk":"989876987","pt":1580492095458,"mc":[{"id":"1.168133543","rc":[{"batb":[[0,1.82,4.99],[1,1.8,5.25],[2,1.76,6]],"ltp":5.7,"tv":41.18,"id":12636}]}]}
{"op":"mcm","clk":"989878280","pt":1580492105481,"mc":[{"id":"1.168133543","rc":[{"batb":[[0,1.83,3],[1,1.82,1.99],[2,1.8,5.25]],"ltp":5.7,"tv":41.18,"id":12636}]}]}
{"op":"mcm","clk":"989879591","pt":1580492116092,"mc":[{"id":"1.168133543","rc":[{"batb":[[0,1.82,1.99],[1,1.81,3]],"ltp":5.7,"tv":41.18,"id":12636}]}]}
{"op":"mcm","clk":"989879915","pt":1580492118425,"mc":[{"id":"1.168133543","rc":[{"batb":[[0,1.83,23.44],[1,1.82,1.99],[2,1.81,3]],"ltp":5.7,"tv":41.18,"id":12636}]}]}
{"op":"mcm","clk":"989880820","pt":1580492125738,"mc":[{"id":"1.168133543","rc":[{"batb":[[0,1.84,3],[1,1.83,23.44],[2,1.82,1.99]],"ltp":5.7,"tv":41.18,"id":12636}]}]}
{"op":"mcm","clk":"989881652","pt":1580492132264,"mc":[{"id":"1.168133543","rc":[{"batb":[[0,1.85,1.99],[1,1.84,3],[2,1.83,23.44]],"ltp":5.7,"tv":41.18,"id":12636}]}]}
{"op":"mcm","clk":"989882322","pt":1580492137189,"mc":[{"id":"1.168133543","rc":[{"batb":[[0,1.85,4.99],[1,1.83,23.44],[2,1.8,5.25]],"ltp":5.7,"tv":41.18,"id":12636}]}]}
{"op":"mcm","clk":"989882499","pt":1580492138469,"mc":[{"id":"1.168133543","rc":[{"batb":[[1,1.8,5.25],[2,1.76,6]],"ltp":5.7,"tv":41.18,"id":12636}]}]}
{"op":"mcm","clk":"989883767","pt":1580492148556,"mc":[{"id":"1.168133543","rc":[{"batb":[[0,1.86,3],[1,1.85,1.99],[2,1.8,5.25]],"ltp":5.7,"tv":41.18,"id":12636}]}]}
{"op":"mcm","clk":"989884951","pt":1580492157304,"mc":[{"id":"1.168133543","rc":[{"batb":[[0,1.87,22.93],[1,1.86,3],[2,1.85,1.99]],"ltp":5.7,"tv":41.18,"id":12636}]}]}
{"op":"mcm","clk":"989885258","pt":1580492159491,"mc":[{"id":"1.168133543","rc":[{"batb":[[1,1.85,1.99],[2,1.8,5.25]],"ltp":5.7,"tv":41.18,"id":12636}]}]}
{"op":"mcm","clk":"989885313","pt":1580492159922,"mc":[{"id":"1.168133543","rc":[{"batb":[[0,1.88,3],[1,1.87,22.93],[2,1.85,1.99]],"ltp":5.7,"tv":41.18,"id":12636}]}]}
{"op":"mcm","clk":"989885689","pt":1580492162533,"mc":[{"id":"1.168133543","rc":[{"batb":[[0,1.85,3.34],[1,1.84,23.31]],"batl":[[2,3.8,3.36]],"ltp":3.35,"tv":50.1,"id":10107355}]}]}
{"op":"mcm","clk":"989885798","pt":1580492163526,"mc":[{"id":"1.168133543","rc":[{"batb":[[0,1.88,8.03]],"ltp":5.7,"tv":41.18,"id":12636},{"batb":[[0,1.65,17.34],[2,1.51,3.36]],"batl":[[1,940,0]],"ltp":0.0,"tv":0.0,"id":10163711},{"batl":[[0,3.35,3.03],[1,3.4,5],[2,3.7,1.86]],"ltp":3.35,"tv":50.1,"id":10107355}]}]}
{"op":"mcm","clk":"989885930","pt":1580492164424,"mc":[{"id":"1.168133543","rc":[{"batb":[[0,1.65,17.34],[2,1.51,3.36]],"ltp":0.0,"tv":0.0,"id":7226819},{"batl":[[0,910,3.23],[1,920,9]],"ltp":0.0,"tv":0.0,"id":10163711},{"batb":[[0,1.65,17.34],[2,1.51,3.36]],"batl":[[0,910,3.23],[1,920,9]],"ltp":0.0,"tv":0.0,"id":22121325}]}]}
{"op":"mcm","clk":"989886955","pt":1580492171852,"mc":[{"id":"1.168133543","rc":[{"batb":[[0,1.89,3],[1,1.88,5.03],[2,1.87,22.93]],"ltp":5.7,"tv":41.18,"id":12636}]}]}
{"op":"mcm","clk":"989887624","pt":1580492177131,"mc":[{"id":"1.168133543","rc":[{"batb":[[0,1.9,22.57],[1,1.89,3],[2,1.88,5.03]],"ltp":5.7,"tv":41.18,"id":12636},{"batb":[[1,1.82,6],[2,1.81,90]],"ltp":3.35,"tv":50.1,"id":10107355}]}]}
{"op":"mcm","clk":"989888659","pt":1580492185142,"mc":[{"id":"1.168133543","rc":[{"batb":[[0,1.91,3],[1,1.9,22.57]],"ltp":5.7,"tv":41.18,"id":12636}]}]}
{"op":"mcm","clk":"989889014","pt":1580492187467,"mc":[{"id":"1.168133543","rc":[{"batl":[[0,4.7,3.59],[1,4.8,1.68],[2,5,1.68]],"ltp":5.7,"tv":41.18,"id":12636}]}]}
{"op":"mcm","clk":"989889096","pt":1580492188064,"mc":[{"id":"1.168133543","rc":[{"batl":[[0,3.3,2],[1,3.35,3.03],[2,3.4,5]],"ltp":3.35,"tv":50.1,"id":10107355}]}]}
{"op":"mcm","clk":"989889718","pt":1580492192367,"mc":[{"id":"1.168133543","rc":[{"batb":[[0,1.67,90],[1,1.65,17.34]],"ltp":0.0,"tv":0.0,"id":7226819},{"batb":[[0,1.67,90],[1,1.65,17.34]],"ltp":0.0,"tv":0.0,"id":10163711},{"batb":[[0,1.67,90],[1,1.65,17.34]],"ltp":0.0,"tv":0.0,"id":22121325}]}]}
{"op":"mcm","clk":"989889792","pt":1580492192955,"mc":[{"id":"1.168133543","rc":[{"batl":[[0,890,9],[1,910,3.23]],"ltp":0.0,"tv":0.0,"id":10163711},{"batl":[[0,890,9],[1,910,3.23]],"ltp":0.0,"tv":0.0,"id":22121325}]}]}
{"op":"mcm","clk":"989890230","pt":1580492196554,"mc":[{"id":"1.168133543","rc":[{"batb":[[1,1.88,5.03],[2,1.85,1.99]],"ltp":5.7,"tv":41.18,"id":12636}]}]}
{"op":"mcm","clk":"989890800","pt":1580492201179,"mc":[{"id":"1.168133543","rc":[{"batb":[[0,1.89,3]],"ltp":5.7,"tv":41.18,"id":12636}]}]}
{"op":"mcm","clk":"989891412","pt":1580492206246,"mc":[{"id":"1.168133543","rc":[{"batb":[[1,1.83,3],[2,1.82,6]],"ltp":3.35,"tv":50.1,"id":10107355}]}]}
{"op":"mcm","clk":"989892581","pt":1580492216220,"mc":[{"id":"1.168133543","rc":[{"batb":[[0,1.9,22.57],[1,1.89,3],[2,1.88,5.03]],"ltp":5.7,"tv":41.18,"id":12636}]}]}
{"op":"mcm","clk":"989893799","pt":1580492226269,"mc":[{"id":"1.168133543","rc":[{"batb":[[0,1.91,3],[1,1.9,22.57]],"ltp":5.7,"tv":41.18,"id":12636}]}]}
{"op":"mcm","clk":"989894889","pt":1580492235884,"mc":[{"id":"1.168133543","rc":[{"batb":[[1,1.88,5.03],[2,1.85,1.99]],"ltp":5.7,"tv":41.18,"id":12636}]}]}
{"op":"mcm","clk":"989895201","pt":1580492238562,"mc":[{"id":"1.168133543","rc":[{"batb":[[0,1.92,1.99],[1,1.91,3],[2,1.88,5.03]],"ltp":5.7,"tv":41.18,"id":12636},{"batb":[[0,1.68,1.99],[1,1.67,90],[2,1.65,15.35]],"ltp":0.0,"tv":0.0,"id":10163711}]}]}
{"op":"mcm","clk":"989895273","pt":1580492239284,"mc":[{"id":"1.168133543","rc":[{"batb":[[0,1.68,1.99],[1,1.67,90],[2,1.65,15.35]],"ltp":0.0,"tv":0.0,"id":7226819},{"batb":[[0,1.68,1.99],[1,1.67,90],[2,1.65,15.35]],"ltp":0.0,"tv":0.0,"id":22121325}]}]}
{"op":"mcm","clk":"989895448","pt":1580492240953,"mc":[{"id":"1.168133543","rc":[{"batb":[[0,1.92,4.99],[1,1.88,5.03],[2,1.76,3]],"ltp":5.7,"tv":41.18,"id":12636}]}]}
{"op":"mcm","clk":"989906806","pt":1580492255366,"mc":[{"id":"1.168133543","rc":[{"batb":[[0,1.93,3],[1,1.92,1.99],[2,1.88,5.03]],"ltp":5.7,"tv":41.18,"id":12636}]}]}
{"op":"mcm","clk":"989908113","pt":1580492266485,"mc":[{"id":"1.168133543","rc":[{"batb":[[0,1.92,1.99],[1,1.89,3]],"ltp":5.7,"tv":41.18,"id":12636}]}]}
{"op":"mcm","clk":"989909762","pt":1580492280188,"mc":[{"id":"1.168133543","rc":[{"batb":[[1,1.9,3]],"ltp":5.7,"tv":41.18,"id":12636}]}]}
{"op":"mcm","clk":"989911382","pt":1580492294234,"mc":[{"id":"1.168133543","rc":[{"batb":[[1,1.91,3]],"ltp":5.7,"tv":41.18,"id":12636}]}]}
{"op":"mcm","clk":"989912795","pt":1580492306979,"mc":[{"id":"1.168133543","rc":[{"batb":[[0,1.92,4.99],[1,1.88,5.03],[2,1.76,3]],"ltp":5.7,"tv":41.18,"id":12636}]}]}
{"op":"mcm","clk":"989914389","pt":1580492321181,"mc":[{"id":"1.168133543","rc":[{"batb":[[0,1.93,3],[1,1.92,1.99],[2,1.88,5.03]],"ltp":5.7,"tv":41.18,"id":12636}]}]}
{"op":"mcm","clk":"989915950","pt":1580492335032,"mc":[{"id":"1.168133543","rc":[{"batb":[[0,1.94,22.11],[2,1.89,3]],"ltp":5.7,"tv":41.18,"id":12636}]}]}
{"op":"mcm","clk":"989917352","pt":1580492348006,"mc":[{"id":"1.168133543","rc":[{"batb":[[0,1.95,3],[1,1.94,22.11],[2,1.92,1.99]],"ltp":5.7,"tv":41.18,"id":12636}]}]}
{"op":"mcm","clk":"989917892","pt":1580492353562,"mc":[{"id":"1.168133543","rc":[{"batb":[[2,1.88,5.03]],"ltp":5.7,"tv":41.18,"id":12636}]}]}
{"op":"mcm","clk":"989917907","pt":1580492353668,"mc":[{"id":"1.168133543","rc":[{"batb":[[0,1.96,1.99],[1,1.95,3],[2,1.94,22.11]],"ltp":5.7,"tv":41.18,"id":12636}]}]}
{"op":"mcm","clk":"989918109","pt":1580492355449,"mc":[{"id":"1.168133543","rc":[{"batb":[[2,1.88,5.03]],"ltp":5.7,"tv":41.18,"id":12636}]}]}
{"op":"mcm","clk":"989918115","pt":1580492355579,"mc":[{"id":"1.168133543","rc":[{"batb":[[0,1.97,21.77],[1,1.96,1.99],[2,1.95,3]],"ltp":5.7,"tv":41.18,"id":12636}]}]}
{"op":"mcm","clk":"989918594","pt":1580492360367,"mc":[{"id":"1.168133543","rc":[{"batb":[[0,1.98,3],[1,1.97,21.77],[2,1.96,1.99]],"ltp":5.7,"tv":41.18,"id":12636}]}]}
{"op":"mcm","clk":"989920062","pt":1580492376223,"mc":[{"id":"1.168133543","rc":[{"batb":[[1,1.96,1.99],[2,1.88,5.03]],"ltp":5.7,"tv":41.18,"id":12636}]}]}
{"op":"mcm","clk":"989920921","pt":1580492384564,"mc":[{"id":"1.168133543","rc":[{"batb":[[0,1.96,1.99],[1,1.89,3]],"ltp":5.7,"tv":41.18,"id":12636}]}]}
{"op":"mcm","clk":"989921989","pt":1580492395882,"mc":[{"id":"1.168133543","rc":[{"batb":[[1,1.9,3]],"ltp":5.7,"tv":41.18,"id":12636}]}]}
{"op":"mcm","clk":"989923590","pt":1580492412103,"mc":[{"id":"1.168133543","rc":[{"batb":[[1,1.91,3]],"ltp":5.7,"tv":41.18,"id":12636}]}]}
{"op":"mcm","clk":"989924912","pt":1580492424516,"mc":[{"id":"1.168133543","rc":[{"batb":[[1,1.88,5.03],[2,1.75,90]],"ltp":5.7,"tv":41.18,"id":12636}]}]}
{"op":"mcm","clk":"989924919","pt":1580492424619,"mc":[{"id":"1.168133543","rc":[{"batb":[[1,1.92,3],[2,1.88,5.03]],"ltp":5.7,"tv":41.18,"id":12636}]}]}
{"op":"mcm","clk":"989926083","pt":1580492435564,"mc":[{"id":"1.168133543","rc":[{"batb":[[1,1.93,3]],"ltp":5.7,"tv":41.18,"id":12636}]}]}
{"op":"mcm","clk":"989926695","pt":1580492441097,"mc":[{"id":"1.168133543","rc":[{"batb":[[0,1.94,1.99]],"ltp":5.7,"tv":41.18,"id":12636}]}]}
{"op":"mcm","clk":"989927328","pt":1580492447570,"mc":[{"id":"1.168133543","rc":[{"batb":[[1,1.88,5.03],[2,1.75,90]],"ltp":5.7,"tv":41.18,"id":12636}]}]}
{"op":"mcm","clk":"989927341","pt":1580492447673,"mc":[{"id":"1.168133543","rc":[{"batb":[[0,1.94,4.99]],"ltp":5.7,"tv":41.18,"id":12636}]}]}
{"op":"mcm","clk":"989928574","pt":1580492459021,"mc":[{"id":"1.168133543","rc":[{"batb":[[0,1.95,3],[1,1.94,1.99],[2,1.88,5.03]],"ltp":5.7,"tv":41.18,"id":12636}]}]}
{"op":"mcm","clk":"989929825","pt":1580492471826,"mc":[{"id":"1.168133543","rc":[{"batb":[[0,1.94,1.99],[1,1.89,3]],"ltp":5.7,"tv":41.18,"id":12636}]}]}
{"op":"mcm","clk":"989930921","pt":1580492482366,"mc":[{"id":"1.168133543","rc":[{"batb":[[1,1.88,5.03],[2,1.75,90]],"ltp":5.7,"tv":41.18,"id":12636}]}]}
{"op":"mcm","clk":"989931003","pt":1580492483264,"mc":[{"id":"1.168133543","rc":[{"batb":[[1,1.9,3],[2,1.88,5.03]],"ltp":5.7,"tv":41.18,"id":12636}]}]}
{"op":"mcm","clk":"989932084","pt":1580492494382,"mc":[{"id":"1.168133543","rc":[{"batb":[[1,1.91,3]],"ltp":5.7,"tv":41.18,"id":12636}]}]}
{"op":"mcm","clk":"989933482","pt":1580492508492,"mc":[{"id":"1.168133543","rc":[{"batb":[[1,1.92,3]],"ltp":5.7,"tv":41.18,"id":12636}]}]}
{"op":"mcm","clk":"989934653","pt":1580492520220,"mc":[{"id":"1.168133543","rc":[{"batb":[[1,1.93,3]],"ltp":5.7,"tv":41.18,"id":12636}]}]}
{"op":"mcm","clk":"989936015","pt":1580492533277,"mc":[{"id":"1.168133543","rc":[{"batb":[[0,1.95,21.99],[1,1.94,1.99],[2,1.93,3]],"ltp":5.7,"tv":41.18,"id":12636}]}]}
{"op":"mcm","clk":"989936310","pt":1580492536395,"mc":[{"id":"1.168133543","rc":[{"batb":[[0,1.96,3],[1,1.95,21.99],[2,1.94,1.99]],"ltp":5.7,"tv":41.18,"id":12636}]}]}
{"op":"mcm","clk":"989937987","pt":1580492553301,"mc":[{"id":"1.168133543","rc":[{"batb":[[1,1.94,1.99],[2,1.88,5.03]],"ltp":5.7,"tv":41.18,"id":12636}]}]}
{"op":"mcm","clk":"989939084","pt":1580492565045,"mc":[{"id":"1.168133543","rc":[{"batb":[[0,1.94,1.99],[1,1.89,3]],"ltp":5.7,"tv":41.18,"id":12636}]}]}
{"op":"mcm","clk":"989940718","pt":1580492581714,"mc":[{"id":"1.168133543","rc":[{"batb":[[1,1.9,3]],"ltp":5.7,"tv":41.18,"id":12636}]}]}
{"op":"mcm","clk":"989941885","pt":1580492594260,"mc":[{"id":"1.168133543","rc":[{"batl":[[0,3,22],[1,3.3,2],[2,3.35,3.03]],"ltp":3.35,"tv":50.1,"id":10107355}]}]}
{"op":"mcm","clk":"989942291","pt":1580492598456,"mc":[{"id":"1.168133543","rc":[{"batb":[[1,1.88,5.03],[2,1.75,90]],"ltp":5.7,"tv":41.18,"id":12636}]}]}
{"op":"mcm","clk":"989942354","pt":1580492599141,"mc":[{"id":"1.168133543","rc":[{"batb":[[1,1.91,3],[2,1.88,5.03]],"ltp":5.7,"tv":41.18,"id":12636}]}]}
{"op":"mcm","clk":"989944013","pt":1580492616766,"mc":[{"id":"1.168133543","rc":[{"batb":[[1,1.92,3]],"ltp":5.7,"tv":41.18,"id":12636}]}]}
{"op":"mcm","clk":"989945429","pt":1580492631089,"mc":[{"id":"1.168133543","rc":[{"batb":[[1,1.93,3]],"ltp":5.7,"tv":41.18,"id":12636}]}]}
{"op":"mcm","clk":"989945757","pt":1580492634109,"mc":[{"id":"1.168133543","rc":[{"batb":[[0,1.95,21.99],[1,1.94,1.99],[2,1.93,3]],"ltp":5.7,"tv":41.18,"id":12636}]}]}
{"op":"mcm","clk":"989947133","pt":1580492647241,"mc":[{"id":"1.168133543","rc":[{"batb":[[0,1.96,3],[1,1.95,21.99],[2,1.94,1.99]],"ltp":5.7,"tv":41.18,"id":12636}]}]}
{"op":"mcm","clk":"989947752","pt":1580492653542,"mc":[{"id":"1.168133543","rc":[{"batb":[[1,1.94,1.99],[2,1.88,5.03]],"ltp":5.7,"tv":41.18,"id":12636}]}]}
{"op":"mcm","clk":"989948851","pt":1580492664431,"mc":[{"id":"1.168133543","rc":[{"batb":[[0,1.94,1.99],[1,1.89,3]],"ltp":5.7,"tv":41.18,"id":12636}]}]}
{"op":"mcm","clk":"989950420","pt":1580492679481,"mc":[{"id":"1.168133543","rc":[{"batb":[[1,1.9,3]],"ltp":5.7,"tv":41.18,"id":12636}]}]}
{"op":"mcm","clk":"989952117","pt":1580492696103,"mc":[{"id":"1.168133543","rc":[{"batb":[[1,1.91,3]],"ltp":5.7,"tv":41.18,"id":12636}]}]}
{"op":"mcm","clk":"989953676","pt":1580492709238,"mc":[{"id":"1.168133543","rc":[{"batb":[[1,1.92,3]],"ltp":5.7,"tv":41.18,"id":12636}]}]}
{"op":"mcm","clk":"989955192","pt":1580492723533,"mc":[{"id":"1.168133543","rc":[{"batb":[[1,1.88,5.03],[2,1.75,90]],"ltp":5.7,"tv":41.18,"id":12636}]}]}
{"op":"mcm","clk":"989955200","pt":1580492723632,"mc":[{"id":"1.168133543","rc":[{"batb":[[1,1.93,3],[2,1.88,5.03]],"ltp":5.7,"tv":41.18,"id":12636}]}]}
{"op":"mcm","clk":"989955938","pt":1580492731128,"mc":[{"id":"1.168133543","rc":[{"batb":[[0,1.95,21.99],[1,1.94,1.99],[2,1.93,3]],"ltp":5.7,"tv":41.18,"id":12636}]}]}
{"op":"mcm","clk":"989956676","pt":1580492737886,"mc":[{"id":"1.168133543","rc":[{"batb":[[0,1.96,3],[1,1.95,21.99],[2,1.94,1.99]],"ltp":5.7,"tv":41.18,"id":12636}]}]}
{"op":"mcm","clk":"989958016","pt":1580492751174,"mc":[{"id":"1.168133543","rc":[{"batb":[[1,1.94,1.99],[2,1.88,5.03]],"ltp":5.7,"tv":41.18,"id":12636}]}]}
{"op":"mcm","clk":"989959170","pt":1580492762572,"mc":[{"id":"1.168133543","rc":[{"batb":[[0,1.94,1.99],[1,1.89,3]],"ltp":5.7,"tv":41.18,"id":12636}]}]}
{"op":"mcm","clk":"989960607","pt":1580492774433,"mc":[{"id":"1.168133543","rc":[{"batb":[[1,1.9,3]],"ltp":5.7,"tv":41.18,"id":12636}]}]}
{"op":"mcm","clk":"989962008","pt":1580492788550,"mc":[{"id":"1.168133543","rc":[{"batb":[[1,1.88,5.03],[2,1.75,90]],"ltp":5.7,"tv":41.18,"id":12636}]}]}
{"op":"mcm","clk":"989962020","pt":1580492788657,"mc":[{"id":"1.168133543","rc":[{"batb":[[1,1.91,3],[2,1.88,5.03]],"ltp":5.7,"tv":41.18,"id":12636}]}]}
{"op":"mcm","clk":"989963549","pt":1580492801500,"mc":[{"id":"1.168133543","rc":[{"batb":[[1,1.92,3]],"ltp":5.7,"tv":41.18,"id":12636}]}]}
{"op":"mcm","clk":"989964789","pt":1580492813974,"mc":[{"id":"1.168133543","rc":[{"batb":[[1,1.93,3]],"ltp":5.7,"tv":41.18,"id":12636}]}]}
{"op":"mcm","clk":"989966669","pt":1580492828630,"mc":[{"id":"1.168133543","rc":[{"batb":[[0,1.95,21.99],[1,1.94,1.99],[2,1.93,3]],"ltp":5.7,"tv":41.18,"id":12636}]}]}
{"op":"mcm","clk":"989966835","pt":1580492829852,"mc":[{"id":"1.168133543","rc":[{"batb":[[0,1.96,3],[1,1.95,21.99],[2,1.94,1.99]],"ltp":5.7,"tv":41.18,"id":12636}]}]}
{"op":"mcm","clk":"989967425","pt":1580492835561,"mc":[{"id":"1.168133543","rc":[{"batb":[[0,1.97,1.99],[1,1.96,3],[2,1.95,21.99]],"ltp":5.7,"tv":41.18,"id":12636}]}]}
{"op":"mcm","clk":"989968442","pt":1580492845121,"mc":[{"id":"1.168133543","rc":[{"batb":[[0,1.97,4.99],[1,1.95,21.99],[2,1.88,5.03]],"ltp":5.7,"tv":41.18,"id":12636}]}]}
{"op":"mcm","clk":"989968875","pt":1580492849294,"mc":[{"id":"1.168133543","rc":[{"batb":[[1,1.88,5.03],[2,1.75,90]],"ltp":5.7,"tv":41.18,"id":12636}]}]}
{"op":"mcm","clk":"989969681","pt":1580492857437,"mc":[{"id":"1.168133543","rc":[{"batb":[[0,1.98,3],[1,1.97,1.99],[2,1.88,5.03]],"ltp":5.7,"tv":41.18,"id":12636}]}]}
{"op":"mcm","clk":"989970582","pt":1580492867426,"mc":[{"id":"1.168133543","rc":[{"batb":[[0,1.97,1.99],[1,1.89,3]],"ltp":5.7,"tv":41.18,"id":12636}]}]}
{"op":"mcm","clk":"989971759","pt":1580492880536,"mc":[{"id":"1.168133543","rc":[{"batb":[[1,1.9,3]],"ltp":5.7,"tv":41.18,"id":12636}]}]}
{"op":"mcm","clk":"989973142","pt":1580492895563,"mc":[{"id":"1.168133543","rc":[{"batb":[[1,1.91,3]],"ltp":5.7,"tv":41.18,"id":12636}]}]}
{"op":"mcm","clk":"989974225","pt":1580492908034,"mc":[{"id":"1.168133543","rc":[{"batb":[[1,1.92,3]],"ltp":5.7,"tv":41.18,"id":12636}]}]}
{"op":"mcm","clk":"989975745","pt":1580492923365,"mc":[{"id":"1.168133543","rc":[{"batb":[[1,1.93,3]],"ltp":5.7,"tv":41.18,"id":12636}]}]}
{"op":"mcm","clk":"989976489","pt":1580492931484,"mc":[{"id":"1.168133543","rc":[{"batb":[[0,1.93,3],[1,1.88,5.03],[2,1.75,90]],"ltp":5.7,"tv":41.18,"id":12636}]}]}
{"op":"mcm","clk":"989976553","pt":1580492932164,"mc":[{"id":"1.168133543","rc":[{"batb":[[0,1.94,1.99],[1,1.93,3],[2,1.88,5.03]],"ltp":5.7,"tv":41.18,"id":12636}]}]}
{"op":"mcm","clk":"989977190","pt":1580492937991,"mc":[{"id":"1.168133543","rc":[{"batb":[[0,1.94,4.99],[1,1.88,5.03],[2,1.75,90]],"ltp":5.7,"tv":41.18,"id":12636}]}]}
{"op":"mcm","clk":"989978466","pt":1580492951090,"mc":[{"id":"1.168133543","rc":[{"batb":[[0,1.95,3],[1,1.94,1.99],[2,1.88,5.03]],"ltp":5.7,"tv":41.18,"id":12636}]}]}
{"op":"mcm","clk":"989979869","pt":1580492965508,"mc":[{"id":"1.168133543","rc":[{"batb":[[0,1.96,21.88]],"ltp":5.7,"tv":41.18,"id":12636}]}]}
{"op":"mcm","clk":"989979881","pt":1580492965608,"mc":[{"id":"1.168133543","rc":[{"batb":[[2,1.89,3]],"ltp":5.7,"tv":41.18,"id":12636}]}]}
{"op":"mcm","clk":"989981366","pt":1580492979342,"mc":[{"id":"1.168133543","rc":[{"batb":[[0,1.97,3],[1,1.96,21.88],[2,1.94,1.99]],"ltp":5.7,"tv":41.18,"id":12636}]}]}
{"op":"mcm","clk":"989981962","pt":1580492985434,"mc":[{"id":"1.168133543","rc":[{"batb":[[1,1.94,1.99],[2,1.88,5.03]],"ltp":5.7,"tv":41.18,"id":12636}]}]}
{"op":"mcm","clk":"989982608","pt":1580492992246,"mc":[{"id":"1.168133543","rc":[{"batb":[[0,1.94,1.99],[1,1.89,3]],"ltp":5.7,"tv":41.18,"id":12636}]}]}
{"op":"mcm","clk":"989984399","pt":1580493009794,"mc":[{"id":"1.168133543","rc":[{"batb":[[1,1.9,3]],"ltp":5.7,"tv":41.18,"id":12636}]}]}
{"op":"mcm","clk":"989985767","pt":1580493023283,"mc":[{"id":"1.168133543","rc":[{"batb":[[1,1.91,3]],"ltp":5.7,"tv":41.18,"id":12636}]}]}
{"op":"mcm","clk":"989987334","pt":1580493038488,"mc":[{"id":"1.168133543","rc":[{"batb":[[1,1.92,3]],"ltp":5.7,"tv":41.18,"id":12636}]}]}
{"op":"mcm","clk":"989987427","pt":1580493039115,"mc":[{"id":"1.168133543","rc":[{"batb":[[0,1.93,1.99]],"ltp":5.7,"tv":41.18,"id":12636}]}]}
{"op":"mcm","clk":"989988191","pt":1580493045202,"mc":[{"id":"1.168133543","rc":[{"batb":[[0,1.94,22.11],[1,1.93,1.99],[2,1.92,3]],"ltp":5.7,"tv":41.18,"id":12636}]}]}
{"op":"mcm","clk":"989989073","pt":1580493052202,"mc":[{"id":"1.168133543","rc":[{"batb":[[0,1.95,3],[1,1.94,22.11],[2,1.93,1.99]],"ltp":5.7,"tv":41.18,"id":12636}]}]}
{"op":"mcm","clk":"989990596","pt":1580493065429,"mc":[{"id":"1.168133543","rc":[{"batb":[[1,1.93,1.99],[2,1.88,5.03]],"ltp":5.7,"tv":41.18,"id":12636}]}]}
{"op":"mcm","clk":"989990775","pt":1580493067047,"mc":[{"id":"1.168133543","rc":[{"batb":[[0,1.93,1.99],[1,1.89,3]],"ltp":5.7,"tv":41.18,"id":12636}]}]}
{"op":"mcm","clk":"989992198","pt":1580493080039,"mc":[{"id":"1.168133543","rc":[{"batb":[[1,1.9,3]],"ltp":5.7,"tv":41.18,"id":12636}]}]}
{"op":"mcm","clk":"989993520","pt":1580493092544,"mc":[{"id":"1.168133543","rc":[{"batb":[[1,1.91,3]],"ltp":5.7,"tv":41.18,"id":12636}]}]}
{"op":"mcm","clk":"989994838","pt":1580493106557,"mc":[{"id":"1.168133543","rc":[{"batb":[[1,1.88,5.03],[2,1.75,90]],"ltp":5.7,"tv":41.18,"id":12636}]}]}
{"op":"mcm","clk":"989994851","pt":1580493106695,"mc":[{"id":"1.168133543","rc":[{"batb":[[1,1.92,3],[2,1.88,5.03]],"ltp":5.7,"tv":41.18,"id":12636}]}]}
{"op":"mcm","clk":"989996410","pt":1580493122269,"mc":[{"id":"1.168133543","rc":[{"batb":[[0,1.93,4.99],[1,1.88,5.03],[2,1.75,90]],"ltp":5.7,"tv":41.18,"id":12636}]}]}
{"op":"mcm","clk":"989997613","pt":1580493135472,"mc":[{"id":"1.168133543","rc":[{"batb":[[0,1.94,3],[1,1.93,1.99],[2,1.88,5.03]],"ltp":5.7,"tv":41.18,"id":12636}]}]}
{"op":"mcm","clk":"989998400","pt":1580493144183,"mc":[{"id":"1.168133543","rc":[{"batb":[[0,1.95,21.99],[1,1.94,3],[2,1.93,1.99]],"ltp":5.7,"tv":41.18,"id":12636}]}]}
{"op":"mcm","clk":"989998550","pt":1580493146190,"mc":[{"id":"1.168133543","rc":[{"batb":[[0,1.96,1.99],[1,1.95,21.99],[2,1.94,3]],"ltp":5.7,"tv":41.18,"id":12636}]}]}
{"op":"mcm","clk":"989998989","pt":1580493151023,"mc":[{"id":"1.168133543","rc":[{"batb":[[0,1.96,4.99],[2,1.88,5.03]],"ltp":5.7,"tv":41.18,"id":12636}]}]}
{"op":"mcm","clk":"990009787","pt":1580493162515,"mc":[{"id":"1.168133543","rc":[{"batb":[[0,1.96,1.99]],"ltp":5.7,"tv":41.18,"id":12636}]}]}
{"op":"mcm","clk":"990009799","pt":1580493162619,"mc":[{"id":"1.168133543","rc":[{"batb":[[0,1.97,3],[1,1.96,1.99],[2,1.95,21.99]],"ltp":5.7,"tv":41.18,"id":12636}]}]}
{"op":"mcm","clk":"990009962","pt":1580493164522,"mc":[{"id":"1.168133543","rc":[{"batb":[[0,1.98,21.66],[1,1.97,3],[2,1.96,1.99]],"ltp":5.7,"tv":41.18,"id":12636}]}]}
{"op":"mcm","clk":"990010832","pt":1580493175360,"mc":[{"id":"1.168133543","rc":[{"batb":[[0,1.99,3],[1,1.98,21.66]],"ltp":5.7,"tv":41.18,"id":12636}]}]}
{"op":"mcm","clk":"990011554","pt":1580493183971,"mc":[{"id":"1.168133543","rc":[{"batb":[[1,1.96,1.99],[2,1.88,5.03]],"ltp":5.7,"tv":41.18,"id":12636}]}]}
{"op":"mcm","clk":"990011999","pt":1580493188462,"mc":[{"id":"1.168133543","rc":[{"batb":[[0,1.96,1.99],[1,1.89,3]],"ltp":5.7,"tv":41.18,"id":12636}]}]}
{"op":"mcm","clk":"990013217","pt":1580493201078,"mc":[{"id":"1.168133543","rc":[{"batb":[[1,1.9,3]],"ltp":5.7,"tv":41.18,"id":12636}]}]}
{"op":"mcm","clk":"990014667","pt":1580493216120,"mc":[{"id":"1.168133543","rc":[{"batb":[[1,1.91,3]],"ltp":5.7,"tv":41.18,"id":12636}]}]}
{"op":"mcm","clk":"990015932","pt":1580493229418,"mc":[{"id":"1.168133543","rc":[{"batb":[[1,1.92,3]],"ltp":5.7,"tv":41.18,"id":12636}]}]}
{"op":"mcm","clk":"990016819","pt":1580493238462,"mc":[{"id":"1.168133543","rc":[{"batb":[[1,1.93,3.03],[2,1.92,3]],"ltp":5.7,"tv":41.18,"id":12636},{"batb":[[0,1.83,6.34],[1,1.82,6],[2,1.81,90]],"batl":[[0,2.98,3.03],[1,3,22],[2,3.3,2]],"ltp":3.35,"tv":50.1,"id":10107355}]}]}
{"op":"mcm","clk":"990016926","pt":1580493239563,"mc":[{"id":"1.168133543","rc":[{"batb":[[0,1.68,17.07],[2,1.51,3.36]],"batl":[[0,880,3.03],[1,890,9],[2,910,0.2]],"ltp":0.0,"tv":0.0,"id":10163711},{"batb":[[0,1.68,17.07],[2,1.51,3.36]],"batl":[[1,910,0.2]],"ltp":0.0,"tv":0.0,"id":22121325}]}]}
{"op":"mcm","clk":"990017014","pt":1580493240445,"mc":[{"id":"1.168133543","rc":[{"batb":[[0,1.68,17.07],[2,1.51,3.36]],"ltp":0.0,"tv":0.0,"id":7226819},{"batl":[[0,880,3.03],[1,890,9],[2,910,0.2]],"ltp":0.0,"tv":0.0,"id":22121325}]}]}
{"op":"mcm","clk":"990017428","pt":1580493244574,"mc":[{"id":"1.168133543","rc":[{"batb":[[0,1.84,23.62],[1,1.83,6.03],[2,1.82,6]],"ltp":3.35,"tv":50.1,"id":10107355}]}]}
{"op":"mcm","clk":"990017571","pt":1580493245988,"mc":[{"id":"1.168133543","rc":[{"batb":[[1,1.94,3],[2,1.93,3.03]],"ltp":5.7,"tv":41.18,"id":12636}]}]}
{"op":"mcm","clk":"990019232","pt":1580493264686,"mc":[{"id":"1.168133543","rc":[{"batb":[[1,1.95,3]],"ltp":5.7,"tv":41.18,"id":12636}]}]}
{"op":"mcm","clk":"990019439","pt":1580493267309,"mc":[{"id":"1.168133543","rc":[{"batb":[[0,1.7,90],[1,1.68,17.07]],"ltp":0.0,"tv":0.0,"id":7226819},{"batb":[[0,1.7,90],[1,1.68,17.07]],"ltp":0.0,"tv":0.0,"id":10163711},{"batb":[[0,1.7,90],[1,1.68,17.07]],"ltp":0.0,"tv":0.0,"id":22121325}]}]}
{"op":"mcm","clk":"990019554","pt":1580493268507,"mc":[{"id":"1.168133543","rc":[{"batl":[[0,860,9],[1,880,3.03]],"ltp":0.0,"tv":0.0,"id":10163711},{"batl":[[0,860,9],[1,880,3.03]],"ltp":0.0,"tv":0.0,"id":22121325}]}]}
{"op":"mcm","clk":"990020395","pt":1580493277517,"mc":[{"id":"1.168133543","rc":[{"batl":[[0,2.96,2],[1,2.98,3.03],[2,3,22]],"ltp":3.35,"tv":50.1,"id":10107355}]}]}
{"op":"mcm","clk":"990020474","pt":1580493278399,"mc":[{"id":"1.168133543","rc":[{"batb":[[0,1.71,1.99],[1,1.7,90],[2,1.68,15.08]],"ltp":0.0,"tv":0.0,"id":10163711}]}]}
{"op":"mcm","clk":"990020567","pt":1580493279481,"mc":[{"id":"1.168133543","rc":[{"batb":[[1,1.68,15.08]],"ltp":0.0,"tv":0.0,"id":7226819},{"batb":[[0,1.71,1.99],[1,1.7,90],[2,1.68,15.08]],"ltp":0.0,"tv":0.0,"id":22121325}]}]}
{"op":"mcm","clk":"990020876","pt":1580493282979,"mc":[{"id":"1.168133543","rc":[{"batb":[[0,1.97,21.77],[1,1.96,1.99],[2,1.95,3]],"ltp":5.7,"tv":41.18,"id":12636}]}]}
{"op":"mcm","clk":"990021047","pt":1580493284891,"mc":[{"id":"1.168133543","rc":[{"batb":[[0,1.98,3],[1,1.97,21.77],[2,1.96,1.99]],"ltp":5.7,"tv":41.18,"id":12636}]}]}
{"op":"mcm","clk":"990022533","pt":1580493302436,"mc":[{"id":"1.168133543","rc":[{"batb":[[1,1.96,1.99],[2,1.93,3.03]],"ltp":5.7,"tv":41.18,"id":12636}]}]}
{"op":"mcm","clk":"990023001","pt":1580493307958,"mc":[{"id":"1.168133543","rc":[{"batb":[[0,1.96,1.99],[1,1.94,3]],"ltp":5.7,"tv":41.18,"id":12636}]}]}
{"op":"mcm","clk":"990024228","pt":1580493322102,"mc":[{"id":"1.168133543","rc":[{"batb":[[0,1.97,21.77],[1,1.96,1.99],[2,1.95,3]],"ltp":5.7,"tv":41.18,"id":12636}]}]}
{"op":"mcm","clk":"990024372","pt":1580493323872,"mc":[{"id":"1.168133543","rc":[{"batb":[[1,1.83,3.03]],"ltp":3.35,"tv":50.1,"id":10107355}]}]}
{"op":"mcm","clk":"990026006","pt":1580493342321,"mc":[{"id":"1.168133543","rc":[{"batb":[[0,1.98,3],[1,1.97,21.77],[2,1.96,1.99]],"ltp":5.7,"tv":41.18,"id":12636}]}]}
{"op":"mcm","clk":"990027747","pt":1580493361015,"mc":[{"id":"1.168133543","rc":[{"batb":[[1,1.96,1.99],[2,1.93,3.03]],"ltp":5.7,"tv":41.18,"id":12636}]}]}
{"op":"mcm","clk":"990028937","pt":1580493376280,"mc":[{"id":"1.168133543","rc":[{"batb":[[0,1.96,1.99],[1,1.94,3]],"ltp":5.7,"tv":41.18,"id":12636}]}]}
{"op":"mcm","clk":"990030053","pt":1580493391471,"mc":[{"id":"1.168133543","rc":[{"batb":[[1,1.95,3]],"ltp":5.7,"tv":41.18,"id":12636}]}]}
{"op":"mcm","clk":"990030827","pt":1580493400523,"mc":[{"id":"1.168133543","rc":[{"batb":[[0,1.97,21.77],[1,1.96,1.99],[2,1.95,3]],"ltp":5.7,"tv":41.18,"id":12636}]}]}
{"op":"mcm","clk":"990031261","pt":1580493406024,"mc":[{"id":"1.168133543","rc":[{"batb":[[0,1.98,3],[1,1.97,21.77],[2,1.96,1.99]],"ltp":5.7,"tv":41.18,"id":12636}]}]}
{"op":"mcm","clk":"990032216","pt":1580493419104,"mc":[{"id":"1.168133543","rc":[{"batb":[[1,1.96,1.99],[2,1.93,3.03]],"ltp":5.7,"tv":41.18,"id":12636}]}]}
{"op":"mcm","clk":"990032911","pt":1580493427358,"mc":[{"id":"1.168133543","rc":[{"batb":[[0,1.99,1.99],[1,1.98,3]],"ltp":5.7,"tv":41.18,"id":12636}]}]}
{"op":"mcm","clk":"990033446","pt":1580493434835,"mc":[{"id":"1.168133543","rc":[{"batb":[[0,1.99,4.99],[1,1.93,3.03],[2,1.75,90]],"ltp":5.7,"tv":41.18,"id":12636}]}]}
{"op":"mcm","clk":"990034750","pt":1580493450335,"mc":[{"id":"1.168133543","rc":[{"batb":[[0,2,3],[1,1.99,1.99],[2,1.93,3.03]],"ltp":5.7,"tv":41.18,"id":12636}]}]}
{"op":"mcm","clk":"990035501","pt":1580493458952,"mc":[{"id":"1.168133543","rc":[{"batb":[[0,2.02,21.23],[1,2,3],[2,1.99,1.99]],"ltp":5.7,"tv":41.18,"id":12636}]}]}
{"op":"mcm","clk":"990036197","pt":1580493467108,"mc":[{"id":"1.168133543","rc":[{"batb":[[0,2.04,3],[1,2.02,21.23]],"ltp":5.7,"tv":41.18,"id":12636}]}]}
{"op":"mcm","clk":"990037169","pt":1580493478993,"mc":[{"id":"1.168133543","rc":[{"batb":[[1,1.99,1.99],[2,1.93,3.03]],"ltp":5.7,"tv":41.18,"id":12636}]}]}
{"op":"mcm","clk":"990037699","pt":1580493485477,"mc":[{"id":"1.168133543","rc":[{"batb":[[0,1.99,1.99],[1,1.93,3.03],[2,1.75,90]],"ltp":5.7,"tv":41.18,"id":12636}]}]}
{"op":"mcm","clk":"990037709","pt":1580493485582,"mc":[{"id":"1.168133543","rc":[{"batb":[[1,1.94,3],[2,1.93,3.03]],"ltp":5.7,"tv":41.18,"id":12636}]}]}
{"op":"mcm","clk":"990039286","pt":1580493504506,"mc":[{"id":"1.168133543","rc":[{"batb":[[1,1.93,3.03],[2,1.75,90]],"ltp":5.7,"tv":41.18,"id":12636}]}]}
{"op":"mcm","clk":"990039298","pt":1580493504611,"mc":[{"id":"1.168133543","rc":[{"batb":[[1,1.95,3],[2,1.93,3.03]],"ltp":5.7,"tv":41.18,"id":12636}]}]}
{"op":"mcm","clk":"990040776","pt":1580493524530,"mc":[{"id":"1.168133543","rc":[{"batb":[[1,1.96,3]],"ltp":5.7,"tv":41.18,"id":12636}]}]}
{"op":"mcm","clk":"990041873","pt":1580493538987,"mc":[{"id":"1.168133543","rc":[{"batb":[[1,1.97,3]],"ltp":5.7,"tv":41.18,"id":12636}]}]}
{"op":"mcm","clk":"990043198","pt":1580493556473,"mc":[{"id":"1.168133543","rc":[{"batb":[[1,1.93,3.03],[2,1.75,90]],"ltp":5.7,"tv":41.18,"id":12636}]}]}
{"op":"mcm","clk":"990043270","pt":1580493557308,"mc":[{"id":"1.168133543","rc":[{"batb":[[0,2,21.44],[1,1.99,1.99],[2,1.98,3]],"ltp":5.7,"tv":41.18,"id":12636}]}]}
{"op":"mcm","clk":"990044518","pt":1580493574108,"mc":[{"id":"1.168133543","rc":[{"batb":[[0,2.02,3],[1,2,21.44],[2,1.99,1.99]],"ltp":5.7,"tv":41.18,"id":12636}]}]}
{"op":"mcm","clk":"990044719","pt":1580493576914,"mc":[{"id":"1.168133543","rc":[{"batb":[[1,1.99,1.99],[2,1.93,3.03]],"ltp":5.7,"tv":41.18,"id":12636}]}]}
{"op":"mcm","clk":"990045381","pt":1580493586831,"mc":[{"id":"1.168133543","rc":[{"batb":[[0,1.99,1.99],[1,1.94,3]],"ltp":5.7,"tv":41.18,"id":12636}]}]}
{"op":"mcm","clk":"990045501","pt":1580493588567,"mc":[{"id":"1.168133543","rc":[{"batl":[[0,3,50],[1,4.7,3.59],[2,4.8,1.68]],"ltp":5.7,"tv":41.18,"id":12636}]}]}
{"op":"mcm","clk":"990046042","pt":1580493596154,"mc":[{"id":"1.168133543","rc":[{"batb":[[1,1.95,3]],"ltp":5.7,"tv":41.18,"id":12636}]}]}
{"op":"mcm","clk":"990047125","pt":1580493607490,"mc":[{"id":"1.168133543","rc":[{"trd":[[3.9,7.56],[4,1.68],[4.1,5.04],[4.2,1.68],[4.3,8.4],[5,5.04],[5.5,5.04],[5.7,5.04]],"batb":[[1,1.96,3],[2,1.93,3.03]],"batl":[[1,4.7,3.58],[2,4.8,1.68]],"ltp":5.7,"tv":41.15,"id":12636},{"batb":[[1,1.68,15.06],[2,1.51,3.36]],"batl":[[0,65,3.23]],"ltp":0.0,"tv":0.0,"id":7226819},{"batb":[[2,1.68,15.06]],"batl":[[1,880,3.03]],"ltp":0.0,"tv":0.0,"id":10163711},{"trd":[[1.55,3.36],[3.35,6],[3.4,4.2],[3.45,7.96],[3.5,1.68],[3.7,24.36]],"batb":[[0,1.84,23.59],[1,1.83,3.03]],"batl":[[1,2.98,3.03]],"ltp":3.35,"tv":50.07,"id":10107355},{"batb":[[2,1.68,15.06]],"batl":[[1,880,3.03]],"ltp":0.0,"tv":0.0,"id":22121325}],"tv":91.63}]}
{"op":"mcm","clk":"990047361","pt":1580493609568,"mc":[{"id":"1.168133543","rc":[{"batl":[[1,3.1,50],[2,4.7,3.58]],"ltp":5.7,"tv":41.15,"id":12636}]}]}
{"op":"mcm","clk":"990048132","pt":1580493618505,"mc":[{"id":"1.168133543","rc":[{"batb":[[1,1.97,3]],"ltp":5.7,"tv":41.15,"id":12636}]}]}
{"op":"mcm","clk":"990048242","pt":1580493619912,"mc":[{"id":"1.168133543","rc":[{"batb":[[0,1.98,1.99]],"ltp":5.7,"tv":41.15,"id":12636}]}]}
{"op":"mcm","clk":"990049300","pt":1580493632520,"mc":[{"id":"1.168133543","rc":[{"batb":[[0,1.99,21.53],[1,1.98,1.99]],"ltp":5.7,"tv":41.15,"id":12636}]}]}
{"op":"mcm","clk":"990049309","pt":1580493632625,"mc":[{"id":"1.168133543","rc":[{"batb":[[1,1.98,4.99]],"ltp":5.7,"tv":41.15,"id":12636}]}]}
{"op":"mcm","clk":"990050511","pt":1580493646911,"mc":[{"id":"1.168133543","rc":[{"batb":[[0,2,3],[1,1.99,21.53],[2,1.98,1.99]],"ltp":5.7,"tv":41.15,"id":12636}]}]}
{"op":"mcm","clk":"990051016","pt":1580493652100,"mc":[{"id":"1.168133543","rc":[{"batb":[[1,1.98,1.99],[2,1.93,3.03]],"ltp":5.7,"tv":41.15,"id":12636}]}]}
{"op":"mcm","clk":"990052139","pt":1580493663038,"mc":[{"id":"1.168133543","rc":[{"batb":[[0,1.98,1.99],[1,1.94,3]],"ltp":5.7,"tv":41.15,"id":12636}]}]}
{"op":"mcm","clk":"990054107","pt":1580493684951,"mc":[{"id":"1.168133543","rc":[{"batb":[[1,1.95,3]],"ltp":5.7,"tv":41.15,"id":12636}]}]}
{"op":"mcm","clk":"990055863","pt":1580493703424,"mc":[{"id":"1.168133543","rc":[{"batb":[[1,1.96,3]],"ltp":5.7,"tv":41.15,"id":12636}]}]}
{"op":"mcm","clk":"990056454","pt":1580493710125,"mc":[{"id":"1.168133543","rc":[{"batb":[[0,3,32],[1,1.71,1.99],[2,1.7,90]],"ltp":0.0,"tv":0.0,"id":10163711}]}]}
{"op":"mcm","clk":"990056997","pt":1580493717168,"mc":[{"id":"1.168133543","rc":[{"batb":[[1,1.97,3]],"ltp":5.7,"tv":41.15,"id":12636}]}]}
{"op":"mcm","clk":"990058679","pt":1580493734393,"mc":[{"id":"1.168133543","rc":[{"batb":[[0,1.98,4.99],[1,1.93,3.03],[2,1.75,90]],"ltp":5.7,"tv":41.15,"id":12636}]}]}
{"op":"mcm","clk":"990059323","pt":1580493741459,"mc":[{"id":"1.168133543","rc":[{"batb":[[1,2.24,90],[2,1.75,500.53]],"ltp":0.0,"tv":0.0,"id":10163711}]}]}
{"op":"mcm","clk":"990060253","pt":1580493752286,"mc":[{"id":"1.168133543","rc":[{"batb":[[0,1.99,3],[1,1.98,1.99],[2,1.93,3.03]],"ltp":5.7,"tv":41.15,"id":12636}]}]}
{"op":"mcm","clk":"990060591","pt":1580493756218,"mc":[{"id":"1.168133543","rc":[{"batb":[[0,2,21.42],[1,1.99,3],[2,1.98,1.99]],"ltp":5.7,"tv":41.15,"id":12636}]}]}
{"op":"mcm","clk":"990061210","pt":1580493762740,"mc":[{"id":"1.168133543","rc":[{"batb":[[0,2,63.42]],"ltp":5.7,"tv":41.15,"id":12636}]}]}
{"op":"mcm","clk":"990061704","pt":1580493767521,"mc":[{"id":"1.168133543","rc":[{"batb":[[0,2.02,3],[1,2,63.42]],"ltp":5.7,"tv":41.15,"id":12636}]}]}
{"op":"mcm","clk":"990061740","pt":1580493768041,"mc":[{"id":"1.168133543","rc":[{"batb":[[0,2.02,45],[1,2,21.42]],"ltp":5.7,"tv":41.15,"id":12636}]}]}
{"op":"mcm","clk":"990062663","pt":1580493776444,"mc":[{"id":"1.168133543","rc":[{"batb":[[1,1.98,1.99],[2,1.93,3.03]],"ltp":5.7,"tv":41.15,"id":12636}]}]}
{"op":"mcm","clk":"990063036","pt":1580493779255,"mc":[{"id":"1.168133543","rc":[{"batb":[[0,2.02,3]],"ltp":5.7,"tv":41.15,"id":12636},{"batb":[[0,2.24,90],[1,1.75,500.53],[2,1.71,1.99]],"ltp":0.0,"tv":0.0,"id":10163711}]}]}
{"op":"mcm","clk":"990064014","pt":1580493788652,"mc":[{"id":"1.168133543","rc":[{"batb":[[0,1.98,1.99],[1,1.94,3]],"ltp":5.7,"tv":41.15,"id":12636}]}]}
{"op":"mcm","clk":"990065376","pt":1580493805126,"mc":[{"id":"1.168133543","rc":[{"batb":[[1,1.95,3]],"ltp":5.7,"tv":41.15,"id":12636}]}]}
{"op":"mcm","clk":"990067130","pt":1580493827766,"mc":[{"id":"1.168133543","rc":[{"batb":[[1,1.96,3]],"ltp":5.7,"tv":41.15,"id":12636}]}]}
{"op":"mcm","clk":"990067970","pt":1580493837385,"mc":[{"id":"1.168133543","rc":[{"batb":[[0,1.97,1.99]],"ltp":5.7,"tv":41.15,"id":12636}]}]}
{"op":"mcm","clk":"990068054","pt":1580493838382,"mc":[{"id":"1.168133543","rc":[{"batb":[[0,1.98,21.63],[1,1.97,1.99],[2,1.96,3]],"ltp":5.7,"tv":41.15,"id":12636},{"batb":[[0,2.26,1.99],[1,2.24,90],[2,1.75,500.53]],"ltp":0.0,"tv":0.0,"id":10163711}]}]}
{"op":"mcm","clk":"990068518","pt":1580493843169,"mc":[{"id":"1.168133543","rc":[{"batb":[[0,1.99,3],[1,1.98,21.63],[2,1.97,1.99]],"ltp":5.7,"tv":41.15,"id":12636}]}]}
{"op":"mcm","clk":"990069729","pt":1580493858738,"mc":[{"id":"1.168133543","rc":[{"batb":[[1,1.97,1.99],[2,1.93,3.03]],"ltp":5.7,"tv":41.15,"id":12636}]}]}
{"op":"mcm","clk":"990070863","pt":1580493872561,"mc":[{"id":"1.168133543","rc":[{"batb":[[0,1.97,1.99],[1,1.93,3.03],[2,1.75,90]],"ltp":5.7,"tv":41.15,"id":12636}]}]}
{"op":"mcm","clk":"990070943","pt":1580493873350,"mc":[{"id":"1.168133543","rc":[{"batb":[[1,1.94,3],[2,1.93,3.03]],"ltp":5.7,"tv":41.15,"id":12636}]}]}
{"op":"mcm","clk":"990071846","pt":1580493883539,"mc":[{"id":"1.168133543","rc":[{"batl":[[0,860,9.2],[2,910,0]],"ltp":0.0,"tv":0.0,"id":10163711},{"batl":[[0,2.96,2.18]],"ltp":3.35,"tv":50.07,"id":10107355},{"batl":[[0,860,9.2],[2,910,0]],"ltp":0.0,"tv":0.0,"id":22121325}]}]}
{"op":"mcm","clk":"990072094","pt":1580493885855,"mc":[{"id":"1.168133543","rc":[{"batb":[[1,1.95,3]],"ltp":5.7,"tv":41.15,"id":12636}]}]}
{"op":"mcm","clk":"990074006","pt":1580493907107,"mc":[{"id":"1.168133543","rc":[{"batb":[[1,1.96,3]],"ltp":5.7,"tv":41.15,"id":12636}]}]}
{"op":"mcm","clk":"990075138","pt":1580493919442,"mc":[{"id":"1.168133543","rc":[{"batb":[[0,1.98,21.63],[1,1.97,1.99],[2,1.96,3]],"ltp":5.7,"tv":41.15,"id":12636}]}]}
{"op":"mcm","clk":"990075585","pt":1580493923927,"mc":[{"id":"1.168133543","rc":[{"batb":[[0,1.99,3],[1,1.98,21.63],[2,1.97,1.99]],"ltp":5.7,"tv":41.15,"id":12636}]}]}
{"op":"mcm","clk":"990077076","pt":1580493939377,"mc":[{"id":"1.168133543","rc":[{"batb":[[1,1.97,1.99],[2,1.93,3.03]],"ltp":5.7,"tv":41.15,"id":12636}]}]}
{"op":"mcm","clk":"990077278","pt":1580493941269,"mc":[{"id":"1.168133543","rc":[{"batb":[[0,1.97,1.99],[1,1.94,3]],"ltp":5.7,"tv":41.15,"id":12636}]}]}
{"op":"mcm","clk":"990078795","pt":1580493956503,"mc":[{"id":"1.168133543","rc":[{"batb":[[1,1.93,3.03],[2,1.75,90]],"ltp":5.7,"tv":41.15,"id":12636}]}]}
{"op":"mcm","clk":"990078808","pt":1580493956575,"mc":[{"id":"1.168133543","rc":[{"batb":[[1,1.95,3],[2,1.93,3.03]],"ltp":5.7,"tv":41.15,"id":12636}]}]}
{"op":"mcm","clk":"990080564","pt":1580493975284,"mc":[{"id":"1.168133543","rc":[{"batb":[[1,1.96,3]],"ltp":5.7,"tv":41.15,"id":12636}]}]}
{"op":"mcm","clk":"990081060","pt":1580493980528,"mc":[{"id":"1.168133543","rc":[{"batb":[[0,1.98,21.63],[1,1.97,1.99],[2,1.96,3]],"ltp":5.7,"tv":41.15,"id":12636}]}]}
{"op":"mcm","clk":"990081853","pt":1580493989048,"mc":[{"id":"1.168133543","rc":[{"batb":[[0,1.99,3],[1,1.98,21.63],[2,1.97,1.99]],"ltp":5.7,"tv":41.15,"id":12636}]}]}
{"op":"mcm","clk":"990082853","pt":1580493999926,"mc":[{"id":"1.168133543","rc":[{"batb":[[1,1.97,1.99],[2,1.93,3.03]],"ltp":5.7,"tv":41.15,"id":12636}]}]}
{"op":"mcm","clk":"990083176","pt":1580494003440,"mc":[{"id":"1.168133543","rc":[{"batb":[[0,1.97,1.99],[1,1.94,3]],"ltp":5.7,"tv":41.15,"id":12636}]}]}
{"op":"mcm","clk":"990084331","pt":1580494016133,"mc":[{"id":"1.168133543","rc":[{"batb":[[0,1.95,1.99]],"ltp":5.7,"tv":41.15,"id":12636}]}]}
{"op":"mcm","clk":"990084676","pt":1580494019471,"mc":[{"id":"1.168133543","rc":[{"batb":[[0,1.96,21.85],[1,1.95,4.99]],"ltp":5.7,"tv":41.15,"id":12636}]}]}
{"op":"mcm","clk":"990085900","pt":1580494032359,"mc":[{"id":"1.168133543","rc":[{"batb":[[0,1.97,10],[1,1.96,21.85],[2,1.95,4.99]],"ltp":5.7,"tv":41.15,"id":12636},{"batb":[[0,1.62,11.99]],"ltp":0.0,"tv":0.0,"id":22308007},{"batb":[[0,1.71,10],[1,1.7,90],[2,1.68,15.06]],"ltp":0.0,"tv":0.0,"id":7226819},{"batb":[[0,2.26,10.84]],"ltp":0.0,"tv":0.0,"id":10163711},{"batb":[[0,1.85,10.31],[1,1.84,23.28],[2,1.83,3.03]],"ltp":3.35,"tv":50.07,"id":10107355},{"batb":[[0,1.71,11.99]],"ltp":0.0,"tv":0.0,"id":22121325},{"batb":[[0,1.62,11.99]],"ltp":0.0,"tv":0.0,"id":26548208},{"batb":[[0,1.62,11.99]],"ltp":0.0,"tv":0.0,"id":27606066},{"batb":[[0,1.62,11.99]],"ltp":0.0,"tv":0.0,"id":24270700},{"batb":[[0,1.62,11.99]],"ltp":0.0,"tv":0.0,"id":13306150}]}]}
{"op":"mcm","clk":"990086184","pt":1580494035358,"mc":[{"id":"1.168133543","rc":[{"batb":[[0,1.98,3],[1,1.97,10],[2,1.96,21.85]],"ltp":5.7,"tv":41.15,"id":12636}]}]}
{"op":"mcm","clk":"990086290","pt":1580494036566,"mc":[{"id":"1.168133543","rc":[{"batb":[[1,1.59,1.04],[2,1.51,3.36]],"ltp":0.0,"tv":0.0,"id":22308007},{"batb":[[1,1.68,15.06],[2,1.51,3.36]],"ltp":0.0,"tv":0.0,"id":7226819},{"batb":[[1,1.68,15.06],[2,1.51,3.36]],"ltp":0.0,"tv":0.0,"id":22121325},{"batb":[[1,1.59,1.04],[2,1.51,3.36]],"ltp":0.0,"tv":0.0,"id":26548208},{"batb":[[1,1.59,1.04],[2,1.51,3.36]],"ltp":0.0,"tv":0.0,"id":27606066},{"batb":[[1,1.59,1.04],[2,1.51,3.36]],"ltp":0.0,"tv":0.0,"id":24270700},{"batb":[[1,1.59,1.04],[2,1.51,3.36]],"ltp":0.0,"tv":0.0,"id":13306150}]}]}
{"op":"mcm","clk":"990086299","pt":1580494036669,"mc":[{"id":"1.168133543","rc":[{"batb":[[0,1.64,90],[1,1.62,11.99],[2,1.59,1.04]],"ltp":0.0,"tv":0.0,"id":22308007},{"batb":[[0,1.73,90],[1,1.71,10],[2,1.68,15.06]],"ltp":0.0,"tv":0.0,"id":7226819},{"batb":[[0,1.73,90],[1,1.71,11.99],[2,1.68,15.06]],"ltp":0.0,"tv":0.0,"id":22121325},{"batb":[[0,1.64,90],[1,1.62,11.99],[2,1.59,1.04]],"ltp":0.0,"tv":0.0,"id":26548208},{"batb":[[0,1.64,90],[1,1.62,11.99],[2,1.59,1.04]],"ltp":0.0,"tv":0.0,"id":27606066},{"batb":[[0,1.64,90],[1,1.62,11.99],[2,1.59,1.04]],"ltp":0.0,"tv":0.0,"id":24270700},{"batb":[[0,1.64,90],[1,1.62,11.99],[2,1.59,1.04]],"ltp":0.0,"tv":0.0,"id":13306150}]}]}
{"op":"mcm","clk":"990086566","pt":1580494039547,"mc":[{"id":"1.168133543","rc":[{"batb":[[2,1.95,1.99]],"ltp":5.7,"tv":41.15,"id":12636},{"batb":[[1,1.83,3.03],[2,1.82,6]],"ltp":3.35,"tv":50.07,"id":10107355}]}]}
{"op":"mcm","clk":"990086658","pt":1580494040549,"mc":[{"id":"1.168133543","rc":[{"batb":[[0,1.99,21.53],[1,1.98,3],[2,1.97,10]],"ltp":5.7,"tv":41.15,"id":12636}]}]}
{"op":"mcm","clk":"990087317","pt":1580494047177,"mc":[{"id":"1.168133543","rc":[{"batb":[[0,2,3],[1,1.99,21.53]],"ltp":5.7,"tv":41.15,"id":12636}]}]}
{"op":"mcm","clk":"990097917","pt":1580494059399,"mc":[{"id":"1.168133543","rc":[{"batb":[[1,1.97,10],[2,1.95,1.99]],"ltp":5.7,"tv":41.15,"id":12636}]}]}
{"op":"mcm","clk":"990098160","pt":1580494061975,"mc":[{"id":"1.168133543","rc":[{"batb":[[2,1.51,3.36]],"ltp":0.0,"tv":0.0,"id":22308007},{"batb":[[2,1.51,3.36]],"ltp":0.0,"tv":0.0,"id":26548208},{"batb":[[2,1.51,3.36]],"ltp":0.0,"tv":0.0,"id":27606066},{"batb":[[2,1.51,3.36]],"ltp":0.0,"tv":0.0,"id":24270700},{"batb":[[2,1.51,3.36]],"ltp":0.0,"tv":0.0,"id":13306150}]}]}
{"op":"mcm","clk":"990099060","pt":1580494072371,"mc":[{"id":"1.168133543","rc":[{"batb":[[0,1.98,3]],"ltp":5.7,"tv":41.15,"id":12636}]}]}
{"op":"mcm","clk":"990099264","pt":1580494074574,"mc":[{"id":"1.168133543","rc":[{"batb":[[0,1.98,3.82]],"ltp":5.7,"tv":41.15,"id":12636},{"batb":[[0,2.26,11.56]],"ltp":0.0,"tv":0.0,"id":10163711},{"batb":[[0,1.85,11.19]],"ltp":3.35,"tv":50.07,"id":10107355}]}]}
{"op":"mcm","clk":"990099294","pt":1580494074996,"mc":[{"id":"1.168133543","rc":[{"batb":[[0,1.64,91]],"ltp":0.0,"tv":0.0,"id":22308007},{"batb":[[0,1.73,90.95]],"ltp":0.0,"tv":0.0,"id":7226819},{"batb":[[0,1.73,90.95]],"ltp":0.0,"tv":0.0,"id":22121325},{"batb":[[0,1.64,91]],"ltp":0.0,"tv":0.0,"id":26548208},{"batb":[[0,1.64,91]],"ltp":0.0,"tv":0.0,"id":27606066},{"batb":[[0,1.64,91]],"ltp":0.0,"tv":0.0,"id":24270700},{"batb":[[0,1.64,91]],"ltp":0.0,"tv":0.0,"id":13306150}]}]}
{"op":"mcm","clk":"990099668","pt":1580494078883,"mc":[{"id":"1.168133543","rc":[{"batb":[[0,1.99,22.34],[1,1.98,3],[2,1.97,10]],"ltp":5.7,"tv":41.15,"id":12636}]}]}
{"op":"mcm","clk":"990100012","pt":1580494083119,"mc":[{"id":"1.168133543","rc":[{"batb":[[0,2,3.82],[1,1.99,21.53]],"ltp":5.7,"tv":41.15,"id":12636}]}]}
{"op":"mcm","clk":"990100964","pt":1580494093523,"mc":[{"id":"1.168133543","rc":[{"batb":[[2,1.95,1.99]],"ltp":5.7,"tv":41.15,"id":12636},{"batb":[[1,1.62,1.99]],"ltp":0.0,"tv":0.0,"id":22308007},{"batb":[[1,1.68,15.06],[2,1.51,3.36]],"ltp":0.0,"tv":0.0,"id":7226819},{"batb":[[1,1.71,1.99]],"ltp":0.0,"tv":0.0,"id":22121325},{"batb":[[1,1.62,1.99]],"ltp":0.0,"tv":0.0,"id":26548208},{"batb":[[1,1.62,1.99]],"ltp":0.0,"tv":0.0,"id":27606066},{"batb":[[1,1.62,1.99]],"ltp":0.0,"tv":0.0,"id":24270700},{"batb":[[1,1.62,1.99]],"ltp":0.0,"tv":0.0,"id":13306150}]}]}
{"op":"mcm","clk":"990101245","pt":1580494096525,"mc":[{"id":"1.168133543","rc":[{"batb":[[0,2.02,3.82]],"ltp":5.7,"tv":41.15,"id":12636}]}]}
{"op":"mcm","clk":"990101416","pt":1580494098411,"mc":[{"id":"1.168133543","rc":[{"batb":[[1,1.95,1.99],[2,1.93,3.03]],"ltp":5.7,"tv":41.15,"id":12636}]}]}
{"op":"mcm","clk":"990102748","pt":1580494111518,"mc":[{"id":"1.168133543","rc":[{"batb":[[0,2.04,3],[1,1.95,2.81]],"ltp":5.7,"tv":41.15,"id":12636}]}]}
{"op":"mcm","clk":"990103992","pt":1580494124409,"mc":[{"id":"1.168133543","rc":[{"batb":[[0,1.96,3.82],[1,1.95,1.99]],"ltp":5.7,"tv":41.15,"id":12636}]}]}
{"op":"mcm","clk":"990105301","pt":1580494136886,"mc":[{"id":"1.168133543","rc":[{"batb":[[0,1.97,3.82]],"ltp":5.7,"tv":41.15,"id":12636}]}]}
{"op":"mcm","clk":"990106913","pt":1580494153771,"mc":[{"id":"1.168133543","rc":[{"batb":[[0,1.98,3.82]],"ltp":5.7,"tv":41.15,"id":12636}]}]}
{"op":"mcm","clk":"990108174","pt":1580494169317,"mc":[{"id":"1.168133543","rc":[{"batb":[[0,2.04,1.99],[1,1.99,3.82]],"ltp":5.7,"tv":41.15,"id":12636},{"batb":[[0,1.86,1.19],[1,1.85,10],[2,1.83,3.03]],"ltp":3.35,"tv":50.07,"id":10107355}]}]}
{"op":"mcm","clk":"990108284","pt":1580494170525,"mc":[{"id":"1.168133543","rc":[{"batb":[[0,2.3,1.99],[1,2.26,9.57],[2,2.24,90]],"ltp":0.0,"tv":0.0,"id":10163711},{"batb":[[1,1.68,15.06],[2,1.51,3.36]],"ltp":0.0,"tv":0.0,"id":22121325}]}]}
{"op":"mcm","clk":"990108357","pt":1580494171525,"mc":[{"id":"1.168133543","rc":[{"batb":[[0,1.75,1.99],[1,1.73,90.95],[2,1.68,15.06]],"ltp":0.0,"tv":0.0,"id":7226819},{"batb":[[0,1.75,1.99],[1,1.73,90.95],[2,1.68,15.06]],"ltp":0.0,"tv":0.0,"id":22121325},{"batb":[[0,1.66,1.99],[1,1.64,91]],"ltp":0.0,"tv":0.0,"id":26548208}]}]}
{"op":"mcm","clk":"990108423","pt":1580494172422,"mc":[{"id":"1.168133543","rc":[{"batb":[[0,1.66,1.99],[1,1.64,91]],"ltp":0.0,"tv":0.0,"id":22308007},{"batb":[[0,1.66,1.99],[1,1.64,91]],"ltp":0.0,"tv":0.0,"id":13306150}]}]}
{"op":"mcm","clk":"990108488","pt":1580494173108,"mc":[{"id":"1.168133543","rc":[{"batb":[[0,1.66,1.99],[1,1.64,91]],"ltp":0.0,"tv":0.0,"id":27606066},{"batb":[[0,1.66,1.99],[1,1.64,91]],"ltp":0.0,"tv":0.0,"id":24270700}]}]}
{"op":"mcm","clk":"990108895","pt":1580494177933,"mc":[{"id":"1.168133543","rc":[{"batl":[[0,2.94,50],[1,3,50]],"ltp":5.7,"tv":41.15,"id":12636}]}]}
{"op":"mcm","clk":"990109444","pt":1580494184245,"mc":[{"id":"1.168133543","rc":[{"batb":[[0,2.04,4.99],[1,1.93,3.85],[2,1.75,90]],"ltp":5.7,"tv":41.15,"id":12636}]}]}
{"op":"mcm","clk":"990110105","pt":1580494190563,"mc":[{"id":"1.168133543","rc":[{"batb":[[0,1.9,10],[1,1.86,1.19],[2,1.85,10]],"ltp":3.35,"tv":50.07,"id":10107355}]}]}
{"op":"mcm","clk":"990110868","pt":1580494198559,"mc":[{"id":"1.168133543","rc":[{"batb":[[0,2.06,3],[1,2.04,1.99],[2,1.93,3.85]],"ltp":5.7,"tv":41.15,"id":12636}]}]}
{"op":"mcm","clk":"990110961","pt":1580494199564,"mc":[{"id":"1.168133543","rc":[{"batb":[[1,1.51,4.36],[2,1.03,1692.42]],"ltp":0.0,"tv":0.0,"id":22308007},{"batb":[[1,1.68,16],[2,1.51,3.36]],"ltp":0.0,"tv":0.0,"id":7226819},{"batb":[[1,1.68,16],[2,1.51,3.36]],"ltp":0.0,"tv":0.0,"id":22121325},{"batb":[[1,1.51,4.36],[2,1.03,1704.17]],"ltp":0.0,"tv":0.0,"id":26548208},{"batb":[[1,1.51,4.36],[2,1.03,1743.65]],"ltp":0.0,"tv":0.0,"id":27606066},{"batb":[[1,1.51,4.36],[2,1.03,1724.33]],"ltp":0.0,"tv":0.0,"id":24270700},{"batb":[[1,1.51,4.36],[2,1.03,1547.12]],"ltp":0.0,"tv":0.0,"id":13306150}]}]}
{"op":"mcm","clk":"990110970","pt":1580494199663,"mc":[{"id":"1.168133543","rc":[{"batb":[[0,1.67,90],[1,1.66,1.99],[2,1.51,4.36]],"ltp":0.0,"tv":0.0,"id":22308007},{"batb":[[0,1.76,90],[1,1.75,1.99],[2,1.68,16]],"ltp":0.0,"tv":0.0,"id":7226819},{"batb":[[0,1.76,90],[1,1.75,1.99],[2,1.68,16]],"ltp":0.0,"tv":0.0,"id":22121325},{"batb":[[0,1.67,90],[1,1.66,1.99],[2,1.51,4.36]],"ltp":0.0,"tv":0.0,"id":26548208},{"batb":[[0,1.67,90],[1,1.66,1.99],[2,1.51,4.36]],"ltp":0.0,"tv":0.0,"id":27606066},{"batb":[[0,1.67,90],[1,1.66,1.99],[2,1.51,4.36]],"ltp":0.0,"tv":0.0,"id":24270700},{"batb":[[0,1.67,90],[1,1.66,1.99],[2,1.51,4.36]],"ltp":0.0,"tv":0.0,"id":13306150}]}]}
{"op":"mcm","clk":"990111637","pt":1580494206986,"mc":[{"id":"1.168133543","rc":[{"batb":[[0,3.4,20],[1,2.3,1.99],[2,2.26,9.57]],"ltp":0.0,"tv":0.0,"id":10163711}]}]}
{"op":"mcm","clk":"990112404","pt":1580494216180,"mc":[{"id":"1.168133543","rc":[{"batb":[[0,2.08,20.59],[1,2.06,3],[2,2.04,1.99]],"ltp":5.7,"tv":41.15,"id":12636},{"batb":[[2,2.24,90.72]],"ltp":0.0,"tv":0.0,"id":10163711},{"batb":[[2,1.83,3.03]],"ltp":3.35,"tv":50.07,"id":10107355}]}]}
{"op":"mcm","clk":"990112509","pt":1580494217495,"mc":[{"id":"1.168133543","rc":[{"batb":[[0,2.1,3],[1,2.08,20.59]],"ltp":5.7,"tv":41.15,"id":12636},{"batb":[[0,6.2,10],[1,1.76,90],[2,1.75,1.99]],"ltp":0.0,"tv":0.0,"id":22121325}]}]}
{"op":"mcm","clk":"990113659","pt":1580494229587,"mc":[{"id":"1.168133543","rc":[{"batb":[[0,12,6],[1,1.67,90],[2,1.66,1.99]],"ltp":0.0,"tv":0.0,"id":22308007}]}]}
{"op":"mcm","clk":"990113945","pt":1580494232459,"mc":[{"id":"1.168133543","rc":[{"batb":[[1,5.5,90],[2,3.7,30.37]],"ltp":0.0,"tv":0.0,"id":22308007},{"batb":[[2,2.24,90]],"ltp":0.0,"tv":0.0,"id":10163711},{"batb":[[1,3.9,90],[2,2.74,129.89]],"ltp":0.0,"tv":0.0,"id":22121325}]}]}
{"op":"mcm","clk":"990114153","pt":1580494234570,"mc":[{"id":"1.168133543","rc":[{"batb":[[0,1000,233.8]],"ltp":1000.0,"tv":0.4,"id":13819977}]}]}
{"op":"mcm","clk":"990114360","pt":1580494236574,"mc":[{"id":"1.168133543","rc":[{"batb":[[1,2.04,1.99],[2,1.93,3.85]],"ltp":5.7,"tv":41.15,"id":12636}]}]}
{"op":"mcm","clk":"990114813","pt":1580494241281,"mc":[{"id":"1.168133543","rc":[{"batb":[[0,13,7],[1,1.76,90],[2,1.75,1.99]],"ltp":0.0,"tv":0.0,"id":7226819}]}]}
{"op":"mcm","clk":"990115396","pt":1580494247797,"mc":[{"id":"1.168133543","rc":[{"batb":[[0,2.04,4.99],[1,1.93,3.85],[2,1.75,90]],"ltp":5.7,"tv":41.15,"id":12636}]}]}
{"op":"mcm","clk":"990116349","pt":1580494258418,"mc":[{"id":"1.168133543","rc":[{"batb":[[0,21,6],[1,1.67,90],[2,1.66,1.99]],"ltp":0.0,"tv":0.0,"id":13306150}]}]}
{"op":"mcm","clk":"990116576","pt":1580494260907,"mc":[{"id":"1.168133543","rc":[{"batb":[[0,2.06,3],[1,2.04,1.99],[2,1.93,3.85]],"ltp":5.7,"tv":41.15,"id":12636}]}]}
{"op":"mcm","clk":"990116978","pt":1580494265323,"mc":[{"id":"1.168133543","rc":[{"batb":[[1,5,90],[2,3.4,52.92]],"ltp":0.0,"tv":0.0,"id":7226819},{"batb":[[1,5.5,90],[2,3.7,30.37]],"ltp":0.0,"tv":0.0,"id":13306150}]}]}
{"op":"mcm","clk":"990117265","pt":1580494268214,"mc":[{"id":"1.168133543","rc":[{"batb":[[0,21,5],[1,1.67,90],[2,1.66,1.99]],"ltp":0.0,"tv":0.0,"id":26548208}]}]}
{"op":"mcm","clk":"990117960","pt":1580494275211,"mc":[{"id":"1.168133543","rc":[{"batb":[[0,2.04,4.99],[1,1.93,3.85],[2,1.75,90]],"ltp":5.7,"tv":41.15,"id":12636}]}]}
{"op":"mcm","clk":"990118287","pt":1580494279240,"mc":[{"id":"1.168133543","rc":[{"batb":[[0,1.91,4.99],[1,1.9,10],[2,1.86,1.19]],"ltp":3.35,"tv":50.07,"id":10107355},{"batb":[[0,1.68,6.68],[1,1.67,90],[2,1.66,1.99]],"ltp":0.0,"tv":0.0,"id":27606066},{"batb":[[0,1.68,6.68],[1,1.67,90],[2,1.66,1.99]],"ltp":0.0,"tv":0.0,"id":24270700}]}]}
{"op":"mcm","clk":"990118406","pt":1580494280550,"mc":[{"id":"1.168133543","rc":[{"batb":[[0,22,5],[1,1.68,6.68],[2,1.67,90]],"ltp":0.0,"tv":0.0,"id":24270700}]}]}
{"op":"mcm","clk":"990118482","pt":1580494281552,"mc":[{"id":"1.168133543","rc":[{"batb":[[0,3.45,1.86],[1,3.4,20],[2,2.3,1.99]],"ltp":0.0,"tv":0.0,"id":10163711}]}]}
{"op":"mcm","clk":"990118540","pt":1580494282137,"mc":[{"id":"1.168133543","rc":[{"batb":[[0,6.2,10.84]],"ltp":0.0,"tv":0.0,"id":22121325}]}]}
{"op":"mcm","clk":"990119024","pt":1580494287745,"mc":[{"id":"1.168133543","rc":[{"batb":[[0,2.06,3],[1,2.04,1.99],[2,1.93,3.85]],"ltp":5.7,"tv":41.15,"id":12636}]}]}
{"op":"mcm","clk":"990119428","pt":1580494292636,"mc":[{"id":"1.168133543","rc":[{"batb":[[0,22,5],[1,1.68,6.68],[2,1.67,90]],"ltp":0.0,"tv":0.0,"id":27606066}]}]}
{"op":"mcm","clk":"990119873","pt":1580494297558,"mc":[{"id":"1.168133543","rc":[{"batb":[[0,2.08,20.59],[1,2.06,3],[2,2.04,1.99]],"ltp":5.7,"tv":41.15,"id":12636},{"batb":[[0,1.92,22.31],[1,1.91,4.99],[2,1.9,10]],"ltp":3.35,"tv":50.07,"id":10107355}]}]}
{"op":"mcm","clk":"990119938","pt":1580494298070,"mc":[{"id":"1.168133543","rc":[{"batb":[[1,5,90],[2,3.4,52.92]],"ltp":0.0,"tv":0.0,"id":26548208},{"batb":[[1,5.5,90],[2,3.7,30.37]],"ltp":0.0,"tv":0.0,"id":27606066},{"batb":[[1,6,90],[2,4,12.33]],"ltp":0.0,"tv":0.0,"id":24270700}]}]}
{"op":"mcm","clk":"990120373","pt":1580494302555,"mc":[{"id":"1.168133543","rc":[{"batb":[[0,2.1,3],[1,2.08,20.59]],"ltp":5.7,"tv":41.15,"id":12636}]}]}
{"op":"mcm","clk":"990120640","pt":1580494304872,"mc":[{"id":"1.168133543","rc":[{"batb":[[0,2.1,10.59]],"ltp":5.7,"tv":41.15,"id":12636},{"batb":[[0,12.5,1.98],[1,12,6],[2,5.5,90]],"ltp":0.0,"tv":0.0,"id":22308007},{"batb":[[0,13.5,1.98],[1,13,7],[2,5,90]],"ltp":0.0,"tv":0.0,"id":7226819},{"batb":[[0,3.5,1.98],[1,3.45,1.86],[2,3.4,20]],"ltp":0.0,"tv":0.0,"id":10163711},{"batb":[[0,1.92,31.39]],"ltp":3.35,"tv":50.07,"id":10107355},{"batb":[[0,6.4,2.82],[1,6.2,10],[2,3.9,90]],"ltp":0.0,"tv":0.0,"id":22121325},{"batb":[[0,22,1.98],[1,21,5],[2,5,90]],"ltp":0.0,"tv":0.0,"id":26548208},{"batb":[[0,23,1.68],[1,22,5],[2,5.5,90]],"ltp":0.0,"tv":0.0,"id":27606066},{"batb":[[0,23,1.68],[1,22,5],[2,6,90]],"ltp":0.0,"tv":0.0,"id":24270700},{"batb":[[0,22,1.98],[1,21,6],[2,5.5,90]],"ltp":0.0,"tv":0.0,"id":13306150}]}]}
{"op":"mcm","clk":"990121031","pt":1580494309443,"mc":[{"id":"1.168133543","rc":[{"batb":[[1,1.9,10],[2,1.83,3.34]],"ltp":3.35,"tv":50.07,"id":10107355}]}]}
{"op":"mcm","clk":"990121300","pt":1580494312438,"mc":[{"id":"1.168133543","rc":[{"batb":[[0,2.12,3.03],[1,2.1,10.59],[2,2.08,20.59]],"batl":[[0,2.92,3.03],[1,2.94,50],[2,3,50]],"ltp":5.7,"tv":41.15,"id":12636},{"batb":[[0,1.93,3.03],[1,1.92,31.39],[2,1.9,10]],"ltp":3.35,"tv":50.07,"id":10107355}]}]}
{"op":"mcm","clk":"990121412","pt":1580494313537,"mc":[{"id":"1.168133543","rc":[{"batb":[[0,13.5,5.01]],"ltp":0.0,"tv":0.0,"id":7226819},{"batb":[[0,3.5,7.94]],"batl":[[0,850,3.23],[1,860,9]],"ltp":0.0,"tv":0.0,"id":10163711},{"batb":[[0,6.4,6.78]],"batl":[[0,850,3.23],[1,860,9]],"ltp":0.0,"tv":0.0,"id":22121325}]}]}
{"op":"mcm","clk":"990121520","pt":1580494314544,"mc":[{"id":"1.168133543","rc":[{"batl":[[0,65,3.03],[1,1000,0.2]],"ltp":0.0,"tv":0.0,"id":22308007}]}]}
{"op":"mcm","clk":"990121786","pt":1580494317483,"mc":[{"id":"1.168133543","rc":[{"batb":[[0,1.93,3.34]],"ltp":3.35,"tv":50.07,"id":10107355}]}]}
{"op":"mcm","clk":"990121877","pt":1580494318499,"mc":[{"id":"1.168133543","rc":[{"batb":[[0,2.14,22],[1,2.12,3.03],[2,2.1,10.59]],"ltp":5.7,"tv":41.15,"id":12636},{"batb":[[0,1.94,22.39],[1,1.93,3.03],[2,1.92,9.09]],"ltp":3.35,"tv":50.07,"id":10107355}]}]}
{"op":"mcm","clk":"990121974","pt":1580494319480,"mc":[{"id":"1.168133543","rc":[{"batb":[[0,3.55,1.99],[1,3.5,7.94],[2,3.45,1.86]],"ltp":0.0,"tv":0.0,"id":10163711},{"batb":[[0,6.6,1.99],[1,6.4,6.78],[2,6.2,10]],"ltp":0.0,"tv":0.0,"id":22121325}]}]}
{"op":"mcm","clk":"990122203","pt":1580494322198,"mc":[{"id":"1.168133543","rc":[{"batb":[[0,2.16,2.52],[1,2.14,22],[2,2.12,3.03]],"ltp":5.7,"tv":41.15,"id":12636},{"batb":[[0,12.5,4.5]],"ltp":0.0,"tv":0.0,"id":22308007},{"batb":[[0,13.5,7.53]],"ltp":0.0,"tv":0.0,"id":7226819},{"batb":[[0,3.55,4.51]],"ltp":0.0,"tv":0.0,"id":10163711},{"batb":[[0,1.95,2.52],[1,1.94,22.39],[2,1.93,3.03]],"ltp":3.35,"tv":50.07,"id":10107355},{"batb":[[0,6.6,4.51]],"ltp":0.0,"tv":0.0,"id":22121325},{"batb":[[0,22,4.5]],"ltp":0.0,"tv":0.0,"id":26548208},{"batb":[[0,23,4.2]],"ltp":0.0,"tv":0.0,"id":27606066},{"batb":[[0,23,4.2]],"ltp":0.0,"tv":0.0,"id":24270700},{"batb":[[0,22,4.5]],"ltp":0.0,"tv":0.0,"id":13306150}]}]}
{"op":"mcm","clk":"990122273","pt":1580494323107,"mc":[{"id":"1.168133543","rc":[{"batb":[[0,2.18,3],[1,2.16,2.52],[2,2.14,22]],"ltp":5.7,"tv":41.15,"id":12636}]}]}
{"op":"mcm","clk":"990122990","pt":1580494331493,"mc":[{"id":"1.168133543","rc":[{"batl":[[1,860,0]],"ltp":0.0,"tv":0.0,"id":10163711},{"batl":[[1,860,0]],"ltp":0.0,"tv":0.0,"id":22121325}]}]}
{"op":"mcm","clk":"990123043","pt":1580494332076,"mc":[{"id":"1.168133543","rc":[{"batl":[[0,830,9],[1,850,3.23]],"ltp":0.0,"tv":0.0,"id":10163711},{"batl":[[0,830,9],[1,850,3.23]],"ltp":0.0,"tv":0.0,"id":22121325}]}]}
{"op":"mcm","clk":"990123614","pt":1580494339189,"mc":[{"id":"1.168133543","rc":[{"batb":[[2,3.4,20]],"ltp":0.0,"tv":0.0,"id":10163711},{"batb":[[1,6.4,5.94]],"ltp":0.0,"tv":0.0,"id":22121325}]}]}
{"op":"mcm","clk":"990123749","pt":1580494340499,"mc":[{"id":"1.168133543","rc":[{"batb":[[0,2.2,19.47],[1,2.18,3],[2,2.16,2.52]],"ltp":5.7,"tv":41.15,"id":12636},{"batb":[[1,1.93,3.34],[2,1.92,9.09]],"ltp":3.35,"tv":50.07,"id":10107355}]}]}
{"op":"mcm","clk":"990124648","pt":1580494351309,"mc":[{"id":"1.168133543","rc":[{"batb":[[0,2.22,3],[1,2.2,19.47]],"ltp":5.7,"tv":41.15,"id":12636}]}]}
{"op":"mcm","clk":"990124856","pt":1580494353927,"mc":[{"id":"1.168133543","rc":[{"batb":[[0,2.22,3.74]],"ltp":5.7,"tv":41.15,"id":12636},{"batb":[[0,3.55,4.97]],"ltp":0.0,"tv":0.0,"id":10163711},{"batb":[[0,1.95,3.36]],"ltp":3.35,"tv":50.07,"id":10107355},{"batb":[[0,6.6,4.75]],"ltp":0.0,"tv":0.0,"id":22121325}]}]}
{"op":"mcm","clk":"990125549","pt":1580494361232,"mc":[{"id":"1.168133543","rc":[{"batb":[[1,2.16,2.52],[2,2.14,1.99]],"ltp":5.7,"tv":41.15,"id":12636}]}]}
{"op":"mcm","clk":"990125832","pt":1580494364552,"mc":[{"id":"1.168133543","rc":[{"batb":[[0,2.16,3.26],[1,2.14,1.99],[2,2.12,3.03]],"ltp":5.7,"tv":41.15,"id":12636}]}]}
{"op":"mcm","clk":"990125909","pt":1580494365443,"mc":[{"id":"1.168133543","rc":[{"batb":[[0,2.24,3],[1,2.16,3.26],[2,2.14,1.99]],"ltp":5.7,"tv":41.15,"id":12636}]}]}
{"op":"mcm","clk":"990127256","pt":1580494380756,"mc":[{"id":"1.168133543","rc":[{"batb":[[0,2.18,3.74],[1,2.16,2.52]],"ltp":5.7,"tv":41.15,"id":12636}]}]}
{"op":"mcm","clk":"990127387","pt":1580494382299,"mc":[{"id":"1.168133543","rc":[{"batb":[[0,2.2,20.21],[1,2.18,3],[2,2.16,2.52]],"ltp":5.7,"tv":41.15,"id":12636},{"batb":[[0,1.94,3.67],[1,1.93,3.03]],"ltp":3.35,"tv":50.07,"id":10107355}]}]}
{"op":"mcm","clk":"990128329","pt":1580494393559,"mc":[{"id":"1.168133543","rc":[{"batb":[[0,2.22,3.74],[1,2.2,19.47]],"ltp":5.7,"tv":41.15,"id":12636}]}]}
{"op":"mcm","clk":"990129151","pt":1580494402994,"mc":[{"id":"1.168133543","rc":[{"batb":[[1,2.16,2.52],[2,2.14,1.99]],"ltp":5.7,"tv":41.15,"id":12636},{"batb":[[0,1.95,22.8],[1,1.94,2.83],[2,1.93,3.03]],"ltp":3.35,"tv":50.07,"id":10107355}]}]}
{"op":"mcm","clk":"990129563","pt":1580494407498,"mc":[{"id":"1.168133543","rc":[{"batb":[[0,2.16,3.26],[1,2.14,1.99],[2,2.12,3.03]],"ltp":5.7,"tv":41.15,"id":12636}]}]}
{"op":"mcm","clk":"990129570","pt":1580494407599,"mc":[{"id":"1.168133543","rc":[{"batb":[[0,2.24,3],[1,2.16,3.26],[2,2.14,1.99]],"ltp":5.7,"tv":41.15,"id":12636}]}]}
{"op":"mcm","clk":"990130978","pt":1580494422024,"mc":[{"id":"1.168133543","rc":[{"batb":[[0,2.18,3.74],[1,2.16,2.52]],"ltp":5.7,"tv":41.15,"id":12636}]}]}
{"op":"mcm","clk":"990131125","pt":1580494423919,"mc":[{"id":"1.168133543","rc":[{"batb":[[0,2.2,20.21],[1,2.18,3],[2,2.16,2.52]],"ltp":5.7,"tv":41.15,"id":12636}]}]}
{"op":"mcm","clk":"990131983","pt":1580494433533,"mc":[{"id":"1.168133543","rc":[{"batb":[[1,2.16,2.52],[2,2.14,1.99]],"ltp":5.7,"tv":41.15,"id":12636}]}]}
{"op":"mcm","clk":"990131995","pt":1580494433641,"mc":[{"id":"1.168133543","rc":[{"batb":[[0,2.22,3.74],[1,2.2,19.47],[2,2.16,2.52]],"ltp":5.7,"tv":41.15,"id":12636}]}]}
{"op":"mcm","clk":"990132818","pt":1580494442521,"mc":[{"id":"1.168133543","rc":[{"batb":[[0,2.22,6.26]],"ltp":5.7,"tv":41.15,"id":12636},{"batb":[[0,1.96,3.36],[1,1.95,21.96],[2,1.94,2.83]],"ltp":3.35,"tv":50.07,"id":10107355}]}]}
{"op":"mcm","clk":"990133032","pt":1580494444832,"mc":[{"id":"1.168133543","rc":[{"batb":[[1,2.16,2.52],[2,2.14,1.99]],"ltp":5.7,"tv":41.15,"id":12636},{"batb":[[1,1.94,2.83],[2,1.93,3.03]],"ltp":3.35,"tv":50.07,"id":10107355}]}]}
{"op":"mcm","clk":"990133522","pt":1580494450128,"mc":[{"id":"1.168133543","rc":[{"batb":[[0,2.24,3],[1,2.22,3.26],[2,2.16,2.52]],"ltp":5.7,"tv":41.15,"id":12636}]}]}
{"op":"mcm","clk":"990135120","pt":1580494466526,"mc":[{"id":"1.168133543","rc":[{"batb":[[0,2.26,18.96],[1,2.24,3],[2,2.22,3.26]],"ltp":5.7,"tv":41.15,"id":12636}]}]}
{"op":"mcm","clk":"990135977","pt":1580494475423,"mc":[{"id":"1.168133543","rc":[{"batb":[[0,2.28,3],[1,2.26,18.96]],"ltp":5.7,"tv":41.15,"id":12636}]}]}
{"op":"mcm","clk":"990136041","pt":1580494476259,"mc":[{"id":"1.168133543","rc":[{"batb":[[0,2.3,1.99],[1,2.28,3],[2,2.26,18.96]],"ltp":5.7,"tv":41.15,"id":12636},{"batb":[[0,1.96,3.67],[1,1.94,2.52]],"ltp":3.35,"tv":50.07,"id":10107355}]}]}
{"op":"mcm","clk":"990136138","pt":1580494477532,"mc":[{"id":"1.168133543","rc":[{"batb":[[0,3.65,1.99],[1,3.55,2.98],[2,3.5,7.94]],"ltp":0.0,"tv":0.0,"id":10163711},{"batb":[[0,7,1.99],[1,6.6,2.76],[2,6.4,5.94]],"ltp":0.0,"tv":0.0,"id":22121325}]}]}
{"op":"mcm","clk":"990137030","pt":1580494486277,"mc":[{"id":"1.168133543","rc":[{"batb":[[2,2.22,3.26]],"ltp":5.7,"tv":41.15,"id":12636}]}]}
{"op":"mcm","clk":"990137172","pt":1580494487557,"mc":[{"id":"1.168133543","rc":[{"batb":[[0,2.34,3],[1,2.32,18.46],[2,2.3,1.99]],"ltp":5.7,"tv":41.15,"id":12636}]}]}
{"op":"mcm","clk":"990137278","pt":1580494488555,"mc":[{"id":"1.168133543","rc":[{"batb":[[2,2.3,9.58]],"ltp":5.7,"tv":41.15,"id":12636},{"batb":[[0,3.7,1.98],[1,3.65,1.99],[2,3.55,2.98]],"ltp":0.0,"tv":0.0,"id":10163711},{"batb":[[0,1.96,12.76]],"ltp":3.35,"tv":50.07,"id":10107355},{"batb":[[0,7.2,1.98],[1,7,1.99],[2,6.6,2.76]],"ltp":0.0,"tv":0.0,"id":22121325}]}]}
{"op":"mcm","clk":"990138542","pt":1580494502292,"mc":[{"id":"1.168133543","rc":[{"batb":[[0,2.34,5.52]],"ltp":5.7,"tv":41.15,"id":12636}]}]}
{"op":"mcm","clk":"990138957","pt":1580494506863,"mc":[{"id":"1.168133543","rc":[{"batb":[[1,2.3,9.58],[2,2.22,3.26]],"ltp":5.7,"tv":41.15,"id":12636}]}]}
{"op":"mcm","clk":"990139316","pt":1580494510762,"mc":[{"id":"1.168133543","rc":[{"batb":[[2,2.22,2.52]],"ltp":5.7,"tv":41.15,"id":12636}]}]}
{"op":"mcm","clk":"990139410","pt":1580494511779,"mc":[{"id":"1.168133543","rc":[{"batb":[[0,2.36,3],[1,2.34,2.52],[2,2.3,9.58]],"ltp":5.7,"tv":41.15,"id":12636}]}]}
{"op":"mcm","clk":"990140110","pt":1580494520569,"mc":[{"id":"1.168133543","rc":[{"batb":[[2,2.32,3.45]],"ltp":5.7,"tv":41.15,"id":12636},{"batb":[[0,1.97,5],[1,1.96,12.45],[2,1.94,2.52]],"ltp":3.35,"tv":50.07,"id":10107355}]}]}
{"op":"mcm","clk":"990140603","pt":1580494526384,"mc":[{"id":"1.168133543","rc":[{"batb":[[0,2.36,3.69]],"ltp":5.7,"tv":41.15,"id":12636}]}]}
{"op":"mcm","clk":"990140641","pt":1580494526952,"mc":[{"id":"1.168133543","rc":[{"batb":[[0,2.38,18.69],[1,2.36,3],[2,2.34,2.52]],"ltp":5.7,"tv":41.15,"id":12636},{"batb":[[0,1.98,21.63],[1,1.97,5],[2,1.96,12.45]],"ltp":3.35,"tv":50.07,"id":10107355}]}]}
{"op":"mcm","clk":"990141290","pt":1580494534387,"mc":[{"id":"1.168133543","rc":[{"batb":[[0,2.4,3],[1,2.38,18.69]],"ltp":5.7,"tv":41.15,"id":12636}]}]}
{"op":"mcm","clk":"990142477","pt":1580494547500,"mc":[{"id":"1.168133543","rc":[{"batb":[[1,2.34,3.21],[2,2.32,3.45]],"ltp":5.7,"tv":41.15,"id":12636}]}]}
{"op":"mcm","clk":"990142648","pt":1580494549502,"mc":[{"id":"1.168133543","rc":[{"batb":[[0,2.36,3.69],[1,2.34,2.52]],"ltp":5.7,"tv":41.15,"id":12636},{"batb":[[0,1.99,4.59],[1,1.98,21.63],[2,1.96,12.76]],"ltp":3.35,"tv":50.07,"id":10107355}]}]}
{"op":"mcm","clk":"990144036","pt":1580494561831,"mc":[{"id":"1.168133543","rc":[{"batb":[[0,1.99,7.11]],"ltp":3.35,"tv":50.07,"id":10107355}]}]}
{"op":"mcm","clk":"990144382","pt":1580494565538,"mc":[{"id":"1.168133543","rc":[{"batb":[[0,2.34,3.21],[1,2.32,3.45],[2,2.3,9.58]],"ltp":5.7,"tv":41.15,"id":12636}]}]}
{"op":"mcm","clk":"990144396","pt":1580494565644,"mc":[{"id":"1.168133543","rc":[{"batb":[[0,2.38,3.69],[1,2.34,2.52],[2,2.32,3.45]],"ltp":5.7,"tv":41.15,"id":12636}]}]}
{"op":"mcm","clk":"990144588","pt":1580494567738,"mc":[{"id":"1.168133543","rc":[{"batb":[[1,1.96,12.76],[2,1.94,2.52]],"ltp":3.35,"tv":50.07,"id":10107355}]}]}
{"op":"mcm","clk":"990146295","pt":1580494583464,"mc":[{"id":"1.168133543","rc":[{"batb":[[0,2.34,3.21],[1,2.32,3.45],[2,2.3,9.58]],"ltp":5.7,"tv":41.15,"id":12636}]}]}
{"op":"mcm","clk":"990146317","pt":1580494583634,"mc":[{"id":"1.168133543","rc":[{"batb":[[0,2.4,3],[1,2.34,3.21],[2,2.32,3.45]],"ltp":5.7,"tv":41.15,"id":12636}]}]}
{"op":"mcm","clk":"990148032","pt":1580494598545,"mc":[{"id":"1.168133543","rc":[{"batb":[[0,2.36,3.69],[1,2.34,2.52]],"ltp":5.7,"tv":41.15,"id":12636}]}]}
{"op":"mcm","clk":"990148978","pt":1580494608479,"mc":[{"id":"1.168133543","rc":[{"batb":[[0,2.38,18.69],[1,2.36,3],[2,2.34,2.52]],"ltp":5.7,"tv":41.15,"id":12636}]}]}
{"op":"mcm","clk":"990149081","pt":1580494609568,"mc":[{"id":"1.168133543","rc":[{"batb":[[0,2.4,3.25],[1,2.38,18.69],[2,2.36,3]],"ltp":5.7,"tv":41.15,"id":12636}]}]}
{"op":"mcm","clk":"990149425","pt":1580494613277,"mc":[{"id":"1.168133543","rc":[{"batb":[[0,2.42,3],[1,2.4,3.25],[2,2.38,18.69]],"ltp":5.7,"tv":41.15,"id":12636}]}]}
{"op":"mcm","clk":"990150291","pt":1580494621897,"mc":[{"id":"1.168133543","rc":[{"batb":[[0,2.42,5.52]],"ltp":5.7,"tv":41.15,"id":12636}]}]}
{"op":"mcm","clk":"990150876","pt":1580494628218,"mc":[{"id":"1.168133543","rc":[{"batb":[[0,2.44,3],[1,2.42,2.52],[2,2.4,3.25]],"ltp":5.7,"tv":41.15,"id":12636}]}]}
{"op":"mcm","clk":"990151028","pt":1580494629605,"mc":[{"id":"1.168133543","rc":[{"batb":[[0,2.46,17.41],[1,2.44,3],[2,2.42,2.52]],"ltp":5.7,"tv":41.15,"id":12636}]}]}
{"op":"mcm","clk":"990152010","pt":1580494639813,"mc":[{"id":"1.168133543","rc":[{"batb":[[0,2.48,3.07],[1,2.46,17.41],[2,2.44,3]],"ltp":5.7,"tv":41.15,"id":12636}]}]}
{"op":"mcm","clk":"990152283","pt":1580494642503,"mc":[{"id":"1.168133543","rc":[{"batb":[[0,2.5,3],[1,2.48,3.07],[2,2.46,17.41]],"ltp":5.7,"tv":41.15,"id":12636}]}]}
{"op":"mcm","clk":"990153006","pt":1580494650295,"mc":[{"id":"1.168133543","rc":[{"batb":[[0,2.52,17],[1,2.5,3],[2,2.48,3.07]],"ltp":5.7,"tv":41.15,"id":12636}]}]}
{"op":"mcm","clk":"990153421","pt":1580494654510,"mc":[{"id":"1.168133543","rc":[{"batb":[[1,2.48,3.07],[2,2.42,2.52]],"ltp":5.7,"tv":41.15,"id":12636}]}]}
{"op":"mcm","clk":"990153435","pt":1580494654612,"mc":[{"id":"1.168133543","rc":[{"batb":[[0,2.54,3],[1,2.52,17],[2,2.48,3.07]],"ltp":5.7,"tv":41.15,"id":12636}]}]}
{"op":"mcm","clk":"990153892","pt":1580494659504,"mc":[{"id":"1.168133543","rc":[{"batb":[[0,2.56,1.99],[1,2.54,3],[2,2.52,17]],"ltp":5.7,"tv":41.15,"id":12636},{"batb":[[0,1.99,7.42],[1,1.96,12.45]],"ltp":3.35,"tv":50.07,"id":10107355}]}]}
{"op":"mcm","clk":"990154074","pt":1580494661344,"mc":[{"id":"1.168133543","rc":[{"batb":[[0,3.75,1.99],[1,3.7,1.98]],"ltp":0.0,"tv":0.0,"id":10163711},{"batb":[[0,7.4,1.99],[1,7.2,1.98]],"ltp":0.0,"tv":0.0,"id":22121325}]}]}
{"op":"mcm","clk":"990154812","pt":1580494669339,"mc":[{"id":"1.168133543","rc":[{"batb":[[0,2.58,3],[1,2.56,2.63]],"ltp":5.7,"tv":41.15,"id":12636}]}]}
{"op":"mcm","clk":"990155138","pt":1580494672341,"mc":[{"id":"1.168133543","rc":[{"batb":[[0,2.6,16.48],[1,2.58,3],[2,2.56,2.63]],"ltp":5.7,"tv":41.15,"id":12636}]}]}
{"op":"mcm","clk":"990156021","pt":1580494681542,"mc":[{"id":"1.168133543","rc":[{"batb":[[0,2.62,2.52],[1,2.6,16.48]],"ltp":5.7,"tv":41.15,"id":12636}]}]}
{"op":"mcm","clk":"990156036","pt":1580494681647,"mc":[{"id":"1.168133543","rc":[{"batb":[[0,2.62,5.52]],"ltp":5.7,"tv":41.15,"id":12636}]}]}
{"op":"mcm","clk":"990157153","pt":1580494692493,"mc":[{"id":"1.168133543","rc":[{"batb":[[0,2.64,3],[1,2.62,2.52],[2,2.6,16.48]],"ltp":5.7,"tv":41.15,"id":12636}]}]}
{"op":"mcm","clk":"990157285","pt":1580494693573,"mc":[{"id":"1.168133543","rc":[{"batb":[[0,2.66,16.1],[1,2.64,3],[2,2.62,2.52]],"ltp":5.7,"tv":41.15,"id":12636}]}]}
{"op":"mcm","clk":"990158188","pt":1580494702158,"mc":[{"id":"1.168133543","rc":[{"batb":[[0,2.68,3],[1,2.66,16.1]],"ltp":5.7,"tv":41.15,"id":12636}]}]}
{"op":"mcm","clk":"990158519","pt":1580494705387,"mc":[{"id":"1.168133543","rc":[{"trd":[[1000,3.76]],"batb":[[0,1000,232.12]],"ltp":1000.0,"tv":3.75,"id":13819977}],"tv":94.98}]}
{"op":"mcm","clk":"990159332","pt":1580494713281,"mc":[{"id":"1.168133543","rc":[{"batb":[[1,2.62,2.52],[2,2.56,2.63]],"ltp":5.7,"tv":41.15,"id":12636}]}]}
{"op":"mcm","clk":"990159502","pt":1580494714696,"mc":[{"id":"1.168133543","rc":[{"batb":[[0,2.64,3]],"ltp":5.7,"tv":41.15,"id":12636}]}]}
{"op":"mcm","clk":"990161570","pt":1580494734962,"mc":[{"id":"1.168133543","rc":[{"batb":[[0,2.66,16.1],[1,2.64,3],[2,2.62,2.52]],"ltp":5.7,"tv":41.15,"id":12636}]}]}
{"op":"mcm","clk":"990162179","pt":1580494741356,"mc":[{"id":"1.168133543","rc":[{"batb":[[0,2.68,3],[1,2.66,16.1]],"ltp":5.7,"tv":41.15,"id":12636}]}]}
{"op":"mcm","clk":"990162298","pt":1580494742574,"mc":[{"id":"1.168133543","rc":[{"batb":[[0,2.68,5.52]],"ltp":5.7,"tv":41.15,"id":12636}]}]}
{"op":"mcm","clk":"990163656","pt":1580494755376,"mc":[{"id":"1.168133543","rc":[{"batb":[[0,2.7,3],[1,2.68,2.52]],"ltp":5.7,"tv":41.15,"id":12636}]}]}
{"op":"mcm","clk":"990164730","pt":1580494766521,"mc":[{"id":"1.168133543","rc":[{"batb":[[0,2.7,3.61]],"ltp":5.7,"tv":41.15,"id":12636}]}]}
{"op":"mcm","clk":"990165272","pt":1580494772499,"mc":[{"id":"1.168133543","rc":[{"batb":[[0,2.72,3.61],[1,2.7,7.59],[2,2.68,2.52]],"ltp":5.7,"tv":41.15,"id":12636},{"batb":[[1,400,4.2],[2,6,90]],"ltp":1000.0,"tv":3.75,"id":13819977},{"batb":[[0,3.8,1.98],[1,3.75,1.99]],"ltp":0.0,"tv":0.0,"id":10163711},{"batb":[[0,1.99,16.51],[1,1.96,3.36]],"ltp":3.35,"tv":50.07,"id":10107355},{"batb":[[0,7.6,1.98],[1,7.4,1.99]],"ltp":0.0,"tv":0.0,"id":22121325}]}]}
{"op":"mcm","clk":"990165619","pt":1580494776237,"mc":[{"id":"1.168133543","rc":[{"batb":[[0,2.74,15.63],[1,2.72,3.61],[2,2.7,7.59]],"ltp":5.7,"tv":41.15,"id":12636}]}]}
{"op":"mcm","clk":"990166640","pt":1580494786451,"mc":[{"id":"1.168133543","rc":[{"batb":[[0,2.76,3],[1,2.74,15.63],[2,2.7,8.2]],"ltp":5.7,"tv":41.15,"id":12636}]}]}
{"op":"mcm","clk":"990166968","pt":1580494789559,"mc":[{"id":"1.168133543","rc":[{"batb":[[0,1.99,11.92]],"ltp":3.35,"tv":50.07,"id":10107355}]}]}
{"op":"mcm","clk":"990167852","pt":1580494798716,"mc":[{"id":"1.168133543","rc":[{"batb":[[1,2.7,8.2],[2,2.68,2.52]],"ltp":5.7,"tv":41.15,"id":12636}]}]}
{"op":"mcm","clk":"990168238","pt":1580494802510,"mc":[{"id":"1.168133543","rc":[{"batb":[[0,2.78,2.96],[1,2.76,3],[2,2.72,3.12]],"ltp":5.7,"tv":41.15,"id":12636},{"batb":[[0,2,4.43],[1,1.99,11.61],[2,1.96,3.36]],"ltp":3.35,"tv":50.07,"id":10107355}]}]}
{"op":"mcm","clk":"990168344","pt":1580494803511,"mc":[{"id":"1.168133543","rc":[{"batb":[[0,12.5,5.26]],"ltp":0.0,"tv":0.0,"id":22308007},{"batb":[[0,13.5,8.24]],"ltp":0.0,"tv":0.0,"id":7226819},{"batb":[[0,3.8,4.15]],"ltp":0.0,"tv":0.0,"id":10163711},{"batb":[[0,7.6,3.07]],"ltp":0.0,"tv":0.0,"id":22121325},{"batb":[[0,22,4.93]],"ltp":0.0,"tv":0.0,"id":26548208},{"batb":[[0,23,4.61]],"ltp":0.0,"tv":0.0,"id":27606066},{"batb":[[0,23,4.61]],"ltp":0.0,"tv":0.0,"id":24270700},{"batb":[[0,22,4.93]],"ltp":0.0,"tv":0.0,"id":13306150}]}]}
{"op":"mcm","clk":"990168786","pt":1580494807513,"mc":[{"id":"1.168133543","rc":[{"batb":[[1,3.55,2.98],[2,3.5,5.96]],"ltp":0.0,"tv":0.0,"id":10163711}]}]}
{"op":"mcm","clk":"990168863","pt":1580494808305,"mc":[{"id":"1.168133543","rc":[{"batb":[[0,3.85,1.99],[1,3.8,4.15],[2,3.55,2.98]],"ltp":0.0,"tv":0.0,"id":10163711},{"batb":[[0,7.8,1.99],[1,7.6,3.07]],"ltp":0.0,"tv":0.0,"id":22121325}]}]}
{"op":"mcm","clk":"990169082","pt":1580494810316,"mc":[{"id":"1.168133543","rc":[{"batb":[[0,2.8,3],[1,2.78,2.96]],"ltp":5.7,"tv":41.15,"id":12636}]}]}
{"op":"mcm","clk":"990170145","pt":1580494819517,"mc":[{"id":"1.168133543","rc":[{"batb":[[0,2.02,21.21],[1,2,4.43],[2,1.99,11.61]],"ltp":3.35,"tv":50.07,"id":10107355}]}]}
{"op":"mcm","clk":"990170194","pt":1580494819891,"mc":[{"id":"1.168133543","rc":[{"batb":[[1,2,8.97]],"ltp":3.35,"tv":50.07,"id":10107355}]}]}
{"op":"mcm","clk":"990170418","pt":1580494821790,"mc":[{"id":"1.168133543","rc":[{"batb":[[0,3.85,3.59]],"ltp":0.0,"tv":0.0,"id":10163711}]}]}
{"op":"mcm","clk":"990170819","pt":1580494825451,"mc":[{"id":"1.168133543","rc":[{"trd":[[2.8,6]],"batb":[[0,2.78,2.96],[1,2.72,3.12],[2,2.7,7.59]],"ltp":2.8,"tv":47.15,"id":12636}],"tv":100.98}]}
{"op":"mcm","clk":"990172062","pt":1580494837418,"mc":[{"id":"1.168133543","rc":[{"batb":[[0,2.04,3.03],[1,2.02,21.21],[2,2,8.97]],"ltp":3.35,"tv":50.07,"id":10107355}]}]}
{"op":"mcm","clk":"990172197","pt":1580494838518,"mc":[{"id":"1.168133543","rc":[{"batb":[[0,3.9,3.03],[1,3.85,3.59],[2,3.8,4.15]],"batl":[[0,820,3.23],[1,830,9]],"ltp":0.0,"tv":0.0,"id":10163711},{"batb":[[0,7.8,5.02]],"batl":[[0,830,9.2],[1,850,0]],"ltp":0.0,"tv":0.0,"id":22121325}]}]}
{"op":"mcm","clk":"990172319","pt":1580494839523,"mc":[{"id":"1.168133543","rc":[{"batb":[[0,13,3.79],[1,12.5,4.5],[2,12,6]],"ltp":0.0,"tv":0.0,"id":22308007},{"batb":[[0,13.5,12.84]],"ltp":0.0,"tv":0.0,"id":7226819},{"batb":[[1,2,8.97],[2,1.99,11.61]],"ltp":3.35,"tv":50.07,"id":10107355},{"batl":[[0,820,3.23],[1,830,9]],"ltp":0.0,"tv":0.0,"id":22121325}]}]}
{"op":"mcm","clk":"990172830","pt":1580494844164,"mc":[{"id":"1.168133543","rc":[{"trd":[[2.78,4]],"batb":[[0,2.72,4.09],[1,2.7,7.59],[2,2.68,2.52]],"ltp":2.78,"tv":51.15,"id":12636}],"tv":104.98}]}
{"op":"mcm","clk":"990173460","pt":1580494850459,"mc":[{"id":"1.168133543","rc":[{"batb":[[1,3.85,1.99]],"ltp":0.0,"tv":0.0,"id":10163711},{"batb":[[1,2.02,4.46],[2,2,4.43]],"ltp":3.35,"tv":50.07,"id":10107355}]}]}
{"op":"mcm","clk":"990173649","pt":1580494852254,"mc":[{"id":"1.168133543","rc":[{"batb":[[0,3.95,1.54],[1,3.9,3.03],[2,3.85,1.99]],"ltp":0.0,"tv":0.0,"id":10163711}]}]}
{"op":"mcm","clk":"990174000","pt":1580494855526,"mc":[{"id":"1.168133543","rc":[{"batl":[[0,800,9],[1,820,3.23]],"ltp":0.0,"tv":0.0,"id":10163711},{"batl":[[0,800,9],[1,820,3.23]],"ltp":0.0,"tv":0.0,"id":22121325}]}]}
{"op":"mcm","clk":"990174199","pt":1580494857394,"mc":[{"id":"1.168133543","rc":[{"batl":[[0,2.92,23.03]],"ltp":2.78,"tv":51.15,"id":12636}]}]}
{"op":"mcm","clk":"990174509","pt":1580494860326,"mc":[{"id":"1.168133543","rc":[{"batl":[[0,800,9.2],[1,820,3.03]],"ltp":0.0,"tv":0.0,"id":10163711},{"batl":[[0,800,9.2],[1,820,3.03]],"ltp":0.0,"tv":0.0,"id":22121325}]}]}
{"op":"mcm","clk":"990174621","pt":1580494861123,"mc":[{"id":"1.168133543","rc":[{"batb":[[0,2.06,20.79],[1,2.04,3.03],[2,2.02,4.46]],"ltp":3.35,"tv":50.07,"id":10107355}]}]}
{"op":"mcm","clk":"990174758","pt":1580494862201,"mc":[{"id":"1.168133543","rc":[{"batb":[[1,3.9,5.55]],"ltp":0.0,"tv":0.0,"id":10163711},{"batb":[[0,2.08,2.52],[1,2.06,20.79],[2,2.04,3.03]],"ltp":3.35,"tv":50.07,"id":10107355},{"batb":[[0,7.8,7.54]],"ltp":0.0,"tv":0.0,"id":22121325}]}]}
{"op":"mcm","clk":"990176257","pt":1580494876530,"mc":[{"id":"1.168133543","rc":[{"batl":[[2,2.96,50]],"ltp":2.78,"tv":51.15,"id":12636}]}]}
{"op":"mcm","clk":"990176589","pt":1580494879521,"mc":[{"id":"1.168133543","rc":[{"batb":[[0,2.08,6.73]],"ltp":3.35,"tv":50.07,"id":10107355}]}]}
{"op":"mcm","clk":"990176756","pt":1580494881467,"mc":[{"id":"1.168133543","rc":[{"batb":[[1,2.04,3.03],[2,2,4.43]],"ltp":3.35,"tv":50.07,"id":10107355}]}]}
{"op":"mcm","clk":"990177419","pt":1580494886973,"mc":[{"id":"1.168133543","rc":[{"batb":[[2,1.99,11.92]],"ltp":3.35,"tv":50.07,"id":10107355}]}]}
{"op":"mcm","clk":"990178708","pt":1580494899365,"mc":[{"id":"1.168133543","rc":[{"batb":[[0,2.1,2.65],[1,2.08,6.73],[2,2.04,3.03]],"ltp":3.35,"tv":50.07,"id":10107355}]}]}
{"op":"mcm","clk":"990179016","pt":1580494902758,"mc":[{"id":"1.168133543","rc":[{"batb":[[0,2.12,20.21],[1,2.1,2.65],[2,2.08,6.73]],"ltp":3.35,"tv":50.07,"id":10107355}]}]}
{"op":"mcm","clk":"990179704","pt":1580494909763,"mc":[{"id":"1.168133543","rc":[{"batb":[[0,2.14,3.99],[1,2.12,20.21],[2,2.1,2.65]],"ltp":3.35,"tv":50.07,"id":10107355}]}]}
{"op":"mcm","clk":"990180631","pt":1580494919168,"mc":[{"id":"1.168133543","rc":[{"batb":[[0,2.88,1.68],[1,2.72,4.09],[2,2.7,7.59]],"ltp":2.78,"tv":51.15,"id":12636}]}]}
{"op":"mcm","clk":"990180854","pt":1580494921313,"mc":[{"id":"1.168133543","rc":[{"batb":[[0,2.9,1.68]],"ltp":2.78,"tv":51.15,"id":12636}]}]}
{"op":"mcm","clk":"990181001","pt":1580494922573,"mc":[{"id":"1.168133543","rc":[{"batb":[[0,2.72,4.09],[1,2.7,7.59],[2,2.68,2.52]],"ltp":2.78,"tv":51.15,"id":12636},{"batb":[[0,2.14,6.51]],"ltp":3.35,"tv":50.07,"id":10107355}]}]}
{"op":"mcm","clk":"990181079","pt":1580494923515,"mc":[{"id":"1.168133543","rc":[{"trd":[[2.92,46.06]],"batb":[[0,2.92,9.43],[1,2.72,4.09],[2,2.7,7.59]],"batl":[[0,2.94,50],[1,2.96,50],[2,9.2,9]],"ltp":2.92,"tv":97.21,"id":12636}],"tv":151.04}]}
{"op":"mcm","clk":"990181170","pt":1580494924303,"mc":[{"id":"1.168133543","rc":[{"batb":[[1,2.1,2.65],[2,2.08,2.52]],"ltp":3.35,"tv":50.07,"id":10107355}]}]}
{"op":"mcm","clk":"990181310","pt":1580494925512,"mc":[{"id":"1.168133543","rc":[{"batb":[[0,2.72,4.09],[1,2.7,7.59],[2,2.68,2.52]],"ltp":2.92,"tv":97.21,"id":12636}]}]}
{"op":"mcm","clk":"990181415","pt":1580494926414,"mc":[{"id":"1.168133543","rc":[{"trd":[[2.94,18.72]],"batl":[[0,2.94,40.64]],"ltp":2.94,"tv":115.93,"id":12636}],"tv":169.77}]}
{"op":"mcm","clk":"990183997","pt":1580494949333,"mc":[{"id":"1.168133543","rc":[{"batl":[[0,2.96,2.6]],"ltp":3.35,"tv":50.07,"id":10107355}]}]}
{"op":"mcm","clk":"990184203","pt":1580494951218,"mc":[{"id":"1.168133543","rc":[{"batl":[[0,2.96,2.18]],"ltp":3.35,"tv":50.07,"id":10107355}]}]}
{"op":"mcm","clk":"990193983","pt":1580494953044,"mc":[{"id":"1.168133543","rc":[{"batb":[[0,4,1.99],[1,3.95,1.54],[2,3.9,5.55]],"ltp":0.0,"tv":0.0,"id":10163711},{"batl":[[0,2.96,2.6]],"ltp":3.35,"tv":50.07,"id":10107355}]}]}
{"op":"mcm","clk":"990194244","pt":1580494955355,"mc":[{"id":"1.168133543","rc":[{"batl":[[0,2.96,2]],"ltp":3.35,"tv":50.07,"id":10107355}]}]}
{"op":"mcm","clk":"990194416","pt":1580494956936,"mc":[{"id":"1.168133543","rc":[{"batl":[[0,2.96,2.42]],"ltp":3.35,"tv":50.07,"id":10107355}]}]}
{"op":"mcm","clk":"990194585","pt":1580494958451,"mc":[{"id":"1.168133543","rc":[{"batl":[[0,2.96,2]],"ltp":3.35,"tv":50.07,"id":10107355}]}]}
{"op":"mcm","clk":"990194757","pt":1580494960431,"mc":[{"id":"1.168133543","rc":[{"batl":[[0,2.96,2.42]],"ltp":3.35,"tv":50.07,"id":10107355}]}]}
{"op":"mcm","clk":"990194839","pt":1580494961428,"mc":[{"id":"1.168133543","rc":[{"batl":[[0,2.92,4],[1,2.94,40.64],[2,2.96,50]],"ltp":2.94,"tv":115.93,"id":12636},{"batl":[[0,2.96,2]],"ltp":3.35,"tv":50.07,"id":10107355}]}]}
{"op":"mcm","clk":"990194919","pt":1580494962464,"mc":[{"id":"1.168133543","rc":[{"batl":[[0,2.96,2.18]],"ltp":3.35,"tv":50.07,"id":10107355}]}]}
{"op":"mcm","clk":"990194984","pt":1580494963248,"mc":[{"id":"1.168133543","rc":[{"batl":[[0,2.96,2.6]],"ltp":3.35,"tv":50.07,"id":10107355}]}]}
{"op":"mcm","clk":"990195140","pt":1580494964926,"mc":[{"id":"1.168133543","rc":[{"batl":[[0,2.96,2.18]],"ltp":3.35,"tv":50.07,"id":10107355}]}]}
{"op":"mcm","clk":"990195387","pt":1580494967540,"mc":[{"id":"1.168133543","rc":[{"trd":[[2.14,0.84]],"batb":[[0,2.14,6.09]],"ltp":2.14,"tv":50.91,"id":10107355}],"tv":170.61}]}
{"op":"mcm","clk":"990196352","pt":1580494978364,"mc":[{"id":"1.168133543","rc":[{"batb":[[0,2.14,6.51]],"ltp":2.14,"tv":50.91,"id":10107355}]}]}
{"op":"mcm","clk":"990196515","pt":1580494980453,"mc":[{"id":"1.168133543","rc":[{"batb":[[0,2.14,6.09]],"ltp":2.14,"tv":50.91,"id":10107355}]}]}
{"op":"mcm","clk":"990196616","pt":1580494981485,"mc":[{"id":"1.168133543","rc":[{"batb":[[0,2.14,6.51]],"ltp":2.14,"tv":50.91,"id":10107355}]}]}
{"op":"mcm","clk":"990196773","pt":1580494983162,"mc":[{"id":"1.168133543","rc":[{"batb":[[0,2.14,6.09]],"ltp":2.14,"tv":50.91,"id":10107355}]}]}
{"op":"mcm","clk":"990196909","pt":1580494984890,"mc":[{"id":"1.168133543","rc":[{"batb":[[0,2.14,6.51]],"ltp":2.14,"tv":50.91,"id":10107355}]}]}
{"op":"mcm","clk":"990197115","pt":1580494986462,"mc":[{"id":"1.168133543","rc":[{"batb":[[0,2.14,6.09]],"ltp":2.14,"tv":50.91,"id":10107355}]}]}
{"op":"mcm","clk":"990197205","pt":1580494987357,"mc":[{"id":"1.168133543","rc":[{"batb":[[0,2.14,6.51]],"ltp":2.14,"tv":50.91,"id":10107355}]}]}
{"op":"mcm","clk":"990197379","pt":1580494989283,"mc":[{"id":"1.168133543","rc":[{"batb":[[0,2.14,6.09]],"ltp":2.14,"tv":50.91,"id":10107355}]}]}
{"op":"mcm","clk":"990197566","pt":1580494991175,"mc":[{"id":"1.168133543","rc":[{"batb":[[0,2.14,6.51]],"ltp":2.14,"tv":50.91,"id":10107355}]}]}
{"op":"mcm","clk":"990197633","pt":1580494992067,"mc":[{"id":"1.168133543","rc":[{"batb":[[0,2.14,6.09]],"ltp":2.14,"tv":50.91,"id":10107355}]}]}
{"op":"mcm","clk":"990197848","pt":1580494994279,"mc":[{"id":"1.168133543","rc":[{"batb":[[0,2.14,6.51]],"ltp":2.14,"tv":50.91,"id":10107355}]}]}
{"op":"mcm","clk":"990197969","pt":1580494995587,"mc":[{"id":"1.168133543","rc":[{"batb":[[0,2.14,6.09]],"ltp":2.14,"tv":50.91,"id":10107355}]}]}
{"op":"mcm","clk":"990198489","pt":1580495001412,"mc":[{"id":"1.168133543","rc":[{"batb":[[0,2.14,6.51]],"ltp":2.14,"tv":50.91,"id":10107355}]}]}
{"op":"mcm","clk":"990199188","pt":1580495008487,"mc":[{"id":"1.168133543","rc":[{"batb":[[0,2.14,6.09]],"ltp":2.14,"tv":50.91,"id":10107355}]}]}
{"op":"mcm","clk":"990199427","pt":1580495011399,"mc":[{"id":"1.168133543","rc":[{"batb":[[0,2.72,11.68],[1,2.68,2.52],[2,2.62,2.52]],"ltp":2.94,"tv":115.93,"id":12636},{"batb":[[0,13.5,1.98],[1,13,3.79],[2,12.5,2.52]],"ltp":0.0,"tv":0.0,"id":22308007},{"batb":[[0,4.1,1.98],[1,4,1.99],[2,3.95,1.54]],"ltp":0.0,"tv":0.0,"id":10163711},{"batb":[[0,2.14,15.18]],"ltp":2.14,"tv":50.91,"id":10107355},{"batb":[[0,8,1.98],[1,7.8,7.54],[2,7.6,1.08]],"ltp":0.0,"tv":0.0,"id":22121325}]}]}
{"op":"mcm","clk":"990202057","pt":1580495040928,"mc":[{"id":"1.168133543","rc":[{"batl":[[0,2.92,24]],"ltp":2.94,"tv":115.93,"id":12636}]}]}
{"op":"mcm","clk":"990202455","pt":1580495045148,"mc":[{"id":"1.168133543","rc":[{"batb":[[0,4.1,3.34]],"ltp":0.0,"tv":0.0,"id":10163711}]}]}
{"op":"mcm","clk":"990203924","pt":1580495060443,"mc":[{"id":"1.168133543","rc":[{"batb":[[2,3.9,5.55]],"ltp":0.0,"tv":0.0,"id":10163711}]}]}
{"op":"mcm","clk":"990206422","pt":1580495085482,"mc":[{"id":"1.168133543","rc":[{"batl":[[0,2.92,20]],"ltp":2.94,"tv":115.93,"id":12636}]}]}
{"op":"mcm","clk":"990207371","pt":1580495094523,"mc":[{"id":"1.168133543","rc":[{"batb":[[0,2.16,3.03],[1,2.14,15.18],[2,2.1,2.65]],"ltp":2.14,"tv":50.91,"id":10107355}]}]}
{"op":"mcm","clk":"990207473","pt":1580495095418,"mc":[{"id":"1.168133543","rc":[{"batb":[[0,4.2,3.03],[1,4.1,3.34],[2,4,1.99]],"ltp":0.0,"tv":0.0,"id":10163711}]}]}
{"op":"mcm","clk":"990207566","pt":1580495096312,"mc":[{"id":"1.168133543","rc":[{"batl":[[0,790,3.23],[1,800,9]],"ltp":0.0,"tv":0.0,"id":10163711},{"batb":[[1,7.8,4.51],[2,7.6,4.11]],"batl":[[0,790,3.23],[1,800,9]],"ltp":0.0,"tv":0.0,"id":22121325}]}]}
{"op":"mcm","clk":"990208191","pt":1580495102212,"mc":[{"id":"1.168133543","rc":[{"batb":[[0,4.2,5.55]],"ltp":0.0,"tv":0.0,"id":10163711}]}]}
{"op":"mcm","clk":"990209526","pt":1580495115451,"mc":[{"id":"1.168133543","rc":[{"batb":[[0,4.3,1.99],[1,4.2,5.55],[2,4.1,3.34]],"ltp":0.0,"tv":0.0,"id":10163711},{"batb":[[0,8.2,1.99],[1,8,1.98],[2,7.8,2.52]],"ltp":0.0,"tv":0.0,"id":22121325}]}]}
{"op":"mcm","clk":"990209636","pt":1580495116547,"mc":[{"id":"1.168133543","rc":[{"batl":[[1,1000,0.28]],"ltp":0.0,"tv":0.0,"id":22308007},{"batl":[[2,1000,0.08]],"ltp":0.0,"tv":0.0,"id":7226819},{"batl":[[0,770,9],[1,790,3.23]],"ltp":0.0,"tv":0.0,"id":10163711},{"batl":[[0,770,9],[1,790,3.23]],"ltp":0.0,"tv":0.0,"id":22121325}]}]}
{"op":"mcm","clk":"990209721","pt":1580495117538,"mc":[{"id":"1.168133543","rc":[{"batl":[[0,65,3.11],[1,1000,0.2]],"ltp":0.0,"tv":0.0,"id":22308007},{"batl":[[0,65,3.31],[2,1000,0]],"ltp":0.0,"tv":0.0,"id":7226819},{"batb":[[0,22,5.15]],"ltp":0.0,"tv":0.0,"id":13306150}]}]}
{"op":"mcm","clk":"990209805","pt":1580495118536,"mc":[{"id":"1.168133543","rc":[{"batb":[[0,13.5,2.35]],"ltp":0.0,"tv":0.0,"id":22308007},{"batb":[[0,4.3,3.15]],"ltp":0.0,"tv":0.0,"id":10163711},{"batb":[[0,22,5.15]],"ltp":0.0,"tv":0.0,"id":26548208},{"batb":[[0,23,4.82]],"ltp":0.0,"tv":0.0,"id":27606066},{"batb":[[0,23,4.82]],"ltp":0.0,"tv":0.0,"id":24270700}]}]}
{"op":"mcm","clk":"990209880","pt":1580495119423,"mc":[{"id":"1.168133543","rc":[{"batb":[[0,14,1.07],[1,13.5,12.13],[2,13,7]],"ltp":0.0,"tv":0.0,"id":7226819},{"batl":[[0,770,9.2],[1,790,3.03]],"ltp":0.0,"tv":0.0,"id":10163711},{"batb":[[0,2.16,6.95],[1,2.14,11.61]],"ltp":2.14,"tv":50.91,"id":10107355},{"batl":[[0,770,9.2],[1,790,3.03]],"ltp":0.0,"tv":0.0,"id":22121325}]}]}
{"op":"mcm","clk":"990210054","pt":1580495121469,"mc":[{"id":"1.168133543","rc":[{"batb":[[0,4.4,1.33],[1,4.3,3.15],[2,4.2,5.55]],"ltp":0.0,"tv":0.0,"id":10163711}]}]}
{"op":"mcm","clk":"990214021","pt":1580495161695,"mc":[{"id":"1.168133543","rc":[{"batb":[[0,13.5,4.87]],"ltp":0.0,"tv":0.0,"id":22308007},{"batb":[[0,2.18,2.52],[1,2.16,6.95],[2,2.14,11.61]],"ltp":2.14,"tv":50.91,"id":10107355}]}]}
{"op":"mcm","clk":"990221597","pt":1580495241254,"mc":[{"id":"1.168133543","rc":[{"batb":[[0,4.5,1.99],[1,4.4,1.33],[2,4.3,1.16]],"ltp":0.0,"tv":0.0,"id":10163711}]}]}
{"op":"mcm","clk":"990224441","pt":1580495275475,"mc":[{"id":"1.168133543","rc":[{"batb":[[0,4.5,5.02],[2,4.2,2.52]],"batl":[[0,760,3.23],[1,770,9]],"ltp":0.0,"tv":0.0,"id":10163711},{"batl":[[0,760,3.23],[1,770,9]],"ltp":0.0,"tv":0.0,"id":22121325}]}]}
{"op":"mcm","clk":"990224502","pt":1580495276474,"mc":[{"id":"1.168133543","rc":[{"batb":[[0,14,3.03],[1,13.5,4.87],[2,12.5,3.28]],"ltp":0.0,"tv":0.0,"id":22308007},{"batb":[[0,4.6,1.09],[1,4.5,5.02],[2,4.4,1.33]],"ltp":0.0,"tv":0.0,"id":10163711}]}]}
{"op":"mcm","clk":"990224721","pt":1580495279316,"mc":[{"id":"1.168133543","rc":[{"batl":[[0,740,9],[1,760,3.23]],"ltp":0.0,"tv":0.0,"id":10163711},{"batl":[[0,740,9],[1,760,3.23]],"ltp":0.0,"tv":0.0,"id":22121325}]}]}
{"op":"mcm","clk":"990224927","pt":1580495281484,"mc":[{"id":"1.168133543","rc":[{"batb":[[0,4.6,3.61]],"ltp":0.0,"tv":0.0,"id":10163711}]}]}
{"op":"mcm","clk":"990225097","pt":1580495283408,"mc":[{"id":"1.168133543","rc":[{"batl":[[0,740,9.2],[1,760,3.03]],"ltp":0.0,"tv":0.0,"id":10163711},{"batl":[[0,740,9.2],[1,760,3.03]],"ltp":0.0,"tv":0.0,"id":22121325}]}]}
{"op":"mcm","clk":"990225826","pt":1580495291524,"mc":[{"id":"1.168133543","rc":[{"batb":[[0,14.5,1.98],[1,14,3.03],[2,13.5,2.89]],"ltp":0.0,"tv":0.0,"id":22308007},{"batb":[[0,4.7,1.98],[1,4.6,3.61],[2,4.5,5.02]],"ltp":0.0,"tv":0.0,"id":10163711},{"batb":[[0,2.18,11.61],[2,2.14,2.52]],"ltp":2.14,"tv":50.91,"id":10107355},{"batb":[[0,8.4,1.98],[1,8.2,1.99]],"ltp":0.0,"tv":0.0,"id":22121325}]}]}
{"op":"mcm","clk":"990225862","pt":1580495292010,"mc":[{"id":"1.168133543","rc":[{"batb":[[2,7.8,3.16]],"ltp":0.0,"tv":0.0,"id":22121325}]}]}
{"op":"mcm","clk":"990227021","pt":1580495306737,"mc":[{"id":"1.168133543","rc":[{"trd":[[2.18,23.2]],"batb":[[0,2.16,6.96],[1,2.14,2.52],[2,2.1,2.65]],"ltp":2.18,"tv":74.1,"id":10107355}],"tv":193.8}]}
{"op":"mcm","clk":"990227356","pt":1580495311435,"mc":[{"id":"1.168133543","rc":[{"trd":[[22,2.7],[23,1.3]],"batb":[[0,22,3.15]],"ltp":22.0,"tv":4.0,"id":13306150}],"tv":197.8}]}
{"op":"mcm","clk":"990227429","pt":1580495312537,"mc":[{"id":"1.168133543","rc":[{"batb":[[0,4.7,3.17]],"ltp":0.0,"tv":0.0,"id":10163711},{"trd":[[2.16,12.76],[2.18,23.21]],"batb":[[0,2.14,3.09],[1,2.1,2.65],[2,2.08,2.52]],"ltp":2.16,"tv":86.88,"id":10107355}],"tv":210.58}]}
{"op":"mcm","clk":"990227884","pt":1580495318935,"mc":[{"id":"1.168133543","rc":[{"trd":[[2.16,13.28]],"batb":[[0,2.14,2.83]],"ltp":2.16,"tv":87.4,"id":10107355}],"tv":211.1}]}
{"op":"mcm","clk":"990228496","pt":1580495326372,"mc":[{"id":"1.168133543","rc":[{"batl":[[0,2.94,14.75],[1,2.96,2],[2,2.98,3.03]],"ltp":2.16,"tv":87.4,"id":10107355}]}]}
{"op":"mcm","clk":"990229542","pt":1580495338681,"mc":[{"id":"1.168133543","rc":[{"batb":[[0,22,4.02]],"ltp":22.0,"tv":4.0,"id":13306150}]}]}
{"op":"mcm","clk":"990229850","pt":1580495342177,"mc":[{"id":"1.168133543","rc":[{"batb":[[0,2.1,2.96],[1,2.08,2.52],[2,1.99,2.52]],"ltp":2.16,"tv":87.4,"id":10107355}]}]}
{"op":"mcm","clk":"990230788","pt":1580495353386,"mc":[{"id":"1.168133543","rc":[{"batb":[[0,2.1,3.38]],"ltp":2.16,"tv":87.4,"id":10107355}]}]}
{"op":"mcm","clk":"990230867","pt":1580495354291,"mc":[{"id":"1.168133543","rc":[{"batb":[[0,2.1,2.96]],"ltp":2.16,"tv":87.4,"id":10107355}]}]}
{"op":"mcm","clk":"990231140","pt":1580495357200,"mc":[{"id":"1.168133543","rc":[{"batb":[[0,2.1,3.38]],"ltp":2.16,"tv":87.4,"id":10107355}]}]}
{"op":"mcm","clk":"990231238","pt":1580495358400,"mc":[{"id":"1.168133543","rc":[{"batb":[[0,2.1,2.96]],"ltp":2.16,"tv":87.4,"id":10107355}]}]}
{"op":"mcm","clk":"990231320","pt":1580495359396,"mc":[{"id":"1.168133543","rc":[{"batl":[[0,2.92,2.18],[1,2.94,14.57]],"ltp":2.16,"tv":87.4,"id":10107355}]}]}
{"op":"mcm","clk":"990231374","pt":1580495360086,"mc":[{"id":"1.168133543","rc":[{"batb":[[0,2.1,3.38]],"ltp":2.16,"tv":87.4,"id":10107355}]}]}
{"op":"mcm","clk":"990231516","pt":1580495361825,"mc":[{"id":"1.168133543","rc":[{"batb":[[0,2.1,2.96]],"ltp":2.16,"tv":87.4,"id":10107355}]}]}
{"op":"mcm","clk":"990231793","pt":1580495365115,"mc":[{"id":"1.168133543","rc":[{"batl":[[1,2.98,3.03],[2,3,22]],"ltp":2.16,"tv":87.4,"id":10107355}]}]}
{"op":"mcm","clk":"990231964","pt":1580495367327,"mc":[{"id":"1.168133543","rc":[{"batb":[[0,2.1,3.38]],"ltp":2.16,"tv":87.4,"id":10107355}]}]}
{"op":"mcm","clk":"990232055","pt":1580495368428,"mc":[{"id":"1.168133543","rc":[{"batb":[[0,2.1,2.96]],"ltp":2.16,"tv":87.4,"id":10107355}]}]}
{"op":"mcm","clk":"990232195","pt":1580495370246,"mc":[{"id":"1.168133543","rc":[{"batb":[[0,2.1,3.38]],"ltp":2.16,"tv":87.4,"id":10107355}]}]}
{"op":"mcm","clk":"990232607","pt":1580495375414,"mc":[{"id":"1.168133543","rc":[{"batb":[[0,2.1,2.96]],"ltp":2.16,"tv":87.4,"id":10107355}]}]}
{"op":"mcm","clk":"990233170","pt":1580495382540,"mc":[{"id":"1.168133543","rc":[{"batb":[[2,13.5,2.52]],"ltp":0.0,"tv":0.0,"id":22308007},{"batb":[[0,4.8,1.04],[1,4.7,3.17],[2,4.6,2.52]],"ltp":0.0,"tv":0.0,"id":10163711},{"batb":[[0,23,1.09],[1,22,3.15],[2,21,6]],"ltp":22.0,"tv":4.0,"id":13306150}]}]}
{"op":"mcm","clk":"990233232","pt":1580495383229,"mc":[{"id":"1.168133543","rc":[{"batb":[[0,14.5,2.32]],"ltp":0.0,"tv":0.0,"id":22308007}]}]}
{"op":"mcm","clk":"990233971","pt":1580495393531,"mc":[{"id":"1.168133543","rc":[{"batl":[[0,2.6,1.68],[1,2.92,2.18],[2,2.98,3.03]],"ltp":2.16,"tv":87.4,"id":10107355}]}]}
{"op":"mcm","clk":"990234710","pt":1580495402562,"mc":[{"id":"1.168133543","rc":[{"batb":[[1,1.99,2.52],[2,1.96,2.52]],"ltp":2.16,"tv":87.4,"id":10107355}]}]}
{"op":"mcm","clk":"990235371","pt":1580495408684,"mc":[{"id":"1.168133543","rc":[{"batb":[[0,22,3.37],[1,21,6],[2,5.5,90]],"ltp":22.0,"tv":4.0,"id":13306150}]}]}
{"op":"mcm","clk":"990235555","pt":1580495410381,"mc":[{"id":"1.168133543","rc":[{"batb":[[0,4.9,1.99],[1,4.8,1.04],[2,4.7,3.17]],"ltp":0.0,"tv":0.0,"id":10163711}]}]}
{"op":"mcm","clk":"990235620","pt":1580495410854,"mc":[{"id":"1.168133543","rc":[{"batb":[[0,8.6,1.99],[1,8.4,1.98]],"ltp":0.0,"tv":0.0,"id":22121325}]}]}
{"op":"mcm","clk":"990236482","pt":1580495420263,"mc":[{"id":"1.168133543","rc":[{"batl":[[0,2.58,2],[1,2.6,1.68],[2,2.98,3.21]],"ltp":2.16,"tv":87.4,"id":10107355}]}]}
{"op":"mcm","clk":"990236660","pt":1580495422572,"mc":[{"id":"1.168133543","rc":[{"batb":[[0,5,1.14],[1,4.9,1.99],[2,4.8,1.04]],"ltp":0.0,"tv":0.0,"id":10163711}]}]}
{"op":"mcm","clk":"990236864","pt":1580495425300,"mc":[{"id":"1.168133543","rc":[{"batl":[[0,2.56,16.73],[1,2.58,2],[2,2.6,1.68]],"ltp":2.16,"tv":87.4,"id":10107355}]}]}
{"op":"mcm","clk":"990239789","pt":1580495462527,"mc":[{"id":"1.168133543","rc":[{"batb":[[2,4.8,3.56]],"ltp":0.0,"tv":0.0,"id":10163711},{"batb":[[1,1.96,2.52],[2,1.94,2.52]],"ltp":2.16,"tv":87.4,"id":10107355}]}]}
{"op":"mcm","clk":"990240521","pt":1580495472515,"mc":[{"id":"1.168133543","rc":[{"batb":[[2,1.95,3]],"ltp":2.16,"tv":87.4,"id":10107355}]}]}
{"op":"mcm","clk":"990241231","pt":1580495481546,"mc":[{"id":"1.168133543","rc":[{"batl":[[0,2.54,2],[1,2.56,16.73]],"ltp":2.16,"tv":87.4,"id":10107355}]}]}
{"op":"mcm","clk":"990241510","pt":1580495485327,"mc":[{"id":"1.168133543","rc":[{"batl":[[1,2.6,1.68],[2,2.98,3.21]],"ltp":2.16,"tv":87.4,"id":10107355}]}]}
{"op":"mcm","clk":"990244978","pt":1580495531541,"mc":[{"id":"1.168133543","rc":[{"batb":[[0,5.1,1.99],[1,5,1.14]],"ltp":0.0,"tv":0.0,"id":10163711}]}]}
{"op":"mcm","clk":"990245678","pt":1580495539523,"mc":[{"id":"1.168133543","rc":[{"batb":[[1,4.8,3.56],[2,4.7,3.17]],"ltp":0.0,"tv":0.0,"id":10163711}]}]}
{"op":"mcm","clk":"990245828","pt":1580495541110,"mc":[{"id":"1.168133543","rc":[{"batb":[[0,5.2,1.08],[1,5.1,1.99],[2,4.8,3.56]],"ltp":0.0,"tv":0.0,"id":10163711}]}]}
{"op":"mcm","clk":"990245960","pt":1580495542418,"mc":[{"id":"1.168133543","rc":[{"batl":[[0,2.6,1.68],[1,2.98,3.21],[2,3,22]],"ltp":2.16,"tv":87.4,"id":10107355}]}]}
{"op":"mcm","clk":"990245980","pt":1580495542623,"mc":[{"id":"1.168133543","rc":[{"batl":[[0,2.58,2],[1,2.6,1.68],[2,2.98,3.21]],"ltp":2.16,"tv":87.4,"id":10107355}]}]}
{"op":"mcm","clk":"990246086","pt":1580495543831,"mc":[{"id":"1.168133543","rc":[{"batl":[[0,2.56,16.73],[1,2.58,2],[2,2.6,1.68]],"ltp":2.16,"tv":87.4,"id":10107355}]}]}
{"op":"mcm","clk":"990249067","pt":1580495575861,"mc":[{"id":"1.168133543","rc":[{"batb":[[0,5.2,3.07]],"ltp":0.0,"tv":0.0,"id":10163711},{"batb":[[0,8.8,1.98],[1,8.6,1.99]],"ltp":0.0,"tv":0.0,"id":22121325}]}]}
{"op":"mcm","clk":"990252113","pt":1580495604302,"mc":[{"id":"1.168133543","rc":[{"batl":[[0,2.54,2],[1,2.56,16.73]],"ltp":2.16,"tv":87.4,"id":10107355}]}]}
{"op":"mcm","clk":"990252535","pt":1580495608478,"mc":[{"id":"1.168133543","rc":[{"batl":[[0,2.54,4.58]],"ltp":2.16,"tv":87.4,"id":10107355}]}]}
{"op":"mcm","clk":"990252612","pt":1580495609408,"mc":[{"id":"1.168133543","rc":[{"batb":[[0,5.3,3.03],[1,5.2,3.07],[2,5.1,1.99]],"batl":[[0,730,3.23],[1,740,9]],"ltp":0.0,"tv":0.0,"id":10163711},{"batl":[[0,730,3.23],[1,740,9]],"ltp":0.0,"tv":0.0,"id":22121325}]}]}
{"op":"mcm","clk":"990253977","pt":1580495623209,"mc":[{"id":"1.168133543","rc":[{"batl":[[1,2.6,1.68],[2,3,22.18]],"ltp":2.16,"tv":87.4,"id":10107355}]}]}
{"op":"mcm","clk":"990254479","pt":1580495629333,"mc":[{"id":"1.168133543","rc":[{"batb":[[1,5.2,1.98]],"ltp":0.0,"tv":0.0,"id":10163711}]}]}
{"op":"mcm","clk":"990254648","pt":1580495631107,"mc":[{"id":"1.168133543","rc":[{"batb":[[0,5.4,1.03],[1,5.3,3.03],[2,5.2,1.98]],"ltp":0.0,"tv":0.0,"id":10163711}]}]}
{"op":"mcm","clk":"990255315","pt":1580495638340,"mc":[{"id":"1.168133543","rc":[{"batl":[[0,710,9],[1,730,3.23]],"ltp":0.0,"tv":0.0,"id":10163711},{"batl":[[0,710,9],[1,730,3.23]],"ltp":0.0,"tv":0.0,"id":22121325}]}]}
{"op":"mcm","clk":"990255439","pt":1580495639747,"mc":[{"id":"1.168133543","rc":[{"batl":[[0,710,9.2],[1,730,3.03]],"ltp":0.0,"tv":0.0,"id":10163711},{"batl":[[0,710,9.2],[1,730,3.03]],"ltp":0.0,"tv":0.0,"id":22121325}]}]}
{"op":"mcm","clk":"990255653","pt":1580495642168,"mc":[{"id":"1.168133543","rc":[{"batb":[[1,5.3,5.55]],"ltp":0.0,"tv":0.0,"id":10163711}]}]}
{"op":"mcm","clk":"990258260","pt":1580495668387,"mc":[{"id":"1.168133543","rc":[{"batb":[[0,5.5,1.99],[1,5.4,1.03],[2,5.3,5.55]],"ltp":0.0,"tv":0.0,"id":10163711}]}]}
{"op":"mcm","clk":"990258291","pt":1580495668651,"mc":[{"id":"1.168133543","rc":[{"batb":[[1,7.8,3.16],[2,7.6,4.11]],"ltp":0.0,"tv":0.0,"id":22121325}]}]}
{"op":"mcm","clk":"990260369","pt":1580495689503,"mc":[{"id":"1.168133543","rc":[{"batb":[[1,5.3,5.55],[2,5.2,1.98]],"ltp":0.0,"tv":0.0,"id":10163711}]}]}
{"op":"mcm","clk":"990264037","pt":1580495721471,"mc":[{"id":"1.168133543","rc":[{"batb":[[0,5.5,2.98]],"ltp":0.0,"tv":0.0,"id":10163711}]}]}
{"op":"mcm","clk":"990269141","pt":1580495768134,"mc":[{"id":"1.168133543","rc":[{"batb":[[0,5.6,2.97],[1,5.5,1.99],[2,5.3,5.55]],"ltp":0.0,"tv":0.0,"id":10163711},{"batb":[[0,8,1.98]],"ltp":0.0,"tv":0.0,"id":22121325}]}]}
{"op":"mcm","clk":"990273598","pt":1580495810263,"mc":[{"id":"1.168133543","rc":[{"batb":[[0,5.7,1.99],[1,5.6,2.97]],"ltp":0.0,"tv":0.0,"id":10163711}]}]}
{"op":"mcm","clk":"990273687","pt":1580495811258,"mc":[{"id":"1.168133543","rc":[{"batb":[[0,8.2,1.99],[1,8,1.98],[2,7.8,3.16]],"ltp":0.0,"tv":0.0,"id":22121325}]}]}
{"op":"mcm","clk":"990276632","pt":1580495839531,"mc":[{"id":"1.168133543","rc":[{"batb":[[1,5.6,1.98]],"ltp":0.0,"tv":0.0,"id":10163711}]}]}
{"op":"mcm","clk":"990276792","pt":1580495841315,"mc":[{"id":"1.168133543","rc":[{"batb":[[0,5.7,2.94]],"ltp":0.0,"tv":0.0,"id":10163711}]}]}
{"op":"mcm","clk":"990291976","pt":1580495892512,"mc":[{"id":"1.168133543","rc":[{"batl":[[0,700,3.23],[1,710,9]],"ltp":0.0,"tv":0.0,"id":10163711},{"batl":[[1,730,0]],"ltp":0.0,"tv":0.0,"id":22121325}]}]}
{"op":"mcm","clk":"990292094","pt":1580495893522,"mc":[{"id":"1.168133543","rc":[{"batl":[[0,700,3.23],[1,710,9]],"ltp":0.0,"tv":0.0,"id":22121325}]}]}
{"op":"mcm","clk":"990292696","pt":1580495898498,"mc":[{"id":"1.168133543","rc":[{"batl":[[1,710,0]],"ltp":0.0,"tv":0.0,"id":10163711},{"batl":[[1,710,0]],"ltp":0.0,"tv":0.0,"id":22121325}]}]}
{"op":"mcm","clk":"990292814","pt":1580495899502,"mc":[{"id":"1.168133543","rc":[{"batl":[[0,680,9],[1,700,3.23]],"ltp":0.0,"tv":0.0,"id":10163711},{"batl":[[0,680,9],[1,700,3.23]],"ltp":0.0,"tv":0.0,"id":22121325}]}]}
{"op":"mcm","clk":"990299868","pt":1580495959909,"mc":[{"id":"1.168133543","rc":[{"batb":[[0,5.8,2.93],[1,5.7,1.99]],"ltp":0.0,"tv":0.0,"id":10163711},{"batb":[[0,8.4,1.98],[1,8.2,1.99]],"ltp":0.0,"tv":0.0,"id":22121325}]}]}
{"op":"mcm","clk":"990300407","pt":1580495965423,"mc":[{"id":"1.168133543","rc":[{"batb":[[0,5.9,1.99],[1,5.8,2.93]],"ltp":0.0,"tv":0.0,"id":10163711},{"batb":[[0,8.6,1.99],[1,8.4,1.98]],"ltp":0.0,"tv":0.0,"id":22121325}]}]}
{"op":"mcm","clk":"990302792","pt":1580495989750,"mc":[{"id":"1.168133543","rc":[{"batb":[[1,5.8,1.98]],"ltp":0.0,"tv":0.0,"id":10163711}]}]}
{"op":"mcm","clk":"990302959","pt":1580495991442,"mc":[{"id":"1.168133543","rc":[{"batb":[[0,5.9,2.9]],"ltp":0.0,"tv":0.0,"id":10163711}]}]}
{"op":"mcm","clk":"990313031","pt":1580496089204,"mc":[{"id":"1.168133543","rc":[{"batb":[[0,2.74,8.26],[1,2.72,10.72],[2,2.68,2.52]],"ltp":2.94,"tv":115.93,"id":12636}]}]}
{"op":"mcm","clk":"990315321","pt":1580496110723,"mc":[{"id":"1.168133543","rc":[{"batb":[[0,6.2,1.99],[1,5.8,2.89]],"ltp":0.0,"tv":0.0,"id":10163711}]}]}
{"op":"mcm","clk":"990316582","pt":1580496121645,"mc":[{"id":"1.168133543","rc":[{"batb":[[0,2.76,3.48],[1,2.74,7.3],[2,2.72,10.72]],"ltp":2.94,"tv":115.93,"id":12636}]}]}
{"op":"mcm","clk":"990318682","pt":1580496139848,"mc":[{"id":"1.168133543","rc":[{"batb":[[1,5.8,1.98]],"ltp":0.0,"tv":0.0,"id":10163711}]}]}
{"op":"mcm","clk":"990318922","pt":1580496142160,"mc":[{"id":"1.168133543","rc":[{"batb":[[0,6.2,2.83]],"ltp":0.0,"tv":0.0,"id":10163711}]}]}
{"op":"mcm","clk":"990319670","pt":1580496148947,"mc":[{"id":"1.168133543","rc":[{"batb":[[1,2.72,10.72],[2,2.68,2.52]],"ltp":2.94,"tv":115.93,"id":12636}]}]}
{"op":"mcm","clk":"990323421","pt":1580496181920,"mc":[{"id":"1.168133543","rc":[{"batb":[[0,2.72,11.68],[1,2.68,2.52],[2,2.62,2.52]],"ltp":2.94,"tv":115.93,"id":12636}]}]}
{"op":"mcm","clk":"990324064","pt":1580496187524,"mc":[{"id":"1.168133543","rc":[{"batl":[[0,670,3.03],[1,680,9],[2,700,0.2]],"ltp":0.0,"tv":0.0,"id":10163711},{"batl":[[0,670,3.03],[1,680,9],[2,700,0.2]],"ltp":0.0,"tv":0.0,"id":22121325}]}]}
{"op":"mcm","clk":"990324273","pt":1580496189551,"mc":[{"id":"1.168133543","rc":[{"batl":[[0,650,9],[1,670,3.03]],"ltp":0.0,"tv":0.0,"id":10163711},{"batl":[[0,650,9],[1,670,3.03]],"ltp":0.0,"tv":0.0,"id":22121325}]}]}
{"op":"mcm","clk":"990328951","pt":1580496236525,"mc":[{"id":"1.168133543","rc":[{"batb":[[1,5.3,5.55],[2,4.8,3.56]],"ltp":0.0,"tv":0.0,"id":10163711},{"batb":[[1,7.8,3.16],[2,7.6,4.11]],"ltp":0.0,"tv":0.0,"id":22121325}]}]}
{"op":"mcm","clk":"990328959","pt":1580496236624,"mc":[{"id":"1.168133543","rc":[{"batb":[[0,6.4,2.82],[1,6.2,1.99],[2,5.3,5.55]],"ltp":0.0,"tv":0.0,"id":10163711},{"batb":[[0,8.8,1.98],[1,8.6,1.99],[2,7.8,3.16]],"ltp":0.0,"tv":0.0,"id":22121325}]}]}
{"op":"mcm","clk":"990335539","pt":1580496308175,"mc":[{"id":"1.168133543","rc":[{"trd":[[2.1,5.3],[2.16,13.9]],"batb":[[0,1.96,2.52],[1,1.95,3],[2,1.94,2.52]],"batl":[[0,2,1.04],[1,2.54,4.58],[2,2.6,1.68]],"ltp":2.1,"tv":93.32,"id":10107355}],"tv":217.02}]}
{"op":"mcm","clk":"990335741","pt":1580496310176,"mc":[{"id":"1.168133543","rc":[{"trd":[[2,2.08]],"batb":[[0,1.96,3.48]],"batl":[[0,2.54,4.58],[1,2.6,1.68],[2,3,22]],"ltp":2.0,"tv":95.4,"id":10107355}],"tv":219.1}]}
{"op":"mcm","clk":"990336280","pt":1580496316085,"mc":[{"id":"1.168133543","rc":[{"batb":[[0,2,1.27],[1,1.96,2.52],[2,1.95,3]],"ltp":2.0,"tv":95.4,"id":10107355}]}]}
{"op":"mcm","clk":"990336439","pt":1580496317410,"mc":[{"id":"1.168133543","rc":[{"batb":[[0,6.6,1.99],[1,6.4,2.82]],"ltp":0.0,"tv":0.0,"id":10163711},{"batb":[[1,7.8,3.16],[2,7.6,4.11]],"ltp":0.0,"tv":0.0,"id":22121325}]}]}
{"op":"mcm","clk":"990336636","pt":1580496319814,"mc":[{"id":"1.168133543","rc":[{"batb":[[1,6.4,1.98]],"ltp":0.0,"tv":0.0,"id":10163711}]}]}
{"op":"mcm","clk":"990336848","pt":1580496322325,"mc":[{"id":"1.168133543","rc":[{"batb":[[0,6.6,2.77]],"ltp":0.0,"tv":0.0,"id":10163711}]}]}
{"op":"mcm","clk":"990346508","pt":1580496430875,"mc":[{"id":"1.168133543","rc":[{"batb":[[0,6.8,2.76],[1,6.6,1.99]],"ltp":0.0,"tv":0.0,"id":10163711},{"batb":[[0,8,1.98]],"ltp":0.0,"tv":0.0,"id":22121325}]}]}
{"op":"mcm","clk":"990347338","pt":1580496440405,"mc":[{"id":"1.168133543","rc":[{"batl":[[0,650,9.2],[2,700,0]],"ltp":0.0,"tv":0.0,"id":10163711},{"batl":[[0,650,9.2],[2,700,0]],"ltp":0.0,"tv":0.0,"id":22121325}]}]}
{"op":"mcm","clk":"990348561","pt":1580496453510,"mc":[{"id":"1.168133543","rc":[{"batb":[[1,5.3,5.55],[2,4.8,3.56]],"ltp":0.0,"tv":0.0,"id":10163711},{"batb":[[0,8.2,1.99],[1,8,1.98],[2,7.8,3.16]],"ltp":0.0,"tv":0.0,"id":22121325}]}]}
{"op":"mcm","clk":"990352244","pt":1580496496496,"mc":[{"id":"1.168133543","rc":[{"batl":[[0,640,3.23],[1,650,9]],"ltp":0.0,"tv":0.0,"id":10163711},{"batl":[[0,640,3.23],[1,650,9]],"ltp":0.0,"tv":0.0,"id":22121325}]}]}
{"op":"mcm","clk":"990353649","pt":1580496512488,"mc":[{"id":"1.168133543","rc":[{"batl":[[0,620,9],[1,640,3.23]],"ltp":0.0,"tv":0.0,"id":10163711},{"batl":[[0,620,9],[1,640,3.23]],"ltp":0.0,"tv":0.0,"id":22121325}]}]}
