{"op":"mcm","clk":"990529863","pt":1580536212759,"mc":[{"id":"1.168136214","rc":[{"batl":[[2,7.8,18.93]],"ltp":5.2,"tv":159.59,"id":12925630}]}]}
{"op":"mcm","clk":"990531236","pt":1580536239957,"mc":[{"id":"1.168136214","rc":[{"batl":[[0,6.8,2.61],[1,7,1]],"ltp":5.2,"tv":159.59,"id":12925630}]}]}
{"op":"mcm","clk":"990532897","pt":1580536271880,"mc":[{"id":"1.168136214","rc":[{"batl":[[0,7,1.93],[1,7.6,1.96]],"ltp":5.2,"tv":159.59,"id":12925630}]}]}
{"op":"mcm","clk":"990533865","pt":1580536289092,"mc":[{"id":"1.168136214","rc":[{"batl":[[1,7.4,5.32],[2,7.6,1.96]],"ltp":5.2,"tv":159.59,"id":12925630}]}]}
{"op":"mcm","clk":"990534429","pt":1580536302814,"mc":[{"id":"1.168136214","rc":[{"batl":[[1,7.2,1.81],[2,7.4,5.32]],"ltp":5.2,"tv":159.59,"id":12925630}]}]}
{"op":"mcm","clk":"990534785","pt":1580536311493,"mc":[{"id":"1.168136214","rc":[{"batl":[[2,7.8,18.93]],"ltp":5.2,"tv":159.59,"id":12925630}]}]}
{"op":"mcm","clk":"990535695","pt":1580536334113,"mc":[{"id":"1.168136214","rc":[{"batl":[[1,7.8,18.93],[2,8,25]],"ltp":5.2,"tv":159.59,"id":12925630}]}]}
{"op":"mcm","clk":"990535709","pt":1580536334521,"mc":[{"id":"1.168136214","rc":[{"batl":[[0,6.8,2.61],[1,7,1],[2,7.8,18.93]],"ltp":5.2,"tv":159.59,"id":12925630}]}]}
{"op":"mcm","clk":"990536962","pt":1580536365934,"mc":[{"id":"1.168136214","rc":[{"batl":[[0,7,1.93],[1,7.6,1.96]],"ltp":5.2,"tv":159.59,"id":12925630}]}]}
{"op":"mcm","clk":"990537774","pt":1580536389675,"mc":[{"id":"1.168136214","rc":[{"batl":[[1,7.4,5.32],[2,7.6,1.96]],"ltp":5.2,"tv":159.59,"id":12925630}]}]}
{"op":"mcm","clk":"990538052","pt":1580536397391,"mc":[{"id":"1.168136214","rc":[{"batl":[[1,7.2,1.81],[2,7.4,5.32]],"ltp":5.2,"tv":159.59,"id":12925630}]}]}
{"op":"mcm","clk":"990538870","pt":1580536415346,"mc":[{"id":"1.168136214","rc":[{"batl":[[2,7.8,18.93]],"ltp":5.2,"tv":159.59,"id":12925630}]}]}
{"op":"mcm","clk":"990539604","pt":1580536429332,"mc":[{"id":"1.168136214","rc":[{"batl":[[0,6.8,2.61],[1,7,1]],"ltp":5.2,"tv":159.59,"id":12925630}]}]}
{"op":"mcm","clk":"990540969","pt":1580536461147,"mc":[{"id":"1.168136214","rc":[{"batl":[[0,7,1.93],[1,7.6,1.96]],"ltp":5.2,"tv":159.59,"id":12925630}]}]}
{"op":"mcm","clk":"990541167","pt":1580536466770,"mc":[{"id":"1.168136214","rc":[{"batl":[[1,7.4,5.32],[2,7.6,1.96]],"ltp":5.2,"tv":159.59,"id":12925630}]}]}
{"op":"mcm","clk":"990542128","pt":1580536492692,"mc":[{"id":"1.168136214","rc":[{"batl":[[1,7.2,1.81],[2,7.4,5.32]],"ltp":5.2,"tv":159.59,"id":12925630}]}]}
{"op":"mcm","clk":"990543183","pt":1580536516213,"mc":[{"id":"1.168136214","rc":[{"batl":[[2,7.8,18.93]],"ltp":5.2,"tv":159.59,"id":12925630}]}]}
{"op":"mcm","clk":"990543616","pt":1580536524809,"mc":[{"id":"1.168136214","rc":[{"batl":[[0,6.8,2.61],[1,7,1]],"ltp":5.2,"tv":159.59,"id":12925630}]}]}
{"op":"mcm","clk":"990545311","pt":1580536556473,"mc":[{"id":"1.168136214","rc":[{"batl":[[0,7,1.93],[1,7.6,1.96]],"ltp":5.2,"tv":159.59,"id":12925630}]}]}
{"op":"mcm","clk":"990545704","pt":1580536563161,"mc":[{"id":"1.168136214","rc":[{"batl":[[1,7.4,5.32],[2,7.6,1.96]],"ltp":5.2,"tv":159.59,"id":12925630}]}]}
{"op":"mcm","clk":"990547086","pt":1580536588103,"mc":[{"id":"1.168136214","rc":[{"batl":[[2,7.8,18.93]],"ltp":5.2,"tv":159.59,"id":12925630}]}]}
{"op":"mcm","clk":"990547093","pt":1580536588205,"mc":[{"id":"1.168136214","rc":[{"batl":[[1,7.2,1.81],[2,7.4,5.32]],"ltp":5.2,"tv":159.59,"id":12925630}]}]}
{"op":"mcm","clk":"990548020","pt":1580536605687,"mc":[{"id":"1.168136214","rc":[{"batl":[[2,7.8,18.93]],"ltp":5.2,"tv":159.59,"id":12925630}]}]}
{"op":"mcm","clk":"990548678","pt":1580536619757,"mc":[{"id":"1.168136214","rc":[{"batl":[[0,6.8,2.61],[1,7,1]],"ltp":5.2,"tv":159.59,"id":12925630}]}]}
{"op":"mcm","clk":"990549080","pt":1580536627726,"mc":[{"id":"1.168136214","rc":[{"trd":[[5.1,81.5]],"batb":[[0,5.1,3.53]],"ltp":5.1,"tv":169.59,"id":12925630}],"tv":2236.55}]}
{"op":"mcm","clk":"990549883","pt":1580536642332,"mc":[{"id":"1.168136214","rc":[{"batl":[[0,6.6,2.6],[1,6.8,2.42],[2,7,1]],"ltp":5.1,"tv":169.59,"id":12925630}]}]}
{"op":"mcm","clk":"990550267","pt":1580536645748,"mc":[{"id":"1.168136214","rc":[{"batl":[[0,6.4,6.34],[1,6.6,2.41],[2,6.8,2.42]],"ltp":5.1,"tv":169.59,"id":12925630}]}]}
{"op":"mcm","clk":"990551390","pt":1580536651739,"mc":[{"id":"1.168136214","rc":[{"batl":[[0,6.2,2.37],[1,6.4,6.15],[2,6.6,2.41]],"ltp":5.1,"tv":169.59,"id":12925630}]}]}
{"op":"mcm","clk":"990551978","pt":1580536656083,"mc":[{"id":"1.168136214","rc":[{"batl":[[0,6.2,2.18]],"ltp":5.1,"tv":169.59,"id":12925630}]}]}
{"op":"mcm","clk":"990551987","pt":1580536656187,"mc":[{"id":"1.168136214","rc":[{"batl":[[0,6.2,2.37]],"ltp":5.1,"tv":169.59,"id":12925630}]}]}
{"op":"mcm","clk":"990552526","pt":1580536665532,"mc":[{"id":"1.168136214","rc":[{"batl":[[1,6.6,2.41],[2,7,1.74]],"ltp":5.1,"tv":169.59,"id":12925630}]}]}
{"op":"mcm","clk":"990553424","pt":1580536683603,"mc":[{"id":"1.168136214","rc":[{"batl":[[0,6.4,1.87]],"ltp":5.1,"tv":169.59,"id":12925630}]}]}
{"op":"mcm","clk":"990559309","pt":1580536825158,"mc":[{"id":"1.168136214","rc":[{"trd":[[5.1,88.56]],"batb":[[0,5,2.97],[1,4.7,22.98],[2,4.5,4.98]],"ltp":5.1,"tv":176.65,"id":12925630}],"tv":2243.61}]}
{"op":"mcm","clk":"990559963","pt":1580536841772,"mc":[{"id":"1.168136214","rc":[{"batb":[[0,4.8,2.97]],"ltp":5.1,"tv":176.65,"id":12925630}]}]}
{"op":"mcm","clk":"990561180","pt":1580536873118,"mc":[{"id":"1.168136214","rc":[{"batb":[[0,4.8,4.66]],"batl":[[0,6.4,3.69]],"ltp":5.1,"tv":176.65,"id":12925630}]}]}
{"op":"mcm","clk":"990561515","pt":1580536882348,"mc":[{"id":"1.168136214","rc":[{"batl":[[0,6.2,6.54],[1,6.4,3.5],[2,6.6,2.41]],"ltp":5.1,"tv":176.65,"id":12925630}]}]}
{"op":"mcm","clk":"990563960","pt":1580536925891,"mc":[{"id":"1.168136214","rc":[{"batl":[[0,6,2.7],[1,6.2,6.35]],"ltp":5.1,"tv":176.65,"id":12925630}]}]}
{"op":"mcm","clk":"990565014","pt":1580536943080,"mc":[{"id":"1.168136214","rc":[{"batl":[[1,6.6,2.41],[2,7,1.74]],"ltp":5.1,"tv":176.65,"id":12925630}]}]}
{"op":"mcm","clk":"990576151","pt":1580536977542,"mc":[{"id":"1.168136214","rc":[{"batl":[[0,6.4,1.87]],"ltp":5.1,"tv":176.65,"id":12925630}]}]}
{"op":"mcm","clk":"990579817","pt":1580537058437,"mc":[{"id":"1.168136214","rc":[{"batl":[[1,7,1.74],[2,7.8,18.93]],"ltp":5.1,"tv":176.65,"id":12925630}]}]}
{"op":"mcm","clk":"990580465","pt":1580537072746,"mc":[{"id":"1.168136214","rc":[{"batl":[[0,6.8,2.61],[1,7,1]],"ltp":5.1,"tv":176.65,"id":12925630}]}]}
{"op":"mcm","clk":"990583295","pt":1580537124799,"mc":[{"id":"1.168136214","rc":[{"batl":[[0,7,1.93],[1,7.6,2.95]],"ltp":5.1,"tv":176.65,"id":12925630}]}]}
{"op":"mcm","clk":"990583337","pt":1580537125674,"mc":[{"id":"1.168136214","rc":[{"batl":[[1,7.4,5.32],[2,7.6,2.95]],"ltp":5.1,"tv":176.65,"id":12925630}]}]}
{"op":"mcm","clk":"990585260","pt":1580537165386,"mc":[{"id":"1.168136214","rc":[{"batl":[[1,7.2,1.81],[2,7.4,5.32]],"ltp":5.1,"tv":176.65,"id":12925630}]}]}
{"op":"mcm","clk":"990585392","pt":1580537168065,"mc":[{"id":"1.168136214","rc":[{"batl":[[2,7.8,18.93]],"ltp":5.1,"tv":176.65,"id":12925630}]}]}
{"op":"mcm","clk":"990586704","pt":1580537197096,"mc":[{"id":"1.168136214","rc":[{"batl":[[0,6.8,2.61],[1,7,1]],"ltp":5.1,"tv":176.65,"id":12925630}]}]}
{"op":"mcm","clk":"990587996","pt":1580537228923,"mc":[{"id":"1.168136214","rc":[{"batl":[[0,7,1.93],[1,7.6,2.95]],"ltp":5.1,"tv":176.65,"id":12925630}]}]}
{"op":"mcm","clk":"990588806","pt":1580537247258,"mc":[{"id":"1.168136214","rc":[{"batl":[[1,7.4,5.32],[2,7.6,2.95]],"ltp":5.1,"tv":176.65,"id":12925630}]}]}
{"op":"mcm","clk":"990589478","pt":1580537260845,"mc":[{"id":"1.168136214","rc":[{"batl":[[1,7.2,1.81],[2,7.4,5.32]],"ltp":5.1,"tv":176.65,"id":12925630}]}]}
{"op":"mcm","clk":"990589860","pt":1580537268144,"mc":[{"id":"1.168136214","rc":[{"batl":[[2,7.8,18.93]],"ltp":5.1,"tv":176.65,"id":12925630}]}]}
{"op":"mcm","clk":"990589888","pt":1580537268760,"mc":[{"id":"1.168136214","rc":[{"trd":[[3.7,51]],"batl":[[0,3.75,16],[1,4.2,50],[2,4.6,1.74]],"ltp":3.7,"tv":534.28,"id":11981493}],"tv":2251.61}]}
{"op":"mcm","clk":"990590619","pt":1580537283094,"mc":[{"id":"1.168136214","rc":[{"trd":[[3.75,32]],"batl":[[0,4.2,50],[1,4.6,1.74],[2,5.1,1.74]],"ltp":3.75,"tv":566.28,"id":11981493}],"tv":2283.61}]}
{"op":"mcm","clk":"990590762","pt":1580537285697,"mc":[{"id":"1.168136214","rc":[{"batb":[[0,3.35,5.14],[1,3.3,6.72],[2,3.25,2.99]],"batl":[[0,4.2,50.19]],"ltp":3.75,"tv":566.28,"id":11981493}]}]}
{"op":"mcm","clk":"990590907","pt":1580537287852,"mc":[{"id":"1.168136214","rc":[{"batb":[[0,3.4,4.68],[1,3.35,5.14],[2,3.3,6.72]],"batl":[[0,4.1,4.07],[1,4.2,50],[2,4.6,1.74]],"ltp":3.75,"tv":566.28,"id":11981493}]}]}
{"op":"mcm","clk":"990590981","pt":1580537289062,"mc":[{"id":"1.168136214","rc":[{"batl":[[2,7.6,5]],"ltp":5.1,"tv":176.65,"id":12925630}]}]}
{"op":"mcm","clk":"990591177","pt":1580537292269,"mc":[{"id":"1.168136214","rc":[{"batl":[[0,6.8,2.61],[1,7,1]],"ltp":5.1,"tv":176.65,"id":12925630}]}]}
{"op":"mcm","clk":"990591425","pt":1580537297005,"mc":[{"id":"1.168136214","rc":[{"batb":[[1,3.35,6.82]],"ltp":3.75,"tv":566.28,"id":11981493}]}]}
{"op":"mcm","clk":"990591826","pt":1580537305128,"mc":[{"id":"1.168136214","rc":[{"batl":[[2,7.8,18.93]],"ltp":5.1,"tv":176.65,"id":12925630}]}]}
{"op":"mcm","clk":"990591831","pt":1580537305231,"mc":[{"id":"1.168136214","rc":[{"batl":[[2,7.2,5]],"ltp":5.1,"tv":176.65,"id":12925630}]}]}
{"op":"mcm","clk":"990591995","pt":1580537308426,"mc":[{"id":"1.168136214","rc":[{"batb":[[0,3.45,4.29],[1,3.4,4.68],[2,3.35,6.82]],"ltp":3.75,"tv":566.28,"id":11981493}]}]}
{"op":"mcm","clk":"990592505","pt":1580537319029,"mc":[{"id":"1.168136214","rc":[{"trd":[[4.8,16.88]],"batb":[[0,4.8,1.57]],"ltp":4.8,"tv":182.83,"id":12925630},{"trd":[[2,588.88]],"batb":[[0,2,109.6]],"ltp":2.0,"tv":1555.46,"id":17336468},{"trd":[[3.45,28.2]],"batb":[[0,3.5,2.11]],"ltp":3.45,"tv":574.86,"id":11981493}],"tv":2313.17}]}
{"op":"mcm","clk":"990592591","pt":1580537320834,"mc":[{"id":"1.168136214","rc":[{"batl":[[1,7,6],[2,7.8,18.93]],"ltp":4.8,"tv":182.83,"id":12925630}]}]}
{"op":"mcm","clk":"990592697","pt":1580537323146,"mc":[{"id":"1.168136214","rc":[{"batb":[[2,4.5,1.98]],"ltp":4.8,"tv":182.83,"id":12925630}]}]}
{"op":"mcm","clk":"990592974","pt":1580537328856,"mc":[{"id":"1.168136214","rc":[{"batl":[[0,6.6,6.16],[1,6.8,7.42],[2,7,1]],"ltp":4.8,"tv":182.83,"id":12925630},{"batl":[[0,4,10.03],[1,4.1,3.88],[2,4.2,50]],"ltp":3.45,"tv":574.86,"id":11981493}]}]}
{"op":"mcm","clk":"990593046","pt":1580537330453,"mc":[{"id":"1.168136214","rc":[{"batl":[[0,6.4,2.48],[1,6.6,6.16],[2,6.8,7.42]],"ltp":4.8,"tv":182.83,"id":12925630},{"batb":[[1,3.35,6.82],[2,3.25,2.99]],"ltp":3.45,"tv":574.86,"id":11981493}]}]}
{"op":"mcm","clk":"990593100","pt":1580537331385,"mc":[{"id":"1.168136214","rc":[{"batl":[[0,6.4,2.67],[1,6.6,5.97]],"ltp":4.8,"tv":182.83,"id":12925630}]}]}
{"op":"mcm","clk":"990593369","pt":1580537337094,"mc":[{"id":"1.168136214","rc":[{"batb":[[1,3.35,5.14]],"ltp":3.45,"tv":574.86,"id":11981493}]}]}
{"op":"mcm","clk":"990593694","pt":1580537345081,"mc":[{"id":"1.168136214","rc":[{"batl":[[0,6.2,5.19],[1,6.4,2.48],[2,6.6,5.97]],"ltp":4.8,"tv":182.83,"id":12925630},{"batb":[[2,3.25,4.67]],"ltp":3.45,"tv":574.86,"id":11981493}]}]}
{"op":"mcm","clk":"990593895","pt":1580537348963,"mc":[{"id":"1.168136214","rc":[{"batl":[[2,6.8,2.42]],"ltp":4.8,"tv":182.83,"id":12925630}]}]}
{"op":"mcm","clk":"990593948","pt":1580537349997,"mc":[{"id":"1.168136214","rc":[{"batl":[[0,6,6.76],[1,6.2,5],[2,6.4,2.48]],"ltp":4.8,"tv":182.83,"id":12925630}]}]}
{"op":"mcm","clk":"990594247","pt":1580537356089,"mc":[{"id":"1.168136214","rc":[{"batl":[[0,5.9,3.13],[1,6,6.57],[2,6.2,5]],"ltp":4.8,"tv":182.83,"id":12925630}]}]}
{"op":"mcm","clk":"990594938","pt":1580537368704,"mc":[{"id":"1.168136214","rc":[{"batl":[[0,5.9,8.13],[1,6.4,2.48],[2,7,1.74]],"ltp":4.8,"tv":182.83,"id":12925630}]}]}
{"op":"mcm","clk":"990595167","pt":1580537372982,"mc":[{"id":"1.168136214","rc":[{"batb":[[0,3.4,2.18]],"ltp":3.45,"tv":574.86,"id":11981493}]}]}
{"op":"mcm","clk":"990595398","pt":1580537377108,"mc":[{"id":"1.168136214","rc":[{"batl":[[0,5.9,3.13],[1,6.2,5],[2,6.4,2.48]],"ltp":4.8,"tv":182.83,"id":12925630}]}]}
{"op":"mcm","clk":"990595753","pt":1580537384125,"mc":[{"id":"1.168136214","rc":[{"batl":[[1,6.4,2.48],[2,7,1.74]],"ltp":4.8,"tv":182.83,"id":12925630}]}]}
{"op":"mcm","clk":"990595759","pt":1580537384228,"mc":[{"id":"1.168136214","rc":[{"batl":[[1,6,5],[2,6.4,2.48]],"ltp":4.8,"tv":182.83,"id":12925630}]}]}
{"op":"mcm","clk":"990596051","pt":1580537389939,"mc":[{"id":"1.168136214","rc":[{"batl":[[0,5.8,6.98],[1,5.9,2.94],[2,6,5]],"ltp":4.8,"tv":182.83,"id":12925630}]}]}
{"op":"mcm","clk":"990597480","pt":1580537418853,"mc":[{"id":"1.168136214","rc":[{"batl":[[0,5.7,2.67],[1,5.8,6.79]],"ltp":4.8,"tv":182.83,"id":12925630}]}]}
{"op":"mcm","clk":"990598055","pt":1580537430148,"mc":[{"id":"1.168136214","rc":[{"batl":[[1,6,5],[2,6.4,2.48]],"ltp":4.8,"tv":182.83,"id":12925630}]}]}
{"op":"mcm","clk":"990599269","pt":1580537451136,"mc":[{"id":"1.168136214","rc":[{"batl":[[0,5.9,2.11]],"ltp":4.8,"tv":182.83,"id":12925630}]}]}
{"op":"mcm","clk":"990605617","pt":1580537559933,"mc":[{"id":"1.168136214","rc":[{"batl":[[2,7,1.74]],"ltp":4.8,"tv":182.83,"id":12925630},{"batl":[[1,4.2,50],[2,4.6,1.74]],"ltp":3.45,"tv":574.86,"id":11981493}]}]}
{"op":"mcm","clk":"990618375","pt":1580537785552,"mc":[{"id":"1.168136214","rc":[{"trd":[[4.7,45.96],[4.8,20.03]],"batb":[[0,4.5,1.98],[1,4.4,3.01],[2,4.3,3]],"ltp":4.7,"tv":231.94,"id":12925630}],"tv":2362.27}]}
{"op":"mcm","clk":"990618510","pt":1580537788135,"mc":[{"id":"1.168136214","rc":[{"batb":[[0,4.5,5.52]],"ltp":4.7,"tv":231.94,"id":12925630}]}]}
{"op":"mcm","clk":"990618614","pt":1580537790044,"mc":[{"id":"1.168136214","rc":[{"batl":[[0,5.8,6.98],[1,5.9,4.61],[2,6,5]],"ltp":4.7,"tv":231.94,"id":12925630}]}]}
{"op":"mcm","clk":"990619264","pt":1580537795959,"mc":[{"id":"1.168136214","rc":[{"batb":[[0,4.6,2.13],[1,4.5,5.52],[2,4.4,3.01]],"batl":[[0,5.7,6.82],[1,5.8,6.79],[2,5.9,2.7]],"ltp":4.7,"tv":231.94,"id":12925630}]}]}
{"op":"mcm","clk":"990620127","pt":1580537809809,"mc":[{"id":"1.168136214","rc":[{"batl":[[1,5.9,2.7],[2,6,5]],"ltp":4.7,"tv":231.94,"id":12925630}]}]}
{"op":"mcm","clk":"990620261","pt":1580537812093,"mc":[{"id":"1.168136214","rc":[{"batl":[[0,5.6,5.19],[1,5.7,6.63],[2,5.9,2.7]],"ltp":4.7,"tv":231.94,"id":12925630}]}]}
{"op":"mcm","clk":"990621391","pt":1580537830508,"mc":[{"id":"1.168136214","rc":[{"batl":[[0,5.5,7.35],[1,5.6,5],[2,5.7,6.63]],"ltp":4.7,"tv":231.94,"id":12925630}]}]}
{"op":"mcm","clk":"990622268","pt":1580537850068,"mc":[{"id":"1.168136214","rc":[{"batl":[[0,5.4,5],[1,5.5,7.35]],"ltp":4.7,"tv":231.94,"id":12925630}]}]}
{"op":"mcm","clk":"990622318","pt":1580537850944,"mc":[{"id":"1.168136214","rc":[{"batl":[[1,5.7,6.82],[2,5.9,2.7]],"ltp":4.7,"tv":231.94,"id":12925630}]}]}
{"op":"mcm","clk":"990632318","pt":1580537864570,"mc":[{"id":"1.168136214","rc":[{"batl":[[0,5.6,5.19],[1,5.7,6.63]],"ltp":4.7,"tv":231.94,"id":12925630}]}]}
{"op":"mcm","clk":"990632422","pt":1580537866274,"mc":[{"id":"1.168136214","rc":[{"batl":[[0,3.95,4.19],[1,4,9.84],[2,4.2,50]],"ltp":3.45,"tv":574.86,"id":11981493}]}]}
{"op":"mcm","clk":"990632656","pt":1580537870870,"mc":[{"id":"1.168136214","rc":[{"batb":[[0,3.45,10.01],[1,3.4,2.18],[2,3.35,5.14]],"batl":[[1,4.2,50],[2,4.6,1.74]],"ltp":3.45,"tv":574.86,"id":11981493}]}]}
{"op":"mcm","clk":"990632697","pt":1580537871796,"mc":[{"id":"1.168136214","rc":[{"batl":[[0,5.5,7.35],[1,5.6,5],[2,5.7,6.63]],"ltp":4.7,"tv":231.94,"id":12925630}]}]}
{"op":"mcm","clk":"990633075","pt":1580537879881,"mc":[{"id":"1.168136214","rc":[{"batb":[[0,3.45,11.69]],"ltp":3.45,"tv":574.86,"id":11981493}]}]}
{"op":"mcm","clk":"990633092","pt":1580537880289,"mc":[{"id":"1.168136214","rc":[{"batl":[[0,5.4,5],[1,5.5,7.35]],"ltp":4.7,"tv":231.94,"id":12925630}]}]}
{"op":"mcm","clk":"990633322","pt":1580537885081,"mc":[{"id":"1.168136214","rc":[{"batb":[[0,3.45,1.68]],"batl":[[0,4.2,50.19],[1,4.6,1.74],[2,5.1,1.74]],"ltp":3.45,"tv":574.86,"id":11981493}]}]}
{"op":"mcm","clk":"990633533","pt":1580537888905,"mc":[{"id":"1.168136214","rc":[{"batb":[[0,3.4,2.18],[1,3.35,5.14],[2,3.25,2.99]],"ltp":3.45,"tv":574.86,"id":11981493}]}]}
{"op":"mcm","clk":"990633614","pt":1580537891116,"mc":[{"id":"1.168136214","rc":[{"batl":[[1,5.7,6.82],[2,5.9,2.7]],"ltp":4.7,"tv":231.94,"id":12925630}]}]}
{"op":"mcm","clk":"990633734","pt":1580537894115,"mc":[{"id":"1.168136214","rc":[{"batl":[[0,4.1,1.41],[1,4.2,50],[2,4.6,1.74]],"ltp":3.45,"tv":574.86,"id":11981493}]}]}
{"op":"mcm","clk":"990633861","pt":1580537898027,"mc":[{"id":"1.168136214","rc":[{"batb":[[2,3.25,4.67]],"ltp":3.45,"tv":574.86,"id":11981493}]}]}
{"op":"mcm","clk":"990634403","pt":1580537911102,"mc":[{"id":"1.168136214","rc":[{"batl":[[0,5.7,6.82],[1,5.9,2.7],[2,7,1.74]],"ltp":4.7,"tv":231.94,"id":12925630}]}]}
{"op":"mcm","clk":"990634407","pt":1580537911206,"mc":[{"id":"1.168136214","rc":[{"batl":[[0,5.6,5.19],[1,5.7,6.63],[2,5.9,2.7]],"ltp":4.7,"tv":231.94,"id":12925630}]}]}
{"op":"mcm","clk":"990635245","pt":1580537929967,"mc":[{"id":"1.168136214","rc":[{"batl":[[0,5.5,7.35],[1,5.6,5],[2,5.7,6.63]],"ltp":4.7,"tv":231.94,"id":12925630}]}]}
{"op":"mcm","clk":"990635256","pt":1580537930232,"mc":[{"id":"1.168136214","rc":[{"batl":[[0,4.1,5.41]],"ltp":3.45,"tv":574.86,"id":11981493}]}]}
{"op":"mcm","clk":"990636184","pt":1580537950089,"mc":[{"id":"1.168136214","rc":[{"batl":[[0,4,10.03],[1,4.1,5.22],[2,4.2,50]],"ltp":3.45,"tv":574.86,"id":11981493}]}]}
{"op":"mcm","clk":"990636230","pt":1580537950764,"mc":[{"id":"1.168136214","rc":[{"batl":[[0,5.4,5],[1,5.5,7.35]],"ltp":4.7,"tv":231.94,"id":12925630}]}]}
{"op":"mcm","clk":"990637196","pt":1580537970112,"mc":[{"id":"1.168136214","rc":[{"batl":[[1,5.7,6.82],[2,5.9,2.7]],"ltp":4.7,"tv":231.94,"id":12925630}]}]}
{"op":"mcm","clk":"990637201","pt":1580537970166,"mc":[{"id":"1.168136214","rc":[{"batl":[[1,4.1,1.22]],"ltp":3.45,"tv":574.86,"id":11981493}]}]}
{"op":"mcm","clk":"990638815","pt":1580538000929,"mc":[{"id":"1.168136214","rc":[{"batl":[[0,3.95,3.69],[1,4,9.84],[2,4.1,1.22]],"ltp":3.45,"tv":574.86,"id":11981493}]}]}
{"op":"mcm","clk":"990639381","pt":1580538011033,"mc":[{"id":"1.168136214","rc":[{"batb":[[0,3.45,10.01],[1,3.4,2.18],[2,3.35,5.14]],"batl":[[1,4.1,1.22],[2,4.2,50]],"ltp":3.45,"tv":574.86,"id":11981493}]}]}
{"op":"mcm","clk":"990639778","pt":1580538018658,"mc":[{"id":"1.168136214","rc":[{"batl":[[2,7,1.74]],"ltp":4.7,"tv":231.94,"id":12925630}]}]}
{"op":"mcm","clk":"990639846","pt":1580538019948,"mc":[{"id":"1.168136214","rc":[{"batl":[[0,5.6,5.19],[1,5.7,6.63]],"ltp":4.7,"tv":231.94,"id":12925630},{"batl":[[0,4.1,4.91],[1,4.2,50],[2,4.6,1.74]],"ltp":3.45,"tv":574.86,"id":11981493}]}]}
{"op":"mcm","clk":"990639897","pt":1580538020931,"mc":[{"id":"1.168136214","rc":[{"batb":[[0,3.5,2.11],[1,3.45,10.01]],"ltp":3.45,"tv":574.86,"id":11981493}]}]}
{"op":"mcm","clk":"990640036","pt":1580538024071,"mc":[{"id":"1.168136214","rc":[{"batb":[[0,3.5,3.79]],"ltp":3.45,"tv":574.86,"id":11981493}]}]}
{"op":"mcm","clk":"990640400","pt":1580538030950,"mc":[{"id":"1.168136214","rc":[{"batl":[[0,5.5,7.35],[1,5.6,5],[2,5.7,6.63]],"ltp":4.7,"tv":231.94,"id":12925630},{"batl":[[0,4,10.03],[1,4.1,4.72],[2,4.2,50]],"ltp":3.45,"tv":574.86,"id":11981493}]}]}
{"op":"mcm","clk":"990640710","pt":1580538037090,"mc":[{"id":"1.168136214","rc":[{"batl":[[0,5.4,5],[1,5.5,7.35]],"ltp":4.7,"tv":231.94,"id":12925630}]}]}
{"op":"mcm","clk":"990641314","pt":1580538049716,"mc":[{"id":"1.168136214","rc":[{"batl":[[0,3.95,3.69],[1,4,9.84],[2,4.1,1.22]],"ltp":3.45,"tv":574.86,"id":11981493}]}]}
{"op":"mcm","clk":"990641405","pt":1580538051421,"mc":[{"id":"1.168136214","rc":[{"batl":[[1,5.7,6.82],[2,7,1.74]],"ltp":4.7,"tv":231.94,"id":12925630},{"batl":[[1,4.1,1.22],[2,4.2,50]],"ltp":3.45,"tv":574.86,"id":11981493}]}]}
{"op":"mcm","clk":"990641825","pt":1580538060999,"mc":[{"id":"1.168136214","rc":[{"batl":[[0,5.6,5.19],[1,5.7,6.63]],"ltp":4.7,"tv":231.94,"id":12925630},{"batl":[[0,4,4.19],[1,4.1,4.72]],"ltp":3.45,"tv":574.86,"id":11981493}]}]}
{"op":"mcm","clk":"990641869","pt":1580538062135,"mc":[{"id":"1.168136214","rc":[{"batl":[[0,3.95,3.69],[1,4,4],[2,4.1,1.22]],"ltp":3.45,"tv":574.86,"id":11981493}]}]}
{"op":"mcm","clk":"990642368","pt":1580538072511,"mc":[{"id":"1.168136214","rc":[{"batl":[[0,5.5,7.35],[1,5.6,5],[2,5.7,6.63]],"ltp":4.7,"tv":231.94,"id":12925630}]}]}
{"op":"mcm","clk":"990642632","pt":1580538078087,"mc":[{"id":"1.168136214","rc":[{"batl":[[1,4.1,1.22],[2,4.2,50]],"ltp":3.45,"tv":574.86,"id":11981493}]}]}
{"op":"mcm","clk":"990642637","pt":1580538078190,"mc":[{"id":"1.168136214","rc":[{"batl":[[1,4.1,5.22]],"ltp":3.45,"tv":574.86,"id":11981493}]}]}
{"op":"mcm","clk":"990643276","pt":1580538090522,"mc":[{"id":"1.168136214","rc":[{"batb":[[1,1.98,15.63],[2,1.97,2]],"ltp":2.0,"tv":1555.46,"id":17336468}]}]}
{"op":"mcm","clk":"990643326","pt":1580538091613,"mc":[{"id":"1.168136214","rc":[{"batl":[[0,4,2.46]],"ltp":3.45,"tv":574.86,"id":11981493}]}]}
{"op":"mcm","clk":"990643384","pt":1580538092810,"mc":[{"id":"1.168136214","rc":[{"trd":[[2.04,87.7]],"batl":[[0,2.04,13.09]],"ltp":2.04,"tv":1579.7,"id":17336468},{"batl":[[0,3.95,10.16],[1,4,2.27],[2,4.1,5.22]],"ltp":3.45,"tv":574.86,"id":11981493}],"tv":2386.5}]}
{"op":"mcm","clk":"990643550","pt":1580538096016,"mc":[{"id":"1.168136214","rc":[{"batb":[[0,2.02,6.06],[1,2,109.6],[2,1.98,15.63]],"ltp":2.04,"tv":1579.7,"id":17336468},{"batl":[[1,4,4.54],[2,4.1,1.22]],"ltp":3.45,"tv":574.86,"id":11981493}]}]}
{"op":"mcm","clk":"990643730","pt":1580538099840,"mc":[{"id":"1.168136214","rc":[{"batl":[[0,5.4,5],[1,5.5,7.35]],"ltp":4.7,"tv":231.94,"id":12925630}]}]}
{"op":"mcm","clk":"990644134","pt":1580538108831,"mc":[{"id":"1.168136214","rc":[{"trd":[[2.04,89.74]],"batl":[[0,2.04,12.07]],"ltp":2.04,"tv":1581.73,"id":17336468}],"tv":2388.54}]}
{"op":"mcm","clk":"990644230","pt":1580538111469,"mc":[{"id":"1.168136214","rc":[{"batl":[[1,5.7,6.82],[2,7,1.74]],"ltp":4.7,"tv":231.94,"id":12925630}]}]}
{"op":"mcm","clk":"990644711","pt":1580538122582,"mc":[{"id":"1.168136214","rc":[{"batl":[[0,5.6,5.19],[1,5.7,6.63]],"ltp":4.7,"tv":231.94,"id":12925630}]}]}
{"op":"mcm","clk":"990645141","pt":1580538131969,"mc":[{"id":"1.168136214","rc":[{"batl":[[0,5.5,7.35],[1,5.6,5],[2,5.7,6.63]],"ltp":4.7,"tv":231.94,"id":12925630}]}]}
{"op":"mcm","clk":"990646186","pt":1580538154583,"mc":[{"id":"1.168136214","rc":[{"batl":[[0,5.4,5],[1,5.5,7.35]],"ltp":4.7,"tv":231.94,"id":12925630}]}]}
{"op":"mcm","clk":"990646231","pt":1580538155921,"mc":[{"id":"1.168136214","rc":[{"batb":[[0,3.55,4.85],[1,3.5,3.79],[2,3.45,10.01]],"ltp":3.45,"tv":574.86,"id":11981493}]}]}
{"op":"mcm","clk":"990646805","pt":1580538171701,"mc":[{"id":"1.168136214","rc":[{"batl":[[1,5.7,6.82],[2,7,1.74]],"ltp":4.7,"tv":231.94,"id":12925630}]}]}
{"op":"mcm","clk":"990647223","pt":1580538181142,"mc":[{"id":"1.168136214","rc":[{"trd":[[4.5,1.18],[4.6,9.31]],"batb":[[0,4.5,4.93],[1,4.4,3.01],[2,4.3,3]],"ltp":4.5,"tv":237.38,"id":12925630},{"trd":[[2.02,210.2]],"batb":[[0,2,109.6],[1,1.98,15.63],[2,1.97,2]],"batl":[[0,2.04,12.08]],"ltp":2.02,"tv":1593.85,"id":17336468},{"trd":[[3.55,51.68]],"batb":[[0,3.6,2.06],[1,3.5,1.68]],"ltp":3.55,"tv":584.55,"id":11981493}],"tv":2415.79}]}
{"op":"mcm","clk":"990647473","pt":1580538187050,"mc":[{"id":"1.168136214","rc":[{"batl":[[0,5.3,3],[1,5.6,5.19],[2,5.7,6.63]],"ltp":4.5,"tv":237.38,"id":12925630},{"batl":[[0,3.9,4.07],[1,3.95,10.16],[2,4,4.54]],"ltp":3.55,"tv":584.55,"id":11981493}]}]}
{"op":"mcm","clk":"990647497","pt":1580538187662,"mc":[{"id":"1.168136214","rc":[{"batb":[[2,4.2,18.93]],"ltp":4.5,"tv":237.38,"id":12925630}]}]}
{"op":"mcm","clk":"990647623","pt":1580538190123,"mc":[{"id":"1.168136214","rc":[{"batl":[[1,3.95,9.97]],"ltp":3.55,"tv":584.55,"id":11981493}]}]}
{"op":"mcm","clk":"990647779","pt":1580538193418,"mc":[{"id":"1.168136214","rc":[{"batl":[[1,4,4.54],[2,4.1,1.22]],"ltp":3.55,"tv":584.55,"id":11981493}]}]}
{"op":"mcm","clk":"990647857","pt":1580538195057,"mc":[{"id":"1.168136214","rc":[{"batl":[[1,5.4,5],[2,5.7,6.82]],"ltp":4.5,"tv":237.38,"id":12925630}]}]}
{"op":"mcm","clk":"990648238","pt":1580538204145,"mc":[{"id":"1.168136214","rc":[{"batb":[[0,4.6,1.98],[1,4.5,4.93],[2,4.4,3.01]],"ltp":4.5,"tv":237.38,"id":12925630}]}]}
{"op":"mcm","clk":"990648258","pt":1580538204653,"mc":[{"id":"1.168136214","rc":[{"batl":[[2,5.7,7.44]],"ltp":4.5,"tv":237.38,"id":12925630}]}]}
{"op":"mcm","clk":"990648938","pt":1580538220069,"mc":[{"id":"1.168136214","rc":[{"batl":[[0,5.3,8],[1,5.7,7.44],[2,7,1.74]],"ltp":4.5,"tv":237.38,"id":12925630}]}]}
{"op":"mcm","clk":"990649264","pt":1580538227795,"mc":[{"id":"1.168136214","rc":[{"batl":[[0,5.3,3],[1,5.6,5.19],[2,5.7,7.25]],"ltp":4.5,"tv":237.38,"id":12925630}]}]}
{"op":"mcm","clk":"990649507","pt":1580538234769,"mc":[{"id":"1.168136214","rc":[{"batb":[[0,3.5,3.79],[1,3.45,10.01],[2,3.25,2.99]],"ltp":3.55,"tv":584.55,"id":11981493}]}]}
{"op":"mcm","clk":"990649554","pt":1580538235494,"mc":[{"id":"1.168136214","rc":[{"batl":[[1,5.4,5],[2,5.7,7.44]],"ltp":4.5,"tv":237.38,"id":12925630}]}]}
{"op":"mcm","clk":"990650184","pt":1580538252106,"mc":[{"id":"1.168136214","rc":[{"batl":[[0,5.3,8],[1,5.7,7.44],[2,7,1.74]],"ltp":4.5,"tv":237.38,"id":12925630}]}]}
{"op":"mcm","clk":"990651099","pt":1580538275147,"mc":[{"id":"1.168136214","rc":[{"batl":[[0,5.3,3],[1,5.6,5.19],[2,5.7,7.25]],"ltp":4.5,"tv":237.38,"id":12925630}]}]}
{"op":"mcm","clk":"990652196","pt":1580538300770,"mc":[{"id":"1.168136214","rc":[{"batl":[[1,5.4,5],[2,5.7,7.44]],"ltp":4.5,"tv":237.38,"id":12925630}]}]}
{"op":"mcm","clk":"990652527","pt":1580538309058,"mc":[{"id":"1.168136214","rc":[{"batl":[[0,5.3,8],[1,5.7,7.44],[2,7,1.74]],"ltp":4.5,"tv":237.38,"id":12925630}]}]}
{"op":"mcm","clk":"990654004","pt":1580538340879,"mc":[{"id":"1.168136214","rc":[{"batl":[[0,5.3,3],[1,5.6,5.19],[2,5.7,7.25]],"ltp":4.5,"tv":237.38,"id":12925630}]}]}
{"op":"mcm","clk":"990654349","pt":1580538348916,"mc":[{"id":"1.168136214","rc":[{"batl":[[1,5.4,5],[2,5.7,7.44]],"ltp":4.5,"tv":237.38,"id":12925630}]}]}
{"op":"mcm","clk":"990654702","pt":1580538357319,"mc":[{"id":"1.168136214","rc":[{"batl":[[0,5.3,8],[1,5.7,7.44],[2,7,1.74]],"ltp":4.5,"tv":237.38,"id":12925630}]}]}
{"op":"mcm","clk":"990655714","pt":1580538381595,"mc":[{"id":"1.168136214","rc":[{"batl":[[0,5.3,3],[1,5.6,5.19],[2,5.7,7.25]],"ltp":4.5,"tv":237.38,"id":12925630}]}]}
{"op":"mcm","clk":"990656072","pt":1580538389291,"mc":[{"id":"1.168136214","rc":[{"batl":[[1,5.4,5],[2,5.7,7.44]],"ltp":4.5,"tv":237.38,"id":12925630}]}]}
{"op":"mcm","clk":"990657552","pt":1580538419112,"mc":[{"id":"1.168136214","rc":[{"batl":[[0,5.4,5],[1,5.7,7.44],[2,7,1.74]],"ltp":4.5,"tv":237.38,"id":12925630},{"batl":[[0,4,4.54],[1,4.1,1.22],[2,4.2,50]],"ltp":3.55,"tv":584.55,"id":11981493}]}]}
{"op":"mcm","clk":"990657743","pt":1580538423028,"mc":[{"id":"1.168136214","rc":[{"batl":[[0,4,4.72]],"ltp":3.55,"tv":584.55,"id":11981493}]}]}
{"op":"mcm","clk":"990658034","pt":1580538430400,"mc":[{"id":"1.168136214","rc":[{"batl":[[0,5.6,5.19],[1,5.7,7.25]],"ltp":4.5,"tv":237.38,"id":12925630}]}]}
{"op":"mcm","clk":"990660193","pt":1580538493201,"mc":[{"id":"1.168136214","rc":[{"batb":[[0,3.55,2],[1,3.5,3.79],[2,3.45,10.01]],"ltp":3.55,"tv":584.55,"id":11981493}]}]}
{"op":"mcm","clk":"990660356","pt":1580538497478,"mc":[{"id":"1.168136214","rc":[{"trd":[[2,614.09]],"batb":[[0,2,97]],"ltp":2.0,"tv":1619.05,"id":17336468}],"tv":2440.99}]}
{"op":"mcm","clk":"990660545","pt":1580538502378,"mc":[{"id":"1.168136214","rc":[{"batb":[[0,3.6,2.06],[1,3.55,2],[2,3.5,1.68]],"ltp":3.55,"tv":584.55,"id":11981493}]}]}
{"op":"mcm","clk":"990663324","pt":1580538573493,"mc":[{"id":"1.168136214","rc":[{"batb":[[0,4.6,26.98]],"ltp":4.5,"tv":237.38,"id":12925630}]}]}
{"op":"mcm","clk":"990671392","pt":1580538745964,"mc":[{"id":"1.168136214","rc":[{"trd":[[4.6,63.27]],"batb":[[0,4.5,4.93],[1,4.4,3.01],[2,4,30.55]],"ltp":4.6,"tv":291.34,"id":12925630}],"tv":2494.95}]}
{"op":"mcm","clk":"990681157","pt":1580538752663,"mc":[{"id":"1.168136214","rc":[{"batb":[[2,4.3,3]],"ltp":4.6,"tv":291.34,"id":12925630}]}]}
{"op":"mcm","clk":"990681197","pt":1580538753945,"mc":[{"id":"1.168136214","rc":[{"batl":[[0,5.5,7.35],[1,5.6,5],[2,5.7,7.25]],"ltp":4.6,"tv":291.34,"id":12925630}]}]}
{"op":"mcm","clk":"990681336","pt":1580538757953,"mc":[{"id":"1.168136214","rc":[{"batl":[[0,5.4,2.95],[1,5.5,7.35],[2,5.6,5]],"ltp":4.6,"tv":291.34,"id":12925630}]}]}
{"op":"mcm","clk":"990681812","pt":1580538769664,"mc":[{"id":"1.168136214","rc":[{"batl":[[0,5.4,7.95],[2,5.7,7.25]],"ltp":4.6,"tv":291.34,"id":12925630}]}]}
{"op":"mcm","clk":"990681920","pt":1580538773060,"mc":[{"id":"1.168136214","rc":[{"batl":[[0,5.3,3.82],[1,5.4,7.95],[2,5.5,7.35]],"ltp":4.6,"tv":291.34,"id":12925630}]}]}
{"op":"mcm","clk":"990681944","pt":1580538774086,"mc":[{"id":"1.168136214","rc":[{"batl":[[2,7,1.93]],"ltp":4.6,"tv":291.34,"id":12925630}]}]}
{"op":"mcm","clk":"990682070","pt":1580538777070,"mc":[{"id":"1.168136214","rc":[{"batb":[[0,4.6,2.74],[1,4.5,4.93],[2,4.4,3.01]],"ltp":4.6,"tv":291.34,"id":12925630}]}]}
{"op":"mcm","clk":"990682748","pt":1580538794108,"mc":[{"id":"1.168136214","rc":[{"batl":[[1,5.4,2.95]],"ltp":4.6,"tv":291.34,"id":12925630}]}]}
{"op":"mcm","clk":"990682763","pt":1580538794316,"mc":[{"id":"1.168136214","rc":[{"batl":[[0,5.3,8.82]],"ltp":4.6,"tv":291.34,"id":12925630}]}]}
{"op":"mcm","clk":"990690103","pt":1580538989568,"mc":[{"id":"1.168136214","rc":[{"batl":[[1,7,1.93],[2,7.8,18.93]],"ltp":4.6,"tv":291.34,"id":12925630}]}]}
{"op":"mcm","clk":"990690316","pt":1580538995389,"mc":[{"id":"1.168136214","rc":[{"batb":[[0,4.6,4.65]],"batl":[[0,5.3,5],[1,6.8,7.16],[2,7,1]],"ltp":4.6,"tv":291.34,"id":12925630}]}]}
{"op":"mcm","clk":"990692052","pt":1580539040956,"mc":[{"id":"1.168136214","rc":[{"batl":[[0,6.6,5.19],[1,6.8,6.97]],"ltp":4.6,"tv":291.34,"id":12925630}]}]}
{"op":"mcm","clk":"990692402","pt":1580539051145,"mc":[{"id":"1.168136214","rc":[{"batl":[[0,6.4,6.34],[1,6.6,5],[2,6.8,6.97]],"ltp":4.6,"tv":291.34,"id":12925630}]}]}
{"op":"mcm","clk":"990692641","pt":1580539057968,"mc":[{"id":"1.168136214","rc":[{"batl":[[0,6.2,5.19],[1,6.4,6.15]],"ltp":4.6,"tv":291.34,"id":12925630}]}]}
{"op":"mcm","clk":"990692682","pt":1580539058948,"mc":[{"id":"1.168136214","rc":[{"batl":[[0,6,3.03],[1,6.2,5],[2,6.4,6.15]],"ltp":4.6,"tv":291.34,"id":12925630}]}]}
{"op":"mcm","clk":"990692960","pt":1580539066390,"mc":[{"id":"1.168136214","rc":[{"batl":[[0,6,3.86]],"ltp":4.6,"tv":291.34,"id":12925630}]}]}
{"op":"mcm","clk":"990693156","pt":1580539070576,"mc":[{"id":"1.168136214","rc":[{"batl":[[0,5.9,6.86],[1,6,3.67],[2,6.2,5]],"ltp":4.6,"tv":291.34,"id":12925630}]}]}
{"op":"mcm","clk":"990693298","pt":1580539074463,"mc":[{"id":"1.168136214","rc":[{"batl":[[1,6,8.67],[2,7,1]],"ltp":4.6,"tv":291.34,"id":12925630}]}]}
{"op":"mcm","clk":"990693968","pt":1580539090996,"mc":[{"id":"1.168136214","rc":[{"batl":[[0,5.8,4.07],[1,5.9,6.67],[2,6,5.83]],"ltp":4.6,"tv":291.34,"id":12925630}]}]}
{"op":"mcm","clk":"990694482","pt":1580539102635,"mc":[{"id":"1.168136214","rc":[{"batl":[[0,5.7,7.79],[1,5.8,3.88],[2,5.9,6.67]],"ltp":4.6,"tv":291.34,"id":12925630}]}]}
{"op":"mcm","clk":"990694704","pt":1580539108130,"mc":[{"id":"1.168136214","rc":[{"batl":[[0,5.6,5.19],[1,5.7,7.6],[2,5.8,3.88]],"ltp":4.6,"tv":291.34,"id":12925630}]}]}
{"op":"mcm","clk":"990694837","pt":1580539111431,"mc":[{"id":"1.168136214","rc":[{"batl":[[0,5.5,7.35],[1,5.6,5],[2,5.7,7.6]],"ltp":4.6,"tv":291.34,"id":12925630}]}]}
{"op":"mcm","clk":"990697419","pt":1580539182082,"mc":[{"id":"1.168136214","rc":[{"batl":[[1,5.7,7.6],[2,5.8,3.88]],"ltp":4.6,"tv":291.34,"id":12925630}]}]}
{"op":"mcm","clk":"990697424","pt":1580539182188,"mc":[{"id":"1.168136214","rc":[{"batl":[[0,5.4,5],[1,5.5,7.35],[2,5.7,7.6]],"ltp":4.6,"tv":291.34,"id":12925630}]}]}
{"op":"mcm","clk":"990697840","pt":1580539192878,"mc":[{"id":"1.168136214","rc":[{"batl":[[1,5.7,7.79],[2,5.8,3.88]],"ltp":4.6,"tv":291.34,"id":12925630}]}]}
{"op":"mcm","clk":"990698067","pt":1580539198909,"mc":[{"id":"1.168136214","rc":[{"batl":[[0,5.6,5.19],[1,5.7,7.6]],"ltp":4.6,"tv":291.34,"id":12925630}]}]}
{"op":"mcm","clk":"990698657","pt":1580539213312,"mc":[{"id":"1.168136214","rc":[{"batl":[[0,5.5,7.35],[1,5.6,5],[2,5.7,7.6]],"ltp":4.6,"tv":291.34,"id":12925630}]}]}
{"op":"mcm","clk":"990699108","pt":1580539223113,"mc":[{"id":"1.168136214","rc":[{"batl":[[0,5.4,5],[1,5.5,7.35]],"ltp":4.6,"tv":291.34,"id":12925630}]}]}
{"op":"mcm","clk":"990699617","pt":1580539234133,"mc":[{"id":"1.168136214","rc":[{"batl":[[1,5.7,7.79],[2,5.8,3.88]],"ltp":4.6,"tv":291.34,"id":12925630}]}]}
{"op":"mcm","clk":"990700454","pt":1580539252105,"mc":[{"id":"1.168136214","rc":[{"batl":[[1,5.6,3.39],[2,5.7,7.6]],"ltp":4.6,"tv":291.34,"id":12925630}]}]}
{"op":"mcm","clk":"990700966","pt":1580539262654,"mc":[{"id":"1.168136214","rc":[{"batl":[[0,4,8.5]],"ltp":3.55,"tv":584.55,"id":11981493}]}]}
{"op":"mcm","clk":"990703337","pt":1580539312520,"mc":[{"id":"1.168136214","rc":[{"batb":[[0,2,99]],"ltp":2.0,"tv":1619.05,"id":17336468}]}]}
{"op":"mcm","clk":"990704067","pt":1580539329133,"mc":[{"id":"1.168136214","rc":[{"batl":[[2,7,1.83]],"ltp":4.6,"tv":291.34,"id":12925630}]}]}
{"op":"mcm","clk":"990708806","pt":1580539432444,"mc":[{"id":"1.168136214","rc":[{"trd":[[2,618.09]],"batb":[[0,2,97]],"ltp":2.0,"tv":1623.05,"id":17336468}],"tv":2498.95}]}
{"op":"mcm","clk":"990712078","pt":1580539497428,"mc":[{"id":"1.168136214","rc":[{"batl":[[0,5.2,20],[1,5.4,5],[2,5.6,3.39]],"ltp":4.6,"tv":291.34,"id":12925630}]}]}
{"op":"mcm","clk":"990712216","pt":1580539500004,"mc":[{"id":"1.168136214","rc":[{"batl":[[2,5.6,3.2]],"ltp":4.6,"tv":291.34,"id":12925630}]}]}
{"op":"mcm","clk":"990712417","pt":1580539503830,"mc":[{"id":"1.168136214","rc":[{"batb":[[0,4.6,24.65]],"ltp":4.6,"tv":291.34,"id":12925630}]}]}
{"op":"mcm","clk":"990714213","pt":1580539539858,"mc":[{"id":"1.168136214","rc":[{"batl":[[1,5.3,5]],"ltp":4.6,"tv":291.34,"id":12925630}]}]}
{"op":"mcm","clk":"990714608","pt":1580539547978,"mc":[{"id":"1.168136214","rc":[{"batl":[[0,5.1,5],[1,5.2,20]],"ltp":4.6,"tv":291.34,"id":12925630}]}]}
{"op":"mcm","clk":"990717147","pt":1580539589292,"mc":[{"id":"1.168136214","rc":[{"batl":[[1,5.5,20]],"ltp":4.6,"tv":291.34,"id":12925630}]}]}
{"op":"mcm","clk":"990719817","pt":1580539639126,"mc":[{"id":"1.168136214","rc":[{"batl":[[0,5.4,5]],"ltp":4.6,"tv":291.34,"id":12925630}]}]}
{"op":"mcm","clk":"990732456","pt":1580539706381,"mc":[{"id":"1.168136214","rc":[{"trd":[[4.6,112.58]],"batb":[[0,4.5,4.93],[1,4.4,3.01],[2,4.3,3]],"batl":[[0,5.3,4.12],[1,5.4,5],[2,5.5,20]],"ltp":4.6,"tv":340.65,"id":12925630}],"tv":2548.26}]}
{"op":"mcm","clk":"990732641","pt":1580539710615,"mc":[{"id":"1.168136214","rc":[{"batb":[[0,4.6,2.74],[1,4.5,4.93],[2,4.4,3.01]],"ltp":4.6,"tv":340.65,"id":12925630}]}]}
{"op":"mcm","clk":"990732768","pt":1580539713103,"mc":[{"id":"1.168136214","rc":[{"batl":[[0,5.2,3.06],[1,5.3,4.12],[2,5.4,5]],"ltp":4.6,"tv":340.65,"id":12925630}]}]}
{"op":"mcm","clk":"990732827","pt":1580539714099,"mc":[{"id":"1.168136214","rc":[{"batl":[[1,5.3,9.12],[2,5.5,20]],"ltp":4.6,"tv":340.65,"id":12925630}]}]}
{"op":"mcm","clk":"990733580","pt":1580539732141,"mc":[{"id":"1.168136214","rc":[{"batl":[[0,5.1,3.04],[1,5.2,3.06],[2,5.3,9.12]],"ltp":4.6,"tv":340.65,"id":12925630}]}]}
{"op":"mcm","clk":"990735353","pt":1580539775141,"mc":[{"id":"1.168136214","rc":[{"batl":[[0,2.06,2.01],[1,2.08,35.91],[2,2.16,15.14]],"ltp":2.0,"tv":1623.05,"id":17336468}]}]}
{"op":"mcm","clk":"990735378","pt":1580539775864,"mc":[{"id":"1.168136214","rc":[{"trd":[[2,642.23]],"batb":[[0,2,84.93]],"ltp":2.0,"tv":1647.2,"id":17336468}],"tv":2572.4}]}
{"op":"mcm","clk":"990735879","pt":1580539787482,"mc":[{"id":"1.168136214","rc":[{"batl":[[0,5.1,8.04],[2,5.3,4.12]],"ltp":4.6,"tv":340.65,"id":12925630}]}]}
{"op":"mcm","clk":"990742528","pt":1580539948283,"mc":[{"id":"1.168136214","rc":[{"batl":[[1,5.3,4.12],[2,5.5,20]],"ltp":4.6,"tv":340.65,"id":12925630}]}]}
{"op":"mcm","clk":"990742833","pt":1580539955585,"mc":[{"id":"1.168136214","rc":[{"batl":[[0,5.1,5],[1,5.2,3.04],[2,5.3,4.12]],"ltp":4.6,"tv":340.65,"id":12925630}]}]}
{"op":"mcm","clk":"990744595","pt":1580540000399,"mc":[{"id":"1.168136214","rc":[{"batb":[[0,4.5,4.93],[1,4.4,3.01],[2,4.3,3]],"ltp":4.6,"tv":340.65,"id":12925630}]}]}
{"op":"mcm","clk":"990755665","pt":1580540296015,"mc":[{"id":"1.168136214","rc":[{"batl":[[0,2.04,3.01],[1,2.06,2],[2,2.08,35.91]],"ltp":2.0,"tv":1647.2,"id":17336468}]}]}
{"op":"mcm","clk":"990758066","pt":1580540361535,"mc":[{"id":"1.168136214","rc":[{"trd":[[2.02,210.22],[2.04,95.74],[2.06,93.81],[2.08,222.16]],"batl":[[0,2.08,13.92],[1,2.16,15.14],[2,2.18,130.14]],"ltp":2.08,"tv":1701.2,"id":17336468}],"tv":2626.4}]}
{"op":"mcm","clk":"990758389","pt":1580540370566,"mc":[{"id":"1.168136214","rc":[{"batl":[[2,2.18,15.14]],"ltp":2.08,"tv":1701.2,"id":17336468}]}]}
{"op":"mcm","clk":"990778978","pt":1580540630782,"mc":[{"id":"1.168136214","rc":[{"trd":[[2,652.23]],"batb":[[0,2,79.93]],"ltp":2.0,"tv":1711.2,"id":17336468}],"tv":2636.4}]}
{"op":"mcm","clk":"990780650","pt":1580540666752,"mc":[{"id":"1.168136214","rc":[{"trd":[[4.5,11.04]],"batb":[[0,4.4,3.01],[1,4.3,3],[2,4.1,3]],"ltp":4.5,"tv":350.51,"id":12925630}],"tv":2646.27}]}
{"op":"mcm","clk":"990780726","pt":1580540668548,"mc":[{"id":"1.168136214","rc":[{"batb":[[1,4.1,3],[2,4,11.62]],"ltp":4.5,"tv":350.51,"id":12925630}]}]}
{"op":"mcm","clk":"990781279","pt":1580540682356,"mc":[{"id":"1.168136214","rc":[{"batb":[[0,4.5,3.54],[1,4.4,3.01],[2,4.1,3]],"ltp":4.5,"tv":350.51,"id":12925630}]}]}
{"op":"mcm","clk":"990781304","pt":1580540683176,"mc":[{"id":"1.168136214","rc":[{"batl":[[0,5,3.18],[1,5.1,5],[2,5.2,3.04]],"ltp":4.5,"tv":350.51,"id":12925630}]}]}
{"op":"mcm","clk":"990781473","pt":1580540687504,"mc":[{"id":"1.168136214","rc":[{"batl":[[0,4.9,2.05],[1,5,3.18],[2,5.1,5]],"ltp":4.5,"tv":350.51,"id":12925630}]}]}
{"op":"mcm","clk":"990781689","pt":1580540693497,"mc":[{"id":"1.168136214","rc":[{"batl":[[0,4.9,7.05],[2,5.3,4.12]],"ltp":4.5,"tv":350.51,"id":12925630}]}]}
{"op":"mcm","clk":"990783009","pt":1580540732323,"mc":[{"id":"1.168136214","rc":[{"batl":[[0,4.9,5],[1,5,5.73]],"ltp":4.5,"tv":350.51,"id":12925630}]}]}
{"op":"mcm","clk":"990783343","pt":1580540741779,"mc":[{"id":"1.168136214","rc":[{"trd":[[4.5,18.12]],"batb":[[0,4.4,3.01],[1,4.1,3],[2,4,11.62]],"batl":[[0,4.9,5.9]],"ltp":4.5,"tv":357.59,"id":12925630}],"tv":2653.34}]}
{"op":"mcm","clk":"990789903","pt":1580540890512,"mc":[{"id":"1.168136214","rc":[{"batb":[[0,3.6,4.06]],"ltp":3.55,"tv":584.55,"id":11981493}]}]}
{"op":"mcm","clk":"990793875","pt":1580540967801,"mc":[{"id":"1.168136214","rc":[{"batl":[[1,5,2.55]],"ltp":4.5,"tv":357.59,"id":12925630}]}]}
{"op":"mcm","clk":"990796934","pt":1580541019767,"mc":[{"id":"1.168136214","rc":[{"trd":[[2,656.23]],"batb":[[0,2,77.93]],"ltp":2.0,"tv":1715.2,"id":17336468}],"tv":2657.34}]}
{"op":"mcm","clk":"990844794","pt":1580541627592,"mc":[{"id":"1.168136214","rc":[{"trd":[[4.4,6.03]],"batb":[[0,4.2,4.51]],"batl":[[2,5.8,43]],"ltp":4.4,"tv":363.62,"id":12925630}],"tv":2663.37}]}
{"op":"mcm","clk":"990845193","pt":1580541633164,"mc":[{"id":"1.168136214","rc":[{"batl":[[2,6.6,38.83]],"ltp":4.4,"tv":363.62,"id":12925630}]}]}
{"op":"mcm","clk":"990847149","pt":1580541663602,"mc":[{"id":"1.168136214","rc":[{"batl":[[2,7,1.83]],"ltp":4.4,"tv":363.62,"id":12925630}]}]}
{"op":"mcm","clk":"990855812","pt":1580541796795,"mc":[{"id":"1.168136214","rc":[{"trd":[[2,664.23]],"batb":[[0,2,73.93]],"ltp":2.0,"tv":1723.2,"id":17336468}],"tv":2671.37}]}
{"op":"mcm","clk":"990857340","pt":1580541822742,"mc":[{"id":"1.168136214","rc":[{"trd":[[2,724.23]],"batb":[[0,2,43.93]],"ltp":2.0,"tv":1783.2,"id":17336468}],"tv":2731.37}]}
{"op":"mcm","clk":"990861403","pt":1580541914530,"mc":[{"id":"1.168136214","rc":[{"batl":[[0,2.08,25.28]],"ltp":2.0,"tv":1783.2,"id":17336468}]}]}
{"op":"mcm","clk":"990861450","pt":1580541915562,"mc":[{"id":"1.168136214","rc":[{"batl":[[0,2.08,13.92]],"ltp":2.0,"tv":1783.2,"id":17336468}]}]}
{"op":"mcm","clk":"990861653","pt":1580541919355,"mc":[{"id":"1.168136214","rc":[{"batl":[[0,2.08,30.58]],"ltp":2.0,"tv":1783.2,"id":17336468}]}]}
{"op":"mcm","clk":"990870378","pt":1580542090061,"mc":[{"id":"1.168136214","rc":[{"trd":[[2,766.23]],"batb":[[0,2,22.93]],"ltp":2.0,"tv":1825.2,"id":17336468},{"trd":[[3.5,32.4],[3.55,55.68],[3.6,22.12]],"batb":[[0,3.45,10.01],[1,3.4,20],[2,3.3,6]],"batl":[[0,3.5,4.26],[1,4,8.32],[2,4.1,1.22]],"ltp":3.5,"tv":600.03,"id":11981493}],"tv":2788.85}]}
{"op":"mcm","clk":"990870418","pt":1580542091091,"mc":[{"id":"1.168136214","rc":[{"trd":[[2,766.53]],"batb":[[0,2,22.78]],"ltp":2.0,"tv":1825.5,"id":17336468},{"trd":[[3.45,28.5]],"batb":[[0,3.45,9.86]],"ltp":3.45,"tv":600.33,"id":11981493}],"tv":2789.46}]}
{"op":"mcm","clk":"990870517","pt":1580542093055,"mc":[{"id":"1.168136214","rc":[{"trd":[[3.45,28.8]],"batb":[[0,3.45,11.39]],"ltp":3.45,"tv":600.63,"id":11981493}],"tv":2789.76}]}
{"op":"mcm","clk":"990870905","pt":1580542099980,"mc":[{"id":"1.168136214","rc":[{"trd":[[3.45,37.32]],"batb":[[0,3.45,1.68]],"batl":[[0,3.95,4.15]],"ltp":3.45,"tv":609.15,"id":11981493}],"tv":2798.28}]}
{"op":"mcm","clk":"990871048","pt":1580542102570,"mc":[{"id":"1.168136214","rc":[{"batl":[[0,3.95,4.34]],"ltp":3.45,"tv":609.15,"id":11981493}]}]}
{"op":"mcm","clk":"990871308","pt":1580542107925,"mc":[{"id":"1.168136214","rc":[{"batb":[[2,3.35,2]],"ltp":3.45,"tv":609.15,"id":11981493}]}]}
{"op":"mcm","clk":"990872080","pt":1580542125122,"mc":[{"id":"1.168136214","rc":[{"batb":[[2,4,13.62]],"ltp":4.4,"tv":363.62,"id":12925630}]}]}
{"op":"mcm","clk":"990872994","pt":1580542145358,"mc":[{"id":"1.168136214","rc":[{"batl":[[0,3.9,2.19],[1,3.95,4.15],[2,4,8.32]],"ltp":3.45,"tv":609.15,"id":11981493}]}]}
{"op":"mcm","clk":"990873951","pt":1580542171100,"mc":[{"id":"1.168136214","rc":[{"trd":[[4.5,19.92]],"batb":[[0,4.7,1.25]],"batl":[[0,4.8,4.28],[1,4.9,5],[2,5,2.55]],"ltp":4.5,"tv":365.42,"id":12925630}],"tv":2800.08}]}
{"op":"mcm","clk":"990875361","pt":1580542212067,"mc":[{"id":"1.168136214","rc":[{"batl":[[0,4.8,9.28],[1,5,2.55],[2,5.5,45]],"ltp":4.5,"tv":365.42,"id":12925630}]}]}
{"op":"mcm","clk":"990876083","pt":1580542229989,"mc":[{"id":"1.168136214","rc":[{"batl":[[0,4.8,4.28],[1,4.9,5],[2,5,2.55]],"ltp":4.5,"tv":365.42,"id":12925630}]}]}
{"op":"mcm","clk":"990876844","pt":1580542247035,"mc":[{"id":"1.168136214","rc":[{"batl":[[0,4.8,9.28],[1,5,2.55],[2,5.5,45]],"ltp":4.5,"tv":365.42,"id":12925630}]}]}
{"op":"mcm","clk":"990877160","pt":1580542254110,"mc":[{"id":"1.168136214","rc":[{"batb":[[1,4.2,4.76],[2,4.1,3]],"ltp":4.5,"tv":365.42,"id":12925630}]}]}
{"op":"mcm","clk":"990877233","pt":1580542256017,"mc":[{"id":"1.168136214","rc":[{"batl":[[0,4.8,4.28],[1,4.9,5],[2,5,2.55]],"ltp":4.5,"tv":365.42,"id":12925630}]}]}
{"op":"mcm","clk":"990879323","pt":1580542297106,"mc":[{"id":"1.168136214","rc":[{"batl":[[0,2.06,3.36],[1,2.08,30.58],[2,2.16,15.14]],"ltp":2.0,"tv":1825.5,"id":17336468}]}]}
{"op":"mcm","clk":"990879355","pt":1580542298083,"mc":[{"id":"1.168136214","rc":[{"batl":[[0,4.8,9.28],[1,5,2.55],[2,5.5,45]],"ltp":4.5,"tv":365.42,"id":12925630},{"batl":[[0,2.08,30.58],[1,2.16,15.14],[2,2.18,15.14]],"ltp":2.0,"tv":1825.5,"id":17336468}]}]}
{"op":"mcm","clk":"990880108","pt":1580542315122,"mc":[{"id":"1.168136214","rc":[{"batl":[[1,5.5,45],[2,7,1.83]],"ltp":4.5,"tv":365.42,"id":12925630}]}]}
{"op":"mcm","clk":"990880154","pt":1580542316097,"mc":[{"id":"1.168136214","rc":[{"batl":[[0,4.8,4.28],[1,4.9,7.96],[2,5.5,45]],"ltp":4.5,"tv":365.42,"id":12925630}]}]}
{"op":"mcm","clk":"990880232","pt":1580542318108,"mc":[{"id":"1.168136214","rc":[{"batl":[[0,3.9,6.26]],"ltp":3.45,"tv":609.15,"id":11981493}]}]}
{"op":"mcm","clk":"990880507","pt":1580542324609,"mc":[{"id":"1.168136214","rc":[{"batl":[[0,4.8,9.28],[1,4.9,2.96],[2,6,42.83]],"ltp":4.5,"tv":365.42,"id":12925630}]}]}
{"op":"mcm","clk":"990881059","pt":1580542339871,"mc":[{"id":"1.168136214","rc":[{"batl":[[0,3.9,2.19]],"ltp":3.45,"tv":609.15,"id":11981493}]}]}
{"op":"mcm","clk":"990891044","pt":1580542354698,"mc":[{"id":"1.168136214","rc":[{"batl":[[2,7,37.83]],"ltp":4.5,"tv":365.42,"id":12925630}]}]}
{"op":"mcm","clk":"990891900","pt":1580542378903,"mc":[{"id":"1.168136214","rc":[{"trd":[[3.4,54.76],[3.45,40.68]],"batb":[[0,3.4,17.68],[1,3.35,2],[2,3.25,2.99]],"ltp":3.4,"tv":617.15,"id":11981493}],"tv":2808.08}]}
{"op":"mcm","clk":"990892115","pt":1580542383840,"mc":[{"id":"1.168136214","rc":[{"batb":[[0,3.45,1.73],[1,3.4,17.68],[2,3.35,2]],"ltp":3.4,"tv":617.15,"id":11981493}]}]}
{"op":"mcm","clk":"990892154","pt":1580542385031,"mc":[{"id":"1.168136214","rc":[{"batl":[[2,7,1.83]],"ltp":4.5,"tv":365.42,"id":12925630}]}]}
{"op":"mcm","clk":"990892200","pt":1580542386123,"mc":[{"id":"1.168136214","rc":[{"batl":[[0,3.9,6.26]],"ltp":3.4,"tv":617.15,"id":11981493}]}]}
{"op":"mcm","clk":"990895970","pt":1580542469747,"mc":[{"id":"1.168136214","rc":[{"batl":[[1,2.16,20.24]],"ltp":2.0,"tv":1825.5,"id":17336468}]}]}
{"op":"mcm","clk":"990896790","pt":1580542490269,"mc":[{"id":"1.168136214","rc":[{"batb":[[0,2,42.78]],"ltp":2.0,"tv":1825.5,"id":17336468}]}]}
{"op":"mcm","clk":"990896929","pt":1580542493610,"mc":[{"id":"1.168136214","rc":[{"trd":[[2,852.09]],"batb":[[0,1.98,15.63],[1,1.97,2],[2,1.96,13.1]],"batl":[[0,2,23.22],[1,2.08,30.58],[2,2.16,20.24]],"ltp":2.0,"tv":1911.06,"id":17336468}],"tv":2893.64}]}
{"op":"mcm","clk":"990900663","pt":1580542588048,"mc":[{"id":"1.168136214","rc":[{"trd":[[4.2,9.52],[4.7,48.46]],"batb":[[0,4.2,4.51],[1,4.1,3],[2,4,13.62]],"batl":[[0,4.8,5]],"ltp":4.2,"tv":377.43,"id":12925630},{"trd":[[3.85,0.38],[3.9,12.15]],"batl":[[0,3.95,4.15],[1,4,8.32],[2,4.1,1.22]],"ltp":3.9,"tv":629.69,"id":11981493}],"tv":2918.19}]}
{"op":"mcm","clk":"990900676","pt":1580542588459,"mc":[{"id":"1.168136214","rc":[{"batb":[[2,4,10.62]],"ltp":4.2,"tv":377.43,"id":12925630}]}]}
{"op":"mcm","clk":"990900875","pt":1580542592959,"mc":[{"id":"1.168136214","rc":[{"batl":[[0,3.95,4.34]],"ltp":3.9,"tv":629.69,"id":11981493}]}]}
{"op":"mcm","clk":"990901261","pt":1580542602096,"mc":[{"id":"1.168136214","rc":[{"trd":[[3.9,12.53],[3.95,3.62]],"batl":[[0,3.95,2.34]],"ltp":3.95,"tv":633.69,"id":11981493}],"tv":2922.19}]}
{"op":"mcm","clk":"990901365","pt":1580542604261,"mc":[{"id":"1.168136214","rc":[{"batl":[[0,3.95,2.53]],"ltp":3.95,"tv":633.69,"id":11981493}]}]}
{"op":"mcm","clk":"990901553","pt":1580542608969,"mc":[{"id":"1.168136214","rc":[{"batb":[[0,4.3,3.7],[1,4.2,4.51],[2,4.1,3]],"ltp":4.2,"tv":377.43,"id":12925630}]}]}
{"op":"mcm","clk":"990902409","pt":1580542631998,"mc":[{"id":"1.168136214","rc":[{"batb":[[0,3.45,3.99]],"ltp":3.95,"tv":633.69,"id":11981493}]}]}
{"op":"mcm","clk":"990903512","pt":1580542662131,"mc":[{"id":"1.168136214","rc":[{"batb":[[1,3.4,19.68]],"ltp":3.95,"tv":633.69,"id":11981493}]}]}
{"op":"mcm","clk":"990906018","pt":1580542721124,"mc":[{"id":"1.168136214","rc":[{"trd":[[3.45,42.71]],"batb":[[0,3.45,2.97]],"ltp":3.45,"tv":635.72,"id":11981493}],"tv":2924.22}]}
{"op":"mcm","clk":"990911523","pt":1580542829038,"mc":[{"id":"1.168136214","rc":[{"batb":[[0,4.2,4.51],[1,4.1,3],[2,4,10.62]],"ltp":4.2,"tv":377.43,"id":12925630}]}]}
{"op":"mcm","clk":"990913701","pt":1580542870934,"mc":[{"id":"1.168136214","rc":[{"trd":[[1.98,69.08]],"batb":[[0,1.98,13.63]],"ltp":1.98,"tv":1915.06,"id":17336468}],"tv":2928.22}]}
{"op":"mcm","clk":"990913927","pt":1580542874700,"mc":[{"id":"1.168136214","rc":[{"trd":[[2,856.05]],"batl":[[0,2,21.24]],"ltp":2.0,"tv":1919.02,"id":17336468}],"tv":2932.18}]}
{"op":"mcm","clk":"990921437","pt":1580543037515,"mc":[{"id":"1.168136214","rc":[{"batl":[[1,2.06,10.18],[2,2.08,43.18]],"ltp":2.0,"tv":1919.02,"id":17336468}]}]}
{"op":"mcm","clk":"990922083","pt":1580543051089,"mc":[{"id":"1.168136214","rc":[{"batl":[[0,1.99,13.04],[1,2,46.24],[2,2.06,10.18]],"ltp":2.0,"tv":1919.02,"id":17336468}]}]}
{"op":"mcm","clk":"990922132","pt":1580543052113,"mc":[{"id":"1.168136214","rc":[{"batl":[[1,2,21.24]],"ltp":2.0,"tv":1919.02,"id":17336468}]}]}
{"op":"mcm","clk":"990922274","pt":1580543055316,"mc":[{"id":"1.168136214","rc":[{"trd":[[1.98,96.34]],"batb":[[0,1.97,2],[1,1.96,13.1],[2,1.95,26.5]],"batl":[[0,1.98,8.37],[1,1.99,13.04],[2,2,21.24]],"ltp":1.98,"tv":1946.28,"id":17336468}],"tv":2959.44}]}
{"op":"mcm","clk":"990922477","pt":1580543059682,"mc":[{"id":"1.168136214","rc":[{"batl":[[2,2,46.24]],"ltp":1.98,"tv":1946.28,"id":17336468}]}]}
{"op":"mcm","clk":"990923389","pt":1580543079052,"mc":[{"id":"1.168136214","rc":[{"trd":[[1.98,113.08]],"batb":[[0,1.98,91.63],[1,1.97,2],[2,1.96,13.1]],"batl":[[0,2,46.24],[1,2.06,10.18],[2,2.08,30.58]],"ltp":1.98,"tv":1963.02,"id":17336468}],"tv":2976.18}]}
{"op":"mcm","clk":"990923446","pt":1580543080331,"mc":[{"id":"1.168136214","rc":[{"batl":[[1,2.06,24.7]],"ltp":1.98,"tv":1963.02,"id":17336468}]}]}
{"op":"mcm","clk":"990923509","pt":1580543081817,"mc":[{"id":"1.168136214","rc":[{"batl":[[1,2.06,42.15]],"ltp":1.98,"tv":1963.02,"id":17336468}]}]}
{"op":"mcm","clk":"990923572","pt":1580543083208,"mc":[{"id":"1.168136214","rc":[{"batl":[[1,2.04,11.76],[2,2.06,42.15]],"ltp":1.98,"tv":1963.02,"id":17336468}]}]}
{"op":"mcm","clk":"990927268","pt":1580543158910,"mc":[{"id":"1.168136214","rc":[{"trd":[[4.8,30.03]],"batb":[[0,4.8,5],[1,4.2,4.51],[2,4.1,3]],"batl":[[0,4.9,2.96],[1,7,1.83],[2,7.8,18.93]],"ltp":4.8,"tv":387.43,"id":12925630}],"tv":2986.18}]}
{"op":"mcm","clk":"990927356","pt":1580543160854,"mc":[{"id":"1.168136214","rc":[{"batb":[[1,4.3,3],[2,4.2,4.51]],"ltp":4.8,"tv":387.43,"id":12925630}]}]}
{"op":"mcm","clk":"990927702","pt":1580543168153,"mc":[{"id":"1.168136214","rc":[{"batb":[[0,4.3,3],[1,4.2,4.51],[2,4.1,3]],"ltp":4.8,"tv":387.43,"id":12925630}]}]}
{"op":"mcm","clk":"990927710","pt":1580543168308,"mc":[{"id":"1.168136214","rc":[{"trd":[[4.9,22.54]],"batb":[[0,4.9,2.04],[1,4.4,3.47],[2,4.3,3]],"batl":[[0,7,1.83],[1,7.8,18.93],[2,8,25]],"ltp":4.9,"tv":393.35,"id":12925630}],"tv":2992.09}]}
{"op":"mcm","clk":"990927798","pt":1580543170154,"mc":[{"id":"1.168136214","rc":[{"batb":[[1,4.5,3],[2,4.2,4.51]],"batl":[[1,7.6,5.18],[2,7.8,18.93]],"ltp":4.9,"tv":393.35,"id":12925630}]}]}
{"op":"mcm","clk":"990927921","pt":1580543172620,"mc":[{"id":"1.168136214","rc":[{"batl":[[0,6,1.01],[1,7,1],[2,7.6,5.18]],"ltp":4.9,"tv":393.35,"id":12925630}]}]}
{"op":"mcm","clk":"990928207","pt":1580543178839,"mc":[{"id":"1.168136214","rc":[{"batl":[[2,7.2,4]],"ltp":4.9,"tv":393.35,"id":12925630}]}]}
{"op":"mcm","clk":"990928356","pt":1580543181657,"mc":[{"id":"1.168136214","rc":[{"batl":[[1,7,3.27]],"ltp":4.9,"tv":393.35,"id":12925630}]}]}
{"op":"mcm","clk":"990928721","pt":1580543189056,"mc":[{"id":"1.168136214","rc":[{"batl":[[1,7,7.27],[2,7.6,5.18]],"ltp":4.9,"tv":393.35,"id":12925630}]}]}
{"op":"mcm","clk":"990928967","pt":1580543190858,"mc":[{"id":"1.168136214","rc":[{"batl":[[2,7.8,18.93]],"ltp":4.9,"tv":393.35,"id":12925630}]}]}
{"op":"mcm","clk":"990929349","pt":1580543193658,"mc":[{"id":"1.168136214","rc":[{"batb":[[1,4.6,9.4],[2,4.5,3]],"ltp":4.9,"tv":393.35,"id":12925630}]}]}
{"op":"mcm","clk":"990929712","pt":1580543199075,"mc":[{"id":"1.168136214","rc":[{"batl":[[1,7,3.27],[2,7.6,4]],"ltp":4.9,"tv":393.35,"id":12925630}]}]}
{"op":"mcm","clk":"990930129","pt":1580543207890,"mc":[{"id":"1.168136214","rc":[{"batl":[[2,7.2,4]],"ltp":4.9,"tv":393.35,"id":12925630}]}]}
{"op":"mcm","clk":"990930365","pt":1580543212195,"mc":[{"id":"1.168136214","rc":[{"batl":[[1,6.8,5.79],[2,7,3.27]],"ltp":4.9,"tv":393.35,"id":12925630}]}]}
{"op":"mcm","clk":"990931270","pt":1580543227107,"mc":[{"id":"1.168136214","rc":[{"batl":[[1,6.8,9.79]],"ltp":4.9,"tv":393.35,"id":12925630}]}]}
{"op":"mcm","clk":"990931312","pt":1580543228131,"mc":[{"id":"1.168136214","rc":[{"batl":[[1,6.6,6],[2,6.8,9.79]],"ltp":4.9,"tv":393.35,"id":12925630}]}]}
{"op":"mcm","clk":"990931416","pt":1580543229993,"mc":[{"id":"1.168136214","rc":[{"batl":[[0,5.8,3.98],[1,5.9,7.78],[2,6.6,6.83]],"ltp":4.9,"tv":393.35,"id":12925630}]}]}
{"op":"mcm","clk":"990931587","pt":1580543234013,"mc":[{"id":"1.168136214","rc":[{"batb":[[1,4.7,3],[2,4.6,9.4]],"batl":[[0,5.7,6.91],[1,5.8,3.98],[2,5.9,7.78]],"ltp":4.9,"tv":393.35,"id":12925630}]}]}
{"op":"mcm","clk":"990931663","pt":1580543235820,"mc":[{"id":"1.168136214","rc":[{"batl":[[1,5.8,7.98]],"ltp":4.9,"tv":393.35,"id":12925630}]}]}
{"op":"mcm","clk":"990932051","pt":1580543244535,"mc":[{"id":"1.168136214","rc":[{"batl":[[0,5.6,4],[1,5.7,6.91],[2,5.8,3.98]],"ltp":4.9,"tv":393.35,"id":12925630}]}]}
{"op":"mcm","clk":"990941995","pt":1580543254834,"mc":[{"id":"1.168136214","rc":[{"batl":[[1,5.8,3.98],[2,5.9,7.78]],"ltp":4.9,"tv":393.35,"id":12925630}]}]}
{"op":"mcm","clk":"990943177","pt":1580543274142,"mc":[{"id":"1.168136214","rc":[{"batb":[[1,4.6,9.4],[2,4.5,3]],"ltp":4.9,"tv":393.35,"id":12925630}]}]}
{"op":"mcm","clk":"990949567","pt":1580543454796,"mc":[{"id":"1.168136214","rc":[{"trd":[[1.98,129.88]],"batb":[[0,1.98,83.23]],"ltp":1.98,"tv":1979.82,"id":17336468}],"tv":3008.9}]}
{"op":"mcm","clk":"990949608","pt":1580543456080,"mc":[{"id":"1.168136214","rc":[{"batl":[[2,6,1.01]],"ltp":4.9,"tv":393.35,"id":12925630}]}]}
{"op":"mcm","clk":"990952027","pt":1580543523149,"mc":[{"id":"1.168136214","rc":[{"trd":[[2,936.05]],"batl":[[0,2,6.24]],"ltp":2.0,"tv":2059.82,"id":17336468},{"trd":[[3.55,59.68]],"ltp":3.55,"tv":639.72,"id":11981493}],"tv":3092.9}]}
{"op":"mcm","clk":"990952086","pt":1580543524849,"mc":[{"id":"1.168136214","rc":[{"batl":[[1,2.06,24.7],[2,2.08,30.58]],"ltp":2.0,"tv":2059.82,"id":17336468}]}]}
{"op":"mcm","clk":"990952552","pt":1580543539800,"mc":[{"id":"1.168136214","rc":[{"batl":[[0,3.9,4.26],[1,3.95,2.34],[2,4,8.32]],"ltp":3.55,"tv":639.72,"id":11981493}]}]}
{"op":"mcm","clk":"990952692","pt":1580543545864,"mc":[{"id":"1.168136214","rc":[{"trd":[[2,942.05]],"batl":[[0,2,3.24]],"ltp":2.0,"tv":2065.82,"id":17336468}],"tv":3098.9}]}
{"op":"mcm","clk":"990952745","pt":1580543548074,"mc":[{"id":"1.168136214","rc":[{"trd":[[4.9,26.62]],"batb":[[0,4.6,9.4],[1,4.5,3],[2,4.1,6]],"batl":[[0,5.6,4.48]],"ltp":4.9,"tv":397.43,"id":12925630}],"tv":3102.98}]}
{"op":"mcm","clk":"990952775","pt":1580543548798,"mc":[{"id":"1.168136214","rc":[{"batb":[[0,4.7,4.31],[1,4.6,9.4],[2,4.5,3]],"batl":[[1,6,1.01],[2,6.2,2]],"ltp":4.9,"tv":397.43,"id":12925630},{"batl":[[1,2.08,30.58],[2,2.16,15.14]],"ltp":2.0,"tv":2065.82,"id":17336468},{"batl":[[1,3.95,4.63],[2,4,6.05]],"ltp":3.55,"tv":639.72,"id":11981493}]}]}
{"op":"mcm","clk":"990952809","pt":1580543549881,"mc":[{"id":"1.168136214","rc":[{"batb":[[0,1.98,83.31]],"ltp":2.0,"tv":2065.82,"id":17336468}]}]}
{"op":"mcm","clk":"990952896","pt":1580543552152,"mc":[{"id":"1.168136214","rc":[{"batl":[[1,6.2,2.83],[2,6.6,6]],"ltp":4.9,"tv":397.43,"id":12925630}]}]}
{"op":"mcm","clk":"990953094","pt":1580543557908,"mc":[{"id":"1.168136214","rc":[{"batl":[[0,5.5,8.48],[1,5.6,4],[2,6.2,2.83]],"ltp":4.9,"tv":397.43,"id":12925630}]}]}
{"op":"mcm","clk":"990953205","pt":1580543561918,"mc":[{"id":"1.168136214","rc":[{"batl":[[0,5.4,3.42],[1,5.5,8],[2,5.6,4]],"ltp":4.9,"tv":397.43,"id":12925630}]}]}
{"op":"mcm","clk":"990953230","pt":1580543562790,"mc":[{"id":"1.168136214","rc":[{"batb":[[0,1.99,3.08],[1,1.98,83.23],[2,1.97,2]],"ltp":2.0,"tv":2065.82,"id":17336468}]}]}
{"op":"mcm","clk":"990953375","pt":1580543568113,"mc":[{"id":"1.168136214","rc":[{"trd":[[2,948.53]],"batb":[[0,2,14.76],[1,1.99,3.08],[2,1.98,83.23]],"batl":[[0,2.08,30.58],[1,2.16,15.14],[2,2.18,15.14]],"ltp":2.0,"tv":2072.3,"id":17336468}],"tv":3109.46}]}
{"op":"mcm","clk":"990953399","pt":1580543569092,"mc":[{"id":"1.168136214","rc":[{"batb":[[1,1.99,3]],"batl":[[1,2.14,4.8],[2,2.16,24.8]],"ltp":2.0,"tv":2072.3,"id":17336468}]}]}
{"op":"mcm","clk":"990953412","pt":1580543569605,"mc":[{"id":"1.168136214","rc":[{"batb":[[0,2,14.84]],"batl":[[0,2.06,12.68],[1,2.08,30.58],[2,2.14,4.8]],"ltp":2.0,"tv":2072.3,"id":17336468}]}]}
{"op":"mcm","clk":"990953489","pt":1580543571821,"mc":[{"id":"1.168136214","rc":[{"trd":[[4.7,48.52]],"batb":[[0,4.7,4.28]],"ltp":4.7,"tv":397.49,"id":12925630},{"trd":[[2.02,210.38]],"batb":[[0,2,14.76]],"ltp":2.02,"tv":2072.46,"id":17336468},{"trd":[[3.45,42.81]],"batb":[[0,3.45,2.92]],"ltp":3.45,"tv":639.82,"id":11981493}],"tv":3109.78}]}
{"op":"mcm","clk":"990953532","pt":1580543573110,"mc":[{"id":"1.168136214","rc":[{"batb":[[2,4.1,6]],"ltp":4.7,"tv":397.49,"id":12925630}]}]}
{"op":"mcm","clk":"990953535","pt":1580543573211,"mc":[{"id":"1.168136214","rc":[{"batb":[[2,4.3,3]],"ltp":4.7,"tv":397.49,"id":12925630}]}]}
{"op":"mcm","clk":"990953774","pt":1580543580004,"mc":[{"id":"1.168136214","rc":[{"batb":[[1,1.98,83.23],[2,1.97,2]],"ltp":2.02,"tv":2072.46,"id":17336468}]}]}
{"op":"mcm","clk":"990953873","pt":1580543583115,"mc":[{"id":"1.168136214","rc":[{"batb":[[1,1.99,6],[2,1.98,83.23]],"ltp":2.02,"tv":2072.46,"id":17336468}]}]}
{"op":"mcm","clk":"990953933","pt":1580543584813,"mc":[{"id":"1.168136214","rc":[{"batl":[[0,5.4,7.42],[2,6.2,2.83]],"ltp":4.7,"tv":397.49,"id":12925630}]}]}
{"op":"mcm","clk":"990954545","pt":1580543602136,"mc":[{"id":"1.168136214","rc":[{"batb":[[1,4.3,3],[2,4,10.62]],"ltp":4.7,"tv":397.49,"id":12925630}]}]}
{"op":"mcm","clk":"990954844","pt":1580543611655,"mc":[{"id":"1.168136214","rc":[{"batb":[[0,4.7,13.18]],"ltp":4.7,"tv":397.49,"id":12925630}]}]}
{"op":"mcm","clk":"990955301","pt":1580543626081,"mc":[{"id":"1.168136214","rc":[{"batl":[[0,2.04,8],[1,2.06,12.68],[2,2.08,30.58]],"ltp":2.02,"tv":2072.46,"id":17336468}]}]}
{"op":"mcm","clk":"990959261","pt":1580543741009,"mc":[{"id":"1.168136214","rc":[{"batb":[[2,4.1,4.05]],"batl":[[0,5.3,17.06],[1,5.4,6.95],[2,5.5,8]],"ltp":4.7,"tv":397.49,"id":12925630}]}]}
{"op":"mcm","clk":"990959499","pt":1580543747702,"mc":[{"id":"1.168136214","rc":[{"batl":[[0,5.3,21.06],[1,5.4,2.95]],"ltp":4.7,"tv":397.49,"id":12925630}]}]}
{"op":"mcm","clk":"990959959","pt":1580543762800,"mc":[{"id":"1.168136214","rc":[{"batl":[[0,3.95,4.82],[1,4,6.05],[2,4.1,1.22]],"ltp":3.45,"tv":639.82,"id":11981493}]}]}
{"op":"mcm","clk":"990960629","pt":1580543784638,"mc":[{"id":"1.168136214","rc":[{"batl":[[1,5.5,8],[2,6,42.83]],"ltp":4.7,"tv":397.49,"id":12925630}]}]}
{"op":"mcm","clk":"990960982","pt":1580543795946,"mc":[{"id":"1.168136214","rc":[{"batl":[[0,5.3,17.06],[1,5.4,4],[2,5.5,8]],"ltp":4.7,"tv":397.49,"id":12925630}]}]}
{"op":"mcm","clk":"990961223","pt":1580543806152,"mc":[{"id":"1.168136214","rc":[{"batl":[[0,5.3,21.06],[1,5.5,8],[2,6,42.83]],"ltp":4.7,"tv":397.49,"id":12925630}]}]}
{"op":"mcm","clk":"990961317","pt":1580543809844,"mc":[{"id":"1.168136214","rc":[{"batl":[[0,5.3,4.48],[1,5.4,7.26],[2,5.5,8]],"ltp":4.7,"tv":397.49,"id":12925630}]}]}
{"op":"mcm","clk":"990962180","pt":1580543843608,"mc":[{"id":"1.168136214","rc":[{"batl":[[0,5.2,3.41],[1,5.3,4]],"ltp":4.7,"tv":397.49,"id":12925630}]}]}
{"op":"mcm","clk":"990962431","pt":1580543853712,"mc":[{"id":"1.168136214","rc":[{"trd":[[2,956.53]],"batb":[[0,2,10.76]],"ltp":2.0,"tv":2080.46,"id":17336468},{"trd":[[3.45,48.66]],"batb":[[0,3.4,19.68],[1,3.35,2],[2,3.3,4.56]],"ltp":3.45,"tv":645.66,"id":11981493}],"tv":3123.63}]}
{"op":"mcm","clk":"990962661","pt":1580543862415,"mc":[{"id":"1.168136214","rc":[{"batl":[[0,5.1,4.48],[1,5.2,2.93]],"ltp":4.7,"tv":397.49,"id":12925630}]}]}
{"op":"mcm","clk":"990963044","pt":1580543876041,"mc":[{"id":"1.168136214","rc":[{"batl":[[0,3.9,4.26],[1,3.95,4.63],[2,4,6.05]],"ltp":3.45,"tv":645.66,"id":11981493}]}]}
{"op":"mcm","clk":"990972405","pt":1580544100847,"mc":[{"id":"1.168136214","rc":[{"batl":[[0,3.95,4.82],[1,4,6.05],[2,4.1,1.22]],"ltp":3.45,"tv":645.66,"id":11981493}]}]}
{"op":"mcm","clk":"990985626","pt":1580544163658,"mc":[{"id":"1.168136214","rc":[{"batl":[[0,3.9,7.79],[1,3.95,4.63],[2,4,6.05]],"ltp":3.45,"tv":645.66,"id":11981493}]}]}
{"op":"mcm","clk":"990989709","pt":1580544253967,"mc":[{"id":"1.168136214","rc":[{"batb":[[1,4.6,2.04],[2,4.3,3]],"batl":[[0,5,2.52],[1,5.1,4],[2,5.2,2.93]],"ltp":4.7,"tv":397.49,"id":12925630},{"batb":[[2,1.98,85.23]],"batl":[[0,2.02,2.06],[1,2.04,10]],"ltp":2.0,"tv":2080.46,"id":17336468},{"batb":[[0,3.4,21.68],[1,3.35,4]],"batl":[[0,3.85,2.23],[1,3.9,7.6],[2,3.95,4.63]],"ltp":3.45,"tv":645.66,"id":11981493}]}]}
{"op":"mcm","clk":"990989889","pt":1580544259064,"mc":[{"id":"1.168136214","rc":[{"batl":[[2,5.2,6.86]],"ltp":4.7,"tv":397.49,"id":12925630}]}]}
{"op":"mcm","clk":"990990247","pt":1580544268688,"mc":[{"id":"1.168136214","rc":[{"batl":[[0,5,2.04]],"ltp":4.7,"tv":397.49,"id":12925630}]}]}
{"op":"mcm","clk":"990990899","pt":1580544287027,"mc":[{"id":"1.168136214","rc":[{"trd":[[2,978.05]],"batb":[[0,1.99,6],[1,1.98,83.23],[2,1.97,4]],"batl":[[0,2.06,2.25],[1,2.08,30.58],[2,2.14,4.8]],"ltp":2.0,"tv":2101.98,"id":17336468},{"batb":[[0,3.45,2.25],[1,3.4,21.68],[2,3.35,4]],"ltp":3.45,"tv":645.66,"id":11981493}],"tv":3145.15}]}
{"op":"mcm","clk":"990991638","pt":1580544307136,"mc":[{"id":"1.168136214","rc":[{"trd":[[1.99,152.67]],"batb":[[0,1.98,83.23],[1,1.97,4],[2,1.96,13.1]],"batl":[[0,1.99,28.72],[1,2.06,2.25],[2,2.08,30.58]],"ltp":1.99,"tv":2113.98,"id":17336468}],"tv":3157.15}]}
{"op":"mcm","clk":"990991646","pt":1580544307340,"mc":[{"id":"1.168136214","rc":[{"batl":[[1,2,2.03],[2,2.02,2.03]],"ltp":1.99,"tv":2113.98,"id":17336468}]}]}
{"op":"mcm","clk":"990992087","pt":1580544316738,"mc":[{"id":"1.168136214","rc":[{"batl":[[0,4.9,4],[1,5.1,2.08]],"ltp":4.7,"tv":397.49,"id":12925630},{"batb":[[1,1.97,2],[2,1.96,15.1]],"ltp":1.99,"tv":2113.98,"id":17336468}]}]}
{"op":"mcm","clk":"990992127","pt":1580544317766,"mc":[{"id":"1.168136214","rc":[{"batl":[[0,4.9,6]],"ltp":4.7,"tv":397.49,"id":12925630}]}]}
{"op":"mcm","clk":"990992151","pt":1580544318439,"mc":[{"id":"1.168136214","rc":[{"batl":[[0,1.99,34.72]],"ltp":1.99,"tv":2113.98,"id":17336468}]}]}
{"op":"mcm","clk":"990994769","pt":1580544386121,"mc":[{"id":"1.168136214","rc":[{"batl":[[0,3.75,2.13],[1,3.8,2],[2,3.85,2.23]],"ltp":3.45,"tv":645.66,"id":11981493}]}]}
{"op":"mcm","clk":"990994950","pt":1580544390815,"mc":[{"id":"1.168136214","rc":[{"batl":[[2,3.85,2.04]],"ltp":3.45,"tv":645.66,"id":11981493}]}]}
{"op":"mcm","clk":"990996784","pt":1580544439075,"mc":[{"id":"1.168136214","rc":[{"batl":[[1,3.85,2.04],[2,3.95,4.63]],"ltp":3.45,"tv":645.66,"id":11981493}]}]}
{"op":"mcm","clk":"990996821","pt":1580544440007,"mc":[{"id":"1.168136214","rc":[{"batl":[[0,3.7,2]],"ltp":3.45,"tv":645.66,"id":11981493}]}]}
{"op":"mcm","clk":"990997545","pt":1580544460131,"mc":[{"id":"1.168136214","rc":[{"batl":[[0,3.65,2.1],[1,3.7,2]],"ltp":3.45,"tv":645.66,"id":11981493}]}]}
{"op":"mcm","clk":"990997951","pt":1580544471460,"mc":[{"id":"1.168136214","rc":[{"trd":[[1.99,196.43]],"batb":[[1,1.97,4]],"batl":[[0,1.99,12.84]],"ltp":1.99,"tv":2157.74,"id":17336468}],"tv":3200.91}]}
{"op":"mcm","clk":"990998118","pt":1580544478054,"mc":[{"id":"1.168136214","rc":[{"trd":[[1.99,220.43]],"batl":[[0,2.02,14.69],[1,2.06,16.89],[2,2.08,30.58]],"ltp":1.99,"tv":2181.74,"id":17336468},{"batl":[[2,3.95,6.97]],"ltp":3.45,"tv":645.66,"id":11981493}],"tv":3224.91}]}
{"op":"mcm","clk":"990998136","pt":1580544478976,"mc":[{"id":"1.168136214","rc":[{"batl":[[1,2.06,7.71]],"ltp":1.99,"tv":2181.74,"id":17336468}]}]}
{"op":"mcm","clk":"990998160","pt":1580544480001,"mc":[{"id":"1.168136214","rc":[{"batb":[[0,1.98,85.23]],"ltp":1.99,"tv":2181.74,"id":17336468}]}]}
{"op":"mcm","clk":"990998372","pt":1580544485988,"mc":[{"id":"1.168136214","rc":[{"batl":[[1,5,5],[2,5.1,2.08]],"ltp":4.7,"tv":397.49,"id":12925630}]}]}
{"op":"mcm","clk":"990998583","pt":1580544493979,"mc":[{"id":"1.168136214","rc":[{"batl":[[0,3.9,2.07],[1,3.95,6.97],[2,4,3.79]],"ltp":3.45,"tv":645.66,"id":11981493}]}]}
{"op":"mcm","clk":"990998603","pt":1580544495108,"mc":[{"id":"1.168136214","rc":[{"batl":[[1,2.06,2.25]],"ltp":1.99,"tv":2181.74,"id":17336468}]}]}
{"op":"mcm","clk":"990998918","pt":1580544509084,"mc":[{"id":"1.168136214","rc":[{"trd":[[4.6,120.66],[4.7,74.88]],"batb":[[0,4.5,4.02],[1,4.4,13.03]],"batl":[[0,4.6,7.8],[1,4.9,6.01],[2,5,5]],"ltp":4.6,"tv":431.93,"id":12925630},{"batb":[[0,1.99,2.15],[1,1.98,85.23],[2,1.97,4]],"batl":[[0,2.02,12.66],[1,2.04,2.15],[2,2.06,2.25]],"ltp":1.99,"tv":2181.74,"id":17336468},{"batl":[[1,3.95,4.63]],"ltp":3.45,"tv":645.66,"id":11981493}],"tv":3259.34}]}
{"op":"mcm","clk":"990998949","pt":1580544510985,"mc":[{"id":"1.168136214","rc":[{"batb":[[1,4.4,2.15]],"ltp":4.6,"tv":431.93,"id":12925630},{"batb":[[0,1.98,85.23],[1,1.97,4],[2,1.96,13.1]],"batl":[[0,2.02,14.66]],"ltp":1.99,"tv":2181.74,"id":17336468}]}]}
{"op":"mcm","clk":"990999136","pt":1580544519785,"mc":[{"id":"1.168136214","rc":[{"batl":[[1,4.8,4.01],[2,4.9,2]],"ltp":4.6,"tv":431.93,"id":12925630}]}]}
{"op":"mcm","clk":"990999338","pt":1580544529623,"mc":[{"id":"1.168136214","rc":[{"batl":[[0,4.6,11.8],[1,4.9,2.01],[2,5,5]],"ltp":4.6,"tv":431.93,"id":12925630}]}]}
{"op":"mcm","clk":"990999698","pt":1580544542845,"mc":[{"id":"1.168136214","rc":[{"trd":[[1.98,161.88]],"batb":[[0,1.98,69.23]],"ltp":1.98,"tv":2213.74,"id":17336468}],"tv":3291.34}]}
{"op":"mcm","clk":"991000416","pt":1580544569156,"mc":[{"id":"1.168136214","rc":[{"batl":[[0,4.6,7.8]],"ltp":4.6,"tv":431.93,"id":12925630}]}]}
{"op":"mcm","clk":"991000438","pt":1580544570086,"mc":[{"id":"1.168136214","rc":[{"batl":[[1,4.8,4.01],[2,4.9,2]],"ltp":4.6,"tv":431.93,"id":12925630},{"batb":[[0,1.98,67.23]],"ltp":1.98,"tv":2213.74,"id":17336468}]}]}
{"op":"mcm","clk":"991000946","pt":1580544588519,"mc":[{"id":"1.168136214","rc":[{"batl":[[0,4.6,11.8],[1,4.9,2.01],[2,5,5]],"ltp":4.6,"tv":431.93,"id":12925630}]}]}
{"op":"mcm","clk":"991001284","pt":1580544600934,"mc":[{"id":"1.168136214","rc":[{"batb":[[0,4.5,6.02]],"batl":[[0,4.6,9.8],[1,4.7,2.01],[2,4.9,2]],"ltp":4.6,"tv":431.93,"id":12925630},{"batb":[[0,1.99,3],[1,1.98,67.23],[2,1.97,4]],"batl":[[0,2.02,12.66],[1,2.06,2.25],[2,2.08,30.58]],"ltp":1.98,"tv":2213.74,"id":17336468},{"trd":[[3.45,57.68]],"batb":[[0,3.4,21.68],[1,3.35,2],[2,3.3,6.56]],"batl":[[0,3.45,23.49],[1,3.55,2],[2,3.6,2]],"ltp":3.45,"tv":654.68,"id":11981493}],"tv":3300.36}]}
{"op":"mcm","clk":"991001339","pt":1580544602136,"mc":[{"id":"1.168136214","rc":[{"trd":[[4.6,132.51]],"batl":[[0,4.6,3.87]],"ltp":4.6,"tv":443.79,"id":12925630},{"trd":[[2,979.73],[2.02,234.03]],"batb":[[0,1.99,3.84]],"batl":[[0,2.06,2.25],[1,2.08,30.58],[2,2.16,131.14]],"ltp":2.02,"tv":2239.07,"id":17336468},{"trd":[[3.45,73.48]],"batb":[[1,3.35,4]],"batl":[[0,3.45,15.59]],"ltp":3.45,"tv":670.48,"id":11981493}],"tv":3353.35}]}
{"op":"mcm","clk":"991001536","pt":1580544609257,"mc":[{"id":"1.168136214","rc":[{"batl":[[2,2.16,15.14]],"ltp":2.02,"tv":2239.07,"id":17336468},{"batl":[[1,3.5,2.05],[2,3.55,2]],"ltp":3.45,"tv":670.48,"id":11981493}]}]}
{"op":"mcm","clk":"991001832","pt":1580544616943,"mc":[{"id":"1.168136214","rc":[{"batb":[[0,4.5,4.02],[2,4.3,5]],"ltp":4.6,"tv":443.79,"id":12925630},{"trd":[[3.45,104.66]],"batl":[[0,3.75,4.4],[1,3.8,12.71],[2,3.85,75.49]],"ltp":3.45,"tv":701.66,"id":11981493}],"tv":3384.53}]}
{"op":"mcm","clk":"991002568","pt":1580544639393,"mc":[{"id":"1.168136214","rc":[{"batb":[[0,3.45,2.21],[1,3.4,21.68],[2,3.35,4]],"batl":[[2,3.85,10.49]],"ltp":3.45,"tv":701.66,"id":11981493}]}]}
{"op":"mcm","clk":"991002703","pt":1580544643673,"mc":[{"id":"1.168136214","rc":[{"batb":[[0,3.5,4.06],[1,3.45,2.21],[2,3.4,21.68]],"ltp":3.45,"tv":701.66,"id":11981493}]}]}
{"op":"mcm","clk":"991002875","pt":1580544647693,"mc":[{"id":"1.168136214","rc":[{"batl":[[0,4.6,5.87]],"ltp":4.6,"tv":443.79,"id":12925630},{"batb":[[0,1.98,71.07],[1,1.97,4],[2,1.96,13.1]],"ltp":2.02,"tv":2239.07,"id":17336468},{"batl":[[1,3.95,2.29],[2,4,3.79]],"ltp":3.45,"tv":701.66,"id":11981493}]}]}
{"op":"mcm","clk":"991003154","pt":1580544655999,"mc":[{"id":"1.168136214","rc":[{"batb":[[0,1.99,6.84],[1,1.98,70.23],[2,1.97,4]],"ltp":2.02,"tv":2239.07,"id":17336468}]}]}
{"op":"mcm","clk":"991004547","pt":1580544700088,"mc":[{"id":"1.168136214","rc":[{"trd":[[4.6,144.25]],"batl":[[0,4.7,2.01],[1,4.9,2],[2,5,5]],"ltp":4.6,"tv":455.53,"id":12925630}],"tv":3396.27}]}
{"op":"mcm","clk":"991004959","pt":1580544713910,"mc":[{"id":"1.168136214","rc":[{"batl":[[1,4.8,4],[2,4.9,2]],"ltp":4.6,"tv":455.53,"id":12925630}]}]}
{"op":"mcm","clk":"991005281","pt":1580544724098,"mc":[{"id":"1.168136214","rc":[{"batl":[[0,4.6,4],[1,4.7,2.01]],"ltp":4.6,"tv":455.53,"id":12925630}]}]}
{"op":"mcm","clk":"991005312","pt":1580544724817,"mc":[{"id":"1.168136214","rc":[{"batl":[[0,4.6,6]],"ltp":4.6,"tv":455.53,"id":12925630},{"trd":[[3.75,40.8]],"batl":[[0,3.95,2.29],[1,4,3.79],[2,4.1,1.22]],"ltp":3.75,"tv":710.46,"id":11981493}],"tv":3405.07}]}
{"op":"mcm","clk":"991005339","pt":1580544726013,"mc":[{"id":"1.168136214","rc":[{"batl":[[0,3.9,2.03],[1,3.95,2.29],[2,4,6.57]],"ltp":3.75,"tv":710.46,"id":11981493}]}]}
{"op":"mcm","clk":"991005395","pt":1580544727626,"mc":[{"id":"1.168136214","rc":[{"batb":[[1,1.98,67.23]],"ltp":2.02,"tv":2239.07,"id":17336468},{"batl":[[2,4,3.79]],"ltp":3.75,"tv":710.46,"id":11981493}]}]}
{"op":"mcm","clk":"991005649","pt":1580544735797,"mc":[{"id":"1.168136214","rc":[{"batl":[[0,3.9,6.1]],"ltp":3.75,"tv":710.46,"id":11981493}]}]}
{"op":"mcm","clk":"991006232","pt":1580544756017,"mc":[{"id":"1.168136214","rc":[{"batl":[[0,4.6,4]],"ltp":4.6,"tv":455.53,"id":12925630},{"trd":[[1.98,174.2],[1.99,232.43],[2,981.41]],"batb":[[0,1.99,3.19],[1,1.98,61.07]],"ltp":1.98,"tv":2265.07,"id":17336468},{"trd":[[3.5,40.52]],"batb":[[0,3.45,2.21],[1,3.4,21.68],[2,3.35,2]],"batl":[[0,3.5,2.94],[1,3.9,6.1],[2,3.95,2.29]],"ltp":3.5,"tv":718.58,"id":11981493}],"tv":3439.18}]}
{"op":"mcm","clk":"991006556","pt":1580544766058,"mc":[{"id":"1.168136214","rc":[{"batl":[[0,4.6,6]],"ltp":4.6,"tv":455.53,"id":12925630},{"batb":[[0,1.98,64.07],[1,1.97,4],[2,1.96,13.1]],"ltp":1.98,"tv":2265.07,"id":17336468},{"trd":[[3.45,110.54]],"batb":[[0,3.45,9.32]],"batl":[[0,3.9,6.1],[1,3.95,2.29],[2,4,3.79]],"ltp":3.45,"tv":724.46,"id":11981493}],"tv":3445.06}]}
{"op":"mcm","clk":"991006579","pt":1580544766936,"mc":[{"id":"1.168136214","rc":[{"batb":[[0,1.98,61.07]],"ltp":1.98,"tv":2265.07,"id":17336468},{"batb":[[0,3.5,2.25],[1,3.45,9.32],[2,3.4,21.68]],"ltp":3.45,"tv":724.46,"id":11981493}]}]}
{"op":"mcm","clk":"991006647","pt":1580544769148,"mc":[{"id":"1.168136214","rc":[{"batb":[[0,1.98,64.07]],"batl":[[0,2.02,2.26],[1,2.04,6],[2,2.06,2.25]],"ltp":1.98,"tv":2265.07,"id":17336468}]}]}
{"op":"mcm","clk":"991006678","pt":1580544770133,"mc":[{"id":"1.168136214","rc":[{"batl":[[0,3.85,2.36],[1,3.9,6.1],[2,3.95,2.29]],"ltp":3.45,"tv":724.46,"id":11981493}]}]}
{"op":"mcm","clk":"991007018","pt":1580544781147,"mc":[{"id":"1.168136214","rc":[{"batb":[[0,1.98,61.07]],"batl":[[0,2,6],[1,2.06,2.25],[2,2.08,30.58]],"ltp":1.98,"tv":2265.07,"id":17336468},{"batl":[[0,3.8,2],[1,3.85,2.36],[2,3.9,6.1]],"ltp":3.45,"tv":724.46,"id":11981493}]}]}
{"op":"mcm","clk":"991007309","pt":1580544787864,"mc":[{"id":"1.168136214","rc":[{"batl":[[1,2.02,2],[2,2.04,2]],"ltp":1.98,"tv":2265.07,"id":17336468},{"trd":[[3.5,41.86]],"batb":[[0,3.45,11.32],[1,3.4,21.68],[2,3.35,2]],"ltp":3.5,"tv":725.8,"id":11981493}],"tv":3446.4}]}
{"op":"mcm","clk":"991007830","pt":1580544802080,"mc":[{"id":"1.168136214","rc":[{"batb":[[0,3.5,2.12],[1,3.45,11.32],[2,3.4,21.68]],"batl":[[0,3.75,1.68],[1,3.85,2.12]],"ltp":3.5,"tv":725.8,"id":11981493}]}]}
{"op":"mcm","clk":"991007900","pt":1580544803901,"mc":[{"id":"1.168136214","rc":[{"trd":[[3.5,42.74]],"batb":[[0,3.5,1.68]],"batl":[[0,3.7,2.12],[1,3.75,1.68],[2,3.9,4.07]],"ltp":3.5,"tv":726.68,"id":11981493}],"tv":3447.28}]}
{"op":"mcm","clk":"991008042","pt":1580544808107,"mc":[{"id":"1.168136214","rc":[{"batb":[[2,3.4,31.68]],"ltp":3.5,"tv":726.68,"id":11981493}]}]}
{"op":"mcm","clk":"991009111","pt":1580544833918,"mc":[{"id":"1.168136214","rc":[{"batl":[[0,3.65,1.68],[1,3.8,2.29]],"ltp":3.5,"tv":726.68,"id":11981493}]}]}
{"op":"mcm","clk":"991009719","pt":1580544848114,"mc":[{"id":"1.168136214","rc":[{"batl":[[1,3.7,2.04],[2,3.8,2.29]],"ltp":3.5,"tv":726.68,"id":11981493}]}]}
{"op":"mcm","clk":"991010401","pt":1580544863061,"mc":[{"id":"1.168136214","rc":[{"trd":[[4.6,147.61]],"batl":[[0,4.6,4.32]],"ltp":4.6,"tv":458.89,"id":12925630}],"tv":3450.65}]}
{"op":"mcm","clk":"991010576","pt":1580544866069,"mc":[{"id":"1.168136214","rc":[{"batl":[[0,3.7,2.04],[1,3.75,1.68]],"ltp":3.5,"tv":726.68,"id":11981493}]}]}
{"op":"mcm","clk":"991010631","pt":1580544867154,"mc":[{"id":"1.168136214","rc":[{"batl":[[0,4.6,2.32]],"ltp":4.6,"tv":458.89,"id":12925630},{"batb":[[0,1.98,64.07]],"ltp":1.98,"tv":2265.07,"id":17336468},{"batl":[[0,3.75,1.68],[1,3.9,2.14],[2,4,3.79]],"ltp":3.5,"tv":726.68,"id":11981493}]}]}
{"op":"mcm","clk":"991010669","pt":1580544867978,"mc":[{"id":"1.168136214","rc":[{"batl":[[0,3.7,2.15],[1,3.75,1.68],[2,4,6.05]],"ltp":3.5,"tv":726.68,"id":11981493}]}]}
{"op":"mcm","clk":"991010857","pt":1580544873083,"mc":[{"id":"1.168136214","rc":[{"batb":[[1,1.97,6]],"ltp":1.98,"tv":2265.07,"id":17336468},{"trd":[[3.45,115.3],[3.5,46.09]],"batb":[[0,3.5,2],[1,3.45,8.94]],"ltp":3.45,"tv":734.8,"id":11981493}],"tv":3458.76}]}
{"op":"mcm","clk":"991010859","pt":1580544873185,"mc":[{"id":"1.168136214","rc":[{"batl":[[2,3.95,3.38]],"ltp":3.45,"tv":734.8,"id":11981493}]}]}
{"op":"mcm","clk":"991012250","pt":1580544903589,"mc":[{"id":"1.168136214","rc":[{"batl":[[0,4.6,4.32]],"ltp":4.6,"tv":458.89,"id":12925630}]}]}
{"op":"mcm","clk":"991015400","pt":1580544970982,"mc":[{"id":"1.168136214","rc":[{"batb":[[0,1.98,61.07]],"ltp":1.98,"tv":2265.07,"id":17336468},{"batb":[[0,3.55,2.05],[1,3.5,17],[2,3.45,8.94]],"ltp":3.45,"tv":734.8,"id":11981493}]}]}
{"op":"mcm","clk":"991016426","pt":1580544989145,"mc":[{"id":"1.168136214","rc":[{"trd":[[3.7,56.04]],"batl":[[0,3.7,2.5]],"ltp":3.7,"tv":739.84,"id":11981493}],"tv":3463.8}]}
{"op":"mcm","clk":"991016473","pt":1580544990127,"mc":[{"id":"1.168136214","rc":[{"batb":[[2,3.45,2]],"batl":[[0,3.7,4.65]],"ltp":3.7,"tv":739.84,"id":11981493}]}]}
{"op":"mcm","clk":"991017226","pt":1580544996711,"mc":[{"id":"1.168136214","rc":[{"batl":[[1,3.95,3.38],[2,4,3.79]],"ltp":3.7,"tv":739.84,"id":11981493}]}]}
{"op":"mcm","clk":"991018314","pt":1580545018935,"mc":[{"id":"1.168136214","rc":[{"batl":[[1,3.95,7.21]],"ltp":3.7,"tv":739.84,"id":11981493}]}]}
{"op":"mcm","clk":"991019478","pt":1580545038950,"mc":[{"id":"1.168136214","rc":[{"trd":[[2,993.41],[2.02,238.03],[2.04,99.74]],"batl":[[0,2.06,2.25],[1,2.08,30.58],[2,2.14,117]],"ltp":2.04,"tv":2285.07,"id":17336468}],"tv":3483.8}]}
{"op":"mcm","clk":"991019552","pt":1580545040084,"mc":[{"id":"1.168136214","rc":[{"batl":[[1,2.08,34.59]],"ltp":2.04,"tv":2285.07,"id":17336468}]}]}
{"op":"mcm","clk":"991019598","pt":1580545040666,"mc":[{"id":"1.168136214","rc":[{"batl":[[2,2.12,11.32]],"ltp":2.04,"tv":2285.07,"id":17336468}]}]}
{"op":"mcm","clk":"991019758","pt":1580545042874,"mc":[{"id":"1.168136214","rc":[{"batb":[[0,1.98,65.07]],"batl":[[0,2.02,2.12],[1,2.04,15.62],[2,2.06,2.25]],"ltp":2.04,"tv":2285.07,"id":17336468}]}]}
{"op":"mcm","clk":"991030353","pt":1580545061569,"mc":[{"id":"1.168136214","rc":[{"batb":[[0,1.98,61.07]],"ltp":2.04,"tv":2285.07,"id":17336468}]}]}
{"op":"mcm","clk":"991031169","pt":1580545075593,"mc":[{"id":"1.168136214","rc":[{"batl":[[0,2.06,2.25],[1,2.08,30.58],[2,2.16,131.14]],"ltp":2.04,"tv":2285.07,"id":17336468}]}]}
{"op":"mcm","clk":"991032087","pt":1580545090000,"mc":[{"id":"1.168136214","rc":[{"batl":[[2,2.16,15.14]],"ltp":2.04,"tv":2285.07,"id":17336468}]}]}
{"op":"mcm","clk":"991032165","pt":1580545091147,"mc":[{"id":"1.168136214","rc":[{"batb":[[0,1.98,65.07]],"ltp":2.04,"tv":2285.07,"id":17336468}]}]}
{"op":"mcm","clk":"991033038","pt":1580545107148,"mc":[{"id":"1.168136214","rc":[{"batl":[[0,2.02,2.14],[1,2.04,16.55],[2,2.06,2.25]],"ltp":2.04,"tv":2285.07,"id":17336468}]}]}
{"op":"mcm","clk":"991033851","pt":1580545120858,"mc":[{"id":"1.168136214","rc":[{"batb":[[0,1.98,61.07]],"ltp":2.04,"tv":2285.07,"id":17336468}]}]}
{"op":"mcm","clk":"991034716","pt":1580545135964,"mc":[{"id":"1.168136214","rc":[{"batb":[[0,4.5,6.02]],"batl":[[0,4.6,2.32]],"ltp":4.6,"tv":458.89,"id":12925630},{"trd":[[1.98,274.2]],"batb":[[0,1.98,11.07]],"ltp":1.98,"tv":2385.07,"id":17336468}],"tv":3583.8}]}
{"op":"mcm","clk":"991034810","pt":1580545137101,"mc":[{"id":"1.168136214","rc":[{"batb":[[0,4.5,4.02]],"ltp":4.6,"tv":458.89,"id":12925630}]}]}
{"op":"mcm","clk":"991034930","pt":1580545139005,"mc":[{"id":"1.168136214","rc":[{"batb":[[0,4.5,6.02]],"ltp":4.6,"tv":458.89,"id":12925630},{"batl":[[0,2.06,14.93],[1,2.08,30.58],[2,2.16,131.14]],"ltp":1.98,"tv":2385.07,"id":17336468}]}]}
{"op":"mcm","clk":"991035546","pt":1580545150116,"mc":[{"id":"1.168136214","rc":[{"batl":[[2,2.16,15.14]],"ltp":1.98,"tv":2385.07,"id":17336468}]}]}
{"op":"mcm","clk":"991035600","pt":1580545151095,"mc":[{"id":"1.168136214","rc":[{"batb":[[0,4.5,4.02]],"batl":[[0,4.6,4.32]],"ltp":4.6,"tv":458.89,"id":12925630}]}]}
{"op":"mcm","clk":"991035986","pt":1580545158117,"mc":[{"id":"1.168136214","rc":[{"trd":[[3.55,63.68]],"batb":[[0,3.5,17.05],[1,3.45,2],[2,3.4,29.68]],"ltp":3.55,"tv":743.84,"id":11981493}],"tv":3587.8}]}
{"op":"mcm","clk":"991036615","pt":1580545170057,"mc":[{"id":"1.168136214","rc":[{"batl":[[0,2.04,3.97],[1,2.06,14.93],[2,2.08,30.58]],"ltp":1.98,"tv":2385.07,"id":17336468}]}]}
{"op":"mcm","clk":"991036645","pt":1580545170725,"mc":[{"id":"1.168136214","rc":[{"batl":[[0,2.02,2.16],[1,2.04,3.97],[2,2.06,14.93]],"ltp":1.98,"tv":2385.07,"id":17336468},{"batb":[[0,3.55,2.05],[1,3.5,17],[2,3.45,2]],"ltp":3.55,"tv":743.84,"id":11981493}]}]}
{"op":"mcm","clk":"991036957","pt":1580545176149,"mc":[{"id":"1.168136214","rc":[{"trd":[[3.5,61.99],[3.55,67.78]],"batb":[[0,3.55,9.21],[1,3.5,9.05]],"batl":[[0,3.7,2.15]],"ltp":3.5,"tv":763.84,"id":11981493}],"tv":3607.8}]}
{"op":"mcm","clk":"991036979","pt":1580545176555,"mc":[{"id":"1.168136214","rc":[{"batb":[[0,3.6,2.19],[1,3.55,9.21],[2,3.5,9.05]],"batl":[[0,3.9,3.2]],"ltp":3.5,"tv":763.84,"id":11981493}]}]}
{"op":"mcm","clk":"991037068","pt":1580545178056,"mc":[{"id":"1.168136214","rc":[{"batl":[[0,3.9,7.27]],"ltp":3.5,"tv":763.84,"id":11981493}]}]}
{"op":"mcm","clk":"991037921","pt":1580545191840,"mc":[{"id":"1.168136214","rc":[{"batl":[[0,3.8,3.28],[1,3.85,2],[2,3.9,7.27]],"ltp":3.5,"tv":763.84,"id":11981493}]}]}
{"op":"mcm","clk":"991038486","pt":1580545200043,"mc":[{"id":"1.168136214","rc":[{"trd":[[1.98,296.34]],"batb":[[0,1.97,2],[1,1.96,18.1],[2,1.95,26.5]],"ltp":1.98,"tv":2407.21,"id":17336468}],"tv":3629.94}]}
{"op":"mcm","clk":"991039349","pt":1580545213872,"mc":[{"id":"1.168136214","rc":[{"batb":[[0,4.5,9.02]],"ltp":4.6,"tv":458.89,"id":12925630}]}]}
{"op":"mcm","clk":"991040263","pt":1580545230095,"mc":[{"id":"1.168136214","rc":[{"batl":[[1,4.7,2]],"ltp":4.6,"tv":458.89,"id":12925630}]}]}
{"op":"mcm","clk":"991041018","pt":1580545243112,"mc":[{"id":"1.168136214","rc":[{"trd":[[4.6,156.25]],"batb":[[0,4.5,9.7]],"batl":[[0,4.7,2],[1,4.9,2],[2,5,5]],"ltp":4.6,"tv":467.53,"id":12925630}],"tv":3638.58}]}
{"op":"mcm","clk":"991041081","pt":1580545243996,"mc":[{"id":"1.168136214","rc":[{"batl":[[0,4.9,2],[1,5,5],[2,5.1,1.58]],"ltp":4.6,"tv":467.53,"id":12925630}]}]}
{"op":"mcm","clk":"991041227","pt":1580545246120,"mc":[{"id":"1.168136214","rc":[{"batl":[[0,3.85,3.24],[1,3.9,7.27],[2,3.95,3.83]],"ltp":3.5,"tv":763.84,"id":11981493}]}]}
{"op":"mcm","clk":"991042722","pt":1580545268051,"mc":[{"id":"1.168136214","rc":[{"batl":[[0,3.75,3.04],[1,3.8,2.44],[2,3.85,3.24]],"ltp":3.5,"tv":763.84,"id":11981493}]}]}
{"op":"mcm","clk":"991042935","pt":1580545271151,"mc":[{"id":"1.168136214","rc":[{"trd":[[1.95,69.67],[1.96,65.75],[1.97,45.34]],"batb":[[0,1.96,3.05],[1,1.95,28.6],[2,1.94,32.5]],"batl":[[2,2.06,2.25]],"ltp":1.95,"tv":2449.21,"id":17336468},{"batb":[[0,3.6,2.06]],"ltp":3.5,"tv":763.84,"id":11981493}],"tv":3680.58}]}
{"op":"mcm","clk":"991042986","pt":1580545272078,"mc":[{"id":"1.168136214","rc":[{"batb":[[0,1.95,28.6],[1,1.94,32.5],[2,1.93,60]],"ltp":1.95,"tv":2449.21,"id":17336468}]}]}
{"op":"mcm","clk":"991043768","pt":1580545285082,"mc":[{"id":"1.168136214","rc":[{"batl":[[0,4.8,2.13],[1,4.9,7],[2,5,5]],"ltp":4.6,"tv":467.53,"id":12925630}]}]}
{"op":"mcm","clk":"991044395","pt":1580545295096,"mc":[{"id":"1.168136214","rc":[{"batb":[[0,4.5,11.7]],"batl":[[0,4.8,5],[1,4.9,2]],"ltp":4.6,"tv":467.53,"id":12925630}]}]}
{"op":"mcm","clk":"991044463","pt":1580545296084,"mc":[{"id":"1.168136214","rc":[{"batb":[[0,4.5,9.7]],"batl":[[0,4.7,2.19],[1,4.8,5],[2,4.9,2]],"ltp":4.6,"tv":467.53,"id":12925630}]}]}
{"op":"mcm","clk":"991044719","pt":1580545299979,"mc":[{"id":"1.168136214","rc":[{"batl":[[0,1.99,2.21],[1,2,1.68],[2,2.08,30.58]],"ltp":1.95,"tv":2449.21,"id":17336468},{"batb":[[0,3.6,2.21]],"batl":[[0,3.85,3.24],[1,3.9,4.07],[2,3.95,3.83]],"ltp":3.5,"tv":763.84,"id":11981493}]}]}
{"op":"mcm","clk":"991045011","pt":1580545304584,"mc":[{"id":"1.168136214","rc":[{"trd":[[4.6,157.61]],"batb":[[0,4.5,9.02]],"batl":[[0,4.6,4.32],[1,4.9,2],[2,5,5]],"ltp":4.6,"tv":468.89,"id":12925630}],"tv":3681.94}]}
{"op":"mcm","clk":"991045592","pt":1580545314088,"mc":[{"id":"1.168136214","rc":[{"batl":[[0,4.7,2.29],[1,4.8,4.32],[2,4.9,2]],"ltp":4.6,"tv":468.89,"id":12925630},{"batb":[[0,1.96,4.29],[1,1.95,28.6],[2,1.94,32.5]],"batl":[[0,2,3.68],[1,2.06,4]],"ltp":1.95,"tv":2449.21,"id":17336468}]}]}
{"op":"mcm","clk":"991045639","pt":1580545315012,"mc":[{"id":"1.168136214","rc":[{"batl":[[0,4.8,4.32],[1,4.9,2],[2,5,5]],"ltp":4.6,"tv":468.89,"id":12925630}]}]}
{"op":"mcm","clk":"991046587","pt":1580545331047,"mc":[{"id":"1.168136214","rc":[{"batl":[[0,4.7,2.05],[1,4.8,4.32],[2,4.9,2]],"ltp":4.6,"tv":468.89,"id":12925630}]}]}
{"op":"mcm","clk":"991046651","pt":1580545332145,"mc":[{"id":"1.168136214","rc":[{"batl":[[0,2.04,3.98]],"ltp":1.95,"tv":2449.21,"id":17336468},{"batb":[[0,3.55,9.21],[1,3.5,9.05],[2,3.4,29.68]],"batl":[[0,3.75,3.06],[1,3.8,2.44],[2,3.85,3.24]],"ltp":3.5,"tv":763.84,"id":11981493}]}]}
{"op":"mcm","clk":"991047403","pt":1580545343144,"mc":[{"id":"1.168136214","rc":[{"batl":[[1,2.08,30.58],[2,2.16,15.14]],"ltp":1.95,"tv":2449.21,"id":17336468}]}]}
{"op":"mcm","clk":"991048582","pt":1580545362884,"mc":[{"id":"1.168136214","rc":[{"batl":[[0,4.6,4.32],[1,4.9,2],[2,5,5]],"ltp":4.6,"tv":468.89,"id":12925630},{"batb":[[0,3.6,2.23],[1,3.55,9.21],[2,3.5,9.05]],"ltp":3.5,"tv":763.84,"id":11981493}]}]}
{"op":"mcm","clk":"991048655","pt":1580545364025,"mc":[{"id":"1.168136214","rc":[{"batl":[[1,4.7,2.24],[2,4.9,2]],"ltp":4.6,"tv":468.89,"id":12925630},{"batl":[[0,2.06,6.17]],"ltp":1.95,"tv":2449.21,"id":17336468},{"batl":[[1,3.85,3.24],[2,3.9,4.07]],"ltp":3.5,"tv":763.84,"id":11981493}]}]}
{"op":"mcm","clk":"991048720","pt":1580545364904,"mc":[{"id":"1.168136214","rc":[{"batl":[[0,3.85,3.24],[1,3.9,4.07],[2,3.95,3.83]],"ltp":3.5,"tv":763.84,"id":11981493}]}]}
{"op":"mcm","clk":"991049664","pt":1580545379008,"mc":[{"id":"1.168136214","rc":[{"batb":[[0,1.96,3]],"batl":[[1,2.08,32.58]],"ltp":1.95,"tv":2449.21,"id":17336468}]}]}
{"op":"mcm","clk":"991050817","pt":1580545397128,"mc":[{"id":"1.168136214","rc":[{"batb":[[2,1.94,36.5]],"ltp":1.95,"tv":2449.21,"id":17336468},{"batl":[[0,3.8,5.44],[1,3.85,3.24],[2,3.9,4.07]],"ltp":3.5,"tv":763.84,"id":11981493}]}]}
{"op":"mcm","clk":"991051750","pt":1580545410656,"mc":[{"id":"1.168136214","rc":[{"batl":[[2,3.95,3.83]],"ltp":3.5,"tv":763.84,"id":11981493}]}]}
{"op":"mcm","clk":"991055704","pt":1580545470060,"mc":[{"id":"1.168136214","rc":[{"trd":[[4.5,37.97],[4.6,161.59]],"batb":[[0,4.3,5],[1,4,17.91],[2,3.95,6]],"batl":[[0,4.5,8.78],[1,4.6,4.33],[2,4.7,2.24]],"ltp":4.6,"tv":490.92,"id":12925630},{"batb":[[0,1.96,6]],"ltp":1.95,"tv":2449.21,"id":17336468}],"tv":3703.98}]}
{"op":"mcm","clk":"991055758","pt":1580545470739,"mc":[{"id":"1.168136214","rc":[{"trd":[[4.5,49.63]],"batl":[[0,4.5,2.95]],"ltp":4.5,"tv":502.58,"id":12925630}],"tv":3715.64}]}
{"op":"mcm","clk":"991056224","pt":1580545477085,"mc":[{"id":"1.168136214","rc":[{"batb":[[0,4.1,8.34],[1,4,20.91]],"batl":[[0,4.6,4.33],[1,4.7,2.24],[2,4.9,2]],"ltp":4.5,"tv":502.58,"id":12925630}]}]}
{"op":"mcm","clk":"991056374","pt":1580545478954,"mc":[{"id":"1.168136214","rc":[{"batl":[[0,4.4,2.33],[1,4.8,2.21]],"ltp":4.5,"tv":502.58,"id":12925630}]}]}
{"op":"mcm","clk":"991057172","pt":1580545490864,"mc":[{"id":"1.168136214","rc":[{"batb":[[2,3.8,3.05]],"ltp":4.5,"tv":502.58,"id":12925630}]}]}
{"op":"mcm","clk":"991057607","pt":1580545499097,"mc":[{"id":"1.168136214","rc":[{"batl":[[0,4.6,2.33],[1,4.9,2],[2,5,5]],"ltp":4.5,"tv":502.58,"id":12925630}]}]}
{"op":"mcm","clk":"991058410","pt":1580545511790,"mc":[{"id":"1.168136214","rc":[{"batl":[[0,4.6,4.33]],"ltp":4.5,"tv":502.58,"id":12925630}]}]}
{"op":"mcm","clk":"991058878","pt":1580545518788,"mc":[{"id":"1.168136214","rc":[{"batl":[[0,4.8,4.43]],"ltp":4.5,"tv":502.58,"id":12925630}]}]}
{"op":"mcm","clk":"991059330","pt":1580545526007,"mc":[{"id":"1.168136214","rc":[{"batb":[[0,4.3,2.14],[1,4.2,7.31],[2,4.1,8.34]],"ltp":4.5,"tv":502.58,"id":12925630}]}]}
{"op":"mcm","clk":"991061241","pt":1580545560049,"mc":[{"id":"1.168136214","rc":[{"trd":[[2.06,99.81]],"batl":[[0,2.06,3.17]],"ltp":2.06,"tv":2455.21,"id":17336468}],"tv":3721.63}]}
{"op":"mcm","clk":"991061288","pt":1580545560874,"mc":[{"id":"1.168136214","rc":[{"batb":[[0,4.4,4.36],[1,4.2,2],[2,4.1,2.2]],"batl":[[0,4.7,4.94],[1,4.8,4.43],[2,4.9,2]],"ltp":4.5,"tv":502.58,"id":12925630}]}]}
{"op":"mcm","clk":"991061354","pt":1580545562064,"mc":[{"id":"1.168136214","rc":[{"trd":[[2.06,105.82]],"batl":[[0,2.08,32.75],[1,2.16,15.14],[2,2.18,15.14]],"ltp":2.06,"tv":2461.21,"id":17336468}],"tv":3727.64}]}
{"op":"mcm","clk":"991061678","pt":1580545567090,"mc":[{"id":"1.168136214","rc":[{"batb":[[0,4.4,2.36],[1,4.3,2.03],[2,4.2,2]],"batl":[[0,4.6,2.33],[1,4.7,4.94],[2,4.8,2.1]],"ltp":4.5,"tv":502.58,"id":12925630},{"batl":[[0,2.06,4.17],[1,2.08,32.58],[2,2.16,15.14]],"ltp":2.06,"tv":2461.21,"id":17336468}]}]}
{"op":"mcm","clk":"991061742","pt":1580545568079,"mc":[{"id":"1.168136214","rc":[{"batl":[[0,4.6,4.33]],"ltp":4.5,"tv":502.58,"id":12925630}]}]}
{"op":"mcm","clk":"991061971","pt":1580545571090,"mc":[{"id":"1.168136214","rc":[{"batl":[[0,4.6,6.09]],"ltp":4.5,"tv":502.58,"id":12925630}]}]}
{"op":"mcm","clk":"991062173","pt":1580545574516,"mc":[{"id":"1.168136214","rc":[{"batl":[[0,4.5,1.76],[1,4.6,6.09],[2,4.7,4.94]],"ltp":4.5,"tv":502.58,"id":12925630}]}]}
{"op":"mcm","clk":"991062497","pt":1580545580590,"mc":[{"id":"1.168136214","rc":[{"trd":[[4.4,9.54]],"batb":[[0,4.3,2.63],[1,4.2,2],[2,4.1,2.2]],"batl":[[0,4.5,3.76]],"ltp":4.4,"tv":506.09,"id":12925630}],"tv":3731.15}]}
{"op":"mcm","clk":"991063236","pt":1580545594115,"mc":[{"id":"1.168136214","rc":[{"batb":[[0,4.3,2.03]],"ltp":4.4,"tv":506.09,"id":12925630},{"batb":[[0,1.97,8.12],[1,1.96,6],[2,1.95,28.6]],"ltp":2.06,"tv":2461.21,"id":17336468}]}]}
{"op":"mcm","clk":"991063282","pt":1580545595100,"mc":[{"id":"1.168136214","rc":[{"trd":[[4.5,53.15]],"batb":[[0,4.1,2.2],[1,4,20.91],[2,3.9,6]],"batl":[[0,4.6,6.09],[1,4.7,4.94],[2,4.8,2.1]],"ltp":4.5,"tv":509.61,"id":12925630},{"batb":[[0,1.97,4.12]],"ltp":2.06,"tv":2461.21,"id":17336468}],"tv":3734.67}]}
{"op":"mcm","clk":"991063363","pt":1580545597011,"mc":[{"id":"1.168136214","rc":[{"batb":[[0,4.1,6.08]],"ltp":4.5,"tv":509.61,"id":12925630}]}]}
{"op":"mcm","clk":"991063391","pt":1580545598043,"mc":[{"id":"1.168136214","rc":[{"batb":[[0,1.97,8.12]],"ltp":2.06,"tv":2461.21,"id":17336468}]}]}
{"op":"mcm","clk":"991063890","pt":1580545607135,"mc":[{"id":"1.168136214","rc":[{"batb":[[2,3.7,3.39]],"ltp":4.5,"tv":509.61,"id":12925630}]}]}
{"op":"mcm","clk":"991064607","pt":1580545621133,"mc":[{"id":"1.168136214","rc":[{"batl":[[0,2.06,2.17]],"ltp":2.06,"tv":2461.21,"id":17336468}]}]}
{"op":"mcm","clk":"991064708","pt":1580545622954,"mc":[{"id":"1.168136214","rc":[{"batb":[[1,1.96,3]],"ltp":2.06,"tv":2461.21,"id":17336468}]}]}
{"op":"mcm","clk":"991068428","pt":1580545696788,"mc":[{"id":"1.168136214","rc":[{"batb":[[0,1.97,4.12]],"batl":[[0,2,23.2],[1,2.08,30.58]],"ltp":2.06,"tv":2461.21,"id":17336468},{"batl":[[0,3.8,2.44]],"ltp":3.5,"tv":763.84,"id":11981493}]}]}
{"op":"mcm","clk":"991068877","pt":1580545706889,"mc":[{"id":"1.168136214","rc":[{"batl":[[1,2.06,11.09],[2,2.08,44.34]],"ltp":2.06,"tv":2461.21,"id":17336468},{"batl":[[0,3.9,4.82],[1,3.95,3.83],[2,4,3.79]],"ltp":3.5,"tv":763.84,"id":11981493}]}]}
{"op":"mcm","clk":"991069775","pt":1580545728052,"mc":[{"id":"1.168136214","rc":[{"batl":[[0,3.85,2],[1,3.9,4.82],[2,3.95,3.83]],"ltp":3.5,"tv":763.84,"id":11981493}]}]}
{"op":"mcm","clk":"991069842","pt":1580545728731,"mc":[{"id":"1.168136214","rc":[{"batl":[[0,3.85,5.26]],"ltp":3.5,"tv":763.84,"id":11981493}]}]}
{"op":"mcm","clk":"991070644","pt":1580545736821,"mc":[{"id":"1.168136214","rc":[{"batl":[[1,2.06,25.29]],"ltp":2.06,"tv":2461.21,"id":17336468}]}]}
{"op":"mcm","clk":"991070778","pt":1580545739052,"mc":[{"id":"1.168136214","rc":[{"batl":[[1,3.9,3.14]],"ltp":3.5,"tv":763.84,"id":11981493}]}]}
{"op":"mcm","clk":"991070826","pt":1580545740031,"mc":[{"id":"1.168136214","rc":[{"batl":[[0,3.8,2.44],[1,3.85,5.26],[2,3.9,3.14]],"ltp":3.5,"tv":763.84,"id":11981493}]}]}
{"op":"mcm","clk":"991071566","pt":1580545754675,"mc":[{"id":"1.168136214","rc":[{"trd":[[1.97,53.58]],"batb":[[0,1.95,28.6],[1,1.94,36.5],[2,1.93,60]],"batl":[[0,1.97,17.08],[1,2,23.2],[2,2.06,25.29]],"ltp":1.97,"tv":2469.45,"id":17336468}],"tv":3742.9}]}
{"op":"mcm","clk":"991071623","pt":1580545756065,"mc":[{"id":"1.168136214","rc":[{"batl":[[0,2,23.2],[1,2.06,25.29],[2,2.08,30.58]],"ltp":1.97,"tv":2469.45,"id":17336468}]}]}
{"op":"mcm","clk":"991071674","pt":1580545757154,"mc":[{"id":"1.168136214","rc":[{"batb":[[0,1.96,4.09],[1,1.95,28.6],[2,1.94,36.5]],"batl":[[1,2.06,33.29]],"ltp":1.97,"tv":2469.45,"id":17336468}]}]}
{"op":"mcm","clk":"991072988","pt":1580545783094,"mc":[{"id":"1.168136214","rc":[{"batl":[[1,3.85,3.26]],"ltp":3.5,"tv":763.84,"id":11981493}]}]}
{"op":"mcm","clk":"991074833","pt":1580545828893,"mc":[{"id":"1.168136214","rc":[{"batb":[[0,4.1,2.2]],"ltp":4.5,"tv":509.61,"id":12925630}]}]}
{"op":"mcm","clk":"991075125","pt":1580545836072,"mc":[{"id":"1.168136214","rc":[{"batb":[[0,4.2,6.05],[1,4.1,22.2],[2,4,20.91]],"batl":[[1,4.7,2]],"ltp":4.5,"tv":509.61,"id":12925630}]}]}
{"op":"mcm","clk":"991075182","pt":1580545837009,"mc":[{"id":"1.168136214","rc":[{"batb":[[0,4.3,2.19],[1,4.2,6.05],[2,4.1,22.2]],"ltp":4.5,"tv":509.61,"id":12925630},{"batl":[[0,3.8,5.44]],"ltp":3.5,"tv":763.84,"id":11981493}]}]}
{"op":"mcm","clk":"991075321","pt":1580545839978,"mc":[{"id":"1.168136214","rc":[{"batb":[[2,4.1,2.2]],"ltp":4.5,"tv":509.61,"id":12925630}]}]}
{"op":"mcm","clk":"991075404","pt":1580545841994,"mc":[{"id":"1.168136214","rc":[{"batb":[[0,1.95,28.6],[1,1.94,36.5],[2,1.93,60]],"batl":[[0,1.99,2.23],[1,2,23.2],[2,2.06,33.29]],"ltp":1.97,"tv":2469.45,"id":17336468}]}]}
{"op":"mcm","clk":"991076275","pt":1580545859928,"mc":[{"id":"1.168136214","rc":[{"batb":[[0,1.96,4.32],[1,1.95,28.6],[2,1.94,36.5]],"batl":[[0,1.99,21.2],[1,2.04,2.32],[2,2.06,10.82]],"ltp":1.97,"tv":2469.45,"id":17336468}]}]}
{"op":"mcm","clk":"991076320","pt":1580545861322,"mc":[{"id":"1.168136214","rc":[{"batl":[[0,2.04,2.32],[1,2.06,10.82],[2,2.08,30.58]],"ltp":1.97,"tv":2469.45,"id":17336468}]}]}
{"op":"mcm","clk":"991076391","pt":1580545863032,"mc":[{"id":"1.168136214","rc":[{"batl":[[0,1.99,21.2],[1,2,2.01],[2,2.04,2.32]],"ltp":1.97,"tv":2469.45,"id":17336468}]}]}
{"op":"mcm","clk":"991076657","pt":1580545870112,"mc":[{"id":"1.168136214","rc":[{"batl":[[0,4.5,2.02],[1,4.6,6.09],[2,4.7,2]],"ltp":4.5,"tv":509.61,"id":12925630}]}]}
{"op":"mcm","clk":"991077642","pt":1580545890054,"mc":[{"id":"1.168136214","rc":[{"batl":[[0,4.4,2.33],[1,4.5,2.02],[2,4.6,3.76]],"ltp":4.5,"tv":509.61,"id":12925630},{"batb":[[0,1.95,28.6],[1,1.94,36.5],[2,1.93,60]],"batl":[[0,1.99,23.2],[2,2.06,10.82]],"ltp":1.97,"tv":2469.45,"id":17336468}]}]}
{"op":"mcm","clk":"991077653","pt":1580545890358,"mc":[{"id":"1.168136214","rc":[{"batl":[[1,4.5,4.02]],"ltp":4.5,"tv":509.61,"id":12925630},{"batb":[[0,1.96,4.16],[1,1.95,28.6],[2,1.94,36.5]],"batl":[[0,1.99,21.2],[2,2.06,24.8]],"ltp":1.97,"tv":2469.45,"id":17336468},{"batl":[[0,3.8,2.44]],"ltp":3.5,"tv":763.84,"id":11981493}]}]}
{"op":"mcm","clk":"991077734","pt":1580545892372,"mc":[{"id":"1.168136214","rc":[{"batb":[[0,4.3,13.97],[1,4.2,8.05]],"ltp":4.5,"tv":509.61,"id":12925630},{"batb":[[0,1.96,30]],"ltp":1.97,"tv":2469.45,"id":17336468},{"batb":[[0,3.6,16.3]],"ltp":3.5,"tv":763.84,"id":11981493}]}]}
{"op":"mcm","clk":"991078284","pt":1580545903064,"mc":[{"id":"1.168136214","rc":[{"batl":[[1,4.5,2]],"ltp":4.5,"tv":509.61,"id":12925630}]}]}
{"op":"mcm","clk":"991080480","pt":1580545950146,"mc":[{"id":"1.168136214","rc":[{"trd":[[3.8,4.89]],"batb":[[0,3.6,16.38]],"batl":[[0,3.85,3.26],[1,3.9,3.14],[2,3.95,3.83]],"ltp":3.8,"tv":768.73,"id":11981493}],"tv":3747.79}]}
{"op":"mcm","clk":"991080504","pt":1580545950563,"mc":[{"id":"1.168136214","rc":[{"batl":[[0,1.99,23.2]],"ltp":1.97,"tv":2469.45,"id":17336468},{"trd":[[3.8,5.05]],"batb":[[0,3.6,16.3],[1,3.55,2]],"batl":[[0,3.8,2.42]],"ltp":3.8,"tv":768.88,"id":11981493}],"tv":3747.95}]}
{"op":"mcm","clk":"991090979","pt":1580545970903,"mc":[{"id":"1.168136214","rc":[{"batl":[[1,3.85,3.16],[2,3.9,3.14]],"ltp":3.8,"tv":768.88,"id":11981493}]}]}
{"op":"mcm","clk":"991092670","pt":1580546010111,"mc":[{"id":"1.168136214","rc":[{"batb":[[2,3.5,11.28]],"ltp":3.8,"tv":768.88,"id":11981493}]}]}
{"op":"mcm","clk":"991096538","pt":1580546103467,"mc":[{"id":"1.168136214","rc":[{"batb":[[0,4.3,25.75]],"ltp":4.5,"tv":509.61,"id":12925630},{"trd":[[1.96,79.38]],"batb":[[0,1.96,52.03]],"ltp":1.96,"tv":2483.08,"id":17336468},{"batb":[[0,3.6,30.37]],"ltp":3.8,"tv":768.88,"id":11981493}],"tv":3761.58}]}
{"op":"mcm","clk":"991096591","pt":1580546104704,"mc":[{"id":"1.168136214","rc":[{"trd":[[1.96,93]],"batb":[[0,1.96,45.22]],"ltp":1.96,"tv":2496.7,"id":17336468}],"tv":3775.2}]}
{"op":"mcm","clk":"991096966","pt":1580546112817,"mc":[{"id":"1.168136214","rc":[{"batl":[[2,2.04,20.45]],"ltp":1.96,"tv":2496.7,"id":17336468}]}]}
{"op":"mcm","clk":"991097110","pt":1580546117093,"mc":[{"id":"1.168136214","rc":[{"batb":[[1,1.95,3]],"ltp":1.96,"tv":2496.7,"id":17336468}]}]}
{"op":"mcm","clk":"991097131","pt":1580546117971,"mc":[{"id":"1.168136214","rc":[{"trd":[[1.96,106.63]],"batb":[[0,1.96,38.42]],"ltp":1.96,"tv":2510.32,"id":17336468}],"tv":3788.82}]}
{"op":"mcm","clk":"991098946","pt":1580546156834,"mc":[{"id":"1.168136214","rc":[{"trd":[[1.96,134.15]],"batb":[[0,1.96,24.66]],"ltp":1.96,"tv":2537.85,"id":17336468}],"tv":3816.35}]}
{"op":"mcm","clk":"991104475","pt":1580546270024,"mc":[{"id":"1.168136214","rc":[{"trd":[[1.96,138.15]],"batb":[[0,1.96,22.66]],"batl":[[2,2.02,10]],"ltp":1.96,"tv":2541.84,"id":17336468}],"tv":3820.35}]}
{"op":"mcm","clk":"991108806","pt":1580546357039,"mc":[{"id":"1.168136214","rc":[{"batb":[[0,1.96,19.66]],"batl":[[0,1.97,10],[1,1.99,23.2],[2,2,2.01]],"ltp":1.96,"tv":2541.84,"id":17336468}]}]}
{"op":"mcm","clk":"991112897","pt":1580546431054,"mc":[{"id":"1.168136214","rc":[{"trd":[[4.3,51.52]],"batb":[[0,4.3,13.79],[2,4.1,5.71]],"ltp":4.3,"tv":561.14,"id":12925630},{"batb":[[0,1.96,49.5]],"batl":[[1,1.98,2.09],[2,1.99,23.2]],"ltp":1.96,"tv":2541.84,"id":17336468},{"batb":[[0,3.6,44.44]],"ltp":3.8,"tv":768.88,"id":11981493}],"tv":3871.87}]}
{"op":"mcm","clk":"991112937","pt":1580546432155,"mc":[{"id":"1.168136214","rc":[{"batb":[[2,4.1,2.2]],"ltp":4.3,"tv":561.14,"id":12925630}]}]}
{"op":"mcm","clk":"991113350","pt":1580546441102,"mc":[{"id":"1.168136214","rc":[{"trd":[[1.97,73.58]],"batl":[[0,1.99,23.2],[1,2,2.01],[2,2.02,10]],"ltp":1.97,"tv":2561.84,"id":17336468},{"batb":[[0,3.65,3],[1,3.6,44.44],[2,3.55,2]],"ltp":3.8,"tv":768.88,"id":11981493}],"tv":3891.87}]}
{"op":"mcm","clk":"991114336","pt":1580546460981,"mc":[{"id":"1.168136214","rc":[{"batb":[[0,3.7,4.51],[1,3.65,3],[2,3.6,44.44]],"ltp":3.8,"tv":768.88,"id":11981493}]}]}
{"op":"mcm","clk":"991120117","pt":1580546559125,"mc":[{"id":"1.168136214","rc":[{"batl":[[0,3.8,5.42]],"ltp":3.8,"tv":768.88,"id":11981493}]}]}
{"op":"mcm","clk":"991120231","pt":1580546561114,"mc":[{"id":"1.168136214","rc":[{"batb":[[0,1.97,4.22],[1,1.96,49.5],[2,1.95,3]],"ltp":1.97,"tv":2561.84,"id":17336468}]}]}
{"op":"mcm","clk":"991126810","pt":1580546681931,"mc":[{"id":"1.168136214","rc":[{"trd":[[1.97,82.01]],"batb":[[0,1.97,3.22]],"ltp":1.97,"tv":2570.28,"id":17336468}],"tv":3900.31}]}
{"op":"mcm","clk":"991132092","pt":1580546767131,"mc":[{"id":"1.168136214","rc":[{"trd":[[1.97,89.59]],"batb":[[0,1.97,1.46]],"ltp":1.97,"tv":2577.86,"id":17336468}],"tv":3907.88}]}
{"op":"mcm","clk":"991132149","pt":1580546767710,"mc":[{"id":"1.168136214","rc":[{"batb":[[1,1.96,47.5]],"ltp":1.97,"tv":2577.86,"id":17336468}]}]}
{"op":"mcm","clk":"991132362","pt":1580546771635,"mc":[{"id":"1.168136214","rc":[{"trd":[[1.97,92.51]],"batb":[[0,1.96,47.5],[1,1.95,3],[2,1.94,86.19]],"batl":[[0,1.97,2.32],[1,1.99,23.2],[2,2,2.01]],"ltp":1.97,"tv":2580.78,"id":17336468}],"tv":3910.81}]}
{"op":"mcm","clk":"991132401","pt":1580546772412,"mc":[{"id":"1.168136214","rc":[{"batl":[[0,1.99,23.2],[1,2,2.01],[2,2.02,10]],"ltp":1.97,"tv":2580.78,"id":17336468}]}]}
{"op":"mcm","clk":"991133486","pt":1580546792060,"mc":[{"id":"1.168136214","rc":[{"batb":[[0,1.97,2.06],[1,1.96,47.5],[2,1.95,3]],"ltp":1.97,"tv":2580.78,"id":17336468}]}]}
{"op":"mcm","clk":"991136480","pt":1580546832009,"mc":[{"id":"1.168136214","rc":[{"trd":[[4.4,14.2]],"batb":[[0,4.4,7.67],[1,4.3,13.79],[2,4.2,8.05]],"batl":[[0,4.5,2],[1,4.6,3.76],[2,4.7,2]],"ltp":4.4,"tv":565.8,"id":12925630}],"tv":3915.47}]}
{"op":"mcm","clk":"991136556","pt":1580546833100,"mc":[{"id":"1.168136214","rc":[{"trd":[[4.4,22.2]],"batb":[[0,4.4,5.67]],"batl":[[0,4.6,3.76],[1,4.7,2],[2,4.8,2.1]],"ltp":4.4,"tv":573.8,"id":12925630},{"batb":[[0,1.96,47.5],[1,1.95,3],[2,1.94,86.19]],"ltp":1.97,"tv":2580.78,"id":17336468},{"batb":[[1,3.65,5]],"ltp":3.8,"tv":768.88,"id":11981493}],"tv":3923.47}]}
{"op":"mcm","clk":"991136910","pt":1580546837934,"mc":[{"id":"1.168136214","rc":[{"batb":[[0,4.4,35.67]],"ltp":4.4,"tv":573.8,"id":12925630},{"batl":[[0,1.98,2.09],[1,1.99,23.2],[2,2,2.01]],"ltp":1.97,"tv":2580.78,"id":17336468},{"batb":[[0,3.7,2.51]],"ltp":3.8,"tv":768.88,"id":11981493}]}]}
{"op":"mcm","clk":"991137929","pt":1580546851834,"mc":[{"id":"1.168136214","rc":[{"batl":[[0,4.6,6.76]],"ltp":4.4,"tv":573.8,"id":12925630}]}]}
{"op":"mcm","clk":"991151244","pt":1580546911027,"mc":[{"id":"1.168136214","rc":[{"trd":[[3.8,15.88]],"batl":[[0,3.8,2]],"ltp":3.8,"tv":779.72,"id":11981493}],"tv":3934.3}]}
{"op":"mcm","clk":"991151295","pt":1580546912056,"mc":[{"id":"1.168136214","rc":[{"batb":[[0,3.7,4.51]],"batl":[[0,3.9,3.14],[1,3.95,3.83],[2,4,3.79]],"ltp":3.8,"tv":779.72,"id":11981493}]}]}
{"op":"mcm","clk":"991152461","pt":1580546928148,"mc":[{"id":"1.168136214","rc":[{"batb":[[0,1.96,45.5]],"ltp":1.97,"tv":2580.78,"id":17336468},{"batb":[[1,3.65,2]],"ltp":3.8,"tv":779.72,"id":11981493}]}]}
{"op":"mcm","clk":"991152546","pt":1580546929078,"mc":[{"id":"1.168136214","rc":[{"trd":[[4.4,26.2]],"batb":[[0,4.4,33.67]],"ltp":4.4,"tv":577.8,"id":12925630}],"tv":3938.3}]}
{"op":"mcm","clk":"991159067","pt":1580547020001,"mc":[{"id":"1.168136214","rc":[{"batb":[[0,4.4,31.67]],"ltp":4.4,"tv":577.8,"id":12925630},{"batb":[[2,3.6,59.44]],"ltp":3.8,"tv":779.72,"id":11981493}]}]}
{"op":"mcm","clk":"991160724","pt":1580547039050,"mc":[{"id":"1.168136214","rc":[{"batb":[[1,3.65,5]],"ltp":3.8,"tv":779.72,"id":11981493}]}]}
{"op":"mcm","clk":"991161781","pt":1580547052064,"mc":[{"id":"1.168136214","rc":[{"trd":[[1.96,148.14]],"batb":[[0,1.96,40.51]],"ltp":1.96,"tv":2590.77,"id":17336468}],"tv":3948.3}]}
{"op":"mcm","clk":"991162187","pt":1580547058106,"mc":[{"id":"1.168136214","rc":[{"batb":[[1,3.65,15]],"ltp":3.8,"tv":779.72,"id":11981493}]}]}
{"op":"mcm","clk":"991163018","pt":1580547070079,"mc":[{"id":"1.168136214","rc":[{"batl":[[0,4.6,8.94]],"ltp":4.4,"tv":577.8,"id":12925630}]}]}
{"op":"mcm","clk":"991163237","pt":1580547072924,"mc":[{"id":"1.168136214","rc":[{"batl":[[0,4.5,2.07],[1,4.6,8.94],[2,4.7,2]],"ltp":4.4,"tv":577.8,"id":12925630},{"batb":[[0,3.7,14.51]],"ltp":3.8,"tv":779.72,"id":11981493}]}]}
{"op":"mcm","clk":"991163882","pt":1580547081908,"mc":[{"id":"1.168136214","rc":[{"batl":[[0,4.6,8.94],[1,4.7,2],[2,4.8,2.1]],"ltp":4.4,"tv":577.8,"id":12925630},{"trd":[[3.7,76.04]],"batb":[[0,3.7,6.51]],"ltp":3.7,"tv":799.72,"id":11981493}],"tv":3968.3}]}
{"op":"mcm","clk":"991164108","pt":1580547085023,"mc":[{"id":"1.168136214","rc":[{"trd":[[4.4,32.2]],"batb":[[0,4.4,28.67]],"batl":[[0,4.6,5.94]],"ltp":4.4,"tv":583.8,"id":12925630}],"tv":3974.3}]}
{"op":"mcm","clk":"991164165","pt":1580547085799,"mc":[{"id":"1.168136214","rc":[{"batb":[[0,4.4,30.67]],"ltp":4.4,"tv":583.8,"id":12925630},{"batb":[[0,3.75,3],[1,3.7,6.51],[2,3.65,12]],"ltp":3.7,"tv":799.72,"id":11981493}]}]}
{"op":"mcm","clk":"991164749","pt":1580547094715,"mc":[{"id":"1.168136214","rc":[{"batl":[[0,4.6,8.94]],"ltp":4.4,"tv":583.8,"id":12925630}]}]}
{"op":"mcm","clk":"991165083","pt":1580547099444,"mc":[{"id":"1.168136214","rc":[{"batb":[[0,4.4,28.67]],"ltp":4.4,"tv":583.8,"id":12925630},{"batl":[[0,3.9,5.14]],"ltp":3.7,"tv":799.72,"id":11981493}]}]}
{"op":"mcm","clk":"991175472","pt":1580547249113,"mc":[{"id":"1.168136214","rc":[{"batl":[[1,1.99,2]],"ltp":1.96,"tv":2590.77,"id":17336468}]}]}
{"op":"mcm","clk":"991175526","pt":1580547249732,"mc":[{"id":"1.168136214","rc":[{"batl":[[0,4.5,2.05],[1,4.6,8.94],[2,4.7,2]],"ltp":4.4,"tv":583.8,"id":12925630},{"batb":[[0,1.96,42.51]],"batl":[[0,2,2.01],[1,2.02,10],[2,2.04,20.45]],"ltp":1.96,"tv":2590.77,"id":17336468}]}]}
{"op":"mcm","clk":"991175587","pt":1580547250614,"mc":[{"id":"1.168136214","rc":[{"trd":[[1.96,159.14]],"batb":[[0,1.96,37.01]],"ltp":1.96,"tv":2601.77,"id":17336468}],"tv":3985.3}]}
{"op":"mcm","clk":"991175935","pt":1580547255136,"mc":[{"id":"1.168136214","rc":[{"batl":[[0,1.99,17.9],[1,2,2.01],[2,2.02,10]],"ltp":1.96,"tv":2601.77,"id":17336468}]}]}
{"op":"mcm","clk":"991175980","pt":1580547255611,"mc":[{"id":"1.168136214","rc":[{"batl":[[0,4.6,8.94],[1,4.7,2],[2,4.8,2.1]],"ltp":4.4,"tv":583.8,"id":12925630},{"batb":[[0,1.96,35.01]],"ltp":1.96,"tv":2601.77,"id":17336468}]}]}
{"op":"mcm","clk":"991176352","pt":1580547260511,"mc":[{"id":"1.168136214","rc":[{"trd":[[1.96,223.11]],"batb":[[0,1.96,3.04]],"ltp":1.96,"tv":2665.74,"id":17336468}],"tv":4049.27}]}
{"op":"mcm","clk":"991176606","pt":1580547263945,"mc":[{"id":"1.168136214","rc":[{"trd":[[4.4,39.46]],"batb":[[0,4.4,25.04]],"ltp":4.4,"tv":591.06,"id":12925630}],"tv":4056.53}]}
{"op":"mcm","clk":"991177073","pt":1580547270542,"mc":[{"id":"1.168136214","rc":[{"batl":[[0,4.5,2.16],[1,4.6,8.94],[2,4.7,2]],"ltp":4.4,"tv":591.06,"id":12925630},{"trd":[[1.99,268.23],[2,997.43],[2.02,256.21]],"batb":[[0,1.96,6.04]],"batl":[[0,2.02,3.07],[1,2.04,20.45],[2,2.06,25.44]],"ltp":2.02,"tv":2723.74,"id":17336468}],"tv":4114.53}]}
{"op":"mcm","clk":"991177179","pt":1580547272040,"mc":[{"id":"1.168136214","rc":[{"batl":[[2,2.06,8]],"ltp":2.02,"tv":2723.74,"id":17336468}]}]}
{"op":"mcm","clk":"991177531","pt":1580547276139,"mc":[{"id":"1.168136214","rc":[{"batl":[[0,2,2.15],[1,2.02,3.07],[2,2.04,20.45]],"ltp":2.02,"tv":2723.74,"id":17336468}]}]}
{"op":"mcm","clk":"991177600","pt":1580547276965,"mc":[{"id":"1.168136214","rc":[{"batl":[[0,1.99,2.19],[1,2,2.15],[2,2.02,3.07]],"ltp":2.02,"tv":2723.74,"id":17336468}]}]}
{"op":"mcm","clk":"991177950","pt":1580547281057,"mc":[{"id":"1.168136214","rc":[{"trd":[[4.4,45.46]],"batb":[[0,4.4,22.04]],"batl":[[1,4.6,5.94]],"ltp":4.4,"tv":597.06,"id":12925630},{"batl":[[0,2,4.15],[1,2.02,3.07],[2,2.06,8]],"ltp":2.02,"tv":2723.74,"id":17336468}],"tv":4120.53}]}
{"op":"mcm","clk":"991178256","pt":1580547285111,"mc":[{"id":"1.168136214","rc":[{"batl":[[0,4.6,5.94],[1,4.7,2],[2,4.8,2.1]],"ltp":4.4,"tv":597.06,"id":12925630},{"batl":[[0,1.99,2.24],[1,2,20.05],[2,2.02,3.07]],"ltp":2.02,"tv":2723.74,"id":17336468}]}]}
{"op":"mcm","clk":"991178360","pt":1580547286774,"mc":[{"id":"1.168136214","rc":[{"batl":[[0,1.99,15.9],[1,2,4.15]],"ltp":2.02,"tv":2723.74,"id":17336468}]}]}
{"op":"mcm","clk":"991179218","pt":1580547300013,"mc":[{"id":"1.168136214","rc":[{"batl":[[0,4.5,2.32],[1,4.6,7.94],[2,4.7,2]],"ltp":4.4,"tv":597.06,"id":12925630},{"batl":[[0,1.99,17.9]],"ltp":2.02,"tv":2723.74,"id":17336468}]}]}
{"op":"mcm","clk":"991179697","pt":1580547308124,"mc":[{"id":"1.168136214","rc":[{"batl":[[1,2,2]],"ltp":2.02,"tv":2723.74,"id":17336468}]}]}
{"op":"mcm","clk":"991182189","pt":1580547349062,"mc":[{"id":"1.168136214","rc":[{"batl":[[1,4.6,5.94]],"ltp":4.4,"tv":597.06,"id":12925630}]}]}
{"op":"mcm","clk":"991182228","pt":1580547349888,"mc":[{"id":"1.168136214","rc":[{"trd":[[4.4,49.46]],"batb":[[0,4.4,20.04]],"ltp":4.4,"tv":601.06,"id":12925630}],"tv":4124.53}]}
{"op":"mcm","clk":"991182380","pt":1580547352068,"mc":[{"id":"1.168136214","rc":[{"batl":[[0,4.6,5.94],[1,4.7,2],[2,4.8,2.1]],"ltp":4.4,"tv":601.06,"id":12925630}]}]}
{"op":"mcm","clk":"991183333","pt":1580547368072,"mc":[{"id":"1.168136214","rc":[{"batl":[[0,4.6,7.94]],"ltp":4.4,"tv":601.06,"id":12925630}]}]}
{"op":"mcm","clk":"991183388","pt":1580547369005,"mc":[{"id":"1.168136214","rc":[{"batl":[[0,4.5,2.04],[1,4.6,7.94],[2,4.7,2]],"ltp":4.4,"tv":601.06,"id":12925630}]}]}
{"op":"mcm","clk":"991184696","pt":1580547391151,"mc":[{"id":"1.168136214","rc":[{"trd":[[4.4,89.54]],"batb":[[0,4.3,13.79],[1,4.2,8.05],[2,4.1,2.2]],"ltp":4.4,"tv":641.13,"id":12925630}],"tv":4164.61}]}
{"op":"mcm","clk":"991185134","pt":1580547398144,"mc":[{"id":"1.168136214","rc":[{"batl":[[1,4.6,5.94]],"ltp":4.4,"tv":641.13,"id":12925630}]}]}
{"op":"mcm","clk":"991185201","pt":1580547399136,"mc":[{"id":"1.168136214","rc":[{"batl":[[0,4.4,2],[1,4.5,2.04],[2,4.6,5.94]],"ltp":4.4,"tv":641.13,"id":12925630}]}]}
{"op":"mcm","clk":"991189282","pt":1580547465957,"mc":[{"id":"1.168136214","rc":[{"trd":[[4.4,93.54],[4.5,61.23]],"batb":[[0,4.5,11.96],[1,4.4,2.25],[2,4.3,13.79]],"batl":[[0,4.6,5.94],[1,4.7,2],[2,4.8,2.1]],"ltp":4.5,"tv":653.21,"id":12925630},{"batb":[[0,1.96,3.04]],"batl":[[0,1.98,2.25],[1,1.99,17.9],[2,2,2]],"ltp":2.02,"tv":2723.74,"id":17336468},{"batb":[[1,3.7,4.51]],"ltp":3.7,"tv":799.72,"id":11981493}],"tv":4176.69}]}
{"op":"mcm","clk":"991189391","pt":1580547468081,"mc":[{"id":"1.168136214","rc":[{"batb":[[0,3.7,4.51],[1,3.65,12],[2,3.6,59.44]],"ltp":3.7,"tv":799.72,"id":11981493}]}]}
{"op":"mcm","clk":"991189440","pt":1580547468973,"mc":[{"id":"1.168136214","rc":[{"batl":[[1,5,5],[2,5.1,49]],"ltp":4.5,"tv":653.21,"id":12925630},{"batb":[[0,3.7,7.51]],"ltp":3.7,"tv":799.72,"id":11981493}]}]}
{"op":"mcm","clk":"991189556","pt":1580547471091,"mc":[{"id":"1.168136214","rc":[{"trd":[[1.98,340.84]],"batb":[[0,1.98,10.75],[1,1.96,3.04],[2,1.95,3]],"batl":[[0,1.99,17.9],[1,2,2],[2,2.06,8.91]],"ltp":1.98,"tv":2768.24,"id":17336468}],"tv":4221.19}]}
{"op":"mcm","clk":"991189607","pt":1580547472076,"mc":[{"id":"1.168136214","rc":[{"trd":[[1.98,362.34]],"batb":[[0,1.96,3.04],[1,1.95,3],[2,1.94,88.19]],"batl":[[0,1.98,4.34],[1,1.99,17.9],[2,2,2]],"ltp":1.98,"tv":2789.74,"id":17336468}],"tv":4242.69}]}
{"op":"mcm","clk":"991189677","pt":1580547472966,"mc":[{"id":"1.168136214","rc":[{"batl":[[0,4.6,3.76],[1,4.9,2.74],[2,5,5]],"ltp":4.5,"tv":653.21,"id":12925630}]}]}
{"op":"mcm","clk":"991189781","pt":1580547474103,"mc":[{"id":"1.168136214","rc":[{"trd":[[1.96,229.2]],"batb":[[0,1.95,3],[1,1.94,88.19],[2,1.93,60]],"batl":[[0,1.96,46.95],[1,1.98,4.34],[2,1.99,17.9]],"ltp":1.96,"tv":2795.84,"id":17336468}],"tv":4248.78}]}
{"op":"mcm","clk":"991189862","pt":1580547475092,"mc":[{"id":"1.168136214","rc":[{"batb":[[0,1.95,10.85],[1,1.94,86.19],[2,1.93,62]],"batl":[[0,1.96,48.95],[1,1.98,2],[2,1.99,15.9]],"ltp":1.96,"tv":2795.84,"id":17336468},{"batb":[[0,3.7,9.51]],"ltp":3.7,"tv":799.72,"id":11981493}]}]}
{"op":"mcm","clk":"991190034","pt":1580547478109,"mc":[{"id":"1.168136214","marketDefinition":{"bspMarket":true,"turnInPlayEnabled":true,"persistenceEnabled":true,"marketBaseRate":5.0,"eventId":"29678828","eventTypeId":"7","numberOfWinners":1,"bettingType":"ODDS","marketType":"WIN","marketTime":"2020-02-01T12:57:00.000Z","suspendTime":"2020-02-01T12:57:00.000Z","bspReconciled":false,"complete":true,"inPlay":false,"crossMatching":true,"runnersVoidable":false,"numberOfActiveRunners":3,"betDelay":0,"status":"OPEN","runners":[{"adjustmentFactor":46.07,"status":"ACTIVE","sortPriority":1,"id":17336468,"name":"Southfield Stone"},{"adjustmentFactor":34.34,"status":"ACTIVE","sortPriority":2,"id":11981493,"name":"Espoir De Teillee"},{"adjustmentFactor":19.58,"status":"ACTIVE","sortPriority":3,"id":12925630,"name":"Mahlervous"}],"regulators":["MR_INT"],"venue":"Musselburgh","countryCode":"GB","discountAllowed":true,"timezone":"Europe/London","openDate":"2020-02-01T12:57:00.000Z","version":3142913258,"name":"2m4f Nov Chs","eventName":"Muss  1st Feb"},"rc":[{"batl":[[1,4.8,2],[2,4.9,2.74]],"ltp":4.5,"tv":653.21,"id":12925630},{"batl":[[1,1.98,14.12]],"ltp":1.96,"tv":2795.84,"id":17336468}]}]}
{"op":"mcm","clk":"991190555","pt":1580547486091,"mc":[{"id":"1.168136214","rc":[{"trd":[[4.6,165.11]],"batl":[[0,4.7,2.03]],"ltp":4.6,"tv":656.73,"id":12925630},{"batl":[[1,1.97,2.03],[2,1.98,14.12]],"ltp":1.96,"tv":2795.84,"id":17336468}],"tv":4252.3}]}
{"op":"mcm","clk":"991190687","pt":1580547488105,"mc":[{"id":"1.168136214","rc":[{"batb":[[2,4.3,16.79]],"batl":[[0,4.6,2],[1,4.7,2.03]],"ltp":4.6,"tv":656.73,"id":12925630}]}]}
{"op":"mcm","clk":"991190739","pt":1580547488929,"mc":[{"id":"1.168136214","rc":[{"batl":[[1,4.8,2.04]],"ltp":4.6,"tv":656.73,"id":12925630}]}]}
{"op":"mcm","clk":"991190904","pt":1580547491110,"mc":[{"id":"1.168136214","rc":[{"batb":[[0,3.7,6.51]],"ltp":3.7,"tv":799.72,"id":11981493}]}]}
{"op":"mcm","clk":"991190914","pt":1580547491317,"mc":[{"id":"1.168136214","rc":[{"batl":[[1,4.7,2.06],[2,4.8,2.04]],"ltp":4.6,"tv":656.73,"id":12925630}]}]}
{"op":"mcm","clk":"991198140","pt":1580547607063,"mc":[{"id":"1.168136214","rc":[{"batl":[[0,4.6,4]],"ltp":4.6,"tv":656.73,"id":12925630},{"trd":[[1.95,71.67]],"batb":[[0,1.95,9.85],[1,1.94,88.19]],"ltp":1.95,"tv":2797.84,"id":17336468}],"tv":4254.3}]}
{"op":"mcm","clk":"991198250","pt":1580547608065,"mc":[{"id":"1.168136214","rc":[{"batl":[[0,4.6,2],[1,4.8,2.04],[2,4.9,2.74]],"ltp":4.6,"tv":656.73,"id":12925630},{"trd":[[1.95,73.67]],"batb":[[0,1.95,8.85]],"ltp":1.95,"tv":2799.84,"id":17336468},{"trd":[[3.7,79.04]],"batb":[[0,3.7,5.01]],"ltp":3.7,"tv":802.72,"id":11981493}],"tv":4259.3}]}
{"op":"mcm","clk":"991198328","pt":1580547608963,"mc":[{"id":"1.168136214","rc":[{"trd":[[1.95,74.67]],"batb":[[0,1.95,8.35]],"ltp":1.95,"tv":2800.84,"id":17336468},{"trd":[[3.7,80.04]],"batb":[[0,3.7,4.51]],"ltp":3.7,"tv":803.72,"id":11981493}],"tv":4261.3}]}
{"op":"mcm","clk":"991199882","pt":1580547629582,"mc":[{"id":"1.168136214","rc":[{"batl":[[0,4.6,4]],"ltp":4.6,"tv":656.73,"id":12925630}]}]}
{"op":"mcm","clk":"991203423","pt":1580547671648,"mc":[{"id":"1.168136214","rc":[{"trd":[[1.96,233.7]],"batl":[[0,1.96,46.7]],"ltp":1.96,"tv":2805.34,"id":17336468}],"tv":4265.8}]}
{"op":"mcm","clk":"991204506","pt":1580547686078,"mc":[{"id":"1.168136214","rc":[{"trd":[[4.6,173.11]],"batl":[[0,4.8,2.04],[1,4.9,2.74],[2,5,5]],"ltp":4.6,"tv":664.73,"id":12925630}],"tv":4273.8}]}
{"op":"mcm","clk":"991204579","pt":1580547687074,"mc":[{"id":"1.168136214","rc":[{"trd":[[4.6,177.11]],"ltp":4.6,"tv":668.73,"id":12925630}],"tv":4277.8}]}
{"op":"mcm","clk":"991205336","pt":1580547697070,"mc":[{"id":"1.168136214","rc":[{"batl":[[0,4.8,4.04]],"ltp":4.6,"tv":668.73,"id":12925630}]}]}
{"op":"mcm","clk":"991223765","pt":1580547819154,"mc":[{"id":"1.168136214","rc":[{"trd":[[1.95,91.37],[1.96,324.42]],"batb":[[0,1.94,86.19],[1,1.93,62],[2,1.92,6]],"batl":[[0,1.95,7.55],[1,1.96,2.21],[2,1.97,2.03]],"ltp":1.95,"tv":2912.76,"id":17336468}],"tv":4385.22}]}
{"op":"mcm","clk":"991223852","pt":1580547820095,"mc":[{"id":"1.168136214","rc":[{"batb":[[0,4.5,14.96]],"ltp":4.6,"tv":668.73,"id":12925630},{"batb":[[0,1.94,88.19]],"batl":[[0,1.97,2.03],[1,1.98,2],[2,1.99,15.9]],"ltp":1.95,"tv":2912.76,"id":17336468}]}]}
{"op":"mcm","clk":"991223923","pt":1580547820794,"mc":[{"id":"1.168136214","rc":[{"batb":[[0,4.5,11.96]],"ltp":4.6,"tv":668.73,"id":12925630},{"batb":[[0,1.94,86.19]],"batl":[[0,1.98,2],[1,1.99,15.9],[2,2,10]],"ltp":1.95,"tv":2912.76,"id":17336468}]}]}
{"op":"mcm","clk":"991224025","pt":1580547822095,"mc":[{"id":"1.168136214","rc":[{"batl":[[1,2,10],[2,2.06,134.56]],"ltp":1.95,"tv":2912.76,"id":17336468}]}]}
{"op":"mcm","clk":"991224037","pt":1580547822299,"mc":[{"id":"1.168136214","rc":[{"batb":[[0,4.5,14.96]],"ltp":4.6,"tv":668.73,"id":12925630},{"batb":[[1,1.93,60],[2,1.92,8]],"batl":[[0,1.99,2.23]],"ltp":1.95,"tv":2912.76,"id":17336468}]}]}
{"op":"mcm","clk":"991224180","pt":1580547824059,"mc":[{"id":"1.168136214","rc":[{"batl":[[0,1.97,2.24],[1,1.98,15.9],[2,1.99,2.23]],"ltp":1.95,"tv":2912.76,"id":17336468}]}]}
{"op":"mcm","clk":"991224342","pt":1580547826080,"mc":[{"id":"1.168136214","rc":[{"batb":[[0,4.5,11.96]],"ltp":4.6,"tv":668.73,"id":12925630},{"batb":[[0,1.94,88.19]],"ltp":1.95,"tv":2912.76,"id":17336468}]}]}
{"op":"mcm","clk":"991224374","pt":1580547826595,"mc":[{"id":"1.168136214","rc":[{"batb":[[0,1.94,86.19],[1,1.93,62]],"batl":[[0,1.97,15.9],[1,1.99,2.23],[2,2,10]],"ltp":1.95,"tv":2912.76,"id":17336468}]}]}
{"op":"mcm","clk":"991224540","pt":1580547828783,"mc":[{"id":"1.168136214","rc":[{"batb":[[0,1.94,75.59]],"batl":[[0,1.97,17.9]],"ltp":1.95,"tv":2912.76,"id":17336468}]}]}
{"op":"mcm","clk":"991225332","pt":1580547838990,"mc":[{"id":"1.168136214","rc":[{"batb":[[0,1.96,5],[1,1.94,77.59],[2,1.93,62]],"batl":[[1,1.98,2.32],[2,1.99,2.23]],"ltp":1.95,"tv":2912.76,"id":17336468}]}]}
{"op":"mcm","clk":"991225887","pt":1580547846711,"mc":[{"id":"1.168136214","rc":[{"batb":[[1,1.95,6],[2,1.94,77.59]],"ltp":1.95,"tv":2912.76,"id":17336468}]}]}
{"op":"mcm","clk":"991229478","pt":1580547895802,"mc":[{"id":"1.168136214","rc":[{"batl":[[2,1.99,10.23]],"ltp":1.95,"tv":2912.76,"id":17336468}]}]}
{"op":"mcm","clk":"991231693","pt":1580547929830,"mc":[{"id":"1.168136214","rc":[{"batl":[[1,4,3.79],[2,4.1,1.22]],"ltp":3.7,"tv":803.72,"id":11981493}]}]}
{"op":"mcm","clk":"991232507","pt":1580547942042,"mc":[{"id":"1.168136214","rc":[{"batl":[[0,4.8,2]],"ltp":4.6,"tv":668.73,"id":12925630}]}]}
{"op":"mcm","clk":"991235262","pt":1580547980130,"mc":[{"id":"1.168136214","rc":[{"trd":[[3.7,83.4]],"batb":[[0,3.7,2.83]],"ltp":3.7,"tv":807.08,"id":11981493}],"tv":4388.58}]}
{"op":"mcm","clk":"991235564","pt":1580547984130,"mc":[{"id":"1.168136214","rc":[{"trd":[[1.96,328.42]],"batb":[[0,1.96,3]],"ltp":1.96,"tv":2916.76,"id":17336468}],"tv":4392.58}]}
{"op":"mcm","clk":"991236223","pt":1580547993111,"mc":[{"id":"1.168136214","rc":[{"batl":[[0,1.97,2]],"ltp":1.96,"tv":2916.76,"id":17336468}]}]}
{"op":"mcm","clk":"991236238","pt":1580547993369,"mc":[{"id":"1.168136214","rc":[{"batl":[[0,1.98,2.32],[1,1.99,10.23],[2,2,18]],"ltp":1.96,"tv":2916.76,"id":17336468}]}]}
{"op":"mcm","clk":"991236660","pt":1580547999099,"mc":[{"id":"1.168136214","rc":[{"batl":[[0,1.98,14.44]],"ltp":1.96,"tv":2916.76,"id":17336468}]}]}
{"op":"mcm","clk":"991236959","pt":1580548003021,"mc":[{"id":"1.168136214","rc":[{"batl":[[2,2,30.12]],"ltp":1.96,"tv":2916.76,"id":17336468}]}]}
{"op":"mcm","clk":"991236997","pt":1580548003589,"mc":[{"id":"1.168136214","rc":[{"batl":[[2,2,42.11]],"ltp":1.96,"tv":2916.76,"id":17336468},{"batb":[[0,3.65,12.83],[1,3.6,59.44],[2,3.5,9.05]],"ltp":3.7,"tv":807.08,"id":11981493}]}]}
{"op":"mcm","clk":"991237156","pt":1580548005718,"mc":[{"id":"1.168136214","rc":[{"trd":[[1.96,334.42]],"batb":[[0,1.95,6],[1,1.94,77.59],[2,1.93,62]],"batl":[[0,1.96,9.12],[1,1.97,2.25],[2,1.98,14.44]],"ltp":1.96,"tv":2922.76,"id":17336468},{"batb":[[0,3.7,3.08],[1,3.65,12],[2,3.6,59.44]],"ltp":3.7,"tv":807.08,"id":11981493}],"tv":4398.58}]}
{"op":"mcm","clk":"991237243","pt":1580548007111,"mc":[{"id":"1.168136214","rc":[{"batl":[[0,1.97,2.25],[1,1.98,14.44],[2,1.99,10.23]],"ltp":1.96,"tv":2922.76,"id":17336468}]}]}
{"op":"mcm","clk":"991237317","pt":1580548008104,"mc":[{"id":"1.168136214","rc":[{"batl":[[0,1.98,2.32],[1,1.99,10.23],[2,2,42.11]],"ltp":1.96,"tv":2922.76,"id":17336468}]}]}
{"op":"mcm","clk":"991237403","pt":1580548009106,"mc":[{"id":"1.168136214","rc":[{"batl":[[0,1.97,12.12],[1,1.98,2.32],[2,1.99,10.23]],"ltp":1.96,"tv":2922.76,"id":17336468}]}]}
{"op":"mcm","clk":"991237488","pt":1580548010142,"mc":[{"id":"1.168136214","rc":[{"batl":[[0,1.98,2.32],[1,1.99,10.23],[2,2,42.11]],"ltp":1.96,"tv":2922.76,"id":17336468}]}]}
{"op":"mcm","clk":"991237550","pt":1580548010917,"mc":[{"id":"1.168136214","rc":[{"batl":[[0,1.98,14.44]],"ltp":1.96,"tv":2922.76,"id":17336468}]}]}
{"op":"mcm","clk":"991238213","pt":1580548020026,"mc":[{"id":"1.168136214","rc":[{"batb":[[0,1.95,16]],"ltp":1.96,"tv":2922.76,"id":17336468}]}]}
{"op":"mcm","clk":"991240622","pt":1580548047948,"mc":[{"id":"1.168136214","rc":[{"trd":[[4.5,68.16]],"batb":[[0,4.5,5.03]],"ltp":4.5,"tv":675.66,"id":12925630},{"trd":[[1.95,107.37]],"batb":[[0,1.94,75.59],[1,1.93,62],[2,1.92,8]],"ltp":1.95,"tv":2938.76,"id":17336468},{"trd":[[3.8,24.09]],"batb":[[0,3.8,1.79],[1,3.65,10.83],[2,3.6,57.21]],"ltp":3.8,"tv":815.29,"id":11981493}],"tv":4429.72}]}
{"op":"mcm","clk":"991240705","pt":1580548048982,"mc":[{"id":"1.168136214","rc":[{"batl":[[2,2,30.12]],"ltp":1.95,"tv":2938.76,"id":17336468},{"batb":[[1,3.75,2.15],[2,3.65,10.83]],"ltp":3.8,"tv":815.29,"id":11981493}]}]}
{"op":"mcm","clk":"991241243","pt":1580548055078,"mc":[{"id":"1.168136214","rc":[{"batb":[[2,4.3,13.79]],"ltp":4.5,"tv":675.66,"id":12925630}]}]}
{"op":"mcm","clk":"991241437","pt":1580548057056,"mc":[{"id":"1.168136214","rc":[{"trd":[[4.5,69.67]],"batb":[[0,4.5,3.52]],"ltp":4.5,"tv":677.17,"id":12925630},{"trd":[[1.95,110.86]],"batl":[[0,1.96,3.47],[1,1.98,14.44],[2,1.99,10.23]],"ltp":1.95,"tv":2942.25,"id":17336468},{"trd":[[3.8,25.88]],"batb":[[0,3.7,3.03],[1,3.65,10],[2,3.6,57.21]],"ltp":3.8,"tv":817.08,"id":11981493}],"tv":4436.51}]}
{"op":"mcm","clk":"991241625","pt":1580548059086,"mc":[{"id":"1.168136214","rc":[{"batl":[[0,1.96,9.47],[1,1.97,2.21],[2,1.98,14.44]],"ltp":1.95,"tv":2942.25,"id":17336468}]}]}
{"op":"mcm","clk":"991245929","pt":1580548111857,"mc":[{"id":"1.168136214","rc":[{"batb":[[0,1.95,66],[1,1.94,77.59],[2,1.93,62]],"ltp":1.95,"tv":2942.25,"id":17336468}]}]}
{"op":"mcm","clk":"991246080","pt":1580548113943,"mc":[{"id":"1.168136214","rc":[{"trd":[[1.95,129.13]],"batb":[[0,1.95,56.87]],"ltp":1.95,"tv":2960.51,"id":17336468}],"tv":4454.78}]}
{"op":"mcm","clk":"991248709","pt":1580548152904,"mc":[{"id":"1.168136214","rc":[{"trd":[[4.5,73.19]],"batb":[[0,4.3,13.79],[1,4.2,8.05],[2,4.1,2.2]],"ltp":4.5,"tv":680.69,"id":12925630},{"trd":[[1.95,137.25]],"batb":[[0,1.95,48.75]],"ltp":1.95,"tv":2968.63,"id":17336468},{"trd":[[3.8,30.05]],"batb":[[0,3.7,3.86]],"batl":[[1,3.95,2.23],[2,4,3.79]],"ltp":3.8,"tv":821.25,"id":11981493}],"tv":4470.59}]}
{"op":"mcm","clk":"991249048","pt":1580548158106,"mc":[{"id":"1.168136214","rc":[{"batl":[[0,4.7,2.09],[1,4.8,2],[2,4.9,2.74]],"ltp":4.5,"tv":680.69,"id":12925630}]}]}
{"op":"mcm","clk":"991250731","pt":1580548183055,"mc":[{"id":"1.168136214","rc":[{"batl":[[0,4.6,2],[1,4.8,2.23]],"ltp":4.5,"tv":680.69,"id":12925630}]}]}
{"op":"mcm","clk":"991251785","pt":1580548201108,"mc":[{"id":"1.168136214","rc":[{"trd":[[1.94,56.51],[1.95,234.75]],"batb":[[0,1.94,77.34],[1,1.93,66.42],[2,1.92,8]],"ltp":1.94,"tv":3066.63,"id":17336468}],"tv":4568.59}]}
{"op":"mcm","clk":"991253219","pt":1580548221793,"mc":[{"id":"1.168136214","rc":[{"batl":[[0,4.6,4]],"ltp":4.5,"tv":680.69,"id":12925630}]}]}
{"op":"mcm","clk":"991253469","pt":1580548225997,"mc":[{"id":"1.168136214","rc":[{"trd":[[1.96,353.36]],"batb":[[0,1.96,10.53],[1,1.95,2.13],[2,1.94,77.34]],"batl":[[0,1.98,14.44],[1,1.99,10.23],[2,2,30.12]],"ltp":1.96,"tv":3085.57,"id":17336468}],"tv":4587.53}]}
{"op":"mcm","clk":"991253580","pt":1580548227700,"mc":[{"id":"1.168136214","rc":[{"batl":[[0,1.98,14.69]],"ltp":1.96,"tv":3085.57,"id":17336468}]}]}
{"op":"mcm","clk":"991255010","pt":1580548249013,"mc":[{"id":"1.168136214","rc":[{"batb":[[0,1.96,76.53]],"ltp":1.96,"tv":3085.57,"id":17336468}]}]}
{"op":"mcm","clk":"991257915","pt":1580548295005,"mc":[{"id":"1.168136214","rc":[{"trd":[[4.3,58.7]],"batb":[[0,4.3,6.61]],"ltp":4.3,"tv":687.87,"id":12925630},{"trd":[[1.97,93.01],[1.98,391.21],[1.99,290.28],[2,1057.66],[2.02,279.58],[2.04,156.3]],"batb":[[0,1.97,3.19],[1,1.96,79.53],[2,1.95,2.13]],"batl":[[0,2.02,2.19],[1,2.04,3.1],[2,2.06,12.65]],"ltp":2.04,"tv":3277.14,"id":17336468},{"trd":[[3.65,52.42],[3.7,86.43],[3.8,30.88]],"batb":[[0,3.7,2],[1,3.65,5.48]],"ltp":3.65,"tv":829.63,"id":11981493}],"tv":4794.66}]}
{"op":"mcm","clk":"991258034","pt":1580548297039,"mc":[{"id":"1.168136214","rc":[{"batb":[[0,1.96,79.53],[1,1.95,2.13],[2,1.94,75.34]],"batl":[[0,2,2],[1,2.04,2.2],[2,2.06,8]],"ltp":2.04,"tv":3277.14,"id":17336468}]}]}
{"op":"mcm","clk":"991258092","pt":1580548298133,"mc":[{"id":"1.168136214","rc":[{"batb":[[0,4.3,9.61]],"ltp":4.3,"tv":687.87,"id":12925630},{"batb":[[0,1.96,76.53]],"batl":[[0,2.04,2.2],[1,2.06,8],[2,2.08,29.09]],"ltp":2.04,"tv":3277.14,"id":17336468}]}]}
{"op":"mcm","clk":"991258203","pt":1580548299976,"mc":[{"id":"1.168136214","rc":[{"batb":[[0,4.3,6.61]],"ltp":4.3,"tv":687.87,"id":12925630},{"batb":[[0,1.96,79.53]],"batl":[[0,2,2.21],[1,2.02,18.5],[2,2.04,2.2]],"ltp":2.04,"tv":3277.14,"id":17336468}]}]}
{"op":"mcm","clk":"991259592","pt":1580548321056,"mc":[{"id":"1.168136214","rc":[{"batb":[[0,1.96,76.53],[2,1.94,78.34]],"batl":[[0,1.97,22],[1,1.99,2],[2,2,2.21]],"ltp":2.04,"tv":3277.14,"id":17336468}]}]}
{"op":"mcm","clk":"991259725","pt":1580548322050,"mc":[{"id":"1.168136214","rc":[{"batl":[[2,2,8.85]],"ltp":2.04,"tv":3277.14,"id":17336468}]}]}
{"op":"mcm","clk":"991260526","pt":1580548332101,"mc":[{"id":"1.168136214","rc":[{"batb":[[0,4.3,9.61]],"ltp":4.3,"tv":687.87,"id":12925630},{"batb":[[1,1.95,4.13]],"ltp":2.04,"tv":3277.14,"id":17336468}]}]}
{"op":"mcm","clk":"991261273","pt":1580548342616,"mc":[{"id":"1.168136214","rc":[{"trd":[[4.3,62.7]],"batb":[[0,4.3,7.61]],"ltp":4.3,"tv":691.86,"id":12925630}],"tv":4798.65}]}
{"op":"mcm","clk":"991261932","pt":1580548351822,"mc":[{"id":"1.168136214","rc":[{"trd":[[4.3,77.93]],"batb":[[0,4.3,2]],"ltp":4.3,"tv":707.1,"id":12925630}],"tv":4813.89}]}
{"op":"mcm","clk":"991262031","pt":1580548353146,"mc":[{"id":"1.168136214","rc":[{"batb":[[0,4.2,8.05],[1,4.1,2.2],[2,4,20.91]],"ltp":4.3,"tv":707.1,"id":12925630}]}]}
{"op":"mcm","clk":"991262094","pt":1580548354065,"mc":[{"id":"1.168136214","rc":[{"batl":[[2,2,2.21]],"ltp":2.04,"tv":3277.14,"id":17336468}]}]}
{"op":"mcm","clk":"991264223","pt":1580548383101,"mc":[{"id":"1.168136214","rc":[{"batl":[[2,2,8.85]],"ltp":2.04,"tv":3277.14,"id":17336468}]}]}
{"op":"mcm","clk":"991266522","pt":1580548416137,"mc":[{"id":"1.168136214","rc":[{"batb":[[0,3.75,5],[1,3.7,2],[2,3.65,5.48]],"ltp":3.65,"tv":829.63,"id":11981493}]}]}
{"op":"mcm","clk":"991266564","pt":1580548416813,"mc":[{"id":"1.168136214","rc":[{"batb":[[0,3.75,7]],"ltp":3.65,"tv":829.63,"id":11981493}]}]}
{"op":"mcm","clk":"991271058","pt":1580548497053,"mc":[{"id":"1.168136214","rc":[{"trd":[[1.96,378.69]],"batb":[[0,1.96,63.86]],"ltp":1.96,"tv":3302.48,"id":17336468}],"tv":4839.22}]}
{"op":"mcm","clk":"991271265","pt":1580548501151,"mc":[{"id":"1.168136214","rc":[{"batl":[[1,1.98,2],[2,1.99,2]],"ltp":1.96,"tv":3302.48,"id":17336468}]}]}
{"op":"mcm","clk":"991271326","pt":1580548502143,"mc":[{"id":"1.168136214","rc":[{"batl":[[2,1.99,14.06]],"ltp":1.96,"tv":3302.48,"id":17336468}]}]}
{"op":"mcm","clk":"991277266","pt":1580548608003,"mc":[{"id":"1.168136214","rc":[{"trd":[[4.2,10.3]],"batb":[[0,4.2,7.66]],"ltp":4.2,"tv":707.88,"id":12925630},{"trd":[[3.75,41.7]],"batb":[[0,3.75,6.55]],"ltp":3.75,"tv":830.53,"id":11981493}],"tv":4840.9}]}
{"op":"mcm","clk":"991277371","pt":1580548609803,"mc":[{"id":"1.168136214","rc":[{"batb":[[2,4,17.91]],"ltp":4.2,"tv":707.88,"id":12925630}]}]}
{"op":"mcm","clk":"991277827","pt":1580548617870,"mc":[{"id":"1.168136214","rc":[{"trd":[[4.2,20.3]],"batb":[[0,4.2,2.66]],"ltp":4.2,"tv":717.88,"id":12925630}],"tv":4850.9}]}
{"op":"mcm","clk":"991277852","pt":1580548618604,"mc":[{"id":"1.168136214","rc":[{"batl":[[0,3.9,2],[1,3.95,5.54]],"ltp":3.75,"tv":830.53,"id":11981493}]}]}
{"op":"mcm","clk":"991278240","pt":1580548625086,"mc":[{"id":"1.168136214","rc":[{"batl":[[2,4,6.3]],"ltp":3.75,"tv":830.53,"id":11981493}]}]}
{"op":"mcm","clk":"991278588","pt":1580548629122,"mc":[{"id":"1.168136214","rc":[{"batb":[[0,3.75,36.55]],"ltp":3.75,"tv":830.53,"id":11981493}]}]}
{"op":"mcm","clk":"991278667","pt":1580548630038,"mc":[{"id":"1.168136214","rc":[{"batb":[[0,3.8,2.05],[1,3.75,36.55],[2,3.7,2]],"ltp":3.75,"tv":830.53,"id":11981493}]}]}
{"op":"mcm","clk":"991279072","pt":1580548636599,"mc":[{"id":"1.168136214","rc":[{"batb":[[2,3.7,7]],"ltp":3.75,"tv":830.53,"id":11981493}]}]}
{"op":"mcm","clk":"991290534","pt":1580548662147,"mc":[{"id":"1.168136214","rc":[{"batb":[[0,3.8,11.46],[1,3.75,76.55]],"ltp":3.75,"tv":830.53,"id":11981493}]}]}
{"op":"mcm","clk":"991290602","pt":1580548663033,"mc":[{"id":"1.168136214","rc":[{"trd":[[1.97,97.13]],"batl":[[0,1.97,19.94]],"ltp":1.97,"tv":3306.6,"id":17336468}],"tv":4855.02}]}
{"op":"mcm","clk":"991290782","pt":1580548666065,"mc":[{"id":"1.168136214","rc":[{"batb":[[2,4,47.91]],"ltp":4.2,"tv":717.88,"id":12925630}]}]}
{"op":"mcm","clk":"991290962","pt":1580548668852,"mc":[{"id":"1.168136214","rc":[{"batl":[[1,3.95,3.31],[2,4,3.79]],"ltp":3.75,"tv":830.53,"id":11981493}]}]}
{"op":"mcm","clk":"991291317","pt":1580548673976,"mc":[{"id":"1.168136214","rc":[{"batb":[[2,4,67.91]],"ltp":4.2,"tv":717.88,"id":12925630}]}]}
{"op":"mcm","clk":"991291612","pt":1580548679098,"mc":[{"id":"1.168136214","rc":[{"batb":[[1,3.75,72]],"ltp":3.75,"tv":830.53,"id":11981493}]}]}
{"op":"mcm","clk":"991293211","pt":1580548703946,"mc":[{"id":"1.168136214","rc":[{"batb":[[2,1.94,80.34]],"ltp":1.97,"tv":3306.6,"id":17336468},{"batb":[[0,3.85,4.55],[1,3.8,9.41],[2,3.75,72]],"ltp":3.75,"tv":830.53,"id":11981493}]}]}
{"op":"mcm","clk":"991294682","pt":1580548728151,"mc":[{"id":"1.168136214","rc":[{"batb":[[1,1.94,80.34],[2,1.93,65]],"ltp":1.97,"tv":3306.6,"id":17336468},{"trd":[[3.9,16.53]],"batb":[[0,3.9,1.28],[1,3.85,4.55],[2,3.8,9.41]],"batl":[[0,3.95,3.31],[1,4,3.79],[2,4.1,1.22]],"ltp":3.9,"tv":834.53,"id":11981493}],"tv":4859.02}]}
{"op":"mcm","clk":"991294934","pt":1580548732141,"mc":[{"id":"1.168136214","rc":[{"batb":[[1,1.95,6],[2,1.94,80.34]],"ltp":1.97,"tv":3306.6,"id":17336468}]}]}
{"op":"mcm","clk":"991295947","pt":1580548747085,"mc":[{"id":"1.168136214","rc":[{"trd":[[4.1,6.26],[4.2,24.96]],"batb":[[0,4,67.91],[1,3.85,2],[2,3.8,6]],"ltp":4.1,"tv":728.8,"id":12925630},{"trd":[[1.96,409.9]],"batb":[[0,1.96,36.71],[2,1.94,75.34]],"batl":[[0,1.97,21.94]],"ltp":1.96,"tv":3337.81,"id":17336468},{"trd":[[3.95,10.24],[4,24.47],[4.1,8.7]],"batb":[[0,4.1,6.22],[1,4,6.5],[2,3.9,1.28]],"batl":[[0,4.4,2.03],[1,4.5,56],[2,4.6,1.74]],"ltp":4.1,"tv":874.32,"id":11981493}],"tv":4940.93}]}
{"op":"mcm","clk":"991296013","pt":1580548748079,"mc":[{"id":"1.168136214","rc":[{"trd":[[4.1,12.49]],"batb":[[0,4.1,1.93],[1,4,67.91],[2,3.85,2]],"batl":[[0,4.6,6],[1,4.8,4.23]],"ltp":4.1,"tv":735.03,"id":12925630},{"trd":[[1.96,470.28]],"batb":[[0,1.95,6],[1,1.94,75.34],[2,1.93,65]],"batl":[[0,1.96,11.2],[1,1.97,21.94],[2,1.98,2]],"ltp":1.96,"tv":3398.18,"id":17336468},{"trd":[[4.1,14.93]],"batb":[[0,4,4.5],[1,3.9,3.32],[2,3.85,4.55]],"ltp":4.1,"tv":880.54,"id":11981493}],"tv":5013.76}]}
{"op":"mcm","clk":"991296092","pt":1580548749089,"mc":[{"id":"1.168136214","rc":[{"trd":[[4.1,16.83]],"ltp":4.1,"tv":882.44,"id":11981493}],"tv":5015.66}]}
{"op":"mcm","clk":"991296233","pt":1580548751091,"mc":[{"id":"1.168136214","rc":[{"batl":[[1,1.97,71.94]],"ltp":1.96,"tv":3398.18,"id":17336468},{"trd":[[4,33.46]],"batb":[[0,3.9,3.32],[1,3.85,4.55],[2,3.75,70]],"batl":[[0,4,5.5],[1,4.4,2.03],[2,4.5,56]],"ltp":4.0,"tv":891.44,"id":11981493}],"tv":5024.66}]}
{"op":"mcm","clk":"991296269","pt":1580548751566,"mc":[{"id":"1.168136214","rc":[{"batl":[[0,1.96,9.2]],"ltp":1.96,"tv":3398.18,"id":17336468},{"batb":[[0,3.9,1.28],[1,3.85,6.55]],"batl":[[0,4,17.5],[1,4.5,56],[2,4.6,1.74]],"ltp":4.0,"tv":891.44,"id":11981493}]}]}
{"op":"mcm","clk":"991296404","pt":1580548753789,"mc":[{"id":"1.168136214","rc":[{"batb":[[2,3.8,6]],"batl":[[0,3.95,2.07],[1,4,17.5],[2,4.5,56]],"ltp":4.0,"tv":891.44,"id":11981493}]}]}
{"op":"mcm","clk":"991296663","pt":1580548757686,"mc":[{"id":"1.168136214","rc":[{"batl":[[2,4.6,1.74]],"ltp":4.0,"tv":891.44,"id":11981493}]}]}
{"op":"mcm","clk":"991296735","pt":1580548758575,"mc":[{"id":"1.168136214","rc":[{"batl":[[0,1.96,23.2]],"ltp":1.96,"tv":3398.18,"id":17336468}]}]}
{"op":"mcm","clk":"991296808","pt":1580548760083,"mc":[{"id":"1.168136214","rc":[{"batl":[[0,4.5,1.93],[1,4.6,6],[2,4.8,4.23]],"ltp":4.1,"tv":735.03,"id":12925630}]}]}
{"op":"mcm","clk":"991296861","pt":1580548760909,"mc":[{"id":"1.168136214","rc":[{"trd":[[4.4,95.47]],"ltp":4.4,"tv":736.97,"id":12925630},{"trd":[[1.94,57.21],[1.95,242.4]],"batb":[[0,1.94,74.99],[1,1.93,65],[2,1.92,6]],"batl":[[0,1.96,35.44]],"ltp":1.94,"tv":3406.53,"id":17336468},{"trd":[[3.85,1.29],[3.9,17.81]],"batb":[[0,3.85,14.96],[1,3.8,6],[2,3.75,70]],"batl":[[0,4,17.5],[1,4.6,1.74],[2,4.7,53]],"ltp":3.85,"tv":893.63,"id":11981493}],"tv":5037.13}]}
{"op":"mcm","clk":"991297023","pt":1580548763102,"mc":[{"id":"1.168136214","rc":[{"batb":[[1,4,70.91]],"ltp":4.4,"tv":736.97,"id":12925630}]}]}
{"op":"mcm","clk":"991297259","pt":1580548767013,"mc":[{"id":"1.168136214","rc":[{"batl":[[0,1.96,41.79]],"ltp":1.94,"tv":3406.53,"id":17336468}]}]}
{"op":"mcm","clk":"991297687","pt":1580548773888,"mc":[{"id":"1.168136214","rc":[{"batl":[[0,4.6,6],[1,4.8,4.23],[2,4.9,2.74]],"ltp":4.4,"tv":736.97,"id":12925630},{"batl":[[0,1.96,43.79]],"ltp":1.94,"tv":3406.53,"id":17336468}]}]}
{"op":"mcm","clk":"991297745","pt":1580548774822,"mc":[{"id":"1.168136214","rc":[{"batl":[[0,4.4,1.93],[1,4.6,6],[2,4.8,4.23]],"ltp":4.4,"tv":736.97,"id":12925630}]}]}
{"op":"mcm","clk":"991298248","pt":1580548782021,"mc":[{"id":"1.168136214","rc":[{"batl":[[1,1.97,21.94]],"ltp":1.94,"tv":3406.53,"id":17336468}]}]}
{"op":"mcm","clk":"991298263","pt":1580548782332,"mc":[{"id":"1.168136214","rc":[{"batl":[[0,1.96,31.55]],"ltp":1.94,"tv":3406.53,"id":17336468}]}]}
{"op":"mcm","clk":"991298439","pt":1580548784736,"mc":[{"id":"1.168136214","rc":[{"batl":[[0,1.96,17.55]],"ltp":1.94,"tv":3406.53,"id":17336468}]}]}
{"op":"mcm","clk":"991298623","pt":1580548787748,"mc":[{"id":"1.168136214","rc":[{"batl":[[2,4.8,52]],"ltp":3.85,"tv":893.63,"id":11981493}]}]}
{"op":"mcm","clk":"991299488","pt":1580548801050,"mc":[{"id":"1.168136214","rc":[{"trd":[[4,53.46]],"batl":[[0,4,7.5]],"ltp":4.0,"tv":913.63,"id":11981493}],"tv":5057.13}]}
{"op":"mcm","clk":"991299502","pt":1580548801255,"mc":[{"id":"1.168136214","rc":[{"batb":[[1,1.93,68]],"ltp":1.94,"tv":3406.53,"id":17336468},{"batb":[[0,3.9,2],[1,3.85,14.96],[2,3.8,6]],"ltp":4.0,"tv":913.63,"id":11981493}]}]}
{"op":"mcm","clk":"991301677","pt":1580548834137,"mc":[{"id":"1.168136214","rc":[{"trd":[[1.96,491.08]],"batl":[[0,1.96,7.15]],"ltp":1.96,"tv":3427.33,"id":17336468}],"tv":5077.93}]}
{"op":"mcm","clk":"991309761","pt":1580548947254,"mc":[{"id":"1.168136214","rc":[{"trd":[[1.94,117.18]],"batb":[[0,1.94,45.02]],"ltp":1.94,"tv":3487.3,"id":17336468}],"tv":5137.9}]}
{"op":"mcm","clk":"991310239","pt":1580548954139,"mc":[{"id":"1.168136214","rc":[{"batl":[[2,5.1,1.74]],"ltp":4.0,"tv":913.63,"id":11981493}]}]}
{"op":"mcm","clk":"991312799","pt":1580548995130,"mc":[{"id":"1.168136214","rc":[{"batl":[[2,4.9,51]],"ltp":4.0,"tv":913.63,"id":11981493}]}]}
{"op":"mcm","clk":"991312872","pt":1580548996141,"mc":[{"id":"1.168136214","rc":[{"batb":[[0,3.85,14.96],[1,3.8,6],[2,3.75,70]],"ltp":4.0,"tv":913.63,"id":11981493}]}]}
{"op":"mcm","clk":"991314814","pt":1580549024984,"mc":[{"id":"1.168136214","rc":[{"batl":[[2,4.8,52]],"ltp":4.0,"tv":913.63,"id":11981493}]}]}
{"op":"mcm","clk":"991315696","pt":1580549038147,"mc":[{"id":"1.168136214","rc":[{"batb":[[1,4,100.91]],"ltp":4.4,"tv":736.97,"id":12925630}]}]}
{"op":"mcm","clk":"991317785","pt":1580549072142,"mc":[{"id":"1.168136214","rc":[{"batb":[[0,3.85,5.64]],"batl":[[1,4.2,180],[2,4.6,1.74]],"ltp":4.0,"tv":913.63,"id":11981493}]}]}
{"op":"mcm","clk":"991317845","pt":1580549073132,"mc":[{"id":"1.168136214","rc":[{"batb":[[0,1.94,51.02]],"batl":[[0,1.96,5.15],[1,1.97,19.94]],"ltp":1.94,"tv":3487.3,"id":17336468},{"batb":[[0,3.85,3.64],[1,3.8,8]],"batl":[[0,3.95,2.17],[1,4,7.5],[2,4.2,180]],"ltp":4.0,"tv":913.63,"id":11981493}]}]}
{"op":"mcm","clk":"991319423","pt":1580549101131,"mc":[{"id":"1.168136214","rc":[{"batl":[[0,4,7.5],[1,4.2,180],[2,4.6,1.74]],"ltp":4.0,"tv":913.63,"id":11981493}]}]}
{"op":"mcm","clk":"991320402","pt":1580549116136,"mc":[{"id":"1.168136214","rc":[{"batb":[[0,4.2,5],[1,4.1,1.93],[2,4,100.91]],"ltp":4.4,"tv":736.97,"id":12925630}]}]}
{"op":"mcm","clk":"991321028","pt":1580549125829,"mc":[{"id":"1.168136214","rc":[{"batl":[[1,1.97,21.94]],"ltp":1.94,"tv":3487.3,"id":17336468}]}]}
{"op":"mcm","clk":"991323203","pt":1580549160093,"mc":[{"id":"1.168136214","rc":[{"batl":[[0,1.96,7.25]],"ltp":1.94,"tv":3487.3,"id":17336468}]}]}
{"op":"mcm","clk":"991324657","pt":1580549181151,"mc":[{"id":"1.168136214","rc":[{"batl":[[0,3.95,2.11],[1,4,7.5],[2,4.1,20]],"ltp":4.0,"tv":913.63,"id":11981493}]}]}
{"op":"mcm","clk":"991326655","pt":1580549212682,"mc":[{"id":"1.168136214","rc":[{"trd":[[1.94,127.18]],"batb":[[0,1.94,46.02]],"ltp":1.94,"tv":3497.3,"id":17336468}],"tv":5147.9}]}
{"op":"mcm","clk":"991329539","pt":1580549261123,"mc":[{"id":"1.168136214","rc":[{"trd":[[3.95,14.46],[4,59.24]],"batl":[[0,4,4.61],[1,4.1,20],[2,4.2,180]],"ltp":4.0,"tv":923.63,"id":11981493}],"tv":5157.9}]}
{"op":"mcm","clk":"991330066","pt":1580549268921,"mc":[{"id":"1.168136214","rc":[{"batl":[[0,4.4,35.93]],"ltp":4.4,"tv":736.97,"id":12925630},{"batb":[[0,1.95,8.26],[1,1.94,46.02],[2,1.93,68]],"batl":[[1,1.97,19.94]],"ltp":1.94,"tv":3497.3,"id":17336468}]}]}
{"op":"mcm","clk":"991331226","pt":1580549284854,"mc":[{"id":"1.168136214","rc":[{"batb":[[0,4.2,2]],"ltp":4.4,"tv":736.97,"id":12925630}]}]}
{"op":"mcm","clk":"991331274","pt":1580549285531,"mc":[{"id":"1.168136214","rc":[{"batb":[[0,4.1,1.93],[1,4,100.91],[2,3.85,2]],"batl":[[0,4.4,34]],"ltp":4.4,"tv":736.97,"id":12925630}]}]}
{"op":"mcm","clk":"991331585","pt":1580549289131,"mc":[{"id":"1.168136214","rc":[{"trd":[[4.1,16.5]],"batb":[[0,4.1,2.04]],"ltp":4.1,"tv":740.97,"id":12925630},{"trd":[[1.96,491.38]],"batl":[[0,1.96,6.95]],"ltp":1.96,"tv":3497.6,"id":17336468},{"trd":[[4,59.39]],"batl":[[0,4,4.46]],"ltp":4.0,"tv":923.78,"id":11981493}],"tv":5162.35}]}
{"op":"mcm","clk":"991331838","pt":1580549292140,"mc":[{"id":"1.168136214","rc":[{"batb":[[1,4,97.91]],"ltp":4.1,"tv":740.97,"id":12925630}]}]}
{"op":"mcm","clk":"991332334","pt":1580549298032,"mc":[{"id":"1.168136214","rc":[{"batl":[[0,4.4,36],[1,4.6,4]],"ltp":4.1,"tv":740.97,"id":12925630}]}]}
{"op":"mcm","clk":"991333356","pt":1580549312112,"mc":[{"id":"1.168136214","rc":[{"trd":[[4.1,21.06]],"batb":[[0,4,97.91],[1,3.85,2],[2,3.75,3]],"ltp":4.1,"tv":745.53,"id":12925630},{"trd":[[1.96,492.38]],"batl":[[0,1.96,5.95]],"ltp":1.96,"tv":3498.6,"id":17336468},{"trd":[[4,59.88]],"batl":[[0,4,3.97]],"ltp":4.0,"tv":924.27,"id":11981493}],"tv":5168.4}]}
{"op":"mcm","clk":"991333404","pt":1580549312734,"mc":[{"id":"1.168136214","rc":[{"batb":[[0,4.1,2.17],[1,4,97.91],[2,3.85,2]],"ltp":4.1,"tv":745.53,"id":12925630},{"batb":[[0,3.85,5.64]],"ltp":4.0,"tv":924.27,"id":11981493}]}]}
{"op":"mcm","clk":"991335551","pt":1580549343145,"mc":[{"id":"1.168136214","rc":[{"trd":[[1.95,246.4]],"batb":[[0,1.95,6.26]],"ltp":1.95,"tv":3502.6,"id":17336468}],"tv":5172.4}]}
{"op":"mcm","clk":"991335614","pt":1580549343873,"mc":[{"id":"1.168136214","rc":[{"batb":[[0,3.85,3.64]],"ltp":4.0,"tv":924.27,"id":11981493}]}]}
{"op":"mcm","clk":"991335676","pt":1580549344655,"mc":[{"id":"1.168136214","rc":[{"trd":[[1.96,496.34]],"batl":[[0,1.96,3.97]],"ltp":1.96,"tv":3506.56,"id":17336468}],"tv":5176.36}]}
{"op":"mcm","clk":"991336085","pt":1580549349768,"mc":[{"id":"1.168136214","rc":[{"batl":[[1,4.1,15]],"ltp":4.0,"tv":924.27,"id":11981493}]}]}
{"op":"mcm","clk":"991336455","pt":1580549353990,"mc":[{"id":"1.168136214","rc":[{"batb":[[1,1.94,30.12]],"ltp":1.96,"tv":3506.56,"id":17336468}]}]}
{"op":"mcm","clk":"991336604","pt":1580549356074,"mc":[{"id":"1.168136214","rc":[{"batb":[[0,1.94,30.12],[1,1.93,68],[2,1.92,6]],"batl":[[0,1.96,15.33]],"ltp":1.96,"tv":3506.56,"id":17336468}]}]}
{"op":"mcm","clk":"991336984","pt":1580549360770,"mc":[{"id":"1.168136214","rc":[{"batb":[[0,1.95,8.11],[1,1.94,30.12],[2,1.93,68]],"ltp":1.96,"tv":3506.56,"id":17336468},{"trd":[[3.85,8.57]],"batb":[[0,3.8,8],[1,3.75,72],[2,3.7,5]],"batl":[[0,3.85,1.36],[1,3.95,2.11],[2,4,3.97]],"ltp":3.85,"tv":931.55,"id":11981493}],"tv":5183.64}]}
{"op":"mcm","clk":"991339418","pt":1580549390148,"mc":[{"id":"1.168136214","rc":[{"batl":[[0,3.95,2.11],[1,4,3.97],[2,4.1,15]],"ltp":3.85,"tv":931.55,"id":11981493}]}]}
{"op":"mcm","clk":"991339952","pt":1580549399050,"mc":[{"id":"1.168136214","rc":[{"batb":[[0,1.94,30.12],[1,1.93,68],[2,1.92,6]],"ltp":1.96,"tv":3506.56,"id":17336468}]}]}
{"op":"mcm","clk":"991341260","pt":1580549415054,"mc":[{"id":"1.168136214","rc":[{"batb":[[0,1.95,3.54],[1,1.94,30.12],[2,1.93,68]],"ltp":1.96,"tv":3506.56,"id":17336468}]}]}
{"op":"mcm","clk":"991341732","pt":1580549422079,"mc":[{"id":"1.168136214","rc":[{"batl":[[2,4.2,180]],"ltp":3.85,"tv":931.55,"id":11981493}]}]}
{"op":"mcm","clk":"991346037","pt":1580549483090,"mc":[{"id":"1.168136214","rc":[{"trd":[[4.4,101.52]],"batl":[[0,4.4,25.95],[1,4.5,5.12],[2,4.6,4]],"ltp":4.4,"tv":751.58,"id":12925630},{"trd":[[1.96,509.91]],"batb":[[1,1.94,33.12]],"batl":[[0,1.96,1.76]],"ltp":1.96,"tv":3520.13,"id":17336468},{"trd":[[3.8,53.88]],"batb":[[0,3.8,2]],"ltp":3.8,"tv":954.55,"id":11981493}],"tv":5226.27}]}
{"op":"mcm","clk":"991346120","pt":1580549484097,"mc":[{"id":"1.168136214","rc":[{"batb":[[1,4,100.91]],"batl":[[0,4.3,5.13],[1,4.4,25.95],[2,4.5,5.12]],"ltp":4.4,"tv":751.58,"id":12925630},{"batb":[[0,1.95,12.67]],"batl":[[0,1.96,7.16]],"ltp":1.96,"tv":3520.13,"id":17336468},{"batl":[[0,3.9,6],[1,3.95,6.11],[2,4,3.97]],"ltp":3.8,"tv":954.55,"id":11981493}]}]}
{"op":"mcm","clk":"991346506","pt":1580549487723,"mc":[{"id":"1.168136214","rc":[{"batb":[[0,4.2,7.76],[1,4.1,2.17],[2,4,100.91]],"batl":[[0,4.4,30.95],[1,4.5,5.12],[2,4.6,4]],"ltp":4.4,"tv":751.58,"id":12925630},{"trd":[[1.96,524.22]],"batb":[[0,1.96,9.47],[1,1.95,12.67],[2,1.94,33.12]],"batl":[[0,1.97,19.94],[1,1.98,2],[2,1.99,14.06]],"ltp":1.96,"tv":3534.44,"id":17336468},{"batb":[[0,3.85,10.47],[1,3.8,2],[2,3.75,72]],"ltp":3.8,"tv":954.55,"id":11981493}],"tv":5240.58}]}
{"op":"mcm","clk":"991347114","pt":1580549495133,"mc":[{"id":"1.168136214","rc":[{"batb":[[0,4.2,9.76]],"ltp":4.4,"tv":751.58,"id":12925630}]}]}
{"op":"mcm","clk":"991347832","pt":1580549501114,"mc":[{"id":"1.168136214","rc":[{"batl":[[1,3.95,2.11],[2,4,13.97]],"ltp":3.8,"tv":954.55,"id":11981493}]}]}
{"op":"mcm","clk":"991348733","pt":1580549511948,"mc":[{"id":"1.168136214","rc":[{"batl":[[2,4,3.97]],"ltp":3.8,"tv":954.55,"id":11981493}]}]}
{"op":"mcm","clk":"991351119","pt":1580549545090,"mc":[{"id":"1.168136214","rc":[{"trd":[[1.96,540.16]],"batb":[[0,1.96,1.5]],"ltp":1.96,"tv":3550.38,"id":17336468}],"tv":5256.51}]}
{"op":"mcm","clk":"991351185","pt":1580549546090,"mc":[{"id":"1.168136214","rc":[{"trd":[[1.95,247.4],[1.96,543.16]],"batb":[[0,1.95,3.04],[1,1.94,33.12],[2,1.93,68]],"batl":[[0,1.97,21.94]],"ltp":1.95,"tv":3554.38,"id":17336468}],"tv":5260.52}]}
{"op":"mcm","clk":"991351222","pt":1580549546814,"mc":[{"id":"1.168136214","rc":[{"batl":[[2,1.99,20.21]],"ltp":1.95,"tv":3554.38,"id":17336468}]}]}
{"op":"mcm","clk":"991361253","pt":1580549553120,"mc":[{"id":"1.168136214","rc":[{"trd":[[3.9,29.8]],"batl":[[0,3.95,2.11],[1,4,3.97],[2,4.1,6]],"ltp":3.9,"tv":966.54,"id":11981493}],"tv":5272.52}]}
{"op":"mcm","clk":"991363876","pt":1580549594980,"mc":[{"id":"1.168136214","rc":[{"batl":[[0,1.97,33.3]],"ltp":1.95,"tv":3554.38,"id":17336468}]}]}
{"op":"mcm","clk":"991367296","pt":1580549642093,"mc":[{"id":"1.168136214","rc":[{"batl":[[2,1.99,30.89]],"ltp":1.95,"tv":3554.38,"id":17336468}]}]}
{"op":"mcm","clk":"991369208","pt":1580549669008,"mc":[{"id":"1.168136214","rc":[{"trd":[[1.97,101.13]],"batl":[[0,1.97,31.3]],"ltp":1.97,"tv":3558.38,"id":17336468}],"tv":5276.52}]}
{"op":"mcm","clk":"991380985","pt":1580549822010,"mc":[{"id":"1.168136214","rc":[{"trd":[[1.97,144.2]],"batl":[[0,1.97,11.76]],"ltp":1.97,"tv":3601.46,"id":17336468},{"batb":[[0,3.85,8.47]],"ltp":3.9,"tv":966.54,"id":11981493}],"tv":5319.59}]}
{"op":"mcm","clk":"991383323","pt":1580549850097,"mc":[{"id":"1.168136214","rc":[{"batl":[[2,1.99,24.74]],"ltp":1.97,"tv":3601.46,"id":17336468}]}]}
{"op":"mcm","clk":"991387550","pt":1580549904075,"mc":[{"id":"1.168136214","rc":[{"trd":[[1.97,148.2]],"batl":[[0,1.97,9.76]],"ltp":1.97,"tv":3605.46,"id":17336468}],"tv":5323.59}]}
{"op":"mcm","clk":"991388907","pt":1580549922115,"mc":[{"id":"1.168136214","rc":[{"batb":[[2,4,105.91]],"ltp":4.4,"tv":751.58,"id":12925630}]}]}
{"op":"mcm","clk":"991390688","pt":1580549945112,"mc":[{"id":"1.168136214","rc":[{"trd":[[1.97,152.2]],"batl":[[0,1.97,7.76]],"ltp":1.97,"tv":3609.46,"id":17336468}],"tv":5327.59}]}
{"op":"mcm","clk":"991393162","pt":1580549978064,"mc":[{"id":"1.168136214","rc":[{"batb":[[0,1.95,12.24]],"batl":[[0,1.97,5.76]],"ltp":1.97,"tv":3609.46,"id":17336468}]}]}
{"op":"mcm","clk":"991393250","pt":1580549979154,"mc":[{"id":"1.168136214","rc":[{"trd":[[4.3,82.35]],"batl":[[0,4.3,6.66],[1,4.4,30.95],[2,4.5,5.12]],"ltp":4.3,"tv":756.0,"id":12925630},{"batb":[[0,1.95,3.04]],"batl":[[0,1.97,7.76]],"ltp":1.97,"tv":3609.46,"id":17336468}],"tv":5332.01}]}
{"op":"mcm","clk":"991394108","pt":1580549988992,"mc":[{"id":"1.168136214","rc":[{"batl":[[0,1.97,5.76]],"ltp":1.97,"tv":3609.46,"id":17336468},{"batb":[[0,3.85,10.47]],"batl":[[0,3.9,8.4],[1,3.95,2.11],[2,4,3.97]],"ltp":3.9,"tv":966.54,"id":11981493}]}]}
{"op":"mcm","clk":"991394209","pt":1580549990090,"mc":[{"id":"1.168136214","rc":[{"batl":[[1,4.4,28.95]],"ltp":4.3,"tv":756.0,"id":12925630}]}]}
{"op":"mcm","clk":"991394289","pt":1580549990980,"mc":[{"id":"1.168136214","rc":[{"batl":[[0,4.3,8.66]],"ltp":4.3,"tv":756.0,"id":12925630},{"batb":[[0,1.95,12.31]],"ltp":1.97,"tv":3609.46,"id":17336468}]}]}
{"op":"mcm","clk":"991395075","pt":1580550000982,"mc":[{"id":"1.168136214","rc":[{"batb":[[0,1.96,21],[1,1.95,12.31],[2,1.94,33.12]],"ltp":1.97,"tv":3609.46,"id":17336468}]}]}
{"op":"mcm","clk":"991398384","pt":1580550039131,"mc":[{"id":"1.168136214","rc":[{"trd":[[3.9,39.8]],"batl":[[0,3.9,3.4]],"ltp":3.9,"tv":976.54,"id":11981493}],"tv":5342.01}]}
{"op":"mcm","clk":"991398711","pt":1580550043057,"mc":[{"id":"1.168136214","rc":[{"trd":[[1.96,585.16]],"batb":[[0,1.95,12.31],[1,1.94,33.12],[2,1.93,68]],"batl":[[0,1.96,9],[1,1.97,5.76],[2,1.98,2]],"ltp":1.96,"tv":3651.46,"id":17336468}],"tv":5384.02}]}
{"op":"mcm","clk":"991398791","pt":1580550044052,"mc":[{"id":"1.168136214","rc":[{"batb":[[0,4.2,10.14]],"ltp":4.3,"tv":756.0,"id":12925630},{"trd":[[1.96,586.77]],"batl":[[0,1.96,8.2]],"ltp":1.96,"tv":3653.06,"id":17336468},{"trd":[[3.9,40.61]],"batl":[[0,3.9,3]],"ltp":3.9,"tv":977.35,"id":11981493}],"tv":5386.43}]}
{"op":"mcm","clk":"991399793","pt":1580550056070,"mc":[{"id":"1.168136214","rc":[{"trd":[[3.9,46.61]],"batb":[[0,3.9,6.24],[1,3.85,21.47],[2,3.8,2]],"batl":[[0,3.95,2.11],[1,4,3.97],[2,4.1,6]],"ltp":3.9,"tv":983.35,"id":11981493}],"tv":5392.43}]}
{"op":"mcm","clk":"991401645","pt":1580550076101,"mc":[{"id":"1.168136214","rc":[{"batl":[[0,4.3,18.06]],"ltp":4.3,"tv":756.0,"id":12925630}]}]}
{"op":"mcm","clk":"991401739","pt":1580550077099,"mc":[{"id":"1.168136214","rc":[{"batb":[[2,4,107.91]],"batl":[[0,4.3,22.06]],"ltp":4.3,"tv":756.0,"id":12925630},{"batb":[[0,3.85,21.47],[1,3.8,2],[2,3.75,72]],"batl":[[0,4,3.97],[1,4.1,9.05],[2,4.2,180]],"ltp":3.9,"tv":983.35,"id":11981493}]}]}
{"op":"mcm","clk":"991402005","pt":1580550080127,"mc":[{"id":"1.168136214","rc":[{"trd":[[4.2,45.22]],"batb":[[0,4.1,2.17],[1,4,107.91],[2,3.95,5]],"batl":[[0,4.2,15.21],[1,4.3,22.06],[2,4.4,28.95]],"ltp":4.2,"tv":776.26,"id":12925630},{"trd":[[1.96,593.19]],"batl":[[0,1.96,4.99]],"ltp":1.96,"tv":3659.49,"id":17336468},{"batb":[[0,3.9,2.1],[1,3.85,21.47],[2,3.8,2]],"ltp":3.9,"tv":983.35,"id":11981493}],"tv":5419.1}]}
{"op":"mcm","clk":"991402081","pt":1580550080807,"mc":[{"id":"1.168136214","rc":[{"batb":[[0,4.1,3.71]],"ltp":4.2,"tv":776.26,"id":12925630},{"trd":[[4,63.82],[4.1,16.89]],"batb":[[0,3.95,1.59],[1,3.9,2.1],[2,3.85,21.47]],"batl":[[0,4.1,11.02],[1,4.2,180],[2,4.4,6]],"ltp":4.1,"tv":987.35,"id":11981493}],"tv":5423.1}]}
{"op":"mcm","clk":"991402201","pt":1580550082119,"mc":[{"id":"1.168136214","rc":[{"batb":[[1,4,104.91]],"ltp":4.2,"tv":776.26,"id":12925630}]}]}
{"op":"mcm","clk":"991402285","pt":1580550083117,"mc":[{"id":"1.168136214","rc":[{"batb":[[0,3.95,3.62]],"ltp":4.1,"tv":987.35,"id":11981493}]}]}
{"op":"mcm","clk":"991402310","pt":1580550083433,"mc":[{"id":"1.168136214","rc":[{"batb":[[0,3.95,1.62]],"batl":[[2,4.6,1.74]],"ltp":4.1,"tv":987.35,"id":11981493}]}]}
{"op":"mcm","clk":"991402581","pt":1580550087026,"mc":[{"id":"1.168136214","rc":[{"batl":[[0,4.1,13.02]],"ltp":4.1,"tv":987.35,"id":11981493}]}]}
{"op":"mcm","clk":"991402672","pt":1580550088137,"mc":[{"id":"1.168136214","rc":[{"batb":[[0,3.95,3.62]],"ltp":4.1,"tv":987.35,"id":11981493}]}]}
{"op":"mcm","clk":"991402827","pt":1580550090016,"mc":[{"id":"1.168136214","rc":[{"trd":[[4.1,25.06]],"batb":[[0,4.1,1.71]],"batl":[[1,4.3,20.06]],"ltp":4.1,"tv":780.26,"id":12925630}],"tv":5427.1}]}
{"op":"mcm","clk":"991402893","pt":1580550090851,"mc":[{"id":"1.168136214","rc":[{"batb":[[0,4.1,3.71]],"ltp":4.1,"tv":780.26,"id":12925630},{"batb":[[0,3.95,1.62]],"ltp":4.1,"tv":987.35,"id":11981493}]}]}
{"op":"mcm","clk":"991403383","pt":1580550096025,"mc":[{"id":"1.168136214","rc":[{"trd":[[4.2,65.2]],"batl":[[0,4.2,5.22]],"ltp":4.2,"tv":800.25,"id":12925630}],"tv":5447.09}]}
{"op":"mcm","clk":"991403725","pt":1580550100049,"mc":[{"id":"1.168136214","rc":[{"trd":[[4.1,29.06]],"batb":[[0,4.1,1.7]],"ltp":4.1,"tv":804.25,"id":12925630}],"tv":5451.1}]}
{"op":"mcm","clk":"991403756","pt":1580550100465,"mc":[{"id":"1.168136214","rc":[{"trd":[[1.95,251.4]],"batb":[[0,1.95,10.31]],"ltp":1.95,"tv":3663.49,"id":17336468}],"tv":5455.1}]}
{"op":"mcm","clk":"991404420","pt":1580550109063,"mc":[{"id":"1.168136214","rc":[{"trd":[[4.1,33.06]],"batb":[[0,4.1,3.96],[1,4,113.11]],"batl":[[1,4.3,13.4]],"ltp":4.1,"tv":808.25,"id":12925630}],"tv":5459.1}]}
{"op":"mcm","clk":"991405903","pt":1580550129090,"mc":[{"id":"1.168136214","rc":[{"trd":[[4.1,37.06]],"batb":[[0,4.1,1.96]],"ltp":4.1,"tv":812.25,"id":12925630}],"tv":5463.1}]}
{"op":"mcm","clk":"991407341","pt":1580550148003,"mc":[{"id":"1.168136214","rc":[{"trd":[[4.1,41.06]],"ltp":4.1,"tv":816.25,"id":12925630}],"tv":5467.1}]}
{"op":"mcm","clk":"991408152","pt":1580550159126,"mc":[{"id":"1.168136214","rc":[{"trd":[[4.1,45.06]],"ltp":4.1,"tv":820.25,"id":12925630}],"tv":5471.1}]}
{"op":"mcm","clk":"991408854","pt":1580550168916,"mc":[{"id":"1.168136214","rc":[{"trd":[[4.1,48.98]],"batb":[[0,4,111.11],[1,3.95,5],[2,3.9,5]],"batl":[[0,4.2,5.26]],"ltp":4.1,"tv":824.17,"id":12925630}],"tv":5475.02}]}
{"op":"mcm","clk":"991411404","pt":1580550201970,"mc":[{"id":"1.168136214","rc":[{"batl":[[0,1.96,7.99]],"ltp":1.95,"tv":3663.49,"id":17336468}]}]}
{"op":"mcm","clk":"991412820","pt":1580550221637,"mc":[{"id":"1.168136214","rc":[{"trd":[[4.1,49.06]],"batb":[[0,4.1,1.72],[1,4,111.11],[2,3.95,5]],"batl":[[0,4.2,5.22]],"ltp":4.1,"tv":824.25,"id":12925630}],"tv":5475.1}]}
{"op":"mcm","clk":"991413025","pt":1580550223931,"mc":[{"id":"1.168136214","rc":[{"trd":[[1.95,255.4]],"batb":[[0,1.95,8.31]],"ltp":1.95,"tv":3667.49,"id":17336468}],"tv":5479.1}]}
{"op":"mcm","clk":"991413427","pt":1580550229121,"mc":[{"id":"1.168136214","rc":[{"trd":[[4.1,52.5]],"batb":[[0,4,111.11],[1,3.95,5],[2,3.9,5]],"batl":[[0,4.2,5.5]],"ltp":4.1,"tv":827.69,"id":12925630}],"tv":5482.53}]}
{"op":"mcm","clk":"991414036","pt":1580550237115,"mc":[{"id":"1.168136214","rc":[{"trd":[[4.1,53.06],[4.2,75.64],[4.3,86.52]],"batl":[[0,4.3,11.32],[1,4.4,28.95],[2,4.5,5.12]],"ltp":4.3,"tv":842.85,"id":12925630},{"batl":[[0,4,2.31],[1,4.1,13.02],[2,4.2,180]],"ltp":4.1,"tv":987.35,"id":11981493}],"tv":5497.69}]}
{"op":"mcm","clk":"991414105","pt":1580550238152,"mc":[{"id":"1.168136214","rc":[{"batb":[[0,4,114.11]],"ltp":4.3,"tv":842.85,"id":12925630}]}]}
{"op":"mcm","clk":"991414163","pt":1580550239142,"mc":[{"id":"1.168136214","rc":[{"batb":[[0,4.1,3.76],[1,4,116.11],[2,3.95,5]],"ltp":4.3,"tv":842.85,"id":12925630}]}]}
{"op":"mcm","clk":"991414516","pt":1580550243747,"mc":[{"id":"1.168136214","rc":[{"batb":[[1,1.94,38.12]],"ltp":1.95,"tv":3667.49,"id":17336468}]}]}
{"op":"mcm","clk":"991414855","pt":1580550248143,"mc":[{"id":"1.168136214","rc":[{"batl":[[0,4.3,13.32]],"ltp":4.3,"tv":842.85,"id":12925630}]}]}
{"op":"mcm","clk":"991416944","pt":1580550273008,"mc":[{"id":"1.168136214","rc":[{"trd":[[4.1,60.57]],"batb":[[0,4,114.11],[1,3.95,5],[2,3.9,5]],"ltp":4.1,"tv":850.36,"id":12925630}],"tv":5505.21}]}
{"op":"mcm","clk":"991417402","pt":1580550278123,"mc":[{"id":"1.168136214","rc":[{"batb":[[0,4,111.11]],"ltp":4.1,"tv":850.36,"id":12925630}]}]}
{"op":"mcm","clk":"991418143","pt":1580550288112,"mc":[{"id":"1.168136214","rc":[{"batb":[[0,4.1,1.76],[1,4,111.11],[2,3.95,5]],"batl":[[0,4.3,9.32]],"ltp":4.1,"tv":850.36,"id":12925630},{"trd":[[3.9,63.29],[3.95,17.7]],"batb":[[0,3.85,21.47],[1,3.8,3.26],[2,3.75,70]],"batl":[[0,3.9,6.04],[1,3.95,2.26],[2,4,2.31]],"ltp":3.9,"tv":1007.27,"id":11981493}],"tv":5525.13}]}
{"op":"mcm","clk":"991418313","pt":1580550290142,"mc":[{"id":"1.168136214","rc":[{"batb":[[0,4.2,2.62],[1,4.1,1.76],[2,4,111.11]],"ltp":4.1,"tv":850.36,"id":12925630},{"trd":[[1.96,604.43]],"batl":[[0,1.96,2.37]],"ltp":1.96,"tv":3678.73,"id":17336468},{"trd":[[3.9,68.93]],"batl":[[0,3.9,3.22]],"ltp":3.9,"tv":1012.92,"id":11981493}],"tv":5542.02}]}
{"op":"mcm","clk":"991418383","pt":1580550291126,"mc":[{"id":"1.168136214","rc":[{"batl":[[1,1.98,2],[2,1.99,24.74]],"ltp":1.96,"tv":3678.73,"id":17336468}]}]}
{"op":"mcm","clk":"991418433","pt":1580550291902,"mc":[{"id":"1.168136214","rc":[{"batl":[[1,1.97,11.36],[2,1.98,2]],"ltp":1.96,"tv":3678.73,"id":17336468}]}]}
{"op":"mcm","clk":"991418640","pt":1580550293943,"mc":[{"id":"1.168136214","rc":[{"batl":[[1,1.98,13.36],[2,1.99,24.74]],"ltp":1.96,"tv":3678.73,"id":17336468}]}]}
{"op":"mcm","clk":"991418739","pt":1580550295143,"mc":[{"id":"1.168136214","rc":[{"batl":[[1,1.97,11.36],[2,1.98,2]],"ltp":1.96,"tv":3678.73,"id":17336468}]}]}
{"op":"mcm","clk":"991419834","pt":1580550307771,"mc":[{"id":"1.168136214","rc":[{"trd":[[4.3,89.44]],"batb":[[0,4.2,4.62],[1,4.1,3.76]],"batl":[[0,4.3,11.39]],"ltp":4.3,"tv":853.29,"id":12925630},{"trd":[[1.95,280.96]],"batb":[[0,1.95,7.75]],"ltp":1.95,"tv":3704.29,"id":17336468},{"trd":[[3.9,72.15]],"batl":[[0,4,2.31],[1,4.1,9.97],[2,4.2,180]],"ltp":3.9,"tv":1016.14,"id":11981493}],"tv":5573.72}]}
{"op":"mcm","clk":"991420140","pt":1580550311054,"mc":[{"id":"1.168136214","rc":[{"batb":[[2,4,114.11]],"ltp":4.3,"tv":853.29,"id":12925630}]}]}
{"op":"mcm","clk":"991443357","pt":1580550464962,"mc":[{"id":"1.168136214","rc":[{"trd":[[4.2,84.88]],"batb":[[0,4.1,3.76],[1,4,116.11],[2,3.95,5]],"batl":[[0,4.2,17.38],[1,4.3,11.39],[2,4.4,28.95]],"ltp":4.2,"tv":862.53,"id":12925630},{"batb":[[0,3.9,3.24],[1,3.85,21.47],[2,3.8,3.26]],"ltp":3.9,"tv":1016.14,"id":11981493}],"tv":5582.96}]}
{"op":"mcm","clk":"991443698","pt":1580550468818,"mc":[{"id":"1.168136214","rc":[{"batb":[[0,1.95,15.75]],"ltp":1.95,"tv":3704.29,"id":17336468}]}]}
{"op":"mcm","clk":"991443790","pt":1580550469955,"mc":[{"id":"1.168136214","rc":[{"batb":[[1,4,113.11]],"ltp":4.2,"tv":862.53,"id":12925630}]}]}
{"op":"mcm","clk":"991445807","pt":1580550495058,"mc":[{"id":"1.168136214","rc":[{"trd":[[4.1,64.57]],"batb":[[0,4,111.11],[1,3.95,5],[2,3.9,5]],"batl":[[1,4.3,9.39]],"ltp":4.1,"tv":866.53,"id":12925630}],"tv":5586.96}]}
{"op":"mcm","clk":"991446382","pt":1580550502084,"mc":[{"id":"1.168136214","rc":[{"trd":[[4.2,87.08]],"batl":[[0,4.2,15.18]],"ltp":4.2,"tv":868.73,"id":12925630},{"trd":[[1.95,317.2]],"batb":[[0,1.94,38.12],[1,1.93,68],[2,1.92,15.26]],"batl":[[0,1.95,27.17],[1,1.96,2.37],[2,1.97,11.36]],"ltp":1.95,"tv":3740.53,"id":17336468},{"trd":[[4,66.13]],"batl":[[0,4.1,9.97],[1,4.2,180],[2,4.6,1.74]],"ltp":4.0,"tv":1018.45,"id":11981493}],"tv":5627.71}]}
{"op":"mcm","clk":"991446453","pt":1580550503077,"mc":[{"id":"1.168136214","rc":[{"trd":[[4.2,88.98]],"batb":[[0,4.1,2.08],[1,4,113.11],[2,3.95,5]],"batl":[[0,4.2,13.28]],"ltp":4.2,"tv":870.63,"id":12925630},{"trd":[[1.95,339.3]],"batl":[[0,1.95,14.07]],"ltp":1.95,"tv":3762.63,"id":17336468},{"trd":[[4,68.13]],"batb":[[1,3.85,23.47]],"ltp":4.0,"tv":1020.45,"id":11981493}],"tv":5653.71}]}
{"op":"mcm","clk":"991446525","pt":1580550503794,"mc":[{"id":"1.168136214","rc":[{"trd":[[4.1,68.57]],"batb":[[0,4,113.19],[1,3.95,5],[2,3.9,5]],"ltp":4.1,"tv":874.63,"id":12925630}],"tv":5657.71}]}
{"op":"mcm","clk":"991446826","pt":1580550507922,"mc":[{"id":"1.168136214","rc":[{"trd":[[4.2,115.54]],"batb":[[0,4.2,40.51],[1,4.1,2.08],[2,4,113.11]],"batl":[[0,4.3,4.39],[1,4.4,28.95],[2,4.5,5.12]],"ltp":4.2,"tv":901.19,"id":12925630},{"batl":[[0,4,2.15],[1,4.1,9.97],[2,4.2,180]],"ltp":4.0,"tv":1020.45,"id":11981493}],"tv":5684.27}]}
{"op":"mcm","clk":"991447914","pt":1580550522116,"mc":[{"id":"1.168136214","rc":[{"batl":[[0,4.3,6.39]],"ltp":4.2,"tv":901.19,"id":12925630}]}]}
{"op":"mcm","clk":"991447986","pt":1580550523106,"mc":[{"id":"1.168136214","rc":[{"trd":[[4.3,102.23],[4.4,121.67]],"batl":[[0,4.4,18.88],[1,4.5,5.12],[2,4.6,13.4]],"ltp":4.4,"tv":934.12,"id":12925630},{"batb":[[0,3.85,23.47],[1,3.8,3.26],[2,3.75,70]],"ltp":4.0,"tv":1020.45,"id":11981493}],"tv":5717.2}]}
{"op":"mcm","clk":"991448018","pt":1580550523522,"mc":[{"id":"1.168136214","rc":[{"batb":[[2,4,116.11]],"ltp":4.4,"tv":934.12,"id":12925630}]}]}
{"op":"mcm","clk":"991448818","pt":1580550534155,"mc":[{"id":"1.168136214","rc":[{"batl":[[0,4.4,20.88]],"ltp":4.4,"tv":934.12,"id":12925630}]}]}
{"op":"mcm","clk":"991454302","pt":1580550604132,"mc":[{"id":"1.168136214","rc":[{"trd":[[1.95,367.44],[1.96,609.17],[1.97,166.37]],"batl":[[0,1.97,6.28],[1,1.98,2],[2,1.99,24.74]],"ltp":1.97,"tv":3809.67,"id":17336468}],"tv":5764.25}]}
{"op":"mcm","clk":"991457367","pt":1580550647091,"mc":[{"id":"1.168136214","rc":[{"batb":[[0,1.94,106.12]],"ltp":1.97,"tv":3809.67,"id":17336468},{"batb":[[0,3.85,19.47]],"ltp":4.0,"tv":1020.45,"id":11981493}]}]}
{"op":"mcm","clk":"991463196","pt":1580550733144,"mc":[{"id":"1.168136214","rc":[{"batb":[[0,3.85,28.04]],"ltp":4.0,"tv":1020.45,"id":11981493}]}]}
{"op":"mcm","clk":"991464306","pt":1580550749100,"mc":[{"id":"1.168136214","rc":[{"trd":[[1.97,178.92]],"batb":[[0,1.97,3.38],[1,1.95,14.15],[2,1.94,101.12]],"batl":[[0,1.98,13.02],[1,1.99,24.74],[2,2,114]],"ltp":1.97,"tv":3822.23,"id":17336468},{"batb":[[1,3.8,6]],"ltp":4.0,"tv":1020.45,"id":11981493}],"tv":5776.81}]}
{"op":"mcm","clk":"991466469","pt":1580550783142,"mc":[{"id":"1.168136214","rc":[{"trd":[[1.98,417.25]],"batb":[[0,1.98,6.98],[1,1.97,3.38],[2,1.96,9.01]],"batl":[[0,1.99,24.74],[1,2,114],[2,2.02,16.84]],"ltp":1.98,"tv":3848.27,"id":17336468}],"tv":5802.85}]}
{"op":"mcm","clk":"991466976","pt":1580550790153,"mc":[{"id":"1.168136214","rc":[{"batl":[[0,1.99,44.74]],"ltp":1.98,"tv":3848.27,"id":17336468}]}]}
{"op":"mcm","clk":"991467671","pt":1580550801058,"mc":[{"id":"1.168136214","rc":[{"trd":[[1.97,178.96],[1.98,431.21]],"batb":[[0,1.97,3.36],[1,1.96,9.01],[2,1.95,14.15]],"batl":[[0,1.98,17],[1,1.99,44.74],[2,2,114]],"ltp":1.97,"tv":3862.27,"id":17336468}],"tv":5816.85}]}
{"op":"mcm","clk":"991467981","pt":1580550806066,"mc":[{"id":"1.168136214","rc":[{"trd":[[1.97,185.68]],"batb":[[0,1.96,9.01],[1,1.95,14.15],[2,1.94,101.12]],"batl":[[0,1.97,13.64]],"ltp":1.97,"tv":3868.99,"id":17336468}],"tv":5823.57}]}
{"op":"mcm","clk":"991468033","pt":1580550807106,"mc":[{"id":"1.168136214","rc":[{"batb":[[0,1.96,13.16],[1,1.95,5]],"batl":[[1,1.98,3.14],[2,1.99,44.74]],"ltp":1.97,"tv":3868.99,"id":17336468}]}]}
{"op":"mcm","clk":"991468335","pt":1580550811102,"mc":[{"id":"1.168136214","rc":[{"trd":[[1.96,635.49]],"batb":[[0,1.95,5],[1,1.94,101.12],[2,1.93,60]],"batl":[[0,1.98,3.62],[1,1.99,44.74],[2,2,114]],"ltp":1.96,"tv":3895.31,"id":17336468}],"tv":5849.89}]}
{"op":"mcm","clk":"991468557","pt":1580550814089,"mc":[{"id":"1.168136214","rc":[{"batl":[[1,1.99,24.74]],"ltp":1.96,"tv":3895.31,"id":17336468}]}]}
{"op":"mcm","clk":"991468822","pt":1580550818092,"mc":[{"id":"1.168136214","rc":[{"trd":[[1.95,368.4]],"batb":[[0,1.95,4.52]],"batl":[[0,1.98,3.14]],"ltp":1.95,"tv":3896.27,"id":17336468}],"tv":5850.85}]}
{"op":"mcm","clk":"991474120","pt":1580550905077,"mc":[{"id":"1.168136214","rc":[{"batb":[[0,1.96,2.1],[1,1.95,4.52],[2,1.94,101.12]],"ltp":1.95,"tv":3896.27,"id":17336468}]}]}
{"op":"mcm","clk":"991474870","pt":1580550919093,"mc":[{"id":"1.168136214","rc":[{"trd":[[1.98,456.21]],"batb":[[1,1.95,14.54]],"batl":[[0,1.98,6.67]],"ltp":1.98,"tv":3921.27,"id":17336468}],"tv":5875.85}]}
{"op":"mcm","clk":"991475573","pt":1580550930115,"mc":[{"id":"1.168136214","rc":[{"batl":[[0,4.3,9],[1,4.4,20.88],[2,4.5,5.12]],"ltp":4.4,"tv":934.12,"id":12925630},{"batb":[[0,3.85,33.04]],"ltp":4.0,"tv":1020.45,"id":11981493}]}]}
{"op":"mcm","clk":"991476259","pt":1580550942138,"mc":[{"id":"1.168136214","rc":[{"batb":[[1,1.95,74.54]],"ltp":1.98,"tv":3921.27,"id":17336468}]}]}
{"op":"mcm","clk":"991479290","pt":1580550999145,"mc":[{"id":"1.168136214","rc":[{"batl":[[0,4.3,11],[1,4.4,18.88]],"ltp":4.4,"tv":934.12,"id":12925630}]}]}
{"op":"mcm","clk":"991479397","pt":1580551001065,"mc":[{"id":"1.168136214","rc":[{"trd":[[1.98,469.55]],"batb":[[0,1.98,5.83],[1,1.96,2.1],[2,1.95,74.54]],"batl":[[0,1.99,24.74],[1,2,114],[2,2.02,16.84]],"ltp":1.98,"tv":3934.61,"id":17336468}],"tv":5889.19}]}
{"op":"mcm","clk":"991479456","pt":1580551002155,"mc":[{"id":"1.168136214","rc":[{"batb":[[0,4.2,38.51]],"batl":[[0,4.3,17]],"ltp":4.4,"tv":934.12,"id":12925630},{"batb":[[1,1.96,13.32]],"batl":[[0,1.99,22.74]],"ltp":1.98,"tv":3934.61,"id":17336468},{"batb":[[0,3.85,28.04]],"ltp":4.0,"tv":1020.45,"id":11981493}]}]}
{"op":"mcm","clk":"991479818","pt":1580551007958,"mc":[{"id":"1.168136214","rc":[{"batl":[[0,1.99,42.74]],"ltp":1.98,"tv":3934.61,"id":17336468}]}]}
{"op":"mcm","clk":"991480634","pt":1580551019584,"mc":[{"id":"1.168136214","rc":[{"batl":[[0,4.3,28]],"ltp":4.4,"tv":934.12,"id":12925630}]}]}
{"op":"mcm","clk":"991482966","pt":1580551054118,"mc":[{"id":"1.168136214","rc":[{"trd":[[1.99,315.28]],"batl":[[0,1.99,30.24]],"ltp":1.99,"tv":3959.6,"id":17336468}],"tv":5914.18}]}
{"op":"mcm","clk":"991486246","pt":1580551099008,"mc":[{"id":"1.168136214","rc":[{"trd":[[1.99,340.28]],"batb":[[0,1.98,8.1],[1,1.97,11.1],[2,1.96,13.32]],"batl":[[0,1.99,17.74]],"ltp":1.99,"tv":3984.61,"id":17336468}],"tv":5939.18}]}
{"op":"mcm","clk":"991486303","pt":1580551100143,"mc":[{"id":"1.168136214","rc":[{"batb":[[2,1.96,24.16]],"ltp":1.99,"tv":3984.61,"id":17336468}]}]}
{"op":"mcm","clk":"991487290","pt":1580551114855,"mc":[{"id":"1.168136214","rc":[{"trd":[[4.3,108.23]],"batl":[[0,4.3,25]],"ltp":4.3,"tv":940.12,"id":12925630}],"tv":5945.18}]}
{"op":"mcm","clk":"991490649","pt":1580551170999,"mc":[{"id":"1.168136214","rc":[{"batb":[[0,4.2,40.51]],"batl":[[0,4.3,19]],"ltp":4.3,"tv":940.12,"id":12925630},{"trd":[[1.98,485.75]],"batb":[[0,1.96,12.94],[1,1.95,74.54],[2,1.94,101.12]],"batl":[[0,1.98,49.9],[1,1.99,20.74],[2,2,114]],"ltp":1.98,"tv":4000.81,"id":17336468},{"batb":[[0,3.85,33.04]],"ltp":4.0,"tv":1020.45,"id":11981493}],"tv":5961.38}]}
{"op":"mcm","clk":"991492626","pt":1580551200953,"mc":[{"id":"1.168136214","rc":[{"trd":[[4.2,119.54]],"batb":[[0,4.2,38.51]],"ltp":4.2,"tv":944.12,"id":12925630}],"tv":5965.38}]}
{"op":"mcm","clk":"991493060","pt":1580551205027,"mc":[{"id":"1.168136214","rc":[{"batb":[[2,4,113.11]],"ltp":4.2,"tv":944.12,"id":12925630}]}]}
{"op":"mcm","clk":"991493945","pt":1580551216065,"mc":[{"id":"1.168136214","rc":[{"batb":[[0,1.97,7.08],[1,1.96,23.94],[2,1.95,74.54]],"batl":[[0,1.98,46.9]],"ltp":1.98,"tv":4000.81,"id":17336468}]}]}
{"op":"mcm","clk":"991495157","pt":1580551234105,"mc":[{"id":"1.168136214","rc":[{"trd":[[4.2,196.56]],"batb":[[0,4.1,2.08],[1,4,113.11],[2,3.95,5]],"batl":[[0,4.3,25]],"ltp":4.2,"tv":1021.13,"id":12925630}],"tv":6042.4}]}
{"op":"mcm","clk":"991495849","pt":1580551242803,"mc":[{"id":"1.168136214","rc":[{"batb":[[0,4.1,18.88]],"ltp":4.2,"tv":1021.13,"id":12925630}]}]}
{"op":"mcm","clk":"991496304","pt":1580551249120,"mc":[{"id":"1.168136214","rc":[{"batb":[[0,4.1,2.08],[1,4,129.91]],"ltp":4.2,"tv":1021.13,"id":12925630}]}]}
{"op":"mcm","clk":"991497160","pt":1580551260138,"mc":[{"id":"1.168136214","rc":[{"trd":[[3.85,18.57]],"batb":[[0,3.85,28.03]],"ltp":3.85,"tv":1030.45,"id":11981493}],"tv":6052.4}]}
{"op":"mcm","clk":"991497829","pt":1580551269071,"mc":[{"id":"1.168136214","rc":[{"batl":[[0,4.3,19]],"ltp":4.2,"tv":1021.13,"id":12925630}]}]}
{"op":"mcm","clk":"991499245","pt":1580551285099,"mc":[{"id":"1.168136214","rc":[{"trd":[[4.1,74.57]],"batb":[[0,4.1,1.21]],"ltp":4.1,"tv":1027.13,"id":12925630},{"batl":[[0,1.98,51.9]],"ltp":1.98,"tv":4000.81,"id":17336468}],"tv":6058.4}]}
{"op":"mcm","clk":"991499957","pt":1580551294976,"mc":[{"id":"1.168136214","rc":[{"batl":[[1,4.1,14.97]],"ltp":3.85,"tv":1030.45,"id":11981493}]}]}
{"op":"mcm","clk":"991500795","pt":1580551303085,"mc":[{"id":"1.168136214","rc":[{"trd":[[4.3,112.23]],"batl":[[0,4.3,17]],"ltp":4.3,"tv":1031.13,"id":12925630}],"tv":6062.4}]}
{"op":"mcm","clk":"991501061","pt":1580551306011,"mc":[{"id":"1.168136214","rc":[{"batb":[[1,4,132.91]],"ltp":4.3,"tv":1031.13,"id":12925630}]}]}
{"op":"mcm","clk":"991502319","pt":1580551322958,"mc":[{"id":"1.168136214","rc":[{"batb":[[0,4,130.91],[1,3.95,5],[2,3.9,5]],"ltp":4.3,"tv":1031.13,"id":12925630}]}]}
{"op":"mcm","clk":"991502407","pt":1580551324051,"mc":[{"id":"1.168136214","rc":[{"batl":[[0,4.3,19]],"ltp":4.3,"tv":1031.13,"id":12925630},{"batl":[[1,4.1,16.97]],"ltp":3.85,"tv":1030.45,"id":11981493}]}]}
{"op":"mcm","clk":"991504490","pt":1580551351090,"mc":[{"id":"1.168136214","rc":[{"batl":[[1,4.1,36.97]],"ltp":3.85,"tv":1030.45,"id":11981493}]}]}
{"op":"mcm","clk":"991514602","pt":1580551354114,"mc":[{"id":"1.168136214","rc":[{"trd":[[1.98,537.75]],"batl":[[0,1.98,25.9]],"ltp":1.98,"tv":4052.81,"id":17336468},{"batb":[[0,3.85,23.03],[2,3.75,82]],"batl":[[0,3.95,14],[1,4,2.15],[2,4.1,36.97]],"ltp":3.85,"tv":1030.45,"id":11981493}],"tv":6114.4}]}
{"op":"mcm","clk":"991514696","pt":1580551355085,"mc":[{"id":"1.168136214","rc":[{"batb":[[0,3.85,28.03],[2,3.75,76]],"batl":[[0,3.9,10],[1,3.95,10],[2,4,12.15]],"ltp":3.85,"tv":1030.45,"id":11981493}]}]}
{"op":"mcm","clk":"991514848","pt":1580551357021,"mc":[{"id":"1.168136214","rc":[{"trd":[[3.85,38.58]],"batb":[[0,3.85,18.03]],"ltp":3.85,"tv":1050.45,"id":11981493}],"tv":6134.4}]}
{"op":"mcm","clk":"991515429","pt":1580551364898,"mc":[{"id":"1.168136214","rc":[{"trd":[[1.97,191.68]],"batb":[[0,1.97,4.08]],"ltp":1.97,"tv":4058.81,"id":17336468}],"tv":6140.4}]}
{"op":"mcm","clk":"991515647","pt":1580551368033,"mc":[{"id":"1.168136214","rc":[{"batb":[[0,4.2,20],[1,4,130.91],[2,3.95,5]],"ltp":4.3,"tv":1031.13,"id":12925630},{"batl":[[1,3.95,12]],"ltp":3.85,"tv":1050.45,"id":11981493}]}]}
{"op":"mcm","clk":"991515942","pt":1580551371127,"mc":[{"id":"1.168136214","rc":[{"batb":[[1,4.1,6],[2,4,130.91]],"ltp":4.3,"tv":1031.13,"id":12925630},{"batl":[[1,1.99,23.96]],"ltp":1.97,"tv":4058.81,"id":17336468}]}]}
{"op":"mcm","clk":"991517041","pt":1580551383094,"mc":[{"id":"1.168136214","rc":[{"trd":[[4.3,151.23]],"batb":[[0,4.2,2.01],[1,4.1,8],[2,4,132.91]],"batl":[[0,4.4,18.88],[1,4.5,5.12],[2,4.6,13.4]],"ltp":4.3,"tv":1070.13,"id":12925630},{"trd":[[1.96,635.69],[1.97,197.67]],"batb":[[0,1.97,13.11],[1,1.96,12.84]],"ltp":1.96,"tv":4064.99,"id":17336468},{"trd":[[3.85,39.7]],"batb":[[0,3.85,16.91]],"ltp":3.85,"tv":1051.57,"id":11981493}],"tv":6186.71}]}
{"op":"mcm","clk":"991518629","pt":1580551399001,"mc":[{"id":"1.168136214","rc":[{"batl":[[1,1.99,20.74]],"ltp":1.96,"tv":4064.99,"id":17336468}]}]}
{"op":"mcm","clk":"991518988","pt":1580551403017,"mc":[{"id":"1.168136214","rc":[{"trd":[[3.85,73.52]],"batb":[[0,3.8,6],[1,3.75,76],[2,3.7,37]],"batl":[[0,3.85,3.09],[1,3.9,10],[2,3.95,12]],"ltp":3.85,"tv":1085.39,"id":11981493}],"tv":6220.53}]}
{"op":"mcm","clk":"991519073","pt":1580551404114,"mc":[{"id":"1.168136214","rc":[{"batl":[[0,4.4,20.88]],"ltp":4.3,"tv":1070.13,"id":12925630},{"batb":[[1,1.96,23.84]],"ltp":1.96,"tv":4064.99,"id":17336468},{"batb":[[0,3.8,26]],"batl":[[1,3.9,12]],"ltp":3.85,"tv":1085.39,"id":11981493}]}]}
{"op":"mcm","clk":"991519865","pt":1580551413037,"mc":[{"id":"1.168136214","rc":[{"trd":[[4.2,201.57]],"batb":[[0,4.2,2.18]],"ltp":4.2,"tv":1075.14,"id":12925630},{"trd":[[1.98,539.85]],"batl":[[0,1.98,23.8]],"ltp":1.98,"tv":4067.09,"id":17336468},{"trd":[[3.85,74.6]],"batl":[[0,3.85,2.01]],"ltp":3.85,"tv":1086.47,"id":11981493}],"tv":6228.72}]}
{"op":"mcm","clk":"991520140","pt":1580551416137,"mc":[{"id":"1.168136214","rc":[{"batb":[[2,4,129.91]],"ltp":4.2,"tv":1075.14,"id":12925630}]}]}
{"op":"mcm","clk":"991521076","pt":1580551424094,"mc":[{"id":"1.168136214","rc":[{"trd":[[4.2,206.75]],"batb":[[0,4.2,2]],"ltp":4.2,"tv":1080.32,"id":12925630},{"trd":[[1.98,541.59]],"batl":[[0,1.98,22.06]],"ltp":1.98,"tv":4068.83,"id":17336468},{"trd":[[3.85,77.73]],"batl":[[0,3.9,12],[1,3.95,12],[2,4,12.15]],"ltp":3.85,"tv":1089.6,"id":11981493}],"tv":6238.77}]}
{"op":"mcm","clk":"991521186","pt":1580551425155,"mc":[{"id":"1.168136214","rc":[{"batl":[[0,3.9,10]],"ltp":3.85,"tv":1089.6,"id":11981493}]}]}
{"op":"mcm","clk":"991521476","pt":1580551427991,"mc":[{"id":"1.168136214","rc":[{"batl":[[0,1.98,29.35]],"ltp":1.98,"tv":4068.83,"id":17336468}]}]}
{"op":"mcm","clk":"991523369","pt":1580551442006,"mc":[{"id":"1.168136214","rc":[{"trd":[[4.2,210.75]],"ltp":4.2,"tv":1084.32,"id":12925630}],"tv":6242.77}]}
{"op":"mcm","clk":"991524531","pt":1580551452665,"mc":[{"id":"1.168136214","rc":[{"trd":[[3.8,70.35]],"batb":[[0,3.8,21.77]],"ltp":3.8,"tv":1106.06,"id":11981493}],"tv":6259.23}]}
{"op":"mcm","clk":"991524714","pt":1580551454146,"mc":[{"id":"1.168136214","rc":[{"trd":[[4.2,214.75]],"batb":[[0,4.1,8],[1,4,129.91],[2,3.95,5]],"ltp":4.2,"tv":1088.32,"id":12925630}],"tv":6263.23}]}
{"op":"mcm","clk":"991524790","pt":1580551454635,"mc":[{"id":"1.168136214","rc":[{"batb":[[0,4.2,2],[1,4.1,8],[2,4,129.91]],"ltp":4.2,"tv":1088.32,"id":12925630}]}]}
{"op":"mcm","clk":"991525975","pt":1580551464067,"mc":[{"id":"1.168136214","rc":[{"trd":[[4.2,218.75]],"batb":[[0,4.1,8],[1,4,129.91],[2,3.95,5]],"batl":[[0,4.2,1],[1,4.4,20.88],[2,4.5,5.12]],"ltp":4.2,"tv":1092.32,"id":12925630}],"tv":6267.23}]}
{"op":"mcm","clk":"991526088","pt":1580551465069,"mc":[{"id":"1.168136214","rc":[{"batb":[[0,4.1,6],[1,4,127.91]],"batl":[[1,4.3,5.13],[2,4.4,20.88]],"ltp":4.2,"tv":1092.32,"id":12925630},{"batl":[[1,1.99,17.74]],"ltp":1.98,"tv":4068.83,"id":17336468},{"batb":[[0,3.85,4.13],[1,3.8,21.77],[2,3.75,76]],"ltp":3.8,"tv":1106.06,"id":11981493}]}]}
{"op":"mcm","clk":"991526293","pt":1580551467147,"mc":[{"id":"1.168136214","rc":[{"batl":[[0,4.2,6]],"ltp":4.2,"tv":1092.32,"id":12925630}]}]}
{"op":"mcm","clk":"991526382","pt":1580551468000,"mc":[{"id":"1.168136214","rc":[{"trd":[[4.2,223.99]],"batl":[[0,4.2,3.38]],"ltp":4.2,"tv":1097.57,"id":12925630},{"batb":[[0,1.97,18.7]],"ltp":1.98,"tv":4068.83,"id":17336468},{"batb":[[0,3.85,6.99]],"ltp":3.8,"tv":1106.06,"id":11981493}],"tv":6272.47}]}
{"op":"mcm","clk":"991526728","pt":1580551471076,"mc":[{"id":"1.168136214","rc":[{"batl":[[0,4.2,2]],"ltp":4.2,"tv":1097.57,"id":12925630}]}]}
{"op":"mcm","clk":"991526985","pt":1580551473099,"mc":[{"id":"1.168136214","rc":[{"trd":[[4.1,78.57]],"batb":[[0,4.1,4]],"batl":[[2,4.4,18.88]],"ltp":4.1,"tv":1101.57,"id":12925630}],"tv":6276.47}]}
{"op":"mcm","clk":"991527269","pt":1580551475108,"mc":[{"id":"1.168136214","rc":[{"trd":[[1.98,581.59]],"batl":[[0,1.98,9.35]],"ltp":1.98,"tv":4108.83,"id":17336468}],"tv":6316.47}]}
{"op":"mcm","clk":"991528650","pt":1580551483100,"mc":[{"id":"1.168136214","rc":[{"batl":[[0,4.2,4]],"ltp":4.1,"tv":1101.57,"id":12925630}]}]}
{"op":"mcm","clk":"991529917","pt":1580551492646,"mc":[{"id":"1.168136214","rc":[{"trd":[[4.1,82.57]],"batb":[[0,4.1,2]],"ltp":4.1,"tv":1105.57,"id":12925630}],"tv":6320.47}]}
{"op":"mcm","clk":"991530119","pt":1580551494120,"mc":[{"id":"1.168136214","rc":[{"trd":[[3.9,79.91]],"batl":[[0,3.9,6.12]],"ltp":3.9,"tv":1113.82,"id":11981493}],"tv":6328.23}]}
{"op":"mcm","clk":"991530771","pt":1580551499152,"mc":[{"id":"1.168136214","rc":[{"trd":[[4.1,92.38]],"batb":[[0,4,127.91],[1,3.95,5],[2,3.9,5]],"batl":[[0,4.1,42.84],[1,4.2,9],[2,4.3,5.13]],"ltp":4.1,"tv":1115.38,"id":12925630},{"trd":[[1.98,590.94],[1.99,342.96]],"batb":[[0,1.98,2.69],[1,1.97,27.7],[2,1.96,23.84]],"batl":[[0,1.99,15.06],[1,2,111],[2,2.02,18.84]],"ltp":1.99,"tv":4120.86,"id":17336468},{"trd":[[3.9,86.03]],"batl":[[0,3.95,10],[1,4,12.15],[2,4.1,34.97]],"ltp":3.9,"tv":1119.94,"id":11981493}],"tv":6356.19}]}
{"op":"mcm","clk":"991531442","pt":1580551504142,"mc":[{"id":"1.168136214","rc":[{"batl":[[0,4.1,48.84],[1,4.2,7]],"ltp":4.1,"tv":1115.38,"id":12925630}]}]}
{"op":"mcm","clk":"991532600","pt":1580551512156,"mc":[{"id":"1.168136214","rc":[{"batl":[[0,4.1,50.84]],"ltp":4.1,"tv":1115.38,"id":12925630}]}]}
{"op":"mcm","clk":"991533648","pt":1580551519945,"mc":[{"id":"1.168136214","rc":[{"batl":[[0,3.95,14]],"ltp":3.9,"tv":1119.94,"id":11981493}]}]}
{"op":"mcm","clk":"991533778","pt":1580551521123,"mc":[{"id":"1.168136214","rc":[{"trd":[[4.1,100.38]],"batl":[[0,4.1,46.84]],"ltp":4.1,"tv":1123.37,"id":12925630},{"batl":[[0,1.99,44.06]],"ltp":1.99,"tv":4120.86,"id":17336468}],"tv":6364.18}]}
{"op":"mcm","clk":"991533908","pt":1580551522132,"mc":[{"id":"1.168136214","rc":[{"trd":[[4.1,101.4]],"batl":[[0,4.1,46.33]],"ltp":4.1,"tv":1124.4,"id":12925630}],"tv":6365.21}]}
{"op":"mcm","clk":"991534432","pt":1580551525943,"mc":[{"id":"1.168136214","rc":[{"trd":[[4.1,194.1],[4.2,237.99],[4.3,154.37]],"batb":[[0,4.1,2.14],[1,4,129.91],[2,3.95,7]],"batl":[[0,4.3,19.94],[1,4.4,18.88],[2,4.5,5.12]],"ltp":4.3,"tv":1234.24,"id":12925630},{"batl":[[1,2,113]],"ltp":1.99,"tv":4120.86,"id":17336468},{"batb":[[2,3.75,73]],"batl":[[0,3.95,16]],"ltp":3.9,"tv":1119.94,"id":11981493}],"tv":6475.05}]}
{"op":"mcm","clk":"991534708","pt":1580551528140,"mc":[{"id":"1.168136214","rc":[{"batl":[[0,4.3,3.56]],"ltp":4.3,"tv":1234.24,"id":12925630}]}]}
{"op":"mcm","clk":"991535163","pt":1580551531764,"mc":[{"id":"1.168136214","rc":[{"batl":[[0,4.3,5.56]],"ltp":4.3,"tv":1234.24,"id":12925630}]}]}
{"op":"mcm","clk":"991535486","pt":1580551534150,"mc":[{"id":"1.168136214","rc":[{"batb":[[1,4,132.91]],"ltp":4.3,"tv":1234.24,"id":12925630},{"batl":[[1,4,14.15],[2,4.1,32.97]],"ltp":3.9,"tv":1119.94,"id":11981493}]}]}
{"op":"mcm","clk":"991540115","pt":1580551575694,"mc":[{"id":"1.168136214","rc":[{"batb":[[1,3.8,32.77]],"ltp":3.9,"tv":1119.94,"id":11981493}]}]}
{"op":"mcm","clk":"991540412","pt":1580551579079,"mc":[{"id":"1.168136214","rc":[{"batb":[[0,4.2,6],[1,4.1,2.14],[2,4,132.91]],"ltp":4.3,"tv":1234.24,"id":12925630},{"batb":[[0,1.98,32.77]],"ltp":1.99,"tv":4120.86,"id":17336468},{"batb":[[0,3.85,2.86]],"ltp":3.9,"tv":1119.94,"id":11981493}]}]}
{"op":"mcm","clk":"991542949","pt":1580551602021,"mc":[{"id":"1.168136214","rc":[{"batl":[[0,4.3,8.09]],"ltp":4.3,"tv":1234.24,"id":12925630}]}]}
{"op":"mcm","clk":"991543434","pt":1580551606116,"mc":[{"id":"1.168136214","rc":[{"trd":[[4.2,243.06]],"batb":[[0,4.2,3.47]],"batl":[[0,4.3,5.56]],"ltp":4.2,"tv":1239.3,"id":12925630}],"tv":6480.11}]}
{"op":"mcm","clk":"991543555","pt":1580551607130,"mc":[{"id":"1.168136214","rc":[{"batb":[[2,4,129.91]],"ltp":4.2,"tv":1239.3,"id":12925630}]}]}
{"op":"mcm","clk":"991543662","pt":1580551608152,"mc":[{"id":"1.168136214","rc":[{"batl":[[0,1.99,29]],"ltp":1.99,"tv":4120.86,"id":17336468}]}]}
{"op":"mcm","clk":"991544143","pt":1580551612143,"mc":[{"id":"1.168136214","rc":[{"batl":[[0,4.3,19.56]],"ltp":4.2,"tv":1239.3,"id":12925630}]}]}
{"op":"mcm","clk":"991546979","pt":1580551636110,"mc":[{"id":"1.168136214","rc":[{"trd":[[1.99,400.96]],"batb":[[0,1.99,121],[1,1.98,41.77],[2,1.97,27.7]],"batl":[[0,2,111],[1,2.02,18.84],[2,2.06,8]],"ltp":1.99,"tv":4178.86,"id":17336468},{"batl":[[0,3.9,2.08],[1,3.95,16],[2,4,14.15]],"ltp":3.9,"tv":1119.94,"id":11981493}],"tv":6538.11}]}
{"op":"mcm","clk":"991547081","pt":1580551637028,"mc":[{"id":"1.168136214","rc":[{"batb":[[0,1.99,131.68]],"batl":[[1,2.02,53.75]],"ltp":1.99,"tv":4178.86,"id":17336468}]}]}
{"op":"mcm","clk":"991547210","pt":1580551637914,"mc":[{"id":"1.168136214","rc":[{"batl":[[1,2.02,71.2]],"ltp":1.99,"tv":4178.86,"id":17336468}]}]}
{"op":"mcm","clk":"991547557","pt":1580551641130,"mc":[{"id":"1.168136214","rc":[{"batl":[[1,2.02,73.2]],"ltp":1.99,"tv":4178.86,"id":17336468}]}]}
{"op":"mcm","clk":"991548642","pt":1580551650108,"mc":[{"id":"1.168136214","rc":[{"trd":[[4.2,245.68]],"batb":[[0,4.1,2.99],[1,4,129.91],[2,3.95,7]],"ltp":4.2,"tv":1241.92,"id":12925630},{"trd":[[2,1285.17]],"batb":[[0,2,4.49],[1,1.99,10.68],[2,1.98,41.77]],"batl":[[0,2.02,73.2],[1,2.04,2.16]],"ltp":2.0,"tv":4406.37,"id":17336468},{"trd":[[3.85,80.59]],"batb":[[0,3.8,32.77],[1,3.75,73],[2,3.7,37]],"ltp":3.85,"tv":1122.8,"id":11981493}],"tv":6771.11}]}
{"op":"mcm","clk":"991548724","pt":1580551650906,"mc":[{"id":"1.168136214","rc":[{"batb":[[1,1.98,41.77],[2,1.97,27.7]],"ltp":2.0,"tv":4406.37,"id":17336468}]}]}
{"op":"mcm","clk":"991548831","pt":1580551651832,"mc":[{"id":"1.168136214","rc":[{"batl":[[1,2.04,19.52]],"ltp":2.0,"tv":4406.37,"id":17336468}]}]}
{"op":"mcm","clk":"991550797","pt":1580551668097,"mc":[{"id":"1.168136214","rc":[{"batb":[[2,1.97,38.49]],"ltp":2.0,"tv":4406.37,"id":17336468}]}]}
{"op":"mcm","clk":"991552408","pt":1580551682013,"mc":[{"id":"1.168136214","rc":[{"trd":[[2,1289.17]],"batb":[[0,2,2.49]],"batl":[[0,2.02,71.2]],"ltp":2.0,"tv":4410.37,"id":17336468}],"tv":6775.11}]}
{"op":"mcm","clk":"991553463","pt":1580551691954,"mc":[{"id":"1.168136214","rc":[{"trd":[[2.02,369.58]],"batl":[[0,2.02,28.2]],"ltp":2.02,"tv":4500.37,"id":17336468}],"tv":6865.11}]}
{"op":"mcm","clk":"991555753","pt":1580551712092,"mc":[{"id":"1.168136214","rc":[{"batb":[[1,1.99,9.06],[2,1.98,41.77]],"ltp":2.02,"tv":4500.37,"id":17336468}]}]}
{"op":"mcm","clk":"991563332","pt":1580551776967,"mc":[{"id":"1.168136214","rc":[{"trd":[[3.8,90.35]],"batb":[[0,3.8,22.77]],"ltp":3.8,"tv":1142.8,"id":11981493}],"tv":6885.11}]}
{"op":"mcm","clk":"991563795","pt":1580551781083,"mc":[{"id":"1.168136214","rc":[{"batl":[[0,4.3,5.56]],"ltp":4.2,"tv":1241.92,"id":12925630}]}]}
{"op":"mcm","clk":"991566762","pt":1580551806095,"mc":[{"id":"1.168136214","rc":[{"batb":[[0,4,128.76],[1,3.95,5],[2,3.9,5]],"ltp":4.2,"tv":1241.92,"id":12925630}]}]}
{"op":"mcm","clk":"991567804","pt":1580551814138,"mc":[{"id":"1.168136214","rc":[{"batb":[[0,4.1,6.85],[1,4,127.91],[2,3.95,5]],"ltp":4.2,"tv":1241.92,"id":12925630}]}]}
{"op":"mcm","clk":"991569972","pt":1580551832076,"mc":[{"id":"1.168136214","rc":[{"trd":[[2.02,389.58]],"batl":[[0,2.02,35.56]],"ltp":2.02,"tv":4520.37,"id":17336468}],"tv":6905.11}]}
{"op":"mcm","clk":"991571099","pt":1580551841072,"mc":[{"id":"1.168136214","rc":[{"trd":[[4.3,170.84],[4.4,135.85]],"batb":[[0,4.1,8.85],[1,4,129.91]],"batl":[[0,4.3,4],[1,4.4,11.79]],"ltp":4.4,"tv":1272.57,"id":12925630},{"trd":[[1.99,410.02],[2,1291.66]],"batb":[[0,1.98,41.77],[1,1.97,38.49],[2,1.96,13]],"ltp":1.99,"tv":4531.92,"id":17336468},{"trd":[[3.8,96.4]],"batb":[[0,3.8,16.72]],"ltp":3.8,"tv":1148.85,"id":11981493}],"tv":6953.36}]}
{"op":"mcm","clk":"991571170","pt":1580551841753,"mc":[{"id":"1.168136214","rc":[{"batb":[[0,4.2,3.07],[1,4.1,8],[2,4,129.91]],"batl":[[0,4.4,11.79],[1,4.5,5.12],[2,4.6,13.4]],"ltp":4.4,"tv":1272.57,"id":12925630},{"batb":[[0,1.98,32.77]],"batl":[[0,2,2.22],[1,2.02,35.56],[2,2.04,19.52]],"ltp":1.99,"tv":4531.92,"id":17336468}]}]}
{"op":"mcm","clk":"991571324","pt":1580551843089,"mc":[{"id":"1.168136214","rc":[{"batb":[[1,1.97,27.7]],"ltp":1.99,"tv":4531.92,"id":17336468}]}]}
{"op":"mcm","clk":"991571445","pt":1580551843991,"mc":[{"id":"1.168136214","rc":[{"batb":[[2,1.96,23.84]],"ltp":1.99,"tv":4531.92,"id":17336468}]}]}
{"op":"mcm","clk":"991572263","pt":1580551851007,"mc":[{"id":"1.168136214","rc":[{"batb":[[2,4,132.91]],"ltp":4.4,"tv":1272.57,"id":12925630}]}]}
{"op":"mcm","clk":"991572754","pt":1580551855017,"mc":[{"id":"1.168136214","rc":[{"trd":[[3.8,106.4]],"batb":[[0,3.8,11.72]],"ltp":3.8,"tv":1158.85,"id":11981493}],"tv":6963.36}]}
{"op":"mcm","clk":"991573927","pt":1580551864143,"mc":[{"id":"1.168136214","rc":[{"batb":[[0,4.1,8.85],[1,4,132.91],[2,3.95,5]],"batl":[[0,4.3,6.02],[1,4.4,11.79],[2,4.5,5.12]],"ltp":4.4,"tv":1272.57,"id":12925630},{"batl":[[0,2,4.22]],"ltp":1.99,"tv":4531.92,"id":17336468}]}]}
{"op":"mcm","clk":"991574308","pt":1580551867054,"mc":[{"id":"1.168136214","rc":[{"trd":[[4.2,246.53]],"batb":[[0,4.1,8]],"ltp":4.2,"tv":1273.42,"id":12925630},{"trd":[[1.98,592.74]],"batb":[[0,1.98,30.97]],"ltp":1.98,"tv":4533.72,"id":17336468},{"trd":[[3.9,91.11]],"batl":[[0,3.95,16],[1,4,14.15],[2,4.1,32.97]],"ltp":3.9,"tv":1163.93,"id":11981493}],"tv":6971.09}]}
{"op":"mcm","clk":"991574427","pt":1580551868062,"mc":[{"id":"1.168136214","rc":[{"batb":[[0,4.2,2.03],[1,4.1,8],[2,4,132.91]],"ltp":4.2,"tv":1273.42,"id":12925630},{"batb":[[0,3.8,14]],"batl":[[0,3.9,2],[1,3.95,16],[2,4,14.15]],"ltp":3.9,"tv":1163.93,"id":11981493}]}]}
{"op":"mcm","clk":"991574672","pt":1580551870039,"mc":[{"id":"1.168136214","rc":[{"batl":[[0,4.3,8.02]],"ltp":4.2,"tv":1273.42,"id":12925630}]}]}
{"op":"mcm","clk":"991575521","pt":1580551877145,"mc":[{"id":"1.168136214","rc":[{"batb":[[2,4,129.91]],"ltp":4.2,"tv":1273.42,"id":12925630}]}]}
{"op":"mcm","clk":"991582338","pt":1580551928077,"mc":[{"id":"1.168136214","rc":[{"batb":[[0,4.1,8],[1,4,129.91],[2,3.95,5]],"ltp":4.2,"tv":1273.42,"id":12925630},{"batb":[[0,1.98,138.97]],"batl":[[0,2,2]],"ltp":1.98,"tv":4533.72,"id":17336468}]}]}
{"op":"mcm","clk":"991582467","pt":1580551929085,"mc":[{"id":"1.168136214","rc":[{"batb":[[0,1.99,10.68],[1,1.98,138.97],[2,1.97,27.7]],"ltp":1.98,"tv":4533.72,"id":17336468}]}]}
{"op":"mcm","clk":"991583426","pt":1580551936098,"mc":[{"id":"1.168136214","rc":[{"batl":[[0,4.3,22.02]],"ltp":4.2,"tv":1273.42,"id":12925630},{"batb":[[1,1.98,138.08]],"ltp":1.98,"tv":4533.72,"id":17336468}]}]}
{"op":"mcm","clk":"991583578","pt":1580551937033,"mc":[{"id":"1.168136214","rc":[{"trd":[[2,1295.66]],"batb":[[0,1.99,18.68]],"batl":[[0,2.02,35.56],[1,2.04,19.52],[2,2.06,8]],"ltp":2.0,"tv":4537.72,"id":17336468}],"tv":6975.09}]}
{"op":"mcm","clk":"991589424","pt":1580551987070,"mc":[{"id":"1.168136214","rc":[{"trd":[[1.99,447.38]],"batb":[[0,1.98,130.08],[1,1.97,27.7],[2,1.96,13]],"batl":[[0,1.99,25.32],[1,2.02,35.56],[2,2.04,19.52]],"ltp":1.99,"tv":4575.08,"id":17336468},{"batl":[[0,3.95,16],[1,4,14.15],[2,4.1,32.97]],"ltp":3.9,"tv":1163.93,"id":11981493}],"tv":7012.45}]}
{"op":"mcm","clk":"991590039","pt":1580551991972,"mc":[{"id":"1.168136214","rc":[{"batb":[[0,1.98,138.08]],"ltp":1.99,"tv":4575.08,"id":17336468},{"trd":[[3.85,84.59]],"batb":[[0,3.85,2],[1,3.8,14],[2,3.75,73]],"batl":[[0,3.9,2.06],[1,3.95,16],[2,4,14.15]],"ltp":3.85,"tv":1167.93,"id":11981493}],"tv":7016.45}]}
{"op":"mcm","clk":"991590171","pt":1580551993080,"mc":[{"id":"1.168136214","rc":[{"batb":[[0,1.98,130.08]],"ltp":1.99,"tv":4575.08,"id":17336468},{"batl":[[0,3.95,16],[1,4,14.15],[2,4.1,32.97]],"ltp":3.85,"tv":1167.93,"id":11981493}]}]}
{"op":"mcm","clk":"991590496","pt":1580551995960,"mc":[{"id":"1.168136214","rc":[{"trd":[[1.99,471.38]],"batl":[[0,1.99,13.32]],"ltp":1.99,"tv":4599.08,"id":17336468}],"tv":7040.45}]}
{"op":"mcm","clk":"991590599","pt":1580551996986,"mc":[{"id":"1.168136214","rc":[{"batl":[[1,2,11.94],[2,2.02,35.56]],"ltp":1.99,"tv":4599.08,"id":17336468}]}]}
{"op":"mcm","clk":"991592256","pt":1580552010813,"mc":[{"id":"1.168136214","rc":[{"batb":[[0,1.98,135.08]],"ltp":1.99,"tv":4599.08,"id":17336468}]}]}
{"op":"mcm","clk":"991593246","pt":1580552019140,"mc":[{"id":"1.168136214","rc":[{"batl":[[2,4.1,27.97]],"ltp":3.85,"tv":1167.93,"id":11981493}]}]}
{"op":"mcm","clk":"991594332","pt":1580552028116,"mc":[{"id":"1.168136214","rc":[{"trd":[[1.98,596.74]],"batb":[[0,1.98,133.08]],"ltp":1.98,"tv":4603.08,"id":17336468}],"tv":7044.45}]}
{"op":"mcm","clk":"991599920","pt":1580552075934,"mc":[{"id":"1.168136214","rc":[{"trd":[[4.3,186.1]],"batl":[[0,4.3,18.39]],"ltp":4.3,"tv":1288.68,"id":12925630},{"batl":[[1,2,13.94]],"ltp":1.98,"tv":4603.08,"id":17336468}],"tv":7059.71}]}
{"op":"mcm","clk":"991601260","pt":1580552086492,"mc":[{"id":"1.168136214","rc":[{"batb":[[1,4,132.91]],"ltp":4.3,"tv":1288.68,"id":12925630}]}]}
{"op":"mcm","clk":"991603758","pt":1580552104783,"mc":[{"id":"1.168136214","rc":[{"trd":[[1.98,600.74]],"batb":[[0,1.98,131.08]],"ltp":1.98,"tv":4607.08,"id":17336468}],"tv":7063.71}]}
{"op":"mcm","clk":"991606128","pt":1580552123064,"mc":[{"id":"1.168136214","rc":[{"trd":[[3.85,88.59]],"batb":[[0,3.8,14],[1,3.75,73],[2,3.7,37]],"batl":[[0,3.85,18],[1,3.95,16],[2,4,14.15]],"ltp":3.85,"tv":1171.93,"id":11981493}],"tv":7067.71}]}
{"op":"mcm","clk":"991606247","pt":1580552124130,"mc":[{"id":"1.168136214","rc":[{"batb":[[0,1.98,139.08]],"batl":[[1,2,11.94]],"ltp":1.98,"tv":4607.08,"id":17336468},{"batl":[[1,3.9,2.12],[2,3.95,16]],"ltp":3.85,"tv":1171.93,"id":11981493}]}]}
{"op":"mcm","clk":"991607483","pt":1580552134257,"mc":[{"id":"1.168136214","rc":[{"trd":[[1.98,621.01]],"batb":[[0,1.98,128.94]],"ltp":1.98,"tv":4627.35,"id":17336468}],"tv":7087.98}]}
{"op":"mcm","clk":"991607802","pt":1580552137050,"mc":[{"id":"1.168136214","rc":[{"trd":[[1.98,629.11]],"batb":[[0,1.98,124.89]],"ltp":1.98,"tv":4635.45,"id":17336468}],"tv":7096.08}]}
{"op":"mcm","clk":"991608372","pt":1580552141848,"mc":[{"id":"1.168136214","rc":[{"trd":[[1.98,709.11],[1.99,489.38]],"batb":[[0,1.98,84.89]],"batl":[[0,1.99,4.32]],"ltp":1.99,"tv":4733.45,"id":17336468}],"tv":7194.08}]}
{"op":"mcm","clk":"991608807","pt":1580552146053,"mc":[{"id":"1.168136214","rc":[{"trd":[[1.99,498.02],[2,1297.02]],"batl":[[0,2,11.26],[1,2.02,35.56],[2,2.04,19.52]],"ltp":2.0,"tv":4743.45,"id":17336468}],"tv":7204.08}]}
{"op":"mcm","clk":"991613829","pt":1580552188100,"mc":[{"id":"1.168136214","rc":[{"trd":[[4.3,213.3]],"batb":[[0,4.2,15.67],[1,4.1,8],[2,4,132.91]],"batl":[[0,4.3,4.79]],"ltp":4.3,"tv":1315.88,"id":12925630},{"batb":[[0,1.98,76.89]],"batl":[[0,2,13.26]],"ltp":2.0,"tv":4743.45,"id":17336468},{"batb":[[0,3.8,11]],"ltp":3.85,"tv":1171.93,"id":11981493}],"tv":7231.28}]}
{"op":"mcm","clk":"991614720","pt":1580552195001,"mc":[{"id":"1.168136214","rc":[{"batl":[[0,4.3,6.79]],"ltp":4.3,"tv":1315.88,"id":12925630},{"trd":[[3.85,108.59]],"batl":[[0,3.85,8]],"ltp":3.85,"tv":1191.93,"id":11981493}],"tv":7251.28}]}
{"op":"mcm","clk":"991615743","pt":1580552202995,"mc":[{"id":"1.168136214","rc":[{"trd":[[1.98,789.11]],"batb":[[0,1.98,36.89]],"ltp":1.98,"tv":4823.45,"id":17336468}],"tv":7331.28}]}
{"op":"mcm","clk":"991616330","pt":1580552208119,"mc":[{"id":"1.168136214","rc":[{"batb":[[1,1.97,14.59]],"batl":[[0,2,63.26]],"ltp":1.98,"tv":4823.45,"id":17336468},{"batb":[[0,3.8,14]],"ltp":3.85,"tv":1191.93,"id":11981493}]}]}
{"op":"mcm","clk":"991620471","pt":1580552240138,"mc":[{"id":"1.168136214","rc":[{"trd":[[2,1423.54]],"batl":[[0,2,2]],"ltp":2.0,"tv":4949.97,"id":17336468}],"tv":7457.8}]}
{"op":"mcm","clk":"991620567","pt":1580552240981,"mc":[{"id":"1.168136214","rc":[{"trd":[[4.3,217.3]],"batl":[[0,4.3,4.79]],"ltp":4.3,"tv":1319.88,"id":12925630}],"tv":7461.8}]}
{"op":"mcm","clk":"991620667","pt":1580552241622,"mc":[{"id":"1.168136214","rc":[{"batl":[[0,4.3,2]],"ltp":4.3,"tv":1319.88,"id":12925630}]}]}
{"op":"mcm","clk":"991620829","pt":1580552243051,"mc":[{"id":"1.168136214","rc":[{"batb":[[0,4.2,16.48]],"ltp":4.3,"tv":1319.88,"id":12925630}]}]}
{"op":"mcm","clk":"991621790","pt":1580552250958,"mc":[{"id":"1.168136214","rc":[{"batb":[[2,4,142.91]],"ltp":4.3,"tv":1319.88,"id":12925630}]}]}
{"op":"mcm","clk":"991632162","pt":1580552255068,"mc":[{"id":"1.168136214","rc":[{"batl":[[0,4.3,6.18]],"ltp":4.3,"tv":1319.88,"id":12925630},{"batb":[[0,1.99,37],[1,1.98,44.89],[2,1.97,14.59]],"ltp":2.0,"tv":4949.97,"id":17336468},{"batb":[[0,3.8,11]],"ltp":3.85,"tv":1191.93,"id":11981493}]}]}
{"op":"mcm","clk":"991632544","pt":1580552258061,"mc":[{"id":"1.168136214","rc":[{"trd":[[3.8,110.4]],"batb":[[0,3.8,9]],"ltp":3.8,"tv":1195.93,"id":11981493}],"tv":7465.8}]}
{"op":"mcm","clk":"991645300","pt":1580552358093,"mc":[{"id":"1.168136214","rc":[{"batl":[[0,2,20]],"ltp":2.0,"tv":4949.97,"id":17336468}]}]}
{"op":"mcm","clk":"991647966","pt":1580552377847,"mc":[{"id":"1.168136214","rc":[{"trd":[[2,1443.54]],"batl":[[0,2,10]],"ltp":2.0,"tv":4969.97,"id":17336468}],"tv":7485.8}]}
{"op":"mcm","clk":"991648384","pt":1580552380755,"mc":[{"id":"1.168136214","rc":[{"trd":[[4.3,223.3]],"batl":[[0,4.3,3.18]],"ltp":4.3,"tv":1325.88,"id":12925630},{"batl":[[0,3.85,10]],"ltp":3.8,"tv":1195.93,"id":11981493}],"tv":7491.8}]}
{"op":"mcm","clk":"991649471","pt":1580552389150,"mc":[{"id":"1.168136214","rc":[{"trd":[[3.8,114.4]],"batb":[[0,3.8,7]],"ltp":3.8,"tv":1199.93,"id":11981493}],"tv":7495.8}]}
{"op":"mcm","clk":"991649816","pt":1580552391852,"mc":[{"id":"1.168136214","rc":[{"trd":[[2,1458.22]],"batl":[[0,2,2.66]],"ltp":2.0,"tv":4984.65,"id":17336468}],"tv":7510.48}]}
{"op":"mcm","clk":"991650085","pt":1580552393839,"mc":[{"id":"1.168136214","rc":[{"batb":[[0,1.99,39]],"ltp":2.0,"tv":4984.65,"id":17336468}]}]}
{"op":"mcm","clk":"991651378","pt":1580552404080,"mc":[{"id":"1.168136214","rc":[{"batl":[[0,4.3,5.18]],"ltp":4.3,"tv":1325.88,"id":12925630},{"trd":[[2,1462.22]],"batl":[[0,2.02,36.22],[1,2.04,19.52],[2,2.06,8]],"ltp":2.0,"tv":4988.65,"id":17336468}],"tv":7514.48}]}
{"op":"mcm","clk":"991651733","pt":1580552406785,"mc":[{"id":"1.168136214","rc":[{"trd":[[3.75,47.7],[3.8,128.4]],"batb":[[0,3.75,70],[1,3.7,40],[2,3.65,10.48]],"ltp":3.75,"tv":1219.93,"id":11981493}],"tv":7534.48}]}
{"op":"mcm","clk":"991654106","pt":1580552425111,"mc":[{"id":"1.168136214","rc":[{"trd":[[4.2,252.53]],"batb":[[0,4.2,15.48]],"ltp":4.2,"tv":1331.88,"id":12925630}],"tv":7540.48}]}
{"op":"mcm","clk":"991655006","pt":1580552432040,"mc":[{"id":"1.168136214","rc":[{"batl":[[0,2.02,41.22]],"ltp":2.0,"tv":4988.65,"id":17336468}]}]}
{"op":"mcm","clk":"991655129","pt":1580552433143,"mc":[{"id":"1.168136214","rc":[{"batb":[[2,4,139.91]],"ltp":4.2,"tv":1331.88,"id":12925630}]}]}
{"op":"mcm","clk":"991655235","pt":1580552434046,"mc":[{"id":"1.168136214","rc":[{"trd":[[4.2,256.57]],"batb":[[0,4.2,13.46]],"ltp":4.2,"tv":1335.93,"id":12925630}],"tv":7544.52}]}
{"op":"mcm","clk":"991670324","pt":1580552553022,"mc":[{"id":"1.168136214","rc":[{"trd":[[2,1463.54]],"batb":[[0,2,9.34],[1,1.99,39],[2,1.98,44.89]],"batl":[[0,2.02,40.56]],"ltp":2.0,"tv":4989.97,"id":17336468}],"tv":7545.84}]}
{"op":"mcm","clk":"991672799","pt":1580552575087,"mc":[{"id":"1.168136214","rc":[{"trd":[[2,1475.54]],"batb":[[0,2,3.34]],"ltp":2.0,"tv":5001.97,"id":17336468},{"trd":[[3.75,53]],"batb":[[0,3.75,67.35]],"ltp":3.75,"tv":1225.23,"id":11981493}],"tv":7563.14}]}
{"op":"mcm","clk":"991686836","pt":1580552682025,"mc":[{"id":"1.168136214","rc":[{"batl":[[0,3.85,10.88]],"ltp":3.75,"tv":1225.23,"id":11981493}]}]}
{"op":"mcm","clk":"991686927","pt":1580552682818,"mc":[{"id":"1.168136214","rc":[{"batl":[[0,3.85,10.57]],"ltp":3.75,"tv":1225.23,"id":11981493}]}]}
{"op":"mcm","clk":"991687052","pt":1580552683827,"mc":[{"id":"1.168136214","rc":[{"batl":[[0,3.85,10]],"ltp":3.75,"tv":1225.23,"id":11981493}]}]}
{"op":"mcm","clk":"991687775","pt":1580552690146,"mc":[{"id":"1.168136214","rc":[{"batl":[[0,3.9,2.12],[1,3.95,16],[2,4,12]],"ltp":3.75,"tv":1225.23,"id":11981493}]}]}
{"op":"mcm","clk":"991692901","pt":1580552729136,"mc":[{"id":"1.168136214","rc":[{"trd":[[2,1482.22]],"batb":[[0,1.99,39],[1,1.98,44.89],[2,1.97,14.59]],"batl":[[0,2,26.66],[1,2.02,40.56],[2,2.04,19.52]],"ltp":2.0,"tv":5008.65,"id":17336468}],"tv":7569.82}]}
{"op":"mcm","clk":"991694165","pt":1580552738142,"mc":[{"id":"1.168136214","rc":[{"trd":[[3.75,69]],"batb":[[0,3.75,59.35]],"ltp":3.75,"tv":1241.23,"id":11981493}],"tv":7585.82}]}
{"op":"mcm","clk":"991702546","pt":1580552797890,"mc":[{"id":"1.168136214","rc":[{"trd":[[2,1502.22]],"batl":[[0,2,16.66]],"ltp":2.0,"tv":5028.65,"id":17336468}],"tv":7605.82}]}
{"op":"mcm","clk":"991707339","pt":1580552834152,"mc":[{"id":"1.168136214","rc":[{"batl":[[0,4.3,2]],"ltp":4.2,"tv":1335.93,"id":12925630},{"batl":[[0,3.85,32],[1,3.9,2.12],[2,3.95,16]],"ltp":3.75,"tv":1241.23,"id":11981493}]}]}
{"op":"mcm","clk":"991717066","pt":1580552902751,"mc":[{"id":"1.168136214","rc":[{"trd":[[1.99,558.02]],"batb":[[0,1.99,9]],"ltp":1.99,"tv":5088.65,"id":17336468}],"tv":7665.82}]}
{"op":"mcm","clk":"991725065","pt":1580552960724,"mc":[{"id":"1.168136214","rc":[{"trd":[[1.99,576.02]],"batb":[[0,1.98,36.89],[1,1.97,14.59],[2,1.96,13]],"batl":[[0,1.99,21],[1,2,18.66],[2,2.02,40.56]],"ltp":1.99,"tv":5106.65,"id":17336468}],"tv":7683.82}]}
{"op":"mcm","clk":"991726112","pt":1580552970742,"mc":[{"id":"1.168136214","rc":[{"batl":[[1,2,33.66]],"ltp":1.99,"tv":5106.65,"id":17336468}]}]}
{"op":"mcm","clk":"991726929","pt":1580552978156,"mc":[{"id":"1.168136214","rc":[{"trd":[[1.98,829.11]],"batb":[[0,1.98,16.89]],"ltp":1.98,"tv":5146.65,"id":17336468}],"tv":7723.82}]}
{"op":"mcm","clk":"991729853","pt":1580553004032,"mc":[{"id":"1.168136214","rc":[{"batl":[[0,3.8,10],[1,3.85,32],[2,3.9,2.12]],"ltp":3.75,"tv":1241.23,"id":11981493}]}]}
{"op":"mcm","clk":"991730340","pt":1580553008155,"mc":[{"id":"1.168136214","rc":[{"trd":[[4.3,225.3]],"batl":[[0,4.4,11.79],[1,4.5,5.12],[2,4.6,13.4]],"ltp":4.3,"tv":1337.93,"id":12925630},{"trd":[[1.98,867.21]],"batb":[[0,1.97,14.59],[1,1.96,13],[2,1.95,14.74]],"batl":[[0,1.98,232.04],[1,1.99,21],[2,2,33.66]],"ltp":1.98,"tv":5184.76,"id":17336468},{"trd":[[3.8,130.66]],"batl":[[0,3.8,7.74]],"ltp":3.8,"tv":1243.49,"id":11981493}],"tv":7766.19}]}
{"op":"mcm","clk":"991730448","pt":1580553008746,"mc":[{"id":"1.168136214","rc":[{"trd":[[4.3,236.16]],"ltp":4.3,"tv":1348.79,"id":12925630},{"trd":[[1.98,881.92]],"batb":[[0,1.97,5.59]],"batl":[[0,1.98,217.33],[1,1.99,23]],"ltp":1.98,"tv":5199.46,"id":17336468},{"trd":[[3.8,138.47]],"batl":[[0,3.85,30],[1,3.9,2.12],[2,3.95,16]],"ltp":3.8,"tv":1251.3,"id":11981493}],"tv":7799.57}]}
{"op":"mcm","clk":"991730945","pt":1580553013040,"mc":[{"id":"1.168136214","rc":[{"batb":[[2,4,142.91]],"ltp":4.3,"tv":1348.79,"id":12925630}]}]}
{"op":"mcm","clk":"991731352","pt":1580553016151,"mc":[{"id":"1.168136214","rc":[{"trd":[[1.98,889]],"batl":[[0,1.98,213.8]],"ltp":1.98,"tv":5206.54,"id":17336468}],"tv":7806.64}]}
{"op":"mcm","clk":"991731810","pt":1580553019766,"mc":[{"id":"1.168136214","rc":[{"batb":[[0,4.3,2.1],[1,4.2,13.46],[2,4.1,8]],"ltp":4.3,"tv":1348.79,"id":12925630},{"batl":[[0,3.8,10],[1,3.85,32],[2,3.9,2.12]],"ltp":3.8,"tv":1251.3,"id":11981493}]}]}
{"op":"mcm","clk":"991732644","pt":1580553025684,"mc":[{"id":"1.168136214","rc":[{"trd":[[4.4,159.43]],"batb":[[0,4.2,2],[1,4.1,8],[2,4,142.91]],"batl":[[0,4.5,5.12],[1,4.6,13.4],[2,5,5]],"ltp":4.4,"tv":1372.37,"id":12925630}],"tv":7830.22}]}
{"op":"mcm","clk":"991733209","pt":1580553030064,"mc":[{"id":"1.168136214","rc":[{"trd":[[1.97,208.85]],"batb":[[0,1.96,2],[1,1.95,28.39],[2,1.94,92.12]],"batl":[[0,1.98,215.8]],"ltp":1.97,"tv":5217.72,"id":17336468}],"tv":7841.4}]}
{"op":"mcm","clk":"991734986","pt":1580553043957,"mc":[{"id":"1.168136214","rc":[{"batl":[[0,4.4,2],[1,4.5,5.12],[2,4.6,13.4]],"ltp":4.4,"tv":1372.37,"id":12925630}]}]}
{"op":"mcm","clk":"991737598","pt":1580553063119,"mc":[{"id":"1.168136214","rc":[{"trd":[[4.2,282.73],[4.3,245]],"ltp":4.2,"tv":1407.37,"id":12925630},{"trd":[[1.98,955.13]],"batl":[[0,1.98,149.67]],"ltp":1.98,"tv":5283.85,"id":17336468},{"trd":[[3.8,148.47],[3.85,132.76]],"batb":[[0,3.8,3.01],[1,3.75,59.35],[2,3.7,40]],"batl":[[0,3.85,5.83],[1,3.9,2.12],[2,3.95,16]],"ltp":3.85,"tv":1285.47,"id":11981493}],"tv":7976.7}]}
{"op":"mcm","clk":"991738707","pt":1580553072134,"mc":[{"id":"1.168136214","rc":[{"trd":[[4.2,316.61]],"batb":[[0,4.1,8],[1,4,142.91],[2,3.95,5]],"batl":[[0,4.2,13.39],[1,4.3,5.06],[2,4.4,7.06]],"ltp":4.2,"tv":1441.25,"id":12925630},{"trd":[[1.98,966.45]],"batb":[[0,1.96,11.06]],"batl":[[0,1.98,138.34]],"ltp":1.98,"tv":5295.18,"id":17336468},{"trd":[[3.85,138.59]],"batl":[[0,3.95,14],[1,4,14],[2,4.1,27.97]],"ltp":3.85,"tv":1291.3,"id":11981493}],"tv":8027.74}]}
{"op":"mcm","clk":"991738842","pt":1580553073148,"mc":[{"id":"1.168136214","rc":[{"trd":[[4.2,331.93]],"batb":[[0,4.1,17.25]],"batl":[[0,4.2,5.73]],"ltp":4.2,"tv":1456.57,"id":12925630}],"tv":8043.06}]}
{"op":"mcm","clk":"991738935","pt":1580553073853,"mc":[{"id":"1.168136214","rc":[{"trd":[[4.2,343.39],[4.3,251.02]],"batb":[[0,4.2,2.07],[1,4.1,17.25],[2,4,142.91]],"batl":[[0,4.4,7.06],[1,4.5,5.12],[2,4.6,13.4]],"ltp":4.3,"tv":1474.05,"id":12925630},{"batb":[[0,1.96,2]],"ltp":1.98,"tv":5295.18,"id":17336468},{"batl":[[0,3.95,16]],"ltp":3.85,"tv":1291.3,"id":11981493}],"tv":8060.54}]}
{"op":"mcm","clk":"991739405","pt":1580553077152,"mc":[{"id":"1.168136214","rc":[{"batl":[[0,4.3,33],[1,4.4,7.06],[2,4.5,5.12]],"ltp":4.3,"tv":1474.05,"id":12925630}]}]}
{"op":"mcm","clk":"991740018","pt":1580553082145,"mc":[{"id":"1.168136214","rc":[{"batb":[[0,4.1,17.25],[1,4,142.91],[2,3.95,5]],"batl":[[0,4.3,71]],"ltp":4.3,"tv":1474.05,"id":12925630},{"batl":[[0,3.95,14]],"ltp":3.85,"tv":1291.3,"id":11981493}]}]}
{"op":"mcm","clk":"991740317","pt":1580553084147,"mc":[{"id":"1.168136214","rc":[{"batl":[[0,4.3,73],[1,4.4,5.06]],"ltp":4.3,"tv":1474.05,"id":12925630}]}]}
{"op":"mcm","clk":"991740819","pt":1580553086749,"mc":[{"id":"1.168136214","rc":[{"batl":[[0,4.3,106]],"ltp":4.3,"tv":1474.05,"id":12925630}]}]}
{"op":"mcm","clk":"991741142","pt":1580553089125,"mc":[{"id":"1.168136214","rc":[{"trd":[[4.3,254.38]],"batl":[[0,4.3,104.32]],"ltp":4.3,"tv":1477.41,"id":12925630}],"tv":8063.9}]}
{"op":"mcm","clk":"991741269","pt":1580553090034,"mc":[{"id":"1.168136214","rc":[{"trd":[[4.3,268.5]],"batl":[[0,4.3,97.26]],"ltp":4.3,"tv":1491.53,"id":12925630}],"tv":8078.02}]}
{"op":"mcm","clk":"991742063","pt":1580553095950,"mc":[{"id":"1.168136214","rc":[{"batl":[[1,4.4,38.06]],"ltp":4.3,"tv":1491.53,"id":12925630}]}]}
{"op":"mcm","clk":"991745968","pt":1580553124072,"mc":[{"id":"1.168136214","rc":[{"trd":[[1.96,666.03]],"batb":[[0,1.95,28.39],[1,1.94,102.12],[2,1.93,70]],"batl":[[0,1.96,4.83],[1,1.98,138.34],[2,1.99,23]],"ltp":1.96,"tv":5325.52,"id":17336468}],"tv":8108.36}]}
{"op":"mcm","clk":"991746189","pt":1580553125616,"mc":[{"id":"1.168136214","rc":[{"batb":[[2,3.7,35]],"ltp":3.85,"tv":1291.3,"id":11981493}]}]}
{"op":"mcm","clk":"991760239","pt":1580553155059,"mc":[{"id":"1.168136214","rc":[{"trd":[[1.95,410.4]],"batb":[[0,1.95,7.39]],"batl":[[2,1.99,2]],"ltp":1.95,"tv":5367.51,"id":17336468}],"tv":8150.35}]}
{"op":"mcm","clk":"991760486","pt":1580553155941,"mc":[{"id":"1.168136214","rc":[{"batl":[[1,1.97,10.12],[2,1.98,138.34]],"ltp":1.95,"tv":5367.51,"id":17336468}]}]}
{"op":"mcm","clk":"991761622","pt":1580553163079,"mc":[{"id":"1.168136214","rc":[{"batl":[[0,4.3,102.26]],"ltp":4.3,"tv":1491.53,"id":12925630}]}]}
{"op":"mcm","clk":"991764386","pt":1580553181151,"mc":[{"id":"1.168136214","rc":[{"trd":[[4.3,270.29]],"batl":[[0,4.3,100.47]],"ltp":4.3,"tv":1493.32,"id":12925630},{"trd":[[1.96,671.76]],"batl":[[0,1.97,10.12],[1,1.98,138.34],[2,1.99,2]],"ltp":1.96,"tv":5373.24,"id":17336468},{"trd":[[3.85,140.59]],"ltp":3.85,"tv":1293.3,"id":11981493}],"tv":8159.87}]}
{"op":"mcm","clk":"991765339","pt":1580553188035,"mc":[{"id":"1.168136214","rc":[{"batl":[[0,1.97,30.12]],"ltp":1.96,"tv":5373.24,"id":17336468}]}]}
{"op":"mcm","clk":"991765465","pt":1580553189049,"mc":[{"id":"1.168136214","rc":[{"batb":[[1,3.75,74.35]],"ltp":3.85,"tv":1293.3,"id":11981493}]}]}
{"op":"mcm","clk":"991767530","pt":1580553203951,"mc":[{"id":"1.168136214","rc":[{"batb":[[0,3.8,18.01]],"ltp":3.85,"tv":1293.3,"id":11981493}]}]}
{"op":"mcm","clk":"991769566","pt":1580553217132,"mc":[{"id":"1.168136214","rc":[{"batb":[[2,1.93,120]],"ltp":1.96,"tv":5373.24,"id":17336468}]}]}
{"op":"mcm","clk":"991770283","pt":1580553222138,"mc":[{"id":"1.168136214","rc":[{"batl":[[0,4.2,30],[1,4.3,100.47],[2,4.4,38.06]],"ltp":4.3,"tv":1493.32,"id":12925630}]}]}
{"op":"mcm","clk":"991770421","pt":1580553223147,"mc":[{"id":"1.168136214","rc":[{"batb":[[0,4.1,26.09]],"ltp":4.3,"tv":1493.32,"id":12925630},{"batb":[[0,1.96,37.84],[1,1.95,11],[2,1.94,102.12]],"batl":[[1,1.98,136.34]],"ltp":1.96,"tv":5373.24,"id":17336468},{"trd":[[3.95,45.71]],"batb":[[0,3.95,4.77],[1,3.8,18.01],[2,3.75,74.35]],"batl":[[0,4,23.15],[1,4.1,27.97],[2,4.2,180]],"ltp":3.95,"tv":1321.31,"id":11981493}],"tv":8187.88}]}
{"op":"mcm","clk":"991770565","pt":1580553224057,"mc":[{"id":"1.168136214","rc":[{"batl":[[0,4.2,36]],"ltp":4.3,"tv":1493.32,"id":12925630},{"trd":[[1.96,687.21]],"batb":[[0,1.96,41.11]],"ltp":1.96,"tv":5388.69,"id":17336468},{"batb":[[1,3.9,4.23],[2,3.85,4.23]],"batl":[[0,4,21.15],[1,4.1,29.97]],"ltp":3.95,"tv":1321.31,"id":11981493}],"tv":8203.33}]}
{"op":"mcm","clk":"991771235","pt":1580553229063,"mc":[{"id":"1.168136214","rc":[{"batb":[[2,3.85,9.23]],"ltp":3.95,"tv":1321.31,"id":11981493}]}]}
{"op":"mcm","clk":"991772288","pt":1580553236072,"mc":[{"id":"1.168136214","rc":[{"trd":[[1.97,218.85]],"batl":[[0,1.97,25.12]],"ltp":1.97,"tv":5398.69,"id":17336468}],"tv":8213.33}]}
{"op":"mcm","clk":"991773309","pt":1580553243101,"mc":[{"id":"1.168136214","rc":[{"trd":[[4.1,198.1]],"batb":[[0,4.1,24.09]],"batl":[[1,4.3,138.47]],"ltp":4.1,"tv":1497.32,"id":12925630}],"tv":8217.33}]}
{"op":"mcm","clk":"991774072","pt":1580553248085,"mc":[{"id":"1.168136214","rc":[{"batb":[[1,4,139.91]],"ltp":4.1,"tv":1497.32,"id":12925630}]}]}
{"op":"mcm","clk":"991774193","pt":1580553248991,"mc":[{"id":"1.168136214","rc":[{"batb":[[1,3.9,19.23]],"ltp":3.95,"tv":1321.31,"id":11981493}]}]}
{"op":"mcm","clk":"991774737","pt":1580553253122,"mc":[{"id":"1.168136214","rc":[{"trd":[[4.1,202.1]],"batb":[[0,4.1,22.09]],"ltp":4.1,"tv":1501.32,"id":12925630}],"tv":8221.33}]}
{"op":"mcm","clk":"991775001","pt":1580553255102,"mc":[{"id":"1.168136214","rc":[{"batl":[[0,4.2,40]],"ltp":4.1,"tv":1501.32,"id":12925630}]}]}
{"op":"mcm","clk":"991775142","pt":1580553256112,"mc":[{"id":"1.168136214","rc":[{"trd":[[4.1,258.34]],"batb":[[0,4,139.91],[1,3.95,7],[2,3.9,5]],"batl":[[0,4.1,5.85],[1,4.2,40],[2,4.3,138.47]],"ltp":4.1,"tv":1557.56,"id":12925630},{"trd":[[1.97,243.96]],"batb":[[0,1.96,61.21]],"batl":[[0,1.98,136.34],[1,2,33.66],[2,2.02,21.2]],"ltp":1.97,"tv":5423.81,"id":17336468},{"trd":[[4,80.5]],"batl":[[0,4,8.78]],"ltp":4.0,"tv":1333.68,"id":11981493}],"tv":8315.05}]}
{"op":"mcm","clk":"991775378","pt":1580553257925,"mc":[{"id":"1.168136214","rc":[{"batb":[[0,1.97,11.09],[1,1.96,61.21],[2,1.95,11]],"batl":[[1,2,68.77]],"ltp":1.97,"tv":5423.81,"id":17336468}]}]}
{"op":"mcm","clk":"991777177","pt":1580553270994,"mc":[{"id":"1.168136214","rc":[{"batl":[[0,4.1,11.85],[1,4.2,36]],"ltp":4.1,"tv":1557.56,"id":12925630}]}]}
