{"op":"mcm","clk":"992861447","pt":1580559515007,"mc":[{"id":"1.168136214","rc":[{"trd":[[4.3,512.47]],"batb":[[2,4,315.47]],"batl":[[0,4.3,144.17]],"ltp":4.3,"tv":4809.02,"id":12925630},{"trd":[[1.93,410.13]],"batb":[[0,1.91,11.19],[1,1.9,46.7],[2,1.89,75.23]],"ltp":1.93,"tv":12659.74,"id":17336468},{"trd":[[4,1014.18]],"batl":[[0,4,43.52]],"ltp":4.0,"tv":4431.89,"id":11981493}],"tv":21900.66}]}
{"op":"mcm","clk":"992861664","pt":1580559516097,"mc":[{"id":"1.168136214","rc":[{"batb":[[0,1.93,46.4],[1,1.91,11.19],[2,1.9,46.7]],"ltp":1.93,"tv":12659.74,"id":17336468},{"batl":[[2,4.2,38.44]],"ltp":4.0,"tv":4431.89,"id":11981493}]}]}
{"op":"mcm","clk":"992861854","pt":1580559517113,"mc":[{"id":"1.168136214","rc":[{"trd":[[1.93,460.55]],"batb":[[0,1.93,32.19],[1,1.92,11.19],[2,1.91,11.19]],"batl":[[0,1.94,35.28],[2,1.96,16.19]],"ltp":1.93,"tv":12710.16,"id":17336468}],"tv":21951.08}]}
{"op":"mcm","clk":"992862439","pt":1580559520094,"mc":[{"id":"1.168136214","rc":[{"batb":[[2,1.91,33.35]],"batl":[[0,1.94,43.28]],"ltp":1.93,"tv":12710.16,"id":17336468}]}]}
{"op":"mcm","clk":"992863465","pt":1580559525137,"mc":[{"id":"1.168136214","rc":[{"trd":[[4.3,647.07]],"batl":[[0,4.3,9.58]],"ltp":4.3,"tv":4943.61,"id":12925630},{"trd":[[1.92,752.96],[1.93,847.01]],"batb":[[0,1.91,33.35],[1,1.9,46.7],[2,1.89,65.23]],"batl":[[0,1.92,2.13],[1,1.93,124.73],[2,1.94,61.28]],"ltp":1.92,"tv":13119.0,"id":17336468},{"trd":[[4,1158.97]],"batl":[[0,4.1,8.49],[1,4.2,38.44],[2,4.3,8.46]],"ltp":4.0,"tv":4576.68,"id":11981493}],"tv":22639.3}]}
{"op":"mcm","clk":"992863653","pt":1580559526007,"mc":[{"id":"1.168136214","rc":[{"batb":[[0,1.91,11.19],[1,1.9,60.41],[2,1.89,34.84]],"ltp":1.92,"tv":13119.0,"id":17336468}]}]}
{"op":"mcm","clk":"992864269","pt":1580559529147,"mc":[{"id":"1.168136214","rc":[{"batb":[[0,4,7.53],[1,3.95,17.45],[2,3.9,33.76]],"batl":[[0,4.1,14.49]],"ltp":4.0,"tv":4576.68,"id":11981493}]}]}
{"op":"mcm","clk":"992864429","pt":1580559529950,"mc":[{"id":"1.168136214","rc":[{"batb":[[0,1.9,60.41],[1,1.89,45.84],[2,1.88,31.79]],"batl":[[1,1.93,274.73]],"ltp":1.92,"tv":13119.0,"id":17336468}]}]}
{"op":"mcm","clk":"992864674","pt":1580559531146,"mc":[{"id":"1.168136214","rc":[{"batb":[[2,1.88,60.19]],"ltp":1.92,"tv":13119.0,"id":17336468}]}]}
{"op":"mcm","clk":"992864877","pt":1580559532129,"mc":[{"id":"1.168136214","rc":[{"batl":[[1,4.2,45.16]],"ltp":4.0,"tv":4576.68,"id":11981493}]}]}
{"op":"mcm","clk":"992865090","pt":1580559533136,"mc":[{"id":"1.168136214","rc":[{"batb":[[0,1.91,2.1],[1,1.9,60.41],[2,1.89,45.84]],"batl":[[0,1.92,52.78]],"ltp":1.92,"tv":13119.0,"id":17336468},{"batb":[[1,3.95,24.29]],"ltp":4.0,"tv":4576.68,"id":11981493}]}]}
{"op":"mcm","clk":"992865300","pt":1580559534125,"mc":[{"id":"1.168136214","rc":[{"trd":[[4.3,666.22]],"batl":[[0,4.4,112.64],[1,4.5,103.78],[2,4.6,20.33]],"ltp":4.3,"tv":4962.77,"id":12925630},{"batb":[[0,1.9,38],[1,1.89,45.84],[2,1.88,60.19]],"batl":[[0,1.92,73.78]],"ltp":1.92,"tv":13119.0,"id":17336468},{"batb":[[0,4,16]],"batl":[[0,4.1,8.49]],"ltp":4.0,"tv":4576.68,"id":11981493}],"tv":22658.46}]}
{"op":"mcm","clk":"992865484","pt":1580559535143,"mc":[{"id":"1.168136214","rc":[{"batb":[[0,4.2,39.12]],"batl":[[1,4.5,57.03]],"ltp":4.3,"tv":4962.77,"id":12925630},{"batb":[[0,1.9,28],[1,1.89,33.66],[2,1.88,71.19]],"ltp":1.92,"tv":13119.0,"id":17336468}]}]}
{"op":"mcm","clk":"992866008","pt":1580559538051,"mc":[{"id":"1.168136214","rc":[{"batb":[[0,4.2,60.44]],"batl":[[0,4.4,130.7]],"ltp":4.3,"tv":4962.77,"id":12925630},{"trd":[[1.9,119.54]],"batb":[[0,1.9,8.5],[1,1.89,22.66]],"batl":[[0,1.91,21.31],[1,1.92,71.65],[2,1.93,274.73]],"ltp":1.9,"tv":13180.54,"id":17336468},{"trd":[[4.1,90.57]],"batb":[[0,4.1,19.34],[1,4,21.33],[2,3.95,24.29]],"batl":[[0,4.2,45.16],[1,4.3,8.46],[2,4.4,13.51]],"ltp":4.1,"tv":4593.67,"id":11981493}],"tv":22736.99}]}
{"op":"mcm","clk":"992866211","pt":1580559539139,"mc":[{"id":"1.168136214","rc":[{"batl":[[0,4.4,112.64]],"ltp":4.3,"tv":4962.77,"id":12925630},{"batb":[[0,1.88,48.28],[1,1.87,68.68],[2,1.86,13.22]],"batl":[[0,1.9,4.89],[1,1.91,42.62],[2,1.92,71.65]],"ltp":1.9,"tv":13180.54,"id":17336468},{"batb":[[1,4,31.46]],"batl":[[0,4.2,38.44]],"ltp":4.1,"tv":4593.67,"id":11981493}]}]}
{"op":"mcm","clk":"992866345","pt":1580559539950,"mc":[{"id":"1.168136214","rc":[{"batb":[[0,4.3,7.94],[1,4.2,69.94],[2,4.1,109.88]],"ltp":4.3,"tv":4962.77,"id":12925630},{"batb":[[0,1.88,39.4],[1,1.87,58.68]],"batl":[[1,1.91,21.32]],"ltp":1.9,"tv":13180.54,"id":17336468},{"batb":[[0,4.1,27.64],[1,4,39.36]],"batl":[[0,4.2,18.18]],"ltp":4.1,"tv":4593.67,"id":11981493}]}]}
{"op":"mcm","clk":"992866576","pt":1580559541146,"mc":[{"id":"1.168136214","rc":[{"trd":[[4.3,685.13]],"batb":[[0,4.2,69.94],[1,4.1,109.88],[2,4,315.47]],"batl":[[0,4.4,131.95]],"ltp":4.3,"tv":4981.68,"id":12925630},{"batb":[[0,1.89,21.24],[1,1.88,69.46],[2,1.87,58.68]],"batl":[[1,1.91,30.15]],"ltp":1.9,"tv":13180.54,"id":17336468}],"tv":22755.9}]}
{"op":"mcm","clk":"992867001","pt":1580559543153,"mc":[{"id":"1.168136214","rc":[{"batb":[[0,4.2,120.59]],"ltp":4.3,"tv":4981.68,"id":12925630}]}]}
{"op":"mcm","clk":"992867408","pt":1580559545065,"mc":[{"id":"1.168136214","rc":[{"batb":[[0,4.3,9.46],[1,4.2,120.59],[2,4.1,109.88]],"ltp":4.3,"tv":4981.68,"id":12925630},{"batl":[[1,4.3,15.18]],"ltp":4.1,"tv":4593.67,"id":11981493}]}]}
{"op":"mcm","clk":"992867839","pt":1580559547153,"mc":[{"id":"1.168136214","rc":[{"batl":[[0,4.4,112.64]],"ltp":4.3,"tv":4981.68,"id":12925630},{"batl":[[0,4.2,73.18]],"ltp":4.1,"tv":4593.67,"id":11981493}]}]}
{"op":"mcm","clk":"992868658","pt":1580559551100,"mc":[{"id":"1.168136214","rc":[{"batb":[[0,4.3,29.47]],"batl":[[0,4.4,109.64]],"ltp":4.3,"tv":4981.68,"id":12925630},{"trd":[[1.9,129.31]],"batb":[[0,1.89,31.24]],"batl":[[0,1.91,30.15],[1,1.92,71.65],[2,1.93,274.73]],"ltp":1.9,"tv":13190.31,"id":17336468},{"trd":[[4.1,145.85]],"batb":[[0,4,39.36],[1,3.95,24.29],[2,3.9,33.76]],"batl":[[0,4.1,22.35],[1,4.2,73.18],[2,4.3,15.18]],"ltp":4.1,"tv":4648.96,"id":11981493}],"tv":22820.96}]}
{"op":"mcm","clk":"992868869","pt":1580559552082,"mc":[{"id":"1.168136214","rc":[{"batb":[[0,4.3,31.47],[1,4.2,128.77]],"ltp":4.3,"tv":4981.68,"id":12925630},{"batb":[[0,1.89,63.02],[2,1.87,67.62]],"batl":[[0,1.91,8.83]],"ltp":1.9,"tv":13190.31,"id":17336468},{"batb":[[0,4,21.33]],"batl":[[0,4.1,28.35],[1,4.2,78.63]],"ltp":4.1,"tv":4648.96,"id":11981493}]}]}
{"op":"mcm","clk":"992869100","pt":1580559553072,"mc":[{"id":"1.168136214","rc":[{"batb":[[1,4.2,135.07]],"ltp":4.3,"tv":4981.68,"id":12925630},{"batb":[[1,1.88,59.64]],"batl":[[0,1.92,71.85],[1,1.93,274.73],[2,1.94,63.19]],"ltp":1.9,"tv":13190.31,"id":17336468}]}]}
{"op":"mcm","clk":"992869298","pt":1580559553981,"mc":[{"id":"1.168136214","rc":[{"batl":[[1,1.93,291.99]],"ltp":1.9,"tv":13190.31,"id":17336468},{"batb":[[0,4,16]],"batl":[[1,4.2,86.49]],"ltp":4.1,"tv":4648.96,"id":11981493}]}]}
{"op":"mcm","clk":"992870341","pt":1580559559130,"mc":[{"id":"1.168136214","rc":[{"trd":[[4.4,175.31]],"batl":[[0,4.4,93.76]],"ltp":4.4,"tv":4997.56,"id":12925630},{"trd":[[1.89,163.02]],"batb":[[0,1.89,10],[1,1.88,82.55]],"batl":[[0,1.91,21.33],[1,1.92,71.65],[2,1.93,291.99]],"ltp":1.89,"tv":13353.33,"id":17336468},{"trd":[[4.1,162.89]],"batb":[[0,4,29]],"batl":[[0,4.1,11.31],[2,4.3,8.46]],"ltp":4.1,"tv":4666.0,"id":11981493}],"tv":23016.9}]}
{"op":"mcm","clk":"992870512","pt":1580559559942,"mc":[{"id":"1.168136214","rc":[{"batb":[[0,1.89,44.32],[1,1.88,61.31]],"ltp":1.89,"tv":13353.33,"id":17336468}]}]}
{"op":"mcm","clk":"992871195","pt":1580559563137,"mc":[{"id":"1.168136214","rc":[{"trd":[[4.4,184.45]],"batl":[[0,4.4,89.19]],"ltp":4.4,"tv":5006.7,"id":12925630},{"batl":[[0,1.91,41.33]],"ltp":1.89,"tv":13353.33,"id":17336468},{"batl":[[0,4.1,5.31],[1,4.2,36.49]],"ltp":4.1,"tv":4666.0,"id":11981493}],"tv":23026.04}]}
{"op":"mcm","clk":"992871608","pt":1580559565152,"mc":[{"id":"1.168136214","rc":[{"batl":[[2,4.3,15.18]],"ltp":4.1,"tv":4666.0,"id":11981493}]}]}
{"op":"mcm","clk":"992871817","pt":1580559566134,"mc":[{"id":"1.168136214","rc":[{"batb":[[0,4,79]],"ltp":4.1,"tv":4666.0,"id":11981493}]}]}
{"op":"mcm","clk":"992871978","pt":1580559567054,"mc":[{"id":"1.168136214","rc":[{"batl":[[0,4.1,55.31]],"ltp":4.1,"tv":4666.0,"id":11981493}]}]}
{"op":"mcm","clk":"992872196","pt":1580559568142,"mc":[{"id":"1.168136214","rc":[{"batl":[[0,1.91,49.33]],"ltp":1.89,"tv":13353.33,"id":17336468}]}]}
{"op":"mcm","clk":"992872576","pt":1580559570046,"mc":[{"id":"1.168136214","rc":[{"batl":[[2,1.93,141.99]],"ltp":1.89,"tv":13353.33,"id":17336468},{"batl":[[0,4.1,50]],"ltp":4.1,"tv":4666.0,"id":11981493}]}]}
{"op":"mcm","clk":"992872815","pt":1580559571148,"mc":[{"id":"1.168136214","rc":[{"trd":[[1.89,173.02]],"batb":[[0,1.89,39.32]],"ltp":1.89,"tv":13363.33,"id":17336468}],"tv":23036.04}]}
{"op":"mcm","clk":"992873630","pt":1580559575071,"mc":[{"id":"1.168136214","rc":[{"batl":[[1,4.5,54.03]],"ltp":4.4,"tv":5006.7,"id":12925630},{"trd":[[1.89,193.02]],"batb":[[0,1.89,38.32]],"ltp":1.89,"tv":13383.33,"id":17336468},{"batb":[[1,3.95,21.29]],"batl":[[2,4.3,8.46]],"ltp":4.1,"tv":4666.0,"id":11981493}],"tv":23056.04}]}
{"op":"mcm","clk":"992874804","pt":1580559580997,"mc":[{"id":"1.168136214","rc":[{"batb":[[1,1.88,77.97]],"batl":[[0,1.91,49.13]],"ltp":1.89,"tv":13383.33,"id":17336468},{"batl":[[1,4.2,43.21]],"ltp":4.1,"tv":4666.0,"id":11981493}]}]}
{"op":"mcm","clk":"992875424","pt":1580559584020,"mc":[{"id":"1.168136214","rc":[{"trd":[[4.4,231.04]],"batl":[[0,4.4,42.6]],"ltp":4.4,"tv":5053.29,"id":12925630},{"trd":[[1.89,384.55]],"batb":[[0,1.89,13.45],[1,1.88,55.06]],"batl":[[0,1.9,20.24],[1,1.91,49.13],[2,1.92,71.65]],"ltp":1.89,"tv":13574.86,"id":17336468},{"trd":[[4.1,212.89]],"batb":[[0,4,84.55]],"batl":[[0,4.2,36.49],[1,4.3,5.46],[2,4.4,13.51]],"ltp":4.1,"tv":4716.0,"id":11981493}],"tv":23344.16}]}
{"op":"mcm","clk":"992875601","pt":1580559584835,"mc":[{"id":"1.168136214","rc":[{"batb":[[1,1.88,38.4]],"batl":[[0,1.91,49.13],[1,1.92,71.65],[2,1.93,141.99]],"ltp":1.89,"tv":13574.86,"id":17336468}]}]}
{"op":"mcm","clk":"992876318","pt":1580559588148,"mc":[{"id":"1.168136214","rc":[{"batl":[[0,1.91,49.33]],"ltp":1.89,"tv":13574.86,"id":17336468}]}]}
{"op":"mcm","clk":"992876500","pt":1580559589124,"mc":[{"id":"1.168136214","rc":[{"batl":[[0,1.9,28.78],[1,1.91,49.33],[2,1.92,71.65]],"ltp":1.89,"tv":13574.86,"id":17336468}]}]}
{"op":"mcm","clk":"992876686","pt":1580559590144,"mc":[{"id":"1.168136214","rc":[{"batl":[[1,1.91,51.53]],"ltp":1.89,"tv":13574.86,"id":17336468},{"batl":[[0,4.2,31.03],[1,4.3,12.18]],"ltp":4.1,"tv":4716.0,"id":11981493}]}]}
{"op":"mcm","clk":"992876912","pt":1580559591133,"mc":[{"id":"1.168136214","rc":[{"batl":[[0,4.2,23.18]],"ltp":4.1,"tv":4716.0,"id":11981493}]}]}
{"op":"mcm","clk":"992877141","pt":1580559592154,"mc":[{"id":"1.168136214","rc":[{"trd":[[4.4,295.04]],"batl":[[0,4.4,10.6]],"ltp":4.4,"tv":5117.3,"id":12925630},{"trd":[[1.9,133.31]],"batl":[[0,1.9,48.44]],"ltp":1.9,"tv":13578.86,"id":17336468}],"tv":23412.17}]}
{"op":"mcm","clk":"992877343","pt":1580559593131,"mc":[{"id":"1.168136214","rc":[{"batl":[[0,1.9,68.44]],"ltp":1.9,"tv":13578.86,"id":17336468}]}]}
{"op":"mcm","clk":"992877526","pt":1580559594151,"mc":[{"id":"1.168136214","rc":[{"batb":[[2,1.87,58.68]],"ltp":1.9,"tv":13578.86,"id":17336468}]}]}
{"op":"mcm","clk":"992878070","pt":1580559597073,"mc":[{"id":"1.168136214","rc":[{"batl":[[0,1.9,76.44],[1,1.91,43.53]],"ltp":1.9,"tv":13578.86,"id":17336468}]}]}
{"op":"mcm","clk":"992879075","pt":1580559601977,"mc":[{"id":"1.168136214","rc":[{"trd":[[4.4,311.84]],"batl":[[0,4.4,2.2]],"ltp":4.4,"tv":5134.09,"id":12925630},{"batl":[[0,1.9,54.78]],"ltp":1.9,"tv":13578.86,"id":17336468},{"trd":[[4,1178.97]],"batb":[[0,4.1,5.31],[1,4,79.55],[2,3.95,21.29]],"ltp":4.0,"tv":4735.99,"id":11981493}],"tv":23448.96}]}
{"op":"mcm","clk":"992881173","pt":1580559611925,"mc":[{"id":"1.168136214","rc":[{"trd":[[4.4,316.23]],"batb":[[2,4.1,59.88]],"batl":[[0,4.5,54.03],[1,4.6,20.33],[2,4.7,33.1]],"ltp":4.4,"tv":5138.49,"id":12925630},{"trd":[[1.88,33.1],[1.89,411.45]],"batb":[[0,1.88,11.85],[1,1.87,35.5],[2,1.86,46.67]],"ltp":1.88,"tv":13638.87,"id":17336468}],"tv":23513.36}]}
{"op":"mcm","clk":"992881415","pt":1580559613151,"mc":[{"id":"1.168136214","rc":[{"batl":[[0,1.89,6.84],[1,1.9,54.78],[2,1.91,43.53]],"ltp":1.88,"tv":13638.87,"id":17336468},{"batl":[[0,4.2,18.18]],"ltp":4.0,"tv":4735.99,"id":11981493}]}]}
{"op":"mcm","clk":"992881825","pt":1580559615037,"mc":[{"id":"1.168136214","rc":[{"batl":[[0,4.5,46.01]],"ltp":4.4,"tv":5138.49,"id":12925630},{"batb":[[0,4,79.55],[1,3.95,21.29],[2,3.9,33.76]],"batl":[[0,4.2,27.62],[1,4.3,212.18]],"ltp":4.0,"tv":4735.99,"id":11981493}]}]}
{"op":"mcm","clk":"992882040","pt":1580559616141,"mc":[{"id":"1.168136214","rc":[{"batl":[[2,1.91,43.33]],"ltp":1.88,"tv":13638.87,"id":17336468}]}]}
{"op":"mcm","clk":"992882640","pt":1580559619151,"mc":[{"id":"1.168136214","rc":[{"batb":[[2,3.9,26.8]],"batl":[[0,4.1,300],[1,4.2,27.62],[2,4.3,212.18]],"ltp":4.0,"tv":4735.99,"id":11981493}]}]}
{"op":"mcm","clk":"992882840","pt":1580559620064,"mc":[{"id":"1.168136214","rc":[{"batb":[[0,4.4,7.92],[1,4.3,47.08],[2,4.2,125.58]],"ltp":4.4,"tv":5138.49,"id":12925630},{"batb":[[0,1.88,20.85]],"ltp":1.88,"tv":13638.87,"id":17336468},{"batb":[[0,4,74.55]],"batl":[[0,4.1,305]],"ltp":4.0,"tv":4735.99,"id":11981493}]}]}
{"op":"mcm","clk":"992883054","pt":1580559621053,"mc":[{"id":"1.168136214","rc":[{"batb":[[0,4.4,19.03]],"batl":[[0,4.5,40.61]],"ltp":4.4,"tv":5138.49,"id":12925630},{"batb":[[0,4,69.01]],"batl":[[1,4.2,32.69]],"ltp":4.0,"tv":4735.99,"id":11981493}]}]}
{"op":"mcm","clk":"992883262","pt":1580559622044,"mc":[{"id":"1.168136214","rc":[{"batl":[[0,4.5,35.36]],"ltp":4.4,"tv":5138.49,"id":12925630}]}]}
{"op":"mcm","clk":"992883735","pt":1580559624147,"mc":[{"id":"1.168136214","rc":[{"batl":[[0,1.89,7.04]],"ltp":1.88,"tv":13638.87,"id":17336468}]}]}
{"op":"mcm","clk":"992884363","pt":1580559627097,"mc":[{"id":"1.168136214","rc":[{"batb":[[1,1.87,58.68]],"ltp":1.88,"tv":13638.87,"id":17336468},{"batl":[[2,4.3,205.46]],"ltp":4.0,"tv":4735.99,"id":11981493}]}]}
{"op":"mcm","clk":"992885608","pt":1580559633111,"mc":[{"id":"1.168136214","rc":[{"batl":[[1,4.2,39.41]],"ltp":4.0,"tv":4735.99,"id":11981493}]}]}
{"op":"mcm","clk":"992886262","pt":1580559636102,"mc":[{"id":"1.168136214","rc":[{"batl":[[0,1.89,37.22],[1,1.9,28]],"ltp":1.88,"tv":13638.87,"id":17336468}]}]}
{"op":"mcm","clk":"992886480","pt":1580559637039,"mc":[{"id":"1.168136214","rc":[{"batb":[[1,1.87,35.5]],"ltp":1.88,"tv":13638.87,"id":17336468}]}]}
{"op":"mcm","clk":"992887979","pt":1580559643920,"mc":[{"id":"1.168136214","rc":[{"trd":[[1.88,39.1]],"batb":[[0,1.88,17.85]],"ltp":1.88,"tv":13644.87,"id":17336468}],"tv":23519.36}]}
{"op":"mcm","clk":"992888187","pt":1580559645011,"mc":[{"id":"1.168136214","rc":[{"batb":[[0,1.88,8.85]],"batl":[[0,1.89,45.22],[1,1.9,20]],"ltp":1.88,"tv":13644.87,"id":17336468}]}]}
{"op":"mcm","clk":"992888773","pt":1580559647837,"mc":[{"id":"1.168136214","rc":[{"trd":[[1.89,438.34]],"batl":[[0,1.89,31.78]],"ltp":1.89,"tv":13671.75,"id":17336468}],"tv":23546.24}]}
{"op":"mcm","clk":"992890989","pt":1580559659062,"mc":[{"id":"1.168136214","rc":[{"batb":[[0,1.88,11.85]],"batl":[[0,1.89,31.98]],"ltp":1.89,"tv":13671.75,"id":17336468}]}]}
{"op":"mcm","clk":"992891198","pt":1580559659979,"mc":[{"id":"1.168136214","rc":[{"trd":[[1.88,62.8]],"batb":[[0,1.87,35.5],[1,1.86,46.67],[2,1.85,17.6]],"batl":[[0,1.88,1.64],[1,1.89,950.98],[2,1.9,20]],"ltp":1.88,"tv":13695.45,"id":17336468},{"batb":[[0,4,74.01]],"batl":[[0,4.1,300]],"ltp":4.0,"tv":4735.99,"id":11981493}],"tv":23569.94}]}
{"op":"mcm","clk":"992891455","pt":1580559661087,"mc":[{"id":"1.168136214","rc":[{"batb":[[0,4.4,24.96]],"ltp":4.4,"tv":5138.49,"id":12925630},{"batl":[[2,1.9,27.77]],"ltp":1.88,"tv":13695.45,"id":17336468}]}]}
{"op":"mcm","clk":"992891659","pt":1580559662077,"mc":[{"id":"1.168136214","rc":[{"batb":[[1,4.3,37.58]],"ltp":4.4,"tv":5138.49,"id":12925630}]}]}
{"op":"mcm","clk":"992892052","pt":1580559663964,"mc":[{"id":"1.168136214","rc":[{"trd":[[1.87,12.12]],"batb":[[0,1.87,19.44]],"ltp":1.87,"tv":13707.56,"id":17336468}],"tv":23582.05}]}
{"op":"mcm","clk":"992892255","pt":1580559665054,"mc":[{"id":"1.168136214","rc":[{"batl":[[0,1.88,31.94],[1,1.89,927.2]],"ltp":1.87,"tv":13707.56,"id":17336468}]}]}
{"op":"mcm","clk":"992892468","pt":1580559666107,"mc":[{"id":"1.168136214","rc":[{"trd":[[4.5,101.65]],"batl":[[0,4.5,21.13]],"ltp":4.5,"tv":5166.95,"id":12925630},{"batb":[[0,1.87,57.29],[1,1.86,10],[2,1.85,41.32]],"ltp":1.87,"tv":13707.56,"id":17336468},{"batb":[[0,4,91.47],[1,3.95,37.5]],"ltp":4.0,"tv":4735.99,"id":11981493}],"tv":23610.52}]}
{"op":"mcm","clk":"992892682","pt":1580559667094,"mc":[{"id":"1.168136214","rc":[{"trd":[[4.5,104.65]],"batl":[[0,4.5,19.63]],"ltp":4.5,"tv":5169.95,"id":12925630}],"tv":23613.51}]}
{"op":"mcm","clk":"992893082","pt":1580559668907,"mc":[{"id":"1.168136214","rc":[{"trd":[[4,1184.96]],"batb":[[0,4,88.47]],"ltp":4.0,"tv":4741.99,"id":11981493}],"tv":23619.51}]}
{"op":"mcm","clk":"992893264","pt":1580559670090,"mc":[{"id":"1.168136214","rc":[{"batl":[[0,1.88,82.59]],"ltp":1.87,"tv":13707.56,"id":17336468}]}]}
{"op":"mcm","clk":"992896128","pt":1580559684065,"mc":[{"id":"1.168136214","rc":[{"batl":[[1,1.89,919.2]],"ltp":1.87,"tv":13707.56,"id":17336468}]}]}
{"op":"mcm","clk":"992896343","pt":1580559685146,"mc":[{"id":"1.168136214","rc":[{"batl":[[0,1.88,90.59]],"ltp":1.87,"tv":13707.56,"id":17336468}]}]}
{"op":"mcm","clk":"992896558","pt":1580559686081,"mc":[{"id":"1.168136214","rc":[{"trd":[[4.5,143.91]],"batb":[[0,4.5,1.36],[1,4.4,24.96],[2,4.3,37.58]],"batl":[[0,4.6,20.33],[1,4.7,33.1],[2,4.8,18.03]],"ltp":4.5,"tv":5209.21,"id":12925630},{"batb":[[0,1.87,118.81]],"ltp":1.87,"tv":13707.56,"id":17336468}],"tv":23658.78}]}
{"op":"mcm","clk":"992896801","pt":1580559687153,"mc":[{"id":"1.168136214","rc":[{"batb":[[0,4.5,22.31],[1,4.4,33.24]],"batl":[[0,4.6,7]],"ltp":4.5,"tv":5209.21,"id":12925630},{"trd":[[1.87,18.12]],"batb":[[0,1.87,104.81]],"ltp":1.87,"tv":13713.56,"id":17336468},{"trd":[[4,1188.96]],"batb":[[0,4,86.47]],"batl":[[0,4.1,306],[1,4.2,47.51]],"ltp":4.0,"tv":4745.99,"id":11981493}],"tv":23668.77}]}
{"op":"mcm","clk":"992897010","pt":1580559688142,"mc":[{"id":"1.168136214","rc":[{"batb":[[0,4.5,31.35],[2,4.3,28.12]],"ltp":4.5,"tv":5209.21,"id":12925630}]}]}
{"op":"mcm","clk":"992897182","pt":1580559689067,"mc":[{"id":"1.168136214","rc":[{"batb":[[0,4,70.69]],"ltp":4.0,"tv":4745.99,"id":11981493}]}]}
{"op":"mcm","clk":"992897374","pt":1580559689857,"mc":[{"id":"1.168136214","rc":[{"trd":[[1.88,66.8]],"batl":[[0,1.88,88.59]],"ltp":1.88,"tv":13717.56,"id":17336468}],"tv":23672.77}]}
{"op":"mcm","clk":"992898025","pt":1580559692950,"mc":[{"id":"1.168136214","rc":[{"batb":[[0,4.5,33.35]],"batl":[[1,4.7,36.1]],"ltp":4.5,"tv":5209.21,"id":12925630},{"trd":[[1.88,89.92]],"batl":[[0,1.88,77.03]],"ltp":1.88,"tv":13740.68,"id":17336468}],"tv":23695.89}]}
{"op":"mcm","clk":"992898237","pt":1580559694151,"mc":[{"id":"1.168136214","rc":[{"batb":[[0,4.5,25.54],[1,4.4,39.17]],"ltp":4.5,"tv":5209.21,"id":12925630}]}]}
{"op":"mcm","clk":"992898428","pt":1580559695101,"mc":[{"id":"1.168136214","rc":[{"batl":[[0,1.88,77.23]],"ltp":1.88,"tv":13740.68,"id":17336468}]}]}
{"op":"mcm","clk":"992898634","pt":1580559696061,"mc":[{"id":"1.168136214","rc":[{"batb":[[1,4.4,46.68]],"ltp":4.5,"tv":5209.21,"id":12925630}]}]}
{"op":"mcm","clk":"992899413","pt":1580559700095,"mc":[{"id":"1.168136214","rc":[{"batb":[[2,1.85,46.32]],"batl":[[0,1.88,82.23]],"ltp":1.88,"tv":13740.68,"id":17336468}]}]}
{"op":"mcm","clk":"992899612","pt":1580559701080,"mc":[{"id":"1.168136214","rc":[{"batl":[[1,1.89,919]],"ltp":1.88,"tv":13740.68,"id":17336468}]}]}
{"op":"mcm","clk":"992900379","pt":1580559704993,"mc":[{"id":"1.168136214","rc":[{"batl":[[0,1.88,31.58]],"ltp":1.88,"tv":13740.68,"id":17336468}]}]}
{"op":"mcm","clk":"992900620","pt":1580559706092,"mc":[{"id":"1.168136214","rc":[{"trd":[[4.6,191.11]],"batb":[[0,4.6,106],[1,4.5,25.54],[2,4.4,46.68]],"batl":[[0,4.7,33.1],[1,4.8,21.03],[2,4.9,5.07]],"ltp":4.6,"tv":5223.21,"id":12925630},{"batl":[[0,1.88,79.83]],"ltp":1.88,"tv":13740.68,"id":17336468},{"batb":[[0,4,65.69],[1,3.95,30.67],[2,3.9,33.76]],"ltp":4.0,"tv":4745.99,"id":11981493}],"tv":23709.89}]}
{"op":"mcm","clk":"992900821","pt":1580559707103,"mc":[{"id":"1.168136214","rc":[{"batb":[[2,4.4,37.74]],"ltp":4.6,"tv":5223.21,"id":12925630}]}]}
{"op":"mcm","clk":"992901210","pt":1580559709102,"mc":[{"id":"1.168136214","rc":[{"trd":[[1.87,24.12]],"batb":[[0,1.87,101.81]],"ltp":1.87,"tv":13746.68,"id":17336468}],"tv":23715.89}]}
{"op":"mcm","clk":"992901384","pt":1580559710072,"mc":[{"id":"1.168136214","rc":[{"trd":[[4.7,181.58]],"batb":[[0,4.7,39.4],[1,4.6,106],[2,4.5,25.54]],"batl":[[0,4.8,18.03],[1,4.9,8.07],[2,5,12.77]],"ltp":4.7,"tv":5329.91,"id":12925630},{"trd":[[1.87,125.93]],"batb":[[0,1.85,37.32],[1,1.84,9.03],[2,1.83,48.18]],"batl":[[0,1.87,45.16],[1,1.88,79.83],[2,1.89,919]],"ltp":1.87,"tv":13848.5,"id":17336468},{"trd":[[4,1236.55]],"batb":[[0,4,18.1]],"ltp":4.0,"tv":4793.58,"id":11981493}],"tv":23972.0}]}
{"op":"mcm","clk":"992901588","pt":1580559711108,"mc":[{"id":"1.168136214","rc":[{"batb":[[0,4.7,13],[1,4.6,13]],"batl":[[0,4.8,5],[1,4.9,3]],"ltp":4.7,"tv":5329.91,"id":12925630},{"batb":[[0,1.85,5],[2,1.83,26]],"ltp":1.87,"tv":13848.5,"id":17336468}]}]}
{"op":"mcm","clk":"992901806","pt":1580559712131,"mc":[{"id":"1.168136214","rc":[{"batb":[[2,4.5,16.5]],"ltp":4.7,"tv":5329.91,"id":12925630},{"batb":[[0,4,41.72]],"ltp":4.0,"tv":4793.58,"id":11981493}]}]}
{"op":"mcm","clk":"992902016","pt":1580559713095,"mc":[{"id":"1.168136214","rc":[{"batl":[[2,5,20.71]],"ltp":4.7,"tv":5329.91,"id":12925630},{"batb":[[2,1.83,38]],"batl":[[0,1.86,26.28],[1,1.87,69.16],[2,1.88,79.83]],"ltp":1.87,"tv":13848.5,"id":17336468}]}]}
{"op":"mcm","clk":"992902217","pt":1580559714127,"mc":[{"id":"1.168136214","rc":[{"batb":[[0,4.6,13],[1,4.5,22.27],[2,4.4,37.74]],"ltp":4.7,"tv":5329.91,"id":12925630},{"batl":[[0,1.86,2]],"ltp":1.87,"tv":13848.5,"id":17336468}]}]}
{"op":"mcm","clk":"992902403","pt":1580559715092,"mc":[{"id":"1.168136214","rc":[{"batl":[[2,1.88,88.71]],"ltp":1.87,"tv":13848.5,"id":17336468}]}]}
{"op":"mcm","clk":"992902947","pt":1580559718110,"mc":[{"id":"1.168136214","rc":[{"batb":[[1,3.95,37.5]],"ltp":4.0,"tv":4793.58,"id":11981493}]}]}
{"op":"mcm","clk":"992903130","pt":1580559719135,"mc":[{"id":"1.168136214","rc":[{"batl":[[0,1.86,4]],"ltp":1.87,"tv":13848.5,"id":17336468}]}]}
{"op":"mcm","clk":"992903271","pt":1580559719933,"mc":[{"id":"1.168136214","rc":[{"batl":[[1,1.87,98.24],[2,1.88,70.33]],"ltp":1.87,"tv":13848.5,"id":17336468}]}]}
{"op":"mcm","clk":"992903496","pt":1580559721143,"mc":[{"id":"1.168136214","rc":[{"batb":[[2,1.83,62.3]],"ltp":1.87,"tv":13848.5,"id":17336468}]}]}
{"op":"mcm","clk":"992904465","pt":1580559726122,"mc":[{"id":"1.168136214","rc":[{"batb":[[0,4.7,20.62],[1,4.6,20.59],[2,4.5,22.27]],"ltp":4.7,"tv":5329.91,"id":12925630},{"batb":[[0,1.85,39.73]],"ltp":1.87,"tv":13848.5,"id":17336468},{"trd":[[4,1319.99]],"batb":[[0,3.95,25.67],[1,3.9,33.76],[2,3.85,7.03]],"batl":[[0,4,358.28],[1,4.1,306],[2,4.2,47.51]],"ltp":4.0,"tv":4877.02,"id":11981493}],"tv":24055.44}]}
{"op":"mcm","clk":"992904658","pt":1580559727146,"mc":[{"id":"1.168136214","rc":[{"trd":[[4.7,201.56]],"batb":[[0,4.7,10.63],[1,4.6,29.03]],"batl":[[0,4.8,12.57]],"ltp":4.7,"tv":5349.9,"id":12925630},{"batb":[[1,3.9,20.56]],"ltp":4.0,"tv":4877.02,"id":11981493}],"tv":24075.43}]}
{"op":"mcm","clk":"992904846","pt":1580559728145,"mc":[{"id":"1.168136214","rc":[{"batb":[[0,4.7,19.28]],"ltp":4.7,"tv":5349.9,"id":12925630},{"batl":[[1,1.87,75.66]],"ltp":1.87,"tv":13848.5,"id":17336468}]}]}
{"op":"mcm","clk":"992905011","pt":1580559729153,"mc":[{"id":"1.168136214","rc":[{"batb":[[0,4.7,10.63]],"ltp":4.7,"tv":5349.9,"id":12925630},{"batl":[[2,1.88,70.13]],"ltp":1.87,"tv":13848.5,"id":17336468}]}]}
{"op":"mcm","clk":"992905378","pt":1580559731108,"mc":[{"id":"1.168136214","rc":[{"batl":[[0,1.86,4.2]],"ltp":1.87,"tv":13848.5,"id":17336468}]}]}
{"op":"mcm","clk":"992905590","pt":1580559732128,"mc":[{"id":"1.168136214","rc":[{"batb":[[0,3.95,38.67]],"ltp":4.0,"tv":4877.02,"id":11981493}]}]}
{"op":"mcm","clk":"992905797","pt":1580559733151,"mc":[{"id":"1.168136214","rc":[{"batl":[[2,4.2,40.79]],"ltp":4.0,"tv":4877.02,"id":11981493}]}]}
{"op":"mcm","clk":"992905968","pt":1580559734123,"mc":[{"id":"1.168136214","rc":[{"batb":[[1,4.6,34.64]],"ltp":4.7,"tv":5349.9,"id":12925630}]}]}
{"op":"mcm","clk":"992906128","pt":1580559735034,"mc":[{"id":"1.168136214","rc":[{"batb":[[0,4.7,18.22]],"batl":[[0,4.8,5]],"ltp":4.7,"tv":5349.9,"id":12925630},{"trd":[[1.86,8.4]],"batb":[[0,1.86,23.39],[1,1.85,39.73],[2,1.84,37.03]],"batl":[[0,1.87,53.08],[1,1.88,63.5],[2,1.89,919]],"ltp":1.86,"tv":13856.9,"id":17336468},{"trd":[[3.95,555.44]],"batb":[[0,3.9,13.6],[1,3.85,14.1],[2,3.8,28.93]],"batl":[[0,3.95,319.62],[1,4,6.08],[2,4.1,306]],"ltp":3.95,"tv":4954.35,"id":11981493}],"tv":24161.16}]}
{"op":"mcm","clk":"992906283","pt":1580559735854,"mc":[{"id":"1.168136214","rc":[{"trd":[[3.95,565.44]],"batl":[[0,3.95,314.62]],"ltp":3.95,"tv":4964.35,"id":11981493}],"tv":24171.16}]}
{"op":"mcm","clk":"992906501","pt":1580559737047,"mc":[{"id":"1.168136214","rc":[{"batl":[[0,1.87,29.08]],"ltp":1.86,"tv":13856.9,"id":17336468},{"batb":[[0,3.9,7.6]],"ltp":3.95,"tv":4964.35,"id":11981493}]}]}
{"op":"mcm","clk":"992906697","pt":1580559738066,"mc":[{"id":"1.168136214","rc":[{"batb":[[0,1.86,28.39]],"ltp":1.86,"tv":13856.9,"id":17336468}]}]}
{"op":"mcm","clk":"992906901","pt":1580559739042,"mc":[{"id":"1.168136214","rc":[{"batl":[[2,4.1,312.72]],"ltp":3.95,"tv":4964.35,"id":11981493}]}]}
{"op":"mcm","clk":"992907296","pt":1580559741151,"mc":[{"id":"1.168136214","rc":[{"batb":[[0,4.7,20.22],[2,4.5,20.27]],"ltp":4.7,"tv":5349.9,"id":12925630},{"trd":[[1.86,24.39]],"batb":[[0,1.86,5]],"batl":[[1,1.88,55.5]],"ltp":1.86,"tv":13872.89,"id":17336468},{"batb":[[0,3.9,16.6]],"ltp":3.95,"tv":4964.35,"id":11981493}],"tv":24187.15}]}
{"op":"mcm","clk":"992907464","pt":1580559742077,"mc":[{"id":"1.168136214","rc":[{"batl":[[0,1.87,34.08]],"ltp":1.86,"tv":13872.89,"id":17336468},{"batb":[[2,3.8,18.07]],"batl":[[2,4.1,306]],"ltp":3.95,"tv":4964.35,"id":11981493}]}]}
{"op":"mcm","clk":"992907664","pt":1580559743149,"mc":[{"id":"1.168136214","rc":[{"batb":[[2,1.84,42.03]],"ltp":1.86,"tv":13872.89,"id":17336468}]}]}
{"op":"mcm","clk":"992907828","pt":1580559744077,"mc":[{"id":"1.168136214","rc":[{"batl":[[1,1.88,53.5]],"ltp":1.86,"tv":13872.89,"id":17336468}]}]}
{"op":"mcm","clk":"992908052","pt":1580559745144,"mc":[{"id":"1.168136214","rc":[{"batl":[[0,1.87,36.08]],"ltp":1.86,"tv":13872.89,"id":17336468}]}]}
{"op":"mcm","clk":"992908569","pt":1580559748152,"mc":[{"id":"1.168136214","rc":[{"batl":[[1,4,12.8]],"ltp":3.95,"tv":4964.35,"id":11981493}]}]}
{"op":"mcm","clk":"992908738","pt":1580559749070,"mc":[{"id":"1.168136214","rc":[{"trd":[[3.95,567.98]],"batl":[[0,3.95,313.35]],"ltp":3.95,"tv":4966.89,"id":11981493}],"tv":24189.69}]}
{"op":"mcm","clk":"992908899","pt":1580559750048,"mc":[{"id":"1.168136214","rc":[{"trd":[[4.7,209.56]],"batb":[[0,4.7,16.22]],"ltp":4.7,"tv":5357.9,"id":12925630},{"batl":[[1,4,17.4]],"ltp":3.95,"tv":4966.89,"id":11981493}],"tv":24197.69}]}
{"op":"mcm","clk":"992909095","pt":1580559751069,"mc":[{"id":"1.168136214","rc":[{"batb":[[0,4.7,22.59]],"ltp":4.7,"tv":5357.9,"id":12925630},{"batb":[[0,1.86,27.64]],"ltp":1.86,"tv":13872.89,"id":17336468},{"batl":[[0,3.95,319.35]],"ltp":3.95,"tv":4966.89,"id":11981493}]}]}
{"op":"mcm","clk":"992909189","pt":1580559751551,"mc":[{"id":"1.168136214","rc":[{"trd":[[1.86,28.39]],"batb":[[0,1.86,25.64]],"batl":[[0,1.87,84.73]],"ltp":1.86,"tv":13876.89,"id":17336468}],"tv":24201.69}]}
{"op":"mcm","clk":"992909804","pt":1580559755063,"mc":[{"id":"1.168136214","rc":[{"trd":[[1.85,5.72],[1.86,79.69]],"batb":[[0,1.85,36.87],[1,1.84,42.03],[2,1.83,71.1]],"batl":[[0,1.87,55.65],[1,1.88,51.25]],"ltp":1.85,"tv":13933.91,"id":17336468}],"tv":24258.7}]}
{"op":"mcm","clk":"992910591","pt":1580559759102,"mc":[{"id":"1.168136214","rc":[{"batb":[[1,4.6,39.79]],"ltp":4.7,"tv":5357.9,"id":12925630}]}]}
{"op":"mcm","clk":"992911320","pt":1580559763098,"mc":[{"id":"1.168136214","rc":[{"trd":[[3.9,234.71]],"batb":[[0,3.9,11.61]],"ltp":3.9,"tv":4976.88,"id":11981493}],"tv":24268.7}]}
{"op":"mcm","clk":"992911728","pt":1580559765128,"mc":[{"id":"1.168136214","rc":[{"trd":[[3.9,244.7]],"batb":[[0,3.9,6.61],[1,3.85,7.03],[2,3.8,25.27]],"ltp":3.9,"tv":4986.88,"id":11981493}],"tv":24278.7}]}
{"op":"mcm","clk":"992911888","pt":1580559765889,"mc":[{"id":"1.168136214","rc":[{"batl":[[0,1.87,55.85]],"ltp":1.85,"tv":13933.91,"id":17336468}]}]}
{"op":"mcm","clk":"992912971","pt":1580559771099,"mc":[{"id":"1.168136214","rc":[{"trd":[[4.8,40.02]],"batb":[[0,4.8,20.77],[1,4.7,22.59],[2,4.6,39.79]],"batl":[[0,5,20.71],[1,5.1,4],[2,5.2,14.3]],"ltp":4.8,"tv":5367.89,"id":12925630},{"trd":[[1.86,106.87]],"batb":[[0,1.85,24.87]],"batl":[[0,1.87,79.85]],"ltp":1.86,"tv":13961.09,"id":17336468}],"tv":24315.87}]}
{"op":"mcm","clk":"992913180","pt":1580559772110,"mc":[{"id":"1.168136214","rc":[{"batb":[[1,4.7,31.03],[2,4.6,31.34]],"batl":[[2,5.2,21.54]],"ltp":4.8,"tv":5367.89,"id":12925630},{"batb":[[1,1.84,18.03]],"batl":[[0,1.86,9.31],[1,1.87,79.85],[2,1.88,51.25]],"ltp":1.86,"tv":13961.09,"id":17336468}]}]}
{"op":"mcm","clk":"992913368","pt":1580559773126,"mc":[{"id":"1.168136214","rc":[{"batb":[[0,4.8,29.25]],"batl":[[0,5,15.77],[1,5.1,7.29]],"ltp":4.8,"tv":5367.89,"id":12925630},{"batl":[[1,4,22.78]],"ltp":3.9,"tv":4986.88,"id":11981493}]}]}
{"op":"mcm","clk":"992913524","pt":1580559773941,"mc":[{"id":"1.168136214","rc":[{"batl":[[1,4,18.18]],"ltp":3.9,"tv":4986.88,"id":11981493}]}]}
{"op":"mcm","clk":"992914158","pt":1580559777137,"mc":[{"id":"1.168136214","rc":[{"batl":[[0,5,23.24]],"ltp":4.8,"tv":5367.89,"id":12925630},{"trd":[[1.86,125.49]],"batb":[[0,1.86,35.69],[1,1.85,24.87],[2,1.84,18.03]],"batl":[[0,1.87,79.85],[1,1.88,51.25],[2,1.89,919]],"ltp":1.86,"tv":13979.71,"id":17336468}],"tv":24334.49}]}
{"op":"mcm","clk":"992914330","pt":1580559778133,"mc":[{"id":"1.168136214","rc":[{"batb":[[1,4.7,22.59]],"batl":[[2,5.2,14.3]],"ltp":4.8,"tv":5367.89,"id":12925630}]}]}
{"op":"mcm","clk":"992914499","pt":1580559779138,"mc":[{"id":"1.168136214","rc":[{"batb":[[0,4.8,20.77],[1,4.7,28.04]],"ltp":4.8,"tv":5367.89,"id":12925630}]}]}
{"op":"mcm","clk":"992914678","pt":1580559780151,"mc":[{"id":"1.168136214","rc":[{"trd":[[1.86,143.49]],"batb":[[0,1.86,26.69]],"ltp":1.86,"tv":13997.71,"id":17336468}],"tv":24352.49}]}
{"op":"mcm","clk":"992915096","pt":1580559782141,"mc":[{"id":"1.168136214","rc":[{"batb":[[2,4.6,38.99]],"ltp":4.8,"tv":5367.89,"id":12925630}]}]}
{"op":"mcm","clk":"992915283","pt":1580559783151,"mc":[{"id":"1.168136214","rc":[{"trd":[[1.86,146.85]],"batb":[[0,1.86,25.01]],"ltp":1.86,"tv":14001.07,"id":17336468},{"trd":[[3.9,255.4]],"batb":[[0,3.9,1.26]],"ltp":3.9,"tv":4997.58,"id":11981493}],"tv":24366.55}]}
{"op":"mcm","clk":"992915492","pt":1580559784126,"mc":[{"id":"1.168136214","rc":[{"trd":[[1.87,129.27]],"batb":[[1,1.85,36.87],[2,1.84,42.03]],"batl":[[0,1.87,78.18]],"ltp":1.87,"tv":14004.41,"id":17336468},{"trd":[[3.9,257.92]],"batb":[[0,3.8,18.07],[1,3.75,47.83],[2,3.7,25]],"batl":[[0,3.9,6.01],[1,3.95,319.35],[2,4,18.18]],"ltp":3.9,"tv":5000.1,"id":11981493}],"tv":24372.41}]}
{"op":"mcm","clk":"992915671","pt":1580559785152,"mc":[{"id":"1.168136214","rc":[{"batl":[[0,5,12.52]],"ltp":4.8,"tv":5367.89,"id":12925630},{"batb":[[0,3.8,7],[1,3.75,40.49],[2,3.7,32.47]],"ltp":3.9,"tv":5000.1,"id":11981493}]}]}
{"op":"mcm","clk":"992916224","pt":1580559788055,"mc":[{"id":"1.168136214","rc":[{"batl":[[0,3.9,26.27]],"ltp":3.9,"tv":5000.1,"id":11981493}]}]}
{"op":"mcm","clk":"992916623","pt":1580559790104,"mc":[{"id":"1.168136214","rc":[{"trd":[[1.87,149.71]],"batl":[[0,1.87,67.97]],"ltp":1.87,"tv":14024.84,"id":17336468},{"batb":[[0,3.8,23.04]],"batl":[[2,4,26.16]],"ltp":3.9,"tv":5000.1,"id":11981493}],"tv":24392.85}]}
{"op":"mcm","clk":"992916952","pt":1580559791878,"mc":[{"id":"1.168136214","rc":[{"batl":[[0,5,13.19]],"ltp":4.8,"tv":5367.89,"id":12925630}]}]}
{"op":"mcm","clk":"992917370","pt":1580559794074,"mc":[{"id":"1.168136214","rc":[{"batl":[[1,5.1,13.13]],"ltp":4.8,"tv":5367.89,"id":12925630},{"trd":[[1.86,154.85]],"batb":[[0,1.86,21.01]],"ltp":1.86,"tv":14032.84,"id":17336468},{"batb":[[0,3.85,50],[1,3.8,23.04],[2,3.75,40.49]],"ltp":3.9,"tv":5000.1,"id":11981493}],"tv":24400.85}]}
{"op":"mcm","clk":"992917733","pt":1580559795986,"mc":[{"id":"1.168136214","rc":[{"batl":[[2,4,19.44]],"ltp":3.9,"tv":5000.1,"id":11981493}]}]}
{"op":"mcm","clk":"992917925","pt":1580559796965,"mc":[{"id":"1.168136214","rc":[{"batl":[[0,5,16.19]],"ltp":4.8,"tv":5367.89,"id":12925630},{"trd":[[1.86,196.87]],"batb":[[0,1.85,36.87],[1,1.84,42.03],[2,1.83,71.1]],"batl":[[0,1.86,14.07],[1,1.87,67.77],[2,1.88,51.25]],"ltp":1.86,"tv":14074.86,"id":17336468}],"tv":24442.87}]}
{"op":"mcm","clk":"992918033","pt":1580559797554,"mc":[{"id":"1.168136214","rc":[{"batb":[[2,3.75,47.83]],"ltp":3.9,"tv":5000.1,"id":11981493}]}]}
{"op":"mcm","clk":"992918279","pt":1580559799086,"mc":[{"id":"1.168136214","rc":[{"trd":[[1.86,224.99]],"batb":[[0,1.86,36.6],[1,1.85,36.87],[2,1.84,42.03]],"batl":[[0,1.87,67.77],[1,1.88,51.25],[2,1.89,919]],"ltp":1.86,"tv":14102.99,"id":17336468}],"tv":24470.99}]}
{"op":"mcm","clk":"992918470","pt":1580559800079,"mc":[{"id":"1.168136214","rc":[{"trd":[[1.86,232.99]],"batb":[[0,1.86,32.6]],"ltp":1.86,"tv":14110.98,"id":17336468}],"tv":24478.99}]}
{"op":"mcm","clk":"992918872","pt":1580559802107,"mc":[{"id":"1.168136214","rc":[{"trd":[[4.8,52.49]],"batb":[[0,4.8,8.3]],"batl":[[0,4.9,8.13],[1,5,15.52],[2,5.1,13.13]],"ltp":4.8,"tv":5380.37,"id":12925630},{"trd":[[1.87,285.69],[1.88,224.31]],"batb":[[0,1.86,55.39],[2,1.84,47]],"batl":[[0,1.88,16],[1,1.89,919],[2,1.9,20.54]],"ltp":1.88,"tv":14381.35,"id":17336468},{"trd":[[3.85,494.03],[3.9,310.48],[3.95,618.7]],"batb":[[0,3.85,41.44],[1,3.8,30.24]],"batl":[[0,3.95,293.99],[1,4,19.44],[2,4.1,300]],"ltp":3.95,"tv":5118.94,"id":11981493}],"tv":24880.67}]}
{"op":"mcm","clk":"992919024","pt":1580559802975,"mc":[{"id":"1.168136214","rc":[{"batb":[[2,4.6,47.43]],"batl":[[1,5,20.4]],"ltp":4.8,"tv":5380.37,"id":12925630}]}]}
{"op":"mcm","clk":"992919218","pt":1580559804111,"mc":[{"id":"1.168136214","rc":[{"batl":[[1,5,27.81]],"ltp":4.8,"tv":5380.37,"id":12925630}]}]}
{"op":"mcm","clk":"992919406","pt":1580559805094,"mc":[{"id":"1.168136214","rc":[{"trd":[[4.8,53.83]],"batb":[[0,4.8,7.63]],"batl":[[0,4.9,7.46]],"ltp":4.8,"tv":5381.71,"id":12925630}],"tv":24882.01}]}
{"op":"mcm","clk":"992919558","pt":1580559805882,"mc":[{"id":"1.168136214","rc":[{"batb":[[0,4.7,9.59],[1,4.6,34.43],[2,4.5,7.13]],"ltp":4.8,"tv":5381.71,"id":12925630},{"batb":[[1,3.8,34.24]],"ltp":3.95,"tv":5118.94,"id":11981493}]}]}
{"op":"mcm","clk":"992919792","pt":1580559807084,"mc":[{"id":"1.168136214","rc":[{"batb":[[0,4.8,10.14],[1,4.7,20.59],[2,4.6,43.28]],"ltp":4.8,"tv":5381.71,"id":12925630}]}]}
{"op":"mcm","clk":"992919982","pt":1580559808109,"mc":[{"id":"1.168136214","rc":[{"batl":[[0,1.88,38.7]],"ltp":1.88,"tv":14381.35,"id":17336468},{"batl":[[0,3.9,9.22],[1,3.95,293.99],[2,4,26.16]],"ltp":3.95,"tv":5118.94,"id":11981493}]}]}
{"op":"mcm","clk":"992920095","pt":1580559808700,"mc":[{"id":"1.168136214","rc":[{"batb":[[2,4.6,34.84]],"ltp":4.8,"tv":5381.71,"id":12925630}]}]}
{"op":"mcm","clk":"992920374","pt":1580559810121,"mc":[{"id":"1.168136214","rc":[{"trd":[[3.85,514.03]],"batb":[[0,3.85,31.44]],"ltp":3.85,"tv":5138.94,"id":11981493}],"tv":24902.01}]}
{"op":"mcm","clk":"992920983","pt":1580559813117,"mc":[{"id":"1.168136214","rc":[{"batb":[[0,3.85,51.7]],"ltp":3.85,"tv":5138.94,"id":11981493}]}]}
{"op":"mcm","clk":"992921393","pt":1580559815141,"mc":[{"id":"1.168136214","rc":[{"batb":[[1,4.7,26.04]],"ltp":4.8,"tv":5381.71,"id":12925630},{"batb":[[0,3.85,71.7]],"batl":[[2,4,19.44]],"ltp":3.85,"tv":5138.94,"id":11981493}]}]}
{"op":"mcm","clk":"992921772","pt":1580559817131,"mc":[{"id":"1.168136214","rc":[{"batb":[[0,3.85,91.7]],"ltp":3.85,"tv":5138.94,"id":11981493}]}]}
{"op":"mcm","clk":"992922179","pt":1580559819149,"mc":[{"id":"1.168136214","rc":[{"batl":[[0,1.88,47.7]],"ltp":1.88,"tv":14381.35,"id":17336468}]}]}
{"op":"mcm","clk":"992922540","pt":1580559821146,"mc":[{"id":"1.168136214","rc":[{"batl":[[1,3.95,300.71]],"ltp":3.85,"tv":5138.94,"id":11981493}]}]}
{"op":"mcm","clk":"992922909","pt":1580559823119,"mc":[{"id":"1.168136214","rc":[{"trd":[[1.88,228.31]],"batl":[[0,1.88,45.7]],"ltp":1.88,"tv":14385.35,"id":17336468}],"tv":24906.01}]}
{"op":"mcm","clk":"992923973","pt":1580559829057,"mc":[{"id":"1.168136214","rc":[{"batl":[[0,1.87,7],[1,1.88,45.7],[2,1.89,919]],"ltp":1.88,"tv":14385.35,"id":17336468}]}]}
{"op":"mcm","clk":"992924153","pt":1580559830056,"mc":[{"id":"1.168136214","rc":[{"batl":[[0,3.9,11.22]],"ltp":3.85,"tv":5138.94,"id":11981493}]}]}
{"op":"mcm","clk":"992925013","pt":1580559835053,"mc":[{"id":"1.168136214","rc":[{"trd":[[1.87,299.69],[1.88,234.31]],"batl":[[0,1.88,42.7],[1,1.89,919],[2,1.9,20.54]],"ltp":1.88,"tv":14405.35,"id":17336468}],"tv":24926.01}]}
{"op":"mcm","clk":"992925212","pt":1580559836087,"mc":[{"id":"1.168136214","rc":[{"trd":[[1.86,289.77]],"batb":[[0,1.86,4.22]],"ltp":1.86,"tv":14462.13,"id":17336468},{"batl":[[0,3.9,2]],"ltp":3.85,"tv":5138.94,"id":11981493}],"tv":24982.79}]}
{"op":"mcm","clk":"992925410","pt":1580559837093,"mc":[{"id":"1.168136214","rc":[{"batb":[[1,4.7,34.26]],"ltp":4.8,"tv":5381.71,"id":12925630},{"batl":[[0,1.87,17.51],[1,1.88,42.7],[2,1.89,919]],"ltp":1.86,"tv":14462.13,"id":17336468},{"batl":[[1,3.95,293.99]],"ltp":3.85,"tv":5138.94,"id":11981493}]}]}
{"op":"mcm","clk":"992925583","pt":1580559838102,"mc":[{"id":"1.168136214","rc":[{"trd":[[1.86,302.22]],"batb":[[0,1.85,36.87],[1,1.84,47],[2,1.83,84.85]],"batl":[[0,1.86,2.77],[1,1.87,17.51],[2,1.88,33.7]],"ltp":1.86,"tv":14474.58,"id":17336468},{"batl":[[2,4,30.12]],"ltp":3.85,"tv":5138.94,"id":11981493}],"tv":24995.24}]}
{"op":"mcm","clk":"992925778","pt":1580559839103,"mc":[{"id":"1.168136214","rc":[{"trd":[[1.86,307.16]],"batl":[[0,1.87,17.81],[1,1.88,43.53],[2,1.89,919]],"ltp":1.86,"tv":14479.52,"id":17336468},{"batb":[[0,3.85,108.69]],"batl":[[0,3.9,4]],"ltp":3.85,"tv":5138.94,"id":11981493}],"tv":25000.18}]}
{"op":"mcm","clk":"992926357","pt":1580559842111,"mc":[{"id":"1.168136214","rc":[{"trd":[[1.85,5.92]],"batb":[[0,1.85,24.77]],"ltp":1.85,"tv":14479.72,"id":17336468},{"trd":[[3.85,514.23]],"batb":[[0,3.85,108.59]],"batl":[[2,4,36.84]],"ltp":3.85,"tv":5139.14,"id":11981493}],"tv":25000.58}]}
{"op":"mcm","clk":"992926745","pt":1580559844108,"mc":[{"id":"1.168136214","rc":[{"batl":[[0,5,27.81],[1,5.1,13.13],[2,5.2,14.3]],"ltp":4.8,"tv":5381.71,"id":12925630},{"batb":[[0,1.85,37.77],[1,1.84,23]],"batl":[[0,1.86,30.38],[1,1.87,17.51],[2,1.88,43.53]],"ltp":1.85,"tv":14479.72,"id":17336468},{"trd":[[3.9,314.48]],"batl":[[0,3.9,2]],"ltp":3.9,"tv":5143.14,"id":11981493}],"tv":25004.58}]}
{"op":"mcm","clk":"992926922","pt":1580559845103,"mc":[{"id":"1.168136214","rc":[{"batl":[[0,5,22.93]],"ltp":4.8,"tv":5381.71,"id":12925630},{"batb":[[1,3.8,36.24]],"ltp":3.9,"tv":5143.14,"id":11981493}]}]}
{"op":"mcm","clk":"992927038","pt":1580559845729,"mc":[{"id":"1.168136214","rc":[{"batl":[[1,5.1,7.29]],"ltp":4.8,"tv":5381.71,"id":12925630}]}]}
{"op":"mcm","clk":"992927665","pt":1580559849130,"mc":[{"id":"1.168136214","rc":[{"batb":[[0,4.8,25.21]],"ltp":4.8,"tv":5381.71,"id":12925630},{"trd":[[1.85,25.87]],"batb":[[0,1.85,27.8]],"ltp":1.85,"tv":14499.67,"id":17336468},{"trd":[[3.85,534.19]],"batb":[[0,3.85,91.61]],"batl":[[0,3.9,11.25]],"ltp":3.85,"tv":5163.1,"id":11981493}],"tv":25044.49}]}
{"op":"mcm","clk":"992927857","pt":1580559850110,"mc":[{"id":"1.168136214","rc":[{"batl":[[0,5,12.52]],"ltp":4.8,"tv":5381.71,"id":12925630},{"batb":[[0,1.85,14.8]],"batl":[[1,1.87,68.16]],"ltp":1.85,"tv":14499.67,"id":17336468}]}]}
{"op":"mcm","clk":"992928044","pt":1580559851133,"mc":[{"id":"1.168136214","rc":[{"batb":[[2,4.6,25.99]],"ltp":4.8,"tv":5381.71,"id":12925630}]}]}
{"op":"mcm","clk":"992929064","pt":1580559856151,"mc":[{"id":"1.168136214","rc":[{"trd":[[1.85,55.49]],"batb":[[0,1.84,23],[1,1.83,84.85],[2,1.82,37.59]],"batl":[[0,1.85,5.18],[1,1.86,195.38],[2,1.87,68.16]],"ltp":1.85,"tv":14529.3,"id":17336468},{"batl":[[0,3.9,2],[2,4,30.12]],"ltp":3.85,"tv":5163.1,"id":11981493}],"tv":25074.11}]}
{"op":"mcm","clk":"992929243","pt":1580559856974,"mc":[{"id":"1.168136214","rc":[{"batb":[[0,1.84,9],[1,1.83,62.3]],"ltp":1.85,"tv":14529.3,"id":17336468},{"batb":[[0,3.85,104.61]],"ltp":3.85,"tv":5163.1,"id":11981493}]}]}
{"op":"mcm","clk":"992930245","pt":1580559862059,"mc":[{"id":"1.168136214","rc":[{"batb":[[0,3.85,111.61]],"batl":[[2,4,36.84]],"ltp":3.85,"tv":5163.1,"id":11981493}]}]}
{"op":"mcm","clk":"992930601","pt":1580559864057,"mc":[{"id":"1.168136214","rc":[{"trd":[[3.85,634.17]],"batb":[[0,3.85,61.63]],"ltp":3.85,"tv":5263.08,"id":11981493}],"tv":25174.09}]}
{"op":"mcm","clk":"992930788","pt":1580559865092,"mc":[{"id":"1.168136214","rc":[{"batb":[[0,4.8,30.15]],"batl":[[0,5,5.05]],"ltp":4.8,"tv":5381.71,"id":12925630},{"batb":[[1,1.83,38]],"ltp":1.85,"tv":14529.3,"id":17336468}]}]}
{"op":"mcm","clk":"992930991","pt":1580559866076,"mc":[{"id":"1.168136214","rc":[{"batb":[[1,4.7,26.04]],"ltp":4.8,"tv":5381.71,"id":12925630}]}]}
{"op":"mcm","clk":"992931374","pt":1580559868094,"mc":[{"id":"1.168136214","rc":[{"trd":[[4.9,32.62]],"batb":[[0,4.9,4.47],[1,4.8,30.15],[2,4.7,26.04]],"ltp":4.9,"tv":5387.7,"id":12925630},{"trd":[[1.84,10.36]],"batb":[[0,1.84,3.82]],"batl":[[0,1.86,195.38],[1,1.87,17.51],[2,1.88,42.04]],"ltp":1.84,"tv":14539.66,"id":17336468}],"tv":25190.45}]}
{"op":"mcm","clk":"992931506","pt":1580559868803,"mc":[{"id":"1.168136214","rc":[{"batb":[[0,4.9,14.62]],"batl":[[0,5,12.52]],"ltp":4.9,"tv":5387.7,"id":12925630},{"trd":[[1.86,347.16]],"batl":[[0,1.86,175.38]],"ltp":1.86,"tv":14579.66,"id":17336468}],"tv":25230.45}]}
{"op":"mcm","clk":"992931774","pt":1580559870071,"mc":[{"id":"1.168136214","rc":[{"batl":[[0,5,16.11]],"ltp":4.9,"tv":5387.7,"id":12925630},{"batb":[[1,1.83,43]],"batl":[[0,1.85,50.65],[1,1.86,180.38],[2,1.87,17.51]],"ltp":1.86,"tv":14579.66,"id":17336468}]}]}
{"op":"mcm","clk":"992932326","pt":1580559873004,"mc":[{"id":"1.168136214","rc":[{"batl":[[0,1.85,50.85]],"ltp":1.86,"tv":14579.66,"id":17336468}]}]}
{"op":"mcm","clk":"992932909","pt":1580559876116,"mc":[{"id":"1.168136214","rc":[{"batb":[[1,4.8,35.46]],"ltp":4.9,"tv":5387.7,"id":12925630}]}]}
{"op":"mcm","clk":"992933131","pt":1580559877092,"mc":[{"id":"1.168136214","rc":[{"batb":[[1,1.83,53]],"ltp":1.86,"tv":14579.66,"id":17336468}]}]}
{"op":"mcm","clk":"992933329","pt":1580559878115,"mc":[{"id":"1.168136214","rc":[{"batb":[[0,1.84,54.47]],"ltp":1.86,"tv":14579.66,"id":17336468}]}]}
{"op":"mcm","clk":"992933507","pt":1580559879146,"mc":[{"id":"1.168136214","rc":[{"batl":[[2,1.87,17.31]],"ltp":1.86,"tv":14579.66,"id":17336468}]}]}
{"op":"mcm","clk":"992934465","pt":1580559884108,"mc":[{"id":"1.168136214","rc":[{"batb":[[1,4.8,43.46]],"ltp":4.9,"tv":5387.7,"id":12925630}]}]}
{"op":"mcm","clk":"992935269","pt":1580559888098,"mc":[{"id":"1.168136214","rc":[{"batl":[[0,1.85,56.85]],"ltp":1.86,"tv":14579.66,"id":17336468}]}]}
{"op":"mcm","clk":"992935425","pt":1580559889001,"mc":[{"id":"1.168136214","rc":[{"batl":[[0,5,11.11]],"ltp":4.9,"tv":5387.7,"id":12925630}]}]}
{"op":"mcm","clk":"992937134","pt":1580559898118,"mc":[{"id":"1.168136214","rc":[{"trd":[[5,18]],"batl":[[0,5.1,7.29],[1,5.2,14.3],[2,5.3,22.19]],"ltp":5.0,"tv":5398.81,"id":12925630},{"trd":[[1.85,85.5]],"batl":[[0,1.85,26.85]],"ltp":1.85,"tv":14609.66,"id":17336468},{"trd":[[3.85,771.86]],"batb":[[0,3.8,36.24],[1,3.75,47.83],[2,3.7,25]],"batl":[[0,3.85,211.93],[1,3.9,2],[2,3.95,6]],"ltp":3.85,"tv":5400.77,"id":11981493}],"tv":25409.25}]}
{"op":"mcm","clk":"992937297","pt":1580559899139,"mc":[{"id":"1.168136214","rc":[{"batb":[[0,5,8.13],[1,4.9,14.62],[2,4.8,50.94]],"batl":[[0,5.1,4.29],[1,5.2,17.3]],"ltp":5.0,"tv":5398.81,"id":12925630},{"batb":[[0,1.84,66.47]],"ltp":1.85,"tv":14609.66,"id":17336468},{"batb":[[0,3.8,22.04],[2,3.7,31]],"batl":[[1,3.9,10.32]],"ltp":3.85,"tv":5400.77,"id":11981493}]}]}
{"op":"mcm","clk":"992937499","pt":1580559900148,"mc":[{"id":"1.168136214","rc":[{"trd":[[5,27.99],[5.1,90.56]],"batb":[[0,5,12.45]],"batl":[[0,5.2,17.3],[1,5.3,22.19],[2,5.7,44]],"ltp":5.1,"tv":5410.81,"id":12925630},{"batl":[[1,1.86,170]],"ltp":1.85,"tv":14609.66,"id":17336468}],"tv":25421.25}]}
{"op":"mcm","clk":"992937737","pt":1580559901141,"mc":[{"id":"1.168136214","rc":[{"batb":[[0,5,19.86]],"batl":[[0,5.1,3.61],[1,5.2,17.3],[2,5.3,25.19]],"ltp":5.1,"tv":5410.81,"id":12925630},{"batl":[[0,1.85,56.22]],"ltp":1.85,"tv":14609.66,"id":17336468},{"trd":[[3.85,775.86]],"batb":[[0,3.8,31.52],[1,3.75,42.16]],"batl":[[0,3.85,217.93]],"ltp":3.85,"tv":5404.77,"id":11981493}],"tv":25425.25}]}
{"op":"mcm","clk":"992937915","pt":1580559902097,"mc":[{"id":"1.168136214","rc":[{"batb":[[2,4.8,42.94]],"ltp":5.1,"tv":5410.81,"id":12925630}]}]}
{"op":"mcm","clk":"992938099","pt":1580559903082,"mc":[{"id":"1.168136214","rc":[{"batb":[[1,4.9,22.62]],"ltp":5.1,"tv":5410.81,"id":12925630},{"trd":[[1.85,131.35]],"batl":[[0,1.85,33.3]],"ltp":1.85,"tv":14655.52,"id":17336468}],"tv":25471.11}]}
{"op":"mcm","clk":"992938285","pt":1580559904117,"mc":[{"id":"1.168136214","rc":[{"batb":[[0,3.8,15.48]],"ltp":3.85,"tv":5404.77,"id":11981493}]}]}
{"op":"mcm","clk":"992938649","pt":1580559906016,"mc":[{"id":"1.168136214","rc":[{"batb":[[1,3.75,64.16]],"ltp":3.85,"tv":5404.77,"id":11981493}]}]}
{"op":"mcm","clk":"992938829","pt":1580559906883,"mc":[{"id":"1.168136214","rc":[{"batb":[[1,4.9,27.78]],"ltp":5.1,"tv":5410.81,"id":12925630}]}]}
{"op":"mcm","clk":"992939311","pt":1580559909099,"mc":[{"id":"1.168136214","rc":[{"batb":[[0,1.84,54.47]],"batl":[[0,1.85,33.5]],"ltp":1.85,"tv":14655.52,"id":17336468},{"batl":[[0,3.9,10.32],[1,3.95,215.93],[2,4,19.44]],"ltp":3.85,"tv":5404.77,"id":11981493}]}]}
{"op":"mcm","clk":"992939458","pt":1580559909911,"mc":[{"id":"1.168136214","rc":[{"batb":[[0,5,16.73]],"ltp":5.1,"tv":5410.81,"id":12925630}]}]}
{"op":"mcm","clk":"992939691","pt":1580559911107,"mc":[{"id":"1.168136214","rc":[{"trd":[[1.85,139.35]],"batl":[[0,1.85,29.5]],"ltp":1.85,"tv":14663.52,"id":17336468},{"batb":[[0,3.8,20.48]],"ltp":3.85,"tv":5404.77,"id":11981493}],"tv":25479.11}]}
{"op":"mcm","clk":"992939905","pt":1580559912088,"mc":[{"id":"1.168136214","rc":[{"trd":[[1.85,185.25]],"batl":[[0,1.85,6.55]],"ltp":1.85,"tv":14709.42,"id":17336468},{"batl":[[1,3.95,222.65]],"ltp":3.85,"tv":5404.77,"id":11981493}],"tv":25525.01}]}
{"op":"mcm","clk":"992940876","pt":1580559917014,"mc":[{"id":"1.168136214","rc":[{"batl":[[0,1.85,12.55]],"ltp":1.85,"tv":14709.42,"id":17336468}]}]}
{"op":"mcm","clk":"992941278","pt":1580559919120,"mc":[{"id":"1.168136214","rc":[{"trd":[[5,35.54]],"batb":[[0,5,9.18]],"ltp":5.0,"tv":5418.36,"id":12925630},{"trd":[[1.84,30.86]],"batb":[[0,1.84,33.97]],"ltp":1.84,"tv":14729.92,"id":17336468},{"trd":[[3.9,344.8]],"batl":[[0,3.95,222.65],[1,4,19.44],[2,4.1,300]],"ltp":3.9,"tv":5435.09,"id":11981493}],"tv":25583.38}]}
{"op":"mcm","clk":"992941427","pt":1580559920110,"mc":[{"id":"1.168136214","rc":[{"batb":[[0,5,7],[1,4.9,22.62]],"batl":[[0,5.1,11.03]],"ltp":5.0,"tv":5418.36,"id":12925630},{"batl":[[0,1.85,36.38]],"ltp":1.84,"tv":14729.92,"id":17336468},{"batb":[[0,3.85,9.41],[1,3.8,33.96],[2,3.75,64.16]],"batl":[[0,3.9,6.1],[1,3.95,231.79],[2,4,19.44]],"ltp":3.9,"tv":5435.09,"id":11981493}]}]}
{"op":"mcm","clk":"992941588","pt":1580559921037,"mc":[{"id":"1.168136214","rc":[{"batb":[[1,4.9,14.62],[2,4.8,50.94]],"batl":[[0,5.1,14.64]],"ltp":5.0,"tv":5418.36,"id":12925630},{"batb":[[1,3.8,88.96],[2,3.75,80.65]],"ltp":3.9,"tv":5435.09,"id":11981493}]}]}
{"op":"mcm","clk":"992942167","pt":1580559924037,"mc":[{"id":"1.168136214","rc":[{"batl":[[0,5.1,17.64]],"ltp":5.0,"tv":5418.36,"id":12925630}]}]}
{"op":"mcm","clk":"992942383","pt":1580559925142,"mc":[{"id":"1.168136214","rc":[{"batb":[[1,3.8,38.96]],"ltp":3.9,"tv":5435.09,"id":11981493}]}]}
{"op":"mcm","clk":"992942535","pt":1580559926065,"mc":[{"id":"1.168136214","rc":[{"batb":[[2,3.75,69.6]],"batl":[[2,4,26.16]],"ltp":3.9,"tv":5435.09,"id":11981493}]}]}
{"op":"mcm","clk":"992942757","pt":1580559927154,"mc":[{"id":"1.168136214","rc":[{"batb":[[1,4.9,19.78]],"ltp":5.0,"tv":5418.36,"id":12925630},{"batb":[[0,3.85,19.41],[1,3.8,46.16]],"batl":[[0,3.9,26.36],[2,4,19.44]],"ltp":3.9,"tv":5435.09,"id":11981493}]}]}
{"op":"mcm","clk":"992942939","pt":1580559928083,"mc":[{"id":"1.168136214","rc":[{"trd":[[3.85,779.86]],"batb":[[0,3.85,17.42]],"ltp":3.85,"tv":5439.09,"id":11981493}],"tv":25587.37}]}
{"op":"mcm","clk":"992943131","pt":1580559929062,"mc":[{"id":"1.168136214","rc":[{"batb":[[1,4.9,22.99],[2,4.8,42.94]],"ltp":5.0,"tv":5418.36,"id":12925630},{"batb":[[0,3.85,10]],"ltp":3.85,"tv":5439.09,"id":11981493}]}]}
{"op":"mcm","clk":"992943306","pt":1580559930081,"mc":[{"id":"1.168136214","rc":[{"trd":[[5.1,97.8]],"batb":[[0,5,14.42]],"batl":[[0,5.1,3.6],[1,5.2,9.73]],"ltp":5.1,"tv":5425.6,"id":12925630},{"trd":[[1.85,210.33]],"batb":[[0,1.84,78.64]],"batl":[[0,1.86,155],[1,1.87,13],[2,1.88,42.04]],"ltp":1.85,"tv":14755.0,"id":17336468},{"trd":[[3.8,678.87],[3.85,799.86]],"batb":[[0,3.75,76.14],[1,3.7,38.47],[2,3.65,26.68]],"batl":[[0,3.8,138.83],[1,3.85,7.16],[2,3.9,26.36]],"ltp":3.8,"tv":5561.41,"id":11981493}],"tv":25742.02}]}
{"op":"mcm","clk":"992943469","pt":1580559930992,"mc":[{"id":"1.168136214","rc":[{"batl":[[0,5.1,7.22],[1,5.2,5]],"ltp":5.1,"tv":5425.6,"id":12925630},{"batb":[[0,3.75,70.69]],"batl":[[2,3.9,31.72]],"ltp":3.8,"tv":5561.41,"id":11981493}]}]}
{"op":"mcm","clk":"992943703","pt":1580559932071,"mc":[{"id":"1.168136214","rc":[{"batl":[[1,1.87,15.26]],"ltp":1.85,"tv":14755.0,"id":17336468}]}]}
{"op":"mcm","clk":"992944478","pt":1580559936082,"mc":[{"id":"1.168136214","rc":[{"trd":[[1.84,34.85]],"batb":[[0,1.84,76.64]],"ltp":1.84,"tv":14758.99,"id":17336468}],"tv":25746.02}]}
{"op":"mcm","clk":"992944686","pt":1580559937098,"mc":[{"id":"1.168136214","rc":[{"batl":[[0,3.8,348.76]],"ltp":3.8,"tv":5561.41,"id":11981493}]}]}
{"op":"mcm","clk":"992944868","pt":1580559938070,"mc":[{"id":"1.168136214","rc":[{"trd":[[1.84,98.14]],"batb":[[0,1.84,45.02],[1,1.83,77.3]],"ltp":1.84,"tv":14822.28,"id":17336468},{"batb":[[0,3.75,46.93]],"ltp":3.8,"tv":5561.41,"id":11981493}],"tv":25809.3}]}
{"op":"mcm","clk":"992945016","pt":1580559938887,"mc":[{"id":"1.168136214","rc":[{"trd":[[3.8,878.87]],"batl":[[0,3.8,248.76]],"ltp":3.8,"tv":5761.41,"id":11981493}],"tv":26009.3}]}
{"op":"mcm","clk":"992945244","pt":1580559940074,"mc":[{"id":"1.168136214","rc":[{"batl":[[1,1.87,13]],"ltp":1.84,"tv":14822.28,"id":17336468}]}]}
{"op":"mcm","clk":"992945415","pt":1580559941097,"mc":[{"id":"1.168136214","rc":[{"batl":[[2,3.9,11.46]],"ltp":3.8,"tv":5761.41,"id":11981493}]}]}
{"op":"mcm","clk":"992945799","pt":1580559943101,"mc":[{"id":"1.168136214","rc":[{"batb":[[0,1.85,2],[1,1.84,45.02],[2,1.83,77.3]],"ltp":1.84,"tv":14822.28,"id":17336468},{"batl":[[1,3.85,21.08]],"ltp":3.8,"tv":5761.41,"id":11981493}]}]}
{"op":"mcm","clk":"992946017","pt":1580559944078,"mc":[{"id":"1.168136214","rc":[{"batl":[[0,1.86,155.2]],"ltp":1.84,"tv":14822.28,"id":17336468}]}]}
{"op":"mcm","clk":"992946398","pt":1580559945978,"mc":[{"id":"1.168136214","rc":[{"batl":[[0,1.86,160.2]],"ltp":1.84,"tv":14822.28,"id":17336468}]}]}
{"op":"mcm","clk":"992948969","pt":1580559959942,"mc":[{"id":"1.168136214","rc":[{"trd":[[3.75,480.79]],"batb":[[0,3.75,31.93]],"ltp":3.75,"tv":5791.41,"id":11981493}],"tv":26039.3}]}
{"op":"mcm","clk":"992950437","pt":1580559967125,"mc":[{"id":"1.168136214","rc":[{"batb":[[1,1.84,44.67]],"ltp":1.84,"tv":14822.28,"id":17336468}]}]}
{"op":"mcm","clk":"992950781","pt":1580559969051,"mc":[{"id":"1.168136214","rc":[{"trd":[[5.1,112.23]],"batl":[[0,5.2,5],[1,5.3,25.19],[2,5.4,6.91]],"ltp":5.1,"tv":5440.03,"id":12925630},{"trd":[[3.75,500.79]],"batb":[[0,3.75,21.93]],"ltp":3.75,"tv":5811.41,"id":11981493}],"tv":26073.74}]}
{"op":"mcm","clk":"992950982","pt":1580559970139,"mc":[{"id":"1.168136214","rc":[{"batb":[[0,5,19.25]],"batl":[[2,5.5,19.31]],"ltp":5.1,"tv":5440.03,"id":12925630}]}]}
{"op":"mcm","clk":"992951159","pt":1580559971051,"mc":[{"id":"1.168136214","rc":[{"batb":[[0,1.85,2.9]],"ltp":1.84,"tv":14822.28,"id":17336468}]}]}
{"op":"mcm","clk":"992951344","pt":1580559972125,"mc":[{"id":"1.168136214","rc":[{"batl":[[2,5.5,12.4]],"ltp":5.1,"tv":5440.03,"id":12925630},{"trd":[[1.85,212.13],[1.86,351.16]],"batb":[[0,1.84,44.67],[1,1.83,77.3],[2,1.82,37.79]],"batl":[[0,1.86,168]],"ltp":1.85,"tv":14828.07,"id":17336468}],"tv":26079.53}]}
{"op":"mcm","clk":"992951807","pt":1580559974772,"mc":[{"id":"1.168136214","rc":[{"batb":[[0,3.75,37.93]],"ltp":3.75,"tv":5811.41,"id":11981493}]}]}
{"op":"mcm","clk":"992952785","pt":1580559980076,"mc":[{"id":"1.168136214","rc":[{"batl":[[0,1.86,168.2]],"ltp":1.85,"tv":14828.07,"id":17336468}]}]}
{"op":"mcm","clk":"992954844","pt":1580559991110,"mc":[{"id":"1.168136214","rc":[{"batb":[[0,5.1,15.42],[1,5,26.84],[2,4.9,22.99]],"batl":[[0,5.2,2]],"ltp":5.1,"tv":5440.03,"id":12925630},{"trd":[[1.84,157.92]],"batb":[[0,1.84,10.04]],"batl":[[0,1.85,24.11],[1,1.86,168.2],[2,1.87,13]],"ltp":1.84,"tv":14887.85,"id":17336468},{"trd":[[3.8,882.87]],"batl":[[0,3.8,246.76]],"ltp":3.8,"tv":5815.41,"id":11981493}],"tv":26143.31}]}
{"op":"mcm","clk":"992955034","pt":1580559992091,"mc":[{"id":"1.168136214","rc":[{"batl":[[1,5.3,18.13],[2,5.4,5.82]],"ltp":5.1,"tv":5440.03,"id":12925630},{"batb":[[1,1.83,53]],"batl":[[0,1.85,34.04],[1,1.86,170.36]],"ltp":1.84,"tv":14887.85,"id":17336468}]}]}
{"op":"mcm","clk":"992955188","pt":1580559993112,"mc":[{"id":"1.168136214","rc":[{"batb":[[0,5.1,18.49],[2,4.9,19.78]],"ltp":5.1,"tv":5440.03,"id":12925630}]}]}
{"op":"mcm","clk":"992956149","pt":1580559998120,"mc":[{"id":"1.168136214","rc":[{"batb":[[2,1.82,42.79]],"batl":[[0,1.85,39.04]],"ltp":1.84,"tv":14887.85,"id":17336468}]}]}
{"op":"mcm","clk":"992956329","pt":1580559999099,"mc":[{"id":"1.168136214","rc":[{"batb":[[1,5,31.89]],"batl":[[1,5.3,13]],"ltp":5.1,"tv":5440.03,"id":12925630}]}]}
{"op":"mcm","clk":"992957105","pt":1580560003114,"mc":[{"id":"1.168136214","rc":[{"batl":[[0,1.85,44.04],[1,1.86,165.36]],"ltp":1.84,"tv":14887.85,"id":17336468}]}]}
{"op":"mcm","clk":"992957285","pt":1580560004116,"mc":[{"id":"1.168136214","rc":[{"batb":[[1,5,39.53]],"ltp":5.1,"tv":5440.03,"id":12925630},{"trd":[[1.85,296.13]],"batb":[[0,1.84,34.17]],"batl":[[0,1.85,2.06]],"ltp":1.85,"tv":14971.85,"id":17336468}],"tv":26227.31}]}
{"op":"mcm","clk":"992957473","pt":1580560005087,"mc":[{"id":"1.168136214","rc":[{"batb":[[1,5,37.05]],"ltp":5.1,"tv":5440.03,"id":12925630},{"batl":[[0,1.85,12.04]],"ltp":1.85,"tv":14971.85,"id":17336468}]}]}
{"op":"mcm","clk":"992957667","pt":1580560006110,"mc":[{"id":"1.168136214","rc":[{"batl":[[2,3.9,19.43]],"ltp":3.8,"tv":5815.41,"id":11981493}]}]}
{"op":"mcm","clk":"992958059","pt":1580560008113,"mc":[{"id":"1.168136214","rc":[{"batl":[[1,1.86,165.16]],"ltp":1.85,"tv":14971.85,"id":17336468}]}]}
{"op":"mcm","clk":"992958608","pt":1580560011102,"mc":[{"id":"1.168136214","rc":[{"batl":[[0,1.85,62.69]],"ltp":1.85,"tv":14971.85,"id":17336468},{"trd":[[3.8,891.27]],"batl":[[0,3.8,242.56]],"ltp":3.8,"tv":5823.82,"id":11981493}],"tv":26235.71}]}
{"op":"mcm","clk":"992959157","pt":1580560014133,"mc":[{"id":"1.168136214","rc":[{"batb":[[1,5,33.65]],"ltp":5.1,"tv":5440.03,"id":12925630}]}]}
{"op":"mcm","clk":"992959320","pt":1580560014928,"mc":[{"id":"1.168136214","rc":[{"batb":[[1,5,31.93]],"ltp":5.1,"tv":5440.03,"id":12925630},{"batl":[[0,1.85,62.89]],"ltp":1.85,"tv":14971.85,"id":17336468}]}]}
{"op":"mcm","clk":"992959875","pt":1580560017932,"mc":[{"id":"1.168136214","rc":[{"batb":[[0,1.84,84.82]],"ltp":1.85,"tv":14971.85,"id":17336468}]}]}
{"op":"mcm","clk":"992960087","pt":1580560019131,"mc":[{"id":"1.168136214","rc":[{"batl":[[1,1.86,163]],"ltp":1.85,"tv":14971.85,"id":17336468}]}]}
{"op":"mcm","clk":"992960470","pt":1580560021147,"mc":[{"id":"1.168136214","rc":[{"trd":[[5.2,49.06]],"batb":[[0,5.2,6],[1,5.1,18.49],[2,5,31.93]],"batl":[[0,5.3,13],[1,5.4,5.82],[2,5.5,12.4]],"ltp":5.2,"tv":5444.03,"id":12925630},{"trd":[[1.84,162.06]],"batb":[[0,1.84,82.75]],"ltp":1.84,"tv":14975.99,"id":17336468},{"trd":[[3.75,520.93]],"batb":[[0,3.75,27.86]],"ltp":3.75,"tv":5843.96,"id":11981493}],"tv":26263.98}]}
{"op":"mcm","clk":"992960672","pt":1580560022135,"mc":[{"id":"1.168136214","rc":[{"trd":[[5.2,61.06]],"batb":[[0,5.1,18.49],[1,5,31.93],[2,4.9,19.78]],"batl":[[0,5.2,2.06],[1,5.3,13],[2,5.4,8.82]],"ltp":5.2,"tv":5456.03,"id":12925630}],"tv":26275.98}]}
{"op":"mcm","clk":"992960797","pt":1580560022842,"mc":[{"id":"1.168136214","rc":[{"batl":[[0,5.2,5.7]],"ltp":5.2,"tv":5456.03,"id":12925630}]}]}
{"op":"mcm","clk":"992961805","pt":1580560028054,"mc":[{"id":"1.168136214","rc":[{"batb":[[0,5.1,38.75],[2,4.9,79.03]],"ltp":5.2,"tv":5456.03,"id":12925630},{"trd":[[1.84,222.56]],"batb":[[0,1.84,50.65]],"ltp":1.84,"tv":15036.48,"id":17336468},{"trd":[[3.8,895.27]],"batb":[[0,3.75,32.1]],"batl":[[0,3.8,240.56]],"ltp":3.8,"tv":5847.96,"id":11981493}],"tv":26340.48}]}
{"op":"mcm","clk":"992962419","pt":1580560031060,"mc":[{"id":"1.168136214","rc":[{"trd":[[5.1,112.56]],"batb":[[0,5.1,38.58]],"ltp":5.1,"tv":5456.37,"id":12925630}],"tv":26340.82}]}
{"op":"mcm","clk":"992962627","pt":1580560032040,"mc":[{"id":"1.168136214","rc":[{"trd":[[5.1,112.9]],"batb":[[0,5.1,38.42]],"batl":[[0,5.2,3.64]],"ltp":5.1,"tv":5456.7,"id":12925630}],"tv":26341.15}]}
{"op":"mcm","clk":"992962847","pt":1580560033156,"mc":[{"id":"1.168136214","rc":[{"trd":[[1.84,226.55],[1.85,300.13]],"batb":[[0,1.84,48.66]],"batl":[[0,1.85,60.89]],"ltp":1.85,"tv":15044.48,"id":17336468}],"tv":26349.15}]}
{"op":"mcm","clk":"992963361","pt":1580560035986,"mc":[{"id":"1.168136214","rc":[{"trd":[[5.2,68.34]],"batb":[[0,5.2,16.36],[1,5.1,38.42],[2,5,31.93]],"batl":[[0,5.3,13],[1,5.4,8.82],[2,5.5,12.4]],"ltp":5.2,"tv":5463.98,"id":12925630},{"batl":[[0,1.85,70.89]],"ltp":1.85,"tv":15044.48,"id":17336468},{"trd":[[3.75,544.93]],"batb":[[0,3.75,20.1]],"batl":[[0,3.8,247.56]],"ltp":3.75,"tv":5871.96,"id":11981493}],"tv":26380.43}]}
{"op":"mcm","clk":"992963528","pt":1580560037079,"mc":[{"id":"1.168136214","rc":[{"batb":[[0,5.2,23.7],[2,5,89.7]],"batl":[[0,5.3,10],[1,5.4,3],[2,5.5,15.4]],"ltp":5.2,"tv":5463.98,"id":12925630}]}]}
{"op":"mcm","clk":"992964578","pt":1580560043098,"mc":[{"id":"1.168136214","rc":[{"batl":[[0,1.85,70.69]],"ltp":1.85,"tv":15044.48,"id":17336468}]}]}
{"op":"mcm","clk":"992964764","pt":1580560044128,"mc":[{"id":"1.168136214","rc":[{"batb":[[2,5,84.66]],"ltp":5.2,"tv":5463.98,"id":12925630},{"batb":[[2,1.82,18.2]],"ltp":1.85,"tv":15044.48,"id":17336468},{"batb":[[1,3.7,31]],"ltp":3.75,"tv":5871.96,"id":11981493}]}]}
{"op":"mcm","clk":"992965146","pt":1580560046106,"mc":[{"id":"1.168136214","rc":[{"trd":[[1.84,276.53]],"batb":[[0,1.84,23.68]],"ltp":1.84,"tv":15094.46,"id":17336468}],"tv":26430.41}]}
{"op":"mcm","clk":"992965340","pt":1580560047136,"mc":[{"id":"1.168136214","rc":[{"trd":[[1.84,323.91]],"batb":[[0,1.83,41],[1,1.82,18.2],[2,1.81,35.2]],"batl":[[0,1.84,70.89],[1,1.85,70.69],[2,1.86,163]],"ltp":1.84,"tv":15141.84,"id":17336468}],"tv":26477.79}]}
{"op":"mcm","clk":"992966119","pt":1580560051123,"mc":[{"id":"1.168136214","rc":[{"batl":[[0,1.84,71.09]],"ltp":1.84,"tv":15141.84,"id":17336468},{"trd":[[3.75,560.93]],"batb":[[0,3.75,12.1]],"ltp":3.75,"tv":5887.96,"id":11981493}],"tv":26493.79}]}
{"op":"mcm","clk":"992966233","pt":1580560051728,"mc":[{"id":"1.168136214","rc":[{"batl":[[0,1.84,71.15],[1,1.85,70.63]],"ltp":1.84,"tv":15141.84,"id":17336468}]}]}
{"op":"mcm","clk":"992966490","pt":1580560052918,"mc":[{"id":"1.168136214","rc":[{"batl":[[0,3.8,252.56]],"ltp":3.75,"tv":5887.96,"id":11981493}]}]}
{"op":"mcm","clk":"992966723","pt":1580560054136,"mc":[{"id":"1.168136214","rc":[{"trd":[[5.3,16]],"batb":[[0,5.2,29.7],[1,5.1,45.67]],"batl":[[0,5.3,2]],"ltp":5.3,"tv":5479.98,"id":12925630}],"tv":26509.79}]}
{"op":"mcm","clk":"992966930","pt":1580560055128,"mc":[{"id":"1.168136214","rc":[{"batl":[[2,5.5,20.17]],"ltp":5.3,"tv":5479.98,"id":12925630}]}]}
{"op":"mcm","clk":"992967500","pt":1580560058116,"mc":[{"id":"1.168136214","marketDefinition":{"bspMarket":true,"turnInPlayEnabled":true,"persistenceEnabled":true,"marketBaseRate":5.0,"eventId":"29678828","eventTypeId":"7","numberOfWinners":1,"bettingType":"ODDS","marketType":"WIN","marketTime":"2020-02-01T12:57:00.000Z","suspendTime":"2020-02-01T12:57:00.000Z","bspReconciled":false,"complete":true,"inPlay":false,"crossMatching":true,"runnersVoidable":false,"numberOfActiveRunners":3,"betDelay":0,"status":"OPEN","runners":[{"adjustmentFactor":54.63,"status":"ACTIVE","sortPriority":1,"id":17336468,"name":"Southfield Stone"},{"adjustmentFactor":26.31,"status":"ACTIVE","sortPriority":2,"id":11981493,"name":"Espoir De Teillee"},{"adjustmentFactor":19.04,"status":"ACTIVE","sortPriority":3,"id":12925630,"name":"Mahlervous"}],"regulators":["MR_INT"],"venue":"Musselburgh","countryCode":"GB","discountAllowed":true,"timezone":"Europe/London","openDate":"2020-02-01T12:57:00.000Z","version":3145070558,"name":"2m4f Nov Chs","eventName":"Muss  1st Feb"},"rc":[{"batl":[[1,5.4,10]],"ltp":5.3,"tv":5479.98,"id":12925630}]}]}
{"op":"mcm","clk":"992967697","pt":1580560059144,"mc":[{"id":"1.168136214","rc":[{"trd":[[1.83,4]],"batb":[[0,1.83,39]],"ltp":1.83,"tv":15145.84,"id":17336468}],"tv":26513.79}]}
{"op":"mcm","clk":"992968234","pt":1580560061956,"mc":[{"id":"1.168136214","rc":[{"batb":[[2,5,87.66]],"ltp":5.3,"tv":5479.98,"id":12925630}]}]}
{"op":"mcm","clk":"992968455","pt":1580560063049,"mc":[{"id":"1.168136214","rc":[{"batl":[[2,1.86,15]],"ltp":1.83,"tv":15145.84,"id":17336468}]}]}
{"op":"mcm","clk":"992969064","pt":1580560066113,"mc":[{"id":"1.168136214","rc":[{"trd":[[5.3,20]],"batb":[[0,5.3,6],[1,5.2,13.34],[2,5.1,45.67]],"batl":[[0,5.4,10],[1,5.5,20.17],[2,5.6,12.3]],"ltp":5.3,"tv":5483.98,"id":12925630},{"batb":[[0,1.83,49]],"ltp":1.83,"tv":15145.84,"id":17336468},{"trd":[[3.75,576.93]],"batb":[[0,3.75,4.1]],"batl":[[0,3.8,245.56]],"ltp":3.75,"tv":5903.95,"id":11981493}],"tv":26533.78}]}
{"op":"mcm","clk":"992969267","pt":1580560067109,"mc":[{"id":"1.168136214","rc":[{"batb":[[0,5.3,13],[1,5.2,21.34]],"batl":[[1,5.5,15.4]],"ltp":5.3,"tv":5483.98,"id":12925630},{"batb":[[0,1.83,39]],"batl":[[0,1.84,81.15]],"ltp":1.83,"tv":15145.84,"id":17336468},{"batl":[[0,3.8,252.56]],"ltp":3.75,"tv":5903.95,"id":11981493}]}]}
{"op":"mcm","clk":"992969428","pt":1580560068012,"mc":[{"id":"1.168136214","rc":[{"batl":[[1,3.85,26.08]],"ltp":3.75,"tv":5903.95,"id":11981493}]}]}
{"op":"mcm","clk":"992970028","pt":1580560071114,"mc":[{"id":"1.168136214","rc":[{"batl":[[0,1.84,131.8]],"ltp":1.83,"tv":15145.84,"id":17336468},{"batb":[[0,3.75,6.1]],"ltp":3.75,"tv":5903.95,"id":11981493}]}]}
{"op":"mcm","clk":"992970229","pt":1580560072108,"mc":[{"id":"1.168136214","rc":[{"batb":[[0,5.3,22.25]],"ltp":5.3,"tv":5483.98,"id":12925630},{"trd":[[1.83,20]],"batb":[[0,1.83,31]],"ltp":1.83,"tv":15161.84,"id":17336468}],"tv":26549.78}]}
{"op":"mcm","clk":"992970404","pt":1580560073124,"mc":[{"id":"1.168136214","rc":[{"batb":[[2,5.1,38.42]],"ltp":5.3,"tv":5483.98,"id":12925630},{"batl":[[2,1.86,23.63]],"ltp":1.83,"tv":15161.84,"id":17336468}]}]}
{"op":"mcm","clk":"992970621","pt":1580560074104,"mc":[{"id":"1.168136214","rc":[{"batl":[[0,1.84,133.8]],"ltp":1.83,"tv":15161.84,"id":17336468}]}]}
{"op":"mcm","clk":"992970797","pt":1580560075114,"mc":[{"id":"1.168136214","rc":[{"batl":[[1,1.85,19.98]],"ltp":1.83,"tv":15161.84,"id":17336468}]}]}
{"op":"mcm","clk":"992970971","pt":1580560076108,"mc":[{"id":"1.168136214","rc":[{"batl":[[0,1.84,165.94],[1,1.85,22.31]],"ltp":1.83,"tv":15161.84,"id":17336468}]}]}
{"op":"mcm","clk":"992971155","pt":1580560077124,"mc":[{"id":"1.168136214","rc":[{"trd":[[5.3,32.09]],"batb":[[0,5.3,2]],"batl":[[0,5.4,17.37]],"ltp":5.3,"tv":5496.07,"id":12925630},{"trd":[[1.82,4.06],[1.83,51]],"batb":[[0,1.82,5.2],[1,1.81,21.82],[2,1.8,31.8]],"batl":[[0,1.83,46.7],[1,1.84,169.94],[2,1.85,26.31]],"ltp":1.82,"tv":15196.9,"id":17336468},{"trd":[[3.8,1425.32],[3.85,853.94]],"batb":[[0,3.8,127.51],[1,3.75,11.1],[2,3.7,125.21]],"batl":[[0,3.9,11.46],[1,3.95,32.42],[2,4,13.36]],"ltp":3.85,"tv":6488.09,"id":11981493}],"tv":27181.07}]}
{"op":"mcm","clk":"992971324","pt":1580560078143,"mc":[{"id":"1.168136214","rc":[{"trd":[[1.82,14.46]],"batb":[[0,1.8,31.8],[1,1.79,19.52],[2,1.78,127.74]],"batl":[[0,1.82,39.2],[1,1.83,46.7],[2,1.84,169.94]],"ltp":1.82,"tv":15207.3,"id":17336468},{"batb":[[0,3.8,134.51]],"batl":[[0,3.9,6.1]],"ltp":3.85,"tv":6488.09,"id":11981493}],"tv":27191.47}]}
{"op":"mcm","clk":"992971512","pt":1580560079137,"mc":[{"id":"1.168136214","rc":[{"batb":[[1,1.79,10]],"batl":[[2,1.84,169.74]],"ltp":1.82,"tv":15207.3,"id":17336468}]}]}
{"op":"mcm","clk":"992971698","pt":1580560080108,"mc":[{"id":"1.168136214","rc":[{"trd":[[5.3,34.09]],"batb":[[0,5.2,11],[1,5.1,35.42],[2,5,29.89]],"batl":[[0,5.3,3],[1,5.4,17.37],[2,5.5,15.4]],"ltp":5.3,"tv":5498.07,"id":12925630},{"trd":[[1.82,96.86],[1.83,559.76]],"batb":[[0,1.8,33.8]],"batl":[[0,1.83,46.73],[1,1.84,164.74],[2,1.85,18.98]],"ltp":1.82,"tv":15798.46,"id":17336468},{"trd":[[3.8,1428.11]],"batb":[[0,3.85,5.32],[1,3.8,129.72],[2,3.75,11.1]],"batl":[[0,3.9,10.02]],"ltp":3.8,"tv":6490.88,"id":11981493}],"tv":27787.42}]}
{"op":"mcm","clk":"992971876","pt":1580560081037,"mc":[{"id":"1.168136214","rc":[{"batb":[[2,1.78,167.04]],"batl":[[2,1.85,34.55]],"ltp":1.82,"tv":15798.46,"id":17336468}]}]}
{"op":"mcm","clk":"992972112","pt":1580560082129,"mc":[{"id":"1.168136214","rc":[{"trd":[[5.3,40.09]],"batb":[[0,5.3,6.65],[1,5.2,11],[2,5.1,35.42]],"batl":[[0,5.4,17.37],[1,5.5,15.4],[2,5.6,12.3]],"ltp":5.3,"tv":5504.07,"id":12925630},{"trd":[[1.81,16]],"batb":[[0,1.8,23.8],[2,1.78,178.04]],"batl":[[0,1.81,2.53],[1,1.82,10],[2,1.83,46.73]],"ltp":1.81,"tv":15814.46,"id":17336468},{"batl":[[1,3.95,21.86],[2,4,23.91]],"ltp":3.8,"tv":6490.88,"id":11981493}],"tv":27809.42}]}
{"op":"mcm","clk":"992972323","pt":1580560083143,"mc":[{"id":"1.168136214","rc":[{"trd":[[5.3,53.39]],"batb":[[0,5.2,11],[1,5.1,15.16],[2,5,29.89]],"batl":[[0,5.3,38.25],[1,5.4,17.37],[2,5.5,15.4]],"ltp":5.3,"tv":5517.37,"id":12925630},{"trd":[[1.81,21.06]],"batb":[[0,1.81,78.04],[1,1.8,49.59],[2,1.79,10]],"batl":[[0,1.82,10],[1,1.83,46.73],[2,1.84,164.74]],"ltp":1.81,"tv":15819.52,"id":17336468},{"trd":[[3.85,864.57]],"batb":[[0,3.8,129.72],[1,3.75,11.1],[2,3.7,125.21]],"ltp":3.85,"tv":6501.51,"id":11981493}],"tv":27838.41}]}
{"op":"mcm","clk":"992972521","pt":1580560084026,"mc":[{"id":"1.168136214","rc":[{"batb":[[0,5.2,6],[1,5.1,12.08],[2,5,33.03]],"batl":[[0,5.3,41.25]],"ltp":5.3,"tv":5517.37,"id":12925630},{"batb":[[1,1.8,59.59]],"batl":[[0,1.83,46.73],[1,1.84,164.74],[2,1.85,18.98]],"ltp":1.81,"tv":15819.52,"id":17336468},{"batb":[[0,3.85,11.81],[1,3.8,129.72],[2,3.75,11.1]],"ltp":3.85,"tv":6501.51,"id":11981493}]}]}
{"op":"mcm","clk":"992972751","pt":1580560085137,"mc":[{"id":"1.168136214","rc":[{"batl":[[0,1.82,25.82],[1,1.83,46.73],[2,1.84,164.74]],"ltp":1.81,"tv":15819.52,"id":17336468},{"trd":[[3.9,360.8]],"batl":[[0,3.95,21.86],[1,4,28.91],[2,4.1,300]],"ltp":3.9,"tv":6517.5,"id":11981493}],"tv":27854.41}]}
{"op":"mcm","clk":"992972944","pt":1580560086112,"mc":[{"id":"1.168136214","rc":[{"batl":[[0,1.82,26.02]],"ltp":1.81,"tv":15819.52,"id":17336468}]}]}
{"op":"mcm","clk":"992973169","pt":1580560087148,"mc":[{"id":"1.168136214","rc":[{"trd":[[1.82,196.84]],"batb":[[0,1.81,88.04]],"batl":[[0,1.83,46.73],[1,1.84,164.74],[2,1.85,18.98]],"ltp":1.82,"tv":15919.5,"id":17336468},{"batb":[[0,3.85,6.8]],"batl":[[0,3.9,9.96],[1,3.95,31.82],[2,4,18.36]],"ltp":3.9,"tv":6517.5,"id":11981493}],"tv":27954.38}]}
{"op":"mcm","clk":"992973379","pt":1580560088150,"mc":[{"id":"1.168136214","rc":[{"batl":[[0,1.82,61.19],[1,1.83,46.73],[2,1.84,164.74]],"ltp":1.82,"tv":15919.5,"id":17336468},{"batb":[[0,3.85,11.8],[2,3.75,16.32]],"ltp":3.9,"tv":6517.5,"id":11981493}]}]}
{"op":"mcm","clk":"992973573","pt":1580560089124,"mc":[{"id":"1.168136214","rc":[{"batb":[[0,1.81,78.04],[1,1.8,84.59]],"ltp":1.82,"tv":15919.5,"id":17336468}]}]}
{"op":"mcm","clk":"992973724","pt":1580560089930,"mc":[{"id":"1.168136214","rc":[{"batl":[[2,1.84,114.09]],"ltp":1.82,"tv":15919.5,"id":17336468},{"batl":[[0,3.9,15.96]],"ltp":3.9,"tv":6517.5,"id":11981493}]}]}
{"op":"mcm","clk":"992973958","pt":1580560091131,"mc":[{"id":"1.168136214","rc":[{"batb":[[2,3.75,12.22]],"ltp":3.9,"tv":6517.5,"id":11981493}]}]}
{"op":"mcm","clk":"992974160","pt":1580560092152,"mc":[{"id":"1.168136214","rc":[{"batb":[[0,3.85,15.8]],"ltp":3.9,"tv":6517.5,"id":11981493}]}]}
{"op":"mcm","clk":"992974344","pt":1580560093075,"mc":[{"id":"1.168136214","rc":[{"batb":[[0,1.8,84.59],[1,1.79,10],[2,1.78,147.65]],"batl":[[0,1.82,61.25],[2,1.84,114.03]],"ltp":1.82,"tv":15919.5,"id":17336468}]}]}
{"op":"mcm","clk":"992974548","pt":1580560094152,"mc":[{"id":"1.168136214","rc":[{"batl":[[0,5.3,33.19]],"ltp":5.3,"tv":5517.37,"id":12925630},{"batb":[[0,3.85,32.06]],"ltp":3.9,"tv":6517.5,"id":11981493}]}]}
{"op":"mcm","clk":"992974932","pt":1580560096044,"mc":[{"id":"1.168136214","rc":[{"batb":[[0,1.8,164.59]],"ltp":1.82,"tv":15919.5,"id":17336468}]}]}
{"op":"mcm","clk":"992976060","pt":1580560102085,"mc":[{"id":"1.168136214","rc":[{"trd":[[3.9,384.79]],"batb":[[0,3.85,42.06]],"batl":[[0,3.9,3.97]],"ltp":3.9,"tv":6541.49,"id":11981493}],"tv":27978.37}]}
{"op":"mcm","clk":"992976257","pt":1580560103053,"mc":[{"id":"1.168136214","rc":[{"batl":[[0,1.81,90],[1,1.82,70.25],[2,1.83,46.73]],"ltp":1.82,"tv":15919.5,"id":17336468},{"batb":[[0,3.85,51.99]],"ltp":3.9,"tv":6541.49,"id":11981493}]}]}
{"op":"mcm","clk":"992976427","pt":1580560103855,"mc":[{"id":"1.168136214","rc":[{"batl":[[1,3.95,15.96]],"ltp":3.9,"tv":6541.49,"id":11981493}]}]}
{"op":"mcm","clk":"992977679","pt":1580560111069,"mc":[{"id":"1.168136214","rc":[{"trd":[[3.9,392.73]],"batb":[[0,3.9,4.03],[1,3.85,51.99],[2,3.8,129.72]],"batl":[[0,3.95,15.96],[1,4,18.36],[2,4.1,300]],"ltp":3.9,"tv":6549.43,"id":11981493}],"tv":27986.31}]}
{"op":"mcm","clk":"992977834","pt":1580560112083,"mc":[{"id":"1.168136214","rc":[{"trd":[[1.81,117.06]],"batl":[[0,1.81,42.06],[1,1.82,70.19]],"ltp":1.81,"tv":16015.5,"id":17336468},{"trd":[[3.9,400.79]],"batb":[[0,3.85,42.06],[1,3.8,129.72],[2,3.75,96.24]],"batl":[[0,3.9,7.97],[1,3.95,15.96],[2,4,18.36]],"ltp":3.9,"tv":6557.49,"id":11981493}],"tv":28090.37}]}
{"op":"mcm","clk":"992978019","pt":1580560113098,"mc":[{"id":"1.168136214","rc":[{"trd":[[3.9,408.79]],"batb":[[2,3.75,12.22]],"batl":[[0,3.9,3.97]],"ltp":3.9,"tv":6565.49,"id":11981493}],"tv":28098.37}]}
{"op":"mcm","clk":"992978314","pt":1580560115093,"mc":[{"id":"1.168136214","rc":[{"batl":[[0,1.81,106.06]],"ltp":1.81,"tv":16015.5,"id":17336468}]}]}
{"op":"mcm","clk":"992978498","pt":1580560116122,"mc":[{"id":"1.168136214","rc":[{"batb":[[0,1.8,167.83]],"ltp":1.81,"tv":16015.5,"id":17336468}]}]}
{"op":"mcm","clk":"992979017","pt":1580560119094,"mc":[{"id":"1.168136214","rc":[{"batl":[[0,1.81,157.55]],"ltp":1.81,"tv":16015.5,"id":17336468}]}]}
{"op":"mcm","clk":"992979205","pt":1580560120126,"mc":[{"id":"1.168136214","rc":[{"batb":[[0,5.2,12.14]],"ltp":5.3,"tv":5517.37,"id":12925630},{"batb":[[0,1.8,185.57]],"batl":[[1,1.82,18.98]],"ltp":1.81,"tv":16015.5,"id":17336468},{"trd":[[3.9,425.15]],"batb":[[2,3.75,96.24]],"batl":[[0,3.9,3.79]],"ltp":3.9,"tv":6581.85,"id":11981493}],"tv":28114.73}]}
{"op":"mcm","clk":"992979310","pt":1580560120717,"mc":[{"id":"1.168136214","rc":[{"batb":[[2,3.75,12.22]],"ltp":3.9,"tv":6581.85,"id":11981493}]}]}
{"op":"mcm","clk":"992979542","pt":1580560122034,"mc":[{"id":"1.168136214","rc":[{"batb":[[0,1.8,163.77]],"batl":[[0,1.81,157.75]],"ltp":1.81,"tv":16015.5,"id":17336468}]}]}
{"op":"mcm","clk":"992979939","pt":1580560124092,"mc":[{"id":"1.168136214","rc":[{"trd":[[1.81,135.06]],"batl":[[0,1.81,148.75],[2,1.83,79.52]],"ltp":1.81,"tv":16033.5,"id":17336468}],"tv":28132.73}]}
{"op":"mcm","clk":"992980082","pt":1580560125102,"mc":[{"id":"1.168136214","rc":[{"trd":[[1.81,382.94]],"batl":[[0,1.81,24.83]],"ltp":1.81,"tv":16281.37,"id":17336468}],"tv":28380.61}]}
{"op":"mcm","clk":"992980221","pt":1580560126026,"mc":[{"id":"1.168136214","rc":[{"trd":[[3.9,432.73]],"batb":[[0,3.9,4.21],[1,3.85,42.06],[2,3.8,129.72]],"batl":[[0,3.95,15.96],[1,4,18.36],[2,4.1,300]],"ltp":3.9,"tv":6589.43,"id":11981493}],"tv":28388.19}]}
{"op":"mcm","clk":"992980454","pt":1580560127129,"mc":[{"id":"1.168136214","rc":[{"batb":[[0,5.2,14.14]],"ltp":5.3,"tv":5517.37,"id":12925630},{"trd":[[1.81,398.93]],"batl":[[0,1.81,16.83]],"ltp":1.81,"tv":16297.37,"id":17336468},{"batb":[[0,3.9,24.47]],"ltp":3.9,"tv":6589.43,"id":11981493}],"tv":28404.18}]}
{"op":"mcm","clk":"992980565","pt":1580560127920,"mc":[{"id":"1.168136214","rc":[{"batl":[[1,4,10.38]],"ltp":3.9,"tv":6589.43,"id":11981493}]}]}
{"op":"mcm","clk":"992981097","pt":1580560131149,"mc":[{"id":"1.168136214","rc":[{"batl":[[0,1.81,22.83]],"ltp":1.81,"tv":16297.37,"id":17336468}]}]}
{"op":"mcm","clk":"992981458","pt":1580560133138,"mc":[{"id":"1.168136214","rc":[{"batb":[[0,3.9,4.21]],"ltp":3.9,"tv":6589.43,"id":11981493}]}]}
{"op":"mcm","clk":"992981594","pt":1580560134053,"mc":[{"id":"1.168136214","rc":[{"batb":[[1,3.85,62.32]],"ltp":3.9,"tv":6589.43,"id":11981493}]}]}
{"op":"mcm","clk":"992982119","pt":1580560137062,"mc":[{"id":"1.168136214","rc":[{"batb":[[0,3.9,6.21]],"ltp":3.9,"tv":6589.43,"id":11981493}]}]}
{"op":"mcm","clk":"992982640","pt":1580560140073,"mc":[{"id":"1.168136214","rc":[{"batl":[[0,1.81,24.83]],"ltp":1.81,"tv":16297.37,"id":17336468},{"batl":[[0,3.95,95.96]],"ltp":3.9,"tv":6589.43,"id":11981493}]}]}
{"op":"mcm","clk":"992982809","pt":1580560141061,"mc":[{"id":"1.168136214","rc":[{"trd":[[1.81,414.92]],"batl":[[0,1.81,16.84]],"ltp":1.81,"tv":16313.36,"id":17336468}],"tv":28420.17}]}
{"op":"mcm","clk":"992983206","pt":1580560143067,"mc":[{"id":"1.168136214","rc":[{"batl":[[1,1.82,68.98]],"ltp":1.81,"tv":16313.36,"id":17336468}]}]}
{"op":"mcm","clk":"992984422","pt":1580560149980,"mc":[{"id":"1.168136214","rc":[{"batb":[[0,5.2,20.14]],"ltp":5.3,"tv":5517.37,"id":12925630},{"trd":[[1.8,136.81]],"batb":[[0,1.8,105.38]],"ltp":1.8,"tv":16450.17,"id":17336468},{"trd":[[3.9,445.15]],"batb":[[0,3.85,62.32],[1,3.8,129.72],[2,3.75,12.22]],"batl":[[0,3.9,25.37],[1,3.95,95.96],[2,4,10.38]],"ltp":3.9,"tv":6601.85,"id":11981493}],"tv":28569.41}]}
{"op":"mcm","clk":"992984590","pt":1580560150998,"mc":[{"id":"1.168136214","rc":[{"batb":[[0,1.8,185.95]],"ltp":1.8,"tv":16450.17,"id":17336468}]}]}
{"op":"mcm","clk":"992984972","pt":1580560153104,"mc":[{"id":"1.168136214","rc":[{"batl":[[0,1.81,16.64]],"ltp":1.8,"tv":16450.17,"id":17336468}]}]}
{"op":"mcm","clk":"992985157","pt":1580560154054,"mc":[{"id":"1.168136214","rc":[{"trd":[[5.2,262.54]],"batb":[[0,5.1,12.08],[1,5,33.03],[2,4.9,13.64]],"ltp":5.2,"tv":5711.58,"id":12925630},{"trd":[[1.81,431.56]],"batl":[[0,1.82,68.98],[1,1.83,79.52],[2,1.84,26.81]],"ltp":1.81,"tv":16466.81,"id":17336468},{"trd":[[3.9,452.88]],"batl":[[0,3.9,17.64]],"ltp":3.9,"tv":6609.58,"id":11981493}],"tv":28787.98}]}
{"op":"mcm","clk":"992985342","pt":1580560155094,"mc":[{"id":"1.168136214","rc":[{"batb":[[0,5.1,24.19]],"ltp":5.2,"tv":5711.58,"id":12925630},{"batb":[[0,1.81,10.07],[1,1.8,185.95],[2,1.79,10]],"batl":[[0,1.82,59.98]],"ltp":1.81,"tv":16466.81,"id":17336468}]}]}
{"op":"mcm","clk":"992985533","pt":1580560156069,"mc":[{"id":"1.168136214","rc":[{"trd":[[1.81,431.96]],"batb":[[0,1.81,9.87]],"ltp":1.81,"tv":16467.21,"id":17336468}],"tv":28788.38}]}
{"op":"mcm","clk":"992985714","pt":1580560157098,"mc":[{"id":"1.168136214","rc":[{"batb":[[1,5,30.03]],"ltp":5.2,"tv":5711.58,"id":12925630}]}]}
{"op":"mcm","clk":"992985919","pt":1580560158073,"mc":[{"id":"1.168136214","rc":[{"batl":[[0,1.82,60.18]],"ltp":1.81,"tv":16467.21,"id":17336468},{"batl":[[1,3.95,15.96],[2,4,90.38]],"ltp":3.9,"tv":6609.58,"id":11981493}]}]}
{"op":"mcm","clk":"992986449","pt":1580560160890,"mc":[{"id":"1.168136214","rc":[{"batl":[[0,1.82,69.18]],"ltp":1.81,"tv":16467.21,"id":17336468}]}]}
{"op":"mcm","clk":"992986640","pt":1580560162097,"mc":[{"id":"1.168136214","rc":[{"trd":[[1.81,451.7]],"batb":[[0,1.81,10.12],[1,1.8,105.38]],"ltp":1.81,"tv":16486.95,"id":17336468}],"tv":28808.12}]}
{"op":"mcm","clk":"992986801","pt":1580560163110,"mc":[{"id":"1.168136214","rc":[{"trd":[[1.81,467.7]],"batb":[[0,1.81,2.12]],"ltp":1.81,"tv":16502.95,"id":17336468}],"tv":28824.12}]}
{"op":"mcm","clk":"992988204","pt":1580560171078,"mc":[{"id":"1.168136214","rc":[{"trd":[[1.81,470.42],[1.82,201.06]],"batb":[[0,1.8,106.14],[1,1.79,10],[2,1.78,149.65]],"batl":[[0,1.82,67.07],[1,1.83,46.73]],"ltp":1.81,"tv":16509.89,"id":17336468},{"trd":[[3.85,865.85]],"batb":[[0,3.85,61.68]],"ltp":3.85,"tv":6610.86,"id":11981493}],"tv":28832.34}]}
{"op":"mcm","clk":"992988391","pt":1580560172063,"mc":[{"id":"1.168136214","rc":[{"batl":[[0,5.2,100],[1,5.3,33.19],[2,5.4,17.37]],"ltp":5.2,"tv":5711.58,"id":12925630},{"trd":[[1.8,178.25],[1.81,492.28]],"batb":[[0,1.8,84.66]],"batl":[[2,1.84,30.81]],"ltp":1.8,"tv":16573.19,"id":17336468},{"trd":[[3.9,456.88]],"batl":[[0,3.9,15.64]],"ltp":3.9,"tv":6614.86,"id":11981493}],"tv":28899.64}]}
{"op":"mcm","clk":"992988578","pt":1580560173084,"mc":[{"id":"1.168136214","rc":[{"trd":[[5.1,120.18]],"batb":[[0,5.1,15.55]],"batl":[[1,5.3,5.55]],"ltp":5.1,"tv":5718.85,"id":12925630},{"batb":[[0,1.81,10.17],[1,1.8,84.66],[2,1.79,10]],"batl":[[1,1.83,52.41]],"ltp":1.8,"tv":16573.19,"id":17336468}],"tv":28906.92}]}
{"op":"mcm","clk":"992988760","pt":1580560174072,"mc":[{"id":"1.168136214","rc":[{"trd":[[5.1,159.73]],"batb":[[0,5,30.03],[1,4.9,22.09],[2,4.8,27.49]],"batl":[[0,5.2,103],[1,5.3,10.41]],"ltp":5.1,"tv":5758.41,"id":12925630},{"trd":[[1.82,224.71]],"batl":[[0,1.82,43.42],[1,1.83,37.41]],"ltp":1.82,"tv":16596.84,"id":17336468},{"trd":[[3.9,477.12]],"batb":[[0,3.9,10.58],[1,3.85,61.68],[2,3.8,129.72]],"batl":[[0,4,85],[1,4.1,304],[2,4.2,51.35]],"ltp":3.9,"tv":6635.1,"id":11981493}],"tv":28990.36}]}
{"op":"mcm","clk":"992988942","pt":1580560174974,"mc":[{"id":"1.168136214","rc":[{"batb":[[0,5,26.89],[1,4.9,25.29]],"ltp":5.1,"tv":5758.41,"id":12925630},{"batb":[[0,1.81,36.7]],"ltp":1.82,"tv":16596.84,"id":17336468}]}]}
{"op":"mcm","clk":"992989131","pt":1580560176056,"mc":[{"id":"1.168136214","rc":[{"batb":[[0,5,14.42]],"batl":[[1,5.3,17.63]],"ltp":5.1,"tv":5758.41,"id":12925630},{"batl":[[1,1.83,52.41]],"ltp":1.82,"tv":16596.84,"id":17336468},{"batb":[[2,3.8,137.93]],"ltp":3.9,"tv":6635.1,"id":11981493}]}]}
{"op":"mcm","clk":"992990039","pt":1580560181091,"mc":[{"id":"1.168136214","rc":[{"trd":[[1.82,311.55]],"batb":[[0,1.82,124.62],[1,1.81,36.7],[2,1.8,84.66]],"batl":[[0,1.83,52.41],[1,1.84,30.81],[2,1.85,13]],"ltp":1.82,"tv":16683.68,"id":17336468}],"tv":29077.2}]}
{"op":"mcm","clk":"992990228","pt":1580560182086,"mc":[{"id":"1.168136214","rc":[{"batb":[[0,5,7.42],[2,4.8,34.49]],"batl":[[0,5.1,3.22],[1,5.2,103],[2,5.3,17.63]],"ltp":5.1,"tv":5758.41,"id":12925630},{"trd":[[1.83,575.76]],"batb":[[0,1.82,136.62]],"batl":[[0,1.83,29.41],[1,1.84,21.89]],"ltp":1.83,"tv":16699.68,"id":17336468},{"batl":[[0,4,100.15]],"ltp":3.9,"tv":6635.1,"id":11981493}],"tv":29093.2}]}
{"op":"mcm","clk":"992990418","pt":1580560183077,"mc":[{"id":"1.168136214","rc":[{"batb":[[1,4.9,22.09]],"ltp":5.1,"tv":5758.41,"id":12925630},{"batb":[[0,3.9,12.58]],"ltp":3.9,"tv":6635.1,"id":11981493}]}]}
{"op":"mcm","clk":"992990576","pt":1580560183877,"mc":[{"id":"1.168136214","rc":[{"batb":[[0,5,13.42],[2,4.8,37.76]],"batl":[[0,5.2,3],[1,5.3,17.63],[2,5.4,17.37]],"ltp":5.1,"tv":5758.41,"id":12925630},{"batb":[[0,3.9,5.4]],"batl":[[0,3.95,4.24],[1,4,100.15],[2,4.1,304]],"ltp":3.9,"tv":6635.1,"id":11981493}]}]}
{"op":"mcm","clk":"992990776","pt":1580560185070,"mc":[{"id":"1.168136214","rc":[{"trd":[[5.2,272.59]],"batb":[[0,5.2,2.95],[1,5,13.42],[2,4.9,22.09]],"batl":[[0,5.3,17.63],[1,5.4,17.37],[2,5.5,15.4]],"ltp":5.2,"tv":5768.46,"id":12925630},{"trd":[[1.82,323.12]],"batb":[[0,1.82,125.05]],"ltp":1.82,"tv":16711.25,"id":17336468},{"trd":[[3.9,482.52]],"batb":[[0,3.85,61.68],[1,3.8,137.93],[2,3.75,96.24]],"batl":[[0,3.95,6.24]],"ltp":3.9,"tv":6640.5,"id":11981493}],"tv":29120.22}]}
{"op":"mcm","clk":"992990955","pt":1580560186064,"mc":[{"id":"1.168136214","rc":[{"trd":[[5.2,278.49]],"batb":[[0,5.1,7.24]],"batl":[[0,5.3,25.58]],"ltp":5.2,"tv":5774.35,"id":12925630},{"trd":[[1.83,591.76]],"batb":[[0,1.82,115.05]],"batl":[[0,1.84,21.89],[1,1.85,13],[2,1.86,27.12]],"ltp":1.83,"tv":16727.25,"id":17336468},{"batb":[[0,3.85,56.68],[2,3.75,12.22]],"ltp":3.9,"tv":6640.5,"id":11981493}],"tv":29142.11}]}
{"op":"mcm","clk":"992991144","pt":1580560187154,"mc":[{"id":"1.168136214","rc":[{"batb":[[0,5,13.42],[1,4.9,22.09],[2,4.8,37.76]],"ltp":5.2,"tv":5774.35,"id":12925630},{"batb":[[0,1.82,133.05],[2,1.8,93.26]],"batl":[[0,1.84,8.89],[1,1.85,18.48],[2,1.86,57.12]],"ltp":1.83,"tv":16727.25,"id":17336468},{"batl":[[0,3.95,22.1],[1,4,105.7]],"ltp":3.9,"tv":6640.5,"id":11981493}]}]}
{"op":"mcm","clk":"992991296","pt":1580560188076,"mc":[{"id":"1.168136214","rc":[{"batl":[[0,5.2,7.97],[1,5.3,25.58],[2,5.4,17.37]],"ltp":5.2,"tv":5774.35,"id":12925630},{"batb":[[0,1.83,11.26],[1,1.82,131.05],[2,1.81,36.7]],"ltp":1.83,"tv":16727.25,"id":17336468},{"batb":[[0,3.85,40.42],[1,3.8,13.21]],"batl":[[0,3.95,33.14]],"ltp":3.9,"tv":6640.5,"id":11981493}]}]}
{"op":"mcm","clk":"992991466","pt":1580560189067,"mc":[{"id":"1.168136214","rc":[{"batb":[[1,1.82,122.05]],"batl":[[1,1.85,13],[2,1.86,42.12]],"ltp":1.83,"tv":16727.25,"id":17336468}]}]}
{"op":"mcm","clk":"992991825","pt":1580560191083,"mc":[{"id":"1.168136214","rc":[{"batb":[[0,5,6],[1,4.9,13.64]],"batl":[[0,5.2,10.97]],"ltp":5.2,"tv":5774.35,"id":12925630},{"trd":[[1.84,358.63]],"batl":[[0,1.85,2],[1,1.86,42.12],[2,1.87,17.27]],"ltp":1.84,"tv":16761.97,"id":17336468}],"tv":29176.83}]}
{"op":"mcm","clk":"992992044","pt":1580560192082,"mc":[{"id":"1.168136214","rc":[{"batb":[[2,4.8,46.21]],"ltp":5.2,"tv":5774.35,"id":12925630},{"batl":[[0,3.9,2],[1,3.95,33.14],[2,4,105.7]],"ltp":3.9,"tv":6640.5,"id":11981493}]}]}
{"op":"mcm","clk":"992992234","pt":1580560193086,"mc":[{"id":"1.168136214","rc":[{"trd":[[5,39.9]],"batb":[[0,4.9,15.64],[1,4.8,46.21],[2,4.7,64.44]],"batl":[[0,5,23.15],[1,5.2,10.97],[2,5.3,25.58]],"ltp":5.0,"tv":5778.71,"id":12925630},{"batb":[[0,1.83,70.96]],"batl":[[0,1.85,2.2],[1,1.86,28.63],[2,1.87,24.79]],"ltp":1.84,"tv":16761.97,"id":17336468},{"batl":[[2,4,112.53]],"ltp":3.9,"tv":6640.5,"id":11981493}],"tv":29181.19}]}
{"op":"mcm","clk":"992992395","pt":1580560194098,"mc":[{"id":"1.168136214","rc":[{"batb":[[2,4.7,9]],"batl":[[1,5.1,3.29],[2,5.2,10.97]],"ltp":5.0,"tv":5778.71,"id":12925630},{"batb":[[0,1.84,33.22],[1,1.83,325.96],[2,1.82,206.28]],"batl":[[1,1.86,20]],"ltp":1.84,"tv":16761.97,"id":17336468},{"batl":[[2,4,116.53]],"ltp":3.9,"tv":6640.5,"id":11981493}]}]}
{"op":"mcm","clk":"992992746","pt":1580560196087,"mc":[{"id":"1.168136214","rc":[{"batb":[[1,4.8,37.76],[2,4.7,17.45]],"ltp":5.0,"tv":5778.71,"id":12925630},{"batb":[[0,1.84,42.22]],"ltp":1.84,"tv":16761.97,"id":17336468}]}]}
{"op":"mcm","clk":"992992907","pt":1580560197064,"mc":[{"id":"1.168136214","rc":[{"batb":[[0,1.84,44.22],[1,1.83,323.96]],"ltp":1.84,"tv":16761.97,"id":17336468}]}]}
{"op":"mcm","clk":"992993324","pt":1580560199095,"mc":[{"id":"1.168136214","rc":[{"batb":[[2,1.82,131.28]],"batl":[[0,1.85,8.2]],"ltp":1.84,"tv":16761.97,"id":17336468}]}]}
{"op":"mcm","clk":"992993500","pt":1580560200106,"mc":[{"id":"1.168136214","rc":[{"batl":[[0,1.85,10.2]],"ltp":1.84,"tv":16761.97,"id":17336468}]}]}
{"op":"mcm","clk":"992994079","pt":1580560203019,"mc":[{"id":"1.168136214","rc":[{"trd":[[1.85,316.13]],"batl":[[0,1.85,2.2]],"ltp":1.85,"tv":16777.97,"id":17336468},{"batl":[[1,3.95,53.4]],"ltp":3.9,"tv":6640.5,"id":11981493}],"tv":29197.19}]}
{"op":"mcm","clk":"992994285","pt":1580560204113,"mc":[{"id":"1.168136214","rc":[{"batb":[[1,1.83,325.96]],"ltp":1.85,"tv":16777.97,"id":17336468}]}]}
{"op":"mcm","clk":"992994443","pt":1580560205122,"mc":[{"id":"1.168136214","rc":[{"batb":[[0,3.85,20.16]],"ltp":3.9,"tv":6640.5,"id":11981493}]}]}
{"op":"mcm","clk":"992994829","pt":1580560206048,"mc":[{"id":"1.168136214","rc":[{"batb":[[0,4.9,8.64]],"batl":[[0,5,26.15]],"ltp":5.0,"tv":5778.71,"id":12925630},{"trd":[[1.85,320.13]],"batb":[[0,1.84,42.22]],"batl":[[0,1.86,5.2],[1,1.87,24.79],[2,1.88,31.04]],"ltp":1.85,"tv":16781.97,"id":17336468}],"tv":29201.19}]}
{"op":"mcm","clk":"992995082","pt":1580560207150,"mc":[{"id":"1.168136214","rc":[{"trd":[[1.84,362.65]],"batb":[[0,1.84,40.21]],"ltp":1.84,"tv":16785.99,"id":17336468}],"tv":29205.21}]}
{"op":"mcm","clk":"992995240","pt":1580560208022,"mc":[{"id":"1.168136214","rc":[{"batb":[[1,4.8,34.49],[2,4.7,20.78]],"ltp":5.0,"tv":5778.71,"id":12925630},{"batl":[[0,3.9,6.04]],"ltp":3.9,"tv":6640.5,"id":11981493}]}]}
{"op":"mcm","clk":"992995576","pt":1580560209955,"mc":[{"id":"1.168136214","rc":[{"batb":[[0,4.9,15.64]],"ltp":5.0,"tv":5778.71,"id":12925630},{"batl":[[0,1.85,6.2],[1,1.86,5],[2,1.87,24.79]],"ltp":1.84,"tv":16785.99,"id":17336468},{"batl":[[0,3.9,2]],"ltp":3.9,"tv":6640.5,"id":11981493}]}]}
{"op":"mcm","clk":"992996429","pt":1580560214074,"mc":[{"id":"1.168136214","rc":[{"batb":[[0,1.84,90.86]],"ltp":1.84,"tv":16785.99,"id":17336468}]}]}
{"op":"mcm","clk":"992996810","pt":1580560216153,"mc":[{"id":"1.168136214","rc":[{"batb":[[0,4.9,8.64]],"ltp":5.0,"tv":5778.71,"id":12925630},{"trd":[[1.85,332.53]],"batb":[[0,1.85,14.88],[1,1.84,90.86],[2,1.83,325.96]],"batl":[[0,1.86,5],[1,1.87,24.79],[2,1.88,46.04]],"ltp":1.85,"tv":16798.39,"id":17336468},{"batl":[[0,3.9,6.08]],"ltp":3.9,"tv":6640.5,"id":11981493}],"tv":29217.61}]}
{"op":"mcm","clk":"992996980","pt":1580560217074,"mc":[{"id":"1.168136214","rc":[{"batl":[[1,1.87,17.27]],"ltp":1.85,"tv":16798.39,"id":17336468}]}]}
{"op":"mcm","clk":"992997367","pt":1580560219078,"mc":[{"id":"1.168136214","rc":[{"trd":[[1.85,350.53]],"batb":[[0,1.85,5.88]],"ltp":1.85,"tv":16816.39,"id":17336468}],"tv":29235.61}]}
{"op":"mcm","clk":"992998168","pt":1580560223061,"mc":[{"id":"1.168136214","rc":[{"batl":[[1,5.1,8.31]],"ltp":5.0,"tv":5778.71,"id":12925630}]}]}
{"op":"mcm","clk":"992999284","pt":1580560229144,"mc":[{"id":"1.168136214","rc":[{"batl":[[0,1.86,5.2]],"ltp":1.85,"tv":16816.39,"id":17336468}]}]}
{"op":"mcm","clk":"993000034","pt":1580560233066,"mc":[{"id":"1.168136214","rc":[{"batb":[[2,4.7,12.34]],"ltp":5.0,"tv":5778.71,"id":12925630},{"trd":[[1.86,355.68]],"batl":[[0,1.86,2.94]],"ltp":1.86,"tv":16820.91,"id":17336468}],"tv":29240.13}]}
{"op":"mcm","clk":"993000573","pt":1580560236141,"mc":[{"id":"1.168136214","rc":[{"trd":[[1.86,361.56]],"batb":[[0,1.86,68.06],[1,1.85,5.88],[2,1.84,90.86]],"batl":[[0,1.87,17.27],[1,1.88,46.04],[2,1.89,930.39]],"ltp":1.86,"tv":16826.79,"id":17336468}],"tv":29246.01}]}
{"op":"mcm","clk":"993000754","pt":1580560237051,"mc":[{"id":"1.168136214","rc":[{"batb":[[0,4.9,4.18],[1,4.8,22.07]],"batl":[[1,5.1,16.07]],"ltp":5.0,"tv":5778.71,"id":12925630},{"trd":[[1.86,393.56]],"batb":[[0,1.86,52.06],[1,1.85,9]],"batl":[[1,1.88,56.05],[2,1.89,946.39]],"ltp":1.86,"tv":16858.79,"id":17336468},{"batb":[[1,3.8,5]],"ltp":3.9,"tv":6640.5,"id":11981493}],"tv":29278.01}]}
{"op":"mcm","clk":"993001001","pt":1580560238144,"mc":[{"id":"1.168136214","rc":[{"batb":[[1,4.8,22.25]],"ltp":5.0,"tv":5778.71,"id":12925630}]}]}
{"op":"mcm","clk":"993001206","pt":1580560239140,"mc":[{"id":"1.168136214","rc":[{"batl":[[2,5.2,18.84]],"ltp":5.0,"tv":5778.71,"id":12925630}]}]}
{"op":"mcm","clk":"993001418","pt":1580560240049,"mc":[{"id":"1.168136214","rc":[{"batl":[[2,1.89,916]],"ltp":1.86,"tv":16858.79,"id":17336468}]}]}
{"op":"mcm","clk":"993002368","pt":1580560245151,"mc":[{"id":"1.168136214","rc":[{"trd":[[3.9,486.52]],"batl":[[0,3.9,4.08]],"ltp":3.9,"tv":6644.5,"id":11981493}],"tv":29282.01}]}
{"op":"mcm","clk":"993002554","pt":1580560246062,"mc":[{"id":"1.168136214","rc":[{"batb":[[0,4.9,6.18]],"ltp":5.0,"tv":5778.71,"id":12925630},{"batb":[[1,3.8,7]],"ltp":3.9,"tv":6644.5,"id":11981493}]}]}
{"op":"mcm","clk":"993002736","pt":1580560247081,"mc":[{"id":"1.168136214","rc":[{"batl":[[2,5.2,10.97]],"ltp":5.0,"tv":5778.71,"id":12925630},{"batb":[[0,3.85,22.16]],"ltp":3.9,"tv":6644.5,"id":11981493}]}]}
{"op":"mcm","clk":"993002970","pt":1580560248156,"mc":[{"id":"1.168136214","rc":[{"trd":[[1.86,405.56]],"batb":[[0,1.86,46.06]],"ltp":1.86,"tv":16870.79,"id":17336468}],"tv":29294.01}]}
{"op":"mcm","clk":"993003487","pt":1580560251114,"mc":[{"id":"1.168136214","rc":[{"batl":[[0,3.9,6.08]],"ltp":3.9,"tv":6644.5,"id":11981493}]}]}
{"op":"mcm","clk":"993004214","pt":1580560255136,"mc":[{"id":"1.168136214","rc":[{"batb":[[2,1.84,40.21]],"ltp":1.86,"tv":16870.79,"id":17336468}]}]}
{"op":"mcm","clk":"993004562","pt":1580560257137,"mc":[{"id":"1.168136214","rc":[{"batb":[[0,1.86,48.06]],"ltp":1.86,"tv":16870.79,"id":17336468}]}]}
{"op":"mcm","clk":"993004739","pt":1580560258051,"mc":[{"id":"1.168136214","rc":[{"batl":[[0,5,34.41]],"ltp":5.0,"tv":5778.71,"id":12925630},{"trd":[[1.87,307.26]],"batl":[[0,1.87,24.73]],"ltp":1.87,"tv":16878.36,"id":17336468}],"tv":29301.58}]}
{"op":"mcm","clk":"993005531","pt":1580560262055,"mc":[{"id":"1.168136214","rc":[{"trd":[[1.87,312.26]],"batl":[[0,1.87,22.23]],"ltp":1.87,"tv":16883.36,"id":17336468}],"tv":29306.58}]}
{"op":"mcm","clk":"993005752","pt":1580560263140,"mc":[{"id":"1.168136214","rc":[{"trd":[[1.87,322.48]],"batl":[[0,1.87,17.12]],"ltp":1.87,"tv":16893.58,"id":17336468}],"tv":29316.8}]}
{"op":"mcm","clk":"993005942","pt":1580560264153,"mc":[{"id":"1.168136214","rc":[{"batl":[[0,1.87,17.32],[1,1.88,106.7]],"ltp":1.87,"tv":16893.58,"id":17336468}]}]}
{"op":"mcm","clk":"993006531","pt":1580560267096,"mc":[{"id":"1.168136214","rc":[{"batl":[[0,5,26.15]],"ltp":5.0,"tv":5778.71,"id":12925630},{"trd":[[1.86,478.22]],"batb":[[0,1.86,11.73]],"batl":[[0,1.87,42.94]],"ltp":1.86,"tv":16966.24,"id":17336468},{"trd":[[3.9,490.52]],"batl":[[0,3.9,4.08]],"ltp":3.9,"tv":6648.5,"id":11981493}],"tv":29393.46}]}
{"op":"mcm","clk":"993006752","pt":1580560268070,"mc":[{"id":"1.168136214","rc":[{"batb":[[0,4.9,13.18]],"ltp":5.0,"tv":5778.71,"id":12925630},{"trd":[[1.86,501.68]],"batb":[[0,1.85,9],[1,1.84,40.21],[2,1.83,325.96]],"batl":[[0,1.87,97.14],[2,1.89,946.39]],"ltp":1.86,"tv":16989.7,"id":17336468},{"batl":[[0,3.9,6.08]],"ltp":3.9,"tv":6648.5,"id":11981493}],"tv":29416.92}]}
{"op":"mcm","clk":"993007106","pt":1580560270073,"mc":[{"id":"1.168136214","rc":[{"batl":[[0,5,34.44]],"ltp":5.0,"tv":5778.71,"id":12925630},{"trd":[[1.87,360.34]],"batb":[[1,1.84,90.86]],"batl":[[0,1.87,54.2]],"ltp":1.87,"tv":17027.57,"id":17336468}],"tv":29454.79}]}
{"op":"mcm","clk":"993007709","pt":1580560273078,"mc":[{"id":"1.168136214","rc":[{"batl":[[2,1.89,916]],"ltp":1.87,"tv":17027.57,"id":17336468}]}]}
{"op":"mcm","clk":"993008280","pt":1580560276136,"mc":[{"id":"1.168136214","rc":[{"batb":[[0,4.9,6.18]],"ltp":5.0,"tv":5778.71,"id":12925630},{"batl":[[0,1.87,60.07]],"ltp":1.87,"tv":17027.57,"id":17336468},{"batb":[[2,3.75,25.01]],"ltp":3.9,"tv":6648.5,"id":11981493}]}]}
{"op":"mcm","clk":"993008665","pt":1580560278054,"mc":[{"id":"1.168136214","rc":[{"batl":[[0,1.86,5],[1,1.87,60.07],[2,1.88,106.7]],"ltp":1.87,"tv":17027.57,"id":17336468}]}]}
{"op":"mcm","clk":"993010232","pt":1580560286146,"mc":[{"id":"1.168136214","rc":[{"trd":[[5,84.64]],"batb":[[1,4.8,27.24]],"batl":[[0,5,3.79]],"ltp":5.0,"tv":5823.44,"id":12925630},{"batl":[[0,1.86,30.86]],"ltp":1.87,"tv":17027.57,"id":17336468}],"tv":29499.52}]}
{"op":"mcm","clk":"993010415","pt":1580560287066,"mc":[{"id":"1.168136214","rc":[{"batb":[[0,4.9,13.18],[2,4.7,21.81]],"ltp":5.0,"tv":5823.44,"id":12925630}]}]}
{"op":"mcm","clk":"993011181","pt":1580560290091,"mc":[{"id":"1.168136214","rc":[{"trd":[[1.86,563.42],[1.87,466.61]],"batl":[[0,1.87,6.94],[1,1.88,106.7],[2,1.89,916]],"ltp":1.87,"tv":17195.57,"id":17336468}],"tv":29667.53}]}
{"op":"mcm","clk":"993011393","pt":1580560291076,"mc":[{"id":"1.168136214","rc":[{"trd":[[5,86.22]],"batl":[[0,5.1,16.07],[1,5.2,10.97],[2,5.3,25.58]],"ltp":5.0,"tv":5825.02,"id":12925630},{"batb":[[0,1.84,90.86],[1,1.83,325.96],[2,1.82,32.08]],"batl":[[0,1.87,14.07]],"ltp":1.87,"tv":17195.57,"id":17336468}],"tv":29669.11}]}
{"op":"mcm","clk":"993012817","pt":1580560298083,"mc":[{"id":"1.168136214","rc":[{"batl":[[0,5.1,27.91]],"ltp":5.0,"tv":5825.02,"id":12925630}]}]}
{"op":"mcm","clk":"993013147","pt":1580560300072,"mc":[{"id":"1.168136214","rc":[{"batb":[[0,1.84,91.06]],"batl":[[0,1.87,14.27]],"ltp":1.87,"tv":17195.57,"id":17336468}]}]}
{"op":"mcm","clk":"993013349","pt":1580560301062,"mc":[{"id":"1.168136214","rc":[{"trd":[[1.84,394.65]],"batb":[[0,1.84,75.06]],"ltp":1.84,"tv":17227.57,"id":17336468}],"tv":29701.11}]}
{"op":"mcm","clk":"993013548","pt":1580560302055,"mc":[{"id":"1.168136214","rc":[{"trd":[[1.84,398.65]],"batb":[[0,1.84,73.06]],"ltp":1.84,"tv":17231.57,"id":17336468}],"tv":29705.11}]}
{"op":"mcm","clk":"993014689","pt":1580560307990,"mc":[{"id":"1.168136214","rc":[{"batb":[[0,4.9,6.18]],"ltp":5.0,"tv":5825.02,"id":12925630},{"batb":[[0,1.85,11.26],[1,1.84,73.06],[2,1.83,325.96]],"batl":[[0,1.86,7],[1,1.87,14.27],[2,1.88,106.7]],"ltp":1.84,"tv":17231.57,"id":17336468}]}]}
{"op":"mcm","clk":"993015071","pt":1580560309885,"mc":[{"id":"1.168136214","rc":[{"batl":[[0,1.86,35.12]],"ltp":1.84,"tv":17231.57,"id":17336468}]}]}
{"op":"mcm","clk":"993016056","pt":1580560315101,"mc":[{"id":"1.168136214","rc":[{"batb":[[0,4.9,8.18]],"ltp":5.0,"tv":5825.02,"id":12925630}]}]}
{"op":"mcm","clk":"993016218","pt":1580560315980,"mc":[{"id":"1.168136214","rc":[{"batb":[[0,3.85,24.16]],"ltp":3.9,"tv":6648.5,"id":11981493}]}]}
{"op":"mcm","clk":"993016578","pt":1580560317994,"mc":[{"id":"1.168136214","rc":[{"batl":[[0,5.1,36.15]],"ltp":5.0,"tv":5825.02,"id":12925630},{"trd":[[1.86,579.42]],"batl":[[0,1.86,27.12]],"ltp":1.86,"tv":17247.57,"id":17336468}],"tv":29721.11}]}
{"op":"mcm","clk":"993016955","pt":1580560320106,"mc":[{"id":"1.168136214","rc":[{"batb":[[0,4.9,17.94]],"ltp":5.0,"tv":5825.02,"id":12925630},{"batb":[[0,1.85,13.26]],"ltp":1.86,"tv":17247.57,"id":17336468}]}]}
{"op":"mcm","clk":"993018398","pt":1580560326111,"mc":[{"id":"1.168136214","rc":[{"trd":[[1.86,595.34]],"batl":[[0,1.86,19.16]],"ltp":1.86,"tv":17263.49,"id":17336468}],"tv":29737.03}]}
{"op":"mcm","clk":"993018838","pt":1580560328107,"mc":[{"id":"1.168136214","rc":[{"batl":[[0,1.86,21.16],[1,1.87,14.07]],"ltp":1.86,"tv":17263.49,"id":17336468}]}]}
{"op":"mcm","clk":"993019708","pt":1580560332105,"mc":[{"id":"1.168136214","rc":[{"batb":[[0,4.9,24.94]],"ltp":5.0,"tv":5825.02,"id":12925630},{"trd":[[1.85,379.1]],"batb":[[0,1.84,73.06],[1,1.83,325.96],[2,1.82,32.08]],"ltp":1.85,"tv":17292.07,"id":17336468}],"tv":29765.6}]}
{"op":"mcm","clk":"993019910","pt":1580560333138,"mc":[{"id":"1.168136214","rc":[{"batb":[[2,4.7,12.34]],"ltp":5.0,"tv":5825.02,"id":12925630}]}]}
{"op":"mcm","clk":"993020083","pt":1580560334002,"mc":[{"id":"1.168136214","rc":[{"trd":[[4.9,52.62]],"batb":[[0,4.9,14.94],[1,4.8,36.71]],"ltp":4.9,"tv":5845.02,"id":12925630},{"batb":[[0,1.85,62.79],[1,1.84,73.06],[2,1.83,325.96]],"batl":[[2,1.88,115.05]],"ltp":1.85,"tv":17292.07,"id":17336468}],"tv":29785.6}]}
{"op":"mcm","clk":"993020308","pt":1580560335144,"mc":[{"id":"1.168136214","rc":[{"batl":[[0,1.86,21.36]],"ltp":1.85,"tv":17292.07,"id":17336468}]}]}
{"op":"mcm","clk":"993020685","pt":1580560337111,"mc":[{"id":"1.168136214","rc":[{"batl":[[2,5.3,32.64]],"ltp":4.9,"tv":5845.02,"id":12925630}]}]}
{"op":"mcm","clk":"993020865","pt":1580560338041,"mc":[{"id":"1.168136214","rc":[{"batb":[[0,4.9,7.94],[1,4.8,27.24],[2,4.7,21.81]],"ltp":4.9,"tv":5845.02,"id":12925630},{"batl":[[0,1.86,27.36]],"ltp":1.85,"tv":17292.07,"id":17336468}]}]}
{"op":"mcm","clk":"993022009","pt":1580560343930,"mc":[{"id":"1.168136214","rc":[{"batb":[[0,5,1.68],[1,4.9,7.94],[2,4.8,27.24]],"ltp":4.9,"tv":5845.02,"id":12925630},{"batb":[[0,1.85,51.72]],"ltp":1.85,"tv":17292.07,"id":17336468}]}]}
{"op":"mcm","clk":"993023223","pt":1580560349888,"mc":[{"id":"1.168136214","rc":[{"batb":[[0,4.9,7.94],[1,4.8,27.24],[2,4.7,21.81]],"ltp":4.9,"tv":5845.02,"id":12925630},{"batb":[[0,1.85,62.72]],"ltp":1.85,"tv":17292.07,"id":17336468}]}]}
{"op":"mcm","clk":"993034277","pt":1580560353101,"mc":[{"id":"1.168136214","rc":[{"trd":[[4.9,56.62]],"batb":[[0,4.9,5.94]],"batl":[[0,5,18],[1,5.1,36.15],[2,5.2,10.97]],"ltp":4.9,"tv":5849.02,"id":12925630}],"tv":29789.6}]}
{"op":"mcm","clk":"993034485","pt":1580560354098,"mc":[{"id":"1.168136214","rc":[{"batl":[[0,1.86,8.2]],"ltp":1.85,"tv":17292.07,"id":17336468},{"trd":[[3.85,869.21]],"batb":[[0,3.85,22.48]],"ltp":3.85,"tv":6651.86,"id":11981493}],"tv":29792.96}]}
{"op":"mcm","clk":"993034656","pt":1580560355137,"mc":[{"id":"1.168136214","rc":[{"batl":[[2,1.88,106.7]],"ltp":1.85,"tv":17292.07,"id":17336468},{"trd":[[3.85,869.63]],"batb":[[0,3.85,22.27]],"ltp":3.85,"tv":6652.28,"id":11981493}],"tv":29793.38}]}
{"op":"mcm","clk":"993034871","pt":1580560356127,"mc":[{"id":"1.168136214","rc":[{"trd":[[1.85,427.93]],"batb":[[0,1.85,11]],"batl":[[0,1.86,34.21]],"ltp":1.85,"tv":17340.9,"id":17336468},{"trd":[[3.9,494.52]],"batb":[[0,3.85,32.67]],"batl":[[0,3.9,4.08]],"ltp":3.9,"tv":6656.28,"id":11981493}],"tv":29846.22}]}
{"op":"mcm","clk":"993036332","pt":1580560363143,"mc":[{"id":"1.168136214","rc":[{"batl":[[0,1.86,34.01]],"ltp":1.85,"tv":17340.9,"id":17336468}]}]}
{"op":"mcm","clk":"993037558","pt":1580560369051,"mc":[{"id":"1.168136214","rc":[{"batb":[[0,3.85,34.67]],"ltp":3.9,"tv":6656.28,"id":11981493}]}]}
{"op":"mcm","clk":"993038004","pt":1580560371019,"mc":[{"id":"1.168136214","rc":[{"batl":[[0,1.86,34.21]],"ltp":1.85,"tv":17340.9,"id":17336468}]}]}
{"op":"mcm","clk":"993038412","pt":1580560373136,"mc":[{"id":"1.168136214","rc":[{"batb":[[2,4.7,12.34]],"ltp":4.9,"tv":5849.02,"id":12925630},{"batb":[[0,1.85,16]],"ltp":1.85,"tv":17340.9,"id":17336468}]}]}
{"op":"mcm","clk":"993038618","pt":1580560374121,"mc":[{"id":"1.168136214","rc":[{"trd":[[1.85,436.25],[1.86,595.5]],"batb":[[0,1.85,11.84]],"batl":[[0,1.86,34.13]],"ltp":1.85,"tv":17349.38,"id":17336468},{"trd":[[3.85,873.63]],"batb":[[0,3.85,22.27]],"ltp":3.85,"tv":6660.28,"id":11981493}],"tv":29858.7}]}
{"op":"mcm","clk":"993042321","pt":1580560392094,"mc":[{"id":"1.168136214","rc":[{"trd":[[1.85,459.93]],"batb":[[0,1.85,9]],"ltp":1.85,"tv":17373.06,"id":17336468},{"batb":[[0,3.85,32.67],[2,3.75,28.01]],"batl":[[0,3.9,6.08]],"ltp":3.85,"tv":6660.28,"id":11981493}],"tv":29882.38}]}
{"op":"mcm","clk":"993043724","pt":1580560398786,"mc":[{"id":"1.168136214","rc":[{"batl":[[0,1.86,33.93]],"ltp":1.85,"tv":17373.06,"id":17336468}]}]}
{"op":"mcm","clk":"993044430","pt":1580560402130,"mc":[{"id":"1.168136214","rc":[{"batb":[[0,4.9,12.94]],"ltp":4.9,"tv":5849.02,"id":12925630},{"trd":[[1.85,513.39]],"batb":[[0,1.85,3]],"batl":[[1,1.87,19.07]],"ltp":1.85,"tv":17426.52,"id":17336468},{"batb":[[1,3.8,10]],"ltp":3.85,"tv":6660.28,"id":11981493}],"tv":29935.84}]}
{"op":"mcm","clk":"993044619","pt":1580560403118,"mc":[{"id":"1.168136214","rc":[{"batb":[[0,4.9,5.94]],"batl":[[0,5,26.32]],"ltp":4.9,"tv":5849.02,"id":12925630},{"batb":[[0,1.85,12.12]],"batl":[[2,1.88,115.41]],"ltp":1.85,"tv":17426.52,"id":17336468},{"batl":[[0,3.9,2]],"ltp":3.85,"tv":6660.28,"id":11981493}]}]}
{"op":"mcm","clk":"993044809","pt":1580560404033,"mc":[{"id":"1.168136214","rc":[{"trd":[[1.85,523.39]],"batb":[[0,1.85,7.12]],"ltp":1.85,"tv":17436.52,"id":17336468}],"tv":29945.84}]}
{"op":"mcm","clk":"993044999","pt":1580560405120,"mc":[{"id":"1.168136214","rc":[{"batb":[[0,4.9,15.7]],"ltp":4.9,"tv":5849.02,"id":12925630},{"batb":[[0,3.85,35.2]],"ltp":3.85,"tv":6660.28,"id":11981493}]}]}
{"op":"mcm","clk":"993045217","pt":1580560406116,"mc":[{"id":"1.168136214","rc":[{"batl":[[0,1.86,34.13]],"ltp":1.85,"tv":17436.52,"id":17336468}]}]}
{"op":"mcm","clk":"993045409","pt":1580560407031,"mc":[{"id":"1.168136214","rc":[{"batb":[[0,1.84,73.06],[1,1.83,325.96],[2,1.82,32.08]],"ltp":1.85,"tv":17436.52,"id":17336468},{"trd":[[3.9,498.52]],"batb":[[0,3.9,1.95],[1,3.85,40.2],[2,3.8,10]],"batl":[[0,3.95,53.4],[1,4,109.7],[2,4.1,304]],"ltp":3.9,"tv":6664.28,"id":11981493}],"tv":29949.83}]}
{"op":"mcm","clk":"993045781","pt":1580560409043,"mc":[{"id":"1.168136214","rc":[{"batb":[[0,1.85,9.15],[1,1.84,73.06],[2,1.83,325.96]],"ltp":1.85,"tv":17436.52,"id":17336468},{"trd":[[3.85,879.73],[3.9,502.41]],"batb":[[0,3.85,28.15],[1,3.8,10],[2,3.75,28.01]],"ltp":3.85,"tv":6674.28,"id":11981493}],"tv":29959.83}]}
{"op":"mcm","clk":"993046552","pt":1580560413120,"mc":[{"id":"1.168136214","rc":[{"batb":[[2,4.7,20.55]],"ltp":4.9,"tv":5849.02,"id":12925630}]}]}
{"op":"mcm","clk":"993047698","pt":1580560419131,"mc":[{"id":"1.168136214","rc":[{"trd":[[4.9,60.62]],"batb":[[0,4.9,13.7]],"ltp":4.9,"tv":5853.02,"id":12925630}],"tv":29963.83}]}
{"op":"mcm","clk":"993048282","pt":1580560422149,"mc":[{"id":"1.168136214","rc":[{"batb":[[0,1.85,19.15]],"ltp":1.85,"tv":17436.52,"id":17336468}]}]}
{"op":"mcm","clk":"993049423","pt":1580560427645,"mc":[{"id":"1.168136214","rc":[{"batb":[[0,1.85,69.15]],"batl":[[0,1.86,84.13]],"ltp":1.85,"tv":17436.52,"id":17336468}]}]}
{"op":"mcm","clk":"993049892","pt":1580560430057,"mc":[{"id":"1.168136214","rc":[{"trd":[[1.85,541.39]],"batb":[[0,1.85,60.15]],"ltp":1.85,"tv":17454.52,"id":17336468}],"tv":29981.83}]}
{"op":"mcm","clk":"993050722","pt":1580560434047,"mc":[{"id":"1.168136214","rc":[{"batl":[[0,1.86,83.93]],"ltp":1.85,"tv":17454.52,"id":17336468}]}]}
{"op":"mcm","clk":"993051138","pt":1580560436089,"mc":[{"id":"1.168136214","rc":[{"batb":[[0,3.85,30.15]],"ltp":3.85,"tv":6674.28,"id":11981493}]}]}
{"op":"mcm","clk":"993051514","pt":1580560437989,"mc":[{"id":"1.168136214","rc":[{"trd":[[4.9,72.62]],"batb":[[0,4.9,7.7]],"ltp":4.9,"tv":5865.02,"id":12925630},{"trd":[[1.85,661.69]],"batb":[[0,1.85,8]],"ltp":1.85,"tv":17574.82,"id":17336468}],"tv":30114.13}]}
{"op":"mcm","clk":"993051939","pt":1580560440064,"mc":[{"id":"1.168136214","rc":[{"batb":[[2,3.75,26.01]],"ltp":3.85,"tv":6674.28,"id":11981493}]}]}
{"op":"mcm","clk":"993052377","pt":1580560442076,"mc":[{"id":"1.168136214","rc":[{"batl":[[0,1.86,84.13]],"ltp":1.85,"tv":17574.82,"id":17336468}]}]}
{"op":"mcm","clk":"993052584","pt":1580560443107,"mc":[{"id":"1.168136214","rc":[{"trd":[[1.85,693.69]],"batb":[[0,1.84,73.06],[1,1.83,325.96],[2,1.82,32.08]],"batl":[[0,1.85,8.55],[1,1.86,84.13],[2,1.87,21.2]],"ltp":1.85,"tv":17606.82,"id":17336468},{"batb":[[0,3.9,2],[1,3.85,30.15],[2,3.8,10]],"batl":[[1,4,107.7]],"ltp":3.85,"tv":6674.28,"id":11981493}],"tv":30146.13}]}
{"op":"mcm","clk":"993052759","pt":1580560444128,"mc":[{"id":"1.168136214","rc":[{"trd":[[1.85,710.79]],"batb":[[0,1.85,7.47],[1,1.84,73.06],[2,1.83,325.96]],"batl":[[0,1.86,84.13],[1,1.87,21.2],[2,1.88,153.35]],"ltp":1.85,"tv":17623.92,"id":17336468},{"trd":[[3.9,534.41]],"batb":[[0,3.85,30.15],[1,3.8,10],[2,3.75,26.01]],"ltp":3.9,"tv":6706.28,"id":11981493}],"tv":30195.23}]}
{"op":"mcm","clk":"993052936","pt":1580560445000,"mc":[{"id":"1.168136214","rc":[{"batl":[[1,1.87,33.56]],"ltp":1.85,"tv":17623.92,"id":17336468}]}]}
{"op":"mcm","clk":"993053164","pt":1580560445998,"mc":[{"id":"1.168136214","rc":[{"batl":[[1,1.87,19.07]],"ltp":1.85,"tv":17623.92,"id":17336468}]}]}
{"op":"mcm","clk":"993053389","pt":1580560447099,"mc":[{"id":"1.168136214","rc":[{"batl":[[2,1.88,115.41]],"ltp":1.85,"tv":17623.92,"id":17336468}]}]}
{"op":"mcm","clk":"993053595","pt":1580560448084,"mc":[{"id":"1.168136214","rc":[{"trd":[[1.85,714.79]],"batb":[[0,1.85,5.47]],"ltp":1.85,"tv":17627.92,"id":17336468}],"tv":30199.23}]}
{"op":"mcm","clk":"993053778","pt":1580560449106,"mc":[{"id":"1.168136214","rc":[{"trd":[[1.86,599.48]],"batl":[[0,1.86,82.14]],"ltp":1.86,"tv":17631.9,"id":17336468}],"tv":30203.21}]}
{"op":"mcm","clk":"993054194","pt":1580560451112,"mc":[{"id":"1.168136214","rc":[{"trd":[[4.9,76.62]],"batb":[[0,4.9,5.7]],"ltp":4.9,"tv":5869.03,"id":12925630},{"trd":[[1.84,529.66],[1.85,725.73]],"batb":[[0,1.85,8.06],[1,1.84,52.88]],"ltp":1.84,"tv":17773.85,"id":17336468},{"batb":[[2,3.75,30.01]],"ltp":3.9,"tv":6706.28,"id":11981493}],"tv":30349.17}]}
{"op":"mcm","clk":"993054606","pt":1580560453116,"mc":[{"id":"1.168136214","rc":[{"batb":[[0,4.9,15.76],[2,4.7,24.55]],"ltp":4.9,"tv":5869.03,"id":12925630},{"trd":[[1.85,741.85]],"batb":[[0,1.84,52.88],[1,1.83,325.96],[2,1.82,32.08]],"batl":[[0,1.85,8.73],[1,1.86,82.14],[2,1.87,19.07]],"ltp":1.85,"tv":17789.97,"id":17336468},{"batb":[[1,3.8,14]],"ltp":3.9,"tv":6706.28,"id":11981493}],"tv":30365.29}]}
{"op":"mcm","clk":"993054796","pt":1580560454119,"mc":[{"id":"1.168136214","rc":[{"trd":[[3.85,887.73]],"batb":[[0,3.85,26.15]],"ltp":3.85,"tv":6714.28,"id":11981493}],"tv":30373.29}]}
{"op":"mcm","clk":"993056052","pt":1580560460121,"mc":[{"id":"1.168136214","rc":[{"trd":[[5,116.22]],"batl":[[0,5,11.32]],"ltp":5.0,"tv":5899.03,"id":12925630}],"tv":30403.29}]}
{"op":"mcm","clk":"993056215","pt":1580560461033,"mc":[{"id":"1.168136214","rc":[{"batb":[[0,4.9,60.76]],"batl":[[0,5.1,36.15],[1,5.2,10.97],[2,5.3,25.58]],"ltp":5.0,"tv":5899.03,"id":12925630},{"batb":[[0,1.84,15.57]],"batl":[[1,1.86,101.14]],"ltp":1.85,"tv":17789.97,"id":17336468}]}]}
{"op":"mcm","clk":"993056427","pt":1580560462114,"mc":[{"id":"1.168136214","rc":[{"batb":[[0,5,9],[1,4.9,60.76],[2,4.8,27.24]],"batl":[[2,5.3,23.03]],"ltp":5.0,"tv":5899.03,"id":12925630},{"batl":[[0,3.9,50],[1,3.95,53.4],[2,4,107.7]],"ltp":3.85,"tv":6714.28,"id":11981493}]}]}
{"op":"mcm","clk":"993056621","pt":1580560463144,"mc":[{"id":"1.168136214","rc":[{"batb":[[1,4.9,63.96],[2,4.8,34.56]],"batl":[[0,5.1,16.54]],"ltp":5.0,"tv":5899.03,"id":12925630},{"batb":[[0,1.84,34.1]],"ltp":1.85,"tv":17789.97,"id":17336468},{"trd":[[3.85,903.73]],"batb":[[0,3.85,7.74],[2,3.75,17.22]],"ltp":3.85,"tv":6730.28,"id":11981493}],"tv":30419.29}]}
{"op":"mcm","clk":"993056805","pt":1580560464141,"mc":[{"id":"1.168136214","rc":[{"batb":[[0,5,19]],"batl":[[0,5.2,10.97],[1,5.3,23.03],[2,5.4,17.37]],"ltp":5.0,"tv":5899.03,"id":12925630},{"batb":[[0,1.84,42.1]],"batl":[[0,1.85,14.66],[1,1.86,95.21]],"ltp":1.85,"tv":17789.97,"id":17336468},{"trd":[[3.85,919.22]],"batb":[[0,3.8,14],[1,3.75,17.22],[2,3.7,57.43]],"batl":[[0,3.85,4.26],[1,3.9,53],[2,3.95,53.4]],"ltp":3.85,"tv":6745.76,"id":11981493}],"tv":30434.77}]}
{"op":"mcm","clk":"993056958","pt":1580560464841,"mc":[{"id":"1.168136214","rc":[{"batb":[[0,3.8,2]],"ltp":3.85,"tv":6745.76,"id":11981493}]}]}
{"op":"mcm","clk":"993057133","pt":1580560466147,"mc":[{"id":"1.168136214","rc":[{"batl":[[1,5.3,26.54]],"ltp":5.0,"tv":5899.03,"id":12925630},{"batl":[[0,1.85,65.31]],"ltp":1.85,"tv":17789.97,"id":17336468},{"batb":[[1,3.75,12]],"ltp":3.85,"tv":6745.76,"id":11981493}]}]}
{"op":"mcm","clk":"993057433","pt":1580560467123,"mc":[{"id":"1.168136214","rc":[{"trd":[[1.84,534.7]],"batb":[[0,1.84,39.58]],"ltp":1.84,"tv":17795.01,"id":17336468}],"tv":30439.81}]}
{"op":"mcm","clk":"993057596","pt":1580560468047,"mc":[{"id":"1.168136214","rc":[{"batb":[[0,5,64],[1,4.9,18.96]],"ltp":5.0,"tv":5899.03,"id":12925630},{"batb":[[0,1.84,31.58]],"ltp":1.84,"tv":17795.01,"id":17336468}]}]}
{"op":"mcm","clk":"993057780","pt":1580560469035,"mc":[{"id":"1.168136214","rc":[{"batb":[[2,4.8,95.36]],"ltp":5.0,"tv":5899.03,"id":12925630}]}]}
{"op":"mcm","clk":"993057954","pt":1580560469918,"mc":[{"id":"1.168136214","rc":[{"batl":[[1,1.86,95.01]],"ltp":1.84,"tv":17795.01,"id":17336468}]}]}
{"op":"mcm","clk":"993058573","pt":1580560473120,"mc":[{"id":"1.168136214","rc":[{"batb":[[0,3.8,14]],"ltp":3.85,"tv":6745.76,"id":11981493}]}]}
{"op":"mcm","clk":"993059149","pt":1580560476059,"mc":[{"id":"1.168136214","rc":[{"batl":[[2,3.95,33.14]],"ltp":3.85,"tv":6745.76,"id":11981493}]}]}
{"op":"mcm","clk":"993059562","pt":1580560478152,"mc":[{"id":"1.168136214","rc":[{"batb":[[0,5.1,45],[1,5,19],[2,4.9,13.26]],"ltp":5.0,"tv":5899.03,"id":12925630},{"batl":[[0,1.85,91.26]],"ltp":1.84,"tv":17795.01,"id":17336468}]}]}
{"op":"mcm","clk":"993059760","pt":1580560479137,"mc":[{"id":"1.168136214","rc":[{"batb":[[0,1.84,5.06]],"ltp":1.84,"tv":17795.01,"id":17336468}]}]}
{"op":"mcm","clk":"993059966","pt":1580560480133,"mc":[{"id":"1.168136214","rc":[{"batb":[[2,1.82,18.23]],"ltp":1.84,"tv":17795.01,"id":17336468}]}]}
{"op":"mcm","clk":"993060129","pt":1580560481148,"mc":[{"id":"1.168136214","rc":[{"batb":[[1,1.83,292.12],[2,1.82,9]],"ltp":1.84,"tv":17795.01,"id":17336468}]}]}
{"op":"mcm","clk":"993060916","pt":1580560485138,"mc":[{"id":"1.168136214","rc":[{"trd":[[5.2,302.22]],"batb":[[0,5.2,32.23],[1,5.1,10.24],[2,5,19]],"batl":[[0,5.3,19.32],[1,5.4,17.37],[2,5.5,12.4]],"ltp":5.2,"tv":5922.76,"id":12925630},{"trd":[[1.84,539.76]],"batb":[[0,1.83,282.86],[1,1.82,9],[2,1.81,34.53]],"batl":[[0,1.85,110.26]],"ltp":1.84,"tv":17800.07,"id":17336468},{"trd":[[3.8,1430.56]],"batb":[[0,3.8,11.55]],"batl":[[0,3.85,7.26]],"ltp":3.8,"tv":6748.21,"id":11981493}],"tv":30471.06}]}
{"op":"mcm","clk":"993061139","pt":1580560486152,"mc":[{"id":"1.168136214","rc":[{"trd":[[5.2,321.78]],"batb":[[0,5.2,22.45]],"batl":[[0,5.3,15.81],[1,5.4,22.81]],"ltp":5.2,"tv":5942.32,"id":12925630},{"batb":[[2,3.7,44.64]],"batl":[[0,3.85,9.26],[2,3.95,46.27]],"ltp":3.8,"tv":6748.21,"id":11981493}],"tv":30490.62}]}
{"op":"mcm","clk":"993061312","pt":1580560487087,"mc":[{"id":"1.168136214","rc":[{"batl":[[0,5.3,10.95],[1,5.4,17.37]],"ltp":5.2,"tv":5942.32,"id":12925630},{"trd":[[1.83,652.93]],"batb":[[0,1.83,252.29]],"ltp":1.83,"tv":17861.24,"id":17336468},{"batl":[[1,3.9,58.42]],"ltp":3.8,"tv":6748.21,"id":11981493}],"tv":30551.79}]}
{"op":"mcm","clk":"993061636","pt":1580560488776,"mc":[{"id":"1.168136214","rc":[{"batl":[[2,3.95,44.27]],"ltp":3.8,"tv":6748.21,"id":11981493}]}]}
{"op":"mcm","clk":"993061897","pt":1580560490067,"mc":[{"id":"1.168136214","rc":[{"batl":[[2,3.95,31.14]],"ltp":3.8,"tv":6748.21,"id":11981493}]}]}
{"op":"mcm","clk":"993062299","pt":1580560492067,"mc":[{"id":"1.168136214","rc":[{"batl":[[0,3.85,11.26]],"ltp":3.8,"tv":6748.21,"id":11981493}]}]}
{"op":"mcm","clk":"993062520","pt":1580560493092,"mc":[{"id":"1.168136214","rc":[{"batb":[[2,5,33.97]],"ltp":5.2,"tv":5942.32,"id":12925630}]}]}
{"op":"mcm","clk":"993063111","pt":1580560496060,"mc":[{"id":"1.168136214","rc":[{"trd":[[5.3,90]],"batb":[[0,5.2,10]],"batl":[[0,5.3,3.21],[2,5.5,14.4]],"ltp":5.3,"tv":5978.93,"id":12925630},{"trd":[[1.83,676.91],[1.84,547.75]],"batb":[[0,1.83,228.31]],"batl":[[0,1.84,50.23],[1,1.85,110.26],[2,1.86,95.01]],"ltp":1.84,"tv":17893.22,"id":17336468},{"trd":[[3.8,1442.11]],"batb":[[0,3.75,29.59],[1,3.7,44.64],[2,3.65,34.68]],"ltp":3.8,"tv":6759.76,"id":11981493}],"tv":30631.92}]}
{"op":"mcm","clk":"993063286","pt":1580560497097,"mc":[{"id":"1.168136214","rc":[{"batb":[[0,5.1,10.24],[1,5,33.97],[2,4.9,13.26]],"ltp":5.3,"tv":5978.93,"id":12925630}]}]}
{"op":"mcm","clk":"993063498","pt":1580560498090,"mc":[{"id":"1.168136214","rc":[{"batb":[[1,5,31.58]],"ltp":5.3,"tv":5978.93,"id":12925630},{"trd":[[3.85,941.74]],"batl":[[0,3.85,3]],"ltp":3.85,"tv":6782.28,"id":11981493}],"tv":30654.44}]}
{"op":"mcm","clk":"993063718","pt":1580560499070,"mc":[{"id":"1.168136214","rc":[{"batb":[[1,5,34.58],[2,4.9,22.98]],"ltp":5.3,"tv":5978.93,"id":12925630},{"batb":[[0,3.75,33.59]],"ltp":3.85,"tv":6782.28,"id":11981493}]}]}
{"op":"mcm","clk":"993064138","pt":1580560501094,"mc":[{"id":"1.168136214","rc":[{"batb":[[1,3.7,59.09]],"ltp":3.85,"tv":6782.28,"id":11981493}]}]}
{"op":"mcm","clk":"993064373","pt":1580560502083,"mc":[{"id":"1.168136214","rc":[{"batb":[[2,3.65,121.87]],"ltp":3.85,"tv":6782.28,"id":11981493}]}]}
{"op":"mcm","clk":"993064578","pt":1580560503094,"mc":[{"id":"1.168136214","rc":[{"batl":[[0,1.84,56.16],[1,1.85,104.33]],"ltp":1.84,"tv":17893.22,"id":17336468},{"batb":[[0,3.75,44.59]],"ltp":3.85,"tv":6782.28,"id":11981493}]}]}
{"op":"mcm","clk":"993066186","pt":1580560510074,"mc":[{"id":"1.168136214","rc":[{"batb":[[1,3.7,44.64]],"batl":[[0,3.8,5],[1,3.85,3],[2,3.9,58.42]],"ltp":3.85,"tv":6782.28,"id":11981493}]}]}
{"op":"mcm","clk":"993066403","pt":1580560511073,"mc":[{"id":"1.168136214","rc":[{"trd":[[3.8,1466.11]],"batb":[[0,3.8,8],[1,3.75,44.59],[2,3.7,44.64]],"batl":[[0,3.85,3],[1,3.9,58.42],[2,3.95,31.14]],"ltp":3.8,"tv":6806.28,"id":11981493}],"tv":30678.44}]}
{"op":"mcm","clk":"993066834","pt":1580560513013,"mc":[{"id":"1.168136214","rc":[{"batl":[[0,5.3,5.21]],"ltp":5.3,"tv":5978.93,"id":12925630},{"batl":[[0,1.84,56.36],[1,1.85,154.33],[2,1.86,45.01]],"ltp":1.84,"tv":17893.22,"id":17336468}]}]}
{"op":"mcm","clk":"993067277","pt":1580560514997,"mc":[{"id":"1.168136214","rc":[{"batb":[[0,5.1,15.72]],"ltp":5.3,"tv":5978.93,"id":12925630}]}]}
{"op":"mcm","clk":"993067524","pt":1580560516107,"mc":[{"id":"1.168136214","rc":[{"batb":[[1,5,44.3],[2,4.9,13.26]],"ltp":5.3,"tv":5978.93,"id":12925630}]}]}
{"op":"mcm","clk":"993068534","pt":1580560521117,"mc":[{"id":"1.168136214","rc":[{"batb":[[0,5.2,8.15],[1,5.1,15.72],[2,5,44.3]],"batl":[[0,5.3,3.21]],"ltp":5.3,"tv":5978.93,"id":12925630},{"trd":[[1.83,916.91]],"batb":[[0,1.83,108.31]],"batl":[[0,1.84,33.24],[1,1.85,154.13]],"ltp":1.83,"tv":18133.22,"id":17336468},{"trd":[[3.75,660.93],[3.8,1482.11]],"batb":[[0,3.75,29.39],[1,3.7,44.64],[2,3.65,34.68]],"batl":[[0,3.85,19.19]],"ltp":3.75,"tv":6906.28,"id":11981493}],"tv":31018.44}]}
{"op":"mcm","clk":"993068709","pt":1580560522005,"mc":[{"id":"1.168136214","rc":[{"batl":[[0,1.84,6.13]],"ltp":1.83,"tv":18133.22,"id":17336468},{"batl":[[2,3.95,44.5]],"ltp":3.75,"tv":6906.28,"id":11981493}]}]}
{"op":"mcm","clk":"993069119","pt":1580560524127,"mc":[{"id":"1.168136214","rc":[{"batl":[[0,1.84,31.53],[1,1.85,128.38]],"ltp":1.83,"tv":18133.22,"id":17336468},{"trd":[[3.85,945.74]],"batl":[[0,3.85,17.19]],"ltp":3.85,"tv":6910.28,"id":11981493}],"tv":31022.44}]}
{"op":"mcm","clk":"993069319","pt":1580560525116,"mc":[{"id":"1.168136214","rc":[{"batb":[[0,5.2,18.15]],"ltp":5.3,"tv":5978.93,"id":12925630},{"batb":[[0,3.75,12.59],[1,3.7,62.22]],"batl":[[0,3.85,20.19]],"ltp":3.85,"tv":6910.28,"id":11981493}]}]}
{"op":"mcm","clk":"993069510","pt":1580560526091,"mc":[{"id":"1.168136214","rc":[{"batb":[[1,5.1,18.79]],"ltp":5.3,"tv":5978.93,"id":12925630},{"batl":[[2,3.95,31.14]],"ltp":3.85,"tv":6910.28,"id":11981493}]}]}
{"op":"mcm","clk":"993069709","pt":1580560526919,"mc":[{"id":"1.168136214","rc":[{"batl":[[0,3.8,5],[1,3.85,20.19],[2,3.9,58.42]],"ltp":3.85,"tv":6910.28,"id":11981493}]}]}
{"op":"mcm","clk":"993069913","pt":1580560528014,"mc":[{"id":"1.168136214","rc":[{"batl":[[1,3.85,40.45]],"ltp":3.85,"tv":6910.28,"id":11981493}]}]}
{"op":"mcm","clk":"993070502","pt":1580560531088,"mc":[{"id":"1.168136214","rc":[{"batb":[[1,5.1,28.51],[2,5,34.58]],"ltp":5.3,"tv":5978.93,"id":12925630}]}]}
{"op":"mcm","clk":"993071252","pt":1580560535000,"mc":[{"id":"1.168136214","rc":[{"batb":[[0,3.75,32.85]],"batl":[[1,3.85,43.61]],"ltp":3.85,"tv":6910.28,"id":11981493}]}]}
{"op":"mcm","clk":"993071462","pt":1580560536150,"mc":[{"id":"1.168136214","rc":[{"batb":[[1,5.1,18.79],[2,5,44.3]],"ltp":5.3,"tv":5978.93,"id":12925630}]}]}
{"op":"mcm","clk":"993071645","pt":1580560537140,"mc":[{"id":"1.168136214","rc":[{"trd":[[5.3,90.32]],"batl":[[0,5.3,3.05]],"ltp":5.3,"tv":5979.25,"id":12925630}],"tv":31022.76}]}
{"op":"mcm","clk":"993071858","pt":1580560538112,"mc":[{"id":"1.168136214","rc":[{"batb":[[2,5,40.9]],"ltp":5.3,"tv":5979.25,"id":12925630}]}]}
{"op":"mcm","clk":"993073475","pt":1580560546134,"mc":[{"id":"1.168136214","rc":[{"trd":[[1.83,936.91]],"batb":[[0,1.83,98.31]],"ltp":1.83,"tv":18153.22,"id":17336468},{"trd":[[3.7,422.45],[3.75,726.65]],"batb":[[0,3.75,9],[1,3.7,35.08],[2,3.65,30.68]],"batl":[[0,3.8,20.87]],"ltp":3.7,"tv":7030.27,"id":11981493}],"tv":31162.75}]}
{"op":"mcm","clk":"993073684","pt":1580560547129,"mc":[{"id":"1.168136214","rc":[{"batb":[[0,3.7,28.58],[1,3.65,30.68],[2,3.6,118.3]],"batl":[[2,3.9,80.31]],"ltp":3.7,"tv":7030.27,"id":11981493}]}]}
{"op":"mcm","clk":"993074039","pt":1580560549047,"mc":[{"id":"1.168136214","rc":[{"batl":[[0,1.84,31.73]],"ltp":1.83,"tv":18153.22,"id":17336468}]}]}
{"op":"mcm","clk":"993074257","pt":1580560550142,"mc":[{"id":"1.168136214","rc":[{"batl":[[0,1.84,31.53]],"ltp":1.83,"tv":18153.22,"id":17336468}]}]}
{"op":"mcm","clk":"993074622","pt":1580560552028,"mc":[{"id":"1.168136214","rc":[{"batb":[[0,5.2,28.15]],"ltp":5.3,"tv":5979.25,"id":12925630}]}]}
{"op":"mcm","clk":"993074831","pt":1580560553087,"mc":[{"id":"1.168136214","rc":[{"batb":[[2,5,98.67]],"ltp":5.3,"tv":5979.25,"id":12925630},{"batl":[[0,3.8,24.87],[2,3.9,66.56]],"ltp":3.7,"tv":7030.27,"id":11981493}]}]}
{"op":"mcm","clk":"993075039","pt":1580560554118,"mc":[{"id":"1.168136214","rc":[{"trd":[[5.3,96.41]],"batl":[[0,5.4,17.37],[1,5.5,14.4],[2,5.6,12.4]],"ltp":5.3,"tv":5985.34,"id":12925630},{"trd":[[1.83,1133.53]],"batb":[[0,1.82,9],[1,1.81,34.53],[2,1.8,84.47]],"batl":[[0,1.83,1.69],[1,1.84,50.53],[2,1.85,128.38]],"ltp":1.83,"tv":18349.84,"id":17336468},{"batb":[[0,3.7,39.66]],"ltp":3.7,"tv":7030.27,"id":11981493}],"tv":31365.46}]}
{"op":"mcm","clk":"993075251","pt":1580560555088,"mc":[{"id":"1.168136214","rc":[{"batb":[[1,5.1,28.55],[2,5,92.34]],"ltp":5.3,"tv":5985.34,"id":12925630},{"batb":[[2,3.6,207.17]],"ltp":3.7,"tv":7030.27,"id":11981493}]}]}
{"op":"mcm","clk":"993075459","pt":1580560556111,"mc":[{"id":"1.168136214","rc":[{"batb":[[1,1.81,38.54]],"batl":[[2,1.85,137.7]],"ltp":1.83,"tv":18349.84,"id":17336468},{"batl":[[0,3.8,20.87]],"ltp":3.7,"tv":7030.27,"id":11981493}]}]}
{"op":"mcm","clk":"993075658","pt":1580560557117,"mc":[{"id":"1.168136214","rc":[{"trd":[[5.2,337.78]],"batb":[[0,5.2,20.16]],"ltp":5.2,"tv":6001.34,"id":12925630},{"batb":[[0,3.75,11.05],[1,3.7,39.66],[2,3.65,30.68]],"ltp":3.7,"tv":7030.27,"id":11981493}],"tv":31381.45}]}
{"op":"mcm","clk":"993076033","pt":1580560559117,"mc":[{"id":"1.168136214","rc":[{"batb":[[1,1.81,34.53]],"ltp":1.83,"tv":18349.84,"id":17336468}]}]}
{"op":"mcm","clk":"993076243","pt":1580560560108,"mc":[{"id":"1.168136214","rc":[{"batb":[[1,3.7,51.66]],"batl":[[0,3.8,5]],"ltp":3.7,"tv":7030.27,"id":11981493}]}]}
{"op":"mcm","clk":"993076433","pt":1580560560993,"mc":[{"id":"1.168136214","rc":[{"batb":[[2,5,34.58]],"batl":[[0,5.4,14.37],[1,5.5,12.4]],"ltp":5.2,"tv":6001.34,"id":12925630}]}]}
{"op":"mcm","clk":"993076667","pt":1580560562135,"mc":[{"id":"1.168136214","rc":[{"batb":[[0,3.75,20.05]],"ltp":3.7,"tv":7030.27,"id":11981493}]}]}
{"op":"mcm","clk":"993076877","pt":1580560563121,"mc":[{"id":"1.168136214","rc":[{"batb":[[1,5.1,23.08]],"ltp":5.2,"tv":6001.34,"id":12925630}]}]}
{"op":"mcm","clk":"993077042","pt":1580560564104,"mc":[{"id":"1.168136214","rc":[{"batb":[[2,5,31.58]],"ltp":5.2,"tv":6001.34,"id":12925630}]}]}
{"op":"mcm","clk":"993077488","pt":1580560566139,"mc":[{"id":"1.168136214","rc":[{"batl":[[0,1.83,16.69]],"ltp":1.83,"tv":18349.84,"id":17336468}]}]}
{"op":"mcm","clk":"993077703","pt":1580560567125,"mc":[{"id":"1.168136214","rc":[{"trd":[[1.82,351.12]],"batb":[[0,1.81,34.53],[1,1.8,84.47],[2,1.79,8.03]],"batl":[[0,1.82,6],[1,1.83,18.69],[2,1.84,50.53]],"ltp":1.82,"tv":18377.84,"id":17336468}],"tv":31409.45}]}
{"op":"mcm","clk":"993077897","pt":1580560568123,"mc":[{"id":"1.168136214","rc":[{"batl":[[1,5.5,7.47]],"ltp":5.2,"tv":6001.34,"id":12925630},{"batb":[[1,1.8,70.28]],"ltp":1.82,"tv":18377.84,"id":17336468}]}]}
{"op":"mcm","clk":"993078894","pt":1580560573154,"mc":[{"id":"1.168136214","rc":[{"batb":[[0,5.2,10.16],[1,5.1,13.32],[2,5,41.34]],"ltp":5.2,"tv":6001.34,"id":12925630},{"batl":[[1,1.83,68.69]],"ltp":1.82,"tv":18377.84,"id":17336468}]}]}
{"op":"mcm","clk":"993079083","pt":1580560574136,"mc":[{"id":"1.168136214","rc":[{"batb":[[0,5.2,16.62]],"ltp":5.2,"tv":6001.34,"id":12925630},{"trd":[[1.82,367.11]],"batb":[[0,1.82,13.66],[1,1.81,34.53],[2,1.8,61.68]],"batl":[[0,1.83,66.69],[1,1.84,50.53],[2,1.85,77.73]],"ltp":1.82,"tv":18393.84,"id":17336468},{"trd":[[3.8,1499.81]],"batb":[[0,3.75,38.32],[2,3.65,117.87]],"batl":[[0,3.85,39.61],[1,3.9,66.56],[2,3.95,31.14]],"ltp":3.8,"tv":7047.97,"id":11981493}],"tv":31443.15}]}
{"op":"mcm","clk":"993079269","pt":1580560575124,"mc":[{"id":"1.168136214","rc":[{"batb":[[2,5,95.36]],"ltp":5.2,"tv":6001.34,"id":12925630},{"trd":[[1.82,394.42]],"batb":[[0,1.81,34.53],[1,1.8,61.68],[2,1.79,8.03]],"batl":[[0,1.82,37.56],[1,1.83,66.69],[2,1.84,50.53]],"ltp":1.82,"tv":18421.14,"id":17336468},{"batl":[[0,3.85,36.45]],"ltp":3.8,"tv":7047.97,"id":11981493}],"tv":31470.45}]}
{"op":"mcm","clk":"993079468","pt":1580560576115,"mc":[{"id":"1.168136214","rc":[{"batb":[[2,5,93.23]],"ltp":5.2,"tv":6001.34,"id":12925630},{"batl":[[1,1.83,84.69]],"ltp":1.82,"tv":18421.14,"id":17336468},{"batb":[[1,3.7,66.63]],"ltp":3.8,"tv":7047.97,"id":11981493}]}]}
{"op":"mcm","clk":"993079655","pt":1580560577123,"mc":[{"id":"1.168136214","rc":[{"batl":[[2,1.84,50.33]],"ltp":1.82,"tv":18421.14,"id":17336468}]}]}
{"op":"mcm","clk":"993079832","pt":1580560578081,"mc":[{"id":"1.168136214","rc":[{"batb":[[2,5,89.73]],"ltp":5.2,"tv":6001.34,"id":12925630}]}]}
{"op":"mcm","clk":"993080004","pt":1580560578994,"mc":[{"id":"1.168136214","rc":[{"batb":[[2,5,89.47]],"ltp":5.2,"tv":6001.34,"id":12925630}]}]}
{"op":"mcm","clk":"993080127","pt":1580560579704,"mc":[{"id":"1.168136214","rc":[{"batl":[[2,1.84,24.93]],"ltp":1.82,"tv":18421.14,"id":17336468}]}]}
{"op":"mcm","clk":"993080367","pt":1580560581118,"mc":[{"id":"1.168136214","rc":[{"batl":[[1,1.83,112.36]],"ltp":1.82,"tv":18421.14,"id":17336468},{"batb":[[2,3.65,30.68]],"ltp":3.8,"tv":7047.97,"id":11981493}]}]}
{"op":"mcm","clk":"993080571","pt":1580560582144,"mc":[{"id":"1.168136214","rc":[{"batb":[[2,3.65,117.87]],"batl":[[0,3.85,39.45]],"ltp":3.8,"tv":7047.97,"id":11981493}]}]}
{"op":"mcm","clk":"993080757","pt":1580560583142,"mc":[{"id":"1.168136214","rc":[{"batb":[[0,3.75,43.32]],"ltp":3.8,"tv":7047.97,"id":11981493}]}]}
{"op":"mcm","clk":"993080955","pt":1580560584134,"mc":[{"id":"1.168136214","rc":[{"batl":[[0,1.82,37.76]],"ltp":1.82,"tv":18421.14,"id":17336468}]}]}
{"op":"mcm","clk":"993081108","pt":1580560585045,"mc":[{"id":"1.168136214","rc":[{"batb":[[0,5.3,8.14],[1,5.2,16.62],[2,5.1,13.32]],"batl":[[0,5.4,7]],"ltp":5.2,"tv":6001.34,"id":12925630},{"trd":[[1.81,512.27]],"batb":[[0,1.8,61.68],[1,1.79,8.03],[2,1.78,147.61]],"ltp":1.81,"tv":18441.13,"id":17336468},{"batb":[[0,3.8,10.95],[1,3.75,43.32],[2,3.7,66.63]],"batl":[[0,3.85,36.45]],"ltp":3.8,"tv":7047.97,"id":11981493}],"tv":31490.44}]}
{"op":"mcm","clk":"993081297","pt":1580560586137,"mc":[{"id":"1.168136214","rc":[{"batl":[[2,5.6,7.28]],"ltp":5.2,"tv":6001.34,"id":12925630},{"batl":[[1,1.83,110.67],[2,1.84,33.95]],"ltp":1.81,"tv":18441.13,"id":17336468}]}]}
{"op":"mcm","clk":"993081487","pt":1580560587099,"mc":[{"id":"1.168136214","rc":[{"batb":[[0,5.2,16.62],[1,5.1,13.32],[2,5,89.47]],"batl":[[0,5.4,15.1],[1,5.6,7.28],[2,5.8,6.35]],"ltp":5.2,"tv":6001.34,"id":12925630},{"trd":[[1.82,408.49]],"batl":[[0,1.82,30.73]],"ltp":1.82,"tv":18455.2,"id":17336468}],"tv":31504.51}]}
{"op":"mcm","clk":"993081700","pt":1580560588136,"mc":[{"id":"1.168136214","rc":[{"batb":[[0,5.2,21.51],[2,5,31.7]],"batl":[[1,5.6,12.15]],"ltp":5.2,"tv":6001.34,"id":12925630},{"batb":[[0,1.81,7.15],[1,1.8,95.87],[2,1.79,8.03]],"ltp":1.82,"tv":18455.2,"id":17336468},{"batb":[[0,3.8,19.95],[2,3.7,51.66]],"batl":[[0,3.85,20.26]],"ltp":3.8,"tv":7047.97,"id":11981493}]}]}
{"op":"mcm","clk":"993081891","pt":1580560589005,"mc":[{"id":"1.168136214","rc":[{"batl":[[2,5.8,13.66]],"ltp":5.2,"tv":6001.34,"id":12925630},{"batb":[[2,3.7,60.22]],"batl":[[1,3.9,58.42]],"ltp":3.8,"tv":7047.97,"id":11981493}]}]}
{"op":"mcm","clk":"993082115","pt":1580560590146,"mc":[{"id":"1.168136214","rc":[{"trd":[[1.82,408.51]],"batl":[[0,1.82,36.65],[2,1.84,28.02]],"ltp":1.82,"tv":18455.22,"id":17336468},{"batl":[[1,3.9,83.42]],"ltp":3.8,"tv":7047.97,"id":11981493}],"tv":31504.53}]}
{"op":"mcm","clk":"993082319","pt":1580560591129,"mc":[{"id":"1.168136214","rc":[{"batb":[[0,3.8,31.95],[2,3.7,48.22]],"ltp":3.8,"tv":7047.97,"id":11981493}]}]}
{"op":"mcm","clk":"993082494","pt":1580560592118,"mc":[{"id":"1.168136214","rc":[{"batl":[[2,5.7,8.31]],"ltp":5.2,"tv":6001.34,"id":12925630}]}]}
{"op":"mcm","clk":"993082646","pt":1580560593146,"mc":[{"id":"1.168136214","rc":[{"batl":[[1,3.9,78]],"ltp":3.8,"tv":7047.97,"id":11981493}]}]}
{"op":"mcm","clk":"993082822","pt":1580560594137,"mc":[{"id":"1.168136214","rc":[{"batb":[[2,5,31.58]],"ltp":5.2,"tv":6001.34,"id":12925630},{"batl":[[0,1.82,41.65]],"ltp":1.82,"tv":18455.22,"id":17336468}]}]}
{"op":"mcm","clk":"993083020","pt":1580560595131,"mc":[{"id":"1.168136214","rc":[{"batb":[[2,1.79,13.03]],"ltp":1.82,"tv":18455.22,"id":17336468}]}]}
{"op":"mcm","clk":"993083181","pt":1580560596066,"mc":[{"id":"1.168136214","rc":[{"trd":[[5.2,393.37]],"batb":[[0,5.2,9]],"batl":[[0,5.4,17.1]],"ltp":5.2,"tv":6056.93,"id":12925630},{"trd":[[1.82,444.37]],"batl":[[0,1.82,5.79]],"ltp":1.82,"tv":18491.08,"id":17336468},{"trd":[[3.85,962.68]],"batl":[[0,3.85,3.31]],"ltp":3.85,"tv":7064.91,"id":11981493}],"tv":31612.93}]}
{"op":"mcm","clk":"993083934","pt":1580560600138,"mc":[{"id":"1.168136214","rc":[{"batb":[[0,5.2,14.37]],"ltp":5.2,"tv":6056.93,"id":12925630}]}]}
{"op":"mcm","clk":"993084542","pt":1580560603052,"mc":[{"id":"1.168136214","rc":[{"batb":[[0,1.81,57.8]],"batl":[[2,1.84,53.02]],"ltp":1.82,"tv":18491.08,"id":17336468}]}]}
{"op":"mcm","clk":"993084780","pt":1580560604144,"mc":[{"id":"1.168136214","rc":[{"batb":[[0,5.2,16.37]],"ltp":5.2,"tv":6056.93,"id":12925630},{"batl":[[0,1.82,56.44]],"ltp":1.82,"tv":18491.08,"id":17336468}]}]}
{"op":"mcm","clk":"993085389","pt":1580560607081,"mc":[{"id":"1.168136214","rc":[{"batl":[[2,5.7,5]],"ltp":5.2,"tv":6056.93,"id":12925630}]}]}
{"op":"mcm","clk":"993085759","pt":1580560609082,"mc":[{"id":"1.168136214","rc":[{"batb":[[0,1.81,50.65]],"batl":[[2,1.84,143.02]],"ltp":1.82,"tv":18491.08,"id":17336468}]}]}
{"op":"mcm","clk":"993085953","pt":1580560610096,"mc":[{"id":"1.168136214","rc":[{"batb":[[1,5.1,23.32]],"ltp":5.2,"tv":6056.93,"id":12925630}]}]}
{"op":"mcm","clk":"993087042","pt":1580560616091,"mc":[{"id":"1.168136214","rc":[{"batl":[[0,1.82,146.44]],"ltp":1.82,"tv":18491.08,"id":17336468}]}]}
{"op":"mcm","clk":"993087224","pt":1580560617088,"mc":[{"id":"1.168136214","rc":[{"batl":[[0,1.82,148.44]],"ltp":1.82,"tv":18491.08,"id":17336468}]}]}
{"op":"mcm","clk":"993087740","pt":1580560620109,"mc":[{"id":"1.168136214","rc":[{"batb":[[0,1.81,52.65]],"batl":[[0,1.82,148.64]],"ltp":1.82,"tv":18491.08,"id":17336468}]}]}
{"op":"mcm","clk":"993088179","pt":1580560622089,"mc":[{"id":"1.168136214","rc":[{"batl":[[1,1.83,95.67]],"ltp":1.82,"tv":18491.08,"id":17336468}]}]}
{"op":"mcm","clk":"993088598","pt":1580560624102,"mc":[{"id":"1.168136214","rc":[{"batb":[[0,5.2,24.63]],"batl":[[0,5.4,15.1],[1,5.5,2.02],[2,5.6,12.15]],"ltp":5.2,"tv":6056.93,"id":12925630},{"batl":[[1,1.83,68]],"ltp":1.82,"tv":18491.08,"id":17336468},{"trd":[[3.8,1519.79]],"batb":[[0,3.8,21.96]],"ltp":3.8,"tv":7084.9,"id":11981493}],"tv":31632.92}]}
{"op":"mcm","clk":"993088808","pt":1580560625107,"mc":[{"id":"1.168136214","rc":[{"trd":[[1.81,617.62]],"batb":[[0,1.8,95.87],[1,1.79,13.03],[2,1.78,147.61]],"batl":[[0,1.81,30.25],[1,1.82,148.64],[2,1.83,68]],"ltp":1.81,"tv":18596.43,"id":17336468},{"trd":[[3.85,969.32]],"batl":[[0,3.9,78],[1,3.95,45.96],[2,4,97.78]],"ltp":3.85,"tv":7091.53,"id":11981493}],"tv":31744.9}]}
{"op":"mcm","clk":"993089014","pt":1580560626096,"mc":[{"id":"1.168136214","rc":[{"batb":[[2,5,89.34]],"batl":[[2,5.6,19.16]],"ltp":5.2,"tv":6056.93,"id":12925630},{"batb":[[0,1.8,61.68],[2,1.78,154.61]],"batl":[[1,1.82,165.64]],"ltp":1.81,"tv":18596.43,"id":17336468},{"batb":[[0,3.8,45.26],[1,3.75,63.85],[2,3.7,133.79]],"batl":[[1,3.95,33.92]],"ltp":3.85,"tv":7091.53,"id":11981493}]}]}
{"op":"mcm","clk":"993089246","pt":1580560627126,"mc":[{"id":"1.168136214","rc":[{"batb":[[0,1.8,53.68]],"ltp":1.81,"tv":18596.43,"id":17336468}]}]}
{"op":"mcm","clk":"993090232","pt":1580560632112,"mc":[{"id":"1.168136214","rc":[{"batl":[[0,1.81,31.04],[1,1.82,164.85]],"ltp":1.81,"tv":18596.43,"id":17336468}]}]}
{"op":"mcm","clk":"993090805","pt":1580560635117,"mc":[{"id":"1.168136214","rc":[{"trd":[[1.81,627.62]],"batl":[[0,1.81,26.04]],"ltp":1.81,"tv":18606.43,"id":17336468}],"tv":31754.9}]}
{"op":"mcm","clk":"993094364","pt":1580560653112,"mc":[{"id":"1.168136214","rc":[{"trd":[[1.8,208.25]],"batb":[[0,1.8,38.68]],"ltp":1.8,"tv":18636.43,"id":17336468}],"tv":31784.9}]}
{"op":"mcm","clk":"993094592","pt":1580560654101,"mc":[{"id":"1.168136214","rc":[{"batb":[[0,5.3,8.21],[1,5.2,24.63],[2,5.1,23.32]],"batl":[[2,5.6,21.16]],"ltp":5.2,"tv":6056.93,"id":12925630},{"batb":[[0,3.85,10.89],[1,3.8,45.26],[2,3.75,48.82]],"batl":[[0,3.9,75],[1,3.95,31.14]],"ltp":3.85,"tv":7091.53,"id":11981493}]}]}
{"op":"mcm","clk":"993094783","pt":1580560655118,"mc":[{"id":"1.168136214","rc":[{"batb":[[0,5.3,17.21],[1,5.2,29.83]],"ltp":5.2,"tv":6056.93,"id":12925630},{"batl":[[0,1.81,26.24],[1,1.82,164.65]],"ltp":1.8,"tv":18636.43,"id":17336468}]}]}
{"op":"mcm","clk":"993096174","pt":1580560662130,"mc":[{"id":"1.168136214","rc":[{"trd":[[1.8,208.42]],"batb":[[0,1.8,38.6]],"ltp":1.8,"tv":18636.6,"id":17336468}],"tv":31785.07}]}
{"op":"mcm","clk":"993096365","pt":1580560662994,"mc":[{"id":"1.168136214","rc":[{"batl":[[0,1.81,76.89]],"ltp":1.8,"tv":18636.6,"id":17336468}]}]}
{"op":"mcm","clk":"993096776","pt":1580560664962,"mc":[{"id":"1.168136214","rc":[{"batl":[[1,1.82,114]],"ltp":1.8,"tv":18636.6,"id":17336468}]}]}
{"op":"mcm","clk":"993097245","pt":1580560667131,"mc":[{"id":"1.168136214","rc":[{"batb":[[1,5.2,39.84],[2,5.1,13.32]],"batl":[[0,5.4,7]],"ltp":5.2,"tv":6056.93,"id":12925630},{"trd":[[3.85,991.11]],"batb":[[0,3.8,45.26],[1,3.75,48.82],[2,3.7,48.22]],"batl":[[0,3.85,15.1],[1,3.9,78],[2,3.95,31.14]],"ltp":3.85,"tv":7113.32,"id":11981493}],"tv":31806.86}]}
{"op":"mcm","clk":"993097467","pt":1580560668114,"mc":[{"id":"1.168136214","rc":[{"batb":[[0,3.8,9.96]],"ltp":3.85,"tv":7113.32,"id":11981493}]}]}
{"op":"mcm","clk":"993097655","pt":1580560669045,"mc":[{"id":"1.168136214","rc":[{"batb":[[2,5.1,69.67]],"ltp":5.2,"tv":6056.93,"id":12925630},{"trd":[[3.85,1015.11]],"batl":[[0,3.85,3.1]],"ltp":3.85,"tv":7137.32,"id":11981493}],"tv":31830.86}]}
{"op":"mcm","clk":"993097881","pt":1580560670136,"mc":[{"id":"1.168136214","rc":[{"batb":[[1,5.2,29.83]],"ltp":5.2,"tv":6056.93,"id":12925630}]}]}
{"op":"mcm","clk":"993098077","pt":1580560671120,"mc":[{"id":"1.168136214","rc":[{"batb":[[2,5.1,72.8]],"ltp":5.2,"tv":6056.93,"id":12925630}]}]}
{"op":"mcm","clk":"993098303","pt":1580560672146,"mc":[{"id":"1.168136214","rc":[{"batb":[[2,5.1,69.78]],"ltp":5.2,"tv":6056.93,"id":12925630}]}]}
{"op":"mcm","clk":"993098482","pt":1580560673034,"mc":[{"id":"1.168136214","rc":[{"batb":[[1,5.2,24.46]],"ltp":5.2,"tv":6056.93,"id":12925630}]}]}
{"op":"mcm","clk":"993099534","pt":1580560678025,"mc":[{"id":"1.168136214","rc":[{"trd":[[1.8,228.42]],"batb":[[0,1.8,28.6]],"ltp":1.8,"tv":18656.6,"id":17336468}],"tv":31850.86}]}
{"op":"mcm","clk":"993100402","pt":1580560682142,"mc":[{"id":"1.168136214","rc":[{"trd":[[5.3,124.75]],"batb":[[0,5.3,3.04]],"batl":[[1,5.5,11.26],[2,5.6,24.38]],"ltp":5.3,"tv":6085.26,"id":12925630}],"tv":31879.19}]}
{"op":"mcm","clk":"993100606","pt":1580560683066,"mc":[{"id":"1.168136214","rc":[{"batb":[[2,5.1,13.43]],"ltp":5.3,"tv":6085.26,"id":12925630},{"trd":[[1.81,651.62]],"batl":[[0,1.81,64.89]],"ltp":1.81,"tv":18680.6,"id":17336468},{"batb":[[1,3.75,64.24]],"ltp":3.85,"tv":7137.32,"id":11981493}],"tv":31903.19}]}
{"op":"mcm","clk":"993100826","pt":1580560684048,"mc":[{"id":"1.168136214","rc":[{"batl":[[0,1.81,64.69]],"ltp":1.81,"tv":18680.6,"id":17336468}]}]}
{"op":"mcm","clk":"993101083","pt":1580560685140,"mc":[{"id":"1.168136214","rc":[{"batb":[[0,5.3,11.24]],"ltp":5.3,"tv":6085.26,"id":12925630},{"trd":[[1.8,252.96]],"batb":[[0,1.8,16.33]],"batl":[[1,1.82,115.68]],"ltp":1.8,"tv":18705.14,"id":17336468}],"tv":31927.73}]}
{"op":"mcm","clk":"993101270","pt":1580560686054,"mc":[{"id":"1.168136214","rc":[{"batb":[[1,1.79,14.71]],"ltp":1.8,"tv":18705.14,"id":17336468},{"batb":[[1,3.75,48.82]],"ltp":3.85,"tv":7137.32,"id":11981493}]}]}
{"op":"mcm","clk":"993101479","pt":1580560687039,"mc":[{"id":"1.168136214","rc":[{"batb":[[0,3.8,16.96]],"ltp":3.85,"tv":7137.32,"id":11981493}]}]}
{"op":"mcm","clk":"993101687","pt":1580560688084,"mc":[{"id":"1.168136214","rc":[{"batl":[[1,5.5,6.49]],"ltp":5.3,"tv":6085.26,"id":12925630}]}]}
{"op":"mcm","clk":"993101893","pt":1580560689057,"mc":[{"id":"1.168136214","rc":[{"trd":[[1.8,254.96]],"batb":[[0,1.8,15.33]],"ltp":1.8,"tv":18707.14,"id":17336468}],"tv":31929.73}]}
{"op":"mcm","clk":"993102311","pt":1580560691076,"mc":[{"id":"1.168136214","rc":[{"batb":[[1,5.2,34.59],[2,5.1,13.32]],"ltp":5.3,"tv":6085.26,"id":12925630},{"batb":[[0,1.8,44.11]],"batl":[[0,1.81,64.89]],"ltp":1.8,"tv":18707.14,"id":17336468},{"batl":[[0,3.85,23.36]],"ltp":3.85,"tv":7137.32,"id":11981493}]}]}
{"op":"mcm","clk":"993102503","pt":1580560692068,"mc":[{"id":"1.168136214","rc":[{"batb":[[0,5.3,16.2],[1,5.2,42.16]],"ltp":5.3,"tv":6085.26,"id":12925630},{"trd":[[1.8,354.93]],"batb":[[0,1.8,1.14]],"batl":[[2,1.83,18]],"ltp":1.8,"tv":18807.12,"id":17336468}],"tv":32029.71}]}
{"op":"mcm","clk":"993102720","pt":1580560693063,"mc":[{"id":"1.168136214","rc":[{"trd":[[5.4,0.29]],"batl":[[0,5.4,6.71]],"ltp":5.4,"tv":6085.55,"id":12925630},{"trd":[[1.8,358.07]],"batb":[[0,1.8,204]],"ltp":1.8,"tv":18810.26,"id":17336468},{"trd":[[3.85,1015.51]],"batl":[[0,3.85,22.96]],"ltp":3.85,"tv":7137.72,"id":11981493}],"tv":32033.54}]}
{"op":"mcm","clk":"993103272","pt":1580560695798,"mc":[{"id":"1.168136214","rc":[{"batb":[[0,1.8,211]],"ltp":1.8,"tv":18810.26,"id":17336468},{"batb":[[0,3.8,37.22]],"ltp":3.85,"tv":7137.72,"id":11981493}]}]}
{"op":"mcm","clk":"993104090","pt":1580560700069,"mc":[{"id":"1.168136214","rc":[{"trd":[[3.85,1019.45]],"batl":[[0,3.85,20.99]],"ltp":3.85,"tv":7141.66,"id":11981493}],"tv":32037.48}]}
{"op":"mcm","clk":"993104928","pt":1580560704075,"mc":[{"id":"1.168136214","rc":[{"trd":[[5.3,130.75]],"batb":[[0,5.3,13.2]],"ltp":5.3,"tv":6091.55,"id":12925630}],"tv":32043.48}]}
{"op":"mcm","clk":"993105131","pt":1580560705112,"mc":[{"id":"1.168136214","rc":[{"trd":[[5.3,140.74]],"batb":[[0,5.3,8.21]],"batl":[[0,5.4,10.77],[1,5.5,2.02]],"ltp":5.3,"tv":6101.54,"id":12925630},{"batb":[[1,1.79,64.71]],"ltp":1.8,"tv":18810.26,"id":17336468}],"tv":32053.47}]}
{"op":"mcm","clk":"993106078","pt":1580560710123,"mc":[{"id":"1.168136214","rc":[{"trd":[[5.4,10.63]],"batl":[[0,5.4,5.6]],"ltp":5.4,"tv":6111.89,"id":12925630}],"tv":32063.82}]}
{"op":"mcm","clk":"993106237","pt":1580560710995,"mc":[{"id":"1.168136214","rc":[{"batl":[[0,5.4,9.67]],"ltp":5.4,"tv":6111.89,"id":12925630}]}]}
{"op":"mcm","clk":"993107779","pt":1580560719104,"mc":[{"id":"1.168136214","rc":[{"batl":[[0,1.81,64.69]],"ltp":1.8,"tv":18810.26,"id":17336468}]}]}
{"op":"mcm","clk":"993109229","pt":1580560726135,"mc":[{"id":"1.168136214","rc":[{"trd":[[1.8,388.07]],"batb":[[0,1.8,196]],"batl":[[0,1.81,64.89]],"ltp":1.8,"tv":18840.26,"id":17336468}],"tv":32093.82}]}
{"op":"mcm","clk":"993109640","pt":1580560728116,"mc":[{"id":"1.168136214","rc":[{"trd":[[5.3,186.42]],"batb":[[0,5.2,32.03],[1,5.1,23.45],[2,5,92.34]],"batl":[[0,5.3,71.53],[1,5.4,9.67],[2,5.5,2.02]],"ltp":5.3,"tv":6157.56,"id":12925630},{"trd":[[1.81,736.72]],"batl":[[0,1.82,115.7],[1,1.83,18],[2,1.84,143.02]],"ltp":1.81,"tv":18925.36,"id":17336468},{"trd":[[3.85,1040.44]],"batb":[[1,3.75,64.54]],"batl":[[0,3.9,78],[1,3.95,31.14],[2,4,97.78]],"ltp":3.85,"tv":7162.65,"id":11981493}],"tv":32245.58}]}
{"op":"mcm","clk":"993109784","pt":1580560728926,"mc":[{"id":"1.168136214","rc":[{"batb":[[0,5.2,16.26],[1,5.1,19.21],[2,5,34.58]],"batl":[[1,5.4,12.67],[2,5.5,10.2]],"ltp":5.3,"tv":6157.56,"id":12925630},{"trd":[[1.81,736.76]],"batb":[[0,1.81,8.24],[1,1.8,196],[2,1.79,64.71]],"batl":[[0,1.82,98.68]],"ltp":1.81,"tv":18925.4,"id":17336468},{"batb":[[2,3.7,133.79]],"ltp":3.85,"tv":7162.65,"id":11981493}],"tv":32245.62}]}
{"op":"mcm","clk":"993109953","pt":1580560730058,"mc":[{"id":"1.168136214","rc":[{"batl":[[0,5.3,74.53]],"ltp":5.3,"tv":6157.56,"id":12925630}]}]}
{"op":"mcm","clk":"993110772","pt":1580560734131,"mc":[{"id":"1.168136214","rc":[{"batl":[[0,1.82,104.68]],"ltp":1.81,"tv":18925.4,"id":17336468}]}]}
{"op":"mcm","clk":"993110913","pt":1580560734845,"mc":[{"id":"1.168136214","rc":[{"trd":[[5.2,425.88]],"batb":[[0,5.1,9.08],[1,5,40.71],[2,4.9,65.24]],"batl":[[1,5.4,17.68]],"ltp":5.2,"tv":6190.08,"id":12925630},{"batb":[[0,3.85,11.04],[1,3.8,37.22],[2,3.75,64.54]],"batl":[[0,3.9,75]],"ltp":3.85,"tv":7162.65,"id":11981493}],"tv":32278.14}]}
{"op":"mcm","clk":"993111174","pt":1580560736141,"mc":[{"id":"1.168136214","rc":[{"batb":[[1,5,31.71],[2,4.9,6]],"batl":[[0,5.2,2.53],[1,5.3,74.53],[2,5.4,21.42]],"ltp":5.2,"tv":6190.08,"id":12925630},{"batb":[[0,1.81,15.2]],"ltp":1.81,"tv":18925.4,"id":17336468},{"batb":[[0,3.85,29.22]],"ltp":3.85,"tv":7162.65,"id":11981493}]}]}
{"op":"mcm","clk":"993111308","pt":1580560736848,"mc":[{"id":"1.168136214","rc":[{"trd":[[5.2,430.94]],"batb":[[0,5.2,3.77],[1,5.1,11.45],[2,5,31.71]],"batl":[[0,5.3,74.53],[1,5.4,21.42],[2,5.5,10.2]],"ltp":5.2,"tv":6195.14,"id":12925630},{"batb":[[0,1.81,33.3]],"ltp":1.81,"tv":18925.4,"id":17336468},{"batb":[[0,3.85,34.7],[2,3.75,48.82]],"ltp":3.85,"tv":7162.65,"id":11981493}],"tv":32283.2}]}
{"op":"mcm","clk":"993111494","pt":1580560737839,"mc":[{"id":"1.168136214","rc":[{"trd":[[5.2,438.48]],"batb":[[0,5.1,11.45],[1,5,31.71],[2,4.9,6]],"batl":[[0,5.2,4.23],[1,5.3,74.53],[2,5.4,17.68]],"ltp":5.2,"tv":6202.68,"id":12925630}],"tv":32290.74}]}
{"op":"mcm","clk":"993111970","pt":1580560740039,"mc":[{"id":"1.168136214","rc":[{"batb":[[1,5,28.71]],"ltp":5.2,"tv":6202.68,"id":12925630}]}]}
{"op":"mcm","clk":"993112356","pt":1580560742012,"mc":[{"id":"1.168136214","rc":[{"batb":[[0,5.1,8.38],[1,5,31.84]],"ltp":5.2,"tv":6202.68,"id":12925630},{"trd":[[1.81,736.88]],"batb":[[0,1.81,33.24]],"ltp":1.81,"tv":18925.52,"id":17336468},{"trd":[[3.85,1040.56]],"batb":[[0,3.85,34.64]],"ltp":3.85,"tv":7162.77,"id":11981493}],"tv":32290.98}]}
{"op":"mcm","clk":"993112569","pt":1580560743096,"mc":[{"id":"1.168136214","rc":[{"trd":[[5.2,444.54]],"batl":[[0,5.3,74.53],[1,5.4,17.68],[2,5.5,10.2]],"ltp":5.2,"tv":6208.74,"id":12925630},{"trd":[[1.81,737.34]],"batb":[[0,1.81,33.01]],"ltp":1.81,"tv":18925.97,"id":17336468},{"trd":[[3.85,1041.01]],"batb":[[0,3.85,34.41]],"ltp":3.85,"tv":7163.23,"id":11981493}],"tv":32297.95}]}
{"op":"mcm","clk":"993112733","pt":1580560744123,"mc":[{"id":"1.168136214","rc":[{"batl":[[0,5.2,3.03],[1,5.3,74.53],[2,5.4,17.68]],"ltp":5.2,"tv":6208.74,"id":12925630}]}]}
{"op":"mcm","clk":"993113295","pt":1580560747053,"mc":[{"id":"1.168136214","rc":[{"trd":[[1.81,797.05]],"batb":[[0,1.81,46.22],[1,1.8,296]],"batl":[[1,1.83,20.17]],"ltp":1.81,"tv":18985.69,"id":17336468},{"batb":[[0,3.85,36.41],[1,3.8,41.22],[2,3.75,52.82]],"ltp":3.85,"tv":7163.23,"id":11981493}],"tv":32357.67}]}
{"op":"mcm","clk":"993113512","pt":1580560748037,"mc":[{"id":"1.168136214","rc":[{"batb":[[0,5.1,20.76]],"batl":[[0,5.2,23.29]],"ltp":5.2,"tv":6208.74,"id":12925630},{"batb":[[0,1.81,96.22],[2,1.79,14.71]],"ltp":1.81,"tv":18985.69,"id":17336468},{"trd":[[3.85,1101]],"batb":[[0,3.85,6.42]],"ltp":3.85,"tv":7223.22,"id":11981493}],"tv":32417.66}]}
{"op":"mcm","clk":"993113686","pt":1580560749017,"mc":[{"id":"1.168136214","rc":[{"batb":[[2,4.9,65.24]],"ltp":5.2,"tv":6208.74,"id":12925630},{"trd":[[1.81,821.51]],"batb":[[0,1.81,84.39]],"ltp":1.81,"tv":19010.14,"id":17336468},{"trd":[[3.85,1125.46]],"batb":[[0,3.85,5.23]],"ltp":3.85,"tv":7247.68,"id":11981493}],"tv":32466.58}]}
{"op":"mcm","clk":"993113907","pt":1580560750154,"mc":[{"id":"1.168136214","rc":[{"batb":[[0,5.1,31.3],[2,4.9,6]],"batl":[[2,5.4,24.87]],"ltp":5.2,"tv":6208.74,"id":12925630},{"trd":[[1.82,523.25]],"batl":[[0,1.82,65.24]],"ltp":1.82,"tv":19089.02,"id":17336468},{"batb":[[0,3.85,19.19]],"ltp":3.85,"tv":7247.68,"id":11981493}],"tv":32545.46}]}
{"op":"mcm","clk":"993114072","pt":1580560751032,"mc":[{"id":"1.168136214","rc":[{"trd":[[1.81,932.63]],"batb":[[0,1.81,72.16]],"batl":[[0,1.82,9.68]],"ltp":1.81,"tv":19200.14,"id":17336468},{"batb":[[0,3.85,35.1]],"ltp":3.85,"tv":7247.68,"id":11981493}],"tv":32656.58}]}
{"op":"mcm","clk":"993114271","pt":1580560752043,"mc":[{"id":"1.168136214","rc":[{"trd":[[1.82,539.25]],"batl":[[0,1.82,1.68],[2,1.84,134]],"ltp":1.82,"tv":19216.14,"id":17336468}],"tv":32672.58}]}
{"op":"mcm","clk":"993114449","pt":1580560753045,"mc":[{"id":"1.168136214","rc":[{"batl":[[2,1.84,160.62]],"ltp":1.82,"tv":19216.14,"id":17336468},{"batb":[[0,3.85,23.96]],"ltp":3.85,"tv":7247.68,"id":11981493}]}]}
{"op":"mcm","clk":"993114668","pt":1580560754151,"mc":[{"id":"1.168136214","rc":[{"trd":[[1.82,542.61]],"batl":[[0,1.82,1.28]],"ltp":1.82,"tv":19219.5,"id":17336468},{"batb":[[0,3.85,30.96],[1,3.8,34.22]],"ltp":3.85,"tv":7247.68,"id":11981493}],"tv":32675.94}]}
{"op":"mcm","clk":"993114903","pt":1580560755150,"mc":[{"id":"1.168136214","rc":[{"batl":[[0,1.82,1.63],[2,1.84,162.3]],"ltp":1.82,"tv":19219.5,"id":17336468}]}]}
{"op":"mcm","clk":"993115102","pt":1580560756132,"mc":[{"id":"1.168136214","rc":[{"batb":[[1,1.8,297.68]],"ltp":1.82,"tv":19219.5,"id":17336468}]}]}
{"op":"mcm","clk":"993115932","pt":1580560760070,"mc":[{"id":"1.168136214","rc":[{"batl":[[1,1.83,70.82]],"ltp":1.82,"tv":19219.5,"id":17336468}]}]}
{"op":"mcm","clk":"993116285","pt":1580560761936,"mc":[{"id":"1.168136214","rc":[{"batl":[[1,1.83,71.02]],"ltp":1.82,"tv":19219.5,"id":17336468}]}]}
{"op":"mcm","clk":"993116505","pt":1580560763154,"mc":[{"id":"1.168136214","rc":[{"batl":[[1,1.83,78.02]],"ltp":1.82,"tv":19219.5,"id":17336468}]}]}
{"op":"mcm","clk":"993116867","pt":1580560765065,"mc":[{"id":"1.168136214","rc":[{"trd":[[5.1,222.77]],"batb":[[0,5,31.84],[1,4.9,6],[2,4.8,88.19]],"batl":[[0,5.2,23.3]],"ltp":5.1,"tv":6271.78,"id":12925630},{"trd":[[1.82,544.64]],"batl":[[0,1.83,78.02],[1,1.84,162.3],[2,1.85,69]],"ltp":1.82,"tv":19221.53,"id":17336468},{"trd":[[3.9,534.98]],"batl":[[0,3.9,74.43]],"ltp":3.9,"tv":7248.25,"id":11981493}],"tv":32741.58}]}
{"op":"mcm","clk":"993117060","pt":1580560766060,"mc":[{"id":"1.168136214","rc":[{"trd":[[5.1,222.79]],"batb":[[0,5.1,19.04],[1,5,34.23],[2,4.9,16.13]],"batl":[[0,5.2,26.29]],"ltp":5.1,"tv":6271.8,"id":12925630},{"trd":[[1.82,560.64]],"batb":[[0,1.82,81.39],[1,1.81,72.16],[2,1.8,297.68]],"batl":[[0,1.83,57.85],[1,1.84,135.68]],"ltp":1.82,"tv":19237.53,"id":17336468}],"tv":32757.59}]}
{"op":"mcm","clk":"993117493","pt":1580560768095,"mc":[{"id":"1.168136214","rc":[{"batb":[[0,5.1,27.76]],"ltp":5.1,"tv":6271.8,"id":12925630},{"trd":[[1.82,700.57]],"batb":[[0,1.82,11.46]],"ltp":1.82,"tv":19377.46,"id":17336468},{"batb":[[0,3.85,42.1]],"ltp":3.9,"tv":7248.25,"id":11981493}],"tv":32897.52}]}
{"op":"mcm","clk":"993117689","pt":1580560769084,"mc":[{"id":"1.168136214","rc":[{"batb":[[2,4.9,6]],"ltp":5.1,"tv":6271.8,"id":12925630}]}]}
{"op":"mcm","clk":"993118037","pt":1580560771067,"mc":[{"id":"1.168136214","rc":[{"batb":[[0,1.82,74.46]],"batl":[[0,1.83,60.85]],"ltp":1.82,"tv":19377.46,"id":17336468},{"batb":[[0,3.85,32.1]],"ltp":3.9,"tv":7248.25,"id":11981493}]}]}
{"op":"mcm","clk":"993119246","pt":1580560778073,"mc":[{"id":"1.168136214","rc":[{"trd":[[5.1,278.17]],"batb":[[0,5,34.3],[1,4.9,6],[2,4.8,88.19]],"ltp":5.1,"tv":6327.18,"id":12925630}],"tv":32952.9}]}
{"op":"mcm","clk":"993119431","pt":1580560779135,"mc":[{"id":"1.168136214","rc":[{"batb":[[0,5,34.23]],"ltp":5.1,"tv":6327.18,"id":12925630}]}]}
{"op":"mcm","clk":"993119615","pt":1580560780113,"mc":[{"id":"1.168136214","rc":[{"batb":[[2,4.8,27.38]],"ltp":5.1,"tv":6327.18,"id":12925630},{"batb":[[0,3.85,53.15]],"ltp":3.9,"tv":7248.25,"id":11981493}]}]}
{"op":"mcm","clk":"993119774","pt":1580560781095,"mc":[{"id":"1.168136214","rc":[{"batb":[[0,3.85,64.15],[1,3.8,13.96]],"ltp":3.9,"tv":7248.25,"id":11981493}]}]}
{"op":"mcm","clk":"993119948","pt":1580560782098,"mc":[{"id":"1.168136214","rc":[{"trd":[[5.2,452.54]],"batl":[[0,5.2,22.29]],"ltp":5.2,"tv":6335.18,"id":12925630},{"batl":[[0,3.9,76.43]],"ltp":3.9,"tv":7248.25,"id":11981493}],"tv":32960.9}]}
{"op":"mcm","clk":"993120645","pt":1580560786024,"mc":[{"id":"1.168136214","rc":[{"trd":[[3.85,1155.47]],"batb":[[0,3.85,38.01]],"ltp":3.85,"tv":7278.26,"id":11981493}],"tv":32990.91}]}
{"op":"mcm","clk":"993120858","pt":1580560787113,"mc":[{"id":"1.168136214","rc":[{"batb":[[2,4.8,88.19]],"ltp":5.2,"tv":6335.18,"id":12925630}]}]}
{"op":"mcm","clk":"993121204","pt":1580560789085,"mc":[{"id":"1.168136214","rc":[{"batb":[[0,5.1,20.26],[1,5,34.23],[2,4.9,6]],"ltp":5.2,"tv":6335.18,"id":12925630}]}]}
{"op":"mcm","clk":"993121338","pt":1580560789923,"mc":[{"id":"1.168136214","rc":[{"batb":[[0,5.1,25.26]],"ltp":5.2,"tv":6335.18,"id":12925630},{"batb":[[0,3.85,27.01]],"ltp":3.85,"tv":7278.26,"id":11981493}]}]}
{"op":"mcm","clk":"993121916","pt":1580560793012,"mc":[{"id":"1.168136214","rc":[{"batl":[[0,1.83,60.65]],"ltp":1.82,"tv":19377.46,"id":17336468}]}]}
{"op":"mcm","clk":"993122291","pt":1580560795103,"mc":[{"id":"1.168136214","rc":[{"batb":[[0,5.1,37.77]],"ltp":5.2,"tv":6335.18,"id":12925630},{"trd":[[1.82,759.95]],"batb":[[0,1.82,54.77],[2,1.8,307.68]],"ltp":1.82,"tv":19436.84,"id":17336468},{"trd":[[3.9,538.98]],"batl":[[0,3.9,74.43]],"ltp":3.9,"tv":7282.26,"id":11981493}],"tv":33054.28}]}
{"op":"mcm","clk":"993122674","pt":1580560797136,"mc":[{"id":"1.168136214","rc":[{"batl":[[0,1.83,60.85]],"ltp":1.82,"tv":19436.84,"id":17336468}]}]}
{"op":"mcm","clk":"993122861","pt":1580560798148,"mc":[{"id":"1.168136214","rc":[{"batb":[[0,3.85,29.01]],"ltp":3.9,"tv":7282.26,"id":11981493}]}]}
{"op":"mcm","clk":"993123427","pt":1580560801036,"mc":[{"id":"1.168136214","rc":[{"batl":[[2,1.85,69.67]],"ltp":1.82,"tv":19436.84,"id":17336468},{"batl":[[2,4,98.45]],"ltp":3.9,"tv":7282.26,"id":11981493}]}]}
{"op":"mcm","clk":"993123856","pt":1580560803143,"mc":[{"id":"1.168136214","rc":[{"trd":[[5.1,334.89]],"batb":[[0,5.1,9.42]],"ltp":5.1,"tv":6391.9,"id":12925630}],"tv":33111.01}]}
{"op":"mcm","clk":"993124054","pt":1580560804125,"mc":[{"id":"1.168136214","rc":[{"batb":[[0,5.1,14.42]],"ltp":5.1,"tv":6391.9,"id":12925630},{"batb":[[0,3.85,40.25]],"ltp":3.9,"tv":7282.26,"id":11981493}]}]}
{"op":"mcm","clk":"993124219","pt":1580560805156,"mc":[{"id":"1.168136214","rc":[{"trd":[[3.85,1165.47]],"batb":[[0,3.85,24.01]],"ltp":3.85,"tv":7292.26,"id":11981493}],"tv":33121.01}]}
{"op":"mcm","clk":"993124402","pt":1580560806138,"mc":[{"id":"1.168136214","rc":[{"trd":[[1.82,769.95]],"batb":[[0,1.82,49.77]],"ltp":1.82,"tv":19446.84,"id":17336468}],"tv":33131.01}]}
{"op":"mcm","clk":"993124604","pt":1580560807137,"mc":[{"id":"1.168136214","rc":[{"batb":[[0,3.85,35.28]],"ltp":3.85,"tv":7292.26,"id":11981493}]}]}
{"op":"mcm","clk":"993124793","pt":1580560807949,"mc":[{"id":"1.168136214","rc":[{"batl":[[2,1.85,82.04]],"ltp":1.82,"tv":19446.84,"id":17336468},{"batl":[[2,4,110.82]],"ltp":3.85,"tv":7292.26,"id":11981493}]}]}
{"op":"mcm","clk":"993124987","pt":1580560809055,"mc":[{"id":"1.168136214","rc":[{"trd":[[1.83,1153.52]],"batl":[[0,1.83,50.86]],"ltp":1.83,"tv":19466.83,"id":17336468}],"tv":33150.99}]}
{"op":"mcm","clk":"993125534","pt":1580560811968,"mc":[{"id":"1.168136214","rc":[{"batb":[[2,1.8,317.68]],"ltp":1.83,"tv":19466.83,"id":17336468}]}]}
{"op":"mcm","clk":"993125763","pt":1580560813109,"mc":[{"id":"1.168136214","rc":[{"trd":[[1.83,1163.64]],"batl":[[0,1.83,45.81]],"ltp":1.83,"tv":19476.94,"id":17336468}],"tv":33161.11}]}
{"op":"mcm","clk":"993126339","pt":1580560816151,"mc":[{"id":"1.168136214","rc":[{"trd":[[1.82,785.09]],"batb":[[0,1.82,42.2]],"ltp":1.82,"tv":19492.09,"id":17336468}],"tv":33176.25}]}
{"op":"mcm","clk":"993126746","pt":1580560818109,"mc":[{"id":"1.168136214","rc":[{"batb":[[1,5,44.42]],"batl":[[0,5.2,31.09]],"ltp":5.1,"tv":6391.9,"id":12925630},{"trd":[[1.83,1203.62]],"batb":[[0,1.82,76.52]],"batl":[[0,1.83,25.83]],"ltp":1.83,"tv":19532.07,"id":17336468},{"trd":[[3.85,1209.45]],"batb":[[0,3.85,2.03]],"batl":[[0,3.9,78.43]],"ltp":3.85,"tv":7336.24,"id":11981493}],"tv":33260.21}]}
{"op":"mcm","clk":"993126937","pt":1580560819047,"mc":[{"id":"1.168136214","rc":[{"batb":[[2,1.8,326.66]],"ltp":1.83,"tv":19532.07,"id":17336468},{"trd":[[3.85,1213.51]],"batb":[[0,3.8,33.88],[1,3.75,52.82],[2,3.7,48.22]],"batl":[[0,3.85,9.97],[1,3.9,78.43],[2,3.95,31.14]],"ltp":3.85,"tv":7340.3,"id":11981493}],"tv":33264.27}]}
{"op":"mcm","clk":"993127096","pt":1580560819821,"mc":[{"id":"1.168136214","rc":[{"batb":[[0,5.1,16.95]],"ltp":5.1,"tv":6391.9,"id":12925630},{"batb":[[0,1.82,80.15]],"ltp":1.83,"tv":19532.07,"id":17336468},{"trd":[[3.85,1227.51]],"batb":[[0,3.8,37.27]],"batl":[[0,3.85,2.97]],"ltp":3.85,"tv":7354.3,"id":11981493}],"tv":33278.27}]}
{"op":"mcm","clk":"993127310","pt":1580560821024,"mc":[{"id":"1.168136214","rc":[{"trd":[[1.83,1223.61]],"batl":[[0,1.83,15.84]],"ltp":1.83,"tv":19552.06,"id":17336468},{"batl":[[0,3.85,13.48]],"ltp":3.85,"tv":7354.3,"id":11981493}],"tv":33298.26}]}
{"op":"mcm","clk":"993127423","pt":1580560821736,"mc":[{"id":"1.168136214","rc":[{"batl":[[0,5.2,22.29]],"ltp":5.1,"tv":6391.9,"id":12925630},{"trd":[[1.83,1243.61]],"batl":[[0,1.83,5.84]],"ltp":1.83,"tv":19572.05,"id":17336468}],"tv":33318.26}]}
{"op":"mcm","clk":"993127997","pt":1580560825137,"mc":[{"id":"1.168136214","rc":[{"batl":[[0,1.83,5.64],[1,1.84,137.36]],"ltp":1.83,"tv":19572.05,"id":17336468}]}]}
{"op":"mcm","clk":"993128189","pt":1580560826124,"mc":[{"id":"1.168136214","rc":[{"trd":[[1.83,1254.89]],"batb":[[0,1.83,4.36],[1,1.82,82.43],[2,1.81,73.84]],"batl":[[0,1.84,137.36],[1,1.85,82.04],[2,1.86,63.37]],"ltp":1.83,"tv":19583.33,"id":17336468}],"tv":33329.54}]}
{"op":"mcm","clk":"993128742","pt":1580560829065,"mc":[{"id":"1.168136214","rc":[{"batb":[[1,5,40.61]],"ltp":5.1,"tv":6391.9,"id":12925630}]}]}
{"op":"mcm","clk":"993128937","pt":1580560830093,"mc":[{"id":"1.168136214","rc":[{"batb":[[1,5,37.75]],"ltp":5.1,"tv":6391.9,"id":12925630}]}]}
{"op":"mcm","clk":"993129142","pt":1580560831156,"mc":[{"id":"1.168136214","rc":[{"batb":[[1,5,34.23]],"ltp":5.1,"tv":6391.9,"id":12925630},{"batl":[[0,1.84,142.36]],"ltp":1.83,"tv":19583.33,"id":17336468}]}]}
{"op":"mcm","clk":"993129307","pt":1580560832064,"mc":[{"id":"1.168136214","rc":[{"batb":[[0,5.1,2.53]],"batl":[[0,5.2,31.17]],"ltp":5.1,"tv":6391.9,"id":12925630},{"trd":[[1.84,872.27]],"batb":[[0,1.84,37.74],[1,1.83,14.53],[2,1.82,82.43]],"batl":[[0,1.85,82.04],[1,1.86,96.18],[2,1.87,28.63]],"ltp":1.84,"tv":19907.85,"id":17336468},{"batb":[[0,3.8,4.35]],"ltp":3.85,"tv":7354.3,"id":11981493}],"tv":33654.06}]}
{"op":"mcm","clk":"993129550","pt":1580560833140,"mc":[{"id":"1.168136214","rc":[{"trd":[[5.1,339.95]],"batb":[[0,5,34.23],[1,4.9,6],[2,4.8,93.19]],"batl":[[0,5.1,5.47],[1,5.2,31.17],[2,5.3,81.6]],"ltp":5.1,"tv":6396.96,"id":12925630},{"batb":[[1,1.83,34.53]],"batl":[[0,1.85,63.24],[1,1.86,63.37]],"ltp":1.84,"tv":19907.85,"id":17336468},{"batb":[[0,3.8,15.53]],"ltp":3.85,"tv":7354.3,"id":11981493}],"tv":33659.12}]}
{"op":"mcm","clk":"993129736","pt":1580560834070,"mc":[{"id":"1.168136214","rc":[{"batb":[[0,5,23.77],[1,4.9,9.2]],"ltp":5.1,"tv":6396.96,"id":12925630},{"batl":[[1,1.86,55.01]],"ltp":1.84,"tv":19907.85,"id":17336468}]}]}
{"op":"mcm","clk":"993129942","pt":1580560835052,"mc":[{"id":"1.168136214","rc":[{"batb":[[0,5,18.52],[2,4.8,32.38]],"batl":[[0,5.1,9.47]],"ltp":5.1,"tv":6396.96,"id":12925630},{"trd":[[1.84,892.27]],"batb":[[1,1.83,36.53],[2,1.82,95.44]],"ltp":1.84,"tv":19927.85,"id":17336468}],"tv":33679.12}]}
{"op":"mcm","clk":"993130142","pt":1580560836070,"mc":[{"id":"1.168136214","rc":[{"batb":[[1,4.9,16.8]],"ltp":5.1,"tv":6396.96,"id":12925630},{"batb":[[1,1.83,58.84]],"ltp":1.84,"tv":19927.85,"id":17336468}]}]}
{"op":"mcm","clk":"993130309","pt":1580560837066,"mc":[{"id":"1.168136214","rc":[{"batb":[[2,4.8,93.19]],"batl":[[1,5.2,38.59]],"ltp":5.1,"tv":6396.96,"id":12925630},{"batb":[[1,1.83,38.84]],"ltp":1.84,"tv":19927.85,"id":17336468}]}]}
{"op":"mcm","clk":"993130511","pt":1580560838146,"mc":[{"id":"1.168136214","rc":[{"batb":[[2,4.8,32.38]],"ltp":5.1,"tv":6396.96,"id":12925630},{"trd":[[1.85,781.85]],"batb":[[0,1.84,62.7]],"batl":[[0,1.85,43.24]],"ltp":1.85,"tv":19967.85,"id":17336468}],"tv":33719.12}]}
{"op":"mcm","clk":"993130679","pt":1580560839074,"mc":[{"id":"1.168136214","rc":[{"trd":[[1.85,791.93]],"batb":[[1,1.83,88.84]],"batl":[[0,1.85,38.2]],"ltp":1.85,"tv":19977.94,"id":17336468}],"tv":33729.2}]}
{"op":"mcm","clk":"993131098","pt":1580560841146,"mc":[{"id":"1.168136214","rc":[{"batb":[[0,5,6]],"ltp":5.1,"tv":6396.96,"id":12925630},{"trd":[[1.85,868.33]],"batb":[[0,1.84,96.54]],"batl":[[0,1.86,55.01],[1,1.87,28.63],[2,1.88,52.76]],"ltp":1.85,"tv":20054.34,"id":17336468},{"batb":[[0,3.8,26.53]],"batl":[[0,3.85,21.88]],"ltp":3.85,"tv":7354.3,"id":11981493}],"tv":33805.6}]}
{"op":"mcm","clk":"993131291","pt":1580560842146,"mc":[{"id":"1.168136214","rc":[{"batb":[[0,4.9,19.76],[1,4.8,35.65],[2,4.7,18.22]],"ltp":5.1,"tv":6396.96,"id":12925630},{"batb":[[0,1.85,22.31],[1,1.84,96.54],[2,1.83,66.53]],"batl":[[0,1.86,36.01]],"ltp":1.85,"tv":20054.34,"id":17336468}]}]}
{"op":"mcm","clk":"993131486","pt":1580560843063,"mc":[{"id":"1.168136214","rc":[{"batl":[[1,5.2,51.08]],"ltp":5.1,"tv":6396.96,"id":12925630},{"batl":[[1,1.87,16.17],[2,1.88,68.76]],"ltp":1.85,"tv":20054.34,"id":17336468},{"batb":[[0,3.8,25.58]],"ltp":3.85,"tv":7354.3,"id":11981493}]}]}
{"op":"mcm","clk":"993131672","pt":1580560844074,"mc":[{"id":"1.168136214","rc":[{"batb":[[0,1.85,27.67],[2,1.83,64.53]],"ltp":1.85,"tv":20054.34,"id":17336468},{"batl":[[0,3.85,13.48]],"ltp":3.85,"tv":7354.3,"id":11981493}]}]}
{"op":"mcm","clk":"993132080","pt":1580560846096,"mc":[{"id":"1.168136214","rc":[{"trd":[[1.86,603.48]],"batl":[[0,1.86,34.02]],"ltp":1.86,"tv":20058.33,"id":17336468}],"tv":33809.6}]}
{"op":"mcm","clk":"993132171","pt":1580560846544,"mc":[{"id":"1.168136214","rc":[{"batl":[[0,5.1,12.49]],"ltp":5.1,"tv":6396.96,"id":12925630}]}]}
{"op":"mcm","clk":"993132324","pt":1580560848148,"mc":[{"id":"1.168136214","rc":[{"batl":[[0,5.1,31.77]],"ltp":5.1,"tv":6396.96,"id":12925630}]}]}
{"op":"mcm","clk":"993132647","pt":1580560849049,"mc":[{"id":"1.168136214","rc":[{"trd":[[1.84,899.55],[1.85,923.67]],"batb":[[0,1.85,5],[1,1.84,92.9]],"batl":[[0,1.86,50.02],[2,1.88,70.76]],"ltp":1.84,"tv":20120.95,"id":17336468}],"tv":33872.22}]}
{"op":"mcm","clk":"993132834","pt":1580560850082,"mc":[{"id":"1.168136214","rc":[{"batb":[[0,1.85,18.42]],"ltp":1.84,"tv":20120.95,"id":17336468}]}]}
{"op":"mcm","clk":"993132985","pt":1580560851059,"mc":[{"id":"1.168136214","rc":[{"batl":[[1,5.2,31.78]],"ltp":5.1,"tv":6396.96,"id":12925630}]}]}
{"op":"mcm","clk":"993133121","pt":1580560851875,"mc":[{"id":"1.168136214","rc":[{"batb":[[0,1.85,13.42],[1,1.84,97.9]],"ltp":1.84,"tv":20120.95,"id":17336468},{"trd":[[3.85,1237.6]],"batl":[[0,3.85,8.43]],"ltp":3.85,"tv":7364.39,"id":11981493}],"tv":33882.31}]}
{"op":"mcm","clk":"993133934","pt":1580560856096,"mc":[{"id":"1.168136214","rc":[{"trd":[[1.85,923.87]],"batb":[[0,1.85,13.32]],"ltp":1.85,"tv":20121.15,"id":17336468}],"tv":33882.51}]}
{"op":"mcm","clk":"993134155","pt":1580560857079,"mc":[{"id":"1.168136214","rc":[{"trd":[[3.8,1529.79],[3.85,1244.32]],"batb":[[0,3.8,20.58]],"batl":[[0,3.85,5.07]],"ltp":3.8,"tv":7381.1,"id":11981493}],"tv":33899.23}]}
{"op":"mcm","clk":"993134364","pt":1580560858072,"mc":[{"id":"1.168136214","rc":[{"batb":[[2,4.7,10.01]],"batl":[[2,5.3,92.21]],"ltp":5.1,"tv":6396.96,"id":12925630}]}]}
{"op":"mcm","clk":"993134597","pt":1580560859102,"mc":[{"id":"1.168136214","rc":[{"batb":[[1,1.84,92.9]],"ltp":1.85,"tv":20121.15,"id":17336468}]}]}
{"op":"mcm","clk":"993134819","pt":1580560860036,"mc":[{"id":"1.168136214","rc":[{"trd":[[1.86,623.47]],"batb":[[0,1.85,42.12]],"batl":[[0,1.86,40.03]],"ltp":1.86,"tv":20141.14,"id":17336468}],"tv":33919.21}]}
{"op":"mcm","clk":"993135033","pt":1580560861082,"mc":[{"id":"1.168136214","rc":[{"trd":[[1.86,638.2]],"batb":[[0,1.85,48.82]],"batl":[[0,1.86,26]],"ltp":1.86,"tv":20155.87,"id":17336468},{"batl":[[0,3.85,25.33]],"ltp":3.8,"tv":7381.1,"id":11981493}],"tv":33933.95}]}
{"op":"mcm","clk":"993135234","pt":1580560862062,"mc":[{"id":"1.168136214","rc":[{"batl":[[2,5.3,81.6]],"ltp":5.1,"tv":6396.96,"id":12925630},{"trd":[[1.86,654.2]],"batb":[[0,1.85,127.28]],"batl":[[0,1.86,2]],"ltp":1.86,"tv":20171.87,"id":17336468}],"tv":33949.95}]}
{"op":"mcm","clk":"993135403","pt":1580560862984,"mc":[{"id":"1.168136214","rc":[{"trd":[[1.86,658.2]],"batb":[[0,1.86,6],[1,1.85,127.28],[2,1.84,92.9]],"batl":[[0,1.87,16.17],[1,1.88,66.82],[2,1.89,928.98]],"ltp":1.86,"tv":20175.87,"id":17336468},{"batl":[[1,3.9,86.14]],"ltp":3.8,"tv":7381.1,"id":11981493}],"tv":33953.95}]}
{"op":"mcm","clk":"993135867","pt":1580560865116,"mc":[{"id":"1.168136214","rc":[{"batl":[[1,1.88,62.05]],"ltp":1.86,"tv":20175.87,"id":17336468}]}]}
{"op":"mcm","clk":"993136255","pt":1580560867102,"mc":[{"id":"1.168136214","rc":[{"batb":[[0,1.86,11]],"ltp":1.86,"tv":20175.87,"id":17336468}]}]}
{"op":"mcm","clk":"993136448","pt":1580560868129,"mc":[{"id":"1.168136214","rc":[{"trd":[[1.87,499.35]],"batb":[[0,1.87,3.63],[1,1.86,11],[2,1.85,127.28]],"batl":[[0,1.88,62.05],[1,1.89,928.98],[2,1.9,433.81]],"ltp":1.87,"tv":20208.61,"id":17336468}],"tv":33986.69}]}
{"op":"mcm","clk":"993136644","pt":1580560869112,"mc":[{"id":"1.168136214","rc":[{"batl":[[0,5,5.04],[1,5.1,35.44],[2,5.2,41.97]],"ltp":5.1,"tv":6396.96,"id":12925630},{"trd":[[1.86,658.94],[1.87,526.61]],"batb":[[0,1.86,22.63],[1,1.85,127.28],[2,1.84,92.9]],"batl":[[0,1.87,31.57],[1,1.88,101.47],[2,1.89,928.98]],"ltp":1.87,"tv":20236.61,"id":17336468},{"batb":[[0,3.8,20],[1,3.75,48.82]],"ltp":3.8,"tv":7381.1,"id":11981493}],"tv":34014.69}]}
{"op":"mcm","clk":"993136866","pt":1580560870114,"mc":[{"id":"1.168136214","rc":[{"batb":[[0,4.9,6]],"batl":[[0,5.1,35.44],[1,5.2,43.97],[2,5.3,83.6]],"ltp":5.1,"tv":6396.96,"id":12925630},{"batl":[[0,1.87,11],[1,1.88,96.47],[2,1.89,923.98]],"ltp":1.87,"tv":20236.61,"id":17336468},{"batb":[[0,3.8,40.26]],"ltp":3.8,"tv":7381.1,"id":11981493}]}]}
{"op":"mcm","clk":"993137086","pt":1580560871130,"mc":[{"id":"1.168136214","rc":[{"batl":[[1,5.2,33.78]],"ltp":5.1,"tv":6396.96,"id":12925630},{"trd":[[1.86,663.87]],"batb":[[0,1.86,20.17]],"ltp":1.86,"tv":20241.54,"id":17336468}],"tv":34019.61}]}
{"op":"mcm","clk":"993137274","pt":1580560872112,"mc":[{"id":"1.168136214","rc":[{"batb":[[0,4.8,35.65],[1,4.7,10.01],[2,4.6,87.31]],"batl":[[0,5,7.06],[1,5.1,35.44],[2,5.2,33.78]],"ltp":5.1,"tv":6396.96,"id":12925630},{"batb":[[0,1.86,31.17],[1,1.85,1627.28]],"batl":[[0,1.88,78.12],[1,1.89,923.98],[2,1.9,446.81]],"ltp":1.86,"tv":20241.54,"id":17336468}]}]}
{"op":"mcm","clk":"993137500","pt":1580560873147,"mc":[{"id":"1.168136214","rc":[{"batb":[[0,4.8,30.66],[2,4.6,23.12]],"ltp":5.1,"tv":6396.96,"id":12925630},{"batb":[[0,1.86,68.67]],"batl":[[0,1.88,45.22]],"ltp":1.86,"tv":20241.54,"id":17336468}]}]}
{"op":"mcm","clk":"993137700","pt":1580560874134,"mc":[{"id":"1.168136214","rc":[{"batb":[[0,4.8,27.39],[1,4.7,22.34]],"batl":[[0,5,2]],"ltp":5.1,"tv":6396.96,"id":12925630},{"batl":[[0,1.88,34.22]],"ltp":1.86,"tv":20241.54,"id":17336468}]}]}
{"op":"mcm","clk":"993137909","pt":1580560875112,"mc":[{"id":"1.168136214","rc":[{"batl":[[1,5.1,42.97],[2,5.2,47.05]],"ltp":5.1,"tv":6396.96,"id":12925630},{"batb":[[0,1.87,4],[1,1.86,68.67],[2,1.85,1627.28]],"batl":[[0,1.88,39.68]],"ltp":1.86,"tv":20241.54,"id":17336468}]}]}
{"op":"mcm","clk":"993138078","pt":1580560876024,"mc":[{"id":"1.168136214","rc":[{"batb":[[1,1.86,119.32]],"batl":[[0,1.88,34.22],[1,1.89,911]],"ltp":1.86,"tv":20241.54,"id":17336468}]}]}
{"op":"mcm","clk":"993138306","pt":1580560877131,"mc":[{"id":"1.168136214","rc":[{"batl":[[2,1.9,457.04]],"ltp":1.86,"tv":20241.54,"id":17336468},{"batl":[[0,3.85,33.73]],"ltp":3.8,"tv":7381.1,"id":11981493}]}]}
{"op":"mcm","clk":"993138520","pt":1580560878059,"mc":[{"id":"1.168136214","rc":[{"batb":[[1,1.86,134.52]],"batl":[[0,1.88,41.22]],"ltp":1.86,"tv":20241.54,"id":17336468}]}]}
{"op":"mcm","clk":"993138960","pt":1580560880047,"mc":[{"id":"1.168136214","rc":[{"batb":[[1,4.7,19.34]],"batl":[[0,5,15.32],[2,5.2,58.02]],"ltp":5.1,"tv":6396.96,"id":12925630},{"trd":[[1.88,291.15]],"batb":[[0,1.87,29.37],[2,1.85,1602.85]],"batl":[[0,1.88,12.81]],"ltp":1.88,"tv":20298.38,"id":17336468}],"tv":34076.45}]}
{"op":"mcm","clk":"993139199","pt":1580560881140,"mc":[{"id":"1.168136214","rc":[{"batb":[[0,4.8,20.07]],"batl":[[0,5,9.22],[1,5.1,45.97]],"ltp":5.1,"tv":6396.96,"id":12925630},{"batb":[[0,1.87,34.44],[1,1.86,140.52]],"batl":[[1,1.89,916]],"ltp":1.88,"tv":20298.38,"id":17336468},{"batb":[[2,3.7,65.28]],"ltp":3.8,"tv":7381.1,"id":11981493}]}]}
{"op":"mcm","clk":"993139411","pt":1580560882143,"mc":[{"id":"1.168136214","rc":[{"trd":[[4.9,80.62]],"batb":[[0,4.9,7.33],[1,4.8,20.07],[2,4.7,19.34]],"batl":[[0,5,16.22]],"ltp":4.9,"tv":6400.96,"id":12925630},{"trd":[[1.88,299.15]],"batl":[[0,1.88,8.81]],"ltp":1.88,"tv":20306.38,"id":17336468},{"batb":[[0,3.8,31.26]],"ltp":3.8,"tv":7381.1,"id":11981493}],"tv":34088.45}]}
{"op":"mcm","clk":"993139585","pt":1580560883040,"mc":[{"id":"1.168136214","rc":[{"trd":[[4.9,81.4]],"batb":[[0,4.9,6.94],[2,4.7,21.43]],"batl":[[2,5.2,47.05]],"ltp":4.9,"tv":6401.74,"id":12925630}],"tv":34089.23}]}
{"op":"mcm","clk":"993139803","pt":1580560884139,"mc":[{"id":"1.168136214","rc":[{"trd":[[3.8,1530.79]],"batb":[[0,3.8,30.76],[2,3.7,48.22]],"ltp":3.8,"tv":7382.1,"id":11981493}],"tv":34090.23}]}
{"op":"mcm","clk":"993140007","pt":1580560885137,"mc":[{"id":"1.168136214","rc":[{"batb":[[1,4.8,70.07]],"ltp":4.9,"tv":6401.74,"id":12925630},{"trd":[[1.88,305.19]],"batb":[[1,1.86,137.52]],"batl":[[0,1.88,5.79]],"ltp":1.88,"tv":20312.42,"id":17336468}],"tv":34096.27}]}
{"op":"mcm","clk":"993140203","pt":1580560886059,"mc":[{"id":"1.168136214","rc":[{"batb":[[1,4.8,73.07]],"ltp":4.9,"tv":6401.74,"id":12925630},{"trd":[[1.87,528.17]],"batb":[[0,1.87,89.8],[2,1.85,1608.85]],"batl":[[0,1.88,61.63],[2,1.9,462.04]],"ltp":1.87,"tv":20313.98,"id":17336468},{"batb":[[1,3.75,52.82]],"batl":[[0,3.85,41.73],[1,3.9,89.14],[2,3.95,33.9]],"ltp":3.8,"tv":7382.1,"id":11981493}],"tv":34097.83}]}
{"op":"mcm","clk":"993140436","pt":1580560887151,"mc":[{"id":"1.168136214","rc":[{"batb":[[1,1.86,122.32]],"ltp":1.87,"tv":20313.98,"id":17336468},{"batb":[[0,3.8,36.76]],"ltp":3.8,"tv":7382.1,"id":11981493}]}]}
{"op":"mcm","clk":"993141020","pt":1580560890151,"mc":[{"id":"1.168136214","rc":[{"batb":[[0,4.9,15.94]],"ltp":4.9,"tv":6401.74,"id":12925630}]}]}
{"op":"mcm","clk":"993141213","pt":1580560891136,"mc":[{"id":"1.168136214","rc":[{"batb":[[2,4.7,18.1]],"ltp":4.9,"tv":6401.74,"id":12925630}]}]}
{"op":"mcm","clk":"993141399","pt":1580560892025,"mc":[{"id":"1.168136214","rc":[{"trd":[[5,118.24]],"batl":[[0,5,15.21]],"ltp":5.0,"tv":6403.76,"id":12925630},{"trd":[[1.88,345.19]],"batb":[[0,1.87,216.91]],"batl":[[0,1.88,158.11]],"ltp":1.88,"tv":20353.98,"id":17336468}],"tv":34139.85}]}
{"op":"mcm","clk":"993141622","pt":1580560893115,"mc":[{"id":"1.168136214","rc":[{"batl":[[0,5,34.87]],"ltp":5.0,"tv":6403.76,"id":12925630}]}]}
{"op":"mcm","clk":"993141788","pt":1580560894029,"mc":[{"id":"1.168136214","rc":[{"batl":[[1,5.1,26.7]],"ltp":5.0,"tv":6403.76,"id":12925630},{"trd":[[1.87,586.31]],"batb":[[0,1.87,187.83]],"batl":[[1,1.89,917.68]],"ltp":1.87,"tv":20412.12,"id":17336468},{"trd":[[3.85,1248.32]],"batl":[[0,3.85,39.73]],"ltp":3.85,"tv":7386.1,"id":11981493}],"tv":34201.99}]}
{"op":"mcm","clk":"993141998","pt":1580560895044,"mc":[{"id":"1.168136214","rc":[{"batb":[[1,1.86,124]],"ltp":1.87,"tv":20412.12,"id":17336468}]}]}
{"op":"mcm","clk":"993142154","pt":1580560895833,"mc":[{"id":"1.168136214","rc":[{"trd":[[1.88,385.19]],"batl":[[0,1.88,138.11]],"ltp":1.88,"tv":20452.12,"id":17336468}],"tv":34241.99}]}
{"op":"mcm","clk":"993142413","pt":1580560897136,"mc":[{"id":"1.168136214","rc":[{"batl":[[0,1.88,143.11]],"ltp":1.88,"tv":20452.12,"id":17336468},{"batb":[[2,3.7,65.28]],"ltp":3.85,"tv":7386.1,"id":11981493}]}]}
{"op":"mcm","clk":"993142607","pt":1580560898143,"mc":[{"id":"1.168136214","rc":[{"trd":[[5,119.2]],"batl":[[0,5,34.39]],"ltp":5.0,"tv":6404.72,"id":12925630},{"trd":[[1.88,415.19]],"batl":[[0,1.88,128.11]],"ltp":1.88,"tv":20482.12,"id":17336468},{"trd":[[3.8,1547.59]],"batb":[[0,3.8,28.36]],"batl":[[0,3.85,31.33]],"ltp":3.8,"tv":7402.91,"id":11981493}],"tv":34289.76}]}
{"op":"mcm","clk":"993142967","pt":1580560900136,"mc":[{"id":"1.168136214","rc":[{"batl":[[2,1.9,464.32]],"ltp":1.88,"tv":20482.12,"id":17336468}]}]}
{"op":"mcm","clk":"993143136","pt":1580560901048,"mc":[{"id":"1.168136214","rc":[{"trd":[[1.88,445.6]],"batl":[[0,1.88,112.9]],"ltp":1.88,"tv":20512.53,"id":17336468}],"tv":34320.16}]}
{"op":"mcm","clk":"993143657","pt":1580560904074,"mc":[{"id":"1.168136214","rc":[{"batb":[[2,4.7,21.1]],"batl":[[2,5.2,50.05]],"ltp":5.0,"tv":6404.72,"id":12925630},{"trd":[[1.87,986.3],[1.88,455.6]],"batb":[[0,1.86,124],[1,1.85,1608.85],[2,1.84,138.61]],"batl":[[0,1.88,128.1]],"ltp":1.88,"tv":20922.52,"id":17336468}],"tv":34730.16}]}
{"op":"mcm","clk":"993143824","pt":1580560904932,"mc":[{"id":"1.168136214","rc":[{"batb":[[1,4.8,80.95]],"ltp":5.0,"tv":6404.72,"id":12925630}]}]}
{"op":"mcm","clk":"993144218","pt":1580560906941,"mc":[{"id":"1.168136214","rc":[{"trd":[[1.88,498.96]],"batl":[[0,1.88,106.42]],"ltp":1.88,"tv":20965.88,"id":17336468}],"tv":34773.52}]}
{"op":"mcm","clk":"993144611","pt":1580560909065,"mc":[{"id":"1.168136214","rc":[{"batl":[[0,1.87,25],[1,1.88,106.42],[2,1.89,917.68]],"ltp":1.88,"tv":20965.88,"id":17336468}]}]}
{"op":"mcm","clk":"993145034","pt":1580560911147,"mc":[{"id":"1.168136214","rc":[{"batb":[[0,4.9,17.94]],"ltp":5.0,"tv":6404.72,"id":12925630},{"batl":[[0,1.87,29]],"ltp":1.88,"tv":20965.88,"id":17336468}]}]}
{"op":"mcm","clk":"993145198","pt":1580560911957,"mc":[{"id":"1.168136214","rc":[{"batb":[[1,1.85,1618.85]],"ltp":1.88,"tv":20965.88,"id":17336468}]}]}
{"op":"mcm","clk":"993145804","pt":1580560915104,"mc":[{"id":"1.168136214","rc":[{"batb":[[1,4.8,30.95]],"ltp":5.0,"tv":6404.72,"id":12925630},{"trd":[[1.86,713.87],[1.87,991.94]],"batb":[[0,1.86,99]],"batl":[[0,1.87,1.18]],"ltp":1.87,"tv":21021.52,"id":17336468}],"tv":34829.16}]}
{"op":"mcm","clk":"993145984","pt":1580560916102,"mc":[{"id":"1.168136214","rc":[{"trd":[[1.86,716.23]],"batb":[[0,1.86,97.82]],"batl":[[0,1.88,106.42],[1,1.89,917.68],[2,1.9,464.32]],"ltp":1.86,"tv":21023.88,"id":17336468}],"tv":34831.52}]}
{"op":"mcm","clk":"993146159","pt":1580560917125,"mc":[{"id":"1.168136214","rc":[{"trd":[[3.8,1553.59]],"batb":[[0,3.8,25.36]],"ltp":3.8,"tv":7408.91,"id":11981493}],"tv":34837.52}]}
{"op":"mcm","clk":"993146338","pt":1580560918093,"mc":[{"id":"1.168136214","rc":[{"trd":[[1.86,736.23]],"batb":[[0,1.86,87.82]],"ltp":1.86,"tv":21043.88,"id":17336468}],"tv":34857.52}]}
{"op":"mcm","clk":"993146516","pt":1580560919120,"mc":[{"id":"1.168136214","rc":[{"trd":[[1.88,518.96]],"batl":[[0,1.88,96.42]],"ltp":1.88,"tv":21063.88,"id":17336468}],"tv":34877.52}]}
{"op":"mcm","clk":"993146909","pt":1580560921136,"mc":[{"id":"1.168136214","rc":[{"batb":[[0,4.9,27.91]],"batl":[[0,5,44.16]],"ltp":5.0,"tv":6404.72,"id":12925630},{"batb":[[0,1.86,165.91]],"batl":[[0,1.88,171.7]],"ltp":1.88,"tv":21063.88,"id":17336468},{"batb":[[0,3.8,39.74]],"batl":[[0,3.85,45.52],[1,3.9,93.2]],"ltp":3.8,"tv":7408.91,"id":11981493}]}]}
{"op":"mcm","clk":"993147102","pt":1580560922124,"mc":[{"id":"1.168136214","rc":[{"batl":[[1,5.1,23.67],[2,5.2,36.78]],"ltp":5.0,"tv":6404.72,"id":12925630},{"trd":[[1.86,737.27]],"batb":[[0,1.86,165.39]],"batl":[[2,1.9,456.54]],"ltp":1.86,"tv":21064.92,"id":17336468},{"trd":[[3.8,1554.64]],"batb":[[0,3.8,39.22]],"batl":[[1,3.9,89.14]],"ltp":3.8,"tv":7409.95,"id":11981493}],"tv":34879.6}]}
{"op":"mcm","clk":"993147305","pt":1580560923115,"mc":[{"id":"1.168136214","rc":[{"batb":[[1,3.75,67.46]],"ltp":3.8,"tv":7409.95,"id":11981493}]}]}
{"op":"mcm","clk":"993147865","pt":1580560926133,"mc":[{"id":"1.168136214","rc":[{"trd":[[1.86,739.31]],"batb":[[0,1.86,164.37]],"ltp":1.86,"tv":21066.96,"id":17336468},{"trd":[[3.8,1556.67]],"batb":[[0,3.8,38.2]],"ltp":3.8,"tv":7411.99,"id":11981493}],"tv":34883.68}]}
{"op":"mcm","clk":"993148225","pt":1580560927936,"mc":[{"id":"1.168136214","rc":[{"trd":[[5,119.42]],"batl":[[0,5,44.05]],"ltp":5.0,"tv":6404.94,"id":12925630}],"tv":34883.9}]}
{"op":"mcm","clk":"993148636","pt":1580560929959,"mc":[{"id":"1.168136214","rc":[{"batb":[[0,1.87,10],[1,1.86,164.37],[2,1.85,1618.85]],"ltp":1.86,"tv":21066.96,"id":17336468}]}]}
{"op":"mcm","clk":"993148885","pt":1580560931049,"mc":[{"id":"1.168136214","rc":[{"trd":[[1.87,1011.94],[1.88,530.36]],"batb":[[0,1.86,164.37],[1,1.85,1618.85],[2,1.84,138.61]],"batl":[[0,1.88,166]],"ltp":1.87,"tv":21098.36,"id":17336468}],"tv":34915.3}]}
{"op":"mcm","clk":"993149083","pt":1580560932156,"mc":[{"id":"1.168136214","rc":[{"trd":[[1.88,630.36]],"batl":[[0,1.88,116]],"ltp":1.88,"tv":21198.36,"id":17336468}],"tv":35015.3}]}
{"op":"mcm","clk":"993149280","pt":1580560933136,"mc":[{"id":"1.168136214","rc":[{"batb":[[1,4.8,41.15]],"ltp":5.0,"tv":6404.94,"id":12925630},{"batb":[[0,1.87,90.94],[1,1.86,3200.37],[2,1.85,1618.85]],"batl":[[0,1.88,96],[1,1.89,1023.66]],"ltp":1.88,"tv":21198.36,"id":17336468},{"batb":[[0,3.8,23.82],[2,3.7,71.28]],"ltp":3.8,"tv":7411.99,"id":11981493}]}]}
{"op":"mcm","clk":"993149465","pt":1580560934068,"mc":[{"id":"1.168136214","rc":[{"batb":[[1,3.75,61.96]],"ltp":3.8,"tv":7411.99,"id":11981493}]}]}
{"op":"mcm","clk":"993149857","pt":1580560936084,"mc":[{"id":"1.168136214","rc":[{"trd":[[1.88,630.37]],"batl":[[0,1.88,95.99]],"ltp":1.88,"tv":21198.37,"id":17336468}],"tv":35015.31}]}
{"op":"mcm","clk":"993150063","pt":1580560937055,"mc":[{"id":"1.168136214","rc":[{"trd":[[5,119.88]],"batl":[[0,5,43.82]],"ltp":5.0,"tv":6405.4,"id":12925630}],"tv":35015.77}]}
{"op":"mcm","clk":"993150260","pt":1580560938082,"mc":[{"id":"1.168136214","rc":[{"batl":[[0,1.88,95.79]],"ltp":1.88,"tv":21198.37,"id":17336468}]}]}
{"op":"mcm","clk":"993150429","pt":1580560938957,"mc":[{"id":"1.168136214","rc":[{"batb":[[0,4.9,17.94]],"ltp":5.0,"tv":6405.4,"id":12925630},{"trd":[[1.88,642.37]],"batb":[[0,1.87,99.94]],"batl":[[0,1.88,89.79]],"ltp":1.88,"tv":21210.37,"id":17336468},{"trd":[[3.85,1298.3]],"batb":[[0,3.8,36.74]],"batl":[[0,3.85,41.74]],"ltp":3.85,"tv":7461.97,"id":11981493}],"tv":35077.75}]}
{"op":"mcm","clk":"993150670","pt":1580560940154,"mc":[{"id":"1.168136214","rc":[{"trd":[[1.88,742.37]],"batl":[[0,1.88,39.99]],"ltp":1.88,"tv":21310.37,"id":17336468}],"tv":35177.75}]}
{"op":"mcm","clk":"993150831","pt":1580560941071,"mc":[{"id":"1.168136214","rc":[{"batb":[[0,4.9,27.81]],"ltp":5.0,"tv":6405.4,"id":12925630},{"trd":[[1.86,739.43],[1.87,1211.82]],"batb":[[0,1.86,3200.31],[1,1.85,1618.85],[2,1.84,138.61]],"ltp":1.86,"tv":21510.37,"id":17336468},{"batl":[[0,3.85,20.54]],"ltp":3.85,"tv":7461.97,"id":11981493}],"tv":35377.75}]}
{"op":"mcm","clk":"993151025","pt":1580560942075,"mc":[{"id":"1.168136214","rc":[{"trd":[[1.86,746.79]],"batb":[[0,1.86,3181.63],[1,1.85,1626.85],[2,1.84,146.61]],"batl":[[2,1.9,466.54]],"ltp":1.86,"tv":21517.73,"id":17336468},{"trd":[[3.85,1322.3]],"batb":[[1,3.75,67.96]],"batl":[[0,3.85,18.54],[1,3.9,101.47]],"ltp":3.85,"tv":7485.97,"id":11981493}],"tv":35409.11}]}
{"op":"mcm","clk":"993151606","pt":1580560945055,"mc":[{"id":"1.168136214","rc":[{"batb":[[1,4.8,45.15]],"batl":[[0,5,47.82],[1,5.1,27.67]],"ltp":5.0,"tv":6405.4,"id":12925630},{"batl":[[0,1.88,48.99]],"ltp":1.86,"tv":21517.73,"id":17336468},{"batl":[[1,3.9,105.47],[2,3.95,37.9]],"ltp":3.85,"tv":7485.97,"id":11981493}]}]}
{"op":"mcm","clk":"993152939","pt":1580560951751,"mc":[{"id":"1.168136214","rc":[{"batl":[[0,1.88,55.99]],"ltp":1.86,"tv":21517.73,"id":17336468}]}]}
{"op":"mcm","clk":"993153933","pt":1580560957086,"mc":[{"id":"1.168136214","rc":[{"trd":[[1.88,802.37]],"batl":[[0,1.88,25.99]],"ltp":1.88,"tv":21577.73,"id":17336468}],"tv":35469.11}]}
{"op":"mcm","clk":"993154696","pt":1580560961112,"mc":[{"id":"1.168136214","rc":[{"batl":[[0,1.87,2],[1,1.88,25.99],[2,1.89,1023.66]],"ltp":1.88,"tv":21577.73,"id":17336468}]}]}
{"op":"mcm","clk":"993154885","pt":1580560962089,"mc":[{"id":"1.168136214","rc":[{"batb":[[2,4.7,26.1]],"batl":[[2,5.2,40.78]],"ltp":5.0,"tv":6405.4,"id":12925630},{"trd":[[1.87,1828.84]],"batb":[[0,1.87,138.49],[1,1.86,3190.63],[2,1.85,1626.85]],"batl":[[0,1.88,25.99],[1,1.89,1134.76],[2,1.9,466.54]],"ltp":1.87,"tv":22194.75,"id":17336468},{"batb":[[2,3.7,78.28]],"batl":[[0,3.85,22.54]],"ltp":3.85,"tv":7485.97,"id":11981493}],"tv":36086.13}]}
{"op":"mcm","clk":"993155067","pt":1580560963116,"mc":[{"id":"1.168136214","rc":[{"batb":[[0,1.87,440.19]],"batl":[[2,1.9,464.27]],"ltp":1.87,"tv":22194.75,"id":17336468},{"batb":[[0,3.8,23.82]],"batl":[[0,3.85,46.24]],"ltp":3.85,"tv":7485.97,"id":11981493}]}]}
{"op":"mcm","clk":"993155423","pt":1580560965142,"mc":[{"id":"1.168136214","rc":[{"trd":[[4.9,123.47]],"batb":[[0,4.8,45.15],[1,4.7,26.1],[2,4.6,102.31]],"batl":[[0,4.9,9.31],[1,5,49.82],[2,5.1,27.67]],"ltp":4.9,"tv":6447.47,"id":12925630},{"trd":[[1.88,1140.69]],"batb":[[0,1.88,8.72],[1,1.87,472.19],[2,1.86,3190.63]],"batl":[[0,1.89,1104.44],[1,1.9,451.5],[2,1.91,69.22]],"ltp":1.88,"tv":22533.07,"id":17336468},{"trd":[[3.8,1580.49]],"batb":[[0,3.75,67.96],[1,3.7,61.22],[2,3.65,60.74]],"batl":[[0,3.8,12.66],[1,3.85,46.24],[2,3.9,118.61]],"ltp":3.8,"tv":7509.79,"id":11981493}],"tv":36490.34}]}
{"op":"mcm","clk":"993155602","pt":1580560966054,"mc":[{"id":"1.168136214","rc":[{"batb":[[2,4.6,38.12]],"batl":[[0,4.9,22.56],[1,5,57.7]],"ltp":4.9,"tv":6447.47,"id":12925630},{"trd":[[1.88,1156.69]],"batb":[[0,1.88,316.3],[2,1.86,3192.31]],"ltp":1.88,"tv":22549.07,"id":17336468},{"batl":[[0,3.8,14.66]],"ltp":3.8,"tv":7509.79,"id":11981493}],"tv":36506.34}]}
{"op":"mcm","clk":"993155818","pt":1580560967139,"mc":[{"id":"1.168136214","rc":[{"trd":[[4.9,131.47]],"batb":[[0,4.8,37.27]],"batl":[[0,4.9,18.56]],"ltp":4.9,"tv":6455.47,"id":12925630},{"batb":[[0,1.88,318.3],[2,1.86,3205.81]],"batl":[[1,1.9,439]],"ltp":1.88,"tv":22549.07,"id":17336468}],"tv":36514.34}]}
{"op":"mcm","clk":"993156020","pt":1580560968139,"mc":[{"id":"1.168136214","rc":[{"trd":[[4.9,139.47]],"batl":[[0,4.9,14.56]],"ltp":4.9,"tv":6463.47,"id":12925630},{"batb":[[0,1.88,336.3]],"ltp":1.88,"tv":22549.07,"id":17336468}],"tv":36522.34}]}
{"op":"mcm","clk":"993156231","pt":1580560969156,"mc":[{"id":"1.168136214","rc":[{"trd":[[4.9,142.09]],"batl":[[0,4.9,13.25]],"ltp":4.9,"tv":6466.09,"id":12925630},{"batb":[[0,1.88,56.97]],"ltp":1.88,"tv":22549.07,"id":17336468}],"tv":36524.96}]}
{"op":"mcm","clk":"993156419","pt":1580560970127,"mc":[{"id":"1.168136214","rc":[{"trd":[[4.9,164.09]],"batl":[[0,4.9,12.01]],"ltp":4.9,"tv":6488.09,"id":12925630},{"trd":[[3.8,1600.49]],"batl":[[0,3.8,4.66]],"ltp":3.8,"tv":7529.79,"id":11981493}],"tv":36566.96}]}
{"op":"mcm","clk":"993156619","pt":1580560971152,"mc":[{"id":"1.168136214","rc":[{"trd":[[4.9,186.09]],"batb":[[0,4.8,42.27]],"batl":[[0,5,57.7],[1,5.1,27.67],[2,5.2,40.78]],"ltp":4.9,"tv":6510.09,"id":12925630},{"trd":[[1.88,1336.63]],"batb":[[0,1.87,472.19],[1,1.86,3205.81],[2,1.85,1626.85]],"batl":[[0,1.88,216.84],[1,1.89,1111.44],[2,1.9,455]],"ltp":1.88,"tv":22729.01,"id":17336468},{"batb":[[0,3.75,83.96]],"ltp":3.8,"tv":7529.79,"id":11981493}],"tv":36768.9}]}
{"op":"mcm","clk":"993156813","pt":1580560972129,"mc":[{"id":"1.168136214","rc":[{"batb":[[0,4.9,6.37],[1,4.8,42.27],[2,4.7,26.1]],"ltp":4.9,"tv":6510.09,"id":12925630},{"trd":[[1.88,1340.61]],"batb":[[1,1.86,3192.31]],"batl":[[0,1.88,214.85]],"ltp":1.88,"tv":22732.99,"id":17336468},{"batb":[[2,3.65,43.68]],"ltp":3.8,"tv":7529.79,"id":11981493}],"tv":36772.88}]}
{"op":"mcm","clk":"993156998","pt":1580560973058,"mc":[{"id":"1.168136214","rc":[{"batb":[[1,4.8,50.15],[2,4.7,33.1]],"ltp":4.9,"tv":6510.09,"id":12925630},{"trd":[[1.88,1354.61]],"batl":[[0,1.88,207.85],[1,1.89,1163.44]],"ltp":1.88,"tv":22746.99,"id":17336468}],"tv":36786.88}]}
{"op":"mcm","clk":"993157433","pt":1580560975062,"mc":[{"id":"1.168136214","rc":[{"batb":[[0,4.9,16.38]],"ltp":4.9,"tv":6510.09,"id":12925630},{"trd":[[1.87,1879.26],[1.88,1382.13]],"batb":[[0,1.87,452.46]],"batl":[[0,1.88,194.29]],"ltp":1.88,"tv":22824.93,"id":17336468},{"batl":[[0,3.8,6.66]],"ltp":3.8,"tv":7529.79,"id":11981493}],"tv":36864.81}]}
{"op":"mcm","clk":"993157684","pt":1580560976057,"mc":[{"id":"1.168136214","rc":[{"batl":[[0,5,51.68]],"ltp":4.9,"tv":6510.09,"id":12925630},{"trd":[[1.87,1945.18]],"batb":[[0,1.87,547.5]],"ltp":1.87,"tv":22890.85,"id":17336468},{"batl":[[0,3.8,4.91]],"ltp":3.8,"tv":7529.79,"id":11981493}],"tv":36930.73}]}
{"op":"mcm","clk":"993158086","pt":1580560978077,"mc":[{"id":"1.168136214","rc":[{"trd":[[1.88,1394.13]],"batl":[[0,1.88,188.29]],"ltp":1.88,"tv":22902.85,"id":17336468}],"tv":36942.73}]}
{"op":"mcm","clk":"993158486","pt":1580560980138,"mc":[{"id":"1.168136214","rc":[{"trd":[[1.88,1494.13]],"batl":[[0,1.88,138.29]],"ltp":1.88,"tv":23002.85,"id":17336468}],"tv":37042.73}]}
{"op":"mcm","clk":"993158663","pt":1580560981067,"mc":[{"id":"1.168136214","rc":[{"batl":[[0,1.88,145.29],[1,1.89,1156.44]],"ltp":1.88,"tv":23002.85,"id":17336468}]}]}
{"op":"mcm","clk":"993158850","pt":1580560982056,"mc":[{"id":"1.168136214","rc":[{"trd":[[4.9,188.13]],"batb":[[0,4.9,5.35]],"ltp":4.9,"tv":6512.13,"id":12925630},{"trd":[[1.88,1522.13]],"batl":[[0,1.88,131.29]],"ltp":1.88,"tv":23030.85,"id":17336468},{"trd":[[3.8,1603.13]],"batl":[[0,3.8,3.59]],"ltp":3.8,"tv":7532.43,"id":11981493}],"tv":37075.41}]}
{"op":"mcm","clk":"993159071","pt":1580560983146,"mc":[{"id":"1.168136214","rc":[{"batl":[[0,1.88,137.29]],"ltp":1.88,"tv":23030.85,"id":17336468}]}]}
{"op":"mcm","clk":"993159433","pt":1580560985058,"mc":[{"id":"1.168136214","rc":[{"batl":[[2,5.2,48.02]],"ltp":4.9,"tv":6512.13,"id":12925630},{"trd":[[1.87,1973.18]],"batb":[[0,1.87,533.5]],"ltp":1.87,"tv":23058.85,"id":17336468}],"tv":37103.41}]}
{"op":"mcm","clk":"993159617","pt":1580560986073,"mc":[{"id":"1.168136214","rc":[{"trd":[[3.75,766.63],[3.8,1614.55]],"batb":[[0,3.75,63.97]],"batl":[[0,3.8,10.48]],"ltp":3.8,"tv":7583.83,"id":11981493}],"tv":37154.82}]}
{"op":"mcm","clk":"993159801","pt":1580560987097,"mc":[{"id":"1.168136214","rc":[{"batl":[[2,5.2,40.78]],"ltp":4.9,"tv":6512.13,"id":12925630},{"batl":[[0,3.8,23.57]],"ltp":3.8,"tv":7583.83,"id":11981493}]}]}
{"op":"mcm","clk":"993159994","pt":1580560988020,"mc":[{"id":"1.168136214","rc":[{"trd":[[1.87,1998.18]],"batb":[[0,1.87,521]],"ltp":1.87,"tv":23083.85,"id":17336468}],"tv":37179.82}]}
{"op":"mcm","clk":"993160232","pt":1580560989110,"mc":[{"id":"1.168136214","rc":[{"batb":[[1,4.8,53.42]],"ltp":4.9,"tv":6512.13,"id":12925630}]}]}
{"op":"mcm","clk":"993160439","pt":1580560990110,"mc":[{"id":"1.168136214","rc":[{"batb":[[0,1.87,546]],"ltp":1.87,"tv":23083.85,"id":17336468}]}]}
{"op":"mcm","clk":"993160847","pt":1580560992128,"mc":[{"id":"1.168136214","rc":[{"batb":[[0,4.9,16.11]],"ltp":4.9,"tv":6512.13,"id":12925630},{"trd":[[1.87,2198.18]],"batb":[[0,1.87,446]],"ltp":1.87,"tv":23283.85,"id":17336468}],"tv":37379.82}]}
{"op":"mcm","clk":"993161230","pt":1580560994114,"mc":[{"id":"1.168136214","rc":[{"batb":[[0,1.87,574]],"ltp":1.87,"tv":23283.85,"id":17336468}]}]}
{"op":"mcm","clk":"993161435","pt":1580560995126,"mc":[{"id":"1.168136214","rc":[{"trd":[[1.87,2228.18]],"batb":[[0,1.87,559]],"ltp":1.87,"tv":23313.85,"id":17336468}],"tv":37409.82}]}
{"op":"mcm","clk":"993161865","pt":1580560997104,"mc":[{"id":"1.168136214","rc":[{"trd":[[3.75,770.63]],"batb":[[0,3.75,61.97]],"ltp":3.75,"tv":7587.83,"id":11981493}],"tv":37413.82}]}
{"op":"mcm","clk":"993162636","pt":1580561001128,"mc":[{"id":"1.168136214","rc":[{"trd":[[3.75,810.63]],"batb":[[0,3.75,52.76]],"ltp":3.75,"tv":7627.83,"id":11981493}],"tv":37453.82}]}
{"op":"mcm","clk":"993163211","pt":1580561004042,"mc":[{"id":"1.168136214","rc":[{"trd":[[1.88,1532.13]],"batl":[[0,1.88,132.29]],"ltp":1.88,"tv":23323.85,"id":17336468}],"tv":37463.82}]}
{"op":"mcm","clk":"993163432","pt":1580561005127,"mc":[{"id":"1.168136214","rc":[{"batb":[[0,1.87,626.08]],"ltp":1.88,"tv":23323.85,"id":17336468},{"batb":[[0,3.75,61.76]],"ltp":3.75,"tv":7627.83,"id":11981493}]}]}
{"op":"mcm","clk":"993163616","pt":1580561006056,"mc":[{"id":"1.168136214","rc":[{"batl":[[0,1.88,132.09]],"ltp":1.88,"tv":23323.85,"id":17336468},{"batl":[[0,3.8,32.57]],"ltp":3.75,"tv":7627.83,"id":11981493}]}]}
{"op":"mcm","clk":"993164608","pt":1580561011052,"mc":[{"id":"1.168136214","rc":[{"batb":[[1,1.86,3141.66]],"batl":[[0,1.88,132.29]],"ltp":1.88,"tv":23323.85,"id":17336468}]}]}
{"op":"mcm","clk":"993166659","pt":1580561021082,"mc":[{"id":"1.168136214","rc":[{"trd":[[1.87,2291.8]],"batb":[[0,1.87,594.27]],"ltp":1.87,"tv":23387.47,"id":17336468}],"tv":37527.44}]}
{"op":"mcm","clk":"993167013","pt":1580561022983,"mc":[{"id":"1.168136214","rc":[{"trd":[[4.9,204.13]],"batb":[[0,4.8,53.42],[1,4.7,33.1],[2,4.6,109.31]],"ltp":4.9,"tv":6528.13,"id":12925630}],"tv":37543.44}]}
{"op":"mcm","clk":"993167800","pt":1580561027097,"mc":[{"id":"1.168136214","rc":[{"trd":[[1.87,2331.8]],"batb":[[0,1.87,574.27]],"ltp":1.87,"tv":23427.47,"id":17336468}],"tv":37583.44}]}
{"op":"mcm","clk":"993167985","pt":1580561028089,"mc":[{"id":"1.168136214","rc":[{"trd":[[1.88,1640.13]],"batl":[[0,1.88,13.2]],"ltp":1.88,"tv":23535.47,"id":17336468}],"tv":37691.44}]}
{"op":"mcm","clk":"993169298","pt":1580561035119,"mc":[{"id":"1.168136214","rc":[{"trd":[[1.88,1640.31]],"batl":[[0,1.88,13.11]],"ltp":1.88,"tv":23535.65,"id":17336468},{"trd":[[3.8,1614.73]],"batl":[[0,3.8,32.48]],"ltp":3.8,"tv":7628.01,"id":11981493}],"tv":37691.8}]}
{"op":"mcm","clk":"993169503","pt":1580561036126,"mc":[{"id":"1.168136214","rc":[{"batl":[[1,1.89,1158.12]],"ltp":1.88,"tv":23535.65,"id":17336468},{"trd":[[3.75,820.63]],"batb":[[0,3.75,56.76]],"ltp":3.75,"tv":7638.01,"id":11981493}],"tv":37701.8}]}
{"op":"mcm","clk":"993169651","pt":1580561036815,"mc":[{"id":"1.168136214","rc":[{"batb":[[1,1.86,3143.34]],"ltp":1.88,"tv":23535.65,"id":17336468}]}]}
{"op":"mcm","clk":"993170085","pt":1580561039102,"mc":[{"id":"1.168136214","rc":[{"batl":[[0,1.88,12.91]],"ltp":1.88,"tv":23535.65,"id":17336468},{"trd":[[3.75,830.63]],"batb":[[0,3.75,51.76]],"ltp":3.75,"tv":7648.01,"id":11981493}],"tv":37711.8}]}
{"op":"mcm","clk":"993171121","pt":1580561044137,"mc":[{"id":"1.168136214","rc":[{"trd":[[1.88,1666.13]],"batb":[[0,1.88,21.09],[1,1.87,574.27],[2,1.86,3143.34]],"batl":[[0,1.89,1158.12],[1,1.9,455],[2,1.91,83.22]],"ltp":1.88,"tv":23561.47,"id":17336468}],"tv":37737.62}]}
{"op":"mcm","clk":"993171340","pt":1580561045129,"mc":[{"id":"1.168136214","rc":[{"batb":[[0,4.8,59.42]],"ltp":4.9,"tv":6528.13,"id":12925630},{"trd":[[1.87,2340.8],[1.88,1714.15]],"batb":[[0,1.87,569.77],[1,1.86,3143.34],[2,1.85,1637.85]],"batl":[[0,1.89,1159.12]],"ltp":1.88,"tv":23618.49,"id":17336468},{"batb":[[0,3.75,65.76]],"batl":[[2,3.9,123.61]],"ltp":3.75,"tv":7648.01,"id":11981493}],"tv":37794.64}]}
{"op":"mcm","clk":"993171538","pt":1580561046122,"mc":[{"id":"1.168136214","rc":[{"trd":[[1.87,2350.8],[1.88,1792.21]],"batb":[[0,1.87,564.77]],"batl":[[0,1.88,187.73],[1,1.89,1106.12],[2,1.9,455]],"ltp":1.87,"tv":23706.55,"id":17336468}],"tv":37882.7}]}
{"op":"mcm","clk":"993171714","pt":1580561047150,"mc":[{"id":"1.168136214","rc":[{"trd":[[1.87,2360.8],[1.88,1800.33]],"batb":[[0,1.87,622.93],[2,1.85,1638.05]],"batl":[[0,1.88,3.94]],"ltp":1.87,"tv":23724.67,"id":17336468}],"tv":37900.82}]}
{"op":"mcm","clk":"993172085","pt":1580561049133,"mc":[{"id":"1.168136214","rc":[{"trd":[[3.75,840.63]],"batb":[[0,3.75,60.76]],"ltp":3.75,"tv":7658.01,"id":11981493}],"tv":37910.82}]}
{"op":"mcm","clk":"993172868","pt":1580561052746,"mc":[{"id":"1.168136214","rc":[{"trd":[[3.8,1614.87]],"batl":[[0,3.8,32.41]],"ltp":3.8,"tv":7658.16,"id":11981493}],"tv":37910.96}]}
{"op":"mcm","clk":"993173321","pt":1580561054939,"mc":[{"id":"1.168136214","rc":[{"trd":[[4.8,57.83]],"batb":[[0,4.8,57.43]],"ltp":4.8,"tv":6532.12,"id":12925630},{"trd":[[3.75,846.63]],"batb":[[0,3.75,57.76],[2,3.65,47.01]],"ltp":3.75,"tv":7664.16,"id":11981493}],"tv":37920.96}]}
{"op":"mcm","clk":"993174078","pt":1580561059048,"mc":[{"id":"1.168136214","rc":[{"trd":[[1.88,1808.21]],"batb":[[0,1.88,190.8],[1,1.87,622.93],[2,1.86,3156.29]],"batl":[[0,1.89,1106.12],[1,1.9,455],[2,1.91,83.22]],"ltp":1.88,"tv":23732.55,"id":17336468},{"trd":[[3.75,946.63]],"batb":[[0,3.75,7.76],[1,3.7,74.08]],"ltp":3.75,"tv":7764.16,"id":11981493}],"tv":38028.84}]}
{"op":"mcm","clk":"993174265","pt":1580561060140,"mc":[{"id":"1.168136214","rc":[{"batb":[[0,1.88,228.8]],"batl":[[1,1.9,681.18]],"ltp":1.88,"tv":23732.55,"id":17336468},{"batb":[[0,3.7,74.08],[1,3.65,47.01],[2,3.6,127.96]],"batl":[[0,3.75,63.05],[1,3.8,48.41],[2,3.85,46.24]],"ltp":3.75,"tv":7764.16,"id":11981493}]}]}
{"op":"mcm","clk":"993174395","pt":1580561060952,"mc":[{"id":"1.168136214","rc":[{"batb":[[0,4.9,16.43],[1,4.8,70.03],[2,4.7,33.1]],"ltp":4.8,"tv":6532.12,"id":12925630},{"batb":[[0,3.7,54.44],[2,3.6,146.97]],"ltp":3.75,"tv":7764.16,"id":11981493}]}]}
{"op":"mcm","clk":"993174610","pt":1580561062148,"mc":[{"id":"1.168136214","rc":[{"batb":[[0,4.9,41.54],[1,4.8,83.04]],"ltp":4.8,"tv":6532.12,"id":12925630},{"trd":[[1.88,1871.87]],"batb":[[0,1.88,201.97]],"ltp":1.88,"tv":23796.21,"id":17336468},{"trd":[[3.75,986.63]],"batb":[[1,3.65,60.53]],"batl":[[0,3.75,43.05]],"ltp":3.75,"tv":7804.16,"id":11981493}],"tv":38132.5}]}
{"op":"mcm","clk":"993174769","pt":1580561063053,"mc":[{"id":"1.168136214","rc":[{"trd":[[1.89,540.38]],"batl":[[0,1.89,1055.1]],"ltp":1.89,"tv":23898.25,"id":17336468}],"tv":38234.54}]}
{"op":"mcm","clk":"993174967","pt":1580561064138,"mc":[{"id":"1.168136214","rc":[{"batb":[[0,1.88,218.97]],"ltp":1.89,"tv":23898.25,"id":17336468},{"batb":[[0,3.7,104.44]],"ltp":3.75,"tv":7804.16,"id":11981493}]}]}
{"op":"mcm","clk":"993175145","pt":1580561065068,"mc":[{"id":"1.168136214","rc":[{"trd":[[1.88,1935.87]],"batb":[[0,1.88,148.97],[1,1.87,750.93]],"ltp":1.88,"tv":23962.25,"id":17336468},{"batb":[[2,3.6,216.83]],"batl":[[0,3.75,30]],"ltp":3.75,"tv":7804.16,"id":11981493}],"tv":38298.54}]}
{"op":"mcm","clk":"993175320","pt":1580561066152,"mc":[{"id":"1.168136214","rc":[{"batb":[[2,1.86,3162.29]],"batl":[[0,1.89,1060.1]],"ltp":1.88,"tv":23962.25,"id":17336468}]}]}
{"op":"mcm","clk":"993175477","pt":1580561067067,"mc":[{"id":"1.168136214","rc":[{"batb":[[0,1.88,22]],"ltp":1.88,"tv":23962.25,"id":17336468},{"batb":[[0,3.7,113.44]],"ltp":3.75,"tv":7804.16,"id":11981493}]}]}
{"op":"mcm","clk":"993175679","pt":1580561068153,"mc":[{"id":"1.168136214","rc":[{"batb":[[0,1.88,5]],"ltp":1.88,"tv":23962.25,"id":17336468}]}]}
{"op":"mcm","clk":"993176031","pt":1580561070061,"mc":[{"id":"1.168136214","rc":[{"trd":[[4.9,209.37]],"batb":[[0,4.9,38.92]],"ltp":4.9,"tv":6537.36,"id":12925630},{"trd":[[1.88,1939.87]],"batb":[[0,1.88,3]],"ltp":1.88,"tv":23966.25,"id":17336468},{"batl":[[0,3.75,33.38]],"ltp":3.75,"tv":7804.16,"id":11981493}],"tv":38307.78}]}
{"op":"mcm","clk":"993176361","pt":1580561072068,"mc":[{"id":"1.168136214","rc":[{"trd":[[5,132.13]],"batb":[[0,4.9,51.31]],"batl":[[0,5,48.55],[1,5.1,42.65]],"ltp":5.0,"tv":6549.62,"id":12925630},{"trd":[[1.87,2378.8],[1.88,1995.87]],"batb":[[0,1.87,716.93],[1,1.86,3162.29],[2,1.85,1638.05]],"ltp":1.87,"tv":24040.25,"id":17336468},{"batl":[[0,3.75,48.28]],"ltp":3.75,"tv":7804.16,"id":11981493}],"tv":38394.03}]}
{"op":"mcm","clk":"993176548","pt":1580561073058,"mc":[{"id":"1.168136214","rc":[{"batl":[[0,5,47.29]],"ltp":5.0,"tv":6549.62,"id":12925630},{"batb":[[0,1.87,718.93]],"batl":[[0,1.88,10],[1,1.89,1060.1],[2,1.9,681.18]],"ltp":1.87,"tv":24040.25,"id":17336468}]}]}
{"op":"mcm","clk":"993176766","pt":1580561074150,"mc":[{"id":"1.168136214","rc":[{"trd":[[1.88,1999.87]],"batl":[[0,1.88,8]],"ltp":1.88,"tv":24044.25,"id":17336468}],"tv":38398.03}]}
{"op":"mcm","clk":"993177168","pt":1580561076057,"mc":[{"id":"1.168136214","rc":[{"trd":[[3.7,429.21],[3.75,1000.19]],"batb":[[0,3.7,110.06]],"batl":[[0,3.75,38.12]],"ltp":3.75,"tv":7824.48,"id":11981493}],"tv":38418.35}]}
{"op":"mcm","clk":"993177339","pt":1580561076977,"mc":[{"id":"1.168136214","rc":[{"trd":[[1.87,2532.8]],"batb":[[0,1.87,641.93]],"batl":[[0,1.88,212.07]],"ltp":1.87,"tv":24198.25,"id":17336468},{"batl":[[0,3.75,23.22]],"ltp":3.75,"tv":7824.48,"id":11981493}],"tv":38572.35}]}
{"op":"mcm","clk":"993177537","pt":1580561078054,"mc":[{"id":"1.168136214","rc":[{"batb":[[2,4.7,95.54]],"ltp":5.0,"tv":6549.62,"id":12925630},{"trd":[[1.88,2074.27]],"batb":[[1,1.86,3149.34]],"batl":[[0,1.88,174.87],[1,1.89,1115.1]],"ltp":1.88,"tv":24272.65,"id":17336468},{"batb":[[2,3.6,127.96]],"ltp":3.75,"tv":7824.48,"id":11981493}],"tv":38646.75}]}
{"op":"mcm","clk":"993177673","pt":1580561078860,"mc":[{"id":"1.168136214","rc":[{"batb":[[2,4.7,33.1]],"ltp":5.0,"tv":6549.62,"id":12925630},{"batl":[[0,1.89,1060.1],[1,1.9,681.18],[2,1.91,83.22]],"ltp":1.88,"tv":24272.65,"id":17336468},{"batb":[[2,3.6,216.83]],"ltp":3.75,"tv":7824.48,"id":11981493}]}]}
{"op":"mcm","clk":"993177901","pt":1580561080152,"mc":[{"id":"1.168136214","rc":[{"trd":[[1.88,2086.27]],"batl":[[0,1.88,2],[1,1.89,1060.1],[2,1.9,681.18]],"ltp":1.88,"tv":24284.65,"id":17336468}],"tv":38658.75}]}
{"op":"mcm","clk":"993178053","pt":1580561081067,"mc":[{"id":"1.168136214","rc":[{"batl":[[1,1.89,1115.1]],"ltp":1.88,"tv":24284.65,"id":17336468}]}]}
{"op":"mcm","clk":"993178242","pt":1580561082095,"mc":[{"id":"1.168136214","rc":[{"batl":[[0,1.88,2.2]],"ltp":1.88,"tv":24284.65,"id":17336468}]}]}
{"op":"mcm","clk":"993178438","pt":1580561083129,"mc":[{"id":"1.168136214","rc":[{"batl":[[0,1.88,8.44]],"ltp":1.88,"tv":24284.65,"id":17336468}]}]}
{"op":"mcm","clk":"993178589","pt":1580561084094,"mc":[{"id":"1.168136214","rc":[{"trd":[[1.88,2103.15],[1.89,543.5]],"batl":[[0,1.89,1113.54],[1,1.9,681.18],[2,1.91,83.22]],"ltp":1.89,"tv":24304.65,"id":17336468},{"batb":[[0,3.7,120.06]],"ltp":3.75,"tv":7824.48,"id":11981493}],"tv":38678.75}]}
{"op":"mcm","clk":"993178740","pt":1580561084961,"mc":[{"id":"1.168136214","rc":[{"batl":[[0,1.89,1058.54]],"ltp":1.89,"tv":24304.65,"id":17336468},{"trd":[[3.7,441.21]],"batb":[[0,3.7,114.06]],"batl":[[0,3.75,39.85]],"ltp":3.7,"tv":7836.48,"id":11981493}],"tv":38690.75}]}
{"op":"mcm","clk":"993179163","pt":1580561087103,"mc":[{"id":"1.168136214","rc":[{"batl":[[0,1.88,500],[1,1.89,1058.54],[2,1.9,681.18]],"ltp":1.89,"tv":24304.65,"id":17336468}]}]}
{"op":"mcm","clk":"993179359","pt":1580561088071,"mc":[{"id":"1.168136214","rc":[{"batb":[[1,4.8,70.03]],"ltp":5.0,"tv":6549.62,"id":12925630},{"trd":[[1.87,2536.8]],"batb":[[0,1.87,585.25]],"batl":[[0,1.88,712],[1,1.89,1212.54]],"ltp":1.87,"tv":24308.65,"id":17336468},{"trd":[[3.75,1046.63]],"batb":[[0,3.75,39.85],[1,3.7,124.44],[2,3.65,79.37]],"batl":[[0,3.8,48.41],[1,3.85,46.24],[2,3.9,123.61]],"ltp":3.75,"tv":7882.92,"id":11981493}],"tv":38741.19}]}
{"op":"mcm","clk":"993179522","pt":1580561089103,"mc":[{"id":"1.168136214","rc":[{"batb":[[2,4.7,46.11]],"ltp":5.0,"tv":6549.62,"id":12925630},{"batb":[[0,3.75,64.85]],"batl":[[0,3.8,32.41]],"ltp":3.75,"tv":7882.92,"id":11981493}]}]}
{"op":"mcm","clk":"993179934","pt":1580561091128,"mc":[{"id":"1.168136214","rc":[{"batb":[[1,4.8,112.03]],"ltp":5.0,"tv":6549.62,"id":12925630},{"trd":[[1.88,2128.65]],"batl":[[0,1.88,699.25]],"ltp":1.88,"tv":24334.15,"id":17336468},{"batb":[[2,3.65,60.53]],"ltp":3.75,"tv":7882.92,"id":11981493}],"tv":38766.69}]}
{"op":"mcm","clk":"993180130","pt":1580561092031,"mc":[{"id":"1.168136214","rc":[{"batb":[[2,4.7,33.1]],"ltp":5.0,"tv":6549.62,"id":12925630},{"trd":[[1.87,2586.8]],"batb":[[0,1.87,560.25]],"ltp":1.87,"tv":24384.15,"id":17336468}],"tv":38816.69}]}
{"op":"mcm","clk":"993180331","pt":1580561093128,"mc":[{"id":"1.168136214","rc":[{"batl":[[0,1.88,704.25],[1,1.89,1207.54]],"ltp":1.87,"tv":24384.15,"id":17336468},{"batb":[[0,3.75,74.85]],"ltp":3.75,"tv":7882.92,"id":11981493}]}]}
{"op":"mcm","clk":"993180539","pt":1580561094103,"mc":[{"id":"1.168136214","rc":[{"trd":[[1.87,2652.8]],"batb":[[0,1.87,399.25]],"batl":[[2,1.9,694.21]],"ltp":1.87,"tv":24450.15,"id":17336468},{"batb":[[0,3.75,84.85]],"ltp":3.75,"tv":7882.92,"id":11981493}],"tv":38882.69}]}
{"op":"mcm","clk":"993180747","pt":1580561095101,"mc":[{"id":"1.168136214","rc":[{"batb":[[2,4.7,41.1]],"ltp":5.0,"tv":6549.62,"id":12925630},{"trd":[[1.87,2890.88]],"batb":[[0,1.86,3149.34],[1,1.85,1638.05],[2,1.84,124.77]],"batl":[[0,1.87,223.97],[1,1.88,704.25],[2,1.89,1207.54]],"ltp":1.87,"tv":24688.23,"id":17336468},{"trd":[[3.8,1679.7]],"batb":[[0,3.8,17.53],[1,3.75,118.32],[2,3.7,124.44]],"batl":[[0,3.85,46.24],[1,3.9,123.61],[2,3.95,16]],"ltp":3.8,"tv":7947.74,"id":11981493}],"tv":39185.6}]}
{"op":"mcm","clk":"993180947","pt":1580561096097,"mc":[{"id":"1.168136214","rc":[{"batb":[[0,4.9,38.92]],"ltp":5.0,"tv":6549.62,"id":12925630},{"trd":[[1.88,2133.65]],"batl":[[0,1.87,400],[1,1.88,701.75]],"ltp":1.88,"tv":24693.23,"id":17336468},{"trd":[[3.75,1055.57],[3.8,1714.76]],"batb":[[0,3.75,113.85],[1,3.7,124.44],[2,3.65,60.53]],"ltp":3.75,"tv":7991.74,"id":11981493}],"tv":39234.6}]}
{"op":"mcm","clk":"993181116","pt":1580561097121,"mc":[{"id":"1.168136214","rc":[{"batb":[[1,3.7,137.68]],"ltp":3.75,"tv":7991.74,"id":11981493}]}]}
{"op":"mcm","clk":"993181309","pt":1580561098101,"mc":[{"id":"1.168136214","rc":[{"batl":[[1,1.88,762.75]],"ltp":1.88,"tv":24693.23,"id":17336468},{"batb":[[2,3.65,147.72]],"ltp":3.75,"tv":7991.74,"id":11981493}]}]}
{"op":"mcm","clk":"993181509","pt":1580561099134,"mc":[{"id":"1.168136214","rc":[{"batl":[[0,3.85,56.24]],"ltp":3.75,"tv":7991.74,"id":11981493}]}]}
{"op":"mcm","clk":"993181699","pt":1580561100117,"mc":[{"id":"1.168136214","rc":[{"trd":[[1.86,756.53]],"batb":[[0,1.86,3144.47]],"batl":[[0,1.87,511.1],[2,1.89,1096.44]],"ltp":1.86,"tv":24702.97,"id":17336468},{"trd":[[3.8,1734.76]],"batb":[[0,3.8,30.71],[1,3.75,113.85],[2,3.7,137.68]],"ltp":3.8,"tv":8011.74,"id":11981493}],"tv":39264.34}]}
{"op":"mcm","clk":"993181940","pt":1580561101122,"mc":[{"id":"1.168136214","rc":[{"trd":[[1.87,2908.9]],"batb":[[0,1.86,3125.13]],"batl":[[0,1.87,756.65]],"ltp":1.87,"tv":24720.99,"id":17336468},{"batl":[[0,3.85,32.54]],"ltp":3.8,"tv":8011.74,"id":11981493}],"tv":39282.36}]}
{"op":"mcm","clk":"993182332","pt":1580561103128,"mc":[{"id":"1.168136214","rc":[{"trd":[[1.86,769.9],[1.87,2912.26]],"batb":[[0,1.86,3118.44]],"batl":[[0,1.87,754.97],[1,1.88,757.75]],"ltp":1.86,"tv":24737.73,"id":17336468}],"tv":39299.1}]}
{"op":"mcm","clk":"993182680","pt":1580561105153,"mc":[{"id":"1.168136214","rc":[{"batb":[[0,3.8,40.71]],"ltp":3.8,"tv":8011.74,"id":11981493}]}]}
{"op":"mcm","clk":"993182841","pt":1580561106040,"mc":[{"id":"1.168136214","rc":[{"trd":[[1.86,800.63]],"batb":[[0,1.86,3103.08]],"ltp":1.86,"tv":24768.45,"id":17336468}],"tv":39329.82}]}
{"op":"mcm","clk":"993183040","pt":1580561107054,"mc":[{"id":"1.168136214","rc":[{"trd":[[1.87,2919.98]],"batl":[[0,1.87,751.11]],"ltp":1.87,"tv":24776.18,"id":17336468},{"batb":[[1,3.75,93.85]],"ltp":3.8,"tv":8011.74,"id":11981493}],"tv":39337.55}]}
{"op":"mcm","clk":"993183402","pt":1580561109125,"mc":[{"id":"1.168136214","rc":[{"trd":[[1.86,910.63]],"batb":[[0,1.86,3048.08]],"ltp":1.86,"tv":24886.18,"id":17336468}],"tv":39447.55}]}
{"op":"mcm","clk":"993183555","pt":1580561110117,"mc":[{"id":"1.168136214","rc":[{"batl":[[1,1.88,787.87]],"ltp":1.86,"tv":24886.18,"id":17336468},{"batb":[[1,3.75,95.85]],"ltp":3.8,"tv":8011.74,"id":11981493}]}]}
{"op":"mcm","clk":"993183746","pt":1580561111153,"mc":[{"id":"1.168136214","rc":[{"trd":[[1.87,2920.18]],"batl":[[0,1.87,751.01],[1,1.88,798.55]],"ltp":1.87,"tv":24886.38,"id":17336468},{"batl":[[0,3.85,37.54]],"ltp":3.8,"tv":8011.74,"id":11981493}],"tv":39447.75}]}
{"op":"mcm","clk":"993183920","pt":1580561112092,"mc":[{"id":"1.168136214","rc":[{"batb":[[1,1.85,1639.73]],"ltp":1.87,"tv":24886.38,"id":17336468}]}]}
{"op":"mcm","clk":"993184083","pt":1580561113077,"mc":[{"id":"1.168136214","rc":[{"trd":[[3.8,1746.76]],"batb":[[0,3.8,34.71]],"ltp":3.8,"tv":8023.74,"id":11981493}],"tv":39459.75}]}
{"op":"mcm","clk":"993184208","pt":1580561113924,"mc":[{"id":"1.168136214","rc":[{"trd":[[1.86,915.67]],"batb":[[0,1.86,3045.56]],"ltp":1.86,"tv":24891.42,"id":17336468}],"tv":39464.79}]}
{"op":"mcm","clk":"993184536","pt":1580561116091,"mc":[{"id":"1.168136214","rc":[{"batb":[[0,3.8,60.07]],"ltp":3.8,"tv":8023.74,"id":11981493}]}]}
{"op":"mcm","clk":"993184704","pt":1580561117114,"mc":[{"id":"1.168136214","rc":[{"batl":[[0,1.87,751.21]],"ltp":1.86,"tv":24891.42,"id":17336468}]}]}
{"op":"mcm","clk":"993184866","pt":1580561117985,"mc":[{"id":"1.168136214","rc":[{"trd":[[5,138.13]],"batl":[[0,5,44.29]],"ltp":5.0,"tv":6555.62,"id":12925630},{"trd":[[1.86,915.87]],"batb":[[0,1.86,3047.46]],"ltp":1.86,"tv":24891.62,"id":17336468},{"batb":[[2,3.7,128.68]],"ltp":3.8,"tv":8023.74,"id":11981493}],"tv":39470.99}]}
{"op":"mcm","clk":"993185456","pt":1580561121097,"mc":[{"id":"1.168136214","rc":[{"trd":[[1.86,933.87]],"batb":[[0,1.86,3038.46]],"ltp":1.86,"tv":24909.62,"id":17336468}],"tv":39488.99}]}
{"op":"mcm","clk":"993185655","pt":1580561122118,"mc":[{"id":"1.168136214","rc":[{"trd":[[1.86,935.87],[1.87,2930.18]],"batb":[[0,1.86,3398.81]],"batl":[[0,1.87,746.21]],"ltp":1.86,"tv":24921.62,"id":17336468},{"batb":[[0,3.8,70.07],[2,3.7,118.68]],"ltp":3.8,"tv":8023.74,"id":11981493}],"tv":39500.99}]}
{"op":"mcm","clk":"993185817","pt":1580561123095,"mc":[{"id":"1.168136214","rc":[{"trd":[[4.9,219.37]],"batb":[[0,4.9,33.92]],"ltp":4.9,"tv":6565.62,"id":12925630},{"batl":[[0,1.87,749.42]],"ltp":1.86,"tv":24921.62,"id":17336468}],"tv":39510.99}]}
{"op":"mcm","clk":"993186131","pt":1580561125106,"mc":[{"id":"1.168136214","rc":[{"trd":[[1.87,3084.18]],"batl":[[0,1.87,672.42]],"ltp":1.87,"tv":25075.62,"id":17336468}],"tv":39664.99}]}
{"op":"mcm","clk":"993186294","pt":1580561126103,"mc":[{"id":"1.168136214","rc":[{"batl":[[0,1.87,417.86]],"ltp":1.87,"tv":25075.62,"id":17336468}]}]}
{"op":"mcm","clk":"993186635","pt":1580561127992,"mc":[{"id":"1.168136214","rc":[{"trd":[[1.86,946.57],[1.87,3114.4]],"batb":[[0,1.86,3393.46]],"batl":[[0,1.87,402.75]],"ltp":1.87,"tv":25116.54,"id":17336468}],"tv":39705.91}]}
{"op":"mcm","clk":"993186813","pt":1580561129122,"mc":[{"id":"1.168136214","rc":[{"trd":[[1.86,986.57]],"batb":[[0,1.86,3373.46]],"ltp":1.86,"tv":25156.54,"id":17336468}],"tv":39745.91}]}
{"op":"mcm","clk":"993186972","pt":1580561130104,"mc":[{"id":"1.168136214","rc":[{"trd":[[1.86,1430.57],[1.87,3114.6]],"batb":[[0,1.86,3151.46]],"batl":[[0,1.87,404.65]],"ltp":1.86,"tv":25600.74,"id":17336468}],"tv":40190.11}]}
{"op":"mcm","clk":"993187142","pt":1580561131130,"mc":[{"id":"1.168136214","rc":[{"batl":[[0,1.87,782.42]],"ltp":1.86,"tv":25600.74,"id":17336468}]}]}
{"op":"mcm","clk":"993187312","pt":1580561132108,"mc":[{"id":"1.168136214","rc":[{"trd":[[1.86,1440.57],[1.87,3124.6]],"batb":[[0,1.86,3146.46]],"batl":[[0,1.87,777.42]],"ltp":1.86,"tv":25620.74,"id":17336468},{"trd":[[3.85,1392.3]],"batl":[[0,3.85,2.54]],"ltp":3.85,"tv":8093.74,"id":11981493}],"tv":40280.11}]}
{"op":"mcm","clk":"993187495","pt":1580561133122,"mc":[{"id":"1.168136214","rc":[{"batl":[[1,1.88,313.8]],"ltp":1.86,"tv":25620.74,"id":17336468}]}]}
