{"op":"mcm","clk":"993324865","pt":1580540661667,"mc":[{"id":"1.168133548","rc":[{"batb":[[0,5.7,3.09],[1,5.6,14.95],[2,5.5,3]],"ltp":6.0,"tv":169.67,"id":17352128}]}]}
{"op":"mcm","clk":"993325080","pt":1580540666444,"mc":[{"id":"1.168133548","rc":[{"batb":[[0,5.8,3.65],[1,5.7,3.09]],"ltp":6.0,"tv":169.67,"id":17352128}]}]}
{"op":"mcm","clk":"993325267","pt":1580540671530,"mc":[{"id":"1.168133548","rc":[{"batb":[[1,5.5,3],[2,5.4,5.93]],"ltp":6.0,"tv":169.67,"id":17352128}]}]}
{"op":"mcm","clk":"993325577","pt":1580540679489,"mc":[{"id":"1.168133548","rc":[{"batb":[[1,5.5,6.21]],"ltp":6.0,"tv":169.67,"id":17352128}]}]}
{"op":"mcm","clk":"993325873","pt":1580540687504,"mc":[{"id":"1.168133548","rc":[{"batb":[[0,5.9,3.39],[1,5.6,3.65],[2,5.5,6.21]],"ltp":6.0,"tv":169.67,"id":17352128}]}]}
{"op":"mcm","clk":"993328133","pt":1580540740372,"mc":[{"id":"1.168133548","rc":[{"batb":[[0,5.9,7.04],[1,5.5,6.21],[2,5.4,5.93]],"ltp":6.0,"tv":169.67,"id":17352128}]}]}
{"op":"mcm","clk":"993328193","pt":1580540741976,"mc":[{"id":"1.168133548","rc":[{"batb":[[0,5.9,3.65]],"ltp":6.0,"tv":169.67,"id":17352128}]}]}
{"op":"mcm","clk":"993329304","pt":1580540766430,"mc":[{"id":"1.168133548","rc":[{"batb":[[0,5.7,52.8],[1,5.5,16.77],[2,5.2,2]],"ltp":5.8,"tv":903.07,"id":9417341},{"batb":[[1,9.6,10.18],[2,9.2,4.4]],"ltp":10.0,"tv":423.44,"id":10616006},{"batb":[[0,16.5,3.8]],"ltp":16.5,"tv":21.49,"id":9001159}]}]}
{"op":"mcm","clk":"993329606","pt":1580540771958,"mc":[{"id":"1.168133548","rc":[{"batb":[[0,5.6,3.65]],"ltp":6.0,"tv":169.67,"id":17352128}]}]}
{"op":"mcm","clk":"993330007","pt":1580540781320,"mc":[{"id":"1.168133548","rc":[{"batb":[[0,5.6,14.95]],"ltp":6.0,"tv":169.67,"id":17352128}]}]}
{"op":"mcm","clk":"993330063","pt":1580540782863,"mc":[{"id":"1.168133548","rc":[{"batb":[[1,5.5,3]],"ltp":6.0,"tv":169.67,"id":17352128}]}]}
{"op":"mcm","clk":"993330096","pt":1580540783839,"mc":[{"id":"1.168133548","rc":[{"trd":[[6.2,9.64]],"batb":[[0,6.2,2.76]],"ltp":6.2,"tv":124.15,"id":10170404}],"tv":2055.21}]}
{"op":"mcm","clk":"993330407","pt":1580540791474,"mc":[{"id":"1.168133548","rc":[{"batb":[[1,6,5.1]],"ltp":6.2,"tv":124.15,"id":10170404},{"batb":[[0,5.7,3.09],[1,5.6,14.95],[2,5.5,3]],"ltp":6.0,"tv":169.67,"id":17352128}]}]}
{"op":"mcm","clk":"993330409","pt":1580540791578,"mc":[{"id":"1.168133548","rc":[{"batl":[[2,60,9.17]],"ltp":18.5,"tv":29.72,"id":9193530}]}]}
{"op":"mcm","clk":"993330580","pt":1580540795443,"mc":[{"id":"1.168133548","rc":[{"batb":[[0,5.7,14.2],[1,5.6,3.65]],"ltp":6.0,"tv":169.67,"id":17352128}]}]}
{"op":"mcm","clk":"993330808","pt":1580540801570,"mc":[{"id":"1.168133548","rc":[{"batl":[[0,6.2,2],[1,6.4,2.69],[2,6.6,3.21]],"ltp":6.0,"tv":169.67,"id":17352128}]}]}
{"op":"mcm","clk":"993330874","pt":1580540802959,"mc":[{"id":"1.168133548","rc":[{"batb":[[0,5.7,17.85],[1,5.5,3],[2,5.4,5.93]],"ltp":6.0,"tv":169.67,"id":17352128}]}]}
{"op":"mcm","clk":"993331132","pt":1580540809295,"mc":[{"id":"1.168133548","rc":[{"batb":[[0,5.7,6.74]],"ltp":6.0,"tv":169.67,"id":17352128}]}]}
{"op":"mcm","clk":"993331359","pt":1580540816506,"mc":[{"id":"1.168133548","rc":[{"batb":[[0,5.7,3.65]],"ltp":6.0,"tv":169.67,"id":17352128}]}]}
{"op":"mcm","clk":"993331464","pt":1580540819492,"mc":[{"id":"1.168133548","rc":[{"batl":[[0,6.2,3.98],[2,7,10]],"ltp":6.0,"tv":169.67,"id":17352128}]}]}
{"op":"mcm","clk":"993331520","pt":1580540820937,"mc":[{"id":"1.168133548","rc":[{"batl":[[0,6,3],[1,6.2,20.62],[2,6.8,102.79]],"ltp":5.9,"tv":138.17,"id":8231803}]}]}
{"op":"mcm","clk":"993331657","pt":1580540824507,"mc":[{"id":"1.168133548","rc":[{"trd":[[10.5,25.26]],"batl":[[0,11,1],[1,11.5,33],[2,12.5,1.18]],"ltp":10.5,"tv":435.8,"id":10616006},{"batb":[[0,6.2,12.98]],"ltp":6.2,"tv":124.15,"id":10170404},{"batb":[[0,5.7,14.75]],"ltp":6.0,"tv":169.67,"id":17352128}],"tv":2067.57}]}
{"op":"mcm","clk":"993331708","pt":1580540825493,"mc":[{"id":"1.168133548","rc":[{"batb":[[0,5.8,3.04],[1,5.7,14.75],[2,5.5,3]],"ltp":6.0,"tv":169.67,"id":17352128}]}]}
{"op":"mcm","clk":"993331733","pt":1580540826115,"mc":[{"id":"1.168133548","rc":[{"batb":[[1,6,2.16]],"ltp":6.2,"tv":124.15,"id":10170404}]}]}
{"op":"mcm","clk":"993332030","pt":1580540834543,"mc":[{"id":"1.168133548","rc":[{"trd":[[6.4,19.48]],"batl":[[0,6.4,2.24]],"ltp":6.4,"tv":129.66,"id":10170404},{"batb":[[1,5.7,11.11]],"ltp":6.0,"tv":169.67,"id":17352128}],"tv":2073.09}]}
{"op":"mcm","clk":"993332037","pt":1580540834646,"mc":[{"id":"1.168133548","rc":[{"batb":[[0,5.8,6.69]],"ltp":6.0,"tv":169.67,"id":17352128}]}]}
{"op":"mcm","clk":"993332225","pt":1580540838513,"mc":[{"id":"1.168133548","rc":[{"batb":[[0,6.2,2.76]],"ltp":6.4,"tv":129.66,"id":10170404},{"batb":[[1,5.5,3],[2,5.4,5.93]],"ltp":6.0,"tv":169.67,"id":17352128}]}]}
{"op":"mcm","clk":"993332392","pt":1580540842108,"mc":[{"id":"1.168133548","rc":[{"batb":[[0,5.8,3.65]],"ltp":6.0,"tv":169.67,"id":17352128}]}]}
{"op":"mcm","clk":"993332706","pt":1580540850420,"mc":[{"id":"1.168133548","rc":[{"batb":[[1,5.5,6.21]],"ltp":6.0,"tv":169.67,"id":17352128}]}]}
{"op":"mcm","clk":"993343014","pt":1580540864473,"mc":[{"id":"1.168133548","rc":[{"batb":[[0,5.6,3.65]],"ltp":6.0,"tv":169.67,"id":17352128}]}]}
{"op":"mcm","clk":"993343113","pt":1580540867358,"mc":[{"id":"1.168133548","rc":[{"batb":[[0,5.6,14.95]],"ltp":6.0,"tv":169.67,"id":17352128}]}]}
{"op":"mcm","clk":"993343433","pt":1580540875493,"mc":[{"id":"1.168133548","rc":[{"batb":[[1,5.5,3]],"ltp":6.0,"tv":169.67,"id":17352128}]}]}
{"op":"mcm","clk":"993343800","pt":1580540882487,"mc":[{"id":"1.168133548","rc":[{"batb":[[0,5.7,3.09],[1,5.6,14.95],[2,5.5,3]],"ltp":6.0,"tv":169.67,"id":17352128}]}]}
{"op":"mcm","clk":"993344234","pt":1580540891490,"mc":[{"id":"1.168133548","rc":[{"batb":[[0,10.5,2],[1,10,13.84],[2,9.6,10.18]],"ltp":10.5,"tv":435.8,"id":10616006}]}]}
{"op":"mcm","clk":"993344361","pt":1580540894214,"mc":[{"id":"1.168133548","rc":[{"batb":[[0,5.7,6.74],[1,5.6,11.31]],"ltp":6.0,"tv":169.67,"id":17352128}]}]}
{"op":"mcm","clk":"993344410","pt":1580540895396,"mc":[{"id":"1.168133548","rc":[{"batb":[[1,5.5,3],[2,5.4,5.93]],"ltp":6.0,"tv":169.67,"id":17352128}]}]}
{"op":"mcm","clk":"993344547","pt":1580540898694,"mc":[{"id":"1.168133548","rc":[{"batb":[[0,5.7,3.65]],"ltp":6.0,"tv":169.67,"id":17352128}]}]}
{"op":"mcm","clk":"993344943","pt":1580540907425,"mc":[{"id":"1.168133548","rc":[{"batb":[[1,5.5,6.21]],"ltp":6.0,"tv":169.67,"id":17352128}]}]}
{"op":"mcm","clk":"993345693","pt":1580540924551,"mc":[{"id":"1.168133548","rc":[{"batb":[[0,5.6,3.65]],"ltp":6.0,"tv":169.67,"id":17352128}]}]}
{"op":"mcm","clk":"993346326","pt":1580540938367,"mc":[{"id":"1.168133548","rc":[{"batb":[[0,5.6,14.95]],"ltp":6.0,"tv":169.67,"id":17352128}]}]}
{"op":"mcm","clk":"993346461","pt":1580540941146,"mc":[{"id":"1.168133548","rc":[{"batb":[[1,5.5,3]],"ltp":6.0,"tv":169.67,"id":17352128}]}]}
{"op":"mcm","clk":"993346798","pt":1580540949062,"mc":[{"id":"1.168133548","rc":[{"batb":[[0,5.7,3.09],[1,5.6,14.95],[2,5.5,3]],"ltp":6.0,"tv":169.67,"id":17352128}]}]}
{"op":"mcm","clk":"993346989","pt":1580540953475,"mc":[{"id":"1.168133548","rc":[{"batb":[[0,5.7,14.2],[1,5.6,3.65]],"ltp":6.0,"tv":169.67,"id":17352128}]}]}
{"op":"mcm","clk":"993347153","pt":1580540956559,"mc":[{"id":"1.168133548","rc":[{"batb":[[0,5.7,17.85],[1,5.5,3],[2,5.4,5.93]],"ltp":6.0,"tv":169.67,"id":17352128}]}]}
{"op":"mcm","clk":"993347539","pt":1580540967391,"mc":[{"id":"1.168133548","rc":[{"batb":[[0,5.7,6.74]],"ltp":6.0,"tv":169.67,"id":17352128}]}]}
{"op":"mcm","clk":"993347737","pt":1580540972519,"mc":[{"id":"1.168133548","rc":[{"batb":[[0,5.7,3.65]],"ltp":6.0,"tv":169.67,"id":17352128}]}]}
{"op":"mcm","clk":"993348103","pt":1580540981522,"mc":[{"id":"1.168133548","rc":[{"batb":[[1,5.5,6.21]],"ltp":6.0,"tv":169.67,"id":17352128}]}]}
{"op":"mcm","clk":"993348429","pt":1580540988453,"mc":[{"id":"1.168133548","rc":[{"batb":[[0,5.6,3.65]],"ltp":6.0,"tv":169.67,"id":17352128}]}]}
{"op":"mcm","clk":"993348737","pt":1580540994519,"mc":[{"id":"1.168133548","rc":[{"batb":[[0,5.7,1],[1,5.6,3.65],[2,5.5,6.21]],"ltp":6.0,"tv":169.67,"id":17352128}]}]}
{"op":"mcm","clk":"993348762","pt":1580540995037,"mc":[{"id":"1.168133548","rc":[{"batb":[[0,5.6,3.65],[1,5.5,6.21],[2,5.4,5.93]],"ltp":6.0,"tv":169.67,"id":17352128}]}]}
{"op":"mcm","clk":"993348809","pt":1580540996322,"mc":[{"id":"1.168133548","rc":[{"batb":[[0,5.6,14.95]],"ltp":6.0,"tv":169.67,"id":17352128}]}]}
{"op":"mcm","clk":"993349013","pt":1580541000344,"mc":[{"id":"1.168133548","rc":[{"batb":[[1,5.5,3]],"ltp":6.0,"tv":169.67,"id":17352128}]}]}
{"op":"mcm","clk":"993349485","pt":1580541010493,"mc":[{"id":"1.168133548","rc":[{"batb":[[0,5.7,14.2],[1,5.6,3.65],[2,5.5,3]],"ltp":6.0,"tv":169.67,"id":17352128}]}]}
{"op":"mcm","clk":"993349910","pt":1580541019502,"mc":[{"id":"1.168133548","rc":[{"batb":[[0,5.7,17.85],[1,5.5,3],[2,5.4,5.93]],"ltp":6.0,"tv":169.67,"id":17352128}]}]}
{"op":"mcm","clk":"993350122","pt":1580541024394,"mc":[{"id":"1.168133548","rc":[{"batb":[[0,5.7,6.74]],"ltp":6.0,"tv":169.67,"id":17352128}]}]}
{"op":"mcm","clk":"993350363","pt":1580541029317,"mc":[{"id":"1.168133548","rc":[{"batb":[[0,5.7,3.65]],"ltp":6.0,"tv":169.67,"id":17352128}]}]}
{"op":"mcm","clk":"993350735","pt":1580541038817,"mc":[{"id":"1.168133548","rc":[{"batb":[[1,5.5,6.21]],"ltp":6.0,"tv":169.67,"id":17352128}]}]}
{"op":"mcm","clk":"993351011","pt":1580541044231,"mc":[{"id":"1.168133548","rc":[{"batb":[[0,5.6,3.65]],"ltp":6.0,"tv":169.67,"id":17352128}]}]}
{"op":"mcm","clk":"993351442","pt":1580541053453,"mc":[{"id":"1.168133548","rc":[{"batb":[[0,5.6,14.95]],"ltp":6.0,"tv":169.67,"id":17352128}]}]}
{"op":"mcm","clk":"993351601","pt":1580541056444,"mc":[{"id":"1.168133548","rc":[{"batb":[[1,5.5,3]],"ltp":6.0,"tv":169.67,"id":17352128}]}]}
{"op":"mcm","clk":"993351983","pt":1580541064960,"mc":[{"id":"1.168133548","rc":[{"batb":[[0,5.7,3.09],[1,5.6,14.95],[2,5.5,3]],"ltp":6.0,"tv":169.67,"id":17352128}]}]}
{"op":"mcm","clk":"993352095","pt":1580541067574,"mc":[{"id":"1.168133548","rc":[{"batb":[[1,5.6,11.31]],"ltp":6.0,"tv":169.67,"id":17352128}]}]}
{"op":"mcm","clk":"993352141","pt":1580541068531,"mc":[{"id":"1.168133548","rc":[{"batb":[[0,5.7,6.74]],"ltp":6.0,"tv":169.67,"id":17352128}]}]}
{"op":"mcm","clk":"993352213","pt":1580541070445,"mc":[{"id":"1.168133548","rc":[{"batb":[[1,5.5,3],[2,5.4,5.93]],"ltp":6.0,"tv":169.67,"id":17352128}]}]}
{"op":"mcm","clk":"993352325","pt":1580541073539,"mc":[{"id":"1.168133548","rc":[{"batb":[[0,5.7,3.65]],"ltp":6.0,"tv":169.67,"id":17352128}]}]}
{"op":"mcm","clk":"993352732","pt":1580541083461,"mc":[{"id":"1.168133548","rc":[{"batb":[[1,5.5,6.21]],"ltp":6.0,"tv":169.67,"id":17352128}]}]}
{"op":"mcm","clk":"993353098","pt":1580541092291,"mc":[{"id":"1.168133548","rc":[{"batb":[[0,5.6,3.65]],"ltp":6.0,"tv":169.67,"id":17352128}]}]}
{"op":"mcm","clk":"993353414","pt":1580541099394,"mc":[{"id":"1.168133548","rc":[{"batb":[[0,5.6,14.95]],"ltp":6.0,"tv":169.67,"id":17352128}]}]}
{"op":"mcm","clk":"993353438","pt":1580541100010,"mc":[{"id":"1.168133548","rc":[{"batb":[[1,5.5,3]],"ltp":6.0,"tv":169.67,"id":17352128}]}]}
{"op":"mcm","clk":"993353754","pt":1580541107503,"mc":[{"id":"1.168133548","rc":[{"batb":[[0,5.7,3.09],[1,5.6,14.95],[2,5.5,3]],"ltp":6.0,"tv":169.67,"id":17352128}]}]}
{"op":"mcm","clk":"993353995","pt":1580541113494,"mc":[{"id":"1.168133548","rc":[{"batb":[[0,5.7,14.2],[1,5.6,3.65]],"ltp":6.0,"tv":169.67,"id":17352128}]}]}
{"op":"mcm","clk":"993354135","pt":1580541116525,"mc":[{"id":"1.168133548","rc":[{"batb":[[0,5.7,17.85],[1,5.5,3],[2,5.4,5.93]],"ltp":6.0,"tv":169.67,"id":17352128}]}]}
{"op":"mcm","clk":"993354674","pt":1580541128367,"mc":[{"id":"1.168133548","rc":[{"batb":[[0,5.7,6.74]],"ltp":6.0,"tv":169.67,"id":17352128}]}]}
{"op":"mcm","clk":"993354880","pt":1580541132545,"mc":[{"id":"1.168133548","rc":[{"batb":[[0,5.7,3.65]],"ltp":6.0,"tv":169.67,"id":17352128}]}]}
{"op":"mcm","clk":"993355206","pt":1580541140160,"mc":[{"id":"1.168133548","rc":[{"batb":[[0,5.6,3.65]],"ltp":6.0,"tv":169.67,"id":17352128}]}]}
{"op":"mcm","clk":"993355287","pt":1580541142469,"mc":[{"id":"1.168133548","rc":[{"batb":[[0,5.6,14.95]],"ltp":6.0,"tv":169.67,"id":17352128}]}]}
{"op":"mcm","clk":"993356932","pt":1580541176285,"mc":[{"id":"1.168133548","rc":[{"batb":[[0,5.7,3.51],[1,5.6,14.95],[2,5.5,3]],"ltp":6.0,"tv":169.67,"id":17352128}]}]}
{"op":"mcm","clk":"993357340","pt":1580541185515,"mc":[{"id":"1.168133548","rc":[{"batb":[[0,5.7,14.62],[1,5.6,3.65]],"ltp":6.0,"tv":169.67,"id":17352128}]}]}
{"op":"mcm","clk":"993357414","pt":1580541187214,"mc":[{"id":"1.168133548","rc":[{"batb":[[0,5.7,18.26],[1,5.5,3],[2,5.4,5.93]],"ltp":6.0,"tv":169.67,"id":17352128}]}]}
{"op":"mcm","clk":"993357958","pt":1580541199524,"mc":[{"id":"1.168133548","rc":[{"batb":[[0,5.7,7.16]],"ltp":6.0,"tv":169.67,"id":17352128}]}]}
{"op":"mcm","clk":"993359280","pt":1580541230389,"mc":[{"id":"1.168133548","rc":[{"batb":[[0,5.7,3.65]],"ltp":6.0,"tv":169.67,"id":17352128}]}]}
{"op":"mcm","clk":"993359315","pt":1580541231058,"mc":[{"id":"1.168133548","rc":[{"trd":[[11.5,26.52]],"batb":[[0,11,1.56],[1,8.8,2.88],[2,8.6,11.63]],"batl":[[0,13.5,29.85]],"ltp":11.5,"tv":65.36,"id":8429550}],"tv":2079.61}]}
{"op":"mcm","clk":"993359363","pt":1580541232347,"mc":[{"id":"1.168133548","rc":[{"batb":[[1,8.8,6.67]],"ltp":11.5,"tv":65.36,"id":8429550}]}]}
{"op":"mcm","clk":"993359463","pt":1580541234565,"mc":[{"id":"1.168133548","rc":[{"batb":[[1,9,3.62],[2,8.8,5.79]],"ltp":11.5,"tv":65.36,"id":8429550},{"batb":[[0,5.8,4.26],[1,5.7,52.8],[2,5.5,16.77]],"ltp":5.8,"tv":903.07,"id":9417341},{"batb":[[0,5.9,6.66]],"ltp":5.9,"tv":138.17,"id":8231803},{"batb":[[0,6.2,6.75]],"ltp":6.4,"tv":129.66,"id":10170404},{"batb":[[1,9.2,4.4]],"ltp":9.0,"tv":186.62,"id":15608820},{"batb":[[0,18.5,2.71]],"ltp":18.5,"tv":29.72,"id":9193530},{"batb":[[0,5.8,4.26],[1,5.7,3.65],[2,5.5,3]],"ltp":6.0,"tv":169.67,"id":17352128}]}]}
{"op":"mcm","clk":"993359502","pt":1580541235542,"mc":[{"id":"1.168133548","rc":[{"batb":[[1,9.2,2.52],[2,9,3.08]],"ltp":11.5,"tv":65.36,"id":8429550},{"batb":[[0,10.5,4.82]],"ltp":10.5,"tv":435.8,"id":10616006},{"batb":[[0,17,1.45],[1,16.5,3.8],[2,16,7.1]],"ltp":16.5,"tv":21.49,"id":9001159},{"batb":[[0,5.8,7.9],[1,5.5,3],[2,5.4,5.93]],"ltp":6.0,"tv":169.67,"id":17352128}]}]}
{"op":"mcm","clk":"993359534","pt":1580541236362,"mc":[{"id":"1.168133548","rc":[{"batb":[[1,9.4,1.34],[2,9.2,2.52]],"ltp":11.5,"tv":65.36,"id":8429550}]}]}
{"op":"mcm","clk":"993359566","pt":1580541236980,"mc":[{"id":"1.168133548","rc":[{"batl":[[0,12.5,4.74],[1,13.5,29.11],[2,17.5,5.29]],"ltp":11.5,"tv":65.36,"id":8429550}]}]}
{"op":"mcm","clk":"993359699","pt":1580541240292,"mc":[{"id":"1.168133548","rc":[{"batb":[[1,9.6,3.86],[2,9.4,1.34]],"ltp":11.5,"tv":65.36,"id":8429550}]}]}
{"op":"mcm","clk":"993359802","pt":1580541242468,"mc":[{"id":"1.168133548","rc":[{"batb":[[1,9.8,6.46],[2,9.6,3.86]],"ltp":11.5,"tv":65.36,"id":8429550},{"batb":[[1,5.9,4.4],[2,5.1,5.35]],"ltp":6.4,"tv":129.66,"id":10170404},{"batb":[[0,18.5,6.14],[1,18,1.85]],"ltp":18.5,"tv":29.72,"id":9193530}]}]}
{"op":"mcm","clk":"993359839","pt":1580541243188,"mc":[{"id":"1.168133548","rc":[{"batb":[[2,9.6,4.17]],"ltp":11.5,"tv":65.36,"id":8429550},{"trd":[[6.4,23.96]],"batl":[[0,6.6,2.18],[1,6.8,2],[2,7,22.64]],"ltp":6.4,"tv":134.15,"id":10170404}],"tv":2084.09}]}
{"op":"mcm","clk":"993360149","pt":1580541249076,"mc":[{"id":"1.168133548","rc":[{"batb":[[1,5.5,6.21]],"ltp":6.0,"tv":169.67,"id":17352128}]}]}
{"op":"mcm","clk":"993360226","pt":1580541250472,"mc":[{"id":"1.168133548","rc":[{"batb":[[1,10,1.59],[2,9.8,6.46]],"ltp":11.5,"tv":65.36,"id":8429550}]}]}
{"op":"mcm","clk":"993360567","pt":1580541257294,"mc":[{"id":"1.168133548","rc":[{"batb":[[2,9.6,4.17]],"ltp":11.5,"tv":65.36,"id":8429550}]}]}
{"op":"mcm","clk":"993360689","pt":1580541259283,"mc":[{"id":"1.168133548","rc":[{"batb":[[1,10.5,1.98],[2,10,1.59]],"ltp":11.5,"tv":65.36,"id":8429550}]}]}
{"op":"mcm","clk":"993361896","pt":1580541283121,"mc":[{"id":"1.168133548","rc":[{"batb":[[0,9.6,1.64],[1,9.4,3.81],[2,9.2,2.68]],"ltp":9.0,"tv":186.62,"id":15608820}]}]}
{"op":"mcm","clk":"993362804","pt":1580541302054,"mc":[{"id":"1.168133548","rc":[{"batb":[[0,19,1.75],[1,18.5,6.14]],"ltp":18.5,"tv":29.72,"id":9193530}]}]}
{"op":"mcm","clk":"993363054","pt":1580541306551,"mc":[{"id":"1.168133548","rc":[{"batb":[[1,18.5,5.96]],"ltp":18.5,"tv":29.72,"id":9193530}]}]}
{"op":"mcm","clk":"993363063","pt":1580541306656,"mc":[{"id":"1.168133548","rc":[{"batb":[[0,19,1.92]],"ltp":18.5,"tv":29.72,"id":9193530}]}]}
{"op":"mcm","clk":"993363144","pt":1580541308457,"mc":[{"id":"1.168133548","rc":[{"batl":[[1,26,3.03]],"ltp":18.5,"tv":29.72,"id":9193530}]}]}
{"op":"mcm","clk":"993372616","pt":1580541487262,"mc":[{"id":"1.168133548","rc":[{"batb":[[2,9.4,1.66]],"ltp":11.5,"tv":65.36,"id":8429550}]}]}
{"op":"mcm","clk":"993373310","pt":1580541503287,"mc":[{"id":"1.168133548","rc":[{"batb":[[1,9.6,2.29],[2,9.4,1.34]],"ltp":11.5,"tv":65.36,"id":8429550}]}]}
{"op":"mcm","clk":"993373981","pt":1580541516441,"mc":[{"id":"1.168133548","rc":[{"batb":[[1,9.6,8.89]],"ltp":11.5,"tv":65.36,"id":8429550}]}]}
{"op":"mcm","clk":"993374536","pt":1580541527546,"mc":[{"id":"1.168133548","rc":[{"batb":[[1,9.8,1.29],[2,9.6,8.89]],"ltp":11.5,"tv":65.36,"id":8429550}]}]}
{"op":"mcm","clk":"993374725","pt":1580541531532,"mc":[{"id":"1.168133548","rc":[{"batb":[[1,9.8,9.55],[2,9.6,2.29]],"ltp":11.5,"tv":65.36,"id":8429550}]}]}
{"op":"mcm","clk":"993375215","pt":1580541541531,"mc":[{"id":"1.168133548","rc":[{"batb":[[2,8.8,4.64]],"ltp":11.5,"tv":65.36,"id":8429550}]}]}
{"op":"mcm","clk":"993375252","pt":1580541542159,"mc":[{"id":"1.168133548","rc":[{"batb":[[1,10,2.29],[2,9.8,9.55]],"ltp":11.5,"tv":65.36,"id":8429550}]}]}
{"op":"mcm","clk":"993375414","pt":1580541545569,"mc":[{"id":"1.168133548","rc":[{"batb":[[2,9.8,3.08]],"ltp":11.5,"tv":65.36,"id":8429550}]}]}
{"op":"mcm","clk":"993375485","pt":1580541547072,"mc":[{"id":"1.168133548","rc":[{"batb":[[2,9.8,1.29]],"ltp":11.5,"tv":65.36,"id":8429550}]}]}
{"op":"mcm","clk":"993375762","pt":1580541552254,"mc":[{"id":"1.168133548","rc":[{"batb":[[1,10.5,1.9],[2,10,2.29]],"ltp":11.5,"tv":65.36,"id":8429550}]}]}
{"op":"mcm","clk":"993376230","pt":1580541561984,"mc":[{"id":"1.168133548","rc":[{"batb":[[0,11,3.55],[2,9.8,1.59]],"ltp":11.5,"tv":65.36,"id":8429550}]}]}
{"op":"mcm","clk":"993378415","pt":1580541605935,"mc":[{"id":"1.168133548","rc":[{"batb":[[1,9.8,1.59],[2,9,2.5]],"ltp":11.5,"tv":65.36,"id":8429550}]}]}
{"op":"mcm","clk":"993379161","pt":1580541620274,"mc":[{"id":"1.168133548","rc":[{"batb":[[0,11,1.56],[1,10,2.29],[2,9.8,1.29]],"ltp":11.5,"tv":65.36,"id":8429550}]}]}
{"op":"mcm","clk":"993381223","pt":1580541663501,"mc":[{"id":"1.168133548","rc":[{"batb":[[1,10,1.98]],"ltp":11.5,"tv":65.36,"id":8429550}]}]}
{"op":"mcm","clk":"993382426","pt":1580541691567,"mc":[{"id":"1.168133548","rc":[{"trd":[[11.5,28],[12.5,6.98]],"batl":[[0,12.5,3.2]],"ltp":12.5,"tv":68.44,"id":8429550},{"trd":[[6,204.98]],"batl":[[0,6,5.29]],"ltp":6.0,"tv":909.07,"id":9417341},{"trd":[[6,10.54]],"batl":[[0,6.2,20.62],[1,6.8,102.79],[2,7,2]],"ltp":6.0,"tv":144.17,"id":8231803},{"trd":[[11,31.5],[11.5,44]],"batl":[[0,11.5,32.4],[1,12.5,1.18],[2,13.5,3]],"ltp":11.5,"tv":439.0,"id":10616006},{"trd":[[6.6,24],[6.8,9.58]],"batl":[[0,6.8,1.53],[1,7,22.64],[2,7.4,3]],"ltp":6.8,"tv":139.45,"id":10170404},{"trd":[[9.8,11.19]],"batl":[[0,9.8,8.71]],"ltp":9.8,"tv":190.3,"id":15608820},{"trd":[[25,1.42]],"batl":[[0,26,3.8],[1,60,9.17],[2,95,2]],"ltp":25.0,"tv":31.15,"id":9193530},{"trd":[[20,1.82]],"batl":[[0,20,7.09],[1,85,9.33],[2,95,2]],"ltp":20.0,"tv":23.31,"id":9001159},{"trd":[[6.2,17.63]],"batl":[[0,6.4,2.69],[1,7,10],[2,7.2,27]],"ltp":6.2,"tv":177.63,"id":17352128}],"tv":2122.55}]}
{"op":"mcm","clk":"993382560","pt":1580541694355,"mc":[{"id":"1.168133548","rc":[{"batb":[[0,5.9,6.6]],"ltp":6.0,"tv":144.17,"id":8231803},{"batl":[[1,85,9.15]],"ltp":20.0,"tv":23.31,"id":9001159}]}]}
{"op":"mcm","clk":"993382648","pt":1580541696467,"mc":[{"id":"1.168133548","rc":[{"batb":[[2,5.5,19.77]],"ltp":6.0,"tv":909.07,"id":9417341},{"batb":[[1,5.9,4.75],[2,5.1,5]],"ltp":6.8,"tv":139.45,"id":10170404}]}]}
{"op":"mcm","clk":"993382756","pt":1580541698377,"mc":[{"id":"1.168133548","rc":[{"batb":[[0,19,2.86]],"ltp":25.0,"tv":31.15,"id":9193530}]}]}
{"op":"mcm","clk":"993382807","pt":1580541699462,"mc":[{"id":"1.168133548","rc":[{"batb":[[0,5.8,7.26]],"ltp":6.0,"tv":909.07,"id":9417341},{"batl":[[1,6.8,4],[2,7,10]],"ltp":6.2,"tv":177.63,"id":17352128}]}]}
{"op":"mcm","clk":"993382932","pt":1580541702557,"mc":[{"id":"1.168133548","rc":[{"batb":[[1,18.5,2.54]],"ltp":25.0,"tv":31.15,"id":9193530}]}]}
{"op":"mcm","clk":"993382939","pt":1580541702663,"mc":[{"id":"1.168133548","rc":[{"batb":[[1,10,8.31]],"ltp":12.5,"tv":68.44,"id":8429550},{"batb":[[0,6.4,9.89],[1,6.2,6.75],[2,5.9,4.75]],"ltp":6.8,"tv":139.45,"id":10170404},{"batb":[[0,19,6.2]],"ltp":25.0,"tv":31.15,"id":9193530},{"batb":[[0,5.9,10.73],[1,5.8,7.9],[2,5.5,6.21]],"ltp":6.2,"tv":177.63,"id":17352128}]}]}
{"op":"mcm","clk":"993383017","pt":1580541704570,"mc":[{"id":"1.168133548","rc":[{"batb":[[1,10.5,1.51],[2,10,8.31]],"ltp":12.5,"tv":68.44,"id":8429550},{"batb":[[2,5.5,3]],"ltp":6.2,"tv":177.63,"id":17352128}]}]}
{"op":"mcm","clk":"993383278","pt":1580541709452,"mc":[{"id":"1.168133548","rc":[{"batb":[[0,19,8.2],[2,12,6.57]],"ltp":25.0,"tv":31.15,"id":9193530}]}]}
{"op":"mcm","clk":"993383446","pt":1580541712496,"mc":[{"id":"1.168133548","rc":[{"batb":[[1,10.5,3.19]],"ltp":12.5,"tv":68.44,"id":8429550},{"batb":[[2,16.5,1.07]],"ltp":25.0,"tv":31.15,"id":9193530},{"batb":[[0,17,4.48]],"ltp":20.0,"tv":23.31,"id":9001159},{"batb":[[0,5.9,13.72]],"ltp":6.2,"tv":177.63,"id":17352128}]}]}
{"op":"mcm","clk":"993383505","pt":1580541713489,"mc":[{"id":"1.168133548","rc":[{"batb":[[0,11.5,1.98],[1,11,4.59],[2,10.5,3.19]],"ltp":12.5,"tv":68.44,"id":8429550},{"batb":[[0,6.4,11.87],[1,6.2,4.76]],"ltp":6.8,"tv":139.45,"id":10170404},{"batb":[[0,17,5.09],[1,16.5,3.2]],"ltp":20.0,"tv":23.31,"id":9001159},{"batb":[[0,5.9,17.37],[1,5.8,4.26]],"batl":[[1,6.6,1.36],[2,6.8,4]],"ltp":6.2,"tv":177.63,"id":17352128}]}]}
{"op":"mcm","clk":"993383728","pt":1580541717474,"mc":[{"id":"1.168133548","rc":[{"batb":[[0,19,4.86]],"ltp":25.0,"tv":31.15,"id":9193530},{"batb":[[1,16,7.4],[2,15.5,1.91]],"ltp":20.0,"tv":23.31,"id":9001159},{"batb":[[0,5.9,6.64]],"ltp":6.2,"tv":177.63,"id":17352128}]}]}
{"op":"mcm","clk":"993383787","pt":1580541718402,"mc":[{"id":"1.168133548","rc":[{"batb":[[0,19.5,3.42],[1,19,4.69],[2,18.5,2.54]],"ltp":25.0,"tv":31.15,"id":9193530},{"batb":[[0,17.5,3.34],[1,17,4.48],[2,16,7.4]],"ltp":20.0,"tv":23.31,"id":9001159}]}]}
{"op":"mcm","clk":"993383836","pt":1580541719380,"mc":[{"id":"1.168133548","rc":[{"batb":[[2,10.5,1.51]],"ltp":12.5,"tv":68.44,"id":8429550},{"batb":[[0,5.9,3.65]],"ltp":6.2,"tv":177.63,"id":17352128}]}]}
{"op":"mcm","clk":"993384101","pt":1580541723374,"mc":[{"id":"1.168133548","rc":[{"batb":[[0,11.5,2.24]],"ltp":12.5,"tv":68.44,"id":8429550},{"batl":[[2,7,10]],"ltp":6.2,"tv":177.63,"id":17352128}]}]}
{"op":"mcm","clk":"993384172","pt":1580541724511,"mc":[{"id":"1.168133548","rc":[{"batb":[[0,5.9,6.66]],"ltp":6.0,"tv":144.17,"id":8231803}]}]}
{"op":"mcm","clk":"993384420","pt":1580541728394,"mc":[{"id":"1.168133548","rc":[{"batb":[[2,5.5,6.21]],"ltp":6.2,"tv":177.63,"id":17352128}]}]}
{"op":"mcm","clk":"993384951","pt":1580541738337,"mc":[{"id":"1.168133548","rc":[{"batb":[[0,19.5,4.32],[1,19,3.75]],"ltp":25.0,"tv":31.15,"id":9193530}]}]}
{"op":"mcm","clk":"993385327","pt":1580541746451,"mc":[{"id":"1.168133548","rc":[{"batb":[[1,17,1.45]],"ltp":20.0,"tv":23.31,"id":9001159},{"batl":[[1,7,10],[2,7.2,27]],"ltp":6.2,"tv":177.63,"id":17352128}]}]}
{"op":"mcm","clk":"993385373","pt":1580541747329,"mc":[{"id":"1.168133548","rc":[{"batl":[[1,6.8,1.32],[2,7,10]],"ltp":6.2,"tv":177.63,"id":17352128}]}]}
{"op":"mcm","clk":"993395447","pt":1580541753059,"mc":[{"id":"1.168133548","rc":[{"trd":[[19.5,2.21],[20,1.78]],"batb":[[0,19.5,2.32]],"ltp":19.5,"tv":35.14,"id":9193530}],"tv":2126.55}]}
{"op":"mcm","clk":"993395832","pt":1580541760532,"mc":[{"id":"1.168133548","rc":[{"batb":[[0,17,2.06],[1,16,7.4],[2,15.5,1.91]],"ltp":20.0,"tv":23.31,"id":9001159}]}]}
{"op":"mcm","clk":"993396175","pt":1580541767844,"mc":[{"id":"1.168133548","rc":[{"batb":[[0,6,3.33],[1,5.9,3.65],[2,5.8,4.26]],"ltp":6.2,"tv":177.63,"id":17352128}]}]}
{"op":"mcm","clk":"993396688","pt":1580541777171,"mc":[{"id":"1.168133548","rc":[{"batb":[[0,17,1.45],[1,16,8.01]],"ltp":20.0,"tv":23.31,"id":9001159}]}]}
{"op":"mcm","clk":"993397043","pt":1580541783989,"mc":[{"id":"1.168133548","rc":[{"batl":[[0,24,2],[1,26,3.8],[2,60,9.17]],"ltp":19.5,"tv":35.14,"id":9193530},{"batb":[[1,5.9,6.64]],"ltp":6.2,"tv":177.63,"id":17352128}]}]}
{"op":"mcm","clk":"993397469","pt":1580541791474,"mc":[{"id":"1.168133548","rc":[{"batl":[[0,26,3.8],[1,60,9.17],[2,95,2]],"ltp":19.5,"tv":35.14,"id":9193530}]}]}
{"op":"mcm","clk":"993397497","pt":1580541791989,"mc":[{"id":"1.168133548","rc":[{"batl":[[0,25,2.77],[1,26,3.03],[2,60,9.17]],"ltp":19.5,"tv":35.14,"id":9193530}]}]}
{"op":"mcm","clk":"993400399","pt":1580541844439,"mc":[{"id":"1.168133548","rc":[{"batb":[[0,6.6,2.61],[1,6.4,11.87],[2,6.2,3.98]],"ltp":6.8,"tv":139.45,"id":10170404},{"batb":[[0,19.5,3.2],[2,18.5,1.61]],"ltp":19.5,"tv":35.14,"id":9193530}]}]}
{"op":"mcm","clk":"993400604","pt":1580541847470,"mc":[{"id":"1.168133548","rc":[{"batl":[[2,7.6,3.35]],"ltp":6.8,"tv":139.45,"id":10170404}]}]}
{"op":"mcm","clk":"993400836","pt":1580541851484,"mc":[{"id":"1.168133548","rc":[{"batb":[[1,6.4,1.98]],"batl":[[2,7.6,6.35]],"ltp":6.8,"tv":139.45,"id":10170404},{"batb":[[0,19,4.63],[1,18.5,1.61],[2,12.5,2.16]],"ltp":19.5,"tv":35.14,"id":9193530}]}]}
{"op":"mcm","clk":"993401607","pt":1580541866385,"mc":[{"id":"1.168133548","rc":[{"trd":[[12.5,13.38]],"batl":[[0,13.5,29.11],[1,17.5,5.29],[2,20,8]],"ltp":12.5,"tv":74.84,"id":8429550},{"trd":[[16.5,4.57],[17,4.94]],"batb":[[0,16,7.1],[1,15.5,1.91],[2,13.5,7.41]],"batl":[[0,20,7.25]],"ltp":16.5,"tv":28.03,"id":9001159}],"tv":2137.67}]}
{"op":"mcm","clk":"993401827","pt":1580541870285,"mc":[{"id":"1.168133548","rc":[{"batb":[[0,16,6]],"ltp":16.5,"tv":28.03,"id":9001159}]}]}
{"op":"mcm","clk":"993402209","pt":1580541877507,"mc":[{"id":"1.168133548","rc":[{"batb":[[2,14,1.26]],"ltp":16.5,"tv":28.03,"id":9001159}]}]}
{"op":"mcm","clk":"993402336","pt":1580541879609,"mc":[{"id":"1.168133548","rc":[{"batl":[[0,20,8.07]],"ltp":16.5,"tv":28.03,"id":9001159}]}]}
{"op":"mcm","clk":"993402851","pt":1580541888397,"mc":[{"id":"1.168133548","rc":[{"batl":[[1,85,9]],"ltp":16.5,"tv":28.03,"id":9001159}]}]}
{"op":"mcm","clk":"993402887","pt":1580541889112,"mc":[{"id":"1.168133548","rc":[{"batl":[[0,19.5,1.24],[1,20,7.09],[2,85,9]],"ltp":16.5,"tv":28.03,"id":9001159}]}]}
{"op":"mcm","clk":"993403012","pt":1580541891330,"mc":[{"id":"1.168133548","rc":[{"batb":[[0,15.5,1.91],[1,14.5,6]],"ltp":16.5,"tv":28.03,"id":9001159}]}]}
{"op":"mcm","clk":"993403214","pt":1580541894422,"mc":[{"id":"1.168133548","rc":[{"batb":[[0,11.5,7.75]],"ltp":12.5,"tv":74.84,"id":8429550},{"batb":[[1,15,3.19],[2,14.5,6]],"ltp":16.5,"tv":28.03,"id":9001159}]}]}
{"op":"mcm","clk":"993403260","pt":1580541895043,"mc":[{"id":"1.168133548","rc":[{"batb":[[0,12,1.44],[1,11.5,7.75],[2,11,3.03]],"ltp":12.5,"tv":74.84,"id":8429550}]}]}
{"op":"mcm","clk":"993403631","pt":1580541901229,"mc":[{"id":"1.168133548","rc":[{"batb":[[0,15.5,2.93]],"ltp":16.5,"tv":28.03,"id":9001159}]}]}
{"op":"mcm","clk":"993404080","pt":1580541908437,"mc":[{"id":"1.168133548","rc":[{"batb":[[0,15.5,6.01],[1,14.5,6],[2,13.5,7.41]],"ltp":16.5,"tv":28.03,"id":9001159},{"batb":[[0,19,2.63],[2,16.5,2]],"ltp":19.5,"tv":35.14,"id":9193530}]}]}
{"op":"mcm","clk":"993404109","pt":1580541908849,"mc":[{"id":"1.168133548","rc":[{"batb":[[1,11.5,9.29]],"ltp":12.5,"tv":74.84,"id":8429550},{"batb":[[1,15,1.18],[2,14.5,6]],"ltp":16.5,"tv":28.03,"id":9001159}]}]}
{"op":"mcm","clk":"993404985","pt":1580541922564,"mc":[{"id":"1.168133548","rc":[{"batb":[[0,12,6.71],[1,11.5,3.78]],"ltp":12.5,"tv":74.84,"id":8429550}]}]}
{"op":"mcm","clk":"993405039","pt":1580541923450,"mc":[{"id":"1.168133548","rc":[{"batb":[[0,19,5.01]],"ltp":19.5,"tv":35.14,"id":9193530}]}]}
{"op":"mcm","clk":"993407678","pt":1580541963034,"mc":[{"id":"1.168133548","rc":[{"batb":[[1,11.5,3.52]],"ltp":12.5,"tv":74.84,"id":8429550}]}]}
{"op":"mcm","clk":"993414225","pt":1580542057544,"mc":[{"id":"1.168133548","rc":[{"trd":[[5.8,248.11]],"batb":[[0,5.8,4.26]],"ltp":5.8,"tv":915.07,"id":9417341}],"tv":2143.67}]}
{"op":"mcm","clk":"993414430","pt":1580542060544,"mc":[{"id":"1.168133548","rc":[{"batb":[[2,5.5,16.77]],"ltp":5.8,"tv":915.07,"id":9417341}]}]}
{"op":"mcm","clk":"993414674","pt":1580542064522,"mc":[{"id":"1.168133548","rc":[{"batl":[[2,7.2,2]],"ltp":6.8,"tv":139.45,"id":10170404}]}]}
{"op":"mcm","clk":"993415456","pt":1580542077355,"mc":[{"id":"1.168133548","rc":[{"batl":[[2,60,9.25]],"ltp":19.5,"tv":35.14,"id":9193530}]}]}
{"op":"mcm","clk":"993415506","pt":1580542078176,"mc":[{"id":"1.168133548","rc":[{"trd":[[10.5,33.26]],"batb":[[0,10,14.66],[1,9.6,10.18],[2,9.2,4.4]],"ltp":10.5,"tv":447.0,"id":10616006}],"tv":2151.67}]}
{"op":"mcm","clk":"993415579","pt":1580542079265,"mc":[{"id":"1.168133548","rc":[{"batb":[[0,12.5,1.29],[1,12,6.71],[2,11.5,3.52]],"ltp":12.5,"tv":74.84,"id":8429550}]}]}
{"op":"mcm","clk":"993415972","pt":1580542085480,"mc":[{"id":"1.168133548","rc":[{"batb":[[1,12,1.44]],"ltp":12.5,"tv":74.84,"id":8429550}]}]}
{"op":"mcm","clk":"993416053","pt":1580542086559,"mc":[{"id":"1.168133548","rc":[{"batb":[[2,11.5,1.98]],"ltp":12.5,"tv":74.84,"id":8429550},{"batl":[[2,85,9.08]],"ltp":16.5,"tv":28.03,"id":9001159}]}]}
{"op":"mcm","clk":"993416433","pt":1580542092691,"mc":[{"id":"1.168133548","rc":[{"trd":[[11.5,59.72]],"batl":[[0,11.5,24.54]],"ltp":11.5,"tv":462.72,"id":10616006}],"tv":2167.39}]}
{"op":"mcm","clk":"993416727","pt":1580542097389,"mc":[{"id":"1.168133548","rc":[{"batb":[[0,10.5,2.34],[1,10,13.84],[2,9.6,10.18]],"ltp":11.5,"tv":462.72,"id":10616006},{"batb":[[0,15.5,4.99]],"batl":[[0,20,7.51],[1,85,9.08],[2,95,2]],"ltp":16.5,"tv":28.03,"id":9001159}]}]}
{"op":"mcm","clk":"993418455","pt":1580542126515,"mc":[{"id":"1.168133548","rc":[{"batl":[[1,7,24.64],[2,7.6,6.35]],"ltp":6.8,"tv":139.45,"id":10170404}]}]}
{"op":"mcm","clk":"993419510","pt":1580542143555,"mc":[{"id":"1.168133548","rc":[{"batb":[[2,11.5,2.24]],"ltp":12.5,"tv":74.84,"id":8429550},{"trd":[[10.5,37.93]],"batb":[[0,10,13.84],[1,9.6,10.18],[2,9.2,4.4]],"batl":[[0,10.5,15.05],[1,11.5,24.54],[2,12.5,1.18]],"ltp":10.5,"tv":467.39,"id":10616006},{"batb":[[0,6.6,11.61]],"ltp":6.8,"tv":139.45,"id":10170404}],"tv":2172.06}]}
{"op":"mcm","clk":"993420415","pt":1580542158376,"mc":[{"id":"1.168133548","rc":[{"batb":[[0,10,15.1]],"ltp":10.5,"tv":467.39,"id":10616006}]}]}
{"op":"mcm","clk":"993420585","pt":1580542161278,"mc":[{"id":"1.168133548","rc":[{"batl":[[1,7,22.64],[2,7.2,2]],"ltp":6.8,"tv":139.45,"id":10170404}]}]}
{"op":"mcm","clk":"993420765","pt":1580542164385,"mc":[{"id":"1.168133548","rc":[{"batb":[[0,10,16.69]],"ltp":10.5,"tv":467.39,"id":10616006}]}]}
{"op":"mcm","clk":"993421341","pt":1580542173392,"mc":[{"id":"1.168133548","rc":[{"batl":[[1,6.8,100]],"ltp":6.0,"tv":144.17,"id":8231803}]}]}
{"op":"mcm","clk":"993424179","pt":1580542216542,"mc":[{"id":"1.168133548","rc":[{"trd":[[10.5,68.04]],"batb":[[0,10.5,13.51],[1,10,16.69],[2,9.6,10.18]],"batl":[[0,11.5,24.54],[1,12.5,1.18],[2,13.5,3]],"ltp":10.5,"tv":497.5,"id":10616006},{"trd":[[6.8,12.64],[7,81.96]],"batl":[[0,7.2,2.65],[1,7.6,6.35],[2,7.8,3]],"ltp":7.0,"tv":186.49,"id":10170404}],"tv":2249.21}]}
{"op":"mcm","clk":"993424554","pt":1580542221473,"mc":[{"id":"1.168133548","rc":[{"batb":[[0,10,16.69],[1,9.6,10.18],[2,9.2,4.4]],"ltp":10.5,"tv":497.5,"id":10616006}]}]}
{"op":"mcm","clk":"993424623","pt":1580542222467,"mc":[{"id":"1.168133548","rc":[{"trd":[[6,215.56]],"batl":[[0,6.4,32.16],[1,6.8,1.25],[2,11,3.26]],"ltp":6.0,"tv":925.65,"id":9417341},{"trd":[[6.2,41.6]],"batl":[[0,6.2,18.49]],"ltp":6.2,"tv":148.43,"id":8231803}],"tv":2264.05}]}
{"op":"mcm","clk":"993424692","pt":1580542223399,"mc":[{"id":"1.168133548","rc":[{"batb":[[2,5.5,19.77]],"ltp":6.0,"tv":925.65,"id":9417341}]}]}
{"op":"mcm","clk":"993425052","pt":1580542228483,"mc":[{"id":"1.168133548","rc":[{"batb":[[0,15.5,1.91]],"ltp":16.5,"tv":28.03,"id":9001159}]}]}
{"op":"mcm","clk":"993425136","pt":1580542229682,"mc":[{"id":"1.168133548","rc":[{"batb":[[0,10,15.1]],"ltp":10.5,"tv":497.5,"id":10616006}]}]}
{"op":"mcm","clk":"993425500","pt":1580542234492,"mc":[{"id":"1.168133548","rc":[{"batb":[[1,14.5,6],[2,13.5,7.41]],"ltp":16.5,"tv":28.03,"id":9001159}]}]}
{"op":"mcm","clk":"993425947","pt":1580542240228,"mc":[{"id":"1.168133548","rc":[{"batl":[[1,7.4,3.56],[2,7.6,6.35]],"ltp":7.0,"tv":186.49,"id":10170404}]}]}
{"op":"mcm","clk":"993426103","pt":1580542242496,"mc":[{"id":"1.168133548","rc":[{"batb":[[1,15,3.19],[2,14.5,6]],"ltp":16.5,"tv":28.03,"id":9001159}]}]}
{"op":"mcm","clk":"993426731","pt":1580542251518,"mc":[{"id":"1.168133548","rc":[{"batb":[[1,15,4.36]],"ltp":16.5,"tv":28.03,"id":9001159}]}]}
{"op":"mcm","clk":"993427122","pt":1580542256436,"mc":[{"id":"1.168133548","rc":[{"batb":[[1,15,1.18]],"ltp":16.5,"tv":28.03,"id":9001159}]}]}
{"op":"mcm","clk":"993427385","pt":1580542259542,"mc":[{"id":"1.168133548","rc":[{"batb":[[1,14.5,6],[2,13.5,7.41]],"ltp":16.5,"tv":28.03,"id":9001159}]}]}
{"op":"mcm","clk":"993427926","pt":1580542267073,"mc":[{"id":"1.168133548","rc":[{"batb":[[2,14,1.26]],"ltp":16.5,"tv":28.03,"id":9001159}]}]}
{"op":"mcm","clk":"993428242","pt":1580542271346,"mc":[{"id":"1.168133548","rc":[{"batb":[[1,15,3.19],[2,14.5,6]],"ltp":16.5,"tv":28.03,"id":9001159}]}]}
{"op":"mcm","clk":"993429151","pt":1580542282763,"mc":[{"id":"1.168133548","rc":[{"batb":[[1,15,4.36]],"ltp":16.5,"tv":28.03,"id":9001159}]}]}
{"op":"mcm","clk":"993429313","pt":1580542285395,"mc":[{"id":"1.168133548","rc":[{"batb":[[1,15,1.18]],"ltp":16.5,"tv":28.03,"id":9001159}]}]}
{"op":"mcm","clk":"993429840","pt":1580542290975,"mc":[{"id":"1.168133548","rc":[{"batb":[[1,14.5,6],[2,13.5,7.41]],"ltp":16.5,"tv":28.03,"id":9001159}]}]}
{"op":"mcm","clk":"993430561","pt":1580542299380,"mc":[{"id":"1.168133548","rc":[{"batb":[[1,15,3.19],[2,14.5,6]],"ltp":16.5,"tv":28.03,"id":9001159}]}]}
{"op":"mcm","clk":"993430643","pt":1580542300507,"mc":[{"id":"1.168133548","rc":[{"batb":[[1,15,4.36]],"ltp":16.5,"tv":28.03,"id":9001159}]}]}
{"op":"mcm","clk":"993431740","pt":1580542314400,"mc":[{"id":"1.168133548","rc":[{"batb":[[1,15,1.18]],"ltp":16.5,"tv":28.03,"id":9001159}]}]}
{"op":"mcm","clk":"993431759","pt":1580542314707,"mc":[{"id":"1.168133548","rc":[{"batb":[[1,14.5,6],[2,13.5,7.41]],"ltp":16.5,"tv":28.03,"id":9001159}]}]}
{"op":"mcm","clk":"993432447","pt":1580542322241,"mc":[{"id":"1.168133548","rc":[{"batb":[[2,14,1.26]],"ltp":16.5,"tv":28.03,"id":9001159}]}]}
{"op":"mcm","clk":"993432931","pt":1580542328423,"mc":[{"id":"1.168133548","rc":[{"batb":[[1,15,3.19],[2,14.5,6]],"ltp":16.5,"tv":28.03,"id":9001159}]}]}
{"op":"mcm","clk":"993433609","pt":1580542338537,"mc":[{"id":"1.168133548","rc":[{"batb":[[1,15,4.36]],"ltp":16.5,"tv":28.03,"id":9001159}]}]}
{"op":"mcm","clk":"993433894","pt":1580542342335,"mc":[{"id":"1.168133548","rc":[{"batb":[[1,15,1.18]],"ltp":16.5,"tv":28.03,"id":9001159}]}]}
{"op":"mcm","clk":"993434249","pt":1580542347545,"mc":[{"id":"1.168133548","rc":[{"batb":[[1,14.5,6],[2,13.5,7.41]],"ltp":16.5,"tv":28.03,"id":9001159}]}]}
{"op":"mcm","clk":"993434323","pt":1580542348777,"mc":[{"id":"1.168133548","rc":[{"batl":[[0,6.2,3.36],[1,6.4,32.16],[2,6.8,1.25]],"ltp":6.0,"tv":925.65,"id":9417341}]}]}
{"op":"mcm","clk":"993434397","pt":1580542349869,"mc":[{"id":"1.168133548","rc":[{"batl":[[0,6.4,32.16],[1,6.8,1.25],[2,11,3.26]],"ltp":6.0,"tv":925.65,"id":9417341}]}]}
{"op":"mcm","clk":"993434705","pt":1580542354956,"mc":[{"id":"1.168133548","rc":[{"batb":[[2,14,1.26]],"ltp":16.5,"tv":28.03,"id":9001159}]}]}
{"op":"mcm","clk":"993434826","pt":1580542357385,"mc":[{"id":"1.168133548","rc":[{"batb":[[1,15,3.19],[2,14.5,6]],"ltp":16.5,"tv":28.03,"id":9001159}]}]}
{"op":"mcm","clk":"993435555","pt":1580542369521,"mc":[{"id":"1.168133548","rc":[{"batb":[[1,15,4.36]],"ltp":16.5,"tv":28.03,"id":9001159}]}]}
{"op":"mcm","clk":"993435680","pt":1580542371480,"mc":[{"id":"1.168133548","rc":[{"batb":[[1,15,1.18]],"ltp":16.5,"tv":28.03,"id":9001159}]}]}
{"op":"mcm","clk":"993436077","pt":1580542377207,"mc":[{"id":"1.168133548","rc":[{"batb":[[1,14.5,6],[2,13.5,7.41]],"ltp":16.5,"tv":28.03,"id":9001159}]}]}
{"op":"mcm","clk":"993436292","pt":1580542380391,"mc":[{"id":"1.168133548","rc":[{"batl":[[1,6.8,102.5]],"ltp":6.2,"tv":148.43,"id":8231803}]}]}
{"op":"mcm","clk":"993436657","pt":1580542385444,"mc":[{"id":"1.168133548","rc":[{"batb":[[1,15,3.19],[2,14.5,6]],"ltp":16.5,"tv":28.03,"id":9001159}]}]}
{"op":"mcm","clk":"993437637","pt":1580542400476,"mc":[{"id":"1.168133548","rc":[{"batb":[[1,14.5,6],[2,13.5,7.41]],"ltp":16.5,"tv":28.03,"id":9001159}]}]}
{"op":"mcm","clk":"993437722","pt":1580542401566,"mc":[{"id":"1.168133548","rc":[{"batb":[[2,14,1.26]],"ltp":16.5,"tv":28.03,"id":9001159}]}]}
{"op":"mcm","clk":"993438290","pt":1580542410075,"mc":[{"id":"1.168133548","rc":[{"batb":[[2,5.5,16.85]],"ltp":6.0,"tv":925.65,"id":9417341}]}]}
{"op":"mcm","clk":"993438595","pt":1580542414379,"mc":[{"id":"1.168133548","rc":[{"batb":[[1,15,3.19],[2,14.5,6]],"ltp":16.5,"tv":28.03,"id":9001159}]}]}
{"op":"mcm","clk":"993439372","pt":1580542425162,"mc":[{"id":"1.168133548","rc":[{"batb":[[1,15,4.36]],"ltp":16.5,"tv":28.03,"id":9001159}]}]}
{"op":"mcm","clk":"993439580","pt":1580542428381,"mc":[{"id":"1.168133548","rc":[{"batb":[[1,15,1.18]],"ltp":16.5,"tv":28.03,"id":9001159}]}]}
{"op":"mcm","clk":"993439833","pt":1580542432680,"mc":[{"id":"1.168133548","rc":[{"batb":[[1,14.5,6],[2,13.5,7.41]],"ltp":16.5,"tv":28.03,"id":9001159}]}]}
{"op":"mcm","clk":"993440371","pt":1580542440493,"mc":[{"id":"1.168133548","rc":[{"batb":[[1,13.5,7.41],[2,12.5,1.41]],"ltp":16.5,"tv":28.03,"id":9001159}]}]}
{"op":"mcm","clk":"993440592","pt":1580542443526,"mc":[{"id":"1.168133548","rc":[{"batb":[[1,14,3.41],[2,13.5,7.41]],"ltp":16.5,"tv":28.03,"id":9001159}]}]}
{"op":"mcm","clk":"993441291","pt":1580542453447,"mc":[{"id":"1.168133548","rc":[{"batb":[[1,14,4.67]],"ltp":16.5,"tv":28.03,"id":9001159}]}]}
{"op":"mcm","clk":"993442182","pt":1580542466949,"mc":[{"id":"1.168133548","rc":[{"trd":[[11.5,67.72]],"batl":[[0,11.5,20.54]],"ltp":11.5,"tv":505.5,"id":10616006}],"tv":2272.05}]}
{"op":"mcm","clk":"993442493","pt":1580542471346,"mc":[{"id":"1.168133548","rc":[{"batl":[[2,13.5,6.46]],"ltp":11.5,"tv":505.5,"id":10616006}]}]}
{"op":"mcm","clk":"993442692","pt":1580542474246,"mc":[{"id":"1.168133548","rc":[{"batb":[[0,10.5,1.51],[1,10,15.1],[2,9.6,10.18]],"ltp":11.5,"tv":505.5,"id":10616006}]}]}
{"op":"mcm","clk":"993444491","pt":1580542501096,"mc":[{"id":"1.168133548","rc":[{"batl":[[1,6.8,100]],"ltp":6.2,"tv":148.43,"id":8231803}]}]}
{"op":"mcm","clk":"993445134","pt":1580542510339,"mc":[{"id":"1.168133548","rc":[{"batb":[[1,14,12.67]],"ltp":16.5,"tv":28.03,"id":9001159}]}]}
{"op":"mcm","clk":"993445449","pt":1580542514513,"mc":[{"id":"1.168133548","rc":[{"batb":[[1,14.5,3.3],[2,14,9.26]],"ltp":16.5,"tv":28.03,"id":9001159}]}]}
{"op":"mcm","clk":"993446553","pt":1580542530370,"mc":[{"id":"1.168133548","rc":[{"batb":[[0,6.8,5],[1,6.6,11.61],[2,6.4,1.98]],"ltp":7.0,"tv":186.49,"id":10170404}]}]}
{"op":"mcm","clk":"993446708","pt":1580542532336,"mc":[{"id":"1.168133548","rc":[{"trd":[[6.8,15.46]],"batb":[[0,6.8,3.59]],"ltp":6.8,"tv":189.31,"id":10170404}],"tv":2274.87}]}
{"op":"mcm","clk":"993446800","pt":1580542533473,"mc":[{"id":"1.168133548","rc":[{"batl":[[2,7.6,3.35]],"ltp":6.8,"tv":189.31,"id":10170404}]}]}
{"op":"mcm","clk":"993446884","pt":1580542534560,"mc":[{"id":"1.168133548","rc":[{"trd":[[6.8,18.28]],"batb":[[0,6.8,2.18]],"ltp":6.8,"tv":192.13,"id":10170404}],"tv":2277.69}]}
{"op":"mcm","clk":"993450587","pt":1580542586446,"mc":[{"id":"1.168133548","rc":[{"batl":[[0,20,7.35]],"ltp":16.5,"tv":28.03,"id":9001159}]}]}
{"op":"mcm","clk":"993454068","pt":1580542636925,"mc":[{"id":"1.168133548","rc":[{"trd":[[7,83.26],[7.2,11.89]],"batl":[[0,7.4,3.69],[1,7.6,3.35],[2,7.8,3]],"ltp":7.2,"tv":197.17,"id":10170404}],"tv":2282.73}]}
{"op":"mcm","clk":"993454169","pt":1580542638216,"mc":[{"id":"1.168133548","rc":[{"batb":[[2,6.4,2.33]],"ltp":7.2,"tv":197.17,"id":10170404}]}]}
{"op":"mcm","clk":"993468045","pt":1580542699416,"mc":[{"id":"1.168133548","rc":[{"batb":[[0,10,15.1],[1,9.6,10.18],[2,9.2,4.4]],"ltp":11.5,"tv":505.5,"id":10616006}]}]}
{"op":"mcm","clk":"993468916","pt":1580542716030,"mc":[{"id":"1.168133548","rc":[{"batl":[[0,13,80],[1,13.5,29.11],[2,17.5,5.29]],"ltp":12.5,"tv":74.84,"id":8429550}]}]}
{"op":"mcm","clk":"993472601","pt":1580542778525,"mc":[{"id":"1.168133548","rc":[{"trd":[[13,159.12]],"batl":[[0,13,2.44]],"ltp":13.0,"tv":229.96,"id":8429550}],"tv":2437.85}]}
{"op":"mcm","clk":"993472761","pt":1580542781330,"mc":[{"id":"1.168133548","rc":[{"batl":[[2,7,17.5]],"ltp":6.2,"tv":177.63,"id":17352128}]}]}
{"op":"mcm","clk":"993473203","pt":1580542789361,"mc":[{"id":"1.168133548","rc":[{"batb":[[2,5.5,20.85]],"ltp":6.0,"tv":925.65,"id":9417341}]}]}
{"op":"mcm","clk":"993473967","pt":1580542803115,"mc":[{"id":"1.168133548","rc":[{"batb":[[1,9.6,17.19]],"ltp":11.5,"tv":505.5,"id":10616006}]}]}
{"op":"mcm","clk":"993474433","pt":1580542811006,"mc":[{"id":"1.168133548","rc":[{"trd":[[10,214.22]],"batb":[[0,10,10.1]],"ltp":10.0,"tv":515.5,"id":10616006}],"tv":2447.85}]}
{"op":"mcm","clk":"993475557","pt":1580542829549,"mc":[{"id":"1.168133548","rc":[{"batl":[[0,11,1.45],[1,11.5,20.54],[2,12.5,1.18]],"ltp":10.0,"tv":515.5,"id":10616006}]}]}
{"op":"mcm","clk":"993476934","pt":1580542851557,"mc":[{"id":"1.168133548","rc":[{"batb":[[0,7,6],[1,6.8,2.18],[2,6.6,11.61]],"ltp":7.2,"tv":197.17,"id":10170404}]}]}
{"op":"mcm","clk":"993477282","pt":1580542858375,"mc":[{"id":"1.168133548","rc":[{"batb":[[0,19,2.63]],"ltp":19.5,"tv":35.14,"id":9193530}]}]}
{"op":"mcm","clk":"993477417","pt":1580542860487,"mc":[{"id":"1.168133548","rc":[{"batl":[[2,8.2,2]],"ltp":7.2,"tv":197.17,"id":10170404}]}]}
{"op":"mcm","clk":"993477589","pt":1580542863488,"mc":[{"id":"1.168133548","rc":[{"batb":[[0,18.5,2.49],[1,17,1.95]],"ltp":19.5,"tv":35.14,"id":9193530}]}]}
{"op":"mcm","clk":"993477641","pt":1580542864417,"mc":[{"id":"1.168133548","rc":[{"batl":[[2,8,3]],"ltp":7.2,"tv":197.17,"id":10170404}]}]}
{"op":"mcm","clk":"993478068","pt":1580542872226,"mc":[{"id":"1.168133548","rc":[{"batl":[[0,7.6,3.48],[1,8,3],[2,8.2,5]],"ltp":7.2,"tv":197.17,"id":10170404}]}]}
{"op":"mcm","clk":"993478121","pt":1580542873412,"mc":[{"id":"1.168133548","rc":[{"batb":[[1,17,4.61]],"ltp":19.5,"tv":35.14,"id":9193530}]}]}
{"op":"mcm","clk":"993478589","pt":1580542883129,"mc":[{"id":"1.168133548","rc":[{"trd":[[9.8,18.85]],"batl":[[0,9.8,4.88]],"ltp":9.8,"tv":197.97,"id":15608820}],"tv":2455.51}]}
{"op":"mcm","clk":"993479580","pt":1580542902954,"mc":[{"id":"1.168133548","rc":[{"trd":[[10,220.88]],"batb":[[0,10,6.77]],"batl":[[0,10.5,25],[1,11,1.45],[2,11.5,20.54]],"ltp":10.0,"tv":522.16,"id":10616006}],"tv":2462.17}]}
{"op":"mcm","clk":"993479691","pt":1580542904555,"mc":[{"id":"1.168133548","rc":[{"batl":[[0,7.6,3.35]],"ltp":7.2,"tv":197.17,"id":10170404}]}]}
{"op":"mcm","clk":"993479719","pt":1580542905072,"mc":[{"id":"1.168133548","rc":[{"batl":[[1,8,3.13]],"ltp":7.2,"tv":197.17,"id":10170404}]}]}
{"op":"mcm","clk":"993479789","pt":1580542906052,"mc":[{"id":"1.168133548","rc":[{"batb":[[1,9.6,13.38]],"ltp":10.0,"tv":522.16,"id":10616006}]}]}
{"op":"mcm","clk":"993480470","pt":1580542918490,"mc":[{"id":"1.168133548","rc":[{"trd":[[10.5,118.04]],"batb":[[0,10.5,23.73],[1,10,6.77],[2,9.6,13.38]],"batl":[[0,11,1.45],[1,11.5,20.54],[2,12.5,1.18]],"ltp":10.5,"tv":572.16,"id":10616006}],"tv":2512.18}]}
{"op":"mcm","clk":"993480545","pt":1580542919522,"mc":[{"id":"1.168133548","rc":[{"batl":[[0,11.5,20.54],[1,12.5,1.18],[2,13.5,6.46]],"ltp":10.5,"tv":572.16,"id":10616006}]}]}
{"op":"mcm","clk":"993480654","pt":1580542921122,"mc":[{"id":"1.168133548","rc":[{"batl":[[2,13.5,8.65]],"ltp":10.5,"tv":572.16,"id":10616006}]}]}
{"op":"mcm","clk":"993480792","pt":1580542923333,"mc":[{"id":"1.168133548","rc":[{"batb":[[0,10.5,6.45],[2,9.8,7.01]],"ltp":10.5,"tv":572.16,"id":10616006}]}]}
{"op":"mcm","clk":"993484710","pt":1580542983538,"mc":[{"id":"1.168133548","rc":[{"batb":[[0,7.2,2.39],[1,7,6],[2,6.8,2.18]],"ltp":7.2,"tv":197.17,"id":10170404}]}]}
{"op":"mcm","clk":"993485566","pt":1580542997578,"mc":[{"id":"1.168133548","rc":[{"trd":[[6,33.31]],"batb":[[0,6,1.33]],"ltp":6.0,"tv":181.63,"id":17352128}],"tv":2516.18}]}
{"op":"mcm","clk":"993485856","pt":1580543002381,"mc":[{"id":"1.168133548","rc":[{"trd":[[6.4,31.38]],"batb":[[0,6,11.88]],"batl":[[0,6.8,2.14],[1,7,17.5],[2,7.2,27]],"ltp":6.4,"tv":185.37,"id":17352128}],"tv":2519.92}]}
{"op":"mcm","clk":"993486028","pt":1580543005479,"mc":[{"id":"1.168133548","rc":[{"batl":[[1,6.8,104.31]],"ltp":6.2,"tv":148.43,"id":8231803}]}]}
{"op":"mcm","clk":"993486094","pt":1580543006668,"mc":[{"id":"1.168133548","rc":[{"batl":[[0,6.8,4.48]],"ltp":6.4,"tv":185.37,"id":17352128}]}]}
{"op":"mcm","clk":"993486199","pt":1580543008567,"mc":[{"id":"1.168133548","rc":[{"batb":[[0,6,10.55]],"ltp":6.4,"tv":185.37,"id":17352128}]}]}
{"op":"mcm","clk":"993486386","pt":1580543012551,"mc":[{"id":"1.168133548","rc":[{"batl":[[0,11,20],[1,11.5,20.54],[2,12.5,1.18]],"ltp":10.5,"tv":572.16,"id":10616006}]}]}
{"op":"mcm","clk":"993486524","pt":1580543015499,"mc":[{"id":"1.168133548","rc":[{"batl":[[1,8.2,2.13],[2,8.6,3]],"ltp":7.2,"tv":197.17,"id":10170404}]}]}
{"op":"mcm","clk":"993486568","pt":1580543016403,"mc":[{"id":"1.168133548","rc":[{"batl":[[2,9,5]],"ltp":7.2,"tv":197.17,"id":10170404},{"batb":[[0,5.9,6.64],[1,5.8,4.26],[2,5.5,7]],"ltp":6.4,"tv":185.37,"id":17352128}]}]}
{"op":"mcm","clk":"993486757","pt":1580543019481,"mc":[{"id":"1.168133548","rc":[{"batl":[[1,8.2,5.13],[2,8.4,3]],"ltp":7.2,"tv":197.17,"id":10170404}]}]}
{"op":"mcm","clk":"993487064","pt":1580543024498,"mc":[{"id":"1.168133548","rc":[{"batb":[[0,5.9,3.65]],"ltp":6.4,"tv":185.37,"id":17352128}]}]}
{"op":"mcm","clk":"993487484","pt":1580543032300,"mc":[{"id":"1.168133548","rc":[{"batb":[[2,5.6,3.15]],"ltp":6.4,"tv":185.37,"id":17352128}]}]}
{"op":"mcm","clk":"993488351","pt":1580543046744,"mc":[{"id":"1.168133548","rc":[{"batl":[[1,6.8,113.5]],"ltp":6.2,"tv":148.43,"id":8231803},{"batl":[[1,8.2,7.49]],"ltp":7.2,"tv":197.17,"id":10170404}]}]}
{"op":"mcm","clk":"993488880","pt":1580543056499,"mc":[{"id":"1.168133548","rc":[{"trd":[[11,71.49]],"batb":[[0,11,18.65],[1,10.5,6.45],[2,10,6.77]],"batl":[[0,11.5,20.54],[1,12.5,1.18],[2,13.5,11.97]],"ltp":11.0,"tv":612.16,"id":10616006},{"trd":[[7.6,8]],"batl":[[0,8.2,7.49],[1,8.4,7.34],[2,8.6,3]],"ltp":7.6,"tv":203.87,"id":10170404}],"tv":2566.61}]}
{"op":"mcm","clk":"993488997","pt":1580543058499,"mc":[{"id":"1.168133548","rc":[{"batl":[[0,8.2,5.13]],"ltp":7.6,"tv":203.87,"id":10170404}]}]}
{"op":"mcm","clk":"993489055","pt":1580543059483,"mc":[{"id":"1.168133548","rc":[{"batl":[[1,8.4,3]],"ltp":7.6,"tv":203.87,"id":10170404},{"batb":[[1,14,9.26],[2,13.5,7.41]],"ltp":16.5,"tv":28.03,"id":9001159},{"batb":[[1,17,1.95]],"ltp":19.5,"tv":35.14,"id":9193530}]}]}
{"op":"mcm","clk":"993489145","pt":1580543061528,"mc":[{"id":"1.168133548","rc":[{"batb":[[0,10.5,6.45],[1,10,6.77],[2,9.8,7.01]],"ltp":11.0,"tv":612.16,"id":10616006}]}]}
{"op":"mcm","clk":"993489217","pt":1580543062505,"mc":[{"id":"1.168133548","rc":[{"batb":[[1,10,10.34]],"ltp":11.0,"tv":612.16,"id":10616006},{"batl":[[0,8,2.13],[1,8.2,5],[2,8.4,3]],"ltp":7.6,"tv":203.87,"id":10170404}]}]}
{"op":"mcm","clk":"993489325","pt":1580543064443,"mc":[{"id":"1.168133548","rc":[{"batb":[[1,10,6.77]],"ltp":11.0,"tv":612.16,"id":10616006}]}]}
{"op":"mcm","clk":"993489492","pt":1580543067531,"mc":[{"id":"1.168133548","rc":[{"trd":[[15.5,3.81]],"batb":[[0,14,9.26],[1,13.5,7.41],[2,12,4.29]],"batl":[[0,20,7.96]],"ltp":15.5,"tv":31.84,"id":9001159}],"tv":2570.43}]}
{"op":"mcm","clk":"993489884","pt":1580543073544,"mc":[{"id":"1.168133548","rc":[{"batb":[[0,14.5,7.66],[1,14,9.26],[2,13.5,7.41]],"ltp":15.5,"tv":31.84,"id":9001159}]}]}
{"op":"mcm","clk":"993489898","pt":1580543073700,"mc":[{"id":"1.168133548","rc":[{"batb":[[2,6.8,7.07]],"batl":[[2,8.4,6.96]],"ltp":7.6,"tv":203.87,"id":10170404}]}]}
{"op":"mcm","clk":"993490813","pt":1580543087314,"mc":[{"id":"1.168133548","rc":[{"batb":[[0,7.2,19.98]],"ltp":7.6,"tv":203.87,"id":10170404}]}]}
{"op":"mcm","clk":"993492199","pt":1580543108560,"mc":[{"id":"1.168133548","rc":[{"batl":[[0,8,5.65],[2,8.4,3]],"ltp":7.6,"tv":203.87,"id":10170404}]}]}
{"op":"mcm","clk":"993492715","pt":1580543116510,"mc":[{"id":"1.168133548","rc":[{"batb":[[0,7.2,2.39]],"batl":[[0,8,3.65]],"ltp":7.6,"tv":203.87,"id":10170404},{"batb":[[1,17,8.34]],"ltp":19.5,"tv":35.14,"id":9193530}]}]}
{"op":"mcm","clk":"993493137","pt":1580543122392,"mc":[{"id":"1.168133548","rc":[{"batb":[[0,7.2,5.82]],"ltp":7.6,"tv":203.87,"id":10170404}]}]}
{"op":"mcm","clk":"993493677","pt":1580543130394,"mc":[{"id":"1.168133548","rc":[{"batb":[[1,17,1.95]],"ltp":19.5,"tv":35.14,"id":9193530}]}]}
{"op":"mcm","clk":"993493745","pt":1580543131424,"mc":[{"id":"1.168133548","rc":[{"batl":[[0,19.5,8.47],[1,20,7.09],[2,85,9.08]],"ltp":15.5,"tv":31.84,"id":9001159}]}]}
{"op":"mcm","clk":"993494424","pt":1580543141515,"mc":[{"id":"1.168133548","rc":[{"batl":[[0,19,2.57],[1,19.5,7.86],[2,20,7.09]],"ltp":15.5,"tv":31.84,"id":9001159}]}]}
{"op":"mcm","clk":"993494667","pt":1580543145419,"mc":[{"id":"1.168133548","rc":[{"batb":[[0,14,9.26],[1,13.5,7.41],[2,12,4.29]],"ltp":15.5,"tv":31.84,"id":9001159}]}]}
{"op":"mcm","clk":"993494685","pt":1580543145724,"mc":[{"id":"1.168133548","rc":[{"batb":[[1,17,8.34]],"ltp":19.5,"tv":35.14,"id":9193530}]}]}
{"op":"mcm","clk":"993495149","pt":1580543154517,"mc":[{"id":"1.168133548","rc":[{"batb":[[1,17,9.38]],"ltp":19.5,"tv":35.14,"id":9193530}]}]}
{"op":"mcm","clk":"993495459","pt":1580543159528,"mc":[{"id":"1.168133548","rc":[{"batb":[[1,17,2.99]],"ltp":19.5,"tv":35.14,"id":9193530}]}]}
{"op":"mcm","clk":"993495502","pt":1580543160341,"mc":[{"id":"1.168133548","rc":[{"batb":[[1,17.5,6.2],[2,17,2.99]],"ltp":19.5,"tv":35.14,"id":9193530}]}]}
{"op":"mcm","clk":"993495647","pt":1580543162548,"mc":[{"id":"1.168133548","rc":[{"batb":[[2,17,1.04]],"ltp":19.5,"tv":35.14,"id":9193530}]}]}
{"op":"mcm","clk":"993495722","pt":1580543163531,"mc":[{"id":"1.168133548","rc":[{"batb":[[1,18,1.85],[2,17.5,6.2]],"ltp":19.5,"tv":35.14,"id":9193530}]}]}
{"op":"mcm","clk":"993496074","pt":1580543169953,"mc":[{"id":"1.168133548","rc":[{"batl":[[0,9.8,9.88]],"ltp":9.8,"tv":197.97,"id":15608820}]}]}
{"op":"mcm","clk":"993496268","pt":1580543173441,"mc":[{"id":"1.168133548","rc":[{"batb":[[2,17,1.04]],"ltp":19.5,"tv":35.14,"id":9193530}]}]}
{"op":"mcm","clk":"993496529","pt":1580543177031,"mc":[{"id":"1.168133548","rc":[{"batb":[[2,16.5,2]],"ltp":19.5,"tv":35.14,"id":9193530}]}]}
{"op":"mcm","clk":"993496865","pt":1580543181142,"mc":[{"id":"1.168133548","rc":[{"batb":[[0,11,2],[1,10.5,6.45],[2,10,6.77]],"ltp":11.0,"tv":612.16,"id":10616006}]}]}
{"op":"mcm","clk":"993496945","pt":1580543182517,"mc":[{"id":"1.168133548","rc":[{"batl":[[0,9.8,4.88]],"ltp":9.8,"tv":197.97,"id":15608820}]}]}
{"op":"mcm","clk":"993498245","pt":1580543198456,"mc":[{"id":"1.168133548","rc":[{"trd":[[11.5,108.81]],"batb":[[0,11.5,5.37],[1,11,2],[2,10.5,6.45]],"batl":[[0,12.5,1.18],[1,13.5,11.97],[2,15,3.73]],"ltp":11.5,"tv":653.24,"id":10616006}],"tv":2611.51}]}
{"op":"mcm","clk":"993498314","pt":1580543199382,"mc":[{"id":"1.168133548","rc":[{"batl":[[2,14.5,6.18]],"ltp":11.5,"tv":653.24,"id":10616006}]}]}
{"op":"mcm","clk":"993498379","pt":1580543200367,"mc":[{"id":"1.168133548","rc":[{"batl":[[1,13.5,3],[2,15,3.73]],"ltp":11.5,"tv":653.24,"id":10616006}]}]}
{"op":"mcm","clk":"993498510","pt":1580543202483,"mc":[{"id":"1.168133548","rc":[{"batl":[[2,15,6.22]],"ltp":11.5,"tv":653.24,"id":10616006},{"batl":[[0,24,6.03],[1,25,2.77],[2,26,3.03]],"ltp":19.5,"tv":35.14,"id":9193530}]}]}
{"op":"mcm","clk":"993498769","pt":1580543204282,"mc":[{"id":"1.168133548","rc":[{"batb":[[0,11,2],[1,10.5,6.45],[2,10,12.21]],"ltp":11.5,"tv":653.24,"id":10616006}]}]}
{"op":"mcm","clk":"993499651","pt":1580543216571,"mc":[{"id":"1.168133548","rc":[{"batl":[[0,25,2.77],[1,26,3.03],[2,60,9.25]],"ltp":19.5,"tv":35.14,"id":9193530}]}]}
{"op":"mcm","clk":"993500116","pt":1580543222409,"mc":[{"id":"1.168133548","rc":[{"batb":[[1,17,1.95]],"ltp":19.5,"tv":35.14,"id":9193530}]}]}
{"op":"mcm","clk":"993500225","pt":1580543223909,"mc":[{"id":"1.168133548","rc":[{"batl":[[1,13,2],[2,13.5,3]],"ltp":11.5,"tv":653.24,"id":10616006}]}]}
{"op":"mcm","clk":"993500484","pt":1580543227310,"mc":[{"id":"1.168133548","rc":[{"batb":[[2,10,6.77]],"ltp":11.5,"tv":653.24,"id":10616006},{"batl":[[0,6.8,2.14]],"ltp":6.4,"tv":185.37,"id":17352128}]}]}
{"op":"mcm","clk":"993500562","pt":1580543228288,"mc":[{"id":"1.168133548","rc":[{"batl":[[0,12.5,3.18]],"ltp":11.5,"tv":653.24,"id":10616006}]}]}
{"op":"mcm","clk":"993504873","pt":1580543289105,"mc":[{"id":"1.168133548","rc":[{"batl":[[0,6.2,5],[1,6.4,32.16],[2,6.8,1.25]],"ltp":6.0,"tv":925.65,"id":9417341},{"trd":[[6,10.66]],"batb":[[0,5.9,6.6]],"batl":[[0,6,4.94],[1,6.2,18.49],[2,6.8,113.5]],"ltp":6.0,"tv":148.55,"id":8231803},{"trd":[[9.6,3.28]],"batb":[[0,9.4,3.81],[1,9.2,2.68],[2,8.8,2.01]],"batl":[[0,9.6,3.36],[1,9.8,4.88],[2,10,6.87]],"ltp":9.6,"tv":201.25,"id":15608820}],"tv":2614.91}]}
{"op":"mcm","clk":"993505792","pt":1580543302532,"mc":[{"id":"1.168133548","rc":[{"batb":[[1,17,8.34]],"ltp":19.5,"tv":35.14,"id":9193530},{"batb":[[0,5.9,25.11]],"ltp":6.4,"tv":185.37,"id":17352128}]}]}
{"op":"mcm","clk":"993506013","pt":1580543306307,"mc":[{"id":"1.168133548","rc":[{"batb":[[2,5.5,7]],"ltp":6.4,"tv":185.37,"id":17352128}]}]}
{"op":"mcm","clk":"993506507","pt":1580543314198,"mc":[{"id":"1.168133548","rc":[{"batb":[[1,17,9.38]],"ltp":19.5,"tv":35.14,"id":9193530},{"batb":[[0,6,2.94],[1,5.9,25.11],[2,5.8,4.26]],"ltp":6.4,"tv":185.37,"id":17352128}]}]}
{"op":"mcm","clk":"993506724","pt":1580543317540,"mc":[{"id":"1.168133548","rc":[{"batb":[[1,17,2.99]],"ltp":19.5,"tv":35.14,"id":9193530},{"batb":[[1,5.9,3.65]],"ltp":6.4,"tv":185.37,"id":17352128}]}]}
{"op":"mcm","clk":"993506731","pt":1580543317642,"mc":[{"id":"1.168133548","rc":[{"batb":[[1,17.5,6.2],[2,17,2.99]],"ltp":19.5,"tv":35.14,"id":9193530},{"batb":[[0,6,24.05]],"ltp":6.4,"tv":185.37,"id":17352128}]}]}
{"op":"mcm","clk":"993507322","pt":1580543326525,"mc":[{"id":"1.168133548","rc":[{"batb":[[0,7.4,6],[1,7.2,5.82],[2,7,6]],"ltp":7.6,"tv":203.87,"id":10170404}]}]}
{"op":"mcm","clk":"993507646","pt":1580543331460,"mc":[{"id":"1.168133548","rc":[{"batb":[[1,17,2.99],[2,16.5,2]],"ltp":19.5,"tv":35.14,"id":9193530},{"batb":[[0,6,2.94]],"ltp":6.4,"tv":185.37,"id":17352128}]}]}
{"op":"mcm","clk":"993508003","pt":1580543337334,"mc":[{"id":"1.168133548","rc":[{"batb":[[1,17,1.95]],"ltp":19.5,"tv":35.14,"id":9193530},{"batb":[[0,5.9,3.65],[1,5.8,4.26],[2,5.5,7]],"ltp":6.4,"tv":185.37,"id":17352128}]}]}
{"op":"mcm","clk":"993508372","pt":1580543343335,"mc":[{"id":"1.168133548","rc":[{"batl":[[1,8.2,2],[2,8.8,3]],"ltp":7.6,"tv":203.87,"id":10170404}]}]}
{"op":"mcm","clk":"993508446","pt":1580543344565,"mc":[{"id":"1.168133548","rc":[{"batl":[[2,9,5]],"ltp":7.6,"tv":203.87,"id":10170404}]}]}
{"op":"mcm","clk":"993508517","pt":1580543345551,"mc":[{"id":"1.168133548","rc":[{"batb":[[2,5.6,3.15]],"ltp":6.4,"tv":185.37,"id":17352128}]}]}
{"op":"mcm","clk":"993508658","pt":1580543347549,"mc":[{"id":"1.168133548","rc":[{"batl":[[2,8.4,3]],"ltp":7.6,"tv":203.87,"id":10170404}]}]}
{"op":"mcm","clk":"993509320","pt":1580543356178,"mc":[{"id":"1.168133548","rc":[{"batl":[[1,20,7.35],[2,25,10]],"ltp":15.5,"tv":31.84,"id":9001159}]}]}
{"op":"mcm","clk":"993509390","pt":1580543357362,"mc":[{"id":"1.168133548","rc":[{"batl":[[0,8.2,2.13],[1,8.4,3],[2,8.6,3]],"ltp":7.6,"tv":203.87,"id":10170404}]}]}
{"op":"mcm","clk":"993509937","pt":1580543366250,"mc":[{"id":"1.168133548","rc":[{"batl":[[0,9.6,8.24],[1,10,6.87],[2,12.5,20.42]],"ltp":9.6,"tv":201.25,"id":15608820}]}]}
{"op":"mcm","clk":"993510233","pt":1580543371782,"mc":[{"id":"1.168133548","rc":[{"batl":[[2,13,2.42]],"ltp":9.6,"tv":201.25,"id":15608820},{"batl":[[2,40,6]],"ltp":15.5,"tv":31.84,"id":9001159}]}]}
{"op":"mcm","clk":"993511412","pt":1580543390491,"mc":[{"id":"1.168133548","rc":[{"batl":[[2,8.6,6.03]],"ltp":7.6,"tv":203.87,"id":10170404}]}]}
{"op":"mcm","clk":"993512218","pt":1580543402319,"mc":[{"id":"1.168133548","rc":[{"batl":[[2,75,3.08]],"ltp":15.5,"tv":31.84,"id":9001159}]}]}
{"op":"mcm","clk":"993514162","pt":1580543430454,"mc":[{"id":"1.168133548","rc":[{"batl":[[0,8.2,5.16],[2,8.6,3]],"ltp":7.6,"tv":203.87,"id":10170404}]}]}
{"op":"mcm","clk":"993514272","pt":1580543432261,"mc":[{"id":"1.168133548","rc":[{"batl":[[2,85,9.08]],"ltp":15.5,"tv":31.84,"id":9001159}]}]}
{"op":"mcm","clk":"993516578","pt":1580543465385,"mc":[{"id":"1.168133548","rc":[{"batb":[[0,7.6,2.27],[1,7.4,6],[2,7.2,3.43]],"ltp":7.6,"tv":203.87,"id":10170404}]}]}
{"op":"mcm","clk":"993517026","pt":1580543471478,"mc":[{"id":"1.168133548","rc":[{"batl":[[1,9,5],[2,9.2,3]],"ltp":7.6,"tv":203.87,"id":10170404}]}]}
{"op":"mcm","clk":"993517094","pt":1580543472511,"mc":[{"id":"1.168133548","rc":[{"trd":[[5.8,256.11]],"batb":[[0,5.7,53.06],[1,5.5,23.79],[2,5.2,2]],"ltp":5.8,"tv":933.65,"id":9417341},{"batl":[[1,8.8,3.81],[2,9,9.56]],"ltp":7.6,"tv":203.87,"id":10170404}],"tv":2622.91}]}
{"op":"mcm","clk":"993517218","pt":1580543474315,"mc":[{"id":"1.168133548","rc":[{"batb":[[1,5.5,17.85]],"ltp":5.8,"tv":933.65,"id":9417341}]}]}
{"op":"mcm","clk":"993517286","pt":1580543475403,"mc":[{"id":"1.168133548","rc":[{"batl":[[1,8.6,3],[2,8.8,3.81]],"ltp":7.6,"tv":203.87,"id":10170404}]}]}
{"op":"mcm","clk":"993517350","pt":1580543476379,"mc":[{"id":"1.168133548","rc":[{"batl":[[2,8.8,6.81]],"ltp":7.6,"tv":203.87,"id":10170404}]}]}
{"op":"mcm","clk":"993518720","pt":1580543497546,"mc":[{"id":"1.168133548","rc":[{"batb":[[1,5.5,23.4]],"ltp":5.8,"tv":933.65,"id":9417341}]}]}
{"op":"mcm","clk":"993518828","pt":1580543499138,"mc":[{"id":"1.168133548","rc":[{"batb":[[1,5.5,26.76]],"ltp":5.8,"tv":933.65,"id":9417341}]}]}
{"op":"mcm","clk":"993520143","pt":1580543518471,"mc":[{"id":"1.168133548","rc":[{"batl":[[0,9.6,3.36],[1,9.8,4.88],[2,10,6.87]],"ltp":9.6,"tv":201.25,"id":15608820}]}]}
{"op":"mcm","clk":"993522173","pt":1580543547559,"mc":[{"id":"1.168133548","rc":[{"batl":[[0,9.6,8.24],[1,10,6.87],[2,12.5,20.42]],"ltp":9.6,"tv":201.25,"id":15608820}]}]}
{"op":"mcm","clk":"993532407","pt":1580543552509,"mc":[{"id":"1.168133548","rc":[{"batl":[[2,13,2.42]],"ltp":9.6,"tv":201.25,"id":15608820}]}]}
{"op":"mcm","clk":"993533428","pt":1580543566443,"mc":[{"id":"1.168133548","rc":[{"batl":[[0,9.6,3.36],[1,9.8,4.88],[2,10,6.87]],"ltp":9.6,"tv":201.25,"id":15608820}]}]}
{"op":"mcm","clk":"993534922","pt":1580543587497,"mc":[{"id":"1.168133548","rc":[{"batb":[[1,12,3.94]],"ltp":13.0,"tv":229.96,"id":8429550}]}]}
{"op":"mcm","clk":"993536132","pt":1580543605328,"mc":[{"id":"1.168133548","rc":[{"batb":[[0,5.9,8.6]],"ltp":6.0,"tv":148.55,"id":8231803}]}]}
{"op":"mcm","clk":"993536798","pt":1580543614449,"mc":[{"id":"1.168133548","rc":[{"batl":[[0,9.6,8.24],[1,10,6.87],[2,12.5,20.42]],"ltp":9.6,"tv":201.25,"id":15608820}]}]}
{"op":"mcm","clk":"993538956","pt":1580543642395,"mc":[{"id":"1.168133548","rc":[{"batl":[[2,13,2.42]],"ltp":9.6,"tv":201.25,"id":15608820}]}]}
{"op":"mcm","clk":"993540862","pt":1580543667492,"mc":[{"id":"1.168133548","rc":[{"batb":[[0,7.6,4.45]],"ltp":7.6,"tv":203.87,"id":10170404}]}]}
{"op":"mcm","clk":"993541217","pt":1580543672393,"mc":[{"id":"1.168133548","rc":[{"batl":[[0,9.6,3.36],[1,9.8,4.88],[2,10,6.87]],"ltp":9.6,"tv":201.25,"id":15608820}]}]}
{"op":"mcm","clk":"993541441","pt":1580543675290,"mc":[{"id":"1.168133548","rc":[{"batb":[[0,7.8,3],[1,7.6,4.45],[2,7.4,6]],"ltp":7.6,"tv":203.87,"id":10170404}]}]}
{"op":"mcm","clk":"993542013","pt":1580543682521,"mc":[{"id":"1.168133548","rc":[{"batl":[[1,8.8,3.81],[2,9,5]],"ltp":7.6,"tv":203.87,"id":10170404}]}]}
{"op":"mcm","clk":"993542352","pt":1580543686520,"mc":[{"id":"1.168133548","rc":[{"batl":[[1,8.8,6.81],[2,9,8]],"ltp":7.6,"tv":203.87,"id":10170404}]}]}
{"op":"mcm","clk":"993542737","pt":1580543691226,"mc":[{"id":"1.168133548","rc":[{"batl":[[0,8.2,5.03],[1,8.8,6.94]],"ltp":7.6,"tv":203.87,"id":10170404}]}]}
{"op":"mcm","clk":"993543450","pt":1580543699511,"mc":[{"id":"1.168133548","rc":[{"batl":[[0,8.2,2]],"ltp":7.6,"tv":203.87,"id":10170404}]}]}
{"op":"mcm","clk":"993544197","pt":1580543708537,"mc":[{"id":"1.168133548","rc":[{"batl":[[1,8.8,3.13],[2,9,11.44]],"ltp":7.6,"tv":203.87,"id":10170404}]}]}
{"op":"mcm","clk":"993544335","pt":1580543710246,"mc":[{"id":"1.168133548","rc":[{"batl":[[0,9.6,8.24],[1,10,6.87],[2,12.5,20.42]],"ltp":9.6,"tv":201.25,"id":15608820}]}]}
{"op":"mcm","clk":"993546042","pt":1580543732390,"mc":[{"id":"1.168133548","rc":[{"batl":[[2,13,2.42]],"ltp":9.6,"tv":201.25,"id":15608820}]}]}
{"op":"mcm","clk":"993546197","pt":1580543734400,"mc":[{"id":"1.168133548","rc":[{"batl":[[1,8.6,3.16],[2,8.8,3]],"ltp":7.6,"tv":203.87,"id":10170404}]}]}
{"op":"mcm","clk":"993547442","pt":1580543749396,"mc":[{"id":"1.168133548","rc":[{"batl":[[0,9.6,3.36],[1,9.8,4.88],[2,10,6.87]],"ltp":9.6,"tv":201.25,"id":15608820}]}]}
{"op":"mcm","clk":"993548158","pt":1580543758516,"mc":[{"id":"1.168133548","rc":[{"trd":[[8.2,4]],"batl":[[0,8.6,3.16],[1,8.8,3],[2,9,8]],"ltp":8.2,"tv":207.87,"id":10170404}],"tv":2626.91}]}
{"op":"mcm","clk":"993548904","pt":1580543767535,"mc":[{"id":"1.168133548","rc":[{"batl":[[0,8.8,3.13],[1,9,8],[2,9.2,3]],"ltp":8.2,"tv":207.87,"id":10170404}]}]}
{"op":"mcm","clk":"993548988","pt":1580543768513,"mc":[{"id":"1.168133548","rc":[{"batl":[[0,8.8,6.16]],"ltp":8.2,"tv":207.87,"id":10170404}]}]}
{"op":"mcm","clk":"993549527","pt":1580543775340,"mc":[{"id":"1.168133548","rc":[{"batl":[[0,8.6,2.13],[1,8.8,6.03],[2,9,8]],"ltp":8.2,"tv":207.87,"id":10170404}]}]}
{"op":"mcm","clk":"993550406","pt":1580543786534,"mc":[{"id":"1.168133548","rc":[{"batl":[[0,12.5,1.18]],"ltp":11.5,"tv":653.24,"id":10616006}]}]}
{"op":"mcm","clk":"993550486","pt":1580543787410,"mc":[{"id":"1.168133548","rc":[{"batl":[[0,19,1.95]],"ltp":15.5,"tv":31.84,"id":9001159}]}]}
{"op":"mcm","clk":"993550737","pt":1580543790449,"mc":[{"id":"1.168133548","rc":[{"batl":[[0,12.5,3.18]],"ltp":11.5,"tv":653.24,"id":10616006}]}]}
{"op":"mcm","clk":"993550907","pt":1580543792452,"mc":[{"id":"1.168133548","rc":[{"batl":[[0,19,2.14]],"ltp":15.5,"tv":31.84,"id":9001159}]}]}
{"op":"mcm","clk":"993551062","pt":1580543794559,"mc":[{"id":"1.168133548","rc":[{"batl":[[0,6.8,20.76]],"ltp":6.4,"tv":185.37,"id":17352128}]}]}
{"op":"mcm","clk":"993552494","pt":1580543812566,"mc":[{"id":"1.168133548","rc":[{"batl":[[0,6.6,4.82],[1,6.8,19.94],[2,7,17.5]],"ltp":6.4,"tv":185.37,"id":17352128}]}]}
{"op":"mcm","clk":"993553826","pt":1580543828475,"mc":[{"id":"1.168133548","rc":[{"batl":[[1,6.8,1.32]],"ltp":6.4,"tv":185.37,"id":17352128}]}]}
{"op":"mcm","clk":"993554666","pt":1580543839483,"mc":[{"id":"1.168133548","rc":[{"batb":[[1,12,6.44]],"ltp":13.0,"tv":229.96,"id":8429550}]}]}
{"op":"mcm","clk":"993555805","pt":1580543854490,"mc":[{"id":"1.168133548","rc":[{"batb":[[2,11.5,3.78]],"ltp":13.0,"tv":229.96,"id":8429550}]}]}
{"op":"mcm","clk":"993557280","pt":1580543873517,"mc":[{"id":"1.168133548","rc":[{"batl":[[0,9.6,8.24],[1,10,6.87],[2,12.5,20.42]],"ltp":9.6,"tv":201.25,"id":15608820}]}]}
{"op":"mcm","clk":"993557926","pt":1580543881455,"mc":[{"id":"1.168133548","rc":[{"batl":[[0,6.8,2.14],[1,7,17.5],[2,7.2,27]],"ltp":6.4,"tv":185.37,"id":17352128}]}]}
{"op":"mcm","clk":"993558021","pt":1580543882539,"mc":[{"id":"1.168133548","rc":[{"batb":[[2,11.5,3.52]],"ltp":13.0,"tv":229.96,"id":8429550}]}]}
{"op":"mcm","clk":"993558131","pt":1580543883520,"mc":[{"id":"1.168133548","rc":[{"batl":[[2,13,2.42]],"ltp":9.6,"tv":201.25,"id":15608820}]}]}
{"op":"mcm","clk":"993558306","pt":1580543885421,"mc":[{"id":"1.168133548","rc":[{"batl":[[0,6.8,20.76]],"ltp":6.4,"tv":185.37,"id":17352128}]}]}
{"op":"mcm","clk":"993563329","pt":1580543940480,"mc":[{"id":"1.168133548","rc":[{"batl":[[0,9.6,3.36],[1,9.8,4.88],[2,10,6.87]],"ltp":9.6,"tv":201.25,"id":15608820}]}]}
{"op":"mcm","clk":"993563457","pt":1580543941520,"mc":[{"id":"1.168133548","rc":[{"trd":[[7.8,6]],"batb":[[0,7.6,4.45],[1,7.4,6],[2,7.2,3.43]],"batl":[[0,7.8,4.4],[1,8.6,2.13],[2,8.8,6.03]],"ltp":7.8,"tv":213.87,"id":10170404}],"tv":2632.91}]}
{"op":"mcm","clk":"993563562","pt":1580543942501,"mc":[{"id":"1.168133548","rc":[{"batb":[[0,14.5,7.66],[1,14,9.26],[2,13.5,7.41]],"ltp":15.5,"tv":31.84,"id":9001159},{"batl":[[0,6.8,2.14]],"ltp":6.4,"tv":185.37,"id":17352128}]}]}
{"op":"mcm","clk":"993563853","pt":1580543945495,"mc":[{"id":"1.168133548","rc":[{"batl":[[1,8.4,2.91],[2,8.6,4.95]],"ltp":7.8,"tv":213.87,"id":10170404}]}]}
{"op":"mcm","clk":"993565104","pt":1580543958420,"mc":[{"id":"1.168133548","rc":[{"batl":[[2,8.6,2.95]],"ltp":7.8,"tv":213.87,"id":10170404}]}]}
{"op":"mcm","clk":"993565554","pt":1580543963532,"mc":[{"id":"1.168133548","rc":[{"batl":[[2,8.6,5.95]],"ltp":7.8,"tv":213.87,"id":10170404}]}]}
{"op":"mcm","clk":"993566083","pt":1580543969408,"mc":[{"id":"1.168133548","rc":[{"batl":[[0,9.6,8.24],[1,10,6.87],[2,12.5,20.42]],"ltp":9.6,"tv":201.25,"id":15608820}]}]}
{"op":"mcm","clk":"993566408","pt":1580543973423,"mc":[{"id":"1.168133548","rc":[{"batl":[[2,13,2.42]],"ltp":9.6,"tv":201.25,"id":15608820}]}]}
{"op":"mcm","clk":"993566574","pt":1580543975527,"mc":[{"id":"1.168133548","rc":[{"batl":[[1,8.4,6.65]],"ltp":7.8,"tv":213.87,"id":10170404}]}]}
{"op":"mcm","clk":"993566780","pt":1580543978148,"mc":[{"id":"1.168133548","rc":[{"batb":[[1,12,8.94]],"ltp":13.0,"tv":229.96,"id":8429550}]}]}
{"op":"mcm","clk":"993566839","pt":1580543978919,"mc":[{"id":"1.168133548","rc":[{"batl":[[0,9.6,3.36],[1,9.8,4.88],[2,10,6.87]],"ltp":9.6,"tv":201.25,"id":15608820}]}]}
{"op":"mcm","clk":"993567551","pt":1580543988563,"mc":[{"id":"1.168133548","rc":[{"batl":[[1,8.4,6.78],[2,8.6,5.82]],"ltp":7.8,"tv":213.87,"id":10170404}]}]}
{"op":"mcm","clk":"993570458","pt":1580544023010,"mc":[{"id":"1.168133548","rc":[{"batb":[[0,11.5,1.74],[1,11,2],[2,10.5,6.45]],"ltp":11.5,"tv":653.24,"id":10616006}]}]}
{"op":"mcm","clk":"993570769","pt":1580544027478,"mc":[{"id":"1.168133548","rc":[{"batl":[[0,9.6,8.24],[1,10,6.87],[2,12.5,20.42]],"ltp":9.6,"tv":201.25,"id":15608820}]}]}
{"op":"mcm","clk":"993570846","pt":1580544028503,"mc":[{"id":"1.168133548","rc":[{"batb":[[0,14,9.26],[1,13.5,7.41],[2,12,4.29]],"ltp":15.5,"tv":31.84,"id":9001159}]}]}
{"op":"mcm","clk":"993571209","pt":1580544033282,"mc":[{"id":"1.168133548","rc":[{"batl":[[2,13,2.42]],"ltp":9.6,"tv":201.25,"id":15608820}]}]}
{"op":"mcm","clk":"993571502","pt":1580544037298,"mc":[{"id":"1.168133548","rc":[{"batl":[[0,9.6,3.36],[1,9.8,4.88],[2,10,6.87]],"ltp":9.6,"tv":201.25,"id":15608820}]}]}
{"op":"mcm","clk":"993571586","pt":1580544038486,"mc":[{"id":"1.168133548","rc":[{"trd":[[12.5,13.55]],"batl":[[0,13,2],[1,13.5,3],[2,15,3.73]],"ltp":12.5,"tv":659.6,"id":10616006},{"trd":[[7.8,18.8]],"batb":[[0,7.8,2],[1,7.6,4.45],[2,7.4,6]],"batl":[[0,8.4,3.04],[1,8.6,9.62],[2,8.8,3]],"ltp":7.8,"tv":226.68,"id":10170404}],"tv":2652.07}]}
{"op":"mcm","clk":"993571712","pt":1580544040225,"mc":[{"id":"1.168133548","rc":[{"batb":[[1,11,4]],"ltp":12.5,"tv":659.6,"id":10616006}]}]}
{"op":"mcm","clk":"993571809","pt":1580544041523,"mc":[{"id":"1.168133548","rc":[{"batl":[[2,15,5.98]],"ltp":12.5,"tv":659.6,"id":10616006},{"batl":[[0,8.6,3.13],[1,8.8,3],[2,9,8]],"ltp":7.8,"tv":226.68,"id":10170404}]}]}
{"op":"mcm","clk":"993571970","pt":1580544043501,"mc":[{"id":"1.168133548","rc":[{"batb":[[0,7.6,4.45],[1,7.4,6],[2,7.2,3.43]],"ltp":7.8,"tv":226.68,"id":10170404},{"batl":[[0,6.8,20.76]],"ltp":6.4,"tv":185.37,"id":17352128}]}]}
{"op":"mcm","clk":"993573865","pt":1580544063512,"mc":[{"id":"1.168133548","rc":[{"batl":[[1,8.8,6.03]],"ltp":7.8,"tv":226.68,"id":10170404}]}]}
{"op":"mcm","clk":"993576129","pt":1580544088360,"mc":[{"id":"1.168133548","rc":[{"batl":[[0,6.6,4.82],[1,6.8,19.94],[2,7,17.5]],"ltp":6.4,"tv":185.37,"id":17352128}]}]}
{"op":"mcm","clk":"993576656","pt":1580544095563,"mc":[{"id":"1.168133548","rc":[{"batl":[[0,8.4,3.03],[1,8.6,3.13],[2,8.8,3]],"ltp":7.8,"tv":226.68,"id":10170404},{"batl":[[1,6.8,18.62]],"ltp":6.4,"tv":185.37,"id":17352128}]}]}
{"op":"mcm","clk":"993576721","pt":1580544096338,"mc":[{"id":"1.168133548","rc":[{"batl":[[0,6.4,2.22],[1,6.6,4],[2,6.8,18.62]],"ltp":6.4,"tv":185.37,"id":17352128}]}]}
{"op":"mcm","clk":"993577069","pt":1580544100377,"mc":[{"id":"1.168133548","rc":[{"batl":[[2,7,17.5]],"ltp":6.4,"tv":185.37,"id":17352128}]}]}
{"op":"mcm","clk":"993577306","pt":1580544103537,"mc":[{"id":"1.168133548","rc":[{"batl":[[0,8.4,3.16],[1,8.6,3]],"ltp":7.8,"tv":226.68,"id":10170404}]}]}
{"op":"mcm","clk":"993577716","pt":1580544109452,"mc":[{"id":"1.168133548","rc":[{"batb":[[1,12,11.44]],"ltp":13.0,"tv":229.96,"id":8429550}]}]}
{"op":"mcm","clk":"993577835","pt":1580544111156,"mc":[{"id":"1.168133548","rc":[{"batb":[[2,11.5,1.98]],"ltp":13.0,"tv":229.96,"id":8429550}]}]}
{"op":"mcm","clk":"993578804","pt":1580544118478,"mc":[{"id":"1.168133548","rc":[{"batb":[[0,12.5,2.7]],"ltp":13.0,"tv":229.96,"id":8429550}]}]}
{"op":"mcm","clk":"993579051","pt":1580544122485,"mc":[{"id":"1.168133548","rc":[{"batl":[[1,7,17.5],[2,7.2,27]],"ltp":6.4,"tv":185.37,"id":17352128}]}]}
{"op":"mcm","clk":"993579391","pt":1580544127565,"mc":[{"id":"1.168133548","rc":[{"batl":[[0,8.6,6.16],[1,8.8,3],[2,9,8]],"ltp":7.8,"tv":226.68,"id":10170404},{"batl":[[0,7,18.32],[1,7.2,27],[2,7.4,50]],"ltp":6.4,"tv":185.37,"id":17352128}]}]}
{"op":"mcm","clk":"993579453","pt":1580544128293,"mc":[{"id":"1.168133548","rc":[{"batl":[[0,6.8,2.14],[1,7,17.5],[2,7.2,27]],"ltp":6.4,"tv":185.37,"id":17352128}]}]}
{"op":"mcm","clk":"993579545","pt":1580544129392,"mc":[{"id":"1.168133548","rc":[{"batl":[[0,6.8,20.76]],"ltp":6.4,"tv":185.37,"id":17352128}]}]}
{"op":"mcm","clk":"993579837","pt":1580544132511,"mc":[{"id":"1.168133548","rc":[{"batl":[[0,8.6,6.03]],"ltp":7.8,"tv":226.68,"id":10170404}]}]}
{"op":"mcm","clk":"993579907","pt":1580544133289,"mc":[{"id":"1.168133548","rc":[{"batl":[[0,8.6,6.16]],"ltp":7.8,"tv":226.68,"id":10170404}]}]}
{"op":"mcm","clk":"993581998","pt":1580544153146,"mc":[{"id":"1.168133548","rc":[{"batl":[[0,9.6,8.24],[1,10,6.87],[2,13,2.42]],"ltp":9.6,"tv":201.25,"id":15608820}]}]}
{"op":"mcm","clk":"993582853","pt":1580544161486,"mc":[{"id":"1.168133548","rc":[{"batl":[[0,8.6,3.13],[1,8.8,6.03]],"ltp":7.8,"tv":226.68,"id":10170404}]}]}
{"op":"mcm","clk":"993584604","pt":1580544182481,"mc":[{"id":"1.168133548","rc":[{"batl":[[0,9.6,3.36],[1,9.8,4.88],[2,10,6.87]],"ltp":9.6,"tv":201.25,"id":15608820}]}]}
{"op":"mcm","clk":"993585533","pt":1580544195989,"mc":[{"id":"1.168133548","rc":[{"batl":[[0,8.4,3.03],[1,8.6,3.13],[2,8.8,3]],"ltp":7.8,"tv":226.68,"id":10170404}]}]}
{"op":"mcm","clk":"993587203","pt":1580544220554,"mc":[{"id":"1.168133548","rc":[{"batl":[[0,8.4,3.16],[1,8.6,3]],"ltp":7.8,"tv":226.68,"id":10170404}]}]}
{"op":"mcm","clk":"993587739","pt":1580544228552,"mc":[{"id":"1.168133548","rc":[{"batl":[[0,8.6,6.16],[1,8.8,3],[2,9,8]],"ltp":7.8,"tv":226.68,"id":10170404}]}]}
{"op":"mcm","clk":"993589748","pt":1580544259268,"mc":[{"id":"1.168133548","rc":[{"batl":[[0,8.6,3.13],[1,8.8,6.03]],"ltp":7.8,"tv":226.68,"id":10170404}]}]}
{"op":"mcm","clk":"993589967","pt":1580544262309,"mc":[{"id":"1.168133548","rc":[{"trd":[[5.7,40.06],[5.8,256.63]],"batb":[[0,5.7,33.06]],"ltp":5.7,"tv":973.65,"id":9417341}],"tv":2692.07}]}
{"op":"mcm","clk":"993590519","pt":1580544270284,"mc":[{"id":"1.168133548","rc":[{"batb":[[1,12,13.94]],"ltp":13.0,"tv":229.96,"id":8429550}]}]}
{"op":"mcm","clk":"993591961","pt":1580544291505,"mc":[{"id":"1.168133548","rc":[{"batl":[[0,8.4,3.03],[1,8.6,3.13],[2,8.8,3]],"ltp":7.8,"tv":226.68,"id":10170404}]}]}
{"op":"mcm","clk":"993592988","pt":1580544307856,"mc":[{"id":"1.168133548","rc":[{"batl":[[0,8.4,3.16],[1,8.6,3]],"ltp":7.8,"tv":226.68,"id":10170404}]}]}
{"op":"mcm","clk":"993594115","pt":1580544322472,"mc":[{"id":"1.168133548","rc":[{"batl":[[0,8.6,3.13],[1,8.8,3],[2,9,8]],"ltp":7.8,"tv":226.68,"id":10170404}]}]}
{"op":"mcm","clk":"993594216","pt":1580544323452,"mc":[{"id":"1.168133548","rc":[{"batl":[[0,8.6,6.16]],"ltp":7.8,"tv":226.68,"id":10170404}]}]}
{"op":"mcm","clk":"993595304","pt":1580544337556,"mc":[{"id":"1.168133548","rc":[{"batl":[[0,9.6,8.24],[1,10,6.87],[2,12.5,20.42]],"ltp":9.6,"tv":201.25,"id":15608820}]}]}
{"op":"mcm","clk":"993595985","pt":1580544346975,"mc":[{"id":"1.168133548","rc":[{"batl":[[0,9.6,3.36],[1,9.8,4.88],[2,10,6.87]],"ltp":9.6,"tv":201.25,"id":15608820}]}]}
{"op":"mcm","clk":"993596096","pt":1580544348261,"mc":[{"id":"1.168133548","rc":[{"batb":[[0,7.8,2.56],[1,7.6,4.45],[2,7.4,6]],"batl":[[0,8.4,2],[1,8.6,6.16],[2,8.8,3]],"ltp":7.8,"tv":226.68,"id":10170404}]}]}
{"op":"mcm","clk":"993596206","pt":1580544349565,"mc":[{"id":"1.168133548","rc":[{"batl":[[2,6.8,2.98]],"ltp":5.7,"tv":973.65,"id":9417341}]}]}
{"op":"mcm","clk":"993596354","pt":1580544351468,"mc":[{"id":"1.168133548","rc":[{"batl":[[1,8.6,3.16],[2,9,5]],"ltp":7.8,"tv":226.68,"id":10170404}]}]}
{"op":"mcm","clk":"993596599","pt":1580544354510,"mc":[{"id":"1.168133548","rc":[{"batl":[[1,8.8,3.16]],"ltp":7.8,"tv":226.68,"id":10170404}]}]}
{"op":"mcm","clk":"993596659","pt":1580544355484,"mc":[{"id":"1.168133548","rc":[{"trd":[[8.4,4]],"batl":[[0,8.8,3.16],[1,9,5],[2,9.8,4]],"ltp":8.4,"tv":230.68,"id":10170404}],"tv":2696.07}]}
{"op":"mcm","clk":"993596726","pt":1580544356511,"mc":[{"id":"1.168133548","rc":[{"batl":[[0,8.8,6.16],[1,9,8],[2,9.2,3]],"ltp":8.4,"tv":230.68,"id":10170404}]}]}
{"op":"mcm","clk":"993596788","pt":1580544357488,"mc":[{"id":"1.168133548","rc":[{"batb":[[2,7.4,6.35]],"ltp":8.4,"tv":230.68,"id":10170404}]}]}
{"op":"mcm","clk":"993596970","pt":1580544360402,"mc":[{"id":"1.168133548","rc":[{"batb":[[0,8,6],[1,7.8,2.56],[2,7.6,4.45]],"ltp":8.4,"tv":230.68,"id":10170404}]}]}
{"op":"mcm","clk":"993597359","pt":1580544365519,"mc":[{"id":"1.168133548","rc":[{"batb":[[0,8.2,4],[1,8,6],[2,7.8,2.56]],"ltp":8.4,"tv":230.68,"id":10170404}]}]}
{"op":"mcm","clk":"993598509","pt":1580544383431,"mc":[{"id":"1.168133548","rc":[{"batl":[[0,8.8,3.16],[1,9,5],[2,9.8,7]],"ltp":8.4,"tv":230.68,"id":10170404}]}]}
{"op":"mcm","clk":"993598570","pt":1580544384515,"mc":[{"id":"1.168133548","rc":[{"batl":[[2,9.8,4]],"ltp":8.4,"tv":230.68,"id":10170404}]}]}
{"op":"mcm","clk":"993598645","pt":1580544385555,"mc":[{"id":"1.168133548","rc":[{"batl":[[0,9.6,8.24],[1,10,6.87],[2,12.5,20.42]],"ltp":9.6,"tv":201.25,"id":15608820}]}]}
{"op":"mcm","clk":"993598719","pt":1580544386443,"mc":[{"id":"1.168133548","rc":[{"batl":[[0,9,5.13],[1,9.8,4],[2,10.5,24]],"ltp":8.4,"tv":230.68,"id":10170404}]}]}
{"op":"mcm","clk":"993598797","pt":1580544387416,"mc":[{"id":"1.168133548","rc":[{"batl":[[1,9.2,3],[2,9.4,3]],"ltp":8.4,"tv":230.68,"id":10170404}]}]}
{"op":"mcm","clk":"993599234","pt":1580544393559,"mc":[{"id":"1.168133548","rc":[{"batl":[[2,13,2.42]],"ltp":9.6,"tv":201.25,"id":15608820}]}]}
{"op":"mcm","clk":"993599350","pt":1580544395263,"mc":[{"id":"1.168133548","rc":[{"batl":[[0,9.6,3.36],[1,9.8,4.88],[2,10,6.87]],"ltp":9.6,"tv":201.25,"id":15608820}]}]}
{"op":"mcm","clk":"993599536","pt":1580544398049,"mc":[{"id":"1.168133548","rc":[{"batb":[[0,8.4,2.94],[1,8.2,4],[2,8,6]],"ltp":8.4,"tv":230.68,"id":10170404}]}]}
{"op":"mcm","clk":"993599940","pt":1580544404346,"mc":[{"id":"1.168133548","rc":[{"batb":[[1,12,16.44]],"ltp":13.0,"tv":229.96,"id":8429550}]}]}
{"op":"mcm","clk":"993600633","pt":1580544415477,"mc":[{"id":"1.168133548","rc":[{"batl":[[1,9.6,5.43],[2,9.8,7]],"ltp":8.4,"tv":230.68,"id":10170404}]}]}
{"op":"mcm","clk":"993600686","pt":1580544416557,"mc":[{"id":"1.168133548","rc":[{"batl":[[2,9.8,4]],"ltp":8.4,"tv":230.68,"id":10170404}]}]}
{"op":"mcm","clk":"993600888","pt":1580544419564,"mc":[{"id":"1.168133548","rc":[{"batl":[[1,9.4,3],[2,9.6,8.43]],"ltp":8.4,"tv":230.68,"id":10170404}]}]}
{"op":"mcm","clk":"993601111","pt":1580544423550,"mc":[{"id":"1.168133548","rc":[{"batl":[[0,9,5]],"ltp":8.4,"tv":230.68,"id":10170404}]}]}
{"op":"mcm","clk":"993601164","pt":1580544424482,"mc":[{"id":"1.168133548","rc":[{"batl":[[1,9.4,3.13]],"ltp":8.4,"tv":230.68,"id":10170404}]}]}
{"op":"mcm","clk":"993613714","pt":1580544463444,"mc":[{"id":"1.168133548","rc":[{"batl":[[0,9.6,8.24],[1,10,6.87],[2,12.5,20.42]],"ltp":9.6,"tv":201.25,"id":15608820}]}]}
{"op":"mcm","clk":"993614959","pt":1580544481762,"mc":[{"id":"1.168133548","rc":[{"batl":[[0,9.6,3.36],[1,9.8,4.88],[2,10,6.87]],"ltp":9.6,"tv":201.25,"id":15608820}]}]}
{"op":"mcm","clk":"993617119","pt":1580544511504,"mc":[{"id":"1.168133548","rc":[{"batl":[[0,9.6,8.24],[1,10,6.87],[2,12.5,20.42]],"ltp":9.6,"tv":201.25,"id":15608820}]}]}
{"op":"mcm","clk":"993617345","pt":1580544514384,"mc":[{"id":"1.168133548","rc":[{"batl":[[2,13,2.42]],"ltp":9.6,"tv":201.25,"id":15608820}]}]}
{"op":"mcm","clk":"993618509","pt":1580544531425,"mc":[{"id":"1.168133548","rc":[{"batb":[[0,8.4,4.99]],"ltp":8.4,"tv":230.68,"id":10170404}]}]}
{"op":"mcm","clk":"993621023","pt":1580544567448,"mc":[{"id":"1.168133548","rc":[{"batb":[[1,12,18.94]],"ltp":13.0,"tv":229.96,"id":8429550}]}]}
{"op":"mcm","clk":"993621163","pt":1580544569471,"mc":[{"id":"1.168133548","rc":[{"trd":[[11,72.01],[11.5,112.29]],"batb":[[0,11,3.74],[1,10.5,6.45],[2,10,6.77]],"ltp":11.0,"tv":663.6,"id":10616006}],"tv":2700.07}]}
{"op":"mcm","clk":"993621706","pt":1580544577377,"mc":[{"id":"1.168133548","rc":[{"batl":[[0,13,3.23]],"ltp":11.0,"tv":663.6,"id":10616006}]}]}
{"op":"mcm","clk":"993622566","pt":1580544589507,"mc":[{"id":"1.168133548","rc":[{"batl":[[0,9.6,3.36],[1,9.8,4.88],[2,10,6.87]],"ltp":9.6,"tv":201.25,"id":15608820}]}]}
{"op":"mcm","clk":"993622804","pt":1580544592532,"mc":[{"id":"1.168133548","rc":[{"batl":[[2,95,2.25]],"ltp":19.5,"tv":35.14,"id":9193530}]}]}
{"op":"mcm","clk":"993626016","pt":1580544637364,"mc":[{"id":"1.168133548","rc":[{"batl":[[0,9.6,8.24],[1,10,6.87],[2,12.5,20.42]],"ltp":9.6,"tv":201.25,"id":15608820}]}]}
{"op":"mcm","clk":"993627513","pt":1580544657498,"mc":[{"id":"1.168133548","rc":[{"batl":[[0,9.6,3.36],[1,9.8,4.88],[2,10,6.87]],"ltp":9.6,"tv":201.25,"id":15608820}]}]}
{"op":"mcm","clk":"993628221","pt":1580544667527,"mc":[{"id":"1.168133548","rc":[{"batb":[[1,12,21.44]],"ltp":13.0,"tv":229.96,"id":8429550}]}]}
{"op":"mcm","clk":"993628276","pt":1580544668300,"mc":[{"id":"1.168133548","rc":[{"trd":[[8.4,8.03]],"batb":[[0,8.4,2.97]],"ltp":8.4,"tv":234.71,"id":10170404}],"tv":2704.11}]}
{"op":"mcm","clk":"993628371","pt":1580544669537,"mc":[{"id":"1.168133548","rc":[{"trd":[[8.2,5.58],[8.4,13.98]],"batb":[[0,8.2,3.21],[1,8,6],[2,7.6,2.18]],"batl":[[1,9.2,4.24],[2,9.4,8.36]],"ltp":8.2,"tv":242.23,"id":10170404}],"tv":2711.63}]}
{"op":"mcm","clk":"993628464","pt":1580544670530,"mc":[{"id":"1.168133548","rc":[{"batb":[[0,5.8,2.97],[1,5.7,33.06],[2,5.5,26.76]],"batl":[[0,6,7.78],[1,6.2,6.93],[2,6.4,32.16]],"ltp":5.7,"tv":973.65,"id":9417341},{"batb":[[0,6,2.87],[1,5.9,3.65],[2,5.8,4.26]],"ltp":6.4,"tv":185.37,"id":17352128}]}]}
{"op":"mcm","clk":"993628531","pt":1580544671549,"mc":[{"id":"1.168133548","rc":[{"batb":[[0,8.2,5.26]],"ltp":8.2,"tv":242.23,"id":10170404}]}]}
{"op":"mcm","clk":"993628601","pt":1580544672529,"mc":[{"id":"1.168133548","rc":[{"batl":[[1,9.4,3.13],[2,9.6,8.43]],"ltp":8.2,"tv":242.23,"id":10170404}]}]}
{"op":"mcm","clk":"993628662","pt":1580544673452,"mc":[{"id":"1.168133548","rc":[{"batl":[[0,6.8,2.14]],"ltp":6.4,"tv":185.37,"id":17352128}]}]}
{"op":"mcm","clk":"993628862","pt":1580544676438,"mc":[{"id":"1.168133548","rc":[{"batl":[[0,9.6,8.24],[1,10,6.87],[2,12.5,20.42]],"ltp":9.6,"tv":201.25,"id":15608820}]}]}
{"op":"mcm","clk":"993629542","pt":1580544686235,"mc":[{"id":"1.168133548","rc":[{"batl":[[0,9.6,3.36],[1,9.8,4.88],[2,10,6.87]],"ltp":9.6,"tv":201.25,"id":15608820}]}]}
{"op":"mcm","clk":"993630365","pt":1580544696467,"mc":[{"id":"1.168133548","rc":[{"batb":[[0,11.5,1.5],[1,11,3.74],[2,10.5,6.45]],"ltp":11.0,"tv":663.6,"id":10616006}]}]}
{"op":"mcm","clk":"993632329","pt":1580544724511,"mc":[{"id":"1.168133548","rc":[{"batl":[[0,13,1.23]],"ltp":11.0,"tv":663.6,"id":10616006}]}]}
{"op":"mcm","clk":"993633853","pt":1580544744431,"mc":[{"id":"1.168133548","rc":[{"batl":[[0,9.6,8.24],[1,10,6.87],[2,12.5,20.42]],"ltp":9.6,"tv":201.25,"id":15608820}]}]}
{"op":"mcm","clk":"993634279","pt":1580544749541,"mc":[{"id":"1.168133548","rc":[{"trd":[[9,6]],"batl":[[0,9,2]],"ltp":9.0,"tv":248.23,"id":10170404}],"tv":2717.63}]}
{"op":"mcm","clk":"993634445","pt":1580544751508,"mc":[{"id":"1.168133548","rc":[{"batl":[[1,9.2,3.16],[2,9.4,3]],"ltp":9.0,"tv":248.23,"id":10170404}]}]}
{"op":"mcm","clk":"993634729","pt":1580544754419,"mc":[{"id":"1.168133548","rc":[{"batl":[[2,13,2.42]],"ltp":9.6,"tv":201.25,"id":15608820}]}]}
{"op":"mcm","clk":"993634938","pt":1580544756432,"mc":[{"id":"1.168133548","rc":[{"batb":[[1,8,6.35]],"ltp":9.0,"tv":248.23,"id":10170404}]}]}
{"op":"mcm","clk":"993635659","pt":1580544764558,"mc":[{"id":"1.168133548","rc":[{"batl":[[0,9,2.13],[1,9.2,3.03]],"ltp":9.0,"tv":248.23,"id":10170404}]}]}
{"op":"mcm","clk":"993637242","pt":1580544784476,"mc":[{"id":"1.168133548","rc":[{"batl":[[1,9.4,6.03],[2,9.6,3]],"ltp":9.0,"tv":248.23,"id":10170404}]}]}
{"op":"mcm","clk":"993637914","pt":1580544793384,"mc":[{"id":"1.168133548","rc":[{"batl":[[0,9,2],[1,9.4,6.16]],"ltp":9.0,"tv":248.23,"id":10170404}]}]}
{"op":"mcm","clk":"993639215","pt":1580544808478,"mc":[{"id":"1.168133548","rc":[{"batl":[[0,13.5,3],[1,15,5.98],[2,15.5,8]],"ltp":11.0,"tv":663.6,"id":10616006},{"batl":[[1,9.2,1.86],[2,9.4,6.03]],"ltp":9.0,"tv":248.23,"id":10170404}]}]}
{"op":"mcm","clk":"993639980","pt":1580544817423,"mc":[{"id":"1.168133548","rc":[{"batl":[[0,9,5.03],[2,9.4,3]],"ltp":9.0,"tv":248.23,"id":10170404}]}]}
{"op":"mcm","clk":"993641283","pt":1580544832518,"mc":[{"id":"1.168133548","rc":[{"trd":[[5.8,262.56]],"batb":[[0,5.7,33.06],[1,5.5,26.76],[2,5.2,2]],"batl":[[0,5.8,7.03]],"ltp":5.8,"tv":979.59,"id":9417341}],"tv":2723.56}]}
{"op":"mcm","clk":"993641534","pt":1580544835526,"mc":[{"id":"1.168133548","rc":[{"batb":[[0,14.5,1.18],[1,14,9.26],[2,13.5,7.41]],"ltp":15.5,"tv":31.84,"id":9001159}]}]}
{"op":"mcm","clk":"993641594","pt":1580544836305,"mc":[{"id":"1.168133548","rc":[{"batl":[[0,6.2,5],[1,6.4,32.16],[2,6.8,2.98]],"ltp":5.8,"tv":979.59,"id":9417341}]}]}
{"op":"mcm","clk":"993641689","pt":1580544837443,"mc":[{"id":"1.168133548","rc":[{"batl":[[1,6.4,38.34]],"ltp":5.8,"tv":979.59,"id":9417341}]}]}
{"op":"mcm","clk":"993641794","pt":1580544838435,"mc":[{"id":"1.168133548","rc":[{"batl":[[1,6.4,32.16]],"ltp":5.8,"tv":979.59,"id":9417341}]}]}
{"op":"mcm","clk":"993642028","pt":1580544841126,"mc":[{"id":"1.168133548","rc":[{"batl":[[0,9.6,3.36],[1,9.8,4.88],[2,10,6.87]],"ltp":9.6,"tv":201.25,"id":15608820}]}]}
{"op":"mcm","clk":"993642727","pt":1580544848530,"mc":[{"id":"1.168133548","rc":[{"batb":[[1,5.5,17.85]],"ltp":5.8,"tv":979.59,"id":9417341},{"batl":[[2,6.8,100]],"ltp":6.0,"tv":148.55,"id":8231803},{"batl":[[1,15,3.73]],"ltp":11.0,"tv":663.6,"id":10616006}]}]}
{"op":"mcm","clk":"993642832","pt":1580544849564,"mc":[{"id":"1.168133548","rc":[{"batb":[[1,5.5,23.4]],"ltp":5.8,"tv":979.59,"id":9417341}]}]}
{"op":"mcm","clk":"993643190","pt":1580544853543,"mc":[{"id":"1.168133548","rc":[{"batb":[[2,5.6,5.89]],"ltp":6.0,"tv":148.55,"id":8231803},{"batb":[[0,14.5,4.74]],"ltp":15.5,"tv":31.84,"id":9001159}]}]}
{"op":"mcm","clk":"993643767","pt":1580544860470,"mc":[{"id":"1.168133548","rc":[{"trd":[[9,16]],"batl":[[0,9.2,1.89],[1,9.4,3],[2,9.6,3]],"ltp":9.0,"tv":258.23,"id":10170404},{"batl":[[0,9.6,8.24],[1,10,6.87],[2,12.5,20.42]],"ltp":9.6,"tv":201.25,"id":15608820}],"tv":2733.56}]}
{"op":"mcm","clk":"993644149","pt":1580544865540,"mc":[{"id":"1.168133548","rc":[{"batb":[[0,8.6,10],[1,8.2,5.26],[2,8,6.35]],"ltp":9.0,"tv":258.23,"id":10170404}]}]}
{"op":"mcm","clk":"993644539","pt":1580544870241,"mc":[{"id":"1.168133548","rc":[{"batb":[[0,8.8,5],[1,8.6,10],[2,8.2,5.26]],"ltp":9.0,"tv":258.23,"id":10170404}]}]}
{"op":"mcm","clk":"993644917","pt":1580544874375,"mc":[{"id":"1.168133548","rc":[{"batl":[[0,6,21.11],[1,6.2,5],[2,6.4,32.16]],"ltp":5.8,"tv":979.59,"id":9417341},{"batl":[[2,13,2.42]],"ltp":9.6,"tv":201.25,"id":15608820},{"batl":[[0,6.8,20.76]],"ltp":6.4,"tv":185.37,"id":17352128}]}]}
{"op":"mcm","clk":"993645409","pt":1580544879561,"mc":[{"id":"1.168133548","rc":[{"trd":[[9,16.06],[9.2,3.3]],"batl":[[0,9.4,3.2],[1,9.6,3],[2,9.8,7]],"ltp":9.2,"tv":261.59,"id":10170404}],"tv":2736.93}]}
{"op":"mcm","clk":"993645586","pt":1580544881486,"mc":[{"id":"1.168133548","rc":[{"batb":[[0,9,3.03],[1,8.8,5],[2,8.6,10]],"ltp":9.2,"tv":261.59,"id":10170404}]}]}
{"op":"mcm","clk":"993645618","pt":1580544881858,"mc":[{"id":"1.168133548","rc":[{"batb":[[0,9,3.24]],"ltp":9.2,"tv":261.59,"id":10170404}]}]}
{"op":"mcm","clk":"993645745","pt":1580544883366,"mc":[{"id":"1.168133548","rc":[{"batl":[[2,6.4,34.02]],"ltp":5.8,"tv":979.59,"id":9417341},{"trd":[[9,22.54]],"batb":[[0,8.8,5],[1,8.6,10],[2,8.2,5.26]],"batl":[[0,9,1.76],[1,9.4,3.2],[2,9.6,3]],"ltp":9.0,"tv":268.07,"id":10170404},{"trd":[[9.4,10.32]],"batb":[[0,9.2,2.68],[1,8.8,2.01],[2,8.6,11.63]],"batl":[[0,9.4,1.19],[1,9.6,8.24],[2,10,6.87]],"ltp":9.4,"tv":208.87,"id":15608820}],"tv":2751.03}]}
{"op":"mcm","clk":"993646424","pt":1580544890515,"mc":[{"id":"1.168133548","rc":[{"batl":[[0,9,6.76],[1,9.2,2.2],[2,9.4,3]],"ltp":9.0,"tv":268.07,"id":10170404},{"batb":[[2,8.6,15.28]],"ltp":9.4,"tv":208.87,"id":15608820}]}]}
{"op":"mcm","clk":"993646950","pt":1580544896482,"mc":[{"id":"1.168133548","rc":[{"trd":[[8.8,10]],"batb":[[0,8.6,10],[1,8.2,5.26],[2,8,6.35]],"ltp":8.8,"tv":278.07,"id":10170404}],"tv":2761.03}]}
{"op":"mcm","clk":"993646974","pt":1580544896693,"mc":[{"id":"1.168133548","rc":[{"batb":[[1,8.4,3.18],[2,8.2,5.26]],"ltp":8.8,"tv":278.07,"id":10170404}]}]}
{"op":"mcm","clk":"993647538","pt":1580544902397,"mc":[{"id":"1.168133548","rc":[{"batl":[[0,6.2,5],[1,6.4,34.02],[2,6.8,2.98]],"ltp":5.8,"tv":979.59,"id":9417341},{"batb":[[1,8.2,5.26],[2,8,6]],"ltp":8.8,"tv":278.07,"id":10170404},{"batl":[[0,6.8,2.14]],"ltp":6.4,"tv":185.37,"id":17352128}]}]}
{"op":"mcm","clk":"993647639","pt":1580544903383,"mc":[{"id":"1.168133548","rc":[{"batl":[[1,6.4,32.16]],"ltp":5.8,"tv":979.59,"id":9417341}]}]}
{"op":"mcm","clk":"993647722","pt":1580544904418,"mc":[{"id":"1.168133548","rc":[{"batb":[[1,8.2,10.54]],"ltp":8.8,"tv":278.07,"id":10170404}]}]}
{"op":"mcm","clk":"993648715","pt":1580544915533,"mc":[{"id":"1.168133548","rc":[{"batl":[[2,9.8,4.02]],"ltp":9.4,"tv":208.87,"id":15608820}]}]}
{"op":"mcm","clk":"993648743","pt":1580544915903,"mc":[{"id":"1.168133548","rc":[{"trd":[[8.6,10.84]],"batb":[[0,8.6,4.58]],"batl":[[1,9.2,2.41]],"ltp":8.6,"tv":288.91,"id":10170404}],"tv":2771.87}]}
{"op":"mcm","clk":"993649533","pt":1580544924552,"mc":[{"id":"1.168133548","rc":[{"batl":[[1,9.2,2.2]],"ltp":8.6,"tv":288.91,"id":10170404}]}]}
{"op":"mcm","clk":"993650373","pt":1580544933473,"mc":[{"id":"1.168133548","rc":[{"batl":[[2,9.8,7]],"ltp":8.6,"tv":288.91,"id":10170404}]}]}
{"op":"mcm","clk":"993650464","pt":1580544934360,"mc":[{"id":"1.168133548","rc":[{"batl":[[2,9.8,4]],"ltp":8.6,"tv":288.91,"id":10170404}]}]}
{"op":"mcm","clk":"993651102","pt":1580544940481,"mc":[{"id":"1.168133548","rc":[{"batl":[[2,9.6,3]],"ltp":8.6,"tv":288.91,"id":10170404}]}]}
{"op":"mcm","clk":"993652734","pt":1580544957482,"mc":[{"id":"1.168133548","rc":[{"batb":[[1,8.8,6.48]],"ltp":9.4,"tv":208.87,"id":15608820}]}]}
{"op":"mcm","clk":"993652849","pt":1580544958464,"mc":[{"id":"1.168133548","rc":[{"batl":[[1,9.2,2],[2,9.6,8.16]],"ltp":8.6,"tv":288.91,"id":10170404},{"trd":[[9.4,12.7],[9.6,18.9]],"batl":[[0,9.8,4.45],[1,10,6.87],[2,12,21.42]],"ltp":9.6,"tv":226.87,"id":15608820}],"tv":2789.87}]}
{"op":"mcm","clk":"993653493","pt":1580544964593,"mc":[{"id":"1.168133548","rc":[{"batl":[[2,13,2.42]],"ltp":9.6,"tv":226.87,"id":15608820}]}]}
{"op":"mcm","clk":"993653691","pt":1580544966507,"mc":[{"id":"1.168133548","rc":[{"batl":[[0,9.8,4.02]],"ltp":9.6,"tv":226.87,"id":15608820}]}]}
{"op":"mcm","clk":"993653787","pt":1580544967499,"mc":[{"id":"1.168133548","rc":[{"batl":[[0,9.8,4.45]],"ltp":9.6,"tv":226.87,"id":15608820}]}]}
{"op":"mcm","clk":"993654640","pt":1580544976488,"mc":[{"id":"1.168133548","rc":[{"batl":[[0,8.8,2],[1,9,6.76]],"ltp":8.6,"tv":288.91,"id":10170404}]}]}
{"op":"mcm","clk":"993655960","pt":1580544989504,"mc":[{"id":"1.168133548","rc":[{"trd":[[5.7,49.18]],"batb":[[0,5.7,28.5]],"ltp":5.7,"tv":988.7,"id":9417341},{"trd":[[5.9,21.69]],"batb":[[0,5.9,4.03]],"ltp":5.9,"tv":157.68,"id":8231803},{"trd":[[11,75.11],[11.5,115.28]],"batb":[[0,11,2.19],[1,10.5,6.45],[2,10,6.77]],"ltp":11.0,"tv":669.69,"id":10616006},{"trd":[[9.2,17.19]],"batb":[[0,8.8,6.48],[1,8.6,15.28],[2,8.4,3]],"batl":[[0,9.8,4.81]],"ltp":9.2,"tv":232.23,"id":15608820}],"tv":2819.56}]}
{"op":"mcm","clk":"993656202","pt":1580544992418,"mc":[{"id":"1.168133548","rc":[{"batl":[[0,13,1.23],[1,13.5,3],[2,15,3.73]],"ltp":11.0,"tv":669.69,"id":10616006}]}]}
{"op":"mcm","clk":"993656302","pt":1580544993309,"mc":[{"id":"1.168133548","rc":[{"batl":[[0,13,3.23]],"ltp":11.0,"tv":669.69,"id":10616006},{"batl":[[0,9.6,2.36],[1,9.8,4.45],[2,10,6.87]],"ltp":9.2,"tv":232.23,"id":15608820}]}]}
{"op":"mcm","clk":"993656711","pt":1580544995558,"mc":[{"id":"1.168133548","rc":[{"batb":[[1,8.6,11.63],[2,8,3]],"ltp":9.2,"tv":232.23,"id":15608820}]}]}
{"op":"mcm","clk":"993657218","pt":1580544999557,"mc":[{"id":"1.168133548","rc":[{"batl":[[0,9.6,2]],"ltp":9.2,"tv":232.23,"id":15608820}]}]}
{"op":"mcm","clk":"993657298","pt":1580545000434,"mc":[{"id":"1.168133548","rc":[{"trd":[[8.8,5.81]],"batb":[[0,8.8,6.12]],"ltp":8.8,"tv":232.95,"id":15608820}],"tv":2820.28}]}
{"op":"mcm","clk":"993657744","pt":1580545004944,"mc":[{"id":"1.168133548","rc":[{"batb":[[0,5.9,6.03]],"ltp":5.9,"tv":157.68,"id":8231803}]}]}
{"op":"mcm","clk":"993658114","pt":1580545006557,"mc":[{"id":"1.168133548","rc":[{"batb":[[2,7.4,39.92]],"ltp":8.8,"tv":232.95,"id":15608820}]}]}
{"op":"mcm","clk":"993658883","pt":1580545014431,"mc":[{"id":"1.168133548","rc":[{"batl":[[0,9.6,2.43],[1,9.8,4.02]],"ltp":8.8,"tv":232.95,"id":15608820}]}]}
{"op":"mcm","clk":"993659171","pt":1580545017539,"mc":[{"id":"1.168133548","rc":[{"trd":[[8.8,14]],"batb":[[0,8.8,6.4],[1,8.6,4.58],[2,8.2,10.54]],"batl":[[0,9,6.76],[1,9.6,8.16],[2,9.8,7]],"ltp":8.8,"tv":292.91,"id":10170404}],"tv":2824.28}]}
{"op":"mcm","clk":"993659753","pt":1580545023362,"mc":[{"id":"1.168133548","rc":[{"batb":[[0,8.6,4.58],[1,8.4,3.97]],"ltp":8.8,"tv":292.91,"id":10170404}]}]}
{"op":"mcm","clk":"993659857","pt":1580545024041,"mc":[{"id":"1.168133548","rc":[{"batl":[[1,9.2,2],[2,9.6,8.16]],"ltp":8.8,"tv":292.91,"id":10170404}]}]}
{"op":"mcm","clk":"993659934","pt":1580545024662,"mc":[{"id":"1.168133548","rc":[{"batb":[[2,7.4,5.92]],"ltp":8.8,"tv":232.95,"id":15608820}]}]}
{"op":"mcm","clk":"993660812","pt":1580545034453,"mc":[{"id":"1.168133548","rc":[{"batl":[[0,8.8,2],[1,9,6.76]],"ltp":8.8,"tv":292.91,"id":10170404}]}]}
{"op":"mcm","clk":"993660837","pt":1580545034764,"mc":[{"id":"1.168133548","rc":[{"batb":[[1,8.2,10.54],[2,8,6]],"ltp":8.8,"tv":292.91,"id":10170404}]}]}
{"op":"mcm","clk":"993666434","pt":1580545091303,"mc":[{"id":"1.168133548","rc":[{"trd":[[5.9,25.69]],"batb":[[0,5.9,4.03]],"ltp":5.9,"tv":161.68,"id":8231803}],"tv":2828.28}]}
{"op":"mcm","clk":"993666733","pt":1580545094516,"mc":[{"id":"1.168133548","rc":[{"trd":[[5.9,29.69]],"batb":[[0,5.9,2.03]],"ltp":5.9,"tv":165.68,"id":8231803}],"tv":2832.28}]}
{"op":"mcm","clk":"993666922","pt":1580545096747,"mc":[{"id":"1.168133548","rc":[{"trd":[[5.7,53.18]],"batb":[[0,5.7,26.5]],"ltp":5.7,"tv":992.7,"id":9417341}],"tv":2836.28}]}
{"op":"mcm","clk":"993668413","pt":1580545114563,"mc":[{"id":"1.168133548","rc":[{"trd":[[13,164]],"batb":[[0,12.5,2.76]],"batl":[[0,13.5,29.11],[1,17,6.2],[2,17.5,10.59]],"ltp":13.0,"tv":234.84,"id":8429550}],"tv":2841.16}]}
{"op":"mcm","clk":"993671772","pt":1580545158319,"mc":[{"id":"1.168133548","rc":[{"trd":[[8.8,18]],"batb":[[0,8.8,6.4],[1,8.6,4.58],[2,8.2,10.54]],"batl":[[0,9,6.76],[1,9.6,8.16],[2,9.8,7]],"ltp":8.8,"tv":296.91,"id":10170404}],"tv":2845.16}]}
{"op":"mcm","clk":"993672128","pt":1580545163547,"mc":[{"id":"1.168133548","rc":[{"batb":[[0,8.6,4.58],[1,8.4,3.79]],"ltp":8.8,"tv":296.91,"id":10170404}]}]}
{"op":"mcm","clk":"993672563","pt":1580545168550,"mc":[{"id":"1.168133548","rc":[{"batl":[[1,9.2,2],[2,9.6,8.16]],"ltp":8.8,"tv":296.91,"id":10170404}]}]}
{"op":"mcm","clk":"993674120","pt":1580545188431,"mc":[{"id":"1.168133548","rc":[{"batl":[[0,8.8,2],[1,9,6.76]],"ltp":8.8,"tv":296.91,"id":10170404}]}]}
{"op":"mcm","clk":"993674217","pt":1580545189568,"mc":[{"id":"1.168133548","rc":[{"batb":[[1,8.2,10.54],[2,8,6]],"ltp":8.8,"tv":296.91,"id":10170404}]}]}
{"op":"mcm","clk":"993676892","pt":1580545224395,"mc":[{"id":"1.168133548","rc":[{"batl":[[0,13,2]],"ltp":11.0,"tv":669.69,"id":10616006}]}]}
{"op":"mcm","clk":"993677546","pt":1580545232425,"mc":[{"id":"1.168133548","rc":[{"batl":[[0,13,16.61]],"ltp":11.0,"tv":669.69,"id":10616006}]}]}
{"op":"mcm","clk":"993677632","pt":1580545233513,"mc":[{"id":"1.168133548","rc":[{"batb":[[0,11.5,2.89],[1,11,2.19]],"ltp":11.0,"tv":669.69,"id":10616006}]}]}
{"op":"mcm","clk":"993678726","pt":1580545246328,"mc":[{"id":"1.168133548","rc":[{"batl":[[0,13,2]],"ltp":11.0,"tv":669.69,"id":10616006}]}]}
{"op":"mcm","clk":"993679170","pt":1580545252540,"mc":[{"id":"1.168133548","rc":[{"trd":[[8.8,22]],"batb":[[0,8.8,7],[1,8.6,4.58],[2,8.2,10.54]],"batl":[[0,9,6.76],[1,9.6,8.16],[2,9.8,7]],"ltp":8.8,"tv":300.91,"id":10170404}],"tv":2849.16}]}
{"op":"mcm","clk":"993679428","pt":1580545256526,"mc":[{"id":"1.168133548","rc":[{"batl":[[1,9.2,2],[2,9.6,8.16]],"ltp":8.8,"tv":300.91,"id":10170404}]}]}
{"op":"mcm","clk":"993679617","pt":1580545259532,"mc":[{"id":"1.168133548","rc":[{"batb":[[2,7.4,4.4]],"ltp":8.8,"tv":232.95,"id":15608820}]}]}
{"op":"mcm","clk":"993679773","pt":1580545261550,"mc":[{"id":"1.168133548","rc":[{"batl":[[0,13.5,3],[1,15,3.73],[2,15.5,8]],"ltp":11.0,"tv":669.69,"id":10616006},{"batb":[[2,7.4,3]],"ltp":8.8,"tv":232.95,"id":15608820}]}]}
{"op":"mcm","clk":"993680247","pt":1580545267436,"mc":[{"id":"1.168133548","rc":[{"trd":[[9,36.06],[9.2,5.78]],"batl":[[0,9.6,8.92],[1,9.8,11.84],[2,10,3]],"ltp":9.2,"tv":316.91,"id":10170404}],"tv":2865.16}]}
{"op":"mcm","clk":"993680396","pt":1580545269553,"mc":[{"id":"1.168133548","rc":[{"batl":[[0,9.6,3.96],[1,9.8,7]],"ltp":9.2,"tv":316.91,"id":10170404}]}]}
{"op":"mcm","clk":"993680582","pt":1580545272446,"mc":[{"id":"1.168133548","rc":[{"batb":[[0,9,4],[1,8.8,7],[2,8.6,4.58]],"ltp":9.2,"tv":316.91,"id":10170404}]}]}
{"op":"mcm","clk":"993680813","pt":1580545275552,"mc":[{"id":"1.168133548","rc":[{"batl":[[0,6,21.11],[1,6.2,5],[2,6.4,32.16]],"ltp":5.7,"tv":992.7,"id":9417341},{"batl":[[0,9.6,15.62]],"ltp":8.8,"tv":232.95,"id":15608820},{"batl":[[0,6.8,20.76]],"ltp":6.4,"tv":185.37,"id":17352128}]}]}
{"op":"mcm","clk":"993680947","pt":1580545277355,"mc":[{"id":"1.168133548","rc":[{"batl":[[0,5.9,7.87],[1,6,21.11],[2,6.2,15]],"ltp":5.7,"tv":992.7,"id":9417341},{"batl":[[0,9.8,7.96],[1,10,3],[2,10.5,3]],"ltp":9.2,"tv":316.91,"id":10170404}]}]}
{"op":"mcm","clk":"993681023","pt":1580545278385,"mc":[{"id":"1.168133548","rc":[{"batl":[[0,9.8,4.96],[1,11,1],[2,11.5,25]],"ltp":9.2,"tv":316.91,"id":10170404}]}]}
{"op":"mcm","clk":"993681101","pt":1580545279375,"mc":[{"id":"1.168133548","rc":[{"batl":[[2,11.5,22]],"ltp":9.2,"tv":316.91,"id":10170404}]}]}
{"op":"mcm","clk":"993681334","pt":1580545282554,"mc":[{"id":"1.168133548","rc":[{"batl":[[1,10,3],[2,11,1]],"ltp":9.2,"tv":316.91,"id":10170404}]}]}
{"op":"mcm","clk":"993681404","pt":1580545283479,"mc":[{"id":"1.168133548","rc":[{"batl":[[2,10.5,3]],"ltp":9.2,"tv":316.91,"id":10170404}]}]}
{"op":"mcm","clk":"993681848","pt":1580545289473,"mc":[{"id":"1.168133548","rc":[{"batl":[[1,6.2,15],[2,6.4,32.16]],"ltp":5.7,"tv":992.7,"id":9417341},{"batl":[[0,9.6,14.15],[1,9.8,4],[2,10,3]],"ltp":9.2,"tv":316.91,"id":10170404}]}]}
{"op":"mcm","clk":"993683247","pt":1580545307411,"mc":[{"id":"1.168133548","rc":[{"batl":[[0,6.6,4.82],[1,6.8,19.94],[2,7,17.5]],"ltp":6.4,"tv":185.37,"id":17352128}]}]}
{"op":"mcm","clk":"993683346","pt":1580545308504,"mc":[{"id":"1.168133548","rc":[{"batl":[[0,5.9,10.82],[1,6.2,16.93]],"ltp":5.7,"tv":992.7,"id":9417341},{"trd":[[8,15.58],[8.2,16.1],[8.6,20],[8.8,36],[9,44.06]],"batb":[[0,7.8,1.48],[1,7.6,35.18],[2,7.4,6]],"batl":[[0,8,71.37],[1,9.6,14.15],[2,9.8,4]],"ltp":8.0,"tv":374.17,"id":10170404}],"tv":2922.42}]}
{"op":"mcm","clk":"993683430","pt":1580545309483,"mc":[{"id":"1.168133548","rc":[{"trd":[[8,53.44]],"batl":[[0,8,52.44]],"ltp":8.0,"tv":412.03,"id":10170404}],"tv":2960.28}]}
{"op":"mcm","clk":"993683503","pt":1580545310414,"mc":[{"id":"1.168133548","rc":[{"trd":[[8,158.32]],"batb":[[0,7.8,3.6],[2,7.4,8.44]],"batl":[[0,9.4,16.13],[1,9.6,21.91]],"ltp":8.0,"tv":516.91,"id":10170404}],"tv":3065.17}]}
{"op":"mcm","clk":"993683594","pt":1580545311505,"mc":[{"id":"1.168133548","rc":[{"batb":[[2,7.4,6]],"batl":[[0,9.4,23.39],[1,9.6,29.17]],"ltp":8.0,"tv":516.91,"id":10170404}]}]}
{"op":"mcm","clk":"993683748","pt":1580545313309,"mc":[{"id":"1.168133548","rc":[{"batl":[[0,9.6,14.15],[1,9.8,4],[2,10,3]],"ltp":8.0,"tv":516.91,"id":10170404}]}]}
{"op":"mcm","clk":"993683822","pt":1580545314294,"mc":[{"id":"1.168133548","rc":[{"batl":[[0,9.4,4.15],[1,9.6,13.95],[2,9.8,4]],"ltp":8.0,"tv":516.91,"id":10170404}]}]}
{"op":"mcm","clk":"993683905","pt":1580545315529,"mc":[{"id":"1.168133548","rc":[{"batl":[[0,9.6,13.62]],"ltp":8.8,"tv":232.95,"id":15608820}]}]}
{"op":"mcm","clk":"993684135","pt":1580545318522,"mc":[{"id":"1.168133548","rc":[{"batl":[[0,9.2,13.76],[1,9.4,4.15],[2,9.8,4.76]],"ltp":8.0,"tv":516.91,"id":10170404},{"batl":[[0,9.8,4.45],[1,10,6.87],[2,12.5,20.42]],"ltp":8.8,"tv":232.95,"id":15608820},{"batl":[[1,6.8,1.32]],"ltp":6.4,"tv":185.37,"id":17352128}]}]}
{"op":"mcm","clk":"993684687","pt":1580545325340,"mc":[{"id":"1.168133548","rc":[{"batb":[[1,7.6,2.18]],"ltp":8.0,"tv":516.91,"id":10170404},{"batl":[[2,13,2.42]],"ltp":8.8,"tv":232.95,"id":15608820}]}]}
{"op":"mcm","clk":"993685558","pt":1580545334534,"mc":[{"id":"1.168133548","rc":[{"batl":[[1,9.8,4.96],[2,10,3]],"ltp":8.0,"tv":516.91,"id":10170404}]}]}
{"op":"mcm","clk":"993685817","pt":1580545337539,"mc":[{"id":"1.168133548","rc":[{"batl":[[0,6.8,2.14],[1,7,17.5],[2,7.2,27]],"ltp":6.4,"tv":185.37,"id":17352128}]}]}
{"op":"mcm","clk":"993686621","pt":1580545346565,"mc":[{"id":"1.168133548","rc":[{"batl":[[1,9.8,4.96]],"ltp":8.0,"tv":516.91,"id":10170404}]}]}
{"op":"mcm","clk":"993686727","pt":1580545347559,"mc":[{"id":"1.168133548","rc":[{"batl":[[0,9.6,16.41],[1,9.8,4]],"ltp":8.0,"tv":516.91,"id":10170404}]}]}
{"op":"mcm","clk":"993686971","pt":1580545350360,"mc":[{"id":"1.168133548","rc":[{"trd":[[6,20.54]],"batb":[[0,6,4.26],[1,5.9,2.03],[2,5.8,2.07]],"batl":[[0,6.2,18.49],[1,6.6,4.67],[2,6.8,102.94]],"ltp":6.0,"tv":175.56,"id":8231803}],"tv":3075.05}]}
{"op":"mcm","clk":"993687060","pt":1580545351552,"mc":[{"id":"1.168133548","rc":[{"batb":[[1,5.5,17.85]],"ltp":5.7,"tv":992.7,"id":9417341}]}]}
{"op":"mcm","clk":"993697170","pt":1580545354452,"mc":[{"id":"1.168133548","rc":[{"batb":[[0,7.6,2.18],[1,7.4,6],[2,7.2,3.03]],"batl":[[0,9.2,3.41],[1,9.4,3.95],[2,9.6,16.41]],"ltp":8.0,"tv":516.91,"id":10170404}]}]}
{"op":"mcm","clk":"993697766","pt":1580545361478,"mc":[{"id":"1.168133548","rc":[{"batl":[[0,9,14.07],[1,9.2,3.41],[2,9.4,3.95]],"ltp":8.0,"tv":516.91,"id":10170404}]}]}
{"op":"mcm","clk":"993697979","pt":1580545363508,"mc":[{"id":"1.168133548","rc":[{"trd":[[6.2,50.12]],"batb":[[0,5.9,2.03],[1,5.8,2.07],[2,5.7,3.28]],"batl":[[0,6.2,14.23]],"ltp":6.2,"tv":184.08,"id":8231803},{"batl":[[0,8.8,2.75],[1,9,14.07],[2,9.2,3.41]],"ltp":8.0,"tv":516.91,"id":10170404}],"tv":3083.57}]}
{"op":"mcm","clk":"993698487","pt":1580545369513,"mc":[{"id":"1.168133548","rc":[{"batl":[[0,8.6,2],[1,8.8,2.75],[2,9,14.07]],"ltp":8.0,"tv":516.91,"id":10170404}]}]}
{"op":"mcm","clk":"993698680","pt":1580545371492,"mc":[{"id":"1.168133548","rc":[{"batl":[[1,8.8,5.99]],"ltp":8.0,"tv":516.91,"id":10170404}]}]}
{"op":"mcm","clk":"993698766","pt":1580545372431,"mc":[{"id":"1.168133548","rc":[{"batb":[[2,5.6,5.89]],"ltp":6.2,"tv":184.08,"id":8231803}]}]}
{"op":"mcm","clk":"993698850","pt":1580545373407,"mc":[{"id":"1.168133548","rc":[{"trd":[[7.6,8.34]],"batb":[[0,7.6,2.01]],"ltp":7.6,"tv":517.25,"id":10170404}],"tv":3083.9}]}
{"op":"mcm","clk":"993699024","pt":1580545375436,"mc":[{"id":"1.168133548","rc":[{"batl":[[2,9.2,3.41]],"ltp":7.6,"tv":517.25,"id":10170404}]}]}
{"op":"mcm","clk":"993699098","pt":1580545376214,"mc":[{"id":"1.168133548","rc":[{"batl":[[0,8.6,16.72]],"ltp":7.6,"tv":517.25,"id":10170404}]}]}
{"op":"mcm","clk":"993700211","pt":1580545389554,"mc":[{"id":"1.168133548","rc":[{"batl":[[0,8.4,3.03],[1,8.6,16.72],[2,8.8,5.99]],"ltp":7.6,"tv":517.25,"id":10170404}]}]}
{"op":"mcm","clk":"993700305","pt":1580545390534,"mc":[{"id":"1.168133548","rc":[{"batl":[[1,8.6,2]],"ltp":7.6,"tv":517.25,"id":10170404}]}]}
{"op":"mcm","clk":"993701154","pt":1580545401472,"mc":[{"id":"1.168133548","rc":[{"batl":[[1,6.8,102.94],[2,7,2]],"ltp":6.2,"tv":184.08,"id":8231803}]}]}
{"op":"mcm","clk":"993702360","pt":1580545416485,"mc":[{"id":"1.168133548","rc":[{"batb":[[1,5.5,20.8]],"ltp":5.7,"tv":992.7,"id":9417341},{"batl":[[1,6.8,111.89]],"ltp":6.2,"tv":184.08,"id":8231803},{"batl":[[0,12,2],[1,13.5,3],[2,15,3.73]],"ltp":11.0,"tv":669.69,"id":10616006}]}]}
{"op":"mcm","clk":"993702611","pt":1580545419485,"mc":[{"id":"1.168133548","rc":[{"batl":[[2,15,6.61]],"ltp":11.0,"tv":669.69,"id":10616006}]}]}
{"op":"mcm","clk":"993702805","pt":1580545421260,"mc":[{"id":"1.168133548","rc":[{"batl":[[0,8.6,5.03],[1,8.8,5.99],[2,9.2,3.41]],"ltp":7.6,"tv":517.25,"id":10170404}]}]}
{"op":"mcm","clk":"993702921","pt":1580545422558,"mc":[{"id":"1.168133548","rc":[{"batl":[[0,9.6,2],[1,9.8,4.45],[2,10,6.87]],"ltp":8.8,"tv":232.95,"id":15608820}]}]}
{"op":"mcm","clk":"993703008","pt":1580545423491,"mc":[{"id":"1.168133548","rc":[{"trd":[[8.6,20.3]],"batl":[[0,8.6,4.88]],"ltp":8.6,"tv":517.55,"id":10170404}],"tv":3084.2}]}
{"op":"mcm","clk":"993704728","pt":1580545444487,"mc":[{"id":"1.168133548","rc":[{"trd":[[12,49.97]],"batb":[[0,11.5,3.41]],"batl":[[0,13.5,3],[1,15,6.61],[2,15.5,8]],"ltp":12.0,"tv":673.69,"id":10616006}],"tv":3088.2}]}
{"op":"mcm","clk":"993705206","pt":1580545449520,"mc":[{"id":"1.168133548","rc":[{"batb":[[0,11.5,2.89]],"ltp":12.0,"tv":673.69,"id":10616006}]}]}
{"op":"mcm","clk":"993705355","pt":1580545451127,"mc":[{"id":"1.168133548","rc":[{"batl":[[0,9.6,2.43],[1,9.8,4.02]],"ltp":8.8,"tv":232.95,"id":15608820}]}]}
{"op":"mcm","clk":"993710172","pt":1580545505500,"mc":[{"id":"1.168133548","rc":[{"batb":[[2,5.7,3.02]],"ltp":6.2,"tv":184.08,"id":8231803}]}]}
{"op":"mcm","clk":"993715172","pt":1580545562478,"mc":[{"id":"1.168133548","rc":[{"batb":[[0,7.8,3.6],[1,7.6,2.01],[2,7.4,6]],"batl":[[0,8.2,2],[1,8.6,4.88],[2,8.8,5.99]],"ltp":8.6,"tv":517.55,"id":10170404}]}]}
{"op":"mcm","clk":"993716943","pt":1580545583390,"mc":[{"id":"1.168133548","rc":[{"batl":[[1,8.6,3.03]],"ltp":8.6,"tv":517.55,"id":10170404}]}]}
{"op":"mcm","clk":"993717287","pt":1580545587493,"mc":[{"id":"1.168133548","rc":[{"trd":[[8.2,20.1]],"batb":[[2,7.4,8.5]],"batl":[[0,8.6,3.03],[1,8.8,5.99],[2,9.8,30.76]],"ltp":8.2,"tv":521.55,"id":10170404}],"tv":3092.2}]}
{"op":"mcm","clk":"993718130","pt":1580545596500,"mc":[{"id":"1.168133548","rc":[{"batl":[[2,9.8,4.76]],"ltp":8.2,"tv":521.55,"id":10170404}]}]}
{"op":"mcm","clk":"993720489","pt":1580545624562,"mc":[{"id":"1.168133548","rc":[{"batb":[[0,8,4],[1,7.8,3.6],[2,7.6,2.01]],"ltp":8.2,"tv":521.55,"id":10170404}]}]}
{"op":"mcm","clk":"993721558","pt":1580545636479,"mc":[{"id":"1.168133548","rc":[{"batl":[[0,8.8,6.21],[1,9.8,4.76],[2,10,3]],"ltp":8.2,"tv":521.55,"id":10170404}]}]}
{"op":"mcm","clk":"993722361","pt":1580545646471,"mc":[{"id":"1.168133548","rc":[{"batl":[[0,9.6,8.52],[1,9.8,8.03]],"ltp":8.2,"tv":521.55,"id":10170404}]}]}
{"op":"mcm","clk":"993723225","pt":1580545657275,"mc":[{"id":"1.168133548","rc":[{"batl":[[0,9.4,13.69],[1,9.6,8.3],[2,9.8,8.03]],"ltp":8.2,"tv":521.55,"id":10170404}]}]}
{"op":"mcm","clk":"993723252","pt":1580545657687,"mc":[{"id":"1.168133548","rc":[{"batl":[[1,9.8,4.76],[2,10,3]],"ltp":8.2,"tv":521.55,"id":10170404}]}]}
{"op":"mcm","clk":"993723971","pt":1580545667446,"mc":[{"id":"1.168133548","rc":[{"batl":[[0,9.2,1.95],[1,9.4,13.47],[2,9.8,4.76]],"ltp":8.2,"tv":521.55,"id":10170404}]}]}
{"op":"mcm","clk":"993724334","pt":1580545672483,"mc":[{"id":"1.168133548","rc":[{"batl":[[1,9.6,13.95],[2,9.8,4]],"ltp":8.2,"tv":521.55,"id":10170404}]}]}
{"op":"mcm","clk":"993725345","pt":1580545686488,"mc":[{"id":"1.168133548","rc":[{"batl":[[1,9.4,13.47],[2,9.8,4.76]],"ltp":8.2,"tv":521.55,"id":10170404}]}]}
{"op":"mcm","clk":"993725663","pt":1580545690493,"mc":[{"id":"1.168133548","rc":[{"batl":[[0,9,2.22],[1,9.2,1.73],[2,9.4,13.47]],"ltp":8.2,"tv":521.55,"id":10170404}]}]}
{"op":"mcm","clk":"993726228","pt":1580545697506,"mc":[{"id":"1.168133548","rc":[{"batb":[[1,7.6,2.01],[2,7.4,11.53]],"batl":[[0,8.8,3.46],[1,9,2.21],[2,9.2,1.73]],"ltp":8.2,"tv":521.55,"id":10170404}]}]}
{"op":"mcm","clk":"993726316","pt":1580545698486,"mc":[{"id":"1.168133548","rc":[{"batl":[[1,9,4.7]],"ltp":8.2,"tv":521.55,"id":10170404}]}]}
{"op":"mcm","clk":"993728334","pt":1580545722535,"mc":[{"id":"1.168133548","rc":[{"batl":[[0,5.8,4],[1,5.9,10.82],[2,6.2,16.93]],"ltp":5.7,"tv":992.7,"id":9417341},{"batb":[[1,7.6,4.77]],"ltp":8.2,"tv":521.55,"id":10170404}]}]}
{"op":"mcm","clk":"993728412","pt":1580545723462,"mc":[{"id":"1.168133548","rc":[{"trd":[[5.8,270.56]],"batb":[[0,5.8,17.51],[1,5.7,26.5],[2,5.5,20.8]],"batl":[[0,5.9,10.82],[1,6.2,16.93],[2,6.4,32.16]],"ltp":5.8,"tv":1000.7,"id":9417341}],"tv":3100.2}]}
{"op":"mcm","clk":"993729377","pt":1580545736559,"mc":[{"id":"1.168133548","rc":[{"trd":[[5.9,150.57]],"batb":[[0,5.8,17.69]],"batl":[[0,6.2,15],[1,6.4,32.16],[2,6.8,2.98]],"ltp":5.9,"tv":1022.34,"id":9417341},{"batl":[[0,6,4],[1,6.2,14.23],[2,6.8,111.89]],"ltp":6.2,"tv":184.08,"id":8231803}],"tv":3121.84}]}
{"op":"mcm","clk":"993729932","pt":1580545743556,"mc":[{"id":"1.168133548","rc":[{"batb":[[2,5.5,23.8]],"ltp":5.9,"tv":1022.34,"id":9417341}]}]}
{"op":"mcm","clk":"993730003","pt":1580545744537,"mc":[{"id":"1.168133548","rc":[{"batl":[[1,9,2.7]],"ltp":8.2,"tv":521.55,"id":10170404}]}]}
{"op":"mcm","clk":"993730163","pt":1580545746555,"mc":[{"id":"1.168133548","rc":[{"trd":[[13,164.12]],"batb":[[0,12.5,2.7]],"batl":[[0,13,1.94],[1,13.5,29.11],[2,17,12.25]],"ltp":13.0,"tv":234.96,"id":8429550}],"tv":3121.96}]}
{"op":"mcm","clk":"993730243","pt":1580545747538,"mc":[{"id":"1.168133548","rc":[{"batl":[[2,17,18.29]],"ltp":13.0,"tv":234.96,"id":8429550}]}]}
{"op":"mcm","clk":"993730867","pt":1580545756065,"mc":[{"id":"1.168133548","rc":[{"batb":[[0,5.9,6.18],[1,5.8,17.51],[2,5.7,26.5]],"ltp":5.9,"tv":1022.34,"id":9417341}]}]}
{"op":"mcm","clk":"993732724","pt":1580545774105,"mc":[{"id":"1.168133548","rc":[{"batl":[[1,9.2,1.73],[2,9.4,3.03]],"ltp":8.2,"tv":521.55,"id":10170404}]}]}
{"op":"mcm","clk":"993733245","pt":1580545781437,"mc":[{"id":"1.168133548","rc":[{"batl":[[0,6.2,35]],"ltp":5.9,"tv":1022.34,"id":9417341}]}]}
{"op":"mcm","clk":"993734713","pt":1580545798858,"mc":[{"id":"1.168133548","rc":[{"batl":[[0,6.2,36.93]],"ltp":5.9,"tv":1022.34,"id":9417341},{"batl":[[0,8.4,2],[1,8.8,3.46],[2,9.2,1.73]],"ltp":8.2,"tv":521.55,"id":10170404}]}]}
{"op":"mcm","clk":"993737537","pt":1580545829562,"mc":[{"id":"1.168133548","rc":[{"batl":[[2,9.4,5.23]],"ltp":8.2,"tv":521.55,"id":10170404}]}]}
{"op":"mcm","clk":"993737618","pt":1580545830493,"mc":[{"id":"1.168133548","rc":[{"batl":[[2,9.4,7.86]],"ltp":8.2,"tv":521.55,"id":10170404}]}]}
{"op":"mcm","clk":"993740675","pt":1580545870112,"mc":[{"id":"1.168133548","rc":[{"trd":[[8.4,17.34]],"batl":[[0,8.8,3.78],[1,9.4,7.86],[2,9.8,4.76]],"ltp":8.4,"tv":524.91,"id":10170404}],"tv":3125.32}]}
{"op":"mcm","clk":"993741068","pt":1580545875526,"mc":[{"id":"1.168133548","rc":[{"batl":[[0,12,2.52],[1,13.5,3],[2,15,6.61]],"ltp":12.0,"tv":673.69,"id":10616006}]}]}
{"op":"mcm","clk":"993741125","pt":1580545876452,"mc":[{"id":"1.168133548","rc":[{"trd":[[12,51.01]],"batl":[[0,12,2]],"ltp":12.0,"tv":674.73,"id":10616006}],"tv":3126.37}]}
{"op":"mcm","clk":"993749017","pt":1580545969564,"mc":[{"id":"1.168133548","rc":[{"batl":[[1,6.4,25]],"ltp":5.9,"tv":1022.34,"id":9417341}]}]}
{"op":"mcm","clk":"993749029","pt":1580545969665,"mc":[{"id":"1.168133548","rc":[{"batl":[[0,6.2,44.09]],"ltp":5.9,"tv":1022.34,"id":9417341}]}]}
{"op":"mcm","clk":"993749793","pt":1580545978396,"mc":[{"id":"1.168133548","rc":[{"batl":[[1,7,67.5]],"ltp":6.4,"tv":185.37,"id":17352128}]}]}
{"op":"mcm","clk":"993750869","pt":1580545990089,"mc":[{"id":"1.168133548","rc":[{"batl":[[0,6.8,6.14]],"ltp":6.4,"tv":185.37,"id":17352128}]}]}
{"op":"mcm","clk":"993752628","pt":1580546012542,"mc":[{"id":"1.168133548","rc":[{"batl":[[0,6.4,20.82],[1,6.8,5.32],[2,7,67.5]],"ltp":6.4,"tv":185.37,"id":17352128}]}]}
{"op":"mcm","clk":"993753598","pt":1580546024554,"mc":[{"id":"1.168133548","rc":[{"batl":[[1,6.6,20],[2,6.8,5.32]],"ltp":6.4,"tv":185.37,"id":17352128}]}]}
{"op":"mcm","clk":"993755401","pt":1580546046556,"mc":[{"id":"1.168133548","rc":[{"trd":[[5.9,154.57]],"batb":[[0,5.9,4.18]],"batl":[[0,6,5],[1,6.2,44.09],[2,6.4,25]],"ltp":5.9,"tv":1026.34,"id":9417341}],"tv":3130.37}]}
{"op":"mcm","clk":"993755484","pt":1580546047480,"mc":[{"id":"1.168133548","rc":[{"batl":[[2,6.8,4]],"ltp":6.4,"tv":185.37,"id":17352128}]}]}
{"op":"mcm","clk":"993755565","pt":1580546048355,"mc":[{"id":"1.168133548","rc":[{"batl":[[0,6.2,1.45],[1,6.4,20.82],[2,6.6,20]],"ltp":6.4,"tv":185.37,"id":17352128}]}]}
{"op":"mcm","clk":"993756067","pt":1580546054499,"mc":[{"id":"1.168133548","rc":[{"batl":[[0,6,19]],"ltp":5.9,"tv":1026.34,"id":9417341}]}]}
{"op":"mcm","clk":"993756211","pt":1580546056362,"mc":[{"id":"1.168133548","rc":[{"trd":[[6,253.56]],"batb":[[0,5.9,17.4]],"batl":[[0,6.2,42.16],[1,6.4,26.86],[2,6.8,2.98]],"ltp":6.0,"tv":1064.34,"id":9417341}],"tv":3168.37}]}
{"op":"mcm","clk":"993756271","pt":1580546057184,"mc":[{"id":"1.168133548","rc":[{"batb":[[0,5.9,18.42]],"ltp":6.0,"tv":1064.34,"id":9417341}]}]}
{"op":"mcm","clk":"993757781","pt":1580546074438,"mc":[{"id":"1.168133548","rc":[{"batl":[[0,9,2],[1,9.6,2.43],[2,9.8,4.02]],"ltp":8.8,"tv":232.95,"id":15608820}]}]}
{"op":"mcm","clk":"993758040","pt":1580546077532,"mc":[{"id":"1.168133548","rc":[{"batb":[[0,8.2,5],[1,8,4],[2,7.6,4.77]],"ltp":8.4,"tv":524.91,"id":10170404}]}]}
{"op":"mcm","clk":"993758379","pt":1580546081146,"mc":[{"id":"1.168133548","rc":[{"batl":[[1,9.4,5.04]],"ltp":8.4,"tv":524.91,"id":10170404}]}]}
{"op":"mcm","clk":"993759608","pt":1580546096454,"mc":[{"id":"1.168133548","rc":[{"batl":[[1,9.6,6.68],[2,9.8,6.25]],"ltp":8.4,"tv":524.91,"id":10170404}]}]}
{"op":"mcm","clk":"993761697","pt":1580546120497,"mc":[{"id":"1.168133548","rc":[{"batl":[[1,9.8,4.45],[2,10,6.87]],"ltp":8.8,"tv":232.95,"id":15608820}]}]}
{"op":"mcm","clk":"993762249","pt":1580546127501,"mc":[{"id":"1.168133548","rc":[{"batl":[[2,10,9.75]],"ltp":8.8,"tv":232.95,"id":15608820}]}]}
{"op":"mcm","clk":"993766399","pt":1580546176557,"mc":[{"id":"1.168133548","rc":[{"batl":[[1,9.8,4.02]],"ltp":8.8,"tv":232.95,"id":15608820}]}]}
{"op":"mcm","clk":"993766470","pt":1580546177485,"mc":[{"id":"1.168133548","rc":[{"batl":[[1,9.8,4.45]],"ltp":8.8,"tv":232.95,"id":15608820}]}]}
{"op":"mcm","clk":"993767898","pt":1580546195498,"mc":[{"id":"1.168133548","rc":[{"batl":[[1,12.5,5],[2,13.5,3]],"ltp":12.0,"tv":674.73,"id":10616006}]}]}
{"op":"mcm","clk":"993769414","pt":1580546212123,"mc":[{"id":"1.168133548","rc":[{"batl":[[0,13,6.94]],"ltp":13.0,"tv":234.96,"id":8429550}]}]}
{"op":"mcm","clk":"993786088","pt":1580546283569,"mc":[{"id":"1.168133548","rc":[{"batl":[[1,9.2,3],[2,9.4,3.2]],"ltp":8.4,"tv":524.91,"id":10170404}]}]}
{"op":"mcm","clk":"993790411","pt":1580546333421,"mc":[{"id":"1.168133548","rc":[{"batb":[[0,6,22.87]],"ltp":6.4,"tv":185.37,"id":17352128}]}]}
{"op":"mcm","clk":"993791392","pt":1580546346523,"mc":[{"id":"1.168133548","rc":[{"trd":[[6.2,20.52]],"batb":[[0,6.2,1.4],[1,6,22.87],[2,5.9,3.65]],"batl":[[0,6.4,20.82],[1,6.6,20],[2,6.8,6]],"ltp":6.2,"tv":188.26,"id":17352128}],"tv":3171.26}]}
{"op":"mcm","clk":"993793572","pt":1580546373454,"mc":[{"id":"1.168133548","rc":[{"trd":[[6.2,20.86]],"batb":[[0,6.2,1.24]],"ltp":6.2,"tv":188.6,"id":17352128}],"tv":3171.59}]}
{"op":"mcm","clk":"993802364","pt":1580546470480,"mc":[{"id":"1.168133548","rc":[{"batl":[[2,13,4.99]],"ltp":12.0,"tv":674.73,"id":10616006}]}]}
{"op":"mcm","clk":"993802903","pt":1580546475512,"mc":[{"id":"1.168133548","rc":[{"batl":[[0,12,5]],"ltp":12.0,"tv":674.73,"id":10616006}]}]}
{"op":"mcm","clk":"993813550","pt":1580546587401,"mc":[{"id":"1.168133548","rc":[{"trd":[[5.8,0.66],[5.9,33.75]],"batb":[[0,5.8,1.74],[1,5.7,3.02],[2,5.6,5.89]],"ltp":5.8,"tv":188.8,"id":8231803}],"tv":3176.31}]}
{"op":"mcm","clk":"993815327","pt":1580546607510,"mc":[{"id":"1.168133548","rc":[{"batl":[[2,6.8,100]],"ltp":5.8,"tv":188.8,"id":8231803}]}]}
{"op":"mcm","clk":"993833021","pt":1580546809561,"mc":[{"id":"1.168133548","rc":[{"trd":[[8.4,17.98]],"batb":[[0,8.4,5.68],[1,8.2,5],[2,8,4]],"batl":[[0,8.8,3.46]],"ltp":8.4,"tv":525.55,"id":10170404}],"tv":3176.95}]}
{"op":"mcm","clk":"993836621","pt":1580546854532,"mc":[{"id":"1.168133548","rc":[{"trd":[[8.8,42.72]],"batb":[[0,8.6,6.92],[1,8.4,5.68],[2,8.2,5]],"batl":[[0,9.2,3],[1,9.4,3.2],[2,9.6,9.47]],"ltp":8.8,"tv":532.28,"id":10170404}],"tv":3183.67}]}
{"op":"mcm","clk":"993836761","pt":1580546856436,"mc":[{"id":"1.168133548","rc":[{"batl":[[2,9.6,3.76]],"ltp":8.8,"tv":532.28,"id":10170404}]}]}
{"op":"mcm","clk":"993837090","pt":1580546860568,"mc":[{"id":"1.168133548","rc":[{"trd":[[8.8,18.06]],"batb":[[0,8.6,11.63],[1,7.6,11.69],[2,7.4,10.54]],"ltp":8.8,"tv":245.21,"id":15608820}],"tv":3195.93}]}
{"op":"mcm","clk":"993837280","pt":1580546863556,"mc":[{"id":"1.168133548","rc":[{"batl":[[0,9.4,3.2],[1,9.6,3.76],[2,9.8,7]],"ltp":8.8,"tv":532.28,"id":10170404}]}]}
{"op":"mcm","clk":"993837341","pt":1580546864568,"mc":[{"id":"1.168133548","rc":[{"batl":[[0,9.8,4.96],[1,10.5,3],[2,11,4]],"ltp":8.8,"tv":532.28,"id":10170404},{"batb":[[1,7.6,19.32]],"ltp":8.8,"tv":245.21,"id":15608820}]}]}
{"op":"mcm","clk":"993837403","pt":1580546865469,"mc":[{"id":"1.168133548","rc":[{"batl":[[1,11,6.85],[2,11.5,22]],"ltp":8.8,"tv":532.28,"id":10170404}]}]}
{"op":"mcm","clk":"993837703","pt":1580546869490,"mc":[{"id":"1.168133548","rc":[{"batl":[[0,9.6,3.96],[1,9.8,7],[2,10,3]],"ltp":8.8,"tv":532.28,"id":10170404}]}]}
{"op":"mcm","clk":"993837781","pt":1580546870370,"mc":[{"id":"1.168133548","rc":[{"batl":[[0,9.4,2.2],[1,9.6,3.76],[2,9.8,7]],"ltp":8.8,"tv":532.28,"id":10170404}]}]}
{"op":"mcm","clk":"993839690","pt":1580546895215,"mc":[{"id":"1.168133548","rc":[{"batl":[[0,9.4,4.68]],"ltp":8.8,"tv":532.28,"id":10170404}]}]}
{"op":"mcm","clk":"993840875","pt":1580546910459,"mc":[{"id":"1.168133548","rc":[{"trd":[[8.6,110.91]],"batb":[[0,8.6,6.63]],"ltp":8.6,"tv":255.21,"id":15608820}],"tv":3205.93}]}
{"op":"mcm","clk":"993841914","pt":1580546923348,"mc":[{"id":"1.168133548","rc":[{"batl":[[0,9.4,2.68]],"ltp":8.8,"tv":532.28,"id":10170404}]}]}
{"op":"mcm","clk":"993851944","pt":1580547047359,"mc":[{"id":"1.168133548","rc":[{"trd":[[11.5,121.06]],"batb":[[0,11,2.19],[1,10,11.28],[2,9.6,10.18]],"batl":[[0,11.5,17.11],[1,12,5],[2,12.5,5]],"ltp":11.5,"tv":680.51,"id":10616006}],"tv":3211.71}]}
{"op":"mcm","clk":"993852103","pt":1580547049479,"mc":[{"id":"1.168133548","rc":[{"batb":[[1,10,6.77]],"batl":[[1,12,2]],"ltp":11.5,"tv":680.51,"id":10616006}]}]}
{"op":"mcm","clk":"993852176","pt":1580547050560,"mc":[{"id":"1.168133548","rc":[{"trd":[[11,79.49]],"batb":[[0,10,6.77],[1,9.6,10.18],[2,9.2,4.4]],"batl":[[0,11,2.91],[1,11.5,17.11],[2,12,2]],"ltp":11.0,"tv":684.89,"id":10616006}],"tv":3216.08}]}
{"op":"mcm","clk":"993852246","pt":1580547051494,"mc":[{"id":"1.168133548","rc":[{"batb":[[1,9.6,13.38]],"ltp":11.0,"tv":684.89,"id":10616006}]}]}
{"op":"mcm","clk":"993853540","pt":1580547066416,"mc":[{"id":"1.168133548","rc":[{"batb":[[0,10.5,1.51],[1,10,6.77],[2,9.6,13.38]],"ltp":11.0,"tv":684.89,"id":10616006}]}]}
{"op":"mcm","clk":"993853869","pt":1580547070389,"mc":[{"id":"1.168133548","rc":[{"trd":[[10.5,121.06]],"batb":[[0,10,6.77],[1,9.6,13.38],[2,9.2,4.4]],"batl":[[0,11,3.4]],"ltp":10.5,"tv":687.91,"id":10616006}],"tv":3219.11}]}
{"op":"mcm","clk":"993857275","pt":1580547114486,"mc":[{"id":"1.168133548","rc":[{"batl":[[1,9.4,1.69],[2,9.8,4.45]],"ltp":8.6,"tv":255.21,"id":15608820},{"batb":[[0,15,7.41],[1,14.5,4.74],[2,14,9.26]],"ltp":15.5,"tv":31.84,"id":9001159}]}]}
{"op":"mcm","clk":"993857335","pt":1580547115209,"mc":[{"id":"1.168133548","rc":[{"batb":[[2,14,8]],"ltp":15.5,"tv":31.84,"id":9001159}]}]}
{"op":"mcm","clk":"993857601","pt":1580547118489,"mc":[{"id":"1.168133548","rc":[{"batl":[[0,19,1.95]],"ltp":15.5,"tv":31.84,"id":9001159}]}]}
{"op":"mcm","clk":"993857919","pt":1580547122529,"mc":[{"id":"1.168133548","rc":[{"batb":[[0,15,8.59]],"ltp":15.5,"tv":31.84,"id":9001159}]}]}
{"op":"mcm","clk":"993858221","pt":1580547125522,"mc":[{"id":"1.168133548","rc":[{"batl":[[0,9.4,3.44],[1,9.6,3]],"ltp":8.8,"tv":532.28,"id":10170404}]}]}
{"op":"mcm","clk":"993858495","pt":1580547129098,"mc":[{"id":"1.168133548","rc":[{"trd":[[6.4,39.2]],"batl":[[0,6.4,16.91]],"ltp":6.4,"tv":196.42,"id":17352128}],"tv":3226.93}]}
{"op":"mcm","clk":"993858588","pt":1580547130395,"mc":[{"id":"1.168133548","rc":[{"batl":[[0,9.6,6.79],[1,9.8,7],[2,10,3]],"ltp":8.8,"tv":532.28,"id":10170404},{"batb":[[0,15,1.18]],"ltp":15.5,"tv":31.84,"id":9001159}]}]}
{"op":"mcm","clk":"993858995","pt":1580547135525,"mc":[{"id":"1.168133548","rc":[{"batl":[[0,9,10],[1,9.6,6.79],[2,9.8,7]],"ltp":8.8,"tv":532.28,"id":10170404}]}]}
{"op":"mcm","clk":"993859164","pt":1580547137496,"mc":[{"id":"1.168133548","rc":[{"trd":[[9,64.07]],"batl":[[0,9.6,6.79],[1,9.8,9.54],[2,10,3]],"ltp":9.0,"tv":552.28,"id":10170404},{"batb":[[0,14.5,4.74],[1,14,8],[2,13.5,7.41]],"ltp":15.5,"tv":31.84,"id":9001159}],"tv":3246.93}]}
{"op":"mcm","clk":"993859333","pt":1580547139506,"mc":[{"id":"1.168133548","rc":[{"batl":[[0,9.4,2.76],[1,9.6,9.29],[2,9.8,11.84]],"ltp":9.0,"tv":552.28,"id":10170404}]}]}
{"op":"mcm","clk":"993859767","pt":1580547145524,"mc":[{"id":"1.168133548","rc":[{"batb":[[0,15,7.41],[1,14.5,5.95],[2,14,8]],"ltp":15.5,"tv":31.84,"id":9001159}]}]}
{"op":"mcm","clk":"993860008","pt":1580547148523,"mc":[{"id":"1.168133548","rc":[{"batb":[[0,10,5.51]],"ltp":10.5,"tv":687.91,"id":10616006}]}]}
{"op":"mcm","clk":"993870961","pt":1580547161572,"mc":[{"id":"1.168133548","rc":[{"batl":[[1,9.8,4.45],[2,10,9.75]],"ltp":8.6,"tv":255.21,"id":15608820},{"batb":[[0,14.5,5.95],[1,14,8],[2,13.5,7.41]],"ltp":15.5,"tv":31.84,"id":9001159}]}]}
{"op":"mcm","clk":"993871007","pt":1580547162247,"mc":[{"id":"1.168133548","rc":[{"batl":[[1,9.6,6.03],[2,9.8,7]],"ltp":9.0,"tv":552.28,"id":10170404}]}]}
{"op":"mcm","clk":"993871157","pt":1580547164264,"mc":[{"id":"1.168133548","rc":[{"batb":[[0,15,8],[1,14.5,5.95]],"ltp":15.5,"tv":31.84,"id":9001159}]}]}
{"op":"mcm","clk":"993874337","pt":1580547202451,"mc":[{"id":"1.168133548","rc":[{"trd":[[8.6,124.17]],"batb":[[0,7.6,19.32],[1,7.4,10.54],[2,7.2,4]],"batl":[[0,8.6,15.8],[1,8.8,2],[2,9.8,4.45]],"ltp":8.6,"tv":268.47,"id":15608820}],"tv":3260.19}]}
{"op":"mcm","clk":"993874493","pt":1580547204548,"mc":[{"id":"1.168133548","rc":[{"batb":[[1,7.4,18.73]],"ltp":8.6,"tv":268.47,"id":15608820}]}]}
{"op":"mcm","clk":"993874580","pt":1580547205540,"mc":[{"id":"1.168133548","rc":[{"batl":[[1,6.4,25],[2,6.6,1.79]],"ltp":6.0,"tv":1064.34,"id":9417341},{"batb":[[0,7.4,3],[1,7.2,4],[2,6.6,2.92]],"batl":[[2,9.6,8.07]],"ltp":8.6,"tv":268.47,"id":15608820}]}]}
{"op":"mcm","clk":"993874724","pt":1580547207353,"mc":[{"id":"1.168133548","rc":[{"batl":[[2,9.6,15.7]],"ltp":8.6,"tv":268.47,"id":15608820}]}]}
{"op":"mcm","clk":"993874908","pt":1580547209485,"mc":[{"id":"1.168133548","rc":[{"batl":[[1,6.4,26.86]],"ltp":6.0,"tv":1064.34,"id":9417341},{"batb":[[0,7.6,2.09],[1,7.4,3],[2,7.2,4]],"ltp":8.6,"tv":268.47,"id":15608820},{"batb":[[1,17,8.34]],"ltp":19.5,"tv":35.14,"id":9193530}]}]}
{"op":"mcm","clk":"993875016","pt":1580547210554,"mc":[{"id":"1.168133548","rc":[{"batb":[[0,7.6,4.18]],"ltp":8.6,"tv":268.47,"id":15608820}]}]}
{"op":"mcm","clk":"993875083","pt":1580547211276,"mc":[{"id":"1.168133548","rc":[{"batl":[[0,8.6,17.8],[1,9.6,15.7],[2,9.8,11.66]],"ltp":8.6,"tv":268.47,"id":15608820}]}]}
{"op":"mcm","clk":"993875186","pt":1580547212572,"mc":[{"id":"1.168133548","rc":[{"batl":[[0,8.6,18.23],[1,9.6,15.27]],"ltp":8.6,"tv":268.47,"id":15608820}]}]}
{"op":"mcm","clk":"993875536","pt":1580547216474,"mc":[{"id":"1.168133548","rc":[{"batb":[[0,7.8,1.61],[1,7.6,4.18],[2,7.4,3]],"ltp":8.6,"tv":268.47,"id":15608820}]}]}
{"op":"mcm","clk":"993876051","pt":1580547222499,"mc":[{"id":"1.168133548","rc":[{"batb":[[1,17,9.38]],"ltp":19.5,"tv":35.14,"id":9193530}]}]}
{"op":"mcm","clk":"993876122","pt":1580547223486,"mc":[{"id":"1.168133548","rc":[{"trd":[[7.8,0.34]],"batb":[[0,7.8,1.45]],"ltp":7.8,"tv":268.81,"id":15608820}],"tv":3260.53}]}
{"op":"mcm","clk":"993876406","pt":1580547227377,"mc":[{"id":"1.168133548","rc":[{"batb":[[1,17.5,6.2],[2,17,2.99]],"ltp":19.5,"tv":35.14,"id":9193530}]}]}
{"op":"mcm","clk":"993876497","pt":1580547228471,"mc":[{"id":"1.168133548","rc":[{"batb":[[2,7.2,4]],"ltp":7.8,"tv":268.81,"id":15608820}]}]}
{"op":"mcm","clk":"993876780","pt":1580547231688,"mc":[{"id":"1.168133548","rc":[{"batl":[[0,8.6,17.8],[1,9.6,15.7]],"ltp":7.8,"tv":268.81,"id":15608820}]}]}
{"op":"mcm","clk":"993877247","pt":1580547237101,"mc":[{"id":"1.168133548","rc":[{"batb":[[2,7.2,7.92]],"ltp":7.8,"tv":268.81,"id":15608820},{"batl":[[0,17,2],[1,19,1.95],[2,20,7.35]],"ltp":15.5,"tv":31.84,"id":9001159}]}]}
{"op":"mcm","clk":"993877750","pt":1580547242413,"mc":[{"id":"1.168133548","rc":[{"batb":[[1,18,1.85],[2,17.5,6.2]],"ltp":19.5,"tv":35.14,"id":9193530}]}]}
{"op":"mcm","clk":"993878100","pt":1580547245533,"mc":[{"id":"1.168133548","rc":[{"batl":[[0,8.4,2],[1,8.6,17.8],[2,9.6,15.7]],"ltp":7.8,"tv":268.81,"id":15608820}]}]}
{"op":"mcm","clk":"993878208","pt":1580547246517,"mc":[{"id":"1.168133548","rc":[{"batb":[[1,18,7.88],[2,17,1.04]],"ltp":19.5,"tv":35.14,"id":9193530}]}]}
{"op":"mcm","clk":"993879576","pt":1580547262537,"mc":[{"id":"1.168133548","rc":[{"batl":[[0,8.4,2.43],[2,9.6,15.27]],"ltp":7.8,"tv":268.81,"id":15608820}]}]}
{"op":"mcm","clk":"993880515","pt":1580547273545,"mc":[{"id":"1.168133548","rc":[{"trd":[[8.2,0.32]],"batl":[[0,8.4,2.27]],"ltp":8.2,"tv":269.13,"id":15608820}],"tv":3260.85}]}
{"op":"mcm","clk":"993883441","pt":1580547306310,"mc":[{"id":"1.168133548","rc":[{"batb":[[1,14.5,4.77]],"ltp":15.5,"tv":31.84,"id":9001159}]}]}
{"op":"mcm","clk":"993883901","pt":1580547311539,"mc":[{"id":"1.168133548","rc":[{"batb":[[0,8.8,5],[1,8.6,6.92],[2,8.4,5.68]],"ltp":9.0,"tv":552.28,"id":10170404}]}]}
{"op":"mcm","clk":"993884671","pt":1580547319507,"mc":[{"id":"1.168133548","rc":[{"batb":[[0,7.6,4.18],[1,7.2,7.92],[2,7,3]],"ltp":8.2,"tv":269.13,"id":15608820}]}]}
{"op":"mcm","clk":"993885499","pt":1580547328543,"mc":[{"id":"1.168133548","rc":[{"batl":[[1,9.6,3.03],[2,9.8,4]],"ltp":9.0,"tv":552.28,"id":10170404}]}]}
{"op":"mcm","clk":"993885999","pt":1580547333424,"mc":[{"id":"1.168133548","rc":[{"batl":[[2,9.8,7]],"ltp":9.0,"tv":552.28,"id":10170404}]}]}
{"op":"mcm","clk":"993888867","pt":1580547363372,"mc":[{"id":"1.168133548","rc":[{"batl":[[0,9.6,3.79],[1,9.8,7],[2,10,3]],"ltp":9.0,"tv":552.28,"id":10170404}]}]}
{"op":"mcm","clk":"993889062","pt":1580547365507,"mc":[{"id":"1.168133548","rc":[{"batl":[[0,16.5,5],[1,17,2],[2,19,1.95]],"ltp":15.5,"tv":31.84,"id":9001159}]}]}
{"op":"mcm","clk":"993889342","pt":1580547368485,"mc":[{"id":"1.168133548","rc":[{"batl":[[2,20,7.35]],"ltp":15.5,"tv":31.84,"id":9001159}]}]}
{"op":"mcm","clk":"993890719","pt":1580547382314,"mc":[{"id":"1.168133548","rc":[{"batb":[[2,7,4.67]],"batl":[[0,7.8,2],[1,8.4,2.27],[2,8.6,15.8]],"ltp":8.2,"tv":269.13,"id":15608820},{"batl":[[2,20,10.82]],"ltp":15.5,"tv":31.84,"id":9001159}]}]}
{"op":"mcm","clk":"993890786","pt":1580547383148,"mc":[{"id":"1.168133548","rc":[{"batl":[[1,8.2,5.07],[2,8.4,2]],"ltp":8.2,"tv":269.13,"id":15608820},{"batb":[[1,14.5,3.47]],"ltp":15.5,"tv":31.84,"id":9001159}]}]}
{"op":"mcm","clk":"993890890","pt":1580547384553,"mc":[{"id":"1.168133548","rc":[{"batb":[[0,5.9,25.31]],"ltp":6.0,"tv":1064.34,"id":9417341},{"batb":[[0,5.8,8.75]],"ltp":5.8,"tv":188.8,"id":8231803}]}]}
{"op":"mcm","clk":"993890972","pt":1580547385433,"mc":[{"id":"1.168133548","rc":[{"batb":[[0,12.5,6.64]],"ltp":13.0,"tv":234.96,"id":8429550},{"batb":[[1,5.6,5.89],[2,5.5,4.76]],"ltp":5.8,"tv":188.8,"id":8231803},{"batb":[[0,10,9.58]],"ltp":10.5,"tv":687.91,"id":10616006},{"batb":[[0,9,4.52],[1,8.8,5],[2,8.6,6.92]],"ltp":9.0,"tv":552.28,"id":10170404},{"trd":[[7.8,4.34]],"batb":[[0,7.8,3.21],[1,7.6,4.18],[2,7.2,7.92]],"batl":[[0,8.2,5.07],[1,8.4,2],[2,8.6,15.8]],"ltp":7.8,"tv":273.13,"id":15608820},{"batb":[[0,15.5,2.62],[1,15,8],[2,14.5,3.47]],"batl":[[2,19.5,2.42]],"ltp":15.5,"tv":31.84,"id":9001159},{"batb":[[0,19,3.02],[1,18.5,1.61],[2,18,7.88]],"ltp":19.5,"tv":35.14,"id":9193530},{"batb":[[1,6,29.65]],"ltp":6.4,"tv":196.42,"id":17352128}],"tv":3264.85}]}
{"op":"mcm","clk":"993891093","pt":1580547386533,"mc":[{"id":"1.168133548","rc":[{"batb":[[0,19,8.74],[2,18,1.85]],"ltp":19.5,"tv":35.14,"id":9193530}]}]}
{"op":"mcm","clk":"993891276","pt":1580547388549,"mc":[{"id":"1.168133548","rc":[{"trd":[[15.5,9.06]],"batb":[[0,15,8],[1,14.5,3.47],[2,13.5,7.41]],"ltp":15.5,"tv":37.09,"id":9001159}],"tv":3270.1}]}
{"op":"mcm","clk":"993891366","pt":1580547389333,"mc":[{"id":"1.168133548","rc":[{"trd":[[7.8,4.88]],"batb":[[0,7.8,2.94]],"batl":[[0,8.2,4.8]],"ltp":7.8,"tv":273.67,"id":15608820}],"tv":3270.64}]}
{"op":"mcm","clk":"993892282","pt":1580547399343,"mc":[{"id":"1.168133548","rc":[{"trd":[[10.5,122.04]],"batb":[[0,10.5,1.51],[1,10,9.58],[2,9.6,13.38]],"batl":[[0,11,2.91]],"ltp":10.5,"tv":688.89,"id":10616006}],"tv":3271.62}]}
{"op":"mcm","clk":"993892451","pt":1580547401475,"mc":[{"id":"1.168133548","rc":[{"batb":[[1,18.5,2.56]],"ltp":19.5,"tv":35.14,"id":9193530}]}]}
{"op":"mcm","clk":"993892560","pt":1580547402565,"mc":[{"id":"1.168133548","rc":[{"batb":[[2,9.6,16.84]],"ltp":10.5,"tv":688.89,"id":10616006}]}]}
{"op":"mcm","clk":"993892806","pt":1580547405056,"mc":[{"id":"1.168133548","rc":[{"batb":[[2,9.6,18.84]],"ltp":10.5,"tv":688.89,"id":10616006}]}]}
{"op":"mcm","clk":"993892909","pt":1580547406149,"mc":[{"id":"1.168133548","rc":[{"batl":[[1,9.8,4],[2,10.5,3]],"ltp":9.0,"tv":552.28,"id":10170404}]}]}
{"op":"mcm","clk":"993893049","pt":1580547407562,"mc":[{"id":"1.168133548","rc":[{"batl":[[2,11,1]],"ltp":9.0,"tv":552.28,"id":10170404}]}]}
{"op":"mcm","clk":"993893407","pt":1580547411258,"mc":[{"id":"1.168133548","rc":[{"batl":[[2,10,3]],"ltp":9.0,"tv":552.28,"id":10170404}]}]}
{"op":"mcm","clk":"993894357","pt":1580547422505,"mc":[{"id":"1.168133548","rc":[{"batb":[[0,19.5,2.59],[1,19,7.85],[2,18.5,2.56]],"ltp":19.5,"tv":35.14,"id":9193530}]}]}
{"op":"mcm","clk":"993894514","pt":1580547424490,"mc":[{"id":"1.168133548","rc":[{"batb":[[0,19.5,8.15],[1,19,2.14]],"ltp":19.5,"tv":35.14,"id":9193530}]}]}
{"op":"mcm","clk":"993894633","pt":1580547425684,"mc":[{"id":"1.168133548","rc":[{"batl":[[1,8.6,15.8],[2,9.6,41.27]],"ltp":7.8,"tv":273.67,"id":15608820}]}]}
{"op":"mcm","clk":"993894977","pt":1580547429536,"mc":[{"id":"1.168133548","rc":[{"batl":[[2,9.6,15.27]],"ltp":7.8,"tv":273.67,"id":15608820}]}]}
{"op":"mcm","clk":"993895900","pt":1580547439225,"mc":[{"id":"1.168133548","rc":[{"batl":[[0,8.2,12.8]],"ltp":7.8,"tv":273.67,"id":15608820}]}]}
{"op":"mcm","clk":"993896351","pt":1580547444265,"mc":[{"id":"1.168133548","rc":[{"batb":[[1,7.6,2.09]],"ltp":7.8,"tv":273.67,"id":15608820}]}]}
{"op":"mcm","clk":"993897656","pt":1580547458074,"mc":[{"id":"1.168133548","rc":[{"batb":[[1,7.2,7.92],[2,7,3]],"ltp":7.8,"tv":273.67,"id":15608820}]}]}
{"op":"mcm","clk":"993898038","pt":1580547462279,"mc":[{"id":"1.168133548","rc":[{"batb":[[1,7.4,2.7],[2,7.2,7.92]],"ltp":7.8,"tv":273.67,"id":15608820}]}]}
{"op":"mcm","clk":"993898517","pt":1580547468765,"mc":[{"id":"1.168133548","rc":[{"batl":[[1,6.4,25]],"ltp":6.0,"tv":1064.34,"id":9417341}]}]}
{"op":"mcm","clk":"993903823","pt":1580547537483,"mc":[{"id":"1.168133548","rc":[{"batl":[[2,6.8,2.98]],"ltp":6.0,"tv":1064.34,"id":9417341}]}]}
{"op":"mcm","clk":"993904350","pt":1580547544096,"mc":[{"id":"1.168133548","rc":[{"batb":[[0,6.2,20.47]],"ltp":6.4,"tv":196.42,"id":17352128}]}]}
{"op":"mcm","clk":"993909457","pt":1580547604524,"mc":[{"id":"1.168133548","rc":[{"trd":[[8.2,24.04],[8.4,29.34],[8.6,34.14],[8.8,52.72],[9,73.1]],"batb":[[0,8.2,3.03],[1,8,4],[2,7.6,35.01]],"batl":[[0,9.4,6.57],[1,9.6,3.79],[2,9.8,4]],"ltp":8.2,"tv":600.44,"id":10170404}],"tv":3319.78}]}
{"op":"mcm","clk":"993909591","pt":1580547605537,"mc":[{"id":"1.168133548","rc":[{"batb":[[0,5.9,2.92],[1,5.8,8.75],[2,5.6,5.89]],"ltp":5.8,"tv":188.8,"id":8231803},{"batb":[[0,15.5,1.11],[1,15,8],[2,14.5,3.47]],"ltp":15.5,"tv":37.09,"id":9001159}]}]}
{"op":"mcm","clk":"993910041","pt":1580547609537,"mc":[{"id":"1.168133548","rc":[{"trd":[[5.9,39.59]],"batb":[[0,5.8,8.75],[1,5.6,5.89],[2,5.5,4.76]],"ltp":5.9,"tv":194.63,"id":8231803},{"batb":[[0,8.4,2.38],[1,8.2,3.03],[2,8,4]],"batl":[[0,9.2,2],[1,9.4,6.57],[2,9.6,3.79]],"ltp":8.2,"tv":600.44,"id":10170404},{"trd":[[7.8,6.88]],"batb":[[0,7.8,1.94]],"ltp":7.8,"tv":275.67,"id":15608820}],"tv":3327.62}]}
{"op":"mcm","clk":"993910263","pt":1580547611574,"mc":[{"id":"1.168133548","rc":[{"batb":[[2,5.5,7.76]],"ltp":5.9,"tv":194.63,"id":8231803}]}]}
{"op":"mcm","clk":"993910349","pt":1580547612459,"mc":[{"id":"1.168133548","rc":[{"batb":[[1,7.4,5.03]],"ltp":7.8,"tv":275.67,"id":15608820}]}]}
{"op":"mcm","clk":"993910808","pt":1580547617571,"mc":[{"id":"1.168133548","rc":[{"trd":[[13,177.99]],"batb":[[0,13,2.81],[1,12.5,6.64],[2,12,21.44]],"batl":[[0,13.5,29.11],[1,17,18.29],[2,17.5,5]],"ltp":13.0,"tv":248.83,"id":8429550},{"trd":[[8.4,37.53]],"batb":[[0,8.4,13.36]],"batl":[[1,9.6,3.79],[2,9.8,4]],"ltp":8.4,"tv":608.64,"id":10170404},{"batb":[[1,7.6,16.66],[2,7.4,5.03]],"ltp":7.8,"tv":275.67,"id":15608820},{"trd":[[6.4,73]],"batb":[[0,6.4,2.89],[1,6.2,20.47],[2,6,29.65]],"batl":[[0,6.6,20],[1,6.8,10.02],[2,7,69.17]],"ltp":6.4,"tv":230.22,"id":17352128}],"tv":3383.49}]}
{"op":"mcm","clk":"993910900","pt":1580547618564,"mc":[{"id":"1.168133548","rc":[{"trd":[[8.4,64.26]],"batb":[[0,8.2,3.03],[1,8,4],[2,7.6,2.01]],"batl":[[0,9.2,2.76],[1,9.6,3.03]],"ltp":8.4,"tv":635.37,"id":10170404},{"batb":[[0,7.8,4.15],[2,7.4,2.7]],"ltp":7.8,"tv":275.67,"id":15608820}],"tv":3410.22}]}
{"op":"mcm","clk":"993910987","pt":1580547619558,"mc":[{"id":"1.168133548","rc":[{"trd":[[8.2,29.42]],"batb":[[0,8,4.34],[1,7.6,9.97],[2,7.4,25.07]],"ltp":8.2,"tv":640.75,"id":10170404},{"batl":[[1,6.8,6]],"ltp":6.4,"tv":230.22,"id":17352128}],"tv":3415.6}]}
{"op":"mcm","clk":"993911072","pt":1580547620655,"mc":[{"id":"1.168133548","rc":[{"batb":[[1,7.6,2.01],[2,7.4,17.12]],"ltp":8.2,"tv":640.75,"id":10170404}]}]}
{"op":"mcm","clk":"993911313","pt":1580547623375,"mc":[{"id":"1.168133548","rc":[{"trd":[[6.6,0.32]],"batl":[[0,6.6,19.84]],"ltp":6.6,"tv":230.54,"id":17352128}],"tv":3415.92}]}
{"op":"mcm","clk":"993911440","pt":1580547624697,"mc":[{"id":"1.168133548","rc":[{"trd":[[7.8,10.88]],"batb":[[0,7.8,2.15]],"ltp":7.8,"tv":279.67,"id":15608820}],"tv":3419.92}]}
{"op":"mcm","clk":"993911687","pt":1580547627071,"mc":[{"id":"1.168133548","rc":[{"batl":[[1,6.4,27]],"ltp":6.0,"tv":1064.34,"id":9417341}]}]}
{"op":"mcm","clk":"993911804","pt":1580547628483,"mc":[{"id":"1.168133548","rc":[{"batb":[[2,6,32.65]],"ltp":6.6,"tv":230.54,"id":17352128}]}]}
{"op":"mcm","clk":"993911879","pt":1580547629373,"mc":[{"id":"1.168133548","rc":[{"trd":[[6.6,3.1]],"batl":[[0,6.6,18.45]],"ltp":6.6,"tv":233.32,"id":17352128}],"tv":3422.69}]}
{"op":"mcm","clk":"993912058","pt":1580547631304,"mc":[{"id":"1.168133548","rc":[{"batb":[[2,7.2,4]],"ltp":7.8,"tv":279.67,"id":15608820}]}]}
{"op":"mcm","clk":"993912316","pt":1580547634500,"mc":[{"id":"1.168133548","rc":[{"batb":[[0,12.5,6.64],[1,12,21.44],[2,11.5,1.98]],"ltp":13.0,"tv":248.83,"id":8429550},{"batb":[[1,7.2,4],[2,7,3]],"ltp":7.8,"tv":279.67,"id":15608820},{"batb":[[0,6.2,20.47],[1,6,32.65],[2,5.9,3.65]],"ltp":6.6,"tv":233.32,"id":17352128}]}]}
{"op":"mcm","clk":"993912394","pt":1580547635388,"mc":[{"id":"1.168133548","rc":[{"batb":[[1,7.4,17.11],[2,7.2,6.44]],"ltp":7.8,"tv":279.67,"id":15608820},{"batb":[[1,6,36.06]],"batl":[[2,7,67.5]],"ltp":6.6,"tv":233.32,"id":17352128}]}]}
{"op":"mcm","clk":"993912493","pt":1580547636392,"mc":[{"id":"1.168133548","rc":[{"batb":[[1,6,32.65]],"ltp":6.6,"tv":233.32,"id":17352128}]}]}
{"op":"mcm","clk":"993914050","pt":1580547653308,"mc":[{"id":"1.168133548","rc":[{"trd":[[10.5,122.26]],"batb":[[0,10.5,1.4]],"ltp":10.5,"tv":689.11,"id":10616006}],"tv":3422.91}]}
{"op":"mcm","clk":"993922099","pt":1580547725549,"mc":[{"id":"1.168133548","rc":[{"trd":[[10.5,123.26]],"batb":[[0,10,10.48],[1,9.6,18.84],[2,9.2,4.4]],"ltp":10.5,"tv":690.11,"id":10616006}],"tv":3423.91}]}
{"op":"mcm","clk":"993925005","pt":1580547750563,"mc":[{"id":"1.168133548","rc":[{"batl":[[1,6.4,25]],"ltp":6.0,"tv":1064.34,"id":9417341}]}]}
{"op":"mcm","clk":"993925937","pt":1580547759884,"mc":[{"id":"1.168133548","rc":[{"trd":[[8.2,8.88]],"batl":[[0,8.2,8.52]],"ltp":8.2,"tv":288.23,"id":15608820}],"tv":3432.47}]}
{"op":"mcm","clk":"993926340","pt":1580547763484,"mc":[{"id":"1.168133548","rc":[{"trd":[[8.2,17.44]],"batl":[[0,8.2,3.72]],"ltp":8.2,"tv":296.78,"id":15608820},{"batb":[[0,15.5,4.14],[2,14.5,1.22]],"ltp":15.5,"tv":37.09,"id":9001159}],"tv":3441.03}]}
{"op":"mcm","clk":"993926656","pt":1580547766408,"mc":[{"id":"1.168133548","rc":[{"batl":[[1,8.4,4.69],[2,8.6,15.8]],"ltp":8.2,"tv":296.78,"id":15608820},{"batb":[[0,15.5,3.21]],"ltp":15.5,"tv":37.09,"id":9001159}]}]}
{"op":"mcm","clk":"993927163","pt":1580547771574,"mc":[{"id":"1.168133548","rc":[{"batb":[[2,13.5,7.41]],"ltp":15.5,"tv":37.09,"id":9001159}]}]}
{"op":"mcm","clk":"993927636","pt":1580547776500,"mc":[{"id":"1.168133548","rc":[{"batb":[[0,13,1.33],[1,12.5,6.64],[2,12,20]],"ltp":13.0,"tv":248.83,"id":8429550},{"batb":[[0,6.4,2.69],[1,6.2,20.47],[2,6,29.78]],"batl":[[2,7,69.17]],"ltp":6.6,"tv":233.32,"id":17352128}]}]}
{"op":"mcm","clk":"993927781","pt":1580547777893,"mc":[{"id":"1.168133548","rc":[{"batb":[[0,15.5,4.35]],"ltp":15.5,"tv":37.09,"id":9001159}]}]}
{"op":"mcm","clk":"993928831","pt":1580547787503,"mc":[{"id":"1.168133548","rc":[{"batb":[[0,10.5,2.9],[1,10,9.58],[2,9.6,18.84]],"ltp":10.5,"tv":690.11,"id":10616006}]}]}
{"op":"mcm","clk":"993929366","pt":1580547792442,"mc":[{"id":"1.168133548","rc":[{"batb":[[1,7.2,6.44],[2,7,3]],"ltp":8.2,"tv":296.78,"id":15608820}]}]}
{"op":"mcm","clk":"993930391","pt":1580547802565,"mc":[{"id":"1.168133548","rc":[{"batb":[[1,7.4,2.15],[2,7.2,6.44]],"ltp":8.2,"tv":296.78,"id":15608820}]}]}
{"op":"mcm","clk":"993931752","pt":1580547817167,"mc":[{"id":"1.168133548","rc":[{"trd":[[11,85.3]],"batl":[[0,11.5,17.11],[1,12,2],[2,12.5,5]],"ltp":11.0,"tv":695.93,"id":10616006}],"tv":3446.85}]}
{"op":"mcm","clk":"993932094","pt":1580547820483,"mc":[{"id":"1.168133548","rc":[{"batl":[[1,6.4,37.94]],"ltp":6.0,"tv":1064.34,"id":9417341}]}]}
{"op":"mcm","clk":"993932682","pt":1580547826390,"mc":[{"id":"1.168133548","rc":[{"batb":[[1,7.6,6.25],[2,7.4,2.15]],"ltp":8.2,"tv":296.78,"id":15608820}]}]}
{"op":"mcm","clk":"993935178","pt":1580547850002,"mc":[{"id":"1.168133548","rc":[{"trd":[[8.2,20.88]],"batl":[[0,8.2,2]],"ltp":8.2,"tv":300.23,"id":15608820}],"tv":3450.29}]}
{"op":"mcm","clk":"993936086","pt":1580547858411,"mc":[{"id":"1.168133548","rc":[{"trd":[[8,164.64],[8.2,30.1]],"batb":[[0,7.6,2.85],[1,7.4,17.12],[2,6.6,10.58]],"ltp":8.0,"tv":647.75,"id":10170404}],"tv":3457.29}]}
{"op":"mcm","clk":"993936411","pt":1580547861124,"mc":[{"id":"1.168133548","rc":[{"batb":[[1,7.4,9.15]],"ltp":8.0,"tv":647.75,"id":10170404}]}]}
{"op":"mcm","clk":"993937406","pt":1580547871316,"mc":[{"id":"1.168133548","rc":[{"batl":[[0,9,1.76],[1,9.2,2.76],[2,9.6,3.03]],"ltp":8.0,"tv":647.75,"id":10170404}]}]}
{"op":"mcm","clk":"993939379","pt":1580547891286,"mc":[{"id":"1.168133548","rc":[{"batl":[[0,8.8,6.86],[1,9,9.2],[2,9.2,2.76]],"ltp":8.0,"tv":647.75,"id":10170404}]}]}
{"op":"mcm","clk":"993939682","pt":1580547894486,"mc":[{"id":"1.168133548","rc":[{"batl":[[0,6,10]],"ltp":5.9,"tv":194.63,"id":8231803},{"trd":[[8,166.32]],"batb":[[0,7.6,2.01]],"batl":[[0,8,3.16],[1,8.8,6.86],[2,9,9.2]],"ltp":8.0,"tv":649.43,"id":10170404}],"tv":3458.97}]}
{"op":"mcm","clk":"993939767","pt":1580547895282,"mc":[{"id":"1.168133548","rc":[{"batb":[[2,6.8,2.7]],"batl":[[1,8.6,7.96],[2,8.8,6.86]],"ltp":8.0,"tv":649.43,"id":10170404}]}]}
{"op":"mcm","clk":"993939888","pt":1580547896480,"mc":[{"id":"1.168133548","rc":[{"batl":[[1,8.6,15.91],[2,8.8,7.62]],"ltp":8.0,"tv":649.43,"id":10170404}]}]}
{"op":"mcm","clk":"993940104","pt":1580547898465,"mc":[{"id":"1.168133548","rc":[{"batb":[[0,7.8,18.38]],"ltp":8.2,"tv":300.23,"id":15608820},{"batb":[[0,6.4,5.58]],"ltp":6.6,"tv":233.32,"id":17352128}]}]}
{"op":"mcm","clk":"993940293","pt":1580547900568,"mc":[{"id":"1.168133548","rc":[{"trd":[[10.5,129.26]],"batb":[[0,10.5,3.18],[2,9.8,2.46]],"ltp":10.5,"tv":701.93,"id":10616006},{"batl":[[1,8.6,23.87]],"ltp":8.0,"tv":649.43,"id":10170404},{"batl":[[2,7,67.5]],"ltp":6.6,"tv":233.32,"id":17352128}],"tv":3464.97}]}
{"op":"mcm","clk":"993940345","pt":1580547901089,"mc":[{"id":"1.168133548","rc":[{"batl":[[2,7,69.17]],"ltp":6.6,"tv":233.32,"id":17352128}]}]}
{"op":"mcm","clk":"993940876","pt":1580547906288,"mc":[{"id":"1.168133548","rc":[{"batl":[[1,8.6,24.63],[2,8.8,6.86]],"ltp":8.0,"tv":649.43,"id":10170404}]}]}
{"op":"mcm","clk":"993941010","pt":1580547907506,"mc":[{"id":"1.168133548","rc":[{"batb":[[0,13,9.02]],"ltp":13.0,"tv":248.83,"id":8429550}]}]}
{"op":"mcm","clk":"993941668","pt":1580547913488,"mc":[{"id":"1.168133548","rc":[{"batl":[[0,8,5.16]],"ltp":8.0,"tv":649.43,"id":10170404}]}]}
{"op":"mcm","clk":"993941773","pt":1580547914535,"mc":[{"id":"1.168133548","rc":[{"batb":[[2,11,23]],"ltp":15.5,"tv":37.09,"id":9001159}]}]}
{"op":"mcm","clk":"993942000","pt":1580547916519,"mc":[{"id":"1.168133548","rc":[{"trd":[[13.5,7.19]],"batl":[[0,13.5,26.4]],"ltp":13.5,"tv":254.24,"id":8429550},{"batb":[[0,6.4,2.69]],"ltp":6.6,"tv":233.32,"id":17352128}],"tv":3470.39}]}
{"op":"mcm","clk":"993942855","pt":1580547925325,"mc":[{"id":"1.168133548","rc":[{"batb":[[0,16,6.25],[1,15.5,4.35],[2,15,8]],"ltp":15.5,"tv":37.09,"id":9001159},{"batb":[[0,20,5],[1,19.5,8.15],[2,19,2.14]],"ltp":19.5,"tv":35.14,"id":9193530}]}]}
{"op":"mcm","clk":"993943656","pt":1580547933525,"mc":[{"id":"1.168133548","rc":[{"trd":[[7.8,16]],"batb":[[0,7.6,6.25],[1,7.4,2.15],[2,7.2,4]],"ltp":7.8,"tv":305.35,"id":15608820},{"trd":[[16.5,14.56]],"batb":[[0,16.5,1.74],[1,16,6.25],[2,15.5,4.35]],"batl":[[0,17,2],[1,19.5,2.42],[2,20,10.56]],"ltp":16.5,"tv":47.08,"id":9001159},{"batb":[[0,21,5.17],[1,20,5],[2,19.5,2.59]],"ltp":19.5,"tv":35.14,"id":9193530}],"tv":3485.5}]}
{"op":"mcm","clk":"993943742","pt":1580547934519,"mc":[{"id":"1.168133548","rc":[{"batb":[[1,7.4,13.62]],"ltp":7.8,"tv":305.35,"id":15608820}]}]}
{"op":"mcm","clk":"993943836","pt":1580547935560,"mc":[{"id":"1.168133548","rc":[{"batb":[[1,7.4,2.15]],"ltp":7.8,"tv":305.35,"id":15608820},{"batl":[[1,20,10.82],[2,24,14.36]],"ltp":16.5,"tv":47.08,"id":9001159}]}]}
{"op":"mcm","clk":"993944325","pt":1580547940471,"mc":[{"id":"1.168133548","rc":[{"batl":[[2,24,4.36]],"ltp":16.5,"tv":47.08,"id":9001159},{"batb":[[1,20,5.88]],"ltp":19.5,"tv":35.14,"id":9193530}]}]}
{"op":"mcm","clk":"993944410","pt":1580547941259,"mc":[{"id":"1.168133548","rc":[{"batl":[[1,19.5,1.08],[2,20,10.56]],"ltp":16.5,"tv":47.08,"id":9001159}]}]}
{"op":"mcm","clk":"993945092","pt":1580547947465,"mc":[{"id":"1.168133548","rc":[{"trd":[[8.2,24.88],[8.4,22.19]],"batl":[[0,8.4,1.32],[1,8.6,15.8],[2,9.6,33.64]],"ltp":8.4,"tv":316.09,"id":15608820}],"tv":3496.24}]}
{"op":"mcm","clk":"993945217","pt":1580547948566,"mc":[{"id":"1.168133548","rc":[{"batl":[[2,20,7.09]],"ltp":16.5,"tv":47.08,"id":9001159}]}]}
{"op":"mcm","clk":"993945352","pt":1580547949562,"mc":[{"id":"1.168133548","rc":[{"batl":[[2,9.6,41.38]],"ltp":8.4,"tv":316.09,"id":15608820}]}]}
{"op":"mcm","clk":"993945557","pt":1580547951567,"mc":[{"id":"1.168133548","rc":[{"batb":[[0,16,6.25],[1,15.5,4.35],[2,15,8]],"ltp":16.5,"tv":47.08,"id":9001159},{"batb":[[0,20,5.88],[1,19.5,2.59],[2,19,2.14]],"ltp":19.5,"tv":35.14,"id":9193530}]}]}
{"op":"mcm","clk":"993945747","pt":1580547953550,"mc":[{"id":"1.168133548","rc":[{"batb":[[1,7.4,5.15]],"ltp":8.4,"tv":316.09,"id":15608820}]}]}
{"op":"mcm","clk":"993945912","pt":1580547955372,"mc":[{"id":"1.168133548","rc":[{"batl":[[2,9.2,7]],"ltp":8.4,"tv":316.09,"id":15608820},{"batb":[[0,20,5]],"ltp":19.5,"tv":35.14,"id":9193530}]}]}
{"op":"mcm","clk":"993946669","pt":1580547963479,"mc":[{"id":"1.168133548","rc":[{"batb":[[2,19,3.07]],"ltp":19.5,"tv":35.14,"id":9193530}]}]}
{"op":"mcm","clk":"993946888","pt":1580547965472,"mc":[{"id":"1.168133548","rc":[{"batl":[[2,8.8,7]],"ltp":8.4,"tv":316.09,"id":15608820}]}]}
{"op":"mcm","clk":"993947742","pt":1580547974496,"mc":[{"id":"1.168133548","rc":[{"batl":[[2,9.6,15.38]],"ltp":8.4,"tv":316.09,"id":15608820}]}]}
{"op":"mcm","clk":"993947860","pt":1580547975491,"mc":[{"id":"1.168133548","rc":[{"batl":[[1,8.6,22.8]],"ltp":8.4,"tv":316.09,"id":15608820}]}]}
{"op":"mcm","clk":"993948484","pt":1580547981493,"mc":[{"id":"1.168133548","rc":[{"batl":[[2,6.8,1.25]],"ltp":6.0,"tv":1064.34,"id":9417341},{"trd":[[5.8,18.16]],"batb":[[0,5.6,5.89],[1,5.5,7.76],[2,5,55.07]],"batl":[[0,5.8,1.25],[1,6,10],[2,6.2,14.23]],"ltp":5.8,"tv":212.13,"id":8231803},{"trd":[[8,176.64]],"batl":[[0,8.6,24.63],[1,9,1.76],[2,9.2,2]],"ltp":8.0,"tv":659.75,"id":10170404},{"batl":[[2,9.6,23.11]],"ltp":8.4,"tv":316.09,"id":15608820},{"batl":[[2,7,67.5]],"ltp":6.6,"tv":233.32,"id":17352128}],"tv":3524.06}]}
{"op":"mcm","clk":"993948565","pt":1580547982419,"mc":[{"id":"1.168133548","rc":[{"batb":[[0,6,2],[1,5.9,25.31],[2,5.8,17.51]],"batl":[[2,6.6,1.79]],"ltp":6.0,"tv":1064.34,"id":9417341},{"trd":[[7.8,22.8]],"ltp":7.8,"tv":663.75,"id":10170404}],"tv":3528.06}]}
{"op":"mcm","clk":"993948657","pt":1580547983408,"mc":[{"id":"1.168133548","rc":[{"batb":[[1,5.5,13.13]],"ltp":5.8,"tv":212.13,"id":8231803}]}]}
{"op":"mcm","clk":"993948732","pt":1580547984234,"mc":[{"id":"1.168133548","rc":[{"batb":[[1,5.5,7.76]],"ltp":5.8,"tv":212.13,"id":8231803}]}]}
{"op":"mcm","clk":"993949048","pt":1580547987502,"mc":[{"id":"1.168133548","rc":[{"batb":[[1,5.5,4.76],[2,5,58.07]],"ltp":5.8,"tv":212.13,"id":8231803}]}]}
{"op":"mcm","clk":"993949191","pt":1580547989113,"mc":[{"id":"1.168133548","rc":[{"batl":[[0,8.2,7.95],[1,8.4,2],[2,8.6,23.87]],"ltp":7.8,"tv":663.75,"id":10170404},{"batl":[[0,8.4,3.32]],"ltp":8.4,"tv":316.09,"id":15608820}]}]}
{"op":"mcm","clk":"993949667","pt":1580547994208,"mc":[{"id":"1.168133548","rc":[{"batb":[[0,16,14.25],[2,12.5,20]],"ltp":16.5,"tv":47.08,"id":9001159}]}]}
{"op":"mcm","clk":"993949885","pt":1580547996490,"mc":[{"id":"1.168133548","rc":[{"trd":[[8,182.64]],"ltp":8.0,"tv":669.75,"id":10170404},{"trd":[[8.4,28.82]],"batb":[[0,8.4,5.68],[1,7.6,6.25],[2,7.4,5.15]],"batl":[[0,8.6,22.8],[1,9.6,23.11],[2,9.8,26]],"ltp":8.4,"tv":322.72,"id":15608820},{"batl":[[2,7,69.17]],"ltp":6.6,"tv":233.32,"id":17352128}],"tv":3540.7}]}
{"op":"mcm","clk":"993950034","pt":1580547998318,"mc":[{"id":"1.168133548","rc":[{"batb":[[2,6.8,6.03]],"ltp":8.0,"tv":669.75,"id":10170404},{"batb":[[1,7.8,2.6],[2,7.6,11.65]],"ltp":8.4,"tv":322.72,"id":15608820}]}]}
{"op":"mcm","clk":"993950110","pt":1580547999204,"mc":[{"id":"1.168133548","rc":[{"batb":[[2,6.8,3.34]],"ltp":8.0,"tv":669.75,"id":10170404},{"batb":[[1,7.8,7.16]],"batl":[[1,9.6,15.48]],"ltp":8.4,"tv":322.72,"id":15608820}]}]}
{"op":"mcm","clk":"993950215","pt":1580548000426,"mc":[{"id":"1.168133548","rc":[{"batb":[[2,5,8.07]],"ltp":5.8,"tv":212.13,"id":8231803},{"batl":[[2,10,6.87]],"ltp":8.4,"tv":322.72,"id":15608820},{"batb":[[1,15.5,3.21],[2,10,25]],"ltp":16.5,"tv":47.08,"id":9001159}]}]}
{"op":"mcm","clk":"993950575","pt":1580548004419,"mc":[{"id":"1.168133548","rc":[{"batb":[[0,7.8,3],[1,7.6,2.01],[2,7.4,9.15]],"ltp":8.0,"tv":669.75,"id":10170404}]}]}
{"op":"mcm","clk":"993950843","pt":1580548007527,"mc":[{"id":"1.168133548","rc":[{"batb":[[0,16.5,1.07],[1,16,14.25],[2,15.5,3.21]],"ltp":16.5,"tv":47.08,"id":9001159}]}]}
{"op":"mcm","clk":"993951037","pt":1580548009524,"mc":[{"id":"1.168133548","rc":[{"batl":[[1,9.6,23.11]],"ltp":8.4,"tv":322.72,"id":15608820}]}]}
{"op":"mcm","clk":"993951061","pt":1580548009829,"mc":[{"id":"1.168133548","rc":[{"batl":[[1,9.6,30.75]],"ltp":8.4,"tv":322.72,"id":15608820}]}]}
{"op":"mcm","clk":"993952282","pt":1580548024458,"mc":[{"id":"1.168133548","rc":[{"batl":[[0,8.6,15.8],[1,9.2,7],[2,9.6,30.75]],"ltp":8.4,"tv":322.72,"id":15608820}]}]}
{"op":"mcm","clk":"993953145","pt":1580548034550,"mc":[{"id":"1.168133548","rc":[{"trd":[[7.6,11.5],[7.8,28.8]],"batb":[[0,7.4,9.58],[1,6.8,7.89],[2,6.6,10.58]],"ltp":7.6,"tv":678.91,"id":10170404},{"batl":[[1,9.2,14.64]],"ltp":8.4,"tv":322.72,"id":15608820}],"tv":3549.86}]}
{"op":"mcm","clk":"993953173","pt":1580548034865,"mc":[{"id":"1.168133548","rc":[{"trd":[[7.4,18.3],[7.6,12.36]],"batb":[[0,7.4,5.57]],"ltp":7.4,"tv":686.93,"id":10170404}],"tv":3557.88}]}
{"op":"mcm","clk":"993953641","pt":1580548040555,"mc":[{"id":"1.168133548","rc":[{"trd":[[7.4,23.88]],"batb":[[0,7.4,2.78],[2,6.6,9]],"ltp":7.4,"tv":692.51,"id":10170404}],"tv":3563.46}]}
{"op":"mcm","clk":"993953692","pt":1580548041073,"mc":[{"id":"1.168133548","rc":[{"batl":[[2,6.8,2.98]],"ltp":6.0,"tv":1064.34,"id":9417341},{"trd":[[7.4,29.44]],"batb":[[0,6.8,3.34],[1,6.6,13.65],[2,6.4,40.98]],"batl":[[0,8.4,2.76],[1,8.6,23.87],[2,9,1.76]],"ltp":7.4,"tv":698.07,"id":10170404},{"batl":[[2,7,67.5]],"ltp":6.6,"tv":233.32,"id":17352128}],"tv":3569.02}]}
{"op":"mcm","clk":"993953840","pt":1580548042559,"mc":[{"id":"1.168133548","rc":[{"batb":[[0,6.6,9],[1,6.4,40.98],[2,6.2,1.47]],"batl":[[0,8.4,6.06]],"ltp":7.4,"tv":698.07,"id":10170404}]}]}
{"op":"mcm","clk":"993954076","pt":1580548045549,"mc":[{"id":"1.168133548","rc":[{"batl":[[0,8.4,2.76]],"ltp":7.4,"tv":698.07,"id":10170404}]}]}
{"op":"mcm","clk":"993964762","pt":1580548054558,"mc":[{"id":"1.168133548","rc":[{"batl":[[1,8.8,7],[2,9.2,7.64]],"ltp":8.4,"tv":322.72,"id":15608820}]}]}
{"op":"mcm","clk":"993965036","pt":1580548057574,"mc":[{"id":"1.168133548","rc":[{"batb":[[0,16.5,4.1],[2,15.5,1.11]],"ltp":16.5,"tv":47.08,"id":9001159}]}]}
{"op":"mcm","clk":"993965112","pt":1580548058507,"mc":[{"id":"1.168133548","rc":[{"batb":[[0,6.8,3.03],[1,6.6,9],[2,6.4,40.98]],"batl":[[2,9,6.63]],"ltp":7.4,"tv":698.07,"id":10170404}]}]}
{"op":"mcm","clk":"993965292","pt":1580548060491,"mc":[{"id":"1.168133548","rc":[{"batb":[[2,6.4,1.98]],"batl":[[0,8.2,7.95],[1,8.4,2],[2,8.6,23.87]],"ltp":7.4,"tv":698.07,"id":10170404}]}]}
{"op":"mcm","clk":"993965513","pt":1580548063417,"mc":[{"id":"1.168133548","rc":[{"trd":[[6,257.56]],"batb":[[0,5.9,25.31],[1,5.8,17.51],[2,5.7,26.5]],"batl":[[0,6,18],[1,6.2,42.16],[2,6.4,37.94]],"ltp":6.0,"tv":1068.34,"id":9417341}],"tv":3573.02}]}
{"op":"mcm","clk":"993965713","pt":1580548065515,"mc":[{"id":"1.168133548","rc":[{"batl":[[2,6.4,25]],"ltp":6.0,"tv":1068.34,"id":9417341}]}]}
{"op":"mcm","clk":"993966424","pt":1580548074501,"mc":[{"id":"1.168133548","rc":[{"batb":[[0,20,5.82],[1,19.5,1.71]],"ltp":19.5,"tv":35.14,"id":9193530}]}]}
{"op":"mcm","clk":"993966516","pt":1580548075539,"mc":[{"id":"1.168133548","rc":[{"batl":[[0,6,10],[1,6.2,14.23],[2,6.6,6]],"ltp":5.8,"tv":212.13,"id":8231803}]}]}
{"op":"mcm","clk":"993968290","pt":1580548095430,"mc":[{"id":"1.168133548","rc":[{"batl":[[0,8.6,22.8],[1,9.2,7.64],[2,9.6,30.75]],"ltp":8.4,"tv":322.72,"id":15608820}]}]}
{"op":"mcm","clk":"993968643","pt":1580548100051,"mc":[{"id":"1.168133548","rc":[{"trd":[[5.9,160.01]],"batb":[[0,5.9,22.59]],"batl":[[1,6.2,44.09]],"ltp":5.9,"tv":1073.78,"id":9417341},{"batl":[[1,9.6,30.75],[2,10,6.87]],"ltp":8.4,"tv":322.72,"id":15608820}],"tv":3578.46}]}
{"op":"mcm","clk":"993968747","pt":1580548101454,"mc":[{"id":"1.168133548","rc":[{"trd":[[8.4,32.82]],"batb":[[0,8.4,3.68]],"ltp":8.4,"tv":326.72,"id":15608820}],"tv":3582.46}]}
{"op":"mcm","clk":"993969071","pt":1580548105449,"mc":[{"id":"1.168133548","rc":[{"batb":[[1,7.8,2.6]],"batl":[[0,8.6,15.8],[1,9.2,7],[2,9.6,30.75]],"ltp":8.4,"tv":326.72,"id":15608820}]}]}
{"op":"mcm","clk":"993969512","pt":1580548111344,"mc":[{"id":"1.168133548","rc":[{"batl":[[1,9.2,14.64]],"ltp":8.4,"tv":326.72,"id":15608820}]}]}
{"op":"mcm","clk":"993970768","pt":1580548126569,"mc":[{"id":"1.168133548","rc":[{"batl":[[1,6.2,42.16]],"ltp":5.9,"tv":1073.78,"id":9417341}]}]}
{"op":"mcm","clk":"993971574","pt":1580548135568,"mc":[{"id":"1.168133548","rc":[{"batl":[[1,8.8,7],[2,9.2,7.64]],"ltp":8.4,"tv":326.72,"id":15608820}]}]}
{"op":"mcm","clk":"993971839","pt":1580548138479,"mc":[{"id":"1.168133548","rc":[{"trd":[[5.9,205.19]],"batb":[[0,5.8,17.51],[1,5.7,41.06],[2,5.5,20.85]],"batl":[[0,5.9,3.53],[1,6,18],[2,6.2,42.16]],"ltp":5.9,"tv":1118.96,"id":9417341}],"tv":3627.64}]}
{"op":"mcm","clk":"993971954","pt":1580548139567,"mc":[{"id":"1.168133548","rc":[{"trd":[[5.8,277.5]],"batb":[[0,5.8,14.04]],"batl":[[0,6,18],[1,6.2,42.16],[2,6.4,25]],"ltp":5.8,"tv":1125.9,"id":9417341}],"tv":3634.58}]}
{"op":"mcm","clk":"993971987","pt":1580548139882,"mc":[{"id":"1.168133548","rc":[{"batb":[[1,5.7,26.5]],"ltp":5.8,"tv":1125.9,"id":9417341}]}]}
{"op":"mcm","clk":"993972146","pt":1580548141500,"mc":[{"id":"1.168133548","rc":[{"batb":[[2,5.5,17.85]],"ltp":5.8,"tv":1125.9,"id":9417341}]}]}
{"op":"mcm","clk":"993972942","pt":1580548150514,"mc":[{"id":"1.168133548","rc":[{"batl":[[2,7,87.5]],"ltp":6.6,"tv":233.32,"id":17352128}]}]}
{"op":"mcm","clk":"993973249","pt":1580548154510,"mc":[{"id":"1.168133548","rc":[{"batl":[[1,9.2,7.64],[2,9.6,30.75]],"ltp":8.4,"tv":326.72,"id":15608820}]}]}
{"op":"mcm","clk":"993973318","pt":1580548155395,"mc":[{"id":"1.168133548","rc":[{"batl":[[0,8.6,22.8]],"ltp":8.4,"tv":326.72,"id":15608820}]}]}
{"op":"mcm","clk":"993973407","pt":1580548156436,"mc":[{"id":"1.168133548","rc":[{"trd":[[13.5,18.55]],"batl":[[0,13.5,20.72]],"ltp":13.5,"tv":265.6,"id":8429550},{"trd":[[5.8,281.5],[6,283.14]],"batb":[[0,5.8,12.04]],"batl":[[0,6,5.21]],"ltp":5.8,"tv":1155.48,"id":9417341},{"trd":[[6,40.54],[6.2,54.88]],"batl":[[0,6.2,11.85],[1,6.6,6],[2,6.8,100]],"ltp":6.2,"tv":236.89,"id":8231803},{"trd":[[11.5,134.4]],"batl":[[0,11.5,10.44]],"ltp":11.5,"tv":715.27,"id":10616006},{"trd":[[6.4,51.91],[6.6,42],[6.8,24.34]],"batb":[[0,6.4,9.18],[1,5.9,4.4],[2,5.8,8.22]],"batl":[[0,8.4,2.76],[1,8.6,23.87],[2,9,4.86]],"ltp":6.4,"tv":750.07,"id":10170404},{"trd":[[8.6,142.01]],"batl":[[0,8.6,13.88],[1,9.6,30.75],[2,10,6.87]],"ltp":8.6,"tv":344.57,"id":15608820},{"trd":[[17,8.94],[19.5,2.16],[20,3.94]],"batb":[[0,17,1.02],[1,16.5,4.1],[2,16,14.25]],"batl":[[0,20,6.03],[1,24,4.36],[2,25,10]],"ltp":20.0,"tv":55.36,"id":9001159},{"trd":[[25,6.96],[26,0.38]],"batl":[[0,26,2.84],[1,95,2.25],[2,190,2]],"ltp":26.0,"tv":41.06,"id":9193530},{"trd":[[6.6,26.34]],"batl":[[0,6.6,6.83]],"ltp":6.6,"tv":256.56,"id":17352128}],"tv":3820.9}]}
{"op":"mcm","clk":"993973494","pt":1580548157327,"mc":[{"id":"1.168133548","rc":[{"batb":[[1,5.9,8.91],[2,5.8,1.83]],"ltp":6.4,"tv":750.07,"id":10170404},{"batl":[[1,25,10],[2,85,9.08]],"ltp":20.0,"tv":55.36,"id":9001159}]}]}
{"op":"mcm","clk":"993973867","pt":1580548161412,"mc":[{"id":"1.168133548","rc":[{"batb":[[0,21,5.99],[1,20,5],[2,19.5,1.71]],"ltp":26.0,"tv":41.06,"id":9193530}]}]}
{"op":"mcm","clk":"993974089","pt":1580548163533,"mc":[{"id":"1.168133548","rc":[{"trd":[[12.5,28.88],[13,196.03]],"batb":[[0,12,20],[1,11.5,8.3],[2,11,8.25]],"batl":[[0,12.5,58.23],[1,13.5,20.72],[2,17,18.29]],"ltp":12.5,"tv":299.14,"id":8429550},{"batb":[[1,5.5,7.76],[2,5,5.07]],"ltp":6.2,"tv":236.89,"id":8231803},{"batb":[[1,5.9,11.81]],"ltp":6.4,"tv":750.07,"id":10170404}],"tv":3854.44}]}
{"op":"mcm","clk":"993974219","pt":1580548164426,"mc":[{"id":"1.168133548","rc":[{"batl":[[0,6,19.21]],"ltp":5.8,"tv":1155.48,"id":9417341},{"batl":[[0,8.2,5.29],[1,8.4,2],[2,8.6,23.87]],"ltp":6.4,"tv":750.07,"id":10170404},{"batl":[[0,8.6,6.88],[1,9.2,7],[2,9.6,30.75]],"ltp":8.6,"tv":344.57,"id":15608820},{"batb":[[0,21,6.87]],"ltp":26.0,"tv":41.06,"id":9193530}]}]}
{"op":"mcm","clk":"993974343","pt":1580548165537,"mc":[{"id":"1.168133548","rc":[{"batb":[[1,11.5,1.98],[2,11,3.03]],"ltp":12.5,"tv":299.14,"id":8429550},{"batl":[[1,9.2,14.64]],"ltp":8.6,"tv":344.57,"id":15608820}]}]}
{"op":"mcm","clk":"993974438","pt":1580548166426,"mc":[{"id":"1.168133548","rc":[{"batb":[[2,11,6.68]],"ltp":12.5,"tv":299.14,"id":8429550}]}]}
{"op":"mcm","clk":"993974788","pt":1580548169506,"mc":[{"id":"1.168133548","rc":[{"batl":[[1,9.2,7],[2,9.6,23.01]],"ltp":8.6,"tv":344.57,"id":15608820}]}]}
{"op":"mcm","clk":"993974866","pt":1580548170448,"mc":[{"id":"1.168133548","rc":[{"batb":[[0,5.8,13.72]],"ltp":5.8,"tv":1155.48,"id":9417341},{"batb":[[0,5.7,1.98],[1,5.6,5.89],[2,5.5,7.76]],"ltp":6.2,"tv":236.89,"id":8231803},{"batb":[[0,6.6,1.98],[1,6.4,9.18],[2,5.9,11.81]],"ltp":6.4,"tv":750.07,"id":10170404},{"batb":[[0,17,3]],"batl":[[1,25,10.52]],"ltp":20.0,"tv":55.36,"id":9001159},{"batb":[[0,22,2.85],[1,21,5.99],[2,20,5]],"ltp":26.0,"tv":41.06,"id":9193530}]}]}
{"op":"mcm","clk":"993974961","pt":1580548171441,"mc":[{"id":"1.168133548","rc":[{"batb":[[0,12,21.98],[1,11,6.68],[2,9.8,27.29]],"ltp":12.5,"tv":299.14,"id":8429550},{"batb":[[0,6.4,6.34]],"ltp":6.6,"tv":256.56,"id":17352128}]}]}
{"op":"mcm","clk":"993975187","pt":1580548173821,"mc":[{"id":"1.168133548","rc":[{"batb":[[1,21,6.84]],"ltp":26.0,"tv":41.06,"id":9193530}]}]}
{"op":"mcm","clk":"993975741","pt":1580548179537,"mc":[{"id":"1.168133548","rc":[{"batb":[[0,5.7,24.2]],"ltp":6.2,"tv":236.89,"id":8231803},{"batb":[[0,22,7.79],[1,21,1.66]],"ltp":26.0,"tv":41.06,"id":9193530}]}]}
{"op":"mcm","clk":"993975820","pt":1580548180465,"mc":[{"id":"1.168133548","rc":[{"batb":[[2,9.8,1.29]],"ltp":12.5,"tv":299.14,"id":8429550},{"batb":[[0,17,4.69]],"batl":[[1,85,9.6],[2,95,2]],"ltp":20.0,"tv":55.36,"id":9001159},{"batl":[[2,220,9]],"ltp":26.0,"tv":41.06,"id":9193530}]}]}
{"op":"mcm","clk":"993975887","pt":1580548181347,"mc":[{"id":"1.168133548","rc":[{"batl":[[0,20,6.85]],"ltp":20.0,"tv":55.36,"id":9001159}]}]}
{"op":"mcm","clk":"993976160","pt":1580548184535,"mc":[{"id":"1.168133548","rc":[{"batb":[[0,17,12.69],[2,16,6.25]],"ltp":20.0,"tv":55.36,"id":9001159}]}]}
{"op":"mcm","clk":"993976464","pt":1580548188030,"mc":[{"id":"1.168133548","rc":[{"batb":[[1,16.5,3.03]],"ltp":20.0,"tv":55.36,"id":9001159}]}]}
{"op":"mcm","clk":"993976574","pt":1580548189272,"mc":[{"id":"1.168133548","rc":[{"batb":[[2,6,3.13]],"ltp":6.4,"tv":750.07,"id":10170404},{"batl":[[1,6.8,7.73]],"ltp":6.6,"tv":256.56,"id":17352128}]}]}
{"op":"mcm","clk":"993977104","pt":1580548194476,"mc":[{"id":"1.168133548","rc":[{"batl":[[0,8,2],[1,8.2,5.29],[2,8.4,2]],"ltp":6.4,"tv":750.07,"id":10170404}]}]}
{"op":"mcm","clk":"993977189","pt":1580548195561,"mc":[{"id":"1.168133548","rc":[{"batb":[[0,17.5,1.01],[1,17,12.69],[2,16.5,3.03]],"batl":[[1,23,1.15],[2,85,9.08]],"ltp":20.0,"tv":55.36,"id":9001159}]}]}
{"op":"mcm","clk":"993977273","pt":1580548196385,"mc":[{"id":"1.168133548","rc":[{"batb":[[1,17,11]],"ltp":20.0,"tv":55.36,"id":9001159},{"batb":[[0,22,2.85]],"ltp":26.0,"tv":41.06,"id":9193530}]}]}
{"op":"mcm","clk":"993977378","pt":1580548197574,"mc":[{"id":"1.168133548","rc":[{"batb":[[0,17.5,2.65]],"ltp":20.0,"tv":55.36,"id":9001159}]}]}
{"op":"mcm","clk":"993978023","pt":1580548203499,"mc":[{"id":"1.168133548","rc":[{"batb":[[1,11,6.94]],"ltp":12.5,"tv":299.14,"id":8429550},{"batb":[[1,21,2.4]],"ltp":26.0,"tv":41.06,"id":9193530}]}]}
{"op":"mcm","clk":"993978384","pt":1580548206455,"mc":[{"id":"1.168133548","rc":[{"batb":[[2,19,2.14]],"ltp":26.0,"tv":41.06,"id":9193530}]}]}
{"op":"mcm","clk":"993978498","pt":1580548207486,"mc":[{"id":"1.168133548","rc":[{"batl":[[2,8.6,23.87]],"ltp":6.4,"tv":750.07,"id":10170404}]}]}
{"op":"mcm","clk":"993979658","pt":1580548218416,"mc":[{"id":"1.168133548","rc":[{"batb":[[0,18,5.56],[1,17.5,2.65],[2,17,11]],"batl":[[0,19.5,1.37],[1,20,6.03],[2,23,1.15]],"ltp":20.0,"tv":55.36,"id":9001159},{"batb":[[0,23,4.35],[1,22,2.85],[2,21,2.4]],"ltp":26.0,"tv":41.06,"id":9193530}]}]}
{"op":"mcm","clk":"993979982","pt":1580548221485,"mc":[{"id":"1.168133548","rc":[{"batb":[[0,23,5.15],[1,22,1.98]],"ltp":26.0,"tv":41.06,"id":9193530}]}]}
{"op":"mcm","clk":"993980221","pt":1580548223510,"mc":[{"id":"1.168133548","rc":[{"batl":[[1,8.8,7]],"ltp":8.6,"tv":344.57,"id":15608820}]}]}
{"op":"mcm","clk":"993981080","pt":1580548231492,"mc":[{"id":"1.168133548","rc":[{"batb":[[0,5.7,1.98]],"ltp":6.2,"tv":236.89,"id":8231803},{"batb":[[1,17.5,1.01]],"ltp":20.0,"tv":55.36,"id":9001159}]}]}
{"op":"mcm","clk":"993981180","pt":1580548232525,"mc":[{"id":"1.168133548","rc":[{"batb":[[2,5.5,10.48]],"ltp":6.2,"tv":236.89,"id":8231803}]}]}
{"op":"mcm","clk":"993981905","pt":1580548239510,"mc":[{"id":"1.168133548","rc":[{"batb":[[2,5.5,7.76]],"ltp":6.2,"tv":236.89,"id":8231803},{"trd":[[8.4,35.54]],"batb":[[0,8.4,2.32]],"batl":[[1,8.8,8.29]],"ltp":8.4,"tv":347.29,"id":15608820}],"tv":3857.16}]}
{"op":"mcm","clk":"993982103","pt":1580548241529,"mc":[{"id":"1.168133548","rc":[{"batb":[[0,5.7,5.01],[2,5.5,7]],"ltp":6.2,"tv":236.89,"id":8231803},{"batl":[[2,8.4,5.45]],"ltp":6.4,"tv":750.07,"id":10170404},{"trd":[[8.6,151.17]],"batl":[[0,8.6,2.3]],"ltp":8.6,"tv":356.45,"id":15608820},{"batl":[[0,95,2.25],[1,210,3.03]],"ltp":26.0,"tv":41.06,"id":9193530}],"tv":3866.32}]}
{"op":"mcm","clk":"993982214","pt":1580548242521,"mc":[{"id":"1.168133548","rc":[{"batl":[[2,8.4,9.74]],"ltp":6.4,"tv":750.07,"id":10170404},{"batl":[[0,8.6,9.3],[1,8.8,1.29]],"ltp":8.6,"tv":356.45,"id":15608820}]}]}
{"op":"mcm","clk":"993982296","pt":1580548243449,"mc":[{"id":"1.168133548","rc":[{"batb":[[2,7.6,6.25]],"ltp":8.6,"tv":356.45,"id":15608820},{"batl":[[0,90,2.35],[1,95,4.1],[2,210,3.03]],"ltp":26.0,"tv":41.06,"id":9193530}]}]}
{"op":"mcm","clk":"993982506","pt":1580548245334,"mc":[{"id":"1.168133548","rc":[{"batl":[[0,95,2.25],[1,200,2.1]],"ltp":26.0,"tv":41.06,"id":9193530}]}]}
{"op":"mcm","clk":"993982713","pt":1580548247559,"mc":[{"id":"1.168133548","rc":[{"batl":[[0,8,6.26],[2,8.4,4.28]],"ltp":6.4,"tv":750.07,"id":10170404},{"batl":[[2,9.4,4.2]],"ltp":8.6,"tv":356.45,"id":15608820}]}]}
{"op":"mcm","clk":"993982838","pt":1580548248547,"mc":[{"id":"1.168133548","rc":[{"batl":[[1,190,3.03],[2,200,2.1]],"ltp":26.0,"tv":41.06,"id":9193530}]}]}
{"op":"mcm","clk":"993983690","pt":1580548256348,"mc":[{"id":"1.168133548","rc":[{"batl":[[2,12.5,7.99]],"ltp":11.5,"tv":715.27,"id":10616006},{"batl":[[1,8.2,13.24]],"ltp":6.4,"tv":750.07,"id":10170404},{"batl":[[1,9.2,6.86],[2,9.4,10.66]],"ltp":8.6,"tv":356.45,"id":15608820}]}]}
{"op":"mcm","clk":"993983810","pt":1580548257543,"mc":[{"id":"1.168133548","rc":[{"batl":[[2,8.6,23.87]],"ltp":6.4,"tv":750.07,"id":10170404}]}]}
{"op":"mcm","clk":"993984025","pt":1580548259472,"mc":[{"id":"1.168133548","rc":[{"batl":[[1,8.2,8.72]],"ltp":6.4,"tv":750.07,"id":10170404}]}]}
{"op":"mcm","clk":"993984146","pt":1580548260565,"mc":[{"id":"1.168133548","rc":[{"batl":[[0,7.8,4.76],[1,8,6.26],[2,8.2,8.72]],"ltp":6.4,"tv":750.07,"id":10170404}]}]}
{"op":"mcm","clk":"993984343","pt":1580548262483,"mc":[{"id":"1.168133548","rc":[{"batb":[[0,23,6.6],[2,19.5,1.73]],"ltp":26.0,"tv":41.06,"id":9193530}]}]}
{"op":"mcm","clk":"993984785","pt":1580548266448,"mc":[{"id":"1.168133548","rc":[{"batb":[[0,24,5.33],[1,23,5.8],[2,22,1.98]],"ltp":26.0,"tv":41.06,"id":9193530}]}]}
{"op":"mcm","clk":"993985821","pt":1580548277998,"mc":[{"id":"1.168133548","rc":[{"batb":[[0,24,6.07]],"ltp":26.0,"tv":41.06,"id":9193530}]}]}
{"op":"mcm","clk":"993986136","pt":1580548281388,"mc":[{"id":"1.168133548","rc":[{"batl":[[0,8.6,2.3],[1,8.8,7],[2,9.2,6.86]],"ltp":8.6,"tv":356.45,"id":15608820}]}]}
{"op":"mcm","clk":"993987722","pt":1580548296516,"mc":[{"id":"1.168133548","rc":[{"batb":[[0,6.6,4.6]],"batl":[[0,7.6,2.09],[1,7.8,4.76],[2,8,6.26]],"ltp":6.4,"tv":750.07,"id":10170404}]}]}
{"op":"mcm","clk":"993988203","pt":1580548301521,"mc":[{"id":"1.168133548","rc":[{"batl":[[0,8.6,9.3],[1,9.2,6.86],[2,9.4,10.66]],"ltp":8.6,"tv":356.45,"id":15608820}]}]}
{"op":"mcm","clk":"993988730","pt":1580548306844,"mc":[{"id":"1.168133548","rc":[{"batl":[[0,90,7.84],[1,95,2],[2,190,3.03]],"ltp":26.0,"tv":41.06,"id":9193530}]}]}
{"op":"mcm","clk":"993989338","pt":1580548311550,"mc":[{"id":"1.168133548","rc":[{"batl":[[2,9.4,4.2]],"ltp":8.6,"tv":356.45,"id":15608820}]}]}
{"op":"mcm","clk":"993990112","pt":1580548320373,"mc":[{"id":"1.168133548","rc":[{"batl":[[1,9.2,13.73]],"ltp":8.6,"tv":356.45,"id":15608820}]}]}
{"op":"mcm","clk":"993990380","pt":1580548322474,"mc":[{"id":"1.168133548","rc":[{"batb":[[0,25,1.33],[1,24,6.07],[2,23,4.35]],"ltp":26.0,"tv":41.06,"id":9193530}]}]}
{"op":"mcm","clk":"993992374","pt":1580548340478,"mc":[{"id":"1.168133548","rc":[{"batl":[[0,8.6,2.3],[1,8.8,7],[2,9.2,6.86]],"ltp":8.6,"tv":356.45,"id":15608820}]}]}
{"op":"mcm","clk":"993993349","pt":1580548349522,"mc":[{"id":"1.168133548","rc":[{"batl":[[1,9.4,4.2],[2,9.6,7.64]],"ltp":8.6,"tv":356.45,"id":15608820},{"trd":[[18,11.12]],"batb":[[0,17.5,1.01],[1,17,11],[2,16.5,7.58]],"batl":[[0,20,6.85],[1,23,1.15],[2,36,7]],"ltp":18.0,"tv":66.48,"id":9001159}],"tv":3877.44}]}
{"op":"mcm","clk":"993993440","pt":1580548350518,"mc":[{"id":"1.168133548","rc":[{"batl":[[0,8.6,9.3]],"ltp":8.6,"tv":356.45,"id":15608820}]}]}
{"op":"mcm","clk":"993993556","pt":1580548351512,"mc":[{"id":"1.168133548","rc":[{"batb":[[2,16.5,3.03]],"ltp":18.0,"tv":66.48,"id":9001159}]}]}
{"op":"mcm","clk":"993994595","pt":1580548361135,"mc":[{"id":"1.168133548","rc":[{"batl":[[2,65,4.08]],"ltp":18.0,"tv":66.48,"id":9001159}]}]}
{"op":"mcm","clk":"993995417","pt":1580548368541,"mc":[{"id":"1.168133548","rc":[{"batl":[[0,8.6,2.3]],"ltp":8.6,"tv":356.45,"id":15608820}]}]}
{"op":"mcm","clk":"993995508","pt":1580548369478,"mc":[{"id":"1.168133548","rc":[{"batl":[[1,9.2,13.26],[2,9.4,10.57]],"ltp":8.6,"tv":356.45,"id":15608820}]}]}
{"op":"mcm","clk":"993996264","pt":1580548376484,"mc":[{"id":"1.168133548","rc":[{"batl":[[1,9.2,7],[2,9.4,4.2]],"ltp":8.6,"tv":356.45,"id":15608820}]}]}
{"op":"mcm","clk":"993996379","pt":1580548377480,"mc":[{"id":"1.168133548","rc":[{"batl":[[1,6.8,6]],"ltp":6.6,"tv":256.56,"id":17352128}]}]}
{"op":"mcm","clk":"993997670","pt":1580548388493,"mc":[{"id":"1.168133548","rc":[{"batl":[[1,8.8,7]],"ltp":8.6,"tv":356.45,"id":15608820}]}]}
{"op":"mcm","clk":"993998015","pt":1580548391572,"mc":[{"id":"1.168133548","rc":[{"batl":[[0,7.6,5.36],[2,8,2]],"ltp":6.4,"tv":750.07,"id":10170404},{"batl":[[2,85,9.08]],"ltp":18.0,"tv":66.48,"id":9001159}]}]}
{"op":"mcm","clk":"993998077","pt":1580548392211,"mc":[{"id":"1.168133548","rc":[{"batl":[[0,7.6,3.27]],"ltp":6.4,"tv":750.07,"id":10170404},{"batl":[[0,85,3.27],[1,90,7.6],[2,95,2]],"ltp":26.0,"tv":41.06,"id":9193530}]}]}
{"op":"mcm","clk":"993998232","pt":1580548393483,"mc":[{"id":"1.168133548","rc":[{"batl":[[1,8,2],[2,8.2,8.72]],"ltp":6.4,"tv":750.07,"id":10170404},{"batl":[[0,85,3.5]],"ltp":26.0,"tv":41.06,"id":9193530}]}]}
{"op":"mcm","clk":"993999816","pt":1580548407527,"mc":[{"id":"1.168133548","rc":[{"batl":[[1,9.4,4.2],[2,9.6,7.64]],"ltp":8.6,"tv":356.45,"id":15608820}]}]}
{"op":"mcm","clk":"993999928","pt":1580548408520,"mc":[{"id":"1.168133548","rc":[{"batl":[[2,8.6,24.63]],"ltp":6.4,"tv":750.07,"id":10170404},{"batl":[[0,8.6,9.3]],"ltp":8.6,"tv":356.45,"id":15608820}]}]}
{"op":"mcm","clk":"994000163","pt":1580548410501,"mc":[{"id":"1.168133548","rc":[{"batl":[[2,12.5,5]],"ltp":11.5,"tv":715.27,"id":10616006},{"batl":[[1,9.2,3.21],[2,9.4,4.2]],"ltp":8.6,"tv":356.45,"id":15608820}]}]}
{"op":"mcm","clk":"994000285","pt":1580548411544,"mc":[{"id":"1.168133548","rc":[{"batl":[[1,9.2,10.07]],"ltp":8.6,"tv":356.45,"id":15608820}]}]}
{"op":"mcm","clk":"994000864","pt":1580548416502,"mc":[{"id":"1.168133548","rc":[{"batl":[[0,20,6.03]],"ltp":18.0,"tv":66.48,"id":9001159}]}]}
{"op":"mcm","clk":"994000988","pt":1580548417541,"mc":[{"id":"1.168133548","rc":[{"batl":[[0,8.6,2.3],[1,8.8,7],[2,9.2,10.07]],"ltp":8.6,"tv":356.45,"id":15608820}]}]}
{"op":"mcm","clk":"994003365","pt":1580548440457,"mc":[{"id":"1.168133548","rc":[{"trd":[[5.7,6.78]],"batb":[[0,5.7,1.62]],"ltp":5.7,"tv":243.67,"id":8231803},{"batl":[[2,9.4,4.2]],"ltp":8.6,"tv":356.45,"id":15608820}],"tv":3884.22}]}
{"op":"mcm","clk":"994003714","pt":1580548444142,"mc":[{"id":"1.168133548","rc":[{"batb":[[2,5.5,4]],"ltp":5.7,"tv":243.67,"id":8231803}]}]}
{"op":"mcm","clk":"994003940","pt":1580548446469,"mc":[{"id":"1.168133548","rc":[{"batb":[[0,25,2.02]],"ltp":26.0,"tv":41.06,"id":9193530}]}]}
{"op":"mcm","clk":"994005395","pt":1580548459565,"mc":[{"id":"1.168133548","rc":[{"batl":[[2,17,19.06]],"ltp":12.5,"tv":299.14,"id":8429550}]}]}
{"op":"mcm","clk":"994006904","pt":1580548473490,"mc":[{"id":"1.168133548","rc":[{"batl":[[2,17,18.29]],"ltp":12.5,"tv":299.14,"id":8429550}]}]}
{"op":"mcm","clk":"994009364","pt":1580548496532,"mc":[{"id":"1.168133548","rc":[{"batl":[[0,8.6,9.3],[1,9.4,4.2],[2,9.6,7.64]],"ltp":8.6,"tv":356.45,"id":15608820}]}]}
{"op":"mcm","clk":"994011157","pt":1580548511574,"mc":[{"id":"1.168133548","rc":[{"batl":[[1,6.6,6.55]],"ltp":5.7,"tv":243.67,"id":8231803},{"batl":[[0,8,2],[1,8.4,6.21],[2,8.6,23.87]],"ltp":6.4,"tv":750.07,"id":10170404}]}]}
{"op":"mcm","clk":"994011333","pt":1580548513074,"mc":[{"id":"1.168133548","rc":[{"batl":[[1,8.4,11.09]],"ltp":6.4,"tv":750.07,"id":10170404},{"batl":[[1,9.2,5.3],[2,9.4,10.45]],"ltp":8.6,"tv":356.45,"id":15608820}]}]}
{"op":"mcm","clk":"994011755","pt":1580548516562,"mc":[{"id":"1.168133548","rc":[{"batl":[[0,8.6,2.3],[1,9.2,12.3]],"ltp":8.6,"tv":356.45,"id":15608820}]}]}
{"op":"mcm","clk":"994011765","pt":1580548516662,"mc":[{"id":"1.168133548","rc":[{"batl":[[1,9.2,18.56]],"ltp":8.6,"tv":356.45,"id":15608820}]}]}
{"op":"mcm","clk":"994012890","pt":1580548526501,"mc":[{"id":"1.168133548","rc":[{"batl":[[1,8.8,7],[2,9.2,11.56]],"ltp":8.6,"tv":356.45,"id":15608820}]}]}
{"op":"mcm","clk":"994013198","pt":1580548528964,"mc":[{"id":"1.168133548","rc":[{"batl":[[2,9.4,4.2]],"ltp":8.6,"tv":356.45,"id":15608820},{"batl":[[1,85,9.08],[2,95,2]],"ltp":18.0,"tv":66.48,"id":9001159}]}]}
{"op":"mcm","clk":"994013385","pt":1580548530481,"mc":[{"id":"1.168133548","rc":[{"batl":[[0,8,6.63]],"ltp":6.4,"tv":750.07,"id":10170404}]}]}
{"op":"mcm","clk":"994013515","pt":1580548531389,"mc":[{"id":"1.168133548","rc":[{"batb":[[0,10.5,12.51]],"ltp":11.5,"tv":715.27,"id":10616006}]}]}
{"op":"mcm","clk":"994013636","pt":1580548532483,"mc":[{"id":"1.168133548","rc":[{"batl":[[1,95,2],[2,190,2]],"ltp":26.0,"tv":41.06,"id":9193530}]}]}
{"op":"mcm","clk":"994013790","pt":1580548533896,"mc":[{"id":"1.168133548","rc":[{"batl":[[1,8.2,8.72],[2,8.4,5.45]],"ltp":6.4,"tv":750.07,"id":10170404}]}]}
{"op":"mcm","clk":"994014695","pt":1580548541409,"mc":[{"id":"1.168133548","rc":[{"batl":[[2,200,2.1]],"ltp":26.0,"tv":41.06,"id":9193530}]}]}
{"op":"mcm","clk":"994015408","pt":1580548546515,"mc":[{"id":"1.168133548","rc":[{"batl":[[0,8.6,9.3],[1,9.4,4.2],[2,9.6,7.64]],"ltp":8.6,"tv":356.45,"id":15608820}]}]}
{"op":"mcm","clk":"994015546","pt":1580548547502,"mc":[{"id":"1.168133548","rc":[{"batl":[[0,80,8.07],[1,85,3.03],[2,95,2]],"ltp":26.0,"tv":41.06,"id":9193530}]}]}
{"op":"mcm","clk":"994016090","pt":1580548552396,"mc":[{"id":"1.168133548","rc":[{"batl":[[0,7.6,3],[1,7.8,3],[2,8,6.63]],"ltp":6.4,"tv":750.07,"id":10170404}]}]}
{"op":"mcm","clk":"994016222","pt":1580548553525,"mc":[{"id":"1.168133548","rc":[{"batl":[[2,8,9.63]],"ltp":6.4,"tv":750.07,"id":10170404}]}]}
{"op":"mcm","clk":"994016320","pt":1580548554389,"mc":[{"id":"1.168133548","rc":[{"batl":[[1,9.2,5.3],[2,9.4,10.45]],"ltp":8.6,"tv":356.45,"id":15608820}]}]}
{"op":"mcm","clk":"994017780","pt":1580548568435,"mc":[{"id":"1.168133548","rc":[{"batl":[[2,8,5]],"ltp":6.4,"tv":750.07,"id":10170404}]}]}
{"op":"mcm","clk":"994019545","pt":1580548583794,"mc":[{"id":"1.168133548","rc":[{"batl":[[1,9.2,12.17]],"ltp":8.6,"tv":356.45,"id":15608820}]}]}
{"op":"mcm","clk":"994020365","pt":1580548590285,"mc":[{"id":"1.168133548","rc":[{"batl":[[2,7,2]],"ltp":5.7,"tv":243.67,"id":8231803}]}]}
{"op":"mcm","clk":"994020596","pt":1580548592298,"mc":[{"id":"1.168133548","rc":[{"batl":[[0,6,100],[1,6.2,11.85],[2,6.6,6.55]],"ltp":5.7,"tv":243.67,"id":8231803}]}]}
{"op":"mcm","clk":"994020839","pt":1580548594551,"mc":[{"id":"1.168133548","rc":[{"batl":[[2,7,2.55]],"ltp":5.7,"tv":243.67,"id":8231803}]}]}
{"op":"mcm","clk":"994022084","pt":1580548605501,"mc":[{"id":"1.168133548","rc":[{"batl":[[0,8.6,2.3],[1,8.8,7],[2,9.2,5.3]],"ltp":8.6,"tv":356.45,"id":15608820}]}]}
{"op":"mcm","clk":"994023050","pt":1580548612473,"mc":[{"id":"1.168133548","rc":[{"trd":[[5.8,293.5]],"batb":[[0,5.8,7.72]],"ltp":5.8,"tv":1167.48,"id":9417341}],"tv":3896.22}]}
{"op":"mcm","clk":"994023209","pt":1580548613314,"mc":[{"id":"1.168133548","rc":[{"batl":[[2,9.4,4.2]],"ltp":8.6,"tv":356.45,"id":15608820}]}]}
{"op":"mcm","clk":"994023553","pt":1580548615528,"mc":[{"id":"1.168133548","rc":[{"batl":[[0,8.6,9.3],[1,9.4,4.2],[2,9.6,7.64]],"ltp":8.6,"tv":356.45,"id":15608820}]}]}
{"op":"mcm","clk":"994024590","pt":1580548625502,"mc":[{"id":"1.168133548","rc":[{"batl":[[0,8.6,2.3],[1,9.2,7],[2,9.4,4.2]],"ltp":8.6,"tv":356.45,"id":15608820}]}]}
{"op":"mcm","clk":"994025363","pt":1580548631513,"mc":[{"id":"1.168133548","rc":[{"batl":[[1,9,3.38],[2,9.2,7]],"ltp":8.6,"tv":356.45,"id":15608820},{"batl":[[1,95,2],[2,190,2]],"ltp":26.0,"tv":41.06,"id":9193530}]}]}
{"op":"mcm","clk":"994025524","pt":1580548632405,"mc":[{"id":"1.168133548","rc":[{"batl":[[0,75,3.27],[1,80,7.82],[2,95,2]],"ltp":26.0,"tv":41.06,"id":9193530}]}]}
{"op":"mcm","clk":"994027221","pt":1580548646524,"mc":[{"id":"1.168133548","rc":[{"batl":[[1,80,7.6]],"ltp":26.0,"tv":41.06,"id":9193530}]}]}
{"op":"mcm","clk":"994027337","pt":1580548647517,"mc":[{"id":"1.168133548","rc":[{"batl":[[0,75,3.53]],"ltp":26.0,"tv":41.06,"id":9193530}]}]}
{"op":"mcm","clk":"994029258","pt":1580548664449,"mc":[{"id":"1.168133548","rc":[{"batl":[[1,8.8,7],[2,9,3.38]],"ltp":8.6,"tv":356.45,"id":15608820}]}]}
{"op":"mcm","clk":"994030389","pt":1580548674551,"mc":[{"id":"1.168133548","rc":[{"batl":[[0,8.6,9.3],[1,9,3.38],[2,9.6,7.64]],"ltp":8.6,"tv":356.45,"id":15608820}]}]}
{"op":"mcm","clk":"994032915","pt":1580548698331,"mc":[{"id":"1.168133548","rc":[{"batl":[[0,6,102]],"ltp":5.7,"tv":243.67,"id":8231803},{"batb":[[0,7,2],[1,6.6,4.6],[2,6.4,9.18]],"ltp":6.4,"tv":750.07,"id":10170404}]}]}
{"op":"mcm","clk":"994033498","pt":1580548704306,"mc":[{"id":"1.168133548","rc":[{"batl":[[0,8.6,2.3],[1,8.8,7],[2,9,3.38]],"ltp":8.6,"tv":356.45,"id":15608820}]}]}
{"op":"mcm","clk":"994034597","pt":1580548713530,"mc":[{"id":"1.168133548","rc":[{"batl":[[1,9,3.38],[2,9.6,7.64]],"ltp":8.6,"tv":356.45,"id":15608820}]}]}
{"op":"mcm","clk":"994034605","pt":1580548713640,"mc":[{"id":"1.168133548","rc":[{"batl":[[0,8.6,9.3]],"ltp":8.6,"tv":356.45,"id":15608820}]}]}
{"op":"mcm","clk":"994034926","pt":1580548716543,"mc":[{"id":"1.168133548","rc":[{"batb":[[0,7.2,3],[1,7,2],[2,6.6,4.6]],"ltp":6.4,"tv":750.07,"id":10170404}]}]}
{"op":"mcm","clk":"994035036","pt":1580548717528,"mc":[{"id":"1.168133548","rc":[{"batb":[[2,6.6,6.88]],"ltp":6.4,"tv":750.07,"id":10170404}]}]}
{"op":"mcm","clk":"994035770","pt":1580548724447,"mc":[{"id":"1.168133548","rc":[{"batl":[[0,8.6,2.3],[1,8.8,7],[2,9,3.38]],"ltp":8.6,"tv":356.45,"id":15608820}]}]}
{"op":"mcm","clk":"994036201","pt":1580548728356,"mc":[{"id":"1.168133548","rc":[{"trd":[[10.5,154.28]],"batb":[[0,10,9.58],[1,9.8,2.46],[2,9.6,2]],"ltp":10.5,"tv":740.29,"id":10616006}],"tv":3921.24}]}
{"op":"mcm","clk":"994036324","pt":1580548729550,"mc":[{"id":"1.168133548","rc":[{"batb":[[1,9.8,6.53]],"ltp":10.5,"tv":740.29,"id":10616006}]}]}
{"op":"mcm","clk":"994036528","pt":1580548731358,"mc":[{"id":"1.168133548","rc":[{"batb":[[1,9.6,2],[2,9.2,4.4]],"ltp":10.5,"tv":740.29,"id":10616006}]}]}
{"op":"mcm","clk":"994036763","pt":1580548733548,"mc":[{"id":"1.168133548","rc":[{"batb":[[2,9.4,6.04]],"ltp":10.5,"tv":740.29,"id":10616006},{"batl":[[0,8.6,9.3],[1,9,3.38],[2,9.6,7.64]],"ltp":8.6,"tv":356.45,"id":15608820}]}]}
{"op":"mcm","clk":"994038508","pt":1580548750568,"mc":[{"id":"1.168133548","rc":[{"batl":[[2,8,3]],"ltp":6.4,"tv":750.07,"id":10170404}]}]}
{"op":"mcm","clk":"994039834","pt":1580548763518,"mc":[{"id":"1.168133548","rc":[{"batl":[[0,8.6,2.3],[1,8.8,7],[2,9,3.38]],"ltp":8.6,"tv":356.45,"id":15608820}]}]}
{"op":"mcm","clk":"994039942","pt":1580548764505,"mc":[{"id":"1.168133548","rc":[{"batl":[[0,6,5.21]],"ltp":5.8,"tv":1167.48,"id":9417341}]}]}
{"op":"mcm","clk":"994040079","pt":1580548765907,"mc":[{"id":"1.168133548","rc":[{"batl":[[0,8.6,5.47],[2,9.6,7.64]],"ltp":8.6,"tv":356.45,"id":15608820}]}]}
{"op":"mcm","clk":"994040773","pt":1580548772491,"mc":[{"id":"1.168133548","rc":[{"batl":[[0,6,19.21]],"ltp":5.8,"tv":1167.48,"id":9417341},{"batl":[[1,95,2],[2,190,2]],"ltp":26.0,"tv":41.06,"id":9193530}]}]}
{"op":"mcm","clk":"994041389","pt":1580548778525,"mc":[{"id":"1.168133548","rc":[{"trd":[[6,303.14]],"batb":[[0,5.9,4.87],[1,5.8,7.72],[2,5.7,26.5]],"batl":[[0,6,9.21]],"ltp":6.0,"tv":1187.48,"id":9417341}],"tv":3941.24}]}
{"op":"mcm","clk":"994041671","pt":1580548781550,"mc":[{"id":"1.168133548","rc":[{"trd":[[7.2,17.89]],"batb":[[0,7,2],[1,6.6,6.88],[2,6.4,9.18]],"ltp":7.2,"tv":756.07,"id":10170404}],"tv":3947.24}]}
{"op":"mcm","clk":"994041760","pt":1580548782540,"mc":[{"id":"1.168133548","rc":[{"batl":[[2,200,2.1]],"ltp":26.0,"tv":41.06,"id":9193530}]}]}
{"op":"mcm","clk":"994041871","pt":1580548783429,"mc":[{"id":"1.168133548","rc":[{"batl":[[0,8.6,12.47],[1,9.6,7.64],[2,10,6.87]],"ltp":8.6,"tv":356.45,"id":15608820}]}]}
{"op":"mcm","clk":"994042291","pt":1580548787436,"mc":[{"id":"1.168133548","rc":[{"batl":[[0,70,8.1],[1,75,3.03],[2,95,2]],"ltp":26.0,"tv":41.06,"id":9193530}]}]}
{"op":"mcm","clk":"994042859","pt":1580548792950,"mc":[{"id":"1.168133548","rc":[{"batl":[[0,8.6,5.47],[1,9.2,7],[2,9.6,7.64]],"ltp":8.6,"tv":356.45,"id":15608820}]}]}
{"op":"mcm","clk":"994043937","pt":1580548803446,"mc":[{"id":"1.168133548","rc":[{"batl":[[1,8.8,7]],"ltp":8.6,"tv":356.45,"id":15608820}]}]}
{"op":"mcm","clk":"994044734","pt":1580548811552,"mc":[{"id":"1.168133548","rc":[{"batb":[[1,6.6,4.6]],"ltp":7.2,"tv":756.07,"id":10170404}]}]}
{"op":"mcm","clk":"994044905","pt":1580548813481,"mc":[{"id":"1.168133548","rc":[{"batl":[[1,9.6,7.64],[2,10,6.87]],"ltp":8.6,"tv":356.45,"id":15608820}]}]}
{"op":"mcm","clk":"994045004","pt":1580548814563,"mc":[{"id":"1.168133548","rc":[{"batl":[[0,8.6,12.47]],"ltp":8.6,"tv":356.45,"id":15608820}]}]}
{"op":"mcm","clk":"994046337","pt":1580548828506,"mc":[{"id":"1.168133548","rc":[{"batl":[[0,5.9,1.93],[1,6,102],[2,6.2,11.85]],"ltp":5.7,"tv":243.67,"id":8231803}]}]}
{"op":"mcm","clk":"994046390","pt":1580548829084,"mc":[{"id":"1.168133548","rc":[{"batl":[[0,6,102],[1,6.2,11.85],[2,7,2.55]],"ltp":5.7,"tv":243.67,"id":8231803}]}]}
{"op":"mcm","clk":"994046826","pt":1580548833531,"mc":[{"id":"1.168133548","rc":[{"batl":[[0,8.6,5.47],[1,9.2,7],[2,9.6,7.64]],"ltp":8.6,"tv":356.45,"id":15608820}]}]}
{"op":"mcm","clk":"994046922","pt":1580548834521,"mc":[{"id":"1.168133548","rc":[{"batb":[[2,9.4,12.17]],"ltp":10.5,"tv":740.29,"id":10616006},{"batl":[[1,9.2,10.29]],"ltp":8.6,"tv":356.45,"id":15608820}]}]}
{"op":"mcm","clk":"994049877","pt":1580548862077,"mc":[{"id":"1.168133548","rc":[{"trd":[[12,6.99]],"batb":[[0,12,21.8]],"ltp":12.0,"tv":299.51,"id":8429550},{"trd":[[5.9,205.97]],"batb":[[0,5.9,4.48]],"ltp":5.9,"tv":1188.25,"id":9417341},{"trd":[[8.4,36.08]],"batb":[[0,8.4,2.05]],"ltp":8.4,"tv":356.99,"id":15608820}],"tv":3948.92}]}
{"op":"mcm","clk":"994050905","pt":1580548872394,"mc":[{"id":"1.168133548","rc":[{"batb":[[0,7,22]],"ltp":7.2,"tv":756.07,"id":10170404}]}]}
{"op":"mcm","clk":"994051311","pt":1580548876502,"mc":[{"id":"1.168133548","rc":[{"batl":[[0,8.6,2.3],[1,9,3.94],[2,9.2,10.29]],"ltp":8.4,"tv":356.99,"id":15608820}]}]}
{"op":"mcm","clk":"994051451","pt":1580548877390,"mc":[{"id":"1.168133548","rc":[{"batl":[[0,65,3.27],[1,70,7.86]],"ltp":26.0,"tv":41.06,"id":9193530}]}]}
{"op":"mcm","clk":"994051982","pt":1580548882504,"mc":[{"id":"1.168133548","rc":[{"batl":[[1,8.8,7],[2,9,3.94]],"ltp":8.4,"tv":356.99,"id":15608820}]}]}
{"op":"mcm","clk":"994053005","pt":1580548892490,"mc":[{"id":"1.168133548","rc":[{"batl":[[0,65,3.57],[1,70,7.6]],"ltp":26.0,"tv":41.06,"id":9193530}]}]}
{"op":"mcm","clk":"994055102","pt":1580548912520,"mc":[{"id":"1.168133548","rc":[{"trd":[[6,60.54]],"batl":[[0,6,92]],"ltp":6.0,"tv":263.67,"id":8231803}],"tv":3968.92}]}
{"op":"mcm","clk":"994055555","pt":1580548917320,"mc":[{"id":"1.168133548","rc":[{"batb":[[0,7.2,2.39],[1,7,22],[2,6.6,1.98]],"ltp":7.2,"tv":756.07,"id":10170404}]}]}
{"op":"mcm","clk":"994055673","pt":1580548918570,"mc":[{"id":"1.168133548","rc":[{"batb":[[2,5.5,7]],"ltp":6.0,"tv":263.67,"id":8231803}]}]}
{"op":"mcm","clk":"994056070","pt":1580548922434,"mc":[{"id":"1.168133548","rc":[{"batl":[[0,8.6,9.3],[1,9,3.94],[2,9.6,7.64]],"ltp":8.4,"tv":356.99,"id":15608820}]}]}
{"op":"mcm","clk":"994058066","pt":1580548941571,"mc":[{"id":"1.168133548","rc":[{"batl":[[0,8.6,2.3],[1,8.8,7],[2,9,3.94]],"ltp":8.4,"tv":356.99,"id":15608820}]}]}
{"op":"mcm","clk":"994059022","pt":1580548951389,"mc":[{"id":"1.168133548","rc":[{"batl":[[0,8.6,9.3],[1,9,3.94],[2,9.6,7.64]],"ltp":8.4,"tv":356.99,"id":15608820}]}]}
{"op":"mcm","clk":"994070226","pt":1580548961373,"mc":[{"id":"1.168133548","rc":[{"batl":[[0,8.6,2.3],[1,8.8,7],[2,9,3.94]],"ltp":8.4,"tv":356.99,"id":15608820}]}]}
{"op":"mcm","clk":"994071714","pt":1580548976518,"mc":[{"id":"1.168133548","rc":[{"batl":[[0,8,7.31],[1,8.2,11.72],[2,8.4,8.45]],"ltp":7.2,"tv":756.07,"id":10170404}]}]}
{"op":"mcm","clk":"994071849","pt":1580548977502,"mc":[{"id":"1.168133548","rc":[{"batl":[[1,8.2,8.72],[2,8.4,5.45]],"ltp":7.2,"tv":756.07,"id":10170404}]}]}
{"op":"mcm","clk":"994072114","pt":1580548980519,"mc":[{"id":"1.168133548","rc":[{"batl":[[1,8.2,11.72],[2,8.4,8.45]],"ltp":7.2,"tv":756.07,"id":10170404}]}]}
{"op":"mcm","clk":"994073760","pt":1580548996554,"mc":[{"id":"1.168133548","rc":[{"batl":[[2,8.4,3]],"ltp":7.2,"tv":756.07,"id":10170404},{"batl":[[0,8.6,5.61],[2,9.6,7.64]],"ltp":8.4,"tv":356.99,"id":15608820}]}]}
{"op":"mcm","clk":"994073782","pt":1580548996760,"mc":[{"id":"1.168133548","rc":[{"batl":[[0,7.8,4.76],[1,8,7.31],[2,8.2,11.72]],"ltp":7.2,"tv":756.07,"id":10170404}]}]}
{"op":"mcm","clk":"994074025","pt":1580548999443,"mc":[{"id":"1.168133548","rc":[{"batb":[[0,8.4,8.43]],"ltp":8.4,"tv":356.99,"id":15608820}]}]}
{"op":"mcm","clk":"994074797","pt":1580549007560,"mc":[{"id":"1.168133548","rc":[{"trd":[[12,48.98]],"batb":[[0,11.5,1.07],[1,11,6.68]],"ltp":12.0,"tv":341.5,"id":8429550}],"tv":4010.92}]}
{"op":"mcm","clk":"994074830","pt":1580549007865,"mc":[{"id":"1.168133548","rc":[{"batb":[[1,7.8,7.74]],"ltp":8.4,"tv":356.99,"id":15608820}]}]}
{"op":"mcm","clk":"994075247","pt":1580549012360,"mc":[{"id":"1.168133548","rc":[{"batb":[[1,11,3.03]],"ltp":12.0,"tv":341.5,"id":8429550},{"batl":[[0,7.6,2],[1,7.8,4.76],[2,8,7.31]],"ltp":7.2,"tv":756.07,"id":10170404},{"batl":[[0,8.6,12.61],[1,9.6,15.27],[2,10,6.87]],"ltp":8.4,"tv":356.99,"id":15608820}]}]}
{"op":"mcm","clk":"994075350","pt":1580549013456,"mc":[{"id":"1.168133548","rc":[{"batl":[[1,95,2],[2,190,2]],"ltp":26.0,"tv":41.06,"id":9193530}]}]}
{"op":"mcm","clk":"994075477","pt":1580549014567,"mc":[{"id":"1.168133548","rc":[{"batl":[[1,9.6,22.91]],"ltp":8.4,"tv":356.99,"id":15608820}]}]}
{"op":"mcm","clk":"994075838","pt":1580549018266,"mc":[{"id":"1.168133548","rc":[{"batb":[[0,7.4,2],[1,7.2,2.39],[2,7,20]],"ltp":7.2,"tv":756.07,"id":10170404}]}]}
{"op":"mcm","clk":"994076116","pt":1580549020477,"mc":[{"id":"1.168133548","rc":[{"batb":[[0,11,3.29],[1,9.8,1.29],[2,9,9.21]],"ltp":12.0,"tv":341.5,"id":8429550}]}]}
{"op":"mcm","clk":"994076224","pt":1580549021487,"mc":[{"id":"1.168133548","rc":[{"batb":[[0,11.5,1.07],[1,11,3.03],[2,10,8.63]],"ltp":12.0,"tv":341.5,"id":8429550}]}]}
{"op":"mcm","clk":"994076312","pt":1580549022373,"mc":[{"id":"1.168133548","rc":[{"batl":[[0,8.6,5.61],[1,9.2,7],[2,9.6,22.91]],"ltp":8.4,"tv":356.99,"id":15608820}]}]}
{"op":"mcm","clk":"994076959","pt":1580549027552,"mc":[{"id":"1.168133548","rc":[{"batl":[[0,60,8.14],[1,65,3.03],[2,95,2]],"ltp":26.0,"tv":41.06,"id":9193530}]}]}
{"op":"mcm","clk":"994078514","pt":1580549042449,"mc":[{"id":"1.168133548","rc":[{"batb":[[0,11,3.84],[1,10,8.92],[2,9.8,1.29]],"ltp":12.0,"tv":341.5,"id":8429550},{"batl":[[1,9.2,10.38],[2,9.6,15.27]],"ltp":8.4,"tv":356.99,"id":15608820}]}]}
{"op":"mcm","clk":"994079212","pt":1580549049259,"mc":[{"id":"1.168133548","rc":[{"trd":[[7.6,16.36]],"batb":[[0,7.4,2.04]],"batl":[[0,7.8,4.76],[1,8,7.31],[2,8.4,3.76]],"ltp":7.6,"tv":760.07,"id":10170404}],"tv":4014.92}]}
{"op":"mcm","clk":"994079329","pt":1580549050562,"mc":[{"id":"1.168133548","rc":[{"batb":[[1,7.2,4.39]],"ltp":7.6,"tv":760.07,"id":10170404}]}]}
{"op":"mcm","clk":"994079387","pt":1580549051196,"mc":[{"id":"1.168133548","rc":[{"batb":[[0,10.5,5],[1,10,9.58],[2,9.6,2]],"ltp":10.5,"tv":740.29,"id":10616006}]}]}
{"op":"mcm","clk":"994080356","pt":1580549061410,"mc":[{"id":"1.168133548","rc":[{"batl":[[1,8.8,7],[2,9.2,3.38]],"ltp":8.4,"tv":356.99,"id":15608820}]}]}
{"op":"mcm","clk":"994080710","pt":1580549065500,"mc":[{"id":"1.168133548","rc":[{"batb":[[0,10,9.58],[1,9.6,2],[2,9.4,19.18]],"ltp":10.5,"tv":740.29,"id":10616006}]}]}
{"op":"mcm","clk":"994081352","pt":1580549071407,"mc":[{"id":"1.168133548","rc":[{"batl":[[0,8.6,12.61],[1,9.2,3.38],[2,9.6,15.27]],"ltp":8.4,"tv":356.99,"id":15608820}]}]}
{"op":"mcm","clk":"994082000","pt":1580549077513,"mc":[{"id":"1.168133548","rc":[{"batb":[[2,9.4,12.17]],"ltp":10.5,"tv":740.29,"id":10616006},{"batl":[[1,9.6,22.91],[2,10,6.87]],"ltp":8.4,"tv":356.99,"id":15608820}]}]}
{"op":"mcm","clk":"994082395","pt":1580549081519,"mc":[{"id":"1.168133548","rc":[{"batb":[[0,8.4,2.05]],"ltp":8.4,"tv":356.99,"id":15608820}]}]}
{"op":"mcm","clk":"994082478","pt":1580549082523,"mc":[{"id":"1.168133548","rc":[{"trd":[[8.6,163.93]],"batl":[[0,8.6,6.23]],"ltp":8.6,"tv":369.75,"id":15608820}],"tv":4027.68}]}
{"op":"mcm","clk":"994082833","pt":1580549085552,"mc":[{"id":"1.168133548","rc":[{"batb":[[1,7.8,2.6]],"ltp":8.6,"tv":369.75,"id":15608820}]}]}
{"op":"mcm","clk":"994083472","pt":1580549091535,"mc":[{"id":"1.168133548","rc":[{"batl":[[0,9.2,6.23]],"ltp":8.6,"tv":369.75,"id":15608820}]}]}
{"op":"mcm","clk":"994083676","pt":1580549093459,"mc":[{"id":"1.168133548","rc":[{"batl":[[1,10,6.87],[2,13,19.42]],"ltp":8.6,"tv":369.75,"id":15608820}]}]}
{"op":"mcm","clk":"994084235","pt":1580549099468,"mc":[{"id":"1.168133548","rc":[{"batl":[[1,9.8,4.54],[2,10,11.27]],"ltp":8.6,"tv":369.75,"id":15608820}]}]}
{"op":"mcm","clk":"994085338","pt":1580549109519,"mc":[{"id":"1.168133548","rc":[{"batl":[[0,8,7.31],[1,8.2,11.73],[2,8.4,3]],"ltp":7.6,"tv":760.07,"id":10170404},{"batl":[[1,9.6,1.14],[2,9.8,4.54]],"ltp":8.6,"tv":369.75,"id":15608820},{"batl":[[1,95,2],[2,190,2]],"ltp":26.0,"tv":41.06,"id":9193530}]}]}
{"op":"mcm","clk":"994085448","pt":1580549110547,"mc":[{"id":"1.168133548","rc":[{"batl":[[0,55,3.27],[1,60,7.89],[2,95,2]],"ltp":26.0,"tv":41.06,"id":9193530}]}]}
{"op":"mcm","clk":"994085542","pt":1580549111437,"mc":[{"id":"1.168133548","rc":[{"batl":[[0,9.6,7.37],[1,9.8,4.54],[2,10,11.27]],"ltp":8.6,"tv":369.75,"id":15608820}]}]}
{"op":"mcm","clk":"994085941","pt":1580549115554,"mc":[{"id":"1.168133548","rc":[{"batl":[[0,12,4],[1,12.5,58.23],[2,13.5,20.72]],"ltp":12.0,"tv":341.5,"id":8429550}]}]}
{"op":"mcm","clk":"994086034","pt":1580549116544,"mc":[{"id":"1.168133548","rc":[{"batb":[[1,8,15.43],[2,7.8,2.6]],"batl":[[1,10,6.87],[2,13,19.42]],"ltp":8.6,"tv":369.75,"id":15608820}]}]}
{"op":"mcm","clk":"994086433","pt":1580549120248,"mc":[{"id":"1.168133548","rc":[{"batl":[[0,55,3.63],[1,60,7.6]],"ltp":26.0,"tv":41.06,"id":9193530}]}]}
{"op":"mcm","clk":"994086546","pt":1580549121439,"mc":[{"id":"1.168133548","rc":[{"batb":[[0,7.4,2]],"ltp":7.6,"tv":760.07,"id":10170404}]}]}
{"op":"mcm","clk":"994086759","pt":1580549123430,"mc":[{"id":"1.168133548","rc":[{"batl":[[2,15.5,16.42]],"ltp":8.6,"tv":369.75,"id":15608820}]}]}
{"op":"mcm","clk":"994087585","pt":1580549131565,"mc":[{"id":"1.168133548","rc":[{"batl":[[0,9.4,1.69],[1,9.6,7.37],[2,10,6.87]],"ltp":8.6,"tv":369.75,"id":15608820}]}]}
{"op":"mcm","clk":"994088247","pt":1580549137279,"mc":[{"id":"1.168133548","rc":[{"batb":[[0,7.6,3.1],[1,7.4,2],[2,7.2,4.39]],"ltp":7.6,"tv":760.07,"id":10170404}]}]}
{"op":"mcm","clk":"994088652","pt":1580549141188,"mc":[{"id":"1.168133548","rc":[{"batl":[[1,9.6,1.14],[2,9.8,6.23]],"ltp":8.6,"tv":369.75,"id":15608820}]}]}
{"op":"mcm","clk":"994088769","pt":1580549142388,"mc":[{"id":"1.168133548","rc":[{"trd":[[12,56.98]],"batl":[[0,12.5,58.23],[1,13.5,20.72],[2,16,16]],"ltp":12.0,"tv":349.5,"id":8429550}],"tv":4035.68}]}
{"op":"mcm","clk":"994089672","pt":1580549151510,"mc":[{"id":"1.168133548","rc":[{"batb":[[1,7.8,2.6],[2,7.6,6.25]],"ltp":8.6,"tv":369.75,"id":15608820},{"batb":[[1,24,1.54]],"ltp":26.0,"tv":41.06,"id":9193530}]}]}
{"op":"mcm","clk":"994089830","pt":1580549153095,"mc":[{"id":"1.168133548","rc":[{"batl":[[2,17,18.29]],"ltp":12.0,"tv":349.5,"id":8429550}]}]}
{"op":"mcm","clk":"994089959","pt":1580549154501,"mc":[{"id":"1.168133548","rc":[{"batl":[[2,8.6,23.87]],"ltp":7.6,"tv":760.07,"id":10170404}]}]}
{"op":"mcm","clk":"994090034","pt":1580549155103,"mc":[{"id":"1.168133548","rc":[{"batb":[[1,23,5.15],[2,22,1.98]],"ltp":26.0,"tv":41.06,"id":9193530}]}]}
{"op":"mcm","clk":"994090473","pt":1580549159207,"mc":[{"id":"1.168133548","rc":[{"batl":[[1,8.2,14.73],[2,8.4,3]],"ltp":7.6,"tv":760.07,"id":10170404}]}]}
{"op":"mcm","clk":"994090694","pt":1580549161503,"mc":[{"id":"1.168133548","rc":[{"batl":[[1,9.6,7.37],[2,10,6.87]],"ltp":8.6,"tv":369.75,"id":15608820}]}]}
{"op":"mcm","clk":"994090788","pt":1580549162501,"mc":[{"id":"1.168133548","rc":[{"trd":[[25,8.34]],"batb":[[0,23,5.15],[1,22,1.98],[2,19,3.05]],"ltp":25.0,"tv":42.44,"id":9193530}],"tv":4037.06}]}
{"op":"mcm","clk":"994090877","pt":1580549163517,"mc":[{"id":"1.168133548","rc":[{"batb":[[0,24,2.19],[1,23,4.35],[2,22,1.98]],"ltp":25.0,"tv":42.44,"id":9193530}]}]}
{"op":"mcm","clk":"994091592","pt":1580549170209,"mc":[{"id":"1.168133548","rc":[{"batl":[[1,9.6,1.14],[2,9.8,6.23]],"ltp":8.6,"tv":369.75,"id":15608820}]}]}
{"op":"mcm","clk":"994092258","pt":1580549176435,"mc":[{"id":"1.168133548","rc":[{"batl":[[0,6,79.21]],"ltp":5.9,"tv":1188.25,"id":9417341}]}]}
{"op":"mcm","clk":"994092689","pt":1580549180157,"mc":[{"id":"1.168133548","rc":[{"batl":[[1,9.6,7.37],[2,10,6.87]],"ltp":8.6,"tv":369.75,"id":15608820}]}]}
{"op":"mcm","clk":"994092838","pt":1580549181457,"mc":[{"id":"1.168133548","rc":[{"batl":[[1,8.2,11.73],[2,8.6,23.87]],"ltp":7.6,"tv":760.07,"id":10170404}]}]}
{"op":"mcm","clk":"994093301","pt":1580549185533,"mc":[{"id":"1.168133548","rc":[{"batb":[[0,11.5,4.98],[1,11,3.03],[2,10,8.92]],"ltp":12.0,"tv":349.5,"id":8429550}]}]}
{"op":"mcm","clk":"994093395","pt":1580549186451,"mc":[{"id":"1.168133548","rc":[{"batl":[[2,8.6,26.87]],"ltp":7.6,"tv":760.07,"id":10170404},{"batl":[[2,7,89.17]],"ltp":6.6,"tv":256.56,"id":17352128}]}]}
{"op":"mcm","clk":"994093501","pt":1580549187555,"mc":[{"id":"1.168133548","rc":[{"batl":[[1,6.2,55.74]],"ltp":5.9,"tv":1188.25,"id":9417341}]}]}
{"op":"mcm","clk":"994093699","pt":1580549189350,"mc":[{"id":"1.168133548","rc":[{"batl":[[1,9.6,1.14],[2,9.8,6.23]],"ltp":8.6,"tv":369.75,"id":15608820}]}]}
{"op":"mcm","clk":"994094985","pt":1580549202941,"mc":[{"id":"1.168133548","rc":[{"batl":[[0,7.8,4.76],[1,8,7.31],[2,8.2,8.72]],"ltp":7.6,"tv":760.07,"id":10170404}]}]}
{"op":"mcm","clk":"994095538","pt":1580549208480,"mc":[{"id":"1.168133548","rc":[{"batl":[[1,9.6,7.37],[2,10,6.87]],"ltp":8.6,"tv":369.75,"id":15608820}]}]}
{"op":"mcm","clk":"994096955","pt":1580549222572,"mc":[{"id":"1.168133548","rc":[{"batb":[[2,10,8.63]],"ltp":12.0,"tv":349.5,"id":8429550}]}]}
{"op":"mcm","clk":"994097001","pt":1580549222936,"mc":[{"id":"1.168133548","rc":[{"batb":[[0,11.5,5.24]],"ltp":12.0,"tv":349.5,"id":8429550}]}]}
{"op":"mcm","clk":"994097467","pt":1580549228240,"mc":[{"id":"1.168133548","rc":[{"batl":[[1,9.6,1.14],[2,9.8,6.23]],"ltp":8.6,"tv":369.75,"id":15608820}]}]}
{"op":"mcm","clk":"994098323","pt":1580549238477,"mc":[{"id":"1.168133548","rc":[{"batl":[[1,9.6,7.37],[2,10,6.87]],"ltp":8.6,"tv":369.75,"id":15608820}]}]}
{"op":"mcm","clk":"994099145","pt":1580549248167,"mc":[{"id":"1.168133548","rc":[{"batl":[[1,9.6,1.14],[2,9.8,6.23]],"ltp":8.6,"tv":369.75,"id":15608820}]}]}
{"op":"mcm","clk":"994099570","pt":1580549252907,"mc":[{"id":"1.168133548","rc":[{"batl":[[1,95,2],[2,190,2]],"ltp":25.0,"tv":42.44,"id":9193530}]}]}
{"op":"mcm","clk":"994100935","pt":1580549268198,"mc":[{"id":"1.168133548","rc":[{"batl":[[0,50,8.2],[1,55,3.03],[2,95,2]],"ltp":25.0,"tv":42.44,"id":9193530}]}]}
{"op":"mcm","clk":"994101147","pt":1580549270528,"mc":[{"id":"1.168133548","rc":[{"batl":[[0,48,3.66],[1,50,7.6]],"ltp":25.0,"tv":42.44,"id":9193530}]}]}
{"op":"mcm","clk":"994101875","pt":1580549278339,"mc":[{"id":"1.168133548","rc":[{"batl":[[1,9.6,7.37],[2,10,6.87]],"ltp":8.6,"tv":369.75,"id":15608820}]}]}
{"op":"mcm","clk":"994102574","pt":1580549285435,"mc":[{"id":"1.168133548","rc":[{"batb":[[0,12,1.44],[1,11.5,5.24],[2,11,3.03]],"ltp":12.0,"tv":349.5,"id":8429550}]}]}
{"op":"mcm","clk":"994104043","pt":1580549299534,"mc":[{"id":"1.168133548","rc":[{"batl":[[1,9.6,1.14],[2,9.8,6.23]],"ltp":8.6,"tv":369.75,"id":15608820}]}]}
{"op":"mcm","clk":"994104959","pt":1580549308983,"mc":[{"id":"1.168133548","rc":[{"batl":[[1,9.6,7.37],[2,10,6.87]],"ltp":8.6,"tv":369.75,"id":15608820}]}]}
{"op":"mcm","clk":"994108524","pt":1580549344241,"mc":[{"id":"1.168133548","rc":[{"batl":[[0,9.6,7.37],[1,10,6.87],[2,12.5,20.42]],"ltp":8.6,"tv":369.75,"id":15608820}]}]}
{"op":"mcm","clk":"994108950","pt":1580549348561,"mc":[{"id":"1.168133548","rc":[{"batl":[[0,9.6,1.14]],"ltp":8.6,"tv":369.75,"id":15608820}]}]}
{"op":"mcm","clk":"994108988","pt":1580549348872,"mc":[{"id":"1.168133548","rc":[{"trd":[[9.6,21.18]],"batl":[[0,9.8,6.23]],"ltp":9.6,"tv":372.02,"id":15608820}],"tv":4039.33}]}
{"op":"mcm","clk":"994109443","pt":1580549353573,"mc":[{"id":"1.168133548","rc":[{"batb":[[0,8.4,5.05]],"ltp":9.6,"tv":372.02,"id":15608820}]}]}
{"op":"mcm","clk":"994109915","pt":1580549358573,"mc":[{"id":"1.168133548","rc":[{"trd":[[11.5,38.48],[12,59.86]],"batb":[[0,11,3.03],[1,10,8.63],[2,9.8,1.29]],"batl":[[0,11.5,3.32],[1,12.5,58.23],[2,13.5,20.72]],"ltp":11.5,"tv":362.86,"id":8429550}],"tv":4052.69}]}
{"op":"mcm","clk":"994109946","pt":1580549358888,"mc":[{"id":"1.168133548","rc":[{"batb":[[1,10,15]],"ltp":11.5,"tv":362.86,"id":8429550},{"batb":[[1,7.8,5.86]],"ltp":9.6,"tv":372.02,"id":15608820},{"batl":[[2,7,87.5]],"ltp":6.6,"tv":256.56,"id":17352128}]}]}
{"op":"mcm","clk":"994110109","pt":1580549360409,"mc":[{"id":"1.168133548","rc":[{"batb":[[1,10,8.63]],"ltp":11.5,"tv":362.86,"id":8429550}]}]}
{"op":"mcm","clk":"994110334","pt":1580549362497,"mc":[{"id":"1.168133548","rc":[{"batl":[[0,10.5,4.2],[1,11.5,10.44],[2,12,2]],"ltp":10.5,"tv":740.29,"id":10616006}]}]}
{"op":"mcm","clk":"994110443","pt":1580549363488,"mc":[{"id":"1.168133548","rc":[{"trd":[[10.5,158.28]],"batl":[[0,10.5,2.2]],"ltp":10.5,"tv":744.29,"id":10616006},{"batl":[[2,15,17.42]],"ltp":9.6,"tv":372.02,"id":15608820}],"tv":4056.68}]}
{"op":"mcm","clk":"994110846","pt":1580549367404,"mc":[{"id":"1.168133548","rc":[{"batb":[[0,11,4.48]],"ltp":11.5,"tv":362.86,"id":8429550},{"batb":[[0,8.6,1.85],[1,8.4,5.05],[2,7.8,5.86]],"ltp":9.6,"tv":372.02,"id":15608820},{"batl":[[2,7,89.17]],"ltp":6.6,"tv":256.56,"id":17352128}]}]}
{"op":"mcm","clk":"994111268","pt":1580549371487,"mc":[{"id":"1.168133548","rc":[{"batb":[[2,8,3.19]],"batl":[[0,9.6,3.03],[1,9.8,6.23],[2,10,6.87]],"ltp":9.6,"tv":372.02,"id":15608820}]}]}
{"op":"mcm","clk":"994111355","pt":1580549372480,"mc":[{"id":"1.168133548","rc":[{"trd":[[5.9,214.93]],"batb":[[0,5.8,7.72],[1,5.7,26.5],[2,5.5,20.85]],"batl":[[0,5.9,2.96],[1,6,70],[2,6.2,55.74]],"ltp":5.9,"tv":1197.21,"id":9417341},{"batb":[[2,9.4,13.37]],"ltp":10.5,"tv":744.29,"id":10616006},{"batl":[[2,7,87.5]],"ltp":6.6,"tv":256.56,"id":17352128}],"tv":4065.64}]}
{"op":"mcm","clk":"994111542","pt":1580549374214,"mc":[{"id":"1.168133548","rc":[{"batl":[[2,6.2,42.16]],"ltp":5.9,"tv":1197.21,"id":9417341}]}]}
{"op":"mcm","clk":"994111703","pt":1580549375499,"mc":[{"id":"1.168133548","rc":[{"trd":[[5.8,308.12]],"batb":[[0,5.7,26.91],[1,5.5,20.85],[2,5.2,50]],"batl":[[0,5.9,16.96]],"ltp":5.8,"tv":1211.83,"id":9417341}],"tv":4080.26}]}
{"op":"mcm","clk":"994111794","pt":1580549376494,"mc":[{"id":"1.168133548","rc":[{"batb":[[1,5.5,34.79]],"ltp":5.8,"tv":1211.83,"id":9417341}]}]}
{"op":"mcm","clk":"994111982","pt":1580549378525,"mc":[{"id":"1.168133548","rc":[{"batl":[[1,10,6.87],[2,15,17.42]],"ltp":9.6,"tv":372.02,"id":15608820}]}]}
{"op":"mcm","clk":"994111991","pt":1580549378628,"mc":[{"id":"1.168133548","rc":[{"batl":[[0,9.6,9.26]],"ltp":9.6,"tv":372.02,"id":15608820}]}]}
{"op":"mcm","clk":"994112224","pt":1580549381131,"mc":[{"id":"1.168133548","rc":[{"batl":[[0,12.5,58.23],[1,13.5,20.72],[2,16,16]],"ltp":11.5,"tv":362.86,"id":8429550},{"batb":[[1,5.5,31.79]],"ltp":5.8,"tv":1211.83,"id":9417341},{"batb":[[2,9.4,12.17]],"ltp":10.5,"tv":744.29,"id":10616006}]}]}
{"op":"mcm","clk":"994112894","pt":1580549388222,"mc":[{"id":"1.168133548","rc":[{"batl":[[0,9.6,3.03],[1,9.8,6.23],[2,10,6.87]],"ltp":9.6,"tv":372.02,"id":15608820}]}]}
{"op":"mcm","clk":"994113079","pt":1580549390251,"mc":[{"id":"1.168133548","rc":[{"batb":[[0,11,3.03]],"ltp":11.5,"tv":362.86,"id":8429550}]}]}
{"op":"mcm","clk":"994113442","pt":1580549393619,"mc":[{"id":"1.168133548","rc":[{"batl":[[2,17,18.29]],"ltp":11.5,"tv":362.86,"id":8429550},{"batb":[[2,5.2,2]],"ltp":5.8,"tv":1211.83,"id":9417341}]}]}
{"op":"mcm","clk":"994113934","pt":1580549398119,"mc":[{"id":"1.168133548","rc":[{"batl":[[0,9.6,9.26],[1,10,6.87],[2,12.5,20.42]],"ltp":9.6,"tv":372.02,"id":15608820}]}]}
{"op":"mcm","clk":"994115529","pt":1580549412867,"mc":[{"id":"1.168133548","rc":[{"batl":[[0,12,4],[1,12.5,58.23],[2,13.5,20.72]],"ltp":11.5,"tv":362.86,"id":8429550}]}]}
{"op":"mcm","clk":"994115699","pt":1580549414479,"mc":[{"id":"1.168133548","rc":[{"batb":[[0,8.8,9.32],[1,8.6,1.85],[2,8.4,5.05]],"ltp":9.6,"tv":372.02,"id":15608820}]}]}
{"op":"mcm","clk":"994115923","pt":1580549416560,"mc":[{"id":"1.168133548","rc":[{"trd":[[5.6,0.76],[5.7,10.02]],"batb":[[0,5.6,5.51],[1,5.5,7],[2,5,55.07]],"ltp":5.6,"tv":267.67,"id":8231803}],"tv":4084.26}]}
{"op":"mcm","clk":"994116028","pt":1580549417547,"mc":[{"id":"1.168133548","rc":[{"batb":[[2,8.4,10.56]],"batl":[[0,9.6,3.03],[1,9.8,6.23],[2,10,6.87]],"ltp":9.6,"tv":372.02,"id":15608820}]}]}
{"op":"mcm","clk":"994116126","pt":1580549418484,"mc":[{"id":"1.168133548","rc":[{"trd":[[6,64.32]],"batl":[[0,6,90.11]],"ltp":6.0,"tv":271.45,"id":8231803}],"tv":4088.04}]}
{"op":"mcm","clk":"994116543","pt":1580549422499,"mc":[{"id":"1.168133548","rc":[{"batl":[[2,7,2]],"ltp":6.0,"tv":271.45,"id":8231803}]}]}
{"op":"mcm","clk":"994116639","pt":1580549423385,"mc":[{"id":"1.168133548","rc":[{"batb":[[0,10.5,3.03],[1,10,12.86]],"ltp":11.5,"tv":362.86,"id":8429550},{"batl":[[0,5.9,2.17],[1,6,90.11],[2,6.2,11.85]],"ltp":6.0,"tv":271.45,"id":8231803}]}]}
{"op":"mcm","clk":"994116766","pt":1580549424478,"mc":[{"id":"1.168133548","rc":[{"batb":[[2,5,5.07]],"ltp":6.0,"tv":271.45,"id":8231803}]}]}
{"op":"mcm","clk":"994117085","pt":1580549427567,"mc":[{"id":"1.168133548","rc":[{"batl":[[0,9.6,9.26],[1,10,6.87],[2,12.5,20.42]],"ltp":9.6,"tv":372.02,"id":15608820}]}]}
{"op":"mcm","clk":"994119131","pt":1580549447518,"mc":[{"id":"1.168133548","rc":[{"batl":[[0,5.9,6.17]],"ltp":6.0,"tv":271.45,"id":8231803},{"trd":[[7.4,33.24],[7.6,22.56]],"batb":[[0,7.2,4.49],[1,7,43.31],[2,6.6,1.98]],"batl":[[1,8.2,8.72],[2,8.6,26.87]],"ltp":7.4,"tv":770.07,"id":10170404}],"tv":4098.04}]}
{"op":"mcm","clk":"994119199","pt":1580549448340,"mc":[{"id":"1.168133548","rc":[{"batl":[[1,8,2],[2,8.2,8.72]],"ltp":7.4,"tv":770.07,"id":10170404}]}]}
{"op":"mcm","clk":"994119700","pt":1580549453414,"mc":[{"id":"1.168133548","rc":[{"batb":[[1,10,4.23]],"ltp":11.5,"tv":362.86,"id":8429550}]}]}
{"op":"mcm","clk":"994119814","pt":1580549454555,"mc":[{"id":"1.168133548","rc":[{"batl":[[2,15,17.42]],"ltp":9.6,"tv":372.02,"id":15608820}]}]}
{"op":"mcm","clk":"994119998","pt":1580549456169,"mc":[{"id":"1.168133548","rc":[{"batb":[[1,7,40]],"batl":[[2,8.6,27.63]],"ltp":7.4,"tv":770.07,"id":10170404}]}]}
{"op":"mcm","clk":"994120115","pt":1580549457256,"mc":[{"id":"1.168133548","rc":[{"batl":[[0,9.6,3.03],[1,9.8,6.23],[2,10,6.87]],"ltp":9.6,"tv":372.02,"id":15608820}]}]}
{"op":"mcm","clk":"994121068","pt":1580549466476,"mc":[{"id":"1.168133548","rc":[{"batb":[[0,24,2.9]],"ltp":25.0,"tv":42.44,"id":9193530}]}]}
{"op":"mcm","clk":"994121481","pt":1580549470347,"mc":[{"id":"1.168133548","rc":[{"batb":[[0,24,7.43]],"ltp":25.0,"tv":42.44,"id":9193530}]}]}
{"op":"mcm","clk":"994122185","pt":1580549477361,"mc":[{"id":"1.168133548","rc":[{"batl":[[0,12,6]],"ltp":11.5,"tv":362.86,"id":8429550}]}]}
{"op":"mcm","clk":"994122735","pt":1580549482570,"mc":[{"id":"1.168133548","rc":[{"batl":[[2,8.6,24.63]],"ltp":7.4,"tv":770.07,"id":10170404}]}]}
{"op":"mcm","clk":"994123108","pt":1580549485510,"mc":[{"id":"1.168133548","rc":[{"batb":[[0,24,8.17]],"ltp":25.0,"tv":42.44,"id":9193530}]}]}
{"op":"mcm","clk":"994123285","pt":1580549486513,"mc":[{"id":"1.168133548","rc":[{"batl":[[2,8.2,3.76]],"ltp":7.4,"tv":770.07,"id":10170404}]}]}
{"op":"mcm","clk":"994123384","pt":1580549487412,"mc":[{"id":"1.168133548","rc":[{"batl":[[0,9.6,9.26],[1,10,6.87],[2,12.5,20.42]],"ltp":9.6,"tv":372.02,"id":15608820}]}]}
{"op":"mcm","clk":"994123784","pt":1580549491533,"mc":[{"id":"1.168133548","rc":[{"batl":[[2,8.2,16.14]],"ltp":7.4,"tv":770.07,"id":10170404}]}]}
{"op":"mcm","clk":"994123995","pt":1580549493527,"mc":[{"id":"1.168133548","rc":[{"batl":[[1,95,2],[2,190,2]],"ltp":25.0,"tv":42.44,"id":9193530}]}]}
{"op":"mcm","clk":"994125600","pt":1580549506354,"mc":[{"id":"1.168133548","rc":[{"batl":[[0,9.6,3.03],[1,9.8,6.23],[2,10,6.87]],"ltp":9.6,"tv":372.02,"id":15608820}]}]}
{"op":"mcm","clk":"994126026","pt":1580549510538,"mc":[{"id":"1.168133548","rc":[{"batl":[[0,46,8.23],[1,48,3.03],[2,95,2]],"ltp":25.0,"tv":42.44,"id":9193530}]}]}
