{"op":"mcm","clk":"994126514","pt":1580549513457,"mc":[{"id":"1.168133548","rc":[{"batl":[[0,8,7.72],[1,8.2,8.07],[2,8.4,10.96]],"ltp":7.4,"tv":770.07,"id":10170404},{"batl":[[0,44,3.27],[1,46,7.98]],"ltp":25.0,"tv":42.44,"id":9193530}]}]}
{"op":"mcm","clk":"994126719","pt":1580549515433,"mc":[{"id":"1.168133548","rc":[{"batl":[[1,46,7.6]],"ltp":25.0,"tv":42.44,"id":9193530}]}]}
{"op":"mcm","clk":"994126815","pt":1580549516364,"mc":[{"id":"1.168133548","rc":[{"batl":[[0,9.6,9.26],[1,10,6.87],[2,12.5,20.42]],"ltp":9.6,"tv":372.02,"id":15608820},{"batl":[[0,44,3.7]],"ltp":25.0,"tv":42.44,"id":9193530}]}]}
{"op":"mcm","clk":"994127974","pt":1580549527570,"mc":[{"id":"1.168133548","rc":[{"batl":[[1,6,76]],"ltp":5.8,"tv":1211.83,"id":9417341}]}]}
{"op":"mcm","clk":"994129899","pt":1580549544572,"mc":[{"id":"1.168133548","rc":[{"batl":[[2,15,17.42]],"ltp":9.6,"tv":372.02,"id":15608820}]}]}
{"op":"mcm","clk":"994129968","pt":1580549545193,"mc":[{"id":"1.168133548","rc":[{"batl":[[0,9.6,3.03],[1,9.8,6.23],[2,10,6.87]],"ltp":9.6,"tv":372.02,"id":15608820}]}]}
{"op":"mcm","clk":"994130423","pt":1580549549511,"mc":[{"id":"1.168133548","rc":[{"trd":[[12,71.86]],"batl":[[0,12.5,58.23],[1,13.5,20.72],[2,16,16]],"ltp":12.0,"tv":374.86,"id":8429550}],"tv":4110.04}]}
{"op":"mcm","clk":"994130877","pt":1580549554019,"mc":[{"id":"1.168133548","rc":[{"batb":[[0,11,1.45],[1,10.5,3.03],[2,10,4.23]],"ltp":12.0,"tv":374.86,"id":8429550}]}]}
{"op":"mcm","clk":"994131007","pt":1580549555422,"mc":[{"id":"1.168133548","rc":[{"batl":[[0,9.6,9.26],[1,10,6.87],[2,15,17.42]],"ltp":9.6,"tv":372.02,"id":15608820}]}]}
{"op":"mcm","clk":"994132099","pt":1580549565562,"mc":[{"id":"1.168133548","rc":[{"batl":[[0,9.6,3.03],[1,9.8,6.23],[2,10,6.87]],"ltp":9.6,"tv":372.02,"id":15608820}]}]}
{"op":"mcm","clk":"994132687","pt":1580549571473,"mc":[{"id":"1.168133548","rc":[{"batb":[[0,11,5.81]],"ltp":12.0,"tv":374.86,"id":8429550}]}]}
{"op":"mcm","clk":"994132976","pt":1580549574067,"mc":[{"id":"1.168133548","rc":[{"batl":[[2,17,18.29]],"ltp":12.0,"tv":374.86,"id":8429550}]}]}
{"op":"mcm","clk":"994133736","pt":1580549581548,"mc":[{"id":"1.168133548","rc":[{"trd":[[6,79.69],[6.2,61.8],[6.4,85.68]],"batb":[[0,6,12.83],[1,5.9,5.28],[2,5.8,4.26]],"ltp":6.0,"tv":356.55,"id":17352128}],"tv":4210.03}]}
{"op":"mcm","clk":"994133833","pt":1580549582492,"mc":[{"id":"1.168133548","rc":[{"batb":[[0,6,9.83],[1,5.8,4.26],[2,5.5,52]],"ltp":6.0,"tv":356.55,"id":17352128}]}]}
{"op":"mcm","clk":"994134156","pt":1580549585075,"mc":[{"id":"1.168133548","rc":[{"batl":[[0,9.6,9.26],[1,10,6.87],[2,12.5,20.42]],"ltp":9.6,"tv":372.02,"id":15608820}]}]}
{"op":"mcm","clk":"994134400","pt":1580549587573,"mc":[{"id":"1.168133548","rc":[{"batb":[[0,5.7,3.02],[1,5.6,5.51],[2,5.5,7]],"ltp":6.0,"tv":271.45,"id":8231803}]}]}
{"op":"mcm","clk":"994135794","pt":1580549601527,"mc":[{"id":"1.168133548","rc":[{"batb":[[1,8.4,10.56],[2,8,3.19]],"ltp":9.6,"tv":372.02,"id":15608820}]}]}
{"op":"mcm","clk":"994136065","pt":1580549603938,"mc":[{"id":"1.168133548","rc":[{"batl":[[2,15,17.42]],"ltp":9.6,"tv":372.02,"id":15608820},{"batb":[[2,5.5,7]],"ltp":6.0,"tv":356.55,"id":17352128}]}]}
{"op":"mcm","clk":"994136295","pt":1580549605515,"mc":[{"id":"1.168133548","rc":[{"batl":[[0,9.6,3.03],[1,9.8,6.23],[2,10,6.87]],"ltp":9.6,"tv":372.02,"id":15608820}]}]}
{"op":"mcm","clk":"994136574","pt":1580549608531,"mc":[{"id":"1.168133548","rc":[{"batb":[[0,7.4,5.2],[1,7.2,4.39],[2,7,40]],"ltp":7.4,"tv":770.07,"id":10170404}]}]}
{"op":"mcm","clk":"994137447","pt":1580549618248,"mc":[{"id":"1.168133548","rc":[{"batl":[[0,5.9,2.17]],"ltp":6.0,"tv":271.45,"id":8231803}]}]}
{"op":"mcm","clk":"994137654","pt":1580549620451,"mc":[{"id":"1.168133548","rc":[{"trd":[[20,16]],"batb":[[0,20,8.97],[1,17.5,1.01],[2,17,11]],"batl":[[0,80,4.29],[1,85,11.1]],"ltp":20.0,"tv":78.54,"id":9001159}],"tv":4222.09}]}
{"op":"mcm","clk":"994137833","pt":1580549622446,"mc":[{"id":"1.168133548","rc":[{"batb":[[1,17.5,5.74]],"batl":[[0,85,9.08],[1,95,2],[2,190,2]],"ltp":20.0,"tv":78.54,"id":9001159}]}]}
{"op":"mcm","clk":"994138019","pt":1580549624439,"mc":[{"id":"1.168133548","rc":[{"batl":[[0,85,9.14]],"ltp":20.0,"tv":78.54,"id":9001159}]}]}
{"op":"mcm","clk":"994138281","pt":1580549627528,"mc":[{"id":"1.168133548","rc":[{"batb":[[0,24,3.64]],"ltp":25.0,"tv":42.44,"id":9193530}]}]}
{"op":"mcm","clk":"994138808","pt":1580549633467,"mc":[{"id":"1.168133548","rc":[{"trd":[[5.7,56.76],[5.8,308.94]],"batb":[[0,5.7,24.71]],"ltp":5.7,"tv":1216.24,"id":9417341},{"trd":[[9.6,27.23]],"batb":[[0,9.6,9.47],[1,8.8,9.32],[2,8.4,10.56]],"batl":[[0,9.8,6.23],[1,10,6.87],[2,15,17.42]],"ltp":9.6,"tv":378.08,"id":15608820},{"batb":[[0,24,2.9]],"ltp":25.0,"tv":42.44,"id":9193530},{"batb":[[1,17.5,8.15]],"ltp":20.0,"tv":78.54,"id":9001159}],"tv":4232.56}]}
{"op":"mcm","clk":"994138859","pt":1580549634049,"mc":[{"id":"1.168133548","rc":[{"batl":[[2,17.5,14.42]],"ltp":9.6,"tv":378.08,"id":15608820},{"batl":[[2,310,2]],"ltp":20.0,"tv":78.54,"id":9001159}]}]}
{"op":"mcm","clk":"994139006","pt":1580549635573,"mc":[{"id":"1.168133548","rc":[{"trd":[[9.6,39.69]],"batb":[[0,9.6,3.24],[1,9,5.25],[2,8.8,16.5]],"batl":[[0,10,6.87],[1,17.5,14.42],[2,18.5,1.25]],"ltp":9.6,"tv":390.54,"id":15608820}],"tv":4245.02}]}
{"op":"mcm","clk":"994139301","pt":1580549638560,"mc":[{"id":"1.168133548","rc":[{"batl":[[1,8.2,5.07],[2,8.4,7.96]],"ltp":7.4,"tv":770.07,"id":10170404}]}]}
{"op":"mcm","clk":"994139401","pt":1580549639558,"mc":[{"id":"1.168133548","rc":[{"batl":[[0,85,9.34]],"ltp":20.0,"tv":78.54,"id":9001159}]}]}
{"op":"mcm","clk":"994139709","pt":1580549642566,"mc":[{"id":"1.168133548","rc":[{"batl":[[2,8.4,10.96]],"ltp":7.4,"tv":770.07,"id":10170404}]}]}
{"op":"mcm","clk":"994139949","pt":1580549644976,"mc":[{"id":"1.168133548","rc":[{"batl":[[1,17,8.42],[2,17.5,14]],"ltp":9.6,"tv":390.54,"id":15608820}]}]}
{"op":"mcm","clk":"994140405","pt":1580549650402,"mc":[{"id":"1.168133548","rc":[{"batb":[[1,8.8,16.5],[2,8.4,5.05]],"ltp":9.6,"tv":390.54,"id":15608820}]}]}
{"op":"mcm","clk":"994140901","pt":1580549655483,"mc":[{"id":"1.168133548","rc":[{"batb":[[1,18,8],[2,17.5,7.14]],"ltp":20.0,"tv":78.54,"id":9001159}]}]}
{"op":"mcm","clk":"994141616","pt":1580549663000,"mc":[{"id":"1.168133548","rc":[{"batb":[[1,18,8.96]],"ltp":20.0,"tv":78.54,"id":9001159}]}]}
{"op":"mcm","clk":"994141707","pt":1580549664037,"mc":[{"id":"1.168133548","rc":[{"batl":[[2,18.5,1.25]],"ltp":9.6,"tv":390.54,"id":15608820},{"batl":[[2,560,2.16]],"ltp":20.0,"tv":78.54,"id":9001159}]}]}
{"op":"mcm","clk":"994142773","pt":1580549674537,"mc":[{"id":"1.168133548","rc":[{"batb":[[1,18.5,5.69],[2,18,8]],"ltp":20.0,"tv":78.54,"id":9001159}]}]}
{"op":"mcm","clk":"994142981","pt":1580549676510,"mc":[{"id":"1.168133548","rc":[{"batb":[[0,11.5,1.5],[1,11,5.81],[2,10.5,3.03]],"ltp":12.0,"tv":374.86,"id":8429550}]}]}
{"op":"mcm","clk":"994143668","pt":1580549683353,"mc":[{"id":"1.168133548","rc":[{"batl":[[0,80,7.93],[1,85,9],[2,95,2]],"ltp":20.0,"tv":78.54,"id":9001159}]}]}
{"op":"mcm","clk":"994143747","pt":1580549684168,"mc":[{"id":"1.168133548","rc":[{"batb":[[1,19,8],[2,18.5,5.69]],"ltp":20.0,"tv":78.54,"id":9001159}]}]}
{"op":"mcm","clk":"994143913","pt":1580549685767,"mc":[{"id":"1.168133548","rc":[{"batb":[[2,18.5,4.73]],"ltp":20.0,"tv":78.54,"id":9001159}]}]}
{"op":"mcm","clk":"994144209","pt":1580549689032,"mc":[{"id":"1.168133548","rc":[{"batl":[[0,80,8.43]],"ltp":20.0,"tv":78.54,"id":9001159}]}]}
{"op":"mcm","clk":"994144619","pt":1580549693433,"mc":[{"id":"1.168133548","rc":[{"batb":[[1,19,8.91]],"ltp":20.0,"tv":78.54,"id":9001159}]}]}
{"op":"mcm","clk":"994144789","pt":1580549695046,"mc":[{"id":"1.168133548","rc":[{"batb":[[0,7.4,5.1]],"ltp":7.4,"tv":770.07,"id":10170404}]}]}
{"op":"mcm","clk":"994145651","pt":1580549703516,"mc":[{"id":"1.168133548","rc":[{"batb":[[0,7.6,2],[1,7.4,5.1],[2,7.2,4.39]],"ltp":7.4,"tv":770.07,"id":10170404}]}]}
{"op":"mcm","clk":"994146680","pt":1580549712486,"mc":[{"id":"1.168133548","rc":[{"batl":[[2,8.4,7.96]],"ltp":7.4,"tv":770.07,"id":10170404}]}]}
{"op":"mcm","clk":"994146997","pt":1580549715390,"mc":[{"id":"1.168133548","rc":[{"trd":[[10,224.88]],"batb":[[0,10,7.58]],"ltp":10.0,"tv":748.29,"id":10616006}],"tv":4249.01}]}
{"op":"mcm","clk":"994147440","pt":1580549719510,"mc":[{"id":"1.168133548","rc":[{"batl":[[1,11,1.45],[2,11.5,10.44]],"ltp":10.0,"tv":748.29,"id":10616006}]}]}
{"op":"mcm","clk":"994149051","pt":1580549735504,"mc":[{"id":"1.168133548","rc":[{"batl":[[1,8.4,13],[2,8.6,26.87]],"ltp":7.4,"tv":770.07,"id":10170404},{"batl":[[1,95,2],[2,190,2]],"ltp":25.0,"tv":42.44,"id":9193530}]}]}
{"op":"mcm","clk":"994150480","pt":1580549749558,"mc":[{"id":"1.168133548","rc":[{"batb":[[0,6.2,18],[1,6,9.83],[2,5.8,4.26]],"ltp":6.0,"tv":356.55,"id":17352128}]}]}
{"op":"mcm","clk":"994150575","pt":1580549750549,"mc":[{"id":"1.168133548","rc":[{"batb":[[2,9.4,6.04]],"ltp":10.0,"tv":748.29,"id":10616006},{"batl":[[0,42,8.27],[1,44,3.03],[2,95,2]],"ltp":25.0,"tv":42.44,"id":9193530}]}]}
{"op":"mcm","clk":"994151835","pt":1580549763976,"mc":[{"id":"1.168133548","rc":[{"trd":[[5.7,16.07]],"batb":[[0,5.6,5.51],[1,5.5,7],[2,5,55.07]],"batl":[[0,5.9,2.66]],"ltp":5.7,"tv":277.5,"id":8231803}],"tv":4255.06}]}
{"op":"mcm","clk":"994152170","pt":1580549767361,"mc":[{"id":"1.168133548","rc":[{"batb":[[0,5.8,2.97],[1,5.7,24.71],[2,5.5,31.79]],"ltp":5.7,"tv":1216.24,"id":9417341},{"batb":[[0,20,9.79]],"ltp":20.0,"tv":78.54,"id":9001159}]}]}
{"op":"mcm","clk":"994152221","pt":1580549767876,"mc":[{"id":"1.168133548","rc":[{"batb":[[1,5.5,4],[2,5,58.07]],"ltp":5.7,"tv":277.5,"id":8231803}]}]}
{"op":"mcm","clk":"994152308","pt":1580549768862,"mc":[{"id":"1.168133548","rc":[{"batb":[[2,5.5,22.16]],"ltp":5.7,"tv":1216.24,"id":9417341}]}]}
{"op":"mcm","clk":"994152787","pt":1580549774476,"mc":[{"id":"1.168133548","rc":[{"batl":[[0,8,2],[1,8.2,5.94],[2,8.4,12.24]],"ltp":7.4,"tv":770.07,"id":10170404}]}]}
{"op":"mcm","clk":"994152838","pt":1580549774992,"mc":[{"id":"1.168133548","rc":[{"batl":[[0,40,3.27],[1,42,8.02]],"ltp":25.0,"tv":42.44,"id":9193530}]}]}
{"op":"mcm","clk":"994153345","pt":1580549780473,"mc":[{"id":"1.168133548","rc":[{"batl":[[0,7.8,7.44],[1,8,17.83],[2,8.2,5.94]],"ltp":7.4,"tv":770.07,"id":10170404}]}]}
{"op":"mcm","clk":"994153741","pt":1580549784203,"mc":[{"id":"1.168133548","rc":[{"batb":[[2,5,8.07]],"ltp":5.7,"tv":277.5,"id":8231803}]}]}
{"op":"mcm","clk":"994153873","pt":1580549785505,"mc":[{"id":"1.168133548","rc":[{"batl":[[0,5.9,6.66]],"ltp":5.7,"tv":277.5,"id":8231803}]}]}
{"op":"mcm","clk":"994154273","pt":1580549789505,"mc":[{"id":"1.168133548","rc":[{"batl":[[0,40,3.74],[1,42,7.6]],"ltp":25.0,"tv":42.44,"id":9193530}]}]}
{"op":"mcm","clk":"994154351","pt":1580549790403,"mc":[{"id":"1.168133548","rc":[{"batb":[[1,11,4.36]],"ltp":12.0,"tv":374.86,"id":8429550}]}]}
{"op":"mcm","clk":"994155286","pt":1580549799445,"mc":[{"id":"1.168133548","rc":[{"batl":[[1,8,2]],"ltp":7.4,"tv":770.07,"id":10170404}]}]}
{"op":"mcm","clk":"994157018","pt":1580549813502,"mc":[{"id":"1.168133548","rc":[{"batl":[[2,8.2,19.26]],"ltp":7.4,"tv":770.07,"id":10170404}]}]}
{"op":"mcm","clk":"994158408","pt":1580549828537,"mc":[{"id":"1.168133548","rc":[{"trd":[[7.6,26.56]],"batb":[[0,7.4,5.1],[1,7.2,4.39],[2,7,40]],"ltp":7.6,"tv":774.07,"id":10170404}],"tv":4259.06}]}
{"op":"mcm","clk":"994171193","pt":1580549854179,"mc":[{"id":"1.168133548","rc":[{"trd":[[10,242.03]],"batb":[[0,9.6,2],[1,9.4,6.04],[2,9.2,11.58]],"batl":[[0,10,2.43],[1,10.5,2.2],[2,11,1.45]],"ltp":10.0,"tv":765.44,"id":10616006}],"tv":4276.21}]}
{"op":"mcm","clk":"994171402","pt":1580549856572,"mc":[{"id":"1.168133548","rc":[{"batb":[[1,9.2,4.4],[2,9,5]],"ltp":10.0,"tv":765.44,"id":10616006}]}]}
{"op":"mcm","clk":"994172321","pt":1580549866520,"mc":[{"id":"1.168133548","rc":[{"batl":[[0,10.5,2.2],[1,11,1.45],[2,11.5,10.44]],"ltp":10.0,"tv":765.44,"id":10616006}]}]}
{"op":"mcm","clk":"994172880","pt":1580549872428,"mc":[{"id":"1.168133548","rc":[{"trd":[[9.6,12.91]],"batb":[[0,9.2,4.4],[1,9,5],[2,8.4,33]],"batl":[[0,10.5,2.63]],"ltp":9.6,"tv":769.44,"id":10616006}],"tv":4280.21}]}
{"op":"mcm","clk":"994173060","pt":1580549874412,"mc":[{"id":"1.168133548","rc":[{"batb":[[2,8.4,3]],"ltp":9.6,"tv":769.44,"id":10616006}]}]}
{"op":"mcm","clk":"994173849","pt":1580549881984,"mc":[{"id":"1.168133548","marketDefinition":{"bspMarket":true,"turnInPlayEnabled":true,"persistenceEnabled":true,"marketBaseRate":5.0,"eventId":"29678760","eventTypeId":"7","numberOfWinners":1,"bettingType":"ODDS","marketType":"WIN","marketTime":"2020-02-01T13:38:00.000Z","suspendTime":"2020-02-01T13:38:00.000Z","bspReconciled":false,"complete":true,"inPlay":false,"crossMatching":true,"runnersVoidable":false,"numberOfActiveRunners":9,"betDelay":0,"status":"OPEN","runners":[{"adjustmentFactor":13.26,"status":"ACTIVE","sortPriority":1,"id":8231803,"name":"Kings Odyssey"},{"adjustmentFactor":18.03,"status":"ACTIVE","sortPriority":2,"id":9417341,"name":"Nuts Well"},{"adjustmentFactor":8.91,"status":"ACTIVE","sortPriority":3,"id":10170404,"name":"Niven"},{"adjustmentFactor":6.9,"status":"ACTIVE","sortPriority":4,"id":17352128,"name":"Kapgarry"},{"adjustmentFactor":10.32,"status":"ACTIVE","sortPriority":5,"id":8429550,"name":"Clan Legend"},{"adjustmentFactor":12.14,"status":"ACTIVE","sortPriority":6,"id":15608820,"name":"The Dubai Way"},{"adjustmentFactor":6.9,"status":"ACTIVE","sortPriority":7,"id":9193530,"name":"Bollin Ace"},{"adjustmentFactor":8.91,"status":"ACTIVE","sortPriority":8,"id":10616006,"name":"Winter Escape"},{"adjustmentFactor":14.58,"status":"ACTIVE","sortPriority":9,"id":9001159,"name":"Pistol Park"}],"regulators":["MR_INT"],"venue":"Wetherby","countryCode":"GB","discountAllowed":true,"timezone":"Europe/London","openDate":"2020-02-01T13:03:00.000Z","version":3143868078,"name":"2m3f Hcap Chs","eventName":"Weth  1st Feb"}}]}
{"op":"mcm","clk":"994174295","pt":1580549887422,"mc":[{"id":"1.168133548","rc":[{"batb":[[0,6.4,2.69],[1,6.2,18],[2,6,9.83]],"ltp":6.0,"tv":356.55,"id":17352128}]}]}
{"op":"mcm","clk":"994175315","pt":1580549898455,"mc":[{"id":"1.168133548","rc":[{"trd":[[6.4,95.68]],"batb":[[0,6.4,1.54],[2,6,15.03]],"ltp":6.4,"tv":366.54,"id":17352128}],"tv":4290.21}]}
{"op":"mcm","clk":"994176320","pt":1580549908564,"mc":[{"id":"1.168133548","rc":[{"batl":[[0,85,9.83],[1,95,2],[2,190,2]],"ltp":20.0,"tv":78.54,"id":9001159}]}]}
{"op":"mcm","clk":"994177670","pt":1580549923516,"mc":[{"id":"1.168133548","rc":[{"batl":[[0,80,8.43],[1,85,9],[2,95,2]],"ltp":20.0,"tv":78.54,"id":9001159}]}]}
{"op":"mcm","clk":"994177901","pt":1580549926327,"mc":[{"id":"1.168133548","rc":[{"batl":[[0,10,2.43],[1,10.5,6.2],[2,11,1.45]],"ltp":9.6,"tv":769.44,"id":10616006}]}]}
{"op":"mcm","clk":"994178472","pt":1580549932549,"mc":[{"id":"1.168133548","rc":[{"trd":[[9.6,13.78],[10,246.03],[10.5,164.09]],"batl":[[0,10.5,3.3],[1,11,1.45],[2,11.5,10.44]],"ltp":10.5,"tv":780.11,"id":10616006}],"tv":4300.88}]}
{"op":"mcm","clk":"994178708","pt":1580549935309,"mc":[{"id":"1.168133548","rc":[{"batb":[[2,7.8,2.84]],"ltp":10.5,"tv":780.11,"id":10616006}]}]}
{"op":"mcm","clk":"994178801","pt":1580549936438,"mc":[{"id":"1.168133548","rc":[{"batb":[[0,9.4,8.72],[1,9.2,4.4],[2,9,5]],"ltp":10.5,"tv":780.11,"id":10616006},{"batb":[[1,22,1.98],[2,19,3.05]],"ltp":25.0,"tv":42.44,"id":9193530}]}]}
{"op":"mcm","clk":"994178992","pt":1580549939022,"mc":[{"id":"1.168133548","rc":[{"batb":[[2,19,2.14]],"ltp":25.0,"tv":42.44,"id":9193530}]}]}
{"op":"mcm","clk":"994179132","pt":1580549940540,"mc":[{"id":"1.168133548","rc":[{"batl":[[1,11,6.41]],"ltp":10.5,"tv":780.11,"id":10616006},{"batb":[[0,25,4],[1,24,2.9],[2,22,1.98]],"ltp":25.0,"tv":42.44,"id":9193530}]}]}
{"op":"mcm","clk":"994179744","pt":1580549946507,"mc":[{"id":"1.168133548","rc":[{"batl":[[1,8,5],[2,8.2,22.26]],"ltp":7.6,"tv":774.07,"id":10170404}]}]}
{"op":"mcm","clk":"994179839","pt":1580549947495,"mc":[{"id":"1.168133548","rc":[{"batb":[[1,24,2.1]],"ltp":25.0,"tv":42.44,"id":9193530}]}]}
{"op":"mcm","clk":"994180466","pt":1580549954440,"mc":[{"id":"1.168133548","rc":[{"batl":[[0,38,1.22],[1,40,3.03],[2,42,7.6]],"ltp":25.0,"tv":42.44,"id":9193530}]}]}
{"op":"mcm","clk":"994181555","pt":1580549966551,"mc":[{"id":"1.168133548","rc":[{"batb":[[0,7.6,2.27],[1,7.4,5.1],[2,7.2,2]],"ltp":7.6,"tv":774.07,"id":10170404}]}]}
{"op":"mcm","clk":"994182490","pt":1580549975182,"mc":[{"id":"1.168133548","rc":[{"batl":[[0,5.9,2.96]],"ltp":5.7,"tv":1216.24,"id":9417341}]}]}
{"op":"mcm","clk":"994182592","pt":1580549976062,"mc":[{"id":"1.168133548","rc":[{"batl":[[2,80,3]],"ltp":25.0,"tv":42.44,"id":9193530}]}]}
{"op":"mcm","clk":"994182766","pt":1580549977649,"mc":[{"id":"1.168133548","rc":[{"batl":[[0,10,2],[1,10.5,3.3],[2,11,6.41]],"ltp":10.5,"tv":780.11,"id":10616006}]}]}
{"op":"mcm","clk":"994182938","pt":1580549979362,"mc":[{"id":"1.168133548","rc":[{"batb":[[0,9.6,2.08],[1,9.4,8.72],[2,9.2,4.4]],"ltp":10.5,"tv":780.11,"id":10616006}]}]}
{"op":"mcm","clk":"994183261","pt":1580549982546,"mc":[{"id":"1.168133548","rc":[{"batl":[[0,5.9,16.96]],"ltp":5.7,"tv":1216.24,"id":9417341}]}]}
{"op":"mcm","clk":"994184279","pt":1580549992393,"mc":[{"id":"1.168133548","rc":[{"batl":[[0,40,3.74],[1,80,3],[2,95,2]],"ltp":25.0,"tv":42.44,"id":9193530}]}]}
{"op":"mcm","clk":"994184405","pt":1580549993483,"mc":[{"id":"1.168133548","rc":[{"batb":[[0,9.8,10],[1,9.6,3.24],[2,8.8,16.5]],"ltp":9.6,"tv":390.54,"id":15608820}]}]}
{"op":"mcm","clk":"994184489","pt":1580549994471,"mc":[{"id":"1.168133548","rc":[{"batb":[[0,9.6,3.24],[1,8.8,16.5],[2,8.4,5.05]],"ltp":9.6,"tv":390.54,"id":15608820},{"batl":[[1,95,2],[2,190,2]],"ltp":25.0,"tv":42.44,"id":9193530}]}]}
{"op":"mcm","clk":"994184573","pt":1580549995516,"mc":[{"id":"1.168133548","rc":[{"batb":[[1,9,10.42],[2,8.8,16.5]],"ltp":9.6,"tv":390.54,"id":15608820}]}]}
{"op":"mcm","clk":"994185620","pt":1580550005499,"mc":[{"id":"1.168133548","rc":[{"batb":[[0,7.6,6.27]],"ltp":7.6,"tv":774.07,"id":10170404}]}]}
{"op":"mcm","clk":"994185734","pt":1580550006499,"mc":[{"id":"1.168133548","rc":[{"batl":[[0,5.8,2.49],[1,5.9,6.17],[2,6,90.11]],"ltp":5.7,"tv":277.5,"id":8231803}]}]}
{"op":"mcm","clk":"994185855","pt":1580550007537,"mc":[{"id":"1.168133548","rc":[{"trd":[[5.7,17.05]],"batl":[[0,5.9,6.66],[1,6,90.11],[2,6.2,11.85]],"ltp":5.7,"tv":278.48,"id":8231803},{"batb":[[1,9,3.24]],"ltp":9.6,"tv":390.54,"id":15608820}],"tv":4301.86}]}
{"op":"mcm","clk":"994186541","pt":1580550014524,"mc":[{"id":"1.168133548","rc":[{"batb":[[2,8.8,7.18]],"ltp":9.6,"tv":390.54,"id":15608820}]}]}
{"op":"mcm","clk":"994187610","pt":1580550025434,"mc":[{"id":"1.168133548","rc":[{"batl":[[2,18,14]],"ltp":9.6,"tv":390.54,"id":15608820},{"batl":[[2,200,2.1]],"ltp":25.0,"tv":42.44,"id":9193530}]}]}
{"op":"mcm","clk":"994191046","pt":1580550060571,"mc":[{"id":"1.168133548","rc":[{"trd":[[7.6,39.1]],"batb":[[0,7.4,5.1],[1,7.2,2],[2,7,40]],"ltp":7.6,"tv":786.61,"id":10170404}],"tv":4314.4}]}
{"op":"mcm","clk":"994191224","pt":1580550062465,"mc":[{"id":"1.168133548","rc":[{"batb":[[2,7,43.05]],"ltp":7.6,"tv":786.61,"id":10170404},{"batb":[[0,25,4.66],[1,24,1.39]],"ltp":25.0,"tv":42.44,"id":9193530}]}]}
{"op":"mcm","clk":"994193269","pt":1580550083533,"mc":[{"id":"1.168133548","rc":[{"batl":[[0,7.6,2.5],[1,7.8,7.44],[2,8,5]],"ltp":7.6,"tv":786.61,"id":10170404}]}]}
{"op":"mcm","clk":"994193446","pt":1580550085250,"mc":[{"id":"1.168133548","rc":[{"batl":[[2,18.5,1.25]],"ltp":9.6,"tv":390.54,"id":15608820}]}]}
{"op":"mcm","clk":"994194751","pt":1580550097438,"mc":[{"id":"1.168133548","rc":[{"batl":[[2,11,4.97]],"ltp":10.5,"tv":780.11,"id":10616006}]}]}
{"op":"mcm","clk":"994195971","pt":1580550110466,"mc":[{"id":"1.168133548","rc":[{"trd":[[7.4,37.24]],"batb":[[0,7.4,3.1]],"ltp":7.4,"tv":790.61,"id":10170404}],"tv":4318.4}]}
{"op":"mcm","clk":"994197726","pt":1580550127473,"mc":[{"id":"1.168133548","rc":[{"batb":[[0,9.6,3.88]],"ltp":10.5,"tv":780.11,"id":10616006},{"batb":[[1,9,5.16]],"ltp":9.6,"tv":390.54,"id":15608820}]}]}
{"op":"mcm","clk":"994199128","pt":1580550140517,"mc":[{"id":"1.168133548","rc":[{"trd":[[7.6,44.1]],"batb":[[0,7.6,5.5],[1,7.4,3.1],[2,7.2,2]],"batl":[[0,7.8,7.44],[1,8,5],[2,8.2,8.94]],"ltp":7.6,"tv":795.61,"id":10170404}],"tv":4323.4}]}
{"op":"mcm","clk":"994199681","pt":1580550145508,"mc":[{"id":"1.168133548","rc":[{"batl":[[2,17.5,14]],"ltp":9.6,"tv":390.54,"id":15608820}]}]}
{"op":"mcm","clk":"994199872","pt":1580550147528,"mc":[{"id":"1.168133548","rc":[{"batl":[[2,11.5,10.44]],"ltp":10.5,"tv":780.11,"id":10616006}]}]}
{"op":"mcm","clk":"994199983","pt":1580550148517,"mc":[{"id":"1.168133548","rc":[{"batl":[[0,10,4.57]],"ltp":10.5,"tv":780.11,"id":10616006},{"batl":[[0,85,9.83],[1,95,2],[2,170,2]],"ltp":20.0,"tv":78.54,"id":9001159}]}]}
{"op":"mcm","clk":"994201461","pt":1580550163405,"mc":[{"id":"1.168133548","rc":[{"batl":[[0,70,7.87],[1,85,9.55],[2,95,2]],"ltp":20.0,"tv":78.54,"id":9001159}]}]}
{"op":"mcm","clk":"994203525","pt":1580550183153,"mc":[{"id":"1.168133548","rc":[{"batl":[[1,85,9.06]],"ltp":20.0,"tv":78.54,"id":9001159}]}]}
{"op":"mcm","clk":"994204173","pt":1580550189348,"mc":[{"id":"1.168133548","rc":[{"trd":[[9.6,43.43]],"batb":[[0,9.6,1.37]],"batl":[[0,10,5]],"ltp":9.6,"tv":394.28,"id":15608820}],"tv":4327.14}]}
{"op":"mcm","clk":"994205677","pt":1580550203490,"mc":[{"id":"1.168133548","rc":[{"batl":[[1,13.5,24.04]],"ltp":12.0,"tv":374.86,"id":8429550},{"batb":[[1,9,1.92],[2,8.6,6.02]],"ltp":9.6,"tv":394.28,"id":15608820}]}]}
{"op":"mcm","clk":"994206735","pt":1580550213898,"mc":[{"id":"1.168133548","rc":[{"batl":[[1,13.5,26.9]],"ltp":12.0,"tv":374.86,"id":8429550},{"batb":[[2,8.4,9.69]],"ltp":9.6,"tv":394.28,"id":15608820}]}]}
{"op":"mcm","clk":"994207772","pt":1580550223519,"mc":[{"id":"1.168133548","rc":[{"trd":[[26,1.56]],"batb":[[0,25,4.08]],"ltp":26.0,"tv":43.62,"id":9193530}],"tv":4328.31}]}
{"op":"mcm","clk":"994208294","pt":1580550228498,"mc":[{"id":"1.168133548","rc":[{"trd":[[5.8,314.87]],"batb":[[0,5.7,24.71],[1,5.5,22.16],[2,5.2,2]],"ltp":5.8,"tv":1222.17,"id":9417341}],"tv":4334.25}]}
{"op":"mcm","clk":"994208402","pt":1580550229541,"mc":[{"id":"1.168133548","rc":[{"batb":[[2,8.6,2.85]],"ltp":9.6,"tv":394.28,"id":15608820}]}]}
{"op":"mcm","clk":"994208508","pt":1580550230428,"mc":[{"id":"1.168133548","rc":[{"trd":[[7.8,43.68]],"batb":[[0,7.8,4.56],[1,7.6,5.5],[2,7.4,3.1]],"batl":[[0,8,5],[1,8.2,8.94],[2,8.4,3]],"ltp":7.8,"tv":810.49,"id":10170404}],"tv":4349.13}]}
{"op":"mcm","clk":"994208645","pt":1580550231421,"mc":[{"id":"1.168133548","rc":[{"batb":[[1,5.5,28.44]],"ltp":5.8,"tv":1222.17,"id":9417341},{"batl":[[1,8.2,19.71]],"ltp":7.8,"tv":810.49,"id":10170404}]}]}
{"op":"mcm","clk":"994209065","pt":1580550235232,"mc":[{"id":"1.168133548","rc":[{"batl":[[1,17,23.42],[2,18.5,1.25]],"ltp":9.6,"tv":394.28,"id":15608820}]}]}
{"op":"mcm","clk":"994209198","pt":1580550236539,"mc":[{"id":"1.168133548","rc":[{"trd":[[8,192.64]],"batb":[[0,8,4],[1,7.8,4.56],[2,7.6,5.5]],"batl":[[0,8.2,11.75],[1,8.4,10.84],[2,8.6,26.87]],"ltp":8.0,"tv":820.49,"id":10170404}],"tv":4359.13}]}
{"op":"mcm","clk":"994209456","pt":1580550238418,"mc":[{"id":"1.168133548","rc":[{"batl":[[1,8.4,3]],"ltp":8.0,"tv":820.49,"id":10170404}]}]}
{"op":"mcm","clk":"994209834","pt":1580550242535,"mc":[{"id":"1.168133548","rc":[{"batb":[[1,22,1.98],[2,19.5,4.84]],"ltp":26.0,"tv":43.62,"id":9193530}]}]}
{"op":"mcm","clk":"994209946","pt":1580550243539,"mc":[{"id":"1.168133548","rc":[{"batb":[[1,23,1.45],[2,22,1.98]],"ltp":26.0,"tv":43.62,"id":9193530}]}]}
{"op":"mcm","clk":"994210146","pt":1580550245528,"mc":[{"id":"1.168133548","rc":[{"batb":[[0,8,6]],"ltp":8.0,"tv":820.49,"id":10170404}]}]}
{"op":"mcm","clk":"994210336","pt":1580550247566,"mc":[{"id":"1.168133548","rc":[{"batl":[[0,10,2]],"ltp":10.5,"tv":780.11,"id":10616006}]}]}
{"op":"mcm","clk":"994210415","pt":1580550248350,"mc":[{"id":"1.168133548","rc":[{"batl":[[2,11,1.97]],"ltp":10.5,"tv":780.11,"id":10616006},{"batl":[[0,8.2,6.57],[1,8.4,8.45]],"ltp":8.0,"tv":820.49,"id":10170404}]}]}
{"op":"mcm","clk":"994211269","pt":1580550257552,"mc":[{"id":"1.168133548","rc":[{"batl":[[0,8.2,3.57],[1,8.4,5.45],[2,8.6,23.87]],"ltp":8.0,"tv":820.49,"id":10170404},{"trd":[[6.4,98.76]],"batb":[[0,6.2,18],[1,6,15.03],[2,5.8,4.26]],"batl":[[0,6.6,7.29]],"ltp":6.4,"tv":369.62,"id":17352128}],"tv":4362.21}]}
{"op":"mcm","clk":"994212104","pt":1580550265185,"mc":[{"id":"1.168133548","rc":[{"batl":[[1,16,16.42],[2,17,8]],"ltp":9.6,"tv":394.28,"id":15608820}]}]}
{"op":"mcm","clk":"994212852","pt":1580550272487,"mc":[{"id":"1.168133548","rc":[{"batl":[[0,6.6,10.29]],"ltp":6.4,"tv":369.62,"id":17352128}]}]}
{"op":"mcm","clk":"994213576","pt":1580550279307,"mc":[{"id":"1.168133548","rc":[{"batl":[[1,15.5,8.42],[2,16,16]],"ltp":9.6,"tv":394.28,"id":15608820}]}]}
{"op":"mcm","clk":"994214567","pt":1580550288219,"mc":[{"id":"1.168133548","rc":[{"batl":[[1,6.8,9]],"ltp":6.4,"tv":369.62,"id":17352128}]}]}
{"op":"mcm","clk":"994215142","pt":1580550294513,"mc":[{"id":"1.168133548","rc":[{"trd":[[11,15.86],[11.5,41.47]],"batb":[[0,11,2.46],[1,10.5,3.03],[2,10,12.86]],"ltp":11.0,"tv":381.65,"id":8429550},{"trd":[[8,200.64]],"batb":[[0,8,2]],"ltp":8.0,"tv":828.49,"id":10170404},{"batl":[[0,42,2.2],[1,70,7.67],[2,85,9.06]],"ltp":20.0,"tv":78.54,"id":9001159}],"tv":4377.0}]}
{"op":"mcm","clk":"994215265","pt":1580550295559,"mc":[{"id":"1.168133548","rc":[{"batl":[[2,17.5,14]],"ltp":9.6,"tv":394.28,"id":15608820}]}]}
{"op":"mcm","clk":"994216103","pt":1580550303272,"mc":[{"id":"1.168133548","rc":[{"batl":[[0,34,2],[1,65,2.6],[2,70,7.6]],"ltp":20.0,"tv":78.54,"id":9001159}]}]}
{"op":"mcm","clk":"994216409","pt":1580550305478,"mc":[{"id":"1.168133548","rc":[{"batb":[[0,8,4]],"ltp":8.0,"tv":828.49,"id":10170404}]}]}
{"op":"mcm","clk":"994216640","pt":1580550307563,"mc":[{"id":"1.168133548","rc":[{"batl":[[0,65,2.6],[1,70,7.6],[2,85,9.06]],"ltp":20.0,"tv":78.54,"id":9001159}]}]}
{"op":"mcm","clk":"994216986","pt":1580550311159,"mc":[{"id":"1.168133548","rc":[{"batl":[[0,12,1.33],[1,12.5,58.23],[2,13.5,26.9]],"ltp":11.0,"tv":381.65,"id":8429550}]}]}
{"op":"mcm","clk":"994218120","pt":1580550321574,"mc":[{"id":"1.168133548","rc":[{"trd":[[8,208.64]],"batb":[[0,7.8,4.56],[1,7.6,5.5],[2,7.4,3.1]],"batl":[[1,8.6,23.87],[2,9,2.85]],"ltp":8.0,"tv":836.48,"id":10170404}],"tv":4385.0}]}
{"op":"mcm","clk":"994218215","pt":1580550322463,"mc":[{"id":"1.168133548","rc":[{"batl":[[0,8.6,24.63],[1,8.8,7.84]],"ltp":8.0,"tv":836.48,"id":10170404},{"batl":[[0,28,1],[1,70,7.87]],"ltp":20.0,"tv":78.54,"id":9001159}]}]}
{"op":"mcm","clk":"994218553","pt":1580550325512,"mc":[{"id":"1.168133548","rc":[{"batl":[[2,18,14]],"ltp":9.6,"tv":394.28,"id":15608820},{"batl":[[1,70,7.67]],"ltp":20.0,"tv":78.54,"id":9001159}]}]}
{"op":"mcm","clk":"994218927","pt":1580550328519,"mc":[{"id":"1.168133548","rc":[{"batl":[[2,9.2,2.85]],"ltp":8.0,"tv":836.48,"id":10170404}]}]}
{"op":"mcm","clk":"994219069","pt":1580550329516,"mc":[{"id":"1.168133548","rc":[{"batl":[[2,9.4,7.44]],"ltp":8.0,"tv":836.48,"id":10170404}]}]}
{"op":"mcm","clk":"994219337","pt":1580550331507,"mc":[{"id":"1.168133548","rc":[{"batl":[[0,25,1]],"ltp":20.0,"tv":78.54,"id":9001159}]}]}
{"op":"mcm","clk":"994219447","pt":1580550332403,"mc":[{"id":"1.168133548","rc":[{"batb":[[0,8,6],[1,7.8,4.56],[2,7.6,5.5]],"batl":[[0,8.4,3.61],[1,8.6,23.87],[2,8.8,7.84]],"ltp":8.0,"tv":836.48,"id":10170404}]}]}
{"op":"mcm","clk":"994219572","pt":1580550333391,"mc":[{"id":"1.168133548","rc":[{"batl":[[1,8.6,26.72],[2,8.8,10.69]],"ltp":8.0,"tv":836.48,"id":10170404}]}]}
{"op":"mcm","clk":"994220556","pt":1580550341241,"mc":[{"id":"1.168133548","rc":[{"trd":[[8.2,31.62]],"batb":[[0,8.2,4.24],[1,8,6],[2,7.8,4.56]],"batl":[[0,8.4,2.85]],"ltp":8.2,"tv":838.0,"id":10170404}],"tv":4386.52}]}
{"op":"mcm","clk":"994221590","pt":1580550350510,"mc":[{"id":"1.168133548","rc":[{"trd":[[8.2,39.66]],"batb":[[0,8,6.22],[1,7.8,4.56],[2,7.6,5.5]],"ltp":8.2,"tv":846.05,"id":10170404}],"tv":4394.56}]}
{"op":"mcm","clk":"994221653","pt":1580550351244,"mc":[{"id":"1.168133548","rc":[{"batl":[[1,8.6,18.76]],"ltp":8.2,"tv":846.05,"id":10170404}]}]}
{"op":"mcm","clk":"994221794","pt":1580550352540,"mc":[{"id":"1.168133548","rc":[{"trd":[[8.2,40.1]],"batb":[[0,8,6]],"ltp":8.2,"tv":846.49,"id":10170404}],"tv":4395.0}]}
{"op":"mcm","clk":"994222162","pt":1580550355548,"mc":[{"id":"1.168133548","rc":[{"batl":[[2,17.5,14]],"ltp":9.6,"tv":394.28,"id":15608820}]}]}
{"op":"mcm","clk":"994223415","pt":1580550366558,"mc":[{"id":"1.168133548","rc":[{"trd":[[6.4,99.68]],"batb":[[0,6.4,1.54],[1,6.2,18],[2,6,15.03]],"batl":[[0,6.6,17.37],[2,7,89.17]],"ltp":6.4,"tv":370.54,"id":17352128}],"tv":4395.92}]}
{"op":"mcm","clk":"994224142","pt":1580550371471,"mc":[{"id":"1.168133548","rc":[{"batl":[[0,8.6,15.91],[1,8.8,7.84],[2,9.2,2.85]],"ltp":8.2,"tv":846.49,"id":10170404}]}]}
{"op":"mcm","clk":"994224251","pt":1580550372467,"mc":[{"id":"1.168133548","rc":[{"batl":[[2,9.4,7.44]],"ltp":8.2,"tv":846.49,"id":10170404}]}]}
{"op":"mcm","clk":"994224571","pt":1580550375480,"mc":[{"id":"1.168133548","rc":[{"batl":[[0,8.4,3.3],[1,8.6,15.91],[2,8.8,7.84]],"ltp":8.2,"tv":846.49,"id":10170404}]}]}
{"op":"mcm","clk":"994225903","pt":1580550385397,"mc":[{"id":"1.168133548","rc":[{"batl":[[2,16,16]],"ltp":9.6,"tv":394.28,"id":15608820}]}]}
{"op":"mcm","clk":"994226373","pt":1580550389478,"mc":[{"id":"1.168133548","rc":[{"batl":[[1,85,9.14],[2,95,2]],"ltp":20.0,"tv":78.54,"id":9001159}]}]}
{"op":"mcm","clk":"994228394","pt":1580550403323,"mc":[{"id":"1.168133548","rc":[{"batl":[[0,23,1]],"ltp":20.0,"tv":78.54,"id":9001159}]}]}
{"op":"mcm","clk":"994228645","pt":1580550405511,"mc":[{"id":"1.168133548","rc":[{"trd":[[25,12.18],[26,1.71]],"batb":[[0,25,2.08]],"ltp":25.0,"tv":47.61,"id":9193530}],"tv":4399.92}]}
{"op":"mcm","clk":"994228870","pt":1580550407430,"mc":[{"id":"1.168133548","rc":[{"trd":[[21,1.64]],"batb":[[0,20,8.97]],"batl":[[0,85,9.32],[1,95,2],[2,170,2]],"ltp":21.0,"tv":80.18,"id":9001159}],"tv":4401.56}]}
{"op":"mcm","clk":"994229042","pt":1580550408525,"mc":[{"id":"1.168133548","rc":[{"batl":[[0,85,9.51]],"ltp":21.0,"tv":80.18,"id":9001159}]}]}
{"op":"mcm","clk":"994229485","pt":1580550412442,"mc":[{"id":"1.168133548","rc":[{"batb":[[1,23,2.25]],"ltp":25.0,"tv":47.61,"id":9193530},{"trd":[[20,16.36]],"batb":[[0,20,8.79]],"batl":[[0,85,9.33]],"ltp":20.0,"tv":80.54,"id":9001159}],"tv":4401.92}]}
{"op":"mcm","clk":"994229887","pt":1580550415459,"mc":[{"id":"1.168133548","rc":[{"batl":[[2,290,2]],"ltp":20.0,"tv":80.54,"id":9001159}]}]}
{"op":"mcm","clk":"994231715","pt":1580550428468,"mc":[{"id":"1.168133548","rc":[{"trd":[[8,224.64]],"batb":[[0,8,5.08]],"ltp":8.0,"tv":862.49,"id":10170404},{"batl":[[0,38,1.13],[1,40,3.03],[2,95,2]],"ltp":25.0,"tv":47.61,"id":9193530}],"tv":4417.92}]}
{"op":"mcm","clk":"994234126","pt":1580550445489,"mc":[{"id":"1.168133548","rc":[{"batl":[[2,410,2.16]],"ltp":20.0,"tv":80.54,"id":9001159}]}]}
{"op":"mcm","clk":"994236783","pt":1580550466321,"mc":[{"id":"1.168133548","rc":[{"batb":[[1,24,2.8],[2,23,1.45]],"ltp":25.0,"tv":47.61,"id":9193530}]}]}
{"op":"mcm","clk":"994237323","pt":1580550470539,"mc":[{"id":"1.168133548","rc":[{"batl":[[0,80,7.92],[1,85,9],[2,95,2]],"ltp":20.0,"tv":80.54,"id":9001159}]}]}
{"op":"mcm","clk":"994237877","pt":1580550475526,"mc":[{"id":"1.168133548","rc":[{"batl":[[0,80,8.42]],"ltp":20.0,"tv":80.54,"id":9001159}]}]}
{"op":"mcm","clk":"994240327","pt":1580550496561,"mc":[{"id":"1.168133548","rc":[{"batb":[[0,6.4,3.54]],"ltp":6.4,"tv":370.54,"id":17352128}]}]}
{"op":"mcm","clk":"994241402","pt":1580550506100,"mc":[{"id":"1.168133548","rc":[{"batl":[[2,17.5,14]],"ltp":9.6,"tv":394.28,"id":15608820}]}]}
{"op":"mcm","clk":"994241894","pt":1580550510517,"mc":[{"id":"1.168133548","rc":[{"batb":[[0,5.6,12.65]],"ltp":5.7,"tv":278.48,"id":8231803}]}]}
{"op":"mcm","clk":"994242038","pt":1580550511509,"mc":[{"id":"1.168133548","rc":[{"batb":[[0,11,6.1]],"ltp":11.0,"tv":381.65,"id":8429550},{"batb":[[0,5.7,31.73]],"ltp":5.8,"tv":1222.17,"id":9417341},{"batb":[[0,8,10.08]],"ltp":8.0,"tv":862.49,"id":10170404},{"batb":[[2,8.6,7.5]],"ltp":9.6,"tv":394.28,"id":15608820},{"batb":[[0,6.4,9.79]],"ltp":6.4,"tv":370.54,"id":17352128}]}]}
{"op":"mcm","clk":"994242124","pt":1580550512294,"mc":[{"id":"1.168133548","rc":[{"batb":[[0,9.6,8.05]],"ltp":10.5,"tv":780.11,"id":10616006},{"batb":[[0,25,3.68]],"ltp":25.0,"tv":47.61,"id":9193530},{"batb":[[0,20,10.79]],"ltp":20.0,"tv":80.54,"id":9001159}]}]}
{"op":"mcm","clk":"994242385","pt":1580550514402,"mc":[{"id":"1.168133548","rc":[{"trd":[[9.6,46.17]],"batb":[[0,9,1.92],[1,8.6,7.5],[2,8.4,8.49]],"batl":[[0,9.6,2.63],[1,10,5],[2,15.5,8.42]],"ltp":9.6,"tv":397.02,"id":15608820}],"tv":4420.66}]}
{"op":"mcm","clk":"994242781","pt":1580550517532,"mc":[{"id":"1.168133548","rc":[{"batb":[[1,8.6,4.65],[2,8.4,5.05]],"ltp":9.6,"tv":397.02,"id":15608820},{"batb":[[1,24,2]],"ltp":25.0,"tv":47.61,"id":9193530}]}]}
{"op":"mcm","clk":"994243297","pt":1580550522224,"mc":[{"id":"1.168133548","rc":[{"batb":[[1,8.8,1.81],[2,8.6,4.65]],"batl":[[0,9.6,2.99]],"ltp":9.6,"tv":397.02,"id":15608820}]}]}
{"op":"mcm","clk":"994244272","pt":1580550530516,"mc":[{"id":"1.168133548","rc":[{"batl":[[0,10.5,3.3],[1,11,1.97],[2,11.5,10.44]],"ltp":10.5,"tv":780.11,"id":10616006}]}]}
{"op":"mcm","clk":"994244700","pt":1580550534532,"mc":[{"id":"1.168133548","rc":[{"batl":[[1,9.8,8],[2,10,5]],"ltp":9.6,"tv":397.02,"id":15608820}]}]}
{"op":"mcm","clk":"994244811","pt":1580550535564,"mc":[{"id":"1.168133548","rc":[{"batl":[[0,9.4,3.39],[1,9.6,2.99],[2,9.8,8]],"ltp":9.6,"tv":397.02,"id":15608820}]}]}
{"op":"mcm","clk":"994244906","pt":1580550536449,"mc":[{"id":"1.168133548","rc":[{"batb":[[1,9.2,4.4],[2,9,5]],"ltp":10.5,"tv":780.11,"id":10616006}]}]}
{"op":"mcm","clk":"994245476","pt":1580550541562,"mc":[{"id":"1.168133548","rc":[{"batb":[[0,9,4.94]],"ltp":9.6,"tv":397.02,"id":15608820}]}]}
{"op":"mcm","clk":"994246376","pt":1580550548374,"mc":[{"id":"1.168133548","rc":[{"batl":[[0,12.5,58.23],[1,13.5,26.9],[2,16,16]],"ltp":11.0,"tv":381.65,"id":8429550},{"batb":[[1,9.2,9.02]],"ltp":10.5,"tv":780.11,"id":10616006},{"batb":[[2,8.6,7.2]],"ltp":9.6,"tv":397.02,"id":15608820}]}]}
{"op":"mcm","clk":"994248234","pt":1580550563500,"mc":[{"id":"1.168133548","rc":[{"trd":[[9.2,23.17]],"batb":[[0,9,5.36]],"batl":[[0,9.8,8],[1,10,5],[2,12,21.42]],"ltp":9.2,"tv":403.0,"id":15608820}],"tv":4426.64}]}
{"op":"mcm","clk":"994248396","pt":1580550564510,"mc":[{"id":"1.168133548","rc":[{"batb":[[0,9,4.94],[2,8.6,10.26]],"batl":[[0,9.2,8],[1,9.6,6.23],[2,10,7.11]],"ltp":9.2,"tv":403.0,"id":15608820}]}]}
{"op":"mcm","clk":"994248639","pt":1580550566387,"mc":[{"id":"1.168133548","rc":[{"batl":[[2,17,18.29]],"ltp":11.0,"tv":381.65,"id":8429550}]}]}
{"op":"mcm","clk":"994249455","pt":1580550572511,"mc":[{"id":"1.168133548","rc":[{"batb":[[1,8.6,10.26],[2,8.4,2.05]],"ltp":9.2,"tv":403.0,"id":15608820}]}]}
{"op":"mcm","clk":"994249689","pt":1580550574439,"mc":[{"id":"1.168133548","rc":[{"trd":[[9,33.87]],"batb":[[0,9,1.95]],"ltp":9.0,"tv":409.0,"id":15608820}],"tv":4432.64}]}
{"op":"mcm","clk":"994249948","pt":1580550576434,"mc":[{"id":"1.168133548","rc":[{"batb":[[1,8.6,7.2]],"ltp":9.0,"tv":409.0,"id":15608820}]}]}
{"op":"mcm","clk":"994250583","pt":1580550581529,"mc":[{"id":"1.168133548","rc":[{"trd":[[8,244.64]],"batb":[[0,7.8,4.64],[1,7.6,5.5],[2,7.4,3.1]],"ltp":8.0,"tv":882.49,"id":10170404}],"tv":4452.64}]}
{"op":"mcm","clk":"994250690","pt":1580550582411,"mc":[{"id":"1.168133548","rc":[{"batl":[[0,5.9,2.96]],"ltp":5.8,"tv":1222.17,"id":9417341},{"batb":[[1,7.6,8.01]],"batl":[[0,8.2,7.02],[1,8.4,3.3],[2,8.6,15.91]],"ltp":8.0,"tv":882.49,"id":10170404},{"batb":[[1,8.6,4.65]],"ltp":9.0,"tv":409.0,"id":15608820},{"batl":[[2,7,87.5]],"ltp":6.4,"tv":370.54,"id":17352128}]}]}
{"op":"mcm","clk":"994250922","pt":1580550584555,"mc":[{"id":"1.168133548","rc":[{"batb":[[1,7.6,5.5]],"ltp":8.0,"tv":882.49,"id":10170404}]}]}
{"op":"mcm","clk":"994251291","pt":1580550587442,"mc":[{"id":"1.168133548","rc":[{"batl":[[0,5.9,16.96]],"ltp":5.8,"tv":1222.17,"id":9417341}]}]}
{"op":"mcm","clk":"994257087","pt":1580550634507,"mc":[{"id":"1.168133548","rc":[{"batl":[[1,13.5,20.72]],"ltp":11.0,"tv":381.65,"id":8429550}]}]}
{"op":"mcm","clk":"994258244","pt":1580550643473,"mc":[{"id":"1.168133548","rc":[{"batl":[[0,8.2,27.02]],"ltp":8.0,"tv":882.49,"id":10170404}]}]}
{"op":"mcm","clk":"994258518","pt":1580550645477,"mc":[{"id":"1.168133548","rc":[{"batl":[[1,13.5,24.04]],"ltp":11.0,"tv":381.65,"id":8429550},{"batb":[[0,8.8,1.95]],"batl":[[1,10,7.11],[2,12.5,20.42]],"ltp":9.0,"tv":409.0,"id":15608820}]}]}
{"op":"mcm","clk":"994258656","pt":1580550646512,"mc":[{"id":"1.168133548","rc":[{"trd":[[8,244.8]],"batb":[[0,7.8,4.56]],"batl":[[0,8,3.38],[1,8.2,27.02]],"ltp":8.0,"tv":882.65,"id":10170404},{"batb":[[0,8.8,2.2]],"batl":[[1,9.8,5.7],[2,10,10.65]],"ltp":9.0,"tv":409.0,"id":15608820}],"tv":4452.81}]}
{"op":"mcm","clk":"994258884","pt":1580550648397,"mc":[{"id":"1.168133548","rc":[{"batl":[[1,8.2,31.99]],"ltp":8.0,"tv":882.65,"id":10170404},{"batl":[[1,9.8,11.41]],"ltp":9.0,"tv":409.0,"id":15608820}]}]}
{"op":"mcm","clk":"994259284","pt":1580550651573,"mc":[{"id":"1.168133548","rc":[{"batl":[[0,8,23.38]],"ltp":8.0,"tv":882.65,"id":10170404}]}]}
{"op":"mcm","clk":"994259403","pt":1580550652520,"mc":[{"id":"1.168133548","rc":[{"batl":[[2,8.4,2.85]],"ltp":8.0,"tv":882.65,"id":10170404}]}]}
{"op":"mcm","clk":"994259522","pt":1580550653520,"mc":[{"id":"1.168133548","rc":[{"batl":[[1,8.2,34.54]],"ltp":8.0,"tv":882.65,"id":10170404},{"trd":[[6.4,119.26]],"batb":[[0,6.2,18],[1,6,15.03],[2,5.8,4.26]],"ltp":6.4,"tv":390.12,"id":17352128}],"tv":4472.39}]}
{"op":"mcm","clk":"994259790","pt":1580550655513,"mc":[{"id":"1.168133548","rc":[{"batl":[[0,9.6,14.23]],"ltp":9.0,"tv":409.0,"id":15608820},{"batb":[[1,6,9.83]],"ltp":6.4,"tv":390.12,"id":17352128}]}]}
{"op":"mcm","clk":"994259912","pt":1580550656504,"mc":[{"id":"1.168133548","rc":[{"batl":[[1,9.8,5.7]],"ltp":9.0,"tv":409.0,"id":15608820}]}]}
{"op":"mcm","clk":"994260078","pt":1580550658021,"mc":[{"id":"1.168133548","rc":[{"batl":[[1,10,5],[2,12.5,20.42]],"ltp":9.0,"tv":409.0,"id":15608820}]}]}
{"op":"mcm","clk":"994261203","pt":1580550667429,"mc":[{"id":"1.168133548","rc":[{"batl":[[0,40,3.74],[1,95,2],[2,190,2]],"ltp":25.0,"tv":47.61,"id":9193530}]}]}
{"op":"mcm","clk":"994262054","pt":1580550673524,"mc":[{"id":"1.168133548","rc":[{"trd":[[5.6,5.12]],"batb":[[0,5.6,10.47]],"ltp":5.6,"tv":282.84,"id":8231803}],"tv":4476.75}]}
{"op":"mcm","clk":"994263666","pt":1580550686380,"mc":[{"id":"1.168133548","rc":[{"batl":[[2,15,17.42]],"ltp":9.0,"tv":409.0,"id":15608820},{"batl":[[2,220,9]],"ltp":25.0,"tv":47.61,"id":9193530}]}]}
{"op":"mcm","clk":"994264596","pt":1580550694391,"mc":[{"id":"1.168133548","rc":[{"batl":[[0,9.6,6.23],[1,9.8,8],[2,10,5]],"ltp":9.0,"tv":409.0,"id":15608820}]}]}
{"op":"mcm","clk":"994264721","pt":1580550695489,"mc":[{"id":"1.168133548","rc":[{"batl":[[0,85,9.82],[1,95,2],[2,190,2]],"ltp":20.0,"tv":80.54,"id":9001159}]}]}
{"op":"mcm","clk":"994266489","pt":1580550712521,"mc":[{"id":"1.168133548","rc":[{"batl":[[0,80,8.42],[1,85,9],[2,95,2]],"ltp":20.0,"tv":80.54,"id":9001159}]}]}
{"op":"mcm","clk":"994266999","pt":1580550717556,"mc":[{"id":"1.168133548","rc":[{"batl":[[1,13.5,26.9]],"ltp":11.0,"tv":381.65,"id":8429550}]}]}
{"op":"mcm","clk":"994267208","pt":1580550719434,"mc":[{"id":"1.168133548","rc":[{"trd":[[5.6,13.12]],"batb":[[0,5.6,6.47]],"ltp":5.6,"tv":290.84,"id":8231803}],"tv":4484.75}]}
{"op":"mcm","clk":"994267754","pt":1580550724038,"mc":[{"id":"1.168133548","rc":[{"batl":[[0,9.6,14.23],[1,10,5],[2,12.5,20.42]],"ltp":9.0,"tv":409.0,"id":15608820}]}]}
{"op":"mcm","clk":"994269939","pt":1580550743371,"mc":[{"id":"1.168133548","rc":[{"batb":[[0,5.6,8.47]],"ltp":5.6,"tv":290.84,"id":8231803}]}]}
{"op":"mcm","clk":"994270350","pt":1580550746499,"mc":[{"id":"1.168133548","rc":[{"batl":[[2,15,17.42]],"ltp":9.0,"tv":409.0,"id":15608820}]}]}
{"op":"mcm","clk":"994282641","pt":1580550764544,"mc":[{"id":"1.168133548","rc":[{"batl":[[1,6,2]],"ltp":5.6,"tv":290.84,"id":8231803}]}]}
{"op":"mcm","clk":"994282748","pt":1580550765534,"mc":[{"id":"1.168133548","rc":[{"batl":[[0,5.8,88.6],[1,5.9,6.17],[2,6,2]],"ltp":5.6,"tv":290.84,"id":8231803}]}]}
{"op":"mcm","clk":"994282857","pt":1580550766525,"mc":[{"id":"1.168133548","rc":[{"batl":[[0,10,2],[1,10.5,3.3],[2,11,1.97]],"ltp":10.5,"tv":780.11,"id":10616006}]}]}
{"op":"mcm","clk":"994283921","pt":1580550776529,"mc":[{"id":"1.168133548","rc":[{"batl":[[2,17,15.42]],"ltp":9.0,"tv":409.0,"id":15608820}]}]}
{"op":"mcm","clk":"994284395","pt":1580550780531,"mc":[{"id":"1.168133548","rc":[{"batl":[[2,8.6,7.96]],"ltp":8.0,"tv":882.65,"id":10170404}]}]}
{"op":"mcm","clk":"994285858","pt":1580550793488,"mc":[{"id":"1.168133548","rc":[{"batl":[[0,9.6,6.23]],"ltp":9.0,"tv":409.0,"id":15608820}]}]}
{"op":"mcm","clk":"994285970","pt":1580550794477,"mc":[{"id":"1.168133548","rc":[{"batl":[[1,9.8,8],[2,10,5]],"ltp":9.0,"tv":409.0,"id":15608820}]}]}
{"op":"mcm","clk":"994286055","pt":1580550795255,"mc":[{"id":"1.168133548","rc":[{"batl":[[1,5.9,2.17]],"ltp":5.6,"tv":290.84,"id":8231803}]}]}
{"op":"mcm","clk":"994286858","pt":1580550803359,"mc":[{"id":"1.168133548","rc":[{"batl":[[0,9.6,14.23],[1,10,5],[2,17,15.42]],"ltp":9.0,"tv":409.0,"id":15608820}]}]}
{"op":"mcm","clk":"994287960","pt":1580550813509,"mc":[{"id":"1.168133548","rc":[{"batl":[[0,9.6,6.23],[1,9.8,8],[2,10,5]],"ltp":9.0,"tv":409.0,"id":15608820}]}]}
{"op":"mcm","clk":"994290368","pt":1580550833529,"mc":[{"id":"1.168133548","rc":[{"batl":[[0,5.7,2.92],[1,5.8,88.6],[2,5.9,2.17]],"ltp":5.6,"tv":290.84,"id":8231803}]}]}
{"op":"mcm","clk":"994290478","pt":1580550834563,"mc":[{"id":"1.168133548","rc":[{"batl":[[0,5.8,88.6],[1,5.9,2.17],[2,6,2]],"ltp":5.6,"tv":290.84,"id":8231803}]}]}
{"op":"mcm","clk":"994294915","pt":1580550872428,"mc":[{"id":"1.168133548","rc":[{"batl":[[0,9.6,14.23],[1,10,5],[2,12.5,20.42]],"ltp":9.0,"tv":409.0,"id":15608820}]}]}
{"op":"mcm","clk":"994297770","pt":1580550896475,"mc":[{"id":"1.168133548","rc":[{"batl":[[2,15,17.42]],"ltp":9.0,"tv":409.0,"id":15608820}]}]}
{"op":"mcm","clk":"994299531","pt":1580550911501,"mc":[{"id":"1.168133548","rc":[{"batl":[[0,9.6,6.23],[1,9.8,8],[2,10,5]],"ltp":9.0,"tv":409.0,"id":15608820}]}]}
{"op":"mcm","clk":"994300643","pt":1580550921488,"mc":[{"id":"1.168133548","rc":[{"batl":[[0,9.6,14.23],[1,10,5],[2,15,17.42]],"ltp":9.0,"tv":409.0,"id":15608820}]}]}
{"op":"mcm","clk":"994301234","pt":1580550926526,"mc":[{"id":"1.168133548","rc":[{"batl":[[2,17,15.42]],"ltp":9.0,"tv":409.0,"id":15608820}]}]}
{"op":"mcm","clk":"994301737","pt":1580550930429,"mc":[{"id":"1.168133548","rc":[{"trd":[[6.2,81.8]],"batb":[[0,6.2,8]],"ltp":6.2,"tv":410.12,"id":17352128}],"tv":4504.75}]}
{"op":"mcm","clk":"994302665","pt":1580550938442,"mc":[{"id":"1.168133548","rc":[{"batl":[[0,85,9.82],[1,95,2],[2,190,2]],"ltp":20.0,"tv":80.54,"id":9001159}]}]}
{"op":"mcm","clk":"994304522","pt":1580550954368,"mc":[{"id":"1.168133548","rc":[{"batl":[[0,80,8.42],[1,85,9],[2,95,2]],"ltp":20.0,"tv":80.54,"id":9001159}]}]}
{"op":"mcm","clk":"994305225","pt":1580550960220,"mc":[{"id":"1.168133548","rc":[{"batl":[[0,9.6,6.23],[1,9.8,8],[2,10,5]],"ltp":9.0,"tv":409.0,"id":15608820}]}]}
{"op":"mcm","clk":"994306570","pt":1580550971504,"mc":[{"id":"1.168133548","rc":[{"batl":[[2,8.4,2.85]],"ltp":8.0,"tv":882.65,"id":10170404}]}]}
{"op":"mcm","clk":"994308371","pt":1580550986572,"mc":[{"id":"1.168133548","rc":[{"batb":[[0,12,21.25],[1,11,6.1],[2,10.5,3.03]],"ltp":11.0,"tv":381.65,"id":8429550}]}]}
{"op":"mcm","clk":"994308440","pt":1580550987245,"mc":[{"id":"1.168133548","rc":[{"trd":[[12,76.44]],"batb":[[0,12,18.96]],"ltp":12.0,"tv":386.23,"id":8429550}],"tv":4509.33}]}
{"op":"mcm","clk":"994308710","pt":1580550989538,"mc":[{"id":"1.168133548","rc":[{"batl":[[1,10,5],[2,12.5,20.42]],"ltp":9.0,"tv":409.0,"id":15608820}]}]}
{"op":"mcm","clk":"994308807","pt":1580550990478,"mc":[{"id":"1.168133548","rc":[{"batl":[[0,9.6,14.23]],"ltp":9.0,"tv":409.0,"id":15608820}]}]}
{"op":"mcm","clk":"994311748","pt":1580551017306,"mc":[{"id":"1.168133548","rc":[{"trd":[[12,83.96]],"batb":[[0,12,15.2]],"ltp":12.0,"tv":393.75,"id":8429550},{"batl":[[2,15,17.42]],"ltp":9.0,"tv":409.0,"id":15608820}],"tv":4516.85}]}
{"op":"mcm","clk":"994311959","pt":1580551019378,"mc":[{"id":"1.168133548","rc":[{"trd":[[12,87.96]],"batb":[[0,12,13.2]],"ltp":12.0,"tv":397.75,"id":8429550},{"batl":[[0,9.6,6.23],[1,9.8,8],[2,10,5]],"ltp":9.0,"tv":409.0,"id":15608820}],"tv":4520.85}]}
{"op":"mcm","clk":"994312231","pt":1580551021493,"mc":[{"id":"1.168133548","rc":[{"batl":[[0,12.5,76.07]],"ltp":12.0,"tv":397.75,"id":8429550}]}]}
{"op":"mcm","clk":"994312671","pt":1580551025484,"mc":[{"id":"1.168133548","rc":[{"trd":[[5.6,23.12]],"batb":[[0,5.6,3.47]],"ltp":5.6,"tv":300.84,"id":8231803}],"tv":4530.85}]}
{"op":"mcm","clk":"994313097","pt":1580551029425,"mc":[{"id":"1.168133548","rc":[{"batl":[[0,9.6,14.23],[1,10,5],[2,15,17.42]],"ltp":9.0,"tv":409.0,"id":15608820}]}]}
{"op":"mcm","clk":"994313779","pt":1580551034540,"mc":[{"id":"1.168133548","rc":[{"trd":[[5.7,64.76]],"batb":[[0,5.7,27.73]],"ltp":5.7,"tv":1230.17,"id":9417341},{"batl":[[2,8.6,7.96]],"ltp":8.0,"tv":882.65,"id":10170404}],"tv":4538.85}]}
{"op":"mcm","clk":"994315245","pt":1580551047339,"mc":[{"id":"1.168133548","rc":[{"batl":[[2,15.5,16.42]],"ltp":9.0,"tv":409.0,"id":15608820}]}]}
{"op":"mcm","clk":"994319059","pt":1580551078498,"mc":[{"id":"1.168133548","rc":[{"trd":[[5.7,84.76]],"batb":[[0,5.7,17.73]],"ltp":5.7,"tv":1250.17,"id":9417341}],"tv":4558.85}]}
{"op":"mcm","clk":"994320321","pt":1580551088493,"mc":[{"id":"1.168133548","rc":[{"batl":[[0,9.6,6.23],[1,9.8,8],[2,10,5]],"ltp":9.0,"tv":409.0,"id":15608820}]}]}
{"op":"mcm","clk":"994321509","pt":1580551098539,"mc":[{"id":"1.168133548","rc":[{"batb":[[1,5.5,24.13]],"ltp":5.7,"tv":1250.17,"id":9417341}]}]}
{"op":"mcm","clk":"994323124","pt":1580551112522,"mc":[{"id":"1.168133548","rc":[{"trd":[[25,18.18]],"batb":[[0,24,2.68],[1,23,1.45],[2,22,1.98]],"ltp":25.0,"tv":53.61,"id":9193530}],"tv":4564.85}]}
{"op":"mcm","clk":"994323239","pt":1580551113554,"mc":[{"id":"1.168133548","rc":[{"trd":[[5.7,104.76]],"batb":[[0,5.7,7.73]],"ltp":5.7,"tv":1270.17,"id":9417341}],"tv":4584.85}]}
{"op":"mcm","clk":"994324353","pt":1580551122354,"mc":[{"id":"1.168133548","rc":[{"batl":[[0,38,1.13],[1,40,3.03],[2,95,2]],"ltp":25.0,"tv":53.61,"id":9193530}]}]}
{"op":"mcm","clk":"994325101","pt":1580551128360,"mc":[{"id":"1.168133548","rc":[{"batb":[[1,5.5,20.75]],"ltp":5.7,"tv":1270.17,"id":9417341}]}]}
{"op":"mcm","clk":"994325217","pt":1580551129552,"mc":[{"id":"1.168133548","rc":[{"batb":[[1,5.5,17.85]],"ltp":5.7,"tv":1270.17,"id":9417341}]}]}
{"op":"mcm","clk":"994326057","pt":1580551136472,"mc":[{"id":"1.168133548","rc":[{"trd":[[8.2,27.08],[8.4,40.18],[8.6,173.23],[8.8,22.45]],"batb":[[0,8.2,13.9],[1,8,3],[2,7.6,6.25]],"ltp":8.2,"tv":429.0,"id":15608820}],"tv":4604.84}]}
{"op":"mcm","clk":"994326195","pt":1580551137567,"mc":[{"id":"1.168133548","rc":[{"batb":[[1,8,6.76]],"ltp":8.2,"tv":429.0,"id":15608820}]}]}
{"op":"mcm","clk":"994326412","pt":1580551139538,"mc":[{"id":"1.168133548","rc":[{"batb":[[1,8,3.76]],"ltp":8.2,"tv":429.0,"id":15608820}]}]}
{"op":"mcm","clk":"994327597","pt":1580551149559,"mc":[{"id":"1.168133548","rc":[{"batb":[[1,7.8,7.33]],"ltp":8.2,"tv":429.0,"id":15608820}]}]}
{"op":"mcm","clk":"994328988","pt":1580551163476,"mc":[{"id":"1.168133548","rc":[{"batb":[[0,5.8,3],[1,5.7,7.73],[2,5.5,17.85]],"ltp":5.7,"tv":1270.17,"id":9417341},{"batb":[[1,7.8,15.17]],"ltp":8.2,"tv":429.0,"id":15608820}]}]}
{"op":"mcm","clk":"994330405","pt":1580551177504,"mc":[{"id":"1.168133548","rc":[{"batl":[[0,9.6,8],[1,10,5],[2,12.5,20.42]],"ltp":8.2,"tv":429.0,"id":15608820}]}]}
{"op":"mcm","clk":"994330613","pt":1580551179287,"mc":[{"id":"1.168133548","rc":[{"batl":[[0,85,9.82],[1,95,2],[2,190,2]],"ltp":20.0,"tv":80.54,"id":9001159}]}]}
{"op":"mcm","clk":"994331298","pt":1580551184524,"mc":[{"id":"1.168133548","rc":[{"batl":[[0,9.8,2],[1,10,2],[2,10.5,3.3]],"ltp":10.5,"tv":780.11,"id":10616006}]}]}
{"op":"mcm","clk":"994331614","pt":1580551187137,"mc":[{"id":"1.168133548","rc":[{"batl":[[0,5.9,2.96]],"ltp":5.7,"tv":1270.17,"id":9417341}]}]}
{"op":"mcm","clk":"994332412","pt":1580551194521,"mc":[{"id":"1.168133548","rc":[{"batl":[[0,5.9,16.96]],"ltp":5.7,"tv":1270.17,"id":9417341},{"batl":[[0,80,8.42],[1,85,9],[2,95,2]],"ltp":20.0,"tv":80.54,"id":9001159}]}]}
{"op":"mcm","clk":"994332622","pt":1580551196562,"mc":[{"id":"1.168133548","rc":[{"batl":[[0,9.8,8],[2,12,10.58]],"ltp":8.2,"tv":429.0,"id":15608820}]}]}
{"op":"mcm","clk":"994333287","pt":1580551200570,"mc":[{"id":"1.168133548","rc":[{"batl":[[0,8.8,2],[1,9.8,8],[2,10,5]],"ltp":8.2,"tv":429.0,"id":15608820}]}]}
{"op":"mcm","clk":"994334123","pt":1580551206550,"mc":[{"id":"1.168133548","rc":[{"batl":[[1,9.6,8]],"ltp":8.2,"tv":429.0,"id":15608820},{"batl":[[0,6.4,10],[1,6.6,17.37],[2,6.8,9]],"ltp":6.2,"tv":410.12,"id":17352128}]}]}
{"op":"mcm","clk":"994334233","pt":1580551207379,"mc":[{"id":"1.168133548","rc":[{"batl":[[2,9.8,2.88]],"ltp":8.2,"tv":429.0,"id":15608820}]}]}
{"op":"mcm","clk":"994334395","pt":1580551208573,"mc":[{"id":"1.168133548","rc":[{"batb":[[1,19,8]],"ltp":20.0,"tv":80.54,"id":9001159}]}]}
{"op":"mcm","clk":"994334542","pt":1580551209538,"mc":[{"id":"1.168133548","rc":[{"batb":[[0,5.7,3.02],[1,5.6,3.47],[2,5.5,4]],"ltp":5.6,"tv":300.84,"id":8231803},{"trd":[[6.4,124.64]],"batl":[[0,6.4,7.31]],"ltp":6.4,"tv":415.5,"id":17352128}],"tv":4610.22}]}
{"op":"mcm","clk":"994334624","pt":1580551210269,"mc":[{"id":"1.168133548","rc":[{"batb":[[0,20,11.61]],"ltp":20.0,"tv":80.54,"id":9001159}]}]}
{"op":"mcm","clk":"994335379","pt":1580551216165,"mc":[{"id":"1.168133548","rc":[{"batb":[[0,21,1.66],[1,20,10.79],[2,19,8]],"ltp":20.0,"tv":80.54,"id":9001159}]}]}
{"op":"mcm","clk":"994335825","pt":1580551219543,"mc":[{"id":"1.168133548","rc":[{"batb":[[2,19,10.4]],"ltp":20.0,"tv":80.54,"id":9001159}]}]}
{"op":"mcm","clk":"994336694","pt":1580551225496,"mc":[{"id":"1.168133548","rc":[{"batl":[[1,9.8,2.88],[2,10,5]],"ltp":8.2,"tv":429.0,"id":15608820}]}]}
{"op":"mcm","clk":"994336797","pt":1580551226386,"mc":[{"id":"1.168133548","rc":[{"batl":[[1,9.2,8],[2,9.8,2.88]],"ltp":8.2,"tv":429.0,"id":15608820}]}]}
{"op":"mcm","clk":"994337850","pt":1580551235524,"mc":[{"id":"1.168133548","rc":[{"batb":[[0,5.7,5.02],[1,5.6,1.47]],"ltp":5.6,"tv":300.84,"id":8231803}]}]}
{"op":"mcm","clk":"994338846","pt":1580551244526,"mc":[{"id":"1.168133548","rc":[{"batb":[[1,8,4.92],[2,7.8,15.17]],"batl":[[2,9.8,6.9]],"ltp":8.2,"tv":429.0,"id":15608820}]}]}
{"op":"mcm","clk":"994340099","pt":1580551255517,"mc":[{"id":"1.168133548","rc":[{"batb":[[0,5.7,3.02],[1,5.6,3.47]],"ltp":5.6,"tv":300.84,"id":8231803}]}]}
{"op":"mcm","clk":"994341675","pt":1580551265459,"mc":[{"id":"1.168133548","rc":[{"batb":[[0,5.7,5.02],[1,5.6,1.47]],"ltp":5.6,"tv":300.84,"id":8231803}]}]}
{"op":"mcm","clk":"994342625","pt":1580551273560,"mc":[{"id":"1.168133548","rc":[{"batb":[[0,8.4,2.38],[1,8.2,13.9],[2,8,4.92]],"ltp":8.2,"tv":429.0,"id":15608820}]}]}
{"op":"mcm","clk":"994342848","pt":1580551275488,"mc":[{"id":"1.168133548","rc":[{"batb":[[0,23,2.13],[1,22,1.98],[2,19.5,3.96]],"ltp":25.0,"tv":53.61,"id":9193530}]}]}
{"op":"mcm","clk":"994343189","pt":1580551278391,"mc":[{"id":"1.168133548","rc":[{"batb":[[0,23,2.96]],"ltp":25.0,"tv":53.61,"id":9193530}]}]}
{"op":"mcm","clk":"994344061","pt":1580551284574,"mc":[{"id":"1.168133548","rc":[{"batl":[[2,8.4,2.85]],"ltp":8.0,"tv":882.65,"id":10170404}]}]}
{"op":"mcm","clk":"994344288","pt":1580551285573,"mc":[{"id":"1.168133548","rc":[{"batb":[[0,5.7,3.02],[1,5.6,3.47]],"ltp":5.6,"tv":300.84,"id":8231803}]}]}
{"op":"mcm","clk":"994346914","pt":1580551305427,"mc":[{"id":"1.168133548","rc":[{"batb":[[0,5.7,5.02],[1,5.6,1.47]],"ltp":5.6,"tv":300.84,"id":8231803}]}]}
{"op":"mcm","clk":"994347918","pt":1580551314551,"mc":[{"id":"1.168133548","rc":[{"batb":[[0,5.7,3.02],[1,5.6,3.47]],"ltp":5.6,"tv":300.84,"id":8231803}]}]}
{"op":"mcm","clk":"994348808","pt":1580551322536,"mc":[{"id":"1.168133548","rc":[{"batb":[[0,23,1.51],[2,20,1.66]],"ltp":25.0,"tv":53.61,"id":9193530}]}]}
{"op":"mcm","clk":"994350040","pt":1580551334499,"mc":[{"id":"1.168133548","rc":[{"batb":[[0,5.7,5.02],[1,5.6,1.47]],"ltp":5.6,"tv":300.84,"id":8231803}]}]}
{"op":"mcm","clk":"994350333","pt":1580551337495,"mc":[{"id":"1.168133548","rc":[{"batb":[[1,21,1.98]],"ltp":25.0,"tv":53.61,"id":9193530}]}]}
{"op":"mcm","clk":"994350529","pt":1580551339476,"mc":[{"id":"1.168133548","rc":[{"batl":[[0,40,3.74],[1,95,2],[2,190,2]],"ltp":25.0,"tv":53.61,"id":9193530}]}]}
{"op":"mcm","clk":"994350629","pt":1580551340570,"mc":[{"id":"1.168133548","rc":[{"batl":[[0,38,8.31],[1,40,3.03],[2,95,2]],"ltp":25.0,"tv":53.61,"id":9193530}]}]}
{"op":"mcm","clk":"994352096","pt":1580551354427,"mc":[{"id":"1.168133548","rc":[{"batl":[[0,8.8,10],[1,9.8,6.9],[2,10,5]],"ltp":8.2,"tv":429.0,"id":15608820}]}]}
{"op":"mcm","clk":"994352308","pt":1580551356289,"mc":[{"id":"1.168133548","rc":[{"batl":[[1,9.8,21.98]],"ltp":8.2,"tv":429.0,"id":15608820}]}]}
{"op":"mcm","clk":"994352477","pt":1580551357484,"mc":[{"id":"1.168133548","rc":[{"batb":[[2,7.8,7.33]],"batl":[[1,9.8,17.96]],"ltp":8.2,"tv":429.0,"id":15608820},{"batl":[[0,36,3.2],[1,38,8.14]],"ltp":25.0,"tv":53.61,"id":9193530}]}]}
{"op":"mcm","clk":"994353034","pt":1580551362509,"mc":[{"id":"1.168133548","rc":[{"trd":[[8.8,31.39]],"batl":[[0,8.8,5.53]],"ltp":8.8,"tv":437.93,"id":15608820}],"tv":4619.16}]}
{"op":"mcm","clk":"994353384","pt":1580551365527,"mc":[{"id":"1.168133548","rc":[{"batl":[[0,36,3.72],[1,38,7.67]],"ltp":25.0,"tv":53.61,"id":9193530}]}]}
{"op":"mcm","clk":"994354901","pt":1580551379489,"mc":[{"id":"1.168133548","rc":[{"batb":[[0,8.2,13.9],[1,7.8,7.33],[2,7.6,6.25]],"ltp":8.8,"tv":437.93,"id":15608820}]}]}
{"op":"mcm","clk":"994355619","pt":1580551384564,"mc":[{"id":"1.168133548","rc":[{"batb":[[0,5.7,3.02],[1,5.6,3.47]],"ltp":5.6,"tv":300.84,"id":8231803}]}]}
{"op":"mcm","clk":"994355739","pt":1580551385464,"mc":[{"id":"1.168133548","rc":[{"trd":[[5.8,320.87]],"batb":[[0,5.7,7.73],[1,5.5,17.85],[2,5.2,2]],"ltp":5.8,"tv":1276.17,"id":9417341},{"batb":[[1,7.8,15.17]],"ltp":8.8,"tv":437.93,"id":15608820}],"tv":4625.16}]}
{"op":"mcm","clk":"994356164","pt":1580551388377,"mc":[{"id":"1.168133548","rc":[{"batl":[[1,9.8,21.98]],"ltp":8.8,"tv":437.93,"id":15608820}]}]}
{"op":"mcm","clk":"994357136","pt":1580551394566,"mc":[{"id":"1.168133548","rc":[{"batb":[[0,5.7,5.02],[1,5.6,1.47]],"ltp":5.6,"tv":300.84,"id":8231803}]}]}
{"op":"mcm","clk":"994359697","pt":1580551413550,"mc":[{"id":"1.168133548","rc":[{"trd":[[12.5,36.99]],"batl":[[0,12.5,72.01]],"ltp":12.5,"tv":405.87,"id":8429550}],"tv":4633.27}]}
{"op":"mcm","clk":"994360667","pt":1580551420451,"mc":[{"id":"1.168133548","rc":[{"batl":[[0,85,9.82],[1,95,2],[2,190,2]],"ltp":20.0,"tv":80.54,"id":9001159}]}]}
{"op":"mcm","clk":"994361265","pt":1580551424568,"mc":[{"id":"1.168133548","rc":[{"trd":[[8.2,35.36]],"batb":[[0,8.2,9.76]],"batl":[[0,9.6,5.53]],"ltp":8.2,"tv":446.21,"id":15608820}],"tv":4641.55}]}
{"op":"mcm","clk":"994361387","pt":1580551425362,"mc":[{"id":"1.168133548","rc":[{"batl":[[0,9.6,11.76]],"ltp":8.2,"tv":446.21,"id":15608820}]}]}
{"op":"mcm","clk":"994361568","pt":1580551426475,"mc":[{"id":"1.168133548","rc":[{"batb":[[1,7.8,7.84]],"batl":[[1,9.8,4.01]],"ltp":8.2,"tv":446.21,"id":15608820}]}]}
{"op":"mcm","clk":"994362929","pt":1580551435509,"mc":[{"id":"1.168133548","rc":[{"batl":[[0,80,8.42],[1,85,9],[2,95,2]],"ltp":20.0,"tv":80.54,"id":9001159}]}]}
{"op":"mcm","clk":"994365371","pt":1580551453559,"mc":[{"id":"1.168133548","rc":[{"trd":[[6.2,97.8]],"batb":[[0,6,9.83],[1,5.8,4.26],[2,5.6,7.14]],"batl":[[0,6.2,8.25],[1,6.4,7.31],[2,6.6,17.37]],"ltp":6.2,"tv":431.5,"id":17352128}],"tv":4657.55}]}
{"op":"mcm","clk":"994365492","pt":1580551454469,"mc":[{"id":"1.168133548","rc":[{"batb":[[0,5.7,3.02]],"ltp":5.6,"tv":300.84,"id":8231803},{"batb":[[1,5.9,5.12],[2,5.8,4.26]],"ltp":6.2,"tv":431.5,"id":17352128}]}]}
{"op":"mcm","clk":"994365618","pt":1580551455441,"mc":[{"id":"1.168133548","rc":[{"batb":[[1,5.6,3.47]],"ltp":5.6,"tv":300.84,"id":8231803},{"batb":[[1,5.8,4.26],[2,5.6,7.14]],"ltp":6.2,"tv":431.5,"id":17352128}]}]}
{"op":"mcm","clk":"994366407","pt":1580551461561,"mc":[{"id":"1.168133548","rc":[{"trd":[[6,83.69]],"batb":[[0,6,7.82]],"ltp":6.0,"tv":435.5,"id":17352128}],"tv":4661.55}]}
{"op":"mcm","clk":"994367326","pt":1580551467471,"mc":[{"id":"1.168133548","rc":[{"batl":[[1,10,5],[2,12,10.58]],"ltp":8.2,"tv":446.21,"id":15608820}]}]}
{"op":"mcm","clk":"994367560","pt":1580551468486,"mc":[{"id":"1.168133548","rc":[{"batl":[[0,9.4,3.95],[1,9.6,11.76],[2,10,5]],"ltp":8.2,"tv":446.21,"id":15608820}]}]}
{"op":"mcm","clk":"994368453","pt":1580551473478,"mc":[{"id":"1.168133548","rc":[{"batb":[[0,9.6,23.05]],"ltp":10.5,"tv":780.11,"id":10616006}]}]}
{"op":"mcm","clk":"994370195","pt":1580551484208,"mc":[{"id":"1.168133548","rc":[{"batb":[[0,8.4,2.38],[1,8.2,9.76],[2,7.8,7.84]],"ltp":8.2,"tv":446.21,"id":15608820}]}]}
{"op":"mcm","clk":"994370550","pt":1580551486524,"mc":[{"id":"1.168133548","rc":[{"batb":[[1,9.2,15.43]],"ltp":10.5,"tv":780.11,"id":10616006},{"batb":[[2,7.6,6.25]],"ltp":8.2,"tv":446.21,"id":15608820}]}]}
{"op":"mcm","clk":"994374193","pt":1580551510471,"mc":[{"id":"1.168133548","rc":[{"trd":[[7.8,52.8]],"batb":[[0,7.6,5.5],[1,7.4,3.1],[2,7.2,2]],"batl":[[0,7.8,10.94],[1,8,23.38],[2,8.2,34.54]],"ltp":7.8,"tv":891.77,"id":10170404}],"tv":4670.67}]}
{"op":"mcm","clk":"994375856","pt":1580551520429,"mc":[{"id":"1.168133548","rc":[{"trd":[[5.7,23.1]],"batb":[[0,5.6,3.47],[1,5.5,4],[2,5,58.07]],"ltp":5.7,"tv":306.89,"id":8231803}],"tv":4676.73}]}
{"op":"mcm","clk":"994376012","pt":1580551521546,"mc":[{"id":"1.168133548","rc":[{"batb":[[0,5.8,2.97],[1,5.7,7.73],[2,5.5,17.85]],"ltp":5.8,"tv":1276.17,"id":9417341}]}]}
{"op":"mcm","clk":"994376305","pt":1580551523546,"mc":[{"id":"1.168133548","rc":[{"batl":[[0,9.2,5.53],[1,9.4,3.95],[2,9.6,6.23]],"ltp":8.2,"tv":446.21,"id":15608820}]}]}
{"op":"mcm","clk":"994376961","pt":1580551527544,"mc":[{"id":"1.168133548","rc":[{"batb":[[2,5,8.07]],"ltp":5.7,"tv":306.89,"id":8231803},{"batb":[[1,21,7.15]],"ltp":25.0,"tv":53.61,"id":9193530},{"batb":[[0,21,3.03]],"ltp":20.0,"tv":80.54,"id":9001159}]}]}
{"op":"mcm","clk":"994377111","pt":1580551528554,"mc":[{"id":"1.168133548","rc":[{"batb":[[1,21,7.94]],"ltp":25.0,"tv":53.61,"id":9193530}]}]}
{"op":"mcm","clk":"994377779","pt":1580551533338,"mc":[{"id":"1.168133548","rc":[{"trd":[[7.6,48.1]],"batb":[[0,7.6,3.5]],"ltp":7.6,"tv":895.77,"id":10170404}],"tv":4680.73}]}
{"op":"mcm","clk":"994379125","pt":1580551541548,"mc":[{"id":"1.168133548","rc":[{"batb":[[1,21,8.78]],"ltp":25.0,"tv":53.61,"id":9193530}]}]}
{"op":"mcm","clk":"994379802","pt":1580551546541,"mc":[{"id":"1.168133548","rc":[{"batb":[[1,21,3.6]],"ltp":25.0,"tv":53.61,"id":9193530}]}]}
{"op":"mcm","clk":"994380247","pt":1580551549548,"mc":[{"id":"1.168133548","rc":[{"batb":[[1,21,2.76]],"ltp":25.0,"tv":53.61,"id":9193530}]}]}
{"op":"mcm","clk":"994382652","pt":1580551565569,"mc":[{"id":"1.168133548","rc":[{"batb":[[1,21,7.94]],"ltp":25.0,"tv":53.61,"id":9193530}]}]}
{"op":"mcm","clk":"994382830","pt":1580551566574,"mc":[{"id":"1.168133548","rc":[{"batl":[[1,95,2.08],[2,190,2]],"ltp":25.0,"tv":53.61,"id":9193530},{"batb":[[1,5.9,9.36],[2,5.8,13.25]],"ltp":6.0,"tv":435.5,"id":17352128}]}]}
{"op":"mcm","clk":"994383000","pt":1580551567529,"mc":[{"id":"1.168133548","rc":[{"batb":[[1,5.9,18.72]],"ltp":6.0,"tv":435.5,"id":17352128}]}]}
{"op":"mcm","clk":"994383776","pt":1580551572552,"mc":[{"id":"1.168133548","rc":[{"batb":[[1,22,2.78],[2,21,7.15]],"ltp":25.0,"tv":53.61,"id":9193530}]}]}
{"op":"mcm","clk":"994385106","pt":1580551581285,"mc":[{"id":"1.168133548","rc":[{"batb":[[1,22,3.58]],"ltp":25.0,"tv":53.61,"id":9193530}]}]}
{"op":"mcm","clk":"994385314","pt":1580551582490,"mc":[{"id":"1.168133548","rc":[{"batl":[[0,9,1.76],[1,9.2,5.53],[2,9.4,3.95]],"ltp":8.2,"tv":446.21,"id":15608820}]}]}
{"op":"mcm","clk":"994385650","pt":1580551584508,"mc":[{"id":"1.168133548","rc":[{"batb":[[0,23,6.23],[2,21,1.98]],"ltp":25.0,"tv":53.61,"id":9193530}]}]}
{"op":"mcm","clk":"994386506","pt":1580551588516,"mc":[{"id":"1.168133548","rc":[{"batl":[[2,220,9]],"ltp":25.0,"tv":53.61,"id":9193530}]}]}
{"op":"mcm","clk":"994387330","pt":1580551592505,"mc":[{"id":"1.168133548","rc":[{"trd":[[9.6,23.77]],"batb":[[0,9.6,18.05]],"ltp":9.6,"tv":790.11,"id":10616006},{"batb":[[0,21,11.03],[2,19,2.4]],"ltp":20.0,"tv":80.54,"id":9001159}],"tv":4690.72}]}
{"op":"mcm","clk":"994387874","pt":1580551595527,"mc":[{"id":"1.168133548","rc":[{"batl":[[2,8.2,37.39]],"ltp":7.6,"tv":895.77,"id":10170404}]}]}
{"op":"mcm","clk":"994389074","pt":1580551602546,"mc":[{"id":"1.168133548","rc":[{"trd":[[6,97.7]],"batb":[[0,5.9,19.54],[1,5.8,13.25],[2,5.6,7.14]],"batl":[[0,6.2,13.5]],"ltp":6.0,"tv":449.51,"id":17352128}],"tv":4704.73}]}
{"op":"mcm","clk":"994389232","pt":1580551603509,"mc":[{"id":"1.168133548","rc":[{"batb":[[0,21,9.66]],"ltp":20.0,"tv":80.54,"id":9001159}]}]}
{"op":"mcm","clk":"994389439","pt":1580551604519,"mc":[{"id":"1.168133548","rc":[{"batb":[[0,22,1.31],[1,21,9.66],[2,20,10.79]],"ltp":20.0,"tv":80.54,"id":9001159}]}]}
{"op":"mcm","clk":"994390234","pt":1580551609536,"mc":[{"id":"1.168133548","rc":[{"trd":[[5.8,10.92],[5.9,37.44],[6,99.34]],"batb":[[0,5.8,7.79],[1,5.6,7.14],[2,5.5,7]],"ltp":5.8,"tv":499.51,"id":17352128}],"tv":4754.73}]}
{"op":"mcm","clk":"994390371","pt":1580551610540,"mc":[{"id":"1.168133548","rc":[{"batb":[[0,5.6,23.05],[1,5.5,16.54],[2,5.4,5.93]],"batl":[[0,6.2,14.29]],"ltp":5.8,"tv":499.51,"id":17352128}]}]}
{"op":"mcm","clk":"994391622","pt":1580551618538,"mc":[{"id":"1.168133548","rc":[{"batb":[[1,5.5,13.54]],"ltp":5.8,"tv":499.51,"id":17352128}]}]}
{"op":"mcm","clk":"994392205","pt":1580551622556,"mc":[{"id":"1.168133548","rc":[{"batl":[[2,9.6,6.23]],"ltp":8.2,"tv":446.21,"id":15608820}]}]}
{"op":"mcm","clk":"994392345","pt":1580551623560,"mc":[{"id":"1.168133548","rc":[{"batl":[[0,9,4.57],[2,10,5]],"ltp":8.2,"tv":446.21,"id":15608820},{"batb":[[0,24,2.07],[1,23,5.55],[2,22,3.58]],"ltp":25.0,"tv":53.61,"id":9193530}]}]}
{"op":"mcm","clk":"994393834","pt":1580551633027,"mc":[{"id":"1.168133548","rc":[{"batl":[[0,8.8,5.53],[1,9,4.57]],"ltp":8.2,"tv":446.21,"id":15608820}]}]}
{"op":"mcm","clk":"994394972","pt":1580551639515,"mc":[{"id":"1.168133548","rc":[{"batl":[[2,10.5,17.47]],"ltp":9.6,"tv":790.11,"id":10616006}]}]}
{"op":"mcm","clk":"994395012","pt":1580551639728,"mc":[{"id":"1.168133548","rc":[{"batl":[[2,10.5,3.3]],"ltp":9.6,"tv":790.11,"id":10616006}]}]}
{"op":"mcm","clk":"994396198","pt":1580551646541,"mc":[{"id":"1.168133548","rc":[{"batb":[[0,8.2,9.76],[1,7.6,6.25],[2,7.2,9.56]],"ltp":8.2,"tv":446.21,"id":15608820}]}]}
{"op":"mcm","clk":"994396354","pt":1580551647507,"mc":[{"id":"1.168133548","rc":[{"batb":[[1,7.8,3.7],[2,7.6,8.64]],"ltp":8.2,"tv":446.21,"id":15608820}]}]}
{"op":"mcm","clk":"994407832","pt":1580551654427,"mc":[{"id":"1.168133548","rc":[{"batl":[[1,9,2.81]],"ltp":8.2,"tv":446.21,"id":15608820}]}]}
{"op":"mcm","clk":"994408927","pt":1580551661524,"mc":[{"id":"1.168133548","rc":[{"batl":[[0,85,9.82],[1,95,2],[2,190,2]],"ltp":20.0,"tv":80.54,"id":9001159}]}]}
{"op":"mcm","clk":"994409207","pt":1580551663497,"mc":[{"id":"1.168133548","rc":[{"batb":[[0,24,4.07],[2,22,1.58]],"ltp":25.0,"tv":53.61,"id":9193530}]}]}
{"op":"mcm","clk":"994410323","pt":1580551670494,"mc":[{"id":"1.168133548","rc":[{"batb":[[0,25,1.45],[1,24,3.39],[2,23,4.72]],"ltp":25.0,"tv":53.61,"id":9193530}]}]}
{"op":"mcm","clk":"994410485","pt":1580551671562,"mc":[{"id":"1.168133548","rc":[{"trd":[[5.6,16]],"batb":[[0,5.6,15.06]],"ltp":5.6,"tv":515.5,"id":17352128}],"tv":4770.72}]}
{"op":"mcm","clk":"994410637","pt":1580551672570,"mc":[{"id":"1.168133548","rc":[{"trd":[[12,91.96]],"batb":[[0,12,11.2]],"ltp":12.0,"tv":409.87,"id":8429550}],"tv":4774.72}]}
{"op":"mcm","clk":"994411266","pt":1580551676388,"mc":[{"id":"1.168133548","rc":[{"batb":[[1,7.8,9.23]],"ltp":8.2,"tv":446.21,"id":15608820}]}]}
{"op":"mcm","clk":"994411440","pt":1580551677499,"mc":[{"id":"1.168133548","rc":[{"batl":[[0,80,8.42],[1,85,9],[2,95,2]],"ltp":20.0,"tv":80.54,"id":9001159}]}]}
{"op":"mcm","clk":"994412093","pt":1580551681487,"mc":[{"id":"1.168133548","rc":[{"batb":[[0,25,5.79],[2,22,1.58]],"ltp":25.0,"tv":53.61,"id":9193530}]}]}
{"op":"mcm","clk":"994412711","pt":1580551685513,"mc":[{"id":"1.168133548","rc":[{"batb":[[0,5.7,3.54],[1,5.6,3.47],[2,5.5,4]],"ltp":5.7,"tv":306.89,"id":8231803}]}]}
{"op":"mcm","clk":"994412851","pt":1580551686415,"mc":[{"id":"1.168133548","rc":[{"batb":[[0,5.5,7.39],[1,5.4,5.93],[2,5,8.07]],"ltp":5.6,"tv":515.5,"id":17352128}]}]}
{"op":"mcm","clk":"994413126","pt":1580551688408,"mc":[{"id":"1.168133548","rc":[{"batb":[[0,5.6,3.13],[1,5.5,7.39],[2,5.4,5.93]],"ltp":5.6,"tv":515.5,"id":17352128}]}]}
{"op":"mcm","clk":"994414771","pt":1580551699544,"mc":[{"id":"1.168133548","rc":[{"trd":[[5.9,220.93]],"batl":[[0,5.9,13.96]],"ltp":5.9,"tv":1282.17,"id":9417341}],"tv":4780.72}]}
{"op":"mcm","clk":"994415254","pt":1580551702565,"mc":[{"id":"1.168133548","rc":[{"batb":[[0,5.7,5.54],[1,5.6,1.47]],"ltp":5.7,"tv":306.89,"id":8231803}]}]}
{"op":"mcm","clk":"994415360","pt":1580551703181,"mc":[{"id":"1.168133548","rc":[{"batb":[[2,5.5,20.85]],"ltp":5.9,"tv":1282.17,"id":9417341}]}]}
{"op":"mcm","clk":"994415582","pt":1580551704454,"mc":[{"id":"1.168133548","rc":[{"trd":[[12,95.96]],"batb":[[0,12,9.2]],"ltp":12.0,"tv":413.87,"id":8429550}],"tv":4784.72}]}
{"op":"mcm","clk":"994416827","pt":1580551712377,"mc":[{"id":"1.168133548","rc":[{"batb":[[0,5.7,3.54],[1,5.6,3.47]],"ltp":5.7,"tv":306.89,"id":8231803}]}]}
{"op":"mcm","clk":"994417020","pt":1580551713568,"mc":[{"id":"1.168133548","rc":[{"batb":[[1,11.5,3.48],[2,11,2.46]],"ltp":12.0,"tv":413.87,"id":8429550},{"batb":[[0,5.8,9.87],[1,5.5,21.56],[2,5.2,2]],"ltp":5.9,"tv":1282.17,"id":9417341},{"batb":[[1,21,11.56],[2,20,8.79]],"ltp":20.0,"tv":80.54,"id":9001159}]}]}
{"op":"mcm","clk":"994418379","pt":1580551719498,"mc":[{"id":"1.168133548","rc":[{"batb":[[1,5.5,28.15]],"ltp":5.9,"tv":1282.17,"id":9417341}]}]}
{"op":"mcm","clk":"994420656","pt":1580551732118,"mc":[{"id":"1.168133548","rc":[{"batb":[[0,5.7,5.54],[1,5.6,1.47]],"ltp":5.7,"tv":306.89,"id":8231803}]}]}
{"op":"mcm","clk":"994421987","pt":1580551739466,"mc":[{"id":"1.168133548","rc":[{"batl":[[0,12.5,54.17],[1,13,17.17],[2,13.5,26.9]],"ltp":12.0,"tv":413.87,"id":8429550},{"batb":[[0,5.5,4],[1,5.4,5.93],[2,5,8.07]],"batl":[[0,6,9.19],[1,6.2,23.48],[2,6.4,16.5]],"ltp":5.6,"tv":515.5,"id":17352128}]}]}
{"op":"mcm","clk":"994422170","pt":1580551740388,"mc":[{"id":"1.168133548","rc":[{"batl":[[1,13.5,20.72],[2,17,6.2]],"ltp":12.0,"tv":413.87,"id":8429550},{"batl":[[0,6,18.55]],"ltp":5.6,"tv":515.5,"id":17352128}]}]}
{"op":"mcm","clk":"994422360","pt":1580551741493,"mc":[{"id":"1.168133548","rc":[{"batl":[[0,12.5,72.01]],"ltp":12.0,"tv":413.87,"id":8429550}]}]}
{"op":"mcm","clk":"994422534","pt":1580551742566,"mc":[{"id":"1.168133548","rc":[{"batl":[[0,10,2],[1,10.5,3.3],[2,11,12.27]],"ltp":9.6,"tv":790.11,"id":10616006},{"batl":[[1,6.2,32.84]],"ltp":5.6,"tv":515.5,"id":17352128}]}]}
{"op":"mcm","clk":"994422854","pt":1580551744490,"mc":[{"id":"1.168133548","rc":[{"batl":[[0,12.5,54.17],[1,13,17.16],[2,13.5,20.72]],"ltp":12.0,"tv":413.87,"id":8429550}]}]}
{"op":"mcm","clk":"994423018","pt":1580551745520,"mc":[{"id":"1.168133548","rc":[{"batl":[[0,12.5,72.01],[1,13.5,20.72],[2,17,6.2]],"ltp":12.0,"tv":413.87,"id":8429550}]}]}
{"op":"mcm","clk":"994423188","pt":1580551746574,"mc":[{"id":"1.168133548","rc":[{"batl":[[0,12.5,54.17],[1,13,17.16],[2,13.5,20.72]],"ltp":12.0,"tv":413.87,"id":8429550},{"trd":[[7.6,55.1]],"batb":[[0,7.4,3.1],[1,7.2,2],[2,7,40]],"batl":[[0,7.6,16.5],[1,7.8,10.94],[2,8,23.38]],"ltp":7.6,"tv":902.77,"id":10170404}],"tv":4791.72}]}
{"op":"mcm","clk":"994423315","pt":1580551747272,"mc":[{"id":"1.168133548","rc":[{"batl":[[0,12.5,72.01],[1,13.5,20.72],[2,17,6.2]],"ltp":12.0,"tv":413.87,"id":8429550},{"batb":[[2,7,44.98]],"ltp":7.6,"tv":902.77,"id":10170404}]}]}
{"op":"mcm","clk":"994423487","pt":1580551748375,"mc":[{"id":"1.168133548","rc":[{"batb":[[2,7,40]],"ltp":7.6,"tv":902.77,"id":10170404},{"trd":[[6,105.34]],"batl":[[0,6,15.55]],"ltp":6.0,"tv":521.5,"id":17352128}],"tv":4797.72}]}
{"op":"mcm","clk":"994423820","pt":1580551750565,"mc":[{"id":"1.168133548","rc":[{"batl":[[0,12.5,54.17],[1,13,17.16],[2,13.5,20.72]],"ltp":12.0,"tv":413.87,"id":8429550},{"batb":[[0,5.6,2.84],[1,5.5,4],[2,5.4,5.93]],"ltp":6.0,"tv":521.5,"id":17352128}]}]}
{"op":"mcm","clk":"994423971","pt":1580551751487,"mc":[{"id":"1.168133548","rc":[{"batl":[[0,12.5,72.01],[1,13.5,20.72],[2,17,6.2]],"ltp":12.0,"tv":413.87,"id":8429550}]}]}
{"op":"mcm","clk":"994424320","pt":1580551753501,"mc":[{"id":"1.168133548","rc":[{"batl":[[0,12.5,54.17],[1,13,17.16],[2,13.5,20.72]],"ltp":12.0,"tv":413.87,"id":8429550}]}]}
{"op":"mcm","clk":"994424503","pt":1580551754508,"mc":[{"id":"1.168133548","rc":[{"batl":[[0,12.5,72.01],[1,13.5,20.72],[2,17,6.2]],"ltp":12.0,"tv":413.87,"id":8429550}]}]}
{"op":"mcm","clk":"994424684","pt":1580551755518,"mc":[{"id":"1.168133548","rc":[{"trd":[[12,114.36]],"batb":[[0,11.5,3.48],[1,11,2.46],[2,10.5,3.03]],"batl":[[0,12,10.8],[1,12.5,72.01],[2,13.5,20.72]],"ltp":12.0,"tv":432.27,"id":8429550},{"batb":[[1,5.5,7]],"ltp":6.0,"tv":521.5,"id":17352128}],"tv":4816.12}]}
{"op":"mcm","clk":"994424832","pt":1580551756313,"mc":[{"id":"1.168133548","rc":[{"batl":[[0,12,29.38],[1,12.5,54.17]],"ltp":12.0,"tv":432.27,"id":8429550}]}]}
{"op":"mcm","clk":"994425826","pt":1580551762232,"mc":[{"id":"1.168133548","rc":[{"batb":[[0,5.7,3.54],[1,5.6,3.47]],"ltp":5.7,"tv":306.89,"id":8231803}]}]}
{"op":"mcm","clk":"994426345","pt":1580551765525,"mc":[{"id":"1.168133548","rc":[{"batl":[[0,10,6.39],[2,11,10.3]],"ltp":9.6,"tv":790.11,"id":10616006}]}]}
{"op":"mcm","clk":"994426491","pt":1580551766549,"mc":[{"id":"1.168133548","rc":[{"trd":[[11.5,48.43]],"batb":[[0,11,2.46],[1,10.5,3.03],[2,10,4.23]],"batl":[[0,11.5,6.52],[1,12,10.8],[2,12.5,54.17]],"ltp":11.5,"tv":439.23,"id":8429550}],"tv":4823.08}]}
{"op":"mcm","clk":"994426623","pt":1580551767548,"mc":[{"id":"1.168133548","rc":[{"batb":[[1,10.5,17.2]],"batl":[[0,11.5,25.87]],"ltp":11.5,"tv":439.23,"id":8429550},{"batb":[[0,5.8,17.36]],"ltp":5.9,"tv":1282.17,"id":9417341},{"batb":[[1,5.6,11.23]],"ltp":5.7,"tv":306.89,"id":8231803},{"batb":[[0,9.8,4.43],[1,9.6,18.05],[2,9.2,15.43]],"ltp":9.6,"tv":790.11,"id":10616006},{"batb":[[1,7.2,8.04]],"ltp":7.6,"tv":902.77,"id":10170404},{"batb":[[0,8.4,5.17],[1,8.2,9.76],[2,7.8,9.23]],"ltp":8.2,"tv":446.21,"id":15608820},{"batb":[[0,26,1.67],[1,25,5.79],[2,24,3.39]],"ltp":25.0,"tv":53.61,"id":9193530},{"batb":[[0,5.7,7.62],[1,5.6,2.84],[2,5.5,7]],"ltp":6.0,"tv":521.5,"id":17352128}]}]}
{"op":"mcm","clk":"994426798","pt":1580551768459,"mc":[{"id":"1.168133548","rc":[{"batb":[[0,26,1.67],[1,22,1.31],[2,21,11.56]],"ltp":20.0,"tv":80.54,"id":9001159}]}]}
{"op":"mcm","clk":"994426968","pt":1580551769529,"mc":[{"id":"1.168133548","rc":[{"batl":[[0,11.5,6.52],[1,12,29.36]],"ltp":11.5,"tv":439.23,"id":8429550},{"batb":[[1,5.5,31.76]],"ltp":5.9,"tv":1282.17,"id":9417341},{"batb":[[2,9.2,9.02]],"ltp":9.6,"tv":790.11,"id":10616006}]}]}
{"op":"mcm","clk":"994427099","pt":1580551770435,"mc":[{"id":"1.168133548","rc":[{"batl":[[0,11.5,25.86],[1,12,10.8]],"ltp":11.5,"tv":439.23,"id":8429550}]}]}
{"op":"mcm","clk":"994427419","pt":1580551772554,"mc":[{"id":"1.168133548","rc":[{"batl":[[0,11.5,6.52]],"ltp":11.5,"tv":439.23,"id":8429550}]}]}
{"op":"mcm","clk":"994427588","pt":1580551773448,"mc":[{"id":"1.168133548","rc":[{"batl":[[0,11.5,25.86]],"ltp":11.5,"tv":439.23,"id":8429550}]}]}
{"op":"mcm","clk":"994427775","pt":1580551774448,"mc":[{"id":"1.168133548","rc":[{"trd":[[11.5,48.87]],"batl":[[0,11.5,25.42]],"ltp":11.5,"tv":439.67,"id":8429550},{"trd":[[5.9,221.79]],"batl":[[0,5.9,13.1]],"ltp":5.9,"tv":1283.03,"id":9417341},{"trd":[[5.8,19.04]],"batl":[[0,5.8,87.72]],"ltp":5.8,"tv":307.77,"id":8231803},{"trd":[[10,246.54]],"batl":[[0,10,5.88]],"ltp":10.0,"tv":790.62,"id":10616006},{"trd":[[7.4,44.13]],"batb":[[0,7.2,8.04],[1,7,40],[2,6.8,7.61]],"batl":[[0,7.4,6.21],[1,7.6,16.5],[2,7.8,10.94]],"ltp":7.4,"tv":909.66,"id":10170404},{"trd":[[8.8,31.97]],"batl":[[0,8.8,4.95]],"ltp":8.8,"tv":446.79,"id":15608820},{"trd":[[30,0.17]],"batl":[[0,36,3.55]],"ltp":30.0,"tv":53.78,"id":9193530},{"trd":[[42,0.12]],"batl":[[0,80,8.3]],"ltp":42.0,"tv":80.66,"id":9001159},{"trd":[[6,106.18]],"batl":[[0,6,14.7]],"ltp":6.0,"tv":522.35,"id":17352128}],"tv":4834.38}]}
{"op":"mcm","clk":"994428095","pt":1580551776470,"mc":[{"id":"1.168133548","rc":[{"batb":[[0,11,3.91]],"ltp":11.5,"tv":439.67,"id":8429550}]}]}
{"op":"mcm","clk":"994428276","pt":1580551777538,"mc":[{"id":"1.168133548","rc":[{"batl":[[0,11.5,6.08],[1,12,29.36]],"ltp":11.5,"tv":439.67,"id":8429550},{"batb":[[0,9.8,10.9]],"ltp":10.0,"tv":790.62,"id":10616006},{"batb":[[0,26,2.78],[1,21,11.56],[2,20,8.79]],"ltp":42.0,"tv":80.66,"id":9001159}]}]}
{"op":"mcm","clk":"994428423","pt":1580551778542,"mc":[{"id":"1.168133548","rc":[{"batl":[[0,11.5,25.42],[1,12,10.8]],"ltp":11.5,"tv":439.67,"id":8429550}]}]}
{"op":"mcm","clk":"994428573","pt":1580551779548,"mc":[{"id":"1.168133548","rc":[{"batb":[[1,25,6.5]],"ltp":30.0,"tv":53.78,"id":9193530}]}]}
{"op":"mcm","clk":"994429327","pt":1580551784450,"mc":[{"id":"1.168133548","rc":[{"batl":[[0,11.5,6.08],[1,12,29.36]],"ltp":11.5,"tv":439.67,"id":8429550},{"batb":[[1,5.5,7],[2,5.4,5.93]],"ltp":6.0,"tv":522.35,"id":17352128}]}]}
{"op":"mcm","clk":"994429399","pt":1580551784971,"mc":[{"id":"1.168133548","rc":[{"batl":[[0,11.5,25.42],[1,12,10.8]],"ltp":11.5,"tv":439.67,"id":8429550}]}]}
{"op":"mcm","clk":"994429780","pt":1580551787492,"mc":[{"id":"1.168133548","rc":[{"trd":[[11.5,49.42]],"batl":[[0,11.5,24.87]],"ltp":11.5,"tv":440.22,"id":8429550},{"trd":[[5.9,222.85]],"batl":[[0,5.9,12.04]],"ltp":5.9,"tv":1284.09,"id":9417341},{"trd":[[5.8,25]],"batl":[[0,5.8,84.2]],"ltp":5.8,"tv":313.73,"id":8231803},{"trd":[[10,247.16]],"batl":[[0,10,5.26]],"ltp":10.0,"tv":791.24,"id":10616006},{"trd":[[7.2,37.03]],"batb":[[0,7,40.58],[1,6.8,5.88],[2,6.6,1.98]],"ltp":7.2,"tv":928.8,"id":10170404},{"trd":[[8.8,32.68]],"batl":[[0,8.8,4.24]],"ltp":8.8,"tv":447.5,"id":15608820},{"trd":[[34,0.18]],"batl":[[0,36,3.37]],"ltp":34.0,"tv":53.97,"id":9193530},{"trd":[[42,0.19],[44,0.08]],"batl":[[0,80,8.15]],"ltp":44.0,"tv":80.81,"id":9001159},{"trd":[[6,107.23]],"batl":[[0,6,13.66]],"ltp":6.0,"tv":523.39,"id":17352128}],"tv":4863.78}]}
{"op":"mcm","clk":"994429944","pt":1580551788467,"mc":[{"id":"1.168133548","rc":[{"batb":[[0,7,40],[1,6.8,23.05]],"ltp":7.2,"tv":928.8,"id":10170404}]}]}
{"op":"mcm","clk":"994430114","pt":1580551789470,"mc":[{"id":"1.168133548","rc":[{"batl":[[0,11.5,5.53]],"ltp":11.5,"tv":440.22,"id":8429550},{"batb":[[0,27,3.04],[1,26,1.67],[2,25,6.5]],"ltp":34.0,"tv":53.97,"id":9193530},{"batb":[[0,36,2.28],[1,26,2.78],[2,21,11.56]],"batl":[[0,80,8.35]],"ltp":44.0,"tv":80.81,"id":9001159}]}]}
{"op":"mcm","clk":"994430294","pt":1580551790489,"mc":[{"id":"1.168133548","rc":[{"batl":[[1,12,29.36]],"ltp":11.5,"tv":440.22,"id":8429550}]}]}
{"op":"mcm","clk":"994430432","pt":1580551791394,"mc":[{"id":"1.168133548","rc":[{"batl":[[0,11.5,24.87],[1,12,10.8]],"ltp":11.5,"tv":440.22,"id":8429550},{"batb":[[1,27,3.39],[2,26,2.78]],"ltp":44.0,"tv":80.81,"id":9001159}]}]}
{"op":"mcm","clk":"994430758","pt":1580551793381,"mc":[{"id":"1.168133548","rc":[{"batl":[[0,11.5,5.53],[1,12,29.36]],"ltp":11.5,"tv":440.22,"id":8429550}]}]}
{"op":"mcm","clk":"994430918","pt":1580551794494,"mc":[{"id":"1.168133548","rc":[{"batl":[[0,11.5,24.87],[1,12,10.8]],"ltp":11.5,"tv":440.22,"id":8429550},{"batb":[[0,5.8,19.35]],"batl":[[0,6,76],[1,6.2,42.16],[2,6.4,25]],"ltp":5.9,"tv":1284.09,"id":9417341}]}]}
{"op":"mcm","clk":"994431245","pt":1580551796516,"mc":[{"id":"1.168133548","rc":[{"batl":[[1,6.2,55.74]],"ltp":5.9,"tv":1284.09,"id":9417341},{"batb":[[0,9.8,4.43]],"ltp":10.0,"tv":791.24,"id":10616006},{"batb":[[2,25,2.16]],"ltp":34.0,"tv":53.97,"id":9193530},{"batb":[[2,26,1.67]],"ltp":44.0,"tv":80.81,"id":9001159}]}]}
{"op":"mcm","clk":"994431387","pt":1580551797419,"mc":[{"id":"1.168133548","rc":[{"trd":[[11,23.68]],"batb":[[0,10.5,17.2],[1,10,4.23],[2,9.8,1.29]],"batl":[[0,11,6.09],[1,11.5,5.53],[2,12,29.36]],"ltp":11.0,"tv":448.03,"id":8429550},{"batb":[[1,26,2.52],[2,21,11.56]],"ltp":44.0,"tv":80.81,"id":9001159}],"tv":4871.6}]}
{"op":"mcm","clk":"994431589","pt":1580551798488,"mc":[{"id":"1.168133548","rc":[{"trd":[[11,30.14]],"batb":[[2,9.8,2.41]],"batl":[[0,11,2.86],[1,11.5,24.87],[2,12,10.8]],"ltp":11.0,"tv":454.49,"id":8429550}],"tv":4878.06}]}
{"op":"mcm","clk":"994431806","pt":1580551799558,"mc":[{"id":"1.168133548","rc":[{"trd":[[11,35.85]],"batb":[[1,10,11.04]],"batl":[[0,11.5,24.87],[1,12,10.8],[2,12.5,54.17]],"ltp":11.0,"tv":460.21,"id":8429550},{"batb":[[1,27,4.23],[2,26,1.67]],"ltp":44.0,"tv":80.81,"id":9001159}],"tv":4883.77}]}
{"op":"mcm","clk":"994431961","pt":1580551800473,"mc":[{"id":"1.168133548","rc":[{"batb":[[2,9.8,1.29]],"ltp":11.0,"tv":460.21,"id":8429550},{"batb":[[1,26,2.52],[2,21,11.56]],"ltp":44.0,"tv":80.81,"id":9001159}]}]}
{"op":"mcm","clk":"994432116","pt":1580551801483,"mc":[{"id":"1.168133548","rc":[{"batb":[[2,25,1.39]],"ltp":34.0,"tv":53.97,"id":9193530}]}]}
{"op":"mcm","clk":"994432275","pt":1580551802497,"mc":[{"id":"1.168133548","rc":[{"batl":[[0,11.5,5.53],[1,12,29.36]],"ltp":11.0,"tv":460.21,"id":8429550},{"batb":[[0,27,3.95],[2,24,2.68]],"ltp":34.0,"tv":53.97,"id":9193530}]}]}
{"op":"mcm","clk":"994432423","pt":1580551803453,"mc":[{"id":"1.168133548","rc":[{"batl":[[0,11.5,24.88],[1,12,10.8]],"ltp":11.0,"tv":460.21,"id":8429550},{"batb":[[1,26,2.95],[2,24,6.54]],"ltp":34.0,"tv":53.97,"id":9193530}]}]}
{"op":"mcm","clk":"994432621","pt":1580551804565,"mc":[{"id":"1.168133548","rc":[{"trd":[[9.8,34.27]],"batb":[[0,9.6,18.75],[1,9.2,9.02],[2,9,5]],"ltp":9.8,"tv":798.7,"id":10616006}],"tv":4891.24}]}
{"op":"mcm","clk":"994432759","pt":1580551805490,"mc":[{"id":"1.168133548","rc":[{"batb":[[2,9.8,2.41]],"batl":[[0,11,2],[1,11.5,24.88],[2,12,10.8]],"ltp":11.0,"tv":460.21,"id":8429550},{"batb":[[1,9.4,2.23],[2,9.2,4.4]],"ltp":9.8,"tv":798.7,"id":10616006}]}]}
{"op":"mcm","clk":"994432964","pt":1580551806568,"mc":[{"id":"1.168133548","rc":[{"batl":[[0,11,22.23],[1,11.5,5.53]],"ltp":11.0,"tv":460.21,"id":8429550},{"batb":[[1,9.2,4.4],[2,9,5]],"ltp":9.8,"tv":798.7,"id":10616006},{"batb":[[1,27,4.23],[2,26,1.67]],"ltp":44.0,"tv":80.81,"id":9001159}]}]}
{"op":"mcm","clk":"994433120","pt":1580551807372,"mc":[{"id":"1.168133548","rc":[{"batl":[[0,11,2],[1,11.5,24.88]],"ltp":11.0,"tv":460.21,"id":8429550}]}]}
{"op":"mcm","clk":"994433299","pt":1580551808480,"mc":[{"id":"1.168133548","rc":[{"batl":[[1,11.5,5.53]],"ltp":11.0,"tv":460.21,"id":8429550},{"batb":[[1,9.2,11.58]],"ltp":9.8,"tv":798.7,"id":10616006},{"batb":[[1,26,2.52],[2,21,11.56]],"ltp":44.0,"tv":80.81,"id":9001159}]}]}
{"op":"mcm","clk":"994433468","pt":1580551809495,"mc":[{"id":"1.168133548","rc":[{"batl":[[0,11,22.22]],"ltp":11.0,"tv":460.21,"id":8429550}]}]}
{"op":"mcm","clk":"994433619","pt":1580551810503,"mc":[{"id":"1.168133548","rc":[{"batl":[[0,11,2],[1,11.5,24.87]],"ltp":11.0,"tv":460.21,"id":8429550},{"batb":[[2,25,1.39]],"ltp":34.0,"tv":53.97,"id":9193530}]}]}
{"op":"mcm","clk":"994433790","pt":1580551811483,"mc":[{"id":"1.168133548","rc":[{"batl":[[0,11,22.22],[1,11.5,5.53]],"ltp":11.0,"tv":460.21,"id":8429550},{"batb":[[0,5.7,5.54],[1,5.6,9.23]],"ltp":5.8,"tv":313.73,"id":8231803}]}]}
{"op":"mcm","clk":"994433958","pt":1580551812389,"mc":[{"id":"1.168133548","rc":[{"trd":[[11,39.24]],"batb":[[0,10.5,7.17],[2,9.8,1.29]],"batl":[[0,11.5,23.55],[1,12,10.8],[2,12.5,54.17]],"ltp":11.0,"tv":463.6,"id":8429550},{"trd":[[6,309.35]],"batl":[[0,6,69.79]],"ltp":6.0,"tv":1290.3,"id":9417341},{"trd":[[5.8,31.43]],"batl":[[0,5.8,77.77]],"ltp":5.8,"tv":320.16,"id":8231803},{"trd":[[10,253.96]],"batl":[[0,10.5,3.3],[1,11,10.3],[2,11.5,10.44]],"ltp":10.0,"tv":805.51,"id":10616006},{"trd":[[7.4,51.51]],"batl":[[0,7.6,16.5],[1,7.8,10.94],[2,8,23.38]],"ltp":7.4,"tv":936.18,"id":10170404},{"trd":[[8.8,36.92]],"batl":[[0,9,2.81],[1,9.8,7.44],[2,10,7.53]],"ltp":8.8,"tv":451.74,"id":15608820},{"trd":[[34,0.52],[36,0.71]],"batl":[[0,36,2.32]],"ltp":36.0,"tv":55.02,"id":9193530},{"trd":[[36,5.27],[38,0.3]],"batb":[[0,26,2.52],[1,22,3.39]],"batl":[[0,42,1.82],[1,80,8.35],[2,85,9]],"ltp":36.0,"tv":86.38,"id":9001159},{"trd":[[6,113.44]],"batl":[[0,6,16.8]],"ltp":6.0,"tv":529.61,"id":17352128}],"tv":4938.53}]}
{"op":"mcm","clk":"994434106","pt":1580551813504,"mc":[{"id":"1.168133548","rc":[{"batl":[[0,42,1.96],[1,80,8.15]],"ltp":36.0,"tv":86.38,"id":9001159}]}]}
{"op":"mcm","clk":"994434280","pt":1580551814528,"mc":[{"id":"1.168133548","rc":[{"batb":[[0,10.5,9.84]],"ltp":11.0,"tv":463.6,"id":8429550},{"batl":[[1,6.2,57.74]],"ltp":6.0,"tv":1290.3,"id":9417341},{"batl":[[1,9.8,12.96]],"ltp":8.8,"tv":451.74,"id":15608820}]}]}
{"op":"mcm","clk":"994434450","pt":1580551815489,"mc":[{"id":"1.168133548","rc":[{"batl":[[0,11.5,5.53],[1,12,28.08]],"ltp":11.0,"tv":463.6,"id":8429550},{"batl":[[1,9.8,5.53]],"ltp":8.8,"tv":451.74,"id":15608820},{"batb":[[0,27,7.97]],"ltp":36.0,"tv":55.02,"id":9193530},{"batb":[[0,26,1.67]],"ltp":36.0,"tv":86.38,"id":9001159}]}]}
{"op":"mcm","clk":"994434576","pt":1580551816189,"mc":[{"id":"1.168133548","rc":[{"batl":[[0,11.5,23.55],[1,12,10.8]],"ltp":11.0,"tv":463.6,"id":8429550},{"batb":[[1,24,1.2],[2,22,3.39]],"ltp":36.0,"tv":86.38,"id":9001159}]}]}
{"op":"mcm","clk":"994434785","pt":1580551817518,"mc":[{"id":"1.168133548","rc":[{"batl":[[0,11.5,5.53],[1,12,28.09]],"ltp":11.0,"tv":463.6,"id":8429550}]}]}
{"op":"mcm","clk":"994434949","pt":1580551818484,"mc":[{"id":"1.168133548","rc":[{"batl":[[0,11.5,23.55],[1,12,10.8]],"ltp":11.0,"tv":463.6,"id":8429550},{"batb":[[2,21,11.56]],"ltp":36.0,"tv":86.38,"id":9001159}]}]}
{"op":"mcm","clk":"994435039","pt":1580551819022,"mc":[{"id":"1.168133548","rc":[{"batl":[[0,42,2.15]],"ltp":36.0,"tv":86.38,"id":9001159}]}]}
{"op":"mcm","clk":"994435399","pt":1580551821123,"mc":[{"id":"1.168133548","rc":[{"batb":[[1,10,13.04]],"batl":[[0,11.5,5.53],[1,12,28.09]],"ltp":11.0,"tv":463.6,"id":8429550}]}]}
{"op":"mcm","clk":"994435624","pt":1580551822404,"mc":[{"id":"1.168133548","rc":[{"batl":[[0,11.5,23.56],[1,12,10.8]],"ltp":11.0,"tv":463.6,"id":8429550}]}]}
{"op":"mcm","clk":"994435816","pt":1580551823524,"mc":[{"id":"1.168133548","rc":[{"batb":[[0,8.6,2],[1,8.4,5.17],[2,8.2,9.76]],"ltp":8.8,"tv":451.74,"id":15608820}]}]}
{"op":"mcm","clk":"994435981","pt":1580551824479,"mc":[{"id":"1.168133548","rc":[{"batl":[[0,11.5,5.53],[1,12,28.09]],"ltp":11.0,"tv":463.6,"id":8429550},{"batb":[[2,21,14.69]],"ltp":36.0,"tv":86.38,"id":9001159}]}]}
{"op":"mcm","clk":"994436171","pt":1580551825535,"mc":[{"id":"1.168133548","rc":[{"batl":[[0,11.5,23.56],[1,12,10.8]],"ltp":11.0,"tv":463.6,"id":8429550}]}]}
{"op":"mcm","clk":"994436490","pt":1580551827555,"mc":[{"id":"1.168133548","rc":[{"trd":[[10.5,41.12]],"batb":[[0,10,13.04],[1,9.8,1.29],[2,9.4,2.67]],"batl":[[0,10.5,18.67],[1,11.5,5.53],[2,12,10.8]],"ltp":10.5,"tv":499.72,"id":8429550},{"batb":[[1,5.5,21.56]],"ltp":6.0,"tv":1290.3,"id":9417341}],"tv":4974.65}]}
{"op":"mcm","clk":"994436687","pt":1580551828568,"mc":[{"id":"1.168133548","rc":[{"trd":[[10.5,53.62]],"batb":[[0,10.5,6.26],[1,10,13.04],[2,9.8,1.29]],"batl":[[0,11.5,5.53],[1,12,10.8],[2,12.5,54.17]],"ltp":10.5,"tv":512.22,"id":8429550}],"tv":4987.15}]}
{"op":"mcm","clk":"994436880","pt":1580551829571,"mc":[{"id":"1.168133548","rc":[{"trd":[[10.5,66.14]],"batb":[[0,10,6.23],[1,9.8,1.29],[2,9.2,11.37]],"batl":[[0,11,5.88],[1,11.5,11.81],[2,12,10.8]],"ltp":10.5,"tv":524.74,"id":8429550},{"batb":[[1,5.5,33.73]],"ltp":6.0,"tv":1290.3,"id":9417341}],"tv":4999.67}]}
{"op":"mcm","clk":"994437016","pt":1580551830470,"mc":[{"id":"1.168133548","rc":[{"batb":[[0,27,9.97]],"ltp":36.0,"tv":55.02,"id":9193530}]}]}
{"op":"mcm","clk":"994437686","pt":1580551834464,"mc":[{"id":"1.168133548","rc":[{"batb":[[0,27,5.95],[2,24,4.54]],"ltp":36.0,"tv":55.02,"id":9193530},{"batb":[[1,21,14.69],[2,20,8.79]],"ltp":36.0,"tv":86.38,"id":9001159}]}]}
{"op":"mcm","clk":"994437874","pt":1580551835472,"mc":[{"id":"1.168133548","rc":[{"batb":[[0,28,4.78],[1,27,5.04],[2,26,2.95]],"ltp":36.0,"tv":55.02,"id":9193530},{"batb":[[1,21,11.56]],"ltp":36.0,"tv":86.38,"id":9001159}]}]}
{"op":"mcm","clk":"994438185","pt":1580551837372,"mc":[{"id":"1.168133548","rc":[{"batb":[[1,8.4,7.17]],"ltp":8.8,"tv":451.74,"id":15608820}]}]}
{"op":"mcm","clk":"994438359","pt":1580551838488,"mc":[{"id":"1.168133548","rc":[{"batl":[[0,9.6,3.97]],"ltp":8.8,"tv":451.74,"id":15608820}]}]}
{"op":"mcm","clk":"994438546","pt":1580551839496,"mc":[{"id":"1.168133548","rc":[{"batl":[[0,10,1.08],[1,10.5,3.3],[2,11,10.3]],"ltp":10.0,"tv":805.51,"id":10616006},{"batl":[[0,95,2.08],[1,210,3.03]],"ltp":36.0,"tv":55.02,"id":9193530}]}]}
{"op":"mcm","clk":"994438729","pt":1580551840474,"mc":[{"id":"1.168133548","rc":[{"batl":[[0,9.6,7.97],[1,10,5],[2,12,10.58]],"ltp":8.8,"tv":451.74,"id":15608820},{"batl":[[0,90,2.18],[1,95,2],[2,210,3.03]],"ltp":36.0,"tv":55.02,"id":9193530}]}]}
{"op":"mcm","clk":"994438952","pt":1580551841482,"mc":[{"id":"1.168133548","rc":[{"batl":[[1,11.5,6.28]],"ltp":10.5,"tv":524.74,"id":8429550},{"batl":[[0,95,2.08],[1,210,3.03],[2,220,9]],"ltp":36.0,"tv":55.02,"id":9193530}]}]}
{"op":"mcm","clk":"994439112","pt":1580551842489,"mc":[{"id":"1.168133548","rc":[{"batl":[[2,12.5,54.17]],"ltp":10.5,"tv":524.74,"id":8429550},{"batb":[[1,27,5.7]],"ltp":36.0,"tv":55.02,"id":9193530}]}]}
{"op":"mcm","clk":"994439632","pt":1580551845479,"mc":[{"id":"1.168133548","rc":[{"batb":[[1,22,1.69],[2,21,11.56]],"ltp":36.0,"tv":86.38,"id":9001159}]}]}
{"op":"mcm","clk":"994440980","pt":1580551853386,"mc":[{"id":"1.168133548","rc":[{"batb":[[1,22,3]],"ltp":36.0,"tv":86.38,"id":9001159}]}]}
{"op":"mcm","clk":"994441948","pt":1580551859145,"mc":[{"id":"1.168133548","rc":[{"batb":[[2,8.2,12.13]],"ltp":8.8,"tv":451.74,"id":15608820}]}]}
{"op":"mcm","clk":"994442351","pt":1580551861547,"mc":[{"id":"1.168133548","rc":[{"trd":[[7,117.26]],"batb":[[0,7,23]],"ltp":7.0,"tv":970.18,"id":10170404},{"batb":[[0,8.6,4.33]],"ltp":8.8,"tv":451.74,"id":15608820}],"tv":5033.67}]}
{"op":"mcm","clk":"994442514","pt":1580551862550,"mc":[{"id":"1.168133548","rc":[{"batb":[[0,28,5.97],[2,26,1.67]],"ltp":36.0,"tv":55.02,"id":9193530}]}]}
{"op":"mcm","clk":"994443191","pt":1580551866419,"mc":[{"id":"1.168133548","rc":[{"batl":[[0,7.8,10.94],[1,8,23.38],[2,8.2,22.85]],"ltp":7.0,"tv":970.18,"id":10170404}]}]}
{"op":"mcm","clk":"994443350","pt":1580551867431,"mc":[{"id":"1.168133548","rc":[{"batl":[[0,7.6,7.38],[1,7.8,10.94],[2,8,23.38]],"ltp":7.0,"tv":970.18,"id":10170404}]}]}
{"op":"mcm","clk":"994444014","pt":1580551871454,"mc":[{"id":"1.168133548","rc":[{"batl":[[0,9.6,3.97],[1,9.8,4],[2,10,5]],"ltp":8.8,"tv":451.74,"id":15608820}]}]}
{"op":"mcm","clk":"994445233","pt":1580551878541,"mc":[{"id":"1.168133548","rc":[{"batl":[[2,95,2]],"ltp":36.0,"tv":86.38,"id":9001159}]}]}
{"op":"mcm","clk":"994445972","pt":1580551882574,"mc":[{"id":"1.168133548","rc":[{"batb":[[1,9.2,11.37],[2,9,1.15]],"ltp":10.5,"tv":524.74,"id":8429550}]}]}
{"op":"mcm","clk":"994446300","pt":1580551884491,"mc":[{"id":"1.168133548","rc":[{"batl":[[2,8,26.23]],"ltp":7.0,"tv":970.18,"id":10170404}]}]}
{"op":"mcm","clk":"994447611","pt":1580551892490,"mc":[{"id":"1.168133548","rc":[{"batb":[[0,28,6.14]],"ltp":36.0,"tv":55.02,"id":9193530}]}]}
{"op":"mcm","clk":"994449244","pt":1580551902514,"mc":[{"id":"1.168133548","rc":[{"batl":[[0,10.5,3.3],[1,11,10.3],[2,11.5,10.44]],"ltp":10.0,"tv":805.51,"id":10616006},{"batl":[[0,9.6,7.97],[1,10,5],[2,12,10.58]],"ltp":8.8,"tv":451.74,"id":15608820},{"batl":[[0,90,7.67],[1,95,2],[2,210,3.03]],"ltp":36.0,"tv":55.02,"id":9193530}]}]}
{"op":"mcm","clk":"994449390","pt":1580551903527,"mc":[{"id":"1.168133548","rc":[{"batl":[[0,10,6.76],[1,10.5,3.3],[2,11,11.28]],"ltp":10.0,"tv":805.51,"id":10616006},{"batl":[[0,85,3.1],[1,90,7.6],[2,95,2]],"ltp":36.0,"tv":55.02,"id":9193530}]}]}
{"op":"mcm","clk":"994449578","pt":1580551904527,"mc":[{"id":"1.168133548","rc":[{"batl":[[1,95,2.55],[2,190,2]],"ltp":36.0,"tv":86.38,"id":9001159}]}]}
{"op":"mcm","clk":"994450971","pt":1580551912395,"mc":[{"id":"1.168133548","rc":[{"batl":[[0,9.6,3.97],[1,9.8,4],[2,10,5]],"ltp":8.8,"tv":451.74,"id":15608820}]}]}
{"op":"mcm","clk":"994451485","pt":1580551915480,"mc":[{"id":"1.168133548","rc":[{"batb":[[1,6.8,17.17]],"ltp":7.0,"tv":970.18,"id":10170404}]}]}
{"op":"mcm","clk":"994451629","pt":1580551916301,"mc":[{"id":"1.168133548","rc":[{"batb":[[0,7,28.71]],"ltp":7.0,"tv":970.18,"id":10170404}]}]}
{"op":"mcm","clk":"994451998","pt":1580551918402,"mc":[{"id":"1.168133548","rc":[{"batl":[[2,270,9]],"ltp":36.0,"tv":86.38,"id":9001159}]}]}
{"op":"mcm","clk":"994452217","pt":1580551919526,"mc":[{"id":"1.168133548","rc":[{"batb":[[0,7.2,4],[1,7,28.71],[2,6.8,17.17]],"ltp":7.0,"tv":970.18,"id":10170404}]}]}
{"op":"mcm","clk":"994452857","pt":1580551922494,"mc":[{"id":"1.168133548","rc":[{"batl":[[0,9.6,7.97],[1,10,5],[2,12,10.58]],"ltp":8.8,"tv":451.74,"id":15608820},{"batl":[[0,85,3.16]],"ltp":36.0,"tv":55.02,"id":9193530}]}]}
{"op":"mcm","clk":"994453220","pt":1580551924416,"mc":[{"id":"1.168133548","rc":[{"batb":[[0,7.4,5],[1,7.2,4],[2,7,28.71]],"ltp":7.0,"tv":970.18,"id":10170404}]}]}
{"op":"mcm","clk":"994456162","pt":1580551939573,"mc":[{"id":"1.168133548","rc":[{"batl":[[1,6.2,55.74]],"ltp":6.0,"tv":1290.3,"id":9417341}]}]}
{"op":"mcm","clk":"994456728","pt":1580551942571,"mc":[{"id":"1.168133548","rc":[{"batl":[[0,9.6,3.97],[1,9.8,4],[2,10,5]],"ltp":8.8,"tv":451.74,"id":15608820}]}]}
{"op":"mcm","clk":"994458088","pt":1580551950573,"mc":[{"id":"1.168133548","rc":[{"trd":[[11,51.01]],"batl":[[0,11.5,6.28],[1,12.5,54.17],[2,13.5,20.72]],"ltp":11.0,"tv":536.5,"id":8429550}],"tv":5045.43}]}
{"op":"mcm","clk":"994458265","pt":1580551951494,"mc":[{"id":"1.168133548","rc":[{"trd":[[11.5,50.5]],"batl":[[0,11.5,5.2]],"ltp":11.5,"tv":537.58,"id":8429550},{"trd":[[5.6,5.64],[5.7,106.18],[5.8,359.57]],"batb":[[0,5.5,33.02],[1,5.2,2],[2,5,6]],"batl":[[0,6,69.94]],"ltp":5.6,"tv":1332.64,"id":9417341},{"trd":[[5.8,33.58]],"batl":[[0,5.8,75.62]],"ltp":5.8,"tv":322.31,"id":8231803},{"trd":[[10,255.21]],"batl":[[0,10,5.51]],"ltp":10.0,"tv":806.76,"id":10616006},{"trd":[[7.6,56.74]],"batl":[[0,7.6,5.74]],"ltp":7.6,"tv":971.82,"id":10170404},{"trd":[[8.2,41.24],[8.4,54.53],[8.6,181.89],[9,34.4],[9.2,23.69],[9.6,46.48]],"batb":[[0,8.2,9.19],[1,7.8,9.23],[2,7.6,6.25]],"batl":[[0,9.6,3.67]],"ltp":8.2,"tv":481.98,"id":15608820},{"trd":[[38,0.08],[80,0.06],[85,0.05]],"batl":[[0,85,2.98]],"ltp":85.0,"tv":55.21,"id":9193530},{"trd":[[40,0.19],[42,0.3]],"batl":[[0,42,1.85]],"ltp":42.0,"tv":86.68,"id":9001159},{"trd":[[5.4,13.63],[5.5,14],[5.7,15.76]],"batb":[[0,5,5.07],[1,4.9,56],[2,4.7,2.63]],"ltp":5.4,"tv":572.99,"id":17352128}],"tv":5167.99}]}
{"op":"mcm","clk":"994458451","pt":1580551952498,"mc":[{"id":"1.168133548","rc":[{"trd":[[5.6,5.94]],"batb":[[0,5.6,8.05],[1,5.5,33.02],[2,5.2,2]],"batl":[[0,6,69.79]],"ltp":5.6,"tv":1332.94,"id":9417341},{"batb":[[1,7.8,17.07]],"ltp":8.2,"tv":481.98,"id":15608820},{"batb":[[0,5.1,5.87],[1,5,11.85],[2,4.9,56]],"ltp":5.4,"tv":572.99,"id":17352128}],"tv":5168.29}]}
{"op":"mcm","clk":"994458829","pt":1580551954513,"mc":[{"id":"1.168133548","rc":[{"batb":[[0,5.5,20.85],[1,5.2,2],[2,5,6]],"ltp":5.6,"tv":1332.94,"id":9417341},{"batb":[[1,7.8,9.23]],"ltp":8.2,"tv":481.98,"id":15608820},{"batl":[[0,85,3.18]],"ltp":85.0,"tv":55.21,"id":9193530},{"batl":[[0,42,2.03]],"ltp":42.0,"tv":86.68,"id":9001159},{"batb":[[0,5,5.07],[1,4.9,56],[2,4.7,2.63]],"ltp":5.4,"tv":572.99,"id":17352128}]}]}
{"op":"mcm","clk":"994459000","pt":1580551955483,"mc":[{"id":"1.168133548","rc":[{"batb":[[2,5.1,9.84]],"batl":[[0,5.9,5.82],[1,6,69.79],[2,6.2,55.74]],"ltp":5.6,"tv":1332.94,"id":9417341}]}]}
{"op":"mcm","clk":"994459183","pt":1580551956501,"mc":[{"id":"1.168133548","rc":[{"batb":[[0,10.5,1.64],[1,10,6.23],[2,9.2,11.37]],"ltp":11.5,"tv":537.58,"id":8429550},{"batb":[[1,5.2,9.69]],"ltp":5.6,"tv":1332.94,"id":9417341},{"batb":[[0,5.1,6.6],[1,5,5.07],[2,4.9,56]],"batl":[[0,5.9,5.7],[1,6,16.8],[2,6.2,32.84]],"ltp":5.4,"tv":572.99,"id":17352128}]}]}
{"op":"mcm","clk":"994459342","pt":1580551957406,"mc":[{"id":"1.168133548","rc":[{"batb":[[1,5.3,9.62],[2,5.2,21.83]],"batl":[[2,6.2,42.16]],"ltp":5.6,"tv":1332.94,"id":9417341},{"batl":[[0,5.9,24.61]],"ltp":5.4,"tv":572.99,"id":17352128}]}]}
{"op":"mcm","clk":"994459546","pt":1580551958422,"mc":[{"id":"1.168133548","rc":[{"batb":[[1,5.3,19.24]],"ltp":5.6,"tv":1332.94,"id":9417341}]}]}
{"op":"mcm","clk":"994460265","pt":1580551962535,"mc":[{"id":"1.168133548","rc":[{"batb":[[0,5.5,17.85]],"ltp":5.6,"tv":1332.94,"id":9417341},{"batl":[[0,9.6,7.67],[1,10,5],[2,12,10.58]],"ltp":8.2,"tv":481.98,"id":15608820}]}]}
{"op":"mcm","clk":"994460785","pt":1580551965517,"mc":[{"id":"1.168133548","rc":[{"batl":[[0,5.9,19.82]],"ltp":5.6,"tv":1332.94,"id":9417341}]}]}
{"op":"mcm","clk":"994460974","pt":1580551966514,"mc":[{"id":"1.168133548","rc":[{"batb":[[0,10.5,3.62]],"ltp":11.5,"tv":537.58,"id":8429550},{"batb":[[0,5.5,19.53]],"ltp":5.6,"tv":1332.94,"id":9417341},{"batb":[[0,7.4,6.98]],"ltp":7.6,"tv":971.82,"id":10170404},{"batb":[[0,8.4,1.98],[1,8.2,9.19],[2,7.8,9.23]],"batl":[[0,9.4,6.32],[1,9.6,7.67],[2,10,5]],"ltp":8.2,"tv":481.98,"id":15608820},{"batb":[[1,23,1.98],[2,22,3]],"ltp":42.0,"tv":86.68,"id":9001159},{"batb":[[0,5.2,1.98],[1,5.1,6.6],[2,5,5.07]],"batl":[[0,5.8,8.23],[1,5.9,24.61],[2,6,16.8]],"ltp":5.4,"tv":572.99,"id":17352128}]}]}
{"op":"mcm","clk":"994461151","pt":1580551967528,"mc":[{"id":"1.168133548","rc":[{"batb":[[1,5.2,21.83],[2,5.1,9.84]],"ltp":5.6,"tv":1332.94,"id":9417341},{"batb":[[2,7.8,5.54]],"ltp":8.2,"tv":481.98,"id":15608820},{"batl":[[1,5.9,33.34]],"ltp":5.4,"tv":572.99,"id":17352128}]}]}
{"op":"mcm","clk":"994461334","pt":1580551968545,"mc":[{"id":"1.168133548","rc":[{"batb":[[2,22,1.69]],"ltp":42.0,"tv":86.68,"id":9001159},{"batb":[[0,5.2,5.54]],"ltp":5.4,"tv":572.99,"id":17352128}]}]}
{"op":"mcm","clk":"994461539","pt":1580551969548,"mc":[{"id":"1.168133548","rc":[{"batb":[[1,23,3.23]],"ltp":42.0,"tv":86.68,"id":9001159}]}]}
{"op":"mcm","clk":"994462118","pt":1580551972539,"mc":[{"id":"1.168133548","rc":[{"batl":[[0,9.2,4],[1,9.4,6.32],[2,9.6,3.67]],"ltp":8.2,"tv":481.98,"id":15608820}]}]}
{"op":"mcm","clk":"994462640","pt":1580551975542,"mc":[{"id":"1.168133548","rc":[{"batb":[[2,21,11.56]],"ltp":42.0,"tv":86.68,"id":9001159}]}]}
{"op":"mcm","clk":"994463594","pt":1580551980564,"mc":[{"id":"1.168133548","rc":[{"batb":[[0,29,1.93],[1,28,5.97],[2,27,5.7]],"ltp":85.0,"tv":55.21,"id":9193530}]}]}
{"op":"mcm","clk":"994463769","pt":1580551981472,"mc":[{"id":"1.168133548","rc":[{"batl":[[1,6,79.79]],"ltp":5.6,"tv":1332.94,"id":9417341},{"batl":[[0,85,3.24]],"ltp":85.0,"tv":55.21,"id":9193530}]}]}
{"op":"mcm","clk":"994463919","pt":1580551982202,"mc":[{"id":"1.168133548","rc":[{"batb":[[1,5.3,2.44],[2,5.2,21.83]],"ltp":5.6,"tv":1332.94,"id":9417341}]}]}
{"op":"mcm","clk":"994464868","pt":1580551987477,"mc":[{"id":"1.168133548","rc":[{"batb":[[1,28,2.09]],"ltp":85.0,"tv":55.21,"id":9193530}]}]}
{"op":"mcm","clk":"994465035","pt":1580551988370,"mc":[{"id":"1.168133548","rc":[{"batb":[[0,29,10.04]],"ltp":85.0,"tv":55.21,"id":9193530},{"batb":[[1,23,9.45],[2,21,10.74]],"ltp":42.0,"tv":86.68,"id":9001159},{"batb":[[0,5.2,29.9]],"ltp":5.4,"tv":572.99,"id":17352128}]}]}
{"op":"mcm","clk":"994465238","pt":1580551989464,"mc":[{"id":"1.168133548","rc":[{"batb":[[2,27,5.04]],"ltp":85.0,"tv":55.21,"id":9193530}]}]}
{"op":"mcm","clk":"994465600","pt":1580551991380,"mc":[{"id":"1.168133548","rc":[{"trd":[[7.6,68.22]],"batb":[[0,7.6,4.26],[1,7.4,6.98],[2,7.2,4]],"batl":[[0,7.8,10.94],[1,8,26.23],[2,8.2,22.85]],"ltp":7.6,"tv":983.3,"id":10170404}],"tv":5179.77}]}
{"op":"mcm","clk":"994465926","pt":1580551993188,"mc":[{"id":"1.168133548","rc":[{"batb":[[2,21,14.67]],"ltp":42.0,"tv":86.68,"id":9001159}]}]}
{"op":"mcm","clk":"994466496","pt":1580551996456,"mc":[{"id":"1.168133548","rc":[{"batb":[[0,7.6,6.24],[1,7.4,5]],"ltp":7.6,"tv":983.3,"id":10170404},{"batb":[[0,29,10.64]],"ltp":85.0,"tv":55.21,"id":9193530}]}]}
{"op":"mcm","clk":"994466650","pt":1580551997528,"mc":[{"id":"1.168133548","rc":[{"batb":[[2,21,13.83]],"ltp":42.0,"tv":86.68,"id":9001159}]}]}
{"op":"mcm","clk":"994466811","pt":1580551998483,"mc":[{"id":"1.168133548","rc":[{"batb":[[0,30,1.23],[1,29,10.64],[2,28,1.18]],"ltp":85.0,"tv":55.21,"id":9193530},{"batb":[[1,25,1.48],[2,23,9.45]],"ltp":42.0,"tv":86.68,"id":9001159}]}]}
{"op":"mcm","clk":"994467831","pt":1580552004484,"mc":[{"id":"1.168133548","rc":[{"batb":[[2,24,1.45]],"ltp":42.0,"tv":86.68,"id":9001159}]}]}
{"op":"mcm","clk":"994468454","pt":1580552008400,"mc":[{"id":"1.168133548","rc":[{"batb":[[0,26,2.33],[1,25,7.7],[2,23,2.72]],"ltp":42.0,"tv":86.68,"id":9001159}]}]}
{"op":"mcm","clk":"994468599","pt":1580552009087,"mc":[{"id":"1.168133548","rc":[{"trd":[[5.8,38.45]],"batl":[[0,5.8,73.18]],"ltp":5.8,"tv":327.19,"id":8231803}],"tv":5184.65}]}
{"op":"mcm","clk":"994469014","pt":1580552011526,"mc":[{"id":"1.168133548","rc":[{"batb":[[0,10.5,7.43]],"ltp":11.5,"tv":537.58,"id":8429550},{"batb":[[0,5.5,26.8]],"ltp":5.6,"tv":1332.94,"id":9417341},{"batb":[[0,5.7,12.56]],"ltp":5.8,"tv":327.19,"id":8231803},{"batb":[[0,7.6,11.5]],"ltp":7.6,"tv":983.3,"id":10170404},{"batb":[[0,5.2,37.59]],"ltp":5.4,"tv":572.99,"id":17352128}]}]}
{"op":"mcm","clk":"994469173","pt":1580552012536,"mc":[{"id":"1.168133548","rc":[{"batb":[[1,5.3,12.07]],"ltp":5.6,"tv":1332.94,"id":9417341},{"batb":[[0,9.6,22.92]],"ltp":10.0,"tv":806.76,"id":10616006},{"batb":[[1,8.2,14.07]],"ltp":8.2,"tv":481.98,"id":15608820},{"batb":[[1,29,12.02]],"ltp":85.0,"tv":55.21,"id":9193530},{"batb":[[0,27,1.98],[1,26,3.87],[2,25,7.7]],"ltp":42.0,"tv":86.68,"id":9001159}]}]}
{"op":"mcm","clk":"994470036","pt":1580552017529,"mc":[{"id":"1.168133548","rc":[{"batl":[[0,7.8,12.98]],"ltp":7.6,"tv":983.3,"id":10170404}]}]}
{"op":"mcm","clk":"994470209","pt":1580552018552,"mc":[{"id":"1.168133548","rc":[{"batb":[[0,11,3.03],[1,10.5,7.43],[2,10,6.23]],"ltp":11.5,"tv":537.58,"id":8429550},{"batl":[[1,5.9,27.63],[2,6,22.41]],"ltp":5.4,"tv":572.99,"id":17352128}]}]}
{"op":"mcm","clk":"994470376","pt":1580552019529,"mc":[{"id":"1.168133548","rc":[{"batb":[[1,9.2,14.55]],"ltp":10.0,"tv":806.76,"id":10616006},{"batb":[[0,5.3,6.35],[1,5.2,37.59]],"ltp":5.4,"tv":572.99,"id":17352128}]}]}
{"op":"mcm","clk":"994470509","pt":1580552020328,"mc":[{"id":"1.168133548","rc":[{"batb":[[0,27,3.35],[2,25,6.21]],"ltp":42.0,"tv":86.68,"id":9001159}]}]}
{"op":"mcm","clk":"994470700","pt":1580552021449,"mc":[{"id":"1.168133548","rc":[{"batb":[[1,26,4.56]],"ltp":42.0,"tv":86.68,"id":9001159}]}]}
{"op":"mcm","clk":"994471528","pt":1580552026533,"mc":[{"id":"1.168133548","rc":[{"batb":[[1,29,3.91]],"ltp":85.0,"tv":55.21,"id":9193530},{"batb":[[2,22,2.31]],"ltp":42.0,"tv":86.68,"id":9001159},{"batb":[[1,5.2,9.67]],"ltp":5.4,"tv":572.99,"id":17352128}]}]}
{"op":"mcm","clk":"994471664","pt":1580552027434,"mc":[{"id":"1.168133548","rc":[{"batb":[[0,30,9.08]],"ltp":85.0,"tv":55.21,"id":9193530},{"batb":[[0,27,9.11]],"ltp":42.0,"tv":86.68,"id":9001159}]}]}
{"op":"mcm","clk":"994473261","pt":1580552036425,"mc":[{"id":"1.168133548","rc":[{"trd":[[7.6,71.18]],"batb":[[0,7.6,5.76]],"ltp":7.6,"tv":986.26,"id":10170404}],"tv":5187.61}]}
{"op":"mcm","clk":"994474214","pt":1580552041552,"mc":[{"id":"1.168133548","rc":[{"batl":[[0,11.5,6.59]],"ltp":11.5,"tv":537.58,"id":8429550}]}]}
{"op":"mcm","clk":"994474369","pt":1580552042545,"mc":[{"id":"1.168133548","rc":[{"batb":[[2,27,5.04]],"ltp":85.0,"tv":55.21,"id":9193530}]}]}
{"op":"mcm","clk":"994474547","pt":1580552043524,"mc":[{"id":"1.168133548","rc":[{"trd":[[7.6,79.7]],"batb":[[0,7.6,1.5]],"ltp":7.6,"tv":994.78,"id":10170404},{"batb":[[0,32,1.03],[1,30,9.08],[2,29,3.91]],"ltp":85.0,"tv":55.21,"id":9193530}],"tv":5196.13}]}
{"op":"mcm","clk":"994474908","pt":1580552045531,"mc":[{"id":"1.168133548","rc":[{"trd":[[7.6,82.7]],"batb":[[0,7.4,5],[1,7.2,4],[2,7,28.71]],"batl":[[0,7.8,13.48]],"ltp":7.6,"tv":997.78,"id":10170404}],"tv":5199.13}]}
{"op":"mcm","clk":"994475842","pt":1580552050568,"mc":[{"id":"1.168133548","rc":[{"batl":[[2,190,2]],"ltp":85.0,"tv":55.21,"id":9193530},{"batl":[[1,270,9.55],[2,390,2.16]],"ltp":42.0,"tv":86.68,"id":9001159}]}]}
{"op":"mcm","clk":"994478109","pt":1580552063456,"mc":[{"id":"1.168133548","rc":[{"batb":[[0,27,17.11]],"ltp":42.0,"tv":86.68,"id":9001159}]}]}
{"op":"mcm","clk":"994478465","pt":1580552065568,"mc":[{"id":"1.168133548","rc":[{"batl":[[0,11.5,5.2]],"ltp":11.5,"tv":537.58,"id":8429550},{"batb":[[0,27,11.35]],"ltp":42.0,"tv":86.68,"id":9001159}]}]}
{"op":"mcm","clk":"994478643","pt":1580552066558,"mc":[{"id":"1.168133548","rc":[{"batb":[[0,28,5.55],[1,27,11.35],[2,26,4.56]],"ltp":42.0,"tv":86.68,"id":9001159}]}]}
{"op":"mcm","clk":"994479056","pt":1580552068559,"mc":[{"id":"1.168133548","rc":[{"batl":[[2,220,9]],"ltp":85.0,"tv":55.21,"id":9193530},{"batl":[[2,640,2.16]],"ltp":42.0,"tv":86.68,"id":9001159}]}]}
{"op":"mcm","clk":"994479413","pt":1580552070554,"mc":[{"id":"1.168133548","rc":[{"batl":[[0,42,1.85]],"ltp":42.0,"tv":86.68,"id":9001159}]}]}
{"op":"mcm","clk":"994479579","pt":1580552071463,"mc":[{"id":"1.168133548","rc":[{"batb":[[2,26,3.87]],"ltp":42.0,"tv":86.68,"id":9001159}]}]}
{"op":"mcm","clk":"994479773","pt":1580552072557,"mc":[{"id":"1.168133548","rc":[{"batb":[[0,10.5,7.57],[1,10,6.23],[2,9.2,11.37]],"ltp":11.5,"tv":537.58,"id":8429550}]}]}
{"op":"mcm","clk":"994480987","pt":1580552079568,"mc":[{"id":"1.168133548","rc":[{"batb":[[2,29,3.31]],"ltp":85.0,"tv":55.21,"id":9193530},{"batb":[[0,28,6.18]],"batl":[[0,42,2.8]],"ltp":42.0,"tv":86.68,"id":9001159}]}]}
{"op":"mcm","clk":"994481938","pt":1580552084558,"mc":[{"id":"1.168133548","rc":[{"batb":[[0,5.6,45.23],[1,5.5,26.8],[2,5.3,12.07]],"ltp":5.6,"tv":1332.94,"id":9417341},{"batb":[[0,8.4,31.75]],"batl":[[1,9.6,3.67],[2,10,5]],"ltp":8.2,"tv":481.98,"id":15608820},{"batb":[[0,5.4,26.88],[1,5.3,6.35],[2,5.2,9.67]],"ltp":5.4,"tv":572.99,"id":17352128}]}]}
{"op":"mcm","clk":"994482260","pt":1580552086492,"mc":[{"id":"1.168133548","rc":[{"batb":[[0,29,1.28],[1,28,6.18],[2,27,9.98]],"batl":[[1,270,9.06]],"ltp":42.0,"tv":86.68,"id":9001159}]}]}
{"op":"mcm","clk":"994482604","pt":1580552088402,"mc":[{"id":"1.168133548","rc":[{"batb":[[0,32,1.59]],"ltp":85.0,"tv":55.21,"id":9193530}]}]}
{"op":"mcm","clk":"994482929","pt":1580552090068,"mc":[{"id":"1.168133548","rc":[{"batl":[[0,7.8,11.44]],"ltp":7.6,"tv":997.78,"id":10170404}]}]}
{"op":"mcm","clk":"994484580","pt":1580552099221,"mc":[{"id":"1.168133548","rc":[{"batl":[[2,890,2.16]],"ltp":42.0,"tv":86.68,"id":9001159}]}]}
{"op":"mcm","clk":"994485306","pt":1580552103487,"mc":[{"id":"1.168133548","rc":[{"batb":[[0,5.5,26.8],[1,5.3,12.07],[2,5.2,9.69]],"ltp":5.6,"tv":1332.94,"id":9417341},{"batb":[[0,8.4,1.98]],"ltp":8.2,"tv":481.98,"id":15608820}]}]}
{"op":"mcm","clk":"994485609","pt":1580552105417,"mc":[{"id":"1.168133548","rc":[{"batb":[[1,5.3,21.9]],"ltp":5.6,"tv":1332.94,"id":9417341},{"batb":[[2,7.8,13.28]],"ltp":8.2,"tv":481.98,"id":15608820}]}]}
{"op":"mcm","clk":"994485801","pt":1580552106529,"mc":[{"id":"1.168133548","rc":[{"batb":[[1,5.3,19.46]],"ltp":5.6,"tv":1332.94,"id":9417341},{"batb":[[2,7.8,5.54]],"ltp":8.2,"tv":481.98,"id":15608820}]}]}
{"op":"mcm","clk":"994485968","pt":1580552107497,"mc":[{"id":"1.168133548","rc":[{"batb":[[0,8.4,4.03]],"ltp":8.2,"tv":481.98,"id":15608820}]}]}
{"op":"mcm","clk":"994487780","pt":1580552117539,"mc":[{"id":"1.168133548","rc":[{"batl":[[0,80,1.15],[1,85,3.04],[2,90,7.6]],"ltp":85.0,"tv":55.21,"id":9193530}]}]}
{"op":"mcm","clk":"994488751","pt":1580552122533,"mc":[{"id":"1.168133548","rc":[{"batb":[[0,5.3,6.35],[1,5.2,9.67],[2,5,5.07]],"ltp":5.4,"tv":572.99,"id":17352128}]}]}
{"op":"mcm","clk":"994488867","pt":1580552123126,"mc":[{"id":"1.168133548","rc":[{"batl":[[0,85,3.99],[1,90,7.6],[2,220,9]],"ltp":85.0,"tv":55.21,"id":9193530}]}]}
{"op":"mcm","clk":"994489489","pt":1580552126532,"mc":[{"id":"1.168133548","rc":[{"trd":[[5.7,27.1]],"batb":[[0,5.7,10.56]],"ltp":5.7,"tv":331.19,"id":8231803}],"tv":5203.13}]}
{"op":"mcm","clk":"994489615","pt":1580552127266,"mc":[{"id":"1.168133548","rc":[{"batl":[[1,220,9],[2,340,2.16]],"ltp":85.0,"tv":55.21,"id":9193530}]}]}
{"op":"mcm","clk":"994490053","pt":1580552129564,"mc":[{"id":"1.168133548","rc":[{"batl":[[2,590,2.16]],"ltp":85.0,"tv":55.21,"id":9193530},{"batl":[[2,950,0.2]],"ltp":42.0,"tv":86.68,"id":9001159}]}]}
{"op":"mcm","clk":"994490196","pt":1580552130466,"mc":[{"id":"1.168133548","rc":[{"batb":[[0,5.4,7],[1,5.3,6.35],[2,5.2,9.67]],"ltp":5.4,"tv":572.99,"id":17352128}]}]}
{"op":"mcm","clk":"994492121","pt":1580552141465,"mc":[{"id":"1.168133548","rc":[{"trd":[[5.8,27.38]],"batb":[[0,5.8,1.77],[1,5.4,7],[2,5.3,6.35]],"batl":[[0,5.9,27.63],[1,6,22.41],[2,6.2,14.29]],"ltp":5.8,"tv":589.45,"id":17352128}],"tv":5219.59}]}
{"op":"mcm","clk":"994492294","pt":1580552142482,"mc":[{"id":"1.168133548","rc":[{"batl":[[0,80,8.55],[1,85,3.04],[2,220,9]],"ltp":85.0,"tv":55.21,"id":9193530}]}]}
{"op":"mcm","clk":"994492480","pt":1580552143493,"mc":[{"id":"1.168133548","rc":[{"batb":[[0,32,1.03]],"ltp":85.0,"tv":55.21,"id":9193530}]}]}
{"op":"mcm","clk":"994494104","pt":1580552153481,"mc":[{"id":"1.168133548","rc":[{"batb":[[1,30,9.66]],"ltp":85.0,"tv":55.21,"id":9193530}]}]}
{"op":"mcm","clk":"994495378","pt":1580552161508,"mc":[{"id":"1.168133548","rc":[{"batl":[[0,75,1.02],[1,80,7.6],[2,85,2.98]],"ltp":85.0,"tv":55.21,"id":9193530}]}]}
{"op":"mcm","clk":"994497186","pt":1580552172292,"mc":[{"id":"1.168133548","rc":[{"batl":[[0,75,4.05],[2,220,9]],"ltp":85.0,"tv":55.21,"id":9193530},{"batb":[[1,5.5,3.78],[2,5.4,7]],"ltp":5.8,"tv":589.45,"id":17352128}]}]}
{"op":"mcm","clk":"994497872","pt":1580552176363,"mc":[{"id":"1.168133548","rc":[{"trd":[[5.8,30.74]],"batb":[[0,5.5,3.87],[1,5.4,7],[2,5.2,9.67]],"ltp":5.8,"tv":592.81,"id":17352128}],"tv":5222.95}]}
{"op":"mcm","clk":"994500000","pt":1580552188483,"mc":[{"id":"1.168133548","rc":[{"trd":[[7.6,94.7]],"batl":[[0,7.6,4.27],[1,7.8,10.94],[2,8,26.23]],"ltp":7.6,"tv":1009.78,"id":10170404}],"tv":5234.95}]}
{"op":"mcm","clk":"994500373","pt":1580552190504,"mc":[{"id":"1.168133548","rc":[{"batl":[[1,6,30.23]],"ltp":5.8,"tv":592.81,"id":17352128}]}]}
{"op":"mcm","clk":"994500921","pt":1580552193517,"mc":[{"id":"1.168133548","rc":[{"trd":[[7.6,103.24]],"batb":[[0,7.6,6.73],[1,7.4,5],[2,7.2,4]],"batl":[[0,7.8,10.94],[1,8,26.23],[2,8.2,22.85]],"ltp":7.6,"tv":1018.32,"id":10170404}],"tv":5243.49}]}
{"op":"mcm","clk":"994501577","pt":1580552197294,"mc":[{"id":"1.168133548","rc":[{"batb":[[2,7.2,6]],"ltp":7.6,"tv":1018.32,"id":10170404}]}]}
{"op":"mcm","clk":"994503285","pt":1580552207495,"mc":[{"id":"1.168133548","rc":[{"trd":[[5.9,37.62]],"batb":[[0,5.5,3.78]],"batl":[[0,5.9,27.54]],"ltp":5.9,"tv":592.99,"id":17352128}],"tv":5243.67}]}
{"op":"mcm","clk":"994509432","pt":1580552239434,"mc":[{"id":"1.168133548","rc":[{"batb":[[1,5.6,7.76]],"ltp":5.7,"tv":331.19,"id":8231803}]}]}
{"op":"mcm","clk":"994509567","pt":1580552240250,"mc":[{"id":"1.168133548","rc":[{"batb":[[0,5.7,12]],"ltp":5.7,"tv":331.19,"id":8231803}]}]}
{"op":"mcm","clk":"994511240","pt":1580552249542,"mc":[{"id":"1.168133548","rc":[{"batb":[[1,10,2]],"ltp":11.5,"tv":537.58,"id":8429550}]}]}
{"op":"mcm","clk":"994518818","pt":1580552287426,"mc":[{"id":"1.168133548","rc":[{"batb":[[0,32,1.57]],"ltp":85.0,"tv":55.21,"id":9193530}]}]}
{"op":"mcm","clk":"994520265","pt":1580552294943,"mc":[{"id":"1.168133548","rc":[{"batb":[[1,9.2,16.9]],"ltp":10.0,"tv":806.76,"id":10616006}]}]}
{"op":"mcm","clk":"994524685","pt":1580552318539,"mc":[{"id":"1.168133548","rc":[{"batb":[[0,29,1.88]],"ltp":42.0,"tv":86.68,"id":9001159}]}]}
{"op":"mcm","clk":"994527255","pt":1580552333482,"mc":[{"id":"1.168133548","rc":[{"trd":[[10,266.23]],"batl":[[0,10.5,3.3],[1,11,11.28],[2,11.5,10.44]],"ltp":10.0,"tv":817.78,"id":10616006}],"tv":5254.69}]}
{"op":"mcm","clk":"994527363","pt":1580552334062,"mc":[{"id":"1.168133548","rc":[{"batb":[[2,9.8,5.7]],"ltp":11.5,"tv":537.58,"id":8429550}]}]}
{"op":"mcm","clk":"994530679","pt":1580552352516,"mc":[{"id":"1.168133548","rc":[{"batl":[[0,5.8,2],[1,5.9,19.82],[2,6,79.79]],"ltp":5.6,"tv":1332.94,"id":9417341}]}]}
{"op":"mcm","clk":"994533621","pt":1580552368431,"mc":[{"id":"1.168133548","rc":[{"batl":[[1,220,9],[2,340,2.16]],"ltp":85.0,"tv":55.21,"id":9193530}]}]}
{"op":"mcm","clk":"994533737","pt":1580552369130,"mc":[{"id":"1.168133548","rc":[{"batl":[[2,590,2.16]],"ltp":85.0,"tv":55.21,"id":9193530}]}]}
{"op":"mcm","clk":"994536610","pt":1580552384563,"mc":[{"id":"1.168133548","rc":[{"batl":[[0,70,8.55],[1,75,3.1],[2,220,9]],"ltp":85.0,"tv":55.21,"id":9193530}]}]}
{"op":"mcm","clk":"994537191","pt":1580552387562,"mc":[{"id":"1.168133548","rc":[{"batb":[[2,9.4,6.81]],"ltp":11.5,"tv":537.58,"id":8429550},{"batb":[[0,5.6,8.16],[1,5.5,3.78],[2,5.4,7]],"batl":[[0,5.7,3],[1,6,13.43]],"ltp":5.9,"tv":592.99,"id":17352128}]}]}
{"op":"mcm","clk":"994537509","pt":1580552389259,"mc":[{"id":"1.168133548","rc":[{"batb":[[2,9.4,13.63]],"ltp":11.5,"tv":537.58,"id":8429550}]}]}
{"op":"mcm","clk":"994537767","pt":1580552390550,"mc":[{"id":"1.168133548","rc":[{"batb":[[2,9.4,20.44]],"ltp":11.5,"tv":537.58,"id":8429550}]}]}
{"op":"mcm","clk":"994538155","pt":1580552392541,"mc":[{"id":"1.168133548","rc":[{"batb":[[0,34,5.29],[1,32,1.57],[2,30,9.66]],"ltp":85.0,"tv":55.21,"id":9193530}]}]}
{"op":"mcm","clk":"994538967","pt":1580552396562,"mc":[{"id":"1.168133548","rc":[{"batl":[[0,65,3.98],[1,70,7.6],[2,220,9.07]],"ltp":85.0,"tv":55.21,"id":9193530}]}]}
{"op":"mcm","clk":"994540143","pt":1580552402467,"mc":[{"id":"1.168133548","rc":[{"batl":[[0,60,1.03],[1,65,3.03],[2,70,7.6]],"ltp":85.0,"tv":55.21,"id":9193530}]}]}
{"op":"mcm","clk":"994541070","pt":1580552407375,"mc":[{"id":"1.168133548","rc":[{"batb":[[2,30,13.17]],"ltp":85.0,"tv":55.21,"id":9193530}]}]}
{"op":"mcm","clk":"994541649","pt":1580552410475,"mc":[{"id":"1.168133548","rc":[{"batb":[[0,36,6.53],[1,34,5.29],[2,32,1.57]],"ltp":85.0,"tv":55.21,"id":9193530}]}]}
{"op":"mcm","clk":"994542420","pt":1580552414504,"mc":[{"id":"1.168133548","rc":[{"trd":[[38,1.97]],"batb":[[0,36,6.56]],"batl":[[0,65,3.11],[1,70,7.6],[2,220,9]],"ltp":38.0,"tv":57.1,"id":9193530}],"tv":5256.59}]}
{"op":"mcm","clk":"994544205","pt":1580552424419,"mc":[{"id":"1.168133548","rc":[{"batb":[[0,36,7.05]],"ltp":38.0,"tv":57.1,"id":9193530}]}]}
{"op":"mcm","clk":"994545172","pt":1580552429521,"mc":[{"id":"1.168133548","rc":[{"batl":[[1,6,23.73]],"ltp":5.9,"tv":592.99,"id":17352128}]}]}
{"op":"mcm","clk":"994546431","pt":1580552436543,"mc":[{"id":"1.168133548","rc":[{"batl":[[0,65,3.71]],"ltp":38.0,"tv":57.1,"id":9193530}]}]}
{"op":"mcm","clk":"994547804","pt":1580552443558,"mc":[{"id":"1.168133548","rc":[{"batl":[[1,6,15.9]],"ltp":5.9,"tv":592.99,"id":17352128}]}]}
{"op":"mcm","clk":"994547997","pt":1580552444568,"mc":[{"id":"1.168133548","rc":[{"trd":[[5.8,110.71]],"batl":[[0,5.8,37.05]],"ltp":5.8,"tv":403.44,"id":8231803}],"tv":5328.85}]}
{"op":"mcm","clk":"994549136","pt":1580552450499,"mc":[{"id":"1.168133548","rc":[{"batb":[[0,9.8,16.7],[1,9.6,22.22],[2,9.2,16.9]],"ltp":10.0,"tv":817.78,"id":10616006}]}]}
{"op":"mcm","clk":"994551442","pt":1580552462387,"mc":[{"id":"1.168133548","rc":[{"batb":[[2,30,4.04]],"ltp":38.0,"tv":57.1,"id":9193530}]}]}
{"op":"mcm","clk":"994551681","pt":1580552463500,"mc":[{"id":"1.168133548","rc":[{"batb":[[0,36,7.93]],"ltp":38.0,"tv":57.1,"id":9193530}]}]}
{"op":"mcm","clk":"994551832","pt":1580552464192,"mc":[{"id":"1.168133548","rc":[{"trd":[[9.8,54.27]],"batb":[[0,9.8,6.7]],"ltp":9.8,"tv":837.78,"id":10616006}],"tv":5348.85}]}
{"op":"mcm","clk":"994553598","pt":1580552473533,"mc":[{"id":"1.168133548","rc":[{"trd":[[5.8,140.71]],"batl":[[0,5.8,22.05]],"ltp":5.8,"tv":433.44,"id":8231803}],"tv":5378.85}]}
{"op":"mcm","clk":"994557778","pt":1580552496505,"mc":[{"id":"1.168133548","rc":[{"batl":[[1,8,23.38]],"ltp":7.6,"tv":1018.32,"id":10170404},{"trd":[[8.4,58.53]],"batb":[[0,8.4,2.03]],"ltp":8.4,"tv":485.98,"id":15608820}],"tv":5382.85}]}
{"op":"mcm","clk":"994557973","pt":1580552497573,"mc":[{"id":"1.168133548","rc":[{"trd":[[5.8,162.71]],"batl":[[0,5.8,11.05]],"ltp":5.8,"tv":455.44,"id":8231803},{"batl":[[2,8.2,20]],"ltp":7.6,"tv":1018.32,"id":10170404}],"tv":5404.85}]}
{"op":"mcm","clk":"994558141","pt":1580552498484,"mc":[{"id":"1.168133548","rc":[{"batb":[[2,5.2,9.67]],"ltp":5.9,"tv":592.99,"id":17352128}]}]}
{"op":"mcm","clk":"994558463","pt":1580552500486,"mc":[{"id":"1.168133548","rc":[{"batl":[[0,7.8,13.79]],"ltp":7.6,"tv":1018.32,"id":10170404}]}]}
{"op":"mcm","clk":"994558629","pt":1580552501490,"mc":[{"id":"1.168133548","rc":[{"batl":[[1,8,26.23],[2,8.2,22.85]],"ltp":7.6,"tv":1018.32,"id":10170404}]}]}
{"op":"mcm","clk":"994559406","pt":1580552505392,"mc":[{"id":"1.168133548","rc":[{"batb":[[0,9.8,8.7]],"ltp":9.8,"tv":837.78,"id":10616006},{"trd":[[5.7,21.76]],"batb":[[0,5.7,4]],"batl":[[0,6,15.9],[1,6.2,16.58],[2,6.4,47.31]],"ltp":5.7,"tv":598.99,"id":17352128}],"tv":5410.85}]}
{"op":"mcm","clk":"994559607","pt":1580552506504,"mc":[{"id":"1.168133548","rc":[{"trd":[[5.8,170.67]],"batl":[[0,5.8,7.07],[1,6,2],[2,6.2,11.85]],"ltp":5.8,"tv":463.4,"id":8231803}],"tv":5418.81}]}
{"op":"mcm","clk":"994559672","pt":1580552506878,"mc":[{"id":"1.168133548","rc":[{"batb":[[1,5.2,9.67],[2,5,5.07]],"batl":[[0,6,10.3]],"ltp":5.7,"tv":598.99,"id":17352128}]}]}
{"op":"mcm","clk":"994559930","pt":1580552508400,"mc":[{"id":"1.168133548","rc":[{"batb":[[1,5.3,2.76],[2,5.2,9.67]],"batl":[[1,6.2,14.29]],"ltp":5.7,"tv":598.99,"id":17352128}]}]}
{"op":"mcm","clk":"994560469","pt":1580552511497,"mc":[{"id":"1.168133548","rc":[{"trd":[[9.2,42.58],[9.6,68.21],[9.8,71.67]],"batb":[[0,9,6.25],[1,8.4,3],[2,8.2,30.61]],"batl":[[0,9.2,100.95],[1,10.5,3.3],[2,11,11.28]],"ltp":9.2,"tv":935.88,"id":10616006}],"tv":5516.91}]}
{"op":"mcm","clk":"994560630","pt":1580552512404,"mc":[{"id":"1.168133548","rc":[{"trd":[[9.2,111.88]],"batb":[[1,8.6,7.44],[2,8.4,6.56]],"batl":[[0,9.2,66.3]],"ltp":9.2,"tv":1005.18,"id":10616006}],"tv":5586.21}]}
{"op":"mcm","clk":"994560829","pt":1580552513521,"mc":[{"id":"1.168133548","rc":[{"batb":[[1,8.4,6.56],[2,8.2,30.61]],"batl":[[1,10,14.7],[2,10.5,10.64]],"ltp":9.2,"tv":1005.18,"id":10616006}]}]}
{"op":"mcm","clk":"994561191","pt":1580552515535,"mc":[{"id":"1.168133548","rc":[{"batb":[[0,11,5.52],[1,10.5,7.43],[2,10,2]],"ltp":11.5,"tv":537.58,"id":8429550},{"batb":[[0,5.6,10.58],[1,5.5,26.8],[2,5.3,19.46]],"ltp":5.6,"tv":1332.94,"id":9417341},{"trd":[[5.8,184.81]],"batb":[[0,5.8,3.15],[1,5.7,12],[2,5.6,7.76]],"batl":[[0,6,2],[1,6.2,11.85],[2,7,39.82]],"ltp":5.8,"tv":477.55,"id":8231803},{"batb":[[1,8.8,6.73],[2,8.4,6.56]],"batl":[[1,10,22.04]],"ltp":9.2,"tv":1005.18,"id":10616006},{"batb":[[1,7.4,13.01]],"ltp":7.6,"tv":1018.32,"id":10170404},{"batb":[[0,8.6,6.89],[1,8.4,2.03],[2,8.2,14.07]],"ltp":8.4,"tv":485.98,"id":15608820},{"batb":[[0,38,2.46],[1,36,7.02],[2,34,5.29]],"ltp":38.0,"tv":57.1,"id":9193530},{"batb":[[0,29,3.92]],"ltp":42.0,"tv":86.68,"id":9001159},{"batb":[[0,5.8,10.22],[1,5.7,4],[2,5.3,2.76]],"ltp":5.7,"tv":598.99,"id":17352128}],"tv":5600.35}]}
{"op":"mcm","clk":"994561402","pt":1580552516498,"mc":[{"id":"1.168133548","rc":[{"batb":[[0,11,6.67]],"ltp":11.5,"tv":537.58,"id":8429550},{"batb":[[0,5.6,12.83],[2,5.3,9.62]],"ltp":5.6,"tv":1332.94,"id":9417341},{"batb":[[0,5.8,5.32]],"batl":[[2,6.8,2.19]],"ltp":5.8,"tv":477.55,"id":8231803},{"trd":[[8.4,37.84],[8.8,15.31],[9,40.78]],"batb":[[0,8.2,30.61],[1,8,3],[2,7.6,15.87]],"batl":[[0,8.4,34.4],[1,9.8,4],[2,10,29.05]],"ltp":8.4,"tv":1068.98,"id":10616006},{"batb":[[0,7.6,8.39]],"ltp":7.6,"tv":1018.32,"id":10170404},{"batb":[[0,8.6,8.35]],"ltp":8.4,"tv":485.98,"id":15608820},{"batb":[[0,29,4.35]],"ltp":42.0,"tv":86.68,"id":9001159},{"batb":[[0,5.8,12.39]],"ltp":5.7,"tv":598.99,"id":17352128}],"tv":5664.16}]}
{"op":"mcm","clk":"994561770","pt":1580552518528,"mc":[{"id":"1.168133548","rc":[{"trd":[[8.4,73.5]],"batl":[[0,8.4,16.56],[1,9.6,14.42],[2,9.8,11.74]],"ltp":8.4,"tv":1104.65,"id":10616006}],"tv":5699.82}]}
{"op":"mcm","clk":"994561951","pt":1580552519502,"mc":[{"id":"1.168133548","rc":[{"trd":[[8.4,88.44]],"batb":[[0,7.6,16.48],[1,6.6,38],[2,6,8.65]],"batl":[[0,8.4,9.09],[1,9.6,22.16]],"ltp":8.4,"tv":1119.59,"id":10616006}],"tv":5714.76}]}
{"op":"mcm","clk":"994562007","pt":1580552519826,"mc":[{"id":"1.168133548","rc":[{"batb":[[1,7.4,3],[2,6.6,38]],"ltp":8.4,"tv":1119.59,"id":10616006}]}]}
{"op":"mcm","clk":"994562362","pt":1580552521524,"mc":[{"id":"1.168133548","rc":[{"trd":[[11.5,51.51]],"batl":[[0,11.5,4.19]],"ltp":11.5,"tv":538.59,"id":8429550},{"trd":[[5.8,361.57]],"batl":[[0,5.9,19.82],[1,6,79.79],[2,6.2,42.16]],"ltp":5.8,"tv":1334.94,"id":9417341},{"trd":[[6,66.39]],"batl":[[0,6.2,11.85],[1,6.8,2.19],[2,7,3.82]],"ltp":6.0,"tv":479.62,"id":8231803},{"trd":[[8,1.45],[8.2,1.22]],"batb":[[0,7.6,21.13],[2,7.2,1.62]],"batl":[[0,8,7.03],[1,9.4,6.53],[2,9.6,6.68]],"ltp":8.0,"tv":1122.26,"id":10616006},{"trd":[[7.8,54.29]],"batl":[[0,7.8,12.3]],"ltp":7.8,"tv":1019.81,"id":10170404},{"trd":[[9.2,24.95]],"batb":[[1,8.4,5.39]],"batl":[[0,9.2,2.74]],"ltp":9.2,"tv":487.24,"id":15608820},{"trd":[[60,0.19]],"batl":[[0,65,3.51]],"ltp":60.0,"tv":57.3,"id":9193530},{"trd":[[34,0.34]],"batl":[[0,42,2.46]],"ltp":34.0,"tv":87.02,"id":9001159},{"trd":[[6,115.37]],"batl":[[0,6,8.37]],"ltp":6.0,"tv":600.92,"id":17352128}],"tv":5727.72}]}
{"op":"mcm","clk":"994562529","pt":1580552522544,"mc":[{"id":"1.168133548","rc":[{"trd":[[8,15.51]],"batb":[[0,8,7.31],[1,7.6,21.13],[2,7.4,3]],"batl":[[0,9.6,6.68],[1,10,29.05],[2,10.5,3.3]],"ltp":8.0,"tv":1136.32,"id":10616006}],"tv":5741.78}]}
{"op":"mcm","clk":"994562723","pt":1580552523507,"mc":[{"id":"1.168133548","rc":[{"batb":[[0,8.4,8.71],[1,8,12.31],[2,7.6,21.13]],"batl":[[0,9.4,6.53],[1,9.6,6.68],[2,10,29.05]],"ltp":8.0,"tv":1136.32,"id":10616006}]}]}
{"op":"mcm","clk":"994562871","pt":1580552524530,"mc":[{"id":"1.168133548","rc":[{"batl":[[0,5.9,14]],"ltp":5.8,"tv":1334.94,"id":9417341},{"batl":[[1,6.8,9.73]],"ltp":6.0,"tv":479.62,"id":8231803},{"batl":[[1,10,7.34],[2,10.5,3.3]],"ltp":8.0,"tv":1136.32,"id":10616006}]}]}
{"op":"mcm","clk":"994563023","pt":1580552525559,"mc":[{"id":"1.168133548","rc":[{"batl":[[1,6.6,1.94],[2,6.8,9.73]],"ltp":6.0,"tv":479.62,"id":8231803},{"batl":[[1,10,3.67]],"ltp":8.0,"tv":1136.32,"id":10616006},{"batb":[[1,34,5.78],[2,30,4.04]],"batl":[[0,60,5.01],[1,65,3.03],[2,70,7.6]],"ltp":60.0,"tv":57.3,"id":9193530},{"batb":[[1,27,10.61],[2,26,3.21]],"ltp":34.0,"tv":87.02,"id":9001159}]}]}
{"op":"mcm","clk":"994563176","pt":1580552526341,"mc":[{"id":"1.168133548","rc":[{"trd":[[6.2,72.48]],"batl":[[0,6.2,3.05]],"ltp":6.2,"tv":497.22,"id":8231803},{"trd":[[9.4,14.36]],"batb":[[0,8.6,5.32],[1,8.4,8.71],[2,8,12.31]],"batl":[[0,10,3.67],[1,10.5,3.3],[2,11,10.3]],"ltp":9.4,"tv":1145.96,"id":10616006}],"tv":5769.03}]}
{"op":"mcm","clk":"994563372","pt":1580552527531,"mc":[{"id":"1.168133548","rc":[{"batl":[[2,6.8,18.92]],"ltp":6.2,"tv":497.22,"id":8231803},{"batl":[[1,10.5,7.78]],"ltp":9.4,"tv":1145.96,"id":10616006},{"batb":[[1,34,9.06]],"ltp":60.0,"tv":57.3,"id":9193530},{"batb":[[1,27,13.82]],"ltp":34.0,"tv":87.02,"id":9001159}]}]}
{"op":"mcm","clk":"994563490","pt":1580552528337,"mc":[{"id":"1.168133548","rc":[{"batb":[[1,5.5,28.8]],"ltp":5.8,"tv":1334.94,"id":9417341},{"trd":[[8.6,10]],"batb":[[0,8.4,9.03],[1,8,15.31],[2,7.6,21.13]],"ltp":8.6,"tv":1155.96,"id":10616006}],"tv":5779.03}]}
{"op":"mcm","clk":"994563906","pt":1580552530919,"mc":[{"id":"1.168133548","rc":[{"batl":[[0,9.8,2],[1,10,3.67],[2,10.5,7.78]],"ltp":8.6,"tv":1155.96,"id":10616006}]}]}
{"op":"mcm","clk":"994564110","pt":1580552532020,"mc":[{"id":"1.168133548","rc":[{"batl":[[2,6.8,2.19]],"ltp":6.2,"tv":497.22,"id":8231803},{"batl":[[1,10.5,3.3],[2,11,10.3]],"ltp":8.6,"tv":1155.96,"id":10616006}]}]}
{"op":"mcm","clk":"994564599","pt":1580552534512,"mc":[{"id":"1.168133548","rc":[{"batb":[[0,8,15.63],[1,7.6,21.13],[2,6.6,38]],"ltp":8.6,"tv":1155.96,"id":10616006}]}]}
{"op":"mcm","clk":"994564665","pt":1580552534890,"mc":[{"id":"1.168133548","rc":[{"batl":[[2,7,2]],"ltp":6.2,"tv":497.22,"id":8231803},{"batb":[[1,7.6,24.15]],"ltp":8.6,"tv":1155.96,"id":10616006}]}]}
{"op":"mcm","clk":"994565209","pt":1580552538131,"mc":[{"id":"1.168133548","rc":[{"batb":[[1,7.6,21.13]],"ltp":8.6,"tv":1155.96,"id":10616006}]}]}
{"op":"mcm","clk":"994565464","pt":1580552539523,"mc":[{"id":"1.168133548","rc":[{"batb":[[0,8,12.63],[2,7.4,3]],"ltp":8.6,"tv":1155.96,"id":10616006}]}]}
{"op":"mcm","clk":"994566953","pt":1580552547433,"mc":[{"id":"1.168133548","rc":[{"batb":[[0,8.2,1.86],[1,8,12.31],[2,7.6,21.13]],"ltp":8.6,"tv":1155.96,"id":10616006}]}]}
{"op":"mcm","clk":"994567328","pt":1580552549511,"mc":[{"id":"1.168133548","rc":[{"batl":[[1,7,2],[2,7.6,9.1]],"ltp":6.2,"tv":497.22,"id":8231803}]}]}
{"op":"mcm","clk":"994567530","pt":1580552550528,"mc":[{"id":"1.168133548","rc":[{"batl":[[1,6.8,1.75],[2,7,2]],"ltp":6.2,"tv":497.22,"id":8231803},{"batb":[[0,8.2,3.8]],"batl":[[1,10,5.6],[2,10.5,3.3]],"ltp":8.6,"tv":1155.96,"id":10616006},{"batl":[[1,70,7.6],[2,140,2]],"ltp":60.0,"tv":57.3,"id":9193530}]}]}
{"op":"mcm","clk":"994567585","pt":1580552550844,"mc":[{"id":"1.168133548","rc":[{"batl":[[0,55,3.12],[1,60,5.01],[2,70,7.6]],"ltp":60.0,"tv":57.3,"id":9193530}]}]}
{"op":"mcm","clk":"994579398","pt":1580552558470,"mc":[{"id":"1.168133548","rc":[{"batb":[[0,5.9,3.39],[1,5.8,5.32],[2,5.7,12]],"ltp":6.2,"tv":497.22,"id":8231803},{"batl":[[0,9.6,2],[1,9.8,2],[2,10,5.6]],"ltp":8.6,"tv":1155.96,"id":10616006}]}]}
{"op":"mcm","clk":"994580292","pt":1580552563482,"mc":[{"id":"1.168133548","rc":[{"batl":[[1,70,8.08],[2,140,2]],"ltp":60.0,"tv":57.3,"id":9193530}]}]}
{"op":"mcm","clk":"994580445","pt":1580552564276,"mc":[{"id":"1.168133548","rc":[{"batl":[[0,50,5.42],[1,55,3.12],[2,70,8.08]],"ltp":60.0,"tv":57.3,"id":9193530}]}]}
{"op":"mcm","clk":"994580611","pt":1580552565385,"mc":[{"id":"1.168133548","rc":[{"batl":[[0,6,79.79],[1,6.2,42.16],[2,6.4,25]],"ltp":5.8,"tv":1334.94,"id":9417341},{"batl":[[2,70,7.6]],"ltp":60.0,"tv":57.3,"id":9193530}]}]}
{"op":"mcm","clk":"994580804","pt":1580552566469,"mc":[{"id":"1.168133548","rc":[{"batl":[[1,6.2,46.42]],"ltp":5.8,"tv":1334.94,"id":9417341},{"trd":[[8.2,4.57],[8.6,10.64]],"batb":[[0,8.2,1.8]],"ltp":8.2,"tv":1159.95,"id":10616006}],"tv":5783.02}]}
{"op":"mcm","clk":"994581179","pt":1580552568511,"mc":[{"id":"1.168133548","rc":[{"trd":[[5.8,50.74]],"batb":[[0,5.8,2.39]],"ltp":5.8,"tv":620.92,"id":17352128}],"tv":5803.02}]}
{"op":"mcm","clk":"994581372","pt":1580552569480,"mc":[{"id":"1.168133548","rc":[{"batl":[[1,6.2,67.15]],"ltp":5.8,"tv":1334.94,"id":9417341},{"batb":[[0,5.8,7.39],[2,5.3,7.76]],"ltp":5.8,"tv":620.92,"id":17352128}]}]}
{"op":"mcm","clk":"994581535","pt":1580552570381,"mc":[{"id":"1.168133548","rc":[{"batb":[[0,5.8,12.39],[2,5.3,12.76]],"ltp":5.8,"tv":620.92,"id":17352128}]}]}
{"op":"mcm","clk":"994581726","pt":1580552571493,"mc":[{"id":"1.168133548","rc":[{"batb":[[1,5.7,9]],"ltp":5.8,"tv":620.92,"id":17352128}]}]}
{"op":"mcm","clk":"994582282","pt":1580552574487,"mc":[{"id":"1.168133548","rc":[{"batb":[[0,7.6,13.39]],"ltp":7.8,"tv":1019.81,"id":10170404}]}]}
{"op":"mcm","clk":"994582445","pt":1580552575399,"mc":[{"id":"1.168133548","rc":[{"batb":[[2,7.2,21]],"ltp":7.8,"tv":1019.81,"id":10170404}]}]}
{"op":"mcm","clk":"994582628","pt":1580552576530,"mc":[{"id":"1.168133548","rc":[{"trd":[[9.6,72.21],[9.8,75.67],[10,277.44],[10.5,178.9],[11,90.75]],"batl":[[0,10.5,2.03],[1,11,7.58],[2,11.5,17.73]],"ltp":10.5,"tv":1199.41,"id":10616006}],"tv":5842.48}]}
{"op":"mcm","clk":"994582975","pt":1580552578506,"mc":[{"id":"1.168133548","rc":[{"batl":[[2,11.5,10.44]],"ltp":10.5,"tv":1199.41,"id":10616006}]}]}
{"op":"mcm","clk":"994583147","pt":1580552579513,"mc":[{"id":"1.168133548","rc":[{"batb":[[0,8.4,9.76],[1,8.2,1.8],[2,8,12.31]],"ltp":10.5,"tv":1199.41,"id":10616006}]}]}
{"op":"mcm","clk":"994583484","pt":1580552581293,"mc":[{"id":"1.168133548","rc":[{"trd":[[7.6,111.24]],"batb":[[0,7.6,9.39]],"ltp":7.6,"tv":1027.81,"id":10170404}],"tv":5850.48}]}
{"op":"mcm","clk":"994583712","pt":1580552582520,"mc":[{"id":"1.168133548","rc":[{"batb":[[0,8.4,11.26]],"batl":[[0,10,2.02],[1,10.5,30.15],[2,11,7.58]],"ltp":10.5,"tv":1199.41,"id":10616006},{"batb":[[0,38,1.59]],"ltp":60.0,"tv":57.3,"id":9193530}]}]}
{"op":"mcm","clk":"994583897","pt":1580552583426,"mc":[{"id":"1.168133548","rc":[{"batb":[[1,36,1.41],[2,34,8.58]],"ltp":60.0,"tv":57.3,"id":9193530}]}]}
{"op":"mcm","clk":"994584081","pt":1580552584433,"mc":[{"id":"1.168133548","rc":[{"batb":[[1,8.2,3.8]],"ltp":10.5,"tv":1199.41,"id":10616006}]}]}
{"op":"mcm","clk":"994584639","pt":1580552587545,"mc":[{"id":"1.168133548","rc":[{"batb":[[0,8.6,4.32],[1,8.4,11.26],[2,8.2,3.8]],"ltp":10.5,"tv":1199.41,"id":10616006}]}]}
{"op":"mcm","clk":"994587608","pt":1580552603562,"mc":[{"id":"1.168133548","rc":[{"batb":[[0,5.9,10],[1,5.8,12.39],[2,5.7,9]],"ltp":5.8,"tv":620.92,"id":17352128}]}]}
{"op":"mcm","clk":"994587699","pt":1580552604046,"mc":[{"id":"1.168133548","rc":[{"batb":[[0,5.9,5.39],[2,5.7,10]],"ltp":6.2,"tv":497.22,"id":8231803}]}]}
{"op":"mcm","clk":"994588555","pt":1580552608572,"mc":[{"id":"1.168133548","rc":[{"batl":[[1,7,3.7],[2,7.2,6.78]],"ltp":6.2,"tv":497.22,"id":8231803},{"batb":[[0,8.8,3.89],[1,8.6,4.32],[2,8.4,11.26]],"ltp":10.5,"tv":1199.41,"id":10616006}]}]}
{"op":"mcm","clk":"994588682","pt":1580552609278,"mc":[{"id":"1.168133548","rc":[{"batb":[[1,8.4,11.26],[2,8.2,3.8]],"ltp":10.5,"tv":1199.41,"id":10616006},{"batl":[[0,48,3.03],[1,50,5.42],[2,70,7.69]],"ltp":60.0,"tv":57.3,"id":9193530}]}]}
{"op":"mcm","clk":"994588768","pt":1580552609786,"mc":[{"id":"1.168133548","rc":[{"batl":[[2,140,2.09]],"ltp":60.0,"tv":57.3,"id":9193530}]}]}
{"op":"mcm","clk":"994589043","pt":1580552611386,"mc":[{"id":"1.168133548","rc":[{"batb":[[0,9,2.13],[1,8.8,3.89],[2,8.4,11.26]],"ltp":10.5,"tv":1199.41,"id":10616006}]}]}
{"op":"mcm","clk":"994589213","pt":1580552612492,"mc":[{"id":"1.168133548","rc":[{"batl":[[1,7,6.72]],"ltp":6.2,"tv":497.22,"id":8231803}]}]}
{"op":"mcm","clk":"994589835","pt":1580552616007,"mc":[{"id":"1.168133548","rc":[{"batb":[[2,8.4,9.76]],"ltp":10.5,"tv":1199.41,"id":10616006}]}]}
{"op":"mcm","clk":"994590150","pt":1580552617908,"mc":[{"id":"1.168133548","rc":[{"batb":[[1,36,1.89]],"ltp":60.0,"tv":57.3,"id":9193530}]}]}
{"op":"mcm","clk":"994590573","pt":1580552620510,"mc":[{"id":"1.168133548","rc":[{"batl":[[1,140,2.09],[2,220,9]],"ltp":60.0,"tv":57.3,"id":9193530}]}]}
{"op":"mcm","clk":"994594141","pt":1580552640212,"mc":[{"id":"1.168133548","rc":[{"batl":[[1,220,9.09],[2,340,2.16]],"ltp":60.0,"tv":57.3,"id":9193530}]}]}
{"op":"mcm","clk":"994595123","pt":1580552645565,"mc":[{"id":"1.168133548","rc":[{"batb":[[0,8.8,1.96],[1,8.6,8.35],[2,8.4,3.36]],"ltp":9.2,"tv":487.24,"id":15608820}]}]}
{"op":"mcm","clk":"994595248","pt":1580552646262,"mc":[{"id":"1.168133548","rc":[{"batb":[[2,8.2,14.07]],"ltp":9.2,"tv":487.24,"id":15608820}]}]}
{"op":"mcm","clk":"994597303","pt":1580552657382,"mc":[{"id":"1.168133548","rc":[{"batb":[[1,8.6,3.89]],"ltp":10.5,"tv":1199.41,"id":10616006}]}]}
{"op":"mcm","clk":"994598788","pt":1580552665476,"mc":[{"id":"1.168133548","rc":[{"batb":[[0,8.6,3.89],[1,8.4,9.76],[2,8.2,2]],"ltp":10.5,"tv":1199.41,"id":10616006},{"batb":[[2,8.2,16.49]],"ltp":9.2,"tv":487.24,"id":15608820}]}]}
{"op":"mcm","clk":"994598960","pt":1580552666487,"mc":[{"id":"1.168133548","rc":[{"batb":[[0,8.8,2.18],[1,8.6,3.89],[2,8.4,9.76]],"ltp":10.5,"tv":1199.41,"id":10616006}]}]}
{"op":"mcm","clk":"994599596","pt":1580552669903,"mc":[{"id":"1.168133548","rc":[{"batl":[[2,590,2.16]],"ltp":60.0,"tv":57.3,"id":9193530}]}]}
{"op":"mcm","clk":"994600390","pt":1580552674498,"mc":[{"id":"1.168133548","rc":[{"trd":[[6.2,78.58]],"batb":[[0,6.2,1.95],[1,5.9,5.39],[2,5.8,5.32]],"batl":[[0,7,6.72],[1,7.2,6.78],[2,7.6,9.1]],"ltp":6.2,"tv":503.32,"id":8231803}],"tv":5856.58}]}
{"op":"mcm","clk":"994600582","pt":1580552675516,"mc":[{"id":"1.168133548","rc":[{"batl":[[0,7,3.7],[1,7.6,9.1],[2,8,2]],"ltp":6.2,"tv":503.32,"id":8231803},{"batb":[[0,8.8,6.4]],"ltp":10.5,"tv":1199.41,"id":10616006}]}]}
{"op":"mcm","clk":"994601071","pt":1580552678538,"mc":[{"id":"1.168133548","rc":[{"batl":[[1,8,2],[2,8.2,32.5]],"ltp":6.2,"tv":503.32,"id":8231803}]}]}
{"op":"mcm","clk":"994601244","pt":1580552679540,"mc":[{"id":"1.168133548","rc":[{"batl":[[0,6.8,37.24],[1,7,3.7],[2,8,2]],"ltp":6.2,"tv":503.32,"id":8231803}]}]}
{"op":"mcm","clk":"994601366","pt":1580552680215,"mc":[{"id":"1.168133548","rc":[{"batl":[[0,6.6,7.3],[1,6.8,37.24],[2,7,3.7]],"ltp":6.2,"tv":503.32,"id":8231803}]}]}
{"op":"mcm","clk":"994603735","pt":1580552694543,"mc":[{"id":"1.168133548","rc":[{"batl":[[0,6.4,2.48],[1,6.6,7.3],[2,6.8,37.24]],"ltp":6.2,"tv":503.32,"id":8231803}]}]}
{"op":"mcm","clk":"994604534","pt":1580552698387,"mc":[{"id":"1.168133548","rc":[{"batl":[[2,7,3.7]],"ltp":6.2,"tv":503.32,"id":8231803}]}]}
{"op":"mcm","clk":"994604919","pt":1580552700479,"mc":[{"id":"1.168133548","rc":[{"batl":[[2,840,2.16]],"ltp":60.0,"tv":57.3,"id":9193530}]}]}
{"op":"mcm","clk":"994608392","pt":1580552719517,"mc":[{"id":"1.168133548","rc":[{"batb":[[1,5.9,2]],"ltp":6.2,"tv":503.32,"id":8231803}]}]}
{"op":"mcm","clk":"994608767","pt":1580552721541,"mc":[{"id":"1.168133548","rc":[{"batb":[[0,9,3.03],[1,8.8,6.4]],"ltp":10.5,"tv":1199.41,"id":10616006}]}]}
{"op":"mcm","clk":"994610172","pt":1580552730421,"mc":[{"id":"1.168133548","rc":[{"batb":[[1,5.9,8.78]],"ltp":6.2,"tv":503.32,"id":8231803},{"batl":[[2,990,1.2]],"ltp":60.0,"tv":57.3,"id":9193530}]}]}
{"op":"mcm","clk":"994610329","pt":1580552731421,"mc":[{"id":"1.168133548","rc":[{"batb":[[0,11,10.31]],"ltp":11.5,"tv":538.59,"id":8429550},{"batb":[[0,5.6,19.97]],"ltp":5.8,"tv":1334.94,"id":9417341},{"batb":[[0,7.6,14.65]],"ltp":7.6,"tv":1027.81,"id":10170404},{"batb":[[1,8.6,13]],"ltp":9.2,"tv":487.24,"id":15608820},{"batb":[[0,5.9,16.78]],"ltp":5.8,"tv":620.92,"id":17352128}]}]}
{"op":"mcm","clk":"994610505","pt":1580552732503,"mc":[{"id":"1.168133548","rc":[{"batb":[[0,9,7.47]],"ltp":10.5,"tv":1199.41,"id":10616006},{"batb":[[2,34,9.76]],"ltp":60.0,"tv":57.3,"id":9193530},{"batb":[[0,29,5.73]],"ltp":34.0,"tv":87.02,"id":9001159}]}]}
{"op":"mcm","clk":"994611882","pt":1580552740233,"mc":[{"id":"1.168133548","rc":[{"batl":[[0,6.6,7.3],[1,7,3.7],[2,8,33]],"ltp":6.2,"tv":503.32,"id":8231803},{"batb":[[1,8.8,2.18]],"ltp":10.5,"tv":1199.41,"id":10616006}]}]}
{"op":"mcm","clk":"994612590","pt":1580552744320,"mc":[{"id":"1.168133548","rc":[{"batb":[[1,36,3.89]],"ltp":60.0,"tv":57.3,"id":9193530}]}]}
{"op":"mcm","clk":"994613168","pt":1580552747527,"mc":[{"id":"1.168133548","rc":[{"batb":[[1,6,5],[2,5.9,8.78]],"batl":[[0,7,3.7],[1,8,33],[2,8.2,2.5]],"ltp":6.2,"tv":503.32,"id":8231803}]}]}
{"op":"mcm","clk":"994613332","pt":1580552748545,"mc":[{"id":"1.168133548","rc":[{"batl":[[1,7.2,6.46],[2,8,33]],"ltp":6.2,"tv":503.32,"id":8231803}]}]}
{"op":"mcm","clk":"994613472","pt":1580552749359,"mc":[{"id":"1.168133548","rc":[{"batl":[[1,8,33],[2,8.2,2.5]],"ltp":6.2,"tv":503.32,"id":8231803}]}]}
{"op":"mcm","clk":"994614782","pt":1580552756473,"mc":[{"id":"1.168133548","rc":[{"batl":[[0,5.9,42.93],[1,6,79.79],[2,6.2,67.15]],"ltp":5.8,"tv":1334.94,"id":9417341},{"batl":[[0,6.8,37.24],[1,7,3.7],[2,8,33]],"ltp":6.2,"tv":503.32,"id":8231803}]}]}
{"op":"mcm","clk":"994615141","pt":1580552758568,"mc":[{"id":"1.168133548","rc":[{"batl":[[2,6.2,42.16]],"ltp":5.8,"tv":1334.94,"id":9417341}]}]}
{"op":"mcm","clk":"994615498","pt":1580552760546,"mc":[{"id":"1.168133548","rc":[{"batl":[[2,8,2]],"ltp":6.2,"tv":503.32,"id":8231803}]}]}
{"op":"mcm","clk":"994615969","pt":1580552763430,"mc":[{"id":"1.168133548","rc":[{"batl":[[0,5.9,43.43]],"ltp":5.8,"tv":1334.94,"id":9417341}]}]}
{"op":"mcm","clk":"994617843","pt":1580552773538,"mc":[{"id":"1.168133548","rc":[{"batb":[[0,9.2,2.09],[1,9,7.47]],"ltp":10.5,"tv":1199.41,"id":10616006}]}]}
{"op":"mcm","clk":"994623088","pt":1580552804517,"mc":[{"id":"1.168133548","rc":[{"batl":[[1,7,2]],"ltp":6.2,"tv":503.32,"id":8231803}]}]}
{"op":"mcm","clk":"994623264","pt":1580552805385,"mc":[{"id":"1.168133548","rc":[{"batl":[[0,6.6,1.94],[1,6.8,37.24],[2,7,2]],"ltp":6.2,"tv":503.32,"id":8231803}]}]}
{"op":"mcm","clk":"994624723","pt":1580552814405,"mc":[{"id":"1.168133548","rc":[{"trd":[[7.6,115.24]],"batb":[[0,7.6,12.65]],"ltp":7.6,"tv":1031.81,"id":10170404}],"tv":5860.58}]}
{"op":"mcm","clk":"994624925","pt":1580552815310,"mc":[{"id":"1.168133548","rc":[{"batl":[[0,6.6,2.82]],"ltp":6.2,"tv":503.32,"id":8231803}]}]}
{"op":"mcm","clk":"994625123","pt":1580552816439,"mc":[{"id":"1.168133548","rc":[{"batl":[[0,6.6,1.94]],"ltp":6.2,"tv":503.32,"id":8231803}]}]}
{"op":"mcm","clk":"994625646","pt":1580552819521,"mc":[{"id":"1.168133548","rc":[{"trd":[[11,55]],"batb":[[0,11,8.31]],"ltp":11.0,"tv":542.59,"id":8429550}],"tv":5864.57}]}
{"op":"mcm","clk":"994633758","pt":1580552867483,"mc":[{"id":"1.168133548","rc":[{"batl":[[0,6.8,37.24],[1,7,2],[2,7.8,1.64]],"ltp":6.2,"tv":503.32,"id":8231803}]}]}
{"op":"mcm","clk":"994635514","pt":1580552877187,"mc":[{"id":"1.168133548","rc":[{"batl":[[1,10.5,32.15]],"ltp":10.5,"tv":1199.41,"id":10616006}]}]}
{"op":"mcm","clk":"994637882","pt":1580552890335,"mc":[{"id":"1.168133548","rc":[{"trd":[[9.2,121.88]],"batb":[[0,9.2,1.92],[2,8.4,14.57]],"batl":[[0,10.5,32.15],[1,11,7.58],[2,11.5,10.44]],"ltp":9.2,"tv":1209.41,"id":10616006}],"tv":5874.57}]}
{"op":"mcm","clk":"994638276","pt":1580552892526,"mc":[{"id":"1.168133548","rc":[{"batl":[[0,10,2.24],[1,10.5,32.15],[2,11,11.02]],"ltp":9.2,"tv":1209.41,"id":10616006}]}]}
{"op":"mcm","clk":"994638429","pt":1580552893536,"mc":[{"id":"1.168133548","rc":[{"batl":[[1,10.5,2]],"ltp":9.2,"tv":1209.41,"id":10616006}]}]}
{"op":"mcm","clk":"994638507","pt":1580552894017,"mc":[{"id":"1.168133548","rc":[{"batl":[[0,10,33.9]],"ltp":9.2,"tv":1209.41,"id":10616006}]}]}
{"op":"mcm","clk":"994641148","pt":1580552908465,"mc":[{"id":"1.168133548","rc":[{"batl":[[0,10,31.66],[2,11,18.02]],"ltp":9.2,"tv":1209.41,"id":10616006}]}]}
{"op":"mcm","clk":"994641812","pt":1580552912551,"mc":[{"id":"1.168133548","rc":[{"batl":[[0,10.5,2],[1,11,18.02],[2,11.5,10.44]],"ltp":9.2,"tv":1209.41,"id":10616006}]}]}
{"op":"mcm","clk":"994641995","pt":1580552913561,"mc":[{"id":"1.168133548","rc":[{"batl":[[0,10.5,32.15],[2,11.5,17.25]],"ltp":9.2,"tv":1209.41,"id":10616006}]}]}
{"op":"mcm","clk":"994644958","pt":1580552931481,"mc":[{"id":"1.168133548","rc":[{"batl":[[0,10,1.59],[1,10.5,32.15],[2,11,18.02]],"ltp":9.2,"tv":1209.41,"id":10616006}]}]}
{"op":"mcm","clk":"994645635","pt":1580552935489,"mc":[{"id":"1.168133548","rc":[{"trd":[[5.9,41.62]],"batb":[[0,5.9,14.78]],"ltp":5.9,"tv":624.92,"id":17352128}],"tv":5878.57}]}
{"op":"mcm","clk":"994647023","pt":1580552943390,"mc":[{"id":"1.168133548","rc":[{"batl":[[2,11,7.58]],"ltp":9.2,"tv":1209.41,"id":10616006}]}]}
{"op":"mcm","clk":"994648266","pt":1580552950470,"mc":[{"id":"1.168133548","rc":[{"batl":[[0,10,33.25],[1,10.5,2]],"ltp":9.2,"tv":1209.41,"id":10616006}]}]}
{"op":"mcm","clk":"994649973","pt":1580552960525,"mc":[{"id":"1.168133548","rc":[{"batl":[[1,7,3]],"ltp":6.2,"tv":503.32,"id":8231803}]}]}
{"op":"mcm","clk":"994650814","pt":1580552965306,"mc":[{"id":"1.168133548","rc":[{"batl":[[0,6.6,1],[1,6.8,37.24],[2,7,2]],"ltp":6.2,"tv":503.32,"id":8231803}]}]}
{"op":"mcm","clk":"994651513","pt":1580552969515,"mc":[{"id":"1.168133548","rc":[{"batl":[[0,10,1.59]],"ltp":9.2,"tv":1209.41,"id":10616006}]}]}
{"op":"mcm","clk":"994651662","pt":1580552970424,"mc":[{"id":"1.168133548","rc":[{"trd":[[10,280.62]],"batl":[[0,10.5,32.15],[1,11,7.58],[2,11.5,10.44]],"ltp":10.0,"tv":1212.59,"id":10616006}],"tv":5881.75}]}
{"op":"mcm","clk":"994651950","pt":1580552972544,"mc":[{"id":"1.168133548","rc":[{"batb":[[0,9.2,3.92]],"ltp":10.0,"tv":1212.59,"id":10616006}]}]}
{"op":"mcm","clk":"994652973","pt":1580552978530,"mc":[{"id":"1.168133548","rc":[{"batb":[[2,8.4,17.57]],"ltp":10.0,"tv":1212.59,"id":10616006}]}]}
{"op":"mcm","clk":"994653110","pt":1580552979216,"mc":[{"id":"1.168133548","rc":[{"batl":[[0,10,1.59],[1,10.5,32.15],[2,11,7.58]],"ltp":10.0,"tv":1212.59,"id":10616006}]}]}
{"op":"mcm","clk":"994654710","pt":1580552988449,"mc":[{"id":"1.168133548","rc":[{"batl":[[1,10.5,2]],"ltp":10.0,"tv":1212.59,"id":10616006}]}]}
{"op":"mcm","clk":"994654906","pt":1580552989557,"mc":[{"id":"1.168133548","rc":[{"batb":[[0,9.4,1.92],[1,9.2,2],[2,9,7.47]],"batl":[[0,10,33.25]],"ltp":10.0,"tv":1212.59,"id":10616006}]}]}
{"op":"mcm","clk":"994655421","pt":1580552992563,"mc":[{"id":"1.168133548","rc":[{"batb":[[2,34,4.47]],"ltp":60.0,"tv":57.3,"id":9193530}]}]}
{"op":"mcm","clk":"994655896","pt":1580552995372,"mc":[{"id":"1.168133548","rc":[{"batb":[[0,40,2.05],[1,38,1.59],[2,36,3.89]],"ltp":60.0,"tv":57.3,"id":9193530}]}]}
{"op":"mcm","clk":"994656093","pt":1580552996441,"mc":[{"id":"1.168133548","rc":[{"batb":[[2,5.2,9.69]],"ltp":5.8,"tv":1334.94,"id":9417341},{"batl":[[2,11,18.59]],"ltp":10.0,"tv":1212.59,"id":10616006}]}]}
{"op":"mcm","clk":"994656828","pt":1580553000537,"mc":[{"id":"1.168133548","rc":[{"batl":[[2,390,2.16]],"ltp":34.0,"tv":87.02,"id":9001159}]}]}
{"op":"mcm","clk":"994658197","pt":1580553007523,"mc":[{"id":"1.168133548","rc":[{"trd":[[10,283.8]],"batl":[[0,10.5,32.15],[1,11,18.59],[2,11.5,10.44]],"ltp":10.0,"tv":1215.77,"id":10616006}],"tv":5884.93}]}
{"op":"mcm","clk":"994658278","pt":1580553008050,"mc":[{"id":"1.168133548","rc":[{"batl":[[2,11.5,17.45]],"ltp":10.0,"tv":1215.77,"id":10616006}]}]}
{"op":"mcm","clk":"994658553","pt":1580553009559,"mc":[{"id":"1.168133548","rc":[{"batl":[[1,11,7.58]],"ltp":10.0,"tv":1215.77,"id":10616006}]}]}
{"op":"mcm","clk":"994661424","pt":1580553026453,"mc":[{"id":"1.168133548","rc":[{"batl":[[0,10,1.59],[1,10.5,32.15],[2,11,7.58]],"ltp":10.0,"tv":1215.77,"id":10616006}]}]}
{"op":"mcm","clk":"994662556","pt":1580553033535,"mc":[{"id":"1.168133548","rc":[{"trd":[[11.5,59.89]],"batb":[[0,11,9.15]],"batl":[[0,12.5,54.17],[1,13.5,20.72],[2,16,16]],"ltp":11.5,"tv":550.97,"id":8429550}],"tv":5893.31}]}
{"op":"mcm","clk":"994662729","pt":1580553034546,"mc":[{"id":"1.168133548","rc":[{"batb":[[1,10.5,5.79]],"batl":[[1,13.5,25.06]],"ltp":11.5,"tv":550.97,"id":8429550}]}]}
{"op":"mcm","clk":"994662782","pt":1580553034954,"mc":[{"id":"1.168133548","rc":[{"batb":[[0,11.5,2.34],[1,11,8.31],[2,10.5,5.79]],"ltp":11.5,"tv":550.97,"id":8429550}]}]}
{"op":"mcm","clk":"994663413","pt":1580553038543,"mc":[{"id":"1.168133548","rc":[{"batl":[[0,5.8,14],[1,5.9,43.43],[2,6,79.79]],"ltp":5.8,"tv":1334.94,"id":9417341},{"batb":[[2,8.2,14.07]],"ltp":9.2,"tv":487.24,"id":15608820},{"batb":[[1,27,10.61]],"ltp":34.0,"tv":87.02,"id":9001159}]}]}
{"op":"mcm","clk":"994663558","pt":1580553039444,"mc":[{"id":"1.168133548","rc":[{"batl":[[1,13.5,29.43]],"ltp":11.5,"tv":550.97,"id":8429550}]}]}
{"op":"mcm","clk":"994664113","pt":1580553042566,"mc":[{"id":"1.168133548","rc":[{"trd":[[9.4,18.2]],"batb":[[0,9.2,2],[1,9,7.47],[2,8.4,12.76]],"batl":[[0,10,1.8]],"ltp":9.4,"tv":1219.61,"id":10616006}],"tv":5897.15}]}
{"op":"mcm","clk":"994664266","pt":1580553043473,"mc":[{"id":"1.168133548","rc":[{"batb":[[2,8.2,16.49]],"ltp":9.2,"tv":487.24,"id":15608820}]}]}
{"op":"mcm","clk":"994664610","pt":1580553045341,"mc":[{"id":"1.168133548","rc":[{"batl":[[1,6,80.29],[2,6.2,42.16]],"ltp":5.8,"tv":1334.94,"id":9417341},{"batl":[[1,7,2],[2,7.8,1.64]],"ltp":6.2,"tv":503.32,"id":8231803},{"batl":[[1,10.5,2]],"ltp":9.4,"tv":1219.61,"id":10616006}]}]}
{"op":"mcm","clk":"994665340","pt":1580553049366,"mc":[{"id":"1.168133548","rc":[{"batl":[[0,10.5,2.21],[1,11,7.58],[2,11.5,10.44]],"ltp":9.4,"tv":1219.61,"id":10616006}]}]}
{"op":"mcm","clk":"994665492","pt":1580553050570,"mc":[{"id":"1.168133548","rc":[{"batb":[[2,8.4,9.76]],"ltp":9.4,"tv":1219.61,"id":10616006}]}]}
{"op":"mcm","clk":"994665570","pt":1580553051167,"mc":[{"id":"1.168133548","rc":[{"batl":[[0,6,80.29],[1,6.2,42.16],[2,6.4,25]],"ltp":5.8,"tv":1334.94,"id":9417341}]}]}
{"op":"mcm","clk":"994665812","pt":1580553052564,"mc":[{"id":"1.168133548","rc":[{"batl":[[1,6.2,44.92]],"ltp":5.8,"tv":1334.94,"id":9417341}]}]}
{"op":"mcm","clk":"994666167","pt":1580553054485,"mc":[{"id":"1.168133548","rc":[{"batl":[[1,6.2,64.02]],"ltp":5.8,"tv":1334.94,"id":9417341}]}]}
{"op":"mcm","clk":"994667250","pt":1580553060500,"mc":[{"id":"1.168133548","rc":[{"batl":[[2,17,6.2]],"ltp":11.5,"tv":550.97,"id":8429550},{"batl":[[2,640,2.16]],"ltp":34.0,"tv":87.02,"id":9001159}]}]}
{"op":"mcm","clk":"994667939","pt":1580553064501,"mc":[{"id":"1.168133548","rc":[{"batl":[[2,7.8,4.31]],"ltp":6.2,"tv":503.32,"id":8231803}]}]}
{"op":"mcm","clk":"994668077","pt":1580553065414,"mc":[{"id":"1.168133548","rc":[{"batl":[[0,10.5,5.24]],"ltp":9.4,"tv":1219.61,"id":10616006}]}]}
{"op":"mcm","clk":"994672655","pt":1580553090529,"mc":[{"id":"1.168133548","rc":[{"trd":[[12.5,38.67]],"batb":[[0,11.5,1.5]],"batl":[[0,12.5,53.33]],"ltp":12.5,"tv":552.65,"id":8429550}],"tv":5898.83}]}
{"op":"mcm","clk":"994672839","pt":1580553091540,"mc":[{"id":"1.168133548","rc":[{"batl":[[2,890,2.16]],"ltp":34.0,"tv":87.02,"id":9001159}]}]}
{"op":"mcm","clk":"994673716","pt":1580553096569,"mc":[{"id":"1.168133548","rc":[{"batb":[[0,6.2,5.18]],"ltp":6.2,"tv":503.32,"id":8231803}]}]}
{"op":"mcm","clk":"994673869","pt":1580553097473,"mc":[{"id":"1.168133548","rc":[{"trd":[[6,66.41],[6.2,88.94]],"batb":[[0,6,11.23],[1,5.9,8.78],[2,5.8,10.69]],"ltp":6.0,"tv":513.69,"id":8231803},{"batl":[[0,10,2.21],[1,10.5,5.03],[2,11,7.58]],"ltp":9.4,"tv":1219.61,"id":10616006}],"tv":5909.21}]}
{"op":"mcm","clk":"994674020","pt":1580553098467,"mc":[{"id":"1.168133548","rc":[{"trd":[[11.5,60.11]],"batb":[[0,11.5,1.28]],"ltp":11.5,"tv":552.86,"id":8429550},{"trd":[[5.6,6.39]],"batb":[[0,5.6,19.51]],"ltp":5.6,"tv":1335.39,"id":9417341},{"trd":[[6.6,25.51]],"batb":[[0,6.6,1.39],[1,6,11.23],[2,5.9,8.78]],"batl":[[0,7,2],[1,7.8,4.31],[2,8,2]],"ltp":6.6,"tv":516.08,"id":8231803},{"trd":[[9.2,122.16]],"batb":[[0,9.2,1.72],[2,8.4,14.65]],"ltp":9.2,"tv":1219.89,"id":10616006},{"trd":[[7.6,115.58]],"batb":[[0,7.6,12.31]],"ltp":7.6,"tv":1032.15,"id":10170404},{"trd":[[8.8,37.21]],"batb":[[0,8.8,1.66]],"ltp":8.8,"tv":487.53,"id":15608820},{"trd":[[40,4.04]],"batb":[[0,38,1.59],[1,36,3.89],[2,34,4.47]],"batl":[[0,46,1.78],[1,48,3.03],[2,220,9.09]],"ltp":40.0,"tv":61.34,"id":9193530},{"trd":[[29,0.09]],"batb":[[0,29,5.64],[1,27,14.44]],"ltp":29.0,"tv":87.11,"id":9001159},{"trd":[[5.9,42.05]],"batb":[[0,5.9,14.35]],"ltp":5.9,"tv":625.35,"id":17352128}],"tv":5917.74}]}
{"op":"mcm","clk":"994674210","pt":1580553099529,"mc":[{"id":"1.168133548","rc":[{"trd":[[6.6,28.29]],"batb":[[0,6,11.23],[1,5.9,8.78],[2,5.8,10.69]],"ltp":6.6,"tv":518.85,"id":8231803},{"batb":[[2,8.4,6.39]],"ltp":8.8,"tv":487.53,"id":15608820},{"batb":[[2,34,1.18]],"ltp":40.0,"tv":61.34,"id":9193530}],"tv":5920.52}]}
{"op":"mcm","clk":"994674543","pt":1580553101527,"mc":[{"id":"1.168133548","rc":[{"batb":[[1,36,3.4]],"ltp":40.0,"tv":61.34,"id":9193530}]}]}
{"op":"mcm","clk":"994674694","pt":1580553102531,"mc":[{"id":"1.168133548","rc":[{"batl":[[0,7.8,9.45]],"ltp":7.6,"tv":1032.15,"id":10170404}]}]}
{"op":"mcm","clk":"994674859","pt":1580553103542,"mc":[{"id":"1.168133548","rc":[{"batl":[[0,5.9,43.43],[1,6,79.79],[2,6.2,64.02]],"ltp":5.6,"tv":1335.39,"id":9417341},{"batl":[[0,6.6,7.3],[1,6.8,37.24],[2,7,2]],"ltp":6.6,"tv":518.85,"id":8231803},{"batl":[[0,10,33.87]],"ltp":9.2,"tv":1219.89,"id":10616006},{"trd":[[7.6,140.18]],"batb":[[0,7.4,13.01],[1,7.2,21],[2,7,28.71]],"batl":[[0,7.6,37.69],[1,7.8,9.45],[2,8,23.38]],"ltp":7.6,"tv":1056.75,"id":10170404},{"trd":[[5.9,70.74]],"batb":[[0,5.8,12.39],[1,5.7,9],[2,5.3,10]],"batl":[[0,5.9,46.91],[1,6,8.37],[2,6.2,14.29]],"ltp":5.9,"tv":654.04,"id":17352128}],"tv":5973.8}]}
{"op":"mcm","clk":"994675013","pt":1580553104438,"mc":[{"id":"1.168133548","rc":[{"batl":[[2,6.2,42.16]],"ltp":5.6,"tv":1335.39,"id":9417341},{"batb":[[2,8.6,2.92]],"ltp":9.2,"tv":1219.89,"id":10616006},{"batb":[[1,36,1.4]],"ltp":40.0,"tv":61.34,"id":9193530}]}]}
{"op":"mcm","clk":"994675199","pt":1580553105573,"mc":[{"id":"1.168133548","rc":[{"batb":[[0,6,14.23]],"ltp":6.6,"tv":518.85,"id":8231803},{"batl":[[1,7.8,17.64]],"ltp":7.6,"tv":1056.75,"id":10170404}]}]}
{"op":"mcm","clk":"994676018","pt":1580553110557,"mc":[{"id":"1.168133548","rc":[{"batb":[[2,34,3.72]],"ltp":40.0,"tv":61.34,"id":9193530}]}]}
{"op":"mcm","clk":"994676489","pt":1580553112752,"mc":[{"id":"1.168133548","rc":[{"batl":[[0,42,2.53]],"ltp":29.0,"tv":87.11,"id":9001159}]}]}
{"op":"mcm","clk":"994678084","pt":1580553121387,"mc":[{"id":"1.168133548","rc":[{"batl":[[2,950,0.2]],"ltp":29.0,"tv":87.11,"id":9001159}]}]}
{"op":"mcm","clk":"994678294","pt":1580553122504,"mc":[{"id":"1.168133548","rc":[{"batl":[[0,6,80.29],[1,6.2,42.16],[2,6.4,25]],"ltp":5.6,"tv":1335.39,"id":9417341},{"batl":[[1,7,2],[2,7.8,4.31]],"ltp":6.6,"tv":518.85,"id":8231803},{"batl":[[0,10,2.21]],"ltp":9.2,"tv":1219.89,"id":10616006},{"batl":[[0,7.8,17.64],[1,8,23.38],[2,8.2,20]],"ltp":7.6,"tv":1056.75,"id":10170404},{"batl":[[0,6,8.37],[1,6.2,14.29],[2,6.4,47.31]],"ltp":5.9,"tv":654.04,"id":17352128}]}]}
{"op":"mcm","clk":"994678469","pt":1580553123375,"mc":[{"id":"1.168133548","rc":[{"batl":[[1,6.2,58.18]],"ltp":5.6,"tv":1335.39,"id":9417341},{"batb":[[0,7.6,7.25],[1,7.4,13.01],[2,7.2,21]],"batl":[[1,8,27.21]],"ltp":7.6,"tv":1056.75,"id":10170404}]}]}
{"op":"mcm","clk":"994678640","pt":1580553124281,"mc":[{"id":"1.168133548","rc":[{"batl":[[1,6.2,67.54]],"ltp":5.6,"tv":1335.39,"id":9417341},{"batl":[[0,7.8,9.45]],"ltp":7.6,"tv":1056.75,"id":10170404}]}]}
{"op":"mcm","clk":"994678978","pt":1580553126095,"mc":[{"id":"1.168133548","rc":[{"batl":[[1,8,23.38]],"ltp":7.6,"tv":1056.75,"id":10170404}]}]}
{"op":"mcm","clk":"994679412","pt":1580553128498,"mc":[{"id":"1.168133548","rc":[{"trd":[[7.6,146.78]],"batb":[[0,7.6,3.95]],"ltp":7.6,"tv":1063.35,"id":10170404}],"tv":5980.4}]}
{"op":"mcm","clk":"994679577","pt":1580553129404,"mc":[{"id":"1.168133548","rc":[{"batb":[[2,7.2,26.55]],"ltp":7.6,"tv":1063.35,"id":10170404}]}]}
{"op":"mcm","clk":"994680487","pt":1580553134499,"mc":[{"id":"1.168133548","rc":[{"batl":[[2,8.2,22.85]],"ltp":7.6,"tv":1063.35,"id":10170404}]}]}
{"op":"mcm","clk":"994682190","pt":1580553144105,"mc":[{"id":"1.168133548","rc":[{"batb":[[0,9.2,3.45]],"ltp":9.2,"tv":1219.89,"id":10616006}]}]}
{"op":"mcm","clk":"994682797","pt":1580553147418,"mc":[{"id":"1.168133548","rc":[{"batl":[[2,8,33]],"ltp":6.6,"tv":518.85,"id":8231803}]}]}
{"op":"mcm","clk":"994682884","pt":1580553147945,"mc":[{"id":"1.168133548","rc":[{"batl":[[2,7.8,1.64]],"ltp":6.6,"tv":518.85,"id":8231803}]}]}
{"op":"mcm","clk":"994683437","pt":1580553151571,"mc":[{"id":"1.168133548","rc":[{"trd":[[36,3.52],[38,5.15]],"batb":[[0,34,3.72],[1,32,2.55],[2,30,9.79]],"ltp":36.0,"tv":67.32,"id":9193530}],"tv":5986.39}]}
{"op":"mcm","clk":"994684111","pt":1580553155458,"mc":[{"id":"1.168133548","rc":[{"batl":[[2,8.2,20]],"ltp":7.6,"tv":1063.35,"id":10170404}]}]}
{"op":"mcm","clk":"994684484","pt":1580553157481,"mc":[{"id":"1.168133548","rc":[{"batb":[[0,34,3.91]],"ltp":36.0,"tv":67.32,"id":9193530}]}]}
{"op":"mcm","clk":"994685242","pt":1580553160475,"mc":[{"id":"1.168133548","rc":[{"batl":[[0,5.9,43.43],[1,6,79.79],[2,6.2,67.54]],"ltp":5.6,"tv":1335.39,"id":9417341},{"batl":[[0,10,33.87]],"ltp":9.2,"tv":1219.89,"id":10616006}]}]}
{"op":"mcm","clk":"994685481","pt":1580553161555,"mc":[{"id":"1.168133548","rc":[{"batb":[[0,7.6,8.95]],"ltp":7.6,"tv":1063.35,"id":10170404}]}]}
{"op":"mcm","clk":"994686825","pt":1580553168506,"mc":[{"id":"1.168133548","rc":[{"batl":[[0,46,2.13]],"ltp":36.0,"tv":67.32,"id":9193530}]}]}
{"op":"mcm","clk":"994687059","pt":1580553169574,"mc":[{"id":"1.168133548","rc":[{"batb":[[0,34,1.37],[2,30,6.5]],"ltp":36.0,"tv":67.32,"id":9193530}]}]}
{"op":"mcm","clk":"994687362","pt":1580553171516,"mc":[{"id":"1.168133548","rc":[{"batb":[[2,5.3,7.55]],"ltp":5.6,"tv":1335.39,"id":9417341}]}]}
{"op":"mcm","clk":"994687522","pt":1580553172506,"mc":[{"id":"1.168133548","rc":[{"batb":[[1,32,2],[2,30,3.29]],"ltp":36.0,"tv":67.32,"id":9193530}]}]}
{"op":"mcm","clk":"994688768","pt":1580553179542,"mc":[{"id":"1.168133548","rc":[{"batl":[[0,6,80.29],[1,6.2,67.54],[2,6.4,25]],"ltp":5.6,"tv":1335.39,"id":9417341},{"batl":[[0,10,2.21]],"ltp":9.2,"tv":1219.89,"id":10616006},{"batb":[[2,30,3.87]],"ltp":36.0,"tv":67.32,"id":9193530}]}]}
{"op":"mcm","clk":"994688937","pt":1580553180558,"mc":[{"id":"1.168133548","rc":[{"trd":[[9.4,18.62]],"batb":[[0,9.4,1.62],[1,9.2,3.45],[2,9,7.47]],"batl":[[0,10,2]],"ltp":9.4,"tv":1220.31,"id":10616006}],"tv":5986.81}]}
{"op":"mcm","clk":"994691052","pt":1580553193271,"mc":[{"id":"1.168133548","rc":[{"batb":[[0,34,1.84]],"ltp":36.0,"tv":67.32,"id":9193530}]}]}
{"op":"mcm","clk":"994693183","pt":1580553205535,"mc":[{"id":"1.168133548","rc":[{"batl":[[0,10.5,5.03],[1,11,7.58],[2,11.5,10.44]],"ltp":9.4,"tv":1220.31,"id":10616006}]}]}
{"op":"mcm","clk":"994695477","pt":1580553218352,"mc":[{"id":"1.168133548","rc":[{"batb":[[1,9.2,1.72]],"batl":[[0,10,6.5],[1,10.5,5.03],[2,11,7.58]],"ltp":9.4,"tv":1220.31,"id":10616006}]}]}
{"op":"mcm","clk":"994710931","pt":1580553309437,"mc":[{"id":"1.168133548","rc":[{"batl":[[1,6.2,69.54]],"ltp":5.6,"tv":1335.39,"id":9417341}]}]}
{"op":"mcm","clk":"994714204","pt":1580553329482,"mc":[{"id":"1.168133548","rc":[{"trd":[[5.6,26.39]],"batb":[[0,5.6,9.51]],"ltp":5.6,"tv":1355.4,"id":9417341}],"tv":6006.81}]}
{"op":"mcm","clk":"994717986","pt":1580553351476,"mc":[{"id":"1.168133548","rc":[{"trd":[[29,11.37]],"batb":[[0,27,14.44],[1,26,3.21],[2,22,4.12]],"batl":[[0,29,4.36],[1,42,2.53],[2,270,9.06]],"ltp":29.0,"tv":98.39,"id":9001159}],"tv":6018.09}]}
{"op":"mcm","clk":"994718164","pt":1580553352488,"mc":[{"id":"1.168133548","rc":[{"trd":[[29,14.79]],"batb":[[1,26,7.2]],"batl":[[0,29,2.65]],"ltp":29.0,"tv":101.81,"id":9001159}],"tv":6021.51}]}
{"op":"mcm","clk":"994718346","pt":1580553353512,"mc":[{"id":"1.168133548","rc":[{"batl":[[1,42,2.46]],"ltp":29.0,"tv":101.81,"id":9001159}]}]}
{"op":"mcm","clk":"994718489","pt":1580553354519,"mc":[{"id":"1.168133548","rc":[{"batb":[[0,27,10.61],[1,26,3.21]],"ltp":29.0,"tv":101.81,"id":9001159}]}]}
{"op":"mcm","clk":"994718652","pt":1580553355492,"mc":[{"id":"1.168133548","rc":[{"batb":[[0,27,9.98]],"ltp":29.0,"tv":101.81,"id":9001159}]}]}
{"op":"mcm","clk":"994719305","pt":1580553359529,"mc":[{"id":"1.168133548","rc":[{"trd":[[5.6,35.66]],"batb":[[0,5.6,4.88]],"ltp":5.6,"tv":1364.66,"id":9417341}],"tv":6030.77}]}
{"op":"mcm","clk":"994719638","pt":1580553361534,"mc":[{"id":"1.168133548","rc":[{"batl":[[0,6,13.37]],"ltp":5.9,"tv":654.04,"id":17352128}]}]}
{"op":"mcm","clk":"994719819","pt":1580553362571,"mc":[{"id":"1.168133548","rc":[{"batb":[[0,27,10.64]],"ltp":29.0,"tv":101.81,"id":9001159}]}]}
{"op":"mcm","clk":"994723990","pt":1580553387382,"mc":[{"id":"1.168133548","rc":[{"batb":[[0,34,1.37]],"batl":[[0,46,1.78]],"ltp":36.0,"tv":67.32,"id":9193530}]}]}
{"op":"mcm","clk":"994724678","pt":1580553391491,"mc":[{"id":"1.168133548","rc":[{"trd":[[27,21.28]],"batb":[[0,26,3.21],[1,22,12.28],[2,20,8.79]],"ltp":27.0,"tv":123.09,"id":9001159}],"tv":6052.05}]}
{"op":"mcm","clk":"994724986","pt":1580553393410,"mc":[{"id":"1.168133548","rc":[{"batl":[[1,8,28.38]],"ltp":7.6,"tv":1063.35,"id":10170404}]}]}
{"op":"mcm","clk":"994725174","pt":1580553394427,"mc":[{"id":"1.168133548","rc":[{"batb":[[1,22,5.88]],"ltp":27.0,"tv":123.09,"id":9001159}]}]}
{"op":"mcm","clk":"994733700","pt":1580553447546,"mc":[{"id":"1.168133548","rc":[{"batb":[[1,23,6],[2,22,5.88]],"ltp":27.0,"tv":123.09,"id":9001159}]}]}
{"op":"mcm","clk":"994734018","pt":1580553449350,"mc":[{"id":"1.168133548","rc":[{"trd":[[6.6,31.06]],"batl":[[0,6.6,5.91]],"ltp":6.6,"tv":521.63,"id":8231803}],"tv":6054.82}]}
{"op":"mcm","clk":"994745214","pt":1580553453574,"mc":[{"id":"1.168133548","rc":[{"batb":[[2,5.8,12.11]],"ltp":6.6,"tv":521.63,"id":8231803}]}]}
{"op":"mcm","clk":"994746697","pt":1580553462478,"mc":[{"id":"1.168133548","rc":[{"trd":[[7.6,156.78]],"batb":[[0,7.6,3.95]],"ltp":7.6,"tv":1073.35,"id":10170404}],"tv":6064.82}]}
{"op":"mcm","clk":"994750564","pt":1580553485491,"mc":[{"id":"1.168133548","rc":[{"batb":[[0,6.2,7.08],[1,6,14.23],[2,5.9,8.78]],"ltp":6.6,"tv":521.63,"id":8231803}]}]}
{"op":"mcm","clk":"994750860","pt":1580553487311,"mc":[{"id":"1.168133548","rc":[{"trd":[[11.5,62.67]],"batb":[[0,11.5,12.52]],"ltp":11.5,"tv":555.42,"id":8429550}],"tv":6067.38}]}
{"op":"mcm","clk":"994751051","pt":1580553488533,"mc":[{"id":"1.168133548","rc":[{"batb":[[1,6,17.41]],"ltp":6.6,"tv":521.63,"id":8231803}]}]}
{"op":"mcm","clk":"994752350","pt":1580553496559,"mc":[{"id":"1.168133548","rc":[{"trd":[[5.8,75.51]],"batb":[[0,5.7,9],[1,5.4,9.63]],"batl":[[0,5.8,47.62],[1,6,13.37],[2,6.2,14.29]],"ltp":5.8,"tv":678.8,"id":17352128}],"tv":6092.15}]}
{"op":"mcm","clk":"994752474","pt":1580553497302,"mc":[{"id":"1.168133548","rc":[{"batb":[[0,6.2,9.08],[2,5.9,6.78]],"ltp":6.6,"tv":521.63,"id":8231803}]}]}
{"op":"mcm","clk":"994753303","pt":1580553502550,"mc":[{"id":"1.168133548","rc":[{"batl":[[1,13.5,20.72]],"ltp":11.5,"tv":555.42,"id":8429550}]}]}
{"op":"mcm","clk":"994753442","pt":1580553503456,"mc":[{"id":"1.168133548","rc":[{"trd":[[5.7,33.04]],"batb":[[0,5.7,3.36]],"ltp":5.7,"tv":690.08,"id":17352128}],"tv":6103.42}]}
{"op":"mcm","clk":"994753766","pt":1580553505526,"mc":[{"id":"1.168133548","rc":[{"trd":[[8.6,198.57],[8.8,40.54]],"batb":[[0,8.6,4.66],[1,8.4,6.39],[2,8.2,16.49]],"ltp":8.6,"tv":507.54,"id":15608820}],"tv":6123.43}]}
{"op":"mcm","clk":"994753922","pt":1580553506541,"mc":[{"id":"1.168133548","rc":[{"batl":[[2,7.4,8.02]],"ltp":6.6,"tv":521.63,"id":8231803},{"batb":[[1,8.2,16.49],[2,7.8,5.54]],"ltp":8.6,"tv":507.54,"id":15608820},{"batb":[[1,5.4,3.08]],"ltp":5.7,"tv":690.08,"id":17352128}]}]}
{"op":"mcm","clk":"994754244","pt":1580553508545,"mc":[{"id":"1.168133548","rc":[{"batl":[[1,13.5,24.04]],"ltp":11.5,"tv":555.42,"id":8429550},{"batl":[[2,7.8,13.16]],"ltp":6.6,"tv":521.63,"id":8231803}]}]}
{"op":"mcm","clk":"994756344","pt":1580553521279,"mc":[{"id":"1.168133548","rc":[{"batl":[[0,5.8,51.42]],"ltp":5.7,"tv":690.08,"id":17352128}]}]}
{"op":"mcm","clk":"994756489","pt":1580553522171,"mc":[{"id":"1.168133548","rc":[{"batl":[[1,13.5,26.9]],"ltp":11.5,"tv":555.42,"id":8429550},{"batl":[[2,7.4,8.02]],"ltp":6.6,"tv":521.63,"id":8231803}]}]}
{"op":"mcm","clk":"994756739","pt":1580553523565,"mc":[{"id":"1.168133548","rc":[{"batl":[[2,7.8,13.16]],"ltp":6.6,"tv":521.63,"id":8231803}]}]}
{"op":"mcm","clk":"994758289","pt":1580553533372,"mc":[{"id":"1.168133548","rc":[{"batb":[[2,30,4.44]],"ltp":36.0,"tv":67.32,"id":9193530}]}]}
{"op":"mcm","clk":"994759243","pt":1580553538569,"mc":[{"id":"1.168133548","rc":[{"batl":[[2,7.4,8.02]],"ltp":6.6,"tv":521.63,"id":8231803}]}]}
{"op":"mcm","clk":"994760841","pt":1580553547504,"mc":[{"id":"1.168133548","rc":[{"trd":[[5.9,223.85],[6,320.35]],"batl":[[0,6,74.29]],"ltp":6.0,"tv":1376.66,"id":9417341},{"trd":[[6.6,42.88]],"batb":[[0,6.2,9.17]],"batl":[[0,7,2],[1,7.4,8.02],[2,7.8,13.16]],"ltp":6.6,"tv":533.45,"id":8231803},{"trd":[[10,289.8]],"batl":[[0,10,3.5]],"ltp":10.0,"tv":1226.31,"id":10616006},{"trd":[[7.8,58.29]],"batl":[[0,7.8,7.45]],"ltp":7.8,"tv":1077.35,"id":10170404},{"trd":[[5.8,87.51]],"batl":[[0,5.8,45.42]],"ltp":5.8,"tv":702.08,"id":17352128}],"tv":6169.25}]}
{"op":"mcm","clk":"994761014","pt":1580553548508,"mc":[{"id":"1.168133548","rc":[{"batl":[[1,7.8,1.64],[2,8,10.58]],"ltp":6.6,"tv":533.45,"id":8231803}]}]}
{"op":"mcm","clk":"994761175","pt":1580553549512,"mc":[{"id":"1.168133548","rc":[{"batb":[[1,6,26.06]],"batl":[[1,7.4,6.1],[2,7.8,6.56]],"ltp":6.6,"tv":533.45,"id":8231803}]}]}
{"op":"mcm","clk":"994761490","pt":1580553551390,"mc":[{"id":"1.168133548","rc":[{"batl":[[1,7.8,1.64],[2,8,2]],"ltp":6.6,"tv":533.45,"id":8231803}]}]}
{"op":"mcm","clk":"994761681","pt":1580553552514,"mc":[{"id":"1.168133548","rc":[{"batb":[[1,5.5,31.8]],"ltp":6.0,"tv":1376.66,"id":9417341}]}]}
{"op":"mcm","clk":"994762204","pt":1580553555535,"mc":[{"id":"1.168133548","rc":[{"batl":[[1,7.2,2.21],[2,7.8,1.64]],"ltp":6.6,"tv":533.45,"id":8231803}]}]}
{"op":"mcm","clk":"994762518","pt":1580553557499,"mc":[{"id":"1.168133548","rc":[{"batb":[[1,5.3,10],[2,5.2,17.36]],"ltp":5.8,"tv":702.08,"id":17352128}]}]}
{"op":"mcm","clk":"994762696","pt":1580553558497,"mc":[{"id":"1.168133548","rc":[{"batb":[[1,5.4,2.5],[2,5.3,10]],"ltp":5.8,"tv":702.08,"id":17352128}]}]}
{"op":"mcm","clk":"994764925","pt":1580553570554,"mc":[{"id":"1.168133548","rc":[{"trd":[[26,4]],"batb":[[0,26,1.21]],"ltp":26.0,"tv":127.09,"id":9001159}],"tv":6173.25}]}
{"op":"mcm","clk":"994765760","pt":1580553575448,"mc":[{"id":"1.168133548","rc":[{"batb":[[2,22,1.81]],"ltp":26.0,"tv":127.09,"id":9001159}]}]}
{"op":"mcm","clk":"994766272","pt":1580553578529,"mc":[{"id":"1.168133548","rc":[{"batb":[[1,23,6.67]],"ltp":26.0,"tv":127.09,"id":9001159}]}]}
{"op":"mcm","clk":"994766422","pt":1580553579533,"mc":[{"id":"1.168133548","rc":[{"trd":[[9.2,124.92],[9.4,21.86]],"batb":[[0,9,7.81],[1,8.6,10.52],[2,8.4,5.13]],"ltp":9.2,"tv":1232.31,"id":10616006}],"tv":6179.25}]}
{"op":"mcm","clk":"994766573","pt":1580553580555,"mc":[{"id":"1.168133548","rc":[{"batb":[[2,8.4,2.13]],"ltp":9.2,"tv":1232.31,"id":10616006}]}]}
{"op":"mcm","clk":"994766739","pt":1580553581513,"mc":[{"id":"1.168133548","rc":[{"batl":[[2,7.8,4.97]],"ltp":6.6,"tv":533.45,"id":8231803},{"batb":[[1,8.6,5.26]],"ltp":9.2,"tv":1232.31,"id":10616006},{"trd":[[7.6,160.78]],"batb":[[0,7.6,1.95]],"ltp":7.6,"tv":1081.35,"id":10170404}],"tv":6183.25}]}
{"op":"mcm","clk":"994766898","pt":1580553582518,"mc":[{"id":"1.168133548","rc":[{"batb":[[1,8.4,2.13],[2,8.2,2]],"ltp":9.2,"tv":1232.31,"id":10616006},{"trd":[[7.6,164.68]],"batb":[[0,7.4,13.01],[1,7.2,26.55],[2,7,23]],"ltp":7.6,"tv":1085.25,"id":10170404}],"tv":6187.15}]}
{"op":"mcm","clk":"994767233","pt":1580553584441,"mc":[{"id":"1.168133548","rc":[{"batl":[[2,7.8,7.66]],"ltp":6.6,"tv":533.45,"id":8231803},{"batb":[[1,8.2,9.44],[2,8,53.75]],"ltp":9.2,"tv":1232.31,"id":10616006}]}]}
{"op":"mcm","clk":"994768193","pt":1580553590468,"mc":[{"id":"1.168133548","rc":[{"trd":[[32,1.26],[34,2.88],[36,3.9]],"batb":[[0,32,1.37],[1,30,4.44],[2,29,6.73]],"ltp":32.0,"tv":71.32,"id":9193530}],"tv":6191.15}]}
{"op":"mcm","clk":"994768377","pt":1580553591552,"mc":[{"id":"1.168133548","rc":[{"batb":[[1,30,1.16],[2,29,3.31]],"ltp":32.0,"tv":71.32,"id":9193530}]}]}
{"op":"mcm","clk":"994769329","pt":1580553597482,"mc":[{"id":"1.168133548","rc":[{"batb":[[1,29,3.88],[2,26,1.67]],"ltp":32.0,"tv":71.32,"id":9193530}]}]}
{"op":"mcm","clk":"994770019","pt":1580553601555,"mc":[{"id":"1.168133548","rc":[{"batb":[[0,9.2,2.07],[1,9,7.47],[2,8.2,9.44]],"ltp":9.2,"tv":1232.31,"id":10616006},{"batb":[[1,23,6]],"ltp":26.0,"tv":127.09,"id":9001159},{"batl":[[0,46,2.13]],"ltp":32.0,"tv":71.32,"id":9193530}]}]}
{"op":"mcm","clk":"994770492","pt":1580553604491,"mc":[{"id":"1.168133548","rc":[{"batl":[[0,46,2.24],[2,220,9]],"ltp":32.0,"tv":71.32,"id":9193530}]}]}
{"op":"mcm","clk":"994773950","pt":1580553625550,"mc":[{"id":"1.168133548","rc":[{"trd":[[9.2,129.06]],"batb":[[0,9,7.47],[1,8.2,9.44],[2,8,15.31]],"batl":[[0,9.2,7.93],[1,10,3.5],[2,10.5,5.03]],"ltp":9.2,"tv":1236.44,"id":10616006},{"batb":[[1,30,1.1],[2,29,3.31]],"ltp":32.0,"tv":71.32,"id":9193530}],"tv":6195.29}]}
{"op":"mcm","clk":"994774310","pt":1580553627526,"mc":[{"id":"1.168133548","rc":[{"batl":[[1,9.8,4.41],[2,10,8.89]],"ltp":9.2,"tv":1236.44,"id":10616006}]}]}
{"op":"mcm","clk":"994774466","pt":1580553628539,"mc":[{"id":"1.168133548","rc":[{"batb":[[0,6.4,5.09],[1,6.2,9.08],[2,6,26.06]],"ltp":6.6,"tv":533.45,"id":8231803}]}]}
{"op":"mcm","clk":"994775066","pt":1580553632549,"mc":[{"id":"1.168133548","rc":[{"batb":[[1,6.2,11.44]],"ltp":6.6,"tv":533.45,"id":8231803},{"batl":[[0,9.8,10.07],[1,10,8.89],[2,10.5,5.03]],"ltp":9.2,"tv":1236.44,"id":10616006},{"batl":[[0,9.2,4.74]],"ltp":8.6,"tv":507.54,"id":15608820}]}]}
{"op":"mcm","clk":"994775226","pt":1580553633470,"mc":[{"id":"1.168133548","rc":[{"batb":[[1,6.2,16.44]],"ltp":6.6,"tv":533.45,"id":8231803},{"batl":[[1,10,14.75]],"ltp":9.2,"tv":1236.44,"id":10616006}]}]}
{"op":"mcm","clk":"994775559","pt":1580553635561,"mc":[{"id":"1.168133548","rc":[{"batl":[[0,10,3.5],[1,10.5,5.03],[2,11,7.58]],"ltp":9.2,"tv":1236.44,"id":10616006}]}]}
{"op":"mcm","clk":"994775819","pt":1580553637373,"mc":[{"id":"1.168133548","rc":[{"batb":[[0,6.4,7.09],[1,6.2,14.44]],"ltp":6.6,"tv":533.45,"id":8231803},{"trd":[[9,55.72]],"batb":[[0,8.4,3.3]],"batl":[[0,10.5,5.56],[1,11,7.58],[2,11.5,10.44]],"ltp":9.0,"tv":1251.38,"id":10616006}],"tv":6210.23}]}
{"op":"mcm","clk":"994775985","pt":1580553638474,"mc":[{"id":"1.168133548","rc":[{"batb":[[1,8.2,4.7]],"ltp":9.0,"tv":1251.38,"id":10616006}]}]}
{"op":"mcm","clk":"994776183","pt":1580553639549,"mc":[{"id":"1.168133548","rc":[{"batb":[[1,8.2,2]],"ltp":9.0,"tv":1251.38,"id":10616006}]}]}
{"op":"mcm","clk":"994776667","pt":1580553642478,"mc":[{"id":"1.168133548","rc":[{"batl":[[0,10.5,7.38]],"ltp":9.0,"tv":1251.38,"id":10616006}]}]}
{"op":"mcm","clk":"994779402","pt":1580553659372,"mc":[{"id":"1.168133548","rc":[{"batl":[[1,11,12.58]],"ltp":9.0,"tv":1251.38,"id":10616006}]}]}
{"op":"mcm","clk":"994783453","pt":1580553684549,"mc":[{"id":"1.168133548","rc":[{"batb":[[0,8.6,2.33],[1,8.4,3.3],[2,8.2,2]],"ltp":9.0,"tv":1251.38,"id":10616006}]}]}
{"op":"mcm","clk":"994783522","pt":1580553684924,"mc":[{"id":"1.168133548","rc":[{"batl":[[0,10,2.53],[1,10.5,6.85],[2,11,12.58]],"ltp":9.0,"tv":1251.38,"id":10616006}]}]}
{"op":"mcm","clk":"994783928","pt":1580553687431,"mc":[{"id":"1.168133548","rc":[{"batb":[[1,22,1.81],[2,21,12.22]],"ltp":26.0,"tv":127.09,"id":9001159}]}]}
{"op":"mcm","clk":"994784109","pt":1580553688548,"mc":[{"id":"1.168133548","rc":[{"batb":[[2,20,8.79]],"ltp":26.0,"tv":127.09,"id":9001159}]}]}
{"op":"mcm","clk":"994784900","pt":1580553693564,"mc":[{"id":"1.168133548","rc":[{"batb":[[2,21,3.03]],"ltp":26.0,"tv":127.09,"id":9001159}]}]}
{"op":"mcm","clk":"994784961","pt":1580553693940,"mc":[{"id":"1.168133548","rc":[{"batb":[[0,8.6,5.36]],"ltp":9.0,"tv":1251.38,"id":10616006}]}]}
{"op":"mcm","clk":"994785444","pt":1580553696551,"mc":[{"id":"1.168133548","rc":[{"batl":[[0,10,34.19]],"ltp":9.0,"tv":1251.38,"id":10616006}]}]}
{"op":"mcm","clk":"994785636","pt":1580553697566,"mc":[{"id":"1.168133548","rc":[{"batb":[[0,30,1.1],[1,29,3.31],[2,26,1.67]],"ltp":32.0,"tv":71.32,"id":9193530}]}]}
{"op":"mcm","clk":"994787312","pt":1580553707539,"mc":[{"id":"1.168133548","rc":[{"batb":[[1,22,4.81]],"ltp":26.0,"tv":127.09,"id":9001159}]}]}
{"op":"mcm","clk":"994788080","pt":1580553712470,"mc":[{"id":"1.168133548","rc":[{"batl":[[1,8,31.23],[2,8.2,22.85]],"ltp":7.6,"tv":1085.25,"id":10170404}]}]}
{"op":"mcm","clk":"994788447","pt":1580553714556,"mc":[{"id":"1.168133548","rc":[{"trd":[[5.5,50.24],[5.6,45.42]],"batb":[[0,5.5,31.68],[1,5.4,2.82],[2,5.3,20.59]],"ltp":5.5,"tv":1386.66,"id":9417341},{"batb":[[0,8.8,40],[1,8.6,4.66],[2,8.2,16.49]],"ltp":8.6,"tv":507.54,"id":15608820}],"tv":6220.22}]}
{"op":"mcm","clk":"994788807","pt":1580553716562,"mc":[{"id":"1.168133548","rc":[{"batb":[[1,5.3,20.59],[2,5.2,2]],"ltp":5.5,"tv":1386.66,"id":9417341},{"batb":[[1,8.6,19.52]],"ltp":8.6,"tv":507.54,"id":15608820}]}]}
{"op":"mcm","clk":"994788949","pt":1580553717471,"mc":[{"id":"1.168133548","rc":[{"batb":[[1,5.3,30.43]],"ltp":5.5,"tv":1386.66,"id":9417341}]}]}
{"op":"mcm","clk":"994789590","pt":1580553721483,"mc":[{"id":"1.168133548","rc":[{"batb":[[0,5.5,28.68]],"ltp":5.5,"tv":1386.66,"id":9417341}]}]}
{"op":"mcm","clk":"994790366","pt":1580553726267,"mc":[{"id":"1.168133548","rc":[{"batl":[[1,8,33.23]],"ltp":7.6,"tv":1085.25,"id":10170404}]}]}
{"op":"mcm","clk":"994791103","pt":1580553730422,"mc":[{"id":"1.168133548","rc":[{"batl":[[0,5.9,5.91],[1,6,74.29],[2,6.2,69.54]],"ltp":5.5,"tv":1386.66,"id":9417341},{"batl":[[1,10,5],[2,12,10.58]],"ltp":8.6,"tv":507.54,"id":15608820}]}]}
{"op":"mcm","clk":"994791270","pt":1580553731386,"mc":[{"id":"1.168133548","rc":[{"batl":[[2,12,12.68]],"ltp":8.6,"tv":507.54,"id":15608820}]}]}
{"op":"mcm","clk":"994791432","pt":1580553732498,"mc":[{"id":"1.168133548","rc":[{"batl":[[2,6.2,44.16]],"ltp":5.5,"tv":1386.66,"id":9417341},{"batl":[[1,9.8,3.5],[2,10,5]],"ltp":8.6,"tv":507.54,"id":15608820}]}]}
{"op":"mcm","clk":"994791900","pt":1580553735511,"mc":[{"id":"1.168133548","rc":[{"batl":[[0,10,2.53]],"ltp":9.0,"tv":1251.38,"id":10616006},{"batb":[[0,8.6,19.52],[1,8.4,7.64]],"batl":[[1,9.8,7.05]],"ltp":8.6,"tv":507.54,"id":15608820}]}]}
{"op":"mcm","clk":"994792073","pt":1580553736525,"mc":[{"id":"1.168133548","rc":[{"batb":[[0,8.6,4.66]],"ltp":8.6,"tv":507.54,"id":15608820}]}]}
{"op":"mcm","clk":"994792265","pt":1580553737499,"mc":[{"id":"1.168133548","rc":[{"batl":[[0,9.2,2],[1,9.6,2.74],[2,9.8,7.05]],"ltp":8.6,"tv":507.54,"id":15608820}]}]}
{"op":"mcm","clk":"994792450","pt":1580553738504,"mc":[{"id":"1.168133548","rc":[{"batl":[[0,5.9,19.91]],"ltp":5.5,"tv":1386.66,"id":9417341}]}]}
{"op":"mcm","clk":"994792620","pt":1580553739522,"mc":[{"id":"1.168133548","rc":[{"batl":[[2,10,5]],"ltp":8.6,"tv":507.54,"id":15608820}]}]}
{"op":"mcm","clk":"994793801","pt":1580553746492,"mc":[{"id":"1.168133548","rc":[{"batb":[[1,8.2,16.49],[2,7.8,5.54]],"ltp":8.6,"tv":507.54,"id":15608820}]}]}
{"op":"mcm","clk":"994795839","pt":1580553758488,"mc":[{"id":"1.168133548","rc":[{"batl":[[0,9.2,4.74],[1,10,5],[2,12,12.68]],"ltp":8.6,"tv":507.54,"id":15608820}]}]}
{"op":"mcm","clk":"994797166","pt":1580553766270,"mc":[{"id":"1.168133548","rc":[{"batl":[[1,9.8,2.81],[2,10,8.25]],"ltp":8.6,"tv":507.54,"id":15608820}]}]}
{"op":"mcm","clk":"994799747","pt":1580553781427,"mc":[{"id":"1.168133548","rc":[{"batl":[[1,9.8,6.36]],"ltp":8.6,"tv":507.54,"id":15608820}]}]}
{"op":"mcm","clk":"994800461","pt":1580553785539,"mc":[{"id":"1.168133548","rc":[{"batb":[[0,7.6,6],[1,7.4,13.01],[2,7.2,26.55]],"ltp":7.6,"tv":1085.25,"id":10170404}]}]}
{"op":"mcm","clk":"994801861","pt":1580553793556,"mc":[{"id":"1.168133548","rc":[{"batl":[[1,7.8,7.66],[2,8,2]],"ltp":6.6,"tv":533.45,"id":8231803}]}]}
{"op":"mcm","clk":"994802014","pt":1580553794451,"mc":[{"id":"1.168133548","rc":[{"batl":[[0,9.8,2.15],[1,10,2],[2,10.5,6.85]],"ltp":9.0,"tv":1251.38,"id":10616006}]}]}
{"op":"mcm","clk":"994802194","pt":1580553795467,"mc":[{"id":"1.168133548","rc":[{"batl":[[1,7.8,3.35],[2,8,5.54]],"ltp":6.6,"tv":533.45,"id":8231803}]}]}
{"op":"mcm","clk":"994803373","pt":1580553802559,"mc":[{"id":"1.168133548","rc":[{"batl":[[2,8,9.19]],"ltp":6.6,"tv":533.45,"id":8231803}]}]}
{"op":"mcm","clk":"994804231","pt":1580553807458,"mc":[{"id":"1.168133548","rc":[{"batl":[[0,9.2,2],[1,9.6,2.74],[2,9.8,6.36]],"ltp":8.6,"tv":507.54,"id":15608820}]}]}
{"op":"mcm","clk":"994804393","pt":1580553808462,"mc":[{"id":"1.168133548","rc":[{"batl":[[1,8,6.2],[2,8.2,2.5]],"ltp":6.6,"tv":533.45,"id":8231803}]}]}
{"op":"mcm","clk":"994804909","pt":1580553811445,"mc":[{"id":"1.168133548","rc":[{"batl":[[1,7.4,34.22],[2,8,6.2]],"ltp":6.6,"tv":533.45,"id":8231803}]}]}
{"op":"mcm","clk":"994805255","pt":1580553813510,"mc":[{"id":"1.168133548","rc":[{"batl":[[2,10,8.25]],"ltp":8.6,"tv":507.54,"id":15608820}]}]}
{"op":"mcm","clk":"994805386","pt":1580553814413,"mc":[{"id":"1.168133548","rc":[{"batl":[[2,8,17.65]],"ltp":6.6,"tv":533.45,"id":8231803}]}]}
{"op":"mcm","clk":"994805564","pt":1580553815521,"mc":[{"id":"1.168133548","rc":[{"batb":[[1,11,11.95],[2,10.5,1.98]],"ltp":11.5,"tv":555.42,"id":8429550},{"batb":[[2,5.3,17.55]],"ltp":5.8,"tv":702.08,"id":17352128}]}]}
{"op":"mcm","clk":"994805671","pt":1580553816156,"mc":[{"id":"1.168133548","rc":[{"batb":[[0,8.6,9.31],[1,8.2,11.61]],"ltp":8.6,"tv":507.54,"id":15608820}]}]}
{"op":"mcm","clk":"994805901","pt":1580553817529,"mc":[{"id":"1.168133548","rc":[{"batb":[[0,29,3.88],[1,26,1.67],[2,21,11.09]],"batl":[[0,46,1.89]],"ltp":32.0,"tv":71.32,"id":9193530}]}]}
{"op":"mcm","clk":"994806057","pt":1580553818428,"mc":[{"id":"1.168133548","rc":[{"batl":[[2,7.8,6.63]],"ltp":6.6,"tv":533.45,"id":8231803},{"batb":[[1,8.4,3.71],[2,8.2,11.61]],"ltp":8.6,"tv":507.54,"id":15608820}]}]}
{"op":"mcm","clk":"994807614","pt":1580553827573,"mc":[{"id":"1.168133548","rc":[{"batl":[[0,9.2,4.74],[1,10,8.25],[2,12,33.68]],"ltp":8.6,"tv":507.54,"id":15608820}]}]}
{"op":"mcm","clk":"994808115","pt":1580553830549,"mc":[{"id":"1.168133548","rc":[{"batl":[[1,7.6,33.98],[2,7.8,5.97]],"ltp":6.6,"tv":533.45,"id":8231803}]}]}
{"op":"mcm","clk":"994808443","pt":1580553832556,"mc":[{"id":"1.168133548","rc":[{"batl":[[2,7.8,11.95]],"ltp":6.6,"tv":533.45,"id":8231803},{"batb":[[1,8.4,6.6]],"batl":[[1,9.8,2.81],[2,10,8.25]],"ltp":8.6,"tv":507.54,"id":15608820}]}]}
{"op":"mcm","clk":"994808748","pt":1580553834352,"mc":[{"id":"1.168133548","rc":[{"batl":[[2,8,8.41]],"ltp":6.6,"tv":533.45,"id":8231803},{"batl":[[1,9.8,6.36]],"ltp":8.6,"tv":507.54,"id":15608820}]}]}
{"op":"mcm","clk":"994810724","pt":1580553846515,"mc":[{"id":"1.168133548","rc":[{"batl":[[0,9.6,2.53],[1,9.8,1.62]],"ltp":9.0,"tv":1251.38,"id":10616006}]}]}
{"op":"mcm","clk":"994811235","pt":1580553849503,"mc":[{"id":"1.168133548","rc":[{"batl":[[1,7.8,33.13]],"ltp":6.6,"tv":533.45,"id":8231803}]}]}
{"op":"mcm","clk":"994811373","pt":1580553850297,"mc":[{"id":"1.168133548","rc":[{"batl":[[1,8,31.23]],"ltp":7.6,"tv":1085.25,"id":10170404},{"batl":[[1,9.8,5.61]],"ltp":8.6,"tv":507.54,"id":15608820}]}]}
{"op":"mcm","clk":"994811894","pt":1580553853515,"mc":[{"id":"1.168133548","rc":[{"batl":[[1,7.6,5.09],[2,7.8,32.47]],"ltp":6.6,"tv":533.45,"id":8231803}]}]}
{"op":"mcm","clk":"994813702","pt":1580553865108,"mc":[{"id":"1.168133548","rc":[{"batl":[[1,10.5,6.85],[2,11,12.58]],"ltp":9.0,"tv":1251.38,"id":10616006}]}]}
{"op":"mcm","clk":"994814257","pt":1580553868513,"mc":[{"id":"1.168133548","rc":[{"batl":[[2,8,4.87]],"ltp":6.6,"tv":533.45,"id":8231803}]}]}
{"op":"mcm","clk":"994814364","pt":1580553869131,"mc":[{"id":"1.168133548","rc":[{"batl":[[1,7.4,34.22],[2,7.6,5.09]],"ltp":6.6,"tv":533.45,"id":8231803},{"batl":[[1,10,31.66],[2,10.5,6.85]],"ltp":9.0,"tv":1251.38,"id":10616006}]}]}
{"op":"mcm","clk":"994815405","pt":1580553875524,"mc":[{"id":"1.168133548","rc":[{"batl":[[0,9.2,2]],"ltp":8.6,"tv":507.54,"id":15608820}]}]}
{"op":"mcm","clk":"994815564","pt":1580553876531,"mc":[{"id":"1.168133548","rc":[{"batl":[[1,9.6,2.74],[2,9.8,5.61]],"ltp":8.6,"tv":507.54,"id":15608820}]}]}
{"op":"mcm","clk":"994816496","pt":1580553882507,"mc":[{"id":"1.168133548","rc":[{"batl":[[2,10,8.25]],"ltp":8.6,"tv":507.54,"id":15608820}]}]}
{"op":"mcm","clk":"994816996","pt":1580553885531,"mc":[{"id":"1.168133548","rc":[{"batl":[[2,180,2.06]],"ltp":26.0,"tv":127.09,"id":9001159}]}]}
{"op":"mcm","clk":"994818264","pt":1580553893438,"mc":[{"id":"1.168133548","rc":[{"trd":[[8.6,201.93]],"batb":[[0,8.6,7.64]],"ltp":8.6,"tv":510.89,"id":15608820}],"tv":6223.58}]}
{"op":"mcm","clk":"994818769","pt":1580553896528,"mc":[{"id":"1.168133548","rc":[{"batb":[[1,8.4,5.85]],"ltp":8.6,"tv":510.89,"id":15608820}]}]}
{"op":"mcm","clk":"994819461","pt":1580553900542,"mc":[{"id":"1.168133548","rc":[{"batb":[[0,8.6,3.03]],"batl":[[0,9.8,2.53]],"ltp":9.0,"tv":1251.38,"id":10616006}]}]}
{"op":"mcm","clk":"994821848","pt":1580553914175,"mc":[{"id":"1.168133548","rc":[{"batl":[[1,9.4,1.69],[2,9.6,2.74]],"ltp":8.6,"tv":510.89,"id":15608820}]}]}
{"op":"mcm","clk":"994823560","pt":1580553925568,"mc":[{"id":"1.168133548","rc":[{"batl":[[0,9.2,4.74],[2,10,5]],"ltp":8.6,"tv":510.89,"id":15608820}]}]}
{"op":"mcm","clk":"994824302","pt":1580553930367,"mc":[{"id":"1.168133548","rc":[{"batl":[[1,7.2,4.67],[2,7.4,34.22]],"ltp":6.6,"tv":533.45,"id":8231803},{"batl":[[2,9.8,2.81]],"ltp":8.6,"tv":510.89,"id":15608820}]}]}
{"op":"mcm","clk":"994826635","pt":1580553944520,"mc":[{"id":"1.168133548","rc":[{"batl":[[0,9.2,2],[2,9.6,2.74]],"ltp":8.6,"tv":510.89,"id":15608820}]}]}
{"op":"mcm","clk":"994826783","pt":1580553945487,"mc":[{"id":"1.168133548","rc":[{"batl":[[2,8,5.53]],"ltp":6.6,"tv":533.45,"id":8231803}]}]}
{"op":"mcm","clk":"994828730","pt":1580553959514,"mc":[{"id":"1.168133548","rc":[{"batl":[[2,7.8,9.24]],"ltp":6.6,"tv":533.45,"id":8231803},{"batl":[[0,44,1],[1,46,1.89],[2,48,3.03]],"ltp":32.0,"tv":71.32,"id":9193530}]}]}
{"op":"mcm","clk":"994829544","pt":1580553964506,"mc":[{"id":"1.168133548","rc":[{"batl":[[1,10.5,6.85],[2,11,12.58]],"ltp":9.0,"tv":1251.38,"id":10616006}]}]}
{"op":"mcm","clk":"994831067","pt":1580553974342,"mc":[{"id":"1.168133548","rc":[{"batl":[[2,8,5.53]],"ltp":6.6,"tv":533.45,"id":8231803}]}]}
{"op":"mcm","clk":"994831275","pt":1580553975498,"mc":[{"id":"1.168133548","rc":[{"batl":[[0,9.2,4.74],[2,10,5]],"ltp":8.6,"tv":510.89,"id":15608820}]}]}
{"op":"mcm","clk":"994831605","pt":1580553977504,"mc":[{"id":"1.168133548","rc":[{"batl":[[2,10,7.95]],"ltp":8.6,"tv":510.89,"id":15608820}]}]}
{"op":"mcm","clk":"994831887","pt":1580553979438,"mc":[{"id":"1.168133548","rc":[{"batl":[[2,10,5]],"ltp":8.6,"tv":510.89,"id":15608820},{"batl":[[0,44,1.84]],"ltp":32.0,"tv":71.32,"id":9193530}]}]}
{"op":"mcm","clk":"994836123","pt":1580554005460,"mc":[{"id":"1.168133548","rc":[{"batl":[[0,9.2,2],[2,9.8,2.74]],"ltp":8.6,"tv":510.89,"id":15608820}]}]}
{"op":"mcm","clk":"994836653","pt":1580554008533,"mc":[{"id":"1.168133548","rc":[{"batl":[[0,10,2.53]],"ltp":9.0,"tv":1251.38,"id":10616006}]}]}
{"op":"mcm","clk":"994838590","pt":1580554020547,"mc":[{"id":"1.168133548","rc":[{"batl":[[1,7.8,3.71],[2,8,4.87]],"ltp":6.6,"tv":533.45,"id":8231803},{"batl":[[2,90,9.08]],"ltp":32.0,"tv":71.32,"id":9193530}]}]}
{"op":"mcm","clk":"994838787","pt":1580554021556,"mc":[{"id":"1.168133548","rc":[{"batl":[[0,44,4.87]],"ltp":32.0,"tv":71.32,"id":9193530}]}]}
{"op":"mcm","clk":"994839059","pt":1580554023374,"mc":[{"id":"1.168133548","rc":[{"batl":[[1,7.4,34.22],[2,7.8,3.71]],"ltp":6.6,"tv":533.45,"id":8231803},{"batl":[[0,10,34.19]],"ltp":9.0,"tv":1251.38,"id":10616006}]}]}
{"op":"mcm","clk":"994839380","pt":1580554025555,"mc":[{"id":"1.168133548","rc":[{"batl":[[2,9.6,2.74]],"ltp":8.6,"tv":510.89,"id":15608820}]}]}
{"op":"mcm","clk":"994840373","pt":1580554032487,"mc":[{"id":"1.168133548","rc":[{"batl":[[1,6,84.29]],"ltp":5.5,"tv":1386.66,"id":9417341}]}]}
{"op":"mcm","clk":"994841547","pt":1580554040527,"mc":[{"id":"1.168133548","rc":[{"batl":[[1,6,74.29]],"ltp":5.5,"tv":1386.66,"id":9417341}]}]}
{"op":"mcm","clk":"994841673","pt":1580554041282,"mc":[{"id":"1.168133548","rc":[{"batl":[[2,7.8,9.69]],"ltp":6.6,"tv":533.45,"id":8231803}]}]}
{"op":"mcm","clk":"994841854","pt":1580554042401,"mc":[{"id":"1.168133548","rc":[{"batl":[[1,7.8,9.69],[2,8,4.87]],"ltp":6.6,"tv":533.45,"id":8231803}]}]}
{"op":"mcm","clk":"994842038","pt":1580554043520,"mc":[{"id":"1.168133548","rc":[{"batl":[[1,7.6,33.98],[2,7.8,9.03]],"ltp":6.6,"tv":533.45,"id":8231803}]}]}
{"op":"mcm","clk":"994844806","pt":1580554058913,"mc":[{"id":"1.168133548","rc":[{"trd":[[7.6,168.68]],"batb":[[0,7.6,4]],"ltp":7.6,"tv":1089.25,"id":10170404}],"tv":6227.58}]}
{"op":"mcm","clk":"994845622","pt":1580554063431,"mc":[{"id":"1.168133548","rc":[{"batl":[[2,7.8,3.05]],"ltp":6.6,"tv":533.45,"id":8231803}]}]}
{"op":"mcm","clk":"994845812","pt":1580554064517,"mc":[{"id":"1.168133548","rc":[{"batl":[[0,9.2,4.74],[2,10,5]],"ltp":8.6,"tv":510.89,"id":15608820}]}]}
{"op":"mcm","clk":"994847835","pt":1580554075546,"mc":[{"id":"1.168133548","rc":[{"batl":[[0,9.2,2],[2,9.8,2.74]],"ltp":8.6,"tv":510.89,"id":15608820}]}]}
{"op":"mcm","clk":"994852548","pt":1580554109480,"mc":[{"id":"1.168133548","rc":[{"batb":[[1,5.4,5.82]],"ltp":5.8,"tv":702.08,"id":17352128}]}]}
{"op":"mcm","clk":"994853254","pt":1580554114479,"mc":[{"id":"1.168133548","rc":[{"batl":[[2,9.6,2.74]],"ltp":8.6,"tv":510.89,"id":15608820}]}]}
{"op":"mcm","clk":"994853928","pt":1580554119508,"mc":[{"id":"1.168133548","rc":[{"batl":[[1,7.4,4.54],[2,7.6,33.98]],"ltp":6.6,"tv":533.45,"id":8231803}]}]}
{"op":"mcm","clk":"994854839","pt":1580554126237,"mc":[{"id":"1.168133548","rc":[{"trd":[[5.7,39.76]],"batb":[[0,5.4,2.5],[1,5.3,21.44],[2,5.2,9.67]],"batl":[[0,5.7,9.64],[1,5.8,45.42],[2,6,13.37]],"ltp":5.7,"tv":708.8,"id":17352128}],"tv":6234.3}]}
{"op":"mcm","clk":"994855316","pt":1580554129550,"mc":[{"id":"1.168133548","rc":[{"batb":[[0,5.3,17.55],[1,5.2,9.67],[2,5,5.07]],"ltp":5.7,"tv":708.8,"id":17352128}]}]}
{"op":"mcm","clk":"994855461","pt":1580554130547,"mc":[{"id":"1.168133548","rc":[{"batl":[[0,5.7,14.64]],"ltp":5.7,"tv":708.8,"id":17352128}]}]}
{"op":"mcm","clk":"994855578","pt":1580554131549,"mc":[{"id":"1.168133548","rc":[{"batl":[[1,9.6,2.74],[2,10,5]],"ltp":8.6,"tv":510.89,"id":15608820}]}]}
{"op":"mcm","clk":"994856000","pt":1580554134524,"mc":[{"id":"1.168133548","rc":[{"batl":[[0,5.5,5],[1,5.7,9.64],[2,5.8,45.42]],"ltp":5.7,"tv":708.8,"id":17352128}]}]}
{"op":"mcm","clk":"994856090","pt":1580554135065,"mc":[{"id":"1.168133548","rc":[{"batl":[[2,10,7.95]],"ltp":8.6,"tv":510.89,"id":15608820},{"batb":[[0,5.4,8.37],[1,5.3,17.55],[2,5.2,9.67]],"ltp":5.7,"tv":708.8,"id":17352128}]}]}
{"op":"mcm","clk":"994856441","pt":1580554137555,"mc":[{"id":"1.168133548","rc":[{"batl":[[2,8,5.53]],"ltp":6.6,"tv":533.45,"id":8231803},{"batl":[[0,10,2.53]],"ltp":9.0,"tv":1251.38,"id":10616006},{"trd":[[7.6,172.68]],"batb":[[0,7.6,2]],"ltp":7.6,"tv":1093.25,"id":10170404}],"tv":6238.3}]}
{"op":"mcm","clk":"994856573","pt":1580554138449,"mc":[{"id":"1.168133548","rc":[{"batb":[[0,8.6,25.12]],"ltp":9.0,"tv":1251.38,"id":10616006},{"batb":[[1,23,6.76],[2,22,4.81]],"ltp":26.0,"tv":127.09,"id":9001159},{"batl":[[1,5.7,19.64]],"ltp":5.7,"tv":708.8,"id":17352128}]}]}
{"op":"mcm","clk":"994856714","pt":1580554139527,"mc":[{"id":"1.168133548","rc":[{"trd":[[5.4,23.63]],"batb":[[0,5.3,17.55],[1,5.2,9.67],[2,5,5.07]],"batl":[[0,5.6,4.73]],"ltp":5.4,"tv":718.8,"id":17352128}],"tv":6248.3}]}
{"op":"mcm","clk":"994856981","pt":1580554141558,"mc":[{"id":"1.168133548","rc":[{"batb":[[1,23,8.49],[2,22,3]],"ltp":26.0,"tv":127.09,"id":9001159}]}]}
{"op":"mcm","clk":"994857107","pt":1580554142567,"mc":[{"id":"1.168133548","rc":[{"trd":[[11.5,66.67]],"batb":[[0,11.5,10.52]],"ltp":11.5,"tv":559.42,"id":8429550}],"tv":6252.3}]}
{"op":"mcm","clk":"994858647","pt":1580554153545,"mc":[{"id":"1.168133548","rc":[{"trd":[[5.3,20]],"batb":[[0,5.3,7.55]],"batl":[[1,5.7,9.64]],"ltp":5.3,"tv":738.8,"id":17352128}],"tv":6272.3}]}
{"op":"mcm","clk":"994858779","pt":1580554154548,"mc":[{"id":"1.168133548","rc":[{"batl":[[0,9.2,4.74],[1,10,7.95],[2,11,4.59]],"ltp":8.6,"tv":510.89,"id":15608820}]}]}
{"op":"mcm","clk":"994859238","pt":1580554157537,"mc":[{"id":"1.168133548","rc":[{"batb":[[1,23,1.73]],"ltp":26.0,"tv":127.09,"id":9001159}]}]}
{"op":"mcm","clk":"994860198","pt":1580554163475,"mc":[{"id":"1.168133548","rc":[{"batl":[[0,9.2,2]],"ltp":8.6,"tv":510.89,"id":15608820}]}]}
{"op":"mcm","clk":"994860340","pt":1580554164480,"mc":[{"id":"1.168133548","rc":[{"batl":[[1,9.8,2.74],[2,10,7.95]],"ltp":8.6,"tv":510.89,"id":15608820}]}]}
{"op":"mcm","clk":"994860866","pt":1580554168564,"mc":[{"id":"1.168133548","rc":[{"batb":[[0,8.8,2.27],[1,8.6,25.12],[2,8.4,3.3]],"ltp":9.0,"tv":1251.38,"id":10616006}]}]}
{"op":"mcm","clk":"994861915","pt":1580554176489,"mc":[{"id":"1.168133548","rc":[{"batb":[[1,8.6,3.03]],"ltp":9.0,"tv":1251.38,"id":10616006}]}]}
{"op":"mcm","clk":"994862954","pt":1580554183491,"mc":[{"id":"1.168133548","rc":[{"batl":[[1,9.6,2.74]],"ltp":8.6,"tv":510.89,"id":15608820}]}]}
{"op":"mcm","clk":"994865535","pt":1580554203334,"mc":[{"id":"1.168133548","rc":[{"trd":[[5.3,30]],"batb":[[0,5.3,2.55]],"ltp":5.3,"tv":748.8,"id":17352128}],"tv":6282.3}]}
{"op":"mcm","clk":"994867262","pt":1580554214506,"mc":[{"id":"1.168133548","rc":[{"batb":[[0,8.8,23.86]],"ltp":9.0,"tv":1251.38,"id":10616006},{"batl":[[0,9.2,4.74],[1,10,7.95],[2,11,4.59]],"ltp":8.6,"tv":510.89,"id":15608820}]}]}
{"op":"mcm","clk":"994868652","pt":1580554224558,"mc":[{"id":"1.168133548","rc":[{"batl":[[1,9.8,2.81],[2,10,5]],"ltp":8.6,"tv":510.89,"id":15608820}]}]}
{"op":"mcm","clk":"994869173","pt":1580554228539,"mc":[{"id":"1.168133548","rc":[{"batl":[[1,7.8,3.69],[2,8,4.87]],"ltp":6.6,"tv":533.45,"id":8231803},{"trd":[[9,56.78]],"batb":[[0,9,2.5],[1,8.8,23.86]],"batl":[[0,10,2]],"ltp":9.0,"tv":1252.44,"id":10616006}],"tv":6283.36}]}
{"op":"mcm","clk":"994869614","pt":1580554231855,"mc":[{"id":"1.168133548","rc":[{"batb":[[0,11.5,14],[1,11,8.31]],"ltp":11.5,"tv":559.42,"id":8429550},{"batb":[[2,6,32.73]],"ltp":6.6,"tv":533.45,"id":8231803}]}]}
{"op":"mcm","clk":"994869846","pt":1580554233548,"mc":[{"id":"1.168133548","rc":[{"batb":[[1,8.8,2.27],[2,8.2,2]],"batl":[[0,10,5.5]],"ltp":9.0,"tv":1252.44,"id":10616006},{"batl":[[0,9.2,2],[1,9.6,2.74],[2,9.8,2.81]],"ltp":8.6,"tv":510.89,"id":15608820}]}]}
{"op":"mcm","clk":"994870123","pt":1580554235570,"mc":[{"id":"1.168133548","rc":[{"batb":[[0,11.5,3.48]],"ltp":11.5,"tv":559.42,"id":8429550}]}]}
{"op":"mcm","clk":"994870255","pt":1580554236475,"mc":[{"id":"1.168133548","rc":[{"batb":[[0,12,10.07],[1,11.5,3.48],[2,11,8.31]],"ltp":11.5,"tv":559.42,"id":8429550},{"batl":[[2,10,5]],"ltp":8.6,"tv":510.89,"id":15608820}]}]}
{"op":"mcm","clk":"994871239","pt":1580554243351,"mc":[{"id":"1.168133548","rc":[{"batl":[[0,9.2,4.74],[1,10,5],[2,11,4.59]],"ltp":8.6,"tv":510.89,"id":15608820}]}]}
{"op":"mcm","clk":"994871795","pt":1580554247283,"mc":[{"id":"1.168133548","rc":[{"batb":[[0,7.6,5]],"ltp":7.6,"tv":1093.25,"id":10170404}]}]}
{"op":"mcm","clk":"994872629","pt":1580554253477,"mc":[{"id":"1.168133548","rc":[{"batl":[[0,9.2,2],[1,9.8,5.55],[2,10,5]],"ltp":8.6,"tv":510.89,"id":15608820}]}]}
{"op":"mcm","clk":"994872709","pt":1580554254061,"mc":[{"id":"1.168133548","rc":[{"batl":[[0,12.5,57.74]],"ltp":11.5,"tv":559.42,"id":8429550},{"batl":[[0,5.9,29.25]],"ltp":5.5,"tv":1386.66,"id":9417341},{"batl":[[0,7,9.87]],"ltp":6.6,"tv":533.45,"id":8231803},{"batl":[[0,10,11.01]],"ltp":9.0,"tv":1252.44,"id":10616006},{"batl":[[0,7.8,14.51]],"ltp":7.6,"tv":1093.25,"id":10170404},{"batl":[[0,9.2,7.99]],"ltp":8.6,"tv":510.89,"id":15608820},{"batl":[[0,5.6,14.57]],"ltp":5.3,"tv":748.8,"id":17352128}]}]}
{"op":"mcm","clk":"994873552","pt":1580554260483,"mc":[{"id":"1.168133548","rc":[{"batl":[[0,12.5,53.33]],"ltp":11.5,"tv":559.42,"id":8429550},{"batl":[[0,5.9,19.91]],"ltp":5.5,"tv":1386.66,"id":9417341},{"batl":[[0,7,2]],"ltp":6.6,"tv":533.45,"id":8231803},{"batl":[[0,10,5.5]],"ltp":9.0,"tv":1252.44,"id":10616006},{"batl":[[0,7.8,7.45]],"ltp":7.6,"tv":1093.25,"id":10170404},{"batl":[[0,9.2,2]],"ltp":8.6,"tv":510.89,"id":15608820},{"batl":[[0,5.6,4.73]],"ltp":5.3,"tv":748.8,"id":17352128}]}]}
{"op":"mcm","clk":"994874281","pt":1580554265565,"mc":[{"id":"1.168133548","rc":[{"batl":[[1,9.8,2.74]],"ltp":8.6,"tv":510.89,"id":15608820}]}]}
{"op":"mcm","clk":"994875340","pt":1580554273497,"mc":[{"id":"1.168133548","rc":[{"batl":[[1,9.6,2.74]],"ltp":8.6,"tv":510.89,"id":15608820}]}]}
{"op":"mcm","clk":"994875591","pt":1580554275504,"mc":[{"id":"1.168133548","rc":[{"batb":[[0,9.2,2.17],[1,9,2.5]],"ltp":9.0,"tv":1252.44,"id":10616006}]}]}
{"op":"mcm","clk":"994879121","pt":1580554301511,"mc":[{"id":"1.168133548","rc":[{"trd":[[6.4,61.22],[6.6,43.06]],"batb":[[0,6.4,11.87]],"ltp":6.4,"tv":539.43,"id":8231803}],"tv":6289.34}]}
{"op":"mcm","clk":"994879364","pt":1580554303440,"mc":[{"id":"1.168133548","rc":[{"batl":[[0,9.2,4.74],[1,10,5],[2,11,4.59]],"ltp":8.6,"tv":510.89,"id":15608820}]}]}
{"op":"mcm","clk":"994879925","pt":1580554308348,"mc":[{"id":"1.168133548","rc":[{"batb":[[2,6,29.73]],"ltp":6.4,"tv":539.43,"id":8231803}]}]}
{"op":"mcm","clk":"994880051","pt":1580554309548,"mc":[{"id":"1.168133548","rc":[{"trd":[[12,118.36]],"batb":[[0,12,8.07]],"ltp":12.0,"tv":563.42,"id":8429550}],"tv":6293.34}]}
{"op":"mcm","clk":"994880150","pt":1580554310551,"mc":[{"id":"1.168133548","rc":[{"batb":[[1,6.2,17.6]],"ltp":6.4,"tv":539.43,"id":8231803},{"batl":[[1,9.8,2.81],[2,10,5]],"ltp":8.6,"tv":510.89,"id":15608820}]}]}
{"op":"mcm","clk":"994880614","pt":1580554314447,"mc":[{"id":"1.168133548","rc":[{"trd":[[29,2.86],[30,1.31]],"batb":[[0,29,1.88]],"ltp":29.0,"tv":75.32,"id":9193530}],"tv":6297.34}]}
{"op":"mcm","clk":"994880880","pt":1580554316554,"mc":[{"id":"1.168133548","rc":[{"trd":[[7.6,182.68]],"batb":[[0,7.4,13.01],[1,7.2,26.55],[2,7,23]],"ltp":7.6,"tv":1103.25,"id":10170404}],"tv":6307.34}]}
{"op":"mcm","clk":"994881020","pt":1580554317556,"mc":[{"id":"1.168133548","rc":[{"batl":[[1,9.8,6.36]],"ltp":8.6,"tv":510.89,"id":15608820},{"batb":[[2,21,6.54]],"ltp":29.0,"tv":75.32,"id":9193530}]}]}
{"op":"mcm","clk":"994881393","pt":1580554320426,"mc":[{"id":"1.168133548","rc":[{"batb":[[0,29,1.38],[1,26,2.17]],"ltp":29.0,"tv":75.32,"id":9193530}]}]}
{"op":"mcm","clk":"994881670","pt":1580554322536,"mc":[{"id":"1.168133548","rc":[{"batl":[[1,7.4,2.15],[2,7.8,3.69]],"ltp":6.4,"tv":539.43,"id":8231803}]}]}
{"op":"mcm","clk":"994881941","pt":1580554324547,"mc":[{"id":"1.168133548","rc":[{"batl":[[1,8,28.38],[2,8.2,20]],"ltp":7.6,"tv":1103.25,"id":10170404}]}]}
{"op":"mcm","clk":"994882077","pt":1580554325561,"mc":[{"id":"1.168133548","rc":[{"batb":[[2,21,7.38]],"batl":[[0,44,4.99],[1,46,1.78]],"ltp":29.0,"tv":75.32,"id":9193530}]}]}
{"op":"mcm","clk":"994882194","pt":1580554326460,"mc":[{"id":"1.168133548","rc":[{"batb":[[2,21,7.61]],"ltp":29.0,"tv":75.32,"id":9193530}]}]}
{"op":"mcm","clk":"994882549","pt":1580554328366,"mc":[{"id":"1.168133548","rc":[{"batl":[[0,7.8,10.3],[1,8,31.23],[2,8.2,22.85]],"ltp":7.6,"tv":1103.25,"id":10170404}]}]}
{"op":"mcm","clk":"994882810","pt":1580554329365,"mc":[{"id":"1.168133548","rc":[{"batb":[[0,9,2.5],[1,8.2,7.31],[2,8,15.31]],"ltp":9.0,"tv":1252.44,"id":10616006},{"batb":[[2,21,1.07]],"ltp":29.0,"tv":75.32,"id":9193530}]}]}
{"op":"mcm","clk":"994883584","pt":1580554333551,"mc":[{"id":"1.168133548","rc":[{"batb":[[2,20,2.23]],"ltp":29.0,"tv":75.32,"id":9193530}]}]}
{"op":"mcm","clk":"994884115","pt":1580554337548,"mc":[{"id":"1.168133548","rc":[{"batb":[[2,8.2,9.19]],"ltp":8.6,"tv":510.89,"id":15608820}]}]}
{"op":"mcm","clk":"994884336","pt":1580554339339,"mc":[{"id":"1.168133548","rc":[{"batl":[[0,5.9,5.91]],"ltp":5.5,"tv":1386.66,"id":9417341}]}]}
{"op":"mcm","clk":"994884768","pt":1580554342449,"mc":[{"id":"1.168133548","rc":[{"batl":[[0,5.9,19.91]],"ltp":5.5,"tv":1386.66,"id":9417341}]}]}
{"op":"mcm","clk":"994884927","pt":1580554343457,"mc":[{"id":"1.168133548","rc":[{"batb":[[0,7.4,18.41],[1,7.2,21]],"ltp":7.6,"tv":1103.25,"id":10170404}]}]}
{"op":"mcm","clk":"994885219","pt":1580554345527,"mc":[{"id":"1.168133548","rc":[{"batb":[[1,7.2,26.36]],"ltp":7.6,"tv":1103.25,"id":10170404}]}]}
{"op":"mcm","clk":"994885671","pt":1580554348547,"mc":[{"id":"1.168133548","rc":[{"batb":[[1,8.4,22.62],[2,8.2,7.31]],"ltp":9.0,"tv":1252.44,"id":10616006}]}]}
{"op":"mcm","clk":"994896847","pt":1580554353260,"mc":[{"id":"1.168133548","rc":[{"batl":[[0,9.2,2],[1,9.6,2.74],[2,9.8,6.36]],"ltp":8.6,"tv":510.89,"id":15608820}]}]}
{"op":"mcm","clk":"994897884","pt":1580554361272,"mc":[{"id":"1.168133548","rc":[{"batl":[[2,10,5]],"ltp":8.6,"tv":510.89,"id":15608820}]}]}
{"op":"mcm","clk":"994898117","pt":1580554363168,"mc":[{"id":"1.168133548","rc":[{"batl":[[0,9.2,4.74],[1,10,5],[2,11,4.59]],"ltp":8.6,"tv":510.89,"id":15608820}]}]}
{"op":"mcm","clk":"994899045","pt":1580554370379,"mc":[{"id":"1.168133548","rc":[{"batb":[[0,8.4,22.62],[1,8.2,7.31],[2,8,15.31]],"ltp":9.0,"tv":1252.44,"id":10616006}]}]}
{"op":"mcm","clk":"994899196","pt":1580554371471,"mc":[{"id":"1.168133548","rc":[{"batl":[[1,9.8,2.81],[2,10,5]],"ltp":8.6,"tv":510.89,"id":15608820}]}]}
{"op":"mcm","clk":"994900010","pt":1580554377460,"mc":[{"id":"1.168133548","rc":[{"batb":[[2,6,21.08]],"ltp":6.4,"tv":539.43,"id":8231803}]}]}
{"op":"mcm","clk":"994900629","pt":1580554382409,"mc":[{"id":"1.168133548","rc":[{"batl":[[0,9.2,2],[1,9.6,2.74],[2,9.8,2.81]],"ltp":8.6,"tv":510.89,"id":15608820}]}]}
{"op":"mcm","clk":"994900788","pt":1580554383568,"mc":[{"id":"1.168133548","rc":[{"batb":[[1,5.4,7.41],[2,5.3,22.88]],"ltp":5.5,"tv":1386.66,"id":9417341}]}]}
{"op":"mcm","clk":"994901000","pt":1580554385317,"mc":[{"id":"1.168133548","rc":[{"batb":[[1,8.2,2]],"ltp":9.0,"tv":1252.44,"id":10616006},{"batl":[[0,7.8,11.78]],"ltp":7.6,"tv":1103.25,"id":10170404},{"batl":[[2,10,5]],"ltp":8.6,"tv":510.89,"id":15608820}]}]}
{"op":"mcm","clk":"994901156","pt":1580554386481,"mc":[{"id":"1.168133548","rc":[{"batb":[[0,8.2,2],[1,8,15.31],[2,7.8,5.13]],"ltp":9.0,"tv":1252.44,"id":10616006}]}]}
{"op":"mcm","clk":"994901285","pt":1580554387408,"mc":[{"id":"1.168133548","rc":[{"batb":[[0,8.4,3.3],[1,8.2,25.17],[2,8,15.31]],"batl":[[0,10,2],[2,11,14.87]],"ltp":9.0,"tv":1252.44,"id":10616006}]}]}
{"op":"mcm","clk":"994901598","pt":1580554390079,"mc":[{"id":"1.168133548","rc":[{"batl":[[0,7.8,10.3]],"ltp":7.6,"tv":1103.25,"id":10170404}]}]}
{"op":"mcm","clk":"994901872","pt":1580554392219,"mc":[{"id":"1.168133548","rc":[{"batl":[[2,11,21.87]],"ltp":9.0,"tv":1252.44,"id":10616006}]}]}
{"op":"mcm","clk":"994903528","pt":1580554405417,"mc":[{"id":"1.168133548","rc":[{"batb":[[1,8.2,2]],"ltp":9.0,"tv":1252.44,"id":10616006},{"trd":[[5.6,20.32]],"batl":[[0,5.6,2.57]],"ltp":5.6,"tv":753.12,"id":17352128}],"tv":6311.66}]}
{"op":"mcm","clk":"994903576","pt":1580554405831,"mc":[{"id":"1.168133548","rc":[{"batb":[[0,8.4,25.92]],"ltp":9.0,"tv":1252.44,"id":10616006}]}]}
{"op":"mcm","clk":"994904039","pt":1580554409543,"mc":[{"id":"1.168133548","rc":[{"batb":[[2,8,20.87]],"ltp":9.0,"tv":1252.44,"id":10616006}]}]}
{"op":"mcm","clk":"994905519","pt":1580554420551,"mc":[{"id":"1.168133548","rc":[{"batl":[[0,5.8,2],[1,5.9,19.91],[2,6,74.29]],"ltp":5.5,"tv":1386.66,"id":9417341}]}]}
{"op":"mcm","clk":"994905781","pt":1580554422514,"mc":[{"id":"1.168133548","rc":[{"trd":[[5.5,58.34]],"batb":[[0,5.5,24.63]],"ltp":5.5,"tv":1394.75,"id":9417341},{"trd":[[6.4,68.18]],"batb":[[0,6.4,8.39]],"ltp":6.4,"tv":546.39,"id":8231803},{"trd":[[8.4,93.74]],"batb":[[0,8.4,23.27]],"ltp":8.4,"tv":1257.74,"id":10616006},{"trd":[[7.4,57.53]],"batb":[[0,7.4,15.4]],"ltp":7.4,"tv":1109.27,"id":10170404},{"trd":[[8.6,207.11]],"batb":[[0,8.6,5.05]],"batl":[[1,10,5],[2,11,4.59]],"ltp":8.6,"tv":516.07,"id":15608820},{"trd":[[5.3,35.1]],"batb":[[0,5.2,11.67],[1,5,5.07],[2,4.9,5]],"batl":[[0,5.3,1.66],[1,5.6,2.57],[2,5.7,9.64]],"ltp":5.3,"tv":758.22,"id":17352128}],"tv":6348.32}]}
{"op":"mcm","clk":"994905943","pt":1580554423522,"mc":[{"id":"1.168133548","rc":[{"batl":[[0,9.2,4.74]],"ltp":8.6,"tv":516.07,"id":15608820}]}]}
{"op":"mcm","clk":"994906068","pt":1580554424321,"mc":[{"id":"1.168133548","rc":[{"batb":[[2,8,17.87]],"ltp":8.4,"tv":1257.74,"id":10616006},{"batb":[[1,7.2,21]],"ltp":7.4,"tv":1109.27,"id":10170404},{"batb":[[1,8.4,4.28]],"ltp":8.6,"tv":516.07,"id":15608820},{"trd":[[5.3,38.42]],"batb":[[0,5.2,9.67],[1,5,11.46]],"batl":[[0,5.6,4.14],[1,5.7,9.64],[2,5.8,45.42]],"ltp":5.3,"tv":761.54,"id":17352128}],"tv":6351.64}]}
{"op":"mcm","clk":"994906201","pt":1580554425219,"mc":[{"id":"1.168133548","rc":[{"batl":[[1,10,7.47]],"ltp":8.6,"tv":516.07,"id":15608820}]}]}
{"op":"mcm","clk":"994906397","pt":1580554426544,"mc":[{"id":"1.168133548","rc":[{"batb":[[0,8.2,25.82],[1,8,17.87],[2,7.8,5.13]],"ltp":8.4,"tv":1257.74,"id":10616006}]}]}
{"op":"mcm","clk":"994907108","pt":1580554431445,"mc":[{"id":"1.168133548","rc":[{"batl":[[0,10,5.71]],"ltp":8.4,"tv":1257.74,"id":10616006}]}]}
{"op":"mcm","clk":"994907759","pt":1580554436378,"mc":[{"id":"1.168133548","rc":[{"batb":[[0,8.4,3.03],[1,8.2,25.17],[2,8,12.31]],"ltp":8.4,"tv":1257.74,"id":10616006},{"batl":[[1,10,5]],"ltp":8.6,"tv":516.07,"id":15608820}]}]}
{"op":"mcm","clk":"994908126","pt":1580554439067,"mc":[{"id":"1.168133548","rc":[{"batl":[[0,9.8,1.62],[1,10,5.71],[2,10.5,6.85]],"ltp":8.4,"tv":1257.74,"id":10616006}]}]}
{"op":"mcm","clk":"994908576","pt":1580554442567,"mc":[{"id":"1.168133548","rc":[{"batl":[[0,9.2,2],[1,9.8,6.29],[2,10,5]],"ltp":8.6,"tv":516.07,"id":15608820}]}]}
{"op":"mcm","clk":"994908948","pt":1580554445473,"mc":[{"id":"1.168133548","rc":[{"batb":[[1,8.2,2]],"ltp":8.4,"tv":1257.74,"id":10616006}]}]}
{"op":"mcm","clk":"994909797","pt":1580554451500,"mc":[{"id":"1.168133548","rc":[{"batl":[[0,9.8,4.89],[2,10.5,2]],"ltp":8.4,"tv":1257.74,"id":10616006}]}]}
{"op":"mcm","clk":"994909934","pt":1580554452557,"mc":[{"id":"1.168133548","rc":[{"batl":[[1,10,2]],"ltp":8.4,"tv":1257.74,"id":10616006},{"batl":[[1,9.8,2.74]],"ltp":8.6,"tv":516.07,"id":15608820}]}]}
{"op":"mcm","clk":"994911552","pt":1580554463493,"mc":[{"id":"1.168133548","rc":[{"batl":[[1,9.6,1.66],[2,9.8,2.74]],"ltp":8.6,"tv":516.07,"id":15608820}]}]}
{"op":"mcm","clk":"994912667","pt":1580554471409,"mc":[{"id":"1.168133548","rc":[{"batb":[[0,5.6,8.05],[1,5.5,24.63],[2,5.4,7.41]],"batl":[[0,5.7,2],[1,5.8,2],[2,5.9,19.91]],"ltp":5.5,"tv":1394.75,"id":9417341}]}]}
{"op":"mcm","clk":"994913118","pt":1580554474525,"mc":[{"id":"1.168133548","rc":[{"batl":[[2,5.9,5.91]],"ltp":5.5,"tv":1394.75,"id":9417341}]}]}
{"op":"mcm","clk":"994914357","pt":1580554482559,"mc":[{"id":"1.168133548","rc":[{"batb":[[1,5.5,17.36]],"batl":[[0,5.8,2],[1,5.9,5.91],[2,6,74.29]],"ltp":5.5,"tv":1394.75,"id":9417341}]}]}
{"op":"mcm","clk":"994914468","pt":1580554483358,"mc":[{"id":"1.168133548","rc":[{"batb":[[0,5.6,15.19]],"ltp":5.5,"tv":1394.75,"id":9417341}]}]}
{"op":"mcm","clk":"994914857","pt":1580554486154,"mc":[{"id":"1.168133548","rc":[{"batb":[[0,7.6,6],[1,7.4,15.4],[2,7.2,21]],"ltp":7.4,"tv":1109.27,"id":10170404}]}]}
{"op":"mcm","clk":"994915347","pt":1580554489370,"mc":[{"id":"1.168133548","rc":[{"batl":[[0,9.6,2],[1,9.8,4.89]],"ltp":8.4,"tv":1257.74,"id":10616006}]}]}
{"op":"mcm","clk":"994917883","pt":1580554505382,"mc":[{"id":"1.168133548","rc":[{"batl":[[1,6,74.29],[2,6.2,44.16]],"ltp":5.5,"tv":1394.75,"id":9417341},{"batb":[[1,8.2,5.03]],"batl":[[1,9.8,1.62],[2,10.5,7.2]],"ltp":8.4,"tv":1257.74,"id":10616006}]}]}
{"op":"mcm","clk":"994918476","pt":1580554508569,"mc":[{"id":"1.168133548","rc":[{"trd":[[8.4,99.8]],"batb":[[0,8.2,5.03],[1,8,12.31],[2,7.8,5.13]],"batl":[[0,8.4,1.97],[1,9.6,2],[2,9.8,1.62]],"ltp":8.4,"tv":1263.8,"id":10616006}],"tv":6357.7}]}
{"op":"mcm","clk":"994918631","pt":1580554509483,"mc":[{"id":"1.168133548","rc":[{"trd":[[8.4,103.74]],"batb":[[0,8.2,5.06]],"batl":[[0,9.6,2],[1,9.8,1.62],[2,10.5,7.2]],"ltp":8.4,"tv":1267.74,"id":10616006}],"tv":6361.64}]}
{"op":"mcm","clk":"994918760","pt":1580554510306,"mc":[{"id":"1.168133548","rc":[{"batb":[[0,8.2,5.66]],"batl":[[2,10,3.5]],"ltp":8.4,"tv":1267.74,"id":10616006}]}]}
{"op":"mcm","clk":"994919331","pt":1580554514109,"mc":[{"id":"1.168133548","rc":[{"trd":[[7.6,186.68]],"batb":[[0,7.6,4]],"ltp":7.6,"tv":1113.27,"id":10170404}],"tv":6365.64}]}
{"op":"mcm","clk":"994920034","pt":1580554518463,"mc":[{"id":"1.168133548","rc":[{"trd":[[12.5,44.67]],"batl":[[0,12.5,50.33]],"ltp":12.5,"tv":569.42,"id":8429550},{"trd":[[7.8,62.17]],"batl":[[0,7.8,8.36]],"ltp":7.8,"tv":1117.15,"id":10170404}],"tv":6375.52}]}
{"op":"mcm","clk":"994920484","pt":1580554521371,"mc":[{"id":"1.168133548","rc":[{"batl":[[1,9.6,4.4],[2,10,5]],"ltp":8.6,"tv":516.07,"id":15608820}]}]}
{"op":"mcm","clk":"994921068","pt":1580554524564,"mc":[{"id":"1.168133548","rc":[{"batl":[[2,10.5,7.2]],"ltp":8.4,"tv":1267.74,"id":10616006}]}]}
{"op":"mcm","clk":"994922089","pt":1580554530795,"mc":[{"id":"1.168133548","rc":[{"batl":[[0,9.2,4.74],[1,9.6,1.66]],"ltp":8.6,"tv":516.07,"id":15608820}]}]}
{"op":"mcm","clk":"994924068","pt":1580554542362,"mc":[{"id":"1.168133548","rc":[{"batl":[[2,9.8,3.55]],"ltp":8.6,"tv":516.07,"id":15608820}]}]}
{"op":"mcm","clk":"994924440","pt":1580554544390,"mc":[{"id":"1.168133548","rc":[{"trd":[[5.6,70.75]],"batb":[[0,5.6,2.52]],"ltp":5.6,"tv":1420.09,"id":9417341}],"tv":6400.85}]}
{"op":"mcm","clk":"994925610","pt":1580554551489,"mc":[{"id":"1.168133548","rc":[{"batl":[[1,6,84.29]],"ltp":5.6,"tv":1420.09,"id":9417341}]}]}
{"op":"mcm","clk":"994927819","pt":1580554563746,"mc":[{"id":"1.168133548","rc":[{"batl":[[1,5.9,5.73],[2,6,84.29]],"ltp":5.6,"tv":1420.09,"id":9417341}]}]}
{"op":"mcm","clk":"994928760","pt":1580554569535,"mc":[{"id":"1.168133548","rc":[{"batl":[[0,9.2,2]],"ltp":8.6,"tv":516.07,"id":15608820}]}]}
{"op":"mcm","clk":"994928943","pt":1580554570549,"mc":[{"id":"1.168133548","rc":[{"batl":[[1,9.6,4.4]],"ltp":8.6,"tv":516.07,"id":15608820}]}]}
{"op":"mcm","clk":"994929108","pt":1580554571524,"mc":[{"id":"1.168133548","rc":[{"trd":[[12.5,44.75]],"batl":[[0,12.5,50.29]],"ltp":12.5,"tv":569.5,"id":8429550},{"batl":[[2,10,5]],"ltp":8.6,"tv":516.07,"id":15608820}],"tv":6400.93}]}
{"op":"mcm","clk":"994930823","pt":1580554581439,"mc":[{"id":"1.168133548","rc":[{"trd":[[12,127.3]],"batb":[[0,12,3.6]],"ltp":12.0,"tv":578.44,"id":8429550},{"batl":[[0,5.8,11.25]],"ltp":5.6,"tv":1420.09,"id":9417341},{"batl":[[0,6.8,7.89],[1,7,2],[2,7.4,2.15]],"ltp":6.4,"tv":546.39,"id":8231803},{"batl":[[0,9.6,7.59]],"ltp":8.4,"tv":1267.74,"id":10616006},{"trd":[[7.6,194.68]],"batb":[[0,7.4,15.4],[1,7.2,21],[2,7,23]],"batl":[[0,7.6,3.06],[1,7.8,8.36],[2,8,31.23]],"ltp":7.6,"tv":1125.15,"id":10170404},{"batl":[[0,9,5.96],[1,9.2,2],[2,9.6,4.4]],"ltp":8.6,"tv":516.07,"id":15608820},{"batl":[[0,5.5,9.76],[1,5.6,4.14],[2,5.7,9.64]],"ltp":5.3,"tv":761.54,"id":17352128}],"tv":6417.87}]}
{"op":"mcm","clk":"994931001","pt":1580554582545,"mc":[{"id":"1.168133548","rc":[{"batb":[[0,5.6,5.89]],"ltp":5.6,"tv":1420.09,"id":9417341},{"batb":[[0,6.6,2.86],[1,6.4,8.39],[2,6.2,17.6]],"ltp":6.4,"tv":546.39,"id":8231803},{"trd":[[7.6,200.8]],"batl":[[0,7.8,8.36],[1,8,31.23],[2,8.2,22.85]],"ltp":7.6,"tv":1131.27,"id":10170404},{"batb":[[0,5.3,3.56],[1,5.2,9.67],[2,5,13.46]],"ltp":5.3,"tv":761.54,"id":17352128}],"tv":6424.0}]}
{"op":"mcm","clk":"994931191","pt":1580554583557,"mc":[{"id":"1.168133548","rc":[{"batb":[[0,12,5.17]],"ltp":12.0,"tv":578.44,"id":8429550},{"batb":[[0,8.6,2.29],[1,8.2,5.66],[2,8,12.31]],"batl":[[0,9.4,6.52],[1,9.6,7.59],[2,9.8,1.62]],"ltp":8.4,"tv":1267.74,"id":10616006},{"batb":[[0,8.6,7.25]],"ltp":8.6,"tv":516.07,"id":15608820},{"batb":[[1,27,1.66],[2,26,1.67]],"ltp":29.0,"tv":75.32,"id":9193530},{"batb":[[1,23,2.52]],"ltp":26.0,"tv":127.09,"id":9001159}]}]}
{"op":"mcm","clk":"994931543","pt":1580554585565,"mc":[{"id":"1.168133548","rc":[{"batl":[[2,7.4,7.34]],"ltp":6.4,"tv":546.39,"id":8231803},{"batl":[[2,9.6,7.86]],"ltp":8.6,"tv":516.07,"id":15608820}]}]}
{"op":"mcm","clk":"994931693","pt":1580554586464,"mc":[{"id":"1.168133548","rc":[{"batl":[[2,7.4,2.15]],"ltp":6.4,"tv":546.39,"id":8231803}]}]}
{"op":"mcm","clk":"994932261","pt":1580554589554,"mc":[{"id":"1.168133548","rc":[{"batl":[[0,8.8,2.74],[1,9,5.96],[2,9.2,2]],"ltp":8.6,"tv":516.07,"id":15608820},{"batb":[[0,30,2],[1,29,1.38],[2,27,1.66]],"ltp":29.0,"tv":75.32,"id":9193530}]}]}
{"op":"mcm","clk":"994932423","pt":1580554590569,"mc":[{"id":"1.168133548","rc":[{"batl":[[2,7.4,9.5]],"ltp":6.4,"tv":546.39,"id":8231803},{"batb":[[2,5,7.07]],"ltp":5.3,"tv":761.54,"id":17352128}]}]}
{"op":"mcm","clk":"994932597","pt":1580554591538,"mc":[{"id":"1.168133548","rc":[{"batl":[[0,5.8,13.25]],"ltp":5.6,"tv":1420.09,"id":9417341},{"batl":[[2,7.4,2.15]],"ltp":6.4,"tv":546.39,"id":8231803},{"batb":[[0,7.6,5],[1,7.4,15.4],[2,7.2,21]],"ltp":7.6,"tv":1131.27,"id":10170404},{"batb":[[2,27,4.04]],"ltp":29.0,"tv":75.32,"id":9193530}]}]}
