{"op":"mcm","clk":"991080550","pt":1580501464144,"mc":[{"id":"1.168133548","rc":[{"batl":[[1,13,10],[2,18.5,1.53]],"ltp":9.0,"tv":118.63,"id":15608820}]}]}
{"op":"mcm","clk":"991085177","pt":1580501492823,"mc":[{"id":"1.168133548","rc":[{"batl":[[0,11.5,2.2],[1,12.5,3.8],[2,13,10]],"ltp":9.0,"tv":118.63,"id":15608820}]}]}
{"op":"mcm","clk":"991086893","pt":1580501503134,"mc":[{"id":"1.168133548","rc":[{"batl":[[0,12,2.2]],"ltp":9.0,"tv":118.63,"id":15608820}]}]}
{"op":"mcm","clk":"991087122","pt":1580501504582,"mc":[{"id":"1.168133548","rc":[{"batl":[[0,12,5.29]],"ltp":9.0,"tv":118.63,"id":15608820}]}]}
{"op":"mcm","clk":"991090630","pt":1580501525549,"mc":[{"id":"1.168133548","rc":[{"batl":[[1,13,10],[2,18.5,1.53]],"ltp":9.0,"tv":118.63,"id":15608820}]}]}
{"op":"mcm","clk":"991090644","pt":1580501525663,"mc":[{"id":"1.168133548","rc":[{"batl":[[0,11.5,3.23],[1,12,5.09],[2,13,10]],"ltp":9.0,"tv":118.63,"id":15608820}]}]}
{"op":"mcm","clk":"991093762","pt":1580501544156,"mc":[{"id":"1.168133548","rc":[{"batl":[[1,12,2]],"ltp":9.0,"tv":118.63,"id":15608820}]}]}
{"op":"mcm","clk":"991096017","pt":1580501557327,"mc":[{"id":"1.168133548","rc":[{"batl":[[0,11,2.2],[1,11.5,3.03]],"ltp":9.0,"tv":118.63,"id":15608820}]}]}
{"op":"mcm","clk":"991096866","pt":1580501562440,"mc":[{"id":"1.168133548","rc":[{"batl":[[1,12.5,3.8]],"ltp":9.0,"tv":118.63,"id":15608820}]}]}
{"op":"mcm","clk":"991097145","pt":1580501564139,"mc":[{"id":"1.168133548","rc":[{"batl":[[1,12,3.09],[2,12.5,3.8]],"ltp":9.0,"tv":118.63,"id":15608820}]}]}
{"op":"mcm","clk":"991097595","pt":1580501566849,"mc":[{"id":"1.168133548","rc":[{"batb":[[0,5.8,4.5],[1,5.7,5.99]],"ltp":6.0,"tv":84.25,"id":9417341},{"batb":[[0,6.8,4.33]],"ltp":7.4,"tv":9.24,"id":10170404},{"batb":[[0,8.6,1.98],[1,8.4,5.55],[2,8.2,1.55]],"ltp":9.0,"tv":118.63,"id":15608820},{"batb":[[1,8.8,1.98],[2,8.6,1.48]],"ltp":9.0,"tv":6.0,"id":9193530},{"batb":[[0,10,1.98],[1,9.8,1.8],[2,9.6,4.6]],"ltp":0.0,"tv":0.0,"id":9001159},{"batb":[[0,5.8,3.97],[2,5.5,2.52]],"ltp":5.7,"tv":24.02,"id":17352128}]}]}
{"op":"mcm","clk":"991098358","pt":1580501571745,"mc":[{"id":"1.168133548","rc":[{"batl":[[0,13,15],[1,13.5,3],[2,14.5,1.35]],"ltp":8.8,"tv":20.0,"id":10616006}]}]}
{"op":"mcm","clk":"991099848","pt":1580501581789,"mc":[{"id":"1.168133548","rc":[{"batb":[[0,6.8,6.85]],"ltp":7.4,"tv":9.24,"id":10170404}]}]}
{"op":"mcm","clk":"991100248","pt":1580501584465,"mc":[{"id":"1.168133548","rc":[{"batl":[[0,12.5,2.97],[1,13,15],[2,13.5,3]],"ltp":8.8,"tv":20.0,"id":10616006}]}]}
{"op":"mcm","clk":"991103535","pt":1580501604553,"mc":[{"id":"1.168133548","rc":[{"trd":[[5.9,6.06]],"batb":[[1,5.7,2.81]],"batl":[[0,5.9,4.47]],"ltp":5.9,"tv":90.3,"id":9417341},{"batl":[[1,11.5,3.03],[2,12,3.09]],"ltp":9.0,"tv":118.63,"id":15608820}],"tv":272.21}]}
{"op":"mcm","clk":"991103677","pt":1580501605365,"mc":[{"id":"1.168133548","rc":[{"batl":[[0,12.5,4.54]],"ltp":8.8,"tv":20.0,"id":10616006},{"batb":[[1,6.4,5.52],[2,6,3.35]],"batl":[[2,8.4,8]],"ltp":7.4,"tv":9.24,"id":10170404}]}]}
{"op":"mcm","clk":"991104539","pt":1580501610552,"mc":[{"id":"1.168133548","rc":[{"batb":[[2,9.6,2.52]],"ltp":0.0,"tv":0.0,"id":9001159}]}]}
{"op":"mcm","clk":"991106462","pt":1580501622374,"mc":[{"id":"1.168133548","rc":[{"batl":[[0,12,15],[1,12.5,4.54]],"ltp":8.8,"tv":20.0,"id":10616006}]}]}
{"op":"mcm","clk":"991106624","pt":1580501623484,"mc":[{"id":"1.168133548","rc":[{"batl":[[1,12.5,1.57]],"ltp":8.8,"tv":20.0,"id":10616006},{"batl":[[2,13,10]],"ltp":9.0,"tv":118.63,"id":15608820}]}]}
{"op":"mcm","clk":"991107435","pt":1580501628427,"mc":[{"id":"1.168133548","rc":[{"trd":[[12,6.08]],"batl":[[0,12,11.96],[1,13.5,3],[2,15,5]],"ltp":12.0,"tv":26.07,"id":10616006},{"batl":[[1,12.5,3.8]],"ltp":9.0,"tv":118.63,"id":15608820}],"tv":278.29}]}
{"op":"mcm","clk":"991108596","pt":1580501635407,"mc":[{"id":"1.168133548","rc":[{"trd":[[5.9,15],[6,110.06]],"batb":[[0,6,22.63],[1,5.8,4.5],[2,5.7,2.81]],"batl":[[0,6.2,38.77],[1,6.4,35.07],[2,6.8,1.25]],"ltp":6.0,"tv":179.04,"id":9417341}],"tv":367.03}]}
{"op":"mcm","clk":"991109610","pt":1580501641511,"mc":[{"id":"1.168133548","rc":[{"batl":[[2,14.5,3.86]],"ltp":12.0,"tv":26.07,"id":10616006}]}]}
{"op":"mcm","clk":"991109843","pt":1580501642816,"mc":[{"id":"1.168133548","rc":[{"batb":[[0,8.4,6.68]],"ltp":12.0,"tv":26.07,"id":10616006},{"batl":[[1,12,3.09],[2,12.5,3.8]],"ltp":9.0,"tv":118.63,"id":15608820}]}]}
{"op":"mcm","clk":"991112345","pt":1580501657630,"mc":[{"id":"1.168133548","rc":[{"trd":[[6.6,7.81]],"batb":[[0,6.4,6.36],[1,6,3.33],[2,5.9,3.03]],"batl":[[0,6.6,1.1],[1,8.2,2.5],[2,29,3.2]],"ltp":6.6,"tv":11.8,"id":8231803}],"tv":374.83}]}
{"op":"mcm","clk":"991112654","pt":1580501659440,"mc":[{"id":"1.168133548","rc":[{"batb":[[0,6.4,3.36],[1,6,6.33]],"ltp":6.6,"tv":11.8,"id":8231803}]}]}
{"op":"mcm","clk":"991113180","pt":1580501662450,"mc":[{"id":"1.168133548","rc":[{"batl":[[1,8,3.03],[2,8.2,2.5]],"ltp":6.6,"tv":11.8,"id":8231803},{"batl":[[1,11.5,3.03],[2,12,3.09]],"ltp":9.0,"tv":118.63,"id":15608820}]}]}
{"op":"mcm","clk":"991113279","pt":1580501663034,"mc":[{"id":"1.168133548","rc":[{"batl":[[2,13,10]],"ltp":9.0,"tv":118.63,"id":15608820}]}]}
{"op":"mcm","clk":"991113780","pt":1580501666052,"mc":[{"id":"1.168133548","rc":[{"trd":[[6.4,6.72]],"batb":[[0,6,6.33],[1,5.9,3.03],[2,5.8,4.53]],"batl":[[0,6.4,3.64],[1,6.6,1.1],[2,8,3.03]],"ltp":6.4,"tv":18.52,"id":8231803}],"tv":381.55}]}
{"op":"mcm","clk":"991114046","pt":1580501667763,"mc":[{"id":"1.168133548","rc":[{"batb":[[0,6,3.33]],"ltp":6.4,"tv":18.52,"id":8231803}]}]}
{"op":"mcm","clk":"991120531","pt":1580501707357,"mc":[{"id":"1.168133548","rc":[{"batb":[[0,6,24.61],[1,5.8,2.52]],"ltp":6.0,"tv":179.04,"id":9417341},{"batb":[[0,6,5.11]],"ltp":6.4,"tv":18.52,"id":8231803}]}]}
{"op":"mcm","clk":"991121626","pt":1580501714192,"mc":[{"id":"1.168133548","rc":[{"batb":[[1,5.8,4.53],[2,5.6,3.47]],"batl":[[2,8.2,2.5]],"ltp":6.4,"tv":18.52,"id":8231803},{"batl":[[1,12.5,3.8]],"ltp":9.0,"tv":118.63,"id":15608820}]}]}
{"op":"mcm","clk":"991122127","pt":1580501717318,"mc":[{"id":"1.168133548","rc":[{"batl":[[0,12,2.2]],"ltp":9.0,"tv":118.63,"id":15608820}]}]}
{"op":"mcm","clk":"991122509","pt":1580501719642,"mc":[{"id":"1.168133548","rc":[{"batl":[[2,18.5,1.53]],"ltp":9.0,"tv":118.63,"id":15608820}]}]}
{"op":"mcm","clk":"991127712","pt":1580501751295,"mc":[{"id":"1.168133548","rc":[{"batl":[[1,18.5,1.53],[2,25,3.03]],"ltp":9.0,"tv":118.63,"id":15608820}]}]}
{"op":"mcm","clk":"991129519","pt":1580501762506,"mc":[{"id":"1.168133548","rc":[{"batb":[[1,5.7,2.81],[2,5.6,100.81]],"ltp":6.0,"tv":179.04,"id":9417341},{"batb":[[0,6,2.59]],"ltp":6.4,"tv":18.52,"id":8231803},{"batb":[[0,8.6,2.52],[1,8.4,6.68],[2,8.2,2.52]],"ltp":12.0,"tv":26.07,"id":10616006}]}]}
{"op":"mcm","clk":"991130932","pt":1580501771535,"mc":[{"id":"1.168133548","rc":[{"batl":[[0,18.5,1.53],[1,25,3.03],[2,26,9]],"ltp":9.0,"tv":118.63,"id":15608820}]}]}
{"op":"mcm","clk":"991130946","pt":1580501771634,"mc":[{"id":"1.168133548","rc":[{"batl":[[0,18.5,1.73]],"ltp":9.0,"tv":118.63,"id":15608820}]}]}
{"op":"mcm","clk":"991132133","pt":1580501779532,"mc":[{"id":"1.168133548","rc":[{"batb":[[1,8.4,2.27]],"ltp":12.0,"tv":26.07,"id":10616006}]}]}
{"op":"mcm","clk":"991135961","pt":1580501802367,"mc":[{"id":"1.168133548","rc":[{"batb":[[0,5.9,2.59]],"ltp":6.4,"tv":18.52,"id":8231803},{"batb":[[0,8.6,3.28],[1,8.4,1.51]],"ltp":12.0,"tv":26.07,"id":10616006}]}]}
{"op":"mcm","clk":"991139168","pt":1580501822127,"mc":[{"id":"1.168133548","rc":[{"batb":[[0,8.4,2.27],[1,8.2,2.52],[2,4.5,90]],"ltp":12.0,"tv":26.07,"id":10616006}]}]}
{"op":"mcm","clk":"991149046","pt":1580501882433,"mc":[{"id":"1.168133548","rc":[{"batb":[[1,4.6,3.61]],"ltp":12.0,"tv":26.07,"id":10616006}]}]}
{"op":"mcm","clk":"991149350","pt":1580501884499,"mc":[{"id":"1.168133548","rc":[{"trd":[[6.2,20]],"batl":[[0,6.2,28.77]],"ltp":6.2,"tv":199.04,"id":9417341}],"tv":401.55}]}
{"op":"mcm","clk":"991150843","pt":1580501894416,"mc":[{"id":"1.168133548","rc":[{"batl":[[0,6.2,29.15]],"ltp":6.2,"tv":199.04,"id":9417341},{"batb":[[1,4.7,7.9],[2,4.6,3.61]],"ltp":12.0,"tv":26.07,"id":10616006}]}]}
{"op":"mcm","clk":"991151247","pt":1580501897244,"mc":[{"id":"1.168133548","rc":[{"batb":[[0,8.4,1.51],[1,4.7,8.66]],"ltp":12.0,"tv":26.07,"id":10616006}]}]}
{"op":"mcm","clk":"991151629","pt":1580501899943,"mc":[{"id":"1.168133548","rc":[{"trd":[[6,110.82]],"batb":[[0,6,24.23]],"batl":[[0,6.2,28.77]],"ltp":6.0,"tv":199.8,"id":9417341}],"tv":402.31}]}
{"op":"mcm","clk":"991158384","pt":1580501942530,"mc":[{"id":"1.168133548","rc":[{"batb":[[1,4.8,3.28],[2,4.7,7.9]],"ltp":12.0,"tv":26.07,"id":10616006}]}]}
{"op":"mcm","clk":"991159774","pt":1580501951113,"mc":[{"id":"1.168133548","rc":[{"batb":[[2,4.6,3.61]],"ltp":12.0,"tv":26.07,"id":10616006}]}]}
{"op":"mcm","clk":"991166882","pt":1580501996256,"mc":[{"id":"1.168133548","rc":[{"trd":[[6,120.95]],"batb":[[0,6,19.16]],"batl":[[1,6.4,30]],"ltp":6.0,"tv":209.94,"id":9417341}],"tv":412.45}]}
{"op":"mcm","clk":"991167782","pt":1580502002496,"mc":[{"id":"1.168133548","rc":[{"batb":[[1,4.6,4.37],[2,4.5,90]],"ltp":12.0,"tv":26.07,"id":10616006}]}]}
{"op":"mcm","clk":"991168890","pt":1580502009385,"mc":[{"id":"1.168133548","rc":[{"batb":[[1,4.7,8.66],[2,4.6,3.61]],"ltp":12.0,"tv":26.07,"id":10616006}]}]}
{"op":"mcm","clk":"991175077","pt":1580502048555,"mc":[{"id":"1.168133548","rc":[{"batb":[[2,5.5,17.66]],"ltp":6.0,"tv":209.94,"id":9417341}]}]}
{"op":"mcm","clk":"991176570","pt":1580502057830,"mc":[{"id":"1.168133548","rc":[{"trd":[[6.8,22.02]],"batb":[[0,6.8,4.44],[1,5.8,3.97],[2,5.7,4.75]],"batl":[[0,7.2,2.4],[1,7.4,1.25],[2,9.8,3.03]],"ltp":6.8,"tv":34.02,"id":17352128}],"tv":422.45}]}
{"op":"mcm","clk":"991177477","pt":1580502062356,"mc":[{"id":"1.168133548","rc":[{"batb":[[1,4.8,3.28],[2,4.7,7.9]],"ltp":12.0,"tv":26.07,"id":10616006},{"batb":[[1,5.9,2.52],[2,5.8,3.97]],"ltp":6.8,"tv":34.02,"id":17352128}]}]}
{"op":"mcm","clk":"991177836","pt":1580502064728,"mc":[{"id":"1.168133548","rc":[{"batb":[[1,6,3],[2,5.9,2.52]],"ltp":6.8,"tv":34.02,"id":17352128}]}]}
{"op":"mcm","clk":"991178376","pt":1580502068451,"mc":[{"id":"1.168133548","rc":[{"batb":[[1,5.8,100],[2,5.7,2.81]],"ltp":6.0,"tv":209.94,"id":9417341},{"batb":[[1,4.9,7.57],[2,4.8,3.28]],"ltp":12.0,"tv":26.07,"id":10616006}]}]}
{"op":"mcm","clk":"991179334","pt":1580502074585,"mc":[{"id":"1.168133548","rc":[{"batb":[[1,5.9,6],[2,5.8,100]],"ltp":6.0,"tv":209.94,"id":9417341}]}]}
{"op":"mcm","clk":"991180316","pt":1580502081225,"mc":[{"id":"1.168133548","rc":[{"batb":[[0,7,3.03],[1,6.8,4.44],[2,6,3]],"ltp":6.8,"tv":34.02,"id":17352128}]}]}
{"op":"mcm","clk":"991181537","pt":1580502089018,"mc":[{"id":"1.168133548","rc":[{"batb":[[0,7,4.14]],"ltp":6.8,"tv":34.02,"id":17352128}]}]}
{"op":"mcm","clk":"991182029","pt":1580502092447,"mc":[{"id":"1.168133548","rc":[{"trd":[[12,24.48]],"batl":[[0,12,2.76]],"ltp":12.0,"tv":44.47,"id":10616006}],"tv":440.85}]}
{"op":"mcm","clk":"991182185","pt":1580502093621,"mc":[{"id":"1.168133548","rc":[{"batl":[[0,11.5,2],[1,12,2.76],[2,13.5,3]],"ltp":12.0,"tv":44.47,"id":10616006},{"batl":[[0,18,2.48],[1,18.5,1.25],[2,25,3.03]],"ltp":9.0,"tv":118.63,"id":15608820}]}]}
{"op":"mcm","clk":"991184773","pt":1580502112433,"mc":[{"id":"1.168133548","rc":[{"trd":[[11.5,4]],"batl":[[0,12,2.76],[1,13.5,3],[2,14.5,3.86]],"ltp":11.5,"tv":48.47,"id":10616006}],"tv":444.85}]}
{"op":"mcm","clk":"991186034","pt":1580502122082,"mc":[{"id":"1.168133548","rc":[{"batb":[[0,6,21.68]],"ltp":6.0,"tv":209.94,"id":9417341},{"batb":[[1,5,2.52],[2,4.9,7.57]],"ltp":11.5,"tv":48.47,"id":10616006},{"batb":[[0,7,6.66]],"ltp":6.8,"tv":34.02,"id":17352128}]}]}
{"op":"mcm","clk":"991186446","pt":1580502124984,"mc":[{"id":"1.168133548","rc":[{"trd":[[12,30]],"batb":[[0,12,1.84],[1,8.4,1.51],[2,5,2.52]],"batl":[[0,13.5,3],[1,14.5,3.86],[2,15,5]],"ltp":12.0,"tv":53.99,"id":10616006}],"tv":450.37}]}
{"op":"mcm","clk":"991187163","pt":1580502130222,"mc":[{"id":"1.168133548","rc":[{"batb":[[0,12,2.6]],"ltp":12.0,"tv":53.99,"id":10616006},{"batb":[[0,7,7.6]],"ltp":6.8,"tv":34.02,"id":17352128}]}]}
{"op":"mcm","clk":"991189856","pt":1580502149138,"mc":[{"id":"1.168133548","rc":[{"batb":[[1,5,2.52],[2,4.8,2.52]],"ltp":12.0,"tv":53.99,"id":10616006}]}]}
{"op":"mcm","clk":"991201427","pt":1580502161696,"mc":[{"id":"1.168133548","rc":[{"batb":[[0,12,3.22]],"ltp":12.0,"tv":53.99,"id":10616006}]}]}
{"op":"mcm","clk":"991204271","pt":1580502182260,"mc":[{"id":"1.168133548","rc":[{"batb":[[1,4.8,2.52],[2,4.6,3.61]],"ltp":12.0,"tv":53.99,"id":10616006}]}]}
{"op":"mcm","clk":"991213142","pt":1580502241870,"mc":[{"id":"1.168133548","rc":[{"batb":[[1,4.6,3.61],[2,4.5,90]],"ltp":12.0,"tv":53.99,"id":10616006}]}]}
{"op":"mcm","clk":"991218206","pt":1580502277779,"mc":[{"id":"1.168133548","rc":[{"trd":[[6,140.91]],"batb":[[0,6,11.7]],"ltp":6.0,"tv":229.9,"id":9417341}],"tv":470.33}]}
{"op":"mcm","clk":"991225842","pt":1580502331540,"mc":[{"id":"1.168133548","rc":[{"trd":[[7,13.97]],"batb":[[0,7,2.6]],"ltp":7.0,"tv":44.01,"id":17352128}],"tv":480.32}]}
{"op":"mcm","clk":"991226548","pt":1580502336473,"mc":[{"id":"1.168133548","rc":[{"trd":[[7,19.18]],"batb":[[0,6.8,4.44],[1,6,3],[2,5.9,2.52]],"batl":[[0,7,7.4],[1,7.2,2.4],[2,7.4,1.25]],"ltp":7.0,"tv":49.22,"id":17352128}],"tv":485.53}]}
{"op":"mcm","clk":"991230189","pt":1580502362094,"mc":[{"id":"1.168133548","rc":[{"batb":[[1,6.2,2.52],[2,6,3]],"ltp":7.0,"tv":49.22,"id":17352128}]}]}
{"op":"mcm","clk":"991230369","pt":1580502363298,"mc":[{"id":"1.168133548","rc":[{"batb":[[0,6.8,6.21]],"ltp":7.0,"tv":49.22,"id":17352128}]}]}
{"op":"mcm","clk":"991238928","pt":1580502422365,"mc":[{"id":"1.168133548","rc":[{"batb":[[1,6,3],[2,5.9,2.52]],"ltp":7.0,"tv":49.22,"id":17352128}]}]}
{"op":"mcm","clk":"991245002","pt":1580502463214,"mc":[{"id":"1.168133548","rc":[{"batl":[[0,12,2],[1,18,2.48],[2,18.5,1.25]],"ltp":9.0,"tv":118.63,"id":15608820}]}]}
{"op":"mcm","clk":"991245157","pt":1580502464236,"mc":[{"id":"1.168133548","rc":[{"batl":[[0,12,2.2],[1,18.5,1.53],[2,25,3.03]],"ltp":9.0,"tv":118.63,"id":15608820}]}]}
{"op":"mcm","clk":"991247395","pt":1580502479400,"mc":[{"id":"1.168133548","rc":[{"batl":[[0,13,2.2]],"ltp":9.0,"tv":118.63,"id":15608820}]}]}
{"op":"mcm","clk":"991247782","pt":1580502482096,"mc":[{"id":"1.168133548","rc":[{"batb":[[2,5.7,2.52]],"ltp":7.0,"tv":49.22,"id":17352128}]}]}
{"op":"mcm","clk":"991251515","pt":1580502507568,"mc":[{"id":"1.168133548","rc":[{"batl":[[0,16,2],[1,34,3.38],[2,36,9]],"ltp":0.0,"tv":0.0,"id":9001159}]}]}
{"op":"mcm","clk":"991252192","pt":1580502511905,"mc":[{"id":"1.168133548","rc":[{"batl":[[0,16,2.2],[1,34,3.18]],"ltp":0.0,"tv":0.0,"id":9001159}]}]}
{"op":"mcm","clk":"991256328","pt":1580502541745,"mc":[{"id":"1.168133548","rc":[{"batb":[[2,5.5,2.52]],"ltp":7.0,"tv":49.22,"id":17352128}]}]}
{"op":"mcm","clk":"991261423","pt":1580502581064,"mc":[{"id":"1.168133548","rc":[{"batb":[[1,9,9],[2,4.6,3.61]],"ltp":12.0,"tv":53.99,"id":10616006},{"batb":[[2,5.6,11]],"ltp":7.0,"tv":49.22,"id":17352128}]}]}
{"op":"mcm","clk":"991274505","pt":1580502675317,"mc":[{"id":"1.168133548","rc":[{"batl":[[0,12.5,2.2],[1,13,2],[2,18.5,1.53]],"ltp":9.0,"tv":118.63,"id":15608820}]}]}
{"op":"mcm","clk":"991277294","pt":1580502695580,"mc":[{"id":"1.168133548","rc":[{"batl":[[0,12.5,5.23]],"ltp":9.0,"tv":118.63,"id":15608820}]}]}
{"op":"mcm","clk":"991283045","pt":1580502736210,"mc":[{"id":"1.168133548","rc":[{"batl":[[0,12.5,2.2]],"ltp":9.0,"tv":118.63,"id":15608820}]}]}
{"op":"mcm","clk":"991288146","pt":1580502771433,"mc":[{"id":"1.168133548","rc":[{"batl":[[0,12.5,5.23]],"ltp":9.0,"tv":118.63,"id":15608820}]}]}
{"op":"mcm","clk":"991292451","pt":1580502804501,"mc":[{"id":"1.168133548","rc":[{"batl":[[0,12.5,2.2]],"ltp":9.0,"tv":118.63,"id":15608820}]}]}
{"op":"mcm","clk":"991297837","pt":1580502844240,"mc":[{"id":"1.168133548","rc":[{"batl":[[0,12.5,5.23]],"ltp":9.0,"tv":118.63,"id":15608820}]}]}
{"op":"mcm","clk":"991303950","pt":1580502889691,"mc":[{"id":"1.168133548","rc":[{"batl":[[0,12.5,2.2]],"ltp":9.0,"tv":118.63,"id":15608820}]}]}
{"op":"mcm","clk":"991305029","pt":1580502897235,"mc":[{"id":"1.168133548","rc":[{"batl":[[2,8.2,8]],"ltp":7.4,"tv":9.24,"id":10170404}]}]}
{"op":"mcm","clk":"991309801","pt":1580502930328,"mc":[{"id":"1.168133548","rc":[{"batl":[[0,12.5,5.23]],"ltp":9.0,"tv":118.63,"id":15608820}]}]}
{"op":"mcm","clk":"991315072","pt":1580502966188,"mc":[{"id":"1.168133548","rc":[{"batl":[[0,12.5,2.2]],"ltp":9.0,"tv":118.63,"id":15608820}]}]}
{"op":"mcm","clk":"991322802","pt":1580503020158,"mc":[{"id":"1.168133548","rc":[{"batl":[[0,12.5,5.23]],"ltp":9.0,"tv":118.63,"id":15608820}]}]}
{"op":"mcm","clk":"991339954","pt":1580503074284,"mc":[{"id":"1.168133548","rc":[{"batl":[[0,12.5,2.2]],"ltp":9.0,"tv":118.63,"id":15608820}]}]}
{"op":"mcm","clk":"991342075","pt":1580503088697,"mc":[{"id":"1.168133548","rc":[{"batl":[[2,15,15]],"ltp":12.0,"tv":53.99,"id":10616006}]}]}
{"op":"mcm","clk":"991344689","pt":1580503107319,"mc":[{"id":"1.168133548","rc":[{"trd":[[5.9,3.56],[6,0.54],[6.2,1.06]],"batb":[[0,5.8,4.53],[1,5.6,3.47],[2,5.5,3]],"batl":[[0,5.9,7.42],[1,6.4,3.64],[2,6.6,1.1]],"ltp":5.9,"tv":23.69,"id":8231803}],"tv":490.69}]}
{"op":"mcm","clk":"991347968","pt":1580503129736,"mc":[{"id":"1.168133548","rc":[{"batl":[[0,12.5,5.23]],"ltp":9.0,"tv":118.63,"id":15608820}]}]}
{"op":"mcm","clk":"991353841","pt":1580503170057,"mc":[{"id":"1.168133548","rc":[{"batl":[[0,12.5,2.2]],"ltp":9.0,"tv":118.63,"id":15608820}]}]}
{"op":"mcm","clk":"991358723","pt":1580503206441,"mc":[{"id":"1.168133548","rc":[{"batl":[[0,6.4,3.64],[1,6.6,1.1],[2,8.2,2.5]],"ltp":5.9,"tv":23.69,"id":8231803}]}]}
{"op":"mcm","clk":"991359801","pt":1580503214753,"mc":[{"id":"1.168133548","rc":[{"batl":[[0,12.5,5.23]],"ltp":9.0,"tv":118.63,"id":15608820}]}]}
{"op":"mcm","clk":"991364311","pt":1580503252804,"mc":[{"id":"1.168133548","rc":[{"batb":[[1,5.6,8.47]],"ltp":5.9,"tv":23.69,"id":8231803}]}]}
{"op":"mcm","clk":"991364470","pt":1580503253989,"mc":[{"id":"1.168133548","rc":[{"batl":[[0,12.5,2.2]],"ltp":9.0,"tv":118.63,"id":15608820}]}]}
{"op":"mcm","clk":"991368792","pt":1580503289491,"mc":[{"id":"1.168133548","rc":[{"batl":[[0,12.5,5.23]],"ltp":9.0,"tv":118.63,"id":15608820}]}]}
{"op":"mcm","clk":"991370041","pt":1580503300425,"mc":[{"id":"1.168133548","rc":[{"trd":[[6,144.27]],"batb":[[0,6,10.02]],"ltp":6.0,"tv":233.26,"id":9417341}],"tv":494.05}]}
{"op":"mcm","clk":"991371627","pt":1580503313475,"mc":[{"id":"1.168133548","rc":[{"trd":[[9,28.28],[12,35.19],[12.5,1.24]],"batb":[[0,4.6,3.61],[1,4.5,90],[2,3.1,44.93]],"ltp":9.0,"tv":87.58,"id":10616006}],"tv":527.64}]}
{"op":"mcm","clk":"991371737","pt":1580503314479,"mc":[{"id":"1.168133548","rc":[{"batb":[[0,9,2],[1,4.6,3.61],[2,4.5,90]],"batl":[[0,12,3.43],[1,13.5,3],[2,14.5,3.86]],"ltp":9.0,"tv":87.58,"id":10616006}]}]}
{"op":"mcm","clk":"991371844","pt":1580503315379,"mc":[{"id":"1.168133548","rc":[{"batb":[[1,8,3],[2,4.6,3.61]],"ltp":9.0,"tv":87.58,"id":10616006}]}]}
{"op":"mcm","clk":"991372640","pt":1580503322366,"mc":[{"id":"1.168133548","rc":[{"batb":[[0,5.8,2.01]],"ltp":5.9,"tv":23.69,"id":8231803}]}]}
{"op":"mcm","clk":"991372665","pt":1580503322579,"mc":[{"id":"1.168133548","rc":[{"batb":[[2,5.7,2.52]],"ltp":7.0,"tv":49.22,"id":17352128}]}]}
{"op":"mcm","clk":"991373498","pt":1580503329385,"mc":[{"id":"1.168133548","rc":[{"batb":[[2,5.5,7]],"batl":[[2,8,3.03]],"ltp":5.9,"tv":23.69,"id":8231803},{"batl":[[0,12.5,2.2]],"ltp":9.0,"tv":118.63,"id":15608820}]}]}
{"op":"mcm","clk":"991377860","pt":1580503364571,"mc":[{"id":"1.168133548","rc":[{"batb":[[1,5.7,3.85],[2,5.6,8.47]],"ltp":5.9,"tv":23.69,"id":8231803}]}]}
{"op":"mcm","clk":"991377953","pt":1580503364886,"mc":[{"id":"1.168133548","rc":[{"batl":[[0,12.5,5.23]],"ltp":9.0,"tv":118.63,"id":15608820}]}]}
{"op":"mcm","clk":"991384082","pt":1580503417140,"mc":[{"id":"1.168133548","rc":[{"batl":[[0,12.5,2.2]],"ltp":9.0,"tv":118.63,"id":15608820}]}]}
{"op":"mcm","clk":"991389322","pt":1580503457797,"mc":[{"id":"1.168133548","rc":[{"batl":[[0,12.5,5.23]],"ltp":9.0,"tv":118.63,"id":15608820}]}]}
{"op":"mcm","clk":"991390124","pt":1580503463816,"mc":[{"id":"1.168133548","rc":[{"batb":[[0,9.2,2.5],[1,9,2],[2,8,3]],"ltp":9.0,"tv":87.58,"id":10616006}]}]}
{"op":"mcm","clk":"991391083","pt":1580503471234,"mc":[{"id":"1.168133548","rc":[{"batl":[[0,12.5,2.2]],"ltp":9.0,"tv":118.63,"id":15608820}]}]}
{"op":"mcm","clk":"991393470","pt":1580503491191,"mc":[{"id":"1.168133548","marketDefinition":{"bspMarket":true,"turnInPlayEnabled":true,"persistenceEnabled":true,"marketBaseRate":5.0,"eventId":"29678760","eventTypeId":"7","numberOfWinners":1,"bettingType":"ODDS","marketType":"WIN","marketTime":"2020-02-01T13:38:00.000Z","suspendTime":"2020-02-01T13:38:00.000Z","bspReconciled":false,"complete":true,"inPlay":false,"crossMatching":false,"runnersVoidable":false,"numberOfActiveRunners":9,"betDelay":0,"status":"OPEN","runners":[{"adjustmentFactor":13.26,"status":"ACTIVE","sortPriority":1,"id":8231803,"name":"Kings Odyssey"},{"adjustmentFactor":18.03,"status":"ACTIVE","sortPriority":2,"id":9417341,"name":"Nuts Well"},{"adjustmentFactor":8.91,"status":"ACTIVE","sortPriority":3,"id":10170404,"name":"Niven"},{"adjustmentFactor":6.9,"status":"ACTIVE","sortPriority":4,"id":17352128,"name":"Kapgarry"},{"adjustmentFactor":10.32,"status":"ACTIVE","sortPriority":5,"id":8429550,"name":"Clan Legend"},{"adjustmentFactor":12.14,"status":"ACTIVE","sortPriority":6,"id":15608820,"name":"The Dubai Way"},{"adjustmentFactor":6.9,"status":"ACTIVE","sortPriority":7,"id":9193530,"name":"Bollin Ace"},{"adjustmentFactor":8.91,"status":"ACTIVE","sortPriority":8,"id":10616006,"name":"Winter Escape"},{"adjustmentFactor":14.58,"status":"ACTIVE","sortPriority":9,"id":9001159,"name":"Pistol Park"}],"regulators":["MR_INT"],"venue":"Wetherby","countryCode":"GB","discountAllowed":true,"timezone":"Europe/London","openDate":"2020-02-01T13:03:00.000Z","version":3143867986,"name":"2m3f Hcap Chs","eventName":"Weth  1st Feb"}}]}
{"op":"mcm","clk":"991394367","pt":1580503498454,"mc":[{"id":"1.168133548","rc":[{"batl":[[0,12.5,5.23]],"ltp":9.0,"tv":118.63,"id":15608820}]}]}
{"op":"mcm","clk":"991394436","pt":1580503499077,"mc":[{"id":"1.168133548","rc":[{"batb":[[0,8.4,3.03],[1,8.2,3.53],[2,8,2.52]],"ltp":0.0,"tv":0.0,"id":8429550},{"batb":[[0,9,4.55]],"ltp":9.0,"tv":6.0,"id":9193530}]}]}
{"op":"mcm","clk":"991394847","pt":1580503502537,"mc":[{"id":"1.168133548","rc":[{"batb":[[0,8.6,1.98],[1,8.4,3.03],[2,8.2,1.55]],"ltp":0.0,"tv":0.0,"id":8429550},{"batl":[[0,12.5,2.2]],"ltp":9.0,"tv":118.63,"id":15608820},{"batb":[[0,9.2,1.98],[1,9,4.55]],"ltp":9.0,"tv":6.0,"id":9193530}]}]}
{"op":"mcm","clk":"991394905","pt":1580503503067,"mc":[{"id":"1.168133548","rc":[{"batb":[[1,8.2,4.58],[2,8,2.52]],"ltp":0.0,"tv":0.0,"id":8429550}]}]}
{"op":"mcm","clk":"991396774","pt":1580503518340,"mc":[{"id":"1.168133548","rc":[{"batb":[[0,9.4,1.52],[1,9.2,1.98],[2,9,3.03]],"ltp":9.0,"tv":6.0,"id":9193530}]}]}
{"op":"mcm","clk":"991399665","pt":1580503541553,"mc":[{"id":"1.168133548","rc":[{"batb":[[0,8.4,1.98]],"ltp":0.0,"tv":0.0,"id":8429550}]}]}
{"op":"mcm","clk":"991401451","pt":1580503555572,"mc":[{"id":"1.168133548","rc":[{"batl":[[1,13.5,5.57],[2,15,15]],"ltp":9.0,"tv":87.58,"id":10616006},{"batl":[[0,12.5,5.23]],"ltp":9.0,"tv":118.63,"id":15608820}]}]}
{"op":"mcm","clk":"991401511","pt":1580503556086,"mc":[{"id":"1.168133548","rc":[{"batl":[[2,14,2.57]],"ltp":9.0,"tv":87.58,"id":10616006},{"batb":[[0,9.4,4.55],[2,8.6,1.48]],"ltp":9.0,"tv":6.0,"id":9193530}]}]}
{"op":"mcm","clk":"991402435","pt":1580503563446,"mc":[{"id":"1.168133548","rc":[{"batl":[[0,12.5,2.2]],"ltp":9.0,"tv":118.63,"id":15608820},{"batb":[[0,9.4,1.52],[2,8.8,3.03]],"ltp":9.0,"tv":6.0,"id":9193530}]}]}
{"op":"mcm","clk":"991404139","pt":1580503577287,"mc":[{"id":"1.168133548","rc":[{"batl":[[0,11.5,1.88],[1,12,3.43],[2,13.5,5.57]],"ltp":9.0,"tv":87.58,"id":10616006}]}]}
{"op":"mcm","clk":"991404522","pt":1580503580723,"mc":[{"id":"1.168133548","rc":[{"batb":[[1,9,1.98]],"ltp":9.0,"tv":6.0,"id":9193530}]}]}
{"op":"mcm","clk":"991408888","pt":1580503618500,"mc":[{"id":"1.168133548","rc":[{"batl":[[0,12.5,5.23]],"ltp":9.0,"tv":118.63,"id":15608820},{"batb":[[1,9.2,3.03],[2,9,1.98]],"ltp":9.0,"tv":6.0,"id":9193530}]}]}
{"op":"mcm","clk":"991409071","pt":1580503619998,"mc":[{"id":"1.168133548","rc":[{"batb":[[0,9.4,3.5],[2,8.6,1.48]],"ltp":9.0,"tv":6.0,"id":9193530}]}]}
{"op":"mcm","clk":"991414403","pt":1580503666458,"mc":[{"id":"1.168133548","rc":[{"batl":[[0,12.5,2.2]],"ltp":9.0,"tv":118.63,"id":15608820},{"batb":[[0,9.6,3.03],[1,9.4,3.5]],"ltp":9.0,"tv":6.0,"id":9193530}]}]}
{"op":"mcm","clk":"991416162","pt":1580503682408,"mc":[{"id":"1.168133548","rc":[{"batb":[[1,9.4,1.98]],"ltp":9.0,"tv":6.0,"id":9193530}]}]}
{"op":"mcm","clk":"991416774","pt":1580503688209,"mc":[{"id":"1.168133548","rc":[{"batb":[[2,8.2,3.13]],"ltp":9.0,"tv":6.0,"id":9193530}]}]}
{"op":"mcm","clk":"991418081","pt":1580503700179,"mc":[{"id":"1.168133548","rc":[{"batb":[[0,9.8,1.3],[1,9.6,3.03],[2,9.4,1.98]],"ltp":9.0,"tv":6.0,"id":9193530}]}]}
{"op":"mcm","clk":"991418317","pt":1580503702483,"mc":[{"id":"1.168133548","rc":[{"batb":[[0,9.8,3.28],[2,8.2,3.13]],"ltp":9.0,"tv":6.0,"id":9193530}]}]}
{"op":"mcm","clk":"991419514","pt":1580503713554,"mc":[{"id":"1.168133548","rc":[{"batl":[[0,12.5,5.23]],"ltp":9.0,"tv":118.63,"id":15608820},{"batb":[[0,10,3.03],[1,9.8,3.28]],"ltp":9.0,"tv":6.0,"id":9193530}]}]}
{"op":"mcm","clk":"991422463","pt":1580503742297,"mc":[{"id":"1.168133548","rc":[{"batb":[[0,10.5,1.98],[1,10,3.03],[2,9.8,1.3]],"ltp":9.0,"tv":6.0,"id":9193530}]}]}
{"op":"mcm","clk":"991422768","pt":1580503744932,"mc":[{"id":"1.168133548","rc":[{"batl":[[0,7.2,1.68],[1,7.4,10],[2,7.6,3.35]],"ltp":7.4,"tv":9.24,"id":10170404}]}]}
{"op":"mcm","clk":"991422937","pt":1580503746235,"mc":[{"id":"1.168133548","rc":[{"batl":[[0,7.4,10],[1,7.6,3.35],[2,8.2,8]],"ltp":7.4,"tv":9.24,"id":10170404}]}]}
{"op":"mcm","clk":"991423322","pt":1580503749536,"mc":[{"id":"1.168133548","rc":[{"batl":[[0,12.5,2.2]],"ltp":9.0,"tv":118.63,"id":15608820},{"batb":[[1,9.8,1.3],[2,8.2,3.13]],"ltp":9.0,"tv":6.0,"id":9193530}]}]}
{"op":"mcm","clk":"991423342","pt":1580503749740,"mc":[{"id":"1.168133548","rc":[{"batb":[[2,8.4,3.03]],"ltp":9.0,"tv":6.0,"id":9193530}]}]}
{"op":"mcm","clk":"991426692","pt":1580503781157,"mc":[{"id":"1.168133548","rc":[{"batb":[[0,9.8,1.3],[1,8.6,1.98]],"ltp":9.0,"tv":6.0,"id":9193530}]}]}
{"op":"mcm","clk":"991427493","pt":1580503789386,"mc":[{"id":"1.168133548","rc":[{"batl":[[0,12.5,5.23]],"ltp":9.0,"tv":118.63,"id":15608820}]}]}
{"op":"mcm","clk":"991427566","pt":1580503790075,"mc":[{"id":"1.168133548","rc":[{"batb":[[1,8.8,3.03],[2,8.6,1.98]],"ltp":9.0,"tv":6.0,"id":9193530}]}]}
{"op":"mcm","clk":"991433107","pt":1580503842486,"mc":[{"id":"1.168133548","rc":[{"batl":[[0,12.5,2.2]],"ltp":9.0,"tv":118.63,"id":15608820},{"batb":[[1,8.6,1.98],[2,8.4,3.03]],"ltp":9.0,"tv":6.0,"id":9193530}]}]}
{"op":"mcm","clk":"991438725","pt":1580503896493,"mc":[{"id":"1.168133548","rc":[{"batl":[[0,12.5,5.23]],"ltp":9.0,"tv":118.63,"id":15608820},{"batb":[[1,8.8,3.03],[2,8.6,1.98]],"ltp":9.0,"tv":6.0,"id":9193530}]}]}
{"op":"mcm","clk":"991455601","pt":1580503963536,"mc":[{"id":"1.168133548","rc":[{"batl":[[0,12.5,2.2]],"ltp":9.0,"tv":118.63,"id":15608820}]}]}
{"op":"mcm","clk":"991455658","pt":1580503964053,"mc":[{"id":"1.168133548","rc":[{"batb":[[1,9,1.98],[2,8.4,3.03]],"ltp":9.0,"tv":6.0,"id":9193530}]}]}
{"op":"mcm","clk":"991457273","pt":1580503979348,"mc":[{"id":"1.168133548","rc":[{"batl":[[2,8.4,8]],"ltp":7.4,"tv":9.24,"id":10170404}]}]}
{"op":"mcm","clk":"991458244","pt":1580503989439,"mc":[{"id":"1.168133548","rc":[{"trd":[[6.4,14]],"batl":[[0,6.6,1.1],[1,8,3.03],[2,8.2,2.5]],"ltp":6.4,"tv":30.97,"id":8231803}],"tv":534.92}]}
{"op":"mcm","clk":"991458736","pt":1580503994386,"mc":[{"id":"1.168133548","rc":[{"batb":[[0,5.9,2],[1,5.8,2.01],[2,5.7,3.85]],"ltp":6.4,"tv":30.97,"id":8231803}]}]}
{"op":"mcm","clk":"991459385","pt":1580504001388,"mc":[{"id":"1.168133548","rc":[{"batl":[[1,7.8,4.76],[2,8,3.03]],"ltp":6.4,"tv":30.97,"id":8231803}]}]}
{"op":"mcm","clk":"991459842","pt":1580504006894,"mc":[{"id":"1.168133548","rc":[{"trd":[[6,164.32]],"batb":[[0,5.9,6],[1,5.8,100],[2,5.7,2.81]],"batl":[[0,6,9.98],[1,6.2,28.77],[2,6.4,30]],"ltp":6.0,"tv":253.3,"id":9417341}],"tv":554.96}]}
{"op":"mcm","clk":"991460861","pt":1580504019390,"mc":[{"id":"1.168133548","rc":[{"batb":[[0,5.9,5.03],[2,5.6,8.47]],"batl":[[1,7.6,3.03],[2,7.8,4.76]],"ltp":6.4,"tv":30.97,"id":8231803}]}]}
{"op":"mcm","clk":"991460917","pt":1580504020072,"mc":[{"id":"1.168133548","rc":[{"batl":[[2,8.2,2.5]],"ltp":6.4,"tv":30.97,"id":8231803},{"batl":[[0,12.5,5.23]],"ltp":9.0,"tv":118.63,"id":15608820},{"batb":[[1,9.2,3.03],[2,9,1.98]],"ltp":9.0,"tv":6.0,"id":9193530}]}]}
{"op":"mcm","clk":"991463771","pt":1580504053534,"mc":[{"id":"1.168133548","rc":[{"batb":[[0,5.9,2],[2,5.7,3.03]],"ltp":6.4,"tv":30.97,"id":8231803},{"batl":[[0,12.5,2.2]],"ltp":9.0,"tv":118.63,"id":15608820}]}]}
{"op":"mcm","clk":"991463809","pt":1580504053939,"mc":[{"id":"1.168133548","rc":[{"batb":[[1,9,1.98],[2,8.4,3.03]],"ltp":9.0,"tv":6.0,"id":9193530}]}]}
{"op":"mcm","clk":"991464058","pt":1580504056535,"mc":[{"id":"1.168133548","rc":[{"batb":[[0,5.9,9.17]],"ltp":6.0,"tv":253.3,"id":9417341},{"batb":[[1,8.6,1.98]],"ltp":9.0,"tv":6.0,"id":9193530}]}]}
{"op":"mcm","clk":"991466264","pt":1580504085491,"mc":[{"id":"1.168133548","rc":[{"batb":[[2,5.6,8.47]],"ltp":6.4,"tv":30.97,"id":8231803}]}]}
{"op":"mcm","clk":"991466309","pt":1580504086282,"mc":[{"id":"1.168133548","rc":[{"batb":[[0,5.9,5.03]],"ltp":6.4,"tv":30.97,"id":8231803},{"batl":[[0,12.5,5.23]],"ltp":9.0,"tv":118.63,"id":15608820},{"batb":[[1,8.8,3.03],[2,8.6,1.98]],"ltp":9.0,"tv":6.0,"id":9193530}]}]}
{"op":"mcm","clk":"991468056","pt":1580504118420,"mc":[{"id":"1.168133548","rc":[{"trd":[[5.9,33.35]],"batb":[[0,5.8,100],[1,5.7,2.81],[2,5.5,17.66]],"batl":[[0,5.9,7.43],[1,6,9.98],[2,6.2,28.77]],"ltp":5.9,"tv":271.65,"id":9417341},{"batb":[[0,5.9,2],[2,5.7,3.03]],"ltp":6.4,"tv":30.97,"id":8231803},{"batl":[[0,12.5,2.2]],"ltp":9.0,"tv":118.63,"id":15608820}],"tv":573.31}]}
{"op":"mcm","clk":"991468081","pt":1580504118835,"mc":[{"id":"1.168133548","rc":[{"batb":[[1,8.6,1.98],[2,8.4,3.03]],"ltp":9.0,"tv":6.0,"id":9193530}]}]}
{"op":"mcm","clk":"991468443","pt":1580504125505,"mc":[{"id":"1.168133548","rc":[{"batl":[[0,5.9,13.43]],"ltp":5.9,"tv":271.65,"id":9417341}]}]}
{"op":"mcm","clk":"991469894","pt":1580504151536,"mc":[{"id":"1.168133548","rc":[{"batb":[[0,5.9,5.03],[2,5.6,8.47]],"ltp":6.4,"tv":30.97,"id":8231803},{"batl":[[0,12.5,5.23]],"ltp":9.0,"tv":118.63,"id":15608820}]}]}
{"op":"mcm","clk":"991469956","pt":1580504152421,"mc":[{"id":"1.168133548","rc":[{"batb":[[0,5.9,6.71]],"ltp":6.4,"tv":30.97,"id":8231803},{"batb":[[1,8.8,3.03],[2,8.4,1.98]],"ltp":9.0,"tv":6.0,"id":9193530}]}]}
{"op":"mcm","clk":"991471777","pt":1580504184173,"mc":[{"id":"1.168133548","rc":[{"batl":[[0,12.5,2.2]],"ltp":9.0,"tv":118.63,"id":15608820},{"batb":[[1,8.4,5.01],[2,8.2,3.13]],"ltp":9.0,"tv":6.0,"id":9193530}]}]}
{"op":"mcm","clk":"991473703","pt":1580504216210,"mc":[{"id":"1.168133548","rc":[{"batl":[[0,12.5,5.23]],"ltp":9.0,"tv":118.63,"id":15608820}]}]}
{"op":"mcm","clk":"991476067","pt":1580504248459,"mc":[{"id":"1.168133548","rc":[{"batl":[[0,12.5,2.2]],"ltp":9.0,"tv":118.63,"id":15608820}]}]}
{"op":"mcm","clk":"991478447","pt":1580504281489,"mc":[{"id":"1.168133548","rc":[{"batl":[[0,7.4,13],[1,7.6,6.35]],"ltp":7.4,"tv":9.24,"id":10170404}]}]}
{"op":"mcm","clk":"991478516","pt":1580504282379,"mc":[{"id":"1.168133548","rc":[{"batl":[[2,7.8,3]],"ltp":7.4,"tv":9.24,"id":10170404},{"batl":[[0,12.5,5.23]],"ltp":9.0,"tv":118.63,"id":15608820}]}]}
{"op":"mcm","clk":"991480673","pt":1580504313909,"mc":[{"id":"1.168133548","rc":[{"batl":[[0,12.5,2.2]],"ltp":9.0,"tv":118.63,"id":15608820}]}]}
{"op":"mcm","clk":"991482999","pt":1580504346542,"mc":[{"id":"1.168133548","rc":[{"batl":[[0,12.5,5.23]],"ltp":9.0,"tv":118.63,"id":15608820}]}]}
{"op":"mcm","clk":"991485491","pt":1580504380563,"mc":[{"id":"1.168133548","rc":[{"batl":[[0,12.5,2.2]],"ltp":9.0,"tv":118.63,"id":15608820}]}]}
{"op":"mcm","clk":"991488369","pt":1580504414392,"mc":[{"id":"1.168133548","rc":[{"batl":[[0,12.5,5.23]],"ltp":9.0,"tv":118.63,"id":15608820}]}]}
{"op":"mcm","clk":"991489651","pt":1580504429342,"mc":[{"id":"1.168133548","rc":[{"batb":[[0,10,3.98]],"ltp":0.0,"tv":0.0,"id":9001159}]}]}
{"op":"mcm","clk":"991491539","pt":1580504454560,"mc":[{"id":"1.168133548","rc":[{"batl":[[0,7,3],[1,7.4,13],[2,7.6,6.35]],"ltp":7.4,"tv":9.24,"id":10170404}]}]}
{"op":"mcm","clk":"991496507","pt":1580504514914,"mc":[{"id":"1.168133548","rc":[{"batl":[[2,17,3.18]],"ltp":9.0,"tv":118.63,"id":15608820}]}]}
{"op":"mcm","clk":"991497934","pt":1580504534928,"mc":[{"id":"1.168133548","rc":[{"batb":[[2,8,3.61]],"ltp":9.0,"tv":87.58,"id":10616006}]}]}
{"op":"mcm","clk":"991498548","pt":1580504544489,"mc":[{"id":"1.168133548","rc":[{"trd":[[9,14.72]],"batl":[[0,9,4.24],[1,12.5,5.23],[2,13,2]],"ltp":9.0,"tv":130.15,"id":15608820}],"tv":584.83}]}
{"op":"mcm","clk":"991498732","pt":1580504546991,"mc":[{"id":"1.168133548","rc":[{"batl":[[1,12.5,5.03]],"ltp":9.0,"tv":130.15,"id":15608820}]}]}
{"op":"mcm","clk":"991500779","pt":1580504575115,"mc":[{"id":"1.168133548","rc":[{"batl":[[2,330,2]],"ltp":9.0,"tv":6.0,"id":9193530}]}]}
{"op":"mcm","clk":"991502253","pt":1580504596552,"mc":[{"id":"1.168133548","rc":[{"batl":[[1,12.5,3.03]],"ltp":9.0,"tv":130.15,"id":15608820}]}]}
{"op":"mcm","clk":"991503737","pt":1580504615270,"mc":[{"id":"1.168133548","rc":[{"batl":[[2,330,2.16]],"ltp":9.0,"tv":6.0,"id":9193530}]}]}
{"op":"mcm","clk":"991507091","pt":1580504655532,"mc":[{"id":"1.168133548","rc":[{"batb":[[0,8.4,4.03]],"ltp":0.0,"tv":0.0,"id":8429550},{"batb":[[0,6,2.87],[1,5.9,6.71],[2,5.8,2.01]],"ltp":6.4,"tv":30.97,"id":8231803},{"batl":[[2,330,0.16]],"ltp":9.0,"tv":6.0,"id":9193530}]}]}
{"op":"mcm","clk":"991507119","pt":1580504655846,"mc":[{"id":"1.168133548","rc":[{"batb":[[0,8.6,3.98]],"ltp":9.0,"tv":130.15,"id":15608820},{"batb":[[1,8.6,2],[2,8.4,5.01]],"ltp":9.0,"tv":6.0,"id":9193530},{"batb":[[0,10.5,1.64],[1,10,3.98],[2,9.8,1.8]],"ltp":0.0,"tv":0.0,"id":9001159}]}]}
{"op":"mcm","clk":"991511073","pt":1580504703491,"mc":[{"id":"1.168133548","rc":[{"batb":[[0,8.6,2.33],[1,8.4,4.03],[2,8.2,4.58]],"ltp":0.0,"tv":0.0,"id":8429550},{"batb":[[0,6,6.2]],"ltp":6.4,"tv":30.97,"id":8231803},{"batb":[[2,8.4,2.38]],"ltp":9.0,"tv":87.58,"id":10616006},{"batb":[[1,8.8,2.27],[2,8.6,2]],"ltp":9.0,"tv":6.0,"id":9193530}]}]}
{"op":"mcm","clk":"991511894","pt":1580504712978,"mc":[{"id":"1.168133548","rc":[{"batb":[[0,8.8,1.98],[1,8.6,2.33],[2,8.4,2.05]],"ltp":0.0,"tv":0.0,"id":8429550},{"batb":[[0,6,7.88],[1,5.9,5.03]],"ltp":6.4,"tv":30.97,"id":8231803},{"batb":[[1,9,1.98],[2,8.8,2.27]],"ltp":9.0,"tv":6.0,"id":9193530}]}]}
{"op":"mcm","clk":"991515594","pt":1580504758421,"mc":[{"id":"1.168133548","rc":[{"batb":[[2,8.6,2]],"ltp":9.0,"tv":6.0,"id":9193530}]}]}
{"op":"mcm","clk":"991516881","pt":1580504775336,"mc":[{"id":"1.168133548","rc":[{"batl":[[0,10.5,2.5],[1,11,3.03],[2,11.5,10]],"ltp":0.0,"tv":0.0,"id":8429550}]}]}
{"op":"mcm","clk":"991519784","pt":1580504810797,"mc":[{"id":"1.168133548","rc":[{"batb":[[1,8.8,1.98]],"ltp":9.0,"tv":6.0,"id":9193530}]}]}
{"op":"mcm","clk":"991535959","pt":1580504889736,"mc":[{"id":"1.168133548","rc":[{"batl":[[0,55,3.12]],"ltp":9.0,"tv":6.0,"id":9193530},{"batl":[[0,16,2]],"ltp":0.0,"tv":0.0,"id":9001159}]}]}
{"op":"mcm","clk":"991542697","pt":1580504966127,"mc":[{"id":"1.168133548","rc":[{"batb":[[1,8.4,2.52]],"batl":[[1,12.5,2]],"ltp":9.0,"tv":130.15,"id":15608820},{"batb":[[1,9,3.03],[2,8.8,1.98]],"ltp":9.0,"tv":6.0,"id":9193530}]}]}
{"op":"mcm","clk":"991544919","pt":1580504997384,"mc":[{"id":"1.168133548","rc":[{"trd":[[5.8,20]],"batb":[[0,5.8,90]],"ltp":5.8,"tv":291.65,"id":9417341}],"tv":604.83}]}
{"op":"mcm","clk":"991545085","pt":1580504999733,"mc":[{"id":"1.168133548","rc":[{"batb":[[1,9.2,1.98],[2,9,3.03]],"ltp":9.0,"tv":6.0,"id":9193530}]}]}
{"op":"mcm","clk":"991545229","pt":1580505001403,"mc":[{"id":"1.168133548","rc":[{"trd":[[5.8,34.62]],"batb":[[0,5.8,82.69],[2,5.5,14.66]],"ltp":5.8,"tv":306.27,"id":9417341}],"tv":619.45}]}
{"op":"mcm","clk":"991545935","pt":1580505011448,"mc":[{"id":"1.168133548","rc":[{"batl":[[0,55,3.32]],"ltp":9.0,"tv":6.0,"id":9193530}]}]}
{"op":"mcm","clk":"991545955","pt":1580505011921,"mc":[{"id":"1.168133548","rc":[{"batl":[[0,16,2.18]],"ltp":0.0,"tv":0.0,"id":9001159}]}]}
{"op":"mcm","clk":"991580367","pt":1580505477217,"mc":[{"id":"1.168133548","rc":[{"batl":[[2,13,2]],"ltp":9.0,"tv":87.58,"id":10616006}]}]}
{"op":"mcm","clk":"991620889","pt":1580505847524,"mc":[{"id":"1.168133548","rc":[{"trd":[[9.6,8.43]],"ltp":9.6,"tv":91.98,"id":10616006},{"trd":[[7,6.04]],"batl":[[0,7,2.98]],"ltp":7.0,"tv":15.28,"id":10170404},{"trd":[[11,4]],"ltp":11.0,"tv":4.0,"id":9001159}],"tv":633.89}]}
{"op":"mcm","clk":"991621240","pt":1580505851439,"mc":[{"id":"1.168133548","rc":[{"batb":[[1,6.4,2.52],[2,6,6.35]],"ltp":7.0,"tv":15.28,"id":10170404}]}]}
{"op":"mcm","clk":"991621333","pt":1580505852533,"mc":[{"id":"1.168133548","rc":[{"batb":[[2,8.4,5.38]],"ltp":9.6,"tv":91.98,"id":10616006}]}]}
{"op":"mcm","clk":"991621424","pt":1580505853524,"mc":[{"id":"1.168133548","rc":[{"batb":[[2,8.6,2]],"ltp":9.6,"tv":91.98,"id":10616006}]}]}
{"op":"mcm","clk":"991636570","pt":1580506083428,"mc":[{"id":"1.168133548","rc":[{"batb":[[0,8.8,3.94],[1,8.6,13.96],[2,8.2,4.58]],"ltp":0.0,"tv":0.0,"id":8429550},{"trd":[[5.9,60.21]],"batb":[[0,5.9,3.52],[1,5.8,82.69],[2,5.7,2.81]],"batl":[[0,6,9.98],[1,6.2,28.77],[2,6.4,30]],"ltp":5.9,"tv":333.13,"id":9417341},{"batb":[[0,6.2,16.13],[1,6,7.88],[2,5.9,5.03]],"ltp":6.4,"tv":30.97,"id":8231803},{"batb":[[0,9.2,13.37]],"ltp":9.6,"tv":91.98,"id":10616006},{"trd":[[7,12]],"batb":[[0,7,11.31],[1,6.8,6.85],[2,6.4,2.52]],"batl":[[0,7.4,13],[1,7.6,6.35],[2,7.8,3]],"ltp":7.0,"tv":21.24,"id":10170404},{"batb":[[0,8.6,15.61]],"ltp":9.0,"tv":130.15,"id":15608820},{"batb":[[0,10.5,11.16]],"ltp":11.0,"tv":4.0,"id":9001159},{"batb":[[1,9.4,1.83],[2,9.2,12.85]],"ltp":9.0,"tv":6.0,"id":9193530},{"trd":[[7,33.98]],"batb":[[0,7,6.89],[1,6.8,6.21],[2,6,3]],"batl":[[0,7.2,2.4],[1,7.4,1.25],[2,7.6,13]],"ltp":7.0,"tv":64.02,"id":17352128}],"tv":681.51}]}
{"op":"mcm","clk":"991636581","pt":1580506083637,"mc":[{"id":"1.168133548","rc":[{"batb":[[0,9.4,1.83],[1,9.2,13.37],[2,9,2]],"ltp":9.6,"tv":91.98,"id":10616006}]}]}
{"op":"mcm","clk":"991637102","pt":1580506092122,"mc":[{"id":"1.168133548","rc":[{"batb":[[0,6.2,17.81],[1,6,6.2]],"ltp":6.4,"tv":30.97,"id":8231803},{"batb":[[0,7,12.99],[1,6.8,5.17]],"ltp":7.0,"tv":21.24,"id":10170404},{"batb":[[0,11,1.98],[1,10.5,11.16],[2,10,2]],"ltp":11.0,"tv":4.0,"id":9001159},{"batb":[[1,9.6,1.98],[2,9.4,1.83]],"ltp":9.0,"tv":6.0,"id":9193530},{"batb":[[0,7,8.66],[1,6.8,4.44]],"ltp":7.0,"tv":64.02,"id":17352128}]}]}
{"op":"mcm","clk":"991637440","pt":1580506098429,"mc":[{"id":"1.168133548","rc":[{"batb":[[1,8.6,11.63]],"ltp":0.0,"tv":0.0,"id":8429550},{"batb":[[1,6,2.87]],"ltp":6.4,"tv":30.97,"id":8231803},{"batb":[[2,9.8,1.8]],"ltp":11.0,"tv":4.0,"id":9001159}]}]}
{"op":"mcm","clk":"991641901","pt":1580506171565,"mc":[{"id":"1.168133548","rc":[{"trd":[[9.6,3.42],[9.8,2.59]],"batb":[[0,9.4,2.1],[1,9.2,10.87],[2,9,3.03]],"ltp":9.6,"tv":12.01,"id":9193530}],"tv":687.52}]}
{"op":"mcm","clk":"991641985","pt":1580506173481,"mc":[{"id":"1.168133548","rc":[{"batb":[[0,7,9.37]],"ltp":7.0,"tv":64.02,"id":17352128}]}]}
{"op":"mcm","clk":"991645499","pt":1580506233328,"mc":[{"id":"1.168133548","rc":[{"batb":[[0,6.4,4.37],[1,6.2,16.13]],"ltp":6.4,"tv":30.97,"id":8231803},{"batb":[[0,7.2,4.07],[1,7,11.31],[2,6.8,5.17]],"ltp":7.0,"tv":21.24,"id":10170404}]}]}
{"op":"mcm","clk":"991658108","pt":1580506420710,"mc":[{"id":"1.168133548","rc":[{"trd":[[8.6,100.91]],"batb":[[0,8.6,12.61]],"ltp":8.6,"tv":136.15,"id":15608820}],"tv":693.52}]}
{"op":"mcm","clk":"991685023","pt":1580506683463,"mc":[{"id":"1.168133548","rc":[{"trd":[[9.2,6.32],[9.4,4.72]],"batb":[[0,9.2,12.2],[1,9,2],[2,8.4,3]],"ltp":9.2,"tv":97.98,"id":10616006}],"tv":699.52}]}
{"op":"mcm","clk":"991685300","pt":1580506687544,"mc":[{"id":"1.168133548","rc":[{"batb":[[2,8,3.61]],"ltp":9.2,"tv":97.98,"id":10616006}]}]}
{"op":"mcm","clk":"991705206","pt":1580506992048,"mc":[{"id":"1.168133548","rc":[{"trd":[[7.2,5.88]],"batb":[[0,7.2,1.13]],"ltp":7.2,"tv":27.12,"id":10170404}],"tv":705.4}]}
{"op":"mcm","clk":"991705831","pt":1580507003361,"mc":[{"id":"1.168133548","rc":[{"trd":[[5.9,67.25]],"batb":[[0,5.8,82.69],[1,5.7,2.81],[2,5.5,17.66]],"batl":[[0,5.9,1.48],[1,6,9.98],[2,6.2,28.77]],"ltp":5.9,"tv":340.17,"id":9417341}],"tv":712.44}]}
{"op":"mcm","clk":"991706867","pt":1580507023527,"mc":[{"id":"1.168133548","rc":[{"trd":[[6.4,20.72]],"batb":[[0,6.4,1.01]],"ltp":6.4,"tv":37.69,"id":8231803},{"trd":[[7,16.46],[7.2,8.15]],"batb":[[0,7,9.08],[1,6.8,5.17],[2,6.4,5.52]],"ltp":7.0,"tv":33.84,"id":10170404}],"tv":725.88}]}
{"op":"mcm","clk":"991707013","pt":1580507026017,"mc":[{"id":"1.168133548","rc":[{"batb":[[2,6.4,2.52]],"ltp":7.0,"tv":33.84,"id":10170404}]}]}
{"op":"mcm","clk":"991708740","pt":1580507058361,"mc":[{"id":"1.168133548","rc":[{"batl":[[0,6,9.98],[1,6.2,28.77],[2,6.4,30]],"ltp":5.9,"tv":340.17,"id":9417341}]}]}
{"op":"mcm","clk":"991709024","pt":1580507063567,"mc":[{"id":"1.168133548","rc":[{"trd":[[8.8,4]],"batb":[[0,8.8,1.94]],"ltp":8.8,"tv":3.99,"id":8429550}],"tv":729.88}]}
{"op":"mcm","clk":"991709861","pt":1580507079894,"mc":[{"id":"1.168133548","rc":[{"batb":[[0,9,1.98],[1,8.8,1.94],[2,8.6,11.63]],"ltp":8.8,"tv":3.99,"id":8429550},{"batb":[[0,5.8,84.37]],"ltp":5.9,"tv":340.17,"id":9417341},{"batb":[[0,7,10.76]],"ltp":7.0,"tv":33.84,"id":10170404}]}]}
{"op":"mcm","clk":"991712939","pt":1580507131335,"mc":[{"id":"1.168133548","rc":[{"batb":[[0,5.9,2.91],[1,5.8,84.37],[2,5.7,2.81]],"ltp":5.9,"tv":340.17,"id":9417341}]}]}
{"op":"mcm","clk":"991714617","pt":1580507157940,"mc":[{"id":"1.168133548","rc":[{"batb":[[0,5.9,4.59],[1,5.8,82.69]],"ltp":5.9,"tv":340.17,"id":9417341}]}]}
{"op":"mcm","clk":"991714953","pt":1580507163568,"mc":[{"id":"1.168133548","rc":[{"trd":[[9.4,10.14],[9.6,3.96]],"batb":[[0,9.2,10.87],[1,9,3.03],[2,8.4,3]],"batl":[[0,55,3.12]],"ltp":9.4,"tv":18.73,"id":9193530}],"tv":736.6}]}
{"op":"mcm","clk":"991714993","pt":1580507164454,"mc":[{"id":"1.168133548","rc":[{"trd":[[10.5,5]],"batl":[[0,11,3.03],[1,11.5,10],[2,25,1.25]],"ltp":10.5,"tv":8.99,"id":8429550},{"trd":[[6,168.24]],"batl":[[0,6,8.02]],"ltp":6.0,"tv":344.09,"id":9417341},{"trd":[[6.6,10.01],[7.6,1.18]],"batl":[[0,7.6,2.44],[1,8.2,2.5],[2,30,9.17]],"ltp":7.6,"tv":41.07,"id":8231803},{"trd":[[11.5,6.04]],"batl":[[0,12,4.29],[1,13,2],[2,13.5,5.57]],"ltp":11.5,"tv":100.02,"id":10616006},{"trd":[[7.4,11.14]],"batl":[[0,7.4,11.4]],"ltp":7.4,"tv":37.04,"id":10170404},{"trd":[[9,17.34]],"batl":[[0,9,2.93]],"ltp":9.0,"tv":138.77,"id":15608820},{"trd":[[16,1.12]],"batb":[[0,11,2.43]],"batl":[[0,16,1.44]],"ltp":16.0,"tv":5.12,"id":9001159},{"trd":[[7.2,4.8]],"batb":[[0,7.2,2.39],[1,7,9.37],[2,6.8,4.44]],"batl":[[0,7.4,1.25],[1,7.6,13],[2,9.8,2.17]],"ltp":7.2,"tv":68.82,"id":17352128}],"tv":762.68}]}
{"op":"mcm","clk":"991715173","pt":1580507167559,"mc":[{"id":"1.168133548","rc":[{"batb":[[0,6.4,4.01]],"ltp":7.6,"tv":41.07,"id":8231803}]}]}
{"op":"mcm","clk":"991715244","pt":1580507168542,"mc":[{"id":"1.168133548","rc":[{"batb":[[2,6.4,5.52]],"ltp":7.4,"tv":37.04,"id":10170404}]}]}
{"op":"mcm","clk":"991715310","pt":1580507169468,"mc":[{"id":"1.168133548","rc":[{"batb":[[2,8.2,3.13]],"batl":[[0,55,3.32]],"ltp":9.4,"tv":18.73,"id":9193530},{"batl":[[0,16,1.63]],"ltp":16.0,"tv":5.12,"id":9001159}]}]}
{"op":"mcm","clk":"991715359","pt":1580507170044,"mc":[{"id":"1.168133548","rc":[{"batb":[[2,4.6,3.13]],"ltp":11.5,"tv":100.02,"id":10616006}]}]}
{"op":"mcm","clk":"991715526","pt":1580507172491,"mc":[{"id":"1.168133548","rc":[{"batl":[[0,7.4,2],[1,7.6,2.44],[2,8.2,2.5]],"ltp":7.6,"tv":41.07,"id":8231803}]}]}
{"op":"mcm","clk":"991715946","pt":1580507178479,"mc":[{"id":"1.168133548","rc":[{"batb":[[0,11.5,3.65],[1,11,1.98],[2,10.5,11.16]],"ltp":16.0,"tv":5.12,"id":9001159}]}]}
{"op":"mcm","clk":"991716556","pt":1580507188974,"mc":[{"id":"1.168133548","rc":[{"batb":[[0,9.4,1.71],[1,9.2,12.2],[2,9,2]],"ltp":11.5,"tv":100.02,"id":10616006},{"batb":[[0,9.4,1.98],[1,9.2,10.87],[2,9,3.03]],"ltp":9.4,"tv":18.73,"id":9193530},{"batb":[[0,12,2.4],[1,11.5,3.23]],"ltp":16.0,"tv":5.12,"id":9001159},{"batb":[[0,7.2,4.17],[1,7,7.6]],"ltp":7.2,"tv":68.82,"id":17352128}]}]}
{"op":"mcm","clk":"991717056","pt":1580507196808,"mc":[{"id":"1.168133548","rc":[{"batb":[[1,10.5,11.16],[2,9.8,1.8]],"ltp":16.0,"tv":5.12,"id":9001159}]}]}
{"op":"mcm","clk":"991718589","pt":1580507221047,"mc":[{"id":"1.168133548","rc":[{"batb":[[0,11,2.4]],"ltp":16.0,"tv":5.12,"id":9001159}]}]}
{"op":"mcm","clk":"991718958","pt":1580507226778,"mc":[{"id":"1.168133548","rc":[{"batb":[[0,9.6,1.27],[1,9.4,1.71],[2,9.2,10.87]],"ltp":11.5,"tv":100.02,"id":10616006}]}]}
{"op":"mcm","clk":"991719367","pt":1580507234493,"mc":[{"id":"1.168133548","rc":[{"batb":[[0,11.5,3.65],[1,11,1.98],[2,10.5,11.16]],"ltp":16.0,"tv":5.12,"id":9001159}]}]}
{"op":"mcm","clk":"991720491","pt":1580507252495,"mc":[{"id":"1.168133548","rc":[{"batb":[[1,10.5,11.16],[2,9.8,1.8]],"ltp":16.0,"tv":5.12,"id":9001159}]}]}
{"op":"mcm","clk":"991720556","pt":1580507253389,"mc":[{"id":"1.168133548","rc":[{"batb":[[0,12,2.4],[1,11.5,3.23],[2,10.5,11.16]],"ltp":16.0,"tv":5.12,"id":9001159}]}]}
{"op":"mcm","clk":"991720587","pt":1580507253797,"mc":[{"id":"1.168133548","rc":[{"batb":[[1,10.5,11.16],[2,9.8,1.8]],"ltp":16.0,"tv":5.12,"id":9001159}]}]}
{"op":"mcm","clk":"991722364","pt":1580507283917,"mc":[{"id":"1.168133548","rc":[{"batb":[[0,11,2.4]],"ltp":16.0,"tv":5.12,"id":9001159}]}]}
{"op":"mcm","clk":"991722777","pt":1580507290918,"mc":[{"id":"1.168133548","rc":[{"batb":[[0,11.5,3.65],[1,11,1.98],[2,10.5,11.16]],"ltp":16.0,"tv":5.12,"id":9001159}]}]}
{"op":"mcm","clk":"991723922","pt":1580507313561,"mc":[{"id":"1.168133548","rc":[{"batb":[[1,10.5,11.16],[2,9.8,1.8]],"ltp":16.0,"tv":5.12,"id":9001159}]}]}
{"op":"mcm","clk":"991723936","pt":1580507314075,"mc":[{"id":"1.168133548","rc":[{"batb":[[0,12,2.4],[1,11.5,3.23],[2,10.5,11.16]],"ltp":16.0,"tv":5.12,"id":9001159}]}]}
{"op":"mcm","clk":"991724781","pt":1580507329250,"mc":[{"id":"1.168133548","rc":[{"batb":[[1,10.5,11.16],[2,9.8,1.8]],"ltp":16.0,"tv":5.12,"id":9001159}]}]}
{"op":"mcm","clk":"991725164","pt":1580507336508,"mc":[{"id":"1.168133548","rc":[{"batl":[[0,12,3.43]],"ltp":11.5,"tv":100.02,"id":10616006}]}]}
{"op":"mcm","clk":"991725176","pt":1580507336715,"mc":[{"id":"1.168133548","rc":[{"batl":[[0,11.5,1.88],[1,12,3.43],[2,13,2]],"ltp":11.5,"tv":100.02,"id":10616006}]}]}
{"op":"mcm","clk":"991725592","pt":1580507344502,"mc":[{"id":"1.168133548","rc":[{"batb":[[0,10.5,11.58],[1,9.8,1.8],[2,9.6,2.52]],"ltp":16.0,"tv":5.12,"id":9001159}]}]}
{"op":"mcm","clk":"991725600","pt":1580507344603,"mc":[{"id":"1.168133548","rc":[{"batb":[[0,11,2.4],[1,10.5,11.16],[2,9.8,1.8]],"ltp":16.0,"tv":5.12,"id":9001159}]}]}
{"op":"mcm","clk":"991725770","pt":1580507348329,"mc":[{"id":"1.168133548","rc":[{"batb":[[0,11.5,3.65],[1,11,1.98],[2,10.5,11.16]],"ltp":16.0,"tv":5.12,"id":9001159}]}]}
{"op":"mcm","clk":"991727495","pt":1580507375334,"mc":[{"id":"1.168133548","rc":[{"batb":[[0,12,2.4],[1,11.5,3.23]],"ltp":16.0,"tv":5.12,"id":9001159}]}]}
{"op":"mcm","clk":"991728188","pt":1580507385853,"mc":[{"id":"1.168133548","rc":[{"batb":[[1,10.5,11.16],[2,9.8,1.8]],"ltp":16.0,"tv":5.12,"id":9001159}]}]}
{"op":"mcm","clk":"991730775","pt":1580507424476,"mc":[{"id":"1.168133548","rc":[{"batl":[[1,13,2],[2,17,3.18]],"ltp":9.0,"tv":138.77,"id":15608820}]}]}
{"op":"mcm","clk":"991730838","pt":1580507425571,"mc":[{"id":"1.168133548","rc":[{"batb":[[2,8.2,4.58]],"batl":[[2,16.5,2.84]],"ltp":9.0,"tv":138.77,"id":15608820},{"batb":[[0,9.4,5.01],[2,8.2,3.13]],"ltp":9.4,"tv":18.73,"id":9193530}]}]}
{"op":"mcm","clk":"991732525","pt":1580507453402,"mc":[{"id":"1.168133548","rc":[{"batb":[[0,11,2.4]],"ltp":16.0,"tv":5.12,"id":9001159}]}]}
{"op":"mcm","clk":"991733016","pt":1580507462334,"mc":[{"id":"1.168133548","rc":[{"batb":[[0,11.5,3.65],[1,11,1.98],[2,10.5,11.16]],"ltp":16.0,"tv":5.12,"id":9001159}]}]}
{"op":"mcm","clk":"991733272","pt":1580507466015,"mc":[{"id":"1.168133548","rc":[{"batb":[[0,8.8,3.03],[1,8.6,12.61],[2,8.4,2.52]],"ltp":9.0,"tv":138.77,"id":15608820}]}]}
{"op":"mcm","clk":"991738162","pt":1580507545439,"mc":[{"id":"1.168133548","rc":[{"batb":[[0,12,2.4],[1,11.5,3.23]],"ltp":16.0,"tv":5.12,"id":9001159}]}]}
{"op":"mcm","clk":"991748671","pt":1580507558344,"mc":[{"id":"1.168133548","rc":[{"batb":[[1,10.5,11.16],[2,9.8,1.8]],"ltp":16.0,"tv":5.12,"id":9001159}]}]}
{"op":"mcm","clk":"991749589","pt":1580507572755,"mc":[{"id":"1.168133548","rc":[{"trd":[[11.5,9.8],[12,40.61]],"batl":[[0,13,2.72],[1,13.5,5.57],[2,14,2.57]],"ltp":12.0,"tv":109.21,"id":10616006}],"tv":771.86}]}
{"op":"mcm","clk":"991749651","pt":1580507574464,"mc":[{"id":"1.168133548","rc":[{"batb":[[0,11,1.97],[1,9.6,1.27],[2,9.4,1.71]],"ltp":12.0,"tv":109.21,"id":10616006}]}]}
{"op":"mcm","clk":"991749664","pt":1580507574682,"mc":[{"id":"1.168133548","rc":[{"trd":[[11,3.94]],"batb":[[0,9.6,1.27],[1,9.4,1.71],[2,9.2,10.87]],"ltp":11.0,"tv":113.15,"id":10616006}],"tv":775.8}]}
{"op":"mcm","clk":"991751900","pt":1580507608992,"mc":[{"id":"1.168133548","rc":[{"trd":[[9.4,13.52]],"batb":[[0,9.4,3.32]],"ltp":9.4,"tv":22.1,"id":9193530}],"tv":779.18}]}
{"op":"mcm","clk":"991753734","pt":1580507639829,"mc":[{"id":"1.168133548","rc":[{"batb":[[0,11,2.4]],"ltp":16.0,"tv":5.12,"id":9001159}]}]}
{"op":"mcm","clk":"991754458","pt":1580507651756,"mc":[{"id":"1.168133548","rc":[{"batb":[[0,11.5,3.65],[1,11,1.98],[2,10.5,11.16]],"ltp":16.0,"tv":5.12,"id":9001159}]}]}
{"op":"mcm","clk":"991755167","pt":1580507664256,"mc":[{"id":"1.168133548","rc":[{"batl":[[0,12.5,2.6],[1,13,2],[2,13.5,5.57]],"ltp":11.0,"tv":113.15,"id":10616006}]}]}
{"op":"mcm","clk":"991755454","pt":1580507668854,"mc":[{"id":"1.168133548","rc":[{"trd":[[7,37.98]],"batb":[[0,6.8,5.17],[1,6.4,5.52],[2,6,3.35]],"batl":[[0,7,9.24],[1,7.4,11.4],[2,7.6,6.35]],"ltp":7.0,"tv":58.56,"id":10170404}],"tv":800.7}]}
{"op":"mcm","clk":"991755695","pt":1580507673260,"mc":[{"id":"1.168133548","rc":[{"batb":[[1,6.4,2.52],[2,6,6.35]],"ltp":7.0,"tv":58.56,"id":10170404}]}]}
{"op":"mcm","clk":"991759441","pt":1580507732917,"mc":[{"id":"1.168133548","rc":[{"batb":[[0,12,2.4],[1,11.5,3.23]],"ltp":16.0,"tv":5.12,"id":9001159}]}]}
{"op":"mcm","clk":"991760294","pt":1580507745914,"mc":[{"id":"1.168133548","rc":[{"batb":[[1,10.5,11.16],[2,9.8,1.8]],"ltp":16.0,"tv":5.12,"id":9001159}]}]}
{"op":"mcm","clk":"991762477","pt":1580507782096,"mc":[{"id":"1.168133548","rc":[{"batb":[[0,11,2.4]],"ltp":16.0,"tv":5.12,"id":9001159}]}]}
{"op":"mcm","clk":"991762561","pt":1580507783755,"mc":[{"id":"1.168133548","rc":[{"batb":[[0,11.5,3.65],[1,11,1.98],[2,10.5,11.16]],"ltp":16.0,"tv":5.12,"id":9001159}]}]}
{"op":"mcm","clk":"991764378","pt":1580507822400,"mc":[{"id":"1.168133548","rc":[{"trd":[[12,42.05],[12.5,5]],"batb":[[0,12.5,1.09],[1,9.6,1.27],[2,9.4,1.71]],"batl":[[0,13,2],[1,13.5,5.57],[2,14,2.57]],"ltp":12.5,"tv":118.35,"id":10616006}],"tv":805.9}]}
{"op":"mcm","clk":"991764433","pt":1580507823429,"mc":[{"id":"1.168133548","rc":[{"batb":[[1,12,1.96],[2,9.6,1.27]],"ltp":12.5,"tv":118.35,"id":10616006}]}]}
{"op":"mcm","clk":"991764891","pt":1580507831522,"mc":[{"id":"1.168133548","rc":[{"batb":[[0,12,2.4],[1,11.5,3.23]],"ltp":16.0,"tv":5.12,"id":9001159}]}]}
{"op":"mcm","clk":"991764949","pt":1580507832542,"mc":[{"id":"1.168133548","rc":[{"batl":[[1,13.5,3],[2,14.5,3.86]],"ltp":12.5,"tv":118.35,"id":10616006}]}]}
{"op":"mcm","clk":"991765314","pt":1580507842159,"mc":[{"id":"1.168133548","rc":[{"batb":[[1,10.5,11.16],[2,9.8,1.8]],"ltp":16.0,"tv":5.12,"id":9001159}]}]}
{"op":"mcm","clk":"991768206","pt":1580507905112,"mc":[{"id":"1.168133548","rc":[{"batb":[[0,9.6,2.08],[1,9.4,3.32],[2,9.2,10.87]],"ltp":9.4,"tv":22.1,"id":9193530}]}]}
{"op":"mcm","clk":"991768993","pt":1580507923172,"mc":[{"id":"1.168133548","rc":[{"batb":[[0,11,2.4]],"ltp":16.0,"tv":5.12,"id":9001159},{"batb":[[0,9.6,2.37],[1,9.4,3.03]],"ltp":9.4,"tv":22.1,"id":9193530}]}]}
{"op":"mcm","clk":"991769637","pt":1580507935992,"mc":[{"id":"1.168133548","rc":[{"batb":[[0,11.5,3.65],[1,11,1.98],[2,10.5,11.16]],"ltp":16.0,"tv":5.12,"id":9001159}]}]}
{"op":"mcm","clk":"991770334","pt":1580507949695,"mc":[{"id":"1.168133548","rc":[{"batl":[[0,7.4,4.25]],"ltp":7.2,"tv":68.82,"id":17352128}]}]}
{"op":"mcm","clk":"991771380","pt":1580507971429,"mc":[{"id":"1.168133548","rc":[{"batb":[[0,8.8,4.71]],"ltp":9.0,"tv":138.77,"id":15608820},{"batb":[[0,12,2.4],[1,11.5,3.23]],"ltp":16.0,"tv":5.12,"id":9001159}]}]}
{"op":"mcm","clk":"991771493","pt":1580507973839,"mc":[{"id":"1.168133548","rc":[{"batb":[[1,10.5,11.16],[2,9.8,1.8]],"ltp":16.0,"tv":5.12,"id":9001159}]}]}
{"op":"mcm","clk":"991771549","pt":1580507975016,"mc":[{"id":"1.168133548","rc":[{"batb":[[0,9.2,1.87],[1,9,4.2]],"ltp":10.5,"tv":8.99,"id":8429550},{"batb":[[0,6.6,3.03],[1,6.4,4.01],[2,6.2,16.13]],"ltp":7.6,"tv":41.07,"id":8231803},{"batb":[[0,12.5,1.6],[1,12,2.4],[2,10.5,11.16]],"ltp":16.0,"tv":5.12,"id":9001159}]}]}
{"op":"mcm","clk":"991771591","pt":1580507976039,"mc":[{"id":"1.168133548","rc":[{"batl":[[0,16,1.44]],"ltp":16.0,"tv":5.12,"id":9001159}]}]}
{"op":"mcm","clk":"991773407","pt":1580508014504,"mc":[{"id":"1.168133548","rc":[{"batb":[[0,9.2,3.79]],"ltp":10.5,"tv":8.99,"id":8429550},{"trd":[[5.5,50],[5.8,34.62],[5.9,67.26],[6,168.24],[6.2,20]],"batb":[[0,5.9,4.6],[2,5.7,2.8]],"batl":[[1,6.2,28.77]],"ltp":6.0,"tv":344.11,"id":9417341},{"trd":[[6.4,20.72],[6.6,10]],"ltp":7.6,"tv":41.07,"id":8231803},{"trd":[[9,28.28],[9.8,7.97]],"ltp":12.5,"tv":118.35,"id":10616006},{"trd":[[7,37.98],[7.2,8.15],[7.6,1.3]],"batb":[[0,6.8,5.16]],"ltp":7.0,"tv":58.56,"id":10170404},{"trd":[[8.4,15.45]],"ltp":9.0,"tv":138.77,"id":15608820},{"batb":[[0,12.5,3.01]],"ltp":16.0,"tv":5.12,"id":9001159},{"trd":[[9,2.04],[9.4,13.52],[9.8,2.58]],"ltp":9.4,"tv":22.1,"id":9193530},{"trd":[[6.2,6.98],[7,33.98]],"batb":[[0,7.2,4.17],[1,7,7.59]],"ltp":7.2,"tv":68.81,"id":17352128}],"tv":805.93}]}
{"op":"mcm","clk":"991773554","pt":1580508018020,"mc":[{"id":"1.168133548","rc":[{"batb":[[0,9.4,1.98],[1,9.2,3.79],[2,9,2.22]],"ltp":10.5,"tv":8.99,"id":8429550},{"batb":[[0,6.6,4.04],[1,6.4,3]],"ltp":7.6,"tv":41.07,"id":8231803},{"batb":[[0,13,1.98],[1,12.5,3.01],[2,10.5,11.58]],"ltp":16.0,"tv":5.12,"id":9001159}]}]}
{"op":"mcm","clk":"991774543","pt":1580508038573,"mc":[{"id":"1.168133548","rc":[{"batb":[[0,9.4,4.11],[2,8.6,11.63]],"ltp":10.5,"tv":8.99,"id":8429550},{"batb":[[0,13.5,1.48],[1,13,1.98],[2,12.5,1.41]],"ltp":16.0,"tv":5.12,"id":9001159}]}]}
{"op":"mcm","clk":"991777990","pt":1580508093554,"mc":[{"id":"1.168133548","rc":[{"trd":[[7.2,10.81],[7.4,2.5]],"batb":[[0,7.2,1.16]],"batl":[[0,7.6,13],[1,9.8,2.17],[2,10,8.42]],"ltp":7.2,"tv":77.32,"id":17352128}],"tv":814.44}]}
{"op":"mcm","clk":"991786673","pt":1580508240560,"mc":[{"id":"1.168133548","rc":[{"trd":[[6,184.28]],"batb":[[0,6,11.98],[1,5.9,4.6],[2,5.8,82.69]],"batl":[[0,6.2,28.77],[1,6.4,30],[2,6.8,1.25]],"ltp":6.0,"tv":360.15,"id":9417341},{"batl":[[1,7.4,3]],"ltp":7.0,"tv":58.56,"id":10170404}],"tv":830.48}]}
{"op":"mcm","clk":"991786684","pt":1580508240764,"mc":[{"id":"1.168133548","rc":[{"batl":[[1,6.4,32.66]],"ltp":6.0,"tv":360.15,"id":9417341},{"batl":[[0,7,17.64]],"ltp":7.0,"tv":58.56,"id":10170404}]}]}
{"op":"mcm","clk":"991787091","pt":1580508248271,"mc":[{"id":"1.168133548","rc":[{"batl":[[1,6.4,30]],"ltp":6.0,"tv":360.15,"id":9417341}]}]}
{"op":"mcm","clk":"991787184","pt":1580508249457,"mc":[{"id":"1.168133548","rc":[{"batb":[[0,6,13.66],[1,5.9,2.92]],"ltp":6.0,"tv":360.15,"id":9417341}]}]}
{"op":"mcm","clk":"991790619","pt":1580508303485,"mc":[{"id":"1.168133548","rc":[{"batb":[[0,9.6,1.8],[1,9.4,4.11],[2,9.2,1.91]],"ltp":10.5,"tv":8.99,"id":8429550}]}]}
{"op":"mcm","clk":"991795654","pt":1580508387538,"mc":[{"id":"1.168133548","rc":[{"batb":[[0,9.8,1.98],[1,9.6,1.8],[2,9.4,2.13]],"ltp":10.5,"tv":8.99,"id":8429550}]}]}
{"op":"mcm","clk":"991797172","pt":1580508412981,"mc":[{"id":"1.168133548","rc":[{"batb":[[2,9.2,1.91]],"ltp":10.5,"tv":8.99,"id":8429550}]}]}
{"op":"mcm","clk":"991819970","pt":1580508617507,"mc":[{"id":"1.168133548","rc":[{"trd":[[7,39.66],[7.2,13.13]],"batb":[[0,7,4.75],[1,6.8,4.44],[2,6.4,3]],"ltp":7.0,"tv":85.32,"id":17352128}],"tv":838.48}]}
{"op":"mcm","clk":"991820034","pt":1580508618492,"mc":[{"id":"1.168133548","rc":[{"batb":[[2,6,3]],"ltp":7.0,"tv":85.32,"id":17352128}]}]}
{"op":"mcm","clk":"991823406","pt":1580508673419,"mc":[{"id":"1.168133548","rc":[{"batb":[[0,6.8,6.85]],"ltp":7.0,"tv":58.56,"id":10170404},{"batb":[[0,7,7.86]],"ltp":7.0,"tv":85.32,"id":17352128}]}]}
{"op":"mcm","clk":"991826592","pt":1580508720389,"mc":[{"id":"1.168133548","rc":[{"batb":[[0,9.8,3.29],[1,9.6,2.08],[2,9.4,3.03]],"ltp":9.4,"tv":22.1,"id":9193530}]}]}
{"op":"mcm","clk":"991826813","pt":1580508723491,"mc":[{"id":"1.168133548","rc":[{"batb":[[0,10,3],[1,9.8,3.29],[2,9.6,2.08]],"ltp":9.4,"tv":22.1,"id":9193530}]}]}
{"op":"mcm","clk":"991826839","pt":1580508723901,"mc":[{"id":"1.168133548","rc":[{"batb":[[1,9.8,6.29]],"ltp":9.4,"tv":22.1,"id":9193530}]}]}
{"op":"mcm","clk":"991826938","pt":1580508725506,"mc":[{"id":"1.168133548","rc":[{"batb":[[1,9.6,2.37],[2,9.2,10.87]],"ltp":9.4,"tv":22.1,"id":9193530}]}]}
{"op":"mcm","clk":"991826941","pt":1580508725609,"mc":[{"id":"1.168133548","rc":[{"batb":[[1,9.8,3.32],[2,9.6,2.08]],"ltp":9.4,"tv":22.1,"id":9193530}]}]}
{"op":"mcm","clk":"991827432","pt":1580508733320,"mc":[{"id":"1.168133548","rc":[{"batb":[[2,9.2,10.87]],"ltp":9.4,"tv":22.1,"id":9193530}]}]}
{"op":"mcm","clk":"991828133","pt":1580508744502,"mc":[{"id":"1.168133548","rc":[{"batb":[[2,11,3]],"ltp":12.5,"tv":118.35,"id":10616006}]}]}
{"op":"mcm","clk":"991828870","pt":1580508756505,"mc":[{"id":"1.168133548","rc":[{"trd":[[6.2,43.96]],"batb":[[0,6,1.68]],"batl":[[0,6.2,16.79]],"ltp":6.2,"tv":384.11,"id":9417341}],"tv":862.44}]}
{"op":"mcm","clk":"991829380","pt":1580508764418,"mc":[{"id":"1.168133548","rc":[{"batb":[[0,10,3.29],[1,9.8,3.03]],"ltp":9.4,"tv":22.1,"id":9193530}]}]}
{"op":"mcm","clk":"991830700","pt":1580508782462,"mc":[{"id":"1.168133548","rc":[{"batb":[[0,6.8,4.32]],"ltp":7.0,"tv":58.56,"id":10170404}]}]}
{"op":"mcm","clk":"991830776","pt":1580508783452,"mc":[{"id":"1.168133548","rc":[{"batb":[[0,6.6,6.56]],"ltp":7.6,"tv":41.07,"id":8231803},{"batb":[[2,11.5,2.52]],"ltp":12.5,"tv":118.35,"id":10616006},{"batb":[[1,6,6.35],[2,5.8,2.52]],"ltp":7.0,"tv":58.56,"id":10170404},{"batb":[[2,8.2,1.55]],"ltp":9.0,"tv":138.77,"id":15608820},{"batb":[[0,10,5.81]],"ltp":9.4,"tv":22.1,"id":9193530}]}]}
{"op":"mcm","clk":"991830813","pt":1580508784072,"mc":[{"id":"1.168133548","rc":[{"batb":[[1,5.9,4.37]],"ltp":6.2,"tv":384.11,"id":9417341},{"batb":[[0,8.8,6.02]],"ltp":9.0,"tv":138.77,"id":15608820}]}]}
{"op":"mcm","clk":"991831496","pt":1580508793914,"mc":[{"id":"1.168133548","rc":[{"batb":[[0,10.5,3.32],[1,10,5.52]],"ltp":9.4,"tv":22.1,"id":9193530}]}]}
{"op":"mcm","clk":"991838927","pt":1580508946254,"mc":[{"id":"1.168133548","rc":[{"batb":[[0,11,1.82],[1,10.5,3.32],[2,10,5.52]],"ltp":9.4,"tv":22.1,"id":9193530}]}]}
{"op":"mcm","clk":"991841049","pt":1580508987422,"mc":[{"id":"1.168133548","rc":[{"batb":[[0,11,2.11],[1,10.5,3.03]],"ltp":9.4,"tv":22.1,"id":9193530}]}]}
{"op":"mcm","clk":"991847704","pt":1580509118948,"mc":[{"id":"1.168133548","rc":[{"batb":[[1,10.5,6.03],[2,10,2.52]],"ltp":9.4,"tv":22.1,"id":9193530}]}]}
{"op":"mcm","clk":"991847763","pt":1580509120380,"mc":[{"id":"1.168133548","rc":[{"batb":[[0,11,5.11],[1,10.5,3.03]],"ltp":9.4,"tv":22.1,"id":9193530}]}]}
{"op":"mcm","clk":"991848701","pt":1580509142391,"mc":[{"id":"1.168133548","rc":[{"batb":[[2,9.2,10.87]],"ltp":9.4,"tv":22.1,"id":9193530}]}]}
{"op":"mcm","clk":"991848714","pt":1580509142597,"mc":[{"id":"1.168133548","rc":[{"batb":[[0,11,7.63]],"ltp":9.4,"tv":22.1,"id":9193530}]}]}
{"op":"mcm","clk":"991873306","pt":1580509455505,"mc":[{"id":"1.168133548","rc":[{"trd":[[11.5,14.84],[12,45.97],[12.5,7.19]],"batb":[[0,11,3],[1,9.6,1.27],[2,9.2,10.87]],"batl":[[0,11.5,4.43],[1,13,2],[2,13.5,3]],"ltp":11.5,"tv":129.5,"id":10616006}],"tv":873.58}]}
{"op":"mcm","clk":"991873415","pt":1580509457519,"mc":[{"id":"1.168133548","rc":[{"trd":[[11.5,18.84]],"batl":[[0,11.5,2.43]],"ltp":11.5,"tv":133.5,"id":10616006}],"tv":877.58}]}
{"op":"mcm","clk":"991873483","pt":1580509458336,"mc":[{"id":"1.168133548","rc":[{"trd":[[11.5,22.84]],"batl":[[0,13,2.43],[1,13.5,3],[2,14.5,3.86]],"ltp":11.5,"tv":137.5,"id":10616006}],"tv":881.58}]}
{"op":"mcm","clk":"991875224","pt":1580509491705,"mc":[{"id":"1.168133548","rc":[{"batl":[[0,6.2,21.86]],"ltp":6.2,"tv":384.11,"id":9417341}]}]}
{"op":"mcm","clk":"991875864","pt":1580509502909,"mc":[{"id":"1.168133548","rc":[{"batb":[[2,9.2,11.32]],"ltp":11.5,"tv":137.5,"id":10616006}]}]}
{"op":"mcm","clk":"991876984","pt":1580509522641,"mc":[{"id":"1.168133548","rc":[{"trd":[[11.5,23.7]],"batb":[[0,11.5,1.55],[1,11,3],[2,9.6,1.27]],"batl":[[0,13,2]],"ltp":11.5,"tv":138.35,"id":10616006}],"tv":882.44}]}
{"op":"mcm","clk":"991902386","pt":1580510088405,"mc":[{"id":"1.168133548","rc":[{"batl":[[0,11,6.03]],"ltp":10.5,"tv":8.99,"id":8429550}]}]}
{"op":"mcm","clk":"991903859","pt":1580510117207,"mc":[{"id":"1.168133548","rc":[{"batl":[[0,6.2,41.86]],"ltp":6.2,"tv":384.11,"id":9417341}]}]}
{"op":"mcm","clk":"991925110","pt":1580510410343,"mc":[{"id":"1.168133548","rc":[{"batl":[[2,990,2.16]],"ltp":9.4,"tv":22.1,"id":9193530}]}]}
{"op":"mcm","clk":"991925264","pt":1580510413452,"mc":[{"id":"1.168133548","rc":[{"trd":[[11,12.06]],"batl":[[0,11.5,10],[1,25,1.25],[2,32,9]],"ltp":11.0,"tv":21.06,"id":8429550},{"trd":[[6.2,127.68]],"batl":[[0,6.4,30],[1,6.8,1.25],[2,11,3.26]],"ltp":6.2,"tv":467.83,"id":9417341},{"trd":[[6.6,23.12]],"batb":[[0,6.4,3],[1,6.2,16.13],[2,5.9,5.03]],"ltp":6.6,"tv":54.19,"id":8231803}],"tv":991.34}]}
{"op":"mcm","clk":"991925516","pt":1580510418957,"mc":[{"id":"1.168133548","rc":[{"batb":[[0,6.6,1.98],[1,6.4,3],[2,6.2,16.13]],"ltp":6.6,"tv":54.19,"id":8231803}]}]}
{"op":"mcm","clk":"991925681","pt":1580510422864,"mc":[{"id":"1.168133548","rc":[{"batl":[[2,990,3.16]],"ltp":9.4,"tv":22.1,"id":9193530}]}]}
{"op":"mcm","clk":"991925773","pt":1580510425285,"mc":[{"id":"1.168133548","rc":[{"batb":[[1,6.2,16.13],[2,6,3]],"ltp":6.6,"tv":54.19,"id":8231803}]}]}
{"op":"mcm","clk":"991925916","pt":1580510429294,"mc":[{"id":"1.168133548","rc":[{"batl":[[0,55,4.06]],"ltp":9.4,"tv":22.1,"id":9193530}]}]}
{"op":"mcm","clk":"991926101","pt":1580510434389,"mc":[{"id":"1.168133548","rc":[{"batb":[[1,5.9,7.37]],"ltp":6.2,"tv":467.83,"id":9417341}]}]}
{"op":"mcm","clk":"991926188","pt":1580510437214,"mc":[{"id":"1.168133548","rc":[{"batl":[[2,990,1.16]],"ltp":9.4,"tv":22.1,"id":9193530}]}]}
{"op":"mcm","clk":"991927123","pt":1580510460931,"mc":[{"id":"1.168133548","rc":[{"batb":[[0,6.4,1.98]],"ltp":6.6,"tv":54.19,"id":8231803}]}]}
{"op":"mcm","clk":"991929032","pt":1580510505407,"mc":[{"id":"1.168133548","rc":[{"trd":[[9,23.2]],"batb":[[0,9,7.07],[1,8.8,6.02],[2,8.6,12.61]],"batl":[[0,13,2],[1,16.5,2.84],[2,17,3.18]],"ltp":9.0,"tv":144.63,"id":15608820}],"tv":997.2}]}
{"op":"mcm","clk":"991929090","pt":1580510507411,"mc":[{"id":"1.168133548","rc":[{"batl":[[1,16,2.32],[2,16.5,2.84]],"ltp":9.0,"tv":144.63,"id":15608820}]}]}
{"op":"mcm","clk":"991929107","pt":1580510507771,"mc":[{"id":"1.168133548","rc":[{"batl":[[0,13,2.18]],"ltp":9.0,"tv":144.63,"id":15608820}]}]}
{"op":"mcm","clk":"991929136","pt":1580510508797,"mc":[{"id":"1.168133548","rc":[{"batl":[[0,12.5,2.18],[1,13,2],[2,16,2.32]],"ltp":9.0,"tv":144.63,"id":15608820}]}]}
{"op":"mcm","clk":"991929555","pt":1580510520118,"mc":[{"id":"1.168133548","rc":[{"trd":[[9.2,1.98]],"ltp":9.2,"tv":146.61,"id":15608820}],"tv":999.18}]}
{"op":"mcm","clk":"991929689","pt":1580510523300,"mc":[{"id":"1.168133548","rc":[{"batl":[[0,12,1.17],[1,12.5,2],[2,13,2]],"ltp":9.2,"tv":146.61,"id":15608820}]}]}
{"op":"mcm","clk":"991929732","pt":1580510524430,"mc":[{"id":"1.168133548","rc":[{"batl":[[0,12.5,2.99],[1,13,2],[2,16,2.32]],"ltp":9.2,"tv":146.61,"id":15608820}]}]}
{"op":"mcm","clk":"991929764","pt":1580510525251,"mc":[{"id":"1.168133548","rc":[{"batl":[[0,12.5,2]],"ltp":9.2,"tv":146.61,"id":15608820}]}]}
{"op":"mcm","clk":"991929824","pt":1580510526437,"mc":[{"id":"1.168133548","rc":[{"batl":[[2,16.5,2.84]],"ltp":9.2,"tv":146.61,"id":15608820}]}]}
{"op":"mcm","clk":"991929881","pt":1580510527526,"mc":[{"id":"1.168133548","rc":[{"trd":[[9.2,3.96]],"ltp":9.2,"tv":148.59,"id":15608820}],"tv":1001.16}]}
{"op":"mcm","clk":"991930049","pt":1580510531453,"mc":[{"id":"1.168133548","rc":[{"batl":[[0,12,1.06],[1,12.5,2],[2,13,2]],"ltp":9.2,"tv":148.59,"id":15608820}]}]}
{"op":"mcm","clk":"991930111","pt":1580510532741,"mc":[{"id":"1.168133548","rc":[{"batl":[[0,12.5,2.19],[1,13,2],[2,16.5,2.84]],"ltp":9.2,"tv":148.59,"id":15608820}]}]}
{"op":"mcm","clk":"991930237","pt":1580510535056,"mc":[{"id":"1.168133548","rc":[{"trd":[[9.2,5.74]],"ltp":9.2,"tv":150.37,"id":15608820}],"tv":1002.94}]}
{"op":"mcm","clk":"991930328","pt":1580510537362,"mc":[{"id":"1.168133548","rc":[{"batb":[[0,8.8,6.02],[1,8.6,12.61],[2,8.2,1.55]],"ltp":9.2,"tv":150.37,"id":15608820}]}]}
{"op":"mcm","clk":"991931671","pt":1580510568570,"mc":[{"id":"1.168133548","rc":[{"trd":[[13,4]],"batb":[[0,13,32],[1,11.5,1.55],[2,11,3]],"batl":[[0,13.5,3],[1,14.5,3.86],[2,15,15]],"ltp":13.0,"tv":142.35,"id":10616006}],"tv":1006.94}]}
{"op":"mcm","clk":"991932105","pt":1580510580314,"mc":[{"id":"1.168133548","rc":[{"batb":[[0,11.5,1.55],[1,11,3],[2,9.6,1.27]],"ltp":13.0,"tv":142.35,"id":10616006}]}]}
{"op":"mcm","clk":"991932920","pt":1580510601145,"mc":[{"id":"1.168133548","rc":[{"batl":[[0,13.5,39]],"ltp":13.0,"tv":142.35,"id":10616006}]}]}
{"op":"mcm","clk":"991933534","pt":1580510614447,"mc":[{"id":"1.168133548","rc":[{"batl":[[0,13,36],[1,13.5,3],[2,14.5,3.86]],"ltp":13.0,"tv":142.35,"id":10616006}]}]}
{"op":"mcm","clk":"991936166","pt":1580510672423,"mc":[{"id":"1.168133548","rc":[{"batb":[[0,9,1.92],[1,8.8,6.02],[2,8.6,11.63]],"ltp":9.2,"tv":150.37,"id":15608820}]}]}
{"op":"mcm","clk":"991936328","pt":1580510676538,"mc":[{"id":"1.168133548","rc":[{"batb":[[0,9.2,1.68],[1,9,1.92],[2,8.8,4.34]],"ltp":9.2,"tv":150.37,"id":15608820}]}]}
{"op":"mcm","clk":"991938578","pt":1580510723405,"mc":[{"id":"1.168133548","rc":[{"batb":[[0,9.2,3.85]],"ltp":9.2,"tv":150.37,"id":15608820}]}]}
{"op":"mcm","clk":"991939155","pt":1580510737103,"mc":[{"id":"1.168133548","rc":[{"trd":[[11,9.94],[11.5,26.8]],"batb":[[0,9.6,1.27],[1,9.2,11.32],[2,9,2]],"batl":[[0,11,5.45],[1,13,36],[2,13.5,3]],"ltp":11.0,"tv":151.46,"id":10616006}],"tv":1016.04}]}
{"op":"mcm","clk":"991939880","pt":1580510752855,"mc":[{"id":"1.168133548","rc":[{"batb":[[0,9.4,1.35],[1,9.2,3.85],[2,9,1.92]],"ltp":9.2,"tv":150.37,"id":15608820}]}]}
{"op":"mcm","clk":"991940954","pt":1580510776483,"mc":[{"id":"1.168133548","rc":[{"batb":[[0,10,1.72],[1,9.8,4.02]],"ltp":11.0,"tv":21.06,"id":8429550},{"batb":[[0,9.4,3.88],[1,9.2,10.87]],"ltp":11.0,"tv":151.46,"id":10616006}]}]}
{"op":"mcm","clk":"991943215","pt":1580510830061,"mc":[{"id":"1.168133548","rc":[{"batb":[[1,9.8,1.98]],"ltp":11.0,"tv":21.06,"id":8429550}]}]}
{"op":"mcm","clk":"991944476","pt":1580510861500,"mc":[{"id":"1.168133548","rc":[{"batb":[[1,9.2,1.91],[2,8.8,2.52]],"ltp":11.0,"tv":21.06,"id":8429550}]}]}
{"op":"mcm","clk":"991944506","pt":1580510862524,"mc":[{"id":"1.168133548","rc":[{"batb":[[0,10.5,1.98],[1,10,1.72],[2,9.2,1.91]],"ltp":11.0,"tv":21.06,"id":8429550}]}]}
{"op":"mcm","clk":"991944976","pt":1580510868244,"mc":[{"id":"1.168133548","rc":[{"batl":[[1,11.5,5],[2,13,36]],"ltp":11.0,"tv":151.46,"id":10616006}]}]}
{"op":"mcm","clk":"991945615","pt":1580510878753,"mc":[{"id":"1.168133548","rc":[{"batl":[[0,11.5,5],[1,13,36],[2,13.5,3]],"ltp":11.0,"tv":151.46,"id":10616006}]}]}
{"op":"mcm","clk":"991947298","pt":1580510903684,"mc":[{"id":"1.168133548","rc":[{"batb":[[1,9,2],[2,4.5,90.61]],"ltp":11.0,"tv":151.46,"id":10616006}]}]}
{"op":"mcm","clk":"991947981","pt":1580510912288,"mc":[{"id":"1.168133548","rc":[{"batb":[[0,9.6,10.42],[1,9.4,3.88],[2,9,2]],"ltp":11.0,"tv":151.46,"id":10616006},{"batb":[[0,14,1.23],[1,13.5,8.89],[2,13,1.98]],"ltp":16.0,"tv":5.12,"id":9001159}]}]}
{"op":"mcm","clk":"991948434","pt":1580510921327,"mc":[{"id":"1.168133548","rc":[{"trd":[[5.9,67.9],[6,187.64]],"batb":[[0,5.9,7.05],[1,5.8,82.69],[2,5.7,2.8]],"ltp":5.9,"tv":471.83,"id":9417341}],"tv":1020.04}]}
{"op":"mcm","clk":"991948761","pt":1580510929036,"mc":[{"id":"1.168133548","rc":[{"trd":[[7,43.66]],"batb":[[0,7,5.86]],"ltp":7.0,"tv":89.32,"id":17352128}],"tv":1024.04}]}
{"op":"mcm","clk":"991948848","pt":1580510931512,"mc":[{"id":"1.168133548","rc":[{"trd":[[6.8,8.64]],"batb":[[0,6,6.35],[1,5.8,2.52],[2,5.7,11]],"ltp":6.8,"tv":67.21,"id":10170404}],"tv":1032.69}]}
{"op":"mcm","clk":"991949041","pt":1580510937437,"mc":[{"id":"1.168133548","rc":[{"batb":[[0,9.8,1.24],[1,9.6,10.42],[2,9,2.45]],"ltp":11.0,"tv":151.46,"id":10616006},{"batb":[[1,13.5,7.41]],"ltp":16.0,"tv":5.12,"id":9001159}]}]}
{"op":"mcm","clk":"991949176","pt":1580510940419,"mc":[{"id":"1.168133548","rc":[{"trd":[[6,12]],"batb":[[0,5.8,2.52],[1,5.7,11],[2,3.9,143.79]],"ltp":6.0,"tv":79.21,"id":10170404}],"tv":1044.69}]}
{"op":"mcm","clk":"991949277","pt":1580510942437,"mc":[{"id":"1.168133548","rc":[{"batb":[[2,9,2]],"ltp":11.0,"tv":151.46,"id":10616006}]}]}
{"op":"mcm","clk":"991949297","pt":1580510942960,"mc":[{"id":"1.168133548","rc":[{"batb":[[0,9.8,1.68]],"ltp":11.0,"tv":151.46,"id":10616006},{"batb":[[1,9.2,5.11]],"ltp":9.2,"tv":150.37,"id":15608820},{"batb":[[0,14,3.6]],"ltp":16.0,"tv":5.12,"id":9001159}]}]}
{"op":"mcm","clk":"991949898","pt":1580510956345,"mc":[{"id":"1.168133548","rc":[{"batb":[[0,5.9,9.03]],"ltp":5.9,"tv":471.83,"id":9417341},{"batb":[[0,5.9,1.98],[1,5.8,2.52],[2,5.7,11]],"ltp":6.0,"tv":79.21,"id":10170404},{"batb":[[0,14,5.58],[2,12.5,1.41]],"ltp":16.0,"tv":5.12,"id":9001159}]}]}
{"op":"mcm","clk":"991950206","pt":1580510963183,"mc":[{"id":"1.168133548","rc":[{"batb":[[0,5.9,5.86]],"batl":[[1,7.4,6.09]],"ltp":6.0,"tv":79.21,"id":10170404}]}]}
{"op":"mcm","clk":"991950620","pt":1580510972485,"mc":[{"id":"1.168133548","rc":[{"batb":[[0,9.4,3.18],[2,8.8,3.03]],"ltp":9.2,"tv":150.37,"id":15608820}]}]}
{"op":"mcm","clk":"991951038","pt":1580510981493,"mc":[{"id":"1.168133548","rc":[{"batb":[[0,5.9,6.03]],"ltp":5.9,"tv":471.83,"id":9417341}]}]}
{"op":"mcm","clk":"991951467","pt":1580510990618,"mc":[{"id":"1.168133548","rc":[{"batb":[[1,9.2,2.94]],"ltp":9.2,"tv":150.37,"id":15608820}]}]}
{"op":"mcm","clk":"991951620","pt":1580510995342,"mc":[{"id":"1.168133548","rc":[{"batb":[[0,5.9,1.98],[1,5.8,6.4]],"ltp":6.0,"tv":79.21,"id":10170404}]}]}
{"op":"mcm","clk":"991952600","pt":1580511016472,"mc":[{"id":"1.168133548","rc":[{"batl":[[2,85,9]],"ltp":16.0,"tv":5.12,"id":9001159}]}]}
{"op":"mcm","clk":"991953744","pt":1580511048235,"mc":[{"id":"1.168133548","rc":[{"batb":[[0,9.6,1.68],[1,9.4,3.18],[2,9.2,1.26]],"ltp":9.2,"tv":150.37,"id":15608820}]}]}
{"op":"mcm","clk":"991953807","pt":1580511050548,"mc":[{"id":"1.168133548","rc":[{"batl":[[0,12.5,2]],"ltp":9.2,"tv":150.37,"id":15608820}]}]}
{"op":"mcm","clk":"991972616","pt":1580511263249,"mc":[{"id":"1.168133548","rc":[{"batb":[[0,9.8,3.72]],"ltp":11.0,"tv":151.46,"id":10616006},{"batb":[[0,5.9,5.37]],"ltp":6.0,"tv":79.21,"id":10170404}]}]}
{"op":"mcm","clk":"991973232","pt":1580511281383,"mc":[{"id":"1.168133548","rc":[{"batb":[[0,6,3.03],[1,5.9,5.37],[2,5.8,2.52]],"ltp":6.0,"tv":79.21,"id":10170404}]}]}
{"op":"mcm","clk":"991974098","pt":1580511302441,"mc":[{"id":"1.168133548","rc":[{"batb":[[2,5.7,11]],"ltp":6.0,"tv":79.21,"id":10170404}]}]}
{"op":"mcm","clk":"991974133","pt":1580511303216,"mc":[{"id":"1.168133548","rc":[{"batb":[[0,6,5.55]],"ltp":6.0,"tv":79.21,"id":10170404}]}]}
{"op":"mcm","clk":"991974325","pt":1580511307119,"mc":[{"id":"1.168133548","rc":[{"batb":[[2,5.8,3]],"ltp":6.0,"tv":79.21,"id":10170404}]}]}
{"op":"mcm","clk":"991974775","pt":1580511317541,"mc":[{"id":"1.168133548","rc":[{"batb":[[1,5.9,1.98]],"ltp":6.0,"tv":79.21,"id":10170404}]}]}
{"op":"mcm","clk":"991974792","pt":1580511317953,"mc":[{"id":"1.168133548","rc":[{"batb":[[0,6.2,3.23],[1,6,5.55],[2,5.9,1.98]],"ltp":6.0,"tv":79.21,"id":10170404},{"batb":[[0,9.8,1.76],[1,9.6,3.76],[2,9.4,1.35]],"ltp":9.2,"tv":150.37,"id":15608820}]}]}
{"op":"mcm","clk":"991975257","pt":1580511329500,"mc":[{"id":"1.168133548","rc":[{"batb":[[0,6.4,1.98],[1,6.2,3.23],[2,6,5.55]],"ltp":6.0,"tv":79.21,"id":10170404},{"batb":[[0,10,1.68],[1,9.8,1.76],[2,9.6,2.08]],"ltp":9.2,"tv":150.37,"id":15608820}]}]}
{"op":"mcm","clk":"991976456","pt":1580511362362,"mc":[{"id":"1.168133548","rc":[{"batb":[[2,9.6,3.28]],"ltp":9.2,"tv":150.37,"id":15608820}]}]}
{"op":"mcm","clk":"991976899","pt":1580511374390,"mc":[{"id":"1.168133548","rc":[{"trd":[[11.5,20]],"batl":[[0,25,1.25],[1,32,9],[2,50,2]],"ltp":11.5,"tv":41.05,"id":8429550},{"trd":[[6.4,59.99]],"batb":[[0,5.9,6.04]],"batl":[[0,6.6,3.81]],"ltp":6.4,"tv":531.82,"id":9417341},{"trd":[[6.4,24.69]],"batb":[[0,6.2,16.13],[1,6,3],[2,5.9,5.03]],"batl":[[0,7.4,2.54]],"ltp":6.4,"tv":58.15,"id":8231803},{"trd":[[10,3.36]],"batb":[[0,9.8,1.76],[1,9.6,3.28],[2,9.4,1.35]],"batl":[[0,12.5,2.84]],"ltp":10.0,"tv":153.73,"id":15608820}],"tv":1132.01}]}
{"op":"mcm","clk":"991976936","pt":1580511375269,"mc":[{"id":"1.168133548","rc":[{"batb":[[1,5.9,5.03],[2,5.8,2.01]],"ltp":6.4,"tv":58.15,"id":8231803}]}]}
{"op":"mcm","clk":"991976988","pt":1580511376500,"mc":[{"id":"1.168133548","rc":[{"batb":[[1,5.9,7.26]],"batl":[[1,8.2,2.5],[2,30,9.17]],"ltp":6.4,"tv":58.15,"id":8231803}]}]}
{"op":"mcm","clk":"991977030","pt":1580511377472,"mc":[{"id":"1.168133548","rc":[{"batl":[[1,8,3.03],[2,8.2,2.5]],"ltp":6.4,"tv":58.15,"id":8231803}]}]}
{"op":"mcm","clk":"991977052","pt":1580511378094,"mc":[{"id":"1.168133548","rc":[{"batl":[[0,25,1.44]],"ltp":11.5,"tv":41.05,"id":8429550}]}]}
{"op":"mcm","clk":"991977124","pt":1580511379998,"mc":[{"id":"1.168133548","rc":[{"batl":[[0,7.8,2.54]],"ltp":6.4,"tv":58.15,"id":8231803}]}]}
{"op":"mcm","clk":"991977173","pt":1580511381189,"mc":[{"id":"1.168133548","rc":[{"batl":[[1,32,9.17]],"ltp":11.5,"tv":41.05,"id":8429550}]}]}
{"op":"mcm","clk":"991977400","pt":1580511387216,"mc":[{"id":"1.168133548","rc":[{"batl":[[0,7.6,5.42],[1,7.8,2],[2,8,3.03]],"ltp":6.4,"tv":58.15,"id":8231803}]}]}
{"op":"mcm","clk":"991978480","pt":1580511410961,"mc":[{"id":"1.168133548","rc":[{"batl":[[1,9.6,2],[2,9.8,2.17]],"ltp":7.0,"tv":89.32,"id":17352128}]}]}
{"op":"mcm","clk":"991978522","pt":1580511411838,"mc":[{"id":"1.168133548","rc":[{"batl":[[1,9.6,4]],"ltp":7.0,"tv":89.32,"id":17352128}]}]}
{"op":"mcm","clk":"991979240","pt":1580511425501,"mc":[{"id":"1.168133548","rc":[{"trd":[[6.4,25.76]],"batb":[[0,6.4,1.45],[1,6.2,16.13],[2,5.9,7.26]],"batl":[[0,7.6,4.88]],"ltp":6.4,"tv":59.23,"id":8231803},{"trd":[[10,5.04]],"batb":[[0,10,1.14],[1,9.8,1.76],[2,9.6,3.28]],"batl":[[0,12.5,2]],"ltp":10.0,"tv":155.41,"id":15608820}],"tv":1134.76}]}
{"op":"mcm","clk":"991979889","pt":1580511440480,"mc":[{"id":"1.168133548","rc":[{"batl":[[2,10,8.42]],"ltp":7.0,"tv":89.32,"id":17352128}]}]}
{"op":"mcm","clk":"991979903","pt":1580511440890,"mc":[{"id":"1.168133548","rc":[{"batb":[[0,6,3.01],[1,5.9,6.03],[2,5.8,82.69]],"ltp":6.4,"tv":531.82,"id":9417341},{"batl":[[1,9.4,2.26],[2,9.6,4]],"ltp":7.0,"tv":89.32,"id":17352128}]}]}
{"op":"mcm","clk":"991980285","pt":1580511450818,"mc":[{"id":"1.168133548","rc":[{"batl":[[1,29,2],[2,32,9.17]],"ltp":11.5,"tv":41.05,"id":8429550},{"batb":[[2,9.6,1.2]],"ltp":10.0,"tv":155.41,"id":15608820}]}]}
{"op":"mcm","clk":"991981541","pt":1580511482534,"mc":[{"id":"1.168133548","rc":[{"batb":[[2,9.4,1.35]],"ltp":10.0,"tv":155.41,"id":15608820}]}]}
{"op":"mcm","clk":"991981919","pt":1580511493738,"mc":[{"id":"1.168133548","rc":[{"batl":[[0,17.5,5],[1,25,1.44],[2,29,2]],"ltp":11.5,"tv":41.05,"id":8429550}]}]}
{"op":"mcm","clk":"991982150","pt":1580511499348,"mc":[{"id":"1.168133548","rc":[{"batl":[[0,17.5,5.19],[1,25,1.25]],"ltp":11.5,"tv":41.05,"id":8429550}]}]}
{"op":"mcm","clk":"991982259","pt":1580511501965,"mc":[{"id":"1.168133548","rc":[{"batl":[[0,17.5,5.48]],"ltp":11.5,"tv":41.05,"id":8429550}]}]}
{"op":"mcm","clk":"991982882","pt":1580511518181,"mc":[{"id":"1.168133548","rc":[{"batb":[[0,11,1.82],[1,10.5,1.98],[2,10,1.72]],"ltp":11.5,"tv":41.05,"id":8429550}]}]}
{"op":"mcm","clk":"991983031","pt":1580511521980,"mc":[{"id":"1.168133548","rc":[{"batb":[[0,11.5,1.98],[1,11,1.82]],"ltp":11.5,"tv":41.05,"id":8429550},{"batb":[[0,6,4.99],[1,5.9,4.05]],"ltp":6.4,"tv":531.82,"id":9417341}]}]}
{"op":"mcm","clk":"991983144","pt":1580511525308,"mc":[{"id":"1.168133548","rc":[{"batl":[[2,32,9]],"ltp":11.5,"tv":41.05,"id":8429550}]}]}
{"op":"mcm","clk":"991984345","pt":1580511552153,"mc":[{"id":"1.168133548","rc":[{"batb":[[0,11.5,3.51]],"ltp":11.5,"tv":41.05,"id":8429550}]}]}
{"op":"mcm","clk":"991984392","pt":1580511553443,"mc":[{"id":"1.168133548","rc":[{"batb":[[0,6,1.99],[1,5.9,7.05]],"ltp":6.4,"tv":531.82,"id":9417341}]}]}
{"op":"mcm","clk":"991985887","pt":1580511587189,"mc":[{"id":"1.168133548","rc":[{"batb":[[1,10,1.72],[2,8.8,2.52]],"ltp":11.5,"tv":41.05,"id":8429550}]}]}
{"op":"mcm","clk":"991987453","pt":1580511614472,"mc":[{"id":"1.168133548","rc":[{"batb":[[0,11.5,1.53],[1,10.5,1.98],[2,10,1.72]],"ltp":11.5,"tv":41.05,"id":8429550}]}]}
{"op":"mcm","clk":"992001152","pt":1580511913700,"mc":[{"id":"1.168133548","rc":[{"batb":[[1,11,1.82],[2,10.5,1.98]],"ltp":11.5,"tv":41.05,"id":8429550},{"batb":[[0,10,3.14]],"ltp":10.0,"tv":155.41,"id":15608820}]}]}
{"op":"mcm","clk":"992003271","pt":1580511962399,"mc":[{"id":"1.168133548","rc":[{"batb":[[1,11,3.38],[2,10.5,4.5]],"ltp":11.5,"tv":41.05,"id":8429550},{"batb":[[2,9.6,1.2]],"ltp":10.0,"tv":155.41,"id":15608820}]}]}
{"op":"mcm","clk":"992003513","pt":1580511967922,"mc":[{"id":"1.168133548","rc":[{"batl":[[0,17,2.48],[1,17.5,5],[2,25,1.25]],"ltp":11.5,"tv":41.05,"id":8429550}]}]}
{"op":"mcm","clk":"992004139","pt":1580511982158,"mc":[{"id":"1.168133548","rc":[{"batl":[[0,16.5,2.44],[1,17,2.29],[2,17.5,5]],"ltp":11.5,"tv":41.05,"id":8429550}]}]}
{"op":"mcm","clk":"992004526","pt":1580511990854,"mc":[{"id":"1.168133548","rc":[{"batl":[[0,6.6,6.84]],"ltp":6.4,"tv":531.82,"id":9417341}]}]}
{"op":"mcm","clk":"992005818","pt":1580512022235,"mc":[{"id":"1.168133548","rc":[{"batl":[[0,16,2.19],[1,16.5,2.25],[2,17.5,5.29]],"ltp":11.5,"tv":41.05,"id":8429550}]}]}
{"op":"mcm","clk":"992006742","pt":1580512042373,"mc":[{"id":"1.168133548","rc":[{"batb":[[0,11.5,3.51],[2,10.5,2.52]],"ltp":11.5,"tv":41.05,"id":8429550}]}]}
{"op":"mcm","clk":"992006756","pt":1580512042636,"mc":[{"id":"1.168133548","rc":[{"batb":[[0,12,1.44],[1,11.5,3.51],[2,11,1.82]],"ltp":11.5,"tv":41.05,"id":8429550}]}]}
{"op":"mcm","clk":"992018131","pt":1580512077401,"mc":[{"id":"1.168133548","rc":[{"batb":[[2,10.5,2.52]],"batl":[[0,16.5,2.44],[1,17.5,5.29],[2,25,1.25]],"ltp":11.5,"tv":41.05,"id":8429550}]}]}
{"op":"mcm","clk":"992018951","pt":1580512094570,"mc":[{"id":"1.168133548","rc":[{"batb":[[0,6,1.98]],"ltp":6.4,"tv":531.82,"id":9417341}]}]}
{"op":"mcm","clk":"992019004","pt":1580512095549,"mc":[{"id":"1.168133548","rc":[{"batb":[[1,5.9,11.01]],"batl":[[0,6.6,3.03]],"ltp":6.4,"tv":531.82,"id":9417341}]}]}
{"op":"mcm","clk":"992027327","pt":1580512300497,"mc":[{"id":"1.168133548","rc":[{"trd":[[5.9,79.13],[6,191.6]],"batb":[[0,5.9,5.39],[1,5.8,82.69],[2,5.7,2.8]],"ltp":5.9,"tv":547.02,"id":9417341}],"tv":1149.96}]}
{"op":"mcm","clk":"992028137","pt":1580512317508,"mc":[{"id":"1.168133548","rc":[{"trd":[[6.2,2.16],[6.4,28.66]],"batb":[[0,6.2,15.58],[1,5.9,7.26],[2,5.8,2.01]],"ltp":6.2,"tv":63.23,"id":8231803}],"tv":1153.96}]}
{"op":"mcm","clk":"992028348","pt":1580512322521,"mc":[{"id":"1.168133548","rc":[{"batb":[[0,6,1.98],[1,5.9,5.39],[2,5.8,82.69]],"ltp":5.9,"tv":547.02,"id":9417341},{"batb":[[0,6.4,1.98],[1,6.2,15.58],[2,5.9,7.26]],"ltp":6.2,"tv":63.23,"id":8231803}]}]}
{"op":"mcm","clk":"992028829","pt":1580512335053,"mc":[{"id":"1.168133548","rc":[{"trd":[[10,11.33]],"batb":[[0,9.8,1.76],[1,9.6,1.2],[2,9.4,1.35]],"ltp":10.0,"tv":161.7,"id":15608820}],"tv":1160.24}]}
{"op":"mcm","clk":"992030781","pt":1580512382426,"mc":[{"id":"1.168133548","rc":[{"batb":[[1,9.4,1.35],[2,8.8,3.03]],"ltp":10.0,"tv":161.7,"id":15608820}]}]}
{"op":"mcm","clk":"992030796","pt":1580512382734,"mc":[{"id":"1.168133548","rc":[{"batb":[[2,9,1.29]],"ltp":10.0,"tv":161.7,"id":15608820}]}]}
{"op":"mcm","clk":"992032522","pt":1580512423747,"mc":[{"id":"1.168133548","rc":[{"batb":[[2,5.9,5.03]],"ltp":6.2,"tv":63.23,"id":8231803}]}]}
{"op":"mcm","clk":"992033920","pt":1580512462590,"mc":[{"id":"1.168133548","rc":[{"batb":[[0,10,1.98],[1,9.8,1.76],[2,9.4,1.35]],"ltp":10.0,"tv":161.7,"id":15608820}]}]}
{"op":"mcm","clk":"992034836","pt":1580512484605,"mc":[{"id":"1.168133548","rc":[{"batl":[[1,9.2,4],[2,9.4,2.26]],"ltp":7.0,"tv":89.32,"id":17352128}]}]}
{"op":"mcm","clk":"992035151","pt":1580512492535,"mc":[{"id":"1.168133548","rc":[{"batl":[[2,10,8.42]],"ltp":7.0,"tv":89.32,"id":17352128}]}]}
{"op":"mcm","clk":"992035156","pt":1580512492637,"mc":[{"id":"1.168133548","rc":[{"batl":[[1,9,2.35],[2,9.2,4]],"ltp":7.0,"tv":89.32,"id":17352128}]}]}
{"op":"mcm","clk":"992037022","pt":1580512535198,"mc":[{"id":"1.168133548","rc":[{"batl":[[0,6.6,8],[1,7,17.64],[2,7.4,6.09]],"ltp":6.0,"tv":79.21,"id":10170404}]}]}
{"op":"mcm","clk":"992037880","pt":1580512555118,"mc":[{"id":"1.168133548","rc":[{"batb":[[2,6,2.52]],"batl":[[2,7.4,3]],"ltp":6.0,"tv":79.21,"id":10170404}]}]}
{"op":"mcm","clk":"992038211","pt":1580512563422,"mc":[{"id":"1.168133548","rc":[{"batb":[[1,6,2.52],[2,5.8,3]],"ltp":6.0,"tv":79.21,"id":10170404}]}]}
{"op":"mcm","clk":"992038660","pt":1580512575564,"mc":[{"id":"1.168133548","rc":[{"trd":[[6.6,16]],"batl":[[0,7,17.64],[1,7.4,3],[2,7.6,6.35]],"ltp":6.6,"tv":95.21,"id":10170404}],"tv":1176.24}]}
{"op":"mcm","clk":"992038702","pt":1580512576284,"mc":[{"id":"1.168133548","rc":[{"batb":[[1,6,2.87]],"ltp":6.6,"tv":95.21,"id":10170404}]}]}
{"op":"mcm","clk":"992039117","pt":1580512586674,"mc":[{"id":"1.168133548","rc":[{"batb":[[2,5.8,7.71]],"batl":[[1,7.4,6.7]],"ltp":6.6,"tv":95.21,"id":10170404}]}]}
{"op":"mcm","clk":"992040660","pt":1580512622051,"mc":[{"id":"1.168133548","rc":[{"batb":[[1,5.9,2.87]],"ltp":6.6,"tv":95.21,"id":10170404}]}]}
{"op":"mcm","clk":"992040845","pt":1580512626153,"mc":[{"id":"1.168133548","rc":[{"batb":[[2,5.8,4.71]],"ltp":6.6,"tv":95.21,"id":10170404}]}]}
{"op":"mcm","clk":"992041795","pt":1580512650469,"mc":[{"id":"1.168133548","rc":[{"batb":[[0,6,2.33],[1,5.9,2.52]],"ltp":6.6,"tv":95.21,"id":10170404}]}]}
{"op":"mcm","clk":"992041814","pt":1580512650880,"mc":[{"id":"1.168133548","rc":[{"batb":[[0,6,5.36],[2,5.7,11]],"ltp":6.6,"tv":95.21,"id":10170404}]}]}
{"op":"mcm","clk":"992044877","pt":1580512723078,"mc":[{"id":"1.168133548","rc":[{"batl":[[0,7.4,50],[1,7.6,13],[2,9,2.35]],"ltp":7.0,"tv":89.32,"id":17352128}]}]}
{"op":"mcm","clk":"992046435","pt":1580512768118,"mc":[{"id":"1.168133548","rc":[{"batl":[[0,6.4,50],[1,6.6,3.03],[2,6.8,1.25]],"ltp":5.9,"tv":547.02,"id":9417341}]}]}
{"op":"mcm","clk":"992048319","pt":1580512807489,"mc":[{"id":"1.168133548","rc":[{"batb":[[2,5.8,3]],"ltp":6.6,"tv":95.21,"id":10170404}]}]}
{"op":"mcm","clk":"992048650","pt":1580512815346,"mc":[{"id":"1.168133548","rc":[{"trd":[[6.4,141.68]],"batl":[[0,6.4,9.16]],"ltp":6.4,"tv":628.7,"id":9417341}],"tv":1257.92}]}
{"op":"mcm","clk":"992049871","pt":1580512847356,"mc":[{"id":"1.168133548","rc":[{"batl":[[0,7.2,2],[1,7.4,50],[2,7.6,13]],"ltp":7.0,"tv":89.32,"id":17352128}]}]}
{"op":"mcm","clk":"992052779","pt":1580512925152,"mc":[{"id":"1.168133548","rc":[{"trd":[[11,3.42],[11.5,0.58]],"batb":[[0,11,5.63]],"ltp":11.0,"tv":26.11,"id":9193530}],"tv":1261.93}]}
{"op":"mcm","clk":"992066841","pt":1580513030112,"mc":[{"id":"1.168133548","rc":[{"batb":[[0,10,1.68],[1,9.8,3.72],[2,9.6,10.42]],"ltp":11.0,"tv":151.46,"id":10616006},{"batb":[[0,11.5,1.98],[1,11,5.63],[2,10.5,3.03]],"ltp":11.0,"tv":26.11,"id":9193530}]}]}
{"op":"mcm","clk":"992067709","pt":1580513050560,"mc":[{"id":"1.168133548","rc":[{"batb":[[0,10.5,1.16],[1,10,1.68],[2,9.6,10.86]],"ltp":11.0,"tv":151.46,"id":10616006},{"batb":[[1,11,5.52]],"ltp":11.0,"tv":26.11,"id":9193530}]}]}
{"op":"mcm","clk":"992068906","pt":1580513080818,"mc":[{"id":"1.168133548","rc":[{"batb":[[2,5.9,7.19]],"ltp":6.2,"tv":63.23,"id":8231803}]}]}
{"op":"mcm","clk":"992070559","pt":1580513128103,"mc":[{"id":"1.168133548","rc":[{"batb":[[1,9.8,2.12],[2,9.6,10.42]],"ltp":11.0,"tv":151.46,"id":10616006}]}]}
{"op":"mcm","clk":"992071624","pt":1580513158439,"mc":[{"id":"1.168133548","rc":[{"batb":[[0,10,1.22]],"ltp":11.0,"tv":151.46,"id":10616006}]}]}
{"op":"mcm","clk":"992072942","pt":1580513195308,"mc":[{"id":"1.168133548","rc":[{"trd":[[6.4,145.68]],"batl":[[0,6.4,7.16]],"ltp":6.4,"tv":632.7,"id":9417341}],"tv":1265.93}]}
{"op":"mcm","clk":"992077083","pt":1580513296204,"mc":[{"id":"1.168133548","rc":[{"trd":[[10,15.29]],"batb":[[0,9.8,1.76],[1,9.4,1.35],[2,9,1.29]],"batl":[[0,12.5,2.54]],"ltp":10.0,"tv":165.66,"id":15608820}],"tv":1269.89}]}
{"op":"mcm","clk":"992081253","pt":1580513395024,"mc":[{"id":"1.168133548","rc":[{"batl":[[0,7,2],[1,7.6,4.88],[2,7.8,2]],"ltp":6.2,"tv":63.23,"id":8231803}]}]}
{"op":"mcm","clk":"992082697","pt":1580513426943,"mc":[{"id":"1.168133548","rc":[{"batl":[[2,8,3.03]],"ltp":6.2,"tv":63.23,"id":8231803}]}]}
{"op":"mcm","clk":"992083281","pt":1580513440063,"mc":[{"id":"1.168133548","rc":[{"trd":[[7,47.66]],"batb":[[0,7,3.86]],"ltp":7.0,"tv":93.32,"id":17352128}],"tv":1273.89}]}
{"op":"mcm","clk":"992083749","pt":1580513450978,"mc":[{"id":"1.168133548","rc":[{"batl":[[2,8,5.03]],"ltp":6.2,"tv":63.23,"id":8231803}]}]}
{"op":"mcm","clk":"992085755","pt":1580513502122,"mc":[{"id":"1.168133548","rc":[{"trd":[[5.9,95.17],[6,195.56]],"batb":[[0,5.8,82.69],[1,5.7,2.8],[2,5.5,16.85]],"ltp":5.9,"tv":652.7,"id":9417341}],"tv":1293.89}]}
{"op":"mcm","clk":"992085982","pt":1580513509271,"mc":[{"id":"1.168133548","rc":[{"batb":[[0,5.9,1.98],[1,5.8,82.69],[2,5.7,2.8]],"ltp":5.9,"tv":652.7,"id":9417341}]}]}
{"op":"mcm","clk":"992086039","pt":1580513511073,"mc":[{"id":"1.168133548","rc":[{"batl":[[0,6.2,2.85],[1,6.4,7.16],[2,6.6,3.03]],"ltp":5.9,"tv":652.7,"id":9417341}]}]}
{"op":"mcm","clk":"992086619","pt":1580513525184,"mc":[{"id":"1.168133548","rc":[{"trd":[[5.8,90.66],[5.9,99.13]],"batb":[[0,5.8,54.67],[1,5.7,2.8],[2,5.5,16.85]],"ltp":5.8,"tv":712.71,"id":9417341}],"tv":1353.9}]}
{"op":"mcm","clk":"992087048","pt":1580513535991,"mc":[{"id":"1.168133548","rc":[{"trd":[[6.4,32.62]],"batb":[[0,6.2,15.58],[1,5.9,7.19],[2,5.8,2.01]],"batl":[[0,7,2.54]],"ltp":6.4,"tv":67.19,"id":8231803}],"tv":1357.86}]}
{"op":"mcm","clk":"992087533","pt":1580513547304,"mc":[{"id":"1.168133548","rc":[{"batl":[[1,8,5.03],[2,8.2,2.5]],"ltp":6.4,"tv":67.19,"id":8231803}]}]}
{"op":"mcm","clk":"992090220","pt":1580513603307,"mc":[{"id":"1.168133548","rc":[{"trd":[[6.4,33.7]],"batb":[[0,6.4,1.45],[1,6.2,15.58],[2,5.9,7.19]],"batl":[[0,7,2]],"ltp":6.4,"tv":68.27,"id":8231803}],"tv":1358.94}]}
{"op":"mcm","clk":"992090338","pt":1580513605470,"mc":[{"id":"1.168133548","rc":[{"batl":[[1,7.8,4.76],[2,8,5.03]],"ltp":6.4,"tv":68.27,"id":8231803}]}]}
{"op":"mcm","clk":"992091031","pt":1580513623112,"mc":[{"id":"1.168133548","rc":[{"batl":[[1,7.6,3.03],[2,7.8,4.76]],"ltp":6.4,"tv":68.27,"id":8231803}]}]}
{"op":"mcm","clk":"992091097","pt":1580513624534,"mc":[{"id":"1.168133548","rc":[{"batl":[[2,8,2]],"ltp":6.4,"tv":68.27,"id":8231803}]}]}
{"op":"mcm","clk":"992092504","pt":1580513656354,"mc":[{"id":"1.168133548","rc":[{"batl":[[1,8,5.03],[2,8.2,2.5]],"ltp":6.4,"tv":68.27,"id":8231803}]}]}
{"op":"mcm","clk":"992092769","pt":1580513662845,"mc":[{"id":"1.168133548","rc":[{"batl":[[1,7.8,4.76],[2,8,5.03]],"ltp":6.4,"tv":68.27,"id":8231803}]}]}
{"op":"mcm","clk":"992093847","pt":1580513689016,"mc":[{"id":"1.168133548","rc":[{"batl":[[1,7.6,3.03],[2,7.8,4.76]],"ltp":6.4,"tv":68.27,"id":8231803}]}]}
{"op":"mcm","clk":"992094445","pt":1580513702006,"mc":[{"id":"1.168133548","rc":[{"batl":[[2,8,2]],"ltp":6.4,"tv":68.27,"id":8231803}]}]}
{"op":"mcm","clk":"992095403","pt":1580513721863,"mc":[{"id":"1.168133548","rc":[{"batl":[[1,8,5.03],[2,8.2,2.5]],"ltp":6.4,"tv":68.27,"id":8231803}]}]}
{"op":"mcm","clk":"992096218","pt":1580513740475,"mc":[{"id":"1.168133548","rc":[{"batl":[[2,6.8,1.25]],"ltp":5.8,"tv":712.71,"id":9417341}]}]}
{"op":"mcm","clk":"992096255","pt":1580513741045,"mc":[{"id":"1.168133548","rc":[{"batl":[[1,7.8,4.76],[2,8,5.03]],"ltp":6.4,"tv":68.27,"id":8231803}]}]}
{"op":"mcm","clk":"992096897","pt":1580513754476,"mc":[{"id":"1.168133548","rc":[{"batl":[[1,7.6,3.03],[2,7.8,4.76]],"ltp":6.4,"tv":68.27,"id":8231803}]}]}
{"op":"mcm","clk":"992097156","pt":1580513759696,"mc":[{"id":"1.168133548","rc":[{"batl":[[2,8,2]],"ltp":6.4,"tv":68.27,"id":8231803}]}]}
{"op":"mcm","clk":"992097861","pt":1580513776103,"mc":[{"id":"1.168133548","rc":[{"trd":[[6.2,133.38]],"batl":[[0,6.4,7.16],[1,6.8,1.25],[2,11,3.26]],"ltp":6.2,"tv":718.41,"id":9417341}],"tv":1364.64}]}
{"op":"mcm","clk":"992098325","pt":1580513786560,"mc":[{"id":"1.168133548","rc":[{"batl":[[1,8,5.03],[2,8.2,2.5]],"ltp":6.4,"tv":68.27,"id":8231803}]}]}
{"op":"mcm","clk":"992098749","pt":1580513796013,"mc":[{"id":"1.168133548","rc":[{"batb":[[0,5.9,1.98],[1,5.8,54.67],[2,5.7,2.8]],"ltp":6.2,"tv":718.41,"id":9417341}]}]}
{"op":"mcm","clk":"992098817","pt":1580513799125,"mc":[{"id":"1.168133548","rc":[{"batl":[[1,7.8,4.76],[2,8,5.03]],"ltp":6.4,"tv":68.27,"id":8231803}]}]}
{"op":"mcm","clk":"992099648","pt":1580513819883,"mc":[{"id":"1.168133548","rc":[{"batl":[[1,7.6,3.03],[2,7.8,4.76]],"ltp":6.4,"tv":68.27,"id":8231803}]}]}
{"op":"mcm","clk":"992100276","pt":1580513834569,"mc":[{"id":"1.168133548","rc":[{"batb":[[0,5.9,4.98]],"ltp":6.2,"tv":718.41,"id":9417341}]}]}
{"op":"mcm","clk":"992100400","pt":1580513836982,"mc":[{"id":"1.168133548","rc":[{"batl":[[2,8,2]],"ltp":6.4,"tv":68.27,"id":8231803}]}]}
{"op":"mcm","clk":"992111080","pt":1580513852387,"mc":[{"id":"1.168133548","rc":[{"batl":[[1,8,5.03],[2,8.2,2.5]],"ltp":6.4,"tv":68.27,"id":8231803}]}]}
{"op":"mcm","clk":"992111245","pt":1580513856708,"mc":[{"id":"1.168133548","rc":[{"batl":[[1,7.8,4.76],[2,8,5.03]],"ltp":6.4,"tv":68.27,"id":8231803}]}]}
{"op":"mcm","clk":"992112554","pt":1580513884554,"mc":[{"id":"1.168133548","rc":[{"batl":[[2,8,2]],"ltp":6.4,"tv":68.27,"id":8231803}]}]}
{"op":"mcm","clk":"992112555","pt":1580513884656,"mc":[{"id":"1.168133548","rc":[{"batl":[[1,7.6,3.03],[2,7.8,4.76]],"ltp":6.4,"tv":68.27,"id":8231803}]}]}
{"op":"mcm","clk":"992112958","pt":1580513894542,"mc":[{"id":"1.168133548","rc":[{"batl":[[2,8,2]],"ltp":6.4,"tv":68.27,"id":8231803}]}]}
{"op":"mcm","clk":"992113944","pt":1580513917050,"mc":[{"id":"1.168133548","rc":[{"batl":[[1,8,5.03],[2,8.2,2.5]],"ltp":6.4,"tv":68.27,"id":8231803}]}]}
{"op":"mcm","clk":"992114503","pt":1580513932869,"mc":[{"id":"1.168133548","rc":[{"batl":[[1,7.8,4.76],[2,8,5.03]],"ltp":6.4,"tv":68.27,"id":8231803}]}]}
{"op":"mcm","clk":"992115069","pt":1580513949413,"mc":[{"id":"1.168133548","rc":[{"batl":[[1,7.6,3.03],[2,7.8,4.76]],"ltp":6.4,"tv":68.27,"id":8231803}]}]}
{"op":"mcm","clk":"992115168","pt":1580513951926,"mc":[{"id":"1.168133548","rc":[{"batl":[[2,8,2]],"ltp":6.4,"tv":68.27,"id":8231803}]}]}
{"op":"mcm","clk":"992116198","pt":1580513981334,"mc":[{"id":"1.168133548","rc":[{"batl":[[1,8,5.03],[2,8.2,2.5]],"ltp":6.4,"tv":68.27,"id":8231803}]}]}
{"op":"mcm","clk":"992116492","pt":1580513990054,"mc":[{"id":"1.168133548","rc":[{"batl":[[1,7.8,4.76],[2,8,5.03]],"ltp":6.4,"tv":68.27,"id":8231803}]}]}
{"op":"mcm","clk":"992117451","pt":1580514014274,"mc":[{"id":"1.168133548","rc":[{"batl":[[1,7.6,3.03],[2,7.8,4.76]],"ltp":6.4,"tv":68.27,"id":8231803}]}]}
{"op":"mcm","clk":"992117546","pt":1580514016383,"mc":[{"id":"1.168133548","rc":[{"batl":[[0,12.5,2]],"ltp":10.0,"tv":165.66,"id":15608820}]}]}
{"op":"mcm","clk":"992118053","pt":1580514028423,"mc":[{"id":"1.168133548","rc":[{"batl":[[2,8,2]],"ltp":6.4,"tv":68.27,"id":8231803}]}]}
{"op":"mcm","clk":"992118788","pt":1580514046119,"mc":[{"id":"1.168133548","rc":[{"batl":[[0,6,15.2],[1,6.4,7.16],[2,6.8,1.25]],"ltp":6.2,"tv":718.41,"id":9417341}]}]}
{"op":"mcm","clk":"992118858","pt":1580514047558,"mc":[{"id":"1.168133548","rc":[{"batl":[[1,7.8,4.76],[2,8,5.03]],"ltp":6.4,"tv":68.27,"id":8231803}]}]}
{"op":"mcm","clk":"992119118","pt":1580514053739,"mc":[{"id":"1.168133548","rc":[{"batb":[[0,5.9,1.98]],"ltp":6.2,"tv":718.41,"id":9417341}]}]}
{"op":"mcm","clk":"992120020","pt":1580514079553,"mc":[{"id":"1.168133548","rc":[{"batl":[[1,7.6,3.03],[2,7.8,4.76]],"ltp":6.4,"tv":68.27,"id":8231803}]}]}
{"op":"mcm","clk":"992120172","pt":1580514085409,"mc":[{"id":"1.168133548","rc":[{"batl":[[2,8,2]],"ltp":6.4,"tv":68.27,"id":8231803}]}]}
{"op":"mcm","clk":"992120961","pt":1580514112544,"mc":[{"id":"1.168133548","rc":[{"batl":[[1,8,2],[2,8.2,2.5]],"ltp":6.4,"tv":68.27,"id":8231803}]}]}
{"op":"mcm","clk":"992120989","pt":1580514113521,"mc":[{"id":"1.168133548","rc":[{"batl":[[1,8,5.03]],"ltp":6.4,"tv":68.27,"id":8231803}]}]}
{"op":"mcm","clk":"992121259","pt":1580514122932,"mc":[{"id":"1.168133548","rc":[{"batl":[[1,7.8,4.76],[2,8,5.03]],"ltp":6.4,"tv":68.27,"id":8231803}]}]}
{"op":"mcm","clk":"992121992","pt":1580514145254,"mc":[{"id":"1.168133548","rc":[{"batl":[[1,7.6,3.03],[2,7.8,4.76]],"ltp":6.4,"tv":68.27,"id":8231803}]}]}
{"op":"mcm","clk":"992122517","pt":1580514161886,"mc":[{"id":"1.168133548","rc":[{"batl":[[2,8,2]],"ltp":6.4,"tv":68.27,"id":8231803}]}]}
{"op":"mcm","clk":"992123139","pt":1580514178807,"mc":[{"id":"1.168133548","rc":[{"batl":[[1,8,5.03],[2,8.2,2.5]],"ltp":6.4,"tv":68.27,"id":8231803}]}]}
{"op":"mcm","clk":"992123199","pt":1580514180903,"mc":[{"id":"1.168133548","rc":[{"batl":[[1,7.8,4.76],[2,8,5.03]],"ltp":6.4,"tv":68.27,"id":8231803}]}]}
{"op":"mcm","clk":"992124468","pt":1580514211368,"mc":[{"id":"1.168133548","rc":[{"batl":[[2,8,2]],"ltp":6.4,"tv":68.27,"id":8231803}]}]}
{"op":"mcm","clk":"992124477","pt":1580514211578,"mc":[{"id":"1.168133548","rc":[{"batl":[[1,7.6,3.03],[2,7.8,4.76]],"ltp":6.4,"tv":68.27,"id":8231803}]}]}
{"op":"mcm","clk":"992124820","pt":1580514220465,"mc":[{"id":"1.168133548","rc":[{"batl":[[2,8,2]],"ltp":6.4,"tv":68.27,"id":8231803}]}]}
{"op":"mcm","clk":"992125430","pt":1580514239274,"mc":[{"id":"1.168133548","rc":[{"batl":[[0,6.4,7.16],[1,6.8,1.25],[2,11,3.26]],"ltp":6.2,"tv":718.41,"id":9417341}]}]}
{"op":"mcm","clk":"992125595","pt":1580514244140,"mc":[{"id":"1.168133548","rc":[{"trd":[[5.8,117.1],[5.9,103.1]],"batb":[[0,5.8,41.44],[1,5.7,2.8],[2,5.5,16.85]],"ltp":5.8,"tv":748.81,"id":9417341}],"tv":1395.04}]}
{"op":"mcm","clk":"992125609","pt":1580514244857,"mc":[{"id":"1.168133548","rc":[{"batl":[[1,8,5.03],[2,8.2,2.5]],"ltp":6.4,"tv":68.27,"id":8231803}]}]}
{"op":"mcm","clk":"992125726","pt":1580514249372,"mc":[{"id":"1.168133548","rc":[{"batb":[[0,5.9,3],[1,5.8,41.44],[2,5.7,2.8]],"ltp":5.8,"tv":748.81,"id":9417341}]}]}
{"op":"mcm","clk":"992125794","pt":1580514252569,"mc":[{"id":"1.168133548","rc":[{"trd":[[7,55.38]],"batb":[[0,6.8,4.44],[1,6,3],[2,5.7,3]],"batl":[[0,7,11.34],[1,7.2,2],[2,7.4,50]],"ltp":7.0,"tv":101.04,"id":17352128}],"tv":1402.77}]}
{"op":"mcm","clk":"992125978","pt":1580514257400,"mc":[{"id":"1.168133548","rc":[{"trd":[[9.8,3.51]],"batb":[[0,9.4,1.35],[1,9,1.29],[2,8.8,3.03]],"batl":[[0,12.5,2.76]],"ltp":9.8,"tv":169.17,"id":15608820}],"tv":1406.28}]}
{"op":"mcm","clk":"992126018","pt":1580514258376,"mc":[{"id":"1.168133548","rc":[{"batl":[[1,7.8,4.76],[2,8,5.03]],"ltp":6.4,"tv":68.27,"id":8231803}]}]}
{"op":"mcm","clk":"992126067","pt":1580514259562,"mc":[{"id":"1.168133548","rc":[{"batb":[[0,6.4,4.13]],"ltp":6.4,"tv":68.27,"id":8231803},{"batb":[[1,9.8,3.87]],"ltp":11.0,"tv":151.46,"id":10616006},{"batb":[[0,6.2,2.78],[1,6,5.36],[2,5.9,2.52]],"ltp":6.6,"tv":95.21,"id":10170404},{"batb":[[0,11.5,3.48]],"ltp":11.0,"tv":26.11,"id":9193530}]}]}
{"op":"mcm","clk":"992126776","pt":1580514279395,"mc":[{"id":"1.168133548","rc":[{"batl":[[1,7.6,3.03],[2,7.8,4.76]],"ltp":6.4,"tv":68.27,"id":8231803}]}]}
{"op":"mcm","clk":"992126956","pt":1580514285289,"mc":[{"id":"1.168133548","rc":[{"batb":[[0,6.4,1.98],[1,6.2,2.78],[2,6,3.38]],"ltp":6.6,"tv":95.21,"id":10170404},{"batb":[[1,9.2,1.78],[2,9,1.29]],"ltp":9.8,"tv":169.17,"id":15608820},{"batb":[[0,6.8,8.74]],"ltp":7.0,"tv":101.04,"id":17352128}]}]}
{"op":"mcm","clk":"992127061","pt":1580514289298,"mc":[{"id":"1.168133548","rc":[{"batb":[[2,5.6,11]],"ltp":7.0,"tv":101.04,"id":17352128}]}]}
{"op":"mcm","clk":"992127364","pt":1580514297421,"mc":[{"id":"1.168133548","rc":[{"batl":[[2,8,2]],"ltp":6.4,"tv":68.27,"id":8231803}]}]}
{"op":"mcm","clk":"992127548","pt":1580514302548,"mc":[{"id":"1.168133548","rc":[{"batb":[[1,6.2,5.3]],"ltp":6.6,"tv":95.21,"id":10170404}]}]}
{"op":"mcm","clk":"992127894","pt":1580514313131,"mc":[{"id":"1.168133548","rc":[{"batl":[[1,8,5.03],[2,8.2,2.5]],"ltp":6.4,"tv":68.27,"id":8231803}]}]}
{"op":"mcm","clk":"992128015","pt":1580514316527,"mc":[{"id":"1.168133548","rc":[{"batl":[[1,7.8,4.76],[2,8,5.03]],"ltp":6.4,"tv":68.27,"id":8231803}]}]}
{"op":"mcm","clk":"992128847","pt":1580514346661,"mc":[{"id":"1.168133548","rc":[{"batl":[[1,7.6,3.03],[2,7.8,4.76]],"ltp":6.4,"tv":68.27,"id":8231803}]}]}
{"op":"mcm","clk":"992129175","pt":1580514355697,"mc":[{"id":"1.168133548","rc":[{"batl":[[2,8,2]],"ltp":6.4,"tv":68.27,"id":8231803}]}]}
{"op":"mcm","clk":"992129920","pt":1580514379517,"mc":[{"id":"1.168133548","rc":[{"batl":[[1,8,2],[2,8.2,2.5]],"ltp":6.4,"tv":68.27,"id":8231803}]}]}
{"op":"mcm","clk":"992129924","pt":1580514379620,"mc":[{"id":"1.168133548","rc":[{"batl":[[1,8,5.03]],"ltp":6.4,"tv":68.27,"id":8231803}]}]}
{"op":"mcm","clk":"992130364","pt":1580514393472,"mc":[{"id":"1.168133548","rc":[{"batb":[[0,5.9,5.92]],"ltp":5.8,"tv":748.81,"id":9417341}]}]}
{"op":"mcm","clk":"992130393","pt":1580514394249,"mc":[{"id":"1.168133548","rc":[{"batl":[[1,7.8,4.76],[2,8,5.03]],"ltp":6.4,"tv":68.27,"id":8231803}]}]}
{"op":"mcm","clk":"992131043","pt":1580514412488,"mc":[{"id":"1.168133548","rc":[{"batl":[[1,7.6,3.03],[2,7.8,4.76]],"ltp":6.4,"tv":68.27,"id":8231803}]}]}
{"op":"mcm","clk":"992131075","pt":1580514413463,"mc":[{"id":"1.168133548","rc":[{"batl":[[2,8,2]],"ltp":6.4,"tv":68.27,"id":8231803}]}]}
{"op":"mcm","clk":"992131867","pt":1580514440042,"mc":[{"id":"1.168133548","rc":[{"batb":[[0,5.9,2.92]],"ltp":5.8,"tv":748.81,"id":9417341}]}]}
{"op":"mcm","clk":"992132043","pt":1580514445149,"mc":[{"id":"1.168133548","rc":[{"batl":[[1,8,5.03],[2,8.2,2.5]],"ltp":6.4,"tv":68.27,"id":8231803}]}]}
{"op":"mcm","clk":"992132254","pt":1580514452363,"mc":[{"id":"1.168133548","rc":[{"batl":[[1,7.8,4.76],[2,8,5.03]],"ltp":6.4,"tv":68.27,"id":8231803}]}]}
{"op":"mcm","clk":"992132986","pt":1580514478487,"mc":[{"id":"1.168133548","rc":[{"batl":[[1,7.6,3.03],[2,7.8,4.76]],"ltp":6.4,"tv":68.27,"id":8231803}]}]}
{"op":"mcm","clk":"992133266","pt":1580514490569,"mc":[{"id":"1.168133548","rc":[{"batl":[[2,8,2]],"ltp":6.4,"tv":68.27,"id":8231803}]}]}
{"op":"mcm","clk":"992133428","pt":1580514496962,"mc":[{"id":"1.168133548","rc":[{"trd":[[6.4,41.97]],"batb":[[0,6.2,15.58],[1,5.9,7.19],[2,5.8,2.01]],"ltp":6.4,"tv":76.53,"id":8231803}],"tv":1414.55}]}
{"op":"mcm","clk":"992133843","pt":1580514511367,"mc":[{"id":"1.168133548","rc":[{"batl":[[1,8,5.03],[2,8.2,2.5]],"ltp":6.4,"tv":76.53,"id":8231803}]}]}
{"op":"mcm","clk":"992134403","pt":1580514528731,"mc":[{"id":"1.168133548","rc":[{"batl":[[1,7.8,4.76],[2,8,5.03]],"ltp":6.4,"tv":76.53,"id":8231803}]}]}
{"op":"mcm","clk":"992134846","pt":1580514544248,"mc":[{"id":"1.168133548","rc":[{"batl":[[1,7.6,3.03],[2,7.8,4.76]],"ltp":6.4,"tv":76.53,"id":8231803}]}]}
{"op":"mcm","clk":"992134939","pt":1580514547844,"mc":[{"id":"1.168133548","rc":[{"batl":[[2,8,2]],"ltp":6.4,"tv":76.53,"id":8231803}]}]}
{"op":"mcm","clk":"992135403","pt":1580514562453,"mc":[{"id":"1.168133548","rc":[{"batb":[[0,6.4,1.98],[1,6.2,15.58],[2,5.9,7.19]],"ltp":6.4,"tv":76.53,"id":8231803}]}]}
{"op":"mcm","clk":"992135768","pt":1580514577290,"mc":[{"id":"1.168133548","rc":[{"batl":[[1,8,5.03],[2,8.2,2.5]],"ltp":6.4,"tv":76.53,"id":8231803}]}]}
{"op":"mcm","clk":"992135902","pt":1580514586593,"mc":[{"id":"1.168133548","rc":[{"batl":[[1,7.8,4.76],[2,8,5.03]],"ltp":6.4,"tv":76.53,"id":8231803}]}]}
{"op":"mcm","clk":"992136240","pt":1580514604165,"mc":[{"id":"1.168133548","rc":[{"batl":[[1,7.2,27]],"ltp":7.0,"tv":101.04,"id":17352128}]}]}
{"op":"mcm","clk":"992136303","pt":1580514609509,"mc":[{"id":"1.168133548","rc":[{"batl":[[2,8,2]],"ltp":6.4,"tv":76.53,"id":8231803}]}]}
{"op":"mcm","clk":"992136308","pt":1580514609611,"mc":[{"id":"1.168133548","rc":[{"batl":[[1,7.6,3.03],[2,7.8,4.76]],"ltp":6.4,"tv":76.53,"id":8231803}]}]}
{"op":"mcm","clk":"992136659","pt":1580514625301,"mc":[{"id":"1.168133548","rc":[{"batl":[[2,8,2]],"ltp":6.4,"tv":76.53,"id":8231803}]}]}
{"op":"mcm","clk":"992136943","pt":1580514635934,"mc":[{"id":"1.168133548","rc":[{"batl":[[0,6.2,2],[1,6.4,7.16],[2,6.8,1.25]],"ltp":5.8,"tv":748.81,"id":9417341}]}]}
{"op":"mcm","clk":"992136987","pt":1580514637343,"mc":[{"id":"1.168133548","rc":[{"batl":[[0,6.4,7.16],[1,6.8,1.25],[2,11,3.26]],"ltp":5.8,"tv":748.81,"id":9417341}]}]}
{"op":"mcm","clk":"992137168","pt":1580514642548,"mc":[{"id":"1.168133548","rc":[{"batl":[[1,8,2],[2,8.2,2.5]],"ltp":6.4,"tv":76.53,"id":8231803}]}]}
{"op":"mcm","clk":"992137171","pt":1580514642650,"mc":[{"id":"1.168133548","rc":[{"batl":[[1,8,5.03]],"ltp":6.4,"tv":76.53,"id":8231803}]}]}
{"op":"mcm","clk":"992137243","pt":1580514644713,"mc":[{"id":"1.168133548","rc":[{"batl":[[1,7.8,4.76],[2,8,5.03]],"ltp":6.4,"tv":76.53,"id":8231803}]}]}
{"op":"mcm","clk":"992137327","pt":1580514647445,"mc":[{"id":"1.168133548","rc":[{"batl":[[0,6.4,32.16]],"ltp":5.8,"tv":748.81,"id":9417341}]}]}
{"op":"mcm","clk":"992137427","pt":1580514650852,"mc":[{"id":"1.168133548","rc":[{"batb":[[1,6.2,17.59]],"ltp":6.4,"tv":76.53,"id":8231803}]}]}
{"op":"mcm","clk":"992137961","pt":1580514675502,"mc":[{"id":"1.168133548","rc":[{"batl":[[2,8,2]],"ltp":6.4,"tv":76.53,"id":8231803}]}]}
{"op":"mcm","clk":"992137966","pt":1580514675604,"mc":[{"id":"1.168133548","rc":[{"batl":[[1,7.6,3.03],[2,7.8,4.76]],"ltp":6.4,"tv":76.53,"id":8231803}]}]}
{"op":"mcm","clk":"992138120","pt":1580514682971,"mc":[{"id":"1.168133548","rc":[{"batl":[[2,8,2]],"ltp":6.4,"tv":76.53,"id":8231803}]}]}
{"op":"mcm","clk":"992138696","pt":1580514708327,"mc":[{"id":"1.168133548","rc":[{"batl":[[1,8,5.03],[2,8.2,2.5]],"ltp":6.4,"tv":76.53,"id":8231803}]}]}
{"op":"mcm","clk":"992138979","pt":1580514720566,"mc":[{"id":"1.168133548","rc":[{"batl":[[1,7.8,4.76],[2,8,5.03]],"ltp":6.4,"tv":76.53,"id":8231803}]}]}
{"op":"mcm","clk":"992139477","pt":1580514740987,"mc":[{"id":"1.168133548","rc":[{"batl":[[1,7.6,3.03],[2,7.8,4.76]],"ltp":6.4,"tv":76.53,"id":8231803}]}]}
{"op":"mcm","clk":"992149518","pt":1580514759124,"mc":[{"id":"1.168133548","rc":[{"batl":[[2,8,2]],"ltp":6.4,"tv":76.53,"id":8231803}]}]}
{"op":"mcm","clk":"992149922","pt":1580514774830,"mc":[{"id":"1.168133548","rc":[{"batl":[[1,8,5.03],[2,8.2,2.5]],"ltp":6.4,"tv":76.53,"id":8231803}]}]}
{"op":"mcm","clk":"992150031","pt":1580514778436,"mc":[{"id":"1.168133548","rc":[{"batl":[[1,7.8,4.76],[2,8,5.03]],"ltp":6.4,"tv":76.53,"id":8231803}]}]}
{"op":"mcm","clk":"992150994","pt":1580514808367,"mc":[{"id":"1.168133548","rc":[{"batl":[[1,7.6,3.03],[2,7.8,4.76]],"ltp":6.4,"tv":76.53,"id":8231803}]}]}
{"op":"mcm","clk":"992151163","pt":1580514816786,"mc":[{"id":"1.168133548","rc":[{"batl":[[2,8,2]],"ltp":6.4,"tv":76.53,"id":8231803}]}]}
{"op":"mcm","clk":"992151636","pt":1580514841354,"mc":[{"id":"1.168133548","rc":[{"batl":[[1,8,5.03],[2,8.2,2.5]],"ltp":6.4,"tv":76.53,"id":8231803}]}]}
{"op":"mcm","clk":"992151924","pt":1580514854859,"mc":[{"id":"1.168133548","rc":[{"batl":[[1,7.8,4.76],[2,8,5.03]],"ltp":6.4,"tv":76.53,"id":8231803}]}]}
{"op":"mcm","clk":"992152450","pt":1580514874361,"mc":[{"id":"1.168133548","rc":[{"batl":[[1,7.6,3.03],[2,8,2]],"ltp":6.4,"tv":76.53,"id":8231803}]}]}
{"op":"mcm","clk":"992153311","pt":1580514907427,"mc":[{"id":"1.168133548","rc":[{"batl":[[1,8,5.03],[2,8.2,2.5]],"ltp":6.4,"tv":76.53,"id":8231803}]}]}
{"op":"mcm","clk":"992153432","pt":1580514911920,"mc":[{"id":"1.168133548","rc":[{"batl":[[1,7.8,4.76],[2,8,5.03]],"ltp":6.4,"tv":76.53,"id":8231803}]}]}
{"op":"mcm","clk":"992154255","pt":1580514940256,"mc":[{"id":"1.168133548","rc":[{"batl":[[1,7.6,3.03],[2,7.8,4.76]],"ltp":6.4,"tv":76.53,"id":8231803}]}]}
{"op":"mcm","clk":"992154509","pt":1580514951252,"mc":[{"id":"1.168133548","rc":[{"batl":[[2,8,2]],"ltp":6.4,"tv":76.53,"id":8231803}]}]}
{"op":"mcm","clk":"992155102","pt":1580514973786,"mc":[{"id":"1.168133548","rc":[{"batl":[[1,8,5.03],[2,8.2,2.5]],"ltp":6.4,"tv":76.53,"id":8231803}]}]}
{"op":"mcm","clk":"992155161","pt":1580514977284,"mc":[{"id":"1.168133548","rc":[{"batl":[[0,12.5,2]],"ltp":9.8,"tv":169.17,"id":15608820}]}]}
{"op":"mcm","clk":"992155175","pt":1580514977794,"mc":[{"id":"1.168133548","rc":[{"batb":[[2,5.9,5.03]],"ltp":6.4,"tv":76.53,"id":8231803}]}]}
{"op":"mcm","clk":"992155452","pt":1580514990187,"mc":[{"id":"1.168133548","rc":[{"batl":[[1,7.8,4.76],[2,8,5.03]],"ltp":6.4,"tv":76.53,"id":8231803}]}]}
{"op":"mcm","clk":"992155779","pt":1580515007328,"mc":[{"id":"1.168133548","rc":[{"batl":[[1,7.6,3.03],[2,7.8,4.76]],"ltp":6.4,"tv":76.53,"id":8231803}]}]}
{"op":"mcm","clk":"992155804","pt":1580515009021,"mc":[{"id":"1.168133548","rc":[{"batl":[[2,8,2]],"ltp":6.4,"tv":76.53,"id":8231803}]}]}
{"op":"mcm","clk":"992156496","pt":1580515041022,"mc":[{"id":"1.168133548","rc":[{"batl":[[1,8,5.03],[2,8.2,2.5]],"ltp":6.4,"tv":76.53,"id":8231803}]}]}
{"op":"mcm","clk":"992156633","pt":1580515047187,"mc":[{"id":"1.168133548","rc":[{"batl":[[1,7.8,4.76],[2,8,5.03]],"ltp":6.4,"tv":76.53,"id":8231803}]}]}
{"op":"mcm","clk":"992157174","pt":1580515073855,"mc":[{"id":"1.168133548","rc":[{"batl":[[1,7.6,3.03],[2,7.8,4.76]],"ltp":6.4,"tv":76.53,"id":8231803}]}]}
{"op":"mcm","clk":"992157450","pt":1580515085450,"mc":[{"id":"1.168133548","rc":[{"batl":[[2,8,2]],"ltp":6.4,"tv":76.53,"id":8231803}]}]}
{"op":"mcm","clk":"992157963","pt":1580515107497,"mc":[{"id":"1.168133548","rc":[{"batl":[[1,8,5.03],[2,8.2,2.5]],"ltp":6.4,"tv":76.53,"id":8231803}]}]}
{"op":"mcm","clk":"992158222","pt":1580515123390,"mc":[{"id":"1.168133548","rc":[{"batl":[[1,7.8,4.76],[2,8,5.03]],"ltp":6.4,"tv":76.53,"id":8231803}]}]}
{"op":"mcm","clk":"992158328","pt":1580515127018,"mc":[{"id":"1.168133548","rc":[{"batb":[[0,12,3.11]],"ltp":11.5,"tv":41.05,"id":8429550}]}]}
{"op":"mcm","clk":"992158513","pt":1580515135693,"mc":[{"id":"1.168133548","rc":[{"batb":[[0,12.5,1.98],[1,12,3.11],[2,11.5,1.53]],"ltp":11.5,"tv":41.05,"id":8429550}]}]}
{"op":"mcm","clk":"992158664","pt":1580515141447,"mc":[{"id":"1.168133548","rc":[{"batl":[[1,7.6,3.03],[2,7.8,4.76]],"ltp":6.4,"tv":76.53,"id":8231803}]}]}
{"op":"mcm","clk":"992158683","pt":1580515142324,"mc":[{"id":"1.168133548","rc":[{"batl":[[2,8,2]],"ltp":6.4,"tv":76.53,"id":8231803}]}]}
{"op":"mcm","clk":"992158697","pt":1580515142942,"mc":[{"id":"1.168133548","rc":[{"batb":[[1,12,5.63]],"ltp":11.5,"tv":41.05,"id":8429550}]}]}
{"op":"mcm","clk":"992159668","pt":1580515176274,"mc":[{"id":"1.168133548","rc":[{"batl":[[1,8,5.03],[2,8.2,2.5]],"ltp":6.4,"tv":76.53,"id":8231803}]}]}
{"op":"mcm","clk":"992159806","pt":1580515181485,"mc":[{"id":"1.168133548","rc":[{"batl":[[1,7.8,4.76],[2,8,5.03]],"ltp":6.4,"tv":76.53,"id":8231803}]}]}
{"op":"mcm","clk":"992160171","pt":1580515194535,"mc":[{"id":"1.168133548","rc":[{"batb":[[0,13,1.54],[1,12.5,1.98],[2,12,3.96]],"ltp":11.5,"tv":41.05,"id":8429550}]}]}
{"op":"mcm","clk":"992160179","pt":1580515194796,"mc":[{"id":"1.168133548","rc":[{"batl":[[0,16.5,2.25]],"ltp":11.5,"tv":41.05,"id":8429550}]}]}
{"op":"mcm","clk":"992160638","pt":1580515210127,"mc":[{"id":"1.168133548","rc":[{"batl":[[1,7.6,3.03],[2,7.8,4.76]],"ltp":6.4,"tv":76.53,"id":8231803}]}]}
{"op":"mcm","clk":"992160879","pt":1580515219843,"mc":[{"id":"1.168133548","rc":[{"batl":[[2,8,2]],"ltp":6.4,"tv":76.53,"id":8231803}]}]}
{"op":"mcm","clk":"992162950","pt":1580515280223,"mc":[{"id":"1.168133548","rc":[{"batb":[[2,5.9,7.44]],"ltp":6.4,"tv":76.53,"id":8231803}]}]}
{"op":"mcm","clk":"992166610","pt":1580515398349,"mc":[{"id":"1.168133548","rc":[{"batl":[[1,8,5.03],[2,8.2,2.5]],"ltp":6.4,"tv":76.53,"id":8231803}]}]}
{"op":"mcm","clk":"992167108","pt":1580515411293,"mc":[{"id":"1.168133548","rc":[{"batl":[[1,7.8,4.76],[2,8,5.03]],"ltp":6.4,"tv":76.53,"id":8231803}]}]}
{"op":"mcm","clk":"992167522","pt":1580515422383,"mc":[{"id":"1.168133548","rc":[{"batl":[[0,6.4,33.93]],"ltp":5.8,"tv":748.81,"id":9417341}]}]}
{"op":"mcm","clk":"992167617","pt":1580515426385,"mc":[{"id":"1.168133548","rc":[{"batl":[[0,6.4,32.16]],"ltp":5.8,"tv":748.81,"id":9417341}]}]}
{"op":"mcm","clk":"992168502","pt":1580515457607,"mc":[{"id":"1.168133548","rc":[{"trd":[[6.4,45.93]],"batb":[[0,6.2,17.59],[1,5.9,7.44],[2,5.6,5.95]],"batl":[[0,7,2.54]],"ltp":6.4,"tv":80.5,"id":8231803}],"tv":1418.51}]}
{"op":"mcm","clk":"992168697","pt":1580515462430,"mc":[{"id":"1.168133548","rc":[{"batl":[[1,7.6,3.03],[2,7.8,4.76]],"ltp":6.4,"tv":80.5,"id":8231803}]}]}
{"op":"mcm","clk":"992168915","pt":1580515469531,"mc":[{"id":"1.168133548","rc":[{"batl":[[2,8,2]],"ltp":6.4,"tv":80.5,"id":8231803}]}]}
{"op":"mcm","clk":"992169693","pt":1580515494489,"mc":[{"id":"1.168133548","rc":[{"batl":[[1,8,2],[2,8.2,2.5]],"ltp":6.4,"tv":80.5,"id":8231803}]}]}
{"op":"mcm","clk":"992169718","pt":1580515495366,"mc":[{"id":"1.168133548","rc":[{"batl":[[1,8,5.03]],"ltp":6.4,"tv":80.5,"id":8231803}]}]}
{"op":"mcm","clk":"992173460","pt":1580515619529,"mc":[{"id":"1.168133548","rc":[{"batl":[[0,6.6,4],[1,7,17.64],[2,7.4,6.7]],"ltp":6.6,"tv":95.21,"id":10170404}]}]}
{"op":"mcm","clk":"992173962","pt":1580515630539,"mc":[{"id":"1.168133548","rc":[{"batb":[[2,5.8,3.35]],"batl":[[2,7.4,3]],"ltp":6.6,"tv":95.21,"id":10170404}]}]}
{"op":"mcm","clk":"992188599","pt":1580515798504,"mc":[{"id":"1.168133548","rc":[{"trd":[[6.4,47.01]],"batb":[[0,6.4,1.45],[1,6.2,17.59],[2,5.9,7.44]],"batl":[[0,7,2]],"ltp":6.4,"tv":81.58,"id":8231803}],"tv":1419.59}]}
{"op":"mcm","clk":"992189185","pt":1580515815600,"mc":[{"id":"1.168133548","rc":[{"batl":[[1,7.8,4.76],[2,8,5.03]],"ltp":6.4,"tv":81.58,"id":8231803}]}]}
{"op":"mcm","clk":"992190097","pt":1580515846348,"mc":[{"id":"1.168133548","rc":[{"batl":[[1,7.6,3.03],[2,7.8,4.76]],"ltp":6.4,"tv":81.58,"id":8231803}]}]}
{"op":"mcm","clk":"992190374","pt":1580515854872,"mc":[{"id":"1.168133548","rc":[{"batl":[[2,8,2]],"ltp":6.4,"tv":81.58,"id":8231803}]}]}
{"op":"mcm","clk":"992191161","pt":1580515880011,"mc":[{"id":"1.168133548","rc":[{"batl":[[1,8,5.03],[2,8.2,2.5]],"ltp":6.4,"tv":81.58,"id":8231803}]}]}
{"op":"mcm","clk":"992191408","pt":1580515893220,"mc":[{"id":"1.168133548","rc":[{"batl":[[1,7.8,4.76],[2,8,5.03]],"ltp":6.4,"tv":81.58,"id":8231803}]}]}
{"op":"mcm","clk":"992191631","pt":1580515903824,"mc":[{"id":"1.168133548","rc":[{"batl":[[0,6,10],[1,6.4,32.16],[2,6.8,1.25]],"ltp":5.8,"tv":748.81,"id":9417341}]}]}
{"op":"mcm","clk":"992191782","pt":1580515911520,"mc":[{"id":"1.168133548","rc":[{"batl":[[1,7.6,3.03],[2,7.8,4.76]],"ltp":6.4,"tv":81.58,"id":8231803}]}]}
{"op":"mcm","clk":"992191806","pt":1580515913032,"mc":[{"id":"1.168133548","rc":[{"batl":[[2,8,2]],"ltp":6.4,"tv":81.58,"id":8231803}]}]}
{"op":"mcm","clk":"992192489","pt":1580515943482,"mc":[{"id":"1.168133548","rc":[{"batl":[[1,8,5.03],[2,8.2,2.5]],"ltp":6.4,"tv":81.58,"id":8231803}]}]}
{"op":"mcm","clk":"992192700","pt":1580515952232,"mc":[{"id":"1.168133548","rc":[{"batl":[[1,7.8,4.76],[2,8,5.03]],"ltp":6.4,"tv":81.58,"id":8231803}]}]}
{"op":"mcm","clk":"992192778","pt":1580515955392,"mc":[{"id":"1.168133548","rc":[{"trd":[[10,2.44]],"batb":[[0,9.8,3.87],[1,9.6,10.42],[2,9,2]],"ltp":10.0,"tv":153.9,"id":10616006}],"tv":1422.03}]}
{"op":"mcm","clk":"992193209","pt":1580515975122,"mc":[{"id":"1.168133548","rc":[{"batl":[[1,7.6,3.03],[2,7.8,4.76]],"ltp":6.4,"tv":81.58,"id":8231803}]}]}
{"op":"mcm","clk":"992193545","pt":1580515985583,"mc":[{"id":"1.168133548","rc":[{"trd":[[9.8,14.17]],"batb":[[0,9.6,11.19],[1,9,2],[2,8.4,3]],"ltp":9.8,"tv":160.1,"id":10616006},{"trd":[[6.2,5.64],[6.4,3.96]],"batb":[[0,6.2,2.48],[1,5.8,3.35],[2,5.7,11]],"ltp":6.2,"tv":104.81,"id":10170404},{"trd":[[14,4.2]],"batb":[[0,14,3.48]],"ltp":14.0,"tv":9.32,"id":9001159}],"tv":1442.03}]}
{"op":"mcm","clk":"992193655","pt":1580515989978,"mc":[{"id":"1.168133548","rc":[{"batl":[[2,8,2]],"ltp":6.4,"tv":81.58,"id":8231803}]}]}
{"op":"mcm","clk":"992193755","pt":1580515993374,"mc":[{"id":"1.168133548","rc":[{"batb":[[1,5.8,3]],"ltp":6.2,"tv":104.81,"id":10170404}]}]}
{"op":"mcm","clk":"992194125","pt":1580516007512,"mc":[{"id":"1.168133548","rc":[{"batl":[[1,8,5.03],[2,8.2,2.5]],"ltp":6.4,"tv":81.58,"id":8231803}]}]}
{"op":"mcm","clk":"992194182","pt":1580516009804,"mc":[{"id":"1.168133548","rc":[{"batl":[[1,7.8,4.76],[2,8,5.03]],"ltp":6.4,"tv":81.58,"id":8231803}]}]}
{"op":"mcm","clk":"992194331","pt":1580516015625,"mc":[{"id":"1.168133548","rc":[{"batl":[[0,11,2],[1,11.5,5],[2,13,36]],"ltp":9.8,"tv":160.1,"id":10616006}]}]}
{"op":"mcm","clk":"992194923","pt":1580516039447,"mc":[{"id":"1.168133548","rc":[{"batl":[[1,7.6,3.03],[2,7.8,4.76]],"ltp":6.4,"tv":81.58,"id":8231803}]}]}
{"op":"mcm","clk":"992194995","pt":1580516042439,"mc":[{"id":"1.168133548","rc":[{"batb":[[0,5.8,5.52],[1,5.7,11],[2,4.8,5.42]],"ltp":6.2,"tv":104.81,"id":10170404}]}]}
{"op":"mcm","clk":"992195070","pt":1580516047229,"mc":[{"id":"1.168133548","rc":[{"batl":[[2,8,2]],"ltp":6.4,"tv":81.58,"id":8231803}]}]}
{"op":"mcm","clk":"992195460","pt":1580516071287,"mc":[{"id":"1.168133548","rc":[{"batl":[[1,8,5.03],[2,8.2,2.5]],"ltp":6.4,"tv":81.58,"id":8231803}]}]}
{"op":"mcm","clk":"992195689","pt":1580516086640,"mc":[{"id":"1.168133548","rc":[{"batl":[[1,7.8,4.76],[2,8,5.03]],"ltp":6.4,"tv":81.58,"id":8231803}]}]}
{"op":"mcm","clk":"992196018","pt":1580516104109,"mc":[{"id":"1.168133548","rc":[{"batl":[[1,7.6,3.03],[2,7.8,4.76]],"ltp":6.4,"tv":81.58,"id":8231803}]}]}
{"op":"mcm","clk":"992196063","pt":1580516106020,"mc":[{"id":"1.168133548","rc":[{"batl":[[2,8,2]],"ltp":6.4,"tv":81.58,"id":8231803}]}]}
{"op":"mcm","clk":"992196759","pt":1580516136835,"mc":[{"id":"1.168133548","rc":[{"batl":[[1,8,5.03],[2,8.2,2.5]],"ltp":6.4,"tv":81.58,"id":8231803}]}]}
{"op":"mcm","clk":"992196964","pt":1580516144262,"mc":[{"id":"1.168133548","rc":[{"batl":[[1,7.8,4.76],[2,8,5.03]],"ltp":6.4,"tv":81.58,"id":8231803}]}]}
{"op":"mcm","clk":"992197283","pt":1580516156757,"mc":[{"id":"1.168133548","rc":[{"batb":[[0,5.8,2.52]],"ltp":6.2,"tv":104.81,"id":10170404}]}]}
{"op":"mcm","clk":"992197677","pt":1580516169960,"mc":[{"id":"1.168133548","rc":[{"batl":[[1,7.6,3.03],[2,7.8,4.76]],"ltp":6.4,"tv":81.58,"id":8231803},{"batb":[[2,4.9,5.09]],"batl":[[1,6.8,3.42],[2,7,17.64]],"ltp":6.2,"tv":104.81,"id":10170404}]}]}
{"op":"mcm","clk":"992197886","pt":1580516177986,"mc":[{"id":"1.168133548","rc":[{"trd":[[6,198.98]],"batl":[[0,6,8.29]],"ltp":6.0,"tv":752.23,"id":9417341}],"tv":1445.45}]}
{"op":"mcm","clk":"992197986","pt":1580516182891,"mc":[{"id":"1.168133548","rc":[{"batl":[[2,8,2]],"ltp":6.4,"tv":81.58,"id":8231803}]}]}
{"op":"mcm","clk":"992198592","pt":1580516203442,"mc":[{"id":"1.168133548","rc":[{"batl":[[1,8,5.03],[2,8.2,2.5]],"ltp":6.4,"tv":81.58,"id":8231803}]}]}
{"op":"mcm","clk":"992198603","pt":1580516203753,"mc":[{"id":"1.168133548","rc":[{"batb":[[0,5.8,6.53],[2,4.8,5.42]],"ltp":6.2,"tv":104.81,"id":10170404}]}]}
{"op":"mcm","clk":"992199030","pt":1580516220566,"mc":[{"id":"1.168133548","rc":[{"batl":[[1,7.8,4.76],[2,8,5.03]],"ltp":6.4,"tv":81.58,"id":8231803}]}]}
{"op":"mcm","clk":"992199669","pt":1580516249018,"mc":[{"id":"1.168133548","rc":[{"trd":[[5.8,1.69]],"batb":[[0,5.8,5.68]],"ltp":5.8,"tv":106.51,"id":10170404}],"tv":1447.14}]}
{"op":"mcm","clk":"992199683","pt":1580516249899,"mc":[{"id":"1.168133548","rc":[{"batl":[[1,7.6,3.03],[2,7.8,4.76]],"ltp":6.4,"tv":81.58,"id":8231803}]}]}
{"op":"mcm","clk":"992199866","pt":1580516259291,"mc":[{"id":"1.168133548","rc":[{"batl":[[2,8,2]],"ltp":6.4,"tv":81.58,"id":8231803}]}]}
{"op":"mcm","clk":"992200391","pt":1580516282440,"mc":[{"id":"1.168133548","rc":[{"batl":[[1,8,5.03],[2,8.2,2.5]],"ltp":6.4,"tv":81.58,"id":8231803}]}]}
{"op":"mcm","clk":"992200741","pt":1580516296422,"mc":[{"id":"1.168133548","rc":[{"batl":[[1,7.8,4.76],[2,8,5.03]],"ltp":6.4,"tv":81.58,"id":8231803}]}]}
{"op":"mcm","clk":"992200750","pt":1580516296730,"mc":[{"id":"1.168133548","rc":[{"batb":[[0,14.5,1.18],[1,14,3.48],[2,13.5,7.41]],"ltp":14.0,"tv":9.32,"id":9001159}]}]}
{"op":"mcm","clk":"992201151","pt":1580516315445,"mc":[{"id":"1.168133548","rc":[{"batl":[[1,7.6,3.03],[2,7.8,4.76]],"ltp":6.4,"tv":81.58,"id":8231803}]}]}
{"op":"mcm","clk":"992201179","pt":1580516316940,"mc":[{"id":"1.168133548","rc":[{"batl":[[2,8,2]],"ltp":6.4,"tv":81.58,"id":8231803}]}]}
{"op":"mcm","clk":"992202038","pt":1580516357379,"mc":[{"id":"1.168133548","rc":[{"batl":[[1,8,5.03],[2,8.2,2.5]],"ltp":6.4,"tv":81.58,"id":8231803}]}]}
{"op":"mcm","clk":"992202418","pt":1580516374991,"mc":[{"id":"1.168133548","rc":[{"batl":[[1,7.8,4.76],[2,8,5.03]],"ltp":6.4,"tv":81.58,"id":8231803}]}]}
{"op":"mcm","clk":"992202653","pt":1580516389523,"mc":[{"id":"1.168133548","rc":[{"batl":[[2,8,2]],"ltp":6.4,"tv":81.58,"id":8231803}]}]}
{"op":"mcm","clk":"992202675","pt":1580516390541,"mc":[{"id":"1.168133548","rc":[{"trd":[[5.9,108.93]],"batb":[[0,5.8,41.44],[1,5.7,2.8],[2,5.5,16.85]],"batl":[[0,5.9,5],[1,6,18.29],[2,6.4,32.16]],"ltp":5.9,"tv":758.06,"id":9417341},{"batl":[[1,7.6,3.03],[2,7.8,4.76]],"ltp":6.4,"tv":81.58,"id":8231803}],"tv":1452.98}]}
{"op":"mcm","clk":"992202725","pt":1580516394259,"mc":[{"id":"1.168133548","rc":[{"batl":[[2,8,2]],"ltp":6.4,"tv":81.58,"id":8231803}]}]}
{"op":"mcm","clk":"992202753","pt":1580516395348,"mc":[{"id":"1.168133548","rc":[{"batl":[[0,6.8,100],[1,7,2],[2,7.6,3.03]],"ltp":6.4,"tv":81.58,"id":8231803}]}]}
{"op":"mcm","clk":"992202778","pt":1580516396533,"mc":[{"id":"1.168133548","rc":[{"batl":[[0,5.9,15],[1,6,8.29]],"ltp":5.9,"tv":758.06,"id":9417341}]}]}
{"op":"mcm","clk":"992202870","pt":1580516404379,"mc":[{"id":"1.168133548","rc":[{"batl":[[0,5.9,10]],"ltp":5.9,"tv":758.06,"id":9417341}]}]}
{"op":"mcm","clk":"992202953","pt":1580516409383,"mc":[{"id":"1.168133548","rc":[{"trd":[[5.8,127.1]],"batb":[[0,5.8,36.44]],"batl":[[0,5.9,5]],"ltp":5.8,"tv":768.06,"id":9417341}],"tv":1462.98}]}
{"op":"mcm","clk":"992202996","pt":1580516412751,"mc":[{"id":"1.168133548","rc":[{"batb":[[0,9.8,2.76],[1,9.6,10.42],[2,9,2]],"ltp":9.8,"tv":160.1,"id":10616006},{"batb":[[0,5.9,1.98],[1,5.8,5.68],[2,5.7,11]],"ltp":5.8,"tv":106.51,"id":10170404}]}]}
{"op":"mcm","clk":"992203163","pt":1580516422565,"mc":[{"id":"1.168133548","rc":[{"batb":[[2,5.9,5.17]],"batl":[[2,8,2]],"ltp":6.4,"tv":81.58,"id":8231803}]}]}
{"op":"mcm","clk":"992203167","pt":1580516422806,"mc":[{"id":"1.168133548","rc":[{"batl":[[0,5.9,10]],"ltp":5.8,"tv":768.06,"id":9417341}]}]}
{"op":"mcm","clk":"992203655","pt":1580516444026,"mc":[{"id":"1.168133548","rc":[{"batl":[[0,11.5,5],[1,13,36],[2,13.5,3]],"ltp":9.8,"tv":160.1,"id":10616006}]}]}
{"op":"mcm","clk":"992204797","pt":1580516488178,"mc":[{"id":"1.168133548","rc":[{"trd":[[6.2,3.26],[6.4,49.9]],"batb":[[0,6.2,17.04],[1,5.9,5.17],[2,5.6,5.95]],"ltp":6.2,"tv":85.57,"id":8231803}],"tv":1466.97}]}
{"op":"mcm","clk":"992204906","pt":1580516492560,"mc":[{"id":"1.168133548","rc":[{"trd":[[9.4,2.7]],"batb":[[0,9.2,1.78],[1,9,1.29],[2,8.8,3.03]],"batl":[[0,9.4,3.65],[1,12.5,2],[2,13,2]],"ltp":9.4,"tv":171.87,"id":15608820}],"tv":1469.67}]}
{"op":"mcm","clk":"992204989","pt":1580516497164,"mc":[{"id":"1.168133548","rc":[{"batl":[[1,13,2],[2,16.5,2.84]],"ltp":9.4,"tv":171.87,"id":15608820}]}]}
{"op":"mcm","clk":"992205095","pt":1580516503457,"mc":[{"id":"1.168133548","rc":[{"batb":[[0,13,2.87],[1,12.5,7.05],[2,12,2.52]],"ltp":11.5,"tv":41.05,"id":8429550},{"batb":[[0,11.5,8.98]],"ltp":11.0,"tv":26.11,"id":9193530},{"batb":[[0,14.5,5.55]],"ltp":14.0,"tv":9.32,"id":9001159}]}]}
{"op":"mcm","clk":"992205342","pt":1580516515205,"mc":[{"id":"1.168133548","rc":[{"batl":[[0,7,21.34]],"ltp":7.0,"tv":101.04,"id":17352128}]}]}
{"op":"mcm","clk":"992205457","pt":1580516521512,"mc":[{"id":"1.168133548","rc":[{"batb":[[1,12.5,1.98]],"ltp":11.5,"tv":41.05,"id":8429550},{"batb":[[2,8.6,11.63]],"batl":[[2,17,3.48]],"ltp":9.4,"tv":171.87,"id":15608820}]}]}
{"op":"mcm","clk":"992205472","pt":1580516522500,"mc":[{"id":"1.168133548","rc":[{"batb":[[1,8.8,1.31]],"batl":[[2,16.5,1.81]],"ltp":9.4,"tv":171.87,"id":15608820},{"batb":[[0,12,2.52],[1,11.5,8.98],[2,11,3]],"ltp":11.0,"tv":26.11,"id":9193530}]}]}
{"op":"mcm","clk":"992205647","pt":1580516530925,"mc":[{"id":"1.168133548","rc":[{"trd":[[9.2,9.3]],"batb":[[0,8.8,1.31],[1,8.6,11.63],[2,8,3]],"batl":[[0,9.2,1.87]],"ltp":9.2,"tv":175.43,"id":15608820}],"tv":1473.23}]}
{"op":"mcm","clk":"992205750","pt":1580516535319,"mc":[{"id":"1.168133548","rc":[{"batl":[[0,11,7.44],[1,11.5,5],[2,13,36]],"ltp":9.8,"tv":160.1,"id":10616006}]}]}
{"op":"mcm","clk":"992205861","pt":1580516540341,"mc":[{"id":"1.168133548","rc":[{"batb":[[1,11.5,3.48]],"ltp":11.0,"tv":26.11,"id":9193530},{"batb":[[0,14.5,1.18]],"ltp":14.0,"tv":9.32,"id":9001159}]}]}
{"op":"mcm","clk":"992205889","pt":1580516541530,"mc":[{"id":"1.168133548","rc":[{"batl":[[0,10,1.87]],"ltp":9.2,"tv":175.43,"id":15608820}]}]}
{"op":"mcm","clk":"992216184","pt":1580516559371,"mc":[{"id":"1.168133548","rc":[{"batl":[[2,16.5,3.17]],"ltp":9.2,"tv":175.43,"id":15608820}]}]}
{"op":"mcm","clk":"992217012","pt":1580516592571,"mc":[{"id":"1.168133548","rc":[{"batb":[[0,8.8,4.34]],"ltp":9.2,"tv":175.43,"id":15608820}]}]}
{"op":"mcm","clk":"992217253","pt":1580516603693,"mc":[{"id":"1.168133548","rc":[{"batl":[[0,9.8,2],[1,10,1.87],[2,13,2]],"ltp":9.2,"tv":175.43,"id":15608820}]}]}
{"op":"mcm","clk":"992217284","pt":1580516605358,"mc":[{"id":"1.168133548","rc":[{"batb":[[0,12,7.8]],"ltp":11.0,"tv":26.11,"id":9193530},{"batb":[[0,14.5,5.55]],"ltp":14.0,"tv":9.32,"id":9001159}]}]}
{"op":"mcm","clk":"992217317","pt":1580516607067,"mc":[{"id":"1.168133548","rc":[{"trd":[[10,6.44]],"ltp":10.0,"tv":164.1,"id":10616006}],"tv":1477.23}]}
{"op":"mcm","clk":"992217909","pt":1580516627592,"mc":[{"id":"1.168133548","rc":[{"batl":[[1,6.8,5.42]],"ltp":5.8,"tv":106.51,"id":10170404}]}]}
{"op":"mcm","clk":"992218362","pt":1580516643910,"mc":[{"id":"1.168133548","rc":[{"batb":[[0,12.5,1.38],[1,12,7.8],[2,11.5,1.98]],"ltp":11.0,"tv":26.11,"id":9193530}]}]}
{"op":"mcm","clk":"992218606","pt":1580516653453,"mc":[{"id":"1.168133548","rc":[{"batb":[[1,12,2.52]],"ltp":11.0,"tv":26.11,"id":9193530}]}]}
{"op":"mcm","clk":"992219193","pt":1580516674279,"mc":[{"id":"1.168133548","rc":[{"batb":[[0,9,1.92],[1,8.8,4.34],[2,8.6,11.63]],"ltp":9.2,"tv":175.43,"id":15608820}]}]}
{"op":"mcm","clk":"992219262","pt":1580516676446,"mc":[{"id":"1.168133548","rc":[{"trd":[[6.8,32.02]],"batb":[[0,6.8,3.74]],"ltp":6.8,"tv":111.05,"id":17352128}],"tv":1487.24}]}
{"op":"mcm","clk":"992219433","pt":1580516683060,"mc":[{"id":"1.168133548","rc":[{"batb":[[2,5.5,13.85]],"ltp":5.8,"tv":768.06,"id":9417341}]}]}
{"op":"mcm","clk":"992219635","pt":1580516691374,"mc":[{"id":"1.168133548","rc":[{"batl":[[0,6.4,5],[1,6.6,4],[2,6.8,5.42]],"ltp":5.8,"tv":106.51,"id":10170404}]}]}
{"op":"mcm","clk":"992219861","pt":1580516700524,"mc":[{"id":"1.168133548","rc":[{"batb":[[1,12,7.8]],"ltp":11.0,"tv":26.11,"id":9193530}]}]}
{"op":"mcm","clk":"992224779","pt":1580516898327,"mc":[{"id":"1.168133548","rc":[{"trd":[[6.4,13.96]],"batl":[[0,6.6,4],[1,6.8,5.42],[2,7,17.64]],"ltp":6.4,"tv":116.51,"id":10170404}],"tv":1497.24}]}
{"op":"mcm","clk":"992224986","pt":1580516907544,"mc":[{"id":"1.168133548","rc":[{"batb":[[1,12,2.52]],"ltp":11.0,"tv":26.11,"id":9193530}]}]}
{"op":"mcm","clk":"992228742","pt":1580517035358,"mc":[{"id":"1.168133548","rc":[{"batb":[[0,13.5,1.98],[1,13,1.33]],"ltp":11.5,"tv":41.05,"id":8429550},{"batb":[[0,12.5,8.43],[2,11,3]],"ltp":11.0,"tv":26.11,"id":9193530},{"batb":[[0,14.5,7.53],[1,14,1.5]],"ltp":14.0,"tv":9.32,"id":9001159},{"batb":[[0,6.2,3.74]],"ltp":6.8,"tv":111.05,"id":17352128}]}]}
{"op":"mcm","clk":"992229355","pt":1580517059411,"mc":[{"id":"1.168133548","rc":[{"batl":[[1,85,9.15],[2,1000,3.19]],"ltp":14.0,"tv":9.32,"id":9001159}]}]}
{"op":"mcm","clk":"992229373","pt":1580517060034,"mc":[{"id":"1.168133548","rc":[{"trd":[[14.5,4.5]],"batb":[[0,14.5,5.28]],"batl":[[2,330,0.16]],"ltp":14.5,"tv":13.82,"id":9001159},{"batl":[[0,6.8,3.12],[1,7,21.34],[2,7.2,27]],"ltp":6.8,"tv":111.05,"id":17352128}],"tv":1501.74}]}
{"op":"mcm","clk":"992229438","pt":1580517062217,"mc":[{"id":"1.168133548","rc":[{"batb":[[0,13,2.52],[1,12.5,8.43]],"ltp":11.0,"tv":26.11,"id":9193530}]}]}
{"op":"mcm","clk":"992229566","pt":1580517067402,"mc":[{"id":"1.168133548","rc":[{"batb":[[1,12.5,3.36]],"ltp":11.0,"tv":26.11,"id":9193530},{"batb":[[0,14.5,1.98]],"ltp":14.5,"tv":13.82,"id":9001159}]}]}
{"op":"mcm","clk":"992230018","pt":1580517082362,"mc":[{"id":"1.168133548","rc":[{"batb":[[1,14,4.91]],"ltp":14.5,"tv":13.82,"id":9001159}]}]}
{"op":"mcm","clk":"992230408","pt":1580517093553,"mc":[{"id":"1.168133548","rc":[{"batb":[[1,5.9,2.76]],"ltp":6.2,"tv":85.57,"id":8231803},{"batl":[[0,6.6,3.21],[1,7,24.36]],"ltp":6.8,"tv":111.05,"id":17352128}]}]}
{"op":"mcm","clk":"992232065","pt":1580517132222,"mc":[{"id":"1.168133548","rc":[{"batl":[[0,7,24.36],[1,7.2,27],[2,7.4,50]],"ltp":6.8,"tv":111.05,"id":17352128}]}]}
{"op":"mcm","clk":"992232339","pt":1580517138627,"mc":[{"id":"1.168133548","rc":[{"trd":[[9,27.03]],"batb":[[0,8.8,4.34],[1,8.6,11.63],[2,8,3]],"batl":[[0,9.8,2.6]],"ltp":9.0,"tv":179.26,"id":15608820}],"tv":1505.57}]}
{"op":"mcm","clk":"992232534","pt":1580517146352,"mc":[{"id":"1.168133548","rc":[{"batb":[[1,14,1.5]],"ltp":14.5,"tv":13.82,"id":9001159}]}]}
{"op":"mcm","clk":"992232627","pt":1580517151465,"mc":[{"id":"1.168133548","rc":[{"batl":[[0,6.8,4],[1,7,24.36],[2,7.2,27]],"ltp":6.8,"tv":111.05,"id":17352128}]}]}
{"op":"mcm","clk":"992232851","pt":1580517162384,"mc":[{"id":"1.168133548","rc":[{"batb":[[1,14,4.91]],"ltp":14.5,"tv":13.82,"id":9001159}]}]}
{"op":"mcm","clk":"992232968","pt":1580517165996,"mc":[{"id":"1.168133548","rc":[{"batl":[[0,6.6,3.21],[1,6.8,4],[2,7,21.34]],"ltp":6.8,"tv":111.05,"id":17352128}]}]}
{"op":"mcm","clk":"992233140","pt":1580517172204,"mc":[{"id":"1.168133548","rc":[{"batl":[[2,7,22.64]],"ltp":6.4,"tv":116.51,"id":10170404}]}]}
{"op":"mcm","clk":"992233274","pt":1580517177317,"mc":[{"id":"1.168133548","rc":[{"trd":[[5.9,114.91]],"batl":[[0,5.9,7.01]],"ltp":5.9,"tv":774.05,"id":9417341},{"batb":[[0,6.4,2.76],[1,6.2,17.04],[2,5.9,2.76]],"ltp":6.2,"tv":85.57,"id":8231803},{"batb":[[0,9.8,4.55]],"ltp":10.0,"tv":164.1,"id":10616006},{"batb":[[1,5.8,8.72]],"ltp":6.4,"tv":116.51,"id":10170404},{"batb":[[0,8.8,6.35]],"ltp":9.0,"tv":179.26,"id":15608820},{"batb":[[2,11,4.6]],"ltp":11.0,"tv":26.11,"id":9193530},{"batb":[[1,14,6.17]],"ltp":14.5,"tv":13.82,"id":9001159},{"batb":[[2,5.7,3.09]],"ltp":6.8,"tv":111.05,"id":17352128}],"tv":1511.55}]}
{"op":"mcm","clk":"992233291","pt":1580517178409,"mc":[{"id":"1.168133548","rc":[{"batb":[[0,14.5,5.28],[1,14,2.76]],"ltp":14.5,"tv":13.82,"id":9001159}]}]}
{"op":"mcm","clk":"992233413","pt":1580517182512,"mc":[{"id":"1.168133548","rc":[{"batb":[[2,5.5,16.85]],"ltp":5.9,"tv":774.05,"id":9417341},{"batb":[[0,6.4,2.69],[1,6.2,3.74],[2,6,3]],"ltp":6.8,"tv":111.05,"id":17352128}]}]}
{"op":"mcm","clk":"992233601","pt":1580517189431,"mc":[{"id":"1.168133548","rc":[{"trd":[[6.2,12.58],[6.4,55.42]],"batb":[[0,6.2,12.38],[1,5.9,2.76],[2,5.6,5.95]],"ltp":6.2,"tv":100.41,"id":8231803}],"tv":1526.39}]}
{"op":"mcm","clk":"992233857","pt":1580517197764,"mc":[{"id":"1.168133548","rc":[{"batl":[[1,7,21.34],[2,7.2,27]],"ltp":6.8,"tv":111.05,"id":17352128}]}]}
{"op":"mcm","clk":"992234185","pt":1580517209509,"mc":[{"id":"1.168133548","rc":[{"batl":[[0,7,24.36],[1,7.2,27],[2,7.4,50]],"ltp":6.8,"tv":111.05,"id":17352128}]}]}
{"op":"mcm","clk":"992234213","pt":1580517210390,"mc":[{"id":"1.168133548","rc":[{"batb":[[0,14.5,1.98]],"ltp":14.5,"tv":13.82,"id":9001159}]}]}
{"op":"mcm","clk":"992234696","pt":1580517229514,"mc":[{"id":"1.168133548","rc":[{"batl":[[0,6.6,3.03],[1,6.8,100],[2,7,2]],"ltp":6.2,"tv":100.41,"id":8231803}]}]}
{"op":"mcm","clk":"992234716","pt":1580517230238,"mc":[{"id":"1.168133548","rc":[{"batl":[[0,6.8,100],[1,7,2],[2,8,2]],"ltp":6.2,"tv":100.41,"id":8231803}]}]}
{"op":"mcm","clk":"992235103","pt":1580517243268,"mc":[{"id":"1.168133548","rc":[{"batl":[[0,6.8,3.12],[1,7,21.34],[2,7.2,27]],"ltp":6.8,"tv":111.05,"id":17352128}]}]}
{"op":"mcm","clk":"992236125","pt":1580517276499,"mc":[{"id":"1.168133548","rc":[{"batl":[[0,7,21.34],[1,7.2,27],[2,7.4,50]],"ltp":6.8,"tv":111.05,"id":17352128}]}]}
{"op":"mcm","clk":"992236133","pt":1580517276808,"mc":[{"id":"1.168133548","rc":[{"batl":[[0,6.6,3.21],[1,7,24.36],[2,7.2,27]],"ltp":6.8,"tv":111.05,"id":17352128}]}]}
{"op":"mcm","clk":"992236416","pt":1580517289417,"mc":[{"id":"1.168133548","rc":[{"batb":[[0,14.5,5.28]],"ltp":14.5,"tv":13.82,"id":9001159}]}]}
{"op":"mcm","clk":"992237374","pt":1580517320551,"mc":[{"id":"1.168133548","rc":[{"batl":[[0,7,24.36],[1,7.2,27],[2,7.4,50]],"ltp":6.8,"tv":111.05,"id":17352128}]}]}
{"op":"mcm","clk":"992237400","pt":1580517321377,"mc":[{"id":"1.168133548","rc":[{"batb":[[0,14.5,1.98]],"ltp":14.5,"tv":13.82,"id":9001159}]}]}
{"op":"mcm","clk":"992238253","pt":1580517349328,"mc":[{"id":"1.168133548","rc":[{"batl":[[0,6.8,4],[1,7,24.36],[2,7.2,27]],"ltp":6.8,"tv":111.05,"id":17352128}]}]}
{"op":"mcm","clk":"992238835","pt":1580517371538,"mc":[{"id":"1.168133548","rc":[{"batl":[[1,7,21.34]],"ltp":6.8,"tv":111.05,"id":17352128}]}]}
{"op":"mcm","clk":"992238862","pt":1580517372519,"mc":[{"id":"1.168133548","rc":[{"batl":[[0,6.6,3.21],[1,6.8,4],[2,7,21.34]],"ltp":6.8,"tv":111.05,"id":17352128}]}]}
{"op":"mcm","clk":"992239209","pt":1580517385348,"mc":[{"id":"1.168133548","rc":[{"batb":[[0,14.5,5.28]],"ltp":14.5,"tv":13.82,"id":9001159}]}]}
{"op":"mcm","clk":"992239367","pt":1580517390445,"mc":[{"id":"1.168133548","rc":[{"batl":[[1,7,21.34],[2,7.2,27]],"ltp":6.8,"tv":111.05,"id":17352128}]}]}
{"op":"mcm","clk":"992239857","pt":1580517409565,"mc":[{"id":"1.168133548","rc":[{"batl":[[0,7,24.36],[1,7.2,27],[2,7.4,50]],"ltp":6.8,"tv":111.05,"id":17352128}]}]}
{"op":"mcm","clk":"992240252","pt":1580517417412,"mc":[{"id":"1.168133548","rc":[{"batb":[[0,14.5,1.98]],"ltp":14.5,"tv":13.82,"id":9001159}]}]}
{"op":"mcm","clk":"992251301","pt":1580517473461,"mc":[{"id":"1.168133548","rc":[{"batl":[[0,6.8,3.12],[1,7,21.34],[2,7.2,27]],"ltp":6.8,"tv":111.05,"id":17352128}]}]}
{"op":"mcm","clk":"992251803","pt":1580517507530,"mc":[{"id":"1.168133548","rc":[{"batl":[[0,6.6,3.21],[1,7,24.36]],"ltp":6.8,"tv":111.05,"id":17352128}]}]}
{"op":"mcm","clk":"992251997","pt":1580517512336,"mc":[{"id":"1.168133548","rc":[{"batb":[[0,14.5,5.28]],"ltp":14.5,"tv":13.82,"id":9001159}]}]}
{"op":"mcm","clk":"992252662","pt":1580517550300,"mc":[{"id":"1.168133548","rc":[{"batl":[[0,7,24.36],[1,7.2,27],[2,7.4,50]],"ltp":6.8,"tv":111.05,"id":17352128}]}]}
{"op":"mcm","clk":"992252803","pt":1580517557923,"mc":[{"id":"1.168133548","rc":[{"batl":[[0,6.8,4],[1,7,24.36],[2,7.2,27]],"ltp":6.8,"tv":111.05,"id":17352128}]}]}
{"op":"mcm","clk":"992252854","pt":1580517560309,"mc":[{"id":"1.168133548","rc":[{"batb":[[0,14.5,1.98]],"ltp":14.5,"tv":13.82,"id":9001159}]}]}
{"op":"mcm","clk":"992253459","pt":1580517591504,"mc":[{"id":"1.168133548","rc":[{"batl":[[1,7,21.34]],"ltp":6.8,"tv":111.05,"id":17352128}]}]}
{"op":"mcm","clk":"992253471","pt":1580517592325,"mc":[{"id":"1.168133548","rc":[{"batb":[[0,14.5,5.28]],"ltp":14.5,"tv":13.82,"id":9001159},{"batl":[[0,6.6,3.21],[1,6.8,4],[2,7,21.34]],"ltp":6.8,"tv":111.05,"id":17352128}]}]}
{"op":"mcm","clk":"992253615","pt":1580517598529,"mc":[{"id":"1.168133548","rc":[{"batl":[[1,7,21.34],[2,7.2,27]],"ltp":6.8,"tv":111.05,"id":17352128}]}]}
{"op":"mcm","clk":"992254216","pt":1580517626262,"mc":[{"id":"1.168133548","rc":[{"batl":[[0,7,24.36],[1,7.2,27],[2,7.4,50]],"ltp":6.8,"tv":111.05,"id":17352128}]}]}
{"op":"mcm","clk":"992254572","pt":1580517640294,"mc":[{"id":"1.168133548","rc":[{"batb":[[0,14.5,1.98]],"ltp":14.5,"tv":13.82,"id":9001159}]}]}
{"op":"mcm","clk":"992254975","pt":1580517653958,"mc":[{"id":"1.168133548","rc":[{"batb":[[0,13,1.33],[1,12.5,1.98]],"ltp":11.5,"tv":41.05,"id":8429550},{"batb":[[0,13.5,1.98],[1,13,2.52],[2,12.5,1.38]],"ltp":11.0,"tv":26.11,"id":9193530},{"batb":[[0,6.4,6.43],[1,6,3],[2,5.7,3.09]],"ltp":6.8,"tv":111.05,"id":17352128}]}]}
{"op":"mcm","clk":"992255381","pt":1580517672421,"mc":[{"id":"1.168133548","rc":[{"batl":[[0,6.8,3.12],[1,7,21.34],[2,7.2,27]],"ltp":6.8,"tv":111.05,"id":17352128}]}]}
{"op":"mcm","clk":"992255463","pt":1580517677111,"mc":[{"id":"1.168133548","rc":[{"batl":[[0,16,2],[1,16.5,2.25],[2,17.5,5.29]],"ltp":11.5,"tv":41.05,"id":8429550}]}]}
{"op":"mcm","clk":"992255667","pt":1580517687321,"mc":[{"id":"1.168133548","rc":[{"batb":[[0,14.5,5.28]],"ltp":14.5,"tv":13.82,"id":9001159}]}]}
{"op":"mcm","clk":"992255918","pt":1580517703356,"mc":[{"id":"1.168133548","rc":[{"batb":[[0,14.5,1.98]],"ltp":14.5,"tv":13.82,"id":9001159}]}]}
{"op":"mcm","clk":"992255939","pt":1580517705260,"mc":[{"id":"1.168133548","rc":[{"batl":[[0,7,24.36],[1,7.2,27],[2,7.4,50]],"ltp":6.8,"tv":111.05,"id":17352128}]}]}
{"op":"mcm","clk":"992259606","pt":1580517859372,"mc":[{"id":"1.168133548","rc":[{"batl":[[0,9.8,2]],"ltp":9.0,"tv":179.26,"id":15608820}]}]}
{"op":"mcm","clk":"992280430","pt":1580518352322,"mc":[{"id":"1.168133548","rc":[{"trd":[[6.2,37.34]],"batb":[[0,5.9,2.76],[1,5.6,5.95],[2,5.5,3]],"batl":[[0,6.2,20.62],[1,6.8,100],[2,7,2]],"ltp":6.2,"tv":125.17,"id":8231803}],"tv":1551.15}]}
{"op":"mcm","clk":"992280455","pt":1580518353411,"mc":[{"id":"1.168133548","rc":[{"batb":[[0,14.5,5.28]],"ltp":14.5,"tv":13.82,"id":9001159},{"batb":[[1,13,7.39]],"ltp":11.0,"tv":26.11,"id":9193530}]}]}
{"op":"mcm","clk":"992280464","pt":1580518353721,"mc":[{"id":"1.168133548","rc":[{"batb":[[1,5.6,8.33]],"ltp":6.2,"tv":125.17,"id":8231803},{"batb":[[0,13.5,3.26],[2,11,4.6]],"ltp":11.0,"tv":26.11,"id":9193530}]}]}
{"op":"mcm","clk":"992280814","pt":1580518368570,"mc":[{"id":"1.168133548","rc":[{"batb":[[0,5.9,2]],"ltp":6.2,"tv":125.17,"id":8231803}]}]}
{"op":"mcm","clk":"992280839","pt":1580518369549,"mc":[{"id":"1.168133548","rc":[{"batb":[[1,5.6,9.08]],"ltp":6.2,"tv":125.17,"id":8231803},{"batb":[[1,13,2.52]],"ltp":11.0,"tv":26.11,"id":9193530}]}]}
{"op":"mcm","clk":"992280842","pt":1580518369653,"mc":[{"id":"1.168133548","rc":[{"batb":[[0,13.5,7.95]],"ltp":11.0,"tv":26.11,"id":9193530}]}]}
{"op":"mcm","clk":"992281086","pt":1580518383478,"mc":[{"id":"1.168133548","rc":[{"batb":[[0,14,2.37],[1,13.5,7.95]],"ltp":11.0,"tv":26.11,"id":9193530}]}]}
{"op":"mcm","clk":"992281094","pt":1580518383683,"mc":[{"id":"1.168133548","rc":[{"batb":[[1,5.6,6.71]],"ltp":6.2,"tv":125.17,"id":8231803}]}]}
{"op":"mcm","clk":"992281396","pt":1580518402392,"mc":[{"id":"1.168133548","rc":[{"batb":[[1,13.5,3.26]],"ltp":11.0,"tv":26.11,"id":9193530}]}]}
{"op":"mcm","clk":"992282108","pt":1580518441566,"mc":[{"id":"1.168133548","rc":[{"batb":[[0,13.5,3.26],[1,11,4.6],[2,10.5,3.03]],"ltp":11.0,"tv":26.11,"id":9193530}]}]}
{"op":"mcm","clk":"992282125","pt":1580518442542,"mc":[{"id":"1.168133548","rc":[{"batb":[[1,11.5,2.52],[2,11,4.6]],"ltp":11.0,"tv":26.11,"id":9193530}]}]}
{"op":"mcm","clk":"992285659","pt":1580518600515,"mc":[{"id":"1.168133548","rc":[{"batl":[[0,10.5,1.88],[1,11,7.44],[2,11.5,5]],"ltp":10.0,"tv":164.1,"id":10616006}]}]}
{"op":"mcm","clk":"992286586","pt":1580518630541,"mc":[{"id":"1.168133548","rc":[{"batl":[[0,10.5,5.46]],"ltp":10.0,"tv":164.1,"id":10616006}]}]}
{"op":"mcm","clk":"992286879","pt":1580518641391,"mc":[{"id":"1.168133548","rc":[{"batb":[[0,13.5,7.95]],"ltp":11.0,"tv":26.11,"id":9193530}]}]}
{"op":"mcm","clk":"992287411","pt":1580518663277,"mc":[{"id":"1.168133548","rc":[{"trd":[[10.5,3.76]],"batl":[[0,11,10.67],[1,11.5,5],[2,13,36]],"ltp":10.5,"tv":167.86,"id":10616006}],"tv":1554.91}]}
{"op":"mcm","clk":"992287670","pt":1580518673395,"mc":[{"id":"1.168133548","rc":[{"batb":[[0,13.5,3.26]],"ltp":11.0,"tv":26.11,"id":9193530}]}]}
{"op":"mcm","clk":"992290468","pt":1580518779809,"mc":[{"id":"1.168133548","rc":[{"trd":[[9.8,15.97]],"batb":[[0,9.8,3.65]],"ltp":9.8,"tv":169.66,"id":10616006}],"tv":1556.71}]}
{"op":"mcm","clk":"992292000","pt":1580518826157,"mc":[{"id":"1.168133548","rc":[{"batb":[[0,13,2.87]],"ltp":11.5,"tv":41.05,"id":8429550},{"batb":[[0,5.9,5.37]],"ltp":6.4,"tv":116.51,"id":10170404}]}]}
{"op":"mcm","clk":"992293746","pt":1580518875643,"mc":[{"id":"1.168133548","rc":[{"batl":[[0,13.5,30],[1,16,2],[2,16.5,2.25]],"ltp":11.5,"tv":41.05,"id":8429550}]}]}
{"op":"mcm","clk":"992293862","pt":1580518880333,"mc":[{"id":"1.168133548","rc":[{"batb":[[0,13.5,7.95]],"ltp":11.0,"tv":26.11,"id":9193530}]}]}
{"op":"mcm","clk":"992294457","pt":1580518889987,"mc":[{"id":"1.168133548","rc":[{"batl":[[2,17.5,5.29]],"ltp":11.5,"tv":41.05,"id":8429550}]}]}
{"op":"mcm","clk":"992294563","pt":1580518891695,"mc":[{"id":"1.168133548","rc":[{"batb":[[0,13,4.85],[1,12,2.52],[2,11.5,1.53]],"ltp":11.5,"tv":41.05,"id":8429550}]}]}
{"op":"mcm","clk":"992295658","pt":1580518922414,"mc":[{"id":"1.168133548","rc":[{"batb":[[0,14,2.37],[1,13.5,7.95]],"ltp":11.0,"tv":26.11,"id":9193530}]}]}
{"op":"mcm","clk":"992295827","pt":1580518928437,"mc":[{"id":"1.168133548","rc":[{"batb":[[0,14,6.89],[1,13.5,3.26]],"ltp":11.0,"tv":26.11,"id":9193530}]}]}
{"op":"mcm","clk":"992296048","pt":1580518936849,"mc":[{"id":"1.168133548","rc":[{"batb":[[0,13,3.31]],"batl":[[1,17.5,5.29],[2,25,1.25]],"ltp":11.5,"tv":41.05,"id":8429550}]}]}
{"op":"mcm","clk":"992299343","pt":1580519072535,"mc":[{"id":"1.168133548","rc":[{"batb":[[0,14.5,1.18],[1,14,6.89],[2,13.5,1.98]],"ltp":11.0,"tv":26.11,"id":9193530}]}]}
{"op":"mcm","clk":"992299446","pt":1580519075531,"mc":[{"id":"1.168133548","rc":[{"batb":[[0,5.8,39.02]],"ltp":5.9,"tv":774.05,"id":9417341}]}]}
{"op":"mcm","clk":"992299588","pt":1580519079655,"mc":[{"id":"1.168133548","rc":[{"batl":[[0,5.9,9.54]],"ltp":5.9,"tv":774.05,"id":9417341}]}]}
{"op":"mcm","clk":"992299789","pt":1580519087347,"mc":[{"id":"1.168133548","rc":[{"batb":[[1,14,2.37]],"ltp":11.0,"tv":26.11,"id":9193530}]}]}
{"op":"mcm","clk":"992300258","pt":1580519102282,"mc":[{"id":"1.168133548","rc":[{"batb":[[1,13.5,1.98],[2,11.5,2.52]],"ltp":11.0,"tv":26.11,"id":9193530}]}]}
{"op":"mcm","clk":"992300287","pt":1580519103371,"mc":[{"id":"1.168133548","rc":[{"batb":[[1,13.5,6.67]],"ltp":11.0,"tv":26.11,"id":9193530}]}]}
{"op":"mcm","clk":"992301546","pt":1580519161021,"mc":[{"id":"1.168133548","rc":[{"trd":[[13,4]],"batb":[[0,13,1.31]],"ltp":13.0,"tv":45.05,"id":8429550}],"tv":1560.71}]}
{"op":"mcm","clk":"992301599","pt":1580519163638,"mc":[{"id":"1.168133548","rc":[{"trd":[[11,19.04]],"batl":[[0,11,6.12]],"ltp":11.0,"tv":178.76,"id":10616006}],"tv":1569.81}]}
{"op":"mcm","clk":"992318466","pt":1580519443532,"mc":[{"id":"1.168133548","rc":[{"batl":[[0,10.5,2.57],[1,11,6.12],[2,11.5,5]],"ltp":11.0,"tv":178.76,"id":10616006}]}]}
{"op":"mcm","clk":"992319638","pt":1580519489467,"mc":[{"id":"1.168133548","rc":[{"batl":[[2,95,2]],"ltp":11.0,"tv":26.11,"id":9193530},{"batl":[[2,95,2]],"ltp":14.5,"tv":13.82,"id":9001159}]}]}
{"op":"mcm","clk":"992320062","pt":1580519509521,"mc":[{"id":"1.168133548","rc":[{"batb":[[0,12.5,1.31]],"ltp":13.0,"tv":45.05,"id":8429550}]}]}
{"op":"mcm","clk":"992331271","pt":1580519971485,"mc":[{"id":"1.168133548","rc":[{"trd":[[12,1.38],[12.5,2.62]],"batb":[[0,12,1.83],[1,11.5,1.53],[2,8.8,2.01]],"ltp":12.0,"tv":49.05,"id":8429550}],"tv":1573.8}]}
{"op":"mcm","clk":"992333789","pt":1580520063507,"mc":[{"id":"1.168133548","rc":[{"batl":[[0,6,1.51],[1,6.2,20.62],[2,6.8,100]],"ltp":6.2,"tv":125.17,"id":8231803}]}]}
{"op":"mcm","clk":"992333803","pt":1580520063970,"mc":[{"id":"1.168133548","rc":[{"batl":[[0,6.2,20.62],[1,6.8,100],[2,7,2]],"ltp":6.2,"tv":125.17,"id":8231803}]}]}
{"op":"mcm","clk":"992334945","pt":1580520123276,"mc":[{"id":"1.168133548","rc":[{"batb":[[0,12,4.35]],"ltp":12.0,"tv":49.05,"id":8429550}]}]}
{"op":"mcm","clk":"992334954","pt":1580520123943,"mc":[{"id":"1.168133548","rc":[{"batb":[[0,12.5,1.38],[1,12,4.35],[2,11.5,1.53]],"ltp":12.0,"tv":49.05,"id":8429550}]}]}
{"op":"mcm","clk":"992346113","pt":1580520182495,"mc":[{"id":"1.168133548","rc":[{"batb":[[2,11,4.6]],"ltp":11.0,"tv":26.11,"id":9193530}]}]}
{"op":"mcm","clk":"992346121","pt":1580520182706,"mc":[{"id":"1.168133548","rc":[{"batb":[[1,14,2.37],[2,13.5,6.67]],"ltp":11.0,"tv":26.11,"id":9193530}]}]}
{"op":"mcm","clk":"992346657","pt":1580520201448,"mc":[{"id":"1.168133548","rc":[{"batb":[[1,14,6.89],[2,13.5,1.98]],"ltp":11.0,"tv":26.11,"id":9193530}]}]}
{"op":"mcm","clk":"992361618","pt":1580520747521,"mc":[{"id":"1.168133548","rc":[{"batb":[[0,14.5,3.17],[2,11,4.6]],"ltp":11.0,"tv":26.11,"id":9193530}]}]}
{"op":"mcm","clk":"992361876","pt":1580520756310,"mc":[{"id":"1.168133548","rc":[{"trd":[[9.8,23.28]],"batb":[[0,9.6,10.42],[1,9,2],[2,5.8,5.68]],"batl":[[0,9.8,1.34],[1,10.5,2.57],[2,11,6.12]],"ltp":9.8,"tv":186.07,"id":10616006}],"tv":1581.12}]}
{"op":"mcm","clk":"992361943","pt":1580520758521,"mc":[{"id":"1.168133548","rc":[{"batb":[[0,14.5,7.53],[1,14,2.37]],"ltp":11.0,"tv":26.11,"id":9193530}]}]}
{"op":"mcm","clk":"992362023","pt":1580520762115,"mc":[{"id":"1.168133548","rc":[{"batb":[[2,8.4,3]],"ltp":9.8,"tv":186.07,"id":10616006}]}]}
{"op":"mcm","clk":"992362363","pt":1580520775904,"mc":[{"id":"1.168133548","rc":[{"batl":[[0,10.5,2.57],[1,11,6.12],[2,11.5,5]],"ltp":9.8,"tv":186.07,"id":10616006}]}]}
{"op":"mcm","clk":"992362546","pt":1580520782324,"mc":[{"id":"1.168133548","rc":[{"batb":[[0,15,2.22],[1,14.5,7.53]],"ltp":11.0,"tv":26.11,"id":9193530}]}]}
{"op":"mcm","clk":"992362745","pt":1580520790532,"mc":[{"id":"1.168133548","rc":[{"batb":[[1,14.5,3.17]],"ltp":11.0,"tv":26.11,"id":9193530}]}]}
{"op":"mcm","clk":"992362749","pt":1580520790632,"mc":[{"id":"1.168133548","rc":[{"batb":[[0,15,6.44]],"ltp":11.0,"tv":26.11,"id":9193530}]}]}
{"op":"mcm","clk":"992366288","pt":1580520932976,"mc":[{"id":"1.168133548","rc":[{"batb":[[0,15.5,1.11],[1,15,6.44],[2,14.5,1.98]],"ltp":11.0,"tv":26.11,"id":9193530}]}]}
{"op":"mcm","clk":"992366405","pt":1580520937399,"mc":[{"id":"1.168133548","rc":[{"batb":[[1,15,2.22]],"ltp":11.0,"tv":26.11,"id":9193530}]}]}
{"op":"mcm","clk":"992366944","pt":1580520962518,"mc":[{"id":"1.168133548","rc":[{"batb":[[1,14.5,1.98],[2,11.5,2.52]],"ltp":11.0,"tv":26.11,"id":9193530}]}]}
{"op":"mcm","clk":"992367069","pt":1580520969410,"mc":[{"id":"1.168133548","rc":[{"batb":[[1,14.5,6.35]],"ltp":11.0,"tv":26.11,"id":9193530}]}]}
{"op":"mcm","clk":"992368197","pt":1580521022171,"mc":[{"id":"1.168133548","rc":[{"batb":[[1,15,2.22],[2,14.5,6.35]],"ltp":11.0,"tv":26.11,"id":9193530}]}]}
{"op":"mcm","clk":"992368539","pt":1580521035468,"mc":[{"id":"1.168133548","rc":[{"batb":[[1,15,6.44],[2,14.5,1.98]],"ltp":11.0,"tv":26.11,"id":9193530}]}]}
{"op":"mcm","clk":"992368923","pt":1580521051477,"mc":[{"id":"1.168133548","rc":[{"batb":[[1,15,2.22]],"ltp":11.0,"tv":26.11,"id":9193530}]}]}
{"op":"mcm","clk":"992379321","pt":1580521082540,"mc":[{"id":"1.168133548","rc":[{"batb":[[1,14.5,1.98],[2,11.5,2.52]],"ltp":11.0,"tv":26.11,"id":9193530}]}]}
{"op":"mcm","clk":"992379341","pt":1580521083310,"mc":[{"id":"1.168133548","rc":[{"batb":[[1,14.5,6.35]],"ltp":11.0,"tv":26.11,"id":9193530}]}]}
{"op":"mcm","clk":"992380379","pt":1580521142210,"mc":[{"id":"1.168133548","rc":[{"batb":[[1,15,2.22],[2,14.5,6.35]],"ltp":11.0,"tv":26.11,"id":9193530}]}]}
{"op":"mcm","clk":"992380457","pt":1580521148534,"mc":[{"id":"1.168133548","rc":[{"batb":[[2,14.5,1.98]],"ltp":11.0,"tv":26.11,"id":9193530}]}]}
{"op":"mcm","clk":"992380458","pt":1580521148638,"mc":[{"id":"1.168133548","rc":[{"batb":[[1,15,6.44]],"ltp":11.0,"tv":26.11,"id":9193530}]}]}
{"op":"mcm","clk":"992380705","pt":1580521164440,"mc":[{"id":"1.168133548","rc":[{"batb":[[1,15,2.22]],"ltp":11.0,"tv":26.11,"id":9193530}]}]}
{"op":"mcm","clk":"992381724","pt":1580521203074,"mc":[{"id":"1.168133548","rc":[{"batb":[[1,14.5,1.98],[2,11.5,2.52]],"ltp":11.0,"tv":26.11,"id":9193530}]}]}
{"op":"mcm","clk":"992381952","pt":1580521215378,"mc":[{"id":"1.168133548","rc":[{"batb":[[1,14.5,6.35]],"ltp":11.0,"tv":26.11,"id":9193530}]}]}
{"op":"mcm","clk":"992382864","pt":1580521262435,"mc":[{"id":"1.168133548","rc":[{"batb":[[2,11,4.6]],"ltp":11.0,"tv":26.11,"id":9193530}]}]}
{"op":"mcm","clk":"992382873","pt":1580521262640,"mc":[{"id":"1.168133548","rc":[{"batb":[[1,15,2.22],[2,14.5,6.35]],"ltp":11.0,"tv":26.11,"id":9193530}]}]}
{"op":"mcm","clk":"992382962","pt":1580521266565,"mc":[{"id":"1.168133548","rc":[{"batb":[[1,15,6.44],[2,14.5,1.98]],"ltp":11.0,"tv":26.11,"id":9193530}]}]}
{"op":"mcm","clk":"992383177","pt":1580521276458,"mc":[{"id":"1.168133548","rc":[{"batb":[[1,15,2.22]],"ltp":11.0,"tv":26.11,"id":9193530}]}]}
{"op":"mcm","clk":"992384132","pt":1580521322029,"mc":[{"id":"1.168133548","rc":[{"batb":[[1,14.5,1.98],[2,11.5,2.52]],"ltp":11.0,"tv":26.11,"id":9193530}]}]}
{"op":"mcm","clk":"992384256","pt":1580521327441,"mc":[{"id":"1.168133548","rc":[{"batb":[[1,14.5,6.35]],"ltp":11.0,"tv":26.11,"id":9193530}]}]}
{"op":"mcm","clk":"992385305","pt":1580521382565,"mc":[{"id":"1.168133548","rc":[{"batb":[[1,15,2.22],[2,14.5,6.35]],"ltp":11.0,"tv":26.11,"id":9193530}]}]}
{"op":"mcm","clk":"992385603","pt":1580521395564,"mc":[{"id":"1.168133548","rc":[{"batb":[[1,15,6.44],[2,14.5,1.98]],"ltp":11.0,"tv":26.11,"id":9193530}]}]}
{"op":"mcm","clk":"992385798","pt":1580521403382,"mc":[{"id":"1.168133548","rc":[{"batb":[[1,15,2.22]],"ltp":11.0,"tv":26.11,"id":9193530}]}]}
{"op":"mcm","clk":"992386716","pt":1580521442459,"mc":[{"id":"1.168133548","rc":[{"batb":[[1,14.5,1.98],[2,11.5,2.52]],"ltp":11.0,"tv":26.11,"id":9193530}]}]}
{"op":"mcm","clk":"992386836","pt":1580521448290,"mc":[{"id":"1.168133548","rc":[{"batb":[[1,14.5,6.35]],"ltp":11.0,"tv":26.11,"id":9193530}]}]}
{"op":"mcm","clk":"992387532","pt":1580521476320,"mc":[{"id":"1.168133548","rc":[{"batb":[[1,9.2,4.4],[2,9,2]],"ltp":9.8,"tv":186.07,"id":10616006}]}]}
{"op":"mcm","clk":"992387871","pt":1580521493426,"mc":[{"id":"1.168133548","rc":[{"batb":[[0,5.9,9.77]],"ltp":6.4,"tv":116.51,"id":10170404}]}]}
{"op":"mcm","clk":"992387943","pt":1580521497247,"mc":[{"id":"1.168133548","rc":[{"batb":[[0,5.9,6.38]],"ltp":6.4,"tv":116.51,"id":10170404}]}]}
{"op":"mcm","clk":"992388065","pt":1580521502477,"mc":[{"id":"1.168133548","rc":[{"batb":[[0,6,2.16],[1,5.9,6.38],[2,5.8,7.05]],"ltp":6.4,"tv":116.51,"id":10170404},{"batb":[[1,15,2.22],[2,14.5,1.98]],"ltp":11.0,"tv":26.11,"id":9193530}]}]}
{"op":"mcm","clk":"992388071","pt":1580521502606,"mc":[{"id":"1.168133548","rc":[{"batb":[[1,15,6.44]],"ltp":11.0,"tv":26.11,"id":9193530}]}]}
{"op":"mcm","clk":"992388232","pt":1580521508352,"mc":[{"id":"1.168133548","rc":[{"batb":[[1,15,2.22]],"ltp":11.0,"tv":26.11,"id":9193530}]}]}
{"op":"mcm","clk":"992389312","pt":1580521562190,"mc":[{"id":"1.168133548","rc":[{"batb":[[1,14.5,1.98],[2,11.5,2.52]],"ltp":11.0,"tv":26.11,"id":9193530}]}]}
{"op":"mcm","clk":"992389431","pt":1580521567403,"mc":[{"id":"1.168133548","rc":[{"batb":[[1,14.5,6.35]],"ltp":11.0,"tv":26.11,"id":9193530}]}]}
{"op":"mcm","clk":"992391151","pt":1580521622502,"mc":[{"id":"1.168133548","rc":[{"batb":[[2,11,4.6]],"ltp":11.0,"tv":26.11,"id":9193530}]}]}
{"op":"mcm","clk":"992391156","pt":1580521622701,"mc":[{"id":"1.168133548","rc":[{"batb":[[1,15,2.22],[2,14.5,6.35]],"ltp":11.0,"tv":26.11,"id":9193530}]}]}
{"op":"mcm","clk":"992391249","pt":1580521626470,"mc":[{"id":"1.168133548","rc":[{"batb":[[1,15,6.44],[2,14.5,1.98]],"ltp":11.0,"tv":26.11,"id":9193530}]}]}
{"op":"mcm","clk":"992391361","pt":1580521631413,"mc":[{"id":"1.168133548","rc":[{"batb":[[1,15,2.22]],"ltp":11.0,"tv":26.11,"id":9193530}]}]}
{"op":"mcm","clk":"992392631","pt":1580521681933,"mc":[{"id":"1.168133548","rc":[{"batb":[[1,14.5,1.98],[2,11.5,2.52]],"ltp":11.0,"tv":26.11,"id":9193530}]}]}
{"op":"mcm","clk":"992395027","pt":1580521796534,"mc":[{"id":"1.168133548","rc":[{"batb":[[1,5.9,1.98]],"ltp":6.4,"tv":116.51,"id":10170404}]}]}
{"op":"mcm","clk":"992395032","pt":1580521796639,"mc":[{"id":"1.168133548","rc":[{"batb":[[0,6,6.56]],"ltp":6.4,"tv":116.51,"id":10170404}]}]}
{"op":"mcm","clk":"992395061","pt":1580521798031,"mc":[{"id":"1.168133548","rc":[{"batb":[[2,5.8,3.04]],"batl":[[1,6.8,2]],"ltp":6.4,"tv":116.51,"id":10170404}]}]}
{"op":"mcm","clk":"992395138","pt":1580521801440,"mc":[{"id":"1.168133548","rc":[{"batb":[[0,6,2.16],[1,5.9,6.38]],"ltp":6.4,"tv":116.51,"id":10170404}]}]}
{"op":"mcm","clk":"992395543","pt":1580521818564,"mc":[{"id":"1.168133548","rc":[{"batb":[[1,9,2],[2,8.4,3]],"ltp":9.8,"tv":186.07,"id":10616006}]}]}
{"op":"mcm","clk":"992395547","pt":1580521818673,"mc":[{"id":"1.168133548","rc":[{"batb":[[1,9.4,4.4],[2,9,2]],"ltp":9.8,"tv":186.07,"id":10616006}]}]}
{"op":"mcm","clk":"992395836","pt":1580521828494,"mc":[{"id":"1.168133548","rc":[{"batb":[[1,9.2,4.4]],"ltp":9.8,"tv":186.07,"id":10616006}]}]}
{"op":"mcm","clk":"992396719","pt":1580521873016,"mc":[{"id":"1.168133548","rc":[{"trd":[[5.9,7.56]],"batb":[[0,5.6,6.71],[1,5.5,3],[2,5,5.07]],"ltp":5.9,"tv":129.17,"id":8231803}],"tv":1585.12}]}
{"op":"mcm","clk":"992396753","pt":1580521874103,"mc":[{"id":"1.168133548","rc":[{"batl":[[0,6,2],[1,6.2,20.62],[2,6.8,100]],"ltp":5.9,"tv":129.17,"id":8231803}]}]}
{"op":"mcm","clk":"992397625","pt":1580521909376,"mc":[{"id":"1.168133548","rc":[{"batb":[[1,14.5,6.35]],"ltp":11.0,"tv":26.11,"id":9193530}]}]}
{"op":"mcm","clk":"992398059","pt":1580521922791,"mc":[{"id":"1.168133548","rc":[{"batb":[[1,15,2.22],[2,14.5,6.35]],"ltp":11.0,"tv":26.11,"id":9193530}]}]}
{"op":"mcm","clk":"992398448","pt":1580521935523,"mc":[{"id":"1.168133548","rc":[{"batb":[[1,15,6.44],[2,14.5,1.98]],"ltp":11.0,"tv":26.11,"id":9193530}]}]}
{"op":"mcm","clk":"992398814","pt":1580521951398,"mc":[{"id":"1.168133548","rc":[{"batb":[[1,15,2.22]],"ltp":11.0,"tv":26.11,"id":9193530}]}]}
{"op":"mcm","clk":"992409273","pt":1580521974047,"mc":[{"id":"1.168133548","rc":[{"batb":[[0,6,4.14],[1,5.9,4.4]],"ltp":6.4,"tv":116.51,"id":10170404},{"batb":[[0,15.5,3.09],[2,11,4.6]],"ltp":11.0,"tv":26.11,"id":9193530}]}]}
{"op":"mcm","clk":"992409515","pt":1580521982568,"mc":[{"id":"1.168133548","rc":[{"batb":[[1,11.5,2.52]],"ltp":11.0,"tv":26.11,"id":9193530}]}]}
{"op":"mcm","clk":"992409519","pt":1580521982671,"mc":[{"id":"1.168133548","rc":[{"batb":[[2,11,3]],"ltp":11.0,"tv":26.11,"id":9193530}]}]}
{"op":"mcm","clk":"992409787","pt":1580521991651,"mc":[{"id":"1.168133548","rc":[{"batb":[[2,11,4.6]],"ltp":11.0,"tv":26.11,"id":9193530}]}]}
{"op":"mcm","clk":"992413788","pt":1580522140552,"mc":[{"id":"1.168133548","rc":[{"batl":[[2,6.8,102.86]],"ltp":5.9,"tv":129.17,"id":8231803}]}]}
{"op":"mcm","clk":"992423028","pt":1580522468716,"mc":[{"id":"1.168133548","rc":[{"batl":[[0,5.9,3.03],[1,6,2],[2,6.2,20.62]],"ltp":5.9,"tv":129.17,"id":8231803}]}]}
{"op":"mcm","clk":"992423058","pt":1580522469703,"mc":[{"id":"1.168133548","rc":[{"batl":[[0,6,2],[1,6.2,20.62],[2,6.8,102.86]],"ltp":5.9,"tv":129.17,"id":8231803}]}]}
{"op":"mcm","clk":"992486284","pt":1580524043084,"mc":[{"id":"1.168133548","rc":[{"batl":[[2,6.8,100]],"ltp":5.9,"tv":129.17,"id":8231803}]}]}
{"op":"mcm","clk":"992494202","pt":1580524278508,"mc":[{"id":"1.168133548","rc":[{"batl":[[0,10,2.89],[1,10.5,2.57],[2,11,3.23]],"ltp":9.8,"tv":186.07,"id":10616006}]}]}
{"op":"mcm","clk":"992497497","pt":1580524348509,"mc":[{"id":"1.168133548","rc":[{"trd":[[6.4,13.88]],"batb":[[0,6,3],[1,5.7,3.09],[2,5.6,11]],"batl":[[0,6.4,9.57],[1,7,24.36],[2,7.2,27]],"ltp":6.4,"tv":123.9,"id":17352128}],"tv":1597.98}]}
{"op":"mcm","clk":"992497550","pt":1580524350438,"mc":[{"id":"1.168133548","rc":[{"batb":[[0,15.5,7.17]],"ltp":11.0,"tv":26.11,"id":9193530}]}]}
{"op":"mcm","clk":"992497615","pt":1580524352422,"mc":[{"id":"1.168133548","rc":[{"batb":[[0,5.7,3.78],[1,5.6,5.95],[2,5.5,3]],"ltp":5.9,"tv":129.17,"id":8231803}]}]}
{"op":"mcm","clk":"992497660","pt":1580524353505,"mc":[{"id":"1.168133548","rc":[{"batb":[[0,9.8,1.76],[1,9.6,10.42],[2,9.2,4.4]],"ltp":9.8,"tv":186.07,"id":10616006},{"batb":[[0,6.2,2.78],[1,6,4.14],[2,5.9,4.4]],"ltp":6.4,"tv":116.51,"id":10170404},{"batb":[[0,15,1.15],[1,14.5,5.28],[2,14,2.76]],"ltp":14.5,"tv":13.82,"id":9001159}]}]}
{"op":"mcm","clk":"992497669","pt":1580524353813,"mc":[{"id":"1.168133548","rc":[{"batb":[[0,5.7,3.09],[1,5.6,11],[2,5.5,3]],"ltp":6.4,"tv":123.9,"id":17352128}]}]}
{"op":"mcm","clk":"992497881","pt":1580524361101,"mc":[{"id":"1.168133548","rc":[{"batb":[[1,6,7.08]],"ltp":6.4,"tv":116.51,"id":10170404}]}]}
{"op":"mcm","clk":"992498131","pt":1580524370520,"mc":[{"id":"1.168133548","rc":[{"trd":[[13.5,1.78]],"batl":[[0,13.5,29.11]],"ltp":13.5,"tv":50.83,"id":8429550},{"trd":[[5.9,118.97]],"batl":[[0,5.9,7.51]],"ltp":5.9,"tv":778.11,"id":9417341},{"trd":[[6,4.54]],"batl":[[0,6.2,20.62],[1,6.8,100],[2,7,2]],"ltp":6.0,"tv":133.17,"id":8231803},{"trd":[[10,12.22]],"batl":[[0,10.5,2.57],[1,11,3.23],[2,11.5,5]],"ltp":10.0,"tv":191.85,"id":10616006},{"trd":[[6.6,19.64]],"batl":[[0,6.6,2.18]],"ltp":6.6,"tv":120.15,"id":10170404},{"trd":[[9.8,7.51]],"batl":[[0,10,1.87],[1,13,2],[2,16.5,3.17]],"ltp":9.8,"tv":183.26,"id":15608820},{"batb":[[0,15.5,7.92]],"ltp":11.0,"tv":26.11,"id":9193530},{"batb":[[0,15,1.92]],"ltp":14.5,"tv":13.82,"id":9001159},{"trd":[[6.4,17.64]],"batl":[[0,6.4,7.69]],"ltp":6.4,"tv":127.66,"id":17352128}],"tv":1625.0}]}
{"op":"mcm","clk":"992498134","pt":1580524370622,"mc":[{"id":"1.168133548","rc":[{"batl":[[0,6.2,4],[1,6.4,7.69],[2,7,24.36]],"ltp":6.4,"tv":127.66,"id":17352128}]}]}
{"op":"mcm","clk":"992498220","pt":1580524373096,"mc":[{"id":"1.168133548","rc":[{"trd":[[6.2,9.4]],"batl":[[0,6.2,2.79]],"ltp":6.2,"tv":130.08,"id":17352128}],"tv":1627.42}]}
{"op":"mcm","clk":"992498411","pt":1580524377212,"mc":[{"id":"1.168133548","rc":[{"batb":[[0,5.8,2.07],[1,5.7,3.78],[2,5.6,5.95]],"ltp":6.0,"tv":133.17,"id":8231803},{"batb":[[1,6,7.43]],"ltp":6.6,"tv":120.15,"id":10170404},{"batb":[[0,9,2.18],[1,8.8,6.35],[2,8.6,11.63]],"ltp":9.8,"tv":183.26,"id":15608820},{"batb":[[0,5.7,6.6]],"ltp":6.2,"tv":130.08,"id":17352128}]}]}
{"op":"mcm","clk":"992498628","pt":1580524382512,"mc":[{"id":"1.168133548","rc":[{"batb":[[0,9,9.22]],"ltp":9.8,"tv":183.26,"id":15608820},{"batb":[[0,16,2.83],[1,15.5,3.09]],"ltp":11.0,"tv":26.11,"id":9193530},{"batb":[[2,14,1.26]],"ltp":14.5,"tv":13.82,"id":9001159}]}]}
{"op":"mcm","clk":"992498648","pt":1580524382821,"mc":[{"id":"1.168133548","rc":[{"batb":[[0,15,3.32]],"ltp":14.5,"tv":13.82,"id":9001159}]}]}
{"op":"mcm","clk":"992499306","pt":1580524398474,"mc":[{"id":"1.168133548","rc":[{"batb":[[1,14.5,1.98]],"ltp":14.5,"tv":13.82,"id":9001159}]}]}
{"op":"mcm","clk":"992499310","pt":1580524398576,"mc":[{"id":"1.168133548","rc":[{"batb":[[0,16,6.78]],"ltp":11.0,"tv":26.11,"id":9193530},{"batb":[[0,15,6.5]],"ltp":14.5,"tv":13.82,"id":9001159}]}]}
{"op":"mcm","clk":"992500106","pt":1580524417468,"mc":[{"id":"1.168133548","rc":[{"batb":[[0,15.5,1.91],[1,15,5.73],[2,14.5,1.98]],"ltp":14.5,"tv":13.82,"id":9001159}]}]}
{"op":"mcm","clk":"992501007","pt":1580524442516,"mc":[{"id":"1.168133548","rc":[{"batb":[[0,9.2,1.26],[1,9,9.22],[2,8.8,5.04]],"ltp":9.8,"tv":183.26,"id":15608820}]}]}
{"op":"mcm","clk":"992501782","pt":1580524465849,"mc":[{"id":"1.168133548","rc":[{"trd":[[6.2,9.68]],"batl":[[0,6.2,2.65]],"ltp":6.2,"tv":130.36,"id":17352128}],"tv":1627.7}]}
{"op":"mcm","clk":"992504203","pt":1580524533183,"mc":[{"id":"1.168133548","rc":[{"batb":[[0,16.5,1.04],[1,16,6.78],[2,15.5,1.98]],"ltp":11.0,"tv":26.11,"id":9193530}]}]}
{"op":"mcm","clk":"992504498","pt":1580524541429,"mc":[{"id":"1.168133548","rc":[{"batb":[[1,16,2.83]],"ltp":11.0,"tv":26.11,"id":9193530}]}]}
{"op":"mcm","clk":"992518377","pt":1580524652902,"mc":[{"id":"1.168133548","rc":[{"batb":[[0,5.8,2.97],[1,5.7,6.6],[2,5.6,11]],"ltp":6.2,"tv":130.36,"id":17352128}]}]}
{"op":"mcm","clk":"992519759","pt":1580524692557,"mc":[{"id":"1.168133548","rc":[{"batb":[[0,15.5,2.23]],"ltp":14.5,"tv":13.82,"id":9001159}]}]}
{"op":"mcm","clk":"992520129","pt":1580524705569,"mc":[{"id":"1.168133548","rc":[{"batb":[[0,15.5,5.31],[1,15,2.55]],"ltp":14.5,"tv":13.82,"id":9001159}]}]}
{"op":"mcm","clk":"992531324","pt":1580525007396,"mc":[{"id":"1.168133548","rc":[{"batl":[[2,7,21.34]],"ltp":6.2,"tv":130.36,"id":17352128}]}]}
{"op":"mcm","clk":"992561042","pt":1580525603545,"mc":[{"id":"1.168133548","rc":[{"batb":[[0,5.8,40.7]],"ltp":5.9,"tv":778.11,"id":9417341},{"batb":[[0,6.2,4.76],[1,6,5.45]],"ltp":6.6,"tv":120.15,"id":10170404},{"batb":[[0,15.5,7.29],[2,14,1.26]],"ltp":14.5,"tv":13.82,"id":9001159},{"batb":[[0,16.5,3.02],[2,11,4.6]],"ltp":11.0,"tv":26.11,"id":9193530},{"batb":[[0,5.8,6.74]],"ltp":6.2,"tv":130.36,"id":17352128}]}]}
{"op":"mcm","clk":"992561057","pt":1580525604265,"mc":[{"id":"1.168133548","rc":[{"batb":[[2,11,5.03]],"ltp":11.0,"tv":26.11,"id":9193530}]}]}
{"op":"mcm","clk":"992561166","pt":1580525608536,"mc":[{"id":"1.168133548","rc":[{"batb":[[0,16.5,6.86],[2,11,4.6]],"ltp":11.0,"tv":26.11,"id":9193530}]}]}
{"op":"mcm","clk":"992561179","pt":1580525609054,"mc":[{"id":"1.168133548","rc":[{"batb":[[0,16.5,7.15]],"ltp":11.0,"tv":26.11,"id":9193530}]}]}
{"op":"mcm","clk":"992562000","pt":1580525642502,"mc":[{"id":"1.168133548","rc":[{"trd":[[16,4]],"batb":[[0,15.5,8.24],[1,14,1.26],[2,13.5,7.41]],"batl":[[0,85,9.15],[1,95,2],[2,330,0.16]],"ltp":16.0,"tv":16.69,"id":9001159},{"batb":[[0,17,2.24],[1,16.5,6.86],[2,11,5.35]],"ltp":11.0,"tv":26.11,"id":9193530}],"tv":1630.57}]}
{"op":"mcm","clk":"992562077","pt":1580525644302,"mc":[{"id":"1.168133548","rc":[{"batl":[[0,85,9.33]],"ltp":16.0,"tv":16.69,"id":9001159}]}]}
{"op":"mcm","clk":"992562336","pt":1580525651529,"mc":[{"id":"1.168133548","rc":[{"batb":[[0,16,3.94],[1,15.5,4.21],[2,14,1.26]],"ltp":16.0,"tv":16.69,"id":9001159},{"batb":[[1,16.5,3.02]],"ltp":11.0,"tv":26.11,"id":9193530}]}]}
{"op":"mcm","clk":"992562438","pt":1580525653638,"mc":[{"id":"1.168133548","rc":[{"batb":[[1,5.7,3.09]],"ltp":6.2,"tv":130.36,"id":17352128}]}]}
{"op":"mcm","clk":"992564147","pt":1580525702905,"mc":[{"id":"1.168133548","rc":[{"batb":[[0,16.5,5.33],[1,11,5.35],[2,10.5,3.03]],"ltp":11.0,"tv":26.11,"id":9193530}]}]}
{"op":"mcm","clk":"992566903","pt":1580525790389,"mc":[{"id":"1.168133548","rc":[{"batl":[[1,6.8,102.79]],"ltp":6.0,"tv":133.17,"id":8231803}]}]}
{"op":"mcm","clk":"992577633","pt":1580526127741,"mc":[{"id":"1.168133548","rc":[{"batl":[[0,6,11.65],[1,6.2,2.65],[2,6.4,7.69]],"ltp":6.2,"tv":130.36,"id":17352128}]}]}
{"op":"mcm","clk":"992578262","pt":1580526147585,"mc":[{"id":"1.168133548","rc":[{"batl":[[1,6.4,7.69],[2,7,21.34]],"ltp":6.2,"tv":130.36,"id":17352128}]}]}
{"op":"mcm","clk":"992601860","pt":1580526541394,"mc":[{"id":"1.168133548","rc":[{"trd":[[6,23.31]],"batl":[[0,6.4,7.69],[1,7,21.34],[2,7.2,27]],"ltp":6.0,"tv":153.67,"id":17352128}],"tv":1653.88}]}
{"op":"mcm","clk":"992601909","pt":1580526542478,"mc":[{"id":"1.168133548","rc":[{"batb":[[0,15.5,5.16],[1,14,1.26],[2,13.5,7.41]],"ltp":16.0,"tv":16.69,"id":9001159}]}]}
{"op":"mcm","clk":"992619550","pt":1580527021560,"mc":[{"id":"1.168133548","rc":[{"batl":[[1,6.8,100]],"ltp":6.0,"tv":133.17,"id":8231803}]}]}
{"op":"mcm","clk":"992624336","pt":1580527153833,"mc":[{"id":"1.168133548","rc":[{"batl":[[0,6.2,4],[1,6.4,7.69],[2,7,21.34]],"ltp":6.0,"tv":153.67,"id":17352128}]}]}
{"op":"mcm","clk":"992624747","pt":1580527165435,"mc":[{"id":"1.168133548","rc":[{"batb":[[0,16,3.94],[1,15.5,4.21],[2,14,1.26]],"ltp":16.0,"tv":16.69,"id":9001159}]}]}
{"op":"mcm","clk":"992651136","pt":1580527745417,"mc":[{"id":"1.168133548","rc":[{"batb":[[0,5.8,38.12]],"batl":[[0,5.9,4.98]],"ltp":5.9,"tv":778.11,"id":9417341}]}]}
{"op":"mcm","clk":"992687653","pt":1580528655396,"mc":[{"id":"1.168133548","rc":[{"trd":[[9,27.87],[9.2,11.82]],"batb":[[0,9,8.8],[1,8.8,5.04],[2,8.6,11.63]],"ltp":9.0,"tv":186.62,"id":15608820}],"tv":1657.24}]}
{"op":"mcm","clk":"992720954","pt":1580529240801,"mc":[{"id":"1.168133548","rc":[{"batb":[[0,16.5,1.98],[1,16,3.94],[2,15.5,2.23]],"ltp":16.0,"tv":16.69,"id":9001159}]}]}
{"op":"mcm","clk":"992723403","pt":1580529318390,"mc":[{"id":"1.168133548","rc":[{"batb":[[2,15.5,1.91]],"ltp":16.0,"tv":16.69,"id":9001159}]}]}
{"op":"mcm","clk":"992723415","pt":1580529318688,"mc":[{"id":"1.168133548","rc":[{"batb":[[0,16.5,2.28]],"ltp":16.0,"tv":16.69,"id":9001159}]}]}
{"op":"mcm","clk":"992791837","pt":1580530660036,"mc":[{"id":"1.168133548","rc":[{"batl":[[0,6.4,5],[1,6.6,2.18],[2,6.8,2]],"ltp":6.6,"tv":120.15,"id":10170404}]}]}
{"op":"mcm","clk":"992801772","pt":1580530918426,"mc":[{"id":"1.168133548","rc":[{"trd":[[5.8,227.11]],"batb":[[0,5.7,52.8],[1,5.5,16.85],[2,5.2,2]],"ltp":5.8,"tv":878.11,"id":9417341}],"tv":1757.25}]}
{"op":"mcm","clk":"992802029","pt":1580530924526,"mc":[{"id":"1.168133548","rc":[{"batb":[[1,5.5,13.85]],"ltp":5.8,"tv":878.11,"id":9417341}]}]}
{"op":"mcm","clk":"992816906","pt":1580531044312,"mc":[{"id":"1.168133548","rc":[{"batb":[[0,5.8,2.97],[1,5.7,52.8],[2,5.5,13.85]],"ltp":5.8,"tv":878.11,"id":9417341}]}]}
{"op":"mcm","clk":"992879819","pt":1580532464102,"mc":[{"id":"1.168133548","rc":[{"batl":[[2,7,10]],"ltp":6.0,"tv":153.67,"id":17352128}]}]}
{"op":"mcm","clk":"992880177","pt":1580532472887,"mc":[{"id":"1.168133548","rc":[{"batl":[[0,6.4,7.69],[1,7,10],[2,7.2,27]],"ltp":6.0,"tv":153.67,"id":17352128}]}]}
{"op":"mcm","clk":"992889867","pt":1580532701892,"mc":[{"id":"1.168133548","rc":[{"trd":[[9.6,8.91],[9.8,26.8]],"batb":[[0,9.6,10.18],[1,9.2,4.4],[2,9,2]],"ltp":9.6,"tv":195.85,"id":10616006}],"tv":1761.24}]}
{"op":"mcm","clk":"993028492","pt":1580535292116,"mc":[{"id":"1.168133548","rc":[{"trd":[[12,6.62],[12.5,5.38]],"batb":[[0,12,1.73],[1,11.5,1.53],[2,8.8,2.01]],"ltp":12.0,"tv":58.83,"id":8429550}],"tv":1769.24}]}
{"op":"mcm","clk":"993029013","pt":1580535302899,"mc":[{"id":"1.168133548","rc":[{"batb":[[2,8.8,2.34]],"ltp":12.0,"tv":58.83,"id":8429550}]}]}
{"op":"mcm","clk":"993047227","pt":1580535488736,"mc":[{"id":"1.168133548","rc":[{"batb":[[0,9.8,1.62],[1,9.6,10.18],[2,9.2,4.4]],"ltp":9.6,"tv":195.85,"id":10616006},{"batb":[[0,5.9,2.7],[1,5.8,6.74],[2,5.7,3.09]],"ltp":6.0,"tv":153.67,"id":17352128}]}]}
{"op":"mcm","clk":"993106480","pt":1580536620528,"mc":[{"id":"1.168133548","rc":[{"batl":[[2,11.5,41]],"ltp":9.6,"tv":195.85,"id":10616006}]}]}
{"op":"mcm","clk":"993116107","pt":1580536820475,"mc":[{"id":"1.168133548","rc":[{"batb":[[0,5.9,2.92],[1,5.8,4.07],[2,5.6,6.71]],"ltp":6.0,"tv":133.17,"id":8231803},{"batb":[[0,9.8,3.62]],"ltp":9.6,"tv":195.85,"id":10616006},{"batl":[[2,16,8]],"ltp":9.0,"tv":186.62,"id":15608820}]}]}
{"op":"mcm","clk":"993116171","pt":1580536821560,"mc":[{"id":"1.168133548","rc":[{"batb":[[1,15.5,2.86],[2,14,1.26]],"ltp":16.0,"tv":16.69,"id":9001159}]}]}
{"op":"mcm","clk":"993116599","pt":1580536831794,"mc":[{"id":"1.168133548","rc":[{"batb":[[1,16,6.95],[2,15.5,1.91]],"ltp":16.0,"tv":16.69,"id":9001159}]}]}
{"op":"mcm","clk":"993116674","pt":1580536833388,"mc":[{"id":"1.168133548","rc":[{"batb":[[0,11.5,1.53],[1,9,1.73]],"ltp":12.0,"tv":58.83,"id":8429550},{"batb":[[0,6,2.87],[1,5.9,6.47]],"ltp":6.0,"tv":153.67,"id":17352128}]}]}
{"op":"mcm","clk":"993116694","pt":1580536833905,"mc":[{"id":"1.168133548","rc":[{"batb":[[2,8.8,2.91]],"ltp":12.0,"tv":58.83,"id":8429550}]}]}
{"op":"mcm","clk":"993116806","pt":1580536836479,"mc":[{"id":"1.168133548","rc":[{"batb":[[1,9,8.77],[2,8.8,2.34]],"ltp":12.0,"tv":58.83,"id":8429550},{"batb":[[0,17,1.02],[1,16.5,5.18],[2,16,6]],"ltp":16.0,"tv":16.69,"id":9001159}]}]}
{"op":"mcm","clk":"993116832","pt":1580536837094,"mc":[{"id":"1.168133548","rc":[{"batb":[[1,9,9.31]],"ltp":12.0,"tv":58.83,"id":8429550},{"batb":[[0,5.9,4.92],[1,5.8,2.07]],"ltp":6.0,"tv":133.17,"id":8231803}]}]}
{"op":"mcm","clk":"993116882","pt":1580536838275,"mc":[{"id":"1.168133548","rc":[{"batb":[[1,9.2,4.58],[2,9,8.77]],"ltp":12.0,"tv":58.83,"id":8429550}]}]}
{"op":"mcm","clk":"993116971","pt":1580536840481,"mc":[{"id":"1.168133548","rc":[{"batb":[[1,9.4,2.13],[2,9.2,4.58]],"ltp":12.0,"tv":58.83,"id":8429550}]}]}
{"op":"mcm","clk":"993117062","pt":1580536842080,"mc":[{"id":"1.168133548","rc":[{"batl":[[2,16,8.32]],"ltp":9.0,"tv":186.62,"id":15608820}]}]}
{"op":"mcm","clk":"993117153","pt":1580536844912,"mc":[{"id":"1.168133548","rc":[{"batl":[[1,6.8,102.79]],"ltp":6.0,"tv":133.17,"id":8231803},{"batb":[[0,10,2],[1,9.8,3.62],[2,9.6,10.18]],"ltp":9.6,"tv":195.85,"id":10616006}]}]}
{"op":"mcm","clk":"993117288","pt":1580536848614,"mc":[{"id":"1.168133548","rc":[{"batb":[[2,9.2,6.49]],"ltp":12.0,"tv":58.83,"id":8429550},{"batb":[[1,16.5,6.25]],"ltp":16.0,"tv":16.69,"id":9001159}]}]}
{"op":"mcm","clk":"993117351","pt":1580536850588,"mc":[{"id":"1.168133548","rc":[{"batb":[[1,9.4,8.87]],"ltp":12.0,"tv":58.83,"id":8429550}]}]}
{"op":"mcm","clk":"993117644","pt":1580536857329,"mc":[{"id":"1.168133548","rc":[{"batb":[[1,9.6,3.86],[2,9.4,8.87]],"ltp":12.0,"tv":58.83,"id":8429550}]}]}
{"op":"mcm","clk":"993117870","pt":1580536862550,"mc":[{"id":"1.168133548","rc":[{"batb":[[1,9.6,4.17]],"ltp":12.0,"tv":58.83,"id":8429550}]}]}
{"op":"mcm","clk":"993118005","pt":1580536864512,"mc":[{"id":"1.168133548","rc":[{"batb":[[1,9.8,6.46],[2,9.6,4.17]],"ltp":12.0,"tv":58.83,"id":8429550}]}]}
{"op":"mcm","clk":"993118526","pt":1580536875546,"mc":[{"id":"1.168133548","rc":[{"batb":[[1,9.8,8.26]],"ltp":12.0,"tv":58.83,"id":8429550}]}]}
{"op":"mcm","clk":"993118572","pt":1580536876525,"mc":[{"id":"1.168133548","rc":[{"batb":[[2,9.4,2.44]],"ltp":12.0,"tv":58.83,"id":8429550}]}]}
{"op":"mcm","clk":"993118823","pt":1580536882247,"mc":[{"id":"1.168133548","rc":[{"batb":[[1,10,1.73],[2,9.8,8.26]],"ltp":12.0,"tv":58.83,"id":8429550},{"batb":[[0,6,6.65],[1,5.9,2.7]],"ltp":6.0,"tv":153.67,"id":17352128}]}]}
{"op":"mcm","clk":"993119282","pt":1580536893477,"mc":[{"id":"1.168133548","rc":[{"batb":[[1,10,8.06],[2,9.8,1.8]],"ltp":12.0,"tv":58.83,"id":8429550}]}]}
{"op":"mcm","clk":"993119829","pt":1580536901344,"mc":[{"id":"1.168133548","rc":[{"trd":[[10.5,8.9]],"batl":[[0,11,3.23],[1,11.5,41],[2,13.5,3]],"ltp":10.5,"tv":200.99,"id":10616006}],"tv":1774.38}]}
{"op":"mcm","clk":"993120439","pt":1580536915150,"mc":[{"id":"1.168133548","rc":[{"batl":[[2,15.5,3.36]],"ltp":9.0,"tv":186.62,"id":15608820}]}]}
{"op":"mcm","clk":"993120525","pt":1580536917046,"mc":[{"id":"1.168133548","rc":[{"batb":[[0,10.5,2],[1,10,2],[2,9.8,3.62]],"ltp":10.5,"tv":200.99,"id":10616006}]}]}
{"op":"mcm","clk":"993120756","pt":1580536922498,"mc":[{"id":"1.168133548","rc":[{"batb":[[1,10,1.73]],"ltp":12.0,"tv":58.83,"id":8429550}]}]}
{"op":"mcm","clk":"993120787","pt":1580536923267,"mc":[{"id":"1.168133548","rc":[{"batb":[[1,10,2.02]],"ltp":12.0,"tv":58.83,"id":8429550}]}]}
{"op":"mcm","clk":"993120892","pt":1580536925271,"mc":[{"id":"1.168133548","rc":[{"batl":[[2,15,8]],"ltp":9.0,"tv":186.62,"id":15608820}]}]}
{"op":"mcm","clk":"993120954","pt":1580536926562,"mc":[{"id":"1.168133548","rc":[{"batb":[[2,8.6,12.17]],"ltp":12.0,"tv":58.83,"id":8429550}]}]}
{"op":"mcm","clk":"993121112","pt":1580536929186,"mc":[{"id":"1.168133548","rc":[{"batb":[[0,9.2,1.98],[1,9,8.8],[2,8.8,5.04]],"ltp":9.0,"tv":186.62,"id":15608820}]}]}
{"op":"mcm","clk":"993121337","pt":1580536933087,"mc":[{"id":"1.168133548","rc":[{"batl":[[2,15,8.34]],"ltp":9.0,"tv":186.62,"id":15608820}]}]}
{"op":"mcm","clk":"993121445","pt":1580536935394,"mc":[{"id":"1.168133548","rc":[{"batb":[[2,8.8,2.55]],"ltp":12.0,"tv":58.83,"id":8429550}]}]}
{"op":"mcm","clk":"993121915","pt":1580536947592,"mc":[{"id":"1.168133548","rc":[{"batb":[[1,9,7.04]],"ltp":9.0,"tv":186.62,"id":15608820}]}]}
{"op":"mcm","clk":"993122331","pt":1580536957524,"mc":[{"id":"1.168133548","rc":[{"batl":[[2,14.5,3.39]],"ltp":9.0,"tv":186.62,"id":15608820}]}]}
{"op":"mcm","clk":"993122922","pt":1580536972116,"mc":[{"id":"1.168133548","rc":[{"batl":[[2,14,8]],"ltp":9.0,"tv":186.62,"id":15608820}]}]}
{"op":"mcm","clk":"993123118","pt":1580536977852,"mc":[{"id":"1.168133548","rc":[{"trd":[[5.9,128.93]],"batb":[[0,5.8,2.99]],"batl":[[0,6,8.29],[1,6.4,32.16],[2,6.8,1.25]],"ltp":5.9,"tv":888.07,"id":9417341}],"tv":1784.34}]}
{"op":"mcm","clk":"993123195","pt":1580536979846,"mc":[{"id":"1.168133548","rc":[{"batb":[[2,5.5,16.85]],"ltp":5.9,"tv":888.07,"id":9417341}]}]}
{"op":"mcm","clk":"993123297","pt":1580536982417,"mc":[{"id":"1.168133548","rc":[{"batb":[[1,10,1.73]],"ltp":12.0,"tv":58.83,"id":8429550}]}]}
{"op":"mcm","clk":"993123337","pt":1580536983443,"mc":[{"id":"1.168133548","rc":[{"batb":[[2,8.8,2.88]],"ltp":12.0,"tv":58.83,"id":8429550}]}]}
{"op":"mcm","clk":"993123543","pt":1580536989967,"mc":[{"id":"1.168133548","rc":[{"batb":[[0,5.8,2.97]],"ltp":5.9,"tv":888.07,"id":9417341}]}]}
{"op":"mcm","clk":"993124058","pt":1580537003244,"mc":[{"id":"1.168133548","rc":[{"batl":[[2,13.5,3.03]],"ltp":9.0,"tv":186.62,"id":15608820}]}]}
{"op":"mcm","clk":"993124437","pt":1580537012163,"mc":[{"id":"1.168133548","rc":[{"batl":[[1,12.5,2.97],[2,13,2]],"ltp":9.0,"tv":186.62,"id":15608820}]}]}
{"op":"mcm","clk":"993124800","pt":1580537020489,"mc":[{"id":"1.168133548","rc":[{"batl":[[1,12.5,11.39]],"ltp":9.0,"tv":186.62,"id":15608820}]}]}
{"op":"mcm","clk":"993124920","pt":1580537024475,"mc":[{"id":"1.168133548","rc":[{"batb":[[1,9,2.61],[2,8.8,2.01]],"ltp":12.0,"tv":58.83,"id":8429550}]}]}
{"op":"mcm","clk":"993124926","pt":1580537024681,"mc":[{"id":"1.168133548","rc":[{"batb":[[2,8.8,3.97]],"ltp":12.0,"tv":58.83,"id":8429550}]}]}
{"op":"mcm","clk":"993125212","pt":1580537032419,"mc":[{"id":"1.168133548","rc":[{"batb":[[1,9.2,4.58],[2,9,2.07]],"ltp":12.0,"tv":58.83,"id":8429550},{"batl":[[1,11.5,3.23],[2,12.5,8.42]],"ltp":9.0,"tv":186.62,"id":15608820}]}]}
{"op":"mcm","clk":"993125220","pt":1580537032623,"mc":[{"id":"1.168133548","rc":[{"batb":[[1,9.4,1.83],[2,9.2,4.58]],"ltp":12.0,"tv":58.83,"id":8429550}]}]}
{"op":"mcm","clk":"993125361","pt":1580537036420,"mc":[{"id":"1.168133548","rc":[{"batb":[[1,9.4,8.57]],"ltp":12.0,"tv":58.83,"id":8429550}]}]}
{"op":"mcm","clk":"993125484","pt":1580537039299,"mc":[{"id":"1.168133548","rc":[{"batl":[[2,12,3.8]],"ltp":9.0,"tv":186.62,"id":15608820}]}]}
{"op":"mcm","clk":"993125623","pt":1580537042830,"mc":[{"id":"1.168133548","rc":[{"batb":[[1,9.4,8.88]],"ltp":12.0,"tv":58.83,"id":8429550}]}]}
{"op":"mcm","clk":"993125919","pt":1580537051133,"mc":[{"id":"1.168133548","rc":[{"batb":[[2,9,2.27]],"ltp":12.0,"tv":58.83,"id":8429550}]}]}
{"op":"mcm","clk":"993126191","pt":1580537059004,"mc":[{"id":"1.168133548","rc":[{"batl":[[1,11.5,11.23]],"ltp":9.0,"tv":186.62,"id":15608820}]}]}
{"op":"mcm","clk":"993126602","pt":1580537071823,"mc":[{"id":"1.168133548","rc":[{"batb":[[1,9.6,2.04],[2,9.4,8.57]],"ltp":12.0,"tv":58.83,"id":8429550}]}]}
{"op":"mcm","clk":"993126698","pt":1580537073362,"mc":[{"id":"1.168133548","rc":[{"batb":[[1,9.8,1.76],[2,9.6,3.88]],"ltp":12.0,"tv":58.83,"id":8429550}]}]}
{"op":"mcm","clk":"993126756","pt":1580537075161,"mc":[{"id":"1.168133548","rc":[{"batl":[[1,11,4.23],[2,11.5,11.23]],"ltp":9.0,"tv":186.62,"id":15608820}]}]}
{"op":"mcm","clk":"993126890","pt":1580537079544,"mc":[{"id":"1.168133548","rc":[{"batb":[[1,9.8,8.22]],"ltp":12.0,"tv":58.83,"id":8429550}]}]}
{"op":"mcm","clk":"993127296","pt":1580537090240,"mc":[{"id":"1.168133548","rc":[{"batl":[[2,11.5,8]],"ltp":9.0,"tv":186.62,"id":15608820}]}]}
{"op":"mcm","clk":"993127795","pt":1580537102566,"mc":[{"id":"1.168133548","rc":[{"batb":[[2,9.6,3.57]],"ltp":12.0,"tv":58.83,"id":8429550}]}]}
{"op":"mcm","clk":"993127812","pt":1580537102876,"mc":[{"id":"1.168133548","rc":[{"batb":[[1,9.8,8.52]],"ltp":12.0,"tv":58.83,"id":8429550}]}]}
{"op":"mcm","clk":"993128091","pt":1580537108351,"mc":[{"id":"1.168133548","rc":[{"batb":[[1,10.5,1.9],[2,9.8,8.52]],"ltp":12.0,"tv":58.83,"id":8429550},{"batb":[[0,9.4,1.68],[1,9.2,1.98],[2,9,7.04]],"ltp":9.0,"tv":186.62,"id":15608820}]}]}
{"op":"mcm","clk":"993128752","pt":1580537122383,"mc":[{"id":"1.168133548","rc":[{"batb":[[1,10.5,7.93],[2,10,2.07]],"ltp":12.0,"tv":58.83,"id":8429550},{"batb":[[2,8.8,5.04]],"ltp":9.0,"tv":186.62,"id":15608820}]}]}
{"op":"mcm","clk":"993128790","pt":1580537123262,"mc":[{"id":"1.168133548","rc":[{"batb":[[1,11,1.56],[2,10.5,7.93]],"ltp":12.0,"tv":58.83,"id":8429550},{"trd":[[11,25.5]],"batl":[[0,11.5,41],[1,13.5,3],[2,15.5,8]],"ltp":11.0,"tv":207.45,"id":10616006}],"tv":1790.8}]}
{"op":"mcm","clk":"993129118","pt":1580537130371,"mc":[{"id":"1.168133548","rc":[{"batb":[[1,11,3.17]],"ltp":12.0,"tv":58.83,"id":8429550}]}]}
{"op":"mcm","clk":"993129504","pt":1580537137291,"mc":[{"id":"1.168133548","rc":[{"batb":[[2,10.5,1.9]],"ltp":12.0,"tv":58.83,"id":8429550}]}]}
{"op":"mcm","clk":"993129552","pt":1580537138321,"mc":[{"id":"1.168133548","rc":[{"batb":[[1,11,1.56]],"ltp":12.0,"tv":58.83,"id":8429550}]}]}
{"op":"mcm","clk":"993130045","pt":1580537149504,"mc":[{"id":"1.168133548","rc":[{"batl":[[2,15,1.37]],"ltp":11.0,"tv":207.45,"id":10616006}]}]}
{"op":"mcm","clk":"993130651","pt":1580537163275,"mc":[{"id":"1.168133548","rc":[{"batb":[[2,9.6,2.03]],"ltp":12.0,"tv":58.83,"id":8429550}]}]}
{"op":"mcm","clk":"993130710","pt":1580537164565,"mc":[{"id":"1.168133548","rc":[{"batb":[[0,11.5,3.26],[2,8.8,2.85]],"ltp":12.0,"tv":58.83,"id":8429550},{"batb":[[0,9.4,3.66],[1,8.8,5.04],[2,8.6,11.63]],"ltp":9.0,"tv":186.62,"id":15608820}]}]}
{"op":"mcm","clk":"993133255","pt":1580537222432,"mc":[{"id":"1.168133548","rc":[{"batb":[[2,8.8,2.88]],"ltp":12.0,"tv":58.83,"id":8429550}]}]}
{"op":"mcm","clk":"993144426","pt":1580537258170,"mc":[{"id":"1.168133548","rc":[{"batb":[[0,9.4,1.68],[1,9,1.98],[2,8.8,5.04]],"ltp":9.0,"tv":186.62,"id":15608820}]}]}
{"op":"mcm","clk":"993144735","pt":1580537266345,"mc":[{"id":"1.168133548","rc":[{"batb":[[1,9,9.02]],"ltp":9.0,"tv":186.62,"id":15608820}]}]}
{"op":"mcm","clk":"993144889","pt":1580537270561,"mc":[{"id":"1.168133548","rc":[{"batb":[[0,9,9.02],[1,8.8,5.04],[2,8.6,11.63]],"ltp":9.0,"tv":186.62,"id":15608820}]}]}
{"op":"mcm","clk":"993144901","pt":1580537270767,"mc":[{"id":"1.168133548","rc":[{"batb":[[0,9.2,1.72],[1,9,9.02],[2,8.8,5.04]],"ltp":9.0,"tv":186.62,"id":15608820}]}]}
{"op":"mcm","clk":"993145003","pt":1580537273642,"mc":[{"id":"1.168133548","rc":[{"batb":[[1,11.5,2.75],[2,11,4.6]],"ltp":11.0,"tv":26.11,"id":9193530}]}]}
{"op":"mcm","clk":"993148033","pt":1580537350980,"mc":[{"id":"1.168133548","rc":[{"batb":[[0,9.2,3.7],[1,9,7.04]],"ltp":9.0,"tv":186.62,"id":15608820}]}]}
{"op":"mcm","clk":"993148083","pt":1580537352472,"mc":[{"id":"1.168133548","rc":[{"batb":[[1,8.8,5.04],[2,8.6,11.63]],"ltp":9.0,"tv":186.62,"id":15608820}]}]}
{"op":"mcm","clk":"993151741","pt":1580537442424,"mc":[{"id":"1.168133548","rc":[{"batb":[[0,11,2],[1,10.5,2],[2,10,2]],"ltp":11.0,"tv":207.45,"id":10616006}]}]}
{"op":"mcm","clk":"993152179","pt":1580537452423,"mc":[{"id":"1.168133548","rc":[{"batb":[[1,16.5,3.35]],"ltp":16.0,"tv":16.69,"id":9001159}]}]}
{"op":"mcm","clk":"993152278","pt":1580537455105,"mc":[{"id":"1.168133548","rc":[{"batb":[[1,16.5,2.28]],"ltp":16.0,"tv":16.69,"id":9001159}]}]}
{"op":"mcm","clk":"993152607","pt":1580537463050,"mc":[{"id":"1.168133548","rc":[{"batb":[[2,16,7.1]],"ltp":16.0,"tv":16.69,"id":9001159}]}]}
{"op":"mcm","clk":"993153013","pt":1580537472343,"mc":[{"id":"1.168133548","rc":[{"batl":[[1,6.8,100]],"ltp":6.0,"tv":133.17,"id":8231803}]}]}
{"op":"mcm","clk":"993155957","pt":1580537539784,"mc":[{"id":"1.168133548","rc":[{"trd":[[5.8,232.11]],"batb":[[0,5.7,53.26],[1,5.5,16.85],[2,5.2,2]],"ltp":5.8,"tv":893.07,"id":9417341}],"tv":1795.8}]}
{"op":"mcm","clk":"993156148","pt":1580537543091,"mc":[{"id":"1.168133548","rc":[{"batb":[[1,5.5,13.85]],"ltp":5.8,"tv":893.07,"id":9417341}]}]}
{"op":"mcm","clk":"993156545","pt":1580537552500,"mc":[{"id":"1.168133548","rc":[{"batb":[[1,16.5,5.18]],"ltp":16.0,"tv":16.69,"id":9001159}]}]}
{"op":"mcm","clk":"993157453","pt":1580537574045,"mc":[{"id":"1.168133548","rc":[{"trd":[[5.9,12.56]],"batb":[[0,5.9,2.41]],"ltp":5.9,"tv":138.17,"id":8231803}],"tv":1800.81}]}
{"op":"mcm","clk":"993157566","pt":1580537576767,"mc":[{"id":"1.168133548","rc":[{"batb":[[0,9.4,1.83],[1,9.2,3.7],[2,8.8,5.04]],"ltp":9.0,"tv":186.62,"id":15608820}]}]}
{"op":"mcm","clk":"993157770","pt":1580537581062,"mc":[{"id":"1.168133548","rc":[{"batb":[[0,9.4,3.81],[1,9.2,1.72]],"ltp":9.0,"tv":186.62,"id":15608820}]}]}
{"op":"mcm","clk":"993160081","pt":1580537630526,"mc":[{"id":"1.168133548","rc":[{"batl":[[1,6.8,102.79]],"ltp":5.9,"tv":138.17,"id":8231803}]}]}
{"op":"mcm","clk":"993161662","pt":1580537669453,"mc":[{"id":"1.168133548","rc":[{"trd":[[11.5,30.8]],"batl":[[0,11.5,39]],"ltp":11.5,"tv":211.45,"id":10616006}],"tv":1804.81}]}
{"op":"mcm","clk":"993162168","pt":1580537683478,"mc":[{"id":"1.168133548","rc":[{"trd":[[11.5,34.8]],"batl":[[0,11.5,37]],"ltp":11.5,"tv":215.45,"id":10616006}],"tv":1808.81}]}
{"op":"mcm","clk":"993162442","pt":1580537691151,"mc":[{"id":"1.168133548","rc":[{"trd":[[11.5,38.8]],"batl":[[0,11.5,35]],"ltp":11.5,"tv":219.45,"id":10616006}],"tv":1812.81}]}
{"op":"mcm","clk":"993212310","pt":1580538630542,"mc":[{"id":"1.168133548","rc":[{"batl":[[0,50,8.54],[1,55,3.12],[2,60,9]],"ltp":11.0,"tv":26.11,"id":9193530}]}]}
{"op":"mcm","clk":"993212540","pt":1580538636040,"mc":[{"id":"1.168133548","rc":[{"batl":[[0,48,3.23],[1,50,8.34],[2,60,9.09]],"ltp":11.0,"tv":26.11,"id":9193530}]}]}
{"op":"mcm","clk":"993212937","pt":1580538644544,"mc":[{"id":"1.168133548","rc":[{"batl":[[2,60,9]],"ltp":11.0,"tv":26.11,"id":9193530}]}]}
{"op":"mcm","clk":"993212969","pt":1580538645113,"mc":[{"id":"1.168133548","rc":[{"batl":[[0,48,3.34]],"ltp":11.0,"tv":26.11,"id":9193530}]}]}
{"op":"mcm","clk":"993213194","pt":1580538651343,"mc":[{"id":"1.168133548","rc":[{"batl":[[1,50,7.6]],"ltp":11.0,"tv":26.11,"id":9193530}]}]}
{"op":"mcm","clk":"993213223","pt":1580538652063,"mc":[{"id":"1.168133548","rc":[{"batl":[[0,46,1.12],[1,48,3.03],[2,50,7.6]],"ltp":11.0,"tv":26.11,"id":9193530}]}]}
{"op":"mcm","clk":"993222068","pt":1580538856519,"mc":[{"id":"1.168133548","rc":[{"batl":[[2,60,9]],"ltp":11.0,"tv":26.11,"id":9193530}]}]}
{"op":"mcm","clk":"993222695","pt":1580538870727,"mc":[{"id":"1.168133548","rc":[{"batl":[[0,44,7.8],[1,48,3.95]],"ltp":11.0,"tv":26.11,"id":9193530}]}]}
{"op":"mcm","clk":"993223206","pt":1580538882103,"mc":[{"id":"1.168133548","rc":[{"batl":[[1,48,3.14]],"ltp":11.0,"tv":26.11,"id":9193530}]}]}
{"op":"mcm","clk":"993223290","pt":1580538884001,"mc":[{"id":"1.168133548","rc":[{"batl":[[0,44,7.92],[1,48,3.03]],"ltp":11.0,"tv":26.11,"id":9193530}]}]}
{"op":"mcm","clk":"993223505","pt":1580538889357,"mc":[{"id":"1.168133548","rc":[{"batl":[[0,42,3.35],[1,44,7.6]],"ltp":11.0,"tv":26.11,"id":9193530}]}]}
{"op":"mcm","clk":"993224049","pt":1580538902556,"mc":[{"id":"1.168133548","rc":[{"batl":[[0,40,1.13],[1,42,3.15],[2,44,7.6]],"ltp":11.0,"tv":26.11,"id":9193530}]}]}
{"op":"mcm","clk":"993226175","pt":1580538960052,"mc":[{"id":"1.168133548","rc":[{"batl":[[0,10,6.87]],"ltp":9.0,"tv":186.62,"id":15608820}]}]}
{"op":"mcm","clk":"993226459","pt":1580538968042,"mc":[{"id":"1.168133548","rc":[{"batl":[[1,10.5,8],[2,11,4.23]],"ltp":9.0,"tv":186.62,"id":15608820}]}]}
{"op":"mcm","clk":"993227161","pt":1580538985550,"mc":[{"id":"1.168133548","rc":[{"batb":[[2,8.8,2.01]],"batl":[[2,11,2.27]],"ltp":9.0,"tv":186.62,"id":15608820}]}]}
{"op":"mcm","clk":"993227717","pt":1580539000500,"mc":[{"id":"1.168133548","rc":[{"trd":[[11.5,42.8]],"batl":[[0,11.5,33]],"ltp":11.5,"tv":223.45,"id":10616006}],"tv":1816.81}]}
{"op":"mcm","clk":"993228461","pt":1580539018492,"mc":[{"id":"1.168133548","rc":[{"batl":[[2,13,2.42]],"ltp":9.0,"tv":186.62,"id":15608820}]}]}
{"op":"mcm","clk":"993228466","pt":1580539018598,"mc":[{"id":"1.168133548","rc":[{"batl":[[0,9.8,2.55],[1,10,6.87],[2,10.5,8]],"ltp":9.0,"tv":186.62,"id":15608820}]}]}
{"op":"mcm","clk":"993229212","pt":1580539033843,"mc":[{"id":"1.168133548","rc":[{"batl":[[0,9.8,10.55],[2,13,2.42]],"ltp":9.0,"tv":186.62,"id":15608820}]}]}
{"op":"mcm","clk":"993240964","pt":1580539088313,"mc":[{"id":"1.168133548","rc":[{"trd":[[10,16.22],[10.5,12.9],[11,29.5]],"batb":[[0,9.8,1.62],[1,9.6,10.18],[2,9.2,4.4]],"batl":[[0,10,94],[1,11.5,33],[2,13.5,3]],"ltp":10.0,"tv":235.45,"id":10616006}],"tv":1828.81}]}
{"op":"mcm","clk":"993241300","pt":1580539096729,"mc":[{"id":"1.168133548","rc":[{"batl":[[2,60,9]],"ltp":11.0,"tv":26.11,"id":9193530}]}]}
{"op":"mcm","clk":"993241390","pt":1580539098699,"mc":[{"id":"1.168133548","rc":[{"batb":[[0,9.8,2.91]],"ltp":10.0,"tv":235.45,"id":10616006}]}]}
{"op":"mcm","clk":"993242020","pt":1580539114526,"mc":[{"id":"1.168133548","rc":[{"batl":[[0,38,7.8]],"ltp":11.0,"tv":26.11,"id":9193530}]}]}
{"op":"mcm","clk":"993242071","pt":1580539116539,"mc":[{"id":"1.168133548","rc":[{"batl":[[0,38,7.6]],"ltp":11.0,"tv":26.11,"id":9193530}]}]}
{"op":"mcm","clk":"993242078","pt":1580539116949,"mc":[{"id":"1.168133548","rc":[{"batl":[[0,38,7.8]],"ltp":11.0,"tv":26.11,"id":9193530}]}]}
{"op":"mcm","clk":"993242319","pt":1580539123539,"mc":[{"id":"1.168133548","rc":[{"batl":[[1,42,3.03]],"ltp":11.0,"tv":26.11,"id":9193530}]}]}
{"op":"mcm","clk":"993242352","pt":1580539124466,"mc":[{"id":"1.168133548","rc":[{"batl":[[0,38,7.94]],"ltp":11.0,"tv":26.11,"id":9193530}]}]}
{"op":"mcm","clk":"993243088","pt":1580539144855,"mc":[{"id":"1.168133548","rc":[{"batl":[[0,36,3.37],[1,38,7.6]],"ltp":11.0,"tv":26.11,"id":9193530}]}]}
{"op":"mcm","clk":"993243437","pt":1580539152767,"mc":[{"id":"1.168133548","rc":[{"batl":[[0,34,1.29],[1,36,3.17],[2,38,7.6]],"ltp":11.0,"tv":26.11,"id":9193530}]}]}
{"op":"mcm","clk":"993248761","pt":1580539281173,"mc":[{"id":"1.168133548","rc":[{"trd":[[10,21.32]],"batl":[[0,10,91.45]],"ltp":10.0,"tv":240.55,"id":10616006}],"tv":1833.91}]}
{"op":"mcm","clk":"993248810","pt":1580539282098,"mc":[{"id":"1.168133548","rc":[{"trd":[[10,54.38]],"batl":[[0,10,74.92]],"ltp":10.0,"tv":273.61,"id":10616006}],"tv":1866.97}]}
{"op":"mcm","clk":"993250068","pt":1580539311293,"mc":[{"id":"1.168133548","rc":[{"trd":[[10,65.4]],"batl":[[0,10,69.41]],"ltp":10.0,"tv":284.63,"id":10616006}],"tv":1877.99}]}
{"op":"mcm","clk":"993251346","pt":1580539339525,"mc":[{"id":"1.168133548","rc":[{"batl":[[2,60,9]],"ltp":11.0,"tv":26.11,"id":9193530}]}]}
{"op":"mcm","clk":"993252241","pt":1580539356881,"mc":[{"id":"1.168133548","rc":[{"batl":[[0,32,7.8],[1,34,1.09],[2,36,3.17]],"ltp":11.0,"tv":26.11,"id":9193530}]}]}
{"op":"mcm","clk":"993252524","pt":1580539364569,"mc":[{"id":"1.168133548","rc":[{"batl":[[1,36,3.17],[2,60,9]],"ltp":11.0,"tv":26.11,"id":9193530}]}]}
{"op":"mcm","clk":"993252574","pt":1580539365545,"mc":[{"id":"1.168133548","rc":[{"batl":[[0,32,7.97],[1,36,3.03]],"ltp":11.0,"tv":26.11,"id":9193530}]}]}
{"op":"mcm","clk":"993252644","pt":1580539367551,"mc":[{"id":"1.168133548","rc":[{"batb":[[0,17,5],[1,16.5,4],[2,11.5,2.75]],"batl":[[0,30,3.4],[1,32,7.6]],"ltp":11.0,"tv":26.11,"id":9193530}]}]}
{"op":"mcm","clk":"993252876","pt":1580539372273,"mc":[{"id":"1.168133548","rc":[{"trd":[[10,67.54]],"batl":[[0,10,68.34],[1,11,1],[2,11.5,33]],"ltp":10.0,"tv":286.77,"id":10616006}],"tv":1880.13}]}
{"op":"mcm","clk":"993253215","pt":1580539380480,"mc":[{"id":"1.168133548","rc":[{"batb":[[2,12,2.22]],"ltp":11.0,"tv":26.11,"id":9193530}]}]}
{"op":"mcm","clk":"993253306","pt":1580539382184,"mc":[{"id":"1.168133548","rc":[{"batb":[[0,17.5,2.97],[1,17,4.01],[2,16.5,2.02]],"ltp":11.0,"tv":26.11,"id":9193530}]}]}
{"op":"mcm","clk":"993253381","pt":1580539383675,"mc":[{"id":"1.168133548","rc":[{"batl":[[0,29,1.48],[1,30,3.2],[2,32,7.6]],"ltp":11.0,"tv":26.11,"id":9193530}]}]}
{"op":"mcm","clk":"993253484","pt":1580539385994,"mc":[{"id":"1.168133548","rc":[{"batb":[[0,9.8,1.62]],"ltp":10.0,"tv":286.77,"id":10616006}]}]}
{"op":"mcm","clk":"993253949","pt":1580539396502,"mc":[{"id":"1.168133548","rc":[{"batb":[[0,17.5,6.58],[1,16.5,2.31],[2,12,2.22]],"ltp":11.0,"tv":26.11,"id":9193530}]}]}
{"op":"mcm","clk":"993255015","pt":1580539423819,"mc":[{"id":"1.168133548","rc":[{"batb":[[1,17,2.29],[2,16.5,2.02]],"ltp":11.0,"tv":26.11,"id":9193530}]}]}
{"op":"mcm","clk":"993255529","pt":1580539434861,"mc":[{"id":"1.168133548","rc":[{"batb":[[2,16.5,3.08]],"ltp":11.0,"tv":26.11,"id":9193530}]}]}
{"op":"mcm","clk":"993255857","pt":1580539441973,"mc":[{"id":"1.168133548","rc":[{"batb":[[0,18,1.85],[1,17.5,6.58],[2,17,2.29]],"ltp":11.0,"tv":26.11,"id":9193530}]}]}
{"op":"mcm","clk":"993255938","pt":1580539443469,"mc":[{"id":"1.168133548","rc":[{"batl":[[1,6.8,100]],"ltp":5.9,"tv":138.17,"id":8231803}]}]}
{"op":"mcm","clk":"993256422","pt":1580539453194,"mc":[{"id":"1.168133548","rc":[{"batb":[[0,18.5,1.98],[1,18,1.85],[2,17.5,4.6]],"ltp":11.0,"tv":26.11,"id":9193530}]}]}
{"op":"mcm","clk":"993256768","pt":1580539460506,"mc":[{"id":"1.168133548","rc":[{"batb":[[0,9.6,10.18],[1,9.2,4.4],[2,9,5]],"ltp":10.0,"tv":286.77,"id":10616006}]}]}
{"op":"mcm","clk":"993257079","pt":1580539467504,"mc":[{"id":"1.168133548","rc":[{"batb":[[1,18,5.36],[2,17,3.27]],"ltp":11.0,"tv":26.11,"id":9193530}]}]}
{"op":"mcm","clk":"993258127","pt":1580539493503,"mc":[{"id":"1.168133548","rc":[{"trd":[[18.5,3.62]],"batb":[[0,18,5.54],[1,17,3.27],[2,16.5,1.07]],"batl":[[1,32,7.77],[2,60,9]],"ltp":18.5,"tv":29.72,"id":9193530}],"tv":1883.74}]}
{"op":"mcm","clk":"993258253","pt":1580539496435,"mc":[{"id":"1.168133548","rc":[{"batb":[[2,11,3.75]],"ltp":18.5,"tv":29.72,"id":9193530}]}]}
{"op":"mcm","clk":"993258676","pt":1580539504242,"mc":[{"id":"1.168133548","rc":[{"batb":[[2,11.5,2.29]],"ltp":18.5,"tv":29.72,"id":9193530}]}]}
{"op":"mcm","clk":"993259568","pt":1580539524546,"mc":[{"id":"1.168133548","rc":[{"batb":[[2,12,3.78]],"ltp":18.5,"tv":29.72,"id":9193530}]}]}
{"op":"mcm","clk":"993259610","pt":1580539525475,"mc":[{"id":"1.168133548","rc":[{"batb":[[2,12,6.57]],"batl":[[1,32,7.87]],"ltp":18.5,"tv":29.72,"id":9193530}]}]}
{"op":"mcm","clk":"993260067","pt":1580539536360,"mc":[{"id":"1.168133548","rc":[{"batb":[[2,12.5,2.16]],"ltp":18.5,"tv":29.72,"id":9193530}]}]}
{"op":"mcm","clk":"993260429","pt":1580539545549,"mc":[{"id":"1.168133548","rc":[{"batb":[[1,17,2.98]],"ltp":18.5,"tv":29.72,"id":9193530}]}]}
{"op":"mcm","clk":"993260448","pt":1580539545967,"mc":[{"id":"1.168133548","rc":[{"batb":[[0,18,5.81]],"ltp":18.5,"tv":29.72,"id":9193530}]}]}
{"op":"mcm","clk":"993262113","pt":1580539583417,"mc":[{"id":"1.168133548","rc":[{"batl":[[1,60,9.27],[2,95,2]],"ltp":18.5,"tv":29.72,"id":9193530}]}]}
{"op":"mcm","clk":"993262436","pt":1580539587980,"mc":[{"id":"1.168133548","rc":[{"batl":[[1,55,3.2],[2,60,9]],"ltp":18.5,"tv":29.72,"id":9193530}]}]}
{"op":"mcm","clk":"993262830","pt":1580539593507,"mc":[{"id":"1.168133548","rc":[{"batl":[[0,55,3.4],[1,60,9],[2,95,2]],"ltp":18.5,"tv":29.72,"id":9193530}]}]}
{"op":"mcm","clk":"993262855","pt":1580539594179,"mc":[{"id":"1.168133548","rc":[{"batl":[[0,50,1.11],[1,55,3.03],[2,60,9]],"ltp":18.5,"tv":29.72,"id":9193530}]}]}
{"op":"mcm","clk":"993262969","pt":1580539596907,"mc":[{"id":"1.168133548","rc":[{"batl":[[0,48,7.97],[1,55,3.77]],"ltp":18.5,"tv":29.72,"id":9193530}]}]}
{"op":"mcm","clk":"993263959","pt":1580539612524,"mc":[{"id":"1.168133548","rc":[{"batl":[[1,55,3.03]],"ltp":18.5,"tv":29.72,"id":9193530}]}]}
{"op":"mcm","clk":"993264444","pt":1580539619826,"mc":[{"id":"1.168133548","rc":[{"batl":[[0,46,3.4],[1,48,7.6]],"ltp":18.5,"tv":29.72,"id":9193530}]}]}
{"op":"mcm","clk":"993265119","pt":1580539632124,"mc":[{"id":"1.168133548","rc":[{"batl":[[0,44,1.21],[1,46,3.03],[2,48,7.6]],"ltp":18.5,"tv":29.72,"id":9193530}]}]}
{"op":"mcm","clk":"993268600","pt":1580539701484,"mc":[{"id":"1.168133548","rc":[{"trd":[[10,122.66]],"batl":[[0,10,40.78]],"ltp":10.0,"tv":341.89,"id":10616006}],"tv":1938.86}]}
{"op":"mcm","clk":"993269277","pt":1580539715502,"mc":[{"id":"1.168133548","rc":[{"batb":[[0,18.5,1.38],[1,18,5.36],[2,17,2]],"ltp":18.5,"tv":29.72,"id":9193530}]}]}
{"op":"mcm","clk":"993271754","pt":1580539770925,"mc":[{"id":"1.168133548","rc":[{"trd":[[16.5,2.76],[17,2.04]],"batb":[[0,16.5,3.8],[1,16,7.1],[2,15.5,1.91]],"ltp":16.5,"tv":21.49,"id":9001159}],"tv":1943.66}]}
{"op":"mcm","clk":"993273263","pt":1580539803297,"mc":[{"id":"1.168133548","rc":[{"trd":[[10,188.8]],"batl":[[0,10,7.71]],"ltp":10.0,"tv":408.03,"id":10616006}],"tv":2009.8}]}
{"op":"mcm","clk":"993273374","pt":1580539805681,"mc":[{"id":"1.168133548","rc":[{"trd":[[10,195.9]],"batl":[[0,10,4.16]],"ltp":10.0,"tv":415.13,"id":10616006}],"tv":2016.9}]}
{"op":"mcm","clk":"993274082","pt":1580539822789,"mc":[{"id":"1.168133548","rc":[{"batl":[[2,60,9]],"ltp":18.5,"tv":29.72,"id":9193530}]}]}
{"op":"mcm","clk":"993274788","pt":1580539839230,"mc":[{"id":"1.168133548","rc":[{"batl":[[0,42,7.97],[1,46,3.87]],"ltp":18.5,"tv":29.72,"id":9193530}]}]}
{"op":"mcm","clk":"993274826","pt":1580539840001,"mc":[{"id":"1.168133548","rc":[{"batl":[[0,40,3.4],[1,42,7.6],[2,60,9.84]],"ltp":18.5,"tv":29.72,"id":9193530}]}]}
{"op":"mcm","clk":"993274902","pt":1580539841340,"mc":[{"id":"1.168133548","rc":[{"batl":[[0,38,1.35],[1,40,3.03],[2,42,7.6]],"ltp":18.5,"tv":29.72,"id":9193530}]}]}
{"op":"mcm","clk":"993279788","pt":1580539951694,"mc":[{"id":"1.168133548","rc":[{"batb":[[1,5.7,3.09],[2,5.5,3]],"ltp":6.0,"tv":153.67,"id":17352128}]}]}
{"op":"mcm","clk":"993289848","pt":1580539956521,"mc":[{"id":"1.168133548","rc":[{"batb":[[1,5.5,3],[2,5.4,5.93]],"ltp":6.0,"tv":153.67,"id":17352128}]}]}
{"op":"mcm","clk":"993290161","pt":1580539965539,"mc":[{"id":"1.168133548","rc":[{"batb":[[1,5.5,6.21]],"ltp":6.0,"tv":153.67,"id":17352128}]}]}
{"op":"mcm","clk":"993295319","pt":1580540064832,"mc":[{"id":"1.168133548","rc":[{"batl":[[2,60,9]],"ltp":18.5,"tv":29.72,"id":9193530}]}]}
{"op":"mcm","clk":"993296106","pt":1580540081875,"mc":[{"id":"1.168133548","rc":[{"batl":[[0,36,7.97],[1,40,4.01]],"ltp":18.5,"tv":29.72,"id":9193530}]}]}
{"op":"mcm","clk":"993296419","pt":1580540088319,"mc":[{"id":"1.168133548","rc":[{"batl":[[1,40,3.03]],"ltp":18.5,"tv":29.72,"id":9193530}]}]}
{"op":"mcm","clk":"993296564","pt":1580540091003,"mc":[{"id":"1.168133548","rc":[{"batl":[[0,34,3.4],[1,36,7.6]],"ltp":18.5,"tv":29.72,"id":9193530}]}]}
{"op":"mcm","clk":"993297440","pt":1580540108348,"mc":[{"id":"1.168133548","rc":[{"batl":[[0,32,1.53],[1,34,3.03],[2,36,7.6]],"ltp":18.5,"tv":29.72,"id":9193530}]}]}
{"op":"mcm","clk":"993303693","pt":1580540226298,"mc":[{"id":"1.168133548","rc":[{"trd":[[6.4,27.64]],"batl":[[0,6.4,2.69]],"ltp":6.4,"tv":163.67,"id":17352128}],"tv":2026.9}]}
{"op":"mcm","clk":"993304098","pt":1580540233501,"mc":[{"id":"1.168133548","rc":[{"batb":[[0,5.8,17.27],[1,5.7,52.8],[2,5.5,13.85]],"ltp":5.8,"tv":893.07,"id":9417341},{"batb":[[0,9.8,3.36],[1,9.6,10.18],[2,9.2,4.4]],"ltp":10.0,"tv":415.13,"id":10616006},{"batb":[[0,16.5,7.16]],"ltp":16.5,"tv":21.49,"id":9001159}]}]}
{"op":"mcm","clk":"993304483","pt":1580540240413,"mc":[{"id":"1.168133548","rc":[{"trd":[[10,204.22]],"batb":[[0,10,13.84],[1,9.8,3.36],[2,9.6,10.18]],"batl":[[0,11,1],[1,11.5,33],[2,13.5,3]],"ltp":10.0,"tv":423.44,"id":10616006},{"batl":[[1,6.8,4],[2,7,10]],"ltp":6.4,"tv":163.67,"id":17352128}],"tv":2035.21}]}
{"op":"mcm","clk":"993304882","pt":1580540248321,"mc":[{"id":"1.168133548","rc":[{"batl":[[0,11,2.45]],"ltp":10.0,"tv":423.44,"id":10616006}]}]}
{"op":"mcm","clk":"993304945","pt":1580540249558,"mc":[{"id":"1.168133548","rc":[{"batl":[[1,6.6,3.21],[2,6.8,4]],"ltp":6.4,"tv":163.67,"id":17352128}]}]}
{"op":"mcm","clk":"993305567","pt":1580540263558,"mc":[{"id":"1.168133548","rc":[{"batl":[[2,7,10]],"ltp":6.4,"tv":163.67,"id":17352128}]}]}
{"op":"mcm","clk":"993305886","pt":1580540270355,"mc":[{"id":"1.168133548","rc":[{"batl":[[1,6.8,102.79]],"ltp":5.9,"tv":138.17,"id":8231803}]}]}
{"op":"mcm","clk":"993307453","pt":1580540307826,"mc":[{"id":"1.168133548","rc":[{"batl":[[2,60,9]],"ltp":18.5,"tv":29.72,"id":9193530}]}]}
{"op":"mcm","clk":"993308135","pt":1580540323960,"mc":[{"id":"1.168133548","rc":[{"batl":[[0,30,7.97],[1,32,1.16],[2,34,3.03]],"ltp":18.5,"tv":29.72,"id":9193530}]}]}
{"op":"mcm","clk":"993308613","pt":1580540336521,"mc":[{"id":"1.168133548","rc":[{"batl":[[1,34,3.03],[2,60,9]],"ltp":18.5,"tv":29.72,"id":9193530}]}]}
{"op":"mcm","clk":"993309027","pt":1580540345092,"mc":[{"id":"1.168133548","rc":[{"batl":[[0,29,3.23],[1,30,7.77]],"ltp":18.5,"tv":29.72,"id":9193530}]}]}
{"op":"mcm","clk":"993309515","pt":1580540355555,"mc":[{"id":"1.168133548","rc":[{"batl":[[0,28,1.53],[1,29,3.03],[2,30,7.77]],"ltp":18.5,"tv":29.72,"id":9193530}]}]}
{"op":"mcm","clk":"993312969","pt":1580540411226,"mc":[{"id":"1.168133548","rc":[{"batb":[[2,5.6,6.65]],"ltp":5.9,"tv":138.17,"id":8231803}]}]}
{"op":"mcm","clk":"993313679","pt":1580540424551,"mc":[{"id":"1.168133548","rc":[{"batl":[[0,10.5,1.18],[1,11,2.45],[2,11.5,33]],"ltp":10.0,"tv":423.44,"id":10616006}]}]}
{"op":"mcm","clk":"993314232","pt":1580540434559,"mc":[{"id":"1.168133548","rc":[{"trd":[[6,29.31]],"batb":[[0,6,3.65]],"ltp":6.0,"tv":169.67,"id":17352128}],"tv":2041.21}]}
{"op":"mcm","clk":"993314560","pt":1580540440453,"mc":[{"id":"1.168133548","rc":[{"batb":[[0,5.9,2.47]],"ltp":5.9,"tv":138.17,"id":8231803}]}]}
{"op":"mcm","clk":"993315114","pt":1580540449404,"mc":[{"id":"1.168133548","rc":[{"batl":[[0,10.5,6.18]],"ltp":10.0,"tv":423.44,"id":10616006},{"batb":[[0,5.6,3.65]],"ltp":6.0,"tv":169.67,"id":17352128}]}]}
{"op":"mcm","clk":"993315924","pt":1580540464542,"mc":[{"id":"1.168133548","rc":[{"batb":[[0,5.7,2.79],[1,5.6,3.65],[2,5.5,6.21]],"ltp":6.0,"tv":169.67,"id":17352128}]}]}
{"op":"mcm","clk":"993316249","pt":1580540471437,"mc":[{"id":"1.168133548","rc":[{"batb":[[0,5.8,3.65],[1,5.7,2.79]],"ltp":6.0,"tv":169.67,"id":17352128}]}]}
{"op":"mcm","clk":"993317021","pt":1580540486349,"mc":[{"id":"1.168133548","rc":[{"batl":[[1,11,1]],"ltp":10.0,"tv":423.44,"id":10616006},{"batb":[[1,5.5,6.21],[2,5.4,5.93]],"ltp":6.0,"tv":169.67,"id":17352128}]}]}
{"op":"mcm","clk":"993317623","pt":1580540494352,"mc":[{"id":"1.168133548","rc":[{"batb":[[0,5.6,14.95]],"ltp":6.0,"tv":169.67,"id":17352128}]}]}
{"op":"mcm","clk":"993317811","pt":1580540498476,"mc":[{"id":"1.168133548","rc":[{"trd":[[5.8,242.11]],"batb":[[0,5.8,12.27]],"ltp":5.8,"tv":903.07,"id":9417341}],"tv":2051.21}]}
{"op":"mcm","clk":"993317863","pt":1580540499556,"mc":[{"id":"1.168133548","rc":[{"batb":[[1,5.5,3]],"ltp":6.0,"tv":169.67,"id":17352128}]}]}
{"op":"mcm","clk":"993318285","pt":1580540508462,"mc":[{"id":"1.168133548","rc":[{"batb":[[0,5.7,14.2],[1,5.6,3.65],[2,5.5,3]],"ltp":6.0,"tv":169.67,"id":17352128}]}]}
{"op":"mcm","clk":"993318702","pt":1580540515188,"mc":[{"id":"1.168133548","rc":[{"batb":[[0,5.8,3.65],[1,5.7,14.2]],"ltp":6.0,"tv":169.67,"id":17352128}]}]}
{"op":"mcm","clk":"993319090","pt":1580540523319,"mc":[{"id":"1.168133548","rc":[{"batb":[[1,5.7,3.09]],"ltp":6.0,"tv":169.67,"id":17352128}]}]}
{"op":"mcm","clk":"993319201","pt":1580540525531,"mc":[{"id":"1.168133548","rc":[{"batb":[[1,5.5,3],[2,5.4,5.93]],"ltp":6.0,"tv":169.67,"id":17352128}]}]}
{"op":"mcm","clk":"993319502","pt":1580540532339,"mc":[{"id":"1.168133548","rc":[{"batb":[[1,5.5,6.21]],"ltp":6.0,"tv":169.67,"id":17352128}]}]}
{"op":"mcm","clk":"993319655","pt":1580540536514,"mc":[{"id":"1.168133548","rc":[{"batb":[[0,5.5,6.21],[1,5.4,5.93],[2,5,5.07]],"ltp":6.0,"tv":169.67,"id":17352128}]}]}
{"op":"mcm","clk":"993319684","pt":1580540537336,"mc":[{"id":"1.168133548","rc":[{"batb":[[0,5.6,14.95],[1,5.5,6.21],[2,5.4,5.93]],"ltp":6.0,"tv":169.67,"id":17352128}]}]}
{"op":"mcm","clk":"993319813","pt":1580540540746,"mc":[{"id":"1.168133548","rc":[{"batb":[[1,5.5,3]],"ltp":6.0,"tv":169.67,"id":17352128}]}]}
{"op":"mcm","clk":"993320163","pt":1580540548833,"mc":[{"id":"1.168133548","rc":[{"batb":[[0,5.7,3.09],[1,5.6,14.95],[2,5.5,3]],"ltp":6.0,"tv":169.67,"id":17352128}]}]}
{"op":"mcm","clk":"993320211","pt":1580540549868,"mc":[{"id":"1.168133548","rc":[{"batl":[[2,60,9.17]],"ltp":18.5,"tv":29.72,"id":9193530}]}]}
{"op":"mcm","clk":"993320295","pt":1580540551468,"mc":[{"id":"1.168133548","rc":[{"batb":[[0,5.7,14.2],[1,5.6,3.65]],"ltp":6.0,"tv":169.67,"id":17352128}]}]}
{"op":"mcm","clk":"993320661","pt":1580540559455,"mc":[{"id":"1.168133548","rc":[{"batb":[[0,5.8,3.65],[1,5.7,14.2]],"ltp":6.0,"tv":169.67,"id":17352128}]}]}
{"op":"mcm","clk":"993320988","pt":1580540566567,"mc":[{"id":"1.168133548","rc":[{"batl":[[0,27,7.8],[1,28,1.33],[2,29,3.03]],"ltp":18.5,"tv":29.72,"id":9193530},{"batb":[[1,5.7,3.09]],"ltp":6.0,"tv":169.67,"id":17352128}]}]}
{"op":"mcm","clk":"993321246","pt":1580540572484,"mc":[{"id":"1.168133548","rc":[{"batb":[[1,5.5,3],[2,5.4,5.93]],"ltp":6.0,"tv":169.67,"id":17352128}]}]}
{"op":"mcm","clk":"993321582","pt":1580540580518,"mc":[{"id":"1.168133548","rc":[{"batb":[[0,5.5,6.21],[1,5.4,5.93],[2,5,5.07]],"ltp":6.0,"tv":169.67,"id":17352128}]}]}
{"op":"mcm","clk":"993321614","pt":1580540581191,"mc":[{"id":"1.168133548","rc":[{"batb":[[0,5.6,3.65],[1,5.5,6.21],[2,5.4,5.93]],"ltp":6.0,"tv":169.67,"id":17352128}]}]}
{"op":"mcm","clk":"993321740","pt":1580540584393,"mc":[{"id":"1.168133548","rc":[{"batl":[[1,29,3.03],[2,60,9.17]],"ltp":18.5,"tv":29.72,"id":9193530}]}]}
{"op":"mcm","clk":"993322171","pt":1580540594352,"mc":[{"id":"1.168133548","rc":[{"batb":[[0,5.6,14.95]],"ltp":6.0,"tv":169.67,"id":17352128}]}]}
{"op":"mcm","clk":"993322247","pt":1580540596461,"mc":[{"id":"1.168133548","rc":[{"batb":[[1,5.5,3]],"ltp":6.0,"tv":169.67,"id":17352128}]}]}
{"op":"mcm","clk":"993322279","pt":1580540597133,"mc":[{"id":"1.168133548","rc":[{"batl":[[0,26,3.23],[1,27,7.6]],"ltp":18.5,"tv":29.72,"id":9193530}]}]}
{"op":"mcm","clk":"993322511","pt":1580540602437,"mc":[{"id":"1.168133548","rc":[{"batb":[[0,5.7,4.2],[1,5.6,14.95],[2,5.5,3]],"ltp":6.0,"tv":169.67,"id":17352128}]}]}
{"op":"mcm","clk":"993322581","pt":1580540604447,"mc":[{"id":"1.168133548","rc":[{"batl":[[0,25,1.48],[1,26,3.23],[2,27,7.6]],"ltp":18.5,"tv":29.72,"id":9193530}]}]}
{"op":"mcm","clk":"993322611","pt":1580540605267,"mc":[{"id":"1.168133548","rc":[{"batb":[[0,5.7,7.29]],"ltp":6.0,"tv":169.67,"id":17352128}]}]}
{"op":"mcm","clk":"993322768","pt":1580540609485,"mc":[{"id":"1.168133548","rc":[{"batb":[[1,5.6,3.65]],"ltp":6.0,"tv":169.67,"id":17352128}]}]}
{"op":"mcm","clk":"993323242","pt":1580540623106,"mc":[{"id":"1.168133548","rc":[{"batb":[[0,5.8,3.65],[1,5.7,7.29]],"ltp":6.0,"tv":169.67,"id":17352128}]}]}
{"op":"mcm","clk":"993323603","pt":1580540632018,"mc":[{"id":"1.168133548","rc":[{"batb":[[1,5.7,3.09]],"ltp":6.0,"tv":169.67,"id":17352128}]}]}
{"op":"mcm","clk":"993323821","pt":1580540637190,"mc":[{"id":"1.168133548","rc":[{"batb":[[1,5.5,3],[2,5.4,5.93]],"ltp":6.0,"tv":169.67,"id":17352128}]}]}
{"op":"mcm","clk":"993324186","pt":1580540645326,"mc":[{"id":"1.168133548","rc":[{"batb":[[0,5.6,3.65],[1,5.5,6.21]],"ltp":6.0,"tv":169.67,"id":17352128}]}]}
{"op":"mcm","clk":"993324444","pt":1580540652319,"mc":[{"id":"1.168133548","rc":[{"batb":[[0,5.6,14.95]],"ltp":6.0,"tv":169.67,"id":17352128}]}]}
{"op":"mcm","clk":"993324494","pt":1580540653600,"mc":[{"id":"1.168133548","rc":[{"batb":[[1,5.5,3]],"ltp":6.0,"tv":169.67,"id":17352128}]}]}
