{"op":"mcm","clk":"991777749","pt":1580553275113,"mc":[{"id":"1.168136214","rc":[{"batl":[[0,4.1,6]],"ltp":4.1,"tv":1557.56,"id":12925630}]}]}
{"op":"mcm","clk":"991777892","pt":1580553276084,"mc":[{"id":"1.168136214","rc":[{"trd":[[4,5.54]],"batb":[[0,4,137.14]],"ltp":4.0,"tv":1563.1,"id":12925630}],"tv":8320.59}]}
{"op":"mcm","clk":"991778275","pt":1580553279080,"mc":[{"id":"1.168136214","rc":[{"batl":[[1,4.2,38.77]],"ltp":4.0,"tv":1563.1,"id":12925630}]}]}
{"op":"mcm","clk":"991778976","pt":1580553284013,"mc":[{"id":"1.168136214","rc":[{"batl":[[2,4.3,149.71]],"ltp":4.0,"tv":1563.1,"id":12925630}]}]}
{"op":"mcm","clk":"991780064","pt":1580553292135,"mc":[{"id":"1.168136214","rc":[{"trd":[[4,56.2]],"batb":[[0,4,111.81]],"ltp":4.0,"tv":1613.76,"id":12925630}],"tv":8371.25}]}
{"op":"mcm","clk":"991780556","pt":1580553295836,"mc":[{"id":"1.168136214","rc":[{"batl":[[1,4.2,44.62]],"ltp":4.0,"tv":1613.76,"id":12925630}]}]}
{"op":"mcm","clk":"991782341","pt":1580553308048,"mc":[{"id":"1.168136214","rc":[{"trd":[[4.1,264.34],[4.2,388.01],[4.3,283.83]],"batb":[[0,4.1,2.04],[1,4,111.81],[2,3.95,7]],"batl":[[0,4.3,136.17],[1,4.4,58.06],[2,4.5,5.12]],"ltp":4.3,"tv":1677.92,"id":12925630},{"trd":[[1.98,1102.8]],"batl":[[0,2,66.77],[1,2.02,21.2],[2,2.04,20.36]],"ltp":1.98,"tv":5560.15,"id":17336468},{"trd":[[3.75,215.7],[3.8,199.81],[3.85,207.73],[3.9,129.57],[3.95,61.48]],"batb":[[0,3.7,35],[1,3.65,3.04],[2,3.6,111.21]],"batl":[[0,3.75,125.18],[1,3.85,4.04],[2,3.9,4.04]],"ltp":3.75,"tv":1653.09,"id":11981493}],"tv":8891.17}]}
{"op":"mcm","clk":"991782468","pt":1580553308962,"mc":[{"id":"1.168136214","rc":[{"batl":[[0,2,31.66],[1,2.02,48.2]],"ltp":1.98,"tv":5560.15,"id":17336468}]}]}
{"op":"mcm","clk":"991782601","pt":1580553309858,"mc":[{"id":"1.168136214","rc":[{"batb":[[1,4,114.81]],"ltp":4.3,"tv":1677.92,"id":12925630}]}]}
{"op":"mcm","clk":"991783048","pt":1580553312924,"mc":[{"id":"1.168136214","rc":[{"trd":[[2,1541.62]],"batb":[[1,1.96,41.11]],"batl":[[0,2,11.96]],"ltp":2.0,"tv":5599.55,"id":17336468}],"tv":8930.57}]}
{"op":"mcm","clk":"991783606","pt":1580553317140,"mc":[{"id":"1.168136214","rc":[{"trd":[[4.3,289.39]],"batl":[[0,4.3,130.61]],"ltp":4.3,"tv":1683.48,"id":12925630},{"trd":[[2,1553.58]],"batl":[[0,2.02,48.2],[1,2.04,20.36],[2,2.06,8]],"ltp":2.0,"tv":5611.51,"id":17336468},{"trd":[[3.7,168.89]],"batb":[[0,3.65,3.04],[1,3.6,111.21],[2,3.55,20]],"batl":[[0,3.7,80.72]],"ltp":3.7,"tv":1735.55,"id":11981493}],"tv":9030.55}]}
{"op":"mcm","clk":"991783711","pt":1580553317939,"mc":[{"id":"1.168136214","rc":[{"trd":[[4.2,393.1]],"batb":[[0,4.1,3.09],[1,4,104.81]],"ltp":4.2,"tv":1688.57,"id":12925630},{"trd":[[2.02,400.16]],"batb":[[1,1.96,48.77]],"batl":[[0,2.02,37.62],[1,2.04,17.36],[2,2.06,11]],"ltp":2.02,"tv":5622.1,"id":17336468},{"trd":[[3.7,174.67]],"batb":[[1,3.6,114.21]],"batl":[[0,3.7,74.94],[1,3.8,5.09],[2,3.85,26.57]],"ltp":3.7,"tv":1741.33,"id":11981493}],"tv":9052.0}]}
{"op":"mcm","clk":"991783867","pt":1580553319061,"mc":[{"id":"1.168136214","rc":[{"batb":[[0,4.1,18.23]],"ltp":4.2,"tv":1688.57,"id":12925630},{"trd":[[2.02,424.36]],"batb":[[0,2,43.03],[1,1.99,12.1],[2,1.97,11.09]],"batl":[[0,2.02,25.52]],"ltp":2.02,"tv":5646.3,"id":17336468},{"trd":[[3.7,208.22]],"batl":[[0,3.7,58.17],[1,3.8,18.63],[2,3.85,7.94]],"ltp":3.7,"tv":1774.87,"id":11981493}],"tv":9109.74}]}
{"op":"mcm","clk":"991784014","pt":1580553320072,"mc":[{"id":"1.168136214","rc":[{"batl":[[0,4.2,4.1],[1,4.3,128.61],[2,4.4,56]],"ltp":4.2,"tv":1688.57,"id":12925630},{"batb":[[2,1.98,10.1]],"batl":[[1,2.04,21.36]],"ltp":2.02,"tv":5646.3,"id":17336468},{"batl":[[0,3.8,13.54],[1,3.85,11.94],[2,4.1,27.97]],"ltp":3.7,"tv":1774.87,"id":11981493}]}]}
{"op":"mcm","clk":"991784171","pt":1580553321147,"mc":[{"id":"1.168136214","rc":[{"batb":[[0,4.1,15.14]],"ltp":4.2,"tv":1688.57,"id":12925630},{"batl":[[0,2.02,55.53]],"ltp":2.02,"tv":5646.3,"id":17336468},{"batl":[[0,4,12.89],[1,4.1,27.97],[2,4.2,180]],"ltp":3.7,"tv":1774.87,"id":11981493}]}]}
{"op":"mcm","clk":"991784323","pt":1580553322156,"mc":[{"id":"1.168136214","rc":[{"trd":[[2,1557.58]],"batb":[[0,2,41.03]],"batl":[[1,2.04,51.37]],"ltp":2.0,"tv":5650.3,"id":17336468},{"batl":[[0,4,28.78]],"ltp":3.7,"tv":1774.87,"id":11981493}],"tv":9113.75}]}
{"op":"mcm","clk":"991784566","pt":1580553324074,"mc":[{"id":"1.168136214","rc":[{"batb":[[0,4.1,18.14]],"ltp":4.2,"tv":1688.57,"id":12925630},{"batl":[[0,2.02,85.54]],"ltp":2.0,"tv":5650.3,"id":17336468},{"batb":[[1,3.6,45.21]],"batl":[[0,4,12.89]],"ltp":3.7,"tv":1774.87,"id":11981493}]}]}
{"op":"mcm","clk":"991784845","pt":1580553326058,"mc":[{"id":"1.168136214","rc":[{"batb":[[1,4,101.81]],"batl":[[0,4.2,24.1]],"ltp":4.2,"tv":1688.57,"id":12925630}]}]}
{"op":"mcm","clk":"991785404","pt":1580553329960,"mc":[{"id":"1.168136214","rc":[{"trd":[[4.1,284.34]],"batb":[[0,4.1,8.13]],"ltp":4.1,"tv":1708.57,"id":12925630}],"tv":9133.75}]}
{"op":"mcm","clk":"991785845","pt":1580553333073,"mc":[{"id":"1.168136214","rc":[{"batb":[[1,4,103.81],[2,3.95,9]],"batl":[[0,4.2,20]],"ltp":4.1,"tv":1708.57,"id":12925630},{"trd":[[1.98,1147],[1.99,600.22],[2,1639.63]],"batb":[[0,1.97,5.17],[1,1.96,35.11],[2,1.95,9.81]],"batl":[[0,1.98,104.78],[1,2.02,93.54],[2,2.04,54.37]],"ltp":1.98,"tv":5800.75,"id":17336468},{"batl":[[0,4,10.78]],"ltp":3.7,"tv":1774.87,"id":11981493}],"tv":9284.2}]}
{"op":"mcm","clk":"991785964","pt":1580553334083,"mc":[{"id":"1.168136214","rc":[{"batb":[[1,1.96,37.11]],"ltp":1.98,"tv":5800.75,"id":17336468}]}]}
{"op":"mcm","clk":"991786093","pt":1580553335065,"mc":[{"id":"1.168136214","rc":[{"batb":[[2,1.94,92.12]],"batl":[[1,2.02,128.07]],"ltp":1.98,"tv":5800.75,"id":17336468}]}]}
{"op":"mcm","clk":"991786973","pt":1580553341092,"mc":[{"id":"1.168136214","rc":[{"trd":[[4.2,405.48]],"batb":[[0,4.1,22.81]],"batl":[[0,4.2,7.62]],"ltp":4.2,"tv":1720.95,"id":12925630},{"trd":[[1.95,451.5],[1.96,761.43],[1.97,254.3]],"batb":[[0,1.94,97.12],[1,1.93,245],[2,1.92,11]],"batl":[[0,1.95,28.62],[1,1.98,10.22],[2,1.99,10.22]],"ltp":1.95,"tv":5926.41,"id":17336468},{"trd":[[4,93.5]],"batb":[[0,3.65,6],[1,3.6,47.21]],"batl":[[0,4.1,29.97],[1,4.2,180],[2,4.5,20]],"ltp":4.0,"tv":1787.87,"id":11981493}],"tv":9435.24}]}
{"op":"mcm","clk":"991787284","pt":1580553343100,"mc":[{"id":"1.168136214","rc":[{"batb":[[1,1.93,251.07]],"batl":[[1,1.97,6.17],[2,1.98,10.22]],"ltp":1.95,"tv":5926.41,"id":17336468}]}]}
{"op":"mcm","clk":"991787417","pt":1580553344101,"mc":[{"id":"1.168136214","rc":[{"trd":[[4.1,288.35]],"batb":[[0,4.1,20.81]],"ltp":4.1,"tv":1724.95,"id":12925630},{"batb":[[1,1.93,247.99]],"batl":[[1,1.97,12.33]],"ltp":1.95,"tv":5926.41,"id":17336468}],"tv":9439.24}]}
{"op":"mcm","clk":"991787595","pt":1580553345061,"mc":[{"id":"1.168136214","rc":[{"batl":[[1,4.3,168.61]],"ltp":4.1,"tv":1724.95,"id":12925630}]}]}
{"op":"mcm","clk":"991787832","pt":1580553346891,"mc":[{"id":"1.168136214","rc":[{"batb":[[0,1.95,5.25],[1,1.94,97.12],[2,1.93,247.99]],"batl":[[0,1.97,12.33],[1,1.99,10.22],[2,2.02,120.07]],"ltp":1.95,"tv":5926.41,"id":17336468},{"batl":[[0,4,2.25],[1,4.1,29.97],[2,4.2,180]],"ltp":4.0,"tv":1787.87,"id":11981493}]}]}
{"op":"mcm","clk":"991788633","pt":1580553353024,"mc":[{"id":"1.168136214","rc":[{"trd":[[4.2,407.62]],"batl":[[0,4.2,5.48]],"ltp":4.2,"tv":1727.09,"id":12925630},{"trd":[[1.94,147.43],[1.95,466.62]],"batb":[[0,1.96,5.25],[1,1.95,5],[2,1.94,87]],"batl":[[2,2,11.25]],"ltp":1.94,"tv":5961.78,"id":17336468},{"trd":[[4,95.75]],"batl":[[0,4,2]],"ltp":4.0,"tv":1790.12,"id":11981493}],"tv":9479.0}]}
{"op":"mcm","clk":"991788757","pt":1580553353886,"mc":[{"id":"1.168136214","rc":[{"batb":[[0,4.1,23]],"ltp":4.2,"tv":1727.09,"id":12925630},{"batb":[[0,1.95,5],[1,1.94,87],[2,1.93,117.99]],"batl":[[0,1.99,10.22],[1,2,11.25],[2,2.02,120.07]],"ltp":1.94,"tv":5961.78,"id":17336468}]}]}
{"op":"mcm","clk":"991788915","pt":1580553355118,"mc":[{"id":"1.168136214","rc":[{"batl":[[0,2.02,131.07],[1,2.04,30.01],[2,2.06,8]],"ltp":1.94,"tv":5961.78,"id":17336468}]}]}
{"op":"mcm","clk":"991789217","pt":1580553357091,"mc":[{"id":"1.168136214","rc":[{"batb":[[0,3.8,7.31],[1,3.75,16],[2,3.6,42.21]],"ltp":4.0,"tv":1790.12,"id":11981493}]}]}
{"op":"mcm","clk":"991789337","pt":1580553358096,"mc":[{"id":"1.168136214","rc":[{"batl":[[0,1.97,2],[1,2,11.31],[2,2.02,131.07]],"ltp":1.94,"tv":5961.78,"id":17336468}]}]}
{"op":"mcm","clk":"991789599","pt":1580553360013,"mc":[{"id":"1.168136214","rc":[{"trd":[[4.2,418.58]],"batb":[[0,4.2,9.52],[1,4.1,23],[2,4,103.81]],"batl":[[0,4.3,168.61],[1,4.4,56],[2,4.5,3]],"ltp":4.2,"tv":1738.05,"id":12925630}],"tv":9489.96}]}
{"op":"mcm","clk":"991789750","pt":1580553361149,"mc":[{"id":"1.168136214","rc":[{"batb":[[1,4.1,28.61]],"ltp":4.2,"tv":1738.05,"id":12925630},{"batl":[[1,1.99,11],[2,2,11.31]],"ltp":1.94,"tv":5961.78,"id":17336468}]}]}
{"op":"mcm","clk":"991790751","pt":1580553367937,"mc":[{"id":"1.168136214","rc":[{"batb":[[0,1.96,16.8],[1,1.95,5],[2,1.94,87]],"ltp":1.94,"tv":5961.78,"id":17336468}]}]}
{"op":"mcm","clk":"991792087","pt":1580553379087,"mc":[{"id":"1.168136214","rc":[{"trd":[[4.2,426.58]],"batb":[[0,4.2,5.52]],"ltp":4.2,"tv":1746.05,"id":12925630}],"tv":9497.96}]}
{"op":"mcm","clk":"991792480","pt":1580553382147,"mc":[{"id":"1.168136214","rc":[{"trd":[[4.2,437.62]],"batb":[[0,4.1,28.61],[1,4,103.81],[2,3.95,9]],"ltp":4.2,"tv":1757.09,"id":12925630}],"tv":9509.0}]}
{"op":"mcm","clk":"991794179","pt":1580553393990,"mc":[{"id":"1.168136214","rc":[{"batl":[[0,4.3,170.61]],"ltp":4.2,"tv":1757.09,"id":12925630}]}]}
{"op":"mcm","clk":"991794468","pt":1580553396122,"mc":[{"id":"1.168136214","rc":[{"trd":[[1.97,258.3]],"batb":[[0,1.98,5.19],[1,1.97,164.8],[2,1.95,11.17]],"batl":[[0,1.99,12.99],[1,2.02,131.07],[2,2.04,30.01]],"ltp":1.97,"tv":5965.78,"id":17336468}],"tv":9513.0}]}
{"op":"mcm","clk":"991794618","pt":1580553397126,"mc":[{"id":"1.168136214","rc":[{"batl":[[0,3.95,10],[1,4,2],[2,4.1,29.97]],"ltp":4.0,"tv":1790.12,"id":11981493}]}]}
{"op":"mcm","clk":"991794765","pt":1580553398136,"mc":[{"id":"1.168136214","rc":[{"batb":[[1,1.97,169.8],[2,1.95,6]],"ltp":1.97,"tv":5965.78,"id":17336468},{"batl":[[0,3.9,10],[1,3.95,12],[2,4,2]],"ltp":4.0,"tv":1790.12,"id":11981493}]}]}
{"op":"mcm","clk":"991795006","pt":1580553399989,"mc":[{"id":"1.168136214","rc":[{"batb":[[1,3.75,23]],"batl":[[0,3.85,10],[1,3.9,10],[2,3.95,12]],"ltp":4.0,"tv":1790.12,"id":11981493}]}]}
{"op":"mcm","clk":"991795238","pt":1580553402000,"mc":[{"id":"1.168136214","rc":[{"trd":[[3.85,227.73]],"batb":[[2,3.7,20]],"batl":[[0,3.9,10],[1,3.95,12],[2,4,2]],"ltp":3.85,"tv":1810.12,"id":11981493}],"tv":9533.0}]}
{"op":"mcm","clk":"991795391","pt":1580553403120,"mc":[{"id":"1.168136214","rc":[{"trd":[[4.1,298.35]],"batb":[[0,4.1,23.61]],"ltp":4.1,"tv":1767.09,"id":12925630}],"tv":9543.0}]}
{"op":"mcm","clk":"991795769","pt":1580553406602,"mc":[{"id":"1.168136214","rc":[{"batl":[[1,2,10.77],[2,2.02,131.07]],"ltp":1.97,"tv":5965.78,"id":17336468}]}]}
{"op":"mcm","clk":"991796229","pt":1580553410142,"mc":[{"id":"1.168136214","rc":[{"batl":[[0,3.85,1],[1,3.9,10],[2,3.95,12]],"ltp":3.85,"tv":1810.12,"id":11981493}]}]}
{"op":"mcm","clk":"991796360","pt":1580553411107,"mc":[{"id":"1.168136214","rc":[{"batl":[[0,3.85,20]],"ltp":3.85,"tv":1810.12,"id":11981493}]}]}
{"op":"mcm","clk":"991796471","pt":1580553411807,"mc":[{"id":"1.168136214","rc":[{"batb":[[0,3.8,27.31],[2,3.7,27]],"ltp":3.85,"tv":1810.12,"id":11981493}]}]}
{"op":"mcm","clk":"991797710","pt":1580553421131,"mc":[{"id":"1.168136214","rc":[{"batb":[[0,1.98,18.27]],"batl":[[1,2,21.93]],"ltp":1.97,"tv":5965.78,"id":17336468}]}]}
{"op":"mcm","clk":"991797847","pt":1580553422149,"mc":[{"id":"1.168136214","rc":[{"batb":[[2,1.96,5]],"ltp":1.97,"tv":5965.78,"id":17336468}]}]}
{"op":"mcm","clk":"991800197","pt":1580553440041,"mc":[{"id":"1.168136214","rc":[{"trd":[[1.99,610.22]],"batl":[[0,1.99,7.99]],"ltp":1.99,"tv":5975.78,"id":17336468}],"tv":9553.0}]}
{"op":"mcm","clk":"991803105","pt":1580553461088,"mc":[{"id":"1.168136214","rc":[{"trd":[[4.2,441.41]],"batl":[[0,4.2,16.21],[1,4.3,170.61],[2,4.4,56]],"ltp":4.2,"tv":1770.88,"id":12925630},{"trd":[[1.99,618.21]],"batl":[[0,2,21.93],[1,2.02,131.07],[2,2.04,30.01]],"ltp":1.99,"tv":5983.77,"id":17336468},{"trd":[[3.85,231.86]],"batl":[[0,3.85,15.87]],"ltp":3.85,"tv":1814.25,"id":11981493}],"tv":9568.91}]}
{"op":"mcm","clk":"991803248","pt":1580553462101,"mc":[{"id":"1.168136214","rc":[{"batb":[[0,4.1,33.74]],"ltp":4.2,"tv":1770.88,"id":12925630},{"batb":[[0,1.99,20.88],[1,1.98,18.27],[2,1.97,169.8]],"ltp":1.99,"tv":5983.77,"id":17336468},{"trd":[[3.85,253.44]],"batl":[[0,3.85,5.08]],"ltp":3.85,"tv":1835.83,"id":11981493}],"tv":9590.49}]}
{"op":"mcm","clk":"991803517","pt":1580553464077,"mc":[{"id":"1.168136214","rc":[{"batl":[[0,4.2,18.21]],"ltp":4.2,"tv":1770.88,"id":12925630},{"trd":[[3.85,263.6]],"batb":[[0,3.85,21.92],[1,3.8,27.31],[2,3.75,23]],"batl":[[0,3.9,10],[1,3.95,12],[2,4,2]],"ltp":3.85,"tv":1845.99,"id":11981493}],"tv":9600.65}]}
{"op":"mcm","clk":"991803740","pt":1580553465972,"mc":[{"id":"1.168136214","rc":[{"trd":[[4.1,302.35]],"batb":[[0,4.1,31.74]],"batl":[[0,4.2,21.21],[1,4.3,168.61]],"ltp":4.1,"tv":1774.88,"id":12925630}],"tv":9604.65}]}
{"op":"mcm","clk":"991803882","pt":1580553467092,"mc":[{"id":"1.168136214","rc":[{"batb":[[0,3.85,7]],"ltp":3.85,"tv":1845.99,"id":11981493}]}]}
{"op":"mcm","clk":"991805020","pt":1580553476101,"mc":[{"id":"1.168136214","rc":[{"trd":[[4.1,327.68]],"batb":[[0,4.1,19.07]],"ltp":4.1,"tv":1800.21,"id":12925630}],"tv":9629.98}]}
{"op":"mcm","clk":"991806265","pt":1580553486127,"mc":[{"id":"1.168136214","rc":[{"trd":[[4.1,331.68]],"batb":[[0,4.1,17.07]],"ltp":4.1,"tv":1804.21,"id":12925630}],"tv":9633.98}]}
{"op":"mcm","clk":"991806743","pt":1580553489806,"mc":[{"id":"1.168136214","rc":[{"batl":[[1,4.3,170.61]],"ltp":4.1,"tv":1804.21,"id":12925630}]}]}
{"op":"mcm","clk":"991806916","pt":1580553491104,"mc":[{"id":"1.168136214","rc":[{"batb":[[2,1.97,153]],"ltp":1.99,"tv":5983.77,"id":17336468}]}]}
{"op":"mcm","clk":"991807049","pt":1580553492117,"mc":[{"id":"1.168136214","rc":[{"trd":[[2,1673.24]],"batl":[[0,2,5.13]],"ltp":2.0,"tv":6017.38,"id":17336468}],"tv":9667.59}]}
{"op":"mcm","clk":"991807891","pt":1580553499137,"mc":[{"id":"1.168136214","rc":[{"batb":[[1,4,136.81]],"ltp":4.1,"tv":1804.21,"id":12925630}]}]}
{"op":"mcm","clk":"991808010","pt":1580553500045,"mc":[{"id":"1.168136214","rc":[{"trd":[[2,1683.49]],"batb":[[0,2,5.19],[1,1.99,20.88],[2,1.98,18.27]],"batl":[[0,2.02,131.07],[1,2.04,41.01],[2,2.06,8]],"ltp":2.0,"tv":6027.63,"id":17336468}],"tv":9677.85}]}
{"op":"mcm","clk":"991808137","pt":1580553501056,"mc":[{"id":"1.168136214","rc":[{"batl":[[0,2.02,11],[1,2.04,11]],"ltp":2.0,"tv":6027.63,"id":17336468}]}]}
{"op":"mcm","clk":"991808261","pt":1580553502122,"mc":[{"id":"1.168136214","rc":[{"batb":[[1,1.99,25.88]],"batl":[[0,2.02,34.73],[1,2.04,28.36]],"ltp":2.0,"tv":6027.63,"id":17336468}]}]}
{"op":"mcm","clk":"991809926","pt":1580553516097,"mc":[{"id":"1.168136214","rc":[{"batl":[[0,2.02,52.08],[1,2.04,45.72]],"ltp":2.0,"tv":6027.63,"id":17336468}]}]}
{"op":"mcm","clk":"991810045","pt":1580553517055,"mc":[{"id":"1.168136214","rc":[{"trd":[[4.1,335.68]],"batb":[[0,4.1,15.07]],"ltp":4.1,"tv":1808.21,"id":12925630},{"batl":[[0,2.02,63.08]],"ltp":2.0,"tv":6027.63,"id":17336468}],"tv":9681.85}]}
{"op":"mcm","clk":"991810538","pt":1580553521071,"mc":[{"id":"1.168136214","rc":[{"batb":[[0,3.85,20]],"batl":[[0,3.9,30]],"ltp":3.85,"tv":1845.99,"id":11981493}]}]}
{"op":"mcm","clk":"991810901","pt":1580553524097,"mc":[{"id":"1.168136214","rc":[{"trd":[[2,1693.87]],"batb":[[0,1.99,25.88],[1,1.98,18.27],[2,1.97,153]],"ltp":2.0,"tv":6038.01,"id":17336468}],"tv":9692.22}]}
{"op":"mcm","clk":"991811675","pt":1580553530979,"mc":[{"id":"1.168136214","rc":[{"batl":[[0,2.02,80.44],[1,2.04,63.08]],"ltp":2.0,"tv":6038.01,"id":17336468}]}]}
{"op":"mcm","clk":"991812524","pt":1580553538569,"mc":[{"id":"1.168136214","rc":[{"batb":[[0,4.1,19.07]],"ltp":4.1,"tv":1808.21,"id":12925630},{"batb":[[0,1.99,20.88]],"batl":[[0,2,45],[1,2.02,80.44],[2,2.04,63.08]],"ltp":2.0,"tv":6038.01,"id":17336468},{"batb":[[0,3.85,27]],"ltp":3.85,"tv":1845.99,"id":11981493}]}]}
{"op":"mcm","clk":"991812822","pt":1580553541109,"mc":[{"id":"1.168136214","rc":[{"trd":[[1.99,659.96]],"batb":[[0,1.98,18.27],[1,1.97,153],[2,1.96,4]],"batl":[[0,1.99,4.12],[1,2,45],[2,2.02,80.44]],"ltp":1.99,"tv":6079.77,"id":17336468}],"tv":9733.98}]}
{"op":"mcm","clk":"991813626","pt":1580553547131,"mc":[{"id":"1.168136214","rc":[{"trd":[[4.1,339.68]],"batb":[[0,4.1,17.07]],"ltp":4.1,"tv":1812.21,"id":12925630}],"tv":9737.98}]}
{"op":"mcm","clk":"991817778","pt":1580553581136,"mc":[{"id":"1.168136214","rc":[{"trd":[[4.1,343.04]],"batb":[[0,4.1,15.39]],"ltp":4.1,"tv":1815.57,"id":12925630}],"tv":9741.34}]}
{"op":"mcm","clk":"991820230","pt":1580553601063,"mc":[{"id":"1.168136214","rc":[{"batb":[[0,1.98,28.1]],"ltp":1.99,"tv":6079.77,"id":17336468}]}]}
{"op":"mcm","clk":"991820618","pt":1580553604110,"mc":[{"id":"1.168136214","rc":[{"trd":[[4.2,465.73]],"batl":[[0,4.2,9.04]],"ltp":4.2,"tv":1839.9,"id":12925630}],"tv":9765.67}]}
{"op":"mcm","clk":"991820747","pt":1580553605136,"mc":[{"id":"1.168136214","rc":[{"trd":[[4.1,347.04]],"batb":[[0,4.1,13.39]],"ltp":4.1,"tv":1843.9,"id":12925630}],"tv":9769.67}]}
{"op":"mcm","clk":"991821962","pt":1580553613925,"mc":[{"id":"1.168136214","rc":[{"batl":[[1,4.3,168.61]],"ltp":4.1,"tv":1843.9,"id":12925630}]}]}
{"op":"mcm","clk":"991822105","pt":1580553615143,"mc":[{"id":"1.168136214","rc":[{"trd":[[4.1,351.04]],"batb":[[0,4.1,11.39]],"ltp":4.1,"tv":1847.9,"id":12925630}],"tv":9773.67}]}
{"op":"mcm","clk":"991822458","pt":1580553618138,"mc":[{"id":"1.168136214","rc":[{"batl":[[1,4.3,176.18]],"ltp":4.1,"tv":1847.9,"id":12925630}]}]}
{"op":"mcm","clk":"991824240","pt":1580553632060,"mc":[{"id":"1.168136214","rc":[{"trd":[[4.1,361.09]],"batb":[[0,4.1,6.37]],"ltp":4.1,"tv":1857.95,"id":12925630}],"tv":9783.72}]}
{"op":"mcm","clk":"991824706","pt":1580553636049,"mc":[{"id":"1.168136214","rc":[{"trd":[[4.1,365.09]],"batb":[[0,4.1,4.37]],"ltp":4.1,"tv":1861.95,"id":12925630}],"tv":9787.72}]}
{"op":"mcm","clk":"991827044","pt":1580553657083,"mc":[{"id":"1.168136214","rc":[{"trd":[[4.1,369.09]],"batb":[[0,4.1,2.37]],"ltp":4.1,"tv":1865.95,"id":12925630}],"tv":9791.71}]}
{"op":"mcm","clk":"991828028","pt":1580553664735,"mc":[{"id":"1.168136214","rc":[{"trd":[[4.1,391.46]],"batb":[[0,4,136.81],[1,3.95,9],[2,3.9,5]],"ltp":4.1,"tv":1888.32,"id":12925630},{"trd":[[1.99,664.08],[2,1725.91]],"batl":[[0,2,12.96],[1,2.02,80.44],[2,2.04,63.08]],"ltp":2.0,"tv":6115.93,"id":17336468},{"trd":[[3.9,148.1]],"batl":[[0,3.9,11.47]],"ltp":3.9,"tv":1864.52,"id":11981493}],"tv":9868.77}]}
{"op":"mcm","clk":"991829190","pt":1580553674121,"mc":[{"id":"1.168136214","rc":[{"batl":[[0,4.2,29.04]],"ltp":4.1,"tv":1888.32,"id":12925630},{"batl":[[0,2,26.96]],"ltp":2.0,"tv":6115.93,"id":17336468}]}]}
{"op":"mcm","clk":"991829423","pt":1580553676135,"mc":[{"id":"1.168136214","rc":[{"trd":[[4.1,393.46]],"ltp":4.1,"tv":1890.32,"id":12925630},{"trd":[[2,1730.01]],"batl":[[0,2,22.86]],"ltp":2.0,"tv":6120.03,"id":17336468},{"trd":[[3.9,150.2]],"batl":[[0,3.9,9.37]],"ltp":3.9,"tv":1866.62,"id":11981493}],"tv":9876.97}]}
{"op":"mcm","clk":"991831689","pt":1580553695066,"mc":[{"id":"1.168136214","rc":[{"trd":[[1.98,1215]],"batb":[[0,1.99,2.18],[1,1.98,13.08],[2,1.97,153]],"ltp":1.98,"tv":6188.03,"id":17336468}],"tv":9944.98}]}
{"op":"mcm","clk":"991831808","pt":1580553696030,"mc":[{"id":"1.168136214","rc":[{"batb":[[0,1.99,4.19],[1,1.98,17.08]],"ltp":1.98,"tv":6188.03,"id":17336468},{"batl":[[1,3.95,10]],"ltp":3.9,"tv":1866.62,"id":11981493}]}]}
{"op":"mcm","clk":"991831921","pt":1580553697033,"mc":[{"id":"1.168136214","rc":[{"batl":[[0,2,34.38]],"ltp":1.98,"tv":6188.03,"id":17336468}]}]}
{"op":"mcm","clk":"991832186","pt":1580553699156,"mc":[{"id":"1.168136214","rc":[{"trd":[[4.1,398.46]],"ltp":4.1,"tv":1895.32,"id":12925630},{"trd":[[2,1740.26]],"batl":[[0,2,24.13]],"ltp":2.0,"tv":6198.28,"id":17336468},{"trd":[[3.9,155.46]],"batl":[[0,3.9,4.11]],"ltp":3.9,"tv":1871.88,"id":11981493}],"tv":9965.49}]}
{"op":"mcm","clk":"991833260","pt":1580553707064,"mc":[{"id":"1.168136214","rc":[{"trd":[[4.1,400.46]],"ltp":4.1,"tv":1897.32,"id":12925630},{"trd":[[2,1744.36]],"batb":[[0,1.99,9.71]],"batl":[[0,2,20.03]],"ltp":2.0,"tv":6202.38,"id":17336468},{"trd":[[3.9,157.56]],"batl":[[0,3.9,2.01]],"ltp":3.9,"tv":1873.98,"id":11981493}],"tv":9973.69}]}
{"op":"mcm","clk":"991833821","pt":1580553711146,"mc":[{"id":"1.168136214","rc":[{"trd":[[4.1,402.37]],"batl":[[0,4.1,1.09],[1,4.2,29.04],[2,4.3,176.18]],"ltp":4.1,"tv":1899.23,"id":12925630},{"trd":[[2,1748.28]],"batb":[[0,1.99,13.65]],"batl":[[0,2,16.11]],"ltp":2.0,"tv":6206.3,"id":17336468},{"trd":[[3.9,159.57]],"batl":[[0,3.95,10],[1,4,2],[2,4.1,33.79]],"ltp":3.9,"tv":1875.99,"id":11981493}],"tv":9981.53}]}
{"op":"mcm","clk":"991834347","pt":1580553715081,"mc":[{"id":"1.168136214","rc":[{"batl":[[0,4.2,29.04],[1,4.3,176.18],[2,4.4,56]],"ltp":4.1,"tv":1899.23,"id":12925630},{"batl":[[0,3.95,12],[2,4.1,29.97]],"ltp":3.9,"tv":1875.99,"id":11981493}]}]}
{"op":"mcm","clk":"991834494","pt":1580553716142,"mc":[{"id":"1.168136214","rc":[{"batl":[[0,4.1,2],[1,4.2,29.04],[2,4.3,176.18]],"ltp":4.1,"tv":1899.23,"id":12925630}]}]}
{"op":"mcm","clk":"991835469","pt":1580553722923,"mc":[{"id":"1.168136214","rc":[{"trd":[[4,66.2]],"batb":[[0,4,131.81]],"ltp":4.0,"tv":1909.23,"id":12925630}],"tv":9991.53}]}
{"op":"mcm","clk":"991836962","pt":1580553733882,"mc":[{"id":"1.168136214","rc":[{"trd":[[4,76.2]],"batb":[[0,4,126.81]],"ltp":4.0,"tv":1919.23,"id":12925630}],"tv":10001.53}]}
{"op":"mcm","clk":"991838692","pt":1580553747123,"mc":[{"id":"1.168136214","rc":[{"trd":[[4.1,406.37]],"batl":[[0,4.2,29.04],[1,4.3,176.18],[2,4.4,56]],"ltp":4.1,"tv":1923.23,"id":12925630},{"trd":[[2,1756.48]],"batb":[[0,1.99,17.77]],"batl":[[0,2,7.91]],"ltp":2.0,"tv":6214.5,"id":17336468},{"trd":[[3.8,237.61],[3.85,317.6],[3.9,163.77]],"batb":[[0,3.85,5],[1,3.8,13.41]],"batl":[[0,3.9,7.18],[1,3.95,12],[2,4,2]],"ltp":3.9,"tv":1971.99,"id":11981493}],"tv":10109.73}]}
{"op":"mcm","clk":"991838800","pt":1580553748027,"mc":[{"id":"1.168136214","rc":[{"batb":[[0,1.99,18.26]],"batl":[[0,2.02,91.84],[1,2.04,63.08],[2,2.06,8]],"ltp":2.0,"tv":6214.5,"id":17336468}]}]}
{"op":"mcm","clk":"991841273","pt":1580553767016,"mc":[{"id":"1.168136214","rc":[{"batl":[[0,4.1,2],[1,4.2,29.04],[2,4.3,176.18]],"ltp":4.1,"tv":1923.23,"id":12925630}]}]}
{"op":"mcm","clk":"991845265","pt":1580553796151,"mc":[{"id":"1.168136214","rc":[{"batl":[[0,3.9,22.18]],"ltp":3.9,"tv":1971.99,"id":11981493}]}]}
{"op":"mcm","clk":"991849913","pt":1580553832079,"mc":[{"id":"1.168136214","rc":[{"trd":[[4.1,408.91]],"batl":[[0,4.2,29.04],[1,4.3,176.18],[2,4.4,56]],"ltp":4.1,"tv":1925.77,"id":12925630},{"trd":[[2,1759.48]],"ltp":2.0,"tv":6217.5,"id":17336468},{"trd":[[3.9,165.31]],"batl":[[0,3.9,20.64]],"ltp":3.9,"tv":1973.53,"id":11981493}],"tv":10116.81}]}
{"op":"mcm","clk":"991850276","pt":1580553835043,"mc":[{"id":"1.168136214","rc":[{"batl":[[0,4.1,2],[1,4.2,29.04],[2,4.3,176.18]],"ltp":4.1,"tv":1925.77,"id":12925630}]}]}
{"op":"mcm","clk":"991851071","pt":1580553841080,"mc":[{"id":"1.168136214","rc":[{"trd":[[3.85,327.6]],"batb":[[0,3.8,13.41],[1,3.75,23],[2,3.7,37]],"batl":[[0,3.85,45],[1,3.9,20.64],[2,3.95,12]],"ltp":3.85,"tv":1983.53,"id":11981493}],"tv":10126.81}]}
{"op":"mcm","clk":"991851218","pt":1580553842152,"mc":[{"id":"1.168136214","rc":[{"batl":[[0,2.02,80.84]],"ltp":2.0,"tv":6217.5,"id":17336468},{"batb":[[1,3.75,20],[2,3.7,34]],"batl":[[1,3.9,22.64]],"ltp":3.85,"tv":1983.53,"id":11981493}]}]}
{"op":"mcm","clk":"991852323","pt":1580553851016,"mc":[{"id":"1.168136214","rc":[{"batl":[[0,3.85,60]],"ltp":3.85,"tv":1983.53,"id":11981493}]}]}
{"op":"mcm","clk":"991852439","pt":1580553852121,"mc":[{"id":"1.168136214","rc":[{"batl":[[1,3.9,7.64]],"ltp":3.85,"tv":1983.53,"id":11981493}]}]}
{"op":"mcm","clk":"991855322","pt":1580553875097,"mc":[{"id":"1.168136214","rc":[{"batl":[[0,3.85,45]],"ltp":3.85,"tv":1983.53,"id":11981493}]}]}
{"op":"mcm","clk":"991855554","pt":1580553877110,"mc":[{"id":"1.168136214","rc":[{"trd":[[4.1,411.44]],"batl":[[0,4.2,29.04],[1,4.3,176.18],[2,4.4,56]],"ltp":4.1,"tv":1928.3,"id":12925630},{"trd":[[2.02,427.36]],"batl":[[0,2.02,77.85]],"ltp":2.02,"tv":6220.49,"id":17336468},{"trd":[[3.8,266.02]],"batb":[[0,3.8,3.2]],"ltp":3.8,"tv":2011.94,"id":11981493}],"tv":10160.74}]}
{"op":"mcm","clk":"991856462","pt":1580553884998,"mc":[{"id":"1.168136214","rc":[{"batl":[[0,4.1,2],[1,4.2,29.04],[2,4.3,176.18]],"ltp":4.1,"tv":1928.3,"id":12925630}]}]}
{"op":"mcm","clk":"991858653","pt":1580553904118,"mc":[{"id":"1.168136214","rc":[{"trd":[[4.1,415.43]],"batb":[[0,4.1,15.16],[1,4,126.81],[2,3.95,9]],"batl":[[0,4.2,29.04],[1,4.3,176.18],[2,4.4,56]],"ltp":4.1,"tv":1932.29,"id":12925630}],"tv":10164.73}]}
{"op":"mcm","clk":"991859879","pt":1580553912954,"mc":[{"id":"1.168136214","rc":[{"trd":[[4.1,419.43]],"batb":[[0,4.1,13.16]],"ltp":4.1,"tv":1936.29,"id":12925630}],"tv":10168.73}]}
{"op":"mcm","clk":"991860010","pt":1580553914107,"mc":[{"id":"1.168136214","rc":[{"trd":[[4.1,455.42]],"batb":[[0,4,126.81],[1,3.95,9],[2,3.9,5]],"ltp":4.1,"tv":1972.28,"id":12925630},{"batb":[[0,2,21.72],[1,1.99,18.26],[2,1.98,17.08]],"batl":[[1,2.04,59.08]],"ltp":2.02,"tv":6220.49,"id":17336468},{"batb":[[0,3.8,14.63]],"ltp":3.8,"tv":2011.94,"id":11981493}],"tv":10204.73}]}
{"op":"mcm","clk":"991860118","pt":1580553914976,"mc":[{"id":"1.168136214","rc":[{"batb":[[0,4.1,10.98],[1,4,126.81],[2,3.95,9]],"ltp":4.1,"tv":1972.28,"id":12925630},{"batb":[[0,2,26.72],[1,1.99,19.05],[2,1.98,4]],"ltp":2.02,"tv":6220.49,"id":17336468},{"batb":[[0,3.8,15.04]],"ltp":3.8,"tv":2011.94,"id":11981493}]}]}
{"op":"mcm","clk":"991860907","pt":1580553921953,"mc":[{"id":"1.168136214","rc":[{"trd":[[2,1763.48]],"batb":[[0,2,24.72]],"ltp":2.0,"tv":6224.49,"id":17336468}],"tv":10208.73}]}
{"op":"mcm","clk":"991861440","pt":1580553926582,"mc":[{"id":"1.168136214","rc":[{"trd":[[2.02,431.32]],"batl":[[0,2.02,75.87]],"ltp":2.02,"tv":6228.45,"id":17336468}],"tv":10212.69}]}
{"op":"mcm","clk":"991861860","pt":1580553929884,"mc":[{"id":"1.168136214","rc":[{"trd":[[4.1,465.43]],"batb":[[0,4.1,5.98]],"ltp":4.1,"tv":1982.28,"id":12925630}],"tv":10222.69}]}
{"op":"mcm","clk":"991863571","pt":1580553944100,"mc":[{"id":"1.168136214","rc":[{"trd":[[4.1,469.43]],"batb":[[0,4.1,3.98]],"ltp":4.1,"tv":1986.28,"id":12925630}],"tv":10226.69}]}
{"op":"mcm","clk":"991865137","pt":1580553957126,"mc":[{"id":"1.168136214","rc":[{"batb":[[1,3.75,4]],"ltp":3.8,"tv":2011.94,"id":11981493}]}]}
{"op":"mcm","clk":"991865235","pt":1580553958020,"mc":[{"id":"1.168136214","rc":[{"batb":[[0,4.1,13.98]],"ltp":4.1,"tv":1986.28,"id":12925630}]}]}
{"op":"mcm","clk":"991866058","pt":1580553964132,"mc":[{"id":"1.168136214","rc":[{"trd":[[4.1,473.43]],"batb":[[0,4.1,11.98]],"ltp":4.1,"tv":1990.28,"id":12925630}],"tv":10230.69}]}
{"op":"mcm","clk":"991867356","pt":1580553974131,"mc":[{"id":"1.168136214","rc":[{"trd":[[4.1,476.78]],"batb":[[0,4.1,10.3]],"ltp":4.1,"tv":1993.64,"id":12925630}],"tv":10234.05}]}
{"op":"mcm","clk":"991867457","pt":1580553975026,"mc":[{"id":"1.168136214","rc":[{"trd":[[4.1,480.78]],"batb":[[0,4.1,8.3]],"ltp":4.1,"tv":1997.64,"id":12925630},{"trd":[[2.02,530.31]],"batl":[[0,2.02,26.37]],"ltp":2.02,"tv":6327.45,"id":17336468}],"tv":10337.04}]}
{"op":"mcm","clk":"991867577","pt":1580553976025,"mc":[{"id":"1.168136214","rc":[{"batl":[[0,2.02,61.1]],"ltp":2.02,"tv":6327.45,"id":17336468}]}]}
{"op":"mcm","clk":"991867709","pt":1580553977140,"mc":[{"id":"1.168136214","rc":[{"batl":[[1,3.9,9.64]],"ltp":3.8,"tv":2011.94,"id":11981493}]}]}
{"op":"mcm","clk":"991869217","pt":1580553990131,"mc":[{"id":"1.168136214","rc":[{"batl":[[0,2.02,43.74]],"ltp":2.02,"tv":6327.45,"id":17336468}]}]}
{"op":"mcm","clk":"991869707","pt":1580553993876,"mc":[{"id":"1.168136214","rc":[{"trd":[[4.1,484.78]],"batb":[[0,4.1,6.3]],"ltp":4.1,"tv":2001.64,"id":12925630}],"tv":10341.04}]}
{"op":"mcm","clk":"991873055","pt":1580554019850,"mc":[{"id":"1.168136214","rc":[{"batl":[[0,2.02,26.37]],"ltp":2.02,"tv":6327.45,"id":17336468}]}]}
{"op":"mcm","clk":"991873970","pt":1580554027144,"mc":[{"id":"1.168136214","rc":[{"trd":[[4.1,497.38]],"batb":[[0,4,126.81],[1,3.95,9],[2,3.9,5]],"batl":[[0,4.1,8.7],[1,4.2,29.04],[2,4.3,176.18]],"ltp":4.1,"tv":2014.24,"id":12925630},{"batb":[[0,2,29.44]],"ltp":2.02,"tv":6327.45,"id":17336468}],"tv":10353.64}]}
{"op":"mcm","clk":"991874086","pt":1580554028095,"mc":[{"id":"1.168136214","rc":[{"trd":[[4,79.58],[4.1,501.99]],"batb":[[0,4,125.12]],"batl":[[0,4.1,8.4]],"ltp":4.0,"tv":2022.22,"id":12925630},{"trd":[[2.02,534.31]],"batb":[[0,2.02,3.04],[1,2,29.44],[2,1.99,19.05]],"batl":[[0,2.04,59.82],[1,2.06,15],[2,2.08,17.55]],"ltp":2.02,"tv":6331.45,"id":17336468},{"batb":[[0,3.8,17.53]],"ltp":3.8,"tv":2011.94,"id":11981493}],"tv":10365.62}]}
{"op":"mcm","clk":"991874197","pt":1580554028995,"mc":[{"id":"1.168136214","rc":[{"trd":[[2,1767.48]],"batb":[[0,2,27.44],[1,1.99,19.05],[2,1.98,4]],"batl":[[0,2.04,55.83],[1,2.06,49.52]],"ltp":2.0,"tv":6335.45,"id":17336468}],"tv":10369.62}]}
{"op":"mcm","clk":"991874544","pt":1580554032110,"mc":[{"id":"1.168136214","rc":[{"trd":[[4.1,505.99]],"batl":[[0,4.1,6.4]],"ltp":4.1,"tv":2026.22,"id":12925630},{"trd":[[3.85,331.6]],"batl":[[0,3.85,43]],"ltp":3.85,"tv":2015.94,"id":11981493}],"tv":10377.62}]}
{"op":"mcm","clk":"991874672","pt":1580554033072,"mc":[{"id":"1.168136214","rc":[{"trd":[[2,1773.6],[2.02,544.43]],"batb":[[0,2.02,5.07],[1,2,24.38],[2,1.99,19.05]],"batl":[[0,2.04,43.67]],"ltp":2.0,"tv":6351.69,"id":17336468}],"tv":10393.86}]}
{"op":"mcm","clk":"991874760","pt":1580554033776,"mc":[{"id":"1.168136214","rc":[{"batl":[[0,4.1,8.4]],"ltp":4.1,"tv":2026.22,"id":12925630},{"trd":[[2.02,554.57]],"batb":[[0,2.02,2]],"ltp":2.02,"tv":6361.83,"id":17336468}],"tv":10404.0}]}
{"op":"mcm","clk":"991874905","pt":1580554035103,"mc":[{"id":"1.168136214","rc":[{"batl":[[0,4.1,6.4]],"ltp":4.1,"tv":2026.22,"id":12925630},{"trd":[[2.02,558.57]],"batb":[[0,2,24.38],[1,1.99,19.05],[2,1.98,4]],"ltp":2.02,"tv":6365.83,"id":17336468}],"tv":10408.0}]}
{"op":"mcm","clk":"991875247","pt":1580554037881,"mc":[{"id":"1.168136214","rc":[{"trd":[[2,1778.7],[2.02,563.67]],"batb":[[0,2,21.83]],"ltp":2.0,"tv":6376.03,"id":17336468}],"tv":10418.2}]}
{"op":"mcm","clk":"991876607","pt":1580554049110,"mc":[{"id":"1.168136214","rc":[{"batl":[[0,4.1,8.4]],"ltp":4.1,"tv":2026.22,"id":12925630},{"trd":[[2.02,642.19],[2.04,181.84]],"batb":[[0,2.02,101.82],[1,2,21.83],[2,1.99,19.05]],"batl":[[0,2.04,23.9]],"ltp":2.02,"tv":6480.09,"id":17336468}],"tv":10522.26}]}
{"op":"mcm","clk":"991876786","pt":1580554050123,"mc":[{"id":"1.168136214","rc":[{"batl":[[0,2.04,7.75]],"ltp":2.02,"tv":6480.09,"id":17336468},{"batb":[[0,3.8,14.33]],"ltp":3.85,"tv":2015.94,"id":11981493}]}]}
{"op":"mcm","clk":"991876967","pt":1580554051026,"mc":[{"id":"1.168136214","rc":[{"batb":[[1,2,45.55]],"batl":[[0,2.06,15],[1,2.08,26.55],[2,2.1,95]],"ltp":2.02,"tv":6480.09,"id":17336468}]}]}
{"op":"mcm","clk":"991877032","pt":1580554051334,"mc":[{"id":"1.168136214","rc":[{"batb":[[0,4,121.12]],"ltp":4.1,"tv":2026.22,"id":12925630}]}]}
{"op":"mcm","clk":"991887181","pt":1580554053132,"mc":[{"id":"1.168136214","rc":[{"batl":[[1,2.08,34.15]],"ltp":2.02,"tv":6480.09,"id":17336468}]}]}
{"op":"mcm","clk":"991889538","pt":1580554069911,"mc":[{"id":"1.168136214","rc":[{"batl":[[1,2.08,20.23]],"ltp":2.02,"tv":6480.09,"id":17336468}]}]}
{"op":"mcm","clk":"991891761","pt":1580554087139,"mc":[{"id":"1.168136214","rc":[{"batb":[[0,4,136.12]],"ltp":4.1,"tv":2026.22,"id":12925630}]}]}
{"op":"mcm","clk":"991892625","pt":1580554094686,"mc":[{"id":"1.168136214","rc":[{"batb":[[0,4,151.12]],"ltp":4.1,"tv":2026.22,"id":12925630},{"batl":[[0,3.85,45]],"ltp":3.85,"tv":2015.94,"id":11981493}]}]}
{"op":"mcm","clk":"991893317","pt":1580554101813,"mc":[{"id":"1.168136214","rc":[{"batb":[[0,4,156.12]],"batl":[[0,4.1,6.4]],"ltp":4.1,"tv":2026.22,"id":12925630},{"batb":[[0,2.02,96.82]],"batl":[[0,2.04,10.11],[1,2.06,27.73],[2,2.08,520.23]],"ltp":2.02,"tv":6480.09,"id":17336468},{"batb":[[0,3.8,19.33]],"batl":[[0,3.85,43],[1,3.9,7.64]],"ltp":3.85,"tv":2015.94,"id":11981493}]}]}
{"op":"mcm","clk":"991894330","pt":1580554111072,"mc":[{"id":"1.168136214","rc":[{"batb":[[0,3.8,29.33]],"ltp":3.85,"tv":2015.94,"id":11981493}]}]}
{"op":"mcm","clk":"991894434","pt":1580554112077,"mc":[{"id":"1.168136214","rc":[{"batl":[[2,2.08,512.63]],"ltp":2.02,"tv":6480.09,"id":17336468}]}]}
{"op":"mcm","clk":"991896682","pt":1580554131654,"mc":[{"id":"1.168136214","rc":[{"trd":[[4.1,518.79]],"batb":[[0,4.1,15.55],[1,4,156.12],[2,3.95,9]],"batl":[[0,4.2,29.04],[1,4.3,176.18],[2,4.4,56]],"ltp":4.1,"tv":2039.02,"id":12925630}],"tv":10535.06}]}
{"op":"mcm","clk":"991896855","pt":1580554133141,"mc":[{"id":"1.168136214","rc":[{"trd":[[2.02,646.19]],"batb":[[0,2.02,94.82]],"ltp":2.02,"tv":6484.09,"id":17336468}],"tv":10539.06}]}
{"op":"mcm","clk":"991897408","pt":1580554138128,"mc":[{"id":"1.168136214","rc":[{"batb":[[0,3.8,31.33]],"ltp":3.85,"tv":2015.94,"id":11981493}]}]}
{"op":"mcm","clk":"991897982","pt":1580554143061,"mc":[{"id":"1.168136214","rc":[{"trd":[[4.1,522.79]],"batb":[[0,4.1,13.55]],"ltp":4.1,"tv":2043.02,"id":12925630}],"tv":10543.06}]}
{"op":"mcm","clk":"991899151","pt":1580554153064,"mc":[{"id":"1.168136214","rc":[{"trd":[[4.1,526.79]],"batb":[[0,4.1,11.55]],"ltp":4.1,"tv":2047.02,"id":12925630}],"tv":10547.06}]}
{"op":"mcm","clk":"991899569","pt":1580554156144,"mc":[{"id":"1.168136214","rc":[{"trd":[[4.1,536.79]],"batb":[[0,4.1,6.55]],"ltp":4.1,"tv":2057.02,"id":12925630}],"tv":10557.06}]}
{"op":"mcm","clk":"991900153","pt":1580554160882,"mc":[{"id":"1.168136214","rc":[{"trd":[[2.02,650.19]],"batb":[[0,2.02,92.82]],"ltp":2.02,"tv":6488.09,"id":17336468}],"tv":10561.06}]}
{"op":"mcm","clk":"991902394","pt":1580554178075,"mc":[{"id":"1.168136214","rc":[{"batl":[[0,2.04,17.86]],"ltp":2.02,"tv":6488.09,"id":17336468}]}]}
{"op":"mcm","clk":"991903087","pt":1580554183073,"mc":[{"id":"1.168136214","rc":[{"trd":[[4.1,540.79]],"batb":[[0,4.1,4.55]],"ltp":4.1,"tv":2061.02,"id":12925630}],"tv":10565.06}]}
{"op":"mcm","clk":"991903301","pt":1580554184878,"mc":[{"id":"1.168136214","rc":[{"batl":[[0,2.04,21.86]],"ltp":2.02,"tv":6488.09,"id":17336468}]}]}
{"op":"mcm","clk":"991904202","pt":1580554191994,"mc":[{"id":"1.168136214","rc":[{"trd":[[4.1,544.79]],"batb":[[0,4.1,2.55]],"ltp":4.1,"tv":2065.02,"id":12925630}],"tv":10569.06}]}
{"op":"mcm","clk":"991905480","pt":1580554201092,"mc":[{"id":"1.168136214","rc":[{"trd":[[2.02,750.19]],"batb":[[0,2.02,42.82]],"ltp":2.02,"tv":6588.09,"id":17336468}],"tv":10669.06}]}
{"op":"mcm","clk":"991905724","pt":1580554203016,"mc":[{"id":"1.168136214","rc":[{"trd":[[4.1,549.89]],"batb":[[0,4.1,18.74]],"ltp":4.1,"tv":2070.12,"id":12925630}],"tv":10674.16}]}
{"op":"mcm","clk":"991908289","pt":1580554222641,"mc":[{"id":"1.168136214","rc":[{"batb":[[0,3.8,33.33]],"ltp":3.85,"tv":2015.94,"id":11981493}]}]}
{"op":"mcm","clk":"991908951","pt":1580554227958,"mc":[{"id":"1.168136214","rc":[{"trd":[[4.2,544.4],[4.3,307.27]],"batb":[[0,4.2,150.37],[1,4.1,45.23],[2,4,156.12]],"batl":[[0,4.3,167.24],[1,4.4,56],[2,4.5,3]],"ltp":4.3,"tv":2166.67,"id":12925630},{"trd":[[2.02,793.01]],"batb":[[0,2,16.83],[1,1.99,36.5],[2,1.98,4]],"ltp":2.02,"tv":6630.91,"id":17336468},{"trd":[[3.8,288.78]],"batb":[[0,3.8,10.56]],"batl":[[0,3.85,46]],"ltp":3.8,"tv":2038.71,"id":11981493}],"tv":10836.3}]}
{"op":"mcm","clk":"991909101","pt":1580554229145,"mc":[{"id":"1.168136214","rc":[{"batb":[[2,4,159.12]],"ltp":4.3,"tv":2166.67,"id":12925630}]}]}
{"op":"mcm","clk":"991909305","pt":1580554230847,"mc":[{"id":"1.168136214","rc":[{"batb":[[1,1.99,19.05]],"ltp":2.02,"tv":6630.91,"id":17336468}]}]}
{"op":"mcm","clk":"991911191","pt":1580554246066,"mc":[{"id":"1.168136214","rc":[{"batb":[[2,1.98,9]],"batl":[[0,2.02,5],[1,2.04,21.86],[2,2.06,27.73]],"ltp":2.02,"tv":6630.91,"id":17336468}]}]}
{"op":"mcm","clk":"991912664","pt":1580554258683,"mc":[{"id":"1.168136214","rc":[{"batl":[[1,4.4,106]],"ltp":4.3,"tv":2166.67,"id":12925630}]}]}
{"op":"mcm","clk":"991914577","pt":1580554273661,"mc":[{"id":"1.168136214","rc":[{"trd":[[4.2,554.4]],"batb":[[0,4.2,145.37]],"ltp":4.2,"tv":2176.67,"id":12925630}],"tv":10846.3}]}
{"op":"mcm","clk":"991915369","pt":1580554281065,"mc":[{"id":"1.168136214","rc":[{"batb":[[2,4,156.12]],"ltp":4.2,"tv":2176.67,"id":12925630}]}]}
{"op":"mcm","clk":"991916162","pt":1580554288095,"mc":[{"id":"1.168136214","rc":[{"trd":[[2,1807.91]],"batb":[[0,2,2.23]],"ltp":2.0,"tv":6660.11,"id":17336468}],"tv":10875.51}]}
{"op":"mcm","clk":"991918895","pt":1580554310030,"mc":[{"id":"1.168136214","rc":[{"batl":[[1,2.04,17.86]],"ltp":2.0,"tv":6660.11,"id":17336468}]}]}
{"op":"mcm","clk":"991919217","pt":1580554313022,"mc":[{"id":"1.168136214","rc":[{"trd":[[4.2,567.52]],"batb":[[0,4.2,137.25]],"ltp":4.2,"tv":2189.79,"id":12925630},{"trd":[[2.02,830.3],[2.04,184.38]],"batb":[[1,1.99,14.86]],"batl":[[0,2.04,16.59],[1,2.06,27.73],[2,2.08,512.63]],"ltp":2.04,"tv":6699.94,"id":17336468},{"trd":[[3.75,219.7],[3.8,299.34],[3.85,366.22]],"batb":[[0,3.75,4],[1,3.7,34],[2,3.65,20]],"batl":[[0,3.85,28.69]],"ltp":3.85,"tv":2087.89,"id":11981493}],"tv":10977.64}]}
{"op":"mcm","clk":"991919968","pt":1580554319146,"mc":[{"id":"1.168136214","rc":[{"trd":[[4.2,573.77]],"batb":[[0,4.2,126]],"ltp":4.2,"tv":2196.04,"id":12925630},{"trd":[[2.02,845.02]],"batb":[[0,2,7.55],[1,1.98,9.79],[2,1.97,148]],"ltp":2.02,"tv":6714.66,"id":17336468},{"trd":[[3.75,226.7]],"batb":[[0,3.75,3.71]],"batl":[[0,3.8,3.32],[1,3.85,28.69],[2,3.9,2]],"ltp":3.75,"tv":2094.89,"id":11981493}],"tv":11005.61}]}
{"op":"mcm","clk":"991920070","pt":1580554320050,"mc":[{"id":"1.168136214","rc":[{"batb":[[0,4.2,132]],"ltp":4.2,"tv":2196.04,"id":12925630},{"batb":[[0,2,2.23],[1,1.99,7.11],[2,1.98,9]],"ltp":2.02,"tv":6714.66,"id":17336468},{"batb":[[0,3.75,7.03]],"batl":[[0,3.85,28.69],[1,3.9,4],[2,3.95,10]],"ltp":3.75,"tv":2094.89,"id":11981493}]}]}
{"op":"mcm","clk":"991920189","pt":1580554321050,"mc":[{"id":"1.168136214","rc":[{"batb":[[1,4.1,26.49]],"ltp":4.2,"tv":2196.04,"id":12925630},{"batb":[[1,1.98,9.79],[2,1.97,148]],"ltp":2.02,"tv":6714.66,"id":17336468}]}]}
{"op":"mcm","clk":"991920467","pt":1580554323060,"mc":[{"id":"1.168136214","rc":[{"batl":[[0,4.3,169.24]],"ltp":4.2,"tv":2196.04,"id":12925630},{"batb":[[1,1.99,6.8],[2,1.98,9]],"ltp":2.02,"tv":6714.66,"id":17336468}]}]}
{"op":"mcm","clk":"991923219","pt":1580554342660,"mc":[{"id":"1.168136214","rc":[{"batb":[[1,1.98,9.79],[2,1.97,148]],"ltp":2.02,"tv":6714.66,"id":17336468},{"batb":[[0,3.75,9.03]],"ltp":3.75,"tv":2094.89,"id":11981493}]}]}
{"op":"mcm","clk":"991924806","pt":1580554355957,"mc":[{"id":"1.168136214","rc":[{"batb":[[1,1.98,22.68]],"ltp":2.02,"tv":6714.66,"id":17336468}]}]}
{"op":"mcm","clk":"991924924","pt":1580554357069,"mc":[{"id":"1.168136214","rc":[{"batb":[[1,1.99,6.98],[2,1.98,21.89]],"ltp":2.02,"tv":6714.66,"id":17336468}]}]}
{"op":"mcm","clk":"991927206","pt":1580554376974,"mc":[{"id":"1.168136214","rc":[{"batb":[[1,1.98,22.68],[2,1.97,148]],"ltp":2.02,"tv":6714.66,"id":17336468}]}]}
{"op":"mcm","clk":"991929196","pt":1580554393009,"mc":[{"id":"1.168136214","rc":[{"trd":[[2,1812.36]],"batb":[[0,1.98,22.68],[1,1.97,148],[2,1.95,6]],"ltp":2.0,"tv":6719.12,"id":17336468}],"tv":11010.06}]}
{"op":"mcm","clk":"991930207","pt":1580554401721,"mc":[{"id":"1.168136214","rc":[{"trd":[[1.98,1229.42],[1.99,665.66]],"batb":[[0,1.98,19.68]],"ltp":1.98,"tv":6735.12,"id":17336468}],"tv":11026.06}]}
{"op":"mcm","clk":"991930717","pt":1580554406105,"mc":[{"id":"1.168136214","rc":[{"batb":[[2,3.65,31]],"ltp":3.75,"tv":2094.89,"id":11981493}]}]}
{"op":"mcm","clk":"991933281","pt":1580554429025,"mc":[{"id":"1.168136214","rc":[{"trd":[[1.98,1249.42]],"batb":[[0,1.98,9.68]],"ltp":1.98,"tv":6755.12,"id":17336468}],"tv":11046.06}]}
{"op":"mcm","clk":"991933702","pt":1580554433067,"mc":[{"id":"1.168136214","rc":[{"batb":[[0,4.2,144.18]],"batl":[[0,4.3,168.24]],"ltp":4.2,"tv":2196.04,"id":12925630},{"trd":[[1.98,1289.32]],"batb":[[0,1.98,20.56],[1,1.97,153],[2,1.96,6.28]],"batl":[[1,2.06,15]],"ltp":1.98,"tv":6795.02,"id":17336468},{"batl":[[2,3.95,13]],"ltp":3.75,"tv":2094.89,"id":11981493}],"tv":11085.96}]}
{"op":"mcm","clk":"991933780","pt":1580554433758,"mc":[{"id":"1.168136214","rc":[{"batb":[[0,4.2,155.23]],"ltp":4.2,"tv":2196.04,"id":12925630},{"batb":[[0,1.99,5.29],[1,1.98,56.72],[2,1.97,153]],"batl":[[0,2.02,12.64],[1,2.04,16.59],[2,2.06,15]],"ltp":1.98,"tv":6795.02,"id":17336468},{"batb":[[0,3.8,32.3],[1,3.75,9.03],[2,3.7,34]],"ltp":3.75,"tv":2094.89,"id":11981493}]}]}
{"op":"mcm","clk":"991933917","pt":1580554435068,"mc":[{"id":"1.168136214","rc":[{"batb":[[0,1.98,56.72],[1,1.97,153],[2,1.95,6]],"batl":[[0,2,7.91],[1,2.02,21.64],[2,2.04,8.84]],"ltp":1.98,"tv":6795.02,"id":17336468},{"batl":[[0,3.85,25.69]],"ltp":3.75,"tv":2094.89,"id":11981493}]}]}
{"op":"mcm","clk":"991934824","pt":1580554443083,"mc":[{"id":"1.168136214","rc":[{"batb":[[0,4.2,173.46]],"ltp":4.2,"tv":2196.04,"id":12925630}]}]}
{"op":"mcm","clk":"991935173","pt":1580554446002,"mc":[{"id":"1.168136214","rc":[{"batl":[[0,1.99,19.95],[1,2,7.91],[2,2.02,21.64]],"ltp":1.98,"tv":6795.02,"id":17336468}]}]}
{"op":"mcm","clk":"991935299","pt":1580554447068,"mc":[{"id":"1.168136214","rc":[{"batb":[[2,1.96,5.03]],"batl":[[0,2,7.91],[1,2.02,21.64],[2,2.04,8.84]],"ltp":1.98,"tv":6795.02,"id":17336468}]}]}
{"op":"mcm","clk":"991935768","pt":1580554450981,"mc":[{"id":"1.168136214","rc":[{"batl":[[0,3.85,30.69]],"ltp":3.75,"tv":2094.89,"id":11981493}]}]}
{"op":"mcm","clk":"991936809","pt":1580554459108,"mc":[{"id":"1.168136214","rc":[{"trd":[[3.8,309.34]],"batb":[[0,3.8,27.3]],"ltp":3.8,"tv":2104.89,"id":11981493}],"tv":11095.96}]}
{"op":"mcm","clk":"991937053","pt":1580554461118,"mc":[{"id":"1.168136214","rc":[{"batb":[[0,1.99,2],[1,1.98,56.72],[2,1.97,153]],"ltp":1.98,"tv":6795.02,"id":17336468}]}]}
{"op":"mcm","clk":"991937426","pt":1580554464077,"mc":[{"id":"1.168136214","rc":[{"batb":[[0,1.98,56.72],[1,1.97,153],[2,1.96,5.03]],"ltp":1.98,"tv":6795.02,"id":17336468}]}]}
{"op":"mcm","clk":"991937882","pt":1580554468113,"mc":[{"id":"1.168136214","rc":[{"batl":[[0,3.85,33.69]],"ltp":3.8,"tv":2104.89,"id":11981493}]}]}
{"op":"mcm","clk":"991938099","pt":1580554469809,"mc":[{"id":"1.168136214","rc":[{"trd":[[4.3,387.27]],"batl":[[0,4.3,128.24]],"ltp":4.3,"tv":2276.04,"id":12925630}],"tv":11175.96}]}
{"op":"mcm","clk":"991938393","pt":1580554472020,"mc":[{"id":"1.168136214","rc":[{"batb":[[2,4,159.12]],"ltp":4.3,"tv":2276.04,"id":12925630}]}]}
{"op":"mcm","clk":"991938516","pt":1580554473026,"mc":[{"id":"1.168136214","rc":[{"batl":[[0,4.3,138.24]],"ltp":4.3,"tv":2276.04,"id":12925630}]}]}
{"op":"mcm","clk":"991939308","pt":1580554479052,"mc":[{"id":"1.168136214","rc":[{"trd":[[1.98,1297.32]],"batb":[[0,1.98,52.72]],"ltp":1.98,"tv":6803.02,"id":17336468}],"tv":11183.96}]}
{"op":"mcm","clk":"991940438","pt":1580554487787,"mc":[{"id":"1.168136214","rc":[{"trd":[[3.85,376.22]],"batl":[[0,3.85,28.69]],"ltp":3.85,"tv":2114.89,"id":11981493}],"tv":11193.96}]}
{"op":"mcm","clk":"991940546","pt":1580554488996,"mc":[{"id":"1.168136214","rc":[{"batl":[[1,3.9,10]],"ltp":3.85,"tv":2114.89,"id":11981493}]}]}
{"op":"mcm","clk":"991941980","pt":1580554500975,"mc":[{"id":"1.168136214","rc":[{"batl":[[0,2,16.43]],"ltp":1.98,"tv":6803.02,"id":17336468}]}]}
{"op":"mcm","clk":"991942223","pt":1580554502768,"mc":[{"id":"1.168136214","rc":[{"batl":[[0,2,8.52]],"ltp":1.98,"tv":6803.02,"id":17336468}]}]}
{"op":"mcm","clk":"991943167","pt":1580554509996,"mc":[{"id":"1.168136214","rc":[{"batb":[[0,1.99,2],[1,1.98,52.72],[2,1.97,153]],"ltp":1.98,"tv":6803.02,"id":17336468}]}]}
{"op":"mcm","clk":"991943650","pt":1580554513104,"mc":[{"id":"1.168136214","rc":[{"batb":[[0,1.98,52.72],[1,1.97,153],[2,1.96,5.03]],"ltp":1.98,"tv":6803.02,"id":17336468}]}]}
{"op":"mcm","clk":"991944890","pt":1580554523054,"mc":[{"id":"1.168136214","rc":[{"trd":[[1.98,1301.32]],"batb":[[0,1.98,50.72]],"ltp":1.98,"tv":6807.02,"id":17336468}],"tv":11197.96}]}
{"op":"mcm","clk":"991946047","pt":1580554530696,"mc":[{"id":"1.168136214","rc":[{"batb":[[0,1.98,75.72]],"ltp":1.98,"tv":6807.02,"id":17336468}]}]}
{"op":"mcm","clk":"991946276","pt":1580554532066,"mc":[{"id":"1.168136214","rc":[{"batb":[[0,4.2,155.23]],"ltp":4.3,"tv":2276.04,"id":12925630}]}]}
{"op":"mcm","clk":"991956290","pt":1580554606043,"mc":[{"id":"1.168136214","rc":[{"batb":[[1,4.1,58.79]],"ltp":4.3,"tv":2276.04,"id":12925630}]}]}
{"op":"mcm","clk":"991956571","pt":1580554608057,"mc":[{"id":"1.168136214","rc":[{"batl":[[0,4.3,140.24]],"ltp":4.3,"tv":2276.04,"id":12925630}]}]}
{"op":"mcm","clk":"991958367","pt":1580554622056,"mc":[{"id":"1.168136214","rc":[{"batl":[[0,2,8.77]],"ltp":1.98,"tv":6807.02,"id":17336468}]}]}
{"op":"mcm","clk":"991958770","pt":1580554624973,"mc":[{"id":"1.168136214","rc":[{"trd":[[4.2,686.21]],"batb":[[0,4.2,99.01]],"ltp":4.2,"tv":2388.48,"id":12925630}],"tv":11310.4}]}
{"op":"mcm","clk":"991959762","pt":1580554633063,"mc":[{"id":"1.168136214","rc":[{"batb":[[2,4,156.12]],"ltp":4.2,"tv":2388.48,"id":12925630}]}]}
{"op":"mcm","clk":"991960608","pt":1580554640998,"mc":[{"id":"1.168136214","rc":[{"batl":[[0,3.85,28.82]],"ltp":3.85,"tv":2114.89,"id":11981493}]}]}
{"op":"mcm","clk":"991962074","pt":1580554652990,"mc":[{"id":"1.168136214","rc":[{"trd":[[4.2,782.91]],"batb":[[0,4.2,50.66]],"ltp":4.2,"tv":2485.18,"id":12925630}],"tv":11407.1}]}
{"op":"mcm","clk":"991962788","pt":1580554659021,"mc":[{"id":"1.168136214","rc":[{"trd":[[4.2,881.05]],"batb":[[0,4.1,58.79],[1,4,156.12],[2,3.95,12]],"batl":[[0,4.3,140.36]],"ltp":4.2,"tv":2583.32,"id":12925630},{"trd":[[2,1829.89],[2.02,894.74],[2.04,189.1]],"batb":[[0,1.99,6.22],[1,1.98,75.72],[2,1.97,153]],"batl":[[0,2.04,6.48],[1,2.06,27.73],[2,2.08,503.63]],"ltp":2.04,"tv":6878.99,"id":17336468},{"trd":[[3.75,231.31],[3.8,363.92]],"batb":[[0,3.75,4.98],[1,3.7,34],[2,3.65,31]],"batl":[[0,3.8,27.27],[1,3.85,28.82],[2,3.9,10]],"ltp":3.75,"tv":2174.08,"id":11981493}],"tv":11636.4}]}
{"op":"mcm","clk":"991962909","pt":1580554660090,"mc":[{"id":"1.168136214","rc":[{"batl":[[0,4.2,1.68],[1,4.3,140.36],[2,4.4,106]],"ltp":4.2,"tv":2583.32,"id":12925630}]}]}
{"op":"mcm","clk":"991963336","pt":1580554664135,"mc":[{"id":"1.168136214","rc":[{"batl":[[0,4.3,140.36],[1,4.4,106],[2,4.5,3]],"ltp":4.2,"tv":2583.32,"id":12925630}]}]}
{"op":"mcm","clk":"991963676","pt":1580554667099,"mc":[{"id":"1.168136214","rc":[{"trd":[[4.1,553.25]],"batb":[[0,4.1,57.11]],"ltp":4.1,"tv":2586.68,"id":12925630}],"tv":11639.76}]}
{"op":"mcm","clk":"991965366","pt":1580554684125,"mc":[{"id":"1.168136214","rc":[{"batb":[[2,3.65,34]],"ltp":3.75,"tv":2174.08,"id":11981493}]}]}
{"op":"mcm","clk":"991965582","pt":1580554686037,"mc":[{"id":"1.168136214","rc":[{"trd":[[1.99,675.64],[2,1829.9]],"batb":[[0,1.99,1.22]],"ltp":1.99,"tv":6888.98,"id":17336468}],"tv":11649.75}]}
{"op":"mcm","clk":"991966781","pt":1580554698149,"mc":[{"id":"1.168136214","rc":[{"trd":[[4.1,563.25]],"ltp":4.1,"tv":2596.68,"id":12925630},{"batb":[[0,1.99,6]],"ltp":1.99,"tv":6888.98,"id":17336468}],"tv":11659.75}]}
{"op":"mcm","clk":"991967382","pt":1580554704055,"mc":[{"id":"1.168136214","rc":[{"batb":[[0,3.75,8.98]],"ltp":3.75,"tv":2174.08,"id":11981493}]}]}
{"op":"mcm","clk":"991968026","pt":1580554710056,"mc":[{"id":"1.168136214","rc":[{"batl":[[0,2,2],[1,2.02,7.16],[2,2.04,6.48]],"ltp":1.99,"tv":6888.98,"id":17336468}]}]}
{"op":"mcm","clk":"991968673","pt":1580554715974,"mc":[{"id":"1.168136214","rc":[{"batb":[[0,1.99,17.72]],"batl":[[2,2.04,15.13]],"ltp":1.99,"tv":6888.98,"id":17336468}]}]}
{"op":"mcm","clk":"991968906","pt":1580554718080,"mc":[{"id":"1.168136214","rc":[{"batl":[[2,2.04,6.48]],"ltp":1.99,"tv":6888.98,"id":17336468}]}]}
{"op":"mcm","clk":"991977163","pt":1580554789068,"mc":[{"id":"1.168136214","rc":[{"trd":[[2,1833.9]],"batl":[[0,2.02,7.16],[1,2.04,6.48],[2,2.06,15]],"ltp":2.0,"tv":6892.98,"id":17336468}],"tv":11663.75}]}
{"op":"mcm","clk":"991977280","pt":1580554790125,"mc":[{"id":"1.168136214","rc":[{"batl":[[0,2.04,6.48],[1,2.06,15],[2,2.08,503.63]],"ltp":2.0,"tv":6892.98,"id":17336468}]}]}
{"op":"mcm","clk":"991979588","pt":1580554806065,"mc":[{"id":"1.168136214","rc":[{"batb":[[0,2,3.36],[1,1.99,17.72],[2,1.98,75.72]],"ltp":2.0,"tv":6892.98,"id":17336468}]}]}
{"op":"mcm","clk":"991980349","pt":1580554811066,"mc":[{"id":"1.168136214","rc":[{"batb":[[1,1.99,28.92]],"ltp":2.0,"tv":6892.98,"id":17336468}]}]}
{"op":"mcm","clk":"991990393","pt":1580554889059,"mc":[{"id":"1.168136214","rc":[{"batb":[[0,2,3.44]],"batl":[[1,2.06,27.73]],"ltp":2.0,"tv":6892.98,"id":17336468}]}]}
{"op":"mcm","clk":"991991322","pt":1580554896074,"mc":[{"id":"1.168136214","rc":[{"batl":[[0,3.8,32.27]],"ltp":3.75,"tv":2174.08,"id":11981493}]}]}
{"op":"mcm","clk":"991993141","pt":1580554910991,"mc":[{"id":"1.168136214","rc":[{"trd":[[3.75,255.27]],"batb":[[0,3.7,34],[1,3.65,34],[2,3.6,89.67]],"batl":[[0,3.75,7.48],[1,3.8,32.27],[2,3.85,28.82]],"ltp":3.75,"tv":2198.04,"id":11981493}],"tv":11687.71}]}
{"op":"mcm","clk":"991995312","pt":1580554926048,"mc":[{"id":"1.168136214","rc":[{"batb":[[0,4.2,5.03],[1,4.1,57.11],[2,4,156.12]],"ltp":4.1,"tv":2596.68,"id":12925630},{"batb":[[0,2,9.47]],"batl":[[2,2.08,509.63]],"ltp":2.0,"tv":6892.98,"id":17336468},{"batb":[[2,3.6,92.67]],"batl":[[0,3.75,27.74],[1,3.8,36.27]],"ltp":3.75,"tv":2198.04,"id":11981493}]}]}
{"op":"mcm","clk":"991996023","pt":1580554931050,"mc":[{"id":"1.168136214","rc":[{"batl":[[0,3.75,31.74]],"ltp":3.75,"tv":2198.04,"id":11981493}]}]}
{"op":"mcm","clk":"991997926","pt":1580554942047,"mc":[{"id":"1.168136214","rc":[{"batl":[[0,3.75,35.44]],"ltp":3.75,"tv":2198.04,"id":11981493}]}]}
{"op":"mcm","clk":"992012617","pt":1580554973153,"mc":[{"id":"1.168136214","rc":[{"trd":[[4.2,887.94]],"batb":[[0,4.2,2.14]],"ltp":4.2,"tv":2603.57,"id":12925630},{"trd":[[2.04,208.58]],"batl":[[0,2.04,5.29]],"ltp":2.04,"tv":6912.46,"id":17336468},{"trd":[[3.7,211.81]],"batb":[[0,3.7,30.41]],"batl":[[2,3.85,30.82]],"ltp":3.7,"tv":2201.63,"id":11981493}],"tv":11717.67}]}
{"op":"mcm","clk":"992015519","pt":1580554991075,"mc":[{"id":"1.168136214","rc":[{"batb":[[0,2,69.47]],"ltp":2.04,"tv":6912.46,"id":17336468}]}]}
{"op":"mcm","clk":"992015690","pt":1580554992090,"mc":[{"id":"1.168136214","rc":[{"batb":[[0,4.1,57.11],[1,4,156.12],[2,3.95,9]],"ltp":4.2,"tv":2603.57,"id":12925630}]}]}
{"op":"mcm","clk":"992021039","pt":1580555027869,"mc":[{"id":"1.168136214","rc":[{"batb":[[0,2,71.47]],"ltp":2.04,"tv":6912.46,"id":17336468}]}]}
{"op":"mcm","clk":"992025053","pt":1580555050054,"mc":[{"id":"1.168136214","rc":[{"batl":[[0,4.2,3.05],[1,4.3,140.36],[2,4.4,106]],"ltp":4.2,"tv":2603.57,"id":12925630},{"batb":[[2,1.98,78.72]],"batl":[[0,2.06,27.73],[1,2.08,9.63],[2,2.1,95]],"ltp":2.04,"tv":6912.46,"id":17336468}]}]}
{"op":"mcm","clk":"992027686","pt":1580555066092,"mc":[{"id":"1.168136214","rc":[{"trd":[[4.1,567.25]],"batb":[[0,4.1,55.11]],"batl":[[1,4.3,138.36]],"ltp":4.1,"tv":2607.57,"id":12925630}],"tv":11721.67}]}
{"op":"mcm","clk":"992029211","pt":1580555074143,"mc":[{"id":"1.168136214","rc":[{"batl":[[0,3.75,15.18]],"ltp":3.7,"tv":2201.63,"id":11981493}]}]}
{"op":"mcm","clk":"992029388","pt":1580555075053,"mc":[{"id":"1.168136214","rc":[{"trd":[[4.1,577.25]],"batb":[[0,4.1,50.11]],"ltp":4.1,"tv":2617.57,"id":12925630}],"tv":11731.67}]}
{"op":"mcm","clk":"992029604","pt":1580555076050,"mc":[{"id":"1.168136214","rc":[{"batb":[[0,4.1,45.11]],"batl":[[0,4.2,12.14]],"ltp":4.1,"tv":2617.57,"id":12925630}]}]}
{"op":"mcm","clk":"992029796","pt":1580555077061,"mc":[{"id":"1.168136214","rc":[{"batb":[[1,1.99,6]],"ltp":2.04,"tv":6912.46,"id":17336468}]}]}
{"op":"mcm","clk":"992031172","pt":1580555084749,"mc":[{"id":"1.168136214","rc":[{"trd":[[4.1,581.25]],"batb":[[0,4.1,43.11]],"ltp":4.1,"tv":2621.57,"id":12925630}],"tv":11735.67}]}
{"op":"mcm","clk":"992034602","pt":1580555103813,"mc":[{"id":"1.168136214","rc":[{"trd":[[4.2,912.27]],"batl":[[0,4.2,2.97]],"ltp":4.2,"tv":2645.9,"id":12925630}],"tv":11760.0}]}
{"op":"mcm","clk":"992034868","pt":1580555105086,"mc":[{"id":"1.168136214","rc":[{"trd":[[4.1,585.25]],"batb":[[0,4.1,41.11]],"ltp":4.1,"tv":2649.9,"id":12925630}],"tv":11764.0}]}
{"op":"mcm","clk":"992038119","pt":1580555123721,"mc":[{"id":"1.168136214","rc":[{"trd":[[4.1,589.25]],"batb":[[0,4.1,39.11]],"ltp":4.1,"tv":2653.9,"id":12925630}],"tv":11768.0}]}
{"op":"mcm","clk":"992042803","pt":1580555153072,"mc":[{"id":"1.168136214","rc":[{"trd":[[4.1,593.25]],"batb":[[0,4.1,37.11]],"ltp":4.1,"tv":2657.9,"id":12925630}],"tv":11772.0}]}
{"op":"mcm","clk":"992044278","pt":1580555162030,"mc":[{"id":"1.168136214","rc":[{"batb":[[2,1.98,53.72]],"ltp":2.04,"tv":6912.46,"id":17336468}]}]}
{"op":"mcm","clk":"992044442","pt":1580555162949,"mc":[{"id":"1.168136214","rc":[{"trd":[[4.1,597.25]],"batb":[[0,4.1,35.11]],"ltp":4.1,"tv":2661.9,"id":12925630}],"tv":11776.0}]}
{"op":"mcm","clk":"992047289","pt":1580555181151,"mc":[{"id":"1.168136214","rc":[{"trd":[[4.2,916.27]],"batl":[[0,4.2,20.97]],"ltp":4.2,"tv":2665.9,"id":12925630}],"tv":11780.0}]}
{"op":"mcm","clk":"992047420","pt":1580555181951,"mc":[{"id":"1.168136214","rc":[{"trd":[[4.1,601.25]],"batb":[[0,4.1,33.11]],"ltp":4.1,"tv":2669.9,"id":12925630}],"tv":11784.0}]}
{"op":"mcm","clk":"992048277","pt":1580555187055,"mc":[{"id":"1.168136214","rc":[{"batl":[[2,3.85,10.13]],"ltp":3.7,"tv":2201.63,"id":11981493}]}]}
{"op":"mcm","clk":"992050504","pt":1580555200077,"mc":[{"id":"1.168136214","rc":[{"batb":[[1,3.65,65]],"batl":[[0,3.75,7.7]],"ltp":3.7,"tv":2201.63,"id":11981493}]}]}
{"op":"mcm","clk":"992050819","pt":1580555202076,"mc":[{"id":"1.168136214","rc":[{"trd":[[4.1,605.25]],"batb":[[0,4.1,31.11]],"ltp":4.1,"tv":2673.9,"id":12925630}],"tv":11788.0}]}
{"op":"mcm","clk":"992055625","pt":1580555232105,"mc":[{"id":"1.168136214","rc":[{"trd":[[4.1,609.25]],"batb":[[0,4.1,29.11]],"ltp":4.1,"tv":2677.9,"id":12925630}],"tv":11792.0}]}
{"op":"mcm","clk":"992059419","pt":1580555251847,"mc":[{"id":"1.168136214","rc":[{"trd":[[4.1,613.25]],"batb":[[0,4.1,27.11]],"ltp":4.1,"tv":2681.9,"id":12925630}],"tv":11796.0}]}
{"op":"mcm","clk":"992060757","pt":1580555259015,"mc":[{"id":"1.168136214","rc":[{"trd":[[2,1837.75],[2.02,894.91]],"batb":[[0,2,69.47]],"ltp":2.0,"tv":6916.47,"id":17336468}],"tv":11800.01}]}
{"op":"mcm","clk":"992061280","pt":1580555262116,"mc":[{"id":"1.168136214","rc":[{"trd":[[4.1,617.25]],"batb":[[0,4.1,25.11]],"ltp":4.1,"tv":2685.9,"id":12925630}],"tv":11804.01}]}
{"op":"mcm","clk":"992063032","pt":1580555271873,"mc":[{"id":"1.168136214","rc":[{"trd":[[4.1,621.25]],"batb":[[0,4.1,23.11]],"ltp":4.1,"tv":2689.9,"id":12925630}],"tv":11808.01}]}
{"op":"mcm","clk":"992063420","pt":1580555273978,"mc":[{"id":"1.168136214","rc":[{"trd":[[3.7,251.81]],"batb":[[0,3.7,10.41]],"ltp":3.7,"tv":2241.63,"id":11981493}],"tv":11848.01}]}
{"op":"mcm","clk":"992064766","pt":1580555282089,"mc":[{"id":"1.168136214","rc":[{"trd":[[4.1,625.25]],"batb":[[0,4.1,21.11]],"ltp":4.1,"tv":2693.9,"id":12925630}],"tv":11852.01}]}
{"op":"mcm","clk":"992067664","pt":1580555298122,"mc":[{"id":"1.168136214","rc":[{"trd":[[2,1841.74]],"batb":[[0,2,67.47]],"ltp":2.0,"tv":6920.47,"id":17336468}],"tv":11856.0}]}
{"op":"mcm","clk":"992068599","pt":1580555303140,"mc":[{"id":"1.168136214","rc":[{"trd":[[4.1,631.25]],"batb":[[0,4.1,18.11]],"ltp":4.1,"tv":2699.9,"id":12925630}],"tv":11862.0}]}
{"op":"mcm","clk":"992068960","pt":1580555305126,"mc":[{"id":"1.168136214","rc":[{"trd":[[2.06,111.82]],"batl":[[0,2.06,24.73]],"ltp":2.06,"tv":6926.47,"id":17336468}],"tv":11868.0}]}
{"op":"mcm","clk":"992070373","pt":1580555313930,"mc":[{"id":"1.168136214","rc":[{"trd":[[3.7,255.81]],"batb":[[0,3.7,8.41]],"ltp":3.7,"tv":2245.63,"id":11981493}],"tv":11872.0}]}
{"op":"mcm","clk":"992070565","pt":1580555315109,"mc":[{"id":"1.168136214","rc":[{"batb":[[0,3.7,11.41]],"ltp":3.7,"tv":2245.63,"id":11981493}]}]}
{"op":"mcm","clk":"992070721","pt":1580555316128,"mc":[{"id":"1.168136214","rc":[{"trd":[[2.02,903.65]],"batb":[[0,2.02,11.43],[1,2,67.47],[2,1.99,6]],"ltp":2.02,"tv":6935.21,"id":17336468},{"batb":[[1,3.65,73.45]],"ltp":3.7,"tv":2245.63,"id":11981493}],"tv":11880.74}]}
{"op":"mcm","clk":"992070855","pt":1580555316941,"mc":[{"id":"1.168136214","rc":[{"trd":[[2.02,920.97]],"batb":[[0,2.02,2.77]],"ltp":2.02,"tv":6952.53,"id":17336468}],"tv":11898.06}]}
{"op":"mcm","clk":"992071055","pt":1580555318127,"mc":[{"id":"1.168136214","rc":[{"batl":[[1,2.08,18.17]],"ltp":2.02,"tv":6952.53,"id":17336468}]}]}
{"op":"mcm","clk":"992075023","pt":1580555340756,"mc":[{"id":"1.168136214","rc":[{"trd":[[4.1,635.25]],"batb":[[0,4.1,16.11]],"ltp":4.1,"tv":2703.9,"id":12925630}],"tv":11902.06}]}
{"op":"mcm","clk":"992075605","pt":1580555344049,"mc":[{"id":"1.168136214","rc":[{"trd":[[4.1,674.51]],"batb":[[0,4,156.12],[1,3.95,9],[2,3.9,5]],"batl":[[0,4.1,53.85],[1,4.2,20.97],[2,4.3,138.36]],"ltp":4.1,"tv":2743.16,"id":12925630},{"trd":[[2.02,932.67],[2.04,222.73]],"batb":[[0,2.02,6]],"batl":[[0,2.06,17.73]],"ltp":2.02,"tv":6978.38,"id":17336468},{"trd":[[3.75,262.97]],"batl":[[0,3.8,36.27],[1,3.85,10.13],[2,3.9,10]],"ltp":3.75,"tv":2253.33,"id":11981493}],"tv":11974.87}]}
{"op":"mcm","clk":"992075783","pt":1580555345131,"mc":[{"id":"1.168136214","rc":[{"batl":[[0,4.1,51.85]],"ltp":4.1,"tv":2743.16,"id":12925630},{"batl":[[0,2.06,23.73]],"ltp":2.02,"tv":6978.38,"id":17336468},{"batb":[[0,3.75,6.04],[1,3.7,11.41],[2,3.65,73.45]],"batl":[[0,3.8,32.27]],"ltp":3.75,"tv":2253.33,"id":11981493}]}]}
{"op":"mcm","clk":"992076805","pt":1580555351080,"mc":[{"id":"1.168136214","rc":[{"batl":[[0,4.1,55.85]],"ltp":4.1,"tv":2743.16,"id":12925630},{"batl":[[0,2.06,17.73]],"ltp":2.02,"tv":6978.38,"id":17336468},{"batb":[[0,3.75,3]],"ltp":3.75,"tv":2253.33,"id":11981493}]}]}
{"op":"mcm","clk":"992077836","pt":1580555357065,"mc":[{"id":"1.168136214","rc":[{"batb":[[1,3.95,12]],"ltp":4.1,"tv":2743.16,"id":12925630},{"trd":[[2.02,942.99]],"batl":[[0,2.06,24.73]],"ltp":2.02,"tv":6988.7,"id":17336468}],"tv":11985.19}]}
{"op":"mcm","clk":"992079085","pt":1580555363898,"mc":[{"id":"1.168136214","rc":[{"trd":[[2.02,944.95]],"batb":[[0,2.02,5.02]],"ltp":2.02,"tv":6990.66,"id":17336468}],"tv":11987.15}]}
{"op":"mcm","clk":"992082323","pt":1580555381136,"mc":[{"id":"1.168136214","rc":[{"batb":[[0,2.04,24.03],[1,2.02,5.02],[2,2,67.47]],"ltp":2.02,"tv":6990.66,"id":17336468}]}]}
{"op":"mcm","clk":"992085868","pt":1580555399967,"mc":[{"id":"1.168136214","rc":[{"trd":[[4,119.58]],"batb":[[0,4,136.12]],"ltp":4.0,"tv":2783.16,"id":12925630},{"batb":[[0,2.04,30.03]],"ltp":2.02,"tv":6990.66,"id":17336468}],"tv":12027.15}]}
{"op":"mcm","clk":"992086007","pt":1580555400661,"mc":[{"id":"1.168136214","rc":[{"batl":[[1,2.08,27.79]],"ltp":2.02,"tv":6990.66,"id":17336468}]}]}
{"op":"mcm","clk":"992086653","pt":1580555403862,"mc":[{"id":"1.168136214","rc":[{"batl":[[1,2.08,127.79]],"ltp":2.02,"tv":6990.66,"id":17336468}]}]}
{"op":"mcm","clk":"992086894","pt":1580555405099,"mc":[{"id":"1.168136214","rc":[{"batb":[[0,2.04,24.03]],"ltp":2.02,"tv":6990.66,"id":17336468}]}]}
{"op":"mcm","clk":"992089414","pt":1580555419052,"mc":[{"id":"1.168136214","rc":[{"batl":[[2,4.3,148.36]],"ltp":4.0,"tv":2783.16,"id":12925630}]}]}
{"op":"mcm","clk":"992089551","pt":1580555419748,"mc":[{"id":"1.168136214","rc":[{"batl":[[1,2.08,27.79]],"ltp":2.02,"tv":6990.66,"id":17336468}]}]}
{"op":"mcm","clk":"992093272","pt":1580555439597,"mc":[{"id":"1.168136214","rc":[{"trd":[[4,136.39]],"batb":[[0,4,127.71]],"ltp":4.0,"tv":2799.97,"id":12925630}],"tv":12043.96}]}
{"op":"mcm","clk":"992093559","pt":1580555441009,"mc":[{"id":"1.168136214","rc":[{"trd":[[4,136.97]],"batb":[[0,4,97.71]],"ltp":4.0,"tv":2800.55,"id":12925630}],"tv":12044.54}]}
{"op":"mcm","clk":"992093771","pt":1580555442107,"mc":[{"id":"1.168136214","rc":[{"batb":[[0,4,92.71]],"ltp":4.0,"tv":2800.55,"id":12925630},{"batb":[[0,2.04,29.03]],"ltp":2.02,"tv":6990.66,"id":17336468}]}]}
{"op":"mcm","clk":"992098676","pt":1580555468147,"mc":[{"id":"1.168136214","rc":[{"batb":[[0,4,77.71],[2,3.9,20]],"ltp":4.0,"tv":2800.55,"id":12925630}]}]}
{"op":"mcm","clk":"992099453","pt":1580555472024,"mc":[{"id":"1.168136214","rc":[{"trd":[[4.1,682.95]],"batl":[[0,4.1,51.63]],"ltp":4.1,"tv":2808.99,"id":12925630},{"batb":[[0,2.04,37.52]],"ltp":2.02,"tv":6990.66,"id":17336468},{"trd":[[3.7,287.98],[3.75,268.97]],"batb":[[0,3.65,73.45],[1,3.6,92.67],[2,3.55,20]],"batl":[[0,3.7,30.09],[1,3.8,32.27],[2,3.85,10.13]],"ltp":3.7,"tv":2291.5,"id":11981493}],"tv":12091.16}]}
{"op":"mcm","clk":"992099582","pt":1580555472737,"mc":[{"id":"1.168136214","rc":[{"batb":[[0,4,84.71]],"batl":[[0,4.1,49.63]],"ltp":4.1,"tv":2808.99,"id":12925630},{"batl":[[0,2.06,17.73]],"ltp":2.02,"tv":6990.66,"id":17336468},{"batl":[[1,3.75,5.06],[2,3.8,37.27]],"ltp":3.7,"tv":2291.5,"id":11981493}]}]}
{"op":"mcm","clk":"992099740","pt":1580555473770,"mc":[{"id":"1.168136214","rc":[{"batb":[[0,4,69.71],[2,3.9,35]],"ltp":4.1,"tv":2808.99,"id":12925630}]}]}
{"op":"mcm","clk":"992100161","pt":1580555476155,"mc":[{"id":"1.168136214","rc":[{"trd":[[3.65,112.6]],"batb":[[0,3.65,43.36]],"batl":[[0,3.75,5.06],[1,3.8,37.27],[2,3.85,10.13]],"ltp":3.65,"tv":2351.68,"id":11981493}],"tv":12151.34}]}
{"op":"mcm","clk":"992100309","pt":1580555476959,"mc":[{"id":"1.168136214","rc":[{"batb":[[0,4,62.71]],"batl":[[0,4.1,51.63]],"ltp":4.1,"tv":2808.99,"id":12925630},{"batb":[[0,3.7,3.08],[1,3.65,43.36],[2,3.6,92.67]],"batl":[[0,3.8,32.27],[1,3.85,10.13],[2,3.9,10]],"ltp":3.65,"tv":2351.68,"id":11981493}]}]}
{"op":"mcm","clk":"992101355","pt":1580555482106,"mc":[{"id":"1.168136214","rc":[{"batb":[[2,2,75.34]],"ltp":2.02,"tv":6990.66,"id":17336468}]}]}
{"op":"mcm","clk":"992102741","pt":1580555488149,"mc":[{"id":"1.168136214","rc":[{"trd":[[4,152.97]],"batb":[[0,4,54.71]],"ltp":4.0,"tv":2824.99,"id":12925630}],"tv":12167.34}]}
{"op":"mcm","clk":"992102967","pt":1580555489135,"mc":[{"id":"1.168136214","rc":[{"batl":[[0,4.1,54.84]],"ltp":4.0,"tv":2824.99,"id":12925630}]}]}
{"op":"mcm","clk":"992103468","pt":1580555491124,"mc":[{"id":"1.168136214","rc":[{"trd":[[4.1,702.47]],"batl":[[0,4.1,45.08]],"ltp":4.1,"tv":2844.51,"id":12925630}],"tv":12186.86}]}
{"op":"mcm","clk":"992107996","pt":1580555511127,"mc":[{"id":"1.168136214","rc":[{"batb":[[2,3.9,65]],"ltp":4.1,"tv":2844.51,"id":12925630}]}]}
{"op":"mcm","clk":"992110447","pt":1580555523091,"mc":[{"id":"1.168136214","rc":[{"batl":[[0,4.1,65.08]],"ltp":4.1,"tv":2844.51,"id":12925630}]}]}
{"op":"mcm","clk":"992110870","pt":1580555525097,"mc":[{"id":"1.168136214","rc":[{"batl":[[0,3.75,20.26],[1,3.8,32.27],[2,3.85,10.13]],"ltp":3.65,"tv":2351.68,"id":11981493}]}]}
{"op":"mcm","clk":"992111049","pt":1580555525914,"mc":[{"id":"1.168136214","rc":[{"batb":[[0,4,61.71]],"ltp":4.1,"tv":2844.51,"id":12925630},{"batl":[[1,3.8,37.27]],"ltp":3.65,"tv":2351.68,"id":11981493}]}]}
{"op":"mcm","clk":"992111737","pt":1580555529013,"mc":[{"id":"1.168136214","rc":[{"trd":[[2.04,262.73]],"batb":[[0,2.04,17.52]],"ltp":2.04,"tv":7030.66,"id":17336468}],"tv":12226.86}]}
{"op":"mcm","clk":"992117444","pt":1580555556972,"mc":[{"id":"1.168136214","rc":[{"trd":[[4.1,727.95]],"batl":[[0,4.1,52.34]],"ltp":4.1,"tv":2869.99,"id":12925630}],"tv":12252.34}]}
{"op":"mcm","clk":"992118332","pt":1580555561154,"mc":[{"id":"1.168136214","rc":[{"trd":[[4.1,789.09]],"batl":[[0,4.1,21.77]],"ltp":4.1,"tv":2931.13,"id":12925630}],"tv":12313.48}]}
{"op":"mcm","clk":"992118510","pt":1580555562074,"mc":[{"id":"1.168136214","rc":[{"batl":[[0,4.1,23.77]],"ltp":4.1,"tv":2931.13,"id":12925630}]}]}
{"op":"mcm","clk":"992119444","pt":1580555567052,"mc":[{"id":"1.168136214","rc":[{"batl":[[0,4.1,25.77]],"ltp":4.1,"tv":2931.13,"id":12925630}]}]}
{"op":"mcm","clk":"992120230","pt":1580555571149,"mc":[{"id":"1.168136214","rc":[{"trd":[[2.04,282.73]],"batb":[[0,2.04,12.51]],"ltp":2.04,"tv":7050.66,"id":17336468}],"tv":12333.48}]}
{"op":"mcm","clk":"992123230","pt":1580555587801,"mc":[{"id":"1.168136214","rc":[{"trd":[[4.1,812.21]],"batl":[[0,4.1,14.21]],"ltp":4.1,"tv":2954.25,"id":12925630}],"tv":12356.6}]}
{"op":"mcm","clk":"992124410","pt":1580555594128,"mc":[{"id":"1.168136214","rc":[{"trd":[[3.7,289.98]],"batb":[[0,3.7,2.08]],"ltp":3.7,"tv":2353.68,"id":11981493}],"tv":12358.6}]}
{"op":"mcm","clk":"992124582","pt":1580555595050,"mc":[{"id":"1.168136214","rc":[{"batb":[[0,3.65,43.36],[1,3.6,92.67],[2,3.55,20]],"ltp":3.7,"tv":2353.68,"id":11981493}]}]}
{"op":"mcm","clk":"992125423","pt":1580555600031,"mc":[{"id":"1.168136214","rc":[{"batb":[[0,3.7,1],[1,3.65,43.36],[2,3.6,92.67]],"ltp":3.7,"tv":2353.68,"id":11981493}]}]}
{"op":"mcm","clk":"992125554","pt":1580555600745,"mc":[{"id":"1.168136214","rc":[{"batb":[[0,3.7,4.11]],"ltp":3.7,"tv":2353.68,"id":11981493}]}]}
{"op":"mcm","clk":"992128062","pt":1580555614063,"mc":[{"id":"1.168136214","rc":[{"trd":[[4.1,822.81]],"batl":[[0,4.1,8.91]],"ltp":4.1,"tv":2964.85,"id":12925630},{"batb":[[0,2.04,38.59]],"ltp":2.04,"tv":7050.66,"id":17336468},{"batb":[[0,3.7,18.49]],"ltp":3.7,"tv":2353.68,"id":11981493}],"tv":12369.2}]}
{"op":"mcm","clk":"992128239","pt":1580555615088,"mc":[{"id":"1.168136214","rc":[{"trd":[[4.1,844.63]],"batb":[[0,4.1,2.06],[1,4,61.71],[2,3.95,12]],"batl":[[0,4.2,20.97],[1,4.3,148.36],[2,4.4,106]],"ltp":4.1,"tv":2986.67,"id":12925630}],"tv":12391.02}]}
{"op":"mcm","clk":"992129417","pt":1580555621122,"mc":[{"id":"1.168136214","rc":[{"batl":[[0,4.2,40.97]],"ltp":4.1,"tv":2986.67,"id":12925630}]}]}
{"op":"mcm","clk":"992134752","pt":1580555649151,"mc":[{"id":"1.168136214","rc":[{"trd":[[4.1,848.63]],"batb":[[0,4,61.78],[1,3.95,12],[2,3.9,65]],"ltp":4.1,"tv":2990.67,"id":12925630}],"tv":12395.02}]}
{"op":"mcm","clk":"992138977","pt":1580555672094,"mc":[{"id":"1.168136214","rc":[{"trd":[[4.2,1021.13]],"batb":[[0,4.2,19.49],[1,4,61.78],[2,3.95,12]],"batl":[[0,4.3,148.36],[1,4.4,106],[2,4.5,11.44]],"ltp":4.2,"tv":3095.53,"id":12925630},{"trd":[[2.04,321.7]],"batb":[[0,2.04,4.62]],"ltp":2.04,"tv":7089.63,"id":17336468},{"trd":[[3.7,311.47]],"batb":[[0,3.65,43.36],[1,3.6,92.67],[2,3.55,20]],"ltp":3.7,"tv":2375.17,"id":11981493}],"tv":12560.34}]}
{"op":"mcm","clk":"992139083","pt":1580555672689,"mc":[{"id":"1.168136214","rc":[{"trd":[[4.2,1044.17]],"batb":[[0,4.2,6.85],[1,4.1,28.72],[2,4,61.71]],"batl":[[0,4.3,146.36],[1,4.4,114.31],[2,4.5,8.44]],"ltp":4.2,"tv":3118.58,"id":12925630},{"trd":[[2.04,326.32]],"batb":[[0,2.02,5.02],[1,2,75.34],[2,1.99,6]],"batl":[[0,2.06,25.73]],"ltp":2.04,"tv":7094.25,"id":17336468},{"trd":[[3.7,314.02]],"batl":[[0,3.75,26.26]],"ltp":3.7,"tv":2377.72,"id":11981493}],"tv":12590.55}]}
{"op":"mcm","clk":"992139333","pt":1580555674116,"mc":[{"id":"1.168136214","rc":[{"batl":[[0,3.75,6]],"ltp":3.7,"tv":2377.72,"id":11981493}]}]}
{"op":"mcm","clk":"992139523","pt":1580555675109,"mc":[{"id":"1.168136214","rc":[{"batl":[[1,4.4,103]],"ltp":4.2,"tv":3118.58,"id":12925630}]}]}
{"op":"mcm","clk":"992140413","pt":1580555680769,"mc":[{"id":"1.168136214","rc":[{"batl":[[0,4.3,148.36]],"ltp":4.2,"tv":3118.58,"id":12925630}]}]}
{"op":"mcm","clk":"992141341","pt":1580555686096,"mc":[{"id":"1.168136214","rc":[{"trd":[[4.1,855.21],[4.2,1057.86]],"batb":[[0,4.1,17.26],[1,4,61.71],[2,3.95,12]],"ltp":4.1,"tv":3138.85,"id":12925630},{"batb":[[0,3.7,3.25],[1,3.65,43.36],[2,3.6,92.67]],"batl":[[0,3.8,37.27],[1,3.85,10.13],[2,3.9,6]],"ltp":3.7,"tv":2377.72,"id":11981493}],"tv":12610.82}]}
{"op":"mcm","clk":"992142909","pt":1580555695117,"mc":[{"id":"1.168136214","rc":[{"batb":[[1,2,80.34]],"batl":[[0,2.06,30.73]],"ltp":2.04,"tv":7094.25,"id":17336468}]}]}
{"op":"mcm","clk":"992143978","pt":1580555701114,"mc":[{"id":"1.168136214","rc":[{"trd":[[2.02,948.95]],"batb":[[0,2.02,3.02]],"ltp":2.02,"tv":7098.25,"id":17336468}],"tv":12614.82}]}
{"op":"mcm","clk":"992144379","pt":1580555703108,"mc":[{"id":"1.168136214","rc":[{"batb":[[0,4.2,12.16],[1,4.1,25.26],[2,4,61.71]],"ltp":4.1,"tv":3138.85,"id":12925630},{"batb":[[0,2,80.34],[1,1.99,6],[2,1.98,45.72]],"batl":[[1,2.08,30.79]],"ltp":2.02,"tv":7098.25,"id":17336468},{"batb":[[0,3.65,43.36],[1,3.6,92.67],[2,3.55,20]],"ltp":3.7,"tv":2377.72,"id":11981493}]}]}
{"op":"mcm","clk":"992145467","pt":1580555709018,"mc":[{"id":"1.168136214","rc":[{"batb":[[2,3.55,23]],"batl":[[0,3.7,2],[1,3.75,7.04],[2,3.8,37.27]],"ltp":3.7,"tv":2377.72,"id":11981493}]}]}
{"op":"mcm","clk":"992146215","pt":1580555712806,"mc":[{"id":"1.168136214","rc":[{"trd":[[4.2,1061.86]],"batb":[[0,4.2,10.16]],"ltp":4.2,"tv":3142.84,"id":12925630}],"tv":12618.82}]}
{"op":"mcm","clk":"992147031","pt":1580555717125,"mc":[{"id":"1.168136214","rc":[{"trd":[[4.1,879.29],[4.2,1082.19]],"batb":[[0,4.1,13.22],[1,4,61.71],[2,3.95,12]],"ltp":4.1,"tv":3187.25,"id":12925630}],"tv":12663.22}]}
{"op":"mcm","clk":"992147197","pt":1580555718046,"mc":[{"id":"1.168136214","rc":[{"batl":[[0,2.06,31.73]],"ltp":2.02,"tv":7098.25,"id":17336468}]}]}
{"op":"mcm","clk":"992148355","pt":1580555724150,"mc":[{"id":"1.168136214","rc":[{"trd":[[2.06,113.33]],"batl":[[0,2.06,30.97]],"ltp":2.06,"tv":7099.76,"id":17336468}],"tv":12664.74}]}
{"op":"mcm","clk":"992156576","pt":1580555771129,"mc":[{"id":"1.168136214","rc":[{"trd":[[3.65,136.6]],"batb":[[0,3.65,34.36]],"ltp":3.65,"tv":2401.72,"id":11981493}],"tv":12688.74}]}
{"op":"mcm","clk":"992159089","pt":1580555785130,"mc":[{"id":"1.168136214","rc":[{"trd":[[3.65,153.4]],"batb":[[0,3.65,25.96]],"ltp":3.65,"tv":2418.52,"id":11981493}],"tv":12705.54}]}
{"op":"mcm","clk":"992159479","pt":1580555787140,"mc":[{"id":"1.168136214","rc":[{"batb":[[0,3.65,17.51]],"ltp":3.65,"tv":2418.52,"id":11981493}]}]}
{"op":"mcm","clk":"992166417","pt":1580555826151,"mc":[{"id":"1.168136214","rc":[{"batl":[[0,2.06,21.97]],"ltp":2.06,"tv":7099.76,"id":17336468},{"batl":[[0,3.7,29.38]],"ltp":3.65,"tv":2418.52,"id":11981493}]}]}
{"op":"mcm","clk":"992170974","pt":1580555849085,"mc":[{"id":"1.168136214","rc":[{"trd":[[2,1861.74]],"batb":[[0,2.02,5.03],[1,2,70.34],[2,1.99,6]],"ltp":2.0,"tv":7119.76,"id":17336468},{"trd":[[3.7,334.01]],"batl":[[0,3.7,19.38]],"ltp":3.7,"tv":2438.51,"id":11981493}],"tv":12745.54}]}
{"op":"mcm","clk":"992183611","pt":1580555862116,"mc":[{"id":"1.168136214","rc":[{"batb":[[1,4,71.84]],"ltp":4.1,"tv":3187.25,"id":12925630},{"batl":[[1,2.08,58.93]],"ltp":2.0,"tv":7119.76,"id":17336468}]}]}
{"op":"mcm","clk":"992188843","pt":1580555888119,"mc":[{"id":"1.168136214","rc":[{"trd":[[2.02,958.95]],"batb":[[0,2,70.37],[1,1.99,6],[2,1.98,45.72]],"ltp":2.02,"tv":7129.76,"id":17336468}],"tv":12755.54}]}
{"op":"mcm","clk":"992189056","pt":1580555889088,"mc":[{"id":"1.168136214","rc":[{"batb":[[0,2.02,5],[1,2,75.34],[2,1.99,6]],"batl":[[0,2.06,31.97]],"ltp":2.02,"tv":7129.76,"id":17336468}]}]}
{"op":"mcm","clk":"992192463","pt":1580555907035,"mc":[{"id":"1.168136214","rc":[{"batl":[[0,2.04,5],[1,2.06,31.97],[2,2.08,58.93]],"ltp":2.02,"tv":7129.76,"id":17336468}]}]}
{"op":"mcm","clk":"992196250","pt":1580555929051,"mc":[{"id":"1.168136214","rc":[{"trd":[[2.02,968.95]],"ltp":2.02,"tv":7139.76,"id":17336468}],"tv":12765.54}]}
{"op":"mcm","clk":"992197899","pt":1580555938949,"mc":[{"id":"1.168136214","rc":[{"trd":[[2.02,972.95]],"batb":[[0,2.02,3]],"ltp":2.02,"tv":7143.76,"id":17336468}],"tv":12769.54}]}
{"op":"mcm","clk":"992203935","pt":1580555974121,"mc":[{"id":"1.168136214","rc":[{"batb":[[0,2.02,5]],"ltp":2.02,"tv":7143.76,"id":17336468},{"batb":[[0,3.7,3.18],[1,3.65,17.51],[2,3.6,92.67]],"batl":[[0,3.8,37.27],[1,3.85,10.13],[2,3.9,6]],"ltp":3.7,"tv":2438.51,"id":11981493}]}]}
{"op":"mcm","clk":"992204436","pt":1580555977146,"mc":[{"id":"1.168136214","rc":[{"batb":[[2,3.6,104.36]],"ltp":3.7,"tv":2438.51,"id":11981493}]}]}
{"op":"mcm","clk":"992204727","pt":1580555979054,"mc":[{"id":"1.168136214","rc":[{"trd":[[2.04,330.32]],"batl":[[0,2.04,3]],"ltp":2.04,"tv":7147.76,"id":17336468}],"tv":12773.54}]}
{"op":"mcm","clk":"992211971","pt":1580556018119,"mc":[{"id":"1.168136214","rc":[{"trd":[[3.65,164.76],[3.7,340.37]],"batb":[[0,3.7,3],[1,3.65,11.83]],"ltp":3.65,"tv":2456.23,"id":11981493}],"tv":12791.26}]}
{"op":"mcm","clk":"992218189","pt":1580556051962,"mc":[{"id":"1.168136214","rc":[{"batb":[[1,4,131.84]],"ltp":4.1,"tv":3187.25,"id":12925630}]}]}
{"op":"mcm","clk":"992227860","pt":1580556108889,"mc":[{"id":"1.168136214","rc":[{"batl":[[1,4.4,107.73]],"ltp":4.1,"tv":3187.25,"id":12925630}]}]}
{"op":"mcm","clk":"992231843","pt":1580556133971,"mc":[{"id":"1.168136214","rc":[{"trd":[[4.1,881.7]],"batb":[[0,4.1,2.81]],"ltp":4.1,"tv":3189.66,"id":12925630},{"trd":[[2.02,977.85]],"batb":[[0,2,75.34],[1,1.99,6],[2,1.98,45.72]],"batl":[[1,2.06,19.24]],"ltp":2.02,"tv":7152.66,"id":17336468},{"trd":[[3.8,438.49],[3.85,399.05]],"batl":[[0,3.85,4.07],[1,3.9,6],[2,3.95,20]],"ltp":3.85,"tv":2553.63,"id":11981493}],"tv":12895.97}]}
{"op":"mcm","clk":"992232009","pt":1580556134956,"mc":[{"id":"1.168136214","rc":[{"batb":[[1,3.65,23.52],[2,3.6,92.67]],"batl":[[2,3.95,30.3]],"ltp":3.85,"tv":2553.63,"id":11981493}]}]}
{"op":"mcm","clk":"992232521","pt":1580556137965,"mc":[{"id":"1.168136214","rc":[{"trd":[[3.7,344.37]],"batb":[[0,3.7,1]],"ltp":3.7,"tv":2557.63,"id":11981493}],"tv":12899.97}]}
{"op":"mcm","clk":"992248238","pt":1580556235141,"mc":[{"id":"1.168136214","rc":[{"batb":[[2,1.98,49.72]],"batl":[[0,2.02,1.14],[1,2.04,3],[2,2.06,19.24]],"ltp":2.02,"tv":7152.66,"id":17336468},{"batb":[[0,3.7,3]],"ltp":3.7,"tv":2557.63,"id":11981493}]}]}
{"op":"mcm","clk":"992248399","pt":1580556236116,"mc":[{"id":"1.168136214","rc":[{"batl":[[0,2.04,3],[1,2.06,19.24],[2,2.08,58.93]],"ltp":2.02,"tv":7152.66,"id":17336468}]}]}
{"op":"mcm","clk":"992253381","pt":1580556269091,"mc":[{"id":"1.168136214","rc":[{"trd":[[2,1867.74],[2.04,336.2]],"batb":[[0,2,72.34]],"batl":[[0,2.06,19.3],[1,2.08,58.93],[2,2.1,95]],"ltp":2.04,"tv":7164.54,"id":17336468}],"tv":12911.85}]}
{"op":"mcm","clk":"992259612","pt":1580556308951,"mc":[{"id":"1.168136214","rc":[{"batl":[[0,3.85,12.07]],"ltp":3.7,"tv":2557.63,"id":11981493}]}]}
{"op":"mcm","clk":"992259804","pt":1580556310060,"mc":[{"id":"1.168136214","rc":[{"batb":[[0,2.02,5.05],[1,2,72.34],[2,1.99,6]],"ltp":2.04,"tv":7164.54,"id":17336468},{"batb":[[1,3.65,11.83],[2,3.6,104.36]],"batl":[[1,3.9,16.3],[2,3.95,20]],"ltp":3.7,"tv":2557.63,"id":11981493}]}]}
{"op":"mcm","clk":"992261585","pt":1580556321066,"mc":[{"id":"1.168136214","rc":[{"batl":[[1,3.9,22.3]],"ltp":3.7,"tv":2557.63,"id":11981493}]}]}
{"op":"mcm","clk":"992262704","pt":1580556328123,"mc":[{"id":"1.168136214","rc":[{"trd":[[4.1,887.32]],"batb":[[0,4,131.84],[1,3.95,12],[2,3.9,35]],"ltp":4.1,"tv":3195.28,"id":12925630}],"tv":12917.47}]}
{"op":"mcm","clk":"992262995","pt":1580556330049,"mc":[{"id":"1.168136214","rc":[{"batl":[[0,4.3,149.05]],"ltp":4.1,"tv":3195.28,"id":12925630}]}]}
{"op":"mcm","clk":"992264240","pt":1580556337709,"mc":[{"id":"1.168136214","rc":[{"batb":[[2,3.6,92.67]],"ltp":3.7,"tv":2557.63,"id":11981493}]}]}
{"op":"mcm","clk":"992264737","pt":1580556340801,"mc":[{"id":"1.168136214","rc":[{"trd":[[3.7,350.37]],"batb":[[0,3.7,3.22]],"batl":[[0,3.8,7.42],[1,3.85,12.07],[2,3.9,22.3]],"ltp":3.7,"tv":2563.63,"id":11981493}],"tv":12923.47}]}
{"op":"mcm","clk":"992268397","pt":1580556365147,"mc":[{"id":"1.168136214","rc":[{"batl":[[0,2.06,9.3]],"ltp":2.04,"tv":7164.54,"id":17336468},{"batl":[[0,3.75,4],[1,3.8,7.42],[2,3.85,12.07]],"ltp":3.7,"tv":2563.63,"id":11981493}]}]}
{"op":"mcm","clk":"992268720","pt":1580556367048,"mc":[{"id":"1.168136214","rc":[{"batl":[[1,2.08,30.79]],"ltp":2.04,"tv":7164.54,"id":17336468}]}]}
{"op":"mcm","clk":"992271358","pt":1580556383978,"mc":[{"id":"1.168136214","rc":[{"batl":[[1,3.8,13.42]],"ltp":3.7,"tv":2563.63,"id":11981493}]}]}
{"op":"mcm","clk":"992275163","pt":1580556407094,"mc":[{"id":"1.168136214","rc":[{"trd":[[3.7,362.81]],"batb":[[0,3.65,11.83],[1,3.6,92.67],[2,3.55,20]],"batl":[[0,3.7,2.71],[1,3.75,4],[2,3.8,6]],"ltp":3.7,"tv":2576.07,"id":11981493}],"tv":12935.9}]}
{"op":"mcm","clk":"992275484","pt":1580556409077,"mc":[{"id":"1.168136214","rc":[{"batb":[[1,2,102.73]],"ltp":2.04,"tv":7164.54,"id":17336468},{"batb":[[2,3.55,23]],"ltp":3.7,"tv":2576.07,"id":11981493}]}]}
{"op":"mcm","clk":"992277611","pt":1580556422105,"mc":[{"id":"1.168136214","rc":[{"trd":[[4,165.23],[4.1,896.93],[4.2,1083.58]],"batb":[[0,4.1,15.6],[1,4,125.72],[2,3.95,12]],"batl":[[0,4.3,148.36]],"ltp":4.2,"tv":3218.54,"id":12925630},{"trd":[[2.04,336.26]],"batb":[[0,2.02,20.47]],"batl":[[0,2.06,20.24]],"ltp":2.04,"tv":7164.6,"id":17336468},{"trd":[[3.7,368.19]],"batb":[[0,3.7,5.75],[1,3.65,8.83],[2,3.6,92.67]],"batl":[[0,3.75,4],[1,3.8,6],[2,3.85,22.73]],"ltp":3.7,"tv":2581.45,"id":11981493}],"tv":12964.6}]}
{"op":"mcm","clk":"992277773","pt":1580556423115,"mc":[{"id":"1.168136214","rc":[{"batb":[[0,4.1,7.6]],"ltp":4.2,"tv":3218.54,"id":12925630},{"batb":[[1,2,72.34]],"batl":[[0,2.06,9.24]],"ltp":2.04,"tv":7164.6,"id":17336468},{"batb":[[0,3.7,8.75],[1,3.65,14.83]],"batl":[[2,3.85,12.07]],"ltp":3.7,"tv":2581.45,"id":11981493}]}]}
{"op":"mcm","clk":"992280967","pt":1580556443057,"mc":[{"id":"1.168136214","rc":[{"batl":[[0,2.06,20.24]],"ltp":2.04,"tv":7164.6,"id":17336468},{"batb":[[0,3.7,5.75],[1,3.65,11.83]],"ltp":3.7,"tv":2581.45,"id":11981493}]}]}
{"op":"mcm","clk":"992281145","pt":1580556444135,"mc":[{"id":"1.168136214","rc":[{"batl":[[1,2.08,58.93]],"ltp":2.04,"tv":7164.6,"id":17336468}]}]}
{"op":"mcm","clk":"992281731","pt":1580556448156,"mc":[{"id":"1.168136214","rc":[{"batl":[[2,3.85,22.73]],"ltp":3.7,"tv":2581.45,"id":11981493}]}]}
{"op":"mcm","clk":"992282142","pt":1580556451056,"mc":[{"id":"1.168136214","rc":[{"batl":[[2,4.5,29.45]],"ltp":4.2,"tv":3218.54,"id":12925630}]}]}
{"op":"mcm","clk":"992291559","pt":1580556514024,"mc":[{"id":"1.168136214","rc":[{"batl":[[0,2.04,2],[1,2.06,20.24],[2,2.08,58.93]],"ltp":2.04,"tv":7164.6,"id":17336468},{"batb":[[0,3.7,8.75]],"ltp":3.7,"tv":2581.45,"id":11981493}]}]}
{"op":"mcm","clk":"992291883","pt":1580556516140,"mc":[{"id":"1.168136214","rc":[{"batl":[[2,3.85,12.07]],"ltp":3.7,"tv":2581.45,"id":11981493}]}]}
{"op":"mcm","clk":"992292362","pt":1580556519142,"mc":[{"id":"1.168136214","rc":[{"batb":[[0,4.1,15.6]],"ltp":4.2,"tv":3218.54,"id":12925630},{"trd":[[2.02,1027.85]],"batb":[[0,2,72.34],[1,1.99,6],[2,1.98,49.72]],"ltp":2.02,"tv":7214.61,"id":17336468}],"tv":13014.61}]}
{"op":"mcm","clk":"992294238","pt":1580556532068,"mc":[{"id":"1.168136214","rc":[{"trd":[[2.04,340.26],[2.06,153.33]],"batl":[[0,2.08,59.17],[1,2.1,95],[2,2.18,6]],"ltp":2.06,"tv":7258.61,"id":17336468}],"tv":13058.61}]}
{"op":"mcm","clk":"992294392","pt":1580556533067,"mc":[{"id":"1.168136214","rc":[{"batb":[[0,4.1,7.6]],"ltp":4.2,"tv":3218.54,"id":12925630},{"batb":[[0,2.02,5.21],[1,2,72.34],[2,1.99,6]],"batl":[[0,2.06,23.73],[1,2.08,58.93],[2,2.1,95]],"ltp":2.06,"tv":7258.61,"id":17336468}]}]}
{"op":"mcm","clk":"992294820","pt":1580556535857,"mc":[{"id":"1.168136214","rc":[{"batl":[[0,2.06,37.73]],"ltp":2.06,"tv":7258.61,"id":17336468}]}]}
{"op":"mcm","clk":"992295886","pt":1580556543053,"mc":[{"id":"1.168136214","rc":[{"trd":[[2,2012.42],[2.02,1038.27]],"batb":[[0,1.99,6],[1,1.98,49.72],[2,1.97,148]],"batl":[[0,2,72.45],[1,2.06,37.73],[2,2.08,58.93]],"ltp":2.0,"tv":7413.71,"id":17336468}],"tv":13213.71}]}
{"op":"mcm","clk":"992296027","pt":1580556544016,"mc":[{"id":"1.168136214","rc":[{"batb":[[0,4.1,17.73],[1,4,115.59]],"batl":[[1,4.4,103]],"ltp":4.2,"tv":3218.54,"id":12925630},{"trd":[[2,2079.42]],"batl":[[0,2,38.95],[1,2.06,53.14],[2,2.08,30.79]],"ltp":2.0,"tv":7480.71,"id":17336468},{"trd":[[3.75,276.97]],"batb":[[1,3.65,23.3]],"batl":[[0,3.8,6],[1,3.85,12.07],[2,3.9,6]],"ltp":3.75,"tv":2589.45,"id":11981493}],"tv":13288.71}]}
{"op":"mcm","clk":"992296362","pt":1580556546124,"mc":[{"id":"1.168136214","rc":[{"batb":[[0,4.1,25.73]],"ltp":4.2,"tv":3218.54,"id":12925630},{"batl":[[1,2.02,11.02],[2,2.04,26.82]],"ltp":2.0,"tv":7480.71,"id":17336468}]}]}
{"op":"mcm","clk":"992297128","pt":1580556551125,"mc":[{"id":"1.168136214","rc":[{"batl":[[0,2.04,19.72],[1,2.06,70.4],[2,2.08,12.63]],"ltp":2.0,"tv":7480.71,"id":17336468}]}]}
{"op":"mcm","clk":"992297511","pt":1580556554023,"mc":[{"id":"1.168136214","rc":[{"batb":[[0,4.1,15.6],[1,4,125.72]],"ltp":4.2,"tv":3218.54,"id":12925630}]}]}
{"op":"mcm","clk":"992298281","pt":1580556559135,"mc":[{"id":"1.168136214","rc":[{"batl":[[1,2.06,53.14]],"ltp":2.0,"tv":7480.71,"id":17336468}]}]}
{"op":"mcm","clk":"992298441","pt":1580556560105,"mc":[{"id":"1.168136214","rc":[{"batl":[[0,2.04,11.02]],"ltp":2.0,"tv":7480.71,"id":17336468}]}]}
{"op":"mcm","clk":"992298877","pt":1580556563026,"mc":[{"id":"1.168136214","rc":[{"batb":[[0,3.7,18.75]],"ltp":3.75,"tv":2589.45,"id":11981493}]}]}
{"op":"mcm","clk":"992302622","pt":1580556588127,"mc":[{"id":"1.168136214","rc":[{"batl":[[1,2.06,153.14]],"ltp":2.0,"tv":7480.71,"id":17336468}]}]}
{"op":"mcm","clk":"992304452","pt":1580556600088,"mc":[{"id":"1.168136214","rc":[{"batb":[[0,4.2,9.5],[1,4.1,15.6],[2,4,125.72]],"ltp":4.2,"tv":3218.54,"id":12925630}]}]}
{"op":"mcm","clk":"992304594","pt":1580556601071,"mc":[{"id":"1.168136214","rc":[{"batb":[[1,4.1,25.73],[2,4,115.59]],"ltp":4.2,"tv":3218.54,"id":12925630}]}]}
{"op":"mcm","clk":"992306454","pt":1580556612103,"mc":[{"id":"1.168136214","rc":[{"batb":[[0,2,75],[1,1.99,6],[2,1.98,49.72]],"ltp":2.0,"tv":7480.71,"id":17336468}]}]}
{"op":"mcm","clk":"992306605","pt":1580556613024,"mc":[{"id":"1.168136214","rc":[{"batb":[[0,2,79]],"ltp":2.0,"tv":7480.71,"id":17336468}]}]}
{"op":"mcm","clk":"992306795","pt":1580556614119,"mc":[{"id":"1.168136214","rc":[{"batb":[[1,4.1,15.6],[2,4,125.72]],"ltp":4.2,"tv":3218.54,"id":12925630},{"batb":[[1,3.65,11.83]],"batl":[[2,3.9,16.66]],"ltp":3.75,"tv":2589.45,"id":11981493}]}]}
{"op":"mcm","clk":"992307714","pt":1580556620120,"mc":[{"id":"1.168136214","rc":[{"trd":[[4.2,1102.58]],"batb":[[0,4.1,25.33],[1,4,125.72],[2,3.95,12]],"ltp":4.2,"tv":3237.54,"id":12925630}],"tv":13307.71}]}
{"op":"mcm","clk":"992307860","pt":1580556621102,"mc":[{"id":"1.168136214","rc":[{"batb":[[1,4,155.72]],"ltp":4.2,"tv":3237.54,"id":12925630}]}]}
{"op":"mcm","clk":"992308334","pt":1580556624056,"mc":[{"id":"1.168136214","rc":[{"batb":[[0,4.1,17.33]],"ltp":4.2,"tv":3237.54,"id":12925630},{"batl":[[2,3.9,6]],"ltp":3.75,"tv":2589.45,"id":11981493}]}]}
{"op":"mcm","clk":"992310424","pt":1580556637994,"mc":[{"id":"1.168136214","rc":[{"batb":[[1,3.65,23.3]],"ltp":3.75,"tv":2589.45,"id":11981493}]}]}
{"op":"mcm","clk":"992319254","pt":1580556692605,"mc":[{"id":"1.168136214","rc":[{"batl":[[0,2.04,19.72]],"ltp":2.0,"tv":7480.71,"id":17336468}]}]}
{"op":"mcm","clk":"992320841","pt":1580556701107,"mc":[{"id":"1.168136214","rc":[{"trd":[[2.04,348.26]],"batl":[[0,2.04,15.72]],"ltp":2.04,"tv":7488.71,"id":17336468}],"tv":13315.71}]}
{"op":"mcm","clk":"992322469","pt":1580556711064,"mc":[{"id":"1.168136214","rc":[{"trd":[[2,2157.32]],"batb":[[0,2,40.05]],"batl":[[0,2.04,19.7]],"ltp":2.0,"tv":7566.61,"id":17336468},{"batb":[[0,3.75,3.27],[1,3.7,18.75],[2,3.65,23.3]],"ltp":3.75,"tv":2589.45,"id":11981493}],"tv":13393.61}]}
{"op":"mcm","clk":"992324225","pt":1580556722069,"mc":[{"id":"1.168136214","rc":[{"batb":[[0,4.1,27.46],[1,4,145.59]],"ltp":4.2,"tv":3237.54,"id":12925630},{"trd":[[2,2247.42]],"batb":[[0,1.99,6],[1,1.98,49.72],[2,1.97,148]],"batl":[[0,2,24.95],[1,2.04,47.85],[2,2.06,125]],"ltp":2.0,"tv":7656.71,"id":17336468}],"tv":13483.71}]}
{"op":"mcm","clk":"992324577","pt":1580556724079,"mc":[{"id":"1.168136214","rc":[{"batb":[[0,4.1,35.46]],"ltp":4.2,"tv":3237.54,"id":12925630},{"batl":[[1,2.02,17.4],[2,2.04,47.85]],"ltp":2.0,"tv":7656.71,"id":17336468},{"trd":[[3.75,283.51]],"batb":[[0,3.7,18.75],[1,3.65,23.3],[2,3.6,92.67]],"batl":[[0,3.75,4.21],[1,3.8,32.66],[2,3.85,12.07]],"ltp":3.75,"tv":2595.99,"id":11981493}],"tv":13490.25}]}
{"op":"mcm","clk":"992344713","pt":1580556785967,"mc":[{"id":"1.168136214","rc":[{"batb":[[0,1.99,11],[2,1.97,153]],"batl":[[0,2,29.95]],"ltp":2.0,"tv":7656.71,"id":17336468}]}]}
{"op":"mcm","clk":"992344914","pt":1580556787147,"mc":[{"id":"1.168136214","rc":[{"batl":[[2,2.04,19.7]],"ltp":2.0,"tv":7656.71,"id":17336468}]}]}
{"op":"mcm","clk":"992345200","pt":1580556788869,"mc":[{"id":"1.168136214","rc":[{"batb":[[0,3.7,23.75]],"batl":[[0,3.75,9.21]],"ltp":3.75,"tv":2595.99,"id":11981493}]}]}
{"op":"mcm","clk":"992347186","pt":1580556799774,"mc":[{"id":"1.168136214","rc":[{"trd":[[4.2,1107.58]],"batb":[[0,4.1,40.46]],"ltp":4.2,"tv":3242.54,"id":12925630},{"trd":[[2,2257.92]],"batl":[[0,2,19.45]],"ltp":2.0,"tv":7667.21,"id":17336468},{"trd":[[3.75,289.11]],"batl":[[0,3.75,3.61]],"ltp":3.75,"tv":2601.59,"id":11981493}],"tv":13511.35}]}
{"op":"mcm","clk":"992347367","pt":1580556801650,"mc":[{"id":"1.168136214","rc":[{"batl":[[1,2.02,12.01]],"ltp":2.0,"tv":7667.21,"id":17336468}]}]}
{"op":"mcm","clk":"992348452","pt":1580556807096,"mc":[{"id":"1.168136214","rc":[{"batl":[[1,3.8,38.66]],"ltp":3.75,"tv":2601.59,"id":11981493}]}]}
{"op":"mcm","clk":"992348629","pt":1580556808004,"mc":[{"id":"1.168136214","rc":[{"trd":[[2,2296.82]],"batb":[[0,2,15.55],[1,1.99,11],[2,1.98,49.72]],"batl":[[0,2.04,19.7],[1,2.06,111],[2,2.08,3.63]],"ltp":2.0,"tv":7706.11,"id":17336468}],"tv":13550.25}]}
{"op":"mcm","clk":"992348994","pt":1580556810061,"mc":[{"id":"1.168136214","rc":[{"batb":[[0,4.1,30.33]],"ltp":4.2,"tv":3242.54,"id":12925630},{"batb":[[2,1.98,80.11]],"ltp":2.0,"tv":7706.11,"id":17336468},{"batb":[[1,3.65,11.83]],"ltp":3.75,"tv":2601.59,"id":11981493}]}]}
{"op":"mcm","clk":"992350997","pt":1580556822075,"mc":[{"id":"1.168136214","rc":[{"batb":[[0,2.02,5.23],[1,2,20.55],[2,1.99,6]],"batl":[[0,2.04,8.7]],"ltp":2.0,"tv":7706.11,"id":17336468}]}]}
{"op":"mcm","clk":"992351051","pt":1580556822461,"mc":[{"id":"1.168136214","rc":[{"batl":[[0,2.04,21.53]],"ltp":2.0,"tv":7706.11,"id":17336468}]}]}
{"op":"mcm","clk":"992351318","pt":1580556824091,"mc":[{"id":"1.168136214","rc":[{"batl":[[0,2.04,23.53]],"ltp":2.0,"tv":7706.11,"id":17336468}]}]}
{"op":"mcm","clk":"992352375","pt":1580556830092,"mc":[{"id":"1.168136214","rc":[{"batl":[[0,2.04,25.53]],"ltp":2.0,"tv":7706.11,"id":17336468}]}]}
{"op":"mcm","clk":"992356814","pt":1580556857153,"mc":[{"id":"1.168136214","rc":[{"trd":[[2.02,1048.73]],"batb":[[0,2,20.55],[1,1.99,6],[2,1.98,80.11]],"batl":[[0,2.02,24.76],[1,2.04,36.53],[2,2.06,111]],"ltp":2.02,"tv":7716.57,"id":17336468}],"tv":13560.71}]}
{"op":"mcm","clk":"992357013","pt":1580556858150,"mc":[{"id":"1.168136214","rc":[{"batb":[[2,1.98,49.72]],"batl":[[2,2.06,139.67]],"ltp":2.02,"tv":7716.57,"id":17336468},{"batb":[[1,3.65,23.3]],"ltp":3.75,"tv":2601.59,"id":11981493}]}]}
{"op":"mcm","clk":"992358696","pt":1580556867964,"mc":[{"id":"1.168136214","rc":[{"batl":[[2,2.06,111]],"ltp":2.02,"tv":7716.57,"id":17336468}]}]}
{"op":"mcm","clk":"992359363","pt":1580556871967,"mc":[{"id":"1.168136214","rc":[{"batl":[[1,3.8,12]],"ltp":3.75,"tv":2601.59,"id":11981493}]}]}
{"op":"mcm","clk":"992364643","pt":1580556903117,"mc":[{"id":"1.168136214","rc":[{"batb":[[0,4.2,12.16],[1,4.1,30.33],[2,4,145.59]],"ltp":4.2,"tv":3242.54,"id":12925630},{"trd":[[3.75,296.33]],"batb":[[0,3.75,11.39],[1,3.7,23.75],[2,3.65,23.3]],"batl":[[0,3.8,6],[1,3.85,12.07],[2,3.9,6]],"ltp":3.75,"tv":2608.81,"id":11981493}],"tv":13567.93}]}
{"op":"mcm","clk":"992364792","pt":1580556904041,"mc":[{"id":"1.168136214","rc":[{"batb":[[1,4.1,40.13]],"ltp":4.2,"tv":3242.54,"id":12925630}]}]}
{"op":"mcm","clk":"992364965","pt":1580556905002,"mc":[{"id":"1.168136214","rc":[{"batb":[[2,3.65,11.83]],"ltp":3.75,"tv":2608.81,"id":11981493}]}]}
{"op":"mcm","clk":"992366006","pt":1580556911049,"mc":[{"id":"1.168136214","rc":[{"batb":[[0,3.75,16.39],[1,3.7,18.75]],"ltp":3.75,"tv":2608.81,"id":11981493}]}]}
{"op":"mcm","clk":"992366815","pt":1580556916130,"mc":[{"id":"1.168136214","rc":[{"batl":[[1,2.04,39.24]],"ltp":2.02,"tv":7716.57,"id":17336468}]}]}
{"op":"mcm","clk":"992366951","pt":1580556917047,"mc":[{"id":"1.168136214","rc":[{"batl":[[1,2.04,36.53]],"ltp":2.02,"tv":7716.57,"id":17336468}]}]}
{"op":"mcm","clk":"992367767","pt":1580556922145,"mc":[{"id":"1.168136214","rc":[{"batb":[[0,4.2,17.16],[1,4.1,35.13]],"ltp":4.2,"tv":3242.54,"id":12925630}]}]}
{"op":"mcm","clk":"992376973","pt":1580556973865,"mc":[{"id":"1.168136214","rc":[{"trd":[[3.75,297.13]],"batb":[[0,3.75,15.99]],"batl":[[2,3.9,6.4]],"ltp":3.75,"tv":2609.61,"id":11981493}],"tv":13568.73}]}
{"op":"mcm","clk":"992378156","pt":1580556979965,"mc":[{"id":"1.168136214","rc":[{"trd":[[4.2,1141.91]],"batb":[[0,4.1,35.13],[1,4,145.59],[2,3.95,12]],"batl":[[0,4.2,50.83],[1,4.3,148.36],[2,4.4,103]],"ltp":4.2,"tv":3276.87,"id":12925630}],"tv":13603.05}]}
{"op":"mcm","clk":"992378555","pt":1580556981968,"mc":[{"id":"1.168136214","rc":[{"batb":[[0,4.1,25.33],[1,4,155.39]],"ltp":4.2,"tv":3276.87,"id":12925630}]}]}
{"op":"mcm","clk":"992379586","pt":1580556988045,"mc":[{"id":"1.168136214","rc":[{"batb":[[0,4.1,30.33]],"batl":[[0,4.2,55.83]],"ltp":4.2,"tv":3276.87,"id":12925630}]}]}
{"op":"mcm","clk":"992380294","pt":1580556992028,"mc":[{"id":"1.168136214","rc":[{"batb":[[1,4,145.59]],"ltp":4.2,"tv":3276.87,"id":12925630}]}]}
{"op":"mcm","clk":"992380673","pt":1580556994049,"mc":[{"id":"1.168136214","rc":[{"trd":[[4.1,900.93]],"batb":[[0,4.1,28.33]],"batl":[[1,4.3,146.36]],"ltp":4.1,"tv":3280.87,"id":12925630}],"tv":13607.05}]}
{"op":"mcm","clk":"992382358","pt":1580557004047,"mc":[{"id":"1.168136214","rc":[{"trd":[[4.1,904.93]],"batb":[[0,4.1,26.33]],"ltp":4.1,"tv":3284.87,"id":12925630}],"tv":13611.05}]}
{"op":"mcm","clk":"992382996","pt":1580557007973,"mc":[{"id":"1.168136214","rc":[{"batb":[[0,4.1,39.8]],"ltp":4.1,"tv":3284.87,"id":12925630},{"trd":[[2.02,1098.25]],"batb":[[0,2.02,2.58],[1,2,20.55],[2,1.99,6]],"batl":[[0,2.04,36.53],[1,2.06,111],[2,2.08,3.63]],"ltp":2.02,"tv":7766.09,"id":17336468},{"trd":[[3.75,337.13]],"batb":[[0,3.75,14.73]],"ltp":3.75,"tv":2649.61,"id":11981493}],"tv":13700.57}]}
{"op":"mcm","clk":"992383148","pt":1580557008893,"mc":[{"id":"1.168136214","rc":[{"batb":[[0,3.75,17.73]],"ltp":3.75,"tv":2649.61,"id":11981493}]}]}
{"op":"mcm","clk":"992384543","pt":1580557016955,"mc":[{"id":"1.168136214","rc":[{"batb":[[2,1.99,16]],"ltp":2.02,"tv":7766.09,"id":17336468}]}]}
{"op":"mcm","clk":"992385293","pt":1580557021127,"mc":[{"id":"1.168136214","rc":[{"batl":[[0,2.04,47.73]],"ltp":2.02,"tv":7766.09,"id":17336468}]}]}
{"op":"mcm","clk":"992385492","pt":1580557022155,"mc":[{"id":"1.168136214","rc":[{"trd":[[2.04,352.26]],"batl":[[0,2.04,45.73]],"ltp":2.04,"tv":7770.09,"id":17336468}],"tv":13704.57}]}
{"op":"mcm","clk":"992385789","pt":1580557023668,"mc":[{"id":"1.168136214","rc":[{"trd":[[4.1,908.93]],"batb":[[0,4.1,37.8]],"ltp":4.1,"tv":3288.87,"id":12925630}],"tv":13708.57}]}
{"op":"mcm","clk":"992386597","pt":1580557028156,"mc":[{"id":"1.168136214","rc":[{"batb":[[0,3.75,22.73]],"batl":[[0,3.8,11]],"ltp":3.75,"tv":2649.61,"id":11981493}]}]}
{"op":"mcm","clk":"992387114","pt":1580557031058,"mc":[{"id":"1.168136214","rc":[{"trd":[[4.2,1142.28]],"batl":[[0,4.2,55.46]],"ltp":4.2,"tv":3289.24,"id":12925630},{"trd":[[2,2338.7],[2.02,1103.41]],"batb":[[0,1.99,16],[1,1.98,80.11],[2,1.97,148]],"ltp":2.0,"tv":7817.13,"id":17336468},{"trd":[[3.8,438.9]],"batl":[[0,3.8,10.59]],"ltp":3.8,"tv":2650.02,"id":11981493}],"tv":13756.4}]}
{"op":"mcm","clk":"992387317","pt":1580557032144,"mc":[{"id":"1.168136214","rc":[{"batb":[[0,2,4],[1,1.99,16],[2,1.98,80.11]],"ltp":2.0,"tv":7817.13,"id":17336468}]}]}
{"op":"mcm","clk":"992387656","pt":1580557033980,"mc":[{"id":"1.168136214","rc":[{"trd":[[4.1,912.93]],"batb":[[0,4.1,35.8]],"ltp":4.1,"tv":3293.24,"id":12925630}],"tv":13760.4}]}
{"op":"mcm","clk":"992388202","pt":1580557037143,"mc":[{"id":"1.168136214","rc":[{"batb":[[0,2,9]],"batl":[[0,2.02,5],[1,2.04,45.73],[2,2.06,111]],"ltp":2.0,"tv":7817.13,"id":17336468}]}]}
{"op":"mcm","clk":"992388329","pt":1580557038055,"mc":[{"id":"1.168136214","rc":[{"batb":[[0,4.1,44.67]],"ltp":4.1,"tv":3293.24,"id":12925630},{"batb":[[0,2,27.18],[2,1.98,49.72]],"ltp":2.0,"tv":7817.13,"id":17336468},{"trd":[[3.8,460.07]],"batl":[[0,3.85,12.07],[1,3.9,6.4],[2,3.95,20]],"ltp":3.8,"tv":2671.2,"id":11981493}],"tv":13781.57}]}
{"op":"mcm","clk":"992388451","pt":1580557038864,"mc":[{"id":"1.168136214","rc":[{"batl":[[0,2.02,15.1]],"ltp":2.0,"tv":7817.13,"id":17336468},{"batb":[[0,3.8,3.1],[1,3.75,22.73],[2,3.7,18.75]],"batl":[[0,3.85,8],[1,3.9,12.4]],"ltp":3.8,"tv":2671.2,"id":11981493}]}]}
{"op":"mcm","clk":"992392027","pt":1580557058120,"mc":[{"id":"1.168136214","rc":[{"batb":[[2,1.98,54.72]],"batl":[[0,2.02,20.1]],"ltp":2.0,"tv":7817.13,"id":17336468}]}]}
{"op":"mcm","clk":"992393266","pt":1580557065137,"mc":[{"id":"1.168136214","rc":[{"trd":[[4.1,916.93]],"batb":[[0,4.1,42.67]],"ltp":4.1,"tv":3297.24,"id":12925630}],"tv":13785.57}]}
{"op":"mcm","clk":"992396597","pt":1580557084117,"mc":[{"id":"1.168136214","rc":[{"trd":[[4.1,920.93]],"batb":[[0,4.1,40.67]],"ltp":4.1,"tv":3301.24,"id":12925630}],"tv":13789.57}]}
{"op":"mcm","clk":"992396751","pt":1580557085149,"mc":[{"id":"1.168136214","rc":[{"trd":[[2,2347.1]],"batb":[[0,2,22.98]],"ltp":2.0,"tv":7825.53,"id":17336468},{"trd":[[3.8,464.58]],"batb":[[0,3.75,23.58],[1,3.7,18.75],[2,3.65,11.83]],"ltp":3.8,"tv":2675.7,"id":11981493}],"tv":13802.48}]}
{"op":"mcm","clk":"992398846","pt":1580557097988,"mc":[{"id":"1.168136214","rc":[{"trd":[[4.1,924.93]],"batb":[[0,4.1,38.67]],"ltp":4.1,"tv":3305.24,"id":12925630}],"tv":13806.48}]}
{"op":"mcm","clk":"992400741","pt":1580557110113,"mc":[{"id":"1.168136214","rc":[{"trd":[[4.1,944.93]],"batb":[[0,4.1,28.67]],"ltp":4.1,"tv":3325.24,"id":12925630}],"tv":13826.48}]}
{"op":"mcm","clk":"992403707","pt":1580557129103,"mc":[{"id":"1.168136214","rc":[{"batl":[[1,2.04,43.73]],"ltp":2.0,"tv":7825.53,"id":17336468}]}]}
{"op":"mcm","clk":"992405264","pt":1580557138976,"mc":[{"id":"1.168136214","rc":[{"batl":[[1,2.04,41.73]],"ltp":2.0,"tv":7825.53,"id":17336468}]}]}
{"op":"mcm","clk":"992405958","pt":1580557142897,"mc":[{"id":"1.168136214","rc":[{"batb":[[0,4.1,34.34]],"ltp":4.1,"tv":3325.24,"id":12925630},{"trd":[[3.75,345.43],[3.8,466.28]],"batb":[[0,3.8,3.32],[1,3.75,18.58],[2,3.7,18.75]],"ltp":3.75,"tv":2685.7,"id":11981493}],"tv":13836.48}]}
{"op":"mcm","clk":"992406691","pt":1580557147214,"mc":[{"id":"1.168136214","rc":[{"trd":[[4.1,948.93]],"batb":[[0,4.1,32.34]],"ltp":4.1,"tv":3329.24,"id":12925630}],"tv":13840.48}]}
{"op":"mcm","clk":"992408011","pt":1580557155033,"mc":[{"id":"1.168136214","rc":[{"batb":[[0,2,26.98]],"batl":[[0,2.02,10]],"ltp":2.0,"tv":7825.53,"id":17336468},{"trd":[[3.8,472.92]],"batb":[[0,3.75,18.58],[1,3.7,18.75],[2,3.65,11.83]],"batl":[[0,3.8,46.68],[1,3.85,14],[2,3.9,12.4]],"ltp":3.8,"tv":2692.34,"id":11981493}],"tv":13847.12}]}
{"op":"mcm","clk":"992408364","pt":1580557157144,"mc":[{"id":"1.168136214","rc":[{"batb":[[2,1.98,85.11]],"ltp":2.0,"tv":7825.53,"id":17336468}]}]}
{"op":"mcm","clk":"992408509","pt":1580557158144,"mc":[{"id":"1.168136214","rc":[{"trd":[[2,2355.1]],"batb":[[0,2,22.98]],"ltp":2.0,"tv":7833.53,"id":17336468},{"trd":[[3.75,357.43]],"batb":[[0,3.75,12.58]],"ltp":3.75,"tv":2704.34,"id":11981493}],"tv":13867.12}]}
{"op":"mcm","clk":"992409768","pt":1580557166067,"mc":[{"id":"1.168136214","rc":[{"batb":[[2,1.98,54.72]],"ltp":2.0,"tv":7833.53,"id":17336468}]}]}
{"op":"mcm","clk":"992411378","pt":1580557176082,"mc":[{"id":"1.168136214","rc":[{"trd":[[3.75,450.79]],"batb":[[0,3.8,2.19],[1,3.75,1.97],[2,3.7,18.75]],"batl":[[0,3.85,8],[1,3.9,12.4],[2,3.95,20]],"ltp":3.75,"tv":2797.7,"id":11981493}],"tv":13960.47}]}
{"op":"mcm","clk":"992411517","pt":1580557177079,"mc":[{"id":"1.168136214","rc":[{"trd":[[2,2385.1]],"batb":[[0,2,3.98]],"batl":[[0,2.02,20]],"ltp":2.0,"tv":7863.53,"id":17336468},{"batb":[[0,3.75,1.97],[1,3.7,18.75],[2,3.65,11.83]],"ltp":3.75,"tv":2797.7,"id":11981493}],"tv":13990.47}]}
{"op":"mcm","clk":"992411695","pt":1580557178140,"mc":[{"id":"1.168136214","rc":[{"trd":[[4.1,952.93]],"batb":[[0,4.1,30.34]],"ltp":4.1,"tv":3333.24,"id":12925630}],"tv":13994.47}]}
{"op":"mcm","clk":"992412373","pt":1580557181936,"mc":[{"id":"1.168136214","rc":[{"trd":[[4.1,962.03]],"batb":[[0,4.1,25.79]],"batl":[[2,4.4,136.73]],"ltp":4.1,"tv":3342.34,"id":12925630}],"tv":14003.58}]}
{"op":"mcm","clk":"992412566","pt":1580557183117,"mc":[{"id":"1.168136214","rc":[{"batb":[[0,4.1,28.01]],"ltp":4.1,"tv":3342.34,"id":12925630},{"batl":[[0,3.8,5],[1,3.85,8],[2,3.9,12.4]],"ltp":3.75,"tv":2797.7,"id":11981493}]}]}
{"op":"mcm","clk":"992412717","pt":1580557184030,"mc":[{"id":"1.168136214","rc":[{"batb":[[0,2,7.98]],"batl":[[0,2.02,10]],"ltp":2.0,"tv":7863.53,"id":17336468},{"batb":[[0,3.75,6.97]],"ltp":3.75,"tv":2797.7,"id":11981493}]}]}
{"op":"mcm","clk":"992414797","pt":1580557196146,"mc":[{"id":"1.168136214","rc":[{"batb":[[0,4.1,14.54]],"ltp":4.1,"tv":3342.34,"id":12925630}]}]}
{"op":"mcm","clk":"992414960","pt":1580557197045,"mc":[{"id":"1.168136214","rc":[{"trd":[[4.1,966.03]],"batb":[[0,4.1,12.54]],"ltp":4.1,"tv":3346.34,"id":12925630}],"tv":14007.58}]}
{"op":"mcm","clk":"992415651","pt":1580557201135,"mc":[{"id":"1.168136214","rc":[{"batb":[[0,4.1,23.79]],"ltp":4.1,"tv":3346.34,"id":12925630}]}]}
{"op":"mcm","clk":"992421835","pt":1580557237072,"mc":[{"id":"1.168136214","rc":[{"trd":[[4.1,970.03]],"batb":[[0,4.1,21.79]],"ltp":4.1,"tv":3350.34,"id":12925630}],"tv":14011.58}]}
{"op":"mcm","clk":"992424629","pt":1580557254784,"mc":[{"id":"1.168136214","rc":[{"trd":[[4.2,1142.29]],"batl":[[0,4.2,55.45]],"ltp":4.2,"tv":3350.35,"id":12925630},{"trd":[[2,2401.08]],"batb":[[0,2,3],[1,1.99,13]],"ltp":2.0,"tv":7879.51,"id":17336468},{"trd":[[3.8,472.94]],"batl":[[0,3.8,4.98]],"ltp":3.8,"tv":2797.72,"id":11981493}],"tv":14027.58}]}
{"op":"mcm","clk":"992426806","pt":1580557267104,"mc":[{"id":"1.168136214","rc":[{"trd":[[4.1,974.03]],"batb":[[0,4.1,19.79]],"ltp":4.1,"tv":3354.35,"id":12925630}],"tv":14031.58}]}
{"op":"mcm","clk":"992428593","pt":1580557277093,"mc":[{"id":"1.168136214","rc":[{"trd":[[4.1,978.03]],"batb":[[0,4.1,17.79]],"ltp":4.1,"tv":3358.35,"id":12925630}],"tv":14035.58}]}
{"op":"mcm","clk":"992428752","pt":1580557278118,"mc":[{"id":"1.168136214","rc":[{"batb":[[0,4.1,27.92]],"ltp":4.1,"tv":3358.35,"id":12925630},{"trd":[[3.8,482.9]],"batb":[[0,3.8,5.95],[1,3.75,6.97],[2,3.7,18.75]],"batl":[[0,3.85,8],[1,3.9,12.4],[2,3.95,20]],"ltp":3.8,"tv":2807.68,"id":11981493}],"tv":14045.54}]}
{"op":"mcm","clk":"992428895","pt":1580557278986,"mc":[{"id":"1.168136214","rc":[{"batb":[[0,4.1,22.25]],"ltp":4.1,"tv":3358.35,"id":12925630},{"batb":[[1,1.99,33.88]],"ltp":2.0,"tv":7879.51,"id":17336468}]}]}
{"op":"mcm","clk":"992429973","pt":1580557285116,"mc":[{"id":"1.168136214","rc":[{"batl":[[0,2.02,24]],"ltp":2.0,"tv":7879.51,"id":17336468},{"batb":[[2,3.7,30]],"ltp":3.8,"tv":2807.68,"id":11981493}]}]}
{"op":"mcm","clk":"992432083","pt":1580557297112,"mc":[{"id":"1.168136214","rc":[{"trd":[[4.1,982.02]],"batb":[[0,4.1,20.25]],"ltp":4.1,"tv":3362.34,"id":12925630}],"tv":14049.54}]}
{"op":"mcm","clk":"992434070","pt":1580557309144,"mc":[{"id":"1.168136214","rc":[{"trd":[[4.2,1149.62]],"batb":[[0,4.1,27.25]],"batl":[[0,4.2,48.12]],"ltp":4.2,"tv":3369.67,"id":12925630},{"trd":[[1.99,764.88],[2,2407.08]],"batb":[[0,1.98,54.72],[1,1.97,148],[2,1.95,6]],"batl":[[0,1.99,44.64],[1,2.02,44.66],[2,2.04,58.12]],"ltp":1.99,"tv":7974.74,"id":17336468},{"trd":[[3.85,407.05]],"batb":[[0,3.8,7.95],[2,3.7,18.75]],"batl":[[0,3.9,12.4],[1,3.95,20],[2,4,75]],"ltp":3.85,"tv":2815.68,"id":11981493}],"tv":14160.1}]}
{"op":"mcm","clk":"992434219","pt":1580557309944,"mc":[{"id":"1.168136214","rc":[{"batb":[[1,3.75,18.22]],"ltp":3.85,"tv":2815.68,"id":11981493}]}]}
{"op":"mcm","clk":"992434394","pt":1580557310926,"mc":[{"id":"1.168136214","rc":[{"batb":[[1,1.97,151],[2,1.96,3.27]],"batl":[[1,2,6.84],[2,2.02,44.66]],"ltp":1.99,"tv":7974.74,"id":17336468}]}]}
{"op":"mcm","clk":"992435533","pt":1580557317073,"mc":[{"id":"1.168136214","rc":[{"batl":[[1,2.02,30.66],[2,2.04,40.22]],"ltp":1.99,"tv":7974.74,"id":17336468}]}]}
{"op":"mcm","clk":"992435720","pt":1580557318149,"mc":[{"id":"1.168136214","rc":[{"trd":[[4.1,986.02]],"batb":[[0,4.1,25.25]],"ltp":4.1,"tv":3373.67,"id":12925630},{"batl":[[1,2.02,37.43],[2,2.04,11]],"ltp":1.99,"tv":7974.74,"id":17336468}],"tv":14164.1}]}
{"op":"mcm","clk":"992436230","pt":1580557321058,"mc":[{"id":"1.168136214","rc":[{"batb":[[0,1.98,69.2]],"ltp":1.99,"tv":7974.74,"id":17336468}]}]}
{"op":"mcm","clk":"992436754","pt":1580557324071,"mc":[{"id":"1.168136214","rc":[{"batb":[[2,3.7,13]],"batl":[[0,3.9,31.88]],"ltp":3.85,"tv":2815.68,"id":11981493}]}]}
{"op":"mcm","clk":"992437256","pt":1580557327081,"mc":[{"id":"1.168136214","rc":[{"trd":[[4.1,990.02]],"batb":[[0,4.1,23.25]],"ltp":4.1,"tv":3377.67,"id":12925630}],"tv":14168.1}]}
{"op":"mcm","clk":"992437420","pt":1580557328056,"mc":[{"id":"1.168136214","rc":[{"trd":[[1.98,1390.61]],"batb":[[0,1.99,3.04],[1,1.98,24.55],[2,1.97,151]],"batl":[[0,2.02,37.43],[1,2.04,11],[2,2.06,111]],"ltp":1.98,"tv":8064.03,"id":17336468},{"batl":[[0,3.85,6.04],[1,3.9,31.88],[2,3.95,20]],"ltp":3.85,"tv":2815.68,"id":11981493}],"tv":14257.39}]}
{"op":"mcm","clk":"992437600","pt":1580557329081,"mc":[{"id":"1.168136214","rc":[{"batl":[[0,2.02,16.77]],"ltp":1.98,"tv":8064.03,"id":17336468},{"batb":[[0,3.8,5.95]],"ltp":3.85,"tv":2815.68,"id":11981493}]}]}
{"op":"mcm","clk":"992437771","pt":1580557330095,"mc":[{"id":"1.168136214","rc":[{"batl":[[0,2.02,10],[2,2.06,139.67]],"ltp":1.98,"tv":8064.03,"id":17336468},{"batb":[[1,3.75,6.97],[2,3.7,24.25]],"ltp":3.85,"tv":2815.68,"id":11981493}]}]}
{"op":"mcm","clk":"992437890","pt":1580557330788,"mc":[{"id":"1.168136214","rc":[{"batl":[[1,2.04,17.7]],"ltp":1.98,"tv":8064.03,"id":17336468}]}]}
{"op":"mcm","clk":"992438327","pt":1580557333113,"mc":[{"id":"1.168136214","rc":[{"batb":[[2,1.97,181.39]],"ltp":1.98,"tv":8064.03,"id":17336468}]}]}
{"op":"mcm","clk":"992438510","pt":1580557334073,"mc":[{"id":"1.168136214","rc":[{"batb":[[0,3.8,14.33]],"ltp":3.85,"tv":2815.68,"id":11981493}]}]}
{"op":"mcm","clk":"992439806","pt":1580557341577,"mc":[{"id":"1.168136214","rc":[{"batb":[[2,1.97,151]],"ltp":1.98,"tv":8064.03,"id":17336468}]}]}
{"op":"mcm","clk":"992440249","pt":1580557344110,"mc":[{"id":"1.168136214","rc":[{"batl":[[0,2.02,24]],"ltp":1.98,"tv":8064.03,"id":17336468}]}]}
{"op":"mcm","clk":"992441080","pt":1580557349109,"mc":[{"id":"1.168136214","rc":[{"trd":[[4.1,994.02]],"batb":[[0,4.1,21.25]],"ltp":4.1,"tv":3381.67,"id":12925630}],"tv":14261.39}]}
{"op":"mcm","clk":"992442869","pt":1580557359081,"mc":[{"id":"1.168136214","rc":[{"trd":[[4.1,998.02]],"batb":[[0,4.1,19.25]],"ltp":4.1,"tv":3385.68,"id":12925630}],"tv":14265.39}]}
{"op":"mcm","clk":"992449346","pt":1580557396099,"mc":[{"id":"1.168136214","rc":[{"trd":[[1.99,765.08]],"batb":[[0,1.98,24.55],[1,1.97,151],[2,1.95,6]],"ltp":1.99,"tv":8064.23,"id":17336468},{"batl":[[0,3.9,31.88],[1,3.95,20],[2,4,75]],"ltp":3.85,"tv":2815.68,"id":11981493}],"tv":14265.59}]}
{"op":"mcm","clk":"992449684","pt":1580557398074,"mc":[{"id":"1.168136214","rc":[{"trd":[[4.1,1002.02]],"batb":[[0,4.1,17.25]],"ltp":4.1,"tv":3389.68,"id":12925630},{"batb":[[0,1.99,3.09],[1,1.98,24.55],[2,1.97,151]],"ltp":1.99,"tv":8064.23,"id":17336468}],"tv":14269.59}]}
{"op":"mcm","clk":"992450556","pt":1580557404092,"mc":[{"id":"1.168136214","rc":[{"batb":[[0,4.1,10.25]],"ltp":4.1,"tv":3389.68,"id":12925630},{"batl":[[0,2,13.03],[1,2.02,34],[2,2.04,17.7]],"ltp":1.99,"tv":8064.23,"id":17336468},{"batb":[[0,3.8,21.33],[1,3.75,1.97]],"ltp":3.85,"tv":2815.68,"id":11981493}]}]}
{"op":"mcm","clk":"992450697","pt":1580557404992,"mc":[{"id":"1.168136214","rc":[{"batl":[[2,2.04,46.37]],"ltp":1.99,"tv":8064.23,"id":17336468},{"batb":[[1,3.75,13.22],[2,3.7,13]],"ltp":3.85,"tv":2815.68,"id":11981493}]}]}
{"op":"mcm","clk":"992451177","pt":1580557408084,"mc":[{"id":"1.168136214","rc":[{"trd":[[4.1,1006.03]],"batb":[[0,4.1,8.25]],"ltp":4.1,"tv":3393.68,"id":12925630}],"tv":14273.59}]}
{"op":"mcm","clk":"992451323","pt":1580557409097,"mc":[{"id":"1.168136214","rc":[{"batb":[[0,4.1,15.25]],"ltp":4.1,"tv":3393.68,"id":12925630}]}]}
{"op":"mcm","clk":"992453008","pt":1580557419028,"mc":[{"id":"1.168136214","rc":[{"batl":[[0,3.85,20],[1,3.9,31.88],[2,3.95,20]],"ltp":3.85,"tv":2815.68,"id":11981493}]}]}
{"op":"mcm","clk":"992453177","pt":1580557420106,"mc":[{"id":"1.168136214","rc":[{"batb":[[0,4.1,23.84]],"ltp":4.1,"tv":3393.68,"id":12925630},{"trd":[[2,2433.14]],"batb":[[0,2,21.91],[1,1.99,3.09],[2,1.98,24.55]],"batl":[[0,2.02,24],[1,2.04,17.7],[2,2.06,139.67]],"ltp":2.0,"tv":8090.29,"id":17336468},{"batb":[[0,3.8,41.74],[1,3.75,1.97],[2,3.7,24.25]],"ltp":3.85,"tv":2815.68,"id":11981493}],"tv":14299.65}]}
{"op":"mcm","clk":"992454628","pt":1580557429091,"mc":[{"id":"1.168136214","rc":[{"trd":[[2,2441.14]],"batb":[[0,2,17.91]],"ltp":2.0,"tv":8098.29,"id":17336468},{"batb":[[0,3.8,43.74]],"ltp":3.85,"tv":2815.68,"id":11981493}],"tv":14307.65}]}
{"op":"mcm","clk":"992454766","pt":1580557429998,"mc":[{"id":"1.168136214","rc":[{"batb":[[2,3.7,13]],"ltp":3.85,"tv":2815.68,"id":11981493}]}]}
{"op":"mcm","clk":"992456102","pt":1580557438086,"mc":[{"id":"1.168136214","rc":[{"trd":[[4.1,1010.03]],"batb":[[0,4.1,21.84]],"ltp":4.1,"tv":3397.68,"id":12925630}],"tv":14311.65}]}
{"op":"mcm","clk":"992457750","pt":1580557448013,"mc":[{"id":"1.168136214","rc":[{"trd":[[4.1,1014.03]],"batb":[[0,4.1,19.83]],"ltp":4.1,"tv":3401.68,"id":12925630}],"tv":14315.65}]}
{"op":"mcm","clk":"992459343","pt":1580557458060,"mc":[{"id":"1.168136214","rc":[{"trd":[[4.1,1018.03]],"batb":[[0,4.1,17.83]],"ltp":4.1,"tv":3405.68,"id":12925630}],"tv":14319.65}]}
{"op":"mcm","clk":"992460818","pt":1580557467653,"mc":[{"id":"1.168136214","rc":[{"trd":[[4.1,1022.03]],"batb":[[0,4.1,15.83]],"ltp":4.1,"tv":3409.68,"id":12925630}],"tv":14323.66}]}
{"op":"mcm","clk":"992461544","pt":1580557472143,"mc":[{"id":"1.168136214","rc":[{"batl":[[1,3.9,12.4]],"ltp":3.85,"tv":2815.68,"id":11981493}]}]}
{"op":"mcm","clk":"992464627","pt":1580557491990,"mc":[{"id":"1.168136214","rc":[{"trd":[[3.8,507.9]],"batb":[[0,3.8,31.24]],"ltp":3.8,"tv":2840.68,"id":11981493}],"tv":14348.66}]}
{"op":"mcm","clk":"992466661","pt":1580557504021,"mc":[{"id":"1.168136214","rc":[{"batb":[[0,4.1,27.99]],"ltp":4.1,"tv":3409.68,"id":12925630}]}]}
{"op":"mcm","clk":"992467566","pt":1580557509111,"mc":[{"id":"1.168136214","rc":[{"batl":[[2,2.06,111]],"ltp":2.0,"tv":8098.29,"id":17336468}]}]}
{"op":"mcm","clk":"992469139","pt":1580557518961,"mc":[{"id":"1.168136214","rc":[{"trd":[[4.1,1026.03]],"batb":[[0,4.1,25.99]],"ltp":4.1,"tv":3413.68,"id":12925630}],"tv":14352.66}]}
{"op":"mcm","clk":"992470112","pt":1580557525125,"mc":[{"id":"1.168136214","rc":[{"trd":[[2.02,1151.41]],"batb":[[0,2.02,99],[1,2,17.91],[2,1.99,3.09]],"batl":[[0,2.04,17.7],[1,2.06,111],[2,2.08,3.63]],"ltp":2.02,"tv":8146.29,"id":17336468},{"batl":[[2,3.95,30.3]],"ltp":3.8,"tv":2840.68,"id":11981493}],"tv":14400.66}]}
{"op":"mcm","clk":"992470276","pt":1580557526087,"mc":[{"id":"1.168136214","rc":[{"batb":[[1,2,32.05]],"ltp":2.02,"tv":8146.29,"id":17336468},{"batb":[[0,3.8,29.24]],"batl":[[0,3.85,26]],"ltp":3.8,"tv":2840.68,"id":11981493}]}]}
{"op":"mcm","clk":"992470562","pt":1580557528104,"mc":[{"id":"1.168136214","rc":[{"trd":[[3.8,511.9]],"batb":[[0,3.8,27.24]],"ltp":3.8,"tv":2844.68,"id":11981493}],"tv":14404.66}]}
{"op":"mcm","clk":"992470718","pt":1580557529137,"mc":[{"id":"1.168136214","rc":[{"trd":[[4.1,1030.03]],"batb":[[0,4.1,23.99]],"ltp":4.1,"tv":3417.68,"id":12925630}],"tv":14408.66}]}
{"op":"mcm","clk":"992471211","pt":1580557532109,"mc":[{"id":"1.168136214","rc":[{"trd":[[4.1,1045.03]],"batb":[[0,4.1,16.49]],"ltp":4.1,"tv":3432.69,"id":12925630}],"tv":14423.67}]}
{"op":"mcm","clk":"992471742","pt":1580557535114,"mc":[{"id":"1.168136214","rc":[{"batl":[[2,3.95,20]],"ltp":3.8,"tv":2844.68,"id":11981493}]}]}
{"op":"mcm","clk":"992472193","pt":1580557538131,"mc":[{"id":"1.168136214","rc":[{"batb":[[0,2.02,104]],"batl":[[0,2.04,22.7]],"ltp":2.02,"tv":8146.29,"id":17336468}]}]}
{"op":"mcm","clk":"992472320","pt":1580557539032,"mc":[{"id":"1.168136214","rc":[{"trd":[[4.1,1049.03]],"batb":[[0,4.1,14.49]],"ltp":4.1,"tv":3436.69,"id":12925630},{"batb":[[1,3.75,3.97]],"ltp":3.8,"tv":2844.68,"id":11981493}],"tv":14427.67}]}
{"op":"mcm","clk":"992472493","pt":1580557540043,"mc":[{"id":"1.168136214","rc":[{"batl":[[1,4.3,151.62]],"ltp":4.1,"tv":3436.69,"id":12925630},{"batl":[[2,2.08,11.32]],"ltp":2.02,"tv":8146.29,"id":17336468},{"batl":[[2,3.95,25.39]],"ltp":3.8,"tv":2844.68,"id":11981493}]}]}
{"op":"mcm","clk":"992472793","pt":1580557542126,"mc":[{"id":"1.168136214","rc":[{"batb":[[2,3.95,17.45]],"ltp":4.1,"tv":3436.69,"id":12925630},{"batb":[[2,1.99,11.28]],"ltp":2.02,"tv":8146.29,"id":17336468},{"batb":[[2,3.7,18.7]],"ltp":3.8,"tv":2844.68,"id":11981493}]}]}
{"op":"mcm","clk":"992474004","pt":1580557549117,"mc":[{"id":"1.168136214","rc":[{"batb":[[2,3.95,22.96]],"batl":[[1,4.3,156.98]],"ltp":4.1,"tv":3436.69,"id":12925630},{"batl":[[2,2.08,18.76]],"ltp":2.02,"tv":8146.29,"id":17336468}]}]}
{"op":"mcm","clk":"992475564","pt":1580557559082,"mc":[{"id":"1.168136214","rc":[{"trd":[[4.1,1053.03]],"batb":[[0,4.1,12.49]],"ltp":4.1,"tv":3440.69,"id":12925630}],"tv":14431.67}]}
{"op":"mcm","clk":"992476691","pt":1580557565089,"mc":[{"id":"1.168136214","rc":[{"trd":[[2.02,1155.41]],"batb":[[0,2.02,102]],"ltp":2.02,"tv":8150.29,"id":17336468}],"tv":14435.67}]}
{"op":"mcm","clk":"992478946","pt":1580557579083,"mc":[{"id":"1.168136214","rc":[{"trd":[[4.1,1057.03]],"batb":[[0,4.1,10.49]],"ltp":4.1,"tv":3444.68,"id":12925630}],"tv":14439.66}]}
{"op":"mcm","clk":"992479766","pt":1580557584116,"mc":[{"id":"1.168136214","rc":[{"batl":[[0,4.2,69.19],[1,4.3,166.68]],"ltp":4.1,"tv":3444.68,"id":12925630}]}]}
{"op":"mcm","clk":"992479917","pt":1580557584948,"mc":[{"id":"1.168136214","rc":[{"trd":[[4.1,1078.02]],"batb":[[0,4,153.79],[1,3.95,22.96],[2,3.9,13]],"ltp":4.1,"tv":3465.67,"id":12925630},{"batb":[[0,2.02,106]],"batl":[[0,2.04,11.7]],"ltp":2.02,"tv":8150.29,"id":17336468},{"batl":[[0,3.85,20]],"ltp":3.8,"tv":2844.68,"id":11981493}],"tv":14460.65}]}
{"op":"mcm","clk":"992480113","pt":1580557586102,"mc":[{"id":"1.168136214","rc":[{"batl":[[0,4.1,81],[1,4.2,57.73],[2,4.3,156.98]],"ltp":4.1,"tv":3465.67,"id":12925630}]}]}
{"op":"mcm","clk":"992481225","pt":1580557593140,"mc":[{"id":"1.168136214","rc":[{"trd":[[2.04,375.66]],"batb":[[0,2.04,2.16],[1,2.02,106],[2,2,17.91]],"batl":[[0,2.06,111],[1,2.08,28.76],[2,2.1,95]],"ltp":2.04,"tv":8173.7,"id":17336468}],"tv":14484.06}]}
{"op":"mcm","clk":"992481341","pt":1580557594044,"mc":[{"id":"1.168136214","rc":[{"batl":[[0,2.06,113]],"ltp":2.04,"tv":8173.7,"id":17336468}]}]}
{"op":"mcm","clk":"992481469","pt":1580557594955,"mc":[{"id":"1.168136214","rc":[{"batb":[[1,3.95,17.45]],"ltp":4.1,"tv":3465.67,"id":12925630}]}]}
{"op":"mcm","clk":"992482303","pt":1580557600052,"mc":[{"id":"1.168136214","rc":[{"trd":[[2.04,379.66]],"batb":[[0,2.02,106.16],[1,2,17.91],[2,1.99,11.28]],"ltp":2.04,"tv":8177.7,"id":17336468}],"tv":14488.06}]}
{"op":"mcm","clk":"992482936","pt":1580557604065,"mc":[{"id":"1.168136214","rc":[{"batb":[[0,2.04,2.16],[1,2.02,106],[2,2,17.91]],"ltp":2.04,"tv":8177.7,"id":17336468}]}]}
{"op":"mcm","clk":"992483084","pt":1580557605071,"mc":[{"id":"1.168136214","rc":[{"batl":[[0,2.06,115]],"ltp":2.04,"tv":8177.7,"id":17336468}]}]}
{"op":"mcm","clk":"992483579","pt":1580557608066,"mc":[{"id":"1.168136214","rc":[{"batl":[[0,4.1,83]],"ltp":4.1,"tv":3465.67,"id":12925630}]}]}
{"op":"mcm","clk":"992484273","pt":1580557612088,"mc":[{"id":"1.168136214","rc":[{"trd":[[2.02,1159.09],[2.04,383.98]],"batb":[[0,2.02,104.16],[1,2,17.91],[2,1.99,11.28]],"ltp":2.02,"tv":8185.7,"id":17336468}],"tv":14496.06}]}
{"op":"mcm","clk":"992486709","pt":1580557624109,"mc":[{"id":"1.168136214","rc":[{"trd":[[3.8,551.9]],"batb":[[0,3.8,7.23]],"batl":[[0,3.85,26]],"ltp":3.8,"tv":2884.68,"id":11981493}],"tv":14536.06}]}
{"op":"mcm","clk":"992488042","pt":1580557632012,"mc":[{"id":"1.168136214","rc":[{"trd":[[3.85,407.09]],"batl":[[0,3.85,25.98]],"ltp":3.85,"tv":2884.72,"id":11981493}],"tv":14536.1}]}
{"op":"mcm","clk":"992489515","pt":1580557641025,"mc":[{"id":"1.168136214","rc":[{"trd":[[2.02,1165.09]],"batb":[[0,2.02,101.16]],"ltp":2.02,"tv":8191.7,"id":17336468}],"tv":14542.1}]}
{"op":"mcm","clk":"992489889","pt":1580557643069,"mc":[{"id":"1.168136214","rc":[{"trd":[[2.06,159.21]],"batl":[[0,2.06,112.06]],"ltp":2.06,"tv":8197.58,"id":17336468}],"tv":14547.98}]}
{"op":"mcm","clk":"992490933","pt":1580557649038,"mc":[{"id":"1.168136214","rc":[{"batb":[[0,3.8,12.23]],"batl":[[0,3.85,30.98]],"ltp":3.85,"tv":2884.72,"id":11981493}]}]}
{"op":"mcm","clk":"992503546","pt":1580557660070,"mc":[{"id":"1.168136214","rc":[{"trd":[[4,175.31]],"batb":[[0,4,148.74]],"ltp":4.0,"tv":3475.75,"id":12925630},{"trd":[[2.02,1170.59]],"batb":[[0,2.02,98.41]],"ltp":2.02,"tv":8203.08,"id":17336468}],"tv":14563.56}]}
{"op":"mcm","clk":"992504261","pt":1580557664102,"mc":[{"id":"1.168136214","rc":[{"batl":[[0,2.04,4],[1,2.06,112.06],[2,2.08,28.76]],"ltp":2.02,"tv":8203.08,"id":17336468}]}]}
{"op":"mcm","clk":"992504602","pt":1580557665980,"mc":[{"id":"1.168136214","rc":[{"batl":[[0,4.1,88],[1,4.2,52.73]],"ltp":4.0,"tv":3475.75,"id":12925630}]}]}
{"op":"mcm","clk":"992510190","pt":1580557693964,"mc":[{"id":"1.168136214","rc":[{"trd":[[4,195.31]],"batb":[[0,4,138.75]],"ltp":4.0,"tv":3495.75,"id":12925630}],"tv":14583.56}]}
{"op":"mcm","clk":"992515436","pt":1580557727144,"mc":[{"id":"1.168136214","rc":[{"trd":[[2.02,1258.59]],"batb":[[0,2.02,54.41]],"ltp":2.02,"tv":8291.08,"id":17336468}],"tv":14671.56}]}
{"op":"mcm","clk":"992521822","pt":1580557768065,"mc":[{"id":"1.168136214","rc":[{"trd":[[3.85,411.09]],"batl":[[0,3.85,28.98]],"ltp":3.85,"tv":2888.72,"id":11981493}],"tv":14675.56}]}
{"op":"mcm","clk":"992536675","pt":1580557858116,"mc":[{"id":"1.168136214","rc":[{"batl":[[1,4.2,43.12]],"ltp":4.0,"tv":3495.75,"id":12925630}]}]}
{"op":"mcm","clk":"992539026","pt":1580557872922,"mc":[{"id":"1.168136214","rc":[{"trd":[[2.02,1308.59]],"batb":[[0,2.02,29.41]],"ltp":2.02,"tv":8341.08,"id":17336468},{"batl":[[0,3.85,22.98]],"ltp":3.85,"tv":2888.72,"id":11981493}],"tv":14725.56}]}
{"op":"mcm","clk":"992539208","pt":1580557874101,"mc":[{"id":"1.168136214","rc":[{"batl":[[0,2.06,112.06],[1,2.08,28.76],[2,2.1,95]],"ltp":2.02,"tv":8341.08,"id":17336468}]}]}
{"op":"mcm","clk":"992539367","pt":1580557875114,"mc":[{"id":"1.168136214","rc":[{"batl":[[2,2.1,99]],"ltp":2.02,"tv":8341.08,"id":17336468}]}]}
{"op":"mcm","clk":"992542878","pt":1580557899025,"mc":[{"id":"1.168136214","rc":[{"batl":[[0,2.06,110.06]],"ltp":2.02,"tv":8341.08,"id":17336468}]}]}
{"op":"mcm","clk":"992543335","pt":1580557902132,"mc":[{"id":"1.168136214","rc":[{"trd":[[2.02,1328.59]],"batb":[[0,2.02,15.41]],"ltp":2.02,"tv":8361.08,"id":17336468}],"tv":14745.56}]}
{"op":"mcm","clk":"992543489","pt":1580557903121,"mc":[{"id":"1.168136214","rc":[{"batl":[[0,2.04,2],[1,2.06,110.06],[2,2.08,28.76]],"ltp":2.02,"tv":8361.08,"id":17336468}]}]}
{"op":"mcm","clk":"992543611","pt":1580557903917,"mc":[{"id":"1.168136214","rc":[{"batl":[[0,4.1,90]],"ltp":4.0,"tv":3495.75,"id":12925630},{"batl":[[0,2.04,12]],"ltp":2.02,"tv":8361.08,"id":17336468}]}]}
{"op":"mcm","clk":"992544376","pt":1580557909110,"mc":[{"id":"1.168136214","rc":[{"batl":[[1,2.06,108.06]],"ltp":2.02,"tv":8361.08,"id":17336468}]}]}
{"op":"mcm","clk":"992544728","pt":1580557911144,"mc":[{"id":"1.168136214","rc":[{"batl":[[0,2.04,32]],"ltp":2.02,"tv":8361.08,"id":17336468}]}]}
{"op":"mcm","clk":"992546830","pt":1580557924084,"mc":[{"id":"1.168136214","rc":[{"trd":[[3.85,447.09]],"batl":[[0,3.85,4.98]],"ltp":3.85,"tv":2924.72,"id":11981493}],"tv":14781.56}]}
{"op":"mcm","clk":"992547014","pt":1580557925091,"mc":[{"id":"1.168136214","rc":[{"batb":[[0,3.8,15.23]],"ltp":3.85,"tv":2924.72,"id":11981493}]}]}
{"op":"mcm","clk":"992547675","pt":1580557929112,"mc":[{"id":"1.168136214","rc":[{"trd":[[2.02,1354.59]],"batb":[[0,2.02,2.41]],"ltp":2.02,"tv":8387.08,"id":17336468}],"tv":14807.56}]}
{"op":"mcm","clk":"992550604","pt":1580557946126,"mc":[{"id":"1.168136214","rc":[{"trd":[[2.02,1359.41]],"batb":[[0,2,17.91],[1,1.99,11.28],[2,1.98,10.08]],"batl":[[0,2.02,77.59],[1,2.04,32],[2,2.06,108.06]],"ltp":2.02,"tv":8391.9,"id":17336468}],"tv":14812.38}]}
{"op":"mcm","clk":"992550749","pt":1580557946989,"mc":[{"id":"1.168136214","rc":[{"trd":[[4.1,1099.98]],"batl":[[0,4.1,79.02]],"ltp":4.1,"tv":3517.71,"id":12925630},{"batb":[[0,2,40.42],[1,1.99,3.09]],"batl":[[2,2.06,136.73]],"ltp":2.02,"tv":8391.9,"id":17336468},{"trd":[[3.85,457.05]],"batb":[[0,3.85,6.71],[1,3.8,15.23],[2,3.75,15.02]],"batl":[[0,3.9,12.4],[1,3.95,26],[2,4,80.55]],"ltp":3.85,"tv":2934.68,"id":11981493}],"tv":14844.3}]}
{"op":"mcm","clk":"992551684","pt":1580557953062,"mc":[{"id":"1.168136214","rc":[{"batb":[[2,1.98,15.08]],"batl":[[0,2.02,82.59]],"ltp":2.02,"tv":8391.9,"id":17336468}]}]}
{"op":"mcm","clk":"992552170","pt":1580557956064,"mc":[{"id":"1.168136214","rc":[{"batl":[[2,2.06,108.06]],"ltp":2.02,"tv":8391.9,"id":17336468},{"batb":[[2,3.75,3.97]],"ltp":3.85,"tv":2934.68,"id":11981493}]}]}
{"op":"mcm","clk":"992553953","pt":1580557966995,"mc":[{"id":"1.168136214","rc":[{"batl":[[0,2.02,87.59]],"ltp":2.02,"tv":8391.9,"id":17336468}]}]}
{"op":"mcm","clk":"992554127","pt":1580557968104,"mc":[{"id":"1.168136214","rc":[{"batb":[[0,2,45.42]],"ltp":2.02,"tv":8391.9,"id":17336468}]}]}
{"op":"mcm","clk":"992559091","pt":1580558001100,"mc":[{"id":"1.168136214","rc":[{"trd":[[2,2445.14]],"batb":[[0,2,43.42]],"ltp":2.0,"tv":8395.9,"id":17336468}],"tv":14848.3}]}
{"op":"mcm","clk":"992559986","pt":1580558007121,"mc":[{"id":"1.168136214","rc":[{"batb":[[0,2,45.42]],"ltp":2.0,"tv":8395.9,"id":17336468}]}]}
{"op":"mcm","clk":"992563461","pt":1580558030133,"mc":[{"id":"1.168136214","rc":[{"batl":[[0,4.1,77.02]],"ltp":4.1,"tv":3517.71,"id":12925630}]}]}
{"op":"mcm","clk":"992563791","pt":1580558032052,"mc":[{"id":"1.168136214","rc":[{"trd":[[2.02,1373.41]],"batl":[[0,2.02,80.59]],"ltp":2.02,"tv":8409.9,"id":17336468}],"tv":14862.3}]}
{"op":"mcm","clk":"992564335","pt":1580558035668,"mc":[{"id":"1.168136214","rc":[{"trd":[[2.02,1377.41]],"batb":[[0,2,43.42]],"batl":[[0,2.02,78.59]],"ltp":2.02,"tv":8413.9,"id":17336468}],"tv":14866.3}]}
{"op":"mcm","clk":"992565172","pt":1580558041050,"mc":[{"id":"1.168136214","rc":[{"trd":[[2,2446.86]],"batb":[[0,2,42.56]],"ltp":2.0,"tv":8415.62,"id":17336468},{"trd":[[3.85,458.77]],"batb":[[0,3.85,5.85]],"ltp":3.85,"tv":2936.4,"id":11981493}],"tv":14869.74}]}
{"op":"mcm","clk":"992565737","pt":1580558044858,"mc":[{"id":"1.168136214","rc":[{"trd":[[2,2446.9]],"batb":[[0,2,42.54]],"ltp":2.0,"tv":8415.66,"id":17336468},{"trd":[[3.85,458.81]],"batb":[[0,3.85,5.83]],"ltp":3.85,"tv":2936.44,"id":11981493}],"tv":14869.82}]}
{"op":"mcm","clk":"992566055","pt":1580558046990,"mc":[{"id":"1.168136214","rc":[{"trd":[[3.9,190.11]],"batl":[[0,3.95,26],[1,4,80.55],[2,4.1,27.62]],"ltp":3.9,"tv":2961.24,"id":11981493}],"tv":14894.62}]}
{"op":"mcm","clk":"992566226","pt":1580558048059,"mc":[{"id":"1.168136214","rc":[{"trd":[[2,2471.2]],"batb":[[0,2,30.38]],"ltp":2.0,"tv":8439.96,"id":17336468},{"trd":[[3.8,564.54],[3.85,470.47]],"batb":[[0,3.8,14.5],[1,3.75,3.97],[2,3.7,18.7]],"batl":[[0,3.9,5.04],[1,3.95,26],[2,4,80.55]],"ltp":3.8,"tv":2985.54,"id":11981493}],"tv":14943.22}]}
{"op":"mcm","clk":"992568628","pt":1580558064112,"mc":[{"id":"1.168136214","rc":[{"trd":[[3.9,200.19]],"batl":[[0,3.9,4.13]],"ltp":3.9,"tv":2995.62,"id":11981493}],"tv":14953.3}]}
{"op":"mcm","clk":"992569433","pt":1580558069030,"mc":[{"id":"1.168136214","rc":[{"trd":[[4.1,1129.98]],"batl":[[0,4.1,62.02]],"ltp":4.1,"tv":3547.71,"id":12925630}],"tv":14983.3}]}
{"op":"mcm","clk":"992569876","pt":1580558072060,"mc":[{"id":"1.168136214","rc":[{"trd":[[2,2479.2]],"batb":[[0,2,29.38]],"ltp":2.0,"tv":8447.96,"id":17336468}],"tv":14991.3}]}
{"op":"mcm","clk":"992570468","pt":1580558076126,"mc":[{"id":"1.168136214","rc":[{"trd":[[3.8,572.54]],"batb":[[0,3.8,10.5]],"ltp":3.8,"tv":3003.62,"id":11981493}],"tv":14999.3}]}
{"op":"mcm","clk":"992570898","pt":1580558079050,"mc":[{"id":"1.168136214","rc":[{"trd":[[3.8,576.54]],"batb":[[0,3.8,8.5]],"ltp":3.8,"tv":3007.62,"id":11981493}],"tv":15003.3}]}
{"op":"mcm","clk":"992571211","pt":1580558081147,"mc":[{"id":"1.168136214","rc":[{"trd":[[3.9,206.19]],"batl":[[0,3.9,1.13]],"ltp":3.9,"tv":3013.62,"id":11981493}],"tv":15009.3}]}
{"op":"mcm","clk":"992571366","pt":1580558082154,"mc":[{"id":"1.168136214","rc":[{"trd":[[3.9,208.45]],"batl":[[0,3.9,3.22],[1,3.95,23]],"ltp":3.9,"tv":3015.88,"id":11981493}],"tv":15011.56}]}
{"op":"mcm","clk":"992571973","pt":1580558086128,"mc":[{"id":"1.168136214","rc":[{"batl":[[0,3.9,8.22]],"ltp":3.9,"tv":3015.88,"id":11981493}]}]}
{"op":"mcm","clk":"992572040","pt":1580558086553,"mc":[{"id":"1.168136214","rc":[{"batb":[[0,3.85,5],[1,3.8,8.5],[2,3.75,3.97]],"ltp":3.9,"tv":3015.88,"id":11981493}]}]}
{"op":"mcm","clk":"992572571","pt":1580558090156,"mc":[{"id":"1.168136214","rc":[{"trd":[[4.1,1139.2]],"batl":[[0,4.1,57.41]],"ltp":4.1,"tv":3556.93,"id":12925630}],"tv":15020.78}]}
{"op":"mcm","clk":"992573274","pt":1580558095131,"mc":[{"id":"1.168136214","rc":[{"trd":[[2,2483.2]],"batb":[[0,2,27.38]],"ltp":2.0,"tv":8451.96,"id":17336468}],"tv":15024.78}]}
{"op":"mcm","clk":"992574148","pt":1580558100979,"mc":[{"id":"1.168136214","rc":[{"batl":[[1,2.04,32.29]],"ltp":2.0,"tv":8451.96,"id":17336468},{"batl":[[1,3.95,23.29]],"ltp":3.9,"tv":3015.88,"id":11981493}]}]}
{"op":"mcm","clk":"992574452","pt":1580558102947,"mc":[{"id":"1.168136214","rc":[{"trd":[[4.1,1163.52]],"batl":[[0,4.1,45.24]],"ltp":4.1,"tv":3581.26,"id":12925630}],"tv":15049.11}]}
{"op":"mcm","clk":"992575071","pt":1580558106793,"mc":[{"id":"1.168136214","rc":[{"batl":[[1,2.04,45.01]],"ltp":2.0,"tv":8451.96,"id":17336468},{"batl":[[1,3.95,36.01]],"ltp":3.9,"tv":3015.88,"id":11981493}]}]}
{"op":"mcm","clk":"992578806","pt":1580558132121,"mc":[{"id":"1.168136214","rc":[{"trd":[[3.85,478.47]],"batb":[[0,3.85,1]],"ltp":3.85,"tv":3023.88,"id":11981493}],"tv":15057.11}]}
{"op":"mcm","clk":"992579065","pt":1580558134109,"mc":[{"id":"1.168136214","rc":[{"batl":[[0,3.9,10.22]],"ltp":3.85,"tv":3023.88,"id":11981493}]}]}
{"op":"mcm","clk":"992580043","pt":1580558141121,"mc":[{"id":"1.168136214","rc":[{"trd":[[3.95,72.48],[4,482.76]],"batb":[[0,4,3.26],[1,3.95,7]],"batl":[[0,4.1,55.24]],"ltp":3.95,"tv":3941.19,"id":12925630},{"trd":[[2.02,1468.88]],"batl":[[0,2.02,11.02],[1,2.04,47.01]],"ltp":2.02,"tv":8543.43,"id":17336468},{"trd":[[3.9,218.67],[3.95,91.58]],"batb":[[1,3.8,10.59],[2,3.75,8.03]],"batl":[[0,3.95,9.91],[1,4,80.55],[2,4.1,27.62]],"ltp":3.95,"tv":3064.2,"id":11981493}],"tv":15548.83}]}
{"op":"mcm","clk":"992580187","pt":1580558142135,"mc":[{"id":"1.168136214","rc":[{"trd":[[4.1,1171.52]],"batb":[[0,3.95,7],[1,3.9,23.48],[2,3.85,28.17]],"batl":[[0,4.1,51.24]],"ltp":4.1,"tv":3949.19,"id":12925630},{"batb":[[1,3.8,5]],"batl":[[0,3.95,7.91]],"ltp":3.95,"tv":3064.2,"id":11981493}],"tv":15556.83}]}
{"op":"mcm","clk":"992580322","pt":1580558143034,"mc":[{"id":"1.168136214","rc":[{"batl":[[0,2.02,16.72]],"ltp":2.02,"tv":8543.43,"id":17336468},{"batb":[[0,3.85,6.23],[1,3.8,21.39]],"ltp":3.95,"tv":3064.2,"id":11981493}]}]}
{"op":"mcm","clk":"992580630","pt":1580558145120,"mc":[{"id":"1.168136214","rc":[{"batl":[[1,4,75]],"ltp":3.95,"tv":3064.2,"id":11981493}]}]}
{"op":"mcm","clk":"992581087","pt":1580558147988,"mc":[{"id":"1.168136214","rc":[{"trd":[[3.95,94.72]],"batb":[[0,3.95,4.36]],"batl":[[0,4.1,53.24]],"ltp":3.95,"tv":3971.43,"id":12925630},{"trd":[[2.02,1474.66]],"batl":[[0,2.02,10.94]],"ltp":2.02,"tv":8549.21,"id":17336468},{"trd":[[3.95,94.54]],"batl":[[0,3.95,4.95],[2,4.1,32.73]],"ltp":3.95,"tv":3067.16,"id":11981493}],"tv":15587.81}]}
{"op":"mcm","clk":"992581199","pt":1580558148820,"mc":[{"id":"1.168136214","rc":[{"batl":[[0,3.95,18.95]],"ltp":3.95,"tv":3067.16,"id":11981493}]}]}
{"op":"mcm","clk":"992586355","pt":1580558183147,"mc":[{"id":"1.168136214","rc":[{"batb":[[0,3.95,7]],"ltp":3.95,"tv":3971.43,"id":12925630},{"trd":[[3.95,132.44]],"batb":[[0,3.9,14.16],[1,3.85,6.23],[2,3.8,21.39]],"batl":[[0,4,77],[1,4.1,34.9],[2,4.2,5.13]],"ltp":3.95,"tv":3105.06,"id":11981493}],"tv":15625.71}]}
{"op":"mcm","clk":"992586508","pt":1580558184119,"mc":[{"id":"1.168136214","rc":[{"batl":[[0,4,2],[1,4.1,53.24],[2,4.2,43.12]],"ltp":3.95,"tv":3971.43,"id":12925630},{"batb":[[0,3.9,14.18]],"ltp":3.95,"tv":3105.06,"id":11981493}]}]}
{"op":"mcm","clk":"992586663","pt":1580558185128,"mc":[{"id":"1.168136214","rc":[{"batb":[[0,3.9,20.18]],"batl":[[1,4.1,32.73]],"ltp":3.95,"tv":3105.06,"id":11981493}]}]}
{"op":"mcm","clk":"992586787","pt":1580558185933,"mc":[{"id":"1.168136214","rc":[{"trd":[[3.9,222.67]],"batb":[[0,3.9,18.18],[2,3.8,10.54]],"ltp":3.9,"tv":3109.06,"id":11981493}],"tv":15629.71}]}
{"op":"mcm","clk":"992589040","pt":1580558200114,"mc":[{"id":"1.168136214","rc":[{"trd":[[3.95,98.72]],"batb":[[0,3.95,5]],"batl":[[1,4.1,51.24]],"ltp":3.95,"tv":3975.43,"id":12925630}],"tv":15633.71}]}
{"op":"mcm","clk":"992589181","pt":1580558200974,"mc":[{"id":"1.168136214","rc":[{"batb":[[0,3.9,13],[1,3.85,38.65],[2,3.8,5.25]],"ltp":3.95,"tv":3975.43,"id":12925630}]}]}
{"op":"mcm","clk":"992589660","pt":1580558204096,"mc":[{"id":"1.168136214","rc":[{"trd":[[3.85,77.32],[3.9,31.67]],"batb":[[0,3.8,5.25],[1,3.75,3],[2,3.6,69]],"batl":[[0,3.85,2.66],[1,4,2],[2,4.1,51.24]],"ltp":3.85,"tv":4084.42,"id":12925630},{"trd":[[2.02,1485.6]],"batl":[[0,2.04,47.01],[1,2.06,108.06],[2,2.08,28.76]],"ltp":2.02,"tv":8560.15,"id":17336468},{"trd":[[4,101.27]],"batl":[[0,4,71.48]],"ltp":4.0,"tv":3114.58,"id":11981493}],"tv":15759.16}]}
{"op":"mcm","clk":"992589767","pt":1580558204780,"mc":[{"id":"1.168136214","rc":[{"trd":[[3.85,82.64]],"batb":[[0,3.9,2.44],[1,3.85,6],[2,3.8,5.25]],"batl":[[0,3.95,4.19],[1,4,6.5],[2,4.1,56.79]],"ltp":3.85,"tv":4089.74,"id":12925630},{"batb":[[0,2.02,4.24],[1,2,27.38],[2,1.99,3.09]],"batl":[[0,2.04,37.01]],"ltp":2.02,"tv":8560.15,"id":17336468},{"batb":[[2,3.8,16.07]],"batl":[[1,4.1,34.73]],"ltp":4.0,"tv":3114.58,"id":11981493}],"tv":15764.48}]}
{"op":"mcm","clk":"992589974","pt":1580558206107,"mc":[{"id":"1.168136214","rc":[{"batl":[[1,4,16.58]],"ltp":3.85,"tv":4089.74,"id":12925630},{"batb":[[2,1.99,11.28]],"ltp":2.02,"tv":8560.15,"id":17336468}]}]}
{"op":"mcm","clk":"992590092","pt":1580558206800,"mc":[{"id":"1.168136214","rc":[{"batb":[[2,3.8,11.25]],"ltp":3.85,"tv":4089.74,"id":12925630}]}]}
{"op":"mcm","clk":"992590281","pt":1580558208094,"mc":[{"id":"1.168136214","rc":[{"batb":[[1,3.85,16.89]],"ltp":4.0,"tv":3114.58,"id":11981493}]}]}
{"op":"mcm","clk":"992590438","pt":1580558209107,"mc":[{"id":"1.168136214","rc":[{"batb":[[2,3.8,11.49]],"ltp":3.85,"tv":4089.74,"id":12925630},{"batl":[[0,2.04,35.01]],"ltp":2.02,"tv":8560.15,"id":17336468}]}]}
{"op":"mcm","clk":"992590749","pt":1580558211127,"mc":[{"id":"1.168136214","rc":[{"trd":[[3.85,94.64],[3.9,36.55]],"batb":[[0,3.8,11.49],[1,3.75,8.44],[2,3.65,5.79]],"batl":[[0,3.85,31.56],[1,3.95,4.19],[2,4,16.58]],"ltp":3.85,"tv":4106.62,"id":12925630}],"tv":15781.36}]}
{"op":"mcm","clk":"992590901","pt":1580558212086,"mc":[{"id":"1.168136214","rc":[{"trd":[[3.85,157.76]],"batb":[[0,3.85,3.95],[1,3.8,29.89],[2,3.75,8.68]],"batl":[[0,3.95,9.89],[1,4,16.58],[2,4.1,56.79]],"ltp":3.85,"tv":4169.74,"id":12925630},{"batb":[[0,2.02,39.3]],"ltp":2.02,"tv":8560.15,"id":17336468},{"batb":[[0,3.95,17.93],[1,3.9,18.18],[2,3.85,16.89]],"batl":[[0,4,69.48]],"ltp":4.0,"tv":3114.58,"id":11981493}],"tv":15844.48}]}
{"op":"mcm","clk":"992591069","pt":1580558213093,"mc":[{"id":"1.168136214","rc":[{"batl":[[0,3.95,4.19]],"ltp":3.85,"tv":4169.74,"id":12925630}]}]}
{"op":"mcm","clk":"992591704","pt":1580558217116,"mc":[{"id":"1.168136214","rc":[{"batb":[[2,3.75,5.68]],"ltp":3.85,"tv":4169.74,"id":12925630},{"batb":[[2,3.85,6.23]],"ltp":4.0,"tv":3114.58,"id":11981493}]}]}
{"op":"mcm","clk":"992591987","pt":1580558219095,"mc":[{"id":"1.168136214","rc":[{"batb":[[2,3.75,5.44]],"ltp":3.85,"tv":4169.74,"id":12925630}]}]}
{"op":"mcm","clk":"992592326","pt":1580558221113,"mc":[{"id":"1.168136214","rc":[{"batl":[[0,3.95,11.93]],"ltp":3.85,"tv":4169.74,"id":12925630},{"trd":[[2.02,1486.64]],"batb":[[0,2.02,55.31]],"ltp":2.02,"tv":8561.19,"id":17336468},{"trd":[[3.95,133.48]],"batb":[[0,3.95,24.94]],"ltp":3.95,"tv":3115.62,"id":11981493}],"tv":15846.56}]}
{"op":"mcm","clk":"992592485","pt":1580558222120,"mc":[{"id":"1.168136214","rc":[{"trd":[[3.95,112.24]],"batb":[[0,3.9,106],[1,3.85,3.95],[2,3.8,29.89]],"batl":[[0,3.95,2.79],[1,4,14.08]],"ltp":3.95,"tv":4183.26,"id":12925630},{"batb":[[0,2.02,35.06]],"batl":[[0,2.04,60.68]],"ltp":2.02,"tv":8561.19,"id":17336468},{"batb":[[0,3.95,17.41]],"ltp":3.95,"tv":3115.62,"id":11981493}],"tv":15860.08}]}
{"op":"mcm","clk":"992592840","pt":1580558224133,"mc":[{"id":"1.168136214","rc":[{"trd":[[2.02,1543.69]],"batb":[[0,2.02,9.54]],"batl":[[0,2.04,35.01]],"ltp":2.02,"tv":8618.23,"id":17336468},{"trd":[[3.95,168.27]],"batb":[[0,3.9,33.39],[1,3.85,6.23],[2,3.8,16.07]],"batl":[[0,3.95,21.08],[1,4,71.48],[2,4.1,34.73]],"ltp":3.95,"tv":3150.42,"id":11981493}],"tv":15951.92}]}
{"op":"mcm","clk":"992593014","pt":1580558225139,"mc":[{"id":"1.168136214","rc":[{"batl":[[1,2.06,110.39]],"ltp":2.02,"tv":8618.23,"id":17336468}]}]}
{"op":"mcm","clk":"992593337","pt":1580558227007,"mc":[{"id":"1.168136214","rc":[{"batl":[[1,2.06,108.06]],"ltp":2.02,"tv":8618.23,"id":17336468}]}]}
{"op":"mcm","clk":"992593963","pt":1580558231101,"mc":[{"id":"1.168136214","rc":[{"batb":[[1,3.85,11.02]],"ltp":3.95,"tv":4183.26,"id":12925630},{"batb":[[1,2,47.55]],"ltp":2.02,"tv":8618.23,"id":17336468},{"batb":[[1,3.85,13.3]],"ltp":3.95,"tv":3150.42,"id":11981493}]}]}
{"op":"mcm","clk":"992595164","pt":1580558239115,"mc":[{"id":"1.168136214","rc":[{"trd":[[2.02,1545.72]],"batb":[[0,2.02,8.52]],"ltp":2.02,"tv":8620.27,"id":17336468},{"trd":[[3.9,224.71]],"batb":[[0,3.9,32.37]],"ltp":3.9,"tv":3152.46,"id":11981493}],"tv":15956.0}]}
{"op":"mcm","clk":"992597828","pt":1580558256145,"mc":[{"id":"1.168136214","rc":[{"trd":[[3.95,117.82]],"batb":[[0,3.95,10.97],[1,3.9,106],[2,3.85,11.02]],"batl":[[0,4,12.08],[1,4.1,56.79],[2,4.2,43.12]],"ltp":3.95,"tv":4188.84,"id":12925630},{"batb":[[0,2.02,5.52],[1,2,49.55]],"batl":[[0,2.04,60.51]],"ltp":2.02,"tv":8620.27,"id":17336468},{"batb":[[2,3.8,19.07]],"ltp":3.9,"tv":3152.46,"id":11981493}],"tv":15961.58}]}
{"op":"mcm","clk":"992597998","pt":1580558257153,"mc":[{"id":"1.168136214","rc":[{"batl":[[0,4,2],[1,4.1,66.88]],"ltp":3.95,"tv":4188.84,"id":12925630},{"batb":[[1,2,29.38],[2,1.99,31.65]],"batl":[[1,2.06,136.73]],"ltp":2.02,"tv":8620.27,"id":17336468}]}]}
{"op":"mcm","clk":"992598122","pt":1580558257948,"mc":[{"id":"1.168136214","rc":[{"trd":[[3.95,137.73]],"batb":[[0,3.95,1.01]],"ltp":3.95,"tv":4208.75,"id":12925630}],"tv":15981.49}]}
{"op":"mcm","clk":"992598274","pt":1580558259058,"mc":[{"id":"1.168136214","rc":[{"batl":[[1,4.1,75.31],[2,4.2,52.7]],"ltp":3.95,"tv":4208.75,"id":12925630},{"batl":[[0,2.04,62.51]],"ltp":2.02,"tv":8620.27,"id":17336468}]}]}
{"op":"mcm","clk":"992599462","pt":1580558266057,"mc":[{"id":"1.168136214","rc":[{"batl":[[1,2.06,108.06]],"ltp":2.02,"tv":8620.27,"id":17336468}]}]}
{"op":"mcm","clk":"992599624","pt":1580558267058,"mc":[{"id":"1.168136214","rc":[{"trd":[[2.02,1556.76]],"batb":[[0,2,29.38],[1,1.99,31.65],[2,1.98,35.65]],"batl":[[0,2.02,21.22],[1,2.04,62.51],[2,2.06,108.06]],"ltp":2.02,"tv":8631.31,"id":17336468},{"trd":[[3.95,172.27]],"batl":[[0,3.95,19.09]],"ltp":3.95,"tv":3156.45,"id":11981493}],"tv":15996.52}]}
{"op":"mcm","clk":"992599780","pt":1580558268066,"mc":[{"id":"1.168136214","rc":[{"batb":[[1,3.9,111.25]],"ltp":3.95,"tv":4208.75,"id":12925630}]}]}
{"op":"mcm","clk":"992599896","pt":1580558268956,"mc":[{"id":"1.168136214","rc":[{"batl":[[1,4.1,75.07]],"ltp":3.95,"tv":4208.75,"id":12925630}]}]}
{"op":"mcm","clk":"992600392","pt":1580558272143,"mc":[{"id":"1.168136214","rc":[{"trd":[[3.95,143.93]],"batb":[[0,3.9,111.25],[1,3.85,11.02],[2,3.8,29.89]],"batl":[[1,4.1,70.07]],"ltp":3.95,"tv":4214.95,"id":12925630},{"trd":[[2.02,1575.13]],"batb":[[0,2,24.38]],"batl":[[0,2.02,7.95]],"ltp":2.02,"tv":8649.68,"id":17336468},{"trd":[[3.95,176.44]],"batb":[[1,3.85,12.3]],"batl":[[0,3.95,14.91]],"ltp":3.95,"tv":3160.62,"id":11981493}],"tv":16025.26}]}
{"op":"mcm","clk":"992600547","pt":1580558273068,"mc":[{"id":"1.168136214","rc":[{"batb":[[0,3.95,4.28],[1,3.9,111.25],[2,3.85,11.02]],"batl":[[0,4,9.56]],"ltp":3.95,"tv":4214.95,"id":12925630},{"batb":[[0,2,41.24]],"ltp":2.02,"tv":8649.68,"id":17336468},{"trd":[[3.95,178.76]],"batb":[[1,3.85,15.07]],"batl":[[0,3.95,13.75]],"ltp":3.95,"tv":3162.94,"id":11981493}],"tv":16027.58}]}
{"op":"mcm","clk":"992601717","pt":1580558280090,"mc":[{"id":"1.168136214","rc":[{"batb":[[1,3.9,118.21]],"ltp":3.95,"tv":4214.95,"id":12925630}]}]}
{"op":"mcm","clk":"992601878","pt":1580558281061,"mc":[{"id":"1.168136214","rc":[{"trd":[[2,2497.2]],"batb":[[0,2,34.24]],"ltp":2.0,"tv":8663.68,"id":17336468}],"tv":16041.58}]}
{"op":"mcm","clk":"992602033","pt":1580558282071,"mc":[{"id":"1.168136214","rc":[{"batb":[[0,3.95,11.84]],"batl":[[0,4,2],[2,4.2,55.28]],"ltp":3.95,"tv":4214.95,"id":12925630}]}]}
{"op":"mcm","clk":"992602197","pt":1580558282982,"mc":[{"id":"1.168136214","rc":[{"batb":[[1,3.9,128.69]],"ltp":3.95,"tv":4214.95,"id":12925630},{"batl":[[0,2.02,13.73]],"ltp":2.0,"tv":8663.68,"id":17336468}]}]}
{"op":"mcm","clk":"992603997","pt":1580558294038,"mc":[{"id":"1.168136214","rc":[{"batb":[[2,1.98,40.65]],"batl":[[0,2.02,18.73]],"ltp":2.0,"tv":8663.68,"id":17336468}]}]}
{"op":"mcm","clk":"992604184","pt":1580558295102,"mc":[{"id":"1.168136214","rc":[{"batb":[[1,1.99,23.46]],"ltp":2.0,"tv":8663.68,"id":17336468}]}]}
{"op":"mcm","clk":"992609065","pt":1580558330792,"mc":[{"id":"1.168136214","rc":[{"batl":[[0,2.02,34.15]],"ltp":2.0,"tv":8663.68,"id":17336468},{"trd":[[3.95,182.76]],"batl":[[0,3.95,11.76]],"ltp":3.95,"tv":3166.94,"id":11981493}],"tv":16045.58}]}
{"op":"mcm","clk":"992614882","pt":1580558358070,"mc":[{"id":"1.168136214","rc":[{"trd":[[2.02,1579.13]],"batl":[[0,2.02,32.15]],"ltp":2.02,"tv":8667.68,"id":17336468}],"tv":16049.58}]}
{"op":"mcm","clk":"992615737","pt":1580558363036,"mc":[{"id":"1.168136214","rc":[{"batl":[[2,2.06,121.69]],"ltp":2.02,"tv":8667.68,"id":17336468}]}]}
{"op":"mcm","clk":"992616612","pt":1580558368010,"mc":[{"id":"1.168136214","rc":[{"batl":[[0,2.02,8.78]],"ltp":2.02,"tv":8667.68,"id":17336468}]}]}
{"op":"mcm","clk":"992616813","pt":1580558369023,"mc":[{"id":"1.168136214","rc":[{"trd":[[2,2548.8]],"batb":[[0,2,5]],"batl":[[0,2.02,25.8]],"ltp":2.0,"tv":8719.27,"id":17336468},{"trd":[[3.95,186.75]],"batl":[[0,3.95,9.76]],"ltp":3.95,"tv":3170.94,"id":11981493}],"tv":16105.17}]}
{"op":"mcm","clk":"992616928","pt":1580558369835,"mc":[{"id":"1.168136214","rc":[{"batb":[[0,1.99,3.09],[1,1.98,40.65],[2,1.97,148]],"ltp":2.0,"tv":8719.27,"id":17336468}]}]}
{"op":"mcm","clk":"992617499","pt":1580558373124,"mc":[{"id":"1.168136214","rc":[{"batl":[[0,4,71.48],[1,4.1,34.73],[2,4.2,5.13]],"ltp":3.95,"tv":3170.94,"id":11981493}]}]}
{"op":"mcm","clk":"992618964","pt":1580558382124,"mc":[{"id":"1.168136214","rc":[{"trd":[[4,486.76],[4.1,1177.96]],"batl":[[0,4,9.17],[1,4.1,66.85]],"ltp":4.1,"tv":4225.39,"id":12925630}],"tv":16115.61}]}
{"op":"mcm","clk":"992619151","pt":1580558383122,"mc":[{"id":"1.168136214","rc":[{"batb":[[1,3.9,120.21]],"ltp":4.1,"tv":4225.39,"id":12925630},{"batb":[[0,1.99,20.17]],"ltp":2.0,"tv":8719.27,"id":17336468}]}]}
{"op":"mcm","clk":"992620329","pt":1580558390143,"mc":[{"id":"1.168136214","rc":[{"batb":[[0,2,18.98],[1,1.99,43.45],[2,1.98,40.65]],"batl":[[2,2.06,126.63]],"ltp":2.0,"tv":8719.27,"id":17336468},{"batb":[[0,3.9,35.37]],"ltp":3.95,"tv":3170.94,"id":11981493}]}]}
{"op":"mcm","clk":"992622225","pt":1580558401110,"mc":[{"id":"1.168136214","rc":[{"trd":[[4,505.1]],"batb":[[0,4,16.16],[1,3.95,11.84],[2,3.9,120.21]],"batl":[[0,4.1,66.85],[1,4.2,55.28],[2,4.3,156.98]],"ltp":4.0,"tv":4243.73,"id":12925630}],"tv":16133.94}]}
{"op":"mcm","clk":"992622437","pt":1580558402095,"mc":[{"id":"1.168136214","rc":[{"batb":[[0,4,21.16]],"batl":[[0,4.1,61.3],[1,4.2,46.12]],"ltp":4.0,"tv":4243.73,"id":12925630},{"batb":[[1,1.99,23.08]],"batl":[[0,2.02,39.8]],"ltp":2.0,"tv":8719.27,"id":17336468}]}]}
{"op":"mcm","clk":"992622644","pt":1580558403084,"mc":[{"id":"1.168136214","rc":[{"trd":[[4,522.67]],"batb":[[0,4,12.38]],"ltp":4.0,"tv":4261.3,"id":12925630},{"batb":[[0,2,36.07]],"ltp":2.0,"tv":8719.27,"id":17336468}],"tv":16151.52}]}
{"op":"mcm","clk":"992623877","pt":1580558409089,"mc":[{"id":"1.168136214","rc":[{"batb":[[1,3.95,18.68]],"ltp":4.0,"tv":4261.3,"id":12925630}]}]}
{"op":"mcm","clk":"992624143","pt":1580558410095,"mc":[{"id":"1.168136214","rc":[{"batl":[[0,2.02,50.49]],"ltp":2.0,"tv":8719.27,"id":17336468}]}]}
{"op":"mcm","clk":"992625020","pt":1580558414798,"mc":[{"id":"1.168136214","rc":[{"trd":[[2,2552.8]],"batb":[[0,2,8.98]],"ltp":2.0,"tv":8723.27,"id":17336468}],"tv":16155.52}]}
{"op":"mcm","clk":"992625231","pt":1580558416120,"mc":[{"id":"1.168136214","rc":[{"batb":[[0,2,10.98]],"ltp":2.0,"tv":8723.27,"id":17336468}]}]}
{"op":"mcm","clk":"992625416","pt":1580558417138,"mc":[{"id":"1.168136214","rc":[{"batb":[[0,4,14.88]],"ltp":4.0,"tv":4261.3,"id":12925630},{"trd":[[2,2574.76]],"batb":[[0,1.99,6],[1,1.98,20.08],[2,1.97,174.79]],"batl":[[0,2,14.8],[1,2.02,50.49],[2,2.04,84.81]],"ltp":2.0,"tv":8745.23,"id":17336468},{"batb":[[0,3.95,9.59],[1,3.9,35.37],[2,3.85,15.07]],"batl":[[0,4,69.48]],"ltp":3.95,"tv":3170.94,"id":11981493}],"tv":16177.48}]}
{"op":"mcm","clk":"992625759","pt":1580558419111,"mc":[{"id":"1.168136214","rc":[{"batb":[[0,4,19.88]],"ltp":4.0,"tv":4261.3,"id":12925630}]}]}
{"op":"mcm","clk":"992626056","pt":1580558420925,"mc":[{"id":"1.168136214","rc":[{"batl":[[0,4,79.48]],"ltp":3.95,"tv":3170.94,"id":11981493}]}]}
{"op":"mcm","clk":"992626615","pt":1580558424135,"mc":[{"id":"1.168136214","rc":[{"batl":[[2,2.04,64.81]],"ltp":2.0,"tv":8745.23,"id":17336468},{"batb":[[1,3.9,42.32]],"ltp":3.95,"tv":3170.94,"id":11981493}]}]}
{"op":"mcm","clk":"992626955","pt":1580558426065,"mc":[{"id":"1.168136214","rc":[{"trd":[[2,2578.76]],"batl":[[0,2,12.8],[2,2.04,35.59]],"ltp":2.0,"tv":8749.23,"id":17336468}],"tv":16181.48}]}
{"op":"mcm","clk":"992629562","pt":1580558441085,"mc":[{"id":"1.168136214","rc":[{"batb":[[0,4,14.88]],"ltp":4.0,"tv":4261.3,"id":12925630},{"batl":[[2,2.04,49.22]],"ltp":2.0,"tv":8749.23,"id":17336468}]}]}
{"op":"mcm","clk":"992630910","pt":1580558448905,"mc":[{"id":"1.168136214","rc":[{"batl":[[0,4.1,59.3]],"ltp":4.0,"tv":4261.3,"id":12925630},{"batl":[[2,2.04,47.22]],"ltp":2.0,"tv":8749.23,"id":17336468}]}]}
{"op":"mcm","clk":"992631115","pt":1580558450130,"mc":[{"id":"1.168136214","rc":[{"batb":[[0,4,19.88]],"ltp":4.0,"tv":4261.3,"id":12925630}]}]}
{"op":"mcm","clk":"992632479","pt":1580558458070,"mc":[{"id":"1.168136214","rc":[{"batl":[[2,4.3,136.55]],"ltp":4.0,"tv":4261.3,"id":12925630}]}]}
{"op":"mcm","clk":"992633295","pt":1580558463064,"mc":[{"id":"1.168136214","rc":[{"batl":[[0,2.02,50.49],[1,2.04,47.22],[2,2.06,113]],"ltp":2.0,"tv":8749.23,"id":17336468},{"batb":[[0,3.95,7.59]],"ltp":3.95,"tv":3170.94,"id":11981493}]}]}
{"op":"mcm","clk":"992633480","pt":1580558464151,"mc":[{"id":"1.168136214","rc":[{"batb":[[0,4,24.88]],"ltp":4.0,"tv":4261.3,"id":12925630},{"batl":[[0,2,26.36],[1,2.02,50.49],[2,2.04,47.22]],"ltp":2.0,"tv":8749.23,"id":17336468},{"batb":[[1,3.9,35.37]],"ltp":3.95,"tv":3170.94,"id":11981493}]}]}
{"op":"mcm","clk":"992633626","pt":1580558465056,"mc":[{"id":"1.168136214","rc":[{"batl":[[1,2.02,58.53]],"ltp":2.0,"tv":8749.23,"id":17336468}]}]}
{"op":"mcm","clk":"992633938","pt":1580558466956,"mc":[{"id":"1.168136214","rc":[{"trd":[[2,2580.76]],"batl":[[0,2,25.36]],"ltp":2.0,"tv":8751.23,"id":17336468}],"tv":16183.48}]}
{"op":"mcm","clk":"992635941","pt":1580558479137,"mc":[{"id":"1.168136214","rc":[{"trd":[[4.1,1179.96]],"batl":[[0,4.1,58.3]],"ltp":4.1,"tv":4263.3,"id":12925630}],"tv":16185.48}]}
{"op":"mcm","clk":"992636241","pt":1580558481076,"mc":[{"id":"1.168136214","rc":[{"batl":[[2,2.04,33.59]],"ltp":2.0,"tv":8751.23,"id":17336468}]}]}
{"op":"mcm","clk":"992636407","pt":1580558482148,"mc":[{"id":"1.168136214","rc":[{"batb":[[0,1.99,9]],"ltp":2.0,"tv":8751.23,"id":17336468}]}]}
{"op":"mcm","clk":"992637884","pt":1580558490056,"mc":[{"id":"1.168136214","rc":[{"batb":[[0,4,17.5]],"ltp":4.1,"tv":4263.3,"id":12925630}]}]}
{"op":"mcm","clk":"992638541","pt":1580558494046,"mc":[{"id":"1.168136214","rc":[{"batb":[[0,1.99,21.87]],"ltp":2.0,"tv":8751.23,"id":17336468}]}]}
{"op":"mcm","clk":"992639055","pt":1580558497049,"mc":[{"id":"1.168136214","rc":[{"batb":[[0,4,7.5]],"ltp":4.1,"tv":4263.3,"id":12925630},{"trd":[[1.99,808.82]],"batb":[[0,1.98,20.08],[1,1.97,174.79],[2,1.96,16.3]],"batl":[[0,1.99,5.88]],"ltp":1.99,"tv":8794.98,"id":17336468},{"trd":[[4,105.27]],"batl":[[0,4,83.48]],"ltp":4.0,"tv":3174.94,"id":11981493}],"tv":16233.22}]}
{"op":"mcm","clk":"992639184","pt":1580558497851,"mc":[{"id":"1.168136214","rc":[{"batb":[[0,4,12.5]],"ltp":4.1,"tv":4263.3,"id":12925630},{"batb":[[1,1.97,154],[2,1.96,43.3]],"batl":[[1,2.02,50.49]],"ltp":1.99,"tv":8794.98,"id":17336468},{"batb":[[0,3.95,16.59]],"batl":[[0,4,77.48]],"ltp":4.0,"tv":3174.94,"id":11981493}]}]}
{"op":"mcm","clk":"992639681","pt":1580558501065,"mc":[{"id":"1.168136214","rc":[{"batb":[[2,3.9,18.21]],"ltp":4.1,"tv":4263.3,"id":12925630}]}]}
{"op":"mcm","clk":"992640443","pt":1580558505079,"mc":[{"id":"1.168136214","rc":[{"batl":[[0,4.1,138.3]],"ltp":4.1,"tv":4263.3,"id":12925630},{"batb":[[1,3.9,42.32]],"ltp":4.0,"tv":3174.94,"id":11981493}]}]}
{"op":"mcm","clk":"992641252","pt":1580558510115,"mc":[{"id":"1.168136214","rc":[{"batl":[[0,4.1,140.3]],"ltp":4.1,"tv":4263.3,"id":12925630}]}]}
{"op":"mcm","clk":"992641759","pt":1580558513076,"mc":[{"id":"1.168136214","rc":[{"batb":[[1,3.95,120.38]],"batl":[[0,4.1,138.3]],"ltp":4.1,"tv":4263.3,"id":12925630}]}]}
{"op":"mcm","clk":"992642560","pt":1580558518131,"mc":[{"id":"1.168136214","rc":[{"batl":[[1,2,20],[2,2.02,50.49]],"ltp":1.99,"tv":8794.98,"id":17336468}]}]}
{"op":"mcm","clk":"992642728","pt":1580558519092,"mc":[{"id":"1.168136214","rc":[{"batb":[[2,3.9,23.4]],"ltp":4.1,"tv":4263.3,"id":12925630},{"batb":[[2,1.96,35.15]],"ltp":1.99,"tv":8794.98,"id":17336468}]}]}
{"op":"mcm","clk":"992643107","pt":1580558521117,"mc":[{"id":"1.168136214","rc":[{"trd":[[1.98,1391.25]],"batb":[[0,1.98,19.76]],"ltp":1.98,"tv":8795.62,"id":17336468},{"trd":[[3.95,187.39]],"batb":[[0,3.95,16.27]],"ltp":3.95,"tv":3175.57,"id":11981493}],"tv":16234.5}]}
{"op":"mcm","clk":"992643292","pt":1580558522095,"mc":[{"id":"1.168136214","rc":[{"trd":[[1.98,1393.52]],"batb":[[0,1.98,18.62]],"ltp":1.98,"tv":8797.89,"id":17336468},{"trd":[[3.95,189.66]],"batb":[[0,3.95,15.13]],"ltp":3.95,"tv":3177.85,"id":11981493}],"tv":16239.04}]}
{"op":"mcm","clk":"992643471","pt":1580558523154,"mc":[{"id":"1.168136214","rc":[{"batb":[[0,1.98,35.98]],"ltp":1.98,"tv":8797.89,"id":17336468}]}]}
{"op":"mcm","clk":"992643640","pt":1580558524116,"mc":[{"id":"1.168136214","rc":[{"batl":[[0,4,96.47]],"ltp":3.95,"tv":3177.85,"id":11981493}]}]}
{"op":"mcm","clk":"992643815","pt":1580558525031,"mc":[{"id":"1.168136214","rc":[{"batb":[[1,3.95,130.68]],"ltp":4.1,"tv":4263.3,"id":12925630},{"trd":[[1.98,1455.51]],"batb":[[0,1.98,6]],"batl":[[0,1.99,23.33]],"ltp":1.98,"tv":8859.88,"id":17336468}],"tv":16301.03}]}
{"op":"mcm","clk":"992644432","pt":1580558528137,"mc":[{"id":"1.168136214","rc":[{"trd":[[3.95,189.86]],"batb":[[0,3.95,15.03]],"ltp":3.95,"tv":3178.05,"id":11981493}],"tv":16301.23}]}
{"op":"mcm","clk":"992644629","pt":1580558529106,"mc":[{"id":"1.168136214","rc":[{"batb":[[1,3.95,133.4],[2,3.9,26.4]],"ltp":4.1,"tv":4263.3,"id":12925630},{"trd":[[1.97,266.72],[1.98,1514.33]],"batb":[[0,1.97,149.79],[1,1.96,35.15],[2,1.95,6]],"batl":[[0,1.99,23.3]],"ltp":1.98,"tv":8927.11,"id":17336468},{"trd":[[3.95,210.08]],"batb":[[0,3.95,7.62]],"ltp":3.95,"tv":3198.26,"id":11981493}],"tv":16388.68}]}
{"op":"mcm","clk":"992644793","pt":1580558530131,"mc":[{"id":"1.168136214","rc":[{"batb":[[0,1.98,6.05],[1,1.97,149.79],[2,1.96,35.15]],"ltp":1.98,"tv":8927.11,"id":17336468}]}]}
{"op":"mcm","clk":"992645127","pt":1580558532113,"mc":[{"id":"1.168136214","rc":[{"batb":[[0,1.98,8.05]],"ltp":1.98,"tv":8927.11,"id":17336468}]}]}
{"op":"mcm","clk":"992645275","pt":1580558533151,"mc":[{"id":"1.168136214","rc":[{"batb":[[0,3.95,16.62]],"ltp":3.95,"tv":3198.26,"id":11981493}]}]}
{"op":"mcm","clk":"992645594","pt":1580558535091,"mc":[{"id":"1.168136214","rc":[{"batl":[[2,2.02,63.17]],"ltp":1.98,"tv":8927.11,"id":17336468}]}]}
{"op":"mcm","clk":"992647485","pt":1580558545084,"mc":[{"id":"1.168136214","rc":[{"trd":[[4.1,1200.48]],"batl":[[0,4.1,128.04]],"ltp":4.1,"tv":4283.82,"id":12925630}],"tv":16409.2}]}
{"op":"mcm","clk":"992664141","pt":1580558581088,"mc":[{"id":"1.168136214","rc":[{"batl":[[1,2,35]],"ltp":1.98,"tv":8927.11,"id":17336468}]}]}
{"op":"mcm","clk":"992664476","pt":1580558583102,"mc":[{"id":"1.168136214","rc":[{"batb":[[1,3.95,123.1]],"batl":[[0,4.1,131.04]],"ltp":4.1,"tv":4283.82,"id":12925630},{"trd":[[1.99,855.45],[2,2606.12]],"batl":[[0,2,7.32],[1,2.02,63.17],[2,2.04,33.06]],"ltp":2.0,"tv":8999.1,"id":17336468},{"batb":[[0,3.9,42.32],[1,3.85,15.07],[2,3.8,19.07]],"batl":[[0,4,99.47]],"ltp":3.95,"tv":3198.26,"id":11981493}],"tv":16481.19}]}
{"op":"mcm","clk":"992664636","pt":1580558583974,"mc":[{"id":"1.168136214","rc":[{"batb":[[0,3.9,35.37]],"ltp":3.95,"tv":3198.26,"id":11981493}]}]}
{"op":"mcm","clk":"992665019","pt":1580558586074,"mc":[{"id":"1.168136214","rc":[{"trd":[[4.1,1250.48]],"batl":[[0,4.1,103.04]],"ltp":4.1,"tv":4333.82,"id":12925630},{"batl":[[0,2,24.69]],"ltp":2.0,"tv":8999.1,"id":17336468},{"batl":[[0,3.95,10],[1,4,99.47],[2,4.1,34.73]],"ltp":3.95,"tv":3198.26,"id":11981493}],"tv":16531.19}]}
{"op":"mcm","clk":"992665176","pt":1580558587086,"mc":[{"id":"1.168136214","rc":[{"batb":[[0,1.98,25.49]],"ltp":2.0,"tv":8999.1,"id":17336468},{"batb":[[0,3.9,27.76]],"batl":[[0,3.95,20]],"ltp":3.95,"tv":3198.26,"id":11981493}]}]}
{"op":"mcm","clk":"992665361","pt":1580558588059,"mc":[{"id":"1.168136214","rc":[{"batl":[[1,2.02,69.29],[2,2.04,43.29]],"ltp":2.0,"tv":8999.1,"id":17336468}]}]}
{"op":"mcm","clk":"992665539","pt":1580558588976,"mc":[{"id":"1.168136214","rc":[{"batl":[[0,1.99,2],[1,2,24.69],[2,2.02,69.29]],"ltp":2.0,"tv":8999.1,"id":17336468}]}]}
{"op":"mcm","clk":"992665743","pt":1580558590099,"mc":[{"id":"1.168136214","rc":[{"trd":[[4,532.66]],"batb":[[0,4,7.5]],"ltp":4.0,"tv":4343.81,"id":12925630},{"batl":[[1,2,7.32]],"ltp":2.0,"tv":8999.1,"id":17336468}],"tv":16541.18}]}
{"op":"mcm","clk":"992665939","pt":1580558591012,"mc":[{"id":"1.168136214","rc":[{"batl":[[0,2,7.32],[1,2.02,72.2],[2,2.04,43.29]],"ltp":2.0,"tv":8999.1,"id":17336468}]}]}
{"op":"mcm","clk":"992666145","pt":1580558592086,"mc":[{"id":"1.168136214","rc":[{"batl":[[1,2.02,63.17]],"ltp":2.0,"tv":8999.1,"id":17336468}]}]}
{"op":"mcm","clk":"992666892","pt":1580558596116,"mc":[{"id":"1.168136214","rc":[{"batl":[[0,1.99,25.11],[1,2,7.32],[2,2.02,63.17]],"ltp":2.0,"tv":8999.1,"id":17336468},{"trd":[[3.95,214.08]],"batl":[[0,3.95,18]],"ltp":3.95,"tv":3202.26,"id":11981493}],"tv":16545.18}]}
{"op":"mcm","clk":"992667068","pt":1580558597085,"mc":[{"id":"1.168136214","rc":[{"batb":[[0,4,20.29]],"batl":[[0,4.1,106.04]],"ltp":4.0,"tv":4343.81,"id":12925630},{"trd":[[1.99,906.85]],"batl":[[0,2,7.32],[1,2.02,63.17],[2,2.04,43.29]],"ltp":1.99,"tv":9050.5,"id":17336468},{"batb":[[0,3.9,40.88]],"ltp":3.95,"tv":3202.26,"id":11981493}],"tv":16596.58}]}
{"op":"mcm","clk":"992667238","pt":1580558598100,"mc":[{"id":"1.168136214","rc":[{"trd":[[4.1,1258.45]],"batb":[[0,4,28.49]],"batl":[[0,4.1,98.07]],"ltp":4.1,"tv":4351.78,"id":12925630},{"trd":[[1.98,1581.82]],"batb":[[0,1.98,7.09]],"batl":[[0,2,24.73],[1,2.02,65.29]],"ltp":1.98,"tv":9118.0,"id":17336468},{"trd":[[3.95,222.35]],"batl":[[0,3.95,9.73]],"ltp":3.95,"tv":3210.53,"id":11981493}],"tv":16680.32}]}
{"op":"mcm","clk":"992667608","pt":1580558600101,"mc":[{"id":"1.168136214","rc":[{"batl":[[1,2.02,71.12]],"ltp":1.98,"tv":9118.0,"id":17336468}]}]}
{"op":"mcm","clk":"992668508","pt":1580558605087,"mc":[{"id":"1.168136214","rc":[{"batb":[[1,1.97,170.58]],"ltp":1.98,"tv":9118.0,"id":17336468}]}]}
{"op":"mcm","clk":"992671560","pt":1580558622103,"mc":[{"id":"1.168136214","rc":[{"batb":[[0,4,31.49]],"ltp":4.1,"tv":4351.78,"id":12925630},{"batb":[[0,1.99,2],[1,1.98,7.09],[2,1.97,170.58]],"ltp":1.98,"tv":9118.0,"id":17336468}]}]}
{"op":"mcm","clk":"992672674","pt":1580558627115,"mc":[{"id":"1.168136214","rc":[{"trd":[[4.1,1265.71]],"batl":[[0,4.1,90.81]],"ltp":4.1,"tv":4359.04,"id":12925630},{"trd":[[1.98,1611.04],[1.99,910.85]],"batb":[[0,1.99,7.23],[1,1.98,7]],"ltp":1.98,"tv":9151.22,"id":17336468},{"trd":[[3.95,234.27]],"batl":[[0,4,99.47],[1,4.1,34.73],[2,4.2,15.36]],"ltp":3.95,"tv":3222.45,"id":11981493}],"tv":16732.72}]}
{"op":"mcm","clk":"992672879","pt":1580558628090,"mc":[{"id":"1.168136214","rc":[{"batl":[[0,4.1,86.78]],"ltp":4.1,"tv":4359.04,"id":12925630},{"batb":[[0,1.98,7],[1,1.97,170.58],[2,1.96,35.15]],"ltp":1.98,"tv":9151.22,"id":17336468},{"batb":[[1,3.85,25.74]],"batl":[[1,4.1,43.88]],"ltp":3.95,"tv":3222.45,"id":11981493}]}]}
{"op":"mcm","clk":"992673249","pt":1580558630076,"mc":[{"id":"1.168136214","rc":[{"batl":[[1,4.1,34.73]],"ltp":3.95,"tv":3222.45,"id":11981493}]}]}
{"op":"mcm","clk":"992674384","pt":1580558636101,"mc":[{"id":"1.168136214","rc":[{"batb":[[1,3.85,15.07]],"ltp":3.95,"tv":3222.45,"id":11981493}]}]}
{"op":"mcm","clk":"992674727","pt":1580558638129,"mc":[{"id":"1.168136214","rc":[{"batl":[[0,4.1,90.81]],"ltp":4.1,"tv":4359.04,"id":12925630}]}]}
{"op":"mcm","clk":"992675995","pt":1580558645052,"mc":[{"id":"1.168136214","rc":[{"batb":[[0,4,50.49]],"ltp":4.1,"tv":4359.04,"id":12925630}]}]}
{"op":"mcm","clk":"992678939","pt":1580558660986,"mc":[{"id":"1.168136214","rc":[{"batb":[[0,1.99,7.11],[1,1.98,27.26],[2,1.97,170.58]],"batl":[[2,2.04,48.29]],"ltp":1.98,"tv":9151.22,"id":17336468}]}]}
{"op":"mcm","clk":"992679973","pt":1580558666588,"mc":[{"id":"1.168136214","rc":[{"trd":[[1.99,914.85]],"batb":[[0,1.99,5.11]],"ltp":1.99,"tv":9155.22,"id":17336468}],"tv":16736.72}]}
{"op":"mcm","clk":"992680874","pt":1580558671789,"mc":[{"id":"1.168136214","rc":[{"batl":[[0,4,80.48]],"ltp":3.95,"tv":3222.45,"id":11981493}]}]}
{"op":"mcm","clk":"992681828","pt":1580558678098,"mc":[{"id":"1.168136214","rc":[{"trd":[[1.99,939.41]],"batb":[[0,1.98,27.26],[1,1.97,170.58],[2,1.96,35.15]],"batl":[[0,1.99,9.57],[1,2,24.73],[2,2.02,71.12]],"ltp":1.99,"tv":9179.78,"id":17336468},{"batb":[[0,3.95,2.16],[1,3.9,40.88],[2,3.85,19.07]],"ltp":3.95,"tv":3222.45,"id":11981493}],"tv":16761.28}]}
{"op":"mcm","clk":"992682092","pt":1580558679130,"mc":[{"id":"1.168136214","rc":[{"batb":[[1,1.97,149.79]],"ltp":1.99,"tv":9179.78,"id":17336468},{"batb":[[0,3.95,14.36]],"batl":[[0,4,77.48]],"ltp":3.95,"tv":3222.45,"id":11981493}]}]}
{"op":"mcm","clk":"992683404","pt":1580558686074,"mc":[{"id":"1.168136214","rc":[{"batb":[[1,3.9,47.83]],"ltp":3.95,"tv":3222.45,"id":11981493}]}]}
{"op":"mcm","clk":"992685984","pt":1580558699953,"mc":[{"id":"1.168136214","rc":[{"batb":[[1,1.97,174.79]],"ltp":1.99,"tv":9179.78,"id":17336468}]}]}
{"op":"mcm","clk":"992686216","pt":1580558701147,"mc":[{"id":"1.168136214","rc":[{"trd":[[1.98,1615.18]],"batb":[[0,1.98,25.19]],"ltp":1.98,"tv":9183.92,"id":17336468},{"trd":[[3.95,238.41]],"batb":[[0,3.95,12.29]],"ltp":3.95,"tv":3226.59,"id":11981493}],"tv":16769.56}]}
{"op":"mcm","clk":"992686607","pt":1580558703143,"mc":[{"id":"1.168136214","rc":[{"trd":[[4.1,1303.21]],"batl":[[0,4.1,72.05]],"ltp":4.1,"tv":4396.54,"id":12925630},{"batl":[[0,1.99,33.25]],"ltp":1.98,"tv":9183.92,"id":17336468}],"tv":16807.06}]}
{"op":"mcm","clk":"992688774","pt":1580558714072,"mc":[{"id":"1.168136214","rc":[{"batb":[[1,1.97,149.79]],"ltp":1.98,"tv":9183.92,"id":17336468}]}]}
{"op":"mcm","clk":"992692661","pt":1580558733080,"mc":[{"id":"1.168136214","rc":[{"batl":[[0,1.99,48.5]],"ltp":1.98,"tv":9183.92,"id":17336468},{"batb":[[0,3.95,12.2]],"ltp":3.95,"tv":3226.59,"id":11981493}]}]}
{"op":"mcm","clk":"992693685","pt":1580558738066,"mc":[{"id":"1.168136214","rc":[{"batb":[[0,1.98,4.93]],"ltp":1.98,"tv":9183.92,"id":17336468}]}]}
{"op":"mcm","clk":"992697665","pt":1580558756111,"mc":[{"id":"1.168136214","rc":[{"batl":[[0,4.1,69.05]],"ltp":4.1,"tv":4396.54,"id":12925630},{"trd":[[1.99,943.41]],"batl":[[0,1.99,46.5]],"ltp":1.99,"tv":9187.92,"id":17336468},{"batb":[[0,3.9,40.88],[1,3.85,19.07],[2,3.8,23.07]],"ltp":3.95,"tv":3226.59,"id":11981493}],"tv":16811.06}]}
{"op":"mcm","clk":"992700454","pt":1580558769124,"mc":[{"id":"1.168136214","rc":[{"trd":[[1.98,1665.52]],"batb":[[0,1.98,11.8]],"batl":[[0,1.99,21.68]],"ltp":1.98,"tv":9238.26,"id":17336468},{"trd":[[4,109.27]],"batb":[[0,3.95,7.68],[1,3.9,40.88],[2,3.85,19.07]],"batl":[[0,4,75.48]],"ltp":4.0,"tv":3230.59,"id":11981493}],"tv":16865.4}]}
{"op":"mcm","clk":"992700651","pt":1580558770042,"mc":[{"id":"1.168136214","rc":[{"batb":[[0,1.98,4.76],[2,1.96,14.15]],"batl":[[1,2,49.61]],"ltp":1.98,"tv":9238.26,"id":17336468},{"batb":[[0,3.95,19.72]],"ltp":4.0,"tv":3230.59,"id":11981493}]}]}
{"op":"mcm","clk":"992700886","pt":1580558771133,"mc":[{"id":"1.168136214","rc":[{"batl":[[1,2,41.73]],"ltp":1.98,"tv":9238.26,"id":17336468}]}]}
{"op":"mcm","clk":"992701100","pt":1580558772147,"mc":[{"id":"1.168136214","rc":[{"batb":[[0,1.98,11.82]],"batl":[[0,1.99,27.84]],"ltp":1.98,"tv":9238.26,"id":17336468}]}]}
{"op":"mcm","clk":"992702131","pt":1580558776931,"mc":[{"id":"1.168136214","rc":[{"batb":[[2,1.96,35.15]],"ltp":1.98,"tv":9238.26,"id":17336468},{"batb":[[1,3.9,47.83]],"ltp":4.0,"tv":3230.59,"id":11981493}]}]}
{"op":"mcm","clk":"992704349","pt":1580558788059,"mc":[{"id":"1.168136214","rc":[{"trd":[[1.98,1669.52]],"batb":[[0,1.98,9.82]],"ltp":1.98,"tv":9242.26,"id":17336468}],"tv":16869.4}]}
{"op":"mcm","clk":"992705760","pt":1580558795062,"mc":[{"id":"1.168136214","rc":[{"trd":[[1.99,947.41]],"batl":[[0,1.99,25.84]],"ltp":1.99,"tv":9246.26,"id":17336468}],"tv":16873.4}]}
{"op":"mcm","clk":"992706159","pt":1580558796947,"mc":[{"id":"1.168136214","rc":[{"batl":[[0,1.99,32]],"ltp":1.99,"tv":9246.26,"id":17336468}]}]}
{"op":"mcm","clk":"992709080","pt":1580558811090,"mc":[{"id":"1.168136214","rc":[{"trd":[[1.98,1703.16]],"batb":[[0,1.97,149.79],[1,1.96,35.15],[2,1.95,34.22]],"batl":[[0,1.98,6.96],[1,1.99,32],[2,2,41.73]],"ltp":1.98,"tv":9279.9,"id":17336468},{"trd":[[4,113.27]],"batl":[[0,4,73.48]],"ltp":4.0,"tv":3234.59,"id":11981493}],"tv":16911.04}]}
{"op":"mcm","clk":"992709195","pt":1580558811589,"mc":[{"id":"1.168136214","rc":[{"batb":[[1,1.96,14.15]],"ltp":1.98,"tv":9279.9,"id":17336468}]}]}
{"op":"mcm","clk":"992712002","pt":1580558824111,"mc":[{"id":"1.168136214","rc":[{"batl":[[0,4,98.81]],"ltp":4.0,"tv":3234.59,"id":11981493}]}]}
{"op":"mcm","clk":"992712201","pt":1580558825137,"mc":[{"id":"1.168136214","rc":[{"trd":[[1.98,1707.16]],"batl":[[0,1.98,4.96]],"ltp":1.98,"tv":9283.9,"id":17336468}],"tv":16915.04}]}
{"op":"mcm","clk":"992713063","pt":1580558828709,"mc":[{"id":"1.168136214","rc":[{"batl":[[0,4.1,79.89]],"ltp":4.1,"tv":4396.54,"id":12925630}]}]}
{"op":"mcm","clk":"992719005","pt":1580558856091,"mc":[{"id":"1.168136214","rc":[{"batb":[[1,3.95,127.1],[2,3.9,30.4]],"ltp":4.1,"tv":4396.54,"id":12925630},{"trd":[[1.98,1717.08]],"batb":[[0,1.98,13.46],[1,1.97,149.79],[2,1.96,14.15]],"batl":[[0,1.99,32],[1,2,51.06],[2,2.02,63.17]],"ltp":1.98,"tv":9293.81,"id":17336468}],"tv":16924.95}]}
{"op":"mcm","clk":"992720466","pt":1580558863079,"mc":[{"id":"1.168136214","rc":[{"trd":[[1.97,339.8],[1.98,1758]],"batb":[[0,1.97,113.25],[1,1.96,14.15],[2,1.95,34.22]],"batl":[[0,1.98,6.09],[1,1.99,32],[2,2,51.06]],"ltp":1.98,"tv":9407.82,"id":17336468}],"tv":17038.96}]}
{"op":"mcm","clk":"992722541","pt":1580558873068,"mc":[{"id":"1.168136214","rc":[{"batl":[[0,1.98,16.09]],"ltp":1.98,"tv":9407.82,"id":17336468}]}]}
{"op":"mcm","clk":"992725338","pt":1580558887124,"mc":[{"id":"1.168136214","rc":[{"trd":[[1.97,359.8]],"batb":[[0,1.97,103.25]],"batl":[[0,1.98,6.09]],"ltp":1.97,"tv":9427.82,"id":17336468}],"tv":17058.96}]}
{"op":"mcm","clk":"992726397","pt":1580558892139,"mc":[{"id":"1.168136214","rc":[{"batb":[[0,1.97,133.25]],"batl":[[2,2,81.06]],"ltp":1.97,"tv":9427.82,"id":17336468}]}]}
{"op":"mcm","clk":"992727864","pt":1580558899149,"mc":[{"id":"1.168136214","rc":[{"trd":[[4,536.66]],"batb":[[0,4,48.49]],"ltp":4.0,"tv":4400.54,"id":12925630}],"tv":17062.95}]}
{"op":"mcm","clk":"992728446","pt":1580558902126,"mc":[{"id":"1.168136214","rc":[{"trd":[[1.98,1762]],"batl":[[0,1.98,4.09]],"ltp":1.98,"tv":9431.82,"id":17336468}],"tv":17066.95}]}
{"op":"mcm","clk":"992730726","pt":1580558914145,"mc":[{"id":"1.168136214","rc":[{"batl":[[0,1.98,27.9]],"ltp":1.98,"tv":9431.82,"id":17336468},{"trd":[[4,117.27]],"batl":[[0,4,96.81]],"ltp":4.0,"tv":3238.59,"id":11981493}],"tv":17070.95}]}
{"op":"mcm","clk":"992731100","pt":1580558916039,"mc":[{"id":"1.168136214","rc":[{"batb":[[1,1.96,6]],"ltp":1.98,"tv":9431.82,"id":17336468}]}]}
{"op":"mcm","clk":"992733217","pt":1580558927145,"mc":[{"id":"1.168136214","rc":[{"trd":[[4.1,1316.68]],"batb":[[0,4,52.49]],"batl":[[0,4.1,66.42]],"ltp":4.1,"tv":4414.01,"id":12925630},{"trd":[[1.98,1789.9]],"batb":[[0,1.98,7.25],[1,1.97,133.25],[2,1.96,6]],"batl":[[0,1.99,14.44],[1,2,81.06],[2,2.02,52.48]],"ltp":1.98,"tv":9459.72,"id":17336468},{"trd":[[3.95,424.41]],"batb":[[0,3.9,40.88],[1,3.85,19.07],[2,3.8,23.07]],"ltp":3.95,"tv":3424.59,"id":11981493}],"tv":17298.32}]}
{"op":"mcm","clk":"992734549","pt":1580558934140,"mc":[{"id":"1.168136214","rc":[{"batb":[[2,1.96,27]],"ltp":1.98,"tv":9459.72,"id":17336468},{"batl":[[0,4,99.81]],"ltp":3.95,"tv":3424.59,"id":11981493}]}]}
{"op":"mcm","clk":"992735178","pt":1580558937127,"mc":[{"id":"1.168136214","rc":[{"batb":[[0,1.98,12.25]],"ltp":1.98,"tv":9459.72,"id":17336468}]}]}
{"op":"mcm","clk":"992736009","pt":1580558941128,"mc":[{"id":"1.168136214","rc":[{"trd":[[4.1,1383.1]],"batb":[[0,4.1,7.53],[1,4,52.49],[2,3.95,127.1]],"batl":[[0,4.2,46.12],[1,4.3,139.55],[2,4.4,103.73]],"ltp":4.1,"tv":4480.42,"id":12925630},{"trd":[[1.97,771.56],[1.98,1840.11]],"batb":[[0,1.97,9.61],[1,1.96,27],[2,1.95,34.22]],"batl":[[0,1.99,31.44]],"ltp":1.98,"tv":9921.68,"id":17336468},{"trd":[[3.95,424.61],[4,185.35]],"batb":[[0,3.95,28.82],[1,3.9,40.88],[2,3.85,19.07]],"batl":[[0,4,28.73]],"ltp":3.95,"tv":3492.87,"id":11981493}],"tv":17894.99}]}
{"op":"mcm","clk":"992736213","pt":1580558942046,"mc":[{"id":"1.168136214","rc":[{"batb":[[1,4,65.94]],"ltp":4.1,"tv":4480.42,"id":12925630},{"batb":[[0,1.96,6],[1,1.95,13],[2,1.94,209.84]],"batl":[[0,1.97,24.39],[1,1.98,3.49],[2,1.99,31.44]],"ltp":1.98,"tv":9921.68,"id":17336468},{"trd":[[4,189.35]],"batl":[[0,4,26.73]],"ltp":4.0,"tv":3496.87,"id":11981493}],"tv":17898.99}]}
{"op":"mcm","clk":"992736434","pt":1580558943071,"mc":[{"id":"1.168136214","rc":[{"batb":[[0,4,76.07],[1,3.95,127.1],[2,3.9,30.4]],"ltp":4.1,"tv":4480.42,"id":12925630},{"trd":[[1.97,820.34],[1.98,1847.08]],"batb":[[0,1.98,14.13],[1,1.97,6.01],[2,1.96,6]],"batl":[[0,1.99,26.51],[1,2,81.06],[2,2.02,52.48]],"ltp":1.98,"tv":9977.44,"id":17336468},{"batb":[[0,3.95,9.12]],"ltp":4.0,"tv":3496.87,"id":11981493}],"tv":17954.74}]}
{"op":"mcm","clk":"992736798","pt":1580558945042,"mc":[{"id":"1.168136214","rc":[{"batb":[[0,3.95,21.14]],"ltp":4.0,"tv":3496.87,"id":11981493}]}]}
{"op":"mcm","clk":"992737459","pt":1580558948066,"mc":[{"id":"1.168136214","rc":[{"trd":[[1.99,1020.25]],"batb":[[0,1.99,43.58],[1,1.98,14.13],[2,1.97,6.01]],"batl":[[0,2,81.06],[1,2.02,52.48],[2,2.04,44.27]],"ltp":1.99,"tv":10050.28,"id":17336468},{"trd":[[3.95,444.43]],"batb":[[0,3.95,11.23]],"ltp":3.95,"tv":3516.69,"id":11981493}],"tv":18047.41}]}
{"op":"mcm","clk":"992737715","pt":1580558949143,"mc":[{"id":"1.168136214","rc":[{"trd":[[1.99,1107.41]],"batb":[[0,1.98,20.13],[1,1.97,6.01],[2,1.96,6]],"batl":[[0,1.99,2],[1,2,64.06],[2,2.02,52.48]],"ltp":1.99,"tv":10137.44,"id":17336468},{"batb":[[0,3.9,40.88],[1,3.85,19.07],[2,3.8,23.07]],"ltp":3.95,"tv":3516.69,"id":11981493}],"tv":18134.57}]}
{"op":"mcm","clk":"992737917","pt":1580558950078,"mc":[{"id":"1.168136214","rc":[{"batb":[[0,4,65.94]],"ltp":4.1,"tv":4480.42,"id":12925630},{"batl":[[2,2.02,56.57]],"ltp":1.99,"tv":10137.44,"id":17336468}]}]}
{"op":"mcm","clk":"992739162","pt":1580558956020,"mc":[{"id":"1.168136214","rc":[{"batb":[[0,1.98,14.13],[2,1.96,27]],"batl":[[1,2,81.06]],"ltp":1.99,"tv":10137.44,"id":17336468}]}]}
{"op":"mcm","clk":"992739351","pt":1580558957021,"mc":[{"id":"1.168136214","rc":[{"batl":[[0,1.99,4]],"ltp":1.99,"tv":10137.44,"id":17336468}]}]}
{"op":"mcm","clk":"992740472","pt":1580558962098,"mc":[{"id":"1.168136214","rc":[{"batb":[[0,4.1,18.71],[1,4,65.94],[2,3.95,127.1]],"ltp":4.1,"tv":4480.42,"id":12925630},{"trd":[[1.98,1875.35]],"batb":[[0,1.97,6.01],[1,1.96,6],[2,1.95,34.22]],"batl":[[0,1.98,12.65],[1,1.99,4],[2,2,81.06]],"ltp":1.98,"tv":10165.7,"id":17336468},{"batl":[[0,3.95,5],[1,4,29.73],[2,4.1,34.73]],"ltp":3.95,"tv":3516.69,"id":11981493}],"tv":18162.83}]}
{"op":"mcm","clk":"992740676","pt":1580558963100,"mc":[{"id":"1.168136214","rc":[{"batb":[[0,1.96,19.17],[1,1.95,34.22],[2,1.94,209.84]],"ltp":1.98,"tv":10165.7,"id":17336468}]}]}
{"op":"mcm","clk":"992740872","pt":1580558964011,"mc":[{"id":"1.168136214","rc":[{"batb":[[1,4,72.66]],"ltp":4.1,"tv":4480.42,"id":12925630}]}]}
{"op":"mcm","clk":"992742130","pt":1580558970125,"mc":[{"id":"1.168136214","rc":[{"batl":[[0,1.97,7],[1,1.98,12.65],[2,1.99,4]],"ltp":1.98,"tv":10165.7,"id":17336468}]}]}
{"op":"mcm","clk":"992742363","pt":1580558971115,"mc":[{"id":"1.168136214","rc":[{"batb":[[0,4.1,36.45],[1,4,82.79]],"ltp":4.1,"tv":4480.42,"id":12925630},{"trd":[[1.97,894.15]],"batb":[[1,1.95,13],[2,1.94,215.84]],"batl":[[0,1.98,30.87],[1,1.99,21.17],[2,2,81.06]],"ltp":1.97,"tv":10239.51,"id":17336468},{"trd":[[3.95,454.43]],"batb":[[0,3.95,25.41],[1,3.9,40.88],[2,3.85,19.07]],"batl":[[0,4,26.73],[1,4.1,34.73],[2,4.2,15.36]],"ltp":3.95,"tv":3526.69,"id":11981493}],"tv":18246.63}]}
{"op":"mcm","clk":"992742577","pt":1580558972136,"mc":[{"id":"1.168136214","rc":[{"batb":[[0,4.1,25.34]],"ltp":4.1,"tv":4480.42,"id":12925630},{"batl":[[2,2,79.79]],"ltp":1.97,"tv":10239.51,"id":17336468},{"trd":[[4,192.15]],"batb":[[1,3.9,46.02]],"batl":[[0,4.1,34.73],[1,4.2,15.36],[2,4.3,1.46]],"ltp":4.0,"tv":3529.49,"id":11981493}],"tv":18249.43}]}
{"op":"mcm","clk":"992742775","pt":1580558973115,"mc":[{"id":"1.168136214","rc":[{"batl":[[0,1.98,42.29]],"ltp":1.97,"tv":10239.51,"id":17336468}]}]}
{"op":"mcm","clk":"992742971","pt":1580558974068,"mc":[{"id":"1.168136214","rc":[{"trd":[[1.97,901.71]],"batb":[[0,1.97,3.22],[1,1.96,19.17],[2,1.95,13]],"batl":[[0,1.98,59.29]],"ltp":1.97,"tv":10247.07,"id":17336468}],"tv":18256.99}]}
{"op":"mcm","clk":"992743167","pt":1580558975154,"mc":[{"id":"1.168136214","rc":[{"batb":[[1,1.96,6]],"batl":[[0,1.98,47.29]],"ltp":1.97,"tv":10247.07,"id":17336468},{"batl":[[0,4.1,42.56]],"ltp":4.0,"tv":3529.49,"id":11981493}]}]}
{"op":"mcm","clk":"992744009","pt":1580558978974,"mc":[{"id":"1.168136214","rc":[{"batb":[[1,3.9,52.98]],"ltp":4.0,"tv":3529.49,"id":11981493}]}]}
{"op":"mcm","clk":"992747780","pt":1580558997140,"mc":[{"id":"1.168136214","rc":[{"trd":[[4.1,1387.09]],"batb":[[0,4.1,23.34]],"ltp":4.1,"tv":4484.42,"id":12925630}],"tv":18260.99}]}
{"op":"mcm","clk":"992748543","pt":1580559000862,"mc":[{"id":"1.168136214","rc":[{"batb":[[0,4.1,48.05]],"ltp":4.1,"tv":4484.42,"id":12925630}]}]}
{"op":"mcm","clk":"992748973","pt":1580559002964,"mc":[{"id":"1.168136214","rc":[{"batb":[[1,4,72.66]],"ltp":4.1,"tv":4484.42,"id":12925630}]}]}
{"op":"mcm","clk":"992749195","pt":1580559004052,"mc":[{"id":"1.168136214","rc":[{"trd":[[3.95,474.43]],"batb":[[0,3.95,15.41]],"ltp":3.95,"tv":3549.49,"id":11981493}],"tv":18280.99}]}
{"op":"mcm","clk":"992749408","pt":1580559005062,"mc":[{"id":"1.168136214","rc":[{"trd":[[1.98,1880.59]],"batl":[[0,1.98,44.67]],"ltp":1.98,"tv":10252.31,"id":17336468}],"tv":18286.23}]}
{"op":"mcm","clk":"992749680","pt":1580559006073,"mc":[{"id":"1.168136214","rc":[{"batl":[[0,1.98,51.51]],"ltp":1.98,"tv":10252.31,"id":17336468}]}]}
{"op":"mcm","clk":"992749921","pt":1580559007065,"mc":[{"id":"1.168136214","rc":[{"trd":[[1.97,908.15]],"batb":[[0,1.96,6],[1,1.95,13],[2,1.94,215.84]],"batl":[[0,1.97,16.79],[1,1.98,51.51],[2,1.99,21.17]],"ltp":1.97,"tv":10258.75,"id":17336468}],"tv":18292.67}]}
{"op":"mcm","clk":"992750109","pt":1580559007955,"mc":[{"id":"1.168136214","rc":[{"batb":[[0,1.95,13],[1,1.94,194.39],[2,1.93,150.61]],"batl":[[0,1.97,38.71],[1,1.98,68.51]],"ltp":1.97,"tv":10258.75,"id":17336468},{"batb":[[0,4,2],[1,3.95,23.29],[2,3.9,63.46]],"batl":[[1,4.2,18.36]],"ltp":3.95,"tv":3549.49,"id":11981493}]}]}
{"op":"mcm","clk":"992750370","pt":1580559009048,"mc":[{"id":"1.168136214","rc":[{"batl":[[0,4.1,37.45]],"ltp":3.95,"tv":3549.49,"id":11981493}]}]}
{"op":"mcm","clk":"992750771","pt":1580559011068,"mc":[{"id":"1.168136214","rc":[{"batl":[[0,4.1,32.23],[1,4.2,25.96]],"ltp":3.95,"tv":3549.49,"id":11981493}]}]}
{"op":"mcm","clk":"992750985","pt":1580559012062,"mc":[{"id":"1.168136214","rc":[{"batb":[[0,4.1,59.05]],"ltp":4.1,"tv":4484.42,"id":12925630},{"trd":[[4,212.15]],"batb":[[0,3.95,23.29],[1,3.9,63.46],[2,3.85,19.07]],"ltp":4.0,"tv":3569.49,"id":11981493}],"tv":18312.67}]}
{"op":"mcm","clk":"992751887","pt":1580559016085,"mc":[{"id":"1.168136214","rc":[{"trd":[[4.1,1391.09]],"batb":[[0,4.1,57.05]],"ltp":4.1,"tv":4488.41,"id":12925630},{"batb":[[0,1.95,31.38]],"ltp":1.97,"tv":10258.75,"id":17336468}],"tv":18316.67}]}
{"op":"mcm","clk":"992752115","pt":1580559017075,"mc":[{"id":"1.168136214","rc":[{"batb":[[0,1.95,44.6]],"ltp":1.97,"tv":10258.75,"id":17336468}]}]}
{"op":"mcm","clk":"992754930","pt":1580559031016,"mc":[{"id":"1.168136214","rc":[{"batb":[[1,3.9,52.98]],"batl":[[0,4,15],[1,4.1,32.23],[2,4.2,25.96]],"ltp":4.0,"tv":3569.49,"id":11981493}]}]}
{"op":"mcm","clk":"992755118","pt":1580559032050,"mc":[{"id":"1.168136214","rc":[{"batb":[[0,1.96,6.17],[1,1.95,44.6],[2,1.94,194.39]],"ltp":1.97,"tv":10258.75,"id":17336468}]}]}
{"op":"mcm","clk":"992755922","pt":1580559036152,"mc":[{"id":"1.168136214","rc":[{"trd":[[4.1,1395.09]],"batb":[[0,4.1,55.06]],"ltp":4.1,"tv":4492.41,"id":12925630}],"tv":18320.66}]}
{"op":"mcm","clk":"992756092","pt":1580559037037,"mc":[{"id":"1.168136214","rc":[{"batl":[[0,4.2,53.7]],"ltp":4.1,"tv":4492.41,"id":12925630},{"trd":[[4,233.91]],"batb":[[1,3.9,41.82]],"batl":[[0,4,4.12]],"ltp":4.0,"tv":3591.25,"id":11981493}],"tv":18342.42}]}
{"op":"mcm","clk":"992756542","pt":1580559039121,"mc":[{"id":"1.168136214","rc":[{"batl":[[0,4.2,46.12]],"ltp":4.1,"tv":4492.41,"id":12925630},{"trd":[[1.96,773.77]],"batb":[[0,1.95,44.6],[1,1.94,194.39],[2,1.93,156.61]],"batl":[[0,1.96,17.84],[1,1.97,16.79],[2,1.98,68.51]],"ltp":1.96,"tv":10271.09,"id":17336468}],"tv":18354.76}]}
{"op":"mcm","clk":"992758963","pt":1580559050872,"mc":[{"id":"1.168136214","rc":[{"trd":[[4.1,1415.08]],"batb":[[0,4.1,45.06]],"ltp":4.1,"tv":4512.41,"id":12925630}],"tv":18374.76}]}
{"op":"mcm","clk":"992759097","pt":1580559051689,"mc":[{"id":"1.168136214","rc":[{"batb":[[1,3.9,52.3]],"ltp":4.0,"tv":3591.25,"id":11981493}]}]}
{"op":"mcm","clk":"992759527","pt":1580559054077,"mc":[{"id":"1.168136214","rc":[{"trd":[[4,242.15]],"batl":[[0,4.1,32.23],[1,4.2,25.96],[2,4.3,1.46]],"ltp":4.0,"tv":3599.49,"id":11981493}],"tv":18382.99}]}
{"op":"mcm","clk":"992759929","pt":1580559056093,"mc":[{"id":"1.168136214","rc":[{"trd":[[4.1,1419.08]],"batb":[[0,4.1,43.06]],"ltp":4.1,"tv":4516.41,"id":12925630}],"tv":18386.99}]}
{"op":"mcm","clk":"992761781","pt":1580559065104,"mc":[{"id":"1.168136214","rc":[{"trd":[[4.1,1423.08]],"batb":[[0,4.1,41.06]],"ltp":4.1,"tv":4520.41,"id":12925630}],"tv":18390.99}]}
{"op":"mcm","clk":"992763803","pt":1580559075134,"mc":[{"id":"1.168136214","rc":[{"trd":[[4.1,1427.08]],"batb":[[0,4.1,39.06]],"ltp":4.1,"tv":4524.41,"id":12925630}],"tv":18394.99}]}
{"op":"mcm","clk":"992763966","pt":1580559076053,"mc":[{"id":"1.168136214","rc":[{"trd":[[1.96,777.77]],"batl":[[0,1.96,15.84]],"ltp":1.96,"tv":10275.09,"id":17336468}],"tv":18398.99}]}
{"op":"mcm","clk":"992765536","pt":1580559083945,"mc":[{"id":"1.168136214","rc":[{"trd":[[4.1,1431.08]],"batb":[[0,4.1,37.06]],"ltp":4.1,"tv":4528.41,"id":12925630}],"tv":18402.99}]}
{"op":"mcm","clk":"992766156","pt":1580559087061,"mc":[{"id":"1.168136214","rc":[{"batl":[[0,1.96,17.84]],"ltp":1.96,"tv":10275.09,"id":17336468}]}]}
{"op":"mcm","clk":"992766695","pt":1580559089795,"mc":[{"id":"1.168136214","rc":[{"batb":[[0,4.1,12.35]],"ltp":4.1,"tv":4528.41,"id":12925630}]}]}
{"op":"mcm","clk":"992766922","pt":1580559091059,"mc":[{"id":"1.168136214","rc":[{"batl":[[1,1.97,33.79]],"ltp":1.96,"tv":10275.09,"id":17336468},{"batb":[[1,3.9,60.35]],"ltp":4.0,"tv":3599.49,"id":11981493}]}]}
{"op":"mcm","clk":"992767519","pt":1580559094094,"mc":[{"id":"1.168136214","rc":[{"trd":[[4.1,1435.08]],"batb":[[0,4.1,10.35]],"ltp":4.1,"tv":4532.41,"id":12925630},{"batl":[[0,1.96,26.23],[2,1.98,85.37]],"ltp":1.96,"tv":10275.09,"id":17336468},{"batb":[[0,4,2],[1,3.95,23.29],[2,3.9,60.35]],"ltp":4.0,"tv":3599.49,"id":11981493}],"tv":18406.99}]}
{"op":"mcm","clk":"992767690","pt":1580559095011,"mc":[{"id":"1.168136214","rc":[{"batb":[[0,4.1,17.98]],"ltp":4.1,"tv":4532.41,"id":12925630},{"batb":[[0,4,21.79]],"ltp":4.0,"tv":3599.49,"id":11981493}]}]}
{"op":"mcm","clk":"992768115","pt":1580559097018,"mc":[{"id":"1.168136214","rc":[{"batb":[[2,3.9,49.87]],"ltp":4.0,"tv":3599.49,"id":11981493}]}]}
{"op":"mcm","clk":"992769089","pt":1580559102099,"mc":[{"id":"1.168136214","rc":[{"batb":[[1,3.95,30.13]],"ltp":4.0,"tv":3599.49,"id":11981493}]}]}
{"op":"mcm","clk":"992771163","pt":1580559113006,"mc":[{"id":"1.168136214","rc":[{"trd":[[4.1,1439.08]],"batb":[[0,4.1,15.98]],"ltp":4.1,"tv":4536.41,"id":12925630},{"batl":[[0,4.1,24.4]],"ltp":4.0,"tv":3599.49,"id":11981493}],"tv":18410.99}]}
{"op":"mcm","clk":"992771929","pt":1580559117126,"mc":[{"id":"1.168136214","rc":[{"batl":[[0,4.2,96.12]],"ltp":4.1,"tv":4536.41,"id":12925630}]}]}
{"op":"mcm","clk":"992772105","pt":1580559118142,"mc":[{"id":"1.168136214","rc":[{"batb":[[0,4.1,7.63]],"ltp":4.1,"tv":4536.41,"id":12925630}]}]}
{"op":"mcm","clk":"992772274","pt":1580559119108,"mc":[{"id":"1.168136214","rc":[{"batb":[[1,4,122.66]],"ltp":4.1,"tv":4536.41,"id":12925630}]}]}
{"op":"mcm","clk":"992772854","pt":1580559122144,"mc":[{"id":"1.168136214","rc":[{"trd":[[4.1,1443.08]],"batb":[[0,4.1,5.63],[1,4,115.94]],"ltp":4.1,"tv":4540.4,"id":12925630},{"trd":[[1.96,787.77]],"batl":[[0,1.96,21.23]],"ltp":1.96,"tv":10285.09,"id":17336468}],"tv":18424.99}]}
{"op":"mcm","clk":"992773220","pt":1580559124140,"mc":[{"id":"1.168136214","rc":[{"trd":[[1.96,824.67]],"batb":[[0,1.95,90.6]],"batl":[[0,1.96,2.77]],"ltp":1.96,"tv":10321.99,"id":17336468},{"trd":[[4,307.69]],"batb":[[0,3.95,23.29],[1,3.9,49.87],[2,3.85,19.07]],"batl":[[0,4,5.23],[1,4.1,39.92],[2,4.2,25.96]],"ltp":4.0,"tv":3665.03,"id":11981493}],"tv":18527.43}]}
{"op":"mcm","clk":"992773401","pt":1580559125126,"mc":[{"id":"1.168136214","rc":[{"trd":[[1.96,830.21]],"batb":[[0,1.96,35.45],[1,1.95,90.6],[2,1.94,194.39]],"batl":[[0,1.97,33.79],[1,1.98,85.37],[2,1.99,21.17]],"ltp":1.96,"tv":10327.53,"id":17336468},{"trd":[[4,318.15]],"batb":[[0,4,22.49],[1,3.95,23.29],[2,3.9,49.87]],"batl":[[0,4.1,39.92],[1,4.2,25.96],[2,4.3,1.46]],"ltp":4.0,"tv":3675.49,"id":11981493}],"tv":18543.43}]}
{"op":"mcm","clk":"992773545","pt":1580559126041,"mc":[{"id":"1.168136214","rc":[{"batb":[[0,4.1,23.9]],"ltp":4.1,"tv":4540.4,"id":12925630},{"trd":[[1.96,834.69]],"batb":[[0,1.96,33.21]],"batl":[[0,1.97,16.79]],"ltp":1.96,"tv":10332.01,"id":17336468},{"trd":[[4,322.23]],"batb":[[0,4,20.45]],"batl":[[0,4.1,55.15]],"ltp":4.0,"tv":3679.57,"id":11981493}],"tv":18551.99}]}
{"op":"mcm","clk":"992773713","pt":1580559126955,"mc":[{"id":"1.168136214","rc":[{"batl":[[1,1.98,68.51]],"ltp":1.96,"tv":10332.01,"id":17336468}]}]}
{"op":"mcm","clk":"992774964","pt":1580559133144,"mc":[{"id":"1.168136214","rc":[{"batb":[[1,4,122.66]],"ltp":4.1,"tv":4540.4,"id":12925630},{"batb":[[2,1.94,215.84]],"ltp":1.96,"tv":10332.01,"id":17336468},{"batb":[[1,3.95,30.13]],"ltp":4.0,"tv":3679.57,"id":11981493}]}]}
{"op":"mcm","clk":"992775340","pt":1580559135077,"mc":[{"id":"1.168136214","rc":[{"batb":[[1,4,109.87]],"ltp":4.1,"tv":4540.4,"id":12925630},{"batb":[[0,4,11.45],[2,3.9,36.76]],"ltp":4.0,"tv":3679.57,"id":11981493}]}]}
{"op":"mcm","clk":"992775515","pt":1580559136056,"mc":[{"id":"1.168136214","rc":[{"trd":[[1.96,887.77]],"batb":[[0,1.96,6.67]],"ltp":1.96,"tv":10385.09,"id":17336468},{"trd":[[4,340.59]],"batb":[[0,4,2.27],[1,3.95,23.29]],"ltp":4.0,"tv":3697.93,"id":11981493}],"tv":18623.44}]}
{"op":"mcm","clk":"992776334","pt":1580559140076,"mc":[{"id":"1.168136214","rc":[{"batb":[[0,4.1,39.38]],"ltp":4.1,"tv":4540.4,"id":12925630}]}]}
{"op":"mcm","clk":"992776553","pt":1580559141065,"mc":[{"id":"1.168136214","rc":[{"trd":[[1.95,485.3],[1.96,901.09]],"batb":[[0,1.95,81.26],[1,1.94,215.84],[2,1.93,156.81]],"ltp":1.95,"tv":10417.09,"id":17336468}],"tv":18655.44}]}
{"op":"mcm","clk":"992776723","pt":1580559142111,"mc":[{"id":"1.168136214","rc":[{"trd":[[4.1,1447.07]],"batb":[[0,4.1,37.39]],"ltp":4.1,"tv":4544.4,"id":12925630}],"tv":18659.44}]}
{"op":"mcm","clk":"992777077","pt":1580559144081,"mc":[{"id":"1.168136214","rc":[{"batl":[[0,1.96,70],[1,1.97,16.79],[2,1.98,68.51]],"ltp":1.95,"tv":10417.09,"id":17336468}]}]}
{"op":"mcm","clk":"992777267","pt":1580559145064,"mc":[{"id":"1.168136214","rc":[{"batb":[[0,4.1,48.39]],"ltp":4.1,"tv":4544.4,"id":12925630},{"batb":[[0,1.95,84.6],[1,1.94,194.39]],"batl":[[0,1.96,76],[1,1.97,33.79]],"ltp":1.95,"tv":10417.09,"id":17336468},{"batb":[[0,4,11.4]],"ltp":4.0,"tv":3697.93,"id":11981493}]}]}
{"op":"mcm","clk":"992777490","pt":1580559146105,"mc":[{"id":"1.168136214","rc":[{"batl":[[2,1.98,57.09]],"ltp":1.95,"tv":10417.09,"id":17336468}]}]}
{"op":"mcm","clk":"992777617","pt":1580559146707,"mc":[{"id":"1.168136214","rc":[{"batl":[[0,1.96,87.54]],"ltp":1.95,"tv":10417.09,"id":17336468}]}]}
{"op":"mcm","clk":"992777993","pt":1580559148117,"mc":[{"id":"1.168136214","rc":[{"batb":[[0,4.1,98.39]],"ltp":4.1,"tv":4544.4,"id":12925630}]}]}
{"op":"mcm","clk":"992778807","pt":1580559151823,"mc":[{"id":"1.168136214","rc":[{"trd":[[4.1,1451.07]],"batb":[[0,4.1,96.39]],"ltp":4.1,"tv":4548.4,"id":12925630}],"tv":18663.43}]}
{"op":"mcm","clk":"992779059","pt":1580559153089,"mc":[{"id":"1.168136214","rc":[{"batb":[[0,4.1,111.38]],"ltp":4.1,"tv":4548.4,"id":12925630},{"batb":[[0,4,2.27],[1,3.95,30.13]],"batl":[[0,4.1,157.15]],"ltp":4.0,"tv":3697.93,"id":11981493}]}]}
{"op":"mcm","clk":"992779261","pt":1580559154121,"mc":[{"id":"1.168136214","rc":[{"batb":[[1,3.95,23.29]],"ltp":4.0,"tv":3697.93,"id":11981493}]}]}
{"op":"mcm","clk":"992779660","pt":1580559156123,"mc":[{"id":"1.168136214","rc":[{"batl":[[0,4.1,107.15]],"ltp":4.0,"tv":3697.93,"id":11981493}]}]}
{"op":"mcm","clk":"992780616","pt":1580559161129,"mc":[{"id":"1.168136214","rc":[{"batl":[[0,1.96,87.74]],"ltp":1.95,"tv":10417.09,"id":17336468}]}]}
{"op":"mcm","clk":"992781831","pt":1580559167142,"mc":[{"id":"1.168136214","rc":[{"batl":[[0,4.2,101.12]],"ltp":4.1,"tv":4548.4,"id":12925630}]}]}
{"op":"mcm","clk":"992782789","pt":1580559172143,"mc":[{"id":"1.168136214","rc":[{"batl":[[0,4.2,98.12]],"ltp":4.1,"tv":4548.4,"id":12925630},{"trd":[[4,344.59]],"batb":[[0,3.95,23.56],[1,3.9,36.76],[2,3.85,19.07]],"ltp":4.0,"tv":3701.93,"id":11981493}],"tv":18667.43}]}
{"op":"mcm","clk":"992783190","pt":1580559174073,"mc":[{"id":"1.168136214","rc":[{"trd":[[1.95,489.3]],"batb":[[0,1.95,82.6]],"batl":[[0,1.96,120.33]],"ltp":1.95,"tv":10421.09,"id":17336468}],"tv":18671.43}]}
{"op":"mcm","clk":"992783601","pt":1580559176054,"mc":[{"id":"1.168136214","rc":[{"trd":[[4.1,1455.07]],"batb":[[0,4.1,109.38]],"ltp":4.1,"tv":4552.4,"id":12925630},{"trd":[[1.96,905.07]],"batb":[[0,1.95,92.65]],"batl":[[0,1.96,118.34]],"ltp":1.96,"tv":10425.07,"id":17336468}],"tv":18679.41}]}
{"op":"mcm","clk":"992784584","pt":1580559181070,"mc":[{"id":"1.168136214","rc":[{"trd":[[1.95,690.51]],"batb":[[0,1.94,234.38],[1,1.93,148.52],[2,1.92,6]],"batl":[[0,1.95,152.69],[1,1.96,118.34],[2,1.97,33.79]],"ltp":1.95,"tv":10626.28,"id":17336468},{"batb":[[0,4,23.61],[1,3.95,23.29],[2,3.9,36.76]],"ltp":4.0,"tv":3701.93,"id":11981493}],"tv":18880.62}]}
{"op":"mcm","clk":"992784806","pt":1580559182127,"mc":[{"id":"1.168136214","rc":[{"batb":[[0,4.1,115.88]],"ltp":4.1,"tv":4552.4,"id":12925630},{"batb":[[0,1.94,237.38],[1,1.93,129.84],[2,1.92,36.92]],"batl":[[1,1.96,139.34]],"ltp":1.95,"tv":10626.28,"id":17336468},{"batb":[[0,4,34.61]],"ltp":4.0,"tv":3701.93,"id":11981493}]}]}
{"op":"mcm","clk":"992785028","pt":1580559183151,"mc":[{"id":"1.168136214","rc":[{"batb":[[1,1.93,121.2]],"ltp":1.95,"tv":10626.28,"id":17336468}]}]}
{"op":"mcm","clk":"992785217","pt":1580559184092,"mc":[{"id":"1.168136214","rc":[{"batl":[[0,4.2,48.12]],"ltp":4.1,"tv":4552.4,"id":12925630},{"trd":[[4,360.6]],"batb":[[0,4,26.61]],"ltp":4.0,"tv":3717.94,"id":11981493}],"tv":18896.63}]}
{"op":"mcm","clk":"992785393","pt":1580559185080,"mc":[{"id":"1.168136214","rc":[{"trd":[[4.2,1167.42]],"batl":[[0,4.2,42.27]],"ltp":4.2,"tv":4570.2,"id":12925630},{"batb":[[0,1.94,197.39]],"ltp":1.95,"tv":10626.28,"id":17336468}],"tv":18914.43}]}
{"op":"mcm","clk":"992785587","pt":1580559186079,"mc":[{"id":"1.168136214","rc":[{"trd":[[4.1,1459.07]],"batb":[[0,4.1,113.88]],"ltp":4.1,"tv":4574.2,"id":12925630}],"tv":18918.43}]}
{"op":"mcm","clk":"992786004","pt":1580559188018,"mc":[{"id":"1.168136214","rc":[{"batl":[[0,4.2,45.32]],"ltp":4.1,"tv":4574.2,"id":12925630}]}]}
{"op":"mcm","clk":"992786304","pt":1580559189101,"mc":[{"id":"1.168136214","rc":[{"batl":[[1,1.96,139.14]],"ltp":1.95,"tv":10626.28,"id":17336468},{"batb":[[1,3.95,30.13]],"ltp":4.0,"tv":3717.94,"id":11981493}]}]}
{"op":"mcm","clk":"992786919","pt":1580559192096,"mc":[{"id":"1.168136214","rc":[{"trd":[[1.94,167.41]],"batb":[[0,1.94,187.4]],"ltp":1.94,"tv":10646.27,"id":17336468}],"tv":18938.41}]}
{"op":"mcm","clk":"992787320","pt":1580559194089,"mc":[{"id":"1.168136214","rc":[{"batb":[[0,4,77.26]],"ltp":4.0,"tv":3717.94,"id":11981493}]}]}
{"op":"mcm","clk":"992787505","pt":1580559195120,"mc":[{"id":"1.168136214","rc":[{"trd":[[4.1,1463.07]],"batb":[[0,4.1,111.88]],"ltp":4.1,"tv":4578.2,"id":12925630},{"batl":[[0,1.95,158.69],[1,1.96,133.14]],"ltp":1.94,"tv":10646.27,"id":17336468}],"tv":18942.41}]}
{"op":"mcm","clk":"992787850","pt":1580559197097,"mc":[{"id":"1.168136214","rc":[{"batl":[[0,1.95,158.89]],"ltp":1.94,"tv":10646.27,"id":17336468}]}]}
{"op":"mcm","clk":"992788359","pt":1580559200118,"mc":[{"id":"1.168136214","rc":[{"trd":[[1.94,173.41]],"batb":[[0,1.94,184.4]],"ltp":1.94,"tv":10652.27,"id":17336468}],"tv":18948.41}]}
{"op":"mcm","clk":"992788508","pt":1580559201143,"mc":[{"id":"1.168136214","rc":[{"batb":[[1,4,211.17]],"ltp":4.1,"tv":4578.2,"id":12925630}]}]}
{"op":"mcm","clk":"992788902","pt":1580559203102,"mc":[{"id":"1.168136214","rc":[{"batb":[[0,4.1,105.38]],"ltp":4.1,"tv":4578.2,"id":12925630},{"batb":[[0,1.94,175.4]],"ltp":1.94,"tv":10652.27,"id":17336468},{"trd":[[4.1,34.99]],"batl":[[0,4.1,21.11]],"ltp":4.1,"tv":3736.04,"id":11981493}],"tv":18966.51}]}
{"op":"mcm","clk":"992789077","pt":1580559204121,"mc":[{"id":"1.168136214","rc":[{"batl":[[1,1.96,65.13]],"ltp":1.94,"tv":10652.27,"id":17336468}]}]}
{"op":"mcm","clk":"992789225","pt":1580559204824,"mc":[{"id":"1.168136214","rc":[{"trd":[[4.1,1467.07]],"batb":[[0,4.1,103.38]],"batl":[[0,4.2,49.32]],"ltp":4.1,"tv":4582.2,"id":12925630},{"batl":[[2,1.97,39.79]],"ltp":1.94,"tv":10652.27,"id":17336468}],"tv":18970.51}]}
{"op":"mcm","clk":"992790731","pt":1580559213047,"mc":[{"id":"1.168136214","rc":[{"trd":[[1.94,315.44]],"batb":[[0,1.94,104.39]],"ltp":1.94,"tv":10794.29,"id":17336468}],"tv":19112.54}]}
{"op":"mcm","clk":"992790914","pt":1580559214144,"mc":[{"id":"1.168136214","rc":[{"trd":[[1.94,341.9]],"batb":[[0,1.94,91.16]],"ltp":1.94,"tv":10820.75,"id":17336468}],"tv":19139.0}]}
{"op":"mcm","clk":"992791459","pt":1580559217156,"mc":[{"id":"1.168136214","rc":[{"batl":[[1,1.96,32.54]],"ltp":1.94,"tv":10820.75,"id":17336468}]}]}
{"op":"mcm","clk":"992791627","pt":1580559218133,"mc":[{"id":"1.168136214","rc":[{"batl":[[0,1.95,190.18]],"ltp":1.94,"tv":10820.75,"id":17336468}]}]}
{"op":"mcm","clk":"992792594","pt":1580559223059,"mc":[{"id":"1.168136214","rc":[{"batl":[[2,4.4,109.64]],"ltp":4.1,"tv":4582.2,"id":12925630}]}]}
{"op":"mcm","clk":"992792772","pt":1580559223973,"mc":[{"id":"1.168136214","rc":[{"batb":[[0,1.94,93.16]],"ltp":1.94,"tv":10820.75,"id":17336468}]}]}
{"op":"mcm","clk":"992792986","pt":1580559225065,"mc":[{"id":"1.168136214","rc":[{"batl":[[0,1.95,189.98]],"ltp":1.94,"tv":10820.75,"id":17336468}]}]}
{"op":"mcm","clk":"992793757","pt":1580559228955,"mc":[{"id":"1.168136214","rc":[{"trd":[[1.95,810.45]],"batl":[[0,1.95,130.04]],"ltp":1.95,"tv":10940.69,"id":17336468}],"tv":19258.94}]}
{"op":"mcm","clk":"992794568","pt":1580559233082,"mc":[{"id":"1.168136214","rc":[{"batl":[[0,1.95,130.24]],"ltp":1.95,"tv":10940.69,"id":17336468}]}]}
{"op":"mcm","clk":"992795012","pt":1580559235119,"mc":[{"id":"1.168136214","rc":[{"batb":[[1,4,312.47]],"ltp":4.1,"tv":4582.2,"id":12925630}]}]}
{"op":"mcm","clk":"992797600","pt":1580559247064,"mc":[{"id":"1.168136214","rc":[{"batl":[[1,1.96,46.37]],"ltp":1.95,"tv":10940.69,"id":17336468}]}]}
{"op":"mcm","clk":"992800611","pt":1580559261116,"mc":[{"id":"1.168136214","rc":[{"batl":[[0,1.95,130.04]],"ltp":1.95,"tv":10940.69,"id":17336468}]}]}
{"op":"mcm","clk":"992800747","pt":1580559261719,"mc":[{"id":"1.168136214","rc":[{"batb":[[0,1.94,91.16]],"ltp":1.95,"tv":10940.69,"id":17336468}]}]}
{"op":"mcm","clk":"992801469","pt":1580559265141,"mc":[{"id":"1.168136214","rc":[{"batl":[[0,1.95,98.75]],"ltp":1.95,"tv":10940.69,"id":17336468}]}]}
{"op":"mcm","clk":"992801683","pt":1580559266131,"mc":[{"id":"1.168136214","rc":[{"trd":[[1.94,403.72]],"batb":[[0,1.94,60.25]],"ltp":1.94,"tv":11002.51,"id":17336468}],"tv":19320.76}]}
{"op":"mcm","clk":"992802122","pt":1580559268135,"mc":[{"id":"1.168136214","rc":[{"batl":[[0,1.95,98.95]],"ltp":1.94,"tv":11002.51,"id":17336468}]}]}
{"op":"mcm","clk":"992802756","pt":1580559271125,"mc":[{"id":"1.168136214","rc":[{"batl":[[0,1.95,100.95]],"ltp":1.94,"tv":11002.51,"id":17336468}]}]}
{"op":"mcm","clk":"992805993","pt":1580559286898,"mc":[{"id":"1.168136214","rc":[{"trd":[[1.94,409.72]],"batb":[[0,1.94,57.25]],"ltp":1.94,"tv":11008.51,"id":17336468}],"tv":19326.76}]}
{"op":"mcm","clk":"992807076","pt":1580559292112,"mc":[{"id":"1.168136214","rc":[{"trd":[[4.2,1187.62]],"batl":[[0,4.2,39.22]],"ltp":4.2,"tv":4602.4,"id":12925630},{"batl":[[1,1.96,32.54]],"ltp":1.94,"tv":11008.51,"id":17336468}],"tv":19346.96}]}
{"op":"mcm","clk":"992807878","pt":1580559296145,"mc":[{"id":"1.168136214","rc":[{"batl":[[0,1.95,100.75]],"ltp":1.94,"tv":11008.51,"id":17336468}]}]}
{"op":"mcm","clk":"992808913","pt":1580559301123,"mc":[{"id":"1.168136214","rc":[{"trd":[[4.2,1235.89]],"batl":[[0,4.2,15.07]],"ltp":4.2,"tv":4650.67,"id":12925630}],"tv":19395.23}]}
{"op":"mcm","clk":"992809334","pt":1580559303135,"mc":[{"id":"1.168136214","rc":[{"batl":[[0,4.1,71.11]],"ltp":4.1,"tv":3736.04,"id":11981493}]}]}
{"op":"mcm","clk":"992809515","pt":1580559303938,"mc":[{"id":"1.168136214","rc":[{"batl":[[0,4.2,11.07]],"ltp":4.2,"tv":4650.67,"id":12925630},{"batl":[[0,1.95,100.95]],"ltp":1.94,"tv":11008.51,"id":17336468},{"batl":[[0,4.1,76.11]],"ltp":4.1,"tv":3736.04,"id":11981493}]}]}
{"op":"mcm","clk":"992810532","pt":1580559309057,"mc":[{"id":"1.168136214","rc":[{"batb":[[0,4,79.26]],"ltp":4.1,"tv":3736.04,"id":11981493}]}]}
{"op":"mcm","clk":"992810911","pt":1580559310953,"mc":[{"id":"1.168136214","rc":[{"trd":[[1.94,472.32]],"batb":[[0,1.94,25.95]],"ltp":1.94,"tv":11071.11,"id":17336468}],"tv":19457.83}]}
{"op":"mcm","clk":"992811493","pt":1580559313748,"mc":[{"id":"1.168136214","rc":[{"trd":[[1.94,484.32]],"batb":[[0,1.94,19.95]],"ltp":1.94,"tv":11083.11,"id":17336468}],"tv":19469.83}]}
{"op":"mcm","clk":"992812765","pt":1580559320069,"mc":[{"id":"1.168136214","rc":[{"trd":[[4,364.6]],"batb":[[0,4,77.26]],"ltp":4.0,"tv":3740.04,"id":11981493}],"tv":19473.83}]}
{"op":"mcm","clk":"992814532","pt":1580559329096,"mc":[{"id":"1.168136214","rc":[{"trd":[[1.95,821.44]],"batl":[[0,1.95,95.46]],"ltp":1.95,"tv":11094.11,"id":17336468}],"tv":19484.82}]}
{"op":"mcm","clk":"992814705","pt":1580559330081,"mc":[{"id":"1.168136214","rc":[{"trd":[[1.94,524.22]],"batb":[[0,1.93,121.2],[1,1.92,36.92],[2,1.91,54.1]],"batl":[[0,1.94,79.05],[1,1.95,95.46],[2,1.96,32.54]],"ltp":1.94,"tv":11134.01,"id":17336468}],"tv":19524.72}]}
{"op":"mcm","clk":"992814865","pt":1580559331009,"mc":[{"id":"1.168136214","rc":[{"batb":[[1,1.92,15],[2,1.91,86.26]],"batl":[[0,1.94,85.05],[1,1.95,112.46],[2,1.96,64.32]],"ltp":1.94,"tv":11134.01,"id":17336468}]}]}
{"op":"mcm","clk":"992815078","pt":1580559332088,"mc":[{"id":"1.168136214","rc":[{"batl":[[0,1.94,96.7],[1,1.95,112.26],[2,1.96,52.78]],"ltp":1.94,"tv":11134.01,"id":17336468}]}]}
{"op":"mcm","clk":"992815248","pt":1580559333001,"mc":[{"id":"1.168136214","rc":[{"batl":[[0,4.1,71.11]],"ltp":4.0,"tv":3740.04,"id":11981493}]}]}
{"op":"mcm","clk":"992815447","pt":1580559334090,"mc":[{"id":"1.168136214","rc":[{"trd":[[4.2,1246.96]],"batb":[[0,4.2,21.82],[1,4.1,103.38],[2,4,312.47]],"batl":[[0,4.3,131.29],[1,4.4,113.64],[2,4.5,48.78]],"ltp":4.2,"tv":4661.74,"id":12925630},{"trd":[[1.94,548.19]],"batl":[[0,1.94,72.73]],"ltp":1.94,"tv":11157.98,"id":17336468},{"trd":[[4,542.92]],"batb":[[0,4,3.94]],"batl":[[1,4.2,27.96]],"ltp":4.0,"tv":3918.36,"id":11981493}],"tv":19738.08}]}
{"op":"mcm","clk":"992815614","pt":1580559334996,"mc":[{"id":"1.168136214","rc":[{"batb":[[1,4.1,113.18]],"batl":[[0,4.3,125.93]],"ltp":4.2,"tv":4661.74,"id":12925630},{"batb":[[0,3.95,23.29],[1,3.9,36.76],[2,3.85,19.07]],"batl":[[0,4.1,76.11]],"ltp":4.0,"tv":3918.36,"id":11981493}]}]}
{"op":"mcm","clk":"992816377","pt":1580559339081,"mc":[{"id":"1.168136214","rc":[{"batl":[[0,1.94,72.93]],"ltp":1.94,"tv":11157.98,"id":17336468}]}]}
{"op":"mcm","clk":"992816575","pt":1580559340103,"mc":[{"id":"1.168136214","rc":[{"batl":[[1,1.95,117.95]],"ltp":1.94,"tv":11157.98,"id":17336468}]}]}
{"op":"mcm","clk":"992816791","pt":1580559341101,"mc":[{"id":"1.168136214","rc":[{"trd":[[1.94,588.19]],"batl":[[0,1.94,52.93]],"ltp":1.94,"tv":11197.98,"id":17336468}],"tv":19778.08}]}
{"op":"mcm","clk":"992817010","pt":1580559342128,"mc":[{"id":"1.168136214","rc":[{"trd":[[4.2,1266.96]],"batb":[[0,4.2,11.82],[1,4.1,119.68]],"ltp":4.2,"tv":4681.74,"id":12925630},{"trd":[[1.93,300.4]],"batb":[[0,1.92,15],[1,1.91,86.26],[2,1.9,67.71]],"batl":[[0,1.93,158.8],[1,1.94,52.93],[2,1.95,117.95]],"ltp":1.93,"tv":11480.38,"id":17336468},{"batb":[[0,4,8.02],[1,3.95,23.29],[2,3.9,36.76]],"ltp":4.0,"tv":3918.36,"id":11981493}],"tv":20080.48}]}
{"op":"mcm","clk":"992817184","pt":1580559343096,"mc":[{"id":"1.168136214","rc":[{"batb":[[0,4.2,21.64]],"ltp":4.2,"tv":4681.74,"id":12925630},{"batb":[[0,1.92,58.11],[2,1.9,77.71]],"batl":[[1,1.94,75.93]],"ltp":1.93,"tv":11480.38,"id":17336468},{"batb":[[0,4,19.25]],"ltp":4.0,"tv":3918.36,"id":11981493}]}]}
{"op":"mcm","clk":"992817384","pt":1580559344106,"mc":[{"id":"1.168136214","rc":[{"batb":[[1,4.1,109.88]],"ltp":4.2,"tv":4681.74,"id":12925630},{"batb":[[1,1.91,64.1],[2,1.9,100.12]],"ltp":1.93,"tv":11480.38,"id":17336468}]}]}
{"op":"mcm","clk":"992817753","pt":1580559346133,"mc":[{"id":"1.168136214","rc":[{"trd":[[1.93,320.4]],"batl":[[0,1.93,148.8]],"ltp":1.93,"tv":11500.38,"id":17336468}],"tv":20100.48}]}
{"op":"mcm","clk":"992817935","pt":1580559347127,"mc":[{"id":"1.168136214","rc":[{"batl":[[1,1.94,81.64]],"ltp":1.93,"tv":11500.38,"id":17336468}]}]}
{"op":"mcm","clk":"992818284","pt":1580559349049,"mc":[{"id":"1.168136214","rc":[{"batl":[[0,1.93,154.8],[1,1.94,75.64]],"ltp":1.93,"tv":11500.38,"id":17336468}]}]}
{"op":"mcm","clk":"992818521","pt":1580559350152,"mc":[{"id":"1.168136214","rc":[{"trd":[[1.93,330.4]],"batl":[[0,1.93,149.8]],"ltp":1.93,"tv":11510.38,"id":17336468}],"tv":20110.48}]}
{"op":"mcm","clk":"992818716","pt":1580559351148,"mc":[{"id":"1.168136214","rc":[{"batb":[[1,3.95,30.13]],"ltp":4.0,"tv":3918.36,"id":11981493}]}]}
{"op":"mcm","clk":"992819510","pt":1580559355156,"mc":[{"id":"1.168136214","rc":[{"batl":[[0,1.93,151.8]],"ltp":1.93,"tv":11510.38,"id":17336468}]}]}
{"op":"mcm","clk":"992819870","pt":1580559357058,"mc":[{"id":"1.168136214","rc":[{"trd":[[1.93,342.46]],"batl":[[0,1.93,145.77]],"ltp":1.93,"tv":11522.44,"id":17336468}],"tv":20122.54}]}
{"op":"mcm","clk":"992820779","pt":1580559361986,"mc":[{"id":"1.168136214","rc":[{"batl":[[1,1.94,106.94]],"ltp":1.93,"tv":11522.44,"id":17336468}]}]}
{"op":"mcm","clk":"992821992","pt":1580559368047,"mc":[{"id":"1.168136214","rc":[{"batl":[[1,1.94,106.74]],"ltp":1.93,"tv":11522.44,"id":17336468}]}]}
{"op":"mcm","clk":"992822163","pt":1580559368971,"mc":[{"id":"1.168136214","rc":[{"batb":[[1,4.1,119.68]],"ltp":4.2,"tv":4681.74,"id":12925630},{"batb":[[0,1.92,25.57]],"ltp":1.93,"tv":11522.44,"id":17336468},{"batl":[[0,4.1,21.11]],"ltp":4.0,"tv":3918.36,"id":11981493}]}]}
{"op":"mcm","clk":"992823420","pt":1580559375086,"mc":[{"id":"1.168136214","rc":[{"batl":[[0,1.93,145.97]],"ltp":1.93,"tv":11522.44,"id":17336468}]}]}
{"op":"mcm","clk":"992823879","pt":1580559377089,"mc":[{"id":"1.168136214","rc":[{"batl":[[0,1.93,147.97],[2,1.95,115.95]],"ltp":1.93,"tv":11522.44,"id":17336468}]}]}
{"op":"mcm","clk":"992825017","pt":1580559383081,"mc":[{"id":"1.168136214","rc":[{"batb":[[0,1.92,55.57]],"ltp":1.93,"tv":11522.44,"id":17336468}]}]}
{"op":"mcm","clk":"992826957","pt":1580559393141,"mc":[{"id":"1.168136214","rc":[{"trd":[[1.92,131.16]],"batb":[[0,1.91,64.1],[1,1.9,100.12],[2,1.88,8.88]],"batl":[[0,1.92,147.18],[1,1.93,10.2],[2,1.94,106.74]],"ltp":1.92,"tv":11653.59,"id":17336468},{"batb":[[0,4,32.04]],"batl":[[0,4.1,13.35]],"ltp":4.0,"tv":3918.36,"id":11981493}],"tv":20253.7}]}
{"op":"mcm","clk":"992827131","pt":1580559394057,"mc":[{"id":"1.168136214","rc":[{"batb":[[0,4.2,33.81]],"ltp":4.2,"tv":4681.74,"id":12925630},{"batb":[[0,1.91,54.1],[1,1.9,57],[2,1.89,32.66]],"batl":[[0,1.92,158.96],[1,1.93,33.38],[2,1.94,95.08]],"ltp":1.92,"tv":11653.59,"id":17336468},{"batb":[[0,4,37.14]],"ltp":4.0,"tv":3918.36,"id":11981493}]}]}
{"op":"mcm","clk":"992827339","pt":1580559395155,"mc":[{"id":"1.168136214","rc":[{"batb":[[1,4.1,109.88]],"ltp":4.2,"tv":4681.74,"id":12925630},{"batb":[[0,4,48.14]],"ltp":4.0,"tv":3918.36,"id":11981493}]}]}
{"op":"mcm","clk":"992827523","pt":1580559396151,"mc":[{"id":"1.168136214","rc":[{"batb":[[0,4.2,35.81]],"ltp":4.2,"tv":4681.74,"id":12925630}]}]}
{"op":"mcm","clk":"992827879","pt":1580559398142,"mc":[{"id":"1.168136214","rc":[{"trd":[[1.92,171.16]],"batl":[[0,1.92,138.96]],"ltp":1.92,"tv":11693.59,"id":17336468}],"tv":20293.7}]}
{"op":"mcm","clk":"992828039","pt":1580559398975,"mc":[{"id":"1.168136214","rc":[{"trd":[[1.92,193.16]],"batl":[[0,1.92,127.96],[2,1.94,63.78]],"ltp":1.92,"tv":11715.59,"id":17336468}],"tv":20315.7}]}
{"op":"mcm","clk":"992828119","pt":1580559399454,"mc":[{"id":"1.168136214","rc":[{"batl":[[0,1.92,159.24]],"ltp":1.92,"tv":11715.59,"id":17336468}]}]}
{"op":"mcm","clk":"992828813","pt":1580559403071,"mc":[{"id":"1.168136214","rc":[{"batl":[[1,1.93,33.18]],"ltp":1.92,"tv":11715.59,"id":17336468}]}]}
{"op":"mcm","clk":"992829156","pt":1580559405060,"mc":[{"id":"1.168136214","rc":[{"trd":[[1.91,24]],"batb":[[0,1.91,42.1]],"batl":[[1,1.93,27.18]],"ltp":1.91,"tv":11739.59,"id":17336468}],"tv":20339.7}]}
{"op":"mcm","clk":"992829804","pt":1580559408091,"mc":[{"id":"1.168136214","rc":[{"trd":[[4.3,400]],"batl":[[0,4.3,113.2]],"ltp":4.3,"tv":4694.47,"id":12925630},{"trd":[[1.91,64.66]],"batb":[[0,1.9,57],[1,1.89,32.66],[2,1.88,8.88]],"batl":[[0,1.91,4.24],[1,1.92,84.24],[2,1.93,27.18]],"ltp":1.91,"tv":11780.25,"id":17336468},{"trd":[[4.1,48.34]],"batl":[[0,4.2,27.96],[1,4.3,1.46],[2,4.4,13.51]],"ltp":4.1,"tv":3931.71,"id":11981493}],"tv":20406.44}]}
{"op":"mcm","clk":"992829919","pt":1580559408694,"mc":[{"id":"1.168136214","rc":[{"batl":[[0,4.3,117.2]],"ltp":4.3,"tv":4694.47,"id":12925630},{"batb":[[0,1.9,47],[2,1.88,18.88]],"batl":[[1,1.92,107.24]],"ltp":1.91,"tv":11780.25,"id":17336468},{"batl":[[0,4.2,22.96],[1,4.3,5.72]],"ltp":4.1,"tv":3931.71,"id":11981493}]}]}
{"op":"mcm","clk":"992830240","pt":1580559410153,"mc":[{"id":"1.168136214","rc":[{"trd":[[4.3,401.88]],"batl":[[0,4.3,115.32]],"ltp":4.3,"tv":4696.35,"id":12925630},{"trd":[[1.91,68.9]],"batl":[[0,1.92,107.44],[1,1.93,25.18],[2,1.94,58.08]],"ltp":1.91,"tv":11784.49,"id":17336468},{"trd":[[4,548.96],[4.1,50.32]],"batb":[[0,4,52.85]],"batl":[[0,4.2,18.18]],"ltp":4.0,"tv":3939.73,"id":11981493}],"tv":20420.58}]}
{"op":"mcm","clk":"992831105","pt":1580559415091,"mc":[{"id":"1.168136214","rc":[{"batl":[[0,1.91,2],[1,1.92,107.44],[2,1.93,23.18]],"ltp":1.91,"tv":11784.49,"id":17336468}]}]}
{"op":"mcm","clk":"992831287","pt":1580559415991,"mc":[{"id":"1.168136214","rc":[{"batb":[[2,4,315.47]],"ltp":4.3,"tv":4696.35,"id":12925630}]}]}
{"op":"mcm","clk":"992831501","pt":1580559417111,"mc":[{"id":"1.168136214","rc":[{"batl":[[2,1.93,30.93]],"ltp":1.91,"tv":11784.49,"id":17336468}]}]}
{"op":"mcm","clk":"992833738","pt":1580559428029,"mc":[{"id":"1.168136214","rc":[{"trd":[[4.3,402.68]],"batl":[[0,4.3,114.52]],"ltp":4.3,"tv":4697.15,"id":12925630},{"trd":[[1.91,70.7]],"batl":[[0,1.92,107.64],[1,1.93,30.93],[2,1.94,58.08]],"ltp":1.91,"tv":11786.29,"id":17336468},{"trd":[[4.1,51.16]],"ltp":4.1,"tv":3940.57,"id":11981493}],"tv":20424.02}]}
{"op":"mcm","clk":"992834056","pt":1580559429133,"mc":[{"id":"1.168136214","rc":[{"batb":[[0,4.1,13.67],[1,4,52.85],[2,3.95,30.13]],"ltp":4.1,"tv":3940.57,"id":11981493}]}]}
{"op":"mcm","clk":"992834219","pt":1580559430046,"mc":[{"id":"1.168136214","rc":[{"trd":[[1.9,34]],"batb":[[0,1.9,30]],"ltp":1.9,"tv":11820.29,"id":17336468},{"batb":[[1,4,62.98]],"ltp":4.1,"tv":3940.57,"id":11981493}],"tv":20458.02}]}
{"op":"mcm","clk":"992835189","pt":1580559435132,"mc":[{"id":"1.168136214","rc":[{"trd":[[1.9,54]],"batb":[[0,1.9,20]],"ltp":1.9,"tv":11840.29,"id":17336468},{"batb":[[0,4.1,21.6]],"ltp":4.1,"tv":3940.57,"id":11981493}],"tv":20478.02}]}
{"op":"mcm","clk":"992835311","pt":1580559435844,"mc":[{"id":"1.168136214","rc":[{"batb":[[1,1.89,10],[2,1.88,41.79]],"batl":[[2,1.94,66.75]],"ltp":1.9,"tv":11840.29,"id":17336468}]}]}
{"op":"mcm","clk":"992835558","pt":1580559437072,"mc":[{"id":"1.168136214","rc":[{"batb":[[1,4,69.7]],"ltp":4.1,"tv":3940.57,"id":11981493}]}]}
{"op":"mcm","clk":"992835953","pt":1580559438975,"mc":[{"id":"1.168136214","rc":[{"batl":[[0,1.92,107.44]],"ltp":1.9,"tv":11840.29,"id":17336468}]}]}
{"op":"mcm","clk":"992836782","pt":1580559443089,"mc":[{"id":"1.168136214","rc":[{"batl":[[0,1.91,71.3],[1,1.92,107.24],[2,1.93,30.93]],"ltp":1.9,"tv":11840.29,"id":17336468}]}]}
{"op":"mcm","clk":"992837164","pt":1580559445087,"mc":[{"id":"1.168136214","rc":[{"batb":[[0,1.9,30]],"ltp":1.9,"tv":11840.29,"id":17336468},{"batb":[[1,4,59.57]],"ltp":4.1,"tv":3940.57,"id":11981493}]}]}
{"op":"mcm","clk":"992837351","pt":1580559446096,"mc":[{"id":"1.168136214","rc":[{"batl":[[0,1.91,71.5]],"ltp":1.9,"tv":11840.29,"id":17336468}]}]}
{"op":"mcm","clk":"992853195","pt":1580559474072,"mc":[{"id":"1.168136214","rc":[{"batl":[[0,4.3,110.52],[1,4.4,109.64]],"ltp":4.3,"tv":4697.15,"id":12925630},{"batl":[[0,1.91,71.3]],"ltp":1.9,"tv":11840.29,"id":17336468}]}]}
{"op":"mcm","clk":"992854786","pt":1580559482082,"mc":[{"id":"1.168136214","rc":[{"batl":[[0,1.91,71.5]],"ltp":1.9,"tv":11840.29,"id":17336468}]}]}
{"op":"mcm","clk":"992855606","pt":1580559485991,"mc":[{"id":"1.168136214","rc":[{"batl":[[1,1.92,75.96]],"ltp":1.9,"tv":11840.29,"id":17336468}]}]}
{"op":"mcm","clk":"992855820","pt":1580559487064,"mc":[{"id":"1.168136214","rc":[{"batl":[[0,1.91,101.79],[1,1.92,78.17]],"ltp":1.9,"tv":11840.29,"id":17336468}]}]}
{"op":"mcm","clk":"992856861","pt":1580559492074,"mc":[{"id":"1.168136214","rc":[{"batl":[[0,4.3,211.82]],"ltp":4.3,"tv":4697.15,"id":12925630}]}]}
{"op":"mcm","clk":"992857035","pt":1580559493086,"mc":[{"id":"1.168136214","rc":[{"batl":[[2,4.4,22.19]],"ltp":4.1,"tv":3940.57,"id":11981493}]}]}
{"op":"mcm","clk":"992857195","pt":1580559493995,"mc":[{"id":"1.168136214","rc":[{"trd":[[4.1,53.18]],"batb":[[0,4.1,20.59]],"ltp":4.1,"tv":3942.59,"id":11981493}],"tv":20480.04}]}
{"op":"mcm","clk":"992857601","pt":1580559496102,"mc":[{"id":"1.168136214","rc":[{"batb":[[0,4.2,21.81]],"batl":[[0,4.3,215.82],[1,4.4,112.64]],"ltp":4.3,"tv":4697.15,"id":12925630},{"trd":[[1.91,274.28],[1.92,721.58],[1.93,369]],"batb":[[0,1.9,40]],"batl":[[0,1.92,21],[1,1.93,36.88],[2,1.94,66.75]],"ltp":1.93,"tv":12598.83,"id":17336468},{"batb":[[0,4.1,8.62],[1,4,55.34],[2,3.95,26.13]],"ltp":4.1,"tv":3942.59,"id":11981493}],"tv":21238.58}]}
{"op":"mcm","clk":"992857797","pt":1580559497026,"mc":[{"id":"1.168136214","rc":[{"batl":[[1,1.93,29.13]],"ltp":1.93,"tv":12598.83,"id":17336468}]}]}
{"op":"mcm","clk":"992858838","pt":1580559502115,"mc":[{"id":"1.168136214","rc":[{"trd":[[4.2,1268.94]],"batb":[[0,4.2,20.83]],"ltp":4.2,"tv":4699.12,"id":12925630},{"batl":[[0,4.2,68.18]],"ltp":4.1,"tv":3942.59,"id":11981493}],"tv":21240.56}]}
{"op":"mcm","clk":"992859044","pt":1580559503106,"mc":[{"id":"1.168136214","rc":[{"batb":[[0,4.2,33.83]],"ltp":4.2,"tv":4699.12,"id":12925630},{"batb":[[1,1.89,32.66]],"batl":[[0,1.92,13.32],[2,1.94,81.51]],"ltp":1.93,"tv":12598.83,"id":17336468},{"batl":[[0,4.2,73.18]],"ltp":4.1,"tv":3942.59,"id":11981493}]}]}
{"op":"mcm","clk":"992859226","pt":1580559504129,"mc":[{"id":"1.168136214","rc":[{"trd":[[4.2,1269.04]],"batb":[[0,4.2,33.78],[2,4,312.47]],"ltp":4.2,"tv":4699.23,"id":12925630}],"tv":21240.66}]}
{"op":"mcm","clk":"992859411","pt":1580559505107,"mc":[{"id":"1.168136214","rc":[{"batl":[[2,4.4,13.51]],"ltp":4.1,"tv":3942.59,"id":11981493}]}]}
{"op":"mcm","clk":"992859580","pt":1580559506021,"mc":[{"id":"1.168136214","rc":[{"trd":[[1.9,58]],"batb":[[0,1.9,38]],"ltp":1.9,"tv":12602.83,"id":17336468}],"tv":21244.66}]}
{"op":"mcm","clk":"992860032","pt":1580559508096,"mc":[{"id":"1.168136214","rc":[{"batl":[[0,1.91,6.78]],"ltp":1.9,"tv":12602.83,"id":17336468}]}]}
{"op":"mcm","clk":"992860435","pt":1580559510120,"mc":[{"id":"1.168136214","rc":[{"batb":[[1,4,105.34]],"ltp":4.1,"tv":3942.59,"id":11981493}]}]}
{"op":"mcm","clk":"992860635","pt":1580559511111,"mc":[{"id":"1.168136214","rc":[{"batl":[[1,1.92,9],[2,1.93,29.13]],"ltp":1.9,"tv":12602.83,"id":17336468},{"batb":[[1,4,155.34]],"batl":[[0,4.2,68.18]],"ltp":4.1,"tv":3942.59,"id":11981493}]}]}
{"op":"mcm","clk":"992860852","pt":1580559512094,"mc":[{"id":"1.168136214","rc":[{"trd":[[4.3,507.08]],"batl":[[0,4.3,149.56]],"ltp":4.3,"tv":4803.63,"id":12925630},{"trd":[[1.91,281.06],[1.92,730.58],[1.93,398.13]],"batb":[[1,1.89,63.05]],"batl":[[0,1.94,58.51],[1,1.95,103.26],[2,1.97,36.67]],"ltp":1.93,"tv":12647.74,"id":17336468},{"trd":[[4,1008.39],[4.1,73.58]],"batb":[[0,3.95,26.13],[1,3.9,33.76],[2,3.85,6.17]],"batl":[[0,4,49.31],[1,4.1,7.17],[2,4.2,75.18]],"ltp":4.0,"tv":4422.42,"id":11981493}],"tv":21873.8}]}
{"op":"mcm","clk":"992861053","pt":1580559513113,"mc":[{"id":"1.168136214","rc":[{"batl":[[0,1.94,43.75]],"ltp":1.93,"tv":12647.74,"id":17336468},{"trd":[[3.95,478.11]],"batb":[[0,3.95,17.45]],"ltp":3.95,"tv":4426.1,"id":11981493}],"tv":21877.48}]}
{"op":"mcm","clk":"992861272","pt":1580559514092,"mc":[{"id":"1.168136214","rc":[{"batb":[[0,1.9,46.7],[1,1.89,75.23]],"batl":[[0,1.94,35.08]],"ltp":1.93,"tv":12647.74,"id":17336468},{"batl":[[2,4.2,88.44]],"ltp":3.95,"tv":4426.1,"id":11981493}]}]}
