{"op":"mcm","clk":"988715143","pt":1580508540877,"mc":[{"id":"1.168136214","rc":[{"batl":[[0,3.55,2.2],[1,3.6,7],[2,3.7,7]],"ltp":3.2,"tv":191.56,"id":11981493}]}]}
{"op":"mcm","clk":"988717951","pt":1580508594777,"mc":[{"id":"1.168136214","rc":[{"batb":[[0,1.95,10.79],[1,1.94,6],[2,1.93,60]],"ltp":2.0,"tv":655.77,"id":17336468}]}]}
{"op":"mcm","clk":"988720810","pt":1580508647947,"mc":[{"id":"1.168136214","rc":[{"batb":[[0,3.15,6.35],[1,3.1,55.78],[2,3.05,32]],"ltp":3.2,"tv":191.56,"id":11981493}]}]}
{"op":"mcm","clk":"988726843","pt":1580508759914,"mc":[{"id":"1.168136214","rc":[{"batl":[[0,1.99,25],[1,2,28.22],[2,2.06,6.38]],"ltp":2.0,"tv":655.77,"id":17336468}]}]}
{"op":"mcm","clk":"988726880","pt":1580508761049,"mc":[{"id":"1.168136214","rc":[{"batl":[[2,2.02,25]],"ltp":2.0,"tv":655.77,"id":17336468}]}]}
{"op":"mcm","clk":"988727626","pt":1580508774365,"mc":[{"id":"1.168136214","rc":[{"batl":[[0,1.98,7.7],[1,1.99,25],[2,2,28.22]],"ltp":2.0,"tv":655.77,"id":17336468}]}]}
{"op":"mcm","clk":"988729374","pt":1580508808008,"mc":[{"id":"1.168136214","rc":[{"batb":[[0,1.94,6.79],[1,1.93,60],[2,1.92,19.69]],"ltp":2.0,"tv":655.77,"id":17336468}]}]}
{"op":"mcm","clk":"988729395","pt":1580508808519,"mc":[{"id":"1.168136214","rc":[{"batl":[[0,1.99,25],[1,2,35.84],[2,2.02,25]],"ltp":2.0,"tv":655.77,"id":17336468}]}]}
{"op":"mcm","clk":"988731082","pt":1580508842085,"mc":[{"id":"1.168136214","rc":[{"batl":[[1,2,28.22]],"ltp":2.0,"tv":655.77,"id":17336468}]}]}
{"op":"mcm","clk":"988731110","pt":1580508842547,"mc":[{"id":"1.168136214","rc":[{"batl":[[0,1.98,7.7],[1,1.99,25],[2,2,28.22]],"ltp":2.0,"tv":655.77,"id":17336468}]}]}
{"op":"mcm","clk":"988732974","pt":1580508879360,"mc":[{"id":"1.168136214","rc":[{"batl":[[0,1.99,25],[1,2,35.84],[2,2.02,25]],"ltp":2.0,"tv":655.77,"id":17336468}]}]}
{"op":"mcm","clk":"988734646","pt":1580508912696,"mc":[{"id":"1.168136214","rc":[{"batl":[[0,1.98,7.7],[1,1.99,25],[2,2,28.22]],"ltp":2.0,"tv":655.77,"id":17336468}]}]}
{"op":"mcm","clk":"988736443","pt":1580508946867,"mc":[{"id":"1.168136214","rc":[{"batl":[[0,1.99,25],[1,2,35.84],[2,2.02,25]],"ltp":2.0,"tv":655.77,"id":17336468}]}]}
{"op":"mcm","clk":"988738456","pt":1580508984010,"mc":[{"id":"1.168136214","rc":[{"batl":[[0,1.98,7.7],[1,1.99,25],[2,2,28.22]],"ltp":2.0,"tv":655.77,"id":17336468}]}]}
{"op":"mcm","clk":"988753161","pt":1580509075001,"mc":[{"id":"1.168136214","rc":[{"batl":[[0,1.99,25],[1,2,35.84],[2,2.02,25]],"ltp":2.0,"tv":655.77,"id":17336468}]}]}
{"op":"mcm","clk":"988757560","pt":1580509152888,"mc":[{"id":"1.168136214","rc":[{"batl":[[0,1.98,7.7],[1,1.99,25],[2,2,28.22]],"ltp":2.0,"tv":655.77,"id":17336468}]}]}
{"op":"mcm","clk":"988759817","pt":1580509195766,"mc":[{"id":"1.168136214","rc":[{"batb":[[0,3.2,3],[1,3.15,6.35],[2,3.1,55.78]],"ltp":3.2,"tv":191.56,"id":11981493}]}]}
{"op":"mcm","clk":"988760609","pt":1580509210966,"mc":[{"id":"1.168136214","rc":[{"batl":[[0,1.99,25],[1,2,35.84],[2,2.02,25]],"ltp":2.0,"tv":655.77,"id":17336468}]}]}
{"op":"mcm","clk":"988763599","pt":1580509269680,"mc":[{"id":"1.168136214","rc":[{"batl":[[0,1.98,7.7],[1,1.99,25],[2,2,28.22]],"ltp":2.0,"tv":655.77,"id":17336468}]}]}
{"op":"mcm","clk":"988765395","pt":1580509303836,"mc":[{"id":"1.168136214","rc":[{"batl":[[0,1.99,25],[1,2,35.84],[2,2.02,25]],"ltp":2.0,"tv":655.77,"id":17336468}]}]}
{"op":"mcm","clk":"988768234","pt":1580509355857,"mc":[{"id":"1.168136214","rc":[{"batl":[[0,1.98,7.7],[1,1.99,25],[2,2,28.22]],"ltp":2.0,"tv":655.77,"id":17336468}]}]}
{"op":"mcm","clk":"988770330","pt":1580509396924,"mc":[{"id":"1.168136214","rc":[{"batl":[[0,1.99,25],[1,2,35.84],[2,2.02,25]],"ltp":2.0,"tv":655.77,"id":17336468}]}]}
{"op":"mcm","clk":"988770555","pt":1580509401254,"mc":[{"id":"1.168136214","rc":[{"batb":[[0,3.2,10]],"ltp":3.2,"tv":191.56,"id":11981493}]}]}
{"op":"mcm","clk":"988772253","pt":1580509437074,"mc":[{"id":"1.168136214","rc":[{"batl":[[1,2,28.22]],"ltp":2.0,"tv":655.77,"id":17336468}]}]}
{"op":"mcm","clk":"988772259","pt":1580509437175,"mc":[{"id":"1.168136214","rc":[{"batl":[[0,1.98,7.7],[1,1.99,25],[2,2,28.22]],"ltp":2.0,"tv":655.77,"id":17336468}]}]}
{"op":"mcm","clk":"988772992","pt":1580509451903,"mc":[{"id":"1.168136214","rc":[{"batb":[[1,3.1,55.78],[2,3.05,32]],"ltp":3.2,"tv":191.56,"id":11981493}]}]}
{"op":"mcm","clk":"988773239","pt":1580509457002,"mc":[{"id":"1.168136214","rc":[{"batb":[[1,3.15,6],[2,3.1,55.78]],"ltp":3.2,"tv":191.56,"id":11981493}]}]}
{"op":"mcm","clk":"988774903","pt":1580509491705,"mc":[{"id":"1.168136214","rc":[{"batl":[[0,1.99,25],[1,2,35.84],[2,2.02,25]],"ltp":2.0,"tv":655.77,"id":17336468}]}]}
{"op":"mcm","clk":"988776083","pt":1580509515818,"mc":[{"id":"1.168136214","rc":[{"batb":[[2,3.1,75.78]],"ltp":3.2,"tv":191.56,"id":11981493}]}]}
{"op":"mcm","clk":"988776599","pt":1580509527450,"mc":[{"id":"1.168136214","rc":[{"batl":[[0,1.98,7.7],[1,1.99,25],[2,2,28.22]],"ltp":2.0,"tv":655.77,"id":17336468}]}]}
{"op":"mcm","clk":"988778276","pt":1580509560984,"mc":[{"id":"1.168136214","rc":[{"batl":[[0,1.99,25],[1,2,35.84],[2,2.02,25]],"ltp":2.0,"tv":655.77,"id":17336468}]}]}
{"op":"mcm","clk":"988780043","pt":1580509594698,"mc":[{"id":"1.168136214","rc":[{"batl":[[0,1.98,7.7],[1,1.99,25],[2,2,28.22]],"ltp":2.0,"tv":655.77,"id":17336468}]}]}
{"op":"mcm","clk":"988781942","pt":1580509628001,"mc":[{"id":"1.168136214","rc":[{"batl":[[0,1.99,25],[1,2,35.84],[2,2.02,25]],"ltp":2.0,"tv":655.77,"id":17336468}]}]}
{"op":"mcm","clk":"988783839","pt":1580509662138,"mc":[{"id":"1.168136214","rc":[{"batl":[[0,1.98,7.7],[1,1.99,25],[2,2,28.22]],"ltp":2.0,"tv":655.77,"id":17336468}]}]}
{"op":"mcm","clk":"988785630","pt":1580509695560,"mc":[{"id":"1.168136214","rc":[{"batl":[[0,1.99,25],[1,2,35.84],[2,2.02,25]],"ltp":2.0,"tv":655.77,"id":17336468}]}]}
{"op":"mcm","clk":"988787625","pt":1580509729940,"mc":[{"id":"1.168136214","rc":[{"batl":[[0,1.98,7.7],[1,1.99,25],[2,2,28.22]],"ltp":2.0,"tv":655.77,"id":17336468}]}]}
{"op":"mcm","clk":"988789081","pt":1580509754064,"mc":[{"id":"1.168136214","rc":[{"trd":[[1.98,19.37]],"batb":[[0,1.98,12.3],[1,1.94,6.79],[2,1.93,60]],"batl":[[0,1.99,25],[1,2,28.22],[2,2.02,25]],"ltp":1.98,"tv":671.17,"id":17336468}],"tv":875.33}]}
{"op":"mcm","clk":"988790907","pt":1580509784778,"mc":[{"id":"1.168136214","rc":[{"batb":[[0,1.94,6.79],[1,1.93,60],[2,1.92,19.69]],"ltp":1.98,"tv":671.17,"id":17336468}]}]}
{"op":"mcm","clk":"988791434","pt":1580509794191,"mc":[{"id":"1.168136214","rc":[{"trd":[[1.99,35.18]],"batl":[[0,1.99,10]],"ltp":1.99,"tv":701.17,"id":17336468}],"tv":905.33}]}
{"op":"mcm","clk":"988811592","pt":1580509986432,"mc":[{"id":"1.168136214","rc":[{"trd":[[3.2,58.37]],"batb":[[0,3.2,8.77]],"ltp":3.2,"tv":194.02,"id":11981493}],"tv":907.79}]}
{"op":"mcm","clk":"988816018","pt":1580510055846,"mc":[{"id":"1.168136214","rc":[{"trd":[[3.2,60.07]],"batb":[[0,3.2,7.92]],"ltp":3.2,"tv":195.72,"id":11981493}],"tv":909.49}]}
{"op":"mcm","clk":"988816148","pt":1580510057958,"mc":[{"id":"1.168136214","rc":[{"trd":[[3.2,61.23]],"batb":[[0,3.2,7.34]],"ltp":3.2,"tv":196.88,"id":11981493}],"tv":910.65}]}
{"op":"mcm","clk":"988816300","pt":1580510059964,"mc":[{"id":"1.168136214","rc":[{"trd":[[3.2,62.39]],"batb":[[0,3.2,6.76]],"ltp":3.2,"tv":198.04,"id":11981493}],"tv":911.81}]}
{"op":"mcm","clk":"988817262","pt":1580510076151,"mc":[{"id":"1.168136214","rc":[{"batl":[[0,3.5,2.74],[1,3.55,2.2],[2,3.6,7]],"ltp":3.2,"tv":198.04,"id":11981493}]}]}
{"op":"mcm","clk":"988817552","pt":1580510080072,"mc":[{"id":"1.168136214","rc":[{"batl":[[1,3.55,2]],"ltp":3.2,"tv":198.04,"id":11981493}]}]}
{"op":"mcm","clk":"988818573","pt":1580510095584,"mc":[{"id":"1.168136214","rc":[{"batl":[[1,3.6,7],[2,3.7,7]],"ltp":3.2,"tv":198.04,"id":11981493}]}]}
{"op":"mcm","clk":"988818749","pt":1580510098768,"mc":[{"id":"1.168136214","rc":[{"batl":[[0,3.55,2.7]],"ltp":3.2,"tv":198.04,"id":11981493}]}]}
{"op":"mcm","clk":"988820526","pt":1580510127549,"mc":[{"id":"1.168136214","rc":[{"trd":[[3.2,62.83]],"batb":[[0,3.2,6.54]],"ltp":3.2,"tv":198.48,"id":11981493}],"tv":912.25}]}
{"op":"mcm","clk":"988820712","pt":1580510129861,"mc":[{"id":"1.168136214","rc":[{"trd":[[3.2,63.13]],"batb":[[0,3.2,6.39]],"ltp":3.2,"tv":198.78,"id":11981493}],"tv":912.55}]}
{"op":"mcm","clk":"988820839","pt":1580510131765,"mc":[{"id":"1.168136214","rc":[{"trd":[[3.2,63.43]],"batb":[[0,3.2,6.24]],"ltp":3.2,"tv":199.08,"id":11981493}],"tv":912.85}]}
{"op":"mcm","clk":"988823009","pt":1580510164218,"mc":[{"id":"1.168136214","rc":[{"batl":[[2,2.02,28.79]],"ltp":1.99,"tv":701.17,"id":17336468}]}]}
{"op":"mcm","clk":"988825115","pt":1580510197144,"mc":[{"id":"1.168136214","rc":[{"trd":[[3.2,63.63]],"batb":[[0,3.2,6.14]],"ltp":3.2,"tv":199.28,"id":11981493}],"tv":913.05}]}
{"op":"mcm","clk":"988825609","pt":1580510205331,"mc":[{"id":"1.168136214","rc":[{"batl":[[0,3.5,2],[1,3.55,2.7],[2,3.6,7]],"ltp":3.2,"tv":199.28,"id":11981493}]}]}
{"op":"mcm","clk":"988832349","pt":1580510314138,"mc":[{"id":"1.168136214","rc":[{"batb":[[0,3.2,12.39]],"ltp":3.2,"tv":199.28,"id":11981493}]}]}
{"op":"mcm","clk":"988836463","pt":1580510389410,"mc":[{"id":"1.168136214","rc":[{"batl":[[0,1.98,3.79],[1,1.99,10],[2,2,28.22]],"ltp":1.99,"tv":701.17,"id":17336468}]}]}
{"op":"mcm","clk":"988837754","pt":1580510413453,"mc":[{"id":"1.168136214","rc":[{"trd":[[3.5,4]],"batb":[[0,3.2,12.91]],"batl":[[0,3.55,2.7],[1,3.6,7],[2,3.7,7]],"ltp":3.5,"tv":203.28,"id":11981493}],"tv":917.05}]}
{"op":"mcm","clk":"988838300","pt":1580510423487,"mc":[{"id":"1.168136214","rc":[{"batb":[[0,3.25,2.67],[1,3.2,12.39],[2,3.15,6]],"ltp":3.5,"tv":203.28,"id":11981493}]}]}
{"op":"mcm","clk":"988856671","pt":1580510755331,"mc":[{"id":"1.168136214","rc":[{"trd":[[1.94,3.48],[1.96,17.2]],"batb":[[0,1.94,10.87]],"ltp":1.94,"tv":706.23,"id":17336468}],"tv":922.11}]}
{"op":"mcm","clk":"988857099","pt":1580510763054,"mc":[{"id":"1.168136214","rc":[{"batl":[[0,1.98,5.53]],"ltp":1.94,"tv":706.23,"id":17336468}]}]}
{"op":"mcm","clk":"988880656","pt":1580510992729,"mc":[{"id":"1.168136214","rc":[{"trd":[[1.94,7.48]],"batb":[[0,1.94,8.87]],"ltp":1.94,"tv":710.23,"id":17336468}],"tv":926.11}]}
{"op":"mcm","clk":"988881976","pt":1580511013077,"mc":[{"id":"1.168136214","rc":[{"batb":[[0,1.94,18.87]],"ltp":1.94,"tv":710.23,"id":17336468}]}]}
{"op":"mcm","clk":"988888640","pt":1580511133880,"mc":[{"id":"1.168136214","rc":[{"batb":[[0,3.25,2.15]],"ltp":3.5,"tv":203.28,"id":11981493}]}]}
{"op":"mcm","clk":"988899060","pt":1580511350223,"mc":[{"id":"1.168136214","rc":[{"batl":[[0,3.5,10],[1,3.55,2.7],[2,3.6,7]],"ltp":3.5,"tv":203.28,"id":11981493}]}]}
{"op":"mcm","clk":"988899940","pt":1580511368577,"mc":[{"id":"1.168136214","rc":[{"batl":[[0,3.45,2.78],[1,3.5,10]],"ltp":3.5,"tv":203.28,"id":11981493}]}]}
{"op":"mcm","clk":"988900231","pt":1580511374803,"mc":[{"id":"1.168136214","rc":[{"trd":[[3.45,5.56]],"batl":[[0,3.5,10],[1,3.6,7],[2,3.65,10]],"ltp":3.45,"tv":208.84,"id":11981493}],"tv":931.67}]}
{"op":"mcm","clk":"988905034","pt":1580511474808,"mc":[{"id":"1.168136214","rc":[{"trd":[[1.98,25.43]],"batl":[[0,1.98,2.5]],"ltp":1.98,"tv":716.29,"id":17336468}],"tv":937.73}]}
{"op":"mcm","clk":"988905089","pt":1580511476004,"mc":[{"id":"1.168136214","rc":[{"batl":[[0,1.97,3.03],[1,1.98,2.5],[2,1.99,10]],"ltp":1.98,"tv":716.29,"id":17336468}]}]}
{"op":"mcm","clk":"988905458","pt":1580511483515,"mc":[{"id":"1.168136214","rc":[{"batl":[[0,1.97,6.77],[1,1.99,10.76],[2,2,28.22]],"ltp":1.98,"tv":716.29,"id":17336468}]}]}
{"op":"mcm","clk":"988905689","pt":1580511487933,"mc":[{"id":"1.168136214","rc":[{"batb":[[0,1.94,8.87]],"ltp":1.98,"tv":716.29,"id":17336468}]}]}
{"op":"mcm","clk":"988907319","pt":1580511522590,"mc":[{"id":"1.168136214","rc":[{"trd":[[5.1,14.18]],"batb":[[0,5,1.68],[1,4.9,1.98],[2,4.5,3]],"batl":[[0,5.1,14.62],[1,8.4,2.46],[2,9,3]],"ltp":5.1,"tv":19.35,"id":12925630}],"tv":944.49}]}
{"op":"mcm","clk":"988907430","pt":1580511524900,"mc":[{"id":"1.168136214","rc":[{"trd":[[1.97,13.54],[1.98,26.94],[1.99,36.12]],"batb":[[0,1.95,8.83],[1,1.94,8.87],[2,1.93,60]],"batl":[[0,1.99,9.53],[1,2,28.22],[2,2.02,25]],"ltp":1.99,"tv":732.29,"id":17336468},{"batb":[[0,3.25,7.45]],"ltp":3.45,"tv":208.84,"id":11981493}],"tv":960.48}]}
{"op":"mcm","clk":"988907584","pt":1580511527878,"mc":[{"id":"1.168136214","rc":[{"batl":[[1,8.4,2.28]],"ltp":5.1,"tv":19.35,"id":12925630}]}]}
{"op":"mcm","clk":"988907847","pt":1580511532912,"mc":[{"id":"1.168136214","rc":[{"batb":[[0,4.9,1.98],[1,4.5,3],[2,4.4,3.01]],"batl":[[1,9,3.6],[2,11,9]],"ltp":5.1,"tv":19.35,"id":12925630}]}]}
{"op":"mcm","clk":"988910660","pt":1580511586311,"mc":[{"id":"1.168136214","rc":[{"trd":[[1.99,40.12]],"batl":[[0,1.99,7.53]],"ltp":1.99,"tv":736.29,"id":17336468}],"tv":964.48}]}
{"op":"mcm","clk":"988911582","pt":1580511603448,"mc":[{"id":"1.168136214","rc":[{"batb":[[0,1.95,18.83]],"ltp":1.99,"tv":736.29,"id":17336468}]}]}
{"op":"mcm","clk":"988911723","pt":1580511605150,"mc":[{"id":"1.168136214","rc":[{"batb":[[0,4.5,3],[1,4.4,3.01],[2,4.1,3]],"ltp":5.1,"tv":19.35,"id":12925630}]}]}
{"op":"mcm","clk":"988911731","pt":1580511605252,"mc":[{"id":"1.168136214","rc":[{"batb":[[0,4.6,1.98],[1,4.5,3],[2,4.4,3.01]],"ltp":5.1,"tv":19.35,"id":12925630}]}]}
{"op":"mcm","clk":"988912294","pt":1580511614526,"mc":[{"id":"1.168136214","rc":[{"trd":[[4.6,3.97]],"batb":[[0,4.5,3],[1,4.4,3.01],[2,4.1,3]],"batl":[[0,5.1,15.16]],"ltp":4.6,"tv":23.31,"id":12925630}],"tv":968.45}]}
{"op":"mcm","clk":"988912603","pt":1580511620664,"mc":[{"id":"1.168136214","rc":[{"batb":[[0,4.4,3.01],[1,4.3,3]],"ltp":4.6,"tv":23.31,"id":12925630}]}]}
{"op":"mcm","clk":"988917642","pt":1580511698634,"mc":[{"id":"1.168136214","rc":[{"batb":[[0,4.5,1.98],[1,4.4,3.01],[2,4.3,3]],"ltp":4.6,"tv":23.31,"id":12925630},{"batb":[[0,1.95,31.95]],"ltp":1.99,"tv":736.29,"id":17336468},{"batb":[[0,3.3,1.98],[1,3.25,7.45],[2,3.2,12.39]],"ltp":3.45,"tv":208.84,"id":11981493}]}]}
{"op":"mcm","clk":"988919096","pt":1580511723848,"mc":[{"id":"1.168136214","rc":[{"batb":[[2,3.2,6.14]],"ltp":3.45,"tv":208.84,"id":11981493}]}]}
{"op":"mcm","clk":"988932034","pt":1580511791481,"mc":[{"id":"1.168136214","rc":[{"trd":[[3.5,8]],"batl":[[0,3.5,8]],"ltp":3.5,"tv":212.84,"id":11981493}],"tv":972.45}]}
{"op":"mcm","clk":"988935004","pt":1580511850565,"mc":[{"id":"1.168136214","rc":[{"trd":[[4.6,5.04],[5.1,20.98]],"batl":[[0,5.1,11.22]],"ltp":5.1,"tv":31.19,"id":12925630}],"tv":980.32}]}
{"op":"mcm","clk":"988935223","pt":1580511854589,"mc":[{"id":"1.168136214","rc":[{"batb":[[0,4.6,3.75],[1,4.5,4.98],[2,4.4,3.01]],"ltp":5.1,"tv":31.19,"id":12925630}]}]}
{"op":"mcm","clk":"988939597","pt":1580511936060,"mc":[{"id":"1.168136214","rc":[{"batb":[[0,3.35,5.14],[1,3.3,8.04],[2,3.25,2.15]],"ltp":3.5,"tv":212.84,"id":11981493}]}]}
{"op":"mcm","clk":"988942618","pt":1580511989977,"mc":[{"id":"1.168136214","rc":[{"batb":[[0,3.4,2.06],[1,3.35,5.14],[2,3.3,1.98]],"ltp":3.5,"tv":212.84,"id":11981493}]}]}
{"op":"mcm","clk":"988946981","pt":1580512076831,"mc":[{"id":"1.168136214","rc":[{"batl":[[0,3.45,8],[1,3.5,8],[2,3.6,7]],"ltp":3.5,"tv":212.84,"id":11981493}]}]}
{"op":"mcm","clk":"988947050","pt":1580512078116,"mc":[{"id":"1.168136214","rc":[{"batl":[[0,3.5,8],[1,3.6,7],[2,3.65,10]],"ltp":3.5,"tv":212.84,"id":11981493}]}]}
{"op":"mcm","clk":"988947101","pt":1580512079042,"mc":[{"id":"1.168136214","rc":[{"trd":[[3.4,4.12]],"batb":[[0,3.35,5.14],[1,3.3,1.98],[2,3.2,6.14]],"batl":[[0,3.4,5.94],[1,3.5,8],[2,3.6,7]],"ltp":3.4,"tv":216.96,"id":11981493}],"tv":984.44}]}
{"op":"mcm","clk":"988955055","pt":1580512225966,"mc":[{"id":"1.168136214","rc":[{"batl":[[0,1.98,3.03],[1,1.99,7.53],[2,2,28.22]],"ltp":1.99,"tv":736.29,"id":17336468}]}]}
{"op":"mcm","clk":"988955270","pt":1580512230079,"mc":[{"id":"1.168136214","rc":[{"batb":[[0,4.6,4.73]],"ltp":5.1,"tv":31.19,"id":12925630},{"batb":[[0,1.96,2.35],[1,1.95,31.95],[2,1.94,8.87]],"ltp":1.99,"tv":736.29,"id":17336468},{"batb":[[0,3.35,6.52]],"ltp":3.4,"tv":216.96,"id":11981493}]}]}
{"op":"mcm","clk":"988957111","pt":1580512261096,"mc":[{"id":"1.168136214","rc":[{"batb":[[1,1.95,21.95]],"ltp":1.99,"tv":736.29,"id":17336468}]}]}
{"op":"mcm","clk":"988957955","pt":1580512275828,"mc":[{"id":"1.168136214","rc":[{"batb":[[0,4.7,22.98],[1,4.6,3.75],[2,4.5,4.98]],"ltp":5.1,"tv":31.19,"id":12925630}]}]}
{"op":"mcm","clk":"988961493","pt":1580512335053,"mc":[{"id":"1.168136214","rc":[{"trd":[[3.4,16]],"batl":[[0,3.5,8],[1,3.6,7],[2,3.65,10]],"ltp":3.4,"tv":228.84,"id":11981493}],"tv":996.33}]}
{"op":"mcm","clk":"988964269","pt":1580512382116,"mc":[{"id":"1.168136214","rc":[{"batb":[[0,4.8,3.59],[1,4.7,22.98]],"ltp":5.1,"tv":31.19,"id":12925630}]}]}
{"op":"mcm","clk":"988965881","pt":1580512409684,"mc":[{"id":"1.168136214","rc":[{"trd":[[1.96,21.91]],"batb":[[0,1.95,21.95],[1,1.94,8.87],[2,1.93,60]],"batl":[[0,1.96,47.65],[1,1.98,3.03],[2,1.99,7.53]],"ltp":1.96,"tv":740.99,"id":17336468}],"tv":1001.03}]}
{"op":"mcm","clk":"988966041","pt":1580512412880,"mc":[{"id":"1.168136214","rc":[{"trd":[[1.96,29.55]],"batl":[[0,1.96,43.83]],"ltp":1.96,"tv":748.63,"id":17336468}],"tv":1008.67}]}
{"op":"mcm","clk":"988966397","pt":1580512419115,"mc":[{"id":"1.168136214","rc":[{"batl":[[0,1.98,3.03],[1,1.99,7.53],[2,2,28.22]],"ltp":1.96,"tv":748.63,"id":17336468}]}]}
{"op":"mcm","clk":"988966818","pt":1580512426524,"mc":[{"id":"1.168136214","rc":[{"trd":[[1.95,67.87]],"batb":[[0,1.94,8.87],[1,1.93,60],[2,1.67,90.5]],"batl":[[0,1.95,21.88],[1,1.98,3.03],[2,1.99,7.53]],"ltp":1.95,"tv":792.54,"id":17336468}],"tv":1052.57}]}
{"op":"mcm","clk":"988967198","pt":1580512433451,"mc":[{"id":"1.168136214","rc":[{"batl":[[0,1.98,3.03],[1,1.99,7.53],[2,2,28.22]],"ltp":1.95,"tv":792.54,"id":17336468}]}]}
{"op":"mcm","clk":"988967589","pt":1580512439554,"mc":[{"id":"1.168136214","rc":[{"trd":[[1.94,25.22]],"batb":[[0,1.93,60],[1,1.67,90.5],[2,1.56,12.68]],"batl":[[0,1.94,13.13],[1,1.98,3.03],[2,1.99,7.53]],"ltp":1.94,"tv":810.28,"id":17336468}],"tv":1070.31}]}
{"op":"mcm","clk":"988967661","pt":1580512440945,"mc":[{"id":"1.168136214","rc":[{"batb":[[0,4.9,4.8],[1,4.8,3.59],[2,4.7,22.98]],"ltp":5.1,"tv":31.19,"id":12925630},{"trd":[[1.94,49.49]],"batl":[[0,1.94,1]],"ltp":1.94,"tv":834.54,"id":17336468},{"batb":[[0,3.4,6.92],[1,3.35,6.52],[2,3.3,1.98]],"ltp":3.4,"tv":228.84,"id":11981493}],"tv":1094.58}]}
{"op":"mcm","clk":"988967808","pt":1580512444074,"mc":[{"id":"1.168136214","rc":[{"batl":[[0,1.94,3.26]],"ltp":1.94,"tv":834.54,"id":17336468}]}]}
{"op":"mcm","clk":"988968713","pt":1580512458273,"mc":[{"id":"1.168136214","rc":[{"trd":[[3.4,29.84]],"batb":[[0,3.35,6.52],[1,3.3,1.98],[2,3.2,6.14]],"batl":[[0,3.4,3.08],[1,3.5,8],[2,3.6,7]],"ltp":3.4,"tv":242.68,"id":11981493}],"tv":1108.42}]}
{"op":"mcm","clk":"988969386","pt":1580512469789,"mc":[{"id":"1.168136214","rc":[{"batl":[[0,3.5,8],[1,3.6,7],[2,3.65,10]],"ltp":3.4,"tv":242.68,"id":11981493}]}]}
{"op":"mcm","clk":"988970027","pt":1580512479916,"mc":[{"id":"1.168136214","rc":[{"trd":[[3.35,7.86]],"batb":[[0,3.35,2.59]],"ltp":3.35,"tv":250.54,"id":11981493}],"tv":1116.28}]}
{"op":"mcm","clk":"988975184","pt":1580512562231,"mc":[{"id":"1.168136214","rc":[{"batb":[[0,5,3.44],[1,4.9,4.8]],"ltp":5.1,"tv":31.19,"id":12925630}]}]}
{"op":"mcm","clk":"988975946","pt":1580512574957,"mc":[{"id":"1.168136214","rc":[{"trd":[[5,6.89]],"batb":[[0,4.9,4.8],[1,4.7,22.98],[2,4.5,4.98]],"ltp":5.0,"tv":38.08,"id":12925630},{"trd":[[1.94,56.01]],"batl":[[0,1.98,3.03],[1,1.99,7.53],[2,2,28.22]],"ltp":1.94,"tv":841.06,"id":17336468}],"tv":1129.69}]}
{"op":"mcm","clk":"988977573","pt":1580512599518,"mc":[{"id":"1.168136214","rc":[{"batb":[[2,1.57,38.12]],"batl":[[0,1.97,29.99],[1,1.98,3.03],[2,1.99,7.53]],"ltp":1.94,"tv":841.06,"id":17336468}]}]}
{"op":"mcm","clk":"988979947","pt":1580512631929,"mc":[{"id":"1.168136214","rc":[{"batl":[[0,1.98,3.03],[1,1.99,7.53],[2,2,36.47]],"ltp":1.94,"tv":841.06,"id":17336468}]}]}
{"op":"mcm","clk":"988991372","pt":1580512664620,"mc":[{"id":"1.168136214","rc":[{"batb":[[0,1.94,30.45],[1,1.93,60],[2,1.67,90.5]],"ltp":1.94,"tv":841.06,"id":17336468}]}]}
{"op":"mcm","clk":"988999341","pt":1580512783552,"mc":[{"id":"1.168136214","rc":[{"trd":[[3.35,13.04]],"batb":[[0,3.3,1.98],[1,3.2,6.14],[2,3.15,6]],"batl":[[0,3.35,7.41],[1,3.5,8],[2,3.6,7]],"ltp":3.35,"tv":255.72,"id":11981493}],"tv":1134.87}]}
{"op":"mcm","clk":"988999598","pt":1580512786568,"mc":[{"id":"1.168136214","rc":[{"batb":[[0,1.95,8.83],[1,1.94,30.45],[2,1.93,60]],"ltp":1.94,"tv":841.06,"id":17336468}]}]}
{"op":"mcm","clk":"988999841","pt":1580512790599,"mc":[{"id":"1.168136214","rc":[{"batb":[[1,1.93,60],[2,1.67,90.5]],"batl":[[2,2,28.22]],"ltp":1.94,"tv":841.06,"id":17336468}]}]}
{"op":"mcm","clk":"989001301","pt":1580512809706,"mc":[{"id":"1.168136214","rc":[{"trd":[[4.9,8]],"batb":[[0,4.7,23.78],[1,4.5,4.98],[2,4.4,3.01]],"ltp":4.9,"tv":46.08,"id":12925630}],"tv":1142.87}]}
{"op":"mcm","clk":"989001618","pt":1580512813844,"mc":[{"id":"1.168136214","rc":[{"batb":[[0,4.8,6.15],[1,4.7,22.98],[2,4.5,4.98]],"ltp":4.9,"tv":46.08,"id":12925630},{"batb":[[0,1.96,13.1],[1,1.95,8.83],[2,1.93,60]],"batl":[[0,1.98,16.04]],"ltp":1.94,"tv":841.06,"id":17336468},{"batb":[[1,3.25,7.9],[2,3.2,6.14]],"ltp":3.35,"tv":255.72,"id":11981493}]}]}
{"op":"mcm","clk":"989001729","pt":1580512815242,"mc":[{"id":"1.168136214","rc":[{"batb":[[2,1.94,6]],"ltp":1.94,"tv":841.06,"id":17336468}]}]}
{"op":"mcm","clk":"989003294","pt":1580512837163,"mc":[{"id":"1.168136214","rc":[{"batl":[[0,1.97,13.9],[1,1.98,16.04],[2,1.99,7.53]],"ltp":1.94,"tv":841.06,"id":17336468}]}]}
{"op":"mcm","clk":"989003703","pt":1580512843151,"mc":[{"id":"1.168136214","rc":[{"trd":[[5.1,30.72]],"batl":[[0,5.1,6.35]],"ltp":5.1,"tv":55.82,"id":12925630},{"trd":[[1.97,38.74]],"batl":[[0,1.97,1.3]],"ltp":1.97,"tv":866.26,"id":17336468},{"trd":[[3.35,27.86]],"batl":[[0,3.5,8],[1,3.6,7],[2,3.65,10]],"ltp":3.35,"tv":270.54,"id":11981493}],"tv":1192.63}]}
{"op":"mcm","clk":"989006894","pt":1580512887616,"mc":[{"id":"1.168136214","rc":[{"trd":[[1.97,41.34],[1.98,44.34]],"batl":[[0,1.98,7.34],[1,1.99,7.53],[2,2,28.22]],"ltp":1.98,"tv":886.26,"id":17336468}],"tv":1212.63}]}
{"op":"mcm","clk":"989011582","pt":1580512952891,"mc":[{"id":"1.168136214","rc":[{"batb":[[0,1.97,8.75],[1,1.96,13.1]],"ltp":1.98,"tv":886.26,"id":17336468}]}]}
{"op":"mcm","clk":"989021726","pt":1580513094108,"mc":[{"id":"1.168136214","rc":[{"trd":[[1.98,50.34]],"batl":[[0,1.98,4.34]],"ltp":1.98,"tv":892.26,"id":17336468}],"tv":1218.63}]}
{"op":"mcm","clk":"989021787","pt":1580513095138,"mc":[{"id":"1.168136214","rc":[{"batl":[[0,1.98,7.37]],"ltp":1.98,"tv":892.26,"id":17336468},{"batb":[[0,3.3,7.2]],"ltp":3.35,"tv":270.54,"id":11981493}]}]}
{"op":"mcm","clk":"989022385","pt":1580513103747,"mc":[{"id":"1.168136214","rc":[{"batb":[[0,4.9,4.31],[1,4.8,5.35],[2,4.7,22.98]],"ltp":5.1,"tv":55.82,"id":12925630}]}]}
{"op":"mcm","clk":"989023524","pt":1580513120568,"mc":[{"id":"1.168136214","rc":[{"trd":[[1.98,54.34]],"batl":[[0,1.98,5.37]],"ltp":1.98,"tv":896.26,"id":17336468}],"tv":1222.63}]}
{"op":"mcm","clk":"989034996","pt":1580513296098,"mc":[{"id":"1.168136214","rc":[{"trd":[[3.5,24]],"batl":[[0,3.6,7],[1,3.65,10],[2,3.7,7]],"ltp":3.5,"tv":286.54,"id":11981493}],"tv":1238.63}]}
{"op":"mcm","clk":"989038772","pt":1580513358160,"mc":[{"id":"1.168136214","rc":[{"trd":[[1.98,65.08]],"batb":[[0,1.98,9.63],[1,1.97,8.75],[2,1.96,13.1]],"batl":[[0,1.99,7.53],[1,2,28.22],[2,2.02,25]],"ltp":1.98,"tv":907.0,"id":17336468}],"tv":1249.37}]}
{"op":"mcm","clk":"989043457","pt":1580513433967,"mc":[{"id":"1.168136214","rc":[{"trd":[[1.99,46.14]],"batl":[[0,1.99,4.52]],"ltp":1.99,"tv":913.02,"id":17336468}],"tv":1255.39}]}
{"op":"mcm","clk":"989043605","pt":1580513436139,"mc":[{"id":"1.168136214","rc":[{"batl":[[0,1.99,7.55]],"ltp":1.99,"tv":913.02,"id":17336468}]}]}
{"op":"mcm","clk":"989049802","pt":1580513535624,"mc":[{"id":"1.168136214","rc":[{"trd":[[4.9,16.63]],"batb":[[0,4.8,5.35],[1,4.7,22.98],[2,4.5,4.98]],"ltp":4.9,"tv":64.45,"id":12925630}],"tv":1264.01}]}
{"op":"mcm","clk":"989076245","pt":1580513831083,"mc":[{"id":"1.168136214","rc":[{"trd":[[1.99,54.72]],"batl":[[0,1.99,3.26]],"ltp":1.99,"tv":921.6,"id":17336468}],"tv":1272.59}]}
{"op":"mcm","clk":"989085160","pt":1580513987748,"mc":[{"id":"1.168136214","rc":[{"batb":[[0,3.35,5.97],[1,3.3,7.2],[2,3.25,7.9]],"ltp":3.5,"tv":286.54,"id":11981493}]}]}
{"op":"mcm","clk":"989092820","pt":1580514122148,"mc":[{"id":"1.168136214","rc":[{"batb":[[0,3.4,5.07],[1,3.35,5.97],[2,3.3,1.98]],"ltp":3.5,"tv":286.54,"id":11981493}]}]}
{"op":"mcm","clk":"989100614","pt":1580514256061,"mc":[{"id":"1.168136214","rc":[{"trd":[[3.6,14]],"batl":[[0,3.65,10],[1,3.7,7],[2,3.75,16]],"ltp":3.6,"tv":300.54,"id":11981493}],"tv":1286.59}]}
{"op":"mcm","clk":"989124693","pt":1580514496492,"mc":[{"id":"1.168136214","rc":[{"trd":[[4.8,10.7]],"batb":[[0,4.7,22.98],[1,4.5,4.98],[2,4.4,3.01]],"ltp":4.8,"tv":75.15,"id":12925630}],"tv":1297.3}]}
{"op":"mcm","clk":"989124906","pt":1580514499896,"mc":[{"id":"1.168136214","rc":[{"batb":[[1,4.5,1.98]],"ltp":4.8,"tv":75.15,"id":12925630}]}]}
{"op":"mcm","clk":"989125467","pt":1580514510793,"mc":[{"id":"1.168136214","rc":[{"trd":[[1.99,58.72]],"batl":[[0,1.99,1.26]],"ltp":1.99,"tv":925.6,"id":17336468}],"tv":1301.3}]}
{"op":"mcm","clk":"989125663","pt":1580514514502,"mc":[{"id":"1.168136214","rc":[{"batb":[[1,1.97,10.75]],"ltp":1.99,"tv":925.6,"id":17336468}]}]}
{"op":"mcm","clk":"989126084","pt":1580514521111,"mc":[{"id":"1.168136214","rc":[{"batb":[[0,1.98,15.63]],"ltp":1.99,"tv":925.6,"id":17336468}]}]}
{"op":"mcm","clk":"989162259","pt":1580515216750,"mc":[{"id":"1.168136214","rc":[{"trd":[[3.65,20]],"batl":[[0,3.7,7],[1,3.75,16],[2,5.8,9]],"ltp":3.65,"tv":320.54,"id":11981493}],"tv":1321.3}]}
{"op":"mcm","clk":"989178738","pt":1580515359294,"mc":[{"id":"1.168136214","rc":[{"trd":[[5.1,43.42]],"batb":[[0,5.1,1.57],[1,4.7,22.98],[2,4.5,1.98]],"batl":[[0,9,3.6],[1,11,9],[2,16,10]],"ltp":5.1,"tv":87.85,"id":12925630}],"tv":1334.0}]}
{"op":"mcm","clk":"989178908","pt":1580515363095,"mc":[{"id":"1.168136214","rc":[{"batb":[[2,4.5,4.98]],"ltp":5.1,"tv":87.85,"id":12925630}]}]}
{"op":"mcm","clk":"989178932","pt":1580515363497,"mc":[{"id":"1.168136214","rc":[{"batl":[[0,9,3.79]],"ltp":5.1,"tv":87.85,"id":12925630}]}]}
{"op":"mcm","clk":"989178999","pt":1580515364880,"mc":[{"id":"1.168136214","rc":[{"batb":[[0,3.5,1.77],[1,3.4,5.07],[2,3.35,5.97]],"ltp":3.65,"tv":320.54,"id":11981493}]}]}
{"op":"mcm","clk":"989179041","pt":1580515366022,"mc":[{"id":"1.168136214","rc":[{"batb":[[0,3.4,5.07],[1,3.35,5.97],[2,3.3,1.98]],"ltp":3.65,"tv":320.54,"id":11981493}]}]}
{"op":"mcm","clk":"989180031","pt":1580515390357,"mc":[{"id":"1.168136214","rc":[{"batb":[[2,4.6,7.39]],"batl":[[0,8.8,4.65],[1,9,3],[2,11,9]],"ltp":5.1,"tv":87.85,"id":12925630}]}]}
{"op":"mcm","clk":"989180077","pt":1580515391348,"mc":[{"id":"1.168136214","rc":[{"batl":[[0,8.6,5.37],[1,8.8,3.86],[2,9,3]],"ltp":5.1,"tv":87.85,"id":12925630}]}]}
{"op":"mcm","clk":"989181941","pt":1580515422078,"mc":[{"id":"1.168136214","rc":[{"batb":[[1,4.8,7.07],[2,4.7,22.98]],"batl":[[1,9,3],[2,11,9]],"ltp":5.1,"tv":87.85,"id":12925630}]}]}
{"op":"mcm","clk":"989181947","pt":1580515422178,"mc":[{"id":"1.168136214","rc":[{"batl":[[0,8.4,3.09],[1,8.6,4.58],[2,9,3]],"ltp":5.1,"tv":87.85,"id":12925630}]}]}
{"op":"mcm","clk":"989182371","pt":1580515429106,"mc":[{"id":"1.168136214","rc":[{"batl":[[1,9,3],[2,11,9]],"ltp":5.1,"tv":87.85,"id":12925630}]}]}
{"op":"mcm","clk":"989184107","pt":1580515453611,"mc":[{"id":"1.168136214","rc":[{"batl":[[0,8.8,2.47]],"ltp":5.1,"tv":87.85,"id":12925630}]}]}
{"op":"mcm","clk":"989185013","pt":1580515467935,"mc":[{"id":"1.168136214","rc":[{"batl":[[0,8.6,5.37],[1,8.8,1.68],[2,9,3]],"ltp":5.1,"tv":87.85,"id":12925630}]}]}
{"op":"mcm","clk":"989185580","pt":1580515479639,"mc":[{"id":"1.168136214","rc":[{"batl":[[0,3.65,2],[1,3.7,7],[2,3.75,16]],"ltp":3.65,"tv":320.54,"id":11981493}]}]}
{"op":"mcm","clk":"989185837","pt":1580515485462,"mc":[{"id":"1.168136214","rc":[{"batl":[[0,8.4,2.55],[1,8.6,4.58]],"ltp":5.1,"tv":87.85,"id":12925630}]}]}
{"op":"mcm","clk":"989185890","pt":1580515486857,"mc":[{"id":"1.168136214","rc":[{"batl":[[1,9,3],[2,11,9]],"ltp":5.1,"tv":87.85,"id":12925630}]}]}
{"op":"mcm","clk":"989187837","pt":1580515530134,"mc":[{"id":"1.168136214","rc":[{"batl":[[0,9,3.79],[1,11,9],[2,16,10]],"ltp":5.1,"tv":87.85,"id":12925630}]}]}
{"op":"mcm","clk":"989187842","pt":1580515530246,"mc":[{"id":"1.168136214","rc":[{"batl":[[0,8.8,2.47],[1,9,3],[2,11,9]],"ltp":5.1,"tv":87.85,"id":12925630}]}]}
{"op":"mcm","clk":"989188550","pt":1580515545757,"mc":[{"id":"1.168136214","rc":[{"batl":[[0,8.6,5.37],[1,8.8,1.68],[2,9,3]],"ltp":5.1,"tv":87.85,"id":12925630}]}]}
{"op":"mcm","clk":"989189565","pt":1580515565784,"mc":[{"id":"1.168136214","rc":[{"batl":[[0,8.4,2.55],[1,8.6,4.58]],"ltp":5.1,"tv":87.85,"id":12925630}]}]}
{"op":"mcm","clk":"989190585","pt":1580515584789,"mc":[{"id":"1.168136214","rc":[{"batl":[[1,9,3],[2,11,9]],"ltp":5.1,"tv":87.85,"id":12925630}]}]}
{"op":"mcm","clk":"989191224","pt":1580515598110,"mc":[{"id":"1.168136214","rc":[{"batl":[[0,8.8,2.47]],"ltp":5.1,"tv":87.85,"id":12925630}]}]}
{"op":"mcm","clk":"989191472","pt":1580515603809,"mc":[{"id":"1.168136214","rc":[{"batl":[[0,8.6,5.37],[1,8.8,1.68],[2,9,3]],"ltp":5.1,"tv":87.85,"id":12925630}]}]}
{"op":"mcm","clk":"989192900","pt":1580515629764,"mc":[{"id":"1.168136214","rc":[{"batl":[[0,8.4,2.55],[1,8.6,4.58]],"ltp":5.1,"tv":87.85,"id":12925630}]}]}
{"op":"mcm","clk":"989193732","pt":1580515642291,"mc":[{"id":"1.168136214","rc":[{"batl":[[1,9,3],[2,11,9]],"ltp":5.1,"tv":87.85,"id":12925630}]}]}
{"op":"mcm","clk":"989194803","pt":1580515661879,"mc":[{"id":"1.168136214","rc":[{"batl":[[0,8.8,2.47]],"ltp":5.1,"tv":87.85,"id":12925630}]}]}
{"op":"mcm","clk":"989195752","pt":1580515680836,"mc":[{"id":"1.168136214","rc":[{"batl":[[0,8.6,5.37],[1,8.8,1.68],[2,9,3]],"ltp":5.1,"tv":87.85,"id":12925630}]}]}
{"op":"mcm","clk":"989196346","pt":1580515693134,"mc":[{"id":"1.168136214","rc":[{"batl":[[1,9,3],[2,11,9]],"ltp":5.1,"tv":87.85,"id":12925630}]}]}
{"op":"mcm","clk":"989196351","pt":1580515693237,"mc":[{"id":"1.168136214","rc":[{"batl":[[0,8.4,2.55],[1,8.6,4.58],[2,9,3]],"ltp":5.1,"tv":87.85,"id":12925630}]}]}
{"op":"mcm","clk":"989196738","pt":1580515700746,"mc":[{"id":"1.168136214","rc":[{"batl":[[0,8.2,4.99],[1,8.4,2.36]],"ltp":5.1,"tv":87.85,"id":12925630}]}]}
{"op":"mcm","clk":"989197342","pt":1580515711052,"mc":[{"id":"1.168136214","rc":[{"batl":[[0,8.2,5.61]],"ltp":5.1,"tv":87.85,"id":12925630}]}]}
{"op":"mcm","clk":"989197370","pt":1580515711562,"mc":[{"id":"1.168136214","rc":[{"batl":[[1,8.4,1.76]],"ltp":5.1,"tv":87.85,"id":12925630}]}]}
{"op":"mcm","clk":"989197836","pt":1580515719770,"mc":[{"id":"1.168136214","rc":[{"batl":[[0,8.4,2.57],[1,9,3],[2,11,9]],"ltp":5.1,"tv":87.85,"id":12925630}]}]}
{"op":"mcm","clk":"989198100","pt":1580515724560,"mc":[{"id":"1.168136214","rc":[{"batl":[[0,8.8,2.49]],"ltp":5.1,"tv":87.85,"id":12925630}]}]}
{"op":"mcm","clk":"989198509","pt":1580515732855,"mc":[{"id":"1.168136214","rc":[{"batl":[[0,2,28.22],[1,2.02,25],[2,2.04,25]],"ltp":1.99,"tv":925.6,"id":17336468}]}]}
{"op":"mcm","clk":"989198538","pt":1580515733372,"mc":[{"id":"1.168136214","rc":[{"batb":[[0,1.99,8.65],[1,1.98,15.63],[2,1.97,2]],"ltp":1.99,"tv":925.6,"id":17336468}]}]}
{"op":"mcm","clk":"989198643","pt":1580515734866,"mc":[{"id":"1.168136214","rc":[{"trd":[[2,235.42]],"batl":[[0,2,26.44]],"ltp":2.0,"tv":929.16,"id":17336468}],"tv":1337.56}]}
{"op":"mcm","clk":"989198917","pt":1580515738988,"mc":[{"id":"1.168136214","rc":[{"batl":[[0,8.6,5.39],[1,8.8,1.68],[2,9,3]],"ltp":5.1,"tv":87.85,"id":12925630}]}]}
{"op":"mcm","clk":"989199851","pt":1580515755908,"mc":[{"id":"1.168136214","rc":[{"batl":[[0,8.4,2.57],[1,8.6,4.58]],"ltp":5.1,"tv":87.85,"id":12925630}]}]}
{"op":"mcm","clk":"989200005","pt":1580515758996,"mc":[{"id":"1.168136214","rc":[{"batl":[[1,9,3],[2,11,9]],"ltp":5.1,"tv":87.85,"id":12925630}]}]}
{"op":"mcm","clk":"989200412","pt":1580515767044,"mc":[{"id":"1.168136214","rc":[{"trd":[[1.99,76.03]],"batb":[[0,1.98,15.63],[1,1.97,2],[2,1.96,13.1]],"ltp":1.99,"tv":946.47,"id":17336468}],"tv":1354.86}]}
{"op":"mcm","clk":"989201466","pt":1580515787272,"mc":[{"id":"1.168136214","rc":[{"batl":[[0,8.8,2.49]],"ltp":5.1,"tv":87.85,"id":12925630}]}]}
{"op":"mcm","clk":"989202011","pt":1580515797377,"mc":[{"id":"1.168136214","rc":[{"batl":[[0,8.6,5.39],[1,8.8,1.68],[2,9,3]],"ltp":5.1,"tv":87.85,"id":12925630}]}]}
{"op":"mcm","clk":"989203292","pt":1580515819314,"mc":[{"id":"1.168136214","rc":[{"batl":[[0,8.4,2.57],[1,8.6,4.58]],"ltp":5.1,"tv":87.85,"id":12925630}]}]}
{"op":"mcm","clk":"989204192","pt":1580515835709,"mc":[{"id":"1.168136214","rc":[{"batl":[[1,9,3],[2,11,9]],"ltp":5.1,"tv":87.85,"id":12925630}]}]}
{"op":"mcm","clk":"989205071","pt":1580515851152,"mc":[{"id":"1.168136214","rc":[{"batl":[[0,8.8,2.49]],"ltp":5.1,"tv":87.85,"id":12925630}]}]}
{"op":"mcm","clk":"989205282","pt":1580515855079,"mc":[{"id":"1.168136214","rc":[{"batl":[[0,8.6,5.39],[1,8.8,1.68],[2,9,3]],"ltp":5.1,"tv":87.85,"id":12925630}]}]}
{"op":"mcm","clk":"989206775","pt":1580515883112,"mc":[{"id":"1.168136214","rc":[{"batl":[[0,8.4,2.57],[1,8.6,4.58]],"ltp":5.1,"tv":87.85,"id":12925630}]}]}
{"op":"mcm","clk":"989207335","pt":1580515893732,"mc":[{"id":"1.168136214","rc":[{"batl":[[1,9,3],[2,11,9]],"ltp":5.1,"tv":87.85,"id":12925630}]}]}
{"op":"mcm","clk":"989208437","pt":1580515915149,"mc":[{"id":"1.168136214","rc":[{"batl":[[0,8.8,2.49]],"ltp":5.1,"tv":87.85,"id":12925630}]}]}
{"op":"mcm","clk":"989209427","pt":1580515931968,"mc":[{"id":"1.168136214","rc":[{"batl":[[0,8.6,5.39],[1,8.8,1.68],[2,9,3]],"ltp":5.1,"tv":87.85,"id":12925630}]}]}
{"op":"mcm","clk":"989210301","pt":1580515946780,"mc":[{"id":"1.168136214","rc":[{"batl":[[0,8.4,2.57],[1,8.6,4.58]],"ltp":5.1,"tv":87.85,"id":12925630}]}]}
{"op":"mcm","clk":"989210410","pt":1580515948590,"mc":[{"id":"1.168136214","rc":[{"trd":[[2,265.71]],"batl":[[0,2,11.29]],"ltp":2.0,"tv":976.76,"id":17336468}],"tv":1385.15}]}
{"op":"mcm","clk":"989210546","pt":1580515950993,"mc":[{"id":"1.168136214","rc":[{"batl":[[1,9,3],[2,11,9]],"ltp":5.1,"tv":87.85,"id":12925630}]}]}
{"op":"mcm","clk":"989212108","pt":1580515978418,"mc":[{"id":"1.168136214","rc":[{"batl":[[0,8.8,2.49]],"ltp":5.1,"tv":87.85,"id":12925630}]}]}
{"op":"mcm","clk":"989212729","pt":1580515989668,"mc":[{"id":"1.168136214","rc":[{"batl":[[0,8.6,5.39],[1,8.8,1.68],[2,9,3]],"ltp":5.1,"tv":87.85,"id":12925630}]}]}
{"op":"mcm","clk":"989213964","pt":1580516010727,"mc":[{"id":"1.168136214","rc":[{"batl":[[0,8.4,2.57],[1,8.6,4.58]],"ltp":5.1,"tv":87.85,"id":12925630}]}]}
{"op":"mcm","clk":"989214936","pt":1580516027721,"mc":[{"id":"1.168136214","rc":[{"batl":[[1,9,3],[2,11,9]],"ltp":5.1,"tv":87.85,"id":12925630}]}]}
{"op":"mcm","clk":"989215717","pt":1580516042132,"mc":[{"id":"1.168136214","rc":[{"batl":[[0,8.8,2.49]],"ltp":5.1,"tv":87.85,"id":12925630}]}]}
{"op":"mcm","clk":"989216003","pt":1580516046970,"mc":[{"id":"1.168136214","rc":[{"batl":[[0,8.6,5.39],[1,8.8,1.68],[2,9,3]],"ltp":5.1,"tv":87.85,"id":12925630}]}]}
{"op":"mcm","clk":"989217472","pt":1580516073398,"mc":[{"id":"1.168136214","rc":[{"batl":[[0,8.4,2.57],[1,8.6,4.58]],"ltp":5.1,"tv":87.85,"id":12925630}]}]}
{"op":"mcm","clk":"989218175","pt":1580516086126,"mc":[{"id":"1.168136214","rc":[{"batl":[[1,9,3],[2,11,9]],"ltp":5.1,"tv":87.85,"id":12925630}]}]}
{"op":"mcm","clk":"989219424","pt":1580516104730,"mc":[{"id":"1.168136214","rc":[{"batl":[[0,8.8,2.49]],"ltp":5.1,"tv":87.85,"id":12925630}]}]}
{"op":"mcm","clk":"989219490","pt":1580516105815,"mc":[{"id":"1.168136214","rc":[{"batl":[[0,8.6,5.39],[1,8.8,1.68],[2,9,3]],"ltp":5.1,"tv":87.85,"id":12925630}]}]}
{"op":"mcm","clk":"989221377","pt":1580516135552,"mc":[{"id":"1.168136214","rc":[{"batl":[[0,8.4,2.57],[1,8.6,4.58]],"ltp":5.1,"tv":87.85,"id":12925630}]}]}
{"op":"mcm","clk":"989221851","pt":1580516143439,"mc":[{"id":"1.168136214","rc":[{"batl":[[1,9,3],[2,11,9]],"ltp":5.1,"tv":87.85,"id":12925630}]}]}
{"op":"mcm","clk":"989223282","pt":1580516167272,"mc":[{"id":"1.168136214","rc":[{"batl":[[0,8.8,2.49]],"ltp":5.1,"tv":87.85,"id":12925630}]}]}
{"op":"mcm","clk":"989223869","pt":1580516177199,"mc":[{"id":"1.168136214","rc":[{"trd":[[3.65,24]],"batb":[[0,3.4,5.59]],"batl":[[0,3.7,7],[1,3.75,16],[2,5.8,9]],"ltp":3.65,"tv":324.54,"id":11981493}],"tv":1389.15}]}
{"op":"mcm","clk":"989224153","pt":1580516181796,"mc":[{"id":"1.168136214","rc":[{"batl":[[0,8.6,5.39],[1,8.8,1.68],[2,9,3]],"ltp":5.1,"tv":87.85,"id":12925630}]}]}
{"op":"mcm","clk":"989225238","pt":1580516198537,"mc":[{"id":"1.168136214","rc":[{"batl":[[0,8.4,2.57],[1,8.6,4.58]],"ltp":5.1,"tv":87.85,"id":12925630}]}]}
{"op":"mcm","clk":"989225352","pt":1580516200758,"mc":[{"id":"1.168136214","rc":[{"batl":[[1,9,3],[2,11,9]],"ltp":5.1,"tv":87.85,"id":12925630}]}]}
{"op":"mcm","clk":"989226887","pt":1580516229968,"mc":[{"id":"1.168136214","rc":[{"batl":[[0,8.8,2.49]],"ltp":5.1,"tv":87.85,"id":12925630},{"batb":[[1,3.3,1.98],[2,3.25,7.9]],"ltp":3.65,"tv":324.54,"id":11981493}]}]}
{"op":"mcm","clk":"989227465","pt":1580516238865,"mc":[{"id":"1.168136214","rc":[{"batl":[[0,8.6,5.39],[1,8.8,1.68],[2,9,3]],"ltp":5.1,"tv":87.85,"id":12925630}]}]}
{"op":"mcm","clk":"989238288","pt":1580516260115,"mc":[{"id":"1.168136214","rc":[{"trd":[[2,288.29],[2.02,157.26],[2.04,16.61]],"batl":[[0,2.04,23.43],[1,2.06,31.09],[2,2.08,10.95]],"ltp":2.04,"tv":1052.48,"id":17336468}],"tv":1464.88}]}
{"op":"mcm","clk":"989238335","pt":1580516261097,"mc":[{"id":"1.168136214","rc":[{"batl":[[0,8.4,2.57],[1,8.6,4.58]],"ltp":5.1,"tv":87.85,"id":12925630}]}]}
{"op":"mcm","clk":"989238651","pt":1580516266941,"mc":[{"id":"1.168136214","rc":[{"batb":[[0,1.99,22.72],[1,1.98,15.63],[2,1.97,2]],"ltp":2.04,"tv":1052.48,"id":17336468}]}]}
{"op":"mcm","clk":"989238702","pt":1580516268023,"mc":[{"id":"1.168136214","rc":[{"trd":[[2.04,62.05]],"batl":[[0,2.06,31.8],[1,2.08,10.95],[2,3.95,19.89]],"ltp":2.04,"tv":1097.92,"id":17336468}],"tv":1510.31}]}
{"op":"mcm","clk":"989238750","pt":1580516268804,"mc":[{"id":"1.168136214","rc":[{"trd":[[2,304.33]],"batb":[[0,2,4.94],[1,1.99,22.72],[2,1.98,15.63]],"batl":[[0,2.06,25.71],[1,2.08,14.34]],"ltp":2.0,"tv":1113.96,"id":17336468},{"trd":[[3.4,33.44],[3.65,25.04]],"batb":[[0,3.4,3.27]],"ltp":3.4,"tv":329.17,"id":11981493}],"tv":1530.99}]}
{"op":"mcm","clk":"989239216","pt":1580516277014,"mc":[{"id":"1.168136214","rc":[{"batl":[[1,9,3],[2,11,9]],"ltp":5.1,"tv":87.85,"id":12925630}]}]}
{"op":"mcm","clk":"989239235","pt":1580516277429,"mc":[{"id":"1.168136214","rc":[{"trd":[[2.04,63.47],[2.06,83.83]],"batl":[[0,2.06,2.99],[1,2.08,10.95]],"ltp":2.06,"tv":1159.4,"id":17336468}],"tv":1576.43}]}
{"op":"mcm","clk":"989239634","pt":1580516283957,"mc":[{"id":"1.168136214","rc":[{"trd":[[2,314.21]],"batb":[[0,1.99,22.72],[1,1.98,15.63],[2,1.97,2]],"ltp":2.0,"tv":1169.28,"id":17336468},{"trd":[[3.4,33.86],[3.45,9.8]],"batb":[[0,3.4,3.06]],"ltp":3.4,"tv":333.83,"id":11981493}],"tv":1590.97}]}
{"op":"mcm","clk":"989240153","pt":1580516293056,"mc":[{"id":"1.168136214","rc":[{"batl":[[0,8.8,2.49]],"ltp":5.1,"tv":87.85,"id":12925630}]}]}
{"op":"mcm","clk":"989240335","pt":1580516295851,"mc":[{"id":"1.168136214","rc":[{"batl":[[0,8.6,5.39],[1,8.8,1.68],[2,9,3]],"ltp":5.1,"tv":87.85,"id":12925630}]}]}
{"op":"mcm","clk":"989241915","pt":1580516324154,"mc":[{"id":"1.168136214","rc":[{"batl":[[0,8.4,2.57],[1,8.6,4.58]],"ltp":5.1,"tv":87.85,"id":12925630}]}]}
{"op":"mcm","clk":"989242506","pt":1580516334372,"mc":[{"id":"1.168136214","rc":[{"batl":[[1,9,3],[2,11,9]],"ltp":5.1,"tv":87.85,"id":12925630}]}]}
{"op":"mcm","clk":"989243815","pt":1580516355259,"mc":[{"id":"1.168136214","rc":[{"batl":[[0,8.8,2.49]],"ltp":5.1,"tv":87.85,"id":12925630}]}]}
{"op":"mcm","clk":"989244907","pt":1580516372978,"mc":[{"id":"1.168136214","rc":[{"batl":[[0,8.6,5.39],[1,8.8,1.68],[2,9,3]],"ltp":5.1,"tv":87.85,"id":12925630}]}]}
{"op":"mcm","clk":"989245761","pt":1580516387034,"mc":[{"id":"1.168136214","rc":[{"batl":[[0,8.4,2.57],[1,8.6,4.58]],"ltp":5.1,"tv":87.85,"id":12925630}]}]}
{"op":"mcm","clk":"989245960","pt":1580516390126,"mc":[{"id":"1.168136214","rc":[{"batl":[[0,3.65,2],[1,3.7,7],[2,3.75,16]],"ltp":3.4,"tv":333.83,"id":11981493}]}]}
{"op":"mcm","clk":"989246081","pt":1580516391932,"mc":[{"id":"1.168136214","rc":[{"batl":[[1,9,3],[2,11,9]],"ltp":5.1,"tv":87.85,"id":12925630}]}]}
{"op":"mcm","clk":"989247938","pt":1580516418717,"mc":[{"id":"1.168136214","rc":[{"batl":[[0,8.8,2.49]],"ltp":5.1,"tv":87.85,"id":12925630}]}]}
{"op":"mcm","clk":"989248828","pt":1580516431100,"mc":[{"id":"1.168136214","rc":[{"batl":[[0,8.6,5.39],[1,8.8,1.68],[2,9,3]],"ltp":5.1,"tv":87.85,"id":12925630}]}]}
{"op":"mcm","clk":"989250093","pt":1580516450117,"mc":[{"id":"1.168136214","rc":[{"batl":[[0,8.4,2.57],[1,8.6,4.58]],"ltp":5.1,"tv":87.85,"id":12925630}]}]}
{"op":"mcm","clk":"989251433","pt":1580516470051,"mc":[{"id":"1.168136214","rc":[{"batl":[[1,9,3],[2,11,9]],"ltp":5.1,"tv":87.85,"id":12925630}]}]}
{"op":"mcm","clk":"989252169","pt":1580516481488,"mc":[{"id":"1.168136214","rc":[{"batl":[[0,8.8,2.49]],"ltp":5.1,"tv":87.85,"id":12925630}]}]}
{"op":"mcm","clk":"989252711","pt":1580516488993,"mc":[{"id":"1.168136214","rc":[{"batl":[[0,8.6,5.39],[1,8.8,1.68],[2,9,3]],"ltp":5.1,"tv":87.85,"id":12925630}]}]}
{"op":"mcm","clk":"989253412","pt":1580516499793,"mc":[{"id":"1.168136214","rc":[{"trd":[[2.06,89.81],[2.08,178.18]],"batl":[[0,2.08,10.91],[1,3.95,19.89],[2,16,2]],"ltp":2.08,"tv":1175.34,"id":17336468}],"tv":1597.03}]}
{"op":"mcm","clk":"989254217","pt":1580516512624,"mc":[{"id":"1.168136214","rc":[{"batl":[[0,8.4,2.57],[1,8.6,4.58]],"ltp":5.1,"tv":87.85,"id":12925630}]}]}
{"op":"mcm","clk":"989255326","pt":1580516527821,"mc":[{"id":"1.168136214","rc":[{"batl":[[1,9,3],[2,11,9]],"ltp":5.1,"tv":87.85,"id":12925630}]}]}
{"op":"mcm","clk":"989256425","pt":1580516543738,"mc":[{"id":"1.168136214","rc":[{"batl":[[0,8.8,2.49]],"ltp":5.1,"tv":87.85,"id":12925630}]}]}
{"op":"mcm","clk":"989256673","pt":1580516546840,"mc":[{"id":"1.168136214","rc":[{"batl":[[0,8.6,5.39],[1,8.8,1.68],[2,9,3]],"ltp":5.1,"tv":87.85,"id":12925630}]}]}
{"op":"mcm","clk":"989258631","pt":1580516574853,"mc":[{"id":"1.168136214","rc":[{"batl":[[0,8.4,2.57],[1,8.6,4.58]],"ltp":5.1,"tv":87.85,"id":12925630}]}]}
{"op":"mcm","clk":"989259413","pt":1580516585800,"mc":[{"id":"1.168136214","rc":[{"batl":[[1,9,3],[2,11,9]],"ltp":5.1,"tv":87.85,"id":12925630}]}]}
{"op":"mcm","clk":"989259893","pt":1580516592836,"mc":[{"id":"1.168136214","rc":[{"batb":[[0,1.99,41.65]],"ltp":2.08,"tv":1175.34,"id":17336468}]}]}
{"op":"mcm","clk":"989259952","pt":1580516593764,"mc":[{"id":"1.168136214","rc":[{"batb":[[2,1.97,20.93]],"ltp":2.08,"tv":1175.34,"id":17336468}]}]}
{"op":"mcm","clk":"989260882","pt":1580516606448,"mc":[{"id":"1.168136214","rc":[{"batl":[[0,8.8,2.49]],"ltp":5.1,"tv":87.85,"id":12925630}]}]}
{"op":"mcm","clk":"989261200","pt":1580516611470,"mc":[{"id":"1.168136214","rc":[{"batb":[[0,2,3],[1,1.99,41.65],[2,1.98,15.63]],"ltp":2.08,"tv":1175.34,"id":17336468}]}]}
{"op":"mcm","clk":"989262054","pt":1580516624027,"mc":[{"id":"1.168136214","rc":[{"batl":[[0,8.6,5.39],[1,8.8,1.68],[2,9,3]],"ltp":5.1,"tv":87.85,"id":12925630}]}]}
{"op":"mcm","clk":"989262945","pt":1580516638129,"mc":[{"id":"1.168136214","rc":[{"batl":[[0,8.4,2.57],[1,8.6,4.58]],"ltp":5.1,"tv":87.85,"id":12925630}]}]}
{"op":"mcm","clk":"989263212","pt":1580516642823,"mc":[{"id":"1.168136214","rc":[{"batl":[[1,9,3],[2,11,9]],"ltp":5.1,"tv":87.85,"id":12925630}]}]}
{"op":"mcm","clk":"989264790","pt":1580516669765,"mc":[{"id":"1.168136214","rc":[{"batl":[[0,8.8,2.49]],"ltp":5.1,"tv":87.85,"id":12925630}]}]}
{"op":"mcm","clk":"989265013","pt":1580516673029,"mc":[{"id":"1.168136214","rc":[{"batb":[[1,1.99,22.72]],"ltp":2.08,"tv":1175.34,"id":17336468}]}]}
{"op":"mcm","clk":"989265275","pt":1580516676962,"mc":[{"id":"1.168136214","rc":[{"batb":[[0,1.99,22.72],[1,1.98,15.63],[2,1.97,2]],"ltp":2.08,"tv":1175.34,"id":17336468}]}]}
{"op":"mcm","clk":"989265665","pt":1580516682746,"mc":[{"id":"1.168136214","rc":[{"batl":[[0,8.6,5.39],[1,8.8,1.68],[2,9,3]],"ltp":5.1,"tv":87.85,"id":12925630}]}]}
{"op":"mcm","clk":"989266960","pt":1580516701379,"mc":[{"id":"1.168136214","rc":[{"batl":[[0,8.4,2.57],[1,8.6,4.58]],"ltp":5.1,"tv":87.85,"id":12925630}]}]}
{"op":"mcm","clk":"989268146","pt":1580516722106,"mc":[{"id":"1.168136214","rc":[{"batl":[[1,9,3],[2,11,9]],"ltp":5.1,"tv":87.85,"id":12925630}]}]}
{"op":"mcm","clk":"989268839","pt":1580516733104,"mc":[{"id":"1.168136214","rc":[{"batl":[[0,8.8,2.49]],"ltp":5.1,"tv":87.85,"id":12925630},{"batb":[[0,2,1],[1,1.99,22.72],[2,1.98,15.63]],"ltp":2.08,"tv":1175.34,"id":17336468}]}]}
{"op":"mcm","clk":"989269356","pt":1580516741119,"mc":[{"id":"1.168136214","rc":[{"batl":[[0,8.6,5.39],[1,8.8,1.68],[2,9,3]],"ltp":5.1,"tv":87.85,"id":12925630}]}]}
{"op":"mcm","clk":"989271004","pt":1580516764898,"mc":[{"id":"1.168136214","rc":[{"batl":[[0,8.4,2.57],[1,8.6,4.58]],"ltp":5.1,"tv":87.85,"id":12925630}]}]}
{"op":"mcm","clk":"989272066","pt":1580516780093,"mc":[{"id":"1.168136214","rc":[{"batl":[[1,9,3],[2,11,9]],"ltp":5.1,"tv":87.85,"id":12925630}]}]}
{"op":"mcm","clk":"989273130","pt":1580516797117,"mc":[{"id":"1.168136214","rc":[{"batl":[[0,8.8,2.49]],"ltp":5.1,"tv":87.85,"id":12925630}]}]}
{"op":"mcm","clk":"989273251","pt":1580516799140,"mc":[{"id":"1.168136214","rc":[{"batl":[[0,8.6,5.39],[1,8.8,1.68],[2,9,3]],"ltp":5.1,"tv":87.85,"id":12925630}]}]}
{"op":"mcm","clk":"989275227","pt":1580516829979,"mc":[{"id":"1.168136214","rc":[{"batl":[[0,8.4,2.57],[1,8.6,4.58]],"ltp":5.1,"tv":87.85,"id":12925630}]}]}
{"op":"mcm","clk":"989275689","pt":1580516837661,"mc":[{"id":"1.168136214","rc":[{"batl":[[1,9,3],[2,11,9]],"ltp":5.1,"tv":87.85,"id":12925630}]}]}
{"op":"mcm","clk":"989277256","pt":1580516861992,"mc":[{"id":"1.168136214","rc":[{"batl":[[0,9,3.81],[1,11,9],[2,16,10]],"ltp":5.1,"tv":87.85,"id":12925630}]}]}
{"op":"mcm","clk":"989277298","pt":1580516862607,"mc":[{"id":"1.168136214","rc":[{"batl":[[0,8.8,2.49],[1,9,3],[2,11,9]],"ltp":5.1,"tv":87.85,"id":12925630}]}]}
{"op":"mcm","clk":"989278147","pt":1580516877225,"mc":[{"id":"1.168136214","rc":[{"batl":[[0,8.6,5.39],[1,8.8,1.68],[2,9,3]],"ltp":5.1,"tv":87.85,"id":12925630}]}]}
{"op":"mcm","clk":"989279167","pt":1580516895033,"mc":[{"id":"1.168136214","rc":[{"batl":[[0,8.4,2.57],[1,8.6,4.58]],"ltp":5.1,"tv":87.85,"id":12925630}]}]}
{"op":"mcm","clk":"989279274","pt":1580516896746,"mc":[{"id":"1.168136214","rc":[{"batl":[[1,9,3],[2,11,9]],"ltp":5.1,"tv":87.85,"id":12925630}]}]}
{"op":"mcm","clk":"989280251","pt":1580516914083,"mc":[{"id":"1.168136214","rc":[{"batb":[[1,4.9,3.24],[2,4.8,7.07]],"ltp":5.1,"tv":87.85,"id":12925630}]}]}
{"op":"mcm","clk":"989281031","pt":1580516927099,"mc":[{"id":"1.168136214","rc":[{"batb":[[1,5,2.97],[2,4.9,3.24]],"batl":[[0,8.8,2.49]],"ltp":5.1,"tv":87.85,"id":12925630}]}]}
{"op":"mcm","clk":"989281325","pt":1580516931071,"mc":[{"id":"1.168136214","rc":[{"batb":[[0,3.45,4.91],[1,3.4,3.06],[2,3.3,1.98]],"batl":[[0,3.5,2],[1,3.65,2],[2,3.7,7]],"ltp":3.4,"tv":333.83,"id":11981493}]}]}
{"op":"mcm","clk":"989281370","pt":1580516931586,"mc":[{"id":"1.168136214","rc":[{"trd":[[3.4,39.98],[3.45,19.62]],"batb":[[0,3.3,1.98],[1,3.25,7.9],[2,3.2,6.14]],"ltp":3.4,"tv":349.77,"id":11981493}],"tv":1612.97}]}
{"op":"mcm","clk":"989281628","pt":1580516935085,"mc":[{"id":"1.168136214","rc":[{"batl":[[0,8.6,5.39],[1,8.8,1.68],[2,9,3]],"ltp":5.1,"tv":87.85,"id":12925630},{"batb":[[0,2,9.61]],"ltp":2.08,"tv":1175.34,"id":17336468}]}]}
{"op":"mcm","clk":"989282327","pt":1580516945493,"mc":[{"id":"1.168136214","rc":[{"batb":[[2,4.9,3]],"ltp":5.1,"tv":87.85,"id":12925630}]}]}
{"op":"mcm","clk":"989283358","pt":1580516960133,"mc":[{"id":"1.168136214","rc":[{"batb":[[0,5.2,3],[1,5.1,1.57],[2,5,2.97]],"batl":[[0,8.4,2.57],[1,8.6,4.58]],"ltp":5.1,"tv":87.85,"id":12925630}]}]}
{"op":"mcm","clk":"989284301","pt":1580516974262,"mc":[{"id":"1.168136214","rc":[{"batl":[[1,9,3],[2,11,9]],"ltp":5.1,"tv":87.85,"id":12925630}]}]}
{"op":"mcm","clk":"989284741","pt":1580516980779,"mc":[{"id":"1.168136214","rc":[{"batl":[[1,3.7,7],[2,3.75,16]],"ltp":3.4,"tv":349.77,"id":11981493}]}]}
{"op":"mcm","clk":"989285555","pt":1580516992411,"mc":[{"id":"1.168136214","rc":[{"batl":[[0,8.8,2.49]],"ltp":5.1,"tv":87.85,"id":12925630}]}]}
{"op":"mcm","clk":"989285648","pt":1580516993612,"mc":[{"id":"1.168136214","rc":[{"batl":[[0,8.6,5.39],[1,8.8,1.68],[2,9,3]],"ltp":5.1,"tv":87.85,"id":12925630}]}]}
{"op":"mcm","clk":"989288078","pt":1580517025148,"mc":[{"id":"1.168136214","rc":[{"batl":[[1,9,3],[2,11,9]],"ltp":5.1,"tv":87.85,"id":12925630}]}]}
{"op":"mcm","clk":"989288141","pt":1580517025878,"mc":[{"id":"1.168136214","rc":[{"batl":[[0,8.4,2.57],[1,8.6,4.58],[2,9,3]],"ltp":5.1,"tv":87.85,"id":12925630}]}]}
{"op":"mcm","clk":"989288650","pt":1580517032951,"mc":[{"id":"1.168136214","rc":[{"batl":[[1,9,3],[2,11,9]],"ltp":5.1,"tv":87.85,"id":12925630}]}]}
{"op":"mcm","clk":"989290415","pt":1580517057909,"mc":[{"id":"1.168136214","rc":[{"batl":[[0,8.8,2.49]],"ltp":5.1,"tv":87.85,"id":12925630}]}]}
{"op":"mcm","clk":"989291409","pt":1580517071827,"mc":[{"id":"1.168136214","rc":[{"batl":[[0,8.6,5.39],[1,8.8,1.68],[2,9,3]],"ltp":5.1,"tv":87.85,"id":12925630}]}]}
{"op":"mcm","clk":"989292957","pt":1580517090435,"mc":[{"id":"1.168136214","rc":[{"batl":[[0,8.4,2.57],[1,8.6,4.58]],"ltp":5.1,"tv":87.85,"id":12925630}]}]}
{"op":"mcm","clk":"989293052","pt":1580517091676,"mc":[{"id":"1.168136214","rc":[{"batl":[[1,9,3],[2,11,9]],"ltp":5.1,"tv":87.85,"id":12925630}]}]}
{"op":"mcm","clk":"989294596","pt":1580517109481,"mc":[{"id":"1.168136214","rc":[{"batb":[[0,5.2,6.31],[1,5.1,22.57]],"ltp":5.1,"tv":87.85,"id":12925630}]}]}
{"op":"mcm","clk":"989295732","pt":1580517122414,"mc":[{"id":"1.168136214","rc":[{"batl":[[0,8.8,2.49]],"ltp":5.1,"tv":87.85,"id":12925630}]}]}
{"op":"mcm","clk":"989296402","pt":1580517130628,"mc":[{"id":"1.168136214","rc":[{"batl":[[0,8.6,5.39],[1,8.8,1.68],[2,9,3]],"ltp":5.1,"tv":87.85,"id":12925630}]}]}
{"op":"mcm","clk":"989297057","pt":1580517137749,"mc":[{"id":"1.168136214","rc":[{"trd":[[3.5,28]],"batb":[[0,3.3,2.5]],"batl":[[0,3.65,9.43]],"ltp":3.5,"tv":353.77,"id":11981493}],"tv":1616.97}]}
{"op":"mcm","clk":"989297454","pt":1580517142550,"mc":[{"id":"1.168136214","rc":[{"batl":[[0,3.6,2],[1,3.65,9.43],[2,3.7,7]],"ltp":3.5,"tv":353.77,"id":11981493}]}]}
{"op":"mcm","clk":"989307821","pt":1580517153978,"mc":[{"id":"1.168136214","rc":[{"batl":[[0,8.4,2.57],[1,8.6,4.58]],"ltp":5.1,"tv":87.85,"id":12925630}]}]}
{"op":"mcm","clk":"989308746","pt":1580517167500,"mc":[{"id":"1.168136214","rc":[{"batb":[[0,5.2,7.99]],"ltp":5.1,"tv":87.85,"id":12925630},{"batb":[[0,2,11.29]],"ltp":2.08,"tv":1175.34,"id":17336468},{"batb":[[1,3.25,9.58]],"ltp":3.5,"tv":353.77,"id":11981493}]}]}
{"op":"mcm","clk":"989308830","pt":1580517169099,"mc":[{"id":"1.168136214","rc":[{"batl":[[1,9,3],[2,11,9]],"ltp":5.1,"tv":87.85,"id":12925630}]}]}
{"op":"mcm","clk":"989309914","pt":1580517185919,"mc":[{"id":"1.168136214","rc":[{"batl":[[0,8.8,2.49]],"ltp":5.1,"tv":87.85,"id":12925630}]}]}
{"op":"mcm","clk":"989310136","pt":1580517189228,"mc":[{"id":"1.168136214","rc":[{"batl":[[0,8.6,5.39],[1,8.8,1.68],[2,9,3]],"ltp":5.1,"tv":87.85,"id":12925630}]}]}
{"op":"mcm","clk":"989311559","pt":1580517210907,"mc":[{"id":"1.168136214","rc":[{"batl":[[1,2.24,31.01],[2,3.95,19.17]],"ltp":2.08,"tv":1175.34,"id":17336468}]}]}
{"op":"mcm","clk":"989311710","pt":1580517213029,"mc":[{"id":"1.168136214","rc":[{"batl":[[2,2.36,30.29]],"ltp":2.08,"tv":1175.34,"id":17336468}]}]}
{"op":"mcm","clk":"989312032","pt":1580517217997,"mc":[{"id":"1.168136214","rc":[{"batl":[[0,8.4,2.57],[1,8.6,4.58]],"ltp":5.1,"tv":87.85,"id":12925630}]}]}
{"op":"mcm","clk":"989312702","pt":1580517228121,"mc":[{"id":"1.168136214","rc":[{"batl":[[1,9,3],[2,11,9]],"ltp":5.1,"tv":87.85,"id":12925630}]}]}
{"op":"mcm","clk":"989314088","pt":1580517250066,"mc":[{"id":"1.168136214","rc":[{"batl":[[0,8.8,2.49]],"ltp":5.1,"tv":87.85,"id":12925630}]}]}
{"op":"mcm","clk":"989315170","pt":1580517266986,"mc":[{"id":"1.168136214","rc":[{"batl":[[0,8.6,5.39],[1,8.8,1.68],[2,9,3]],"ltp":5.1,"tv":87.85,"id":12925630}]}]}
{"op":"mcm","clk":"989316180","pt":1580517282904,"mc":[{"id":"1.168136214","rc":[{"batl":[[0,8.4,2.57],[1,8.6,4.58]],"ltp":5.1,"tv":87.85,"id":12925630}]}]}
{"op":"mcm","clk":"989316415","pt":1580517286716,"mc":[{"id":"1.168136214","rc":[{"batl":[[1,9,3],[2,11,9]],"ltp":5.1,"tv":87.85,"id":12925630}]}]}
{"op":"mcm","clk":"989318275","pt":1580517316141,"mc":[{"id":"1.168136214","rc":[{"batl":[[0,8.8,2.49]],"ltp":5.1,"tv":87.85,"id":12925630}]}]}
{"op":"mcm","clk":"989318957","pt":1580517326068,"mc":[{"id":"1.168136214","rc":[{"batl":[[0,8.6,5.39],[1,8.8,1.68],[2,9,3]],"ltp":5.1,"tv":87.85,"id":12925630}]}]}
{"op":"mcm","clk":"989319404","pt":1580517333092,"mc":[{"id":"1.168136214","rc":[{"trd":[[1.99,79.05],[2,336.8]],"batb":[[0,2,1.68],[1,1.99,21.21]],"ltp":1.99,"tv":1200.93,"id":17336468},{"trd":[[3.3,13.36],[3.5,29.04]],"batb":[[0,3.25,10.1],[1,3.2,6.14],[2,3.15,6]],"batl":[[1,3.7,7],[2,3.75,16]],"ltp":3.3,"tv":368.17,"id":11981493}],"tv":1656.96}]}
{"op":"mcm","clk":"989319558","pt":1580517335680,"mc":[{"id":"1.168136214","rc":[{"batl":[[0,2.08,11.88]],"ltp":1.99,"tv":1200.93,"id":17336468}]}]}
{"op":"mcm","clk":"989320349","pt":1580517347931,"mc":[{"id":"1.168136214","rc":[{"batl":[[0,8.4,2.57],[1,8.6,4.58]],"ltp":5.1,"tv":87.85,"id":12925630}]}]}
{"op":"mcm","clk":"989320878","pt":1580517356415,"mc":[{"id":"1.168136214","rc":[{"batl":[[0,3.65,11.43]],"ltp":3.3,"tv":368.17,"id":11981493}]}]}
{"op":"mcm","clk":"989321508","pt":1580517364428,"mc":[{"id":"1.168136214","rc":[{"batl":[[1,9,3],[2,11,9]],"ltp":5.1,"tv":87.85,"id":12925630}]}]}
{"op":"mcm","clk":"989322547","pt":1580517380557,"mc":[{"id":"1.168136214","rc":[{"batl":[[0,8.8,2.49]],"ltp":5.1,"tv":87.85,"id":12925630}]}]}
{"op":"mcm","clk":"989322782","pt":1580517384060,"mc":[{"id":"1.168136214","rc":[{"batl":[[0,8.6,5.39],[1,8.8,1.68],[2,9,3]],"ltp":5.1,"tv":87.85,"id":12925630}]}]}
{"op":"mcm","clk":"989324893","pt":1580517413914,"mc":[{"id":"1.168136214","rc":[{"batl":[[0,8.4,2.57],[1,8.6,4.58]],"ltp":5.1,"tv":87.85,"id":12925630}]}]}
{"op":"mcm","clk":"989325417","pt":1580517421933,"mc":[{"id":"1.168136214","rc":[{"batl":[[1,9,3],[2,11,9]],"ltp":5.1,"tv":87.85,"id":12925630}]}]}
{"op":"mcm","clk":"989327013","pt":1580517445856,"mc":[{"id":"1.168136214","rc":[{"batl":[[0,8.8,2.49]],"ltp":5.1,"tv":87.85,"id":12925630}]}]}
{"op":"mcm","clk":"989327882","pt":1580517460746,"mc":[{"id":"1.168136214","rc":[{"batl":[[0,8.6,5.39],[1,8.8,1.68],[2,9,3]],"ltp":5.1,"tv":87.85,"id":12925630}]}]}
{"op":"mcm","clk":"989328907","pt":1580517477413,"mc":[{"id":"1.168136214","rc":[{"batl":[[0,8.4,2.57],[1,8.6,4.58]],"ltp":5.1,"tv":87.85,"id":12925630}]}]}
{"op":"mcm","clk":"989329089","pt":1580517479978,"mc":[{"id":"1.168136214","rc":[{"batl":[[1,9,3],[2,11,9]],"ltp":5.1,"tv":87.85,"id":12925630}]}]}
{"op":"mcm","clk":"989330967","pt":1580517510120,"mc":[{"id":"1.168136214","rc":[{"batl":[[0,8.8,2.49]],"ltp":5.1,"tv":87.85,"id":12925630}]}]}
{"op":"mcm","clk":"989331499","pt":1580517518980,"mc":[{"id":"1.168136214","rc":[{"batl":[[0,8.6,5.39],[1,8.8,1.68],[2,9,3]],"ltp":5.1,"tv":87.85,"id":12925630}]}]}
{"op":"mcm","clk":"989332903","pt":1580517542106,"mc":[{"id":"1.168136214","rc":[{"batl":[[1,9,3],[2,11,9]],"ltp":5.1,"tv":87.85,"id":12925630}]}]}
{"op":"mcm","clk":"989332940","pt":1580517542569,"mc":[{"id":"1.168136214","rc":[{"batl":[[0,8.4,2.57],[1,8.6,4.58],[2,9,3]],"ltp":5.1,"tv":87.85,"id":12925630}]}]}
{"op":"mcm","clk":"989333900","pt":1580517558128,"mc":[{"id":"1.168136214","rc":[{"batl":[[1,9,3],[2,11,9]],"ltp":5.1,"tv":87.85,"id":12925630}]}]}
{"op":"mcm","clk":"989335057","pt":1580517575460,"mc":[{"id":"1.168136214","rc":[{"batl":[[0,8.8,2.49]],"ltp":5.1,"tv":87.85,"id":12925630}]}]}
{"op":"mcm","clk":"989335181","pt":1580517577372,"mc":[{"id":"1.168136214","rc":[{"batl":[[0,8.6,5.39],[1,8.8,1.68],[2,9,3]],"ltp":5.1,"tv":87.85,"id":12925630}]}]}
{"op":"mcm","clk":"989337296","pt":1580517609139,"mc":[{"id":"1.168136214","rc":[{"batl":[[0,8.4,2.57],[1,8.6,4.58]],"ltp":5.1,"tv":87.85,"id":12925630}]}]}
{"op":"mcm","clk":"989337874","pt":1580517617148,"mc":[{"id":"1.168136214","rc":[{"batl":[[1,9,3],[2,11,9]],"ltp":5.1,"tv":87.85,"id":12925630}]}]}
{"op":"mcm","clk":"989339240","pt":1580517640086,"mc":[{"id":"1.168136214","rc":[{"batl":[[0,8.8,2.49]],"ltp":5.1,"tv":87.85,"id":12925630}]}]}
{"op":"mcm","clk":"989340161","pt":1580517655971,"mc":[{"id":"1.168136214","rc":[{"batl":[[0,8.6,5.39],[1,8.8,1.68],[2,9,3]],"ltp":5.1,"tv":87.85,"id":12925630}]}]}
{"op":"mcm","clk":"989341412","pt":1580517674326,"mc":[{"id":"1.168136214","rc":[{"batl":[[0,8.4,2.57],[1,8.6,4.58]],"ltp":5.1,"tv":87.85,"id":12925630}]}]}
{"op":"mcm","clk":"989341564","pt":1580517676695,"mc":[{"id":"1.168136214","rc":[{"batl":[[1,9,3],[2,11,9]],"ltp":5.1,"tv":87.85,"id":12925630}]}]}
{"op":"mcm","clk":"989343555","pt":1580517708096,"mc":[{"id":"1.168136214","rc":[{"batl":[[0,8.8,2.49]],"ltp":5.1,"tv":87.85,"id":12925630}]}]}
{"op":"mcm","clk":"989344001","pt":1580517715484,"mc":[{"id":"1.168136214","rc":[{"batl":[[0,8.6,5.39],[1,8.8,1.68],[2,9,3]],"ltp":5.1,"tv":87.85,"id":12925630}]}]}
{"op":"mcm","clk":"989345587","pt":1580517740514,"mc":[{"id":"1.168136214","rc":[{"batl":[[0,8.4,2.57],[1,8.6,4.58]],"ltp":5.1,"tv":87.85,"id":12925630}]}]}
{"op":"mcm","clk":"989346514","pt":1580517754929,"mc":[{"id":"1.168136214","rc":[{"batl":[[1,9,3],[2,11,9]],"ltp":5.1,"tv":87.85,"id":12925630}]}]}
{"op":"mcm","clk":"989347603","pt":1580517773311,"mc":[{"id":"1.168136214","rc":[{"batl":[[0,8.8,2.49]],"ltp":5.1,"tv":87.85,"id":12925630}]}]}
{"op":"mcm","clk":"989347667","pt":1580517774441,"mc":[{"id":"1.168136214","rc":[{"batl":[[0,8.6,5.39],[1,8.8,1.68],[2,9,3]],"ltp":5.1,"tv":87.85,"id":12925630}]}]}
{"op":"mcm","clk":"989349416","pt":1580517805010,"mc":[{"id":"1.168136214","rc":[{"batl":[[0,8.4,2.57],[1,8.6,4.58]],"ltp":5.1,"tv":87.85,"id":12925630}]}]}
{"op":"mcm","clk":"989349944","pt":1580517814110,"mc":[{"id":"1.168136214","rc":[{"batl":[[1,9,3],[2,11,9]],"ltp":5.1,"tv":87.85,"id":12925630}]}]}
{"op":"mcm","clk":"989351213","pt":1580517835917,"mc":[{"id":"1.168136214","rc":[{"batl":[[0,8.8,2.49]],"ltp":5.1,"tv":87.85,"id":12925630}]}]}
{"op":"mcm","clk":"989352323","pt":1580517853779,"mc":[{"id":"1.168136214","rc":[{"batl":[[0,8.6,5.39],[1,8.8,1.68],[2,9,3]],"ltp":5.1,"tv":87.85,"id":12925630}]}]}
{"op":"mcm","clk":"989353143","pt":1580517866996,"mc":[{"id":"1.168136214","rc":[{"batl":[[0,8.4,2.57],[1,8.6,4.58]],"ltp":5.1,"tv":87.85,"id":12925630}]}]}
{"op":"mcm","clk":"989353601","pt":1580517874991,"mc":[{"id":"1.168136214","rc":[{"batl":[[1,9,3],[2,11,9]],"ltp":5.1,"tv":87.85,"id":12925630}]}]}
{"op":"mcm","clk":"989355024","pt":1580517898056,"mc":[{"id":"1.168136214","rc":[{"batl":[[0,8.8,2.49]],"ltp":5.1,"tv":87.85,"id":12925630}]}]}
{"op":"mcm","clk":"989355716","pt":1580517914024,"mc":[{"id":"1.168136214","rc":[{"batl":[[0,8.6,5.39],[1,8.8,1.68],[2,9,3]],"ltp":5.1,"tv":87.85,"id":12925630}]}]}
{"op":"mcm","clk":"989356414","pt":1580517929663,"mc":[{"id":"1.168136214","rc":[{"batl":[[0,8.4,2.57],[1,8.6,4.58]],"ltp":5.1,"tv":87.85,"id":12925630}]}]}
{"op":"mcm","clk":"989356607","pt":1580517933796,"mc":[{"id":"1.168136214","rc":[{"batl":[[1,9,3],[2,11,9]],"ltp":5.1,"tv":87.85,"id":12925630}]}]}
{"op":"mcm","clk":"989357898","pt":1580517961015,"mc":[{"id":"1.168136214","rc":[{"batl":[[0,8.8,2.49]],"ltp":5.1,"tv":87.85,"id":12925630}]}]}
{"op":"mcm","clk":"989358508","pt":1580517972846,"mc":[{"id":"1.168136214","rc":[{"batl":[[0,8.6,5.39],[1,8.8,1.68],[2,9,3]],"ltp":5.1,"tv":87.85,"id":12925630}]}]}
{"op":"mcm","clk":"989359455","pt":1580517992738,"mc":[{"id":"1.168136214","rc":[{"batl":[[0,8.4,2.57],[1,8.6,4.58]],"ltp":5.1,"tv":87.85,"id":12925630}]}]}
{"op":"mcm","clk":"989360482","pt":1580518012091,"mc":[{"id":"1.168136214","rc":[{"batl":[[1,9,3],[2,11,9]],"ltp":5.1,"tv":87.85,"id":12925630}]}]}
{"op":"mcm","clk":"989361274","pt":1580518025113,"mc":[{"id":"1.168136214","rc":[{"batl":[[0,8.8,2.49]],"ltp":5.1,"tv":87.85,"id":12925630}]}]}
{"op":"mcm","clk":"989361710","pt":1580518032088,"mc":[{"id":"1.168136214","rc":[{"batl":[[0,8.6,5.39],[1,8.8,1.68],[2,9,3]],"ltp":5.1,"tv":87.85,"id":12925630}]}]}
{"op":"mcm","clk":"989372669","pt":1580518057125,"mc":[{"id":"1.168136214","rc":[{"batl":[[1,9,3],[2,11,9]],"ltp":5.1,"tv":87.85,"id":12925630}]}]}
{"op":"mcm","clk":"989372720","pt":1580518058145,"mc":[{"id":"1.168136214","rc":[{"batl":[[0,8.4,2.57],[1,8.6,4.58],[2,9,3]],"ltp":5.1,"tv":87.85,"id":12925630}]}]}
{"op":"mcm","clk":"989373454","pt":1580518070964,"mc":[{"id":"1.168136214","rc":[{"batl":[[1,9,3],[2,11,9]],"ltp":5.1,"tv":87.85,"id":12925630}]}]}
{"op":"mcm","clk":"989374457","pt":1580518088679,"mc":[{"id":"1.168136214","rc":[{"batl":[[0,8.8,2.49]],"ltp":5.1,"tv":87.85,"id":12925630}]}]}
{"op":"mcm","clk":"989374583","pt":1580518090952,"mc":[{"id":"1.168136214","rc":[{"batl":[[0,8.6,5.39],[1,8.8,1.68],[2,9,3]],"ltp":5.1,"tv":87.85,"id":12925630}]}]}
{"op":"mcm","clk":"989376316","pt":1580518120103,"mc":[{"id":"1.168136214","rc":[{"batl":[[1,9,3],[2,11,9]],"ltp":5.1,"tv":87.85,"id":12925630}]}]}
{"op":"mcm","clk":"989376358","pt":1580518120823,"mc":[{"id":"1.168136214","rc":[{"batl":[[0,8.4,2.57],[1,8.6,4.58],[2,9,3]],"ltp":5.1,"tv":87.85,"id":12925630}]}]}
{"op":"mcm","clk":"989376788","pt":1580518128609,"mc":[{"id":"1.168136214","rc":[{"batl":[[1,9,3],[2,11,9]],"ltp":5.1,"tv":87.85,"id":12925630}]}]}
{"op":"mcm","clk":"989378237","pt":1580518152032,"mc":[{"id":"1.168136214","rc":[{"batl":[[0,8.8,2.49]],"ltp":5.1,"tv":87.85,"id":12925630}]}]}
{"op":"mcm","clk":"989379252","pt":1580518168082,"mc":[{"id":"1.168136214","rc":[{"batl":[[0,8.6,5.39],[1,8.8,1.68],[2,9,3]],"ltp":5.1,"tv":87.85,"id":12925630}]}]}
{"op":"mcm","clk":"989380209","pt":1580518183581,"mc":[{"id":"1.168136214","rc":[{"batl":[[0,8.4,2.57],[1,8.6,4.58]],"ltp":5.1,"tv":87.85,"id":12925630}]}]}
{"op":"mcm","clk":"989380448","pt":1580518187008,"mc":[{"id":"1.168136214","rc":[{"batl":[[1,9,3],[2,11,9]],"ltp":5.1,"tv":87.85,"id":12925630}]}]}
{"op":"mcm","clk":"989382294","pt":1580518215137,"mc":[{"id":"1.168136214","rc":[{"batl":[[0,9,3.81],[1,11,9],[2,16,10]],"ltp":5.1,"tv":87.85,"id":12925630}]}]}
{"op":"mcm","clk":"989382312","pt":1580518215547,"mc":[{"id":"1.168136214","rc":[{"batl":[[0,8.8,2.49],[1,9,3],[2,11,9]],"ltp":5.1,"tv":87.85,"id":12925630}]}]}
{"op":"mcm","clk":"989383047","pt":1580518227860,"mc":[{"id":"1.168136214","rc":[{"batl":[[0,8.6,5.39],[1,8.8,1.68],[2,9,3]],"ltp":5.1,"tv":87.85,"id":12925630}]}]}
{"op":"mcm","clk":"989384138","pt":1580518246999,"mc":[{"id":"1.168136214","rc":[{"batl":[[0,8.4,2.57],[1,8.6,4.58]],"ltp":5.1,"tv":87.85,"id":12925630}]}]}
{"op":"mcm","clk":"989385257","pt":1580518266659,"mc":[{"id":"1.168136214","rc":[{"batl":[[1,9,3],[2,11,9]],"ltp":5.1,"tv":87.85,"id":12925630}]}]}
{"op":"mcm","clk":"989385912","pt":1580518278380,"mc":[{"id":"1.168136214","rc":[{"batl":[[0,8.8,2.49]],"ltp":5.1,"tv":87.85,"id":12925630}]}]}
{"op":"mcm","clk":"989386300","pt":1580518285769,"mc":[{"id":"1.168136214","rc":[{"batl":[[0,8.6,5.39],[1,8.8,1.68],[2,9,3]],"ltp":5.1,"tv":87.85,"id":12925630}]}]}
{"op":"mcm","clk":"989387771","pt":1580518309533,"mc":[{"id":"1.168136214","rc":[{"batl":[[0,8.4,2.57],[1,8.6,4.58]],"ltp":5.1,"tv":87.85,"id":12925630}]}]}
{"op":"mcm","clk":"989388574","pt":1580518325643,"mc":[{"id":"1.168136214","rc":[{"batl":[[1,9,3],[2,11,9]],"ltp":5.1,"tv":87.85,"id":12925630}]}]}
{"op":"mcm","clk":"989388835","pt":1580518330853,"mc":[{"id":"1.168136214","rc":[{"batl":[[0,8.2,19.74],[1,8.4,1.76],[2,9,3]],"ltp":5.1,"tv":87.85,"id":12925630}]}]}
{"op":"mcm","clk":"989389233","pt":1580518338796,"mc":[{"id":"1.168136214","rc":[{"trd":[[3.65,47.9]],"batl":[[0,3.7,7],[1,3.75,16],[2,5.8,9]],"ltp":3.65,"tv":391.03,"id":11981493}],"tv":1679.82}]}
{"op":"mcm","clk":"989389345","pt":1580518340920,"mc":[{"id":"1.168136214","rc":[{"batl":[[0,8,2.67],[1,8.2,18.93]],"ltp":5.1,"tv":87.85,"id":12925630}]}]}
{"op":"mcm","clk":"989389594","pt":1580518345130,"mc":[{"id":"1.168136214","rc":[{"batl":[[0,7.8,5.24],[1,8,2.48],[2,8.2,18.93]],"ltp":5.1,"tv":87.85,"id":12925630}]}]}
{"op":"mcm","clk":"989390179","pt":1580518354030,"mc":[{"id":"1.168136214","rc":[{"batl":[[1,8,1.86]],"ltp":5.1,"tv":87.85,"id":12925630}]}]}
{"op":"mcm","clk":"989390221","pt":1580518354645,"mc":[{"id":"1.168136214","rc":[{"batl":[[0,7.8,5.9]],"ltp":5.1,"tv":87.85,"id":12925630}]}]}
{"op":"mcm","clk":"989391186","pt":1580518372138,"mc":[{"id":"1.168136214","rc":[{"batl":[[0,7.6,2.79],[1,7.8,5.05]],"ltp":5.1,"tv":87.85,"id":12925630}]}]}
{"op":"mcm","clk":"989391782","pt":1580518383062,"mc":[{"id":"1.168136214","rc":[{"batl":[[1,8.2,18.93],[2,9,3]],"ltp":5.1,"tv":87.85,"id":12925630}]}]}
{"op":"mcm","clk":"989391959","pt":1580518385895,"mc":[{"id":"1.168136214","rc":[{"batl":[[1,8,25],[2,8.2,18.93]],"ltp":5.1,"tv":87.85,"id":12925630}]}]}
{"op":"mcm","clk":"989392545","pt":1580518397291,"mc":[{"id":"1.168136214","rc":[{"batl":[[0,2.08,36.88]],"ltp":1.99,"tv":1200.93,"id":17336468}]}]}
{"op":"mcm","clk":"989392609","pt":1580518398678,"mc":[{"id":"1.168136214","rc":[{"batl":[[1,2.2,25],[2,2.24,31.01]],"ltp":1.99,"tv":1200.93,"id":17336468}]}]}
{"op":"mcm","clk":"989392867","pt":1580518403063,"mc":[{"id":"1.168136214","rc":[{"batl":[[0,7.8,2.76]],"ltp":5.1,"tv":87.85,"id":12925630}]}]}
{"op":"mcm","clk":"989393932","pt":1580518421200,"mc":[{"id":"1.168136214","rc":[{"batl":[[0,7.6,6.03],[1,7.8,1.91],[2,8,25]],"ltp":5.1,"tv":87.85,"id":12925630}]}]}
{"op":"mcm","clk":"989394737","pt":1580518434662,"mc":[{"id":"1.168136214","rc":[{"batl":[[0,7.4,2.17],[1,7.6,5.84]],"ltp":5.1,"tv":87.85,"id":12925630}]}]}
{"op":"mcm","clk":"989394817","pt":1580518436151,"mc":[{"id":"1.168136214","rc":[{"batb":[[0,3.3,2.73],[1,3.25,9.58],[2,3.2,6.14]],"ltp":3.65,"tv":391.03,"id":11981493}]}]}
{"op":"mcm","clk":"989401050","pt":1580518549494,"mc":[{"id":"1.168136214","rc":[{"batl":[[2,7.8,18.93]],"ltp":5.1,"tv":87.85,"id":12925630}]}]}
{"op":"mcm","clk":"989408588","pt":1580518684927,"mc":[{"id":"1.168136214","rc":[{"trd":[[5.1,51.74],[5.2,17.38]],"batb":[[0,5.1,18.41],[1,5,2.97],[2,4.7,22.98]],"ltp":5.1,"tv":112.15,"id":12925630},{"trd":[[1.99,85.48],[2,340.16]],"batb":[[0,1.99,17.99],[1,1.98,15.63],[2,1.97,2]],"batl":[[0,2.06,13.65],[1,2.08,35.91],[2,2.2,25]],"ltp":1.99,"tv":1210.73,"id":17336468}],"tv":1713.92}]}
{"op":"mcm","clk":"989408603","pt":1580518685236,"mc":[{"id":"1.168136214","rc":[{"batb":[[0,5.2,1.71],[1,5.1,18.41],[2,5,2.97]],"ltp":5.1,"tv":112.15,"id":12925630},{"batb":[[0,2,1.68],[1,1.99,17.99],[2,1.98,15.63]],"ltp":1.99,"tv":1210.73,"id":17336468}]}]}
{"op":"mcm","clk":"989409347","pt":1580518699065,"mc":[{"id":"1.168136214","rc":[{"trd":[[2,343.5]],"batb":[[0,1.99,18],[1,1.98,15.63],[2,1.97,2]],"ltp":2.0,"tv":1214.08,"id":17336468}],"tv":1717.26}]}
{"op":"mcm","clk":"989410740","pt":1580518722926,"mc":[{"id":"1.168136214","rc":[{"batl":[[0,2.06,12.68]],"ltp":2.0,"tv":1214.08,"id":17336468}]}]}
{"op":"mcm","clk":"989412244","pt":1580518747945,"mc":[{"id":"1.168136214","rc":[{"batb":[[0,3.3,8.79]],"ltp":3.65,"tv":391.03,"id":11981493}]}]}
{"op":"mcm","clk":"989420291","pt":1580518862050,"mc":[{"id":"1.168136214","rc":[{"batb":[[0,2,8.62],[1,1.99,17.99],[2,1.98,15.63]],"ltp":2.0,"tv":1214.08,"id":17336468}]}]}
{"op":"mcm","clk":"989420677","pt":1580518866866,"mc":[{"id":"1.168136214","rc":[{"trd":[[2,343.52]],"batb":[[0,2,8.61]],"ltp":2.0,"tv":1214.09,"id":17336468}],"tv":1717.28}]}
{"op":"mcm","clk":"989420768","pt":1580518867949,"mc":[{"id":"1.168136214","rc":[{"batb":[[0,2,10.29]],"ltp":2.0,"tv":1214.09,"id":17336468}]}]}
{"op":"mcm","clk":"989437465","pt":1580518969768,"mc":[{"id":"1.168136214","rc":[{"batb":[[1,1.98,15.63],[2,1.97,2]],"ltp":2.0,"tv":1214.09,"id":17336468}]}]}
{"op":"mcm","clk":"989437729","pt":1580518973862,"mc":[{"id":"1.168136214","rc":[{"batb":[[0,2,8.61]],"ltp":2.0,"tv":1214.09,"id":17336468}]}]}
{"op":"mcm","clk":"989438079","pt":1580518979570,"mc":[{"id":"1.168136214","rc":[{"batb":[[1,1.99,1.68],[2,1.98,15.63]],"ltp":2.0,"tv":1214.09,"id":17336468}]}]}
{"op":"mcm","clk":"989440114","pt":1580519013099,"mc":[{"id":"1.168136214","rc":[{"batb":[[0,5.2,5.02]],"ltp":5.1,"tv":112.15,"id":12925630}]}]}
{"op":"mcm","clk":"989441242","pt":1580519031932,"mc":[{"id":"1.168136214","rc":[{"trd":[[5.2,27.42]],"batb":[[0,5.1,18.41],[1,5,2.97],[2,4.7,22.98]],"ltp":5.2,"tv":122.19,"id":12925630},{"trd":[[2,360.74]],"batb":[[0,1.99,1.68],[1,1.98,15.63],[2,1.97,2]],"batl":[[0,2,1.67]],"ltp":2.0,"tv":1231.32,"id":17336468},{"trd":[[3.3,14.4]],"batb":[[0,3.3,2.56]],"ltp":3.3,"tv":392.07,"id":11981493}],"tv":1745.59}]}
{"op":"mcm","clk":"989441545","pt":1580519036468,"mc":[{"id":"1.168136214","rc":[{"batl":[[2,5.1,1.74]],"ltp":3.3,"tv":392.07,"id":11981493}]}]}
{"op":"mcm","clk":"989459287","pt":1580519298614,"mc":[{"id":"1.168136214","rc":[{"trd":[[3.7,14]],"batl":[[0,3.75,16],[1,5.1,1.74],[2,5.8,9]],"ltp":3.7,"tv":406.07,"id":11981493}],"tv":1759.59}]}
{"op":"mcm","clk":"989462462","pt":1580519342882,"mc":[{"id":"1.168136214","rc":[{"batb":[[0,3.3,7.78]],"ltp":3.7,"tv":406.07,"id":11981493}]}]}
{"op":"mcm","clk":"989487320","pt":1580519728760,"mc":[{"id":"1.168136214","rc":[{"batl":[[1,2.06,3],[2,2.08,35.91]],"ltp":2.0,"tv":1231.32,"id":17336468}]}]}
{"op":"mcm","clk":"989492842","pt":1580519825992,"mc":[{"id":"1.168136214","rc":[{"batl":[[0,7.4,3.17]],"ltp":5.2,"tv":122.19,"id":12925630}]}]}
{"op":"mcm","clk":"989493662","pt":1580519841169,"mc":[{"id":"1.168136214","rc":[{"batl":[[1,7.8,19.59],[2,8,25]],"ltp":5.2,"tv":122.19,"id":12925630}]}]}
{"op":"mcm","clk":"989504873","pt":1580519868115,"mc":[{"id":"1.168136214","rc":[{"batl":[[0,7.4,1.19],[1,7.6,2.62],[2,7.8,18.93]],"ltp":5.2,"tv":122.19,"id":12925630}]}]}
{"op":"mcm","clk":"989505630","pt":1580519879443,"mc":[{"id":"1.168136214","rc":[{"batl":[[0,7.4,6.51]],"ltp":5.2,"tv":122.19,"id":12925630}]}]}
{"op":"mcm","clk":"989506115","pt":1580519886142,"mc":[{"id":"1.168136214","rc":[{"batl":[[0,7.4,7.2],[1,7.6,1.96]],"ltp":5.2,"tv":122.19,"id":12925630}]}]}
{"op":"mcm","clk":"989506998","pt":1580519899339,"mc":[{"id":"1.168136214","rc":[{"batl":[[0,7.2,2.95],[1,7.4,6.32]],"ltp":5.2,"tv":122.19,"id":12925630}]}]}
{"op":"mcm","clk":"989508235","pt":1580519917771,"mc":[{"id":"1.168136214","rc":[{"batl":[[1,7.4,1]],"ltp":5.2,"tv":122.19,"id":12925630}]}]}
{"op":"mcm","clk":"989509109","pt":1580519931094,"mc":[{"id":"1.168136214","rc":[{"batl":[[0,7.4,1.88],[1,7.6,1.96]],"ltp":5.2,"tv":122.19,"id":12925630}]}]}
{"op":"mcm","clk":"989509490","pt":1580519937015,"mc":[{"id":"1.168136214","rc":[{"batl":[[0,7.4,7.2]],"ltp":5.2,"tv":122.19,"id":12925630}]}]}
{"op":"mcm","clk":"989511213","pt":1580519963068,"mc":[{"id":"1.168136214","rc":[{"batl":[[0,7.2,2.95],[1,7.4,6.32]],"ltp":5.2,"tv":122.19,"id":12925630}]}]}
{"op":"mcm","clk":"989512107","pt":1580519976363,"mc":[{"id":"1.168136214","rc":[{"batl":[[1,7.4,1]],"ltp":5.2,"tv":122.19,"id":12925630}]}]}
{"op":"mcm","clk":"989513202","pt":1580519994077,"mc":[{"id":"1.168136214","rc":[{"batl":[[0,7.4,1.88],[1,7.6,1.96]],"ltp":5.2,"tv":122.19,"id":12925630}]}]}
{"op":"mcm","clk":"989513307","pt":1580519995581,"mc":[{"id":"1.168136214","rc":[{"batl":[[0,7.4,7.2]],"ltp":5.2,"tv":122.19,"id":12925630}]}]}
{"op":"mcm","clk":"989513860","pt":1580520004113,"mc":[{"id":"1.168136214","rc":[{"batb":[[0,3.35,10.19],[1,3.3,7.78],[2,3.25,9.58]],"batl":[[0,3.6,1.51],[1,3.75,16],[2,5.1,1.74]],"ltp":3.7,"tv":406.07,"id":11981493}]}]}
{"op":"mcm","clk":"989513900","pt":1580520004633,"mc":[{"id":"1.168136214","rc":[{"batl":[[0,3.75,16],[1,5.1,1.74],[2,5.8,9]],"ltp":3.7,"tv":406.07,"id":11981493}]}]}
{"op":"mcm","clk":"989514349","pt":1580520011146,"mc":[{"id":"1.168136214","rc":[{"batb":[[2,3.25,7.9]],"ltp":3.7,"tv":406.07,"id":11981493}]}]}
{"op":"mcm","clk":"989514408","pt":1580520012028,"mc":[{"id":"1.168136214","rc":[{"batl":[[0,3.6,1.51],[1,3.75,16],[2,5.1,1.74]],"ltp":3.7,"tv":406.07,"id":11981493}]}]}
{"op":"mcm","clk":"989514444","pt":1580520012543,"mc":[{"id":"1.168136214","rc":[{"batl":[[0,3.75,16],[1,5.1,1.74],[2,5.8,9]],"ltp":3.7,"tv":406.07,"id":11981493}]}]}
{"op":"mcm","clk":"989514803","pt":1580520018045,"mc":[{"id":"1.168136214","rc":[{"batb":[[0,3.35,11.87]],"ltp":3.7,"tv":406.07,"id":11981493}]}]}
{"op":"mcm","clk":"989515308","pt":1580520025752,"mc":[{"id":"1.168136214","rc":[{"batl":[[0,7.2,2.95],[1,7.4,6.32]],"ltp":5.2,"tv":122.19,"id":12925630}]}]}
{"op":"mcm","clk":"989515806","pt":1580520033757,"mc":[{"id":"1.168136214","rc":[{"batl":[[1,7.4,1]],"ltp":5.2,"tv":122.19,"id":12925630}]}]}
{"op":"mcm","clk":"989517317","pt":1580520057156,"mc":[{"id":"1.168136214","rc":[{"batl":[[0,7.4,1.88],[1,7.8,18.93],[2,8,25]],"ltp":5.2,"tv":122.19,"id":12925630}]}]}
{"op":"mcm","clk":"989517324","pt":1580520057260,"mc":[{"id":"1.168136214","rc":[{"batl":[[1,7.6,1.96],[2,7.8,18.93]],"ltp":5.2,"tv":122.19,"id":12925630}]}]}
{"op":"mcm","clk":"989518364","pt":1580520073406,"mc":[{"id":"1.168136214","rc":[{"batl":[[0,7.4,7.2]],"ltp":5.2,"tv":122.19,"id":12925630}]}]}
{"op":"mcm","clk":"989519307","pt":1580520088731,"mc":[{"id":"1.168136214","rc":[{"batl":[[0,7.2,2.95],[1,7.4,6.32]],"ltp":5.2,"tv":122.19,"id":12925630}]}]}
{"op":"mcm","clk":"989519556","pt":1580520092846,"mc":[{"id":"1.168136214","rc":[{"batl":[[1,7.4,1]],"ltp":5.2,"tv":122.19,"id":12925630}]}]}
{"op":"mcm","clk":"989521332","pt":1580520120388,"mc":[{"id":"1.168136214","rc":[{"batl":[[0,7.4,1.88],[1,7.6,1.96]],"ltp":5.2,"tv":122.19,"id":12925630}]}]}
{"op":"mcm","clk":"989522116","pt":1580520132373,"mc":[{"id":"1.168136214","rc":[{"batl":[[0,7.4,7.2]],"ltp":5.2,"tv":122.19,"id":12925630}]}]}
{"op":"mcm","clk":"989522303","pt":1580520135168,"mc":[{"id":"1.168136214","rc":[{"batl":[[1,2.08,35.91],[2,2.2,25]],"ltp":2.0,"tv":1231.32,"id":17336468}]}]}
{"op":"mcm","clk":"989522415","pt":1580520137188,"mc":[{"id":"1.168136214","rc":[{"batl":[[1,2.06,4],[2,2.08,35.91]],"ltp":2.0,"tv":1231.32,"id":17336468}]}]}
{"op":"mcm","clk":"989522938","pt":1580520145596,"mc":[{"id":"1.168136214","rc":[{"trd":[[2,364.08]],"batb":[[0,2,1.36],[1,1.99,1.68],[2,1.98,15.63]],"batl":[[0,2.06,4],[1,2.08,35.91],[2,2.2,25]],"ltp":2.0,"tv":1234.66,"id":17336468}],"tv":1762.93}]}
{"op":"mcm","clk":"989523311","pt":1580520151800,"mc":[{"id":"1.168136214","rc":[{"batl":[[1,7.8,18.93],[2,8,25]],"ltp":5.2,"tv":122.19,"id":12925630}]}]}
{"op":"mcm","clk":"989523357","pt":1580520152473,"mc":[{"id":"1.168136214","rc":[{"batl":[[0,7.2,2.95],[1,7.4,1],[2,7.8,18.93]],"ltp":5.2,"tv":122.19,"id":12925630}]}]}
{"op":"mcm","clk":"989523496","pt":1580520154791,"mc":[{"id":"1.168136214","rc":[{"batb":[[0,3.4,5.07],[1,3.35,11.87],[2,3.3,2.56]],"ltp":3.7,"tv":406.07,"id":11981493}]}]}
{"op":"mcm","clk":"989523836","pt":1580520160720,"mc":[{"id":"1.168136214","rc":[{"batb":[[0,1.99,1.68],[1,1.98,15.63],[2,1.97,2]],"ltp":2.0,"tv":1234.66,"id":17336468}]}]}
{"op":"mcm","clk":"989524028","pt":1580520164122,"mc":[{"id":"1.168136214","rc":[{"batb":[[0,1.99,16.83]],"ltp":2.0,"tv":1234.66,"id":17336468}]}]}
{"op":"mcm","clk":"989524236","pt":1580520167787,"mc":[{"id":"1.168136214","rc":[{"batb":[[0,2,4.2],[1,1.99,16.83],[2,1.98,15.63]],"batl":[[2,2.18,15.14]],"ltp":2.0,"tv":1234.66,"id":17336468}]}]}
{"op":"mcm","clk":"989524265","pt":1580520168299,"mc":[{"id":"1.168136214","rc":[{"batb":[[0,1.99,16.83],[1,1.98,15.63],[2,1.97,2]],"ltp":2.0,"tv":1234.66,"id":17336468}]}]}
{"op":"mcm","clk":"989524380","pt":1580520170211,"mc":[{"id":"1.168136214","rc":[{"batl":[[2,2.16,15.14]],"ltp":2.0,"tv":1234.66,"id":17336468}]}]}
{"op":"mcm","clk":"989524788","pt":1580520177226,"mc":[{"id":"1.168136214","rc":[{"batl":[[0,2.08,35.91],[1,2.16,15.14],[2,2.18,15.14]],"ltp":2.0,"tv":1234.66,"id":17336468}]}]}
{"op":"mcm","clk":"989525141","pt":1580520183012,"mc":[{"id":"1.168136214","rc":[{"batl":[[0,7.4,1.88],[1,7.6,1.96]],"ltp":5.2,"tv":122.19,"id":12925630}]}]}
{"op":"mcm","clk":"989525652","pt":1580520191733,"mc":[{"id":"1.168136214","rc":[{"batl":[[0,7.4,7.2]],"ltp":5.2,"tv":122.19,"id":12925630}]}]}
{"op":"mcm","clk":"989526963","pt":1580520214061,"mc":[{"id":"1.168136214","rc":[{"batl":[[1,7.8,18.93],[2,8,25]],"ltp":5.2,"tv":122.19,"id":12925630}]}]}
{"op":"mcm","clk":"989526970","pt":1580520214165,"mc":[{"id":"1.168136214","rc":[{"batl":[[0,7.2,2.95],[1,7.4,6.32],[2,7.8,18.93]],"ltp":5.2,"tv":122.19,"id":12925630}]}]}
{"op":"mcm","clk":"989527939","pt":1580520230318,"mc":[{"id":"1.168136214","rc":[{"batl":[[1,7.4,1]],"ltp":5.2,"tv":122.19,"id":12925630}]}]}
{"op":"mcm","clk":"989528896","pt":1580520245490,"mc":[{"id":"1.168136214","rc":[{"batl":[[0,7.4,1.88],[1,7.6,1.96]],"ltp":5.2,"tv":122.19,"id":12925630}]}]}
{"op":"mcm","clk":"989529173","pt":1580520250098,"mc":[{"id":"1.168136214","rc":[{"batl":[[0,7.4,7.2]],"ltp":5.2,"tv":122.19,"id":12925630}]}]}
{"op":"mcm","clk":"989530833","pt":1580520277155,"mc":[{"id":"1.168136214","rc":[{"batl":[[0,7.2,2.95],[1,7.4,6.32]],"ltp":5.2,"tv":122.19,"id":12925630}]}]}
{"op":"mcm","clk":"989531548","pt":1580520289040,"mc":[{"id":"1.168136214","rc":[{"batl":[[1,7.4,1]],"ltp":5.2,"tv":122.19,"id":12925630}]}]}
{"op":"mcm","clk":"989532847","pt":1580520308490,"mc":[{"id":"1.168136214","rc":[{"batl":[[0,7.4,1.88],[1,7.6,1.96]],"ltp":5.2,"tv":122.19,"id":12925630}]}]}
{"op":"mcm","clk":"989532918","pt":1580520309624,"mc":[{"id":"1.168136214","rc":[{"batl":[[0,7.4,7.2]],"ltp":5.2,"tv":122.19,"id":12925630}]}]}
{"op":"mcm","clk":"989534777","pt":1580520339923,"mc":[{"id":"1.168136214","rc":[{"batl":[[0,7.2,2.95],[1,7.4,6.32]],"ltp":5.2,"tv":122.19,"id":12925630}]}]}
{"op":"mcm","clk":"989535306","pt":1580520348426,"mc":[{"id":"1.168136214","rc":[{"batl":[[1,7.4,1]],"ltp":5.2,"tv":122.19,"id":12925630}]}]}
{"op":"mcm","clk":"989536786","pt":1580520371398,"mc":[{"id":"1.168136214","rc":[{"batl":[[0,7.4,1.88],[1,7.6,1.96]],"ltp":5.2,"tv":122.19,"id":12925630}]}]}
{"op":"mcm","clk":"989537802","pt":1580520387199,"mc":[{"id":"1.168136214","rc":[{"batl":[[0,7.4,7.2]],"ltp":5.2,"tv":122.19,"id":12925630}]}]}
{"op":"mcm","clk":"989538765","pt":1580520403124,"mc":[{"id":"1.168136214","rc":[{"batl":[[1,7.8,18.93],[2,8,25]],"ltp":5.2,"tv":122.19,"id":12925630}]}]}
{"op":"mcm","clk":"989538773","pt":1580520403228,"mc":[{"id":"1.168136214","rc":[{"batl":[[0,7.2,2.95],[1,7.4,6.32],[2,7.8,18.93]],"ltp":5.2,"tv":122.19,"id":12925630}]}]}
{"op":"mcm","clk":"989538987","pt":1580520406735,"mc":[{"id":"1.168136214","rc":[{"batl":[[1,7.4,1]],"ltp":5.2,"tv":122.19,"id":12925630}]}]}
{"op":"mcm","clk":"989540547","pt":1580520434578,"mc":[{"id":"1.168136214","rc":[{"batl":[[0,7.4,1.88],[1,7.6,1.96]],"ltp":5.2,"tv":122.19,"id":12925630}]}]}
{"op":"mcm","clk":"989541282","pt":1580520446074,"mc":[{"id":"1.168136214","rc":[{"batl":[[0,7.4,7.2]],"ltp":5.2,"tv":122.19,"id":12925630}]}]}
{"op":"mcm","clk":"989542626","pt":1580520466815,"mc":[{"id":"1.168136214","rc":[{"batl":[[0,7.2,2.95],[1,7.4,6.32]],"ltp":5.2,"tv":122.19,"id":12925630}]}]}
{"op":"mcm","clk":"989543700","pt":1580520484526,"mc":[{"id":"1.168136214","rc":[{"batl":[[1,7.4,1]],"ltp":5.2,"tv":122.19,"id":12925630}]}]}
{"op":"mcm","clk":"989544487","pt":1580520497965,"mc":[{"id":"1.168136214","rc":[{"batl":[[0,7.4,1.88],[1,7.6,1.96]],"ltp":5.2,"tv":122.19,"id":12925630}]}]}
{"op":"mcm","clk":"989544812","pt":1580520503962,"mc":[{"id":"1.168136214","rc":[{"batl":[[0,7.4,7.2]],"ltp":5.2,"tv":122.19,"id":12925630}]}]}
{"op":"mcm","clk":"989546337","pt":1580520529883,"mc":[{"id":"1.168136214","rc":[{"batl":[[0,7.2,2.95],[1,7.4,6.32]],"ltp":5.2,"tv":122.19,"id":12925630}]}]}
{"op":"mcm","clk":"989547220","pt":1580520542580,"mc":[{"id":"1.168136214","rc":[{"batl":[[1,7.4,1]],"ltp":5.2,"tv":122.19,"id":12925630}]}]}
{"op":"mcm","clk":"989548386","pt":1580520561044,"mc":[{"id":"1.168136214","rc":[{"batl":[[0,7.4,1.88],[1,7.6,1.96]],"ltp":5.2,"tv":122.19,"id":12925630}]}]}
{"op":"mcm","clk":"989548488","pt":1580520562545,"mc":[{"id":"1.168136214","rc":[{"batl":[[0,7.4,7.2]],"ltp":5.2,"tv":122.19,"id":12925630}]}]}
{"op":"mcm","clk":"989550466","pt":1580520592146,"mc":[{"id":"1.168136214","rc":[{"batl":[[1,7.8,18.93],[2,8,25]],"ltp":5.2,"tv":122.19,"id":12925630}]}]}
{"op":"mcm","clk":"989550477","pt":1580520592347,"mc":[{"id":"1.168136214","rc":[{"batl":[[0,7.2,2.95],[1,7.4,6.32],[2,7.8,18.93]],"ltp":5.2,"tv":122.19,"id":12925630}]}]}
{"op":"mcm","clk":"989551090","pt":1580520601547,"mc":[{"id":"1.168136214","rc":[{"batl":[[1,7.4,1]],"ltp":5.2,"tv":122.19,"id":12925630}]}]}
{"op":"mcm","clk":"989552470","pt":1580520623601,"mc":[{"id":"1.168136214","rc":[{"batl":[[0,7.4,1.88],[1,7.6,1.96]],"ltp":5.2,"tv":122.19,"id":12925630}]}]}
{"op":"mcm","clk":"989553496","pt":1580520640126,"mc":[{"id":"1.168136214","rc":[{"batl":[[0,7.4,7.2]],"ltp":5.2,"tv":122.19,"id":12925630}]}]}
{"op":"mcm","clk":"989554457","pt":1580520654862,"mc":[{"id":"1.168136214","rc":[{"batl":[[0,7.2,2.95],[1,7.4,6.32]],"ltp":5.2,"tv":122.19,"id":12925630}]}]}
{"op":"mcm","clk":"989554789","pt":1580520659667,"mc":[{"id":"1.168136214","rc":[{"batl":[[1,7.4,1]],"ltp":5.2,"tv":122.19,"id":12925630}]}]}
{"op":"mcm","clk":"989556593","pt":1580520686108,"mc":[{"id":"1.168136214","rc":[{"batl":[[0,7.4,1.88],[1,7.8,18.93],[2,8,25]],"ltp":5.2,"tv":122.19,"id":12925630}]}]}
{"op":"mcm","clk":"989556675","pt":1580520687102,"mc":[{"id":"1.168136214","rc":[{"batl":[[1,7.6,1.96],[2,7.8,18.93]],"ltp":5.2,"tv":122.19,"id":12925630}]}]}
{"op":"mcm","clk":"989557535","pt":1580520698594,"mc":[{"id":"1.168136214","rc":[{"batl":[[0,7.4,7.2]],"ltp":5.2,"tv":122.19,"id":12925630}]}]}
{"op":"mcm","clk":"989558951","pt":1580520717326,"mc":[{"id":"1.168136214","rc":[{"batl":[[0,7.2,2.95],[1,7.4,6.32]],"ltp":5.2,"tv":122.19,"id":12925630}]}]}
{"op":"mcm","clk":"989559054","pt":1580520718519,"mc":[{"id":"1.168136214","rc":[{"batl":[[1,7.4,1]],"ltp":5.2,"tv":122.19,"id":12925630}]}]}
{"op":"mcm","clk":"989561444","pt":1580520749074,"mc":[{"id":"1.168136214","rc":[{"batl":[[0,7.4,1.88],[1,7.6,1.96]],"ltp":5.2,"tv":122.19,"id":12925630}]}]}
{"op":"mcm","clk":"989571678","pt":1580520757802,"mc":[{"id":"1.168136214","rc":[{"batl":[[0,7.4,7.2]],"ltp":5.2,"tv":122.19,"id":12925630}]}]}
{"op":"mcm","clk":"989573380","pt":1580520781135,"mc":[{"id":"1.168136214","rc":[{"batl":[[0,7.2,2.95],[1,7.4,6.32]],"ltp":5.2,"tv":122.19,"id":12925630}]}]}
{"op":"mcm","clk":"989574405","pt":1580520796064,"mc":[{"id":"1.168136214","rc":[{"batl":[[1,7.4,1]],"ltp":5.2,"tv":122.19,"id":12925630}]}]}
{"op":"mcm","clk":"989575075","pt":1580520806081,"mc":[{"id":"1.168136214","rc":[{"batb":[[0,5.1,20.61]],"ltp":5.2,"tv":122.19,"id":12925630}]}]}
{"op":"mcm","clk":"989575443","pt":1580520811558,"mc":[{"id":"1.168136214","rc":[{"batl":[[0,7.4,1.88],[1,7.6,1.96]],"ltp":5.2,"tv":122.19,"id":12925630}]}]}
{"op":"mcm","clk":"989575768","pt":1580520816058,"mc":[{"id":"1.168136214","rc":[{"batl":[[0,7.4,7.2]],"ltp":5.2,"tv":122.19,"id":12925630}]}]}
{"op":"mcm","clk":"989577601","pt":1580520842791,"mc":[{"id":"1.168136214","rc":[{"batl":[[0,7.2,2.95],[1,7.4,6.32]],"ltp":5.2,"tv":122.19,"id":12925630}]}]}
{"op":"mcm","clk":"989578421","pt":1580520855133,"mc":[{"id":"1.168136214","rc":[{"batl":[[0,7,5.82],[1,7.2,2.76],[2,7.4,1]],"ltp":5.2,"tv":122.19,"id":12925630}]}]}
{"op":"mcm","clk":"989579799","pt":1580520873972,"mc":[{"id":"1.168136214","rc":[{"batl":[[0,6.8,2.33],[1,7,5.63],[2,7.4,1.69]],"ltp":5.2,"tv":122.19,"id":12925630}]}]}
{"op":"mcm","clk":"989579978","pt":1580520877002,"mc":[{"id":"1.168136214","rc":[{"batl":[[0,6.8,3.07],[2,7.4,1]],"ltp":5.2,"tv":122.19,"id":12925630}]}]}
{"op":"mcm","clk":"989580173","pt":1580520879902,"mc":[{"id":"1.168136214","rc":[{"batl":[[0,6.8,2.88]],"ltp":5.2,"tv":122.19,"id":12925630}]}]}
{"op":"mcm","clk":"989580180","pt":1580520880406,"mc":[{"id":"1.168136214","rc":[{"batl":[[0,6.8,3.07]],"ltp":5.2,"tv":122.19,"id":12925630}]}]}
{"op":"mcm","clk":"989581089","pt":1580520893136,"mc":[{"id":"1.168136214","rc":[{"batl":[[0,6.6,6.16],[1,6.8,2.88]],"ltp":5.2,"tv":122.19,"id":12925630}]}]}
{"op":"mcm","clk":"989581944","pt":1580520905087,"mc":[{"id":"1.168136214","rc":[{"batl":[[1,7.4,1.74],[2,7.8,18.93]],"ltp":5.2,"tv":122.19,"id":12925630}]}]}
{"op":"mcm","clk":"989581981","pt":1580520905587,"mc":[{"id":"1.168136214","rc":[{"batl":[[0,6.4,2.45],[1,6.6,5.97],[2,7.4,1.74]],"ltp":5.2,"tv":122.19,"id":12925630}]}]}
{"op":"mcm","clk":"989582473","pt":1580520912979,"mc":[{"id":"1.168136214","rc":[{"batl":[[1,7.4,1.74],[2,7.8,18.93]],"ltp":5.2,"tv":122.19,"id":12925630}]}]}
{"op":"mcm","clk":"989583924","pt":1580520936261,"mc":[{"id":"1.168136214","rc":[{"batl":[[0,7.2,2.61],[1,7.4,1]],"ltp":5.2,"tv":122.19,"id":12925630}]}]}
{"op":"mcm","clk":"989584035","pt":1580520938064,"mc":[{"id":"1.168136214","rc":[{"batl":[[0,7.2,2.42]],"ltp":5.2,"tv":122.19,"id":12925630}]}]}
{"op":"mcm","clk":"989584041","pt":1580520938168,"mc":[{"id":"1.168136214","rc":[{"batl":[[0,7.2,2.61]],"ltp":5.2,"tv":122.19,"id":12925630}]}]}
{"op":"mcm","clk":"989585845","pt":1580520967304,"mc":[{"id":"1.168136214","rc":[{"batl":[[0,7.4,1.93],[1,7.6,1.96]],"ltp":5.2,"tv":122.19,"id":12925630}]}]}
{"op":"mcm","clk":"989585990","pt":1580520969617,"mc":[{"id":"1.168136214","rc":[{"batl":[[0,7.4,7.25]],"ltp":5.2,"tv":122.19,"id":12925630}]}]}
{"op":"mcm","clk":"989587979","pt":1580520998965,"mc":[{"id":"1.168136214","rc":[{"batl":[[0,7.2,3],[1,7.4,6.32]],"ltp":5.2,"tv":122.19,"id":12925630}]}]}
{"op":"mcm","clk":"989588650","pt":1580521008144,"mc":[{"id":"1.168136214","rc":[{"batl":[[1,7.4,1]],"ltp":5.2,"tv":122.19,"id":12925630}]}]}
{"op":"mcm","clk":"989590140","pt":1580521030373,"mc":[{"id":"1.168136214","rc":[{"batl":[[0,7.4,1.93],[1,7.6,1.96]],"ltp":5.2,"tv":122.19,"id":12925630}]}]}
{"op":"mcm","clk":"989591129","pt":1580521046074,"mc":[{"id":"1.168136214","rc":[{"batl":[[0,7.4,7.25]],"ltp":5.2,"tv":122.19,"id":12925630}]}]}
{"op":"mcm","clk":"989592162","pt":1580521061527,"mc":[{"id":"1.168136214","rc":[{"batl":[[0,7.2,3],[1,7.4,6.32]],"ltp":5.2,"tv":122.19,"id":12925630}]}]}
{"op":"mcm","clk":"989592428","pt":1580521065429,"mc":[{"id":"1.168136214","rc":[{"batl":[[1,7.4,1]],"ltp":5.2,"tv":122.19,"id":12925630}]}]}
{"op":"mcm","clk":"989594274","pt":1580521092922,"mc":[{"id":"1.168136214","rc":[{"batl":[[0,7.4,1.93],[1,7.6,1.96]],"ltp":5.2,"tv":122.19,"id":12925630}]}]}
{"op":"mcm","clk":"989595086","pt":1580521104274,"mc":[{"id":"1.168136214","rc":[{"batl":[[0,7.4,7.25]],"ltp":5.2,"tv":122.19,"id":12925630}]}]}
{"op":"mcm","clk":"989596470","pt":1580521124011,"mc":[{"id":"1.168136214","rc":[{"batl":[[1,7.8,18.93],[2,8,25]],"ltp":5.2,"tv":122.19,"id":12925630}]}]}
{"op":"mcm","clk":"989596485","pt":1580521124216,"mc":[{"id":"1.168136214","rc":[{"batl":[[0,7.2,3],[1,7.4,6.32],[2,7.8,18.93]],"ltp":5.2,"tv":122.19,"id":12925630}]}]}
{"op":"mcm","clk":"989597849","pt":1580521142210,"mc":[{"id":"1.168136214","rc":[{"batl":[[1,7.4,1]],"ltp":5.2,"tv":122.19,"id":12925630}]}]}
{"op":"mcm","clk":"989598747","pt":1580521155535,"mc":[{"id":"1.168136214","rc":[{"batl":[[0,7.4,1.93],[1,7.6,1.96]],"ltp":5.2,"tv":122.19,"id":12925630}]}]}
{"op":"mcm","clk":"989599132","pt":1580521161247,"mc":[{"id":"1.168136214","rc":[{"batl":[[0,7.4,7.25]],"ltp":5.2,"tv":122.19,"id":12925630}]}]}
{"op":"mcm","clk":"989600940","pt":1580521186956,"mc":[{"id":"1.168136214","rc":[{"batl":[[0,7.2,3],[1,7.4,6.32]],"ltp":5.2,"tv":122.19,"id":12925630}]}]}
{"op":"mcm","clk":"989602093","pt":1580521199984,"mc":[{"id":"1.168136214","rc":[{"batl":[[1,7.4,1]],"ltp":5.2,"tv":122.19,"id":12925630}]}]}
{"op":"mcm","clk":"989603434","pt":1580521218982,"mc":[{"id":"1.168136214","rc":[{"batl":[[0,7.4,1.93],[1,7.6,1.96]],"ltp":5.2,"tv":122.19,"id":12925630}]}]}
{"op":"mcm","clk":"989604793","pt":1580521237830,"mc":[{"id":"1.168136214","rc":[{"batl":[[0,7.4,7.25]],"ltp":5.2,"tv":122.19,"id":12925630}]}]}
{"op":"mcm","clk":"989605676","pt":1580521249930,"mc":[{"id":"1.168136214","rc":[{"batl":[[1,7.8,18.93],[2,8,25]],"ltp":5.2,"tv":122.19,"id":12925630}]}]}
{"op":"mcm","clk":"989605754","pt":1580521251109,"mc":[{"id":"1.168136214","rc":[{"batl":[[0,7.2,3],[1,7.4,6.32],[2,7.8,18.93]],"ltp":5.2,"tv":122.19,"id":12925630}]}]}
{"op":"mcm","clk":"989606178","pt":1580521256972,"mc":[{"id":"1.168136214","rc":[{"batl":[[1,7.4,1]],"ltp":5.2,"tv":122.19,"id":12925630}]}]}
{"op":"mcm","clk":"989608020","pt":1580521281709,"mc":[{"id":"1.168136214","rc":[{"batl":[[0,7.4,1.93],[1,7.6,1.96]],"ltp":5.2,"tv":122.19,"id":12925630}]}]}
{"op":"mcm","clk":"989608961","pt":1580521294906,"mc":[{"id":"1.168136214","rc":[{"batl":[[0,7.4,7.25]],"ltp":5.2,"tv":122.19,"id":12925630}]}]}
{"op":"mcm","clk":"989610249","pt":1580521313112,"mc":[{"id":"1.168136214","rc":[{"batl":[[0,7.2,3],[1,7.4,6.32]],"ltp":5.2,"tv":122.19,"id":12925630}]}]}
{"op":"mcm","clk":"989610354","pt":1580521314602,"mc":[{"id":"1.168136214","rc":[{"batl":[[1,7.4,1]],"ltp":5.2,"tv":122.19,"id":12925630}]}]}
{"op":"mcm","clk":"989612504","pt":1580521344847,"mc":[{"id":"1.168136214","rc":[{"batl":[[0,7.4,1.93],[1,7.6,1.96]],"ltp":5.2,"tv":122.19,"id":12925630}]}]}
{"op":"mcm","clk":"989613152","pt":1580521353641,"mc":[{"id":"1.168136214","rc":[{"batl":[[0,7.4,7.25]],"ltp":5.2,"tv":122.19,"id":12925630}]}]}
{"op":"mcm","clk":"989614812","pt":1580521376081,"mc":[{"id":"1.168136214","rc":[{"batl":[[0,7.2,3],[1,7.4,6.32]],"ltp":5.2,"tv":122.19,"id":12925630}]}]}
{"op":"mcm","clk":"989615243","pt":1580521381690,"mc":[{"id":"1.168136214","rc":[{"trd":[[5.1,64.88]],"batb":[[0,5.1,14.04]],"ltp":5.1,"tv":135.33,"id":12925630},{"trd":[[1.99,119.13]],"batb":[[0,1.98,15.63],[1,1.97,2],[2,1.96,13.1]],"batl":[[0,2.08,35.92]],"ltp":1.99,"tv":1268.3,"id":17336468},{"trd":[[3.35,37.72],[3.4,50.12]],"batb":[[0,3.35,1.68],[1,3.25,7.9],[2,3.2,6.14]],"batl":[[0,3.7,6.5],[1,3.75,16],[2,5.1,1.74]],"ltp":3.35,"tv":426.07,"id":11981493}],"tv":1829.71}]}
{"op":"mcm","clk":"989615389","pt":1580521383704,"mc":[{"id":"1.168136214","rc":[{"batb":[[0,5.2,3.31],[1,5.1,14.04],[2,5,2.97]],"ltp":5.1,"tv":135.33,"id":12925630},{"trd":[[1.99,119.15]],"batb":[[0,1.99,2.11],[1,1.98,15.63],[2,1.97,2]],"batl":[[0,2.06,12.68],[1,2.08,35.91],[2,2.16,15.14]],"ltp":1.99,"tv":1268.32,"id":17336468},{"batb":[[0,3.25,7.9],[1,3.2,6.14],[2,3.15,6]],"ltp":3.35,"tv":426.07,"id":11981493}],"tv":1829.73}]}
{"op":"mcm","clk":"989616057","pt":1580521391964,"mc":[{"id":"1.168136214","rc":[{"batb":[[0,3.25,9.58]],"ltp":3.35,"tv":426.07,"id":11981493}]}]}
{"op":"mcm","clk":"989616139","pt":1580521393093,"mc":[{"id":"1.168136214","rc":[{"batl":[[1,7.4,1]],"ltp":5.1,"tv":135.33,"id":12925630}]}]}
{"op":"mcm","clk":"989617509","pt":1580521408609,"mc":[{"id":"1.168136214","rc":[{"batl":[[0,7.4,1.93],[1,7.6,1.96]],"ltp":5.1,"tv":135.33,"id":12925630}]}]}
{"op":"mcm","clk":"989617775","pt":1580521412023,"mc":[{"id":"1.168136214","rc":[{"batl":[[0,7.4,7.25]],"ltp":5.1,"tv":135.33,"id":12925630}]}]}
{"op":"mcm","clk":"989619657","pt":1580521439565,"mc":[{"id":"1.168136214","rc":[{"batl":[[0,7.2,3],[1,7.4,6.32]],"ltp":5.1,"tv":135.33,"id":12925630}]}]}
{"op":"mcm","clk":"989620493","pt":1580521449997,"mc":[{"id":"1.168136214","rc":[{"batl":[[1,7.4,1]],"ltp":5.1,"tv":135.33,"id":12925630}]}]}
{"op":"mcm","clk":"989621124","pt":1580521459331,"mc":[{"id":"1.168136214","rc":[{"trd":[[3.7,27]],"batl":[[0,3.75,16],[1,5.1,1.74],[2,5.8,9]],"ltp":3.7,"tv":439.07,"id":11981493}],"tv":1842.73}]}
{"op":"mcm","clk":"989621278","pt":1580521461499,"mc":[{"id":"1.168136214","rc":[{"batl":[[0,3.75,16.19]],"ltp":3.7,"tv":439.07,"id":11981493}]}]}
{"op":"mcm","clk":"989621923","pt":1580521471096,"mc":[{"id":"1.168136214","rc":[{"batl":[[0,7.4,1.93],[1,7.6,1.96]],"ltp":5.1,"tv":135.33,"id":12925630}]}]}
{"op":"mcm","clk":"989623193","pt":1580521488649,"mc":[{"id":"1.168136214","rc":[{"batl":[[0,7.4,7.25]],"ltp":5.1,"tv":135.33,"id":12925630}]}]}
{"op":"mcm","clk":"989623439","pt":1580521491938,"mc":[{"id":"1.168136214","rc":[{"batb":[[0,3.3,2.24],[1,3.25,9.58],[2,3.2,6.14]],"ltp":3.7,"tv":439.07,"id":11981493}]}]}
{"op":"mcm","clk":"989624286","pt":1580521503071,"mc":[{"id":"1.168136214","rc":[{"batl":[[0,7.2,3],[1,7.4,6.32]],"ltp":5.1,"tv":135.33,"id":12925630}]}]}
{"op":"mcm","clk":"989624645","pt":1580521508037,"mc":[{"id":"1.168136214","rc":[{"batl":[[1,7.4,1]],"ltp":5.1,"tv":135.33,"id":12925630}]}]}
{"op":"mcm","clk":"989626613","pt":1580521533748,"mc":[{"id":"1.168136214","rc":[{"batl":[[0,7.4,1.93],[1,7.6,1.96]],"ltp":5.1,"tv":135.33,"id":12925630},{"batb":[[0,1.99,10.76]],"ltp":1.99,"tv":1268.32,"id":17336468}]}]}
{"op":"mcm","clk":"989627619","pt":1580521547457,"mc":[{"id":"1.168136214","rc":[{"batl":[[0,7.4,7.25]],"ltp":5.1,"tv":135.33,"id":12925630}]}]}
{"op":"mcm","clk":"989628841","pt":1580521564982,"mc":[{"id":"1.168136214","rc":[{"batl":[[0,7.2,3],[1,7.4,6.32]],"ltp":5.1,"tv":135.33,"id":12925630}]}]}
{"op":"mcm","clk":"989628939","pt":1580521566582,"mc":[{"id":"1.168136214","rc":[{"batl":[[1,7.4,1]],"ltp":5.1,"tv":135.33,"id":12925630}]}]}
{"op":"mcm","clk":"989630997","pt":1580521595519,"mc":[{"id":"1.168136214","rc":[{"batl":[[0,7.4,1.93],[1,7.6,1.96]],"ltp":5.1,"tv":135.33,"id":12925630}]}]}
{"op":"mcm","clk":"989631864","pt":1580521604933,"mc":[{"id":"1.168136214","rc":[{"batl":[[0,7.4,7.25]],"ltp":5.1,"tv":135.33,"id":12925630}]}]}
{"op":"mcm","clk":"989633390","pt":1580521626675,"mc":[{"id":"1.168136214","rc":[{"batl":[[0,7.2,3],[1,7.4,6.32]],"ltp":5.1,"tv":135.33,"id":12925630}]}]}
{"op":"mcm","clk":"989634398","pt":1580521642791,"mc":[{"id":"1.168136214","rc":[{"batl":[[1,7.4,1]],"ltp":5.1,"tv":135.33,"id":12925630}]}]}
{"op":"mcm","clk":"989644914","pt":1580521657793,"mc":[{"id":"1.168136214","rc":[{"batl":[[0,7.4,1.93],[1,7.6,1.96]],"ltp":5.1,"tv":135.33,"id":12925630}]}]}
{"op":"mcm","clk":"989645205","pt":1580521661901,"mc":[{"id":"1.168136214","rc":[{"batl":[[0,7.4,7.25]],"ltp":5.1,"tv":135.33,"id":12925630}]}]}
{"op":"mcm","clk":"989646616","pt":1580521683779,"mc":[{"id":"1.168136214","rc":[{"batb":[[0,3.3,7.46]],"ltp":3.7,"tv":439.07,"id":11981493}]}]}
{"op":"mcm","clk":"989646738","pt":1580521685580,"mc":[{"id":"1.168136214","rc":[{"batb":[[0,5.2,5.51],[1,5.1,11.84]],"ltp":5.1,"tv":135.33,"id":12925630}]}]}
{"op":"mcm","clk":"989646955","pt":1580521688978,"mc":[{"id":"1.168136214","rc":[{"batl":[[0,7.2,3],[1,7.4,6.32]],"ltp":5.1,"tv":135.33,"id":12925630}]}]}
{"op":"mcm","clk":"989647636","pt":1580521699895,"mc":[{"id":"1.168136214","rc":[{"batl":[[1,7.4,1]],"ltp":5.1,"tv":135.33,"id":12925630}]}]}
{"op":"mcm","clk":"989648136","pt":1580521707990,"mc":[{"id":"1.168136214","rc":[{"trd":[[5.2,35.64]],"batb":[[0,5.2,1.4]],"ltp":5.2,"tv":143.55,"id":12925630},{"trd":[[1.99,140.67]],"batb":[[0,1.98,15.63],[1,1.97,2],[2,1.96,13.1]],"ltp":1.99,"tv":1289.85,"id":17336468},{"trd":[[3.3,22.9]],"batb":[[0,3.25,10.55],[1,3.2,6.14],[2,3.15,6]],"ltp":3.3,"tv":447.57,"id":11981493}],"tv":1880.98}]}
{"op":"mcm","clk":"989648854","pt":1580521720089,"mc":[{"id":"1.168136214","rc":[{"batl":[[0,7.4,1.93],[1,7.6,1.96]],"ltp":5.2,"tv":143.55,"id":12925630}]}]}
{"op":"mcm","clk":"989650009","pt":1580521739149,"mc":[{"id":"1.168136214","rc":[{"batl":[[0,7.4,7.25]],"ltp":5.2,"tv":143.55,"id":12925630}]}]}
{"op":"mcm","clk":"989650799","pt":1580521751278,"mc":[{"id":"1.168136214","rc":[{"batl":[[0,7.2,3],[1,7.4,6.32]],"ltp":5.2,"tv":143.55,"id":12925630}]}]}
{"op":"mcm","clk":"989651232","pt":1580521758109,"mc":[{"id":"1.168136214","rc":[{"batl":[[1,7.4,1]],"ltp":5.2,"tv":143.55,"id":12925630}]}]}
{"op":"mcm","clk":"989651463","pt":1580521761518,"mc":[{"id":"1.168136214","rc":[{"batb":[[0,1.99,10],[1,1.98,15.63],[2,1.97,2]],"ltp":1.99,"tv":1289.85,"id":17336468},{"batl":[[0,3.7,2.19],[1,3.75,16],[2,5.1,1.74]],"ltp":3.3,"tv":447.57,"id":11981493}]}]}
{"op":"mcm","clk":"989652850","pt":1580521782402,"mc":[{"id":"1.168136214","rc":[{"batl":[[0,7.4,1.93],[1,7.6,1.96]],"ltp":5.2,"tv":143.55,"id":12925630}]}]}
{"op":"mcm","clk":"989653814","pt":1580521796946,"mc":[{"id":"1.168136214","rc":[{"batl":[[0,7.4,7.25]],"ltp":5.2,"tv":143.55,"id":12925630}]}]}
{"op":"mcm","clk":"989654925","pt":1580521813458,"mc":[{"id":"1.168136214","rc":[{"batl":[[0,7.2,3],[1,7.4,6.32]],"ltp":5.2,"tv":143.55,"id":12925630}]}]}
{"op":"mcm","clk":"989655048","pt":1580521815577,"mc":[{"id":"1.168136214","rc":[{"batl":[[1,7.4,1]],"ltp":5.2,"tv":143.55,"id":12925630}]}]}
{"op":"mcm","clk":"989657270","pt":1580521844874,"mc":[{"id":"1.168136214","rc":[{"batl":[[0,7.4,1.93],[1,7.6,1.96]],"ltp":5.2,"tv":143.55,"id":12925630}]}]}
{"op":"mcm","clk":"989657832","pt":1580521853815,"mc":[{"id":"1.168136214","rc":[{"batl":[[0,7.4,7.25]],"ltp":5.2,"tv":143.55,"id":12925630}]}]}
{"op":"mcm","clk":"989659253","pt":1580521876009,"mc":[{"id":"1.168136214","rc":[{"batl":[[0,7.2,3],[1,7.4,6.32]],"ltp":5.2,"tv":143.55,"id":12925630}]}]}
{"op":"mcm","clk":"989660347","pt":1580521892967,"mc":[{"id":"1.168136214","rc":[{"batl":[[1,7.4,1]],"ltp":5.2,"tv":143.55,"id":12925630}]}]}
{"op":"mcm","clk":"989661407","pt":1580521908550,"mc":[{"id":"1.168136214","rc":[{"batl":[[0,7.4,1.93],[1,7.6,1.96]],"ltp":5.2,"tv":143.55,"id":12925630}]}]}
{"op":"mcm","clk":"989661674","pt":1580521912888,"mc":[{"id":"1.168136214","rc":[{"batl":[[0,7.4,7.25]],"ltp":5.2,"tv":143.55,"id":12925630}]}]}
{"op":"mcm","clk":"989663539","pt":1580521940574,"mc":[{"id":"1.168136214","rc":[{"batl":[[0,7.2,3],[1,7.4,6.32]],"ltp":5.2,"tv":143.55,"id":12925630}]}]}
{"op":"mcm","clk":"989664334","pt":1580521952837,"mc":[{"id":"1.168136214","rc":[{"batl":[[1,7.4,1]],"ltp":5.2,"tv":143.55,"id":12925630}]}]}
{"op":"mcm","clk":"989665572","pt":1580521971932,"mc":[{"id":"1.168136214","rc":[{"batl":[[0,7.4,1.93],[1,7.6,1.96]],"ltp":5.2,"tv":143.55,"id":12925630}]}]}
{"op":"mcm","clk":"989665626","pt":1580521972708,"mc":[{"id":"1.168136214","rc":[{"batl":[[0,7.4,7.25]],"ltp":5.2,"tv":143.55,"id":12925630}]}]}
{"op":"mcm","clk":"989667605","pt":1580522003975,"mc":[{"id":"1.168136214","rc":[{"batl":[[0,7.2,3],[1,7.4,6.32]],"ltp":5.2,"tv":143.55,"id":12925630}]}]}
{"op":"mcm","clk":"989668125","pt":1580522011973,"mc":[{"id":"1.168136214","rc":[{"batl":[[1,7.4,1]],"ltp":5.2,"tv":143.55,"id":12925630}]}]}
{"op":"mcm","clk":"989669602","pt":1580522035649,"mc":[{"id":"1.168136214","rc":[{"batl":[[0,7.4,1.93],[1,7.6,1.96]],"ltp":5.2,"tv":143.55,"id":12925630}]}]}
{"op":"mcm","clk":"989670627","pt":1580522052145,"mc":[{"id":"1.168136214","rc":[{"batl":[[0,7.4,7.25]],"ltp":5.2,"tv":143.55,"id":12925630}]}]}
{"op":"mcm","clk":"989671658","pt":1580522067149,"mc":[{"id":"1.168136214","rc":[{"batl":[[1,7.8,18.93],[2,8,25]],"ltp":5.2,"tv":143.55,"id":12925630}]}]}
{"op":"mcm","clk":"989671665","pt":1580522067252,"mc":[{"id":"1.168136214","rc":[{"batl":[[0,7.2,3],[1,7.4,6.32],[2,7.8,18.93]],"ltp":5.2,"tv":143.55,"id":12925630}]}]}
{"op":"mcm","clk":"989672008","pt":1580522072259,"mc":[{"id":"1.168136214","rc":[{"batl":[[1,7.4,1]],"ltp":5.2,"tv":143.55,"id":12925630}]}]}
{"op":"mcm","clk":"989673948","pt":1580522099069,"mc":[{"id":"1.168136214","rc":[{"batl":[[0,7.4,1.93],[1,7.6,1.96]],"ltp":5.2,"tv":143.55,"id":12925630}]}]}
{"op":"mcm","clk":"989674762","pt":1580522110580,"mc":[{"id":"1.168136214","rc":[{"batl":[[0,7.4,7.25]],"ltp":5.2,"tv":143.55,"id":12925630}]}]}
{"op":"mcm","clk":"989676180","pt":1580522131004,"mc":[{"id":"1.168136214","rc":[{"batl":[[1,7.8,18.93],[2,8,25]],"ltp":5.2,"tv":143.55,"id":12925630}]}]}
{"op":"mcm","clk":"989676196","pt":1580522131206,"mc":[{"id":"1.168136214","rc":[{"batl":[[0,7.2,3],[1,7.4,6.32],[2,7.8,18.93]],"ltp":5.2,"tv":143.55,"id":12925630}]}]}
{"op":"mcm","clk":"989677488","pt":1580522150059,"mc":[{"id":"1.168136214","rc":[{"batl":[[1,7.4,1]],"ltp":5.2,"tv":143.55,"id":12925630}]}]}
{"op":"mcm","clk":"989677505","pt":1580522150366,"mc":[{"id":"1.168136214","rc":[{"batl":[[0,7,6.56],[1,7.2,2.07],[2,7.4,1]],"ltp":5.2,"tv":143.55,"id":12925630}]}]}
{"op":"mcm","clk":"989678344","pt":1580522162661,"mc":[{"id":"1.168136214","rc":[{"batl":[[0,6.8,3.08],[1,7,5.63]],"ltp":5.2,"tv":143.55,"id":12925630}]}]}
{"op":"mcm","clk":"989678879","pt":1580522170543,"mc":[{"id":"1.168136214","rc":[{"batl":[[1,7.4,1],[2,7.8,18.93]],"ltp":5.2,"tv":143.55,"id":12925630}]}]}
{"op":"mcm","clk":"989680625","pt":1580522195095,"mc":[{"id":"1.168136214","rc":[{"batl":[[0,7.4,1.93],[1,7.6,1.96]],"ltp":5.2,"tv":143.55,"id":12925630}]}]}
{"op":"mcm","clk":"989681587","pt":1580522209672,"mc":[{"id":"1.168136214","rc":[{"batl":[[0,7.4,7.25]],"ltp":5.2,"tv":143.55,"id":12925630}]}]}
{"op":"mcm","clk":"989682682","pt":1580522225821,"mc":[{"id":"1.168136214","rc":[{"batb":[[0,1.99,25.14]],"ltp":1.99,"tv":1289.85,"id":17336468}]}]}
{"op":"mcm","clk":"989682777","pt":1580522226912,"mc":[{"id":"1.168136214","rc":[{"batl":[[0,7.2,3],[1,7.4,6.32]],"ltp":5.2,"tv":143.55,"id":12925630}]}]}
{"op":"mcm","clk":"989682928","pt":1580522228818,"mc":[{"id":"1.168136214","rc":[{"batl":[[1,7.4,1]],"ltp":5.2,"tv":143.55,"id":12925630}]}]}
{"op":"mcm","clk":"989684020","pt":1580522243851,"mc":[{"id":"1.168136214","rc":[{"batb":[[0,1.99,15.14]],"ltp":1.99,"tv":1289.85,"id":17336468}]}]}
{"op":"mcm","clk":"989685019","pt":1580522258760,"mc":[{"id":"1.168136214","rc":[{"batl":[[0,7.4,1.93],[1,7.6,1.96]],"ltp":5.2,"tv":143.55,"id":12925630}]}]}
{"op":"mcm","clk":"989685643","pt":1580522268069,"mc":[{"id":"1.168136214","rc":[{"batl":[[0,7.4,7.25]],"ltp":5.2,"tv":143.55,"id":12925630}]}]}
{"op":"mcm","clk":"989687154","pt":1580522290109,"mc":[{"id":"1.168136214","rc":[{"batl":[[1,7.8,18.93],[2,8,25]],"ltp":5.2,"tv":143.55,"id":12925630}]}]}
{"op":"mcm","clk":"989687164","pt":1580522290211,"mc":[{"id":"1.168136214","rc":[{"batl":[[0,7.2,3],[1,7.4,6.32],[2,7.8,18.93]],"ltp":5.2,"tv":143.55,"id":12925630}]}]}
{"op":"mcm","clk":"989688389","pt":1580522307727,"mc":[{"id":"1.168136214","rc":[{"batl":[[1,7.4,1]],"ltp":5.2,"tv":143.55,"id":12925630}]}]}
{"op":"mcm","clk":"989689300","pt":1580522321973,"mc":[{"id":"1.168136214","rc":[{"batl":[[0,7.4,1.93],[1,7.6,1.96]],"ltp":5.2,"tv":143.55,"id":12925630}]}]}
{"op":"mcm","clk":"989689619","pt":1580522327061,"mc":[{"id":"1.168136214","rc":[{"batl":[[0,7.4,7.25]],"ltp":5.2,"tv":143.55,"id":12925630}]}]}
{"op":"mcm","clk":"989691311","pt":1580522354106,"mc":[{"id":"1.168136214","rc":[{"batl":[[1,7.8,18.93],[2,8,25]],"ltp":5.2,"tv":143.55,"id":12925630}]}]}
{"op":"mcm","clk":"989691318","pt":1580522354208,"mc":[{"id":"1.168136214","rc":[{"batl":[[0,7.2,3],[1,7.4,6.32],[2,7.8,18.93]],"ltp":5.2,"tv":143.55,"id":12925630}]}]}
{"op":"mcm","clk":"989692003","pt":1580522364935,"mc":[{"id":"1.168136214","rc":[{"batl":[[1,7.4,1]],"ltp":5.2,"tv":143.55,"id":12925630}]}]}
{"op":"mcm","clk":"989693278","pt":1580522386147,"mc":[{"id":"1.168136214","rc":[{"batl":[[0,7.4,1.93],[1,7.6,1.96]],"ltp":5.2,"tv":143.55,"id":12925630}]}]}
{"op":"mcm","clk":"989694507","pt":1580522403494,"mc":[{"id":"1.168136214","rc":[{"batl":[[0,7.4,7.25]],"ltp":5.2,"tv":143.55,"id":12925630}]}]}
{"op":"mcm","clk":"989695511","pt":1580522417094,"mc":[{"id":"1.168136214","rc":[{"batl":[[1,7.8,18.93],[2,8,25]],"ltp":5.2,"tv":143.55,"id":12925630}]}]}
{"op":"mcm","clk":"989695522","pt":1580522417198,"mc":[{"id":"1.168136214","rc":[{"batl":[[0,7.2,3],[1,7.4,6.32],[2,7.8,18.93]],"ltp":5.2,"tv":143.55,"id":12925630}]}]}
{"op":"mcm","clk":"989695920","pt":1580522422729,"mc":[{"id":"1.168136214","rc":[{"batl":[[1,7.4,1]],"ltp":5.2,"tv":143.55,"id":12925630}]}]}
{"op":"mcm","clk":"989697914","pt":1580522448974,"mc":[{"id":"1.168136214","rc":[{"batl":[[0,7.4,1.93],[1,7.6,1.96]],"ltp":5.2,"tv":143.55,"id":12925630}]}]}
{"op":"mcm","clk":"989698948","pt":1580522462110,"mc":[{"id":"1.168136214","rc":[{"batl":[[0,7.4,7.25]],"ltp":5.2,"tv":143.55,"id":12925630}]}]}
{"op":"mcm","clk":"989700569","pt":1580522480918,"mc":[{"id":"1.168136214","rc":[{"batl":[[0,7.2,3],[1,7.4,6.32]],"ltp":5.2,"tv":143.55,"id":12925630}]}]}
{"op":"mcm","clk":"989700649","pt":1580522482147,"mc":[{"id":"1.168136214","rc":[{"batl":[[1,7.4,1]],"ltp":5.2,"tv":143.55,"id":12925630}]}]}
{"op":"mcm","clk":"989702788","pt":1580522512085,"mc":[{"id":"1.168136214","rc":[{"batl":[[0,7.4,1.93],[1,7.6,1.96]],"ltp":5.2,"tv":143.55,"id":12925630}]}]}
{"op":"mcm","clk":"989703435","pt":1580522520123,"mc":[{"id":"1.168136214","rc":[{"batl":[[0,7.4,7.25]],"ltp":5.2,"tv":143.55,"id":12925630}]}]}
{"op":"mcm","clk":"989704938","pt":1580522543418,"mc":[{"id":"1.168136214","rc":[{"batl":[[0,7.2,3],[1,7.4,6.32]],"ltp":5.2,"tv":143.55,"id":12925630}]}]}
{"op":"mcm","clk":"989715510","pt":1580522558826,"mc":[{"id":"1.168136214","rc":[{"batl":[[1,7.4,1]],"ltp":5.2,"tv":143.55,"id":12925630}]}]}
{"op":"mcm","clk":"989716588","pt":1580522574779,"mc":[{"id":"1.168136214","rc":[{"batl":[[0,7.4,1.93],[1,7.6,1.96]],"ltp":5.2,"tv":143.55,"id":12925630}]}]}
{"op":"mcm","clk":"989716866","pt":1580522578763,"mc":[{"id":"1.168136214","rc":[{"batl":[[0,7.4,7.25]],"ltp":5.2,"tv":143.55,"id":12925630}]}]}
{"op":"mcm","clk":"989718672","pt":1580522606133,"mc":[{"id":"1.168136214","rc":[{"batl":[[1,7.8,18.93],[2,8,25]],"ltp":5.2,"tv":143.55,"id":12925630}]}]}
{"op":"mcm","clk":"989718681","pt":1580522606182,"mc":[{"id":"1.168136214","rc":[{"batl":[[0,7.2,3],[1,7.4,6.32],[2,7.8,18.93]],"ltp":5.2,"tv":143.55,"id":12925630}]}]}
{"op":"mcm","clk":"989719306","pt":1580522616034,"mc":[{"id":"1.168136214","rc":[{"batl":[[1,7.4,1]],"ltp":5.2,"tv":143.55,"id":12925630}]}]}
{"op":"mcm","clk":"989720574","pt":1580522637546,"mc":[{"id":"1.168136214","rc":[{"batl":[[0,7.4,1.93],[1,7.6,1.96]],"ltp":5.2,"tv":143.55,"id":12925630}]}]}
{"op":"mcm","clk":"989721596","pt":1580522655153,"mc":[{"id":"1.168136214","rc":[{"batl":[[0,7.4,7.25]],"ltp":5.2,"tv":143.55,"id":12925630}]}]}
{"op":"mcm","clk":"989722501","pt":1580522669063,"mc":[{"id":"1.168136214","rc":[{"batl":[[0,7.2,3],[1,7.4,6.32]],"ltp":5.2,"tv":143.55,"id":12925630}]}]}
{"op":"mcm","clk":"989722801","pt":1580522674062,"mc":[{"id":"1.168136214","rc":[{"batl":[[1,7.4,1]],"ltp":5.2,"tv":143.55,"id":12925630}]}]}
{"op":"mcm","clk":"989724487","pt":1580522700840,"mc":[{"id":"1.168136214","rc":[{"batl":[[0,7.4,1.93],[1,7.6,1.96]],"ltp":5.2,"tv":143.55,"id":12925630}]}]}
{"op":"mcm","clk":"989725290","pt":1580522712956,"mc":[{"id":"1.168136214","rc":[{"batl":[[0,7.4,7.25]],"ltp":5.2,"tv":143.55,"id":12925630}]}]}
{"op":"mcm","clk":"989726440","pt":1580522732272,"mc":[{"id":"1.168136214","rc":[{"batl":[[0,7.2,3],[1,7.4,6.32]],"ltp":5.2,"tv":143.55,"id":12925630}]}]}
{"op":"mcm","clk":"989727575","pt":1580522751094,"mc":[{"id":"1.168136214","rc":[{"batl":[[1,7.4,1]],"ltp":5.2,"tv":143.55,"id":12925630}]}]}
{"op":"mcm","clk":"989824321","pt":1580524210192,"mc":[{"id":"1.168136214","rc":[{"batl":[[2,4.5,50]],"ltp":3.3,"tv":447.57,"id":11981493}]}]}
{"op":"mcm","clk":"989824664","pt":1580524216072,"mc":[{"id":"1.168136214","rc":[{"batl":[[0,3.7,6.19]],"ltp":3.3,"tv":447.57,"id":11981493}]}]}
{"op":"mcm","clk":"989871947","pt":1580524869343,"mc":[{"id":"1.168136214","rc":[{"batl":[[0,7,1.93],[1,7.2,2.07]],"ltp":5.2,"tv":143.55,"id":12925630}]}]}
{"op":"mcm","clk":"989881752","pt":1580525065801,"mc":[{"id":"1.168136214","rc":[{"batl":[[0,3.55,21],[1,3.7,6.19],[2,3.75,16]],"ltp":3.3,"tv":447.57,"id":11981493}]}]}
{"op":"mcm","clk":"989881813","pt":1580525066877,"mc":[{"id":"1.168136214","rc":[{"batl":[[1,3.7,6]],"ltp":3.3,"tv":447.57,"id":11981493}]}]}
{"op":"mcm","clk":"989881914","pt":1580525068882,"mc":[{"id":"1.168136214","rc":[{"batl":[[1,3.7,2]],"ltp":3.3,"tv":447.57,"id":11981493}]}]}
{"op":"mcm","clk":"989902689","pt":1580525301420,"mc":[{"id":"1.168136214","rc":[{"trd":[[3.55,42]],"batl":[[0,3.7,2],[1,3.75,16],[2,4.2,50]],"ltp":3.55,"tv":489.57,"id":11981493}],"tv":1922.98}]}
{"op":"mcm","clk":"989903075","pt":1580525309745,"mc":[{"id":"1.168136214","rc":[{"batl":[[0,3.7,6]],"ltp":3.55,"tv":489.57,"id":11981493}]}]}
{"op":"mcm","clk":"989922732","pt":1580525736937,"mc":[{"id":"1.168136214","rc":[{"batl":[[0,6.8,2.61],[1,7,1]],"ltp":5.2,"tv":143.55,"id":12925630}]}]}
{"op":"mcm","clk":"989924305","pt":1580525767798,"mc":[{"id":"1.168136214","rc":[{"batl":[[0,7,1.93],[1,7.6,1.96]],"ltp":5.2,"tv":143.55,"id":12925630}]}]}
{"op":"mcm","clk":"989924909","pt":1580525781120,"mc":[{"id":"1.168136214","rc":[{"batl":[[1,7.4,5.32],[2,7.6,1.96]],"ltp":5.2,"tv":143.55,"id":12925630}]}]}
{"op":"mcm","clk":"989925783","pt":1580525800123,"mc":[{"id":"1.168136214","rc":[{"batl":[[1,7.2,1.81],[2,7.4,5.32]],"ltp":5.2,"tv":143.55,"id":12925630}]}]}
{"op":"mcm","clk":"989925814","pt":1580525800799,"mc":[{"id":"1.168136214","rc":[{"batl":[[2,7.8,18.93]],"ltp":5.2,"tv":143.55,"id":12925630}]}]}
{"op":"mcm","clk":"989927289","pt":1580525832682,"mc":[{"id":"1.168136214","rc":[{"batl":[[0,6.8,2.61],[1,7,1]],"ltp":5.2,"tv":143.55,"id":12925630}]}]}
{"op":"mcm","clk":"989928708","pt":1580525864614,"mc":[{"id":"1.168136214","rc":[{"batl":[[0,7,1.93],[1,7.6,1.96]],"ltp":5.2,"tv":143.55,"id":12925630}]}]}
{"op":"mcm","clk":"989929286","pt":1580525878226,"mc":[{"id":"1.168136214","rc":[{"batl":[[1,7.4,5.32],[2,7.6,1.96]],"ltp":5.2,"tv":143.55,"id":12925630}]}]}
{"op":"mcm","clk":"989930145","pt":1580525896365,"mc":[{"id":"1.168136214","rc":[{"batl":[[1,7.2,1.81],[2,7.4,5.32]],"ltp":5.2,"tv":143.55,"id":12925630}]}]}
{"op":"mcm","clk":"989930223","pt":1580525897546,"mc":[{"id":"1.168136214","rc":[{"batl":[[2,7.8,18.93]],"ltp":5.2,"tv":143.55,"id":12925630}]}]}
{"op":"mcm","clk":"989931698","pt":1580525927833,"mc":[{"id":"1.168136214","rc":[{"batl":[[0,6.8,2.61],[1,7,1]],"ltp":5.2,"tv":143.55,"id":12925630}]}]}
{"op":"mcm","clk":"989933218","pt":1580525960044,"mc":[{"id":"1.168136214","rc":[{"batl":[[0,7,1.93],[1,7.6,1.96]],"ltp":5.2,"tv":143.55,"id":12925630}]}]}
{"op":"mcm","clk":"989933795","pt":1580525973622,"mc":[{"id":"1.168136214","rc":[{"batl":[[1,7.4,5.32],[2,7.6,1.96]],"ltp":5.2,"tv":143.55,"id":12925630}]}]}
{"op":"mcm","clk":"989934672","pt":1580525990958,"mc":[{"id":"1.168136214","rc":[{"batl":[[1,7.2,1.81],[2,7.4,5.32]],"ltp":5.2,"tv":143.55,"id":12925630}]}]}
{"op":"mcm","clk":"989934787","pt":1580525993231,"mc":[{"id":"1.168136214","rc":[{"batl":[[2,7.8,18.93]],"ltp":5.2,"tv":143.55,"id":12925630}]}]}
{"op":"mcm","clk":"989936419","pt":1580526022903,"mc":[{"id":"1.168136214","rc":[{"batl":[[0,6.8,2.61],[1,7,1]],"ltp":5.2,"tv":143.55,"id":12925630}]}]}
{"op":"mcm","clk":"989938011","pt":1580526054153,"mc":[{"id":"1.168136214","rc":[{"batl":[[0,7,1.93],[1,7.6,1.96]],"ltp":5.2,"tv":143.55,"id":12925630}]}]}
{"op":"mcm","clk":"989939006","pt":1580526069589,"mc":[{"id":"1.168136214","rc":[{"batl":[[1,7.4,5.32],[2,7.6,1.96]],"ltp":5.2,"tv":143.55,"id":12925630}]}]}
{"op":"mcm","clk":"989939818","pt":1580526085728,"mc":[{"id":"1.168136214","rc":[{"batl":[[1,7.2,1.81],[2,7.4,5.32]],"ltp":5.2,"tv":143.55,"id":12925630}]}]}
{"op":"mcm","clk":"989939993","pt":1580526089243,"mc":[{"id":"1.168136214","rc":[{"batl":[[2,7.8,18.93]],"ltp":5.2,"tv":143.55,"id":12925630}]}]}
{"op":"mcm","clk":"989941316","pt":1580526117146,"mc":[{"id":"1.168136214","rc":[{"batl":[[0,6.8,2.61],[1,7,1]],"ltp":5.2,"tv":143.55,"id":12925630}]}]}
{"op":"mcm","clk":"989942692","pt":1580526148560,"mc":[{"id":"1.168136214","rc":[{"batl":[[0,7,1.93],[1,7.6,1.96]],"ltp":5.2,"tv":143.55,"id":12925630}]}]}
{"op":"mcm","clk":"989953162","pt":1580526167098,"mc":[{"id":"1.168136214","rc":[{"batl":[[1,7.4,5.32],[2,7.6,1.96]],"ltp":5.2,"tv":143.55,"id":12925630}]}]}
{"op":"mcm","clk":"989953825","pt":1580526180319,"mc":[{"id":"1.168136214","rc":[{"batl":[[1,7.2,1.81],[2,7.4,5.32]],"ltp":5.2,"tv":143.55,"id":12925630}]}]}
{"op":"mcm","clk":"989954180","pt":1580526186399,"mc":[{"id":"1.168136214","rc":[{"batl":[[2,7.8,18.93]],"ltp":5.2,"tv":143.55,"id":12925630}]}]}
{"op":"mcm","clk":"989955459","pt":1580526211855,"mc":[{"id":"1.168136214","rc":[{"batl":[[0,6.8,2.61],[1,7,1]],"ltp":5.2,"tv":143.55,"id":12925630}]}]}
{"op":"mcm","clk":"989956952","pt":1580526243114,"mc":[{"id":"1.168136214","rc":[{"batl":[[0,7,1.93],[1,7.8,18.93],[2,8,25]],"ltp":5.2,"tv":143.55,"id":12925630}]}]}
{"op":"mcm","clk":"989956959","pt":1580526243216,"mc":[{"id":"1.168136214","rc":[{"batl":[[1,7.6,1.96],[2,7.8,18.93]],"ltp":5.2,"tv":143.55,"id":12925630}]}]}
{"op":"mcm","clk":"989957041","pt":1580526244764,"mc":[{"id":"1.168136214","rc":[{"batl":[[1,7.4,5.32],[2,7.6,1.96]],"ltp":5.2,"tv":143.55,"id":12925630}]}]}
{"op":"mcm","clk":"989958552","pt":1580526274700,"mc":[{"id":"1.168136214","rc":[{"batl":[[1,7.2,1.81],[2,7.4,5.32]],"ltp":5.2,"tv":143.55,"id":12925630}]}]}
{"op":"mcm","clk":"989958966","pt":1580526282891,"mc":[{"id":"1.168136214","rc":[{"batl":[[2,7.8,18.93]],"ltp":5.2,"tv":143.55,"id":12925630}]}]}
{"op":"mcm","clk":"989960110","pt":1580526306151,"mc":[{"id":"1.168136214","rc":[{"batl":[[0,6.8,2.61],[1,7,1]],"ltp":5.2,"tv":143.55,"id":12925630}]}]}
{"op":"mcm","clk":"989961637","pt":1580526337872,"mc":[{"id":"1.168136214","rc":[{"batl":[[0,7,1.93],[1,7.6,1.96]],"ltp":5.2,"tv":143.55,"id":12925630}]}]}
{"op":"mcm","clk":"989961783","pt":1580526340917,"mc":[{"id":"1.168136214","rc":[{"batl":[[1,7.4,5.32],[2,7.6,1.96]],"ltp":5.2,"tv":143.55,"id":12925630}]}]}
{"op":"mcm","clk":"989963097","pt":1580526369946,"mc":[{"id":"1.168136214","rc":[{"batl":[[1,7.2,1.81],[2,7.4,5.32]],"ltp":5.2,"tv":143.55,"id":12925630}]}]}
{"op":"mcm","clk":"989963618","pt":1580526380353,"mc":[{"id":"1.168136214","rc":[{"batl":[[2,7.8,18.93]],"ltp":5.2,"tv":143.55,"id":12925630}]}]}
{"op":"mcm","clk":"989964634","pt":1580526401294,"mc":[{"id":"1.168136214","rc":[{"batl":[[0,6.8,2.61],[1,7,1]],"ltp":5.2,"tv":143.55,"id":12925630}]}]}
{"op":"mcm","clk":"989966338","pt":1580526433142,"mc":[{"id":"1.168136214","rc":[{"batl":[[0,7,1.93],[1,7.6,1.96]],"ltp":5.2,"tv":143.55,"id":12925630}]}]}
{"op":"mcm","clk":"989966645","pt":1580526438244,"mc":[{"id":"1.168136214","rc":[{"batl":[[1,7.4,5.32],[2,7.6,1.96]],"ltp":5.2,"tv":143.55,"id":12925630}]}]}
{"op":"mcm","clk":"989967990","pt":1580526464707,"mc":[{"id":"1.168136214","rc":[{"batl":[[1,7.2,1.81],[2,7.4,5.32]],"ltp":5.2,"tv":143.55,"id":12925630}]}]}
{"op":"mcm","clk":"989968639","pt":1580526476997,"mc":[{"id":"1.168136214","rc":[{"batl":[[2,7.8,18.93]],"ltp":5.2,"tv":143.55,"id":12925630}]}]}
{"op":"mcm","clk":"989969639","pt":1580526496118,"mc":[{"id":"1.168136214","rc":[{"batl":[[1,7.8,18.93],[2,8,25]],"ltp":5.2,"tv":143.55,"id":12925630}]}]}
{"op":"mcm","clk":"989969645","pt":1580526496221,"mc":[{"id":"1.168136214","rc":[{"batl":[[0,6.8,2.61],[1,7,1],[2,7.8,18.93]],"ltp":5.2,"tv":143.55,"id":12925630}]}]}
{"op":"mcm","clk":"989969897","pt":1580526501868,"mc":[{"id":"1.168136214","rc":[{"trd":[[3.7,39]],"batl":[[0,3.75,16],[1,4.2,50],[2,4.6,1.74]],"ltp":3.7,"tv":501.57,"id":11981493}],"tv":1934.97}]}
{"op":"mcm","clk":"989970086","pt":1580526506039,"mc":[{"id":"1.168136214","rc":[{"batb":[[0,3.3,5.45],[1,3.25,9.58],[2,3.2,6.14]],"ltp":3.7,"tv":501.57,"id":11981493}]}]}
{"op":"mcm","clk":"989971081","pt":1580526528064,"mc":[{"id":"1.168136214","rc":[{"batl":[[0,7,1.93],[1,7.6,1.96]],"ltp":5.2,"tv":143.55,"id":12925630}]}]}
{"op":"mcm","clk":"989971361","pt":1580526535377,"mc":[{"id":"1.168136214","rc":[{"batl":[[1,7.4,5.32],[2,7.6,1.96]],"ltp":5.2,"tv":143.55,"id":12925630}]}]}
{"op":"mcm","clk":"989971867","pt":1580526546603,"mc":[{"id":"1.168136214","rc":[{"batb":[[0,3.35,2.21],[1,3.3,5.45],[2,3.25,9.58]],"ltp":3.7,"tv":501.57,"id":11981493}]}]}
{"op":"mcm","clk":"989972495","pt":1580526559508,"mc":[{"id":"1.168136214","rc":[{"batl":[[1,7.2,1.81],[2,7.4,5.32]],"ltp":5.2,"tv":143.55,"id":12925630}]}]}
{"op":"mcm","clk":"989973164","pt":1580526574467,"mc":[{"id":"1.168136214","rc":[{"batl":[[2,7.8,18.93]],"ltp":5.2,"tv":143.55,"id":12925630}]}]}
{"op":"mcm","clk":"989973889","pt":1580526591372,"mc":[{"id":"1.168136214","rc":[{"batl":[[0,6.8,2.61],[1,7,1]],"ltp":5.2,"tv":143.55,"id":12925630}]}]}
{"op":"mcm","clk":"989975263","pt":1580526623014,"mc":[{"id":"1.168136214","rc":[{"batl":[[0,7,1.93],[1,7.6,1.96]],"ltp":5.2,"tv":143.55,"id":12925630}]}]}
{"op":"mcm","clk":"989975667","pt":1580526631457,"mc":[{"id":"1.168136214","rc":[{"batl":[[1,7.4,5.32],[2,7.6,1.96]],"ltp":5.2,"tv":143.55,"id":12925630}]}]}
{"op":"mcm","clk":"989976834","pt":1580526654748,"mc":[{"id":"1.168136214","rc":[{"batl":[[1,7.2,1.81],[2,7.4,5.32]],"ltp":5.2,"tv":143.55,"id":12925630}]}]}
{"op":"mcm","clk":"989977632","pt":1580526669913,"mc":[{"id":"1.168136214","rc":[{"batl":[[2,7.8,18.93]],"ltp":5.2,"tv":143.55,"id":12925630}]}]}
{"op":"mcm","clk":"989978443","pt":1580526686299,"mc":[{"id":"1.168136214","rc":[{"batl":[[0,6.8,2.61],[1,7,1]],"ltp":5.2,"tv":143.55,"id":12925630}]}]}
{"op":"mcm","clk":"989979697","pt":1580526717758,"mc":[{"id":"1.168136214","rc":[{"batl":[[0,7,1.93],[1,7.6,1.96]],"ltp":5.2,"tv":143.55,"id":12925630}]}]}
{"op":"mcm","clk":"989980148","pt":1580526728163,"mc":[{"id":"1.168136214","rc":[{"batl":[[1,7.4,5.32],[2,7.6,1.96]],"ltp":5.2,"tv":143.55,"id":12925630}]}]}
{"op":"mcm","clk":"989981030","pt":1580526749422,"mc":[{"id":"1.168136214","rc":[{"batl":[[1,7.2,1.81],[2,7.4,5.32]],"ltp":5.2,"tv":143.55,"id":12925630}]}]}
{"op":"mcm","clk":"989981757","pt":1580526766147,"mc":[{"id":"1.168136214","rc":[{"batl":[[2,7.8,18.93]],"ltp":5.2,"tv":143.55,"id":12925630}]}]}
{"op":"mcm","clk":"989982384","pt":1580526780970,"mc":[{"id":"1.168136214","rc":[{"batl":[[0,6.8,2.61],[1,7,1]],"ltp":5.2,"tv":143.55,"id":12925630}]}]}
{"op":"mcm","clk":"989983756","pt":1580526812591,"mc":[{"id":"1.168136214","rc":[{"batl":[[0,7,1.93],[1,7.6,1.96]],"ltp":5.2,"tv":143.55,"id":12925630}]}]}
{"op":"mcm","clk":"989984251","pt":1580526824501,"mc":[{"id":"1.168136214","rc":[{"batl":[[1,7.4,5.32],[2,7.6,1.96]],"ltp":5.2,"tv":143.55,"id":12925630}]}]}
{"op":"mcm","clk":"989985038","pt":1580526843959,"mc":[{"id":"1.168136214","rc":[{"batl":[[1,7.2,1.81],[2,7.4,5.32]],"ltp":5.2,"tv":143.55,"id":12925630}]}]}
{"op":"mcm","clk":"989985915","pt":1580526863065,"mc":[{"id":"1.168136214","rc":[{"batl":[[2,7.8,18.93]],"ltp":5.2,"tv":143.55,"id":12925630}]}]}
{"op":"mcm","clk":"989986502","pt":1580526875800,"mc":[{"id":"1.168136214","rc":[{"batl":[[0,6.8,2.61],[1,7,1]],"ltp":5.2,"tv":143.55,"id":12925630}]}]}
{"op":"mcm","clk":"989988018","pt":1580526907435,"mc":[{"id":"1.168136214","rc":[{"batl":[[0,7,1.93],[1,7.6,1.96]],"ltp":5.2,"tv":143.55,"id":12925630}]}]}
{"op":"mcm","clk":"989988575","pt":1580526920851,"mc":[{"id":"1.168136214","rc":[{"batl":[[1,7.4,5.32],[2,7.6,1.96]],"ltp":5.2,"tv":143.55,"id":12925630}]}]}
{"op":"mcm","clk":"989989338","pt":1580526939074,"mc":[{"id":"1.168136214","rc":[{"batl":[[2,7.8,18.93]],"ltp":5.2,"tv":143.55,"id":12925630}]}]}
{"op":"mcm","clk":"989989382","pt":1580526939843,"mc":[{"id":"1.168136214","rc":[{"batl":[[1,7.2,1.81],[2,7.4,5.32]],"ltp":5.2,"tv":143.55,"id":12925630}]}]}
{"op":"mcm","clk":"989989402","pt":1580526940358,"mc":[{"id":"1.168136214","rc":[{"batl":[[2,7.8,18.93]],"ltp":5.2,"tv":143.55,"id":12925630}]}]}
{"op":"mcm","clk":"989990710","pt":1580526971616,"mc":[{"id":"1.168136214","rc":[{"batl":[[0,6.8,2.61],[1,7,1]],"ltp":5.2,"tv":143.55,"id":12925630}]}]}
{"op":"mcm","clk":"989992206","pt":1580527003131,"mc":[{"id":"1.168136214","rc":[{"batl":[[0,7,1.93],[1,7.8,18.93],[2,8,25]],"ltp":5.2,"tv":143.55,"id":12925630}]}]}
{"op":"mcm","clk":"989992215","pt":1580527003233,"mc":[{"id":"1.168136214","rc":[{"batl":[[1,7.6,1.96],[2,7.8,18.93]],"ltp":5.2,"tv":143.55,"id":12925630}]}]}
{"op":"mcm","clk":"989993114","pt":1580527018154,"mc":[{"id":"1.168136214","rc":[{"batl":[[1,7.4,5.32],[2,7.6,1.96]],"ltp":5.2,"tv":143.55,"id":12925630}]}]}
{"op":"mcm","clk":"989993772","pt":1580527035098,"mc":[{"id":"1.168136214","rc":[{"batl":[[1,7.2,1.81],[2,7.4,5.32]],"ltp":5.2,"tv":143.55,"id":12925630}]}]}
{"op":"mcm","clk":"989993832","pt":1580527036906,"mc":[{"id":"1.168136214","rc":[{"batl":[[2,7.8,18.93]],"ltp":5.2,"tv":143.55,"id":12925630}]}]}
{"op":"mcm","clk":"990004363","pt":1580527067032,"mc":[{"id":"1.168136214","rc":[{"batl":[[1,7.8,18.93],[2,8,25]],"ltp":5.2,"tv":143.55,"id":12925630}]}]}
{"op":"mcm","clk":"990004370","pt":1580527067234,"mc":[{"id":"1.168136214","rc":[{"batl":[[0,6.8,2.61],[1,7,1],[2,7.8,18.93]],"ltp":5.2,"tv":143.55,"id":12925630}]}]}
{"op":"mcm","clk":"990005647","pt":1580527099889,"mc":[{"id":"1.168136214","rc":[{"batl":[[0,7,1.93],[1,7.6,1.96]],"ltp":5.2,"tv":143.55,"id":12925630}]}]}
{"op":"mcm","clk":"990006167","pt":1580527114195,"mc":[{"id":"1.168136214","rc":[{"batl":[[1,7.4,5.32],[2,7.6,1.96]],"ltp":5.2,"tv":143.55,"id":12925630}]}]}
{"op":"mcm","clk":"990006785","pt":1580527131535,"mc":[{"id":"1.168136214","rc":[{"batl":[[1,7.2,1.81],[2,7.4,5.32]],"ltp":5.2,"tv":143.55,"id":12925630}]}]}
{"op":"mcm","clk":"990006862","pt":1580527133745,"mc":[{"id":"1.168136214","rc":[{"batl":[[2,7.8,18.93]],"ltp":5.2,"tv":143.55,"id":12925630}]}]}
{"op":"mcm","clk":"990007952","pt":1580527163107,"mc":[{"id":"1.168136214","rc":[{"batl":[[0,6.8,2.61],[1,7,1]],"ltp":5.2,"tv":143.55,"id":12925630}]}]}
{"op":"mcm","clk":"990009082","pt":1580527194753,"mc":[{"id":"1.168136214","rc":[{"batl":[[0,7,1.93],[1,7.6,1.96]],"ltp":5.2,"tv":143.55,"id":12925630}]}]}
{"op":"mcm","clk":"990009715","pt":1580527210699,"mc":[{"id":"1.168136214","rc":[{"batl":[[1,7.4,5.32],[2,7.6,1.96]],"ltp":5.2,"tv":143.55,"id":12925630}]}]}
{"op":"mcm","clk":"990010335","pt":1580527226471,"mc":[{"id":"1.168136214","rc":[{"batl":[[1,7.2,1.81],[2,7.4,5.32]],"ltp":5.2,"tv":143.55,"id":12925630}]}]}
{"op":"mcm","clk":"990010487","pt":1580527230186,"mc":[{"id":"1.168136214","rc":[{"batl":[[2,7.8,18.93]],"ltp":5.2,"tv":143.55,"id":12925630}]}]}
{"op":"mcm","clk":"990011593","pt":1580527257954,"mc":[{"id":"1.168136214","rc":[{"batl":[[0,6.8,2.61],[1,7,1]],"ltp":5.2,"tv":143.55,"id":12925630}]}]}
{"op":"mcm","clk":"990012925","pt":1580527289550,"mc":[{"id":"1.168136214","rc":[{"batl":[[0,7,1.93],[1,7.6,1.96]],"ltp":5.2,"tv":143.55,"id":12925630}]}]}
{"op":"mcm","clk":"990013662","pt":1580527306400,"mc":[{"id":"1.168136214","rc":[{"batl":[[1,7.4,5.32],[2,7.6,1.96]],"ltp":5.2,"tv":143.55,"id":12925630}]}]}
{"op":"mcm","clk":"990014325","pt":1580527321078,"mc":[{"id":"1.168136214","rc":[{"batl":[[2,7.8,18.93]],"ltp":5.2,"tv":143.55,"id":12925630}]}]}
{"op":"mcm","clk":"990014330","pt":1580527321180,"mc":[{"id":"1.168136214","rc":[{"batl":[[1,7.2,1.81],[2,7.4,5.32]],"ltp":5.2,"tv":143.55,"id":12925630}]}]}
{"op":"mcm","clk":"990014554","pt":1580527325804,"mc":[{"id":"1.168136214","rc":[{"batl":[[2,7.8,18.93]],"ltp":5.2,"tv":143.55,"id":12925630}]}]}
{"op":"mcm","clk":"990015816","pt":1580527352779,"mc":[{"id":"1.168136214","rc":[{"batl":[[0,6.8,2.61],[1,7,1]],"ltp":5.2,"tv":143.55,"id":12925630}]}]}
{"op":"mcm","clk":"990017262","pt":1580527384607,"mc":[{"id":"1.168136214","rc":[{"batl":[[0,7,1.93],[1,7.6,1.96]],"ltp":5.2,"tv":143.55,"id":12925630}]}]}
{"op":"mcm","clk":"990017974","pt":1580527402349,"mc":[{"id":"1.168136214","rc":[{"batl":[[1,7.4,5.32],[2,7.6,1.96]],"ltp":5.2,"tv":143.55,"id":12925630}]}]}
{"op":"mcm","clk":"990018542","pt":1580527416045,"mc":[{"id":"1.168136214","rc":[{"batl":[[1,7.2,1.81],[2,7.4,5.32]],"ltp":5.2,"tv":143.55,"id":12925630}]}]}
{"op":"mcm","clk":"990018827","pt":1580527422472,"mc":[{"id":"1.168136214","rc":[{"batl":[[2,7.8,18.93]],"ltp":5.2,"tv":143.55,"id":12925630}]}]}
{"op":"mcm","clk":"990019860","pt":1580527447695,"mc":[{"id":"1.168136214","rc":[{"batl":[[0,6.8,2.61],[1,7,1]],"ltp":5.2,"tv":143.55,"id":12925630}]}]}
{"op":"mcm","clk":"990021015","pt":1580527479136,"mc":[{"id":"1.168136214","rc":[{"batl":[[0,7,1.93],[1,7.6,1.96]],"ltp":5.2,"tv":143.55,"id":12925630}]}]}
{"op":"mcm","clk":"990021071","pt":1580527480629,"mc":[{"id":"1.168136214","rc":[{"batl":[[1,7.4,5.32],[2,7.6,1.96]],"ltp":5.2,"tv":143.55,"id":12925630}]}]}
{"op":"mcm","clk":"990022316","pt":1580527510752,"mc":[{"id":"1.168136214","rc":[{"batl":[[1,7.2,1.81],[2,7.4,5.32]],"ltp":5.2,"tv":143.55,"id":12925630}]}]}
{"op":"mcm","clk":"990022599","pt":1580527518788,"mc":[{"id":"1.168136214","rc":[{"batl":[[2,7.8,18.93]],"ltp":5.2,"tv":143.55,"id":12925630}]}]}
{"op":"mcm","clk":"990023420","pt":1580527542673,"mc":[{"id":"1.168136214","rc":[{"batl":[[0,6.8,2.61],[1,7,1]],"ltp":5.2,"tv":143.55,"id":12925630}]}]}
{"op":"mcm","clk":"990024792","pt":1580527574024,"mc":[{"id":"1.168136214","rc":[{"batl":[[0,7,1.93],[1,7.6,1.96]],"ltp":5.2,"tv":143.55,"id":12925630}]}]}
{"op":"mcm","clk":"990024973","pt":1580527578056,"mc":[{"id":"1.168136214","rc":[{"batl":[[1,7.4,5.32],[2,7.6,1.96]],"ltp":5.2,"tv":143.55,"id":12925630}]}]}
{"op":"mcm","clk":"990026109","pt":1580527605669,"mc":[{"id":"1.168136214","rc":[{"batl":[[1,7.2,1.81],[2,7.4,5.32]],"ltp":5.2,"tv":143.55,"id":12925630}]}]}
{"op":"mcm","clk":"990026642","pt":1580527617007,"mc":[{"id":"1.168136214","rc":[{"batl":[[2,7.8,18.93]],"ltp":5.2,"tv":143.55,"id":12925630}]}]}
{"op":"mcm","clk":"990027518","pt":1580527637503,"mc":[{"id":"1.168136214","rc":[{"batl":[[0,6.8,2.61],[1,7,1]],"ltp":5.2,"tv":143.55,"id":12925630}]}]}
{"op":"mcm","clk":"990028837","pt":1580527669378,"mc":[{"id":"1.168136214","rc":[{"batl":[[0,7,1.93],[1,7.6,1.96]],"ltp":5.2,"tv":143.55,"id":12925630}]}]}
{"op":"mcm","clk":"990029103","pt":1580527675109,"mc":[{"id":"1.168136214","rc":[{"batl":[[1,7.4,5.32],[2,7.6,1.96]],"ltp":5.2,"tv":143.55,"id":12925630}]}]}
{"op":"mcm","clk":"990030293","pt":1580527701049,"mc":[{"id":"1.168136214","rc":[{"batl":[[1,7.2,1.81],[2,7.4,5.32]],"ltp":5.2,"tv":143.55,"id":12925630}]}]}
{"op":"mcm","clk":"990030924","pt":1580527713759,"mc":[{"id":"1.168136214","rc":[{"batl":[[2,7.8,18.93]],"ltp":5.2,"tv":143.55,"id":12925630}]}]}
{"op":"mcm","clk":"990031817","pt":1580527732394,"mc":[{"id":"1.168136214","rc":[{"batl":[[0,6.8,2.61],[1,7,1]],"ltp":5.2,"tv":143.55,"id":12925630}]}]}
{"op":"mcm","clk":"990033228","pt":1580527764125,"mc":[{"id":"1.168136214","rc":[{"batl":[[0,7,1.93],[1,7.8,18.93],[2,8,25]],"ltp":5.2,"tv":143.55,"id":12925630}]}]}
{"op":"mcm","clk":"990033231","pt":1580527764229,"mc":[{"id":"1.168136214","rc":[{"batl":[[1,7.6,1.96],[2,7.8,18.93]],"ltp":5.2,"tv":143.55,"id":12925630}]}]}
{"op":"mcm","clk":"990033535","pt":1580527771427,"mc":[{"id":"1.168136214","rc":[{"batl":[[1,7.4,5.32],[2,7.6,1.96]],"ltp":5.2,"tv":143.55,"id":12925630}]}]}
{"op":"mcm","clk":"990034646","pt":1580527796063,"mc":[{"id":"1.168136214","rc":[{"batl":[[1,7.2,1.81],[2,7.4,5.32]],"ltp":5.2,"tv":143.55,"id":12925630}]}]}
{"op":"mcm","clk":"990035284","pt":1580527810165,"mc":[{"id":"1.168136214","rc":[{"batl":[[2,7.8,18.93]],"ltp":5.2,"tv":143.55,"id":12925630}]}]}
{"op":"mcm","clk":"990036026","pt":1580527827630,"mc":[{"id":"1.168136214","rc":[{"batl":[[0,6.8,2.61],[1,7,1]],"ltp":5.2,"tv":143.55,"id":12925630}]}]}
{"op":"mcm","clk":"990037154","pt":1580527859067,"mc":[{"id":"1.168136214","rc":[{"batl":[[0,7,1.93],[1,7.6,1.96]],"ltp":5.2,"tv":143.55,"id":12925630}]}]}
{"op":"mcm","clk":"990037505","pt":1580527869292,"mc":[{"id":"1.168136214","rc":[{"batl":[[1,7.4,5.32],[2,7.6,1.96]],"ltp":5.2,"tv":143.55,"id":12925630}]}]}
{"op":"mcm","clk":"990038195","pt":1580527890815,"mc":[{"id":"1.168136214","rc":[{"batl":[[1,7.2,1.81],[2,7.4,5.32]],"ltp":5.2,"tv":143.55,"id":12925630}]}]}
{"op":"mcm","clk":"990038794","pt":1580527907848,"mc":[{"id":"1.168136214","rc":[{"batl":[[2,7.8,18.93]],"ltp":5.2,"tv":143.55,"id":12925630}]}]}
{"op":"mcm","clk":"990039385","pt":1580527923076,"mc":[{"id":"1.168136214","rc":[{"batl":[[0,6.8,2.61],[1,7,1]],"ltp":5.2,"tv":143.55,"id":12925630}]}]}
{"op":"mcm","clk":"990050110","pt":1580527953990,"mc":[{"id":"1.168136214","rc":[{"batl":[[0,7,1.93],[1,7.6,1.96]],"ltp":5.2,"tv":143.55,"id":12925630}]}]}
{"op":"mcm","clk":"990050562","pt":1580527966315,"mc":[{"id":"1.168136214","rc":[{"batl":[[1,7.4,5.32],[2,7.6,1.96]],"ltp":5.2,"tv":143.55,"id":12925630}]}]}
{"op":"mcm","clk":"990051280","pt":1580527985782,"mc":[{"id":"1.168136214","rc":[{"batl":[[1,7.2,1.81],[2,7.4,5.32]],"ltp":5.2,"tv":143.55,"id":12925630}]}]}
{"op":"mcm","clk":"990051930","pt":1580528004721,"mc":[{"id":"1.168136214","rc":[{"batl":[[2,7.8,18.93]],"ltp":5.2,"tv":143.55,"id":12925630}]}]}
{"op":"mcm","clk":"990052343","pt":1580528017114,"mc":[{"id":"1.168136214","rc":[{"batl":[[1,7.8,18.93],[2,8,25]],"ltp":5.2,"tv":143.55,"id":12925630}]}]}
{"op":"mcm","clk":"990052362","pt":1580528017631,"mc":[{"id":"1.168136214","rc":[{"batl":[[0,6.8,2.61],[1,7,1],[2,7.8,18.93]],"ltp":5.2,"tv":143.55,"id":12925630}]}]}
{"op":"mcm","clk":"990053419","pt":1580528048966,"mc":[{"id":"1.168136214","rc":[{"batl":[[0,7,1.93],[1,7.6,1.96]],"ltp":5.2,"tv":143.55,"id":12925630}]}]}
{"op":"mcm","clk":"990054012","pt":1580528063085,"mc":[{"id":"1.168136214","rc":[{"batl":[[1,7.4,5.32],[2,7.6,1.96]],"ltp":5.2,"tv":143.55,"id":12925630}]}]}
{"op":"mcm","clk":"990054682","pt":1580528081009,"mc":[{"id":"1.168136214","rc":[{"batl":[[1,7.2,1.81],[2,7.4,5.32]],"ltp":5.2,"tv":143.55,"id":12925630}]}]}
{"op":"mcm","clk":"990054735","pt":1580528082495,"mc":[{"id":"1.168136214","rc":[{"batl":[[2,7.8,18.93]],"ltp":5.2,"tv":143.55,"id":12925630}]}]}
{"op":"mcm","clk":"990055848","pt":1580528112092,"mc":[{"id":"1.168136214","rc":[{"batl":[[1,7.8,18.93],[2,8,25]],"ltp":5.2,"tv":143.55,"id":12925630}]}]}
{"op":"mcm","clk":"990055852","pt":1580528112194,"mc":[{"id":"1.168136214","rc":[{"batl":[[0,6.8,2.61],[1,7,1],[2,7.8,18.93]],"ltp":5.2,"tv":143.55,"id":12925630}]}]}
{"op":"mcm","clk":"990056939","pt":1580528144135,"mc":[{"id":"1.168136214","rc":[{"batl":[[0,7,1.93],[1,7.6,1.96]],"ltp":5.2,"tv":143.55,"id":12925630}]}]}
{"op":"mcm","clk":"990057450","pt":1580528158455,"mc":[{"id":"1.168136214","rc":[{"batl":[[1,7.4,5.32],[2,7.6,1.96]],"ltp":5.2,"tv":143.55,"id":12925630}]}]}
{"op":"mcm","clk":"990058028","pt":1580528175088,"mc":[{"id":"1.168136214","rc":[{"batl":[[2,7.8,18.93]],"ltp":5.2,"tv":143.55,"id":12925630}]}]}
{"op":"mcm","clk":"990058031","pt":1580528175191,"mc":[{"id":"1.168136214","rc":[{"batl":[[1,7.2,1.81],[2,7.4,5.32]],"ltp":5.2,"tv":143.55,"id":12925630}]}]}
{"op":"mcm","clk":"990058140","pt":1580528178077,"mc":[{"id":"1.168136214","rc":[{"batl":[[2,7.8,18.93]],"ltp":5.2,"tv":143.55,"id":12925630}]}]}
{"op":"mcm","clk":"990059125","pt":1580528206941,"mc":[{"id":"1.168136214","rc":[{"batl":[[0,6.8,2.61],[1,7,1]],"ltp":5.2,"tv":143.55,"id":12925630}]}]}
{"op":"mcm","clk":"990060234","pt":1580528239154,"mc":[{"id":"1.168136214","rc":[{"batl":[[0,7,1.93],[1,7.6,1.96]],"ltp":5.2,"tv":143.55,"id":12925630}]}]}
{"op":"mcm","clk":"990060778","pt":1580528255087,"mc":[{"id":"1.168136214","rc":[{"batl":[[1,7.4,5.32],[2,7.6,1.96]],"ltp":5.2,"tv":143.55,"id":12925630}]}]}
{"op":"mcm","clk":"990061330","pt":1580528270904,"mc":[{"id":"1.168136214","rc":[{"batl":[[1,7.2,1.81],[2,7.4,5.32]],"ltp":5.2,"tv":143.55,"id":12925630}]}]}
{"op":"mcm","clk":"990061463","pt":1580528274702,"mc":[{"id":"1.168136214","rc":[{"batl":[[2,7.8,18.93]],"ltp":5.2,"tv":143.55,"id":12925630}]}]}
{"op":"mcm","clk":"990062459","pt":1580528302565,"mc":[{"id":"1.168136214","rc":[{"batl":[[0,6.8,2.61],[1,7,1]],"ltp":5.2,"tv":143.55,"id":12925630}]}]}
{"op":"mcm","clk":"990063558","pt":1580528334073,"mc":[{"id":"1.168136214","rc":[{"batl":[[0,7,1.93],[1,7.6,1.96]],"ltp":5.2,"tv":143.55,"id":12925630}]}]}
{"op":"mcm","clk":"990064199","pt":1580528352088,"mc":[{"id":"1.168136214","rc":[{"batl":[[1,7.4,5.32],[2,7.6,1.96]],"ltp":5.2,"tv":143.55,"id":12925630}]}]}
{"op":"mcm","clk":"990064658","pt":1580528365845,"mc":[{"id":"1.168136214","rc":[{"batl":[[1,7.2,1.81],[2,7.4,5.32]],"ltp":5.2,"tv":143.55,"id":12925630}]}]}
{"op":"mcm","clk":"990064868","pt":1580528372156,"mc":[{"id":"1.168136214","rc":[{"batl":[[2,7.8,18.93]],"ltp":5.2,"tv":143.55,"id":12925630}]}]}
{"op":"mcm","clk":"990065742","pt":1580528398078,"mc":[{"id":"1.168136214","rc":[{"batl":[[0,6.8,2.61],[1,7,1]],"ltp":5.2,"tv":143.55,"id":12925630}]}]}
{"op":"mcm","clk":"990066973","pt":1580528428833,"mc":[{"id":"1.168136214","rc":[{"batl":[[0,7,1.93],[1,7.6,1.96]],"ltp":5.2,"tv":143.55,"id":12925630}]}]}
{"op":"mcm","clk":"990066997","pt":1580528429812,"mc":[{"id":"1.168136214","rc":[{"batl":[[1,7.4,5.32],[2,7.6,1.96]],"ltp":5.2,"tv":143.55,"id":12925630}]}]}
{"op":"mcm","clk":"990068168","pt":1580528460464,"mc":[{"id":"1.168136214","rc":[{"batl":[[1,7.2,1.81],[2,7.4,5.32]],"ltp":5.2,"tv":143.55,"id":12925630}]}]}
{"op":"mcm","clk":"990068509","pt":1580528469089,"mc":[{"id":"1.168136214","rc":[{"batl":[[2,7.8,18.93]],"ltp":5.2,"tv":143.55,"id":12925630}]}]}
{"op":"mcm","clk":"990069360","pt":1580528491842,"mc":[{"id":"1.168136214","rc":[{"batl":[[0,6.8,2.61],[1,7,1]],"ltp":5.2,"tv":143.55,"id":12925630}]}]}
{"op":"mcm","clk":"990070589","pt":1580528523072,"mc":[{"id":"1.168136214","rc":[{"batl":[[0,7,1.93],[1,7.8,18.93],[2,8,25]],"ltp":5.2,"tv":143.55,"id":12925630}]}]}
{"op":"mcm","clk":"990070593","pt":1580528523176,"mc":[{"id":"1.168136214","rc":[{"batl":[[1,7.6,1.96],[2,7.8,18.93]],"ltp":5.2,"tv":143.55,"id":12925630}]}]}
{"op":"mcm","clk":"990070716","pt":1580528526368,"mc":[{"id":"1.168136214","rc":[{"batl":[[1,7.4,5.32],[2,7.6,1.96]],"ltp":5.2,"tv":143.55,"id":12925630}]}]}
{"op":"mcm","clk":"990071843","pt":1580528555031,"mc":[{"id":"1.168136214","rc":[{"batl":[[1,7.2,1.81],[2,7.4,5.32]],"ltp":5.2,"tv":143.55,"id":12925630}]}]}
{"op":"mcm","clk":"990072205","pt":1580528565060,"mc":[{"id":"1.168136214","rc":[{"batl":[[2,7.8,18.93]],"ltp":5.2,"tv":143.55,"id":12925630}]}]}
{"op":"mcm","clk":"990072939","pt":1580528586492,"mc":[{"id":"1.168136214","rc":[{"batl":[[0,6.8,2.61],[1,7,1]],"ltp":5.2,"tv":143.55,"id":12925630}]}]}
{"op":"mcm","clk":"990074094","pt":1580528618138,"mc":[{"id":"1.168136214","rc":[{"batl":[[0,7,1.93],[1,7.6,1.96]],"ltp":5.2,"tv":143.55,"id":12925630}]}]}
{"op":"mcm","clk":"990074280","pt":1580528623439,"mc":[{"id":"1.168136214","rc":[{"batl":[[1,7.4,5.32],[2,7.6,1.96]],"ltp":5.2,"tv":143.55,"id":12925630}]}]}
{"op":"mcm","clk":"990075168","pt":1580528650089,"mc":[{"id":"1.168136214","rc":[{"batl":[[1,7.2,1.81],[2,7.4,5.32]],"ltp":5.2,"tv":143.55,"id":12925630}]}]}
{"op":"mcm","clk":"990075587","pt":1580528661712,"mc":[{"id":"1.168136214","rc":[{"batl":[[2,7.8,18.93]],"ltp":5.2,"tv":143.55,"id":12925630}]}]}
{"op":"mcm","clk":"990076337","pt":1580528681838,"mc":[{"id":"1.168136214","rc":[{"batl":[[0,6.8,2.61],[1,7,1]],"ltp":5.2,"tv":143.55,"id":12925630}]}]}
{"op":"mcm","clk":"990077390","pt":1580528713596,"mc":[{"id":"1.168136214","rc":[{"batl":[[0,7,1.93],[1,7.6,1.96]],"ltp":5.2,"tv":143.55,"id":12925630}]}]}
{"op":"mcm","clk":"990077586","pt":1580528719571,"mc":[{"id":"1.168136214","rc":[{"batl":[[1,7.4,5.32],[2,7.6,1.96]],"ltp":5.2,"tv":143.55,"id":12925630}]}]}
{"op":"mcm","clk":"990078505","pt":1580528744927,"mc":[{"id":"1.168136214","rc":[{"batl":[[1,7.2,1.81],[2,7.4,5.32]],"ltp":5.2,"tv":143.55,"id":12925630}]}]}
{"op":"mcm","clk":"990078957","pt":1580528757422,"mc":[{"id":"1.168136214","rc":[{"batl":[[2,7.8,18.93]],"ltp":5.2,"tv":143.55,"id":12925630}]}]}
{"op":"mcm","clk":"990079712","pt":1580528776748,"mc":[{"id":"1.168136214","rc":[{"batl":[[0,6.8,2.61],[1,7,1]],"ltp":5.2,"tv":143.55,"id":12925630}]}]}
{"op":"mcm","clk":"990081290","pt":1580528808388,"mc":[{"id":"1.168136214","rc":[{"batl":[[0,7,1.93],[1,7.6,1.96]],"ltp":5.2,"tv":143.55,"id":12925630}]}]}
{"op":"mcm","clk":"990081706","pt":1580528816128,"mc":[{"id":"1.168136214","rc":[{"batl":[[1,7.4,5.32],[2,7.6,1.96]],"ltp":5.2,"tv":143.55,"id":12925630}]}]}
{"op":"mcm","clk":"990082816","pt":1580528840968,"mc":[{"id":"1.168136214","rc":[{"batl":[[1,7.2,1.81],[2,7.4,5.32]],"ltp":5.2,"tv":143.55,"id":12925630}]}]}
{"op":"mcm","clk":"990092676","pt":1580528854960,"mc":[{"id":"1.168136214","rc":[{"batl":[[2,7.8,18.93]],"ltp":5.2,"tv":143.55,"id":12925630}]}]}
{"op":"mcm","clk":"990093187","pt":1580528872900,"mc":[{"id":"1.168136214","rc":[{"batl":[[0,6.8,2.61],[1,7,1]],"ltp":5.2,"tv":143.55,"id":12925630}]}]}
{"op":"mcm","clk":"990094257","pt":1580528905135,"mc":[{"id":"1.168136214","rc":[{"batl":[[0,7,1.93],[1,7.6,1.96]],"ltp":5.2,"tv":143.55,"id":12925630}]}]}
{"op":"mcm","clk":"990094495","pt":1580528912351,"mc":[{"id":"1.168136214","rc":[{"batl":[[1,7.4,5.32],[2,7.6,1.96]],"ltp":5.2,"tv":143.55,"id":12925630}]}]}
{"op":"mcm","clk":"990095231","pt":1580528936983,"mc":[{"id":"1.168136214","rc":[{"batl":[[1,7.2,1.81],[2,7.4,5.32]],"ltp":5.2,"tv":143.55,"id":12925630}]}]}
{"op":"mcm","clk":"990095645","pt":1580528952039,"mc":[{"id":"1.168136214","rc":[{"batl":[[2,7.8,18.93]],"ltp":5.2,"tv":143.55,"id":12925630}]}]}
{"op":"mcm","clk":"990096158","pt":1580528968655,"mc":[{"id":"1.168136214","rc":[{"batl":[[0,6.8,2.61],[1,7,1]],"ltp":5.2,"tv":143.55,"id":12925630}]}]}
{"op":"mcm","clk":"990097398","pt":1580529000457,"mc":[{"id":"1.168136214","rc":[{"batl":[[0,7,1.93],[1,7.6,1.96]],"ltp":5.2,"tv":143.55,"id":12925630}]}]}
{"op":"mcm","clk":"990097699","pt":1580529008691,"mc":[{"id":"1.168136214","rc":[{"batl":[[1,7.4,5.32],[2,7.6,1.96]],"ltp":5.2,"tv":143.55,"id":12925630}]}]}
{"op":"mcm","clk":"990098496","pt":1580529032400,"mc":[{"id":"1.168136214","rc":[{"batl":[[1,7.2,1.81],[2,7.4,5.32]],"ltp":5.2,"tv":143.55,"id":12925630}]}]}
{"op":"mcm","clk":"990098970","pt":1580529046955,"mc":[{"id":"1.168136214","rc":[{"batl":[[2,7.8,18.93]],"ltp":5.2,"tv":143.55,"id":12925630}]}]}
{"op":"mcm","clk":"990099592","pt":1580529066038,"mc":[{"id":"1.168136214","rc":[{"batl":[[0,6.8,2.61],[1,7,1]],"ltp":5.2,"tv":143.55,"id":12925630}]}]}
{"op":"mcm","clk":"990100552","pt":1580529098573,"mc":[{"id":"1.168136214","rc":[{"batl":[[0,7,1.93],[1,7.6,1.96]],"ltp":5.2,"tv":143.55,"id":12925630}]}]}
{"op":"mcm","clk":"990100742","pt":1580529105887,"mc":[{"id":"1.168136214","rc":[{"batl":[[1,7.4,5.32],[2,7.6,1.96]],"ltp":5.2,"tv":143.55,"id":12925630}]}]}
{"op":"mcm","clk":"990101454","pt":1580529131615,"mc":[{"id":"1.168136214","rc":[{"batl":[[1,7.2,1.81],[2,7.4,5.32]],"ltp":5.2,"tv":143.55,"id":12925630}]}]}
{"op":"mcm","clk":"990101814","pt":1580529144562,"mc":[{"id":"1.168136214","rc":[{"batl":[[2,7.8,18.93]],"ltp":5.2,"tv":143.55,"id":12925630}]}]}
{"op":"mcm","clk":"990102514","pt":1580529164879,"mc":[{"id":"1.168136214","rc":[{"batl":[[0,6.8,2.61],[1,7,1]],"ltp":5.2,"tv":143.55,"id":12925630}]}]}
{"op":"mcm","clk":"990103619","pt":1580529197633,"mc":[{"id":"1.168136214","rc":[{"batl":[[0,7,1.93],[1,7.6,1.96]],"ltp":5.2,"tv":143.55,"id":12925630}]}]}
{"op":"mcm","clk":"990103763","pt":1580529203027,"mc":[{"id":"1.168136214","rc":[{"batl":[[1,7.4,5.32],[2,7.6,1.96]],"ltp":5.2,"tv":143.55,"id":12925630}]}]}
{"op":"mcm","clk":"990104525","pt":1580529230681,"mc":[{"id":"1.168136214","rc":[{"batl":[[1,7.2,1.81],[2,7.4,5.32]],"ltp":5.2,"tv":143.55,"id":12925630}]}]}
{"op":"mcm","clk":"990104869","pt":1580529240184,"mc":[{"id":"1.168136214","rc":[{"batl":[[0,2.04,25.21],[1,2.06,12.68],[2,2.08,35.91]],"ltp":1.99,"tv":1289.85,"id":17336468}]}]}
{"op":"mcm","clk":"990104953","pt":1580529242863,"mc":[{"id":"1.168136214","rc":[{"batl":[[2,7.8,18.93]],"ltp":5.2,"tv":143.55,"id":12925630}]}]}
{"op":"mcm","clk":"990105476","pt":1580529262885,"mc":[{"id":"1.168136214","rc":[{"batl":[[0,6.8,2.61],[1,7,1]],"ltp":5.2,"tv":143.55,"id":12925630}]}]}
{"op":"mcm","clk":"990106310","pt":1580529295060,"mc":[{"id":"1.168136214","rc":[{"batl":[[0,7,1.93],[1,7.8,18.93],[2,8,25]],"ltp":5.2,"tv":143.55,"id":12925630}]}]}
{"op":"mcm","clk":"990106314","pt":1580529295163,"mc":[{"id":"1.168136214","rc":[{"batl":[[1,7.6,1.96],[2,7.8,18.93]],"ltp":5.2,"tv":143.55,"id":12925630}]}]}
{"op":"mcm","clk":"990106432","pt":1580529300164,"mc":[{"id":"1.168136214","rc":[{"batl":[[1,7.4,5.32],[2,7.6,1.96]],"ltp":5.2,"tv":143.55,"id":12925630}]}]}
{"op":"mcm","clk":"990107154","pt":1580529327465,"mc":[{"id":"1.168136214","rc":[{"batl":[[1,7.2,1.81],[2,7.4,5.32]],"ltp":5.2,"tv":143.55,"id":12925630}]}]}
{"op":"mcm","clk":"990107531","pt":1580529339694,"mc":[{"id":"1.168136214","rc":[{"batl":[[2,7.8,18.93]],"ltp":5.2,"tv":143.55,"id":12925630}]}]}
{"op":"mcm","clk":"990108098","pt":1580529359737,"mc":[{"id":"1.168136214","rc":[{"batl":[[0,6.8,2.61],[1,7,1]],"ltp":5.2,"tv":143.55,"id":12925630}]}]}
{"op":"mcm","clk":"990109039","pt":1580529391883,"mc":[{"id":"1.168136214","rc":[{"batl":[[0,7,1.93],[1,7.6,1.96]],"ltp":5.2,"tv":143.55,"id":12925630}]}]}
{"op":"mcm","clk":"990109213","pt":1580529397249,"mc":[{"id":"1.168136214","rc":[{"batl":[[1,7.4,5.32],[2,7.6,1.96]],"ltp":5.2,"tv":143.55,"id":12925630}]}]}
{"op":"mcm","clk":"990109908","pt":1580529424122,"mc":[{"id":"1.168136214","rc":[{"batl":[[1,7.2,1.81],[2,7.4,5.32]],"ltp":5.2,"tv":143.55,"id":12925630}]}]}
{"op":"mcm","clk":"990110189","pt":1580529435960,"mc":[{"id":"1.168136214","rc":[{"batl":[[2,7.8,18.93]],"ltp":5.2,"tv":143.55,"id":12925630}]}]}
{"op":"mcm","clk":"990110709","pt":1580529455851,"mc":[{"id":"1.168136214","rc":[{"batl":[[0,6.8,2.61],[1,7,1]],"ltp":5.2,"tv":143.55,"id":12925630}]}]}
{"op":"mcm","clk":"990111592","pt":1580529487987,"mc":[{"id":"1.168136214","rc":[{"batl":[[0,7,1.93],[1,7.6,1.96]],"ltp":5.2,"tv":143.55,"id":12925630}]}]}
{"op":"mcm","clk":"990111791","pt":1580529495111,"mc":[{"id":"1.168136214","rc":[{"batl":[[1,7.4,5.32],[2,7.6,1.96]],"ltp":5.2,"tv":143.55,"id":12925630}]}]}
{"op":"mcm","clk":"990112441","pt":1580529519870,"mc":[{"id":"1.168136214","rc":[{"batl":[[1,7.2,1.81],[2,7.4,5.32]],"ltp":5.2,"tv":143.55,"id":12925630}]}]}
{"op":"mcm","clk":"990112834","pt":1580529532910,"mc":[{"id":"1.168136214","rc":[{"batl":[[2,7.8,18.93]],"ltp":5.2,"tv":143.55,"id":12925630}]}]}
{"op":"mcm","clk":"990113357","pt":1580529551863,"mc":[{"id":"1.168136214","rc":[{"batl":[[0,6.8,2.61],[1,7,1]],"ltp":5.2,"tv":143.55,"id":12925630}]}]}
{"op":"mcm","clk":"990114337","pt":1580529583787,"mc":[{"id":"1.168136214","rc":[{"batl":[[0,7,1.93],[1,7.6,1.96]],"ltp":5.2,"tv":143.55,"id":12925630}]}]}
{"op":"mcm","clk":"990114543","pt":1580529590800,"mc":[{"id":"1.168136214","rc":[{"batl":[[1,7.4,5.32],[2,7.6,1.96]],"ltp":5.2,"tv":143.55,"id":12925630}]}]}
{"op":"mcm","clk":"990115659","pt":1580529615797,"mc":[{"id":"1.168136214","rc":[{"batl":[[1,7.2,1.81],[2,7.4,5.32]],"ltp":5.2,"tv":143.55,"id":12925630}]}]}
{"op":"mcm","clk":"990116298","pt":1580529629607,"mc":[{"id":"1.168136214","rc":[{"batl":[[2,7.8,18.93]],"ltp":5.2,"tv":143.55,"id":12925630}]}]}
{"op":"mcm","clk":"990117071","pt":1580529652872,"mc":[{"id":"1.168136214","rc":[{"batl":[[0,6.8,2.61],[1,7,1]],"ltp":5.2,"tv":143.55,"id":12925630}]}]}
{"op":"mcm","clk":"990118324","pt":1580529691132,"mc":[{"id":"1.168136214","rc":[{"batl":[[0,7,1.93],[1,7.6,1.96]],"ltp":5.2,"tv":143.55,"id":12925630}]}]}
{"op":"mcm","clk":"990118834","pt":1580529705560,"mc":[{"id":"1.168136214","rc":[{"batl":[[1,7.4,5.32],[2,7.6,1.96]],"ltp":5.2,"tv":143.55,"id":12925630}]}]}
{"op":"mcm","clk":"990119966","pt":1580529728026,"mc":[{"id":"1.168136214","rc":[{"batl":[[1,7.2,1.81],[2,7.4,5.32]],"ltp":5.2,"tv":143.55,"id":12925630}]}]}
{"op":"mcm","clk":"990120624","pt":1580529744743,"mc":[{"id":"1.168136214","rc":[{"batl":[[2,7.8,18.93]],"ltp":5.2,"tv":143.55,"id":12925630}]}]}
{"op":"mcm","clk":"990130844","pt":1580529765459,"mc":[{"id":"1.168136214","rc":[{"batl":[[0,6.8,2.61],[1,7,1]],"ltp":5.2,"tv":143.55,"id":12925630}]}]}
{"op":"mcm","clk":"990132554","pt":1580529812432,"mc":[{"id":"1.168136214","rc":[{"batl":[[0,7,1.93],[1,7.6,1.96]],"ltp":5.2,"tv":143.55,"id":12925630}]}]}
{"op":"mcm","clk":"990132827","pt":1580529821283,"mc":[{"id":"1.168136214","rc":[{"batl":[[1,7.4,5.32],[2,7.6,1.96]],"ltp":5.2,"tv":143.55,"id":12925630}]}]}
{"op":"mcm","clk":"990133743","pt":1580529849533,"mc":[{"id":"1.168136214","rc":[{"batl":[[1,7.2,1.81],[2,7.4,5.32]],"ltp":5.2,"tv":143.55,"id":12925630}]}]}
{"op":"mcm","clk":"990134083","pt":1580529860062,"mc":[{"id":"1.168136214","rc":[{"batl":[[2,7.8,18.93]],"ltp":5.2,"tv":143.55,"id":12925630}]}]}
{"op":"mcm","clk":"990134862","pt":1580529886539,"mc":[{"id":"1.168136214","rc":[{"batl":[[0,6.8,2.61],[1,7,1]],"ltp":5.2,"tv":143.55,"id":12925630}]}]}
{"op":"mcm","clk":"990136047","pt":1580529925122,"mc":[{"id":"1.168136214","rc":[{"batl":[[0,7,1.93],[1,7.6,1.96]],"ltp":5.2,"tv":143.55,"id":12925630}]}]}
{"op":"mcm","clk":"990136368","pt":1580529937418,"mc":[{"id":"1.168136214","rc":[{"batl":[[1,7.4,5.32],[2,7.6,1.96]],"ltp":5.2,"tv":143.55,"id":12925630}]}]}
{"op":"mcm","clk":"990137098","pt":1580529961605,"mc":[{"id":"1.168136214","rc":[{"batl":[[1,7.2,1.81],[2,7.4,5.32]],"ltp":5.2,"tv":143.55,"id":12925630}]}]}
{"op":"mcm","clk":"990137514","pt":1580529975293,"mc":[{"id":"1.168136214","rc":[{"batl":[[2,7.8,18.93]],"ltp":5.2,"tv":143.55,"id":12925630}]}]}
{"op":"mcm","clk":"990138057","pt":1580529994059,"mc":[{"id":"1.168136214","rc":[{"batl":[[1,7.8,18.93],[2,8,25]],"ltp":5.2,"tv":143.55,"id":12925630}]}]}
{"op":"mcm","clk":"990138062","pt":1580529994162,"mc":[{"id":"1.168136214","rc":[{"batl":[[0,6.8,2.61],[1,7,1],[2,7.8,18.93]],"ltp":5.2,"tv":143.55,"id":12925630}]}]}
{"op":"mcm","clk":"990139237","pt":1580530026447,"mc":[{"id":"1.168136214","rc":[{"batl":[[0,7,1.93],[1,7.6,1.96]],"ltp":5.2,"tv":143.55,"id":12925630}]}]}
{"op":"mcm","clk":"990139566","pt":1580530034064,"mc":[{"id":"1.168136214","rc":[{"batl":[[1,7.4,5.32],[2,7.6,1.96]],"ltp":5.2,"tv":143.55,"id":12925630}]}]}
{"op":"mcm","clk":"990140458","pt":1580530058287,"mc":[{"id":"1.168136214","rc":[{"batl":[[1,7.2,1.81],[2,7.4,5.32]],"ltp":5.2,"tv":143.55,"id":12925630}]}]}
{"op":"mcm","clk":"990141043","pt":1580530072884,"mc":[{"id":"1.168136214","rc":[{"batl":[[2,7.8,18.93]],"ltp":5.2,"tv":143.55,"id":12925630}]}]}
{"op":"mcm","clk":"990142355","pt":1580530090441,"mc":[{"id":"1.168136214","rc":[{"batl":[[0,6.8,2.61],[1,7,1]],"ltp":5.2,"tv":143.55,"id":12925630}]}]}
{"op":"mcm","clk":"990144670","pt":1580530122583,"mc":[{"id":"1.168136214","rc":[{"batl":[[0,7,1.93],[1,7.6,1.96]],"ltp":5.2,"tv":143.55,"id":12925630}]}]}
{"op":"mcm","clk":"990145162","pt":1580530130204,"mc":[{"id":"1.168136214","rc":[{"batl":[[1,7.4,5.32],[2,7.6,1.96]],"ltp":5.2,"tv":143.55,"id":12925630}]}]}
{"op":"mcm","clk":"990146828","pt":1580530154569,"mc":[{"id":"1.168136214","rc":[{"batl":[[1,7.2,1.81],[2,7.4,5.32]],"ltp":5.2,"tv":143.55,"id":12925630}]}]}
{"op":"mcm","clk":"990147831","pt":1580530169060,"mc":[{"id":"1.168136214","rc":[{"batl":[[2,7.8,18.93]],"ltp":5.2,"tv":143.55,"id":12925630}]}]}
{"op":"mcm","clk":"990148871","pt":1580530186263,"mc":[{"id":"1.168136214","rc":[{"batl":[[0,6.8,2.61],[1,7,1]],"ltp":5.2,"tv":143.55,"id":12925630}]}]}
{"op":"mcm","clk":"990150898","pt":1580530219108,"mc":[{"id":"1.168136214","rc":[{"batl":[[0,7,1.93],[1,7.8,18.93],[2,8,25]],"ltp":5.2,"tv":143.55,"id":12925630}]}]}
{"op":"mcm","clk":"990150905","pt":1580530219213,"mc":[{"id":"1.168136214","rc":[{"batl":[[1,7.6,1.96],[2,7.8,18.93]],"ltp":5.2,"tv":143.55,"id":12925630}]}]}
{"op":"mcm","clk":"990151354","pt":1580530226066,"mc":[{"id":"1.168136214","rc":[{"batl":[[1,7.4,5.32],[2,7.6,1.96]],"ltp":5.2,"tv":143.55,"id":12925630}]}]}
{"op":"mcm","clk":"990152762","pt":1580530251310,"mc":[{"id":"1.168136214","rc":[{"batl":[[1,7.2,1.81],[2,7.4,5.32]],"ltp":5.2,"tv":143.55,"id":12925630}]}]}
{"op":"mcm","clk":"990153803","pt":1580530264815,"mc":[{"id":"1.168136214","rc":[{"batl":[[2,7.8,18.93]],"ltp":5.2,"tv":143.55,"id":12925630}]}]}
{"op":"mcm","clk":"990154947","pt":1580530283105,"mc":[{"id":"1.168136214","rc":[{"batl":[[1,7.8,18.93],[2,8,25]],"ltp":5.2,"tv":143.55,"id":12925630}]}]}
{"op":"mcm","clk":"990154956","pt":1580530283260,"mc":[{"id":"1.168136214","rc":[{"batl":[[0,6.8,2.61],[1,7,1],[2,7.8,18.93]],"ltp":5.2,"tv":143.55,"id":12925630}]}]}
{"op":"mcm","clk":"990156750","pt":1580530315152,"mc":[{"id":"1.168136214","rc":[{"batl":[[0,7,1.93],[1,7.6,1.96]],"ltp":5.2,"tv":143.55,"id":12925630}]}]}
{"op":"mcm","clk":"990157231","pt":1580530323446,"mc":[{"id":"1.168136214","rc":[{"batl":[[1,7.4,5.32],[2,7.6,1.96]],"ltp":5.2,"tv":143.55,"id":12925630}]}]}
{"op":"mcm","clk":"990158542","pt":1580530347015,"mc":[{"id":"1.168136214","rc":[{"batl":[[1,7.2,1.81],[2,7.4,5.32]],"ltp":5.2,"tv":143.55,"id":12925630}]}]}
{"op":"mcm","clk":"990159258","pt":1580530361307,"mc":[{"id":"1.168136214","rc":[{"batl":[[2,7.8,18.93]],"ltp":5.2,"tv":143.55,"id":12925630}]}]}
{"op":"mcm","clk":"990160510","pt":1580530379155,"mc":[{"id":"1.168136214","rc":[{"batl":[[0,6.8,2.61],[1,7,1]],"ltp":5.2,"tv":143.55,"id":12925630}]}]}
{"op":"mcm","clk":"990162753","pt":1580530411137,"mc":[{"id":"1.168136214","rc":[{"batl":[[0,7,1.93],[1,7.8,18.93],[2,8,25]],"ltp":5.2,"tv":143.55,"id":12925630}]}]}
{"op":"mcm","clk":"990162761","pt":1580530411240,"mc":[{"id":"1.168136214","rc":[{"batl":[[1,7.6,1.96],[2,7.8,18.93]],"ltp":5.2,"tv":143.55,"id":12925630}]}]}
{"op":"mcm","clk":"990163351","pt":1580530419928,"mc":[{"id":"1.168136214","rc":[{"batl":[[1,7.4,5.32],[2,7.6,1.96]],"ltp":5.2,"tv":143.55,"id":12925630}]}]}
{"op":"mcm","clk":"990164631","pt":1580530443888,"mc":[{"id":"1.168136214","rc":[{"batl":[[1,7.2,1.81],[2,7.4,5.32]],"ltp":5.2,"tv":143.55,"id":12925630}]}]}
{"op":"mcm","clk":"990165402","pt":1580530458507,"mc":[{"id":"1.168136214","rc":[{"batl":[[2,7.8,18.93]],"ltp":5.2,"tv":143.55,"id":12925630}]}]}
{"op":"mcm","clk":"990166285","pt":1580530475938,"mc":[{"id":"1.168136214","rc":[{"batl":[[0,6.8,2.61],[1,7,1]],"ltp":5.2,"tv":143.55,"id":12925630}]}]}
{"op":"mcm","clk":"990167807","pt":1580530507995,"mc":[{"id":"1.168136214","rc":[{"batl":[[0,7,1.93],[1,7.6,1.96]],"ltp":5.2,"tv":143.55,"id":12925630}]}]}
{"op":"mcm","clk":"990168283","pt":1580530516937,"mc":[{"id":"1.168136214","rc":[{"batl":[[1,7.4,5.32],[2,7.6,1.96]],"ltp":5.2,"tv":143.55,"id":12925630}]}]}
{"op":"mcm","clk":"990169430","pt":1580530540148,"mc":[{"id":"1.168136214","rc":[{"batl":[[1,7.2,1.81],[2,7.4,5.32]],"ltp":5.2,"tv":143.55,"id":12925630}]}]}
{"op":"mcm","clk":"990170199","pt":1580530555968,"mc":[{"id":"1.168136214","rc":[{"batl":[[2,7.8,18.93]],"ltp":5.2,"tv":143.55,"id":12925630}]}]}
{"op":"mcm","clk":"990170976","pt":1580530572124,"mc":[{"id":"1.168136214","rc":[{"batl":[[0,6.8,2.61],[1,7,1]],"ltp":5.2,"tv":143.55,"id":12925630}]}]}
{"op":"mcm","clk":"990173085","pt":1580530604012,"mc":[{"id":"1.168136214","rc":[{"batl":[[0,7,1.93],[1,7.6,1.96]],"ltp":5.2,"tv":143.55,"id":12925630}]}]}
{"op":"mcm","clk":"990173683","pt":1580530612933,"mc":[{"id":"1.168136214","rc":[{"batl":[[1,7.4,5.32],[2,7.6,1.96]],"ltp":5.2,"tv":143.55,"id":12925630}]}]}
{"op":"mcm","clk":"990174947","pt":1580530635895,"mc":[{"id":"1.168136214","rc":[{"batl":[[1,7.2,1.81],[2,7.4,5.32]],"ltp":5.2,"tv":143.55,"id":12925630}]}]}
{"op":"mcm","clk":"990175770","pt":1580530651303,"mc":[{"id":"1.168136214","rc":[{"batl":[[2,7.8,18.93]],"ltp":5.2,"tv":143.55,"id":12925630}]}]}
{"op":"mcm","clk":"990186073","pt":1580530667957,"mc":[{"id":"1.168136214","rc":[{"batl":[[0,6.8,2.61],[1,7,1]],"ltp":5.2,"tv":143.55,"id":12925630}]}]}
{"op":"mcm","clk":"990187800","pt":1580530699888,"mc":[{"id":"1.168136214","rc":[{"batl":[[0,7,1.93],[1,7.6,1.96]],"ltp":5.2,"tv":143.55,"id":12925630}]}]}
{"op":"mcm","clk":"990188415","pt":1580530710359,"mc":[{"id":"1.168136214","rc":[{"batl":[[1,7.4,5.32],[2,7.6,1.96]],"ltp":5.2,"tv":143.55,"id":12925630}]}]}
{"op":"mcm","clk":"990189561","pt":1580530731726,"mc":[{"id":"1.168136214","rc":[{"batl":[[1,7.2,1.81],[2,7.4,5.32]],"ltp":5.2,"tv":143.55,"id":12925630}]}]}
{"op":"mcm","clk":"990190543","pt":1580530748329,"mc":[{"id":"1.168136214","rc":[{"batl":[[2,7.8,18.93]],"ltp":5.2,"tv":143.55,"id":12925630}]}]}
{"op":"mcm","clk":"990191368","pt":1580530764138,"mc":[{"id":"1.168136214","rc":[{"batl":[[0,6.8,2.61],[1,7,1]],"ltp":5.2,"tv":143.55,"id":12925630}]}]}
{"op":"mcm","clk":"990193192","pt":1580530795843,"mc":[{"id":"1.168136214","rc":[{"batl":[[0,7,1.93],[1,7.6,1.96]],"ltp":5.2,"tv":143.55,"id":12925630}]}]}
{"op":"mcm","clk":"990193743","pt":1580530806723,"mc":[{"id":"1.168136214","rc":[{"batl":[[1,7.4,5.32],[2,7.6,1.96]],"ltp":5.2,"tv":143.55,"id":12925630}]}]}
{"op":"mcm","clk":"990194869","pt":1580530828093,"mc":[{"id":"1.168136214","rc":[{"batl":[[1,7.2,1.81],[2,7.4,5.32]],"ltp":5.2,"tv":143.55,"id":12925630}]}]}
{"op":"mcm","clk":"990195756","pt":1580530845221,"mc":[{"id":"1.168136214","rc":[{"batl":[[2,7.8,18.93]],"ltp":5.2,"tv":143.55,"id":12925630}]}]}
{"op":"mcm","clk":"990196520","pt":1580530860019,"mc":[{"id":"1.168136214","rc":[{"batl":[[0,6.8,2.61],[1,7,1]],"ltp":5.2,"tv":143.55,"id":12925630}]}]}
{"op":"mcm","clk":"990198272","pt":1580530892469,"mc":[{"id":"1.168136214","rc":[{"batl":[[0,7,1.93],[1,7.6,1.96]],"ltp":5.2,"tv":143.55,"id":12925630}]}]}
{"op":"mcm","clk":"990198849","pt":1580530903117,"mc":[{"id":"1.168136214","rc":[{"batl":[[1,7.4,5.32],[2,7.6,1.96]],"ltp":5.2,"tv":143.55,"id":12925630}]}]}
{"op":"mcm","clk":"990200134","pt":1580530924629,"mc":[{"id":"1.168136214","rc":[{"batl":[[1,7.2,1.81],[2,7.4,5.32]],"ltp":5.2,"tv":143.55,"id":12925630}]}]}
{"op":"mcm","clk":"990201073","pt":1580530943042,"mc":[{"id":"1.168136214","rc":[{"batl":[[2,7.8,18.93]],"ltp":5.2,"tv":143.55,"id":12925630}]}]}
{"op":"mcm","clk":"990201760","pt":1580530957097,"mc":[{"id":"1.168136214","rc":[{"batl":[[0,6.8,2.61],[1,7,1]],"ltp":5.2,"tv":143.55,"id":12925630}]}]}
{"op":"mcm","clk":"990203224","pt":1580530988940,"mc":[{"id":"1.168136214","rc":[{"batl":[[0,7,1.93],[1,7.6,1.96]],"ltp":5.2,"tv":143.55,"id":12925630}]}]}
{"op":"mcm","clk":"990203812","pt":1580531001642,"mc":[{"id":"1.168136214","rc":[{"batl":[[1,7.4,5.32],[2,7.6,1.96]],"ltp":5.2,"tv":143.55,"id":12925630}]}]}
{"op":"mcm","clk":"990204645","pt":1580531020974,"mc":[{"id":"1.168136214","rc":[{"batl":[[1,7.2,1.81],[2,7.4,5.32]],"ltp":5.2,"tv":143.55,"id":12925630}]}]}
{"op":"mcm","clk":"990205543","pt":1580531040809,"mc":[{"id":"1.168136214","rc":[{"batl":[[2,7.8,18.93]],"ltp":5.2,"tv":143.55,"id":12925630}]}]}
{"op":"mcm","clk":"990206038","pt":1580531052854,"mc":[{"id":"1.168136214","rc":[{"batl":[[0,6.8,2.61],[1,7,1]],"ltp":5.2,"tv":143.55,"id":12925630}]}]}
{"op":"mcm","clk":"990207355","pt":1580531085887,"mc":[{"id":"1.168136214","rc":[{"batl":[[0,7,1.93],[1,7.6,1.96]],"ltp":5.2,"tv":143.55,"id":12925630}]}]}
{"op":"mcm","clk":"990207992","pt":1580531099132,"mc":[{"id":"1.168136214","rc":[{"batl":[[1,7.4,5.32],[2,7.6,1.96]],"ltp":5.2,"tv":143.55,"id":12925630}]}]}
{"op":"mcm","clk":"990208761","pt":1580531117556,"mc":[{"id":"1.168136214","rc":[{"batl":[[1,7.2,1.81],[2,7.4,5.32]],"ltp":5.2,"tv":143.55,"id":12925630}]}]}
{"op":"mcm","clk":"990208808","pt":1580531118950,"mc":[{"id":"1.168136214","rc":[{"batl":[[2,7.8,18.93]],"ltp":5.2,"tv":143.55,"id":12925630}]}]}
{"op":"mcm","clk":"990210070","pt":1580531149400,"mc":[{"id":"1.168136214","rc":[{"batl":[[0,6.8,2.61],[1,7,1]],"ltp":5.2,"tv":143.55,"id":12925630}]}]}
{"op":"mcm","clk":"990211343","pt":1580531181443,"mc":[{"id":"1.168136214","rc":[{"batl":[[0,7,1.93],[1,7.6,1.96]],"ltp":5.2,"tv":143.55,"id":12925630}]}]}
{"op":"mcm","clk":"990211985","pt":1580531197484,"mc":[{"id":"1.168136214","rc":[{"batl":[[1,7.4,5.32],[2,7.6,1.96]],"ltp":5.2,"tv":143.55,"id":12925630}]}]}
{"op":"mcm","clk":"990212595","pt":1580531214000,"mc":[{"id":"1.168136214","rc":[{"batl":[[1,7.2,1.81],[2,7.4,5.32]],"ltp":5.2,"tv":143.55,"id":12925630}]}]}
{"op":"mcm","clk":"990212709","pt":1580531216829,"mc":[{"id":"1.168136214","rc":[{"batl":[[2,7.8,18.93]],"ltp":5.2,"tv":143.55,"id":12925630}]}]}
{"op":"mcm","clk":"990213816","pt":1580531245655,"mc":[{"id":"1.168136214","rc":[{"batl":[[0,6.8,2.61],[1,7,1]],"ltp":5.2,"tv":143.55,"id":12925630}]}]}
{"op":"mcm","clk":"990215192","pt":1580531277676,"mc":[{"id":"1.168136214","rc":[{"batl":[[0,7,1.93],[1,7.6,1.96]],"ltp":5.2,"tv":143.55,"id":12925630}]}]}
{"op":"mcm","clk":"990215925","pt":1580531293965,"mc":[{"id":"1.168136214","rc":[{"batl":[[1,7.4,5.32],[2,7.6,1.96]],"ltp":5.2,"tv":143.55,"id":12925630}]}]}
{"op":"mcm","clk":"990216575","pt":1580531309707,"mc":[{"id":"1.168136214","rc":[{"batl":[[1,7.2,1.81],[2,7.4,5.32]],"ltp":5.2,"tv":143.55,"id":12925630}]}]}
{"op":"mcm","clk":"990216778","pt":1580531313989,"mc":[{"id":"1.168136214","rc":[{"batl":[[2,7.8,18.93]],"ltp":5.2,"tv":143.55,"id":12925630}]}]}
{"op":"mcm","clk":"990217893","pt":1580531341821,"mc":[{"id":"1.168136214","rc":[{"batl":[[0,6.8,2.61],[1,7,1]],"ltp":5.2,"tv":143.55,"id":12925630}]}]}
{"op":"mcm","clk":"990219259","pt":1580531374583,"mc":[{"id":"1.168136214","rc":[{"batl":[[0,7,1.93],[1,7.6,1.96]],"ltp":5.2,"tv":143.55,"id":12925630}]}]}
{"op":"mcm","clk":"990219993","pt":1580531391985,"mc":[{"id":"1.168136214","rc":[{"batl":[[1,7.4,5.32],[2,7.6,1.96]],"ltp":5.2,"tv":143.55,"id":12925630}]}]}
{"op":"mcm","clk":"990220689","pt":1580531407099,"mc":[{"id":"1.168136214","rc":[{"batl":[[1,7.2,1.81],[2,7.4,5.32]],"ltp":5.2,"tv":143.55,"id":12925630}]}]}
{"op":"mcm","clk":"990220880","pt":1580531411999,"mc":[{"id":"1.168136214","rc":[{"batl":[[2,7.8,18.93]],"ltp":5.2,"tv":143.55,"id":12925630}]}]}
{"op":"mcm","clk":"990222025","pt":1580531439152,"mc":[{"id":"1.168136214","rc":[{"batl":[[0,6.8,2.61],[1,7,1]],"ltp":5.2,"tv":143.55,"id":12925630}]}]}
{"op":"mcm","clk":"990223950","pt":1580531471093,"mc":[{"id":"1.168136214","rc":[{"batl":[[0,7,1.93],[1,7.6,1.96]],"ltp":5.2,"tv":143.55,"id":12925630}]}]}
{"op":"mcm","clk":"990225173","pt":1580531489497,"mc":[{"id":"1.168136214","rc":[{"batl":[[1,7.4,5.32],[2,7.6,1.96]],"ltp":5.2,"tv":143.55,"id":12925630}]}]}
{"op":"mcm","clk":"990226028","pt":1580531504098,"mc":[{"id":"1.168136214","rc":[{"batl":[[1,7.2,1.81],[2,7.4,5.32]],"ltp":5.2,"tv":143.55,"id":12925630}]}]}
{"op":"mcm","clk":"990226414","pt":1580531508744,"mc":[{"id":"1.168136214","rc":[{"batl":[[2,7.8,18.93]],"ltp":5.2,"tv":143.55,"id":12925630}]}]}
{"op":"mcm","clk":"990227790","pt":1580531535061,"mc":[{"id":"1.168136214","rc":[{"batl":[[1,7.8,18.93],[2,8,25]],"ltp":5.2,"tv":143.55,"id":12925630}]}]}
{"op":"mcm","clk":"990227794","pt":1580531535163,"mc":[{"id":"1.168136214","rc":[{"batl":[[0,6.8,2.61],[1,7,1],[2,7.8,18.93]],"ltp":5.2,"tv":143.55,"id":12925630}]}]}
{"op":"mcm","clk":"990238817","pt":1580531567099,"mc":[{"id":"1.168136214","rc":[{"batl":[[0,7,1.93],[1,7.6,1.96]],"ltp":5.2,"tv":143.55,"id":12925630}]}]}
{"op":"mcm","clk":"990238842","pt":1580531567665,"mc":[{"id":"1.168136214","rc":[{"batl":[[1,7.4,5.32],[2,7.6,1.96]],"ltp":5.2,"tv":143.55,"id":12925630}]}]}
{"op":"mcm","clk":"990240643","pt":1580531599096,"mc":[{"id":"1.168136214","rc":[{"batl":[[1,7.2,1.81],[2,7.4,5.32]],"ltp":5.2,"tv":143.55,"id":12925630}]}]}
{"op":"mcm","clk":"990241000","pt":1580531606737,"mc":[{"id":"1.168136214","rc":[{"batl":[[2,7.8,18.93]],"ltp":5.2,"tv":143.55,"id":12925630}]}]}
{"op":"mcm","clk":"990242064","pt":1580531630964,"mc":[{"id":"1.168136214","rc":[{"batl":[[0,6.8,2.61],[1,7,1]],"ltp":5.2,"tv":143.55,"id":12925630}]}]}
{"op":"mcm","clk":"990243317","pt":1580531662876,"mc":[{"id":"1.168136214","rc":[{"batl":[[0,7,1.93],[1,7.6,1.96]],"ltp":5.2,"tv":143.55,"id":12925630}]}]}
{"op":"mcm","clk":"990243409","pt":1580531665034,"mc":[{"id":"1.168136214","rc":[{"batl":[[1,7.4,5.32],[2,7.6,1.96]],"ltp":5.2,"tv":143.55,"id":12925630}]}]}
{"op":"mcm","clk":"990244747","pt":1580531695151,"mc":[{"id":"1.168136214","rc":[{"batl":[[1,7.2,1.81],[2,7.4,5.32]],"ltp":5.2,"tv":143.55,"id":12925630}]}]}
{"op":"mcm","clk":"990245084","pt":1580531702755,"mc":[{"id":"1.168136214","rc":[{"batl":[[2,7.8,18.93]],"ltp":5.2,"tv":143.55,"id":12925630}]}]}
{"op":"mcm","clk":"990246188","pt":1580531728057,"mc":[{"id":"1.168136214","rc":[{"batl":[[0,6.8,2.61],[1,7,1]],"ltp":5.2,"tv":143.55,"id":12925630}]}]}
{"op":"mcm","clk":"990247512","pt":1580531760004,"mc":[{"id":"1.168136214","rc":[{"batl":[[0,7,1.93],[1,7.6,1.96]],"ltp":5.2,"tv":143.55,"id":12925630}]}]}
{"op":"mcm","clk":"990247606","pt":1580531762019,"mc":[{"id":"1.168136214","rc":[{"batl":[[1,7.4,5.32],[2,7.6,1.96]],"ltp":5.2,"tv":143.55,"id":12925630}]}]}
{"op":"mcm","clk":"990248753","pt":1580531791710,"mc":[{"id":"1.168136214","rc":[{"batl":[[1,7.2,1.81],[2,7.4,5.32]],"ltp":5.2,"tv":143.55,"id":12925630}]}]}
{"op":"mcm","clk":"990249059","pt":1580531801086,"mc":[{"id":"1.168136214","rc":[{"batl":[[2,7.8,18.93]],"ltp":5.2,"tv":143.55,"id":12925630}]}]}
{"op":"mcm","clk":"990249893","pt":1580531823731,"mc":[{"id":"1.168136214","rc":[{"batl":[[0,6.8,2.61],[1,7,1]],"ltp":5.2,"tv":143.55,"id":12925630}]}]}
{"op":"mcm","clk":"990251024","pt":1580531855661,"mc":[{"id":"1.168136214","rc":[{"batl":[[0,7,1.93],[1,7.6,1.96]],"ltp":5.2,"tv":143.55,"id":12925630}]}]}
{"op":"mcm","clk":"990251135","pt":1580531858560,"mc":[{"id":"1.168136214","rc":[{"batl":[[1,7.4,5.32],[2,7.6,1.96]],"ltp":5.2,"tv":143.55,"id":12925630}]}]}
{"op":"mcm","clk":"990252300","pt":1580531887824,"mc":[{"id":"1.168136214","rc":[{"batl":[[1,7.2,1.81],[2,7.4,5.32]],"ltp":5.2,"tv":143.55,"id":12925630}]}]}
{"op":"mcm","clk":"990252727","pt":1580531898513,"mc":[{"id":"1.168136214","rc":[{"batl":[[2,7.8,18.93]],"ltp":5.2,"tv":143.55,"id":12925630}]}]}
{"op":"mcm","clk":"990253642","pt":1580531919681,"mc":[{"id":"1.168136214","rc":[{"batl":[[0,6.8,2.61],[1,7,1]],"ltp":5.2,"tv":143.55,"id":12925630}]}]}
{"op":"mcm","clk":"990255145","pt":1580531952028,"mc":[{"id":"1.168136214","rc":[{"batl":[[0,7,1.93],[1,7.6,1.96]],"ltp":5.2,"tv":143.55,"id":12925630}]}]}
{"op":"mcm","clk":"990255366","pt":1580531956921,"mc":[{"id":"1.168136214","rc":[{"batl":[[1,7.4,5.32],[2,7.6,1.96]],"ltp":5.2,"tv":143.55,"id":12925630}]}]}
{"op":"mcm","clk":"990256753","pt":1580531983645,"mc":[{"id":"1.168136214","rc":[{"batl":[[1,7.2,1.81],[2,7.4,5.32]],"ltp":5.2,"tv":143.55,"id":12925630}]}]}
{"op":"mcm","clk":"990257178","pt":1580531995260,"mc":[{"id":"1.168136214","rc":[{"batl":[[2,7.8,18.93]],"ltp":5.2,"tv":143.55,"id":12925630}]}]}
{"op":"mcm","clk":"990258119","pt":1580532015487,"mc":[{"id":"1.168136214","rc":[{"batl":[[0,6.8,2.61],[1,7,1]],"ltp":5.2,"tv":143.55,"id":12925630}]}]}
{"op":"mcm","clk":"990259742","pt":1580532047544,"mc":[{"id":"1.168136214","rc":[{"batl":[[0,7,1.93],[1,7.6,1.96]],"ltp":5.2,"tv":143.55,"id":12925630}]}]}
{"op":"mcm","clk":"990260003","pt":1580532054044,"mc":[{"id":"1.168136214","rc":[{"batl":[[1,7.4,5.32],[2,7.6,1.96]],"ltp":5.2,"tv":143.55,"id":12925630}]}]}
{"op":"mcm","clk":"990261202","pt":1580532079772,"mc":[{"id":"1.168136214","rc":[{"batl":[[1,7.2,1.81],[2,7.4,5.32]],"ltp":5.2,"tv":143.55,"id":12925630}]}]}
{"op":"mcm","clk":"990261752","pt":1580532091478,"mc":[{"id":"1.168136214","rc":[{"batl":[[2,7.8,18.93]],"ltp":5.2,"tv":143.55,"id":12925630}]}]}
{"op":"mcm","clk":"990262665","pt":1580532111896,"mc":[{"id":"1.168136214","rc":[{"batl":[[0,6.8,2.61],[1,7,1]],"ltp":5.2,"tv":143.55,"id":12925630}]}]}
{"op":"mcm","clk":"990264329","pt":1580532144147,"mc":[{"id":"1.168136214","rc":[{"batl":[[0,7,1.93],[1,7.6,1.96]],"ltp":5.2,"tv":143.55,"id":12925630}]}]}
{"op":"mcm","clk":"990264601","pt":1580532149449,"mc":[{"id":"1.168136214","rc":[{"batl":[[1,7.4,5.32],[2,7.6,1.96]],"ltp":5.2,"tv":143.55,"id":12925630}]}]}
{"op":"mcm","clk":"990265853","pt":1580532176266,"mc":[{"id":"1.168136214","rc":[{"batl":[[1,7.2,1.81],[2,7.4,5.32]],"ltp":5.2,"tv":143.55,"id":12925630}]}]}
{"op":"mcm","clk":"990266444","pt":1580532188995,"mc":[{"id":"1.168136214","rc":[{"batl":[[2,7.8,18.93]],"ltp":5.2,"tv":143.55,"id":12925630}]}]}
{"op":"mcm","clk":"990266776","pt":1580532196819,"mc":[{"id":"1.168136214","rc":[{"batb":[[0,2,222],[1,1.99,15.14],[2,1.98,15.63]],"batl":[[1,2.08,35.91],[2,2.16,15.14]],"ltp":1.99,"tv":1289.85,"id":17336468}]}]}
{"op":"mcm","clk":"990266795","pt":1580532197289,"mc":[{"id":"1.168136214","rc":[{"batb":[[0,2.02,11.88],[1,2,222],[2,1.99,15.14]],"ltp":1.99,"tv":1289.85,"id":17336468}]}]}
{"op":"mcm","clk":"990267343","pt":1580532208612,"mc":[{"id":"1.168136214","rc":[{"batl":[[0,6.8,2.61],[1,7,1]],"ltp":5.2,"tv":143.55,"id":12925630}]}]}
{"op":"mcm","clk":"990268852","pt":1580532240505,"mc":[{"id":"1.168136214","rc":[{"batl":[[0,7,1.93],[1,7.6,1.96]],"ltp":5.2,"tv":143.55,"id":12925630}]}]}
{"op":"mcm","clk":"990269156","pt":1580532246707,"mc":[{"id":"1.168136214","rc":[{"batl":[[1,7.4,5.32],[2,7.6,1.96]],"ltp":5.2,"tv":143.55,"id":12925630}]}]}
{"op":"mcm","clk":"990269225","pt":1580532248004,"mc":[{"id":"1.168136214","rc":[{"trd":[[5.1,71.5],[5.2,38.44]],"batb":[[0,5.1,8.53],[1,5,2.97],[2,4.7,22.98]],"ltp":5.1,"tv":152.97,"id":12925630},{"trd":[[2.02,181.02]],"batb":[[0,2,222],[1,1.99,15.14],[2,1.98,15.63]],"ltp":2.02,"tv":1313.61,"id":17336468},{"trd":[[3.3,33.02]],"batb":[[0,3.25,9.97],[1,3.2,6.14],[2,3.15,6]],"ltp":3.3,"tv":511.68,"id":11981493}],"tv":1978.27}]}
{"op":"mcm","clk":"990270367","pt":1580532272319,"mc":[{"id":"1.168136214","rc":[{"batl":[[1,7.2,1.81],[2,7.4,5.32]],"ltp":5.1,"tv":152.97,"id":12925630}]}]}
{"op":"mcm","clk":"990270948","pt":1580532285573,"mc":[{"id":"1.168136214","rc":[{"batl":[[2,7.8,18.93]],"ltp":5.1,"tv":152.97,"id":12925630}]}]}
{"op":"mcm","clk":"990271809","pt":1580532304985,"mc":[{"id":"1.168136214","rc":[{"batl":[[0,6.8,2.61],[1,7,1]],"ltp":5.1,"tv":152.97,"id":12925630}]}]}
{"op":"mcm","clk":"990273120","pt":1580532337125,"mc":[{"id":"1.168136214","rc":[{"batl":[[0,7,1.93],[1,7.6,1.96]],"ltp":5.1,"tv":152.97,"id":12925630}]}]}
{"op":"mcm","clk":"990273376","pt":1580532342819,"mc":[{"id":"1.168136214","rc":[{"batl":[[1,7.4,5.32],[2,7.6,1.96]],"ltp":5.1,"tv":152.97,"id":12925630}]}]}
{"op":"mcm","clk":"990273933","pt":1580532354246,"mc":[{"id":"1.168136214","rc":[{"batl":[[0,3.7,2],[1,3.75,16],[2,4.2,50]],"ltp":3.3,"tv":511.68,"id":11981493}]}]}
{"op":"mcm","clk":"990274628","pt":1580532368348,"mc":[{"id":"1.168136214","rc":[{"batl":[[1,7.2,1.81],[2,7.4,5.32]],"ltp":5.1,"tv":152.97,"id":12925630}]}]}
{"op":"mcm","clk":"990275257","pt":1580532381357,"mc":[{"id":"1.168136214","rc":[{"batl":[[2,7.8,18.93]],"ltp":5.1,"tv":152.97,"id":12925630}]}]}
{"op":"mcm","clk":"990276170","pt":1580532394100,"mc":[{"id":"1.168136214","rc":[{"batb":[[0,5.2,3.31],[1,5.1,8.53],[2,5,2.97]],"ltp":5.1,"tv":152.97,"id":12925630},{"batb":[[0,2.02,8.53],[1,2,222],[2,1.99,15.14]],"ltp":2.02,"tv":1313.61,"id":17336468}]}]}
{"op":"mcm","clk":"990276472","pt":1580532400126,"mc":[{"id":"1.168136214","rc":[{"batl":[[1,7.8,18.93],[2,8,25]],"ltp":5.1,"tv":152.97,"id":12925630}]}]}
{"op":"mcm","clk":"990276477","pt":1580532400228,"mc":[{"id":"1.168136214","rc":[{"batl":[[0,6.8,2.61],[1,7,1],[2,7.8,18.93]],"ltp":5.1,"tv":152.97,"id":12925630}]}]}
{"op":"mcm","clk":"990276838","pt":1580532407623,"mc":[{"id":"1.168136214","rc":[{"trd":[[5.2,45.06]],"batb":[[0,5.1,8.53],[1,5,2.97],[2,4.7,22.98]],"ltp":5.2,"tv":159.59,"id":12925630},{"trd":[[2.02,198.08]],"batb":[[0,2,222],[1,1.99,15.14],[2,1.98,15.63]],"ltp":2.02,"tv":1330.66,"id":17336468},{"trd":[[3.25,9.82],[3.3,33.8]],"batb":[[0,3.25,4.67]],"ltp":3.25,"tv":522.28,"id":11981493}],"tv":2012.55}]}
{"op":"mcm","clk":"990277008","pt":1580532410723,"mc":[{"id":"1.168136214","rc":[{"batb":[[0,3.25,2.99]],"ltp":3.25,"tv":522.28,"id":11981493}]}]}
{"op":"mcm","clk":"990277335","pt":1580532418410,"mc":[{"id":"1.168136214","rc":[{"batb":[[1,3.2,7.82]],"ltp":3.25,"tv":522.28,"id":11981493}]}]}
{"op":"mcm","clk":"990277901","pt":1580532432448,"mc":[{"id":"1.168136214","rc":[{"batl":[[0,7,1.93],[1,7.6,1.96]],"ltp":5.2,"tv":159.59,"id":12925630}]}]}
{"op":"mcm","clk":"990278202","pt":1580532439654,"mc":[{"id":"1.168136214","rc":[{"batl":[[1,7.4,5.32],[2,7.6,1.96]],"ltp":5.2,"tv":159.59,"id":12925630}]}]}
{"op":"mcm","clk":"990288615","pt":1580532464366,"mc":[{"id":"1.168136214","rc":[{"batl":[[1,7.2,1.81],[2,7.4,5.32]],"ltp":5.2,"tv":159.59,"id":12925630}]}]}
{"op":"mcm","clk":"990289265","pt":1580532477619,"mc":[{"id":"1.168136214","rc":[{"batl":[[2,7.8,18.93]],"ltp":5.2,"tv":159.59,"id":12925630}]}]}
{"op":"mcm","clk":"990290195","pt":1580532497136,"mc":[{"id":"1.168136214","rc":[{"batl":[[1,7.8,18.93],[2,8,25]],"ltp":5.2,"tv":159.59,"id":12925630}]}]}
{"op":"mcm","clk":"990290206","pt":1580532497300,"mc":[{"id":"1.168136214","rc":[{"batl":[[0,6.8,2.61],[1,7,1],[2,7.8,18.93]],"ltp":5.2,"tv":159.59,"id":12925630}]}]}
{"op":"mcm","clk":"990290490","pt":1580532503429,"mc":[{"id":"1.168136214","rc":[{"trd":[[3.7,43]],"batb":[[0,3.25,3.51]],"batl":[[0,3.75,16],[1,4.2,50],[2,4.6,1.74]],"ltp":3.7,"tv":526.28,"id":11981493}],"tv":2016.55}]}
{"op":"mcm","clk":"990290830","pt":1580532511114,"mc":[{"id":"1.168136214","rc":[{"batb":[[2,3.1,75.78]],"ltp":3.7,"tv":526.28,"id":11981493}]}]}
{"op":"mcm","clk":"990291031","pt":1580532515133,"mc":[{"id":"1.168136214","rc":[{"batb":[[0,3.3,2.76],[1,3.25,2.99],[2,3.2,7.82]],"ltp":3.7,"tv":526.28,"id":11981493}]}]}
{"op":"mcm","clk":"990291499","pt":1580532524261,"mc":[{"id":"1.168136214","rc":[{"batb":[[1,3.25,5.99]],"ltp":3.7,"tv":526.28,"id":11981493}]}]}
{"op":"mcm","clk":"990291762","pt":1580532529278,"mc":[{"id":"1.168136214","rc":[{"batl":[[0,7,1.93],[1,7.6,1.96]],"ltp":5.2,"tv":159.59,"id":12925630}]}]}
{"op":"mcm","clk":"990292164","pt":1580532537291,"mc":[{"id":"1.168136214","rc":[{"batl":[[1,7.4,5.32],[2,7.6,1.96]],"ltp":5.2,"tv":159.59,"id":12925630}]}]}
{"op":"mcm","clk":"990293416","pt":1580532561123,"mc":[{"id":"1.168136214","rc":[{"batl":[[2,7.8,18.93]],"ltp":5.2,"tv":159.59,"id":12925630}]}]}
{"op":"mcm","clk":"990293456","pt":1580532561800,"mc":[{"id":"1.168136214","rc":[{"batl":[[1,7.2,1.81],[2,7.4,5.32]],"ltp":5.2,"tv":159.59,"id":12925630}]}]}
{"op":"mcm","clk":"990294248","pt":1580532576039,"mc":[{"id":"1.168136214","rc":[{"batl":[[2,7.8,18.93]],"ltp":5.2,"tv":159.59,"id":12925630}]}]}
{"op":"mcm","clk":"990295114","pt":1580532594044,"mc":[{"id":"1.168136214","rc":[{"batl":[[0,6.8,2.61],[1,7,1]],"ltp":5.2,"tv":159.59,"id":12925630}]}]}
{"op":"mcm","clk":"990296956","pt":1580532625083,"mc":[{"id":"1.168136214","rc":[{"batl":[[0,7,1.93],[1,7.8,18.93],[2,8,25]],"ltp":5.2,"tv":159.59,"id":12925630}]}]}
{"op":"mcm","clk":"990296966","pt":1580532625290,"mc":[{"id":"1.168136214","rc":[{"batl":[[1,7.6,1.96],[2,7.8,18.93]],"ltp":5.2,"tv":159.59,"id":12925630}]}]}
{"op":"mcm","clk":"990297484","pt":1580532634906,"mc":[{"id":"1.168136214","rc":[{"batl":[[1,7.4,5.32],[2,7.6,1.96]],"ltp":5.2,"tv":159.59,"id":12925630}]}]}
{"op":"mcm","clk":"990298684","pt":1580532657010,"mc":[{"id":"1.168136214","rc":[{"batl":[[1,7.2,1.81],[2,7.4,5.32]],"ltp":5.2,"tv":159.59,"id":12925630}]}]}
{"op":"mcm","clk":"990299556","pt":1580532673869,"mc":[{"id":"1.168136214","rc":[{"batl":[[2,7.8,18.93]],"ltp":5.2,"tv":159.59,"id":12925630}]}]}
{"op":"mcm","clk":"990300310","pt":1580532688915,"mc":[{"id":"1.168136214","rc":[{"batl":[[0,6.8,2.61],[1,7,1]],"ltp":5.2,"tv":159.59,"id":12925630}]}]}
{"op":"mcm","clk":"990302240","pt":1580532720913,"mc":[{"id":"1.168136214","rc":[{"batl":[[0,7,1.93],[1,7.6,1.96]],"ltp":5.2,"tv":159.59,"id":12925630}]}]}
{"op":"mcm","clk":"990302971","pt":1580532731959,"mc":[{"id":"1.168136214","rc":[{"batl":[[1,7.4,5.32],[2,7.6,1.96]],"ltp":5.2,"tv":159.59,"id":12925630}]}]}
{"op":"mcm","clk":"990304309","pt":1580532753055,"mc":[{"id":"1.168136214","rc":[{"batl":[[1,7.2,1.81],[2,7.4,5.32]],"ltp":5.2,"tv":159.59,"id":12925630}]}]}
{"op":"mcm","clk":"990305341","pt":1580532769983,"mc":[{"id":"1.168136214","rc":[{"batl":[[2,7.8,18.93]],"ltp":5.2,"tv":159.59,"id":12925630}]}]}
{"op":"mcm","clk":"990306219","pt":1580532785497,"mc":[{"id":"1.168136214","rc":[{"batl":[[0,6.8,2.61],[1,7,1]],"ltp":5.2,"tv":159.59,"id":12925630}]}]}
{"op":"mcm","clk":"990308076","pt":1580532818061,"mc":[{"id":"1.168136214","rc":[{"batl":[[0,7,1.93],[1,7.6,1.96]],"ltp":5.2,"tv":159.59,"id":12925630}]}]}
{"op":"mcm","clk":"990308626","pt":1580532828821,"mc":[{"id":"1.168136214","rc":[{"batl":[[1,7.4,5.32],[2,7.6,1.96]],"ltp":5.2,"tv":159.59,"id":12925630}]}]}
{"op":"mcm","clk":"990309832","pt":1580532850120,"mc":[{"id":"1.168136214","rc":[{"batl":[[1,7.2,1.81],[2,7.4,5.32]],"ltp":5.2,"tv":159.59,"id":12925630}]}]}
{"op":"mcm","clk":"990310810","pt":1580532866960,"mc":[{"id":"1.168136214","rc":[{"batl":[[2,7.8,18.93]],"ltp":5.2,"tv":159.59,"id":12925630}]}]}
{"op":"mcm","clk":"990311626","pt":1580532881566,"mc":[{"id":"1.168136214","rc":[{"batl":[[0,6.8,2.61],[1,7,1]],"ltp":5.2,"tv":159.59,"id":12925630}]}]}
{"op":"mcm","clk":"990313249","pt":1580532913798,"mc":[{"id":"1.168136214","rc":[{"batl":[[0,7,1.93],[1,7.6,1.96]],"ltp":5.2,"tv":159.59,"id":12925630}]}]}
{"op":"mcm","clk":"990313839","pt":1580532925200,"mc":[{"id":"1.168136214","rc":[{"batl":[[1,7.4,5.32],[2,7.6,1.96]],"ltp":5.2,"tv":159.59,"id":12925630}]}]}
{"op":"mcm","clk":"990314921","pt":1580532946059,"mc":[{"id":"1.168136214","rc":[{"batl":[[2,7.8,18.93]],"ltp":5.2,"tv":159.59,"id":12925630}]}]}
{"op":"mcm","clk":"990314970","pt":1580532947039,"mc":[{"id":"1.168136214","rc":[{"batl":[[1,7.2,1.81],[2,7.4,5.32]],"ltp":5.2,"tv":159.59,"id":12925630}]}]}
{"op":"mcm","clk":"990315159","pt":1580532951155,"mc":[{"id":"1.168136214","rc":[{"trd":[[2,564.08]],"batb":[[0,2,122]],"ltp":2.0,"tv":1530.66,"id":17336468}],"tv":2216.55}]}
{"op":"mcm","clk":"990315828","pt":1580532964257,"mc":[{"id":"1.168136214","rc":[{"batl":[[2,7.8,18.93]],"ltp":5.2,"tv":159.59,"id":12925630}]}]}
{"op":"mcm","clk":"990316577","pt":1580532978295,"mc":[{"id":"1.168136214","rc":[{"batl":[[0,6.8,2.61],[1,7,1]],"ltp":5.2,"tv":159.59,"id":12925630}]}]}
{"op":"mcm","clk":"990318425","pt":1580533010332,"mc":[{"id":"1.168136214","rc":[{"batl":[[0,7,1.93],[1,7.6,1.96]],"ltp":5.2,"tv":159.59,"id":12925630}]}]}
{"op":"mcm","clk":"990318990","pt":1580533021554,"mc":[{"id":"1.168136214","rc":[{"batl":[[1,7.4,5.32],[2,7.6,1.96]],"ltp":5.2,"tv":159.59,"id":12925630}]}]}
{"op":"mcm","clk":"990319968","pt":1580533042148,"mc":[{"id":"1.168136214","rc":[{"batl":[[2,7.8,18.93]],"ltp":5.2,"tv":159.59,"id":12925630}]}]}
{"op":"mcm","clk":"990320001","pt":1580533042878,"mc":[{"id":"1.168136214","rc":[{"batl":[[1,7.2,1.81],[2,7.4,5.32]],"ltp":5.2,"tv":159.59,"id":12925630}]}]}
{"op":"mcm","clk":"990320878","pt":1580533061118,"mc":[{"id":"1.168136214","rc":[{"batl":[[2,7.8,18.93]],"ltp":5.2,"tv":159.59,"id":12925630}]}]}
{"op":"mcm","clk":"990321540","pt":1580533074521,"mc":[{"id":"1.168136214","rc":[{"batl":[[0,6.8,2.61],[1,7,1]],"ltp":5.2,"tv":159.59,"id":12925630}]}]}
{"op":"mcm","clk":"990323371","pt":1580533108338,"mc":[{"id":"1.168136214","rc":[{"batl":[[0,7,1.93],[1,7.6,1.96]],"ltp":5.2,"tv":159.59,"id":12925630}]}]}
{"op":"mcm","clk":"990323991","pt":1580533119777,"mc":[{"id":"1.168136214","rc":[{"batl":[[1,7.4,5.32],[2,7.6,1.96]],"ltp":5.2,"tv":159.59,"id":12925630}]}]}
{"op":"mcm","clk":"990325144","pt":1580533140326,"mc":[{"id":"1.168136214","rc":[{"batl":[[1,7.2,1.81],[2,7.4,5.32]],"ltp":5.2,"tv":159.59,"id":12925630}]}]}
{"op":"mcm","clk":"990326101","pt":1580533158749,"mc":[{"id":"1.168136214","rc":[{"batl":[[2,7.8,18.93]],"ltp":5.2,"tv":159.59,"id":12925630}]}]}
{"op":"mcm","clk":"990326814","pt":1580533172155,"mc":[{"id":"1.168136214","rc":[{"batl":[[0,6.8,2.61],[1,7,1]],"ltp":5.2,"tv":159.59,"id":12925630}]}]}
{"op":"mcm","clk":"990328613","pt":1580533204080,"mc":[{"id":"1.168136214","rc":[{"batl":[[0,7,1.93],[1,7.6,1.96]],"ltp":5.2,"tv":159.59,"id":12925630}]}]}
{"op":"mcm","clk":"990329404","pt":1580533217615,"mc":[{"id":"1.168136214","rc":[{"batl":[[1,7.4,5.32],[2,7.6,1.96]],"ltp":5.2,"tv":159.59,"id":12925630}]}]}
{"op":"mcm","clk":"990329713","pt":1580533223949,"mc":[{"id":"1.168136214","rc":[{"batb":[[0,3.35,10.23],[1,3.3,2.24],[2,3.25,5.99]],"ltp":3.7,"tv":526.28,"id":11981493}]}]}
{"op":"mcm","clk":"990329750","pt":1580533224718,"mc":[{"id":"1.168136214","rc":[{"batb":[[0,3.3,2.24],[1,3.25,2.99],[2,3.2,7.82]],"batl":[[0,3.7,4],[1,3.75,16],[2,4.2,50]],"ltp":3.7,"tv":526.28,"id":11981493}]}]}
{"op":"mcm","clk":"990330676","pt":1580533241867,"mc":[{"id":"1.168136214","rc":[{"batl":[[0,3.75,16],[1,4.2,50],[2,4.6,1.74]],"ltp":3.7,"tv":526.28,"id":11981493}]}]}
{"op":"mcm","clk":"990331344","pt":1580533254053,"mc":[{"id":"1.168136214","rc":[{"batl":[[1,7.2,1.81],[2,7.4,5.32]],"ltp":5.2,"tv":159.59,"id":12925630}]}]}
{"op":"mcm","clk":"990331489","pt":1580533256944,"mc":[{"id":"1.168136214","rc":[{"batl":[[2,7.8,18.93]],"ltp":5.2,"tv":159.59,"id":12925630}]}]}
{"op":"mcm","clk":"990333823","pt":1580533304905,"mc":[{"id":"1.168136214","rc":[{"batl":[[0,6.8,2.61],[1,7,1]],"ltp":5.2,"tv":159.59,"id":12925630}]}]}
{"op":"mcm","clk":"990345650","pt":1580533355889,"mc":[{"id":"1.168136214","rc":[{"batl":[[0,7,1.93],[1,7.6,1.96]],"ltp":5.2,"tv":159.59,"id":12925630},{"batb":[[1,3.25,8.29]],"ltp":3.7,"tv":526.28,"id":11981493}]}]}
{"op":"mcm","clk":"990346479","pt":1580533375555,"mc":[{"id":"1.168136214","rc":[{"batl":[[1,7.4,5.32],[2,7.6,1.96]],"ltp":5.2,"tv":159.59,"id":12925630}]}]}
{"op":"mcm","clk":"990348424","pt":1580533419095,"mc":[{"id":"1.168136214","rc":[{"batl":[[1,7.2,1.81],[2,7.4,5.32]],"ltp":5.2,"tv":159.59,"id":12925630}]}]}
{"op":"mcm","clk":"990349178","pt":1580533436026,"mc":[{"id":"1.168136214","rc":[{"batl":[[2,7.8,18.93]],"ltp":5.2,"tv":159.59,"id":12925630}]}]}
{"op":"mcm","clk":"990351122","pt":1580533482662,"mc":[{"id":"1.168136214","rc":[{"batl":[[0,6.8,2.61],[1,7,1]],"ltp":5.2,"tv":159.59,"id":12925630}]}]}
{"op":"mcm","clk":"990354915","pt":1580533571737,"mc":[{"id":"1.168136214","rc":[{"batl":[[0,7,1.93],[1,7.6,1.96]],"ltp":5.2,"tv":159.59,"id":12925630}]}]}
{"op":"mcm","clk":"990355672","pt":1580533588567,"mc":[{"id":"1.168136214","rc":[{"batl":[[1,7.4,5.32],[2,7.6,1.96]],"ltp":5.2,"tv":159.59,"id":12925630}]}]}
{"op":"mcm","clk":"990356295","pt":1580533603893,"mc":[{"id":"1.168136214","rc":[{"batl":[[1,7.2,1.81],[2,7.4,5.32]],"ltp":5.2,"tv":159.59,"id":12925630}]}]}
{"op":"mcm","clk":"990356504","pt":1580533608176,"mc":[{"id":"1.168136214","rc":[{"batl":[[2,7.8,18.93]],"ltp":5.2,"tv":159.59,"id":12925630}]}]}
{"op":"mcm","clk":"990358114","pt":1580533636642,"mc":[{"id":"1.168136214","rc":[{"batl":[[0,6.8,2.61],[1,7,1]],"ltp":5.2,"tv":159.59,"id":12925630}]}]}
{"op":"mcm","clk":"990359701","pt":1580533668729,"mc":[{"id":"1.168136214","rc":[{"batl":[[0,7,1.93],[1,7.6,1.96]],"ltp":5.2,"tv":159.59,"id":12925630}]}]}
{"op":"mcm","clk":"990360538","pt":1580533685146,"mc":[{"id":"1.168136214","rc":[{"batl":[[1,7.4,5.32],[2,7.6,1.96]],"ltp":5.2,"tv":159.59,"id":12925630}]}]}
{"op":"mcm","clk":"990361214","pt":1580533700672,"mc":[{"id":"1.168136214","rc":[{"batl":[[1,7.2,1.81],[2,7.4,5.32]],"ltp":5.2,"tv":159.59,"id":12925630}]}]}
{"op":"mcm","clk":"990361379","pt":1580533704654,"mc":[{"id":"1.168136214","rc":[{"batl":[[2,7.8,18.93]],"ltp":5.2,"tv":159.59,"id":12925630}]}]}
{"op":"mcm","clk":"990362650","pt":1580533732891,"mc":[{"id":"1.168136214","rc":[{"batl":[[0,6.8,2.61],[1,7,1]],"ltp":5.2,"tv":159.59,"id":12925630}]}]}
{"op":"mcm","clk":"990364177","pt":1580533765564,"mc":[{"id":"1.168136214","rc":[{"batl":[[0,7,1.93],[1,7.6,1.96]],"ltp":5.2,"tv":159.59,"id":12925630}]}]}
{"op":"mcm","clk":"990364982","pt":1580533782798,"mc":[{"id":"1.168136214","rc":[{"batl":[[1,7.4,5.32],[2,7.6,1.96]],"ltp":5.2,"tv":159.59,"id":12925630}]}]}
{"op":"mcm","clk":"990365718","pt":1580533797588,"mc":[{"id":"1.168136214","rc":[{"batl":[[1,7.2,1.81],[2,7.4,5.32]],"ltp":5.2,"tv":159.59,"id":12925630}]}]}
{"op":"mcm","clk":"990365952","pt":1580533801781,"mc":[{"id":"1.168136214","rc":[{"batl":[[2,7.8,18.93]],"ltp":5.2,"tv":159.59,"id":12925630}]}]}
{"op":"mcm","clk":"990367388","pt":1580533829836,"mc":[{"id":"1.168136214","rc":[{"batl":[[0,6.8,2.61],[1,7,1]],"ltp":5.2,"tv":159.59,"id":12925630}]}]}
{"op":"mcm","clk":"990369055","pt":1580533861914,"mc":[{"id":"1.168136214","rc":[{"batl":[[0,7,1.93],[1,7.6,1.96]],"ltp":5.2,"tv":159.59,"id":12925630}]}]}
{"op":"mcm","clk":"990369957","pt":1580533878700,"mc":[{"id":"1.168136214","rc":[{"batl":[[1,7.4,5.32],[2,7.6,1.96]],"ltp":5.2,"tv":159.59,"id":12925630}]}]}
{"op":"mcm","clk":"990370712","pt":1580533894354,"mc":[{"id":"1.168136214","rc":[{"batl":[[1,7.2,1.81],[2,7.4,5.32]],"ltp":5.2,"tv":159.59,"id":12925630}]}]}
{"op":"mcm","clk":"990370892","pt":1580533897746,"mc":[{"id":"1.168136214","rc":[{"batl":[[2,7.8,18.93]],"ltp":5.2,"tv":159.59,"id":12925630}]}]}
{"op":"mcm","clk":"990372337","pt":1580533926576,"mc":[{"id":"1.168136214","rc":[{"batl":[[0,6.8,2.61],[1,7,1]],"ltp":5.2,"tv":159.59,"id":12925630}]}]}
{"op":"mcm","clk":"990373842","pt":1580533958720,"mc":[{"id":"1.168136214","rc":[{"batl":[[0,7,1.93],[1,7.6,1.96]],"ltp":5.2,"tv":159.59,"id":12925630}]}]}
{"op":"mcm","clk":"990374559","pt":1580533973854,"mc":[{"id":"1.168136214","rc":[{"batl":[[1,7.4,5.32],[2,7.6,1.96]],"ltp":5.2,"tv":159.59,"id":12925630}]}]}
{"op":"mcm","clk":"990375387","pt":1580533990999,"mc":[{"id":"1.168136214","rc":[{"batl":[[1,7.2,1.81],[2,7.4,5.32]],"ltp":5.2,"tv":159.59,"id":12925630}]}]}
{"op":"mcm","clk":"990375493","pt":1580533993055,"mc":[{"id":"1.168136214","rc":[{"batl":[[2,7.8,18.93]],"ltp":5.2,"tv":159.59,"id":12925630}]}]}
{"op":"mcm","clk":"990377135","pt":1580534022728,"mc":[{"id":"1.168136214","rc":[{"batl":[[0,6.8,2.61],[1,7,1]],"ltp":5.2,"tv":159.59,"id":12925630}]}]}
{"op":"mcm","clk":"990379034","pt":1580534054681,"mc":[{"id":"1.168136214","rc":[{"batl":[[0,7,1.93],[1,7.6,1.96]],"ltp":5.2,"tv":159.59,"id":12925630}]}]}
{"op":"mcm","clk":"990379798","pt":1580534068782,"mc":[{"id":"1.168136214","rc":[{"batl":[[1,7.4,5.32],[2,7.6,1.96]],"ltp":5.2,"tv":159.59,"id":12925630}]}]}
{"op":"mcm","clk":"990380847","pt":1580534087343,"mc":[{"id":"1.168136214","rc":[{"batl":[[1,7.2,1.81],[2,7.4,5.32]],"ltp":5.2,"tv":159.59,"id":12925630}]}]}
{"op":"mcm","clk":"990380903","pt":1580534088324,"mc":[{"id":"1.168136214","rc":[{"batl":[[2,7.8,18.93]],"ltp":5.2,"tv":159.59,"id":12925630}]}]}
{"op":"mcm","clk":"990382705","pt":1580534119331,"mc":[{"id":"1.168136214","rc":[{"batl":[[0,6.8,2.61],[1,7,1]],"ltp":5.2,"tv":159.59,"id":12925630}]}]}
{"op":"mcm","clk":"990384275","pt":1580534151321,"mc":[{"id":"1.168136214","rc":[{"batl":[[0,7,1.93],[1,7.6,1.96]],"ltp":5.2,"tv":159.59,"id":12925630}]}]}
{"op":"mcm","clk":"990385031","pt":1580534166097,"mc":[{"id":"1.168136214","rc":[{"batl":[[1,7.4,5.32],[2,7.6,1.96]],"ltp":5.2,"tv":159.59,"id":12925630}]}]}
{"op":"mcm","clk":"990385804","pt":1580534183113,"mc":[{"id":"1.168136214","rc":[{"batl":[[1,7.2,1.81],[2,7.4,5.32]],"ltp":5.2,"tv":159.59,"id":12925630}]}]}
{"op":"mcm","clk":"990385868","pt":1580534184714,"mc":[{"id":"1.168136214","rc":[{"batl":[[2,7.8,18.93]],"ltp":5.2,"tv":159.59,"id":12925630}]}]}
{"op":"mcm","clk":"990387322","pt":1580534213323,"mc":[{"id":"1.168136214","rc":[{"batl":[[0,3.7,4],[1,3.75,16],[2,4.2,50]],"ltp":3.7,"tv":526.28,"id":11981493}]}]}
{"op":"mcm","clk":"990387420","pt":1580534214618,"mc":[{"id":"1.168136214","rc":[{"batl":[[0,6.8,2.61],[1,7,1]],"ltp":5.2,"tv":159.59,"id":12925630}]}]}
{"op":"mcm","clk":"990389099","pt":1580534246555,"mc":[{"id":"1.168136214","rc":[{"batl":[[0,7,1.93],[1,7.6,1.96]],"ltp":5.2,"tv":159.59,"id":12925630}]}]}
{"op":"mcm","clk":"990399264","pt":1580534261152,"mc":[{"id":"1.168136214","rc":[{"batl":[[1,7.4,5.32],[2,7.6,1.96]],"ltp":5.2,"tv":159.59,"id":12925630}]}]}
{"op":"mcm","clk":"990400012","pt":1580534278738,"mc":[{"id":"1.168136214","rc":[{"batl":[[1,7.2,1.81],[2,7.4,5.32]],"ltp":5.2,"tv":159.59,"id":12925630}]}]}
{"op":"mcm","clk":"990400094","pt":1580534280749,"mc":[{"id":"1.168136214","rc":[{"batl":[[2,7.8,18.93]],"ltp":5.2,"tv":159.59,"id":12925630}]}]}
{"op":"mcm","clk":"990401373","pt":1580534310978,"mc":[{"id":"1.168136214","rc":[{"batl":[[0,6.8,2.61],[1,7,1]],"ltp":5.2,"tv":159.59,"id":12925630}]}]}
{"op":"mcm","clk":"990402766","pt":1580534343028,"mc":[{"id":"1.168136214","rc":[{"batl":[[0,7,1.93],[1,7.6,1.96]],"ltp":5.2,"tv":159.59,"id":12925630}]}]}
{"op":"mcm","clk":"990403479","pt":1580534358896,"mc":[{"id":"1.168136214","rc":[{"batl":[[1,7.4,5.32],[2,7.6,1.96]],"ltp":5.2,"tv":159.59,"id":12925630}]}]}
{"op":"mcm","clk":"990404129","pt":1580534374927,"mc":[{"id":"1.168136214","rc":[{"batl":[[1,7.2,1.81],[2,7.4,5.32]],"ltp":5.2,"tv":159.59,"id":12925630}]}]}
{"op":"mcm","clk":"990404205","pt":1580534376113,"mc":[{"id":"1.168136214","rc":[{"batb":[[0,2.02,2.02],[1,2,122],[2,1.99,15.14]],"ltp":2.0,"tv":1530.66,"id":17336468}]}]}
{"op":"mcm","clk":"990404247","pt":1580534376935,"mc":[{"id":"1.168136214","rc":[{"batb":[[0,2,122],[1,1.99,15.14],[2,1.98,15.63]],"ltp":2.0,"tv":1530.66,"id":17336468}]}]}
{"op":"mcm","clk":"990404381","pt":1580534379824,"mc":[{"id":"1.168136214","rc":[{"batl":[[2,7.8,18.93]],"ltp":5.2,"tv":159.59,"id":12925630}]}]}
{"op":"mcm","clk":"990405687","pt":1580534407062,"mc":[{"id":"1.168136214","rc":[{"batl":[[0,6.8,2.61],[1,7,1]],"ltp":5.2,"tv":159.59,"id":12925630}]}]}
{"op":"mcm","clk":"990407219","pt":1580534440817,"mc":[{"id":"1.168136214","rc":[{"batl":[[0,7,1.93],[1,7.6,1.96]],"ltp":5.2,"tv":159.59,"id":12925630}]}]}
{"op":"mcm","clk":"990408043","pt":1580534457131,"mc":[{"id":"1.168136214","rc":[{"batl":[[1,7.4,5.32],[2,7.6,1.96]],"ltp":5.2,"tv":159.59,"id":12925630}]}]}
{"op":"mcm","clk":"990408876","pt":1580534474063,"mc":[{"id":"1.168136214","rc":[{"batl":[[2,7.8,18.93]],"ltp":5.2,"tv":159.59,"id":12925630}]}]}
{"op":"mcm","clk":"990408915","pt":1580534474740,"mc":[{"id":"1.168136214","rc":[{"batl":[[1,7.2,1.81],[2,7.4,5.32]],"ltp":5.2,"tv":159.59,"id":12925630}]}]}
{"op":"mcm","clk":"990409039","pt":1580534477132,"mc":[{"id":"1.168136214","rc":[{"batl":[[2,7.8,18.93]],"ltp":5.2,"tv":159.59,"id":12925630}]}]}
{"op":"mcm","clk":"990410637","pt":1580534510511,"mc":[{"id":"1.168136214","rc":[{"batl":[[0,6.8,2.61],[1,7,1]],"ltp":5.2,"tv":159.59,"id":12925630}]}]}
{"op":"mcm","clk":"990412302","pt":1580534542123,"mc":[{"id":"1.168136214","rc":[{"batl":[[0,7,1.93],[1,7.6,1.96]],"ltp":5.2,"tv":159.59,"id":12925630}]}]}
{"op":"mcm","clk":"990412882","pt":1580534555166,"mc":[{"id":"1.168136214","rc":[{"batl":[[1,7.4,5.32],[2,7.6,1.96]],"ltp":5.2,"tv":159.59,"id":12925630}]}]}
{"op":"mcm","clk":"990413794","pt":1580534574153,"mc":[{"id":"1.168136214","rc":[{"batl":[[1,7.2,1.81],[2,7.4,5.32]],"ltp":5.2,"tv":159.59,"id":12925630}]}]}
{"op":"mcm","clk":"990413839","pt":1580534575074,"mc":[{"id":"1.168136214","rc":[{"batl":[[2,7.8,18.93]],"ltp":5.2,"tv":159.59,"id":12925630}]}]}
{"op":"mcm","clk":"990415517","pt":1580534606116,"mc":[{"id":"1.168136214","rc":[{"batl":[[1,7.8,18.93],[2,8,25]],"ltp":5.2,"tv":159.59,"id":12925630}]}]}
{"op":"mcm","clk":"990415540","pt":1580534606474,"mc":[{"id":"1.168136214","rc":[{"batl":[[0,6.8,2.61],[1,7,1],[2,7.8,18.93]],"ltp":5.2,"tv":159.59,"id":12925630}]}]}
{"op":"mcm","clk":"990417196","pt":1580534638050,"mc":[{"id":"1.168136214","rc":[{"batl":[[0,7,1.93],[1,7.6,1.96]],"ltp":5.2,"tv":159.59,"id":12925630}]}]}
{"op":"mcm","clk":"990417938","pt":1580534653065,"mc":[{"id":"1.168136214","rc":[{"batl":[[1,7.4,5.32],[2,7.6,1.96]],"ltp":5.2,"tv":159.59,"id":12925630}]}]}
{"op":"mcm","clk":"990418865","pt":1580534670096,"mc":[{"id":"1.168136214","rc":[{"batl":[[2,7.8,18.93]],"ltp":5.2,"tv":159.59,"id":12925630}]}]}
{"op":"mcm","clk":"990418927","pt":1580534671022,"mc":[{"id":"1.168136214","rc":[{"batl":[[1,7.2,1.81],[2,7.4,5.32]],"ltp":5.2,"tv":159.59,"id":12925630}]}]}
{"op":"mcm","clk":"990419017","pt":1580534672515,"mc":[{"id":"1.168136214","rc":[{"batl":[[2,7.8,18.93]],"ltp":5.2,"tv":159.59,"id":12925630}]}]}
{"op":"mcm","clk":"990420519","pt":1580534702122,"mc":[{"id":"1.168136214","rc":[{"batl":[[1,7.8,18.93],[2,8,25]],"ltp":5.2,"tv":159.59,"id":12925630}]}]}
{"op":"mcm","clk":"990420529","pt":1580534702325,"mc":[{"id":"1.168136214","rc":[{"batl":[[0,6.8,2.61],[1,7,1],[2,7.8,18.93]],"ltp":5.2,"tv":159.59,"id":12925630}]}]}
{"op":"mcm","clk":"990422126","pt":1580534733953,"mc":[{"id":"1.168136214","rc":[{"batl":[[0,7,1.93],[1,7.6,1.96]],"ltp":5.2,"tv":159.59,"id":12925630}]}]}
{"op":"mcm","clk":"990422988","pt":1580534749066,"mc":[{"id":"1.168136214","rc":[{"batl":[[1,7.4,5.32],[2,7.6,1.96]],"ltp":5.2,"tv":159.59,"id":12925630}]}]}
{"op":"mcm","clk":"990423917","pt":1580534765807,"mc":[{"id":"1.168136214","rc":[{"batl":[[1,7.2,1.81],[2,7.4,5.32]],"ltp":5.2,"tv":159.59,"id":12925630}]}]}
{"op":"mcm","clk":"990424159","pt":1580534769911,"mc":[{"id":"1.168136214","rc":[{"batl":[[2,7.8,18.93]],"ltp":5.2,"tv":159.59,"id":12925630}]}]}
{"op":"mcm","clk":"990425835","pt":1580534797149,"mc":[{"id":"1.168136214","rc":[{"batl":[[1,7.8,18.93],[2,8,25]],"ltp":5.2,"tv":159.59,"id":12925630}]}]}
{"op":"mcm","clk":"990425839","pt":1580534797249,"mc":[{"id":"1.168136214","rc":[{"batl":[[0,6.8,2.61],[1,7,1],[2,7.8,18.93]],"ltp":5.2,"tv":159.59,"id":12925630}]}]}
{"op":"mcm","clk":"990427721","pt":1580534828671,"mc":[{"id":"1.168136214","rc":[{"batl":[[0,7,1.93],[1,7.6,1.96]],"ltp":5.2,"tv":159.59,"id":12925630}]}]}
{"op":"mcm","clk":"990428738","pt":1580534845892,"mc":[{"id":"1.168136214","rc":[{"batl":[[1,7.4,5.32],[2,7.6,1.96]],"ltp":5.2,"tv":159.59,"id":12925630}]}]}
{"op":"mcm","clk":"990429834","pt":1580534860744,"mc":[{"id":"1.168136214","rc":[{"batl":[[1,7.2,1.81],[2,7.4,5.32]],"ltp":5.2,"tv":159.59,"id":12925630}]}]}
{"op":"mcm","clk":"990430126","pt":1580534865110,"mc":[{"id":"1.168136214","rc":[{"batl":[[2,7.8,18.93]],"ltp":5.2,"tv":159.59,"id":12925630}]}]}
{"op":"mcm","clk":"990431774","pt":1580534892776,"mc":[{"id":"1.168136214","rc":[{"batl":[[0,6.8,2.61],[1,7,1]],"ltp":5.2,"tv":159.59,"id":12925630}]}]}
{"op":"mcm","clk":"990433597","pt":1580534924092,"mc":[{"id":"1.168136214","rc":[{"batl":[[0,7,1.93],[1,7.6,1.96]],"ltp":5.2,"tv":159.59,"id":12925630}]}]}
{"op":"mcm","clk":"990434677","pt":1580534941920,"mc":[{"id":"1.168136214","rc":[{"batl":[[1,7.4,5.32],[2,7.6,1.96]],"ltp":5.2,"tv":159.59,"id":12925630}]}]}
{"op":"mcm","clk":"990435590","pt":1580534955656,"mc":[{"id":"1.168136214","rc":[{"batl":[[1,7.2,1.81],[2,7.4,5.32]],"ltp":5.2,"tv":159.59,"id":12925630}]}]}
{"op":"mcm","clk":"990435973","pt":1580534961562,"mc":[{"id":"1.168136214","rc":[{"batl":[[2,7.8,18.93]],"ltp":5.2,"tv":159.59,"id":12925630}]}]}
{"op":"mcm","clk":"990437714","pt":1580534989117,"mc":[{"id":"1.168136214","rc":[{"batl":[[0,6.8,2.61],[1,7,1]],"ltp":5.2,"tv":159.59,"id":12925630}]}]}
{"op":"mcm","clk":"990439643","pt":1580535020771,"mc":[{"id":"1.168136214","rc":[{"batl":[[0,7,1.93],[1,7.6,1.96]],"ltp":5.2,"tv":159.59,"id":12925630}]}]}
{"op":"mcm","clk":"990440705","pt":1580535038173,"mc":[{"id":"1.168136214","rc":[{"batl":[[1,7.4,5.32],[2,7.6,1.96]],"ltp":5.2,"tv":159.59,"id":12925630}]}]}
{"op":"mcm","clk":"990441546","pt":1580535052833,"mc":[{"id":"1.168136214","rc":[{"batl":[[1,7.2,1.81],[2,7.4,5.32]],"ltp":5.2,"tv":159.59,"id":12925630}]}]}
{"op":"mcm","clk":"990441849","pt":1580535057824,"mc":[{"id":"1.168136214","rc":[{"batl":[[2,7.8,18.93]],"ltp":5.2,"tv":159.59,"id":12925630}]}]}
{"op":"mcm","clk":"990443580","pt":1580535084139,"mc":[{"id":"1.168136214","rc":[{"batl":[[1,7.8,18.93],[2,8,25]],"ltp":5.2,"tv":159.59,"id":12925630}]}]}
{"op":"mcm","clk":"990443614","pt":1580535084654,"mc":[{"id":"1.168136214","rc":[{"batl":[[0,6.8,2.61],[1,7,1],[2,7.8,18.93]],"ltp":5.2,"tv":159.59,"id":12925630}]}]}
{"op":"mcm","clk":"990445444","pt":1580535115875,"mc":[{"id":"1.168136214","rc":[{"batl":[[0,7,1.93],[1,7.6,1.96]],"ltp":5.2,"tv":159.59,"id":12925630}]}]}
{"op":"mcm","clk":"990446680","pt":1580535134626,"mc":[{"id":"1.168136214","rc":[{"batl":[[1,7.4,5.32],[2,7.6,1.96]],"ltp":5.2,"tv":159.59,"id":12925630}]}]}
{"op":"mcm","clk":"990447712","pt":1580535147469,"mc":[{"id":"1.168136214","rc":[{"batl":[[1,7.2,1.81],[2,7.4,5.32]],"ltp":5.2,"tv":159.59,"id":12925630}]}]}
{"op":"mcm","clk":"990457681","pt":1580535154060,"mc":[{"id":"1.168136214","rc":[{"batl":[[2,7.8,18.93]],"ltp":5.2,"tv":159.59,"id":12925630}]}]}
{"op":"mcm","clk":"990459784","pt":1580535179023,"mc":[{"id":"1.168136214","rc":[{"batl":[[0,6.8,2.61],[1,7,1]],"ltp":5.2,"tv":159.59,"id":12925630}]}]}
{"op":"mcm","clk":"990461888","pt":1580535210373,"mc":[{"id":"1.168136214","rc":[{"batl":[[0,7,1.93],[1,7.6,1.96]],"ltp":5.2,"tv":159.59,"id":12925630}]}]}
{"op":"mcm","clk":"990461995","pt":1580535212151,"mc":[{"id":"1.168136214","rc":[{"batl":[[1,7.4,5.32],[2,7.6,1.96]],"ltp":5.2,"tv":159.59,"id":12925630}]}]}
{"op":"mcm","clk":"990463900","pt":1580535242092,"mc":[{"id":"1.168136214","rc":[{"batl":[[1,7.2,1.81],[2,7.4,5.32]],"ltp":5.2,"tv":159.59,"id":12925630}]}]}
{"op":"mcm","clk":"990464438","pt":1580535250122,"mc":[{"id":"1.168136214","rc":[{"batl":[[2,7.8,18.93]],"ltp":5.2,"tv":159.59,"id":12925630}]}]}
{"op":"mcm","clk":"990466096","pt":1580535274351,"mc":[{"id":"1.168136214","rc":[{"batl":[[0,6.8,2.61],[1,7,1]],"ltp":5.2,"tv":159.59,"id":12925630}]}]}
{"op":"mcm","clk":"990468261","pt":1580535305950,"mc":[{"id":"1.168136214","rc":[{"batl":[[0,7,1.93],[1,7.6,1.96]],"ltp":5.2,"tv":159.59,"id":12925630}]}]}
{"op":"mcm","clk":"990468352","pt":1580535307343,"mc":[{"id":"1.168136214","rc":[{"batl":[[1,7.4,5.32],[2,7.6,1.96]],"ltp":5.2,"tv":159.59,"id":12925630}]}]}
{"op":"mcm","clk":"990470153","pt":1580535337860,"mc":[{"id":"1.168136214","rc":[{"batl":[[1,7.2,1.81],[2,7.4,5.32]],"ltp":5.2,"tv":159.59,"id":12925630}]}]}
{"op":"mcm","clk":"990470595","pt":1580535345506,"mc":[{"id":"1.168136214","rc":[{"batl":[[2,7.8,18.93]],"ltp":5.2,"tv":159.59,"id":12925630}]}]}
{"op":"mcm","clk":"990472055","pt":1580535369747,"mc":[{"id":"1.168136214","rc":[{"batl":[[0,6.8,2.61],[1,7,1]],"ltp":5.2,"tv":159.59,"id":12925630}]}]}
{"op":"mcm","clk":"990473985","pt":1580535401902,"mc":[{"id":"1.168136214","rc":[{"batl":[[0,7,1.93],[1,7.6,1.96]],"ltp":5.2,"tv":159.59,"id":12925630}]}]}
{"op":"mcm","clk":"990474048","pt":1580535402984,"mc":[{"id":"1.168136214","rc":[{"batl":[[1,7.4,5.32],[2,7.6,1.96]],"ltp":5.2,"tv":159.59,"id":12925630}]}]}
{"op":"mcm","clk":"990475707","pt":1580535434446,"mc":[{"id":"1.168136214","rc":[{"batl":[[1,7.2,1.81],[2,7.4,5.32]],"ltp":5.2,"tv":159.59,"id":12925630}]}]}
{"op":"mcm","clk":"990476175","pt":1580535441669,"mc":[{"id":"1.168136214","rc":[{"batl":[[2,7.8,18.93]],"ltp":5.2,"tv":159.59,"id":12925630}]}]}
{"op":"mcm","clk":"990478383","pt":1580535467314,"mc":[{"id":"1.168136214","rc":[{"batl":[[0,6.8,2.61],[1,7,1]],"ltp":5.2,"tv":159.59,"id":12925630}]}]}
{"op":"mcm","clk":"990480365","pt":1580535499473,"mc":[{"id":"1.168136214","rc":[{"batl":[[0,7,1.93],[1,7.6,1.96]],"ltp":5.2,"tv":159.59,"id":12925630}]}]}
{"op":"mcm","clk":"990480413","pt":1580535500189,"mc":[{"id":"1.168136214","rc":[{"batl":[[1,7.4,5.32],[2,7.6,1.96]],"ltp":5.2,"tv":159.59,"id":12925630}]}]}
{"op":"mcm","clk":"990482203","pt":1580535531602,"mc":[{"id":"1.168136214","rc":[{"batl":[[1,7.2,1.81],[2,7.4,5.32]],"ltp":5.2,"tv":159.59,"id":12925630}]}]}
{"op":"mcm","clk":"990482571","pt":1580535539046,"mc":[{"id":"1.168136214","rc":[{"batl":[[2,7.8,18.93]],"ltp":5.2,"tv":159.59,"id":12925630}]}]}
{"op":"mcm","clk":"990483787","pt":1580535563040,"mc":[{"id":"1.168136214","rc":[{"batl":[[0,6.8,2.61],[1,7,1]],"ltp":5.2,"tv":159.59,"id":12925630}]}]}
{"op":"mcm","clk":"990485633","pt":1580535594800,"mc":[{"id":"1.168136214","rc":[{"batl":[[0,7,1.93],[1,7.6,1.96]],"ltp":5.2,"tv":159.59,"id":12925630}]}]}
{"op":"mcm","clk":"990485790","pt":1580535597526,"mc":[{"id":"1.168136214","rc":[{"batl":[[1,7.4,5.32],[2,7.6,1.96]],"ltp":5.2,"tv":159.59,"id":12925630}]}]}
{"op":"mcm","clk":"990487392","pt":1580535627134,"mc":[{"id":"1.168136214","rc":[{"batl":[[2,7.8,18.93]],"ltp":5.2,"tv":159.59,"id":12925630}]}]}
{"op":"mcm","clk":"990487406","pt":1580535627341,"mc":[{"id":"1.168136214","rc":[{"batl":[[1,7.2,1.81],[2,7.4,5.32]],"ltp":5.2,"tv":159.59,"id":12925630}]}]}
{"op":"mcm","clk":"990487939","pt":1580535636577,"mc":[{"id":"1.168136214","rc":[{"batl":[[2,7.8,18.93]],"ltp":5.2,"tv":159.59,"id":12925630}]}]}
{"op":"mcm","clk":"990489403","pt":1580535661311,"mc":[{"id":"1.168136214","rc":[{"batl":[[0,6.8,2.61],[1,7,1]],"ltp":5.2,"tv":159.59,"id":12925630}]}]}
{"op":"mcm","clk":"990491418","pt":1580535694979,"mc":[{"id":"1.168136214","rc":[{"batl":[[0,7,1.93],[1,7.6,1.96]],"ltp":5.2,"tv":159.59,"id":12925630}]}]}
{"op":"mcm","clk":"990492454","pt":1580535712803,"mc":[{"id":"1.168136214","rc":[{"batl":[[1,7.4,5.32],[2,7.6,1.96]],"ltp":5.2,"tv":159.59,"id":12925630}]}]}
{"op":"mcm","clk":"990493305","pt":1580535728020,"mc":[{"id":"1.168136214","rc":[{"batl":[[1,7.2,1.81],[2,7.4,5.32]],"ltp":5.2,"tv":159.59,"id":12925630}]}]}
{"op":"mcm","clk":"990493545","pt":1580535732417,"mc":[{"id":"1.168136214","rc":[{"batl":[[2,7.8,18.93]],"ltp":5.2,"tv":159.59,"id":12925630}]}]}
{"op":"mcm","clk":"990495080","pt":1580535760079,"mc":[{"id":"1.168136214","rc":[{"batl":[[0,6.8,2.61],[1,7,1]],"ltp":5.2,"tv":159.59,"id":12925630}]}]}
{"op":"mcm","clk":"990496845","pt":1580535791710,"mc":[{"id":"1.168136214","rc":[{"batl":[[0,7,1.93],[1,7.6,1.96]],"ltp":5.2,"tv":159.59,"id":12925630}]}]}
{"op":"mcm","clk":"990497746","pt":1580535808620,"mc":[{"id":"1.168136214","rc":[{"batl":[[1,7.4,5.32],[2,7.6,1.96]],"ltp":5.2,"tv":159.59,"id":12925630}]}]}
{"op":"mcm","clk":"990498575","pt":1580535823455,"mc":[{"id":"1.168136214","rc":[{"batl":[[1,7.2,1.81],[2,7.4,5.32]],"ltp":5.2,"tv":159.59,"id":12925630}]}]}
{"op":"mcm","clk":"990498825","pt":1580535827982,"mc":[{"id":"1.168136214","rc":[{"batl":[[2,7.8,18.93]],"ltp":5.2,"tv":159.59,"id":12925630}]}]}
{"op":"mcm","clk":"990500625","pt":1580535857373,"mc":[{"id":"1.168136214","rc":[{"batl":[[0,6.8,2.61],[1,7,1]],"ltp":5.2,"tv":159.59,"id":12925630}]}]}
{"op":"mcm","clk":"990502348","pt":1580535889336,"mc":[{"id":"1.168136214","rc":[{"batl":[[0,7,1.93],[1,7.6,1.96]],"ltp":5.2,"tv":159.59,"id":12925630}]}]}
{"op":"mcm","clk":"990503156","pt":1580535904350,"mc":[{"id":"1.168136214","rc":[{"batl":[[1,7.4,5.32],[2,7.6,1.96]],"ltp":5.2,"tv":159.59,"id":12925630}]}]}
{"op":"mcm","clk":"990504174","pt":1580535921562,"mc":[{"id":"1.168136214","rc":[{"batl":[[1,7.2,1.81],[2,7.4,5.32]],"ltp":5.2,"tv":159.59,"id":12925630}]}]}
{"op":"mcm","clk":"990504316","pt":1580535923931,"mc":[{"id":"1.168136214","rc":[{"batl":[[2,7.8,18.93]],"ltp":5.2,"tv":159.59,"id":12925630}]}]}
{"op":"mcm","clk":"990505881","pt":1580535954293,"mc":[{"id":"1.168136214","rc":[{"batl":[[0,6.8,2.61],[1,7,1]],"ltp":5.2,"tv":159.59,"id":12925630}]}]}
{"op":"mcm","clk":"990507735","pt":1580535987078,"mc":[{"id":"1.168136214","rc":[{"batl":[[0,7,1.93],[1,7.6,1.96]],"ltp":5.2,"tv":159.59,"id":12925630}]}]}
{"op":"mcm","clk":"990508489","pt":1580536000828,"mc":[{"id":"1.168136214","rc":[{"batl":[[1,7.4,5.32],[2,7.6,1.96]],"ltp":5.2,"tv":159.59,"id":12925630}]}]}
{"op":"mcm","clk":"990509663","pt":1580536019945,"mc":[{"id":"1.168136214","rc":[{"batl":[[1,7.2,1.81],[2,7.8,18.93]],"ltp":5.2,"tv":159.59,"id":12925630}]}]}
{"op":"mcm","clk":"990511428","pt":1580536051391,"mc":[{"id":"1.168136214","rc":[{"batl":[[0,6.8,2.61],[1,7,1]],"ltp":5.2,"tv":159.59,"id":12925630}]}]}
{"op":"mcm","clk":"990522570","pt":1580536082784,"mc":[{"id":"1.168136214","rc":[{"batl":[[0,7,1.93],[1,7.6,1.96]],"ltp":5.2,"tv":159.59,"id":12925630}]}]}
{"op":"mcm","clk":"990523225","pt":1580536096324,"mc":[{"id":"1.168136214","rc":[{"batl":[[1,7.4,5.32],[2,7.6,1.96]],"ltp":5.2,"tv":159.59,"id":12925630}]}]}
{"op":"mcm","clk":"990523677","pt":1580536103639,"mc":[{"id":"1.168136214","rc":[{"batl":[[1,2.06,2],[2,2.08,35.91]],"ltp":2.0,"tv":1530.66,"id":17336468}]}]}
{"op":"mcm","clk":"990524304","pt":1580536114140,"mc":[{"id":"1.168136214","rc":[{"batl":[[1,7.2,1.81],[2,7.4,5.32]],"ltp":5.2,"tv":159.59,"id":12925630}]}]}
{"op":"mcm","clk":"990524407","pt":1580536115645,"mc":[{"id":"1.168136214","rc":[{"batl":[[2,7.8,18.93]],"ltp":5.2,"tv":159.59,"id":12925630}]}]}
{"op":"mcm","clk":"990526249","pt":1580536145676,"mc":[{"id":"1.168136214","rc":[{"batl":[[0,6.8,2.61],[1,7,1]],"ltp":5.2,"tv":159.59,"id":12925630}]}]}
{"op":"mcm","clk":"990527026","pt":1580536160281,"mc":[{"id":"1.168136214","rc":[{"trd":[[2,574.08]],"batb":[[0,2,117]],"ltp":2.0,"tv":1540.66,"id":17336468}],"tv":2226.55}]}
{"op":"mcm","clk":"990528043","pt":1580536176893,"mc":[{"id":"1.168136214","rc":[{"batl":[[0,7,1.93],[1,7.6,1.96]],"ltp":5.2,"tv":159.59,"id":12925630}]}]}
{"op":"mcm","clk":"990528922","pt":1580536192617,"mc":[{"id":"1.168136214","rc":[{"batl":[[1,7.4,5.32],[2,7.6,1.96]],"ltp":5.2,"tv":159.59,"id":12925630}]}]}
{"op":"mcm","clk":"990529676","pt":1580536208431,"mc":[{"id":"1.168136214","rc":[{"batl":[[1,7.2,1.81],[2,7.4,5.32]],"ltp":5.2,"tv":159.59,"id":12925630}]}]}
