{"op":"mcm","clk":"987754447","pt":1580470905697,"mc":[{"id":"1.168130661","marketDefinition":{"bspMarket":true,"turnInPlayEnabled":true,"persistenceEnabled":true,"marketBaseRate":5.0,"eventId":"29678694","eventTypeId":"7","numberOfWinners":1,"bettingType":"ODDS","marketType":"WIN","marketTime":"2020-02-01T12:35:00.000Z","suspendTime":"2020-02-01T12:35:00.000Z","bspReconciled":false,"complete":true,"inPlay":false,"crossMatching":false,"runnersVoidable":false,"numberOfActiveRunners":6,"betDelay":0,"status":"OPEN","runners":[{"adjustmentFactor":33.12,"status":"ACTIVE","sortPriority":1,"id":26314798,"name":"Ayr Harbour"},{"adjustmentFactor":30.53,"status":"ACTIVE","sortPriority":2,"id":25238892,"name":"Phuket Power"},{"adjustmentFactor":14.91,"status":"ACTIVE","sortPriority":3,"id":420,"name":"Barking Mad"},{"adjustmentFactor":8.45,"status":"ACTIVE","sortPriority":4,"id":24420205,"name":"Rodney Le Roc"},{"adjustmentFactor":7.01,"status":"ACTIVE","sortPriority":5,"id":24707172,"name":"Thomas Lanfiere"},{"adjustmentFactor":5.95,"status":"ACTIVE","sortPriority":6,"id":25545675,"name":"Gift Of Youth"}],"regulators":["MR_INT"],"venue":"Lingfield","countryCode":"GB","discountAllowed":false,"timezone":"Europe/London","openDate":"2020-02-01T12:35:00.000Z","version":3142902892,"name":"7f Hcap","eventName":"Ling  1st Feb"},"rc":[{"batb":[[0,1.51,1.68],[1,1.01,2817.88]],"ltp":0.0,"tv":0.0,"id":25545675},{"batb":[[0,1.51,1.68],[1,1.01,2817.88]],"ltp":0.0,"tv":0.0,"id":25238892},{"batb":[[0,1.51,1.68],[1,1.01,2817.88]],"ltp":0.0,"tv":0.0,"id":24707172},{"batb":[[0,1.51,1.68],[1,1.01,2817.88]],"ltp":0.0,"tv":0.0,"id":24420205},{"batb":[[0,1.51,1.68],[1,1.01,2817.88]],"ltp":0.0,"tv":0.0,"id":26314798},{"batb":[[0,1.51,1.68],[1,1.01,2817.88]],"ltp":0.0,"tv":0.0,"id":420}]}]}
{"op":"mcm","clk":"987754522","pt":1580470906694,"mc":[{"id":"1.168130661","rc":[{"batb":[[1,1.01,2827.88]],"ltp":0.0,"tv":0.0,"id":25238892},{"batb":[[1,1.01,2827.88]],"ltp":0.0,"tv":0.0,"id":26314798}]}]}
{"op":"mcm","clk":"987754576","pt":1580470907524,"mc":[{"id":"1.168130661","rc":[{"batb":[[1,1.01,2827.88]],"ltp":0.0,"tv":0.0,"id":25545675},{"batb":[[1,1.01,2827.88]],"ltp":0.0,"tv":0.0,"id":24707172},{"batb":[[1,1.01,2827.88]],"ltp":0.0,"tv":0.0,"id":24420205},{"batb":[[1,1.01,2827.88]],"ltp":0.0,"tv":0.0,"id":420}]}]}
{"op":"mcm","clk":"987754630","pt":1580470908611,"mc":[{"id":"1.168130661","rc":[{"batb":[[0,1.51,3.36],[1,1.01,2829.56]],"ltp":0.0,"tv":0.0,"id":25545675},{"batb":[[0,1.51,3.36],[1,1.01,2829.56]],"ltp":0.0,"tv":0.0,"id":25238892},{"batb":[[0,1.51,3.36],[1,1.01,2829.56]],"ltp":0.0,"tv":0.0,"id":24707172},{"batb":[[0,1.51,3.36],[1,1.01,2829.56]],"ltp":0.0,"tv":0.0,"id":24420205},{"batb":[[0,1.51,3.36],[1,1.01,2829.56]],"ltp":0.0,"tv":0.0,"id":26314798},{"batb":[[0,1.51,3.36],[1,1.01,2829.56]],"ltp":0.0,"tv":0.0,"id":420}]}]}
{"op":"mcm","clk":"987754702","pt":1580470909607,"mc":[{"id":"1.168130661","marketDefinition":{"bspMarket":true,"turnInPlayEnabled":true,"persistenceEnabled":true,"marketBaseRate":5.0,"eventId":"29678694","eventTypeId":"7","numberOfWinners":1,"bettingType":"ODDS","marketType":"WIN","marketTime":"2020-02-01T12:35:00.000Z","suspendTime":"2020-02-01T12:35:00.000Z","bspReconciled":false,"complete":true,"inPlay":false,"crossMatching":false,"runnersVoidable":false,"numberOfActiveRunners":6,"betDelay":0,"status":"OPEN","runners":[{"adjustmentFactor":33.12,"status":"ACTIVE","sortPriority":1,"id":26314798,"name":"Ayr Harbour"},{"adjustmentFactor":30.53,"status":"ACTIVE","sortPriority":2,"id":25238892,"name":"Phuket Power"},{"adjustmentFactor":14.91,"status":"ACTIVE","sortPriority":3,"id":420,"name":"Barking Mad"},{"adjustmentFactor":8.45,"status":"ACTIVE","sortPriority":4,"id":24420205,"name":"Rodney Le Roc"},{"adjustmentFactor":7.01,"status":"ACTIVE","sortPriority":5,"id":24707172,"name":"Thomas Lanfiere"},{"adjustmentFactor":5.95,"status":"ACTIVE","sortPriority":6,"id":25545675,"name":"Gift Of Youth"}],"regulators":["MR_INT"],"venue":"Lingfield","countryCode":"GB","discountAllowed":true,"timezone":"Europe/London","openDate":"2020-02-01T12:35:00.000Z","version":3142902892,"name":"7f Hcap","eventName":"Ling  1st Feb"}}]}
{"op":"mcm","clk":"987755926","pt":1580470929533,"mc":[{"id":"1.168130661","rc":[{"batb":[[1,1.01,2688.96]],"ltp":0.0,"tv":0.0,"id":26314798}]}]}
{"op":"mcm","clk":"987756201","pt":1580470933630,"mc":[{"id":"1.168130661","rc":[{"batb":[[1,1.01,2688.96]],"ltp":0.0,"tv":0.0,"id":25545675},{"batb":[[1,1.01,2688.96]],"ltp":0.0,"tv":0.0,"id":25238892}]}]}
{"op":"mcm","clk":"987756306","pt":1580470935268,"mc":[{"id":"1.168130661","rc":[{"batb":[[1,1.01,2688.96]],"ltp":0.0,"tv":0.0,"id":24707172}]}]}
{"op":"mcm","clk":"987756785","pt":1580470942413,"mc":[{"id":"1.168130661","rc":[{"batb":[[1,1.03,5.18],[2,1.01,2688.96]],"ltp":0.0,"tv":0.0,"id":25545675},{"batb":[[1,1.03,5.18],[2,1.01,2688.96]],"ltp":0.0,"tv":0.0,"id":25238892},{"batb":[[1,1.03,5.18],[2,1.01,2688.96]],"ltp":0.0,"tv":0.0,"id":24707172},{"batb":[[1,1.03,5.18],[2,1.01,2829.56]],"ltp":0.0,"tv":0.0,"id":24420205},{"batb":[[1,1.03,5.18],[2,1.01,2688.96]],"ltp":0.0,"tv":0.0,"id":26314798},{"batb":[[1,1.03,5.18],[2,1.01,2829.56]],"ltp":0.0,"tv":0.0,"id":420}]}]}
{"op":"mcm","clk":"987757132","pt":1580470947350,"mc":[{"id":"1.168130661","rc":[{"batb":[[2,1.01,2688.96]],"ltp":0.0,"tv":0.0,"id":24420205}]}]}
{"op":"mcm","clk":"987757256","pt":1580470949343,"mc":[{"id":"1.168130661","rc":[{"batb":[[2,1.01,2688.96]],"ltp":0.0,"tv":0.0,"id":420}]}]}
{"op":"mcm","clk":"987757651","pt":1580470955247,"mc":[{"id":"1.168130661","rc":[{"batb":[[1,1.03,1571.38]],"ltp":0.0,"tv":0.0,"id":25545675},{"batb":[[1,1.03,1826.11]],"ltp":0.0,"tv":0.0,"id":25238892},{"batb":[[1,1.03,1617.62]],"ltp":0.0,"tv":0.0,"id":24707172},{"batb":[[1,1.03,1682.35]],"ltp":0.0,"tv":0.0,"id":24420205},{"batb":[[1,1.03,1642]],"ltp":0.0,"tv":0.0,"id":26314798},{"batb":[[1,1.03,1784.92]],"ltp":0.0,"tv":0.0,"id":420}]}]}
{"op":"mcm","clk":"987758816","pt":1580470972586,"mc":[{"id":"1.168130661","rc":[{"batl":[[0,1000,0.2]],"ltp":0.0,"tv":0.0,"id":25545675},{"batl":[[0,1000,0.2]],"ltp":0.0,"tv":0.0,"id":25238892},{"batl":[[0,1000,0.2]],"ltp":0.0,"tv":0.0,"id":24707172},{"batl":[[0,1000,0.2]],"ltp":0.0,"tv":0.0,"id":24420205},{"batl":[[0,1000,0.2]],"ltp":0.0,"tv":0.0,"id":26314798},{"batl":[[0,1000,0.2]],"ltp":0.0,"tv":0.0,"id":420}]}]}
{"op":"mcm","clk":"987760009","pt":1580470989487,"mc":[{"id":"1.168130661","rc":[{"batb":[[2,1.01,2690.96]],"ltp":0.0,"tv":0.0,"id":25545675},{"batb":[[2,1.01,2690.96]],"ltp":0.0,"tv":0.0,"id":25238892},{"batb":[[2,1.01,2690.96]],"ltp":0.0,"tv":0.0,"id":24707172},{"batb":[[2,1.01,2690.96]],"ltp":0.0,"tv":0.0,"id":24420205},{"batb":[[2,1.01,2690.96]],"ltp":0.0,"tv":0.0,"id":26314798},{"batb":[[2,1.01,2690.96]],"ltp":0.0,"tv":0.0,"id":420}]}]}
{"op":"mcm","clk":"987762149","pt":1580471025661,"mc":[{"id":"1.168130661","rc":[{"batb":[[2,1.02,1.99]],"ltp":0.0,"tv":0.0,"id":26314798}]}]}
{"op":"mcm","clk":"987762208","pt":1580471026654,"mc":[{"id":"1.168130661","rc":[{"batb":[[2,1.02,1.99]],"ltp":0.0,"tv":0.0,"id":25238892}]}]}
{"op":"mcm","clk":"987762256","pt":1580471027336,"mc":[{"id":"1.168130661","rc":[{"batb":[[2,1.02,1.99]],"ltp":0.0,"tv":0.0,"id":420}]}]}
{"op":"mcm","clk":"987762345","pt":1580471028631,"mc":[{"id":"1.168130661","rc":[{"batb":[[2,1.01,2692.96]],"ltp":0.0,"tv":0.0,"id":24707172},{"batb":[[2,1.02,1.99]],"ltp":0.0,"tv":0.0,"id":24420205}]}]}
{"op":"mcm","clk":"987762401","pt":1580471029717,"mc":[{"id":"1.168130661","rc":[{"batb":[[2,1.02,1.99]],"ltp":0.0,"tv":0.0,"id":24707172}]}]}
{"op":"mcm","clk":"987762440","pt":1580471030659,"mc":[{"id":"1.168130661","rc":[{"batb":[[2,1.02,1.99]],"ltp":0.0,"tv":0.0,"id":25545675}]}]}
{"op":"mcm","clk":"987788456","pt":1580471405379,"mc":[{"id":"1.168130661","rc":[{"batb":[[0,7,7],[1,1.51,3.36],[2,1.03,1571.38]],"ltp":0.0,"tv":0.0,"id":25545675},{"batb":[[0,1.6,44],[1,1.51,3.36],[2,1.03,1826.11]],"ltp":0.0,"tv":0.0,"id":25238892},{"batb":[[0,6,7],[1,1.51,3.36],[2,1.03,1617.62]],"ltp":0.0,"tv":0.0,"id":24707172},{"batb":[[0,4,11],[1,1.51,3.36],[2,1.03,1682.35]],"ltp":0.0,"tv":0.0,"id":24420205},{"batb":[[0,1.6,44],[1,1.51,3.36],[2,1.03,1642]],"ltp":0.0,"tv":0.0,"id":26314798},{"batb":[[0,4,12],[1,1.51,3.36],[2,1.03,1784.92]],"ltp":0.0,"tv":0.0,"id":420}]}]}
{"op":"mcm","clk":"987789192","pt":1580471414287,"mc":[{"id":"1.168130661","rc":[{"batb":[[0,1.61,7.5],[1,1.6,44],[2,1.51,3.36]],"ltp":0.0,"tv":0.0,"id":25238892},{"batb":[[0,1.61,7.5],[1,1.6,44],[2,1.51,3.36]],"ltp":0.0,"tv":0.0,"id":26314798}]}]}
{"op":"mcm","clk":"987789617","pt":1580471419795,"mc":[{"id":"1.168130661","rc":[{"batb":[[0,6,7.88]],"ltp":0.0,"tv":0.0,"id":24707172},{"batb":[[0,4.1,1.48],[1,4,11],[2,1.51,3.36]],"ltp":0.0,"tv":0.0,"id":24420205},{"batb":[[0,4.1,1.48],[1,4,12],[2,1.51,3.36]],"ltp":0.0,"tv":0.0,"id":420}]}]}
{"op":"mcm","clk":"987789773","pt":1580471421836,"mc":[{"id":"1.168130661","rc":[{"batb":[[0,7.2,2.78],[1,7,7],[2,1.51,3.36]],"ltp":0.0,"tv":0.0,"id":25545675},{"batb":[[0,1.62,3],[1,1.61,7.5],[2,1.6,44]],"ltp":0.0,"tv":0.0,"id":25238892},{"batb":[[0,1.62,3],[1,1.61,7.5],[2,1.6,44]],"ltp":0.0,"tv":0.0,"id":26314798}]}]}
{"op":"mcm","clk":"987789995","pt":1580471424505,"mc":[{"id":"1.168130661","rc":[{"batb":[[1,1.61,51.5],[2,1.51,3.36]],"ltp":0.0,"tv":0.0,"id":25238892},{"batb":[[1,1.61,51.5],[2,1.51,3.36]],"ltp":0.0,"tv":0.0,"id":26314798}]}]}
{"op":"mcm","clk":"987790369","pt":1580471429905,"mc":[{"id":"1.168130661","rc":[{"batb":[[0,7.2,9.78],[1,1.51,3.36],[2,1.03,1571.38]],"ltp":0.0,"tv":0.0,"id":25545675}]}]}
{"op":"mcm","clk":"987790852","pt":1580471437243,"mc":[{"id":"1.168130661","rc":[{"batb":[[0,1.62,47],[1,1.61,7.5]],"ltp":0.0,"tv":0.0,"id":25238892},{"batb":[[0,1.62,47],[1,1.61,7.5]],"ltp":0.0,"tv":0.0,"id":26314798}]}]}
{"op":"mcm","clk":"987791320","pt":1580471444416,"mc":[{"id":"1.168130661","rc":[{"batb":[[0,1.63,7.26],[1,1.62,47]],"ltp":0.0,"tv":0.0,"id":25238892},{"batb":[[0,1.63,7.26],[1,1.62,47]],"ltp":0.0,"tv":0.0,"id":26314798}]}]}
{"op":"mcm","clk":"987791471","pt":1580471447132,"mc":[{"id":"1.168130661","rc":[{"batb":[[0,1.64,1.99],[1,1.63,7.26],[2,1.62,47]],"ltp":0.0,"tv":0.0,"id":26314798}]}]}
{"op":"mcm","clk":"987791528","pt":1580471448127,"mc":[{"id":"1.168130661","rc":[{"batb":[[0,1.64,1.99],[1,1.63,7.26],[2,1.62,47]],"ltp":0.0,"tv":0.0,"id":25238892}]}]}
{"op":"mcm","clk":"987810345","pt":1580471615107,"mc":[{"id":"1.168130661","rc":[{"batb":[[0,1.64,4.99],[2,1.62,44]],"ltp":0.0,"tv":0.0,"id":25238892},{"batb":[[0,1.64,4.99],[2,1.62,44]],"ltp":0.0,"tv":0.0,"id":26314798}]}]}
{"op":"mcm","clk":"987871415","pt":1580472379595,"mc":[{"id":"1.168130661","rc":[{"batb":[[0,7.4,2.7],[1,7.2,9.78],[2,1.51,3.36]],"ltp":0.0,"tv":0.0,"id":25545675},{"batb":[[0,1.64,14.99],[1,1.63,7.25]],"ltp":0.0,"tv":0.0,"id":25238892},{"batb":[[0,6.2,4.11],[1,6,7],[2,1.51,3.36]],"ltp":0.0,"tv":0.0,"id":24707172},{"batb":[[0,4.1,6.36]],"ltp":0.0,"tv":0.0,"id":24420205},{"batb":[[0,1.64,14.99],[1,1.63,7.25]],"ltp":0.0,"tv":0.0,"id":26314798},{"batb":[[0,4.1,6.36]],"ltp":0.0,"tv":0.0,"id":420}]}]}
{"op":"mcm","clk":"987873547","pt":1580472405391,"mc":[{"id":"1.168130661","rc":[{"batb":[[0,1.65,7.03],[1,1.64,14.99]],"ltp":0.0,"tv":0.0,"id":25238892},{"batb":[[0,1.65,7.03],[1,1.64,14.99]],"ltp":0.0,"tv":0.0,"id":26314798}]}]}
{"op":"mcm","clk":"987875460","pt":1580472423498,"mc":[{"id":"1.168130661","rc":[{"batb":[[0,1.66,1.99],[1,1.65,7.03],[2,1.64,13]],"ltp":0.0,"tv":0.0,"id":26314798}]}]}
{"op":"mcm","clk":"987875508","pt":1580472424018,"mc":[{"id":"1.168130661","rc":[{"batb":[[0,1.66,1.99],[1,1.65,7.03],[2,1.64,13]],"ltp":0.0,"tv":0.0,"id":25238892}]}]}
{"op":"mcm","clk":"987888290","pt":1580472469261,"mc":[{"id":"1.168130661","rc":[{"batb":[[0,1.66,11.99],[2,1.64,3]],"ltp":0.0,"tv":0.0,"id":25238892},{"batb":[[0,1.66,11.99],[2,1.64,3]],"ltp":0.0,"tv":0.0,"id":26314798}]}]}
{"op":"mcm","clk":"987890990","pt":1580472495518,"mc":[{"id":"1.168130661","rc":[{"batb":[[0,1.67,6.83],[1,1.66,11.99]],"ltp":0.0,"tv":0.0,"id":25238892},{"batb":[[0,1.67,6.83],[1,1.66,11.99]],"ltp":0.0,"tv":0.0,"id":26314798}]}]}
{"op":"mcm","clk":"987892649","pt":1580472511620,"mc":[{"id":"1.168130661","rc":[{"batb":[[1,1.66,10]],"ltp":0.0,"tv":0.0,"id":25238892},{"batb":[[0,1.68,1.99],[1,1.67,6.83],[2,1.66,10]],"ltp":0.0,"tv":0.0,"id":26314798}]}]}
{"op":"mcm","clk":"987892660","pt":1580472511728,"mc":[{"id":"1.168130661","rc":[{"batb":[[0,1.68,1.99],[1,1.67,6.83],[2,1.66,10]],"ltp":0.0,"tv":0.0,"id":25238892}]}]}
{"op":"mcm","clk":"987897854","pt":1580472560130,"mc":[{"id":"1.168130661","rc":[{"batb":[[0,1.68,11.99],[2,1.64,3]],"ltp":0.0,"tv":0.0,"id":25238892},{"batb":[[0,1.68,11.99],[2,1.64,3]],"ltp":0.0,"tv":0.0,"id":26314798}]}]}
{"op":"mcm","clk":"987900304","pt":1580472585445,"mc":[{"id":"1.168130661","rc":[{"batb":[[0,1.69,6.63],[1,1.68,11.99]],"ltp":0.0,"tv":0.0,"id":25238892},{"batb":[[0,1.69,6.63],[1,1.68,11.99]],"ltp":0.0,"tv":0.0,"id":26314798}]}]}
{"op":"mcm","clk":"987901225","pt":1580472595628,"mc":[{"id":"1.168130661","rc":[{"batb":[[0,1.7,1.99],[1,1.69,6.63],[2,1.68,10]],"ltp":0.0,"tv":0.0,"id":26314798}]}]}
{"op":"mcm","clk":"987901252","pt":1580472595938,"mc":[{"id":"1.168130661","rc":[{"batb":[[0,1.7,1.99],[1,1.69,6.63],[2,1.68,10]],"ltp":0.0,"tv":0.0,"id":25238892}]}]}
{"op":"mcm","clk":"987907016","pt":1580472650524,"mc":[{"id":"1.168130661","rc":[{"batb":[[2,1.64,3]],"ltp":0.0,"tv":0.0,"id":25238892},{"batb":[[2,1.64,3]],"ltp":0.0,"tv":0.0,"id":26314798}]}]}
{"op":"mcm","clk":"987907038","pt":1580472650734,"mc":[{"id":"1.168130661","rc":[{"batb":[[0,1.7,11.99]],"ltp":0.0,"tv":0.0,"id":25238892},{"batb":[[0,1.7,11.99]],"ltp":0.0,"tv":0.0,"id":26314798}]}]}
{"op":"mcm","clk":"987909529","pt":1580472674929,"mc":[{"id":"1.168130661","rc":[{"batb":[[0,1.71,6.44],[1,1.7,11.99]],"ltp":0.0,"tv":0.0,"id":25238892},{"batb":[[0,1.71,6.44],[1,1.7,11.99]],"ltp":0.0,"tv":0.0,"id":26314798}]}]}
{"op":"mcm","clk":"987911178","pt":1580472690683,"mc":[{"id":"1.168130661","rc":[{"batb":[[0,1.72,1.99],[1,1.71,6.44],[2,1.7,10]],"ltp":0.0,"tv":0.0,"id":25238892},{"batb":[[0,1.72,1.99],[1,1.71,6.44],[2,1.7,10]],"ltp":0.0,"tv":0.0,"id":26314798}]}]}
{"op":"mcm","clk":"987916541","pt":1580472740860,"mc":[{"id":"1.168130661","rc":[{"batb":[[2,1.64,3]],"ltp":0.0,"tv":0.0,"id":25238892},{"batb":[[2,1.64,3]],"ltp":0.0,"tv":0.0,"id":26314798}]}]}
{"op":"mcm","clk":"987928218","pt":1580472850914,"mc":[{"id":"1.168130661","rc":[{"batb":[[1,7.2,7]],"ltp":0.0,"tv":0.0,"id":25545675},{"batb":[[2,1.62,44]],"ltp":0.0,"tv":0.0,"id":25238892},{"batb":[[2,1.62,44]],"ltp":0.0,"tv":0.0,"id":26314798}]}]}
{"op":"mcm","clk":"987934979","pt":1580472920618,"mc":[{"id":"1.168130661","rc":[{"batb":[[0,1.72,11.99]],"ltp":0.0,"tv":0.0,"id":25238892},{"batb":[[0,1.72,11.99]],"ltp":0.0,"tv":0.0,"id":26314798}]}]}
{"op":"mcm","clk":"987937483","pt":1580472945428,"mc":[{"id":"1.168130661","rc":[{"batb":[[0,1.73,6.26],[1,1.72,11.99]],"ltp":0.0,"tv":0.0,"id":26314798}]}]}
{"op":"mcm","clk":"987937511","pt":1580472945729,"mc":[{"id":"1.168130661","rc":[{"batb":[[0,1.73,6.26],[1,1.72,11.99]],"ltp":0.0,"tv":0.0,"id":25238892}]}]}
{"op":"mcm","clk":"987938522","pt":1580472956442,"mc":[{"id":"1.168130661","rc":[{"batb":[[0,1.74,1.99],[1,1.73,6.26],[2,1.72,10]],"ltp":0.0,"tv":0.0,"id":26314798}]}]}
{"op":"mcm","clk":"987938564","pt":1580472956853,"mc":[{"id":"1.168130661","rc":[{"batb":[[0,1.74,1.99],[1,1.73,6.26],[2,1.72,10]],"ltp":0.0,"tv":0.0,"id":25238892}]}]}
{"op":"mcm","clk":"987944013","pt":1580473010639,"mc":[{"id":"1.168130661","rc":[{"batb":[[0,7.4,9.7],[1,1.51,3.36],[2,1.03,1571.78]],"ltp":0.0,"tv":0.0,"id":25545675},{"batb":[[0,1.74,55.99],[2,1.51,3.36]],"ltp":0.0,"tv":0.0,"id":25238892},{"batb":[[0,6.2,11.11],[1,1.51,3.36],[2,1.03,1618.03]],"ltp":0.0,"tv":0.0,"id":24707172},{"batb":[[0,4.2,11],[1,4.1,6.36]],"ltp":0.0,"tv":0.0,"id":24420205},{"batb":[[0,1.74,55.99],[2,1.51,3.36]],"ltp":0.0,"tv":0.0,"id":26314798},{"batb":[[0,4.2,12],[1,4.1,6.36]],"ltp":0.0,"tv":0.0,"id":420}]}]}
{"op":"mcm","clk":"987946722","pt":1580473035583,"mc":[{"id":"1.168130661","rc":[{"batb":[[0,1.75,6.09],[1,1.74,55.99]],"ltp":0.0,"tv":0.0,"id":25238892},{"batb":[[1,4.1,4.88]],"ltp":0.0,"tv":0.0,"id":24420205},{"batb":[[0,1.75,6.09],[1,1.74,55.99]],"ltp":0.0,"tv":0.0,"id":26314798},{"batb":[[1,4.1,4.88]],"ltp":0.0,"tv":0.0,"id":420}]}]}
{"op":"mcm","clk":"987947091","pt":1580473038660,"mc":[{"id":"1.168130661","rc":[{"batb":[[1,1.74,54]],"ltp":0.0,"tv":0.0,"id":26314798}]}]}
{"op":"mcm","clk":"987947160","pt":1580473039268,"mc":[{"id":"1.168130661","rc":[{"batb":[[1,1.74,54]],"ltp":0.0,"tv":0.0,"id":25238892}]}]}
{"op":"mcm","clk":"987947331","pt":1580473040999,"mc":[{"id":"1.168130661","rc":[{"batb":[[0,4.3,1.39],[1,4.2,11],[2,4.1,4.88]],"ltp":0.0,"tv":0.0,"id":24420205},{"batb":[[0,4.3,1.39],[1,4.2,12],[2,4.1,4.88]],"ltp":0.0,"tv":0.0,"id":420}]}]}
{"op":"mcm","clk":"987953716","pt":1580473101086,"mc":[{"id":"1.168130661","rc":[{"batb":[[0,4.3,6.04],[2,1.51,3.36]],"ltp":0.0,"tv":0.0,"id":24420205},{"batb":[[0,4.3,6.04],[2,1.51,3.36]],"ltp":0.0,"tv":0.0,"id":420}]}]}
{"op":"mcm","clk":"987960418","pt":1580473169790,"mc":[{"id":"1.168130661","rc":[{"batb":[[0,7.6,2.63],[1,7.4,9.7],[2,1.51,3.36]],"ltp":0.0,"tv":0.0,"id":25545675},{"batb":[[0,1.76,3],[1,1.75,6.09],[2,1.74,54]],"ltp":0.0,"tv":0.0,"id":25238892},{"batb":[[0,6.4,3],[1,6.2,11.11],[2,1.51,3.36]],"ltp":0.0,"tv":0.0,"id":24707172},{"batb":[[0,1.76,3],[1,1.75,6.09],[2,1.74,54]],"ltp":0.0,"tv":0.0,"id":26314798}]}]}
{"op":"mcm","clk":"987961959","pt":1580473185291,"mc":[{"id":"1.168130661","rc":[{"batb":[[1,6.2,10.23]],"ltp":0.0,"tv":0.0,"id":24707172}]}]}
{"op":"mcm","clk":"987962457","pt":1580473190623,"mc":[{"id":"1.168130661","rc":[{"batb":[[0,6.4,3.82]],"ltp":0.0,"tv":0.0,"id":24707172}]}]}
{"op":"mcm","clk":"987962514","pt":1580473191204,"mc":[{"id":"1.168130661","rc":[{"batb":[[0,1.76,13],[2,1.74,44]],"ltp":0.0,"tv":0.0,"id":25238892},{"batb":[[0,6.6,3.85],[1,6.4,3],[2,6.2,7]],"ltp":0.0,"tv":0.0,"id":24707172},{"batb":[[0,1.76,13],[2,1.74,44]],"ltp":0.0,"tv":0.0,"id":26314798}]}]}
{"op":"mcm","clk":"987963057","pt":1580473196713,"mc":[{"id":"1.168130661","rc":[{"batb":[[0,1.77,1.99],[1,1.76,13],[2,1.75,6.09]],"ltp":0.0,"tv":0.0,"id":25238892},{"batb":[[0,1.77,1.99],[1,1.76,13],[2,1.75,6.09]],"ltp":0.0,"tv":0.0,"id":26314798}]}]}
{"op":"mcm","clk":"987963156","pt":1580473197654,"mc":[{"id":"1.168130661","rc":[{"batb":[[0,6.8,1.99],[1,6.6,3.85],[2,6.4,3]],"ltp":0.0,"tv":0.0,"id":24707172}]}]}
{"op":"mcm","clk":"987964951","pt":1580473215472,"mc":[{"id":"1.168130661","rc":[{"batb":[[0,1.77,7.92],[2,1.74,44]],"ltp":0.0,"tv":0.0,"id":25238892},{"batb":[[1,6.6,3.03]],"ltp":0.0,"tv":0.0,"id":24707172},{"batb":[[0,1.77,7.92],[2,1.74,44]],"ltp":0.0,"tv":0.0,"id":26314798}]}]}
{"op":"mcm","clk":"987965451","pt":1580473220379,"mc":[{"id":"1.168130661","rc":[{"batb":[[0,6.8,2.75]],"ltp":0.0,"tv":0.0,"id":24707172}]}]}
{"op":"mcm","clk":"987972211","pt":1580473282170,"mc":[{"id":"1.168130661","rc":[{"batb":[[0,7.2,1.99],[1,7,3.62]],"ltp":0.0,"tv":0.0,"id":24707172}]}]}
{"op":"mcm","clk":"987990325","pt":1580473380375,"mc":[{"id":"1.168130661","rc":[{"batb":[[0,1.78,3],[1,1.77,7.92],[2,1.76,10]],"ltp":0.0,"tv":0.0,"id":25238892},{"batb":[[0,1.78,3],[1,1.77,7.92],[2,1.76,10]],"ltp":0.0,"tv":0.0,"id":26314798}]}]}
{"op":"mcm","clk":"987998429","pt":1580473460209,"mc":[{"id":"1.168130661","rc":[{"batb":[[0,1.79,1.99],[1,1.78,3],[2,1.77,5.93]],"ltp":0.0,"tv":0.0,"id":25238892},{"batb":[[0,1.79,1.99],[1,1.78,3],[2,1.77,5.93]],"ltp":0.0,"tv":0.0,"id":26314798}]}]}
{"op":"mcm","clk":"987998857","pt":1580473464047,"mc":[{"id":"1.168130661","rc":[{"batb":[[0,1.79,11.99]],"ltp":0.0,"tv":0.0,"id":25238892},{"batb":[[0,1.79,11.99]],"ltp":0.0,"tv":0.0,"id":26314798}]}]}
{"op":"mcm","clk":"988000759","pt":1580473485461,"mc":[{"id":"1.168130661","rc":[{"batb":[[0,1.8,5.71],[1,1.79,11.99],[2,1.78,3]],"ltp":0.0,"tv":0.0,"id":25238892},{"batb":[[0,1.8,5.71],[1,1.79,11.99],[2,1.78,3]],"ltp":0.0,"tv":0.0,"id":26314798}]}]}
{"op":"mcm","clk":"988001388","pt":1580473491992,"mc":[{"id":"1.168130661","rc":[{"batb":[[2,1.74,44]],"ltp":0.0,"tv":0.0,"id":25238892},{"batb":[[2,1.74,44]],"ltp":0.0,"tv":0.0,"id":26314798}]}]}
{"op":"mcm","clk":"988006331","pt":1580473546466,"mc":[{"id":"1.168130661","rc":[{"batb":[[0,1.81,1.99],[1,1.8,5.71],[2,1.79,10]],"ltp":0.0,"tv":0.0,"id":25238892},{"batb":[[0,1.81,1.99],[1,1.8,5.71],[2,1.79,10]],"ltp":0.0,"tv":0.0,"id":26314798}]}]}
{"op":"mcm","clk":"988007139","pt":1580473554977,"mc":[{"id":"1.168130661","rc":[{"batb":[[0,1.81,11.99],[2,1.74,44]],"ltp":0.0,"tv":0.0,"id":25238892},{"batb":[[0,1.81,11.99],[2,1.74,44]],"ltp":0.0,"tv":0.0,"id":26314798}]}]}
{"op":"mcm","clk":"988009099","pt":1580473575530,"mc":[{"id":"1.168130661","rc":[{"batb":[[0,1.82,5.58],[1,1.81,11.99]],"ltp":0.0,"tv":0.0,"id":25238892},{"batb":[[0,1.82,5.58],[1,1.81,11.99]],"ltp":0.0,"tv":0.0,"id":26314798}]}]}
{"op":"mcm","clk":"988014485","pt":1580473625431,"mc":[{"id":"1.168130661","rc":[{"batb":[[0,1.83,1.99],[1,1.82,5.58],[2,1.81,10]],"ltp":0.0,"tv":0.0,"id":25238892},{"batb":[[0,1.83,1.99],[1,1.82,5.58],[2,1.81,10]],"ltp":0.0,"tv":0.0,"id":26314798}]}]}
{"op":"mcm","clk":"988016662","pt":1580473645353,"mc":[{"id":"1.168130661","rc":[{"batb":[[0,1.83,11.99],[2,1.74,44]],"ltp":0.0,"tv":0.0,"id":25238892},{"batb":[[0,1.83,11.99],[2,1.74,44]],"ltp":0.0,"tv":0.0,"id":26314798}]}]}
{"op":"mcm","clk":"988018699","pt":1580473665096,"mc":[{"id":"1.168130661","rc":[{"batb":[[0,1.84,5.44],[1,1.83,11.99]],"ltp":0.0,"tv":0.0,"id":25238892},{"batb":[[0,1.84,5.44],[1,1.83,11.99]],"ltp":0.0,"tv":0.0,"id":26314798}]}]}
{"op":"mcm","clk":"988022992","pt":1580473707657,"mc":[{"id":"1.168130661","rc":[{"batb":[[1,1.83,10]],"ltp":0.0,"tv":0.0,"id":26314798}]}]}
{"op":"mcm","clk":"988023037","pt":1580473708181,"mc":[{"id":"1.168130661","rc":[{"batb":[[0,1.85,1.99],[1,1.84,5.44],[2,1.83,10]],"ltp":0.0,"tv":0.0,"id":25238892},{"batb":[[0,1.85,1.99],[1,1.84,5.44],[2,1.83,10]],"ltp":0.0,"tv":0.0,"id":26314798}]}]}
{"op":"mcm","clk":"988025355","pt":1580473731799,"mc":[{"id":"1.168130661","rc":[{"batb":[[1,1.84,8.44]],"ltp":0.0,"tv":0.0,"id":25238892},{"batb":[[1,1.84,8.44]],"ltp":0.0,"tv":0.0,"id":26314798}]}]}
{"op":"mcm","clk":"988025722","pt":1580473735593,"mc":[{"id":"1.168130661","rc":[{"batb":[[0,1.85,11.99],[2,1.74,44]],"ltp":0.0,"tv":0.0,"id":25238892},{"batb":[[0,1.85,11.99],[2,1.74,44]],"ltp":0.0,"tv":0.0,"id":26314798}]}]}
{"op":"mcm","clk":"988027738","pt":1580473755249,"mc":[{"id":"1.168130661","rc":[{"batb":[[0,1.86,5.32],[1,1.85,11.99],[2,1.84,3]],"ltp":0.0,"tv":0.0,"id":25238892},{"batb":[[0,1.86,5.32],[1,1.85,11.99],[2,1.84,3]],"ltp":0.0,"tv":0.0,"id":26314798}]}]}
{"op":"mcm","clk":"988031441","pt":1580473793619,"mc":[{"id":"1.168130661","rc":[{"batb":[[0,1.86,8.32],[2,1.74,44]],"ltp":0.0,"tv":0.0,"id":25238892},{"batb":[[0,1.87,1.99],[1,1.86,8.32],[2,1.85,10]],"ltp":0.0,"tv":0.0,"id":26314798}]}]}
{"op":"mcm","clk":"988031464","pt":1580473793890,"mc":[{"id":"1.168130661","rc":[{"batb":[[0,1.87,1.99],[1,1.86,8.32],[2,1.85,10]],"ltp":0.0,"tv":0.0,"id":25238892}]}]}
{"op":"mcm","clk":"988034686","pt":1580473825851,"mc":[{"id":"1.168130661","rc":[{"batb":[[0,1.87,11.99],[2,1.74,44]],"ltp":0.0,"tv":0.0,"id":25238892},{"batb":[[0,1.87,11.99],[2,1.74,44]],"ltp":0.0,"tv":0.0,"id":26314798}]}]}
{"op":"mcm","clk":"988036725","pt":1580473845197,"mc":[{"id":"1.168130661","rc":[{"batb":[[0,1.88,5.2],[1,1.87,11.99],[2,1.86,3]],"ltp":0.0,"tv":0.0,"id":25238892},{"batb":[[0,1.88,5.2],[1,1.87,11.99],[2,1.86,3]],"ltp":0.0,"tv":0.0,"id":26314798}]}]}
{"op":"mcm","clk":"988037173","pt":1580473850002,"mc":[{"id":"1.168130661","rc":[{"batb":[[0,1.88,8.2],[2,1.74,44]],"ltp":0.0,"tv":0.0,"id":25238892},{"batb":[[0,1.88,8.2],[2,1.74,44]],"ltp":0.0,"tv":0.0,"id":26314798}]}]}
{"op":"mcm","clk":"988041659","pt":1580473889276,"mc":[{"id":"1.168130661","rc":[{"batb":[[0,1.89,1.99],[1,1.88,8.2],[2,1.87,10]],"ltp":0.0,"tv":0.0,"id":25238892},{"batb":[[0,1.89,1.99],[1,1.88,8.2],[2,1.87,10]],"ltp":0.0,"tv":0.0,"id":26314798}]}]}
{"op":"mcm","clk":"988044699","pt":1580473915996,"mc":[{"id":"1.168130661","rc":[{"batb":[[2,1.74,44]],"ltp":0.0,"tv":0.0,"id":25238892},{"batb":[[2,1.74,44]],"ltp":0.0,"tv":0.0,"id":26314798}]}]}
{"op":"mcm","clk":"988051408","pt":1580473972476,"mc":[{"id":"1.168130661","rc":[{"batb":[[1,1.88,5.2],[2,1.75,3]],"ltp":0.0,"tv":0.0,"id":25238892},{"batb":[[1,1.88,5.2],[2,1.75,3]],"ltp":0.0,"tv":0.0,"id":26314798}]}]}
{"op":"mcm","clk":"988064287","pt":1580474095343,"mc":[{"id":"1.168130661","rc":[{"batb":[[0,1.89,11.99]],"ltp":0.0,"tv":0.0,"id":25238892},{"batb":[[0,1.89,11.99]],"ltp":0.0,"tv":0.0,"id":26314798}]}]}
{"op":"mcm","clk":"988066471","pt":1580474115276,"mc":[{"id":"1.168130661","rc":[{"batb":[[0,1.9,5.08],[1,1.89,11.99]],"ltp":0.0,"tv":0.0,"id":25238892},{"batb":[[0,1.9,5.08],[1,1.89,11.99]],"ltp":0.0,"tv":0.0,"id":26314798}]}]}
{"op":"mcm","clk":"988068807","pt":1580474139424,"mc":[{"id":"1.168130661","rc":[{"batb":[[0,1.9,8.08],[2,1.74,44]],"ltp":0.0,"tv":0.0,"id":25238892},{"batb":[[0,1.91,1.99],[1,1.9,8.08],[2,1.89,10]],"ltp":0.0,"tv":0.0,"id":26314798}]}]}
{"op":"mcm","clk":"988068850","pt":1580474139901,"mc":[{"id":"1.168130661","rc":[{"batb":[[0,1.91,1.99],[1,1.9,8.08],[2,1.89,10]],"ltp":0.0,"tv":0.0,"id":25238892}]}]}
{"op":"mcm","clk":"988073526","pt":1580474186870,"mc":[{"id":"1.168130661","rc":[{"batb":[[2,1.74,44]],"ltp":0.0,"tv":0.0,"id":25238892},{"batb":[[2,1.74,44]],"ltp":0.0,"tv":0.0,"id":26314798}]}]}
{"op":"mcm","clk":"988075010","pt":1580474200602,"mc":[{"id":"1.168130661","rc":[{"batb":[[1,1.9,5.08]],"ltp":0.0,"tv":0.0,"id":25238892},{"batb":[[1,1.9,5.08]],"ltp":0.0,"tv":0.0,"id":26314798}]}]}
{"op":"mcm","clk":"988075039","pt":1580474200806,"mc":[{"id":"1.168130661","rc":[{"batb":[[2,1.75,3]],"ltp":0.0,"tv":0.0,"id":25238892},{"batb":[[2,1.75,3]],"ltp":0.0,"tv":0.0,"id":26314798}]}]}
{"op":"mcm","clk":"988099755","pt":1580474368250,"mc":[{"id":"1.168130661","rc":[{"batb":[[0,1.91,11.99]],"ltp":0.0,"tv":0.0,"id":25238892},{"batb":[[0,1.91,11.99]],"ltp":0.0,"tv":0.0,"id":26314798}]}]}
{"op":"mcm","clk":"988100758","pt":1580474378354,"mc":[{"id":"1.168130661","rc":[{"batb":[[2,1.74,44]],"ltp":0.0,"tv":0.0,"id":25238892},{"batb":[[2,1.74,44]],"ltp":0.0,"tv":0.0,"id":26314798}]}]}
{"op":"mcm","clk":"988101538","pt":1580474385982,"mc":[{"id":"1.168130661","rc":[{"batb":[[0,1.92,4.97],[1,1.91,11.99]],"ltp":0.0,"tv":0.0,"id":25238892},{"batb":[[0,1.92,4.97],[1,1.91,11.99]],"ltp":0.0,"tv":0.0,"id":26314798}]}]}
{"op":"mcm","clk":"988101902","pt":1580474389467,"mc":[{"id":"1.168130661","rc":[{"batb":[[0,1.93,1.99],[1,1.92,4.97],[2,1.91,10]],"ltp":0.0,"tv":0.0,"id":25238892},{"batb":[[0,1.93,1.99],[1,1.92,4.97],[2,1.91,10]],"ltp":0.0,"tv":0.0,"id":26314798}]}]}
{"op":"mcm","clk":"988109061","pt":1580474458491,"mc":[{"id":"1.168130661","rc":[{"batb":[[2,1.74,44]],"ltp":0.0,"tv":0.0,"id":25238892},{"batb":[[2,1.74,44]],"ltp":0.0,"tv":0.0,"id":26314798}]}]}
{"op":"mcm","clk":"988112239","pt":1580474487643,"mc":[{"id":"1.168130661","rc":[{"batb":[[0,1.92,4.97],[1,1.74,44],[2,1.51,3.36]],"ltp":0.0,"tv":0.0,"id":25238892},{"batb":[[0,1.92,4.97],[1,1.74,44],[2,1.51,3.36]],"ltp":0.0,"tv":0.0,"id":26314798}]}]}
{"op":"mcm","clk":"988113118","pt":1580474495662,"mc":[{"id":"1.168130661","rc":[{"batb":[[1,1.75,3],[2,1.74,44]],"ltp":0.0,"tv":0.0,"id":25238892},{"batb":[[1,1.75,3],[2,1.74,44]],"ltp":0.0,"tv":0.0,"id":26314798}]}]}
{"op":"mcm","clk":"988120873","pt":1580474566563,"mc":[{"id":"1.168130661","rc":[{"batb":[[0,1.93,1.99],[1,1.92,4.97],[2,1.75,3]],"ltp":0.0,"tv":0.0,"id":26314798}]}]}
{"op":"mcm","clk":"988120921","pt":1580474567085,"mc":[{"id":"1.168130661","rc":[{"batb":[[0,1.93,1.99],[1,1.92,4.97],[2,1.75,3]],"ltp":0.0,"tv":0.0,"id":25238892}]}]}
{"op":"mcm","clk":"988129080","pt":1580474639269,"mc":[{"id":"1.168130661","rc":[{"batb":[[0,1.93,11.99]],"ltp":0.0,"tv":0.0,"id":25238892},{"batb":[[0,1.93,11.99]],"ltp":0.0,"tv":0.0,"id":26314798}]}]}
{"op":"mcm","clk":"988130948","pt":1580474655313,"mc":[{"id":"1.168130661","rc":[{"batb":[[0,1.94,4.86],[1,1.93,11.99]],"ltp":0.0,"tv":0.0,"id":25238892},{"batb":[[0,1.94,4.86],[1,1.93,11.99]],"ltp":0.0,"tv":0.0,"id":26314798}]}]}
{"op":"mcm","clk":"988133127","pt":1580474674692,"mc":[{"id":"1.168130661","rc":[{"batb":[[2,1.74,44]],"ltp":0.0,"tv":0.0,"id":25238892},{"batb":[[2,1.74,44]],"ltp":0.0,"tv":0.0,"id":26314798}]}]}
{"op":"mcm","clk":"988138695","pt":1580474725565,"mc":[{"id":"1.168130661","rc":[{"batb":[[1,1.93,10]],"ltp":0.0,"tv":0.0,"id":26314798}]}]}
{"op":"mcm","clk":"988138736","pt":1580474725876,"mc":[{"id":"1.168130661","rc":[{"batb":[[1,1.93,10]],"ltp":0.0,"tv":0.0,"id":25238892}]}]}
{"op":"mcm","clk":"988139183","pt":1580474730107,"mc":[{"id":"1.168130661","rc":[{"batb":[[1,1.75,10]],"ltp":0.0,"tv":0.0,"id":25238892},{"batb":[[1,1.75,10]],"ltp":0.0,"tv":0.0,"id":26314798}]}]}
{"op":"mcm","clk":"988146161","pt":1580474797622,"mc":[{"id":"1.168130661","rc":[{"batb":[[1,1.76,3],[2,1.75,10]],"ltp":0.0,"tv":0.0,"id":25238892},{"batb":[[1,1.76,3],[2,1.75,10]],"ltp":0.0,"tv":0.0,"id":26314798}]}]}
{"op":"mcm","clk":"988148980","pt":1580474822055,"mc":[{"id":"1.168130661","rc":[{"batb":[[2,1.74,44]],"ltp":0.0,"tv":0.0,"id":25238892},{"batb":[[2,1.74,44]],"ltp":0.0,"tv":0.0,"id":26314798}]}]}
{"op":"mcm","clk":"988152582","pt":1580474858154,"mc":[{"id":"1.168130661","rc":[{"batb":[[1,1.75,3]],"ltp":0.0,"tv":0.0,"id":25238892},{"batb":[[1,1.75,3]],"ltp":0.0,"tv":0.0,"id":26314798}]}]}
{"op":"mcm","clk":"988194230","pt":1580475183147,"mc":[{"id":"1.168130661","rc":[{"batb":[[1,1.76,10],[2,1.75,3]],"ltp":0.0,"tv":0.0,"id":25238892},{"batb":[[1,1.76,10],[2,1.75,3]],"ltp":0.0,"tv":0.0,"id":26314798}]}]}
{"op":"mcm","clk":"988201163","pt":1580475266076,"mc":[{"id":"1.168130661","rc":[{"batb":[[1,1.77,3],[2,1.76,10]],"ltp":0.0,"tv":0.0,"id":25238892},{"batb":[[1,1.77,3],[2,1.76,10]],"ltp":0.0,"tv":0.0,"id":26314798}]}]}
{"op":"mcm","clk":"988201723","pt":1580475273406,"mc":[{"id":"1.168130661","rc":[{"batb":[[1,1.78,10],[2,1.77,3]],"ltp":0.0,"tv":0.0,"id":25238892},{"batb":[[1,1.78,10],[2,1.77,3]],"ltp":0.0,"tv":0.0,"id":26314798}]}]}
{"op":"mcm","clk":"988205601","pt":1580475319682,"mc":[{"id":"1.168130661","rc":[{"batb":[[0,1.95,1.99],[1,1.94,4.86],[2,1.78,10]],"ltp":0.0,"tv":0.0,"id":26314798}]}]}
{"op":"mcm","clk":"988205688","pt":1580475320680,"mc":[{"id":"1.168130661","rc":[{"batb":[[0,1.95,1.99],[1,1.94,4.86],[2,1.78,10]],"ltp":0.0,"tv":0.0,"id":25238892}]}]}
{"op":"mcm","clk":"988208989","pt":1580475360631,"mc":[{"id":"1.168130661","rc":[{"batb":[[2,1.77,3]],"ltp":0.0,"tv":0.0,"id":25238892},{"batb":[[2,1.77,3]],"ltp":0.0,"tv":0.0,"id":26314798}]}]}
{"op":"mcm","clk":"988209002","pt":1580475360733,"mc":[{"id":"1.168130661","rc":[{"batb":[[0,1.95,11.99]],"ltp":0.0,"tv":0.0,"id":25238892},{"batb":[[0,1.95,11.99]],"ltp":0.0,"tv":0.0,"id":26314798}]}]}
{"op":"mcm","clk":"988210276","pt":1580475375577,"mc":[{"id":"1.168130661","rc":[{"batb":[[0,1.96,4.76],[1,1.95,11.99]],"ltp":0.0,"tv":0.0,"id":25238892},{"batb":[[0,1.96,4.76],[1,1.95,11.99]],"ltp":0.0,"tv":0.0,"id":26314798}]}]}
{"op":"mcm","clk":"988212182","pt":1580475397308,"mc":[{"id":"1.168130661","rc":[{"batb":[[1,1.95,10]],"ltp":0.0,"tv":0.0,"id":25238892},{"batb":[[1,1.95,10]],"ltp":0.0,"tv":0.0,"id":26314798}]}]}
{"op":"mcm","clk":"988212256","pt":1580475398311,"mc":[{"id":"1.168130661","rc":[{"batb":[[2,1.74,44]],"ltp":0.0,"tv":0.0,"id":25238892},{"batb":[[2,1.74,44]],"ltp":0.0,"tv":0.0,"id":26314798}]}]}
{"op":"mcm","clk":"988215244","pt":1580475434260,"mc":[{"id":"1.168130661","rc":[{"batb":[[0,7.6,2.84]],"ltp":0.0,"tv":0.0,"id":25545675},{"batb":[[0,1.96,5.6]],"ltp":0.0,"tv":0.0,"id":25238892},{"batb":[[0,7.2,2.22]],"ltp":0.0,"tv":0.0,"id":24707172},{"batb":[[0,4.3,6.41]],"ltp":0.0,"tv":0.0,"id":24420205},{"batb":[[0,1.96,5.6]],"ltp":0.0,"tv":0.0,"id":26314798},{"batb":[[0,4.3,6.41]],"ltp":0.0,"tv":0.0,"id":420}]}]}
{"op":"mcm","clk":"988215335","pt":1580475435678,"mc":[{"id":"1.168130661","rc":[{"batb":[[0,4.3,5.03]],"ltp":0.0,"tv":0.0,"id":24420205},{"batb":[[0,4.3,5.03]],"ltp":0.0,"tv":0.0,"id":420}]}]}
{"op":"mcm","clk":"988215796","pt":1580475442089,"mc":[{"id":"1.168130661","rc":[{"batb":[[0,4.4,1.72],[1,4.3,4.65],[2,4.2,11]],"ltp":0.0,"tv":0.0,"id":24420205},{"batb":[[0,4.4,1.72],[1,4.3,4.65],[2,4.2,12]],"ltp":0.0,"tv":0.0,"id":420}]}]}
{"op":"mcm","clk":"988216995","pt":1580475457598,"mc":[{"id":"1.168130661","rc":[{"batb":[[1,7.4,7]],"ltp":0.0,"tv":0.0,"id":25545675},{"batb":[[1,1.74,44],[2,1.51,3.36]],"ltp":0.0,"tv":0.0,"id":25238892},{"batb":[[1,1.74,44],[2,1.51,3.36]],"ltp":0.0,"tv":0.0,"id":26314798}]}]}
{"op":"mcm","clk":"988218701","pt":1580475478678,"mc":[{"id":"1.168130661","rc":[{"batb":[[0,4.5,1.99],[1,4.4,1.72],[2,4.3,4.65]],"ltp":0.0,"tv":0.0,"id":24420205},{"batb":[[0,4.5,1.99],[1,4.4,1.72],[2,4.3,4.65]],"ltp":0.0,"tv":0.0,"id":420}]}]}
{"op":"mcm","clk":"988218724","pt":1580475478977,"mc":[{"id":"1.168130661","rc":[{"batb":[[0,8,1.99],[1,7.6,2.84],[2,7.4,7]],"ltp":0.0,"tv":0.0,"id":25545675}]}]}
{"op":"mcm","clk":"988224638","pt":1580475553366,"mc":[{"id":"1.168130661","rc":[{"batb":[[0,4.5,6.43],[2,4.2,11]],"ltp":0.0,"tv":0.0,"id":24420205},{"batb":[[0,4.5,6.43],[2,4.2,12]],"ltp":0.0,"tv":0.0,"id":420}]}]}
{"op":"mcm","clk":"988224805","pt":1580475555412,"mc":[{"id":"1.168130661","rc":[{"batb":[[1,4.2,11.38],[2,1.51,3.36]],"ltp":0.0,"tv":0.0,"id":24420205},{"batb":[[1,4.2,12.38],[2,1.51,3.36]],"ltp":0.0,"tv":0.0,"id":420}]}]}
{"op":"mcm","clk":"988225198","pt":1580475559984,"mc":[{"id":"1.168130661","rc":[{"batb":[[0,4.6,1.27],[1,4.5,6.43],[2,4.2,11.38]],"ltp":0.0,"tv":0.0,"id":24420205},{"batb":[[0,4.6,1.27],[1,4.5,6.43],[2,4.2,12.38]],"ltp":0.0,"tv":0.0,"id":420}]}]}
{"op":"mcm","clk":"988226731","pt":1580475579616,"mc":[{"id":"1.168130661","rc":[{"batb":[[0,4.7,1.99],[1,4.6,1.27],[2,4.5,4.44]],"ltp":0.0,"tv":0.0,"id":24420205},{"batb":[[0,4.7,1.99],[1,4.6,1.27],[2,4.5,4.44]],"ltp":0.0,"tv":0.0,"id":420}]}]}
{"op":"mcm","clk":"988233204","pt":1580475648179,"mc":[{"id":"1.168130661","rc":[{"batb":[[2,4.2,11.38]],"ltp":0.0,"tv":0.0,"id":24420205},{"batb":[[2,4.2,12.38]],"ltp":0.0,"tv":0.0,"id":420}]}]}
{"op":"mcm","clk":"988367977","pt":1580476743900,"mc":[{"id":"1.168130661","rc":[{"batb":[[1,1.75,3],[2,1.74,44]],"ltp":0.0,"tv":0.0,"id":25238892},{"batb":[[2,4.3,3.38]],"ltp":0.0,"tv":0.0,"id":24420205},{"batb":[[1,1.75,3],[2,1.74,44]],"ltp":0.0,"tv":0.0,"id":26314798},{"batb":[[2,4.3,3.38]],"ltp":0.0,"tv":0.0,"id":420}]}]}
{"op":"mcm","clk":"988449959","pt":1580477373953,"mc":[{"id":"1.168130661","rc":[{"batb":[[0,7.2,2.91]],"ltp":0.0,"tv":0.0,"id":24707172}]}]}
{"op":"mcm","clk":"988451356","pt":1580477387537,"mc":[{"id":"1.168130661","rc":[{"batb":[[1,7.4,7.87],[2,1.51,3.36]],"ltp":0.0,"tv":0.0,"id":25545675},{"batb":[[2,4.4,1.52]],"ltp":0.0,"tv":0.0,"id":24420205},{"batb":[[2,4.4,1.52]],"ltp":0.0,"tv":0.0,"id":420}]}]}
{"op":"mcm","clk":"988454552","pt":1580477416365,"mc":[{"id":"1.168130661","rc":[{"batb":[[1,6.4,3.76],[2,6.2,7]],"ltp":0.0,"tv":0.0,"id":24707172}]}]}
{"op":"mcm","clk":"988518793","pt":1580477931722,"mc":[{"id":"1.168130661","rc":[{"batb":[[0,8,4.49]],"ltp":0.0,"tv":0.0,"id":25545675},{"batb":[[0,1.97,10.84],[1,1.96,4.76],[2,1.75,3]],"ltp":0.0,"tv":0.0,"id":25238892},{"batb":[[0,7.4,2.7],[1,7.2,2.91],[2,6.4,3.76]],"ltp":0.0,"tv":0.0,"id":24707172},{"batb":[[0,4.7,6.25]],"ltp":0.0,"tv":0.0,"id":24420205},{"batb":[[0,1.97,10.84],[1,1.96,4.76],[2,1.75,3]],"ltp":0.0,"tv":0.0,"id":26314798},{"batb":[[0,4.7,6.25]],"ltp":0.0,"tv":0.0,"id":420}]}]}
{"op":"mcm","clk":"988518898","pt":1580477932615,"mc":[{"id":"1.168130661","rc":[{"batb":[[1,7.4,7.21]],"ltp":0.0,"tv":0.0,"id":25545675},{"batb":[[0,4.8,1.04],[1,4.7,6.25],[2,4.6,1.27]],"ltp":0.0,"tv":0.0,"id":24420205},{"batb":[[2,4.3,3.38]],"ltp":0.0,"tv":0.0,"id":420}]}]}
{"op":"mcm","clk":"988518958","pt":1580477933148,"mc":[{"id":"1.168130661","rc":[{"batb":[[0,8,5.1]],"ltp":0.0,"tv":0.0,"id":25545675},{"batb":[[0,4.8,1.04],[1,4.7,6.25],[2,4.6,1.27]],"ltp":0.0,"tv":0.0,"id":420}]}]}
{"op":"mcm","clk":"988521353","pt":1580477955701,"mc":[{"id":"1.168130661","rc":[{"batb":[[1,1.75,3],[2,1.74,44]],"ltp":0.0,"tv":0.0,"id":25238892},{"batb":[[0,1.98,4.66],[1,1.97,10.84]],"ltp":0.0,"tv":0.0,"id":26314798}]}]}
{"op":"mcm","clk":"988521399","pt":1580477956016,"mc":[{"id":"1.168130661","rc":[{"batb":[[0,1.98,4.66],[1,1.97,10.84],[2,1.75,3]],"ltp":0.0,"tv":0.0,"id":25238892},{"batb":[[2,4.3,3.38]],"ltp":0.0,"tv":0.0,"id":24420205},{"batb":[[2,4.3,3.38]],"ltp":0.0,"tv":0.0,"id":420}]}]}
{"op":"mcm","clk":"988521887","pt":1580477960695,"mc":[{"id":"1.168130661","rc":[{"batb":[[0,4.8,2.24]],"ltp":0.0,"tv":0.0,"id":24420205},{"batb":[[0,4.8,2.24]],"ltp":0.0,"tv":0.0,"id":420}]}]}
{"op":"mcm","clk":"988522311","pt":1580477964611,"mc":[{"id":"1.168130661","rc":[{"batb":[[1,7,1.68],[2,6.4,3]],"ltp":0.0,"tv":0.0,"id":24707172},{"batb":[[0,4.9,1.99],[1,4.8,2.24],[2,4.7,4.26]],"ltp":0.0,"tv":0.0,"id":24420205},{"batb":[[0,4.9,1.99],[1,4.8,2.24],[2,4.7,4.26]],"ltp":0.0,"tv":0.0,"id":420}]}]}
{"op":"mcm","clk":"988522409","pt":1580477965615,"mc":[{"id":"1.168130661","rc":[{"batb":[[0,8.4,1.99],[1,8,3.11],[2,7.4,7.21]],"ltp":0.0,"tv":0.0,"id":25545675},{"batb":[[2,1.74,44]],"ltp":0.0,"tv":0.0,"id":25238892},{"batb":[[0,7.6,1.99],[1,7.4,2.7],[2,7,1.68]],"ltp":0.0,"tv":0.0,"id":24707172},{"batb":[[2,1.74,44]],"ltp":0.0,"tv":0.0,"id":26314798}]}]}
{"op":"mcm","clk":"988522428","pt":1580477965819,"mc":[{"id":"1.168130661","rc":[{"batb":[[0,1.98,7.66]],"ltp":0.0,"tv":0.0,"id":25238892},{"batb":[[0,1.98,7.66]],"ltp":0.0,"tv":0.0,"id":26314798}]}]}
{"op":"mcm","clk":"988524458","pt":1580477985737,"mc":[{"id":"1.168130661","rc":[{"batb":[[1,4.8,1.04]],"ltp":0.0,"tv":0.0,"id":24420205},{"batb":[[1,4.8,1.04]],"ltp":0.0,"tv":0.0,"id":420}]}]}
{"op":"mcm","clk":"988524921","pt":1580477990460,"mc":[{"id":"1.168130661","rc":[{"batb":[[0,5,1.14],[1,4.9,1.99],[2,4.8,1.04]],"ltp":0.0,"tv":0.0,"id":24420205},{"batb":[[0,5,1.14],[1,4.9,1.99],[2,4.8,1.04]],"ltp":0.0,"tv":0.0,"id":420}]}]}
{"op":"mcm","clk":"988527933","pt":1580478017608,"mc":[{"id":"1.168130661","rc":[{"batb":[[1,7.4,7.82],[2,1.51,3.36]],"ltp":0.0,"tv":0.0,"id":25545675},{"batb":[[1,7,1.68],[2,6.2,7]],"ltp":0.0,"tv":0.0,"id":24707172}]}]}
{"op":"mcm","clk":"988528039","pt":1580478018504,"mc":[{"id":"1.168130661","rc":[{"batb":[[0,8.4,4.95],[1,7.4,7.21]],"ltp":0.0,"tv":0.0,"id":25545675},{"batb":[[1,7.2,3.7],[2,6.2,7.76]],"ltp":0.0,"tv":0.0,"id":24707172},{"batb":[[0,5,5.14]],"ltp":0.0,"tv":0.0,"id":24420205},{"batb":[[0,5,5.14]],"ltp":0.0,"tv":0.0,"id":420}]}]}
{"op":"mcm","clk":"988529529","pt":1580478033226,"mc":[{"id":"1.168130661","rc":[{"batb":[[1,7.6,2.84],[2,7.4,7]],"ltp":0.0,"tv":0.0,"id":25545675}]}]}
{"op":"mcm","clk":"988530001","pt":1580478037617,"mc":[{"id":"1.168130661","rc":[{"batb":[[0,5.1,1.99],[1,5,5.14]],"ltp":0.0,"tv":0.0,"id":24420205},{"batb":[[0,5.1,1.99],[1,5,5.14]],"ltp":0.0,"tv":0.0,"id":420}]}]}
{"op":"mcm","clk":"988530129","pt":1580478038635,"mc":[{"id":"1.168130661","rc":[{"batb":[[0,8.8,1.99],[1,8.4,2.96],[2,7.6,2.84]],"ltp":0.0,"tv":0.0,"id":25545675},{"batb":[[0,7.4,1.99]],"ltp":0.0,"tv":0.0,"id":24707172}]}]}
{"op":"mcm","clk":"988530989","pt":1580478045866,"mc":[{"id":"1.168130661","rc":[{"batb":[[1,5,4]],"ltp":0.0,"tv":0.0,"id":24420205},{"batb":[[1,5,4]],"ltp":0.0,"tv":0.0,"id":420}]}]}
{"op":"mcm","clk":"988531570","pt":1580478050897,"mc":[{"id":"1.168130661","rc":[{"batb":[[0,5.2,1.09],[1,5.1,1.99],[2,5,4]],"ltp":0.0,"tv":0.0,"id":24420205},{"batb":[[0,5.2,1.09],[1,5.1,1.99],[2,5,4]],"ltp":0.0,"tv":0.0,"id":420}]}]}
{"op":"mcm","clk":"988532596","pt":1580478061184,"mc":[{"id":"1.168130661","rc":[{"batb":[[1,5.1,2.97]],"ltp":0.0,"tv":0.0,"id":24420205},{"batb":[[1,5.1,2.97]],"ltp":0.0,"tv":0.0,"id":420}]}]}
{"op":"mcm","clk":"988536049","pt":1580478094537,"mc":[{"id":"1.168130661","rc":[{"batb":[[2,7.4,7.21]],"ltp":0.0,"tv":0.0,"id":25545675},{"batb":[[2,6.4,3.76]],"ltp":0.0,"tv":0.0,"id":24707172}]}]}
{"op":"mcm","clk":"988536960","pt":1580478103664,"mc":[{"id":"1.168130661","rc":[{"batb":[[0,8.8,4.26],[1,7.4,7.79],[2,1.51,3.36]],"ltp":0.0,"tv":0.0,"id":25545675},{"batb":[[0,5.2,4.94],[2,4.3,3]],"ltp":0.0,"tv":0.0,"id":24420205},{"batb":[[0,5.2,4.94],[2,4.3,3]],"ltp":0.0,"tv":0.0,"id":420}]}]}
{"op":"mcm","clk":"988537048","pt":1580478104351,"mc":[{"id":"1.168130661","rc":[{"batb":[[0,5.2,5.88],[1,5.1,1.99]],"ltp":0.0,"tv":0.0,"id":24420205},{"batb":[[0,5.2,5.88],[1,5.1,1.99]],"ltp":0.0,"tv":0.0,"id":420}]}]}
{"op":"mcm","clk":"988537182","pt":1580478105675,"mc":[{"id":"1.168130661","rc":[{"batb":[[0,5.2,4.79]],"ltp":0.0,"tv":0.0,"id":24420205}]}]}
{"op":"mcm","clk":"988537189","pt":1580478105766,"mc":[{"id":"1.168130661","rc":[{"batb":[[0,5.2,4.79]],"ltp":0.0,"tv":0.0,"id":420}]}]}
{"op":"mcm","clk":"988537711","pt":1580478110464,"mc":[{"id":"1.168130661","rc":[{"batb":[[0,5.3,2.01],[1,5.2,3.85],[2,5.1,1.99]],"ltp":0.0,"tv":0.0,"id":24420205},{"batb":[[0,5.3,2.01],[1,5.2,3.85],[2,5.1,1.99]],"ltp":0.0,"tv":0.0,"id":420}]}]}
{"op":"mcm","clk":"988538479","pt":1580478117595,"mc":[{"id":"1.168130661","rc":[{"batb":[[0,5.4,1.99],[1,5.3,2.01],[2,5.2,3.85]],"ltp":0.0,"tv":0.0,"id":420}]}]}
{"op":"mcm","clk":"988538551","pt":1580478118286,"mc":[{"id":"1.168130661","rc":[{"batb":[[0,8.8,2.27]],"ltp":0.0,"tv":0.0,"id":25545675},{"batb":[[0,5.4,1.99],[1,5.3,2.01],[2,5.2,3.85]],"ltp":0.0,"tv":0.0,"id":24420205}]}]}
{"op":"mcm","clk":"988540238","pt":1580478135428,"mc":[{"id":"1.168130661","rc":[{"batb":[[1,5.2,4.79],[2,4.3,3]],"ltp":0.0,"tv":0.0,"id":24420205},{"batb":[[1,5.2,4.79],[2,4.3,3]],"ltp":0.0,"tv":0.0,"id":420}]}]}
{"op":"mcm","clk":"988540691","pt":1580478140127,"mc":[{"id":"1.168130661","rc":[{"batb":[[0,5.5,1.01],[1,5.4,1.99],[2,5.2,4.79]],"ltp":0.0,"tv":0.0,"id":24420205},{"batb":[[0,5.5,1.01],[1,5.4,1.99],[2,5.2,4.79]],"ltp":0.0,"tv":0.0,"id":420}]}]}
{"op":"mcm","clk":"988545683","pt":1580478188352,"mc":[{"id":"1.168130661","rc":[{"batb":[[0,5.6,1.99],[1,5.5,1.01]],"ltp":0.0,"tv":0.0,"id":24420205},{"batb":[[0,5.6,1.99],[1,5.5,1.01]],"ltp":0.0,"tv":0.0,"id":420}]}]}
{"op":"mcm","clk":"988545817","pt":1580478189611,"mc":[{"id":"1.168130661","rc":[{"batb":[[0,8,3.08],[1,7.4,7.21]],"ltp":0.0,"tv":0.0,"id":25545675},{"batb":[[0,5.6,5.56],[2,4.2,11.94]],"ltp":0.0,"tv":0.0,"id":24420205},{"batb":[[0,5.6,5.56],[2,4.2,12.94]],"ltp":0.0,"tv":0.0,"id":420}]}]}
{"op":"mcm","clk":"988546604","pt":1580478196007,"mc":[{"id":"1.168130661","rc":[{"batb":[[1,4.2,11.94],[2,1.51,3.36]],"ltp":0.0,"tv":0.0,"id":24420205},{"batb":[[1,4.2,12.94],[2,1.51,3.36]],"ltp":0.0,"tv":0.0,"id":420}]}]}
{"op":"mcm","clk":"988547156","pt":1580478200798,"mc":[{"id":"1.168130661","rc":[{"batb":[[0,5.6,6.54]],"ltp":0.0,"tv":0.0,"id":24420205},{"batb":[[0,5.6,6.54]],"ltp":0.0,"tv":0.0,"id":420}]}]}
{"op":"mcm","clk":"988549039","pt":1580478217793,"mc":[{"id":"1.168130661","rc":[{"batb":[[1,7.6,2.84],[2,7.4,7]],"ltp":0.0,"tv":0.0,"id":25545675}]}]}
{"op":"mcm","clk":"988554778","pt":1580478271683,"mc":[{"id":"1.168130661","rc":[{"batb":[[1,4.2,11]],"ltp":0.0,"tv":0.0,"id":24420205},{"batb":[[1,4.2,12]],"ltp":0.0,"tv":0.0,"id":420}]}]}
{"op":"mcm","clk":"988554829","pt":1580478272209,"mc":[{"id":"1.168130661","rc":[{"batb":[[0,5.7,1.86],[1,5.6,5.56],[2,4.2,11]],"ltp":0.0,"tv":0.0,"id":24420205},{"batb":[[0,5.7,1.86],[1,5.6,5.56],[2,4.2,12]],"ltp":0.0,"tv":0.0,"id":420}]}]}
{"op":"mcm","clk":"988555222","pt":1580478275704,"mc":[{"id":"1.168130661","rc":[{"batb":[[0,7.8,3.35],[1,7.6,2.63]],"ltp":0.0,"tv":0.0,"id":25545675},{"batb":[[1,5.6,3.57]],"ltp":0.0,"tv":0.0,"id":24420205},{"batb":[[1,5.6,3.57]],"ltp":0.0,"tv":0.0,"id":420}]}]}
{"op":"mcm","clk":"988555270","pt":1580478276077,"mc":[{"id":"1.168130661","rc":[{"batb":[[0,8.8,1.99],[1,7.8,3.35],[2,7.6,2.63]],"ltp":0.0,"tv":0.0,"id":25545675}]}]}
{"op":"mcm","clk":"988555669","pt":1580478279386,"mc":[{"id":"1.168130661","rc":[{"batb":[[2,4.3,3]],"ltp":0.0,"tv":0.0,"id":24420205},{"batb":[[2,4.3,3]],"ltp":0.0,"tv":0.0,"id":420}]}]}
{"op":"mcm","clk":"988562721","pt":1580478348553,"mc":[{"id":"1.168130661","rc":[{"batb":[[0,7.8,3.35],[1,7.6,2.63],[2,7.4,7]],"ltp":0.0,"tv":0.0,"id":25545675}]}]}
{"op":"mcm","clk":"988563919","pt":1580478360549,"mc":[{"id":"1.168130661","rc":[{"batb":[[1,4.3,7.65],[2,4.2,11]],"ltp":0.0,"tv":0.0,"id":24420205},{"batb":[[1,4.3,7.65],[2,4.2,12]],"ltp":0.0,"tv":0.0,"id":420}]}]}
{"op":"mcm","clk":"988566962","pt":1580478391261,"mc":[{"id":"1.168130661","rc":[{"batb":[[1,4.3,4.65]],"ltp":0.0,"tv":0.0,"id":24420205},{"batb":[[1,4.3,4.65]],"ltp":0.0,"tv":0.0,"id":420}]}]}
{"op":"mcm","clk":"988627571","pt":1580479041326,"mc":[{"id":"1.168130661","rc":[{"batb":[[0,2,1.68],[1,1.98,7.66],[2,1.97,10.84]],"ltp":0.0,"tv":0.0,"id":25238892}]}]}
{"op":"mcm","clk":"988627637","pt":1580479042221,"mc":[{"id":"1.168130661","rc":[{"batb":[[0,1.98,7.66],[1,1.97,10.84],[2,1.74,44]],"ltp":0.0,"tv":0.0,"id":25238892}]}]}
{"op":"mcm","clk":"988688656","pt":1580479652226,"mc":[{"id":"1.168130661","rc":[{"batb":[[0,1.98,7.66],[1,1.97,10.84]],"ltp":0.0,"tv":0.0,"id":25238892},{"batb":[[2,6.4,3.76]],"ltp":0.0,"tv":0.0,"id":24707172},{"batb":[[0,5.7,1.85]],"ltp":0.0,"tv":0.0,"id":24420205},{"batb":[[0,1.98,7.66],[1,1.97,10.84]],"ltp":0.0,"tv":0.0,"id":26314798},{"batb":[[0,5.7,1.85]],"ltp":0.0,"tv":0.0,"id":420}]}]}
{"op":"mcm","clk":"988934369","pt":1580482334425,"mc":[{"id":"1.168130661","rc":[{"batb":[[0,2.42,2],[1,1.98,7.66],[2,1.97,10.84]],"ltp":0.0,"tv":0.0,"id":25238892}]}]}
{"op":"mcm","clk":"988944656","pt":1580482365902,"mc":[{"id":"1.168130661","rc":[{"batb":[[2,1.74,44.84]],"ltp":0.0,"tv":0.0,"id":25238892}]}]}
{"op":"mcm","clk":"988944998","pt":1580482371678,"mc":[{"id":"1.168130661","rc":[{"batb":[[0,1.98,7.66],[1,1.74,44.84],[2,1.51,3.36]],"ltp":0.0,"tv":0.0,"id":25238892}]}]}
{"op":"mcm","clk":"988945500","pt":1580482379905,"mc":[{"id":"1.168130661","rc":[{"batb":[[0,1.98,4.66],[1,1.75,3.84],[2,1.74,44]],"ltp":0.0,"tv":0.0,"id":25238892}]}]}
{"op":"mcm","clk":"988954106","pt":1580482527281,"mc":[{"id":"1.168130661","rc":[{"batb":[[0,1.98,14.66]],"ltp":0.0,"tv":0.0,"id":25238892}]}]}
{"op":"mcm","clk":"988954875","pt":1580482540369,"mc":[{"id":"1.168130661","rc":[{"batb":[[0,1.99,3],[1,1.98,14.66],[2,1.74,44.84]],"ltp":0.0,"tv":0.0,"id":25238892}]}]}
{"op":"mcm","clk":"988955242","pt":1580482546459,"mc":[{"id":"1.168130661","rc":[{"batb":[[0,1.99,7.61],[1,1.98,10]],"ltp":0.0,"tv":0.0,"id":25238892}]}]}
{"op":"mcm","clk":"988956311","pt":1580482565205,"mc":[{"id":"1.168130661","rc":[{"batb":[[0,2,1.99],[1,1.99,7.61],[2,1.98,10]],"ltp":0.0,"tv":0.0,"id":25238892}]}]}
{"op":"mcm","clk":"988957763","pt":1580482590350,"mc":[{"id":"1.168130661","rc":[{"batb":[[1,1.99,4.61]],"ltp":0.0,"tv":0.0,"id":25238892}]}]}
{"op":"mcm","clk":"988959398","pt":1580482617962,"mc":[{"id":"1.168130661","rc":[{"batb":[[0,2,11.99],[2,1.74,44.84]],"ltp":0.0,"tv":0.0,"id":25238892}]}]}
{"op":"mcm","clk":"988960480","pt":1580482636151,"mc":[{"id":"1.168130661","rc":[{"batb":[[0,2.02,4.47],[1,2,11.99]],"ltp":0.0,"tv":0.0,"id":25238892}]}]}
{"op":"mcm","clk":"988961796","pt":1580482658379,"mc":[{"id":"1.168130661","rc":[{"batb":[[0,2.04,1.99],[1,2.02,4.47],[2,2,10]],"ltp":0.0,"tv":0.0,"id":25238892}]}]}
{"op":"mcm","clk":"988965458","pt":1580482715146,"mc":[{"id":"1.168130661","rc":[{"batb":[[0,2.04,11.79],[2,1.74,44.84]],"ltp":0.0,"tv":0.0,"id":25238892}]}]}
{"op":"mcm","clk":"988966071","pt":1580482726355,"mc":[{"id":"1.168130661","rc":[{"batb":[[0,2.06,4.31],[1,2.04,11.79]],"ltp":0.0,"tv":0.0,"id":25238892}]}]}
{"op":"mcm","clk":"988967396","pt":1580482741677,"mc":[{"id":"1.168130661","rc":[{"batb":[[2,1.74,44]],"ltp":0.0,"tv":0.0,"id":25238892}]}]}
{"op":"mcm","clk":"988968009","pt":1580482750973,"mc":[{"id":"1.168130661","rc":[{"batb":[[0,2.06,7.31]],"ltp":0.0,"tv":0.0,"id":25238892}]}]}
{"op":"mcm","clk":"988968667","pt":1580482762714,"mc":[{"id":"1.168130661","rc":[{"batb":[[1,2.04,9.8]],"ltp":0.0,"tv":0.0,"id":25238892}]}]}
{"op":"mcm","clk":"988971597","pt":1580482798236,"mc":[{"id":"1.168130661","rc":[{"batb":[[1,1.75,10]],"ltp":0.0,"tv":0.0,"id":25238892}]}]}
{"op":"mcm","clk":"988971835","pt":1580482801152,"mc":[{"id":"1.168130661","rc":[{"batb":[[0,2.06,4.31],[1,1.76,3],[2,1.75,10]],"ltp":0.0,"tv":0.0,"id":25238892}]}]}
{"op":"mcm","clk":"988978789","pt":1580482881318,"mc":[{"id":"1.168130661","rc":[{"batb":[[2,1.74,44]],"ltp":0.0,"tv":0.0,"id":25238892}]}]}
{"op":"mcm","clk":"988980853","pt":1580482906355,"mc":[{"id":"1.168130661","rc":[{"batb":[[1,1.74,44],[2,1.51,3.36]],"ltp":0.0,"tv":0.0,"id":25238892}]}]}
{"op":"mcm","clk":"989004185","pt":1580483194154,"mc":[{"id":"1.168130661","rc":[{"batb":[[1,1.75,10],[2,1.74,44]],"ltp":0.0,"tv":0.0,"id":25238892}]}]}
{"op":"mcm","clk":"989074755","pt":1580484028184,"mc":[{"id":"1.168130661","rc":[{"batb":[[1,1.76,3],[2,1.75,10]],"ltp":0.0,"tv":0.0,"id":25238892}]}]}
{"op":"mcm","clk":"989075283","pt":1580484034956,"mc":[{"id":"1.168130661","rc":[{"batb":[[1,1.77,10],[2,1.76,3]],"ltp":0.0,"tv":0.0,"id":25238892}]}]}
{"op":"mcm","clk":"989078388","pt":1580484074090,"mc":[{"id":"1.168130661","rc":[{"batb":[[1,1.78,3],[2,1.77,10]],"ltp":0.0,"tv":0.0,"id":25238892}]}]}
{"op":"mcm","clk":"989081304","pt":1580484109713,"mc":[{"id":"1.168130661","rc":[{"batb":[[1,1.79,10],[2,1.78,3]],"ltp":0.0,"tv":0.0,"id":25238892}]}]}
{"op":"mcm","clk":"989082065","pt":1580484119237,"mc":[{"id":"1.168130661","rc":[{"batb":[[1,1.8,3],[2,1.79,10]],"ltp":0.0,"tv":0.0,"id":25238892}]}]}
{"op":"mcm","clk":"989095916","pt":1580484184416,"mc":[{"id":"1.168130661","rc":[{"batb":[[1,1.81,10],[2,1.8,3]],"ltp":0.0,"tv":0.0,"id":25238892}]}]}
{"op":"mcm","clk":"989097750","pt":1580484209020,"mc":[{"id":"1.168130661","rc":[{"batb":[[1,1.82,3],[2,1.81,10]],"ltp":0.0,"tv":0.0,"id":25238892}]}]}
{"op":"mcm","clk":"989101737","pt":1580484259701,"mc":[{"id":"1.168130661","rc":[{"batb":[[1,1.83,10],[2,1.82,3]],"ltp":0.0,"tv":0.0,"id":25238892}]}]}
{"op":"mcm","clk":"989104887","pt":1580484299596,"mc":[{"id":"1.168130661","rc":[{"batb":[[1,1.84,3],[2,1.83,10]],"ltp":0.0,"tv":0.0,"id":25238892}]}]}
{"op":"mcm","clk":"989107810","pt":1580484334671,"mc":[{"id":"1.168130661","rc":[{"batb":[[1,1.85,10],[2,1.84,3]],"ltp":0.0,"tv":0.0,"id":25238892}]}]}
{"op":"mcm","clk":"989108593","pt":1580484345578,"mc":[{"id":"1.168130661","rc":[{"batb":[[1,1.86,3],[2,1.85,10]],"ltp":0.0,"tv":0.0,"id":25238892}]}]}
{"op":"mcm","clk":"989113370","pt":1580484410219,"mc":[{"id":"1.168130661","rc":[{"batb":[[1,1.87,10],[2,1.86,3]],"ltp":0.0,"tv":0.0,"id":25238892}]}]}
{"op":"mcm","clk":"989115560","pt":1580484441656,"mc":[{"id":"1.168130661","rc":[{"batb":[[0,2.08,1.99],[1,2.06,4.31],[2,1.88,3]],"ltp":0.0,"tv":0.0,"id":25238892}]}]}
{"op":"mcm","clk":"989118474","pt":1580484484832,"mc":[{"id":"1.168130661","rc":[{"batb":[[0,2.08,11.61]],"ltp":0.0,"tv":0.0,"id":25238892}]}]}
{"op":"mcm","clk":"989118910","pt":1580484491482,"mc":[{"id":"1.168130661","rc":[{"batb":[[0,2.1,3],[1,2.08,11.61],[2,2.06,4.31]],"ltp":0.0,"tv":0.0,"id":25238892}]}]}
{"op":"mcm","clk":"989119227","pt":1580484496502,"mc":[{"id":"1.168130661","rc":[{"batb":[[0,2.1,7.15],[2,1.74,44]],"ltp":0.0,"tv":0.0,"id":25238892}]}]}
{"op":"mcm","clk":"989121609","pt":1580484532139,"mc":[{"id":"1.168130661","rc":[{"batb":[[1,2.08,9.62]],"ltp":0.0,"tv":0.0,"id":25238892}]}]}
{"op":"mcm","clk":"989123695","pt":1580484560463,"mc":[{"id":"1.168130661","rc":[{"batb":[[1,1.75,10]],"ltp":0.0,"tv":0.0,"id":25238892}]}]}
{"op":"mcm","clk":"989125519","pt":1580484587394,"mc":[{"id":"1.168130661","rc":[{"batb":[[0,2.1,4.15],[1,1.76,3],[2,1.75,10]],"ltp":0.0,"tv":0.0,"id":25238892}]}]}
{"op":"mcm","clk":"989129243","pt":1580484637153,"mc":[{"id":"1.168130661","rc":[{"batb":[[1,1.77,10],[2,1.76,3]],"ltp":0.0,"tv":0.0,"id":25238892}]}]}
{"op":"mcm","clk":"989129336","pt":1580484638668,"mc":[{"id":"1.168130661","rc":[{"batb":[[1,1.78,3],[2,1.77,10]],"ltp":0.0,"tv":0.0,"id":25238892}]}]}
{"op":"mcm","clk":"989135561","pt":1580484714455,"mc":[{"id":"1.168130661","rc":[{"batb":[[1,1.79,10],[2,1.78,3]],"ltp":0.0,"tv":0.0,"id":25238892}]}]}
{"op":"mcm","clk":"989137393","pt":1580484739462,"mc":[{"id":"1.168130661","rc":[{"batb":[[1,1.8,3],[2,1.79,10]],"ltp":0.0,"tv":0.0,"id":25238892}]}]}
{"op":"mcm","clk":"989141618","pt":1580484790232,"mc":[{"id":"1.168130661","rc":[{"batb":[[1,1.81,10],[2,1.8,3]],"ltp":0.0,"tv":0.0,"id":25238892}]}]}
{"op":"mcm","clk":"989144934","pt":1580484835334,"mc":[{"id":"1.168130661","rc":[{"batb":[[1,1.82,3],[2,1.81,10]],"ltp":0.0,"tv":0.0,"id":25238892}]}]}
{"op":"mcm","clk":"989147112","pt":1580484865871,"mc":[{"id":"1.168130661","rc":[{"batb":[[1,1.83,10],[2,1.82,3]],"ltp":0.0,"tv":0.0,"id":25238892}]}]}
{"op":"mcm","clk":"989148160","pt":1580484880187,"mc":[{"id":"1.168130661","rc":[{"batb":[[1,1.84,3],[2,1.83,10]],"ltp":0.0,"tv":0.0,"id":25238892}]}]}
{"op":"mcm","clk":"989152825","pt":1580484941051,"mc":[{"id":"1.168130661","rc":[{"batb":[[1,1.85,10],[2,1.84,3]],"ltp":0.0,"tv":0.0,"id":25238892}]}]}
{"op":"mcm","clk":"989156419","pt":1580484982500,"mc":[{"id":"1.168130661","rc":[{"batb":[[1,1.86,3],[2,1.85,10]],"ltp":0.0,"tv":0.0,"id":25238892}]}]}
{"op":"mcm","clk":"989159608","pt":1580485016541,"mc":[{"id":"1.168130661","rc":[{"batb":[[1,1.87,10],[2,1.86,3]],"ltp":0.0,"tv":0.0,"id":25238892}]}]}
{"op":"mcm","clk":"989161408","pt":1580485034338,"mc":[{"id":"1.168130661","rc":[{"batb":[[1,1.88,3],[2,1.87,10]],"ltp":0.0,"tv":0.0,"id":25238892}]}]}
{"op":"mcm","clk":"989175156","pt":1580485092688,"mc":[{"id":"1.168130661","rc":[{"batb":[[1,1.89,10],[2,1.88,3]],"ltp":0.0,"tv":0.0,"id":25238892}]}]}
{"op":"mcm","clk":"989178331","pt":1580485130640,"mc":[{"id":"1.168130661","rc":[{"batb":[[1,1.9,3],[2,1.89,10]],"ltp":0.0,"tv":0.0,"id":25238892}]}]}
{"op":"mcm","clk":"989181111","pt":1580485165119,"mc":[{"id":"1.168130661","rc":[{"batb":[[1,1.91,10],[2,1.9,3]],"ltp":0.0,"tv":0.0,"id":25238892}]}]}
{"op":"mcm","clk":"989182269","pt":1580485180934,"mc":[{"id":"1.168130661","rc":[{"batb":[[1,1.92,3],[2,1.91,10]],"ltp":0.0,"tv":0.0,"id":25238892}]}]}
{"op":"mcm","clk":"989184098","pt":1580485205079,"mc":[{"id":"1.168130661","rc":[{"batb":[[0,2.12,1.99],[1,2.1,4.15],[2,1.92,3]],"ltp":0.0,"tv":0.0,"id":25238892}]}]}
{"op":"mcm","clk":"989186985","pt":1580485242289,"mc":[{"id":"1.168130661","rc":[{"batb":[[0,2.12,11.42]],"ltp":0.0,"tv":0.0,"id":25238892}]}]}
{"op":"mcm","clk":"989187282","pt":1580485246387,"mc":[{"id":"1.168130661","rc":[{"batb":[[0,2.14,4],[1,2.12,11.42]],"ltp":0.0,"tv":0.0,"id":25238892}]}]}
{"op":"mcm","clk":"989187597","pt":1580485250582,"mc":[{"id":"1.168130661","rc":[{"batb":[[1,2.12,9.43]],"ltp":0.0,"tv":0.0,"id":25238892}]}]}
{"op":"mcm","clk":"989189898","pt":1580485281202,"mc":[{"id":"1.168130661","rc":[{"batb":[[0,2.14,7],[2,1.74,44]],"ltp":0.0,"tv":0.0,"id":25238892}]}]}
{"op":"mcm","clk":"989192586","pt":1580485318471,"mc":[{"id":"1.168130661","rc":[{"batb":[[1,1.75,10]],"ltp":0.0,"tv":0.0,"id":25238892}]}]}
{"op":"mcm","clk":"989193530","pt":1580485331568,"mc":[{"id":"1.168130661","rc":[{"batb":[[0,2.14,4],[1,1.76,3],[2,1.75,10]],"ltp":0.0,"tv":0.0,"id":25238892}]}]}
{"op":"mcm","clk":"989197992","pt":1580485393532,"mc":[{"id":"1.168130661","rc":[{"batb":[[1,1.77,10],[2,1.76,3]],"ltp":0.0,"tv":0.0,"id":25238892}]}]}
{"op":"mcm","clk":"989200433","pt":1580485427280,"mc":[{"id":"1.168130661","rc":[{"batb":[[1,1.78,3],[2,1.77,10]],"ltp":0.0,"tv":0.0,"id":25238892}]}]}
{"op":"mcm","clk":"989203911","pt":1580485468630,"mc":[{"id":"1.168130661","rc":[{"batb":[[1,1.79,10],[2,1.78,3]],"ltp":0.0,"tv":0.0,"id":25238892}]}]}
{"op":"mcm","clk":"989204704","pt":1580485478035,"mc":[{"id":"1.168130661","rc":[{"batb":[[1,1.8,3],[2,1.79,10]],"ltp":0.0,"tv":0.0,"id":25238892}]}]}
{"op":"mcm","clk":"989210358","pt":1580485543977,"mc":[{"id":"1.168130661","rc":[{"batb":[[1,1.81,10],[2,1.8,3]],"ltp":0.0,"tv":0.0,"id":25238892}]}]}
{"op":"mcm","clk":"989212326","pt":1580485568671,"mc":[{"id":"1.168130661","rc":[{"batb":[[1,1.82,3],[2,1.81,10]],"ltp":0.0,"tv":0.0,"id":25238892}]}]}
{"op":"mcm","clk":"989216349","pt":1580485616184,"mc":[{"id":"1.168130661","rc":[{"batb":[[2,1.74,44]],"ltp":0.0,"tv":0.0,"id":25238892}]}]}
{"op":"mcm","clk":"989219760","pt":1580485660254,"mc":[{"id":"1.168130661","rc":[{"batb":[[1,1.75,3]],"ltp":0.0,"tv":0.0,"id":25238892}]}]}
{"op":"mcm","clk":"989259003","pt":1580486056191,"mc":[{"id":"1.168130661","rc":[{"batb":[[1,1.76,10],[2,1.75,3]],"ltp":0.0,"tv":0.0,"id":25238892}]}]}
{"op":"mcm","clk":"989263454","pt":1580486105151,"mc":[{"id":"1.168130661","rc":[{"batb":[[1,1.77,3],[2,1.76,10]],"ltp":0.0,"tv":0.0,"id":25238892}]}]}
{"op":"mcm","clk":"989265269","pt":1580486127457,"mc":[{"id":"1.168130661","rc":[{"batb":[[1,1.78,10],[2,1.77,3]],"ltp":0.0,"tv":0.0,"id":25238892}]}]}
{"op":"mcm","clk":"989266800","pt":1580486150586,"mc":[{"id":"1.168130661","rc":[{"batb":[[1,1.79,3],[2,1.78,10]],"ltp":0.0,"tv":0.0,"id":25238892}]}]}
{"op":"mcm","clk":"989271307","pt":1580486212040,"mc":[{"id":"1.168130661","rc":[{"batb":[[1,1.8,10],[2,1.79,3]],"ltp":0.0,"tv":0.0,"id":25238892}]}]}
{"op":"mcm","clk":"989276366","pt":1580486274689,"mc":[{"id":"1.168130661","rc":[{"batb":[[1,1.81,3],[2,1.8,10]],"ltp":0.0,"tv":0.0,"id":25238892}]}]}
{"op":"mcm","clk":"989278581","pt":1580486304380,"mc":[{"id":"1.168130661","rc":[{"batb":[[1,1.82,10],[2,1.81,3]],"ltp":0.0,"tv":0.0,"id":25238892}]}]}
{"op":"mcm","clk":"989282025","pt":1580486342253,"mc":[{"id":"1.168130661","rc":[{"batb":[[1,1.83,3],[2,1.82,10]],"ltp":0.0,"tv":0.0,"id":25238892}]}]}
{"op":"mcm","clk":"989286067","pt":1580486388495,"mc":[{"id":"1.168130661","rc":[{"batb":[[1,1.84,10],[2,1.83,3]],"ltp":0.0,"tv":0.0,"id":25238892}]}]}
{"op":"mcm","clk":"989288174","pt":1580486410772,"mc":[{"id":"1.168130661","rc":[{"batb":[[0,2.14,3.99],[2,1.74,44]],"ltp":0.0,"tv":0.0,"id":25238892},{"batb":[[2,6.4,3.76]],"ltp":0.0,"tv":0.0,"id":24707172},{"batb":[[0,5.7,1.85]],"ltp":0.0,"tv":0.0,"id":24420205},{"batb":[[0,1.98,7.64],[1,1.97,10.84]],"ltp":0.0,"tv":0.0,"id":26314798},{"batb":[[0,5.7,1.85]],"ltp":0.0,"tv":0.0,"id":420}]}]}
{"op":"mcm","clk":"989293886","pt":1580486467695,"mc":[{"id":"1.168130661","rc":[{"batb":[[1,1.75,10]],"ltp":0.0,"tv":0.0,"id":25238892}]}]}
{"op":"mcm","clk":"989311037","pt":1580486639270,"mc":[{"id":"1.168130661","rc":[{"batb":[[0,1.99,1.68],[1,1.98,7.64],[2,1.97,10.84]],"ltp":0.0,"tv":0.0,"id":26314798}]}]}
{"op":"mcm","clk":"989311120","pt":1580486640167,"mc":[{"id":"1.168130661","rc":[{"batb":[[0,1.98,7.64],[1,1.97,10.84],[2,1.74,44]],"ltp":0.0,"tv":0.0,"id":26314798}]}]}
{"op":"mcm","clk":"989400062","pt":1580487458702,"mc":[{"id":"1.168130661","rc":[{"batb":[[0,1.99,4.62],[1,1.98,7.64],[2,1.97,10.84]],"batl":[[0,1000,0.21]],"ltp":0.0,"tv":0.0,"id":26314798}]}]}
{"op":"mcm","clk":"989400145","pt":1580487459610,"mc":[{"id":"1.168130661","rc":[{"batb":[[1,1.76,3.5],[2,1.75,10]],"batl":[[0,1000,0.21]],"ltp":0.0,"tv":0.0,"id":25238892},{"batb":[[1,4.4,1.68],[2,4.3,4.65]],"batl":[[0,1000,1.88]],"ltp":0.0,"tv":0.0,"id":420}]}]}
{"op":"mcm","clk":"989400227","pt":1580487460719,"mc":[{"id":"1.168130661","rc":[{"batb":[[1,4.4,1.68],[2,4.3,4.65]],"batl":[[0,1000,0.21]],"ltp":0.0,"tv":0.0,"id":24420205},{"batl":[[0,1000,0.21]],"ltp":0.0,"tv":0.0,"id":420}]}]}
{"op":"mcm","clk":"989400315","pt":1580487461719,"mc":[{"id":"1.168130661","rc":[{"batb":[[0,8,2.26],[1,7.8,2.77],[2,7.6,2.63]],"ltp":0.0,"tv":0.0,"id":25545675},{"batb":[[0,7.6,1.68],[1,7.4,1.99],[2,7.2,3.7]],"batl":[[0,1000,0.22]],"ltp":0.0,"tv":0.0,"id":24707172}]}]}
{"op":"mcm","clk":"989400370","pt":1580487462352,"mc":[{"id":"1.168130661","rc":[{"batl":[[0,1000,0.22]],"ltp":0.0,"tv":0.0,"id":25545675}]}]}
{"op":"mcm","clk":"989400995","pt":1580487468631,"mc":[{"id":"1.168130661","rc":[{"batb":[[0,2,1.99],[1,1.99,4.62],[2,1.98,7.64]],"ltp":0.0,"tv":0.0,"id":26314798}]}]}
{"op":"mcm","clk":"989401068","pt":1580487469424,"mc":[{"id":"1.168130661","rc":[{"batb":[[0,8.8,1.99],[1,8,2.26],[2,7.6,2.84]],"ltp":0.0,"tv":0.0,"id":25545675},{"batb":[[2,1.74,44]],"ltp":0.0,"tv":0.0,"id":25238892},{"batb":[[0,7.8,1.99],[1,7.6,1.68]],"ltp":0.0,"tv":0.0,"id":24707172},{"batb":[[2,4.2,11]],"ltp":0.0,"tv":0.0,"id":24420205},{"batb":[[2,4.2,12]],"ltp":0.0,"tv":0.0,"id":420}]}]}
{"op":"mcm","clk":"989407059","pt":1580487538239,"mc":[{"id":"1.168130661","rc":[{"batb":[[2,7,1.68]],"ltp":0.0,"tv":0.0,"id":24707172}]}]}
{"op":"mcm","clk":"989409814","pt":1580487572694,"mc":[{"id":"1.168130661","rc":[{"batb":[[0,2.16,1.88],[1,2.14,3.99]],"ltp":0.0,"tv":0.0,"id":25238892},{"batb":[[0,2.02,1.68],[1,2,1.99]],"ltp":0.0,"tv":0.0,"id":26314798},{"batb":[[1,4.2,12],[2,1.51,3.36]],"ltp":0.0,"tv":0.0,"id":420}]}]}
{"op":"mcm","clk":"989409898","pt":1580487573600,"mc":[{"id":"1.168130661","rc":[{"batb":[[1,7.6,3.42],[2,7.4,7]],"ltp":0.0,"tv":0.0,"id":25545675},{"batb":[[0,8,1.68],[1,7.8,1.99]],"ltp":0.0,"tv":0.0,"id":24707172},{"batb":[[0,5.8,1.68],[1,5.7,1.85]],"ltp":0.0,"tv":0.0,"id":24420205},{"batb":[[0,5.8,1.68],[1,5.7,1.85],[2,4.2,12]],"ltp":0.0,"tv":0.0,"id":420}]}]}
{"op":"mcm","clk":"989409928","pt":1580487573819,"mc":[{"id":"1.168130661","rc":[{"batb":[[0,9,1.68],[1,8.8,1.99],[2,7.6,3.42]],"ltp":0.0,"tv":0.0,"id":25545675}]}]}
{"op":"mcm","clk":"989410915","pt":1580487587513,"mc":[{"id":"1.168130661","rc":[{"batb":[[1,4.2,11.88],[2,1.51,3.36]],"ltp":0.0,"tv":0.0,"id":24420205},{"batb":[[1,4.2,12.88],[2,1.51,3.36]],"ltp":0.0,"tv":0.0,"id":420}]}]}
{"op":"mcm","clk":"989411222","pt":1580487591516,"mc":[{"id":"1.168130661","rc":[{"batb":[[0,5.8,2.61]],"ltp":0.0,"tv":0.0,"id":24420205},{"batb":[[0,2.04,1.99],[1,2.02,1.68]],"ltp":0.0,"tv":0.0,"id":26314798},{"batb":[[0,5.8,2.61]],"ltp":0.0,"tv":0.0,"id":420}]}]}
{"op":"mcm","clk":"989411299","pt":1580487592622,"mc":[{"id":"1.168130661","rc":[{"batb":[[0,9.2,1.99],[1,9,1.68]],"ltp":0.0,"tv":0.0,"id":25545675},{"batb":[[0,8.2,1.99],[1,8,1.68]],"ltp":0.0,"tv":0.0,"id":24707172}]}]}
{"op":"mcm","clk":"989411669","pt":1580487597430,"mc":[{"id":"1.168130661","rc":[{"batb":[[2,7.6,3.21]],"ltp":0.0,"tv":0.0,"id":25545675}]}]}
{"op":"mcm","clk":"989414708","pt":1580487633702,"mc":[{"id":"1.168130661","rc":[{"batb":[[0,8,1.68],[1,7,1.68],[2,6.4,3]],"ltp":0.0,"tv":0.0,"id":24707172},{"batb":[[0,6,1.99],[1,5.8,2.61],[2,4.2,11.88]],"ltp":0.0,"tv":0.0,"id":24420205},{"batb":[[0,6,1.99],[1,5.8,2.61],[2,4.2,12.88]],"ltp":0.0,"tv":0.0,"id":420}]}]}
{"op":"mcm","clk":"989415756","pt":1580487646667,"mc":[{"id":"1.168130661","rc":[{"batb":[[1,5.8,1.68]],"ltp":0.0,"tv":0.0,"id":24420205},{"batb":[[1,5.8,1.68]],"ltp":0.0,"tv":0.0,"id":420}]}]}
{"op":"mcm","clk":"989416039","pt":1580487650202,"mc":[{"id":"1.168130661","rc":[{"batb":[[0,6,2.86]],"ltp":0.0,"tv":0.0,"id":24420205},{"batb":[[0,6,2.86]],"ltp":0.0,"tv":0.0,"id":420}]}]}
{"op":"mcm","clk":"989417801","pt":1580487668701,"mc":[{"id":"1.168130661","rc":[{"batb":[[0,2.16,8]],"batl":[[0,1000,0.22]],"ltp":0.0,"tv":0.0,"id":25238892},{"batb":[[0,2.06,1.68],[1,2.04,1.99]],"ltp":0.0,"tv":0.0,"id":26314798}]}]}
{"op":"mcm","clk":"989417907","pt":1580487669705,"mc":[{"id":"1.168130661","rc":[{"batb":[[0,9.4,1.68],[1,9.2,1.99]],"ltp":0.0,"tv":0.0,"id":25545675},{"batb":[[0,7,1.68],[1,6.6,1.68]],"ltp":0.0,"tv":0.0,"id":24707172},{"batb":[[0,6.2,2.55],[1,6,1.99]],"ltp":0.0,"tv":0.0,"id":24420205}]}]}
{"op":"mcm","clk":"989418565","pt":1580487676919,"mc":[{"id":"1.168130661","rc":[{"batb":[[0,2.18,3.85],[1,2.16,8]],"ltp":0.0,"tv":0.0,"id":25238892},{"batb":[[0,7.2,3.7],[1,6.6,2.44]],"ltp":0.0,"tv":0.0,"id":24707172}]}]}
{"op":"mcm","clk":"989418755","pt":1580487679634,"mc":[{"id":"1.168130661","rc":[{"batb":[[0,6.4,1.99],[1,6.2,2.55]],"ltp":0.0,"tv":0.0,"id":24420205},{"batb":[[0,2.08,1.99],[1,2.06,1.68]],"ltp":0.0,"tv":0.0,"id":26314798},{"batb":[[0,6.4,1.99],[1,5.8,2.55]],"ltp":0.0,"tv":0.0,"id":420}]}]}
{"op":"mcm","clk":"989418820","pt":1580487680635,"mc":[{"id":"1.168130661","rc":[{"batb":[[0,9.6,1.99],[1,9.4,1.68]],"ltp":0.0,"tv":0.0,"id":25545675},{"batb":[[0,7.4,1.99],[1,7.2,3.7],[2,6.6,2.44]],"ltp":0.0,"tv":0.0,"id":24707172}]}]}
{"op":"mcm","clk":"989421033","pt":1580487707079,"mc":[{"id":"1.168130661","rc":[{"batb":[[1,6.2,1.68]],"ltp":0.0,"tv":0.0,"id":24420205},{"batb":[[1,5.8,1.68]],"ltp":0.0,"tv":0.0,"id":420}]}]}
{"op":"mcm","clk":"989421319","pt":1580487710480,"mc":[{"id":"1.168130661","rc":[{"batb":[[0,6.4,2.8]],"ltp":0.0,"tv":0.0,"id":24420205},{"batb":[[0,6.4,2.8]],"ltp":0.0,"tv":0.0,"id":420}]}]}
{"op":"mcm","clk":"989422847","pt":1580487728320,"mc":[{"id":"1.168130661","rc":[{"batb":[[0,6.8,1.99],[1,6.2,2.49]],"ltp":0.0,"tv":0.0,"id":24420205},{"batb":[[0,5.8,2.49],[1,4.2,12.88],[2,1.51,3.36]],"ltp":0.0,"tv":0.0,"id":420}]}]}
{"op":"mcm","clk":"989423566","pt":1580487736699,"mc":[{"id":"1.168130661","rc":[{"batb":[[1,6.2,1.68]],"ltp":0.0,"tv":0.0,"id":24420205}]}]}
{"op":"mcm","clk":"989423849","pt":1580487740235,"mc":[{"id":"1.168130661","rc":[{"batb":[[0,6.8,2.75]],"ltp":0.0,"tv":0.0,"id":24420205}]}]}
{"op":"mcm","clk":"989424579","pt":1580487748714,"mc":[{"id":"1.168130661","rc":[{"batb":[[0,2.2,2.96],[1,2.18,3.85]],"ltp":0.0,"tv":0.0,"id":25238892},{"batb":[[1,4.2,11.88],[2,1.51,3.36]],"ltp":0.0,"tv":0.0,"id":24420205},{"batb":[[0,2.1,1.68],[1,2.08,1.99]],"ltp":0.0,"tv":0.0,"id":26314798},{"batb":[[0,5.7,1.69],[1,4.3,1.68],[2,4.2,12]],"ltp":0.0,"tv":0.0,"id":420}]}]}
{"op":"mcm","clk":"989424648","pt":1580487749510,"mc":[{"id":"1.168130661","rc":[{"batb":[[0,9.8,1.68],[1,9.6,1.99]],"ltp":0.0,"tv":0.0,"id":25545675},{"batb":[[0,7.6,1.68],[1,7.4,1.99],[2,7.2,3.7]],"ltp":0.0,"tv":0.0,"id":24707172},{"batb":[[0,7,2.44],[1,6.8,1.99],[2,4.2,11.88]],"ltp":0.0,"tv":0.0,"id":24420205}]}]}
{"op":"mcm","clk":"989434487","pt":1580487752527,"mc":[{"id":"1.168130661","rc":[{"batb":[[0,2.2,3.7]],"ltp":0.0,"tv":0.0,"id":25238892},{"batb":[[0,2.1,2.47]],"ltp":0.0,"tv":0.0,"id":26314798},{"batb":[[1,4.3,2.06]],"ltp":0.0,"tv":0.0,"id":420}]}]}
{"op":"mcm","clk":"989434508","pt":1580487752836,"mc":[{"id":"1.168130661","rc":[{"batb":[[0,9.8,1.85]],"ltp":0.0,"tv":0.0,"id":25545675},{"batb":[[0,7,2.68]],"ltp":0.0,"tv":0.0,"id":24420205}]}]}
{"op":"mcm","clk":"989435968","pt":1580487770649,"mc":[{"id":"1.168130661","rc":[{"batb":[[0,2.24,1.99],[1,2.2,3.7],[2,2.18,3.85]],"ltp":0.0,"tv":0.0,"id":25238892},{"batb":[[1,4.2,11.88],[2,1.51,3.36]],"ltp":0.0,"tv":0.0,"id":24420205},{"batb":[[0,2.12,1.99],[1,2.1,2.47]],"ltp":0.0,"tv":0.0,"id":26314798}]}]}
{"op":"mcm","clk":"989436048","pt":1580487771488,"mc":[{"id":"1.168130661","rc":[{"batb":[[1,7.6,3.21],[2,7.4,7]],"ltp":0.0,"tv":0.0,"id":25545675},{"batb":[[0,7.8,1.99],[1,7.6,1.68]],"ltp":0.0,"tv":0.0,"id":24707172}]}]}
{"op":"mcm","clk":"989439917","pt":1580487814717,"mc":[{"id":"1.168130661","rc":[{"batb":[[2,7,1.68]],"ltp":0.0,"tv":0.0,"id":24707172},{"batb":[[0,2.14,1.68],[1,2.12,1.99],[2,1.98,8.43]],"ltp":0.0,"tv":0.0,"id":26314798}]}]}
{"op":"mcm","clk":"989440021","pt":1580487815707,"mc":[{"id":"1.168130661","rc":[{"batb":[[0,2.26,1.68],[1,2.24,1.99],[2,2.18,4.6]],"ltp":0.0,"tv":0.0,"id":25238892},{"batb":[[0,8,1.68],[1,7.8,4.55]],"ltp":0.0,"tv":0.0,"id":24707172},{"batb":[[0,5.7,1.87],[1,4.3,1.68],[2,4.2,11]],"ltp":0.0,"tv":0.0,"id":24420205},{"batb":[[0,5.8,2.49],[1,4.4,1.25]],"ltp":0.0,"tv":0.0,"id":420}]}]}
{"op":"mcm","clk":"989440061","pt":1580487816124,"mc":[{"id":"1.168130661","rc":[{"batb":[[0,7.8,2.43],[1,7.6,2.63]],"ltp":0.0,"tv":0.0,"id":25545675}]}]}
{"op":"mcm","clk":"989442312","pt":1580487839887,"mc":[{"id":"1.168130661","rc":[{"batb":[[1,4.2,12.88],[2,1.51,3.36]],"ltp":0.0,"tv":0.0,"id":420}]}]}
{"op":"mcm","clk":"989443601","pt":1580487853677,"mc":[{"id":"1.168130661","rc":[{"batb":[[0,2.28,1.99],[1,2.26,1.68]],"ltp":0.0,"tv":0.0,"id":25238892},{"batb":[[1,7.8,2.56]],"ltp":0.0,"tv":0.0,"id":24707172},{"batb":[[0,2.16,1.99],[1,2.14,1.68]],"ltp":0.0,"tv":0.0,"id":26314798}]}]}
{"op":"mcm","clk":"989443613","pt":1580487853772,"mc":[{"id":"1.168130661","rc":[{"batb":[[0,8.2,1.99],[1,8,1.68],[2,7.8,2.56]],"ltp":0.0,"tv":0.0,"id":24707172}]}]}
{"op":"mcm","clk":"989446205","pt":1580487883896,"mc":[{"id":"1.168130661","rc":[{"batb":[[2,7,1.68]],"ltp":0.0,"tv":0.0,"id":24707172}]}]}
{"op":"mcm","clk":"989446446","pt":1580487886630,"mc":[{"id":"1.168130661","rc":[{"batb":[[0,2.3,1.68],[1,2.28,1.99]],"ltp":0.0,"tv":0.0,"id":25238892},{"batb":[[0,2.18,1.68],[1,2.16,1.99]],"ltp":0.0,"tv":0.0,"id":26314798},{"batb":[[0,5.7,1.69],[1,4.3,1.68],[2,4.2,12]],"ltp":0.0,"tv":0.0,"id":420}]}]}
{"op":"mcm","clk":"989446498","pt":1580487887235,"mc":[{"id":"1.168130661","rc":[{"batb":[[0,8.4,1.68],[1,8.2,1.99]],"ltp":0.0,"tv":0.0,"id":24707172},{"batb":[[0,5.8,2.68],[1,4.2,11.88],[2,1.51,3.36]],"ltp":0.0,"tv":0.0,"id":24420205}]}]}
{"op":"mcm","clk":"989447247","pt":1580487896418,"mc":[{"id":"1.168130661","rc":[{"batb":[[0,2.32,1.99],[1,2.3,1.68]],"ltp":0.0,"tv":0.0,"id":25238892},{"batb":[[1,7,1.68],[2,6.4,3]],"ltp":0.0,"tv":0.0,"id":24707172},{"batb":[[0,2.2,1.99],[1,2.18,1.68]],"ltp":0.0,"tv":0.0,"id":26314798}]}]}
{"op":"mcm","clk":"989451342","pt":1580487943405,"mc":[{"id":"1.168130661","rc":[{"batl":[[0,1000,0.64]],"ltp":0.0,"tv":0.0,"id":25238892}]}]}
{"op":"mcm","clk":"989451541","pt":1580487945622,"mc":[{"id":"1.168130661","rc":[{"batl":[[0,1000,1.9]],"ltp":0.0,"tv":0.0,"id":25238892}]}]}
{"op":"mcm","clk":"989451607","pt":1580487946314,"mc":[{"id":"1.168130661","rc":[{"batl":[[0,1000,0.64]],"ltp":0.0,"tv":0.0,"id":25238892}]}]}
{"op":"mcm","clk":"989451870","pt":1580487949430,"mc":[{"id":"1.168130661","rc":[{"batl":[[0,1000,0.22]],"ltp":0.0,"tv":0.0,"id":25238892}]}]}
{"op":"mcm","clk":"989451969","pt":1580487950522,"mc":[{"id":"1.168130661","rc":[{"batl":[[0,1000,1.9]],"ltp":0.0,"tv":0.0,"id":25238892}]}]}
{"op":"mcm","clk":"989452072","pt":1580487951720,"mc":[{"id":"1.168130661","rc":[{"batl":[[0,1000,0.64]],"ltp":0.0,"tv":0.0,"id":25238892},{"batb":[[0,2.22,1.68],[1,2.2,1.99]],"ltp":0.0,"tv":0.0,"id":26314798}]}]}
{"op":"mcm","clk":"989452151","pt":1580487952631,"mc":[{"id":"1.168130661","rc":[{"batb":[[0,2.34,1.68],[1,2.32,1.99]],"batl":[[0,1000,0.22]],"ltp":0.0,"tv":0.0,"id":25238892},{"batb":[[0,5.7,1.87],[1,4.2,11]],"ltp":0.0,"tv":0.0,"id":24420205},{"batb":[[0,5.8,2.49],[1,4.2,12.88],[2,1.51,3.36]],"ltp":0.0,"tv":0.0,"id":420}]}]}
{"op":"mcm","clk":"989452261","pt":1580487953590,"mc":[{"id":"1.168130661","rc":[{"batl":[[0,1000,0.64]],"ltp":0.0,"tv":0.0,"id":25238892},{"batb":[[0,7,1.68],[1,6.6,1.68]],"ltp":0.0,"tv":0.0,"id":24707172},{"batb":[[1,4.3,1.68],[2,4.2,11]],"ltp":0.0,"tv":0.0,"id":24420205}]}]}
{"op":"mcm","clk":"989452402","pt":1580487955115,"mc":[{"id":"1.168130661","rc":[{"batl":[[0,1000,0.22]],"ltp":0.0,"tv":0.0,"id":25238892}]}]}
{"op":"mcm","clk":"989452506","pt":1580487956418,"mc":[{"id":"1.168130661","rc":[{"batl":[[0,1000,0.64]],"ltp":0.0,"tv":0.0,"id":25238892}]}]}
{"op":"mcm","clk":"989452650","pt":1580487958316,"mc":[{"id":"1.168130661","rc":[{"batl":[[0,1000,0.22]],"ltp":0.0,"tv":0.0,"id":25238892}]}]}
{"op":"mcm","clk":"989453189","pt":1580487964510,"mc":[{"id":"1.168130661","rc":[{"batl":[[0,1000,1.9]],"ltp":0.0,"tv":0.0,"id":25238892}]}]}
{"op":"mcm","clk":"989453279","pt":1580487965436,"mc":[{"id":"1.168130661","rc":[{"batl":[[0,1000,0.64]],"ltp":0.0,"tv":0.0,"id":25238892}]}]}
{"op":"mcm","clk":"989453951","pt":1580487973141,"mc":[{"id":"1.168130661","rc":[{"batb":[[2,2.18,3.85]],"ltp":0.0,"tv":0.0,"id":25238892},{"batb":[[2,1.98,7.64]],"ltp":0.0,"tv":0.0,"id":26314798}]}]}
{"op":"mcm","clk":"989454063","pt":1580487974520,"mc":[{"id":"1.168130661","rc":[{"batb":[[1,1.98,7.64],[2,1.74,44]],"ltp":0.0,"tv":0.0,"id":26314798}]}]}
{"op":"mcm","clk":"989454134","pt":1580487975354,"mc":[{"id":"1.168130661","rc":[{"batb":[[0,2.36,1.99],[1,2.34,1.68]],"batl":[[0,1000,0.22]],"ltp":0.0,"tv":0.0,"id":25238892},{"batb":[[0,7.4,1.99],[1,7,1.68],[2,6.6,1.68]],"ltp":0.0,"tv":0.0,"id":24707172}]}]}
{"op":"mcm","clk":"989454683","pt":1580487981654,"mc":[{"id":"1.168130661","rc":[{"batl":[[0,1000,0.64]],"ltp":0.0,"tv":0.0,"id":25238892}]}]}
{"op":"mcm","clk":"989454878","pt":1580487983934,"mc":[{"id":"1.168130661","rc":[{"batl":[[0,1000,0.22]],"ltp":0.0,"tv":0.0,"id":25238892}]}]}
{"op":"mcm","clk":"989455084","pt":1580487986667,"mc":[{"id":"1.168130661","rc":[{"batl":[[0,1000,1.89]],"ltp":0.0,"tv":0.0,"id":26314798}]}]}
{"op":"mcm","clk":"989455164","pt":1580487987558,"mc":[{"id":"1.168130661","rc":[{"batl":[[0,1000,0.63]],"ltp":0.0,"tv":0.0,"id":26314798}]}]}
{"op":"mcm","clk":"989455314","pt":1580487989035,"mc":[{"id":"1.168130661","rc":[{"batl":[[0,1000,0.21]],"ltp":0.0,"tv":0.0,"id":26314798}]}]}
{"op":"mcm","clk":"989455418","pt":1580487990349,"mc":[{"id":"1.168130661","rc":[{"batl":[[0,1000,1.89]],"ltp":0.0,"tv":0.0,"id":26314798}]}]}
{"op":"mcm","clk":"989455508","pt":1580487991657,"mc":[{"id":"1.168130661","rc":[{"batl":[[0,1000,0.63]],"ltp":0.0,"tv":0.0,"id":26314798}]}]}
{"op":"mcm","clk":"989455574","pt":1580487992552,"mc":[{"id":"1.168130661","rc":[{"batl":[[0,1000,0.21]],"ltp":0.0,"tv":0.0,"id":26314798}]}]}
{"op":"mcm","clk":"989455662","pt":1580487993659,"mc":[{"id":"1.168130661","rc":[{"batl":[[0,1000,1.89]],"ltp":0.0,"tv":0.0,"id":26314798}]}]}
{"op":"mcm","clk":"989455728","pt":1580487994451,"mc":[{"id":"1.168130661","rc":[{"batl":[[0,1000,0.63]],"ltp":0.0,"tv":0.0,"id":26314798}]}]}
{"op":"mcm","clk":"989455803","pt":1580487995442,"mc":[{"id":"1.168130661","rc":[{"batl":[[0,1000,0.21]],"ltp":0.0,"tv":0.0,"id":26314798}]}]}
{"op":"mcm","clk":"989455966","pt":1580487997465,"mc":[{"id":"1.168130661","rc":[{"batl":[[0,1000,0.63]],"ltp":0.0,"tv":0.0,"id":26314798}]}]}
{"op":"mcm","clk":"989456074","pt":1580487998791,"mc":[{"id":"1.168130661","rc":[{"batl":[[0,1000,0.21]],"ltp":0.0,"tv":0.0,"id":26314798}]}]}
{"op":"mcm","clk":"989459269","pt":1580488032721,"mc":[{"id":"1.168130661","rc":[{"batb":[[0,2.38,1.68],[1,2.36,1.99]],"ltp":0.0,"tv":0.0,"id":25238892},{"batb":[[1,4.2,11],[2,1.51,3.36]],"ltp":0.0,"tv":0.0,"id":24420205},{"batb":[[0,1.99,1.68]],"ltp":0.0,"tv":0.0,"id":26314798},{"batb":[[0,5.7,1.69],[1,4.3,1.68],[2,4.2,12]],"ltp":0.0,"tv":0.0,"id":420}]}]}
{"op":"mcm","clk":"989459310","pt":1580488033205,"mc":[{"id":"1.168130661","rc":[{"batb":[[0,7.6,1.68],[1,7.4,1.99],[2,7,1.68]],"ltp":0.0,"tv":0.0,"id":24707172},{"batb":[[0,5.8,2.68],[1,4.2,11.88]],"ltp":0.0,"tv":0.0,"id":24420205}]}]}
{"op":"mcm","clk":"989461794","pt":1580488058632,"mc":[{"id":"1.168130661","rc":[{"batb":[[1,2.18,3.85],[2,1.74,44]],"ltp":0.0,"tv":0.0,"id":25238892}]}]}
{"op":"mcm","clk":"989461827","pt":1580488059050,"mc":[{"id":"1.168130661","rc":[{"batb":[[0,2.4,1.99],[1,2.38,1.68],[2,2.18,3.85]],"ltp":0.0,"tv":0.0,"id":25238892},{"batb":[[0,7.8,1.99],[1,7.6,1.68]],"ltp":0.0,"tv":0.0,"id":24707172}]}]}
{"op":"mcm","clk":"989465214","pt":1580488093694,"mc":[{"id":"1.168130661","rc":[{"batb":[[1,2.18,3.85],[2,1.74,44]],"ltp":0.0,"tv":0.0,"id":25238892},{"batb":[[0,1.99,8.61]],"batl":[[0,1000,0.22]],"ltp":0.0,"tv":0.0,"id":26314798}]}]}
{"op":"mcm","clk":"989465299","pt":1580488094695,"mc":[{"id":"1.168130661","rc":[{"batb":[[0,2.42,1.68],[1,2.4,1.99],[2,2.18,3.85]],"ltp":0.0,"tv":0.0,"id":25238892},{"batb":[[1,7,1.68],[2,6.4,3]],"ltp":0.0,"tv":0.0,"id":24707172},{"batb":[[0,5.7,1.87],[1,4.3,1.68],[2,4.2,11]],"ltp":0.0,"tv":0.0,"id":24420205},{"batb":[[0,5.8,2.49],[1,4.2,12.88],[2,1.51,3.36]],"ltp":0.0,"tv":0.0,"id":420}]}]}
{"op":"mcm","clk":"989465317","pt":1580488094854,"mc":[{"id":"1.168130661","rc":[{"batb":[[0,8,1.68],[1,7.8,1.99],[2,7,1.68]],"ltp":0.0,"tv":0.0,"id":24707172}]}]}
{"op":"mcm","clk":"989465523","pt":1580488097558,"mc":[{"id":"1.168130661","rc":[{"batb":[[0,2,4.55],[1,1.99,8.61],[2,1.98,3]],"ltp":0.0,"tv":0.0,"id":26314798}]}]}
{"op":"mcm","clk":"989465874","pt":1580488101516,"mc":[{"id":"1.168130661","rc":[{"batb":[[1,2.18,3.85],[2,1.74,44]],"ltp":0.0,"tv":0.0,"id":25238892},{"batb":[[0,8.2,1.99],[1,8,1.68]],"ltp":0.0,"tv":0.0,"id":24707172},{"batb":[[0,2.02,1.99],[1,2,4.55],[2,1.99,8.61]],"ltp":0.0,"tv":0.0,"id":26314798}]}]}
{"op":"mcm","clk":"989469593","pt":1580488135761,"mc":[{"id":"1.168130661","rc":[{"batb":[[1,2,7.55]],"ltp":0.0,"tv":0.0,"id":26314798},{"batb":[[1,4.3,3.88],[2,4.2,12]],"ltp":0.0,"tv":0.0,"id":420}]}]}
{"op":"mcm","clk":"989470339","pt":1580488142381,"mc":[{"id":"1.168130661","rc":[{"batb":[[0,8,1.68],[1,7,1.68],[2,6.2,7]],"ltp":0.0,"tv":0.0,"id":24707172}]}]}
{"op":"mcm","clk":"989473541","pt":1580488176520,"mc":[{"id":"1.168130661","rc":[{"batb":[[0,2.2,1.68]],"ltp":0.0,"tv":0.0,"id":25238892},{"batb":[[0,2.04,2.39],[1,2.02,1.99],[2,2,7.55]],"ltp":0.0,"tv":0.0,"id":26314798},{"batb":[[0,5.7,1.69],[1,4.4,1.68],[2,4.3,3]],"ltp":0.0,"tv":0.0,"id":420}]}]}
{"op":"mcm","clk":"989473650","pt":1580488177672,"mc":[{"id":"1.168130661","rc":[{"batb":[[0,7,1.68],[1,6.4,1.68]],"ltp":0.0,"tv":0.0,"id":24707172},{"batb":[[0,5.8,2.68],[1,4.2,11.88],[2,1.51,3.36]],"ltp":0.0,"tv":0.0,"id":24420205}]}]}
{"op":"mcm","clk":"989473924","pt":1580488181015,"mc":[{"id":"1.168130661","rc":[{"batb":[[2,1.75,3]],"ltp":0.0,"tv":0.0,"id":25238892},{"batb":[[1,4.3,3.88],[2,4.2,11]],"ltp":0.0,"tv":0.0,"id":24420205},{"batb":[[2,2,4.55]],"ltp":0.0,"tv":0.0,"id":26314798}]}]}
{"op":"mcm","clk":"989475105","pt":1580488194706,"mc":[{"id":"1.168130661","rc":[{"batb":[[0,7.4,1.99],[1,7,1.68],[2,6.4,1.68]],"ltp":0.0,"tv":0.0,"id":24707172},{"batb":[[0,2.06,1.99],[1,2.04,2.39]],"ltp":0.0,"tv":0.0,"id":26314798}]}]}
{"op":"mcm","clk":"989477673","pt":1580488224701,"mc":[{"id":"1.168130661","rc":[{"batb":[[0,5.7,1.87],[1,4.4,1.68],[2,4.3,3]],"ltp":0.0,"tv":0.0,"id":24420205},{"batb":[[0,2.08,1.68],[1,2.06,1.99]],"ltp":0.0,"tv":0.0,"id":26314798},{"batb":[[0,5.8,2.49],[1,4.3,3.88],[2,4.2,12]],"ltp":0.0,"tv":0.0,"id":420}]}]}
{"op":"mcm","clk":"989477694","pt":1580488224858,"mc":[{"id":"1.168130661","rc":[{"batb":[[0,7.6,1.68],[1,7.4,1.99],[2,7,1.68]],"ltp":0.0,"tv":0.0,"id":24707172}]}]}
{"op":"mcm","clk":"989480979","pt":1580488266723,"mc":[{"id":"1.168130661","rc":[{"batb":[[0,7.8,1.99],[1,7.6,1.68]],"ltp":0.0,"tv":0.0,"id":24707172},{"batb":[[0,2.1,1.99],[1,2.08,1.68]],"ltp":0.0,"tv":0.0,"id":26314798}]}]}
{"op":"mcm","clk":"989483353","pt":1580488296664,"mc":[{"id":"1.168130661","rc":[{"batb":[[0,2.12,1.68],[1,2.1,1.99]],"ltp":0.0,"tv":0.0,"id":26314798},{"batb":[[0,5.7,1.69],[1,4.3,3]],"ltp":0.0,"tv":0.0,"id":420}]}]}
{"op":"mcm","clk":"989483444","pt":1580488297705,"mc":[{"id":"1.168130661","rc":[{"batb":[[0,8,1.68],[1,7.8,1.99]],"ltp":0.0,"tv":0.0,"id":24707172},{"batb":[[0,5.8,2.68],[1,4.3,3.88],[2,4.2,11]],"ltp":0.0,"tv":0.0,"id":24420205},{"batb":[[1,4.4,1.68],[2,4.3,3]],"ltp":0.0,"tv":0.0,"id":420}]}]}
{"op":"mcm","clk":"989485181","pt":1580488316619,"mc":[{"id":"1.168130661","rc":[{"batb":[[0,8.2,1.99],[1,8,1.68]],"ltp":0.0,"tv":0.0,"id":24707172},{"batb":[[0,2.14,1.99],[1,2.12,1.68]],"ltp":0.0,"tv":0.0,"id":26314798}]}]}
{"op":"mcm","clk":"989489525","pt":1580488365660,"mc":[{"id":"1.168130661","rc":[{"batb":[[0,8,1.68],[1,7,1.68],[2,6.2,7]],"ltp":0.0,"tv":0.0,"id":24707172}]}]}
{"op":"mcm","clk":"989491006","pt":1580488382396,"mc":[{"id":"1.168130661","rc":[{"batb":[[2,6.4,3]],"ltp":0.0,"tv":0.0,"id":24707172}]}]}
{"op":"mcm","clk":"989492753","pt":1580488403702,"mc":[{"id":"1.168130661","rc":[{"batb":[[0,5.7,1.87],[1,4.3,3]],"ltp":0.0,"tv":0.0,"id":24420205},{"batb":[[0,2.16,1.68],[1,2.14,1.99]],"ltp":0.0,"tv":0.0,"id":26314798},{"batb":[[0,5.8,2.49],[1,4.3,3.88],[2,4.2,12]],"ltp":0.0,"tv":0.0,"id":420}]}]}
{"op":"mcm","clk":"989492827","pt":1580488404634,"mc":[{"id":"1.168130661","rc":[{"batb":[[0,7,1.68],[1,6.6,1.68]],"ltp":0.0,"tv":0.0,"id":24707172},{"batb":[[1,4.4,1.68],[2,4.3,3]],"ltp":0.0,"tv":0.0,"id":24420205}]}]}
{"op":"mcm","clk":"989493016","pt":1580488406624,"mc":[{"id":"1.168130661","rc":[{"batb":[[0,2.18,1.99],[1,2.16,1.68]],"ltp":0.0,"tv":0.0,"id":26314798}]}]}
{"op":"mcm","clk":"989493116","pt":1580488407666,"mc":[{"id":"1.168130661","rc":[{"batb":[[0,7.4,1.99],[1,7,1.68],[2,6.6,1.68]],"ltp":0.0,"tv":0.0,"id":24707172}]}]}
{"op":"mcm","clk":"989499801","pt":1580488491516,"mc":[{"id":"1.168130661","rc":[{"batb":[[0,5.8,2.68],[1,4.3,3.88],[2,4.2,11]],"ltp":0.0,"tv":0.0,"id":24420205},{"batb":[[0,2.2,1.68],[1,2.18,1.99]],"ltp":0.0,"tv":0.0,"id":26314798},{"batb":[[0,5.7,1.69],[1,4.4,1.68],[2,4.3,3]],"ltp":0.0,"tv":0.0,"id":420}]}]}
{"op":"mcm","clk":"989499918","pt":1580488492721,"mc":[{"id":"1.168130661","rc":[{"batb":[[0,7.6,1.68],[1,7.4,1.99],[2,7,1.68]],"ltp":0.0,"tv":0.0,"id":24707172}]}]}
{"op":"mcm","clk":"989500230","pt":1580488496723,"mc":[{"id":"1.168130661","rc":[{"batb":[[1,2,4.55],[2,1.75,3]],"ltp":0.0,"tv":0.0,"id":26314798}]}]}
{"op":"mcm","clk":"989500271","pt":1580488497240,"mc":[{"id":"1.168130661","rc":[{"batb":[[0,7.8,1.99],[1,7.6,1.68]],"ltp":0.0,"tv":0.0,"id":24707172},{"batb":[[0,2.22,1.99],[1,2.2,1.68],[2,2,4.55]],"ltp":0.0,"tv":0.0,"id":26314798}]}]}
{"op":"mcm","clk":"989507735","pt":1580488579658,"mc":[{"id":"1.168130661","rc":[{"batb":[[0,5.7,1.87],[1,4.4,1.68],[2,4.3,3]],"ltp":0.0,"tv":0.0,"id":24420205},{"batb":[[0,2.24,1.68],[1,2.22,1.99]],"ltp":0.0,"tv":0.0,"id":26314798},{"batb":[[0,5.8,2.49],[1,4.3,3.88],[2,4.2,12]],"ltp":0.0,"tv":0.0,"id":420}]}]}
{"op":"mcm","clk":"989507816","pt":1580488580651,"mc":[{"id":"1.168130661","rc":[{"batb":[[0,8,1.68],[1,7.8,1.99]],"ltp":0.0,"tv":0.0,"id":24707172},{"batb":[[1,2,4.55],[2,1.75,3]],"ltp":0.0,"tv":0.0,"id":26314798}]}]}
{"op":"mcm","clk":"989507889","pt":1580488581327,"mc":[{"id":"1.168130661","rc":[{"batb":[[0,8.2,1.99],[1,8,1.68]],"ltp":0.0,"tv":0.0,"id":24707172}]}]}
{"op":"mcm","clk":"989511395","pt":1580488620902,"mc":[{"id":"1.168130661","rc":[{"batb":[[0,8,1.68],[1,7,1.68],[2,6.2,7]],"ltp":0.0,"tv":0.0,"id":24707172}]}]}
{"op":"mcm","clk":"989512859","pt":1580488638224,"mc":[{"id":"1.168130661","rc":[{"batb":[[2,6.4,3]],"ltp":0.0,"tv":0.0,"id":24707172}]}]}
{"op":"mcm","clk":"989523673","pt":1580488652635,"mc":[{"id":"1.168130661","rc":[{"batb":[[1,4.3,3],[2,4.2,11]],"ltp":0.0,"tv":0.0,"id":24420205},{"batb":[[0,2.02,1.68]],"ltp":0.0,"tv":0.0,"id":26314798},{"batb":[[0,5.7,1.69],[1,4.4,1.68],[2,4.3,3]],"ltp":0.0,"tv":0.0,"id":420}]}]}
{"op":"mcm","clk":"989523766","pt":1580488653634,"mc":[{"id":"1.168130661","rc":[{"batb":[[0,7,1.68],[1,6.6,1.68]],"ltp":0.0,"tv":0.0,"id":24707172},{"batb":[[0,5.8,2.68],[1,4.3,3.88]],"ltp":0.0,"tv":0.0,"id":24420205}]}]}
{"op":"mcm","clk":"989524418","pt":1580488661563,"mc":[{"id":"1.168130661","rc":[{"batb":[[0,7.4,1.99],[1,7,1.68],[2,6.6,1.68]],"ltp":0.0,"tv":0.0,"id":24707172}]}]}
{"op":"mcm","clk":"989529157","pt":1580488717621,"mc":[{"id":"1.168130661","rc":[{"batb":[[2,6.2,7]],"ltp":0.0,"tv":0.0,"id":24707172},{"batb":[[0,5.7,1.87],[1,4.4,1.68],[2,4.3,3]],"ltp":0.0,"tv":0.0,"id":24420205},{"batb":[[0,5.8,2.49],[1,4.3,3.88],[2,4.2,12]],"ltp":0.0,"tv":0.0,"id":420}]}]}
{"op":"mcm","clk":"989529269","pt":1580488718719,"mc":[{"id":"1.168130661","rc":[{"batb":[[0,7.6,1.68],[1,7.4,1.99],[2,7,1.68]],"ltp":0.0,"tv":0.0,"id":24707172}]}]}
{"op":"mcm","clk":"989532450","pt":1580488753651,"mc":[{"id":"1.168130661","rc":[{"batb":[[0,7.8,1.99],[1,7.6,1.68]],"ltp":0.0,"tv":0.0,"id":24707172}]}]}
{"op":"mcm","clk":"989536307","pt":1580488800718,"mc":[{"id":"1.168130661","rc":[{"batb":[[0,5.7,1.69],[1,4.4,1.68],[2,4.3,3]],"ltp":0.0,"tv":0.0,"id":420}]}]}
{"op":"mcm","clk":"989536419","pt":1580488801704,"mc":[{"id":"1.168130661","rc":[{"batb":[[0,8,1.68],[1,7.8,1.99]],"ltp":0.0,"tv":0.0,"id":24707172},{"batb":[[0,5.8,2.68],[1,4.3,3.88],[2,4.2,11]],"ltp":0.0,"tv":0.0,"id":24420205}]}]}
{"op":"mcm","clk":"989540043","pt":1580488846171,"mc":[{"id":"1.168130661","rc":[{"batb":[[0,8.2,1.99],[1,8,1.68]],"ltp":0.0,"tv":0.0,"id":24707172}]}]}
{"op":"mcm","clk":"989542982","pt":1580488880623,"mc":[{"id":"1.168130661","rc":[{"batb":[[1,7,1.68],[2,6.2,7]],"ltp":0.0,"tv":0.0,"id":24707172},{"batb":[[0,5.7,1.87],[1,4.4,1.68],[2,4.3,3]],"ltp":0.0,"tv":0.0,"id":24420205},{"batb":[[0,5.8,2.49],[1,4.3,3.88],[2,4.2,12]],"ltp":0.0,"tv":0.0,"id":420}]}]}
{"op":"mcm","clk":"989543063","pt":1580488881604,"mc":[{"id":"1.168130661","rc":[{"batb":[[0,8.4,1.68],[1,8.2,1.99],[2,7,1.68]],"ltp":0.0,"tv":0.0,"id":24707172}]}]}
{"op":"mcm","clk":"989545268","pt":1580488906363,"mc":[{"id":"1.168130661","rc":[{"batb":[[1,7,1.68],[2,6.2,7]],"ltp":0.0,"tv":0.0,"id":24707172}]}]}
{"op":"mcm","clk":"989545360","pt":1580488907451,"mc":[{"id":"1.168130661","rc":[{"batb":[[1,7,1.45]],"ltp":0.0,"tv":0.0,"id":24707172}]}]}
{"op":"mcm","clk":"989548204","pt":1580488937429,"mc":[{"id":"1.168130661","rc":[{"batb":[[2,6.4,3]],"ltp":0.0,"tv":0.0,"id":24707172}]}]}
{"op":"mcm","clk":"989549270","pt":1580488948702,"mc":[{"id":"1.168130661","rc":[{"batb":[[0,5.7,1.69],[1,4.4,1.68],[2,4.3,3]],"ltp":0.0,"tv":0.0,"id":420}]}]}
{"op":"mcm","clk":"989549360","pt":1580488949604,"mc":[{"id":"1.168130661","rc":[{"batb":[[0,7,1.45],[1,6.6,1.68]],"ltp":0.0,"tv":0.0,"id":24707172},{"batb":[[0,5.8,2.68],[1,4.3,3.88],[2,4.2,11]],"ltp":0.0,"tv":0.0,"id":24420205}]}]}
{"op":"mcm","clk":"989549863","pt":1580488954925,"mc":[{"id":"1.168130661","rc":[{"batb":[[0,7.4,1.99],[1,7,1.45],[2,6.6,1.68]],"ltp":0.0,"tv":0.0,"id":24707172}]}]}
{"op":"mcm","clk":"989555805","pt":1580489032699,"mc":[{"id":"1.168130661","rc":[{"batb":[[0,5.8,2.49],[1,4.3,3.88],[2,4.2,12]],"ltp":0.0,"tv":0.0,"id":420}]}]}
{"op":"mcm","clk":"989555871","pt":1580489033594,"mc":[{"id":"1.168130661","rc":[{"batb":[[0,7.6,1.68],[1,7.4,1.99],[2,7,1.45]],"ltp":0.0,"tv":0.0,"id":24707172},{"batb":[[0,5.7,1.87],[1,4.4,1.68],[2,4.3,3]],"ltp":0.0,"tv":0.0,"id":24420205}]}]}
{"op":"mcm","clk":"989558250","pt":1580489063161,"mc":[{"id":"1.168130661","rc":[{"batb":[[0,7.8,1.99],[1,7.6,1.68]],"ltp":0.0,"tv":0.0,"id":24707172}]}]}
{"op":"mcm","clk":"989562311","pt":1580489114636,"mc":[{"id":"1.168130661","rc":[{"batb":[[0,5.7,1.69],[1,4.3,3]],"ltp":0.0,"tv":0.0,"id":420}]}]}
{"op":"mcm","clk":"989562415","pt":1580489115719,"mc":[{"id":"1.168130661","rc":[{"batb":[[0,8,1.68],[1,7.8,1.99]],"ltp":0.0,"tv":0.0,"id":24707172},{"batb":[[0,5.8,2.68],[1,4.3,3.88],[2,4.2,11]],"ltp":0.0,"tv":0.0,"id":24420205},{"batb":[[1,4.4,1.68],[2,4.3,3]],"ltp":0.0,"tv":0.0,"id":420}]}]}
{"op":"mcm","clk":"989565124","pt":1580489148303,"mc":[{"id":"1.168130661","rc":[{"batb":[[0,8.2,1.99],[1,8,1.68]],"ltp":0.0,"tv":0.0,"id":24707172}]}]}
{"op":"mcm","clk":"989568265","pt":1580489189945,"mc":[{"id":"1.168130661","rc":[{"batb":[[0,8,1.68],[1,7,1.45],[2,6.2,7]],"ltp":0.0,"tv":0.0,"id":24707172}]}]}
{"op":"mcm","clk":"989568381","pt":1580489191671,"mc":[{"id":"1.168130661","rc":[{"batb":[[0,5.7,1.87],[1,4.4,1.68],[2,4.3,3]],"ltp":0.0,"tv":0.0,"id":24420205},{"batb":[[0,5.8,2.49],[1,4.3,3.88],[2,4.2,12]],"ltp":0.0,"tv":0.0,"id":420}]}]}
{"op":"mcm","clk":"989568439","pt":1580489192658,"mc":[{"id":"1.168130661","rc":[{"batb":[[0,7,1.45],[1,6.4,1.68]],"ltp":0.0,"tv":0.0,"id":24707172}]}]}
{"op":"mcm","clk":"989571854","pt":1580489241471,"mc":[{"id":"1.168130661","rc":[{"batb":[[0,7.4,1.99],[1,7,1.45],[2,6.4,1.68]],"ltp":0.0,"tv":0.0,"id":24707172}]}]}
{"op":"mcm","clk":"989572229","pt":1580489246548,"mc":[{"id":"1.168130661","rc":[{"batb":[[0,7.8,9.43],[2,1.51,3.36]],"ltp":0.0,"tv":0.0,"id":25545675},{"batb":[[2,6.4,8.68]],"ltp":0.0,"tv":0.0,"id":24707172},{"batb":[[1,4.4,12.68]],"ltp":0.0,"tv":0.0,"id":24420205}]}]}
{"op":"mcm","clk":"989572516","pt":1580489250538,"mc":[{"id":"1.168130661","rc":[{"batb":[[0,5.7,1.69],[1,4.4,1.68],[2,4.3,3]],"ltp":0.0,"tv":0.0,"id":420}]}]}
{"op":"mcm","clk":"989572615","pt":1580489251709,"mc":[{"id":"1.168130661","rc":[{"batb":[[0,7.6,1.68],[1,7.4,1.99],[2,7,1.45]],"ltp":0.0,"tv":0.0,"id":24707172},{"batb":[[0,5.8,2.68],[1,4.4,11.88]],"ltp":0.0,"tv":0.0,"id":24420205}]}]}
{"op":"mcm","clk":"989573823","pt":1580489271070,"mc":[{"id":"1.168130661","rc":[{"batb":[[0,8,3.25],[1,7.8,8.68]],"ltp":0.0,"tv":0.0,"id":25545675},{"batb":[[1,4.5,3.88],[2,4.4,11]],"ltp":0.0,"tv":0.0,"id":24420205}]}]}
{"op":"mcm","clk":"989575916","pt":1580489301640,"mc":[{"id":"1.168130661","rc":[{"batb":[[0,7.8,1.99],[1,7.6,1.68]],"ltp":0.0,"tv":0.0,"id":24707172}]}]}
{"op":"mcm","clk":"989576526","pt":1580489310702,"mc":[{"id":"1.168130661","rc":[{"batb":[[1,7.8,7]],"ltp":0.0,"tv":0.0,"id":25545675},{"batb":[[0,8,1.68],[1,7.8,1.99]],"ltp":0.0,"tv":0.0,"id":24707172},{"batb":[[0,5.7,1.87],[1,4.6,1.68],[2,4.5,3]],"ltp":0.0,"tv":0.0,"id":24420205},{"batb":[[0,5.8,2.49],[1,4.3,3.88],[2,4.2,12]],"ltp":0.0,"tv":0.0,"id":420}]}]}
{"op":"mcm","clk":"989576647","pt":1580489311701,"mc":[{"id":"1.168130661","rc":[{"batb":[[0,8.2,2.43],[1,8,2.5],[2,7.8,7]],"ltp":0.0,"tv":0.0,"id":25545675}]}]}
{"op":"mcm","clk":"989578320","pt":1580489338912,"mc":[{"id":"1.168130661","rc":[{"batb":[[0,8.2,1.99],[1,8,1.68]],"ltp":0.0,"tv":0.0,"id":24707172}]}]}
{"op":"mcm","clk":"989580760","pt":1580489377089,"mc":[{"id":"1.168130661","rc":[{"batb":[[0,8,1.68],[1,7,1.45],[2,6.4,7]],"ltp":0.0,"tv":0.0,"id":24707172}]}]}
{"op":"mcm","clk":"989580946","pt":1580489379690,"mc":[{"id":"1.168130661","rc":[{"batb":[[0,7,1.45],[1,6.6,1.68]],"ltp":0.0,"tv":0.0,"id":24707172},{"batb":[[0,5.8,2.68],[1,4.5,3.88],[2,4.4,11]],"ltp":0.0,"tv":0.0,"id":24420205},{"batb":[[0,5.7,1.69],[1,4.4,1.68],[2,4.3,3]],"ltp":0.0,"tv":0.0,"id":420}]}]}
{"op":"mcm","clk":"989582250","pt":1580489400614,"mc":[{"id":"1.168130661","rc":[{"batl":[[0,3.6,8],[1,1000,0.22]],"ltp":0.0,"tv":0.0,"id":25238892}]}]}
{"op":"mcm","clk":"989583681","pt":1580489420630,"mc":[{"id":"1.168130661","rc":[{"batb":[[0,7.4,1.99],[1,7,1.45],[2,6.6,1.68]],"ltp":0.0,"tv":0.0,"id":24707172}]}]}
{"op":"mcm","clk":"989585542","pt":1580489445473,"mc":[{"id":"1.168130661","rc":[{"batl":[[0,3.55,1.68],[1,3.6,8],[2,990,0.2]],"ltp":0.0,"tv":0.0,"id":25238892},{"batb":[[0,5.8,2.49],[1,4.3,3.88],[2,4.2,12]],"ltp":0.0,"tv":0.0,"id":420}]}]}
{"op":"mcm","clk":"989585624","pt":1580489446666,"mc":[{"id":"1.168130661","rc":[{"batb":[[0,7.6,1.68],[1,7.4,1.99],[2,7,1.45]],"ltp":0.0,"tv":0.0,"id":24707172},{"batb":[[0,5.7,1.87],[1,4.6,1.68],[2,4.5,3]],"ltp":0.0,"tv":0.0,"id":24420205}]}]}
{"op":"mcm","clk":"989586913","pt":1580489464513,"mc":[{"id":"1.168130661","rc":[{"batb":[[0,7.8,1.99],[1,7.6,1.68]],"ltp":0.0,"tv":0.0,"id":24707172}]}]}
{"op":"mcm","clk":"989591261","pt":1580489522606,"mc":[{"id":"1.168130661","rc":[{"batb":[[0,8,1.68],[1,7.8,1.99]],"ltp":0.0,"tv":0.0,"id":24707172},{"batb":[[0,5.8,2.68],[1,4.5,3.88],[2,4.4,11]],"ltp":0.0,"tv":0.0,"id":24420205},{"batb":[[0,5.7,1.69],[1,4.4,1.68],[2,4.3,3]],"ltp":0.0,"tv":0.0,"id":420}]}]}
{"op":"mcm","clk":"989608495","pt":1580489603636,"mc":[{"id":"1.168130661","rc":[{"batb":[[0,5.7,1.87],[1,4.6,1.68],[2,4.5,3]],"ltp":0.0,"tv":0.0,"id":24420205},{"batb":[[0,5.8,2.49],[1,4.3,3.88],[2,4.2,12]],"ltp":0.0,"tv":0.0,"id":420}]}]}
{"op":"mcm","clk":"989611289","pt":1580489638263,"mc":[{"id":"1.168130661","rc":[{"batb":[[0,8.2,1.99],[1,8,1.68]],"ltp":0.0,"tv":0.0,"id":24707172}]}]}
{"op":"mcm","clk":"989616031","pt":1580489700650,"mc":[{"id":"1.168130661","rc":[{"batb":[[1,7,1.45],[2,6.4,7]],"ltp":0.0,"tv":0.0,"id":24707172},{"batb":[[0,5.8,2.68],[1,4.5,3.88],[2,4.4,11]],"ltp":0.0,"tv":0.0,"id":24420205},{"batb":[[0,5.7,1.69],[1,4.4,1.68],[2,4.3,3]],"ltp":0.0,"tv":0.0,"id":420}]}]}
{"op":"mcm","clk":"989616120","pt":1580489701667,"mc":[{"id":"1.168130661","rc":[{"batb":[[0,8.4,1.68],[1,8.2,1.99],[2,7,1.45]],"ltp":0.0,"tv":0.0,"id":24707172}]}]}
{"op":"mcm","clk":"989617156","pt":1580489713687,"mc":[{"id":"1.168130661","rc":[{"batb":[[1,7,1.45],[2,6.4,7]],"ltp":0.0,"tv":0.0,"id":24707172}]}]}
{"op":"mcm","clk":"989617208","pt":1580489714278,"mc":[{"id":"1.168130661","rc":[{"batb":[[2,6.6,3]],"ltp":0.0,"tv":0.0,"id":24707172}]}]}
{"op":"mcm","clk":"989624432","pt":1580489809586,"mc":[{"id":"1.168130661","rc":[{"batb":[[0,8.8,2.44],[1,8.2,2.26],[2,8,2.5]],"ltp":0.0,"tv":0.0,"id":25545675},{"batb":[[0,2.2,10.77]],"ltp":0.0,"tv":0.0,"id":25238892},{"batb":[[1,7.4,2.7],[2,7,1.45]],"ltp":0.0,"tv":0.0,"id":24707172},{"batb":[[0,5.9,4.38],[1,5.8,1.68],[2,4.5,3.88]],"ltp":0.0,"tv":0.0,"id":24420205},{"batb":[[0,2.02,11.58]],"ltp":0.0,"tv":0.0,"id":26314798},{"batb":[[0,5.8,4.26],[1,4.4,2.56]],"ltp":0.0,"tv":0.0,"id":420}]}]}
{"op":"mcm","clk":"989626399","pt":1580489837221,"mc":[{"id":"1.168130661","rc":[{"batb":[[0,2.22,3.73],[1,2.2,10.77]],"ltp":0.0,"tv":0.0,"id":25238892},{"batb":[[0,2.04,4.38],[1,2.02,11.58]],"ltp":0.0,"tv":0.0,"id":26314798}]}]}
{"op":"mcm","clk":"989627659","pt":1580489853166,"mc":[{"id":"1.168130661","rc":[{"batb":[[2,7.8,7]],"ltp":0.0,"tv":0.0,"id":25545675},{"batb":[[0,2.22,6.73],[2,1.74,44]],"ltp":0.0,"tv":0.0,"id":25238892},{"batb":[[2,4.4,11.88]],"ltp":0.0,"tv":0.0,"id":24420205},{"batb":[[0,2.04,7.38],[2,1.74,44]],"ltp":0.0,"tv":0.0,"id":26314798},{"batb":[[2,4.2,12]],"ltp":0.0,"tv":0.0,"id":420}]}]}
{"op":"mcm","clk":"989628044","pt":1580489857628,"mc":[{"id":"1.168130661","rc":[{"batb":[[0,2.06,1.68],[1,2.04,7.38],[2,2.02,9.9]],"ltp":0.0,"tv":0.0,"id":26314798}]}]}
{"op":"mcm","clk":"989628145","pt":1580489858558,"mc":[{"id":"1.168130661","rc":[{"batb":[[0,2.24,1.68],[1,2.22,6.73],[2,2.2,9.09]],"ltp":0.0,"tv":0.0,"id":25238892},{"batb":[[0,7.4,2.7],[1,7,1.45],[2,6.4,7]],"ltp":0.0,"tv":0.0,"id":24707172},{"batb":[[0,6,2.68],[1,5.9,3.39]],"ltp":0.0,"tv":0.0,"id":24420205},{"batb":[[0,5.9,2.49],[1,5.8,3.45],[2,4.2,12.88]],"ltp":0.0,"tv":0.0,"id":420}]}]}
{"op":"mcm","clk":"989628248","pt":1580489859652,"mc":[{"id":"1.168130661","rc":[{"batb":[[0,9,1.85],[1,8.8,2.27],[2,7.8,7.58]],"ltp":0.0,"tv":0.0,"id":25545675},{"batb":[[0,7.6,1.68],[1,7.4,2.7],[2,7,1.45]],"ltp":0.0,"tv":0.0,"id":24707172}]}]}
{"op":"mcm","clk":"989628834","pt":1580489867237,"mc":[{"id":"1.168130661","rc":[{"batb":[[0,2.24,5.35],[1,2.22,3]],"ltp":0.0,"tv":0.0,"id":25238892},{"batb":[[0,2.06,5.98],[1,2.04,3]],"ltp":0.0,"tv":0.0,"id":26314798}]}]}
{"op":"mcm","clk":"989629746","pt":1580489879564,"mc":[{"id":"1.168130661","rc":[{"batb":[[0,2.26,1.99],[1,2.24,5.35],[2,2.22,3]],"ltp":0.0,"tv":0.0,"id":25238892},{"batb":[[0,2.08,1.99],[1,2.06,5.98],[2,2.04,3]],"ltp":0.0,"tv":0.0,"id":26314798}]}]}
{"op":"mcm","clk":"989629797","pt":1580489880156,"mc":[{"id":"1.168130661","rc":[{"batb":[[0,10,1.99],[1,9,1.85],[2,8.8,2.27]],"ltp":0.0,"tv":0.0,"id":25545675},{"batb":[[0,7.8,1.99],[1,7.6,1.68],[2,7.4,2.7]],"ltp":0.0,"tv":0.0,"id":24707172}]}]}
{"op":"mcm","clk":"989630638","pt":1580489890074,"mc":[{"id":"1.168130661","rc":[{"batb":[[0,10,3.99],[2,7.8,7.58]],"ltp":0.0,"tv":0.0,"id":25545675},{"batb":[[0,2.26,10.84]],"ltp":0.0,"tv":0.0,"id":25238892},{"batb":[[0,7.8,4.55],[2,7,1.45]],"ltp":0.0,"tv":0.0,"id":24707172},{"batb":[[0,6.2,4.22],[1,6,1.68]],"ltp":0.0,"tv":0.0,"id":24420205},{"batb":[[0,2.08,11.61]],"ltp":0.0,"tv":0.0,"id":26314798},{"batb":[[0,6,4.14],[1,5.9,1.68]],"ltp":0.0,"tv":0.0,"id":420}]}]}
{"op":"mcm","clk":"989631247","pt":1580489897263,"mc":[{"id":"1.168130661","rc":[{"batb":[[0,2.28,3.56],[1,2.26,10.84],[2,2.24,1.68]],"ltp":0.0,"tv":0.0,"id":25238892},{"batb":[[0,2.1,4.14],[1,2.08,11.61],[2,2.06,1.68]],"ltp":0.0,"tv":0.0,"id":26314798}]}]}
{"op":"mcm","clk":"989631357","pt":1580489898468,"mc":[{"id":"1.168130661","rc":[{"batl":[[0,1000,1.9]],"ltp":0.0,"tv":0.0,"id":26314798}]}]}
{"op":"mcm","clk":"989631446","pt":1580489899466,"mc":[{"id":"1.168130661","rc":[{"batl":[[0,1000,0.64]],"ltp":0.0,"tv":0.0,"id":26314798}]}]}
{"op":"mcm","clk":"989631591","pt":1580489901500,"mc":[{"id":"1.168130661","rc":[{"batl":[[0,1000,0.22]],"ltp":0.0,"tv":0.0,"id":26314798}]}]}
{"op":"mcm","clk":"989631832","pt":1580489904476,"mc":[{"id":"1.168130661","rc":[{"batl":[[0,1000,0.64]],"ltp":0.0,"tv":0.0,"id":26314798}]}]}
{"op":"mcm","clk":"989631909","pt":1580489905783,"mc":[{"id":"1.168130661","rc":[{"batl":[[0,1000,0.22]],"ltp":0.0,"tv":0.0,"id":26314798}]}]}
{"op":"mcm","clk":"989632355","pt":1580489912218,"mc":[{"id":"1.168130661","rc":[{"batl":[[2,1000,0.62]],"ltp":0.0,"tv":0.0,"id":25238892}]}]}
{"op":"mcm","clk":"989632403","pt":1580489913105,"mc":[{"id":"1.168130661","rc":[{"batl":[[0,3.55,2.1],[2,990,0.2]],"ltp":0.0,"tv":0.0,"id":25238892}]}]}
{"op":"mcm","clk":"989632471","pt":1580489913898,"mc":[{"id":"1.168130661","rc":[{"batl":[[0,3.55,1.68]],"ltp":0.0,"tv":0.0,"id":25238892}]}]}
{"op":"mcm","clk":"989632609","pt":1580489915589,"mc":[{"id":"1.168130661","rc":[{"batb":[[1,2.26,13.84]],"ltp":0.0,"tv":0.0,"id":25238892},{"batl":[[0,1000,0.64]],"ltp":0.0,"tv":0.0,"id":26314798}]}]}
{"op":"mcm","clk":"989632746","pt":1580489917310,"mc":[{"id":"1.168130661","rc":[{"batl":[[0,1000,0.22]],"ltp":0.0,"tv":0.0,"id":26314798}]}]}
{"op":"mcm","clk":"989632848","pt":1580489918602,"mc":[{"id":"1.168130661","rc":[{"batl":[[0,1000,1.9]],"ltp":0.0,"tv":0.0,"id":26314798}]}]}
{"op":"mcm","clk":"989632905","pt":1580489919395,"mc":[{"id":"1.168130661","rc":[{"batl":[[0,1000,0.64]],"ltp":0.0,"tv":0.0,"id":26314798}]}]}
{"op":"mcm","clk":"989632977","pt":1580489920694,"mc":[{"id":"1.168130661","rc":[{"batl":[[0,1000,0.22]],"ltp":0.0,"tv":0.0,"id":26314798}]}]}
{"op":"mcm","clk":"989633248","pt":1580489924696,"mc":[{"id":"1.168130661","rc":[{"batl":[[0,1000,0.64]],"ltp":0.0,"tv":0.0,"id":26314798}]}]}
{"op":"mcm","clk":"989633361","pt":1580489926307,"mc":[{"id":"1.168130661","rc":[{"batl":[[0,1000,0.22]],"ltp":0.0,"tv":0.0,"id":26314798}]}]}
{"op":"mcm","clk":"989633544","pt":1580489928711,"mc":[{"id":"1.168130661","rc":[{"batb":[[2,7.8,7]],"ltp":0.0,"tv":0.0,"id":25545675},{"batb":[[0,2.1,4.56]],"ltp":0.0,"tv":0.0,"id":26314798}]}]}
{"op":"mcm","clk":"989633598","pt":1580489929433,"mc":[{"id":"1.168130661","rc":[{"batb":[[0,10,4.47]],"ltp":0.0,"tv":0.0,"id":25545675}]}]}
{"op":"mcm","clk":"989633674","pt":1580489930532,"mc":[{"id":"1.168130661","rc":[{"batb":[[0,2.1,4.98]],"ltp":0.0,"tv":0.0,"id":26314798}]}]}
{"op":"mcm","clk":"989633779","pt":1580489931622,"mc":[{"id":"1.168130661","rc":[{"batb":[[0,2.84,1.26],[1,2.1,4.14],[2,2.08,11.61]],"ltp":0.0,"tv":0.0,"id":26314798}]}]}
{"op":"mcm","clk":"989634233","pt":1580489938330,"mc":[{"id":"1.168130661","rc":[{"batl":[[0,1000,1.9]],"ltp":0.0,"tv":0.0,"id":26314798}]}]}
{"op":"mcm","clk":"989634311","pt":1580489939220,"mc":[{"id":"1.168130661","rc":[{"trd":[[3.25,0.84]],"batl":[[0,1000,0.22]],"ltp":3.25,"tv":0.84,"id":26314798}],"tv":0.84}]}
{"op":"mcm","clk":"989634473","pt":1580489941365,"mc":[{"id":"1.168130661","rc":[{"batl":[[0,1000,0.64]],"ltp":3.25,"tv":0.84,"id":26314798}]}]}
{"op":"mcm","clk":"989634638","pt":1580489943557,"mc":[{"id":"1.168130661","rc":[{"batl":[[0,1000,0.22]],"ltp":3.25,"tv":0.84,"id":26314798}]}]}
{"op":"mcm","clk":"989634780","pt":1580489945648,"mc":[{"id":"1.168130661","rc":[{"batb":[[1,2.12,3],[2,2.1,4.14]],"batl":[[0,1000,0.64]],"ltp":3.25,"tv":0.84,"id":26314798}]}]}
{"op":"mcm","clk":"989634895","pt":1580489947265,"mc":[{"id":"1.168130661","rc":[{"batl":[[0,1000,0.22]],"ltp":3.25,"tv":0.84,"id":26314798}]}]}
{"op":"mcm","clk":"989635224","pt":1580489951546,"mc":[{"id":"1.168130661","rc":[{"batb":[[0,2.9,1.68],[1,2.84,1.26],[2,2.12,3]],"ltp":3.25,"tv":0.84,"id":26314798}]}]}
{"op":"mcm","clk":"989635749","pt":1580489958684,"mc":[{"id":"1.168130661","rc":[{"batb":[[2,2.1,4.14]],"ltp":3.25,"tv":0.84,"id":26314798}]}]}
{"op":"mcm","clk":"989635820","pt":1580489959528,"mc":[{"id":"1.168130661","rc":[{"batb":[[0,7.8,5.17],[2,6.4,7.76]],"ltp":0.0,"tv":0.0,"id":24707172},{"batb":[[1,2.86,3],[2,2.84,1.26]],"ltp":3.25,"tv":0.84,"id":26314798}]}]}
{"op":"mcm","clk":"989635876","pt":1580489960253,"mc":[{"id":"1.168130661","rc":[{"batl":[[0,1000,1.9]],"ltp":3.25,"tv":0.84,"id":26314798}]}]}
{"op":"mcm","clk":"989635972","pt":1580489961300,"mc":[{"id":"1.168130661","rc":[{"batl":[[0,1000,0.64]],"ltp":3.25,"tv":0.84,"id":26314798}]}]}
{"op":"mcm","clk":"989636105","pt":1580489962356,"mc":[{"id":"1.168130661","rc":[{"batl":[[0,1000,0.22]],"ltp":3.25,"tv":0.84,"id":26314798}]}]}
{"op":"mcm","clk":"989636317","pt":1580489964460,"mc":[{"id":"1.168130661","rc":[{"batl":[[0,1000,0.64]],"ltp":3.25,"tv":0.84,"id":26314798}]}]}
{"op":"mcm","clk":"989636459","pt":1580489966280,"mc":[{"id":"1.168130661","rc":[{"batl":[[0,1000,0.22]],"ltp":3.25,"tv":0.84,"id":26314798}]}]}
{"op":"mcm","clk":"989636538","pt":1580489967374,"mc":[{"id":"1.168130661","rc":[{"batl":[[0,1000,0.64]],"ltp":3.25,"tv":0.84,"id":26314798}]}]}
{"op":"mcm","clk":"989636676","pt":1580489969250,"mc":[{"id":"1.168130661","rc":[{"batl":[[0,1000,0.22]],"ltp":3.25,"tv":0.84,"id":26314798}]}]}
{"op":"mcm","clk":"989636742","pt":1580489970411,"mc":[{"id":"1.168130661","rc":[{"batl":[[0,1000,0.64]],"ltp":3.25,"tv":0.84,"id":26314798}]}]}
{"op":"mcm","clk":"989636839","pt":1580489971696,"mc":[{"id":"1.168130661","rc":[{"batb":[[1,2.84,1.26],[2,2.1,4.14]],"ltp":3.25,"tv":0.84,"id":26314798}]}]}
{"op":"mcm","clk":"989636935","pt":1580489972695,"mc":[{"id":"1.168130661","rc":[{"batb":[[0,2.3,1.99],[1,2.28,3.56],[2,2.26,11.85]],"ltp":0.0,"tv":0.0,"id":25238892},{"batb":[[0,7.8,3.18]],"ltp":0.0,"tv":0.0,"id":24707172},{"batb":[[0,2.92,1.99],[1,2.9,1.68],[2,2.88,3]],"batl":[[0,1000,0.22]],"ltp":3.25,"tv":0.84,"id":26314798},{"batb":[[0,6.8,1.99],[1,6,4.14],[2,5.9,1.68]],"ltp":0.0,"tv":0.0,"id":420}]}]}
{"op":"mcm","clk":"989637032","pt":1580489973696,"mc":[{"id":"1.168130661","rc":[{"batb":[[0,10,2.48]],"ltp":0.0,"tv":0.0,"id":25545675},{"batb":[[0,8.2,1.99],[1,7.8,3.18],[2,7.6,1.68]],"ltp":0.0,"tv":0.0,"id":24707172},{"batl":[[0,1000,0.64]],"ltp":3.25,"tv":0.84,"id":26314798}]}]}
{"op":"mcm","clk":"989637219","pt":1580489975689,"mc":[{"id":"1.168130661","rc":[{"batb":[[1,2.28,12.33],[2,2.26,3]],"ltp":0.0,"tv":0.0,"id":25238892},{"batb":[[0,8.2,4.43],[1,7.6,1.68],[2,6.4,7.76]],"ltp":0.0,"tv":0.0,"id":24707172},{"batb":[[0,2.92,8.84]],"batl":[[0,1000,0.22]],"ltp":3.25,"tv":0.84,"id":26314798},{"batb":[[0,6.8,4.93],[1,5.9,2.49],[2,4.2,12.88]],"ltp":0.0,"tv":0.0,"id":420}]}]}
{"op":"mcm","clk":"989637303","pt":1580489976690,"mc":[{"id":"1.168130661","rc":[{"batb":[[1,7.8,7.17],[2,1.51,3.36]],"ltp":0.0,"tv":0.0,"id":25545675},{"batb":[[0,2.32,1.68],[1,2.3,1.99],[2,2.28,12.33]],"ltp":0.0,"tv":0.0,"id":25238892},{"batb":[[0,8.4,2.28],[1,8.2,4.43]],"ltp":0.0,"tv":0.0,"id":24707172},{"batb":[[0,6.4,2.68],[1,6.2,3.23]],"ltp":0.0,"tv":0.0,"id":24420205},{"batl":[[0,1000,1.9]],"ltp":3.25,"tv":0.84,"id":26314798}]}]}
{"op":"mcm","clk":"989637383","pt":1580489977687,"mc":[{"id":"1.168130661","rc":[{"batb":[[0,10.5,2.16],[1,10,2],[2,7.8,7.17]],"ltp":0.0,"tv":0.0,"id":25545675},{"batl":[[0,1000,0.64]],"ltp":3.25,"tv":0.84,"id":26314798}]}]}
{"op":"mcm","clk":"989637473","pt":1580489978797,"mc":[{"id":"1.168130661","rc":[{"batl":[[0,1000,0.22]],"ltp":3.25,"tv":0.84,"id":26314798}]}]}
{"op":"mcm","clk":"989637621","pt":1580489980506,"mc":[{"id":"1.168130661","rc":[{"batl":[[0,1000,0.64]],"ltp":3.25,"tv":0.84,"id":26314798}]}]}
{"op":"mcm","clk":"989637708","pt":1580489981406,"mc":[{"id":"1.168130661","rc":[{"batl":[[0,1000,0.22]],"ltp":3.25,"tv":0.84,"id":26314798}]}]}
{"op":"mcm","clk":"989637805","pt":1580489982913,"mc":[{"id":"1.168130661","rc":[{"batb":[[1,2.88,3],[2,2.84,1.26]],"ltp":3.25,"tv":0.84,"id":26314798}]}]}
{"op":"mcm","clk":"989637927","pt":1580489984489,"mc":[{"id":"1.168130661","rc":[{"batb":[[0,2.94,3],[1,2.92,8.84],[2,2.1,4.14]],"ltp":3.25,"tv":0.84,"id":26314798}]}]}
{"op":"mcm","clk":"989638110","pt":1580489987317,"mc":[{"id":"1.168130661","rc":[{"batb":[[1,2.3,5.5],[2,2.28,8.77]],"ltp":0.0,"tv":0.0,"id":25238892},{"batb":[[2,2.06,1.68]],"ltp":3.25,"tv":0.84,"id":26314798},{"batb":[[1,5.9,1.68]],"ltp":0.0,"tv":0.0,"id":420}]}]}
{"op":"mcm","clk":"989638218","pt":1580489988633,"mc":[{"id":"1.168130661","rc":[{"batl":[[0,1000,1.9]],"ltp":3.25,"tv":0.84,"id":26314798}]}]}
{"op":"mcm","clk":"989638314","pt":1580489989708,"mc":[{"id":"1.168130661","rc":[{"batl":[[0,1000,0.64]],"ltp":3.25,"tv":0.84,"id":26314798}]}]}
{"op":"mcm","clk":"989638391","pt":1580489990712,"mc":[{"id":"1.168130661","rc":[{"batb":[[0,2.94,5.34]],"batl":[[0,1000,0.22]],"ltp":3.25,"tv":0.84,"id":26314798},{"batb":[[0,6.8,5.69]],"ltp":0.0,"tv":0.0,"id":420}]}]}
{"op":"mcm","clk":"989638473","pt":1580489991606,"mc":[{"id":"1.168130661","rc":[{"batl":[[0,1000,0.64]],"ltp":3.25,"tv":0.84,"id":26314798}]}]}
{"op":"mcm","clk":"989638615","pt":1580489993328,"mc":[{"id":"1.168130661","rc":[{"batb":[[0,2.96,3],[1,2.94,2.34],[2,2.92,8.84]],"batl":[[0,1000,0.22]],"ltp":3.25,"tv":0.84,"id":26314798}]}]}
{"op":"mcm","clk":"989638718","pt":1580489994643,"mc":[{"id":"1.168130661","rc":[{"batl":[[0,1000,0.64]],"ltp":3.25,"tv":0.84,"id":26314798}]}]}
{"op":"mcm","clk":"989638871","pt":1580489996351,"mc":[{"id":"1.168130661","rc":[{"batl":[[0,1000,0.22]],"ltp":3.25,"tv":0.84,"id":26314798}]}]}
{"op":"mcm","clk":"989641054","pt":1580490017244,"mc":[{"id":"1.168130661","rc":[{"batb":[[0,2.96,3.84]],"ltp":3.25,"tv":0.84,"id":26314798}]}]}
{"op":"mcm","clk":"989641212","pt":1580490019171,"mc":[{"id":"1.168130661","rc":[{"batb":[[0,3.15,1.68],[1,2.98,3],[2,2.94,2.34]],"ltp":3.25,"tv":0.84,"id":26314798}]}]}
{"op":"mcm","clk":"989641794","pt":1580490025483,"mc":[{"id":"1.168130661","rc":[{"trd":[[3.6,3.36]],"ltp":3.6,"tv":4.2,"id":26314798}],"tv":4.2}]}
{"op":"mcm","clk":"989641910","pt":1580490027054,"mc":[{"id":"1.168130661","rc":[{"trd":[[3.6,6.72]],"ltp":3.6,"tv":7.56,"id":26314798}],"tv":7.56}]}
{"op":"mcm","clk":"989642011","pt":1580490028459,"mc":[{"id":"1.168130661","rc":[{"trd":[[3.6,10.09]],"ltp":3.6,"tv":10.92,"id":26314798}],"tv":10.92}]}
{"op":"mcm","clk":"989642229","pt":1580490030666,"mc":[{"id":"1.168130661","rc":[{"trd":[[3.6,13.45]],"batb":[[1,3,3]],"ltp":3.6,"tv":14.28,"id":26314798}],"tv":14.28}]}
{"op":"mcm","clk":"989642336","pt":1580490031676,"mc":[{"id":"1.168130661","rc":[{"batl":[[0,3.6,1.68],[1,1000,0.22]],"ltp":3.6,"tv":14.28,"id":26314798}]}]}
{"op":"mcm","clk":"989642347","pt":1580490031780,"mc":[{"id":"1.168130661","rc":[{"trd":[[3.6,16.81]],"batl":[[0,1000,0.22],[1,1000,0]],"ltp":3.6,"tv":17.64,"id":26314798}],"tv":17.64}]}
{"op":"mcm","clk":"989642439","pt":1580490032983,"mc":[{"id":"1.168130661","rc":[{"trd":[[3.6,20.17]],"ltp":3.6,"tv":21.01,"id":26314798}],"tv":21.01}]}
{"op":"mcm","clk":"989642584","pt":1580490034670,"mc":[{"id":"1.168130661","rc":[{"trd":[[3.6,23.53]],"ltp":3.6,"tv":24.37,"id":26314798}],"tv":24.37}]}
{"op":"mcm","clk":"989642650","pt":1580490035464,"mc":[{"id":"1.168130661","rc":[{"batb":[[0,2.32,2.39]],"ltp":0.0,"tv":0.0,"id":25238892},{"batb":[[0,8.4,2.48]],"ltp":0.0,"tv":0.0,"id":24707172},{"batb":[[1,3,3.54]],"batl":[[0,3.6,1.68],[1,1000,0.22]],"ltp":3.6,"tv":24.37,"id":26314798},{"batb":[[0,6.8,5.92]],"ltp":0.0,"tv":0.0,"id":420}]}]}
{"op":"mcm","clk":"989642825","pt":1580490037308,"mc":[{"id":"1.168130661","rc":[{"batl":[[0,1000,0.22],[1,1000,0]],"ltp":3.6,"tv":24.37,"id":26314798}]}]}
{"op":"mcm","clk":"989642887","pt":1580490037984,"mc":[{"id":"1.168130661","rc":[{"batl":[[0,3.55,1.68],[1,1000,0.22]],"ltp":3.6,"tv":24.37,"id":26314798}]}]}
{"op":"mcm","clk":"989643123","pt":1580490040397,"mc":[{"id":"1.168130661","rc":[{"batl":[[0,1000,0.22],[1,1000,0]],"ltp":3.6,"tv":24.37,"id":26314798}]}]}
{"op":"mcm","clk":"989643256","pt":1580490041862,"mc":[{"id":"1.168130661","rc":[{"batl":[[0,3.7,1.68],[1,1000,0.22]],"ltp":3.6,"tv":24.37,"id":26314798}]}]}
{"op":"mcm","clk":"989643358","pt":1580490043160,"mc":[{"id":"1.168130661","rc":[{"batl":[[0,1000,0.22],[1,1000,0]],"ltp":3.6,"tv":24.37,"id":26314798}]}]}
{"op":"mcm","clk":"989643520","pt":1580490044888,"mc":[{"id":"1.168130661","rc":[{"batl":[[0,3.65,1.68],[1,1000,0.22]],"ltp":3.6,"tv":24.37,"id":26314798}]}]}
{"op":"mcm","clk":"989643690","pt":1580490046607,"mc":[{"id":"1.168130661","rc":[{"batl":[[0,1000,0.22],[1,1000,0]],"ltp":3.6,"tv":24.37,"id":26314798}]}]}
{"op":"mcm","clk":"989643772","pt":1580490047504,"mc":[{"id":"1.168130661","rc":[{"batb":[[0,7,1.7],[1,6.8,4.93],[2,5.9,1.68]],"ltp":0.0,"tv":0.0,"id":420}]}]}
{"op":"mcm","clk":"989643879","pt":1580490048710,"mc":[{"id":"1.168130661","rc":[{"batb":[[1,7.8,7.17],[2,1.51,3.36]],"ltp":0.0,"tv":0.0,"id":25545675},{"batb":[[2,1.74,44]],"ltp":0.0,"tv":0.0,"id":25238892},{"batb":[[1,8.2,1.99]],"ltp":0.0,"tv":0.0,"id":24707172},{"batb":[[1,4.4,11.88],[2,1.51,3.36]],"ltp":0.0,"tv":0.0,"id":24420205},{"batl":[[0,1000,0.64]],"ltp":3.6,"tv":24.37,"id":26314798}]}]}
{"op":"mcm","clk":"989643988","pt":1580490050172,"mc":[{"id":"1.168130661","rc":[{"batl":[[0,1000,0.22]],"ltp":3.6,"tv":24.37,"id":26314798}]}]}
{"op":"mcm","clk":"989644118","pt":1580490051721,"mc":[{"id":"1.168130661","rc":[{"batl":[[0,1000,1.06]],"ltp":3.6,"tv":24.37,"id":26314798}]}]}
{"op":"mcm","clk":"989644211","pt":1580490052693,"mc":[{"id":"1.168130661","rc":[{"batl":[[0,990,1.04],[1,1000,0.02]],"ltp":3.6,"tv":24.37,"id":26314798}]}]}
{"op":"mcm","clk":"989644242","pt":1580490053013,"mc":[{"id":"1.168130661","rc":[{"batl":[[0,1000,0.22],[1,1000,0]],"ltp":3.6,"tv":24.37,"id":26314798}]}]}
{"op":"mcm","clk":"989644395","pt":1580490054907,"mc":[{"id":"1.168130661","rc":[{"batb":[[0,3,3.54],[1,2.94,2.34],[2,2.92,1.99]],"ltp":3.6,"tv":24.37,"id":26314798}]}]}
{"op":"mcm","clk":"989644606","pt":1580490057686,"mc":[{"id":"1.168130661","rc":[{"batb":[[1,2.3,3.51]],"ltp":0.0,"tv":0.0,"id":25238892},{"batb":[[0,3.1,1.99],[1,3,3.54],[2,2.94,2.34]],"batl":[[0,1000,1.9]],"ltp":3.6,"tv":24.37,"id":26314798},{"batb":[[1,6.8,2.94]],"ltp":0.0,"tv":0.0,"id":420}]}]}
{"op":"mcm","clk":"989644731","pt":1580490058625,"mc":[{"id":"1.168130661","rc":[{"batb":[[1,6.4,7.76],[2,1.51,3.36]],"ltp":0.0,"tv":0.0,"id":24707172},{"trd":[[3.55,0.84]],"batl":[[0,1000,0.22]],"ltp":3.55,"tv":25.21,"id":26314798}],"tv":25.21}]}
{"op":"mcm","clk":"989644954","pt":1580490060506,"mc":[{"id":"1.168130661","rc":[{"batl":[[0,1000,0.64]],"ltp":3.55,"tv":25.21,"id":26314798}]}]}
{"op":"mcm","clk":"989645211","pt":1580490062631,"mc":[{"id":"1.168130661","rc":[{"batl":[[0,1000,0.22]],"ltp":3.55,"tv":25.21,"id":26314798}]}]}
{"op":"mcm","clk":"989645310","pt":1580490063535,"mc":[{"id":"1.168130661","rc":[{"batl":[[0,1000,1.9]],"ltp":3.55,"tv":25.21,"id":26314798}]}]}
{"op":"mcm","clk":"989645403","pt":1580490064545,"mc":[{"id":"1.168130661","rc":[{"batl":[[0,1000,0.64]],"ltp":3.55,"tv":25.21,"id":26314798}]}]}
{"op":"mcm","clk":"989645511","pt":1580490065693,"mc":[{"id":"1.168130661","rc":[{"batl":[[0,1000,0.22]],"ltp":3.55,"tv":25.21,"id":26314798}]}]}
{"op":"mcm","clk":"989646499","pt":1580490075506,"mc":[{"id":"1.168130661","rc":[{"batl":[[0,1000,1.06]],"ltp":3.55,"tv":25.21,"id":26314798}]}]}
{"op":"mcm","clk":"989646553","pt":1580490076247,"mc":[{"id":"1.168130661","rc":[{"trd":[[3.55,2.52]],"batl":[[0,1000,0.22]],"ltp":3.55,"tv":26.89,"id":26314798}],"tv":26.89}]}
{"op":"mcm","clk":"989646701","pt":1580490077721,"mc":[{"id":"1.168130661","rc":[{"batl":[[0,1000,1.06]],"ltp":3.55,"tv":26.89,"id":26314798}]}]}
{"op":"mcm","clk":"989646758","pt":1580490078350,"mc":[{"id":"1.168130661","rc":[{"trd":[[3.55,4.2]],"batl":[[0,1000,0.22]],"ltp":3.55,"tv":28.57,"id":26314798}],"tv":28.57}]}
{"op":"mcm","clk":"989646859","pt":1580490079718,"mc":[{"id":"1.168130661","rc":[{"batl":[[0,1000,1.06]],"ltp":3.55,"tv":28.57,"id":26314798}]}]}
{"op":"mcm","clk":"989646914","pt":1580490080249,"mc":[{"id":"1.168130661","rc":[{"trd":[[3.55,5.88]],"batl":[[0,1000,0.22]],"ltp":3.55,"tv":30.25,"id":26314798}],"tv":30.25}]}
{"op":"mcm","clk":"989647029","pt":1580490081569,"mc":[{"id":"1.168130661","rc":[{"batl":[[0,1000,1.9]],"ltp":3.55,"tv":30.25,"id":26314798}]}]}
{"op":"mcm","clk":"989647093","pt":1580490082523,"mc":[{"id":"1.168130661","rc":[{"trd":[[3.55,7.56]],"batl":[[0,1000,0.22]],"ltp":3.55,"tv":31.93,"id":26314798}],"tv":31.93}]}
{"op":"mcm","clk":"989647164","pt":1580490083421,"mc":[{"id":"1.168130661","rc":[{"batl":[[0,1000,1.9]],"ltp":3.55,"tv":31.93,"id":26314798}]}]}
{"op":"mcm","clk":"989647226","pt":1580490084363,"mc":[{"id":"1.168130661","rc":[{"trd":[[3.55,9.24]],"batl":[[0,1000,0.22]],"ltp":3.55,"tv":33.61,"id":26314798}],"tv":33.61}]}
{"op":"mcm","clk":"989647453","pt":1580490086651,"mc":[{"id":"1.168130661","rc":[{"batl":[[0,990,1.04],[1,1000,0.02]],"ltp":3.55,"tv":33.61,"id":26314798}]}]}
{"op":"mcm","clk":"989647482","pt":1580490086872,"mc":[{"id":"1.168130661","rc":[{"trd":[[3.55,10.93]],"batl":[[0,1000,0.22],[1,1000,0]],"ltp":3.55,"tv":35.29,"id":26314798}],"tv":35.29}]}
{"op":"mcm","clk":"989647690","pt":1580490088419,"mc":[{"id":"1.168130661","rc":[{"batl":[[0,1000,1.06]],"ltp":3.55,"tv":35.29,"id":26314798}]}]}
{"op":"mcm","clk":"989647778","pt":1580490089409,"mc":[{"id":"1.168130661","rc":[{"trd":[[3.55,12.61]],"batl":[[0,1000,0.22]],"ltp":3.55,"tv":36.97,"id":26314798}],"tv":36.97}]}
{"op":"mcm","clk":"989647885","pt":1580490090628,"mc":[{"id":"1.168130661","rc":[{"batl":[[0,1000,1.06]],"ltp":3.55,"tv":36.97,"id":26314798}]}]}
{"op":"mcm","clk":"989647954","pt":1580490091561,"mc":[{"id":"1.168130661","rc":[{"trd":[[3.55,14.29]],"batl":[[0,1000,0.22]],"ltp":3.55,"tv":38.66,"id":26314798}],"tv":38.66}]}
{"op":"mcm","clk":"989648052","pt":1580490092759,"mc":[{"id":"1.168130661","rc":[{"batl":[[0,990,1.04],[1,1000,0.02]],"ltp":3.55,"tv":38.66,"id":26314798}]}]}
{"op":"mcm","clk":"989648323","pt":1580490095449,"mc":[{"id":"1.168130661","rc":[{"batb":[[0,3.1,13.99]],"batl":[[1,1000,0.86]],"ltp":3.55,"tv":38.66,"id":26314798}]}]}
{"op":"mcm","clk":"989648358","pt":1580490095866,"mc":[{"id":"1.168130661","rc":[{"batl":[[0,3.55,1.68],[1,1000,0.22]],"ltp":3.55,"tv":38.66,"id":26314798}]}]}
{"op":"mcm","clk":"989648532","pt":1580490098162,"mc":[{"id":"1.168130661","rc":[{"batl":[[1,3.7,2.52],[2,1000,0.22]],"ltp":3.55,"tv":38.66,"id":26314798}]}]}
{"op":"mcm","clk":"989648765","pt":1580490100989,"mc":[{"id":"1.168130661","rc":[{"batb":[[0,11,1.98],[1,10.5,2.16],[2,7.8,7.17]],"ltp":0.0,"tv":0.0,"id":25545675},{"batb":[[0,2.34,1.98],[1,2.32,2.39],[2,2.3,3.51]],"ltp":0.0,"tv":0.0,"id":25238892},{"batb":[[0,8.6,1.98],[1,8.4,2.48],[2,6.4,7.76]],"ltp":0.0,"tv":0.0,"id":24707172},{"batb":[[0,6.6,2.98],[1,6.4,1.68],[2,4.4,11.88]],"ltp":0.0,"tv":0.0,"id":24420205},{"batb":[[0,3.1,17.95]],"ltp":3.55,"tv":38.66,"id":26314798},{"batb":[[0,7,3.69]],"ltp":0.0,"tv":0.0,"id":420}]}]}
{"op":"mcm","clk":"989649778","pt":1580490112268,"mc":[{"id":"1.168130661","rc":[{"batb":[[1,5.9,1.68],[2,4.2,12]],"ltp":0.0,"tv":0.0,"id":420}]}]}
{"op":"mcm","clk":"989650002","pt":1580490115293,"mc":[{"id":"1.168130661","rc":[{"batb":[[0,7,1.7],[1,6,1.98],[2,5.9,1.68]],"ltp":0.0,"tv":0.0,"id":420}]}]}
{"op":"mcm","clk":"989650123","pt":1580490116392,"mc":[{"id":"1.168130661","rc":[{"batl":[[0,3.5,2.52],[1,3.55,1.68],[2,3.7,2.52]],"ltp":3.55,"tv":38.66,"id":26314798}]}]}
{"op":"mcm","clk":"989650353","pt":1580490118454,"mc":[{"id":"1.168130661","rc":[{"batl":[[0,3.45,2.52]],"ltp":3.55,"tv":38.66,"id":26314798}]}]}
{"op":"mcm","clk":"989650418","pt":1580490119387,"mc":[{"id":"1.168130661","rc":[{"batl":[[0,3.55,1.68],[1,3.7,2.52],[2,1000,0.22]],"ltp":3.55,"tv":38.66,"id":26314798}]}]}
{"op":"mcm","clk":"989650487","pt":1580490120171,"mc":[{"id":"1.168130661","rc":[{"batl":[[0,3.7,2.52],[1,1000,0.22],[2,1000,0]],"ltp":3.55,"tv":38.66,"id":26314798}]}]}
{"op":"mcm","clk":"989650541","pt":1580490120962,"mc":[{"id":"1.168130661","rc":[{"batl":[[0,3.6,2.52],[1,3.7,2.52],[2,1000,0.22]],"ltp":3.55,"tv":38.66,"id":26314798}]}]}
{"op":"mcm","clk":"989653374","pt":1580490151631,"mc":[{"id":"1.168130661","rc":[{"batb":[[0,2.36,1.99],[1,2.34,1.98],[2,2.32,2.39]],"ltp":0.0,"tv":0.0,"id":25238892}]}]}
{"op":"mcm","clk":"989653408","pt":1580490152199,"mc":[{"id":"1.168130661","rc":[{"batb":[[0,7.2,1.99],[1,6.6,2.98],[2,6.4,1.68]],"ltp":0.0,"tv":0.0,"id":24420205}]}]}
{"op":"mcm","clk":"989654033","pt":1580490158437,"mc":[{"id":"1.168130661","rc":[{"batb":[[0,2.38,1.98],[1,2.36,1.99]],"ltp":0.0,"tv":0.0,"id":25238892},{"batb":[[0,7.4,1.98],[1,7.2,1.99],[2,6.4,2.68]],"ltp":0.0,"tv":0.0,"id":24420205}]}]}
{"op":"mcm","clk":"989655525","pt":1580490176640,"mc":[{"id":"1.168130661","rc":[{"batl":[[2,990,0.2]],"ltp":3.55,"tv":38.66,"id":26314798}]}]}
{"op":"mcm","clk":"989655597","pt":1580490177584,"mc":[{"id":"1.168130661","rc":[{"batb":[[0,2.4,1.68],[1,2.38,1.98],[2,2.36,1.99]],"ltp":0.0,"tv":0.0,"id":25238892},{"batb":[[0,7.6,1.68],[1,7.4,1.98],[2,7.2,1.99]],"ltp":0.0,"tv":0.0,"id":24420205},{"batl":[[0,3.55,1.68],[1,3.6,2.52],[2,3.7,2.52]],"ltp":3.55,"tv":38.66,"id":26314798}]}]}
{"op":"mcm","clk":"989655686","pt":1580490178646,"mc":[{"id":"1.168130661","rc":[{"batb":[[0,11.5,1.68],[1,11,1.98],[2,7.8,7.65]],"ltp":0.0,"tv":0.0,"id":25545675},{"batb":[[0,8.8,1.68],[1,8.6,1.98],[2,7,1.55]],"ltp":0.0,"tv":0.0,"id":24707172}]}]}
{"op":"mcm","clk":"989655987","pt":1580490181767,"mc":[{"id":"1.168130661","rc":[{"batb":[[2,1.51,4.01]],"ltp":0.0,"tv":0.0,"id":25545675}]}]}
{"op":"mcm","clk":"989656624","pt":1580490188602,"mc":[{"id":"1.168130661","rc":[{"batb":[[1,1.52,2.63],[2,1.51,3.36]],"ltp":0.0,"tv":0.0,"id":25545675},{"batb":[[1,7.2,2.78],[2,1.51,4.12]],"ltp":0.0,"tv":0.0,"id":24707172}]}]}
{"op":"mcm","clk":"989661556","pt":1580490240451,"mc":[{"id":"1.168130661","rc":[{"batb":[[0,2.42,1.99],[1,2.4,1.68],[2,2.38,1.98]],"ltp":0.0,"tv":0.0,"id":25238892},{"batb":[[0,7.8,1.99],[1,7.6,1.68],[2,7.4,1.98]],"ltp":0.0,"tv":0.0,"id":24420205}]}]}
{"op":"mcm","clk":"989662178","pt":1580490246324,"mc":[{"id":"1.168130661","rc":[{"batb":[[0,2.44,1.98],[1,2.42,1.99],[2,2.4,1.68]],"ltp":0.0,"tv":0.0,"id":25238892},{"batb":[[0,8,1.98],[1,7.8,1.99],[2,7.6,1.68]],"ltp":0.0,"tv":0.0,"id":24420205}]}]}
{"op":"mcm","clk":"989666670","pt":1580490295503,"mc":[{"id":"1.168130661","rc":[{"batl":[[0,3.4,50],[1,3.55,1.68],[2,3.6,8]],"ltp":0.0,"tv":0.0,"id":25238892}]}]}
{"op":"mcm","clk":"989668478","pt":1580490314949,"mc":[{"id":"1.168130661","rc":[{"batb":[[2,1.7,20.76]],"ltp":0.0,"tv":0.0,"id":24707172}]}]}
{"op":"mcm","clk":"989668929","pt":1580490320545,"mc":[{"id":"1.168130661","rc":[{"batb":[[0,2.46,1.99],[1,2.44,1.98]],"ltp":0.0,"tv":0.0,"id":25238892}]}]}
{"op":"mcm","clk":"989669014","pt":1580490321541,"mc":[{"id":"1.168130661","rc":[{"batb":[[0,8.2,1.99],[1,8,1.98]],"ltp":0.0,"tv":0.0,"id":24420205}]}]}
{"op":"mcm","clk":"989670893","pt":1580490341955,"mc":[{"id":"1.168130661","rc":[{"batb":[[0,12,1.98],[1,11.5,1.68],[2,1.51,4.01]],"ltp":0.0,"tv":0.0,"id":25545675},{"batb":[[0,2.48,1.98],[1,2.46,1.99]],"ltp":0.0,"tv":0.0,"id":25238892},{"batb":[[0,9,1.98],[1,8.8,1.68],[2,7,1.55]],"ltp":0.0,"tv":0.0,"id":24707172},{"batb":[[0,8.4,1.98],[1,8.2,1.99]],"ltp":0.0,"tv":0.0,"id":24420205},{"batb":[[0,7.2,1.98],[1,7,1.7]],"ltp":0.0,"tv":0.0,"id":420}]}]}
{"op":"mcm","clk":"989672390","pt":1580490357393,"mc":[{"id":"1.168130661","rc":[{"batb":[[0,2.48,2.65]],"ltp":0.0,"tv":0.0,"id":25238892},{"batb":[[0,8.4,2.18]],"ltp":0.0,"tv":0.0,"id":24420205}]}]}
{"op":"mcm","clk":"989674245","pt":1580490378622,"mc":[{"id":"1.168130661","rc":[{"batb":[[0,11.5,1.68],[1,1.52,2.63],[2,1.51,3.36]],"ltp":0.0,"tv":0.0,"id":25545675},{"batb":[[0,8.8,1.68],[1,7.2,2.78],[2,1.7,20.76]],"ltp":0.0,"tv":0.0,"id":24707172}]}]}
{"op":"mcm","clk":"989676681","pt":1580490408643,"mc":[{"id":"1.168130661","rc":[{"batb":[[0,2.5,1.99],[1,2.48,2.65]],"ltp":0.0,"tv":0.0,"id":25238892}]}]}
{"op":"mcm","clk":"989676733","pt":1580490409338,"mc":[{"id":"1.168130661","rc":[{"batb":[[0,8.6,1.99],[1,8.4,2.18]],"ltp":0.0,"tv":0.0,"id":24420205}]}]}
{"op":"mcm","clk":"989677269","pt":1580490415956,"mc":[{"id":"1.168130661","rc":[{"batb":[[0,12,1.98],[1,11.5,1.68],[2,1.51,4.01]],"ltp":0.0,"tv":0.0,"id":25545675},{"batb":[[0,2.52,1.98],[1,2.5,1.99],[2,2.4,2.35]],"ltp":0.0,"tv":0.0,"id":25238892},{"batb":[[0,9,1.98],[1,8.8,1.68],[2,7,1.55]],"ltp":0.0,"tv":0.0,"id":24707172},{"batb":[[0,8.8,1.98],[1,8.6,1.99],[2,7.6,1.88]],"ltp":0.0,"tv":0.0,"id":24420205}]}]}
{"op":"mcm","clk":"989690179","pt":1580490454708,"mc":[{"id":"1.168130661","rc":[{"batb":[[0,11.5,1.68],[1,1.52,2.63],[2,1.51,3.36]],"ltp":0.0,"tv":0.0,"id":25545675},{"batb":[[0,8.8,1.68],[1,7.2,2.78],[2,1.51,4.12]],"ltp":0.0,"tv":0.0,"id":24707172}]}]}
{"op":"mcm","clk":"989693355","pt":1580490490574,"mc":[{"id":"1.168130661","rc":[{"batb":[[0,12,1.98],[1,11.5,1.68],[2,1.51,4.01]],"ltp":0.0,"tv":0.0,"id":25545675},{"batb":[[0,9,1.98],[1,8.8,1.68],[2,7,1.55]],"ltp":0.0,"tv":0.0,"id":24707172}]}]}
{"op":"mcm","clk":"989694050","pt":1580490497560,"mc":[{"id":"1.168130661","rc":[{"batb":[[0,3.1,20.95]],"ltp":3.55,"tv":38.66,"id":26314798}]}]}
{"op":"mcm","clk":"989694336","pt":1580490500659,"mc":[{"id":"1.168130661","rc":[{"batb":[[0,3.2,3],[1,3.1,17.95],[2,3,3.54]],"ltp":3.55,"tv":38.66,"id":26314798}]}]}
{"op":"mcm","clk":"989694395","pt":1580490501304,"mc":[{"id":"1.168130661","rc":[{"batb":[[0,3.1,17.95],[1,3,3.54],[2,2.94,2.34]],"ltp":3.55,"tv":38.66,"id":26314798}]}]}
{"op":"mcm","clk":"989694918","pt":1580490507565,"mc":[{"id":"1.168130661","rc":[{"batb":[[0,2.54,1.99],[1,2.52,1.98]],"ltp":0.0,"tv":0.0,"id":25238892},{"batb":[[0,9.2,1.99],[1,9,1.98],[2,8.8,1.68]],"ltp":0.0,"tv":0.0,"id":24707172},{"batb":[[1,7.6,1.88],[2,5.7,1.64]],"ltp":0.0,"tv":0.0,"id":24420205}]}]}
{"op":"mcm","clk":"989696570","pt":1580490526405,"mc":[{"id":"1.168130661","rc":[{"batb":[[0,11.5,1.68],[1,1.52,2.63],[2,1.51,3.36]],"ltp":0.0,"tv":0.0,"id":25545675},{"batb":[[0,2.56,1.98],[1,2.54,1.99]],"ltp":0.0,"tv":0.0,"id":25238892},{"batb":[[0,9.4,1.98],[1,9.2,1.99]],"ltp":0.0,"tv":0.0,"id":24707172},{"batb":[[0,7.8,2.18],[1,7.6,1.68]],"ltp":0.0,"tv":0.0,"id":24420205}]}]}
{"op":"mcm","clk":"989700155","pt":1580490563634,"mc":[{"id":"1.168130661","rc":[{"batb":[[1,1.51,4.01],[2,1.03,1571.78]],"ltp":0.0,"tv":0.0,"id":25545675}]}]}
{"op":"mcm","clk":"989700197","pt":1580490564049,"mc":[{"id":"1.168130661","rc":[{"batb":[[0,12,1.98],[1,11.5,1.68],[2,1.51,4.01]],"ltp":0.0,"tv":0.0,"id":25545675}]}]}
{"op":"mcm","clk":"989702597","pt":1580490590573,"mc":[{"id":"1.168130661","rc":[{"batb":[[0,2.58,1.99],[1,2.56,1.98]],"ltp":0.0,"tv":0.0,"id":25238892},{"batb":[[0,8.6,1.99],[1,7.8,2.18],[2,7.6,1.68]],"ltp":0.0,"tv":0.0,"id":24420205}]}]}
{"op":"mcm","clk":"989702659","pt":1580490591293,"mc":[{"id":"1.168130661","rc":[{"batb":[[0,9.6,1.99],[1,9.4,1.98]],"ltp":0.0,"tv":0.0,"id":24707172}]}]}
{"op":"mcm","clk":"989708009","pt":1580490647940,"mc":[{"id":"1.168130661","rc":[{"batb":[[0,11.5,1.68],[1,1.52,2.63],[2,1.51,3.36]],"ltp":0.0,"tv":0.0,"id":25545675},{"batb":[[0,2.6,1.98],[1,2.58,1.99]],"ltp":0.0,"tv":0.0,"id":25238892},{"batb":[[0,9.8,1.98],[1,9.6,1.99]],"ltp":0.0,"tv":0.0,"id":24707172},{"batb":[[0,8.8,1.98],[1,8.6,1.99],[2,7.6,1.88]],"ltp":0.0,"tv":0.0,"id":24420205}]}]}
{"op":"mcm","clk":"989710699","pt":1580490674660,"mc":[{"id":"1.168130661","rc":[{"batb":[[0,2.62,1.99],[1,2.6,1.98]],"ltp":0.0,"tv":0.0,"id":25238892}]}]}
{"op":"mcm","clk":"989710788","pt":1580490675496,"mc":[{"id":"1.168130661","rc":[{"batb":[[0,10,1.99],[1,9.8,1.98]],"ltp":0.0,"tv":0.0,"id":24707172},{"batb":[[1,7.6,1.88],[2,5.7,1.64]],"ltp":0.0,"tv":0.0,"id":24420205}]}]}
{"op":"mcm","clk":"989714456","pt":1580490712041,"mc":[{"id":"1.168130661","rc":[{"batb":[[2,2.4,1.68]],"ltp":0.0,"tv":0.0,"id":25238892}]}]}
{"op":"mcm","clk":"989717808","pt":1580490743568,"mc":[{"id":"1.168130661","rc":[{"batb":[[0,12,1.98],[1,11.5,1.68],[2,1.51,4.01]],"ltp":0.0,"tv":0.0,"id":25545675},{"batb":[[0,2.64,1.98],[1,2.62,1.99]],"ltp":0.0,"tv":0.0,"id":25238892},{"batb":[[0,10.5,1.98],[1,10,1.99]],"ltp":0.0,"tv":0.0,"id":24707172},{"batb":[[0,7.8,2.18],[1,7.6,1.68]],"ltp":0.0,"tv":0.0,"id":24420205}]}]}
{"op":"mcm","clk":"989718237","pt":1580490747656,"mc":[{"id":"1.168130661","rc":[{"batb":[[0,2.64,2.61]],"ltp":0.0,"tv":0.0,"id":25238892}]}]}
{"op":"mcm","clk":"989720461","pt":1580490769597,"mc":[{"id":"1.168130661","rc":[{"batb":[[0,2.66,1.99],[1,2.64,2.61]],"ltp":0.0,"tv":0.0,"id":25238892}]}]}
{"op":"mcm","clk":"989720579","pt":1580490770699,"mc":[{"id":"1.168130661","rc":[{"batb":[[1,8.8,1.68],[2,7,1.36]],"ltp":0.0,"tv":0.0,"id":24707172},{"batb":[[0,8.6,1.99],[1,7.8,2.18],[2,7.6,1.68]],"ltp":0.0,"tv":0.0,"id":24420205}]}]}
{"op":"mcm","clk":"989727667","pt":1580490836461,"mc":[{"id":"1.168130661","rc":[{"batb":[[0,11.5,1.68],[1,1.52,2.63],[2,1.51,3.36]],"ltp":0.0,"tv":0.0,"id":25545675},{"batb":[[0,2.68,1.98],[1,2.66,1.99],[2,2.4,2.31]],"ltp":0.0,"tv":0.0,"id":25238892},{"batb":[[0,8.8,1.68],[1,7.2,2.58],[2,1.51,4.12]],"ltp":0.0,"tv":0.0,"id":24707172},{"batb":[[0,8.8,1.98],[1,8.6,1.99],[2,7.6,1.88]],"ltp":0.0,"tv":0.0,"id":24420205}]}]}
{"op":"mcm","clk":"989729920","pt":1580490857670,"mc":[{"id":"1.168130661","rc":[{"batb":[[0,2.7,1.99],[1,2.68,1.98]],"ltp":0.0,"tv":0.0,"id":25238892}]}]}
{"op":"mcm","clk":"989729977","pt":1580490858208,"mc":[{"id":"1.168130661","rc":[{"batb":[[1,7.6,1.88],[2,5.7,1.64]],"ltp":0.0,"tv":0.0,"id":24420205}]}]}
{"op":"mcm","clk":"989734723","pt":1580490901957,"mc":[{"id":"1.168130661","rc":[{"trd":[[3.1,35.9]],"batb":[[0,3,3.54],[1,2.94,2.34],[2,2.06,1.68]],"batl":[[0,3.1,1.02],[1,3.55,1.68],[2,3.6,2.52]],"ltp":3.1,"tv":74.55,"id":26314798}],"tv":74.55}]}
{"op":"mcm","clk":"989735019","pt":1580490904669,"mc":[{"id":"1.168130661","rc":[{"batl":[[0,3.5,18.97]],"ltp":3.1,"tv":74.55,"id":26314798}]}]}
{"op":"mcm","clk":"989735868","pt":1580490911978,"mc":[{"id":"1.168130661","rc":[{"batb":[[0,2.94,2.88],[1,2.88,3]],"ltp":3.1,"tv":74.55,"id":26314798}]}]}
{"op":"mcm","clk":"989736193","pt":1580490914670,"mc":[{"id":"1.168130661","rc":[{"batl":[[0,3.45,10.78],[1,3.5,18.97],[2,3.55,1.68]],"ltp":3.1,"tv":74.55,"id":26314798}]}]}
{"op":"mcm","clk":"989737896","pt":1580490929397,"mc":[{"id":"1.168130661","rc":[{"batb":[[0,12,1.98],[1,11.5,1.68],[2,1.51,4.01]],"ltp":0.0,"tv":0.0,"id":25545675},{"batb":[[0,2.72,1.98],[1,2.7,1.99]],"ltp":0.0,"tv":0.0,"id":25238892},{"batb":[[0,9,1.98],[1,8.8,1.68],[2,7,1.36]],"ltp":0.0,"tv":0.0,"id":24707172},{"batb":[[0,7.8,2.18],[1,7.6,1.68]],"ltp":0.0,"tv":0.0,"id":24420205},{"batb":[[0,2.96,2.52],[1,2.94,2.34],[2,2.88,3]],"ltp":3.1,"tv":74.55,"id":26314798}]}]}
{"op":"mcm","clk":"989739130","pt":1580490940702,"mc":[{"id":"1.168130661","rc":[{"batb":[[0,2.74,1.99],[1,2.72,1.98]],"ltp":0.0,"tv":0.0,"id":25238892},{"batb":[[0,8.6,1.99],[1,7.8,2.18],[2,7.6,1.68]],"ltp":0.0,"tv":0.0,"id":24420205}]}]}
{"op":"mcm","clk":"989739239","pt":1580490941691,"mc":[{"id":"1.168130661","rc":[{"batb":[[0,9.2,1.99],[1,9,1.98],[2,8.8,1.68]],"ltp":0.0,"tv":0.0,"id":24707172}]}]}
{"op":"mcm","clk":"989740108","pt":1580490949526,"mc":[{"id":"1.168130661","rc":[{"batl":[[0,3.4,2],[1,3.45,10.78],[2,3.5,18.97]],"ltp":3.1,"tv":74.55,"id":26314798}]}]}
{"op":"mcm","clk":"989741469","pt":1580490962333,"mc":[{"id":"1.168130661","rc":[{"batb":[[0,11.5,1.68],[1,1.52,2.63],[2,1.51,3.36]],"ltp":0.0,"tv":0.0,"id":25545675},{"batb":[[0,2.76,1.98],[1,2.74,1.99]],"ltp":0.0,"tv":0.0,"id":25238892},{"batb":[[0,9.4,1.98],[1,9.2,1.99]],"ltp":0.0,"tv":0.0,"id":24707172},{"batb":[[0,8.8,1.98],[1,8.6,1.99],[2,7.6,1.88]],"ltp":0.0,"tv":0.0,"id":24420205}]}]}
{"op":"mcm","clk":"989743403","pt":1580490978638,"mc":[{"id":"1.168130661","rc":[{"batb":[[2,2.4,1.68]],"ltp":0.0,"tv":0.0,"id":25238892}]}]}
{"op":"mcm","clk":"989745600","pt":1580490998372,"mc":[{"id":"1.168130661","rc":[{"batb":[[0,12,1.98],[1,11.5,1.68],[2,1.51,4.01]],"ltp":0.0,"tv":0.0,"id":25545675}]}]}
{"op":"mcm","clk":"989747280","pt":1580491013486,"mc":[{"id":"1.168130661","rc":[{"batb":[[0,7.2,4.76]],"ltp":0.0,"tv":0.0,"id":420}]}]}
{"op":"mcm","clk":"989747521","pt":1580491015693,"mc":[{"id":"1.168130661","rc":[{"batb":[[0,2.76,2.58]],"ltp":0.0,"tv":0.0,"id":25238892}]}]}
{"op":"mcm","clk":"989748277","pt":1580491022679,"mc":[{"id":"1.168130661","rc":[{"batb":[[1,2.4,1.68],[2,2.3,3.51]],"ltp":0.0,"tv":0.0,"id":25238892},{"batb":[[1,8.8,1.68],[2,7,1.36]],"ltp":0.0,"tv":0.0,"id":24707172},{"batb":[[1,7.6,1.88],[2,5.7,1.64]],"ltp":0.0,"tv":0.0,"id":24420205}]}]}
{"op":"mcm","clk":"989748373","pt":1580491023477,"mc":[{"id":"1.168130661","rc":[{"batb":[[0,9.6,1.99],[1,9.4,1.98],[2,8.8,1.68]],"ltp":0.0,"tv":0.0,"id":24707172}]}]}
{"op":"mcm","clk":"989749358","pt":1580491032703,"mc":[{"id":"1.168130661","rc":[{"batb":[[0,11.5,1.68],[1,1.52,2.63],[2,1.51,3.36]],"ltp":0.0,"tv":0.0,"id":25545675},{"batb":[[0,2.42,2.58]],"ltp":0.0,"tv":0.0,"id":25238892},{"batb":[[0,9.8,1.98],[1,9.6,1.99]],"ltp":0.0,"tv":0.0,"id":24707172},{"batb":[[0,7.8,2.18],[1,7.6,1.68]],"ltp":0.0,"tv":0.0,"id":24420205}]}]}
{"op":"mcm","clk":"989760357","pt":1580491138308,"mc":[{"id":"1.168130661","rc":[{"batb":[[0,10,1.99],[1,9.8,1.98]],"ltp":0.0,"tv":0.0,"id":24707172},{"batb":[[0,8.6,1.99],[1,7.8,2.18],[2,7.6,1.68]],"ltp":0.0,"tv":0.0,"id":24420205}]}]}
{"op":"mcm","clk":"989763815","pt":1580491169667,"mc":[{"id":"1.168130661","rc":[{"batb":[[0,12,1.98],[1,11.5,1.68],[2,1.51,4.01]],"ltp":0.0,"tv":0.0,"id":25545675},{"batb":[[0,10.5,1.98],[1,10,1.99]],"ltp":0.0,"tv":0.0,"id":24707172},{"batb":[[0,8.8,1.98],[1,8.6,1.99],[2,7.6,1.88]],"ltp":0.0,"tv":0.0,"id":24420205}]}]}
{"op":"mcm","clk":"989764063","pt":1580491172357,"mc":[{"id":"1.168130661","rc":[{"batb":[[2,10,2.48]],"ltp":0.0,"tv":0.0,"id":25545675}]}]}
{"op":"mcm","clk":"989764472","pt":1580491176697,"mc":[{"id":"1.168130661","rc":[{"trd":[[2.76,1.2]],"batb":[[0,2.42,1.98]],"batl":[[0,2.76,1.4],[1,3.4,50],[2,3.55,1.68]],"ltp":2.76,"tv":1.19,"id":25238892}],"tv":75.75}]}
{"op":"mcm","clk":"989765710","pt":1580491189703,"mc":[{"id":"1.168130661","rc":[{"batl":[[1,2.86,2],[2,3.4,50]],"ltp":2.76,"tv":1.19,"id":25238892}]}]}
{"op":"mcm","clk":"989765767","pt":1580491190285,"mc":[{"id":"1.168130661","rc":[{"batb":[[0,2.42,4.98]],"ltp":2.76,"tv":1.19,"id":25238892}]}]}
{"op":"mcm","clk":"989766960","pt":1580491201895,"mc":[{"id":"1.168130661","rc":[{"batb":[[0,2.44,3],[1,2.42,1.98],[2,2.4,1.68]],"ltp":2.76,"tv":1.19,"id":25238892}]}]}
{"op":"mcm","clk":"989768607","pt":1580491217230,"mc":[{"id":"1.168130661","rc":[{"batb":[[0,2.42,4.98],[1,2.4,1.68],[2,2.32,18.97]],"ltp":2.76,"tv":1.19,"id":25238892}]}]}
{"op":"mcm","clk":"989769411","pt":1580491224642,"mc":[{"id":"1.168130661","rc":[{"batl":[[0,980,9],[1,1000,0.22]],"ltp":0.0,"tv":0.0,"id":25545675},{"batl":[[0,980,9],[1,1000,0.22]],"ltp":0.0,"tv":0.0,"id":24707172},{"batl":[[0,980,9],[1,1000,0.21]],"ltp":0.0,"tv":0.0,"id":24420205},{"batl":[[0,980,9],[1,1000,0.21]],"ltp":0.0,"tv":0.0,"id":420}]}]}
{"op":"mcm","clk":"989769861","pt":1580491229655,"mc":[{"id":"1.168130661","rc":[{"batb":[[0,2.42,1.98]],"ltp":2.76,"tv":1.19,"id":25238892}]}]}
{"op":"mcm","clk":"989769960","pt":1580491230649,"mc":[{"id":"1.168130661","rc":[{"batb":[[0,2.44,4.99],[1,2.42,1.98],[2,2.4,1.68]],"ltp":2.76,"tv":1.19,"id":25238892},{"batb":[[1,8.8,1.68],[2,8.6,2.33]],"ltp":0.0,"tv":0.0,"id":24707172},{"batb":[[1,7.6,1.88],[2,5.7,1.64]],"ltp":0.0,"tv":0.0,"id":24420205}]}]}
{"op":"mcm","clk":"989770270","pt":1580491233622,"mc":[{"id":"1.168130661","rc":[{"batl":[[0,980,9.2],[1,1000,0.02]],"ltp":0.0,"tv":0.0,"id":25545675},{"batl":[[0,980,9.2],[1,1000,0.02]],"ltp":0.0,"tv":0.0,"id":24707172},{"batl":[[0,980,9.2],[1,1000,0.01]],"ltp":0.0,"tv":0.0,"id":24420205},{"batl":[[0,980,9.2],[1,1000,0.01]],"ltp":0.0,"tv":0.0,"id":420}]}]}
{"op":"mcm","clk":"989771596","pt":1580491245687,"mc":[{"id":"1.168130661","rc":[{"batb":[[0,2.46,3],[1,2.44,1.99],[2,2.42,1.98]],"ltp":2.76,"tv":1.19,"id":25238892}]}]}
{"op":"mcm","clk":"989772258","pt":1580491251384,"mc":[{"id":"1.168130661","rc":[{"batb":[[0,11.5,1.68],[1,10.5,2.46],[2,10,2]],"ltp":0.0,"tv":0.0,"id":25545675},{"batb":[[0,2.46,4.98],[2,2.4,1.68]],"ltp":2.76,"tv":1.19,"id":25238892},{"batb":[[0,8.8,3.67],[1,8.6,2.33],[2,7,1.36]],"ltp":0.0,"tv":0.0,"id":24707172},{"batb":[[0,7.8,2.18],[1,7.6,1.68]],"ltp":0.0,"tv":0.0,"id":24420205}]}]}
{"op":"mcm","clk":"989772882","pt":1580491256690,"mc":[{"id":"1.168130661","rc":[{"batb":[[0,2.48,3],[1,2.46,1.98],[2,2.44,1.99]],"ltp":2.76,"tv":1.19,"id":25238892}]}]}
{"op":"mcm","clk":"989773244","pt":1580491259511,"mc":[{"id":"1.168130661","rc":[{"batb":[[2,4.5,3.17]],"ltp":0.0,"tv":0.0,"id":25545675},{"batb":[[1,7,1.36],[2,3.95,3]],"ltp":0.0,"tv":0.0,"id":24707172},{"batb":[[2,7.2,2.78]],"ltp":0.0,"tv":0.0,"id":24420205}]}]}
{"op":"mcm","clk":"989774126","pt":1580491267889,"mc":[{"id":"1.168130661","rc":[{"batb":[[0,2.46,4.98],[1,2.44,1.99],[2,2.4,1.68]],"ltp":2.76,"tv":1.19,"id":25238892}]}]}
{"op":"mcm","clk":"989775626","pt":1580491281524,"mc":[{"id":"1.168130661","rc":[{"batb":[[0,2.48,3],[1,2.46,1.98],[2,2.44,1.99]],"ltp":2.76,"tv":1.19,"id":25238892}]}]}
{"op":"mcm","clk":"989776940","pt":1580491292326,"mc":[{"id":"1.168130661","rc":[{"batb":[[0,2.46,4.98],[1,2.44,1.99],[2,2.4,1.68]],"ltp":2.76,"tv":1.19,"id":25238892}]}]}
{"op":"mcm","clk":"989778713","pt":1580491308051,"mc":[{"id":"1.168130661","rc":[{"batb":[[0,2.48,3],[1,2.46,1.98],[2,2.44,1.99]],"ltp":2.76,"tv":1.19,"id":25238892}]}]}
{"op":"mcm","clk":"989779837","pt":1580491318653,"mc":[{"id":"1.168130661","rc":[{"batb":[[0,2.46,1.98],[1,2.44,1.99],[2,2.4,1.68]],"ltp":2.76,"tv":1.19,"id":25238892}]}]}
{"op":"mcm","clk":"989779847","pt":1580491318758,"mc":[{"id":"1.168130661","rc":[{"batb":[[0,2.46,4.98]],"ltp":2.76,"tv":1.19,"id":25238892}]}]}
{"op":"mcm","clk":"989781076","pt":1580491330980,"mc":[{"id":"1.168130661","rc":[{"batb":[[0,2.48,3],[1,2.46,1.98],[2,2.44,1.99]],"ltp":2.76,"tv":1.19,"id":25238892}]}]}
{"op":"mcm","clk":"989782178","pt":1580491342716,"mc":[{"id":"1.168130661","rc":[{"batb":[[0,2.46,4.98],[1,2.44,1.99],[2,2.4,1.68]],"ltp":2.76,"tv":1.19,"id":25238892}]}]}
{"op":"mcm","clk":"989782417","pt":1580491345395,"mc":[{"id":"1.168130661","rc":[{"batb":[[0,8.8,1.68],[1,7.2,2.58],[2,3.95,3.76]],"ltp":0.0,"tv":0.0,"id":24707172}]}]}
{"op":"mcm","clk":"989782961","pt":1580491350711,"mc":[{"id":"1.168130661","rc":[{"batb":[[1,7.2,2.81]],"ltp":0.0,"tv":0.0,"id":24707172}]}]}
{"op":"mcm","clk":"989793164","pt":1580491356318,"mc":[{"id":"1.168130661","rc":[{"batb":[[0,2.48,3],[1,2.46,1.98],[2,2.44,1.99]],"ltp":2.76,"tv":1.19,"id":25238892}]}]}
{"op":"mcm","clk":"989793824","pt":1580491364644,"mc":[{"id":"1.168130661","rc":[{"batb":[[0,2.5,1.99],[1,2.48,3],[2,2.46,1.98]],"ltp":2.76,"tv":1.19,"id":25238892},{"batb":[[0,8.6,1.99],[1,7.8,2.18],[2,7.6,1.68]],"ltp":0.0,"tv":0.0,"id":24420205}]}]}
{"op":"mcm","clk":"989794446","pt":1580491371620,"mc":[{"id":"1.168130661","rc":[{"batb":[[1,2.46,1.98],[2,2.4,1.68]],"ltp":2.76,"tv":1.19,"id":25238892}]}]}
{"op":"mcm","clk":"989794455","pt":1580491371725,"mc":[{"id":"1.168130661","rc":[{"batb":[[0,2.5,4.99]],"ltp":2.76,"tv":1.19,"id":25238892}]}]}
{"op":"mcm","clk":"989795071","pt":1580491378427,"mc":[{"id":"1.168130661","rc":[{"batb":[[2,3.9,90.76]],"ltp":0.0,"tv":0.0,"id":24707172}]}]}
{"op":"mcm","clk":"989795769","pt":1580491385879,"mc":[{"id":"1.168130661","rc":[{"batb":[[0,2.52,3],[1,2.5,1.99],[2,2.46,1.98]],"ltp":2.76,"tv":1.19,"id":25238892}]}]}
{"op":"mcm","clk":"989796866","pt":1580491397955,"mc":[{"id":"1.168130661","rc":[{"batb":[[0,2.5,1.99],[1,2.48,3]],"ltp":2.76,"tv":1.19,"id":25238892}]}]}
{"op":"mcm","clk":"989797919","pt":1580491408666,"mc":[{"id":"1.168130661","rc":[{"batb":[[1,2.46,1.98],[2,2.4,1.68]],"ltp":2.76,"tv":1.19,"id":25238892}]}]}
{"op":"mcm","clk":"989797948","pt":1580491408968,"mc":[{"id":"1.168130661","rc":[{"batb":[[0,2.5,4.99]],"ltp":2.76,"tv":1.19,"id":25238892}]}]}
{"op":"mcm","clk":"989799581","pt":1580491424090,"mc":[{"id":"1.168130661","rc":[{"batb":[[0,2.52,3],[1,2.5,1.99],[2,2.46,1.98]],"ltp":2.76,"tv":1.19,"id":25238892}]}]}
{"op":"mcm","clk":"989800730","pt":1580491435510,"mc":[{"id":"1.168130661","rc":[{"batb":[[0,2.5,1.99],[1,2.48,3]],"ltp":2.76,"tv":1.19,"id":25238892}]}]}
{"op":"mcm","clk":"989801534","pt":1580491443818,"mc":[{"id":"1.168130661","rc":[{"batb":[[0,12,1.98],[1,11.5,1.68],[2,4.5,3.65]],"ltp":0.0,"tv":0.0,"id":25545675},{"batb":[[0,2.5,3.97],[2,2.4,1.68]],"ltp":2.76,"tv":1.19,"id":25238892},{"batb":[[0,9,1.98],[1,8.8,1.68],[2,7,1.58]],"ltp":0.0,"tv":0.0,"id":24707172},{"batb":[[0,8.8,1.98],[1,8.6,1.99],[2,7.6,1.88]],"ltp":0.0,"tv":0.0,"id":24420205}]}]}
{"op":"mcm","clk":"989802009","pt":1580491448632,"mc":[{"id":"1.168130661","rc":[{"batb":[[0,2.52,3],[1,2.5,3.97]],"ltp":2.76,"tv":1.19,"id":25238892}]}]}
{"op":"mcm","clk":"989803182","pt":1580491461435,"mc":[{"id":"1.168130661","rc":[{"batb":[[2,4.4,90.65]],"ltp":0.0,"tv":0.0,"id":25545675}]}]}
{"op":"mcm","clk":"989803537","pt":1580491464826,"mc":[{"id":"1.168130661","rc":[{"batb":[[2,7,1.36]],"ltp":0.0,"tv":0.0,"id":24707172}]}]}
{"op":"mcm","clk":"989807176","pt":1580491501472,"mc":[{"id":"1.168130661","rc":[{"batb":[[0,2.54,1.99],[1,2.52,3],[2,2.5,1.98]],"ltp":2.76,"tv":1.19,"id":25238892}]}]}
{"op":"mcm","clk":"989807294","pt":1580491502487,"mc":[{"id":"1.168130661","rc":[{"batb":[[0,9.2,1.99],[1,9,1.98],[2,8.8,1.68]],"ltp":0.0,"tv":0.0,"id":24707172},{"batb":[[1,7.6,1.88],[2,5.7,1.64]],"ltp":0.0,"tv":0.0,"id":24420205}]}]}
{"op":"mcm","clk":"989808342","pt":1580491511603,"mc":[{"id":"1.168130661","rc":[{"batb":[[0,2.54,4.99],[1,2.5,1.98],[2,2.4,1.68]],"ltp":2.76,"tv":1.19,"id":25238892}]}]}
{"op":"mcm","clk":"989809324","pt":1580491522321,"mc":[{"id":"1.168130661","rc":[{"batb":[[2,10,2.48]],"ltp":0.0,"tv":0.0,"id":25545675},{"batb":[[2,7.2,2.78]],"ltp":0.0,"tv":0.0,"id":24420205}]}]}
{"op":"mcm","clk":"989809699","pt":1580491525719,"mc":[{"id":"1.168130661","rc":[{"batb":[[0,2.56,3],[1,2.54,1.99],[2,2.5,1.98]],"ltp":2.76,"tv":1.19,"id":25238892}]}]}
{"op":"mcm","clk":"989810971","pt":1580491538426,"mc":[{"id":"1.168130661","rc":[{"batb":[[0,11.5,1.68],[1,10.5,2.46],[2,10,2]],"ltp":0.0,"tv":0.0,"id":25545675},{"batb":[[0,2.54,3.97],[1,2.52,3],[2,2.4,1.68]],"ltp":2.76,"tv":1.19,"id":25238892},{"batb":[[0,9.4,1.98],[1,9.2,1.99]],"ltp":0.0,"tv":0.0,"id":24707172},{"batb":[[0,7.8,2.18],[1,7.6,1.68]],"ltp":0.0,"tv":0.0,"id":24420205}]}]}
{"op":"mcm","clk":"989812102","pt":1580491549863,"mc":[{"id":"1.168130661","rc":[{"batb":[[0,2.56,3],[1,2.54,3.97]],"ltp":2.76,"tv":1.19,"id":25238892}]}]}
{"op":"mcm","clk":"989812804","pt":1580491556524,"mc":[{"id":"1.168130661","rc":[{"batb":[[2,4.5,3.17]],"ltp":0.0,"tv":0.0,"id":25545675}]}]}
{"op":"mcm","clk":"989820239","pt":1580491627516,"mc":[{"id":"1.168130661","rc":[{"batb":[[0,2.58,1.99],[1,2.56,3],[2,2.54,1.98]],"ltp":2.76,"tv":1.19,"id":25238892},{"batb":[[0,8.6,1.99],[1,7.8,2.18],[2,7.6,1.68]],"ltp":0.0,"tv":0.0,"id":24420205}]}]}
{"op":"mcm","clk":"989820270","pt":1580491627824,"mc":[{"id":"1.168130661","rc":[{"batb":[[0,9.6,1.99],[1,9.4,1.98]],"ltp":0.0,"tv":0.0,"id":24707172}]}]}
{"op":"mcm","clk":"989820796","pt":1580491632716,"mc":[{"id":"1.168130661","rc":[{"batb":[[0,12,1.98],[1,11.5,1.68],[2,4.5,3.65]],"ltp":0.0,"tv":0.0,"id":25545675},{"batb":[[0,2.58,3.97],[2,2.4,1.68]],"ltp":2.76,"tv":1.19,"id":25238892},{"batb":[[0,9.8,1.98],[1,9.6,1.99]],"ltp":0.0,"tv":0.0,"id":24707172},{"batb":[[0,8.8,1.98],[1,8.6,1.99],[2,7.6,1.88]],"ltp":0.0,"tv":0.0,"id":24420205}]}]}
{"op":"mcm","clk":"989820836","pt":1580491633130,"mc":[{"id":"1.168130661","rc":[{"batb":[[0,2.6,3],[1,2.58,3.97]],"ltp":2.76,"tv":1.19,"id":25238892}]}]}
{"op":"mcm","clk":"989821559","pt":1580491639969,"mc":[{"id":"1.168130661","rc":[{"batb":[[2,10,2.48]],"ltp":0.0,"tv":0.0,"id":25545675}]}]}
{"op":"mcm","clk":"989830185","pt":1580491722537,"mc":[{"id":"1.168130661","rc":[{"trd":[[2.76,4],[2.86,4]],"batb":[[0,2.86,6.6],[1,2.6,3],[2,2.58,3.97]],"batl":[[0,3.4,50],[1,3.55,1.68],[2,3.6,8]],"ltp":2.86,"tv":7.99,"id":25238892}],"tv":82.55}]}
{"op":"mcm","clk":"989830381","pt":1580491724853,"mc":[{"id":"1.168130661","rc":[{"batb":[[1,2.74,3]],"ltp":2.86,"tv":7.99,"id":25238892}]}]}
{"op":"mcm","clk":"989830722","pt":1580491728655,"mc":[{"id":"1.168130661","rc":[{"batb":[[0,11.5,1.68],[1,10.5,2.46],[2,10,2]],"ltp":0.0,"tv":0.0,"id":25545675},{"batb":[[0,2.88,1.98],[1,2.86,6.6],[2,2.74,3]],"ltp":2.86,"tv":7.99,"id":25238892}]}]}
{"op":"mcm","clk":"989830877","pt":1580491730060,"mc":[{"id":"1.168130661","rc":[{"batb":[[1,2.74,3],[2,2.7,6.6]],"ltp":2.86,"tv":7.99,"id":25238892}]}]}
{"op":"mcm","clk":"989831170","pt":1580491732457,"mc":[{"id":"1.168130661","rc":[{"batb":[[0,2.9,1.99],[1,2.88,1.98],[2,2.74,3]],"ltp":2.86,"tv":7.99,"id":25238892},{"batb":[[0,10,1.99],[1,9.8,1.98]],"ltp":0.0,"tv":0.0,"id":24707172},{"batb":[[1,7.6,1.88],[2,5.7,1.64]],"ltp":0.0,"tv":0.0,"id":24420205}]}]}
{"op":"mcm","clk":"989831418","pt":1580491734857,"mc":[{"id":"1.168130661","rc":[{"batb":[[2,2.76,6.6]],"ltp":2.86,"tv":7.99,"id":25238892}]}]}
{"op":"mcm","clk":"989831819","pt":1580491738764,"mc":[{"id":"1.168130661","rc":[{"trd":[[2.9,3.98]],"batb":[[0,2.88,1.98],[1,2.76,6.6],[2,2.74,3]],"batl":[[0,2.9,1.01],[1,3.4,50],[2,3.55,1.68]],"ltp":2.9,"tv":11.97,"id":25238892}],"tv":86.53}]}
{"op":"mcm","clk":"989831969","pt":1580491740274,"mc":[{"id":"1.168130661","rc":[{"trd":[[2.9,6]],"batb":[[0,2.9,5.59],[1,2.88,1.98]],"batl":[[0,3.4,50],[1,3.55,1.68],[2,3.6,8]],"ltp":2.9,"tv":13.99,"id":25238892}],"tv":88.55}]}
{"op":"mcm","clk":"989832587","pt":1580491746645,"mc":[{"id":"1.168130661","rc":[{"batb":[[2,4.4,90.17]],"ltp":0.0,"tv":0.0,"id":25545675}]}]}
{"op":"mcm","clk":"989832951","pt":1580491749681,"mc":[{"id":"1.168130661","rc":[{"batl":[[0,2.96,4],[1,3.4,50],[2,3.55,1.68]],"ltp":2.9,"tv":13.99,"id":25238892}]}]}
{"op":"mcm","clk":"989834427","pt":1580491764186,"mc":[{"id":"1.168130661","rc":[{"trd":[[2.9,10]],"batb":[[0,2.9,3.59]],"ltp":2.9,"tv":17.99,"id":25238892}],"tv":92.55}]}
{"op":"mcm","clk":"989835662","pt":1580491776508,"mc":[{"id":"1.168130661","rc":[{"batl":[[1,3,4],[2,3.4,50]],"ltp":2.9,"tv":17.99,"id":25238892}]}]}
{"op":"mcm","clk":"989838386","pt":1580491801714,"mc":[{"id":"1.168130661","rc":[{"trd":[[2.9,17.18]],"batb":[[0,2.88,1.98],[1,2.74,3],[2,2.4,1.68]],"ltp":2.9,"tv":25.17,"id":25238892}],"tv":99.73}]}
{"op":"mcm","clk":"989838614","pt":1580491803442,"mc":[{"id":"1.168130661","rc":[{"batb":[[2,4.5,3.17]],"ltp":0.0,"tv":0.0,"id":25545675},{"batb":[[2,7.2,2.78]],"ltp":0.0,"tv":0.0,"id":24420205}]}]}
{"op":"mcm","clk":"989839851","pt":1580491814150,"mc":[{"id":"1.168130661","rc":[{"batl":[[2,3.1,6]],"ltp":2.9,"tv":25.17,"id":25238892}]}]}
{"op":"mcm","clk":"989840718","pt":1580491819632,"mc":[{"id":"1.168130661","rc":[{"batb":[[0,12,1.98],[1,11.5,1.68],[2,4.5,3.65]],"ltp":0.0,"tv":0.0,"id":25545675},{"batb":[[0,2.76,1.98]],"ltp":2.9,"tv":25.17,"id":25238892},{"batb":[[0,10.5,1.98],[1,10,1.99]],"ltp":0.0,"tv":0.0,"id":24707172},{"batb":[[0,7.8,2.18],[1,7.6,1.68]],"ltp":0.0,"tv":0.0,"id":24420205}]}]}
{"op":"mcm","clk":"989841506","pt":1580491825633,"mc":[{"id":"1.168130661","rc":[{"batb":[[2,4.4,90.65]],"ltp":0.0,"tv":0.0,"id":25545675}]}]}
{"op":"mcm","clk":"989841520","pt":1580491825744,"mc":[{"id":"1.168130661","rc":[{"batb":[[2,10,2.48]],"ltp":0.0,"tv":0.0,"id":25545675}]}]}
{"op":"mcm","clk":"989843059","pt":1580491836673,"mc":[{"id":"1.168130661","rc":[{"batb":[[1,8.8,1.68],[2,8.6,2.33]],"ltp":0.0,"tv":0.0,"id":24707172},{"batb":[[0,8.6,1.99],[1,7.8,2.18],[2,7.6,1.68]],"ltp":0.0,"tv":0.0,"id":24420205}]}]}
{"op":"mcm","clk":"989845247","pt":1580491853880,"mc":[{"id":"1.168130661","rc":[{"batb":[[2,7.2,3.38]],"ltp":0.0,"tv":0.0,"id":24707172}]}]}
{"op":"mcm","clk":"989853154","pt":1580491913667,"mc":[{"id":"1.168130661","rc":[{"batb":[[0,11.5,1.68],[1,10.5,2.46],[2,10,2]],"ltp":0.0,"tv":0.0,"id":25545675},{"batb":[[0,8.8,1.68],[1,7.4,2.58],[2,7.2,2.78]],"ltp":0.0,"tv":0.0,"id":24707172},{"batb":[[0,8.8,1.98],[1,8.6,1.99],[2,7.6,1.88]],"ltp":0.0,"tv":0.0,"id":24420205}]}]}
{"op":"mcm","clk":"989853196","pt":1580491913986,"mc":[{"id":"1.168130661","rc":[{"batb":[[1,2.74,15]],"ltp":2.9,"tv":25.17,"id":25238892}]}]}
{"op":"mcm","clk":"989854251","pt":1580491920649,"mc":[{"id":"1.168130661","rc":[{"batb":[[2,4.5,3.17]],"ltp":0.0,"tv":0.0,"id":25545675}]}]}
{"op":"mcm","clk":"989855583","pt":1580491930401,"mc":[{"id":"1.168130661","rc":[{"batb":[[1,7.6,1.88],[2,5.7,1.64]],"ltp":0.0,"tv":0.0,"id":24420205}]}]}
{"op":"mcm","clk":"989858218","pt":1580491948692,"mc":[{"id":"1.168130661","rc":[{"batb":[[2,7.2,2.78]],"ltp":0.0,"tv":0.0,"id":24420205}]}]}
{"op":"mcm","clk":"989859244","pt":1580491957111,"mc":[{"id":"1.168130661","rc":[{"batb":[[2,2.42,18.97]],"ltp":2.9,"tv":25.17,"id":25238892}]}]}
{"op":"mcm","clk":"989864860","pt":1580492005344,"mc":[{"id":"1.168130661","rc":[{"batb":[[0,12,1.98],[1,11.5,1.68],[2,4.5,3.65]],"ltp":0.0,"tv":0.0,"id":25545675},{"batb":[[0,9,1.98],[1,8.8,1.68],[2,7.2,3.38]],"ltp":0.0,"tv":0.0,"id":24707172},{"batb":[[0,7.8,2.18],[1,7.6,1.68]],"ltp":0.0,"tv":0.0,"id":24420205}]}]}
{"op":"mcm","clk":"989867093","pt":1580492021660,"mc":[{"id":"1.168130661","rc":[{"batb":[[2,10,2.48]],"ltp":0.0,"tv":0.0,"id":25545675}]}]}
{"op":"mcm","clk":"989867832","pt":1580492026393,"mc":[{"id":"1.168130661","rc":[{"batb":[[0,9.2,1.99],[1,9,1.98],[2,8.8,1.68]],"ltp":0.0,"tv":0.0,"id":24707172},{"batb":[[0,8.6,1.99],[1,7.8,2.18],[2,7.6,1.68]],"ltp":0.0,"tv":0.0,"id":24420205}]}]}
{"op":"mcm","clk":"989877377","pt":1580492098561,"mc":[{"id":"1.168130661","rc":[{"batb":[[0,11.5,1.68],[1,10.5,2.46],[2,10,2]],"ltp":0.0,"tv":0.0,"id":25545675},{"batb":[[0,9.4,1.98],[1,9.2,1.99]],"ltp":0.0,"tv":0.0,"id":24707172},{"batb":[[0,8.8,1.98],[1,8.6,1.99],[2,7.6,1.88]],"ltp":0.0,"tv":0.0,"id":24420205}]}]}
{"op":"mcm","clk":"989878253","pt":1580492105272,"mc":[{"id":"1.168130661","rc":[{"batb":[[2,4.5,3.17]],"ltp":0.0,"tv":0.0,"id":25545675}]}]}
{"op":"mcm","clk":"989881276","pt":1580492129587,"mc":[{"id":"1.168130661","rc":[{"batb":[[0,9.6,1.99],[1,9.4,1.98]],"ltp":0.0,"tv":0.0,"id":24707172},{"batb":[[1,7.6,1.88],[2,5.7,1.64]],"ltp":0.0,"tv":0.0,"id":24420205}]}]}
{"op":"mcm","clk":"989881779","pt":1580492133305,"mc":[{"id":"1.168130661","rc":[{"batb":[[2,7.2,2.78]],"ltp":0.0,"tv":0.0,"id":24420205}]}]}
{"op":"mcm","clk":"989883567","pt":1580492147029,"mc":[{"id":"1.168130661","rc":[{"batl":[[0,11,4],[1,980,9.2],[2,1000,0.01]],"ltp":0.0,"tv":0.0,"id":420}]}]}
{"op":"mcm","clk":"989884117","pt":1580492151038,"mc":[{"id":"1.168130661","rc":[{"batl":[[1,21,9],[2,1000,0.21]],"ltp":0.0,"tv":0.0,"id":420}]}]}
{"op":"mcm","clk":"989889679","pt":1580492192080,"mc":[{"id":"1.168130661","rc":[{"batb":[[0,12,1.98],[1,11.5,1.68],[2,4.5,3.65]],"ltp":0.0,"tv":0.0,"id":25545675},{"batb":[[0,9.8,1.98],[1,9.6,1.99]],"ltp":0.0,"tv":0.0,"id":24707172},{"batb":[[0,7.8,2.18],[1,7.6,1.68]],"ltp":0.0,"tv":0.0,"id":24420205}]}]}
{"op":"mcm","clk":"989891389","pt":1580492206089,"mc":[{"id":"1.168130661","rc":[{"batb":[[2,10,2.48]],"ltp":0.0,"tv":0.0,"id":25545675}]}]}
{"op":"mcm","clk":"989894755","pt":1580492234715,"mc":[{"id":"1.168130661","rc":[{"batb":[[0,8.6,1.99],[1,7.8,2.18],[2,7.6,1.68]],"ltp":0.0,"tv":0.0,"id":24420205}]}]}
{"op":"mcm","clk":"989894789","pt":1580492235040,"mc":[{"id":"1.168130661","rc":[{"batb":[[0,10,1.99],[1,9.8,1.98]],"ltp":0.0,"tv":0.0,"id":24707172}]}]}
{"op":"mcm","clk":"989910521","pt":1580492286682,"mc":[{"id":"1.168130661","rc":[{"batb":[[0,11.5,1.68],[1,10,2.48],[2,4.4,90.17]],"ltp":0.0,"tv":0.0,"id":25545675},{"batb":[[1,8.8,1.68],[2,8.6,2.33]],"ltp":0.0,"tv":0.0,"id":24707172},{"batb":[[1,7.6,1.88],[2,5.7,1.64]],"ltp":0.0,"tv":0.0,"id":24420205}]}]}
{"op":"mcm","clk":"989910644","pt":1580492287686,"mc":[{"id":"1.168130661","rc":[{"batb":[[1,10.5,2.46],[2,10,2]],"ltp":0.0,"tv":0.0,"id":25545675},{"batb":[[0,10.5,1.98],[1,10,1.99],[2,8.8,1.68]],"ltp":0.0,"tv":0.0,"id":24707172},{"batb":[[0,8.8,1.98],[1,8.6,1.99],[2,7.6,1.88]],"ltp":0.0,"tv":0.0,"id":24420205}]}]}
{"op":"mcm","clk":"989912658","pt":1580492305706,"mc":[{"id":"1.168130661","rc":[{"batb":[[2,4.5,3.17]],"ltp":0.0,"tv":0.0,"id":25545675}]}]}
{"op":"mcm","clk":"989917561","pt":1580492350151,"mc":[{"id":"1.168130661","rc":[{"batb":[[1,8.8,1.68],[2,8.6,2.33]],"ltp":0.0,"tv":0.0,"id":24707172},{"batb":[[1,7.6,1.88],[2,5.7,1.64]],"ltp":0.0,"tv":0.0,"id":24420205}]}]}
{"op":"mcm","clk":"989918716","pt":1580492361670,"mc":[{"id":"1.168130661","rc":[{"batb":[[2,7,1.36]],"ltp":0.0,"tv":0.0,"id":24707172}]}]}
{"op":"mcm","clk":"989918723","pt":1580492361732,"mc":[{"id":"1.168130661","rc":[{"batb":[[2,7.2,3.38]],"ltp":0.0,"tv":0.0,"id":24707172},{"batb":[[2,7.2,2.78]],"ltp":0.0,"tv":0.0,"id":24420205}]}]}
{"op":"mcm","clk":"989920475","pt":1580492380171,"mc":[{"id":"1.168130661","rc":[{"batb":[[0,12,1.98],[1,11.5,1.68],[2,4.5,3.65]],"ltp":0.0,"tv":0.0,"id":25545675},{"batb":[[0,8.8,1.68],[1,7.4,2.58],[2,7.2,2.78]],"ltp":0.0,"tv":0.0,"id":24707172},{"batb":[[0,7.8,2.18],[1,7.6,1.68]],"ltp":0.0,"tv":0.0,"id":24420205}]}]}
{"op":"mcm","clk":"989921373","pt":1580492389683,"mc":[{"id":"1.168130661","rc":[{"batb":[[2,10,2.48]],"ltp":0.0,"tv":0.0,"id":25545675}]}]}
{"op":"mcm","clk":"989926282","pt":1580492437716,"mc":[{"id":"1.168130661","rc":[{"batb":[[0,8.6,1.99],[1,7.8,2.18],[2,7.6,1.68]],"ltp":0.0,"tv":0.0,"id":24420205}]}]}
{"op":"mcm","clk":"989941792","pt":1580492593237,"mc":[{"id":"1.168130661","rc":[{"batl":[[0,11,4.2],[2,1000,0.01]],"ltp":0.0,"tv":0.0,"id":420}]}]}
{"op":"mcm","clk":"989943802","pt":1580492614212,"mc":[{"id":"1.168130661","rc":[{"batb":[[0,11.5,1.68],[1,10.5,2.46],[2,10,2]],"ltp":0.0,"tv":0.0,"id":25545675},{"batb":[[0,9,1.98],[1,8.8,1.68],[2,7.2,3.38]],"ltp":0.0,"tv":0.0,"id":24707172},{"batb":[[0,8.8,1.98],[1,8.6,1.99],[2,7.6,1.88]],"ltp":0.0,"tv":0.0,"id":24420205}]}]}
{"op":"mcm","clk":"989945378","pt":1580492630661,"mc":[{"id":"1.168130661","rc":[{"batb":[[1,7.6,1.88],[2,5.7,1.64]],"ltp":0.0,"tv":0.0,"id":24420205}]}]}
{"op":"mcm","clk":"989945454","pt":1580492631343,"mc":[{"id":"1.168130661","rc":[{"batb":[[2,4.4,90.17]],"ltp":0.0,"tv":0.0,"id":25545675},{"batb":[[0,9.2,1.99],[1,9,1.98],[2,8.8,1.68]],"ltp":0.0,"tv":0.0,"id":24707172}]}]}
{"op":"mcm","clk":"989958861","pt":1580492759325,"mc":[{"id":"1.168130661","rc":[{"batb":[[0,12,1.98],[1,11.5,1.68],[2,4.4,90.65]],"ltp":0.0,"tv":0.0,"id":25545675},{"batb":[[0,9.4,1.98],[1,9.2,1.99]],"ltp":0.0,"tv":0.0,"id":24707172},{"batb":[[0,7.8,2.18],[1,7.6,1.68]],"ltp":0.0,"tv":0.0,"id":24420205}]}]}
{"op":"mcm","clk":"989966401","pt":1580492826185,"mc":[{"id":"1.168130661","rc":[{"batb":[[2,10,2.48]],"ltp":0.0,"tv":0.0,"id":25545675},{"batb":[[2,7.2,2.78]],"ltp":0.0,"tv":0.0,"id":24420205}]}]}
{"op":"mcm","clk":"989966896","pt":1580492830363,"mc":[{"id":"1.168130661","rc":[{"batb":[[0,8.6,1.99],[1,7.8,2.18],[2,7.6,1.68]],"ltp":0.0,"tv":0.0,"id":24420205}]}]}
{"op":"mcm","clk":"989966954","pt":1580492830844,"mc":[{"id":"1.168130661","rc":[{"batb":[[0,9.6,1.99],[1,9.4,1.98]],"ltp":0.0,"tv":0.0,"id":24707172}]}]}
{"op":"mcm","clk":"989973519","pt":1580492899605,"mc":[{"id":"1.168130661","rc":[{"batb":[[0,11.5,1.68],[1,10.5,2.46],[2,10,2]],"ltp":0.0,"tv":0.0,"id":25545675},{"batb":[[0,9.8,1.98],[1,9.6,1.99]],"ltp":0.0,"tv":0.0,"id":24707172},{"batb":[[0,8.8,1.98],[1,8.6,1.99],[2,7.6,1.88]],"ltp":0.0,"tv":0.0,"id":24420205}]}]}
{"op":"mcm","clk":"989975542","pt":1580492920848,"mc":[{"id":"1.168130661","rc":[{"batb":[[2,4.5,3.17]],"ltp":0.0,"tv":0.0,"id":25545675}]}]}
{"op":"mcm","clk":"989976115","pt":1580492927630,"mc":[{"id":"1.168130661","rc":[{"batb":[[1,8.8,1.68],[2,8.6,2.33]],"ltp":0.0,"tv":0.0,"id":24707172},{"batb":[[1,7.6,1.88],[2,5.7,1.64]],"ltp":0.0,"tv":0.0,"id":24420205}]}]}
{"op":"mcm","clk":"989976120","pt":1580492927734,"mc":[{"id":"1.168130661","rc":[{"batb":[[0,10,1.99],[1,9.8,1.98],[2,8.8,1.68]],"ltp":0.0,"tv":0.0,"id":24707172}]}]}
{"op":"mcm","clk":"989977705","pt":1580492943450,"mc":[{"id":"1.168130661","rc":[{"batb":[[2,7.2,2.78]],"ltp":0.0,"tv":0.0,"id":24420205}]}]}
{"op":"mcm","clk":"989979997","pt":1580492966958,"mc":[{"id":"1.168130661","rc":[{"trd":[[2.76,7.96]],"batb":[[0,2.74,15],[1,2.42,18.97],[2,2.4,1.68]],"batl":[[0,2.96,4.02]],"ltp":2.76,"tv":29.14,"id":25238892}],"tv":103.69}]}
{"op":"mcm","clk":"989981006","pt":1580492975982,"mc":[{"id":"1.168130661","rc":[{"batl":[[0,2.78,2.02],[1,2.96,4],[2,3,4]],"ltp":2.76,"tv":29.14,"id":25238892}]}]}
{"op":"mcm","clk":"989981270","pt":1580492978402,"mc":[{"id":"1.168130661","rc":[{"batb":[[0,2.74,12],[1,2.62,3],[2,2.42,18.97]],"ltp":2.76,"tv":29.14,"id":25238892}]}]}
{"op":"mcm","clk":"989982743","pt":1580492993393,"mc":[{"id":"1.168130661","rc":[{"batl":[[1,2.84,2],[2,2.96,4]],"ltp":2.76,"tv":29.14,"id":25238892}]}]}
{"op":"mcm","clk":"989987174","pt":1580493037122,"mc":[{"id":"1.168130661","rc":[{"batb":[[0,9.8,1.98],[1,8.8,1.68],[2,8.6,2.33]],"ltp":0.0,"tv":0.0,"id":24707172}]}]}
{"op":"mcm","clk":"989987341","pt":1580493038538,"mc":[{"id":"1.168130661","rc":[{"batb":[[2,7.2,3.38]],"ltp":0.0,"tv":0.0,"id":24707172}]}]}
{"op":"mcm","clk":"989988217","pt":1580493045459,"mc":[{"id":"1.168130661","rc":[{"batb":[[0,12,1.98],[1,11.5,1.68],[2,4.5,3.65]],"ltp":0.0,"tv":0.0,"id":25545675},{"batb":[[0,2.74,17.06]],"ltp":2.76,"tv":29.14,"id":25238892},{"batb":[[0,8.8,1.68],[1,7.4,2.58],[2,7.2,2.78]],"ltp":0.0,"tv":0.0,"id":24707172},{"batb":[[0,7.8,2.18],[1,7.6,1.68]],"ltp":0.0,"tv":0.0,"id":24420205}]}]}
{"op":"mcm","clk":"989990262","pt":1580493062156,"mc":[{"id":"1.168130661","rc":[{"batl":[[2,2.94,2]],"ltp":2.76,"tv":29.14,"id":25238892}]}]}
{"op":"mcm","clk":"989990728","pt":1580493066683,"mc":[{"id":"1.168130661","rc":[{"batb":[[2,10,2.48]],"ltp":0.0,"tv":0.0,"id":25545675}]}]}
{"op":"mcm","clk":"989998211","pt":1580493141933,"mc":[{"id":"1.168130661","rc":[{"batb":[[0,8.6,1.99],[1,7.8,2.18],[2,7.6,1.68]],"ltp":0.0,"tv":0.0,"id":24420205}]}]}
{"op":"mcm","clk":"989998836","pt":1580493149670,"mc":[{"id":"1.168130661","rc":[{"batb":[[0,2.74,5.06]],"ltp":2.76,"tv":29.14,"id":25238892}]}]}
{"op":"mcm","clk":"990010273","pt":1580493168888,"mc":[{"id":"1.168130661","rc":[{"batl":[[0,2.78,2]],"ltp":2.76,"tv":29.14,"id":25238892}]}]}
{"op":"mcm","clk":"990010444","pt":1580493170778,"mc":[{"id":"1.168130661","rc":[{"batl":[[0,2.84,2],[1,2.94,2],[2,2.96,4]],"ltp":2.76,"tv":29.14,"id":25238892}]}]}
{"op":"mcm","clk":"990010628","pt":1580493173004,"mc":[{"id":"1.168130661","rc":[{"batl":[[0,2.94,2],[1,2.96,4],[2,3,4]],"ltp":2.76,"tv":29.14,"id":25238892}]}]}
{"op":"mcm","clk":"990011327","pt":1580493181178,"mc":[{"id":"1.168130661","rc":[{"batl":[[0,3.4,50],[1,3.55,1.68],[2,3.6,8]],"ltp":2.76,"tv":29.14,"id":25238892}]}]}
{"op":"mcm","clk":"990011520","pt":1580493183597,"mc":[{"id":"1.168130661","rc":[{"batb":[[0,11.5,1.68],[1,10.5,2.46],[2,10,2]],"ltp":0.0,"tv":0.0,"id":25545675},{"batb":[[0,2.64,5.06]],"ltp":2.76,"tv":29.14,"id":25238892},{"batb":[[0,9,1.98],[1,8.8,1.68],[2,7.2,3.38]],"ltp":0.0,"tv":0.0,"id":24707172},{"batb":[[0,8.8,1.98],[1,8.6,1.99],[2,7.6,1.88]],"ltp":0.0,"tv":0.0,"id":24420205}]}]}
{"op":"mcm","clk":"990012019","pt":1580493188720,"mc":[{"id":"1.168130661","rc":[{"batb":[[2,4.4,90.17]],"ltp":0.0,"tv":0.0,"id":25545675}]}]}
{"op":"mcm","clk":"990012040","pt":1580493188892,"mc":[{"id":"1.168130661","rc":[{"batb":[[2,4.5,3.17]],"ltp":0.0,"tv":0.0,"id":25545675}]}]}
{"op":"mcm","clk":"990012400","pt":1580493192624,"mc":[{"id":"1.168130661","rc":[{"batb":[[0,2.66,1.68],[1,2.64,5.06],[2,2.62,3]],"ltp":2.76,"tv":29.14,"id":25238892},{"batl":[[0,970,1.88],[1,980,9]],"ltp":0.0,"tv":0.0,"id":24420205},{"batl":[[0,3.35,1.68],[1,3.4,2],[2,3.45,10.78]],"ltp":3.1,"tv":74.55,"id":26314798},{"batl":[[0,10.5,1.88],[1,11,4],[2,21,9]],"ltp":0.0,"tv":0.0,"id":420}]}]}
{"op":"mcm","clk":"990012502","pt":1580493193616,"mc":[{"id":"1.168130661","rc":[{"batb":[[0,11,1.68]],"batl":[[0,970,1.88],[1,980,9]],"ltp":0.0,"tv":0.0,"id":25545675},{"batb":[[0,9.2,1.68],[1,9,1.98]],"batl":[[0,970,1.88],[1,980,9]],"ltp":0.0,"tv":0.0,"id":24707172}]}]}
{"op":"mcm","clk":"990012757","pt":1580493196225,"mc":[{"id":"1.168130661","rc":[{"batb":[[0,2.66,9.2]],"ltp":2.76,"tv":29.14,"id":25238892},{"batl":[[0,3.3,2],[1,3.35,1.68]],"ltp":3.1,"tv":74.55,"id":26314798}]}]}
{"op":"mcm","clk":"990013179","pt":1580493200610,"mc":[{"id":"1.168130661","rc":[{"batl":[[0,3.3,13.27],[2,3.5,18.97]],"ltp":3.1,"tv":74.55,"id":26314798}]}]}
{"op":"mcm","clk":"990013227","pt":1580493201229,"mc":[{"id":"1.168130661","rc":[{"batb":[[0,2.68,2.71],[1,2.66,9.2],[2,2.64,5.06]],"ltp":2.76,"tv":29.14,"id":25238892}]}]}
{"op":"mcm","clk":"990013283","pt":1580493201910,"mc":[{"id":"1.168130661","rc":[{"trd":[[2.86,10]],"ltp":2.86,"tv":35.14,"id":25238892}],"tv":109.69}]}
{"op":"mcm","clk":"990014461","pt":1580493213941,"mc":[{"id":"1.168130661","rc":[{"batb":[[0,2.7,3],[1,2.68,2.71],[2,2.66,9.2]],"ltp":2.86,"tv":35.14,"id":25238892}]}]}
{"op":"mcm","clk":"990014695","pt":1580493216432,"mc":[{"id":"1.168130661","rc":[{"trd":[[2.88,6]],"ltp":2.88,"tv":41.14,"id":25238892}],"tv":115.69}]}
{"op":"mcm","clk":"990015901","pt":1580493229053,"mc":[{"id":"1.168130661","rc":[{"batl":[[0,2.96,4],[1,3.4,50],[2,3.55,1.68]],"ltp":2.88,"tv":41.14,"id":25238892}]}]}
{"op":"mcm","clk":"990018902","pt":1580493260568,"mc":[{"id":"1.168130661","rc":[{"batb":[[2,2.66,1.68]],"batl":[[0,2.94,2],[1,2.96,4],[2,3.4,50]],"ltp":2.88,"tv":41.14,"id":25238892}]}]}
{"op":"mcm","clk":"990019750","pt":1580493270680,"mc":[{"id":"1.168130661","rc":[{"batl":[[0,2.94,4]],"ltp":2.88,"tv":41.14,"id":25238892}]}]}
{"op":"mcm","clk":"990019984","pt":1580493273294,"mc":[{"id":"1.168130661","rc":[{"batb":[[1,7.6,1.88],[2,5.7,1.64]],"ltp":0.0,"tv":0.0,"id":24420205}]}]}
{"op":"mcm","clk":"990020071","pt":1580493274075,"mc":[{"id":"1.168130661","rc":[{"batb":[[0,9.4,1.99],[1,9.2,1.68],[2,9,1.98]],"ltp":0.0,"tv":0.0,"id":24707172}]}]}
{"op":"mcm","clk":"990022643","pt":1580493303633,"mc":[{"id":"1.168130661","rc":[{"batb":[[0,2.72,1.68],[1,2.7,3],[2,2.68,2.71]],"ltp":2.88,"tv":41.14,"id":25238892},{"batb":[[1,9,1.98],[2,7.2,3.38]],"ltp":0.0,"tv":0.0,"id":24707172},{"batl":[[0,3.25,1.68],[1,3.3,13.27]],"ltp":3.1,"tv":74.55,"id":26314798}]}]}
{"op":"mcm","clk":"990022681","pt":1580493304049,"mc":[{"id":"1.168130661","rc":[{"batb":[[0,9.6,1.68],[1,9.4,1.99],[2,9,1.98]],"ltp":0.0,"tv":0.0,"id":24707172}]}]}
{"op":"mcm","clk":"990022733","pt":1580493304728,"mc":[{"id":"1.168130661","rc":[{"batl":[[0,2.88,2],[1,2.94,4],[2,2.96,4]],"ltp":2.88,"tv":41.14,"id":25238892}]}]}
{"op":"mcm","clk":"990022882","pt":1580493306345,"mc":[{"id":"1.168130661","rc":[{"batb":[[0,2.72,4.68],[1,2.68,2.71],[2,2.64,5.06]],"ltp":2.88,"tv":41.14,"id":25238892},{"batb":[[2,7.2,2.78]],"ltp":0.0,"tv":0.0,"id":24420205}]}]}
{"op":"mcm","clk":"990024142","pt":1580493320954,"mc":[{"id":"1.168130661","rc":[{"trd":[[2.74,4]],"batb":[[0,2.74,1],[1,2.72,1.68],[2,2.68,2.71]],"ltp":2.74,"tv":45.14,"id":25238892}],"tv":119.69}]}
{"op":"mcm","clk":"990024409","pt":1580493324236,"mc":[{"id":"1.168130661","rc":[{"batb":[[0,11.5,1.98],[1,11,1.68],[2,4.5,3.65]],"ltp":0.0,"tv":0.0,"id":25545675},{"batb":[[1,2.72,6.74]],"ltp":2.74,"tv":45.14,"id":25238892},{"batb":[[0,9.8,1.98],[1,9.6,1.68],[2,9.4,1.99]],"ltp":0.0,"tv":0.0,"id":24707172},{"batb":[[0,7.8,2.18],[1,7.6,1.68]],"ltp":0.0,"tv":0.0,"id":24420205}]}]}
{"op":"mcm","clk":"990025088","pt":1580493332474,"mc":[{"id":"1.168130661","rc":[{"batl":[[0,2.86,2],[1,2.88,2],[2,2.94,2]],"ltp":2.74,"tv":45.14,"id":25238892},{"batl":[[0,3.2,2],[1,3.25,1.68],[2,3.3,11.27]],"ltp":3.1,"tv":74.55,"id":26314798}]}]}
{"op":"mcm","clk":"990025727","pt":1580493339074,"mc":[{"id":"1.168130661","rc":[{"batl":[[0,3.2,13.62],[2,3.5,18.97]],"ltp":3.1,"tv":74.55,"id":26314798}]}]}
{"op":"mcm","clk":"990025830","pt":1580493340278,"mc":[{"id":"1.168130661","rc":[{"batb":[[0,2.72,6.74],[1,2.68,2.71],[2,2.62,1]],"ltp":2.74,"tv":45.14,"id":25238892}]}]}
{"op":"mcm","clk":"990026566","pt":1580493348075,"mc":[{"id":"1.168130661","rc":[{"batl":[[2,2.9,3]],"ltp":2.74,"tv":45.14,"id":25238892}]}]}
{"op":"mcm","clk":"990027704","pt":1580493360598,"mc":[{"id":"1.168130661","rc":[{"batb":[[1,4.5,3.65],[2,4.4,90]],"ltp":0.0,"tv":0.0,"id":25545675},{"batb":[[0,10,1.68],[1,9.8,1.98]],"ltp":0.0,"tv":0.0,"id":24707172},{"batb":[[0,8,1.88],[1,7.8,1.98]],"ltp":0.0,"tv":0.0,"id":24420205},{"batl":[[0,3.15,1.68],[1,3.2,13.62]],"ltp":3.1,"tv":74.55,"id":26314798}]}]}
{"op":"mcm","clk":"990027798","pt":1580493361698,"mc":[{"id":"1.168130661","rc":[{"batb":[[0,12,1.68],[1,11.5,1.98],[2,4.5,3.65]],"ltp":0.0,"tv":0.0,"id":25545675}]}]}
{"op":"mcm","clk":"990029172","pt":1580493379506,"mc":[{"id":"1.168130661","rc":[{"batb":[[2,4.4,90.65]],"ltp":0.0,"tv":0.0,"id":25545675}]}]}
{"op":"mcm","clk":"990031016","pt":1580493402855,"mc":[{"id":"1.168130661","rc":[{"batl":[[1,3.2,11.62]],"ltp":3.1,"tv":74.55,"id":26314798}]}]}
{"op":"mcm","clk":"990031185","pt":1580493405033,"mc":[{"id":"1.168130661","rc":[{"batb":[[0,12,5.11]],"ltp":0.0,"tv":0.0,"id":25545675}]}]}
{"op":"mcm","clk":"990031670","pt":1580493411632,"mc":[{"id":"1.168130661","rc":[{"batb":[[2,8.6,2.33]],"ltp":0.0,"tv":0.0,"id":24707172},{"batb":[[0,8.6,1.99],[1,8,1.88],[2,7.8,1.98]],"ltp":0.0,"tv":0.0,"id":24420205}]}]}
{"op":"mcm","clk":"990033409","pt":1580493434260,"mc":[{"id":"1.168130661","rc":[{"batb":[[2,7,1.36]],"ltp":0.0,"tv":0.0,"id":24707172}]}]}
{"op":"mcm","clk":"990034254","pt":1580493444586,"mc":[{"id":"1.168130661","rc":[{"batb":[[0,10,6.13]],"ltp":0.0,"tv":0.0,"id":24707172}]}]}
{"op":"mcm","clk":"990036126","pt":1580493466112,"mc":[{"id":"1.168130661","rc":[{"batb":[[0,12.5,1.98],[1,12,5.11]],"ltp":0.0,"tv":0.0,"id":25545675},{"batb":[[0,10.5,1.98],[1,10,6.13]],"ltp":0.0,"tv":0.0,"id":24707172},{"batb":[[0,8.8,1.98],[1,8.6,1.99],[2,8,1.88]],"ltp":0.0,"tv":0.0,"id":24420205}]}]}
{"op":"mcm","clk":"990037720","pt":1580493485705,"mc":[{"id":"1.168130661","rc":[{"batb":[[0,2.74,19],[1,2.72,6.74],[2,2.68,2.71]],"ltp":2.74,"tv":45.14,"id":25238892}]}]}
{"op":"mcm","clk":"990037862","pt":1580493487520,"mc":[{"id":"1.168130661","rc":[{"batb":[[0,13,1.77],[1,12.5,1.98]],"ltp":0.0,"tv":0.0,"id":25545675},{"batb":[[0,2.76,1.68],[1,2.74,19],[2,2.72,5.06]],"ltp":2.74,"tv":45.14,"id":25238892},{"batb":[[0,11,2.03],[1,10.5,1.98]],"ltp":0.0,"tv":0.0,"id":24707172}]}]}
{"op":"mcm","clk":"990039281","pt":1580493504408,"mc":[{"id":"1.168130661","rc":[{"trd":[[8.6,3.98],[8.8,3.96]],"batb":[[0,8,1.88],[1,5.7,1.64],[2,3.4,90]],"batl":[[0,8.6,1.03],[1,970,1.88],[2,980,9]],"ltp":8.6,"tv":7.94,"id":24420205}],"tv":127.64}]}
{"op":"mcm","clk":"990039319","pt":1580493504922,"mc":[{"id":"1.168130661","rc":[{"batl":[[1,970,1.68]],"ltp":8.6,"tv":7.94,"id":24420205}]}]}
{"op":"mcm","clk":"990039808","pt":1580493511326,"mc":[{"id":"1.168130661","rc":[{"batl":[[1,950,9],[2,970,1.68]],"ltp":8.6,"tv":7.94,"id":24420205}]}]}
{"op":"mcm","clk":"990040534","pt":1580493521524,"mc":[{"id":"1.168130661","rc":[{"batb":[[1,7.2,3],[2,5.7,1.64]],"ltp":8.6,"tv":7.94,"id":24420205}]}]}
{"op":"mcm","clk":"990041105","pt":1580493528645,"mc":[{"id":"1.168130661","rc":[{"batb":[[0,2.76,4.01]],"ltp":2.74,"tv":45.14,"id":25238892},{"batb":[[0,7.2,3.2],[1,5.7,1.64],[2,3.4,90]],"ltp":8.6,"tv":7.94,"id":24420205}]}]}
{"op":"mcm","clk":"990041177","pt":1580493529543,"mc":[{"id":"1.168130661","rc":[{"batb":[[0,13,4.72]],"ltp":0.0,"tv":0.0,"id":25545675},{"batb":[[0,11,5.58]],"ltp":0.0,"tv":0.0,"id":24707172},{"batb":[[0,7.4,1.88],[1,7.2,3],[2,5.7,1.64]],"batl":[[1,940,1.68],[2,950,9]],"ltp":8.6,"tv":7.94,"id":24420205}]}]}
{"op":"mcm","clk":"990041310","pt":1580493531322,"mc":[{"id":"1.168130661","rc":[{"batl":[[1,920,9],[2,940,1.68]],"ltp":8.6,"tv":7.94,"id":24420205}]}]}
{"op":"mcm","clk":"990041744","pt":1580493537320,"mc":[{"id":"1.168130661","rc":[{"batb":[[0,7.4,4.88],[1,5.7,1.64],[2,3.4,90]],"ltp":8.6,"tv":7.94,"id":24420205}]}]}
{"op":"mcm","clk":"990041980","pt":1580493540520,"mc":[{"id":"1.168130661","rc":[{"batl":[[0,2.88,2],[1,2.9,3],[2,2.94,2]],"ltp":2.74,"tv":45.14,"id":25238892}]}]}
{"op":"mcm","clk":"990042145","pt":1580493543147,"mc":[{"id":"1.168130661","rc":[{"trd":[[8.4,0.4]],"batb":[[0,7.4,4.68]],"batl":[[0,920,9.83],[1,940,1.68],[2,940,0]],"ltp":8.4,"tv":8.34,"id":24420205}],"tv":128.04}]}
{"op":"mcm","clk":"990044188","pt":1580493569662,"mc":[{"id":"1.168130661","rc":[{"trd":[[7.8,1.66]],"batl":[[0,920,9],[1,940,0]],"ltp":7.8,"tv":10.0,"id":24420205}],"tv":129.7}]}
{"op":"mcm","clk":"990044242","pt":1580493570287,"mc":[{"id":"1.168130661","rc":[{"batb":[[0,7.4,11.67]],"batl":[[0,910,1.68],[1,920,9]],"ltp":7.8,"tv":10.0,"id":24420205}]}]}
{"op":"mcm","clk":"990044414","pt":1580493572656,"mc":[{"id":"1.168130661","rc":[{"batb":[[0,7.4,8.67],[1,7,3.76],[2,3.4,90.88]],"ltp":7.8,"tv":10.0,"id":24420205}]}]}
{"op":"mcm","clk":"990045071","pt":1580493582559,"mc":[{"id":"1.168130661","rc":[{"batl":[[0,12.5,10],[1,910,1.68],[2,920,9]],"ltp":7.8,"tv":10.0,"id":24420205}]}]}
{"op":"mcm","clk":"990045738","pt":1580493592101,"mc":[{"id":"1.168130661","rc":[{"batl":[[1,38,9],[2,910,1.68]],"ltp":7.8,"tv":10.0,"id":24420205}]}]}
{"op":"mcm","clk":"990046179","pt":1580493597680,"mc":[{"id":"1.168130661","rc":[{"batl":[[0,3.2,11.62],[1,3.5,18.97],[2,3.6,2.52]],"ltp":3.1,"tv":74.55,"id":26314798}]}]}
{"op":"mcm","clk":"990046247","pt":1580493598515,"mc":[{"id":"1.168130661","rc":[{"batb":[[0,7.2,8.67]],"batl":[[0,12,4.75],[1,12.5,10],[2,38,9]],"ltp":7.8,"tv":10.0,"id":24420205},{"trd":[[2.96,3.97],[3.05,1.08]],"batb":[[0,2.94,2.34],[1,2.88,3],[2,2.54,21.91]],"ltp":2.96,"tv":79.6,"id":26314798}],"tv":134.74}]}
{"op":"mcm","clk":"990047018","pt":1580493606408,"mc":[{"id":"1.168130661","rc":[{"batb":[[0,13,4.71],[1,12.5,1.98]],"batl":[[0,970,1.88]],"ltp":0.0,"tv":0.0,"id":25545675},{"trd":[[2.76,7.96]],"batb":[[0,2.76,4.01],[2,2.72,5.06]],"ltp":2.74,"tv":45.13,"id":25238892},{"batb":[[0,11,5.57],[1,10.5,1.98]],"batl":[[0,970,1.88]],"ltp":0.0,"tv":0.0,"id":24707172},{"trd":[[8.8,3.96]],"batb":[[0,7.2,8.66]],"batl":[[0,12,4.75]],"ltp":7.8,"tv":9.99,"id":24420205},{"trd":[[2.96,3.96],[3.1,35.86],[3.55,14.28],[3.6,23.52]],"batb":[[0,2.94,2.34],[1,2.86,3],[2,2.54,21.89]],"batl":[[0,3.2,11.61],[1,3.5,18.95],[2,3.6,2.52]],"ltp":2.96,"tv":79.53,"id":26314798},{"batb":[[0,7.2,4.76],[2,5.9,1.68]],"batl":[[0,10.5,1.88]],"ltp":0.0,"tv":0.0,"id":420}],"tv":134.67}]}
{"op":"mcm","clk":"990047116","pt":1580493607436,"mc":[{"id":"1.168130661","rc":[{"batb":[[0,13.5,1.98],[1,13,4.71]],"ltp":0.0,"tv":0.0,"id":25545675},{"batb":[[0,2.76,9.06],[2,2.68,2.71]],"ltp":2.74,"tv":45.13,"id":25238892},{"batb":[[0,11.5,1.98],[1,11,5.57]],"ltp":0.0,"tv":0.0,"id":24707172},{"batb":[[0,7.4,1.98],[1,7.2,8.66],[2,7,3.76]],"ltp":7.8,"tv":9.99,"id":24420205}]}]}
{"op":"mcm","clk":"990047725","pt":1580493613524,"mc":[{"id":"1.168130661","rc":[{"batb":[[1,7,3.76],[2,3.4,90.88]],"ltp":7.8,"tv":9.99,"id":24420205}]}]}
{"op":"mcm","clk":"990047761","pt":1580493614039,"mc":[{"id":"1.168130661","rc":[{"batb":[[0,12,1.89],[1,11.5,1.98]],"ltp":0.0,"tv":0.0,"id":24707172},{"batb":[[0,7.6,2.66],[1,7.4,1.98],[2,7,3.76]],"ltp":7.8,"tv":9.99,"id":24420205}]}]}
{"op":"mcm","clk":"990047912","pt":1580493615720,"mc":[{"id":"1.168130661","rc":[{"batl":[[0,3.5,18.95],[1,3.6,2.52],[2,3.7,2.52]],"ltp":2.96,"tv":79.53,"id":26314798}]}]}
{"op":"mcm","clk":"990047942","pt":1580493616134,"mc":[{"id":"1.168130661","rc":[{"batl":[[0,11.5,3.23],[1,12,4.75],[2,12.5,10]],"ltp":7.8,"tv":9.99,"id":24420205},{"batl":[[0,3.45,10.77],[1,3.5,18.95],[2,3.6,2.52]],"ltp":2.96,"tv":79.53,"id":26314798}]}]}
{"op":"mcm","clk":"990048128","pt":1580493618405,"mc":[{"id":"1.168130661","rc":[{"batb":[[0,25,4.49],[1,13.5,1.98],[2,13,4.71]],"ltp":0.0,"tv":0.0,"id":25545675},{"batb":[[0,15,7.7],[1,12,1.89],[2,11.5,1.98]],"ltp":0.0,"tv":0.0,"id":24707172},{"batb":[[2,6.8,18.6]],"ltp":0.0,"tv":0.0,"id":420}]}]}
{"op":"mcm","clk":"990052815","pt":1580493670407,"mc":[{"id":"1.168130661","rc":[{"batl":[[0,2.96,1],[1,3.45,10.77],[2,3.5,18.95]],"ltp":2.96,"tv":79.53,"id":26314798}]}]}
{"op":"mcm","clk":"990053398","pt":1580493676198,"mc":[{"id":"1.168130661","rc":[{"trd":[[2.94,2]],"batb":[[0,2.94,1.34]],"ltp":2.94,"tv":81.53,"id":26314798}],"tv":136.67}]}
{"op":"mcm","clk":"990053540","pt":1580493678106,"mc":[{"id":"1.168130661","rc":[{"batl":[[1,3,1],[2,3.45,10.77]],"ltp":2.94,"tv":81.53,"id":26314798}]}]}
{"op":"mcm","clk":"990053738","pt":1580493680706,"mc":[{"id":"1.168130661","rc":[{"batl":[[2,3.1,1]],"ltp":2.94,"tv":81.53,"id":26314798}]}]}
{"op":"mcm","clk":"990054019","pt":1580493683681,"mc":[{"id":"1.168130661","rc":[{"batb":[[1,2.74,3]],"ltp":2.94,"tv":81.53,"id":26314798}]}]}
{"op":"mcm","clk":"990059229","pt":1580493740353,"mc":[{"id":"1.168130661","rc":[{"batb":[[0,2.94,2.32]],"batl":[[0,3.5,18.95],[1,3.6,2.52],[2,3.7,2.52]],"ltp":2.94,"tv":81.53,"id":26314798}]}]}
{"op":"mcm","clk":"990059830","pt":1580493747559,"mc":[{"id":"1.168130661","rc":[{"batb":[[0,2.94,1.34]],"ltp":2.94,"tv":81.53,"id":26314798}]}]}
{"op":"mcm","clk":"990059977","pt":1580493749382,"mc":[{"id":"1.168130661","rc":[{"trd":[[3.45,74.78],[3.5,1.68]],"batb":[[0,3.45,6.66],[1,2.94,1.34],[2,2.74,3]],"batl":[[0,3.5,18.1]],"ltp":3.5,"tv":157.99,"id":26314798}],"tv":213.13}]}
{"op":"mcm","clk":"990060043","pt":1580493750167,"mc":[{"id":"1.168130661","rc":[{"batb":[[1,3.25,3],[2,2.94,1.34]],"ltp":3.5,"tv":157.99,"id":26314798}]}]}
{"op":"mcm","clk":"990060623","pt":1580493756579,"mc":[{"id":"1.168130661","rc":[{"trd":[[3.45,88.1]],"batb":[[0,3.25,3],[1,2.94,1.34],[2,2.54,21.89]],"batl":[[0,3.45,4.11],[1,3.5,18.1],[2,3.6,2.52]],"ltp":3.45,"tv":171.31,"id":26314798}],"tv":226.45}]}
{"op":"mcm","clk":"990061599","pt":1580493766100,"mc":[{"id":"1.168130661","rc":[{"batb":[[0,2.94,1.34],[1,2.56,3]],"ltp":3.45,"tv":171.31,"id":26314798}]}]}
{"op":"mcm","clk":"990061781","pt":1580493768512,"mc":[{"id":"1.168130661","rc":[{"batb":[[1,2.78,3.9],[2,2.56,3]],"ltp":3.45,"tv":171.31,"id":26314798}]}]}
{"op":"mcm","clk":"990062257","pt":1580493772410,"mc":[{"id":"1.168130661","rc":[{"batl":[[0,3.4,1],[1,3.45,4.11],[2,3.5,18.1]],"ltp":3.45,"tv":171.31,"id":26314798}]}]}
{"op":"mcm","clk":"990062384","pt":1580493773781,"mc":[{"id":"1.168130661","rc":[{"batl":[[2,3.5,19.1]],"ltp":3.45,"tv":171.31,"id":26314798}]}]}
{"op":"mcm","clk":"990063926","pt":1580493787707,"mc":[{"id":"1.168130661","rc":[{"batb":[[1,2.8,3],[2,2.78,3.9]],"ltp":3.45,"tv":171.31,"id":26314798}]}]}
{"op":"mcm","clk":"990064705","pt":1580493796697,"mc":[{"id":"1.168130661","rc":[{"batb":[[0,26,1.98],[1,25,4.49]],"ltp":0.0,"tv":0.0,"id":25545675},{"batb":[[0,15.5,1.98],[1,15,7.7],[2,12,1.89]],"ltp":0.0,"tv":0.0,"id":24707172},{"batb":[[0,7.8,1.98],[1,7.6,2.66]],"ltp":7.8,"tv":9.99,"id":24420205},{"batb":[[1,2.84,1.98],[2,2.82,8.15]],"ltp":3.45,"tv":171.31,"id":26314798}]}]}
{"op":"mcm","clk":"990065028","pt":1580493801014,"mc":[{"id":"1.168130661","rc":[{"batb":[[1,2.86,3],[2,2.84,1.98]],"ltp":3.45,"tv":171.31,"id":26314798}]}]}
{"op":"mcm","clk":"990067054","pt":1580493826869,"mc":[{"id":"1.168130661","rc":[{"batb":[[1,2.88,3]],"ltp":3.45,"tv":171.31,"id":26314798}]}]}
{"op":"mcm","clk":"990068342","pt":1580493840978,"mc":[{"id":"1.168130661","rc":[{"batb":[[1,2.9,3]],"ltp":3.45,"tv":171.31,"id":26314798}]}]}
{"op":"mcm","clk":"990068969","pt":1580493849271,"mc":[{"id":"1.168130661","rc":[{"trd":[[2.76,17.96]],"batb":[[0,2.76,4.06]],"ltp":2.76,"tv":55.13,"id":25238892}],"tv":236.45}]}
{"op":"mcm","clk":"990069554","pt":1580493856910,"mc":[{"id":"1.168130661","rc":[{"batb":[[1,2.92,3]],"ltp":3.45,"tv":171.31,"id":26314798}]}]}
{"op":"mcm","clk":"990070799","pt":1580493871723,"mc":[{"id":"1.168130661","rc":[{"batb":[[0,2.94,4.34],[1,2.84,1.98],[2,2.78,3.9]],"ltp":3.45,"tv":171.31,"id":26314798}]}]}
{"op":"mcm","clk":"990072063","pt":1580493885420,"mc":[{"id":"1.168130661","rc":[{"batb":[[0,2.96,3],[1,2.94,1.34],[2,2.84,1.98]],"ltp":3.45,"tv":171.31,"id":26314798}]}]}
{"op":"mcm","clk":"990072156","pt":1580493886735,"mc":[{"id":"1.168130661","rc":[{"batl":[[0,750,2],[1,970,1.88],[2,980,9]],"ltp":0.0,"tv":0.0,"id":24707172}]}]}
{"op":"mcm","clk":"990073179","pt":1580493898554,"mc":[{"id":"1.168130661","rc":[{"batl":[[0,730,9],[1,750,2],[2,970,1.88]],"ltp":0.0,"tv":0.0,"id":24707172}]}]}
{"op":"mcm","clk":"990073830","pt":1580493905197,"mc":[{"id":"1.168130661","rc":[{"batb":[[0,2.94,1.34],[1,2.86,3]],"ltp":3.45,"tv":171.31,"id":26314798}]}]}
{"op":"mcm","clk":"990074634","pt":1580493913802,"mc":[{"id":"1.168130661","rc":[{"batl":[[0,750,2],[1,970,1.88],[2,980,9]],"ltp":0.0,"tv":0.0,"id":25545675}]}]}
{"op":"mcm","clk":"990075221","pt":1580493920293,"mc":[{"id":"1.168130661","rc":[{"batl":[[0,730,9],[1,750,2],[2,970,1.88]],"ltp":0.0,"tv":0.0,"id":25545675}]}]}
{"op":"mcm","clk":"990075555","pt":1580493923612,"mc":[{"id":"1.168130661","rc":[{"batb":[[1,2.88,3]],"ltp":3.45,"tv":171.31,"id":26314798}]}]}
{"op":"mcm","clk":"990077132","pt":1580493939945,"mc":[{"id":"1.168130661","rc":[{"batb":[[1,2.9,3]],"ltp":3.45,"tv":171.31,"id":26314798}]}]}
{"op":"mcm","clk":"990078704","pt":1580493955563,"mc":[{"id":"1.168130661","rc":[{"batb":[[1,2.92,3]],"ltp":3.45,"tv":171.31,"id":26314798}]}]}
{"op":"mcm","clk":"990080406","pt":1580493973473,"mc":[{"id":"1.168130661","rc":[{"batb":[[0,2.94,4.34],[1,2.84,1.98],[2,2.78,3.9]],"ltp":3.45,"tv":171.31,"id":26314798}]}]}
{"op":"mcm","clk":"990081745","pt":1580493988003,"mc":[{"id":"1.168130661","rc":[{"batb":[[0,2.96,3],[1,2.94,1.34],[2,2.84,1.98]],"ltp":3.45,"tv":171.31,"id":26314798}]}]}
{"op":"mcm","clk":"990083094","pt":1580494002402,"mc":[{"id":"1.168130661","rc":[{"batb":[[0,2.94,1.34],[1,2.86,3]],"ltp":3.45,"tv":171.31,"id":26314798}]}]}
{"op":"mcm","clk":"990084199","pt":1580494014717,"mc":[{"id":"1.168130661","rc":[{"batl":[[2,3.5,1]],"ltp":3.45,"tv":171.31,"id":26314798}]}]}
{"op":"mcm","clk":"990084381","pt":1580494016658,"mc":[{"id":"1.168130661","rc":[{"batl":[[1,3.5,1],[2,3.6,3.52]],"ltp":3.45,"tv":171.31,"id":26314798}]}]}
{"op":"mcm","clk":"990084431","pt":1580494017037,"mc":[{"id":"1.168130661","rc":[{"batl":[[2,3.55,3.99]],"ltp":3.45,"tv":171.31,"id":26314798}]}]}
{"op":"mcm","clk":"990084588","pt":1580494018665,"mc":[{"id":"1.168130661","rc":[{"batb":[[1,2.88,3]],"ltp":3.45,"tv":171.31,"id":26314798}]}]}
{"op":"mcm","clk":"990084688","pt":1580494019632,"mc":[{"id":"1.168130661","rc":[{"batb":[[0,26,2.72]],"ltp":0.0,"tv":0.0,"id":25545675},{"batb":[[0,2.76,11.31]],"ltp":2.76,"tv":55.13,"id":25238892},{"batb":[[0,16,1.25],[1,15.5,1.98],[2,15,7.7]],"ltp":0.0,"tv":0.0,"id":24707172},{"batb":[[0,7.8,4.54]],"ltp":7.8,"tv":9.99,"id":24420205},{"batb":[[1,2.9,6.9],[2,2.88,3]],"ltp":3.45,"tv":171.31,"id":26314798}]}]}
{"op":"mcm","clk":"990086095","pt":1580494034368,"mc":[{"id":"1.168130661","rc":[{"batb":[[1,2.92,3],[2,2.9,6.9]],"ltp":3.45,"tv":171.31,"id":26314798}]}]}
{"op":"mcm","clk":"990086165","pt":1580494035156,"mc":[{"id":"1.168130661","rc":[{"batb":[[1,2.92,4.98]],"ltp":3.45,"tv":171.31,"id":26314798}]}]}
{"op":"mcm","clk":"990086301","pt":1580494036677,"mc":[{"id":"1.168130661","rc":[{"batb":[[0,2.94,9.15]],"ltp":3.45,"tv":171.31,"id":26314798}]}]}
{"op":"mcm","clk":"990086597","pt":1580494039857,"mc":[{"id":"1.168130661","rc":[{"batb":[[1,2.68,2.71],[2,2.62,1]],"ltp":2.76,"tv":55.13,"id":25238892}]}]}
{"op":"mcm","clk":"990087138","pt":1580494045490,"mc":[{"id":"1.168130661","rc":[{"batb":[[0,2.96,3],[1,2.94,9.15],[2,2.92,1.98]],"ltp":3.45,"tv":171.31,"id":26314798}]}]}
{"op":"mcm","clk":"990097606","pt":1580494055881,"mc":[{"id":"1.168130661","rc":[{"batb":[[1,2.94,1.34]],"ltp":3.45,"tv":171.31,"id":26314798}]}]}
{"op":"mcm","clk":"990097812","pt":1580494058001,"mc":[{"id":"1.168130661","rc":[{"batb":[[0,2.94,4.34],[1,2.92,1.98],[2,2.9,6.9]],"ltp":3.45,"tv":171.31,"id":26314798}]}]}
{"op":"mcm","clk":"990098969","pt":1580494071417,"mc":[{"id":"1.168130661","rc":[{"batb":[[0,2.96,3],[1,2.94,1.34],[2,2.92,1.98]],"ltp":3.45,"tv":171.31,"id":26314798}]}]}
{"op":"mcm","clk":"990099872","pt":1580494081357,"mc":[{"id":"1.168130661","rc":[{"batb":[[0,2.76,4.06]],"ltp":2.76,"tv":55.13,"id":25238892},{"batl":[[1,3.5,3]],"ltp":3.45,"tv":171.31,"id":26314798}]}]}
{"op":"mcm","clk":"990099941","pt":1580494082263,"mc":[{"id":"1.168130661","rc":[{"batb":[[0,2.94,4.34],[1,2.92,1.98],[2,2.78,3.9]],"ltp":3.45,"tv":171.31,"id":26314798}]}]}
{"op":"mcm","clk":"990101067","pt":1580494094567,"mc":[{"id":"1.168130661","rc":[{"batb":[[0,2.96,3],[1,2.94,1.34],[2,2.92,1.98]],"ltp":3.45,"tv":171.31,"id":26314798}]}]}
{"op":"mcm","clk":"990101305","pt":1580494097072,"mc":[{"id":"1.168130661","rc":[{"batl":[[1,3.45,4.11],[2,3.5,3]],"ltp":3.45,"tv":171.31,"id":26314798}]}]}
{"op":"mcm","clk":"990102515","pt":1580494109309,"mc":[{"id":"1.168130661","rc":[{"batb":[[0,2.94,4.34],[1,2.92,1.98],[2,2.78,3.9]],"ltp":3.45,"tv":171.31,"id":26314798}]}]}
{"op":"mcm","clk":"990103810","pt":1580494122410,"mc":[{"id":"1.168130661","rc":[{"batb":[[0,2.96,3],[1,2.94,1.34],[2,2.92,1.98]],"ltp":3.45,"tv":171.31,"id":26314798}]}]}
{"op":"mcm","clk":"990105182","pt":1580494135609,"mc":[{"id":"1.168130661","rc":[{"batb":[[0,2.94,4.34],[1,2.92,1.98],[2,2.78,3.9]],"ltp":3.45,"tv":171.31,"id":26314798}]}]}
{"op":"mcm","clk":"990105866","pt":1580494142342,"mc":[{"id":"1.168130661","rc":[{"batl":[[0,3.4,3],[2,3.5,1]],"ltp":3.45,"tv":171.31,"id":26314798}]}]}
{"op":"mcm","clk":"990106766","pt":1580494152138,"mc":[{"id":"1.168130661","rc":[{"batb":[[0,2.96,3],[1,2.94,1.34],[2,2.92,1.98]],"ltp":3.45,"tv":171.31,"id":26314798}]}]}
{"op":"mcm","clk":"990107151","pt":1580494156581,"mc":[{"id":"1.168130661","rc":[{"batl":[[0,3.35,4.23],[1,3.4,3]],"ltp":3.45,"tv":171.31,"id":26314798}]}]}
{"op":"mcm","clk":"990108058","pt":1580494167691,"mc":[{"id":"1.168130661","rc":[{"batb":[[0,2.94,1.34],[1,2.92,1.98],[2,2.78,3.9]],"ltp":3.45,"tv":171.31,"id":26314798}]}]}
{"op":"mcm","clk":"990108065","pt":1580494167798,"mc":[{"id":"1.168130661","rc":[{"batb":[[0,2.94,4.34]],"ltp":3.45,"tv":171.31,"id":26314798}]}]}
{"op":"mcm","clk":"990109313","pt":1580494182980,"mc":[{"id":"1.168130661","rc":[{"batl":[[2,3,5]],"ltp":2.76,"tv":55.13,"id":25238892},{"batb":[[0,2.96,3],[1,2.94,1.34],[2,2.92,1.98]],"ltp":3.45,"tv":171.31,"id":26314798}]}]}
{"op":"mcm","clk":"990109482","pt":1580494184629,"mc":[{"id":"1.168130661","rc":[{"batl":[[1,3,5],[2,3.4,50]],"ltp":2.76,"tv":55.13,"id":25238892}]}]}
{"op":"mcm","clk":"990109640","pt":1580494186290,"mc":[{"id":"1.168130661","rc":[{"batl":[[0,3,5],[1,3.4,50],[2,3.55,3.12]],"ltp":2.76,"tv":55.13,"id":25238892}]}]}
{"op":"mcm","clk":"990110761","pt":1580494197408,"mc":[{"id":"1.168130661","rc":[{"batb":[[0,2.94,4.34],[1,2.92,1.98],[2,2.78,3.9]],"ltp":3.45,"tv":171.31,"id":26314798}]}]}
{"op":"mcm","clk":"990111286","pt":1580494203101,"mc":[{"id":"1.168130661","rc":[{"batl":[[0,2.98,2],[1,3,5],[2,3.4,50]],"ltp":2.76,"tv":55.13,"id":25238892},{"batl":[[0,3.3,2],[1,3.35,4.23],[2,3.4,1]],"ltp":3.45,"tv":171.31,"id":26314798}]}]}
{"op":"mcm","clk":"990112321","pt":1580494215114,"mc":[{"id":"1.168130661","rc":[{"batb":[[0,2.96,3],[1,2.94,1.34],[2,2.92,1.98]],"ltp":3.45,"tv":171.31,"id":26314798}]}]}
{"op":"mcm","clk":"990113313","pt":1580494225431,"mc":[{"id":"1.168130661","rc":[{"batl":[[0,2.98,4]],"ltp":2.76,"tv":55.13,"id":25238892}]}]}
{"op":"mcm","clk":"990113484","pt":1580494227270,"mc":[{"id":"1.168130661","rc":[{"batb":[[0,2.7,4.06]],"ltp":2.76,"tv":55.13,"id":25238892},{"batb":[[0,2.98,1.98],[1,2.96,3],[2,2.94,1.34]],"ltp":3.45,"tv":171.31,"id":26314798}]}]}
{"op":"mcm","clk":"990114007","pt":1580494233086,"mc":[{"id":"1.168130661","rc":[{"batb":[[0,2.98,4.98],[1,2.94,1.34],[2,2.78,3.9]],"ltp":3.45,"tv":171.31,"id":26314798}]}]}
{"op":"mcm","clk":"990115115","pt":1580494244596,"mc":[{"id":"1.168130661","rc":[{"batl":[[0,730,9.2],[2,970,1.68]],"ltp":0.0,"tv":0.0,"id":25545675},{"batl":[[0,2.98,4.18]],"ltp":2.76,"tv":55.13,"id":25238892},{"batl":[[0,730,9.2],[2,970,1.68]],"ltp":0.0,"tv":0.0,"id":24707172}]}]}
{"op":"mcm","clk":"990115329","pt":1580494246996,"mc":[{"id":"1.168130661","rc":[{"batb":[[0,3,3],[1,2.98,1.98],[2,2.94,1.34]],"ltp":3.45,"tv":171.31,"id":26314798}]}]}
{"op":"mcm","clk":"990116494","pt":1580494260108,"mc":[{"id":"1.168130661","rc":[{"batb":[[0,2.98,1.98],[1,2.96,3]],"ltp":3.45,"tv":171.31,"id":26314798}]}]}
{"op":"mcm","clk":"990117839","pt":1580494274191,"mc":[{"id":"1.168130661","rc":[{"batb":[[0,2.98,4.98],[1,2.94,1.34],[2,2.78,3.9]],"ltp":3.45,"tv":171.31,"id":26314798}]}]}
{"op":"mcm","clk":"990118943","pt":1580494286839,"mc":[{"id":"1.168130661","rc":[{"batb":[[0,3,3],[1,2.98,1.98],[2,2.94,1.34]],"ltp":3.45,"tv":171.31,"id":26314798}]}]}
{"op":"mcm","clk":"990119037","pt":1580494287944,"mc":[{"id":"1.168130661","rc":[{"batl":[[0,2.92,2],[1,2.98,4.18],[2,3,5]],"ltp":2.76,"tv":55.13,"id":25238892}]}]}
{"op":"mcm","clk":"990120209","pt":1580494301018,"mc":[{"id":"1.168130661","rc":[{"batb":[[0,2.98,1.98],[1,2.96,3]],"ltp":3.45,"tv":171.31,"id":26314798}]}]}
{"op":"mcm","clk":"990122045","pt":1580494320277,"mc":[{"id":"1.168130661","rc":[{"batb":[[0,2.98,4.98],[1,2.94,1.34],[2,2.78,3.9]],"ltp":3.45,"tv":171.31,"id":26314798}]}]}
{"op":"mcm","clk":"990122427","pt":1580494324667,"mc":[{"id":"1.168130661","rc":[{"batl":[[0,2.9,2],[1,2.92,2],[2,2.98,2.18]],"ltp":2.76,"tv":55.13,"id":25238892}]}]}
{"op":"mcm","clk":"990123407","pt":1580494336466,"mc":[{"id":"1.168130661","rc":[{"batb":[[0,3,3],[1,2.98,1.98],[2,2.94,1.34]],"ltp":3.45,"tv":171.31,"id":26314798}]}]}
{"op":"mcm","clk":"990124590","pt":1580494350257,"mc":[{"id":"1.168130661","rc":[{"batb":[[0,2.98,1.98],[1,2.96,3]],"ltp":3.45,"tv":171.31,"id":26314798}]}]}
{"op":"mcm","clk":"990125765","pt":1580494363707,"mc":[{"id":"1.168130661","rc":[{"batb":[[1,2.94,1.34],[2,2.78,3.9]],"ltp":3.45,"tv":171.31,"id":26314798}]}]}
{"op":"mcm","clk":"990125774","pt":1580494363815,"mc":[{"id":"1.168130661","rc":[{"batb":[[0,2.98,4.98]],"ltp":3.45,"tv":171.31,"id":26314798}]}]}
{"op":"mcm","clk":"990127183","pt":1580494379904,"mc":[{"id":"1.168130661","rc":[{"batb":[[0,3,3],[1,2.98,1.98],[2,2.94,1.34]],"ltp":3.45,"tv":171.31,"id":26314798}]}]}
{"op":"mcm","clk":"990127725","pt":1580494386401,"mc":[{"id":"1.168130661","rc":[{"batl":[[1,2.92,7]],"ltp":2.76,"tv":55.13,"id":25238892}]}]}
{"op":"mcm","clk":"990128239","pt":1580494392402,"mc":[{"id":"1.168130661","rc":[{"batb":[[0,2.98,1.98],[1,2.96,3]],"ltp":3.45,"tv":171.31,"id":26314798}]}]}
{"op":"mcm","clk":"990129452","pt":1580494406543,"mc":[{"id":"1.168130661","rc":[{"batb":[[0,2.98,4.98],[1,2.94,1.34],[2,2.78,3.9]],"ltp":3.45,"tv":171.31,"id":26314798}]}]}
{"op":"mcm","clk":"990130778","pt":1580494420057,"mc":[{"id":"1.168130661","rc":[{"batb":[[0,3,3],[1,2.98,1.98],[2,2.94,1.34]],"ltp":3.45,"tv":171.31,"id":26314798}]}]}
{"op":"mcm","clk":"990131865","pt":1580494432270,"mc":[{"id":"1.168130661","rc":[{"batb":[[0,2.98,1.98],[1,2.96,3]],"ltp":3.45,"tv":171.31,"id":26314798}]}]}
{"op":"mcm","clk":"990133460","pt":1580494449473,"mc":[{"id":"1.168130661","rc":[{"batb":[[0,2.98,4.98],[1,2.94,1.34],[2,2.78,3.9]],"ltp":3.45,"tv":171.31,"id":26314798}]}]}
{"op":"mcm","clk":"990134330","pt":1580494457995,"mc":[{"id":"1.168130661","rc":[{"batl":[[1,2.92,2]],"ltp":2.76,"tv":55.13,"id":25238892}]}]}
{"op":"mcm","clk":"990134664","pt":1580494461476,"mc":[{"id":"1.168130661","rc":[{"batb":[[0,3,3],[1,2.98,1.98],[2,2.94,1.34]],"ltp":3.45,"tv":171.31,"id":26314798}]}]}
{"op":"mcm","clk":"990134705","pt":1580494461906,"mc":[{"id":"1.168130661","rc":[{"batl":[[2,3,5.18]],"ltp":2.76,"tv":55.13,"id":25238892}]}]}
{"op":"mcm","clk":"990134880","pt":1580494463578,"mc":[{"id":"1.168130661","rc":[{"batl":[[2,3.4,50.18]],"ltp":2.76,"tv":55.13,"id":25238892}]}]}
{"op":"mcm","clk":"990135881","pt":1580494474516,"mc":[{"id":"1.168130661","rc":[{"batl":[[0,720,1.88],[1,730,9],[2,750,2]],"ltp":0.0,"tv":0.0,"id":24707172},{"batb":[[0,8,1.8],[1,7.8,4.54]],"batl":[[0,11,1.84],[1,11.5,3.23]],"ltp":7.8,"tv":9.99,"id":24420205},{"batb":[[0,2.98,1.98],[1,2.96,3]],"ltp":3.45,"tv":171.31,"id":26314798}]}]}
{"op":"mcm","clk":"990135994","pt":1580494475634,"mc":[{"id":"1.168130661","rc":[{"batl":[[0,720,1.88],[1,730,9],[2,750,2]],"ltp":0.0,"tv":0.0,"id":25545675}]}]}
{"op":"mcm","clk":"990137075","pt":1580494486701,"mc":[{"id":"1.168130661","rc":[{"batb":[[0,2.98,4.98],[1,2.94,1.34],[2,2.78,3.9]],"ltp":3.45,"tv":171.31,"id":26314798}]}]}
{"op":"mcm","clk":"990138116","pt":1580494497841,"mc":[{"id":"1.168130661","rc":[{"batb":[[0,3,3],[1,2.98,1.98],[2,2.94,1.34]],"ltp":3.45,"tv":171.31,"id":26314798}]}]}
{"op":"mcm","clk":"990139297","pt":1580494510558,"mc":[{"id":"1.168130661","rc":[{"batb":[[0,2.98,1.98],[1,2.96,3]],"ltp":3.45,"tv":171.31,"id":26314798}]}]}
{"op":"mcm","clk":"990140316","pt":1580494522679,"mc":[{"id":"1.168130661","rc":[{"batb":[[1,2.94,1.34],[2,2.78,3.9]],"ltp":3.45,"tv":171.31,"id":26314798}]}]}
{"op":"mcm","clk":"990140325","pt":1580494522792,"mc":[{"id":"1.168130661","rc":[{"batb":[[0,2.98,4.98]],"ltp":3.45,"tv":171.31,"id":26314798}]}]}
{"op":"mcm","clk":"990141186","pt":1580494533184,"mc":[{"id":"1.168130661","rc":[{"batb":[[0,3,3],[1,2.98,1.98],[2,2.94,1.34]],"ltp":3.45,"tv":171.31,"id":26314798}]}]}
{"op":"mcm","clk":"990142466","pt":1580494547340,"mc":[{"id":"1.168130661","rc":[{"batb":[[0,2.98,1.98],[1,2.96,3]],"ltp":3.45,"tv":171.31,"id":26314798}]}]}
{"op":"mcm","clk":"990144263","pt":1580494564363,"mc":[{"id":"1.168130661","rc":[{"batb":[[0,2.98,4.98],[1,2.94,1.34],[2,2.78,3.9]],"ltp":3.45,"tv":171.31,"id":26314798}]}]}
{"op":"mcm","clk":"990146201","pt":1580494582675,"mc":[{"id":"1.168130661","rc":[{"batb":[[0,3,3],[1,2.98,1.98],[2,2.94,1.34]],"ltp":3.45,"tv":171.31,"id":26314798}]}]}
{"op":"mcm","clk":"990147915","pt":1580494597482,"mc":[{"id":"1.168130661","rc":[{"batb":[[0,2.98,1.98],[1,2.96,3]],"ltp":3.45,"tv":171.31,"id":26314798}]}]}
{"op":"mcm","clk":"990149280","pt":1580494611617,"mc":[{"id":"1.168130661","rc":[{"batb":[[0,2.98,4.98],[1,2.94,1.34],[2,2.78,3.9]],"ltp":3.45,"tv":171.31,"id":26314798}]}]}
{"op":"mcm","clk":"990150715","pt":1580494626645,"mc":[{"id":"1.168130661","rc":[{"batb":[[0,2.98,1.98]],"ltp":3.45,"tv":171.31,"id":26314798}]}]}
{"op":"mcm","clk":"990150729","pt":1580494626743,"mc":[{"id":"1.168130661","rc":[{"batb":[[0,3,3],[1,2.98,1.98],[2,2.94,1.34]],"ltp":3.45,"tv":171.31,"id":26314798}]}]}
{"op":"mcm","clk":"990152099","pt":1580494640656,"mc":[{"id":"1.168130661","rc":[{"batb":[[0,2.98,1.98],[1,2.96,3]],"ltp":3.45,"tv":171.31,"id":26314798}]}]}
{"op":"mcm","clk":"990153340","pt":1580494653713,"mc":[{"id":"1.168130661","rc":[{"batb":[[0,2.98,4.98],[1,2.94,1.34],[2,2.78,3.9]],"ltp":3.45,"tv":171.31,"id":26314798}]}]}
{"op":"mcm","clk":"990154671","pt":1580494668213,"mc":[{"id":"1.168130661","rc":[{"batb":[[0,3,3],[1,2.98,1.98],[2,2.94,1.34]],"ltp":3.45,"tv":171.31,"id":26314798}]}]}
{"op":"mcm","clk":"990155876","pt":1580494680110,"mc":[{"id":"1.168130661","rc":[{"batb":[[0,2.98,1.98],[1,2.96,3]],"ltp":3.45,"tv":171.31,"id":26314798}]}]}
{"op":"mcm","clk":"990156701","pt":1580494688347,"mc":[{"id":"1.168130661","rc":[{"batl":[[0,2.9,7]],"ltp":2.76,"tv":55.13,"id":25238892}]}]}
{"op":"mcm","clk":"990157036","pt":1580494691456,"mc":[{"id":"1.168130661","rc":[{"batb":[[0,2.98,4.98],[1,2.94,1.34],[2,2.78,3.9]],"ltp":3.45,"tv":171.31,"id":26314798}]}]}
{"op":"mcm","clk":"990157669","pt":1580494697430,"mc":[{"id":"1.168130661","rc":[{"batb":[[0,8.2,1.98],[1,8,1.8],[2,7.8,2.56]],"ltp":7.8,"tv":9.99,"id":24420205}]}]}
{"op":"mcm","clk":"990158118","pt":1580494701671,"mc":[{"id":"1.168130661","rc":[{"batb":[[0,3,3],[1,2.98,1.98],[2,2.94,1.34]],"ltp":3.45,"tv":171.31,"id":26314798}]}]}
{"op":"mcm","clk":"990159352","pt":1580494713481,"mc":[{"id":"1.168130661","rc":[{"batb":[[0,2.98,1.98],[1,2.96,3]],"ltp":3.45,"tv":171.31,"id":26314798}]}]}
{"op":"mcm","clk":"990160629","pt":1580494725395,"mc":[{"id":"1.168130661","rc":[{"batb":[[0,2.98,4.98],[1,2.94,1.34],[2,2.78,3.9]],"ltp":3.45,"tv":171.31,"id":26314798}]}]}
{"op":"mcm","clk":"990162029","pt":1580494739896,"mc":[{"id":"1.168130661","rc":[{"batb":[[0,3,3],[1,2.98,1.98],[2,2.94,1.34]],"ltp":3.45,"tv":171.31,"id":26314798}]}]}
{"op":"mcm","clk":"990162798","pt":1580494746918,"mc":[{"id":"1.168130661","rc":[{"batb":[[2,7,3.76]],"ltp":7.8,"tv":9.99,"id":24420205}]}]}
{"op":"mcm","clk":"990163495","pt":1580494753654,"mc":[{"id":"1.168130661","rc":[{"batb":[[0,2.98,1.98],[1,2.94,1.34],[2,2.78,3.9]],"ltp":3.45,"tv":171.31,"id":26314798}]}]}
{"op":"mcm","clk":"990163503","pt":1580494753757,"mc":[{"id":"1.168130661","rc":[{"batb":[[1,2.96,3],[2,2.94,1.34]],"ltp":3.45,"tv":171.31,"id":26314798}]}]}
{"op":"mcm","clk":"990164984","pt":1580494768981,"mc":[{"id":"1.168130661","rc":[{"batl":[[0,2.88,2.25],[1,2.9,7],[2,2.92,2]],"ltp":2.76,"tv":55.13,"id":25238892}]}]}
{"op":"mcm","clk":"990165173","pt":1580494771188,"mc":[{"id":"1.168130661","rc":[{"batb":[[0,2.98,4.98],[1,2.94,1.34],[2,2.78,3.9]],"ltp":3.45,"tv":171.31,"id":26314798}]}]}
{"op":"mcm","clk":"990166553","pt":1580494785515,"mc":[{"id":"1.168130661","rc":[{"batb":[[0,3,3],[1,2.98,1.98],[2,2.94,1.34]],"ltp":3.45,"tv":171.31,"id":26314798}]}]}
{"op":"mcm","clk":"990167715","pt":1580494797211,"mc":[{"id":"1.168130661","rc":[{"batb":[[0,2.98,1.98],[1,2.96,3]],"ltp":3.45,"tv":171.31,"id":26314798}]}]}
{"op":"mcm","clk":"990168652","pt":1580494806211,"mc":[{"id":"1.168130661","rc":[{"batl":[[1,2.9,5]],"ltp":2.76,"tv":55.13,"id":25238892}]}]}
{"op":"mcm","clk":"990168991","pt":1580494809530,"mc":[{"id":"1.168130661","rc":[{"batb":[[0,2.98,4.98],[1,2.94,1.34],[2,2.78,3.9]],"ltp":3.45,"tv":171.31,"id":26314798}]}]}
{"op":"mcm","clk":"990170449","pt":1580494822063,"mc":[{"id":"1.168130661","rc":[{"batb":[[0,3,3],[1,2.98,1.98],[2,2.94,1.34]],"ltp":3.45,"tv":171.31,"id":26314798}]}]}
{"op":"mcm","clk":"990172133","pt":1580494837991,"mc":[{"id":"1.168130661","rc":[{"batb":[[0,2.98,1.98],[1,2.96,3]],"ltp":3.45,"tv":171.31,"id":26314798}]}]}
{"op":"mcm","clk":"990173485","pt":1580494850681,"mc":[{"id":"1.168130661","rc":[{"batb":[[0,2.98,4.98],[1,2.94,1.34],[2,2.78,3.9]],"ltp":3.45,"tv":171.31,"id":26314798}]}]}
{"op":"mcm","clk":"990174653","pt":1580494861349,"mc":[{"id":"1.168130661","rc":[{"batb":[[0,3,3],[1,2.98,1.98],[2,2.94,1.34]],"ltp":3.45,"tv":171.31,"id":26314798}]}]}
{"op":"mcm","clk":"990174913","pt":1580494863629,"mc":[{"id":"1.168130661","rc":[{"trd":[[8,0.04],[8.2,3.96]],"batb":[[0,8,1.78],[1,7,3.76],[2,5.8,3]],"ltp":8.0,"tv":13.99,"id":24420205}],"tv":240.44}]}
{"op":"mcm","clk":"990176378","pt":1580494877641,"mc":[{"id":"1.168130661","rc":[{"batb":[[2,4.5,90.88]],"ltp":8.0,"tv":13.99,"id":24420205},{"batb":[[0,2.98,1.98],[1,2.96,3]],"ltp":3.45,"tv":171.31,"id":26314798}]}]}
{"op":"mcm","clk":"990176460","pt":1580494878376,"mc":[{"id":"1.168130661","rc":[{"batb":[[2,4.6,3.88]],"ltp":8.0,"tv":13.99,"id":24420205}]}]}
{"op":"mcm","clk":"990177579","pt":1580494888442,"mc":[{"id":"1.168130661","rc":[{"batb":[[0,2.98,4.98],[1,2.94,1.34],[2,2.78,3.9]],"ltp":3.45,"tv":171.31,"id":26314798}]}]}
{"op":"mcm","clk":"990179088","pt":1580494903493,"mc":[{"id":"1.168130661","rc":[{"batb":[[0,3,3],[1,2.98,1.98],[2,2.94,1.34]],"ltp":3.45,"tv":171.31,"id":26314798}]}]}
{"op":"mcm","clk":"990180773","pt":1580494920629,"mc":[{"id":"1.168130661","rc":[{"batl":[[2,2.92,24]],"ltp":2.76,"tv":55.13,"id":25238892},{"batb":[[0,2.98,1.98],[1,2.96,3]],"ltp":3.45,"tv":171.31,"id":26314798}]}]}
{"op":"mcm","clk":"990181274","pt":1580494925194,"mc":[{"id":"1.168130661","rc":[{"batl":[[0,2.86,2],[1,2.88,2.25],[2,2.9,5]],"ltp":2.76,"tv":55.13,"id":25238892}]}]}
{"op":"mcm","clk":"990182184","pt":1580494932703,"mc":[{"id":"1.168130661","rc":[{"batb":[[0,8.2,1.98],[1,8,1.78],[2,7,3.76]],"ltp":8.0,"tv":13.99,"id":24420205},{"batb":[[0,2.98,4.98],[1,2.94,1.34],[2,2.78,3.9]],"ltp":3.45,"tv":171.31,"id":26314798}]}]}
{"op":"mcm","clk":"990183663","pt":1580494946151,"mc":[{"id":"1.168130661","rc":[{"batb":[[0,3,3],[1,2.98,1.98],[2,2.94,1.34]],"ltp":3.45,"tv":171.31,"id":26314798}]}]}
{"op":"mcm","clk":"990194957","pt":1580494962894,"mc":[{"id":"1.168130661","rc":[{"batb":[[0,2.98,1.98],[1,2.96,3]],"ltp":3.45,"tv":171.31,"id":26314798}]}]}
{"op":"mcm","clk":"990197127","pt":1580494986514,"mc":[{"id":"1.168130661","rc":[{"batb":[[0,2.98,4.98],[1,2.94,1.34],[2,2.78,3.9]],"ltp":3.45,"tv":171.31,"id":26314798}]}]}
{"op":"mcm","clk":"990198436","pt":1580495000832,"mc":[{"id":"1.168130661","rc":[{"batb":[[0,3,3],[1,2.98,1.98],[2,2.94,1.34]],"ltp":3.45,"tv":171.31,"id":26314798}]}]}
{"op":"mcm","clk":"990199205","pt":1580495008639,"mc":[{"id":"1.168130661","rc":[{"batl":[[1,2.9,5],[2,2.92,24]],"ltp":2.76,"tv":55.13,"id":25238892}]}]}
{"op":"mcm","clk":"990199287","pt":1580495009629,"mc":[{"id":"1.168130661","rc":[{"batl":[[0,2.84,1.06],[1,2.86,2],[2,2.9,5]],"ltp":2.76,"tv":55.13,"id":25238892}]}]}
{"op":"mcm","clk":"990199635","pt":1580495013859,"mc":[{"id":"1.168130661","rc":[{"batb":[[0,2.98,1.98],[1,2.96,3]],"ltp":3.45,"tv":171.31,"id":26314798}]}]}
{"op":"mcm","clk":"990201168","pt":1580495031305,"mc":[{"id":"1.168130661","rc":[{"batb":[[0,2.98,4.98],[1,2.94,1.34],[2,2.78,3.9]],"ltp":3.45,"tv":171.31,"id":26314798}]}]}
{"op":"mcm","clk":"990202472","pt":1580495045303,"mc":[{"id":"1.168130661","rc":[{"batl":[[1,2.88,2]],"ltp":2.76,"tv":55.13,"id":25238892}]}]}
{"op":"mcm","clk":"990202771","pt":1580495048637,"mc":[{"id":"1.168130661","rc":[{"batb":[[0,2.98,1.98]],"ltp":3.45,"tv":171.31,"id":26314798}]}]}
{"op":"mcm","clk":"990202789","pt":1580495048744,"mc":[{"id":"1.168130661","rc":[{"batb":[[0,3,3],[1,2.98,1.98],[2,2.94,1.34]],"ltp":3.45,"tv":171.31,"id":26314798}]}]}
{"op":"mcm","clk":"990204607","pt":1580495067630,"mc":[{"id":"1.168130661","rc":[{"batb":[[0,2.98,1.98],[1,2.96,3]],"ltp":3.45,"tv":171.31,"id":26314798}]}]}
{"op":"mcm","clk":"990206441","pt":1580495085635,"mc":[{"id":"1.168130661","rc":[{"batb":[[0,2.98,4.98],[1,2.94,1.34],[2,2.78,3.9]],"ltp":3.45,"tv":171.31,"id":26314798}]}]}
{"op":"mcm","clk":"990207579","pt":1580495096375,"mc":[{"id":"1.168130661","rc":[{"batb":[[0,3,3],[1,2.98,1.98],[2,2.94,1.34]],"ltp":3.45,"tv":171.31,"id":26314798}]}]}
{"op":"mcm","clk":"990208866","pt":1580495108891,"mc":[{"id":"1.168130661","rc":[{"batb":[[0,2.98,1.98],[1,2.96,3]],"ltp":3.45,"tv":171.31,"id":26314798}]}]}
{"op":"mcm","clk":"990210125","pt":1580495122206,"mc":[{"id":"1.168130661","rc":[{"batb":[[0,2.98,4.98],[1,2.94,1.34],[2,2.78,3.9]],"ltp":3.45,"tv":171.31,"id":26314798}]}]}
{"op":"mcm","clk":"990211440","pt":1580495135532,"mc":[{"id":"1.168130661","rc":[{"batb":[[0,3,3],[1,2.98,1.98],[2,2.94,1.34]],"ltp":3.45,"tv":171.31,"id":26314798}]}]}
{"op":"mcm","clk":"990212664","pt":1580495147655,"mc":[{"id":"1.168130661","rc":[{"batb":[[0,2.98,1.98],[1,2.96,3]],"ltp":3.45,"tv":171.31,"id":26314798}]}]}
{"op":"mcm","clk":"990213487","pt":1580495156274,"mc":[{"id":"1.168130661","rc":[{"batb":[[0,2.98,4.98],[1,2.94,1.34],[2,2.9,20.18]],"ltp":3.45,"tv":171.31,"id":26314798}]}]}
{"op":"mcm","clk":"990214750","pt":1580495169679,"mc":[{"id":"1.168130661","rc":[{"batb":[[0,3,3],[1,2.98,1.98],[2,2.94,1.34]],"ltp":3.45,"tv":171.31,"id":26314798}]}]}
{"op":"mcm","clk":"990215796","pt":1580495180424,"mc":[{"id":"1.168130661","rc":[{"batb":[[0,2.98,1.98],[1,2.96,3]],"ltp":3.45,"tv":171.31,"id":26314798}]}]}
{"op":"mcm","clk":"990217187","pt":1580495195297,"mc":[{"id":"1.168130661","rc":[{"batb":[[0,2.98,4.98],[1,2.94,1.34],[2,2.9,20.18]],"ltp":3.45,"tv":171.31,"id":26314798}]}]}
{"op":"mcm","clk":"990218330","pt":1580495206384,"mc":[{"id":"1.168130661","rc":[{"batb":[[0,3,3],[1,2.98,1.98],[2,2.94,1.34]],"ltp":3.45,"tv":171.31,"id":26314798}]}]}
{"op":"mcm","clk":"990219167","pt":1580495215380,"mc":[{"id":"1.168130661","rc":[{"batb":[[0,3.05,1.98],[1,3,3]],"ltp":3.45,"tv":171.31,"id":26314798}]}]}
{"op":"mcm","clk":"990219535","pt":1580495219274,"mc":[{"id":"1.168130661","rc":[{"batb":[[0,3.05,4.98],[1,2.94,1.34],[2,2.9,20.18]],"ltp":3.45,"tv":171.31,"id":26314798}]}]}
{"op":"mcm","clk":"990220203","pt":1580495226120,"mc":[{"id":"1.168130661","rc":[{"batl":[[0,3.35,4.23],[1,3.4,1],[2,3.5,1]],"ltp":3.45,"tv":171.31,"id":26314798}]}]}
{"op":"mcm","clk":"990220344","pt":1580495227332,"mc":[{"id":"1.168130661","rc":[{"batl":[[0,3.4,1],[1,3.5,1],[2,3.55,3.99]],"ltp":3.45,"tv":171.31,"id":26314798}]}]}
{"op":"mcm","clk":"990220788","pt":1580495232001,"mc":[{"id":"1.168130661","rc":[{"batb":[[0,3.1,3],[1,3.05,1.98],[2,2.94,1.34]],"ltp":3.45,"tv":171.31,"id":26314798}]}]}
{"op":"mcm","clk":"990221699","pt":1580495242469,"mc":[{"id":"1.168130661","rc":[{"batb":[[0,3.05,1.98],[1,2.96,3]],"ltp":3.45,"tv":171.31,"id":26314798}]}]}
{"op":"mcm","clk":"990221994","pt":1580495245668,"mc":[{"id":"1.168130661","rc":[{"batl":[[0,2.88,2],[1,2.9,5],[2,2.92,24]],"ltp":2.76,"tv":55.13,"id":25238892}]}]}
{"op":"mcm","clk":"990222066","pt":1580495246640,"mc":[{"id":"1.168130661","rc":[{"batl":[[0,2.86,2.02],[1,2.88,2],[2,2.9,5]],"ltp":2.76,"tv":55.13,"id":25238892}]}]}
{"op":"mcm","clk":"990222612","pt":1580495253288,"mc":[{"id":"1.168130661","rc":[{"batb":[[1,2.98,3]],"ltp":3.45,"tv":171.31,"id":26314798}]}]}
{"op":"mcm","clk":"990223531","pt":1580495264203,"mc":[{"id":"1.168130661","rc":[{"batb":[[1,3,3]],"ltp":3.45,"tv":171.31,"id":26314798}]}]}
{"op":"mcm","clk":"990223958","pt":1580495269204,"mc":[{"id":"1.168130661","rc":[{"batb":[[0,3.3,20.92],[1,3.05,1.98],[2,3,3]],"ltp":3.45,"tv":171.31,"id":26314798}]}]}
{"op":"mcm","clk":"990224080","pt":1580495270927,"mc":[{"id":"1.168130661","rc":[{"batb":[[0,3.05,1.98],[1,3,3],[2,2.94,1.34]],"ltp":3.45,"tv":171.31,"id":26314798}]}]}
{"op":"mcm","clk":"990224382","pt":1580495274703,"mc":[{"id":"1.168130661","rc":[{"batb":[[0,3.05,4.98],[1,2.94,1.34],[2,2.9,20.18]],"ltp":3.45,"tv":171.31,"id":26314798}]}]}
{"op":"mcm","clk":"990225169","pt":1580495284143,"mc":[{"id":"1.168130661","rc":[{"batb":[[0,3.1,3],[1,3.05,1.98],[2,2.94,1.34]],"ltp":3.45,"tv":171.31,"id":26314798}]}]}
{"op":"mcm","clk":"990225406","pt":1580495286656,"mc":[{"id":"1.168130661","rc":[{"batl":[[1,2.9,5],[2,2.92,24]],"ltp":2.76,"tv":55.13,"id":25238892}]}]}
{"op":"mcm","clk":"990225463","pt":1580495287352,"mc":[{"id":"1.168130661","rc":[{"batl":[[0,2.84,2],[1,2.86,2.02],[2,2.9,5]],"ltp":2.76,"tv":55.13,"id":25238892}]}]}
{"op":"mcm","clk":"990225697","pt":1580495289949,"mc":[{"id":"1.168130661","rc":[{"batb":[[0,3.1,3.42]],"ltp":3.45,"tv":171.31,"id":26314798}]}]}
{"op":"mcm","clk":"990225804","pt":1580495291262,"mc":[{"id":"1.168130661","rc":[{"batb":[[0,3.1,3]],"ltp":3.45,"tv":171.31,"id":26314798}]}]}
{"op":"mcm","clk":"990225909","pt":1580495292638,"mc":[{"id":"1.168130661","rc":[{"batb":[[0,3.1,3.42]],"ltp":3.45,"tv":171.31,"id":26314798}]}]}
{"op":"mcm","clk":"990226030","pt":1580495294158,"mc":[{"id":"1.168130661","rc":[{"batb":[[0,3.1,3]],"ltp":3.45,"tv":171.31,"id":26314798}]}]}
{"op":"mcm","clk":"990226426","pt":1580495298638,"mc":[{"id":"1.168130661","rc":[{"batb":[[0,3.05,1.98],[1,2.96,3]],"ltp":3.45,"tv":171.31,"id":26314798}]}]}
{"op":"mcm","clk":"990227425","pt":1580495312484,"mc":[{"id":"1.168130661","rc":[{"batl":[[0,2.82,2],[1,2.84,2],[2,2.86,2.02]],"ltp":2.76,"tv":55.13,"id":25238892}]}]}
{"op":"mcm","clk":"990227550","pt":1580495314416,"mc":[{"id":"1.168130661","rc":[{"batb":[[1,2.98,3]],"ltp":3.45,"tv":171.31,"id":26314798}]}]}
{"op":"mcm","clk":"990227719","pt":1580495316895,"mc":[{"id":"1.168130661","rc":[{"batb":[[0,3.05,2.4]],"ltp":3.45,"tv":171.31,"id":26314798}]}]}
{"op":"mcm","clk":"990227820","pt":1580495318308,"mc":[{"id":"1.168130661","rc":[{"batb":[[0,3.05,1.98]],"ltp":3.45,"tv":171.31,"id":26314798}]}]}
{"op":"mcm","clk":"990227957","pt":1580495319890,"mc":[{"id":"1.168130661","rc":[{"batb":[[0,3.05,2.4]],"ltp":3.45,"tv":171.31,"id":26314798}]}]}
{"op":"mcm","clk":"990228068","pt":1580495321203,"mc":[{"id":"1.168130661","rc":[{"batb":[[0,3.05,1.98]],"ltp":3.45,"tv":171.31,"id":26314798}]}]}
{"op":"mcm","clk":"990228243","pt":1580495323382,"mc":[{"id":"1.168130661","rc":[{"batb":[[0,3.05,2.4]],"ltp":3.45,"tv":171.31,"id":26314798}]}]}
{"op":"mcm","clk":"990228356","pt":1580495324695,"mc":[{"id":"1.168130661","rc":[{"batb":[[0,3.1,3],[1,3.05,1.98]],"ltp":3.45,"tv":171.31,"id":26314798}]}]}
{"op":"mcm","clk":"990229156","pt":1580495334364,"mc":[{"id":"1.168130661","rc":[{"batb":[[0,3.05,1.98],[1,2.96,3]],"ltp":3.45,"tv":171.31,"id":26314798}]}]}
{"op":"mcm","clk":"990230274","pt":1580495347566,"mc":[{"id":"1.168130661","rc":[{"batb":[[1,2.98,3]],"batl":[[1,3.5,3]],"ltp":3.45,"tv":171.31,"id":26314798}]}]}
{"op":"mcm","clk":"990231523","pt":1580495361843,"mc":[{"id":"1.168130661","rc":[{"batb":[[1,3,3]],"ltp":3.45,"tv":171.31,"id":26314798}]}]}
{"op":"mcm","clk":"990231661","pt":1580495363681,"mc":[{"id":"1.168130661","rc":[{"batl":[[2,3.6,1]],"ltp":3.45,"tv":171.31,"id":26314798}]}]}
{"op":"mcm","clk":"990231720","pt":1580495364275,"mc":[{"id":"1.168130661","rc":[{"batl":[[1,3.45,4.11],[2,3.5,3]],"ltp":3.45,"tv":171.31,"id":26314798}]}]}
