{"op":"mcm","clk":"984588704","pt":1580471452098,"mc":[{"id":"1.168136214","marketDefinition":{"bspMarket":true,"turnInPlayEnabled":true,"persistenceEnabled":true,"marketBaseRate":5.0,"eventId":"29678828","eventTypeId":"7","numberOfWinners":1,"bettingType":"ODDS","marketType":"WIN","marketTime":"2020-02-01T12:57:00.000Z","suspendTime":"2020-02-01T12:57:00.000Z","bspReconciled":false,"complete":true,"inPlay":false,"crossMatching":false,"runnersVoidable":false,"numberOfActiveRunners":3,"betDelay":0,"status":"OPEN","runners":[{"adjustmentFactor":46.07,"status":"ACTIVE","sortPriority":1,"id":17336468,"name":"Southfield Stone"},{"adjustmentFactor":34.34,"status":"ACTIVE","sortPriority":2,"id":11981493,"name":"Espoir De Teillee"},{"adjustmentFactor":19.58,"status":"ACTIVE","sortPriority":3,"id":12925630,"name":"Mahlervous"}],"regulators":["MR_INT"],"venue":"Musselburgh","countryCode":"GB","discountAllowed":false,"timezone":"Europe/London","openDate":"2020-02-01T12:57:00.000Z","version":3142913258,"name":"2m4f Nov Chs","eventName":"Muss  1st Feb"},"rc":[{"batb":[[0,1.01,2816.2]],"ltp":0.0,"tv":0.0,"id":12925630},{"batb":[[0,1.01,2826.2]],"ltp":0.0,"tv":0.0,"id":17336468},{"batb":[[0,1.01,2816.2]],"ltp":0.0,"tv":0.0,"id":11981493}]}]}
{"op":"mcm","clk":"984588836","pt":1580471453093,"mc":[{"id":"1.168136214","rc":[{"batb":[[0,1.51,3.36],[1,1.01,2829.56]],"ltp":0.0,"tv":0.0,"id":12925630},{"batb":[[0,1.51,3.36],[1,1.01,2829.56]],"ltp":0.0,"tv":0.0,"id":17336468},{"batb":[[0,1.51,3.36],[1,1.01,2829.56]],"ltp":0.0,"tv":0.0,"id":11981493}]}]}
{"op":"mcm","clk":"984589066","pt":1580471455087,"mc":[{"id":"1.168136214","marketDefinition":{"bspMarket":true,"turnInPlayEnabled":true,"persistenceEnabled":true,"marketBaseRate":5.0,"eventId":"29678828","eventTypeId":"7","numberOfWinners":1,"bettingType":"ODDS","marketType":"WIN","marketTime":"2020-02-01T12:57:00.000Z","suspendTime":"2020-02-01T12:57:00.000Z","bspReconciled":false,"complete":true,"inPlay":false,"crossMatching":false,"runnersVoidable":false,"numberOfActiveRunners":3,"betDelay":0,"status":"OPEN","runners":[{"adjustmentFactor":46.07,"status":"ACTIVE","sortPriority":1,"id":17336468,"name":"Southfield Stone"},{"adjustmentFactor":34.34,"status":"ACTIVE","sortPriority":2,"id":11981493,"name":"Espoir De Teillee"},{"adjustmentFactor":19.58,"status":"ACTIVE","sortPriority":3,"id":12925630,"name":"Mahlervous"}],"regulators":["MR_INT"],"venue":"Musselburgh","countryCode":"GB","discountAllowed":true,"timezone":"Europe/London","openDate":"2020-02-01T12:57:00.000Z","version":3142913258,"name":"2m4f Nov Chs","eventName":"Muss  1st Feb"}}]}
{"op":"mcm","clk":"984591047","pt":1580471471747,"mc":[{"id":"1.168136214","rc":[{"batb":[[1,1.01,2688.96]],"ltp":0.0,"tv":0.0,"id":11981493}]}]}
{"op":"mcm","clk":"984591406","pt":1580471475051,"mc":[{"id":"1.168136214","rc":[{"batb":[[1,1.01,2688.96]],"ltp":0.0,"tv":0.0,"id":12925630}]}]}
{"op":"mcm","clk":"984592386","pt":1580471482958,"mc":[{"id":"1.168136214","rc":[{"batb":[[1,1.03,5.18],[2,1.01,2688.96]],"ltp":0.0,"tv":0.0,"id":12925630},{"batb":[[1,1.03,5.18],[2,1.01,2829.56]],"ltp":0.0,"tv":0.0,"id":17336468},{"batb":[[1,1.03,5.18],[2,1.01,2688.96]],"ltp":0.0,"tv":0.0,"id":11981493}]}]}
{"op":"mcm","clk":"984592985","pt":1580471487939,"mc":[{"id":"1.168136214","rc":[{"batb":[[2,1.01,2688.96]],"ltp":0.0,"tv":0.0,"id":17336468}]}]}
{"op":"mcm","clk":"984609517","pt":1580471632020,"mc":[{"id":"1.168136214","rc":[{"batb":[[2,1.01,2690.96]],"ltp":0.0,"tv":0.0,"id":12925630},{"batb":[[2,1.01,2690.96]],"ltp":0.0,"tv":0.0,"id":17336468},{"batb":[[2,1.01,2690.96]],"ltp":0.0,"tv":0.0,"id":11981493}]}]}
{"op":"mcm","clk":"984610138","pt":1580471637101,"mc":[{"id":"1.168136214","rc":[{"batb":[[2,1.01,2692.64]],"ltp":0.0,"tv":0.0,"id":17336468}]}]}
{"op":"mcm","clk":"984610236","pt":1580471637833,"mc":[{"id":"1.168136214","rc":[{"batb":[[2,1.01,2692.64]],"ltp":0.0,"tv":0.0,"id":12925630},{"batb":[[2,1.01,2692.64]],"ltp":0.0,"tv":0.0,"id":11981493}]}]}
{"op":"mcm","clk":"984610385","pt":1580471639030,"mc":[{"id":"1.168136214","rc":[{"batb":[[2,1.01,2696.63]],"ltp":0.0,"tv":0.0,"id":17336468}]}]}
{"op":"mcm","clk":"984610520","pt":1580471640120,"mc":[{"id":"1.168136214","rc":[{"batb":[[2,1.02,1.99]],"ltp":0.0,"tv":0.0,"id":17336468},{"batb":[[2,1.01,2696.63]],"ltp":0.0,"tv":0.0,"id":11981493}]}]}
{"op":"mcm","clk":"984610589","pt":1580471640717,"mc":[{"id":"1.168136214","rc":[{"batb":[[2,1.02,1.99]],"ltp":0.0,"tv":0.0,"id":11981493}]}]}
{"op":"mcm","clk":"984610716","pt":1580471641712,"mc":[{"id":"1.168136214","rc":[{"batb":[[2,1.01,2696.63]],"ltp":0.0,"tv":0.0,"id":12925630}]}]}
{"op":"mcm","clk":"984610797","pt":1580471642292,"mc":[{"id":"1.168136214","rc":[{"batb":[[2,1.02,1.99]],"ltp":0.0,"tv":0.0,"id":12925630}]}]}
{"op":"mcm","clk":"984624117","pt":1580471751686,"mc":[{"id":"1.168136214","rc":[{"batb":[[1,1.04,10],[2,1.03,5.18]],"ltp":0.0,"tv":0.0,"id":12925630},{"batb":[[1,1.04,10],[2,1.03,5.18]],"ltp":0.0,"tv":0.0,"id":17336468},{"batb":[[1,1.04,10],[2,1.03,5.18]],"ltp":0.0,"tv":0.0,"id":11981493}]}]}
{"op":"mcm","clk":"984635686","pt":1580471852261,"mc":[{"id":"1.168136214","rc":[{"batb":[[1,1.03,15.18],[2,1.02,1.99]],"ltp":0.0,"tv":0.0,"id":12925630},{"batb":[[1,1.03,15.18],[2,1.02,1.99]],"ltp":0.0,"tv":0.0,"id":17336468},{"batb":[[1,1.03,15.18],[2,1.02,1.99]],"ltp":0.0,"tv":0.0,"id":11981493}]}]}
{"op":"mcm","clk":"984677186","pt":1580472152041,"mc":[{"id":"1.168136214","rc":[{"batb":[[1,1.03,15.18]],"ltp":0.0,"tv":0.0,"id":12925630},{"batb":[[1,1.03,15.18]],"ltp":0.0,"tv":0.0,"id":17336468},{"batb":[[1,1.03,15.18]],"ltp":0.0,"tv":0.0,"id":11981493}]}]}
{"op":"mcm","clk":"984686172","pt":1580472182648,"mc":[{"id":"1.168136214","rc":[{"batb":[[1,1.03,1686.05]],"ltp":0.0,"tv":0.0,"id":12925630},{"batb":[[1,1.03,1603.64]],"ltp":0.0,"tv":0.0,"id":17336468},{"batb":[[1,1.03,1554.03]],"ltp":0.0,"tv":0.0,"id":11981493}]}]}
{"op":"mcm","clk":"984836158","pt":1580473169780,"mc":[{"id":"1.168136214","rc":[{"batb":[[1,1.04,3],[2,1.03,1686.05]],"ltp":0.0,"tv":0.0,"id":12925630},{"batb":[[1,1.04,3],[2,1.03,1603.64]],"ltp":0.0,"tv":0.0,"id":17336468},{"batb":[[1,1.04,3],[2,1.03,1554.03]],"ltp":0.0,"tv":0.0,"id":11981493}]}]}
{"op":"mcm","clk":"984842503","pt":1580473212789,"mc":[{"id":"1.168136214","rc":[{"batb":[[1,1.05,10],[2,1.04,3]],"ltp":0.0,"tv":0.0,"id":12925630},{"batb":[[1,1.05,10],[2,1.04,3]],"ltp":0.0,"tv":0.0,"id":17336468},{"batb":[[1,1.05,10],[2,1.04,3]],"ltp":0.0,"tv":0.0,"id":11981493}]}]}
{"op":"mcm","clk":"984856930","pt":1580473303875,"mc":[{"id":"1.168136214","rc":[{"batb":[[1,1.04,13],[2,1.03,1676.05]],"ltp":0.0,"tv":0.0,"id":12925630},{"batb":[[1,1.04,13],[2,1.03,1593.64]],"ltp":0.0,"tv":0.0,"id":17336468},{"batb":[[1,1.04,13],[2,1.03,1544.03]],"ltp":0.0,"tv":0.0,"id":11981493}]}]}
{"op":"mcm","clk":"985049810","pt":1580474585274,"mc":[{"id":"1.168136214","rc":[{"batl":[[0,1000,0.2]],"ltp":0.0,"tv":0.0,"id":12925630},{"batl":[[0,1000,0.2]],"ltp":0.0,"tv":0.0,"id":17336468},{"batl":[[0,1000,0.2]],"ltp":0.0,"tv":0.0,"id":11981493}]}]}
{"op":"mcm","clk":"985176656","pt":1580475445134,"mc":[{"id":"1.168136214","rc":[{"batb":[[0,1.52,1.09],[1,1.51,3.36],[2,1.04,13]],"ltp":0.0,"tv":0.0,"id":12925630},{"batb":[[0,1.52,1.09],[1,1.51,3.36],[2,1.04,13]],"ltp":0.0,"tv":0.0,"id":17336468},{"batb":[[0,1.52,1.09],[1,1.51,3.36],[2,1.04,13]],"ltp":0.0,"tv":0.0,"id":11981493}]}]}
{"op":"mcm","clk":"985182947","pt":1580475491384,"mc":[{"id":"1.168136214","rc":[{"batb":[[0,1.52,11.09],[2,1.04,3]],"ltp":0.0,"tv":0.0,"id":12925630},{"batb":[[0,1.52,11.09],[2,1.04,3]],"ltp":0.0,"tv":0.0,"id":17336468},{"batb":[[0,1.52,11.09],[2,1.04,3]],"ltp":0.0,"tv":0.0,"id":11981493}]}]}
{"op":"mcm","clk":"985189113","pt":1580475537471,"mc":[{"id":"1.168136214","rc":[{"batb":[[2,1.03,1676.05]],"ltp":0.0,"tv":0.0,"id":12925630},{"batb":[[2,1.03,1593.64]],"ltp":0.0,"tv":0.0,"id":17336468},{"batb":[[2,1.03,1544.03]],"ltp":0.0,"tv":0.0,"id":11981493}]}]}
{"op":"mcm","clk":"985375305","pt":1580476795151,"mc":[{"id":"1.168136214","rc":[{"batb":[[0,1.53,3],[1,1.52,11.09],[2,1.51,3.36]],"ltp":0.0,"tv":0.0,"id":12925630},{"batb":[[0,1.53,3],[1,1.52,11.09],[2,1.51,3.36]],"ltp":0.0,"tv":0.0,"id":17336468},{"batb":[[0,1.53,3],[1,1.52,11.09],[2,1.51,3.36]],"ltp":0.0,"tv":0.0,"id":11981493}]}]}
{"op":"mcm","clk":"985375407","pt":1580476796125,"mc":[{"id":"1.168136214","rc":[{"batb":[[0,1.54,1.99],[1,1.53,3],[2,1.52,11.09]],"ltp":0.0,"tv":0.0,"id":12925630},{"batb":[[0,1.54,1.99],[1,1.53,3],[2,1.52,11.09]],"ltp":0.0,"tv":0.0,"id":17336468},{"batb":[[0,1.54,1.99],[1,1.53,3],[2,1.52,11.09]],"ltp":0.0,"tv":0.0,"id":11981493}]}]}
{"op":"mcm","clk":"985380436","pt":1580476835766,"mc":[{"id":"1.168136214","rc":[{"batb":[[2,1.52,1.09]],"ltp":0.0,"tv":0.0,"id":12925630},{"batb":[[2,1.52,1.09]],"ltp":0.0,"tv":0.0,"id":17336468},{"batb":[[2,1.52,1.09]],"ltp":0.0,"tv":0.0,"id":11981493}]}]}
{"op":"mcm","clk":"985397597","pt":1580476973330,"mc":[{"id":"1.168136214","rc":[{"batb":[[1,1.52,1.09],[2,1.51,3.36]],"ltp":0.0,"tv":0.0,"id":12925630},{"batb":[[1,1.52,1.09],[2,1.51,3.36]],"ltp":0.0,"tv":0.0,"id":17336468},{"batb":[[1,1.52,1.09],[2,1.51,3.36]],"ltp":0.0,"tv":0.0,"id":11981493}]}]}
{"op":"mcm","clk":"985401892","pt":1580477006985,"mc":[{"id":"1.168136214","rc":[{"batb":[[1,1.53,10],[2,1.52,1.09]],"ltp":0.0,"tv":0.0,"id":12925630},{"batb":[[1,1.53,10],[2,1.52,1.09]],"ltp":0.0,"tv":0.0,"id":17336468},{"batb":[[1,1.53,10],[2,1.52,1.09]],"ltp":0.0,"tv":0.0,"id":11981493}]}]}
{"op":"mcm","clk":"985413296","pt":1580477093304,"mc":[{"id":"1.168136214","rc":[{"batb":[[1,1.52,11.09],[2,1.51,3.36]],"ltp":0.0,"tv":0.0,"id":12925630},{"batb":[[1,1.52,11.09],[2,1.51,3.36]],"ltp":0.0,"tv":0.0,"id":17336468},{"batb":[[1,1.52,11.09],[2,1.51,3.36]],"ltp":0.0,"tv":0.0,"id":11981493}]}]}
{"op":"mcm","clk":"985415407","pt":1580477109142,"mc":[{"id":"1.168136214","rc":[{"batb":[[0,1.53,1.99]],"ltp":0.0,"tv":0.0,"id":17336468},{"batb":[[0,1.53,1.99]],"ltp":0.0,"tv":0.0,"id":11981493}]}]}
{"op":"mcm","clk":"985415479","pt":1580477109659,"mc":[{"id":"1.168136214","rc":[{"batb":[[0,1.53,1.99]],"ltp":0.0,"tv":0.0,"id":12925630}]}]}
{"op":"mcm","clk":"985715617","pt":1580479352044,"mc":[{"id":"1.168136214","rc":[{"batb":[[1,1.52,11.09]],"ltp":0.0,"tv":0.0,"id":12925630},{"batb":[[1,1.52,11.09]],"ltp":0.0,"tv":0.0,"id":17336468},{"batb":[[1,1.52,11.09]],"ltp":0.0,"tv":0.0,"id":11981493}]}]}
{"op":"mcm","clk":"986474971","pt":1580486552063,"mc":[{"id":"1.168136214","rc":[{"batb":[[1,1.52,11.08]],"ltp":0.0,"tv":0.0,"id":12925630},{"batb":[[1,1.52,11.08]],"ltp":0.0,"tv":0.0,"id":17336468},{"batb":[[1,1.52,11.08]],"ltp":0.0,"tv":0.0,"id":11981493}]}]}
{"op":"mcm","clk":"986493203","pt":1580486665546,"mc":[{"id":"1.168136214","rc":[{"batb":[[0,1.54,1.68],[1,1.53,1.99],[2,1.52,11.08]],"ltp":0.0,"tv":0.0,"id":17336468}]}]}
{"op":"mcm","clk":"986493318","pt":1580486666366,"mc":[{"id":"1.168136214","rc":[{"batb":[[0,1.53,1.99],[1,1.52,11.08],[2,1.51,3.36]],"ltp":0.0,"tv":0.0,"id":17336468}]}]}
{"op":"mcm","clk":"986494252","pt":1580486673840,"mc":[{"id":"1.168136214","rc":[{"batb":[[0,1.54,3.27],[1,1.53,1.99],[2,1.52,11.08]],"batl":[[0,1000,1.88]],"ltp":0.0,"tv":0.0,"id":12925630},{"batb":[[0,1.54,3.27],[1,1.53,1.99],[2,1.52,11.08]],"batl":[[0,1000,1.88]],"ltp":0.0,"tv":0.0,"id":17336468},{"batb":[[0,1.54,3.27],[1,1.53,1.99],[2,1.52,11.08]],"batl":[[0,1000,1.88]],"ltp":0.0,"tv":0.0,"id":11981493}]}]}
{"op":"mcm","clk":"986496169","pt":1580486690974,"mc":[{"id":"1.168136214","rc":[{"batb":[[0,1.54,13.27],[2,1.52,1.08]],"ltp":0.0,"tv":0.0,"id":12925630},{"batb":[[0,1.54,13.27],[2,1.52,1.08]],"ltp":0.0,"tv":0.0,"id":17336468},{"batb":[[0,1.54,13.27],[2,1.52,1.08]],"ltp":0.0,"tv":0.0,"id":11981493}]}]}
{"op":"mcm","clk":"986498322","pt":1580486712006,"mc":[{"id":"1.168136214","rc":[{"batb":[[0,1.55,1.99],[1,1.54,13.27]],"ltp":0.0,"tv":0.0,"id":17336468}]}]}
{"op":"mcm","clk":"986498389","pt":1580486712658,"mc":[{"id":"1.168136214","rc":[{"batb":[[0,1.55,1.99],[1,1.54,13.27]],"ltp":0.0,"tv":0.0,"id":12925630},{"batb":[[0,1.55,1.99],[1,1.54,13.27]],"ltp":0.0,"tv":0.0,"id":11981493}]}]}
{"op":"mcm","clk":"986501465","pt":1580486743072,"mc":[{"id":"1.168136214","rc":[{"batb":[[0,1.56,3.23],[1,1.55,1.99],[2,1.54,10]],"ltp":0.0,"tv":0.0,"id":17336468}]}]}
{"op":"mcm","clk":"986501537","pt":1580486743553,"mc":[{"id":"1.168136214","rc":[{"batb":[[0,1.56,3.23],[1,1.55,1.99],[2,1.54,10]],"ltp":0.0,"tv":0.0,"id":12925630},{"batb":[[0,1.56,3.23],[1,1.55,1.99],[2,1.54,10]],"ltp":0.0,"tv":0.0,"id":11981493}]}]}
{"op":"mcm","clk":"986502253","pt":1580486750130,"mc":[{"id":"1.168136214","rc":[{"batb":[[0,1.57,1.99],[1,1.56,3.23]],"ltp":0.0,"tv":0.0,"id":17336468}]}]}
{"op":"mcm","clk":"986502331","pt":1580486750873,"mc":[{"id":"1.168136214","rc":[{"batb":[[0,1.57,1.99],[1,1.56,3.23]],"ltp":0.0,"tv":0.0,"id":12925630},{"batb":[[0,1.57,1.99],[1,1.56,3.23]],"ltp":0.0,"tv":0.0,"id":11981493}]}]}
{"op":"mcm","clk":"986503930","pt":1580486766499,"mc":[{"id":"1.168136214","rc":[{"batb":[[0,1.57,11.99],[2,1.52,1.08]],"ltp":0.0,"tv":0.0,"id":12925630},{"batb":[[0,1.57,11.99],[2,1.52,1.08]],"ltp":0.0,"tv":0.0,"id":17336468},{"batb":[[0,1.57,11.99],[2,1.52,1.08]],"ltp":0.0,"tv":0.0,"id":11981493}]}]}
{"op":"mcm","clk":"986505795","pt":1580486784091,"mc":[{"id":"1.168136214","rc":[{"batb":[[2,1.51,3.36]],"ltp":0.0,"tv":0.0,"id":12925630},{"batb":[[2,1.51,3.36]],"ltp":0.0,"tv":0.0,"id":17336468}]}]}
{"op":"mcm","clk":"986505812","pt":1580486784197,"mc":[{"id":"1.168136214","rc":[{"batb":[[2,1.51,3.36]],"ltp":0.0,"tv":0.0,"id":11981493}]}]}
{"op":"mcm","clk":"986507266","pt":1580486797091,"mc":[{"id":"1.168136214","rc":[{"batb":[[0,1.58,1.04],[1,1.57,11.99],[2,1.56,3.23]],"ltp":0.0,"tv":0.0,"id":17336468},{"batb":[[0,1.58,1.04],[1,1.57,11.99],[2,1.56,3.23]],"ltp":0.0,"tv":0.0,"id":11981493}]}]}
{"op":"mcm","clk":"986507284","pt":1580486797195,"mc":[{"id":"1.168136214","rc":[{"batb":[[0,1.58,1.04],[1,1.57,11.99],[2,1.56,3.23]],"ltp":0.0,"tv":0.0,"id":12925630}]}]}
{"op":"mcm","clk":"986510224","pt":1580486825073,"mc":[{"id":"1.168136214","rc":[{"batb":[[0,1.58,4.23],[2,1.51,3.36]],"ltp":0.0,"tv":0.0,"id":17336468},{"batb":[[0,1.58,4.23],[2,1.51,3.36]],"ltp":0.0,"tv":0.0,"id":11981493}]}]}
{"op":"mcm","clk":"986510266","pt":1580486825448,"mc":[{"id":"1.168136214","rc":[{"batb":[[0,1.58,4.23],[2,1.51,3.36]],"ltp":0.0,"tv":0.0,"id":12925630}]}]}
{"op":"mcm","clk":"986511935","pt":1580486838980,"mc":[{"id":"1.168136214","rc":[{"batb":[[0,1.59,1.99],[1,1.58,4.23],[2,1.57,10]],"ltp":0.0,"tv":0.0,"id":17336468}]}]}
{"op":"mcm","clk":"986512015","pt":1580486839788,"mc":[{"id":"1.168136214","rc":[{"batb":[[0,1.59,1.99],[1,1.58,4.23],[2,1.57,10]],"ltp":0.0,"tv":0.0,"id":12925630},{"batb":[[0,1.59,1.99],[1,1.58,4.23],[2,1.57,10]],"ltp":0.0,"tv":0.0,"id":11981493}]}]}
{"op":"mcm","clk":"986516536","pt":1580486884125,"mc":[{"id":"1.168136214","rc":[{"batb":[[0,1.6,1.68],[1,1.59,1.99],[2,1.58,1.04]],"ltp":0.0,"tv":0.0,"id":12925630},{"batb":[[0,1.6,1.68],[1,1.58,1.04]],"ltp":0.0,"tv":0.0,"id":17336468},{"batb":[[0,1.6,1.68],[1,1.59,1.99],[2,1.58,1.04]],"ltp":0.0,"tv":0.0,"id":11981493}]}]}
{"op":"mcm","clk":"986516589","pt":1580486884617,"mc":[{"id":"1.168136214","rc":[{"batb":[[0,1.61,1.99],[1,1.6,1.68],[2,1.58,1.04]],"ltp":0.0,"tv":0.0,"id":17336468},{"batb":[[0,1.61,1.99],[1,1.6,1.68]],"ltp":0.0,"tv":0.0,"id":11981493}]}]}
{"op":"mcm","clk":"986520482","pt":1580486924382,"mc":[{"id":"1.168136214","rc":[{"batb":[[0,1.61,1.99],[1,1.6,1.68]],"ltp":0.0,"tv":0.0,"id":12925630}]}]}
{"op":"mcm","clk":"986522097","pt":1580486941026,"mc":[{"id":"1.168136214","rc":[{"batb":[[0,1.62,1.68],[1,1.61,1.99]],"ltp":0.0,"tv":0.0,"id":17336468},{"batb":[[1,1.58,1.04],[2,1.51,3.36]],"ltp":0.0,"tv":0.0,"id":11981493}]}]}
{"op":"mcm","clk":"986522170","pt":1580486941798,"mc":[{"id":"1.168136214","rc":[{"batb":[[0,1.62,1.68],[1,1.61,1.99]],"ltp":0.0,"tv":0.0,"id":12925630},{"batb":[[0,1.62,1.68],[1,1.61,1.99],[2,1.58,1.04]],"ltp":0.0,"tv":0.0,"id":11981493}]}]}
{"op":"mcm","clk":"986524733","pt":1580486970112,"mc":[{"id":"1.168136214","rc":[{"batb":[[0,1.63,1.99],[1,1.62,1.68]],"ltp":0.0,"tv":0.0,"id":17336468}]}]}
{"op":"mcm","clk":"986524799","pt":1580486970820,"mc":[{"id":"1.168136214","rc":[{"batb":[[0,1.63,1.99],[1,1.62,1.68]],"ltp":0.0,"tv":0.0,"id":12925630},{"batb":[[0,1.63,1.99],[1,1.62,1.68]],"ltp":0.0,"tv":0.0,"id":11981493}]}]}
{"op":"mcm","clk":"986527234","pt":1580486998057,"mc":[{"id":"1.168136214","rc":[{"batb":[[1,1.58,1.04],[2,1.51,3.36]],"ltp":0.0,"tv":0.0,"id":17336468}]}]}
{"op":"mcm","clk":"986527313","pt":1580486998862,"mc":[{"id":"1.168136214","rc":[{"batb":[[0,1.64,1.68],[1,1.63,1.99]],"ltp":0.0,"tv":0.0,"id":12925630},{"batb":[[0,1.64,1.68],[1,1.63,1.99],[2,1.58,1.04]],"ltp":0.0,"tv":0.0,"id":17336468},{"batb":[[0,1.64,1.68],[1,1.63,1.99]],"ltp":0.0,"tv":0.0,"id":11981493}]}]}
{"op":"mcm","clk":"986528838","pt":1580487014857,"mc":[{"id":"1.168136214","rc":[{"batb":[[2,1.51,3.36]],"ltp":0.0,"tv":0.0,"id":12925630},{"batb":[[2,1.51,3.36]],"ltp":0.0,"tv":0.0,"id":17336468},{"batb":[[2,1.51,3.36]],"ltp":0.0,"tv":0.0,"id":11981493}]}]}
{"op":"mcm","clk":"986529128","pt":1580487018065,"mc":[{"id":"1.168136214","rc":[{"batb":[[1,1.51,3.36],[2,1.03,1593.64]],"ltp":0.0,"tv":0.0,"id":17336468}]}]}
{"op":"mcm","clk":"986529219","pt":1580487019076,"mc":[{"id":"1.168136214","rc":[{"batb":[[1,1.51,3.36],[2,1.03,1676.05]],"ltp":0.0,"tv":0.0,"id":12925630},{"batb":[[0,1.65,1.99],[1,1.64,1.68],[2,1.51,3.36]],"ltp":0.0,"tv":0.0,"id":17336468},{"batb":[[0,1.65,1.99],[1,1.64,1.68]],"ltp":0.0,"tv":0.0,"id":11981493}]}]}
{"op":"mcm","clk":"986529231","pt":1580487019179,"mc":[{"id":"1.168136214","rc":[{"batb":[[0,1.65,1.99],[1,1.64,1.68],[2,1.51,3.36]],"ltp":0.0,"tv":0.0,"id":12925630}]}]}
{"op":"mcm","clk":"986530135","pt":1580487027851,"mc":[{"id":"1.168136214","rc":[{"batb":[[0,1.65,2.99]],"ltp":0.0,"tv":0.0,"id":12925630},{"batb":[[0,1.65,2.99]],"ltp":0.0,"tv":0.0,"id":17336468},{"batb":[[0,1.65,2.99]],"ltp":0.0,"tv":0.0,"id":11981493}]}]}
{"op":"mcm","clk":"986531118","pt":1580487038097,"mc":[{"id":"1.168136214","rc":[{"batb":[[1,1.51,3.36],[2,1.03,1676.05]],"ltp":0.0,"tv":0.0,"id":12925630},{"batb":[[0,1.66,1.68],[1,1.65,2.99]],"ltp":0.0,"tv":0.0,"id":17336468},{"batb":[[0,1.66,1.68],[1,1.65,2.99]],"ltp":0.0,"tv":0.0,"id":11981493}]}]}
{"op":"mcm","clk":"986531130","pt":1580487038204,"mc":[{"id":"1.168136214","rc":[{"batb":[[0,1.66,1.68],[1,1.65,2.99],[2,1.51,3.36]],"ltp":0.0,"tv":0.0,"id":12925630}]}]}
{"op":"mcm","clk":"986532862","pt":1580487056538,"mc":[{"id":"1.168136214","rc":[{"batb":[[0,1.66,11.68]],"ltp":0.0,"tv":0.0,"id":12925630},{"batb":[[0,1.66,11.68]],"ltp":0.0,"tv":0.0,"id":17336468},{"batb":[[0,1.66,11.68]],"ltp":0.0,"tv":0.0,"id":11981493}]}]}
{"op":"mcm","clk":"986534456","pt":1580487072844,"mc":[{"id":"1.168136214","rc":[{"batb":[[0,1.67,1.99],[1,1.66,11.68],[2,1.51,4.36]],"ltp":0.0,"tv":0.0,"id":17336468},{"batb":[[0,1.67,1.99],[1,1.66,11.68],[2,1.51,4.36]],"ltp":0.0,"tv":0.0,"id":11981493}]}]}
{"op":"mcm","clk":"986534524","pt":1580487073573,"mc":[{"id":"1.168136214","rc":[{"batb":[[0,1.67,1.99],[1,1.66,11.68],[2,1.51,4.36]],"ltp":0.0,"tv":0.0,"id":12925630}]}]}
{"op":"mcm","clk":"986534872","pt":1580487076800,"mc":[{"id":"1.168136214","rc":[{"batb":[[0,1.67,8.79]],"ltp":0.0,"tv":0.0,"id":12925630},{"batb":[[0,1.67,8.79]],"ltp":0.0,"tv":0.0,"id":17336468},{"batb":[[0,1.67,8.79]],"ltp":0.0,"tv":0.0,"id":11981493}]}]}
{"op":"mcm","clk":"986535729","pt":1580487086049,"mc":[{"id":"1.168136214","rc":[{"batb":[[1,1.66,10]],"ltp":0.0,"tv":0.0,"id":12925630},{"batb":[[0,1.68,1.68],[1,1.67,8.79],[2,1.66,10]],"ltp":0.0,"tv":0.0,"id":17336468},{"batb":[[0,1.68,1.68],[1,1.67,8.79],[2,1.66,10]],"ltp":0.0,"tv":0.0,"id":11981493}]}]}
{"op":"mcm","clk":"986535741","pt":1580487086157,"mc":[{"id":"1.168136214","rc":[{"batb":[[0,1.68,1.68],[1,1.67,8.79],[2,1.66,10]],"ltp":0.0,"tv":0.0,"id":12925630}]}]}
{"op":"mcm","clk":"986538384","pt":1580487113038,"mc":[{"id":"1.168136214","rc":[{"batb":[[0,1.69,1.99],[1,1.68,1.68],[2,1.67,6.8]],"ltp":0.0,"tv":0.0,"id":17336468}]}]}
{"op":"mcm","clk":"986538523","pt":1580487114139,"mc":[{"id":"1.168136214","rc":[{"batb":[[0,1.69,1.99],[1,1.68,1.68],[2,1.67,6.8]],"ltp":0.0,"tv":0.0,"id":12925630},{"batb":[[0,1.69,1.99],[1,1.68,1.68],[2,1.67,6.8]],"ltp":0.0,"tv":0.0,"id":11981493}]}]}
{"op":"mcm","clk":"986539445","pt":1580487123155,"mc":[{"id":"1.168136214","rc":[{"batb":[[0,1.7,1.68],[1,1.69,1.99]],"ltp":0.0,"tv":0.0,"id":17336468}]}]}
{"op":"mcm","clk":"986539535","pt":1580487123837,"mc":[{"id":"1.168136214","rc":[{"batb":[[0,1.7,1.68],[1,1.69,1.99]],"ltp":0.0,"tv":0.0,"id":12925630},{"batb":[[0,1.7,1.68],[1,1.69,1.99]],"ltp":0.0,"tv":0.0,"id":11981493}]}]}
{"op":"mcm","clk":"986539750","pt":1580487125743,"mc":[{"id":"1.168136214","rc":[{"batb":[[0,1.7,11.68]],"ltp":0.0,"tv":0.0,"id":12925630},{"batb":[[0,1.7,11.68]],"ltp":0.0,"tv":0.0,"id":17336468},{"batb":[[0,1.7,11.68]],"ltp":0.0,"tv":0.0,"id":11981493}]}]}
{"op":"mcm","clk":"986540861","pt":1580487136663,"mc":[{"id":"1.168136214","rc":[{"batb":[[0,1.71,6.41],[1,1.7,11.68],[2,1.69,1.99]],"ltp":0.0,"tv":0.0,"id":12925630},{"batb":[[0,1.71,6.41],[1,1.7,11.68],[2,1.69,1.99]],"ltp":0.0,"tv":0.0,"id":17336468},{"batb":[[0,1.71,6.41],[1,1.7,11.68],[2,1.69,1.99]],"ltp":0.0,"tv":0.0,"id":11981493}]}]}
{"op":"mcm","clk":"986543330","pt":1580487160790,"mc":[{"id":"1.168136214","rc":[{"batb":[[0,1.71,7.37]],"ltp":0.0,"tv":0.0,"id":12925630},{"batb":[[0,1.71,7.37]],"ltp":0.0,"tv":0.0,"id":17336468},{"batb":[[0,1.71,7.37]],"ltp":0.0,"tv":0.0,"id":11981493}]}]}
{"op":"mcm","clk":"986543478","pt":1580487162110,"mc":[{"id":"1.168136214","rc":[{"batb":[[2,1.51,3.36]],"ltp":0.0,"tv":0.0,"id":12925630},{"batb":[[0,1.73,1.99],[1,1.71,7.37],[2,1.7,11.68]],"ltp":0.0,"tv":0.0,"id":17336468},{"batb":[[0,1.73,1.99],[1,1.71,7.37],[2,1.7,11.68]],"ltp":0.0,"tv":0.0,"id":11981493}]}]}
{"op":"mcm","clk":"986543485","pt":1580487162166,"mc":[{"id":"1.168136214","rc":[{"batb":[[0,1.73,1.99],[1,1.71,7.37],[2,1.7,11.68]],"ltp":0.0,"tv":0.0,"id":12925630}]}]}
{"op":"mcm","clk":"986545868","pt":1580487184152,"mc":[{"id":"1.168136214","rc":[{"batb":[[2,1.7,10]],"ltp":0.0,"tv":0.0,"id":12925630},{"batb":[[0,1.74,1.68],[1,1.73,1.99],[2,1.71,7.37]],"ltp":0.0,"tv":0.0,"id":17336468},{"batb":[[0,1.74,1.68],[1,1.73,1.99],[2,1.71,7.37]],"ltp":0.0,"tv":0.0,"id":11981493}]}]}
{"op":"mcm","clk":"986545876","pt":1580487184260,"mc":[{"id":"1.168136214","rc":[{"batb":[[0,1.74,1.68],[1,1.73,1.99],[2,1.71,7.37]],"ltp":0.0,"tv":0.0,"id":12925630}]}]}
{"op":"mcm","clk":"986546946","pt":1580487194890,"mc":[{"id":"1.168136214","rc":[{"batb":[[0,1.74,11.68]],"ltp":0.0,"tv":0.0,"id":12925630},{"batb":[[0,1.74,11.68]],"ltp":0.0,"tv":0.0,"id":17336468},{"batb":[[0,1.74,11.68]],"ltp":0.0,"tv":0.0,"id":11981493}]}]}
{"op":"mcm","clk":"986547116","pt":1580487196555,"mc":[{"id":"1.168136214","rc":[{"batb":[[0,1.75,6.07],[1,1.74,11.68],[2,1.73,1.99]],"ltp":0.0,"tv":0.0,"id":12925630},{"batb":[[0,1.75,6.07],[1,1.74,11.68],[2,1.73,1.99]],"ltp":0.0,"tv":0.0,"id":17336468},{"batb":[[0,1.75,6.07],[1,1.74,11.68],[2,1.73,1.99]],"ltp":0.0,"tv":0.0,"id":11981493}]}]}
{"op":"mcm","clk":"986548200","pt":1580487207978,"mc":[{"id":"1.168136214","rc":[{"batb":[[0,1.76,1.99],[1,1.75,6.07],[2,1.74,11.68]],"ltp":0.0,"tv":0.0,"id":17336468},{"batb":[[0,1.76,1.99],[1,1.75,6.07],[2,1.74,11.68]],"ltp":0.0,"tv":0.0,"id":11981493}]}]}
{"op":"mcm","clk":"986548235","pt":1580487208395,"mc":[{"id":"1.168136214","rc":[{"batb":[[0,1.76,1.99],[1,1.75,6.07],[2,1.74,11.68]],"ltp":0.0,"tv":0.0,"id":12925630}]}]}
{"op":"mcm","clk":"986550175","pt":1580487227050,"mc":[{"id":"1.168136214","rc":[{"batb":[[0,1.77,1.68],[1,1.76,1.99],[2,1.75,6.07]],"ltp":0.0,"tv":0.0,"id":12925630},{"batb":[[0,1.77,1.68],[1,1.76,1.99],[2,1.75,6.07]],"ltp":0.0,"tv":0.0,"id":17336468},{"batb":[[0,1.77,1.68],[1,1.76,1.99],[2,1.75,6.07]],"ltp":0.0,"tv":0.0,"id":11981493}]}]}
{"op":"mcm","clk":"986553044","pt":1580487254061,"mc":[{"id":"1.168136214","rc":[{"batb":[[1,1.75,6.07],[2,1.74,10]],"ltp":0.0,"tv":0.0,"id":17336468}]}]}
{"op":"mcm","clk":"986553125","pt":1580487254859,"mc":[{"id":"1.168136214","rc":[{"batb":[[0,1.78,1.99],[1,1.77,1.68],[2,1.75,6.07]],"ltp":0.0,"tv":0.0,"id":17336468},{"batb":[[0,1.78,1.99],[1,1.77,1.68]],"ltp":0.0,"tv":0.0,"id":11981493}]}]}
{"op":"mcm","clk":"986553188","pt":1580487255443,"mc":[{"id":"1.168136214","rc":[{"batb":[[0,1.78,1.99],[1,1.77,1.68]],"ltp":0.0,"tv":0.0,"id":12925630}]}]}
{"op":"mcm","clk":"986554110","pt":1580487264537,"mc":[{"id":"1.168136214","rc":[{"batb":[[0,1.78,11.99]],"ltp":0.0,"tv":0.0,"id":12925630},{"batb":[[0,1.78,11.99]],"ltp":0.0,"tv":0.0,"id":17336468},{"batb":[[0,1.78,11.99]],"ltp":0.0,"tv":0.0,"id":11981493}]}]}
{"op":"mcm","clk":"986554759","pt":1580487270947,"mc":[{"id":"1.168136214","rc":[{"batb":[[0,1.79,1.68],[1,1.78,11.99]],"ltp":0.0,"tv":0.0,"id":17336468},{"batb":[[0,1.79,1.68],[1,1.78,11.99]],"ltp":0.0,"tv":0.0,"id":11981493}]}]}
{"op":"mcm","clk":"986554792","pt":1580487271372,"mc":[{"id":"1.168136214","rc":[{"batb":[[0,1.79,1.68],[1,1.78,11.99]],"ltp":0.0,"tv":0.0,"id":12925630}]}]}
{"op":"mcm","clk":"986556262","pt":1580487286868,"mc":[{"id":"1.168136214","rc":[{"batb":[[0,1.79,7.44],[2,1.51,3.36]],"ltp":0.0,"tv":0.0,"id":12925630},{"batb":[[0,1.79,7.44],[2,1.51,3.36]],"ltp":0.0,"tv":0.0,"id":17336468},{"batb":[[0,1.79,7.44],[2,1.51,3.36]],"ltp":0.0,"tv":0.0,"id":11981493}]}]}
{"op":"mcm","clk":"986557047","pt":1580487294580,"mc":[{"id":"1.168136214","rc":[{"batb":[[0,1.79,8.36]],"ltp":0.0,"tv":0.0,"id":12925630},{"batb":[[0,1.79,8.36]],"ltp":0.0,"tv":0.0,"id":17336468},{"batb":[[0,1.79,8.36]],"ltp":0.0,"tv":0.0,"id":11981493}]}]}
{"op":"mcm","clk":"986557164","pt":1580487295994,"mc":[{"id":"1.168136214","rc":[{"batb":[[1,1.78,10]],"ltp":0.0,"tv":0.0,"id":17336468}]}]}
{"op":"mcm","clk":"986557256","pt":1580487296893,"mc":[{"id":"1.168136214","rc":[{"batb":[[0,1.81,1.99],[1,1.79,8.36],[2,1.78,10]],"ltp":0.0,"tv":0.0,"id":12925630},{"batb":[[0,1.81,1.99],[1,1.79,8.36],[2,1.78,10]],"ltp":0.0,"tv":0.0,"id":17336468},{"batb":[[0,1.81,1.99],[1,1.79,8.36],[2,1.78,10]],"ltp":0.0,"tv":0.0,"id":11981493}]}]}
{"op":"mcm","clk":"986559497","pt":1580487319047,"mc":[{"id":"1.168136214","rc":[{"batb":[[0,1.82,1.68],[1,1.81,1.99],[2,1.79,6.67]],"ltp":0.0,"tv":0.0,"id":17336468}]}]}
{"op":"mcm","clk":"986559572","pt":1580487319733,"mc":[{"id":"1.168136214","rc":[{"batb":[[0,1.82,1.68],[1,1.81,1.99],[2,1.79,6.67]],"ltp":0.0,"tv":0.0,"id":12925630},{"batb":[[0,1.82,1.68],[1,1.81,1.99],[2,1.79,6.67]],"ltp":0.0,"tv":0.0,"id":11981493}]}]}
{"op":"mcm","clk":"986561113","pt":1580487333664,"mc":[{"id":"1.168136214","rc":[{"batb":[[0,1.82,11.68]],"ltp":0.0,"tv":0.0,"id":12925630},{"batb":[[0,1.82,11.68]],"ltp":0.0,"tv":0.0,"id":17336468},{"batb":[[0,1.82,11.68]],"ltp":0.0,"tv":0.0,"id":11981493}]}]}
{"op":"mcm","clk":"986561702","pt":1580487338848,"mc":[{"id":"1.168136214","rc":[{"batb":[[0,1.83,1.99],[1,1.82,11.68]],"ltp":0.0,"tv":0.0,"id":17336468}]}]}
{"op":"mcm","clk":"986561787","pt":1580487339641,"mc":[{"id":"1.168136214","rc":[{"batb":[[0,1.83,1.99],[1,1.82,11.68]],"ltp":0.0,"tv":0.0,"id":12925630},{"batb":[[0,1.83,1.99],[1,1.82,11.68]],"ltp":0.0,"tv":0.0,"id":11981493}]}]}
{"op":"mcm","clk":"986562592","pt":1580487346887,"mc":[{"id":"1.168136214","rc":[{"batb":[[0,1.83,7.48],[2,1.51,4.28]],"ltp":0.0,"tv":0.0,"id":12925630},{"batb":[[0,1.83,7.48],[2,1.51,4.28]],"ltp":0.0,"tv":0.0,"id":17336468},{"batb":[[0,1.83,7.48],[2,1.51,4.28]],"ltp":0.0,"tv":0.0,"id":11981493}]}]}
{"op":"mcm","clk":"986565128","pt":1580487371083,"mc":[{"id":"1.168136214","rc":[{"batb":[[0,1.84,1.68],[1,1.83,7.48],[2,1.82,10]],"ltp":0.0,"tv":0.0,"id":12925630},{"batb":[[0,1.84,1.68],[1,1.83,7.48],[2,1.82,10]],"ltp":0.0,"tv":0.0,"id":17336468},{"batb":[[0,1.84,1.68],[1,1.83,7.48],[2,1.82,10]],"ltp":0.0,"tv":0.0,"id":11981493}]}]}
{"op":"mcm","clk":"986565784","pt":1580487378096,"mc":[{"id":"1.168136214","rc":[{"batb":[[0,1.85,1.99],[1,1.84,1.68],[2,1.83,5.49]],"ltp":0.0,"tv":0.0,"id":12925630},{"batb":[[0,1.85,1.99],[1,1.84,1.68],[2,1.83,5.49]],"ltp":0.0,"tv":0.0,"id":17336468},{"batb":[[0,1.85,1.99],[1,1.84,1.68],[2,1.83,5.49]],"ltp":0.0,"tv":0.0,"id":11981493}]}]}
{"op":"mcm","clk":"986568305","pt":1580487405143,"mc":[{"id":"1.168136214","rc":[{"batb":[[0,1.86,1.68],[1,1.85,1.99]],"ltp":0.0,"tv":0.0,"id":12925630},{"batb":[[0,1.86,1.68],[1,1.85,1.99]],"ltp":0.0,"tv":0.0,"id":17336468},{"batb":[[0,1.86,1.68],[1,1.85,1.99]],"ltp":0.0,"tv":0.0,"id":11981493}]}]}
{"op":"mcm","clk":"986570110","pt":1580487425045,"mc":[{"id":"1.168136214","rc":[{"batb":[[0,1.87,1.99],[1,1.86,1.68]],"ltp":0.0,"tv":0.0,"id":17336468},{"batb":[[0,1.87,1.99],[1,1.86,1.68]],"ltp":0.0,"tv":0.0,"id":11981493}]}]}
{"op":"mcm","clk":"986570146","pt":1580487425415,"mc":[{"id":"1.168136214","rc":[{"batb":[[0,1.87,1.99],[1,1.86,1.68]],"ltp":0.0,"tv":0.0,"id":12925630}]}]}
{"op":"mcm","clk":"986571553","pt":1580487440048,"mc":[{"id":"1.168136214","rc":[{"batb":[[0,1.87,2.87]],"ltp":0.0,"tv":0.0,"id":12925630},{"batb":[[0,1.87,2.87]],"ltp":0.0,"tv":0.0,"id":17336468},{"batb":[[0,1.87,2.87]],"ltp":0.0,"tv":0.0,"id":11981493}]}]}
{"op":"mcm","clk":"986583214","pt":1580487463092,"mc":[{"id":"1.168136214","rc":[{"batb":[[0,1.88,1.68],[1,1.87,2.87]],"ltp":0.0,"tv":0.0,"id":17336468},{"batb":[[0,1.88,1.68],[1,1.87,2.87]],"ltp":0.0,"tv":0.0,"id":11981493}]}]}
{"op":"mcm","clk":"986583304","pt":1580487463893,"mc":[{"id":"1.168136214","rc":[{"batb":[[0,1.88,1.68],[1,1.87,2.87]],"ltp":0.0,"tv":0.0,"id":12925630}]}]}
{"op":"mcm","clk":"986584202","pt":1580487472919,"mc":[{"id":"1.168136214","rc":[{"batb":[[0,1.89,1.99],[1,1.88,1.68],[2,1.83,6.37]],"ltp":0.0,"tv":0.0,"id":17336468},{"batb":[[0,1.89,1.99],[1,1.88,1.68],[2,1.83,6.37]],"ltp":0.0,"tv":0.0,"id":11981493}]}]}
{"op":"mcm","clk":"986584275","pt":1580487473714,"mc":[{"id":"1.168136214","rc":[{"batb":[[0,1.89,1.99],[1,1.88,1.68],[2,1.83,6.37]],"ltp":0.0,"tv":0.0,"id":12925630}]}]}
{"op":"mcm","clk":"986593338","pt":1580487574103,"mc":[{"id":"1.168136214","rc":[{"batb":[[1,1.83,6.37],[2,1.51,3.36]],"ltp":0.0,"tv":0.0,"id":17336468}]}]}
{"op":"mcm","clk":"986593404","pt":1580487575004,"mc":[{"id":"1.168136214","rc":[{"batb":[[0,1.9,1.68],[1,1.89,1.99]],"ltp":0.0,"tv":0.0,"id":12925630},{"batb":[[0,1.9,1.68],[1,1.89,1.99],[2,1.83,6.37]],"ltp":0.0,"tv":0.0,"id":17336468},{"batb":[[0,1.9,1.68],[1,1.89,1.99]],"ltp":0.0,"tv":0.0,"id":11981493}]}]}
{"op":"mcm","clk":"986594992","pt":1580487596124,"mc":[{"id":"1.168136214","rc":[{"batb":[[0,1.91,1.99],[1,1.9,1.68]],"ltp":0.0,"tv":0.0,"id":17336468},{"batb":[[1,1.83,6.37],[2,1.51,3.36]],"ltp":0.0,"tv":0.0,"id":11981493}]}]}
{"op":"mcm","clk":"986595050","pt":1580487596713,"mc":[{"id":"1.168136214","rc":[{"batb":[[0,1.91,1.99],[1,1.9,1.68]],"ltp":0.0,"tv":0.0,"id":12925630},{"batb":[[0,1.91,1.99],[1,1.9,1.68],[2,1.83,6.37]],"ltp":0.0,"tv":0.0,"id":11981493}]}]}
{"op":"mcm","clk":"986601005","pt":1580487670130,"mc":[{"id":"1.168136214","rc":[{"batb":[[0,1.92,1.68],[1,1.91,1.99]],"ltp":0.0,"tv":0.0,"id":17336468}]}]}
{"op":"mcm","clk":"986601061","pt":1580487670827,"mc":[{"id":"1.168136214","rc":[{"batb":[[0,1.92,1.68],[1,1.91,1.99]],"ltp":0.0,"tv":0.0,"id":12925630},{"batb":[[0,1.92,1.68],[1,1.91,1.99]],"ltp":0.0,"tv":0.0,"id":11981493}]}]}
{"op":"mcm","clk":"986601970","pt":1580487682325,"mc":[{"id":"1.168136214","rc":[{"batb":[[0,1.92,11.68]],"ltp":0.0,"tv":0.0,"id":12925630},{"batb":[[0,1.92,11.68]],"ltp":0.0,"tv":0.0,"id":17336468},{"batb":[[0,1.92,11.68]],"ltp":0.0,"tv":0.0,"id":11981493}]}]}
{"op":"mcm","clk":"986602066","pt":1580487683642,"mc":[{"id":"1.168136214","rc":[{"batb":[[0,1.93,1.99],[1,1.92,11.68]],"ltp":0.0,"tv":0.0,"id":17336468},{"batb":[[0,1.93,1.99],[1,1.92,11.68]],"ltp":0.0,"tv":0.0,"id":11981493}]}]}
{"op":"mcm","clk":"986602082","pt":1580487684478,"mc":[{"id":"1.168136214","rc":[{"batb":[[0,1.93,1.99],[1,1.92,11.68]],"ltp":0.0,"tv":0.0,"id":12925630}]}]}
{"op":"mcm","clk":"986603608","pt":1580487706132,"mc":[{"id":"1.168136214","rc":[{"batb":[[2,1.83,5.49]],"ltp":0.0,"tv":0.0,"id":12925630},{"batb":[[2,1.83,5.49]],"ltp":0.0,"tv":0.0,"id":17336468},{"batb":[[2,1.83,5.49]],"ltp":0.0,"tv":0.0,"id":11981493}]}]}
{"op":"mcm","clk":"986603638","pt":1580487706659,"mc":[{"id":"1.168136214","rc":[{"batb":[[0,1.93,6.88],[2,1.51,3.36]],"ltp":0.0,"tv":0.0,"id":12925630},{"batb":[[0,1.93,6.88],[2,1.51,3.36]],"ltp":0.0,"tv":0.0,"id":17336468},{"batb":[[0,1.93,6.88],[2,1.51,3.36]],"ltp":0.0,"tv":0.0,"id":11981493}]}]}
{"op":"mcm","clk":"986604245","pt":1580487714924,"mc":[{"id":"1.168136214","rc":[{"batl":[[0,1000,3.56]],"ltp":0.0,"tv":0.0,"id":17336468}]}]}
{"op":"mcm","clk":"986604317","pt":1580487716076,"mc":[{"id":"1.168136214","rc":[{"batl":[[0,1000,2.3]],"ltp":0.0,"tv":0.0,"id":17336468}]}]}
{"op":"mcm","clk":"986604522","pt":1580487718865,"mc":[{"id":"1.168136214","rc":[{"batb":[[0,1.93,7.73]],"ltp":0.0,"tv":0.0,"id":12925630},{"batb":[[0,1.93,7.73]],"ltp":0.0,"tv":0.0,"id":17336468},{"batb":[[0,1.93,7.73]],"ltp":0.0,"tv":0.0,"id":11981493}]}]}
{"op":"mcm","clk":"986604606","pt":1580487720177,"mc":[{"id":"1.168136214","rc":[{"batl":[[0,1000,1.88]],"ltp":0.0,"tv":0.0,"id":17336468}]}]}
{"op":"mcm","clk":"986605227","pt":1580487729947,"mc":[{"id":"1.168136214","rc":[{"batb":[[0,1.95,1.99],[1,1.93,5.74],[2,1.92,11.68]],"ltp":0.0,"tv":0.0,"id":17336468},{"batb":[[0,1.95,1.99],[1,1.93,5.74],[2,1.92,11.68]],"ltp":0.0,"tv":0.0,"id":11981493}]}]}
{"op":"mcm","clk":"986605258","pt":1580487730471,"mc":[{"id":"1.168136214","rc":[{"batb":[[0,1.95,1.99],[1,1.93,5.74],[2,1.92,11.68]],"ltp":0.0,"tv":0.0,"id":12925630}]}]}
{"op":"mcm","clk":"986606499","pt":1580487749765,"mc":[{"id":"1.168136214","rc":[{"batb":[[2,1.92,10]],"ltp":0.0,"tv":0.0,"id":17336468}]}]}
{"op":"mcm","clk":"986606575","pt":1580487750826,"mc":[{"id":"1.168136214","rc":[{"batb":[[0,1.96,1.68],[1,1.95,1.99],[2,1.93,5.74]],"ltp":0.0,"tv":0.0,"id":12925630},{"batb":[[0,1.96,1.68],[1,1.95,1.99],[2,1.93,5.74]],"ltp":0.0,"tv":0.0,"id":17336468},{"batb":[[0,1.96,1.68],[1,1.95,1.99],[2,1.93,5.74]],"ltp":0.0,"tv":0.0,"id":11981493}]}]}
{"op":"mcm","clk":"986606628","pt":1580487751595,"mc":[{"id":"1.168136214","rc":[{"batb":[[0,1.96,11.68]],"ltp":0.0,"tv":0.0,"id":12925630},{"batb":[[0,1.96,11.68]],"ltp":0.0,"tv":0.0,"id":17336468},{"batb":[[0,1.96,11.68]],"ltp":0.0,"tv":0.0,"id":11981493}]}]}
{"op":"mcm","clk":"986607636","pt":1580487767126,"mc":[{"id":"1.168136214","rc":[{"batb":[[0,1.97,4.7],[1,1.96,11.68],[2,1.95,1.99]],"ltp":0.0,"tv":0.0,"id":12925630},{"batb":[[0,1.97,4.7],[1,1.96,11.68],[2,1.95,1.99]],"ltp":0.0,"tv":0.0,"id":17336468},{"batb":[[0,1.97,4.7],[1,1.96,11.68],[2,1.95,1.99]],"ltp":0.0,"tv":0.0,"id":11981493}]}]}
{"op":"mcm","clk":"986608181","pt":1580487775150,"mc":[{"id":"1.168136214","rc":[{"batb":[[2,1.51,4.21]],"ltp":0.0,"tv":0.0,"id":12925630},{"batb":[[0,1.98,1.99],[1,1.97,4.7],[2,1.96,11.68]],"ltp":0.0,"tv":0.0,"id":17336468},{"batb":[[0,1.98,1.99],[1,1.97,4.7],[2,1.96,11.68]],"ltp":0.0,"tv":0.0,"id":11981493}]}]}
{"op":"mcm","clk":"986608243","pt":1580487776143,"mc":[{"id":"1.168136214","rc":[{"batb":[[0,1.98,1.99],[1,1.97,4.7],[2,1.96,11.68]],"ltp":0.0,"tv":0.0,"id":12925630}]}]}
{"op":"mcm","clk":"986610887","pt":1580487817114,"mc":[{"id":"1.168136214","rc":[{"batb":[[0,1.99,1.68],[1,1.98,1.99],[2,1.97,4.7]],"ltp":0.0,"tv":0.0,"id":12925630},{"batb":[[0,1.99,1.68],[1,1.98,1.99],[2,1.97,4.7]],"ltp":0.0,"tv":0.0,"id":17336468},{"batb":[[0,1.99,1.68],[1,1.98,1.99],[2,1.97,4.7]],"ltp":0.0,"tv":0.0,"id":11981493}]}]}
{"op":"mcm","clk":"986611095","pt":1580487820420,"mc":[{"id":"1.168136214","rc":[{"batb":[[0,1.99,11.68]],"ltp":0.0,"tv":0.0,"id":12925630},{"batb":[[0,1.99,11.68]],"ltp":0.0,"tv":0.0,"id":17336468},{"batb":[[0,1.99,11.68]],"ltp":0.0,"tv":0.0,"id":11981493}]}]}
{"op":"mcm","clk":"986611557","pt":1580487826994,"mc":[{"id":"1.168136214","rc":[{"batb":[[0,2,4.55],[1,1.99,11.68],[2,1.98,1.99]],"ltp":0.0,"tv":0.0,"id":12925630},{"batb":[[0,2,4.55],[1,1.99,11.68],[2,1.98,1.99]],"ltp":0.0,"tv":0.0,"id":17336468},{"batb":[[0,2,4.55],[1,1.99,11.68],[2,1.98,1.99]],"ltp":0.0,"tv":0.0,"id":11981493}]}]}
{"op":"mcm","clk":"986613498","pt":1580487853146,"mc":[{"id":"1.168136214","rc":[{"batb":[[0,2,5.37]],"ltp":0.0,"tv":0.0,"id":12925630},{"batb":[[0,2,5.37]],"ltp":0.0,"tv":0.0,"id":17336468},{"batb":[[0,2,5.37]],"ltp":0.0,"tv":0.0,"id":11981493}]}]}
{"op":"mcm","clk":"986613853","pt":1580487856962,"mc":[{"id":"1.168136214","rc":[{"batb":[[0,2.04,1.99],[1,2,5.37],[2,1.99,11.68]],"ltp":0.0,"tv":0.0,"id":17336468}]}]}
{"op":"mcm","clk":"986613905","pt":1580487857642,"mc":[{"id":"1.168136214","rc":[{"batb":[[0,2.04,1.99],[1,2,5.37],[2,1.99,11.68]],"ltp":0.0,"tv":0.0,"id":12925630},{"batb":[[0,2.04,1.99],[1,2,5.37],[2,1.99,11.68]],"ltp":0.0,"tv":0.0,"id":11981493}]}]}
{"op":"mcm","clk":"986615942","pt":1580487887797,"mc":[{"id":"1.168136214","rc":[{"batb":[[0,2.06,1.68],[1,2.04,1.99],[2,2,5.37]],"ltp":0.0,"tv":0.0,"id":12925630},{"batb":[[0,2.06,1.68],[1,2.04,1.99],[2,2,5.37]],"ltp":0.0,"tv":0.0,"id":11981493}]}]}
{"op":"mcm","clk":"986616056","pt":1580487889474,"mc":[{"id":"1.168136214","rc":[{"batb":[[0,2.06,11.39]],"ltp":0.0,"tv":0.0,"id":12925630},{"batb":[[0,2.04,11.79],[2,1.99,1.68]],"ltp":0.0,"tv":0.0,"id":17336468},{"batb":[[0,2.06,11.39]],"ltp":0.0,"tv":0.0,"id":11981493}]}]}
{"op":"mcm","clk":"986616719","pt":1580487899091,"mc":[{"id":"1.168136214","rc":[{"batb":[[1,2,5.37],[2,1.51,3.36]],"ltp":0.0,"tv":0.0,"id":11981493}]}]}
{"op":"mcm","clk":"986616756","pt":1580487899617,"mc":[{"id":"1.168136214","rc":[{"batb":[[0,2.08,1.99],[1,2.06,11.39]],"ltp":0.0,"tv":0.0,"id":12925630},{"batb":[[0,2.08,1.99],[1,2.06,11.39],[2,2,5.37]],"ltp":0.0,"tv":0.0,"id":11981493}]}]}
{"op":"mcm","clk":"986617901","pt":1580487916742,"mc":[{"id":"1.168136214","rc":[{"batb":[[0,2.08,6.21],[2,1.51,4.18]],"ltp":0.0,"tv":0.0,"id":12925630},{"batb":[[0,2.06,4.29],[1,2.04,11.79],[2,1.99,2.5]],"ltp":0.0,"tv":0.0,"id":17336468},{"batb":[[0,2.08,6.21],[2,1.51,4.18]],"ltp":0.0,"tv":0.0,"id":11981493}]}]}
{"op":"mcm","clk":"986619141","pt":1580487936929,"mc":[{"id":"1.168136214","rc":[{"batb":[[0,2.08,1.99],[1,2.06,4.29],[2,2.04,9.8]],"ltp":0.0,"tv":0.0,"id":17336468}]}]}
{"op":"mcm","clk":"986620039","pt":1580487953688,"mc":[{"id":"1.168136214","rc":[{"batb":[[0,2.1,1.68],[1,2.08,6.21],[2,2.06,9.71]],"ltp":0.0,"tv":0.0,"id":12925630},{"batb":[[0,2.1,1.68],[1,2.08,6.21],[2,2.06,9.71]],"ltp":0.0,"tv":0.0,"id":11981493}]}]}
{"op":"mcm","clk":"986620356","pt":1580487958782,"mc":[{"id":"1.168136214","rc":[{"batb":[[2,1.51,4.18]],"ltp":0.0,"tv":0.0,"id":12925630},{"batb":[[2,1.99,2.5]],"ltp":0.0,"tv":0.0,"id":17336468},{"batb":[[2,1.51,4.18]],"ltp":0.0,"tv":0.0,"id":11981493}]}]}
{"op":"mcm","clk":"986620381","pt":1580487959196,"mc":[{"id":"1.168136214","rc":[{"batb":[[0,2.1,11.2]],"ltp":0.0,"tv":0.0,"id":12925630},{"batb":[[0,2.08,11.61]],"ltp":0.0,"tv":0.0,"id":17336468},{"batb":[[0,2.1,11.2]],"ltp":0.0,"tv":0.0,"id":11981493}]}]}
{"op":"mcm","clk":"986621363","pt":1580487976090,"mc":[{"id":"1.168136214","rc":[{"batb":[[0,2.12,1.99],[1,2.1,11.2],[2,2.08,4.22]],"ltp":0.0,"tv":0.0,"id":11981493}]}]}
{"op":"mcm","clk":"986621384","pt":1580487976645,"mc":[{"id":"1.168136214","rc":[{"batb":[[0,2.12,6.06],[1,2.1,11.2]],"ltp":0.0,"tv":0.0,"id":12925630},{"batb":[[0,2.1,4.14],[1,2.08,11.61]],"ltp":0.0,"tv":0.0,"id":17336468},{"batb":[[0,2.12,6.06],[2,1.51,4.18]],"ltp":0.0,"tv":0.0,"id":11981493}]}]}
{"op":"mcm","clk":"986622769","pt":1580487997316,"mc":[{"id":"1.168136214","rc":[{"batb":[[2,1.51,3.36]],"ltp":0.0,"tv":0.0,"id":12925630},{"batb":[[2,1.51,3.36]],"ltp":0.0,"tv":0.0,"id":11981493}]}]}
{"op":"mcm","clk":"986623929","pt":1580488016844,"mc":[{"id":"1.168136214","rc":[{"batb":[[0,2.12,4.07]],"ltp":0.0,"tv":0.0,"id":12925630},{"batb":[[0,2.12,1.99],[1,2.1,4.14],[2,2.08,9.62]],"ltp":0.0,"tv":0.0,"id":17336468},{"batb":[[0,2.12,4.07]],"ltp":0.0,"tv":0.0,"id":11981493}]}]}
{"op":"mcm","clk":"986624723","pt":1580488028394,"mc":[{"id":"1.168136214","rc":[{"batb":[[0,2.12,11.42],[2,1.99,2.5]],"ltp":0.0,"tv":0.0,"id":17336468}]}]}
{"op":"mcm","clk":"986625068","pt":1580488033983,"mc":[{"id":"1.168136214","rc":[{"batb":[[0,2.14,1.68],[1,2.12,4.07],[2,2.1,9.52]],"ltp":0.0,"tv":0.0,"id":12925630},{"batb":[[0,2.14,1.68],[1,2.12,4.07],[2,2.1,9.52]],"ltp":0.0,"tv":0.0,"id":11981493}]}]}
{"op":"mcm","clk":"986625240","pt":1580488036862,"mc":[{"id":"1.168136214","rc":[{"batb":[[0,2.14,3.99],[1,2.12,11.42]],"ltp":0.0,"tv":0.0,"id":17336468}]}]}
{"op":"mcm","clk":"986625792","pt":1580488046277,"mc":[{"id":"1.168136214","rc":[{"batb":[[2,1.99,1.68]],"ltp":0.0,"tv":0.0,"id":17336468}]}]}
{"op":"mcm","clk":"986626600","pt":1580488058625,"mc":[{"id":"1.168136214","rc":[{"batb":[[0,2.14,2.45]],"ltp":0.0,"tv":0.0,"id":12925630},{"batb":[[0,2.14,4.75]],"ltp":0.0,"tv":0.0,"id":17336468},{"batb":[[0,2.14,2.45]],"ltp":0.0,"tv":0.0,"id":11981493}]}]}
{"op":"mcm","clk":"986626721","pt":1580488060116,"mc":[{"id":"1.168136214","rc":[{"batb":[[0,2.18,1.99],[1,2.14,4.75],[2,2.12,9.43]],"ltp":0.0,"tv":0.0,"id":17336468}]}]}
{"op":"mcm","clk":"986626807","pt":1580488060735,"mc":[{"id":"1.168136214","rc":[{"batb":[[0,2.16,1.99],[1,2.14,2.45],[2,2.12,4.07]],"ltp":0.0,"tv":0.0,"id":12925630},{"batb":[[0,2.16,1.99],[1,2.14,2.45],[2,2.12,4.07]],"ltp":0.0,"tv":0.0,"id":11981493}]}]}
{"op":"mcm","clk":"986629559","pt":1580488095066,"mc":[{"id":"1.168136214","rc":[{"batb":[[1,2.12,4.84],[2,2.1,9.52]],"ltp":0.0,"tv":0.0,"id":11981493}]}]}
{"op":"mcm","clk":"986629593","pt":1580488095497,"mc":[{"id":"1.168136214","rc":[{"batb":[[0,2.18,1.68],[1,2.16,1.99],[2,2.12,4.84]],"ltp":0.0,"tv":0.0,"id":12925630},{"batb":[[0,2.18,1.68],[1,2.16,1.99],[2,2.12,4.84]],"ltp":0.0,"tv":0.0,"id":11981493}]}]}
{"op":"mcm","clk":"986629759","pt":1580488097348,"mc":[{"id":"1.168136214","rc":[{"batb":[[0,2.18,10.85]],"ltp":0.0,"tv":0.0,"id":12925630},{"batb":[[0,2.18,11.16],[2,1.99,1.68]],"ltp":0.0,"tv":0.0,"id":17336468},{"batb":[[0,2.18,10.85]],"ltp":0.0,"tv":0.0,"id":11981493}]}]}
{"op":"mcm","clk":"986630143","pt":1580488102683,"mc":[{"id":"1.168136214","rc":[{"batb":[[0,2.2,1.99],[1,2.18,10.85]],"ltp":0.0,"tv":0.0,"id":12925630},{"batb":[[0,2.2,1.99],[1,2.18,10.85]],"ltp":0.0,"tv":0.0,"id":11981493}]}]}
{"op":"mcm","clk":"986631933","pt":1580488126803,"mc":[{"id":"1.168136214","rc":[{"batb":[[0,2.2,5.78],[2,1.51,4.13]],"ltp":0.0,"tv":0.0,"id":12925630},{"batb":[[0,2.2,3.79],[1,2.18,11.16],[2,1.99,2.44]],"ltp":0.0,"tv":0.0,"id":17336468},{"batb":[[0,2.2,5.78],[2,1.51,4.13]],"ltp":0.0,"tv":0.0,"id":11981493}]}]}
{"op":"mcm","clk":"986633307","pt":1580488143120,"mc":[{"id":"1.168136214","rc":[{"batb":[[1,2.18,9.17]],"ltp":0.0,"tv":0.0,"id":17336468}]}]}
{"op":"mcm","clk":"986633343","pt":1580488143538,"mc":[{"id":"1.168136214","rc":[{"batb":[[0,2.22,1.99],[1,2.2,3.79],[2,2.18,9.17]],"ltp":0.0,"tv":0.0,"id":17336468}]}]}
{"op":"mcm","clk":"986634701","pt":1580488166536,"mc":[{"id":"1.168136214","rc":[{"batb":[[0,2.22,11],[2,1.99,2.44]],"ltp":0.0,"tv":0.0,"id":17336468}]}]}
{"op":"mcm","clk":"986635313","pt":1580488177774,"mc":[{"id":"1.168136214","rc":[{"batb":[[0,2.22,1.68],[1,2.2,5.78],[2,2.18,9.17]],"ltp":0.0,"tv":0.0,"id":12925630},{"batb":[[0,2.22,1.68],[1,2.2,5.78],[2,2.18,9.17]],"ltp":0.0,"tv":0.0,"id":11981493}]}]}
{"op":"mcm","clk":"986635712","pt":1580488186404,"mc":[{"id":"1.168136214","rc":[{"batb":[[0,2.24,3.67],[1,2.22,11]],"ltp":0.0,"tv":0.0,"id":17336468}]}]}
{"op":"mcm","clk":"986636240","pt":1580488196100,"mc":[{"id":"1.168136214","rc":[{"batb":[[1,2.2,3.79]],"ltp":0.0,"tv":0.0,"id":12925630},{"batb":[[0,2.26,1.99],[1,2.24,3.67],[2,2.22,9.01]],"ltp":0.0,"tv":0.0,"id":17336468},{"batb":[[0,2.24,1.99],[1,2.22,1.68],[2,2.2,3.79]],"ltp":0.0,"tv":0.0,"id":11981493}]}]}
{"op":"mcm","clk":"986636243","pt":1580488196207,"mc":[{"id":"1.168136214","rc":[{"batb":[[0,2.24,1.99],[1,2.22,1.68],[2,2.2,3.79]],"ltp":0.0,"tv":0.0,"id":12925630}]}]}
{"op":"mcm","clk":"986637631","pt":1580488225125,"mc":[{"id":"1.168136214","rc":[{"batb":[[1,2.2,3.79],[2,2.18,9.17]],"ltp":0.0,"tv":0.0,"id":11981493}]}]}
{"op":"mcm","clk":"986637656","pt":1580488225536,"mc":[{"id":"1.168136214","rc":[{"batb":[[0,2.26,1.68],[1,2.24,1.99]],"ltp":0.0,"tv":0.0,"id":12925630},{"batb":[[0,2.26,1.68],[1,2.24,1.99],[2,2.2,3.79]],"ltp":0.0,"tv":0.0,"id":11981493}]}]}
{"op":"mcm","clk":"986638200","pt":1580488236147,"mc":[{"id":"1.168136214","rc":[{"batb":[[0,2.26,10.53]],"ltp":0.0,"tv":0.0,"id":12925630},{"batb":[[0,2.26,10.84],[2,1.99,2.44]],"ltp":0.0,"tv":0.0,"id":17336468},{"batb":[[0,2.26,10.53]],"ltp":0.0,"tv":0.0,"id":11981493}]}]}
{"op":"mcm","clk":"986638429","pt":1580488240066,"mc":[{"id":"1.168136214","rc":[{"batb":[[2,1.99,1.68]],"ltp":0.0,"tv":0.0,"id":17336468}]}]}
{"op":"mcm","clk":"986638830","pt":1580488246791,"mc":[{"id":"1.168136214","rc":[{"batb":[[0,2.28,3.56],[1,2.26,10.53],[2,2.24,1.99]],"ltp":0.0,"tv":0.0,"id":12925630},{"batb":[[0,2.28,3.56],[1,2.26,10.84]],"ltp":0.0,"tv":0.0,"id":17336468},{"batb":[[0,2.28,3.56],[1,2.26,10.53],[2,2.24,1.99]],"ltp":0.0,"tv":0.0,"id":11981493}]}]}
{"op":"mcm","clk":"986639193","pt":1580488252581,"mc":[{"id":"1.168136214","rc":[{"batb":[[0,2.28,4.27]],"ltp":0.0,"tv":0.0,"id":12925630},{"batb":[[0,2.28,4.27]],"ltp":0.0,"tv":0.0,"id":17336468},{"batb":[[0,2.28,4.27]],"ltp":0.0,"tv":0.0,"id":11981493}]}]}
{"op":"mcm","clk":"986640150","pt":1580488268702,"mc":[{"id":"1.168136214","rc":[{"batb":[[0,2.32,1.99],[1,2.28,4.27],[2,2.26,8.85]],"ltp":0.0,"tv":0.0,"id":17336468}]}]}
{"op":"mcm","clk":"986640210","pt":1580488269730,"mc":[{"id":"1.168136214","rc":[{"batb":[[0,2.32,1.99],[1,2.28,4.27],[2,2.26,10.53]],"ltp":0.0,"tv":0.0,"id":12925630},{"batb":[[0,2.32,1.99],[1,2.28,4.27],[2,2.26,10.53]],"ltp":0.0,"tv":0.0,"id":11981493}]}]}
{"op":"mcm","clk":"986641810","pt":1580488299153,"mc":[{"id":"1.168136214","rc":[{"batb":[[0,2.34,1.68],[1,2.32,1.99],[2,2.28,4.27]],"ltp":0.0,"tv":0.0,"id":12925630},{"trd":[[2.32,3.98]],"batb":[[0,2.28,4.27],[1,2.26,8.85],[2,1.51,3.36]],"batl":[[0,990,0.2]],"ltp":2.32,"tv":3.98,"id":17336468},{"batb":[[0,2.34,1.68],[1,2.32,1.99],[2,2.28,4.27]],"ltp":0.0,"tv":0.0,"id":11981493}],"tv":3.98}]}
{"op":"mcm","clk":"986642013","pt":1580488302650,"mc":[{"id":"1.168136214","rc":[{"batb":[[1,1.51,3.36],[2,1.03,1593.64]],"ltp":2.32,"tv":3.98,"id":17336468}]}]}
{"op":"mcm","clk":"986642671","pt":1580488313570,"mc":[{"id":"1.168136214","rc":[{"batl":[[0,1000,0.2]],"ltp":2.32,"tv":3.98,"id":17336468}]}]}
{"op":"mcm","clk":"986642850","pt":1580488316862,"mc":[{"id":"1.168136214","rc":[{"batb":[[1,2.24,3],[2,1.51,3.36]],"ltp":2.32,"tv":3.98,"id":17336468}]}]}
{"op":"mcm","clk":"986642919","pt":1580488318058,"mc":[{"id":"1.168136214","rc":[{"batb":[[0,2.36,1.99],[1,2.34,1.68]],"ltp":0.0,"tv":0.0,"id":11981493}]}]}
{"op":"mcm","clk":"986642951","pt":1580488318477,"mc":[{"id":"1.168136214","rc":[{"batb":[[0,2.36,1.99],[1,2.34,1.68]],"ltp":0.0,"tv":0.0,"id":12925630}]}]}
{"op":"mcm","clk":"986656217","pt":1580488382553,"mc":[{"id":"1.168136214","rc":[{"batb":[[2,2.28,7.27]],"ltp":0.0,"tv":0.0,"id":12925630},{"batb":[[2,1.52,3]],"ltp":2.32,"tv":3.98,"id":17336468},{"batb":[[2,2.28,7.27]],"ltp":0.0,"tv":0.0,"id":11981493}]}]}
{"op":"mcm","clk":"986657700","pt":1580488406152,"mc":[{"id":"1.168136214","rc":[{"batb":[[1,2.28,7.27],[2,1.51,3.36]],"ltp":0.0,"tv":0.0,"id":12925630},{"batb":[[2,1.53,4.84]],"ltp":2.32,"tv":3.98,"id":17336468},{"batb":[[0,2.38,1.68],[1,2.36,1.99]],"ltp":0.0,"tv":0.0,"id":11981493}]}]}
{"op":"mcm","clk":"986657740","pt":1580488406572,"mc":[{"id":"1.168136214","rc":[{"batb":[[0,2.38,1.68],[1,2.36,1.99],[2,2.28,7.27]],"ltp":0.0,"tv":0.0,"id":12925630}]}]}
{"op":"mcm","clk":"986657823","pt":1580488407770,"mc":[{"id":"1.168136214","rc":[{"batb":[[0,2.4,1.99],[1,2.38,1.68]],"ltp":0.0,"tv":0.0,"id":12925630},{"batb":[[0,2.4,1.99],[1,2.38,1.68]],"ltp":0.0,"tv":0.0,"id":11981493}]}]}
{"op":"mcm","clk":"986663384","pt":1580488493464,"mc":[{"id":"1.168136214","rc":[{"batb":[[0,2.42,1.68],[1,2.4,1.99]],"ltp":0.0,"tv":0.0,"id":12925630}]}]}
{"op":"mcm","clk":"986663613","pt":1580488497876,"mc":[{"id":"1.168136214","rc":[{"batb":[[0,2.44,1.99],[1,2.42,1.68]],"ltp":0.0,"tv":0.0,"id":12925630}]}]}
{"op":"mcm","clk":"986664935","pt":1580488519207,"mc":[{"id":"1.168136214","rc":[{"batb":[[2,2.28,6.56]],"ltp":0.0,"tv":0.0,"id":12925630}]}]}
{"op":"mcm","clk":"986666472","pt":1580488546935,"mc":[{"id":"1.168136214","rc":[{"batb":[[2,2.3,3.51]],"ltp":0.0,"tv":0.0,"id":12925630}]}]}
{"op":"mcm","clk":"986668357","pt":1580488581635,"mc":[{"id":"1.168136214","rc":[{"batb":[[0,2.46,1.68],[1,2.44,1.99]],"ltp":0.0,"tv":0.0,"id":12925630}]}]}
{"op":"mcm","clk":"986670307","pt":1580488621788,"mc":[{"id":"1.168136214","rc":[{"batb":[[0,2.48,1.99],[1,2.46,1.68]],"ltp":0.0,"tv":0.0,"id":12925630}]}]}
{"op":"mcm","clk":"986671985","pt":1580488654791,"mc":[{"id":"1.168136214","rc":[{"batb":[[0,2.5,1.68],[1,2.48,1.99]],"ltp":0.0,"tv":0.0,"id":12925630}]}]}
{"op":"mcm","clk":"986672358","pt":1580488662616,"mc":[{"id":"1.168136214","rc":[{"batb":[[0,2.52,1.99],[1,2.5,1.68]],"ltp":0.0,"tv":0.0,"id":12925630}]}]}
{"op":"mcm","clk":"986674246","pt":1580488697636,"mc":[{"id":"1.168136214","rc":[{"trd":[[2.24,6],[2.28,7.12],[2.3,1.44]],"batb":[[0,1.53,4.84],[1,1.52,3],[2,1.51,3.36]],"batl":[[0,1000,0.92]],"ltp":2.24,"tv":18.53,"id":17336468}],"tv":18.53}]}
{"op":"mcm","clk":"986674473","pt":1580488701669,"mc":[{"id":"1.168136214","rc":[{"batb":[[0,2.52,2.64]],"ltp":0.0,"tv":0.0,"id":12925630}]}]}
{"op":"mcm","clk":"986674702","pt":1580488705644,"mc":[{"id":"1.168136214","rc":[{"batb":[[0,1.54,25.62],[1,1.53,4.84],[2,1.52,3]],"ltp":2.24,"tv":18.53,"id":17336468}]}]}
{"op":"mcm","clk":"986675073","pt":1580488712091,"mc":[{"id":"1.168136214","rc":[{"batb":[[2,1.51,3.36]],"ltp":2.24,"tv":18.53,"id":17336468}]}]}
{"op":"mcm","clk":"986675534","pt":1580488719611,"mc":[{"id":"1.168136214","rc":[{"batb":[[0,2.54,1.68],[1,2.52,10.58]],"ltp":0.0,"tv":0.0,"id":12925630},{"batb":[[0,1.55,14.78],[1,1.54,25.62]],"ltp":2.24,"tv":18.53,"id":17336468},{"batb":[[0,2.4,10.32]],"ltp":0.0,"tv":0.0,"id":11981493}]}]}
{"op":"mcm","clk":"986675816","pt":1580488725291,"mc":[{"id":"1.168136214","rc":[{"batb":[[1,1.51,3.36],[2,1.03,1593.64]],"ltp":2.24,"tv":18.53,"id":17336468}]}]}
{"op":"mcm","clk":"986675903","pt":1580488727010,"mc":[{"id":"1.168136214","rc":[{"batb":[[2,1.52,3]],"ltp":0.0,"tv":0.0,"id":12925630},{"batb":[[0,1.56,12.2],[1,1.55,14.78],[2,1.51,3.36]],"ltp":2.24,"tv":18.53,"id":17336468},{"batb":[[0,2.42,3.21],[1,2.4,10.32],[2,2.38,1.68]],"ltp":0.0,"tv":0.0,"id":11981493}]}]}
{"op":"mcm","clk":"986676073","pt":1580488730705,"mc":[{"id":"1.168136214","rc":[{"batb":[[0,2.54,4.64]],"ltp":0.0,"tv":0.0,"id":12925630}]}]}
{"op":"mcm","clk":"986676801","pt":1580488745086,"mc":[{"id":"1.168136214","rc":[{"batb":[[0,1.57,25.13],[1,1.56,12.2],[2,1.55,14.78]],"ltp":2.24,"tv":18.53,"id":17336468}]}]}
{"op":"mcm","clk":"986677026","pt":1580488749812,"mc":[{"id":"1.168136214","rc":[{"batb":[[0,2.42,3.88]],"ltp":0.0,"tv":0.0,"id":11981493}]}]}
{"op":"mcm","clk":"986677286","pt":1580488756097,"mc":[{"id":"1.168136214","rc":[{"batb":[[1,2.52,8.59]],"ltp":0.0,"tv":0.0,"id":12925630},{"batb":[[0,2.46,1.99],[1,2.42,3.88],[2,2.4,8.33]],"ltp":0.0,"tv":0.0,"id":11981493}]}]}
{"op":"mcm","clk":"986677558","pt":1580488761968,"mc":[{"id":"1.168136214","rc":[{"batb":[[2,1.51,3.36]],"ltp":0.0,"tv":0.0,"id":12925630}]}]}
{"op":"mcm","clk":"986678743","pt":1580488789586,"mc":[{"id":"1.168136214","rc":[{"batb":[[2,1.55,4.78]],"ltp":2.24,"tv":18.53,"id":17336468},{"batb":[[2,2.38,1.68]],"ltp":0.0,"tv":0.0,"id":11981493}]}]}
{"op":"mcm","clk":"986679328","pt":1580488802705,"mc":[{"id":"1.168136214","rc":[{"batb":[[0,1.58,4.68],[1,1.57,25.13],[2,1.56,12.2]],"ltp":2.24,"tv":18.53,"id":17336468}]}]}
{"op":"mcm","clk":"986680274","pt":1580488822140,"mc":[{"id":"1.168136214","rc":[{"batb":[[1,1.56,12.2],[2,1.51,3.36]],"ltp":2.24,"tv":18.53,"id":17336468}]}]}
{"op":"mcm","clk":"986683129","pt":1580488881514,"mc":[{"id":"1.168136214","rc":[{"batb":[[1,1.57,3],[2,1.56,12.2]],"ltp":2.24,"tv":18.53,"id":17336468},{"batb":[[2,2.4,3]],"ltp":0.0,"tv":0.0,"id":11981493}]}]}
{"op":"mcm","clk":"986683942","pt":1580488898353,"mc":[{"id":"1.168136214","rc":[{"batb":[[0,1.59,24.81],[1,1.58,4.68],[2,1.57,3]],"ltp":2.24,"tv":18.53,"id":17336468}]}]}
{"op":"mcm","clk":"986685638","pt":1580488929460,"mc":[{"id":"1.168136214","rc":[{"batb":[[0,1.6,10],[1,1.59,24.81],[2,1.58,4.68]],"ltp":2.24,"tv":18.53,"id":17336468},{"batb":[[0,2.46,10.12]],"ltp":0.0,"tv":0.0,"id":11981493}]}]}
{"op":"mcm","clk":"986686039","pt":1580488936598,"mc":[{"id":"1.168136214","rc":[{"batb":[[1,1.58,4.68],[2,1.57,3]],"ltp":2.24,"tv":18.53,"id":17336468},{"batb":[[0,2.48,3.07],[1,2.46,10.12],[2,2.4,3.68]],"ltp":0.0,"tv":0.0,"id":11981493}]}]}
{"op":"mcm","clk":"986686856","pt":1580488950777,"mc":[{"id":"1.168136214","rc":[{"batb":[[0,1.61,3.67],[1,1.6,10]],"ltp":2.24,"tv":18.53,"id":17336468}]}]}
{"op":"mcm","clk":"986687109","pt":1580488955822,"mc":[{"id":"1.168136214","rc":[{"batb":[[0,1.62,24.36],[1,1.61,3.67],[2,1.6,10]],"ltp":2.24,"tv":18.53,"id":17336468}]}]}
{"op":"mcm","clk":"986687208","pt":1580488957813,"mc":[{"id":"1.168136214","rc":[{"batb":[[0,2.5,1.99],[1,2.48,3.07],[2,2.46,8.13]],"ltp":0.0,"tv":0.0,"id":11981493}]}]}
{"op":"mcm","clk":"986689052","pt":1580488998599,"mc":[{"id":"1.168136214","rc":[{"batb":[[0,1.63,10],[1,1.62,24.36],[2,1.61,3.67]],"ltp":2.24,"tv":18.53,"id":17336468},{"batb":[[0,2.5,9.99],[2,2.38,2.36]],"ltp":0.0,"tv":0.0,"id":11981493}]}]}
{"op":"mcm","clk":"986689713","pt":1580489013102,"mc":[{"id":"1.168136214","rc":[{"batb":[[1,1.61,3.67],[2,1.56,12.2]],"ltp":2.24,"tv":18.53,"id":17336468}]}]}
{"op":"mcm","clk":"986690435","pt":1580489026515,"mc":[{"id":"1.168136214","rc":[{"batb":[[1,2.38,2.36],[2,1.51,3.36]],"ltp":0.0,"tv":0.0,"id":11981493}]}]}
{"op":"mcm","clk":"986690656","pt":1580489030920,"mc":[{"id":"1.168136214","rc":[{"batb":[[0,2.52,3],[1,2.5,9.99],[2,2.38,2.36]],"ltp":0.0,"tv":0.0,"id":11981493}]}]}
{"op":"mcm","clk":"986690853","pt":1580489034997,"mc":[{"id":"1.168136214","rc":[{"batb":[[0,1.64,3.41],[1,1.63,10]],"ltp":2.24,"tv":18.53,"id":17336468}]}]}
{"op":"mcm","clk":"986691732","pt":1580489051700,"mc":[{"id":"1.168136214","rc":[{"batb":[[0,1.65,23.92],[1,1.64,3.41],[2,1.63,10]],"ltp":2.24,"tv":18.53,"id":17336468}]}]}
{"op":"mcm","clk":"986692533","pt":1580489066006,"mc":[{"id":"1.168136214","rc":[{"batb":[[0,2.54,1.99],[1,2.52,3],[2,2.5,8]],"ltp":0.0,"tv":0.0,"id":11981493}]}]}
{"op":"mcm","clk":"986692634","pt":1580489068139,"mc":[{"id":"1.168136214","rc":[{"batb":[[0,1.66,10],[1,1.65,23.92],[2,1.64,3.41]],"ltp":2.24,"tv":18.53,"id":17336468},{"batb":[[0,2.54,9.86],[2,2.38,2.36]],"ltp":0.0,"tv":0.0,"id":11981493}]}]}
{"op":"mcm","clk":"986692806","pt":1580489070943,"mc":[{"id":"1.168136214","rc":[{"batb":[[1,1.64,3.41],[2,1.56,12.2]],"ltp":2.24,"tv":18.53,"id":17336468}]}]}
{"op":"mcm","clk":"986693751","pt":1580489087061,"mc":[{"id":"1.168136214","rc":[{"batb":[[1,2.38,2.36],[2,1.51,3.36]],"ltp":0.0,"tv":0.0,"id":11981493}]}]}
{"op":"mcm","clk":"986693850","pt":1580489088752,"mc":[{"id":"1.168136214","rc":[{"batb":[[1,2.38,1.68]],"ltp":0.0,"tv":0.0,"id":11981493}]}]}
{"op":"mcm","clk":"986694506","pt":1580489101310,"mc":[{"id":"1.168136214","rc":[{"batb":[[0,2.54,10.5]],"ltp":0.0,"tv":0.0,"id":11981493}]}]}
{"op":"mcm","clk":"986695035","pt":1580489110018,"mc":[{"id":"1.168136214","rc":[{"batb":[[0,2.58,1.99],[1,2.54,8.51],[2,2.38,1.68]],"ltp":0.0,"tv":0.0,"id":11981493}]}]}
{"op":"mcm","clk":"986695422","pt":1580489117007,"mc":[{"id":"1.168136214","rc":[{"batb":[[0,1.67,3.36],[1,1.66,10]],"ltp":2.24,"tv":18.53,"id":17336468}]}]}
{"op":"mcm","clk":"986695640","pt":1580489121286,"mc":[{"id":"1.168136214","rc":[{"batb":[[1,2.56,3.56],[2,2.54,7.87]],"ltp":0.0,"tv":0.0,"id":11981493}]}]}
{"op":"mcm","clk":"986696006","pt":1580489127712,"mc":[{"id":"1.168136214","rc":[{"batb":[[0,1.68,23.48],[1,1.67,3.36],[2,1.66,10]],"ltp":2.24,"tv":18.53,"id":17336468}]}]}
{"op":"mcm","clk":"986696494","pt":1580489137115,"mc":[{"id":"1.168136214","rc":[{"batb":[[2,1.56,12.2]],"ltp":2.24,"tv":18.53,"id":17336468},{"batb":[[2,2.38,1.68]],"ltp":0.0,"tv":0.0,"id":11981493}]}]}
{"op":"mcm","clk":"986696501","pt":1580489137216,"mc":[{"id":"1.168136214","rc":[{"batb":[[0,1.69,10],[1,1.68,23.48],[2,1.67,3.36]],"ltp":2.24,"tv":18.53,"id":17336468},{"batb":[[0,2.58,9.74]],"ltp":0.0,"tv":0.0,"id":11981493}]}]}
{"op":"mcm","clk":"986697030","pt":1580489147006,"mc":[{"id":"1.168136214","rc":[{"batb":[[1,1.67,3.36],[2,1.56,12.2]],"ltp":2.24,"tv":18.53,"id":17336468},{"batb":[[1,2.38,2.32],[2,1.51,3.36]],"ltp":0.0,"tv":0.0,"id":11981493}]}]}
{"op":"mcm","clk":"986697234","pt":1580489151087,"mc":[{"id":"1.168136214","rc":[{"batb":[[0,2.6,2.85],[1,2.58,9.74],[2,2.38,2.32]],"ltp":0.0,"tv":0.0,"id":11981493}]}]}
{"op":"mcm","clk":"986699560","pt":1580489190728,"mc":[{"id":"1.168136214","rc":[{"batb":[[0,2.62,1.99],[1,2.6,2.85],[2,2.58,7.75]],"ltp":0.0,"tv":0.0,"id":11981493}]}]}
{"op":"mcm","clk":"986699709","pt":1580489193133,"mc":[{"id":"1.168136214","rc":[{"batb":[[1,1.56,12.2],[2,1.51,3.36]],"ltp":2.24,"tv":18.53,"id":17336468}]}]}
{"op":"mcm","clk":"986699715","pt":1580489193239,"mc":[{"id":"1.168136214","rc":[{"batb":[[0,1.7,3.3],[1,1.69,10],[2,1.56,12.2]],"ltp":2.24,"tv":18.53,"id":17336468}]}]}
{"op":"mcm","clk":"986700351","pt":1580489203741,"mc":[{"id":"1.168136214","rc":[{"batb":[[0,1.71,23.07],[1,1.7,3.3],[2,1.69,10]],"ltp":2.24,"tv":18.53,"id":17336468}]}]}
{"op":"mcm","clk":"986700489","pt":1580489206119,"mc":[{"id":"1.168136214","rc":[{"batb":[[2,1.56,12.2]],"ltp":2.24,"tv":18.53,"id":17336468},{"batb":[[2,2.38,2.32]],"ltp":0.0,"tv":0.0,"id":11981493}]}]}
{"op":"mcm","clk":"986712627","pt":1580489252796,"mc":[{"id":"1.168136214","rc":[{"batb":[[0,1.72,3.25],[1,1.71,23.07]],"ltp":2.24,"tv":18.53,"id":17336468}]}]}
{"op":"mcm","clk":"986712981","pt":1580489259590,"mc":[{"id":"1.168136214","rc":[{"batb":[[2,2.4,3.64]],"ltp":0.0,"tv":0.0,"id":11981493}]}]}
{"op":"mcm","clk":"986713074","pt":1580489261220,"mc":[{"id":"1.168136214","rc":[{"batb":[[1,1.56,12.2],[2,1.51,3.36]],"ltp":2.24,"tv":18.53,"id":17336468}]}]}
{"op":"mcm","clk":"986716062","pt":1580489312130,"mc":[{"id":"1.168136214","rc":[{"batb":[[0,1.56,12.2],[1,1.51,3.36],[2,1.03,1593.64]],"ltp":2.24,"tv":18.53,"id":17336468}]}]}
{"op":"mcm","clk":"986716107","pt":1580489313137,"mc":[{"id":"1.168136214","rc":[{"batb":[[0,1.57,3.25],[1,1.56,12.2],[2,1.51,3.36]],"ltp":2.24,"tv":18.53,"id":17336468}]}]}
{"op":"mcm","clk":"986716422","pt":1580489319560,"mc":[{"id":"1.168136214","rc":[{"batb":[[0,1.58,24.97],[1,1.57,3.25],[2,1.56,12.2]],"ltp":2.24,"tv":18.53,"id":17336468}]}]}
{"op":"mcm","clk":"986717034","pt":1580489333762,"mc":[{"id":"1.168136214","rc":[{"batl":[[0,1000,3.56]],"ltp":0.0,"tv":0.0,"id":11981493}]}]}
{"op":"mcm","clk":"986717081","pt":1580489334843,"mc":[{"id":"1.168136214","rc":[{"batl":[[0,1000,2.3]],"ltp":0.0,"tv":0.0,"id":11981493}]}]}
{"op":"mcm","clk":"986717112","pt":1580489336115,"mc":[{"id":"1.168136214","rc":[{"batl":[[0,1000,1.88]],"ltp":0.0,"tv":0.0,"id":11981493}]}]}
{"op":"mcm","clk":"986717148","pt":1580489336876,"mc":[{"id":"1.168136214","rc":[{"batl":[[0,1000,2.3]],"ltp":0.0,"tv":0.0,"id":11981493}]}]}
{"op":"mcm","clk":"986717281","pt":1580489339080,"mc":[{"id":"1.168136214","rc":[{"batl":[[0,1000,1.88]],"ltp":0.0,"tv":0.0,"id":11981493}]}]}
{"op":"mcm","clk":"986717553","pt":1580489344377,"mc":[{"id":"1.168136214","rc":[{"batb":[[0,1.59,10],[1,1.58,24.97],[2,1.57,3.25]],"ltp":2.24,"tv":18.53,"id":17336468},{"batb":[[0,2.62,9.62]],"ltp":0.0,"tv":0.0,"id":11981493}]}]}
{"op":"mcm","clk":"986718173","pt":1580489357001,"mc":[{"id":"1.168136214","rc":[{"batb":[[1,2.4,3.64],[2,2.38,1.68]],"ltp":0.0,"tv":0.0,"id":11981493}]}]}
{"op":"mcm","clk":"986718210","pt":1580489357685,"mc":[{"id":"1.168136214","rc":[{"batb":[[1,1.57,3.25],[2,1.56,12.2]],"ltp":2.24,"tv":18.53,"id":17336468}]}]}
{"op":"mcm","clk":"986718365","pt":1580489360982,"mc":[{"id":"1.168136214","rc":[{"batb":[[0,2.64,2.78],[1,2.62,9.62],[2,2.4,3.64]],"ltp":0.0,"tv":0.0,"id":11981493}]}]}
{"op":"mcm","clk":"986719210","pt":1580489377821,"mc":[{"id":"1.168136214","rc":[{"batb":[[0,2.66,1.99],[1,2.64,2.78],[2,2.62,7.63]],"ltp":0.0,"tv":0.0,"id":11981493}]}]}
{"op":"mcm","clk":"986719372","pt":1580489381099,"mc":[{"id":"1.168136214","rc":[{"batb":[[0,1.6,3.2],[1,1.59,10]],"ltp":2.24,"tv":18.53,"id":17336468}]}]}
{"op":"mcm","clk":"986720144","pt":1580489395936,"mc":[{"id":"1.168136214","rc":[{"batb":[[0,1.61,24.51],[1,1.6,3.2],[2,1.59,10]],"ltp":2.24,"tv":18.53,"id":17336468}]}]}
{"op":"mcm","clk":"986721059","pt":1580489413538,"mc":[{"id":"1.168136214","rc":[{"batb":[[0,1.62,10],[1,1.61,24.51],[2,1.6,3.2]],"ltp":2.24,"tv":18.53,"id":17336468},{"batb":[[0,2.66,9.51],[2,2.38,2.32]],"ltp":0.0,"tv":0.0,"id":11981493}]}]}
{"op":"mcm","clk":"986721140","pt":1580489415056,"mc":[{"id":"1.168136214","rc":[{"batb":[[1,1.6,3.2],[2,1.56,12.2]],"ltp":2.24,"tv":18.53,"id":17336468}]}]}
{"op":"mcm","clk":"986721212","pt":1580489416660,"mc":[{"id":"1.168136214","rc":[{"batb":[[1,2.38,2.32],[2,1.51,3.36]],"ltp":0.0,"tv":0.0,"id":11981493}]}]}
{"op":"mcm","clk":"986721430","pt":1580489420739,"mc":[{"id":"1.168136214","rc":[{"batb":[[0,2.68,2.71],[1,2.66,9.51],[2,2.38,2.32]],"ltp":0.0,"tv":0.0,"id":11981493}]}]}
{"op":"mcm","clk":"986721487","pt":1580489421982,"mc":[{"id":"1.168136214","rc":[{"batb":[[1,2.66,7.52]],"ltp":0.0,"tv":0.0,"id":11981493}]}]}
{"op":"mcm","clk":"986721544","pt":1580489423057,"mc":[{"id":"1.168136214","rc":[{"batb":[[0,2.7,1.99],[1,2.68,2.71],[2,2.66,7.52]],"ltp":0.0,"tv":0.0,"id":11981493}]}]}
{"op":"mcm","clk":"986722938","pt":1580489447644,"mc":[{"id":"1.168136214","rc":[{"batb":[[0,1.63,3.14],[1,1.62,10]],"ltp":2.24,"tv":18.53,"id":17336468}]}]}
{"op":"mcm","clk":"986723203","pt":1580489452749,"mc":[{"id":"1.168136214","rc":[{"batb":[[0,2.7,2.6]],"ltp":0.0,"tv":0.0,"id":11981493}]}]}
{"op":"mcm","clk":"986723262","pt":1580489453945,"mc":[{"id":"1.168136214","rc":[{"batb":[[0,1.64,24.06],[1,1.63,3.14],[2,1.62,10]],"ltp":2.24,"tv":18.53,"id":17336468}]}]}
{"op":"mcm","clk":"986725066","pt":1580489483413,"mc":[{"id":"1.168136214","rc":[{"batb":[[0,1.65,10],[1,1.64,24.06],[2,1.63,3.14]],"ltp":2.24,"tv":18.53,"id":17336468},{"batb":[[0,2.7,10.01],[2,2.38,1.68]],"ltp":0.0,"tv":0.0,"id":11981493}]}]}
{"op":"mcm","clk":"986725756","pt":1580489492522,"mc":[{"id":"1.168136214","rc":[{"batb":[[1,1.63,3.14],[2,1.56,12.2]],"ltp":2.24,"tv":18.53,"id":17336468}]}]}
{"op":"mcm","clk":"986726693","pt":1580489506910,"mc":[{"id":"1.168136214","rc":[{"batb":[[1,2.38,1.68],[2,1.51,3.36]],"ltp":0.0,"tv":0.0,"id":11981493}]}]}
{"op":"mcm","clk":"986726998","pt":1580489511224,"mc":[{"id":"1.168136214","rc":[{"batb":[[0,2.72,2.65],[1,2.7,10.01],[2,2.38,1.68]],"ltp":0.0,"tv":0.0,"id":11981493}]}]}
{"op":"mcm","clk":"986728074","pt":1580489524058,"mc":[{"id":"1.168136214","rc":[{"batb":[[0,1.66,3.08],[1,1.65,10]],"ltp":2.24,"tv":18.53,"id":17336468},{"batb":[[2,1.51,3.36]],"batl":[[0,990,0.2]],"ltp":0.0,"tv":0.0,"id":11981493}]}]}
{"op":"mcm","clk":"986728141","pt":1580489525061,"mc":[{"id":"1.168136214","rc":[{"trd":[[2.72,5.3]],"batb":[[0,2.7,10.01],[1,1.51,3.36],[2,1.03,1544.03]],"ltp":2.72,"tv":5.29,"id":11981493}],"tv":23.83}]}
{"op":"mcm","clk":"986728234","pt":1580489526825,"mc":[{"id":"1.168136214","rc":[{"batb":[[1,2.62,3],[2,1.51,3.36]],"ltp":2.72,"tv":5.29,"id":11981493}]}]}
{"op":"mcm","clk":"986728277","pt":1580489527348,"mc":[{"id":"1.168136214","rc":[{"batl":[[0,1000,0.2]],"ltp":2.72,"tv":5.29,"id":11981493}]}]}
{"op":"mcm","clk":"986728554","pt":1580489530974,"mc":[{"id":"1.168136214","rc":[{"batb":[[0,1.67,23.63],[1,1.66,3.08],[2,1.65,10]],"ltp":2.24,"tv":18.53,"id":17336468}]}]}
{"op":"mcm","clk":"986729139","pt":1580489537083,"mc":[{"id":"1.168136214","rc":[{"batb":[[2,2.44,4.74]],"ltp":2.72,"tv":5.29,"id":11981493}]}]}
{"op":"mcm","clk":"986730171","pt":1580489552568,"mc":[{"id":"1.168136214","rc":[{"batb":[[0,1.68,10],[1,1.67,23.63],[2,1.66,3.08]],"ltp":2.24,"tv":18.53,"id":17336468},{"batb":[[0,2.7,2.6],[1,2.64,7.58],[2,2.62,3]],"ltp":2.72,"tv":5.29,"id":11981493}]}]}
{"op":"mcm","clk":"986731276","pt":1580489568683,"mc":[{"id":"1.168136214","rc":[{"batb":[[1,1.66,3.08],[2,1.56,12.2]],"ltp":2.24,"tv":18.53,"id":17336468}]}]}
{"op":"mcm","clk":"986733362","pt":1580489593821,"mc":[{"id":"1.168136214","rc":[{"batb":[[0,2.68,8],[1,2.54,4.64],[2,2.52,8.59]],"ltp":0.0,"tv":0.0,"id":12925630}]}]}
{"op":"mcm","clk":"986733577","pt":1580489596800,"mc":[{"id":"1.168136214","rc":[{"batb":[[1,2.54,1.68]],"ltp":0.0,"tv":0.0,"id":12925630}]}]}
{"op":"mcm","clk":"986733779","pt":1580489600404,"mc":[{"id":"1.168136214","rc":[{"batb":[[0,2.7,2.68],[1,2.68,8],[2,2.54,1.68]],"ltp":0.0,"tv":0.0,"id":12925630}]}]}
{"op":"mcm","clk":"986734090","pt":1580489604987,"mc":[{"id":"1.168136214","rc":[{"batb":[[0,1.69,3.03],[1,1.68,10]],"ltp":2.24,"tv":18.53,"id":17336468}]}]}
{"op":"mcm","clk":"986734115","pt":1580489605301,"mc":[{"id":"1.168136214","rc":[{"batb":[[0,2.72,1.68],[1,2.7,2.68],[2,2.68,8]],"ltp":0.0,"tv":0.0,"id":12925630}]}]}
{"op":"mcm","clk":"986734223","pt":1580489606907,"mc":[{"id":"1.168136214","rc":[{"batb":[[0,1.7,23.21],[1,1.69,3.03],[2,1.68,10]],"ltp":2.24,"tv":18.53,"id":17336468}]}]}
{"op":"mcm","clk":"986735101","pt":1580489621128,"mc":[{"id":"1.168136214","rc":[{"batb":[[2,1.56,12.2]],"ltp":2.24,"tv":18.53,"id":17336468},{"batb":[[1,2.62,3],[2,2.44,4.74]],"ltp":2.72,"tv":5.29,"id":11981493}]}]}
{"op":"mcm","clk":"986735162","pt":1580489622121,"mc":[{"id":"1.168136214","rc":[{"batb":[[0,2.76,8],[1,2.72,9.03],[2,2.7,2.68]],"ltp":0.0,"tv":0.0,"id":12925630},{"batb":[[0,1.71,10],[1,1.7,23.21],[2,1.69,3.03]],"ltp":2.24,"tv":18.53,"id":17336468},{"batb":[[2,2.46,8.13]],"ltp":2.72,"tv":5.29,"id":11981493}]}]}
{"op":"mcm","clk":"986735410","pt":1580489626126,"mc":[{"id":"1.168136214","rc":[{"batb":[[1,1.69,3.03],[2,1.56,12.2]],"ltp":2.24,"tv":18.53,"id":17336468}]}]}
{"op":"mcm","clk":"986735453","pt":1580489626849,"mc":[{"id":"1.168136214","rc":[{"batb":[[2,1.51,3.36]],"ltp":0.0,"tv":0.0,"id":12925630}]}]}
{"op":"mcm","clk":"986735682","pt":1580489630648,"mc":[{"id":"1.168136214","rc":[{"batb":[[0,2.78,2.56],[1,2.76,8],[2,2.72,9.03]],"ltp":0.0,"tv":0.0,"id":12925630}]}]}
{"op":"mcm","clk":"986735948","pt":1580489635044,"mc":[{"id":"1.168136214","rc":[{"batb":[[0,2.78,3.15]],"ltp":0.0,"tv":0.0,"id":12925630}]}]}
{"op":"mcm","clk":"986736335","pt":1580489642047,"mc":[{"id":"1.168136214","rc":[{"batb":[[0,2.62,3.61],[1,2.46,8.13],[2,2.44,4.74]],"ltp":2.72,"tv":5.29,"id":11981493}]}]}
{"op":"mcm","clk":"986736382","pt":1580489642830,"mc":[{"id":"1.168136214","rc":[{"batb":[[0,2.8,1.99],[1,2.78,3.15],[2,2.76,8]],"ltp":0.0,"tv":0.0,"id":12925630}]}]}
{"op":"mcm","clk":"986737300","pt":1580489658270,"mc":[{"id":"1.168136214","rc":[{"batb":[[0,2.88,8],[1,2.8,1.99],[2,2.78,3.15]],"ltp":0.0,"tv":0.0,"id":12925630}]}]}
{"op":"mcm","clk":"986738710","pt":1580489682507,"mc":[{"id":"1.168136214","rc":[{"batb":[[2,2.78,2.56]],"ltp":0.0,"tv":0.0,"id":12925630}]}]}
{"op":"mcm","clk":"986738963","pt":1580489686725,"mc":[{"id":"1.168136214","rc":[{"batb":[[2,2.72,9.03]],"ltp":0.0,"tv":0.0,"id":12925630}]}]}
{"op":"mcm","clk":"986739227","pt":1580489691040,"mc":[{"id":"1.168136214","rc":[{"batb":[[0,2.9,2.4],[1,2.88,8],[2,2.8,1.99]],"ltp":0.0,"tv":0.0,"id":12925630},{"batb":[[0,1.69,3.03],[1,1.56,12.2],[2,1.51,3.36]],"ltp":2.24,"tv":18.53,"id":17336468},{"batb":[[1,2.44,4.74],[2,2.38,5.57]],"ltp":2.72,"tv":5.29,"id":11981493}]}]}
{"op":"mcm","clk":"986739278","pt":1580489692024,"mc":[{"id":"1.168136214","rc":[{"batb":[[0,2.9,9.3]],"ltp":0.0,"tv":0.0,"id":12925630},{"batb":[[1,1.57,10],[2,1.56,12.2]],"ltp":2.24,"tv":18.53,"id":17336468},{"batb":[[0,2.64,8.19],[1,2.62,3],[2,2.44,4.74]],"ltp":2.72,"tv":5.29,"id":11981493}]}]}
{"op":"mcm","clk":"986739516","pt":1580489695736,"mc":[{"id":"1.168136214","rc":[{"batb":[[0,2.9,9.87]],"ltp":0.0,"tv":0.0,"id":12925630}]}]}
{"op":"mcm","clk":"986739982","pt":1580489703145,"mc":[{"id":"1.168136214","rc":[{"batb":[[0,2.92,1.68],[1,2.9,9.87],[2,2.88,8]],"ltp":0.0,"tv":0.0,"id":12925630},{"batb":[[0,1.58,3.03]],"ltp":2.24,"tv":18.53,"id":17336468}]}]}
{"op":"mcm","clk":"986740819","pt":1580489717048,"mc":[{"id":"1.168136214","rc":[{"batb":[[0,2.98,8],[1,2.94,1.99],[2,2.92,1.68]],"ltp":0.0,"tv":0.0,"id":12925630}]}]}
{"op":"mcm","clk":"986741031","pt":1580489720647,"mc":[{"id":"1.168136214","rc":[{"batb":[[2,2.92,4.05]],"ltp":0.0,"tv":0.0,"id":12925630}]}]}
{"op":"mcm","clk":"986741117","pt":1580489722068,"mc":[{"id":"1.168136214","rc":[{"batb":[[0,1.59,24.81],[1,1.58,3.03],[2,1.57,10]],"ltp":2.24,"tv":18.53,"id":17336468}]}]}
{"op":"mcm","clk":"986742594","pt":1580489746881,"mc":[{"id":"1.168136214","rc":[{"batb":[[2,2.92,1.68]],"ltp":0.0,"tv":0.0,"id":12925630}]}]}
{"op":"mcm","clk":"986742854","pt":1580489751371,"mc":[{"id":"1.168136214","rc":[{"batb":[[0,3,2.28],[1,2.98,8],[2,2.94,1.99]],"ltp":0.0,"tv":0.0,"id":12925630}]}]}
{"op":"mcm","clk":"986743332","pt":1580489759520,"mc":[{"id":"1.168136214","rc":[{"batb":[[2,1.56,12.2]],"ltp":2.24,"tv":18.53,"id":17336468},{"batb":[[0,2.62,3.61],[1,2.44,4.74],[2,2.38,5.57]],"ltp":2.72,"tv":5.29,"id":11981493}]}]}
{"op":"mcm","clk":"986743569","pt":1580489762877,"mc":[{"id":"1.168136214","rc":[{"batb":[[0,3.1,8],[1,3,2.28]],"ltp":0.0,"tv":0.0,"id":12925630}]}]}
{"op":"mcm","clk":"986744518","pt":1580489777120,"mc":[{"id":"1.168136214","rc":[{"batb":[[1,2.94,1.99],[2,2.92,1.68]],"ltp":0.0,"tv":0.0,"id":12925630}]}]}
{"op":"mcm","clk":"986744855","pt":1580489782431,"mc":[{"id":"1.168136214","rc":[{"batb":[[0,3.15,2.12],[1,3.1,8],[2,2.94,1.99]],"ltp":0.0,"tv":0.0,"id":12925630}]}]}
{"op":"mcm","clk":"986746052","pt":1580489800431,"mc":[{"id":"1.168136214","rc":[{"batb":[[0,3.2,1.99],[1,3.15,2.12],[2,3.1,8]],"ltp":0.0,"tv":0.0,"id":12925630}]}]}
{"op":"mcm","clk":"986746384","pt":1580489805058,"mc":[{"id":"1.168136214","rc":[{"batb":[[0,3.2,2.5]],"ltp":0.0,"tv":0.0,"id":12925630}]}]}
{"op":"mcm","clk":"986746581","pt":1580489808735,"mc":[{"id":"1.168136214","rc":[{"batb":[[2,2.4,3]],"ltp":2.72,"tv":5.29,"id":11981493}]}]}
{"op":"mcm","clk":"986749448","pt":1580489860693,"mc":[{"id":"1.168136214","rc":[{"batb":[[0,3.25,1.68],[1,3.2,2.5],[2,3.15,2.12]],"ltp":0.0,"tv":0.0,"id":12925630},{"batb":[[0,1.6,2.99],[1,1.59,24.81]],"ltp":2.24,"tv":18.53,"id":17336468}]}]}
{"op":"mcm","clk":"986749958","pt":1580489869604,"mc":[{"id":"1.168136214","rc":[{"batb":[[1,1.56,12.2],[2,1.51,3.36]],"ltp":2.24,"tv":18.53,"id":17336468}]}]}
{"op":"mcm","clk":"986750404","pt":1580489876730,"mc":[{"id":"1.168136214","rc":[{"batl":[[0,1000,2.6]],"ltp":2.24,"tv":18.53,"id":17336468}]}]}
{"op":"mcm","clk":"986750468","pt":1580489877784,"mc":[{"id":"1.168136214","rc":[{"batl":[[0,2.34,1.14],[1,1000,0.2]],"ltp":2.24,"tv":18.53,"id":17336468}]}]}
{"op":"mcm","clk":"986750516","pt":1580489878727,"mc":[{"id":"1.168136214","rc":[{"batl":[[0,1000,0.92],[1,1000,0]],"ltp":2.24,"tv":18.53,"id":17336468}]}]}
{"op":"mcm","clk":"986750799","pt":1580489883518,"mc":[{"id":"1.168136214","rc":[{"batb":[[0,3.3,1.99],[1,3.25,1.68],[2,3.15,2.63]],"ltp":0.0,"tv":0.0,"id":12925630}]}]}
{"op":"mcm","clk":"986752584","pt":1580489914851,"mc":[{"id":"1.168136214","rc":[{"batb":[[1,1.57,3],[2,1.56,12.2]],"ltp":2.24,"tv":18.53,"id":17336468}]}]}
{"op":"mcm","clk":"986752915","pt":1580489921939,"mc":[{"id":"1.168136214","rc":[{"batb":[[0,3.3,8.05]],"ltp":0.0,"tv":0.0,"id":12925630},{"batb":[[1,1.58,10],[2,1.57,3]],"ltp":2.24,"tv":18.53,"id":17336468},{"batb":[[0,2.64,8.19],[1,2.62,3],[2,2.44,4.74]],"ltp":2.72,"tv":5.29,"id":11981493}]}]}
{"op":"mcm","clk":"986753210","pt":1580489927086,"mc":[{"id":"1.168136214","rc":[{"batb":[[2,3.1,8.51]],"ltp":0.0,"tv":0.0,"id":12925630}]}]}
{"op":"mcm","clk":"986753440","pt":1580489931981,"mc":[{"id":"1.168136214","rc":[{"batb":[[0,3.35,1.93],[1,3.3,8.05],[2,3.25,1.68]],"ltp":0.0,"tv":0.0,"id":12925630}]}]}
{"op":"mcm","clk":"986756051","pt":1580489975689,"mc":[{"id":"1.168136214","rc":[{"batb":[[0,3.4,1.99],[1,3.35,1.93],[2,3.3,6.06]],"ltp":0.0,"tv":0.0,"id":12925630}]}]}
{"op":"mcm","clk":"986756222","pt":1580489978517,"mc":[{"id":"1.168136214","rc":[{"batb":[[0,3.45,1.68],[1,3.4,1.99],[2,3.35,1.93]],"ltp":0.0,"tv":0.0,"id":12925630},{"batb":[[0,1.59,2.99]],"ltp":2.24,"tv":18.53,"id":17336468}]}]}
{"op":"mcm","clk":"986756313","pt":1580489980121,"mc":[{"id":"1.168136214","rc":[{"batb":[[0,1.6,24.66],[1,1.59,2.99],[2,1.58,10]],"ltp":2.24,"tv":18.53,"id":17336468}]}]}
{"op":"mcm","clk":"986757442","pt":1580490000061,"mc":[{"id":"1.168136214","rc":[{"batb":[[2,1.57,3]],"ltp":2.24,"tv":18.53,"id":17336468},{"batb":[[0,2.62,3.61],[1,2.44,4.74],[2,2.4,3]],"ltp":2.72,"tv":5.29,"id":11981493}]}]}
{"op":"mcm","clk":"986757937","pt":1580490005067,"mc":[{"id":"1.168136214","rc":[{"batb":[[2,1.56,12.2]],"ltp":2.24,"tv":18.53,"id":17336468}]}]}
{"op":"mcm","clk":"986761698","pt":1580490061529,"mc":[{"id":"1.168136214","rc":[{"batb":[[0,3.5,1.99],[1,3.45,1.68]],"ltp":0.0,"tv":0.0,"id":12925630}]}]}
{"op":"mcm","clk":"986764101","pt":1580490095659,"mc":[{"id":"1.168136214","rc":[{"batb":[[0,3.5,2.46]],"ltp":0.0,"tv":0.0,"id":12925630}]}]}
{"op":"mcm","clk":"986778307","pt":1580490176956,"mc":[{"id":"1.168136214","rc":[{"trd":[[2.62,4.78],[2.7,1.22]],"batb":[[0,2.44,5.35],[1,2.4,3],[2,2.38,5.57]],"ltp":2.62,"tv":11.29,"id":11981493}],"tv":29.83}]}
{"op":"mcm","clk":"986778650","pt":1580490180076,"mc":[{"id":"1.168136214","rc":[{"batb":[[0,3.55,1.68],[1,3.5,2.46]],"ltp":0.0,"tv":0.0,"id":12925630},{"batb":[[0,1.61,2.96],[1,1.6,24.66]],"ltp":2.24,"tv":18.53,"id":17336468}]}]}
{"op":"mcm","clk":"986778923","pt":1580490182659,"mc":[{"id":"1.168136214","rc":[{"batb":[[1,1.56,12.2],[2,1.51,3.36]],"ltp":2.24,"tv":18.53,"id":17336468}]}]}
{"op":"mcm","clk":"986782780","pt":1580490232956,"mc":[{"id":"1.168136214","rc":[{"batb":[[1,2.38,5.57],[2,1.51,3.36]],"ltp":2.62,"tv":11.29,"id":11981493}]}]}
{"op":"mcm","clk":"986783383","pt":1580490243154,"mc":[{"id":"1.168136214","rc":[{"batb":[[0,1.61,5.96]],"ltp":2.24,"tv":18.53,"id":17336468}]}]}
{"op":"mcm","clk":"986783451","pt":1580490244050,"mc":[{"id":"1.168136214","rc":[{"batb":[[0,3.6,1.99],[1,3.55,1.68],[2,3.35,2.4]],"ltp":0.0,"tv":0.0,"id":12925630},{"batb":[[0,2.48,1.99],[1,2.44,5.35],[2,2.38,5.57]],"ltp":2.62,"tv":11.29,"id":11981493}]}]}
{"op":"mcm","clk":"986783554","pt":1580490245579,"mc":[{"id":"1.168136214","rc":[{"batb":[[0,1.63,3],[1,1.61,2.96],[2,1.56,12.2]],"ltp":2.24,"tv":18.53,"id":17336468}]}]}
{"op":"mcm","clk":"986783656","pt":1580490246853,"mc":[{"id":"1.168136214","rc":[{"batb":[[0,1.61,2.96],[1,1.56,12.2],[2,1.51,3.36]],"ltp":2.24,"tv":18.53,"id":17336468}]}]}
{"op":"mcm","clk":"986783693","pt":1580490247585,"mc":[{"id":"1.168136214","rc":[{"batb":[[0,2.48,2.6],[1,2.44,4.74]],"ltp":2.62,"tv":11.29,"id":11981493}]}]}
{"op":"mcm","clk":"986784476","pt":1580490260075,"mc":[{"id":"1.168136214","rc":[{"batb":[[0,3.6,2.54]],"ltp":0.0,"tv":0.0,"id":12925630}]}]}
{"op":"mcm","clk":"986788270","pt":1580490324134,"mc":[{"id":"1.168136214","rc":[{"batb":[[0,2.44,5.35],[1,2.38,5.57],[2,1.51,3.36]],"ltp":2.62,"tv":11.29,"id":11981493}]}]}
{"op":"mcm","clk":"986793379","pt":1580490413532,"mc":[{"id":"1.168136214","rc":[{"batb":[[0,2.48,1.99],[1,2.44,5.35],[2,2.38,5.57]],"ltp":2.62,"tv":11.29,"id":11981493}]}]}
{"op":"mcm","clk":"986793739","pt":1580490418809,"mc":[{"id":"1.168136214","rc":[{"batb":[[0,2.48,2.6],[1,2.44,4.74]],"ltp":2.62,"tv":11.29,"id":11981493}]}]}
{"op":"mcm","clk":"986799467","pt":1580490510118,"mc":[{"id":"1.168136214","rc":[{"batb":[[0,2.44,5.35],[1,2.38,5.57],[2,1.51,3.36]],"ltp":2.62,"tv":11.29,"id":11981493}]}]}
{"op":"mcm","clk":"986804165","pt":1580490593886,"mc":[{"id":"1.168136214","rc":[{"batb":[[0,2.48,1.99],[1,2.44,5.35],[2,2.38,5.57]],"ltp":2.62,"tv":11.29,"id":11981493}]}]}
{"op":"mcm","clk":"986804572","pt":1580490601124,"mc":[{"id":"1.168136214","rc":[{"batb":[[0,2.48,2.6],[1,2.44,4.74]],"ltp":2.62,"tv":11.29,"id":11981493}]}]}
{"op":"mcm","clk":"986809178","pt":1580490678336,"mc":[{"id":"1.168136214","rc":[{"batb":[[0,2.44,5.35],[1,2.38,5.57],[2,1.51,3.36]],"ltp":2.62,"tv":11.29,"id":11981493}]}]}
{"op":"mcm","clk":"986815228","pt":1580490773375,"mc":[{"id":"1.168136214","rc":[{"batb":[[0,2.48,1.99],[1,2.44,5.35],[2,2.38,5.57]],"ltp":2.62,"tv":11.29,"id":11981493}]}]}
{"op":"mcm","clk":"986815409","pt":1580490776682,"mc":[{"id":"1.168136214","rc":[{"batb":[[0,2.48,2.6],[1,2.44,4.74]],"ltp":2.62,"tv":11.29,"id":11981493}]}]}
{"op":"mcm","clk":"986816094","pt":1580490786104,"mc":[{"id":"1.168136214","rc":[{"batb":[[0,2.48,1.99]],"ltp":2.62,"tv":11.29,"id":11981493}]}]}
{"op":"mcm","clk":"986816158","pt":1580490786888,"mc":[{"id":"1.168136214","rc":[{"batb":[[0,2.48,2.6]],"ltp":2.62,"tv":11.29,"id":11981493}]}]}
{"op":"mcm","clk":"986821346","pt":1580490860610,"mc":[{"id":"1.168136214","rc":[{"batb":[[0,2.44,5.35],[1,2.38,5.57],[2,1.51,3.36]],"ltp":2.62,"tv":11.29,"id":11981493}]}]}
{"op":"mcm","clk":"986826595","pt":1580490942756,"mc":[{"id":"1.168136214","rc":[{"batb":[[0,2.48,1.99],[1,2.44,5.35],[2,2.38,5.57]],"ltp":2.62,"tv":11.29,"id":11981493}]}]}
{"op":"mcm","clk":"986826756","pt":1580490945594,"mc":[{"id":"1.168136214","rc":[{"batb":[[0,2.48,2.6],[1,2.44,4.74]],"ltp":2.62,"tv":11.29,"id":11981493}]}]}
{"op":"mcm","clk":"986831439","pt":1580491025111,"mc":[{"id":"1.168136214","rc":[{"batb":[[0,2.44,5.35],[1,2.38,5.57],[2,1.51,3.36]],"ltp":2.62,"tv":11.29,"id":11981493}]}]}
{"op":"mcm","clk":"986847301","pt":1580491141183,"mc":[{"id":"1.168136214","rc":[{"batb":[[0,2.48,1.99],[1,2.44,5.35],[2,2.38,5.57]],"ltp":2.62,"tv":11.29,"id":11981493}]}]}
{"op":"mcm","clk":"986847685","pt":1580491147899,"mc":[{"id":"1.168136214","rc":[{"batb":[[0,2.48,2.6],[1,2.44,4.74]],"ltp":2.62,"tv":11.29,"id":11981493}]}]}
{"op":"mcm","clk":"986848407","pt":1580491161106,"mc":[{"id":"1.168136214","rc":[{"batb":[[1,1.57,3],[2,1.56,12.2]],"ltp":2.24,"tv":18.53,"id":17336468},{"batb":[[2,2.4,3]],"ltp":2.62,"tv":11.29,"id":11981493}]}]}
{"op":"mcm","clk":"986851533","pt":1580491216594,"mc":[{"id":"1.168136214","rc":[{"batl":[[0,980,9],[1,1000,1.88]],"ltp":0.0,"tv":0.0,"id":12925630},{"batl":[[0,980,9.72],[1,1000,0.2]],"ltp":2.24,"tv":18.53,"id":17336468},{"batl":[[0,980,9],[1,1000,0.2]],"ltp":2.62,"tv":11.29,"id":11981493}]}]}
{"op":"mcm","clk":"986851727","pt":1580491219397,"mc":[{"id":"1.168136214","rc":[{"batl":[[0,980,9.2],[1,1000,1.68]],"ltp":0.0,"tv":0.0,"id":12925630},{"batl":[[0,980,9.2],[1,1000,0]],"ltp":2.62,"tv":11.29,"id":11981493}]}]}
{"op":"mcm","clk":"986852561","pt":1580491233622,"mc":[{"id":"1.168136214","rc":[{"batb":[[0,2.44,5.35],[1,2.4,3],[2,2.38,5.57]],"ltp":2.62,"tv":11.29,"id":11981493}]}]}
{"op":"mcm","clk":"986853246","pt":1580491246091,"mc":[{"id":"1.168136214","rc":[{"batb":[[0,2.44,4.74]],"ltp":2.62,"tv":11.29,"id":11981493}]}]}
{"op":"mcm","clk":"986853301","pt":1580491246985,"mc":[{"id":"1.168136214","rc":[{"batb":[[0,2.44,5.35]],"ltp":2.62,"tv":11.29,"id":11981493}]}]}
{"op":"mcm","clk":"986857219","pt":1580491310883,"mc":[{"id":"1.168136214","rc":[{"batb":[[2,3.4,3.47]],"ltp":0.0,"tv":0.0,"id":12925630},{"batb":[[1,2.38,5.57],[2,1.89,3]],"ltp":2.62,"tv":11.29,"id":11981493}]}]}
{"op":"mcm","clk":"986860902","pt":1580491367452,"mc":[{"id":"1.168136214","rc":[{"batb":[[0,2.48,1.99],[1,2.44,5.35],[2,2.38,5.57]],"ltp":2.62,"tv":11.29,"id":11981493}]}]}
{"op":"mcm","clk":"986861293","pt":1580491374477,"mc":[{"id":"1.168136214","rc":[{"batb":[[0,2.48,2.6],[1,2.44,4.74]],"ltp":2.62,"tv":11.29,"id":11981493}]}]}
{"op":"mcm","clk":"986862878","pt":1580491406836,"mc":[{"id":"1.168136214","rc":[{"batb":[[2,2.4,3]],"ltp":2.62,"tv":11.29,"id":11981493}]}]}
{"op":"mcm","clk":"986868470","pt":1580491505066,"mc":[{"id":"1.168136214","rc":[{"batb":[[0,2.44,5.35],[1,2.4,3],[2,2.38,5.57]],"ltp":2.62,"tv":11.29,"id":11981493}]}]}
{"op":"mcm","clk":"986871650","pt":1580491556681,"mc":[{"id":"1.168136214","rc":[{"batb":[[1,2.38,5.57],[2,1.89,3]],"ltp":2.62,"tv":11.29,"id":11981493}]}]}
{"op":"mcm","clk":"986875694","pt":1580491630978,"mc":[{"id":"1.168136214","rc":[{"batb":[[0,2.48,1.99],[1,2.44,5.35],[2,2.38,5.57]],"ltp":2.62,"tv":11.29,"id":11981493}]}]}
{"op":"mcm","clk":"986875845","pt":1580491634072,"mc":[{"id":"1.168136214","rc":[{"batb":[[0,2.48,2.6],[1,2.44,4.74]],"ltp":2.62,"tv":11.29,"id":11981493}]}]}
{"op":"mcm","clk":"986877571","pt":1580491662766,"mc":[{"id":"1.168136214","rc":[{"batb":[[2,2.4,3]],"ltp":2.62,"tv":11.29,"id":11981493}]}]}
{"op":"mcm","clk":"986881588","pt":1580491735684,"mc":[{"id":"1.168136214","rc":[{"batb":[[0,2.44,5.35],[1,2.4,3],[2,2.38,5.57]],"ltp":2.62,"tv":11.29,"id":11981493}]}]}
{"op":"mcm","clk":"986883426","pt":1580491769128,"mc":[{"id":"1.168136214","rc":[{"batb":[[1,2.38,5.57],[2,1.88,90]],"ltp":2.62,"tv":11.29,"id":11981493}]}]}
{"op":"mcm","clk":"986883506","pt":1580491770130,"mc":[{"id":"1.168136214","rc":[{"batb":[[2,1.89,3]],"ltp":2.62,"tv":11.29,"id":11981493}]}]}
{"op":"mcm","clk":"986885340","pt":1580491802778,"mc":[{"id":"1.168136214","rc":[{"batb":[[0,3.6,8.1]],"ltp":0.0,"tv":0.0,"id":12925630},{"batb":[[1,1.58,10],[2,1.57,3]],"ltp":2.24,"tv":18.53,"id":17336468},{"batb":[[0,2.46,8.74],[1,2.44,4.74],[2,2.38,5.57]],"ltp":2.62,"tv":11.29,"id":11981493}]}]}
{"op":"mcm","clk":"986886660","pt":1580491820103,"mc":[{"id":"1.168136214","rc":[{"batb":[[2,3.1,8.47]],"ltp":0.0,"tv":0.0,"id":12925630},{"batb":[[1,1.59,3],[2,1.58,10]],"ltp":2.24,"tv":18.53,"id":17336468}]}]}
{"op":"mcm","clk":"986886854","pt":1580491822303,"mc":[{"id":"1.168136214","rc":[{"batb":[[0,3.65,1.71],[1,3.6,8.1],[2,3.55,1.68]],"ltp":0.0,"tv":0.0,"id":12925630}]}]}
{"op":"mcm","clk":"986888240","pt":1580491839149,"mc":[{"id":"1.168136214","rc":[{"batb":[[1,3.6,6.11]],"ltp":0.0,"tv":0.0,"id":12925630}]}]}
{"op":"mcm","clk":"986888245","pt":1580491839216,"mc":[{"id":"1.168136214","rc":[{"batb":[[0,3.7,1.99],[1,3.65,1.71],[2,3.6,6.11]],"ltp":0.0,"tv":0.0,"id":12925630}]}]}
{"op":"mcm","clk":"986890553","pt":1580491869154,"mc":[{"id":"1.168136214","rc":[{"batb":[[2,3.55,2.23]],"ltp":0.0,"tv":0.0,"id":12925630},{"batb":[[2,1.56,12.2]],"ltp":2.24,"tv":18.53,"id":17336468},{"batb":[[0,2.44,5.35],[1,2.38,5.57],[2,1.88,90]],"ltp":2.62,"tv":11.29,"id":11981493}]}]}
{"op":"mcm","clk":"986891162","pt":1580491876323,"mc":[{"id":"1.168136214","rc":[{"batb":[[1,1.57,3]],"ltp":2.24,"tv":18.53,"id":17336468}]}]}
{"op":"mcm","clk":"986895316","pt":1580491932670,"mc":[{"id":"1.168136214","rc":[{"batb":[[0,2.48,1.99],[1,2.44,5.35],[2,2.38,5.57]],"ltp":2.62,"tv":11.29,"id":11981493}]}]}
{"op":"mcm","clk":"986895527","pt":1580491935994,"mc":[{"id":"1.168136214","rc":[{"batb":[[0,2.48,2.6],[1,2.44,4.74]],"ltp":2.62,"tv":11.29,"id":11981493}]}]}
{"op":"mcm","clk":"986906389","pt":1580491953946,"mc":[{"id":"1.168136214","rc":[{"batb":[[2,2.4,3]],"ltp":2.62,"tv":11.29,"id":11981493}]}]}
{"op":"mcm","clk":"986911709","pt":1580492029001,"mc":[{"id":"1.168136214","rc":[{"batb":[[0,2.44,5.35],[1,2.4,3],[2,2.38,5.57]],"ltp":2.62,"tv":11.29,"id":11981493}]}]}
{"op":"mcm","clk":"986912097","pt":1580492034097,"mc":[{"id":"1.168136214","rc":[{"batb":[[0,2.44,4.74]],"ltp":2.62,"tv":11.29,"id":11981493}]}]}
{"op":"mcm","clk":"986912107","pt":1580492034219,"mc":[{"id":"1.168136214","rc":[{"batb":[[0,2.44,5.35]],"ltp":2.62,"tv":11.29,"id":11981493}]}]}
{"op":"mcm","clk":"986914490","pt":1580492066148,"mc":[{"id":"1.168136214","rc":[{"batb":[[1,2.38,5.57],[2,1.88,90]],"ltp":2.62,"tv":11.29,"id":11981493}]}]}
{"op":"mcm","clk":"986914497","pt":1580492066256,"mc":[{"id":"1.168136214","rc":[{"batb":[[2,1.89,3]],"ltp":2.62,"tv":11.29,"id":11981493}]}]}
{"op":"mcm","clk":"986918780","pt":1580492123536,"mc":[{"id":"1.168136214","rc":[{"batb":[[0,3.7,7.4]],"ltp":0.0,"tv":0.0,"id":12925630},{"batb":[[1,1.58,10],[2,1.57,3]],"ltp":2.24,"tv":18.53,"id":17336468},{"batb":[[0,2.46,8.74],[1,2.44,4.74],[2,2.38,5.57]],"ltp":2.62,"tv":11.29,"id":11981493}]}]}
{"op":"mcm","clk":"986918884","pt":1580492125060,"mc":[{"id":"1.168136214","rc":[{"batb":[[0,2.46,8.13]],"ltp":2.62,"tv":11.29,"id":11981493}]}]}
{"op":"mcm","clk":"986918892","pt":1580492125163,"mc":[{"id":"1.168136214","rc":[{"batb":[[0,2.46,8.74]],"ltp":2.62,"tv":11.29,"id":11981493}]}]}
{"op":"mcm","clk":"986919073","pt":1580492127688,"mc":[{"id":"1.168136214","rc":[{"batb":[[1,1.59,3],[2,1.58,10]],"ltp":2.24,"tv":18.53,"id":17336468}]}]}
{"op":"mcm","clk":"986920481","pt":1580492147300,"mc":[{"id":"1.168136214","rc":[{"batb":[[1,3.55,2.23],[2,3.1,8.47]],"ltp":0.0,"tv":0.0,"id":12925630}]}]}
{"op":"mcm","clk":"986920821","pt":1580492150991,"mc":[{"id":"1.168136214","rc":[{"batb":[[0,3.75,1.65],[1,3.7,7.4],[2,3.55,2.23]],"ltp":0.0,"tv":0.0,"id":12925630}]}]}
{"op":"mcm","clk":"986923635","pt":1580492187466,"mc":[{"id":"1.168136214","rc":[{"batb":[[1,1.6,10],[2,1.59,3]],"ltp":2.24,"tv":18.53,"id":17336468},{"batb":[[0,2.44,5.35],[1,2.4,8.33]],"ltp":2.62,"tv":11.29,"id":11981493}]}]}
{"op":"mcm","clk":"986923959","pt":1580492192265,"mc":[{"id":"1.168136214","rc":[{"batb":[[0,1.62,24.36],[1,1.61,2.96],[2,1.6,10]],"ltp":2.24,"tv":18.53,"id":17336468}]}]}
{"op":"mcm","clk":"986927243","pt":1580492237869,"mc":[{"id":"1.168136214","rc":[{"batb":[[0,3.8,1.99],[1,3.75,1.65],[2,3.7,5.41]],"ltp":0.0,"tv":0.0,"id":12925630},{"batb":[[0,2.48,1.99],[1,2.44,5.35],[2,2.4,8.33]],"ltp":2.62,"tv":11.29,"id":11981493}]}]}
{"op":"mcm","clk":"986927367","pt":1580492239738,"mc":[{"id":"1.168136214","rc":[{"batb":[[0,2.48,2.6],[1,2.44,4.74]],"ltp":2.62,"tv":11.29,"id":11981493}]}]}
{"op":"mcm","clk":"986928182","pt":1580492251785,"mc":[{"id":"1.168136214","rc":[{"batb":[[0,3.8,7.25],[2,3.55,2.23]],"ltp":0.0,"tv":0.0,"id":12925630},{"batb":[[0,1.63,10],[1,1.62,24.36],[2,1.61,2.96]],"ltp":2.24,"tv":18.53,"id":17336468},{"batb":[[1,2.46,8.13],[2,2.44,4.74]],"ltp":2.62,"tv":11.29,"id":11981493}]}]}
{"op":"mcm","clk":"986929199","pt":1580492267070,"mc":[{"id":"1.168136214","rc":[{"batb":[[1,1.61,2.96],[2,1.56,12.2]],"ltp":2.24,"tv":18.53,"id":17336468}]}]}
{"op":"mcm","clk":"986929265","pt":1580492267969,"mc":[{"id":"1.168136214","rc":[{"batb":[[1,3.55,2.23],[2,3.1,8.47]],"ltp":0.0,"tv":0.0,"id":12925630}]}]}
{"op":"mcm","clk":"986929563","pt":1580492271995,"mc":[{"id":"1.168136214","rc":[{"batb":[[0,3.85,1.6],[1,3.8,7.25],[2,3.55,2.23]],"ltp":0.0,"tv":0.0,"id":12925630}]}]}
{"op":"mcm","clk":"986932685","pt":1580492315679,"mc":[{"id":"1.168136214","rc":[{"batb":[[0,1.61,2.96],[1,1.57,10]],"ltp":2.24,"tv":18.53,"id":17336468},{"batb":[[0,2.5,8.61],[1,2.48,1.99]],"ltp":2.62,"tv":11.29,"id":11981493}]}]}
{"op":"mcm","clk":"986935435","pt":1580492353029,"mc":[{"id":"1.168136214","rc":[{"batb":[[0,3.9,1.99],[1,3.85,1.6],[2,3.8,5.26]],"ltp":0.0,"tv":0.0,"id":12925630},{"batb":[[1,2.44,4.74],[2,2.38,5.57]],"ltp":2.62,"tv":11.29,"id":11981493}]}]}
{"op":"mcm","clk":"986936114","pt":1580492362151,"mc":[{"id":"1.168136214","rc":[{"batb":[[1,1.58,3],[2,1.57,10]],"ltp":2.24,"tv":18.53,"id":17336468}]}]}
{"op":"mcm","clk":"986937304","pt":1580492379285,"mc":[{"id":"1.168136214","rc":[{"batb":[[2,3.55,2.23]],"ltp":0.0,"tv":0.0,"id":12925630},{"batb":[[2,1.56,12.2]],"ltp":2.24,"tv":18.53,"id":17336468},{"batb":[[0,2.44,5.35],[1,2.38,5.57],[2,1.88,90]],"ltp":2.62,"tv":11.29,"id":11981493}]}]}
{"op":"mcm","clk":"986941399","pt":1580492436875,"mc":[{"id":"1.168136214","rc":[{"batb":[[1,1.56,12.2],[2,1.55,90]],"ltp":2.24,"tv":18.53,"id":17336468}]}]}
{"op":"mcm","clk":"986941675","pt":1580492440090,"mc":[{"id":"1.168136214","rc":[{"batb":[[0,2.48,1.99],[1,2.44,5.35],[2,2.38,5.57]],"ltp":2.62,"tv":11.29,"id":11981493}]}]}
{"op":"mcm","clk":"986942160","pt":1580492446986,"mc":[{"id":"1.168136214","rc":[{"batb":[[0,2.48,2.6],[1,2.44,4.74]],"ltp":2.62,"tv":11.29,"id":11981493}]}]}
{"op":"mcm","clk":"986947822","pt":1580492527149,"mc":[{"id":"1.168136214","rc":[{"batb":[[0,2.44,5.35],[1,2.38,5.57],[2,1.88,90]],"ltp":2.62,"tv":11.29,"id":11981493}]}]}
{"op":"mcm","clk":"986948453","pt":1580492535068,"mc":[{"id":"1.168136214","rc":[{"batb":[[0,2.44,4.74]],"ltp":2.62,"tv":11.29,"id":11981493}]}]}
{"op":"mcm","clk":"986948509","pt":1580492535654,"mc":[{"id":"1.168136214","rc":[{"batb":[[0,2.44,5.35]],"ltp":2.62,"tv":11.29,"id":11981493}]}]}
{"op":"mcm","clk":"986955943","pt":1580492632885,"mc":[{"id":"1.168136214","rc":[{"batb":[[0,2.48,1.99],[1,2.44,5.35],[2,2.38,5.57]],"ltp":2.62,"tv":11.29,"id":11981493}]}]}
{"op":"mcm","clk":"986957042","pt":1580492646511,"mc":[{"id":"1.168136214","rc":[{"batb":[[0,2.48,2.6],[1,2.44,4.74]],"ltp":2.62,"tv":11.29,"id":11981493}]}]}
{"op":"mcm","clk":"986962774","pt":1580492727829,"mc":[{"id":"1.168136214","rc":[{"batb":[[0,2.44,5.35],[1,2.38,5.57],[2,1.88,90]],"ltp":2.62,"tv":11.29,"id":11981493}]}]}
{"op":"mcm","clk":"986970951","pt":1580492834084,"mc":[{"id":"1.168136214","rc":[{"batb":[[0,2.48,1.99],[1,2.44,5.35],[2,2.38,5.57]],"ltp":2.62,"tv":11.29,"id":11981493}]}]}
{"op":"mcm","clk":"986971847","pt":1580492844489,"mc":[{"id":"1.168136214","rc":[{"batb":[[0,2.48,2.6],[1,2.44,4.74]],"ltp":2.62,"tv":11.29,"id":11981493}]}]}
{"op":"mcm","clk":"986987469","pt":1580492930868,"mc":[{"id":"1.168136214","rc":[{"batb":[[0,2.44,5.35],[1,2.38,5.57],[2,1.88,90]],"ltp":2.62,"tv":11.29,"id":11981493}]}]}
{"op":"mcm","clk":"986994905","pt":1580493038374,"mc":[{"id":"1.168136214","rc":[{"batb":[[0,2.48,1.99],[1,2.44,5.35],[2,2.38,5.57]],"ltp":2.62,"tv":11.29,"id":11981493}]}]}
{"op":"mcm","clk":"986995953","pt":1580493051512,"mc":[{"id":"1.168136214","rc":[{"batb":[[0,2.48,2.6],[1,2.44,4.74]],"ltp":2.62,"tv":11.29,"id":11981493}]}]}
{"op":"mcm","clk":"987003366","pt":1580493144993,"mc":[{"id":"1.168136214","rc":[{"batb":[[0,2.44,5.35],[1,2.38,5.57],[2,1.88,90]],"ltp":2.62,"tv":11.29,"id":11981493}]}]}
{"op":"mcm","clk":"987007181","pt":1580493197076,"mc":[{"id":"1.168136214","rc":[{"batb":[[0,3.95,1.68],[1,3.9,1.99],[2,3.85,1.6]],"ltp":0.0,"tv":0.0,"id":12925630},{"batb":[[0,1.57,2.96]],"ltp":2.24,"tv":18.53,"id":17336468}]}]}
{"op":"mcm","clk":"987007790","pt":1580493205679,"mc":[{"id":"1.168136214","rc":[{"batb":[[0,1.58,24.97],[1,1.57,2.96],[2,1.56,12.2]],"ltp":2.24,"tv":18.53,"id":17336468}]}]}
{"op":"mcm","clk":"987013048","pt":1580493276994,"mc":[{"id":"1.168136214","rc":[{"batb":[[0,4,1.99],[1,3.95,1.68],[2,3.9,5.13]],"ltp":0.0,"tv":0.0,"id":12925630},{"batb":[[0,1.59,10],[1,1.58,24.97],[2,1.57,2.96]],"ltp":2.24,"tv":18.53,"id":17336468},{"batb":[[0,2.48,10.05],[1,2.44,5.35],[2,2.38,5.57]],"ltp":2.62,"tv":11.29,"id":11981493}]}]}
{"op":"mcm","clk":"987013113","pt":1580493277801,"mc":[{"id":"1.168136214","rc":[{"batb":[[1,1.57,2.96],[2,1.56,12.2]],"ltp":2.24,"tv":18.53,"id":17336468}]}]}
{"op":"mcm","clk":"987013545","pt":1580493284113,"mc":[{"id":"1.168136214","rc":[{"batb":[[0,2.48,10.66],[1,2.44,4.74]],"ltp":2.62,"tv":11.29,"id":11981493}]}]}
{"op":"mcm","clk":"987015073","pt":1580493305132,"mc":[{"id":"1.168136214","rc":[{"batb":[[0,4.1,1.68],[1,4,1.99]],"ltp":0.0,"tv":0.0,"id":12925630},{"batb":[[0,1.6,2.9],[1,1.59,10]],"ltp":2.24,"tv":18.53,"id":17336468}]}]}
{"op":"mcm","clk":"987015862","pt":1580493314751,"mc":[{"id":"1.168136214","rc":[{"batb":[[0,1.61,24.51],[1,1.6,2.9],[2,1.59,10]],"ltp":2.24,"tv":18.53,"id":17336468}]}]}
{"op":"mcm","clk":"987016301","pt":1580493320897,"mc":[{"id":"1.168136214","rc":[{"batb":[[2,3.95,1.54]],"ltp":0.0,"tv":0.0,"id":12925630}]}]}
{"op":"mcm","clk":"987018471","pt":1580493351394,"mc":[{"id":"1.168136214","rc":[{"batb":[[2,1.56,12.2]],"ltp":2.24,"tv":18.53,"id":17336468}]}]}
{"op":"mcm","clk":"987019354","pt":1580493362014,"mc":[{"id":"1.168136214","rc":[{"batb":[[0,1.62,2.87],[1,1.61,24.51]],"ltp":2.24,"tv":18.53,"id":17336468}]}]}
{"op":"mcm","clk":"987019925","pt":1580493368787,"mc":[{"id":"1.168136214","rc":[{"batb":[[1,1.56,12.2],[2,1.55,90]],"ltp":2.24,"tv":18.53,"id":17336468}]}]}
{"op":"mcm","clk":"987022798","pt":1580493406123,"mc":[{"id":"1.168136214","rc":[{"batb":[[0,1.57,2.87]],"ltp":2.24,"tv":18.53,"id":17336468}]}]}
{"op":"mcm","clk":"987024143","pt":1580493423047,"mc":[{"id":"1.168136214","rc":[{"batb":[[0,1.58,24.97],[1,1.57,2.87],[2,1.56,12.2]],"ltp":2.24,"tv":18.53,"id":17336468}]}]}
{"op":"mcm","clk":"987024396","pt":1580493426057,"mc":[{"id":"1.168136214","rc":[{"batb":[[0,2.48,8.67]],"ltp":2.62,"tv":11.29,"id":11981493}]}]}
{"op":"mcm","clk":"987024457","pt":1580493426743,"mc":[{"id":"1.168136214","rc":[{"batb":[[0,4.2,1.99],[1,4.1,1.68]],"ltp":0.0,"tv":0.0,"id":12925630}]}]}
{"op":"mcm","clk":"987025796","pt":1580493445152,"mc":[{"id":"1.168136214","rc":[{"batb":[[1,1.56,12.2],[2,1.55,90]],"ltp":2.24,"tv":18.53,"id":17336468}]}]}
{"op":"mcm","clk":"987025879","pt":1580493446144,"mc":[{"id":"1.168136214","rc":[{"batb":[[0,4.3,1.68],[1,4.2,1.99]],"ltp":0.0,"tv":0.0,"id":12925630},{"batb":[[0,1.59,2.83],[1,1.58,24.97],[2,1.56,12.2]],"ltp":2.24,"tv":18.53,"id":17336468}]}]}
{"op":"mcm","clk":"987027053","pt":1580493459800,"mc":[{"id":"1.168136214","rc":[{"batb":[[1,1.56,12.2],[2,1.55,90]],"ltp":2.24,"tv":18.53,"id":17336468}]}]}
{"op":"mcm","clk":"987029369","pt":1580493488106,"mc":[{"id":"1.168136214","rc":[{"batb":[[0,1.56,12.2],[1,1.55,90],[2,1.51,3.36]],"ltp":2.24,"tv":18.53,"id":17336468}]}]}
{"op":"mcm","clk":"987029474","pt":1580493489089,"mc":[{"id":"1.168136214","rc":[{"batb":[[0,1.57,2.83],[1,1.56,12.2],[2,1.55,90]],"ltp":2.24,"tv":18.53,"id":17336468}]}]}
{"op":"mcm","clk":"987029786","pt":1580493492000,"mc":[{"id":"1.168136214","rc":[{"batb":[[0,4.3,6.33]],"ltp":0.0,"tv":0.0,"id":12925630},{"batb":[[0,1.57,12.83]],"ltp":2.24,"tv":18.53,"id":17336468},{"batb":[[0,2.44,5.35],[1,2.4,8.33]],"ltp":2.62,"tv":11.29,"id":11981493}]}]}
{"op":"mcm","clk":"987030148","pt":1580493495709,"mc":[{"id":"1.168136214","rc":[{"batb":[[0,1.58,24.97],[1,1.57,12.83],[2,1.56,12.2]],"ltp":2.24,"tv":18.53,"id":17336468}]}]}
{"op":"mcm","clk":"987030318","pt":1580493497896,"mc":[{"id":"1.168136214","rc":[{"batb":[[2,3.5,1.02]],"ltp":0.0,"tv":0.0,"id":12925630}]}]}
{"op":"mcm","clk":"987030617","pt":1580493501119,"mc":[{"id":"1.168136214","rc":[{"batb":[[0,4.4,1.34],[1,4.3,6.33],[2,4.2,1.99]],"ltp":0.0,"tv":0.0,"id":12925630}]}]}
{"op":"mcm","clk":"987033064","pt":1580493530071,"mc":[{"id":"1.168136214","rc":[{"batb":[[0,1.59,2.8],[1,1.58,24.97],[2,1.57,10]],"ltp":2.24,"tv":18.53,"id":17336468}]}]}
{"op":"mcm","clk":"987033335","pt":1580493533063,"mc":[{"id":"1.168136214","rc":[{"batb":[[1,1.57,10],[2,1.56,12.2]],"ltp":2.24,"tv":18.53,"id":17336468}]}]}
{"op":"mcm","clk":"987036607","pt":1580493569084,"mc":[{"id":"1.168136214","rc":[{"batb":[[0,2.46,8.74],[1,2.44,4.74]],"ltp":2.62,"tv":11.29,"id":11981493}]}]}
{"op":"mcm","clk":"987036673","pt":1580493569974,"mc":[{"id":"1.168136214","rc":[{"batb":[[0,4.4,2.48]],"ltp":0.0,"tv":0.0,"id":12925630}]}]}
{"op":"mcm","clk":"987036775","pt":1580493571085,"mc":[{"id":"1.168136214","rc":[{"batb":[[0,4.5,1.68],[1,4.4,2.48],[2,4.3,4.65]],"ltp":0.0,"tv":0.0,"id":12925630},{"batb":[[0,1.58,2.8]],"ltp":2.24,"tv":18.53,"id":17336468}]}]}
{"op":"mcm","clk":"987038211","pt":1580493588037,"mc":[{"id":"1.168136214","rc":[{"batb":[[1,4.4,1.14]],"ltp":0.0,"tv":0.0,"id":12925630},{"batb":[[0,1.59,24.81],[1,1.58,2.8],[2,1.57,10]],"ltp":2.24,"tv":18.53,"id":17336468}]}]}
{"op":"mcm","clk":"987041029","pt":1580493614875,"mc":[{"id":"1.168136214","rc":[{"batb":[[0,4.4,2.82],[1,4.3,4.65],[2,4.2,1.99]],"batl":[[1,1000,1.68]],"ltp":0.0,"tv":0.0,"id":12925630},{"trd":[[2.28,7.11],[2.32,3.98]],"batb":[[0,1.6,2.76],[1,1.59,24.78]],"ltp":2.24,"tv":18.53,"id":17336468},{"trd":[[2.72,5.29]],"batb":[[1,2.44,4.74],[2,2.38,5.56]],"ltp":2.62,"tv":11.29,"id":11981493}],"tv":29.82}]}
{"op":"mcm","clk":"987041442","pt":1580493619082,"mc":[{"id":"1.168136214","rc":[{"batb":[[2,3.5,1.02]],"ltp":0.0,"tv":0.0,"id":12925630}]}]}
{"op":"mcm","clk":"987041452","pt":1580493619187,"mc":[{"id":"1.168136214","rc":[{"batb":[[0,4.5,1.99],[1,4.4,2.82],[2,4.3,4.65]],"ltp":0.0,"tv":0.0,"id":12925630}]}]}
{"op":"mcm","clk":"987041672","pt":1580493621585,"mc":[{"id":"1.168136214","rc":[{"batb":[[0,4.5,3.29]],"ltp":0.0,"tv":0.0,"id":12925630}]}]}
{"op":"mcm","clk":"987041933","pt":1580493624878,"mc":[{"id":"1.168136214","rc":[{"batb":[[1,1.57,10],[2,1.56,12.19]],"ltp":2.24,"tv":18.53,"id":17336468}]}]}
{"op":"mcm","clk":"987043333","pt":1580493640726,"mc":[{"id":"1.168136214","rc":[{"batb":[[0,4.5,7.73],[2,3.5,1.02]],"ltp":0.0,"tv":0.0,"id":12925630},{"batb":[[0,2.44,5.35],[1,2.4,8.33]],"ltp":2.62,"tv":11.29,"id":11981493}]}]}
{"op":"mcm","clk":"987044107","pt":1580493648695,"mc":[{"id":"1.168136214","rc":[{"batb":[[2,3.1,8]],"ltp":0.0,"tv":0.0,"id":12925630}]}]}
{"op":"mcm","clk":"987045520","pt":1580493661150,"mc":[{"id":"1.168136214","rc":[{"batb":[[0,1.61,1.23],[1,1.6,2.76],[2,1.57,10]],"ltp":2.24,"tv":18.53,"id":17336468}]}]}
{"op":"mcm","clk":"987045619","pt":1580493661810,"mc":[{"id":"1.168136214","rc":[{"batb":[[0,4.6,1.88],[1,4.5,7.73],[2,4.4,1.68]],"ltp":0.0,"tv":0.0,"id":12925630},{"batb":[[0,2.46,1.41],[1,2.44,4.74],[2,2.4,8.33]],"ltp":2.62,"tv":11.29,"id":11981493}]}]}
{"op":"mcm","clk":"987047068","pt":1580493677639,"mc":[{"id":"1.168136214","rc":[{"batb":[[1,4.5,6.43]],"ltp":0.0,"tv":0.0,"id":12925630}]}]}
{"op":"mcm","clk":"987047350","pt":1580493680650,"mc":[{"id":"1.168136214","rc":[{"batb":[[0,4.6,3.14]],"ltp":0.0,"tv":0.0,"id":12925630}]}]}
{"op":"mcm","clk":"987048629","pt":1580493691056,"mc":[{"id":"1.168136214","rc":[{"batl":[[0,16,10],[1,980,9.2],[2,1000,1.68]],"ltp":0.0,"tv":0.0,"id":12925630}]}]}
{"op":"mcm","clk":"987050201","pt":1580493707753,"mc":[{"id":"1.168136214","rc":[{"batl":[[0,15,9],[1,16,10],[2,1000,1.88]],"ltp":0.0,"tv":0.0,"id":12925630}]}]}
{"op":"mcm","clk":"987050430","pt":1580493710125,"mc":[{"id":"1.168136214","rc":[{"batb":[[2,1.56,12.19]],"ltp":2.24,"tv":18.53,"id":17336468},{"batb":[[2,2.38,5.56]],"ltp":2.62,"tv":11.29,"id":11981493}]}]}
{"op":"mcm","clk":"987051101","pt":1580493717059,"mc":[{"id":"1.168136214","rc":[{"batl":[[0,15,9.34]],"ltp":0.0,"tv":0.0,"id":12925630}]}]}
{"op":"mcm","clk":"987072853","pt":1580493836914,"mc":[{"id":"1.168136214","rc":[{"batb":[[0,4.7,1.99],[1,4.6,3.14],[2,4.5,4.44]],"ltp":0.0,"tv":0.0,"id":12925630},{"batb":[[0,2.48,1.99],[1,2.46,1.41],[2,2.44,4.74]],"ltp":2.62,"tv":11.29,"id":11981493}]}]}
{"op":"mcm","clk":"987073317","pt":1580493841601,"mc":[{"id":"1.168136214","rc":[{"batb":[[0,2.48,2.6],[1,2.44,5.54],[2,2.38,5.56]],"ltp":2.62,"tv":11.29,"id":11981493}]}]}
{"op":"mcm","clk":"987074842","pt":1580493858112,"mc":[{"id":"1.168136214","rc":[{"batb":[[1,4.6,1.88]],"ltp":0.0,"tv":0.0,"id":12925630}]}]}
{"op":"mcm","clk":"987077314","pt":1580493883225,"mc":[{"id":"1.168136214","rc":[{"batl":[[0,15,9.54],[2,1000,1.68]],"ltp":0.0,"tv":0.0,"id":12925630}]}]}
{"op":"mcm","clk":"987080932","pt":1580493921253,"mc":[{"id":"1.168136214","rc":[{"batb":[[1,4.6,3.14]],"ltp":0.0,"tv":0.0,"id":12925630}]}]}
{"op":"mcm","clk":"987083376","pt":1580493947566,"mc":[{"id":"1.168136214","rc":[{"batb":[[1,4.6,1.88]],"ltp":0.0,"tv":0.0,"id":12925630}]}]}
{"op":"mcm","clk":"987083705","pt":1580493950995,"mc":[{"id":"1.168136214","rc":[{"batb":[[0,4.7,3.22]],"ltp":0.0,"tv":0.0,"id":12925630}]}]}
{"op":"mcm","clk":"987083771","pt":1580493951660,"mc":[{"id":"1.168136214","rc":[{"batb":[[0,4.8,1.04],[1,4.7,3.22],[2,4.5,5.23]],"ltp":0.0,"tv":0.0,"id":12925630}]}]}
{"op":"mcm","clk":"987086162","pt":1580493977804,"mc":[{"id":"1.168136214","rc":[{"batb":[[1,4.7,1.99]],"ltp":0.0,"tv":0.0,"id":12925630}]}]}
{"op":"mcm","clk":"987086450","pt":1580493981428,"mc":[{"id":"1.168136214","rc":[{"batb":[[0,4.8,2.24]],"ltp":0.0,"tv":0.0,"id":12925630}]}]}
{"op":"mcm","clk":"987089373","pt":1580494015135,"mc":[{"id":"1.168136214","rc":[{"batb":[[1,4.5,5.23],[2,4.4,1.68]],"ltp":0.0,"tv":0.0,"id":12925630},{"batb":[[0,2.46,1.41],[1,2.44,4.74]],"ltp":2.62,"tv":11.29,"id":11981493}]}]}
{"op":"mcm","clk":"987089385","pt":1580494015237,"mc":[{"id":"1.168136214","rc":[{"batb":[[0,4.9,1.99],[1,4.8,2.24],[2,4.5,5.23]],"ltp":0.0,"tv":0.0,"id":12925630}]}]}
{"op":"mcm","clk":"987091528","pt":1580494038071,"mc":[{"id":"1.168136214","rc":[{"batb":[[1,4.8,1.04]],"ltp":0.0,"tv":0.0,"id":12925630}]}]}
{"op":"mcm","clk":"987091597","pt":1580494038653,"mc":[{"id":"1.168136214","rc":[{"batb":[[2,4.4,2.47]],"ltp":0.0,"tv":0.0,"id":12925630}]}]}
{"op":"mcm","clk":"987097298","pt":1580494096211,"mc":[{"id":"1.168136214","rc":[{"trd":[[2.44,9.18],[2.46,2.82]],"batb":[[0,2.38,5.7],[1,1.88,90],[2,1.53,82.19]],"ltp":2.44,"tv":23.29,"id":11981493}],"tv":41.82}]}
{"op":"mcm","clk":"987104212","pt":1580494168213,"mc":[{"id":"1.168136214","rc":[{"batb":[[0,2.46,1.99],[1,2.38,5.7],[2,1.88,90]],"ltp":2.44,"tv":23.29,"id":11981493}]}]}
{"op":"mcm","clk":"987108974","pt":1580494221304,"mc":[{"id":"1.168136214","rc":[{"batb":[[0,5,1.14],[1,4.9,1.99],[2,4.8,1.04]],"ltp":0.0,"tv":0.0,"id":12925630}]}]}
{"op":"mcm","clk":"987117455","pt":1580494316543,"mc":[{"id":"1.168136214","rc":[{"batb":[[0,5.1,1.99],[1,5,1.14]],"ltp":0.0,"tv":0.0,"id":12925630}]}]}
{"op":"mcm","clk":"987119565","pt":1580494337779,"mc":[{"id":"1.168136214","rc":[{"batb":[[1,4.8,1.04],[2,4.4,2.47]],"ltp":0.0,"tv":0.0,"id":12925630}]}]}
{"op":"mcm","clk":"987133488","pt":1580494475059,"mc":[{"id":"1.168136214","rc":[{"batb":[[0,4.8,1.04],[1,4.4,2.47],[2,3.1,8]],"ltp":0.0,"tv":0.0,"id":12925630},{"batb":[[1,1.6,15.81]],"ltp":2.24,"tv":18.53,"id":17336468}]}]}
{"op":"mcm","clk":"987133572","pt":1580494475840,"mc":[{"id":"1.168136214","rc":[{"batb":[[0,4.9,1.99],[1,4.8,1.04],[2,4.4,2.47]],"batl":[[0,14.5,2.22],[1,15,9],[2,16,10]],"ltp":0.0,"tv":0.0,"id":12925630},{"batl":[[0,980,9.75]],"ltp":2.24,"tv":18.53,"id":17336468}]}]}
{"op":"mcm","clk":"987135315","pt":1580494493364,"mc":[{"id":"1.168136214","rc":[{"batl":[[0,13.5,9],[1,14.5,2.22]],"ltp":0.0,"tv":0.0,"id":12925630}]}]}
{"op":"mcm","clk":"987135475","pt":1580494495149,"mc":[{"id":"1.168136214","rc":[{"batl":[[1,14.5,1.88]],"ltp":0.0,"tv":0.0,"id":12925630}]}]}
{"op":"mcm","clk":"987135592","pt":1580494496155,"mc":[{"id":"1.168136214","rc":[{"batl":[[0,13.5,9.38]],"ltp":0.0,"tv":0.0,"id":12925630}]}]}
{"op":"mcm","clk":"987138086","pt":1580494521693,"mc":[{"id":"1.168136214","rc":[{"batb":[[0,5,1.14],[1,4.9,1.99],[2,4.8,1.04]],"ltp":0.0,"tv":0.0,"id":12925630}]}]}
{"op":"mcm","clk":"987159329","pt":1580494658303,"mc":[{"id":"1.168136214","rc":[{"batb":[[0,5.1,1.99],[1,5,1.14]],"ltp":0.0,"tv":0.0,"id":12925630}]}]}
{"op":"mcm","clk":"987160001","pt":1580494667738,"mc":[{"id":"1.168136214","rc":[{"batb":[[1,4.8,1.04],[2,4.4,2.47]],"ltp":0.0,"tv":0.0,"id":12925630}]}]}
{"op":"mcm","clk":"987160290","pt":1580494671132,"mc":[{"id":"1.168136214","rc":[{"batb":[[0,5.2,1.08],[1,5.1,1.99],[2,4.8,1.04]],"ltp":0.0,"tv":0.0,"id":12925630}]}]}
{"op":"mcm","clk":"987162891","pt":1580494706977,"mc":[{"id":"1.168136214","rc":[{"batb":[[0,5.2,1.78]],"ltp":0.0,"tv":0.0,"id":12925630}]}]}
{"op":"mcm","clk":"987167377","pt":1580494770029,"mc":[{"id":"1.168136214","rc":[{"batl":[[0,13,2.06],[1,13.5,9],[2,16,10.2]],"ltp":0.0,"tv":0.0,"id":12925630},{"batb":[[1,1.57,15.81]],"ltp":2.24,"tv":18.53,"id":17336468}]}]}
{"op":"mcm","clk":"987167741","pt":1580494774931,"mc":[{"id":"1.168136214","rc":[{"batb":[[1,1.58,24.94],[2,1.57,15.81]],"ltp":2.24,"tv":18.53,"id":17336468}]}]}
{"op":"mcm","clk":"987168494","pt":1580494786937,"mc":[{"id":"1.168136214","rc":[{"batl":[[0,12,9],[1,13,2.06]],"ltp":0.0,"tv":0.0,"id":12925630}]}]}
{"op":"mcm","clk":"987168697","pt":1580494789247,"mc":[{"id":"1.168136214","rc":[{"batb":[[1,1.59,3],[2,1.58,24.94]],"ltp":2.24,"tv":18.53,"id":17336468},{"batb":[[2,1.89,3]],"ltp":2.44,"tv":23.29,"id":11981493}]}]}
{"op":"mcm","clk":"987169042","pt":1580494794407,"mc":[{"id":"1.168136214","rc":[{"batb":[[2,1.57,15.81]],"ltp":2.24,"tv":18.53,"id":17336468}]}]}
{"op":"mcm","clk":"987169834","pt":1580494805933,"mc":[{"id":"1.168136214","rc":[{"batb":[[1,4.8,1.04],[2,4.4,1.68]],"ltp":0.0,"tv":0.0,"id":12925630}]}]}
{"op":"mcm","clk":"987172419","pt":1580494838144,"mc":[{"id":"1.168136214","rc":[{"batl":[[0,12,9.2],[2,16,10]],"ltp":0.0,"tv":0.0,"id":12925630}]}]}
{"op":"mcm","clk":"987172769","pt":1580494842822,"mc":[{"id":"1.168136214","rc":[{"batb":[[1,1.58,3]],"ltp":2.24,"tv":18.53,"id":17336468}]}]}
{"op":"mcm","clk":"987173284","pt":1580494850354,"mc":[{"id":"1.168136214","rc":[{"batb":[[1,1.59,24.78],[2,1.58,3]],"ltp":2.24,"tv":18.53,"id":17336468}]}]}
{"op":"mcm","clk":"987176414","pt":1580494895050,"mc":[{"id":"1.168136214","rc":[{"batb":[[2,1.57,15.81]],"ltp":2.24,"tv":18.53,"id":17336468}]}]}
{"op":"mcm","clk":"987176443","pt":1580494895462,"mc":[{"id":"1.168136214","rc":[{"batb":[[1,1.6,3],[2,1.59,24.78]],"ltp":2.24,"tv":18.53,"id":17336468}]}]}
{"op":"mcm","clk":"987177095","pt":1580494904066,"mc":[{"id":"1.168136214","rc":[{"batl":[[0,2.98,9.72],[1,980,9.03],[2,1000,0.2]],"ltp":2.24,"tv":18.53,"id":17336468}]}]}
{"op":"mcm","clk":"987177275","pt":1580494906081,"mc":[{"id":"1.168136214","rc":[{"batb":[[2,1.57,15.81]],"ltp":2.24,"tv":18.53,"id":17336468}]}]}
{"op":"mcm","clk":"987178355","pt":1580494919892,"mc":[{"id":"1.168136214","rc":[{"batl":[[1,3.95,9],[2,1000,0.23]],"ltp":2.24,"tv":18.53,"id":17336468}]}]}
{"op":"mcm","clk":"987179959","pt":1580494942809,"mc":[{"id":"1.168136214","rc":[{"batb":[[1,1.58,3]],"ltp":2.24,"tv":18.53,"id":17336468}]}]}
{"op":"mcm","clk":"987180109","pt":1580494944734,"mc":[{"id":"1.168136214","rc":[{"batb":[[1,1.59,24.78],[2,1.58,3]],"ltp":2.24,"tv":18.53,"id":17336468}]}]}
{"op":"mcm","clk":"987182185","pt":1580494970976,"mc":[{"id":"1.168136214","rc":[{"batb":[[0,5.3,1.98],[1,5.2,1.78],[2,4.8,1.04]],"ltp":0.0,"tv":0.0,"id":12925630},{"batb":[[1,1.6,1.98],[2,1.59,24.78]],"ltp":2.24,"tv":18.53,"id":17336468},{"batb":[[0,2.48,1.98],[1,2.46,1.99],[2,2.38,5.7]],"ltp":2.44,"tv":23.29,"id":11981493}]}]}
{"op":"mcm","clk":"987183121","pt":1580494981965,"mc":[{"id":"1.168136214","rc":[{"batb":[[2,1.58,3]],"ltp":2.24,"tv":18.53,"id":17336468}]}]}
{"op":"mcm","clk":"987183833","pt":1580494990699,"mc":[{"id":"1.168136214","rc":[{"batb":[[2,2.4,3.14]],"ltp":2.44,"tv":23.29,"id":11981493}]}]}
{"op":"mcm","clk":"987184481","pt":1580494997893,"mc":[{"id":"1.168136214","rc":[{"batb":[[1,4.8,1.74],[2,4.5,3]],"ltp":0.0,"tv":0.0,"id":12925630}]}]}
{"op":"mcm","clk":"987184842","pt":1580495001983,"mc":[{"id":"1.168136214","rc":[{"batb":[[0,5.4,1.03],[1,5.3,1.98],[2,4.8,1.74]],"ltp":0.0,"tv":0.0,"id":12925630}]}]}
{"op":"mcm","clk":"987185651","pt":1580495010882,"mc":[{"id":"1.168136214","rc":[{"batl":[[0,11.5,1.88],[1,12,9],[2,16,10.38]],"ltp":0.0,"tv":0.0,"id":12925630},{"batb":[[0,1.61,2.91]],"batl":[[0,2.96,5.4],[1,2.98,9],[2,3.95,9]],"ltp":2.24,"tv":18.53,"id":17336468}]}]}
{"op":"mcm","clk":"987186079","pt":1580495016094,"mc":[{"id":"1.168136214","rc":[{"batl":[[0,11.5,1.68]],"ltp":0.0,"tv":0.0,"id":12925630}]}]}
{"op":"mcm","clk":"987186095","pt":1580495016201,"mc":[{"id":"1.168136214","rc":[{"batl":[[0,11.5,1.88]],"ltp":0.0,"tv":0.0,"id":12925630}]}]}
{"op":"mcm","clk":"987186408","pt":1580495020092,"mc":[{"id":"1.168136214","rc":[{"batl":[[0,2.94,14.13],[1,2.96,4.68],[2,2.98,9]],"ltp":2.24,"tv":18.53,"id":17336468}]}]}
{"op":"mcm","clk":"987188453","pt":1580495044047,"mc":[{"id":"1.168136214","rc":[{"batb":[[2,1.57,3]],"ltp":2.24,"tv":18.53,"id":17336468}]}]}
{"op":"mcm","clk":"987193722","pt":1580495113617,"mc":[{"id":"1.168136214","rc":[{"batb":[[1,2.4,3.14],[2,2.38,5.56]],"ltp":2.44,"tv":23.29,"id":11981493}]}]}
{"op":"mcm","clk":"987196382","pt":1580495151119,"mc":[{"id":"1.168136214","rc":[{"batb":[[1,2.38,5.7],[2,1.89,3]],"ltp":2.44,"tv":23.29,"id":11981493}]}]}
{"op":"mcm","clk":"987204885","pt":1580495252967,"mc":[{"id":"1.168136214","rc":[{"batb":[[1,4.9,2.68],[2,4.8,1.04]],"ltp":0.0,"tv":0.0,"id":12925630},{"batb":[[0,1.62,1.98],[1,1.61,2.91]],"ltp":2.24,"tv":18.53,"id":17336468},{"batb":[[0,2.4,2.13],[1,2.38,5.56]],"ltp":2.44,"tv":23.29,"id":11981493}]}]}
{"op":"mcm","clk":"987217658","pt":1580495397630,"mc":[{"id":"1.168136214","rc":[{"batb":[[0,1.63,1.68],[1,1.62,1.98],[2,1.61,1.23]],"ltp":2.24,"tv":18.53,"id":17336468}]}]}
{"op":"mcm","clk":"987218937","pt":1580495408777,"mc":[{"id":"1.168136214","rc":[{"batb":[[0,2.46,1.99],[1,2.4,2.13],[2,2.38,5.56]],"ltp":2.44,"tv":23.29,"id":11981493}]}]}
{"op":"mcm","clk":"987220127","pt":1580495420778,"mc":[{"id":"1.168136214","rc":[{"batb":[[1,2.4,5.13]],"ltp":2.44,"tv":23.29,"id":11981493}]}]}
{"op":"mcm","clk":"987230347","pt":1580495538629,"mc":[{"id":"1.168136214","rc":[{"batb":[[0,2.48,1.98],[1,2.46,1.99],[2,2.4,3.14]],"ltp":2.44,"tv":23.29,"id":11981493}]}]}
{"op":"mcm","clk":"987251162","pt":1580495667590,"mc":[{"id":"1.168136214","rc":[{"batb":[[1,2.4,3.14],[2,2.38,5.56]],"ltp":2.44,"tv":23.29,"id":11981493}]}]}
{"op":"mcm","clk":"987253591","pt":1580495697330,"mc":[{"id":"1.168136214","rc":[{"batb":[[1,2.38,5.7],[2,1.88,90]],"ltp":2.44,"tv":23.29,"id":11981493}]}]}
{"op":"mcm","clk":"987255983","pt":1580495725747,"mc":[{"id":"1.168136214","rc":[{"batb":[[0,2.4,2.13],[1,2.38,5.56]],"ltp":2.44,"tv":23.29,"id":11981493}]}]}
{"op":"mcm","clk":"987262577","pt":1580495809049,"mc":[{"id":"1.168136214","rc":[{"batb":[[0,2.46,1.99],[1,2.4,2.13],[2,2.38,5.56]],"ltp":2.44,"tv":23.29,"id":11981493}]}]}
{"op":"mcm","clk":"987262814","pt":1580495812157,"mc":[{"id":"1.168136214","rc":[{"batb":[[1,2.4,5.13]],"ltp":2.44,"tv":23.29,"id":11981493}]}]}
{"op":"mcm","clk":"987270370","pt":1580495920136,"mc":[{"id":"1.168136214","rc":[{"batb":[[1,2.4,3.14]],"ltp":2.44,"tv":23.29,"id":11981493}]}]}
{"op":"mcm","clk":"987270378","pt":1580495920236,"mc":[{"id":"1.168136214","rc":[{"batb":[[0,2.48,1.98],[1,2.46,1.99],[2,2.4,3.14]],"ltp":2.44,"tv":23.29,"id":11981493}]}]}
{"op":"mcm","clk":"987273366","pt":1580495962810,"mc":[{"id":"1.168136214","rc":[{"batb":[[1,2.4,3.14],[2,2.38,5.56]],"ltp":2.44,"tv":23.29,"id":11981493}]}]}
{"op":"mcm","clk":"987274837","pt":1580495985451,"mc":[{"id":"1.168136214","rc":[{"batb":[[1,2.38,5.7],[2,1.89,3]],"ltp":2.44,"tv":23.29,"id":11981493}]}]}
{"op":"mcm","clk":"987291135","pt":1580496206879,"mc":[{"id":"1.168136214","rc":[{"batb":[[0,2.4,2.13],[1,2.38,5.56]],"ltp":2.44,"tv":23.29,"id":11981493}]}]}
{"op":"mcm","clk":"987300248","pt":1580496315606,"mc":[{"id":"1.168136214","rc":[{"batb":[[0,2.46,1.99],[1,2.4,2.13],[2,2.38,5.56]],"ltp":2.44,"tv":23.29,"id":11981493}]}]}
{"op":"mcm","clk":"987302495","pt":1580496343546,"mc":[{"id":"1.168136214","rc":[{"batb":[[1,2.4,5.13]],"ltp":2.44,"tv":23.29,"id":11981493}]}]}
{"op":"mcm","clk":"987306593","pt":1580496394056,"mc":[{"id":"1.168136214","rc":[{"batb":[[0,2.48,1.98],[1,2.46,1.99],[2,2.4,3.14]],"ltp":2.44,"tv":23.29,"id":11981493}]}]}
{"op":"mcm","clk":"987307227","pt":1580496402438,"mc":[{"id":"1.168136214","rc":[{"batb":[[0,2.5,20],[1,2.48,1.98],[2,2.46,1.99]],"ltp":2.44,"tv":23.29,"id":11981493}]}]}
{"op":"mcm","clk":"987311423","pt":1580496451711,"mc":[{"id":"1.168136214","rc":[{"batb":[[2,2.38,5.7]],"ltp":2.44,"tv":23.29,"id":11981493}]}]}
{"op":"mcm","clk":"987322681","pt":1580496470735,"mc":[{"id":"1.168136214","rc":[{"batb":[[0,2.5,24]],"ltp":2.44,"tv":23.29,"id":11981493}]}]}
{"op":"mcm","clk":"987330892","pt":1580496584813,"mc":[{"id":"1.168136214","rc":[{"batb":[[1,5.3,3.77],[2,4.9,2.68]],"ltp":0.0,"tv":0.0,"id":12925630},{"batb":[[0,1.64,1.98],[1,1.63,11.68]],"ltp":2.24,"tv":18.53,"id":17336468},{"batb":[[0,2.52,9.92],[1,2.5,24]],"ltp":2.44,"tv":23.29,"id":11981493}]}]}
{"op":"mcm","clk":"987332095","pt":1580496602559,"mc":[{"id":"1.168136214","rc":[{"batb":[[0,1.65,1.68],[1,1.64,1.98],[2,1.63,10]],"ltp":2.24,"tv":18.53,"id":17336468}]}]}
{"op":"mcm","clk":"987332940","pt":1580496614081,"mc":[{"id":"1.168136214","rc":[{"batb":[[0,1.65,25.57]],"ltp":2.24,"tv":18.53,"id":17336468}]}]}
{"op":"mcm","clk":"987334462","pt":1580496637737,"mc":[{"id":"1.168136214","rc":[{"batb":[[0,2.54,20],[1,2.52,9.92],[2,2.5,24]],"ltp":2.44,"tv":23.29,"id":11981493}]}]}
{"op":"mcm","clk":"987334907","pt":1580496645413,"mc":[{"id":"1.168136214","rc":[{"batb":[[2,1.61,1.23]],"ltp":2.24,"tv":18.53,"id":17336468},{"batb":[[1,2.52,1.98]],"ltp":2.44,"tv":23.29,"id":11981493}]}]}
{"op":"mcm","clk":"987342001","pt":1580496736800,"mc":[{"id":"1.168136214","rc":[{"batb":[[0,2.6,20],[1,2.54,20],[2,2.52,1.98]],"ltp":2.44,"tv":23.29,"id":11981493}]}]}
{"op":"mcm","clk":"987343072","pt":1580496749610,"mc":[{"id":"1.168136214","rc":[{"batb":[[0,2.66,3],[1,2.6,20],[2,2.54,20]],"ltp":2.44,"tv":23.29,"id":11981493}]}]}
{"op":"mcm","clk":"987344374","pt":1580496767046,"mc":[{"id":"1.168136214","rc":[{"batb":[[0,1.66,10],[1,1.65,25.57],[2,1.64,1.98]],"ltp":2.24,"tv":18.53,"id":17336468},{"batb":[[1,2.62,7.63],[2,2.6,20]],"ltp":2.44,"tv":23.29,"id":11981493}]}]}
{"op":"mcm","clk":"987345592","pt":1580496780352,"mc":[{"id":"1.168136214","rc":[{"batb":[[1,1.65,1.68]],"ltp":2.24,"tv":18.53,"id":17336468}]}]}
{"op":"mcm","clk":"987346215","pt":1580496789062,"mc":[{"id":"1.168136214","rc":[{"batb":[[0,2.68,3.36],[1,2.66,3],[2,2.62,7.63]],"ltp":2.44,"tv":23.29,"id":11981493}]}]}
{"op":"mcm","clk":"987347093","pt":1580496802129,"mc":[{"id":"1.168136214","rc":[{"batb":[[0,1.67,1.68],[1,1.66,10]],"ltp":2.24,"tv":18.53,"id":17336468}]}]}
{"op":"mcm","clk":"987348891","pt":1580496827532,"mc":[{"id":"1.168136214","rc":[{"batb":[[1,1.64,1.98],[2,1.61,1.23]],"ltp":2.24,"tv":18.53,"id":17336468},{"batb":[[2,2.6,20]],"ltp":2.44,"tv":23.29,"id":11981493}]}]}
{"op":"mcm","clk":"987349360","pt":1580496834145,"mc":[{"id":"1.168136214","rc":[{"batb":[[0,1.65,1.68]],"ltp":2.24,"tv":18.53,"id":17336468}]}]}
{"op":"mcm","clk":"987351208","pt":1580496860688,"mc":[{"id":"1.168136214","rc":[{"batb":[[0,2.68,23.36]],"ltp":2.44,"tv":23.29,"id":11981493}]}]}
{"op":"mcm","clk":"987351568","pt":1580496866118,"mc":[{"id":"1.168136214","rc":[{"batb":[[0,5.4,3.01],[2,4.8,1.74]],"ltp":0.0,"tv":0.0,"id":12925630},{"batb":[[0,1.66,1.98],[1,1.65,1.68]],"ltp":2.24,"tv":18.53,"id":17336468},{"batb":[[0,2.7,1.98],[1,2.68,23.36],[2,2.66,3]],"ltp":2.44,"tv":23.29,"id":11981493}]}]}
{"op":"mcm","clk":"987351703","pt":1580496868006,"mc":[{"id":"1.168136214","rc":[{"batb":[[0,1.67,1.68],[1,1.66,1.98]],"ltp":2.24,"tv":18.53,"id":17336468}]}]}
{"op":"mcm","clk":"987352583","pt":1580496881148,"mc":[{"id":"1.168136214","rc":[{"batl":[[2,16,10]],"ltp":0.0,"tv":0.0,"id":12925630}]}]}
{"op":"mcm","clk":"987352652","pt":1580496881934,"mc":[{"id":"1.168136214","rc":[{"batb":[[0,5.4,3.92],[2,4.4,2.38]],"batl":[[0,11.5,2.31]],"ltp":0.0,"tv":0.0,"id":12925630}]}]}
{"op":"mcm","clk":"987353086","pt":1580496888837,"mc":[{"id":"1.168136214","rc":[{"batb":[[0,5.5,4.55],[1,5.4,1.98]],"ltp":0.0,"tv":0.0,"id":12925630}]}]}
{"op":"mcm","clk":"987353312","pt":1580496891945,"mc":[{"id":"1.168136214","rc":[{"batb":[[0,5.5,5.56]],"ltp":0.0,"tv":0.0,"id":12925630}]}]}
{"op":"mcm","clk":"987353827","pt":1580496898649,"mc":[{"id":"1.168136214","rc":[{"batb":[[2,4.5,3.7]],"ltp":0.0,"tv":0.0,"id":12925630}]}]}
{"op":"mcm","clk":"987353904","pt":1580496899858,"mc":[{"id":"1.168136214","rc":[{"batl":[[0,11,9.2],[1,11.5,2.11]],"ltp":0.0,"tv":0.0,"id":12925630}]}]}
{"op":"mcm","clk":"987353998","pt":1580496900976,"mc":[{"id":"1.168136214","rc":[{"batl":[[0,10.5,1.68],[1,11,9.2],[2,16,10.43]],"ltp":0.0,"tv":0.0,"id":12925630}]}]}
{"op":"mcm","clk":"987357573","pt":1580496949120,"mc":[{"id":"1.168136214","rc":[{"batb":[[0,1.67,11.68]],"ltp":2.24,"tv":18.53,"id":17336468},{"batb":[[0,2.7,9.39]],"ltp":2.44,"tv":23.29,"id":11981493}]}]}
{"op":"mcm","clk":"987359524","pt":1580496975783,"mc":[{"id":"1.168136214","rc":[{"batb":[[0,1.91,100],[1,1.67,11.68],[2,1.66,1.98]],"ltp":2.24,"tv":18.53,"id":17336468}]}]}
{"op":"mcm","clk":"987360878","pt":1580496997119,"mc":[{"id":"1.168136214","rc":[{"batb":[[0,1.92,1.68],[1,1.91,100],[2,1.67,10]],"ltp":2.24,"tv":18.53,"id":17336468}]}]}
{"op":"mcm","clk":"987361535","pt":1580497007177,"mc":[{"id":"1.168136214","rc":[{"batb":[[0,2.7,19.39]],"ltp":2.44,"tv":23.29,"id":11981493}]}]}
{"op":"mcm","clk":"987363079","pt":1580497029892,"mc":[{"id":"1.168136214","rc":[{"batb":[[0,1.92,18.33]],"batl":[[1,2.96,10.33]],"ltp":2.24,"tv":18.53,"id":17336468}]}]}
{"op":"mcm","clk":"987363281","pt":1580497033124,"mc":[{"id":"1.168136214","rc":[{"batb":[[0,1.93,20.42],[1,1.92,18.33],[2,1.91,100]],"ltp":2.24,"tv":18.53,"id":17336468}]}]}
{"op":"mcm","clk":"987364856","pt":1580497057083,"mc":[{"id":"1.168136214","rc":[{"batb":[[1,4.5,3.7],[2,4.4,1.68]],"ltp":0.0,"tv":0.0,"id":12925630}]}]}
{"op":"mcm","clk":"987364865","pt":1580497057187,"mc":[{"id":"1.168136214","rc":[{"batb":[[0,5.6,1.98],[1,5.5,5.56],[2,4.5,3.7]],"ltp":0.0,"tv":0.0,"id":12925630},{"batb":[[0,1.94,1.98],[1,1.93,20.42],[2,1.92,18.33]],"ltp":2.24,"tv":18.53,"id":17336468}]}]}
{"op":"mcm","clk":"987365250","pt":1580497063108,"mc":[{"id":"1.168136214","rc":[{"batb":[[0,1.95,5.6],[1,1.94,1.98],[2,1.93,20.42]],"batl":[[0,2.92,6.83],[1,2.94,13.41]],"ltp":2.24,"tv":18.53,"id":17336468}]}]}
{"op":"mcm","clk":"987365604","pt":1580497067988,"mc":[{"id":"1.168136214","rc":[{"batb":[[1,5.5,4.55]],"ltp":0.0,"tv":0.0,"id":12925630}]}]}
{"op":"mcm","clk":"987365669","pt":1580497068988,"mc":[{"id":"1.168136214","rc":[{"batb":[[2,1.92,6]],"batl":[[1,2.98,9],[2,3.95,9]],"ltp":2.24,"tv":18.53,"id":17336468}]}]}
{"op":"mcm","clk":"987365823","pt":1580497071509,"mc":[{"id":"1.168136214","rc":[{"batb":[[0,5.6,2.95]],"ltp":0.0,"tv":0.0,"id":12925630}]}]}
{"op":"mcm","clk":"987366915","pt":1580497086413,"mc":[{"id":"1.168136214","rc":[{"batb":[[2,4.4,2.38]],"ltp":0.0,"tv":0.0,"id":12925630}]}]}
{"op":"mcm","clk":"987367441","pt":1580497093960,"mc":[{"id":"1.168136214","rc":[{"batb":[[1,5.2,1.61],[2,4.4,1.68]],"ltp":0.0,"tv":0.0,"id":12925630}]}]}
{"op":"mcm","clk":"987367656","pt":1580497097050,"mc":[{"id":"1.168136214","rc":[{"batb":[[0,2.8,5],[1,2.7,19.39],[2,2.68,23.36]],"ltp":2.44,"tv":23.29,"id":11981493}]}]}
{"op":"mcm","clk":"987373069","pt":1580497162996,"mc":[{"id":"1.168136214","rc":[{"batb":[[0,1.95,15.6]],"ltp":2.24,"tv":18.53,"id":17336468}]}]}
{"op":"mcm","clk":"987378881","pt":1580497216699,"mc":[{"id":"1.168136214","rc":[{"batb":[[1,2.74,40],[2,2.7,19.39]],"ltp":2.44,"tv":23.29,"id":11981493}]}]}
{"op":"mcm","clk":"987380781","pt":1580497231041,"mc":[{"id":"1.168136214","rc":[{"batb":[[2,2.7,11.98]],"ltp":2.44,"tv":23.29,"id":11981493}]}]}
{"op":"mcm","clk":"987382559","pt":1580497243826,"mc":[{"id":"1.168136214","rc":[{"batb":[[0,5.5,1.88],[1,5.3,1.98],[2,4.4,2.38]],"ltp":0.0,"tv":0.0,"id":12925630},{"batb":[[0,1.96,1.98],[1,1.95,15.6]],"ltp":2.24,"tv":18.53,"id":17336468},{"batb":[[0,2.82,1.98],[1,2.8,5],[2,2.74,40]],"ltp":2.44,"tv":23.29,"id":11981493}]}]}
{"op":"mcm","clk":"987385701","pt":1580497266425,"mc":[{"id":"1.168136214","rc":[{"batb":[[0,1.96,2.99]],"ltp":2.24,"tv":18.53,"id":17336468}]}]}
{"op":"mcm","clk":"987386183","pt":1580497269617,"mc":[{"id":"1.168136214","rc":[{"batb":[[0,1.97,20.01],[1,1.96,2.99],[2,1.95,15.6]],"ltp":2.24,"tv":18.53,"id":17336468}]}]}
{"op":"mcm","clk":"987389047","pt":1580497290302,"mc":[{"id":"1.168136214","rc":[{"batb":[[2,1.95,5.6]],"ltp":2.24,"tv":18.53,"id":17336468}]}]}
{"op":"mcm","clk":"987411596","pt":1580497379125,"mc":[{"id":"1.168136214","rc":[{"batb":[[0,1.98,5.52],[1,1.97,20.01],[2,1.96,2.99]],"ltp":2.24,"tv":18.53,"id":17336468}]}]}
{"op":"mcm","clk":"987413831","pt":1580497395017,"mc":[{"id":"1.168136214","rc":[{"batb":[[1,1.96,2.99],[2,1.92,6]],"ltp":2.24,"tv":18.53,"id":17336468}]}]}
{"op":"mcm","clk":"987428380","pt":1580497483955,"mc":[{"id":"1.168136214","rc":[{"batl":[[0,10.5,1.88],[1,11,9]],"ltp":0.0,"tv":0.0,"id":12925630}]}]}
{"op":"mcm","clk":"987440220","pt":1580497556130,"mc":[{"id":"1.168136214","rc":[{"batb":[[0,1.97,5.52]],"ltp":2.24,"tv":18.53,"id":17336468}]}]}
{"op":"mcm","clk":"987440727","pt":1580497559132,"mc":[{"id":"1.168136214","rc":[{"batb":[[0,1.98,19.9],[1,1.97,5.52],[2,1.96,2.99]],"ltp":2.24,"tv":18.53,"id":17336468}]}]}
{"op":"mcm","clk":"987451878","pt":1580497628135,"mc":[{"id":"1.168136214","rc":[{"batb":[[0,1.99,5.46],[1,1.98,19.9]],"ltp":2.24,"tv":18.53,"id":17336468}]}]}
{"op":"mcm","clk":"987452291","pt":1580497630727,"mc":[{"id":"1.168136214","rc":[{"batb":[[1,1.96,2.99],[2,1.92,6]],"ltp":2.24,"tv":18.53,"id":17336468}]}]}
{"op":"mcm","clk":"987459350","pt":1580497677133,"mc":[{"id":"1.168136214","rc":[{"batb":[[0,1.97,5.46]],"ltp":2.24,"tv":18.53,"id":17336468}]}]}
{"op":"mcm","clk":"987460633","pt":1580497685244,"mc":[{"id":"1.168136214","rc":[{"batb":[[0,1.98,19.9],[1,1.97,5.46],[2,1.96,2.99]],"ltp":2.24,"tv":18.53,"id":17336468}]}]}
{"op":"mcm","clk":"987467377","pt":1580497728990,"mc":[{"id":"1.168136214","rc":[{"batb":[[0,1.99,5.4],[1,1.98,19.9]],"ltp":2.24,"tv":18.53,"id":17336468}]}]}
{"op":"mcm","clk":"987469035","pt":1580497739609,"mc":[{"id":"1.168136214","rc":[{"batb":[[1,1.96,2.99],[2,1.92,6]],"ltp":2.24,"tv":18.53,"id":17336468}]}]}
{"op":"mcm","clk":"987472221","pt":1580497761067,"mc":[{"id":"1.168136214","rc":[{"batb":[[0,1.97,5.4]],"ltp":2.24,"tv":18.53,"id":17336468}]}]}
{"op":"mcm","clk":"987474615","pt":1580497777563,"mc":[{"id":"1.168136214","rc":[{"batb":[[0,1.98,19.9],[1,1.97,5.4],[2,1.96,2.99]],"ltp":2.24,"tv":18.53,"id":17336468}]}]}
{"op":"mcm","clk":"987477102","pt":1580497794048,"mc":[{"id":"1.168136214","rc":[{"batb":[[0,1.99,5.35],[1,1.98,19.9]],"ltp":2.24,"tv":18.53,"id":17336468}]}]}
{"op":"mcm","clk":"987477425","pt":1580497796075,"mc":[{"id":"1.168136214","rc":[{"batb":[[1,1.96,2.99],[2,1.92,6]],"ltp":2.24,"tv":18.53,"id":17336468}]}]}
{"op":"mcm","clk":"987477485","pt":1580497796452,"mc":[{"id":"1.168136214","rc":[{"batb":[[0,2,19.7],[1,1.99,5.35],[2,1.96,2.99]],"ltp":2.24,"tv":18.53,"id":17336468}]}]}
{"op":"mcm","clk":"987532920","pt":1580498173690,"mc":[{"id":"1.168136214","rc":[{"batb":[[2,2.78,20]],"ltp":2.44,"tv":23.29,"id":11981493}]}]}
{"op":"mcm","clk":"987576830","pt":1580498390241,"mc":[{"id":"1.168136214","rc":[{"batb":[[0,5.6,4.54],[1,5.3,2.89]],"ltp":0.0,"tv":0.0,"id":12925630},{"batb":[[0,2.82,9.07]],"ltp":2.44,"tv":23.29,"id":11981493}]}]}
{"op":"mcm","clk":"987585974","pt":1580498450622,"mc":[{"id":"1.168136214","rc":[{"batb":[[0,2.02,9.9],[1,2,19.7],[2,1.99,5.35]],"ltp":2.24,"tv":18.53,"id":17336468}]}]}
{"op":"mcm","clk":"987588444","pt":1580498467146,"mc":[{"id":"1.168136214","rc":[{"batb":[[1,1.99,5.35],[2,1.96,2.99]],"ltp":2.24,"tv":18.53,"id":17336468}]}]}
{"op":"mcm","clk":"987590017","pt":1580498477677,"mc":[{"id":"1.168136214","rc":[{"batb":[[2,1.96,1.98]],"ltp":2.24,"tv":18.53,"id":17336468}]}]}
{"op":"mcm","clk":"987591936","pt":1580498490891,"mc":[{"id":"1.168136214","rc":[{"batb":[[0,2.02,10.87]],"ltp":2.24,"tv":18.53,"id":17336468}]}]}
{"op":"mcm","clk":"987594124","pt":1580498506128,"mc":[{"id":"1.168136214","rc":[{"batb":[[0,1.99,6.32],[1,1.96,1.98],[2,1.92,6]],"ltp":2.24,"tv":18.53,"id":17336468}]}]}
{"op":"mcm","clk":"987594141","pt":1580498506236,"mc":[{"id":"1.168136214","rc":[{"batb":[[0,2,10.97],[1,1.99,5.35],[2,1.96,1.98]],"ltp":2.24,"tv":18.53,"id":17336468}]}]}
{"op":"mcm","clk":"987594741","pt":1580498510126,"mc":[{"id":"1.168136214","rc":[{"batl":[[0,10.5,2.36],[2,16,10]],"ltp":0.0,"tv":0.0,"id":12925630},{"batb":[[0,3.1,20],[1,2.82,9.07],[2,2.8,5]],"ltp":2.44,"tv":23.29,"id":11981493}]}]}
{"op":"mcm","clk":"987596292","pt":1580498520671,"mc":[{"id":"1.168136214","rc":[{"batb":[[0,2.02,20.47],[1,2,10],[2,1.99,5.35]],"ltp":2.24,"tv":18.53,"id":17336468}]}]}
{"op":"mcm","clk":"987602565","pt":1580498562126,"mc":[{"id":"1.168136214","rc":[{"trd":[[5.7,1.94]],"batb":[[0,5.3,2.89],[1,4.4,2.38],[2,3.1,98]],"batl":[[0,10.5,2.37]],"ltp":5.7,"tv":1.93,"id":12925630},{"trd":[[2.02,23.31],[2.04,1.94]],"batb":[[0,2.02,7.86],[1,1.99,5.35],[2,1.96,1.98]],"ltp":2.02,"tv":43.77,"id":17336468},{"trd":[[3.1,16.46]],"batb":[[0,3.1,11.77],[1,2.82,1.98]],"ltp":3.1,"tv":39.75,"id":11981493}],"tv":85.47}]}
{"op":"mcm","clk":"987603066","pt":1580498565248,"mc":[{"id":"1.168136214","rc":[{"batb":[[1,5,3.7],[2,4.4,1.68]],"ltp":5.7,"tv":1.93,"id":12925630}]}]}
{"op":"mcm","clk":"987604529","pt":1580498574528,"mc":[{"id":"1.168136214","rc":[{"batl":[[0,10,4.15],[1,10.5,2.16],[2,11,9]],"ltp":5.7,"tv":1.93,"id":12925630},{"batl":[[0,2.9,8.84],[1,2.92,6.11],[2,2.98,9]],"ltp":2.02,"tv":43.77,"id":17336468}]}]}
{"op":"mcm","clk":"987604950","pt":1580498577105,"mc":[{"id":"1.168136214","rc":[{"batl":[[0,2.88,2.81],[1,2.9,8.12]],"ltp":2.02,"tv":43.77,"id":17336468}]}]}
{"op":"mcm","clk":"987605065","pt":1580498577853,"mc":[{"id":"1.168136214","rc":[{"batl":[[0,9.8,1.69],[1,10,4.14],[2,11,9.48]],"ltp":5.7,"tv":1.93,"id":12925630}]}]}
{"op":"mcm","clk":"987607161","pt":1580498591663,"mc":[{"id":"1.168136214","rc":[{"batl":[[1,10,3.94]],"ltp":5.7,"tv":1.93,"id":12925630}]}]}
{"op":"mcm","clk":"987607336","pt":1580498592944,"mc":[{"id":"1.168136214","rc":[{"batl":[[2,11,9]],"ltp":5.7,"tv":1.93,"id":12925630},{"batl":[[0,2.86,14.5],[1,2.88,2.09]],"ltp":2.02,"tv":43.77,"id":17336468}]}]}
{"op":"mcm","clk":"987607429","pt":1580498593554,"mc":[{"id":"1.168136214","rc":[{"batl":[[0,9.8,2.2]],"ltp":5.7,"tv":1.93,"id":12925630}]}]}
{"op":"mcm","clk":"987608215","pt":1580498599068,"mc":[{"id":"1.168136214","rc":[{"batl":[[0,9.8,2.4]],"ltp":5.7,"tv":1.93,"id":12925630}]}]}
{"op":"mcm","clk":"987608674","pt":1580498602053,"mc":[{"id":"1.168136214","rc":[{"batb":[[0,5.2,1.61],[1,5,3]],"ltp":5.7,"tv":1.93,"id":12925630}]}]}
{"op":"mcm","clk":"987608692","pt":1580498602159,"mc":[{"id":"1.168136214","rc":[{"batb":[[1,5.1,1.98],[2,5,3]],"ltp":5.7,"tv":1.93,"id":12925630}]}]}
{"op":"mcm","clk":"987609078","pt":1580498604955,"mc":[{"id":"1.168136214","rc":[{"batl":[[0,9.8,2.2]],"ltp":5.7,"tv":1.93,"id":12925630}]}]}
{"op":"mcm","clk":"987609840","pt":1580498610096,"mc":[{"id":"1.168136214","rc":[{"batl":[[1,2.98,9],[2,3.95,9]],"ltp":2.02,"tv":43.77,"id":17336468}]}]}
{"op":"mcm","clk":"987609902","pt":1580498610506,"mc":[{"id":"1.168136214","rc":[{"batl":[[0,2.84,2.84],[1,2.86,13.78],[2,2.98,9]],"ltp":2.02,"tv":43.77,"id":17336468}]}]}
{"op":"mcm","clk":"987610146","pt":1580498611991,"mc":[{"id":"1.168136214","rc":[{"batl":[[0,2.82,9.06],[1,2.84,2.12]],"ltp":2.02,"tv":43.77,"id":17336468}]}]}
{"op":"mcm","clk":"987610193","pt":1580498612276,"mc":[{"id":"1.168136214","rc":[{"batl":[[0,9.8,2.38]],"ltp":5.7,"tv":1.93,"id":12925630}]}]}
{"op":"mcm","clk":"987610993","pt":1580498617509,"mc":[{"id":"1.168136214","rc":[{"batl":[[0,2.8,2.72],[1,2.82,8.34],[2,2.84,2.12]],"ltp":2.02,"tv":43.77,"id":17336468}]}]}
{"op":"mcm","clk":"987611092","pt":1580498618244,"mc":[{"id":"1.168136214","rc":[{"batl":[[0,9.8,2.2]],"ltp":5.7,"tv":1.93,"id":12925630}]}]}
{"op":"mcm","clk":"987612251","pt":1580498626134,"mc":[{"id":"1.168136214","rc":[{"batl":[[0,9.8,2.4]],"ltp":5.7,"tv":1.93,"id":12925630}]}]}
{"op":"mcm","clk":"987612800","pt":1580498629957,"mc":[{"id":"1.168136214","rc":[{"batl":[[1,11,9],[2,16,10]],"ltp":5.7,"tv":1.93,"id":12925630},{"batl":[[0,2.78,9.18],[1,2.8,2]],"ltp":2.02,"tv":43.77,"id":17336468}]}]}
{"op":"mcm","clk":"987613179","pt":1580498632645,"mc":[{"id":"1.168136214","rc":[{"batl":[[0,9.8,2.2]],"ltp":5.7,"tv":1.93,"id":12925630}]}]}
{"op":"mcm","clk":"987614133","pt":1580498639748,"mc":[{"id":"1.168136214","rc":[{"batl":[[0,9.8,2.39]],"ltp":5.7,"tv":1.93,"id":12925630}]}]}
{"op":"mcm","clk":"987614740","pt":1580498644145,"mc":[{"id":"1.168136214","rc":[{"batl":[[0,2.76,2.9],[1,2.78,8.46],[2,2.8,2]],"ltp":2.02,"tv":43.77,"id":17336468}]}]}
{"op":"mcm","clk":"987614975","pt":1580498645959,"mc":[{"id":"1.168136214","rc":[{"batl":[[0,9.8,2.2]],"ltp":5.7,"tv":1.93,"id":12925630}]}]}
{"op":"mcm","clk":"987615321","pt":1580498648786,"mc":[{"id":"1.168136214","rc":[{"batl":[[0,2.74,9.31],[1,2.76,2.18]],"ltp":2.02,"tv":43.77,"id":17336468}]}]}
{"op":"mcm","clk":"987615872","pt":1580498652884,"mc":[{"id":"1.168136214","rc":[{"batl":[[0,9.8,2.4]],"ltp":5.7,"tv":1.93,"id":12925630},{"batl":[[0,2.72,20.42],[1,2.74,8.59],[2,2.76,2.18]],"ltp":2.02,"tv":43.77,"id":17336468}]}]}
{"op":"mcm","clk":"987616745","pt":1580498659260,"mc":[{"id":"1.168136214","rc":[{"batl":[[0,9.8,2.2]],"ltp":5.7,"tv":1.93,"id":12925630}]}]}
{"op":"mcm","clk":"987617830","pt":1580498666885,"mc":[{"id":"1.168136214","rc":[{"batl":[[0,9.8,2.38]],"ltp":5.7,"tv":1.93,"id":12925630},{"batl":[[1,2.76,2.18],[2,2.8,2]],"ltp":2.02,"tv":43.77,"id":17336468}]}]}
{"op":"mcm","clk":"987617866","pt":1580498667200,"mc":[{"id":"1.168136214","rc":[{"batl":[[0,2.7,9.43],[1,2.72,19.7],[2,2.76,2.18]],"ltp":2.02,"tv":43.77,"id":17336468}]}]}
{"op":"mcm","clk":"987618200","pt":1580498669113,"mc":[{"id":"1.168136214","rc":[{"batl":[[0,3.95,14.4],[1,980,9.2]],"ltp":3.1,"tv":39.75,"id":11981493}]}]}
{"op":"mcm","clk":"987618724","pt":1580498672822,"mc":[{"id":"1.168136214","rc":[{"batl":[[0,2.68,2.72],[1,2.7,8.71],[2,2.72,19.7]],"ltp":2.02,"tv":43.77,"id":17336468}]}]}
{"op":"mcm","clk":"987618843","pt":1580498673692,"mc":[{"id":"1.168136214","rc":[{"batl":[[0,9.8,2.2]],"ltp":5.7,"tv":1.93,"id":12925630},{"batl":[[0,3.95,14.6],[1,980,9]],"ltp":3.1,"tv":39.75,"id":11981493}]}]}
{"op":"mcm","clk":"987619023","pt":1580498674822,"mc":[{"id":"1.168136214","rc":[{"batl":[[0,4.4,14.6]],"ltp":3.1,"tv":39.75,"id":11981493}]}]}
{"op":"mcm","clk":"987619473","pt":1580498678015,"mc":[{"id":"1.168136214","rc":[{"batl":[[1,5.5,14.4],[2,5.8,9]],"ltp":3.1,"tv":39.75,"id":11981493}]}]}
{"op":"mcm","clk":"987619775","pt":1580498680097,"mc":[{"id":"1.168136214","rc":[{"batl":[[0,2.66,2.99],[1,2.68,2],[2,2.7,8.71]],"ltp":2.02,"tv":43.77,"id":17336468}]}]}
{"op":"mcm","clk":"987619853","pt":1580498680629,"mc":[{"id":"1.168136214","rc":[{"batl":[[0,9.8,2.38]],"ltp":5.7,"tv":1.93,"id":12925630}]}]}
{"op":"mcm","clk":"987620307","pt":1580498684017,"mc":[{"id":"1.168136214","rc":[{"batb":[[2,2.8,19.4]],"ltp":3.1,"tv":39.75,"id":11981493}]}]}
{"op":"mcm","clk":"987620507","pt":1580498685637,"mc":[{"id":"1.168136214","rc":[{"batl":[[0,2.64,9.63],[1,2.66,2.27],[2,2.68,2]],"ltp":2.02,"tv":43.77,"id":17336468}]}]}
{"op":"mcm","clk":"987620864","pt":1580498688207,"mc":[{"id":"1.168136214","rc":[{"batl":[[0,9.8,2.2]],"ltp":5.7,"tv":1.93,"id":12925630}]}]}
{"op":"mcm","clk":"987621818","pt":1580498695147,"mc":[{"id":"1.168136214","rc":[{"batl":[[0,9.8,2.4]],"ltp":5.7,"tv":1.93,"id":12925630}]}]}
{"op":"mcm","clk":"987622673","pt":1580498701486,"mc":[{"id":"1.168136214","rc":[{"batl":[[0,9.8,2.2]],"ltp":5.7,"tv":1.93,"id":12925630}]}]}
{"op":"mcm","clk":"987623801","pt":1580498708588,"mc":[{"id":"1.168136214","rc":[{"batl":[[0,9.8,2.4]],"ltp":5.7,"tv":1.93,"id":12925630}]}]}
{"op":"mcm","clk":"987624521","pt":1580498713085,"mc":[{"id":"1.168136214","rc":[{"batl":[[0,2.62,3.02],[1,2.64,8.91]],"ltp":2.02,"tv":43.77,"id":17336468}]}]}
{"op":"mcm","clk":"987624911","pt":1580498715705,"mc":[{"id":"1.168136214","rc":[{"batl":[[0,9.8,2.2]],"ltp":5.7,"tv":1.93,"id":12925630}]}]}
{"op":"mcm","clk":"987625804","pt":1580498722035,"mc":[{"id":"1.168136214","rc":[{"batl":[[0,2.6,9.77],[1,2.62,2.3]],"ltp":2.02,"tv":43.77,"id":17336468}]}]}
{"op":"mcm","clk":"987626621","pt":1580498727630,"mc":[{"id":"1.168136214","rc":[{"batl":[[2,2.72,19.7]],"ltp":2.02,"tv":43.77,"id":17336468}]}]}
{"op":"mcm","clk":"987629219","pt":1580498745067,"mc":[{"id":"1.168136214","rc":[{"batl":[[1,2.72,19.7],[2,2.96,19.7]],"ltp":2.02,"tv":43.77,"id":17336468}]}]}
{"op":"mcm","clk":"987629286","pt":1580498745658,"mc":[{"id":"1.168136214","rc":[{"batl":[[0,2.58,3.05],[1,2.6,9.05],[2,2.72,19.7]],"ltp":2.02,"tv":43.77,"id":17336468}]}]}
{"op":"mcm","clk":"987630947","pt":1580498758033,"mc":[{"id":"1.168136214","rc":[{"batl":[[0,2.56,9.91],[1,2.58,2.33]],"ltp":2.02,"tv":43.77,"id":17336468}]}]}
{"op":"mcm","clk":"987633544","pt":1580498776903,"mc":[{"id":"1.168136214","rc":[{"batl":[[0,2.54,3.1],[1,2.56,9.19]],"ltp":2.02,"tv":43.77,"id":17336468}]}]}
{"op":"mcm","clk":"987635826","pt":1580498794727,"mc":[{"id":"1.168136214","rc":[{"batl":[[0,2.52,10.06],[1,2.54,2.38]],"ltp":2.02,"tv":43.77,"id":17336468}]}]}
{"op":"mcm","clk":"987636041","pt":1580498796313,"mc":[{"id":"1.168136214","rc":[{"batb":[[1,3,10],[2,2.82,1.98]],"ltp":3.1,"tv":39.75,"id":11981493}]}]}
{"op":"mcm","clk":"987637795","pt":1580498810057,"mc":[{"id":"1.168136214","rc":[{"batl":[[0,2.5,3.13],[1,2.52,9.34]],"ltp":2.02,"tv":43.77,"id":17336468}]}]}
{"op":"mcm","clk":"987638203","pt":1580498812775,"mc":[{"id":"1.168136214","rc":[{"batl":[[1,2.72,19.7],[2,2.96,19.7]],"ltp":2.02,"tv":43.77,"id":17336468}]}]}
{"op":"mcm","clk":"987638255","pt":1580498813160,"mc":[{"id":"1.168136214","rc":[{"batl":[[0,2.48,10.21],[1,2.5,2.41],[2,2.72,19.7]],"ltp":2.02,"tv":43.77,"id":17336468}]}]}
{"op":"mcm","clk":"987641901","pt":1580498842847,"mc":[{"id":"1.168136214","rc":[{"batl":[[0,2.46,3.17],[1,2.48,9.49]],"ltp":2.02,"tv":43.77,"id":17336468}]}]}
{"op":"mcm","clk":"987642665","pt":1580498849051,"mc":[{"id":"1.168136214","rc":[{"batl":[[1,2.72,19.7],[2,2.96,19.7]],"ltp":2.02,"tv":43.77,"id":17336468}]}]}
{"op":"mcm","clk":"987642716","pt":1580498849419,"mc":[{"id":"1.168136214","rc":[{"batl":[[0,2.44,10.36],[1,2.46,2.45],[2,2.72,19.7]],"ltp":2.02,"tv":43.77,"id":17336468}]}]}
{"op":"mcm","clk":"987645965","pt":1580498876097,"mc":[{"id":"1.168136214","rc":[{"batl":[[0,2.42,3.21],[1,2.44,9.64]],"ltp":2.02,"tv":43.77,"id":17336468}]}]}
{"op":"mcm","clk":"987647192","pt":1580498885677,"mc":[{"id":"1.168136214","rc":[{"batl":[[0,2.4,10.53],[1,2.42,2.49]],"ltp":2.02,"tv":43.77,"id":17336468}]}]}
{"op":"mcm","clk":"987649956","pt":1580498907932,"mc":[{"id":"1.168136214","rc":[{"batl":[[0,2.38,3.26],[1,2.4,9.81]],"ltp":2.02,"tv":43.77,"id":17336468}]}]}
{"op":"mcm","clk":"987651618","pt":1580498921849,"mc":[{"id":"1.168136214","rc":[{"batl":[[1,2.72,19.7],[2,2.96,19.7]],"ltp":2.02,"tv":43.77,"id":17336468}]}]}
{"op":"mcm","clk":"987651656","pt":1580498922178,"mc":[{"id":"1.168136214","rc":[{"batl":[[0,2.36,10.69],[1,2.38,2.54],[2,2.72,19.7]],"ltp":2.02,"tv":43.77,"id":17336468}]}]}
{"op":"mcm","clk":"987653874","pt":1580498939891,"mc":[{"id":"1.168136214","rc":[{"batl":[[0,2.34,3.3],[1,2.36,9.97]],"ltp":2.02,"tv":43.77,"id":17336468}]}]}
{"op":"mcm","clk":"987653974","pt":1580498940822,"mc":[{"id":"1.168136214","rc":[{"batl":[[0,2.32,10.86],[1,2.34,2.58]],"ltp":2.02,"tv":43.77,"id":17336468}]}]}
{"op":"mcm","clk":"987657716","pt":1580498971884,"mc":[{"id":"1.168136214","rc":[{"batl":[[0,2.3,3.34],[1,2.32,10.14]],"ltp":2.02,"tv":43.77,"id":17336468}]}]}
{"op":"mcm","clk":"987658315","pt":1580498976972,"mc":[{"id":"1.168136214","rc":[{"batl":[[0,2.28,11.04],[1,2.3,2.62]],"ltp":2.02,"tv":43.77,"id":17336468}]}]}
{"op":"mcm","clk":"987661513","pt":1580499003768,"mc":[{"id":"1.168136214","rc":[{"batl":[[0,2.26,3.39],[1,2.28,10.32]],"ltp":2.02,"tv":43.77,"id":17336468}]}]}
{"op":"mcm","clk":"987663240","pt":1580499014652,"mc":[{"id":"1.168136214","rc":[{"batl":[[0,2.24,11.22],[1,2.26,2.67]],"ltp":2.02,"tv":43.77,"id":17336468}]}]}
{"op":"mcm","clk":"987664093","pt":1580499020672,"mc":[{"id":"1.168136214","rc":[{"batb":[[1,3.05,12],[2,3,10]],"ltp":3.1,"tv":39.75,"id":11981493}]}]}
{"op":"mcm","clk":"987666092","pt":1580499036110,"mc":[{"id":"1.168136214","rc":[{"batl":[[0,2.22,2.71],[1,2.24,11.22]],"ltp":2.02,"tv":43.77,"id":17336468}]}]}
{"op":"mcm","clk":"987668242","pt":1580499050936,"mc":[{"id":"1.168136214","rc":[{"batl":[[0,2.2,10.69],[1,2.22,2.71],[2,2.72,20.42]],"ltp":2.02,"tv":43.77,"id":17336468}]}]}
{"op":"mcm","clk":"987671117","pt":1580499067830,"mc":[{"id":"1.168136214","rc":[{"batl":[[0,2.18,2.76],[1,2.2,10.69]],"ltp":2.02,"tv":43.77,"id":17336468}]}]}
{"op":"mcm","clk":"987671316","pt":1580499068958,"mc":[{"id":"1.168136214","rc":[{"batl":[[1,2.72,20.42],[2,2.96,19.7]],"ltp":2.02,"tv":43.77,"id":17336468}]}]}
{"op":"mcm","clk":"987671394","pt":1580499069358,"mc":[{"id":"1.168136214","rc":[{"batl":[[0,2.16,10.89],[1,2.18,2.76],[2,2.72,20.42]],"ltp":2.02,"tv":43.77,"id":17336468}]}]}
{"op":"mcm","clk":"987675852","pt":1580499099075,"mc":[{"id":"1.168136214","rc":[{"batl":[[1,2.72,20.42],[2,2.96,19.7]],"ltp":2.02,"tv":43.77,"id":17336468}]}]}
{"op":"mcm","clk":"987675940","pt":1580499099716,"mc":[{"id":"1.168136214","rc":[{"batl":[[0,2.14,2.81],[1,2.16,10.89],[2,2.72,20.42]],"ltp":2.02,"tv":43.77,"id":17336468}]}]}
{"op":"mcm","clk":"987676956","pt":1580499105812,"mc":[{"id":"1.168136214","rc":[{"batl":[[1,2.72,20.42],[2,2.96,19.7]],"ltp":2.02,"tv":43.77,"id":17336468}]}]}
{"op":"mcm","clk":"987677009","pt":1580499106188,"mc":[{"id":"1.168136214","rc":[{"batl":[[0,2.12,11.09],[1,2.14,2.81],[2,2.72,20.42]],"ltp":2.02,"tv":43.77,"id":17336468}]}]}
{"op":"mcm","clk":"987746866","pt":1580499487418,"mc":[{"id":"1.168136214","rc":[{"batl":[[0,2.08,100],[1,2.12,11.09],[2,2.14,2.81]],"ltp":2.02,"tv":43.77,"id":17336468}]}]}
{"op":"mcm","clk":"987749038","pt":1580499501976,"mc":[{"id":"1.168136214","rc":[{"batl":[[1,2.14,2.81],[2,2.72,20.42]],"ltp":2.02,"tv":43.77,"id":17336468}]}]}
{"op":"mcm","clk":"987749086","pt":1580499502255,"mc":[{"id":"1.168136214","rc":[{"batl":[[0,2.06,11.42],[1,2.08,100],[2,2.14,2.81]],"ltp":2.02,"tv":43.77,"id":17336468}]}]}
{"op":"mcm","clk":"987751314","pt":1580499518795,"mc":[{"id":"1.168136214","rc":[{"batb":[[1,1.99,2.32]],"batl":[[2,2.72,20.42]],"ltp":2.02,"tv":43.77,"id":17336468}]}]}
{"op":"mcm","clk":"987755474","pt":1580499547955,"mc":[{"id":"1.168136214","rc":[{"batl":[[0,2.04,1.68],[1,2.06,11.42],[2,2.08,100]],"ltp":2.02,"tv":43.77,"id":17336468}]}]}
{"op":"mcm","clk":"987755547","pt":1580499548372,"mc":[{"id":"1.168136214","rc":[{"batl":[[0,2.06,11.42],[1,2.08,100],[2,2.72,20.42]],"ltp":2.02,"tv":43.77,"id":17336468}]}]}
{"op":"mcm","clk":"987756135","pt":1580499552061,"mc":[{"id":"1.168136214","rc":[{"batb":[[1,5.1,2.04]],"ltp":5.7,"tv":1.93,"id":12925630}]}]}
{"op":"mcm","clk":"987810383","pt":1580499952109,"mc":[{"id":"1.168136214","rc":[{"batl":[[0,7.2,1.01],[1,9.8,2.19],[2,11,9]],"ltp":5.7,"tv":1.93,"id":12925630}]}]}
{"op":"mcm","clk":"987810406","pt":1580499952275,"mc":[{"id":"1.168136214","rc":[{"trd":[[5.6,0.02]],"batl":[[0,9.8,2.2],[1,11,9],[2,16,10]],"ltp":5.6,"tv":1.95,"id":12925630}],"tv":85.49}]}
{"op":"mcm","clk":"987810618","pt":1580499954210,"mc":[{"id":"1.168136214","rc":[{"batb":[[0,3.1,16.77]],"ltp":3.1,"tv":39.75,"id":11981493}]}]}
{"op":"mcm","clk":"987812621","pt":1580499969704,"mc":[{"id":"1.168136214","rc":[{"trd":[[5.5,0.02]],"batb":[[0,5.2,1.6]],"batl":[[0,9.8,2.19]],"ltp":5.5,"tv":1.97,"id":12925630}],"tv":85.51}]}
{"op":"mcm","clk":"987812913","pt":1580499972104,"mc":[{"id":"1.168136214","rc":[{"trd":[[2.02,33.3]],"batb":[[0,2.02,2.86]],"ltp":2.02,"tv":53.77,"id":17336468}],"tv":95.5}]}
{"op":"mcm","clk":"987815945","pt":1580499996993,"mc":[{"id":"1.168136214","rc":[{"batb":[[2,3,30]],"ltp":3.1,"tv":39.75,"id":11981493}]}]}
{"op":"mcm","clk":"987839230","pt":1580500112106,"mc":[{"id":"1.168136214","rc":[{"batb":[[0,3.1,36.77]],"ltp":3.1,"tv":39.75,"id":11981493}]}]}
{"op":"mcm","clk":"987860020","pt":1580500304039,"mc":[{"id":"1.168136214","rc":[{"trd":[[2.06,22.85],[2.08,27.14]],"batl":[[0,2.08,86.43],[1,2.72,20.42],[2,2.96,19.7]],"ltp":2.08,"tv":103.76,"id":17336468}],"tv":145.49}]}
{"op":"mcm","clk":"987860938","pt":1580500312951,"mc":[{"id":"1.168136214","rc":[{"batl":[[0,2.06,4.9],[1,2.08,86.43],[2,2.72,20.42]],"ltp":2.08,"tv":103.76,"id":17336468}]}]}
{"op":"mcm","clk":"987876434","pt":1580500469936,"mc":[{"id":"1.168136214","rc":[{"trd":[[2.02,39.04]],"batb":[[0,1.99,2.32],[1,1.96,1.98],[2,1.92,25.7]],"batl":[[0,2.02,1.13],[1,2.06,4.9],[2,2.08,86.43]],"ltp":2.02,"tv":109.49,"id":17336468}],"tv":151.23}]}
{"op":"mcm","clk":"987876593","pt":1580500471525,"mc":[{"id":"1.168136214","rc":[{"trd":[[2.02,41.3]],"batb":[[0,1.99,2.78]],"batl":[[0,2.06,4.9],[1,2.08,86.43],[2,2.72,20.42]],"ltp":2.02,"tv":111.75,"id":17336468}],"tv":153.49}]}
{"op":"mcm","clk":"987877654","pt":1580500483057,"mc":[{"id":"1.168136214","rc":[{"trd":[[3.1,20.46]],"batb":[[0,3.1,34.77]],"ltp":3.1,"tv":43.75,"id":11981493}],"tv":157.49}]}
{"op":"mcm","clk":"987880798","pt":1580500517805,"mc":[{"id":"1.168136214","rc":[{"batl":[[0,4.3,2.2],[1,4.4,14.4],[2,5.5,14.4]],"ltp":3.1,"tv":43.75,"id":11981493}]}]}
{"op":"mcm","clk":"987907282","pt":1580500819448,"mc":[{"id":"1.168136214","rc":[{"batb":[[0,5.2,1.6]],"ltp":5.5,"tv":1.97,"id":12925630},{"trd":[[2.02,41.28],[2.04,1.94],[2.06,22.84],[2.28,7.11],[2.3,1.44]],"batb":[[2,1.92,25.69]],"batl":[[0,2.06,4.89],[2,2.72,20.41]],"ltp":2.02,"tv":111.73,"id":17336468},{"trd":[[2.44,9.18],[2.46,2.82],[2.7,1.22],[2.72,5.29]],"batl":[[1,4.4,14.39],[2,5.5,14.39]],"ltp":3.1,"tv":43.75,"id":11981493}],"tv":157.46}]}
{"op":"mcm","clk":"987910631","pt":1580500849638,"mc":[{"id":"1.168136214","rc":[{"trd":[[2.06,26.84]],"batl":[[0,2.06,2.89]],"ltp":2.06,"tv":115.73,"id":17336468}],"tv":161.46}]}
{"op":"mcm","clk":"987923064","pt":1580500951114,"mc":[{"id":"1.168136214","rc":[{"batb":[[0,3.1,54.77]],"ltp":3.1,"tv":43.75,"id":11981493}]}]}
{"op":"mcm","clk":"987934052","pt":1580500961284,"mc":[{"id":"1.168136214","rc":[{"batb":[[2,3,10]],"ltp":3.1,"tv":43.75,"id":11981493}]}]}
{"op":"mcm","clk":"987956156","pt":1580501120969,"mc":[{"id":"1.168136214","rc":[{"trd":[[1.99,4.64],[2.02,42.2]],"batb":[[0,1.96,1.98],[1,1.92,25.69],[2,1.91,100]],"batl":[[0,2.06,3.16]],"ltp":1.99,"tv":121.29,"id":17336468}],"tv":167.02}]}
{"op":"mcm","clk":"987956227","pt":1580501121460,"mc":[{"id":"1.168136214","rc":[{"trd":[[3.1,24.36]],"batb":[[0,3.1,52.82]],"ltp":3.1,"tv":47.65,"id":11981493}],"tv":170.92}]}
{"op":"mcm","clk":"987960920","pt":1580501152423,"mc":[{"id":"1.168136214","rc":[{"batb":[[1,5.1,3.71]],"ltp":5.5,"tv":1.97,"id":12925630}]}]}
{"op":"mcm","clk":"987961362","pt":1580501155102,"mc":[{"id":"1.168136214","rc":[{"batb":[[1,1.93,6.92],[2,1.92,25.69]],"batl":[[0,2.04,6.82],[1,2.06,2.89],[2,2.08,86.43]],"ltp":1.99,"tv":121.29,"id":17336468}]}]}
{"op":"mcm","clk":"987963049","pt":1580501166069,"mc":[{"id":"1.168136214","rc":[{"batl":[[1,2.08,86.43],[2,2.72,20.41]],"ltp":1.99,"tv":121.29,"id":17336468}]}]}
{"op":"mcm","clk":"987966414","pt":1580501187117,"mc":[{"id":"1.168136214","rc":[{"batb":[[0,1.97,2.23],[1,1.96,1.98]],"batl":[[0,2.08,86.7],[1,2.72,20.41],[2,2.96,19.69]],"ltp":1.99,"tv":121.29,"id":17336468}]}]}
{"op":"mcm","clk":"987966473","pt":1580501187537,"mc":[{"id":"1.168136214","rc":[{"batl":[[0,2.06,6.75],[1,2.08,86.43],[2,2.72,20.41]],"ltp":1.99,"tv":121.29,"id":17336468}]}]}
{"op":"mcm","clk":"987968780","pt":1580501203433,"mc":[{"id":"1.168136214","rc":[{"batl":[[0,2.04,6.03],[1,2.06,6.48],[2,2.08,86.43]],"ltp":1.99,"tv":121.29,"id":17336468}]}]}
{"op":"mcm","clk":"987993047","pt":1580501359622,"mc":[{"id":"1.168136214","rc":[{"trd":[[1.99,5.18],[2.04,13.46]],"batb":[[0,1.97,2.24]],"batl":[[0,2.06,6.48],[1,2.08,86.43],[2,2.72,20.41]],"ltp":2.04,"tv":133.35,"id":17336468}],"tv":182.98}]}
{"op":"mcm","clk":"987994866","pt":1580501371113,"mc":[{"id":"1.168136214","rc":[{"trd":[[2.04,13.48]],"batb":[[0,1.97,2.23]],"ltp":2.04,"tv":133.37,"id":17336468}],"tv":183.0}]}
{"op":"mcm","clk":"988022037","pt":1580501543887,"mc":[{"id":"1.168136214","rc":[{"batb":[[2,1.93,9.79]],"ltp":2.04,"tv":133.37,"id":17336468}]}]}
{"op":"mcm","clk":"988027641","pt":1580501583766,"mc":[{"id":"1.168136214","rc":[{"trd":[[2.06,37.68]],"batl":[[0,2.06,1.07]],"ltp":2.06,"tv":144.2,"id":17336468}],"tv":193.84}]}
{"op":"mcm","clk":"988042376","pt":1580501689439,"mc":[{"id":"1.168136214","rc":[{"batb":[[2,3,35]],"ltp":3.1,"tv":47.65,"id":11981493}]}]}
{"op":"mcm","clk":"988063041","pt":1580501830590,"mc":[{"id":"1.168136214","rc":[{"trd":[[2.06,39.82],[2.08,35.34]],"batl":[[0,2.08,82.33],[1,2.72,20.41],[2,2.96,19.69]],"ltp":2.08,"tv":154.54,"id":17336468}],"tv":204.17}]}
{"op":"mcm","clk":"988076073","pt":1580501855028,"mc":[{"id":"1.168136214","rc":[{"batb":[[0,1.97,6.79]],"ltp":2.08,"tv":154.54,"id":17336468}]}]}
{"op":"mcm","clk":"988078820","pt":1580501873481,"mc":[{"id":"1.168136214","rc":[{"trd":[[5.1,7.42],[5.2,1.4],[5.5,1.82]],"batb":[[0,5,3],[1,4.4,1.68],[2,4,15]],"batl":[[0,5.1,16],[1,9.8,2.19],[2,11,9]],"ltp":5.1,"tv":12.59,"id":12925630}],"tv":214.79}]}
{"op":"mcm","clk":"988079344","pt":1580501877032,"mc":[{"id":"1.168136214","rc":[{"batb":[[0,4.4,1.68],[1,4.1,3]],"ltp":5.1,"tv":12.59,"id":12925630}]}]}
{"op":"mcm","clk":"988080331","pt":1580501883520,"mc":[{"id":"1.168136214","rc":[{"batb":[[1,4.2,3]],"ltp":5.1,"tv":12.59,"id":12925630}]}]}
{"op":"mcm","clk":"988080875","pt":1580501886840,"mc":[{"id":"1.168136214","rc":[{"batb":[[0,4.3,1.68]],"ltp":5.1,"tv":12.59,"id":12925630}]}]}
{"op":"mcm","clk":"988080990","pt":1580501887594,"mc":[{"id":"1.168136214","rc":[{"batl":[[0,9.8,2.19],[1,11,9],[2,16,10]],"ltp":5.1,"tv":12.59,"id":12925630}]}]}
{"op":"mcm","clk":"988081636","pt":1580501892033,"mc":[{"id":"1.168136214","rc":[{"batb":[[1,4,15],[2,3.1,98]],"ltp":5.1,"tv":12.59,"id":12925630}]}]}
{"op":"mcm","clk":"988081649","pt":1580501892165,"mc":[{"id":"1.168136214","rc":[{"batb":[[0,4.3,4.68]],"ltp":5.1,"tv":12.59,"id":12925630}]}]}
{"op":"mcm","clk":"988083130","pt":1580501902058,"mc":[{"id":"1.168136214","rc":[{"batb":[[0,4.3,1.68]],"ltp":5.1,"tv":12.59,"id":12925630}]}]}
{"op":"mcm","clk":"988083232","pt":1580501902643,"mc":[{"id":"1.168136214","rc":[{"batb":[[0,4.4,6.01],[1,4.3,1.68],[2,4,15]],"ltp":5.1,"tv":12.59,"id":12925630}]}]}
{"op":"mcm","clk":"988084572","pt":1580501911058,"mc":[{"id":"1.168136214","rc":[{"batb":[[0,4.4,3.01]],"ltp":5.1,"tv":12.59,"id":12925630}]}]}
{"op":"mcm","clk":"988084606","pt":1580501911272,"mc":[{"id":"1.168136214","rc":[{"batb":[[0,4.5,3],[1,4.4,3.01],[2,4.3,1.68]],"ltp":5.1,"tv":12.59,"id":12925630}]}]}
{"op":"mcm","clk":"988085794","pt":1580501919067,"mc":[{"id":"1.168136214","rc":[{"batb":[[0,4.6,1.68],[1,4.5,3],[2,4.4,3.01]],"ltp":5.1,"tv":12.59,"id":12925630}]}]}
{"op":"mcm","clk":"988091866","pt":1580501961128,"mc":[{"id":"1.168136214","rc":[{"batb":[[0,4.7,1.98],[1,4.6,1.68],[2,4.5,3]],"ltp":5.1,"tv":12.59,"id":12925630},{"batb":[[0,1.98,1.98],[1,1.97,6.79]],"ltp":2.08,"tv":154.54,"id":17336468},{"batb":[[0,3.15,1.98],[1,3.1,52.82],[2,3.05,12]],"ltp":3.1,"tv":47.65,"id":11981493}]}]}
{"op":"mcm","clk":"988094600","pt":1580501979847,"mc":[{"id":"1.168136214","rc":[{"batb":[[0,1.99,2],[1,1.98,1.98],[2,1.97,6.79]],"ltp":2.08,"tv":154.54,"id":17336468}]}]}
{"op":"mcm","clk":"988095098","pt":1580501982964,"mc":[{"id":"1.168136214","rc":[{"batb":[[0,4.8,1.68],[1,4.7,1.98]],"ltp":5.1,"tv":12.59,"id":12925630},{"batb":[[0,2,1.68],[1,1.99,2],[2,1.98,1.98]],"ltp":2.08,"tv":154.54,"id":17336468}]}]}
{"op":"mcm","clk":"988100003","pt":1580502014077,"mc":[{"id":"1.168136214","rc":[{"batb":[[0,2,6.68]],"ltp":2.08,"tv":154.54,"id":17336468}]}]}
{"op":"mcm","clk":"988100132","pt":1580502014984,"mc":[{"id":"1.168136214","rc":[{"trd":[[2.08,77.32]],"batl":[[0,2.08,61.34]],"ltp":2.08,"tv":196.52,"id":17336468}],"tv":256.77}]}
{"op":"mcm","clk":"988106138","pt":1580502052245,"mc":[{"id":"1.168136214","rc":[{"batb":[[1,1.98,1.98],[2,1.96,2]],"ltp":2.08,"tv":196.52,"id":17336468}]}]}
{"op":"mcm","clk":"988110344","pt":1580502076820,"mc":[{"id":"1.168136214","rc":[{"batb":[[0,1.99,6.68]],"ltp":2.08,"tv":196.52,"id":17336468}]}]}
{"op":"mcm","clk":"988113197","pt":1580502092447,"mc":[{"id":"1.168136214","rc":[{"batb":[[0,2,50],[1,1.99,6.68],[2,1.98,1.98]],"ltp":2.08,"tv":196.52,"id":17336468}]}]}
{"op":"mcm","clk":"988118466","pt":1580502125672,"mc":[{"id":"1.168136214","rc":[{"batl":[[0,4.1,4],[1,4.3,2.2],[2,4.4,14.39]],"ltp":3.1,"tv":47.65,"id":11981493}]}]}
{"op":"mcm","clk":"988118580","pt":1580502126257,"mc":[{"id":"1.168136214","rc":[{"batl":[[0,4.1,4.2],[1,4.3,2]],"ltp":3.1,"tv":47.65,"id":11981493}]}]}
{"op":"mcm","clk":"988120878","pt":1580502141131,"mc":[{"id":"1.168136214","rc":[{"batl":[[1,4.4,14.39],[2,5.5,14.39]],"ltp":3.1,"tv":47.65,"id":11981493}]}]}
{"op":"mcm","clk":"988125002","pt":1580502167903,"mc":[{"id":"1.168136214","rc":[{"batb":[[0,2,51]],"ltp":2.08,"tv":196.52,"id":17336468}]}]}
{"op":"mcm","clk":"988135959","pt":1580502237066,"mc":[{"id":"1.168136214","rc":[{"batb":[[0,2,52]],"ltp":2.08,"tv":196.52,"id":17336468}]}]}
{"op":"mcm","clk":"988137393","pt":1580502246579,"mc":[{"id":"1.168136214","rc":[{"batl":[[0,4,2.2],[1,4.1,4],[2,4.4,14.39]],"ltp":3.1,"tv":47.65,"id":11981493}]}]}
{"op":"mcm","clk":"988137729","pt":1580502249129,"mc":[{"id":"1.168136214","rc":[{"batl":[[0,4,2]],"ltp":3.1,"tv":47.65,"id":11981493}]}]}
{"op":"mcm","clk":"988137746","pt":1580502249230,"mc":[{"id":"1.168136214","rc":[{"batl":[[0,4,2.2]],"ltp":3.1,"tv":47.65,"id":11981493}]}]}
{"op":"mcm","clk":"988138843","pt":1580502256821,"mc":[{"id":"1.168136214","rc":[{"trd":[[2.08,80.68]],"batl":[[0,2.08,59.66]],"ltp":2.08,"tv":199.88,"id":17336468}],"tv":260.13}]}
{"op":"mcm","clk":"988144110","pt":1580502293990,"mc":[{"id":"1.168136214","rc":[{"trd":[[2.08,122.98]],"batl":[[0,2.08,38.51]],"ltp":2.08,"tv":242.18,"id":17336468}],"tv":302.43}]}
{"op":"mcm","clk":"988147509","pt":1580502316317,"mc":[{"id":"1.168136214","rc":[{"batb":[[0,4.8,5.68]],"ltp":5.1,"tv":12.59,"id":12925630}]}]}
{"op":"mcm","clk":"988151973","pt":1580502344067,"mc":[{"id":"1.168136214","rc":[{"trd":[[2.08,165.32]],"batl":[[0,2.08,17.34]],"ltp":2.08,"tv":284.52,"id":17336468}],"tv":344.77}]}
{"op":"mcm","clk":"988164535","pt":1580502428497,"mc":[{"id":"1.168136214","rc":[{"batl":[[0,9.4,2],[1,9.8,2.19],[2,11,9]],"ltp":5.1,"tv":12.59,"id":12925630}]}]}
{"op":"mcm","clk":"988168176","pt":1580502456008,"mc":[{"id":"1.168136214","rc":[{"batl":[[1,11,9.51],[2,16,10]],"ltp":5.1,"tv":12.59,"id":12925630}]}]}
{"op":"mcm","clk":"988168313","pt":1580502457022,"mc":[{"id":"1.168136214","rc":[{"batl":[[0,9.2,1.68],[1,9.4,2],[2,11,9.51]],"ltp":5.1,"tv":12.59,"id":12925630}]}]}
{"op":"mcm","clk":"988270536","pt":1580503159848,"mc":[{"id":"1.168136214","rc":[{"trd":[[2.08,178.1]],"batb":[[1,1.98,1.98],[2,1.94,20]],"batl":[[0,2.08,10.95]],"ltp":2.08,"tv":297.3,"id":17336468}],"tv":357.55}]}
{"op":"mcm","clk":"988274446","pt":1580503190479,"mc":[{"id":"1.168136214","rc":[{"trd":[[2,3.36]],"batb":[[0,2,50.32]],"ltp":2.0,"tv":300.66,"id":17336468}],"tv":360.91}]}
{"op":"mcm","clk":"988281085","pt":1580503236362,"mc":[{"id":"1.168136214","rc":[{"batb":[[2,3.05,32]],"ltp":3.1,"tv":47.65,"id":11981493}]}]}
{"op":"mcm","clk":"988282580","pt":1580503245797,"mc":[{"id":"1.168136214","rc":[{"batl":[[0,2.06,1.63],[1,2.08,10.95],[2,2.72,20.41]],"ltp":2.0,"tv":300.66,"id":17336468}]}]}
{"op":"mcm","clk":"988309862","pt":1580503449074,"mc":[{"id":"1.168136214","rc":[{"trd":[[3.1,40.4],[3.15,3.96]],"batb":[[0,3.1,44.8],[1,3.05,32],[2,3,35]],"ltp":3.1,"tv":67.65,"id":11981493}],"tv":380.91}]}
{"op":"mcm","clk":"988314054","pt":1580503489551,"mc":[{"id":"1.168136214","rc":[{"batb":[[0,1.98,1.98],[1,1.97,50.32]],"ltp":2.0,"tv":300.66,"id":17336468}]}]}
{"op":"mcm","clk":"988314447","pt":1580503493065,"mc":[{"id":"1.168136214","rc":[{"batb":[[0,1.98,52.3],[1,1.94,20],[2,1.93,9.79]],"ltp":2.0,"tv":300.66,"id":17336468}]}]}
{"op":"mcm","clk":"988314726","pt":1580503496047,"mc":[{"id":"1.168136214","rc":[{"trd":[[1.98,3.96]],"batb":[[0,1.96,50.32]],"ltp":1.98,"tv":304.62,"id":17336468}],"tv":384.87}]}
{"op":"mcm","clk":"988314992","pt":1580503498869,"mc":[{"id":"1.168136214","rc":[{"batb":[[0,1.98,50.32]],"ltp":1.98,"tv":304.62,"id":17336468}]}]}
{"op":"mcm","clk":"988315306","pt":1580503502066,"mc":[{"id":"1.168136214","rc":[{"batb":[[1,1.95,17.58],[2,1.94,20]],"batl":[[0,2.06,18.27]],"ltp":1.98,"tv":304.62,"id":17336468}]}]}
{"op":"mcm","clk":"988315794","pt":1580503506079,"mc":[{"id":"1.168136214","rc":[{"batb":[[0,1.97,50.32]],"ltp":1.98,"tv":304.62,"id":17336468},{"trd":[[3.1,70.4]],"batb":[[0,3.1,29.8]],"ltp":3.1,"tv":97.65,"id":11981493}],"tv":414.87}]}
{"op":"mcm","clk":"988318205","pt":1580503529032,"mc":[{"id":"1.168136214","rc":[{"batb":[[0,1.98,50.32]],"ltp":1.98,"tv":304.62,"id":17336468}]}]}
{"op":"mcm","clk":"988318428","pt":1580503531153,"mc":[{"id":"1.168136214","rc":[{"batb":[[0,1.95,17.58],[1,1.94,20],[2,1.93,9.79]],"ltp":1.98,"tv":304.62,"id":17336468}]}]}
{"op":"mcm","clk":"988318438","pt":1580503531253,"mc":[{"id":"1.168136214","rc":[{"batb":[[0,1.97,50.32],[1,1.95,17.58],[2,1.94,20]],"ltp":1.98,"tv":304.62,"id":17336468}]}]}
{"op":"mcm","clk":"988318848","pt":1580503535156,"mc":[{"id":"1.168136214","rc":[{"batb":[[0,1.98,16.97],[1,1.97,50.32]],"batl":[[0,2.06,1.63],[2,2.1,7.31]],"ltp":1.98,"tv":304.62,"id":17336468}]}]}
{"op":"mcm","clk":"988319289","pt":1580503538951,"mc":[{"id":"1.168136214","rc":[{"batb":[[0,1.99,50.32],[1,1.98,16.97]],"batl":[[0,2.06,8.01]],"ltp":1.98,"tv":304.62,"id":17336468}]}]}
{"op":"mcm","clk":"988319615","pt":1580503541865,"mc":[{"id":"1.168136214","rc":[{"batb":[[0,2,50.32]],"ltp":1.98,"tv":304.62,"id":17336468}]}]}
{"op":"mcm","clk":"988322387","pt":1580503567092,"mc":[{"id":"1.168136214","rc":[{"batb":[[1,1.94,20],[2,1.93,9.79]],"batl":[[2,2.72,20.41]],"ltp":1.98,"tv":304.62,"id":17336468}]}]}
{"op":"mcm","clk":"988326799","pt":1580503611905,"mc":[{"id":"1.168136214","rc":[{"batb":[[0,1.98,50.32]],"ltp":1.98,"tv":304.62,"id":17336468}]}]}
{"op":"mcm","clk":"988328947","pt":1580503633014,"mc":[{"id":"1.168136214","rc":[{"batb":[[1,1.95,17.58],[2,1.94,20]],"batl":[[0,2.04,16.81],[1,2.06,8.01],[2,2.08,10.95]],"ltp":1.98,"tv":304.62,"id":17336468}]}]}
{"op":"mcm","clk":"988329242","pt":1580503636356,"mc":[{"id":"1.168136214","rc":[{"batb":[[0,1.97,50.32]],"ltp":1.98,"tv":304.62,"id":17336468}]}]}
{"op":"mcm","clk":"988330205","pt":1580503646957,"mc":[{"id":"1.168136214","rc":[{"batb":[[0,2,50.32]],"ltp":1.98,"tv":304.62,"id":17336468}]}]}
{"op":"mcm","clk":"988330469","pt":1580503649779,"mc":[{"id":"1.168136214","rc":[{"batb":[[0,1.97,50.32]],"batl":[[1,2.06,1.63]],"ltp":1.98,"tv":304.62,"id":17336468}]}]}
{"op":"mcm","clk":"988341452","pt":1580503662910,"mc":[{"id":"1.168136214","rc":[{"trd":[[2.02,46.2]],"ltp":2.02,"tv":308.62,"id":17336468}],"tv":418.87}]}
{"op":"mcm","clk":"988341636","pt":1580503664995,"mc":[{"id":"1.168136214","rc":[{"trd":[[2,7.36]],"ltp":2.0,"tv":312.62,"id":17336468}],"tv":422.87}]}
{"op":"mcm","clk":"988341713","pt":1580503665877,"mc":[{"id":"1.168136214","rc":[{"batb":[[0,1.98,23.5],[1,1.97,50.32]],"batl":[[0,2.06,1.63],[1,2.08,10.95],[2,2.1,7.35]],"ltp":2.0,"tv":312.62,"id":17336468}]}]}
{"op":"mcm","clk":"988341780","pt":1580503666773,"mc":[{"id":"1.168136214","rc":[{"batb":[[0,2,2],[1,1.98,23.5],[2,1.97,50.32]],"ltp":2.0,"tv":312.62,"id":17336468}]}]}
{"op":"mcm","clk":"988341935","pt":1580503668403,"mc":[{"id":"1.168136214","rc":[{"batb":[[0,1.98,23.5],[1,1.97,50.32],[2,1.94,20]],"ltp":2.0,"tv":312.62,"id":17336468}]}]}
{"op":"mcm","clk":"988342015","pt":1580503669395,"mc":[{"id":"1.168136214","rc":[{"trd":[[2.02,50.2]],"batb":[[0,1.98,16.97]],"batl":[[0,2.06,8.01]],"ltp":2.02,"tv":316.62,"id":17336468}],"tv":426.87}]}
{"op":"mcm","clk":"988342196","pt":1580503671482,"mc":[{"id":"1.168136214","rc":[{"trd":[[2.02,54.2]],"ltp":2.02,"tv":320.62,"id":17336468}],"tv":430.87}]}
{"op":"mcm","clk":"988342349","pt":1580503673405,"mc":[{"id":"1.168136214","rc":[{"batb":[[0,2,2],[1,1.98,16.97],[2,1.97,50.32]],"ltp":2.02,"tv":320.62,"id":17336468}]}]}
{"op":"mcm","clk":"988342516","pt":1580503675595,"mc":[{"id":"1.168136214","rc":[{"batb":[[0,1.98,16.97],[1,1.97,50.32],[2,1.94,20]],"ltp":2.02,"tv":320.62,"id":17336468}]}]}
{"op":"mcm","clk":"988342595","pt":1580503676489,"mc":[{"id":"1.168136214","rc":[{"trd":[[2.02,58.2]],"ltp":2.02,"tv":324.62,"id":17336468}],"tv":434.87}]}
{"op":"mcm","clk":"988342775","pt":1580503678617,"mc":[{"id":"1.168136214","rc":[{"trd":[[2.02,62.2]],"ltp":2.02,"tv":328.62,"id":17336468}],"tv":438.87}]}
{"op":"mcm","clk":"988342920","pt":1580503680099,"mc":[{"id":"1.168136214","rc":[{"trd":[[2.02,66.2]],"ltp":2.02,"tv":332.62,"id":17336468}],"tv":442.87}]}
{"op":"mcm","clk":"988343064","pt":1580503681730,"mc":[{"id":"1.168136214","rc":[{"trd":[[2.02,70.2]],"ltp":2.02,"tv":336.62,"id":17336468}],"tv":446.87}]}
{"op":"mcm","clk":"988343235","pt":1580503683714,"mc":[{"id":"1.168136214","rc":[{"trd":[[2.02,74.2]],"ltp":2.02,"tv":340.62,"id":17336468}],"tv":450.87}]}
{"op":"mcm","clk":"988343402","pt":1580503685594,"mc":[{"id":"1.168136214","rc":[{"trd":[[2.02,78.2]],"ltp":2.02,"tv":344.62,"id":17336468}],"tv":454.87}]}
{"op":"mcm","clk":"988343662","pt":1580503688316,"mc":[{"id":"1.168136214","rc":[{"trd":[[2.02,82.2]],"ltp":2.02,"tv":348.62,"id":17336468}],"tv":458.87}]}
{"op":"mcm","clk":"988343856","pt":1580503690350,"mc":[{"id":"1.168136214","rc":[{"trd":[[2.02,86.2]],"ltp":2.02,"tv":352.62,"id":17336468}],"tv":462.87}]}
{"op":"mcm","clk":"988344322","pt":1580503694713,"mc":[{"id":"1.168136214","rc":[{"batb":[[0,2,2],[1,1.98,16.97],[2,1.97,50.32]],"ltp":2.02,"tv":352.62,"id":17336468}]}]}
{"op":"mcm","clk":"988344584","pt":1580503697030,"mc":[{"id":"1.168136214","rc":[{"trd":[[2.02,90.2]],"batb":[[0,1.98,16.97],[1,1.97,50.32],[2,1.94,20]],"ltp":2.02,"tv":356.62,"id":17336468}],"tv":466.87}]}
{"op":"mcm","clk":"988345504","pt":1580503706151,"mc":[{"id":"1.168136214","rc":[{"batb":[[0,3.25,1.68],[1,3.1,29.8],[2,3.05,32]],"ltp":3.1,"tv":97.65,"id":11981493}]}]}
{"op":"mcm","clk":"988345583","pt":1580503707073,"mc":[{"id":"1.168136214","rc":[{"batb":[[0,3.1,29.8],[1,3.05,32],[2,3,35]],"ltp":3.1,"tv":97.65,"id":11981493}]}]}
{"op":"mcm","clk":"988346808","pt":1580503719981,"mc":[{"id":"1.168136214","rc":[{"batb":[[1,1.93,9.79],[2,1.92,25.69]],"ltp":2.02,"tv":356.62,"id":17336468}]}]}
{"op":"mcm","clk":"988347282","pt":1580503724622,"mc":[{"id":"1.168136214","rc":[{"batl":[[0,2.06,6.38]],"ltp":2.02,"tv":356.62,"id":17336468}]}]}
{"op":"mcm","clk":"988347888","pt":1580503731124,"mc":[{"id":"1.168136214","rc":[{"batb":[[0,1.94,16.97],[1,1.93,16.42]],"batl":[[0,2.08,10.95],[1,2.1,7.35],[2,2.72,20.41]],"ltp":2.02,"tv":356.62,"id":17336468}]}]}
{"op":"mcm","clk":"988348114","pt":1580503733701,"mc":[{"id":"1.168136214","rc":[{"batb":[[0,4.9,1.98],[1,4.8,5.68]],"ltp":5.1,"tv":12.59,"id":12925630},{"batb":[[0,1.95,1.98],[1,1.94,16.97],[2,1.93,16.42]],"ltp":2.02,"tv":356.62,"id":17336468},{"batb":[[0,3.15,1.98],[1,3.1,29.8],[2,3.05,32]],"ltp":3.1,"tv":97.65,"id":11981493}]}]}
{"op":"mcm","clk":"988348884","pt":1580503742027,"mc":[{"id":"1.168136214","rc":[{"trd":[[2,9.36]],"batb":[[2,1.93,9.79]],"batl":[[0,2.06,6.38],[1,2.08,10.95],[2,2.1,7.35]],"ltp":2.0,"tv":358.62,"id":17336468}],"tv":468.87}]}
{"op":"mcm","clk":"988350049","pt":1580503754819,"mc":[{"id":"1.168136214","rc":[{"batb":[[0,1.97,6.55],[1,1.96,25],[2,1.95,1.98]],"batl":[[0,2.08,10.95],[1,2.1,7.35],[2,2.72,20.41]],"ltp":2.0,"tv":358.62,"id":17336468}]}]}
{"op":"mcm","clk":"988350206","pt":1580503756647,"mc":[{"id":"1.168136214","rc":[{"batb":[[0,1.98,25],[1,1.97,6.55],[2,1.96,25]],"ltp":2.0,"tv":358.62,"id":17336468}]}]}
{"op":"mcm","clk":"988350380","pt":1580503758650,"mc":[{"id":"1.168136214","rc":[{"batb":[[2,1.95,1.98]],"ltp":2.0,"tv":358.62,"id":17336468}]}]}
{"op":"mcm","clk":"988350750","pt":1580503763135,"mc":[{"id":"1.168136214","rc":[{"batb":[[1,4.8,4]],"ltp":5.1,"tv":12.59,"id":12925630},{"batb":[[0,1.99,7.89],[1,1.98,25],[2,1.97,6.55]],"ltp":2.0,"tv":358.62,"id":17336468}]}]}
{"op":"mcm","clk":"988350798","pt":1580503763659,"mc":[{"id":"1.168136214","rc":[{"batb":[[0,5,1.68],[1,4.9,1.98],[2,4.8,4]],"ltp":5.1,"tv":12.59,"id":12925630}]}]}
{"op":"mcm","clk":"988351094","pt":1580503766779,"mc":[{"id":"1.168136214","rc":[{"batb":[[1,1.95,1.98],[2,1.93,9.79]],"batl":[[0,2.06,6.38],[1,2.08,10.95],[2,2.1,7.35]],"ltp":2.0,"tv":358.62,"id":17336468}]}]}
{"op":"mcm","clk":"988353322","pt":1580503790274,"mc":[{"id":"1.168136214","rc":[{"batb":[[1,1.95,26.98]],"ltp":2.0,"tv":358.62,"id":17336468}]}]}
{"op":"mcm","clk":"988353891","pt":1580503796006,"mc":[{"id":"1.168136214","rc":[{"batb":[[0,1.96,7.89]],"ltp":2.0,"tv":358.62,"id":17336468}]}]}
{"op":"mcm","clk":"988354077","pt":1580503797784,"mc":[{"id":"1.168136214","rc":[{"batb":[[0,1.97,25],[1,1.96,7.89],[2,1.95,26.98]],"ltp":2.0,"tv":358.62,"id":17336468}]}]}
{"op":"mcm","clk":"988354181","pt":1580503798771,"mc":[{"id":"1.168136214","rc":[{"batb":[[2,1.95,1.98]],"ltp":2.0,"tv":358.62,"id":17336468}]}]}
{"op":"mcm","clk":"988357079","pt":1580503828154,"mc":[{"id":"1.168136214","rc":[{"batb":[[0,1.98,7.81],[1,1.97,25]],"ltp":2.0,"tv":358.62,"id":17336468}]}]}
{"op":"mcm","clk":"988357434","pt":1580503832062,"mc":[{"id":"1.168136214","rc":[{"batb":[[1,1.95,1.98],[2,1.93,9.79]],"ltp":2.0,"tv":358.62,"id":17336468}]}]}
{"op":"mcm","clk":"988357482","pt":1580503832539,"mc":[{"id":"1.168136214","rc":[{"batb":[[1,1.95,26.98]],"ltp":2.0,"tv":358.62,"id":17336468}]}]}
{"op":"mcm","clk":"988358178","pt":1580503840773,"mc":[{"id":"1.168136214","rc":[{"batb":[[1,1.95,1.98]],"ltp":2.0,"tv":358.62,"id":17336468}]}]}
{"op":"mcm","clk":"988358313","pt":1580503841964,"mc":[{"id":"1.168136214","rc":[{"batb":[[1,1.95,26.98]],"ltp":2.0,"tv":358.62,"id":17336468}]}]}
{"op":"mcm","clk":"988359057","pt":1580503849557,"mc":[{"id":"1.168136214","rc":[{"batb":[[1,1.95,1.98]],"ltp":2.0,"tv":358.62,"id":17336468}]}]}
{"op":"mcm","clk":"988359766","pt":1580503855581,"mc":[{"id":"1.168136214","rc":[{"batb":[[1,1.95,11.98]],"ltp":2.0,"tv":358.62,"id":17336468}]}]}
{"op":"mcm","clk":"988360171","pt":1580503859892,"mc":[{"id":"1.168136214","rc":[{"batb":[[0,1.96,7.81]],"ltp":2.0,"tv":358.62,"id":17336468}]}]}
{"op":"mcm","clk":"988366721","pt":1580503925751,"mc":[{"id":"1.168136214","rc":[{"trd":[[1.96,15.62]],"batb":[[0,1.95,11.98],[1,1.93,9.79],[2,1.92,25.69]],"batl":[[0,1.96,12.19],[1,2.06,6.38],[2,2.08,10.95]],"ltp":1.96,"tv":374.24,"id":17336468}],"tv":484.5}]}
{"op":"mcm","clk":"988367634","pt":1580503935780,"mc":[{"id":"1.168136214","rc":[{"trd":[[1.95,23.96]],"batb":[[0,1.93,16.42],[1,1.92,25.69],[2,1.91,100]],"batl":[[0,2.08,11.16],[1,2.1,7.35],[2,2.72,20.41]],"ltp":1.95,"tv":398.21,"id":17336468}],"tv":508.46}]}
{"op":"mcm","clk":"988367736","pt":1580503936501,"mc":[{"id":"1.168136214","rc":[{"batl":[[0,2.02,9.86],[1,2.08,10.95],[2,2.1,7.35]],"ltp":1.95,"tv":398.21,"id":17336468}]}]}
{"op":"mcm","clk":"988368244","pt":1580503942377,"mc":[{"id":"1.168136214","rc":[{"batl":[[0,2.02,9.65]],"ltp":1.95,"tv":398.21,"id":17336468}]}]}
{"op":"mcm","clk":"988382416","pt":1580504102887,"mc":[{"id":"1.168136214","rc":[{"batb":[[0,1.93,118.62]],"ltp":1.95,"tv":398.21,"id":17336468}]}]}
{"op":"mcm","clk":"988388542","pt":1580504179585,"mc":[{"id":"1.168136214","rc":[{"batl":[[0,2,11],[1,2.02,9.65],[2,2.08,10.95]],"ltp":1.95,"tv":398.21,"id":17336468}]}]}
{"op":"mcm","clk":"988390394","pt":1580504199588,"mc":[{"id":"1.168136214","rc":[{"batl":[[0,3.95,5.2],[1,4,2],[2,4.1,4]],"ltp":3.1,"tv":97.65,"id":11981493}]}]}
{"op":"mcm","clk":"988392271","pt":1580504221324,"mc":[{"id":"1.168136214","rc":[{"batb":[[0,5,3.68]],"ltp":5.1,"tv":12.59,"id":12925630}]}]}
{"op":"mcm","clk":"988392421","pt":1580504223426,"mc":[{"id":"1.168136214","rc":[{"trd":[[1.93,18]],"batb":[[0,1.93,109.62]],"ltp":1.93,"tv":416.21,"id":17336468},{"trd":[[3.1,84.44],[3.15,7.92]],"batb":[[0,3.1,22.78],[1,3.05,32],[2,3,35]],"ltp":3.1,"tv":115.65,"id":11981493}],"tv":544.46}]}
{"op":"mcm","clk":"988392853","pt":1580504230693,"mc":[{"id":"1.168136214","rc":[{"batb":[[0,1.95,100],[1,1.93,109.62],[2,1.92,25.69]],"ltp":1.93,"tv":416.21,"id":17336468}]}]}
{"op":"mcm","clk":"988392947","pt":1580504232303,"mc":[{"id":"1.168136214","rc":[{"batb":[[1,1.94,6],[2,1.93,109.62]],"ltp":1.93,"tv":416.21,"id":17336468}]}]}
{"op":"mcm","clk":"988394118","pt":1580504253130,"mc":[{"id":"1.168136214","rc":[{"batl":[[1,2.06,9.65]],"ltp":1.93,"tv":416.21,"id":17336468}]}]}
{"op":"mcm","clk":"988396254","pt":1580504286103,"mc":[{"id":"1.168136214","rc":[{"batb":[[0,5,1.68]],"ltp":5.1,"tv":12.59,"id":12925630},{"batl":[[0,4,2.2],[1,4.1,4],[2,4.4,14.39]],"ltp":3.1,"tv":115.65,"id":11981493}]}]}
{"op":"mcm","clk":"988398109","pt":1580504315110,"mc":[{"id":"1.168136214","rc":[{"batb":[[0,1.95,100.79],[2,1.93,108.83]],"ltp":1.93,"tv":416.21,"id":17336468}]}]}
{"op":"mcm","clk":"988398438","pt":1580504320115,"mc":[{"id":"1.168136214","rc":[{"trd":[[2,31.36]],"batl":[[0,2.06,9.65],[1,2.08,10.95],[2,2.14,5.17]],"ltp":2.0,"tv":438.21,"id":17336468},{"batb":[[2,3,56]],"ltp":3.1,"tv":115.65,"id":11981493}],"tv":566.46}]}
{"op":"mcm","clk":"988399167","pt":1580504331044,"mc":[{"id":"1.168136214","rc":[{"batb":[[0,1.96,10.79],[1,1.95,100],[2,1.94,6]],"ltp":2.0,"tv":438.21,"id":17336468}]}]}
{"op":"mcm","clk":"988399300","pt":1580504333553,"mc":[{"id":"1.168136214","rc":[{"batl":[[0,2.08,10.95],[1,2.14,5.17],[2,2.72,20.41]],"ltp":2.0,"tv":438.21,"id":17336468}]}]}
{"op":"mcm","clk":"988399700","pt":1580504340125,"mc":[{"id":"1.168136214","rc":[{"batb":[[0,1.96,38.49]],"batl":[[1,2.14,32.5]],"ltp":2.0,"tv":438.21,"id":17336468}]}]}
{"op":"mcm","clk":"988405335","pt":1580504418076,"mc":[{"id":"1.168136214","rc":[{"batb":[[0,1.96,38.74]],"ltp":2.0,"tv":438.21,"id":17336468}]}]}
{"op":"mcm","clk":"988406504","pt":1580504433710,"mc":[{"id":"1.168136214","rc":[{"batb":[[0,3.1,42.78]],"ltp":3.1,"tv":115.65,"id":11981493}]}]}
{"op":"mcm","clk":"988406896","pt":1580504439148,"mc":[{"id":"1.168136214","rc":[{"batb":[[2,4.5,3]],"ltp":5.1,"tv":12.59,"id":12925630}]}]}
{"op":"mcm","clk":"988407023","pt":1580504440542,"mc":[{"id":"1.168136214","rc":[{"batl":[[1,11,9.51],[2,16,10]],"ltp":5.1,"tv":12.59,"id":12925630}]}]}
{"op":"mcm","clk":"988407131","pt":1580504442154,"mc":[{"id":"1.168136214","rc":[{"batl":[[1,4.4,14.39],[2,5.5,14.39]],"ltp":3.1,"tv":115.65,"id":11981493}]}]}
{"op":"mcm","clk":"988409864","pt":1580504475974,"mc":[{"id":"1.168136214","rc":[{"batl":[[0,9.6,1.68]],"ltp":5.1,"tv":12.59,"id":12925630}]}]}
{"op":"mcm","clk":"988410266","pt":1580504480968,"mc":[{"id":"1.168136214","rc":[{"batl":[[0,4.4,14.59],[1,5.5,14.39],[2,5.8,9]],"ltp":3.1,"tv":115.65,"id":11981493}]}]}
{"op":"mcm","clk":"988413447","pt":1580504521005,"mc":[{"id":"1.168136214","rc":[{"batb":[[0,1.97,3.25],[1,1.96,38.49],[2,1.95,100]],"ltp":2.0,"tv":438.21,"id":17336468},{"batb":[[0,3.15,3],[1,3.1,42.78],[2,3.05,32]],"ltp":3.1,"tv":115.65,"id":11981493}]}]}
{"op":"mcm","clk":"988414870","pt":1580504539080,"mc":[{"id":"1.168136214","rc":[{"batb":[[1,1.96,10.79]],"ltp":2.0,"tv":438.21,"id":17336468}]}]}
{"op":"mcm","clk":"988414939","pt":1580504540062,"mc":[{"id":"1.168136214","rc":[{"batb":[[0,1.98,10.43],[1,1.97,3.25],[2,1.96,10.79]],"ltp":2.0,"tv":438.21,"id":17336468}]}]}
{"op":"mcm","clk":"988425562","pt":1580504553805,"mc":[{"id":"1.168136214","rc":[{"batb":[[0,1.98,10.68],[1,1.97,3]],"batl":[[0,2.06,6.38],[1,2.08,10.95],[2,2.14,32.5]],"ltp":2.0,"tv":438.21,"id":17336468}]}]}
{"op":"mcm","clk":"988425742","pt":1580504556786,"mc":[{"id":"1.168136214","rc":[{"batb":[[0,1.99,3.25],[1,1.98,10.43]],"ltp":2.0,"tv":438.21,"id":17336468}]}]}
{"op":"mcm","clk":"988431277","pt":1580504642081,"mc":[{"id":"1.168136214","rc":[{"trd":[[3.15,13.92]],"batb":[[0,3.1,42.78],[1,3.05,32],[2,3,56]],"batl":[[0,3.15,7],[1,4.4,14.59],[2,5.5,14.39]],"ltp":3.15,"tv":121.65,"id":11981493}],"tv":572.46}]}
{"op":"mcm","clk":"988431637","pt":1580504648119,"mc":[{"id":"1.168136214","rc":[{"batl":[[1,4.4,14.39]],"ltp":3.15,"tv":121.65,"id":11981493}]}]}
{"op":"mcm","clk":"988431851","pt":1580504652029,"mc":[{"id":"1.168136214","rc":[{"trd":[[3.1,98.44]],"batb":[[0,3.1,35.78]],"batl":[[0,4.4,14.39],[1,5.5,14.39],[2,5.8,9]],"ltp":3.1,"tv":135.65,"id":11981493}],"tv":586.46}]}
{"op":"mcm","clk":"988432057","pt":1580504655116,"mc":[{"id":"1.168136214","rc":[{"batl":[[0,4.4,14.58]],"ltp":3.1,"tv":135.65,"id":11981493}]}]}
{"op":"mcm","clk":"988434543","pt":1580504692865,"mc":[{"id":"1.168136214","rc":[{"batb":[[0,3.15,6.35],[1,3.1,35.78],[2,3.05,32]],"batl":[[0,4.3,2.19],[1,4.4,14.39],[2,5.5,14.39]],"ltp":3.1,"tv":135.65,"id":11981493}]}]}
{"op":"mcm","clk":"988440076","pt":1580504762714,"mc":[{"id":"1.168136214","rc":[{"batb":[[2,1.95,100.79]],"ltp":2.0,"tv":438.21,"id":17336468}]}]}
{"op":"mcm","clk":"988441208","pt":1580504777440,"mc":[{"id":"1.168136214","rc":[{"batb":[[2,1.94,6.79]],"ltp":2.0,"tv":438.21,"id":17336468}]}]}
{"op":"mcm","clk":"988442748","pt":1580504797571,"mc":[{"id":"1.168136214","rc":[{"batb":[[0,1.98,10.68],[1,1.94,6.79],[2,1.93,102.2]],"ltp":2.0,"tv":438.21,"id":17336468}]}]}
{"op":"mcm","clk":"988442978","pt":1580504801019,"mc":[{"id":"1.168136214","rc":[{"batb":[[0,1.98,7.73]],"ltp":2.0,"tv":438.21,"id":17336468}]}]}
{"op":"mcm","clk":"988443072","pt":1580504802110,"mc":[{"id":"1.168136214","rc":[{"batb":[[0,2,100.25],[1,1.98,7.48],[2,1.94,6.79]],"ltp":2.0,"tv":438.21,"id":17336468}]}]}
{"op":"mcm","clk":"988445426","pt":1580504834813,"mc":[{"id":"1.168136214","rc":[{"batb":[[1,1.94,6.79],[2,1.93,102.2]],"batl":[[2,2.14,7.12]],"ltp":2.0,"tv":438.21,"id":17336468}]}]}
{"op":"mcm","clk":"988448885","pt":1580504889855,"mc":[{"id":"1.168136214","rc":[{"batl":[[0,4.3,2]],"ltp":3.1,"tv":135.65,"id":11981493}]}]}
{"op":"mcm","clk":"988451881","pt":1580504935298,"mc":[{"id":"1.168136214","rc":[{"batb":[[1,1.95,1.04],[2,1.94,6]],"ltp":2.0,"tv":438.21,"id":17336468}]}]}
{"op":"mcm","clk":"988452423","pt":1580504942317,"mc":[{"id":"1.168136214","rc":[{"batb":[[2,1.94,6.25]],"ltp":2.0,"tv":438.21,"id":17336468}]}]}
{"op":"mcm","clk":"988454499","pt":1580504968820,"mc":[{"id":"1.168136214","rc":[{"batl":[[0,4.3,4.2]],"ltp":3.1,"tv":135.65,"id":11981493}]}]}
{"op":"mcm","clk":"988454558","pt":1580504969410,"mc":[{"id":"1.168136214","rc":[{"batl":[[0,4.2,9.38],[1,4.3,4.2],[2,4.4,14.39]],"ltp":3.1,"tv":135.65,"id":11981493}]}]}
{"op":"mcm","clk":"988456107","pt":1580504991138,"mc":[{"id":"1.168136214","rc":[{"batl":[[1,4.3,2]],"ltp":3.1,"tv":135.65,"id":11981493}]}]}
{"op":"mcm","clk":"988457440","pt":1580505006923,"mc":[{"id":"1.168136214","rc":[{"trd":[[2,131.36]],"batb":[[0,2,50.25]],"ltp":2.0,"tv":538.21,"id":17336468}],"tv":686.46}]}
{"op":"mcm","clk":"988457499","pt":1580505007610,"mc":[{"id":"1.168136214","rc":[{"batb":[[0,2.02,8.53],[1,2,50.25],[2,1.95,1.04]],"ltp":2.0,"tv":538.21,"id":17336468},{"batb":[[0,3.2,5.38],[1,3.15,6.35],[2,3.1,35.78]],"ltp":3.1,"tv":135.65,"id":11981493}]}]}
{"op":"mcm","clk":"988457678","pt":1580505009841,"mc":[{"id":"1.168136214","rc":[{"batl":[[0,9.6,1.86]],"ltp":5.1,"tv":12.59,"id":12925630},{"batl":[[0,4.2,9.56]],"ltp":3.1,"tv":135.65,"id":11981493}]}]}
{"op":"mcm","clk":"988458151","pt":1580505015314,"mc":[{"id":"1.168136214","rc":[{"batl":[[0,4.1,2.18],[1,4.2,9.38]],"ltp":3.1,"tv":135.65,"id":11981493}]}]}
{"op":"mcm","clk":"988459022","pt":1580505024958,"mc":[{"id":"1.168136214","rc":[{"batl":[[2,2.2,4.33]],"ltp":2.0,"tv":538.21,"id":17336468}]}]}
{"op":"mcm","clk":"988462987","pt":1580505070054,"mc":[{"id":"1.168136214","rc":[{"batl":[[0,4,2.54],[1,4.1,2],[2,4.2,9.38]],"ltp":3.1,"tv":135.65,"id":11981493}]}]}
{"op":"mcm","clk":"988464099","pt":1580505082800,"mc":[{"id":"1.168136214","rc":[{"batl":[[2,4.4,14.39]],"ltp":3.1,"tv":135.65,"id":11981493}]}]}
{"op":"mcm","clk":"988465009","pt":1580505092897,"mc":[{"id":"1.168136214","rc":[{"batl":[[0,4.1,2.18],[1,4.4,14.39],[2,5.5,14.39]],"ltp":3.1,"tv":135.65,"id":11981493}]}]}
{"op":"mcm","clk":"988467875","pt":1580505124156,"mc":[{"id":"1.168136214","rc":[{"batl":[[0,4.3,2.18]],"ltp":3.1,"tv":135.65,"id":11981493}]}]}
{"op":"mcm","clk":"988468288","pt":1580505129155,"mc":[{"id":"1.168136214","rc":[{"batl":[[0,4.3,2]],"ltp":3.1,"tv":135.65,"id":11981493}]}]}
{"op":"mcm","clk":"988468297","pt":1580505129252,"mc":[{"id":"1.168136214","rc":[{"batl":[[0,4.3,2.18]],"ltp":3.1,"tv":135.65,"id":11981493}]}]}
{"op":"mcm","clk":"988468908","pt":1580505136882,"mc":[{"id":"1.168136214","rc":[{"batb":[[2,1.94,1.04]],"ltp":2.0,"tv":538.21,"id":17336468}]}]}
{"op":"mcm","clk":"988469316","pt":1580505142683,"mc":[{"id":"1.168136214","rc":[{"batb":[[2,1.93,1.04]],"ltp":2.0,"tv":538.21,"id":17336468}]}]}
{"op":"mcm","clk":"988469512","pt":1580505144995,"mc":[{"id":"1.168136214","rc":[{"batb":[[2,1.92,20.48]],"ltp":2.0,"tv":538.21,"id":17336468}]}]}
{"op":"mcm","clk":"988470296","pt":1580505154068,"mc":[{"id":"1.168136214","rc":[{"batl":[[0,4.2,2.43],[1,4.3,2],[2,4.4,14.39]],"ltp":3.1,"tv":135.65,"id":11981493}]}]}
{"op":"mcm","clk":"988472099","pt":1580505175919,"mc":[{"id":"1.168136214","rc":[{"batl":[[0,4.3,2.18],[1,4.4,14.39],[2,5.5,14.39]],"ltp":3.1,"tv":135.65,"id":11981493}]}]}
{"op":"mcm","clk":"988473970","pt":1580505198107,"mc":[{"id":"1.168136214","rc":[{"batl":[[0,4.2,2.43],[1,4.3,2],[2,4.4,14.39]],"ltp":3.1,"tv":135.65,"id":11981493}]}]}
{"op":"mcm","clk":"988475995","pt":1580505220630,"mc":[{"id":"1.168136214","rc":[{"batl":[[0,4.3,4.38],[1,4.4,14.39],[2,5.5,14.39]],"ltp":3.1,"tv":135.65,"id":11981493}]}]}
{"op":"mcm","clk":"988477191","pt":1580505234662,"mc":[{"id":"1.168136214","rc":[{"batl":[[0,4.2,9.56],[1,4.3,4.2],[2,4.4,14.39]],"ltp":3.1,"tv":135.65,"id":11981493}]}]}
{"op":"mcm","clk":"988477970","pt":1580505242882,"mc":[{"id":"1.168136214","rc":[{"batl":[[1,4.3,2]],"ltp":3.1,"tv":135.65,"id":11981493}]}]}
{"op":"mcm","clk":"988479488","pt":1580505260699,"mc":[{"id":"1.168136214","rc":[{"trd":[[2.02,107.26]],"batb":[[0,2,50.25],[1,1.92,20.48],[2,1.81,20.19]],"batl":[[0,2.02,1.47],[1,2.06,6.38],[2,2.08,10.95]],"ltp":2.02,"tv":555.26,"id":17336468}],"tv":703.51}]}
{"op":"mcm","clk":"988479986","pt":1580505267140,"mc":[{"id":"1.168136214","rc":[{"batl":[[0,2.06,6.38],[1,2.08,10.95],[2,2.2,4.33]],"ltp":2.02,"tv":555.26,"id":17336468}]}]}
{"op":"mcm","clk":"988479994","pt":1580505267197,"mc":[{"id":"1.168136214","rc":[{"trd":[[2,134.3]],"batb":[[0,2,48.78]],"ltp":2.0,"tv":558.2,"id":17336468}],"tv":706.45}]}
{"op":"mcm","clk":"988481525","pt":1580505284845,"mc":[{"id":"1.168136214","rc":[{"batl":[[0,4.1,2.18],[1,4.2,9.38]],"ltp":3.1,"tv":135.65,"id":11981493}]}]}
{"op":"mcm","clk":"988484251","pt":1580505316470,"mc":[{"id":"1.168136214","rc":[{"trd":[[2,140.3]],"batb":[[0,2,45.78]],"ltp":2.0,"tv":564.2,"id":17336468}],"tv":712.45}]}
{"op":"mcm","clk":"988484634","pt":1580505320875,"mc":[{"id":"1.168136214","rc":[{"batl":[[0,4,2.54],[1,4.1,2],[2,4.2,9.38]],"ltp":3.1,"tv":135.65,"id":11981493}]}]}
{"op":"mcm","clk":"988485349","pt":1580505329903,"mc":[{"id":"1.168136214","rc":[{"batl":[[2,4.4,14.39]],"ltp":3.1,"tv":135.65,"id":11981493}]}]}
{"op":"mcm","clk":"988486058","pt":1580505337917,"mc":[{"id":"1.168136214","rc":[{"batl":[[0,3.95,2.18],[1,4,2.36]],"ltp":3.1,"tv":135.65,"id":11981493}]}]}
{"op":"mcm","clk":"988486414","pt":1580505342913,"mc":[{"id":"1.168136214","rc":[{"batl":[[0,3.9,2.6],[1,3.95,2]],"ltp":3.1,"tv":135.65,"id":11981493}]}]}
{"op":"mcm","clk":"988488238","pt":1580505365328,"mc":[{"id":"1.168136214","rc":[{"batl":[[0,3.95,2.18],[1,4.4,14.39],[2,5.5,14.39]],"ltp":3.1,"tv":135.65,"id":11981493}]}]}
{"op":"mcm","clk":"988489970","pt":1580505387573,"mc":[{"id":"1.168136214","rc":[{"batl":[[0,3.9,2.6],[1,3.95,2],[2,4.4,14.39]],"ltp":3.1,"tv":135.65,"id":11981493}]}]}
{"op":"mcm","clk":"988490277","pt":1580505391681,"mc":[{"id":"1.168136214","rc":[{"batl":[[0,3.85,2.18],[1,3.9,2.42]],"ltp":3.1,"tv":135.65,"id":11981493}]}]}
{"op":"mcm","clk":"988491563","pt":1580505410108,"mc":[{"id":"1.168136214","rc":[{"batl":[[0,3.8,2.67],[1,3.85,2]],"ltp":3.1,"tv":135.65,"id":11981493}]}]}
{"op":"mcm","clk":"988493117","pt":1580505432113,"mc":[{"id":"1.168136214","rc":[{"batb":[[1,1.93,60.79],[2,1.92,19.69]],"ltp":2.0,"tv":564.2,"id":17336468},{"batl":[[0,3.85,2.18],[1,4.3,2.2]],"ltp":3.1,"tv":135.65,"id":11981493}]}]}
{"op":"mcm","clk":"988493811","pt":1580505440621,"mc":[{"id":"1.168136214","rc":[{"batb":[[1,1.94,6.79],[2,1.93,60]],"ltp":2.0,"tv":564.2,"id":17336468}]}]}
{"op":"mcm","clk":"988494029","pt":1580505443660,"mc":[{"id":"1.168136214","rc":[{"batl":[[1,4.2,9.38],[2,4.3,2.2]],"ltp":3.1,"tv":135.65,"id":11981493}]}]}
{"op":"mcm","clk":"988494116","pt":1580505444857,"mc":[{"id":"1.168136214","rc":[{"batl":[[0,4.1,2.18]],"ltp":3.1,"tv":135.65,"id":11981493}]}]}
{"op":"mcm","clk":"988504269","pt":1580505454475,"mc":[{"id":"1.168136214","rc":[{"batl":[[0,4,2.54],[1,4.1,2],[2,4.2,9.38]],"ltp":3.1,"tv":135.65,"id":11981493}]}]}
{"op":"mcm","clk":"988504632","pt":1580505459688,"mc":[{"id":"1.168136214","rc":[{"trd":[[2,150.3]],"batb":[[0,2,40.78]],"ltp":2.0,"tv":574.2,"id":17336468}],"tv":722.45}]}
{"op":"mcm","clk":"988504843","pt":1580505462714,"mc":[{"id":"1.168136214","rc":[{"batl":[[2,4.4,14.39]],"ltp":3.1,"tv":135.65,"id":11981493}]}]}
{"op":"mcm","clk":"988505856","pt":1580505477116,"mc":[{"id":"1.168136214","rc":[{"batl":[[0,4.1,2.18],[1,4.3,2.2]],"ltp":3.1,"tv":135.65,"id":11981493}]}]}
{"op":"mcm","clk":"988506161","pt":1580505482006,"mc":[{"id":"1.168136214","rc":[{"batl":[[1,4.2,9.38],[2,4.3,2.2]],"ltp":3.1,"tv":135.65,"id":11981493}]}]}
{"op":"mcm","clk":"988507366","pt":1580505499826,"mc":[{"id":"1.168136214","rc":[{"batl":[[2,4.4,14.39]],"ltp":3.1,"tv":135.65,"id":11981493}]}]}
{"op":"mcm","clk":"988508962","pt":1580505522682,"mc":[{"id":"1.168136214","rc":[{"batl":[[0,4,2.54],[1,4.1,2],[2,4.2,9.38]],"ltp":3.1,"tv":135.65,"id":11981493}]}]}
{"op":"mcm","clk":"988510107","pt":1580505538368,"mc":[{"id":"1.168136214","rc":[{"batl":[[2,4.4,14.39]],"ltp":3.1,"tv":135.65,"id":11981493}]}]}
{"op":"mcm","clk":"988510558","pt":1580505544798,"mc":[{"id":"1.168136214","rc":[{"batl":[[0,4.1,2.18],[1,4.4,14.39],[2,5.5,14.39]],"ltp":3.1,"tv":135.65,"id":11981493}]}]}
{"op":"mcm","clk":"988511140","pt":1580505552407,"mc":[{"id":"1.168136214","rc":[{"batl":[[0,4.3,2.18]],"ltp":3.1,"tv":135.65,"id":11981493}]}]}
{"op":"mcm","clk":"988512141","pt":1580505567044,"mc":[{"id":"1.168136214","rc":[{"batl":[[0,4.2,2.43],[1,4.3,2],[2,4.4,14.39]],"ltp":3.1,"tv":135.65,"id":11981493}]}]}
{"op":"mcm","clk":"988513827","pt":1580505590066,"mc":[{"id":"1.168136214","rc":[{"batl":[[0,4.3,2.18],[1,4.4,14.39],[2,5.5,14.39]],"ltp":3.1,"tv":135.65,"id":11981493}]}]}
{"op":"mcm","clk":"988513834","pt":1580505590169,"mc":[{"id":"1.168136214","rc":[{"batl":[[0,4.3,4.38]],"ltp":3.1,"tv":135.65,"id":11981493}]}]}
{"op":"mcm","clk":"988514190","pt":1580505594950,"mc":[{"id":"1.168136214","rc":[{"batl":[[0,4.2,9.56],[1,4.3,4.2],[2,4.4,14.39]],"ltp":3.1,"tv":135.65,"id":11981493}]}]}
{"op":"mcm","clk":"988515099","pt":1580505606000,"mc":[{"id":"1.168136214","rc":[{"batl":[[0,4.1,2.18],[1,4.2,9.38],[2,4.3,2.2]],"ltp":3.1,"tv":135.65,"id":11981493}]}]}
{"op":"mcm","clk":"988515672","pt":1580505612629,"mc":[{"id":"1.168136214","rc":[{"batl":[[0,4,2.54],[1,4.1,2],[2,4.2,9.38]],"ltp":3.1,"tv":135.65,"id":11981493}]}]}
{"op":"mcm","clk":"988515801","pt":1580505613939,"mc":[{"id":"1.168136214","rc":[{"batl":[[2,4.4,14.39]],"ltp":3.1,"tv":135.65,"id":11981493}]}]}
{"op":"mcm","clk":"988517540","pt":1580505635329,"mc":[{"id":"1.168136214","rc":[{"batl":[[0,4.1,2.18],[1,4.3,2.2]],"ltp":3.1,"tv":135.65,"id":11981493}]}]}
{"op":"mcm","clk":"988518834","pt":1580505651878,"mc":[{"id":"1.168136214","rc":[{"batl":[[1,4.2,9.38],[2,4.3,2.2]],"ltp":3.1,"tv":135.65,"id":11981493}]}]}
{"op":"mcm","clk":"988519268","pt":1580505657874,"mc":[{"id":"1.168136214","rc":[{"batl":[[0,4,2.54],[1,4.1,2],[2,4.2,9.38]],"ltp":3.1,"tv":135.65,"id":11981493}]}]}
{"op":"mcm","clk":"988520222","pt":1580505670915,"mc":[{"id":"1.168136214","rc":[{"batl":[[2,4.4,14.39]],"ltp":3.1,"tv":135.65,"id":11981493}]}]}
{"op":"mcm","clk":"988520889","pt":1580505680118,"mc":[{"id":"1.168136214","rc":[{"batl":[[0,4.1,2.18],[1,4.3,2.2]],"ltp":3.1,"tv":135.65,"id":11981493}]}]}
{"op":"mcm","clk":"988521598","pt":1580505690020,"mc":[{"id":"1.168136214","rc":[{"batl":[[1,4.2,9.38],[2,4.3,2.2]],"ltp":3.1,"tv":135.65,"id":11981493}]}]}
{"op":"mcm","clk":"988522535","pt":1580505702262,"mc":[{"id":"1.168136214","rc":[{"batl":[[0,4,2.54],[1,4.1,2],[2,4.2,9.38]],"ltp":3.1,"tv":135.65,"id":11981493}]}]}
{"op":"mcm","clk":"988523098","pt":1580505709647,"mc":[{"id":"1.168136214","rc":[{"batl":[[2,4.4,14.39]],"ltp":3.1,"tv":135.65,"id":11981493}]}]}
{"op":"mcm","clk":"988523338","pt":1580505712769,"mc":[{"id":"1.168136214","rc":[{"batl":[[0,3.95,2.18],[1,4,2.36]],"ltp":3.1,"tv":135.65,"id":11981493}]}]}
{"op":"mcm","clk":"988524231","pt":1580505725084,"mc":[{"id":"1.168136214","rc":[{"batl":[[0,3.9,2.6],[1,3.95,2]],"ltp":3.1,"tv":135.65,"id":11981493}]}]}
{"op":"mcm","clk":"988525859","pt":1580505747017,"mc":[{"id":"1.168136214","rc":[{"batl":[[0,3.95,2.18],[1,4.3,2.2]],"ltp":3.1,"tv":135.65,"id":11981493}]}]}
{"op":"mcm","clk":"988525999","pt":1580505749122,"mc":[{"id":"1.168136214","rc":[{"batl":[[1,4.2,9.38],[2,4.3,2.2]],"ltp":3.1,"tv":135.65,"id":11981493}]}]}
{"op":"mcm","clk":"988527131","pt":1580505766648,"mc":[{"id":"1.168136214","rc":[{"batl":[[0,4.1,2.18]],"ltp":3.1,"tv":135.65,"id":11981493}]}]}
{"op":"mcm","clk":"988527331","pt":1580505769368,"mc":[{"id":"1.168136214","rc":[{"batl":[[0,4,2.54],[1,4.1,2],[2,4.2,9.38]],"ltp":3.1,"tv":135.65,"id":11981493}]}]}
{"op":"mcm","clk":"988528559","pt":1580505788124,"mc":[{"id":"1.168136214","rc":[{"batl":[[2,4.4,14.39]],"ltp":3.1,"tv":135.65,"id":11981493}]}]}
{"op":"mcm","clk":"988528868","pt":1580505792347,"mc":[{"id":"1.168136214","rc":[{"batl":[[0,4.1,2.18],[1,4.3,2.2]],"ltp":3.1,"tv":135.65,"id":11981493}]}]}
{"op":"mcm","clk":"988529802","pt":1580505807149,"mc":[{"id":"1.168136214","rc":[{"batl":[[1,4.2,9.38],[2,4.3,2.2]],"ltp":3.1,"tv":135.65,"id":11981493}]}]}
{"op":"mcm","clk":"988530284","pt":1580505814478,"mc":[{"id":"1.168136214","rc":[{"batl":[[0,4,2.54],[1,4.1,2],[2,4.2,9.38]],"ltp":3.1,"tv":135.65,"id":11981493}]}]}
{"op":"mcm","clk":"988531095","pt":1580505826860,"mc":[{"id":"1.168136214","rc":[{"batl":[[2,4.4,14.39]],"ltp":3.1,"tv":135.65,"id":11981493}]}]}
{"op":"mcm","clk":"988531775","pt":1580505837094,"mc":[{"id":"1.168136214","rc":[{"batl":[[0,4.1,2.18],[1,4.3,2.2]],"ltp":3.1,"tv":135.65,"id":11981493}]}]}
{"op":"mcm","clk":"988532342","pt":1580505845910,"mc":[{"id":"1.168136214","rc":[{"batl":[[1,4.2,9.38],[2,4.3,2.2]],"ltp":3.1,"tv":135.65,"id":11981493}]}]}
{"op":"mcm","clk":"988533204","pt":1580505859152,"mc":[{"id":"1.168136214","rc":[{"batl":[[2,4.4,14.39]],"ltp":3.1,"tv":135.65,"id":11981493}]}]}
{"op":"mcm","clk":"988533249","pt":1580505859628,"mc":[{"id":"1.168136214","rc":[{"batl":[[0,4,2.54],[1,4.1,2],[2,4.2,9.38]],"ltp":3.1,"tv":135.65,"id":11981493}]}]}
{"op":"mcm","clk":"988533580","pt":1580505864931,"mc":[{"id":"1.168136214","rc":[{"batl":[[2,4.4,14.39]],"ltp":3.1,"tv":135.65,"id":11981493}]}]}
{"op":"mcm","clk":"988534139","pt":1580505873980,"mc":[{"id":"1.168136214","rc":[{"batl":[[0,3.95,2.18],[1,4,2.36]],"ltp":3.1,"tv":135.65,"id":11981493}]}]}
{"op":"mcm","clk":"988534598","pt":1580505881686,"mc":[{"id":"1.168136214","rc":[{"batl":[[0,3.9,2.6],[1,3.95,2]],"ltp":3.1,"tv":135.65,"id":11981493}]}]}
{"op":"mcm","clk":"988535958","pt":1580505904315,"mc":[{"id":"1.168136214","rc":[{"batl":[[0,3.95,2.18],[1,4.3,2.2]],"ltp":3.1,"tv":135.65,"id":11981493}]}]}
{"op":"mcm","clk":"988536995","pt":1580505922026,"mc":[{"id":"1.168136214","rc":[{"batl":[[1,4.2,9.38],[2,4.3,2.2]],"ltp":3.1,"tv":135.65,"id":11981493}]}]}
{"op":"mcm","clk":"988537281","pt":1580505927116,"mc":[{"id":"1.168136214","rc":[{"batl":[[0,3.9,2.6],[2,4.4,14.39]],"ltp":3.1,"tv":135.65,"id":11981493}]}]}
{"op":"mcm","clk":"988537346","pt":1580505928049,"mc":[{"id":"1.168136214","rc":[{"batl":[[1,4.1,2],[2,4.2,9.38]],"ltp":3.1,"tv":135.65,"id":11981493}]}]}
{"op":"mcm","clk":"988538115","pt":1580505940954,"mc":[{"id":"1.168136214","rc":[{"batl":[[2,4.4,14.39]],"ltp":3.1,"tv":135.65,"id":11981493}]}]}
{"op":"mcm","clk":"988538571","pt":1580505949381,"mc":[{"id":"1.168136214","rc":[{"batl":[[0,4.1,2.18],[1,4.3,2.2]],"ltp":3.1,"tv":135.65,"id":11981493}]}]}
{"op":"mcm","clk":"988539165","pt":1580505960868,"mc":[{"id":"1.168136214","rc":[{"batl":[[1,4.2,9.38],[2,4.3,2.2]],"ltp":3.1,"tv":135.65,"id":11981493}]}]}
{"op":"mcm","clk":"988539799","pt":1580505971798,"mc":[{"id":"1.168136214","rc":[{"batl":[[0,4,2.54],[1,4.1,2],[2,4.2,9.38]],"ltp":3.1,"tv":135.65,"id":11981493}]}]}
{"op":"mcm","clk":"988540280","pt":1580505980021,"mc":[{"id":"1.168136214","rc":[{"batl":[[2,4.4,14.39]],"ltp":3.1,"tv":135.65,"id":11981493}]}]}
{"op":"mcm","clk":"988540359","pt":1580505981117,"mc":[{"id":"1.168136214","rc":[{"batl":[[0,3.95,2.18],[1,4,2.36]],"ltp":3.1,"tv":135.65,"id":11981493}]}]}
{"op":"mcm","clk":"988541138","pt":1580505994557,"mc":[{"id":"1.168136214","rc":[{"batl":[[0,3.9,2.6],[1,3.95,2]],"ltp":3.1,"tv":135.65,"id":11981493}]}]}
{"op":"mcm","clk":"988542580","pt":1580506017075,"mc":[{"id":"1.168136214","rc":[{"batl":[[0,3.95,2.18],[1,4.2,9.38],[2,4.3,2.2]],"ltp":3.1,"tv":135.65,"id":11981493}]}]}
{"op":"mcm","clk":"988543613","pt":1580506033918,"mc":[{"id":"1.168136214","rc":[{"batl":[[0,4.1,2.18]],"ltp":3.1,"tv":135.65,"id":11981493}]}]}
{"op":"mcm","clk":"988543959","pt":1580506039311,"mc":[{"id":"1.168136214","rc":[{"batl":[[0,4,2.54],[1,4.1,2],[2,4.2,9.38]],"ltp":3.1,"tv":135.65,"id":11981493}]}]}
{"op":"mcm","clk":"988544543","pt":1580506049096,"mc":[{"id":"1.168136214","rc":[{"trd":[[2,170.3]],"batb":[[0,2,30.78]],"ltp":2.0,"tv":594.2,"id":17336468}],"tv":742.45}]}
{"op":"mcm","clk":"988544883","pt":1580506055073,"mc":[{"id":"1.168136214","rc":[{"batl":[[2,4.4,14.39]],"ltp":3.1,"tv":135.65,"id":11981493}]}]}
{"op":"mcm","clk":"988545307","pt":1580506062013,"mc":[{"id":"1.168136214","rc":[{"batl":[[0,4.1,2.18],[1,4.3,2.2]],"ltp":3.1,"tv":135.65,"id":11981493}]}]}
{"op":"mcm","clk":"988546044","pt":1580506074121,"mc":[{"id":"1.168136214","rc":[{"batl":[[1,4.2,9.38],[2,4.3,2.2]],"ltp":3.1,"tv":135.65,"id":11981493}]}]}
{"op":"mcm","clk":"988546614","pt":1580506083739,"mc":[{"id":"1.168136214","rc":[{"batl":[[0,4,2.54],[1,4.1,2],[2,4.2,9.38]],"ltp":3.1,"tv":135.65,"id":11981493}]}]}
{"op":"mcm","clk":"988547260","pt":1580506093839,"mc":[{"id":"1.168136214","rc":[{"batl":[[2,4.4,14.39]],"ltp":3.1,"tv":135.65,"id":11981493}]}]}
{"op":"mcm","clk":"988548109","pt":1580506105802,"mc":[{"id":"1.168136214","rc":[{"batl":[[0,4.1,2.18],[1,4.3,2.2]],"ltp":3.1,"tv":135.65,"id":11981493}]}]}
{"op":"mcm","clk":"988548489","pt":1580506112400,"mc":[{"id":"1.168136214","rc":[{"batl":[[1,4.2,9.38],[2,4.3,2.2]],"ltp":3.1,"tv":135.65,"id":11981493}]}]}
{"op":"mcm","clk":"988549519","pt":1580506127613,"mc":[{"id":"1.168136214","rc":[{"batl":[[0,4,2.54],[1,4.1,2],[2,4.2,9.38]],"ltp":3.1,"tv":135.65,"id":11981493}]}]}
{"op":"mcm","clk":"988549787","pt":1580506131696,"mc":[{"id":"1.168136214","rc":[{"batl":[[2,4.4,14.39]],"ltp":3.1,"tv":135.65,"id":11981493}]}]}
{"op":"mcm","clk":"988550399","pt":1580506140933,"mc":[{"id":"1.168136214","rc":[{"batl":[[0,3.95,2.18],[1,4,2.36]],"ltp":3.1,"tv":135.65,"id":11981493}]}]}
{"op":"mcm","clk":"988550702","pt":1580506145149,"mc":[{"id":"1.168136214","rc":[{"batl":[[0,3.95,2]],"ltp":3.1,"tv":135.65,"id":11981493}]}]}
{"op":"mcm","clk":"988550774","pt":1580506146145,"mc":[{"id":"1.168136214","rc":[{"batl":[[0,3.95,2.18]],"ltp":3.1,"tv":135.65,"id":11981493}]}]}
{"op":"mcm","clk":"988551055","pt":1580506150648,"mc":[{"id":"1.168136214","rc":[{"batl":[[0,3.9,2.6],[1,3.95,2]],"ltp":3.1,"tv":135.65,"id":11981493}]}]}
{"op":"mcm","clk":"988552555","pt":1580506172965,"mc":[{"id":"1.168136214","rc":[{"batl":[[0,3.95,2.18],[1,4.3,2.2]],"ltp":3.1,"tv":135.65,"id":11981493}]}]}
{"op":"mcm","clk":"988553537","pt":1580506188913,"mc":[{"id":"1.168136214","rc":[{"batl":[[1,4.2,9.38],[2,4.3,2.2]],"ltp":3.1,"tv":135.65,"id":11981493}]}]}
{"op":"mcm","clk":"988553921","pt":1580506194602,"mc":[{"id":"1.168136214","rc":[{"batl":[[0,4.1,2.18]],"ltp":3.1,"tv":135.65,"id":11981493}]}]}
{"op":"mcm","clk":"988554007","pt":1580506195898,"mc":[{"id":"1.168136214","rc":[{"batl":[[0,4,2.54],[1,4.1,2],[2,4.2,9.38]],"ltp":3.1,"tv":135.65,"id":11981493}]}]}
{"op":"mcm","clk":"988554928","pt":1580506208495,"mc":[{"id":"1.168136214","rc":[{"batl":[[2,4.4,14.39]],"ltp":3.1,"tv":135.65,"id":11981493}]}]}
{"op":"mcm","clk":"988555647","pt":1580506217986,"mc":[{"id":"1.168136214","rc":[{"batl":[[0,4.1,2.18],[1,4.4,14.39],[2,5.5,14.39]],"ltp":3.1,"tv":135.65,"id":11981493}]}]}
{"op":"mcm","clk":"988555697","pt":1580506218811,"mc":[{"id":"1.168136214","rc":[{"batl":[[1,4.3,2.2],[2,4.4,14.39]],"ltp":3.1,"tv":135.65,"id":11981493}]}]}
{"op":"mcm","clk":"988556353","pt":1580506227905,"mc":[{"id":"1.168136214","rc":[{"batl":[[1,4.2,9.38],[2,4.3,2.2]],"ltp":3.1,"tv":135.65,"id":11981493}]}]}
{"op":"mcm","clk":"988557335","pt":1580506240631,"mc":[{"id":"1.168136214","rc":[{"batl":[[0,4,2.54],[1,4.1,2],[2,4.2,9.38]],"ltp":3.1,"tv":135.65,"id":11981493}]}]}
{"op":"mcm","clk":"988557806","pt":1580506247048,"mc":[{"id":"1.168136214","rc":[{"batl":[[2,4.4,14.39]],"ltp":3.1,"tv":135.65,"id":11981493}]}]}
{"op":"mcm","clk":"988557897","pt":1580506248555,"mc":[{"id":"1.168136214","rc":[{"batl":[[0,3.95,2.18],[1,4,2.36]],"ltp":3.1,"tv":135.65,"id":11981493}]}]}
{"op":"mcm","clk":"988559176","pt":1580506262939,"mc":[{"id":"1.168136214","rc":[{"batl":[[0,3.9,2.6],[1,3.95,2]],"ltp":3.1,"tv":135.65,"id":11981493}]}]}
{"op":"mcm","clk":"988560240","pt":1580506280959,"mc":[{"id":"1.168136214","rc":[{"trd":[[2,174.3]],"batb":[[0,2,28.78]],"ltp":2.0,"tv":598.2,"id":17336468}],"tv":746.45}]}
{"op":"mcm","clk":"988560478","pt":1580506284726,"mc":[{"id":"1.168136214","rc":[{"batl":[[0,3.95,2.18],[1,4.3,2.2]],"ltp":3.1,"tv":135.65,"id":11981493}]}]}
{"op":"mcm","clk":"988560561","pt":1580506285936,"mc":[{"id":"1.168136214","rc":[{"batl":[[1,4.2,9.38],[2,4.3,2.2]],"ltp":3.1,"tv":135.65,"id":11981493}]}]}
{"op":"mcm","clk":"988561705","pt":1580506303971,"mc":[{"id":"1.168136214","rc":[{"batl":[[0,4.1,2.18]],"ltp":3.1,"tv":135.65,"id":11981493}]}]}
{"op":"mcm","clk":"988561912","pt":1580506307074,"mc":[{"id":"1.168136214","rc":[{"batl":[[2,4.4,14.39]],"ltp":3.1,"tv":135.65,"id":11981493}]}]}
{"op":"mcm","clk":"988561926","pt":1580506307277,"mc":[{"id":"1.168136214","rc":[{"batl":[[0,4,2.54],[1,4.1,2],[2,4.2,9.38]],"ltp":3.1,"tv":135.65,"id":11981493}]}]}
{"op":"mcm","clk":"988562702","pt":1580506319376,"mc":[{"id":"1.168136214","rc":[{"batb":[[0,2,30.78]],"ltp":2.0,"tv":598.2,"id":17336468}]}]}
{"op":"mcm","clk":"988563026","pt":1580506324475,"mc":[{"id":"1.168136214","rc":[{"batl":[[2,4.4,14.39]],"ltp":3.1,"tv":135.65,"id":11981493}]}]}
{"op":"mcm","clk":"988563422","pt":1580506329713,"mc":[{"id":"1.168136214","rc":[{"batl":[[0,4.1,2.18],[1,4.3,2.2]],"ltp":3.1,"tv":135.65,"id":11981493}]}]}
{"op":"mcm","clk":"988564412","pt":1580506344031,"mc":[{"id":"1.168136214","rc":[{"batl":[[1,4.2,9.38],[2,4.3,2.2]],"ltp":3.1,"tv":135.65,"id":11981493}]}]}
{"op":"mcm","clk":"988564992","pt":1580506351714,"mc":[{"id":"1.168136214","rc":[{"batl":[[0,4,2.54],[1,4.1,2],[2,4.2,9.38]],"ltp":3.1,"tv":135.65,"id":11981493}]}]}
{"op":"mcm","clk":"988574664","pt":1580506355156,"mc":[{"id":"1.168136214","rc":[{"batb":[[0,2,28.78]],"ltp":2.0,"tv":598.2,"id":17336468}]}]}
{"op":"mcm","clk":"988575302","pt":1580506363413,"mc":[{"id":"1.168136214","rc":[{"batl":[[2,4.4,14.39]],"ltp":3.1,"tv":135.65,"id":11981493}]}]}
{"op":"mcm","clk":"988576184","pt":1580506374949,"mc":[{"id":"1.168136214","rc":[{"batl":[[0,4.1,2.18],[1,4.3,2.2]],"ltp":3.1,"tv":135.65,"id":11981493}]}]}
{"op":"mcm","clk":"988576785","pt":1580506383062,"mc":[{"id":"1.168136214","rc":[{"batl":[[1,4.2,9.38],[2,4.3,2.2]],"ltp":3.1,"tv":135.65,"id":11981493}]}]}
{"op":"mcm","clk":"988577757","pt":1580506396784,"mc":[{"id":"1.168136214","rc":[{"batl":[[0,4,2.54],[1,4.1,2],[2,4.2,9.38]],"ltp":3.1,"tv":135.65,"id":11981493}]}]}
{"op":"mcm","clk":"988578103","pt":1580506401494,"mc":[{"id":"1.168136214","rc":[{"batl":[[2,4.4,14.39]],"ltp":3.1,"tv":135.65,"id":11981493}]}]}
{"op":"mcm","clk":"988578902","pt":1580506411984,"mc":[{"id":"1.168136214","rc":[{"batl":[[0,3.95,2.18],[1,4,2.36]],"ltp":3.1,"tv":135.65,"id":11981493}]}]}
{"op":"mcm","clk":"988579475","pt":1580506419820,"mc":[{"id":"1.168136214","rc":[{"batl":[[0,3.9,2.6],[1,3.95,2]],"ltp":3.1,"tv":135.65,"id":11981493}]}]}
{"op":"mcm","clk":"988581667","pt":1580506448048,"mc":[{"id":"1.168136214","rc":[{"batl":[[0,3.95,2.18],[1,4.3,2.2]],"ltp":3.1,"tv":135.65,"id":11981493}]}]}
{"op":"mcm","clk":"988582462","pt":1580506459075,"mc":[{"id":"1.168136214","rc":[{"batl":[[1,4.2,9.38],[2,4.3,2.2]],"ltp":3.1,"tv":135.65,"id":11981493}]}]}
{"op":"mcm","clk":"988582978","pt":1580506466586,"mc":[{"id":"1.168136214","rc":[{"batl":[[0,4.1,2.18]],"ltp":3.1,"tv":135.65,"id":11981493}]}]}
{"op":"mcm","clk":"988583109","pt":1580506468086,"mc":[{"id":"1.168136214","rc":[{"batl":[[0,4.1,2]],"ltp":3.1,"tv":135.65,"id":11981493}]}]}
{"op":"mcm","clk":"988583141","pt":1580506468462,"mc":[{"id":"1.168136214","rc":[{"batl":[[0,4.1,2.18]],"ltp":3.1,"tv":135.65,"id":11981493}]}]}
{"op":"mcm","clk":"988583262","pt":1580506469950,"mc":[{"id":"1.168136214","rc":[{"batl":[[2,4.4,14.39]],"ltp":3.1,"tv":135.65,"id":11981493}]}]}
{"op":"mcm","clk":"988583336","pt":1580506470893,"mc":[{"id":"1.168136214","rc":[{"batl":[[0,4,2.54],[1,4.1,2],[2,4.2,9.38]],"ltp":3.1,"tv":135.65,"id":11981493}]}]}
{"op":"mcm","clk":"988583853","pt":1580506477983,"mc":[{"id":"1.168136214","rc":[{"batl":[[2,4.4,14.39]],"ltp":3.1,"tv":135.65,"id":11981493}]}]}
{"op":"mcm","clk":"988584827","pt":1580506493119,"mc":[{"id":"1.168136214","rc":[{"batl":[[0,4.1,2.18],[1,4.3,2.2]],"ltp":3.1,"tv":135.65,"id":11981493}]}]}
{"op":"mcm","clk":"988585174","pt":1580506497001,"mc":[{"id":"1.168136214","rc":[{"batl":[[1,4.2,9.38],[2,4.3,2.2]],"ltp":3.1,"tv":135.65,"id":11981493}]}]}
{"op":"mcm","clk":"988586578","pt":1580506515909,"mc":[{"id":"1.168136214","rc":[{"batl":[[0,4,2.54],[1,4.1,2],[2,4.2,9.38]],"ltp":3.1,"tv":135.65,"id":11981493}]}]}
{"op":"mcm","clk":"988587963","pt":1580506534766,"mc":[{"id":"1.168136214","rc":[{"batl":[[2,4.4,14.39]],"ltp":3.1,"tv":135.65,"id":11981493}]}]}
{"op":"mcm","clk":"988588221","pt":1580506538091,"mc":[{"id":"1.168136214","rc":[{"batl":[[0,4.1,2.18],[1,4.3,2.2]],"ltp":3.1,"tv":135.65,"id":11981493}]}]}
{"op":"mcm","clk":"988589325","pt":1580506554182,"mc":[{"id":"1.168136214","rc":[{"batl":[[1,4.2,9.38],[2,4.3,2.2]],"ltp":3.1,"tv":135.65,"id":11981493}]}]}
{"op":"mcm","clk":"988589825","pt":1580506560581,"mc":[{"id":"1.168136214","rc":[{"batl":[[0,4,2.54],[1,4.1,2],[2,4.2,9.38]],"ltp":3.1,"tv":135.65,"id":11981493}]}]}
{"op":"mcm","clk":"988590783","pt":1580506573430,"mc":[{"id":"1.168136214","rc":[{"batl":[[2,4.4,14.39]],"ltp":3.1,"tv":135.65,"id":11981493}]}]}
{"op":"mcm","clk":"988590867","pt":1580506574630,"mc":[{"id":"1.168136214","rc":[{"batl":[[0,3.95,2.18],[1,4,2.36]],"ltp":3.1,"tv":135.65,"id":11981493}]}]}
{"op":"mcm","clk":"988591122","pt":1580506578117,"mc":[{"id":"1.168136214","rc":[{"batl":[[0,3.95,2]],"ltp":3.1,"tv":135.65,"id":11981493}]}]}
{"op":"mcm","clk":"988591128","pt":1580506578223,"mc":[{"id":"1.168136214","rc":[{"batl":[[0,3.95,2.18]],"ltp":3.1,"tv":135.65,"id":11981493}]}]}
{"op":"mcm","clk":"988591439","pt":1580506582837,"mc":[{"id":"1.168136214","rc":[{"batl":[[0,3.9,2.6],[1,3.95,2]],"ltp":3.1,"tv":135.65,"id":11981493}]}]}
{"op":"mcm","clk":"988593019","pt":1580506605038,"mc":[{"id":"1.168136214","rc":[{"batl":[[0,3.95,2.18],[1,4.3,2.2]],"ltp":3.1,"tv":135.65,"id":11981493}]}]}
{"op":"mcm","clk":"988593479","pt":1580506611181,"mc":[{"id":"1.168136214","rc":[{"batl":[[1,4.2,9.38],[2,4.3,2.2]],"ltp":3.1,"tv":135.65,"id":11981493}]}]}
{"op":"mcm","clk":"988593587","pt":1580506613081,"mc":[{"id":"1.168136214","rc":[{"batl":[[0,3.6,7],[1,3.95,2.18],[2,4.2,9.38]],"ltp":3.1,"tv":135.65,"id":11981493}]}]}
{"op":"mcm","clk":"988594128","pt":1580506621485,"mc":[{"id":"1.168136214","rc":[{"batl":[[1,3.75,11],[2,3.95,2.18]],"ltp":3.1,"tv":135.65,"id":11981493}]}]}
{"op":"mcm","clk":"988594628","pt":1580506628093,"mc":[{"id":"1.168136214","rc":[{"batl":[[0,3.55,2.66],[1,3.6,7],[2,3.75,11]],"ltp":3.1,"tv":135.65,"id":11981493}]}]}
{"op":"mcm","clk":"988594771","pt":1580506630078,"mc":[{"id":"1.168136214","rc":[{"batl":[[2,3.7,7]],"ltp":3.1,"tv":135.65,"id":11981493}]}]}
{"op":"mcm","clk":"988598209","pt":1580506682156,"mc":[{"id":"1.168136214","rc":[{"batl":[[0,3.5,2],[1,3.55,2.66],[2,3.6,7]],"ltp":3.1,"tv":135.65,"id":11981493}]}]}
{"op":"mcm","clk":"988604805","pt":1580506779669,"mc":[{"id":"1.168136214","rc":[{"batb":[[0,5.1,3.38],[1,5,5.68],[2,4.9,1.98]],"ltp":5.1,"tv":12.59,"id":12925630}]}]}
{"op":"mcm","clk":"988606974","pt":1580506812356,"mc":[{"id":"1.168136214","rc":[{"batb":[[1,5,1.68]],"ltp":5.1,"tv":12.59,"id":12925630}]}]}
{"op":"mcm","clk":"988610402","pt":1580506860901,"mc":[{"id":"1.168136214","rc":[{"trd":[[2,194.3]],"batb":[[0,2,18.78]],"ltp":2.0,"tv":618.2,"id":17336468}],"tv":766.45}]}
{"op":"mcm","clk":"988656275","pt":1580507473859,"mc":[{"id":"1.168136214","rc":[{"trd":[[2,198.3]],"batb":[[0,2,16.78]],"ltp":2.0,"tv":622.2,"id":17336468}],"tv":770.45}]}
{"op":"mcm","clk":"988668203","pt":1580507740388,"mc":[{"id":"1.168136214","rc":[{"trd":[[3.2,10.76]],"batb":[[0,3.15,6.35],[1,3.1,35.78],[2,3.05,32]],"batl":[[0,3.2,19.62],[1,3.5,2],[2,3.55,2.66]],"ltp":3.2,"tv":146.42,"id":11981493}],"tv":781.22}]}
{"op":"mcm","clk":"988668488","pt":1580507746537,"mc":[{"id":"1.168136214","rc":[{"batl":[[0,3.2,22.57],[2,3.6,7]],"ltp":3.2,"tv":146.42,"id":11981493}]}]}
{"op":"mcm","clk":"988669135","pt":1580507761920,"mc":[{"id":"1.168136214","rc":[{"batb":[[0,3.1,35.78],[1,3.05,32],[2,3,56]],"ltp":3.2,"tv":146.42,"id":11981493}]}]}
{"op":"mcm","clk":"988669179","pt":1580507762953,"mc":[{"id":"1.168136214","rc":[{"batl":[[1,3.6,7],[2,3.7,7]],"ltp":3.2,"tv":146.42,"id":11981493}]}]}
{"op":"mcm","clk":"988670929","pt":1580507797596,"mc":[{"id":"1.168136214","rc":[{"batl":[[0,9,3],[1,9.6,1.86],[2,11,9.51]],"ltp":5.1,"tv":12.59,"id":12925630}]}]}
{"op":"mcm","clk":"988671061","pt":1580507800576,"mc":[{"id":"1.168136214","rc":[{"batl":[[0,9,3.18],[1,9.6,1.68]],"ltp":5.1,"tv":12.59,"id":12925630}]}]}
{"op":"mcm","clk":"988671552","pt":1580507811972,"mc":[{"id":"1.168136214","rc":[{"batl":[[0,9,3.75],[2,11,9]],"ltp":5.1,"tv":12.59,"id":12925630}]}]}
{"op":"mcm","clk":"988672282","pt":1580507831415,"mc":[{"id":"1.168136214","rc":[{"batl":[[0,8.8,2.43],[1,9,3]],"ltp":5.1,"tv":12.59,"id":12925630}]}]}
{"op":"mcm","clk":"988672851","pt":1580507845850,"mc":[{"id":"1.168136214","rc":[{"batl":[[0,8.6,4.76],[1,8.8,2.25],[2,9,3]],"ltp":5.1,"tv":12.59,"id":12925630}]}]}
{"op":"mcm","clk":"988673598","pt":1580507864860,"mc":[{"id":"1.168136214","rc":[{"batl":[[0,8.4,1.86],[1,8.6,4.58],[2,9,3.57]],"ltp":5.1,"tv":12.59,"id":12925630}]}]}
{"op":"mcm","clk":"988673643","pt":1580507866047,"mc":[{"id":"1.168136214","rc":[{"batl":[[2,9,3]],"ltp":5.1,"tv":12.59,"id":12925630}]}]}
{"op":"mcm","clk":"988673657","pt":1580507866356,"mc":[{"id":"1.168136214","rc":[{"batl":[[0,8.4,2.46]],"ltp":5.1,"tv":12.59,"id":12925630}]}]}
{"op":"mcm","clk":"988674426","pt":1580507883812,"mc":[{"id":"1.168136214","rc":[{"batl":[[1,9,3],[2,11,9]],"ltp":5.1,"tv":12.59,"id":12925630}]}]}
{"op":"mcm","clk":"988680651","pt":1580508041853,"mc":[{"id":"1.168136214","rc":[{"trd":[[5.2,1.4]],"batb":[[0,5.1,3.38]],"ltp":5.1,"tv":12.59,"id":12925630},{"trd":[[1.96,15.62],[2.04,13.47],[2.08,178.1],[2.3,1.44]],"batl":[[2,2.2,4.34]],"ltp":2.0,"tv":622.21,"id":17336468},{"trd":[[2.46,2.82],[2.7,1.22],[3.15,13.93],[3.2,10.77]],"ltp":3.2,"tv":146.42,"id":11981493}],"tv":781.22}]}
{"op":"mcm","clk":"988699823","pt":1580508223136,"mc":[{"id":"1.168136214","rc":[{"trd":[[2,231.86]],"batb":[[0,1.94,6.79],[1,1.93,63.34],[2,1.92,19.69]],"batl":[[0,2,3.22],[1,2.06,6.38],[2,2.08,10.95]],"ltp":2.0,"tv":655.77,"id":17336468}],"tv":814.78}]}
{"op":"mcm","clk":"988701284","pt":1580508253002,"mc":[{"id":"1.168136214","rc":[{"batb":[[1,1.93,60]],"ltp":2.0,"tv":655.77,"id":17336468}]}]}
{"op":"mcm","clk":"988712597","pt":1580508488284,"mc":[{"id":"1.168136214","rc":[{"batb":[[0,3.1,55.78]],"ltp":3.2,"tv":146.42,"id":11981493}]}]}
{"op":"mcm","clk":"988713978","pt":1580508517018,"mc":[{"id":"1.168136214","rc":[{"trd":[[3.2,55.91]],"batl":[[0,3.6,7],[1,3.7,7],[2,3.75,11]],"ltp":3.2,"tv":191.56,"id":11981493}],"tv":859.92}]}
{"op":"mcm","clk":"988714062","pt":1580508518718,"mc":[{"id":"1.168136214","rc":[{"batl":[[0,3.6,7.2]],"ltp":3.2,"tv":191.56,"id":11981493}]}]}
