{"op":"mcm","clk":"987630876","pt":1580469297561,"mc":[{"id":"1.168133548","marketDefinition":{"bspMarket":true,"turnInPlayEnabled":true,"persistenceEnabled":true,"marketBaseRate":5.0,"eventId":"29678760","eventTypeId":"7","numberOfWinners":1,"bettingType":"ODDS","marketType":"WIN","marketTime":"2020-02-01T13:38:00.000Z","suspendTime":"2020-02-01T13:38:00.000Z","bspReconciled":false,"complete":true,"inPlay":false,"crossMatching":false,"runnersVoidable":false,"numberOfActiveRunners":9,"betDelay":0,"status":"OPEN","runners":[{"adjustmentFactor":18.03,"status":"ACTIVE","sortPriority":1,"id":9417341,"name":"Nuts Well"},{"adjustmentFactor":14.58,"status":"ACTIVE","sortPriority":2,"id":9001159,"name":"Pistol Park"},{"adjustmentFactor":13.26,"status":"ACTIVE","sortPriority":3,"id":8231803,"name":"Kings Odyssey"},{"adjustmentFactor":12.14,"status":"ACTIVE","sortPriority":4,"id":15608820,"name":"The Dubai Way"},{"adjustmentFactor":10.32,"status":"ACTIVE","sortPriority":5,"id":8429550,"name":"Clan Legend"},{"adjustmentFactor":8.91,"status":"ACTIVE","sortPriority":6,"id":10616006,"name":"Winter Escape"},{"adjustmentFactor":8.91,"status":"ACTIVE","sortPriority":7,"id":10170404,"name":"Niven"},{"adjustmentFactor":6.9,"status":"ACTIVE","sortPriority":8,"id":9193530,"name":"Bollin Ace"},{"adjustmentFactor":6.9,"status":"ACTIVE","sortPriority":9,"id":17352128,"name":"Kapgarry"}],"regulators":["MR_INT"],"venue":"Wetherby","countryCode":"GB","discountAllowed":false,"timezone":"Europe/London","openDate":"2020-02-01T13:03:00.000Z","version":3142859070,"name":"2m3f Hcap Chs","eventName":"Weth  1st Feb"},"rc":[{"batb":[[0,1.01,4237.2]],"ltp":0.0,"tv":0.0,"id":8429550},{"batb":[[0,1.01,4237.2]],"ltp":0.0,"tv":0.0,"id":9417341},{"batb":[[0,1.01,4237.2]],"ltp":0.0,"tv":0.0,"id":8231803},{"batb":[[0,1.01,4227.2]],"ltp":0.0,"tv":0.0,"id":10616006},{"batb":[[0,1.01,4227.2]],"ltp":0.0,"tv":0.0,"id":10170404},{"batb":[[0,1.01,4237.2]],"ltp":0.0,"tv":0.0,"id":15608820},{"batb":[[0,1.01,4227.2]],"ltp":0.0,"tv":0.0,"id":9193530},{"batb":[[0,1.01,4237.2]],"ltp":0.0,"tv":0.0,"id":9001159},{"batb":[[0,1.01,4227.2]],"ltp":0.0,"tv":0.0,"id":17352128}]}]}
{"op":"mcm","clk":"987630969","pt":1580469298561,"mc":[{"id":"1.168133548","marketDefinition":{"bspMarket":true,"turnInPlayEnabled":true,"persistenceEnabled":true,"marketBaseRate":5.0,"eventId":"29678760","eventTypeId":"7","numberOfWinners":1,"bettingType":"ODDS","marketType":"WIN","marketTime":"2020-02-01T13:38:00.000Z","suspendTime":"2020-02-01T13:38:00.000Z","bspReconciled":false,"complete":true,"inPlay":false,"crossMatching":false,"runnersVoidable":false,"numberOfActiveRunners":9,"betDelay":0,"status":"OPEN","runners":[{"adjustmentFactor":18.03,"status":"ACTIVE","sortPriority":1,"id":9417341,"name":"Nuts Well"},{"adjustmentFactor":14.58,"status":"ACTIVE","sortPriority":2,"id":9001159,"name":"Pistol Park"},{"adjustmentFactor":13.26,"status":"ACTIVE","sortPriority":3,"id":8231803,"name":"Kings Odyssey"},{"adjustmentFactor":12.14,"status":"ACTIVE","sortPriority":4,"id":15608820,"name":"The Dubai Way"},{"adjustmentFactor":10.32,"status":"ACTIVE","sortPriority":5,"id":8429550,"name":"Clan Legend"},{"adjustmentFactor":8.91,"status":"ACTIVE","sortPriority":6,"id":10616006,"name":"Winter Escape"},{"adjustmentFactor":8.91,"status":"ACTIVE","sortPriority":7,"id":10170404,"name":"Niven"},{"adjustmentFactor":6.9,"status":"ACTIVE","sortPriority":8,"id":9193530,"name":"Bollin Ace"},{"adjustmentFactor":6.9,"status":"ACTIVE","sortPriority":9,"id":17352128,"name":"Kapgarry"}],"regulators":["MR_INT"],"venue":"Wetherby","countryCode":"GB","discountAllowed":true,"timezone":"Europe/London","openDate":"2020-02-01T13:03:00.000Z","version":3142859070,"name":"2m3f Hcap Chs","eventName":"Weth  1st Feb"},"rc":[{"batb":[[0,1.51,3.36],[1,1.01,4240.56]],"ltp":0.0,"tv":0.0,"id":8429550},{"batb":[[0,1.51,3.36],[1,1.01,4240.56]],"ltp":0.0,"tv":0.0,"id":9417341},{"batb":[[0,1.51,3.36],[1,1.01,4240.56]],"ltp":0.0,"tv":0.0,"id":8231803},{"batb":[[0,1.51,3.36],[1,1.01,4240.56]],"ltp":0.0,"tv":0.0,"id":10616006},{"batb":[[0,1.51,3.36],[1,1.01,4240.56]],"ltp":0.0,"tv":0.0,"id":10170404},{"batb":[[0,1.51,3.36],[1,1.01,4240.56]],"ltp":0.0,"tv":0.0,"id":15608820},{"batb":[[0,1.51,3.36],[1,1.01,4240.56]],"ltp":0.0,"tv":0.0,"id":9193530},{"batb":[[0,1.51,3.36],[1,1.01,4240.56]],"ltp":0.0,"tv":0.0,"id":9001159},{"batb":[[0,1.51,3.36],[1,1.01,4240.56]],"ltp":0.0,"tv":0.0,"id":17352128}]}]}
{"op":"mcm","clk":"987631851","pt":1580469308501,"mc":[{"id":"1.168133548","rc":[{"batb":[[1,1.01,4099.96]],"ltp":0.0,"tv":0.0,"id":10616006},{"batb":[[1,1.01,4099.96]],"ltp":0.0,"tv":0.0,"id":15608820},{"batb":[[1,1.01,4099.96]],"ltp":0.0,"tv":0.0,"id":17352128}]}]}
{"op":"mcm","clk":"987631998","pt":1580469310475,"mc":[{"id":"1.168133548","rc":[{"batb":[[1,1.01,4099.96]],"ltp":0.0,"tv":0.0,"id":8429550}]}]}
{"op":"mcm","clk":"987632060","pt":1580469311368,"mc":[{"id":"1.168133548","rc":[{"batb":[[1,1.01,4099.96]],"ltp":0.0,"tv":0.0,"id":9193530}]}]}
{"op":"mcm","clk":"987632124","pt":1580469312304,"mc":[{"id":"1.168133548","rc":[{"batb":[[1,1.01,4099.96]],"ltp":0.0,"tv":0.0,"id":9001159}]}]}
{"op":"mcm","clk":"987632207","pt":1580469313506,"mc":[{"id":"1.168133548","rc":[{"batb":[[1,1.01,4099.96]],"ltp":0.0,"tv":0.0,"id":10170404}]}]}
{"op":"mcm","clk":"987632321","pt":1580469314288,"mc":[{"id":"1.168133548","rc":[{"batb":[[1,1.01,4099.96]],"ltp":0.0,"tv":0.0,"id":8231803}]}]}
{"op":"mcm","clk":"987632404","pt":1580469315279,"mc":[{"id":"1.168133548","rc":[{"batb":[[1,1.01,4099.96]],"ltp":0.0,"tv":0.0,"id":9417341}]}]}
{"op":"mcm","clk":"987632887","pt":1580469322421,"mc":[{"id":"1.168133548","rc":[{"batb":[[1,1.03,5.18],[2,1.01,4099.96]],"ltp":0.0,"tv":0.0,"id":8429550},{"batb":[[1,1.03,5.18],[2,1.01,4099.96]],"ltp":0.0,"tv":0.0,"id":9417341},{"batb":[[1,1.03,5.18],[2,1.01,4099.96]],"ltp":0.0,"tv":0.0,"id":8231803},{"batb":[[1,1.03,5.18],[2,1.01,4099.96]],"ltp":0.0,"tv":0.0,"id":10616006},{"batb":[[1,1.03,5.18],[2,1.01,4099.96]],"ltp":0.0,"tv":0.0,"id":10170404},{"batb":[[1,1.03,5.18],[2,1.01,4099.96]],"ltp":0.0,"tv":0.0,"id":15608820},{"batb":[[1,1.03,5.18],[2,1.01,4099.96]],"ltp":0.0,"tv":0.0,"id":9193530},{"batb":[[1,1.03,5.18],[2,1.01,4099.96]],"ltp":0.0,"tv":0.0,"id":9001159},{"batb":[[1,1.03,5.18],[2,1.01,4099.96]],"ltp":0.0,"tv":0.0,"id":17352128}]}]}
{"op":"mcm","clk":"987633327","pt":1580469328310,"mc":[{"id":"1.168133548","rc":[{"batb":[[2,1.01,4101.96]],"ltp":0.0,"tv":0.0,"id":8429550},{"batb":[[2,1.01,4101.96]],"ltp":0.0,"tv":0.0,"id":9417341},{"batb":[[2,1.01,4101.96]],"ltp":0.0,"tv":0.0,"id":8231803},{"batb":[[2,1.01,4101.96]],"ltp":0.0,"tv":0.0,"id":10616006},{"batb":[[2,1.01,4101.96]],"ltp":0.0,"tv":0.0,"id":10170404},{"batb":[[2,1.01,4101.96]],"ltp":0.0,"tv":0.0,"id":15608820},{"batb":[[2,1.01,4101.96]],"ltp":0.0,"tv":0.0,"id":9193530},{"batb":[[2,1.01,4101.96]],"ltp":0.0,"tv":0.0,"id":9001159},{"batb":[[2,1.01,4101.96]],"ltp":0.0,"tv":0.0,"id":17352128}]}]}
{"op":"mcm","clk":"987633431","pt":1580469330036,"mc":[{"id":"1.168133548","rc":[{"batb":[[1,1.03,1541.12]],"ltp":0.0,"tv":0.0,"id":8429550},{"batb":[[1,1.03,1739.52]],"ltp":0.0,"tv":0.0,"id":9417341},{"batb":[[1,1.03,1743.72]],"ltp":0.0,"tv":0.0,"id":8231803},{"batb":[[1,1.03,1605.01]],"ltp":0.0,"tv":0.0,"id":10616006},{"batb":[[1,1.03,1721.03]],"ltp":0.0,"tv":0.0,"id":10170404},{"batb":[[1,1.03,1812.66]],"ltp":0.0,"tv":0.0,"id":15608820},{"batb":[[1,1.03,1825.27]],"ltp":0.0,"tv":0.0,"id":9193530},{"batb":[[1,1.03,1595.76]],"ltp":0.0,"tv":0.0,"id":9001159},{"batb":[[1,1.03,1537.76]],"ltp":0.0,"tv":0.0,"id":17352128}]}]}
{"op":"mcm","clk":"987641851","pt":1580469437298,"mc":[{"id":"1.168133548","rc":[{"batb":[[2,1.01,4103.64]],"ltp":0.0,"tv":0.0,"id":9417341},{"batb":[[2,1.01,4103.64]],"ltp":0.0,"tv":0.0,"id":8231803},{"batb":[[2,1.01,4103.64]],"ltp":0.0,"tv":0.0,"id":9001159}]}]}
{"op":"mcm","clk":"987641937","pt":1580469438495,"mc":[{"id":"1.168133548","rc":[{"batb":[[2,1.01,4103.64]],"ltp":0.0,"tv":0.0,"id":8429550},{"batb":[[2,1.01,4103.64]],"ltp":0.0,"tv":0.0,"id":10616006},{"batb":[[2,1.01,4103.64]],"ltp":0.0,"tv":0.0,"id":10170404},{"batb":[[2,1.01,4103.64]],"ltp":0.0,"tv":0.0,"id":15608820}]}]}
{"op":"mcm","clk":"987641976","pt":1580469439117,"mc":[{"id":"1.168133548","rc":[{"batb":[[2,1.01,4103.64]],"ltp":0.0,"tv":0.0,"id":9193530},{"batb":[[2,1.01,4103.64]],"ltp":0.0,"tv":0.0,"id":17352128}]}]}
{"op":"mcm","clk":"987651107","pt":1580469557506,"mc":[{"id":"1.168133548","rc":[{"batb":[[2,1.01,4107.63]],"ltp":0.0,"tv":0.0,"id":9417341}]}]}
{"op":"mcm","clk":"987651182","pt":1580469558504,"mc":[{"id":"1.168133548","rc":[{"batb":[[2,1.02,1.99]],"ltp":0.0,"tv":0.0,"id":9417341},{"batb":[[2,1.01,4107.63]],"ltp":0.0,"tv":0.0,"id":9001159}]}]}
{"op":"mcm","clk":"987651275","pt":1580469559494,"mc":[{"id":"1.168133548","rc":[{"batb":[[2,1.01,4105.64]],"ltp":0.0,"tv":0.0,"id":8231803},{"batb":[[2,1.02,1.99]],"ltp":0.0,"tv":0.0,"id":9001159}]}]}
{"op":"mcm","clk":"987651346","pt":1580469560325,"mc":[{"id":"1.168133548","rc":[{"batb":[[2,1.02,1.99]],"ltp":0.0,"tv":0.0,"id":8231803}]}]}
{"op":"mcm","clk":"987651414","pt":1580469561238,"mc":[{"id":"1.168133548","rc":[{"batb":[[2,1.02,1.99]],"ltp":0.0,"tv":0.0,"id":15608820}]}]}
{"op":"mcm","clk":"987651522","pt":1580469562547,"mc":[{"id":"1.168133548","rc":[{"batb":[[2,1.02,1.99]],"ltp":0.0,"tv":0.0,"id":8429550}]}]}
{"op":"mcm","clk":"987651619","pt":1580469563569,"mc":[{"id":"1.168133548","rc":[{"batb":[[2,1.01,4105.64]],"ltp":0.0,"tv":0.0,"id":10616006}]}]}
{"op":"mcm","clk":"987651684","pt":1580469564329,"mc":[{"id":"1.168133548","rc":[{"batb":[[2,1.02,1.99]],"ltp":0.0,"tv":0.0,"id":10616006},{"batb":[[2,1.01,4107.63]],"ltp":0.0,"tv":0.0,"id":10170404}]}]}
{"op":"mcm","clk":"987651778","pt":1580469565419,"mc":[{"id":"1.168133548","rc":[{"batb":[[2,1.02,1.99]],"ltp":0.0,"tv":0.0,"id":10170404},{"batb":[[2,1.01,4105.64]],"ltp":0.0,"tv":0.0,"id":9193530}]}]}
{"op":"mcm","clk":"987651864","pt":1580469566420,"mc":[{"id":"1.168133548","rc":[{"batb":[[2,1.02,1.99]],"ltp":0.0,"tv":0.0,"id":9193530},{"batb":[[2,1.01,4105.64]],"ltp":0.0,"tv":0.0,"id":17352128}]}]}
{"op":"mcm","clk":"987651909","pt":1580469567040,"mc":[{"id":"1.168133548","rc":[{"batb":[[2,1.02,1.99]],"ltp":0.0,"tv":0.0,"id":17352128}]}]}
{"op":"mcm","clk":"987661766","pt":1580469702817,"mc":[{"id":"1.168133548","rc":[{"batb":[[1,1.04,3],[2,1.03,1541.12]],"ltp":0.0,"tv":0.0,"id":8429550},{"batb":[[1,1.04,3],[2,1.03,1739.52]],"ltp":0.0,"tv":0.0,"id":9417341},{"batb":[[1,1.04,3],[2,1.03,1743.72]],"ltp":0.0,"tv":0.0,"id":8231803},{"batb":[[1,1.04,3],[2,1.03,1605.01]],"ltp":0.0,"tv":0.0,"id":10616006},{"batb":[[1,1.04,3],[2,1.03,1721.03]],"ltp":0.0,"tv":0.0,"id":10170404},{"batb":[[1,1.04,3],[2,1.03,1812.66]],"ltp":0.0,"tv":0.0,"id":15608820},{"batb":[[1,1.04,3],[2,1.03,1825.27]],"ltp":0.0,"tv":0.0,"id":9193530},{"batb":[[1,1.04,3],[2,1.03,1595.76]],"ltp":0.0,"tv":0.0,"id":9001159},{"batb":[[1,1.04,3],[2,1.03,1537.76]],"ltp":0.0,"tv":0.0,"id":17352128}]}]}
{"op":"mcm","clk":"987758990","pt":1580470974943,"mc":[{"id":"1.168133548","rc":[{"batl":[[0,1000,0.2]],"ltp":0.0,"tv":0.0,"id":8429550},{"batl":[[0,1000,0.2]],"ltp":0.0,"tv":0.0,"id":9417341},{"batl":[[0,1000,0.2]],"ltp":0.0,"tv":0.0,"id":8231803},{"batl":[[0,1000,0.2]],"ltp":0.0,"tv":0.0,"id":10616006},{"batl":[[0,1000,0.2]],"ltp":0.0,"tv":0.0,"id":10170404},{"batl":[[0,1000,0.2]],"ltp":0.0,"tv":0.0,"id":15608820},{"batl":[[0,1000,0.2]],"ltp":0.0,"tv":0.0,"id":9001159},{"batl":[[0,1000,0.2]],"ltp":0.0,"tv":0.0,"id":9193530},{"batl":[[0,1000,0.2]],"ltp":0.0,"tv":0.0,"id":17352128}]}]}
{"op":"mcm","clk":"987883046","pt":1580472452127,"mc":[{"id":"1.168133548","rc":[{"batb":[[2,1.03,1541.51]],"ltp":0.0,"tv":0.0,"id":8429550},{"batb":[[2,1.03,1739.96]],"ltp":0.0,"tv":0.0,"id":9417341},{"batb":[[2,1.03,1744.16]],"ltp":0.0,"tv":0.0,"id":8231803},{"batb":[[2,1.03,1605.42]],"ltp":0.0,"tv":0.0,"id":10616006},{"batb":[[2,1.03,1721.46]],"ltp":0.0,"tv":0.0,"id":10170404},{"batb":[[2,1.03,1813.12]],"ltp":0.0,"tv":0.0,"id":15608820},{"batb":[[2,1.03,1825.73]],"ltp":0.0,"tv":0.0,"id":9193530},{"batb":[[2,1.03,1596.17]],"ltp":0.0,"tv":0.0,"id":9001159},{"batb":[[2,1.03,1538.14]],"ltp":0.0,"tv":0.0,"id":17352128}]}]}
{"op":"mcm","clk":"987901498","pt":1580472598486,"mc":[{"id":"1.168133548","rc":[{"batb":[[1,1.05,10],[2,1.04,3]],"ltp":0.0,"tv":0.0,"id":8429550},{"batb":[[1,1.05,10],[2,1.04,3]],"ltp":0.0,"tv":0.0,"id":9417341},{"batb":[[1,1.05,10],[2,1.04,3]],"ltp":0.0,"tv":0.0,"id":8231803},{"batb":[[1,1.05,10],[2,1.04,3]],"ltp":0.0,"tv":0.0,"id":10616006},{"batb":[[1,1.05,10],[2,1.04,3]],"ltp":0.0,"tv":0.0,"id":10170404},{"batb":[[1,1.05,10],[2,1.04,3]],"ltp":0.0,"tv":0.0,"id":15608820},{"batb":[[1,1.05,10],[2,1.04,3]],"ltp":0.0,"tv":0.0,"id":9193530},{"batb":[[1,1.05,10],[2,1.04,3]],"ltp":0.0,"tv":0.0,"id":9001159},{"batb":[[1,1.05,10],[2,1.04,3]],"ltp":0.0,"tv":0.0,"id":17352128}]}]}
{"op":"mcm","clk":"987927645","pt":1580472845368,"mc":[{"id":"1.168133548","rc":[{"batb":[[2,1.03,1541.51]],"ltp":0.0,"tv":0.0,"id":8429550},{"batb":[[2,1.03,1739.96]],"ltp":0.0,"tv":0.0,"id":9417341},{"batb":[[2,1.03,1744.16]],"ltp":0.0,"tv":0.0,"id":8231803},{"batb":[[2,1.03,1605.42]],"ltp":0.0,"tv":0.0,"id":10616006},{"batb":[[2,1.03,1721.46]],"ltp":0.0,"tv":0.0,"id":10170404},{"batb":[[2,1.03,1813.12]],"ltp":0.0,"tv":0.0,"id":15608820},{"batb":[[2,1.03,1825.73]],"ltp":0.0,"tv":0.0,"id":9193530},{"batb":[[2,1.03,1596.17]],"ltp":0.0,"tv":0.0,"id":9001159},{"batb":[[2,1.03,1538.14]],"ltp":0.0,"tv":0.0,"id":17352128}]}]}
{"op":"mcm","clk":"987929973","pt":1580472868427,"mc":[{"id":"1.168133548","rc":[{"batb":[[1,1.04,10]],"ltp":0.0,"tv":0.0,"id":8429550},{"batb":[[1,1.04,10]],"ltp":0.0,"tv":0.0,"id":9417341},{"batb":[[1,1.04,10]],"ltp":0.0,"tv":0.0,"id":8231803},{"batb":[[1,1.04,10]],"ltp":0.0,"tv":0.0,"id":10616006},{"batb":[[1,1.04,10]],"ltp":0.0,"tv":0.0,"id":10170404},{"batb":[[1,1.04,10]],"ltp":0.0,"tv":0.0,"id":15608820},{"batb":[[1,1.04,10]],"ltp":0.0,"tv":0.0,"id":9193530},{"batb":[[1,1.04,10]],"ltp":0.0,"tv":0.0,"id":9001159},{"batb":[[1,1.04,10]],"ltp":0.0,"tv":0.0,"id":17352128}]}]}
{"op":"mcm","clk":"987959860","pt":1580473164049,"mc":[{"id":"1.168133548","rc":[{"batb":[[1,1.05,3],[2,1.04,10]],"ltp":0.0,"tv":0.0,"id":8429550},{"batb":[[1,1.05,3],[2,1.04,10]],"ltp":0.0,"tv":0.0,"id":9417341},{"batb":[[1,1.05,3],[2,1.04,10]],"ltp":0.0,"tv":0.0,"id":8231803},{"batb":[[1,1.05,3],[2,1.04,10]],"ltp":0.0,"tv":0.0,"id":10616006},{"batb":[[1,1.05,3],[2,1.04,10]],"ltp":0.0,"tv":0.0,"id":10170404},{"batb":[[1,1.05,3],[2,1.04,10]],"ltp":0.0,"tv":0.0,"id":15608820},{"batb":[[1,1.05,3],[2,1.04,10]],"ltp":0.0,"tv":0.0,"id":9193530},{"batb":[[1,1.05,3],[2,1.04,10]],"ltp":0.0,"tv":0.0,"id":9001159},{"batb":[[1,1.05,3],[2,1.04,10]],"ltp":0.0,"tv":0.0,"id":17352128}]}]}
{"op":"mcm","clk":"987966474","pt":1580473229516,"mc":[{"id":"1.168133548","rc":[{"batb":[[2,1.03,1541.51]],"ltp":0.0,"tv":0.0,"id":8429550},{"batb":[[2,1.03,1739.96]],"ltp":0.0,"tv":0.0,"id":9417341},{"batb":[[2,1.03,1744.16]],"ltp":0.0,"tv":0.0,"id":8231803},{"batb":[[2,1.03,1605.42]],"ltp":0.0,"tv":0.0,"id":10616006},{"batb":[[2,1.03,1721.46]],"ltp":0.0,"tv":0.0,"id":10170404},{"batb":[[2,1.03,1813.12]],"ltp":0.0,"tv":0.0,"id":15608820},{"batb":[[2,1.03,1825.73]],"ltp":0.0,"tv":0.0,"id":9193530},{"batb":[[2,1.03,1596.17]],"ltp":0.0,"tv":0.0,"id":9001159},{"batb":[[2,1.03,1538.14]],"ltp":0.0,"tv":0.0,"id":17352128}]}]}
{"op":"mcm","clk":"987994429","pt":1580473419751,"mc":[{"id":"1.168133548","rc":[{"batb":[[1,1.04,3]],"ltp":0.0,"tv":0.0,"id":8429550},{"batb":[[1,1.04,3]],"ltp":0.0,"tv":0.0,"id":9417341},{"batb":[[1,1.04,3]],"ltp":0.0,"tv":0.0,"id":8231803},{"batb":[[1,1.04,3]],"ltp":0.0,"tv":0.0,"id":10616006},{"batb":[[1,1.04,3]],"ltp":0.0,"tv":0.0,"id":10170404},{"batb":[[1,1.04,3]],"ltp":0.0,"tv":0.0,"id":15608820},{"batb":[[1,1.04,3]],"ltp":0.0,"tv":0.0,"id":9193530},{"batb":[[1,1.04,3]],"ltp":0.0,"tv":0.0,"id":9001159},{"batb":[[1,1.04,3]],"ltp":0.0,"tv":0.0,"id":17352128}]}]}
{"op":"mcm","clk":"988215956","pt":1580475444514,"mc":[{"id":"1.168133548","rc":[{"batb":[[0,1.52,1.09],[1,1.51,3.36],[2,1.04,3]],"ltp":0.0,"tv":0.0,"id":8429550},{"batb":[[0,1.52,1.09],[1,1.51,3.36],[2,1.04,3]],"ltp":0.0,"tv":0.0,"id":9417341},{"batb":[[0,1.52,1.09],[1,1.51,3.36],[2,1.04,3]],"ltp":0.0,"tv":0.0,"id":8231803},{"batb":[[0,1.52,1.09],[1,1.51,3.36],[2,1.04,3]],"ltp":0.0,"tv":0.0,"id":15608820},{"batb":[[0,1.52,1.09],[1,1.51,3.36],[2,1.04,3]],"ltp":0.0,"tv":0.0,"id":9001159}]}]}
{"op":"mcm","clk":"988215980","pt":1580475444821,"mc":[{"id":"1.168133548","rc":[{"batb":[[0,1.52,1.09],[1,1.51,3.36],[2,1.04,3]],"ltp":0.0,"tv":0.0,"id":10616006},{"batb":[[0,1.52,1.09],[1,1.51,3.36],[2,1.04,3]],"ltp":0.0,"tv":0.0,"id":10170404},{"batb":[[0,1.52,1.09],[1,1.51,3.36],[2,1.04,3]],"ltp":0.0,"tv":0.0,"id":9193530},{"batb":[[0,1.52,1.09],[1,1.51,3.36],[2,1.04,3]],"ltp":0.0,"tv":0.0,"id":17352128}]}]}
{"op":"mcm","clk":"988584362","pt":1580478572055,"mc":[{"id":"1.168133548","rc":[{"batb":[[0,1.52,11.09]],"ltp":0.0,"tv":0.0,"id":8429550},{"batb":[[0,1.52,11.09]],"ltp":0.0,"tv":0.0,"id":9417341},{"batb":[[0,1.52,11.09]],"ltp":0.0,"tv":0.0,"id":8231803},{"batb":[[0,1.52,11.09]],"ltp":0.0,"tv":0.0,"id":10616006},{"batb":[[0,1.52,11.09]],"ltp":0.0,"tv":0.0,"id":10170404},{"batb":[[0,1.52,11.09]],"ltp":0.0,"tv":0.0,"id":15608820},{"batb":[[0,1.52,11.09]],"ltp":0.0,"tv":0.0,"id":9193530},{"batb":[[0,1.52,11.09]],"ltp":0.0,"tv":0.0,"id":9001159},{"batb":[[0,1.52,11.09]],"ltp":0.0,"tv":0.0,"id":17352128}]}]}
{"op":"mcm","clk":"988587360","pt":1580478608910,"mc":[{"id":"1.168133548","rc":[{"batb":[[0,1.53,3],[1,1.52,11.09],[2,1.51,3.36]],"ltp":0.0,"tv":0.0,"id":8429550},{"batb":[[0,1.53,3],[1,1.52,11.09],[2,1.51,3.36]],"ltp":0.0,"tv":0.0,"id":9417341},{"batb":[[0,1.53,3],[1,1.52,11.09],[2,1.51,3.36]],"ltp":0.0,"tv":0.0,"id":8231803},{"batb":[[0,1.53,3],[1,1.52,11.09],[2,1.51,3.36]],"ltp":0.0,"tv":0.0,"id":10616006},{"batb":[[0,1.53,3],[1,1.52,11.09],[2,1.51,3.36]],"ltp":0.0,"tv":0.0,"id":10170404},{"batb":[[0,1.53,3],[1,1.52,11.09],[2,1.51,3.36]],"ltp":0.0,"tv":0.0,"id":15608820},{"batb":[[0,1.53,3],[1,1.52,11.09],[2,1.51,3.36]],"ltp":0.0,"tv":0.0,"id":9193530},{"batb":[[0,1.53,3],[1,1.52,11.09],[2,1.51,3.36]],"ltp":0.0,"tv":0.0,"id":9001159},{"batb":[[0,1.53,3],[1,1.52,11.09],[2,1.51,3.36]],"ltp":0.0,"tv":0.0,"id":17352128}]}]}
{"op":"mcm","clk":"988592547","pt":1580478669325,"mc":[{"id":"1.168133548","rc":[{"batb":[[0,1.54,1.99],[1,1.53,3],[2,1.52,11.09]],"ltp":0.0,"tv":0.0,"id":9417341},{"batb":[[0,1.54,1.99],[1,1.53,3],[2,1.52,11.09]],"ltp":0.0,"tv":0.0,"id":9001159}]}]}
{"op":"mcm","clk":"988592575","pt":1580478669692,"mc":[{"id":"1.168133548","rc":[{"batb":[[0,1.54,1.99],[1,1.53,3],[2,1.52,11.09]],"ltp":0.0,"tv":0.0,"id":8231803}]}]}
{"op":"mcm","clk":"988592715","pt":1580478671511,"mc":[{"id":"1.168133548","rc":[{"batb":[[0,1.54,1.99],[1,1.53,3],[2,1.52,11.09]],"ltp":0.0,"tv":0.0,"id":8429550},{"batb":[[0,1.54,1.99],[1,1.53,3],[2,1.52,11.09]],"ltp":0.0,"tv":0.0,"id":10616006},{"batb":[[0,1.54,1.99],[1,1.53,3],[2,1.52,11.09]],"ltp":0.0,"tv":0.0,"id":15608820}]}]}
{"op":"mcm","clk":"988592781","pt":1580478672542,"mc":[{"id":"1.168133548","rc":[{"batb":[[0,1.54,1.99],[1,1.53,3],[2,1.52,11.09]],"ltp":0.0,"tv":0.0,"id":10170404}]}]}
{"op":"mcm","clk":"988592824","pt":1580478673115,"mc":[{"id":"1.168133548","rc":[{"batb":[[0,1.54,1.99],[1,1.53,3],[2,1.52,11.09]],"ltp":0.0,"tv":0.0,"id":9193530},{"batb":[[0,1.54,1.99],[1,1.53,3],[2,1.52,11.09]],"ltp":0.0,"tv":0.0,"id":17352128}]}]}
{"op":"mcm","clk":"988598277","pt":1580478743219,"mc":[{"id":"1.168133548","rc":[{"batb":[[2,1.52,1.09]],"ltp":0.0,"tv":0.0,"id":8429550},{"batb":[[2,1.52,1.09]],"ltp":0.0,"tv":0.0,"id":9417341},{"batb":[[2,1.52,1.09]],"ltp":0.0,"tv":0.0,"id":8231803},{"batb":[[2,1.52,1.09]],"ltp":0.0,"tv":0.0,"id":10616006},{"batb":[[2,1.52,1.09]],"ltp":0.0,"tv":0.0,"id":10170404},{"batb":[[2,1.52,1.09]],"ltp":0.0,"tv":0.0,"id":15608820},{"batb":[[2,1.52,1.09]],"ltp":0.0,"tv":0.0,"id":9193530},{"batb":[[2,1.52,1.09]],"ltp":0.0,"tv":0.0,"id":9001159},{"batb":[[2,1.52,1.09]],"ltp":0.0,"tv":0.0,"id":17352128}]}]}
{"op":"mcm","clk":"988608428","pt":1580478765356,"mc":[{"id":"1.168133548","rc":[{"batb":[[1,1.52,1.09],[2,1.51,3.36]],"ltp":0.0,"tv":0.0,"id":8429550},{"batb":[[1,1.52,1.09],[2,1.51,3.36]],"ltp":0.0,"tv":0.0,"id":9417341},{"batb":[[1,1.52,1.09],[2,1.51,3.36]],"ltp":0.0,"tv":0.0,"id":8231803},{"batb":[[1,1.52,1.09],[2,1.51,3.36]],"ltp":0.0,"tv":0.0,"id":10616006},{"batb":[[1,1.52,1.09],[2,1.51,3.36]],"ltp":0.0,"tv":0.0,"id":10170404},{"batb":[[1,1.52,1.09],[2,1.51,3.36]],"ltp":0.0,"tv":0.0,"id":15608820},{"batb":[[1,1.52,1.09],[2,1.51,3.36]],"ltp":0.0,"tv":0.0,"id":9001159},{"batb":[[1,1.52,1.09],[2,1.51,3.36]],"ltp":0.0,"tv":0.0,"id":9193530},{"batb":[[1,1.52,1.09],[2,1.51,3.36]],"ltp":0.0,"tv":0.0,"id":17352128}]}]}
{"op":"mcm","clk":"988612291","pt":1580478818409,"mc":[{"id":"1.168133548","rc":[{"batb":[[0,1.53,1.99]],"ltp":0.0,"tv":0.0,"id":9417341},{"batb":[[0,1.53,1.99]],"ltp":0.0,"tv":0.0,"id":9001159}]}]}
{"op":"mcm","clk":"988612356","pt":1580478819189,"mc":[{"id":"1.168133548","rc":[{"batb":[[0,1.53,1.99]],"ltp":0.0,"tv":0.0,"id":8231803},{"batb":[[0,1.53,1.99]],"ltp":0.0,"tv":0.0,"id":15608820}]}]}
{"op":"mcm","clk":"988612484","pt":1580478820493,"mc":[{"id":"1.168133548","rc":[{"batb":[[0,1.53,1.99]],"ltp":0.0,"tv":0.0,"id":8429550},{"batb":[[0,1.53,1.99]],"ltp":0.0,"tv":0.0,"id":10616006},{"batb":[[0,1.52,1.09],[1,1.51,3.36],[2,1.04,3]],"ltp":0.0,"tv":0.0,"id":10170404}]}]}
{"op":"mcm","clk":"988612564","pt":1580478821481,"mc":[{"id":"1.168133548","rc":[{"batb":[[0,1.53,1.99],[1,1.52,1.09],[2,1.51,3.36]],"ltp":0.0,"tv":0.0,"id":10170404},{"batb":[[0,1.53,1.99]],"ltp":0.0,"tv":0.0,"id":9193530}]}]}
{"op":"mcm","clk":"988612598","pt":1580478821791,"mc":[{"id":"1.168133548","rc":[{"batb":[[0,1.53,1.99]],"ltp":0.0,"tv":0.0,"id":17352128}]}]}
{"op":"mcm","clk":"988630741","pt":1580479086619,"mc":[{"id":"1.168133548","rc":[{"batb":[[0,1.53,11.99]],"ltp":0.0,"tv":0.0,"id":8429550},{"batb":[[0,1.53,11.99]],"ltp":0.0,"tv":0.0,"id":9417341},{"batb":[[0,1.53,11.99]],"ltp":0.0,"tv":0.0,"id":8231803},{"batb":[[0,1.53,11.99]],"ltp":0.0,"tv":0.0,"id":10616006},{"batb":[[0,1.53,11.99]],"ltp":0.0,"tv":0.0,"id":10170404},{"batb":[[0,1.53,11.99]],"ltp":0.0,"tv":0.0,"id":15608820},{"batb":[[0,1.53,11.99]],"ltp":0.0,"tv":0.0,"id":9001159},{"batb":[[0,1.53,11.99]],"ltp":0.0,"tv":0.0,"id":9193530},{"batb":[[0,1.53,11.99]],"ltp":0.0,"tv":0.0,"id":17352128}]}]}
{"op":"mcm","clk":"988686252","pt":1580479652122,"mc":[{"id":"1.168133548","rc":[{"batb":[[1,1.52,1.09]],"ltp":0.0,"tv":0.0,"id":8429550},{"batb":[[1,1.52,1.09]],"ltp":0.0,"tv":0.0,"id":9417341},{"batb":[[1,1.52,1.09]],"ltp":0.0,"tv":0.0,"id":8231803},{"batb":[[1,1.52,1.09]],"ltp":0.0,"tv":0.0,"id":10616006},{"batb":[[1,1.52,1.09]],"ltp":0.0,"tv":0.0,"id":10170404},{"batb":[[1,1.52,1.09]],"ltp":0.0,"tv":0.0,"id":15608820},{"batb":[[1,1.52,1.09]],"ltp":0.0,"tv":0.0,"id":9001159},{"batb":[[1,1.52,1.09]],"ltp":0.0,"tv":0.0,"id":9193530},{"batb":[[1,1.52,1.09]],"ltp":0.0,"tv":0.0,"id":17352128}]}]}
{"op":"mcm","clk":"989323212","pt":1580486752676,"mc":[{"id":"1.168133548","rc":[{"batb":[[1,1.52,1.08]],"ltp":0.0,"tv":0.0,"id":8429550},{"batb":[[0,1.54,1.68],[1,1.53,11.99],[2,1.52,1.08]],"ltp":0.0,"tv":0.0,"id":9417341},{"batb":[[1,1.52,1.08]],"ltp":0.0,"tv":0.0,"id":8231803},{"batb":[[1,1.52,1.08]],"ltp":0.0,"tv":0.0,"id":10616006},{"batb":[[1,1.52,1.08]],"ltp":0.0,"tv":0.0,"id":10170404},{"batb":[[1,1.52,1.08]],"ltp":0.0,"tv":0.0,"id":15608820},{"batb":[[1,1.52,1.08]],"ltp":0.0,"tv":0.0,"id":9001159},{"batb":[[1,1.52,1.08]],"ltp":0.0,"tv":0.0,"id":9193530},{"batb":[[1,1.52,1.08]],"ltp":0.0,"tv":0.0,"id":17352128}]}]}
{"op":"mcm","clk":"989323432","pt":1580486755051,"mc":[{"id":"1.168133548","rc":[{"batb":[[0,1.53,11.99],[1,1.52,1.08],[2,1.51,3.36]],"ltp":0.0,"tv":0.0,"id":9417341}]}]}
{"op":"mcm","clk":"989614588","pt":1580489682403,"mc":[{"id":"1.168133548","rc":[{"batb":[[0,1.53,14.99]],"ltp":0.0,"tv":0.0,"id":9001159}]}]}
{"op":"mcm","clk":"989614900","pt":1580489686306,"mc":[{"id":"1.168133548","rc":[{"batb":[[0,3.35,3],[1,1.53,11.99],[2,1.52,1.08]],"ltp":0.0,"tv":0.0,"id":9001159}]}]}
{"op":"mcm","clk":"989615000","pt":1580489687447,"mc":[{"id":"1.168133548","rc":[{"batb":[[0,1.53,11.99],[1,1.52,1.08],[2,1.51,3.36]],"ltp":0.0,"tv":0.0,"id":9001159}]}]}
{"op":"mcm","clk":"989769600","pt":1580491226525,"mc":[{"id":"1.168133548","rc":[{"batb":[[0,1.55,90],[1,1.53,11.99],[2,1.52,1.08]],"batl":[[0,980,9],[1,1000,0.2]],"ltp":0.0,"tv":0.0,"id":8429550},{"batb":[[0,1.55,90],[1,1.53,11.99],[2,1.52,1.08]],"batl":[[0,980,9],[1,1000,0.2]],"ltp":0.0,"tv":0.0,"id":9417341},{"batb":[[0,1.55,90],[1,1.53,11.99],[2,1.52,1.08]],"batl":[[0,980,9],[1,1000,0.2]],"ltp":0.0,"tv":0.0,"id":8231803},{"batb":[[0,1.55,90],[1,1.53,11.99],[2,1.52,1.08]],"batl":[[0,980,9],[1,1000,0.2]],"ltp":0.0,"tv":0.0,"id":10616006},{"batb":[[0,1.55,90],[1,1.53,11.99],[2,1.52,1.08]],"batl":[[0,980,9],[1,1000,0.2]],"ltp":0.0,"tv":0.0,"id":10170404},{"batb":[[0,1.55,90],[1,1.53,11.99],[2,1.52,1.08]],"batl":[[0,980,9],[1,1000,0.2]],"ltp":0.0,"tv":0.0,"id":15608820},{"batb":[[0,1.55,90],[1,1.53,11.99],[2,1.52,1.08]],"batl":[[0,980,9],[1,1000,0.2]],"ltp":0.0,"tv":0.0,"id":9001159},{"batb":[[0,1.55,90],[1,1.53,11.99],[2,1.52,1.08]],"batl":[[0,980,9],[1,1000,0.2]],"ltp":0.0,"tv":0.0,"id":9193530},{"batb":[[0,1.55,90],[1,1.53,11.99],[2,1.52,1.08]],"batl":[[0,980,9],[1,1000,0.2]],"ltp":0.0,"tv":0.0,"id":17352128}]}]}
{"op":"mcm","clk":"989770497","pt":1580491235534,"mc":[{"id":"1.168133548","rc":[{"batl":[[0,980,9.2],[1,1000,0]],"ltp":0.0,"tv":0.0,"id":8429550},{"batl":[[0,980,9.2],[1,1000,0]],"ltp":0.0,"tv":0.0,"id":9417341},{"batl":[[0,980,9.2],[1,1000,0]],"ltp":0.0,"tv":0.0,"id":8231803},{"batl":[[0,980,9.2],[1,1000,0]],"ltp":0.0,"tv":0.0,"id":10616006},{"batl":[[0,980,9.2],[1,1000,0]],"ltp":0.0,"tv":0.0,"id":10170404},{"batl":[[0,980,9.2],[1,1000,0]],"ltp":0.0,"tv":0.0,"id":15608820},{"batl":[[0,980,9.2],[1,1000,0]],"ltp":0.0,"tv":0.0,"id":9001159},{"batl":[[0,980,9.2],[1,1000,0]],"ltp":0.0,"tv":0.0,"id":9193530},{"batl":[[0,980,9.2],[1,1000,0]],"ltp":0.0,"tv":0.0,"id":17352128}]}]}
{"op":"mcm","clk":"989771940","pt":1580491248503,"mc":[{"id":"1.168133548","rc":[{"batb":[[2,1.52,22.93]],"batl":[[0,970,3.23],[1,980,9]],"ltp":0.0,"tv":0.0,"id":8429550},{"batb":[[2,1.52,24.29]],"batl":[[0,970,3.23],[1,980,9]],"ltp":0.0,"tv":0.0,"id":9417341},{"batb":[[2,1.52,23.25]],"batl":[[0,970,3.23],[1,980,9]],"ltp":0.0,"tv":0.0,"id":8231803},{"batb":[[2,1.52,26.58]],"batl":[[0,40,3.03],[1,980,9.2]],"ltp":0.0,"tv":0.0,"id":10616006},{"batb":[[2,1.52,22.93]],"batl":[[0,970,3.23],[1,980,9]],"ltp":0.0,"tv":0.0,"id":10170404},{"batb":[[2,1.52,26.58]],"batl":[[0,970,3.23],[1,980,9]],"ltp":0.0,"tv":0.0,"id":15608820},{"batb":[[2,1.52,22.6]],"batl":[[0,970,3.23],[1,980,9]],"ltp":0.0,"tv":0.0,"id":9001159}]}]}
{"op":"mcm","clk":"989772048","pt":1580491249495,"mc":[{"id":"1.168133548","rc":[{"batb":[[0,1.56,1.99],[1,1.55,90],[2,1.53,10]],"ltp":0.0,"tv":0.0,"id":9417341},{"batl":[[0,40,3.23],[1,980,9]],"ltp":0.0,"tv":0.0,"id":10616006},{"batb":[[2,1.52,22.6]],"batl":[[0,970,3.23],[1,980,9]],"ltp":0.0,"tv":0.0,"id":9193530},{"batb":[[2,1.52,22.93]],"batl":[[0,970,3.23],[1,980,9]],"ltp":0.0,"tv":0.0,"id":17352128}]}]}
{"op":"mcm","clk":"989772106","pt":1580491249974,"mc":[{"id":"1.168133548","rc":[{"batb":[[0,1.56,1.99],[1,1.55,90],[2,1.53,10]],"ltp":0.0,"tv":0.0,"id":9001159}]}]}
{"op":"mcm","clk":"989772247","pt":1580491251286,"mc":[{"id":"1.168133548","rc":[{"batb":[[0,1.56,1.99],[1,1.55,90],[2,1.53,10]],"ltp":0.0,"tv":0.0,"id":8231803}]}]}
{"op":"mcm","clk":"989772373","pt":1580491252296,"mc":[{"id":"1.168133548","rc":[{"batb":[[0,1.56,1.99],[1,1.55,90],[2,1.53,10]],"ltp":0.0,"tv":0.0,"id":15608820}]}]}
{"op":"mcm","clk":"989772489","pt":1580491253395,"mc":[{"id":"1.168133548","rc":[{"batb":[[0,1.56,1.99],[1,1.55,90],[2,1.53,10]],"ltp":0.0,"tv":0.0,"id":8429550},{"batb":[[0,1.56,1.99],[1,1.55,90],[2,1.53,10]],"ltp":0.0,"tv":0.0,"id":10616006}]}]}
{"op":"mcm","clk":"989772721","pt":1580491255503,"mc":[{"id":"1.168133548","rc":[{"batb":[[0,1.56,1.99],[1,1.55,90],[2,1.53,10]],"ltp":0.0,"tv":0.0,"id":10170404}]}]}
{"op":"mcm","clk":"989772849","pt":1580491256398,"mc":[{"id":"1.168133548","rc":[{"batb":[[0,1.56,1.99],[1,1.55,90],[2,1.53,10]],"ltp":0.0,"tv":0.0,"id":9193530}]}]}
{"op":"mcm","clk":"989772992","pt":1580491257519,"mc":[{"id":"1.168133548","rc":[{"batb":[[0,1.56,1.99],[1,1.55,90],[2,1.53,10]],"ltp":0.0,"tv":0.0,"id":17352128}]}]}
{"op":"mcm","clk":"989773762","pt":1580491264839,"mc":[{"id":"1.168133548","rc":[{"batb":[[0,1.56,4.99]],"ltp":0.0,"tv":0.0,"id":8429550},{"batb":[[0,1.56,4.99]],"ltp":0.0,"tv":0.0,"id":9417341},{"batb":[[0,1.56,4.99]],"ltp":0.0,"tv":0.0,"id":8231803},{"batb":[[0,1.56,4.99]],"ltp":0.0,"tv":0.0,"id":10616006},{"batb":[[0,1.56,4.99]],"ltp":0.0,"tv":0.0,"id":10170404},{"batb":[[0,1.56,4.99]],"ltp":0.0,"tv":0.0,"id":15608820},{"batb":[[0,1.56,4.99]],"ltp":0.0,"tv":0.0,"id":9001159},{"batb":[[0,1.56,4.99]],"ltp":0.0,"tv":0.0,"id":9193530},{"batb":[[0,1.56,4.99]],"ltp":0.0,"tv":0.0,"id":17352128}]}]}
{"op":"mcm","clk":"989774596","pt":1580491272125,"mc":[{"id":"1.168133548","rc":[{"batb":[[2,1.52,22.93]],"ltp":0.0,"tv":0.0,"id":8429550},{"batb":[[2,1.52,24.29]],"ltp":0.0,"tv":0.0,"id":9417341},{"batb":[[2,1.52,23.25]],"ltp":0.0,"tv":0.0,"id":8231803},{"batb":[[2,1.52,26.58]],"ltp":0.0,"tv":0.0,"id":10616006},{"batb":[[2,1.52,22.93]],"ltp":0.0,"tv":0.0,"id":10170404},{"batb":[[2,1.52,26.58]],"ltp":0.0,"tv":0.0,"id":15608820},{"batb":[[2,1.52,22.6]],"ltp":0.0,"tv":0.0,"id":9001159},{"batb":[[2,1.52,22.6]],"ltp":0.0,"tv":0.0,"id":9193530},{"batb":[[2,1.52,22.93]],"ltp":0.0,"tv":0.0,"id":17352128}]}]}
{"op":"mcm","clk":"989776823","pt":1580491291321,"mc":[{"id":"1.168133548","rc":[{"batb":[[0,1.58,90],[1,1.56,4.99]],"ltp":0.0,"tv":0.0,"id":8429550},{"batb":[[0,1.58,90],[1,1.56,4.99]],"ltp":0.0,"tv":0.0,"id":9417341},{"batb":[[0,1.58,90],[1,1.56,4.99]],"ltp":0.0,"tv":0.0,"id":8231803},{"batb":[[0,1.58,90],[1,1.56,4.99]],"ltp":0.0,"tv":0.0,"id":10616006},{"batb":[[0,1.58,90],[1,1.56,4.99]],"ltp":0.0,"tv":0.0,"id":10170404},{"batb":[[0,1.58,90],[1,1.56,4.99]],"ltp":0.0,"tv":0.0,"id":15608820},{"batb":[[0,1.58,90],[1,1.56,4.99]],"ltp":0.0,"tv":0.0,"id":9001159},{"batb":[[0,1.58,90],[1,1.56,4.99]],"ltp":0.0,"tv":0.0,"id":9193530},{"batb":[[0,1.58,90],[1,1.56,4.99]],"ltp":0.0,"tv":0.0,"id":17352128}]}]}
{"op":"mcm","clk":"989776964","pt":1580491292539,"mc":[{"id":"1.168133548","rc":[{"batl":[[0,950,9],[1,970,3.23]],"ltp":0.0,"tv":0.0,"id":8429550},{"batl":[[0,950,9],[1,970,3.23]],"ltp":0.0,"tv":0.0,"id":9417341},{"batl":[[0,950,9],[1,970,3.23]],"ltp":0.0,"tv":0.0,"id":8231803},{"batl":[[0,36,9],[1,40,3.23]],"ltp":0.0,"tv":0.0,"id":10616006},{"batl":[[0,950,9],[1,970,3.23]],"ltp":0.0,"tv":0.0,"id":10170404},{"batl":[[0,950,9],[1,970,3.23]],"ltp":0.0,"tv":0.0,"id":15608820},{"batl":[[0,950,9],[1,970,3.23]],"ltp":0.0,"tv":0.0,"id":9001159},{"batl":[[0,950,9],[1,970,3.23]],"ltp":0.0,"tv":0.0,"id":9193530},{"batl":[[0,950,9],[1,970,3.23]],"ltp":0.0,"tv":0.0,"id":17352128}]}]}
{"op":"mcm","clk":"989777053","pt":1580491293328,"mc":[{"id":"1.168133548","rc":[{"batl":[[0,950,9.2],[1,970,3.03]],"ltp":0.0,"tv":0.0,"id":8429550},{"batl":[[0,950,9.2],[1,970,3.03]],"ltp":0.0,"tv":0.0,"id":9417341},{"batl":[[0,950,9.2],[1,970,3.03]],"ltp":0.0,"tv":0.0,"id":8231803},{"batl":[[0,36,9.2],[1,40,3.03]],"ltp":0.0,"tv":0.0,"id":10616006},{"batl":[[0,950,9.2],[1,970,3.03]],"ltp":0.0,"tv":0.0,"id":10170404},{"batl":[[0,950,9.2],[1,970,3.03]],"ltp":0.0,"tv":0.0,"id":15608820},{"batl":[[0,950,9.2],[1,970,3.03]],"ltp":0.0,"tv":0.0,"id":9001159},{"batl":[[0,950,9.2],[1,970,3.03]],"ltp":0.0,"tv":0.0,"id":9193530},{"batl":[[0,950,9.2],[1,970,3.03]],"ltp":0.0,"tv":0.0,"id":17352128}]}]}
{"op":"mcm","clk":"989777511","pt":1580491297241,"mc":[{"id":"1.168133548","rc":[{"batl":[[0,55,3],[1,950,9.2],[2,970,3.03]],"ltp":0.0,"tv":0.0,"id":9417341}]}]}
{"op":"mcm","clk":"989778639","pt":1580491307371,"mc":[{"id":"1.168133548","rc":[{"batb":[[2,1.52,21.84]],"ltp":0.0,"tv":0.0,"id":8429550},{"batb":[[2,1.52,23.21]],"batl":[[0,55,3.2],[1,950,9]],"ltp":0.0,"tv":0.0,"id":9417341},{"batb":[[2,1.52,22.17]],"ltp":0.0,"tv":0.0,"id":8231803},{"batb":[[2,1.52,25.49]],"ltp":0.0,"tv":0.0,"id":10616006},{"batb":[[2,1.52,21.84]],"ltp":0.0,"tv":0.0,"id":10170404},{"batb":[[2,1.52,25.49]],"ltp":0.0,"tv":0.0,"id":15608820},{"batb":[[2,1.52,21.52]],"ltp":0.0,"tv":0.0,"id":9001159},{"batb":[[2,1.52,21.52]],"ltp":0.0,"tv":0.0,"id":9193530},{"batb":[[2,1.52,21.84]],"ltp":0.0,"tv":0.0,"id":17352128}]}]}
{"op":"mcm","clk":"989779697","pt":1580491317189,"mc":[{"id":"1.168133548","rc":[{"batb":[[1,1.56,1.99]],"ltp":0.0,"tv":0.0,"id":8429550},{"batb":[[1,1.56,1.99]],"ltp":0.0,"tv":0.0,"id":9417341},{"batb":[[1,1.56,1.99]],"ltp":0.0,"tv":0.0,"id":8231803},{"batb":[[1,1.56,1.99]],"ltp":0.0,"tv":0.0,"id":10616006},{"batb":[[1,1.56,1.99]],"ltp":0.0,"tv":0.0,"id":10170404},{"batb":[[1,1.56,1.99]],"ltp":0.0,"tv":0.0,"id":15608820},{"batb":[[1,1.56,1.99]],"ltp":0.0,"tv":0.0,"id":9001159},{"batb":[[1,1.56,1.99]],"ltp":0.0,"tv":0.0,"id":9193530},{"batb":[[1,1.56,1.99]],"ltp":0.0,"tv":0.0,"id":17352128}]}]}
{"op":"mcm","clk":"989780151","pt":1580491321198,"mc":[{"id":"1.168133548","rc":[{"batb":[[0,1.59,1.04],[1,1.58,90],[2,1.56,1.99]],"ltp":0.0,"tv":0.0,"id":8429550},{"batb":[[0,1.59,1.04],[1,1.58,90],[2,1.56,1.99]],"ltp":0.0,"tv":0.0,"id":9417341},{"batb":[[0,1.59,1.04],[1,1.58,90],[2,1.56,1.99]],"ltp":0.0,"tv":0.0,"id":8231803},{"batb":[[0,1.59,1.04],[1,1.58,90],[2,1.56,1.99]],"ltp":0.0,"tv":0.0,"id":10616006},{"batb":[[0,1.59,1.04],[1,1.58,90],[2,1.56,1.99]],"ltp":0.0,"tv":0.0,"id":10170404},{"batb":[[0,1.59,1.04],[1,1.58,90],[2,1.56,1.99]],"ltp":0.0,"tv":0.0,"id":15608820},{"batb":[[0,1.59,1.04],[1,1.58,90],[2,1.56,1.99]],"ltp":0.0,"tv":0.0,"id":9001159},{"batb":[[0,1.59,1.04],[1,1.58,90],[2,1.56,1.99]],"ltp":0.0,"tv":0.0,"id":9193530},{"batb":[[0,1.59,1.04],[1,1.58,90],[2,1.56,1.99]],"ltp":0.0,"tv":0.0,"id":17352128}]}]}
{"op":"mcm","clk":"989781339","pt":1580491333491,"mc":[{"id":"1.168133548","rc":[{"batl":[[0,48,9],[1,55,3.2]],"ltp":0.0,"tv":0.0,"id":9417341}]}]}
{"op":"mcm","clk":"989781503","pt":1580491335417,"mc":[{"id":"1.168133548","rc":[{"batl":[[0,48,9.2],[1,55,3]],"ltp":0.0,"tv":0.0,"id":9417341}]}]}
{"op":"mcm","clk":"989796144","pt":1580491390321,"mc":[{"id":"1.168133548","rc":[{"batb":[[0,1.6,1.99],[1,1.59,1.04],[2,1.58,90]],"ltp":0.0,"tv":0.0,"id":9417341}]}]}
{"op":"mcm","clk":"989796190","pt":1580491390941,"mc":[{"id":"1.168133548","rc":[{"batb":[[0,1.6,1.99],[1,1.59,1.04],[2,1.58,90]],"ltp":0.0,"tv":0.0,"id":9001159}]}]}
{"op":"mcm","clk":"989796342","pt":1580491392514,"mc":[{"id":"1.168133548","rc":[{"batb":[[0,1.6,1.99],[1,1.59,1.04],[2,1.58,90]],"ltp":0.0,"tv":0.0,"id":8231803}]}]}
{"op":"mcm","clk":"989796360","pt":1580491392719,"mc":[{"id":"1.168133548","rc":[{"batb":[[0,1.6,1.99],[1,1.59,1.04],[2,1.58,90]],"ltp":0.0,"tv":0.0,"id":15608820}]}]}
{"op":"mcm","clk":"989796533","pt":1580491394545,"mc":[{"id":"1.168133548","rc":[{"batb":[[0,1.6,1.99],[1,1.59,1.04],[2,1.58,90]],"ltp":0.0,"tv":0.0,"id":8429550},{"batb":[[0,1.6,1.99],[1,1.59,1.04],[2,1.58,90]],"ltp":0.0,"tv":0.0,"id":10616006}]}]}
{"op":"mcm","clk":"989796671","pt":1580491395918,"mc":[{"id":"1.168133548","rc":[{"batb":[[0,1.6,1.99],[1,1.59,1.04],[2,1.58,90]],"ltp":0.0,"tv":0.0,"id":10170404}]}]}
{"op":"mcm","clk":"989796782","pt":1580491397046,"mc":[{"id":"1.168133548","rc":[{"batb":[[0,1.6,1.99],[1,1.59,1.04],[2,1.58,90]],"ltp":0.0,"tv":0.0,"id":9193530}]}]}
{"op":"mcm","clk":"989796879","pt":1580491398111,"mc":[{"id":"1.168133548","rc":[{"batb":[[0,1.6,1.99],[1,1.59,1.04],[2,1.58,90]],"ltp":0.0,"tv":0.0,"id":17352128}]}]}
{"op":"mcm","clk":"989797812","pt":1580491407460,"mc":[{"id":"1.168133548","rc":[{"batb":[[0,1.61,90],[1,1.6,1.99],[2,1.59,1.04]],"ltp":0.0,"tv":0.0,"id":8429550},{"batb":[[0,1.61,90],[1,1.6,1.99],[2,1.59,1.04]],"ltp":0.0,"tv":0.0,"id":9417341},{"batb":[[0,1.61,90],[1,1.6,1.99],[2,1.59,1.04]],"ltp":0.0,"tv":0.0,"id":8231803},{"batb":[[0,1.61,90],[1,1.6,1.99],[2,1.59,1.04]],"ltp":0.0,"tv":0.0,"id":10616006},{"batb":[[0,1.61,90],[1,1.6,1.99],[2,1.59,1.04]],"ltp":0.0,"tv":0.0,"id":10170404},{"batb":[[0,1.61,90],[1,1.6,1.99],[2,1.59,1.04]],"ltp":0.0,"tv":0.0,"id":15608820},{"batb":[[0,1.61,90],[1,1.6,1.99],[2,1.59,1.04]],"ltp":0.0,"tv":0.0,"id":9193530},{"batb":[[0,1.61,90],[1,1.6,1.99],[2,1.59,1.04]],"ltp":0.0,"tv":0.0,"id":9001159},{"batb":[[0,1.61,90],[1,1.6,1.99],[2,1.59,1.04]],"ltp":0.0,"tv":0.0,"id":17352128}]}]}
{"op":"mcm","clk":"989798864","pt":1580491417047,"mc":[{"id":"1.168133548","rc":[{"batb":[[0,4,60],[1,1.61,90],[2,1.6,1.99]],"ltp":0.0,"tv":0.0,"id":9193530}]}]}
{"op":"mcm","clk":"989801551","pt":1580491443979,"mc":[{"id":"1.168133548","rc":[{"batb":[[1,3.6,90],[2,2.74,12.33]],"ltp":0.0,"tv":0.0,"id":9193530}]}]}
{"op":"mcm","clk":"989805012","pt":1580491479234,"mc":[{"id":"1.168133548","rc":[{"batb":[[1,3.9,90]],"ltp":0.0,"tv":0.0,"id":9193530}]}]}
{"op":"mcm","clk":"989809351","pt":1580491522536,"mc":[{"id":"1.168133548","rc":[{"batb":[[0,1.62,1.99],[1,1.61,90]],"ltp":0.0,"tv":0.0,"id":9417341}]}]}
{"op":"mcm","clk":"989809467","pt":1580491523529,"mc":[{"id":"1.168133548","rc":[{"batb":[[0,1.62,1.99],[1,1.61,90]],"ltp":0.0,"tv":0.0,"id":9001159}]}]}
{"op":"mcm","clk":"989809548","pt":1580491524309,"mc":[{"id":"1.168133548","rc":[{"batb":[[0,1.62,1.99],[1,1.61,90]],"ltp":0.0,"tv":0.0,"id":8231803}]}]}
{"op":"mcm","clk":"989809629","pt":1580491525036,"mc":[{"id":"1.168133548","rc":[{"batb":[[0,1.62,1.99],[1,1.61,90]],"ltp":0.0,"tv":0.0,"id":15608820}]}]}
{"op":"mcm","clk":"989809773","pt":1580491526558,"mc":[{"id":"1.168133548","rc":[{"batb":[[1,1.59,1.04],[2,1.52,21.84]],"ltp":0.0,"tv":0.0,"id":8429550}]}]}
{"op":"mcm","clk":"989809825","pt":1580491527132,"mc":[{"id":"1.168133548","rc":[{"batb":[[0,1.62,1.99],[1,1.61,90],[2,1.59,1.04]],"ltp":0.0,"tv":0.0,"id":8429550},{"batb":[[0,1.62,1.99],[1,1.61,90]],"ltp":0.0,"tv":0.0,"id":10616006}]}]}
{"op":"mcm","clk":"989809954","pt":1580491528542,"mc":[{"id":"1.168133548","rc":[{"batb":[[0,1.62,1.99],[1,1.61,90]],"ltp":0.0,"tv":0.0,"id":10170404}]}]}
{"op":"mcm","clk":"989810046","pt":1580491529322,"mc":[{"id":"1.168133548","rc":[{"batb":[[0,4.1,1.99],[1,4,60],[2,3.9,90]],"ltp":0.0,"tv":0.0,"id":9193530},{"batb":[[0,1.62,1.99],[1,1.61,90]],"ltp":0.0,"tv":0.0,"id":17352128}]}]}
{"op":"mcm","clk":"989811168","pt":1580491540265,"mc":[{"id":"1.168133548","rc":[{"batb":[[2,3.95,6]],"ltp":0.0,"tv":0.0,"id":9193530}]}]}
{"op":"mcm","clk":"989825688","pt":1580491679559,"mc":[{"id":"1.168133548","rc":[{"batb":[[0,1.62,23.77]],"ltp":0.0,"tv":0.0,"id":9417341}]}]}
{"op":"mcm","clk":"989825814","pt":1580491680475,"mc":[{"id":"1.168133548","rc":[{"batl":[[0,46,3.23],[1,48,9],[2,55,3]],"ltp":0.0,"tv":0.0,"id":9417341},{"batb":[[0,1.62,22.18]],"batl":[[0,940,3.23],[1,950,9]],"ltp":0.0,"tv":0.0,"id":9001159}]}]}
{"op":"mcm","clk":"989825957","pt":1580491681400,"mc":[{"id":"1.168133548","rc":[{"batb":[[0,1.62,22.79]],"batl":[[0,940,3.23],[1,950,9]],"ltp":0.0,"tv":0.0,"id":8231803}]}]}
{"op":"mcm","clk":"989826085","pt":1580491682498,"mc":[{"id":"1.168133548","rc":[{"batb":[[0,1.62,22.48]],"batl":[[0,940,3.23],[1,950,9]],"ltp":0.0,"tv":0.0,"id":8429550},{"batl":[[0,46,3.03]],"ltp":0.0,"tv":0.0,"id":9417341},{"batl":[[0,940,3.03]],"ltp":0.0,"tv":0.0,"id":8231803},{"batb":[[0,1.62,25.91]],"batl":[[0,940,3.03],[1,950,9]],"ltp":0.0,"tv":0.0,"id":15608820},{"batl":[[0,940,3.03]],"ltp":0.0,"tv":0.0,"id":9001159}]}]}
{"op":"mcm","clk":"989826215","pt":1580491683514,"mc":[{"id":"1.168133548","rc":[{"batl":[[0,46,3.23]],"ltp":0.0,"tv":0.0,"id":9417341},{"batl":[[0,940,3.23]],"ltp":0.0,"tv":0.0,"id":8231803},{"batb":[[0,1.62,25.91]],"batl":[[0,34,3.23],[1,36,9]],"ltp":0.0,"tv":0.0,"id":10616006},{"batb":[[0,1.62,22.48]],"batl":[[1,970,0]],"ltp":0.0,"tv":0.0,"id":10170404},{"batl":[[0,940,3.23]],"ltp":0.0,"tv":0.0,"id":15608820},{"batl":[[0,940,3.23]],"ltp":0.0,"tv":0.0,"id":9001159}]}]}
{"op":"mcm","clk":"989826346","pt":1580491684490,"mc":[{"id":"1.168133548","rc":[{"batl":[[0,940,3.23],[1,950,9]],"ltp":0.0,"tv":0.0,"id":10170404},{"batb":[[0,4.1,9.96]],"batl":[[0,940,3.23],[1,950,9]],"ltp":0.0,"tv":0.0,"id":9193530},{"batb":[[0,1.62,22.48]],"batl":[[1,970,0]],"ltp":0.0,"tv":0.0,"id":17352128}]}]}
{"op":"mcm","clk":"989826471","pt":1580491685479,"mc":[{"id":"1.168133548","rc":[{"batl":[[0,940,3.23],[1,950,9]],"ltp":0.0,"tv":0.0,"id":17352128}]}]}
{"op":"mcm","clk":"989827340","pt":1580491693382,"mc":[{"id":"1.168133548","rc":[{"batb":[[0,1.64,90],[1,1.62,22.48]],"ltp":0.0,"tv":0.0,"id":8429550},{"batb":[[0,1.64,90],[1,1.62,23.77]],"ltp":0.0,"tv":0.0,"id":9417341},{"batb":[[0,1.64,90],[1,1.62,22.79]],"ltp":0.0,"tv":0.0,"id":8231803},{"batb":[[0,1.64,90],[1,1.62,25.91]],"ltp":0.0,"tv":0.0,"id":10616006},{"batb":[[0,1.64,90],[1,1.62,22.48]],"ltp":0.0,"tv":0.0,"id":10170404},{"batb":[[0,1.64,90],[1,1.62,25.91]],"ltp":0.0,"tv":0.0,"id":15608820},{"batb":[[0,1.64,90],[1,1.62,22.18]],"ltp":0.0,"tv":0.0,"id":9001159},{"batb":[[0,1.64,90],[1,1.62,22.48]],"ltp":0.0,"tv":0.0,"id":17352128}]}]}
{"op":"mcm","clk":"989827412","pt":1580491694002,"mc":[{"id":"1.168133548","rc":[{"batl":[[0,920,9],[1,940,3.23]],"ltp":0.0,"tv":0.0,"id":8429550},{"batl":[[0,42,9],[1,46,3.23]],"ltp":0.0,"tv":0.0,"id":9417341},{"batl":[[0,920,9],[1,940,3.23]],"ltp":0.0,"tv":0.0,"id":8231803},{"batl":[[0,920,9],[1,940,3.23]],"ltp":0.0,"tv":0.0,"id":10170404},{"batl":[[0,920,9],[1,940,3.23]],"ltp":0.0,"tv":0.0,"id":15608820},{"batl":[[0,920,9],[1,940,3.23]],"ltp":0.0,"tv":0.0,"id":9193530},{"batl":[[0,920,9],[1,940,3.23]],"ltp":0.0,"tv":0.0,"id":9001159},{"batl":[[0,920,9],[1,940,3.23]],"ltp":0.0,"tv":0.0,"id":17352128}]}]}
{"op":"mcm","clk":"989827779","pt":1580491697516,"mc":[{"id":"1.168133548","rc":[{"batl":[[0,920,9.2],[1,940,3.03]],"ltp":0.0,"tv":0.0,"id":8429550},{"batl":[[0,42,9.2],[1,46,3.03]],"ltp":0.0,"tv":0.0,"id":9417341},{"batl":[[0,920,9.2],[1,940,3.03]],"ltp":0.0,"tv":0.0,"id":8231803},{"batl":[[0,920,9.2],[1,940,3.03]],"ltp":0.0,"tv":0.0,"id":10170404},{"batl":[[0,920,9.2],[1,940,3.03]],"ltp":0.0,"tv":0.0,"id":15608820},{"batl":[[0,920,9.2],[1,940,3.03]],"ltp":0.0,"tv":0.0,"id":9193530},{"batl":[[0,920,9.2],[1,940,3.03]],"ltp":0.0,"tv":0.0,"id":9001159},{"batl":[[0,920,9.2],[1,940,3.03]],"ltp":0.0,"tv":0.0,"id":17352128}]}]}
{"op":"mcm","clk":"989828778","pt":1580491707536,"mc":[{"id":"1.168133548","rc":[{"batb":[[2,1.51,3.36]],"ltp":0.0,"tv":0.0,"id":8429550},{"batb":[[2,1.51,3.36]],"ltp":0.0,"tv":0.0,"id":9417341},{"batb":[[2,1.51,3.36]],"ltp":0.0,"tv":0.0,"id":8231803},{"batb":[[2,1.51,3.36]],"ltp":0.0,"tv":0.0,"id":10616006},{"batb":[[2,1.51,3.36]],"ltp":0.0,"tv":0.0,"id":10170404},{"batb":[[2,1.51,3.36]],"ltp":0.0,"tv":0.0,"id":15608820},{"batb":[[2,1.51,3.36]],"ltp":0.0,"tv":0.0,"id":9001159},{"batb":[[2,1.51,3.36]],"ltp":0.0,"tv":0.0,"id":17352128}]}]}
{"op":"mcm","clk":"989830091","pt":1580491721475,"mc":[{"id":"1.168133548","rc":[{"batb":[[0,1.64,91]],"ltp":0.0,"tv":0.0,"id":8429550},{"batb":[[0,1.64,91]],"ltp":0.0,"tv":0.0,"id":9417341},{"batb":[[0,1.64,91]],"ltp":0.0,"tv":0.0,"id":8231803},{"batb":[[0,1.64,91]],"ltp":0.0,"tv":0.0,"id":10616006},{"batb":[[0,1.64,91]],"ltp":0.0,"tv":0.0,"id":10170404},{"batb":[[0,1.64,91]],"ltp":0.0,"tv":0.0,"id":15608820},{"batb":[[0,4.1,10.36]],"ltp":0.0,"tv":0.0,"id":9193530},{"batb":[[0,1.64,91]],"ltp":0.0,"tv":0.0,"id":9001159},{"batb":[[0,1.64,91]],"ltp":0.0,"tv":0.0,"id":17352128}]}]}
{"op":"mcm","clk":"989833044","pt":1580491750519,"mc":[{"id":"1.168133548","rc":[{"batb":[[0,1.66,1.99],[1,1.64,91],[2,1.62,21.78]],"ltp":0.0,"tv":0.0,"id":9417341}]}]}
{"op":"mcm","clk":"989833210","pt":1580491752306,"mc":[{"id":"1.168133548","rc":[{"batb":[[0,1.66,1.99],[1,1.64,91],[2,1.62,20.19]],"ltp":0.0,"tv":0.0,"id":9001159}]}]}
{"op":"mcm","clk":"989833319","pt":1580491753306,"mc":[{"id":"1.168133548","rc":[{"batb":[[0,1.66,1.99],[1,1.64,91],[2,1.62,20.8]],"ltp":0.0,"tv":0.0,"id":8231803}]}]}
{"op":"mcm","clk":"989833376","pt":1580491753793,"mc":[{"id":"1.168133548","rc":[{"batb":[[0,1.66,1.99],[1,1.64,91],[2,1.62,23.92]],"ltp":0.0,"tv":0.0,"id":15608820}]}]}
{"op":"mcm","clk":"989833553","pt":1580491755417,"mc":[{"id":"1.168133548","rc":[{"batb":[[0,1.66,1.99],[1,1.64,91],[2,1.62,20.49]],"ltp":0.0,"tv":0.0,"id":8429550},{"batb":[[0,1.66,1.99],[1,1.64,91],[2,1.62,23.92]],"ltp":0.0,"tv":0.0,"id":10616006}]}]}
{"op":"mcm","clk":"989833678","pt":1580491756537,"mc":[{"id":"1.168133548","rc":[{"batb":[[0,1.66,1.99],[1,1.64,91],[2,1.62,20.49]],"ltp":0.0,"tv":0.0,"id":10170404}]}]}
{"op":"mcm","clk":"989833715","pt":1580491756894,"mc":[{"id":"1.168133548","rc":[{"batb":[[0,4.3,1.99],[1,4.1,8.37],[2,4,60]],"ltp":0.0,"tv":0.0,"id":9193530}]}]}
{"op":"mcm","clk":"989833812","pt":1580491757932,"mc":[{"id":"1.168133548","rc":[{"batb":[[0,1.66,1.99],[1,1.64,91],[2,1.62,20.49]],"ltp":0.0,"tv":0.0,"id":17352128}]}]}
{"op":"mcm","clk":"989834580","pt":1580491765538,"mc":[{"id":"1.168133548","rc":[{"batb":[[0,1.67,90],[1,1.66,1.99],[2,1.62,21.49]],"ltp":0.0,"tv":0.0,"id":8429550},{"batb":[[0,1.67,90],[1,1.66,1.99],[2,1.62,22.77]],"ltp":0.0,"tv":0.0,"id":9417341},{"batb":[[0,1.67,90],[1,1.66,1.99],[2,1.62,21.8]],"ltp":0.0,"tv":0.0,"id":8231803},{"batb":[[0,1.67,90],[1,1.66,1.99],[2,1.62,24.92]],"ltp":0.0,"tv":0.0,"id":10616006},{"batb":[[0,1.67,90],[1,1.66,1.99],[2,1.62,21.49]],"ltp":0.0,"tv":0.0,"id":10170404},{"batb":[[0,1.67,90],[1,1.66,1.99],[2,1.62,24.92]],"ltp":0.0,"tv":0.0,"id":15608820},{"batb":[[0,1.67,90],[1,1.66,1.99],[2,1.62,21.19]],"ltp":0.0,"tv":0.0,"id":9001159},{"batb":[[0,1.67,90],[1,1.66,1.99],[2,1.62,21.49]],"ltp":0.0,"tv":0.0,"id":17352128}]}]}
{"op":"mcm","clk":"989845002","pt":1580491852345,"mc":[{"id":"1.168133548","rc":[{"batb":[[0,1.68,1.99],[1,1.67,90]],"ltp":0.0,"tv":0.0,"id":9417341}]}]}
{"op":"mcm","clk":"989845208","pt":1580491853555,"mc":[{"id":"1.168133548","rc":[{"batb":[[0,1.68,1.99],[1,1.67,90]],"ltp":0.0,"tv":0.0,"id":9001159}]}]}
{"op":"mcm","clk":"989845325","pt":1580491854552,"mc":[{"id":"1.168133548","rc":[{"batb":[[0,1.68,1.99],[1,1.67,90]],"ltp":0.0,"tv":0.0,"id":8231803},{"batb":[[0,1.68,1.99],[1,1.67,90]],"ltp":0.0,"tv":0.0,"id":15608820}]}]}
{"op":"mcm","clk":"989845441","pt":1580491855443,"mc":[{"id":"1.168133548","rc":[{"batb":[[0,1.68,1.99],[1,1.67,90]],"ltp":0.0,"tv":0.0,"id":8429550},{"batb":[[0,1.68,1.99],[1,1.67,90]],"ltp":0.0,"tv":0.0,"id":10616006}]}]}
{"op":"mcm","clk":"989845563","pt":1580491856451,"mc":[{"id":"1.168133548","rc":[{"batb":[[0,1.68,1.99],[1,1.67,90]],"ltp":0.0,"tv":0.0,"id":10170404}]}]}
{"op":"mcm","clk":"989845762","pt":1580491857861,"mc":[{"id":"1.168133548","rc":[{"batb":[[0,1.68,1.99],[1,1.67,90]],"ltp":0.0,"tv":0.0,"id":17352128}]}]}
{"op":"mcm","clk":"989870541","pt":1580492044505,"mc":[{"id":"1.168133548","rc":[{"batb":[[0,2,5],[1,1.68,1.99],[2,1.67,90]],"ltp":0.0,"tv":0.0,"id":8429550}]}]}
{"op":"mcm","clk":"989870695","pt":1580492045720,"mc":[{"id":"1.168133548","rc":[{"batb":[[0,1.68,1.99],[1,1.67,90],[2,1.62,21.49]],"ltp":0.0,"tv":0.0,"id":8429550}]}]}
{"op":"mcm","clk":"989886066","pt":1580492165431,"mc":[{"id":"1.168133548","rc":[{"batb":[[0,1.68,22.99],[2,1.51,4.36]],"batl":[[0,40,3.23],[1,42,9]],"ltp":0.0,"tv":0.0,"id":9417341},{"batb":[[0,1.68,21.46],[2,1.51,4.36]],"batl":[[1,940,0]],"ltp":0.0,"tv":0.0,"id":9001159}]}]}
{"op":"mcm","clk":"989886234","pt":1580492166537,"mc":[{"id":"1.168133548","rc":[{"batb":[[0,1.68,22.05],[2,1.51,4.36]],"batl":[[0,910,3.23],[1,920,9]],"ltp":0.0,"tv":0.0,"id":8231803},{"batb":[[0,1.68,25.06],[2,1.51,4.36]],"ltp":0.0,"tv":0.0,"id":15608820},{"batl":[[0,910,3.23],[1,920,9]],"ltp":0.0,"tv":0.0,"id":9001159}]}]}
{"op":"mcm","clk":"989886366","pt":1580492167531,"mc":[{"id":"1.168133548","rc":[{"batb":[[0,1.68,21.75],[2,1.51,4.36]],"batl":[[0,910,3.23],[1,920,9]],"ltp":0.0,"tv":0.0,"id":8429550},{"batb":[[2,1.51,4.36]],"ltp":0.0,"tv":0.0,"id":10616006},{"batl":[[0,910,3.23],[1,920,9]],"ltp":0.0,"tv":0.0,"id":15608820}]}]}
{"op":"mcm","clk":"989886494","pt":1580492168427,"mc":[{"id":"1.168133548","rc":[{"batb":[[0,1.68,25.06]],"ltp":0.0,"tv":0.0,"id":10616006},{"batb":[[0,1.68,21.75],[2,1.51,4.36]],"batl":[[0,910,3.23],[1,920,9]],"ltp":0.0,"tv":0.0,"id":10170404},{"batl":[[0,910,3.23],[1,920,9]],"ltp":0.0,"tv":0.0,"id":9193530}]}]}
{"op":"mcm","clk":"989886657","pt":1580492169534,"mc":[{"id":"1.168133548","rc":[{"batb":[[0,1.68,21.75],[2,1.51,4.36]],"batl":[[0,910,3.23],[1,920,9]],"ltp":0.0,"tv":0.0,"id":17352128}]}]}
{"op":"mcm","clk":"989890230","pt":1580492196554,"mc":[{"id":"1.168133548","rc":[{"batb":[[0,1.7,90],[1,1.68,21.75]],"ltp":0.0,"tv":0.0,"id":8429550},{"batb":[[0,1.7,90],[1,1.68,22.99]],"ltp":0.0,"tv":0.0,"id":9417341},{"batb":[[0,1.7,90],[1,1.68,22.05]],"ltp":0.0,"tv":0.0,"id":8231803},{"batb":[[0,1.7,90],[1,1.68,25.06]],"ltp":0.0,"tv":0.0,"id":10616006},{"batb":[[0,1.7,90],[1,1.68,21.75]],"ltp":0.0,"tv":0.0,"id":10170404},{"batb":[[0,1.7,90],[1,1.68,25.06]],"ltp":0.0,"tv":0.0,"id":15608820},{"batb":[[0,1.7,90],[1,1.68,21.46]],"ltp":0.0,"tv":0.0,"id":9001159},{"batb":[[0,1.7,90],[1,1.68,21.75]],"ltp":0.0,"tv":0.0,"id":17352128}]}]}
{"op":"mcm","clk":"989890267","pt":1580492196828,"mc":[{"id":"1.168133548","rc":[{"batl":[[0,890,9],[1,910,3.23]],"ltp":0.0,"tv":0.0,"id":8429550},{"batl":[[0,36,9],[1,40,3.23]],"ltp":0.0,"tv":0.0,"id":9417341},{"batl":[[0,890,9],[1,910,3.23]],"ltp":0.0,"tv":0.0,"id":8231803},{"batl":[[0,890,9],[1,910,3.23]],"ltp":0.0,"tv":0.0,"id":10170404},{"batl":[[0,890,9],[1,910,3.23]],"ltp":0.0,"tv":0.0,"id":15608820},{"batl":[[0,890,9],[1,910,3.23]],"ltp":0.0,"tv":0.0,"id":9193530},{"batl":[[0,890,9],[1,910,3.23]],"ltp":0.0,"tv":0.0,"id":9001159},{"batl":[[0,890,9],[1,910,3.23]],"ltp":0.0,"tv":0.0,"id":17352128}]}]}
{"op":"mcm","clk":"989892748","pt":1580492217541,"mc":[{"id":"1.168133548","rc":[{"batb":[[2,1.51,3.36]],"ltp":0.0,"tv":0.0,"id":8429550},{"batb":[[2,1.51,3.36]],"ltp":0.0,"tv":0.0,"id":9417341},{"batb":[[2,1.51,3.36]],"ltp":0.0,"tv":0.0,"id":8231803},{"batb":[[2,1.51,3.36]],"ltp":0.0,"tv":0.0,"id":10616006},{"batb":[[2,1.51,3.36]],"ltp":0.0,"tv":0.0,"id":10170404},{"batb":[[2,1.51,3.36]],"ltp":0.0,"tv":0.0,"id":15608820},{"batb":[[2,1.51,3.36]],"ltp":0.0,"tv":0.0,"id":9001159},{"batb":[[2,1.51,3.36]],"ltp":0.0,"tv":0.0,"id":17352128}]}]}
{"op":"mcm","clk":"989906485","pt":1580492252489,"mc":[{"id":"1.168133548","rc":[{"batb":[[0,1.71,1.99],[1,1.7,90],[2,1.68,21]],"ltp":0.0,"tv":0.0,"id":9417341},{"batb":[[1,1.68,19.47]],"ltp":0.0,"tv":0.0,"id":9001159}]}]}
{"op":"mcm","clk":"989906522","pt":1580492252751,"mc":[{"id":"1.168133548","rc":[{"batb":[[0,1.71,1.99],[1,1.7,90],[2,1.68,19.47]],"ltp":0.0,"tv":0.0,"id":9001159}]}]}
{"op":"mcm","clk":"989906645","pt":1580492254002,"mc":[{"id":"1.168133548","rc":[{"batb":[[0,1.71,1.99],[1,1.7,90],[2,1.68,20.06]],"ltp":0.0,"tv":0.0,"id":8231803}]}]}
{"op":"mcm","clk":"989906850","pt":1580492255795,"mc":[{"id":"1.168133548","rc":[{"batb":[[0,1.71,1.99],[1,1.7,90],[2,1.68,23.07]],"ltp":0.0,"tv":0.0,"id":15608820}]}]}
{"op":"mcm","clk":"989906982","pt":1580492257105,"mc":[{"id":"1.168133548","rc":[{"batb":[[0,1.71,1.99],[1,1.7,90],[2,1.68,19.76]],"ltp":0.0,"tv":0.0,"id":8429550},{"batb":[[1,1.68,23.07]],"ltp":0.0,"tv":0.0,"id":10616006}]}]}
{"op":"mcm","clk":"989907072","pt":1580492258003,"mc":[{"id":"1.168133548","rc":[{"batb":[[0,1.71,1.99],[1,1.7,90],[2,1.68,19.76]],"ltp":0.0,"tv":0.0,"id":10170404}]}]}
{"op":"mcm","clk":"989907234","pt":1580492259209,"mc":[{"id":"1.168133548","rc":[{"batb":[[0,1.71,1.99],[1,1.7,90],[2,1.68,19.76]],"ltp":0.0,"tv":0.0,"id":17352128}]}]}
{"op":"mcm","clk":"990017014","pt":1580493240445,"mc":[{"id":"1.168133548","rc":[{"batb":[[0,1.71,22.62],[2,1.51,3.36]],"batl":[[1,55,3.2],[2,55,0]],"ltp":0.0,"tv":0.0,"id":9417341}]}]}
{"op":"mcm","clk":"990017113","pt":1580493241537,"mc":[{"id":"1.168133548","rc":[{"batl":[[0,34,3.03],[1,36,9],[2,55,3.2]],"ltp":0.0,"tv":0.0,"id":9417341},{"batb":[[2,1.51,3.36]],"ltp":0.0,"tv":0.0,"id":8231803},{"batb":[[0,1.71,21.12],[2,1.51,3.36]],"batl":[[0,880,3.03],[1,890,9],[2,910,0.2]],"ltp":0.0,"tv":0.0,"id":9001159}]}]}
{"op":"mcm","clk":"990017221","pt":1580493242535,"mc":[{"id":"1.168133548","rc":[{"batb":[[0,1.71,21.7]],"batl":[[0,880,3.03],[1,890,9],[2,910,0.2]],"ltp":0.0,"tv":0.0,"id":8231803},{"batb":[[0,1.71,24.65],[2,1.51,3.36]],"batl":[[0,880,3.03],[1,890,9],[2,910,0.2]],"ltp":0.0,"tv":0.0,"id":15608820}]}]}
{"op":"mcm","clk":"990017313","pt":1580493243469,"mc":[{"id":"1.168133548","rc":[{"batb":[[0,1.71,21.41],[2,1.51,3.36]],"batl":[[0,880,3.03],[1,890,9],[2,910,0.2]],"ltp":0.0,"tv":0.0,"id":8429550},{"batb":[[0,1.71,22.66],[1,1.7,90]],"ltp":0.0,"tv":0.0,"id":10616006}]}]}
{"op":"mcm","clk":"990017428","pt":1580493244574,"mc":[{"id":"1.168133548","rc":[{"batb":[[0,1.71,21.41],[2,1.51,3.36]],"batl":[[0,880,3.03],[1,890,9],[2,910,0.2]],"ltp":0.0,"tv":0.0,"id":10170404},{"batl":[[0,880,3.03],[1,890,9],[2,910,0.2]],"ltp":0.0,"tv":0.0,"id":9193530},{"batb":[[0,1.71,21.41],[2,1.51,3.36]],"ltp":0.0,"tv":0.0,"id":17352128}]}]}
{"op":"mcm","clk":"990017442","pt":1580493244771,"mc":[{"id":"1.168133548","rc":[{"batl":[[0,880,3.03],[1,890,9],[2,910,0.2]],"ltp":0.0,"tv":0.0,"id":17352128}]}]}
{"op":"mcm","clk":"990019833","pt":1580493271473,"mc":[{"id":"1.168133548","rc":[{"batb":[[0,1.73,90],[1,1.71,21.41]],"ltp":0.0,"tv":0.0,"id":8429550},{"batb":[[0,1.73,90],[1,1.71,22.62]],"ltp":0.0,"tv":0.0,"id":9417341},{"batb":[[0,1.73,90],[1,1.71,21.7]],"ltp":0.0,"tv":0.0,"id":8231803},{"batb":[[0,1.73,90],[1,1.71,22.66]],"ltp":0.0,"tv":0.0,"id":10616006},{"batb":[[0,1.73,90],[1,1.71,21.41]],"ltp":0.0,"tv":0.0,"id":10170404},{"batb":[[0,1.73,90],[1,1.71,24.65]],"ltp":0.0,"tv":0.0,"id":15608820},{"batb":[[0,1.73,90],[1,1.71,21.12]],"ltp":0.0,"tv":0.0,"id":9001159},{"batb":[[0,1.73,90],[1,1.71,21.41]],"ltp":0.0,"tv":0.0,"id":17352128}]}]}
{"op":"mcm","clk":"990019850","pt":1580493271779,"mc":[{"id":"1.168133548","rc":[{"batl":[[0,860,9],[1,880,3.03]],"ltp":0.0,"tv":0.0,"id":8429550},{"batl":[[0,30,9],[1,34,3.03]],"ltp":0.0,"tv":0.0,"id":9417341},{"batl":[[0,860,9],[1,880,3.03]],"ltp":0.0,"tv":0.0,"id":8231803},{"batl":[[0,860,9],[1,880,3.03]],"ltp":0.0,"tv":0.0,"id":10170404},{"batl":[[0,860,9],[1,880,3.03]],"ltp":0.0,"tv":0.0,"id":15608820},{"batl":[[0,860,9],[1,880,3.03]],"ltp":0.0,"tv":0.0,"id":9001159},{"batl":[[0,860,9],[1,880,3.03]],"ltp":0.0,"tv":0.0,"id":9193530},{"batl":[[0,860,9],[1,880,3.03]],"ltp":0.0,"tv":0.0,"id":17352128}]}]}
{"op":"mcm","clk":"990021664","pt":1580493292496,"mc":[{"id":"1.168133548","rc":[{"batb":[[0,1.74,1.99],[1,1.73,90],[2,1.71,20.63]],"ltp":0.0,"tv":0.0,"id":9417341},{"batb":[[0,1.74,1.99],[1,1.73,90],[2,1.71,19.13]],"ltp":0.0,"tv":0.0,"id":9001159}]}]}
{"op":"mcm","clk":"990021739","pt":1580493293499,"mc":[{"id":"1.168133548","rc":[{"batb":[[1,1.71,19.71]],"ltp":0.0,"tv":0.0,"id":8231803}]}]}
{"op":"mcm","clk":"990021810","pt":1580493294519,"mc":[{"id":"1.168133548","rc":[{"batb":[[0,1.74,1.99],[1,1.73,90],[2,1.71,19.71]],"ltp":0.0,"tv":0.0,"id":8231803},{"batb":[[1,1.71,22.66]],"ltp":0.0,"tv":0.0,"id":15608820}]}]}
{"op":"mcm","clk":"990021889","pt":1580493295300,"mc":[{"id":"1.168133548","rc":[{"batb":[[0,1.74,1.99],[1,1.73,90],[2,1.71,19.42]],"ltp":0.0,"tv":0.0,"id":8429550},{"batb":[[0,1.74,1.99],[1,1.73,90],[2,1.71,22.66]],"ltp":0.0,"tv":0.0,"id":15608820}]}]}
{"op":"mcm","clk":"990021987","pt":1580493296495,"mc":[{"id":"1.168133548","rc":[{"batb":[[0,1.74,1.99],[1,1.73,90],[2,1.71,19.42]],"ltp":0.0,"tv":0.0,"id":10170404}]}]}
{"op":"mcm","clk":"990022085","pt":1580493297531,"mc":[{"id":"1.168133548","rc":[{"batb":[[1,1.71,19.42]],"ltp":0.0,"tv":0.0,"id":17352128}]}]}
{"op":"mcm","clk":"990022169","pt":1580493298506,"mc":[{"id":"1.168133548","rc":[{"batb":[[0,1.74,1.99],[1,1.73,90],[2,1.71,19.42]],"ltp":0.0,"tv":0.0,"id":17352128}]}]}
{"op":"mcm","clk":"990024105","pt":1580493320378,"mc":[{"id":"1.168133548","rc":[{"batl":[[0,21,6],[1,860,9],[2,880,3.03]],"ltp":0.0,"tv":0.0,"id":17352128}]}]}
{"op":"mcm","clk":"990025656","pt":1580493338397,"mc":[{"id":"1.168133548","rc":[{"batl":[[1,48,9]],"ltp":0.0,"tv":0.0,"id":17352128}]}]}
{"op":"mcm","clk":"990082795","pt":1580493999310,"mc":[{"id":"1.168133548","rc":[{"batb":[[2,1.71,19.39]],"batl":[[1,880,3.03]],"ltp":0.0,"tv":0.0,"id":8429550},{"batb":[[0,3.2,30],[1,1.74,1.99],[2,1.73,90]],"batl":[[1,34,3.03]],"ltp":0.0,"tv":0.0,"id":9417341},{"batb":[[2,1.71,19.69]],"batl":[[1,880,3.03]],"ltp":0.0,"tv":0.0,"id":8231803},{"batb":[[1,1.71,22.64],[2,1.51,3.36]],"batl":[[0,34,3.23]],"ltp":0.0,"tv":0.0,"id":10616006},{"batb":[[2,1.71,19.39]],"batl":[[1,880,3.03]],"ltp":0.0,"tv":0.0,"id":10170404},{"batb":[[2,1.71,22.64]],"batl":[[1,880,3.03]],"ltp":0.0,"tv":0.0,"id":15608820},{"batb":[[2,1.71,19.1]],"batl":[[1,880,3.03]],"ltp":0.0,"tv":0.0,"id":9001159},{"batb":[[1,4.1,8.36]],"batl":[[1,880,3.03]],"ltp":0.0,"tv":0.0,"id":9193530},{"batb":[[2,1.71,19.39]],"batl":[[2,880,3.03]],"ltp":0.0,"tv":0.0,"id":17352128}]}]}
{"op":"mcm","clk":"990083506","pt":1580494007223,"mc":[{"id":"1.168133548","rc":[{"batb":[[1,2.38,90],[2,1.83,190.67]],"ltp":0.0,"tv":0.0,"id":9417341}]}]}
{"op":"mcm","clk":"990083702","pt":1580494009646,"mc":[{"id":"1.168133548","rc":[{"batb":[[0,4,20],[1,1.74,1.99],[2,1.73,90]],"ltp":0.0,"tv":0.0,"id":8231803}]}]}
{"op":"mcm","clk":"990084968","pt":1580494022568,"mc":[{"id":"1.168133548","rc":[{"batb":[[0,4.4,15],[1,1.74,1.99],[2,1.73,90]],"ltp":0.0,"tv":0.0,"id":8429550}]}]}
{"op":"mcm","clk":"990085496","pt":1580494028439,"mc":[{"id":"1.168133548","rc":[{"batb":[[0,3.25,1.99],[1,3.2,30],[2,2.38,90]],"ltp":0.0,"tv":0.0,"id":9417341}]}]}
{"op":"mcm","clk":"990085711","pt":1580494030561,"mc":[{"id":"1.168133548","rc":[{"batb":[[0,4.1,1.99],[1,4,20]],"ltp":0.0,"tv":0.0,"id":8231803}]}]}
{"op":"mcm","clk":"990085765","pt":1580494031051,"mc":[{"id":"1.168133548","rc":[{"batb":[[0,5,20],[1,1.74,1.99],[2,1.73,90]],"ltp":0.0,"tv":0.0,"id":17352128}]}]}
{"op":"mcm","clk":"990085976","pt":1580494033160,"mc":[{"id":"1.168133548","rc":[{"batb":[[0,4.5,1.99],[1,4.4,15]],"ltp":0.0,"tv":0.0,"id":8429550}]}]}
{"op":"mcm","clk":"990086566","pt":1580494039547,"mc":[{"id":"1.168133548","rc":[{"batb":[[2,1.71,19.39]],"ltp":0.0,"tv":0.0,"id":8429550},{"batb":[[2,1.71,19.69]],"ltp":0.0,"tv":0.0,"id":8231803},{"batb":[[2,1.71,19.39]],"ltp":0.0,"tv":0.0,"id":17352128}]}]}
{"op":"mcm","clk":"990086658","pt":1580494040549,"mc":[{"id":"1.168133548","rc":[{"batb":[[2,2.88,90]],"ltp":0.0,"tv":0.0,"id":8429550},{"batb":[[2,2.64,90]],"ltp":0.0,"tv":0.0,"id":8231803},{"batb":[[1,3.9,90],[2,2.74,12.33]],"ltp":0.0,"tv":0.0,"id":17352128}]}]}
{"op":"mcm","clk":"990087358","pt":1580494047764,"mc":[{"id":"1.168133548","rc":[{"batb":[[0,4.6,18],[1,1.74,1.99],[2,1.73,90]],"ltp":0.0,"tv":0.0,"id":10170404}]}]}
{"op":"mcm","clk":"990097917","pt":1580494059399,"mc":[{"id":"1.168133548","rc":[{"batb":[[0,5,20],[1,1.74,1.99],[2,1.73,90]],"ltp":0.0,"tv":0.0,"id":9001159}]}]}
{"op":"mcm","clk":"990099060","pt":1580494072371,"mc":[{"id":"1.168133548","rc":[{"batb":[[1,3.25,90],[2,2.36,58.79]],"ltp":0.0,"tv":0.0,"id":10170404},{"batb":[[1,2.36,90],[2,1.82,195.2]],"ltp":0.0,"tv":0.0,"id":9001159}]}]}
{"op":"mcm","clk":"990099760","pt":1580494079985,"mc":[{"id":"1.168133548","rc":[{"batb":[[0,6,10],[1,4.3,1.99],[2,4.1,8.36]],"ltp":0.0,"tv":0.0,"id":9193530}]}]}
{"op":"mcm","clk":"990100592","pt":1580494089384,"mc":[{"id":"1.168133548","rc":[{"batb":[[0,6.6,10],[1,1.74,1.99],[2,1.73,90]],"ltp":0.0,"tv":0.0,"id":15608820}]}]}
{"op":"mcm","clk":"990100670","pt":1580494090285,"mc":[{"id":"1.168133548","rc":[{"batl":[[2,1000,2]],"ltp":0.0,"tv":0.0,"id":10616006}]}]}
{"op":"mcm","clk":"990100759","pt":1580494091398,"mc":[{"id":"1.168133548","rc":[{"batl":[[0,30,9.17]],"ltp":0.0,"tv":0.0,"id":9417341}]}]}
{"op":"mcm","clk":"990100861","pt":1580494092517,"mc":[{"id":"1.168133548","rc":[{"batb":[[0,4.1,3.21]],"ltp":0.0,"tv":0.0,"id":8231803},{"batl":[[0,34,3.39],[2,1000,0]],"ltp":0.0,"tv":0.0,"id":10616006}]}]}
{"op":"mcm","clk":"990100964","pt":1580494093523,"mc":[{"id":"1.168133548","rc":[{"batl":[[0,21,6.25]],"ltp":0.0,"tv":0.0,"id":17352128}]}]}
{"op":"mcm","clk":"990101245","pt":1580494096525,"mc":[{"id":"1.168133548","rc":[{"batb":[[0,8,10],[1,1.73,90],[2,1.71,22.64]],"ltp":0.0,"tv":0.0,"id":10616006}]}]}
{"op":"mcm","clk":"990101416","pt":1580494098411,"mc":[{"id":"1.168133548","rc":[{"batb":[[2,4.1,7.96]],"ltp":0.0,"tv":0.0,"id":9193530}]}]}
{"op":"mcm","clk":"990102045","pt":1580494104485,"mc":[{"id":"1.168133548","rc":[{"batb":[[1,3.4,90]],"ltp":0.0,"tv":0.0,"id":10616006},{"batb":[[1,2.76,90],[2,1.74,1.99]],"ltp":0.0,"tv":0.0,"id":15608820}]}]}
{"op":"mcm","clk":"990102139","pt":1580494105428,"mc":[{"id":"1.168133548","rc":[{"batb":[[2,2.44,46.15]],"ltp":0.0,"tv":0.0,"id":10616006},{"batb":[[2,2.06,117.04]],"ltp":0.0,"tv":0.0,"id":15608820}]}]}
{"op":"mcm","clk":"990102192","pt":1580494106007,"mc":[{"id":"1.168133548","rc":[{"batb":[[0,4.5,3.1]],"ltp":0.0,"tv":0.0,"id":8429550},{"batb":[[0,5,20.98]],"ltp":0.0,"tv":0.0,"id":17352128}]}]}
{"op":"mcm","clk":"990102748","pt":1580494111518,"mc":[{"id":"1.168133548","rc":[{"batb":[[0,4.5,3.46]],"ltp":0.0,"tv":0.0,"id":8429550},{"batb":[[0,3.25,2.5]],"ltp":0.0,"tv":0.0,"id":9417341},{"batb":[[0,4.1,3.6]],"ltp":0.0,"tv":0.0,"id":8231803},{"batb":[[0,8,10.2]],"ltp":0.0,"tv":0.0,"id":10616006},{"batb":[[0,4.6,18.35]],"ltp":0.0,"tv":0.0,"id":10170404},{"batb":[[0,6.6,10.24]],"ltp":0.0,"tv":0.0,"id":15608820},{"batb":[[0,5,20.32]],"ltp":0.0,"tv":0.0,"id":9001159},{"batb":[[0,6,10.27]],"ltp":0.0,"tv":0.0,"id":9193530}]}]}
{"op":"mcm","clk":"990102756","pt":1580494111625,"mc":[{"id":"1.168133548","rc":[{"batb":[[0,5.1,1.3],[1,5,20],[2,3.9,90]],"ltp":0.0,"tv":0.0,"id":17352128}]}]}
{"op":"mcm","clk":"990105173","pt":1580494135559,"mc":[{"id":"1.168133548","rc":[{"batb":[[0,5.1,1.3],[1,5,20],[2,2.36,90]],"ltp":0.0,"tv":0.0,"id":9001159}]}]}
{"op":"mcm","clk":"990105191","pt":1580494135675,"mc":[{"id":"1.168133548","rc":[{"batb":[[0,4.7,1.41],[1,4.6,18],[2,3.25,90]],"ltp":0.0,"tv":0.0,"id":10170404}]}]}
{"op":"mcm","clk":"990106157","pt":1580494144991,"mc":[{"id":"1.168133548","rc":[{"batb":[[0,4.5,5.98]],"ltp":0.0,"tv":0.0,"id":8429550},{"batb":[[0,3.25,5.02]],"ltp":0.0,"tv":0.0,"id":9417341},{"batb":[[0,4.1,6.12]],"ltp":0.0,"tv":0.0,"id":8231803},{"batb":[[0,8.2,2.72],[1,8,10],[2,3.4,90]],"ltp":0.0,"tv":0.0,"id":10616006},{"batb":[[0,4.7,3.93]],"ltp":0.0,"tv":0.0,"id":10170404},{"batb":[[0,6.8,2.76],[1,6.6,10],[2,2.76,90]],"ltp":0.0,"tv":0.0,"id":15608820},{"batb":[[0,5.1,3.82]],"ltp":0.0,"tv":0.0,"id":9001159},{"batb":[[0,6.2,2.79],[1,6,10],[2,4.3,1.99]],"ltp":0.0,"tv":0.0,"id":9193530},{"batb":[[0,5.1,3.82]],"ltp":0.0,"tv":0.0,"id":17352128}]}]}
{"op":"mcm","clk":"990108042","pt":1580494167488,"mc":[{"id":"1.168133548","rc":[{"batb":[[0,6.8,3.5]],"ltp":0.0,"tv":0.0,"id":15608820},{"batb":[[0,6.2,3.6]],"ltp":0.0,"tv":0.0,"id":9193530}]}]}
{"op":"mcm","clk":"990108050","pt":1580494167593,"mc":[{"id":"1.168133548","rc":[{"batb":[[0,8.2,3.33]],"ltp":0.0,"tv":0.0,"id":10616006}]}]}
{"op":"mcm","clk":"990109189","pt":1580494181528,"mc":[{"id":"1.168133548","rc":[{"batb":[[0,5.2,1.99],[1,5.1,3.82],[2,5,20]],"ltp":0.0,"tv":0.0,"id":9001159}]}]}
{"op":"mcm","clk":"990109241","pt":1580494182245,"mc":[{"id":"1.168133548","rc":[{"batb":[[0,4.3,1.99],[1,4.1,4.13],[2,4,20]],"ltp":0.0,"tv":0.0,"id":8231803}]}]}
{"op":"mcm","clk":"990109444","pt":1580494184245,"mc":[{"id":"1.168133548","rc":[{"batb":[[0,7,1.99],[1,6.8,3.5],[2,6.6,10]],"ltp":0.0,"tv":0.0,"id":15608820}]}]}
{"op":"mcm","clk":"990109522","pt":1580494185141,"mc":[{"id":"1.168133548","rc":[{"batb":[[0,4.7,1.99],[1,4.5,3.99],[2,4.4,15]],"ltp":0.0,"tv":0.0,"id":8429550}]}]}
{"op":"mcm","clk":"990109649","pt":1580494186350,"mc":[{"id":"1.168133548","rc":[{"batb":[[0,4.8,1.99],[1,4.7,3.93],[2,4.6,18]],"ltp":0.0,"tv":0.0,"id":10170404},{"batb":[[0,6.4,1.99],[1,6.2,3.6],[2,6,10]],"ltp":0.0,"tv":0.0,"id":9193530}]}]}
{"op":"mcm","clk":"990109713","pt":1580494186933,"mc":[{"id":"1.168133548","rc":[{"batb":[[0,5.2,1.99],[1,5.1,3.82],[2,5,20]],"ltp":0.0,"tv":0.0,"id":17352128}]}]}
{"op":"mcm","clk":"990112951","pt":1580494221502,"mc":[{"id":"1.168133548","rc":[{"batb":[[0,3.3,1.98],[1,3.25,5.02],[2,3.2,30]],"ltp":0.0,"tv":0.0,"id":9417341},{"batb":[[0,4.8,3.19]],"ltp":0.0,"tv":0.0,"id":10170404},{"batb":[[0,6.4,2.8]],"ltp":0.0,"tv":0.0,"id":9193530},{"batb":[[0,5.3,1.06],[1,5.2,1.99],[2,5.1,3.82]],"ltp":0.0,"tv":0.0,"id":17352128}]}]}
{"op":"mcm","clk":"990113028","pt":1580494222197,"mc":[{"id":"1.168133548","rc":[{"batb":[[1,4.6,1.62],[2,4.5,3.63]],"ltp":0.0,"tv":0.0,"id":8429550},{"batb":[[1,4.2,1.82],[2,4.1,3.74]],"ltp":0.0,"tv":0.0,"id":8231803},{"batb":[[0,4.9,1.02],[1,4.8,3.19],[2,4.7,2.87]],"ltp":0.0,"tv":0.0,"id":10170404},{"batb":[[0,5.3,1.06],[1,5.2,1.99],[2,5.1,3.82]],"ltp":0.0,"tv":0.0,"id":9001159}]}]}
{"op":"mcm","clk":"990115620","pt":1580494250474,"mc":[{"id":"1.168133548","rc":[{"batb":[[1,4.8,1.99]],"ltp":0.0,"tv":0.0,"id":10170404}]}]}
{"op":"mcm","clk":"990115765","pt":1580494252004,"mc":[{"id":"1.168133548","rc":[{"batb":[[0,4.9,2.19]],"ltp":0.0,"tv":0.0,"id":10170404}]}]}
{"op":"mcm","clk":"990121520","pt":1580494314544,"mc":[{"id":"1.168133548","rc":[{"batb":[[0,3.3,11.22]],"batl":[[0,29,3.2],[1,30,9]],"ltp":0.0,"tv":0.0,"id":9417341},{"batb":[[0,5.3,4.09]],"ltp":0.0,"tv":0.0,"id":9001159}]}]}
{"op":"mcm","clk":"990121623","pt":1580494315548,"mc":[{"id":"1.168133548","rc":[{"batb":[[0,4.3,5.02],[2,4.1,2.52]],"batl":[[0,850,3.03],[1,860,9]],"ltp":0.0,"tv":0.0,"id":8231803},{"batb":[[0,7,5.86]],"ltp":0.0,"tv":0.0,"id":15608820},{"batb":[[0,5.3,5.02],[2,5.1,2.84]],"batl":[[0,850,3.03],[1,860,9]],"ltp":0.0,"tv":0.0,"id":9001159}]}]}
{"op":"mcm","clk":"990121716","pt":1580494316543,"mc":[{"id":"1.168133548","rc":[{"batb":[[0,4.7,5.02]],"batl":[[0,850,3.03],[1,860,9]],"ltp":0.0,"tv":0.0,"id":8429550},{"batb":[[0,4.4,1.14],[1,4.3,5.02],[2,4.2,1.82]],"ltp":0.0,"tv":0.0,"id":8231803},{"batb":[[0,8.4,3.33],[1,8.2,3.33],[2,8,10]],"ltp":0.0,"tv":0.0,"id":10616006},{"batb":[[0,7,6.55],[1,6.8,2.76]],"batl":[[0,850,3.03],[1,860,9]],"ltp":0.0,"tv":0.0,"id":15608820}]}]}
{"op":"mcm","clk":"990121786","pt":1580494317483,"mc":[{"id":"1.168133548","rc":[{"batb":[[2,4.5,2.52]],"ltp":0.0,"tv":0.0,"id":8429550},{"batb":[[1,8.2,2.72]],"ltp":0.0,"tv":0.0,"id":10616006},{"batb":[[0,4.9,8.45]],"batl":[[0,850,3.03],[1,860,9]],"ltp":0.0,"tv":0.0,"id":10170404}]}]}
{"op":"mcm","clk":"990121877","pt":1580494318499,"mc":[{"id":"1.168133548","rc":[{"batb":[[0,4.8,1.04],[1,4.7,5.02],[2,4.6,1.62]],"ltp":0.0,"tv":0.0,"id":8429550},{"batb":[[0,8.4,3.91]],"ltp":0.0,"tv":0.0,"id":10616006},{"batb":[[0,6.4,6.9],[1,6.2,2.79]],"batl":[[0,850,3.03],[1,860,9]],"ltp":0.0,"tv":0.0,"id":9193530},{"batb":[[0,5.3,4.09]],"batl":[[0,20,3.28],[1,21,6],[2,48,9]],"ltp":0.0,"tv":0.0,"id":17352128}]}]}
{"op":"mcm","clk":"990121974","pt":1580494319480,"mc":[{"id":"1.168133548","rc":[{"batb":[[0,6.6,1.57],[1,6.4,6.09],[2,6.2,2.79]],"ltp":0.0,"tv":0.0,"id":9193530},{"batb":[[0,5.3,5.02],[2,5.1,2.84]],"ltp":0.0,"tv":0.0,"id":17352128}]}]}
{"op":"mcm","clk":"990122365","pt":1580494323989,"mc":[{"id":"1.168133548","rc":[{"batb":[[0,4.8,3.56]],"ltp":0.0,"tv":0.0,"id":8429550},{"batb":[[0,3.35,2.52],[1,3.3,11.22],[2,3.25,5.02]],"ltp":0.0,"tv":0.0,"id":9417341},{"batb":[[0,4.4,3.66]],"ltp":0.0,"tv":0.0,"id":8231803},{"batb":[[0,5,2.52],[1,4.9,8.45],[2,4.8,1.99]],"ltp":0.0,"tv":0.0,"id":10170404},{"batb":[[0,7.2,3.21],[1,7,5.86],[2,6.8,2.76]],"ltp":0.0,"tv":0.0,"id":15608820},{"batb":[[0,5.3,7.54]],"ltp":0.0,"tv":0.0,"id":9001159},{"batb":[[0,6.6,4.09]],"ltp":0.0,"tv":0.0,"id":9193530},{"batb":[[0,5.3,7.54]],"ltp":0.0,"tv":0.0,"id":17352128}]}]}
{"op":"mcm","clk":"990123306","pt":1580494335412,"mc":[{"id":"1.168133548","rc":[{"batl":[[0,830,9],[1,850,3.03]],"ltp":0.0,"tv":0.0,"id":8429550},{"batl":[[0,27,9],[1,29,3.2]],"ltp":0.0,"tv":0.0,"id":9417341},{"batl":[[0,830,9],[1,850,3.03]],"ltp":0.0,"tv":0.0,"id":8231803},{"batl":[[0,830,9],[1,850,3.03]],"ltp":0.0,"tv":0.0,"id":10170404},{"batl":[[0,830,9],[1,850,3.03]],"ltp":0.0,"tv":0.0,"id":15608820},{"batl":[[0,830,9],[1,850,3.03]],"ltp":0.0,"tv":0.0,"id":9001159},{"batl":[[0,830,9],[1,850,3.03]],"ltp":0.0,"tv":0.0,"id":9193530}]}]}
{"op":"mcm","clk":"990123614","pt":1580494339189,"mc":[{"id":"1.168133548","rc":[{"batb":[[2,4.5,2.88]],"ltp":0.0,"tv":0.0,"id":8429550},{"batb":[[1,3.3,9.25]],"ltp":0.0,"tv":0.0,"id":9417341},{"batb":[[2,4.1,2.91]],"ltp":0.0,"tv":0.0,"id":8231803},{"batb":[[1,4.9,7.28]],"ltp":0.0,"tv":0.0,"id":10170404},{"batb":[[0,5.3,6.48]],"ltp":0.0,"tv":0.0,"id":9001159},{"batb":[[0,5.3,6.48]],"ltp":0.0,"tv":0.0,"id":17352128}]}]}
{"op":"mcm","clk":"990124090","pt":1580494344521,"mc":[{"id":"1.168133548","rc":[{"batb":[[0,3.4,1.99],[1,3.35,2.52],[2,3.3,9.25]],"ltp":0.0,"tv":0.0,"id":9417341},{"batb":[[0,5.5,1.99],[1,5.3,6.48]],"ltp":0.0,"tv":0.0,"id":9001159}]}]}
{"op":"mcm","clk":"990124267","pt":1580494346318,"mc":[{"id":"1.168133548","rc":[{"batb":[[0,4.5,1.99],[1,4.4,3.66],[2,4.3,3.03]],"ltp":0.0,"tv":0.0,"id":8231803},{"batb":[[0,7.4,1.99],[1,7.2,3.21],[2,7,3.87]],"ltp":0.0,"tv":0.0,"id":15608820}]}]}
{"op":"mcm","clk":"990124385","pt":1580494347520,"mc":[{"id":"1.168133548","rc":[{"batb":[[0,4.9,1.99],[1,4.8,3.56],[2,4.7,3.03]],"ltp":0.0,"tv":0.0,"id":8429550},{"batl":[[1,29,3.03]],"ltp":0.0,"tv":0.0,"id":9417341},{"batb":[[0,8.8,1.99],[1,8.4,3.91],[2,8.2,2.72]],"ltp":0.0,"tv":0.0,"id":10616006}]}]}
{"op":"mcm","clk":"990124453","pt":1580494348306,"mc":[{"id":"1.168133548","rc":[{"batl":[[0,27,9.19]],"ltp":0.0,"tv":0.0,"id":9417341},{"batb":[[0,5.1,1.99],[1,5,2.52],[2,4.9,7.28]],"ltp":0.0,"tv":0.0,"id":10170404}]}]}
{"op":"mcm","clk":"990124504","pt":1580494349207,"mc":[{"id":"1.168133548","rc":[{"batb":[[0,6.8,1.99],[1,6.6,4.09],[2,6.4,4.1]],"ltp":0.0,"tv":0.0,"id":9193530}]}]}
{"op":"mcm","clk":"990124552","pt":1580494349787,"mc":[{"id":"1.168133548","rc":[{"batb":[[0,5.5,1.99],[1,5.3,6.48]],"ltp":0.0,"tv":0.0,"id":17352128}]}]}
{"op":"mcm","clk":"990126234","pt":1580494369362,"mc":[{"id":"1.168133548","rc":[{"batb":[[1,6.6,3.28]],"ltp":0.0,"tv":0.0,"id":9193530}]}]}
{"op":"mcm","clk":"990127654","pt":1580494385571,"mc":[{"id":"1.168133548","rc":[{"batb":[[1,8.6,3.1],[2,8.4,3.33]],"ltp":0.0,"tv":0.0,"id":10616006}]}]}
{"op":"mcm","clk":"990131254","pt":1580494425224,"mc":[{"id":"1.168133548","rc":[{"batl":[[0,830,9.2],[2,910,0]],"ltp":0.0,"tv":0.0,"id":8429550},{"batl":[[0,27,9.39],[2,55,3]],"ltp":0.0,"tv":0.0,"id":9417341},{"batl":[[0,830,9.2],[2,910,0]],"ltp":0.0,"tv":0.0,"id":8231803},{"batl":[[0,830,9.2],[2,910,0]],"ltp":0.0,"tv":0.0,"id":10170404},{"batl":[[0,830,9.2],[2,910,0]],"ltp":0.0,"tv":0.0,"id":15608820},{"batl":[[0,830,9.2],[2,910,0]],"ltp":0.0,"tv":0.0,"id":9001159},{"batl":[[0,830,9.2],[2,910,0]],"ltp":0.0,"tv":0.0,"id":9193530},{"batl":[[0,20,3.48]],"ltp":0.0,"tv":0.0,"id":17352128}]}]}
{"op":"mcm","clk":"990140306","pt":1580494522565,"mc":[{"id":"1.168133548","rc":[{"batb":[[0,5,1.14],[1,4.9,1.99],[2,4.8,3.56]],"ltp":0.0,"tv":0.0,"id":8429550},{"batb":[[1,3.35,4.45]],"ltp":0.0,"tv":0.0,"id":9417341},{"batb":[[0,4.5,3.29],[1,4.4,2.52]],"ltp":0.0,"tv":0.0,"id":8231803},{"batb":[[0,5.2,1.08],[1,5.1,1.99],[2,5,2.52]],"ltp":0.0,"tv":0.0,"id":10170404},{"batb":[[0,5.5,2.98]],"ltp":0.0,"tv":0.0,"id":9001159},{"batb":[[0,6.8,2.75]],"ltp":0.0,"tv":0.0,"id":9193530},{"batb":[[0,5.5,2.98]],"ltp":0.0,"tv":0.0,"id":17352128}]}]}
{"op":"mcm","clk":"990140328","pt":1580494522899,"mc":[{"id":"1.168133548","rc":[{"batb":[[0,4.6,1.09],[1,4.5,3.29],[2,4.4,2.52]],"ltp":0.0,"tv":0.0,"id":8231803}]}]}
{"op":"mcm","clk":"990142648","pt":1580494549502,"mc":[{"id":"1.168133548","rc":[{"batb":[[1,3.35,2.52]],"ltp":0.0,"tv":0.0,"id":9417341},{"batb":[[1,4.5,1.99]],"ltp":0.0,"tv":0.0,"id":8231803}]}]}
{"op":"mcm","clk":"990142857","pt":1580494550825,"mc":[{"id":"1.168133548","rc":[{"batb":[[0,3.4,3.88]],"ltp":0.0,"tv":0.0,"id":9417341},{"batb":[[0,4.6,2.36]],"ltp":0.0,"tv":0.0,"id":8231803}]}]}
{"op":"mcm","clk":"990155532","pt":1580494676550,"mc":[{"id":"1.168133548","rc":[{"batb":[[0,5.4,1.92],[1,5.3,5.55]],"ltp":0.0,"tv":0.0,"id":9001159}]}]}
{"op":"mcm","clk":"990155541","pt":1580494676679,"mc":[{"id":"1.168133548","rc":[{"batb":[[0,5.7,1.99],[1,5.4,1.92],[2,5.3,5.55]],"ltp":0.0,"tv":0.0,"id":9001159}]}]}
{"op":"mcm","clk":"990155728","pt":1580494678532,"mc":[{"id":"1.168133548","rc":[{"batb":[[0,4.7,1.99],[1,4.6,2.36]],"ltp":0.0,"tv":0.0,"id":8231803}]}]}
{"op":"mcm","clk":"990155787","pt":1580494679159,"mc":[{"id":"1.168133548","rc":[{"batb":[[0,5.1,1.99],[1,5,1.14]],"ltp":0.0,"tv":0.0,"id":8429550}]}]}
{"op":"mcm","clk":"990155871","pt":1580494680059,"mc":[{"id":"1.168133548","rc":[{"batb":[[0,5.3,1.99],[1,5.2,1.08]],"ltp":0.0,"tv":0.0,"id":10170404}]}]}
{"op":"mcm","clk":"990156021","pt":1580494681542,"mc":[{"id":"1.168133548","rc":[{"batb":[[0,7.2,1.99],[1,6.6,4.04]],"ltp":0.0,"tv":0.0,"id":9193530},{"batb":[[0,5.7,1.99],[1,5.4,1.92],[2,5.3,5.55]],"ltp":0.0,"tv":0.0,"id":17352128}]}]}
{"op":"mcm","clk":"990157862","pt":1580494699177,"mc":[{"id":"1.168133548","rc":[{"batb":[[1,4.8,3.56],[2,4.7,3.03]],"ltp":0.0,"tv":0.0,"id":8429550},{"batb":[[1,4.6,1.09]],"ltp":0.0,"tv":0.0,"id":8231803},{"batb":[[1,5,2.52],[2,4.9,7.28]],"ltp":0.0,"tv":0.0,"id":10170404},{"batb":[[1,5.3,6.48],[2,5.1,2.52]],"ltp":0.0,"tv":0.0,"id":9001159},{"batb":[[1,5.3,6.48],[2,5.1,2.52]],"ltp":0.0,"tv":0.0,"id":17352128}]}]}
{"op":"mcm","clk":"990165758","pt":1580494777602,"mc":[{"id":"1.168133548","rc":[{"batb":[[2,5.2,3]],"ltp":0.0,"tv":0.0,"id":9001159},{"batb":[[2,5.2,3]],"ltp":0.0,"tv":0.0,"id":17352128}]}]}
{"op":"mcm","clk":"990170145","pt":1580494819517,"mc":[{"id":"1.168133548","rc":[{"batb":[[0,5.3,6.48],[1,5.2,3],[2,5.1,2.52]],"ltp":0.0,"tv":0.0,"id":9001159}]}]}
{"op":"mcm","clk":"990170194","pt":1580494819891,"mc":[{"id":"1.168133548","rc":[{"batb":[[0,5.5,1.99],[1,5.3,6.48],[2,5.2,3]],"ltp":0.0,"tv":0.0,"id":9001159}]}]}
{"op":"mcm","clk":"990170418","pt":1580494821790,"mc":[{"id":"1.168133548","rc":[{"batb":[[0,5.2,1.08],[1,5.1,1.99],[2,4.8,3.56]],"ltp":0.0,"tv":0.0,"id":8429550},{"batb":[[2,4.5,1.3]],"ltp":0.0,"tv":0.0,"id":8231803},{"batb":[[0,5.4,1.03],[1,5.3,1.99],[2,5,2.52]],"ltp":0.0,"tv":0.0,"id":10170404},{"batb":[[0,5.5,2.94]],"ltp":0.0,"tv":0.0,"id":9001159},{"batb":[[0,5.7,2.94]],"ltp":0.0,"tv":0.0,"id":17352128}]}]}
{"op":"mcm","clk":"990170524","pt":1580494822753,"mc":[{"id":"1.168133548","rc":[{"batb":[[1,4.9,1.99]],"ltp":0.0,"tv":0.0,"id":8429550}]}]}
{"op":"mcm","clk":"990170664","pt":1580494823808,"mc":[{"id":"1.168133548","rc":[{"batb":[[1,5.1,1.99]],"ltp":0.0,"tv":0.0,"id":10170404}]}]}
{"op":"mcm","clk":"990170819","pt":1580494825451,"mc":[{"id":"1.168133548","rc":[{"batb":[[0,5.5,2.94]],"ltp":0.0,"tv":0.0,"id":17352128}]}]}
{"op":"mcm","clk":"990172319","pt":1580494839523,"mc":[{"id":"1.168133548","rc":[{"batb":[[0,3.45,3.91],[1,3.4,3.88],[2,3.35,2.52]],"batl":[[1,55,3],[2,55,0]],"ltp":0.0,"tv":0.0,"id":9417341}]}]}
{"op":"mcm","clk":"990172423","pt":1580494840523,"mc":[{"id":"1.168133548","rc":[{"batl":[[0,26,3.42],[1,27,9],[2,55,3]],"ltp":0.0,"tv":0.0,"id":9417341},{"batb":[[0,4.7,5.02],[1,4.5,1.3],[2,4.4,2.52]],"batl":[[0,820,3.23],[1,830,9]],"ltp":0.0,"tv":0.0,"id":8231803},{"batl":[[0,820,3.23],[1,830,9]],"ltp":0.0,"tv":0.0,"id":9001159}]}]}
{"op":"mcm","clk":"990172553","pt":1580494841514,"mc":[{"id":"1.168133548","rc":[{"batb":[[0,4.8,1.04],[1,4.7,5.02],[2,4.5,1.3]],"ltp":0.0,"tv":0.0,"id":8231803},{"batb":[[0,7.4,5.68],[1,7.2,2.52],[2,6.8,2.76]],"batl":[[0,820,3.23],[1,830,9]],"ltp":0.0,"tv":0.0,"id":15608820}]}]}
{"op":"mcm","clk":"990172664","pt":1580494842554,"mc":[{"id":"1.168133548","rc":[{"batb":[[1,5,4.01],[2,4.9,1.99]],"batl":[[0,820,3.23],[1,830,9]],"ltp":0.0,"tv":0.0,"id":8429550},{"batb":[[0,8.8,5.02],[1,8.6,2.52],[2,8.2,2.72]],"ltp":0.0,"tv":0.0,"id":10616006},{"batb":[[1,5.1,5.2]],"batl":[[1,850,0]],"ltp":0.0,"tv":0.0,"id":10170404}]}]}
{"op":"mcm","clk":"990172743","pt":1580494843239,"mc":[{"id":"1.168133548","rc":[{"batb":[[0,8.8,5.58]],"ltp":0.0,"tv":0.0,"id":10616006},{"batl":[[0,820,3.23],[1,830,9]],"ltp":0.0,"tv":0.0,"id":10170404},{"batb":[[1,6.8,3.79],[2,6.6,3.28]],"batl":[[0,820,3.23],[1,830,9]],"ltp":0.0,"tv":0.0,"id":9193530}]}]}
{"op":"mcm","clk":"990173363","pt":1580494849518,"mc":[{"id":"1.168133548","rc":[{"batb":[[1,3.4,1.99]],"ltp":0.0,"tv":0.0,"id":9417341}]}]}
{"op":"mcm","clk":"990173460","pt":1580494850459,"mc":[{"id":"1.168133548","rc":[{"batb":[[2,4.4,2.52]],"ltp":0.0,"tv":0.0,"id":8231803}]}]}
{"op":"mcm","clk":"990173563","pt":1580494851460,"mc":[{"id":"1.168133548","rc":[{"batb":[[0,3.5,1.82],[1,3.45,3.91],[2,3.4,1.99]],"ltp":0.0,"tv":0.0,"id":9417341},{"batb":[[0,4.8,2.24]],"ltp":0.0,"tv":0.0,"id":8231803}]}]}
{"op":"mcm","clk":"990173773","pt":1580494853424,"mc":[{"id":"1.168133548","rc":[{"batl":[[0,820,3.03]],"ltp":0.0,"tv":0.0,"id":8429550},{"batl":[[0,820,3.03]],"ltp":0.0,"tv":0.0,"id":8231803},{"batl":[[0,820,3.03]],"ltp":0.0,"tv":0.0,"id":10170404},{"batl":[[0,820,3.03]],"ltp":0.0,"tv":0.0,"id":15608820},{"batl":[[0,820,3.03]],"ltp":0.0,"tv":0.0,"id":9001159},{"batl":[[0,820,3.03]],"ltp":0.0,"tv":0.0,"id":9193530}]}]}
{"op":"mcm","clk":"990173847","pt":1580494854004,"mc":[{"id":"1.168133548","rc":[{"batl":[[0,820,3.23]],"ltp":0.0,"tv":0.0,"id":8429550},{"batl":[[0,820,3.23]],"ltp":0.0,"tv":0.0,"id":8231803},{"batl":[[0,820,3.23]],"ltp":0.0,"tv":0.0,"id":10170404},{"batl":[[0,820,3.23]],"ltp":0.0,"tv":0.0,"id":15608820},{"batl":[[0,820,3.23]],"ltp":0.0,"tv":0.0,"id":9001159},{"batl":[[0,820,3.23]],"ltp":0.0,"tv":0.0,"id":9193530}]}]}
{"op":"mcm","clk":"990174293","pt":1580494858391,"mc":[{"id":"1.168133548","rc":[{"batl":[[0,800,9],[1,820,3.23]],"ltp":0.0,"tv":0.0,"id":8429550},{"batl":[[0,24,9],[1,26,3.42]],"ltp":0.0,"tv":0.0,"id":9417341},{"batl":[[0,800,9],[1,820,3.23]],"ltp":0.0,"tv":0.0,"id":8231803},{"batl":[[0,800,9],[1,820,3.23]],"ltp":0.0,"tv":0.0,"id":10170404},{"batl":[[0,800,9],[1,820,3.23]],"ltp":0.0,"tv":0.0,"id":15608820},{"batl":[[0,800,9],[1,820,3.23]],"ltp":0.0,"tv":0.0,"id":9001159},{"batl":[[0,800,9],[1,820,3.23]],"ltp":0.0,"tv":0.0,"id":9193530}]}]}
{"op":"mcm","clk":"990174509","pt":1580494860326,"mc":[{"id":"1.168133548","rc":[{"batl":[[0,800,9.2],[1,820,3.03]],"ltp":0.0,"tv":0.0,"id":8429550},{"batl":[[0,24,9.2],[1,26,3.22]],"ltp":0.0,"tv":0.0,"id":9417341},{"batl":[[0,800,9.2],[1,820,3.03]],"ltp":0.0,"tv":0.0,"id":8231803},{"batl":[[0,800,9.2],[1,820,3.03]],"ltp":0.0,"tv":0.0,"id":10170404},{"batl":[[0,800,9.2],[1,820,3.03]],"ltp":0.0,"tv":0.0,"id":15608820},{"batl":[[0,800,9.2],[1,820,3.03]],"ltp":0.0,"tv":0.0,"id":9001159},{"batl":[[0,800,9.2],[1,820,3.03]],"ltp":0.0,"tv":0.0,"id":9193530}]}]}
{"op":"mcm","clk":"990174970","pt":1580494864208,"mc":[{"id":"1.168133548","rc":[{"batb":[[1,5,6.53]],"ltp":0.0,"tv":0.0,"id":8429550},{"batb":[[1,3.45,6.43]],"ltp":0.0,"tv":0.0,"id":9417341},{"batb":[[0,4.8,4.76]],"ltp":0.0,"tv":0.0,"id":8231803},{"batb":[[1,5.2,2.52],[2,5.1,5.2]],"ltp":0.0,"tv":0.0,"id":10170404}]}]}
{"op":"mcm","clk":"990175079","pt":1580494865202,"mc":[{"id":"1.168133548","rc":[{"batl":[[0,24,9.42],[1,26,3.03]],"ltp":0.0,"tv":0.0,"id":9417341}]}]}
{"op":"mcm","clk":"990196077","pt":1580494974871,"mc":[{"id":"1.168133548","rc":[{"batb":[[0,3.55,1.99],[1,3.5,1.82],[2,3.45,6.43]],"ltp":0.0,"tv":0.0,"id":9417341}]}]}
{"op":"mcm","clk":"990196180","pt":1580494976170,"mc":[{"id":"1.168133548","rc":[{"batb":[[0,5.9,1.99],[1,5.4,1.88],[2,5.3,5.55]],"ltp":0.0,"tv":0.0,"id":9001159}]}]}
{"op":"mcm","clk":"990196220","pt":1580494976752,"mc":[{"id":"1.168133548","rc":[{"batb":[[0,4.9,1.99],[1,4.8,4.76],[2,4.7,3.03]],"ltp":0.0,"tv":0.0,"id":8231803}]}]}
{"op":"mcm","clk":"990196352","pt":1580494978364,"mc":[{"id":"1.168133548","rc":[{"batb":[[0,7.8,1.99],[1,7.4,3.69],[2,7.2,2.52]],"ltp":0.0,"tv":0.0,"id":15608820}]}]}
{"op":"mcm","clk":"990196446","pt":1580494979563,"mc":[{"id":"1.168133548","rc":[{"batb":[[2,4.8,2.52]],"ltp":0.0,"tv":0.0,"id":8429550}]}]}
{"op":"mcm","clk":"990196515","pt":1580494980453,"mc":[{"id":"1.168133548","rc":[{"batb":[[0,5.3,1.99],[1,5.2,1.08],[2,5,6.53]],"ltp":0.0,"tv":0.0,"id":8429550},{"batb":[[0,9.2,1.99],[1,8.8,3.59],[2,8.6,2.52]],"ltp":0.0,"tv":0.0,"id":10616006}]}]}
{"op":"mcm","clk":"990196701","pt":1580494982376,"mc":[{"id":"1.168133548","rc":[{"batb":[[0,5.5,1.99],[1,5.4,1.03],[2,5.2,2.52]],"ltp":0.0,"tv":0.0,"id":10170404}]}]}
{"op":"mcm","clk":"990196773","pt":1580494983162,"mc":[{"id":"1.168133548","rc":[{"batb":[[0,5.9,1.99],[1,5.4,1.88],[2,5.3,5.55]],"ltp":0.0,"tv":0.0,"id":17352128}]}]}
{"op":"mcm","clk":"990198344","pt":1580494999991,"mc":[{"id":"1.168133548","rc":[{"batb":[[1,5,6.53],[2,4.8,2.52]],"ltp":0.0,"tv":0.0,"id":8429550},{"batb":[[1,4.8,3.56]],"ltp":0.0,"tv":0.0,"id":8231803},{"batb":[[1,5.2,2.52],[2,5.1,3.21]],"ltp":0.0,"tv":0.0,"id":10170404},{"batb":[[1,5.3,6.48],[2,5.2,3]],"ltp":0.0,"tv":0.0,"id":9001159},{"batb":[[1,5.3,6.48],[2,5.2,3]],"ltp":0.0,"tv":0.0,"id":17352128}]}]}
{"op":"mcm","clk":"990198489","pt":1580495001412,"mc":[{"id":"1.168133548","rc":[{"batb":[[0,5,1.14],[1,4.9,1.99],[2,4.8,3.56]],"ltp":0.0,"tv":0.0,"id":8231803},{"batb":[[0,5.9,2.9]],"ltp":0.0,"tv":0.0,"id":9001159}]}]}
{"op":"mcm","clk":"990198609","pt":1580495002562,"mc":[{"id":"1.168133548","rc":[{"batb":[[2,5.1,2.52]],"ltp":0.0,"tv":0.0,"id":9001159}]}]}
{"op":"mcm","clk":"990205418","pt":1580495075488,"mc":[{"id":"1.168133548","rc":[{"batb":[[2,6.6,2.52]],"ltp":0.0,"tv":0.0,"id":9193530}]}]}
{"op":"mcm","clk":"990205447","pt":1580495075798,"mc":[{"id":"1.168133548","rc":[{"batb":[[1,5.2,3.48]],"ltp":0.0,"tv":0.0,"id":10170404},{"batb":[[1,7,1.47],[2,6.8,3.03]],"ltp":0.0,"tv":0.0,"id":9193530}]}]}
{"op":"mcm","clk":"990208443","pt":1580495104627,"mc":[{"id":"1.168133548","rc":[{"batb":[[1,7,3.99]],"ltp":0.0,"tv":0.0,"id":9193530}]}]}
{"op":"mcm","clk":"990210054","pt":1580495121469,"mc":[{"id":"1.168133548","rc":[{"batb":[[0,5.4,1.03],[1,5.3,1.99],[2,5,6.53]],"ltp":0.0,"tv":0.0,"id":8429550},{"batb":[[0,5.5,2.98]],"ltp":0.0,"tv":0.0,"id":10170404},{"batb":[[0,5.9,2.9]],"ltp":0.0,"tv":0.0,"id":17352128}]}]}
{"op":"mcm","clk":"990210633","pt":1580495127563,"mc":[{"id":"1.168133548","rc":[{"batb":[[0,5.4,1.84],[1,5.3,5.55]],"ltp":0.0,"tv":0.0,"id":9001159}]}]}
{"op":"mcm","clk":"990210730","pt":1580495128558,"mc":[{"id":"1.168133548","rc":[{"batb":[[0,5.1,1.99],[1,5,1.14]],"ltp":0.0,"tv":0.0,"id":8231803},{"batb":[[0,6.2,1.99],[1,5.4,1.84],[2,5.3,5.55]],"ltp":0.0,"tv":0.0,"id":9001159}]}]}
{"op":"mcm","clk":"990210908","pt":1580495130485,"mc":[{"id":"1.168133548","rc":[{"batb":[[0,5.5,1.99],[1,5.4,1.03]],"ltp":0.0,"tv":0.0,"id":8429550},{"batb":[[0,5.7,1.99],[1,5.2,4.46]],"ltp":0.0,"tv":0.0,"id":10170404}]}]}
{"op":"mcm","clk":"990210982","pt":1580495131163,"mc":[{"id":"1.168133548","rc":[{"batb":[[0,6.2,1.99],[1,5.4,1.84],[2,5.3,5.55]],"ltp":0.0,"tv":0.0,"id":17352128}]}]}
{"op":"mcm","clk":"990212813","pt":1580495149488,"mc":[{"id":"1.168133548","rc":[{"batb":[[1,5,6.53],[2,4.8,2.52]],"ltp":0.0,"tv":0.0,"id":8429550},{"batb":[[1,5.2,3.48]],"ltp":0.0,"tv":0.0,"id":10170404}]}]}
{"op":"mcm","clk":"990212913","pt":1580495150492,"mc":[{"id":"1.168133548","rc":[{"batb":[[1,4.8,3.56],[2,4.7,3.03]],"ltp":0.0,"tv":0.0,"id":8231803},{"batb":[[1,5.3,6.48],[2,5.1,2.52]],"ltp":0.0,"tv":0.0,"id":9001159},{"batb":[[1,5.3,6.48],[2,5.2,3]],"ltp":0.0,"tv":0.0,"id":17352128}]}]}
{"op":"mcm","clk":"990213033","pt":1580495151809,"mc":[{"id":"1.168133548","rc":[{"batb":[[0,5.5,2.98]],"ltp":0.0,"tv":0.0,"id":8429550},{"batb":[[0,5.2,1.08],[1,5.1,1.99],[2,4.8,3.56]],"ltp":0.0,"tv":0.0,"id":8231803},{"batb":[[0,5.7,2.94]],"ltp":0.0,"tv":0.0,"id":10170404},{"batb":[[0,6.2,2.83]],"ltp":0.0,"tv":0.0,"id":9001159},{"batb":[[0,6.2,2.83]],"ltp":0.0,"tv":0.0,"id":17352128}]}]}
{"op":"mcm","clk":"990215170","pt":1580495174145,"mc":[{"id":"1.168133548","rc":[{"batb":[[2,5.1,2.52]],"ltp":0.0,"tv":0.0,"id":17352128}]}]}
{"op":"mcm","clk":"990222786","pt":1580495255370,"mc":[{"id":"1.168133548","rc":[{"batb":[[0,6.6,1.99],[1,5.4,1.77],[2,5.3,5.55]],"ltp":0.0,"tv":0.0,"id":9001159}]}]}
{"op":"mcm","clk":"990222865","pt":1580495256475,"mc":[{"id":"1.168133548","rc":[{"batb":[[0,5.3,1.99],[1,5.2,1.08]],"ltp":0.0,"tv":0.0,"id":8231803}]}]}
{"op":"mcm","clk":"990223035","pt":1580495258550,"mc":[{"id":"1.168133548","rc":[{"batb":[[0,5.7,1.99],[1,5.1,1.97],[2,5,5.55]],"ltp":0.0,"tv":0.0,"id":8429550},{"batb":[[0,5.9,1.99],[1,5.2,4.43]],"ltp":0.0,"tv":0.0,"id":10170404}]}]}
{"op":"mcm","clk":"990223185","pt":1580495260377,"mc":[{"id":"1.168133548","rc":[{"batb":[[0,6.6,1.99],[1,5.4,1.77],[2,5.3,5.55]],"ltp":0.0,"tv":0.0,"id":17352128}]}]}
{"op":"mcm","clk":"990223983","pt":1580495269567,"mc":[{"id":"1.168133548","rc":[{"batb":[[1,5.3,6.48],[2,5.1,2.52]],"ltp":0.0,"tv":0.0,"id":9001159}]}]}
{"op":"mcm","clk":"990224051","pt":1580495270396,"mc":[{"id":"1.168133548","rc":[{"batb":[[1,5,6.53],[2,4.8,2.52]],"ltp":0.0,"tv":0.0,"id":8429550},{"batb":[[1,4.8,3.56],[2,4.7,3.03]],"ltp":0.0,"tv":0.0,"id":8231803},{"batb":[[1,5.2,3.48]],"ltp":0.0,"tv":0.0,"id":10170404},{"batb":[[1,5.3,6.48],[2,5.1,2.52]],"ltp":0.0,"tv":0.0,"id":17352128}]}]}
{"op":"mcm","clk":"990224112","pt":1580495271390,"mc":[{"id":"1.168133548","rc":[{"batb":[[0,5.7,2.94]],"ltp":0.0,"tv":0.0,"id":8429550},{"batb":[[0,5.4,1.03],[1,5.3,1.99],[2,4.8,3.56]],"ltp":0.0,"tv":0.0,"id":8231803},{"batb":[[0,6.6,2.77]],"ltp":0.0,"tv":0.0,"id":9001159}]}]}
{"op":"mcm","clk":"990224184","pt":1580495272291,"mc":[{"id":"1.168133548","rc":[{"batb":[[0,5.9,2.9]],"ltp":0.0,"tv":0.0,"id":10170404},{"batb":[[0,6.6,2.77]],"ltp":0.0,"tv":0.0,"id":17352128}]}]}
{"op":"mcm","clk":"990224502","pt":1580495276474,"mc":[{"id":"1.168133548","rc":[{"batb":[[0,3.55,5.02],[2,3.45,2.52]],"batl":[[0,23,3.45],[1,24,9]],"ltp":0.0,"tv":0.0,"id":9417341},{"batl":[[1,820,0]],"ltp":0.0,"tv":0.0,"id":9001159}]}]}
{"op":"mcm","clk":"990224578","pt":1580495277573,"mc":[{"id":"1.168133548","rc":[{"batl":[[1,820,0]],"ltp":0.0,"tv":0.0,"id":8429550},{"batb":[[2,4.9,3.03]],"batl":[[0,790,3.23],[1,800,9]],"ltp":0.0,"tv":0.0,"id":8231803},{"batl":[[0,790,3.23],[1,800,9]],"ltp":0.0,"tv":0.0,"id":15608820},{"batl":[[0,790,3.23],[1,800,9]],"ltp":0.0,"tv":0.0,"id":9001159}]}]}
{"op":"mcm","clk":"990224643","pt":1580495278484,"mc":[{"id":"1.168133548","rc":[{"batl":[[0,790,3.23],[1,800,9]],"ltp":0.0,"tv":0.0,"id":8429550},{"batb":[[1,5.3,3.03],[2,5.2,3.48]],"batl":[[0,790,3.23],[1,800,9]],"ltp":0.0,"tv":0.0,"id":10170404},{"batb":[[0,7.2,5.02],[2,6.6,2.52]],"ltp":0.0,"tv":0.0,"id":9193530}]}]}
{"op":"mcm","clk":"990224721","pt":1580495279316,"mc":[{"id":"1.168133548","rc":[{"batb":[[0,7.2,5.7],[1,7,3.28]],"batl":[[0,790,3.23],[1,800,9]],"ltp":0.0,"tv":0.0,"id":9193530}]}]}
{"op":"mcm","clk":"990225018","pt":1580495282398,"mc":[{"id":"1.168133548","rc":[{"batl":[[0,770,9],[1,790,3.23]],"ltp":0.0,"tv":0.0,"id":8429550},{"batl":[[0,21,9],[1,23,3.45]],"ltp":0.0,"tv":0.0,"id":9417341},{"batl":[[0,770,9],[1,790,3.23]],"ltp":0.0,"tv":0.0,"id":8231803},{"batl":[[0,770,9],[1,790,3.23]],"ltp":0.0,"tv":0.0,"id":10170404},{"batl":[[0,770,9],[1,790,3.23]],"ltp":0.0,"tv":0.0,"id":15608820},{"batl":[[0,770,9],[1,790,3.23]],"ltp":0.0,"tv":0.0,"id":9193530},{"batl":[[0,770,9],[1,790,3.23]],"ltp":0.0,"tv":0.0,"id":9001159}]}]}
{"op":"mcm","clk":"990225163","pt":1580495284109,"mc":[{"id":"1.168133548","rc":[{"batl":[[0,770,9.2],[1,790,3.03]],"ltp":0.0,"tv":0.0,"id":8429550},{"batb":[[0,3.55,7.54]],"batl":[[0,21,9.2],[1,23,3.25]],"ltp":0.0,"tv":0.0,"id":9417341},{"batb":[[2,5,2.52]],"batl":[[0,770,9.2],[1,790,3.03]],"ltp":0.0,"tv":0.0,"id":8231803},{"batb":[[1,5.4,2.52],[2,5.3,3.03]],"batl":[[0,770,9.2],[1,790,3.03]],"ltp":0.0,"tv":0.0,"id":10170404},{"batl":[[0,770,9.2],[1,790,3.03]],"ltp":0.0,"tv":0.0,"id":15608820},{"batl":[[0,770,9.2],[1,790,3.03]],"ltp":0.0,"tv":0.0,"id":9193530},{"batl":[[0,770,9.2],[1,790,3.03]],"ltp":0.0,"tv":0.0,"id":9001159}]}]}
{"op":"mcm","clk":"990226502","pt":1580495299519,"mc":[{"id":"1.168133548","rc":[{"batb":[[1,3.45,2.52],[2,3.35,2.52]],"ltp":0.0,"tv":0.0,"id":9417341}]}]}
{"op":"mcm","clk":"990227429","pt":1580495312537,"mc":[{"id":"1.168133548","rc":[{"batb":[[0,5.8,1.23],[1,5.7,1.99],[2,5,6.53]],"ltp":0.0,"tv":0.0,"id":8429550},{"batb":[[0,3.55,8]],"ltp":0.0,"tv":0.0,"id":9417341},{"batb":[[0,5.4,1.34]],"ltp":0.0,"tv":0.0,"id":8231803},{"batb":[[0,6,1.18],[1,5.9,1.99],[2,5.4,2.52]],"ltp":0.0,"tv":0.0,"id":10170404},{"batb":[[0,6.8,1.02],[1,6.6,1.99],[2,5.3,6.48]],"ltp":0.0,"tv":0.0,"id":9001159},{"batb":[[0,6.8,1.02],[1,6.6,1.99],[2,5.3,6.48]],"ltp":0.0,"tv":0.0,"id":17352128}]}]}
{"op":"mcm","clk":"990227470","pt":1580495313157,"mc":[{"id":"1.168133548","rc":[{"batb":[[0,7.2,5.92]],"ltp":0.0,"tv":0.0,"id":9193530}]}]}
{"op":"mcm","clk":"990230050","pt":1580495344597,"mc":[{"id":"1.168133548","rc":[{"batb":[[0,7.4,3.42],[1,7.2,5.02],[2,7,3.28]],"ltp":0.0,"tv":0.0,"id":9193530}]}]}
{"op":"mcm","clk":"990230490","pt":1580495349477,"mc":[{"id":"1.168133548","rc":[{"batl":[[1,23,3.03]],"ltp":0.0,"tv":0.0,"id":9417341}]}]}
{"op":"mcm","clk":"990230535","pt":1580495350003,"mc":[{"id":"1.168133548","rc":[{"batl":[[0,21,9.45]],"ltp":0.0,"tv":0.0,"id":9417341}]}]}
{"op":"mcm","clk":"990236482","pt":1580495420263,"mc":[{"id":"1.168133548","rc":[{"batb":[[0,3.65,1.99],[1,3.55,6.01],[2,3.45,2.52]],"ltp":0.0,"tv":0.0,"id":9417341},{"batb":[[0,7,1.99],[1,6.8,1.02]],"ltp":0.0,"tv":0.0,"id":9001159}]}]}
{"op":"mcm","clk":"990236551","pt":1580495421090,"mc":[{"id":"1.168133548","rc":[{"batb":[[0,5.5,1.99],[1,5.4,1.34]],"ltp":0.0,"tv":0.0,"id":8231803}]}]}
{"op":"mcm","clk":"990236660","pt":1580495422572,"mc":[{"id":"1.168133548","rc":[{"batb":[[0,5.9,1.99],[1,5.8,1.23]],"ltp":0.0,"tv":0.0,"id":8429550},{"batb":[[1,3.6,2.21],[2,3.55,5.55]],"ltp":0.0,"tv":0.0,"id":9417341},{"batb":[[0,6.2,1.99],[1,6,1.18]],"ltp":0.0,"tv":0.0,"id":10170404}]}]}
{"op":"mcm","clk":"990236734","pt":1580495423565,"mc":[{"id":"1.168133548","rc":[{"batb":[[2,5.4,3.45]],"ltp":0.0,"tv":0.0,"id":10170404},{"batb":[[0,7.6,1.99],[1,7.4,3.42],[2,7.2,3.03]],"ltp":0.0,"tv":0.0,"id":9193530},{"batb":[[0,7,1.99],[1,6.8,1.02]],"ltp":0.0,"tv":0.0,"id":17352128}]}]}
{"op":"mcm","clk":"990238819","pt":1580495449503,"mc":[{"id":"1.168133548","rc":[{"batb":[[1,5.1,1.26],[2,5,5.55]],"ltp":0.0,"tv":0.0,"id":8429550},{"batb":[[1,5,2.82],[2,4.9,3.03]],"ltp":0.0,"tv":0.0,"id":8231803}]}]}
{"op":"mcm","clk":"990238887","pt":1580495450501,"mc":[{"id":"1.168133548","rc":[{"batb":[[1,5.4,3.72],[2,5.3,3.03]],"ltp":0.0,"tv":0.0,"id":10170404}]}]}
{"op":"mcm","clk":"990238919","pt":1580495451026,"mc":[{"id":"1.168133548","rc":[{"batb":[[0,5.9,2.9]],"ltp":0.0,"tv":0.0,"id":8429550},{"batb":[[0,5.5,2.98]],"ltp":0.0,"tv":0.0,"id":8231803},{"batb":[[0,6.2,2.83]],"ltp":0.0,"tv":0.0,"id":10170404}]}]}
{"op":"mcm","clk":"990246758","pt":1580495551243,"mc":[{"id":"1.168133548","rc":[{"batb":[[0,5.7,1.99],[1,5.4,1.29],[2,5,2.52]],"ltp":0.0,"tv":0.0,"id":8231803}]}]}
{"op":"mcm","clk":"990246913","pt":1580495553247,"mc":[{"id":"1.168133548","rc":[{"batb":[[0,6.2,1.99],[1,5.8,1.19],[2,5,6.53]],"ltp":0.0,"tv":0.0,"id":8429550}]}]}
{"op":"mcm","clk":"990247027","pt":1580495554351,"mc":[{"id":"1.168133548","rc":[{"batb":[[0,6.6,1.99],[1,6,1.12],[2,5.4,3.45]],"ltp":0.0,"tv":0.0,"id":10170404}]}]}
{"op":"mcm","clk":"990248365","pt":1580495569506,"mc":[{"id":"1.168133548","rc":[{"batb":[[1,5.1,1.26],[2,5,5.55]],"ltp":0.0,"tv":0.0,"id":8429550},{"batb":[[1,5,2.82],[2,4.9,3.03]],"ltp":0.0,"tv":0.0,"id":8231803},{"batb":[[1,5.4,3.72],[2,5.3,3.03]],"ltp":0.0,"tv":0.0,"id":10170404}]}]}
{"op":"mcm","clk":"990248521","pt":1580495570946,"mc":[{"id":"1.168133548","rc":[{"batb":[[0,6.2,2.83]],"ltp":0.0,"tv":0.0,"id":8429550},{"batb":[[0,5.7,2.94]],"ltp":0.0,"tv":0.0,"id":8231803},{"batb":[[0,6.6,2.77]],"ltp":0.0,"tv":0.0,"id":10170404}]}]}
{"op":"mcm","clk":"990252739","pt":1580495610565,"mc":[{"id":"1.168133548","rc":[{"batb":[[0,3.65,5.02],[2,3.55,2.52]],"batl":[[0,20,3.48],[1,21,9]],"ltp":0.0,"tv":0.0,"id":9417341},{"batb":[[1,5.1,3.34],[2,5,2.52]],"batl":[[1,790,0]],"ltp":0.0,"tv":0.0,"id":8231803},{"batl":[[0,760,3.23],[1,770,9]],"ltp":0.0,"tv":0.0,"id":9001159}]}]}
{"op":"mcm","clk":"990252826","pt":1580495611473,"mc":[{"id":"1.168133548","rc":[{"batl":[[0,760,3.23],[1,770,9]],"ltp":0.0,"tv":0.0,"id":8429550},{"batl":[[0,760,3.23],[1,770,9]],"ltp":0.0,"tv":0.0,"id":8231803},{"batb":[[1,5.5,3.31],[2,5.4,3.45]],"ltp":0.0,"tv":0.0,"id":10170404},{"batl":[[0,760,3.23],[1,770,9]],"ltp":0.0,"tv":0.0,"id":15608820}]}]}
{"op":"mcm","clk":"990252907","pt":1580495612400,"mc":[{"id":"1.168133548","rc":[{"batl":[[0,760,3.23],[1,770,9]],"ltp":0.0,"tv":0.0,"id":10170404},{"batb":[[0,7.6,5.02],[2,7,3.28]],"batl":[[0,760,3.23],[1,770,9]],"ltp":0.0,"tv":0.0,"id":9193530}]}]}
{"op":"mcm","clk":"990254479","pt":1580495629333,"mc":[{"id":"1.168133548","rc":[{"batb":[[1,3.55,2.98],[2,3.45,2.52]],"ltp":0.0,"tv":0.0,"id":9417341}]}]}
{"op":"mcm","clk":"990254648","pt":1580495631107,"mc":[{"id":"1.168133548","rc":[{"batb":[[0,3.7,1.68],[1,3.65,5.02],[2,3.55,2.98]],"ltp":0.0,"tv":0.0,"id":9417341}]}]}
{"op":"mcm","clk":"990255580","pt":1580495641337,"mc":[{"id":"1.168133548","rc":[{"batl":[[0,740,9],[1,760,3.23]],"ltp":0.0,"tv":0.0,"id":8429550},{"batl":[[0,19,9],[1,20,3.48]],"ltp":0.0,"tv":0.0,"id":9417341},{"batl":[[0,740,9],[1,760,3.23]],"ltp":0.0,"tv":0.0,"id":8231803},{"batl":[[0,740,9],[1,760,3.23]],"ltp":0.0,"tv":0.0,"id":10170404},{"batl":[[0,740,9],[1,760,3.23]],"ltp":0.0,"tv":0.0,"id":15608820},{"batl":[[0,740,9],[1,760,3.23]],"ltp":0.0,"tv":0.0,"id":9193530},{"batl":[[0,740,9],[1,760,3.23]],"ltp":0.0,"tv":0.0,"id":9001159}]}]}
{"op":"mcm","clk":"990255845","pt":1580495644150,"mc":[{"id":"1.168133548","rc":[{"batb":[[0,3.7,4.2]],"ltp":0.0,"tv":0.0,"id":9417341},{"batb":[[1,5.2,2.82],[2,5.1,3.03]],"ltp":0.0,"tv":0.0,"id":8231803},{"batb":[[1,5.6,2.79],[2,5.5,3.03]],"ltp":0.0,"tv":0.0,"id":10170404}]}]}
{"op":"mcm","clk":"990256187","pt":1580495647363,"mc":[{"id":"1.168133548","rc":[{"batl":[[0,740,9.2],[1,760,3.03]],"ltp":0.0,"tv":0.0,"id":8429550},{"batl":[[0,19,9.2],[1,20,3.28]],"ltp":0.0,"tv":0.0,"id":9417341},{"batl":[[0,740,9.2],[1,760,3.03]],"ltp":0.0,"tv":0.0,"id":8231803},{"batl":[[0,740,9.2],[1,760,3.03]],"ltp":0.0,"tv":0.0,"id":10170404},{"batl":[[0,740,9.2],[1,760,3.03]],"ltp":0.0,"tv":0.0,"id":15608820},{"batl":[[0,740,9.2],[1,760,3.03]],"ltp":0.0,"tv":0.0,"id":9193530},{"batl":[[0,740,9.2],[1,760,3.03]],"ltp":0.0,"tv":0.0,"id":9001159}]}]}
{"op":"mcm","clk":"990257793","pt":1580495663552,"mc":[{"id":"1.168133548","rc":[{"batb":[[1,7.4,2.74]],"ltp":0.0,"tv":0.0,"id":9193530}]}]}
{"op":"mcm","clk":"990257890","pt":1580495664439,"mc":[{"id":"1.168133548","rc":[{"batl":[[0,19,9.47],[1,20,3.03]],"ltp":0.0,"tv":0.0,"id":9417341},{"batb":[[0,7.6,5.66]],"ltp":0.0,"tv":0.0,"id":9193530}]}]}
{"op":"mcm","clk":"990259105","pt":1580495677289,"mc":[{"id":"1.168133548","rc":[{"batb":[[0,3.75,1.99],[1,3.7,4.2],[2,3.65,3.03]],"ltp":0.0,"tv":0.0,"id":9417341}]}]}
{"op":"mcm","clk":"990259221","pt":1580495678282,"mc":[{"id":"1.168133548","rc":[{"batb":[[0,5.9,1.99],[1,5.4,1.25],[2,5.2,2.52]],"ltp":0.0,"tv":0.0,"id":8231803}]}]}
{"op":"mcm","clk":"990259354","pt":1580495679499,"mc":[{"id":"1.168133548","rc":[{"batb":[[0,6.6,1.99],[1,5.8,1.13],[2,5,6.53]],"ltp":0.0,"tv":0.0,"id":8429550},{"batb":[[0,7,1.99],[1,6,1.05],[2,5.6,2.52]],"ltp":0.0,"tv":0.0,"id":10170404}]}]}
{"op":"mcm","clk":"990259435","pt":1580495680280,"mc":[{"id":"1.168133548","rc":[{"batb":[[0,8,1.99],[1,7.6,3.67],[2,7.4,2.74]],"ltp":0.0,"tv":0.0,"id":9193530}]}]}
{"op":"mcm","clk":"990260369","pt":1580495689503,"mc":[{"id":"1.168133548","rc":[{"batb":[[1,5.1,1.26],[2,5,5.55]],"ltp":0.0,"tv":0.0,"id":8429550},{"batb":[[1,3.7,2.52]],"ltp":0.0,"tv":0.0,"id":9417341},{"batb":[[1,5.2,2.82],[2,5.1,3.03]],"ltp":0.0,"tv":0.0,"id":8231803}]}]}
{"op":"mcm","clk":"990264037","pt":1580495721471,"mc":[{"id":"1.168133548","rc":[{"batb":[[0,6.6,2.77]],"ltp":0.0,"tv":0.0,"id":8429550},{"batb":[[1,3.7,4.2]],"ltp":0.0,"tv":0.0,"id":9417341},{"batb":[[0,5.9,2.9]],"ltp":0.0,"tv":0.0,"id":8231803}]}]}
{"op":"mcm","clk":"990267152","pt":1580495750521,"mc":[{"id":"1.168133548","rc":[{"batb":[[1,3.7,2.52]],"ltp":0.0,"tv":0.0,"id":9417341}]}]}
{"op":"mcm","clk":"990267250","pt":1580495751319,"mc":[{"id":"1.168133548","rc":[{"batb":[[0,3.75,3.64]],"ltp":0.0,"tv":0.0,"id":9417341}]}]}
{"op":"mcm","clk":"990275429","pt":1580495827493,"mc":[{"id":"1.168133548","rc":[{"batb":[[0,5.4,1.21],[1,5.2,2.52]],"ltp":0.0,"tv":0.0,"id":8231803}]}]}
{"op":"mcm","clk":"990275440","pt":1580495827592,"mc":[{"id":"1.168133548","rc":[{"batb":[[0,6.2,1.99],[1,5.4,1.21],[2,5.2,2.52]],"ltp":0.0,"tv":0.0,"id":8231803}]}]}
{"op":"mcm","clk":"990275546","pt":1580495828802,"mc":[{"id":"1.168133548","rc":[{"batb":[[0,7,1.99],[1,5.8,1.06],[2,5,6.53]],"ltp":0.0,"tv":0.0,"id":8429550}]}]}
{"op":"mcm","clk":"990276632","pt":1580495839531,"mc":[{"id":"1.168133548","rc":[{"batb":[[1,5.2,2.82],[2,5.1,3.03]],"ltp":0.0,"tv":0.0,"id":8231803}]}]}
{"op":"mcm","clk":"990276792","pt":1580495841315,"mc":[{"id":"1.168133548","rc":[{"batb":[[0,6.2,2.83]],"ltp":0.0,"tv":0.0,"id":8231803}]}]}
{"op":"mcm","clk":"990292094","pt":1580495893522,"mc":[{"id":"1.168133548","rc":[{"batb":[[0,3.8,3.03],[1,3.75,3.64],[2,3.7,2.52]],"batl":[[0,18.5,3.5],[1,19,9]],"ltp":0.0,"tv":0.0,"id":9417341},{"batb":[[2,5,2.52]],"ltp":0.0,"tv":0.0,"id":8231803},{"batl":[[0,730,3.23],[1,740,9]],"ltp":0.0,"tv":0.0,"id":9001159}]}]}
{"op":"mcm","clk":"990292206","pt":1580495894380,"mc":[{"id":"1.168133548","rc":[{"batl":[[1,760,0]],"ltp":0.0,"tv":0.0,"id":8429550},{"batb":[[1,5.3,3.34],[2,5.2,2.52]],"batl":[[0,730,3.23],[1,740,9]],"ltp":0.0,"tv":0.0,"id":8231803},{"batl":[[0,730,3.23],[1,740,9]],"ltp":0.0,"tv":0.0,"id":15608820}]}]}
{"op":"mcm","clk":"990292324","pt":1580495895276,"mc":[{"id":"1.168133548","rc":[{"batl":[[0,730,3.23],[1,740,9]],"ltp":0.0,"tv":0.0,"id":8429550},{"batb":[[2,5.7,3.03]],"batl":[[0,730,3.23],[1,740,9]],"ltp":0.0,"tv":0.0,"id":10170404},{"batl":[[0,730,3.23],[1,740,9]],"ltp":0.0,"tv":0.0,"id":9193530}]}]}
{"op":"mcm","clk":"990292895","pt":1580495900192,"mc":[{"id":"1.168133548","rc":[{"batb":[[1,3.75,1.99]],"ltp":0.0,"tv":0.0,"id":9417341}]}]}
{"op":"mcm","clk":"990293043","pt":1580495901515,"mc":[{"id":"1.168133548","rc":[{"batl":[[1,740,0]],"ltp":0.0,"tv":0.0,"id":8429550},{"batb":[[0,3.85,1.6],[1,3.8,3.03],[2,3.75,1.99]],"batl":[[1,55,3],[2,55,0]],"ltp":0.0,"tv":0.0,"id":9417341},{"batl":[[1,740,0]],"ltp":0.0,"tv":0.0,"id":8231803},{"batl":[[1,740,0]],"ltp":0.0,"tv":0.0,"id":10170404},{"batl":[[1,740,0]],"ltp":0.0,"tv":0.0,"id":15608820},{"batl":[[1,740,0]],"ltp":0.0,"tv":0.0,"id":9193530},{"batl":[[1,740,0]],"ltp":0.0,"tv":0.0,"id":9001159}]}]}
{"op":"mcm","clk":"990293106","pt":1580495902093,"mc":[{"id":"1.168133548","rc":[{"batl":[[0,710,9],[1,730,3.23]],"ltp":0.0,"tv":0.0,"id":8429550},{"batl":[[0,17.5,9],[1,18.5,3.5],[2,55,3]],"ltp":0.0,"tv":0.0,"id":9417341},{"batl":[[0,710,9],[1,730,3.23]],"ltp":0.0,"tv":0.0,"id":8231803},{"batl":[[0,710,9],[1,730,3.23]],"ltp":0.0,"tv":0.0,"id":10170404},{"batl":[[0,710,9],[1,730,3.23]],"ltp":0.0,"tv":0.0,"id":15608820},{"batl":[[0,710,9],[1,730,3.23]],"ltp":0.0,"tv":0.0,"id":9193530},{"batl":[[0,710,9],[1,730,3.23]],"ltp":0.0,"tv":0.0,"id":9001159}]}]}
{"op":"mcm","clk":"990298099","pt":1580495943291,"mc":[{"id":"1.168133548","rc":[{"batb":[[1,3.8,5.55]],"ltp":0.0,"tv":0.0,"id":9417341},{"batb":[[1,5.4,2.82],[2,5.3,3.03]],"ltp":0.0,"tv":0.0,"id":8231803},{"batb":[[2,5.8,2.52]],"ltp":0.0,"tv":0.0,"id":10170404}]}]}
{"op":"mcm","clk":"990300720","pt":1580495968494,"mc":[{"id":"1.168133548","rc":[{"batl":[[0,17.5,5],[1,34,3.39],[2,36,9]],"ltp":0.0,"tv":0.0,"id":10616006}]}]}
{"op":"mcm","clk":"990301927","pt":1580495980458,"mc":[{"id":"1.168133548","rc":[{"batb":[[0,3.9,1.99],[1,3.85,1.6],[2,3.8,5.55]],"ltp":0.0,"tv":0.0,"id":9417341}]}]}
{"op":"mcm","clk":"990301980","pt":1580495981138,"mc":[{"id":"1.168133548","rc":[{"batb":[[0,5.4,3.67],[1,5.3,3.03],[2,5.2,2.52]],"ltp":0.0,"tv":0.0,"id":8231803}]}]}
{"op":"mcm","clk":"990302995","pt":1580495991853,"mc":[{"id":"1.168133548","rc":[{"batb":[[1,3.85,13.6]],"ltp":0.0,"tv":0.0,"id":9417341}]}]}
{"op":"mcm","clk":"990304053","pt":1580496002980,"mc":[{"id":"1.168133548","rc":[{"batb":[[0,3.9,4.51]],"ltp":0.0,"tv":0.0,"id":9417341}]}]}
{"op":"mcm","clk":"990305096","pt":1580496014308,"mc":[{"id":"1.168133548","rc":[{"batb":[[0,3.9,16.51],[1,3.85,1.6]],"ltp":0.0,"tv":0.0,"id":9417341}]}]}
{"op":"mcm","clk":"990305652","pt":1580496020089,"mc":[{"id":"1.168133548","rc":[{"batb":[[1,3.8,5.55],[2,3.7,2.52]],"ltp":0.0,"tv":0.0,"id":9417341}]}]}
{"op":"mcm","clk":"990305825","pt":1580496021914,"mc":[{"id":"1.168133548","rc":[{"batb":[[0,3.95,1.54],[1,3.9,16.51],[2,3.8,5.55]],"ltp":0.0,"tv":0.0,"id":9417341}]}]}
{"op":"mcm","clk":"990310644","pt":1580496067538,"mc":[{"id":"1.168133548","rc":[{"batl":[[1,18.5,3.23]],"ltp":0.0,"tv":0.0,"id":9417341},{"batl":[[1,34,3.23]],"ltp":0.0,"tv":0.0,"id":10616006},{"trd":[[6.8,2.02],[7,3.98]],"batb":[[0,5.3,6.49],[1,5.1,2.52],[2,5,20]],"ltp":6.8,"tv":6.0,"id":17352128}],"tv":6.0}]}
{"op":"mcm","clk":"990310692","pt":1580496068022,"mc":[{"id":"1.168133548","rc":[{"batl":[[0,17.5,9.29]],"ltp":0.0,"tv":0.0,"id":9417341},{"batl":[[0,17.5,5.29]],"ltp":0.0,"tv":0.0,"id":10616006}]}]}
{"op":"mcm","clk":"990310811","pt":1580496069236,"mc":[{"id":"1.168133548","rc":[{"batl":[[0,19.5,2.1],[1,20,3.28],[2,21,6]],"ltp":6.8,"tv":6.0,"id":17352128}]}]}
{"op":"mcm","clk":"990311169","pt":1580496072527,"mc":[{"id":"1.168133548","rc":[{"trd":[[6.8,2.04]],"batb":[[0,5.3,6.48]],"batl":[[0,6.8,4.99],[1,19.5,2.1],[2,20,3.28]],"ltp":6.8,"tv":6.02,"id":17352128}],"tv":6.02}]}
{"op":"mcm","clk":"990312937","pt":1580496088409,"mc":[{"id":"1.168133548","rc":[{"batl":[[1,20,3.48],[2,21,6]],"ltp":6.8,"tv":6.02,"id":17352128}]}]}
{"op":"mcm","clk":"990313692","pt":1580496095286,"mc":[{"id":"1.168133548","rc":[{"trd":[[9,0.02],[9.2,3.98]],"batb":[[0,8.8,3.58],[1,8.6,2.52],[2,8.2,2.72]],"ltp":9.0,"tv":4.0,"id":10616006}],"tv":10.02}]}
{"op":"mcm","clk":"990318232","pt":1580496135726,"mc":[{"id":"1.168133548","rc":[{"batb":[[0,4,1.99],[1,3.95,1.54],[2,3.9,14.52]],"ltp":0.0,"tv":0.0,"id":9417341}]}]}
{"op":"mcm","clk":"990324170","pt":1580496188545,"mc":[{"id":"1.168133548","rc":[{"batb":[[0,4,5.02]],"batl":[[0,17,3.32],[1,17.5,9],[2,55,3.2]],"ltp":0.0,"tv":0.0,"id":9417341},{"batl":[[0,700,3.03],[1,710,9],[2,730,0.2]],"ltp":0.0,"tv":0.0,"id":9001159}]}]}
{"op":"mcm","clk":"990324273","pt":1580496189551,"mc":[{"id":"1.168133548","rc":[{"batl":[[1,730,0.2]],"ltp":0.0,"tv":0.0,"id":8429550},{"batb":[[0,4.1,1.22],[1,4,5.02],[2,3.95,1.54]],"ltp":0.0,"tv":0.0,"id":9417341},{"batb":[[0,5.5,3.87],[1,5.4,2.82]],"batl":[[0,700,3.03],[1,710,9],[2,730,0.2]],"ltp":0.0,"tv":0.0,"id":8231803},{"batl":[[0,700,3.03],[1,710,9],[2,730,0.2]],"ltp":0.0,"tv":0.0,"id":15608820}]}]}
{"op":"mcm","clk":"990324397","pt":1580496190546,"mc":[{"id":"1.168133548","rc":[{"batl":[[0,700,3.03],[1,710,9],[2,730,0.2]],"ltp":0.0,"tv":0.0,"id":8429550},{"batb":[[0,8.6,3.07],[1,8.4,3.03]],"batl":[[0,17,3.32],[1,17.5,5],[2,36,9.2]],"ltp":9.0,"tv":4.0,"id":10616006},{"batb":[[2,5.9,3.03]],"ltp":0.0,"tv":0.0,"id":10170404}]}]}
{"op":"mcm","clk":"990324482","pt":1580496191242,"mc":[{"id":"1.168133548","rc":[{"batb":[[1,6,1.88]],"batl":[[0,700,3.03],[1,710,9],[2,730,0.2]],"ltp":0.0,"tv":0.0,"id":10170404},{"batl":[[0,700,3.03],[1,710,9],[2,730,0.2]],"ltp":0.0,"tv":0.0,"id":9193530}]}]}
{"op":"mcm","clk":"990324587","pt":1580496192143,"mc":[{"id":"1.168133548","rc":[{"batl":[[0,680,9],[1,700,3.03]],"ltp":0.0,"tv":0.0,"id":8429550},{"batl":[[0,16,9],[1,17,3.32]],"ltp":0.0,"tv":0.0,"id":9417341},{"batl":[[0,680,9],[1,700,3.03]],"ltp":0.0,"tv":0.0,"id":8231803},{"batl":[[0,680,9],[1,700,3.03]],"ltp":0.0,"tv":0.0,"id":10170404},{"batl":[[0,680,9],[1,700,3.03]],"ltp":0.0,"tv":0.0,"id":15608820},{"batl":[[0,680,9],[1,700,3.03]],"ltp":0.0,"tv":0.0,"id":9193530},{"batl":[[0,680,9],[1,700,3.03]],"ltp":0.0,"tv":0.0,"id":9001159}]}]}
{"op":"mcm","clk":"990324900","pt":1580496195523,"mc":[{"id":"1.168133548","rc":[{"batl":[[0,680,9.2],[2,730,0]],"ltp":0.0,"tv":0.0,"id":8429550},{"batl":[[0,16,9.2],[2,55,3]],"ltp":0.0,"tv":0.0,"id":9417341},{"batl":[[0,680,9.2],[2,730,0]],"ltp":0.0,"tv":0.0,"id":8231803},{"batl":[[0,17,3.52],[2,36,9]],"ltp":9.0,"tv":4.0,"id":10616006},{"batl":[[0,680,9.2],[2,730,0]],"ltp":0.0,"tv":0.0,"id":10170404},{"batl":[[0,680,9.2],[2,730,0]],"ltp":0.0,"tv":0.0,"id":15608820},{"batl":[[0,680,9.2],[2,730,0]],"ltp":0.0,"tv":0.0,"id":9193530},{"batl":[[0,680,9.2],[2,730,0]],"ltp":0.0,"tv":0.0,"id":9001159}]}]}
{"op":"mcm","clk":"990325296","pt":1580496199338,"mc":[{"id":"1.168133548","rc":[{"batb":[[2,3.9,14.52]],"ltp":0.0,"tv":0.0,"id":9417341}]}]}
{"op":"mcm","clk":"990325490","pt":1580496201081,"mc":[{"id":"1.168133548","rc":[{"batb":[[0,4.1,2.69]],"ltp":0.0,"tv":0.0,"id":9417341}]}]}
{"op":"mcm","clk":"990327431","pt":1580496220409,"mc":[{"id":"1.168133548","rc":[{"batl":[[0,16,9.52],[1,17,3.03]],"ltp":0.0,"tv":0.0,"id":9417341}]}]}
{"op":"mcm","clk":"990328067","pt":1580496227111,"mc":[{"id":"1.168133548","rc":[{"batb":[[1,5.1,5.52]],"ltp":6.8,"tv":6.02,"id":17352128}]}]}
{"op":"mcm","clk":"990329683","pt":1580496243650,"mc":[{"id":"1.168133548","rc":[{"batb":[[0,4.1,5.21]],"ltp":0.0,"tv":0.0,"id":9417341},{"batb":[[1,6,4.4]],"ltp":0.0,"tv":0.0,"id":10170404}]}]}
{"op":"mcm","clk":"990333928","pt":1580496290058,"mc":[{"id":"1.168133548","rc":[{"batl":[[0,6.2,33.8],[1,16,9.52],[2,17,3.03]],"ltp":0.0,"tv":0.0,"id":9417341}]}]}
{"op":"mcm","clk":"990336848","pt":1580496322325,"mc":[{"id":"1.168133548","rc":[{"batl":[[1,13,9],[2,17,3.55]],"ltp":0.0,"tv":0.0,"id":9417341}]}]}
{"op":"mcm","clk":"990337643","pt":1580496331409,"mc":[{"id":"1.168133548","rc":[{"batb":[[0,4.2,1.99],[1,4.1,5.21],[2,4,3.03]],"ltp":0.0,"tv":0.0,"id":9417341}]}]}
{"op":"mcm","clk":"990339275","pt":1580496349380,"mc":[{"id":"1.168133548","rc":[{"batb":[[1,4.1,3.74]],"ltp":0.0,"tv":0.0,"id":9417341}]}]}
{"op":"mcm","clk":"990339400","pt":1580496351108,"mc":[{"id":"1.168133548","rc":[{"batb":[[0,4.2,3.41]],"ltp":0.0,"tv":0.0,"id":9417341}]}]}
{"op":"mcm","clk":"990343429","pt":1580496394469,"mc":[{"id":"1.168133548","rc":[{"batb":[[1,4.1,2.52]],"ltp":0.0,"tv":0.0,"id":9417341}]}]}
{"op":"mcm","clk":"990343457","pt":1580496394784,"mc":[{"id":"1.168133548","rc":[{"batb":[[0,4.3,1.16],[1,4.2,3.41],[2,4.1,2.52]],"ltp":0.0,"tv":0.0,"id":9417341}]}]}
{"op":"mcm","clk":"990344286","pt":1580496404543,"mc":[{"id":"1.168133548","rc":[{"batb":[[0,7.2,1.98],[1,7,1.99],[2,5.8,1.06]],"ltp":0.0,"tv":0.0,"id":8429550},{"batb":[[0,4.3,3.14]],"ltp":0.0,"tv":0.0,"id":9417341},{"batb":[[0,5.6,2.82],[1,5.5,3.03],[2,5.4,2.82]],"ltp":0.0,"tv":0.0,"id":8231803},{"batb":[[0,8.8,2.53],[1,8.6,2.52],[2,8.4,3.03]],"ltp":9.0,"tv":4.0,"id":10616006},{"batb":[[0,7.2,1.98],[1,7,1.99],[2,6,4.4]],"ltp":0.0,"tv":0.0,"id":10170404},{"batb":[[0,8,1.98],[1,7.8,1.99],[2,7.4,3.69]],"ltp":0.0,"tv":0.0,"id":15608820},{"batb":[[0,8.2,1.98],[1,8,1.99],[2,7.6,3.67]],"ltp":0.0,"tv":0.0,"id":9193530},{"batb":[[0,7.2,1.98],[1,7,1.99],[2,6.8,1.02]],"ltp":0.0,"tv":0.0,"id":9001159},{"batb":[[0,5.3,8.4]],"ltp":6.8,"tv":6.02,"id":17352128}]}]}
{"op":"mcm","clk":"990344724","pt":1580496409859,"mc":[{"id":"1.168133548","rc":[{"batb":[[1,4.2,1.99]],"ltp":0.0,"tv":0.0,"id":9417341}]}]}
{"op":"mcm","clk":"990344905","pt":1580496411964,"mc":[{"id":"1.168133548","rc":[{"batb":[[0,4.4,1.33],[1,4.3,3.14],[2,4.2,1.99]],"ltp":0.0,"tv":0.0,"id":9417341}]}]}
{"op":"mcm","clk":"990345851","pt":1580496422671,"mc":[{"id":"1.168133548","rc":[{"batb":[[1,4.3,5.66]],"ltp":0.0,"tv":0.0,"id":9417341},{"batb":[[2,7.6,3.18]],"ltp":0.0,"tv":0.0,"id":15608820},{"batb":[[2,7.8,3.16]],"ltp":0.0,"tv":0.0,"id":9193530}]}]}
{"op":"mcm","clk":"990346954","pt":1580496435876,"mc":[{"id":"1.168133548","rc":[{"batl":[[0,5.5,20],[1,6.2,33.8],[2,13,9]],"ltp":0.0,"tv":0.0,"id":9417341}]}]}
{"op":"mcm","clk":"990348043","pt":1580496447832,"mc":[{"id":"1.168133548","rc":[{"batb":[[1,5.1,2.52]],"ltp":6.8,"tv":6.02,"id":17352128}]}]}
{"op":"mcm","clk":"990349410","pt":1580496463442,"mc":[{"id":"1.168133548","rc":[{"batb":[[0,4.5,1.99],[1,4.4,1.33],[2,4.3,5.66]],"ltp":0.0,"tv":0.0,"id":9417341}]}]}
{"op":"mcm","clk":"990349464","pt":1580496464134,"mc":[{"id":"1.168133548","rc":[{"batb":[[0,7.4,1.99],[1,7.2,1.98]],"ltp":0.0,"tv":0.0,"id":9001159}]}]}
{"op":"mcm","clk":"990349673","pt":1580496466530,"mc":[{"id":"1.168133548","rc":[{"batb":[[1,5.8,1.06],[2,5.2,2.52]],"ltp":0.0,"tv":0.0,"id":8429550},{"batb":[[0,8.2,1.99],[1,8,1.98]],"ltp":0.0,"tv":0.0,"id":15608820}]}]}
{"op":"mcm","clk":"990349733","pt":1580496467355,"mc":[{"id":"1.168133548","rc":[{"batb":[[0,7.4,1.99],[1,7.2,1.98],[2,5.8,1.06]],"ltp":0.0,"tv":0.0,"id":8429550},{"batb":[[0,7.4,1.99],[1,7.2,1.98]],"ltp":0.0,"tv":0.0,"id":10170404}]}]}
{"op":"mcm","clk":"990349809","pt":1580496468528,"mc":[{"id":"1.168133548","rc":[{"batb":[[1,7.8,3.16],[2,7.6,3.03]],"ltp":0.0,"tv":0.0,"id":9193530}]}]}
{"op":"mcm","clk":"990349817","pt":1580496468620,"mc":[{"id":"1.168133548","rc":[{"batb":[[0,8.4,1.99],[1,8.2,1.98],[2,7.8,3.16]],"ltp":0.0,"tv":0.0,"id":9193530}]}]}
{"op":"mcm","clk":"990352244","pt":1580496496496,"mc":[{"id":"1.168133548","rc":[{"batb":[[0,4.5,5.02]],"ltp":0.0,"tv":0.0,"id":9417341}]}]}
{"op":"mcm","clk":"990352351","pt":1580496497492,"mc":[{"id":"1.168133548","rc":[{"batl":[[1,6,3.03],[2,6.2,33.8]],"ltp":0.0,"tv":0.0,"id":9417341},{"batl":[[1,700,0]],"ltp":0.0,"tv":0.0,"id":8231803},{"batb":[[0,7.4,5.02]],"batl":[[0,670,3.23],[1,680,9]],"ltp":0.0,"tv":0.0,"id":9001159}]}]}
{"op":"mcm","clk":"990352458","pt":1580496498496,"mc":[{"id":"1.168133548","rc":[{"batl":[[1,700,0]],"ltp":0.0,"tv":0.0,"id":8429550},{"batl":[[0,670,3.23],[1,680,9]],"ltp":0.0,"tv":0.0,"id":8231803},{"batb":[[0,8.2,5.02]],"batl":[[0,670,3.23],[1,680,9]],"ltp":0.0,"tv":0.0,"id":15608820}]}]}
{"op":"mcm","clk":"990352563","pt":1580496499499,"mc":[{"id":"1.168133548","rc":[{"batl":[[0,670,3.23],[1,680,9]],"ltp":0.0,"tv":0.0,"id":8429550},{"batb":[[0,8.8,5.56],[2,8.2,2.72]],"ltp":9.0,"tv":4.0,"id":10616006},{"batl":[[0,670,3.23],[1,680,9]],"ltp":0.0,"tv":0.0,"id":10170404},{"batl":[[1,700,0]],"ltp":0.0,"tv":0.0,"id":9193530}]}]}
{"op":"mcm","clk":"990352574","pt":1580496499600,"mc":[{"id":"1.168133548","rc":[{"batl":[[0,670,3.23],[1,680,9]],"ltp":0.0,"tv":0.0,"id":9193530}]}]}
{"op":"mcm","clk":"990353903","pt":1580496515899,"mc":[{"id":"1.168133548","rc":[{"batl":[[0,650,9],[1,670,3.23]],"ltp":0.0,"tv":0.0,"id":8429550},{"batl":[[0,650,9],[1,670,3.23]],"ltp":0.0,"tv":0.0,"id":8231803},{"batl":[[0,650,9],[1,670,3.23]],"ltp":0.0,"tv":0.0,"id":10170404},{"batl":[[0,650,9],[1,670,3.23]],"ltp":0.0,"tv":0.0,"id":15608820},{"batl":[[0,650,9],[1,670,3.23]],"ltp":0.0,"tv":0.0,"id":9193530},{"batl":[[0,650,9],[1,670,3.23]],"ltp":0.0,"tv":0.0,"id":9001159}]}]}
{"op":"mcm","clk":"990356140","pt":1580496542561,"mc":[{"id":"1.168133548","rc":[{"batb":[[0,4.5,7.54]],"ltp":0.0,"tv":0.0,"id":9417341},{"batb":[[0,8.2,7.54]],"ltp":0.0,"tv":0.0,"id":15608820},{"batb":[[0,7.4,7.54]],"ltp":0.0,"tv":0.0,"id":9001159}]}]}
{"op":"mcm","clk":"990357044","pt":1580496552573,"mc":[{"id":"1.168133548","rc":[{"batb":[[0,7.4,8.2]],"ltp":0.0,"tv":0.0,"id":9001159}]}]}
{"op":"mcm","clk":"990358834","pt":1580496573788,"mc":[{"id":"1.168133548","rc":[{"batl":[[1,6,5.03]],"ltp":0.0,"tv":0.0,"id":9417341}]}]}
{"op":"mcm","clk":"990359497","pt":1580496582421,"mc":[{"id":"1.168133548","rc":[{"batb":[[2,7.6,2.52]],"ltp":0.0,"tv":0.0,"id":15608820}]}]}
{"op":"mcm","clk":"990359534","pt":1580496582842,"mc":[{"id":"1.168133548","rc":[{"batb":[[0,8.2,8.14]],"ltp":0.0,"tv":0.0,"id":15608820}]}]}
{"op":"mcm","clk":"990360656","pt":1580496596320,"mc":[{"id":"1.168133548","rc":[{"batb":[[0,7.6,1.98],[1,7.4,1.99]],"ltp":0.0,"tv":0.0,"id":8429550},{"batb":[[0,4.5,9.52],[2,4.3,3.68]],"ltp":0.0,"tv":0.0,"id":9417341},{"batb":[[0,7.6,1.98],[1,7.4,1.99]],"ltp":0.0,"tv":0.0,"id":10170404},{"batb":[[0,8.4,2.58],[1,8.2,7.54]],"ltp":0.0,"tv":0.0,"id":15608820},{"batb":[[0,8.6,1.98],[1,8.4,1.99]],"ltp":0.0,"tv":0.0,"id":9193530},{"batb":[[0,7.6,2.64],[1,7.4,7.54]],"ltp":0.0,"tv":0.0,"id":9001159}]}]}
{"op":"mcm","clk":"990361360","pt":1580496603977,"mc":[{"id":"1.168133548","rc":[{"batb":[[0,7.8,1.99],[1,7.6,2.64],[2,7.4,5.55]],"ltp":0.0,"tv":0.0,"id":9001159}]}]}
{"op":"mcm","clk":"990361450","pt":1580496604868,"mc":[{"id":"1.168133548","rc":[{"batb":[[0,8.6,1.99],[1,8.4,2.58],[2,8.2,5.55]],"ltp":0.0,"tv":0.0,"id":15608820}]}]}
{"op":"mcm","clk":"990361530","pt":1580496605746,"mc":[{"id":"1.168133548","rc":[{"batb":[[0,7.8,1.99],[1,7.6,1.98]],"ltp":0.0,"tv":0.0,"id":8429550}]}]}
{"op":"mcm","clk":"990361647","pt":1580496607059,"mc":[{"id":"1.168133548","rc":[{"batb":[[1,6,4.4],[2,5.9,3.03]],"ltp":0.0,"tv":0.0,"id":10170404}]}]}
{"op":"mcm","clk":"990361733","pt":1580496607954,"mc":[{"id":"1.168133548","rc":[{"batb":[[0,8.8,1.99],[1,8.6,1.98]],"ltp":0.0,"tv":0.0,"id":9193530}]}]}
{"op":"mcm","clk":"990371215","pt":1580496700720,"mc":[{"id":"1.168133548","rc":[{"batb":[[0,5.6,3.71]],"ltp":0.0,"tv":0.0,"id":8231803}]}]}
{"op":"mcm","clk":"990371551","pt":1580496703213,"mc":[{"id":"1.168133548","rc":[{"trd":[[5.5,4.1]],"batl":[[0,5.5,17.95]],"ltp":5.5,"tv":4.1,"id":9417341}],"tv":14.12}]}
{"op":"mcm","clk":"990371968","pt":1580496707044,"mc":[{"id":"1.168133548","rc":[{"batb":[[0,4.6,3],[1,4.5,9.52],[2,4.4,1.33]],"ltp":5.5,"tv":4.1,"id":9417341}]}]}
{"op":"mcm","clk":"990372136","pt":1580496708569,"mc":[{"id":"1.168133548","rc":[{"batb":[[0,5.4,3.93],[1,5.3,7.47],[2,5.1,2.52]],"ltp":6.8,"tv":6.02,"id":17352128}]}]}
{"op":"mcm","clk":"990373311","pt":1580496719545,"mc":[{"id":"1.168133548","rc":[{"batb":[[0,5.3,8.4],[1,5.1,2.52],[2,5,20]],"ltp":6.8,"tv":6.02,"id":17352128}]}]}
{"op":"mcm","clk":"990373422","pt":1580496720534,"mc":[{"id":"1.168133548","rc":[{"batb":[[0,5.5,3],[1,5.3,8.4],[2,5.1,2.52]],"ltp":6.8,"tv":6.02,"id":17352128}]}]}
{"op":"mcm","clk":"990373772","pt":1580496723562,"mc":[{"id":"1.168133548","rc":[{"batb":[[0,5.6,6.23]],"ltp":0.0,"tv":0.0,"id":8231803}]}]}
{"op":"mcm","clk":"990374518","pt":1580496730477,"mc":[{"id":"1.168133548","rc":[{"batb":[[0,5.4,3.93],[1,5.3,7.47]],"ltp":6.8,"tv":6.02,"id":17352128}]}]}
{"op":"mcm","clk":"990375197","pt":1580496736800,"mc":[{"id":"1.168133548","rc":[{"batl":[[0,17,15],[1,650,9],[2,670,3.23]],"ltp":0.0,"tv":0.0,"id":10170404}]}]}
{"op":"mcm","clk":"990375700","pt":1580496741480,"mc":[{"id":"1.168133548","rc":[{"batb":[[0,5.5,3],[1,5.3,8.4]],"ltp":6.8,"tv":6.02,"id":17352128}]}]}
{"op":"mcm","clk":"990375795","pt":1580496742104,"mc":[{"id":"1.168133548","rc":[{"batl":[[1,36,9]],"ltp":0.0,"tv":0.0,"id":10170404}]}]}
{"op":"mcm","clk":"990376508","pt":1580496748912,"mc":[{"id":"1.168133548","rc":[{"batb":[[0,4.7,1.99],[1,4.6,3],[2,4.5,7.53]],"ltp":5.5,"tv":4.1,"id":9417341}]}]}
{"op":"mcm","clk":"990376640","pt":1580496750122,"mc":[{"id":"1.168133548","rc":[{"batb":[[0,8.4,2.58],[1,8.2,5.55],[2,7.6,2.52]],"ltp":0.0,"tv":0.0,"id":15608820}]}]}
{"op":"mcm","clk":"990386556","pt":1580496752490,"mc":[{"id":"1.168133548","rc":[{"batb":[[0,4.7,4.99],[1,4.5,7.53],[2,4.4,1.33]],"ltp":5.5,"tv":4.1,"id":9417341}]}]}
{"op":"mcm","clk":"990386656","pt":1580496753422,"mc":[{"id":"1.168133548","rc":[{"batb":[[0,5.4,3.93],[1,5.3,7.47]],"ltp":6.8,"tv":6.02,"id":17352128}]}]}
{"op":"mcm","clk":"990386762","pt":1580496754426,"mc":[{"id":"1.168133548","rc":[{"batb":[[0,4.8,3.03],[1,4.7,4.99],[2,4.5,4.5]],"ltp":5.5,"tv":4.1,"id":9417341},{"batb":[[0,7.8,5.02],[2,7.4,2.52]],"batl":[[1,670,0.2]],"ltp":0.0,"tv":0.0,"id":9001159}]}]}
{"op":"mcm","clk":"990386892","pt":1580496755420,"mc":[{"id":"1.168133548","rc":[{"batb":[[0,5.7,3.87],[1,5.6,5.39]],"batl":[[0,640,3.03],[1,650,9],[2,670,0.2]],"ltp":0.0,"tv":0.0,"id":8231803},{"batl":[[0,640,3.03],[1,650,9],[2,670,0.2]],"ltp":0.0,"tv":0.0,"id":15608820},{"batl":[[0,640,3.03],[1,650,9],[2,670,0.2]],"ltp":0.0,"tv":0.0,"id":9001159}]}]}
{"op":"mcm","clk":"990387018","pt":1580496756517,"mc":[{"id":"1.168133548","rc":[{"batl":[[0,640,3.03],[1,650,9],[2,670,0.2]],"ltp":0.0,"tv":0.0,"id":8429550},{"batb":[[1,6.2,3.81],[2,6,3.62]],"batl":[[0,16.5,3.03],[1,17,15],[2,36,9]],"ltp":0.0,"tv":0.0,"id":10170404},{"batl":[[1,670,0.2]],"ltp":0.0,"tv":0.0,"id":9193530}]}]}
{"op":"mcm","clk":"990387138","pt":1580496757520,"mc":[{"id":"1.168133548","rc":[{"batb":[[2,4.6,50]],"ltp":5.5,"tv":4.1,"id":9417341},{"batl":[[0,640,3.03],[1,650,9],[2,670,0.2]],"ltp":0.0,"tv":0.0,"id":9193530},{"batb":[[0,5.5,3.03],[1,5.4,3.93],[2,5.3,4.43]],"ltp":6.8,"tv":6.02,"id":17352128}]}]}
{"op":"mcm","clk":"990387494","pt":1580496761531,"mc":[{"id":"1.168133548","rc":[{"batb":[[1,4.7,1.99]],"ltp":5.5,"tv":4.1,"id":9417341}]}]}
{"op":"mcm","clk":"990387562","pt":1580496762143,"mc":[{"id":"1.168133548","rc":[{"batb":[[0,4.9,3],[1,4.8,3.03],[2,4.7,1.99]],"ltp":5.5,"tv":4.1,"id":9417341},{"batb":[[0,5.6,3],[1,5.5,3.03],[2,5.3,5.36]],"ltp":6.8,"tv":6.02,"id":17352128}]}]}
{"op":"mcm","clk":"990388745","pt":1580496771564,"mc":[{"id":"1.168133548","rc":[{"batb":[[0,5,50],[1,4.9,3],[2,4.8,3.03]],"ltp":5.5,"tv":4.1,"id":9417341}]}]}
{"op":"mcm","clk":"990388880","pt":1580496772731,"mc":[{"id":"1.168133548","rc":[{"batb":[[0,5,53],[1,4.8,3.03],[2,4.7,1.99]],"ltp":5.5,"tv":4.1,"id":9417341}]}]}
{"op":"mcm","clk":"990389149","pt":1580496775451,"mc":[{"id":"1.168133548","rc":[{"batl":[[0,620,9],[1,640,3.03]],"ltp":0.0,"tv":0.0,"id":8429550},{"batl":[[0,620,9],[1,640,3.03]],"ltp":0.0,"tv":0.0,"id":8231803},{"batl":[[0,620,9],[1,640,3.03]],"ltp":0.0,"tv":0.0,"id":15608820},{"batl":[[0,620,9],[1,640,3.03]],"ltp":0.0,"tv":0.0,"id":9193530},{"batl":[[0,620,9],[1,640,3.03]],"ltp":0.0,"tv":0.0,"id":9001159}]}]}
{"op":"mcm","clk":"990390082","pt":1580496782976,"mc":[{"id":"1.168133548","rc":[{"batb":[[0,5.1,2.52],[1,5,53],[2,4.8,3.03]],"ltp":5.5,"tv":4.1,"id":9417341},{"batb":[[0,7.8,7.54]],"ltp":0.0,"tv":0.0,"id":9001159},{"batb":[[0,5.6,5.52]],"ltp":6.8,"tv":6.02,"id":17352128}]}]}
{"op":"mcm","clk":"990391797","pt":1580496797477,"mc":[{"id":"1.168133548","rc":[{"batb":[[0,5.7,3],[1,5.6,2.52],[2,5.5,3.03]],"ltp":6.8,"tv":6.02,"id":17352128}]}]}
{"op":"mcm","clk":"990392402","pt":1580496802701,"mc":[{"id":"1.168133548","rc":[{"batl":[[1,20,3.28]],"ltp":6.8,"tv":6.02,"id":17352128}]}]}
{"op":"mcm","clk":"990392592","pt":1580496804505,"mc":[{"id":"1.168133548","rc":[{"batb":[[0,5.1,6.44]],"ltp":5.5,"tv":4.1,"id":9417341}]}]}
{"op":"mcm","clk":"990398475","pt":1580496860001,"mc":[{"id":"1.168133548","rc":[{"trd":[[5.5,40]],"batb":[[0,5.5,18.84],[1,5.1,6.44],[2,5,53]],"batl":[[0,6,5.03],[1,6.2,33.8],[2,6.4,20]],"ltp":5.5,"tv":39.99,"id":9417341}],"tv":50.01}]}
{"op":"mcm","clk":"990399090","pt":1580496865394,"mc":[{"id":"1.168133548","rc":[{"batb":[[1,5.1,2.52]],"ltp":5.5,"tv":39.99,"id":9417341}]}]}
{"op":"mcm","clk":"990400118","pt":1580496874838,"mc":[{"id":"1.168133548","rc":[{"batb":[[0,8,1.98],[1,7.8,1.99]],"ltp":0.0,"tv":0.0,"id":8429550},{"batb":[[0,5.5,20.82]],"ltp":5.5,"tv":39.99,"id":9417341},{"batb":[[0,5.8,2.82],[1,5.7,3.03],[2,5.6,3.41]],"ltp":0.0,"tv":0.0,"id":8231803},{"batb":[[0,6.4,2.76],[1,6.2,3.03]],"ltp":0.0,"tv":0.0,"id":10170404},{"batb":[[0,9,1.98],[1,8.8,1.99]],"ltp":0.0,"tv":0.0,"id":9193530},{"batb":[[0,8,1.98],[1,7.8,7.54],[2,7.4,3.18]],"ltp":0.0,"tv":0.0,"id":9001159},{"batb":[[0,5.7,4.91]],"ltp":6.8,"tv":6.02,"id":17352128}]}]}
{"op":"mcm","clk":"990400505","pt":1580496878411,"mc":[{"id":"1.168133548","rc":[{"trd":[[5.5,49.99]],"batb":[[0,5.5,15.82]],"ltp":5.5,"tv":49.99,"id":9417341}],"tv":60.01}]}
{"op":"mcm","clk":"990400937","pt":1580496882249,"mc":[{"id":"1.168133548","rc":[{"batb":[[0,5.8,3],[1,5.7,1.91],[2,5.6,2.52]],"ltp":6.8,"tv":6.02,"id":17352128}]}]}
{"op":"mcm","clk":"990401489","pt":1580496887144,"mc":[{"id":"1.168133548","rc":[{"batb":[[0,5.6,1.99],[1,5.5,15.82],[2,5.1,2.52]],"ltp":5.5,"tv":49.99,"id":9417341}]}]}
{"op":"mcm","clk":"990401615","pt":1580496888248,"mc":[{"id":"1.168133548","rc":[{"batb":[[0,8.2,1.99],[1,8,1.98],[2,7.8,5.55]],"ltp":0.0,"tv":0.0,"id":9001159}]}]}
{"op":"mcm","clk":"990401784","pt":1580496889563,"mc":[{"id":"1.168133548","rc":[{"batb":[[1,5.8,1.06],[2,5.2,2.52]],"ltp":0.0,"tv":0.0,"id":8429550}]}]}
{"op":"mcm","clk":"990401839","pt":1580496890040,"mc":[{"id":"1.168133548","rc":[{"batb":[[0,7,1.99],[1,6.4,2.76],[2,6.2,3.03]],"ltp":0.0,"tv":0.0,"id":10170404}]}]}
{"op":"mcm","clk":"990401952","pt":1580496891051,"mc":[{"id":"1.168133548","rc":[{"batb":[[0,9.2,1.99],[1,9,1.98]],"ltp":0.0,"tv":0.0,"id":9193530}]}]}
{"op":"mcm","clk":"990402048","pt":1580496891945,"mc":[{"id":"1.168133548","rc":[{"batb":[[0,5.7,4.91],[1,5.6,2.52],[2,5.5,3.03]],"ltp":6.8,"tv":6.02,"id":17352128}]}]}
{"op":"mcm","clk":"990403472","pt":1580496903375,"mc":[{"id":"1.168133548","rc":[{"batb":[[0,5.6,4.51]],"ltp":5.5,"tv":49.99,"id":9417341},{"batb":[[1,6.4,5.28]],"ltp":0.0,"tv":0.0,"id":10170404},{"batb":[[0,5.8,3],[1,5.7,1.91],[2,5.6,2.52]],"ltp":6.8,"tv":6.02,"id":17352128}]}]}
{"op":"mcm","clk":"990405055","pt":1580496914380,"mc":[{"id":"1.168133548","rc":[{"batb":[[0,5.7,4.91],[1,5.6,2.52],[2,5.5,3.03]],"ltp":6.8,"tv":6.02,"id":17352128}]}]}
{"op":"mcm","clk":"990406607","pt":1580496927202,"mc":[{"id":"1.168133548","rc":[{"batb":[[0,5.8,3],[1,5.7,1.91],[2,5.6,2.52]],"ltp":6.8,"tv":6.02,"id":17352128}]}]}
{"op":"mcm","clk":"990407707","pt":1580496937909,"mc":[{"id":"1.168133548","rc":[{"batb":[[0,5.7,4.91],[1,5.6,2.52],[2,5.5,3.03]],"ltp":6.8,"tv":6.02,"id":17352128}]}]}
{"op":"mcm","clk":"990408786","pt":1580496947541,"mc":[{"id":"1.168133548","rc":[{"batb":[[0,5.8,3],[1,5.7,1.91],[2,5.6,2.52]],"ltp":6.8,"tv":6.02,"id":17352128}]}]}
{"op":"mcm","clk":"990409890","pt":1580496957436,"mc":[{"id":"1.168133548","rc":[{"batb":[[0,5.7,4.91],[1,5.6,2.52],[2,5.5,3.03]],"ltp":6.8,"tv":6.02,"id":17352128}]}]}
{"op":"mcm","clk":"990411047","pt":1580496969137,"mc":[{"id":"1.168133548","rc":[{"batb":[[0,5.8,3],[1,5.7,1.91],[2,5.6,2.52]],"ltp":6.8,"tv":6.02,"id":17352128}]}]}
{"op":"mcm","clk":"990411529","pt":1580496974065,"mc":[{"id":"1.168133548","rc":[{"batl":[[2,6.4,25.91]],"ltp":5.5,"tv":49.99,"id":9417341}]}]}
{"op":"mcm","clk":"990412153","pt":1580496979880,"mc":[{"id":"1.168133548","rc":[{"batb":[[0,5.7,4.91],[1,5.6,2.52],[2,5.5,3.03]],"ltp":6.8,"tv":6.02,"id":17352128}]}]}
{"op":"mcm","clk":"990412993","pt":1580496988118,"mc":[{"id":"1.168133548","rc":[{"batb":[[0,5.8,3],[1,5.7,1.91],[2,5.6,2.52]],"ltp":6.8,"tv":6.02,"id":17352128}]}]}
{"op":"mcm","clk":"990414192","pt":1580496999522,"mc":[{"id":"1.168133548","rc":[{"batb":[[0,5.7,4.91],[1,5.6,2.52],[2,5.5,3.03]],"ltp":6.8,"tv":6.02,"id":17352128}]}]}
{"op":"mcm","clk":"990415152","pt":1580497009262,"mc":[{"id":"1.168133548","rc":[{"batb":[[0,5.8,3],[1,5.7,1.91],[2,5.6,2.52]],"ltp":6.8,"tv":6.02,"id":17352128}]}]}
{"op":"mcm","clk":"990415971","pt":1580497017976,"mc":[{"id":"1.168133548","rc":[{"batb":[[0,5.7,4.91],[1,5.6,2.52],[2,5.5,3.03]],"ltp":6.8,"tv":6.02,"id":17352128}]}]}
{"op":"mcm","clk":"990416814","pt":1580497026425,"mc":[{"id":"1.168133548","rc":[{"batl":[[1,670,0.2],[2,670,0]],"ltp":0.0,"tv":0.0,"id":8231803},{"batl":[[0,610,3.03],[1,620,9]],"ltp":0.0,"tv":0.0,"id":9001159}]}]}
{"op":"mcm","clk":"990416933","pt":1580497027431,"mc":[{"id":"1.168133548","rc":[{"batb":[[2,5.3,3.03]],"batl":[[1,670,0.2],[2,670,0]],"ltp":0.0,"tv":0.0,"id":8429550},{"batl":[[0,610,3.03],[1,620,9],[2,670,0.2]],"ltp":0.0,"tv":0.0,"id":8231803},{"batl":[[0,610,3.03],[1,620,9]],"ltp":0.0,"tv":0.0,"id":15608820}]}]}
{"op":"mcm","clk":"990417047","pt":1580497028534,"mc":[{"id":"1.168133548","rc":[{"batl":[[0,610,3.03],[1,620,9],[2,670,0.2]],"ltp":0.0,"tv":0.0,"id":8429550},{"batb":[[1,6.6,3.81],[2,6.4,4.5]],"ltp":0.0,"tv":0.0,"id":10170404},{"batl":[[0,610,3.03],[1,620,9]],"ltp":0.0,"tv":0.0,"id":9193530},{"batb":[[0,5.8,6.03],[1,5.7,1.91],[2,5.6,2.52]],"ltp":6.8,"tv":6.02,"id":17352128}]}]}
{"op":"mcm","clk":"990418016","pt":1580497037739,"mc":[{"id":"1.168133548","rc":[{"batb":[[0,5.9,3],[1,5.8,3.03],[2,5.7,1.91]],"ltp":6.8,"tv":6.02,"id":17352128}]}]}
{"op":"mcm","clk":"990418998","pt":1580497046557,"mc":[{"id":"1.168133548","rc":[{"batl":[[2,6.4,35.91]],"ltp":5.5,"tv":49.99,"id":9417341}]}]}
{"op":"mcm","clk":"990420900","pt":1580497064509,"mc":[{"id":"1.168133548","rc":[{"batb":[[0,5.8,1.06],[1,5.4,1.98]],"ltp":0.0,"tv":0.0,"id":8429550},{"batb":[[0,5.6,6.49],[1,5.5,13.84]],"ltp":5.5,"tv":49.99,"id":9417341},{"batb":[[0,7.2,1.98],[1,7,1.99],[2,6.6,3.81]],"ltp":0.0,"tv":0.0,"id":10170404},{"batb":[[0,9.4,1.98],[1,9.2,1.99]],"ltp":0.0,"tv":0.0,"id":9193530},{"batb":[[0,8.4,1.98],[1,8.2,1.99]],"ltp":0.0,"tv":0.0,"id":9001159},{"batb":[[0,5.9,4.91],[2,5.6,2.52]],"ltp":6.8,"tv":6.02,"id":17352128}]}]}
{"op":"mcm","clk":"990421032","pt":1580497065708,"mc":[{"id":"1.168133548","rc":[{"batb":[[0,6,3],[1,5.9,1.91],[2,5.8,3.03]],"ltp":6.8,"tv":6.02,"id":17352128}]}]}
{"op":"mcm","clk":"990422363","pt":1580497078919,"mc":[{"id":"1.168133548","rc":[{"batb":[[0,5.9,4.91],[1,5.8,3.03],[2,5.6,2.52]],"ltp":6.8,"tv":6.02,"id":17352128}]}]}
{"op":"mcm","clk":"990422781","pt":1580497082930,"mc":[{"id":"1.168133548","rc":[{"batb":[[1,5.4,4.5]],"ltp":0.0,"tv":0.0,"id":8429550},{"batb":[[2,6.8,3.3]],"ltp":0.0,"tv":0.0,"id":10170404},{"batb":[[0,5.9,7.43]],"ltp":6.8,"tv":6.02,"id":17352128}]}]}
{"op":"mcm","clk":"990423458","pt":1580497089419,"mc":[{"id":"1.168133548","rc":[{"batb":[[0,6,3],[1,5.9,4.43],[2,5.8,3.03]],"ltp":6.8,"tv":6.02,"id":17352128}]}]}
{"op":"mcm","clk":"990425004","pt":1580497105716,"mc":[{"id":"1.168133548","rc":[{"batl":[[0,590,9],[1,610,3.03]],"ltp":0.0,"tv":0.0,"id":8429550},{"batl":[[0,590,9],[1,610,3.03]],"ltp":0.0,"tv":0.0,"id":8231803},{"batl":[[0,590,9],[1,610,3.03]],"ltp":0.0,"tv":0.0,"id":15608820},{"batl":[[0,590,9],[1,610,3.03]],"ltp":0.0,"tv":0.0,"id":9193530},{"batl":[[0,590,9],[1,610,3.03]],"ltp":0.0,"tv":0.0,"id":9001159}]}]}
{"op":"mcm","clk":"990426462","pt":1580497122340,"mc":[{"id":"1.168133548","rc":[{"batl":[[0,9,5],[1,16.5,3.03],[2,17,15]],"ltp":0.0,"tv":0.0,"id":10170404}]}]}
{"op":"mcm","clk":"990428691","pt":1580497146078,"mc":[{"id":"1.168133548","rc":[{"batl":[[0,6,55.03]],"ltp":5.5,"tv":49.99,"id":9417341}]}]}
{"op":"mcm","clk":"990428936","pt":1580497148368,"mc":[{"id":"1.168133548","rc":[{"batl":[[0,580,3.03],[1,590,9]],"ltp":0.0,"tv":0.0,"id":9001159}]}]}
{"op":"mcm","clk":"990429047","pt":1580497149571,"mc":[{"id":"1.168133548","rc":[{"batb":[[1,5.5,3.03],[2,5.4,4.5]],"batl":[[0,580,3.03],[1,590,9]],"ltp":0.0,"tv":0.0,"id":8429550},{"batl":[[0,580,3.03],[1,590,9]],"ltp":0.0,"tv":0.0,"id":8231803},{"batl":[[0,580,3.03],[1,590,9]],"ltp":0.0,"tv":0.0,"id":15608820}]}]}
{"op":"mcm","clk":"990429167","pt":1580497150574,"mc":[{"id":"1.168133548","rc":[{"batl":[[0,8.8,3.03],[1,9,5]],"ltp":0.0,"tv":0.0,"id":10170404},{"batl":[[0,580,3.03],[1,590,9]],"ltp":0.0,"tv":0.0,"id":9193530},{"batb":[[0,6,6.03],[2,5.6,2.52]],"ltp":6.8,"tv":6.02,"id":17352128}]}]}
{"op":"mcm","clk":"990433581","pt":1580497192729,"mc":[{"id":"1.168133548","rc":[{"batb":[[0,8.6,1.99],[1,8.4,1.98]],"ltp":0.0,"tv":0.0,"id":9001159}]}]}
{"op":"mcm","clk":"990433788","pt":1580497194574,"mc":[{"id":"1.168133548","rc":[{"batb":[[0,7,1.99],[1,5.8,1.06],[2,5.5,3.03]],"ltp":0.0,"tv":0.0,"id":8429550}]}]}
{"op":"mcm","clk":"990433856","pt":1580497195272,"mc":[{"id":"1.168133548","rc":[{"batb":[[0,7.4,1.99],[1,7.2,1.98]],"ltp":0.0,"tv":0.0,"id":10170404}]}]}
{"op":"mcm","clk":"990433966","pt":1580497196374,"mc":[{"id":"1.168133548","rc":[{"batb":[[1,7.8,3.16],[2,7.6,3.03]],"ltp":0.0,"tv":0.0,"id":9193530}]}]}
{"op":"mcm","clk":"990434910","pt":1580497203554,"mc":[{"id":"1.168133548","rc":[{"batb":[[0,7.2,1.98],[1,7,1.99],[2,5.8,1.06]],"ltp":0.0,"tv":0.0,"id":8429550},{"batb":[[0,7.4,3.97],[1,6.8,3.3],[2,6.6,3.03]],"ltp":0.0,"tv":0.0,"id":10170404},{"batb":[[0,8,1.98]],"ltp":0.0,"tv":0.0,"id":9193530},{"batb":[[0,8.8,1.98],[1,8.6,1.99]],"ltp":0.0,"tv":0.0,"id":9001159},{"batb":[[0,6,7.95],[1,5.9,2.52]],"ltp":6.8,"tv":6.02,"id":17352128}]}]}
{"op":"mcm","clk":"990435003","pt":1580497204160,"mc":[{"id":"1.168133548","rc":[{"batb":[[0,6.2,2.52],[1,6,7.95],[2,5.9,2.52]],"ltp":6.8,"tv":6.02,"id":17352128}]}]}
{"op":"mcm","clk":"990437053","pt":1580497219799,"mc":[{"id":"1.168133548","rc":[{"batl":[[0,560,9],[1,580,3.03]],"ltp":0.0,"tv":0.0,"id":8429550},{"batl":[[0,560,9],[1,580,3.03]],"ltp":0.0,"tv":0.0,"id":8231803},{"batl":[[0,560,9],[1,580,3.03]],"ltp":0.0,"tv":0.0,"id":15608820},{"batl":[[0,560,9],[1,580,3.03]],"ltp":0.0,"tv":0.0,"id":9193530},{"batl":[[0,560,9],[1,580,3.03]],"ltp":0.0,"tv":0.0,"id":9001159}]}]}
{"op":"mcm","clk":"990439962","pt":1580497241443,"mc":[{"id":"1.168133548","rc":[{"batl":[[0,550,3.03],[1,560,9]],"ltp":0.0,"tv":0.0,"id":9001159}]}]}
{"op":"mcm","clk":"990440099","pt":1580497242519,"mc":[{"id":"1.168133548","rc":[{"batl":[[0,550,3.03],[1,560,9]],"ltp":0.0,"tv":0.0,"id":8429550},{"batl":[[0,550,3.03],[1,560,9]],"ltp":0.0,"tv":0.0,"id":8231803},{"batl":[[0,550,3.03],[1,560,9]],"ltp":0.0,"tv":0.0,"id":15608820},{"batb":[[2,7.4,2.74]],"ltp":0.0,"tv":0.0,"id":9193530}]}]}
{"op":"mcm","clk":"990440211","pt":1580497243336,"mc":[{"id":"1.168133548","rc":[{"batb":[[0,8,5.01]],"batl":[[0,550,3.03],[1,560,9]],"ltp":0.0,"tv":0.0,"id":9193530}]}]}
{"op":"mcm","clk":"990441688","pt":1580497254452,"mc":[{"id":"1.168133548","rc":[{"batb":[[2,5.6,3.3]],"ltp":0.0,"tv":0.0,"id":8429550}]}]}
{"op":"mcm","clk":"990443283","pt":1580497266486,"mc":[{"id":"1.168133548","rc":[{"batb":[[0,7.2,2.21]],"ltp":0.0,"tv":0.0,"id":8429550},{"batb":[[0,5.6,6.78]],"ltp":5.5,"tv":49.99,"id":9417341}]}]}
{"op":"mcm","clk":"990445893","pt":1580497287188,"mc":[{"id":"1.168133548","rc":[{"batl":[[0,5.9,2],[1,6,55.03],[2,6.2,33.8]],"ltp":5.5,"tv":49.99,"id":9417341}]}]}
{"op":"mcm","clk":"990445975","pt":1580497287879,"mc":[{"id":"1.168133548","rc":[{"batl":[[0,6,55.03],[1,6.2,33.8],[2,6.4,35.91]],"ltp":5.5,"tv":49.99,"id":9417341}]}]}
{"op":"mcm","clk":"990451540","pt":1580497329456,"mc":[{"id":"1.168133548","rc":[{"batb":[[0,5.6,4.79]],"ltp":5.5,"tv":49.99,"id":9417341}]}]}
{"op":"mcm","clk":"990451663","pt":1580497330361,"mc":[{"id":"1.168133548","rc":[{"batb":[[0,9,1.99],[1,8.8,1.98]],"ltp":0.0,"tv":0.0,"id":9001159}]}]}
{"op":"mcm","clk":"990451960","pt":1580497332541,"mc":[{"id":"1.168133548","rc":[{"batb":[[0,7.4,1.99],[1,7.2,2.21]],"ltp":0.0,"tv":0.0,"id":8429550},{"batb":[[1,7.8,2.52]],"ltp":0.0,"tv":0.0,"id":9193530}]}]}
{"op":"mcm","clk":"990452098","pt":1580497333446,"mc":[{"id":"1.168133548","rc":[{"batb":[[2,5.7,1.66]],"batl":[[0,530,9],[1,550,3.03]],"ltp":0.0,"tv":0.0,"id":8429550},{"batl":[[0,530,9],[1,550,3.03]],"ltp":0.0,"tv":0.0,"id":8231803},{"batl":[[0,530,9],[1,550,3.03]],"ltp":0.0,"tv":0.0,"id":15608820},{"batb":[[0,8.2,2.6],[1,8,5.01],[2,7.8,2.52]],"batl":[[0,530,9],[1,550,3.03]],"ltp":0.0,"tv":0.0,"id":9193530},{"batl":[[0,530,9],[1,550,3.03]],"ltp":0.0,"tv":0.0,"id":9001159}]}]}
{"op":"mcm","clk":"990453522","pt":1580497343554,"mc":[{"id":"1.168133548","rc":[{"batb":[[0,7.6,1.98],[1,7.4,1.99],[2,6.8,1.01]],"ltp":0.0,"tv":0.0,"id":8429550},{"batb":[[0,8.4,1.98],[1,8.2,2.6],[2,8,3.03]],"ltp":0.0,"tv":0.0,"id":9193530},{"batb":[[0,9.2,1.98],[1,9,1.99]],"ltp":0.0,"tv":0.0,"id":9001159},{"batb":[[0,6.2,4.43],[1,6,6.03]],"ltp":6.8,"tv":6.02,"id":17352128}]}]}
{"op":"mcm","clk":"990458858","pt":1580497383164,"mc":[{"id":"1.168133548","rc":[{"batb":[[1,8.2,5.12]],"ltp":0.0,"tv":0.0,"id":9193530}]}]}
{"op":"mcm","clk":"990463079","pt":1580497414456,"mc":[{"id":"1.168133548","rc":[{"batl":[[1,10,1.25],[2,20,3.28]],"ltp":6.8,"tv":6.02,"id":17352128}]}]}
{"op":"mcm","clk":"990463200","pt":1580497415272,"mc":[{"id":"1.168133548","rc":[{"batl":[[1,10,2.5]],"ltp":6.8,"tv":6.02,"id":17352128}]}]}
{"op":"mcm","clk":"990467269","pt":1580497444517,"mc":[{"id":"1.168133548","rc":[{"batb":[[1,7.8,5.55],[2,7.4,3.18]],"ltp":0.0,"tv":0.0,"id":9001159}]}]}
{"op":"mcm","clk":"990467278","pt":1580497444587,"mc":[{"id":"1.168133548","rc":[{"batb":[[0,9.4,1.99],[1,9.2,1.98],[2,7.8,5.55]],"ltp":0.0,"tv":0.0,"id":9001159}]}]}
{"op":"mcm","clk":"990467714","pt":1580497447842,"mc":[{"id":"1.168133548","rc":[{"batb":[[0,7.8,1.99],[1,7.6,1.98]],"ltp":0.0,"tv":0.0,"id":8429550}]}]}
{"op":"mcm","clk":"990467842","pt":1580497448797,"mc":[{"id":"1.168133548","rc":[{"batb":[[0,8.6,1.99],[1,8.4,1.98],[2,8.2,3.13]],"ltp":0.0,"tv":0.0,"id":9193530}]}]}
{"op":"mcm","clk":"990470392","pt":1580497466557,"mc":[{"id":"1.168133548","rc":[{"batl":[[1,670,0.2],[2,670,0]],"ltp":0.0,"tv":0.0,"id":9001159}]}]}
{"op":"mcm","clk":"990470539","pt":1580497467528,"mc":[{"id":"1.168133548","rc":[{"batl":[[1,670,0.2],[2,670,0]],"ltp":0.0,"tv":0.0,"id":8429550},{"batl":[[0,520,3.03],[1,530,9]],"ltp":0.0,"tv":0.0,"id":8231803},{"batl":[[0,520,3.03],[1,530,9]],"ltp":0.0,"tv":0.0,"id":15608820},{"batl":[[0,520,3.03],[1,530,9],[2,670,0.2]],"ltp":0.0,"tv":0.0,"id":9001159}]}]}
{"op":"mcm","clk":"990470644","pt":1580497468160,"mc":[{"id":"1.168133548","rc":[{"batl":[[0,520,3.03],[1,530,9],[2,670,0.2]],"ltp":0.0,"tv":0.0,"id":8429550},{"batl":[[0,520,3.03],[1,530,9]],"ltp":0.0,"tv":0.0,"id":9193530},{"batb":[[1,6,3]],"batl":[[2,21,6.25]],"ltp":6.8,"tv":6.02,"id":17352128}]}]}
{"op":"mcm","clk":"990472563","pt":1580497482180,"mc":[{"id":"1.168133548","rc":[{"batb":[[0,8,1.98],[1,7.8,1.99]],"ltp":0.0,"tv":0.0,"id":8429550},{"batb":[[0,8.8,1.98],[1,8.6,1.99]],"ltp":0.0,"tv":0.0,"id":9193530},{"batb":[[0,9.6,1.98],[1,9.4,1.99]],"ltp":0.0,"tv":0.0,"id":9001159}]}]}
{"op":"mcm","clk":"990472981","pt":1580497485177,"mc":[{"id":"1.168133548","rc":[{"batl":[[0,520,3.23],[2,670,0]],"ltp":0.0,"tv":0.0,"id":8429550},{"batl":[[0,520,3.23],[2,670,0]],"ltp":0.0,"tv":0.0,"id":8231803},{"batl":[[0,520,3.23],[2,670,0]],"ltp":0.0,"tv":0.0,"id":15608820},{"batl":[[0,520,3.23],[2,670,0]],"ltp":0.0,"tv":0.0,"id":9193530},{"batl":[[0,520,3.23],[2,670,0]],"ltp":0.0,"tv":0.0,"id":9001159}]}]}
{"op":"mcm","clk":"990473828","pt":1580497491469,"mc":[{"id":"1.168133548","rc":[{"batb":[[0,5.9,4.23],[1,5.8,1.98],[2,5.7,3.03]],"ltp":0.0,"tv":0.0,"id":8231803},{"batb":[[0,9,2.77],[1,8.8,5.01],[2,8.6,2.52]],"ltp":9.0,"tv":4.0,"id":10616006},{"batb":[[0,8.6,2.33],[1,8.4,2.58],[2,8.2,5.55]],"ltp":0.0,"tv":0.0,"id":15608820},{"batb":[[0,8.8,4.25]],"ltp":0.0,"tv":0.0,"id":9193530},{"batb":[[0,9.6,4.06]],"ltp":0.0,"tv":0.0,"id":9001159}]}]}
{"op":"mcm","clk":"990474028","pt":1580497492992,"mc":[{"id":"1.168133548","rc":[{"batl":[[0,500,9],[1,520,3.23]],"ltp":0.0,"tv":0.0,"id":8429550},{"batl":[[0,500,9],[1,520,3.23]],"ltp":0.0,"tv":0.0,"id":8231803},{"batl":[[0,500,9],[1,520,3.23]],"ltp":0.0,"tv":0.0,"id":15608820},{"batl":[[0,500,9],[1,520,3.23]],"ltp":0.0,"tv":0.0,"id":9193530},{"batl":[[0,500,9],[1,520,3.23]],"ltp":0.0,"tv":0.0,"id":9001159}]}]}
{"op":"mcm","clk":"990474894","pt":1580497499181,"mc":[{"id":"1.168133548","rc":[{"batl":[[0,500,9.2],[1,520,3.03]],"ltp":0.0,"tv":0.0,"id":8429550},{"batl":[[0,500,9.2],[1,520,3.03]],"ltp":0.0,"tv":0.0,"id":8231803},{"batl":[[0,500,9.2],[1,520,3.03]],"ltp":0.0,"tv":0.0,"id":15608820},{"batl":[[0,500,9.2],[1,520,3.03]],"ltp":0.0,"tv":0.0,"id":9193530},{"batl":[[0,500,9.2],[1,520,3.03]],"ltp":0.0,"tv":0.0,"id":9001159}]}]}
{"op":"mcm","clk":"990475543","pt":1580497503962,"mc":[{"id":"1.168133548","rc":[{"batb":[[0,5.9,6.75]],"ltp":0.0,"tv":0.0,"id":8231803},{"batb":[[0,9,5.29]],"ltp":9.0,"tv":4.0,"id":10616006},{"batb":[[0,8.8,6.77]],"ltp":0.0,"tv":0.0,"id":9193530},{"batb":[[0,9.6,6.58]],"ltp":0.0,"tv":0.0,"id":9001159}]}]}
{"op":"mcm","clk":"990477618","pt":1580497519504,"mc":[{"id":"1.168133548","rc":[{"batl":[[2,9.2,8]],"ltp":0.0,"tv":0.0,"id":10170404}]}]}
{"op":"mcm","clk":"990477846","pt":1580497520968,"mc":[{"id":"1.168133548","rc":[{"batb":[[0,6,1.12],[1,5.9,5.91],[2,5.8,1.98]],"ltp":0.0,"tv":0.0,"id":8231803}]}]}
{"op":"mcm","clk":"990480707","pt":1580497541233,"mc":[{"id":"1.168133548","rc":[{"trd":[[5.6,3.41],[5.7,0.58]],"batb":[[0,5.6,2.8]],"ltp":5.6,"tv":53.98,"id":9417341}],"tv":64.01}]}
{"op":"mcm","clk":"990481667","pt":1580497548390,"mc":[{"id":"1.168133548","rc":[{"batb":[[1,5.9,2.52]],"ltp":0.0,"tv":0.0,"id":8231803}]}]}
{"op":"mcm","clk":"990483821","pt":1580497564068,"mc":[{"id":"1.168133548","rc":[{"batb":[[1,5.8,4.5],[2,5.7,3.03]],"ltp":0.0,"tv":0.0,"id":8231803}]}]}
{"op":"mcm","clk":"990488548","pt":1580497598517,"mc":[{"id":"1.168133548","rc":[{"batb":[[1,7.8,5.55],[2,7.4,3.18]],"ltp":0.0,"tv":0.0,"id":9001159}]}]}
{"op":"mcm","clk":"990488795","pt":1580497600445,"mc":[{"id":"1.168133548","rc":[{"batb":[[1,6.8,1.01],[2,5.6,3.4]],"ltp":0.0,"tv":0.0,"id":8429550}]}]}
{"op":"mcm","clk":"990488904","pt":1580497601158,"mc":[{"id":"1.168133548","rc":[{"batb":[[0,9,1.99],[1,8.8,6.77]],"ltp":0.0,"tv":0.0,"id":9193530}]}]}
{"op":"mcm","clk":"990491093","pt":1580497616504,"mc":[{"id":"1.168133548","rc":[{"batb":[[1,5.8,6.51]],"ltp":0.0,"tv":0.0,"id":8231803}]}]}
{"op":"mcm","clk":"990512622","pt":1580497700499,"mc":[{"id":"1.168133548","rc":[{"batb":[[1,5.9,3.03],[2,5.8,6.51]],"ltp":0.0,"tv":0.0,"id":8231803},{"batl":[[0,490,3.23],[1,500,9]],"ltp":0.0,"tv":0.0,"id":9001159}]}]}
{"op":"mcm","clk":"990512769","pt":1580497701513,"mc":[{"id":"1.168133548","rc":[{"batl":[[0,490,3.23],[1,500,9]],"ltp":0.0,"tv":0.0,"id":8231803},{"batb":[[0,8.6,5.36],[2,8.2,2.52]],"batl":[[0,490,3.23],[1,500,9]],"ltp":0.0,"tv":0.0,"id":15608820}]}]}
{"op":"mcm","clk":"990512902","pt":1580497702391,"mc":[{"id":"1.168133548","rc":[{"batb":[[2,5.7,3.91]],"batl":[[0,490,3.23],[1,500,9]],"ltp":0.0,"tv":0.0,"id":8429550},{"batb":[[0,9.2,3.03],[1,9,5.29],[2,8.8,1.98]],"ltp":9.0,"tv":4.0,"id":10616006},{"batl":[[1,520,0]],"ltp":0.0,"tv":0.0,"id":9193530}]}]}
{"op":"mcm","clk":"990512939","pt":1580497702596,"mc":[{"id":"1.168133548","rc":[{"batl":[[0,490,3.23],[1,500,9]],"ltp":0.0,"tv":0.0,"id":9193530}]}]}
{"op":"mcm","clk":"990515908","pt":1580497723753,"mc":[{"id":"1.168133548","rc":[{"batl":[[0,470,9],[1,490,3.23]],"ltp":0.0,"tv":0.0,"id":8429550},{"batl":[[0,470,9],[1,490,3.23]],"ltp":0.0,"tv":0.0,"id":8231803},{"batl":[[0,470,9],[1,490,3.23]],"ltp":0.0,"tv":0.0,"id":15608820},{"batl":[[0,470,9],[1,490,3.23]],"ltp":0.0,"tv":0.0,"id":9193530},{"batl":[[0,470,9],[1,490,3.23]],"ltp":0.0,"tv":0.0,"id":9001159}]}]}
{"op":"mcm","clk":"990516146","pt":1580497725395,"mc":[{"id":"1.168133548","rc":[{"batl":[[0,470,9.2],[1,490,3.03]],"ltp":0.0,"tv":0.0,"id":8429550},{"batl":[[0,470,9.2],[1,490,3.03]],"ltp":0.0,"tv":0.0,"id":8231803},{"batb":[[1,9,3.07]],"ltp":9.0,"tv":4.0,"id":10616006},{"batl":[[0,470,9.2],[1,490,3.03]],"ltp":0.0,"tv":0.0,"id":15608820},{"batl":[[0,470,9.2],[1,490,3.03]],"ltp":0.0,"tv":0.0,"id":9193530},{"batl":[[0,470,9.2],[1,490,3.03]],"ltp":0.0,"tv":0.0,"id":9001159}]}]}
{"op":"mcm","clk":"990518717","pt":1580497744226,"mc":[{"id":"1.168133548","rc":[{"batb":[[2,5.8,2.52]],"ltp":0.0,"tv":0.0,"id":8429550},{"batb":[[0,8.6,7.88]],"ltp":0.0,"tv":0.0,"id":15608820}]}]}
{"op":"mcm","clk":"990522150","pt":1580497767358,"mc":[{"id":"1.168133548","rc":[{"batb":[[0,6.8,1.01],[1,5.9,1.98]],"ltp":0.0,"tv":0.0,"id":8429550},{"batb":[[0,6,3.1],[2,5.8,4.53]],"ltp":0.0,"tv":0.0,"id":8231803},{"batb":[[0,9.4,1.98],[1,9.2,3.03],[2,9,3.07]],"ltp":9.0,"tv":4.0,"id":10616006},{"batb":[[0,8.8,1.98],[1,8.6,7.88],[2,8.2,3.12]],"ltp":0.0,"tv":0.0,"id":15608820},{"batb":[[0,9.2,1.98],[1,9,1.99],[2,8.8,4.79]],"ltp":0.0,"tv":0.0,"id":9193530}]}]}
{"op":"mcm","clk":"990524822","pt":1580497785439,"mc":[{"id":"1.168133548","rc":[{"batb":[[2,8.8,2.52]],"ltp":0.0,"tv":0.0,"id":9193530}]}]}
{"op":"mcm","clk":"990527597","pt":1580497803161,"mc":[{"id":"1.168133548","rc":[{"batb":[[0,6,5.62]],"ltp":0.0,"tv":0.0,"id":8231803}]}]}
{"op":"mcm","clk":"990535721","pt":1580497856960,"mc":[{"id":"1.168133548","rc":[{"batb":[[0,7.4,1.99],[1,6.8,1.01],[2,5.9,1.98]],"ltp":0.0,"tv":0.0,"id":8429550}]}]}
{"op":"mcm","clk":"990535913","pt":1580497858334,"mc":[{"id":"1.168133548","rc":[{"batb":[[0,9.4,1.99],[1,9.2,1.98]],"ltp":0.0,"tv":0.0,"id":9193530}]}]}
{"op":"mcm","clk":"990538888","pt":1580497878211,"mc":[{"id":"1.168133548","rc":[{"batl":[[1,7.2,2.4],[2,10,2.5]],"ltp":6.8,"tv":6.02,"id":17352128}]}]}
{"op":"mcm","clk":"990541206","pt":1580497892962,"mc":[{"id":"1.168133548","rc":[{"batl":[[0,8.2,2.5],[1,470,9.2],[2,490,3.03]],"ltp":0.0,"tv":0.0,"id":8231803}]}]}
{"op":"mcm","clk":"990546753","pt":1580497929518,"mc":[{"id":"1.168133548","rc":[{"batl":[[1,460,3.23],[2,470,9]],"ltp":0.0,"tv":0.0,"id":8231803},{"batl":[[0,460,3.23],[1,470,9]],"ltp":0.0,"tv":0.0,"id":15608820},{"batl":[[0,460,3.23],[1,470,9]],"ltp":0.0,"tv":0.0,"id":9001159}]}]}
{"op":"mcm","clk":"990546864","pt":1580497930221,"mc":[{"id":"1.168133548","rc":[{"batb":[[2,5.9,5.01]],"batl":[[0,460,3.23],[1,470,9]],"ltp":0.0,"tv":0.0,"id":8429550},{"batl":[[0,460,3.23],[1,470,9]],"ltp":0.0,"tv":0.0,"id":9193530}]}]}
{"op":"mcm","clk":"990555050","pt":1580497982751,"mc":[{"id":"1.168133548","rc":[{"batb":[[2,6,2.52]],"ltp":0.0,"tv":0.0,"id":8429550}]}]}
{"op":"mcm","clk":"990556720","pt":1580497993879,"mc":[{"id":"1.168133548","rc":[{"batb":[[2,6.2,3.03]],"ltp":0.0,"tv":0.0,"id":8429550}]}]}
{"op":"mcm","clk":"990562074","pt":1580498029472,"mc":[{"id":"1.168133548","rc":[{"batl":[[0,440,9.2],[1,460,3.03]],"ltp":0.0,"tv":0.0,"id":8429550},{"batl":[[1,30,9],[2,460,3.23]],"ltp":0.0,"tv":0.0,"id":8231803},{"batl":[[0,440,9.2],[1,460,3.03]],"ltp":0.0,"tv":0.0,"id":15608820},{"batl":[[0,440,9.2],[1,460,3.03]],"ltp":0.0,"tv":0.0,"id":9193530},{"batl":[[0,440,9.2],[1,460,3.03]],"ltp":0.0,"tv":0.0,"id":9001159}]}]}
{"op":"mcm","clk":"990562321","pt":1580498031154,"mc":[{"id":"1.168133548","rc":[{"batl":[[0,8.6,10],[1,8.8,3.03],[2,9,5]],"ltp":0.0,"tv":0.0,"id":10170404}]}]}
{"op":"mcm","clk":"990563958","pt":1580498042463,"mc":[{"id":"1.168133548","rc":[{"batb":[[2,6.4,2.52]],"ltp":0.0,"tv":0.0,"id":8429550}]}]}
{"op":"mcm","clk":"990565396","pt":1580498051778,"mc":[{"id":"1.168133548","rc":[{"batl":[[1,30,9.17]],"ltp":0.0,"tv":0.0,"id":8231803}]}]}
{"op":"mcm","clk":"990566104","pt":1580498056476,"mc":[{"id":"1.168133548","rc":[{"batl":[[1,29,3.2],[2,30,9]],"ltp":0.0,"tv":0.0,"id":8231803},{"batl":[[0,430,3.23],[1,440,9]],"ltp":0.0,"tv":0.0,"id":9001159}]}]}
{"op":"mcm","clk":"990566264","pt":1580498057472,"mc":[{"id":"1.168133548","rc":[{"batb":[[2,6.6,3.03]],"batl":[[0,430,3.23],[1,440,9]],"ltp":0.0,"tv":0.0,"id":8429550},{"batl":[[1,9,5],[2,9.2,8]],"ltp":0.0,"tv":0.0,"id":10170404},{"batl":[[0,430,3.23],[1,440,9]],"ltp":0.0,"tv":0.0,"id":15608820}]}]}
{"op":"mcm","clk":"990566391","pt":1580498058203,"mc":[{"id":"1.168133548","rc":[{"batl":[[0,8.4,3.03],[1,8.6,10],[2,9,5]],"ltp":0.0,"tv":0.0,"id":10170404},{"batl":[[0,430,3.23],[1,440,9]],"ltp":0.0,"tv":0.0,"id":9193530}]}]}
{"op":"mcm","clk":"990572662","pt":1580498100315,"mc":[{"id":"1.168133548","rc":[{"batl":[[0,16.5,5.2],[1,17,3.32]],"ltp":9.0,"tv":4.0,"id":10616006}]}]}
{"op":"mcm","clk":"990572805","pt":1580498101223,"mc":[{"id":"1.168133548","rc":[{"batb":[[0,7.6,1.98],[1,7.4,1.99],[2,6.8,1.01]],"ltp":0.0,"tv":0.0,"id":8429550},{"batb":[[0,9.6,1.98],[1,9.4,1.99]],"ltp":0.0,"tv":0.0,"id":9193530}]}]}
{"op":"mcm","clk":"990573016","pt":1580498102692,"mc":[{"id":"1.168133548","rc":[{"batb":[[2,6.8,3.53]],"ltp":0.0,"tv":0.0,"id":8429550}]}]}
{"op":"mcm","clk":"990574012","pt":1580498108929,"mc":[{"id":"1.168133548","rc":[{"batb":[[0,7.8,1.99],[1,7.6,1.98]],"ltp":0.0,"tv":0.0,"id":8429550}]}]}
{"op":"mcm","clk":"990574177","pt":1580498109929,"mc":[{"id":"1.168133548","rc":[{"batb":[[1,8.8,2.52],[2,8.2,3.13]],"ltp":0.0,"tv":0.0,"id":9193530}]}]}
{"op":"mcm","clk":"990574730","pt":1580498113195,"mc":[{"id":"1.168133548","rc":[{"batb":[[0,8,1.98],[1,7.8,1.99]],"ltp":0.0,"tv":0.0,"id":8429550},{"batb":[[0,9,1.98]],"ltp":0.0,"tv":0.0,"id":9193530}]}]}
{"op":"mcm","clk":"990574949","pt":1580498114508,"mc":[{"id":"1.168133548","rc":[{"batb":[[0,5.6,3.37]],"ltp":5.6,"tv":53.98,"id":9417341},{"batb":[[0,6.2,1.37],[1,6,4.78],[2,5.9,3.03]],"ltp":0.0,"tv":0.0,"id":8231803},{"batb":[[0,9.6,7.09]],"ltp":0.0,"tv":0.0,"id":9001159}]}]}
{"op":"mcm","clk":"990575021","pt":1580498114941,"mc":[{"id":"1.168133548","rc":[{"batb":[[1,7.8,2.41]],"ltp":0.0,"tv":0.0,"id":8429550},{"batb":[[0,9.4,2.51]],"ltp":9.0,"tv":4.0,"id":10616006},{"batb":[[0,7.4,4.62]],"ltp":0.0,"tv":0.0,"id":10170404},{"batb":[[0,8.8,2.54]],"ltp":0.0,"tv":0.0,"id":15608820},{"batb":[[0,9,2.53]],"ltp":0.0,"tv":0.0,"id":9193530},{"batb":[[0,6.2,4.95]],"ltp":6.8,"tv":6.02,"id":17352128}]}]}
{"op":"mcm","clk":"990577824","pt":1580498132446,"mc":[{"id":"1.168133548","rc":[{"batl":[[1,6.2,38.8]],"ltp":5.6,"tv":53.98,"id":9417341}]}]}
{"op":"mcm","clk":"990578187","pt":1580498134545,"mc":[{"id":"1.168133548","rc":[{"batl":[[0,410,9],[1,430,3.23]],"ltp":0.0,"tv":0.0,"id":8429550},{"batb":[[1,8.6,5.55]],"batl":[[0,410,9],[1,430,3.23]],"ltp":0.0,"tv":0.0,"id":15608820},{"batl":[[0,410,9],[1,430,3.23]],"ltp":0.0,"tv":0.0,"id":9193530},{"batl":[[0,410,9],[1,430,3.23]],"ltp":0.0,"tv":0.0,"id":9001159}]}]}
{"op":"mcm","clk":"990582805","pt":1580498163138,"mc":[{"id":"1.168133548","rc":[{"batb":[[1,8.2,3.13],[2,8,3.03]],"ltp":0.0,"tv":0.0,"id":9193530}]}]}
{"op":"mcm","clk":"990584674","pt":1580498175263,"mc":[{"id":"1.168133548","rc":[{"batb":[[0,8.4,2.53]],"ltp":0.0,"tv":0.0,"id":9193530}]}]}
{"op":"mcm","clk":"990587872","pt":1580498195523,"mc":[{"id":"1.168133548","rc":[{"trd":[[8.6,11.1],[8.8,5.08]],"batb":[[0,8.2,3.12],[1,7.6,2.52],[2,7.2,2.52]],"batl":[[0,8.6,41.91],[1,410,9],[2,430,3.23]],"ltp":8.6,"tv":16.18,"id":15608820}],"tv":80.19}]}
{"op":"mcm","clk":"990587985","pt":1580498196218,"mc":[{"id":"1.168133548","rc":[{"batb":[[2,7.4,3]],"ltp":8.6,"tv":16.18,"id":15608820}]}]}
{"op":"mcm","clk":"990588911","pt":1580498202101,"mc":[{"id":"1.168133548","rc":[{"batl":[[2,430,3.03]],"ltp":8.6,"tv":16.18,"id":15608820}]}]}
{"op":"mcm","clk":"990592124","pt":1580498223194,"mc":[{"id":"1.168133548","rc":[{"batb":[[0,7.6,3.12],[1,7.4,3],[2,7.2,2.52]],"ltp":8.6,"tv":16.18,"id":15608820}]}]}
{"op":"mcm","clk":"990596016","pt":1580498249452,"mc":[{"id":"1.168133548","rc":[{"batb":[[1,7.4,6.03]],"batl":[[2,430,0.06]],"ltp":8.6,"tv":16.18,"id":15608820},{"batl":[[0,400,3.03],[1,410,9],[2,430,0.2]],"ltp":0.0,"tv":0.0,"id":9001159}]}]}
{"op":"mcm","clk":"990596161","pt":1580498250457,"mc":[{"id":"1.168133548","rc":[{"batb":[[0,7,2.63],[1,6.8,3.3],[2,6.6,3.03]],"batl":[[0,400,3.03],[1,410,9],[2,430,0.2]],"ltp":0.0,"tv":0.0,"id":8429550},{"batl":[[0,16,3.03],[1,16.5,5.2],[2,36,9.29]],"ltp":9.0,"tv":4.0,"id":10616006},{"batb":[[0,7.4,2.63]],"ltp":0.0,"tv":0.0,"id":10170404},{"batl":[[0,400,3.03],[1,410,9],[2,430,0.2]],"ltp":0.0,"tv":0.0,"id":9193530}]}]}
{"op":"mcm","clk":"990596284","pt":1580498251337,"mc":[{"id":"1.168133548","rc":[{"batb":[[0,9.2,1.99],[1,8.4,2.53],[2,8.2,3.13]],"ltp":0.0,"tv":0.0,"id":9193530}]}]}
{"op":"mcm","clk":"990597005","pt":1580498256493,"mc":[{"id":"1.168133548","rc":[{"batb":[[1,7.4,3]],"batl":[[2,430,0]],"ltp":8.6,"tv":16.18,"id":15608820}]}]}
{"op":"mcm","clk":"990597125","pt":1580498257358,"mc":[{"id":"1.168133548","rc":[{"batb":[[0,7,5.66],[2,6.4,2.52]],"ltp":0.0,"tv":0.0,"id":8429550},{"trd":[[8.6,14.2]],"batb":[[0,7.8,3.63],[1,7.6,2.52],[2,7.4,3]],"batl":[[0,8.6,40.36]],"ltp":8.6,"tv":19.28,"id":15608820}],"tv":83.29}]}
{"op":"mcm","clk":"990597179","pt":1580498257794,"mc":[{"id":"1.168133548","rc":[{"batb":[[1,7,3.03],[2,6.8,3.3]],"ltp":0.0,"tv":0.0,"id":10170404}]}]}
{"op":"mcm","clk":"990597831","pt":1580498262517,"mc":[{"id":"1.168133548","rc":[{"batb":[[0,7.2,2.63]],"ltp":0.0,"tv":0.0,"id":10170404},{"batb":[[0,9.4,1.98],[1,9.2,1.99],[2,8.2,3.68]],"ltp":0.0,"tv":0.0,"id":9193530}]}]}
{"op":"mcm","clk":"990599171","pt":1580498271904,"mc":[{"id":"1.168133548","rc":[{"trd":[[8.4,1.2]],"batb":[[0,7.6,5.55],[1,7.4,3],[2,7.2,2.52]],"batl":[[0,8.4,4.09],[1,8.6,40.36],[2,410,9]],"ltp":8.4,"tv":20.48,"id":15608820}],"tv":84.49}]}
{"op":"mcm","clk":"990601127","pt":1580498285548,"mc":[{"id":"1.168133548","rc":[{"batl":[[0,400,3.23],[2,430,0]],"ltp":0.0,"tv":0.0,"id":8429550},{"batl":[[0,400,3.23],[2,430,0]],"ltp":0.0,"tv":0.0,"id":9193530},{"batl":[[0,400,3.23],[2,430,0]],"ltp":0.0,"tv":0.0,"id":9001159}]}]}
{"op":"mcm","clk":"990601256","pt":1580498286352,"mc":[{"id":"1.168133548","rc":[{"batl":[[0,380,9],[1,400,3.23]],"ltp":0.0,"tv":0.0,"id":8429550},{"batl":[[2,26,9]],"ltp":8.4,"tv":20.48,"id":15608820},{"batl":[[0,380,9],[1,400,3.23]],"ltp":0.0,"tv":0.0,"id":9193530},{"batl":[[0,380,9],[1,400,3.23]],"ltp":0.0,"tv":0.0,"id":9001159}]}]}
{"op":"mcm","clk":"990603789","pt":1580498305511,"mc":[{"id":"1.168133548","rc":[{"batl":[[0,380,9.2],[1,400,3.03]],"ltp":0.0,"tv":0.0,"id":8429550},{"batl":[[0,380,9.2],[1,400,3.03]],"ltp":0.0,"tv":0.0,"id":9193530},{"batl":[[0,380,9.2],[1,400,3.03]],"ltp":0.0,"tv":0.0,"id":9001159}]}]}
{"op":"mcm","clk":"990612990","pt":1580498374025,"mc":[{"id":"1.168133548","rc":[{"batb":[[0,7.8,1.99],[1,7.6,5.55],[2,7.4,3]],"ltp":8.4,"tv":20.48,"id":15608820}]}]}
{"op":"mcm","clk":"990613075","pt":1580498374935,"mc":[{"id":"1.168133548","rc":[{"batb":[[0,8,1.99],[1,7,5.66],[2,6.8,3.3]],"ltp":0.0,"tv":0.0,"id":8429550}]}]}
{"op":"mcm","clk":"990613277","pt":1580498376721,"mc":[{"id":"1.168133548","rc":[{"batb":[[1,8.2,3.68],[2,8,3.03]],"ltp":0.0,"tv":0.0,"id":9193530}]}]}
{"op":"mcm","clk":"990614590","pt":1580498387529,"mc":[{"id":"1.168133548","rc":[{"batb":[[1,7,3.68]],"ltp":0.0,"tv":0.0,"id":8429550},{"trd":[[7.6,1.3]],"batb":[[0,7.2,1.98]],"batl":[[0,7.6,3.35],[1,8.4,3.03],[2,8.6,10]],"ltp":7.6,"tv":1.29,"id":10170404},{"batb":[[0,8.2,3.68],[1,8,3.03],[2,7.8,2.52]],"ltp":0.0,"tv":0.0,"id":9193530}],"tv":85.79}]}
{"op":"mcm","clk":"990614602","pt":1580498387636,"mc":[{"id":"1.168133548","rc":[{"batb":[[0,8.2,1.98],[1,8,1.99],[2,7,3.68]],"ltp":0.0,"tv":0.0,"id":8429550},{"batb":[[0,8.4,2.53],[1,8.2,3.13],[2,8,3.03]],"ltp":0.0,"tv":0.0,"id":9193530}]}]}
{"op":"mcm","clk":"990616377","pt":1580498402172,"mc":[{"id":"1.168133548","rc":[{"batb":[[2,7.2,3.17]],"ltp":0.0,"tv":0.0,"id":8429550}]}]}
{"op":"mcm","clk":"990617644","pt":1580498412118,"mc":[{"id":"1.168133548","rc":[{"batb":[[0,9.6,2.08],[1,9.4,2.51],[2,9.2,3.03]],"ltp":9.0,"tv":4.0,"id":10616006}]}]}
{"op":"mcm","clk":"990622618","pt":1580498448915,"mc":[{"id":"1.168133548","rc":[{"batb":[[0,9.8,1.98],[1,9.6,2.08],[2,9.2,3.56]],"ltp":9.0,"tv":4.0,"id":10616006}]}]}
{"op":"mcm","clk":"990624511","pt":1580498462134,"mc":[{"id":"1.168133548","rc":[{"batb":[[2,9.4,3.04]],"ltp":9.0,"tv":4.0,"id":10616006}]}]}
{"op":"mcm","clk":"990626510","pt":1580498476868,"mc":[{"id":"1.168133548","rc":[{"batl":[[2,10,4.5]],"ltp":6.8,"tv":6.02,"id":17352128}]}]}
{"op":"mcm","clk":"990627897","pt":1580498487691,"mc":[{"id":"1.168133548","rc":[{"batl":[[2,7.4,1.25]],"ltp":6.8,"tv":6.02,"id":17352128}]}]}
{"op":"mcm","clk":"990630689","pt":1580498508453,"mc":[{"id":"1.168133548","rc":[{"batl":[[1,400,0]],"ltp":0.0,"tv":0.0,"id":8429550},{"batb":[[1,7.6,2.52]],"ltp":8.4,"tv":20.48,"id":15608820},{"batl":[[0,370,3.23],[1,380,9]],"ltp":0.0,"tv":0.0,"id":9001159}]}]}
{"op":"mcm","clk":"990630827","pt":1580498509533,"mc":[{"id":"1.168133548","rc":[{"batl":[[0,370,3.23],[1,380,9]],"ltp":0.0,"tv":0.0,"id":8429550},{"batb":[[0,9.8,5.01]],"ltp":9.0,"tv":4.0,"id":10616006},{"batb":[[1,6.8,3.3],[2,6.4,5.52]],"batl":[[1,8.6,10],[2,9,5]],"ltp":7.6,"tv":1.29,"id":10170404},{"batl":[[0,370,3.23],[1,380,9]],"ltp":0.0,"tv":0.0,"id":9193530}]}]}
{"op":"mcm","clk":"990630969","pt":1580498510563,"mc":[{"id":"1.168133548","rc":[{"batb":[[1,7.2,3.17],[2,7,3.03]],"ltp":0.0,"tv":0.0,"id":8429550}]}]}
{"op":"mcm","clk":"990630985","pt":1580498510625,"mc":[{"id":"1.168133548","rc":[{"batb":[[0,7.4,1.99],[1,7.2,1.98],[2,6.8,3.3]],"ltp":7.6,"tv":1.29,"id":10170404}]}]}
{"op":"mcm","clk":"990631204","pt":1580498512238,"mc":[{"id":"1.168133548","rc":[{"batb":[[0,9.2,1.99],[1,8.4,2.53],[2,8.2,3.13]],"ltp":0.0,"tv":0.0,"id":9193530}]}]}
{"op":"mcm","clk":"990632608","pt":1580498522551,"mc":[{"id":"1.168133548","rc":[{"batb":[[0,9.8,7.53]],"ltp":9.0,"tv":4.0,"id":10616006}]}]}
{"op":"mcm","clk":"990632671","pt":1580498523080,"mc":[{"id":"1.168133548","rc":[{"batb":[[1,9.4,3.04],[2,9,3.07]],"ltp":9.0,"tv":4.0,"id":10616006}]}]}
{"op":"mcm","clk":"990633562","pt":1580498529157,"mc":[{"id":"1.168133548","rc":[{"batb":[[0,5.6,103.37]],"ltp":5.6,"tv":53.98,"id":9417341}]}]}
{"op":"mcm","clk":"990635668","pt":1580498542568,"mc":[{"id":"1.168133548","rc":[{"batb":[[0,7.2,3.17],[1,7,3.03],[2,6.8,3.3]],"batl":[[0,350,9],[1,370,3.23]],"ltp":0.0,"tv":0.0,"id":8429550},{"batb":[[1,6.8,3.3],[2,6.4,5.52]],"ltp":7.6,"tv":1.29,"id":10170404},{"batb":[[1,8.2,3.68],[2,8,3.03]],"batl":[[0,350,9],[1,370,3.23]],"ltp":0.0,"tv":0.0,"id":9193530},{"batl":[[0,350,9],[1,370,3.23]],"ltp":0.0,"tv":0.0,"id":9001159}]}]}
{"op":"mcm","clk":"990635683","pt":1580498542674,"mc":[{"id":"1.168133548","rc":[{"batb":[[0,7.4,2.4],[1,7.2,2.75],[2,7,3.03]],"ltp":0.0,"tv":0.0,"id":8429550},{"batb":[[0,7.4,3.97]],"ltp":7.6,"tv":1.29,"id":10170404},{"batb":[[0,9.4,1.98],[1,9.2,1.99],[2,8.2,3.68]],"ltp":0.0,"tv":0.0,"id":9193530}]}]}
{"op":"mcm","clk":"990652748","pt":1580498592569,"mc":[{"id":"1.168133548","rc":[{"batl":[[1,370,3.03]],"ltp":0.0,"tv":0.0,"id":8429550},{"batl":[[1,370,3.03]],"ltp":0.0,"tv":0.0,"id":9193530},{"batl":[[1,370,3.03]],"ltp":0.0,"tv":0.0,"id":9001159}]}]}
{"op":"mcm","clk":"990652790","pt":1580498592841,"mc":[{"id":"1.168133548","rc":[{"batl":[[0,350,9.2]],"ltp":0.0,"tv":0.0,"id":8429550},{"batl":[[0,350,9.2]],"ltp":0.0,"tv":0.0,"id":9193530},{"batl":[[0,350,9.2]],"ltp":0.0,"tv":0.0,"id":9001159}]}]}
{"op":"mcm","clk":"990653108","pt":1580498595046,"mc":[{"id":"1.168133548","rc":[{"trd":[[8.4,9.39]],"batb":[[0,7.8,2.89]],"batl":[[0,8.6,40.36],[1,26,9],[2,26,0]],"ltp":8.4,"tv":28.67,"id":15608820}],"tv":93.98}]}
{"op":"mcm","clk":"990653632","pt":1580498598251,"mc":[{"id":"1.168133548","rc":[{"trd":[[7.4,7.94]],"batb":[[0,6.8,3.3],[1,6.4,5.52],[2,6,3.35]],"ltp":7.4,"tv":9.24,"id":10170404}],"tv":101.93}]}
{"op":"mcm","clk":"990653691","pt":1580498598678,"mc":[{"id":"1.168133548","rc":[{"batb":[[0,7.8,1.99]],"ltp":8.4,"tv":28.67,"id":15608820}]}]}
{"op":"mcm","clk":"990654440","pt":1580498603554,"mc":[{"id":"1.168133548","rc":[{"batl":[[0,8.4,3.03],[1,8.6,40.36],[2,26,9]],"ltp":8.4,"tv":28.67,"id":15608820},{"batl":[[0,340,3.23],[1,350,9]],"ltp":0.0,"tv":0.0,"id":9001159}]}]}
{"op":"mcm","clk":"990654563","pt":1580498604464,"mc":[{"id":"1.168133548","rc":[{"batl":[[0,340,3.23],[1,350,9]],"ltp":0.0,"tv":0.0,"id":8429550},{"batb":[[2,7.4,5.51]],"ltp":8.4,"tv":28.67,"id":15608820}]}]}
{"op":"mcm","clk":"990654605","pt":1580498604783,"mc":[{"id":"1.168133548","rc":[{"batl":[[0,340,3.23],[1,350,9]],"ltp":0.0,"tv":0.0,"id":9193530}]}]}
{"op":"mcm","clk":"990656071","pt":1580498613989,"mc":[{"id":"1.168133548","rc":[{"trd":[[8.4,15.45],[8.6,18.56]],"batl":[[0,8.6,38.18],[1,26,9],[2,26,0]],"ltp":8.6,"tv":39.09,"id":15608820}],"tv":112.35}]}
{"op":"mcm","clk":"990656887","pt":1580498619425,"mc":[{"id":"1.168133548","rc":[{"trd":[[8.6,27.74]],"batb":[[0,7.8,5.02],[2,7.4,3]],"batl":[[0,8.6,33.59]],"ltp":8.6,"tv":48.27,"id":15608820}],"tv":121.52}]}
{"op":"mcm","clk":"990656928","pt":1580498619745,"mc":[{"id":"1.168133548","rc":[{"batb":[[0,7.8,5.77]],"ltp":8.6,"tv":48.27,"id":15608820}]}]}
{"op":"mcm","clk":"990658922","pt":1580498633959,"mc":[{"id":"1.168133548","rc":[{"batb":[[0,7.8,1.99]],"ltp":8.6,"tv":48.27,"id":15608820}]}]}
{"op":"mcm","clk":"990659935","pt":1580498640958,"mc":[{"id":"1.168133548","rc":[{"batb":[[0,8,1.99],[1,7.4,2.4],[2,7.2,2.75]],"ltp":0.0,"tv":0.0,"id":8429550}]}]}
{"op":"mcm","clk":"990660100","pt":1580498642082,"mc":[{"id":"1.168133548","rc":[{"batb":[[0,6.4,6.3],[1,6,3.35],[2,5.8,2.52]],"ltp":7.4,"tv":9.24,"id":10170404},{"batb":[[1,8.2,3.68],[2,8,3.03]],"ltp":0.0,"tv":0.0,"id":9193530}]}]}
{"op":"mcm","clk":"990661234","pt":1580498649559,"mc":[{"id":"1.168133548","rc":[{"trd":[[8.6,33.65]],"batl":[[0,8.6,30.63]],"ltp":8.6,"tv":54.18,"id":15608820}],"tv":127.44}]}
{"op":"mcm","clk":"990661371","pt":1580498650485,"mc":[{"id":"1.168133548","rc":[{"batl":[[1,8.4,3.03],[2,8.6,10]],"ltp":7.4,"tv":9.24,"id":10170404},{"batl":[[0,8.4,1.67],[1,8.6,30.63],[2,26,9]],"ltp":8.6,"tv":54.18,"id":15608820}]}]}
{"op":"mcm","clk":"990661390","pt":1580498650580,"mc":[{"id":"1.168133548","rc":[{"batb":[[2,5.9,2.41]],"ltp":7.4,"tv":9.24,"id":10170404}]}]}
{"op":"mcm","clk":"990663740","pt":1580498666495,"mc":[{"id":"1.168133548","rc":[{"batb":[[2,5.8,2.52]],"ltp":7.4,"tv":9.24,"id":10170404},{"batl":[[0,8.6,30.63],[1,9,4.38]],"ltp":8.6,"tv":54.18,"id":15608820}]}]}
{"op":"mcm","clk":"990663757","pt":1580498666604,"mc":[{"id":"1.168133548","rc":[{"batb":[[0,6.6,3.81],[1,6.4,5.52],[2,6,3.35]],"ltp":7.4,"tv":9.24,"id":10170404}]}]}
{"op":"mcm","clk":"990666495","pt":1580498684719,"mc":[{"id":"1.168133548","rc":[{"batb":[[0,8.2,1.98],[1,8,1.99],[2,7.2,3.17]],"ltp":0.0,"tv":0.0,"id":8429550},{"batb":[[0,8.4,2.53],[1,8.2,3.13]],"ltp":0.0,"tv":0.0,"id":9193530}]}]}
{"op":"mcm","clk":"990668272","pt":1580498696558,"mc":[{"id":"1.168133548","rc":[{"batl":[[0,320,9],[1,340,3.23]],"ltp":0.0,"tv":0.0,"id":8429550},{"batl":[[0,320,9],[1,340,3.23]],"ltp":0.0,"tv":0.0,"id":9193530},{"batl":[[0,320,9],[1,340,3.23]],"ltp":0.0,"tv":0.0,"id":9001159}]}]}
{"op":"mcm","clk":"990669211","pt":1580498702466,"mc":[{"id":"1.168133548","rc":[{"batl":[[0,320,9.2],[1,340,3.03]],"ltp":0.0,"tv":0.0,"id":8429550},{"batl":[[0,320,9.2],[1,340,3.03]],"ltp":0.0,"tv":0.0,"id":9193530},{"batl":[[0,320,9.2],[1,340,3.03]],"ltp":0.0,"tv":0.0,"id":9001159}]}]}
{"op":"mcm","clk":"990673065","pt":1580498727438,"mc":[{"id":"1.168133548","rc":[{"batl":[[0,310,3.23],[1,320,9]],"ltp":0.0,"tv":0.0,"id":9001159}]}]}
{"op":"mcm","clk":"990673174","pt":1580498728121,"mc":[{"id":"1.168133548","rc":[{"batl":[[0,310,3.23],[1,320,9]],"ltp":0.0,"tv":0.0,"id":8429550},{"batl":[[0,310,3.23],[1,320,9]],"ltp":0.0,"tv":0.0,"id":9193530}]}]}
{"op":"mcm","clk":"990680035","pt":1580498771405,"mc":[{"id":"1.168133548","rc":[{"batb":[[1,7.2,3.17],[2,7,3.03]],"ltp":0.0,"tv":0.0,"id":8429550}]}]}
{"op":"mcm","clk":"990680135","pt":1580498771906,"mc":[{"id":"1.168133548","rc":[{"batb":[[0,9.2,1.99],[1,8.4,2.53],[2,8.2,3.13]],"ltp":0.0,"tv":0.0,"id":9193530}]}]}
{"op":"mcm","clk":"990681002","pt":1580498777386,"mc":[{"id":"1.168133548","rc":[{"batb":[[0,7.4,2.4],[1,7.2,2.75]],"ltp":0.0,"tv":0.0,"id":8429550},{"batb":[[0,9.4,1.98],[1,9.2,1.99],[2,8.2,3.68]],"ltp":0.0,"tv":0.0,"id":9193530}]}]}
{"op":"mcm","clk":"990686473","pt":1580498812952,"mc":[{"id":"1.168133548","rc":[{"batl":[[0,25,1.25],[1,310,3.23],[2,320,9]],"ltp":0.0,"tv":0.0,"id":8429550}]}]}
{"op":"mcm","clk":"990687315","pt":1580498818787,"mc":[{"id":"1.168133548","rc":[{"batl":[[0,25,1.45],[1,310,3.03]],"ltp":0.0,"tv":0.0,"id":8429550}]}]}
{"op":"mcm","clk":"990690517","pt":1580498840331,"mc":[{"id":"1.168133548","rc":[{"batl":[[2,18.5,1.25]],"ltp":8.6,"tv":54.18,"id":15608820}]}]}
{"op":"mcm","clk":"990692334","pt":1580498851429,"mc":[{"id":"1.168133548","rc":[{"batl":[[1,290,9],[2,310,3.03]],"ltp":0.0,"tv":0.0,"id":8429550},{"batl":[[2,19.5,1.54]],"ltp":9.0,"tv":4.0,"id":10616006},{"batl":[[0,290,9],[1,310,3.23]],"ltp":0.0,"tv":0.0,"id":9193530},{"batl":[[0,290,9],[1,310,3.23]],"ltp":0.0,"tv":0.0,"id":9001159}]}]}
{"op":"mcm","clk":"990692687","pt":1580498853528,"mc":[{"id":"1.168133548","rc":[{"batl":[[0,290,9.2],[1,310,3.03]],"ltp":0.0,"tv":0.0,"id":9193530},{"batl":[[0,290,9.2],[1,310,3.03]],"ltp":0.0,"tv":0.0,"id":9001159}]}]}
{"op":"mcm","clk":"990693633","pt":1580498859248,"mc":[{"id":"1.168133548","rc":[{"trd":[[8.6,42.95]],"batl":[[0,8.6,25.98]],"ltp":8.6,"tv":63.48,"id":15608820}],"tv":136.74}]}
{"op":"mcm","clk":"990697518","pt":1580498884381,"mc":[{"id":"1.168133548","rc":[{"trd":[[7.2,4]],"ltp":7.2,"tv":4.0,"id":8231803}],"tv":140.74}]}
{"op":"mcm","clk":"990698183","pt":1580498888974,"mc":[{"id":"1.168133548","rc":[{"batb":[[0,6.2,4.37]],"ltp":7.2,"tv":4.0,"id":8231803}]}]}
{"op":"mcm","clk":"990699745","pt":1580498899513,"mc":[{"id":"1.168133548","rc":[{"batl":[[1,310,0]],"ltp":0.0,"tv":0.0,"id":9001159}]}]}
{"op":"mcm","clk":"990699906","pt":1580498900498,"mc":[{"id":"1.168133548","rc":[{"batl":[[1,280,3.03],[2,290,9]],"ltp":0.0,"tv":0.0,"id":8429550},{"batl":[[0,280,3.23],[1,290,9]],"ltp":0.0,"tv":0.0,"id":9193530},{"batl":[[0,280,3.23],[1,290,9]],"ltp":0.0,"tv":0.0,"id":9001159}]}]}
{"op":"mcm","clk":"990700300","pt":1580498902989,"mc":[{"id":"1.168133548","rc":[{"batb":[[0,6.4,3.84],[1,6,5.31]],"ltp":7.2,"tv":4.0,"id":8231803}]}]}
{"op":"mcm","clk":"990701431","pt":1580498910351,"mc":[{"id":"1.168133548","rc":[{"batb":[[0,8,1.99],[1,7.4,2.4],[2,7.2,2.75]],"ltp":0.0,"tv":0.0,"id":8429550}]}]}
{"op":"mcm","clk":"990701607","pt":1580498911547,"mc":[{"id":"1.168133548","rc":[{"batb":[[1,8.2,3.68],[2,8,3.03]],"ltp":0.0,"tv":0.0,"id":9193530}]}]}
{"op":"mcm","clk":"990710448","pt":1580498968463,"mc":[{"id":"1.168133548","rc":[{"batb":[[0,8.2,1.98],[1,8,1.99],[2,7.2,3.17]],"ltp":0.0,"tv":0.0,"id":8429550},{"batb":[[0,6.6,1.98],[1,6.4,3.84],[2,6,3.32]],"ltp":7.2,"tv":4.0,"id":8231803},{"batb":[[0,8.4,2.53],[1,8.2,3.13]],"ltp":0.0,"tv":0.0,"id":9193530}]}]}
{"op":"mcm","clk":"990715483","pt":1580499002477,"mc":[{"id":"1.168133548","rc":[{"batb":[[1,6.4,6.36]],"ltp":7.2,"tv":4.0,"id":8231803}]}]}
{"op":"mcm","clk":"990716426","pt":1580499008122,"mc":[{"id":"1.168133548","rc":[{"batl":[[1,260,9],[2,280,3.03]],"ltp":0.0,"tv":0.0,"id":8429550},{"batl":[[0,260,9],[1,280,3.23]],"ltp":0.0,"tv":0.0,"id":9193530},{"batl":[[0,260,9],[1,280,3.23]],"ltp":0.0,"tv":0.0,"id":9001159}]}]}
{"op":"mcm","clk":"990716772","pt":1580499010399,"mc":[{"id":"1.168133548","rc":[{"batl":[[0,260,9.2],[1,280,3.03]],"ltp":0.0,"tv":0.0,"id":9193530},{"batl":[[0,260,9.2],[1,280,3.03]],"ltp":0.0,"tv":0.0,"id":9001159}]}]}
{"op":"mcm","clk":"990721036","pt":1580499039122,"mc":[{"id":"1.168133548","rc":[{"trd":[[8.6,70.93]],"batl":[[0,8.6,11.99]],"ltp":8.6,"tv":91.46,"id":15608820}],"tv":168.72}]}
{"op":"mcm","clk":"990721617","pt":1580499043415,"mc":[{"id":"1.168133548","rc":[{"batb":[[1,7.2,3.17],[2,7,3.03]],"ltp":0.0,"tv":0.0,"id":8429550}]}]}
{"op":"mcm","clk":"990721798","pt":1580499044531,"mc":[{"id":"1.168133548","rc":[{"batb":[[0,9.2,1.99],[1,8.4,2.53],[2,8.2,3.13]],"ltp":0.0,"tv":0.0,"id":9193530}]}]}
{"op":"mcm","clk":"990723911","pt":1580499058528,"mc":[{"id":"1.168133548","rc":[{"batb":[[0,7.2,3.17],[1,7,3.03],[2,6.8,3.3]],"ltp":0.0,"tv":0.0,"id":8429550},{"batb":[[1,8.2,3.68],[2,8,3.03]],"ltp":0.0,"tv":0.0,"id":9193530}]}]}
{"op":"mcm","clk":"990723937","pt":1580499058636,"mc":[{"id":"1.168133548","rc":[{"batb":[[0,7.4,2.4],[1,7.2,2.75],[2,7,3.03]],"ltp":0.0,"tv":0.0,"id":8429550},{"batb":[[0,9.4,1.98],[1,9.2,1.99],[2,8.2,3.68]],"ltp":0.0,"tv":0.0,"id":9193530}]}]}
{"op":"mcm","clk":"990724524","pt":1580499062422,"mc":[{"id":"1.168133548","rc":[{"batl":[[1,250,3.03],[2,260,9]],"ltp":0.0,"tv":0.0,"id":8429550},{"batl":[[1,280,0]],"ltp":0.0,"tv":0.0,"id":9193530},{"batl":[[0,250,3.23],[1,260,9]],"ltp":0.0,"tv":0.0,"id":9001159}]}]}
{"op":"mcm","clk":"990724587","pt":1580499062845,"mc":[{"id":"1.168133548","rc":[{"batl":[[0,250,3.23],[1,260,9]],"ltp":0.0,"tv":0.0,"id":9193530}]}]}
{"op":"mcm","clk":"990732138","pt":1580499113213,"mc":[{"id":"1.168133548","rc":[{"batl":[[1,230,9],[2,250,3.03]],"ltp":0.0,"tv":0.0,"id":8429550},{"batl":[[0,230,9],[1,250,3.23]],"ltp":0.0,"tv":0.0,"id":9193530},{"batl":[[0,230,9],[1,250,3.23]],"ltp":0.0,"tv":0.0,"id":9001159}]}]}
{"op":"mcm","clk":"990733262","pt":1580499120223,"mc":[{"id":"1.168133548","rc":[{"batl":[[0,230,9.2],[1,250,3.03]],"ltp":0.0,"tv":0.0,"id":9193530},{"batl":[[0,230,9.2],[1,250,3.03]],"ltp":0.0,"tv":0.0,"id":9001159}]}]}
{"op":"mcm","clk":"990738162","pt":1580499152520,"mc":[{"id":"1.168133548","rc":[{"batl":[[2,17,2.29]],"ltp":9.0,"tv":4.0,"id":10616006}]}]}
{"op":"mcm","clk":"990739630","pt":1580499161465,"mc":[{"id":"1.168133548","rc":[{"trd":[[8.6,80.23]],"batl":[[0,8.6,7.34]],"ltp":8.6,"tv":100.76,"id":15608820}],"tv":178.02}]}
{"op":"mcm","clk":"990741764","pt":1580499175208,"mc":[{"id":"1.168133548","rc":[{"batl":[[2,19.5,3.54]],"ltp":9.0,"tv":4.0,"id":10616006}]}]}
{"op":"mcm","clk":"990742018","pt":1580499177019,"mc":[{"id":"1.168133548","rc":[{"batb":[[0,8,1.99],[1,7.4,2.4],[2,7.2,2.75]],"ltp":0.0,"tv":0.0,"id":8429550}]}]}
{"op":"mcm","clk":"990742298","pt":1580499178701,"mc":[{"id":"1.168133548","rc":[{"batb":[[1,8.2,3.68],[2,8,3.03]],"ltp":0.0,"tv":0.0,"id":9193530}]}]}
{"op":"mcm","clk":"990743544","pt":1580499186304,"mc":[{"id":"1.168133548","rc":[{"batl":[[1,220,3.03],[2,230,9]],"ltp":0.0,"tv":0.0,"id":8429550},{"batl":[[0,220,3.23],[1,230,9]],"ltp":0.0,"tv":0.0,"id":9193530},{"batl":[[0,220,3.23],[1,230,9]],"ltp":0.0,"tv":0.0,"id":9001159}]}]}
{"op":"mcm","clk":"990746499","pt":1580499205153,"mc":[{"id":"1.168133548","rc":[{"batl":[[0,15.5,8],[1,16,3.03],[2,16.5,5.2]],"ltp":9.0,"tv":4.0,"id":10616006}]}]}
{"op":"mcm","clk":"990748918","pt":1580499221751,"mc":[{"id":"1.168133548","rc":[{"batl":[[0,11.5,10],[1,25,1.45],[2,220,3.03]],"ltp":0.0,"tv":0.0,"id":8429550}]}]}
{"op":"mcm","clk":"990751509","pt":1580499240395,"mc":[{"id":"1.168133548","rc":[{"trd":[[6,30.26]],"batl":[[0,6,39.9]],"ltp":6.0,"tv":84.24,"id":9417341}],"tv":208.28}]}
{"op":"mcm","clk":"990751865","pt":1580499243031,"mc":[{"id":"1.168133548","rc":[{"batb":[[1,5.5,16.84]],"ltp":6.0,"tv":84.24,"id":9417341}]}]}
{"op":"mcm","clk":"990752611","pt":1580499248520,"mc":[{"id":"1.168133548","rc":[{"batb":[[1,7.2,3.17],[2,7,3.03]],"ltp":0.0,"tv":0.0,"id":8429550},{"batb":[[0,8.2,3.68],[1,8,3.03],[2,7.8,2.52]],"ltp":0.0,"tv":0.0,"id":9193530}]}]}
{"op":"mcm","clk":"990752644","pt":1580499248844,"mc":[{"id":"1.168133548","rc":[{"batb":[[0,8.2,1.98],[1,8,1.99],[2,7.2,3.17]],"ltp":0.0,"tv":0.0,"id":8429550},{"batb":[[0,8.4,2.53],[1,8.2,3.13],[2,8,3.03]],"ltp":0.0,"tv":0.0,"id":9193530}]}]}
{"op":"mcm","clk":"990755243","pt":1580499267166,"mc":[{"id":"1.168133548","rc":[{"batl":[[2,32,9]],"ltp":0.0,"tv":0.0,"id":8429550},{"batl":[[0,200,9],[1,220,3.23]],"ltp":0.0,"tv":0.0,"id":9193530},{"batl":[[0,200,9],[1,220,3.23]],"ltp":0.0,"tv":0.0,"id":9001159}]}]}
{"op":"mcm","clk":"990756148","pt":1580499273493,"mc":[{"id":"1.168133548","rc":[{"batl":[[1,220,3.03]],"ltp":0.0,"tv":0.0,"id":9193530},{"batl":[[1,220,3.03]],"ltp":0.0,"tv":0.0,"id":9001159}]}]}
{"op":"mcm","clk":"990756170","pt":1580499273603,"mc":[{"id":"1.168133548","rc":[{"batl":[[0,200,9.2]],"ltp":0.0,"tv":0.0,"id":9193530},{"batl":[[0,200,9.2]],"ltp":0.0,"tv":0.0,"id":9001159}]}]}
{"op":"mcm","clk":"990760651","pt":1580499306352,"mc":[{"id":"1.168133548","rc":[{"trd":[[8.6,94.91],[9,3.2]],"batl":[[0,9,2.78],[1,18.5,1.25],[2,26,9]],"ltp":9.0,"tv":118.64,"id":15608820}],"tv":226.16}]}
{"op":"mcm","clk":"990761473","pt":1580499311855,"mc":[{"id":"1.168133548","rc":[{"batl":[[2,26,9.2]],"ltp":9.0,"tv":118.64,"id":15608820}]}]}
{"op":"mcm","clk":"990762536","pt":1580499319076,"mc":[{"id":"1.168133548","rc":[{"batb":[[1,7.2,3.17],[2,7,3.03]],"ltp":0.0,"tv":0.0,"id":8429550}]}]}
{"op":"mcm","clk":"990762647","pt":1580499319853,"mc":[{"id":"1.168133548","rc":[{"batb":[[0,9.2,1.99],[1,8.4,2.53],[2,8.2,3.13]],"ltp":0.0,"tv":0.0,"id":9193530}]}]}
{"op":"mcm","clk":"990766001","pt":1580499342480,"mc":[{"id":"1.168133548","rc":[{"batb":[[0,7.2,3.17],[1,7,3.03],[2,6.8,3.3]],"ltp":0.0,"tv":0.0,"id":8429550},{"batb":[[1,8.2,3.68],[2,8,3.03]],"ltp":0.0,"tv":0.0,"id":9193530}]}]}
{"op":"mcm","clk":"990766015","pt":1580499342580,"mc":[{"id":"1.168133548","rc":[{"batb":[[0,7.4,2.4],[1,7.2,2.75],[2,7,3.03]],"ltp":0.0,"tv":0.0,"id":8429550},{"batb":[[0,9.4,1.98],[1,9.2,1.99],[2,8.2,3.68]],"ltp":0.0,"tv":0.0,"id":9193530}]}]}
{"op":"mcm","clk":"990766334","pt":1580499344377,"mc":[{"id":"1.168133548","rc":[{"batb":[[0,5.7,3.61],[1,5.6,102.8],[2,5.5,16.84]],"ltp":6.0,"tv":84.24,"id":9417341}]}]}
{"op":"mcm","clk":"990766518","pt":1580499345476,"mc":[{"id":"1.168133548","rc":[{"batb":[[0,5.7,3.77]],"ltp":6.0,"tv":84.24,"id":9417341},{"batl":[[0,18.5,1.25],[1,26,9.2],[2,1000,1]],"ltp":9.0,"tv":118.64,"id":15608820},{"batl":[[0,190,3.23],[1,200,9]],"ltp":0.0,"tv":0.0,"id":9001159}]}]}
{"op":"mcm","clk":"990766680","pt":1580499346570,"mc":[{"id":"1.168133548","rc":[{"batl":[[0,11,3.03],[1,11.5,10],[2,25,1.45]],"ltp":0.0,"tv":0.0,"id":8429550},{"batb":[[2,7.4,6.03]],"batl":[[1,25,1.2],[2,26,9]],"ltp":9.0,"tv":118.64,"id":15608820},{"batl":[[0,190,3.23],[1,200,9]],"ltp":0.0,"tv":0.0,"id":9193530}]}]}
{"op":"mcm","clk":"990767035","pt":1580499349229,"mc":[{"id":"1.168133548","rc":[{"batl":[[0,18.5,1.45]],"ltp":9.0,"tv":118.64,"id":15608820}]}]}
{"op":"mcm","clk":"990768150","pt":1580499357555,"mc":[{"id":"1.168133548","rc":[{"batl":[[0,15,5],[1,15.5,8],[2,16,3.03]],"ltp":9.0,"tv":4.0,"id":10616006}]}]}
{"op":"mcm","clk":"990770275","pt":1580499372374,"mc":[{"id":"1.168133548","rc":[{"batl":[[0,170,9],[1,190,3.23]],"ltp":0.0,"tv":0.0,"id":9193530},{"batl":[[0,170,9],[1,190,3.23]],"ltp":0.0,"tv":0.0,"id":9001159}]}]}
{"op":"mcm","clk":"990771036","pt":1580499377811,"mc":[{"id":"1.168133548","rc":[{"batl":[[0,170,9.2],[1,190,3.03]],"ltp":0.0,"tv":0.0,"id":9193530},{"batl":[[0,170,9.2],[1,190,3.03]],"ltp":0.0,"tv":0.0,"id":9001159}]}]}
{"op":"mcm","clk":"990779455","pt":1580499438114,"mc":[{"id":"1.168133548","rc":[{"batb":[[0,5.7,5.75],[1,5.6,100.81]],"ltp":6.0,"tv":84.24,"id":9417341},{"batb":[[0,8,1.98],[1,7.8,1.99],[2,7.6,2.52]],"ltp":9.0,"tv":118.64,"id":15608820}]}]}
{"op":"mcm","clk":"990793558","pt":1580499467549,"mc":[{"id":"1.168133548","rc":[{"batb":[[1,7.6,2.52],[2,7.4,6.03]],"ltp":9.0,"tv":118.64,"id":15608820}]}]}
{"op":"mcm","clk":"990793823","pt":1580499469483,"mc":[{"id":"1.168133548","rc":[{"batb":[[0,8,1.99],[1,7.4,2.4],[2,7.2,2.75]],"ltp":0.0,"tv":0.0,"id":8429550},{"batb":[[1,8.2,3.68],[2,8,3.03]],"ltp":0.0,"tv":0.0,"id":9193530}]}]}
{"op":"mcm","clk":"990802905","pt":1580499531714,"mc":[{"id":"1.168133548","rc":[{"batb":[[0,8.2,1.98],[1,8,1.99],[2,7.2,3.17]],"ltp":0.0,"tv":0.0,"id":8429550},{"batb":[[0,7.8,1.98]],"ltp":9.0,"tv":118.64,"id":15608820},{"batb":[[0,8.4,2.53],[1,8.2,3.13]],"ltp":0.0,"tv":0.0,"id":9193530}]}]}
{"op":"mcm","clk":"990809177","pt":1580499573527,"mc":[{"id":"1.168133548","rc":[{"batb":[[0,7.8,5.01],[2,7.4,3]],"ltp":9.0,"tv":118.64,"id":15608820},{"batl":[[0,160,3.23],[1,170,9]],"ltp":0.0,"tv":0.0,"id":9193530},{"batl":[[0,160,3.23],[1,170,9]],"ltp":0.0,"tv":0.0,"id":9001159}]}]}
{"op":"mcm","clk":"990810054","pt":1580499578937,"mc":[{"id":"1.168133548","rc":[{"trd":[[9.8,4]],"batb":[[0,9.8,5.53]],"ltp":9.8,"tv":8.0,"id":10616006}],"tv":230.16}]}
{"op":"mcm","clk":"990813568","pt":1580499602835,"mc":[{"id":"1.168133548","rc":[{"batb":[[0,9.8,3.01]],"ltp":9.8,"tv":8.0,"id":10616006}]}]}
{"op":"mcm","clk":"990814069","pt":1580499606210,"mc":[{"id":"1.168133548","rc":[{"batb":[[0,8,1.99],[1,7.8,5.01],[2,7.6,2.52]],"ltp":9.0,"tv":118.64,"id":15608820}]}]}
{"op":"mcm","clk":"990814337","pt":1580499607934,"mc":[{"id":"1.168133548","rc":[{"batb":[[1,7.2,3.17],[2,7,3.03]],"ltp":0.0,"tv":0.0,"id":8429550}]}]}
{"op":"mcm","clk":"990814645","pt":1580499609812,"mc":[{"id":"1.168133548","rc":[{"batb":[[0,9.2,1.99],[1,8.4,2.53],[2,8.2,3.13]],"ltp":0.0,"tv":0.0,"id":9193530}]}]}
{"op":"mcm","clk":"990817593","pt":1580499628891,"mc":[{"id":"1.168133548","rc":[{"batb":[[0,7.4,2.4],[1,7.2,2.75]],"ltp":0.0,"tv":0.0,"id":8429550},{"batb":[[0,10,1.98],[1,9.8,3.01],[2,9.4,3.04]],"ltp":9.8,"tv":8.0,"id":10616006},{"batb":[[0,8.2,1.98],[1,8,1.99],[2,7.8,3.03]],"ltp":9.0,"tv":118.64,"id":15608820},{"batb":[[0,9.4,1.98],[1,9.2,1.99],[2,8.2,3.68]],"ltp":0.0,"tv":0.0,"id":9193530}]}]}
{"op":"mcm","clk":"990819582","pt":1580499641518,"mc":[{"id":"1.168133548","rc":[{"batl":[[0,5.9,1.68],[1,6,39.9],[2,6.2,38.8]],"ltp":6.0,"tv":84.24,"id":9417341}]}]}
{"op":"mcm","clk":"990819755","pt":1580499642523,"mc":[{"id":"1.168133548","rc":[{"batl":[[0,6,39.9],[1,6.2,38.8],[2,6.4,35.91]],"ltp":6.0,"tv":84.24,"id":9417341}]}]}
{"op":"mcm","clk":"990822941","pt":1580499661863,"mc":[{"id":"1.168133548","rc":[{"batb":[[1,8,4.51]],"ltp":9.0,"tv":118.64,"id":15608820}]}]}
{"op":"mcm","clk":"990824592","pt":1580499672484,"mc":[{"id":"1.168133548","rc":[{"batl":[[0,140,9],[1,160,3.23]],"ltp":0.0,"tv":0.0,"id":9193530},{"batl":[[0,140,9],[1,160,3.23]],"ltp":0.0,"tv":0.0,"id":9001159}]}]}
{"op":"mcm","clk":"990825678","pt":1580499679303,"mc":[{"id":"1.168133548","rc":[{"batl":[[0,140,9.2],[1,160,3.03]],"ltp":0.0,"tv":0.0,"id":9193530},{"batl":[[0,140,9.2],[1,160,3.03]],"ltp":0.0,"tv":0.0,"id":9001159}]}]}
{"op":"mcm","clk":"990828613","pt":1580499698435,"mc":[{"id":"1.168133548","rc":[{"batb":[[0,8.2,5.01],[2,7.6,2.52]],"ltp":9.0,"tv":118.64,"id":15608820},{"batl":[[0,130,3.23],[1,140,9]],"ltp":0.0,"tv":0.0,"id":9001159}]}]}
{"op":"mcm","clk":"990828778","pt":1580499699461,"mc":[{"id":"1.168133548","rc":[{"batb":[[1,9.6,3.01]],"ltp":9.8,"tv":8.0,"id":10616006},{"batl":[[0,130,3.23],[1,140,9]],"ltp":0.0,"tv":0.0,"id":9193530}]}]}
{"op":"mcm","clk":"990828925","pt":1580499700369,"mc":[{"id":"1.168133548","rc":[{"batl":[[2,6.4,35.07]],"ltp":6.0,"tv":84.24,"id":9417341}]}]}
{"op":"mcm","clk":"990829902","pt":1580499706551,"mc":[{"id":"1.168133548","rc":[{"batl":[[0,130,3.03]],"ltp":0.0,"tv":0.0,"id":9193530}]}]}
{"op":"mcm","clk":"990829960","pt":1580499706977,"mc":[{"id":"1.168133548","rc":[{"batl":[[0,14.5,2.56],[1,15,5],[2,15.5,8]],"ltp":9.8,"tv":8.0,"id":10616006},{"batl":[[0,130,3.23]],"ltp":0.0,"tv":0.0,"id":9193530}]}]}
{"op":"mcm","clk":"990833151","pt":1580499727031,"mc":[{"id":"1.168133548","rc":[{"batb":[[0,9.8,1.98]],"ltp":9.8,"tv":8.0,"id":10616006}]}]}
{"op":"mcm","clk":"990833749","pt":1580499731128,"mc":[{"id":"1.168133548","rc":[{"batb":[[1,8,2.52]],"ltp":9.0,"tv":118.64,"id":15608820}]}]}
{"op":"mcm","clk":"990833940","pt":1580499732250,"mc":[{"id":"1.168133548","rc":[{"batb":[[0,8,1.99],[1,7.4,2.4],[2,7.2,2.75]],"ltp":0.0,"tv":0.0,"id":8429550}]}]}
{"op":"mcm","clk":"990834069","pt":1580499733050,"mc":[{"id":"1.168133548","rc":[{"batb":[[1,8.2,3.68],[2,8,3.03]],"ltp":0.0,"tv":0.0,"id":9193530}]}]}
{"op":"mcm","clk":"990835940","pt":1580499745372,"mc":[{"id":"1.168133548","rc":[{"batb":[[0,6.6,4.23],[1,6.2,4.95],[2,6,3]],"ltp":6.8,"tv":6.02,"id":17352128}]}]}
{"op":"mcm","clk":"990838161","pt":1580499759380,"mc":[{"id":"1.168133548","rc":[{"trd":[[6.8,10.5]],"batb":[[0,6.2,4.95],[1,6,3],[2,5.9,2.52]],"batl":[[0,7.2,3.16],[1,7.4,1.25],[2,10,4.5]],"ltp":6.8,"tv":14.48,"id":17352128}],"tv":238.62}]}
{"op":"mcm","clk":"990838242","pt":1580499759902,"mc":[{"id":"1.168133548","rc":[{"trd":[[6.8,12.02]],"batl":[[0,7.2,2.4]],"ltp":6.8,"tv":16.0,"id":17352128}],"tv":240.14}]}
{"op":"mcm","clk":"990839004","pt":1580499764917,"mc":[{"id":"1.168133548","rc":[{"batl":[[1,8.4,11.03]],"ltp":7.4,"tv":9.24,"id":10170404}]}]}
{"op":"mcm","clk":"990845564","pt":1580499807029,"mc":[{"id":"1.168133548","rc":[{"trd":[[9,1.1],[9.4,3.96]],"batb":[[0,8.2,3.13],[1,8,3.03],[2,7.8,2.52]],"batl":[[0,130,3.7]],"ltp":9.0,"tv":5.06,"id":9193530}],"tv":245.2}]}
{"op":"mcm","clk":"990845835","pt":1580499808577,"mc":[{"id":"1.168133548","rc":[{"batl":[[0,130,3.5]],"ltp":9.0,"tv":5.06,"id":9193530}]}]}
{"op":"mcm","clk":"990846312","pt":1580499811779,"mc":[{"id":"1.168133548","rc":[{"batb":[[1,8,6.03]],"ltp":9.0,"tv":5.06,"id":9193530}]}]}
{"op":"mcm","clk":"990847238","pt":1580499817785,"mc":[{"id":"1.168133548","rc":[{"trd":[[9.6,4.04],[9.8,7.97]],"batb":[[0,9.4,4.04],[1,9,3.07],[2,8.6,2.52]],"ltp":9.6,"tv":16.0,"id":10616006}],"tv":253.2}]}
{"op":"mcm","clk":"990847911","pt":1580499822182,"mc":[{"id":"1.168133548","rc":[{"batb":[[0,8.2,1.98],[1,8,1.99],[2,7.2,3.17]],"ltp":0.0,"tv":0.0,"id":8429550},{"batb":[[0,8.4,1.98],[1,8.2,3.13],[2,8,6.03]],"batl":[[0,110,9.47],[1,130,3.03]],"ltp":9.0,"tv":5.06,"id":9193530},{"batl":[[0,110,9],[1,130,3.23]],"ltp":0.0,"tv":0.0,"id":9001159}]}]}
{"op":"mcm","clk":"990849024","pt":1580499829467,"mc":[{"id":"1.168133548","rc":[{"batl":[[1,130,3.03]],"ltp":0.0,"tv":0.0,"id":9001159}]}]}
{"op":"mcm","clk":"990849161","pt":1580499830294,"mc":[{"id":"1.168133548","rc":[{"batl":[[0,110,9.2]],"ltp":0.0,"tv":0.0,"id":9001159}]}]}
{"op":"mcm","clk":"990849635","pt":1580499833488,"mc":[{"id":"1.168133548","rc":[{"batl":[[1,130,0]],"ltp":0.0,"tv":0.0,"id":9001159}]}]}
{"op":"mcm","clk":"990849791","pt":1580499834510,"mc":[{"id":"1.168133548","rc":[{"batb":[[0,8.2,1.98],[2,7.8,3.03]],"ltp":9.0,"tv":118.64,"id":15608820},{"batl":[[0,100,3.5],[1,110,9]],"ltp":9.0,"tv":5.06,"id":9193530},{"batl":[[0,100,3.23],[1,110,9]],"ltp":0.0,"tv":0.0,"id":9001159}]}]}
{"op":"mcm","clk":"990849896","pt":1580499835218,"mc":[{"id":"1.168133548","rc":[{"batb":[[1,6,5.61]],"batl":[[2,9.8,3.03]],"ltp":6.8,"tv":16.0,"id":17352128}]}]}
{"op":"mcm","clk":"990850990","pt":1580499842283,"mc":[{"id":"1.168133548","rc":[{"batb":[[0,9.4,1.52]],"ltp":9.6,"tv":16.0,"id":10616006}]}]}
{"op":"mcm","clk":"990852294","pt":1580499851191,"mc":[{"id":"1.168133548","rc":[{"batl":[[0,100,3.55]],"ltp":9.0,"tv":5.06,"id":9193530},{"batl":[[0,100,3.28]],"ltp":0.0,"tv":0.0,"id":9001159}]}]}
{"op":"mcm","clk":"990852776","pt":1580499854511,"mc":[{"id":"1.168133548","rc":[{"batb":[[1,7.2,3.17],[2,7,3.03]],"ltp":0.0,"tv":0.0,"id":8429550}]}]}
{"op":"mcm","clk":"990852795","pt":1580499854627,"mc":[{"id":"1.168133548","rc":[{"batb":[[0,8.6,1.99],[1,8.4,1.98],[2,8.2,3.13]],"ltp":9.0,"tv":5.06,"id":9193530}]}]}
{"op":"mcm","clk":"990860006","pt":1580499902520,"mc":[{"id":"1.168133548","rc":[{"batb":[[1,8.6,3.07],[2,8.4,3]],"ltp":9.6,"tv":16.0,"id":10616006}]}]}
{"op":"mcm","clk":"990861915","pt":1580499914860,"mc":[{"id":"1.168133548","rc":[{"batb":[[0,7.4,2.4],[1,7.2,2.75]],"ltp":0.0,"tv":0.0,"id":8429550},{"batb":[[0,8.8,1.98],[1,8.6,1.99]],"ltp":9.0,"tv":5.06,"id":9193530}]}]}
{"op":"mcm","clk":"990863301","pt":1580499923966,"mc":[{"id":"1.168133548","rc":[{"batl":[[0,90,9.47],[1,100,3.08]],"ltp":9.0,"tv":5.06,"id":9193530},{"batl":[[0,90,9.2],[1,100,3.08]],"ltp":0.0,"tv":0.0,"id":9001159}]}]}
{"op":"mcm","clk":"990863649","pt":1580499926252,"mc":[{"id":"1.168133548","rc":[{"batl":[[0,6.8,5],[1,7.2,2.4],[2,7.4,1.25]],"ltp":6.8,"tv":16.0,"id":17352128}]}]}
{"op":"mcm","clk":"990865931","pt":1580499941567,"mc":[{"id":"1.168133548","rc":[{"batl":[[1,100,3.03],[2,1000,0.06]],"ltp":9.0,"tv":5.06,"id":9193530},{"batl":[[1,100,3.03]],"ltp":0.0,"tv":0.0,"id":9001159}]}]}
{"op":"mcm","clk":"990865991","pt":1580499941996,"mc":[{"id":"1.168133548","rc":[{"batl":[[0,90,9.53],[2,1000,0]],"ltp":9.0,"tv":5.06,"id":9193530},{"batl":[[0,90,9.26]],"ltp":0.0,"tv":0.0,"id":9001159}]}]}
{"op":"mcm","clk":"990869558","pt":1580499965214,"mc":[{"id":"1.168133548","rc":[{"batb":[[0,8,1.99],[1,7.4,2.4],[2,7.2,2.75]],"ltp":0.0,"tv":0.0,"id":8429550}]}]}
{"op":"mcm","clk":"990869732","pt":1580499966207,"mc":[{"id":"1.168133548","rc":[{"trd":[[9,2.04]],"batb":[[0,9,1.52],[1,8.8,1.98]],"batl":[[0,90,9.06]],"ltp":9.0,"tv":6.0,"id":9193530}],"tv":254.14}]}
{"op":"mcm","clk":"990869988","pt":1580499968189,"mc":[{"id":"1.168133548","rc":[{"batl":[[0,90,9.26]],"ltp":9.0,"tv":6.0,"id":9193530}]}]}
{"op":"mcm","clk":"990874006","pt":1580499995482,"mc":[{"id":"1.168133548","rc":[{"batb":[[0,9,1.08],[1,8.6,2.52]],"ltp":9.6,"tv":16.0,"id":10616006},{"batb":[[0,8.2,5.01],[2,7.6,2.52]],"ltp":9.0,"tv":118.64,"id":15608820},{"batl":[[0,85,3.29],[1,90,9]],"ltp":0.0,"tv":0.0,"id":9001159}]}]}
{"op":"mcm","clk":"990874067","pt":1580499995916,"mc":[{"id":"1.168133548","rc":[{"batl":[[0,85,3.29],[1,90,9]],"ltp":9.0,"tv":6.0,"id":9193530},{"batb":[[1,6,3]],"ltp":6.8,"tv":16.0,"id":17352128}]}]}
{"op":"mcm","clk":"990876165","pt":1580500010413,"mc":[{"id":"1.168133548","rc":[{"batb":[[0,8.2,1.98],[1,8,1.99],[2,7.2,3.17]],"ltp":0.0,"tv":0.0,"id":8429550},{"batb":[[1,8.4,1.98]],"ltp":9.0,"tv":6.0,"id":9193530}]}]}
{"op":"mcm","clk":"990884247","pt":1580500070921,"mc":[{"id":"1.168133548","rc":[{"batl":[[0,75,9],[1,85,3.29]],"ltp":9.0,"tv":6.0,"id":9193530},{"batl":[[0,75,9],[1,85,3.29]],"ltp":0.0,"tv":0.0,"id":9001159}]}]}
{"op":"mcm","clk":"990884611","pt":1580500073827,"mc":[{"id":"1.168133548","rc":[{"batl":[[0,75,9.2],[1,85,3.09]],"ltp":9.0,"tv":6.0,"id":9193530},{"batl":[[0,75,9.2],[1,85,3.09]],"ltp":0.0,"tv":0.0,"id":9001159}]}]}
{"op":"mcm","clk":"990886762","pt":1580500090324,"mc":[{"id":"1.168133548","rc":[{"batb":[[1,7.2,3.17],[2,7,3.03]],"ltp":0.0,"tv":0.0,"id":8429550}]}]}
{"op":"mcm","clk":"990887040","pt":1580500092561,"mc":[{"id":"1.168133548","rc":[{"batl":[[0,75,9.27],[1,85,3.03]],"ltp":9.0,"tv":6.0,"id":9193530},{"batl":[[0,75,9.27],[1,85,3.03]],"ltp":0.0,"tv":0.0,"id":9001159}]}]}
{"op":"mcm","clk":"990888164","pt":1580500101510,"mc":[{"id":"1.168133548","rc":[{"batb":[[0,7.2,3.17],[1,7,3.03],[2,6.8,3.3]],"ltp":0.0,"tv":0.0,"id":8429550}]}]}
{"op":"mcm","clk":"990888191","pt":1580500101583,"mc":[{"id":"1.168133548","rc":[{"batb":[[0,7.4,2.4],[1,7.2,2.75],[2,7,3.03]],"ltp":0.0,"tv":0.0,"id":8429550}]}]}
{"op":"mcm","clk":"990891108","pt":1580500125432,"mc":[{"id":"1.168133548","rc":[{"batb":[[0,8.2,1.98],[2,7.8,3.03]],"ltp":9.0,"tv":118.64,"id":15608820},{"batl":[[0,70,3.3],[1,75,9]],"ltp":0.0,"tv":0.0,"id":9001159}]}]}
{"op":"mcm","clk":"990891215","pt":1580500126439,"mc":[{"id":"1.168133548","rc":[{"batl":[[0,14.5,3.91]],"ltp":9.6,"tv":16.0,"id":10616006},{"batl":[[0,70,3.3],[1,75,9]],"ltp":9.0,"tv":6.0,"id":9193530}]}]}
{"op":"mcm","clk":"990899632","pt":1580500195336,"mc":[{"id":"1.168133548","rc":[{"batl":[[0,13.5,3],[1,14.5,3.91],[2,15,5]],"ltp":9.6,"tv":16.0,"id":10616006}]}]}
{"op":"mcm","clk":"990900584","pt":1580500203134,"mc":[{"id":"1.168133548","rc":[{"batl":[[1,14.5,1.35]],"ltp":9.6,"tv":16.0,"id":10616006}]}]}
{"op":"mcm","clk":"990900857","pt":1580500205247,"mc":[{"id":"1.168133548","rc":[{"batl":[[0,7.4,10],[1,7.6,3.35],[2,8.4,11.03]],"ltp":7.4,"tv":9.24,"id":10170404}]}]}
{"op":"mcm","clk":"990901297","pt":1580500208724,"mc":[{"id":"1.168133548","rc":[{"trd":[[6.2,6.98],[6.4,1.02]],"batb":[[0,6,3.95],[1,5.9,2.52],[2,5.6,2.52]],"ltp":6.2,"tv":24.0,"id":17352128}],"tv":262.14}]}
{"op":"mcm","clk":"990901456","pt":1580500210038,"mc":[{"id":"1.168133548","rc":[{"batb":[[0,8,1.99],[1,7.4,2.4],[2,7.2,2.75]],"ltp":0.0,"tv":0.0,"id":8429550}]}]}
{"op":"mcm","clk":"990901642","pt":1580500211567,"mc":[{"id":"1.168133548","rc":[{"batl":[[1,75,0]],"ltp":9.0,"tv":6.0,"id":9193530},{"batl":[[1,75,0]],"ltp":0.0,"tv":0.0,"id":9001159}]}]}
{"op":"mcm","clk":"990901655","pt":1580500211635,"mc":[{"id":"1.168133548","rc":[{"batl":[[0,60,9],[1,70,3.3]],"ltp":9.0,"tv":6.0,"id":9193530},{"batl":[[0,60,9],[1,70,3.3]],"ltp":0.0,"tv":0.0,"id":9001159}]}]}
{"op":"mcm","clk":"990901952","pt":1580500214262,"mc":[{"id":"1.168133548","rc":[{"batb":[[0,5.9,3.47],[1,5.6,2.52],[2,5.5,3]],"ltp":6.2,"tv":24.0,"id":17352128}]}]}
{"op":"mcm","clk":"990902018","pt":1580500214740,"mc":[{"id":"1.168133548","rc":[{"batl":[[0,60,9.2],[1,70,3.1]],"ltp":9.0,"tv":6.0,"id":9193530},{"batl":[[0,60,9.2],[1,70,3.1]],"ltp":0.0,"tv":0.0,"id":9001159}]}]}
{"op":"mcm","clk":"990902375","pt":1580500217369,"mc":[{"id":"1.168133548","rc":[{"batl":[[1,24,2],[2,25,1.2]],"ltp":9.0,"tv":118.64,"id":15608820}]}]}
{"op":"mcm","clk":"990905305","pt":1580500242491,"mc":[{"id":"1.168133548","rc":[{"batl":[[1,70,3.03],[2,1000,0.09]],"ltp":9.0,"tv":6.0,"id":9193530},{"batl":[[0,60,9.29],[1,70,3.03]],"ltp":0.0,"tv":0.0,"id":9001159}]}]}
{"op":"mcm","clk":"990905349","pt":1580500242811,"mc":[{"id":"1.168133548","rc":[{"batl":[[0,60,9.29],[2,1000,0]],"ltp":9.0,"tv":6.0,"id":9193530}]}]}
{"op":"mcm","clk":"990907565","pt":1580500263265,"mc":[{"id":"1.168133548","rc":[{"batb":[[0,5.6,3.47],[1,5.5,3],[2,5.3,3.45]],"ltp":6.2,"tv":24.0,"id":17352128}]}]}
{"op":"mcm","clk":"990908306","pt":1580500269565,"mc":[{"id":"1.168133548","rc":[{"batb":[[0,8.2,5.01],[2,7.6,2.52]],"batl":[[2,26,9.2]],"ltp":9.0,"tv":118.64,"id":15608820},{"batl":[[0,55,3.32],[1,60,9]],"ltp":0.0,"tv":0.0,"id":9001159}]}]}
{"op":"mcm","clk":"990908413","pt":1580500270476,"mc":[{"id":"1.168133548","rc":[{"batl":[[1,23,3.03],[2,24,2]],"ltp":9.0,"tv":118.64,"id":15608820},{"batl":[[0,55,3.32],[1,60,9]],"ltp":9.0,"tv":6.0,"id":9193530}]}]}
{"op":"mcm","clk":"990908422","pt":1580500270578,"mc":[{"id":"1.168133548","rc":[{"batb":[[2,5.4,3.41]],"ltp":6.2,"tv":24.0,"id":17352128}]}]}
{"op":"mcm","clk":"990908635","pt":1580500272376,"mc":[{"id":"1.168133548","rc":[{"batl":[[2,26,9.2]],"ltp":9.0,"tv":118.64,"id":15608820}]}]}
{"op":"mcm","clk":"990908853","pt":1580500274281,"mc":[{"id":"1.168133548","rc":[{"batl":[[1,23,3.26],[2,26,9]],"ltp":9.0,"tv":118.64,"id":15608820}]}]}
{"op":"mcm","clk":"990911097","pt":1580500294355,"mc":[{"id":"1.168133548","rc":[{"batb":[[0,8.2,1.98],[1,8,1.99],[2,7.2,3.17]],"ltp":0.0,"tv":0.0,"id":8429550}]}]}
{"op":"mcm","clk":"990914026","pt":1580500322551,"mc":[{"id":"1.168133548","rc":[{"batl":[[0,48,9],[1,55,3.32]],"ltp":0.0,"tv":0.0,"id":9001159}]}]}
{"op":"mcm","clk":"990914525","pt":1580500327080,"mc":[{"id":"1.168133548","rc":[{"batl":[[0,48,9.2],[1,55,3.12]],"ltp":0.0,"tv":0.0,"id":9001159}]}]}
{"op":"mcm","clk":"990914950","pt":1580500331368,"mc":[{"id":"1.168133548","rc":[{"batl":[[0,48,9.31],[1,55,3.03]],"ltp":0.0,"tv":0.0,"id":9001159}]}]}
{"op":"mcm","clk":"990915256","pt":1580500334481,"mc":[{"id":"1.168133548","rc":[{"batl":[[0,48,9.11]],"ltp":0.0,"tv":0.0,"id":9001159}]}]}
{"op":"mcm","clk":"990915263","pt":1580500334585,"mc":[{"id":"1.168133548","rc":[{"batl":[[0,48,9.31]],"ltp":0.0,"tv":0.0,"id":9001159}]}]}
{"op":"mcm","clk":"990926748","pt":1580500352699,"mc":[{"id":"1.168133548","rc":[{"batb":[[1,7.2,3.17],[2,7,3.03]],"ltp":0.0,"tv":0.0,"id":8429550}]}]}
{"op":"mcm","clk":"990929921","pt":1580500382038,"mc":[{"id":"1.168133548","rc":[{"batl":[[1,21,2],[2,23,3.26]],"ltp":9.0,"tv":118.64,"id":15608820}]}]}
{"op":"mcm","clk":"990930787","pt":1580500389492,"mc":[{"id":"1.168133548","rc":[{"batb":[[0,7.2,3.17],[1,7,3.03],[2,6.8,3.3]],"ltp":0.0,"tv":0.0,"id":8429550},{"batb":[[1,8.8,1.68],[2,8.6,2.52]],"ltp":9.6,"tv":16.0,"id":10616006}]}]}
{"op":"mcm","clk":"990930795","pt":1580500389594,"mc":[{"id":"1.168133548","rc":[{"batb":[[0,7.4,2.4],[1,7.2,2.75],[2,7,3.03]],"ltp":0.0,"tv":0.0,"id":8429550}]}]}
{"op":"mcm","clk":"990932233","pt":1580500403503,"mc":[{"id":"1.168133548","rc":[{"batb":[[0,8.2,1.98]],"ltp":9.0,"tv":118.64,"id":15608820},{"batl":[[0,46,3.34],[1,48,9]],"ltp":0.0,"tv":0.0,"id":9001159}]}]}
{"op":"mcm","clk":"990932338","pt":1580500404507,"mc":[{"id":"1.168133548","rc":[{"batb":[[2,7.8,3.03]],"batl":[[1,20,3.03],[2,21,2]],"ltp":9.0,"tv":118.64,"id":15608820},{"batb":[[2,5.3,3.45]],"ltp":6.2,"tv":24.0,"id":17352128}]}]}
{"op":"mcm","clk":"990932346","pt":1580500404611,"mc":[{"id":"1.168133548","rc":[{"batb":[[0,5.7,3.98],[1,5.6,2.52],[2,5.5,3]],"ltp":6.2,"tv":24.0,"id":17352128}]}]}
{"op":"mcm","clk":"990934212","pt":1580500423286,"mc":[{"id":"1.168133548","rc":[{"batl":[[1,20,3.29]],"ltp":9.0,"tv":118.64,"id":15608820}]}]}
{"op":"mcm","clk":"990936652","pt":1580500448317,"mc":[{"id":"1.168133548","rc":[{"batl":[[1,19,2],[2,20,3.29]],"ltp":9.0,"tv":118.64,"id":15608820}]}]}
{"op":"mcm","clk":"990937061","pt":1580500452636,"mc":[{"id":"1.168133548","rc":[{"trd":[[5.7,0.02]],"batb":[[0,5.7,3.97]],"ltp":5.7,"tv":24.02,"id":17352128}],"tv":262.16}]}
{"op":"mcm","clk":"990937841","pt":1580500461233,"mc":[{"id":"1.168133548","rc":[{"batb":[[2,5.3,3.45]],"ltp":5.7,"tv":24.02,"id":17352128}]}]}
{"op":"mcm","clk":"990939253","pt":1580500476107,"mc":[{"id":"1.168133548","rc":[{"batl":[[0,42,9],[1,46,3.34]],"ltp":0.0,"tv":0.0,"id":9001159}]}]}
{"op":"mcm","clk":"990939886","pt":1580500482159,"mc":[{"id":"1.168133548","rc":[{"batl":[[0,42,9.12],[1,46,3.23]],"ltp":0.0,"tv":0.0,"id":9001159}]}]}
{"op":"mcm","clk":"990943644","pt":1580500517400,"mc":[{"id":"1.168133548","rc":[{"batb":[[0,8.2,5.01],[2,7.6,2.52]],"ltp":9.0,"tv":118.64,"id":15608820},{"batl":[[0,40,3.15],[1,42,9],[2,44,0.2]],"ltp":0.0,"tv":0.0,"id":9001159}]}]}
{"op":"mcm","clk":"990943703","pt":1580500518003,"mc":[{"id":"1.168133548","rc":[{"batl":[[0,18.5,4.48],[2,26,9.26]],"ltp":9.0,"tv":118.64,"id":15608820},{"batb":[[0,5.6,3.46],[1,5.4,3.96],[2,5.3,2.52]],"ltp":5.7,"tv":24.02,"id":17352128}]}]}
{"op":"mcm","clk":"990946327","pt":1580500542252,"mc":[{"id":"1.168133548","rc":[{"batl":[[0,18.5,4.76],[2,26,9]],"ltp":9.0,"tv":118.64,"id":15608820}]}]}
{"op":"mcm","clk":"990948659","pt":1580500562254,"mc":[{"id":"1.168133548","rc":[{"batb":[[0,5.5,3.46]],"ltp":5.7,"tv":24.02,"id":17352128}]}]}
{"op":"mcm","clk":"990950661","pt":1580500580115,"mc":[{"id":"1.168133548","rc":[{"batb":[[0,8,1.99],[1,7.4,2.4],[2,7.2,2.75]],"ltp":0.0,"tv":0.0,"id":8429550}]}]}
{"op":"mcm","clk":"990953428","pt":1580500605453,"mc":[{"id":"1.168133548","rc":[{"batl":[[1,26,9],[2,26,0]],"ltp":9.0,"tv":118.64,"id":15608820}]}]}
{"op":"mcm","clk":"990955679","pt":1580500626487,"mc":[{"id":"1.168133548","rc":[{"batb":[[0,8.2,1.98],[2,7.8,3.03]],"ltp":9.0,"tv":118.64,"id":15608820},{"batb":[[0,5.6,3.97],[1,5.5,2.52],[2,5.3,3.45]],"ltp":5.7,"tv":24.02,"id":17352128}]}]}
{"op":"mcm","clk":"990955880","pt":1580500628376,"mc":[{"id":"1.168133548","rc":[{"batl":[[0,36,9],[1,40,3.15]],"ltp":0.0,"tv":0.0,"id":9001159}]}]}
{"op":"mcm","clk":"990956341","pt":1580500632475,"mc":[{"id":"1.168133548","rc":[{"batl":[[0,36,9.15],[1,40,3.03]],"ltp":0.0,"tv":0.0,"id":9001159}]}]}
{"op":"mcm","clk":"990960682","pt":1580500671539,"mc":[{"id":"1.168133548","rc":[{"batb":[[0,8.2,1.98],[1,8,1.99],[2,7.2,3.17]],"ltp":0.0,"tv":0.0,"id":8429550}]}]}
{"op":"mcm","clk":"990964751","pt":1580500711418,"mc":[{"id":"1.168133548","rc":[{"batl":[[1,44,0.2],[2,44,0]],"ltp":0.0,"tv":0.0,"id":9001159}]}]}
{"op":"mcm","clk":"990964809","pt":1580500712205,"mc":[{"id":"1.168133548","rc":[{"batb":[[0,8.2,5.01],[2,7.6,2.52]],"ltp":9.0,"tv":118.64,"id":15608820},{"batl":[[0,34,3.18],[1,36,9],[2,44,0.2]],"ltp":0.0,"tv":0.0,"id":9001159},{"batb":[[0,5.5,3.46],[1,5.4,3.96],[2,5.3,2.52]],"ltp":5.7,"tv":24.02,"id":17352128}]}]}
{"op":"mcm","clk":"990971936","pt":1580500782464,"mc":[{"id":"1.168133548","rc":[{"batb":[[1,7.2,3.17],[2,7,3.03]],"ltp":0.0,"tv":0.0,"id":8429550}]}]}
{"op":"mcm","clk":"990973177","pt":1580500793486,"mc":[{"id":"1.168133548","rc":[{"batb":[[0,8.2,1.98]],"ltp":9.0,"tv":118.64,"id":15608820}]}]}
{"op":"mcm","clk":"990973214","pt":1580500793948,"mc":[{"id":"1.168133548","rc":[{"batb":[[2,7.8,3.03]],"ltp":9.0,"tv":118.64,"id":15608820},{"batb":[[0,5.6,3.97],[1,5.5,2.52],[2,5.3,3.45]],"ltp":5.7,"tv":24.02,"id":17352128}]}]}
{"op":"mcm","clk":"990974726","pt":1580500807766,"mc":[{"id":"1.168133548","rc":[{"batb":[[1,7.2,3.17],[2,7,3.03]],"batl":[[0,11,3.03]],"ltp":0.0,"tv":0.0,"id":8429550},{"trd":[[5.5,50],[6,30.26]],"batb":[[2,5.5,16.84]],"batl":[[1,6.2,38.77],[2,6.4,35.07]],"ltp":6.0,"tv":84.25,"id":9417341},{"batb":[[2,6,3.33]],"batl":[[1,29,3.2]],"ltp":7.2,"tv":4.0,"id":8231803},{"trd":[[9.6,4.03]],"ltp":9.6,"tv":16.0,"id":10616006},{"trd":[[7.6,1.3]],"batb":[[0,6.6,3.81]],"batl":[[2,8.4,11.03]],"ltp":7.4,"tv":9.24,"id":10170404},{"trd":[[8.4,15.45],[8.6,94.91],[8.8,5.08]],"batb":[[2,7.8,3.03]],"batl":[[0,18.5,4.76]],"ltp":9.0,"tv":118.63,"id":15608820},{"batb":[[0,9.6,7.09],[1,7.8,5.55]],"batl":[[0,34,3.18]],"ltp":0.0,"tv":0.0,"id":9001159},{"batl":[[0,55,3.32]],"ltp":9.0,"tv":6.0,"id":9193530},{"batb":[[0,5.6,3.97]],"ltp":5.7,"tv":24.02,"id":17352128}],"tv":262.15}]}
{"op":"mcm","clk":"990976239","pt":1580500821346,"mc":[{"id":"1.168133548","rc":[{"batl":[[0,34,3.38],[2,44,0]],"ltp":0.0,"tv":0.0,"id":9001159}]}]}
{"op":"mcm","clk":"990981634","pt":1580500865559,"mc":[{"id":"1.168133548","rc":[{"batb":[[0,8.2,5.01],[2,7.6,2.52]],"ltp":9.0,"tv":118.63,"id":15608820},{"batb":[[0,5.5,3.46],[1,5.3,3.45],[2,5.1,2.52]],"ltp":5.7,"tv":24.02,"id":17352128}]}]}
{"op":"mcm","clk":"990981701","pt":1580500866042,"mc":[{"id":"1.168133548","rc":[{"batb":[[1,5.4,3.96],[2,5.3,2.52]],"ltp":5.7,"tv":24.02,"id":17352128}]}]}
{"op":"mcm","clk":"990992569","pt":1580500947455,"mc":[{"id":"1.168133548","rc":[{"batb":[[0,8.2,1.98],[2,7.8,3.03]],"ltp":9.0,"tv":118.63,"id":15608820},{"batb":[[0,5.6,3.97],[1,5.5,2.52],[2,5.3,3.45]],"ltp":5.7,"tv":24.02,"id":17352128}]}]}
{"op":"mcm","clk":"990993492","pt":1580500954197,"mc":[{"id":"1.168133548","rc":[{"batb":[[0,7.4,2.41],[1,7.2,2.75]],"ltp":0.0,"tv":0.0,"id":8429550}]}]}
{"op":"mcm","clk":"990996712","pt":1580500975532,"mc":[{"id":"1.168133548","rc":[{"batb":[[0,8,1.99],[1,7.4,2.41],[2,7.2,2.75]],"ltp":0.0,"tv":0.0,"id":8429550}]}]}
{"op":"mcm","clk":"990996855","pt":1580500976469,"mc":[{"id":"1.168133548","rc":[{"batl":[[0,5.9,7.5],[1,6,39.9],[2,6.2,38.77]],"ltp":6.0,"tv":84.25,"id":9417341}]}]}
{"op":"mcm","clk":"990999328","pt":1580500993151,"mc":[{"id":"1.168133548","rc":[{"batb":[[0,8.2,5.01],[2,7.6,2.52]],"ltp":9.0,"tv":118.63,"id":15608820},{"batb":[[0,5.5,3.46],[1,5.4,3.96],[2,5.3,2.52]],"ltp":5.7,"tv":24.02,"id":17352128}]}]}
{"op":"mcm","clk":"991004399","pt":1580501027292,"mc":[{"id":"1.168133548","rc":[{"batb":[[0,8.2,1.98],[2,7.8,3.03]],"ltp":9.0,"tv":118.63,"id":15608820},{"batb":[[0,5.6,3.97],[1,5.5,2.52],[2,5.3,3.45]],"ltp":5.7,"tv":24.02,"id":17352128}]}]}
{"op":"mcm","clk":"991013541","pt":1580501088508,"mc":[{"id":"1.168133548","rc":[{"batb":[[2,7.6,2.52]],"ltp":9.0,"tv":118.63,"id":15608820}]}]}
{"op":"mcm","clk":"991013627","pt":1580501089025,"mc":[{"id":"1.168133548","rc":[{"batb":[[0,8.2,5.01]],"ltp":9.0,"tv":118.63,"id":15608820},{"batb":[[0,5.5,3.46],[1,5.4,3.96],[2,5.3,2.52]],"ltp":5.7,"tv":24.02,"id":17352128}]}]}
{"op":"mcm","clk":"991021846","pt":1580501142430,"mc":[{"id":"1.168133548","rc":[{"batb":[[0,8.2,1.98],[1,8,1.99],[2,7.2,3.17]],"ltp":0.0,"tv":0.0,"id":8429550}]}]}
{"op":"mcm","clk":"991022607","pt":1580501147513,"mc":[{"id":"1.168133548","rc":[{"batb":[[0,8.2,1.98],[2,7.8,3.03]],"ltp":9.0,"tv":118.63,"id":15608820},{"batb":[[0,5.6,3.97],[1,5.5,2.52],[2,5.3,3.45]],"ltp":5.7,"tv":24.02,"id":17352128}]}]}
{"op":"mcm","clk":"991022905","pt":1580501149500,"mc":[{"id":"1.168133548","rc":[{"batb":[[1,7.2,3.17],[2,7,3.03]],"ltp":0.0,"tv":0.0,"id":8429550}]}]}
{"op":"mcm","clk":"991027770","pt":1580501182088,"mc":[{"id":"1.168133548","rc":[{"batl":[[0,13,10],[1,18.5,4.76],[2,26,9]],"ltp":9.0,"tv":118.63,"id":15608820}]}]}
{"op":"mcm","clk":"991028374","pt":1580501186117,"mc":[{"id":"1.168133548","rc":[{"batl":[[0,13,10.2],[1,18.5,4.56]],"ltp":9.0,"tv":118.63,"id":15608820}]}]}
{"op":"mcm","clk":"991032522","pt":1580501213571,"mc":[{"id":"1.168133548","rc":[{"batb":[[0,8.2,5.01],[2,7.6,2.52]],"batl":[[1,18.5,1.53]],"ltp":9.0,"tv":118.63,"id":15608820}]}]}
{"op":"mcm","clk":"991032597","pt":1580501214038,"mc":[{"id":"1.168133548","rc":[{"batl":[[0,12.5,3.89],[1,13,10],[2,18.5,1.53]],"ltp":9.0,"tv":118.63,"id":15608820},{"batb":[[0,5.5,3.46],[1,5.4,3.96],[2,5.3,2.52]],"ltp":5.7,"tv":24.02,"id":17352128}]}]}
{"op":"mcm","clk":"991033298","pt":1580501218456,"mc":[{"id":"1.168133548","rc":[{"batl":[[0,12,3.09],[1,12.5,3.89],[2,13,10]],"ltp":9.0,"tv":118.63,"id":15608820}]}]}
{"op":"mcm","clk":"991033588","pt":1580501220248,"mc":[{"id":"1.168133548","rc":[{"batl":[[0,12,3.29],[1,12.5,3.69]],"ltp":9.0,"tv":118.63,"id":15608820}]}]}
{"op":"mcm","clk":"991035806","pt":1580501234725,"mc":[{"id":"1.168133548","rc":[{"batl":[[0,11.5,2.2],[1,12,3.09],[2,12.5,3.69]],"ltp":9.0,"tv":118.63,"id":15608820}]}]}
{"op":"mcm","clk":"991037000","pt":1580501242757,"mc":[{"id":"1.168133548","rc":[{"trd":[[8.8,1.84],[9,1.12],[9.4,1.06]],"batb":[[0,8.6,3.28],[1,8.4,3],[2,8.2,2.52]],"ltp":8.8,"tv":20.0,"id":10616006}],"tv":266.15}]}
{"op":"mcm","clk":"991037853","pt":1580501248145,"mc":[{"id":"1.168133548","rc":[{"batb":[[1,8.2,2.52],[2,8,10]],"ltp":8.8,"tv":20.0,"id":10616006}]}]}
{"op":"mcm","clk":"991049825","pt":1580501262416,"mc":[{"id":"1.168133548","rc":[{"batb":[[0,8.2,1.98],[2,7.8,3.03]],"batl":[[0,11.5,5.23],[2,13,10]],"ltp":9.0,"tv":118.63,"id":15608820}]}]}
{"op":"mcm","clk":"991049964","pt":1580501263019,"mc":[{"id":"1.168133548","rc":[{"batb":[[0,5.6,3.97],[1,5.5,2.52],[2,5.3,3.45]],"ltp":5.7,"tv":24.02,"id":17352128}]}]}
{"op":"mcm","clk":"991052361","pt":1580501279536,"mc":[{"id":"1.168133548","rc":[{"batl":[[1,13,10],[2,18.5,1.53]],"ltp":9.0,"tv":118.63,"id":15608820}]}]}
{"op":"mcm","clk":"991052555","pt":1580501280741,"mc":[{"id":"1.168133548","rc":[{"batb":[[0,7.4,2.41],[1,7.2,2.75]],"ltp":0.0,"tv":0.0,"id":8429550}]}]}
{"op":"mcm","clk":"991052819","pt":1580501282685,"mc":[{"id":"1.168133548","rc":[{"batb":[[0,8.2,3.28],[1,8,10],[2,7.4,3]],"ltp":8.8,"tv":20.0,"id":10616006}]}]}
{"op":"mcm","clk":"991055804","pt":1580501303443,"mc":[{"id":"1.168133548","rc":[{"batb":[[0,8,1.99],[1,7.4,2.41],[2,7.2,2.75]],"ltp":0.0,"tv":0.0,"id":8429550}]}]}
{"op":"mcm","clk":"991059847","pt":1580501329296,"mc":[{"id":"1.168133548","rc":[{"batb":[[0,8.2,5.01],[2,7.6,2.52]],"ltp":9.0,"tv":118.63,"id":15608820}]}]}
{"op":"mcm","clk":"991059982","pt":1580501330209,"mc":[{"id":"1.168133548","rc":[{"batl":[[0,11.5,2.2],[1,12.5,3.8],[2,13,10]],"ltp":9.0,"tv":118.63,"id":15608820},{"batb":[[0,5.5,3.46],[1,5.4,3.96],[2,5.3,2.52]],"ltp":5.7,"tv":24.02,"id":17352128}]}]}
{"op":"mcm","clk":"991061203","pt":1580501338503,"mc":[{"id":"1.168133548","rc":[{"batl":[[1,12,3.09],[2,12.5,3.8]],"ltp":9.0,"tv":118.63,"id":15608820}]}]}
{"op":"mcm","clk":"991066124","pt":1580501372415,"mc":[{"id":"1.168133548","rc":[{"batb":[[0,8.2,1.98],[2,7.8,3.03]],"batl":[[0,11.5,5.23],[2,13,10]],"ltp":9.0,"tv":118.63,"id":15608820},{"batb":[[0,5.6,3.97],[1,5.5,2.52],[2,5.3,3.45]],"ltp":5.7,"tv":24.02,"id":17352128}]}]}
{"op":"mcm","clk":"991066692","pt":1580501376284,"mc":[{"id":"1.168133548","rc":[{"batb":[[0,8.2,1.98],[1,8,1.99],[2,7.2,3.17]],"ltp":0.0,"tv":0.0,"id":8429550}]}]}
{"op":"mcm","clk":"991067310","pt":1580501380383,"mc":[{"id":"1.168133548","rc":[{"batl":[[1,13,10],[2,18.5,1.53]],"ltp":9.0,"tv":118.63,"id":15608820}]}]}
{"op":"mcm","clk":"991068340","pt":1580501386398,"mc":[{"id":"1.168133548","rc":[{"batb":[[0,8.2,3.53]],"ltp":0.0,"tv":0.0,"id":8429550},{"batb":[[0,5.7,7.98]],"ltp":6.0,"tv":84.25,"id":9417341},{"batb":[[0,6.6,3.91]],"ltp":7.2,"tv":4.0,"id":8231803},{"batb":[[0,8.4,2.27],[1,8.2,2.52],[2,8,10]],"ltp":8.8,"tv":20.0,"id":10616006},{"batb":[[0,6.8,2.65],[1,6.6,3.03],[2,6.4,5.52]],"ltp":7.4,"tv":9.24,"id":10170404},{"batb":[[0,8.2,3.53]],"ltp":9.0,"tv":118.63,"id":15608820},{"batb":[[1,8.6,1.48],[2,8.4,1.98]],"ltp":9.0,"tv":6.0,"id":9193530},{"batb":[[0,9.8,1.8],[1,9.6,6.58],[2,7.8,5.55]],"ltp":0.0,"tv":0.0,"id":9001159},{"batb":[[0,5.7,2.23],[1,5.6,3.97],[2,5.5,2.52]],"ltp":5.7,"tv":24.02,"id":17352128}]}]}
{"op":"mcm","clk":"991071027","pt":1580501403239,"mc":[{"id":"1.168133548","rc":[{"batb":[[1,8,4.51]],"ltp":0.0,"tv":0.0,"id":8429550},{"batb":[[0,5.8,2.52],[1,5.7,7.98],[2,5.6,100.81]],"ltp":6.0,"tv":84.25,"id":9417341},{"batb":[[0,5.7,4.75]],"ltp":5.7,"tv":24.02,"id":17352128}]}]}
{"op":"mcm","clk":"991072817","pt":1580501414468,"mc":[{"id":"1.168133548","rc":[{"batb":[[0,8.4,3.03],[1,8.2,3.53],[2,8,2.52]],"batl":[[0,11.5,2.2],[1,12.5,3.8],[2,13,10]],"ltp":9.0,"tv":118.63,"id":15608820},{"batb":[[0,5.8,3.03],[1,5.7,4.75],[2,5.5,3.46]],"ltp":5.7,"tv":24.02,"id":17352128}]}]}
{"op":"mcm","clk":"991074038","pt":1580501422460,"mc":[{"id":"1.168133548","rc":[{"batl":[[1,12,3.09],[2,12.5,3.8]],"ltp":9.0,"tv":118.63,"id":15608820}]}]}
{"op":"mcm","clk":"991080014","pt":1580501460520,"mc":[{"id":"1.168133548","rc":[{"batl":[[0,11.5,5.23],[2,13,10]],"ltp":9.0,"tv":118.63,"id":15608820}]}]}
{"op":"mcm","clk":"991080261","pt":1580501462229,"mc":[{"id":"1.168133548","rc":[{"batb":[[1,8,2.52]],"ltp":0.0,"tv":0.0,"id":8429550},{"batb":[[0,8.4,5.55]],"ltp":9.0,"tv":118.63,"id":15608820}]}]}
