{"op":"mcm","clk":"996316250","pt":1580561550562,"mc":[{"id":"1.168133553","rc":[{"trd":[[1.33,3209.73]],"batl":[[0,1.33,393.3]],"ltp":1.33,"tv":15240.55,"id":16325787}],"tv":18196.62}]}
{"op":"mcm","clk":"996334803","pt":1580561596567,"mc":[{"id":"1.168133553","rc":[{"batl":[[0,1.33,993.3]],"ltp":1.33,"tv":15240.55,"id":16325787}]}]}
{"op":"mcm","clk":"996340263","pt":1580561628545,"mc":[{"id":"1.168133553","rc":[{"trd":[[1.32,5671.39]],"batb":[[0,1.32,84.54]],"ltp":1.32,"tv":15290.55,"id":16325787}],"tv":18246.62}]}
{"op":"mcm","clk":"996355805","pt":1580561722542,"mc":[{"id":"1.168133553","rc":[{"batl":[[2,1.35,1655.19]],"ltp":1.32,"tv":15290.55,"id":16325787}]}]}
{"op":"mcm","clk":"996360245","pt":1580561749520,"mc":[{"id":"1.168133553","rc":[{"trd":[[1.32,5721.39]],"batb":[[0,1.32,59.54]],"ltp":1.32,"tv":15340.55,"id":16325787}],"tv":18296.62}]}
{"op":"mcm","clk":"996362211","pt":1580561761560,"mc":[{"id":"1.168133553","rc":[{"trd":[[1.32,5801.39]],"batb":[[0,1.32,19.54]],"ltp":1.32,"tv":15420.55,"id":16325787}],"tv":18376.62}]}
{"op":"mcm","clk":"996362558","pt":1580561763561,"mc":[{"id":"1.168133553","rc":[{"trd":[[1.32,5807.45]],"batb":[[0,1.32,16.51]],"ltp":1.32,"tv":15426.61,"id":16325787}],"tv":18382.68}]}
{"op":"mcm","clk":"996362745","pt":1580561764554,"mc":[{"id":"1.168133553","rc":[{"batb":[[0,1.32,19.54]],"ltp":1.32,"tv":15426.61,"id":16325787}]}]}
{"op":"mcm","clk":"996370723","pt":1580561810479,"mc":[{"id":"1.168133553","rc":[{"trd":[[5.3,211.04]],"batb":[[0,5.3,4.37]],"ltp":5.3,"tv":2493.33,"id":21641292},{"trd":[[1.32,5846.53]],"batb":[[0,1.31,249.05],[1,1.3,225],[2,1.29,213.65]],"batl":[[0,1.32,30.46],[1,1.33,993.3],[2,1.34,1525.33]],"ltp":1.32,"tv":15465.69,"id":16325787}],"tv":18427.76}]}
{"op":"mcm","clk":"996370909","pt":1580561811453,"mc":[{"id":"1.168133553","rc":[{"batl":[[0,1.32,62.39],[1,1.33,963.37]],"ltp":1.32,"tv":15465.69,"id":16325787}]}]}
{"op":"mcm","clk":"996371080","pt":1580561812481,"mc":[{"id":"1.168133553","rc":[{"batb":[[0,5.3,22.66]],"ltp":5.3,"tv":2493.33,"id":21641292},{"batb":[[0,1.31,285.09]],"batl":[[0,1.32,32.46],[1,1.33,993.3]],"ltp":1.32,"tv":15465.69,"id":16325787}]}]}
{"op":"mcm","clk":"996371237","pt":1580561813470,"mc":[{"id":"1.168133553","rc":[{"batb":[[0,17.5,7.35]],"ltp":17.5,"tv":468.73,"id":27227336},{"batb":[[1,5.2,8.83],[2,5,2.49]],"ltp":5.3,"tv":2493.33,"id":21641292}]}]}
{"op":"mcm","clk":"996372502","pt":1580561821545,"mc":[{"id":"1.168133553","rc":[{"batb":[[1,5.2,1.42]],"ltp":5.3,"tv":2493.33,"id":21641292}]}]}
{"op":"mcm","clk":"996372757","pt":1580561823552,"mc":[{"id":"1.168133553","rc":[{"batl":[[0,18,45.59]],"ltp":17.5,"tv":468.73,"id":27227336}]}]}
{"op":"mcm","clk":"996374240","pt":1580561831485,"mc":[{"id":"1.168133553","rc":[{"batl":[[0,1.32,62.39],[1,1.33,963.37]],"ltp":1.32,"tv":15465.69,"id":16325787}]}]}
{"op":"mcm","clk":"996374431","pt":1580561832498,"mc":[{"id":"1.168133553","rc":[{"batl":[[0,1.32,32.46],[1,1.33,993.3]],"ltp":1.32,"tv":15465.69,"id":16325787}]}]}
{"op":"mcm","clk":"996377074","pt":1580561847518,"mc":[{"id":"1.168133553","rc":[{"batb":[[2,1.29,218.65]],"batl":[[0,1.32,37.46]],"ltp":1.32,"tv":15465.69,"id":16325787}]}]}
{"op":"mcm","clk":"996377766","pt":1580561851502,"mc":[{"id":"1.168133553","rc":[{"batl":[[1,1.33,963.37]],"ltp":1.32,"tv":15465.69,"id":16325787}]}]}
{"op":"mcm","clk":"996377947","pt":1580561852519,"mc":[{"id":"1.168133553","rc":[{"batl":[[1,1.33,993.3]],"ltp":1.32,"tv":15465.69,"id":16325787}]}]}
{"op":"mcm","clk":"996381448","pt":1580561872557,"mc":[{"id":"1.168133553","rc":[{"batl":[[1,1.33,963.37]],"ltp":1.32,"tv":15465.69,"id":16325787}]}]}
{"op":"mcm","clk":"996381649","pt":1580561873561,"mc":[{"id":"1.168133553","rc":[{"batl":[[1,1.33,993.3]],"ltp":1.32,"tv":15465.69,"id":16325787}]}]}
{"op":"mcm","clk":"996387401","pt":1580561905529,"mc":[{"id":"1.168133553","rc":[{"batb":[[1,1.3,276.02]],"ltp":1.32,"tv":15465.69,"id":16325787}]}]}
{"op":"mcm","clk":"996399515","pt":1580561974495,"mc":[{"id":"1.168133553","rc":[{"batl":[[0,18,41.37]],"ltp":17.5,"tv":468.73,"id":27227336}]}]}
{"op":"mcm","clk":"996403445","pt":1580561996515,"mc":[{"id":"1.168133553","rc":[{"batl":[[1,1.33,963.37]],"ltp":1.32,"tv":15465.69,"id":16325787}]}]}
{"op":"mcm","clk":"996403606","pt":1580561997482,"mc":[{"id":"1.168133553","rc":[{"batl":[[1,1.33,993.3]],"ltp":1.32,"tv":15465.69,"id":16325787}]}]}
{"op":"mcm","clk":"996407734","pt":1580562016517,"mc":[{"id":"1.168133553","rc":[{"batl":[[1,1.33,963.37]],"ltp":1.32,"tv":15465.69,"id":16325787}]}]}
{"op":"mcm","clk":"996407891","pt":1580562017504,"mc":[{"id":"1.168133553","rc":[{"batl":[[1,1.33,993.3]],"ltp":1.32,"tv":15465.69,"id":16325787}]}]}
{"op":"mcm","clk":"996415436","pt":1580562057533,"mc":[{"id":"1.168133553","rc":[{"batl":[[1,1.33,963.37]],"ltp":1.32,"tv":15465.69,"id":16325787}]}]}
{"op":"mcm","clk":"996415635","pt":1580562058528,"mc":[{"id":"1.168133553","rc":[{"batl":[[1,1.33,993.3]],"ltp":1.32,"tv":15465.69,"id":16325787}]}]}
{"op":"mcm","clk":"996419258","pt":1580562077502,"mc":[{"id":"1.168133553","rc":[{"batl":[[0,1.32,67.39],[1,1.33,963.37]],"ltp":1.32,"tv":15465.69,"id":16325787}]}]}
{"op":"mcm","clk":"996419458","pt":1580562078478,"mc":[{"id":"1.168133553","rc":[{"batl":[[0,1.32,37.46],[1,1.33,993.3]],"ltp":1.32,"tv":15465.69,"id":16325787}]}]}
{"op":"mcm","clk":"996421133","pt":1580562087492,"mc":[{"id":"1.168133553","rc":[{"trd":[[17.5,95.76]],"batb":[[0,17,1.02],[1,16.5,2.53],[2,16,11.87]],"batl":[[0,18,42.02]],"ltp":17.5,"tv":483.43,"id":27227336}],"tv":18442.45}]}
{"op":"mcm","clk":"996423132","pt":1580562098504,"mc":[{"id":"1.168133553","rc":[{"batb":[[0,1.31,315.48]],"ltp":1.32,"tv":15465.69,"id":16325787}]}]}
{"op":"mcm","clk":"996424923","pt":1580562107504,"mc":[{"id":"1.168133553","rc":[{"batb":[[0,1.31,285.09]],"ltp":1.32,"tv":15465.69,"id":16325787}]}]}
{"op":"mcm","clk":"996427093","pt":1580562119564,"mc":[{"id":"1.168133553","rc":[{"trd":[[1.32,5864.53]],"batl":[[0,1.32,26.46]],"ltp":1.32,"tv":15483.69,"id":16325787}],"tv":18460.45}]}
{"op":"mcm","clk":"996431151","pt":1580562140473,"mc":[{"id":"1.168133553","rc":[{"batb":[[0,1.31,315.48]],"batl":[[1,1.33,963.37]],"ltp":1.32,"tv":15483.69,"id":16325787}]}]}
{"op":"mcm","clk":"996431344","pt":1580562141566,"mc":[{"id":"1.168133553","rc":[{"batl":[[1,1.33,993.3]],"ltp":1.32,"tv":15483.69,"id":16325787}]}]}
{"op":"mcm","clk":"996431499","pt":1580562142548,"mc":[{"id":"1.168133553","rc":[{"trd":[[17,28.18]],"batb":[[0,16.5,2.53],[1,16,11.87],[2,15,1.45]],"batl":[[0,17.5,1.58],[1,18,41.37],[2,18.5,3.54]],"ltp":17.0,"tv":487.52,"id":27227336},{"trd":[[5.4,398.57]],"batl":[[0,5.4,4.5]],"ltp":5.4,"tv":2499.79,"id":21641292},{"trd":[[1.32,5890.99]],"batl":[[0,1.33,993.3],[1,1.34,1525.33],[2,1.35,1655.19]],"ltp":1.32,"tv":15510.15,"id":16325787}],"tv":18497.47}]}
{"op":"mcm","clk":"996431664","pt":1580562143559,"mc":[{"id":"1.168133553","rc":[{"trd":[[16.5,10.53]],"batb":[[0,16,12.48],[1,15,1.45],[2,13.5,19.01]],"batl":[[2,18.5,2.53]],"ltp":16.5,"tv":495.51,"id":27227336},{"batb":[[0,1.32,13.05],[1,1.31,315.48],[2,1.3,276.02]],"ltp":1.32,"tv":15510.15,"id":16325787}],"tv":18505.46}]}
{"op":"mcm","clk":"996432340","pt":1580562147478,"mc":[{"id":"1.168133553","rc":[{"batb":[[2,12.5,30.49]],"ltp":16.5,"tv":495.51,"id":27227336}]}]}
{"op":"mcm","clk":"996432975","pt":1580562150495,"mc":[{"id":"1.168133553","rc":[{"batb":[[1,1.31,285.09]],"ltp":1.32,"tv":15510.15,"id":16325787}]}]}
{"op":"mcm","clk":"996434038","pt":1580562155369,"mc":[{"id":"1.168133553","rc":[{"batl":[[0,17.5,15.58]],"ltp":16.5,"tv":495.51,"id":27227336}]}]}
{"op":"mcm","clk":"996435718","pt":1580562164254,"mc":[{"id":"1.168133553","rc":[{"batl":[[0,17.5,16.58]],"ltp":16.5,"tv":495.51,"id":27227336}]}]}
{"op":"mcm","clk":"996435961","pt":1580562165574,"mc":[{"id":"1.168133553","rc":[{"batl":[[0,17.5,19.11],[2,19,50]],"ltp":16.5,"tv":495.51,"id":27227336}]}]}
{"op":"mcm","clk":"996437640","pt":1580562174487,"mc":[{"id":"1.168133553","rc":[{"batb":[[2,13,2.54]],"ltp":16.5,"tv":495.51,"id":27227336}]}]}
{"op":"mcm","clk":"996438336","pt":1580562178196,"mc":[{"id":"1.168133553","rc":[{"batb":[[2,12.5,30.52]],"ltp":16.5,"tv":495.51,"id":27227336}]}]}
{"op":"mcm","clk":"996445110","pt":1580562213536,"mc":[{"id":"1.168133553","rc":[{"trd":[[16.5,10.63]],"batb":[[0,16,12.43]],"ltp":16.5,"tv":495.61,"id":27227336}],"tv":18505.56}]}
{"op":"mcm","clk":"996445282","pt":1580562214521,"mc":[{"id":"1.168133553","rc":[{"batb":[[0,16,12.45],[2,12.5,30.49]],"ltp":16.5,"tv":495.61,"id":27227336}]}]}
{"op":"mcm","clk":"996448799","pt":1580562232487,"mc":[{"id":"1.168133553","rc":[{"batb":[[0,16,12.43],[2,12.5,30.52]],"ltp":16.5,"tv":495.61,"id":27227336}]}]}
{"op":"mcm","clk":"996455137","pt":1580562261560,"mc":[{"id":"1.168133553","rc":[{"batb":[[0,16,12.45],[2,12.5,30.49]],"ltp":16.5,"tv":495.61,"id":27227336}]}]}
{"op":"mcm","clk":"996462188","pt":1580562294542,"mc":[{"id":"1.168133553","rc":[{"batb":[[0,16,12.43]],"ltp":16.5,"tv":495.61,"id":27227336}]}]}
{"op":"mcm","clk":"996467848","pt":1580562320545,"mc":[{"id":"1.168133553","rc":[{"batb":[[0,16,14.96]],"ltp":16.5,"tv":495.61,"id":27227336}]}]}
{"op":"mcm","clk":"996473256","pt":1580562345518,"mc":[{"id":"1.168133553","rc":[{"batb":[[0,16,12.43],[2,13,2.54]],"ltp":16.5,"tv":495.61,"id":27227336}]}]}
{"op":"mcm","clk":"996478405","pt":1580562369493,"mc":[{"id":"1.168133553","rc":[{"trd":[[5.3,215.06]],"batb":[[0,5.3,20.65]],"ltp":5.3,"tv":2503.82,"id":21641292}],"tv":18509.59}]}
{"op":"mcm","clk":"996478812","pt":1580562371515,"mc":[{"id":"1.168133553","rc":[{"batb":[[0,16,14.96],[2,12.5,30.49]],"ltp":16.5,"tv":495.61,"id":27227336}]}]}
{"op":"mcm","clk":"996480510","pt":1580562379571,"mc":[{"id":"1.168133553","rc":[{"batb":[[0,16,12.43],[2,13,2.54]],"ltp":16.5,"tv":495.61,"id":27227336}]}]}
{"op":"mcm","clk":"996482265","pt":1580562387490,"mc":[{"id":"1.168133553","rc":[{"batb":[[2,12.5,30.49]],"ltp":16.5,"tv":495.61,"id":27227336}]}]}
{"op":"mcm","clk":"996483079","pt":1580562391483,"mc":[{"id":"1.168133553","rc":[{"trd":[[16,2.88],[16.5,11.75]],"batb":[[0,16,10.43]],"ltp":16.0,"tv":499.61,"id":27227336}],"tv":18513.59}]}
{"op":"mcm","clk":"996484131","pt":1580562396504,"mc":[{"id":"1.168133553","rc":[{"batl":[[0,17,2.93],[1,17.5,18.18],[2,18,41.37]],"ltp":16.0,"tv":499.61,"id":27227336}]}]}
{"op":"mcm","clk":"996484361","pt":1580562397571,"mc":[{"id":"1.168133553","rc":[{"batl":[[0,17,8.6]],"ltp":16.0,"tv":499.61,"id":27227336},{"batb":[[1,1.31,315.48]],"ltp":1.32,"tv":15510.15,"id":16325787}]}]}
{"op":"mcm","clk":"996485475","pt":1580562402484,"mc":[{"id":"1.168133553","rc":[{"batb":[[2,14,1.01]],"ltp":16.0,"tv":499.61,"id":27227336}]}]}
{"op":"mcm","clk":"996487614","pt":1580562412514,"mc":[{"id":"1.168133553","rc":[{"batb":[[1,15.5,2.53],[2,15,1.45]],"ltp":16.0,"tv":499.61,"id":27227336}]}]}
{"op":"mcm","clk":"996510598","pt":1580562466404,"mc":[{"id":"1.168133553","rc":[{"trd":[[5.3,225.06]],"batb":[[0,5.3,15.65]],"ltp":5.3,"tv":2513.81,"id":21641292}],"tv":18523.58}]}
{"op":"mcm","clk":"996511358","pt":1580562470536,"mc":[{"id":"1.168133553","rc":[{"batb":[[1,15,1.45],[2,14,1.01]],"ltp":16.0,"tv":499.61,"id":27227336}]}]}
{"op":"mcm","clk":"996516501","pt":1580562494536,"mc":[{"id":"1.168133553","rc":[{"batb":[[1,1.31,285.09]],"ltp":1.32,"tv":15510.15,"id":16325787}]}]}
{"op":"mcm","clk":"996516895","pt":1580562496549,"mc":[{"id":"1.168133553","rc":[{"batb":[[1,15.5,2.53],[2,15,1.45]],"ltp":16.0,"tv":499.61,"id":27227336}]}]}
{"op":"mcm","clk":"996518606","pt":1580562504559,"mc":[{"id":"1.168133553","rc":[{"batb":[[0,16.5,1.04],[1,16,10.43],[2,15.5,2.53]],"ltp":16.0,"tv":499.61,"id":27227336}]}]}
{"op":"mcm","clk":"996519224","pt":1580562507361,"mc":[{"id":"1.168133553","rc":[{"trd":[[1.32,5894.99]],"batb":[[0,1.32,11.05]],"ltp":1.32,"tv":15514.15,"id":16325787}],"tv":18527.58}]}
{"op":"mcm","clk":"996519485","pt":1580562508570,"mc":[{"id":"1.168133553","rc":[{"batb":[[0,1.32,13.05]],"ltp":1.32,"tv":15514.15,"id":16325787}]}]}
{"op":"mcm","clk":"996521872","pt":1580562519516,"mc":[{"id":"1.168133553","rc":[{"batb":[[1,16,12.96],[2,15,1.45]],"ltp":16.0,"tv":499.61,"id":27227336},{"trd":[[5.3,229.06]],"batb":[[0,5.3,13.65]],"ltp":5.3,"tv":2517.81,"id":21641292},{"trd":[[1.32,5900.99]],"batb":[[0,1.32,10.05]],"ltp":1.32,"tv":15520.15,"id":16325787}],"tv":18537.58}]}
{"op":"mcm","clk":"996523848","pt":1580562528521,"mc":[{"id":"1.168133553","rc":[{"batb":[[1,16,10.43],[2,15.5,2.53]],"ltp":16.0,"tv":499.61,"id":27227336}]}]}
{"op":"mcm","clk":"996526682","pt":1580562541346,"mc":[{"id":"1.168133553","rc":[{"trd":[[5.3,230.78]],"batb":[[0,5.3,12.79]],"ltp":5.3,"tv":2519.53,"id":21641292}],"tv":18539.3}]}
{"op":"mcm","clk":"996526967","pt":1580562542545,"mc":[{"id":"1.168133553","rc":[{"trd":[[5.3,230.82]],"batb":[[0,5.3,12.77]],"ltp":5.3,"tv":2519.57,"id":21641292}],"tv":18539.34}]}
{"op":"mcm","clk":"996528017","pt":1580562547562,"mc":[{"id":"1.168133553","rc":[{"trd":[[5.3,255.13]],"batb":[[0,5.2,2.04],[1,5,2.49],[2,4.7,10]],"ltp":5.3,"tv":2543.88,"id":21641292}],"tv":18563.65}]}
{"op":"mcm","clk":"996528213","pt":1580562548562,"mc":[{"id":"1.168133553","rc":[{"batl":[[0,1.33,963.37]],"ltp":1.32,"tv":15520.15,"id":16325787}]}]}
{"op":"mcm","clk":"996528419","pt":1580562549571,"mc":[{"id":"1.168133553","rc":[{"batl":[[1,1.34,1555.26]],"ltp":1.32,"tv":15520.15,"id":16325787}]}]}
{"op":"mcm","clk":"996529105","pt":1580562552468,"mc":[{"id":"1.168133553","rc":[{"batb":[[2,15,1.45]],"ltp":16.0,"tv":499.61,"id":27227336}]}]}
{"op":"mcm","clk":"996529306","pt":1580562553365,"mc":[{"id":"1.168133553","rc":[{"batb":[[0,16.5,3.57]],"ltp":16.0,"tv":499.61,"id":27227336}]}]}
{"op":"mcm","clk":"996531055","pt":1580562561408,"mc":[{"id":"1.168133553","rc":[{"batl":[[1,1.34,1555.04]],"ltp":1.32,"tv":15520.15,"id":16325787}]}]}
{"op":"mcm","clk":"996539279","pt":1580562600824,"mc":[{"id":"1.168133553","rc":[{"batl":[[0,5.4,4.56]],"ltp":5.3,"tv":2543.88,"id":21641292}]}]}
{"op":"mcm","clk":"996539862","pt":1580562603457,"mc":[{"id":"1.168133553","rc":[{"trd":[[17,28.95]],"batl":[[0,17,7.83]],"ltp":17.0,"tv":500.38,"id":27227336},{"trd":[[5.4,401]],"batl":[[0,5.4,2.36]],"ltp":5.4,"tv":2546.31,"id":21641292},{"trd":[[1.32,5931.04]],"batb":[[0,1.31,285.09],[1,1.3,276.02],[2,1.29,218.65]],"ltp":1.32,"tv":15550.2,"id":16325787}],"tv":18596.89}]}
{"op":"mcm","clk":"996540759","pt":1580562607467,"mc":[{"id":"1.168133553","rc":[{"batb":[[1,5.1,7.4],[2,5,2.49]],"batl":[[0,5.4,15.08]],"ltp":5.4,"tv":2546.31,"id":21641292},{"batb":[[1,1.3,305.07]],"ltp":1.32,"tv":15550.2,"id":16325787}]}]}
{"op":"mcm","clk":"996540969","pt":1580562608483,"mc":[{"id":"1.168133553","rc":[{"batb":[[0,16.5,3.95],[1,16,12.96]],"ltp":17.0,"tv":500.38,"id":27227336},{"batb":[[1,5.1,14.81]],"ltp":5.4,"tv":2546.31,"id":21641292},{"batb":[[0,1.32,30.39],[1,1.31,285.09],[2,1.3,305.07]],"batl":[[0,1.33,993.08],[1,1.34,1525.33]],"ltp":1.32,"tv":15550.2,"id":16325787}]}]}
{"op":"mcm","clk":"996541214","pt":1580562609553,"mc":[{"id":"1.168133553","rc":[{"batl":[[1,17.5,15.65],[2,18,43.9]],"ltp":17.0,"tv":500.38,"id":27227336},{"batl":[[0,1.33,963.37],[1,1.34,1555.04]],"ltp":1.32,"tv":15550.2,"id":16325787}]}]}
{"op":"mcm","clk":"996543033","pt":1580562617538,"mc":[{"id":"1.168133553","rc":[{"batb":[[0,1.31,315.48],[1,1.3,305.07],[2,1.29,218.65]],"ltp":1.32,"tv":15550.2,"id":16325787}]}]}
{"op":"mcm","clk":"996545228","pt":1580562627569,"mc":[{"id":"1.168133553","rc":[{"batl":[[0,1.33,993.08],[1,1.34,1525.33]],"ltp":1.32,"tv":15550.2,"id":16325787}]}]}
{"op":"mcm","clk":"996545443","pt":1580562628567,"mc":[{"id":"1.168133553","rc":[{"batl":[[1,17.5,18.18],[2,18,41.37]],"ltp":17.0,"tv":500.38,"id":27227336}]}]}
{"op":"mcm","clk":"996548803","pt":1580562644517,"mc":[{"id":"1.168133553","rc":[{"trd":[[16.5,17.75]],"batb":[[0,16,13.91],[1,15,1.45],[2,14,1.01]],"ltp":16.5,"tv":506.38,"id":27227336},{"batl":[[0,1.33,993.3]],"ltp":1.32,"tv":15550.2,"id":16325787}],"tv":18602.9}]}
{"op":"mcm","clk":"996549876","pt":1580562649534,"mc":[{"id":"1.168133553","rc":[{"trd":[[16,25],[16.5,19.63]],"batb":[[0,16,1.9]],"ltp":16.0,"tv":530.38,"id":27227336}],"tv":18626.9}]}
{"op":"mcm","clk":"996550104","pt":1580562650512,"mc":[{"id":"1.168133553","rc":[{"batb":[[0,15,1.45],[1,14,1.01],[2,13.5,2.9]],"batl":[[1,17.5,18.61]],"ltp":16.0,"tv":530.38,"id":27227336},{"batb":[[0,5.2,9.45],[1,5.1,7.4]],"ltp":5.4,"tv":2546.31,"id":21641292},{"batl":[[0,1.33,963.37]],"ltp":1.32,"tv":15550.2,"id":16325787}]}]}
{"op":"mcm","clk":"996551028","pt":1580562654563,"mc":[{"id":"1.168133553","rc":[{"batb":[[1,14,5.02]],"ltp":16.0,"tv":530.38,"id":27227336}]}]}
{"op":"mcm","clk":"996552083","pt":1580562659567,"mc":[{"id":"1.168133553","rc":[{"batb":[[2,13.5,1]],"ltp":16.0,"tv":530.38,"id":27227336}]}]}
{"op":"mcm","clk":"996554005","pt":1580562668492,"mc":[{"id":"1.168133553","rc":[{"batl":[[1,1.34,1555.04]],"ltp":1.32,"tv":15550.2,"id":16325787}]}]}
{"op":"mcm","clk":"996557640","pt":1580562685535,"mc":[{"id":"1.168133553","rc":[{"trd":[[5.4,431.15]],"batb":[[0,5.4,7.92],[1,5.2,9.45],[2,5.1,7.4]],"batl":[[0,5.5,17.71],[1,5.6,10],[2,5.7,10]],"ltp":5.4,"tv":2576.46,"id":21641292}],"tv":18657.06}]}
{"op":"mcm","clk":"996557835","pt":1580562686526,"mc":[{"id":"1.168133553","rc":[{"batl":[[0,1.33,993.08],[1,1.34,1525.33]],"ltp":1.32,"tv":15550.2,"id":16325787}]}]}
{"op":"mcm","clk":"996558062","pt":1580562687521,"mc":[{"id":"1.168133553","rc":[{"batl":[[2,5.7,17.18]],"ltp":5.4,"tv":2576.46,"id":21641292},{"batl":[[2,1.35,1678.76]],"ltp":1.32,"tv":15550.2,"id":16325787}]}]}
{"op":"mcm","clk":"996558290","pt":1580562688524,"mc":[{"id":"1.168133553","rc":[{"batb":[[1,14,1.01],[2,13.5,5.01]],"ltp":16.0,"tv":530.38,"id":27227336},{"batb":[[1,5.2,16.63]],"ltp":5.4,"tv":2576.46,"id":21641292},{"batb":[[0,1.31,341.57],[2,1.29,245.56]],"ltp":1.32,"tv":15550.2,"id":16325787}]}]}
{"op":"mcm","clk":"996558516","pt":1580562689498,"mc":[{"id":"1.168133553","rc":[{"batl":[[0,16.5,3.4],[1,17,7.83],[2,17.5,18.61]],"ltp":16.0,"tv":530.38,"id":27227336},{"trd":[[5.4,446.99]],"batb":[[0,5.2,16.63],[1,5.1,7.4],[2,5,10.14]],"batl":[[0,5.4,12.08],[1,5.5,17.71],[2,5.6,10]],"ltp":5.4,"tv":2592.3,"id":21641292}],"tv":18672.9}]}
{"op":"mcm","clk":"996559381","pt":1580562693506,"mc":[{"id":"1.168133553","rc":[{"batb":[[0,5.3,20.62],[1,5.2,16.01],[2,5.1,7.4]],"ltp":5.4,"tv":2592.3,"id":21641292}]}]}
{"op":"mcm","clk":"996559826","pt":1580562695564,"mc":[{"id":"1.168133553","rc":[{"batb":[[1,5.2,8.6]],"ltp":5.4,"tv":2592.3,"id":21641292}]}]}
{"op":"mcm","clk":"996560289","pt":1580562697559,"mc":[{"id":"1.168133553","rc":[{"batl":[[2,17.5,4.61]],"ltp":16.0,"tv":530.38,"id":27227336}]}]}
{"op":"mcm","clk":"996560506","pt":1580562698544,"mc":[{"id":"1.168133553","rc":[{"trd":[[5.3,263.12]],"batb":[[0,5.3,16.62]],"ltp":5.3,"tv":2600.3,"id":21641292},{"trd":[[1.33,3229.73]],"batl":[[0,1.33,983.08]],"ltp":1.33,"tv":15570.2,"id":16325787}],"tv":18700.89}]}
{"op":"mcm","clk":"996560943","pt":1580562700391,"mc":[{"id":"1.168133553","rc":[{"batb":[[2,5.1,10]],"ltp":5.3,"tv":2600.3,"id":21641292}]}]}
{"op":"mcm","clk":"996561634","pt":1580562703569,"mc":[{"id":"1.168133553","rc":[{"batl":[[0,1.33,983.3]],"ltp":1.33,"tv":15570.2,"id":16325787}]}]}
{"op":"mcm","clk":"996564272","pt":1580562715562,"mc":[{"id":"1.168133553","rc":[{"batl":[[1,17,9.83]],"ltp":16.0,"tv":530.38,"id":27227336},{"batb":[[0,5.3,22.62],[1,5.2,14.6]],"batl":[[1,5.5,22.71]],"ltp":5.3,"tv":2600.3,"id":21641292},{"batb":[[0,1.32,24.28],[1,1.31,366.57],[2,1.3,305.07]],"batl":[[1,1.34,1544.33],[2,1.35,1697.76]],"ltp":1.33,"tv":15570.2,"id":16325787}]}]}
{"op":"mcm","clk":"996564651","pt":1580562717440,"mc":[{"id":"1.168133553","rc":[{"batb":[[2,5.1,18]],"batl":[[2,5.6,16]],"ltp":5.3,"tv":2600.3,"id":21641292}]}]}
{"op":"mcm","clk":"996564879","pt":1580562718561,"mc":[{"id":"1.168133553","rc":[{"batl":[[0,1.33,953.37],[1,1.34,1574.04]],"ltp":1.33,"tv":15570.2,"id":16325787}]}]}
{"op":"mcm","clk":"996565008","pt":1580562719171,"mc":[{"id":"1.168133553","rc":[{"batb":[[2,13.5,6.91]],"ltp":16.0,"tv":530.38,"id":27227336},{"batl":[[0,1.33,975.37]],"ltp":1.33,"tv":15570.2,"id":16325787}]}]}
{"op":"mcm","clk":"996565689","pt":1580562722531,"mc":[{"id":"1.168133553","rc":[{"trd":[[5.3,264.16]],"batb":[[0,5.3,22.1]],"ltp":5.3,"tv":2601.34,"id":21641292},{"trd":[[1.32,5936.22]],"batb":[[0,1.32,21.69]],"ltp":1.32,"tv":15575.38,"id":16325787}],"tv":18707.11}]}
{"op":"mcm","clk":"996565886","pt":1580562723428,"mc":[{"id":"1.168133553","rc":[{"batb":[[0,5.3,25.1],[1,5.2,18.6]],"ltp":5.3,"tv":2601.34,"id":21641292},{"batb":[[0,1.32,36],[1,1.31,377.57],[2,1.3,342.07]],"batl":[[1,1.34,1584.04],[2,1.35,1707.76]],"ltp":1.32,"tv":15575.38,"id":16325787}]}]}
{"op":"mcm","clk":"996566126","pt":1580562724524,"mc":[{"id":"1.168133553","rc":[{"trd":[[15.5,26.07]],"batl":[[0,15.5,26.35],[1,16,3.02],[2,16.5,6.4]],"ltp":15.5,"tv":534.59,"id":27227336},{"trd":[[5.4,459.07]],"batl":[[0,5.5,17.71],[1,5.6,16],[2,5.7,17.18]],"ltp":5.4,"tv":2613.42,"id":21641292},{"trd":[[1.33,3278.78]],"batl":[[0,1.33,904.32]],"ltp":1.33,"tv":15624.43,"id":16325787}],"tv":18772.45}]}
{"op":"mcm","clk":"996566319","pt":1580562725504,"mc":[{"id":"1.168133553","rc":[{"trd":[[15.5,27.69]],"batl":[[0,15.5,24.73]],"ltp":15.5,"tv":536.21,"id":27227336},{"trd":[[5.5,254.09]],"batb":[[0,5.3,32.17]],"batl":[[0,5.5,13.15]],"ltp":5.5,"tv":2617.98,"id":21641292},{"trd":[[1.32,6027.22]],"batb":[[0,1.32,35]],"ltp":1.32,"tv":15715.43,"id":16325787}],"tv":18869.63}]}
{"op":"mcm","clk":"996566559","pt":1580562726533,"mc":[{"id":"1.168133553","rc":[{"batl":[[1,16,6.26],[2,16.5,10.78]],"ltp":15.5,"tv":536.21,"id":27227336},{"batl":[[2,5.7,21.87]],"ltp":5.5,"tv":2617.98,"id":21641292},{"batl":[[1,1.34,1599.61]],"ltp":1.32,"tv":15715.43,"id":16325787}]}]}
{"op":"mcm","clk":"996566741","pt":1580562727324,"mc":[{"id":"1.168133553","rc":[{"batb":[[2,13.5,11.18]],"ltp":15.5,"tv":536.21,"id":27227336},{"batb":[[0,5.4,12.03],[1,5.3,36.98],[2,5.2,18.6]],"ltp":5.5,"tv":2617.98,"id":21641292},{"batb":[[1,1.31,394.98]],"ltp":1.32,"tv":15715.43,"id":16325787}]}]}
{"op":"mcm","clk":"996566969","pt":1580562728435,"mc":[{"id":"1.168133553","rc":[{"batb":[[2,13.5,9.27]],"ltp":15.5,"tv":536.21,"id":27227336},{"trd":[[5.5,260.73]],"batl":[[0,5.5,9.83]],"ltp":5.5,"tv":2624.62,"id":21641292},{"batb":[[0,1.32,48.84]],"ltp":1.32,"tv":15715.43,"id":16325787}],"tv":18876.27}]}
{"op":"mcm","clk":"996567567","pt":1580562731038,"mc":[{"id":"1.168133553","rc":[{"batb":[[2,5.2,23.4]],"ltp":5.5,"tv":2624.62,"id":21641292},{"batb":[[1,1.31,460.02]],"ltp":1.32,"tv":15715.43,"id":16325787}]}]}
{"op":"mcm","clk":"996567865","pt":1580562732455,"mc":[{"id":"1.168133553","rc":[{"trd":[[5.5,280.39]],"batb":[[1,5.3,41.67]],"batl":[[0,5.6,16],[1,5.7,21.87],[2,5.8,10]],"ltp":5.5,"tv":2644.28,"id":21641292}],"tv":18895.93}]}
{"op":"mcm","clk":"996568010","pt":1580562733327,"mc":[{"id":"1.168133553","rc":[{"batb":[[1,5.3,45.67]],"batl":[[0,5.6,10],[1,5.7,31.63]],"ltp":5.5,"tv":2644.28,"id":21641292},{"batl":[[0,1.33,945.32],[1,1.34,1611.61],[2,1.35,1718.76]],"ltp":1.32,"tv":15715.43,"id":16325787}]}]}
{"op":"mcm","clk":"996568214","pt":1580562734523,"mc":[{"id":"1.168133553","rc":[{"batb":[[2,13.5,13.03]],"ltp":15.5,"tv":536.21,"id":27227336},{"batl":[[1,5.7,25.18]],"ltp":5.5,"tv":2644.28,"id":21641292}]}]}
{"op":"mcm","clk":"996568395","pt":1580562735486,"mc":[{"id":"1.168133553","rc":[{"trd":[[15,20.18]],"batb":[[0,15,5],[1,14.5,5.08],[2,14,6.07]],"ltp":15.0,"tv":539.11,"id":27227336},{"batl":[[0,1.33,946.32]],"ltp":1.32,"tv":15715.43,"id":16325787}],"tv":18898.83}]}
{"op":"mcm","clk":"996568595","pt":1580562736539,"mc":[{"id":"1.168133553","rc":[{"batb":[[0,14.5,5.08],[1,14,6.07],[2,13.5,9.27]],"batl":[[0,15.5,27.73]],"ltp":15.0,"tv":539.11,"id":27227336}]}]}
{"op":"mcm","clk":"996568760","pt":1580562737528,"mc":[{"id":"1.168133553","rc":[{"batl":[[0,1.33,976.03],[1,1.34,1581.89]],"ltp":1.32,"tv":15715.43,"id":16325787}]}]}
{"op":"mcm","clk":"996568979","pt":1580562738534,"mc":[{"id":"1.168133553","rc":[{"batl":[[0,15.5,31.91]],"ltp":15.0,"tv":539.11,"id":27227336}]}]}
{"op":"mcm","clk":"996569722","pt":1580562742529,"mc":[{"id":"1.168133553","rc":[{"trd":[[5.4,461.11]],"batb":[[0,5.4,11.01]],"ltp":5.4,"tv":2646.32,"id":21641292}],"tv":18900.87}]}
{"op":"mcm","clk":"996571722","pt":1580562752516,"mc":[{"id":"1.168133553","rc":[{"batb":[[1,14,7.97],[2,13.5,5.27]],"batl":[[2,16.5,7.38]],"ltp":15.0,"tv":539.11,"id":27227336}]}]}
{"op":"mcm","clk":"996572093","pt":1580562754541,"mc":[{"id":"1.168133553","rc":[{"trd":[[5.4,467.11]],"batb":[[0,5.4,8.01]],"ltp":5.4,"tv":2652.32,"id":21641292},{"batl":[[0,1.33,976.25]],"ltp":1.32,"tv":15715.43,"id":16325787}],"tv":18906.87}]}
{"op":"mcm","clk":"996573079","pt":1580562759560,"mc":[{"id":"1.168133553","rc":[{"trd":[[15.5,31.3]],"batl":[[0,15.5,28.3]],"ltp":15.5,"tv":542.72,"id":27227336},{"trd":[[5.6,90.29]],"batb":[[0,5.5,4.72],[1,5.4,13],[2,5.3,45.67]],"batl":[[0,5.7,17.18],[1,5.8,18],[2,5.9,49.92]],"ltp":5.6,"tv":2662.32,"id":21641292},{"trd":[[1.32,6251.33]],"batb":[[0,1.31,460.02],[1,1.3,342.07],[2,1.29,300.13]],"batl":[[0,1.32,286.83],[1,1.33,976.25],[2,1.34,1581.89]],"ltp":1.32,"tv":15939.54,"id":16325787}],"tv":19144.59}]}
{"op":"mcm","clk":"996573270","pt":1580562760558,"mc":[{"id":"1.168133553","rc":[{"batl":[[1,16,3.02],[2,16.5,10.52]],"ltp":15.5,"tv":542.72,"id":27227336},{"batb":[[0,5.5,19.94],[1,5.4,27.72],[2,5.3,38.6]],"ltp":5.6,"tv":2662.32,"id":21641292},{"batb":[[0,1.31,364.58]],"ltp":1.32,"tv":15939.54,"id":16325787}]}]}
{"op":"mcm","clk":"996573496","pt":1580562761565,"mc":[{"id":"1.168133553","rc":[{"batb":[[0,1.31,347.18],[1,1.3,409.29]],"ltp":1.32,"tv":15939.54,"id":16325787}]}]}
{"op":"mcm","clk":"996573913","pt":1580562763523,"mc":[{"id":"1.168133553","rc":[{"batl":[[0,5.7,12]],"ltp":5.6,"tv":2662.32,"id":21641292},{"batb":[[0,1.31,321.09]],"ltp":1.32,"tv":15939.54,"id":16325787}]}]}
{"op":"mcm","clk":"996574769","pt":1580562767543,"mc":[{"id":"1.168133553","rc":[{"batl":[[0,15.5,18.3]],"ltp":15.5,"tv":542.72,"id":27227336},{"batb":[[0,5.5,24.42]],"ltp":5.6,"tv":2662.32,"id":21641292}]}]}
{"op":"mcm","clk":"996574959","pt":1580562768567,"mc":[{"id":"1.168133553","rc":[{"batl":[[0,15.5,14.12]],"ltp":15.5,"tv":542.72,"id":27227336}]}]}
{"op":"mcm","clk":"996575148","pt":1580562769444,"mc":[{"id":"1.168133553","rc":[{"batb":[[1,5.4,20.65]],"ltp":5.6,"tv":2662.32,"id":21641292}]}]}
{"op":"mcm","clk":"996575531","pt":1580562771563,"mc":[{"id":"1.168133553","rc":[{"batl":[[2,16.5,7.38]],"ltp":15.5,"tv":542.72,"id":27227336}]}]}
{"op":"mcm","clk":"996575905","pt":1580562773568,"mc":[{"id":"1.168133553","rc":[{"batl":[[0,1.32,317],[1,1.33,946.32]],"ltp":1.32,"tv":15939.54,"id":16325787}]}]}
{"op":"mcm","clk":"996577947","pt":1580562784564,"mc":[{"id":"1.168133553","rc":[{"trd":[[14.5,26.5]],"batb":[[0,14,7.97],[1,13.5,5.27],[2,13,1]],"ltp":14.5,"tv":553.1,"id":27227336},{"trd":[[5.7,200.33]],"batl":[[0,5.7,11.44]],"ltp":5.7,"tv":2662.88,"id":21641292},{"trd":[[1.32,6290.88]],"batl":[[0,1.32,296.01]],"ltp":1.32,"tv":15979.09,"id":16325787}],"tv":19195.09}]}
{"op":"mcm","clk":"996578130","pt":1580562785571,"mc":[{"id":"1.168133553","rc":[{"batb":[[0,15,5],[1,14.5,5],[2,14,7.97]],"batl":[[0,15.5,11.12]],"ltp":14.5,"tv":553.1,"id":27227336}]}]}
{"op":"mcm","clk":"996578330","pt":1580562786561,"mc":[{"id":"1.168133553","rc":[{"batb":[[0,14.5,5],[1,14,6.07],[2,13.5,7.17]],"batl":[[0,15.5,14.12]],"ltp":14.5,"tv":553.1,"id":27227336},{"batl":[[0,1.32,265.85],[1,1.33,976.48]],"ltp":1.32,"tv":15979.09,"id":16325787}]}]}
{"op":"mcm","clk":"996578579","pt":1580562787556,"mc":[{"id":"1.168133553","rc":[{"batb":[[0,15,5],[1,14.5,5],[2,14,6.07]],"batl":[[0,15.5,11.12]],"ltp":14.5,"tv":553.1,"id":27227336}]}]}
{"op":"mcm","clk":"996578770","pt":1580562788554,"mc":[{"id":"1.168133553","rc":[{"batb":[[1,14.5,9.51]],"ltp":14.5,"tv":553.1,"id":27227336}]}]}
{"op":"mcm","clk":"996578972","pt":1580562789549,"mc":[{"id":"1.168133553","rc":[{"batb":[[0,14.5,9.51],[1,14,6.07],[2,13.5,7.17]],"batl":[[0,15,3.18],[1,15.5,11.12],[2,16,3.02]],"ltp":14.5,"tv":553.1,"id":27227336}]}]}
{"op":"mcm","clk":"996579160","pt":1580562790549,"mc":[{"id":"1.168133553","rc":[{"trd":[[15,25.95]],"batb":[[0,14.5,5],[1,14,9.3]],"batl":[[0,15.5,14.42],[1,16,3.02],[2,16.5,7.38]],"ltp":15.0,"tv":558.87,"id":27227336},{"trd":[[5.7,209.11]],"batl":[[0,5.7,7.05]],"ltp":5.7,"tv":2671.66,"id":21641292},{"batb":[[0,1.31,340.19]],"ltp":1.32,"tv":15979.09,"id":16325787}],"tv":19209.63}]}
{"op":"mcm","clk":"996579532","pt":1580562792574,"mc":[{"id":"1.168133553","rc":[{"batb":[[1,14,6.07]],"batl":[[1,16,5.29]],"ltp":15.0,"tv":558.87,"id":27227336}]}]}
{"op":"mcm","clk":"996579881","pt":1580562794558,"mc":[{"id":"1.168133553","rc":[{"trd":[[1.31,3301.08]],"batb":[[0,1.31,74.34],[2,1.29,305.13]],"batl":[[0,1.32,5]],"ltp":1.31,"tv":16510.79,"id":16325787}],"tv":19741.33}]}
{"op":"mcm","clk":"996580056","pt":1580562795553,"mc":[{"id":"1.168133553","rc":[{"trd":[[15,26.54]],"batb":[[0,14.5,7.65]],"batl":[[0,15.5,11.12]],"ltp":15.0,"tv":559.47,"id":27227336},{"batb":[[0,5.6,5.44],[1,5.5,19.94],[2,5.4,25.23]],"batl":[[2,5.9,57.92]],"ltp":5.7,"tv":2671.66,"id":21641292},{"batl":[[0,1.32,7]],"ltp":1.31,"tv":16510.79,"id":16325787}],"tv":19741.93}]}
{"op":"mcm","clk":"996580269","pt":1580562796567,"mc":[{"id":"1.168133553","rc":[{"batb":[[2,5.4,29.12]],"batl":[[0,5.7,14.98]],"ltp":5.7,"tv":2671.66,"id":21641292},{"batb":[[0,1.31,91.74]],"ltp":1.31,"tv":16510.79,"id":16325787}]}]}
{"op":"mcm","clk":"996580473","pt":1580562797475,"mc":[{"id":"1.168133553","rc":[{"batl":[[1,16,3.02]],"ltp":15.0,"tv":559.47,"id":27227336}]}]}
{"op":"mcm","clk":"996580697","pt":1580562798556,"mc":[{"id":"1.168133553","rc":[{"batl":[[1,1.33,976.25]],"ltp":1.31,"tv":16510.79,"id":16325787}]}]}
{"op":"mcm","clk":"996581290","pt":1580562801534,"mc":[{"id":"1.168133553","rc":[{"batl":[[0,1.32,9]],"ltp":1.31,"tv":16510.79,"id":16325787}]}]}
{"op":"mcm","clk":"996581486","pt":1580562802565,"mc":[{"id":"1.168133553","rc":[{"trd":[[5.6,98.29]],"batb":[[0,5.6,1.45]],"ltp":5.6,"tv":2679.66,"id":21641292}],"tv":19749.92}]}
{"op":"mcm","clk":"996581706","pt":1580562803559,"mc":[{"id":"1.168133553","rc":[{"batl":[[0,1.32,11],[1,1.33,974.25]],"ltp":1.31,"tv":16510.79,"id":16325787}]}]}
{"op":"mcm","clk":"996582865","pt":1580562809445,"mc":[{"id":"1.168133553","rc":[{"batb":[[1,14,7.97],[2,13.5,5.27]],"ltp":15.0,"tv":559.47,"id":27227336}]}]}
{"op":"mcm","clk":"996588451","pt":1580562837492,"mc":[{"id":"1.168133553","rc":[{"trd":[[14.5,36.66]],"batb":[[0,14.5,2.57]],"ltp":14.5,"tv":569.63,"id":27227336},{"trd":[[1.32,6312.88]],"batb":[[0,1.31,92.7]],"batl":[[0,1.33,974.25],[1,1.34,1581.89],[2,1.35,1718.76]],"ltp":1.32,"tv":16532.79,"id":16325787}],"tv":19782.08}]}
{"op":"mcm","clk":"996588653","pt":1580562838527,"mc":[{"id":"1.168133553","rc":[{"batb":[[1,14,6.07],[2,13.5,7.17]],"ltp":14.5,"tv":569.63,"id":27227336},{"batb":[[2,5.4,31.96]],"ltp":5.6,"tv":2679.66,"id":21641292},{"trd":[[1.32,6314.8]],"batb":[[0,1.31,122.13],[1,1.3,413.29]],"ltp":1.32,"tv":16534.71,"id":16325787}],"tv":19784.0}]}
{"op":"mcm","clk":"996588862","pt":1580562839532,"mc":[{"id":"1.168133553","rc":[{"batb":[[1,5.5,15.22]],"ltp":5.6,"tv":2679.66,"id":21641292}]}]}
{"op":"mcm","clk":"996590205","pt":1580562845545,"mc":[{"id":"1.168133553","rc":[{"batb":[[0,1.31,187.18]],"ltp":1.32,"tv":16534.71,"id":16325787}]}]}
{"op":"mcm","clk":"996591520","pt":1580562851540,"mc":[{"id":"1.168133553","rc":[{"batb":[[2,13.5,5.27]],"ltp":14.5,"tv":569.63,"id":27227336},{"batb":[[0,1.31,156.79]],"batl":[[0,1.33,944.32]],"ltp":1.32,"tv":16534.71,"id":16325787}]}]}
{"op":"mcm","clk":"996591701","pt":1580562852470,"mc":[{"id":"1.168133553","rc":[{"trd":[[1.31,3321.08],[1.33,3294.78]],"batb":[[0,1.31,146.79]],"batl":[[0,1.33,936.32]],"ltp":1.33,"tv":16570.71,"id":16325787}],"tv":19820.0}]}
{"op":"mcm","clk":"996591920","pt":1580562853470,"mc":[{"id":"1.168133553","rc":[{"batb":[[0,5.5,15.22],[1,5.4,31.96],[2,5.3,38.6]],"ltp":5.6,"tv":2679.66,"id":21641292}]}]}
{"op":"mcm","clk":"996593202","pt":1580562859464,"mc":[{"id":"1.168133553","rc":[{"batb":[[1,5.4,25.23]],"ltp":5.6,"tv":2679.66,"id":21641292}]}]}
{"op":"mcm","clk":"996597735","pt":1580562880474,"mc":[{"id":"1.168133553","rc":[{"trd":[[14.5,41.81]],"batb":[[0,14,6.07],[1,13.5,5.27],[2,13,1]],"batl":[[0,14.5,3.78],[1,15.5,11.12],[2,16,3.02]],"ltp":14.5,"tv":574.78,"id":27227336},{"batb":[[0,5.6,11.06],[1,5.5,15.22],[2,5.4,25.23]],"ltp":5.6,"tv":2679.66,"id":21641292},{"batb":[[0,1.32,8.43],[1,1.31,146.79],[2,1.3,413.29]],"ltp":1.33,"tv":16570.71,"id":16325787}],"tv":19825.16}]}
{"op":"mcm","clk":"996597941","pt":1580562881472,"mc":[{"id":"1.168133553","rc":[{"batb":[[1,1.31,171.02]],"ltp":1.33,"tv":16570.71,"id":16325787}]}]}
{"op":"mcm","clk":"996598160","pt":1580562882468,"mc":[{"id":"1.168133553","rc":[{"batb":[[1,13.5,1]],"batl":[[1,15.5,15.47]],"ltp":14.5,"tv":574.78,"id":27227336},{"batb":[[1,5.5,20.2]],"ltp":5.6,"tv":2679.66,"id":21641292}]}]}
{"op":"mcm","clk":"996599372","pt":1580562888261,"mc":[{"id":"1.168133553","rc":[{"batb":[[1,5.5,24.68]],"ltp":5.6,"tv":2679.66,"id":21641292}]}]}
{"op":"mcm","clk":"996604231","pt":1580562910404,"mc":[{"id":"1.168133553","rc":[{"batb":[[1,13.5,5.03],[2,13,3.53]],"batl":[[1,15,3.03],[2,15.5,18.47]],"ltp":14.5,"tv":574.78,"id":27227336},{"batb":[[0,5.6,23.06]],"ltp":5.6,"tv":2679.66,"id":21641292},{"batb":[[0,1.32,41.46],[1,1.31,201.41]],"batl":[[0,1.33,966.25]],"ltp":1.33,"tv":16570.71,"id":16325787}]}]}
{"op":"mcm","clk":"996604465","pt":1580562911523,"mc":[{"id":"1.168133553","rc":[{"batb":[[1,13.5,9.47]],"ltp":14.5,"tv":574.78,"id":27227336},{"trd":[[5.6,108.28]],"batb":[[0,5.6,18.07]],"ltp":5.6,"tv":2689.65,"id":21641292}],"tv":19835.15}]}
{"op":"mcm","clk":"996605882","pt":1580562918527,"mc":[{"id":"1.168133553","rc":[{"batl":[[0,14.5,5.79]],"ltp":14.5,"tv":574.78,"id":27227336},{"trd":[[1.33,3305.64]],"batb":[[0,1.32,33.03]],"batl":[[0,1.33,960.82]],"ltp":1.33,"tv":16581.57,"id":16325787}],"tv":19846.01}]}
{"op":"mcm","clk":"996608833","pt":1580562933555,"mc":[{"id":"1.168133553","rc":[{"batb":[[1,13.5,12.01],[2,13,1]],"ltp":14.5,"tv":574.78,"id":27227336}]}]}
{"op":"mcm","clk":"996613735","pt":1580562956465,"mc":[{"id":"1.168133553","rc":[{"trd":[[14,18.86]],"batb":[[0,13.5,12.01],[1,13,1],[2,12.5,4.15]],"batl":[[0,15.5,18.47],[1,16,6.26],[2,16.5,7.38]],"ltp":14.0,"tv":586.92,"id":27227336},{"trd":[[1.33,3318.54]],"batb":[[0,1.31,201.41],[1,1.3,413.29],[2,1.29,305.13]],"batl":[[0,1.33,954.37]],"ltp":1.33,"tv":16594.47,"id":16325787}],"tv":19871.05}]}
{"op":"mcm","clk":"996613937","pt":1580562957501,"mc":[{"id":"1.168133553","rc":[{"batb":[[0,13.5,9.47],[1,13,3.53]],"batl":[[1,16,3.02]],"ltp":14.0,"tv":586.92,"id":27227336},{"batb":[[1,5.5,31.43]],"ltp":5.6,"tv":2689.65,"id":21641292}]}]}
{"op":"mcm","clk":"996614381","pt":1580562959502,"mc":[{"id":"1.168133553","rc":[{"batb":[[0,13.5,5.03]],"batl":[[0,15,4.32],[1,15.5,18.47],[2,16,3.02]],"ltp":14.0,"tv":586.92,"id":27227336}]}]}
{"op":"mcm","clk":"996619013","pt":1580562981557,"mc":[{"id":"1.168133553","rc":[{"batb":[[1,5.5,24.68]],"ltp":5.6,"tv":2689.65,"id":21641292}]}]}
{"op":"mcm","clk":"996625750","pt":1580563013469,"mc":[{"id":"1.168133553","rc":[{"batb":[[1,13,7.53]],"batl":[[0,14,6.07],[1,15,4.32],[2,15.5,18.47]],"ltp":14.0,"tv":586.92,"id":27227336},{"trd":[[1.33,3330.8]],"batb":[[0,1.32,40.29],[1,1.31,201.41],[2,1.3,413.29]],"batl":[[0,1.33,906.24]],"ltp":1.33,"tv":16606.73,"id":16325787}],"tv":19883.31}]}
{"op":"mcm","clk":"996627321","pt":1580563021366,"mc":[{"id":"1.168133553","rc":[{"trd":[[5.6,108.92]],"batb":[[0,5.6,17.75]],"ltp":5.6,"tv":2690.29,"id":21641292}],"tv":19883.95}]}
{"op":"mcm","clk":"996627776","pt":1580563023495,"mc":[{"id":"1.168133553","rc":[{"trd":[[5.6,111.19]],"batb":[[0,5.6,16.61]],"ltp":5.6,"tv":2692.56,"id":21641292}],"tv":19886.22}]}
{"op":"mcm","clk":"996627958","pt":1580563024491,"mc":[{"id":"1.168133553","rc":[{"trd":[[5.6,111.39]],"batb":[[0,5.6,16.51]],"ltp":5.6,"tv":2692.76,"id":21641292}],"tv":19886.42}]}
{"op":"mcm","clk":"996628150","pt":1580563025392,"mc":[{"id":"1.168133553","rc":[{"batl":[[0,14,16.92]],"ltp":14.0,"tv":586.92,"id":27227336}]}]}
{"op":"mcm","clk":"996628351","pt":1580563026490,"mc":[{"id":"1.168133553","rc":[{"batl":[[1,14.5,4.03],[2,15,4.32]],"ltp":14.0,"tv":586.92,"id":27227336},{"trd":[[5.6,131.6]],"batb":[[0,5.5,24.68],[1,5.4,25.23],[2,5.3,38.6]],"ltp":5.6,"tv":2712.98,"id":21641292}],"tv":19906.63}]}
{"op":"mcm","clk":"996629953","pt":1580563034407,"mc":[{"id":"1.168133553","rc":[{"batl":[[2,15,7.77]],"ltp":14.0,"tv":586.92,"id":27227336}]}]}
{"op":"mcm","clk":"996630605","pt":1580563037423,"mc":[{"id":"1.168133553","rc":[{"batl":[[1,14.5,8.14]],"ltp":14.0,"tv":586.92,"id":27227336}]}]}
{"op":"mcm","clk":"996634076","pt":1580563055485,"mc":[{"id":"1.168133553","rc":[{"batl":[[1,1.34,1594.77]],"ltp":1.33,"tv":16606.73,"id":16325787}]}]}
{"op":"mcm","clk":"996634304","pt":1580563056561,"mc":[{"id":"1.168133553","rc":[{"trd":[[14,19.66]],"batl":[[0,14,16.12]],"ltp":14.0,"tv":587.72,"id":27227336},{"trd":[[5.6,133.6]],"ltp":5.6,"tv":2714.98,"id":21641292},{"trd":[[1.33,3339.22]],"batl":[[0,1.33,897.82]],"ltp":1.33,"tv":16615.15,"id":16325787}],"tv":19917.85}]}
{"op":"mcm","clk":"996638536","pt":1580563078503,"mc":[{"id":"1.168133553","rc":[{"trd":[[1.32,6327.4]],"batb":[[0,1.32,33.99]],"ltp":1.32,"tv":16627.75,"id":16325787}],"tv":19930.45}]}
{"op":"mcm","clk":"996639963","pt":1580563085533,"mc":[{"id":"1.168133553","rc":[{"trd":[[1.32,6389.8]],"batb":[[0,1.32,2.79]],"ltp":1.32,"tv":16690.15,"id":16325787}],"tv":19992.85}]}
{"op":"mcm","clk":"996640165","pt":1580563086441,"mc":[{"id":"1.168133553","rc":[{"batb":[[0,5.5,31.43]],"ltp":5.6,"tv":2714.98,"id":21641292}]}]}
{"op":"mcm","clk":"996641247","pt":1580563091457,"mc":[{"id":"1.168133553","rc":[{"batl":[[0,14,10.85]],"ltp":14.0,"tv":587.72,"id":27227336}]}]}
{"op":"mcm","clk":"996641509","pt":1580563092547,"mc":[{"id":"1.168133553","rc":[{"trd":[[13.5,19.51]],"batb":[[0,13,7.53],[1,12.5,9.15],[2,12,6.35]],"ltp":13.5,"tv":598.7,"id":27227336},{"trd":[[5.7,211.29]],"batl":[[0,5.7,12.8]],"ltp":5.7,"tv":2717.16,"id":21641292},{"trd":[[1.33,3365.56]],"batb":[[0,1.32,39]],"batl":[[0,1.33,879.98]],"ltp":1.33,"tv":16716.49,"id":16325787}],"tv":20032.35}]}
{"op":"mcm","clk":"996641737","pt":1580563093543,"mc":[{"id":"1.168133553","rc":[{"batl":[[0,1.33,850.05],[1,1.34,1624.7]],"ltp":1.33,"tv":16716.49,"id":16325787}]}]}
{"op":"mcm","clk":"996641926","pt":1580563094476,"mc":[{"id":"1.168133553","rc":[{"trd":[[1.32,6409.8]],"batb":[[0,1.32,29]],"ltp":1.32,"tv":16736.49,"id":16325787}],"tv":20052.35}]}
{"op":"mcm","clk":"996643937","pt":1580563104564,"mc":[{"id":"1.168133553","rc":[{"batl":[[1,1.34,1624.48]],"ltp":1.32,"tv":16736.49,"id":16325787}]}]}
{"op":"mcm","clk":"996644577","pt":1580563107476,"mc":[{"id":"1.168133553","rc":[{"batb":[[0,13.5,1],[1,13,7.53],[2,12.5,9.15]],"ltp":13.5,"tv":598.7,"id":27227336}]}]}
{"op":"mcm","clk":"996650919","pt":1580563138495,"mc":[{"id":"1.168133553","rc":[{"trd":[[13.5,26.17]],"batb":[[0,13,7.53],[1,12.5,9.15],[2,12,6.35]],"ltp":13.5,"tv":605.36,"id":27227336},{"trd":[[5.7,222.33]],"batl":[[0,5.7,1.76]],"ltp":5.7,"tv":2728.2,"id":21641292},{"trd":[[1.33,3436.04]],"batl":[[0,1.33,791.16]],"ltp":1.33,"tv":16806.97,"id":16325787}],"tv":20140.53}]}
{"op":"mcm","clk":"996651122","pt":1580563139482,"mc":[{"id":"1.168133553","rc":[{"batb":[[0,13,5],[1,12.5,13.44]],"ltp":13.5,"tv":605.36,"id":27227336},{"trd":[[5.7,225.85]],"batl":[[0,5.8,10],[1,5.9,57.92],[2,6,26.43]],"ltp":5.7,"tv":2731.72,"id":21641292},{"batb":[[0,1.32,40]],"batl":[[0,1.33,867.87],[1,1.34,1594.77]],"ltp":1.33,"tv":16806.97,"id":16325787}],"tv":20144.05}]}
{"op":"mcm","clk":"996652097","pt":1580563144502,"mc":[{"id":"1.168133553","rc":[{"batl":[[0,5.8,24]],"ltp":5.7,"tv":2731.72,"id":21641292}]}]}
{"op":"mcm","clk":"996654562","pt":1580563156516,"mc":[{"id":"1.168133553","rc":[{"trd":[[14,20.86]],"batl":[[0,14,9.65]],"ltp":14.0,"tv":606.56,"id":27227336},{"trd":[[5.6,136.6]],"ltp":5.6,"tv":2734.72,"id":21641292},{"trd":[[1.33,3448.67]],"batl":[[0,1.33,855.46]],"ltp":1.33,"tv":16819.6,"id":16325787}],"tv":20160.89}]}
{"op":"mcm","clk":"996654781","pt":1580563157553,"mc":[{"id":"1.168133553","rc":[{"batb":[[1,12.5,16.04]],"ltp":14.0,"tv":606.56,"id":27227336}]}]}
{"op":"mcm","clk":"996655771","pt":1580563162508,"mc":[{"id":"1.168133553","rc":[{"batl":[[1,5.9,55.07]],"ltp":5.6,"tv":2734.72,"id":21641292}]}]}
{"op":"mcm","clk":"996657912","pt":1580563173515,"mc":[{"id":"1.168133553","rc":[{"batl":[[0,14.5,4.11],[1,15,7.77],[2,15.5,18.47]],"ltp":14.0,"tv":606.56,"id":27227336},{"batb":[[0,1.31,201.41],[1,1.3,413.29],[2,1.29,305.13]],"ltp":1.33,"tv":16819.6,"id":16325787}]}]}
{"op":"mcm","clk":"996658096","pt":1580563174543,"mc":[{"id":"1.168133553","rc":[{"batb":[[0,13,8.9]],"batl":[[1,15,4.32]],"ltp":14.0,"tv":606.56,"id":27227336},{"batb":[[0,5.5,40.64]],"ltp":5.6,"tv":2734.72,"id":21641292},{"batb":[[0,1.31,240.08]],"ltp":1.33,"tv":16819.6,"id":16325787}]}]}
{"op":"mcm","clk":"996658303","pt":1580563175536,"mc":[{"id":"1.168133553","rc":[{"batl":[[0,15,4],[1,15.5,18.47],[2,16.5,4.38]],"ltp":14.0,"tv":606.56,"id":27227336},{"batb":[[1,5.4,27.57]],"ltp":5.6,"tv":2734.72,"id":21641292}]}]}
{"op":"mcm","clk":"996658497","pt":1580563176522,"mc":[{"id":"1.168133553","rc":[{"batl":[[0,15.5,18.47],[1,16.5,4.38],[2,17,5.21]],"ltp":14.0,"tv":606.56,"id":27227336},{"batb":[[1,5.4,25.23]],"batl":[[0,5.8,31]],"ltp":5.6,"tv":2734.72,"id":21641292}]}]}
{"op":"mcm","clk":"996658883","pt":1580563178522,"mc":[{"id":"1.168133553","rc":[{"batl":[[0,15,1.63],[1,15.5,18.47],[2,16.5,4.38]],"ltp":14.0,"tv":606.56,"id":27227336}]}]}
{"op":"mcm","clk":"996659059","pt":1580563179487,"mc":[{"id":"1.168133553","rc":[{"batl":[[2,16,2.27]],"ltp":14.0,"tv":606.56,"id":27227336}]}]}
{"op":"mcm","clk":"996661520","pt":1580563191530,"mc":[{"id":"1.168133553","rc":[{"trd":[[13,13.4]],"batb":[[0,13.5,4.27],[1,13,2.2],[2,12.5,16.04]],"batl":[[1,15.5,20.47]],"ltp":13.0,"tv":619.96,"id":27227336},{"trd":[[1.33,3471.19]],"batl":[[0,1.33,844.2]],"ltp":1.33,"tv":16842.12,"id":16325787}],"tv":20196.8}]}
{"op":"mcm","clk":"996662742","pt":1580563197503,"mc":[{"id":"1.168133553","rc":[{"batb":[[1,13,4.73],[2,12.5,13.51]],"ltp":13.0,"tv":619.96,"id":27227336}]}]}
{"op":"mcm","clk":"996663365","pt":1580563200535,"mc":[{"id":"1.168133553","rc":[{"batl":[[0,15,6.95]],"ltp":13.0,"tv":619.96,"id":27227336},{"batl":[[0,5.8,24]],"ltp":5.6,"tv":2734.72,"id":21641292}]}]}
{"op":"mcm","clk":"996664722","pt":1580563206565,"mc":[{"id":"1.168133553","rc":[{"batb":[[0,13.5,9.27]],"ltp":13.0,"tv":619.96,"id":27227336}]}]}
{"op":"mcm","clk":"996669555","pt":1580563228530,"mc":[{"id":"1.168133553","rc":[{"batb":[[1,1.3,384.24]],"ltp":1.33,"tv":16842.12,"id":16325787}]}]}
{"op":"mcm","clk":"996671699","pt":1580563238416,"mc":[{"id":"1.168133553","rc":[{"trd":[[13.5,40.39]],"batb":[[0,13.5,6.37]],"batl":[[0,14.5,2.99],[1,15,6.95],[2,15.5,20.47]],"ltp":13.5,"tv":634.18,"id":27227336},{"trd":[[1.33,3488.93]],"batl":[[0,1.33,835.33]],"ltp":1.33,"tv":16859.86,"id":16325787}],"tv":20228.76}]}
{"op":"mcm","clk":"996672145","pt":1580563240522,"mc":[{"id":"1.168133553","rc":[{"batb":[[1,13,8.73]],"batl":[[1,15,5.32]],"ltp":13.5,"tv":634.18,"id":27227336}]}]}
{"op":"mcm","clk":"996678237","pt":1580563268545,"mc":[{"id":"1.168133553","rc":[{"trd":[[13.5,59.85]],"batb":[[0,14,4.04],[1,13.5,3.69],[2,13,8.73]],"batl":[[0,15,5.32],[1,15.5,20.47],[2,16,5.51]],"ltp":13.5,"tv":653.64,"id":27227336},{"trd":[[1.33,3511.24]],"batb":[[0,1.32,41.04],[1,1.31,240.08],[2,1.3,384.24]],"batl":[[0,1.33,777.17]],"ltp":1.33,"tv":16882.17,"id":16325787}],"tv":20270.54}]}
{"op":"mcm","clk":"996678461","pt":1580563269535,"mc":[{"id":"1.168133553","rc":[{"batb":[[0,13.5,4],[1,13,8.73],[2,12.5,13.51]],"batl":[[0,15.5,20.47],[1,16,2.27],[2,16.5,4.38]],"ltp":13.5,"tv":653.64,"id":27227336},{"batb":[[0,1.31,240.08],[1,1.3,384.24],[2,1.29,391.25]],"batl":[[0,1.33,818.17]],"ltp":1.33,"tv":16882.17,"id":16325787}]}]}
{"op":"mcm","clk":"996678864","pt":1580563271562,"mc":[{"id":"1.168133553","rc":[{"batl":[[1,16.5,4.38],[2,17,5.21]],"ltp":13.5,"tv":653.64,"id":27227336}]}]}
{"op":"mcm","clk":"996680483","pt":1580563279533,"mc":[{"id":"1.168133553","rc":[{"trd":[[13.5,73.91]],"batb":[[0,13.5,4.1],[2,12.5,13.3]],"batl":[[0,15,5.71],[1,15.5,20.47],[2,16.5,4.38]],"ltp":13.5,"tv":667.7,"id":27227336},{"trd":[[5.5,284.39]],"batb":[[0,5.6,6.74],[1,5.5,31.89],[2,5.4,25.23]],"batl":[[0,5.8,31]],"ltp":5.5,"tv":2738.72,"id":21641292},{"trd":[[1.33,3540.23]],"batb":[[0,1.31,268.91]],"batl":[[0,1.33,800.68]],"ltp":1.33,"tv":16911.16,"id":16325787}],"tv":20317.58}]}
{"op":"mcm","clk":"996680682","pt":1580563280507,"mc":[{"id":"1.168133553","rc":[{"batb":[[1,13,6.2],[2,12.5,15.83]],"ltp":13.5,"tv":667.7,"id":27227336}]}]}
{"op":"mcm","clk":"996680897","pt":1580563281499,"mc":[{"id":"1.168133553","rc":[{"batb":[[2,12.5,11.04]],"ltp":13.5,"tv":667.7,"id":27227336},{"batb":[[0,5.6,22.85]],"ltp":5.5,"tv":2738.72,"id":21641292}]}]}
{"op":"mcm","clk":"996681749","pt":1580563285495,"mc":[{"id":"1.168133553","rc":[{"trd":[[5.6,140.74]],"batb":[[0,5.6,20.78]],"ltp":5.6,"tv":2742.86,"id":21641292}],"tv":20321.72}]}
{"op":"mcm","clk":"996682141","pt":1580563287520,"mc":[{"id":"1.168133553","rc":[{"trd":[[13.5,77.91]],"batl":[[0,15,12.71]],"ltp":13.5,"tv":671.7,"id":27227336}],"tv":20325.72}]}
{"op":"mcm","clk":"996682323","pt":1580563288502,"mc":[{"id":"1.168133553","rc":[{"batl":[[0,15,5.71]],"ltp":13.5,"tv":671.7,"id":27227336}]}]}
{"op":"mcm","clk":"996682776","pt":1580563290524,"mc":[{"id":"1.168133553","rc":[{"trd":[[13.5,97.13]],"batb":[[0,13,6.2],[1,12.5,15.04],[2,12,10.35]],"batl":[[0,15.5,23.47],[1,16.5,4.38],[2,17,2.16]],"ltp":13.5,"tv":690.92,"id":27227336},{"batl":[[0,5.8,24]],"ltp":5.6,"tv":2742.86,"id":21641292},{"batb":[[0,1.32,43.16],[1,1.31,268.91],[2,1.3,384.24]],"batl":[[0,1.33,762.68]],"ltp":1.33,"tv":16911.16,"id":16325787}],"tv":20344.95}]}
{"op":"mcm","clk":"996682995","pt":1580563291520,"mc":[{"id":"1.168133553","rc":[{"batl":[[0,5.8,31]],"ltp":5.6,"tv":2742.86,"id":21641292},{"batb":[[0,1.31,268.91],[1,1.3,384.24],[2,1.29,391.25]],"batl":[[0,1.33,795.68]],"ltp":1.33,"tv":16911.16,"id":16325787}]}]}
{"op":"mcm","clk":"996683211","pt":1580563292527,"mc":[{"id":"1.168133553","rc":[{"batl":[[0,15,1.6],[1,15.5,23.47],[2,16,2.4]],"ltp":13.5,"tv":690.92,"id":27227336},{"trd":[[1.31,3381.08]],"batb":[[0,1.31,238.91]],"ltp":1.31,"tv":16971.16,"id":16325787}],"tv":20404.95}]}
{"op":"mcm","clk":"996683584","pt":1580563294525,"mc":[{"id":"1.168133553","rc":[{"batl":[[2,16,4.52]],"ltp":13.5,"tv":690.92,"id":27227336},{"batb":[[0,1.31,173.86]],"batl":[[0,1.32,2],[1,1.33,795.68],[2,1.34,1594.77]],"ltp":1.31,"tv":16971.16,"id":16325787}]}]}
{"op":"mcm","clk":"996683740","pt":1580563295409,"mc":[{"id":"1.168133553","rc":[{"batb":[[0,1.31,175.86]],"ltp":1.31,"tv":16971.16,"id":16325787}]}]}
{"op":"mcm","clk":"996684372","pt":1580563298478,"mc":[{"id":"1.168133553","rc":[{"batb":[[0,5.6,25.17]],"ltp":5.6,"tv":2742.86,"id":21641292},{"trd":[[1.31,3427.73]],"batb":[[0,1.31,152.54]],"ltp":1.31,"tv":17017.8,"id":16325787}],"tv":20451.59}]}
{"op":"mcm","clk":"996684574","pt":1580563299463,"mc":[{"id":"1.168133553","rc":[{"batb":[[2,5.4,30.23]],"ltp":5.6,"tv":2742.86,"id":21641292},{"batb":[[0,1.31,193.54]],"ltp":1.31,"tv":17017.8,"id":16325787}]}]}
{"op":"mcm","clk":"996685024","pt":1580563301566,"mc":[{"id":"1.168133553","rc":[{"batb":[[1,5.5,38.64]],"ltp":5.6,"tv":2742.86,"id":21641292}]}]}
{"op":"mcm","clk":"996685188","pt":1580563302496,"mc":[{"id":"1.168133553","rc":[{"batb":[[0,13,8.73],[1,12.5,12.51]],"batl":[[0,15,7.31]],"ltp":13.5,"tv":690.92,"id":27227336}]}]}
{"op":"mcm","clk":"996685394","pt":1580563303483,"mc":[{"id":"1.168133553","rc":[{"batl":[[0,15,15.31]],"ltp":13.5,"tv":690.92,"id":27227336},{"batl":[[0,5.8,24]],"ltp":5.6,"tv":2742.86,"id":21641292}]}]}
{"op":"mcm","clk":"996687186","pt":1580563311572,"mc":[{"id":"1.168133553","rc":[{"batl":[[0,15,18.76]],"ltp":13.5,"tv":690.92,"id":27227336},{"batb":[[1,5.5,31.89]],"ltp":5.6,"tv":2742.86,"id":21641292}]}]}
{"op":"mcm","clk":"996687398","pt":1580563312569,"mc":[{"id":"1.168133553","rc":[{"trd":[[5.6,144.74]],"batb":[[0,5.6,23.17]],"ltp":5.6,"tv":2746.86,"id":21641292}],"tv":20455.59}]}
{"op":"mcm","clk":"996690361","pt":1580563325563,"mc":[{"id":"1.168133553","rc":[{"batl":[[0,14.5,6.98],[1,15,18.76],[2,15.5,23.47]],"ltp":13.5,"tv":690.92,"id":27227336}]}]}
{"op":"mcm","clk":"996690605","pt":1580563326550,"mc":[{"id":"1.168133553","rc":[{"batl":[[1,15,17.16]],"ltp":13.5,"tv":690.92,"id":27227336}]}]}
{"op":"mcm","clk":"996691347","pt":1580563329574,"mc":[{"id":"1.168133553","rc":[{"trd":[[14,21.05]],"batl":[[0,13.5,5.79],[1,14,9.04],[2,14.5,19.32]],"ltp":14.0,"tv":691.11,"id":27227336},{"trd":[[5.8,113.53]],"batl":[[0,5.8,23.54]],"ltp":5.8,"tv":2747.32,"id":21641292},{"trd":[[1.32,6411.8],[1.33,3558.25]],"batl":[[0,1.33,753.67],[1,1.34,1594.77],[2,1.35,1718.76]],"ltp":1.33,"tv":17037.82,"id":16325787}],"tv":20476.26}]}
{"op":"mcm","clk":"996691575","pt":1580563330570,"mc":[{"id":"1.168133553","rc":[{"trd":[[13.5,106.27]],"batl":[[0,13.5,1.22]],"ltp":13.5,"tv":700.25,"id":27227336},{"batb":[[0,5.7,27.87],[1,5.6,23.17],[2,5.5,31.89]],"batl":[[2,6,33.43]],"ltp":5.8,"tv":2747.32,"id":21641292},{"batb":[[0,1.32,87.73],[1,1.31,193.54],[2,1.3,384.24]],"ltp":1.33,"tv":17037.82,"id":16325787}],"tv":20485.4}]}
{"op":"mcm","clk":"996691769","pt":1580563331361,"mc":[{"id":"1.168133553","rc":[{"batl":[[2,14.5,27.19]],"ltp":13.5,"tv":700.25,"id":27227336},{"batb":[[1,1.31,163.15]],"ltp":1.33,"tv":17037.82,"id":16325787}]}]}
{"op":"mcm","clk":"996692911","pt":1580563336500,"mc":[{"id":"1.168133553","rc":[{"batb":[[1,1.31,228.19]],"ltp":1.33,"tv":17037.82,"id":16325787}]}]}
{"op":"mcm","clk":"996695083","pt":1580563346474,"mc":[{"id":"1.168133553","rc":[{"batl":[[2,14.5,27.32]],"ltp":13.5,"tv":700.25,"id":27227336}]}]}
{"op":"mcm","clk":"996709817","pt":1580563363471,"mc":[{"id":"1.168133553","rc":[{"trd":[[1.32,6415.8]],"batb":[[0,1.32,85.73]],"ltp":1.32,"tv":17041.82,"id":16325787}],"tv":20489.4}]}
{"op":"mcm","clk":"996713021","pt":1580563378549,"mc":[{"id":"1.168133553","rc":[{"trd":[[13,28.03]],"batb":[[0,13,1.41]],"batl":[[0,14.5,27.32],[1,15,13.71],[2,15.5,23.47]],"ltp":13.0,"tv":714.89,"id":27227336},{"batb":[[0,1.32,93.58]],"batl":[[0,1.33,790.67]],"ltp":1.32,"tv":17041.82,"id":16325787}],"tv":20504.04}]}
{"op":"mcm","clk":"996713251","pt":1580563379566,"mc":[{"id":"1.168133553","rc":[{"batb":[[0,13,5.73]],"batl":[[0,14.5,23.9]],"ltp":13.0,"tv":714.89,"id":27227336}]}]}
{"op":"mcm","clk":"996713475","pt":1580563380549,"mc":[{"id":"1.168133553","rc":[{"batb":[[0,1.32,52.58]],"ltp":1.32,"tv":17041.82,"id":16325787}]}]}
{"op":"mcm","clk":"996715959","pt":1580563391480,"mc":[{"id":"1.168133553","rc":[{"batl":[[0,14.5,19.32],[1,15,18.14]],"ltp":13.0,"tv":714.89,"id":27227336}]}]}
{"op":"mcm","clk":"996716223","pt":1580563392574,"mc":[{"id":"1.168133553","rc":[{"trd":[[5.7,229.85]],"batb":[[0,5.7,25.87]],"ltp":5.7,"tv":2751.32,"id":21641292}],"tv":20508.04}]}
{"op":"mcm","clk":"996720247","pt":1580563411555,"mc":[{"id":"1.168133553","rc":[{"batb":[[0,1.32,44.73]],"ltp":1.32,"tv":17041.82,"id":16325787}]}]}
{"op":"mcm","clk":"996720464","pt":1580563412516,"mc":[{"id":"1.168133553","rc":[{"trd":[[13,42.09]],"batb":[[0,13,4.17]],"batl":[[0,14.5,22.17],[1,15,20.23]],"ltp":13.0,"tv":728.94,"id":27227336},{"trd":[[5.8,114.81]],"batl":[[0,5.8,22.26]],"ltp":5.8,"tv":2752.6,"id":21641292},{"trd":[[1.33,3578.46]],"batl":[[0,1.33,777.78]],"ltp":1.33,"tv":17062.03,"id":16325787}],"tv":20543.58}]}
{"op":"mcm","clk":"996726248","pt":1580563441490,"mc":[{"id":"1.168133553","rc":[{"trd":[[5.7,230.05]],"batb":[[0,5.7,25.77]],"ltp":5.7,"tv":2752.8,"id":21641292}],"tv":20543.78}]}
{"op":"mcm","clk":"996726693","pt":1580563443470,"mc":[{"id":"1.168133553","rc":[{"batb":[[0,1.32,46.73]],"ltp":1.33,"tv":17062.03,"id":16325787}]}]}
{"op":"mcm","clk":"996727324","pt":1580563446508,"mc":[{"id":"1.168133553","rc":[{"trd":[[1.33,3588.16]],"batl":[[0,1.33,772.93]],"ltp":1.33,"tv":17071.73,"id":16325787}],"tv":20553.48}]}
{"op":"mcm","clk":"996727470","pt":1580563447297,"mc":[{"id":"1.168133553","rc":[{"trd":[[5.7,249.88]],"batb":[[0,5.7,15.86]],"ltp":5.7,"tv":2772.62,"id":21641292},{"batb":[[0,1.32,89.73]],"ltp":1.33,"tv":17071.73,"id":16325787}],"tv":20573.3}]}
{"op":"mcm","clk":"996730263","pt":1580563460427,"mc":[{"id":"1.168133553","rc":[{"trd":[[13,52.37]],"batb":[[0,13,3.11]],"ltp":13.0,"tv":739.22,"id":27227336},{"trd":[[5.8,119.16]],"batl":[[0,5.8,17.91]],"ltp":5.8,"tv":2776.97,"id":21641292},{"trd":[[1.33,3624.64]],"batl":[[0,1.33,745.21]],"ltp":1.33,"tv":17108.21,"id":16325787}],"tv":20624.41}]}
{"op":"mcm","clk":"996732611","pt":1580563472546,"mc":[{"id":"1.168133553","rc":[{"batl":[[0,14.5,15.18]],"ltp":13.0,"tv":739.22,"id":27227336}]}]}
{"op":"mcm","clk":"996732788","pt":1580563473556,"mc":[{"id":"1.168133553","rc":[{"batl":[[0,14.5,10.85]],"ltp":13.0,"tv":739.22,"id":27227336}]}]}
{"op":"mcm","clk":"996735558","pt":1580563487562,"mc":[{"id":"1.168133553","rc":[{"batl":[[1,15,13.71]],"ltp":13.0,"tv":739.22,"id":27227336},{"batl":[[0,1.33,715.28]],"ltp":1.33,"tv":17108.21,"id":16325787}]}]}
{"op":"mcm","clk":"996735734","pt":1580563488558,"mc":[{"id":"1.168133553","rc":[{"trd":[[5.7,253.88]],"batb":[[0,5.7,13.86]],"ltp":5.7,"tv":2780.97,"id":21641292}],"tv":20628.41}]}
{"op":"mcm","clk":"996737872","pt":1580563499488,"mc":[{"id":"1.168133553","rc":[{"batl":[[1,15,20.23]],"ltp":13.0,"tv":739.22,"id":27227336},{"batl":[[0,1.33,745.21]],"ltp":1.33,"tv":17108.21,"id":16325787}]}]}
{"op":"mcm","clk":"996738784","pt":1580563504494,"mc":[{"id":"1.168133553","rc":[{"trd":[[13,58.59]],"batb":[[0,12.5,8.51],[1,12,6.35],[2,11.5,1]],"batl":[[0,13,3.22],[1,14.5,10.85],[2,15,14.52]],"ltp":13.0,"tv":745.44,"id":27227336},{"trd":[[5.8,154.98]],"batb":[[0,5.8,19.99],[1,5.7,26.84],[2,5.6,23.17]],"batl":[[0,5.9,42.36],[1,6,33.43],[2,6.4,27.39]],"ltp":5.8,"tv":2816.79,"id":21641292},{"trd":[[1.33,3642.56]],"batb":[[0,1.32,96.73],[2,1.3,398.24]],"batl":[[0,1.33,699.25]],"ltp":1.33,"tv":17126.13,"id":16325787}],"tv":20688.37}]}
{"op":"mcm","clk":"996738982","pt":1580563505527,"mc":[{"id":"1.168133553","rc":[{"trd":[[5.9,156.08]],"batb":[[1,5.7,28.1],[2,5.6,30.84]],"batl":[[0,5.9,27.17]],"ltp":5.9,"tv":2832.45,"id":21641292}],"tv":20704.03}]}
{"op":"mcm","clk":"996739198","pt":1580563506519,"mc":[{"id":"1.168133553","rc":[{"batl":[[1,14.5,15.27],[2,15,19.77]],"ltp":13.0,"tv":745.44,"id":27227336},{"batb":[[2,5.6,40.48]],"batl":[[2,6.2,6.03]],"ltp":5.9,"tv":2832.45,"id":21641292}]}]}
{"op":"mcm","clk":"996739690","pt":1580563509197,"mc":[{"id":"1.168133553","rc":[{"batb":[[0,12.5,6.76],[1,12,10.45]],"ltp":13.0,"tv":745.44,"id":27227336}]}]}
{"op":"mcm","clk":"996740195","pt":1580563511511,"mc":[{"id":"1.168133553","rc":[{"batb":[[1,12,8.18]],"ltp":13.0,"tv":745.44,"id":27227336}]}]}
{"op":"mcm","clk":"996741198","pt":1580563516431,"mc":[{"id":"1.168133553","rc":[{"batl":[[1,14.5,21.79],[2,15,13.24]],"ltp":13.0,"tv":745.44,"id":27227336},{"batb":[[1,5.7,32.39]],"ltp":5.9,"tv":2832.45,"id":21641292}]}]}
{"op":"mcm","clk":"996743673","pt":1580563529552,"mc":[{"id":"1.168133553","rc":[{"trd":[[1.33,3662.96]],"batl":[[0,1.33,689.05]],"ltp":1.33,"tv":17146.53,"id":16325787}],"tv":20724.43}]}
{"op":"mcm","clk":"996743851","pt":1580563530496,"mc":[{"id":"1.168133553","rc":[{"trd":[[5.8,162.98]],"batb":[[0,5.8,15.99]],"ltp":5.8,"tv":2840.44,"id":21641292}],"tv":20732.42}]}
{"op":"mcm","clk":"996744035","pt":1580563531573,"mc":[{"id":"1.168133553","rc":[{"batl":[[1,14.5,22.01]],"ltp":13.0,"tv":745.44,"id":27227336}]}]}
{"op":"mcm","clk":"996745860","pt":1580563540503,"mc":[{"id":"1.168133553","rc":[{"batl":[[1,14.5,33.13]],"ltp":13.0,"tv":745.44,"id":27227336}]}]}
{"op":"mcm","clk":"996748108","pt":1580563551504,"mc":[{"id":"1.168133553","rc":[{"batl":[[0,13,6.43]],"ltp":13.0,"tv":745.44,"id":27227336},{"trd":[[1.33,3677.3]],"batb":[[0,1.32,46.73]],"batl":[[0,1.33,713.88]],"ltp":1.33,"tv":17160.87,"id":16325787}],"tv":20746.76}]}
{"op":"mcm","clk":"996748344","pt":1580563552499,"mc":[{"id":"1.168133553","rc":[{"batl":[[2,15,10.13]],"ltp":13.0,"tv":745.44,"id":27227336},{"batb":[[1,5.7,38.86]],"ltp":5.8,"tv":2840.44,"id":21641292},{"batb":[[0,1.32,96.73]],"batl":[[0,1.33,681.88]],"ltp":1.33,"tv":17160.87,"id":16325787}]}]}
{"op":"mcm","clk":"996750943","pt":1580563565546,"mc":[{"id":"1.168133553","rc":[{"trd":[[5.8,172.24]],"batb":[[0,5.8,11.36]],"ltp":5.8,"tv":2849.7,"id":21641292}],"tv":20756.02}]}
{"op":"mcm","clk":"996752761","pt":1580563574478,"mc":[{"id":"1.168133553","rc":[{"trd":[[1.32,6495.81]],"batb":[[0,1.32,56.73]],"ltp":1.32,"tv":17240.87,"id":16325787}],"tv":20836.03}]}
{"op":"mcm","clk":"996752951","pt":1580563575489,"mc":[{"id":"1.168133553","rc":[{"trd":[[13,65.48]],"batb":[[0,12.5,12.64]],"batl":[[0,13,2.98]],"ltp":13.0,"tv":752.33,"id":27227336},{"batb":[[1,5.7,32.39]],"ltp":5.8,"tv":2849.7,"id":21641292}],"tv":20842.92}]}
{"op":"mcm","clk":"996753175","pt":1580563576485,"mc":[{"id":"1.168133553","rc":[{"trd":[[1.32,6535.81]],"batb":[[0,1.32,36.73]],"ltp":1.32,"tv":17280.87,"id":16325787}],"tv":20882.92}]}
{"op":"mcm","clk":"996754758","pt":1580563584505,"mc":[{"id":"1.168133553","rc":[{"batl":[[1,14,4],[2,14.5,33.13]],"ltp":13.0,"tv":752.33,"id":27227336},{"batl":[[0,5.9,30.02]],"ltp":5.8,"tv":2849.7,"id":21641292}]}]}
{"op":"mcm","clk":"996756114","pt":1580563591538,"mc":[{"id":"1.168133553","rc":[{"trd":[[13,71.44]],"batb":[[0,13,1.93],[1,12.5,12.64],[2,12,8.18]],"batl":[[0,14,4],[1,14.5,33.13],[2,15,8]],"ltp":13.0,"tv":758.29,"id":27227336},{"batb":[[0,5.8,22.38]],"ltp":5.8,"tv":2849.7,"id":21641292},{"batb":[[0,1.32,85.13]],"ltp":1.32,"tv":17280.87,"id":16325787}],"tv":20888.88}]}
{"op":"mcm","clk":"996756318","pt":1580563592572,"mc":[{"id":"1.168133553","rc":[{"batb":[[2,12,11.52]],"batl":[[0,14,13.17]],"ltp":13.0,"tv":758.29,"id":27227336},{"batb":[[0,5.8,27.02]],"ltp":5.8,"tv":2849.7,"id":21641292},{"batb":[[0,1.32,48.4]],"batl":[[0,1.33,713.88]],"ltp":1.32,"tv":17280.87,"id":16325787}]}]}
{"op":"mcm","clk":"996757700","pt":1580563599485,"mc":[{"id":"1.168133553","rc":[{"batb":[[1,12.5,14.4]],"ltp":13.0,"tv":758.29,"id":27227336}]}]}
{"op":"mcm","clk":"996758109","pt":1580563601498,"mc":[{"id":"1.168133553","rc":[{"trd":[[12.5,9.6],[13,75.3]],"batb":[[0,12.5,9.6],[1,12,11.52],[2,11.5,1]],"batl":[[0,14,19.08]],"ltp":12.5,"tv":771.75,"id":27227336},{"trd":[[1.33,3694.68]],"batl":[[0,1.33,705.19]],"ltp":1.33,"tv":17298.25,"id":16325787}],"tv":20919.72}]}
{"op":"mcm","clk":"996758313","pt":1580563602491,"mc":[{"id":"1.168133553","rc":[{"batb":[[0,12.5,7.84],[1,12,8.18],[2,11.5,5.42]],"batl":[[0,13.5,6.1],[1,14,19.08],[2,14.5,33.13]],"ltp":12.5,"tv":771.75,"id":27227336}]}]}
{"op":"mcm","clk":"996758544","pt":1580563603474,"mc":[{"id":"1.168133553","rc":[{"batl":[[2,14.5,26.39]],"ltp":12.5,"tv":771.75,"id":27227336},{"batb":[[0,1.32,98.4]],"ltp":1.33,"tv":17298.25,"id":16325787}]}]}
{"op":"mcm","clk":"996759575","pt":1580563608470,"mc":[{"id":"1.168133553","rc":[{"batl":[[1,14,15.08]],"ltp":12.5,"tv":771.75,"id":27227336}]}]}
{"op":"mcm","clk":"996761364","pt":1580563617561,"mc":[{"id":"1.168133553","rc":[{"batl":[[1,14,22.07]],"ltp":12.5,"tv":771.75,"id":27227336}]}]}
{"op":"mcm","clk":"996761552","pt":1580563618549,"mc":[{"id":"1.168133553","rc":[{"batb":[[0,13,3.31],[1,12.5,11.84],[2,12,8.18]],"ltp":12.5,"tv":771.75,"id":27227336},{"trd":[[5.8,176.24]],"batb":[[0,5.8,25.02]],"ltp":5.8,"tv":2853.7,"id":21641292}],"tv":20923.72}]}
{"op":"mcm","clk":"996763074","pt":1580563626556,"mc":[{"id":"1.168133553","rc":[{"batb":[[1,12.5,13.6]],"ltp":12.5,"tv":771.75,"id":27227336}]}]}
{"op":"mcm","clk":"996763256","pt":1580563627570,"mc":[{"id":"1.168133553","rc":[{"trd":[[5.8,180.32]],"batb":[[0,5.8,22.98]],"ltp":5.8,"tv":2857.78,"id":21641292}],"tv":20927.8}]}
{"op":"mcm","clk":"996765414","pt":1580563638502,"mc":[{"id":"1.168133553","rc":[{"batl":[[0,1.33,705.39]],"ltp":1.33,"tv":17298.25,"id":16325787}]}]}
{"op":"mcm","clk":"996767338","pt":1580563648501,"mc":[{"id":"1.168133553","rc":[{"trd":[[13,76.56]],"batb":[[0,12.5,9.6],[1,12,8.18],[2,11.5,5.42]],"ltp":13.0,"tv":773.01,"id":27227336},{"batl":[[1,1.34,1584.77]],"ltp":1.33,"tv":17298.25,"id":16325787}],"tv":20929.06}]}
{"op":"mcm","clk":"996767509","pt":1580563649541,"mc":[{"id":"1.168133553","rc":[{"batb":[[0,12.5,7.84]],"ltp":13.0,"tv":773.01,"id":27227336}]}]}
{"op":"mcm","clk":"996769507","pt":1580563659556,"mc":[{"id":"1.168133553","rc":[{"trd":[[1.33,3704.68]],"batl":[[0,1.33,700.39]],"ltp":1.33,"tv":17308.25,"id":16325787}],"tv":20939.06}]}
{"op":"mcm","clk":"996769741","pt":1580563660543,"mc":[{"id":"1.168133553","rc":[{"batb":[[0,12.5,8.49]],"ltp":13.0,"tv":773.01,"id":27227336}]}]}
{"op":"mcm","clk":"996771536","pt":1580563669572,"mc":[{"id":"1.168133553","rc":[{"batl":[[0,1.33,700.59]],"ltp":1.33,"tv":17308.25,"id":16325787}]}]}
{"op":"mcm","clk":"996772413","pt":1580563674475,"mc":[{"id":"1.168133553","rc":[{"batl":[[0,1.33,700.39]],"ltp":1.33,"tv":17308.25,"id":16325787}]}]}
{"op":"mcm","clk":"996773371","pt":1580563679500,"mc":[{"id":"1.168133553","rc":[{"batb":[[0,13,15],[1,12.5,8.49],[2,12,8.18]],"ltp":13.0,"tv":773.01,"id":27227336}]}]}
{"op":"mcm","clk":"996775008","pt":1580563687521,"mc":[{"id":"1.168133553","rc":[{"batb":[[1,12.5,10.25]],"ltp":13.0,"tv":773.01,"id":27227336}]}]}
{"op":"mcm","clk":"996775217","pt":1580563688526,"mc":[{"id":"1.168133553","rc":[{"trd":[[13,91.84]],"batb":[[0,13,13.16]],"ltp":13.0,"tv":788.29,"id":27227336},{"trd":[[1.33,3719.5]],"batl":[[0,1.33,692.98]],"ltp":1.33,"tv":17323.07,"id":16325787}],"tv":20969.16}]}
{"op":"mcm","clk":"996777983","pt":1580563701544,"mc":[{"id":"1.168133553","rc":[{"batl":[[0,1.33,693.18]],"ltp":1.33,"tv":17323.07,"id":16325787}]}]}
{"op":"mcm","clk":"996778196","pt":1580563702545,"mc":[{"id":"1.168133553","rc":[{"batl":[[0,1.33,692.98]],"ltp":1.33,"tv":17323.07,"id":16325787}]}]}
{"op":"mcm","clk":"996783889","pt":1580563729495,"mc":[{"id":"1.168133553","rc":[{"batl":[[0,1.33,692.78]],"ltp":1.33,"tv":17323.07,"id":16325787}]}]}
{"op":"mcm","clk":"996784581","pt":1580563732355,"mc":[{"id":"1.168133553","rc":[{"batl":[[0,1.33,692.98]],"ltp":1.33,"tv":17323.07,"id":16325787}]}]}
{"op":"mcm","clk":"996785382","pt":1580563736504,"mc":[{"id":"1.168133553","rc":[{"trd":[[13,107.66]],"batb":[[0,13,5.25]],"batl":[[0,13.5,9.09]],"ltp":13.0,"tv":804.11,"id":27227336},{"trd":[[5.8,184.32]],"batb":[[0,5.8,20.98]],"ltp":5.8,"tv":2861.78,"id":21641292},{"trd":[[1.33,3728.02]],"batl":[[0,1.33,688.72]],"ltp":1.33,"tv":17331.59,"id":16325787}],"tv":20997.5}]}
{"op":"mcm","clk":"996785561","pt":1580563737485,"mc":[{"id":"1.168133553","rc":[{"batl":[[0,13.5,6.1]],"ltp":13.0,"tv":804.11,"id":27227336}]}]}
{"op":"mcm","clk":"996786463","pt":1580563741548,"mc":[{"id":"1.168133553","rc":[{"trd":[[13.5,112.95]],"batl":[[0,13.5,2.76]],"ltp":13.5,"tv":810.79,"id":27227336}],"tv":21004.18}]}
{"op":"mcm","clk":"996790314","pt":1580563761360,"mc":[{"id":"1.168133553","rc":[{"batl":[[0,1.33,688.52]],"ltp":1.33,"tv":17331.59,"id":16325787}]}]}
{"op":"mcm","clk":"996790912","pt":1580563764400,"mc":[{"id":"1.168133553","rc":[{"batl":[[0,1.33,688.72]],"ltp":1.33,"tv":17331.59,"id":16325787}]}]}
{"op":"mcm","clk":"996791879","pt":1580563769503,"mc":[{"id":"1.168133553","rc":[{"trd":[[13,118.16]],"batb":[[0,12.5,10.25],[1,12,8.18],[2,11.5,5.42]],"batl":[[0,13,2.54],[1,13.5,2.76],[2,14,22.07]],"ltp":13.0,"tv":821.29,"id":27227336},{"trd":[[1.33,3736.42]],"batl":[[0,1.33,684.52]],"ltp":1.33,"tv":17339.99,"id":16325787}],"tv":21023.08}]}
{"op":"mcm","clk":"996792062","pt":1580563770546,"mc":[{"id":"1.168133553","rc":[{"batb":[[0,12.5,8.49]],"batl":[[1,13.5,11.92]],"ltp":13.0,"tv":821.29,"id":27227336},{"batb":[[0,5.8,26.02]],"ltp":5.8,"tv":2861.78,"id":21641292},{"batb":[[1,1.31,242.19]],"batl":[[0,1.33,652.52]],"ltp":1.33,"tv":17339.99,"id":16325787}]}]}
{"op":"mcm","clk":"996795558","pt":1580563788561,"mc":[{"id":"1.168133553","rc":[{"batb":[[2,5.6,37.8]],"ltp":5.8,"tv":2861.78,"id":21641292},{"batb":[[1,1.31,213.36]],"ltp":1.33,"tv":17339.99,"id":16325787}]}]}
{"op":"mcm","clk":"996795743","pt":1580563789555,"mc":[{"id":"1.168133553","rc":[{"batb":[[0,5.8,28.6],[1,5.7,37.28]],"ltp":5.8,"tv":2861.78,"id":21641292},{"batb":[[0,1.32,127.01]],"ltp":1.33,"tv":17339.99,"id":16325787}]}]}
{"op":"mcm","clk":"996796334","pt":1580563792468,"mc":[{"id":"1.168133553","rc":[{"batl":[[0,1.33,652.32]],"ltp":1.33,"tv":17339.99,"id":16325787}]}]}
{"op":"mcm","clk":"996796867","pt":1580563795471,"mc":[{"id":"1.168133553","rc":[{"batl":[[0,1.33,652.52]],"ltp":1.33,"tv":17339.99,"id":16325787}]}]}
{"op":"mcm","clk":"996797784","pt":1580563800477,"mc":[{"id":"1.168133553","rc":[{"trd":[[1.32,6559.81]],"batb":[[0,1.32,115.01]],"ltp":1.32,"tv":17364.0,"id":16325787}],"tv":21047.08}]}
{"op":"mcm","clk":"996799316","pt":1580563807481,"mc":[{"id":"1.168133553","rc":[{"batb":[[2,5.6,28.17]],"ltp":5.8,"tv":2861.78,"id":21641292}]}]}
{"op":"mcm","clk":"996799894","pt":1580563810487,"mc":[{"id":"1.168133553","rc":[{"batl":[[0,13.5,2.76],[1,14,22.07],[2,14.5,26.39]],"ltp":13.0,"tv":821.29,"id":27227336}]}]}
{"op":"mcm","clk":"996800107","pt":1580563811561,"mc":[{"id":"1.168133553","rc":[{"batl":[[0,13,6.38],[1,13.5,11.81],[2,14,25.22]],"ltp":13.0,"tv":821.29,"id":27227336},{"trd":[[1.33,3749.6]],"batl":[[0,1.33,645.93]],"ltp":1.33,"tv":17377.18,"id":16325787}],"tv":21060.26}]}
{"op":"mcm","clk":"996802690","pt":1580563824490,"mc":[{"id":"1.168133553","rc":[{"batl":[[0,1.33,645.73]],"ltp":1.33,"tv":17377.18,"id":16325787}]}]}
{"op":"mcm","clk":"996803228","pt":1580563827502,"mc":[{"id":"1.168133553","rc":[{"batl":[[0,1.33,645.93]],"ltp":1.33,"tv":17377.18,"id":16325787}]}]}
{"op":"mcm","clk":"996807119","pt":1580563848544,"mc":[{"id":"1.168133553","rc":[{"batl":[[0,1.33,747.24]],"ltp":1.33,"tv":17377.18,"id":16325787}]}]}
{"op":"mcm","clk":"996808401","pt":1580563855569,"mc":[{"id":"1.168133553","rc":[{"batl":[[0,1.33,747.04]],"ltp":1.33,"tv":17377.18,"id":16325787}]}]}
{"op":"mcm","clk":"996809139","pt":1580563859542,"mc":[{"id":"1.168133553","rc":[{"batl":[[0,1.33,747.24]],"ltp":1.33,"tv":17377.18,"id":16325787}]}]}
{"op":"mcm","clk":"996810879","pt":1580563868569,"mc":[{"id":"1.168133553","rc":[{"batl":[[0,13.5,2.76],[1,14,25.22],[2,14.5,26.39]],"ltp":13.0,"tv":821.29,"id":27227336},{"batl":[[0,1.33,778.24]],"ltp":1.33,"tv":17377.18,"id":16325787}]}]}
{"op":"mcm","clk":"996811064","pt":1580563869566,"mc":[{"id":"1.168133553","rc":[{"trd":[[12.5,25.25]],"batb":[[0,12,8.86],[1,11.5,5.42],[2,11,1]],"batl":[[0,13.5,5.76]],"ltp":12.5,"tv":836.94,"id":27227336},{"trd":[[1.33,3764.86]],"batl":[[0,1.33,770.61]],"ltp":1.33,"tv":17392.44,"id":16325787}],"tv":21091.17}]}
{"op":"mcm","clk":"996811239","pt":1580563870455,"mc":[{"id":"1.168133553","rc":[{"batl":[[1,14,22.07]],"ltp":12.5,"tv":836.94,"id":27227336}]}]}
{"op":"mcm","clk":"996812406","pt":1580563876483,"mc":[{"id":"1.168133553","rc":[{"trd":[[12.5,29.92]],"batb":[[0,12,8.18]],"ltp":12.5,"tv":841.61,"id":27227336},{"trd":[[5.9,163.11]],"batl":[[0,5.9,22.99]],"ltp":5.9,"tv":2868.81,"id":21641292},{"trd":[[1.33,3796.06]],"batl":[[0,1.33,739.41]],"ltp":1.33,"tv":17423.64,"id":16325787}],"tv":21134.07}]}
{"op":"mcm","clk":"996812617","pt":1580563877496,"mc":[{"id":"1.168133553","rc":[{"batb":[[0,12.5,4.08],[1,12,8.18],[2,11.5,5.42]],"ltp":12.5,"tv":841.61,"id":27227336},{"trd":[[5.8,200.32]],"batb":[[0,5.8,24.92]],"ltp":5.8,"tv":2884.81,"id":21641292}],"tv":21150.07}]}
{"op":"mcm","clk":"996815305","pt":1580563890547,"mc":[{"id":"1.168133553","rc":[{"batb":[[0,12.5,9.16]],"ltp":12.5,"tv":841.61,"id":27227336},{"batl":[[0,1.33,739.61]],"ltp":1.33,"tv":17423.64,"id":16325787}]}]}
{"op":"mcm","clk":"996815530","pt":1580563891523,"mc":[{"id":"1.168133553","rc":[{"trd":[[5.8,206.32]],"batb":[[0,5.8,21.92]],"ltp":5.8,"tv":2890.81,"id":21641292}],"tv":21156.07}]}
{"op":"mcm","clk":"996815705","pt":1580563892521,"mc":[{"id":"1.168133553","rc":[{"batb":[[0,5.8,27.39]],"ltp":5.8,"tv":2890.81,"id":21641292},{"trd":[[1.32,6575.81]],"batb":[[0,1.32,107.01]],"ltp":1.32,"tv":17439.64,"id":16325787}],"tv":21172.07}]}
{"op":"mcm","clk":"996816489","pt":1580563896480,"mc":[{"id":"1.168133553","rc":[{"batl":[[0,1.33,739.41]],"ltp":1.32,"tv":17439.64,"id":16325787}]}]}
{"op":"mcm","clk":"996816874","pt":1580563898505,"mc":[{"id":"1.168133553","rc":[{"trd":[[13.5,123.55]],"batl":[[0,14,22.53],[1,14.5,26.39],[2,15.5,4.35]],"ltp":13.5,"tv":852.22,"id":27227336}],"tv":21182.68}]}
{"op":"mcm","clk":"996817084","pt":1580563899496,"mc":[{"id":"1.168133553","rc":[{"batl":[[0,14,22.07]],"ltp":13.5,"tv":852.22,"id":27227336}]}]}
{"op":"mcm","clk":"996818780","pt":1580563908529,"mc":[{"id":"1.168133553","rc":[{"trd":[[12.5,45.38]],"batb":[[0,12.5,1.43]],"batl":[[0,13.5,3.02],[1,14,22.07],[2,14.5,26.39]],"ltp":12.5,"tv":867.68,"id":27227336},{"trd":[[5.8,222.31]],"batb":[[0,5.8,19.39]],"ltp":5.8,"tv":2906.81,"id":21641292},{"trd":[[1.33,3811.24]],"batl":[[0,1.33,731.82],[2,1.35,1708.76]],"ltp":1.33,"tv":17454.82,"id":16325787}],"tv":21229.31}]}
{"op":"mcm","clk":"996821311","pt":1580563921547,"mc":[{"id":"1.168133553","rc":[{"batl":[[0,1.33,732.02]],"ltp":1.33,"tv":17454.82,"id":16325787}]}]}
{"op":"mcm","clk":"996821546","pt":1580563922557,"mc":[{"id":"1.168133553","rc":[{"trd":[[5.8,226.31]],"batb":[[0,5.8,17.39]],"ltp":5.8,"tv":2910.81,"id":21641292}],"tv":21233.31}]}
{"op":"mcm","clk":"996821927","pt":1580563924475,"mc":[{"id":"1.168133553","rc":[{"batl":[[0,1.33,731.82]],"ltp":1.33,"tv":17454.82,"id":16325787}]}]}
{"op":"mcm","clk":"996823542","pt":1580563932499,"mc":[{"id":"1.168133553","rc":[{"trd":[[12.5,52.76]],"batb":[[0,12,8.18],[1,11.5,5.42],[2,11,1]],"batl":[[0,13.5,3.03]],"ltp":12.5,"tv":875.06,"id":27227336},{"trd":[[5.9,172.7]],"batl":[[0,5.9,13.4]],"ltp":5.9,"tv":2920.4,"id":21641292},{"trd":[[1.32,6591.81],[1.33,3876.54]],"batb":[[0,1.32,99.01]],"batl":[[0,1.33,677.89]],"ltp":1.33,"tv":17536.11,"id":16325787}],"tv":21331.59}]}
{"op":"mcm","clk":"996827148","pt":1580563950495,"mc":[{"id":"1.168133553","rc":[{"batl":[[0,1.33,677.69]],"ltp":1.33,"tv":17536.11,"id":16325787}]}]}
{"op":"mcm","clk":"996827650","pt":1580563952571,"mc":[{"id":"1.168133553","rc":[{"batl":[[0,13.5,11.19]],"ltp":12.5,"tv":875.06,"id":27227336}]}]}
{"op":"mcm","clk":"996827870","pt":1580563953483,"mc":[{"id":"1.168133553","rc":[{"batl":[[0,13.5,3.03]],"ltp":12.5,"tv":875.06,"id":27227336},{"trd":[[5.8,230.31]],"batb":[[0,5.8,25.88],[1,5.7,43.75]],"batl":[[1,6,28.69]],"ltp":5.8,"tv":2924.4,"id":21641292},{"batl":[[0,1.33,677.89]],"ltp":1.33,"tv":17536.11,"id":16325787}],"tv":21335.59}]}
{"op":"mcm","clk":"996828279","pt":1580563955468,"mc":[{"id":"1.168133553","rc":[{"batl":[[2,6.2,10.63]],"ltp":5.8,"tv":2924.4,"id":21641292}]}]}
{"op":"mcm","clk":"996829049","pt":1580563959511,"mc":[{"id":"1.168133553","rc":[{"trd":[[13.5,129.61]],"batl":[[0,14,22.07],[1,14.5,26.39],[2,15.5,4.35]],"ltp":13.5,"tv":881.12,"id":27227336},{"batb":[[0,5.8,30.54],[1,5.7,37.28]],"ltp":5.8,"tv":2924.4,"id":21641292},{"batb":[[0,1.32,49.01]],"ltp":1.33,"tv":17536.11,"id":16325787}],"tv":21341.65}]}
{"op":"mcm","clk":"996833681","pt":1580563980560,"mc":[{"id":"1.168133553","rc":[{"batl":[[0,13.5,4],[1,14,22.07],[2,14.5,26.39]],"ltp":13.5,"tv":881.12,"id":27227336},{"batb":[[0,1.32,104.01]],"ltp":1.33,"tv":17536.11,"id":16325787}]}]}
{"op":"mcm","clk":"996833917","pt":1580563981569,"mc":[{"id":"1.168133553","rc":[{"batl":[[0,1.33,677.69]],"ltp":1.33,"tv":17536.11,"id":16325787}]}]}
{"op":"mcm","clk":"996834777","pt":1580563985503,"mc":[{"id":"1.168133553","rc":[{"batl":[[0,1.33,677.89]],"ltp":1.33,"tv":17536.11,"id":16325787}]}]}
{"op":"mcm","clk":"996837697","pt":1580563999549,"mc":[{"id":"1.168133553","rc":[{"trd":[[12.5,61.54]],"batb":[[0,13,1.15],[1,12.5,5.18],[2,12,8.18]],"ltp":12.5,"tv":889.9,"id":27227336},{"trd":[[5.9,186.1]],"batl":[[0,5.9,5.53],[1,6,34.22]],"ltp":5.9,"tv":2937.8,"id":21641292},{"trd":[[1.33,3951.02]],"batl":[[0,1.33,610.93]],"ltp":1.33,"tv":17610.59,"id":16325787}],"tv":21438.31}]}
{"op":"mcm","clk":"996837900","pt":1580564000542,"mc":[{"id":"1.168133553","rc":[{"batl":[[1,6,27.22]],"ltp":5.9,"tv":2937.8,"id":21641292},{"batl":[[0,1.33,579.93]],"ltp":1.33,"tv":17610.59,"id":16325787}]}]}
{"op":"mcm","clk":"996838078","pt":1580564001570,"mc":[{"id":"1.168133553","rc":[{"batb":[[2,12,10.81]],"ltp":12.5,"tv":889.9,"id":27227336},{"batl":[[1,6,33.22]],"ltp":5.9,"tv":2937.8,"id":21641292},{"batl":[[0,1.33,604.93]],"ltp":1.33,"tv":17610.59,"id":16325787}]}]}
{"op":"mcm","clk":"996840469","pt":1580564013540,"mc":[{"id":"1.168133553","rc":[{"batl":[[0,1.33,604.73]],"ltp":1.33,"tv":17610.59,"id":16325787}]}]}
{"op":"mcm","clk":"996841062","pt":1580564016536,"mc":[{"id":"1.168133553","rc":[{"batl":[[0,1.33,604.93]],"ltp":1.33,"tv":17610.59,"id":16325787}]}]}
{"op":"mcm","clk":"996841248","pt":1580564017556,"mc":[{"id":"1.168133553","rc":[{"trd":[[5.8,234.31]],"batb":[[0,5.8,28.54]],"ltp":5.8,"tv":2941.8,"id":21641292}],"tv":21442.31}]}
{"op":"mcm","clk":"996844686","pt":1580564034565,"mc":[{"id":"1.168133553","rc":[{"trd":[[12.5,73.27],[13,120.46]],"batb":[[0,12,10.81],[1,11.5,5.42],[2,11,1]],"batl":[[0,13.5,7.06]],"ltp":12.5,"tv":903.93,"id":27227336},{"trd":[[5.9,189]],"batl":[[0,6,33.22],[1,6.2,10.63],[2,6.4,33.02]],"ltp":5.9,"tv":2944.7,"id":21641292},{"trd":[[1.33,3984.5]],"batl":[[0,1.33,581.75]],"ltp":1.33,"tv":17644.07,"id":16325787}],"tv":21492.71}]}
{"op":"mcm","clk":"996844864","pt":1580564035483,"mc":[{"id":"1.168133553","rc":[{"batb":[[0,12,6.35],[1,11.5,7.34]],"batl":[[0,13,6.08],[1,13.5,7.06],[2,14,22.07]],"ltp":12.5,"tv":903.93,"id":27227336},{"batl":[[0,6,27.22],[2,6.4,27.39]],"ltp":5.9,"tv":2944.7,"id":21641292},{"batb":[[0,1.32,49.01]],"ltp":1.33,"tv":17644.07,"id":16325787}]}]}
{"op":"mcm","clk":"996845066","pt":1580564036488,"mc":[{"id":"1.168133553","rc":[{"batl":[[1,13.5,15.06]],"ltp":12.5,"tv":903.93,"id":27227336},{"batb":[[0,1.32,106.01]],"ltp":1.33,"tv":17644.07,"id":16325787}]}]}
{"op":"mcm","clk":"996845260","pt":1580564037501,"mc":[{"id":"1.168133553","rc":[{"batl":[[1,13.5,19.47]],"ltp":12.5,"tv":903.93,"id":27227336}]}]}
{"op":"mcm","clk":"996845471","pt":1580564038573,"mc":[{"id":"1.168133553","rc":[{"batl":[[1,13.5,26.46],[2,14,15.08]],"ltp":12.5,"tv":903.93,"id":27227336}]}]}
{"op":"mcm","clk":"996846703","pt":1580564044489,"mc":[{"id":"1.168133553","rc":[{"batl":[[0,1.33,581.55]],"ltp":1.33,"tv":17644.07,"id":16325787}]}]}
{"op":"mcm","clk":"996846906","pt":1580564045476,"mc":[{"id":"1.168133553","rc":[{"batl":[[1,13.5,22.46]],"ltp":12.5,"tv":903.93,"id":27227336}]}]}
{"op":"mcm","clk":"996847303","pt":1580564047520,"mc":[{"id":"1.168133553","rc":[{"batl":[[0,1.33,581.75]],"ltp":1.33,"tv":17644.07,"id":16325787}]}]}
{"op":"mcm","clk":"996847712","pt":1580564049548,"mc":[{"id":"1.168133553","rc":[{"batl":[[1,13.5,15.47],[2,14,22.07]],"ltp":12.5,"tv":903.93,"id":27227336}]}]}
{"op":"mcm","clk":"996849458","pt":1580564058515,"mc":[{"id":"1.168133553","rc":[{"trd":[[13,132.58]],"batl":[[0,13.5,15.49],[1,14,22.07],[2,14.5,26.39]],"ltp":13.0,"tv":916.05,"id":27227336},{"batb":[[0,1.32,49.01]],"ltp":1.33,"tv":17644.07,"id":16325787}],"tv":21504.83}]}
{"op":"mcm","clk":"996849641","pt":1580564059540,"mc":[{"id":"1.168133553","rc":[{"batl":[[0,13.5,11.08]],"ltp":13.0,"tv":916.05,"id":27227336}]}]}
{"op":"mcm","clk":"996849829","pt":1580564060554,"mc":[{"id":"1.168133553","rc":[{"batl":[[0,13.5,15.39],[1,14,24.93]],"ltp":13.0,"tv":916.05,"id":27227336}]}]}
{"op":"mcm","clk":"996850999","pt":1580564066567,"mc":[{"id":"1.168133553","rc":[{"batb":[[0,5.8,32.74]],"ltp":5.9,"tv":2944.7,"id":21641292}]}]}
{"op":"mcm","clk":"996853656","pt":1580564079500,"mc":[{"id":"1.168133553","rc":[{"batl":[[0,1.33,581.95]],"ltp":1.33,"tv":17644.07,"id":16325787}]}]}
{"op":"mcm","clk":"996853890","pt":1580564080499,"mc":[{"id":"1.168133553","rc":[{"batl":[[2,6.4,33.02]],"ltp":5.9,"tv":2944.7,"id":21641292}]}]}
{"op":"mcm","clk":"996854106","pt":1580564081508,"mc":[{"id":"1.168133553","rc":[{"batl":[[0,12.5,6.33],[1,13.5,19.07],[2,14,24.93]],"ltp":13.0,"tv":916.05,"id":27227336},{"batl":[[0,6,21.69]],"ltp":5.9,"tv":2944.7,"id":21641292},{"trd":[[1.33,4002.76]],"batl":[[0,1.33,572.82]],"ltp":1.33,"tv":17662.33,"id":16325787}],"tv":21523.09}]}
{"op":"mcm","clk":"996854337","pt":1580564082509,"mc":[{"id":"1.168133553","rc":[{"batb":[[0,12,2]],"batl":[[1,13.5,26.06],[2,14,17.94]],"ltp":13.0,"tv":916.05,"id":27227336}]}]}
{"op":"mcm","clk":"996854541","pt":1580564083487,"mc":[{"id":"1.168133553","rc":[{"batb":[[0,5.9,11.23],[1,5.8,39.07],[2,5.7,37.28]],"ltp":5.9,"tv":2944.7,"id":21641292},{"batl":[[0,1.33,542.88],[1,1.34,1614.7]],"ltp":1.33,"tv":17662.33,"id":16325787}]}]}
{"op":"mcm","clk":"996854762","pt":1580564084500,"mc":[{"id":"1.168133553","rc":[{"batl":[[0,1.33,542.68]],"ltp":1.33,"tv":17662.33,"id":16325787}]}]}
{"op":"mcm","clk":"996855190","pt":1580564086489,"mc":[{"id":"1.168133553","rc":[{"trd":[[12.5,85.94]],"batl":[[0,13.5,26.06],[1,14,17.94],[2,14.5,26.39]],"ltp":12.5,"tv":928.71,"id":27227336},{"batl":[[2,6.4,27.39]],"ltp":5.9,"tv":2944.7,"id":21641292}],"tv":21535.75}]}
{"op":"mcm","clk":"996855429","pt":1580564087567,"mc":[{"id":"1.168133553","rc":[{"batl":[[0,13.5,22.38]],"ltp":12.5,"tv":928.71,"id":27227336}]}]}
{"op":"mcm","clk":"996855836","pt":1580564089511,"mc":[{"id":"1.168133553","rc":[{"batb":[[1,5.8,32.74]],"ltp":5.9,"tv":2944.7,"id":21641292}]}]}
{"op":"mcm","clk":"996856475","pt":1580564092481,"mc":[{"id":"1.168133553","rc":[{"batl":[[0,13.5,15.39],[1,14,24.93]],"ltp":12.5,"tv":928.71,"id":27227336}]}]}
{"op":"mcm","clk":"996857560","pt":1580564097523,"mc":[{"id":"1.168133553","rc":[{"batl":[[0,1.33,572.62],[1,1.34,1584.77]],"ltp":1.33,"tv":17662.33,"id":16325787}]}]}
{"op":"mcm","clk":"996860161","pt":1580564109556,"mc":[{"id":"1.168133553","rc":[{"batb":[[0,1.32,53.01]],"ltp":1.33,"tv":17662.33,"id":16325787}]}]}
{"op":"mcm","clk":"996860342","pt":1580564110487,"mc":[{"id":"1.168133553","rc":[{"trd":[[5.9,193]],"batb":[[0,5.9,9.23]],"ltp":5.9,"tv":2948.7,"id":21641292}],"tv":21539.75}]}
{"op":"mcm","clk":"996860554","pt":1580564111475,"mc":[{"id":"1.168133553","rc":[{"batl":[[2,6.4,33.39]],"ltp":5.9,"tv":2948.7,"id":21641292},{"batb":[[1,1.31,217.36]],"batl":[[0,1.33,572.82]],"ltp":1.33,"tv":17662.33,"id":16325787}]}]}
{"op":"mcm","clk":"996860781","pt":1580564112491,"mc":[{"id":"1.168133553","rc":[{"batb":[[2,1.3,402.24]],"batl":[[0,1.33,572.62]],"ltp":1.33,"tv":17662.33,"id":16325787}]}]}
{"op":"mcm","clk":"996862193","pt":1580564119493,"mc":[{"id":"1.168133553","rc":[{"batl":[[0,13,4.33],[1,13.5,15.37],[2,14,24.93]],"ltp":12.5,"tv":928.71,"id":27227336}]}]}
{"op":"mcm","clk":"996862816","pt":1580564122512,"mc":[{"id":"1.168133553","rc":[{"batl":[[1,13.5,22.36],[2,14,17.94]],"ltp":12.5,"tv":928.71,"id":27227336}]}]}
{"op":"mcm","clk":"996864242","pt":1580564129522,"mc":[{"id":"1.168133553","rc":[{"batb":[[1,1.31,267.36]],"ltp":1.33,"tv":17662.33,"id":16325787}]}]}
{"op":"mcm","clk":"996865263","pt":1580564134446,"mc":[{"id":"1.168133553","rc":[{"batl":[[1,13.5,22.62]],"ltp":12.5,"tv":928.71,"id":27227336}]}]}
{"op":"mcm","clk":"996865732","pt":1580564136542,"mc":[{"id":"1.168133553","rc":[{"trd":[[12,22.99]],"batb":[[0,11.5,7.34],[1,11,1],[2,10.5,6.39]],"ltp":12.0,"tv":937.06,"id":27227336},{"trd":[[6,123.54]],"batl":[[0,6,12.99]],"ltp":6.0,"tv":2957.4,"id":21641292},{"trd":[[1.33,4066.01]],"batl":[[0,1.33,521.37]],"ltp":1.33,"tv":17725.58,"id":16325787}],"tv":21620.05}]}
{"op":"mcm","clk":"996865919","pt":1580564137540,"mc":[{"id":"1.168133553","rc":[{"batb":[[0,12,5.76],[1,11.5,7.34],[2,11,1]],"batl":[[0,13,7.45]],"ltp":12.0,"tv":937.06,"id":27227336}]}]}
{"op":"mcm","clk":"996867027","pt":1580564142561,"mc":[{"id":"1.168133553","rc":[{"batl":[[0,1.33,521.57]],"ltp":1.33,"tv":17725.58,"id":16325787}]}]}
{"op":"mcm","clk":"996868251","pt":1580564148497,"mc":[{"id":"1.168133553","rc":[{"batl":[[0,1.33,521.37]],"ltp":1.33,"tv":17725.58,"id":16325787}]}]}
{"op":"mcm","clk":"996869046","pt":1580564152492,"mc":[{"id":"1.168133553","rc":[{"batb":[[0,1.32,111.01]],"ltp":1.33,"tv":17725.58,"id":16325787}]}]}
{"op":"mcm","clk":"996870705","pt":1580564160539,"mc":[{"id":"1.168133553","rc":[{"batb":[[2,5.7,23.04]],"ltp":6.0,"tv":2957.4,"id":21641292}]}]}
{"op":"mcm","clk":"996870895","pt":1580564161529,"mc":[{"id":"1.168133553","rc":[{"batl":[[0,13,15.45]],"ltp":12.0,"tv":937.06,"id":27227336},{"trd":[[6,149.52]],"batb":[[0,5.9,9.77],[1,5.8,46.08]],"batl":[[0,6.2,10.63],[1,6.4,33.39],[2,6.6,33.72]],"ltp":6.0,"tv":2983.38,"id":21641292},{"batb":[[0,1.32,53.01]],"ltp":1.33,"tv":17725.58,"id":16325787}],"tv":21646.04}]}
{"op":"mcm","clk":"996871057","pt":1580564162425,"mc":[{"id":"1.168133553","rc":[{"batb":[[1,11.5,2.92]],"ltp":12.0,"tv":937.06,"id":27227336},{"batb":[[0,5.9,14.53],[1,5.8,52.68]],"batl":[[0,6.2,6.03],[2,6.6,32.07]],"ltp":6.0,"tv":2983.38,"id":21641292}]}]}
{"op":"mcm","clk":"996872304","pt":1580564168508,"mc":[{"id":"1.168133553","rc":[{"batb":[[0,5.9,13.99]],"ltp":6.0,"tv":2983.38,"id":21641292}]}]}
{"op":"mcm","clk":"996872521","pt":1580564169541,"mc":[{"id":"1.168133553","rc":[{"trd":[[6.2,33.39]],"batb":[[1,5.8,46.08]],"batl":[[0,6.2,5.51]],"ltp":6.2,"tv":2984.42,"id":21641292}],"tv":21647.08}]}
{"op":"mcm","clk":"996872746","pt":1580564170574,"mc":[{"id":"1.168133553","rc":[{"trd":[[12,34.51]],"batb":[[0,11.5,2.92],[1,11,1],[2,10.5,6.39]],"batl":[[0,12,1.01],[1,13,15.45],[2,13.5,22.62]],"ltp":12.0,"tv":948.58,"id":27227336},{"batb":[[0,5.9,24.9]],"batl":[[0,6.4,33.39],[1,6.6,32.07],[2,6.8,4.68]],"ltp":6.2,"tv":2984.42,"id":21641292},{"trd":[[1.33,4086.65]],"batb":[[0,1.32,113.01]],"batl":[[0,1.33,511.05]],"ltp":1.33,"tv":17746.22,"id":16325787}],"tv":21679.24}]}
{"op":"mcm","clk":"996872970","pt":1580564171558,"mc":[{"id":"1.168133553","rc":[{"trd":[[12,35.52]],"batb":[[0,11.5,1],[2,10.5,18.9]],"batl":[[0,13,15.45],[1,13.5,25.77],[2,14,17.94]],"ltp":12.0,"tv":949.59,"id":27227336},{"trd":[[5.9,194.96],[6,151.54]],"batb":[[0,5.9,23.92]],"ltp":5.9,"tv":2988.4,"id":21641292},{"trd":[[1.33,4095.76]],"batb":[[0,1.32,53.01]],"batl":[[0,1.33,501.94]],"ltp":1.33,"tv":17755.33,"id":16325787}],"tv":21693.34}]}
{"op":"mcm","clk":"996873181","pt":1580564172544,"mc":[{"id":"1.168133553","rc":[{"batb":[[0,11.5,15.4],[2,10.5,12.42]],"batl":[[1,13.5,22.62]],"ltp":12.0,"tv":949.59,"id":27227336},{"batb":[[1,1.31,202.32]],"ltp":1.33,"tv":17755.33,"id":16325787}]}]}
{"op":"mcm","clk":"996873401","pt":1580564173547,"mc":[{"id":"1.168133553","rc":[{"batl":[[0,1.33,502.14]],"ltp":1.33,"tv":17755.33,"id":16325787}]}]}
{"op":"mcm","clk":"996873620","pt":1580564174546,"mc":[{"id":"1.168133553","rc":[{"batb":[[0,11.5,19.82]],"ltp":12.0,"tv":949.59,"id":27227336}]}]}
{"op":"mcm","clk":"996874084","pt":1580564176457,"mc":[{"id":"1.168133553","rc":[{"batb":[[2,10.5,14.59]],"ltp":12.0,"tv":949.59,"id":27227336},{"batl":[[0,1.33,501.94]],"ltp":1.33,"tv":17755.33,"id":16325787}]}]}
{"op":"mcm","clk":"996874720","pt":1580564179546,"mc":[{"id":"1.168133553","rc":[{"trd":[[5.9,214.96]],"batb":[[0,6,9.1],[1,5.9,18.04],[2,5.8,46.08]],"ltp":5.9,"tv":3008.4,"id":21641292},{"batl":[[1,1.34,1576.77]],"ltp":1.33,"tv":17755.33,"id":16325787}],"tv":21713.33}]}
{"op":"mcm","clk":"996874932","pt":1580564180520,"mc":[{"id":"1.168133553","rc":[{"batb":[[1,11,3.02],[2,10.5,17.83]],"ltp":12.0,"tv":949.59,"id":27227336},{"batb":[[1,5.9,24.37],[2,5.8,39.75]],"ltp":5.9,"tv":3008.4,"id":21641292}]}]}
{"op":"mcm","clk":"996875346","pt":1580564182518,"mc":[{"id":"1.168133553","rc":[{"batl":[[0,6.4,61.4]],"ltp":5.9,"tv":3008.4,"id":21641292}]}]}
{"op":"mcm","clk":"996876202","pt":1580564186509,"mc":[{"id":"1.168133553","rc":[{"trd":[[1.32,6595.81]],"batb":[[0,1.32,51.01]],"ltp":1.32,"tv":17759.33,"id":16325787}],"tv":21717.33}]}
{"op":"mcm","clk":"996878170","pt":1580564195487,"mc":[{"id":"1.168133553","rc":[{"trd":[[1.33,4247.76]],"batl":[[0,1.33,425.94]],"ltp":1.33,"tv":17911.33,"id":16325787}],"tv":21869.33}]}
{"op":"mcm","clk":"996878379","pt":1580564196518,"mc":[{"id":"1.168133553","rc":[{"trd":[[6,167.18]],"batb":[[0,6,1.28],[1,5.9,18.91]],"batl":[[0,6.2,11.47],[1,6.4,61.4],[2,6.6,32.07]],"ltp":6.0,"tv":3024.04,"id":21641292},{"batl":[[0,1.33,491.75]],"ltp":1.33,"tv":17911.33,"id":16325787}],"tv":21884.97}]}
{"op":"mcm","clk":"996878558","pt":1580564197498,"mc":[{"id":"1.168133553","rc":[{"batb":[[1,5.9,12.58],[2,5.8,55.53]],"ltp":6.0,"tv":3024.04,"id":21641292}]}]}
{"op":"mcm","clk":"996879574","pt":1580564202533,"mc":[{"id":"1.168133553","rc":[{"batb":[[0,11.5,5.42]],"ltp":12.0,"tv":949.59,"id":27227336},{"batl":[[1,6.4,33.39]],"ltp":6.0,"tv":3024.04,"id":21641292}]}]}
{"op":"mcm","clk":"996879757","pt":1580564203528,"mc":[{"id":"1.168133553","rc":[{"batb":[[0,11.5,1]],"ltp":12.0,"tv":949.59,"id":27227336},{"batb":[[1,1.31,267.36]],"ltp":1.33,"tv":17911.33,"id":16325787}]}]}
{"op":"mcm","clk":"996880206","pt":1580564205542,"mc":[{"id":"1.168133553","rc":[{"batb":[[2,10.5,12.42]],"ltp":12.0,"tv":949.59,"id":27227336},{"batl":[[0,1.33,491.95]],"ltp":1.33,"tv":17911.33,"id":16325787}]}]}
{"op":"mcm","clk":"996881339","pt":1580564210545,"mc":[{"id":"1.168133553","rc":[{"batl":[[0,1.33,491.75]],"ltp":1.33,"tv":17911.33,"id":16325787}]}]}
{"op":"mcm","clk":"996881755","pt":1580564212574,"mc":[{"id":"1.168133553","rc":[{"batb":[[2,5.8,52.95]],"ltp":6.0,"tv":3024.04,"id":21641292},{"batb":[[0,1.32,22.4]],"ltp":1.33,"tv":17911.33,"id":16325787}]}]}
{"op":"mcm","clk":"996882162","pt":1580564214571,"mc":[{"id":"1.168133553","rc":[{"batl":[[0,12.5,4],[1,13,15.45],[2,13.5,22.62]],"ltp":12.0,"tv":949.59,"id":27227336}]}]}
{"op":"mcm","clk":"996882559","pt":1580564216570,"mc":[{"id":"1.168133553","rc":[{"batb":[[1,5.9,18.91],[2,5.8,46.62]],"ltp":6.0,"tv":3024.04,"id":21641292}]}]}
{"op":"mcm","clk":"996882765","pt":1580564217562,"mc":[{"id":"1.168133553","rc":[{"trd":[[12.5,91.33]],"batl":[[0,12.5,1.3]],"ltp":12.5,"tv":954.99,"id":27227336}],"tv":21890.37}]}
{"op":"mcm","clk":"996882965","pt":1580564218548,"mc":[{"id":"1.168133553","rc":[{"batl":[[2,13.5,27.16]],"ltp":12.5,"tv":954.99,"id":27227336}]}]}
{"op":"mcm","clk":"996885518","pt":1580564230514,"mc":[{"id":"1.168133553","rc":[{"batl":[[0,12,6.86],[1,12.5,13.59],[2,13,22.98]],"ltp":12.5,"tv":954.99,"id":27227336},{"batb":[[0,6,8]],"batl":[[0,6.2,5.47]],"ltp":6.0,"tv":3024.04,"id":21641292},{"trd":[[1.33,4264.18]],"batb":[[0,1.32,90.45],[2,1.3,420.24]],"batl":[[0,1.33,483.54],[2,1.35,1700.76]],"ltp":1.33,"tv":17927.75,"id":16325787}],"tv":21906.79}]}
{"op":"mcm","clk":"996885705","pt":1580564231479,"mc":[{"id":"1.168133553","rc":[{"batb":[[0,11.5,1.87]],"ltp":12.5,"tv":954.99,"id":27227336},{"trd":[[6,173.18],[6.2,36.65]],"batb":[[0,6,5]],"batl":[[0,6.2,3.84]],"ltp":6.2,"tv":3033.29,"id":21641292},{"batb":[[0,1.32,98.09]],"ltp":1.33,"tv":17927.75,"id":16325787}],"tv":21916.05}]}
{"op":"mcm","clk":"996886910","pt":1580564237550,"mc":[{"id":"1.168133553","rc":[{"batl":[[1,12.5,12.29]],"ltp":12.5,"tv":954.99,"id":27227336},{"batl":[[0,1.33,483.74]],"ltp":1.33,"tv":17927.75,"id":16325787}]}]}
{"op":"mcm","clk":"996887095","pt":1580564238555,"mc":[{"id":"1.168133553","rc":[{"batb":[[0,11.5,4.8]],"ltp":12.5,"tv":954.99,"id":27227336},{"batb":[[0,6,7.5],[1,5.9,24.91],[2,5.8,42.62]],"ltp":6.2,"tv":3033.29,"id":21641292},{"batb":[[0,1.32,110.65]],"batl":[[0,1.33,473.54],[1,1.34,1568.77],[2,1.35,1693.76]],"ltp":1.33,"tv":17927.75,"id":16325787}]}]}
{"op":"mcm","clk":"996888265","pt":1580564244514,"mc":[{"id":"1.168133553","rc":[{"batl":[[1,12.5,19.82],[2,13,15.45]],"ltp":12.5,"tv":954.99,"id":27227336}]}]}
{"op":"mcm","clk":"996901169","pt":1580564256534,"mc":[{"id":"1.168133553","rc":[{"batl":[[1,12.5,20.12]],"ltp":12.5,"tv":954.99,"id":27227336}]}]}
{"op":"mcm","clk":"996901567","pt":1580564258537,"mc":[{"id":"1.168133553","rc":[{"trd":[[12,37.28]],"batl":[[0,12,5.98]],"ltp":12.0,"tv":956.75,"id":27227336}],"tv":21917.81}]}
{"op":"mcm","clk":"996901917","pt":1580564260550,"mc":[{"id":"1.168133553","rc":[{"trd":[[1.33,4304.18]],"batl":[[0,1.33,453.54]],"ltp":1.33,"tv":17967.75,"id":16325787}],"tv":21957.81}]}
{"op":"mcm","clk":"996902357","pt":1580564262532,"mc":[{"id":"1.168133553","rc":[{"batb":[[0,6,12.96]],"ltp":6.2,"tv":3033.29,"id":21641292},{"trd":[[1.32,6605.81]],"batb":[[0,1.32,105.65]],"ltp":1.32,"tv":17977.75,"id":16325787}],"tv":21967.81}]}
{"op":"mcm","clk":"996902782","pt":1580564264548,"mc":[{"id":"1.168133553","rc":[{"trd":[[12,43.26]],"batl":[[0,12.5,20.12],[1,13,15.45],[2,13.5,15.37]],"ltp":12.0,"tv":962.73,"id":27227336},{"trd":[[6,261.22]],"batb":[[0,6,6]],"ltp":6.0,"tv":3121.33,"id":21641292},{"trd":[[1.33,4358.13]],"batl":[[0,1.33,333.78]],"ltp":1.33,"tv":18031.7,"id":16325787}],"tv":22115.77}]}
{"op":"mcm","clk":"996902996","pt":1580564265538,"mc":[{"id":"1.168133553","rc":[{"batb":[[1,5.9,20.79]],"ltp":6.0,"tv":3121.33,"id":21641292},{"batb":[[2,1.3,403.24]],"ltp":1.33,"tv":18031.7,"id":16325787}]}]}
{"op":"mcm","clk":"996903170","pt":1580564266551,"mc":[{"id":"1.168133553","rc":[{"batb":[[0,12,5.3],[1,11.5,4.8],[2,11,3.02]],"batl":[[0,12.5,12.29],[1,13,22.98]],"ltp":12.0,"tv":962.73,"id":27227336},{"batb":[[0,6,16.31]],"batl":[[0,6.2,10.09]],"ltp":6.0,"tv":3121.33,"id":21641292},{"batl":[[0,1.33,406.81]],"ltp":1.33,"tv":18031.7,"id":16325787}]}]}
{"op":"mcm","clk":"996903365","pt":1580564267547,"mc":[{"id":"1.168133553","rc":[{"batb":[[1,11.5,9.37]],"ltp":12.0,"tv":962.73,"id":27227336}]}]}
{"op":"mcm","clk":"996903602","pt":1580564268545,"mc":[{"id":"1.168133553","rc":[{"trd":[[1.33,4378.13]],"batl":[[0,1.33,397.01]],"ltp":1.33,"tv":18051.7,"id":16325787}],"tv":22135.77}]}
{"op":"mcm","clk":"996904379","pt":1580564272573,"mc":[{"id":"1.168133553","rc":[{"batb":[[1,1.31,489.36]],"ltp":1.33,"tv":18051.7,"id":16325787}]}]}
{"op":"mcm","clk":"996904566","pt":1580564273559,"mc":[{"id":"1.168133553","rc":[{"batb":[[1,5.9,24.91]],"ltp":6.0,"tv":3121.33,"id":21641292}]}]}
{"op":"mcm","clk":"996904742","pt":1580564274552,"mc":[{"id":"1.168133553","rc":[{"batb":[[1,11.5,11.29]],"ltp":12.0,"tv":962.73,"id":27227336},{"batl":[[0,1.33,396.81]],"ltp":1.33,"tv":18051.7,"id":16325787}]}]}
{"op":"mcm","clk":"996905370","pt":1580564277492,"mc":[{"id":"1.168133553","rc":[{"batl":[[2,6.6,37.31]],"ltp":6.0,"tv":3121.33,"id":21641292}]}]}
{"op":"mcm","clk":"996905538","pt":1580564278485,"mc":[{"id":"1.168133553","rc":[{"trd":[[6,265.22]],"batb":[[0,6,14.31]],"ltp":6.0,"tv":3125.33,"id":21641292}],"tv":22139.77}]}
{"op":"mcm","clk":"996905727","pt":1580564279480,"mc":[{"id":"1.168133553","rc":[{"batb":[[0,11.5,11.29],[1,11,9.2],[2,10.5,8.52]],"ltp":12.0,"tv":962.73,"id":27227336},{"batb":[[0,6,17.31]],"batl":[[0,6.2,3.84]],"ltp":6.0,"tv":3125.33,"id":21641292}]}]}
{"op":"mcm","clk":"996905946","pt":1580564280484,"mc":[{"id":"1.168133553","rc":[{"batb":[[0,11.5,4.8]],"ltp":12.0,"tv":962.73,"id":27227336},{"batb":[[1,5.9,18.58]],"ltp":6.0,"tv":3125.33,"id":21641292}]}]}
{"op":"mcm","clk":"996906196","pt":1580564281574,"mc":[{"id":"1.168133553","rc":[{"batb":[[1,11,3.02]],"ltp":12.0,"tv":962.73,"id":27227336},{"batb":[[0,6,23.64]],"ltp":6.0,"tv":3125.33,"id":21641292}]}]}
{"op":"mcm","clk":"996906300","pt":1580564282193,"mc":[{"id":"1.168133553","rc":[{"batl":[[2,6.6,32.07]],"ltp":6.0,"tv":3125.33,"id":21641292}]}]}
{"op":"mcm","clk":"996906591","pt":1580564283493,"mc":[{"id":"1.168133553","rc":[{"batb":[[0,11.5,19.2]],"ltp":12.0,"tv":962.73,"id":27227336}]}]}
{"op":"mcm","clk":"996906789","pt":1580564284494,"mc":[{"id":"1.168133553","rc":[{"batb":[[0,11.5,23.4]],"ltp":12.0,"tv":962.73,"id":27227336}]}]}
{"op":"mcm","clk":"996907186","pt":1580564286488,"mc":[{"id":"1.168133553","rc":[{"batb":[[0,6,17.31],[1,5.9,24.91]],"ltp":6.0,"tv":3125.33,"id":21641292}]}]}
{"op":"mcm","clk":"996907388","pt":1580564287486,"mc":[{"id":"1.168133553","rc":[{"trd":[[6,277.22]],"batb":[[0,6,11.31]],"ltp":6.0,"tv":3137.33,"id":21641292}],"tv":22151.77}]}
{"op":"mcm","clk":"996908628","pt":1580564293471,"mc":[{"id":"1.168133553","rc":[{"batb":[[0,6,15.31]],"batl":[[0,6.2,11.91],[1,6.4,61.4]],"ltp":6.0,"tv":3137.33,"id":21641292}]}]}
{"op":"mcm","clk":"996909615","pt":1580564298463,"mc":[{"id":"1.168133553","rc":[{"trd":[[1.32,6609.17]],"batb":[[0,1.32,103.97]],"ltp":1.32,"tv":18055.07,"id":16325787}],"tv":22155.13}]}
{"op":"mcm","clk":"996909800","pt":1580564299542,"mc":[{"id":"1.168133553","rc":[{"batl":[[0,1.33,397.01]],"ltp":1.32,"tv":18055.07,"id":16325787}]}]}
{"op":"mcm","clk":"996910375","pt":1580564302562,"mc":[{"id":"1.168133553","rc":[{"trd":[[12.5,115.57]],"batl":[[0,13,23.16],[1,13.5,15.37],[2,14,5.91]],"ltp":12.5,"tv":986.96,"id":27227336},{"batl":[[0,1.33,396.81]],"ltp":1.32,"tv":18055.07,"id":16325787}],"tv":22179.36}]}
{"op":"mcm","clk":"996910556","pt":1580564303557,"mc":[{"id":"1.168133553","rc":[{"batb":[[0,11.5,9]],"batl":[[0,13,15.63],[1,13.5,22.62]],"ltp":12.5,"tv":986.96,"id":27227336},{"batl":[[1,6.4,33.39]],"ltp":6.0,"tv":3137.33,"id":21641292},{"batb":[[0,1.32,51.97]],"ltp":1.32,"tv":18055.07,"id":16325787}]}]}
{"op":"mcm","clk":"996910731","pt":1580564304554,"mc":[{"id":"1.168133553","rc":[{"batb":[[0,11.5,4.8]],"batl":[[0,13,15.45],[1,13.5,27.24]],"ltp":12.5,"tv":986.96,"id":27227336}]}]}
{"op":"mcm","clk":"996911122","pt":1580564306541,"mc":[{"id":"1.168133553","rc":[{"batl":[[1,13.5,22.62]],"ltp":12.5,"tv":986.96,"id":27227336}]}]}
{"op":"mcm","clk":"996912104","pt":1580564311562,"mc":[{"id":"1.168133553","rc":[{"batl":[[2,6.6,40.07]],"ltp":6.0,"tv":3137.33,"id":21641292}]}]}
{"op":"mcm","clk":"996912933","pt":1580564315492,"mc":[{"id":"1.168133553","rc":[{"trd":[[11.5,11.15]],"batb":[[0,11.5,3.19]],"ltp":11.5,"tv":997.57,"id":27227336},{"trd":[[6.2,38.5]],"batl":[[0,6.2,10.06],[1,6.4,36.39]],"ltp":6.2,"tv":3139.18,"id":21641292},{"trd":[[1.33,4428.1]],"batb":[[1,1.31,507.36],[2,1.3,425.24]],"batl":[[0,1.33,375.5],[1,1.34,1576.77],[2,1.35,1701.76]],"ltp":1.33,"tv":18105.04,"id":16325787}],"tv":22241.79}]}
{"op":"mcm","clk":"996913123","pt":1580564316503,"mc":[{"id":"1.168133553","rc":[{"trd":[[6,281.22],[6.2,42.47],[6.4,127.25]],"batb":[[0,6,13.31]],"batl":[[0,6.4,36.38],[1,6.6,40.07],[2,6.8,4.68]],"ltp":6.4,"tv":3147.18,"id":21641292}],"tv":22249.79}]}
{"op":"mcm","clk":"996913331","pt":1580564317518,"mc":[{"id":"1.168133553","rc":[{"batb":[[1,1.31,442.32]],"ltp":1.33,"tv":18105.04,"id":16325787}]}]}
{"op":"mcm","clk":"996914566","pt":1580564323479,"mc":[{"id":"1.168133553","rc":[{"batb":[[0,11.5,17.59]],"ltp":11.5,"tv":997.57,"id":27227336}]}]}
{"op":"mcm","clk":"996914750","pt":1580564324477,"mc":[{"id":"1.168133553","rc":[{"batb":[[0,11.5,21.78]],"ltp":11.5,"tv":997.57,"id":27227336}]}]}
{"op":"mcm","clk":"996915378","pt":1580564327521,"mc":[{"id":"1.168133553","rc":[{"batl":[[0,1.33,375.3]],"ltp":1.33,"tv":18105.04,"id":16325787}]}]}
{"op":"mcm","clk":"996916222","pt":1580564331515,"mc":[{"id":"1.168133553","rc":[{"batl":[[0,1.33,375.5]],"ltp":1.33,"tv":18105.04,"id":16325787}]}]}
{"op":"mcm","clk":"996916611","pt":1580564333531,"mc":[{"id":"1.168133553","rc":[{"batl":[[1,13.5,15.37],[2,14,12.9]],"ltp":11.5,"tv":997.57,"id":27227336},{"batl":[[0,6.2,9.29],[1,6.4,64.39],[2,6.6,40.07]],"ltp":6.4,"tv":3147.18,"id":21641292}]}]}
{"op":"mcm","clk":"996916832","pt":1580564334531,"mc":[{"id":"1.168133553","rc":[{"batl":[[2,6.6,45.5]],"ltp":6.4,"tv":3147.18,"id":21641292}]}]}
{"op":"mcm","clk":"996918066","pt":1580564340479,"mc":[{"id":"1.168133553","rc":[{"batl":[[2,6.6,40.07]],"ltp":6.4,"tv":3147.18,"id":21641292}]}]}
{"op":"mcm","clk":"996918275","pt":1580564341516,"mc":[{"id":"1.168133553","rc":[{"trd":[[6,281.42]],"batb":[[0,6,13.21]],"ltp":6.0,"tv":3147.38,"id":21641292},{"batb":[[1,1.31,507.36]],"ltp":1.33,"tv":18105.04,"id":16325787}],"tv":22249.99}]}
{"op":"mcm","clk":"996918669","pt":1580564343507,"mc":[{"id":"1.168133553","rc":[{"batb":[[0,11.5,7.38]],"ltp":11.5,"tv":997.57,"id":27227336},{"batl":[[0,6.4,36.38],[1,6.6,40.07],[2,6.8,4.68]],"ltp":6.0,"tv":3147.38,"id":21641292}]}]}
{"op":"mcm","clk":"996918863","pt":1580564344540,"mc":[{"id":"1.168133553","rc":[{"batb":[[0,11.5,3.19]],"ltp":11.5,"tv":997.57,"id":27227336},{"batb":[[1,1.31,442.32]],"ltp":1.33,"tv":18105.04,"id":16325787}]}]}
{"op":"mcm","clk":"996919070","pt":1580564345509,"mc":[{"id":"1.168133553","rc":[{"trd":[[11.5,17.53]],"batb":[[0,11,9.03],[1,10.5,9.32],[2,10,35.03]],"batl":[[0,11.5,3.72],[1,13,15.43],[2,13.5,15.37]],"ltp":11.5,"tv":1003.95,"id":27227336},{"batb":[[0,6,31.51],[2,5.8,33.17]],"batl":[[0,6.4,27.38]],"ltp":6.0,"tv":3147.38,"id":21641292},{"trd":[[1.33,4449.96]],"batb":[[0,1.32,124.99]],"batl":[[0,1.33,364.57]],"ltp":1.33,"tv":18126.9,"id":16325787}],"tv":22278.23}]}
{"op":"mcm","clk":"996919269","pt":1580564346515,"mc":[{"id":"1.168133553","rc":[{"batb":[[1,10.5,6.39]],"ltp":11.5,"tv":1003.95,"id":27227336}]}]}
{"op":"mcm","clk":"996919510","pt":1580564347465,"mc":[{"id":"1.168133553","rc":[{"batl":[[1,13,22.42]],"ltp":11.5,"tv":1003.95,"id":27227336},{"batb":[[0,6.2,8.03],[1,6,31.51],[2,5.9,18.58]],"ltp":6.0,"tv":3147.38,"id":21641292}]}]}
{"op":"mcm","clk":"996919777","pt":1580564348376,"mc":[{"id":"1.168133553","rc":[{"trd":[[11.5,18.58]],"batl":[[0,11.5,2.67]],"ltp":11.5,"tv":1005.0,"id":27227336},{"trd":[[6.2,60.48]],"batb":[[0,6,31.51],[1,5.9,18.58],[2,5.8,33.17]],"ltp":6.2,"tv":3165.39,"id":21641292},{"trd":[[1.33,4459.05]],"batl":[[0,1.33,355.48]],"ltp":1.33,"tv":18135.99,"id":16325787}],"tv":22306.38}]}
{"op":"mcm","clk":"996920086","pt":1580564349510,"mc":[{"id":"1.168133553","rc":[{"batl":[[1,13,19.42],[2,13.5,12.37]],"ltp":11.5,"tv":1005.0,"id":27227336},{"batb":[[0,6.2,4],[1,6,28.51],[2,5.9,18.58]],"ltp":6.2,"tv":3165.39,"id":21641292},{"batb":[[0,1.32,89.97],[1,1.31,408.32],[2,1.3,390.24]],"batl":[[0,1.33,341.48],[1,1.34,1562.77],[2,1.35,1687.76]],"ltp":1.33,"tv":18135.99,"id":16325787}]}]}
{"op":"mcm","clk":"996920553","pt":1580564351500,"mc":[{"id":"1.168133553","rc":[{"trd":[[11.5,23.92]],"batb":[[0,11.5,1.39],[1,11,9.03],[2,10.5,6.39]],"batl":[[0,12.5,11.6]],"ltp":11.5,"tv":1010.34,"id":27227336},{"batb":[[0,6,28.51],[1,5.9,18.58],[2,5.8,33.17]],"batl":[[0,6.4,34.38]],"ltp":6.2,"tv":3165.39,"id":21641292},{"batb":[[0,1.32,51.97]],"batl":[[0,1.33,354.48],[1,1.34,1575.77],[2,1.35,1700.76]],"ltp":1.33,"tv":18135.99,"id":16325787}],"tv":22311.72}]}
{"op":"mcm","clk":"996920772","pt":1580564352507,"mc":[{"id":"1.168133553","rc":[{"batb":[[2,10.5,10.82]],"ltp":11.5,"tv":1010.34,"id":27227336},{"batb":[[1,5.9,20.95]],"ltp":6.2,"tv":3165.39,"id":21641292},{"batb":[[1,1.31,473.36]],"ltp":1.33,"tv":18135.99,"id":16325787}]}]}
{"op":"mcm","clk":"996920965","pt":1580564353506,"mc":[{"id":"1.168133553","rc":[{"batb":[[0,11.5,15.79],[2,10.5,12.95]],"ltp":11.5,"tv":1010.34,"id":27227336}]}]}
{"op":"mcm","clk":"996921172","pt":1580564354495,"mc":[{"id":"1.168133553","rc":[{"batb":[[1,5.9,18.58]],"ltp":6.2,"tv":3165.39,"id":21641292}]}]}
{"op":"mcm","clk":"996921391","pt":1580564355565,"mc":[{"id":"1.168133553","rc":[{"batb":[[0,11.5,19.98]],"ltp":11.5,"tv":1010.34,"id":27227336}]}]}
{"op":"mcm","clk":"996922193","pt":1580564359502,"mc":[{"id":"1.168133553","rc":[{"batb":[[1,11,11.05]],"batl":[[1,13,19.96]],"ltp":11.5,"tv":1010.34,"id":27227336}]}]}
{"op":"mcm","clk":"996922831","pt":1580564362483,"mc":[{"id":"1.168133553","rc":[{"batl":[[0,1.33,354.68]],"ltp":1.33,"tv":18135.99,"id":16325787}]}]}
{"op":"mcm","clk":"996923049","pt":1580564363561,"mc":[{"id":"1.168133553","rc":[{"batl":[[0,6.4,62.39]],"ltp":6.2,"tv":3165.39,"id":21641292}]}]}
{"op":"mcm","clk":"996924004","pt":1580564368485,"mc":[{"id":"1.168133553","rc":[{"batl":[[1,13,12.43],[2,13.5,19.62]],"ltp":11.5,"tv":1010.34,"id":27227336},{"trd":[[6,285.42]],"batb":[[0,6,26.51]],"ltp":6.0,"tv":3169.39,"id":21641292},{"batl":[[0,1.33,354.48]],"ltp":1.33,"tv":18135.99,"id":16325787}],"tv":22315.72}]}
{"op":"mcm","clk":"996924896","pt":1580564372502,"mc":[{"id":"1.168133553","rc":[{"batl":[[0,6.2,5.45],[1,6.4,62.39],[2,6.6,40.07]],"ltp":6.0,"tv":3169.39,"id":21641292},{"trd":[[1.33,4499.05]],"batl":[[0,1.33,334.48]],"ltp":1.33,"tv":18175.99,"id":16325787}],"tv":22355.72}]}
{"op":"mcm","clk":"996925103","pt":1580564373476,"mc":[{"id":"1.168133553","rc":[{"batb":[[0,11.5,5.58]],"batl":[[0,12.5,14.55],[1,13,15.43],[2,13.5,22.62]],"ltp":11.5,"tv":1010.34,"id":27227336},{"trd":[[6,324.48]],"batb":[[0,6,25.32]],"batl":[[1,6.4,38.38]],"ltp":6.0,"tv":3208.45,"id":21641292},{"batb":[[1,1.31,507.36],[2,1.3,425.24]],"ltp":1.33,"tv":18175.99,"id":16325787}],"tv":22394.78}]}
{"op":"mcm","clk":"996925319","pt":1580564374477,"mc":[{"id":"1.168133553","rc":[{"batb":[[0,11.5,1.39]],"batl":[[0,12.5,18.7]],"ltp":11.5,"tv":1010.34,"id":27227336}]}]}
{"op":"mcm","clk":"996925514","pt":1580564375513,"mc":[{"id":"1.168133553","rc":[{"trd":[[12.5,152.97],[13,152.88]],"batb":[[0,11.5,12.25],[1,11,15.05]],"batl":[[0,12.5,8],[1,13,15.24]],"ltp":13.0,"tv":1068.03,"id":27227336},{"batb":[[0,6,31.4]],"batl":[[0,6.2,16.64]],"ltp":6.0,"tv":3208.45,"id":21641292}],"tv":22452.48}]}
{"op":"mcm","clk":"996925737","pt":1580564376510,"mc":[{"id":"1.168133553","rc":[{"batb":[[0,11.5,16.53]],"batl":[[0,13,15.24],[1,13.5,22.62],[2,14,5.91]],"ltp":13.0,"tv":1068.03,"id":27227336}]}]}
{"op":"mcm","clk":"996925941","pt":1580564377488,"mc":[{"id":"1.168133553","rc":[{"batl":[[1,13.5,15.37],[2,14,12.9]],"ltp":13.0,"tv":1068.03,"id":27227336},{"batb":[[0,6,24.42]],"ltp":6.0,"tv":3208.45,"id":21641292}]}]}
{"op":"mcm","clk":"996926144","pt":1580564378479,"mc":[{"id":"1.168133553","rc":[{"batl":[[2,6.6,45.5]],"ltp":6.0,"tv":3208.45,"id":21641292}]}]}
{"op":"mcm","clk":"996926530","pt":1580564380518,"mc":[{"id":"1.168133553","rc":[{"batb":[[0,6,18.34]],"ltp":6.0,"tv":3208.45,"id":21641292}]}]}
{"op":"mcm","clk":"996926764","pt":1580564381529,"mc":[{"id":"1.168133553","rc":[{"batb":[[1,5.9,24.66]],"ltp":6.0,"tv":3208.45,"id":21641292}]}]}
{"op":"mcm","clk":"996927990","pt":1580564386551,"mc":[{"id":"1.168133553","rc":[{"trd":[[1.33,4503.05]],"batl":[[0,1.33,332.48]],"ltp":1.33,"tv":18179.99,"id":16325787}],"tv":22456.48}]}
{"op":"mcm","clk":"996928676","pt":1580564389514,"mc":[{"id":"1.168133553","rc":[{"trd":[[11.5,36.25]],"batb":[[0,12,7.02],[1,11.5,10.37],[2,11,15.05]],"batl":[[0,13,18.48]],"ltp":11.5,"tv":1080.36,"id":27227336},{"trd":[[1.33,4527.99]],"batl":[[0,1.33,320.01]],"ltp":1.33,"tv":18204.93,"id":16325787}],"tv":22493.75}]}
{"op":"mcm","clk":"996928923","pt":1580564390532,"mc":[{"id":"1.168133553","rc":[{"batb":[[0,12,10.02]],"batl":[[1,13.5,22.36],[2,14,5.91]],"ltp":11.5,"tv":1080.36,"id":27227336},{"batb":[[1,5.9,18.58]],"ltp":6.0,"tv":3208.45,"id":21641292},{"batb":[[1,1.31,442.32]],"ltp":1.33,"tv":18204.93,"id":16325787}]}]}
{"op":"mcm","clk":"996929140","pt":1580564391539,"mc":[{"id":"1.168133553","rc":[{"batl":[[0,6.2,11.19],[2,6.6,40.07]],"ltp":6.0,"tv":3208.45,"id":21641292},{"trd":[[1.32,6713.11]],"batb":[[0,1.31,442.32],[1,1.3,425.24],[2,1.29,402.29]],"batl":[[0,1.32,77.96],[1,1.33,290.07],[2,1.34,1575.77]],"ltp":1.32,"tv":18308.86,"id":16325787}],"tv":22597.69}]}
{"op":"mcm","clk":"996929354","pt":1580564392539,"mc":[{"id":"1.168133553","rc":[{"batb":[[0,1.31,418.09]],"batl":[[0,1.32,48.03],[1,1.33,320.01]],"ltp":1.32,"tv":18308.86,"id":16325787}]}]}
{"op":"mcm","clk":"996929743","pt":1580564394435,"mc":[{"id":"1.168133553","rc":[{"trd":[[6,336.48]],"batb":[[0,6,12.34]],"ltp":6.0,"tv":3220.45,"id":21641292},{"trd":[[1.32,6731.11]],"batl":[[0,1.32,39.23]],"ltp":1.32,"tv":18326.86,"id":16325787}],"tv":22627.69}]}
{"op":"mcm","clk":"996929950","pt":1580564395540,"mc":[{"id":"1.168133553","rc":[{"batb":[[0,6,18.34]],"batl":[[0,6.2,5.51],[2,6.6,44.07]],"ltp":6.0,"tv":3220.45,"id":21641292}]}]}
{"op":"mcm","clk":"996930172","pt":1580564396542,"mc":[{"id":"1.168133553","rc":[{"batl":[[1,1.33,319.81]],"ltp":1.32,"tv":18326.86,"id":16325787}]}]}
{"op":"mcm","clk":"996930378","pt":1580564397535,"mc":[{"id":"1.168133553","rc":[{"trd":[[13,158.66]],"batl":[[0,13,15.59]],"ltp":13.0,"tv":1086.14,"id":27227336},{"batl":[[0,6.2,17.82]],"ltp":6.0,"tv":3220.45,"id":21641292}],"tv":22633.47}]}
{"op":"mcm","clk":"996930567","pt":1580564398547,"mc":[{"id":"1.168133553","rc":[{"batb":[[1,11.5,12.29]],"ltp":13.0,"tv":1086.14,"id":27227336}]}]}
{"op":"mcm","clk":"996930974","pt":1580564400530,"mc":[{"id":"1.168133553","rc":[{"batb":[[0,12.5,17.7],[1,12,10.02],[2,11.5,12.29]],"batl":[[0,13,3.24],[1,13.5,15.37],[2,14,12.9]],"ltp":13.0,"tv":1086.14,"id":27227336},{"batb":[[0,1.31,400.69]],"ltp":1.32,"tv":18326.86,"id":16325787}]}]}
{"op":"mcm","clk":"996931433","pt":1580564402560,"mc":[{"id":"1.168133553","rc":[{"trd":[[13,159.21]],"batl":[[0,13,2.68]],"ltp":13.0,"tv":1086.69,"id":27227336},{"trd":[[6,374.36]],"batb":[[0,6,7]],"ltp":6.0,"tv":3258.33,"id":21641292},{"trd":[[1.32,6736.56]],"batl":[[0,1.32,33.78]],"ltp":1.32,"tv":18332.31,"id":16325787}],"tv":22677.35}]}
{"op":"mcm","clk":"996931846","pt":1580564404512,"mc":[{"id":"1.168133553","rc":[{"batl":[[0,1.32,63.71],[1,1.33,289.87]],"ltp":1.32,"tv":18332.31,"id":16325787}]}]}
{"op":"mcm","clk":"996932670","pt":1580564408568,"mc":[{"id":"1.168133553","rc":[{"batb":[[0,12.5,24.44],[1,12,11.85]],"ltp":13.0,"tv":1086.69,"id":27227336},{"batb":[[1,5.9,24.78]],"ltp":6.0,"tv":3258.33,"id":21641292}]}]}
{"op":"mcm","clk":"996932859","pt":1580564409558,"mc":[{"id":"1.168133553","rc":[{"batl":[[2,6.6,49.5]],"ltp":6.0,"tv":3258.33,"id":21641292}]}]}
{"op":"mcm","clk":"996933978","pt":1580564415073,"mc":[{"id":"1.168133553","rc":[{"batl":[[2,6.6,44.07]],"ltp":6.0,"tv":3258.33,"id":21641292},{"batl":[[0,1.32,63.94]],"ltp":1.32,"tv":18332.31,"id":16325787}]}]}
{"op":"mcm","clk":"996935556","pt":1580564422570,"mc":[{"id":"1.168133553","rc":[{"trd":[[1.32,6744.96]],"batl":[[0,1.32,59.74]],"ltp":1.32,"tv":18340.71,"id":16325787}],"tv":22685.75}]}
{"op":"mcm","clk":"996935735","pt":1580564423478,"mc":[{"id":"1.168133553","rc":[{"trd":[[6,380.36]],"batb":[[0,6,4]],"ltp":6.0,"tv":3264.33,"id":21641292},{"trd":[[1.32,6762.96]],"batl":[[0,1.32,50.74]],"ltp":1.32,"tv":18358.71,"id":16325787}],"tv":22709.75}]}
{"op":"mcm","clk":"996935955","pt":1580564424574,"mc":[{"id":"1.168133553","rc":[{"batb":[[1,5.9,18.58],[2,5.8,39.37]],"ltp":6.0,"tv":3264.33,"id":21641292},{"batl":[[0,1.32,50.94]],"ltp":1.32,"tv":18358.71,"id":16325787}]}]}
{"op":"mcm","clk":"996937245","pt":1580564430494,"mc":[{"id":"1.168133553","rc":[{"batl":[[0,1.32,50.74]],"ltp":1.32,"tv":18358.71,"id":16325787}]}]}
{"op":"mcm","clk":"996937720","pt":1580564432494,"mc":[{"id":"1.168133553","rc":[{"trd":[[1.32,6782.96]],"batl":[[0,1.32,40.74]],"ltp":1.32,"tv":18378.71,"id":16325787}],"tv":22729.75}]}
{"op":"mcm","clk":"996938490","pt":1580564436421,"mc":[{"id":"1.168133553","rc":[{"batl":[[2,14,5.91]],"ltp":13.0,"tv":1086.69,"id":27227336}]}]}
{"op":"mcm","clk":"996938923","pt":1580564438514,"mc":[{"id":"1.168133553","rc":[{"trd":[[6.2,64.48]],"batl":[[0,6.2,15.82]],"ltp":6.2,"tv":3268.33,"id":21641292}],"tv":22733.74}]}
{"op":"mcm","clk":"996939742","pt":1580564442516,"mc":[{"id":"1.168133553","rc":[{"batb":[[0,12.5,29.01]],"ltp":13.0,"tv":1086.69,"id":27227336}]}]}
{"op":"mcm","clk":"996940333","pt":1580564445528,"mc":[{"id":"1.168133553","rc":[{"trd":[[12.5,169.49]],"batb":[[0,12.5,20.75]],"ltp":12.5,"tv":1103.21,"id":27227336},{"trd":[[1.32,6798.6]],"batl":[[0,1.32,32.92]],"ltp":1.32,"tv":18394.35,"id":16325787}],"tv":22765.9}]}
{"op":"mcm","clk":"996940971","pt":1580564448552,"mc":[{"id":"1.168133553","rc":[{"trd":[[6,384.36]],"batb":[[0,6,2]],"batl":[[0,6.2,17.82]],"ltp":6.0,"tv":3272.33,"id":21641292},{"trd":[[1.32,6816.59]],"batl":[[0,1.32,23.93]],"ltp":1.32,"tv":18412.35,"id":16325787}],"tv":22787.9}]}
{"op":"mcm","clk":"996941200","pt":1580564449540,"mc":[{"id":"1.168133553","rc":[{"batl":[[0,6.2,19.82]],"ltp":6.0,"tv":3272.33,"id":21641292}]}]}
{"op":"mcm","clk":"996941421","pt":1580564450542,"mc":[{"id":"1.168133553","rc":[{"batl":[[2,14,12.9]],"ltp":12.5,"tv":1103.21,"id":27227336},{"batl":[[0,1.32,17.5]],"ltp":1.32,"tv":18412.35,"id":16325787}]}]}
{"op":"mcm","clk":"996941683","pt":1580564451543,"mc":[{"id":"1.168133553","rc":[{"trd":[[13,163.2]],"batl":[[0,13.5,16.06],[1,14,19.9],[2,14.5,18.39]],"ltp":13.0,"tv":1107.21,"id":27227336},{"batb":[[0,6,7]],"ltp":6.0,"tv":3272.33,"id":21641292}],"tv":22791.89}]}
{"op":"mcm","clk":"996941919","pt":1580564452548,"mc":[{"id":"1.168133553","rc":[{"trd":[[13,164.58]],"batl":[[0,13.5,15.37],[1,14,22.65]],"ltp":13.0,"tv":1108.59,"id":27227336}],"tv":22793.27}]}
{"op":"mcm","clk":"996942348","pt":1580564454562,"mc":[{"id":"1.168133553","rc":[{"batl":[[1,14,19.9]],"ltp":13.0,"tv":1108.59,"id":27227336}]}]}
{"op":"mcm","clk":"996942546","pt":1580564455556,"mc":[{"id":"1.168133553","rc":[{"batl":[[0,1.32,17.7]],"ltp":1.32,"tv":18412.35,"id":16325787}]}]}
{"op":"mcm","clk":"996942751","pt":1580564456550,"mc":[{"id":"1.168133553","rc":[{"batb":[[0,13,3.3],[1,12.5,20.75],[2,12,11.85]],"batl":[[0,13.5,11.06]],"ltp":13.0,"tv":1108.59,"id":27227336},{"batb":[[0,5.9,18.58],[1,5.8,39.37],[2,5.7,17.18]],"ltp":6.0,"tv":3272.33,"id":21641292},{"trd":[[1.32,6852]],"batb":[[0,1.32,7.29],[1,1.31,400.69],[2,1.3,425.24]],"batl":[[0,1.33,289.87],[1,1.34,1575.77],[2,1.35,1700.76]],"ltp":1.32,"tv":18447.75,"id":16325787}],"tv":22828.68}]}
{"op":"mcm","clk":"996942942","pt":1580564457505,"mc":[{"id":"1.168133553","rc":[{"batb":[[0,12.5,20.75],[1,12,11.85],[2,11.5,12.29]],"ltp":13.0,"tv":1108.59,"id":27227336},{"batb":[[0,5.9,14.46]],"ltp":6.0,"tv":3272.33,"id":21641292}]}]}
{"op":"mcm","clk":"996943796","pt":1580564461488,"mc":[{"id":"1.168133553","rc":[{"trd":[[1.31,3613.1],[1.32,6866.58]],"batb":[[0,1.31,308.02],[1,1.3,425.24],[2,1.29,377.29]],"ltp":1.31,"tv":18647.71,"id":16325787}],"tv":23028.63}]}
{"op":"mcm","clk":"996943985","pt":1580564462488,"mc":[{"id":"1.168133553","rc":[{"batb":[[0,13,3],[1,12.5,23.98],[2,12,11.85]],"ltp":13.0,"tv":1108.59,"id":27227336},{"batl":[[0,6.2,16.31]],"ltp":6.0,"tv":3272.33,"id":21641292},{"batb":[[0,1.31,424.22]],"batl":[[0,1.32,23],[1,1.33,289.87],[2,1.34,1575.77]],"ltp":1.31,"tv":18647.71,"id":16325787}]}]}
{"op":"mcm","clk":"996944195","pt":1580564463531,"mc":[{"id":"1.168133553","rc":[{"batl":[[1,6.4,40.38]],"ltp":6.0,"tv":3272.33,"id":21641292},{"batl":[[0,1.32,29.43]],"ltp":1.31,"tv":18647.71,"id":16325787}]}]}
{"op":"mcm","clk":"996944802","pt":1580564466523,"mc":[{"id":"1.168133553","rc":[{"trd":[[13.5,129.85]],"batb":[[0,13,9.35]],"batl":[[0,13.5,2.94]],"ltp":13.5,"tv":1108.83,"id":27227336},{"trd":[[5.9,240.19]],"batb":[[0,5.9,7]],"ltp":5.9,"tv":3297.56,"id":21641292},{"trd":[[1.31,3726.78]],"batb":[[0,1.31,367.38]],"ltp":1.31,"tv":18761.39,"id":16325787}],"tv":23167.79}]}
{"op":"mcm","clk":"996945198","pt":1580564468519,"mc":[{"id":"1.168133553","rc":[{"trd":[[5.9,248.19]],"batb":[[0,5.9,3]],"ltp":5.9,"tv":3305.56,"id":21641292},{"trd":[[1.32,6886.58]],"batl":[[0,1.32,19.43]],"ltp":1.32,"tv":18781.39,"id":16325787}],"tv":23195.79}]}
{"op":"mcm","clk":"996945427","pt":1580564469570,"mc":[{"id":"1.168133553","rc":[{"batb":[[0,5.9,7],[1,5.8,33.17]],"batl":[[0,6.2,32.15]],"ltp":5.9,"tv":3305.56,"id":21641292},{"batl":[[0,1.32,6.43]],"ltp":1.32,"tv":18781.39,"id":16325787}]}]}
{"op":"mcm","clk":"996945635","pt":1580564470549,"mc":[{"id":"1.168133553","rc":[{"batb":[[1,12.5,25.73]],"ltp":13.5,"tv":1108.83,"id":27227336}]}]}
{"op":"mcm","clk":"996948102","pt":1580564481544,"mc":[{"id":"1.168133553","rc":[{"batb":[[0,13,3]],"ltp":13.5,"tv":1108.83,"id":27227336},{"trd":[[1.32,6899.45]],"batb":[[0,1.32,143.56],[1,1.31,427.77],[2,1.3,425.24]],"batl":[[0,1.33,289.87],[1,1.34,1575.77],[2,1.35,1700.76]],"ltp":1.32,"tv":18794.26,"id":16325787}],"tv":23208.66}]}
{"op":"mcm","clk":"996948291","pt":1580564482484,"mc":[{"id":"1.168133553","rc":[{"batb":[[1,1.31,444.28]],"ltp":1.32,"tv":18794.26,"id":16325787}]}]}
{"op":"mcm","clk":"996948525","pt":1580564483572,"mc":[{"id":"1.168133553","rc":[{"batb":[[0,5.8,33.17],[1,5.7,17.18],[2,5.6,7.67]],"ltp":5.9,"tv":3305.56,"id":21641292},{"batb":[[1,1.31,494.28],[2,1.3,445.24]],"ltp":1.32,"tv":18794.26,"id":16325787}]}]}
{"op":"mcm","clk":"996948728","pt":1580564484553,"mc":[{"id":"1.168133553","rc":[{"batb":[[0,5.8,28.97]],"ltp":5.9,"tv":3305.56,"id":21641292}]}]}
{"op":"mcm","clk":"996948986","pt":1580564485563,"mc":[{"id":"1.168133553","rc":[{"batl":[[0,1.33,290.07]],"ltp":1.32,"tv":18794.26,"id":16325787}]}]}
{"op":"mcm","clk":"996949425","pt":1580564487552,"mc":[{"id":"1.168133553","rc":[{"batb":[[1,1.31,463.89]],"ltp":1.32,"tv":18794.26,"id":16325787}]}]}
{"op":"mcm","clk":"996950022","pt":1580564490485,"mc":[{"id":"1.168133553","rc":[{"batl":[[0,6,15],[1,6.2,32.15],[2,6.4,40.38]],"ltp":5.9,"tv":3305.56,"id":21641292}]}]}
{"op":"mcm","clk":"996950263","pt":1580564491574,"mc":[{"id":"1.168133553","rc":[{"batl":[[0,6,30]],"ltp":5.9,"tv":3305.56,"id":21641292}]}]}
{"op":"mcm","clk":"996950494","pt":1580564492550,"mc":[{"id":"1.168133553","rc":[{"batb":[[0,5.8,21.96]],"ltp":5.9,"tv":3305.56,"id":21641292},{"batb":[[1,1.31,488.12]],"ltp":1.32,"tv":18794.26,"id":16325787}]}]}
{"op":"mcm","clk":"996950685","pt":1580564493497,"mc":[{"id":"1.168133553","rc":[{"trd":[[12.5,179.28],[13,170.58]],"batb":[[1,12.5,19.08]],"ltp":12.5,"tv":1124.63,"id":27227336},{"batb":[[0,1.32,151]],"ltp":1.32,"tv":18794.26,"id":16325787}],"tv":23224.46}]}
{"op":"mcm","clk":"996950927","pt":1580564494481,"mc":[{"id":"1.168133553","rc":[{"trd":[[1.33,4545.99]],"batl":[[0,1.33,281.07]],"ltp":1.33,"tv":18812.26,"id":16325787}],"tv":23242.46}]}
{"op":"mcm","clk":"996951347","pt":1580564496509,"mc":[{"id":"1.168133553","rc":[{"batb":[[0,13,12.41]],"ltp":12.5,"tv":1124.63,"id":27227336},{"batb":[[0,5.8,30.02]],"ltp":5.9,"tv":3305.56,"id":21641292},{"trd":[[1.32,7235.52]],"batb":[[0,1.32,66.77]],"ltp":1.32,"tv":19148.33,"id":16325787}],"tv":23578.53}]}
{"op":"mcm","clk":"996951758","pt":1580564498549,"mc":[{"id":"1.168133553","rc":[{"batb":[[1,1.31,553.17]],"ltp":1.32,"tv":19148.33,"id":16325787}]}]}
{"op":"mcm","clk":"996952416","pt":1580564501532,"mc":[{"id":"1.168133553","rc":[{"batb":[[0,13,9.41],[1,12.5,20.84]],"ltp":12.5,"tv":1124.63,"id":27227336}]}]}
{"op":"mcm","clk":"996954943","pt":1580564513556,"mc":[{"id":"1.168133553","rc":[{"batb":[[1,1.31,583.56]],"ltp":1.32,"tv":19148.33,"id":16325787}]}]}
{"op":"mcm","clk":"996955573","pt":1580564516493,"mc":[{"id":"1.168133553","rc":[{"batl":[[0,1.33,281.27]],"ltp":1.32,"tv":19148.33,"id":16325787}]}]}
{"op":"mcm","clk":"996956674","pt":1580564521508,"mc":[{"id":"1.168133553","rc":[{"batl":[[0,1.33,281.07]],"ltp":1.32,"tv":19148.33,"id":16325787}]}]}
{"op":"mcm","clk":"996957112","pt":1580564523511,"mc":[{"id":"1.168133553","rc":[{"batb":[[0,13,11.9]],"ltp":12.5,"tv":1124.63,"id":27227336},{"trd":[[5.8,244.31]],"batb":[[0,5.8,29.02]],"ltp":5.8,"tv":3315.56,"id":21641292},{"trd":[[1.33,4561.99]],"batb":[[0,1.32,141.77]],"batl":[[0,1.33,273.07]],"ltp":1.33,"tv":19164.33,"id":16325787}],"tv":23604.53}]}
{"op":"mcm","clk":"996957321","pt":1580564524541,"mc":[{"id":"1.168133553","rc":[{"batb":[[1,1.31,553.17]],"ltp":1.33,"tv":19164.33,"id":16325787}]}]}
{"op":"mcm","clk":"996958262","pt":1580564528504,"mc":[{"id":"1.168133553","rc":[{"trd":[[5.8,248.45]],"batb":[[0,5.8,26.95]],"ltp":5.8,"tv":3319.7,"id":21641292}],"tv":23608.67}]}
{"op":"mcm","clk":"996961646","pt":1580564543562,"mc":[{"id":"1.168133553","rc":[{"trd":[[13,186.24]],"batb":[[0,13,4.07]],"ltp":13.0,"tv":1140.29,"id":27227336},{"trd":[[1.33,4570.57]],"batl":[[0,1.33,268.78]],"ltp":1.33,"tv":19172.91,"id":16325787}],"tv":23632.91}]}
{"op":"mcm","clk":"996961833","pt":1580564544480,"mc":[{"id":"1.168133553","rc":[{"batb":[[1,12.5,17.84],[2,12,8.85]],"ltp":13.0,"tv":1140.29,"id":27227336},{"batb":[[1,5.7,23.68]],"ltp":5.8,"tv":3319.7,"id":21641292}]}]}
{"op":"mcm","clk":"996962069","pt":1580564545572,"mc":[{"id":"1.168133553","rc":[{"batb":[[0,13,7.07],[1,12.5,21.84],[2,12,12.98]],"ltp":13.0,"tv":1140.29,"id":27227336}]}]}
{"op":"mcm","clk":"996962267","pt":1580564546479,"mc":[{"id":"1.168133553","rc":[{"trd":[[5.8,252.45]],"batb":[[0,5.8,24.96]],"ltp":5.8,"tv":3323.69,"id":21641292},{"batl":[[0,1.33,268.98]],"ltp":1.33,"tv":19172.91,"id":16325787}],"tv":23636.9}]}
{"op":"mcm","clk":"996962477","pt":1580564547513,"mc":[{"id":"1.168133553","rc":[{"batb":[[1,12.5,21.96],[2,12,12.85]],"ltp":13.0,"tv":1140.29,"id":27227336}]}]}
{"op":"mcm","clk":"996962891","pt":1580564549513,"mc":[{"id":"1.168133553","rc":[{"batb":[[1,5.7,17.18],[2,5.6,14.17]],"ltp":5.8,"tv":3323.69,"id":21641292}]}]}
{"op":"mcm","clk":"996963790","pt":1580564553514,"mc":[{"id":"1.168133553","rc":[{"trd":[[1.33,4574.57]],"batl":[[0,1.33,266.78]],"ltp":1.33,"tv":19176.91,"id":16325787}],"tv":23640.9}]}
{"op":"mcm","clk":"996965750","pt":1580564562556,"mc":[{"id":"1.168133553","rc":[{"batb":[[0,1.32,143.77]],"ltp":1.33,"tv":19176.91,"id":16325787}]}]}
{"op":"mcm","clk":"996966348","pt":1580564565556,"mc":[{"id":"1.168133553","rc":[{"trd":[[13.5,133.85]],"batl":[[0,14,20.84],[1,14.5,18.39],[2,15,4.33]],"ltp":13.5,"tv":1144.28,"id":27227336}],"tv":23644.9}]}
{"op":"mcm","clk":"996966575","pt":1580564566543,"mc":[{"id":"1.168133553","rc":[{"batl":[[0,14,13.85],[1,14.5,25.13]],"ltp":13.5,"tv":1144.28,"id":27227336},{"batl":[[0,6,35.8]],"ltp":5.8,"tv":3323.69,"id":21641292},{"batb":[[0,1.32,68.77],[1,1.31,488.12]],"ltp":1.33,"tv":19176.91,"id":16325787}]}]}
{"op":"mcm","clk":"996966795","pt":1580564567545,"mc":[{"id":"1.168133553","rc":[{"batl":[[1,14.5,30.92]],"ltp":13.5,"tv":1144.28,"id":27227336},{"batb":[[2,5.6,7.67]],"ltp":5.8,"tv":3323.69,"id":21641292}]}]}
{"op":"mcm","clk":"996967205","pt":1580564569572,"mc":[{"id":"1.168133553","rc":[{"batb":[[1,1.31,490.12]],"ltp":1.33,"tv":19176.91,"id":16325787}]}]}
{"op":"mcm","clk":"996968252","pt":1580564574468,"mc":[{"id":"1.168133553","rc":[{"trd":[[13,201.42]],"batb":[[0,13,2.49]],"ltp":13.0,"tv":1159.46,"id":27227336},{"trd":[[1.33,4582.93]],"batl":[[0,1.33,262.6]],"ltp":1.33,"tv":19185.27,"id":16325787}],"tv":23668.43}]}
{"op":"mcm","clk":"996968481","pt":1580564575570,"mc":[{"id":"1.168133553","rc":[{"batb":[[1,12.5,21.84],[2,12,12.98]],"ltp":13.0,"tv":1159.46,"id":27227336}]}]}
{"op":"mcm","clk":"996968667","pt":1580564576491,"mc":[{"id":"1.168133553","rc":[{"batb":[[2,1.3,447.24]],"ltp":1.33,"tv":19185.27,"id":16325787}]}]}
{"op":"mcm","clk":"996968913","pt":1580564577481,"mc":[{"id":"1.168133553","rc":[{"batl":[[0,1.33,262.8]],"ltp":1.33,"tv":19185.27,"id":16325787}]}]}
{"op":"mcm","clk":"996969562","pt":1580564580501,"mc":[{"id":"1.168133553","rc":[{"batb":[[0,1.32,70.77]],"ltp":1.33,"tv":19185.27,"id":16325787}]}]}
{"op":"mcm","clk":"996969791","pt":1580564581509,"mc":[{"id":"1.168133553","rc":[{"trd":[[5.8,280.44]],"batb":[[0,5.8,6.96]],"ltp":5.8,"tv":3351.69,"id":21641292},{"batl":[[0,1.33,262.6]],"ltp":1.33,"tv":19185.27,"id":16325787}],"tv":23696.43}]}
{"op":"mcm","clk":"996970456","pt":1580564584512,"mc":[{"id":"1.168133553","rc":[{"batb":[[0,13,11.19]],"batl":[[0,14,12.91]],"ltp":13.0,"tv":1159.46,"id":27227336},{"batb":[[0,5.8,13.96]],"batl":[[0,6,30]],"ltp":5.8,"tv":3351.69,"id":21641292},{"trd":[[1.32,7377.1]],"batb":[[0,1.31,490.12],[1,1.3,447.24],[2,1.29,403.25]],"batl":[[0,1.32,29.19],[1,1.33,262.6],[2,1.34,1575.77]],"ltp":1.32,"tv":19326.85,"id":16325787}],"tv":23838.01}]}
{"op":"mcm","clk":"996970668","pt":1580564585501,"mc":[{"id":"1.168133553","rc":[{"batl":[[0,14,9.95],[1,14.5,25.13]],"ltp":13.0,"tv":1159.46,"id":27227336},{"trd":[[5.8,283.81]],"batb":[[0,5.8,12.28]],"ltp":5.8,"tv":3355.05,"id":21641292},{"batb":[[2,1.29,406.25]],"ltp":1.32,"tv":19326.85,"id":16325787}],"tv":23841.37}]}
{"op":"mcm","clk":"996970889","pt":1580564586502,"mc":[{"id":"1.168133553","rc":[{"batl":[[0,5.9,2],[1,6,30],[2,6.2,32.15]],"ltp":5.8,"tv":3355.05,"id":21641292}]}]}
{"op":"mcm","clk":"996971106","pt":1580564587495,"mc":[{"id":"1.168133553","rc":[{"batb":[[1,5.7,23.85],[2,5.6,14.67]],"ltp":5.8,"tv":3355.05,"id":21641292}]}]}
{"op":"mcm","clk":"996971765","pt":1580564590503,"mc":[{"id":"1.168133553","rc":[{"batl":[[0,1.32,84.19]],"ltp":1.32,"tv":19326.85,"id":16325787}]}]}
{"op":"mcm","clk":"996971987","pt":1580564591536,"mc":[{"id":"1.168133553","rc":[{"batb":[[2,12,33.98]],"batl":[[0,14,2.95],[1,14.5,33.13]],"ltp":13.0,"tv":1159.46,"id":27227336},{"batl":[[1,1.33,266.89]],"ltp":1.32,"tv":19326.85,"id":16325787}]}]}
{"op":"mcm","clk":"996972188","pt":1580564592505,"mc":[{"id":"1.168133553","rc":[{"batb":[[1,12.5,21.96],[2,12,33.86]],"ltp":13.0,"tv":1159.46,"id":27227336},{"batb":[[0,1.31,465.89]],"ltp":1.32,"tv":19326.85,"id":16325787}]}]}
{"op":"mcm","clk":"996972393","pt":1580564593529,"mc":[{"id":"1.168133553","rc":[{"trd":[[5.8,289.81]],"batb":[[0,5.8,9.28],[1,5.7,17.18],[2,5.6,21.34]],"ltp":5.8,"tv":3361.05,"id":21641292}],"tv":23847.37}]}
{"op":"mcm","clk":"996972596","pt":1580564594513,"mc":[{"id":"1.168133553","rc":[{"batb":[[0,5.8,2.28]],"ltp":5.8,"tv":3361.05,"id":21641292}]}]}
{"op":"mcm","clk":"996973011","pt":1580564596515,"mc":[{"id":"1.168133553","rc":[{"batl":[[1,1.33,262.6]],"ltp":1.32,"tv":19326.85,"id":16325787}]}]}
{"op":"mcm","clk":"996973219","pt":1580564597555,"mc":[{"id":"1.168133553","rc":[{"batb":[[0,13,7.98],[1,12.5,20.21],[2,12,11.02]],"batl":[[0,14,11.04]],"ltp":13.0,"tv":1159.46,"id":27227336},{"batb":[[1,5.7,12.89]],"batl":[[0,5.9,28.91]],"ltp":5.8,"tv":3361.05,"id":21641292},{"trd":[[1.32,7545.48],[1.33,6414.45]],"batb":[[0,1.32,185.9],[1,1.31,490.92],[2,1.3,380.02]],"batl":[[0,1.33,21],[1,1.34,1689.89],[2,1.35,1700.76]],"ltp":1.33,"tv":21326.75,"id":16325787}],"tv":25847.27}]}
{"op":"mcm","clk":"996973414","pt":1580564598564,"mc":[{"id":"1.168133553","rc":[{"batb":[[1,12.5,20.08],[2,12,11.15]],"ltp":13.0,"tv":1159.46,"id":27227336},{"trd":[[5.8,294.36]],"batb":[[0,5.7,8],[1,5.6,14.67],[2,5.5,20.86]],"batl":[[0,5.8,9.72],[1,5.9,28.91],[2,6,30]],"ltp":5.8,"tv":3365.61,"id":21641292},{"batb":[[2,1.3,500.18]],"ltp":1.33,"tv":21326.75,"id":16325787}],"tv":25851.83}]}
{"op":"mcm","clk":"996973634","pt":1580564599504,"mc":[{"id":"1.168133553","rc":[{"batb":[[0,5.6,7],[1,5.5,27.86],[2,5.4,25.83]],"batl":[[2,6,37.11]],"ltp":5.8,"tv":3365.61,"id":21641292}]}]}
{"op":"mcm","clk":"996975388","pt":1580564607524,"mc":[{"id":"1.168133553","rc":[{"batl":[[0,14,2.95]],"ltp":13.0,"tv":1159.46,"id":27227336},{"batl":[[0,1.33,21.2]],"ltp":1.33,"tv":21326.75,"id":16325787}]}]}
{"op":"mcm","clk":"996976259","pt":1580564611538,"mc":[{"id":"1.168133553","rc":[{"trd":[[13,242.96],[14,23.06]],"batb":[[0,12.5,20.08],[1,12,20.34],[2,11.5,12.18]],"batl":[[0,13,6.59],[1,14.5,34.07]],"ltp":13.0,"tv":1203.01,"id":27227336},{"trd":[[5.6,184.74],[5.8,299.4]],"batb":[[0,5.6,17.72],[2,5.4,78.35]],"batl":[[0,5.8,4.68]],"ltp":5.8,"tv":3410.65,"id":21641292},{"trd":[[1.33,6457.65],[1.34,2072.72]],"batb":[[2,1.3,380.02]],"batl":[[0,1.34,1530.3],[1,1.35,1678.76],[2,1.36,86.24]],"ltp":1.34,"tv":21557.54,"id":16325787}],"tv":26171.21}]}
{"op":"mcm","clk":"996976479","pt":1580564612544,"mc":[{"id":"1.168133553","rc":[{"batl":[[0,1.34,1514.73]],"ltp":1.34,"tv":21557.54,"id":16325787}]}]}
{"op":"mcm","clk":"996976681","pt":1580564613542,"mc":[{"id":"1.168133553","rc":[{"batb":[[1,12,11.15]],"batl":[[1,14.5,43.64]],"ltp":13.0,"tv":1203.01,"id":27227336},{"batl":[[0,5.8,10.79]],"ltp":5.8,"tv":3410.65,"id":21641292},{"trd":[[1.34,2172.72]],"batl":[[0,1.34,1464.73]],"ltp":1.34,"tv":21657.54,"id":16325787}],"tv":26271.21}]}
{"op":"mcm","clk":"996976875","pt":1580564614563,"mc":[{"id":"1.168133553","rc":[{"batl":[[0,13,13.62],[1,13.5,9.18],[2,14,9.12]],"ltp":13.0,"tv":1203.01,"id":27227336},{"batl":[[0,5.8,4.68]],"ltp":5.8,"tv":3410.65,"id":21641292},{"trd":[[1.33,6489.65]],"batb":[[0,1.33,69.72],[1,1.32,185.9],[2,1.31,490.92]],"batl":[[0,1.34,1350.61]],"ltp":1.33,"tv":21689.54,"id":16325787}],"tv":26303.21}]}
{"op":"mcm","clk":"996977078","pt":1580564615540,"mc":[{"id":"1.168133553","rc":[{"batb":[[1,12,11.02],[2,11.5,12.31]],"batl":[[1,13.5,15.93]],"ltp":13.0,"tv":1203.01,"id":27227336},{"batb":[[0,1.33,119.72]],"batl":[[0,1.34,1371.61],[1,1.35,1700.76]],"ltp":1.33,"tv":21689.54,"id":16325787}]}]}
{"op":"mcm","clk":"996977293","pt":1580564616541,"mc":[{"id":"1.168133553","rc":[{"batb":[[0,12.5,13.34]],"ltp":13.0,"tv":1203.01,"id":27227336},{"trd":[[5.6,213.16]],"batb":[[0,5.7,7.19],[1,5.6,11.51],[2,5.5,27.86]],"batl":[[0,5.8,10.81]],"ltp":5.6,"tv":3439.07,"id":21641292},{"trd":[[1.34,2212.72]],"batl":[[0,1.34,1330.61],[1,1.35,1678.76]],"ltp":1.34,"tv":21729.54,"id":16325787}],"tv":26371.63}]}
{"op":"mcm","clk":"996977498","pt":1580564617535,"mc":[{"id":"1.168133553","rc":[{"batb":[[0,12.5,8.78]],"ltp":13.0,"tv":1203.01,"id":27227336}]}]}
{"op":"mcm","clk":"996977666","pt":1580564618328,"mc":[{"id":"1.168133553","rc":[{"trd":[[5.7,266.91]],"batb":[[0,5.6,12.18],[1,5.5,27.86],[2,5.4,78.35]],"ltp":5.7,"tv":3452.1,"id":21641292},{"trd":[[1.34,4812.71]],"batb":[[1,1.32,217.8]],"batl":[[0,1.34,30.62]],"ltp":1.34,"tv":24329.53,"id":16325787}],"tv":28984.66}]}
{"op":"mcm","clk":"996977902","pt":1580564619500,"mc":[{"id":"1.168133553","rc":[{"batb":[[2,5.4,25.83]],"ltp":5.7,"tv":3452.1,"id":21641292}]}]}
{"op":"mcm","clk":"996978146","pt":1580564620504,"mc":[{"id":"1.168133553","rc":[{"batb":[[2,5.4,29.18]],"batl":[[1,5.9,33.92]],"ltp":5.7,"tv":3452.1,"id":21641292},{"batl":[[0,1.34,530.62]],"ltp":1.34,"tv":24329.53,"id":16325787}]}]}
{"op":"mcm","clk":"996978365","pt":1580564621476,"mc":[{"id":"1.168133553","rc":[{"batl":[[1,13.5,20.46]],"ltp":13.0,"tv":1203.01,"id":27227336},{"batb":[[1,5.5,34.57],[2,5.4,81.7]],"ltp":5.7,"tv":3452.1,"id":21641292},{"trd":[[1.33,6505.65]],"batb":[[0,1.33,158.86]],"batl":[[1,1.35,1716.96]],"ltp":1.33,"tv":24345.53,"id":16325787}],"tv":29000.66}]}
{"op":"mcm","clk":"996978591","pt":1580564622482,"mc":[{"id":"1.168133553","rc":[{"batl":[[1,1.35,1866.96]],"ltp":1.33,"tv":24345.53,"id":16325787}]}]}
{"op":"mcm","clk":"996978981","pt":1580564624512,"mc":[{"id":"1.168133553","rc":[{"batl":[[2,1.36,236.24]],"ltp":1.33,"tv":24345.53,"id":16325787}]}]}
{"op":"mcm","clk":"996979177","pt":1580564625511,"mc":[{"id":"1.168133553","rc":[{"batl":[[1,13.5,20.97]],"ltp":13.0,"tv":1203.01,"id":27227336}]}]}
{"op":"mcm","clk":"996979594","pt":1580564627572,"mc":[{"id":"1.168133553","rc":[{"batl":[[0,1.34,533.62]],"ltp":1.33,"tv":24345.53,"id":16325787}]}]}
{"op":"mcm","clk":"996981898","pt":1580564638498,"mc":[{"id":"1.168133553","rc":[{"trd":[[5.6,231.96],[5.7,268.25]],"batb":[[0,5.6,2.11]],"ltp":5.6,"tv":3472.24,"id":21641292},{"trd":[[1.34,4858.69]],"batl":[[0,1.34,510.83]],"ltp":1.34,"tv":24391.52,"id":16325787}],"tv":29066.78}]}
{"op":"mcm","clk":"996982519","pt":1580564641496,"mc":[{"id":"1.168133553","rc":[{"batb":[[1,5.5,27.86]],"ltp":5.6,"tv":3472.24,"id":21641292}]}]}
{"op":"mcm","clk":"996984939","pt":1580564653567,"mc":[{"id":"1.168133553","rc":[{"batl":[[1,1.35,1828.76]],"ltp":1.34,"tv":24391.52,"id":16325787}]}]}
{"op":"mcm","clk":"996985118","pt":1580564654528,"mc":[{"id":"1.168133553","rc":[{"batl":[[1,1.35,1866.96]],"ltp":1.34,"tv":24391.52,"id":16325787}]}]}
{"op":"mcm","clk":"996986791","pt":1580564662532,"mc":[{"id":"1.168133553","rc":[{"batl":[[0,1.34,520.83]],"ltp":1.34,"tv":24391.52,"id":16325787}]}]}
{"op":"mcm","clk":"996987953","pt":1580564668502,"mc":[{"id":"1.168133553","rc":[{"batl":[[0,1.34,521.03]],"ltp":1.34,"tv":24391.52,"id":16325787}]}]}
{"op":"mcm","clk":"996988384","pt":1580564670509,"mc":[{"id":"1.168133553","rc":[{"trd":[[12.5,194.12]],"batb":[[0,12.5,1.36]],"batl":[[0,13,6.59]],"ltp":12.5,"tv":1217.85,"id":27227336},{"trd":[[1.34,4870.63]],"batl":[[0,1.34,515.07]],"ltp":1.34,"tv":24403.45,"id":16325787}],"tv":29093.55}]}
{"op":"mcm","clk":"996988564","pt":1580564671504,"mc":[{"id":"1.168133553","rc":[{"batb":[[2,11.5,23.53]],"ltp":12.5,"tv":1217.85,"id":27227336}]}]}
{"op":"mcm","clk":"996989405","pt":1580564675533,"mc":[{"id":"1.168133553","rc":[{"batl":[[0,1.34,514.87]],"ltp":1.34,"tv":24403.45,"id":16325787}]}]}
{"op":"mcm","clk":"996990232","pt":1580564679509,"mc":[{"id":"1.168133553","rc":[{"batl":[[1,1.35,1828.76]],"ltp":1.34,"tv":24403.45,"id":16325787}]}]}
{"op":"mcm","clk":"996990824","pt":1580564682508,"mc":[{"id":"1.168133553","rc":[{"trd":[[13,247.79]],"batb":[[0,12.5,12.63]],"batl":[[0,13,1.76],[1,13.5,13.72],[2,14,21.78]],"ltp":13.0,"tv":1222.68,"id":27227336},{"trd":[[5.8,310.22]],"batb":[[0,5.8,3.76],[1,5.6,20.65],[2,5.5,27.86]],"batl":[[0,5.9,7.96],[1,6,37.11],[2,6.2,32.15]],"ltp":5.8,"tv":3483.06,"id":21641292},{"trd":[[1.33,7058.45]],"batb":[[0,1.33,2.48],[1,1.32,185.9],[2,1.31,522.82]],"batl":[[0,1.34,535.87],[1,1.35,1850.76]],"ltp":1.33,"tv":24956.26,"id":16325787}],"tv":29662.0}]}
{"op":"mcm","clk":"996991006","pt":1580564683515,"mc":[{"id":"1.168133553","rc":[{"batl":[[0,1.34,619.84]],"ltp":1.33,"tv":24956.26,"id":16325787}]}]}
{"op":"mcm","clk":"996991208","pt":1580564684526,"mc":[{"id":"1.168133553","rc":[{"batl":[[0,13,11],[1,13.5,9.18]],"ltp":13.0,"tv":1222.68,"id":27227336},{"batb":[[1,5.7,8.24],[2,5.6,20.65]],"ltp":5.8,"tv":3483.06,"id":21641292}]}]}
{"op":"mcm","clk":"996991393","pt":1580564685527,"mc":[{"id":"1.168133553","rc":[{"batl":[[1,13.5,13.72]],"ltp":13.0,"tv":1222.68,"id":27227336},{"trd":[[5.8,315.29]],"batb":[[0,5.8,1.23],[2,5.6,33.22]],"ltp":5.8,"tv":3488.13,"id":21641292},{"batl":[[2,1.36,259.24]],"ltp":1.33,"tv":24956.26,"id":16325787}],"tv":29667.08}]}
{"op":"mcm","clk":"996991592","pt":1580564686557,"mc":[{"id":"1.168133553","rc":[{"batb":[[2,5.6,39.89]],"ltp":5.8,"tv":3488.13,"id":21641292}]}]}
{"op":"mcm","clk":"996991797","pt":1580564687549,"mc":[{"id":"1.168133553","rc":[{"batb":[[2,1.31,490.92]],"ltp":1.33,"tv":24956.26,"id":16325787}]}]}
{"op":"mcm","clk":"996992807","pt":1580564692556,"mc":[{"id":"1.168133553","rc":[{"batb":[[0,5.8,11.23]],"ltp":5.8,"tv":3488.13,"id":21641292},{"batl":[[0,1.34,618.17]],"ltp":1.33,"tv":24956.26,"id":16325787}]}]}
{"op":"mcm","clk":"996993217","pt":1580564694552,"mc":[{"id":"1.168133553","rc":[{"batl":[[1,13.5,20.71],[2,14,14.79]],"ltp":13.0,"tv":1222.68,"id":27227336}]}]}
{"op":"mcm","clk":"996994224","pt":1580564699563,"mc":[{"id":"1.168133553","rc":[{"batl":[[0,1.34,618.37]],"ltp":1.33,"tv":24956.26,"id":16325787}]}]}
{"op":"mcm","clk":"996995285","pt":1580564703567,"mc":[{"id":"1.168133553","rc":[{"batl":[[1,13.5,20.97]],"ltp":13.0,"tv":1222.68,"id":27227336},{"batl":[[0,1.34,618.17]],"ltp":1.33,"tv":24956.26,"id":16325787}]}]}
{"op":"mcm","clk":"996997920","pt":1580564714455,"mc":[{"id":"1.168133553","rc":[{"batb":[[1,1.32,197.28]],"ltp":1.33,"tv":24956.26,"id":16325787}]}]}
{"op":"mcm","clk":"996998123","pt":1580564715561,"mc":[{"id":"1.168133553","rc":[{"trd":[[5.8,334.03]],"batb":[[0,5.8,1.86]],"ltp":5.8,"tv":3506.87,"id":21641292}],"tv":29685.82}]}
{"op":"mcm","clk":"996998385","pt":1580564716557,"mc":[{"id":"1.168133553","rc":[{"trd":[[1.34,5878.86]],"batb":[[0,1.33,152.48],[1,1.32,381.02]],"batl":[[0,1.34,114.05]],"ltp":1.34,"tv":25964.5,"id":16325787}],"tv":30694.05}]}
{"op":"mcm","clk":"996998560","pt":1580564717474,"mc":[{"id":"1.168133553","rc":[{"batb":[[0,12.5,9.19]],"ltp":13.0,"tv":1222.68,"id":27227336},{"trd":[[5.8,337.75]],"batb":[[0,5.7,8.24],[1,5.6,33.57],[2,5.5,72.53]],"batl":[[0,5.9,24.05]],"ltp":5.8,"tv":3510.59,"id":21641292}],"tv":30697.77}]}
{"op":"mcm","clk":"996998774","pt":1580564718567,"mc":[{"id":"1.168133553","rc":[{"batl":[[0,13,18.53],[1,13.5,13.72]],"ltp":13.0,"tv":1222.68,"id":27227336},{"batb":[[1,5.6,21.54],[2,5.5,27.86]],"ltp":5.8,"tv":3510.59,"id":21641292},{"batb":[[0,1.33,231.48]],"batl":[[0,1.34,30.08]],"ltp":1.34,"tv":25964.5,"id":16325787}]}]}
{"op":"mcm","clk":"996998978","pt":1580564719571,"mc":[{"id":"1.168133553","rc":[{"batb":[[1,1.32,384.02]],"ltp":1.34,"tv":25964.5,"id":16325787}]}]}
{"op":"mcm","clk":"996999367","pt":1580564721466,"mc":[{"id":"1.168133553","rc":[{"trd":[[12.5,209.56]],"batb":[[0,12.5,5.47]],"ltp":12.5,"tv":1238.11,"id":27227336},{"trd":[[1.34,5893.52]],"batb":[[1,1.32,350.28]],"batl":[[0,1.34,22.75]],"ltp":1.34,"tv":25979.16,"id":16325787}],"tv":30727.87}]}
{"op":"mcm","clk":"996999595","pt":1580564722502,"mc":[{"id":"1.168133553","rc":[{"batl":[[0,13,9.29]],"ltp":12.5,"tv":1238.11,"id":27227336},{"batl":[[0,5.8,42.01],[1,5.9,28.75],[2,6,37.11]],"ltp":5.8,"tv":3510.59,"id":21641292}]}]}
{"op":"mcm","clk":"997000628","pt":1580564727565,"mc":[{"id":"1.168133553","rc":[{"batl":[[0,13,1.76],[1,13.5,20.97]],"ltp":12.5,"tv":1238.11,"id":27227336},{"batl":[[0,1.34,22.55]],"ltp":1.34,"tv":25979.16,"id":16325787}]}]}
{"op":"mcm","clk":"997000999","pt":1580564729476,"mc":[{"id":"1.168133553","rc":[{"batl":[[0,5.9,28.75],[1,6,37.11],[2,6.2,32.15]],"ltp":5.8,"tv":3510.59,"id":21641292},{"batl":[[0,1.34,22.75]],"ltp":1.34,"tv":25979.16,"id":16325787}]}]}
{"op":"mcm","clk":"997001207","pt":1580564730525,"mc":[{"id":"1.168133553","rc":[{"trd":[[5.7,352.27]],"batb":[[0,5.7,7]],"batl":[[0,5.8,16.16],[1,5.9,28.75],[2,6,37.11]],"ltp":5.7,"tv":3594.61,"id":21641292},{"batl":[[0,1.34,1.75]],"ltp":1.34,"tv":25979.16,"id":16325787}],"tv":30811.89}]}
{"op":"mcm","clk":"997001420","pt":1580564731504,"mc":[{"id":"1.168133553","rc":[{"batl":[[0,5.9,28.75],[1,6,46.32],[2,6.2,32.15]],"ltp":5.7,"tv":3594.61,"id":21641292},{"batl":[[0,1.34,44.07]],"ltp":1.34,"tv":25979.16,"id":16325787}]}]}
{"op":"mcm","clk":"997001643","pt":1580564732500,"mc":[{"id":"1.168133553","rc":[{"batl":[[1,6,37.11]],"ltp":5.7,"tv":3594.61,"id":21641292}]}]}
{"op":"mcm","clk":"997002082","pt":1580564734503,"mc":[{"id":"1.168133553","rc":[{"trd":[[5.7,356.27]],"batb":[[0,5.7,5]],"ltp":5.7,"tv":3598.61,"id":21641292}],"tv":30815.89}]}
{"op":"mcm","clk":"997003430","pt":1580564741512,"mc":[{"id":"1.168133553","rc":[{"trd":[[5.7,364.83]],"batb":[[0,5.7,7]],"batl":[[0,5.8,6.47],[1,5.9,28.75],[2,6,37.11]],"ltp":5.7,"tv":3607.17,"id":21641292},{"trd":[[1.34,5923.52]],"batb":[[1,1.32,475.63]],"batl":[[0,1.34,29.07]],"ltp":1.34,"tv":26009.16,"id":16325787}],"tv":30854.45}]}
{"op":"mcm","clk":"997003636","pt":1580564742539,"mc":[{"id":"1.168133553","rc":[{"batl":[[0,13,9.99]],"ltp":12.5,"tv":1238.11,"id":27227336},{"batb":[[0,5.6,21.54],[1,5.5,27.86],[2,5.4,29.18]],"batl":[[0,5.8,22.7]],"ltp":5.7,"tv":3607.17,"id":21641292},{"batb":[[0,1.34,19.51],[1,1.33,365.65],[2,1.32,475.63]],"batl":[[0,1.35,328.76],[1,1.36,283.24],[2,1.37,94.11]],"ltp":1.34,"tv":26009.16,"id":16325787}]}]}
{"op":"mcm","clk":"997003849","pt":1580564743536,"mc":[{"id":"1.168133553","rc":[{"batl":[[0,13,17.24],[1,13.5,13.72]],"ltp":12.5,"tv":1238.11,"id":27227336},{"batb":[[0,5.6,6.33],[1,5.5,21.19],[2,5.4,42.85]],"ltp":5.7,"tv":3607.17,"id":21641292},{"batl":[[0,1.35,305.19]],"ltp":1.34,"tv":26009.16,"id":16325787}]}]}
{"op":"mcm","clk":"997004096","pt":1580564744499,"mc":[{"id":"1.168133553","rc":[{"batb":[[0,1.34,94.75],[1,1.33,381.39]],"batl":[[1,1.36,236.24]],"ltp":1.34,"tv":26009.16,"id":16325787}]}]}
{"op":"mcm","clk":"997004292","pt":1580564745552,"mc":[{"id":"1.168133553","rc":[{"batb":[[0,12.5,1.47]],"batl":[[0,13,20.8]],"ltp":12.5,"tv":1238.11,"id":27227336},{"batb":[[1,1.33,415.68]],"ltp":1.34,"tv":26009.16,"id":16325787}]}]}
{"op":"mcm","clk":"997004489","pt":1580564746507,"mc":[{"id":"1.168133553","rc":[{"batl":[[0,5.7,6],[1,5.8,22.7],[2,5.9,28.75]],"ltp":5.7,"tv":3607.17,"id":21641292},{"batb":[[1,1.33,440.57]],"ltp":1.34,"tv":26009.16,"id":16325787}]}]}
{"op":"mcm","clk":"997004700","pt":1580564747546,"mc":[{"id":"1.168133553","rc":[{"batb":[[1,12,11.15],[2,11.5,23.4]],"ltp":12.5,"tv":1238.11,"id":27227336}]}]}
{"op":"mcm","clk":"997005541","pt":1580564752491,"mc":[{"id":"1.168133553","rc":[{"batl":[[0,13,21.08]],"ltp":12.5,"tv":1238.11,"id":27227336}]}]}
{"op":"mcm","clk":"997007138","pt":1580564760500,"mc":[{"id":"1.168133553","rc":[{"trd":[[1.35,16.01]],"batl":[[0,1.35,305.38]],"ltp":1.35,"tv":26009.18,"id":16325787}],"tv":30854.47}]}
{"op":"mcm","clk":"997007571","pt":1580564762499,"mc":[{"id":"1.168133553","rc":[{"batb":[[1,12,11.02],[2,11.5,23.53]],"ltp":12.5,"tv":1238.11,"id":27227336},{"trd":[[5.6,242.28]],"batb":[[0,5.6,1.17]],"ltp":5.6,"tv":3617.48,"id":21641292}],"tv":30864.78}]}
{"op":"mcm","clk":"997007786","pt":1580564763504,"mc":[{"id":"1.168133553","rc":[{"batb":[[0,12.5,5.06]],"batl":[[0,13,17.52]],"ltp":12.5,"tv":1238.11,"id":27227336},{"batb":[[0,5.5,38.56],[1,5.4,42.85],[2,5.3,82.46]],"ltp":5.6,"tv":3617.48,"id":21641292}]}]}
{"op":"mcm","clk":"997008021","pt":1580564764570,"mc":[{"id":"1.168133553","rc":[{"trd":[[12.5,219.68]],"batb":[[0,12,9.02],[1,11.5,21.53],[2,11,32.14]],"batl":[[0,12.5,2.8],[1,13,21.08],[2,13.5,10.54]],"ltp":12.5,"tv":1248.23,"id":27227336},{"batb":[[0,5.6,10.56],[1,5.5,42.1],[2,5.4,39.85]],"batl":[[2,5.9,23.66]],"ltp":5.6,"tv":3617.48,"id":21641292},{"batb":[[0,1.34,75.64],[1,1.33,413.57],[2,1.32,452.63]],"ltp":1.35,"tv":26009.18,"id":16325787}],"tv":30874.9}]}
{"op":"mcm","clk":"997008217","pt":1580564765507,"mc":[{"id":"1.168133553","rc":[{"batb":[[1,11.5,10.31]],"ltp":12.5,"tv":1248.23,"id":27227336},{"trd":[[5.7,376.83]],"batb":[[0,5.7,6],[1,5.6,10.56],[2,5.5,48.77]],"batl":[[0,5.8,22.7],[1,5.9,23.66],[2,6,37.11]],"ltp":5.7,"tv":3629.48,"id":21641292},{"batb":[[1,1.33,379.29]],"ltp":1.35,"tv":26009.18,"id":16325787}],"tv":30886.9}]}
{"op":"mcm","clk":"997008987","pt":1580564769501,"mc":[{"id":"1.168133553","rc":[{"batl":[[0,5.8,16.23]],"ltp":5.7,"tv":3629.48,"id":21641292},{"trd":[[1.34,6180.8]],"batb":[[0,1.33,426.11],[1,1.32,452.63],[2,1.31,1215.26]],"batl":[[0,1.34,171.36],[1,1.35,317.38],[2,1.36,248.24]],"ltp":1.34,"tv":26266.46,"id":16325787}],"tv":31144.18}]}
{"op":"mcm","clk":"997009168","pt":1580564770519,"mc":[{"id":"1.168133553","rc":[{"batb":[[2,11,9.03]],"batl":[[0,12.5,17.63],[1,13,13.55]],"ltp":12.5,"tv":1248.23,"id":27227336},{"batb":[[0,5.7,11]],"batl":[[0,5.9,18.96],[1,6,37.11],[2,6.2,30.15]],"ltp":5.7,"tv":3629.48,"id":21641292},{"trd":[[1.34,6196.8]],"batb":[[0,1.33,410.36],[2,1.31,469.92]],"batl":[[0,1.34,163.36]],"ltp":1.34,"tv":26282.46,"id":16325787}],"tv":31160.18}]}
{"op":"mcm","clk":"997009372","pt":1580564771496,"mc":[{"id":"1.168133553","rc":[{"batb":[[0,12,2]],"batl":[[0,12.5,2.8],[1,13,21.08]],"ltp":12.5,"tv":1248.23,"id":27227336},{"batb":[[1,5.6,18.15]],"ltp":5.7,"tv":3629.48,"id":21641292},{"batb":[[0,1.33,385.47]],"ltp":1.34,"tv":26282.46,"id":16325787}]}]}
{"op":"mcm","clk":"997010749","pt":1580564778571,"mc":[{"id":"1.168133553","rc":[{"batl":[[0,12.5,9.9]],"ltp":12.5,"tv":1248.23,"id":27227336}]}]}
{"op":"mcm","clk":"997010923","pt":1580564779472,"mc":[{"id":"1.168133553","rc":[{"batb":[[0,12,9.48]],"batl":[[0,12.5,2.8]],"ltp":12.5,"tv":1248.23,"id":27227336}]}]}
{"op":"mcm","clk":"997011288","pt":1580564781544,"mc":[{"id":"1.168133553","rc":[{"batb":[[1,5.6,24.83],[2,5.5,42.1]],"ltp":5.7,"tv":3629.48,"id":21641292}]}]}
{"op":"mcm","clk":"997011772","pt":1580564784274,"mc":[{"id":"1.168133553","rc":[{"trd":[[5.7,395.87]],"batb":[[0,5.7,6]],"batl":[[0,5.8,6.47],[1,5.9,18.96],[2,6,37.11]],"ltp":5.7,"tv":3648.52,"id":21641292},{"trd":[[1.34,6212.8]],"batl":[[0,1.34,155.36]],"ltp":1.34,"tv":26298.46,"id":16325787}],"tv":31195.22}]}
{"op":"mcm","clk":"997012003","pt":1580564785502,"mc":[{"id":"1.168133553","rc":[{"batb":[[0,12,14.04]],"ltp":12.5,"tv":1248.23,"id":27227336},{"batb":[[0,5.7,15.61]],"ltp":5.7,"tv":3648.52,"id":21641292},{"trd":[[1.34,6294.53]],"batl":[[0,1.34,114.5]],"ltp":1.34,"tv":26380.18,"id":16325787}],"tv":31276.95}]}
{"op":"mcm","clk":"997012877","pt":1580564790485,"mc":[{"id":"1.168133553","rc":[{"batl":[[0,1.34,114.7]],"ltp":1.34,"tv":26380.18,"id":16325787}]}]}
{"op":"mcm","clk":"997013246","pt":1580564792492,"mc":[{"id":"1.168133553","rc":[{"batl":[[0,13,21.08],[1,13.5,10.54],[2,14.5,19.33]],"ltp":12.5,"tv":1248.23,"id":27227336}]}]}
{"op":"mcm","clk":"997013469","pt":1580564793516,"mc":[{"id":"1.168133553","rc":[{"batb":[[0,12,6.56]],"batl":[[0,12.5,14.22],[1,13,13.55],[2,13.5,16.44]],"ltp":12.5,"tv":1248.23,"id":27227336},{"batb":[[0,5.7,28.48]],"batl":[[0,5.9,13],[1,6,37.11],[2,6.2,30.15]],"ltp":5.7,"tv":3648.52,"id":21641292},{"trd":[[1.33,7280.45],[1.34,6307.13]],"batb":[[0,1.33,274.47]],"batl":[[0,1.34,133.4]],"ltp":1.33,"tv":26614.78,"id":16325787}],"tv":31511.55}]}
{"op":"mcm","clk":"997013631","pt":1580564794428,"mc":[{"id":"1.168133553","rc":[{"batl":[[0,12.5,13.69],[1,13,21.08]],"ltp":12.5,"tv":1248.23,"id":27227336},{"batl":[[0,5.9,2]],"ltp":5.7,"tv":3648.52,"id":21641292},{"batl":[[0,1.34,318.24]],"ltp":1.33,"tv":26614.78,"id":16325787}]}]}
{"op":"mcm","clk":"997013824","pt":1580564795521,"mc":[{"id":"1.168133553","rc":[{"batb":[[2,5.5,93.44]],"ltp":5.7,"tv":3648.52,"id":21641292}]}]}
{"op":"mcm","clk":"997014002","pt":1580564796388,"mc":[{"id":"1.168133553","rc":[{"batl":[[0,12.5,6.69]],"ltp":12.5,"tv":1248.23,"id":27227336},{"batb":[[1,5.6,18.15]],"batl":[[0,5.9,15]],"ltp":5.7,"tv":3648.52,"id":21641292},{"batl":[[1,1.35,317.18]],"ltp":1.33,"tv":26614.78,"id":16325787}]}]}
{"op":"mcm","clk":"997014213","pt":1580564797519,"mc":[{"id":"1.168133553","rc":[{"batl":[[0,12.5,13.69]],"ltp":12.5,"tv":1248.23,"id":27227336},{"batb":[[0,5.7,33.32]],"batl":[[0,5.9,2]],"ltp":5.7,"tv":3648.52,"id":21641292},{"batl":[[1,1.35,322.18],[2,1.36,253.24]],"ltp":1.33,"tv":26614.78,"id":16325787}]}]}
{"op":"mcm","clk":"997014537","pt":1580564799382,"mc":[{"id":"1.168133553","rc":[{"batb":[[1,11.5,6.02]],"ltp":12.5,"tv":1248.23,"id":27227336},{"batl":[[1,6,30]],"ltp":5.7,"tv":3648.52,"id":21641292}]}]}
{"op":"mcm","clk":"997014719","pt":1580564800509,"mc":[{"id":"1.168133553","rc":[{"batb":[[1,11.5,10.63]],"ltp":12.5,"tv":1248.23,"id":27227336},{"batb":[[0,5.8,2],[1,5.7,33.32],[2,5.6,18.15]],"batl":[[0,5.9,4]],"ltp":5.7,"tv":3648.52,"id":21641292}]}]}
{"op":"mcm","clk":"997014920","pt":1580564801489,"mc":[{"id":"1.168133553","rc":[{"batl":[[0,1.34,293.24]],"ltp":1.33,"tv":26614.78,"id":16325787}]}]}
{"op":"mcm","clk":"997015690","pt":1580564805494,"mc":[{"id":"1.168133553","rc":[{"batl":[[0,12.5,21.22],[1,13,13.55]],"ltp":12.5,"tv":1248.23,"id":27227336}]}]}
{"op":"mcm","clk":"997015850","pt":1580564806182,"mc":[{"id":"1.168133553","rc":[{"trd":[[1.34,6313.19]],"batl":[[0,1.34,290.21]],"ltp":1.34,"tv":26620.84,"id":16325787}],"tv":31517.61}]}
{"op":"mcm","clk":"997016092","pt":1580564807419,"mc":[{"id":"1.168133553","rc":[{"batl":[[0,1.34,108.4]],"ltp":1.34,"tv":26620.84,"id":16325787}]}]}
{"op":"mcm","clk":"997016314","pt":1580564808517,"mc":[{"id":"1.168133553","rc":[{"batl":[[0,1.34,113.4]],"ltp":1.34,"tv":26620.84,"id":16325787}]}]}
{"op":"mcm","clk":"997016500","pt":1580564809431,"mc":[{"id":"1.168133553","rc":[{"batb":[[0,1.33,279.47]],"ltp":1.34,"tv":26620.84,"id":16325787}]}]}
{"op":"mcm","clk":"997017092","pt":1580564812520,"mc":[{"id":"1.168133553","rc":[{"batl":[[1,1.35,324.18]],"ltp":1.34,"tv":26620.84,"id":16325787}]}]}
{"op":"mcm","clk":"997017272","pt":1580564813391,"mc":[{"id":"1.168133553","rc":[{"batb":[[0,5.8,8.4],[2,5.6,68.38]],"ltp":5.7,"tv":3648.52,"id":21641292},{"trd":[[1.33,7650.14]],"batb":[[0,1.33,152.63]],"ltp":1.33,"tv":26990.52,"id":16325787}],"tv":31887.29}]}
{"op":"mcm","clk":"997017491","pt":1580564814528,"mc":[{"id":"1.168133553","rc":[{"batb":[[0,5.8,14.4],[1,5.7,40.88],[2,5.6,18.15]],"ltp":5.7,"tv":3648.52,"id":21641292}]}]}
{"op":"mcm","clk":"997017787","pt":1580564815516,"mc":[{"id":"1.168133553","rc":[{"batl":[[0,12.5,21.52]],"ltp":12.5,"tv":1248.23,"id":27227336}]}]}
{"op":"mcm","clk":"997018180","pt":1580564817418,"mc":[{"id":"1.168133553","rc":[{"trd":[[1.33,7716.14]],"batb":[[0,1.33,119.63]],"ltp":1.33,"tv":27056.52,"id":16325787}],"tv":31953.29}]}
{"op":"mcm","clk":"997018354","pt":1580564818403,"mc":[{"id":"1.168133553","marketDefinition":{"bspMarket":true,"turnInPlayEnabled":true,"persistenceEnabled":true,"marketBaseRate":5.0,"eventId":"29678760","eventTypeId":"7","numberOfWinners":1,"bettingType":"ODDS","marketType":"WIN","marketTime":"2020-02-01T14:12:00.000Z","suspendTime":"2020-02-01T14:12:00.000Z","bspReconciled":false,"complete":true,"inPlay":false,"crossMatching":true,"runnersVoidable":false,"numberOfActiveRunners":3,"betDelay":0,"status":"OPEN","runners":[{"adjustmentFactor":74.71,"status":"ACTIVE","sortPriority":1,"id":16325787,"name":"Kalooki"},{"adjustmentFactor":16.94,"status":"ACTIVE","sortPriority":2,"id":21641292,"name":"Lemon T"},{"adjustmentFactor":8.33,"status":"ACTIVE","sortPriority":3,"id":27227336,"name":"Islandray"}],"regulators":["MR_INT"],"venue":"Wetherby","countryCode":"GB","discountAllowed":true,"timezone":"Europe/London","openDate":"2020-02-01T13:03:00.000Z","version":3145318569,"name":"2m5f Nov Hrd","eventName":"Weth  1st Feb"},"rc":[{"batb":[[1,11.5,10.5],[2,11,9.16]],"ltp":12.5,"tv":1248.23,"id":27227336},{"batb":[[0,5.8,8]],"batl":[[0,5.9,10.44]],"ltp":5.7,"tv":3648.52,"id":21641292},{"trd":[[1.34,6373.19]],"batl":[[0,1.34,78.2]],"ltp":1.34,"tv":27116.52,"id":16325787}],"tv":32013.29}]}
{"op":"mcm","clk":"997018514","pt":1580564819422,"mc":[{"id":"1.168133553","rc":[{"batb":[[0,5.8,2],[1,5.7,33.32],[2,5.6,25.72]],"ltp":5.7,"tv":3648.52,"id":21641292},{"trd":[[1.33,7720.14]],"batb":[[0,1.33,112.63]],"ltp":1.33,"tv":27120.52,"id":16325787}],"tv":32017.29}]}
{"op":"mcm","clk":"997018686","pt":1580564820516,"mc":[{"id":"1.168133553","rc":[{"batb":[[0,1.33,189.82]],"ltp":1.33,"tv":27120.52,"id":16325787}]}]}
{"op":"mcm","clk":"997018849","pt":1580564821438,"mc":[{"id":"1.168133553","rc":[{"trd":[[1.33,7726.14],[1.34,6377.15]],"batb":[[0,1.33,186.82]],"batl":[[0,1.34,76.42]],"ltp":1.33,"tv":27130.48,"id":16325787}],"tv":32027.25}]}
{"op":"mcm","clk":"997019023","pt":1580564822422,"mc":[{"id":"1.168133553","rc":[{"batb":[[0,1.33,191.82]],"batl":[[0,1.34,81.42]],"ltp":1.33,"tv":27130.48,"id":16325787}]}]}
{"op":"mcm","clk":"997019530","pt":1580564824523,"mc":[{"id":"1.168133553","rc":[{"batl":[[0,5.9,32.44]],"ltp":5.7,"tv":3648.52,"id":21641292}]}]}
{"op":"mcm","clk":"997019864","pt":1580564826063,"mc":[{"id":"1.168133553","rc":[{"batl":[[0,5.9,22.44]],"ltp":5.7,"tv":3648.52,"id":21641292}]}]}
{"op":"mcm","clk":"997021339","pt":1580564834549,"mc":[{"id":"1.168133553","rc":[{"batl":[[0,5.9,20.44]],"ltp":5.7,"tv":3648.52,"id":21641292}]}]}
{"op":"mcm","clk":"997021515","pt":1580564835542,"mc":[{"id":"1.168133553","rc":[{"batb":[[0,5.7,33.32],[1,5.6,25.72],[2,5.5,93.44]],"ltp":5.7,"tv":3648.52,"id":21641292}]}]}
{"op":"mcm","clk":"997021689","pt":1580564836536,"mc":[{"id":"1.168133553","rc":[{"trd":[[12.5,229.68]],"batl":[[0,12.5,16.52]],"ltp":12.5,"tv":1258.23,"id":27227336}],"tv":32037.25}]}
{"op":"mcm","clk":"997022267","pt":1580564839552,"mc":[{"id":"1.168133553","rc":[{"trd":[[12,45.22]],"batb":[[0,12,4.56],[2,11,1.13]],"batl":[[1,13,24.67]],"ltp":12.0,"tv":1260.19,"id":27227336}],"tv":32039.21}]}
{"op":"mcm","clk":"997022442","pt":1580564840538,"mc":[{"id":"1.168133553","rc":[{"batl":[[1,6,40]],"ltp":5.7,"tv":3648.52,"id":21641292}]}]}
{"op":"mcm","clk":"997023300","pt":1580564845516,"mc":[{"id":"1.168133553","rc":[{"batb":[[0,12,9.09]],"ltp":12.0,"tv":1260.19,"id":27227336},{"batb":[[0,5.7,42.87]],"ltp":5.7,"tv":3648.52,"id":21641292},{"batb":[[0,1.33,232.73]],"ltp":1.33,"tv":27130.48,"id":16325787}]}]}
{"op":"mcm","clk":"997023506","pt":1580564846495,"mc":[{"id":"1.168133553","rc":[{"trd":[[5.7,419.86]],"batb":[[0,5.7,24.44],[2,5.5,42.1]],"ltp":5.7,"tv":3672.52,"id":21641292}],"tv":32063.2}]}
{"op":"mcm","clk":"997024435","pt":1580564851536,"mc":[{"id":"1.168133553","rc":[{"batl":[[0,1.34,81.62]],"ltp":1.33,"tv":27130.48,"id":16325787}]}]}
{"op":"mcm","clk":"997024618","pt":1580564852571,"mc":[{"id":"1.168133553","rc":[{"batb":[[0,12,16.62]],"ltp":12.0,"tv":1260.19,"id":27227336},{"batb":[[0,5.7,33.99],[2,5.5,93.44]],"ltp":5.7,"tv":3672.52,"id":21641292},{"batb":[[0,1.33,273.64]],"ltp":1.33,"tv":27130.48,"id":16325787}]}]}
{"op":"mcm","clk":"997025709","pt":1580564858454,"mc":[{"id":"1.168133553","rc":[{"batl":[[0,1.34,81.42]],"ltp":1.33,"tv":27130.48,"id":16325787}]}]}
{"op":"mcm","clk":"997027540","pt":1580564867467,"mc":[{"id":"1.168133553","rc":[{"trd":[[12,78.46]],"batb":[[0,11.5,17.89],[1,11,4.39],[2,10.5,30.72]],"batl":[[0,12,15.38],[1,12.5,16.52],[2,13,24.67]],"ltp":12.0,"tv":1293.43,"id":27227336},{"batl":[[0,5.9,8.44]],"ltp":5.7,"tv":3672.52,"id":21641292}],"tv":32096.45}]}
{"op":"mcm","clk":"997027701","pt":1580564868351,"mc":[{"id":"1.168133553","rc":[{"batb":[[0,11.5,30.66],[1,11,15.49]],"batl":[[1,12.5,20.86],[2,13,16.44]],"ltp":12.0,"tv":1293.43,"id":27227336},{"batb":[[0,5.8,12.62],[1,5.7,46.91],[2,5.6,25.72]],"batl":[[0,5.9,19.7]],"ltp":5.7,"tv":3672.52,"id":21641292},{"trd":[[1.34,6596.28]],"batb":[[0,1.34,50.26],[1,1.33,310.21],[2,1.32,452.63]],"batl":[[0,1.35,324.18],[1,1.36,253.24],[2,1.37,96.11]],"ltp":1.34,"tv":27349.61,"id":16325787}],"tv":32315.57}]}
{"op":"mcm","clk":"997027918","pt":1580564869455,"mc":[{"id":"1.168133553","rc":[{"batb":[[0,11.5,18.66],[1,11,4.39]],"batl":[[0,12,23.53],[1,12.5,13.03]],"ltp":12.0,"tv":1293.43,"id":27227336},{"batb":[[2,5.6,18.15]],"ltp":5.7,"tv":3672.52,"id":21641292},{"batb":[[0,1.34,132.1],[1,1.33,326.46]],"ltp":1.34,"tv":27349.61,"id":16325787}]}]}
{"op":"mcm","clk":"997028258","pt":1580564871157,"mc":[{"id":"1.168133553","rc":[{"trd":[[1.34,6796.28]],"batb":[[0,1.34,82.1],[2,1.32,554.15]],"ltp":1.34,"tv":27549.61,"id":16325787}],"tv":32515.57}]}
{"op":"mcm","clk":"997028632","pt":1580564873388,"mc":[{"id":"1.168133553","rc":[{"batl":[[2,1.37,97.11]],"ltp":1.34,"tv":27549.61,"id":16325787}]}]}
{"op":"mcm","clk":"997029348","pt":1580564877415,"mc":[{"id":"1.168133553","rc":[{"trd":[[1.34,6798.28]],"batb":[[0,1.34,81.1]],"batl":[[2,1.37,96.11]],"ltp":1.34,"tv":27551.61,"id":16325787}],"tv":32517.57}]}
{"op":"mcm","clk":"997030037","pt":1580564881562,"mc":[{"id":"1.168133553","rc":[{"trd":[[5.8,347.75]],"batb":[[0,5.8,7.62]],"ltp":5.8,"tv":3682.52,"id":21641292},{"batl":[[0,1.35,324.38],[2,1.37,94.11]],"ltp":1.34,"tv":27551.61,"id":16325787}],"tv":32527.57}]}
{"op":"mcm","clk":"997030371","pt":1580564883547,"mc":[{"id":"1.168133553","rc":[{"batb":[[1,1.33,349.83]],"ltp":1.34,"tv":27551.61,"id":16325787}]}]}
{"op":"mcm","clk":"997030927","pt":1580564886549,"mc":[{"id":"1.168133553","rc":[{"batl":[[0,12,31.6],[1,12.5,11.34]],"ltp":12.0,"tv":1293.43,"id":27227336},{"batb":[[0,1.34,88.66]],"ltp":1.34,"tv":27551.61,"id":16325787}]}]}
{"op":"mcm","clk":"997031031","pt":1580564887023,"mc":[{"id":"1.168133553","rc":[{"batb":[[2,10.5,6.39]],"ltp":12.0,"tv":1293.43,"id":27227336},{"trd":[[5.8,357.75]],"batb":[[0,5.8,2.62]],"ltp":5.8,"tv":3692.52,"id":21641292},{"trd":[[1.35,50.01]],"batl":[[0,1.35,307.38]],"ltp":1.35,"tv":27585.61,"id":16325787}],"tv":32571.57}]}
{"op":"mcm","clk":"997031441","pt":1580564889405,"mc":[{"id":"1.168133553","rc":[{"batl":[[0,5.9,17.7]],"ltp":5.8,"tv":3692.52,"id":21641292}]}]}
{"op":"mcm","clk":"997032105","pt":1580564893551,"mc":[{"id":"1.168133553","rc":[{"trd":[[1.34,6878.28]],"batb":[[0,1.34,48.66]],"ltp":1.34,"tv":27665.61,"id":16325787}],"tv":32651.57}]}
{"op":"mcm","clk":"997032265","pt":1580564894452,"mc":[{"id":"1.168133553","rc":[{"batb":[[0,1.34,115.82]],"ltp":1.34,"tv":27665.61,"id":16325787}]}]}
{"op":"mcm","clk":"997033354","pt":1580564900571,"mc":[{"id":"1.168133553","rc":[{"trd":[[11.5,41.24]],"batb":[[0,11.5,14.17]],"ltp":11.5,"tv":1298.43,"id":27227336},{"batl":[[0,5.9,20.2],[1,6,35]],"ltp":5.8,"tv":3692.52,"id":21641292}],"tv":32656.56}]}
{"op":"mcm","clk":"997034761","pt":1580564909574,"mc":[{"id":"1.168133553","rc":[{"trd":[[5.7,460.99],[5.8,362.99]],"batb":[[0,5.7,26.35],[1,5.6,18.15],[2,5.5,93.44]],"batl":[[0,5.8,12.38],[1,5.9,20.2],[2,6,35]],"ltp":5.7,"tv":3738.89,"id":21641292},{"batl":[[0,1.35,290.38],[2,1.37,107.11]],"ltp":1.34,"tv":27665.61,"id":16325787}],"tv":32702.93}]}
{"op":"mcm","clk":"997034904","pt":1580564910486,"mc":[{"id":"1.168133553","rc":[{"batb":[[0,11.5,16.17],[2,10.5,30.72]],"ltp":11.5,"tv":1298.43,"id":27227336},{"batb":[[0,5.7,30.35],[2,5.5,42.1]],"ltp":5.7,"tv":3738.89,"id":21641292},{"batl":[[0,1.35,290.18],[1,1.36,248.24]],"ltp":1.34,"tv":27665.61,"id":16325787}]}]}
{"op":"mcm","clk":"997035067","pt":1580564911474,"mc":[{"id":"1.168133553","rc":[{"batl":[[2,6,41.96]],"ltp":5.7,"tv":3738.89,"id":21641292}]}]}
{"op":"mcm","clk":"997035202","pt":1580564912283,"mc":[{"id":"1.168133553","rc":[{"batl":[[0,1.35,290.38]],"ltp":1.34,"tv":27665.61,"id":16325787}]}]}
{"op":"mcm","clk":"997035839","pt":1580564916474,"mc":[{"id":"1.168133553","rc":[{"trd":[[12,84.44]],"batb":[[0,11.5,24.78]],"batl":[[0,12,25.62],[1,12.5,8.34]],"ltp":12.0,"tv":1304.41,"id":27227336},{"trd":[[5.8,375.37]],"batb":[[0,5.8,24.14],[1,5.7,30.35],[2,5.6,68.38]],"batl":[[0,5.9,8.94],[1,6,35],[2,6.2,25.84]],"ltp":5.8,"tv":3751.27,"id":21641292},{"trd":[[1.34,7253.51]],"batb":[[0,1.33,299.26],[1,1.32,554.15],[2,1.31,470.12]],"batl":[[0,1.34,116.32],[1,1.35,304.38],[2,1.36,248.24]],"ltp":1.34,"tv":28040.84,"id":16325787}],"tv":33096.52}]}
{"op":"mcm","clk":"997035907","pt":1580564916865,"mc":[{"id":"1.168133553","rc":[{"batb":[[0,11.5,29.06]],"ltp":12.0,"tv":1304.41,"id":27227336},{"batb":[[1,5.7,35.39]],"ltp":5.8,"tv":3751.27,"id":21641292}]}]}
{"op":"mcm","clk":"997037272","pt":1580564925425,"mc":[{"id":"1.168133553","rc":[{"trd":[[1.33,7826.14]],"batb":[[0,1.33,249.26]],"ltp":1.33,"tv":28140.84,"id":16325787}],"tv":33196.52}]}
{"op":"mcm","clk":"997037388","pt":1580564926105,"mc":[{"id":"1.168133553","rc":[{"batl":[[0,5.9,2.5]],"ltp":5.8,"tv":3751.27,"id":21641292},{"batb":[[0,1.33,282.21]],"ltp":1.33,"tv":28140.84,"id":16325787}]}]}
{"op":"mcm","clk":"997037610","pt":1580564927415,"mc":[{"id":"1.168133553","rc":[{"trd":[[5.9,253.19]],"batl":[[0,6,35],[1,6.2,25.84],[2,6.4,38.38]],"ltp":5.9,"tv":3756.27,"id":21641292},{"trd":[[1.33,7830.14]],"batb":[[0,1.33,256.84]],"ltp":1.33,"tv":28144.84,"id":16325787}],"tv":33205.52}]}
{"op":"mcm","clk":"997037927","pt":1580564929405,"mc":[{"id":"1.168133553","rc":[{"batl":[[0,5.9,1.9],[1,6,35],[2,6.2,25.84]],"ltp":5.9,"tv":3756.27,"id":21641292}]}]}
{"op":"mcm","clk":"997038108","pt":1580564930524,"mc":[{"id":"1.168133553","rc":[{"trd":[[5.8,391.37]],"batb":[[0,5.8,16.14],[2,5.6,18.15]],"ltp":5.8,"tv":3772.27,"id":21641292}],"tv":33221.52}]}
{"op":"mcm","clk":"997038225","pt":1580564931317,"mc":[{"id":"1.168133553","rc":[{"batl":[[2,6.2,37.95]],"ltp":5.8,"tv":3772.27,"id":21641292}]}]}
{"op":"mcm","clk":"997038309","pt":1580564931816,"mc":[{"id":"1.168133553","rc":[{"batl":[[0,5.9,4.41]],"ltp":5.8,"tv":3772.27,"id":21641292}]}]}
{"op":"mcm","clk":"997039492","pt":1580564938813,"mc":[{"id":"1.168133553","rc":[{"batl":[[1,1.35,302.38]],"ltp":1.33,"tv":28144.84,"id":16325787}]}]}
{"op":"mcm","clk":"997040074","pt":1580564942513,"mc":[{"id":"1.168133553","rc":[{"batl":[[0,1.34,116.52]],"ltp":1.33,"tv":28144.84,"id":16325787}]}]}
{"op":"mcm","clk":"997040262","pt":1580564943708,"mc":[{"id":"1.168133553","rc":[{"trd":[[1.33,7870.14]],"batb":[[0,1.33,236.84]],"ltp":1.33,"tv":28184.84,"id":16325787}],"tv":33261.52}]}
{"op":"mcm","clk":"997040720","pt":1580564946540,"mc":[{"id":"1.168133553","rc":[{"trd":[[11.5,59.72]],"batb":[[0,11.5,19.82]],"batl":[[0,12,10.55]],"ltp":11.5,"tv":1322.89,"id":27227336},{"trd":[[1.34,7257.51]],"batb":[[0,1.33,253.21]],"batl":[[0,1.34,114.52],[1,1.35,305.38]],"ltp":1.34,"tv":28188.84,"id":16325787}],"tv":33284.0}]}
{"op":"mcm","clk":"997040900","pt":1580564947509,"mc":[{"id":"1.168133553","rc":[{"batb":[[0,11.5,19.95],[1,11,4.26]],"batl":[[0,12,2.4],[1,12.5,16.17]],"ltp":11.5,"tv":1322.89,"id":27227336}]}]}
{"op":"mcm","clk":"997041068","pt":1580564948533,"mc":[{"id":"1.168133553","rc":[{"batl":[[1,12.5,22.46]],"ltp":11.5,"tv":1322.89,"id":27227336}]}]}
{"op":"mcm","clk":"997041350","pt":1580564950339,"mc":[{"id":"1.168133553","rc":[{"batl":[[1,1.35,305.18]],"ltp":1.34,"tv":28188.84,"id":16325787}]}]}
{"op":"mcm","clk":"997042982","pt":1580564960457,"mc":[{"id":"1.168133553","rc":[{"trd":[[12,89.24],[12.5,233.84]],"batl":[[0,12.5,20.38],[1,13,16.44],[2,13.5,4.54]],"ltp":12.5,"tv":1331.85,"id":27227336}],"tv":33292.97}]}
{"op":"mcm","clk":"997043163","pt":1580564961446,"mc":[{"id":"1.168133553","rc":[{"batl":[[1,13,18.64]],"ltp":12.5,"tv":1331.85,"id":27227336},{"trd":[[5.8,423.64]],"batb":[[0,5.7,35.39],[1,5.6,18.15],[2,5.5,93.44]],"batl":[[0,5.8,10.37],[1,5.9,4.41],[2,6,35]],"ltp":5.8,"tv":3804.54,"id":21641292}],"tv":33325.24}]}
{"op":"mcm","clk":"997043278","pt":1580564962139,"mc":[{"id":"1.168133553","rc":[{"batl":[[0,12.5,22.46]],"ltp":12.5,"tv":1331.85,"id":27227336},{"batl":[[1,5.9,12.52]],"ltp":5.8,"tv":3804.54,"id":21641292}]}]}
{"op":"mcm","clk":"997043489","pt":1580564963533,"mc":[{"id":"1.168133553","rc":[{"batl":[[0,12.5,18.12]],"ltp":12.5,"tv":1331.85,"id":27227336},{"batb":[[1,5.6,20.29]],"ltp":5.8,"tv":3804.54,"id":21641292}]}]}
{"op":"mcm","clk":"997043660","pt":1580564964743,"mc":[{"id":"1.168133553","rc":[{"batb":[[1,5.6,18.15]],"ltp":5.8,"tv":3804.54,"id":21641292}]}]}
{"op":"mcm","clk":"997044659","pt":1580564970519,"mc":[{"id":"1.168133553","rc":[{"trd":[[5.7,466.99]],"batb":[[0,5.7,32.39]],"ltp":5.7,"tv":3810.54,"id":21641292}],"tv":33331.24}]}
{"op":"mcm","clk":"997044802","pt":1580564971329,"mc":[{"id":"1.168133553","rc":[{"trd":[[12,93.82]],"batb":[[0,11.5,19.82],[1,11,6.8]],"batl":[[2,13.5,14.54]],"ltp":12.0,"tv":1336.43,"id":27227336},{"trd":[[5.8,434.91]],"batl":[[0,5.9,12.52],[1,6,35],[2,6.2,25.84]],"ltp":5.8,"tv":3821.81,"id":21641292},{"trd":[[1.34,7298.47]],"batl":[[0,1.34,73.56]],"ltp":1.34,"tv":28229.8,"id":16325787}],"tv":33388.04}]}
{"op":"mcm","clk":"997045020","pt":1580564972553,"mc":[{"id":"1.168133553","rc":[{"batl":[[1,6,45.75]],"ltp":5.8,"tv":3821.81,"id":21641292}]}]}
{"op":"mcm","clk":"997045188","pt":1580564973481,"mc":[{"id":"1.168133553","rc":[{"batl":[[1,6,35]],"ltp":5.8,"tv":3821.81,"id":21641292}]}]}
{"op":"mcm","clk":"997045379","pt":1580564974462,"mc":[{"id":"1.168133553","rc":[{"trd":[[11.5,74.87]],"batb":[[0,11.5,15.24]],"ltp":11.5,"tv":1351.57,"id":27227336}],"tv":33403.19}]}
{"op":"mcm","clk":"997046114","pt":1580564978563,"mc":[{"id":"1.168133553","rc":[{"batl":[[0,1.34,73.36]],"ltp":1.34,"tv":28229.8,"id":16325787}]}]}
{"op":"mcm","clk":"997046513","pt":1580564980558,"mc":[{"id":"1.168133553","rc":[{"trd":[[11.5,91.01]],"batb":[[0,11.5,15.37]],"batl":[[0,12.5,25.93]],"ltp":11.5,"tv":1367.71,"id":27227336},{"batb":[[0,5.8,5.22],[1,5.7,32.39],[2,5.6,18.15]],"batl":[[0,5.9,4.41]],"ltp":5.8,"tv":3821.81,"id":21641292},{"trd":[[1.34,7315.15]],"batl":[[0,1.34,65.02]],"ltp":1.34,"tv":28246.48,"id":16325787}],"tv":33436.01}]}
{"op":"mcm","clk":"997046653","pt":1580564981339,"mc":[{"id":"1.168133553","rc":[{"batb":[[0,11.5,11.19]],"batl":[[0,12.5,30.18]],"ltp":11.5,"tv":1367.71,"id":27227336}]}]}
{"op":"mcm","clk":"997048068","pt":1580564989573,"mc":[{"id":"1.168133553","rc":[{"batb":[[0,1.33,289.48]],"ltp":1.34,"tv":28246.48,"id":16325787}]}]}
{"op":"mcm","clk":"997048263","pt":1580564990559,"mc":[{"id":"1.168133553","rc":[{"batl":[[0,12,4.27],[1,12.5,30.18],[2,13,18.64]],"ltp":11.5,"tv":1367.71,"id":27227336},{"trd":[[5.8,438.91]],"batb":[[0,5.8,3.22]],"ltp":5.8,"tv":3825.81,"id":21641292}],"tv":33440.01}]}
{"op":"mcm","clk":"997048432","pt":1580564991438,"mc":[{"id":"1.168133553","rc":[{"batb":[[0,11.5,17.95]],"ltp":11.5,"tv":1367.71,"id":27227336},{"batb":[[0,5.8,16.62]],"batl":[[0,5.9,11.07]],"ltp":5.8,"tv":3825.81,"id":21641292},{"trd":[[1.34,7431.17]],"batl":[[0,1.34,7.01]],"ltp":1.34,"tv":28362.5,"id":16325787}],"tv":33556.03}]}
{"op":"mcm","clk":"997048615","pt":1580564992569,"mc":[{"id":"1.168133553","rc":[{"batb":[[0,11.5,22.23]],"ltp":11.5,"tv":1367.71,"id":27227336},{"batb":[[0,1.33,305.39]],"ltp":1.34,"tv":28362.5,"id":16325787}]}]}
{"op":"mcm","clk":"997048746","pt":1580564993428,"mc":[{"id":"1.168133553","rc":[{"trd":[[12,94.6]],"batl":[[0,12,3.49]],"ltp":12.0,"tv":1368.49,"id":27227336},{"trd":[[5.8,477.71]],"batb":[[0,5.7,47.61],[1,5.6,18.15],[2,5.5,42.1]],"batl":[[0,5.9,21.07]],"ltp":5.8,"tv":3864.61,"id":21641292},{"trd":[[1.34,7438.18]],"batb":[[0,1.34,44.29],[1,1.33,677.5],[2,1.32,554.15]],"batl":[[0,1.35,291.18],[1,1.36,248.24],[2,1.37,107.11]],"ltp":1.34,"tv":28369.51,"id":16325787}],"tv":33602.63}]}
{"op":"mcm","clk":"997048940","pt":1580564994535,"mc":[{"id":"1.168133553","rc":[{"batb":[[2,1.32,491.48]],"ltp":1.34,"tv":28369.51,"id":16325787}]}]}
{"op":"mcm","clk":"997049512","pt":1580564997561,"mc":[{"id":"1.168133553","rc":[{"batb":[[1,1.33,641.23]],"ltp":1.34,"tv":28369.51,"id":16325787}]}]}
{"op":"mcm","clk":"997050261","pt":1580565001561,"mc":[{"id":"1.168133553","rc":[{"batl":[[0,1.35,291.38]],"ltp":1.34,"tv":28369.51,"id":16325787}]}]}
{"op":"mcm","clk":"997050429","pt":1580565002558,"mc":[{"id":"1.168133553","rc":[{"trd":[[11.5,95.01]],"batb":[[0,11.5,20.23],[2,10.5,6.39]],"ltp":11.5,"tv":1372.49,"id":27227336}],"tv":33606.63}]}
{"op":"mcm","clk":"997051966","pt":1580565010884,"mc":[{"id":"1.168133553","rc":[{"trd":[[1.34,7477.88]],"batb":[[0,1.34,24.44]],"ltp":1.34,"tv":28409.21,"id":16325787}],"tv":33646.33}]}
{"op":"mcm","clk":"997052247","pt":1580565012472,"mc":[{"id":"1.168133553","rc":[{"trd":[[5.7,472.99]],"batb":[[0,5.7,44.61]],"ltp":5.7,"tv":3870.61,"id":21641292},{"trd":[[1.35,76.01]],"batb":[[0,1.34,128.76],[1,1.33,680.18]],"batl":[[0,1.35,278.38]],"ltp":1.35,"tv":28435.21,"id":16325787}],"tv":33678.32}]}
{"op":"mcm","clk":"997052446","pt":1580565013559,"mc":[{"id":"1.168133553","rc":[{"batb":[[0,11.5,15.95]],"ltp":11.5,"tv":1372.49,"id":27227336},{"batl":[[1,6,47.35]],"ltp":5.7,"tv":3870.61,"id":21641292},{"batb":[[0,1.34,147.72]],"ltp":1.35,"tv":28435.21,"id":16325787}]}]}
{"op":"mcm","clk":"997052925","pt":1580565016491,"mc":[{"id":"1.168133553","rc":[{"trd":[[12,101.58]],"batb":[[0,12,1.43],[1,11.5,15.95],[2,11,5.8]],"batl":[[0,12.5,30.18],[1,13,18.64],[2,13.5,14.54]],"ltp":12.0,"tv":1379.47,"id":27227336}],"tv":33685.3}]}
{"op":"mcm","clk":"997053090","pt":1580565017489,"mc":[{"id":"1.168133553","rc":[{"trd":[[12,104.43]],"batb":[[0,11.5,17.95],[1,11,5.8],[2,10.5,6.39]],"batl":[[0,12,3.09],[1,12.5,29.36],[2,13,27.35]],"ltp":12.0,"tv":1382.33,"id":27227336},{"batb":[[0,1.34,165.28]],"ltp":1.35,"tv":28435.21,"id":16325787}],"tv":33688.16}]}
{"op":"mcm","clk":"997055245","pt":1580565030274,"mc":[{"id":"1.168133553","rc":[{"batl":[[0,1.35,278.18]],"ltp":1.35,"tv":28435.21,"id":16325787}]}]}
{"op":"mcm","clk":"997055758","pt":1580565033384,"mc":[{"id":"1.168133553","rc":[{"trd":[[11.5,111.37]],"batb":[[0,11.5,9.77]],"batl":[[0,12,7.06]],"ltp":11.5,"tv":1398.69,"id":27227336},{"batb":[[0,1.34,174.75]],"ltp":1.35,"tv":28435.21,"id":16325787}],"tv":33704.52}]}
{"op":"mcm","clk":"997055948","pt":1580565034567,"mc":[{"id":"1.168133553","rc":[{"batb":[[0,11.5,8.76]],"ltp":11.5,"tv":1398.69,"id":27227336}]}]}
{"op":"mcm","clk":"997057349","pt":1580565043564,"mc":[{"id":"1.168133553","rc":[{"trd":[[12,104.55]],"batl":[[0,12,7]],"ltp":12.0,"tv":1398.81,"id":27227336}],"tv":33704.64}]}
{"op":"mcm","clk":"997057783","pt":1580565046408,"mc":[{"id":"1.168133553","rc":[{"batl":[[0,12,3.03]],"ltp":12.0,"tv":1398.81,"id":27227336},{"trd":[[1.34,7497.88]],"batb":[[0,1.34,164.75]],"ltp":1.34,"tv":28455.21,"id":16325787}],"tv":33724.64}]}
{"op":"mcm","clk":"997059683","pt":1580565058507,"mc":[{"id":"1.168133553","rc":[{"trd":[[11.5,121.37]],"batb":[[0,11.5,3.76]],"ltp":11.5,"tv":1408.81,"id":27227336}],"tv":33734.64}]}
{"op":"mcm","clk":"997059988","pt":1580565060523,"mc":[{"id":"1.168133553","rc":[{"batl":[[0,1.35,278.38]],"ltp":1.34,"tv":28455.21,"id":16325787}]}]}
{"op":"mcm","clk":"997060638","pt":1580565064502,"mc":[{"id":"1.168133553","rc":[{"trd":[[5.6,253.05],[5.7,562.22]],"batb":[[0,5.7,13.82],[1,5.6,26.84],[2,5.5,69.71]],"ltp":5.6,"tv":3970.61,"id":21641292}],"tv":33834.64}]}
{"op":"mcm","clk":"997060820","pt":1580565065492,"mc":[{"id":"1.168133553","rc":[{"trd":[[5.7,574.22]],"batb":[[0,5.7,12.82]],"ltp":5.7,"tv":3982.61,"id":21641292}],"tv":33846.64}]}
{"op":"mcm","clk":"997060972","pt":1580565066300,"mc":[{"id":"1.168133553","rc":[{"trd":[[12,124.63]],"batl":[[1,12.5,27.36]],"ltp":12.0,"tv":1428.89,"id":27227336},{"batl":[[0,5.8,6.87],[1,5.9,21.07],[2,6,47.35]],"ltp":5.7,"tv":3982.61,"id":21641292},{"batl":[[0,1.35,288.38]],"ltp":1.34,"tv":28455.21,"id":16325787}],"tv":33866.72}]}
{"op":"mcm","clk":"997061186","pt":1580565067494,"mc":[{"id":"1.168133553","rc":[{"trd":[[11.5,135.56]],"batb":[[0,11.5,1.4],[1,11,14.9],[2,10.5,30.72]],"ltp":11.5,"tv":1443.08,"id":27227336},{"trd":[[5.8,484.58]],"batb":[[0,5.7,15.48]],"batl":[[0,5.9,21.07],[1,6,47.35],[2,6.2,25.84]],"ltp":5.8,"tv":3989.48,"id":21641292},{"trd":[[1.35,114.71]],"batb":[[0,1.34,155.28]],"batl":[[0,1.35,254.28]],"ltp":1.35,"tv":28493.91,"id":16325787}],"tv":33926.48}]}
{"op":"mcm","clk":"997061353","pt":1580565068478,"mc":[{"id":"1.168133553","rc":[{"batb":[[0,11,17.08],[1,10.5,33.72],[2,10,58.88]],"batl":[[0,12,5.03]],"ltp":11.5,"tv":1443.08,"id":27227336}]}]}
{"op":"mcm","clk":"997061501","pt":1580565069284,"mc":[{"id":"1.168133553","rc":[{"batb":[[1,10.5,9.39]],"batl":[[1,12.5,29.71]],"ltp":11.5,"tv":1443.08,"id":27227336}]}]}
{"op":"mcm","clk":"997063101","pt":1580565079499,"mc":[{"id":"1.168133553","rc":[{"batb":[[1,5.6,35.78],[2,5.5,60.78]],"ltp":5.8,"tv":3989.48,"id":21641292}]}]}
{"op":"mcm","clk":"997063422","pt":1580565081496,"mc":[{"id":"1.168133553","rc":[{"trd":[[5.7,578.22]],"batb":[[0,5.7,13.48]],"ltp":5.7,"tv":3993.48,"id":21641292},{"trd":[[1.34,7503.88],[1.35,132.7]],"batb":[[0,1.34,152.28]],"batl":[[0,1.35,245.29]],"ltp":1.35,"tv":28517.9,"id":16325787}],"tv":33954.47}]}
{"op":"mcm","clk":"997065689","pt":1580565093521,"mc":[{"id":"1.168133553","rc":[{"trd":[[1.35,142.69]],"batl":[[0,1.35,240.3]],"ltp":1.35,"tv":28527.9,"id":16325787}],"tv":33964.46}]}
{"op":"mcm","clk":"997066003","pt":1580565095507,"mc":[{"id":"1.168133553","rc":[{"batb":[[2,5.5,52.9]],"ltp":5.7,"tv":3993.48,"id":21641292},{"trd":[[1.34,7513.88]],"batb":[[0,1.34,147.28]],"ltp":1.34,"tv":28537.9,"id":16325787}],"tv":33974.46}]}
{"op":"mcm","clk":"997066505","pt":1580565098551,"mc":[{"id":"1.168133553","rc":[{"batl":[[0,1.35,240.1]],"ltp":1.34,"tv":28537.9,"id":16325787}]}]}
{"op":"mcm","clk":"997067396","pt":1580565103418,"mc":[{"id":"1.168133553","rc":[{"batb":[[0,11.5,8],[1,11,17.08],[2,10.5,9.39]],"ltp":11.5,"tv":1443.08,"id":27227336},{"batb":[[0,1.34,165.28]],"ltp":1.34,"tv":28537.9,"id":16325787}]}]}
{"op":"mcm","clk":"997069357","pt":1580565113558,"mc":[{"id":"1.168133553","rc":[{"trd":[[11.5,146.96]],"batb":[[0,11.5,2.3]],"batl":[[0,12,9.07]],"ltp":11.5,"tv":1454.48,"id":27227336},{"batb":[[0,5.7,20.33]],"ltp":5.7,"tv":3993.48,"id":21641292},{"trd":[[1.34,7567.63],[1.35,160.5]],"batb":[[0,1.34,86.25]],"batl":[[0,1.35,231.2]],"ltp":1.35,"tv":28609.46,"id":16325787}],"tv":34057.42}]}
{"op":"mcm","clk":"997070384","pt":1580565119489,"mc":[{"id":"1.168133553","rc":[{"batl":[[0,1.35,231.4]],"ltp":1.35,"tv":28609.46,"id":16325787}]}]}
{"op":"mcm","clk":"997070494","pt":1580565120202,"mc":[{"id":"1.168133553","rc":[{"batb":[[0,1.34,88.25]],"ltp":1.35,"tv":28609.46,"id":16325787}]}]}
{"op":"mcm","clk":"997070737","pt":1580565121567,"mc":[{"id":"1.168133553","rc":[{"batb":[[1,11,23.87]],"batl":[[2,13,33.69]],"ltp":11.5,"tv":1454.48,"id":27227336},{"batb":[[1,5.6,43.29]],"batl":[[1,6,54.69]],"ltp":5.7,"tv":3993.48,"id":21641292},{"batb":[[2,1.32,517.21]],"ltp":1.35,"tv":28609.46,"id":16325787}]}]}
{"op":"mcm","clk":"997070895","pt":1580565122491,"mc":[{"id":"1.168133553","rc":[{"trd":[[5.6,275.69],[5.7,618.87]],"batb":[[0,5.6,31.98],[1,5.5,52.9],[2,5.4,93.19]],"ltp":5.6,"tv":4056.77,"id":21641292}],"tv":34120.72}]}
{"op":"mcm","clk":"997071069","pt":1580565123461,"mc":[{"id":"1.168133553","rc":[{"batb":[[0,11.5,6.36]],"batl":[[0,12,5.03]],"ltp":11.5,"tv":1454.48,"id":27227336},{"batb":[[0,5.7,19.13],[1,5.6,28.04],[2,5.5,61.83]],"ltp":5.6,"tv":4056.77,"id":21641292}]}]}
{"op":"mcm","clk":"997071925","pt":1580565128496,"mc":[{"id":"1.168133553","rc":[{"trd":[[11.5,150.32]],"batb":[[0,11.5,4.68]],"ltp":11.5,"tv":1457.84,"id":27227336}],"tv":34124.08}]}
{"op":"mcm","clk":"997072729","pt":1580565133503,"mc":[{"id":"1.168133553","rc":[{"trd":[[12,142.63]],"batb":[[0,11.5,7.06]],"batl":[[0,12,1.1]],"ltp":12.0,"tv":1475.84,"id":27227336},{"batb":[[0,5.7,14.13]],"batl":[[0,5.8,6.93],[1,5.9,21.07],[2,6,54.69]],"ltp":5.6,"tv":4056.77,"id":21641292}],"tv":34142.08}]}
{"op":"mcm","clk":"997072870","pt":1580565134376,"mc":[{"id":"1.168133553","rc":[{"batb":[[0,11.5,12.54],[2,10.5,33.72]],"batl":[[1,12.5,27.36],[2,13,27.99]],"ltp":12.0,"tv":1475.84,"id":27227336},{"batl":[[2,6,62]],"ltp":5.6,"tv":4056.77,"id":21641292}]}]}
{"op":"mcm","clk":"997072930","pt":1580565134698,"mc":[{"id":"1.168133553","rc":[{"batl":[[2,13,34.5]],"ltp":12.0,"tv":1475.84,"id":27227336}]}]}
{"op":"mcm","clk":"997073197","pt":1580565136361,"mc":[{"id":"1.168133553","rc":[{"batb":[[0,1.34,103.25]],"batl":[[0,1.35,260.41]],"ltp":1.35,"tv":28609.46,"id":16325787}]}]}
{"op":"mcm","clk":"997073373","pt":1580565137336,"mc":[{"id":"1.168133553","rc":[{"trd":[[5.7,626.87]],"batb":[[0,5.7,10.13]],"ltp":5.7,"tv":4064.77,"id":21641292}],"tv":34150.08}]}
{"op":"mcm","clk":"997073895","pt":1580565140250,"mc":[{"id":"1.168133553","rc":[{"batl":[[1,1.36,249.92]],"ltp":1.35,"tv":28609.46,"id":16325787}]}]}
{"op":"mcm","clk":"997074033","pt":1580565140949,"mc":[{"id":"1.168133553","rc":[{"batb":[[1,1.33,681.86]],"ltp":1.35,"tv":28609.46,"id":16325787}]}]}
{"op":"mcm","clk":"997074793","pt":1580565144553,"mc":[{"id":"1.168133553","rc":[{"trd":[[1.35,165.04]],"batl":[[0,1.35,260.41]],"ltp":1.35,"tv":28614.0,"id":16325787}],"tv":34154.62}]}
{"op":"mcm","clk":"997074959","pt":1580565145467,"mc":[{"id":"1.168133553","rc":[{"batl":[[0,1.35,310.41]],"ltp":1.35,"tv":28614.0,"id":16325787}]}]}
{"op":"mcm","clk":"997075179","pt":1580565146555,"mc":[{"id":"1.168133553","rc":[{"trd":[[1.34,7572.21]],"batb":[[0,1.34,228.97]],"batl":[[0,1.35,308.14]],"ltp":1.34,"tv":28618.57,"id":16325787}],"tv":34159.19}]}
{"op":"mcm","clk":"997075306","pt":1580565147257,"mc":[{"id":"1.168133553","rc":[{"batb":[[1,1.33,642.97]],"ltp":1.34,"tv":28618.57,"id":16325787}]}]}
{"op":"mcm","clk":"997075700","pt":1580565149449,"mc":[{"id":"1.168133553","rc":[{"trd":[[11.5,160.31]],"batb":[[0,11.5,7.55]],"ltp":11.5,"tv":1485.83,"id":27227336}],"tv":34169.18}]}
{"op":"mcm","clk":"997076069","pt":1580565151566,"mc":[{"id":"1.168133553","rc":[{"batl":[[0,12,3.1]],"ltp":11.5,"tv":1485.83,"id":27227336}]}]}
{"op":"mcm","clk":"997076227","pt":1580565152460,"mc":[{"id":"1.168133553","rc":[{"trd":[[12,152.83]],"batb":[[0,12,9.9],[1,11.5,9.55],[2,11,23.87]],"batl":[[0,12.5,27.36],[1,13,34.5],[2,13.5,14.54]],"ltp":12.0,"tv":1496.03,"id":27227336}],"tv":34179.38}]}
{"op":"mcm","clk":"997076359","pt":1580565153273,"mc":[{"id":"1.168133553","rc":[{"batb":[[2,11,31.06]],"batl":[[0,12.5,21.88],[1,13,27.99]],"ltp":12.0,"tv":1496.03,"id":27227336},{"batl":[[0,5.8,18.11]],"ltp":5.7,"tv":4064.77,"id":21641292},{"batl":[[0,1.35,324.14]],"ltp":1.34,"tv":28618.57,"id":16325787}]}]}
{"op":"mcm","clk":"997076598","pt":1580565154559,"mc":[{"id":"1.168133553","rc":[{"batb":[[0,12,13.9],[1,11.5,18.44],[2,11,28.51]],"batl":[[0,12.5,17.64]],"ltp":12.0,"tv":1496.03,"id":27227336},{"batb":[[0,5.6,28.04],[1,5.5,61.83],[2,5.4,40.68]],"ltp":5.7,"tv":4064.77,"id":21641292},{"batl":[[0,1.35,308.14]],"ltp":1.34,"tv":28618.57,"id":16325787}]}]}
{"op":"mcm","clk":"997076777","pt":1580565155494,"mc":[{"id":"1.168133553","rc":[{"batb":[[1,5.5,51.03]],"ltp":5.7,"tv":4064.77,"id":21641292}]}]}
{"op":"mcm","clk":"997076944","pt":1580565156264,"mc":[{"id":"1.168133553","rc":[{"batl":[[1,13,25.78]],"ltp":12.0,"tv":1496.03,"id":27227336},{"batb":[[0,5.6,20.52]],"ltp":5.7,"tv":4064.77,"id":21641292}]}]}
{"op":"mcm","clk":"997077140","pt":1580565157563,"mc":[{"id":"1.168133553","rc":[{"trd":[[12,156.83]],"batb":[[0,12,11.9]],"ltp":12.0,"tv":1500.03,"id":27227336},{"batl":[[0,1.35,307.94]],"ltp":1.34,"tv":28618.57,"id":16325787}],"tv":34183.38}]}
{"op":"mcm","clk":"997077640","pt":1580565160368,"mc":[{"id":"1.168133553","rc":[{"batb":[[2,11,33.51]],"ltp":12.0,"tv":1500.03,"id":27227336},{"batl":[[1,1.36,264.92]],"ltp":1.34,"tv":28618.57,"id":16325787}]}]}
{"op":"mcm","clk":"997078669","pt":1580565166435,"mc":[{"id":"1.168133553","rc":[{"batb":[[0,1.34,233.97]],"ltp":1.34,"tv":28618.57,"id":16325787}]}]}
{"op":"mcm","clk":"997079012","pt":1580565168521,"mc":[{"id":"1.168133553","rc":[{"batb":[[1,1.33,637.97]],"ltp":1.34,"tv":28618.57,"id":16325787}]}]}
{"op":"mcm","clk":"997079432","pt":1580565171237,"mc":[{"id":"1.168133553","rc":[{"batb":[[1,1.33,562.78]],"ltp":1.34,"tv":28618.57,"id":16325787}]}]}
{"op":"mcm","clk":"997079960","pt":1580565174534,"mc":[{"id":"1.168133553","rc":[{"batb":[[1,11.5,15.89],[2,11,37.2]],"ltp":12.0,"tv":1500.03,"id":27227336},{"batb":[[0,5.6,19.07],[1,5.5,42.1]],"ltp":5.7,"tv":4064.77,"id":21641292},{"trd":[[1.35,764.97]],"batl":[[0,1.35,8.01]],"ltp":1.35,"tv":29218.5,"id":16325787}],"tv":34783.31}]}
{"op":"mcm","clk":"997080049","pt":1580565175055,"mc":[{"id":"1.168133553","rc":[{"batb":[[1,11.5,9.55]],"ltp":12.0,"tv":1500.03,"id":27227336},{"batb":[[2,5.4,49.61]],"ltp":5.7,"tv":4064.77,"id":21641292},{"batl":[[1,1.36,319.6]],"ltp":1.35,"tv":29218.5,"id":16325787}]}]}
{"op":"mcm","clk":"997080582","pt":1580565178432,"mc":[{"id":"1.168133553","rc":[{"batl":[[0,1.35,8.21]],"ltp":1.35,"tv":29218.5,"id":16325787}]}]}
{"op":"mcm","clk":"997082717","pt":1580565192483,"mc":[{"id":"1.168133553","rc":[{"trd":[[12,161.43]],"batb":[[0,12,9.6]],"ltp":12.0,"tv":1504.63,"id":27227336},{"trd":[[5.6,283.69]],"batb":[[0,5.6,15.07]],"ltp":5.6,"tv":4072.77,"id":21641292}],"tv":34795.91}]}
{"op":"mcm","clk":"997084518","pt":1580565203516,"mc":[{"id":"1.168133553","rc":[{"batl":[[0,1.35,59.21]],"ltp":1.35,"tv":29218.5,"id":16325787}]}]}
{"op":"mcm","clk":"997084650","pt":1580565204530,"mc":[{"id":"1.168133553","rc":[{"trd":[[12.5,234.38]],"batb":[[1,11.5,16.24]],"batl":[[0,12.5,17.37]],"ltp":12.5,"tv":1505.17,"id":27227336},{"batb":[[1,5.5,51.03],[2,5.4,40.68]],"ltp":5.6,"tv":4072.77,"id":21641292},{"batl":[[1,1.36,358.34]],"ltp":1.35,"tv":29218.5,"id":16325787}],"tv":34796.45}]}
{"op":"mcm","clk":"997084984","pt":1580565206512,"mc":[{"id":"1.168133553","rc":[{"batl":[[0,1.35,59.01]],"ltp":1.35,"tv":29218.5,"id":16325787}]}]}
{"op":"mcm","clk":"997085777","pt":1580565211451,"mc":[{"id":"1.168133553","rc":[{"trd":[[5.6,287.69]],"batb":[[0,5.6,13.07]],"ltp":5.6,"tv":4076.77,"id":21641292}],"tv":34800.45}]}
{"op":"mcm","clk":"997086073","pt":1580565213537,"mc":[{"id":"1.168133553","rc":[{"trd":[[12,165.43]],"batb":[[0,12,7.6]],"ltp":12.0,"tv":1509.17,"id":27227336},{"batb":[[1,5.5,42.1],[2,5.4,49.61]],"batl":[[0,5.7,7.09],[1,5.8,18.11],[2,5.9,21.07]],"ltp":5.6,"tv":4076.77,"id":21641292},{"trd":[[1.35,882.99],[1.36,18.8]],"batb":[[0,1.35,12.76],[1,1.34,233.97],[2,1.33,562.78]],"batl":[[0,1.36,389.4],[1,1.37,107.11],[2,1.38,45.09]],"ltp":1.36,"tv":29338.5,"id":16325787}],"tv":34924.45}]}
{"op":"mcm","clk":"997086124","pt":1580565213828,"mc":[{"id":"1.168133553","rc":[{"batb":[[0,12,3.6]],"ltp":12.0,"tv":1509.17,"id":27227336},{"batl":[[1,1.37,124.45]],"ltp":1.36,"tv":29338.5,"id":16325787}]}]}
{"op":"mcm","clk":"997086444","pt":1580565216559,"mc":[{"id":"1.168133553","rc":[{"trd":[[11.5,169.03],[12,172.63]],"batb":[[0,11.5,5.19],[1,11,37.2],[2,10.5,33.72]],"ltp":11.5,"tv":1525.09,"id":27227336},{"batb":[[0,1.35,38.62],[1,1.34,258.55]],"batl":[[0,1.36,318.61],[1,1.37,126.13]],"ltp":1.36,"tv":29338.5,"id":16325787}],"tv":34940.37}]}
{"op":"mcm","clk":"997086667","pt":1580565217537,"mc":[{"id":"1.168133553","rc":[{"batb":[[0,11.5,7.19],[1,11,41.11]],"batl":[[0,12.5,24.08]],"ltp":11.5,"tv":1525.09,"id":27227336},{"batb":[[0,1.35,84.62],[1,1.34,303.27]],"ltp":1.36,"tv":29338.5,"id":16325787}]}]}
{"op":"mcm","clk":"997086828","pt":1580565218555,"mc":[{"id":"1.168133553","rc":[{"batb":[[1,11,30.02]],"ltp":11.5,"tv":1525.09,"id":27227336},{"batl":[[0,1.36,299.48]],"ltp":1.36,"tv":29338.5,"id":16325787}]}]}
{"op":"mcm","clk":"997086956","pt":1580565219356,"mc":[{"id":"1.168133553","rc":[{"batl":[[0,1.36,249.49],[1,1.37,161.3]],"ltp":1.36,"tv":29338.5,"id":16325787}]}]}
{"op":"mcm","clk":"997087139","pt":1580565220548,"mc":[{"id":"1.168133553","rc":[{"batl":[[0,1.36,266.77]],"ltp":1.36,"tv":29338.5,"id":16325787}]}]}
{"op":"mcm","clk":"997087281","pt":1580565221426,"mc":[{"id":"1.168133553","rc":[{"batb":[[0,5.6,5]],"ltp":5.6,"tv":4076.77,"id":21641292},{"batb":[[0,1.35,148.62]],"batl":[[0,1.36,249.49]],"ltp":1.36,"tv":29338.5,"id":16325787}]}]}
{"op":"mcm","clk":"997087451","pt":1580565222445,"mc":[{"id":"1.168133553","rc":[{"batl":[[0,12.5,17.37]],"ltp":11.5,"tv":1525.09,"id":27227336}]}]}
{"op":"mcm","clk":"997087636","pt":1580565223557,"mc":[{"id":"1.168133553","rc":[{"batl":[[0,1.36,234.49]],"ltp":1.36,"tv":29338.5,"id":16325787}]}]}
{"op":"mcm","clk":"997087743","pt":1580565224345,"mc":[{"id":"1.168133553","rc":[{"batb":[[0,1.35,149.61]],"ltp":1.36,"tv":29338.5,"id":16325787}]}]}
{"op":"mcm","clk":"997088056","pt":1580565226455,"mc":[{"id":"1.168133553","rc":[{"batb":[[0,1.35,164.61]],"ltp":1.36,"tv":29338.5,"id":16325787}]}]}
{"op":"mcm","clk":"997088355","pt":1580565228550,"mc":[{"id":"1.168133553","rc":[{"batl":[[1,1.37,108.79]],"ltp":1.36,"tv":29338.5,"id":16325787}]}]}
{"op":"mcm","clk":"997088837","pt":1580565231551,"mc":[{"id":"1.168133553","rc":[{"batb":[[0,1.35,179.61],[1,1.34,288.27]],"ltp":1.36,"tv":29338.5,"id":16325787}]}]}
{"op":"mcm","clk":"997089020","pt":1580565232547,"mc":[{"id":"1.168133553","rc":[{"trd":[[5.6,297.69]],"batb":[[0,5.5,42.1],[1,5.4,49.61],[2,5.3,28.73]],"batl":[[0,5.6,5],[1,5.7,7.09],[2,5.8,18.11]],"ltp":5.6,"tv":4086.77,"id":21641292}],"tv":34950.37}]}
{"op":"mcm","clk":"997089184","pt":1580565233562,"mc":[{"id":"1.168133553","rc":[{"trd":[[5.6,307.69]],"batb":[[0,5.6,3],[1,5.5,42.1],[2,5.4,49.61]],"batl":[[0,5.7,18.38],[1,5.8,25.65],[2,5.9,21.07]],"ltp":5.6,"tv":4096.77,"id":21641292},{"batl":[[0,1.36,237.49],[2,1.38,60.09]],"ltp":1.36,"tv":29338.5,"id":16325787}],"tv":34960.37}]}
{"op":"mcm","clk":"997089842","pt":1580565237446,"mc":[{"id":"1.168133553","rc":[{"batl":[[0,1.36,237.69]],"ltp":1.36,"tv":29338.5,"id":16325787}]}]}
{"op":"mcm","clk":"997090527","pt":1580565241537,"mc":[{"id":"1.168133553","rc":[{"trd":[[5.6,307.81]],"batb":[[0,5.6,2.94]],"ltp":5.6,"tv":4096.89,"id":21641292}],"tv":34960.49}]}
{"op":"mcm","clk":"997090718","pt":1580565242566,"mc":[{"id":"1.168133553","rc":[{"trd":[[5.6,308.27]],"batb":[[0,5.6,2.71]],"ltp":5.6,"tv":4097.35,"id":21641292}],"tv":34960.95}]}
{"op":"mcm","clk":"997091212","pt":1580565245568,"mc":[{"id":"1.168133553","rc":[{"batl":[[0,1.36,287.69]],"ltp":1.36,"tv":29338.5,"id":16325787}]}]}
{"op":"mcm","clk":"997091341","pt":1580565246452,"mc":[{"id":"1.168133553","rc":[{"trd":[[5.5,303.43],[5.6,313.69]],"batb":[[0,5.5,32.58],[1,5.4,49.61],[2,5.3,28.73]],"ltp":5.5,"tv":4121.8,"id":21641292}],"tv":34985.4}]}
{"op":"mcm","clk":"997091455","pt":1580565247255,"mc":[{"id":"1.168133553","rc":[{"batb":[[0,5.5,26.05],[1,5.4,58.73]],"batl":[[0,5.7,20.38]],"ltp":5.5,"tv":4121.8,"id":21641292}]}]}
{"op":"mcm","clk":"997091640","pt":1580565248363,"mc":[{"id":"1.168133553","rc":[{"batb":[[1,5.4,49.61]],"batl":[[1,5.8,37.83]],"ltp":5.5,"tv":4121.8,"id":21641292}]}]}
{"op":"mcm","clk":"997091846","pt":1580565249555,"mc":[{"id":"1.168133553","rc":[{"batl":[[0,5.7,18.38]],"ltp":5.5,"tv":4121.8,"id":21641292}]}]}
{"op":"mcm","clk":"997092182","pt":1580565251556,"mc":[{"id":"1.168133553","rc":[{"batl":[[0,5.6,2],[1,5.7,18.38],[2,5.8,37.83]],"ltp":5.5,"tv":4121.8,"id":21641292},{"batl":[[0,1.36,272.69]],"ltp":1.36,"tv":29338.5,"id":16325787}]}]}
{"op":"mcm","clk":"997092226","pt":1580565251902,"mc":[{"id":"1.168133553","rc":[{"trd":[[5.5,311.43]],"batb":[[0,5.5,22.05]],"batl":[[2,5.8,45.78]],"ltp":5.5,"tv":4129.8,"id":21641292}],"tv":34993.4}]}
{"op":"mcm","clk":"997092795","pt":1580565255480,"mc":[{"id":"1.168133553","rc":[{"batl":[[0,5.7,18.38],[1,5.8,45.78],[2,5.9,21.07]],"ltp":5.5,"tv":4129.8,"id":21641292}]}]}
{"op":"mcm","clk":"997092958","pt":1580565256396,"mc":[{"id":"1.168133553","rc":[{"trd":[[5.5,315.43]],"batb":[[0,5.5,20.05]],"batl":[[1,5.8,37.83]],"ltp":5.5,"tv":4133.8,"id":21641292}],"tv":34997.4}]}
{"op":"mcm","clk":"997093148","pt":1580565257489,"mc":[{"id":"1.168133553","rc":[{"trd":[[12.5,254.37]],"batl":[[0,12.5,5.91]],"ltp":12.5,"tv":1545.08,"id":27227336},{"batb":[[1,5.4,40.68],[2,5.3,37.66]],"batl":[[0,5.6,7.25],[1,5.7,18.38],[2,5.8,37.83]],"ltp":5.5,"tv":4133.8,"id":21641292},{"batb":[[0,1.35,173.31]],"ltp":1.36,"tv":29338.5,"id":16325787}],"tv":35017.39}]}
{"op":"mcm","clk":"997093311","pt":1580565258473,"mc":[{"id":"1.168133553","rc":[{"batb":[[0,11.5,14.47]],"batl":[[0,12,7.67],[1,12.5,5.91],[2,13,25.78]],"ltp":12.5,"tv":1545.08,"id":27227336},{"trd":[[5.6,343.58]],"batb":[[0,5.5,27.3]],"batl":[[0,5.6,2.31]],"ltp":5.6,"tv":4163.69,"id":21641292},{"trd":[[1.36,23.14]],"batb":[[0,1.35,235.33]],"batl":[[0,1.36,270.52]],"ltp":1.36,"tv":29342.84,"id":16325787}],"tv":35051.62}]}
{"op":"mcm","clk":"997093489","pt":1580565259500,"mc":[{"id":"1.168133553","rc":[{"trd":[[11.5,173.03]],"batb":[[0,11.5,12.47]],"ltp":11.5,"tv":1549.08,"id":27227336},{"batb":[[1,1.34,245.23]],"ltp":1.36,"tv":29342.84,"id":16325787}],"tv":35055.62}]}
{"op":"mcm","clk":"997094455","pt":1580565265543,"mc":[{"id":"1.168133553","rc":[{"trd":[[11.5,189.03]],"batb":[[0,11.5,16.83]],"ltp":11.5,"tv":1565.08,"id":27227336},{"batl":[[0,1.36,270.32]],"ltp":1.36,"tv":29342.84,"id":16325787}],"tv":35071.62}]}
{"op":"mcm","clk":"997094629","pt":1580565266514,"mc":[{"id":"1.168133553","rc":[{"batb":[[0,11.5,20.92]],"batl":[[0,12,9.67]],"ltp":11.5,"tv":1565.08,"id":27227336},{"trd":[[5.6,360.38]],"batl":[[0,5.6,1.91],[1,5.7,29.31]],"ltp":5.6,"tv":4180.49,"id":21641292},{"batb":[[0,1.35,270.18]],"batl":[[0,1.36,284.32]],"ltp":1.36,"tv":29342.84,"id":16325787}],"tv":35088.42}]}
{"op":"mcm","clk":"997094757","pt":1580565267569,"mc":[{"id":"1.168133553","rc":[{"batl":[[0,12,7.67]],"ltp":11.5,"tv":1565.08,"id":27227336},{"batl":[[0,5.7,29.31],[1,5.8,37.83],[2,5.9,21.07]],"ltp":5.6,"tv":4180.49,"id":21641292},{"batl":[[0,1.36,270.32]],"ltp":1.36,"tv":29342.84,"id":16325787}]}]}
{"op":"mcm","clk":"997094902","pt":1580565268438,"mc":[{"id":"1.168133553","rc":[{"batl":[[0,1.36,270.52]],"ltp":1.36,"tv":29342.84,"id":16325787}]}]}
{"op":"mcm","clk":"997095269","pt":1580565271042,"mc":[{"id":"1.168133553","rc":[{"batb":[[1,5.4,49.61],[2,5.3,28.73]],"ltp":5.6,"tv":4180.49,"id":21641292}]}]}
{"op":"mcm","clk":"997096627","pt":1580565279539,"mc":[{"id":"1.168133553","rc":[{"trd":[[1.35,956.71]],"batb":[[0,1.35,233.31]],"ltp":1.35,"tv":29416.56,"id":16325787}],"tv":35162.15}]}
{"op":"mcm","clk":"997096884","pt":1580565281069,"mc":[{"id":"1.168133553","rc":[{"trd":[[5.5,331.43]],"batb":[[0,5.5,23.3]],"ltp":5.5,"tv":4196.49,"id":21641292}],"tv":35178.15}]}
{"op":"mcm","clk":"997097527","pt":1580565285395,"mc":[{"id":"1.168133553","rc":[{"batl":[[0,5.6,3],[1,5.7,29.31],[2,5.8,37.83]],"ltp":5.5,"tv":4196.49,"id":21641292}]}]}
{"op":"mcm","clk":"997097705","pt":1580565286574,"mc":[{"id":"1.168133553","rc":[{"batb":[[0,11.5,27.41],[1,11,53.12]],"ltp":11.5,"tv":1565.08,"id":27227336}]}]}
{"op":"mcm","clk":"997097873","pt":1580565287558,"mc":[{"id":"1.168133553","rc":[{"trd":[[12,188.63]],"batl":[[0,12.5,5.91],[1,13,25.78],[2,13.5,14.54]],"ltp":12.0,"tv":1581.08,"id":27227336}],"tv":35194.15}]}
{"op":"mcm","clk":"997098009","pt":1580565288525,"mc":[{"id":"1.168133553","rc":[{"batb":[[0,12,3.26],[1,11.5,27.41],[2,11,53.12]],"batl":[[1,13,35.14]],"ltp":12.0,"tv":1581.08,"id":27227336},{"batb":[[0,5.5,7.25],[1,5.4,40.68],[2,5.3,41.66]],"batl":[[0,5.6,13.26]],"ltp":5.5,"tv":4196.49,"id":21641292},{"batl":[[0,1.36,284.52]],"ltp":1.35,"tv":29416.56,"id":16325787}]}]}
{"op":"mcm","clk":"997098155","pt":1580565289505,"mc":[{"id":"1.168133553","rc":[{"batl":[[1,13,25.78]],"ltp":12.0,"tv":1581.08,"id":27227336},{"batl":[[1,5.7,36.27]],"ltp":5.5,"tv":4196.49,"id":21641292}]}]}
{"op":"mcm","clk":"997098734","pt":1580565293516,"mc":[{"id":"1.168133553","rc":[{"batl":[[1,1.37,110.47]],"ltp":1.35,"tv":29416.56,"id":16325787}]}]}
{"op":"mcm","clk":"997098854","pt":1580565294321,"mc":[{"id":"1.168133553","rc":[{"batb":[[1,1.34,246.91]],"ltp":1.35,"tv":29416.56,"id":16325787}]}]}
{"op":"mcm","clk":"997098954","pt":1580565294923,"mc":[{"id":"1.168133553","rc":[{"batb":[[0,1.35,283.31]],"batl":[[0,1.36,334.52]],"ltp":1.35,"tv":29416.56,"id":16325787}]}]}
{"op":"mcm","clk":"997099172","pt":1580565296431,"mc":[{"id":"1.168133553","rc":[{"batl":[[0,1.36,334.32]],"ltp":1.35,"tv":29416.56,"id":16325787}]}]}
{"op":"mcm","clk":"997099503","pt":1580565298535,"mc":[{"id":"1.168133553","rc":[{"trd":[[11.5,196.81],[12,195.15]],"batb":[[0,11.5,23.52],[1,11,53.12],[2,10.5,33.72]],"ltp":11.5,"tv":1595.38,"id":27227336},{"trd":[[1.36,39.66]],"batl":[[0,1.36,326.06]],"ltp":1.36,"tv":29433.08,"id":16325787}],"tv":35224.97}]}
{"op":"mcm","clk":"997099639","pt":1580565299416,"mc":[{"id":"1.168133553","rc":[{"batb":[[0,12,3],[1,11.5,23.52],[2,11,53.12]],"ltp":11.5,"tv":1595.38,"id":27227336}]}]}
{"op":"mcm","clk":"997099983","pt":1580565301535,"mc":[{"id":"1.168133553","rc":[{"batl":[[2,5.8,38.5]],"ltp":5.5,"tv":4196.49,"id":21641292}]}]}
{"op":"mcm","clk":"997100289","pt":1580565303546,"mc":[{"id":"1.168133553","rc":[{"batb":[[0,11.5,23.52],[1,11,53.12],[2,10.5,33.72]],"batl":[[0,12.5,13.79]],"ltp":11.5,"tv":1595.38,"id":27227336},{"batb":[[0,5.4,40.68],[1,5.3,41.66],[2,5.2,62.51]],"batl":[[0,5.6,31.8]],"ltp":5.5,"tv":4196.49,"id":21641292},{"trd":[[1.36,715.78]],"batb":[[0,1.36,161.94],[1,1.35,283.31],[2,1.34,246.91]],"batl":[[0,1.37,110.47],[1,1.38,60.09],[2,1.39,26.23]],"ltp":1.36,"tv":30109.2,"id":16325787}],"tv":35901.09}]}
{"op":"mcm","clk":"997100435","pt":1580565304558,"mc":[{"id":"1.168133553","rc":[{"batb":[[1,11,30.02]],"batl":[[0,12,3.02],[1,12.5,13.79],[2,13,25.78]],"ltp":11.5,"tv":1595.38,"id":27227336},{"batb":[[0,5.4,21.53],[1,5.3,32.73],[2,5.2,20.43]],"batl":[[0,5.5,21.15],[1,5.6,31.8],[2,5.7,36.27]],"ltp":5.5,"tv":4196.49,"id":21641292},{"trd":[[1.37,28]],"batb":[[0,1.36,203.94],[1,1.35,389.95]],"batl":[[0,1.37,54.09],[2,1.39,38.23]],"ltp":1.37,"tv":30125.2,"id":16325787}],"tv":35917.09}]}
{"op":"mcm","clk":"997100586","pt":1580565305512,"mc":[{"id":"1.168133553","rc":[{"batb":[[0,11.5,17.03]],"ltp":11.5,"tv":1595.38,"id":27227336},{"batl":[[0,5.5,31.15]],"ltp":5.5,"tv":4196.49,"id":21641292},{"trd":[[1.37,136.18]],"batb":[[0,1.37,43.72],[1,1.36,203.94],[2,1.35,389.95]],"batl":[[0,1.38,60.09],[1,1.39,38.23],[2,1.4,79.05]],"ltp":1.37,"tv":30233.38,"id":16325787}],"tv":36025.27}]}
{"op":"mcm","clk":"997100751","pt":1580565306537,"mc":[{"id":"1.168133553","rc":[{"batb":[[0,11.5,7.67],[1,11,38.24]],"batl":[[0,12,7.24],[1,12.5,20.63]],"ltp":11.5,"tv":1595.38,"id":27227336},{"trd":[[5.4,470.93]],"batb":[[0,5.4,19.62]],"batl":[[0,5.5,42.48]],"ltp":5.4,"tv":4200.31,"id":21641292},{"batb":[[0,1.37,49.72]],"batl":[[0,1.38,115.42],[1,1.39,124.52]],"ltp":1.37,"tv":30233.38,"id":16325787}],"tv":36029.09}]}
{"op":"mcm","clk":"997100879","pt":1580565307344,"mc":[{"id":"1.168133553","rc":[{"trd":[[5.4,482.93]],"batb":[[0,5.4,13.62]],"ltp":5.4,"tv":4212.31,"id":21641292},{"batb":[[2,1.35,344.3]],"ltp":1.37,"tv":30233.38,"id":16325787}],"tv":36041.09}]}
{"op":"mcm","clk":"997101025","pt":1580565308314,"mc":[{"id":"1.168133553","rc":[{"batl":[[2,5.7,48.64]],"ltp":5.4,"tv":4212.31,"id":21641292}]}]}
{"op":"mcm","clk":"997101195","pt":1580565309463,"mc":[{"id":"1.168133553","rc":[{"batl":[[1,12.5,13.79]],"ltp":11.5,"tv":1595.38,"id":27227336},{"trd":[[1.36,716.34],[1.37,235.62]],"batb":[[0,1.36,203.66],[1,1.35,320.17],[2,1.34,246.91]],"batl":[[1,1.39,167.61]],"ltp":1.36,"tv":30333.38,"id":16325787}],"tv":36141.09}]}
{"op":"mcm","clk":"997101353","pt":1580565310444,"mc":[{"id":"1.168133553","rc":[{"batb":[[1,1.35,309.45]],"ltp":1.36,"tv":30333.38,"id":16325787}]}]}
{"op":"mcm","clk":"997101669","pt":1580565312131,"mc":[{"id":"1.168133553","rc":[{"batl":[[0,12,12.24]],"ltp":11.5,"tv":1595.38,"id":27227336},{"batb":[[0,1.37,34.35],[1,1.36,203.66],[2,1.35,309.45]],"ltp":1.36,"tv":30333.38,"id":16325787}]}]}
{"op":"mcm","clk":"997101839","pt":1580565313244,"mc":[{"id":"1.168133553","rc":[{"batl":[[1,12.5,20.5]],"ltp":11.5,"tv":1595.38,"id":27227336}]}]}
{"op":"mcm","clk":"997102058","pt":1580565314543,"mc":[{"id":"1.168133553","rc":[{"batl":[[0,5.5,31.15]],"ltp":5.4,"tv":4212.31,"id":21641292},{"trd":[[1.37,304.31]],"batb":[[0,1.36,264.43],[1,1.35,309.45],[2,1.34,246.91]],"batl":[[0,1.37,265.65],[1,1.38,115.42],[2,1.39,167.61]],"ltp":1.37,"tv":30402.08,"id":16325787}],"tv":36209.78}]}
{"op":"mcm","clk":"997102228","pt":1580565315546,"mc":[{"id":"1.168133553","rc":[{"batb":[[2,10.5,9.39]],"ltp":11.5,"tv":1595.38,"id":27227336},{"batb":[[1,1.35,312.59]],"batl":[[2,1.39,134.63]],"ltp":1.37,"tv":30402.08,"id":16325787}]}]}
{"op":"mcm","clk":"997102319","pt":1580565316139,"mc":[{"id":"1.168133553","rc":[{"batb":[[1,1.35,309.45]],"ltp":1.37,"tv":30402.08,"id":16325787}]}]}
{"op":"mcm","clk":"997102790","pt":1580565319035,"mc":[{"id":"1.168133553","rc":[{"batb":[[0,5.4,33.62]],"ltp":5.4,"tv":4212.31,"id":21641292}]}]}
{"op":"mcm","clk":"997103157","pt":1580565321532,"mc":[{"id":"1.168133553","rc":[{"batl":[[1,5.6,38.86]],"ltp":5.4,"tv":4212.31,"id":21641292}]}]}
{"op":"mcm","clk":"997103258","pt":1580565322017,"mc":[{"id":"1.168133553","rc":[{"batb":[[2,5.2,40.43]],"ltp":5.4,"tv":4212.31,"id":21641292}]}]}
{"op":"mcm","clk":"997103859","pt":1580565325539,"mc":[{"id":"1.168133553","rc":[{"trd":[[1.37,308.31]],"batl":[[0,1.37,263.65]],"ltp":1.37,"tv":30406.08,"id":16325787}],"tv":36213.78}]}
{"op":"mcm","clk":"997104008","pt":1580565326381,"mc":[{"id":"1.168133553","rc":[{"batl":[[0,1.37,263.85]],"ltp":1.37,"tv":30406.08,"id":16325787}]}]}
{"op":"mcm","clk":"997104188","pt":1580565327424,"mc":[{"id":"1.168133553","rc":[{"trd":[[1.36,725.02]],"batb":[[0,1.36,260.09]],"batl":[[1,1.38,117.42]],"ltp":1.36,"tv":30414.76,"id":16325787}],"tv":36222.47}]}
{"op":"mcm","clk":"997104999","pt":1580565332225,"mc":[{"id":"1.168133553","rc":[{"trd":[[11.5,200.81]],"batb":[[0,11.5,5.67]],"ltp":11.5,"tv":1599.38,"id":27227336},{"trd":[[5.4,486.93]],"batb":[[0,5.4,31.62]],"ltp":5.4,"tv":4216.31,"id":21641292},{"trd":[[1.37,312.31]],"batl":[[0,1.37,261.85]],"ltp":1.37,"tv":30418.76,"id":16325787}],"tv":36234.47}]}
{"op":"mcm","clk":"997105203","pt":1580565333565,"mc":[{"id":"1.168133553","rc":[{"trd":[[1.37,318.31]],"batl":[[0,1.37,258.85]],"ltp":1.37,"tv":30424.76,"id":16325787}],"tv":36240.47}]}
{"op":"mcm","clk":"997105840","pt":1580565337469,"mc":[{"id":"1.168133553","rc":[{"batb":[[1,1.35,405.25]],"ltp":1.37,"tv":30424.76,"id":16325787}]}]}
{"op":"mcm","clk":"997106202","pt":1580565339571,"mc":[{"id":"1.168133553","rc":[{"trd":[[1.36,741.02]],"batb":[[0,1.36,252.09]],"batl":[[0,1.37,668.85],[1,1.38,112.42]],"ltp":1.36,"tv":30440.76,"id":16325787}],"tv":36256.47}]}
{"op":"mcm","clk":"997106352","pt":1580565340475,"mc":[{"id":"1.168133553","rc":[{"trd":[[1.36,749.02]],"batb":[[0,1.36,248.09]],"ltp":1.36,"tv":30448.76,"id":16325787}],"tv":36264.47}]}
{"op":"mcm","clk":"997106569","pt":1580565341853,"mc":[{"id":"1.168133553","rc":[{"batl":[[0,12,19.18]],"ltp":11.5,"tv":1599.38,"id":27227336},{"batb":[[0,1.36,253.36]],"ltp":1.36,"tv":30448.76,"id":16325787}]}]}
{"op":"mcm","clk":"997106831","pt":1580565343485,"mc":[{"id":"1.168133553","rc":[{"trd":[[11.5,212.15]],"batb":[[0,11,38.24],[1,10.5,9.39],[2,10,65.54]],"batl":[[0,11.5,8.33],[1,12,19.18],[2,12.5,22.88]],"ltp":11.5,"tv":1610.72,"id":27227336},{"batb":[[0,5.4,34.62],[1,5.3,41.66],[2,5.2,31.49]],"batl":[[0,5.5,21.15]],"ltp":5.4,"tv":4216.31,"id":21641292},{"trd":[[1.36,753.02],[1.37,342.27]],"batb":[[0,1.36,251.36]],"batl":[[0,1.37,646.87]],"ltp":1.36,"tv":30476.72,"id":16325787}],"tv":36303.77}]}
{"op":"mcm","clk":"997107002","pt":1580565344458,"mc":[{"id":"1.168133553","rc":[{"trd":[[11.5,228.82]],"batb":[[0,11.5,3.36],[1,11,40.82],[2,10.5,13.08]],"batl":[[0,12,25.71],[1,12.5,22.88],[2,13,25.78]],"ltp":11.5,"tv":1627.39,"id":27227336},{"trd":[[5.5,358.73]],"batb":[[0,5.5,10.42],[1,5.4,34.62],[2,5.3,41.66]],"batl":[[0,5.6,31.8],[1,5.7,48.64],[2,5.8,38.5]],"ltp":5.5,"tv":4243.62,"id":21641292},{"trd":[[1.37,402.27]],"batb":[[0,1.36,348.7]],"batl":[[0,1.37,616.87]],"ltp":1.37,"tv":30536.72,"id":16325787}],"tv":36407.74}]}
{"op":"mcm","clk":"997107086","pt":1580565344952,"mc":[{"id":"1.168133553","rc":[{"batb":[[0,11.5,5.36]],"batl":[[0,12,35.9]],"ltp":11.5,"tv":1627.39,"id":27227336},{"trd":[[5.5,366.73]],"batb":[[0,5.5,6.42]],"ltp":5.5,"tv":4251.62,"id":21641292},{"batl":[[0,1.37,626.87]],"ltp":1.37,"tv":30536.72,"id":16325787}],"tv":36415.74}]}
{"op":"mcm","clk":"997107335","pt":1580565346388,"mc":[{"id":"1.168133553","rc":[{"batb":[[2,1.34,263.72]],"ltp":1.37,"tv":30536.72,"id":16325787}]}]}
{"op":"mcm","clk":"997108280","pt":1580565352453,"mc":[{"id":"1.168133553","rc":[{"batl":[[1,12.5,28.14]],"ltp":11.5,"tv":1627.39,"id":27227336}]}]}
{"op":"mcm","clk":"997108597","pt":1580565354462,"mc":[{"id":"1.168133553","rc":[{"batl":[[0,1.37,626.67]],"ltp":1.37,"tv":30536.72,"id":16325787}]}]}
{"op":"mcm","clk":"997108769","pt":1580565355573,"mc":[{"id":"1.168133553","rc":[{"trd":[[11.5,229.04]],"batb":[[0,11.5,5.25]],"ltp":11.5,"tv":1627.61,"id":27227336},{"trd":[[5.5,367.17]],"batb":[[0,5.5,6.2]],"ltp":5.5,"tv":4252.06,"id":21641292}],"tv":36416.4}]}
{"op":"mcm","clk":"997109234","pt":1580565358564,"mc":[{"id":"1.168133553","rc":[{"batb":[[1,11,44.51],[2,10.5,9.39]],"ltp":11.5,"tv":1627.61,"id":27227336}]}]}
{"op":"mcm","clk":"997109311","pt":1580565358998,"mc":[{"id":"1.168133553","rc":[{"batl":[[2,1.39,138.63]],"ltp":1.37,"tv":30536.72,"id":16325787}]}]}
{"op":"mcm","clk":"997109879","pt":1580565362574,"mc":[{"id":"1.168133553","rc":[{"trd":[[1.37,424.76]],"batl":[[0,1.37,615.43]],"ltp":1.37,"tv":30559.2,"id":16325787}],"tv":36438.88}]}
{"op":"mcm","clk":"997110008","pt":1580565363382,"mc":[{"id":"1.168133553","rc":[{"trd":[[5.6,374.38]],"batl":[[0,5.6,24.8]],"ltp":5.6,"tv":4266.06,"id":21641292},{"batl":[[1,1.38,143.42]],"ltp":1.37,"tv":30559.2,"id":16325787}],"tv":36452.88}]}
{"op":"mcm","clk":"997110124","pt":1580565364188,"mc":[{"id":"1.168133553","rc":[{"batl":[[0,5.6,27.31]],"ltp":5.6,"tv":4266.06,"id":21641292}]}]}
{"op":"mcm","clk":"997110324","pt":1580565365378,"mc":[{"id":"1.168133553","rc":[{"trd":[[12,199.15]],"batl":[[0,12,33.9]],"ltp":12.0,"tv":1631.61,"id":27227336},{"batl":[[0,1.37,675.43]],"ltp":1.37,"tv":30559.2,"id":16325787}],"tv":36456.88}]}
{"op":"mcm","clk":"997110513","pt":1580565366509,"mc":[{"id":"1.168133553","rc":[{"batl":[[0,12,23.71]],"ltp":12.0,"tv":1631.61,"id":27227336},{"trd":[[1.36,1209.56]],"batb":[[0,1.36,120.42]],"ltp":1.36,"tv":31015.74,"id":16325787}],"tv":36913.42}]}
{"op":"mcm","clk":"997110654","pt":1580565367390,"mc":[{"id":"1.168133553","rc":[{"batl":[[0,12,17.18],[1,12.5,22.88]],"ltp":12.0,"tv":1631.61,"id":27227336},{"batb":[[0,5.5,13.73]],"batl":[[0,5.6,31.05]],"ltp":5.6,"tv":4266.06,"id":21641292},{"batb":[[0,1.36,160.42]],"ltp":1.36,"tv":31015.74,"id":16325787}]}]}
{"op":"mcm","clk":"997110787","pt":1580565368424,"mc":[{"id":"1.168133553","rc":[{"batl":[[2,13,40.78]],"ltp":12.0,"tv":1631.61,"id":27227336}]}]}
{"op":"mcm","clk":"997111122","pt":1580565370573,"mc":[{"id":"1.168133553","rc":[{"batb":[[0,11.5,14.59]],"ltp":12.0,"tv":1631.61,"id":27227336},{"batl":[[0,5.6,19.93]],"ltp":5.6,"tv":4266.06,"id":21641292},{"trd":[[1.36,1596.4]],"batb":[[0,1.35,481.58],[1,1.34,263.72],[2,1.33,1213.74]],"batl":[[0,1.36,94.58],[1,1.37,675.43],[2,1.38,143.42]],"ltp":1.36,"tv":31402.58,"id":16325787}],"tv":37300.26}]}
{"op":"mcm","clk":"997111247","pt":1580565371380,"mc":[{"id":"1.168133553","rc":[{"batb":[[2,10.5,33.72]],"ltp":12.0,"tv":1631.61,"id":27227336},{"trd":[[5.5,381.17]],"batb":[[0,5.5,6.73],[1,5.4,50.97],[2,5.3,32.73]],"ltp":5.5,"tv":4280.06,"id":21641292},{"batb":[[0,1.35,442.7],[2,1.33,513.58]],"batl":[[1,1.37,700.21]],"ltp":1.36,"tv":31402.58,"id":16325787}],"tv":37314.26}]}
{"op":"mcm","clk":"997111372","pt":1580565372194,"mc":[{"id":"1.168133553","rc":[{"batb":[[0,11.5,23.43]],"ltp":12.0,"tv":1631.61,"id":27227336},{"batb":[[0,5.5,11.73],[1,5.4,52.97]],"ltp":5.5,"tv":4280.06,"id":21641292},{"batb":[[0,1.35,433.24],[1,1.34,312.62],[2,1.33,502.58]],"batl":[[1,1.37,705.21],[2,1.38,148.42]],"ltp":1.36,"tv":31402.58,"id":16325787}]}]}
{"op":"mcm","clk":"997112370","pt":1580565378413,"mc":[{"id":"1.168133553","rc":[{"batl":[[0,12,12.96]],"ltp":12.0,"tv":1631.61,"id":27227336},{"batl":[[0,5.6,12.51]],"ltp":5.5,"tv":4280.06,"id":21641292},{"trd":[[1.35,1005.45]],"batb":[[0,1.35,408.87]],"ltp":1.35,"tv":31451.32,"id":16325787}],"tv":37362.99}]}
{"op":"mcm","clk":"997112518","pt":1580565379408,"mc":[{"id":"1.168133553","rc":[{"batb":[[0,11.5,16.59],[2,10.5,35.72]],"batl":[[0,12,11.94]],"ltp":12.0,"tv":1631.61,"id":27227336},{"batl":[[1,5.7,44.35],[2,5.8,34.32]],"ltp":5.5,"tv":4280.06,"id":21641292},{"trd":[[1.35,1149.45]],"batb":[[0,1.35,358.24],[1,1.34,302.06]],"ltp":1.35,"tv":31595.32,"id":16325787}],"tv":37506.99}]}
{"op":"mcm","clk":"997112687","pt":1580565380545,"mc":[{"id":"1.168133553","rc":[{"trd":[[1.35,1176.33]],"batb":[[0,1.35,321.71]],"batl":[[0,1.36,158.11]],"ltp":1.35,"tv":31622.2,"id":16325787}],"tv":37533.88}]}
{"op":"mcm","clk":"997112858","pt":1580565381531,"mc":[{"id":"1.168133553","rc":[{"batb":[[0,1.35,273.8],[1,1.34,321.37]],"ltp":1.35,"tv":31622.2,"id":16325787}]}]}
{"op":"mcm","clk":"997113284","pt":1580565384431,"mc":[{"id":"1.168133553","rc":[{"trd":[[1.35,1180.53]],"batb":[[0,1.35,271.7]],"batl":[[0,1.36,158.31]],"ltp":1.35,"tv":31626.4,"id":16325787}],"tv":37538.08}]}
{"op":"mcm","clk":"997113449","pt":1580565385530,"mc":[{"id":"1.168133553","rc":[{"batl":[[0,1.36,189.31]],"ltp":1.35,"tv":31626.4,"id":16325787}]}]}
{"op":"mcm","clk":"997113630","pt":1580565386517,"mc":[{"id":"1.168133553","rc":[{"trd":[[5.6,384.38]],"batb":[[0,5.5,23.98]],"batl":[[0,5.6,2.51]],"ltp":5.6,"tv":4290.06,"id":21641292},{"trd":[[1.36,1638.4]],"batl":[[0,1.36,168.31]],"ltp":1.36,"tv":31668.4,"id":16325787}],"tv":37590.08}]}
{"op":"mcm","clk":"997113779","pt":1580565387548,"mc":[{"id":"1.168133553","rc":[{"trd":[[5.5,385.16]],"batb":[[0,5.5,21.99]],"batl":[[1,5.7,37.39]],"ltp":5.5,"tv":4294.05,"id":21641292}],"tv":37594.07}]}
{"op":"mcm","clk":"997113911","pt":1580565388533,"mc":[{"id":"1.168133553","rc":[{"trd":[[11.5,233.04],[12,200.32]],"batb":[[0,11.5,14.59]],"batl":[[0,12,10.77]],"ltp":11.5,"tv":1636.78,"id":27227336},{"trd":[[5.6,394.89]],"batb":[[0,5.5,29.61]],"batl":[[0,5.7,26.9],[1,5.8,34.32],[2,5.9,7.9]],"ltp":5.6,"tv":4304.56,"id":21641292},{"trd":[[1.34,7607.96],[1.35,1734.34]],"batb":[[0,1.35,113.77],[1,1.34,303.5]],"batl":[[1,1.37,711.21],[2,1.38,154.42]],"ltp":1.34,"tv":32257.98,"id":16325787}],"tv":38199.32}]}
{"op":"mcm","clk":"997114039","pt":1580565389443,"mc":[{"id":"1.168133553","rc":[{"trd":[[11.5,246.96]],"batb":[[0,11.5,7.63]],"batl":[[0,12,3.83]],"ltp":11.5,"tv":1650.7,"id":27227336},{"batb":[[0,5.6,17.1],[1,5.5,29.61],[2,5.4,52.97]],"ltp":5.6,"tv":4304.56,"id":21641292},{"trd":[[1.36,1652.62]],"batb":[[0,1.35,135.28],[1,1.34,256.28]],"batl":[[0,1.36,182.2]],"ltp":1.36,"tv":32272.2,"id":16325787}],"tv":38227.46}]}
{"op":"mcm","clk":"997114187","pt":1580565390468,"mc":[{"id":"1.168133553","rc":[{"batb":[[0,5.6,24.66]],"ltp":5.6,"tv":4304.56,"id":21641292},{"batb":[[0,1.35,156.8]],"ltp":1.36,"tv":32272.2,"id":16325787}]}]}
{"op":"mcm","clk":"997114354","pt":1580565391554,"mc":[{"id":"1.168133553","rc":[{"batb":[[0,11.5,10.63]],"ltp":11.5,"tv":1650.7,"id":27227336},{"batb":[[0,5.6,36.63]],"batl":[[0,5.7,12.37]],"ltp":5.6,"tv":4304.56,"id":21641292},{"trd":[[1.35,1934.34]],"batb":[[0,1.35,86.68]],"batl":[[0,1.36,262.66]],"ltp":1.35,"tv":32472.2,"id":16325787}],"tv":38427.46}]}
