{"op":"mcm","clk":"994057142","pt":1580548932711,"mc":[{"id":"1.168130661","rc":[{"batb":[[0,17.5,6.57],[2,16.5,5.44]],"ltp":18.0,"tv":525.95,"id":24707172}]}]}
{"op":"mcm","clk":"994057340","pt":1580548934634,"mc":[{"id":"1.168130661","rc":[{"batl":[[0,10.5,10],[1,11,2.12],[2,11.5,15.73]],"ltp":10.5,"tv":629.89,"id":420}]}]}
{"op":"mcm","clk":"994057767","pt":1580548938634,"mc":[{"id":"1.168130661","rc":[{"batb":[[0,18.5,3],[1,17.5,6.57],[2,17,1.3]],"ltp":18.0,"tv":525.95,"id":24707172}]}]}
{"op":"mcm","clk":"994057865","pt":1580548939537,"mc":[{"id":"1.168130661","rc":[{"batb":[[1,18,2.1],[2,17.5,6.57]],"batl":[[0,19.5,8.32]],"ltp":18.0,"tv":525.95,"id":24707172},{"trd":[[12,106.45]],"batb":[[0,12,2.47]],"ltp":12.0,"tv":821.44,"id":24420205}],"tv":8706.72}]}
{"op":"mcm","clk":"994058353","pt":1580548944649,"mc":[{"id":"1.168130661","rc":[{"batb":[[2,11,1.82]],"ltp":12.0,"tv":821.44,"id":24420205}]}]}
{"op":"mcm","clk":"994059044","pt":1580548951654,"mc":[{"id":"1.168130661","rc":[{"trd":[[2.7,644.05]],"batl":[[0,2.7,19.71]],"ltp":2.7,"tv":3357.8,"id":26314798}],"tv":8725.22}]}
{"op":"mcm","clk":"994069923","pt":1580548958672,"mc":[{"id":"1.168130661","rc":[{"trd":[[2.66,138.12]],"batb":[[0,2.66,21],[1,2.64,16.19],[2,2.62,85.08]],"batl":[[0,2.7,19],[1,2.72,88.34],[2,2.74,19]],"ltp":2.66,"tv":3284.57,"id":25238892},{"batl":[[0,10.5,12]],"ltp":10.5,"tv":629.89,"id":420}],"tv":8731.22}]}
{"op":"mcm","clk":"994070135","pt":1580548960696,"mc":[{"id":"1.168130661","rc":[{"batb":[[1,2.64,23.33]],"ltp":2.66,"tv":3284.57,"id":25238892}]}]}
{"op":"mcm","clk":"994070313","pt":1580548962564,"mc":[{"id":"1.168130661","rc":[{"batl":[[0,19.5,7.48]],"ltp":18.0,"tv":525.95,"id":24707172}]}]}
{"op":"mcm","clk":"994070530","pt":1580548964661,"mc":[{"id":"1.168130661","rc":[{"trd":[[2.7,653.85]],"batl":[[0,2.7,14.81]],"ltp":2.7,"tv":3367.6,"id":26314798}],"tv":8741.02}]}
{"op":"mcm","clk":"994071502","pt":1580548974688,"mc":[{"id":"1.168130661","rc":[{"batl":[[2,2.74,142]],"ltp":2.66,"tv":3284.57,"id":25238892}]}]}
{"op":"mcm","clk":"994071613","pt":1580548975578,"mc":[{"id":"1.168130661","rc":[{"batl":[[0,2.7,29.99]],"ltp":2.66,"tv":3284.57,"id":25238892}]}]}
{"op":"mcm","clk":"994071754","pt":1580548976671,"mc":[{"id":"1.168130661","rc":[{"trd":[[2.66,144.12]],"batb":[[0,2.66,18]],"ltp":2.66,"tv":3290.57,"id":25238892}],"tv":8747.02}]}
{"op":"mcm","clk":"994071863","pt":1580548977704,"mc":[{"id":"1.168130661","rc":[{"trd":[[18.5,39.31]],"batb":[[0,18,2.1],[1,17.5,6.57],[2,17,1.3]],"batl":[[0,19,2],[1,19.5,7.48],[2,20,8.25]],"ltp":18.5,"tv":531.95,"id":24707172}],"tv":8753.02}]}
{"op":"mcm","clk":"994072270","pt":1580548981511,"mc":[{"id":"1.168130661","rc":[{"batl":[[1,60,1.77],[2,65,2]],"ltp":50.0,"tv":111.54,"id":25545675}]}]}
{"op":"mcm","clk":"994072834","pt":1580548986626,"mc":[{"id":"1.168130661","rc":[{"batb":[[1,9.8,2.23]],"ltp":10.5,"tv":629.89,"id":420}]}]}
{"op":"mcm","clk":"994073845","pt":1580548997511,"mc":[{"id":"1.168130661","rc":[{"trd":[[18,49.45]],"batb":[[0,17.5,4.57],[1,17,1.3],[2,16.5,2.31]],"batl":[[0,18,1.9],[1,19,2],[2,19.5,2.28]],"ltp":18.0,"tv":536.15,"id":24707172}],"tv":8757.22}]}
{"op":"mcm","clk":"994074127","pt":1580549000635,"mc":[{"id":"1.168130661","rc":[{"batl":[[1,18.5,3],[2,19,2]],"ltp":18.0,"tv":536.15,"id":24707172}]}]}
{"op":"mcm","clk":"994074499","pt":1580549004643,"mc":[{"id":"1.168130661","rc":[{"trd":[[17.5,40.26]],"batb":[[0,17,1.3],[1,16.5,2.31],[2,16,1.08]],"batl":[[0,17.5,1.72],[1,18,1.9],[2,18.5,3]],"ltp":17.5,"tv":545.3,"id":24707172}],"tv":8766.36}]}
{"op":"mcm","clk":"994074604","pt":1580549005638,"mc":[{"id":"1.168130661","rc":[{"trd":[[16.5,21.87],[17,42.94]],"batb":[[0,16.5,1.61],[1,16,3.28],[2,15.5,5.09]],"ltp":16.5,"tv":549.3,"id":24707172}],"tv":8770.36}]}
{"op":"mcm","clk":"994074711","pt":1580549006524,"mc":[{"id":"1.168130661","rc":[{"trd":[[16.5,25.09]],"batb":[[0,16,1.08],[1,15.5,5.09],[2,14,20.61]],"ltp":16.5,"tv":552.52,"id":24707172}],"tv":8773.58}]}
{"op":"mcm","clk":"994074792","pt":1580549007554,"mc":[{"id":"1.168130661","rc":[{"batb":[[2,14.5,4.21]],"ltp":16.5,"tv":552.52,"id":24707172}]}]}
{"op":"mcm","clk":"994074981","pt":1580549009538,"mc":[{"id":"1.168130661","rc":[{"trd":[[15.5,62.11],[16,49.83]],"batb":[[0,15.5,4.17],[1,14.5,4.21],[2,14,20.61]],"ltp":15.5,"tv":556.51,"id":24707172}],"tv":8777.58}]}
{"op":"mcm","clk":"994075187","pt":1580549011639,"mc":[{"id":"1.168130661","rc":[{"batb":[[0,36,5.73]],"ltp":50.0,"tv":111.54,"id":25545675},{"trd":[[2.7,683.45]],"batb":[[0,2.7,48.37],[1,2.68,105.82],[2,2.66,24.2]],"batl":[[0,2.72,342.74],[1,2.74,81.55],[2,2.76,226]],"ltp":2.7,"tv":3397.2,"id":26314798}],"tv":8807.18}]}
{"op":"mcm","clk":"994075376","pt":1580549013673,"mc":[{"id":"1.168130661","rc":[{"batb":[[1,2.68,117.75]],"ltp":2.7,"tv":3397.2,"id":26314798}]}]}
{"op":"mcm","clk":"994076008","pt":1580549019681,"mc":[{"id":"1.168130661","rc":[{"batb":[[0,36,2.93]],"ltp":50.0,"tv":111.54,"id":25545675},{"trd":[[15.5,70.45]],"batb":[[0,14.5,4.21],[1,14,20.61],[2,13.5,12.02]],"batl":[[0,15.5,3.65],[1,17.5,1.72],[2,18,1.9]],"ltp":15.5,"tv":564.85,"id":24707172},{"batb":[[0,2.68,117.75],[1,2.66,24.2],[2,2.64,39.2]],"ltp":2.7,"tv":3397.2,"id":26314798}],"tv":8815.52}]}
{"op":"mcm","clk":"994076138","pt":1580549020679,"mc":[{"id":"1.168130661","rc":[{"batb":[[0,2.68,3.21],[1,2.66,24.51],[2,2.64,23.33]],"batl":[[1,2.72,81.34]],"ltp":2.66,"tv":3290.57,"id":25238892},{"batb":[[0,12,4.47]],"batl":[[0,13,20.8],[1,13.5,2],[2,14,2.36]],"ltp":12.0,"tv":821.44,"id":24420205},{"batb":[[0,2.7,16.62],[1,2.68,117.75],[2,2.66,24.2]],"batl":[[1,2.74,79.55]],"ltp":2.7,"tv":3397.2,"id":26314798},{"batl":[[0,10.5,10]],"ltp":10.5,"tv":629.89,"id":420}]}]}
{"op":"mcm","clk":"994076232","pt":1580549021545,"mc":[{"id":"1.168130661","rc":[{"batb":[[2,2.64,16.19]],"ltp":2.66,"tv":3290.57,"id":25238892},{"batb":[[0,15,1.26]],"ltp":15.5,"tv":564.85,"id":24707172},{"batb":[[0,12,6.04]],"ltp":12.0,"tv":821.44,"id":24420205},{"batb":[[1,2.68,111.51],[2,2.66,10.21]],"ltp":2.7,"tv":3397.2,"id":26314798},{"batb":[[0,10,6.21]],"ltp":10.5,"tv":629.89,"id":420}]}]}
{"op":"mcm","clk":"994076402","pt":1580549023265,"mc":[{"id":"1.168130661","rc":[{"batb":[[1,14,2.61]],"ltp":15.5,"tv":564.85,"id":24707172}]}]}
{"op":"mcm","clk":"994076977","pt":1580549027693,"mc":[{"id":"1.168130661","rc":[{"batb":[[0,38,4.93],[1,36,2.93],[2,34,4.66]],"ltp":50.0,"tv":111.54,"id":25545675}]}]}
{"op":"mcm","clk":"994077094","pt":1580549028660,"mc":[{"id":"1.168130661","rc":[{"batb":[[0,2.66,24.51],[1,2.64,16.19],[2,2.62,81.95]],"batl":[[1,2.72,89.34]],"ltp":2.66,"tv":3290.57,"id":25238892},{"trd":[[15.5,77.75]],"batb":[[0,15.5,4.35],[1,15,1.26],[2,14,2.61]],"batl":[[0,17,5.66]],"ltp":15.5,"tv":572.15,"id":24707172},{"batl":[[0,12.5,3.26],[1,13,20.8],[2,13.5,2]],"ltp":12.0,"tv":821.44,"id":24420205},{"batb":[[0,2.7,6.41]],"batl":[[1,2.74,81.55]],"ltp":2.7,"tv":3397.2,"id":26314798}],"tv":8822.82}]}
{"op":"mcm","clk":"994077202","pt":1580549029659,"mc":[{"id":"1.168130661","rc":[{"batb":[[1,36,5.55]],"ltp":50.0,"tv":111.54,"id":25545675}]}]}
{"op":"mcm","clk":"994077295","pt":1580549030584,"mc":[{"id":"1.168130661","rc":[{"batb":[[1,2.64,24.47]],"ltp":2.66,"tv":3290.57,"id":25238892},{"batb":[[2,14.5,2.63]],"ltp":15.5,"tv":572.15,"id":24707172},{"batb":[[1,2.68,105.82]],"ltp":2.7,"tv":3397.2,"id":26314798}]}]}
{"op":"mcm","clk":"994077490","pt":1580549032677,"mc":[{"id":"1.168130661","rc":[{"batb":[[0,12,4.04],[2,10.5,10.56]],"ltp":12.0,"tv":821.44,"id":24420205}]}]}
{"op":"mcm","clk":"994077595","pt":1580549033682,"mc":[{"id":"1.168130661","rc":[{"trd":[[16.5,31.09]],"ltp":16.5,"tv":578.15,"id":24707172}],"tv":8828.82}]}
{"op":"mcm","clk":"994077781","pt":1580549035699,"mc":[{"id":"1.168130661","rc":[{"batb":[[0,38,2]],"ltp":50.0,"tv":111.54,"id":25545675}]}]}
{"op":"mcm","clk":"994077994","pt":1580549037687,"mc":[{"id":"1.168130661","rc":[{"batb":[[1,36,6.03]],"ltp":50.0,"tv":111.54,"id":25545675}]}]}
{"op":"mcm","clk":"994078196","pt":1580549039714,"mc":[{"id":"1.168130661","rc":[{"batb":[[1,36,3.42]],"ltp":50.0,"tv":111.54,"id":25545675},{"batb":[[0,16.5,3],[1,15.5,4.35],[2,15,1.26]],"ltp":16.5,"tv":578.15,"id":24707172}]}]}
{"op":"mcm","clk":"994078543","pt":1580549042711,"mc":[{"id":"1.168130661","rc":[{"batl":[[0,2.72,340.74]],"ltp":2.7,"tv":3397.2,"id":26314798}]}]}
{"op":"mcm","clk":"994078865","pt":1580549045719,"mc":[{"id":"1.168130661","rc":[{"trd":[[2.68,626.82],[2.7,696.27]],"batb":[[0,2.68,36.17],[1,2.66,10.21],[2,2.64,39.2]],"ltp":2.68,"tv":3549.23,"id":26314798}],"tv":8980.85}]}
{"op":"mcm","clk":"994078918","pt":1580549046192,"mc":[{"id":"1.168130661","rc":[{"batl":[[2,2.74,145]],"ltp":2.66,"tv":3290.57,"id":25238892},{"batb":[[0,2.68,26.17],[1,2.66,12.81]],"ltp":2.68,"tv":3549.23,"id":26314798}]}]}
{"op":"mcm","clk":"994079068","pt":1580549047697,"mc":[{"id":"1.168130661","rc":[{"batb":[[1,2.66,22.29]],"ltp":2.68,"tv":3549.23,"id":26314798}]}]}
{"op":"mcm","clk":"994080284","pt":1580549060631,"mc":[{"id":"1.168130661","rc":[{"batb":[[1,2.64,26.78]],"ltp":2.66,"tv":3290.57,"id":25238892}]}]}
{"op":"mcm","clk":"994081795","pt":1580549075582,"mc":[{"id":"1.168130661","rc":[{"batl":[[0,2.7,15.37],[1,2.72,340.74],[2,2.74,81.55]],"ltp":2.68,"tv":3549.23,"id":26314798}]}]}
{"op":"mcm","clk":"994081919","pt":1580549076682,"mc":[{"id":"1.168130661","rc":[{"batl":[[1,17.5,4.91]],"ltp":16.5,"tv":578.15,"id":24707172},{"batb":[[0,2.68,36.17]],"ltp":2.68,"tv":3549.23,"id":26314798}]}]}
{"op":"mcm","clk":"994082405","pt":1580549081677,"mc":[{"id":"1.168130661","rc":[{"trd":[[17,49.56]],"batl":[[0,17,2.35]],"ltp":17.0,"tv":584.77,"id":24707172}],"tv":8987.47}]}
{"op":"mcm","clk":"994082491","pt":1580549082674,"mc":[{"id":"1.168130661","rc":[{"trd":[[2.66,152.12]],"batb":[[0,2.66,20.51]],"ltp":2.66,"tv":3298.57,"id":25238892}],"tv":8995.47}]}
{"op":"mcm","clk":"994082601","pt":1580549083667,"mc":[{"id":"1.168130661","rc":[{"batl":[[0,2.7,35.37]],"ltp":2.68,"tv":3549.23,"id":26314798}]}]}
{"op":"mcm","clk":"994084259","pt":1580549099683,"mc":[{"id":"1.168130661","rc":[{"batb":[[2,2.64,39.5]],"ltp":2.68,"tv":3549.23,"id":26314798}]}]}
{"op":"mcm","clk":"994084329","pt":1580549100303,"mc":[{"id":"1.168130661","rc":[{"trd":[[12,110.46]],"batb":[[0,12,2.04]],"ltp":12.0,"tv":825.44,"id":24420205}],"tv":8999.47}]}
{"op":"mcm","clk":"994084558","pt":1580549102595,"mc":[{"id":"1.168130661","rc":[{"batb":[[2,2.64,39.2]],"ltp":2.68,"tv":3549.23,"id":26314798}]}]}
{"op":"mcm","clk":"994084912","pt":1580549105709,"mc":[{"id":"1.168130661","rc":[{"batb":[[2,2.62,82.26]],"ltp":2.66,"tv":3298.57,"id":25238892}]}]}
{"op":"mcm","clk":"994085112","pt":1580549107591,"mc":[{"id":"1.168130661","rc":[{"trd":[[38,15.57]],"batb":[[1,36,2.93]],"batl":[[0,48,2.02],[1,50,10.38],[2,60,1.77]],"ltp":38.0,"tv":115.54,"id":25545675},{"batb":[[0,2.68,4.02],[1,2.66,20.51],[2,2.64,26.78]],"ltp":2.66,"tv":3298.57,"id":25238892}],"tv":9003.47}]}
{"op":"mcm","clk":"994085358","pt":1580549109720,"mc":[{"id":"1.168130661","rc":[{"batb":[[2,2.64,18.5]],"ltp":2.66,"tv":3298.57,"id":25238892}]}]}
{"op":"mcm","clk":"994085443","pt":1580549110499,"mc":[{"id":"1.168130661","rc":[{"batb":[[2,9.6,2.06]],"ltp":10.5,"tv":629.89,"id":420}]}]}
{"op":"mcm","clk":"994085563","pt":1580549111700,"mc":[{"id":"1.168130661","rc":[{"batb":[[2,9.6,2]],"ltp":10.5,"tv":629.89,"id":420}]}]}
{"op":"mcm","clk":"994085818","pt":1580549114308,"mc":[{"id":"1.168130661","rc":[{"batb":[[2,2.64,39.5]],"ltp":2.68,"tv":3549.23,"id":26314798}]}]}
{"op":"mcm","clk":"994085936","pt":1580549115508,"mc":[{"id":"1.168130661","rc":[{"batb":[[2,34,5.18]],"ltp":38.0,"tv":115.54,"id":25545675},{"batb":[[2,2.64,39.2]],"ltp":2.68,"tv":3549.23,"id":26314798}]}]}
{"op":"mcm","clk":"994086684","pt":1580549122649,"mc":[{"id":"1.168130661","rc":[{"trd":[[48,6.61]],"batl":[[0,50,10.38],[1,60,1.77],[2,65,2]],"ltp":48.0,"tv":118.79,"id":25545675},{"trd":[[2.7,174.36]],"batb":[[0,2.66,20.51],[1,2.64,18.5],[2,2.62,81.95]],"batl":[[0,2.7,15.95]],"ltp":2.7,"tv":3312.61,"id":25238892},{"trd":[[17,52.03],[17.5,43.7]],"batb":[[0,17,5.73],[1,16.5,3],[2,15.5,4.35]],"batl":[[0,18,5.02],[1,18.5,3],[2,19,2]],"ltp":17.5,"tv":590.68,"id":24707172},{"trd":[[12.5,86.85]],"batl":[[0,12.5,2.23]],"ltp":12.5,"tv":828.47,"id":24420205},{"trd":[[2.7,710.3]],"batl":[[0,2.7,21.33]],"ltp":2.7,"tv":3563.27,"id":26314798},{"trd":[[10,151.96]],"batb":[[0,9.8,2.23],[1,9.6,2],[2,9.2,2.49]],"ltp":10.0,"tv":646.1,"id":420}],"tv":9059.95}]}
{"op":"mcm","clk":"994086775","pt":1580549123635,"mc":[{"id":"1.168130661","rc":[{"batb":[[0,2.68,12.13],[1,2.66,20.51],[2,2.64,18.5]],"ltp":2.7,"tv":3312.61,"id":25238892},{"trd":[[18,53.25]],"batl":[[0,19,5.12],[1,20,8.25],[2,21,26.12]],"ltp":18.0,"tv":594.48,"id":24707172},{"batb":[[0,2.68,26.17]],"batl":[[1,2.72,342.74]],"ltp":2.7,"tv":3563.27,"id":26314798},{"batb":[[1,9.6,4.97]],"ltp":10.0,"tv":646.1,"id":420}],"tv":9063.75}]}
{"op":"mcm","clk":"994086880","pt":1580549124722,"mc":[{"id":"1.168130661","rc":[{"batb":[[1,2.66,22.85]],"ltp":2.7,"tv":3312.61,"id":25238892},{"batb":[[0,16.5,3],[1,15.5,4.35],[2,15,1.26]],"batl":[[1,20,10.37]],"ltp":18.0,"tv":594.48,"id":24707172},{"batb":[[1,9.6,2]],"ltp":10.0,"tv":646.1,"id":420}]}]}
{"op":"mcm","clk":"994086982","pt":1580549125620,"mc":[{"id":"1.168130661","rc":[{"batb":[[1,2.66,24.85]],"ltp":2.7,"tv":3312.61,"id":25238892}]}]}
{"op":"mcm","clk":"994087047","pt":1580549126245,"mc":[{"id":"1.168130661","rc":[{"batb":[[1,16,2.51],[2,15.5,4.35]],"batl":[[1,20,8.25]],"ltp":18.0,"tv":594.48,"id":24707172}]}]}
{"op":"mcm","clk":"994087117","pt":1580549126929,"mc":[{"id":"1.168130661","rc":[{"batb":[[2,11,1.82]],"ltp":12.5,"tv":828.47,"id":24420205}]}]}
{"op":"mcm","clk":"994087386","pt":1580549129639,"mc":[{"id":"1.168130661","rc":[{"batb":[[1,15.5,4.35],[2,15,1.26]],"ltp":18.0,"tv":594.48,"id":24707172},{"trd":[[12,114.52]],"batb":[[0,11.5,2.1],[1,11,4.21],[2,10.5,10.56]],"batl":[[0,13,20.8],[1,13.5,2],[2,14,2.36]],"ltp":12.0,"tv":832.54,"id":24420205}],"tv":9067.81}]}
{"op":"mcm","clk":"994087445","pt":1580549130157,"mc":[{"id":"1.168130661","rc":[{"batb":[[2,34,4.66]],"ltp":48.0,"tv":118.79,"id":25545675}]}]}
{"op":"mcm","clk":"994087582","pt":1580549131516,"mc":[{"id":"1.168130661","rc":[{"batl":[[0,50,10.71]],"ltp":48.0,"tv":118.79,"id":25545675}]}]}
{"op":"mcm","clk":"994087917","pt":1580549134641,"mc":[{"id":"1.168130661","rc":[{"batb":[[0,17.5,3],[1,16.5,3],[2,15.5,4.35]],"ltp":18.0,"tv":594.48,"id":24707172},{"batb":[[1,11,1.82]],"ltp":12.0,"tv":832.54,"id":24420205},{"batl":[[0,10.5,12]],"ltp":10.0,"tv":646.1,"id":420}]}]}
{"op":"mcm","clk":"994088471","pt":1580549139468,"mc":[{"id":"1.168130661","rc":[{"batl":[[2,2.74,143]],"ltp":2.7,"tv":3312.61,"id":25238892},{"batb":[[0,9.8,4.23]],"ltp":10.0,"tv":646.1,"id":420}]}]}
{"op":"mcm","clk":"994088853","pt":1580549143478,"mc":[{"id":"1.168130661","rc":[{"batl":[[2,21,14.12]],"ltp":18.0,"tv":594.48,"id":24707172}]}]}
{"op":"mcm","clk":"994089567","pt":1580549150683,"mc":[{"id":"1.168130661","rc":[{"batb":[[1,10.5,10.56],[2,10,21.27]],"ltp":12.0,"tv":832.54,"id":24420205}]}]}
{"op":"mcm","clk":"994089687","pt":1580549151674,"mc":[{"id":"1.168130661","rc":[{"batb":[[0,11,8.55]],"ltp":12.0,"tv":832.54,"id":24420205}]}]}
{"op":"mcm","clk":"994090709","pt":1580549161704,"mc":[{"id":"1.168130661","rc":[{"trd":[[2.68,630.82]],"batb":[[0,2.68,24.17]],"ltp":2.68,"tv":3567.27,"id":26314798}],"tv":9071.81}]}
{"op":"mcm","clk":"994090800","pt":1580549162701,"mc":[{"id":"1.168130661","rc":[{"trd":[[17,58.03],[17.5,49.7]],"batb":[[0,17,2.73]],"batl":[[0,17.5,3],[1,19,5.12],[2,20,8.25]],"ltp":17.0,"tv":606.48,"id":24707172},{"trd":[[2.7,714.26]],"batl":[[0,2.7,19.35]],"ltp":2.7,"tv":3571.23,"id":26314798}],"tv":9087.77}]}
{"op":"mcm","clk":"994090965","pt":1580549164206,"mc":[{"id":"1.168130661","rc":[{"batb":[[1,2.66,37.89]],"ltp":2.7,"tv":3571.23,"id":26314798}]}]}
{"op":"mcm","clk":"994091630","pt":1580549170671,"mc":[{"id":"1.168130661","rc":[{"trd":[[2.7,178.8]],"batb":[[2,2.64,16.5]],"batl":[[0,2.7,10.73],[2,2.74,9]],"ltp":2.7,"tv":3317.05,"id":25238892}],"tv":9092.21}]}
{"op":"mcm","clk":"994091741","pt":1580549171712,"mc":[{"id":"1.168130661","rc":[{"batb":[[0,2.68,14.1]],"ltp":2.7,"tv":3317.05,"id":25238892}]}]}
{"op":"mcm","clk":"994091868","pt":1580549172695,"mc":[{"id":"1.168130661","rc":[{"batb":[[0,38,4]],"ltp":48.0,"tv":118.79,"id":25545675},{"batl":[[0,13,18.8]],"ltp":12.0,"tv":832.54,"id":24420205}]}]}
{"op":"mcm","clk":"994092373","pt":1580549177586,"mc":[{"id":"1.168130661","rc":[{"batb":[[1,36,2.29]],"ltp":48.0,"tv":118.79,"id":25545675}]}]}
{"op":"mcm","clk":"994092969","pt":1580549182703,"mc":[{"id":"1.168130661","rc":[{"trd":[[17,63.49]],"batb":[[0,16.5,3],[1,15.5,4.35],[2,15,1.26]],"batl":[[0,17,3.27],[1,17.5,3],[2,19,5.12]],"ltp":17.0,"tv":611.94,"id":24707172}],"tv":9097.67}]}
{"op":"mcm","clk":"994093093","pt":1580549183695,"mc":[{"id":"1.168130661","rc":[{"batb":[[1,36,4.48]],"ltp":48.0,"tv":118.79,"id":25545675}]}]}
{"op":"mcm","clk":"994093175","pt":1580549184323,"mc":[{"id":"1.168130661","rc":[{"batb":[[1,36,4.97]],"ltp":48.0,"tv":118.79,"id":25545675}]}]}
{"op":"mcm","clk":"994093690","pt":1580549189345,"mc":[{"id":"1.168130661","rc":[{"trd":[[2.7,182.8]],"batl":[[0,2.7,8.73]],"ltp":2.7,"tv":3321.05,"id":25238892}],"tv":9101.67}]}
{"op":"mcm","clk":"994097320","pt":1580549226630,"mc":[{"id":"1.168130661","rc":[{"trd":[[16.5,37.09]],"batb":[[0,15.5,4.35],[1,15,1.26],[2,14,2.61]],"ltp":16.5,"tv":617.94,"id":24707172}],"tv":9107.67}]}
{"op":"mcm","clk":"994097763","pt":1580549231723,"mc":[{"id":"1.168130661","rc":[{"batb":[[0,38,6.93]],"ltp":48.0,"tv":118.79,"id":25545675},{"batb":[[0,11.5,11.01],[1,11,8.55],[2,10.5,10.56]],"ltp":12.0,"tv":832.54,"id":24420205}]}]}
{"op":"mcm","clk":"994097838","pt":1580549232608,"mc":[{"id":"1.168130661","rc":[{"batb":[[0,12,2.06],[1,11.5,11.01],[2,11,8.55]],"ltp":12.0,"tv":832.54,"id":24420205}]}]}
{"op":"mcm","clk":"994098099","pt":1580549235717,"mc":[{"id":"1.168130661","rc":[{"batb":[[0,42,2.08],[1,40,1.68],[2,38,6.93]],"ltp":48.0,"tv":118.79,"id":25545675}]}]}
{"op":"mcm","clk":"994098438","pt":1580549239672,"mc":[{"id":"1.168130661","rc":[{"batb":[[2,38,4]],"ltp":48.0,"tv":118.79,"id":25545675},{"batb":[[0,11.5,2.1],[1,11,8.55],[2,10.5,10.56]],"ltp":12.0,"tv":832.54,"id":24420205}]}]}
{"op":"mcm","clk":"994099287","pt":1580549249644,"mc":[{"id":"1.168130661","rc":[{"batb":[[0,16.5,3],[1,15.5,4.35],[2,15,1.26]],"ltp":16.5,"tv":617.94,"id":24707172}]}]}
{"op":"mcm","clk":"994099371","pt":1580549250521,"mc":[{"id":"1.168130661","rc":[{"trd":[[16.5,43.09]],"batb":[[0,15.5,4.35],[1,15,1.26],[2,14,2.61]],"ltp":16.5,"tv":623.94,"id":24707172}],"tv":9113.67}]}
{"op":"mcm","clk":"994099446","pt":1580549251456,"mc":[{"id":"1.168130661","rc":[{"batb":[[1,15,3.54]],"ltp":16.5,"tv":623.94,"id":24707172}]}]}
{"op":"mcm","clk":"994099722","pt":1580549254535,"mc":[{"id":"1.168130661","rc":[{"batb":[[1,15,1.26]],"ltp":16.5,"tv":623.94,"id":24707172}]}]}
{"op":"mcm","clk":"994099804","pt":1580549255574,"mc":[{"id":"1.168130661","rc":[{"batb":[[0,10,3.72],[1,9.8,4.23],[2,9.6,2]],"ltp":10.0,"tv":646.1,"id":420}]}]}
{"op":"mcm","clk":"994100019","pt":1580549257676,"mc":[{"id":"1.168130661","rc":[{"batb":[[0,12,6.4],[1,11.5,2.1],[2,11,8.55]],"batl":[[0,13,20.8]],"ltp":12.0,"tv":832.54,"id":24420205}]}]}
{"op":"mcm","clk":"994100723","pt":1580549265717,"mc":[{"id":"1.168130661","rc":[{"batb":[[0,10,7.95]],"batl":[[0,10.5,10]],"ltp":10.0,"tv":646.1,"id":420}]}]}
{"op":"mcm","clk":"994100892","pt":1580549267678,"mc":[{"id":"1.168130661","rc":[{"batb":[[0,40,2.71],[1,38,4],[2,36,2.97]],"ltp":48.0,"tv":118.79,"id":25545675}]}]}
{"op":"mcm","clk":"994104248","pt":1580549301721,"mc":[{"id":"1.168130661","rc":[{"trd":[[2.68,154.49]],"batb":[[0,2.68,12.1]],"ltp":2.68,"tv":3325.05,"id":25238892}],"tv":9117.67}]}
{"op":"mcm","clk":"994104925","pt":1580549308621,"mc":[{"id":"1.168130661","rc":[{"trd":[[16,53.83]],"ltp":16.0,"tv":627.94,"id":24707172}],"tv":9121.67}]}
{"op":"mcm","clk":"994105005","pt":1580549309451,"mc":[{"id":"1.168130661","rc":[{"batb":[[0,12,6.5]],"ltp":12.0,"tv":832.54,"id":24420205}]}]}
{"op":"mcm","clk":"994105238","pt":1580549311541,"mc":[{"id":"1.168130661","rc":[{"batb":[[0,16.5,3],[1,15.5,4.35],[2,15,1.26]],"ltp":16.0,"tv":627.94,"id":24707172}]}]}
{"op":"mcm","clk":"994105352","pt":1580549312632,"mc":[{"id":"1.168130661","rc":[{"trd":[[40,7.29]],"batb":[[0,40,2.17]],"batl":[[0,48,2.5],[1,50,12.38],[2,60,1.77]],"ltp":40.0,"tv":124.22,"id":25545675},{"trd":[[16.5,49.09]],"batb":[[0,15.5,4.35],[1,15,1.26],[2,14,2.61]],"ltp":16.5,"tv":633.94,"id":24707172},{"batl":[[1,2.72,340.74],[2,2.74,79.55]],"ltp":2.7,"tv":3571.23,"id":26314798}],"tv":9133.1}]}
{"op":"mcm","clk":"994105687","pt":1580549315653,"mc":[{"id":"1.168130661","rc":[{"batb":[[0,10,12.95]],"ltp":10.0,"tv":646.1,"id":420}]}]}
{"op":"mcm","clk":"994106104","pt":1580549319662,"mc":[{"id":"1.168130661","rc":[{"batl":[[0,48,2.17]],"ltp":40.0,"tv":124.22,"id":25545675}]}]}
{"op":"mcm","clk":"994107275","pt":1580549331581,"mc":[{"id":"1.168130661","rc":[{"batb":[[0,11.5,2.1],[1,11,8.55],[2,10.5,10.56]],"ltp":12.0,"tv":832.54,"id":24420205}]}]}
{"op":"mcm","clk":"994108157","pt":1580549340681,"mc":[{"id":"1.168130661","rc":[{"batl":[[1,17.5,6],[2,19,2]],"ltp":16.5,"tv":633.94,"id":24707172},{"trd":[[2.68,679.15]],"batb":[[0,2.66,37.89],[1,2.64,39.2],[2,2.62,92.95]],"batl":[[0,2.68,30.84],[1,2.7,19.35],[2,2.72,340.74]],"ltp":2.68,"tv":3619.56,"id":26314798}],"tv":9181.43}]}
{"op":"mcm","clk":"994108263","pt":1580549341680,"mc":[{"id":"1.168130661","rc":[{"batl":[[0,16.5,5.84],[1,17,3.27],[2,17.5,6]],"ltp":16.5,"tv":633.94,"id":24707172},{"batb":[[0,2.66,25.8],[1,2.64,53.09]],"ltp":2.68,"tv":3619.56,"id":26314798}]}]}
{"op":"mcm","clk":"994108379","pt":1580549342668,"mc":[{"id":"1.168130661","rc":[{"batb":[[0,2.68,15.1]],"ltp":2.68,"tv":3325.05,"id":25238892},{"batl":[[1,17,6.27]],"ltp":16.5,"tv":633.94,"id":24707172}]}]}
{"op":"mcm","clk":"994108439","pt":1580549343295,"mc":[{"id":"1.168130661","rc":[{"batb":[[1,9.8,9.23]],"ltp":10.0,"tv":646.1,"id":420}]}]}
{"op":"mcm","clk":"994108575","pt":1580549344707,"mc":[{"id":"1.168130661","rc":[{"batb":[[0,40,4.95]],"ltp":40.0,"tv":124.22,"id":25545675},{"batb":[[0,2.68,12.1]],"ltp":2.68,"tv":3325.05,"id":25238892},{"batb":[[0,2.66,15.59]],"ltp":2.68,"tv":3619.56,"id":26314798},{"trd":[[10.5,153.12]],"batb":[[0,10.5,6.45],[1,10,12.95],[2,9.8,7]],"batl":[[0,11.5,15.73],[1,12,5.75],[2,14,18.91]],"ltp":10.5,"tv":666.09,"id":420}],"tv":9201.42}]}
{"op":"mcm","clk":"994108658","pt":1580549345592,"mc":[{"id":"1.168130661","rc":[{"batl":[[0,16.5,8.84]],"ltp":16.5,"tv":633.94,"id":24707172},{"batb":[[0,2.64,68.8],[1,2.62,92.95],[2,2.6,24.29]],"ltp":2.68,"tv":3619.56,"id":26314798},{"trd":[[11,59.56]],"batb":[[1,10,10.95]],"batl":[[0,11.5,13.73],[1,12,7.75],[2,14,18]],"ltp":11.0,"tv":668.03,"id":420}],"tv":9203.36}]}
{"op":"mcm","clk":"994108750","pt":1580549346683,"mc":[{"id":"1.168130661","rc":[{"batb":[[2,14.5,2.63]],"ltp":16.5,"tv":633.94,"id":24707172},{"batb":[[0,2.64,54.91],[1,2.62,107.86]],"ltp":2.68,"tv":3619.56,"id":26314798}]}]}
{"op":"mcm","clk":"994109183","pt":1580549350706,"mc":[{"id":"1.168130661","rc":[{"trd":[[15.5,83.75]],"batb":[[0,15.5,1.35]],"ltp":15.5,"tv":639.94,"id":24707172}],"tv":9209.36}]}
{"op":"mcm","clk":"994109237","pt":1580549351285,"mc":[{"id":"1.168130661","rc":[{"trd":[[15.5,86.45]],"batb":[[0,15,1.26],[1,14.5,2.63],[2,14,5.69]],"batl":[[0,15.5,2.55],[1,16.5,8.84],[2,17,6.27]],"ltp":15.5,"tv":642.64,"id":24707172},{"batb":[[0,11,2.06],[1,10.5,6.45],[2,10,10.95]],"batl":[[2,14,18.91]],"ltp":11.0,"tv":668.03,"id":420}],"tv":9212.06}]}
{"op":"mcm","clk":"994109373","pt":1580549352692,"mc":[{"id":"1.168130661","rc":[{"batb":[[1,14,5.69],[2,13.5,12.82]],"batl":[[1,16,3.07],[2,16.5,8.84]],"ltp":15.5,"tv":642.64,"id":24707172}]}]}
{"op":"mcm","clk":"994109450","pt":1580549353626,"mc":[{"id":"1.168130661","rc":[{"batb":[[1,14,2.61],[2,13.5,15.31]],"ltp":15.5,"tv":642.64,"id":24707172}]}]}
{"op":"mcm","clk":"994109543","pt":1580549354517,"mc":[{"id":"1.168130661","rc":[{"batl":[[2,15.5,3.23]],"ltp":11.0,"tv":668.03,"id":420}]}]}
{"op":"mcm","clk":"994109670","pt":1580549355709,"mc":[{"id":"1.168130661","rc":[{"batb":[[2,13.5,12.82]],"ltp":15.5,"tv":642.64,"id":24707172}]}]}
{"op":"mcm","clk":"994110360","pt":1580549362708,"mc":[{"id":"1.168130661","rc":[{"batb":[[2,13.5,12.02]],"ltp":15.5,"tv":642.64,"id":24707172},{"trd":[[2.68,740.83]],"batb":[[0,2.68,50.16],[1,2.66,9.12],[2,2.64,54.91]],"batl":[[0,2.7,19.35],[1,2.72,340.74],[2,2.74,79.55]],"ltp":2.68,"tv":3681.24,"id":26314798}],"tv":9273.74}]}
{"op":"mcm","clk":"994110559","pt":1580549364631,"mc":[{"id":"1.168130661","rc":[{"trd":[[12.5,95.65]],"ltp":12.5,"tv":841.34,"id":24420205},{"batb":[[1,2.66,22.21]],"ltp":2.68,"tv":3681.24,"id":26314798}],"tv":9282.54}]}
{"op":"mcm","clk":"994110759","pt":1580549366516,"mc":[{"id":"1.168130661","rc":[{"batl":[[0,48,2.5]],"ltp":40.0,"tv":124.22,"id":25545675}]}]}
{"op":"mcm","clk":"994110872","pt":1580549367621,"mc":[{"id":"1.168130661","rc":[{"batb":[[0,11,4.06],[1,10.5,8.45]],"ltp":11.0,"tv":668.03,"id":420}]}]}
{"op":"mcm","clk":"994110971","pt":1580549368407,"mc":[{"id":"1.168130661","rc":[{"batb":[[0,40,2.17]],"ltp":40.0,"tv":124.22,"id":25545675}]}]}
{"op":"mcm","clk":"994111603","pt":1580549374613,"mc":[{"id":"1.168130661","rc":[{"batb":[[1,14,32.61]],"batl":[[2,16.5,3]],"ltp":15.5,"tv":642.64,"id":24707172}]}]}
{"op":"mcm","clk":"994112132","pt":1580549380139,"mc":[{"id":"1.168130661","rc":[{"trd":[[2.68,750.83]],"batb":[[0,2.68,45.16]],"ltp":2.68,"tv":3691.24,"id":26314798}],"tv":9292.54}]}
{"op":"mcm","clk":"994112539","pt":1580549384570,"mc":[{"id":"1.168130661","rc":[{"batl":[[1,50,12.1]],"ltp":40.0,"tv":124.22,"id":25545675},{"trd":[[2.68,164.49]],"batb":[[0,2.68,7.1]],"ltp":2.68,"tv":3335.05,"id":25238892}],"tv":9302.54}]}
{"op":"mcm","clk":"994112634","pt":1580549385558,"mc":[{"id":"1.168130661","rc":[{"batl":[[0,48,2.81]],"ltp":40.0,"tv":124.22,"id":25545675}]}]}
{"op":"mcm","clk":"994113037","pt":1580549389680,"mc":[{"id":"1.168130661","rc":[{"batl":[[0,11.5,15.11]],"ltp":11.0,"tv":668.03,"id":420}]}]}
{"op":"mcm","clk":"994113053","pt":1580549389840,"mc":[{"id":"1.168130661","rc":[{"batl":[[0,2.7,24.35]],"ltp":2.68,"tv":3691.24,"id":26314798}]}]}
{"op":"mcm","clk":"994113402","pt":1580549393260,"mc":[{"id":"1.168130661","rc":[{"batb":[[1,2.66,22.51]],"ltp":2.68,"tv":3335.05,"id":25238892},{"trd":[[15,76.13]],"batb":[[0,14,32.61],[1,13.5,12.02],[2,13,6.7]],"batl":[[0,15,33.74],[1,15.5,5.55],[2,16,3.07]],"ltp":15.0,"tv":645.16,"id":24707172}],"tv":9305.06}]}
{"op":"mcm","clk":"994114855","pt":1580549406701,"mc":[{"id":"1.168130661","rc":[{"batl":[[0,15,51.74]],"ltp":15.0,"tv":645.16,"id":24707172}]}]}
{"op":"mcm","clk":"994114967","pt":1580549407589,"mc":[{"id":"1.168130661","rc":[{"batb":[[1,13.5,12.82]],"batl":[[0,14.5,6.35],[1,15,78.74],[2,15.5,5.55]],"ltp":15.0,"tv":645.16,"id":24707172},{"batl":[[0,13,18.8]],"ltp":12.5,"tv":841.34,"id":24420205}]}]}
{"op":"mcm","clk":"994115080","pt":1580549408586,"mc":[{"id":"1.168130661","rc":[{"batb":[[0,40,4.95]],"ltp":40.0,"tv":124.22,"id":25545675},{"trd":[[14.5,89.86]],"batb":[[0,14.5,6.76],[1,14,32.61],[2,13.5,12.02]],"batl":[[0,15,78.74],[1,15.5,5.55],[2,16,3.07]],"ltp":14.5,"tv":657.85,"id":24707172}],"tv":9317.75}]}
{"op":"mcm","clk":"994116034","pt":1580549417605,"mc":[{"id":"1.168130661","rc":[{"batb":[[0,40,2.17]],"ltp":40.0,"tv":124.22,"id":25545675},{"batb":[[0,14,32.61],[1,13.5,16.03],[2,13,6.7]],"ltp":14.5,"tv":657.85,"id":24707172}]}]}
{"op":"mcm","clk":"994116253","pt":1580549419591,"mc":[{"id":"1.168130661","rc":[{"batl":[[0,46,10.3],[1,50,2.43]],"ltp":40.0,"tv":124.22,"id":25545675}]}]}
{"op":"mcm","clk":"994117872","pt":1580549435642,"mc":[{"id":"1.168130661","rc":[{"batb":[[0,40,2.6]],"ltp":40.0,"tv":124.22,"id":25545675}]}]}
{"op":"mcm","clk":"994117972","pt":1580549436639,"mc":[{"id":"1.168130661","rc":[{"batl":[[0,46,12.3]],"ltp":40.0,"tv":124.22,"id":25545675}]}]}
{"op":"mcm","clk":"994118539","pt":1580549441664,"mc":[{"id":"1.168130661","rc":[{"trd":[[14,39.96]],"batb":[[0,13.5,16.03],[1,13,6.7],[2,12.5,2.91]],"ltp":14.0,"tv":665.84,"id":24707172}],"tv":9325.75}]}
{"op":"mcm","clk":"994118631","pt":1580549442524,"mc":[{"id":"1.168130661","rc":[{"batb":[[0,13.5,40.63],[1,13,18.54],[2,12.5,2]],"ltp":14.0,"tv":665.84,"id":24707172}]}]}
{"op":"mcm","clk":"994119234","pt":1580549448658,"mc":[{"id":"1.168130661","rc":[{"batb":[[0,14,1.14],[1,13.5,40.63],[2,13,18.54]],"ltp":14.0,"tv":665.84,"id":24707172}]}]}
{"op":"mcm","clk":"994119729","pt":1580549453681,"mc":[{"id":"1.168130661","rc":[{"batb":[[1,13.5,41.43],[2,13,6.7]],"batl":[[0,14.5,4],[1,15,78.74],[2,15.5,5.55]],"ltp":14.0,"tv":665.84,"id":24707172}]}]}
{"op":"mcm","clk":"994119942","pt":1580549455648,"mc":[{"id":"1.168130661","rc":[{"batb":[[0,42,2.27],[1,40,2.6],[2,38,4]],"ltp":40.0,"tv":124.22,"id":25545675},{"batb":[[0,2.68,45.73]],"ltp":2.68,"tv":3335.05,"id":25238892},{"batb":[[1,13.5,48.5]],"ltp":14.0,"tv":665.84,"id":24707172},{"batb":[[0,12,9.96],[1,11.5,2.1],[2,11,8.55]],"batl":[[0,13,20.8]],"ltp":12.5,"tv":841.34,"id":24420205},{"batb":[[0,2.68,89.79]],"ltp":2.68,"tv":3691.24,"id":26314798},{"batb":[[0,11,12.74]],"ltp":11.0,"tv":668.03,"id":420}]}]}
{"op":"mcm","clk":"994120043","pt":1580549456585,"mc":[{"id":"1.168130661","rc":[{"batb":[[1,2.66,36.5]],"ltp":2.68,"tv":3335.05,"id":25238892},{"batb":[[2,2.64,39.2]],"ltp":2.68,"tv":3691.24,"id":26314798}]}]}
{"op":"mcm","clk":"994120150","pt":1580549457573,"mc":[{"id":"1.168130661","rc":[{"trd":[[2.7,762.93]],"batb":[[0,2.7,24.04],[1,2.68,105.27],[2,2.66,22.21]],"batl":[[0,2.72,340.74],[1,2.74,79.55],[2,2.76,224]],"ltp":2.7,"tv":3739.91,"id":26314798}],"tv":9374.42}]}
{"op":"mcm","clk":"994120272","pt":1580549458660,"mc":[{"id":"1.168130661","rc":[{"batb":[[1,2.68,125.42]],"ltp":2.7,"tv":3739.91,"id":26314798}]}]}
{"op":"mcm","clk":"994120374","pt":1580549459658,"mc":[{"id":"1.168130661","rc":[{"batb":[[1,2.68,128.14]],"ltp":2.7,"tv":3739.91,"id":26314798}]}]}
{"op":"mcm","clk":"994120961","pt":1580549465496,"mc":[{"id":"1.168130661","rc":[{"batb":[[0,2.68,128.14],[1,2.66,22.21],[2,2.64,39.2]],"ltp":2.7,"tv":3739.91,"id":26314798}]}]}
{"op":"mcm","clk":"994121183","pt":1580549467369,"mc":[{"id":"1.168130661","rc":[{"batb":[[0,2.68,125.42]],"ltp":2.7,"tv":3739.91,"id":26314798}]}]}
{"op":"mcm","clk":"994121277","pt":1580549468308,"mc":[{"id":"1.168130661","rc":[{"trd":[[2.7,195.6]],"batl":[[0,2.7,2.33]],"ltp":2.7,"tv":3347.85,"id":25238892},{"trd":[[11,73.56]],"batb":[[0,11,7.74]],"ltp":11.0,"tv":682.03,"id":420}],"tv":9401.22}]}
{"op":"mcm","clk":"994121366","pt":1580549469195,"mc":[{"id":"1.168130661","rc":[{"trd":[[13.5,68.67],[14,42.24]],"batb":[[0,13.5,28.84],[1,13,7.54],[2,12.5,2.91]],"ltp":13.5,"tv":705.84,"id":24707172},{"batl":[[2,2.76,226]],"ltp":2.7,"tv":3739.91,"id":26314798}],"tv":9441.22}]}
{"op":"mcm","clk":"994121704","pt":1580549472690,"mc":[{"id":"1.168130661","rc":[{"batl":[[2,15.5,2.32]],"ltp":11.0,"tv":682.03,"id":420}]}]}
{"op":"mcm","clk":"994121790","pt":1580549473509,"mc":[{"id":"1.168130661","rc":[{"batb":[[0,42,4.27]],"batl":[[0,46,10.3],[1,48,2.4],[2,50,2.1]],"ltp":40.0,"tv":124.22,"id":25545675},{"trd":[[2.7,200.26]],"batb":[[0,2.7,7.91],[1,2.68,45.73],[2,2.66,36.5]],"batl":[[0,2.72,81.34],[1,2.74,9],[2,2.76,8.07]],"ltp":2.7,"tv":3352.51,"id":25238892},{"batl":[[2,2.76,224]],"ltp":2.7,"tv":3739.91,"id":26314798},{"trd":[[11,90.94]],"batb":[[0,10.5,8.45],[1,10,15.69],[2,9.8,5]],"batl":[[0,11,4.08],[1,11.5,17.11],[2,12,7.75]],"ltp":11.0,"tv":699.4,"id":420}],"tv":9463.25}]}
{"op":"mcm","clk":"994121951","pt":1580549475072,"mc":[{"id":"1.168130661","rc":[{"batb":[[2,2.66,22.51]],"ltp":2.7,"tv":3352.51,"id":25238892},{"trd":[[11,94.94]],"batb":[[1,10,12.95]],"batl":[[0,11,2.08]],"ltp":11.0,"tv":703.4,"id":420}],"tv":9467.25}]}
{"op":"mcm","clk":"994122648","pt":1580549481687,"mc":[{"id":"1.168130661","rc":[{"batl":[[0,46,12.3]],"ltp":40.0,"tv":124.22,"id":25545675},{"trd":[[2.72,258.46]],"batb":[[0,2.7,128.91]],"batl":[[0,2.72,70.37]],"ltp":2.72,"tv":3374.45,"id":25238892},{"batl":[[0,14.5,7]],"ltp":13.5,"tv":705.84,"id":24707172}],"tv":9489.19}]}
{"op":"mcm","clk":"994122711","pt":1580549482314,"mc":[{"id":"1.168130661","rc":[{"trd":[[2.72,269.89]],"batl":[[0,2.72,64.66]],"ltp":2.72,"tv":3385.87,"id":25238892}],"tv":9500.62}]}
{"op":"mcm","clk":"994122837","pt":1580549483612,"mc":[{"id":"1.168130661","rc":[{"batl":[[1,11.5,15.73]],"ltp":11.0,"tv":703.4,"id":420}]}]}
{"op":"mcm","clk":"994123145","pt":1580549485616,"mc":[{"id":"1.168130661","rc":[{"batb":[[0,10.5,10.45]],"ltp":11.0,"tv":703.4,"id":420}]}]}
{"op":"mcm","clk":"994123765","pt":1580549491328,"mc":[{"id":"1.168130661","rc":[{"batb":[[1,2.68,56.73],[2,2.66,11.51]],"ltp":2.72,"tv":3385.87,"id":25238892},{"batl":[[1,2.74,81.55]],"ltp":2.7,"tv":3739.91,"id":26314798}]}]}
{"op":"mcm","clk":"994123889","pt":1580549492630,"mc":[{"id":"1.168130661","rc":[{"batb":[[1,2.68,70.7]],"batl":[[1,2.76,8.07],[2,2.78,8.17]],"ltp":2.72,"tv":3385.87,"id":25238892},{"batl":[[0,2.7,8],[1,2.72,340.74],[2,2.74,81.55]],"ltp":2.7,"tv":3739.91,"id":26314798}]}]}
{"op":"mcm","clk":"994124104","pt":1580549494628,"mc":[{"id":"1.168130661","rc":[{"trd":[[2.72,281.31]],"batl":[[0,2.72,58.95],[1,2.76,20.32]],"ltp":2.72,"tv":3397.3,"id":25238892},{"batb":[[0,13.5,30.84]],"ltp":13.5,"tv":705.84,"id":24707172}],"tv":9512.04}]}
{"op":"mcm","clk":"994124177","pt":1580549495447,"mc":[{"id":"1.168130661","rc":[{"batl":[[0,14.5,3]],"ltp":13.5,"tv":705.84,"id":24707172}]}]}
{"op":"mcm","clk":"994124314","pt":1580549496543,"mc":[{"id":"1.168130661","rc":[{"trd":[[2.72,302.23]],"batl":[[0,2.72,48.49]],"ltp":2.72,"tv":3418.22,"id":25238892}],"tv":9532.96}]}
{"op":"mcm","clk":"994125504","pt":1580549505571,"mc":[{"id":"1.168130661","rc":[{"batb":[[1,40,3.04]],"ltp":40.0,"tv":124.22,"id":25545675},{"trd":[[13.5,108.67]],"batb":[[0,13.5,10.84]],"ltp":13.5,"tv":745.84,"id":24707172}],"tv":9572.96}]}
{"op":"mcm","clk":"994126232","pt":1580549511586,"mc":[{"id":"1.168130661","rc":[{"batb":[[0,13.5,21.07]],"ltp":13.5,"tv":745.84,"id":24707172},{"batb":[[2,2.64,117.18]],"ltp":2.7,"tv":3739.91,"id":26314798}]}]}
{"op":"mcm","clk":"994126433","pt":1580549512684,"mc":[{"id":"1.168130661","rc":[{"trd":[[13.5,115.48]],"batb":[[0,13.5,17.67]],"ltp":13.5,"tv":752.64,"id":24707172}],"tv":9579.76}]}
{"op":"mcm","clk":"994126846","pt":1580549516680,"mc":[{"id":"1.168130661","rc":[{"batb":[[0,2.68,133.42]],"ltp":2.7,"tv":3739.91,"id":26314798}]}]}
{"op":"mcm","clk":"994127516","pt":1580549523390,"mc":[{"id":"1.168130661","rc":[{"batb":[[0,2.7,137.01]],"ltp":2.72,"tv":3418.22,"id":25238892}]}]}
{"op":"mcm","clk":"994128529","pt":1580549531706,"mc":[{"id":"1.168130661","rc":[{"batl":[[1,15,80.74]],"ltp":13.5,"tv":752.64,"id":24707172},{"batb":[[0,12.5,3.48],[1,12,9.96],[2,11.5,2.1]],"ltp":12.5,"tv":841.34,"id":24420205}]}]}
{"op":"mcm","clk":"994128636","pt":1580549532696,"mc":[{"id":"1.168130661","rc":[{"batb":[[1,40,5.25]],"ltp":40.0,"tv":124.22,"id":25545675},{"batb":[[1,2.68,72.7],[2,2.66,13.51]],"ltp":2.72,"tv":3418.22,"id":25238892},{"batb":[[0,12.5,5.48]],"ltp":12.5,"tv":841.34,"id":24420205}]}]}
{"op":"mcm","clk":"994128860","pt":1580549534574,"mc":[{"id":"1.168130661","rc":[{"batl":[[0,2.7,83.98]],"ltp":2.7,"tv":3739.91,"id":26314798}]}]}
{"op":"mcm","clk":"994129332","pt":1580549539619,"mc":[{"id":"1.168130661","rc":[{"trd":[[12.5,106.61]],"batb":[[0,12.5,2]],"ltp":12.5,"tv":852.3,"id":24420205},{"batb":[[1,2.66,26.09]],"ltp":2.7,"tv":3739.91,"id":26314798}],"tv":9590.72}]}
{"op":"mcm","clk":"994129429","pt":1580549540609,"mc":[{"id":"1.168130661","rc":[{"batb":[[0,12,9.96],[1,11.5,4.81],[2,11,8.55]],"ltp":12.5,"tv":852.3,"id":24420205}]}]}
{"op":"mcm","clk":"994130219","pt":1580549547333,"mc":[{"id":"1.168130661","rc":[{"trd":[[13.5,125.48]],"batb":[[0,13.5,12.67]],"ltp":13.5,"tv":762.64,"id":24707172}],"tv":9600.72}]}
{"op":"mcm","clk":"994130823","pt":1580549553441,"mc":[{"id":"1.168130661","rc":[{"batl":[[1,48,2.07]],"ltp":40.0,"tv":124.22,"id":25545675}]}]}
{"op":"mcm","clk":"994131692","pt":1580549561423,"mc":[{"id":"1.168130661","rc":[{"batb":[[1,11.5,2.1]],"ltp":12.5,"tv":852.3,"id":24420205},{"trd":[[2.68,760.83]],"batb":[[0,2.68,128.42]],"ltp":2.68,"tv":3749.91,"id":26314798}],"tv":9610.72}]}
{"op":"mcm","clk":"994131988","pt":1580549564454,"mc":[{"id":"1.168130661","rc":[{"trd":[[46,0.42]],"batl":[[0,46,11.99]],"ltp":46.0,"tv":124.53,"id":25545675},{"trd":[[2.72,307.49]],"batl":[[0,2.72,43.23]],"ltp":2.72,"tv":3423.48,"id":25238892},{"trd":[[13.5,151.88]],"batb":[[0,13,6.7],[1,12.5,2.91],[2,12,1.09]],"ltp":13.5,"tv":789.05,"id":24707172},{"trd":[[13,29.66]],"batl":[[0,13,19.7]],"ltp":13.0,"tv":853.4,"id":24420205},{"trd":[[2.7,768.23]],"batl":[[0,2.7,78.68]],"ltp":2.7,"tv":3755.21,"id":26314798},{"trd":[[11,97.8]],"batb":[[0,11,2.24],[1,10.5,10.45],[2,10,12.95]],"batl":[[0,11.5,13.73],[1,12,7.75],[2,14.5,17]],"ltp":11.0,"tv":706.27,"id":420}],"tv":9651.96}]}
{"op":"mcm","clk":"994132299","pt":1580549567636,"mc":[{"id":"1.168130661","rc":[{"trd":[[13,10]],"batb":[[0,13,1.7]],"ltp":13.0,"tv":799.04,"id":24707172}],"tv":9661.96}]}
{"op":"mcm","clk":"994133316","pt":1580549577673,"mc":[{"id":"1.168130661","rc":[{"batl":[[0,2.7,86.68]],"ltp":2.7,"tv":3755.21,"id":26314798}]}]}
{"op":"mcm","clk":"994133415","pt":1580549578660,"mc":[{"id":"1.168130661","rc":[{"trd":[[13.5,153.48]],"batl":[[0,13.5,3.52],[1,14,29],[2,14.5,3]],"ltp":13.5,"tv":800.64,"id":24707172},{"batb":[[0,2.68,132.42],[1,2.66,34.09]],"ltp":2.7,"tv":3755.21,"id":26314798}],"tv":9663.56}]}
{"op":"mcm","clk":"994133518","pt":1580549579653,"mc":[{"id":"1.168130661","rc":[{"trd":[[13.5,160.52]],"batb":[[0,13.5,2.67],[1,13,3.7],[2,12.5,2.91]],"batl":[[0,14,32],[1,14.5,3],[2,15,77.74]],"ltp":13.5,"tv":807.68,"id":24707172}],"tv":9670.6}]}
{"op":"mcm","clk":"994133629","pt":1580549580656,"mc":[{"id":"1.168130661","rc":[{"trd":[[2.72,393.91]],"batb":[[0,2.72,54.92],[1,2.7,137.01],[2,2.68,72.7]],"batl":[[0,2.76,12.25],[1,2.78,8.17],[2,2.8,9]],"ltp":2.72,"tv":3509.89,"id":25238892},{"batb":[[2,12.5,2]],"ltp":13.5,"tv":807.68,"id":24707172},{"trd":[[2.7,941.58]],"batb":[[0,2.7,31.17],[1,2.68,132.42],[2,2.66,34.09]],"batl":[[0,2.72,340.74],[1,2.74,81.55],[2,2.76,224]],"ltp":2.7,"tv":3928.56,"id":26314798},{"batl":[[0,11.5,15.73]],"ltp":11.0,"tv":706.27,"id":420}],"tv":9930.36}]}
{"op":"mcm","clk":"994133845","pt":1580549582643,"mc":[{"id":"1.168130661","rc":[{"batb":[[0,2.74,5.01],[1,2.72,54.92],[2,2.7,150.09]],"batl":[[0,2.84,10.01],[1,2.88,95],[2,2.9,53.18]],"ltp":2.72,"tv":3509.89,"id":25238892},{"batl":[[0,12.5,3.01],[1,13,19.7],[2,13.5,2]],"ltp":13.0,"tv":853.4,"id":24420205},{"batb":[[1,2.68,142.13]],"ltp":2.7,"tv":3928.56,"id":26314798},{"batl":[[2,14.5,17.84]],"ltp":11.0,"tv":706.27,"id":420}]}]}
{"op":"mcm","clk":"994133981","pt":1580549583697,"mc":[{"id":"1.168130661","rc":[{"batb":[[2,2.7,137.01]],"batl":[[0,2.82,3.8],[1,2.84,4.48],[2,2.86,8.01]],"ltp":2.72,"tv":3509.89,"id":25238892},{"batl":[[2,14.5,17]],"ltp":11.0,"tv":706.27,"id":420}]}]}
{"op":"mcm","clk":"994134025","pt":1580549584070,"mc":[{"id":"1.168130661","rc":[{"batl":[[2,2.86,10.01]],"ltp":2.72,"tv":3509.89,"id":25238892}]}]}
{"op":"mcm","clk":"994134184","pt":1580549585380,"mc":[{"id":"1.168130661","rc":[{"batl":[[0,2.86,8.01],[1,2.88,93],[2,2.9,55.18]],"ltp":2.72,"tv":3509.89,"id":25238892}]}]}
{"op":"mcm","clk":"994134293","pt":1580549586575,"mc":[{"id":"1.168130661","rc":[{"batb":[[1,40,4.82]],"ltp":46.0,"tv":124.53,"id":25545675}]}]}
{"op":"mcm","clk":"994134320","pt":1580549587215,"mc":[{"id":"1.168130661","rc":[{"batb":[[0,42,4.67]],"ltp":46.0,"tv":124.53,"id":25545675}]}]}
{"op":"mcm","clk":"994134635","pt":1580549589705,"mc":[{"id":"1.168130661","rc":[{"batb":[[0,2.72,5],[1,2.7,137.01],[2,2.68,53.73]],"batl":[[0,2.86,18.59],[2,2.9,53.18]],"ltp":2.72,"tv":3509.89,"id":25238892},{"batb":[[0,2.68,129.13],[1,2.66,34.09],[2,2.64,117.18]],"batl":[[0,2.72,343.74]],"ltp":2.7,"tv":3928.56,"id":26314798}]}]}
{"op":"mcm","clk":"994134745","pt":1580549590698,"mc":[{"id":"1.168130661","rc":[{"trd":[[42,0.02],[44,6.35]],"batb":[[0,42,4.26]],"ltp":42.0,"tv":124.94,"id":25545675},{"trd":[[2.82,132.19]],"batl":[[0,2.86,28.54]],"ltp":2.82,"tv":3516.3,"id":25238892},{"trd":[[13.5,161.86]],"batb":[[0,13,1.7],[1,12.5,4.91],[2,11.5,1.19]],"batl":[[0,13.5,3.05],[1,14,32],[2,14.5,3]],"ltp":13.5,"tv":809.02,"id":24707172},{"trd":[[12,116.03]],"batb":[[0,12,8.45]],"ltp":12.0,"tv":854.91,"id":24420205},{"trd":[[2.68,767.57]],"batb":[[0,2.68,122.39]],"ltp":2.68,"tv":3935.3,"id":26314798},{"trd":[[11,99.44]],"batb":[[0,11,2.05],[1,10.5,8.45],[2,10,10.95]],"ltp":11.0,"tv":707.91,"id":420}],"tv":9948.41}]}
{"op":"mcm","clk":"994134847","pt":1580549591687,"mc":[{"id":"1.168130661","rc":[{"batl":[[0,2.82,8.06],[1,2.84,1.07],[2,2.86,28.54]],"ltp":2.82,"tv":3516.3,"id":25238892},{"batb":[[0,2.68,112.68]],"ltp":2.68,"tv":3935.3,"id":26314798}]}]}
{"op":"mcm","clk":"994135106","pt":1580549594302,"mc":[{"id":"1.168130661","rc":[{"batl":[[2,15.5,2.32]],"ltp":11.0,"tv":707.91,"id":420}]}]}
{"op":"mcm","clk":"994135314","pt":1580549596592,"mc":[{"id":"1.168130661","rc":[{"batl":[[2,2.86,18.59]],"ltp":2.82,"tv":3516.3,"id":25238892}]}]}
{"op":"mcm","clk":"994136180","pt":1580549604622,"mc":[{"id":"1.168130661","rc":[{"batl":[[0,2.84,9.2],[1,2.86,18.59],[2,2.88,6]],"ltp":2.82,"tv":3516.3,"id":25238892},{"batl":[[0,2.7,8],[1,2.72,343.74],[2,2.74,81.55]],"ltp":2.68,"tv":3935.3,"id":26314798},{"batb":[[0,10.5,10.45],[1,10,10.95],[2,9.8,5]],"ltp":11.0,"tv":707.91,"id":420}]}]}
{"op":"mcm","clk":"994136306","pt":1580549605719,"mc":[{"id":"1.168130661","rc":[{"batb":[[0,2.68,120.68]],"ltp":2.68,"tv":3935.3,"id":26314798}]}]}
{"op":"mcm","clk":"994137680","pt":1580549620718,"mc":[{"id":"1.168130661","rc":[{"batl":[[2,2.88,15.88]],"ltp":2.82,"tv":3516.3,"id":25238892}]}]}
{"op":"mcm","clk":"994138012","pt":1580549624336,"mc":[{"id":"1.168130661","rc":[{"batl":[[0,2.82,2.98],[1,2.84,9.2],[2,2.86,18.59]],"ltp":2.82,"tv":3516.3,"id":25238892}]}]}
{"op":"mcm","clk":"994139233","pt":1580549637868,"mc":[{"id":"1.168130661","rc":[{"batb":[[1,2.7,148.01],[2,2.68,42.73]],"ltp":2.82,"tv":3516.3,"id":25238892}]}]}
{"op":"mcm","clk":"994139910","pt":1580549644661,"mc":[{"id":"1.168130661","rc":[{"batb":[[0,2.76,5.02],[1,2.74,20.11],[2,2.72,5]],"batl":[[1,2.84,11.2]],"ltp":2.82,"tv":3516.3,"id":25238892},{"batl":[[0,13.5,31.05]],"ltp":13.5,"tv":809.02,"id":24707172}]}]}
{"op":"mcm","clk":"994140247","pt":1580549648362,"mc":[{"id":"1.168130661","rc":[{"batb":[[0,2.72,5],[1,2.7,146.29],[2,2.68,42.73]],"batl":[[1,2.84,9.2]],"ltp":2.82,"tv":3516.3,"id":25238892}]}]}
{"op":"mcm","clk":"994140421","pt":1580549650662,"mc":[{"id":"1.168130661","rc":[{"batb":[[1,2.7,144.01]],"ltp":2.82,"tv":3516.3,"id":25238892},{"trd":[[12.5,4.6],[13,13.4]],"batb":[[0,12,2.15],[1,11.5,1.09],[2,10.5,4.69]],"ltp":12.5,"tv":817.02,"id":24707172},{"batb":[[0,2.68,133.68]],"batl":[[1,2.72,340.74]],"ltp":2.68,"tv":3935.3,"id":26314798}],"tv":9956.41}]}
{"op":"mcm","clk":"994140685","pt":1580549653464,"mc":[{"id":"1.168130661","rc":[{"batl":[[1,14,3]],"ltp":12.5,"tv":817.02,"id":24707172}]}]}
{"op":"mcm","clk":"994140912","pt":1580549655682,"mc":[{"id":"1.168130661","rc":[{"batl":[[0,2.8,1.08],[1,2.82,2.98],[2,2.84,8.13]],"ltp":2.82,"tv":3516.3,"id":25238892},{"trd":[[2.7,945.58]],"batl":[[0,2.7,6]],"ltp":2.7,"tv":3939.3,"id":26314798}],"tv":9960.41}]}
{"op":"mcm","clk":"994141006","pt":1580549656671,"mc":[{"id":"1.168130661","rc":[{"batb":[[2,10.5,3.9]],"ltp":12.5,"tv":817.02,"id":24707172}]}]}
{"op":"mcm","clk":"994141583","pt":1580549662685,"mc":[{"id":"1.168130661","rc":[{"trd":[[12.5,6.42]],"batl":[[0,12.5,2.21],[1,13,30],[2,13.5,31.05]],"ltp":12.5,"tv":818.84,"id":24707172}],"tv":9962.23}]}
{"op":"mcm","clk":"994141664","pt":1580549663667,"mc":[{"id":"1.168130661","rc":[{"trd":[[12.5,10.84],[13,22.62]],"batb":[[0,11,2.22],[1,10,16.42],[2,9.4,27]],"batl":[[0,13,28.39],[1,13.5,31.05],[2,15,77.74]],"ltp":13.0,"tv":832.48,"id":24707172},{"batl":[[0,13,19.7],[1,13.5,2],[2,14,2.36]],"ltp":12.0,"tv":854.91,"id":24420205},{"trd":[[2.7,957.58]],"batb":[[0,2.7,7.12],[1,2.68,133.68],[2,2.66,34.09]],"batl":[[0,2.72,340.74],[1,2.74,79.55],[2,2.76,227]],"ltp":2.7,"tv":3951.3,"id":26314798},{"batb":[[0,11,2.12],[1,10.5,10.45],[2,10,10.95]],"ltp":11.0,"tv":707.91,"id":420}],"tv":9987.87}]}
{"op":"mcm","clk":"994141771","pt":1580549664655,"mc":[{"id":"1.168130661","rc":[{"batb":[[0,42,5.31]],"ltp":42.0,"tv":124.94,"id":25545675},{"batb":[[0,2.78,14.06],[1,2.76,5.13],[2,2.74,5.13]],"batl":[[0,2.8,3.08]],"ltp":2.82,"tv":3516.3,"id":25238892},{"batb":[[0,11,4.51]],"ltp":13.0,"tv":832.48,"id":24707172},{"batb":[[0,12,10.55]],"ltp":12.0,"tv":854.91,"id":24420205},{"batb":[[0,2.7,13],[1,2.68,143.08]],"ltp":2.7,"tv":3951.3,"id":26314798},{"batb":[[1,10.5,12.85]],"batl":[[0,11.5,13.73]],"ltp":11.0,"tv":707.91,"id":420}]}]}
{"op":"mcm","clk":"994141857","pt":1580549665692,"mc":[{"id":"1.168130661","rc":[{"batb":[[0,2.68,143.08],[1,2.66,34.09],[2,2.64,117.18]],"ltp":2.7,"tv":3951.3,"id":26314798}]}]}
{"op":"mcm","clk":"994141994","pt":1580549666680,"mc":[{"id":"1.168130661","rc":[{"batb":[[1,2.76,9.97]],"ltp":2.82,"tv":3516.3,"id":25238892},{"batb":[[1,10,17.54]],"batl":[[0,12.5,3.14],[1,13,28.39],[2,13.5,31.05]],"ltp":13.0,"tv":832.48,"id":24707172},{"batb":[[1,2.66,26.39]],"batl":[[1,2.74,82.55]],"ltp":2.7,"tv":3951.3,"id":26314798}]}]}
{"op":"mcm","clk":"994142106","pt":1580549667713,"mc":[{"id":"1.168130661","rc":[{"trd":[[2.8,180.57]],"batb":[[0,2.8,3.71],[1,2.78,14.06],[2,2.76,9.97]],"batl":[[0,2.82,2.98],[1,2.84,8.13],[2,2.86,8.01]],"ltp":2.8,"tv":3522.47,"id":25238892},{"batb":[[1,2.66,34.99]],"ltp":2.7,"tv":3951.3,"id":26314798}],"tv":9994.03}]}
{"op":"mcm","clk":"994142282","pt":1580549669674,"mc":[{"id":"1.168130661","rc":[{"trd":[[2.82,142.19]],"batb":[[0,2.8,8.87],[2,2.76,5.13]],"batl":[[0,2.82,8.67],[1,2.84,2]],"ltp":2.82,"tv":3532.47,"id":25238892}],"tv":10004.03}]}
{"op":"mcm","clk":"994142576","pt":1580549672621,"mc":[{"id":"1.168130661","rc":[{"batb":[[0,11.5,1.49],[1,11,4.41],[2,10.5,1.32]],"ltp":13.0,"tv":832.48,"id":24707172}]}]}
{"op":"mcm","clk":"994142855","pt":1580549675316,"mc":[{"id":"1.168130661","rc":[{"trd":[[2.72,286.93]],"batl":[[0,2.72,335.74]],"ltp":2.72,"tv":3961.3,"id":26314798}],"tv":10014.03}]}
{"op":"mcm","clk":"994143000","pt":1580549676715,"mc":[{"id":"1.168130661","rc":[{"batl":[[0,46,9.99]],"ltp":42.0,"tv":124.94,"id":25545675},{"trd":[[11,8.82],[11.5,2.78],[12,0.2]],"batb":[[0,10.5,9.61],[1,10,22.97],[2,9.4,27]],"batl":[[0,11,14.1],[1,11.5,3.2],[2,12.5,3.14]],"ltp":11.0,"tv":844.28,"id":24707172},{"batl":[[1,2.74,79.55]],"ltp":2.72,"tv":3961.3,"id":26314798}],"tv":10025.83}]}
{"op":"mcm","clk":"994143172","pt":1580549678417,"mc":[{"id":"1.168130661","rc":[{"batb":[[1,10,18.42]],"ltp":11.0,"tv":844.28,"id":24707172}]}]}
{"op":"mcm","clk":"994143308","pt":1580549679707,"mc":[{"id":"1.168130661","rc":[{"batl":[[0,11.5,3.2],[1,12.5,3.14],[2,13,25.39]],"ltp":11.0,"tv":844.28,"id":24707172}]}]}
{"op":"mcm","clk":"994143404","pt":1580549680695,"mc":[{"id":"1.168130661","rc":[{"batl":[[0,12.5,3.14],[1,13,25.39],[2,13.5,28]],"ltp":11.0,"tv":844.28,"id":24707172},{"batl":[[1,2.74,82.55]],"ltp":2.72,"tv":3961.3,"id":26314798}]}]}
{"op":"mcm","clk":"994143702","pt":1580549683701,"mc":[{"id":"1.168130661","rc":[{"batb":[[0,2.8,3.71]],"ltp":2.82,"tv":3532.47,"id":25238892},{"batb":[[0,11.5,2.23],[1,11,13.3],[2,10.5,2.2]],"ltp":11.0,"tv":844.28,"id":24707172},{"batb":[[0,2.68,130.08]],"batl":[[0,2.72,445.74]],"ltp":2.72,"tv":3961.3,"id":26314798}]}]}
{"op":"mcm","clk":"994143907","pt":1580549685714,"mc":[{"id":"1.168130661","rc":[{"trd":[[46,0.94]],"batl":[[0,46,9.47]],"ltp":46.0,"tv":125.46,"id":25545675},{"trd":[[2.82,151.12]],"batl":[[0,2.86,8.01],[1,2.88,8],[2,2.9,53.18]],"ltp":2.82,"tv":3541.4,"id":25238892},{"trd":[[10.5,6.66],[11,35.42],[11.5,7.24]],"batb":[[0,10.5,2.25],[1,10,20.65],[2,9.2,27.54]],"batl":[[0,13,29.39],[1,13.5,28],[2,15,77.74]],"ltp":10.5,"tv":882.0,"id":24707172},{"trd":[[13,31.48]],"batl":[[0,13,17.88]],"ltp":13.0,"tv":856.73,"id":24420205},{"trd":[[2.72,295.65]],"batl":[[0,2.72,437.02]],"ltp":2.72,"tv":3970.02,"id":26314798},{"trd":[[11.5,22.23]],"batl":[[0,11.5,13.66]],"ltp":11.5,"tv":709.98,"id":420}],"tv":10085.61}]}
{"op":"mcm","clk":"994143993","pt":1580549686544,"mc":[{"id":"1.168130661","rc":[{"batb":[[0,2.8,5.71]],"ltp":2.82,"tv":3541.4,"id":25238892}]}]}
{"op":"mcm","clk":"994144172","pt":1580549688718,"mc":[{"id":"1.168130661","rc":[{"batb":[[2,9.8,5.73]],"batl":[[0,12.5,8.5],[1,13,29.39],[2,13.5,28]],"ltp":10.5,"tv":882.0,"id":24707172}]}]}
{"op":"mcm","clk":"994144539","pt":1580549692703,"mc":[{"id":"1.168130661","rc":[{"batl":[[0,12,4],[1,12.5,8.5],[2,13,29.39]],"ltp":10.5,"tv":882.0,"id":24707172},{"batl":[[0,2.72,442.02]],"ltp":2.72,"tv":3970.02,"id":26314798},{"batl":[[0,11.5,11.66]],"ltp":11.5,"tv":709.98,"id":420}]}]}
{"op":"mcm","clk":"994144565","pt":1580549692913,"mc":[{"id":"1.168130661","rc":[{"batb":[[1,2.66,39.99]],"ltp":2.72,"tv":3970.02,"id":26314798}]}]}
{"op":"mcm","clk":"994144860","pt":1580549695714,"mc":[{"id":"1.168130661","rc":[{"batb":[[0,10.5,3.76]],"ltp":10.5,"tv":882.0,"id":24707172}]}]}
{"op":"mcm","clk":"994145434","pt":1580549701534,"mc":[{"id":"1.168130661","rc":[{"batl":[[0,12,8]],"ltp":10.5,"tv":882.0,"id":24707172},{"trd":[[12,129.2]],"batb":[[0,12,3.96]],"ltp":12.0,"tv":869.9,"id":24420205},{"trd":[[2.72,335.65]],"batl":[[0,2.72,422.02]],"ltp":2.72,"tv":4010.02,"id":26314798}],"tv":10138.79}]}
{"op":"mcm","clk":"994145921","pt":1580549705630,"mc":[{"id":"1.168130661","rc":[{"batb":[[0,2.8,10.71]],"ltp":2.82,"tv":3541.4,"id":25238892},{"batb":[[1,2.66,44.99]],"batl":[[0,2.72,427.02]],"ltp":2.72,"tv":4010.02,"id":26314798}]}]}
{"op":"mcm","clk":"994146024","pt":1580549706555,"mc":[{"id":"1.168130661","rc":[{"batl":[[0,12,4]],"ltp":10.5,"tv":882.0,"id":24707172}]}]}
{"op":"mcm","clk":"994146263","pt":1580549708638,"mc":[{"id":"1.168130661","rc":[{"trd":[[2.72,345.65]],"batl":[[0,2.72,422.02]],"ltp":2.72,"tv":4020.02,"id":26314798}],"tv":10148.79}]}
{"op":"mcm","clk":"994146470","pt":1580549710669,"mc":[{"id":"1.168130661","rc":[{"trd":[[12,8.2],[12.5,22.84]],"batl":[[0,12.5,2.5],[1,13,29.39],[2,13.5,28]],"ltp":12.5,"tv":902.0,"id":24707172}],"tv":10168.78}]}
{"op":"mcm","clk":"994147023","pt":1580549715654,"mc":[{"id":"1.168130661","rc":[{"batb":[[1,2.78,17.8]],"ltp":2.82,"tv":3541.4,"id":25238892}]}]}
{"op":"mcm","clk":"994147118","pt":1580549716537,"mc":[{"id":"1.168130661","rc":[{"batb":[[0,10.5,8.33]],"ltp":12.5,"tv":902.0,"id":24707172}]}]}
{"op":"mcm","clk":"994147666","pt":1580549721485,"mc":[{"id":"1.168130661","rc":[{"batl":[[0,2.88,13],[1,2.9,55.18],[2,2.94,6]],"ltp":2.82,"tv":3541.4,"id":25238892},{"batl":[[0,11.5,50],[1,12.5,2.5],[2,13,29.39]],"ltp":12.5,"tv":902.0,"id":24707172},{"batb":[[0,2.68,143.08]],"ltp":2.72,"tv":4020.02,"id":26314798}]}]}
{"op":"mcm","clk":"994147875","pt":1580549723664,"mc":[{"id":"1.168130661","rc":[{"batl":[[0,2.86,2],[1,2.88,15],[2,2.9,55.18]],"ltp":2.82,"tv":3541.4,"id":25238892}]}]}
{"op":"mcm","clk":"994148448","pt":1580549729501,"mc":[{"id":"1.168130661","rc":[{"batb":[[0,2.82,48.15],[1,2.8,10.71],[2,2.78,17.8]],"batl":[[0,2.86,4]],"ltp":2.82,"tv":3541.4,"id":25238892},{"trd":[[11,45.56]],"batb":[[1,10,22.65]],"batl":[[0,11,44.93]],"ltp":11.0,"tv":912.14,"id":24707172}],"tv":10178.92}]}
{"op":"mcm","clk":"994148562","pt":1580549730697,"mc":[{"id":"1.168130661","rc":[{"batb":[[0,2.84,10.73],[1,2.82,53.15],[2,2.8,23.75]],"batl":[[1,2.88,8],[2,2.9,62.18]],"ltp":2.82,"tv":3541.4,"id":25238892},{"trd":[[11,86.53]],"batl":[[0,11,24.44],[1,11.5,4.16],[2,12.5,2.5]],"ltp":11.0,"tv":953.1,"id":24707172}],"tv":10219.89}]}
{"op":"mcm","clk":"994148682","pt":1580549732114,"mc":[{"id":"1.168130661","rc":[{"batb":[[1,2.82,56.48],[2,2.8,10.71]],"ltp":2.82,"tv":3541.4,"id":25238892}]}]}
{"op":"mcm","clk":"994148818","pt":1580549733412,"mc":[{"id":"1.168130661","rc":[{"trd":[[2.86,175.23]],"batb":[[0,2.84,15.73],[2,2.8,7]],"batl":[[0,2.88,6],[1,2.9,62.18],[2,2.98,6]],"ltp":2.86,"tv":3549.4,"id":25238892}],"tv":10227.89}]}
{"op":"mcm","clk":"994149251","pt":1580549737529,"mc":[{"id":"1.168130661","rc":[{"batb":[[1,2.82,8.33]],"ltp":2.86,"tv":3549.4,"id":25238892}]}]}
{"op":"mcm","clk":"994149349","pt":1580549738625,"mc":[{"id":"1.168130661","rc":[{"batb":[[2,2.8,9]],"ltp":2.86,"tv":3549.4,"id":25238892}]}]}
{"op":"mcm","clk":"994150309","pt":1580549747711,"mc":[{"id":"1.168130661","rc":[{"batl":[[2,3,10.19]],"ltp":2.86,"tv":3549.4,"id":25238892}]}]}
{"op":"mcm","clk":"994150593","pt":1580549750706,"mc":[{"id":"1.168130661","rc":[{"trd":[[11,103.44]],"batb":[[0,10.5,12.97],[1,10,10.95],[2,9.8,5]],"ltp":11.0,"tv":713.98,"id":420}],"tv":10231.89}]}
{"op":"mcm","clk":"994150672","pt":1580549751638,"mc":[{"id":"1.168130661","rc":[{"batb":[[2,8.8,28.54]],"ltp":11.0,"tv":953.1,"id":24707172}]}]}
{"op":"mcm","clk":"994150772","pt":1580549752618,"mc":[{"id":"1.168130661","rc":[{"trd":[[11,96.75]],"batl":[[0,11,19.33]],"ltp":11.0,"tv":963.32,"id":24707172}],"tv":10242.11}]}
{"op":"mcm","clk":"994151011","pt":1580549755529,"mc":[{"id":"1.168130661","rc":[{"batb":[[1,10,21.68]],"ltp":11.0,"tv":963.32,"id":24707172}]}]}
{"op":"mcm","clk":"994151710","pt":1580549762665,"mc":[{"id":"1.168130661","rc":[{"batb":[[2,9.6,14.87]],"ltp":11.0,"tv":963.32,"id":24707172}]}]}
{"op":"mcm","clk":"994152331","pt":1580549769178,"mc":[{"id":"1.168130661","rc":[{"batl":[[2,12.5,2.6]],"ltp":11.0,"tv":963.32,"id":24707172}]}]}
{"op":"mcm","clk":"994154568","pt":1580549792693,"mc":[{"id":"1.168130661","rc":[{"trd":[[10.5,10.66]],"batb":[[0,10.5,6.33]],"ltp":10.5,"tv":967.32,"id":24707172}],"tv":10246.11}]}
{"op":"mcm","clk":"994155044","pt":1580549797679,"mc":[{"id":"1.168130661","rc":[{"batb":[[0,2.7,6.38],[1,2.68,143.08],[2,2.66,44.99]],"ltp":2.72,"tv":4020.02,"id":26314798}]}]}
{"op":"mcm","clk":"994155151","pt":1580549798719,"mc":[{"id":"1.168130661","rc":[{"batl":[[0,2.88,8]],"ltp":2.86,"tv":3549.4,"id":25238892},{"batb":[[0,10.5,8.33]],"ltp":10.5,"tv":967.32,"id":24707172},{"batl":[[1,2.74,79.55]],"ltp":2.72,"tv":4020.02,"id":26314798},{"batb":[[0,11,2.12],[1,10.5,12.85],[2,10,10.95]],"ltp":11.0,"tv":713.98,"id":420}]}]}
{"op":"mcm","clk":"994155321","pt":1580549799707,"mc":[{"id":"1.168130661","rc":[{"batb":[[2,2.66,36.39]],"ltp":2.72,"tv":4020.02,"id":26314798}]}]}
{"op":"mcm","clk":"994156331","pt":1580549806505,"mc":[{"id":"1.168130661","rc":[{"batl":[[0,2.88,6]],"ltp":2.86,"tv":3549.4,"id":25238892},{"trd":[[2.7,970.34]],"batb":[[0,2.68,143.08],[1,2.66,36.39],[2,2.64,117.18]],"batl":[[0,2.7,1.62],[1,2.72,422.02],[2,2.74,82.55]],"ltp":2.7,"tv":4032.78,"id":26314798}],"tv":10258.86}]}
{"op":"mcm","clk":"994156474","pt":1580549807640,"mc":[{"id":"1.168130661","rc":[{"batb":[[0,2.68,151.08]],"ltp":2.7,"tv":4032.78,"id":26314798}]}]}
{"op":"mcm","clk":"994156654","pt":1580549809615,"mc":[{"id":"1.168130661","rc":[{"batl":[[0,2.7,52.27]],"ltp":2.7,"tv":4032.78,"id":26314798}]}]}
{"op":"mcm","clk":"994156756","pt":1580549810700,"mc":[{"id":"1.168130661","rc":[{"batb":[[1,2.66,44.99]],"ltp":2.7,"tv":4032.78,"id":26314798}]}]}
{"op":"mcm","clk":"994156807","pt":1580549811112,"mc":[{"id":"1.168130661","rc":[{"trd":[[2.7,974.34]],"batl":[[0,2.7,50.27]],"ltp":2.7,"tv":4036.78,"id":26314798}],"tv":10262.86}]}
{"op":"mcm","clk":"994156933","pt":1580549812626,"mc":[{"id":"1.168130661","rc":[{"batl":[[2,12.5,3.51]],"ltp":10.5,"tv":967.32,"id":24707172}]}]}
{"op":"mcm","clk":"994157131","pt":1580549814648,"mc":[{"id":"1.168130661","rc":[{"trd":[[2.7,1036.68]],"batl":[[0,2.7,19.1]],"ltp":2.7,"tv":4099.12,"id":26314798}],"tv":10325.2}]}
{"op":"mcm","clk":"994157209","pt":1580549815533,"mc":[{"id":"1.168130661","rc":[{"batb":[[2,38,2]],"ltp":46.0,"tv":125.46,"id":25545675}]}]}
{"op":"mcm","clk":"994157322","pt":1580549816625,"mc":[{"id":"1.168130661","rc":[{"trd":[[2.88,129.67]],"batb":[[0,2.88,100],[1,2.84,15.73],[2,2.82,8.33]],"batl":[[0,2.9,62.18],[1,3,10.19],[2,3.15,6]],"ltp":2.88,"tv":3561.4,"id":25238892},{"trd":[[10.5,26.66]],"batb":[[0,10,22.01],[1,9.6,14.87],[2,8.8,28.54]],"batl":[[2,12.5,2.6]],"ltp":10.5,"tv":983.33,"id":24707172}],"tv":10353.21}]}
{"op":"mcm","clk":"994157422","pt":1580549817714,"mc":[{"id":"1.168130661","rc":[{"batl":[[0,46,11.47]],"ltp":46.0,"tv":125.46,"id":25545675},{"trd":[[2.88,329.67]],"batb":[[0,2.84,5],[1,2.82,8.33],[2,2.8,9]],"batl":[[0,2.9,60.18],[1,2.92,7.31],[2,2.94,7.31]],"ltp":2.88,"tv":3761.4,"id":25238892},{"trd":[[10.5,31.32]],"batb":[[0,10,19.68],[1,9.8,4.13],[2,9.6,14.87]],"ltp":10.5,"tv":987.99,"id":24707172},{"batl":[[0,12.5,3.31],[1,13,17.88],[2,13.5,2]],"ltp":12.0,"tv":869.9,"id":24420205}],"tv":10557.87}]}
{"op":"mcm","clk":"994157493","pt":1580549818643,"mc":[{"id":"1.168130661","rc":[{"batb":[[0,2.86,11],[1,2.84,5],[2,2.82,5]],"batl":[[0,2.9,53.18]],"ltp":2.88,"tv":3761.4,"id":25238892},{"batb":[[1,9.8,11.14]],"ltp":10.5,"tv":987.99,"id":24707172}]}]}
{"op":"mcm","clk":"994157681","pt":1580549820719,"mc":[{"id":"1.168130661","rc":[{"batb":[[1,2.84,8.83]],"batl":[[0,2.9,59.18]],"ltp":2.88,"tv":3761.4,"id":25238892}]}]}
{"op":"mcm","clk":"994159128","pt":1580549835649,"mc":[{"id":"1.168130661","rc":[{"batb":[[0,2.86,6]],"ltp":2.88,"tv":3761.4,"id":25238892}]}]}
{"op":"mcm","clk":"994159318","pt":1580549837573,"mc":[{"id":"1.168130661","rc":[{"trd":[[2.9,139.9]],"batl":[[0,2.9,6.18]],"ltp":2.9,"tv":3867.4,"id":25238892}],"tv":10663.87}]}
{"op":"mcm","clk":"994159511","pt":1580549839658,"mc":[{"id":"1.168130661","rc":[{"trd":[[2.9,140.26]],"batb":[[0,2.86,11],[1,2.84,5]],"batl":[[0,2.92,7.31],[1,2.94,7.31],[2,3,10.19]],"ltp":2.9,"tv":3867.76,"id":25238892}],"tv":10664.23}]}
{"op":"mcm","clk":"994159606","pt":1580549840641,"mc":[{"id":"1.168130661","rc":[{"batl":[[0,2.98,6.1],[1,3,10.19],[2,3.1,81]],"ltp":2.9,"tv":3867.76,"id":25238892},{"batb":[[0,12,2.1]],"ltp":12.0,"tv":869.9,"id":24420205},{"batb":[[0,2.68,138.08]],"batl":[[1,2.72,425.02]],"ltp":2.7,"tv":4099.12,"id":26314798}]}]}
{"op":"mcm","clk":"994159681","pt":1580549841686,"mc":[{"id":"1.168130661","rc":[{"batb":[[1,2.84,8.83]],"batl":[[1,3,14.5],[2,3.05,9.33]],"ltp":2.9,"tv":3867.76,"id":25238892},{"batb":[[0,12,4.1]],"ltp":12.0,"tv":869.9,"id":24420205},{"batb":[[0,2.68,151.08]],"batl":[[1,2.72,422.02]],"ltp":2.7,"tv":4099.12,"id":26314798}]}]}
{"op":"mcm","clk":"994159774","pt":1580549842570,"mc":[{"id":"1.168130661","rc":[{"batl":[[1,3,10.19]],"ltp":2.9,"tv":3867.76,"id":25238892},{"batl":[[0,10.5,10],[1,11,23.33],[2,11.5,4.16]],"ltp":10.5,"tv":987.99,"id":24707172}]}]}
{"op":"mcm","clk":"994159919","pt":1580549843655,"mc":[{"id":"1.168130661","rc":[{"trd":[[2.68,1069.71]],"batb":[[0,2.66,44.99],[1,2.64,117.18],[2,2.62,14]],"batl":[[0,2.68,21.98],[1,2.7,19.1],[2,2.72,422.02]],"ltp":2.68,"tv":4401.25,"id":26314798}],"tv":10966.36}]}
{"op":"mcm","clk":"994159985","pt":1580549844583,"mc":[{"id":"1.168130661","rc":[{"batl":[[0,46,9.47]],"ltp":46.0,"tv":125.46,"id":25545675},{"batl":[[0,13,17.88],[1,13.5,2],[2,14,2.36]],"ltp":12.0,"tv":869.9,"id":24420205},{"batb":[[1,2.64,141.26],[2,2.62,32]],"batl":[[2,2.72,425.02]],"ltp":2.68,"tv":4401.25,"id":26314798}]}]}
{"op":"mcm","clk":"994160063","pt":1580549845367,"mc":[{"id":"1.168130661","rc":[{"batb":[[0,2.66,31]],"ltp":2.68,"tv":4401.25,"id":26314798}]}]}
{"op":"mcm","clk":"994160215","pt":1580549847394,"mc":[{"id":"1.168130661","rc":[{"batb":[[1,2.64,127.59]],"ltp":2.68,"tv":4401.25,"id":26314798}]}]}
{"op":"mcm","clk":"994160332","pt":1580549848695,"mc":[{"id":"1.168130661","rc":[{"batl":[[0,2.68,26.98]],"ltp":2.68,"tv":4401.25,"id":26314798}]}]}
{"op":"mcm","clk":"994160422","pt":1580549849679,"mc":[{"id":"1.168130661","rc":[{"batl":[[0,2.96,4.39],[1,2.98,6.1],[2,3,10.19]],"ltp":2.9,"tv":3867.76,"id":25238892},{"batb":[[2,2.62,37]],"ltp":2.68,"tv":4401.25,"id":26314798}]}]}
{"op":"mcm","clk":"994160590","pt":1580549851399,"mc":[{"id":"1.168130661","rc":[{"trd":[[2.68,1079.71]],"batl":[[0,2.68,21.98]],"ltp":2.68,"tv":4411.25,"id":26314798}],"tv":10976.36}]}
{"op":"mcm","clk":"994171126","pt":1580549853574,"mc":[{"id":"1.168130661","rc":[{"trd":[[10,12.06]],"batb":[[0,10,13.65]],"ltp":10.0,"tv":1000.04,"id":24707172},{"trd":[[2.68,1089.71]],"batl":[[0,2.68,16.98]],"ltp":2.68,"tv":4421.25,"id":26314798}],"tv":10998.42}]}
{"op":"mcm","clk":"994171236","pt":1580549854696,"mc":[{"id":"1.168130661","rc":[{"batb":[[0,2.9,3],[1,2.86,11],[2,2.84,8.83]],"ltp":2.9,"tv":3867.76,"id":25238892},{"batb":[[2,2.62,42]],"batl":[[0,2.68,21.98]],"ltp":2.68,"tv":4421.25,"id":26314798}]}]}
{"op":"mcm","clk":"994171315","pt":1580549855689,"mc":[{"id":"1.168130661","rc":[{"batb":[[0,2.9,8.19],[2,2.84,3.83]],"ltp":2.9,"tv":3867.76,"id":25238892}]}]}
{"op":"mcm","clk":"994171404","pt":1580549856576,"mc":[{"id":"1.168130661","rc":[{"trd":[[10,22.06]],"batb":[[0,10,12.85]],"ltp":10.0,"tv":1010.04,"id":24707172},{"batl":[[0,12.5,2.19],[1,13,17.88],[2,13.5,2]],"ltp":12.0,"tv":869.9,"id":24420205},{"batb":[[0,2.66,78.05]],"ltp":2.68,"tv":4421.25,"id":26314798},{"batb":[[0,11,6.32]],"ltp":11.0,"tv":713.98,"id":420}],"tv":11008.42}]}
{"op":"mcm","clk":"994171435","pt":1580549856886,"mc":[{"id":"1.168130661","rc":[{"batb":[[1,9.8,4.13]],"ltp":10.0,"tv":1010.04,"id":24707172}]}]}
{"op":"mcm","clk":"994171586","pt":1580549858704,"mc":[{"id":"1.168130661","rc":[{"batb":[[1,2.64,131.19]],"ltp":2.68,"tv":4421.25,"id":26314798}]}]}
{"op":"mcm","clk":"994171614","pt":1580549858970,"mc":[{"id":"1.168130661","rc":[{"batb":[[2,2.62,47]],"batl":[[0,2.68,26.98]],"ltp":2.68,"tv":4421.25,"id":26314798}]}]}
{"op":"mcm","clk":"994171863","pt":1580549861672,"mc":[{"id":"1.168130661","rc":[{"batb":[[0,2.9,10.19]],"ltp":2.9,"tv":3867.76,"id":25238892}]}]}
{"op":"mcm","clk":"994171947","pt":1580549862707,"mc":[{"id":"1.168130661","rc":[{"batb":[[0,2.92,8.59],[1,2.9,10.19],[2,2.86,11]],"ltp":2.9,"tv":3867.76,"id":25238892},{"batl":[[1,11,25.33]],"ltp":10.0,"tv":1010.04,"id":24707172}]}]}
{"op":"mcm","clk":"994172046","pt":1580549863698,"mc":[{"id":"1.168130661","rc":[{"batl":[[0,46,11.47]],"ltp":46.0,"tv":125.46,"id":25545675},{"batb":[[0,2.94,6],[1,2.92,8.59],[2,2.9,10.19]],"batl":[[2,3,15.19]],"ltp":2.9,"tv":3867.76,"id":25238892},{"batl":[[1,2.7,24.1]],"ltp":2.68,"tv":4421.25,"id":26314798}]}]}
{"op":"mcm","clk":"994172123","pt":1580549864687,"mc":[{"id":"1.168130661","rc":[{"batl":[[0,10.5,14],[1,11,29.54]],"ltp":10.0,"tv":1010.04,"id":24707172},{"batb":[[2,2.62,52]],"batl":[[0,2.68,31.98],[1,2.7,29.1]],"ltp":2.68,"tv":4421.25,"id":26314798}]}]}
{"op":"mcm","clk":"994172491","pt":1580549868500,"mc":[{"id":"1.168130661","rc":[{"batb":[[1,2.92,10.59]],"ltp":2.9,"tv":3867.76,"id":25238892}]}]}
{"op":"mcm","clk":"994172570","pt":1580549869301,"mc":[{"id":"1.168130661","rc":[{"batb":[[2,2.62,57]],"batl":[[0,2.68,36.98]],"ltp":2.68,"tv":4421.25,"id":26314798}]}]}
{"op":"mcm","clk":"994172871","pt":1580549872337,"mc":[{"id":"1.168130661","rc":[{"batb":[[2,2.9,7.19]],"ltp":2.9,"tv":3867.76,"id":25238892}]}]}
{"op":"mcm","clk":"994173811","pt":1580549881618,"mc":[{"id":"1.168130661","rc":[{"batl":[[2,60,1.87]],"ltp":46.0,"tv":125.46,"id":25545675},{"batl":[[0,2.98,6.1],[1,3,15.19],[2,3.2,5]],"ltp":2.9,"tv":3867.76,"id":25238892}]}]}
{"op":"mcm","clk":"994175028","pt":1580549895222,"mc":[{"id":"1.168130661","rc":[{"batb":[[0,42,5.7]],"ltp":46.0,"tv":125.46,"id":25545675},{"batb":[[0,2.96,10.41],[1,2.94,6],[2,2.92,5.36]],"batl":[[0,3,10.19],[1,3.05,7.37]],"ltp":2.9,"tv":3867.76,"id":25238892},{"batb":[[0,12,2.1]],"ltp":12.0,"tv":869.9,"id":24420205},{"batb":[[0,2.66,65.05]],"batl":[[1,2.7,32.1]],"ltp":2.68,"tv":4421.25,"id":26314798}]}]}
{"op":"mcm","clk":"994175157","pt":1580549896630,"mc":[{"id":"1.168130661","rc":[{"batb":[[1,2.94,9.62]],"ltp":2.9,"tv":3867.76,"id":25238892},{"trd":[[2.66,259.88]],"batb":[[0,2.66,60.9]],"ltp":2.66,"tv":4429.55,"id":26314798}],"tv":11016.72}]}
{"op":"mcm","clk":"994175431","pt":1580549899647,"mc":[{"id":"1.168130661","rc":[{"batb":[[1,2.94,3.62]],"ltp":2.9,"tv":3867.76,"id":25238892}]}]}
{"op":"mcm","clk":"994175526","pt":1580549900634,"mc":[{"id":"1.168130661","rc":[{"batb":[[0,2.98,6],[1,2.96,10.41],[2,2.94,3.62]],"batl":[[2,3.15,2]],"ltp":2.9,"tv":3867.76,"id":25238892},{"batb":[[2,2.62,47]],"ltp":2.66,"tv":4429.55,"id":26314798}]}]}
{"op":"mcm","clk":"994175596","pt":1580549901470,"mc":[{"id":"1.168130661","rc":[{"batb":[[0,10,8.65]],"ltp":10.0,"tv":1010.04,"id":24707172},{"batb":[[0,2.66,13.85]],"ltp":2.66,"tv":4429.55,"id":26314798},{"batb":[[0,11,2.12]],"ltp":11.0,"tv":713.98,"id":420}]}]}
{"op":"mcm","clk":"994176005","pt":1580549905692,"mc":[{"id":"1.168130661","rc":[{"batb":[[1,2.64,120.78]],"ltp":2.66,"tv":4429.55,"id":26314798}]}]}
{"op":"mcm","clk":"994176221","pt":1580549907676,"mc":[{"id":"1.168130661","rc":[{"batl":[[1,60,1.87],[2,65,2]],"ltp":46.0,"tv":125.46,"id":25545675},{"trd":[[2.98,7.7]],"batb":[[0,2.98,2.15]],"ltp":2.98,"tv":3875.46,"id":25238892}],"tv":11024.42}]}
{"op":"mcm","clk":"994176506","pt":1580549910588,"mc":[{"id":"1.168130661","rc":[{"batb":[[2,2.92,5.36]],"batl":[[2,3.2,5]],"ltp":2.98,"tv":3875.46,"id":25238892}]}]}
{"op":"mcm","clk":"994176533","pt":1580549910852,"mc":[{"id":"1.168130661","rc":[{"batb":[[1,2.96,14.41]],"ltp":2.98,"tv":3875.46,"id":25238892}]}]}
{"op":"mcm","clk":"994176877","pt":1580549914676,"mc":[{"id":"1.168130661","rc":[{"trd":[[2.64,576.37],[2.66,287.58]],"batb":[[0,2.62,47],[1,2.6,51.09],[2,2.58,31.63]],"batl":[[0,2.64,22.21],[1,2.68,36.98],[2,2.7,32.1]],"ltp":2.64,"tv":4721.21,"id":26314798}],"tv":11316.08}]}
{"op":"mcm","clk":"994176968","pt":1580549915558,"mc":[{"id":"1.168130661","rc":[{"batl":[[0,46,9.47]],"ltp":46.0,"tv":125.46,"id":25545675},{"batb":[[0,2.98,6.34]],"batl":[[1,3.05,5.29]],"ltp":2.98,"tv":3875.46,"id":25238892},{"batb":[[0,12,4.1]],"ltp":12.0,"tv":869.9,"id":24420205},{"batb":[[1,2.6,63.09],[2,2.58,43.63]],"batl":[[1,2.68,39.98]],"ltp":2.64,"tv":4721.21,"id":26314798}]}]}
{"op":"mcm","clk":"994177066","pt":1580549916559,"mc":[{"id":"1.168130661","rc":[{"batb":[[1,2.6,78.07]],"ltp":2.64,"tv":4721.21,"id":26314798}]}]}
{"op":"mcm","clk":"994177143","pt":1580549917291,"mc":[{"id":"1.168130661","rc":[{"batl":[[1,2.68,45.47]],"ltp":2.64,"tv":4721.21,"id":26314798}]}]}
{"op":"mcm","clk":"994177388","pt":1580549920214,"mc":[{"id":"1.168130661","rc":[{"trd":[[2.64,586.36]],"batl":[[0,2.64,17.22]],"ltp":2.64,"tv":4731.21,"id":26314798}],"tv":11326.08}]}
{"op":"mcm","clk":"994177930","pt":1580549926690,"mc":[{"id":"1.168130661","rc":[{"batl":[[1,2.68,39.98]],"ltp":2.64,"tv":4731.21,"id":26314798}]}]}
{"op":"mcm","clk":"994178750","pt":1580549935717,"mc":[{"id":"1.168130661","rc":[{"batb":[[2,2.58,41.63]],"ltp":2.64,"tv":4731.21,"id":26314798}]}]}
{"op":"mcm","clk":"994179848","pt":1580549947647,"mc":[{"id":"1.168130661","rc":[{"trd":[[10.5,36.52]],"batl":[[0,10.5,11.4]],"ltp":10.5,"tv":1015.24,"id":24707172}],"tv":11331.28}]}
{"op":"mcm","clk":"994181380","pt":1580549964668,"mc":[{"id":"1.168130661","rc":[{"trd":[[44,7.14]],"batb":[[0,42,5.31]],"batl":[[0,44,1.61],[1,46,9.47],[2,60,1.87]],"ltp":44.0,"tv":126.25,"id":25545675}],"tv":11332.06}]}
{"op":"mcm","clk":"994181455","pt":1580549965558,"mc":[{"id":"1.168130661","rc":[{"batb":[[0,42,5.7]],"batl":[[0,46,9.47],[1,60,1.87],[2,65,2]],"ltp":44.0,"tv":126.25,"id":25545675}]}]}
{"op":"mcm","clk":"994182064","pt":1580549971581,"mc":[{"id":"1.168130661","rc":[{"trd":[[10,27.1],[10.5,46.52]],"batb":[[0,10,6.13]],"batl":[[0,10.5,6.4]],"ltp":10.0,"tv":1030.28,"id":24707172}],"tv":11347.1}]}
{"op":"mcm","clk":"994182292","pt":1580549973667,"mc":[{"id":"1.168130661","rc":[{"batl":[[1,11,25.33]],"ltp":10.0,"tv":1030.28,"id":24707172}]}]}
{"op":"mcm","clk":"994182389","pt":1580549974390,"mc":[{"id":"1.168130661","rc":[{"batl":[[0,10.5,2.4],[1,11,12.73]],"ltp":10.0,"tv":1030.28,"id":24707172},{"batb":[[0,2.62,43]],"ltp":2.64,"tv":4731.21,"id":26314798},{"batl":[[0,11.5,13.66]],"ltp":11.0,"tv":713.98,"id":420}]}]}
{"op":"mcm","clk":"994183794","pt":1580549987489,"mc":[{"id":"1.168130661","rc":[{"batl":[[1,11,10.73]],"ltp":10.0,"tv":1030.28,"id":24707172}]}]}
{"op":"mcm","clk":"994185200","pt":1580550001602,"mc":[{"id":"1.168130661","rc":[{"batb":[[0,2.98,22.47]],"ltp":2.98,"tv":3875.46,"id":25238892}]}]}
{"op":"mcm","clk":"994186675","pt":1580550015621,"mc":[{"id":"1.168130661","rc":[{"batb":[[1,2.96,21.91]],"ltp":2.98,"tv":3875.46,"id":25238892}]}]}
{"op":"mcm","clk":"994188383","pt":1580550033716,"mc":[{"id":"1.168130661","rc":[{"trd":[[42,0.42],[44,7.91]],"batb":[[0,42,5.1]],"ltp":42.0,"tv":127.43,"id":25545675}],"tv":11348.28}]}
{"op":"mcm","clk":"994189032","pt":1580550040278,"mc":[{"id":"1.168130661","rc":[{"trd":[[2.98,20.82]],"batb":[[0,2.98,17.91],[1,2.96,19.91]],"ltp":2.98,"tv":3888.57,"id":25238892},{"batb":[[1,2.6,73.07],[2,2.58,36.63]],"batl":[[1,2.68,46.54]],"ltp":2.64,"tv":4731.21,"id":26314798}],"tv":11361.4}]}
{"op":"mcm","clk":"994189860","pt":1580550047696,"mc":[{"id":"1.168130661","rc":[{"trd":[[2.98,28.82]],"batb":[[0,2.98,13.91]],"ltp":2.98,"tv":3896.57,"id":25238892}],"tv":11369.4}]}
{"op":"mcm","clk":"994190476","pt":1580550054236,"mc":[{"id":"1.168130661","rc":[{"trd":[[2.62,387.27]],"batb":[[0,2.62,33]],"ltp":2.62,"tv":4751.21,"id":26314798}],"tv":11389.4}]}
{"op":"mcm","clk":"994190690","pt":1580550056434,"mc":[{"id":"1.168130661","rc":[{"batb":[[0,42,3.1]],"ltp":42.0,"tv":127.43,"id":25545675},{"trd":[[10.5,47.32]],"batl":[[0,11,10.73],[1,11.5,4.16],[2,13,25.49]],"ltp":10.5,"tv":1031.08,"id":24707172},{"batb":[[0,12,2.1]],"ltp":12.0,"tv":869.9,"id":24420205},{"batb":[[0,10.5,12.85],[1,10,10.95],[2,9.8,5]],"ltp":11.0,"tv":713.98,"id":420}],"tv":11390.2}]}
{"op":"mcm","clk":"994190793","pt":1580550057532,"mc":[{"id":"1.168130661","rc":[{"batb":[[1,40,4.38]],"ltp":42.0,"tv":127.43,"id":25545675}]}]}
{"op":"mcm","clk":"994191417","pt":1580550064708,"mc":[{"id":"1.168130661","rc":[{"batb":[[2,38,2.46]],"ltp":42.0,"tv":127.43,"id":25545675}]}]}
{"op":"mcm","clk":"994191602","pt":1580550066641,"mc":[{"id":"1.168130661","rc":[{"batb":[[0,2.98,24.84],[2,2.92,2]],"ltp":2.98,"tv":3896.57,"id":25238892},{"batb":[[0,2.62,67.45]],"ltp":2.62,"tv":4751.21,"id":26314798},{"batb":[[0,11,6.2],[1,10.5,12.85],[2,10,10.95]],"ltp":11.0,"tv":713.98,"id":420}]}]}
{"op":"mcm","clk":"994192247","pt":1580550073543,"mc":[{"id":"1.168130661","rc":[{"trd":[[2.64,586.97]],"batl":[[0,2.64,16.91]],"ltp":2.64,"tv":4751.81,"id":26314798}],"tv":11390.8}]}
{"op":"mcm","clk":"994193589","pt":1580550086655,"mc":[{"id":"1.168130661","rc":[{"trd":[[2.98,32.82]],"batb":[[0,2.98,22.84]],"ltp":2.98,"tv":3900.57,"id":25238892}],"tv":11394.8}]}
{"op":"mcm","clk":"994193845","pt":1580550089277,"mc":[{"id":"1.168130661","rc":[{"trd":[[11,107.44]],"batb":[[0,11,4.2]],"ltp":11.0,"tv":717.97,"id":420}],"tv":11398.8}]}
{"op":"mcm","clk":"994194107","pt":1580550091687,"mc":[{"id":"1.168130661","rc":[{"batb":[[0,2.98,20.84]],"ltp":2.98,"tv":3900.57,"id":25238892},{"trd":[[2.64,620.79]],"batb":[[0,2.64,2.58],[1,2.62,67.45],[2,2.6,73.07]],"batl":[[0,2.68,46.54],[1,2.7,32.1],[2,2.72,425.02]],"ltp":2.64,"tv":4785.64,"id":26314798}],"tv":11432.63}]}
{"op":"mcm","clk":"994194353","pt":1580550093670,"mc":[{"id":"1.168130661","rc":[{"trd":[[3,20.38]],"batb":[[0,3,5.74],[1,2.98,22.84],[2,2.96,19.91]],"batl":[[0,3.05,5.29],[1,3.2,5],[2,3.3,1.54]],"ltp":3.0,"tv":3920.96,"id":25238892},{"batb":[[0,2.64,14.08],[2,2.6,58.09]],"batl":[[0,2.68,57.56],[1,2.7,37.89]],"ltp":2.64,"tv":4785.64,"id":26314798}],"tv":11453.01}]}
{"op":"mcm","clk":"994194453","pt":1580550094711,"mc":[{"id":"1.168130661","rc":[{"batb":[[0,3,7.74],[2,2.96,12.41]],"batl":[[0,3.05,3]],"ltp":3.0,"tv":3920.96,"id":25238892},{"batb":[[1,2.62,72.33]],"batl":[[1,2.7,32.1]],"ltp":2.64,"tv":4785.64,"id":26314798}]}]}
{"op":"mcm","clk":"994194534","pt":1580550095498,"mc":[{"id":"1.168130661","rc":[{"batb":[[0,3,5.74]],"batl":[[0,3.15,3.19]],"ltp":3.0,"tv":3920.96,"id":25238892}]}]}
{"op":"mcm","clk":"994195480","pt":1580550105612,"mc":[{"id":"1.168130661","rc":[{"batb":[[0,3,7.74]],"ltp":3.0,"tv":3920.96,"id":25238892},{"batl":[[2,15,17]],"ltp":11.0,"tv":717.97,"id":420}]}]}
{"op":"mcm","clk":"994197019","pt":1580550120710,"mc":[{"id":"1.168130661","rc":[{"trd":[[2.64,648.95]],"batb":[[0,2.62,72.33],[1,2.6,58.09],[2,2.58,36.63]],"batl":[[0,2.64,32.13],[1,2.66,2],[2,2.68,57.56]],"ltp":2.64,"tv":4813.8,"id":26314798}],"tv":11481.17}]}
{"op":"mcm","clk":"994197112","pt":1580550121602,"mc":[{"id":"1.168130661","rc":[{"batb":[[0,2.62,64.33]],"batl":[[2,2.68,63.05]],"ltp":2.64,"tv":4813.8,"id":26314798}]}]}
{"op":"mcm","clk":"994197218","pt":1580550122689,"mc":[{"id":"1.168130661","rc":[{"batb":[[0,2.62,59.45],[1,2.6,72.13]],"ltp":2.64,"tv":4813.8,"id":26314798}]}]}
{"op":"mcm","clk":"994198058","pt":1580550130547,"mc":[{"id":"1.168130661","rc":[{"batl":[[0,3.1,6.27],[1,3.15,3.19],[2,3.2,5]],"ltp":3.0,"tv":3920.96,"id":25238892},{"batb":[[0,11,2.2]],"ltp":11.0,"tv":717.97,"id":420}]}]}
{"op":"mcm","clk":"994198606","pt":1580550135543,"mc":[{"id":"1.168130661","rc":[{"batl":[[2,15.5,18.32]],"ltp":11.0,"tv":717.97,"id":420}]}]}
{"op":"mcm","clk":"994199017","pt":1580550139582,"mc":[{"id":"1.168130661","rc":[{"trd":[[2.62,387.29]],"batb":[[0,2.62,59.44]],"ltp":2.62,"tv":4813.82,"id":26314798}],"tv":11481.19}]}
{"op":"mcm","clk":"994200302","pt":1580550151687,"mc":[{"id":"1.168130661","rc":[{"trd":[[3,40.38]],"batb":[[0,3,2.17],[2,2.96,15.39]],"ltp":3.0,"tv":3940.95,"id":25238892}],"tv":11501.19}]}
{"op":"mcm","clk":"994200394","pt":1580550152599,"mc":[{"id":"1.168130661","rc":[{"batb":[[0,3,32.17]],"ltp":3.0,"tv":3940.95,"id":25238892},{"batb":[[0,10.5,1.64],[1,10,6.13],[2,9.8,4.13]],"batl":[[2,12.5,1.01]],"ltp":10.5,"tv":1031.08,"id":24707172}]}]}
{"op":"mcm","clk":"994200497","pt":1580550153679,"mc":[{"id":"1.168130661","rc":[{"trd":[[11,111.84]],"batb":[[0,10.5,4.4],[1,10,12.95],[2,9.8,5]],"batl":[[0,11,9.8],[1,11.5,13.66],[2,12,7.75]],"ltp":11.0,"tv":722.38,"id":420}],"tv":11505.59}]}
{"op":"mcm","clk":"994200583","pt":1580550154569,"mc":[{"id":"1.168130661","rc":[{"batb":[[1,2.98,33.46]],"ltp":3.0,"tv":3940.95,"id":25238892}]}]}
{"op":"mcm","clk":"994201465","pt":1580550163506,"mc":[{"id":"1.168130661","rc":[{"batl":[[2,12,17.75]],"ltp":11.0,"tv":722.38,"id":420}]}]}
{"op":"mcm","clk":"994201782","pt":1580550166635,"mc":[{"id":"1.168130661","rc":[{"batb":[[0,3.05,2],[1,3,32.17],[2,2.98,33.46]],"ltp":3.0,"tv":3940.95,"id":25238892}]}]}
{"op":"mcm","clk":"994201885","pt":1580550167723,"mc":[{"id":"1.168130661","rc":[{"trd":[[3.05,4]],"batb":[[0,3,32.17],[1,2.98,33.46],[2,2.96,15.39]],"ltp":3.05,"tv":3944.95,"id":25238892}],"tv":11509.59}]}
{"op":"mcm","clk":"994203770","pt":1580550185649,"mc":[{"id":"1.168130661","rc":[{"batl":[[2,3.2,15]],"ltp":3.05,"tv":3944.95,"id":25238892}]}]}
{"op":"mcm","clk":"994204424","pt":1580550191642,"mc":[{"id":"1.168130661","rc":[{"batl":[[0,3.1,9.27]],"ltp":3.05,"tv":3944.95,"id":25238892}]}]}
{"op":"mcm","clk":"994206574","pt":1580550212586,"mc":[{"id":"1.168130661","rc":[{"batl":[[0,3.1,6.27]],"ltp":3.05,"tv":3944.95,"id":25238892},{"batb":[[0,2.62,66.44]],"ltp":2.62,"tv":4813.82,"id":26314798},{"trd":[[10.5,161.92]],"batb":[[0,10,12.95],[1,9.8,5],[2,9.6,7]],"batl":[[0,11,10.4]],"ltp":10.5,"tv":731.17,"id":420}],"tv":11518.39}]}
{"op":"mcm","clk":"994206803","pt":1580550214581,"mc":[{"id":"1.168130661","rc":[{"batl":[[0,10.5,7.6],[1,11,9.8],[2,11.5,13.66]],"ltp":10.5,"tv":731.17,"id":420}]}]}
{"op":"mcm","clk":"994208316","pt":1580550228708,"mc":[{"id":"1.168130661","rc":[{"batb":[[2,11,10.55]],"ltp":12.0,"tv":869.9,"id":24420205},{"batb":[[0,10,16.95]],"ltp":10.5,"tv":731.17,"id":420}]}]}
{"op":"mcm","clk":"994209570","pt":1580550239668,"mc":[{"id":"1.168130661","rc":[{"batb":[[0,3,2.17]],"batl":[[0,3.1,9.27]],"ltp":3.05,"tv":3944.95,"id":25238892},{"batl":[[1,2.68,63.05],[2,2.7,32.1]],"ltp":2.62,"tv":4813.82,"id":26314798}]}]}
{"op":"mcm","clk":"994209960","pt":1580550243648,"mc":[{"id":"1.168130661","rc":[{"batl":[[0,3.05,10],[1,3.1,9.27],[2,3.15,3.19]],"ltp":3.05,"tv":3944.95,"id":25238892}]}]}
{"op":"mcm","clk":"994210048","pt":1580550244584,"mc":[{"id":"1.168130661","rc":[{"batb":[[1,2.98,22.84],[2,2.96,12.41]],"batl":[[1,3.1,3]],"ltp":3.05,"tv":3944.95,"id":25238892},{"batl":[[0,10.5,5.6]],"ltp":10.5,"tv":731.17,"id":420}]}]}
{"op":"mcm","clk":"994210245","pt":1580550246573,"mc":[{"id":"1.168130661","rc":[{"batl":[[2,3.15,13.19]],"ltp":3.05,"tv":3944.95,"id":25238892}]}]}
{"op":"mcm","clk":"994210894","pt":1580550253694,"mc":[{"id":"1.168130661","rc":[{"batb":[[1,10,9.49]],"ltp":10.5,"tv":1031.08,"id":24707172},{"batb":[[0,10,22.83]],"ltp":10.5,"tv":731.17,"id":420}]}]}
{"op":"mcm","clk":"994210959","pt":1580550254379,"mc":[{"id":"1.168130661","rc":[{"batl":[[0,11,6.73]],"ltp":10.5,"tv":1031.08,"id":24707172}]}]}
{"op":"mcm","clk":"994212158","pt":1580550265718,"mc":[{"id":"1.168130661","rc":[{"batb":[[0,42,3.52]],"ltp":42.0,"tv":127.43,"id":25545675}]}]}
{"op":"mcm","clk":"994212886","pt":1580550272701,"mc":[{"id":"1.168130661","rc":[{"trd":[[42,7.44]],"batb":[[0,40,4.39],[1,38,2.46],[2,36,2.48]],"ltp":42.0,"tv":134.45,"id":25545675},{"batl":[[1,2.66,25],[2,2.68,63.05]],"ltp":2.62,"tv":4813.82,"id":26314798}],"tv":11525.41}]}
{"op":"mcm","clk":"994213088","pt":1580550274629,"mc":[{"id":"1.168130661","rc":[{"batb":[[0,40,2.18],[1,38,2],[2,36,5.68]],"ltp":42.0,"tv":134.45,"id":25545675},{"trd":[[2.62,437.29]],"batb":[[0,2.62,41.44]],"ltp":2.62,"tv":4863.82,"id":26314798}],"tv":11575.41}]}
{"op":"mcm","clk":"994213206","pt":1580550275614,"mc":[{"id":"1.168130661","rc":[{"batl":[[1,2.68,63.05],[2,2.7,32.1]],"ltp":2.62,"tv":4863.82,"id":26314798}]}]}
{"op":"mcm","clk":"994213722","pt":1580550280623,"mc":[{"id":"1.168130661","rc":[{"batb":[[0,40,11.29]],"ltp":42.0,"tv":134.45,"id":25545675},{"batl":[[0,3.05,13]],"ltp":3.05,"tv":3944.95,"id":25238892},{"trd":[[10.5,173.11]],"batb":[[0,10.5,20.53],[1,10,22.83],[2,9.8,5]],"batl":[[0,11,7.8],[1,11.5,13.66],[2,12,15.75]],"ltp":10.5,"tv":742.37,"id":420}],"tv":11586.6}]}
{"op":"mcm","clk":"994213830","pt":1580550281548,"mc":[{"id":"1.168130661","rc":[{"trd":[[11,127.44]],"batl":[[0,11.5,13.66],[1,12,15.75],[2,12.5,10]],"ltp":11.0,"tv":757.97,"id":420}],"tv":11602.2}]}
{"op":"mcm","clk":"994213962","pt":1580550282638,"mc":[{"id":"1.168130661","rc":[{"batb":[[0,40,11.71]],"ltp":42.0,"tv":134.45,"id":25545675}]}]}
{"op":"mcm","clk":"994214079","pt":1580550283525,"mc":[{"id":"1.168130661","rc":[{"batb":[[0,3,2]],"ltp":3.05,"tv":3944.95,"id":25238892},{"batl":[[0,11,9.73]],"ltp":10.5,"tv":1031.08,"id":24707172},{"batb":[[0,2.62,34.44]],"batl":[[1,2.66,2.23],[2,2.68,63.05]],"ltp":2.62,"tv":4863.82,"id":26314798}]}]}
{"op":"mcm","clk":"994214609","pt":1580550288637,"mc":[{"id":"1.168130661","rc":[{"batb":[[0,40,2.6]],"ltp":42.0,"tv":134.45,"id":25545675},{"batb":[[0,2.62,41.44]],"ltp":2.62,"tv":4863.82,"id":26314798},{"batb":[[0,10.5,2],[2,9.8,18.64]],"ltp":11.0,"tv":757.97,"id":420}]}]}
{"op":"mcm","clk":"994214953","pt":1580550292429,"mc":[{"id":"1.168130661","rc":[{"batb":[[0,40,2.18]],"ltp":42.0,"tv":134.45,"id":25545675}]}]}
{"op":"mcm","clk":"994215715","pt":1580550299661,"mc":[{"id":"1.168130661","rc":[{"batb":[[2,36,6.16]],"ltp":42.0,"tv":134.45,"id":25545675}]}]}
{"op":"mcm","clk":"994216154","pt":1580550303690,"mc":[{"id":"1.168130661","rc":[{"batb":[[0,38,2.01],[1,36,2.97],[2,34,2.35]],"ltp":42.0,"tv":134.45,"id":25545675},{"batb":[[2,9.8,5]],"batl":[[0,11.5,4.17]],"ltp":11.0,"tv":757.97,"id":420}]}]}
{"op":"mcm","clk":"994216284","pt":1580550304689,"mc":[{"id":"1.168130661","rc":[{"batl":[[0,3.05,10]],"ltp":3.05,"tv":3944.95,"id":25238892},{"batl":[[1,2.68,63.05],[2,2.7,32.1]],"ltp":2.62,"tv":4863.82,"id":26314798},{"batb":[[0,10.5,12]],"batl":[[0,11,10],[1,11.5,4.17],[2,12,15.75]],"ltp":11.0,"tv":757.97,"id":420}]}]}
{"op":"mcm","clk":"994216425","pt":1580550305583,"mc":[{"id":"1.168130661","rc":[{"batb":[[0,34,3.14],[1,30,3.5],[2,29,2.3]],"ltp":42.0,"tv":134.45,"id":25545675},{"batl":[[0,11,6.73]],"ltp":10.5,"tv":1031.08,"id":24707172}]}]}
{"op":"mcm","clk":"994216837","pt":1580550309655,"mc":[{"id":"1.168130661","rc":[{"batb":[[0,34,2.65]],"ltp":42.0,"tv":134.45,"id":25545675}]}]}
{"op":"mcm","clk":"994216938","pt":1580550310698,"mc":[{"id":"1.168130661","rc":[{"batb":[[0,34,3.09]],"ltp":42.0,"tv":134.45,"id":25545675}]}]}
{"op":"mcm","clk":"994217687","pt":1580550317717,"mc":[{"id":"1.168130661","rc":[{"batb":[[2,29,2.9]],"ltp":42.0,"tv":134.45,"id":25545675},{"trd":[[2.64,668.73]],"batl":[[0,2.64,22.24]],"ltp":2.64,"tv":4883.6,"id":26314798}],"tv":11621.98}]}
{"op":"mcm","clk":"994218122","pt":1580550321623,"mc":[{"id":"1.168130661","rc":[{"batl":[[0,11,15.75],[1,11.5,10.8]],"ltp":11.0,"tv":757.97,"id":420}]}]}
{"op":"mcm","clk":"994218247","pt":1580550322718,"mc":[{"id":"1.168130661","rc":[{"batb":[[0,36,2.86],[1,34,2.35],[2,30,3.5]],"ltp":42.0,"tv":134.45,"id":25545675},{"batb":[[0,10.5,10]],"batl":[[0,11,24.22],[1,11.5,331.8]],"ltp":11.0,"tv":757.97,"id":420}]}]}
{"op":"mcm","clk":"994218456","pt":1580550324718,"mc":[{"id":"1.168130661","rc":[{"batb":[[1,2.6,372.13]],"ltp":2.64,"tv":4883.6,"id":26314798}]}]}
{"op":"mcm","clk":"994218581","pt":1580550325717,"mc":[{"id":"1.168130661","rc":[{"batb":[[0,2.98,22.84],[1,2.96,12.41],[2,2.92,2]],"ltp":3.05,"tv":3944.95,"id":25238892},{"batl":[[1,2.68,52.03]],"ltp":2.64,"tv":4883.6,"id":26314798}]}]}
{"op":"mcm","clk":"994218942","pt":1580550328629,"mc":[{"id":"1.168130661","rc":[{"batb":[[1,2.96,20.03]],"ltp":3.05,"tv":3944.95,"id":25238892},{"batb":[[0,12,4.1]],"ltp":12.0,"tv":869.9,"id":24420205},{"batl":[[1,2.68,49.03]],"ltp":2.64,"tv":4883.6,"id":26314798},{"batb":[[0,10.5,12]],"batl":[[1,11.5,10.8],[2,12,336.75]],"ltp":11.0,"tv":757.97,"id":420}]}]}
{"op":"mcm","clk":"994220219","pt":1580550338561,"mc":[{"id":"1.168130661","rc":[{"batl":[[0,46,13.47]],"ltp":42.0,"tv":134.45,"id":25545675},{"batb":[[0,3,3.21],[1,2.98,22.84],[2,2.96,20.03]],"ltp":3.05,"tv":3944.95,"id":25238892}]}]}
{"op":"mcm","clk":"994220340","pt":1580550339562,"mc":[{"id":"1.168130661","rc":[{"batl":[[0,11,18.47]],"ltp":11.0,"tv":757.97,"id":420}]}]}
{"op":"mcm","clk":"994220853","pt":1580550343667,"mc":[{"id":"1.168130661","rc":[{"batl":[[0,11,10.73],[2,12,10.1]],"ltp":10.5,"tv":1031.08,"id":24707172},{"trd":[[10.5,178.41]],"batb":[[0,10.5,9.35]],"batl":[[0,11,16.47]],"ltp":10.5,"tv":763.26,"id":420}],"tv":11627.27}]}
{"op":"mcm","clk":"994220956","pt":1580550344553,"mc":[{"id":"1.168130661","rc":[{"trd":[[36,8.14],[42,7.46]],"batb":[[0,34,2.35],[1,30,3.5],[2,29,2.9]],"batl":[[0,36,47.14],[1,46,13.47],[2,60,1.87]],"ltp":36.0,"tv":140.17,"id":25545675}],"tv":11632.99}]}
{"op":"mcm","clk":"994221289","pt":1580550347688,"mc":[{"id":"1.168130661","rc":[{"batl":[[0,36,49.14]],"ltp":36.0,"tv":140.17,"id":25545675},{"batb":[[0,2.98,22.84],[1,2.96,12.41],[2,2.92,2]],"ltp":3.05,"tv":3944.95,"id":25238892},{"trd":[[12,141.4]],"batb":[[0,11.5,2.1],[1,11,10.55],[2,10.5,10.56]],"batl":[[0,12,3.9],[1,12.5,2.19],[2,13,17.88]],"ltp":12.0,"tv":882.1,"id":24420205}],"tv":11645.19}]}
{"op":"mcm","clk":"994221406","pt":1580550348680,"mc":[{"id":"1.168130661","rc":[{"batb":[[0,11.5,5.46]],"ltp":12.0,"tv":882.1,"id":24420205}]}]}
{"op":"mcm","clk":"994221671","pt":1580550351553,"mc":[{"id":"1.168130661","rc":[{"trd":[[36,13.8]],"batl":[[0,36,46.31]],"ltp":36.0,"tv":145.83,"id":25545675},{"trd":[[3.05,24]],"batb":[[0,3.05,23.46],[1,2.98,22.84],[2,2.96,12.41]],"batl":[[0,3.1,3],[1,3.15,13.19],[2,3.2,15]],"ltp":3.05,"tv":3964.96,"id":25238892},{"batb":[[0,10.5,11.36]],"ltp":10.5,"tv":1031.08,"id":24707172},{"trd":[[12,149.2]],"batb":[[0,12,4.6],[1,11.5,5.46],[2,11,10.55]],"batl":[[0,12.5,2.19],[1,13,17.88],[2,13.5,2]],"ltp":12.0,"tv":889.9,"id":24420205},{"trd":[[2.64,713.22]],"batb":[[0,2.64,16.41],[1,2.62,41.44],[2,2.6,372.13]],"batl":[[0,2.68,49.03],[1,2.7,32.1],[2,2.72,425.02]],"ltp":2.64,"tv":4928.08,"id":26314798},{"batb":[[0,10.5,19.07]],"batl":[[1,11.5,20.8]],"ltp":10.5,"tv":763.26,"id":420}],"tv":11723.15}]}
{"op":"mcm","clk":"994221809","pt":1580550352695,"mc":[{"id":"1.168130661","rc":[{"trd":[[3.05,70.91],[3.1,9.8]],"batb":[[0,2.98,20.84],[1,2.92,2],[2,2.88,6]],"batl":[[0,3.1,7.51],[2,3.2,19]],"ltp":3.1,"tv":4021.67,"id":25238892},{"batl":[[2,12,11.09]],"ltp":10.5,"tv":1031.08,"id":24707172},{"batl":[[0,2.68,51.03],[1,2.7,40.88]],"ltp":2.64,"tv":4928.08,"id":26314798},{"batb":[[0,10.5,17.07]],"batl":[[0,11,18.47],[1,11.5,16.66]],"ltp":10.5,"tv":763.26,"id":420}],"tv":11779.86}]}
{"op":"mcm","clk":"994221892","pt":1580550353472,"mc":[{"id":"1.168130661","rc":[{"batb":[[0,3,6.28],[1,2.98,23.84],[2,2.92,2]],"batl":[[2,3.2,27.9]],"ltp":3.1,"tv":4021.67,"id":25238892},{"batl":[[0,11,6.73],[2,12,10.1]],"ltp":10.5,"tv":1031.08,"id":24707172},{"batb":[[0,2.64,26.41],[1,2.62,47.09]],"batl":[[0,2.68,43.54],[1,2.7,32.1]],"ltp":2.64,"tv":4928.08,"id":26314798}]}]}
{"op":"mcm","clk":"994222314","pt":1580550356696,"mc":[{"id":"1.168130661","rc":[{"batb":[[0,2.98,12.91],[1,2.96,2.48]],"ltp":3.1,"tv":4021.67,"id":25238892},{"batl":[[0,11,8.73]],"ltp":10.5,"tv":1031.08,"id":24707172},{"batb":[[0,12,6.6]],"ltp":12.0,"tv":889.9,"id":24420205},{"batb":[[0,10.5,19.07]],"batl":[[1,11.5,14.17]],"ltp":10.5,"tv":763.26,"id":420}]}]}
{"op":"mcm","clk":"994222879","pt":1580550361389,"mc":[{"id":"1.168130661","rc":[{"batb":[[1,2.62,59.66]],"batl":[[1,2.7,48.27]],"ltp":2.64,"tv":4928.08,"id":26314798}]}]}
{"op":"mcm","clk":"994223330","pt":1580550365680,"mc":[{"id":"1.168130661","rc":[{"trd":[[2.64,733.22]],"batb":[[0,2.64,16.41]],"ltp":2.64,"tv":4948.09,"id":26314798}],"tv":11799.86}]}
{"op":"mcm","clk":"994223634","pt":1580550368496,"mc":[{"id":"1.168130661","rc":[{"batb":[[2,2.6,358.09]],"ltp":2.64,"tv":4948.09,"id":26314798}]}]}
{"op":"mcm","clk":"994225376","pt":1580550380711,"mc":[{"id":"1.168130661","rc":[{"batb":[[0,10.5,13.36],[1,10,11.49]],"ltp":10.5,"tv":1031.08,"id":24707172},{"trd":[[2.64,786.04]],"batb":[[0,2.62,59.66],[1,2.6,358.09],[2,2.58,40.63]],"batl":[[0,2.64,10.56],[1,2.68,43.54],[2,2.7,48.27]],"ltp":2.64,"tv":5000.9,"id":26314798},{"batl":[[0,11,16.47]],"ltp":10.5,"tv":763.26,"id":420}],"tv":11852.68}]}
{"op":"mcm","clk":"994225473","pt":1580550381606,"mc":[{"id":"1.168130661","rc":[{"batb":[[0,2.98,14.91]],"ltp":3.1,"tv":4021.67,"id":25238892},{"batl":[[0,13,17.88],[1,13.5,2],[2,14,2.36]],"ltp":12.0,"tv":889.9,"id":24420205}]}]}
{"op":"mcm","clk":"994225548","pt":1580550382322,"mc":[{"id":"1.168130661","rc":[{"batb":[[1,2.94,5.49],[2,2.92,10.89]],"ltp":3.1,"tv":4021.67,"id":25238892},{"batb":[[0,2.62,54.01]],"ltp":2.64,"tv":5000.9,"id":26314798}]}]}
{"op":"mcm","clk":"994227235","pt":1580550395654,"mc":[{"id":"1.168130661","rc":[{"trd":[[2.62,438.33]],"batb":[[0,2.62,53.49]],"ltp":2.62,"tv":5001.94,"id":26314798}],"tv":11853.72}]}
{"op":"mcm","clk":"994227404","pt":1580550396660,"mc":[{"id":"1.168130661","rc":[{"batb":[[0,2.62,66.02]],"ltp":2.62,"tv":5001.94,"id":26314798}]}]}
{"op":"mcm","clk":"994228548","pt":1580550404678,"mc":[{"id":"1.168130661","rc":[{"trd":[[2.98,36.82]],"batb":[[0,2.98,12.91]],"ltp":2.98,"tv":4025.67,"id":25238892}],"tv":11857.72}]}
{"op":"mcm","clk":"994229185","pt":1580550409722,"mc":[{"id":"1.168130661","rc":[{"trd":[[2.98,37.86]],"batb":[[0,2.98,12.39]],"ltp":2.98,"tv":4026.71,"id":25238892}],"tv":11858.76}]}
{"op":"mcm","clk":"994229267","pt":1580550410660,"mc":[{"id":"1.168130661","rc":[{"trd":[[2.6,535.82],[2.62,570.38]],"batb":[[0,2.6,190.11],[1,2.58,35.63],[2,2.56,62.5]],"batl":[[1,2.68,46.54]],"ltp":2.6,"tv":5481.95,"id":26314798}],"tv":12338.77}]}
{"op":"mcm","clk":"994229366","pt":1580550411454,"mc":[{"id":"1.168130661","rc":[{"batb":[[1,2.58,51.1]],"batl":[[1,2.68,58.8]],"ltp":2.6,"tv":5481.95,"id":26314798}]}]}
{"op":"mcm","clk":"994229539","pt":1580550412700,"mc":[{"id":"1.168130661","rc":[{"batb":[[0,3,9.64],[1,2.98,12.39],[2,2.94,5.49]],"ltp":2.98,"tv":4026.71,"id":25238892}]}]}
{"op":"mcm","clk":"994229632","pt":1580550413375,"mc":[{"id":"1.168130661","rc":[{"trd":[[3.1,10.1]],"batl":[[0,3.1,7.36]],"ltp":3.1,"tv":4027.01,"id":25238892}],"tv":12339.07}]}
{"op":"mcm","clk":"994229798","pt":1580550414674,"mc":[{"id":"1.168130661","rc":[{"batb":[[1,2.98,15.76]],"ltp":3.1,"tv":4027.01,"id":25238892},{"batb":[[0,2.62,6.29],[1,2.6,190.11],[2,2.58,51.1]],"ltp":2.6,"tv":5481.95,"id":26314798}]}]}
{"op":"mcm","clk":"994231868","pt":1580550429716,"mc":[{"id":"1.168130661","rc":[{"batl":[[1,2.68,356.8]],"ltp":2.6,"tv":5481.95,"id":26314798}]}]}
{"op":"mcm","clk":"994231995","pt":1580550430707,"mc":[{"id":"1.168130661","rc":[{"trd":[[2.6,603.24],[2.62,582.96]],"batb":[[0,2.6,156.4],[1,2.58,38.73],[2,2.56,62.5]],"batl":[[1,2.66,14.14],[2,2.68,356.8]],"ltp":2.6,"tv":5561.95,"id":26314798}],"tv":12419.07}]}
{"op":"mcm","clk":"994232110","pt":1580550431701,"mc":[{"id":"1.168130661","rc":[{"batb":[[0,12.5,3.48],[1,12,6.6],[2,11.5,5.46]],"ltp":12.0,"tv":889.9,"id":24420205},{"batb":[[0,2.62,5.05],[1,2.6,156.4],[2,2.58,43.73]],"batl":[[0,2.64,15.56],[1,2.66,26.52]],"ltp":2.6,"tv":5561.95,"id":26314798}]}]}
{"op":"mcm","clk":"994232952","pt":1580550438629,"mc":[{"id":"1.168130661","rc":[{"batl":[[0,3.05,2],[1,3.1,7.36],[2,3.15,13.19]],"ltp":3.1,"tv":4027.01,"id":25238892}]}]}
{"op":"mcm","clk":"994233090","pt":1580550439719,"mc":[{"id":"1.168130661","rc":[{"trd":[[3.05,74.91]],"batb":[[0,3.05,3.2],[1,3,9.64],[2,2.98,15.76]],"batl":[[0,3.1,3.2],[1,3.15,13.19],[2,3.2,27.9]],"ltp":3.05,"tv":4031.01,"id":25238892},{"batb":[[0,2.6,156.4],[1,2.58,43.73],[2,2.56,62.5]],"ltp":2.6,"tv":5561.95,"id":26314798}],"tv":12423.07}]}
{"op":"mcm","clk":"994233223","pt":1580550440407,"mc":[{"id":"1.168130661","rc":[{"batb":[[2,2.98,12.39]],"ltp":3.05,"tv":4031.01,"id":25238892},{"batb":[[1,2.58,55.08]],"ltp":2.6,"tv":5561.95,"id":26314798}]}]}
{"op":"mcm","clk":"994235026","pt":1580550452636,"mc":[{"id":"1.168130661","rc":[{"trd":[[10.5,51.32]],"batb":[[0,10.5,11.36]],"ltp":10.5,"tv":1035.08,"id":24707172}],"tv":12427.06}]}
{"op":"mcm","clk":"994235748","pt":1580550458569,"mc":[{"id":"1.168130661","rc":[{"batl":[[0,3.1,5.2]],"ltp":3.05,"tv":4031.01,"id":25238892}]}]}
{"op":"mcm","clk":"994236468","pt":1580550463652,"mc":[{"id":"1.168130661","rc":[{"trd":[[3.05,78.91]],"batb":[[0,3.05,1.2]],"ltp":3.05,"tv":4035.01,"id":25238892}],"tv":12431.06}]}
{"op":"mcm","clk":"994236581","pt":1580550464652,"mc":[{"id":"1.168130661","rc":[{"trd":[[11,114.21]],"batb":[[0,11,1.27],[1,10.5,11.36],[2,10,11.49]],"batl":[[0,11.5,4.16],[1,12,11.09],[2,13,26.3]],"ltp":11.0,"tv":1052.54,"id":24707172},{"batl":[[0,11,18.47]],"ltp":10.5,"tv":763.26,"id":420}],"tv":12448.52}]}
{"op":"mcm","clk":"994236792","pt":1580550466370,"mc":[{"id":"1.168130661","rc":[{"batb":[[1,3,6.28],[2,2.98,16.15]],"ltp":3.05,"tv":4035.01,"id":25238892},{"batb":[[2,10,8.13]],"ltp":11.0,"tv":1052.54,"id":24707172},{"batb":[[2,11.5,2.1]],"ltp":12.0,"tv":889.9,"id":24420205},{"batb":[[1,10,16.95]],"ltp":10.5,"tv":763.26,"id":420}]}]}
{"op":"mcm","clk":"994237265","pt":1580550470065,"mc":[{"id":"1.168130661","rc":[{"batb":[[2,10,10.13]],"ltp":11.0,"tv":1052.54,"id":24707172}]}]}
{"op":"mcm","clk":"994238583","pt":1580550481644,"mc":[{"id":"1.168130661","rc":[{"batb":[[2,2.98,12.39]],"ltp":3.05,"tv":4035.01,"id":25238892}]}]}
{"op":"mcm","clk":"994239658","pt":1580550490719,"mc":[{"id":"1.168130661","rc":[{"batb":[[2,2.98,15.39]],"ltp":3.05,"tv":4035.01,"id":25238892},{"batb":[[0,11,3.32]],"batl":[[0,12,14.09],[1,13,26.3],[2,13.5,28]],"ltp":11.0,"tv":1052.54,"id":24707172},{"batb":[[0,12.5,5.48]],"ltp":12.0,"tv":889.9,"id":24420205},{"trd":[[2.58,168.27],[2.6,916.04]],"batb":[[0,2.56,62.5],[1,2.54,20],[2,2.52,10]],"batl":[[0,2.58,285.51],[1,2.64,15.56],[2,2.66,26.52]],"ltp":2.58,"tv":6000.91,"id":26314798}],"tv":12887.49}]}
{"op":"mcm","clk":"994239727","pt":1580550491210,"mc":[{"id":"1.168130661","rc":[{"trd":[[11,116.75]],"batb":[[0,10.5,9.36],[1,10,8.13],[2,9.8,4.13]],"batl":[[0,11.5,6.28],[1,12,13.1],[2,13,26.23]],"ltp":11.0,"tv":1055.08,"id":24707172},{"batb":[[1,2.54,61.21],[2,2.52,19]],"batl":[[1,2.6,7.05],[2,2.62,7.05]],"ltp":2.58,"tv":6000.91,"id":26314798}],"tv":12890.03}]}
{"op":"mcm","clk":"994239892","pt":1580550492609,"mc":[{"id":"1.168130661","rc":[{"batl":[[2,3.2,19]],"ltp":3.05,"tv":4035.01,"id":25238892},{"batb":[[0,11,2.06],[1,10.5,9.36],[2,10,8.13]],"batl":[[1,12,14.09]],"ltp":11.0,"tv":1055.08,"id":24707172},{"trd":[[2.56,21.9]],"batb":[[0,2.56,60.5],[1,2.54,42.61]],"batl":[[0,2.58,311.01]],"ltp":2.56,"tv":6004.91,"id":26314798}],"tv":12894.03}]}
{"op":"mcm","clk":"994240224","pt":1580550495522,"mc":[{"id":"1.168130661","rc":[{"trd":[[2.56,61.9]],"batb":[[0,2.56,40.5]],"ltp":2.56,"tv":6044.91,"id":26314798}],"tv":12934.03}]}
{"op":"mcm","clk":"994240274","pt":1580550496038,"mc":[{"id":"1.168130661","rc":[{"batb":[[2,2.52,24]],"batl":[[0,2.58,316.01]],"ltp":2.56,"tv":6044.91,"id":26314798}]}]}
{"op":"mcm","clk":"994240873","pt":1580550501513,"mc":[{"id":"1.168130661","rc":[{"batb":[[2,2.52,29]],"batl":[[0,2.58,321.01]],"ltp":2.56,"tv":6044.91,"id":26314798}]}]}
{"op":"mcm","clk":"994241455","pt":1580550506568,"mc":[{"id":"1.168130661","rc":[{"batb":[[2,2.52,34]],"batl":[[0,2.58,326.01]],"ltp":2.56,"tv":6044.91,"id":26314798}]}]}
{"op":"mcm","clk":"994241580","pt":1580550507554,"mc":[{"id":"1.168130661","rc":[{"trd":[[2.58,178.27]],"batl":[[0,2.58,321.01]],"ltp":2.58,"tv":6054.91,"id":26314798}],"tv":12944.03}]}
{"op":"mcm","clk":"994242029","pt":1580550511455,"mc":[{"id":"1.168130661","rc":[{"batb":[[2,2.52,39]],"batl":[[0,2.58,326.01]],"ltp":2.58,"tv":6054.91,"id":26314798}]}]}
{"op":"mcm","clk":"994242416","pt":1580550514659,"mc":[{"id":"1.168130661","rc":[{"batb":[[0,2.56,50.5],[2,2.52,29]],"ltp":2.58,"tv":6054.91,"id":26314798}]}]}
{"op":"mcm","clk":"994242632","pt":1580550516530,"mc":[{"id":"1.168130661","rc":[{"batb":[[2,2.52,34]],"batl":[[0,2.58,331.01]],"ltp":2.58,"tv":6054.91,"id":26314798}]}]}
{"op":"mcm","clk":"994244009","pt":1580550528690,"mc":[{"id":"1.168130661","rc":[{"trd":[[36,15.81]],"batl":[[0,36,44.3]],"ltp":36.0,"tv":147.84,"id":25545675},{"trd":[[3.1,15.3],[3.15,17.83]],"batb":[[0,2.98,15.39],[1,2.94,5.49],[2,2.92,2]],"batl":[[0,3.15,11.72],[1,3.2,17],[2,3.25,29.54]],"ltp":3.15,"tv":4058.04,"id":25238892},{"trd":[[11.5,13.52]],"batl":[[0,12,10.1],[1,12.5,3.26],[2,13,25.39]],"ltp":11.5,"tv":1061.36,"id":24707172},{"trd":[[13,37.05]],"batl":[[0,13,10.32]],"ltp":13.0,"tv":895.47,"id":24420205},{"trd":[[2.5,126.72],[2.52,223.12],[2.54,112.06],[2.56,162.9]],"batb":[[0,2.46,6.26],[1,2.44,50.73],[2,2.42,103]],"batl":[[0,2.5,83.98],[1,2.54,9.26],[2,2.56,9.26]],"ltp":2.5,"tv":6409.11,"id":26314798},{"trd":[[11,134.02]],"batl":[[0,11,9.89]],"ltp":11.0,"tv":769.84,"id":420}],"tv":13341.69}]}
{"op":"mcm","clk":"994244148","pt":1580550529681,"mc":[{"id":"1.168130661","rc":[{"batl":[[2,3.25,20.79]],"ltp":3.15,"tv":4058.04,"id":25238892},{"batb":[[2,2.42,107]],"batl":[[0,2.48,26.52],[1,2.5,83.98],[2,2.52,9.27]],"ltp":2.5,"tv":6409.11,"id":26314798}]}]}
{"op":"mcm","clk":"994244274","pt":1580550530614,"mc":[{"id":"1.168130661","rc":[{"batb":[[0,34,3.84],[1,32,2.27],[2,30,3.5]],"ltp":36.0,"tv":147.84,"id":25545675},{"trd":[[3.15,41.26],[3.2,20.24]],"batb":[[0,3.15,40.39],[1,3.1,25.34],[2,3.05,10.27]],"batl":[[0,3.2,4.88],[1,3.25,22.79],[2,3.3,10.76]],"ltp":3.2,"tv":4101.71,"id":25238892},{"batb":[[0,11.5,4.41],[1,11,2.06],[2,10.5,11.36]],"batl":[[0,12,13.1],[2,13,26.23]],"ltp":11.5,"tv":1061.36,"id":24707172},{"trd":[[13,57.67]],"batb":[[0,13,20.91],[1,12.5,9.53],[2,12,6.6]],"batl":[[0,14,2.36],[1,14.5,2],[2,15,2]],"ltp":13.0,"tv":916.09,"id":24420205},{"batb":[[0,2.46,22.59]],"batl":[[1,2.5,92.98]],"ltp":2.5,"tv":6409.11,"id":26314798},{"trd":[[11,153.79]],"batb":[[0,11,7.8],[1,10.5,23.89],[2,10,16.95]],"batl":[[0,11.5,14.17],[1,12,336.75],[2,12.5,10]],"ltp":11.0,"tv":789.61,"id":420}],"tv":13425.76}]}
{"op":"mcm","clk":"994244383","pt":1580550531653,"mc":[{"id":"1.168130661","rc":[{"trd":[[2.48,12.73]],"batl":[[0,2.48,23.5]],"ltp":2.48,"tv":6415.16,"id":26314798}],"tv":13431.8}]}
{"op":"mcm","clk":"994244501","pt":1580550532708,"mc":[{"id":"1.168130661","rc":[{"batb":[[1,32,4.96]],"ltp":36.0,"tv":147.84,"id":25545675},{"batb":[[0,2.46,29.06]],"ltp":2.48,"tv":6415.16,"id":26314798}]}]}
{"op":"mcm","clk":"994245179","pt":1580550538692,"mc":[{"id":"1.168130661","rc":[{"batb":[[0,3.15,9]],"ltp":3.2,"tv":4101.71,"id":25238892},{"batb":[[0,13,2],[2,12,21.97]],"ltp":13.0,"tv":916.09,"id":24420205},{"batb":[[0,10.5,23.89],[1,10,16.95],[2,9.8,5]],"ltp":11.0,"tv":789.61,"id":420}]}]}
{"op":"mcm","clk":"994245368","pt":1580550540673,"mc":[{"id":"1.168130661","rc":[{"batl":[[1,12.5,4.17],[2,13,25.39]],"ltp":11.5,"tv":1061.36,"id":24707172},{"batb":[[2,12,6.6]],"ltp":13.0,"tv":916.09,"id":24420205},{"trd":[[2.46,63.21]],"batb":[[0,2.46,11.57],[1,2.44,48.73]],"ltp":2.46,"tv":6446.15,"id":26314798}],"tv":13462.79}]}
{"op":"mcm","clk":"994245499","pt":1580550541720,"mc":[{"id":"1.168130661","rc":[{"trd":[[3.15,46.84]],"batb":[[0,3.15,6.21]],"ltp":3.15,"tv":4107.29,"id":25238892},{"trd":[[11.5,22.33]],"batb":[[0,11,2.06],[1,10.5,11.36],[2,10,8.13]],"batl":[[0,12,13.69]],"ltp":11.5,"tv":1070.18,"id":24707172},{"trd":[[2.48,13.64]],"batl":[[0,2.48,23.05]],"ltp":2.48,"tv":6447.05,"id":26314798}],"tv":13478.09}]}
{"op":"mcm","clk":"994245635","pt":1580550542712,"mc":[{"id":"1.168130661","rc":[{"batl":[[1,12.5,3.26]],"ltp":11.5,"tv":1070.18,"id":24707172},{"batl":[[0,13.5,2.82],[1,14,2.36],[2,14.5,2]],"ltp":13.0,"tv":916.09,"id":24420205},{"batb":[[0,2.46,27.15]],"ltp":2.48,"tv":6447.05,"id":26314798}]}]}
{"op":"mcm","clk":"994245748","pt":1580550543701,"mc":[{"id":"1.168130661","rc":[{"batb":[[1,32,5.51]],"ltp":36.0,"tv":147.84,"id":25545675},{"trd":[[3.2,24.24]],"batl":[[0,3.2,2.88]],"ltp":3.2,"tv":4111.29,"id":25238892},{"batb":[[1,10.5,14.07]],"ltp":11.5,"tv":1070.18,"id":24707172},{"batl":[[1,14,7.36]],"ltp":13.0,"tv":916.09,"id":24420205}],"tv":13482.09}]}
{"op":"mcm","clk":"994245871","pt":1580550544696,"mc":[{"id":"1.168130661","rc":[{"batb":[[1,10.5,11.36]],"ltp":11.5,"tv":1070.18,"id":24707172}]}]}
{"op":"mcm","clk":"994246015","pt":1580550545700,"mc":[{"id":"1.168130661","rc":[{"trd":[[11,120.87]],"batb":[[0,10.5,11.36],[1,10,8.13],[2,9.8,4.13]],"batl":[[0,11,2.94],[1,12,13.69],[2,12.5,3.26]],"ltp":11.0,"tv":1074.3,"id":24707172}],"tv":13486.21}]}
{"op":"mcm","clk":"994246133","pt":1580550546635,"mc":[{"id":"1.168130661","rc":[{"trd":[[34,12.35]],"batb":[[0,32,5.51],[1,30,3.5],[2,29,2.3]],"batl":[[0,34,3.16],[1,36,44.3],[2,46,13.47]],"ltp":34.0,"tv":155.52,"id":25545675},{"trd":[[11,126.75]],"batb":[[0,11,6.56],[1,10.5,11.36],[2,10,8.13]],"batl":[[0,12,13.69],[1,12.5,3.26],[2,13,25.39]],"ltp":11.0,"tv":1080.18,"id":24707172}],"tv":13499.77}]}
{"op":"mcm","clk":"994246263","pt":1580550547685,"mc":[{"id":"1.168130661","rc":[{"batb":[[0,32,3.24],[1,30,5.5]],"batl":[[1,36,42.3]],"ltp":34.0,"tv":155.52,"id":25545675},{"batb":[[0,11,8.56]],"ltp":11.0,"tv":1080.18,"id":24707172},{"batb":[[0,2.46,31.15]],"ltp":2.48,"tv":6447.05,"id":26314798}]}]}
{"op":"mcm","clk":"994246418","pt":1580550548691,"mc":[{"id":"1.168130661","rc":[{"batb":[[0,30,6.06],[1,29,2.3],[2,28,5.18]],"ltp":34.0,"tv":155.52,"id":25545675},{"trd":[[2.42,8.18],[2.44,97.46],[2.46,125.52]],"batb":[[0,2.44,4.04],[1,2.42,102.91],[2,2.3,6.79]],"batl":[[1,2.5,9]],"ltp":2.42,"tv":6615.0,"id":26314798}],"tv":13667.72}]}
{"op":"mcm","clk":"994246544","pt":1580550549721,"mc":[{"id":"1.168130661","rc":[{"batb":[[0,2.46,6.47],[1,2.44,4.04],[2,2.42,102.91]],"batl":[[0,2.5,9],[1,2.52,9.27],[2,2.54,19.26]],"ltp":2.42,"tv":6615.0,"id":26314798}]}]}
{"op":"mcm","clk":"994246674","pt":1580550550718,"mc":[{"id":"1.168130661","rc":[{"batb":[[0,30,2.55],[1,29,4.3]],"ltp":34.0,"tv":155.52,"id":25545675},{"trd":[[2.46,137.42],[2.48,21.74]],"batb":[[0,2.46,4.51],[2,2.42,98.91]],"batl":[[0,2.52,11.55],[1,2.54,19.26],[2,2.58,30]],"ltp":2.46,"tv":6635.0,"id":26314798}],"tv":13687.72}]}
{"op":"mcm","clk":"994246788","pt":1580550551605,"mc":[{"id":"1.168130661","rc":[{"batb":[[0,29,4.85],[1,28,5.18],[2,27,5.05]],"ltp":34.0,"tv":155.52,"id":25545675},{"batl":[[0,11.5,5.59],[1,12,13.1],[2,12.5,4.17]],"ltp":11.0,"tv":1080.18,"id":24707172}]}]}
{"op":"mcm","clk":"994246935","pt":1580550552707,"mc":[{"id":"1.168130661","rc":[{"batb":[[0,29,4.3]],"ltp":34.0,"tv":155.52,"id":25545675},{"batl":[[0,2.56,9.06],[1,2.58,30],[2,2.64,25.63]],"ltp":2.46,"tv":6635.0,"id":26314798}]}]}
{"op":"mcm","clk":"994247053","pt":1580550553640,"mc":[{"id":"1.168130661","rc":[{"batl":[[0,2.56,19.06]],"ltp":2.46,"tv":6635.0,"id":26314798}]}]}
{"op":"mcm","clk":"994247157","pt":1580550554636,"mc":[{"id":"1.168130661","rc":[{"batl":[[0,34,5.16]],"ltp":34.0,"tv":155.52,"id":25545675},{"trd":[[11,136.75]],"batb":[[0,11,3.56]],"ltp":11.0,"tv":1090.18,"id":24707172},{"batl":[[1,2.58,34.96]],"ltp":2.46,"tv":6635.0,"id":26314798}],"tv":13697.72}]}
{"op":"mcm","clk":"994247438","pt":1580550556715,"mc":[{"id":"1.168130661","rc":[{"batb":[[2,2.32,108]],"batl":[[0,2.54,13.48],[1,2.56,19.06],[2,2.58,34.96]],"ltp":2.46,"tv":6635.0,"id":26314798}]}]}
{"op":"mcm","clk":"994247563","pt":1580550557704,"mc":[{"id":"1.168130661","rc":[{"batl":[[2,2.58,30]],"ltp":2.46,"tv":6635.0,"id":26314798}]}]}
{"op":"mcm","clk":"994247829","pt":1580550559630,"mc":[{"id":"1.168130661","rc":[{"batb":[[2,2.34,6]],"ltp":2.46,"tv":6635.0,"id":26314798}]}]}
{"op":"mcm","clk":"994247940","pt":1580550560623,"mc":[{"id":"1.168130661","rc":[{"batb":[[1,28,5.81]],"ltp":34.0,"tv":155.52,"id":25545675}]}]}
{"op":"mcm","clk":"994249471","pt":1580550572665,"mc":[{"id":"1.168130661","rc":[{"trd":[[11,143.87]],"batb":[[0,10.5,11.36],[1,10,8.13],[2,9.8,4.13]],"batl":[[0,11,1.44],[1,11.5,5.59],[2,12,13.1]],"ltp":11.0,"tv":1097.3,"id":24707172}],"tv":13704.84}]}
{"op":"mcm","clk":"994249610","pt":1580550573720,"mc":[{"id":"1.168130661","rc":[{"trd":[[11,146.75]],"batb":[[1,10,12.97]],"batl":[[0,11.5,9.59],[1,12,13.1],[2,12.5,3.26]],"ltp":11.0,"tv":1100.18,"id":24707172}],"tv":13707.72}]}
{"op":"mcm","clk":"994249843","pt":1580550575644,"mc":[{"id":"1.168130661","rc":[{"batb":[[1,10,10.13]],"ltp":11.0,"tv":1100.18,"id":24707172}]}]}
{"op":"mcm","clk":"994251070","pt":1580550585667,"mc":[{"id":"1.168130661","rc":[{"batl":[[0,11.5,5.59]],"ltp":11.0,"tv":1100.18,"id":24707172},{"trd":[[2.46,149.42],[2.48,27.14]],"batb":[[0,2.42,5],[1,2.36,4.24]],"batl":[[0,2.46,2.3],[1,2.54,13.48],[2,2.56,19.06]],"ltp":2.48,"tv":6652.4,"id":26314798},{"batb":[[1,10,18.95]],"ltp":11.0,"tv":789.61,"id":420}],"tv":13725.13}]}
{"op":"mcm","clk":"994251181","pt":1580550586602,"mc":[{"id":"1.168130661","rc":[{"batl":[[1,2.54,2]],"ltp":2.48,"tv":6652.4,"id":26314798}]}]}
{"op":"mcm","clk":"994251416","pt":1580550588690,"mc":[{"id":"1.168130661","rc":[{"trd":[[34,12.52]],"batb":[[0,29,6.04]],"batl":[[0,34,2.99]],"ltp":34.0,"tv":155.69,"id":25545675},{"trd":[[3,61.68],[3.05,173.64],[3.1,66],[3.15,61.06]],"batb":[[0,3,8.25],[1,2.98,7.39],[2,2.96,2]],"batl":[[0,3.05,39.26],[1,3.1,3.26],[2,3.15,3.26]],"ltp":3.05,"tv":4292.23,"id":25238892},{"trd":[[11.5,22.82]],"batb":[[0,10.5,16.18]],"batl":[[0,11.5,5.1]],"ltp":11.5,"tv":1100.67,"id":24707172},{"trd":[[13.5,28.14]],"batb":[[0,13,5.9]],"batl":[[0,13.5,2.4]],"ltp":13.5,"tv":916.51,"id":24420205},{"trd":[[2.46,151.72]],"batb":[[0,2.44,4.25],[1,2.42,29.93]],"batl":[[0,2.54,13.48],[1,2.56,10],[2,2.58,39]],"ltp":2.46,"tv":6654.7,"id":26314798},{"trd":[[11.5,22.72]],"batb":[[0,10.5,30.71]],"batl":[[0,11.5,13.67]],"ltp":11.5,"tv":790.11,"id":420}],"tv":13909.94}]}
{"op":"mcm","clk":"994251542","pt":1580550589683,"mc":[{"id":"1.168130661","rc":[{"trd":[[3,69.62]],"batb":[[0,3,8.28],[1,2.98,24.32],[2,2.96,4.26]],"batl":[[1,3.1,10.35],[2,3.15,6]],"ltp":3.0,"tv":4300.17,"id":25238892},{"batl":[[2,2.58,35]],"ltp":2.46,"tv":6654.7,"id":26314798},{"batb":[[0,11,4.26],[1,10.5,32.71],[2,10,18.95]],"batl":[[0,11.5,11.67]],"ltp":11.5,"tv":790.11,"id":420}],"tv":13917.88}]}
{"op":"mcm","clk":"994251648","pt":1580550590571,"mc":[{"id":"1.168130661","rc":[{"batb":[[1,2.98,11.39]],"ltp":3.0,"tv":4300.17,"id":25238892},{"batb":[[2,2.3,6.79]],"ltp":2.46,"tv":6654.7,"id":26314798}]}]}
{"op":"mcm","clk":"994251780","pt":1580550591674,"mc":[{"id":"1.168130661","rc":[{"batl":[[1,2.58,35],[2,2.64,25.63]],"ltp":2.46,"tv":6654.7,"id":26314798}]}]}
{"op":"mcm","clk":"994251928","pt":1580550592670,"mc":[{"id":"1.168130661","rc":[{"batl":[[2,2.6,10]],"ltp":2.46,"tv":6654.7,"id":26314798}]}]}
{"op":"mcm","clk":"994252192","pt":1580550594699,"mc":[{"id":"1.168130661","rc":[{"batl":[[2,3.15,10]],"ltp":3.0,"tv":4300.17,"id":25238892}]}]}
{"op":"mcm","clk":"994252319","pt":1580550595688,"mc":[{"id":"1.168130661","rc":[{"batb":[[1,2.42,39.93],[2,2.38,11.05]],"batl":[[1,2.56,10.28],[2,2.58,35]],"ltp":2.46,"tv":6654.7,"id":26314798}]}]}
{"op":"mcm","clk":"994252468","pt":1580550596688,"mc":[{"id":"1.168130661","rc":[{"batb":[[0,29,6.57]],"ltp":34.0,"tv":155.69,"id":25545675}]}]}
{"op":"mcm","clk":"994253100","pt":1580550601583,"mc":[{"id":"1.168130661","rc":[{"trd":[[3,77.62]],"batb":[[0,3,4.28]],"batl":[[2,3.15,6]],"ltp":3.0,"tv":4308.17,"id":25238892}],"tv":13925.88}]}
{"op":"mcm","clk":"994253338","pt":1580550603400,"mc":[{"id":"1.168130661","rc":[{"batb":[[0,11,6.26],[2,10,16.95]],"ltp":11.5,"tv":790.11,"id":420}]}]}
{"op":"mcm","clk":"994253498","pt":1580550604659,"mc":[{"id":"1.168130661","rc":[{"batl":[[1,3.1,14.35]],"ltp":3.0,"tv":4308.17,"id":25238892}]}]}
{"op":"mcm","clk":"994253971","pt":1580550608630,"mc":[{"id":"1.168130661","rc":[{"trd":[[11.5,37.66]],"batl":[[0,11.5,4.2]],"ltp":11.5,"tv":805.04,"id":420}],"tv":13940.82}]}
{"op":"mcm","clk":"994254426","pt":1580550611701,"mc":[{"id":"1.168130661","rc":[{"trd":[[11.5,46.06]],"batb":[[0,11,7.06]],"batl":[[0,12,336.75],[1,12.5,10],[2,13,10]],"ltp":11.5,"tv":813.44,"id":420}],"tv":13949.22}]}
{"op":"mcm","clk":"994254517","pt":1580550612435,"mc":[{"id":"1.168130661","rc":[{"batb":[[2,10,25.58]],"ltp":11.5,"tv":813.44,"id":420}]}]}
{"op":"mcm","clk":"994256325","pt":1580550627464,"mc":[{"id":"1.168130661","rc":[{"batl":[[0,2.52,5.94],[1,2.54,13.48]],"ltp":2.46,"tv":6654.7,"id":26314798}]}]}
{"op":"mcm","clk":"994257497","pt":1580550637664,"mc":[{"id":"1.168130661","rc":[{"trd":[[3.05,238.52]],"batl":[[0,3.05,6.8]],"ltp":3.05,"tv":4373.06,"id":25238892},{"batl":[[0,2.52,10.94]],"ltp":2.46,"tv":6654.7,"id":26314798}],"tv":14014.1}]}
{"op":"mcm","clk":"994257639","pt":1580550638664,"mc":[{"id":"1.168130661","rc":[{"batb":[[0,2.48,4.2],[1,2.46,5],[2,2.44,4.25]],"ltp":2.46,"tv":6654.7,"id":26314798}]}]}
{"op":"mcm","clk":"994257761","pt":1580550639708,"mc":[{"id":"1.168130661","rc":[{"batb":[[0,30,3.89],[1,29,6.04],[2,28,5.81]],"ltp":34.0,"tv":155.69,"id":25545675},{"trd":[[3.05,252.12]],"batb":[[0,3.05,30.23],[1,3,4.28],[2,2.98,11.39]],"batl":[[0,3.1,8.35],[1,3.15,6],[2,3.2,8.09]],"ltp":3.05,"tv":4386.66,"id":25238892},{"batb":[[0,11,11.37],[1,10.5,16.18],[2,10,10.13]],"ltp":11.5,"tv":1100.67,"id":24707172},{"batb":[[0,13,13.65]],"ltp":13.5,"tv":916.51,"id":24420205},{"batb":[[0,2.5,44.3],[1,2.48,4.2],[2,2.46,9]],"batl":[[1,2.54,2]],"ltp":2.46,"tv":6654.7,"id":26314798},{"batb":[[0,11,16.22]],"ltp":11.5,"tv":813.44,"id":420}],"tv":14027.7}]}
{"op":"mcm","clk":"994257899","pt":1580550640698,"mc":[{"id":"1.168130661","rc":[{"trd":[[34,18.5]],"batb":[[0,34,5.21],[1,30,5.89],[2,29,6.04]],"batl":[[0,36,42.3],[1,46,13.47],[2,60,1.87]],"ltp":34.0,"tv":161.67,"id":25545675}],"tv":14033.68}]}
{"op":"mcm","clk":"994258035","pt":1580550641695,"mc":[{"id":"1.168130661","rc":[{"batb":[[1,32,2.22],[2,30,5.89]],"batl":[[1,44,6.78],[2,46,16.86]],"ltp":34.0,"tv":161.67,"id":25545675},{"batb":[[1,2.48,18.35]],"ltp":2.46,"tv":6654.7,"id":26314798}]}]}
{"op":"mcm","clk":"994258153","pt":1580550642686,"mc":[{"id":"1.168130661","rc":[{"trd":[[13,77.67]],"batb":[[0,13,3.65]],"ltp":13.0,"tv":936.51,"id":24420205}],"tv":14053.68}]}
{"op":"mcm","clk":"994258259","pt":1580550643684,"mc":[{"id":"1.168130661","rc":[{"batb":[[1,32,5.1]],"batl":[[1,44,10.17]],"ltp":34.0,"tv":161.67,"id":25545675},{"batb":[[0,13,5.65]],"ltp":13.0,"tv":936.51,"id":24420205}]}]}
{"op":"mcm","clk":"994258549","pt":1580550645710,"mc":[{"id":"1.168130661","rc":[{"trd":[[13,92.96]],"batb":[[0,12.5,9.53],[1,12,11.36],[2,11.5,2.1]],"batl":[[0,13,2.39]],"ltp":13.0,"tv":951.8,"id":24420205},{"trd":[[2.5,132.72]],"batb":[[0,2.5,41.3]],"ltp":2.5,"tv":6660.71,"id":26314798}],"tv":14074.98}]}
{"op":"mcm","clk":"994258803","pt":1580550647719,"mc":[{"id":"1.168130661","rc":[{"batb":[[1,12,6.6]],"ltp":13.0,"tv":951.8,"id":24420205}]}]}
{"op":"mcm","clk":"994259818","pt":1580550655722,"mc":[{"id":"1.168130661","rc":[{"batb":[[1,32,5.66]],"ltp":34.0,"tv":161.67,"id":25545675}]}]}
{"op":"mcm","clk":"994260262","pt":1580550659693,"mc":[{"id":"1.168130661","rc":[{"batl":[[0,2.52,5]],"ltp":2.5,"tv":6660.71,"id":26314798}]}]}
{"op":"mcm","clk":"994260603","pt":1580550662630,"mc":[{"id":"1.168130661","rc":[{"trd":[[3.05,256.13]],"batb":[[0,3.05,28.23]],"ltp":3.05,"tv":4390.66,"id":25238892}],"tv":14078.98}]}
{"op":"mcm","clk":"994263313","pt":1580550683646,"mc":[{"id":"1.168130661","rc":[{"trd":[[32,28.44],[34,28.92]],"batb":[[0,32,4.87],[1,30,5.89],[2,29,6.04]],"ltp":32.0,"tv":177.68,"id":25545675}],"tv":14094.98}]}
{"op":"mcm","clk":"994263441","pt":1580550684689,"mc":[{"id":"1.168130661","rc":[{"batb":[[0,32,2.55],[1,30,9.51]],"ltp":32.0,"tv":177.68,"id":25545675}]}]}
{"op":"mcm","clk":"994264925","pt":1580550697686,"mc":[{"id":"1.168130661","rc":[{"trd":[[2.5,171.14]],"batb":[[0,2.5,22.08]],"ltp":2.5,"tv":6699.12,"id":26314798}],"tv":14133.4}]}
{"op":"mcm","clk":"994265225","pt":1580550700715,"mc":[{"id":"1.168130661","rc":[{"batb":[[1,30,5.89]],"ltp":32.0,"tv":177.68,"id":25545675}]}]}
{"op":"mcm","clk":"994265341","pt":1580550701705,"mc":[{"id":"1.168130661","rc":[{"batb":[[0,32,2]],"ltp":32.0,"tv":177.68,"id":25545675}]}]}
{"op":"mcm","clk":"994266063","pt":1580550708690,"mc":[{"id":"1.168130661","rc":[{"batb":[[1,30,6.48]],"ltp":32.0,"tv":177.68,"id":25545675}]}]}
{"op":"mcm","clk":"994266275","pt":1580550710626,"mc":[{"id":"1.168130661","rc":[{"batb":[[0,11,15.42]],"ltp":11.5,"tv":813.44,"id":420}]}]}
{"op":"mcm","clk":"994266799","pt":1580550715635,"mc":[{"id":"1.168130661","rc":[{"trd":[[3.05,268.29]],"batb":[[0,3.05,22.15]],"ltp":3.05,"tv":4402.82,"id":25238892},{"trd":[[2.5,185.96]],"batb":[[0,2.5,14.66]],"ltp":2.5,"tv":6713.95,"id":26314798}],"tv":14160.38}]}
{"op":"mcm","clk":"994268016","pt":1580550726224,"mc":[{"id":"1.168130661","rc":[{"batb":[[2,10,41.13]],"ltp":11.5,"tv":1100.67,"id":24707172}]}]}
{"op":"mcm","clk":"994268400","pt":1580550729566,"mc":[{"id":"1.168130661","rc":[{"batb":[[1,2.48,9.32]],"ltp":2.5,"tv":6713.95,"id":26314798}]}]}
{"op":"mcm","clk":"994282535","pt":1580550763405,"mc":[{"id":"1.168130661","rc":[{"batl":[[0,3.1,41.6]],"ltp":3.05,"tv":4402.82,"id":25238892},{"batl":[[0,11.5,14.06]],"ltp":11.5,"tv":1100.67,"id":24707172},{"batl":[[0,13,10.32],[1,13.5,2.23],[2,14,7.36]],"ltp":13.0,"tv":951.8,"id":24420205},{"batl":[[0,2.52,45.9],[2,2.56,4.23]],"ltp":2.5,"tv":6713.95,"id":26314798},{"batl":[[0,11.5,8.96],[1,12,336.75],[2,12.5,10]],"ltp":11.5,"tv":813.44,"id":420}]}]}
{"op":"mcm","clk":"994282669","pt":1580550764704,"mc":[{"id":"1.168130661","rc":[{"batl":[[2,2.56,39.08]],"ltp":2.5,"tv":6713.95,"id":26314798}]}]}
{"op":"mcm","clk":"994283268","pt":1580550770621,"mc":[{"id":"1.168130661","rc":[{"batb":[[0,30,6.48],[1,29,6.04],[2,28,5.18]],"ltp":32.0,"tv":177.68,"id":25545675},{"trd":[[3.1,149.16]],"batb":[[0,3.1,40.14],[1,3.05,22.15],[2,3,4.28]],"batl":[[0,3.15,6],[1,3.2,8.09],[2,3.25,20.79]],"ltp":3.1,"tv":4485.98,"id":25238892},{"trd":[[11.5,50.93]],"batb":[[0,11.5,38.53],[1,11,11.37],[2,10.5,16.18]],"batl":[[0,12,14.09],[1,12.5,3.26],[2,13,26.23]],"ltp":11.5,"tv":1128.77,"id":24707172},{"trd":[[13,113.58]],"batb":[[0,13,28.09],[1,12.5,9.53],[2,12,6.6]],"batl":[[0,14,7.36],[1,14.5,2],[2,15,2]],"ltp":13.0,"tv":972.42,"id":24420205},{"batb":[[0,2.5,10.66]],"ltp":2.5,"tv":6713.95,"id":26314798},{"trd":[[11.5,67.32]],"batb":[[0,11.5,11.4],[1,11,15.42],[2,10.5,32.71]],"batl":[[0,12,336.75],[1,12.5,10],[2,13,10.84]],"ltp":11.5,"tv":834.71,"id":420}],"tv":14313.53}]}
{"op":"mcm","clk":"994283388","pt":1580550771657,"mc":[{"id":"1.168130661","rc":[{"batl":[[0,34,2.27],[1,36,42.3],[2,44,10.17]],"ltp":32.0,"tv":177.68,"id":25545675},{"trd":[[3.15,73.06]],"batb":[[0,3.15,4.1],[1,3.1,44.14],[2,3.05,22.15]],"batl":[[0,3.2,8.09],[1,3.25,20.79],[2,3.3,10.76]],"ltp":3.15,"tv":4497.98,"id":25238892},{"batl":[[0,12,39.48],[1,12.5,6.98],[2,13.5,28.84]],"ltp":11.5,"tv":1128.77,"id":24707172},{"trd":[[13,123.58]],"batb":[[0,13,25.1]],"batl":[[0,13.5,2.4],[1,14,2.36],[2,14.5,2]],"ltp":13.0,"tv":982.42,"id":24420205},{"trd":[[2.5,207.28]],"batb":[[0,2.48,5.12],[1,2.46,14],[2,2.44,4.25]],"batl":[[0,2.5,5.23],[1,2.52,54.9],[2,2.54,6.27]],"ltp":2.5,"tv":6735.27,"id":26314798}],"tv":14356.85}]}
{"op":"mcm","clk":"994283502","pt":1580550772648,"mc":[{"id":"1.168130661","rc":[{"trd":[[3.15,81.26]],"batb":[[0,3.1,44.14],[1,3.05,22.15],[2,3,4.28]],"batl":[[0,3.15,5.9],[1,3.2,8.09],[2,3.25,24.79]],"ltp":3.15,"tv":4506.18,"id":25238892},{"batl":[[0,12,38.49],[1,12.5,4.17]],"ltp":11.5,"tv":1128.77,"id":24707172},{"batb":[[0,2.46,14],[1,2.44,4.25],[2,2.42,25.93]],"batl":[[0,2.5,7.23]],"ltp":2.5,"tv":6735.27,"id":26314798}],"tv":14365.05}]}
{"op":"mcm","clk":"994283610","pt":1580550773630,"mc":[{"id":"1.168130661","rc":[{"batb":[[0,3.1,47.14]],"ltp":3.15,"tv":4506.18,"id":25238892},{"batb":[[0,11.5,40.53]],"ltp":11.5,"tv":1128.77,"id":24707172},{"trd":[[2.5,213.28]],"batl":[[0,2.5,7]],"ltp":2.5,"tv":6741.27,"id":26314798}],"tv":14371.05}]}
{"op":"mcm","clk":"994283724","pt":1580550774662,"mc":[{"id":"1.168130661","rc":[{"batb":[[1,2.44,9.56]],"ltp":2.5,"tv":6741.27,"id":26314798}]}]}
{"op":"mcm","clk":"994283830","pt":1580550775549,"mc":[{"id":"1.168130661","rc":[{"batl":[[0,2.5,21]],"ltp":2.5,"tv":6741.27,"id":26314798}]}]}
{"op":"mcm","clk":"994284185","pt":1580550778661,"mc":[{"id":"1.168130661","rc":[{"batb":[[0,3.1,7]],"ltp":3.15,"tv":4506.18,"id":25238892},{"trd":[[11.5,54.93]],"batb":[[0,11,11.37],[1,10.5,16.18],[2,10,39.13]],"batl":[[0,11.5,4.28],[1,12,38.49],[2,12.5,4.17]],"ltp":11.5,"tv":1132.77,"id":24707172},{"batb":[[0,13,2]],"ltp":13.0,"tv":982.42,"id":24420205},{"batl":[[0,2.5,16]],"ltp":2.5,"tv":6741.27,"id":26314798},{"batb":[[0,11,15.42],[1,10.5,32.71],[2,10,25.58]],"batl":[[2,13,10]],"ltp":11.5,"tv":834.71,"id":420}],"tv":14375.05}]}
{"op":"mcm","clk":"994284309","pt":1580550779651,"mc":[{"id":"1.168130661","rc":[{"batl":[[2,12.5,3.26]],"ltp":11.5,"tv":1132.77,"id":24707172}]}]}
{"op":"mcm","clk":"994284404","pt":1580550780636,"mc":[{"id":"1.168130661","rc":[{"batb":[[1,10.5,19.01]],"ltp":11.5,"tv":1132.77,"id":24707172},{"batb":[[2,12,11.13]],"ltp":13.0,"tv":982.42,"id":24420205}]}]}
{"op":"mcm","clk":"994284531","pt":1580550781679,"mc":[{"id":"1.168130661","rc":[{"batb":[[1,10.5,16.18]],"ltp":11.5,"tv":1132.77,"id":24707172},{"batb":[[2,12,6.6]],"ltp":13.0,"tv":982.42,"id":24420205}]}]}
{"op":"mcm","clk":"994284642","pt":1580550782678,"mc":[{"id":"1.168130661","rc":[{"batl":[[0,13.5,5.4]],"ltp":13.0,"tv":982.42,"id":24420205},{"trd":[[11,154.29]],"batb":[[0,11,15.17]],"ltp":11.0,"tv":835.21,"id":420}],"tv":14375.55}]}
{"op":"mcm","clk":"994284756","pt":1580550783564,"mc":[{"id":"1.168130661","rc":[{"trd":[[3.1,149.66]],"batb":[[0,3.1,6.75]],"ltp":3.1,"tv":4506.68,"id":25238892}],"tv":14376.05}]}
{"op":"mcm","clk":"994284968","pt":1580550785681,"mc":[{"id":"1.168130661","rc":[{"batl":[[0,11.5,10],[1,12,336.75],[2,12.5,10]],"ltp":11.0,"tv":835.21,"id":420}]}]}
{"op":"mcm","clk":"994285086","pt":1580550786673,"mc":[{"id":"1.168130661","rc":[{"batl":[[1,12,42.49]],"ltp":11.5,"tv":1132.77,"id":24707172}]}]}
{"op":"mcm","clk":"994285203","pt":1580550787670,"mc":[{"id":"1.168130661","rc":[{"batl":[[1,3.2,5.88]],"ltp":3.1,"tv":4506.68,"id":25238892},{"batl":[[0,2.5,16.25]],"ltp":2.5,"tv":6741.27,"id":26314798},{"trd":[[11,174.3]],"batb":[[0,11,8.17]],"batl":[[1,12,338.75]],"ltp":11.0,"tv":855.21,"id":420}],"tv":14396.05}]}
{"op":"mcm","clk":"994285313","pt":1580550788704,"mc":[{"id":"1.168130661","rc":[{"trd":[[11.5,63.48]],"batb":[[0,11.5,36.25],[1,11,11.37],[2,10.5,16.18]],"batl":[[0,12,39.49],[1,12.5,4.17],[2,13.5,28.84]],"ltp":11.5,"tv":1141.33,"id":24707172},{"batb":[[1,10.5,42.71]],"ltp":11.0,"tv":855.21,"id":420}],"tv":14404.61}]}
{"op":"mcm","clk":"994285446","pt":1580550789690,"mc":[{"id":"1.168130661","rc":[{"trd":[[3.1,150.16]],"batb":[[0,3.1,6.5]],"ltp":3.1,"tv":4507.18,"id":25238892}],"tv":14405.11}]}
{"op":"mcm","clk":"994285566","pt":1580550790679,"mc":[{"id":"1.168130661","rc":[{"trd":[[3.1,163.16]],"batb":[[0,3.05,22.15],[1,3,4.28],[2,2.98,11.39]],"batl":[[0,3.1,3.5],[1,3.15,5.9],[2,3.2,5.88]],"ltp":3.1,"tv":4520.18,"id":25238892}],"tv":14418.11}]}
{"op":"mcm","clk":"994285674","pt":1580550791679,"mc":[{"id":"1.168130661","rc":[{"trd":[[3.1,170.16]],"batb":[[1,3,14.28]],"batl":[[0,3.15,5.9],[1,3.2,7.88],[2,3.25,24.79]],"ltp":3.1,"tv":4527.18,"id":25238892}],"tv":14425.11}]}
{"op":"mcm","clk":"994285769","pt":1580550792666,"mc":[{"id":"1.168130661","rc":[{"batb":[[1,3,24.28]],"ltp":3.1,"tv":4527.18,"id":25238892}]}]}
{"op":"mcm","clk":"994286180","pt":1580550796608,"mc":[{"id":"1.168130661","rc":[{"batl":[[0,3.1,10],[1,3.15,5.9],[2,3.2,7.88]],"ltp":3.1,"tv":4527.18,"id":25238892}]}]}
{"op":"mcm","clk":"994286260","pt":1580550797678,"mc":[{"id":"1.168130661","rc":[{"batb":[[0,11.5,2]],"ltp":11.5,"tv":1141.33,"id":24707172}]}]}
{"op":"mcm","clk":"994286353","pt":1580550798660,"mc":[{"id":"1.168130661","rc":[{"batb":[[2,10.5,29.15]],"batl":[[0,12,38.49]],"ltp":11.5,"tv":1141.33,"id":24707172}]}]}
{"op":"mcm","clk":"994286691","pt":1580550801687,"mc":[{"id":"1.168130661","rc":[{"batb":[[0,11,10.17]],"ltp":11.0,"tv":855.21,"id":420}]}]}
{"op":"mcm","clk":"994287331","pt":1580550807625,"mc":[{"id":"1.168130661","rc":[{"trd":[[11.5,87.31]],"batb":[[0,11.5,1.41],[1,11,10.17],[2,10.5,42.71]],"batl":[[0,12,338.75],[1,12.5,10],[2,13,10]],"ltp":11.5,"tv":875.2,"id":420}],"tv":14445.09}]}
{"op":"mcm","clk":"994287437","pt":1580550808616,"mc":[{"id":"1.168130661","rc":[{"batb":[[2,10.5,16.18]],"ltp":11.5,"tv":1141.33,"id":24707172}]}]}
{"op":"mcm","clk":"994287981","pt":1580550813614,"mc":[{"id":"1.168130661","rc":[{"trd":[[11.5,90.13]],"batb":[[0,11,10.17],[1,10.5,42.71],[2,10,25.58]],"batl":[[0,11.5,8.59],[1,12,338.75],[2,12.5,10]],"ltp":11.5,"tv":878.02,"id":420}],"tv":14447.91}]}
{"op":"mcm","clk":"994289649","pt":1580550827671,"mc":[{"id":"1.168130661","rc":[{"trd":[[13,127.58]],"batb":[[0,12.5,9.53],[1,12,6.6],[2,11.5,2.1]],"batl":[[0,13,3],[1,13.5,5.4],[2,14,2.36]],"ltp":13.0,"tv":986.42,"id":24420205}],"tv":14451.91}]}
{"op":"mcm","clk":"994289748","pt":1580550828658,"mc":[{"id":"1.168130661","rc":[{"trd":[[13,131.58]],"batl":[[0,13,1],[1,13.5,3]],"ltp":13.0,"tv":990.42,"id":24420205}],"tv":14455.91}]}
{"op":"mcm","clk":"994290022","pt":1580550830659,"mc":[{"id":"1.168130661","rc":[{"trd":[[12,55.62]],"batl":[[0,12,14.78]],"ltp":12.0,"tv":1188.75,"id":24707172}],"tv":14503.33}]}
{"op":"mcm","clk":"994290472","pt":1580550834459,"mc":[{"id":"1.168130661","rc":[{"trd":[[2.5,217.28]],"batl":[[0,2.5,14.25]],"ltp":2.5,"tv":6745.27,"id":26314798}],"tv":14507.33}]}
{"op":"mcm","clk":"994290705","pt":1580550836691,"mc":[{"id":"1.168130661","rc":[{"trd":[[3.1,190.15]],"batb":[[0,3.1,34.15],[1,3.05,22.15],[2,3,24.28]],"batl":[[0,3.15,5.9],[1,3.2,7.88],[2,3.25,24.79]],"ltp":3.1,"tv":4547.17,"id":25238892}],"tv":14527.32}]}
{"op":"mcm","clk":"994290829","pt":1580550837633,"mc":[{"id":"1.168130661","rc":[{"batb":[[2,10.5,18.68]],"batl":[[0,12,15.77]],"ltp":12.0,"tv":1188.75,"id":24707172}]}]}
{"op":"mcm","clk":"994291383","pt":1580550842699,"mc":[{"id":"1.168130661","rc":[{"trd":[[3.1,203.76]],"batb":[[0,3.1,27.34]],"ltp":3.1,"tv":4560.78,"id":25238892},{"batb":[[0,2.46,16]],"ltp":2.5,"tv":6745.27,"id":26314798}],"tv":14540.93}]}
{"op":"mcm","clk":"994291789","pt":1580550845698,"mc":[{"id":"1.168130661","rc":[{"batb":[[0,3.1,4]],"ltp":3.1,"tv":4560.78,"id":25238892}]}]}
{"op":"mcm","clk":"994292406","pt":1580550850709,"mc":[{"id":"1.168130661","rc":[{"batl":[[0,12,14.78]],"ltp":12.0,"tv":1188.75,"id":24707172}]}]}
{"op":"mcm","clk":"994292501","pt":1580550851679,"mc":[{"id":"1.168130661","rc":[{"batl":[[0,12,15.77]],"ltp":12.0,"tv":1188.75,"id":24707172}]}]}
{"op":"mcm","clk":"994292636","pt":1580550852720,"mc":[{"id":"1.168130661","rc":[{"batl":[[0,12,14.78]],"ltp":12.0,"tv":1188.75,"id":24707172}]}]}
{"op":"mcm","clk":"994292776","pt":1580550853716,"mc":[{"id":"1.168130661","rc":[{"batl":[[0,12,15.77]],"ltp":12.0,"tv":1188.75,"id":24707172}]}]}
{"op":"mcm","clk":"994293034","pt":1580550855706,"mc":[{"id":"1.168130661","rc":[{"batl":[[0,12,14.78]],"ltp":12.0,"tv":1188.75,"id":24707172}]}]}
{"op":"mcm","clk":"994293258","pt":1580550857705,"mc":[{"id":"1.168130661","rc":[{"batl":[[0,12,15.77]],"ltp":12.0,"tv":1188.75,"id":24707172}]}]}
{"op":"mcm","clk":"994293366","pt":1580550858692,"mc":[{"id":"1.168130661","rc":[{"batl":[[0,12,14.78]],"ltp":12.0,"tv":1188.75,"id":24707172}]}]}
{"op":"mcm","clk":"994293477","pt":1580550859619,"mc":[{"id":"1.168130661","rc":[{"trd":[[12.5,108.61]],"batb":[[0,13,2.1],[1,12.5,8.53],[2,12,6.6]],"batl":[[0,13.5,3],[1,14,2.36],[2,14.5,2]],"ltp":12.5,"tv":992.42,"id":24420205}],"tv":14542.93}]}
{"op":"mcm","clk":"994294273","pt":1580550866717,"mc":[{"id":"1.168130661","rc":[{"trd":[[11.5,73.48]],"batb":[[0,11,11.37],[1,10.5,18.68],[2,10,39.13]],"batl":[[1,12.5,3.26]],"ltp":11.5,"tv":1198.75,"id":24707172}],"tv":14552.93}]}
{"op":"mcm","clk":"994294389","pt":1580550867646,"mc":[{"id":"1.168130661","rc":[{"batb":[[0,11.5,6.38],[1,11,11.37],[2,10.5,18.68]],"batl":[[1,12.5,4.17],[2,13.5,28.8]],"ltp":11.5,"tv":1198.75,"id":24707172}]}]}
{"op":"mcm","clk":"994294487","pt":1580550868632,"mc":[{"id":"1.168130661","rc":[{"batb":[[0,11.5,8.38],[2,10.5,16.18]],"ltp":11.5,"tv":1198.75,"id":24707172}]}]}
{"op":"mcm","clk":"994295580","pt":1580550877666,"mc":[{"id":"1.168130661","rc":[{"trd":[[11,183.5]],"batb":[[0,11,5.57]],"ltp":11.0,"tv":887.22,"id":420}],"tv":14562.13}]}
{"op":"mcm","clk":"994296915","pt":1580550888690,"mc":[{"id":"1.168130661","rc":[{"trd":[[34,32.41]],"batl":[[0,36,42.3],[1,44,10.17],[2,46,13.47]],"ltp":34.0,"tv":181.17,"id":25545675},{"trd":[[3.05,339.41],[3.1,211.76]],"batb":[[0,3,24.28],[1,2.98,11.39],[2,2.96,13]],"ltp":3.05,"tv":4639.91,"id":25238892},{"trd":[[12,58.59]],"batl":[[0,12,11.81]],"ltp":12.0,"tv":1201.72,"id":24707172},{"trd":[[13.5,31.5]],"batl":[[0,13.5,2.4],[1,14.5,2.36],[2,15,2]],"ltp":13.5,"tv":995.78,"id":24420205},{"trd":[[2.5,231.53]],"batb":[[0,2.48,14.11],[1,2.46,19],[2,2.44,12.31]],"batl":[[0,2.52,50.9],[1,2.54,6.27],[2,2.56,22.32]],"ltp":2.5,"tv":6759.52,"id":26314798},{"trd":[[11.5,93.23]],"batl":[[0,11.5,5.49],[1,12,336.75]],"ltp":11.5,"tv":890.32,"id":420}],"tv":14668.43}]}
{"op":"mcm","clk":"994297033","pt":1580550889675,"mc":[{"id":"1.168130661","rc":[{"batb":[[0,3.05,3.26],[1,3,24.28],[2,2.98,18.44]],"ltp":3.05,"tv":4639.91,"id":25238892},{"batb":[[0,2.48,22.11]],"batl":[[0,2.52,53.9]],"ltp":2.5,"tv":6759.52,"id":26314798}]}]}
{"op":"mcm","clk":"994297148","pt":1580550890664,"mc":[{"id":"1.168130661","rc":[{"batb":[[2,2.98,11.39]],"ltp":3.05,"tv":4639.91,"id":25238892},{"batl":[[0,13.5,6.76],[1,14,2.63],[2,14.5,2]],"ltp":13.5,"tv":995.78,"id":24420205}]}]}
{"op":"mcm","clk":"994297372","pt":1580550892676,"mc":[{"id":"1.168130661","rc":[{"batb":[[1,2.46,26.59]],"ltp":2.5,"tv":6759.52,"id":26314798}]}]}
{"op":"mcm","clk":"994297476","pt":1580550893712,"mc":[{"id":"1.168130661","rc":[{"batb":[[0,34,5],[1,30,6.48],[2,29,6.04]],"ltp":34.0,"tv":181.17,"id":25545675}]}]}
{"op":"mcm","clk":"994297589","pt":1580550894696,"mc":[{"id":"1.168130661","rc":[{"batb":[[1,32,2.29],[2,30,6.48]],"ltp":34.0,"tv":181.17,"id":25545675}]}]}
{"op":"mcm","clk":"994297906","pt":1580550897674,"mc":[{"id":"1.168130661","rc":[{"batb":[[0,2.48,14.11]],"batl":[[1,2.54,99.53]],"ltp":2.5,"tv":6759.52,"id":26314798}]}]}
{"op":"mcm","clk":"994298028","pt":1580550898707,"mc":[{"id":"1.168130661","rc":[{"batl":[[0,2.52,76.59],[2,2.58,30]],"ltp":2.5,"tv":6759.52,"id":26314798}]}]}
{"op":"mcm","clk":"994299344","pt":1580550909630,"mc":[{"id":"1.168130661","rc":[{"batb":[[1,32,4.51]],"ltp":34.0,"tv":181.17,"id":25545675},{"batb":[[1,2.46,19]],"ltp":2.5,"tv":6759.52,"id":26314798}]}]}
{"op":"mcm","clk":"994299882","pt":1580550914624,"mc":[{"id":"1.168130661","rc":[{"batb":[[0,34,7],[2,30,5.89]],"ltp":34.0,"tv":181.17,"id":25545675},{"trd":[[3.05,358.03]],"batb":[[0,3,24.28],[1,2.98,11.39],[2,2.96,13]],"batl":[[0,3.05,15.69],[1,3.15,5.9],[2,3.2,7.88]],"ltp":3.05,"tv":4658.53,"id":25238892},{"batb":[[0,2.48,22.11]],"batl":[[0,2.52,73.59]],"ltp":2.5,"tv":6759.52,"id":26314798}],"tv":14687.05}]}
{"op":"mcm","clk":"994300112","pt":1580550916643,"mc":[{"id":"1.168130661","rc":[{"batb":[[1,2.98,19.48]],"ltp":3.05,"tv":4658.53,"id":25238892}]}]}
{"op":"mcm","clk":"994300545","pt":1580550920651,"mc":[{"id":"1.168130661","rc":[{"trd":[[36,50.16]],"batb":[[0,34,5]],"batl":[[0,36,25.12]],"ltp":36.0,"tv":215.51,"id":25545675},{"trd":[[3.05,389.4]],"batb":[[0,3.05,11.05],[1,3,24.28],[2,2.98,19.48]],"batl":[[0,3.15,5.9],[1,3.2,7.88],[2,3.25,27.79]],"ltp":3.05,"tv":4689.9,"id":25238892},{"trd":[[12,82.2]],"batb":[[0,12,23.02],[1,11.5,8.38],[2,11,11.37]],"batl":[[0,12.5,4.17],[1,13.5,28.8],[2,15,77.74]],"ltp":12.0,"tv":1225.33,"id":24707172},{"batb":[[0,2.48,14.11]],"batl":[[0,2.52,76.59]],"ltp":2.5,"tv":6759.52,"id":26314798}],"tv":14776.37}]}
{"op":"mcm","clk":"994300668","pt":1580550921708,"mc":[{"id":"1.168130661","rc":[{"batl":[[2,3.25,36.54]],"ltp":3.05,"tv":4689.9,"id":25238892},{"batl":[[0,13,9.1],[1,13.5,28],[2,15,78.51]],"ltp":12.0,"tv":1225.33,"id":24707172},{"batb":[[0,12.5,8.53],[1,12,6.6],[2,11.5,2.1]],"ltp":13.5,"tv":995.78,"id":24420205},{"batb":[[1,2.46,28.07]],"batl":[[0,2.5,3.11],[1,2.52,76.59],[2,2.54,99.53]],"ltp":2.5,"tv":6759.52,"id":26314798},{"batb":[[0,11,2.57]],"ltp":11.5,"tv":890.32,"id":420}]}]}
{"op":"mcm","clk":"994300782","pt":1580550922638,"mc":[{"id":"1.168130661","rc":[{"batb":[[1,32,5.06]],"ltp":36.0,"tv":215.51,"id":25545675},{"batl":[[0,3.1,5.57],[1,3.15,5.9],[2,3.2,7.88]],"ltp":3.05,"tv":4689.9,"id":25238892},{"batb":[[0,12.5,2.12],[1,12,23.02],[2,11.5,8.38]],"batl":[[0,13.5,31],[1,15,78.51],[2,15.5,2.55]],"ltp":12.0,"tv":1225.33,"id":24707172},{"batl":[[0,13.5,4]],"ltp":13.5,"tv":995.78,"id":24420205},{"batb":[[1,2.46,19]],"ltp":2.5,"tv":6759.52,"id":26314798}]}]}
{"op":"mcm","clk":"994300913","pt":1580550923625,"mc":[{"id":"1.168130661","rc":[{"batl":[[0,13.5,31.8]],"ltp":12.0,"tv":1225.33,"id":24707172}]}]}
{"op":"mcm","clk":"994301020","pt":1580550924659,"mc":[{"id":"1.168130661","rc":[{"batb":[[2,11.5,2]],"batl":[[1,14.5,12.61],[2,15,83.65]],"ltp":12.0,"tv":1225.33,"id":24707172}]}]}
{"op":"mcm","clk":"994301128","pt":1580550925645,"mc":[{"id":"1.168130661","rc":[{"trd":[[12.5,26.04]],"batb":[[0,12,23.54],[1,11.5,2],[2,11,9.16]],"batl":[[1,14.5,14.81]],"ltp":12.5,"tv":1228.53,"id":24707172}],"tv":14779.57}]}
{"op":"mcm","clk":"994301258","pt":1580550926695,"mc":[{"id":"1.168130661","rc":[{"batb":[[0,12,21.02],[1,11,9.16],[2,10.5,14.18]],"batl":[[0,13.5,31],[1,14.5,14.79]],"ltp":12.5,"tv":1228.53,"id":24707172},{"batl":[[0,2.5,5.11]],"ltp":2.5,"tv":6759.52,"id":26314798}]}]}
{"op":"mcm","clk":"994301351","pt":1580550927672,"mc":[{"id":"1.168130661","rc":[{"batb":[[0,12.5,2.14],[1,12,21.02],[2,11,21.8]],"batl":[[0,13.5,31.8]],"ltp":12.5,"tv":1228.53,"id":24707172}]}]}
{"op":"mcm","clk":"994301460","pt":1580550928662,"mc":[{"id":"1.168130661","rc":[{"batb":[[0,3.05,3]],"ltp":3.05,"tv":4689.9,"id":25238892},{"batb":[[0,11.5,2.15],[1,11,15.49],[2,10.5,14.18]],"ltp":12.5,"tv":1228.53,"id":24707172}]}]}
{"op":"mcm","clk":"994301587","pt":1580550929649,"mc":[{"id":"1.168130661","rc":[{"batl":[[0,13.5,31],[1,14.5,14.04]],"ltp":12.5,"tv":1228.53,"id":24707172}]}]}
{"op":"mcm","clk":"994301756","pt":1580550930630,"mc":[{"id":"1.168130661","rc":[{"batb":[[2,2.98,11.39]],"ltp":3.05,"tv":4689.9,"id":25238892},{"batb":[[1,11,11.81]],"ltp":12.5,"tv":1228.53,"id":24707172}]}]}
{"op":"mcm","clk":"994301876","pt":1580550931666,"mc":[{"id":"1.168130661","rc":[{"batb":[[1,11,9.16]],"ltp":12.5,"tv":1228.53,"id":24707172}]}]}
{"op":"mcm","clk":"994302150","pt":1580550933644,"mc":[{"id":"1.168130661","rc":[{"batl":[[0,13,7],[1,13.5,31],[2,14.5,14.04]],"ltp":12.5,"tv":1228.53,"id":24707172}]}]}
{"op":"mcm","clk":"994302368","pt":1580550935673,"mc":[{"id":"1.168130661","rc":[{"batl":[[2,15,77.74]],"ltp":12.5,"tv":1228.53,"id":24707172},{"batl":[[0,2.5,2]],"ltp":2.5,"tv":6759.52,"id":26314798},{"batb":[[0,11,6.76]],"ltp":11.5,"tv":890.32,"id":420}]}]}
{"op":"mcm","clk":"994303301","pt":1580550943709,"mc":[{"id":"1.168130661","rc":[{"batb":[[2,2.44,17.31]],"batl":[[0,2.5,7]],"ltp":2.5,"tv":6759.52,"id":26314798}]}]}
{"op":"mcm","clk":"994303844","pt":1580550948700,"mc":[{"id":"1.168130661","rc":[{"batb":[[2,2.44,22.31]],"batl":[[0,2.5,12]],"ltp":2.5,"tv":6759.52,"id":26314798}]}]}
{"op":"mcm","clk":"994304669","pt":1580550955617,"mc":[{"id":"1.168130661","rc":[{"trd":[[3.1,251.76]],"batl":[[0,3.1,4.27]],"ltp":3.1,"tv":4729.9,"id":25238892},{"batb":[[0,11,2.57]],"ltp":11.5,"tv":890.32,"id":420}],"tv":14819.57}]}
{"op":"mcm","clk":"994305432","pt":1580550961693,"mc":[{"id":"1.168130661","rc":[{"batb":[[0,11,6.57]],"ltp":11.5,"tv":890.32,"id":420}]}]}
{"op":"mcm","clk":"994306019","pt":1580550966592,"mc":[{"id":"1.168130661","rc":[{"trd":[[2.5,255.53]],"batb":[[0,2.5,18],[1,2.48,23.11],[2,2.46,19]],"batl":[[0,2.52,76.59],[1,2.54,99.53],[2,2.58,30]],"ltp":2.5,"tv":6783.52,"id":26314798}],"tv":14843.57}]}
{"op":"mcm","clk":"994306344","pt":1580550969622,"mc":[{"id":"1.168130661","rc":[{"batb":[[1,2.48,29.33]],"ltp":2.5,"tv":6783.52,"id":26314798}]}]}
{"op":"mcm","clk":"994307042","pt":1580550975219,"mc":[{"id":"1.168130661","rc":[{"batb":[[0,12,6.4],[1,11.5,2.15],[2,11,9.16]],"ltp":12.5,"tv":1228.53,"id":24707172},{"batl":[[0,2.52,73.59]],"ltp":2.5,"tv":6783.52,"id":26314798}]}]}
{"op":"mcm","clk":"994308477","pt":1580550987666,"mc":[{"id":"1.168130661","rc":[{"trd":[[2.5,285.53]],"batb":[[0,2.5,3]],"ltp":2.5,"tv":6813.52,"id":26314798}],"tv":14873.57}]}
{"op":"mcm","clk":"994308730","pt":1580550989658,"mc":[{"id":"1.168130661","rc":[{"batl":[[0,13,3]],"ltp":12.5,"tv":1228.53,"id":24707172}]}]}
{"op":"mcm","clk":"994309844","pt":1580550999670,"mc":[{"id":"1.168130661","rc":[{"batb":[[1,2.48,23.11]],"ltp":2.5,"tv":6813.52,"id":26314798}]}]}
{"op":"mcm","clk":"994310879","pt":1580551009262,"mc":[{"id":"1.168130661","rc":[{"trd":[[2.52,253.48]],"batl":[[0,2.52,58.41]],"ltp":2.52,"tv":6843.88,"id":26314798}],"tv":14903.93}]}
{"op":"mcm","clk":"994311626","pt":1580551016626,"mc":[{"id":"1.168130661","rc":[{"batl":[[0,3.1,16.27]],"ltp":3.1,"tv":4729.9,"id":25238892}]}]}
{"op":"mcm","clk":"994316128","pt":1580551054688,"mc":[{"id":"1.168130661","rc":[{"batb":[[0,32,5.06],[1,30,13.19],[2,29,4.04]],"ltp":36.0,"tv":215.51,"id":25545675}]}]}
{"op":"mcm","clk":"994316247","pt":1580551055683,"mc":[{"id":"1.168130661","rc":[{"batb":[[0,32,2.84]],"ltp":36.0,"tv":215.51,"id":25545675}]}]}
{"op":"mcm","clk":"994317043","pt":1580551062710,"mc":[{"id":"1.168130661","rc":[{"trd":[[2.52,277.48]],"batl":[[0,2.52,46.41]],"ltp":2.52,"tv":6867.88,"id":26314798}],"tv":14927.93}]}
{"op":"mcm","clk":"994317948","pt":1580551069703,"mc":[{"id":"1.168130661","rc":[{"trd":[[12,95]],"batb":[[0,11.5,6.38],[1,11,15.05],[2,10.5,14.18]],"batl":[[0,12,8.6],[1,13,3],[2,13.5,31]],"ltp":12.0,"tv":1241.33,"id":24707172},{"trd":[[12.5,129.68]],"batb":[[0,12,6.6],[1,11.5,8.42],[2,11,11.75]],"batl":[[0,12.5,4.46],[1,13,2.27],[2,13.5,4]],"ltp":12.5,"tv":1016.85,"id":24420205},{"batb":[[0,2.5,12.27]],"ltp":2.52,"tv":6867.88,"id":26314798}],"tv":14961.8}]}
{"op":"mcm","clk":"994318077","pt":1580551070694,"mc":[{"id":"1.168130661","rc":[{"trd":[[12,112.19]],"batb":[[0,12,12.43],[1,11.5,6.38],[2,11,15.05]],"batl":[[0,13,3],[1,13.5,31],[2,15,77.74]],"ltp":12.0,"tv":1258.52,"id":24707172},{"trd":[[12.5,138.6]],"batb":[[0,12.5,21.57],[1,12,6.6],[2,11.5,8.42]],"batl":[[0,13.5,6],[1,14,2.63],[2,14.5,2]],"ltp":12.5,"tv":1025.77,"id":24420205},{"batb":[[0,2.5,3]],"ltp":2.52,"tv":6867.88,"id":26314798}],"tv":14987.91}]}
{"op":"mcm","clk":"994318199","pt":1580551071723,"mc":[{"id":"1.168130661","rc":[{"batb":[[2,2.98,14.35]],"ltp":3.1,"tv":4729.9,"id":25238892},{"batl":[[2,14.5,2.2]],"ltp":12.0,"tv":1258.52,"id":24707172},{"batb":[[1,2.48,27.44]],"batl":[[0,2.52,49.41]],"ltp":2.52,"tv":6867.88,"id":26314798},{"trd":[[11,186.86]],"batb":[[0,10.5,43.59],[1,10,25.58],[2,9.8,15]],"ltp":11.0,"tv":893.68,"id":420}],"tv":14991.27}]}
{"op":"mcm","clk":"994318311","pt":1580551072713,"mc":[{"id":"1.168130661","rc":[{"batb":[[2,2.98,11.39]],"ltp":3.1,"tv":4729.9,"id":25238892},{"batl":[[2,15,77.74]],"ltp":12.0,"tv":1258.52,"id":24707172},{"batb":[[1,2.48,23.11]],"ltp":2.52,"tv":6867.88,"id":26314798}]}]}
{"op":"mcm","clk":"994318849","pt":1580551076722,"mc":[{"id":"1.168130661","rc":[{"batb":[[0,10.5,42.71]],"ltp":11.0,"tv":893.68,"id":420}]}]}
{"op":"mcm","clk":"994319204","pt":1580551079638,"mc":[{"id":"1.168130661","rc":[{"batb":[[0,11.5,6.38],[1,11,15.05],[2,10.5,14.18]],"ltp":12.0,"tv":1258.52,"id":24707172},{"batb":[[0,12.5,2]],"ltp":12.5,"tv":1025.77,"id":24420205}]}]}
{"op":"mcm","clk":"994319320","pt":1580551080575,"mc":[{"id":"1.168130661","rc":[{"batb":[[1,11,21.53]],"ltp":12.0,"tv":1258.52,"id":24707172},{"batb":[[2,11.5,14.59]],"ltp":12.5,"tv":1025.77,"id":24420205}]}]}
{"op":"mcm","clk":"994320107","pt":1580551086637,"mc":[{"id":"1.168130661","rc":[{"trd":[[3.1,271.76]],"batl":[[0,3.1,6.27]],"ltp":3.1,"tv":4749.9,"id":25238892}],"tv":15011.27}]}
{"op":"mcm","clk":"994320955","pt":1580551093651,"mc":[{"id":"1.168130661","rc":[{"batb":[[1,11,9.16]],"ltp":12.0,"tv":1258.52,"id":24707172},{"batb":[[2,11.5,2.1]],"ltp":12.5,"tv":1025.77,"id":24420205}]}]}
{"op":"mcm","clk":"994321312","pt":1580551096616,"mc":[{"id":"1.168130661","rc":[{"batb":[[0,10.5,44.71]],"ltp":11.0,"tv":893.68,"id":420}]}]}
{"op":"mcm","clk":"994321645","pt":1580551099631,"mc":[{"id":"1.168130661","rc":[{"batb":[[0,12.5,6.25]],"ltp":12.5,"tv":1025.77,"id":24420205}]}]}
{"op":"mcm","clk":"994321906","pt":1580551101706,"mc":[{"id":"1.168130661","rc":[{"batl":[[0,11,23],[1,11.5,5.49],[2,12,336.75]],"ltp":11.0,"tv":893.68,"id":420}]}]}
{"op":"mcm","clk":"994322011","pt":1580551102645,"mc":[{"id":"1.168130661","rc":[{"batl":[[0,13.5,4]],"ltp":12.5,"tv":1025.77,"id":24420205}]}]}
{"op":"mcm","clk":"994322928","pt":1580551110656,"mc":[{"id":"1.168130661","rc":[{"batb":[[0,11,9.16],[1,10.5,19.57],[2,10,39.13]],"batl":[[0,12.5,4],[1,13,3],[2,13.5,31]],"ltp":12.0,"tv":1258.52,"id":24707172}]}]}
{"op":"mcm","clk":"994323043","pt":1580551111684,"mc":[{"id":"1.168130661","rc":[{"batb":[[0,11.5,6.38],[1,11,9.16],[2,10.5,19.57]],"ltp":12.0,"tv":1258.52,"id":24707172}]}]}
{"op":"mcm","clk":"994323264","pt":1580551113677,"mc":[{"id":"1.168130661","rc":[{"batl":[[1,13,7.06]],"ltp":12.0,"tv":1258.52,"id":24707172}]}]}
{"op":"mcm","clk":"994323964","pt":1580551119659,"mc":[{"id":"1.168130661","rc":[{"batl":[[1,2.54,97.53]],"ltp":2.52,"tv":6867.88,"id":26314798}]}]}
{"op":"mcm","clk":"994324132","pt":1580551120691,"mc":[{"id":"1.168130661","rc":[{"trd":[[2.52,281.48]],"batl":[[0,2.52,47.41]],"ltp":2.52,"tv":6871.88,"id":26314798}],"tv":15015.27}]}
{"op":"mcm","clk":"994324385","pt":1580551122667,"mc":[{"id":"1.168130661","rc":[{"batb":[[0,12.5,2]],"ltp":12.5,"tv":1025.77,"id":24420205}]}]}
{"op":"mcm","clk":"994324681","pt":1580551124716,"mc":[{"id":"1.168130661","rc":[{"batb":[[0,11.5,16.38]],"ltp":12.0,"tv":1258.52,"id":24707172}]}]}
{"op":"mcm","clk":"994325236","pt":1580551129710,"mc":[{"id":"1.168130661","rc":[{"batb":[[1,10,23.58]],"ltp":11.0,"tv":893.68,"id":420}]}]}
{"op":"mcm","clk":"994326214","pt":1580551137723,"mc":[{"id":"1.168130661","rc":[{"batb":[[2,11.5,4.76]],"ltp":12.5,"tv":1025.77,"id":24420205}]}]}
{"op":"mcm","clk":"994326325","pt":1580551138705,"mc":[{"id":"1.168130661","rc":[{"trd":[[2.52,285.48]],"batl":[[0,2.52,45.41]],"ltp":2.52,"tv":6875.88,"id":26314798}],"tv":15019.27}]}
{"op":"mcm","clk":"994327276","pt":1580551146644,"mc":[{"id":"1.168130661","rc":[{"batb":[[1,30,12.66]],"ltp":36.0,"tv":215.51,"id":25545675}]}]}
{"op":"mcm","clk":"994327605","pt":1580551149660,"mc":[{"id":"1.168130661","rc":[{"batl":[[2,12,331]],"ltp":11.0,"tv":893.68,"id":420}]}]}
{"op":"mcm","clk":"994330085","pt":1580551174693,"mc":[{"id":"1.168130661","rc":[{"batb":[[1,10,27.58]],"ltp":11.0,"tv":893.68,"id":420}]}]}
{"op":"mcm","clk":"994330742","pt":1580551180599,"mc":[{"id":"1.168130661","rc":[{"batl":[[0,2.52,53.92]],"ltp":2.52,"tv":6875.88,"id":26314798}]}]}
{"op":"mcm","clk":"994331155","pt":1580551183632,"mc":[{"id":"1.168130661","rc":[{"trd":[[3.05,401.4]],"batb":[[0,3,24.28],[1,2.98,11.39],[2,2.96,13]],"batl":[[0,3.05,4],[1,3.1,6.27],[2,3.15,5.9]],"ltp":3.05,"tv":4761.9,"id":25238892},{"batb":[[0,2.5,13.23]],"batl":[[0,2.52,50.92]],"ltp":2.52,"tv":6875.88,"id":26314798}],"tv":15031.27}]}
{"op":"mcm","clk":"994331444","pt":1580551185621,"mc":[{"id":"1.168130661","rc":[{"trd":[[3.05,409.4]],"batb":[[0,3.05,6.43],[1,3,24.28],[2,2.98,19.48]],"batl":[[0,3.1,6.27],[1,3.15,5.9],[2,3.2,7.88]],"ltp":3.05,"tv":4769.9,"id":25238892}],"tv":15039.27}]}
{"op":"mcm","clk":"994331569","pt":1580551186723,"mc":[{"id":"1.168130661","rc":[{"batb":[[0,3.05,9.43]],"ltp":3.05,"tv":4769.9,"id":25238892},{"batb":[[0,2.5,3]],"ltp":2.52,"tv":6875.88,"id":26314798}]}]}
{"op":"mcm","clk":"994331680","pt":1580551187607,"mc":[{"id":"1.168130661","rc":[{"batb":[[1,2.48,27.76]],"ltp":2.52,"tv":6875.88,"id":26314798}]}]}
{"op":"mcm","clk":"994331754","pt":1580551188331,"mc":[{"id":"1.168130661","rc":[{"batb":[[1,2.48,23.11]],"ltp":2.52,"tv":6875.88,"id":26314798}]}]}
{"op":"mcm","clk":"994332951","pt":1580551198657,"mc":[{"id":"1.168130661","rc":[{"batb":[[0,12,2.26],[1,11.5,10],[2,11,9.16]],"ltp":12.0,"tv":1258.52,"id":24707172},{"trd":[[12.5,142.6]],"batb":[[0,12.5,2.31],[2,11.5,2.1]],"ltp":12.5,"tv":1029.77,"id":24420205}],"tv":15043.27}]}
{"op":"mcm","clk":"994333901","pt":1580551204659,"mc":[{"id":"1.168130661","rc":[{"trd":[[30,48.49],[32,34.12]],"batb":[[0,30,4.5],[1,29,4.04],[2,27,5.23]],"batl":[[0,34,2.02],[1,36,25.12],[2,44,10.17]],"ltp":30.0,"tv":241.51,"id":25545675}],"tv":15069.28}]}
{"op":"mcm","clk":"994333992","pt":1580551205450,"mc":[{"id":"1.168130661","rc":[{"batb":[[1,29,6.53]],"ltp":30.0,"tv":241.51,"id":25545675}]}]}
{"op":"mcm","clk":"994334101","pt":1580551206338,"mc":[{"id":"1.168130661","rc":[{"batb":[[1,29,4.04]],"ltp":30.0,"tv":241.51,"id":25545675}]}]}
{"op":"mcm","clk":"994334261","pt":1580551207643,"mc":[{"id":"1.168130661","rc":[{"batb":[[0,30,2.2]],"ltp":30.0,"tv":241.51,"id":25545675}]}]}
{"op":"mcm","clk":"994334557","pt":1580551209643,"mc":[{"id":"1.168130661","rc":[{"trd":[[34,35.88]],"batl":[[0,36,25.12],[1,44,10.17],[2,46,13.47]],"ltp":34.0,"tv":244.98,"id":25545675},{"trd":[[3.1,278.03]],"batl":[[0,3.15,5.9],[1,3.2,7.88],[2,3.25,27.79]],"ltp":3.1,"tv":4776.17,"id":25238892},{"trd":[[11.5,107.93],[12,116.71]],"batb":[[0,11,9.16],[1,10.5,14.18],[2,10,39.13]],"batl":[[0,11.5,11.67],[1,12,4.05],[2,12.5,4]],"ltp":11.5,"tv":1297.49,"id":24707172},{"trd":[[13.5,32.94]],"batl":[[0,13.5,2.56]],"ltp":13.5,"tv":1031.21,"id":24420205},{"trd":[[2.52,293.19]],"batl":[[0,2.52,43.21]],"ltp":2.52,"tv":6883.59,"id":26314798},{"trd":[[11,188.63]],"batl":[[0,11,21.23]],"ltp":11.0,"tv":895.45,"id":420}],"tv":15128.91}]}
{"op":"mcm","clk":"994334669","pt":1580551210647,"mc":[{"id":"1.168130661","rc":[{"batb":[[1,10.5,18.85]],"ltp":11.5,"tv":1297.49,"id":24707172}]}]}
{"op":"mcm","clk":"994334786","pt":1580551211536,"mc":[{"id":"1.168130661","rc":[{"batb":[[1,10.5,14.18]],"ltp":11.5,"tv":1297.49,"id":24707172}]}]}
{"op":"mcm","clk":"994335175","pt":1580551214647,"mc":[{"id":"1.168130661","rc":[{"batb":[[0,30,2]],"ltp":34.0,"tv":244.98,"id":25545675}]}]}
{"op":"mcm","clk":"994335559","pt":1580551217646,"mc":[{"id":"1.168130661","rc":[{"batl":[[0,36,25.59]],"ltp":34.0,"tv":244.98,"id":25545675},{"batb":[[2,2.98,11.39]],"ltp":3.1,"tv":4776.17,"id":25238892}]}]}
{"op":"mcm","clk":"994336259","pt":1580551222694,"mc":[{"id":"1.168130661","rc":[{"batl":[[2,13,7.06]],"ltp":11.5,"tv":1297.49,"id":24707172}]}]}
{"op":"mcm","clk":"994337962","pt":1580551236623,"mc":[{"id":"1.168130661","rc":[{"trd":[[34,36.35],[36,50.57]],"batl":[[0,36,24.71]],"ltp":36.0,"tv":245.86,"id":25545675},{"trd":[[3.15,91.08]],"batb":[[0,3.05,3]],"batl":[[0,3.2,2.88],[1,3.25,27.79],[2,3.3,10.76]],"ltp":3.15,"tv":4785.99,"id":25238892},{"trd":[[11.5,110.62]],"batl":[[0,11.5,8.98]],"ltp":11.5,"tv":1300.18,"id":24707172},{"trd":[[12,169.94],[12.5,148.5]],"batb":[[0,11,9.28],[1,10.5,25.34],[2,10,24.27]],"batl":[[0,12,17.42],[1,12.5,3.19],[2,13.5,2.56]],"ltp":12.0,"tv":1057.84,"id":24420205},{"trd":[[2.52,305.46]],"batb":[[0,2.5,13.19]],"batl":[[0,2.52,30.94],[1,2.54,93.26],[2,2.56,3.19]],"ltp":2.52,"tv":6895.86,"id":26314798},{"trd":[[11,191.44]],"batl":[[0,11,18.42]],"ltp":11.0,"tv":898.26,"id":420}],"tv":15184.01}]}
{"op":"mcm","clk":"994338096","pt":1580551237679,"mc":[{"id":"1.168130661","rc":[{"batb":[[1,10.5,24.02],[2,10,25.39]],"ltp":12.0,"tv":1057.84,"id":24420205}]}]}
{"op":"mcm","clk":"994338201","pt":1580551238723,"mc":[{"id":"1.168130661","rc":[{"trd":[[36,51.53]],"batl":[[0,36,23.75]],"ltp":36.0,"tv":246.82,"id":25545675},{"trd":[[3.15,102.08]],"ltp":3.15,"tv":4796.99,"id":25238892},{"trd":[[11.5,113.63]],"batl":[[0,11.5,5.97]],"ltp":11.5,"tv":1303.19,"id":24707172},{"trd":[[12,172.83]],"batl":[[0,12,14.53]],"ltp":12.0,"tv":1060.73,"id":24420205},{"trd":[[2.52,319.21]],"batb":[[1,2.48,27.74]],"batl":[[0,2.52,17.19]],"ltp":2.52,"tv":6909.61,"id":26314798},{"trd":[[11,194.59]],"batl":[[0,11,15.27]],"ltp":11.0,"tv":901.41,"id":420}],"tv":15218.77}]}
{"op":"mcm","clk":"994338290","pt":1580551239716,"mc":[{"id":"1.168130661","rc":[{"batl":[[0,2.52,8.52]],"ltp":2.52,"tv":6909.61,"id":26314798}]}]}
{"op":"mcm","clk":"994338408","pt":1580551240710,"mc":[{"id":"1.168130661","rc":[{"trd":[[3.2,39.6]],"batb":[[0,3.15,3.22],[1,3.1,3.22],[2,3.05,3]],"batl":[[0,3.2,5.33],[1,3.25,29.79],[2,3.3,17.76]],"ltp":3.2,"tv":4812.34,"id":25238892},{"trd":[[11.5,125.56]],"batb":[[0,11.5,7.01],[1,11,9.16],[2,10.5,14.18]],"batl":[[0,12.5,4.22],[1,13,7.06],[2,13.5,28]],"ltp":11.5,"tv":1315.12,"id":24707172},{"batb":[[2,10,24.27]],"ltp":12.0,"tv":1060.73,"id":24420205},{"trd":[[2.52,336.24]],"batb":[[0,2.52,91.99],[1,2.5,13.19],[2,2.48,27.74]],"batl":[[0,2.54,93.26],[1,2.56,3.19],[2,2.58,33]],"ltp":2.52,"tv":6926.64,"id":26314798}],"tv":15263.09}]}
{"op":"mcm","clk":"994338546","pt":1580551241709,"mc":[{"id":"1.168130661","rc":[{"trd":[[34,36.74]],"batl":[[0,36,23.83]],"ltp":34.0,"tv":247.21,"id":25545675},{"trd":[[3.05,419.83]],"batb":[[0,3.05,3.22],[1,3,24.28],[2,2.98,7.39]],"batl":[[0,3.2,7.22],[1,3.25,27.79]],"ltp":3.05,"tv":4822.77,"id":25238892},{"trd":[[13,23.66]],"batl":[[0,12.5,3],[1,13,6.02]],"ltp":13.0,"tv":1316.16,"id":24707172},{"trd":[[12,173.96]],"batl":[[0,12,13.4]],"ltp":12.0,"tv":1061.86,"id":24420205},{"trd":[[2.54,140.04]],"batb":[[0,2.52,101.99]],"batl":[[0,2.54,76.62],[1,2.58,33],[2,2.64,25.63]],"ltp":2.54,"tv":6954.62,"id":26314798},{"trd":[[11,195.82]],"batl":[[0,11,14.04]],"ltp":11.0,"tv":902.64,"id":420}],"tv":15305.29}]}
{"op":"mcm","clk":"994338654","pt":1580551242703,"mc":[{"id":"1.168130661","rc":[{"batl":[[0,3.2,9.84]],"ltp":3.05,"tv":4822.77,"id":25238892},{"batl":[[0,13,6.02],[1,13.5,28],[2,15,94.74]],"ltp":13.0,"tv":1316.16,"id":24707172},{"batb":[[1,2.5,26.35]],"batl":[[1,2.58,45.49]],"ltp":2.54,"tv":6954.62,"id":26314798}]}]}
{"op":"mcm","clk":"994338863","pt":1580551244628,"mc":[{"id":"1.168130661","rc":[{"batl":[[0,12,15.96],[2,14,2.63]],"ltp":12.0,"tv":1061.86,"id":24420205}]}]}
{"op":"mcm","clk":"994339166","pt":1580551247702,"mc":[{"id":"1.168130661","rc":[{"trd":[[29,25.23],[30,52.49]],"batb":[[1,29,3.04]],"ltp":29.0,"tv":253.21,"id":25545675},{"batb":[[0,12,2.24],[1,11.5,7.01],[2,11,9.16]],"batl":[[2,15,77.74]],"ltp":13.0,"tv":1316.16,"id":24707172}],"tv":15311.29}]}
{"op":"mcm","clk":"994339252","pt":1580551248643,"mc":[{"id":"1.168130661","rc":[{"batl":[[0,3.2,2.62]],"ltp":3.05,"tv":4822.77,"id":25238892},{"batb":[[0,11.5,2],[1,11,9.16],[2,10.5,14.18]],"batl":[[0,12.5,6.05],[1,13,6.02],[2,13.5,28]],"ltp":13.0,"tv":1316.16,"id":24707172},{"batb":[[0,2.5,26.35],[1,2.48,27.74],[2,2.46,19]],"batl":[[1,2.56,2.26],[2,2.58,45.49]],"ltp":2.54,"tv":6954.62,"id":26314798}]}]}
{"op":"mcm","clk":"994339409","pt":1580551250545,"mc":[{"id":"1.168130661","rc":[{"batb":[[2,27,7.59]],"ltp":29.0,"tv":253.21,"id":25545675},{"batb":[[2,10.5,16.9]],"ltp":13.0,"tv":1316.16,"id":24707172},{"batb":[[0,2.5,13.19]],"ltp":2.54,"tv":6954.62,"id":26314798}]}]}
{"op":"mcm","clk":"994339673","pt":1580551252648,"mc":[{"id":"1.168130661","rc":[{"batb":[[0,2.5,3]],"batl":[[0,2.54,79.62]],"ltp":2.54,"tv":6954.62,"id":26314798}]}]}
{"op":"mcm","clk":"994340589","pt":1580551258621,"mc":[{"id":"1.168130661","rc":[{"batl":[[0,12.5,8.05]],"ltp":13.0,"tv":1316.16,"id":24707172}]}]}
{"op":"mcm","clk":"994341045","pt":1580551261643,"mc":[{"id":"1.168130661","rc":[{"trd":[[2.54,144.04]],"batl":[[0,2.54,77.62]],"ltp":2.54,"tv":6958.62,"id":26314798}],"tv":15315.29}]}
{"op":"mcm","clk":"994341910","pt":1580551267564,"mc":[{"id":"1.168130661","rc":[{"batb":[[1,2.48,23.11]],"ltp":2.54,"tv":6958.62,"id":26314798}]}]}
{"op":"mcm","clk":"994342035","pt":1580551268658,"mc":[{"id":"1.168130661","rc":[{"trd":[[11.5,129.56]],"batb":[[0,11,9.16],[1,10.5,16.9],[2,10,39.13]],"batl":[[0,12.5,2]],"ltp":11.5,"tv":1320.16,"id":24707172}],"tv":15319.29}]}
{"op":"mcm","clk":"994342282","pt":1580551270646,"mc":[{"id":"1.168130661","rc":[{"batb":[[1,10.5,14.18]],"ltp":11.5,"tv":1320.16,"id":24707172},{"batb":[[1,2.48,28.11]],"batl":[[0,2.54,82.62]],"ltp":2.54,"tv":6958.62,"id":26314798}]}]}
{"op":"mcm","clk":"994342867","pt":1580551275648,"mc":[{"id":"1.168130661","rc":[{"batb":[[1,2.48,33.11]],"batl":[[0,2.54,87.62]],"ltp":2.54,"tv":6958.62,"id":26314798}]}]}
{"op":"mcm","clk":"994347076","pt":1580551306711,"mc":[{"id":"1.168130661","rc":[{"trd":[[3.05,423.83]],"batb":[[0,3.05,1.22]],"ltp":3.05,"tv":4826.77,"id":25238892}],"tv":15323.29}]}
{"op":"mcm","clk":"994348097","pt":1580551316345,"mc":[{"id":"1.168130661","rc":[{"batb":[[0,3.05,3.22]],"ltp":3.05,"tv":4826.77,"id":25238892},{"batb":[[0,2.5,13.28]],"ltp":2.54,"tv":6958.62,"id":26314798}]}]}
{"op":"mcm","clk":"994348216","pt":1580551317652,"mc":[{"id":"1.168130661","rc":[{"batb":[[1,2.48,37.77]],"ltp":2.54,"tv":6958.62,"id":26314798}]}]}
{"op":"mcm","clk":"994348449","pt":1580551319672,"mc":[{"id":"1.168130661","rc":[{"batb":[[1,3,31.67],[2,2.96,10]],"ltp":3.05,"tv":4826.77,"id":25238892}]}]}
{"op":"mcm","clk":"994349578","pt":1580551329653,"mc":[{"id":"1.168130661","rc":[{"batb":[[1,3,31.59]],"ltp":3.05,"tv":4826.77,"id":25238892}]}]}
{"op":"mcm","clk":"994349669","pt":1580551330700,"mc":[{"id":"1.168130661","rc":[{"batb":[[0,11.5,3.81],[1,11,9.28],[2,10.5,24.02]],"ltp":12.0,"tv":1061.86,"id":24420205}]}]}
{"op":"mcm","clk":"994349751","pt":1580551331528,"mc":[{"id":"1.168130661","rc":[{"batl":[[0,2.54,84.62]],"ltp":2.54,"tv":6958.62,"id":26314798}]}]}
{"op":"mcm","clk":"994350635","pt":1580551340675,"mc":[{"id":"1.168130661","rc":[{"trd":[[2.54,164.82]],"batl":[[0,2.54,74.22]],"ltp":2.54,"tv":6979.4,"id":26314798}],"tv":15344.07}]}
{"op":"mcm","clk":"994351064","pt":1580551344708,"mc":[{"id":"1.168130661","rc":[{"trd":[[2.5,291.53]],"batb":[[0,2.5,10.28]],"ltp":2.5,"tv":6985.4,"id":26314798}],"tv":15350.07}]}
{"op":"mcm","clk":"994352357","pt":1580551356719,"mc":[{"id":"1.168130661","rc":[{"batb":[[1,2.48,33.11]],"ltp":2.5,"tv":6985.4,"id":26314798}]}]}
{"op":"mcm","clk":"994353687","pt":1580551368659,"mc":[{"id":"1.168130661","rc":[{"batb":[[0,2.52,2],[1,2.5,10.28],[2,2.48,33.11]],"ltp":2.5,"tv":6985.4,"id":26314798}]}]}
{"op":"mcm","clk":"994353785","pt":1580551369653,"mc":[{"id":"1.168130661","rc":[{"batb":[[0,2.5,10.28],[1,2.48,33.11],[2,2.46,19]],"ltp":2.5,"tv":6985.4,"id":26314798}]}]}
{"op":"mcm","clk":"994354352","pt":1580551374629,"mc":[{"id":"1.168130661","rc":[{"batl":[[0,3.2,7.62]],"ltp":3.05,"tv":4826.77,"id":25238892},{"trd":[[11,156.75]],"batb":[[0,11,4.16]],"ltp":11.0,"tv":1330.16,"id":24707172}],"tv":15360.07}]}
{"op":"mcm","clk":"994354752","pt":1580551378444,"mc":[{"id":"1.168130661","rc":[{"trd":[[3.05,429.83]],"batb":[[0,3,31.81],[1,2.96,10],[2,2.94,75.92]],"ltp":3.05,"tv":4832.77,"id":25238892}],"tv":15366.07}]}
{"op":"mcm","clk":"994357610","pt":1580551397692,"mc":[{"id":"1.168130661","rc":[{"batb":[[1,2.48,38.11]],"batl":[[0,2.54,79.22]],"ltp":2.5,"tv":6985.4,"id":26314798}]}]}
{"op":"mcm","clk":"994359056","pt":1580551408707,"mc":[{"id":"1.168130661","rc":[{"trd":[[3.2,39.8]],"batl":[[0,3.2,7.52]],"ltp":3.2,"tv":4832.97,"id":25238892},{"trd":[[10.5,206.41]],"batb":[[0,10.5,30.71]],"ltp":10.5,"tv":930.65,"id":420}],"tv":15394.27}]}
{"op":"mcm","clk":"994360575","pt":1580551419710,"mc":[{"id":"1.168130661","rc":[{"batb":[[0,3.05,3],[1,3,31.59],[2,2.96,10]],"ltp":3.2,"tv":4832.97,"id":25238892},{"batb":[[0,2.48,38.11],[1,2.46,19],[2,2.44,12]],"batl":[[0,2.54,81.22]],"ltp":2.5,"tv":6985.4,"id":26314798}]}]}
{"op":"mcm","clk":"994360690","pt":1580551420715,"mc":[{"id":"1.168130661","rc":[{"batb":[[0,29,5.04],[1,27,7.59],[2,26,20.09]],"ltp":29.0,"tv":253.21,"id":25545675},{"batb":[[0,11.5,7.01],[1,11,4.16],[2,10.5,14.18]],"batl":[[0,12.5,5.22]],"ltp":11.0,"tv":1330.16,"id":24707172},{"trd":[[2.5,297.39]],"batb":[[0,2.5,99.8],[1,2.48,38.11],[2,2.46,23.07]],"batl":[[0,2.54,79.22]],"ltp":2.5,"tv":6991.26,"id":26314798}],"tv":15400.13}]}
{"op":"mcm","clk":"994360821","pt":1580551421628,"mc":[{"id":"1.168130661","rc":[{"trd":[[34,36.82],[36,54.59]],"batl":[[0,36,20.69]],"ltp":36.0,"tv":256.35,"id":25545675},{"trd":[[3.05,472.83]],"batb":[[0,3.05,3.22]],"ltp":3.05,"tv":4875.97,"id":25238892},{"trd":[[11.5,133.56],[12.5,31.26],[13,27.33]],"batb":[[0,11.5,7.01]],"batl":[[0,12.5,2],[1,13,2.35]],"ltp":11.5,"tv":1343.05,"id":24707172},{"trd":[[12,183.36]],"batl":[[0,12,6.56]],"ltp":12.0,"tv":1071.26,"id":24420205},{"trd":[[2.54,209.26]],"batb":[[0,2.52,10.22],[1,2.5,99.8],[2,2.48,38.11]],"batl":[[0,2.54,34.79]],"ltp":2.54,"tv":7035.69,"id":26314798},{"trd":[[11,206.07]],"batl":[[0,11,3.79]],"ltp":11.0,"tv":940.9,"id":420}],"tv":15523.24}]}
{"op":"mcm","clk":"994360974","pt":1580551422702,"mc":[{"id":"1.168130661","rc":[{"trd":[[11,54.99],[11.5,151.87]],"batb":[[0,11,9.09],[1,10.5,24.02],[2,10,24.27]],"batl":[[0,12,2.56]],"ltp":11.0,"tv":1079.26,"id":24420205}],"tv":15531.24}]}
{"op":"mcm","clk":"994361129","pt":1580551423721,"mc":[{"id":"1.168130661","rc":[{"batb":[[1,10.5,27.44]],"ltp":11.0,"tv":1079.26,"id":24420205}]}]}
{"op":"mcm","clk":"994361279","pt":1580551424627,"mc":[{"id":"1.168130661","rc":[{"batb":[[0,34,5],[1,29,5.04],[2,27,7.59]],"ltp":36.0,"tv":256.35,"id":25545675},{"batb":[[1,10.5,24.02]],"ltp":11.0,"tv":1079.26,"id":24420205},{"batb":[[2,2.48,124.52]],"ltp":2.54,"tv":7035.69,"id":26314798}]}]}
{"op":"mcm","clk":"994361412","pt":1580551425517,"mc":[{"id":"1.168130661","rc":[{"batb":[[1,32,2.24],[2,29,5.04]],"ltp":36.0,"tv":256.35,"id":25545675},{"trd":[[2.54,234.46]],"batl":[[0,2.54,22.18]],"ltp":2.54,"tv":7060.9,"id":26314798}],"tv":15556.45}]}
{"op":"mcm","clk":"994361586","pt":1580551426634,"mc":[{"id":"1.168130661","rc":[{"batb":[[1,32,4.46]],"ltp":36.0,"tv":256.35,"id":25545675}]}]}
{"op":"mcm","clk":"994361853","pt":1580551428650,"mc":[{"id":"1.168130661","rc":[{"batb":[[0,11.5,2]],"ltp":11.5,"tv":1343.05,"id":24707172},{"batb":[[0,2.5,10],[1,2.48,124.52],[2,2.46,19]],"ltp":2.54,"tv":7060.9,"id":26314798}]}]}
{"op":"mcm","clk":"994362004","pt":1580551429632,"mc":[{"id":"1.168130661","rc":[{"batb":[[2,10.5,18.85]],"ltp":11.5,"tv":1343.05,"id":24707172},{"batb":[[1,2.48,128.56]],"ltp":2.54,"tv":7060.9,"id":26314798}]}]}
{"op":"mcm","clk":"994362251","pt":1580551431641,"mc":[{"id":"1.168130661","rc":[{"trd":[[36,55.75]],"batl":[[0,36,19.53]],"ltp":36.0,"tv":257.51,"id":25545675},{"trd":[[3,148.47],[3.05,489.36]],"batb":[[0,2.98,12.66],[1,2.96,10],[2,2.94,75.92]],"batl":[[0,3,8.43],[1,3.2,12],[2,3.25,27.79]],"ltp":3.0,"tv":4963.35,"id":25238892},{"trd":[[12.5,33.26],[13,28.62]],"batl":[[0,13,3.06],[1,13.5,28],[2,15,77.74]],"ltp":13.0,"tv":1346.34,"id":24707172},{"trd":[[12,185.92],[12.5,149.38]],"batb":[[0,11.5,2.27],[1,11,9.09],[2,10.5,24.02]],"batl":[[0,14,2.63],[1,14.5,2],[2,15,2]],"ltp":12.5,"tv":1082.7,"id":24420205},{"trd":[[2.54,250.91]],"batb":[[2,2.46,23]],"batl":[[0,2.54,5.74],[1,2.58,45.49],[2,2.64,75.63]],"ltp":2.54,"tv":7077.34,"id":26314798},{"trd":[[11,209.86]],"batb":[[0,11,1.56],[1,10.5,30.71],[2,10,25.86]],"batl":[[0,11.5,5.49],[1,12,331],[2,12.5,10]],"ltp":11.0,"tv":944.69,"id":420}],"tv":15671.95}]}
{"op":"mcm","clk":"994362405","pt":1580551432656,"mc":[{"id":"1.168130661","rc":[{"batb":[[1,2.96,12],[2,2.94,77.92]],"ltp":3.0,"tv":4963.35,"id":25238892},{"batb":[[2,10.5,14.18]],"ltp":13.0,"tv":1346.34,"id":24707172},{"batb":[[1,2.48,124.52]],"batl":[[1,2.58,33]],"ltp":2.54,"tv":7077.34,"id":26314798}]}]}
{"op":"mcm","clk":"994362566","pt":1580551433631,"mc":[{"id":"1.168130661","rc":[{"batb":[[1,2.96,16.34]],"ltp":3.0,"tv":4963.35,"id":25238892}]}]}
{"op":"mcm","clk":"994362959","pt":1580551435673,"mc":[{"id":"1.168130661","rc":[{"trd":[[3,165.33]],"batb":[[0,2.98,13.04]],"batl":[[0,3.2,12],[1,3.25,27.79],[2,3.3,17.76]],"ltp":3.0,"tv":4980.21,"id":25238892},{"batl":[[0,2.52,40],[1,2.54,5.74],[2,2.56,2.3]],"ltp":2.54,"tv":7077.34,"id":26314798}],"tv":15688.81}]}
{"op":"mcm","clk":"994363102","pt":1580551436534,"mc":[{"id":"1.168130661","rc":[{"batb":[[0,2.96,16.73],[1,2.94,77.92],[2,2.9,6]],"batl":[[0,3.15,2.52],[1,3.2,12],[2,3.25,27.79]],"ltp":3.0,"tv":4980.21,"id":25238892},{"batb":[[0,12,2.2],[1,11.5,2],[2,11,4.16]],"ltp":13.0,"tv":1346.34,"id":24707172},{"batb":[[0,12,2.2],[1,11.5,2.27],[2,11,9.09]],"ltp":12.5,"tv":1082.7,"id":24420205},{"batb":[[0,2.5,20.57]],"ltp":2.54,"tv":7077.34,"id":26314798},{"trd":[[11,212.99]],"batb":[[0,10.5,33.23],[1,10,25.86],[2,9.8,15]],"ltp":11.0,"tv":947.81,"id":420}],"tv":15691.94}]}
{"op":"mcm","clk":"994363249","pt":1580551437668,"mc":[{"id":"1.168130661","rc":[{"trd":[[34,40.18]],"batb":[[0,34,3.32]],"ltp":34.0,"tv":260.87,"id":25545675},{"batb":[[0,2.96,12.38]],"batl":[[0,3.15,2.8]],"ltp":3.0,"tv":4980.21,"id":25238892},{"batl":[[0,13,8.96]],"ltp":13.0,"tv":1346.34,"id":24707172},{"batb":[[0,12.5,2.31],[1,12,2.2],[2,11.5,2.27]],"ltp":12.5,"tv":1082.7,"id":24420205},{"trd":[[2.5,338.53]],"batb":[[0,2.48,124.52],[1,2.46,23],[2,2.44,12]],"batl":[[0,2.5,19.43]],"ltp":2.5,"tv":7118.49,"id":26314798}],"tv":15736.44}]}
{"op":"mcm","clk":"994363369","pt":1580551438481,"mc":[{"id":"1.168130661","rc":[{"batb":[[1,2.94,83.58]],"ltp":3.0,"tv":4980.21,"id":25238892},{"batb":[[1,2.46,30.85],[2,2.44,23]],"batl":[[1,2.54,8.74]],"ltp":2.5,"tv":7118.49,"id":26314798}]}]}
{"op":"mcm","clk":"994363530","pt":1580551439660,"mc":[{"id":"1.168130661","rc":[{"trd":[[2.5,358.53]],"batb":[[1,2.46,37.17]],"batl":[[0,2.5,9.43]],"ltp":2.5,"tv":7138.49,"id":26314798}],"tv":15756.44}]}
{"op":"mcm","clk":"994363943","pt":1580551442587,"mc":[{"id":"1.168130661","rc":[{"batl":[[0,14,6.63]],"ltp":12.5,"tv":1082.7,"id":24420205}]}]}
{"op":"mcm","clk":"994364041","pt":1580551443384,"mc":[{"id":"1.168130661","rc":[{"batb":[[0,12,4.2],[1,11.5,2.27],[2,11,3]],"ltp":12.5,"tv":1082.7,"id":24420205}]}]}
{"op":"mcm","clk":"994364211","pt":1580551444673,"mc":[{"id":"1.168130661","rc":[{"batb":[[0,34,5]],"ltp":34.0,"tv":260.87,"id":25545675}]}]}
{"op":"mcm","clk":"994365517","pt":1580551454686,"mc":[{"id":"1.168130661","rc":[{"trd":[[2.5,371.53]],"batl":[[0,2.5,2.93]],"ltp":2.5,"tv":7151.49,"id":26314798}],"tv":15769.44}]}
{"op":"mcm","clk":"994366160","pt":1580551459691,"mc":[{"id":"1.168130661","rc":[{"batb":[[2,2.8,89]],"ltp":3.0,"tv":4980.21,"id":25238892}]}]}
{"op":"mcm","clk":"994366254","pt":1580551460399,"mc":[{"id":"1.168130661","rc":[{"batb":[[2,2.82,6]],"ltp":3.0,"tv":4980.21,"id":25238892}]}]}
{"op":"mcm","clk":"994367997","pt":1580551470603,"mc":[{"id":"1.168130661","rc":[{"batb":[[0,2.98,3.54],[1,2.96,12],[2,2.94,83.58]],"ltp":3.0,"tv":4980.21,"id":25238892},{"batl":[[0,12.5,2.16],[1,13,8.96],[2,13.5,28]],"ltp":13.0,"tv":1346.34,"id":24707172}]}]}
{"op":"mcm","clk":"994368327","pt":1580551472572,"mc":[{"id":"1.168130661","rc":[{"trd":[[2.48,61.14]],"batb":[[0,2.48,107.52]],"ltp":2.48,"tv":7185.49,"id":26314798}],"tv":15803.44}]}
{"op":"mcm","clk":"994368455","pt":1580551473535,"mc":[{"id":"1.168130661","rc":[{"trd":[[34,50.18]],"batb":[[0,32,4.46],[1,29,5.04],[2,27,5.23]],"ltp":34.0,"tv":270.87,"id":25545675}],"tv":15813.44}]}
{"op":"mcm","clk":"994368599","pt":1580551474516,"mc":[{"id":"1.168130661","rc":[{"batb":[[0,32,2.24],[1,29,9.08]],"ltp":34.0,"tv":270.87,"id":25545675},{"batb":[[2,2.94,77.92]],"ltp":3.0,"tv":4980.21,"id":25238892}]}]}
{"op":"mcm","clk":"994368808","pt":1580551475723,"mc":[{"id":"1.168130661","rc":[{"batb":[[0,30,2.19]],"ltp":34.0,"tv":270.87,"id":25545675},{"trd":[[2.48,67]],"batb":[[0,2.5,10.19],[1,2.48,108.48],[2,2.46,37.17]],"batl":[[0,2.54,5.74],[1,2.58,33],[2,2.64,75.63]],"ltp":2.48,"tv":7191.35,"id":26314798}],"tv":15819.3}]}
{"op":"mcm","clk":"994368967","pt":1580551476716,"mc":[{"id":"1.168130661","rc":[{"batb":[[1,29,5.04]],"ltp":34.0,"tv":270.87,"id":25545675},{"trd":[[2.96,82.96],[2.98,44.18],[3,166.09]],"batb":[[0,2.98,6.4],[1,2.96,2.64]],"ltp":2.96,"tv":5027.45,"id":25238892},{"batl":[[0,12.5,4.4]],"ltp":13.0,"tv":1346.34,"id":24707172},{"batl":[[1,2.58,36],[2,2.6,3.19]],"ltp":2.48,"tv":7191.35,"id":26314798}],"tv":15866.54}]}
{"op":"mcm","clk":"994369108","pt":1580551477684,"mc":[{"id":"1.168130661","rc":[{"batb":[[2,2.46,30.85]],"ltp":2.48,"tv":7191.35,"id":26314798}]}]}
{"op":"mcm","clk":"994371031","pt":1580551489632,"mc":[{"id":"1.168130661","rc":[{"batb":[[0,2.98,3]],"ltp":2.96,"tv":5027.45,"id":25238892},{"batb":[[2,11,6.16]],"batl":[[0,12.5,2]],"ltp":13.0,"tv":1346.34,"id":24707172},{"trd":[[2.5,411.53]],"batb":[[0,2.48,108.48],[1,2.46,26.85],[2,2.44,19]],"batl":[[1,2.58,33]],"ltp":2.5,"tv":7231.35,"id":26314798}],"tv":15906.54}]}
{"op":"mcm","clk":"994371292","pt":1580551491624,"mc":[{"id":"1.168130661","rc":[{"batb":[[1,2.46,34.71]],"ltp":2.5,"tv":7231.35,"id":26314798}]}]}
{"op":"mcm","clk":"994373604","pt":1580551506689,"mc":[{"id":"1.168130661","rc":[{"trd":[[2.98,50.18]],"batb":[[0,2.96,3.03],[1,2.94,75.92],[2,2.86,6]],"batl":[[0,3.1,7.95]],"ltp":2.98,"tv":5033.45,"id":25238892}],"tv":15912.54}]}
{"op":"mcm","clk":"994373756","pt":1580551507667,"mc":[{"id":"1.168130661","rc":[{"batl":[[0,3.1,10.59]],"ltp":2.98,"tv":5033.45,"id":25238892}]}]}
{"op":"mcm","clk":"994374910","pt":1580551514572,"mc":[{"id":"1.168130661","rc":[{"batl":[[0,3.05,3],[1,3.1,7.95],[2,3.2,12]],"ltp":2.98,"tv":5033.45,"id":25238892},{"batl":[[1,2.56,10],[2,2.58,33]],"ltp":2.5,"tv":7231.35,"id":26314798}]}]}
{"op":"mcm","clk":"994375443","pt":1580551517703,"mc":[{"id":"1.168130661","rc":[{"batb":[[0,12.5,2.09],[1,12,24.59],[2,11.5,2.27]],"ltp":12.5,"tv":1082.7,"id":24420205}]}]}
{"op":"mcm","clk":"994376335","pt":1580551523701,"mc":[{"id":"1.168130661","rc":[{"batl":[[1,2.58,33],[2,2.6,3.19]],"ltp":2.5,"tv":7231.35,"id":26314798}]}]}
{"op":"mcm","clk":"994376690","pt":1580551525723,"mc":[{"id":"1.168130661","rc":[{"batb":[[0,12.5,21.66],[1,12,4.2]],"ltp":12.5,"tv":1082.7,"id":24420205}]}]}
{"op":"mcm","clk":"994376825","pt":1580551526628,"mc":[{"id":"1.168130661","rc":[{"batb":[[0,12.5,21.57]],"batl":[[0,14,4.36]],"ltp":12.5,"tv":1082.7,"id":24420205}]}]}
{"op":"mcm","clk":"994377264","pt":1580551529626,"mc":[{"id":"1.168130661","rc":[{"batb":[[2,2.82,89]],"ltp":2.98,"tv":5033.45,"id":25238892}]}]}
{"op":"mcm","clk":"994377407","pt":1580551530640,"mc":[{"id":"1.168130661","rc":[{"batb":[[2,2.84,6]],"ltp":2.98,"tv":5033.45,"id":25238892}]}]}
{"op":"mcm","clk":"994378359","pt":1580551536705,"mc":[{"id":"1.168130661","rc":[{"trd":[[13,134.94],[14,6.26]],"batb":[[0,12.5,22.09]],"batl":[[0,14,4.11]],"ltp":13.0,"tv":1086.56,"id":24420205}],"tv":15916.4}]}
{"op":"mcm","clk":"994378523","pt":1580551537721,"mc":[{"id":"1.168130661","rc":[{"batb":[[1,12,6.5]],"ltp":13.0,"tv":1086.56,"id":24420205}]}]}
{"op":"mcm","clk":"994379097","pt":1580551541436,"mc":[{"id":"1.168130661","rc":[{"batb":[[0,12.5,2.52]],"ltp":13.0,"tv":1086.56,"id":24420205}]}]}
{"op":"mcm","clk":"994379266","pt":1580551542663,"mc":[{"id":"1.168130661","rc":[{"batb":[[0,12,6.5],[1,11.5,7.81],[2,11,3]],"ltp":13.0,"tv":1086.56,"id":24420205}]}]}
{"op":"mcm","clk":"994379516","pt":1580551544575,"mc":[{"id":"1.168130661","rc":[{"batb":[[1,11.5,2.27]],"ltp":13.0,"tv":1086.56,"id":24420205}]}]}
{"op":"mcm","clk":"994380104","pt":1580551548578,"mc":[{"id":"1.168130661","rc":[{"batl":[[1,2.58,43]],"ltp":2.5,"tv":7231.35,"id":26314798}]}]}
{"op":"mcm","clk":"994380248","pt":1580551549569,"mc":[{"id":"1.168130661","rc":[{"batb":[[0,12.5,19.57],[1,12,6.5],[2,11.5,2.27]],"ltp":13.0,"tv":1086.56,"id":24420205}]}]}
{"op":"mcm","clk":"994380410","pt":1580551550717,"mc":[{"id":"1.168130661","rc":[{"trd":[[36,56.24]],"batl":[[0,36,19.04]],"ltp":36.0,"tv":271.36,"id":25545675},{"trd":[[2.98,56.11]],"ltp":2.98,"tv":5039.38,"id":25238892},{"trd":[[12.5,35.85]],"batl":[[0,13,8.96],[1,13.5,28],[2,15,77.74]],"ltp":12.5,"tv":1348.93,"id":24707172},{"trd":[[14,7.52]],"batb":[[0,13,7.77],[1,12.5,19.57],[2,12,6.5]],"batl":[[0,14,2.85]],"ltp":14.0,"tv":1087.82,"id":24420205},{"trd":[[2.5,418.6]],"batl":[[1,2.58,33]],"ltp":2.5,"tv":7238.42,"id":26314798},{"trd":[[11.5,94.77]],"batl":[[0,11.5,3.95]],"ltp":11.5,"tv":949.35,"id":420}],"tv":15935.28}]}
{"op":"mcm","clk":"994381455","pt":1580551557704,"mc":[{"id":"1.168130661","rc":[{"batl":[[0,12.5,2.31],[1,13,8.96],[2,13.5,28]],"ltp":12.5,"tv":1348.93,"id":24707172},{"trd":[[13,142.98]],"batb":[[0,13,5.75],[1,12,6.5],[2,11.5,2.27]],"ltp":13.0,"tv":1095.86,"id":24420205}],"tv":15943.32}]}
{"op":"mcm","clk":"994381616","pt":1580551558719,"mc":[{"id":"1.168130661","rc":[{"batb":[[1,12,12.54]],"ltp":13.0,"tv":1095.86,"id":24420205}]}]}
{"op":"mcm","clk":"994381910","pt":1580551560681,"mc":[{"id":"1.168130661","rc":[{"batb":[[0,2.5,17],[1,2.48,108.48],[2,2.46,34.71]],"ltp":2.5,"tv":7238.42,"id":26314798}]}]}
{"op":"mcm","clk":"994382029","pt":1580551561560,"mc":[{"id":"1.168130661","rc":[{"batb":[[1,12,9.07]],"ltp":13.0,"tv":1095.86,"id":24420205}]}]}
{"op":"mcm","clk":"994383794","pt":1580551572703,"mc":[{"id":"1.168130661","rc":[{"batl":[[0,13.5,2.91],[1,14,2.85],[2,14.5,2]],"ltp":13.0,"tv":1095.86,"id":24420205}]}]}
{"op":"mcm","clk":"994383943","pt":1580551573718,"mc":[{"id":"1.168130661","rc":[{"batb":[[1,12.5,2.07],[2,12,9.07]],"ltp":13.0,"tv":1095.86,"id":24420205}]}]}
{"op":"mcm","clk":"994384267","pt":1580551575694,"mc":[{"id":"1.168130661","rc":[{"batb":[[0,2.96,6.03]],"ltp":2.98,"tv":5039.38,"id":25238892}]}]}
{"op":"mcm","clk":"994384705","pt":1580551578717,"mc":[{"id":"1.168130661","rc":[{"trd":[[12,121.12]],"batb":[[0,11.5,2],[1,11,6.16],[2,10.5,16.43]],"batl":[[0,12,4.8],[1,12.5,2.31],[2,13,3.06]],"ltp":12.0,"tv":1353.33,"id":24707172}],"tv":15947.73}]}
{"op":"mcm","clk":"994385504","pt":1580551583712,"mc":[{"id":"1.168130661","rc":[{"batl":[[1,2.56,10],[2,2.58,33]],"ltp":2.5,"tv":7238.42,"id":26314798}]}]}
{"op":"mcm","clk":"994385671","pt":1580551584615,"mc":[{"id":"1.168130661","rc":[{"batb":[[2,2.82,6]],"ltp":2.98,"tv":5039.38,"id":25238892},{"trd":[[11.5,137.56]],"batb":[[0,11,6.16],[1,10.5,16.43],[2,10,39.13]],"batl":[[0,11.5,2.8],[1,13,3.06],[2,13.5,28]],"ltp":11.5,"tv":1357.33,"id":24707172},{"batl":[[0,2.54,99],[1,2.56,13]],"ltp":2.5,"tv":7238.42,"id":26314798}],"tv":15951.73}]}
{"op":"mcm","clk":"994385988","pt":1580551586624,"mc":[{"id":"1.168130661","rc":[{"trd":[[36,56.49]],"batl":[[0,36,18.79]],"ltp":36.0,"tv":271.61,"id":25545675},{"trd":[[3.05,492.36]],"batl":[[0,3.1,7.95],[1,3.2,12],[2,3.25,27.79]],"ltp":3.05,"tv":5042.38,"id":25238892},{"trd":[[11.5,138.36]],"batb":[[1,10.5,16.18]],"batl":[[0,11.5,2]],"ltp":11.5,"tv":1358.13,"id":24707172},{"trd":[[13.5,33.62]],"batl":[[0,13.5,2.23]],"ltp":13.5,"tv":1096.54,"id":24420205},{"trd":[[2.52,339.87]],"batb":[[2,2.46,19]],"batl":[[0,2.52,7.81],[1,2.54,99]],"ltp":2.52,"tv":7242.05,"id":26314798},{"trd":[[11.5,95.57]],"batb":[[0,11,4.14],[1,10.5,33.23],[2,10,25.86]],"batl":[[0,11.5,3.15]],"ltp":11.5,"tv":950.15,"id":420}],"tv":15960.89}]}
{"op":"mcm","clk":"994386254","pt":1580551587694,"mc":[{"id":"1.168130661","rc":[{"batb":[[1,2.48,114.37]],"batl":[[2,2.56,3.15]],"ltp":2.52,"tv":7242.05,"id":26314798}]}]}
{"op":"mcm","clk":"994386546","pt":1580551588713,"mc":[{"id":"1.168130661","rc":[{"trd":[[11,160.75]],"batb":[[0,11,4.16]],"batl":[[0,13,3.06],[1,13.5,28],[2,15,77.74]],"ltp":11.0,"tv":1362.13,"id":24707172},{"batb":[[0,10.5,33.23],[1,10,25.86],[2,9.8,15]],"ltp":11.5,"tv":950.15,"id":420}],"tv":15964.89}]}
{"op":"mcm","clk":"994387384","pt":1580551592718,"mc":[{"id":"1.168130661","rc":[{"batl":[[0,3.1,10.95]],"ltp":3.05,"tv":5042.38,"id":25238892}]}]}
{"op":"mcm","clk":"994387520","pt":1580551593431,"mc":[{"id":"1.168130661","rc":[{"trd":[[11.5,101.87]],"batb":[[0,11.5,1.85],[1,11,4.18],[2,10.5,33.23]],"batl":[[0,12,331],[1,12.5,10],[2,13,10]],"ltp":11.5,"tv":956.45,"id":420}],"tv":15971.19}]}
{"op":"mcm","clk":"994388802","pt":1580551600674,"mc":[{"id":"1.168130661","rc":[{"batb":[[0,2.96,9.03]],"ltp":3.05,"tv":5042.38,"id":25238892}]}]}
{"op":"mcm","clk":"994389097","pt":1580551602669,"mc":[{"id":"1.168130661","rc":[{"batb":[[1,2.94,79.1]],"ltp":3.05,"tv":5042.38,"id":25238892},{"batl":[[0,14,2.85],[1,14.5,2],[2,15,2]],"ltp":13.5,"tv":1096.54,"id":24420205}]}]}
{"op":"mcm","clk":"994389267","pt":1580551603669,"mc":[{"id":"1.168130661","rc":[{"batb":[[0,2.5,9]],"batl":[[1,2.54,102]],"ltp":2.52,"tv":7242.05,"id":26314798}]}]}
{"op":"mcm","clk":"994389634","pt":1580551605693,"mc":[{"id":"1.168130661","rc":[{"batb":[[1,2.48,108.48]],"ltp":2.52,"tv":7242.05,"id":26314798},{"trd":[[11.5,104.65]],"batb":[[0,11,4.64],[1,10.5,33.23],[2,10,25.86]],"ltp":11.5,"tv":959.23,"id":420}],"tv":15973.96}]}
{"op":"mcm","clk":"994389795","pt":1580551606656,"mc":[{"id":"1.168130661","rc":[{"batb":[[1,2.94,75.92]],"ltp":3.05,"tv":5042.38,"id":25238892}]}]}
{"op":"mcm","clk":"994389952","pt":1580551607671,"mc":[{"id":"1.168130661","rc":[{"batb":[[1,2.94,79.1]],"ltp":3.05,"tv":5042.38,"id":25238892}]}]}
{"op":"mcm","clk":"994390800","pt":1580551612684,"mc":[{"id":"1.168130661","rc":[{"batl":[[0,2.52,27.81]],"ltp":2.52,"tv":7242.05,"id":26314798}]}]}
{"op":"mcm","clk":"994392367","pt":1580551623716,"mc":[{"id":"1.168130661","rc":[{"batb":[[0,3,3.01],[1,2.98,2.64],[2,2.96,19.03]],"batl":[[0,3.1,3.28]],"ltp":3.05,"tv":5042.38,"id":25238892},{"batb":[[0,10.5,33.69],[1,10,25.86],[2,9.8,15]],"ltp":11.5,"tv":959.23,"id":420}]}]}
{"op":"mcm","clk":"994392511","pt":1580551624719,"mc":[{"id":"1.168130661","rc":[{"batb":[[1,10,30.55]],"ltp":11.5,"tv":959.23,"id":420}]}]}
{"op":"mcm","clk":"994392661","pt":1580551625720,"mc":[{"id":"1.168130661","rc":[{"batb":[[0,3.05,10],[1,3,3.01],[2,2.98,5.64]],"ltp":3.05,"tv":5042.38,"id":25238892},{"batb":[[1,10,25.86]],"ltp":11.5,"tv":959.23,"id":420}]}]}
{"op":"mcm","clk":"994393131","pt":1580551628694,"mc":[{"id":"1.168130661","rc":[{"batl":[[0,3.1,5.28]],"ltp":3.05,"tv":5042.38,"id":25238892}]}]}
{"op":"mcm","clk":"994393942","pt":1580551633623,"mc":[{"id":"1.168130661","rc":[{"batb":[[0,3.05,13]],"ltp":3.05,"tv":5042.38,"id":25238892},{"batl":[[0,13.5,2.53],[1,14,2.85],[2,14.5,2]],"ltp":13.5,"tv":1096.54,"id":24420205}]}]}
{"op":"mcm","clk":"994394296","pt":1580551635630,"mc":[{"id":"1.168130661","rc":[{"batl":[[0,3.1,7.28]],"ltp":3.05,"tv":5042.38,"id":25238892}]}]}
{"op":"mcm","clk":"994394975","pt":1580551639520,"mc":[{"id":"1.168130661","rc":[{"batl":[[0,3.1,9.28]],"ltp":3.05,"tv":5042.38,"id":25238892}]}]}
{"op":"mcm","clk":"994408009","pt":1580551655647,"mc":[{"id":"1.168130661","rc":[{"batb":[[0,30,2.76]],"ltp":36.0,"tv":271.61,"id":25545675}]}]}
{"op":"mcm","clk":"994408150","pt":1580551656651,"mc":[{"id":"1.168130661","rc":[{"batb":[[0,2.5,18.13]],"batl":[[0,2.52,36.75]],"ltp":2.52,"tv":7242.05,"id":26314798}]}]}
{"op":"mcm","clk":"994408646","pt":1580551659660,"mc":[{"id":"1.168130661","rc":[{"batb":[[1,2.48,114.75]],"ltp":2.52,"tv":7242.05,"id":26314798}]}]}
{"op":"mcm","clk":"994413744","pt":1580551692719,"mc":[{"id":"1.168130661","rc":[{"trd":[[2.5,454.87]],"batb":[[0,2.48,199.45],[1,2.46,27.42],[2,2.44,19]],"batl":[[0,2.5,65.89],[1,2.52,39.75],[2,2.54,102]],"ltp":2.5,"tv":7278.31,"id":26314798}],"tv":16010.23}]}
{"op":"mcm","clk":"994413901","pt":1580551693719,"mc":[{"id":"1.168130661","rc":[{"batl":[[0,2.5,74.89]],"ltp":2.5,"tv":7278.31,"id":26314798}]}]}
{"op":"mcm","clk":"994414000","pt":1580551694561,"mc":[{"id":"1.168130661","rc":[{"batb":[[0,2.48,193.18],[1,2.46,33.17]],"ltp":2.5,"tv":7278.31,"id":26314798}]}]}
{"op":"mcm","clk":"994414323","pt":1580551696605,"mc":[{"id":"1.168130661","rc":[{"trd":[[10.5,225.49],[11.5,105.57]],"batb":[[0,10.5,23.69]],"ltp":10.5,"tv":979.22,"id":420}],"tv":16030.22}]}
{"op":"mcm","clk":"994415433","pt":1580551703653,"mc":[{"id":"1.168130661","rc":[{"batl":[[0,11.5,1.39],[1,12,331],[2,12.5,10]],"ltp":10.5,"tv":979.22,"id":420}]}]}
{"op":"mcm","clk":"994416088","pt":1580551707680,"mc":[{"id":"1.168130661","rc":[{"batl":[[1,2.52,41.75]],"ltp":2.5,"tv":7278.31,"id":26314798}]}]}
{"op":"mcm","clk":"994416260","pt":1580551708635,"mc":[{"id":"1.168130661","rc":[{"batl":[[0,2.5,96.22],[1,2.52,39.75]],"ltp":2.5,"tv":7278.31,"id":26314798}]}]}
{"op":"mcm","clk":"994418981","pt":1580551722722,"mc":[{"id":"1.168130661","rc":[{"batl":[[0,2.5,30.33],[1,2.52,36.75]],"ltp":2.5,"tv":7278.31,"id":26314798}]}]}
{"op":"mcm","clk":"994419140","pt":1580551723646,"mc":[{"id":"1.168130661","rc":[{"batb":[[0,2.48,108.48]],"ltp":2.5,"tv":7278.31,"id":26314798}]}]}
{"op":"mcm","clk":"994419310","pt":1580551724661,"mc":[{"id":"1.168130661","rc":[{"trd":[[2.5,491.13]],"batl":[[0,2.5,12.2]],"ltp":2.5,"tv":7314.57,"id":26314798}],"tv":16066.48}]}
{"op":"mcm","clk":"994420696","pt":1580551732375,"mc":[{"id":"1.168130661","rc":[{"batl":[[1,2.52,46.75]],"ltp":2.5,"tv":7314.57,"id":26314798}]}]}
{"op":"mcm","clk":"994422553","pt":1580551742719,"mc":[{"id":"1.168130661","rc":[{"trd":[[30,58.49]],"batb":[[0,30,1.76]],"batl":[[0,34,2.01],[1,36,18.79],[2,44,10.17]],"ltp":30.0,"tv":277.61,"id":25545675},{"batb":[[1,3,13.01]],"ltp":3.05,"tv":5042.38,"id":25238892},{"batl":[[1,2.52,36.75]],"ltp":2.5,"tv":7314.57,"id":26314798}],"tv":16072.48}]}
{"op":"mcm","clk":"994424017","pt":1580551751706,"mc":[{"id":"1.168130661","rc":[{"batl":[[0,34,2.48]],"ltp":30.0,"tv":277.61,"id":25545675}]}]}
{"op":"mcm","clk":"994428124","pt":1580551776685,"mc":[{"id":"1.168130661","rc":[{"batb":[[1,3,3.01]],"ltp":3.05,"tv":5042.38,"id":25238892}]}]}
{"op":"mcm","clk":"994431270","pt":1580551796709,"mc":[{"id":"1.168130661","rc":[{"batl":[[1,3.15,4],[2,3.2,12]],"ltp":3.05,"tv":5042.38,"id":25238892}]}]}
{"op":"mcm","clk":"994438074","pt":1580551836688,"mc":[{"id":"1.168130661","rc":[{"batl":[[1,2.52,39.75]],"ltp":2.5,"tv":7314.57,"id":26314798},{"batb":[[0,11,1.56],[1,10.5,23.69],[2,10,25.86]],"ltp":10.5,"tv":979.22,"id":420}]}]}
{"op":"mcm","clk":"994438987","pt":1580551841708,"mc":[{"id":"1.168130661","rc":[{"trd":[[3.05,500.36]],"batb":[[0,3.05,9]],"ltp":3.05,"tv":5050.38,"id":25238892}],"tv":16080.48}]}
{"op":"mcm","clk":"994442017","pt":1580551859625,"mc":[{"id":"1.168130661","rc":[{"batb":[[1,3,8.01]],"ltp":3.05,"tv":5050.38,"id":25238892}]}]}
{"op":"mcm","clk":"994442196","pt":1580551860658,"mc":[{"id":"1.168130661","rc":[{"batl":[[0,14,2.85],[1,14.5,2],[2,15,2]],"ltp":13.5,"tv":1096.54,"id":24420205}]}]}
{"op":"mcm","clk":"994442353","pt":1580551861553,"mc":[{"id":"1.168130661","rc":[{"trd":[[30,62.49]],"ltp":30.0,"tv":281.61,"id":25545675},{"batb":[[0,13.5,1.28],[1,13,5.75],[2,12.5,2.07]],"ltp":13.5,"tv":1096.54,"id":24420205},{"trd":[[11,216.11]],"batb":[[0,10.5,23.69],[1,10,25.86],[2,9.8,15]],"batl":[[0,11.5,1.83]],"ltp":11.0,"tv":982.35,"id":420}],"tv":16087.61}]}
{"op":"mcm","clk":"994442559","pt":1580551862718,"mc":[{"id":"1.168130661","rc":[{"batb":[[2,27,7.46]],"ltp":30.0,"tv":281.61,"id":25545675},{"batb":[[2,9.8,16.75]],"ltp":11.0,"tv":982.35,"id":420}]}]}
{"op":"mcm","clk":"994443379","pt":1580551867648,"mc":[{"id":"1.168130661","rc":[{"trd":[[13,45.84]],"batl":[[0,13,2.35]],"ltp":13.0,"tv":1379.35,"id":24707172}],"tv":16104.83}]}
{"op":"mcm","clk":"994443886","pt":1580551870627,"mc":[{"id":"1.168130661","rc":[{"batl":[[1,2.52,41.75]],"ltp":2.5,"tv":7314.57,"id":26314798}]}]}
{"op":"mcm","clk":"994444599","pt":1580551874651,"mc":[{"id":"1.168130661","rc":[{"trd":[[3.05,510.36]],"batb":[[0,3.05,1]],"ltp":3.05,"tv":5060.38,"id":25238892},{"batl":[[0,13.5,30.35],[1,15,77.74],[2,15.5,2.55]],"ltp":13.0,"tv":1379.35,"id":24707172}],"tv":16114.83}]}
{"op":"mcm","clk":"994444886","pt":1580551876561,"mc":[{"id":"1.168130661","rc":[{"batb":[[2,2.98,8.81]],"ltp":3.05,"tv":5060.38,"id":25238892},{"batl":[[0,13,2.43],[1,13.5,30],[2,14.5,5.91]],"ltp":13.0,"tv":1379.35,"id":24707172}]}]}
{"op":"mcm","clk":"994445252","pt":1580551878643,"mc":[{"id":"1.168130661","rc":[{"batb":[[0,13.5,3.37],[1,13,15.75]],"ltp":13.5,"tv":1096.54,"id":24420205}]}]}
{"op":"mcm","clk":"994446508","pt":1580551885660,"mc":[{"id":"1.168130661","rc":[{"trd":[[34,54.29]],"batl":[[0,34,2]],"ltp":34.0,"tv":285.72,"id":25545675},{"trd":[[3.1,287.31]],"batb":[[0,3.05,9.65],[2,2.98,6.17]],"batl":[[0,3.15,11.59],[1,3.2,12],[2,3.25,27.79]],"ltp":3.1,"tv":5069.66,"id":25238892},{"trd":[[10,41.14],[10.5,88.31],[11,170.52],[11.5,142.98]],"batb":[[0,10.5,9.82],[1,10,32.11],[2,9.8,4.13]],"batl":[[0,13,2.08],[2,15,77.74]],"ltp":10.5,"tv":1444.77,"id":24707172},{"trd":[[14,11.16]],"batl":[[0,15,5.13],[1,17.5,17.24],[2,20,8]],"ltp":14.0,"tv":1100.18,"id":24420205},{"trd":[[2.5,504.02]],"batb":[[0,2.5,15.33],[1,2.48,108.48],[2,2.46,33.17]],"batl":[[0,2.52,38.75],[1,2.54,99],[2,2.56,3.15]],"ltp":2.5,"tv":7327.46,"id":26314798},{"trd":[[11,216.55],[11.5,106.95],[12,26.71]],"batb":[[0,11,4.13],[1,10.5,23.69],[2,10,25.86]],"batl":[[0,11.5,4.47],[1,12,330.33]],"ltp":12.0,"tv":984.84,"id":420}],"tv":16212.66}]}
{"op":"mcm","clk":"994446691","pt":1580551886692,"mc":[{"id":"1.168130661","rc":[{"batb":[[0,3.05,6.65]],"ltp":3.1,"tv":5069.66,"id":25238892},{"batb":[[0,10.5,8.79]],"ltp":10.5,"tv":1444.77,"id":24707172},{"batb":[[0,2.5,6.2],[2,2.46,27.42]],"batl":[[1,2.54,102]],"ltp":2.5,"tv":7327.46,"id":26314798},{"batb":[[0,10.5,23.69],[1,10,28.82],[2,9.8,17.24]],"ltp":12.0,"tv":984.84,"id":420}]}]}
{"op":"mcm","clk":"994446840","pt":1580551887651,"mc":[{"id":"1.168130661","rc":[{"batb":[[0,3.05,9.65],[1,3,10.01],[2,2.98,8.17]],"ltp":3.1,"tv":5069.66,"id":25238892},{"trd":[[11,172.52]],"batl":[[0,13,2.98]],"ltp":11.0,"tv":1446.77,"id":24707172},{"batl":[[0,14,2.15],[1,15,5.13],[2,17.5,17.24]],"ltp":14.0,"tv":1100.18,"id":24420205},{"batl":[[0,12,330.33],[1,12.5,10],[2,13,10]],"ltp":12.0,"tv":984.84,"id":420}],"tv":16214.66}]}
{"op":"mcm","clk":"994447012","pt":1580551888662,"mc":[{"id":"1.168130661","rc":[{"batb":[[2,2.46,19]],"ltp":2.5,"tv":7327.46,"id":26314798},{"batb":[[1,10,25.86]],"ltp":12.0,"tv":984.84,"id":420}]}]}
{"op":"mcm","clk":"994447177","pt":1580551889669,"mc":[{"id":"1.168130661","rc":[{"batb":[[1,3,12.01]],"ltp":3.1,"tv":5069.66,"id":25238892}]}]}
{"op":"mcm","clk":"994447432","pt":1580551891395,"mc":[{"id":"1.168130661","rc":[{"batl":[[2,17,4.03]],"ltp":14.0,"tv":1100.18,"id":24420205}]}]}
{"op":"mcm","clk":"994447637","pt":1580551892692,"mc":[{"id":"1.168130661","rc":[{"trd":[[2.5,516.42]],"batb":[[0,2.48,108.48],[1,2.46,19],[2,2.44,19]],"batl":[[0,2.5,8.8],[1,2.52,41.75],[2,2.54,102]],"ltp":2.5,"tv":7339.86,"id":26314798}],"tv":16227.06}]}
{"op":"mcm","clk":"994447886","pt":1580551894187,"mc":[{"id":"1.168130661","rc":[{"batb":[[1,2.46,33.17]],"ltp":2.5,"tv":7339.86,"id":26314798}]}]}
{"op":"mcm","clk":"994448335","pt":1580551896699,"mc":[{"id":"1.168130661","rc":[{"trd":[[2.48,84.6]],"batb":[[0,2.48,104.79]],"batl":[[0,2.52,38.75],[1,2.54,102],[2,2.56,3.15]],"ltp":2.48,"tv":7357.46,"id":26314798}],"tv":16244.66}]}
{"op":"mcm","clk":"994448488","pt":1580551897667,"mc":[{"id":"1.168130661","rc":[{"batl":[[0,14.5,3.25]],"ltp":14.0,"tv":1100.18,"id":24420205}]}]}
{"op":"mcm","clk":"994449270","pt":1580551902716,"mc":[{"id":"1.168130661","rc":[{"batl":[[0,11.5,3.01],[1,12,330.33],[2,12.5,10]],"ltp":12.0,"tv":984.84,"id":420}]}]}
{"op":"mcm","clk":"994449610","pt":1580551904697,"mc":[{"id":"1.168130661","rc":[{"trd":[[3.05,519.92]],"batb":[[0,3.05,1.87]],"ltp":3.05,"tv":5079.22,"id":25238892},{"trd":[[2.48,96.34]],"batb":[[0,2.48,98.92]],"ltp":2.48,"tv":7369.2,"id":26314798}],"tv":16265.96}]}
{"op":"mcm","clk":"994450660","pt":1580551910619,"mc":[{"id":"1.168130661","rc":[{"batl":[[0,3.1,5],[1,3.15,11.59],[2,3.2,12]],"ltp":3.05,"tv":5079.22,"id":25238892}]}]}
{"op":"mcm","clk":"994453089","pt":1580551923661,"mc":[{"id":"1.168130661","rc":[{"trd":[[34,58.29]],"batb":[[2,27,5.23]],"batl":[[0,36,18.79],[1,44,10.17],[2,46,13.47]],"ltp":34.0,"tv":289.72,"id":25545675},{"trd":[[11.5,112.97]],"batb":[[2,9.8,15]],"batl":[[0,11.5,4.51]],"ltp":11.5,"tv":990.86,"id":420}],"tv":16275.98}]}
{"op":"mcm","clk":"994453268","pt":1580551924637,"mc":[{"id":"1.168130661","rc":[{"batl":[[0,14,3.37]],"ltp":14.0,"tv":1100.18,"id":24420205},{"batl":[[0,12,330.33],[1,12.5,10],[2,13,10]],"ltp":11.5,"tv":990.86,"id":420}]}]}
{"op":"mcm","clk":"994453386","pt":1580551925344,"mc":[{"id":"1.168130661","rc":[{"batb":[[2,2.98,5]],"ltp":3.05,"tv":5079.22,"id":25238892}]}]}
{"op":"mcm","clk":"994454229","pt":1580551929645,"mc":[{"id":"1.168130661","rc":[{"batl":[[2,3.2,16]],"ltp":3.05,"tv":5079.22,"id":25238892}]}]}
{"op":"mcm","clk":"994454412","pt":1580551930641,"mc":[{"id":"1.168130661","rc":[{"batl":[[1,14.5,4],[2,15,5.13]],"ltp":14.0,"tv":1100.18,"id":24420205}]}]}
{"op":"mcm","clk":"994455591","pt":1580551936670,"mc":[{"id":"1.168130661","rc":[{"batl":[[0,12.5,4.9],[1,13,2.08],[2,13.5,30]],"ltp":11.0,"tv":1446.77,"id":24707172}]}]}
{"op":"mcm","clk":"994460470","pt":1580551963694,"mc":[{"id":"1.168130661","rc":[{"batl":[[0,14,2.38]],"ltp":14.0,"tv":1100.18,"id":24420205}]}]}
{"op":"mcm","clk":"994463039","pt":1580551977701,"mc":[{"id":"1.168130661","rc":[{"batb":[[0,3.05,9.87]],"ltp":3.05,"tv":5079.22,"id":25238892}]}]}
{"op":"mcm","clk":"994463622","pt":1580551980722,"mc":[{"id":"1.168130661","rc":[{"batl":[[0,2.52,47.2]],"ltp":2.48,"tv":7369.2,"id":26314798}]}]}
{"op":"mcm","clk":"994465459","pt":1580551990692,"mc":[{"id":"1.168130661","rc":[{"batl":[[0,12.5,2.9]],"ltp":11.0,"tv":1446.77,"id":24707172}]}]}
{"op":"mcm","clk":"994466489","pt":1580551996406,"mc":[{"id":"1.168130661","rc":[{"batl":[[0,2.52,45.2]],"ltp":2.48,"tv":7369.2,"id":26314798}]}]}
{"op":"mcm","clk":"994467982","pt":1580552005537,"mc":[{"id":"1.168130661","rc":[{"batl":[[2,13.5,38.27]],"ltp":11.0,"tv":1446.77,"id":24707172}]}]}
{"op":"mcm","clk":"994470221","pt":1580552018561,"mc":[{"id":"1.168130661","rc":[{"batb":[[0,2.48,109]],"batl":[[0,2.5,10],[1,2.52,49.2],[2,2.54,102]],"ltp":2.48,"tv":7369.2,"id":26314798}]}]}
{"op":"mcm","clk":"994470892","pt":1580552022566,"mc":[{"id":"1.168130661","rc":[{"trd":[[13.5,36.98]],"batb":[[0,13.5,1.69]],"ltp":13.5,"tv":1103.54,"id":24420205}],"tv":16279.34}]}
{"op":"mcm","clk":"994472962","pt":1580552034647,"mc":[{"id":"1.168130661","rc":[{"trd":[[11,174.32]],"batb":[[0,10.5,2.79]],"batl":[[0,13,2.08],[1,13.5,38.27],[2,15,77.74]],"ltp":11.0,"tv":1448.57,"id":24707172}],"tv":16281.14}]}
{"op":"mcm","clk":"994473288","pt":1580552036585,"mc":[{"id":"1.168130661","rc":[{"batb":[[0,10.5,8.28]],"ltp":11.0,"tv":1448.57,"id":24707172}]}]}
{"op":"mcm","clk":"994474718","pt":1580552044522,"mc":[{"id":"1.168130661","rc":[{"batb":[[0,30,2.33]],"ltp":34.0,"tv":289.72,"id":25545675}]}]}
{"op":"mcm","clk":"994477133","pt":1580552057649,"mc":[{"id":"1.168130661","rc":[{"trd":[[2.48,132.34]],"batb":[[0,2.48,91]],"ltp":2.48,"tv":7405.2,"id":26314798}],"tv":16317.14}]}
{"op":"mcm","clk":"994478664","pt":1580552066668,"mc":[{"id":"1.168130661","rc":[{"batb":[[0,2.48,105.49]],"ltp":2.48,"tv":7405.2,"id":26314798}]}]}
{"op":"mcm","clk":"994480648","pt":1580552077658,"mc":[{"id":"1.168130661","rc":[{"trd":[[2.5,524.42]],"batl":[[0,2.5,6]],"ltp":2.5,"tv":7413.2,"id":26314798}],"tv":16325.14}]}
{"op":"mcm","clk":"994482666","pt":1580552088678,"mc":[{"id":"1.168130661","rc":[{"batl":[[0,13,3.31]],"ltp":11.0,"tv":1448.57,"id":24707172}]}]}
{"op":"mcm","clk":"994483887","pt":1580552095695,"mc":[{"id":"1.168130661","rc":[{"trd":[[3.05,531.92]],"batb":[[0,3,12.88],[1,2.98,5],[2,2.96,22.03]],"ltp":3.05,"tv":5091.22,"id":25238892}],"tv":16337.13}]}
{"op":"mcm","clk":"994484081","pt":1580552096709,"mc":[{"id":"1.168130661","rc":[{"batb":[[1,2.98,9.49]],"ltp":3.05,"tv":5091.22,"id":25238892}]}]}
{"op":"mcm","clk":"994484285","pt":1580552097721,"mc":[{"id":"1.168130661","rc":[{"batb":[[0,10.5,2.79]],"ltp":11.0,"tv":1448.57,"id":24707172}]}]}
{"op":"mcm","clk":"994484472","pt":1580552098693,"mc":[{"id":"1.168130661","rc":[{"batl":[[0,12.5,4],[1,13,3.31],[2,13.5,38.27]],"ltp":11.0,"tv":1448.57,"id":24707172}]}]}
{"op":"mcm","clk":"994487240","pt":1580552114653,"mc":[{"id":"1.168130661","rc":[{"batl":[[1,13,2.08]],"ltp":11.0,"tv":1448.57,"id":24707172}]}]}
{"op":"mcm","clk":"994489129","pt":1580552124655,"mc":[{"id":"1.168130661","rc":[{"trd":[[2.5,528.42]],"batl":[[0,2.5,4]],"ltp":2.5,"tv":7417.2,"id":26314798}],"tv":16341.13}]}
{"op":"mcm","clk":"994493723","pt":1580552151691,"mc":[{"id":"1.168130661","rc":[{"batl":[[0,12.5,2]],"ltp":11.0,"tv":1448.57,"id":24707172}]}]}
{"op":"mcm","clk":"994494308","pt":1580552154671,"mc":[{"id":"1.168130661","rc":[{"batl":[[0,13,2.08],[1,13.5,38.27],[2,15,77.74]],"ltp":11.0,"tv":1448.57,"id":24707172}]}]}
{"op":"mcm","clk":"994495236","pt":1580552160717,"mc":[{"id":"1.168130661","rc":[{"batb":[[0,10.5,8.28]],"ltp":11.0,"tv":1448.57,"id":24707172}]}]}
{"op":"mcm","clk":"994495416","pt":1580552161721,"mc":[{"id":"1.168130661","rc":[{"batl":[[0,34,2.5],[1,36,18.79],[2,44,10.17]],"ltp":34.0,"tv":289.72,"id":25545675}]}]}
{"op":"mcm","clk":"994496364","pt":1580552167691,"mc":[{"id":"1.168130661","rc":[{"batb":[[0,11,5.6],[1,10.5,23.69],[2,10,25.86]],"ltp":11.5,"tv":990.86,"id":420}]}]}
{"op":"mcm","clk":"994497414","pt":1580552173684,"mc":[{"id":"1.168130661","rc":[{"trd":[[11,174.92]],"batb":[[0,10.5,7.98]],"ltp":11.0,"tv":1449.17,"id":24707172}],"tv":16341.73}]}
{"op":"mcm","clk":"994497721","pt":1580552175664,"mc":[{"id":"1.168130661","rc":[{"batb":[[0,10.5,8.17]],"ltp":11.0,"tv":1449.17,"id":24707172}]}]}
{"op":"mcm","clk":"994498061","pt":1580552177628,"mc":[{"id":"1.168130661","rc":[{"batb":[[1,10.5,33.69]],"ltp":11.5,"tv":990.86,"id":420}]}]}
{"op":"mcm","clk":"994498247","pt":1580552178641,"mc":[{"id":"1.168130661","rc":[{"trd":[[3,176.35],[3.05,533.66]],"batb":[[0,3,6.88]],"ltp":3.0,"tv":5103.22,"id":25238892},{"trd":[[10.5,99.21],[11,176.02]],"batb":[[0,10.5,2.17]],"ltp":10.5,"tv":1461.17,"id":24707172}],"tv":16365.73}]}
{"op":"mcm","clk":"994498444","pt":1580552179667,"mc":[{"id":"1.168130661","rc":[{"batb":[[0,3,9.88]],"ltp":3.0,"tv":5103.22,"id":25238892},{"batb":[[0,11,2.09],[1,10.5,2.17],[2,10,32.11]],"ltp":10.5,"tv":1461.17,"id":24707172}]}]}
{"op":"mcm","clk":"994499186","pt":1580552183659,"mc":[{"id":"1.168130661","rc":[{"batl":[[0,12,330.83]],"ltp":11.5,"tv":990.86,"id":420}]}]}
{"op":"mcm","clk":"994499503","pt":1580552185688,"mc":[{"id":"1.168130661","rc":[{"batl":[[0,14.5,4],[1,15,5.13],[2,17.5,14.03]],"ltp":13.5,"tv":1103.54,"id":24420205},{"batl":[[0,11.5,4.76],[1,12,330.83],[2,12.5,10]],"ltp":11.5,"tv":990.86,"id":420}]}]}
{"op":"mcm","clk":"994499662","pt":1580552186679,"mc":[{"id":"1.168130661","rc":[{"batl":[[0,13,3.31]],"ltp":10.5,"tv":1461.17,"id":24707172},{"batl":[[1,12,330.33]],"ltp":11.5,"tv":990.86,"id":420}]}]}
{"op":"mcm","clk":"994499834","pt":1580552187665,"mc":[{"id":"1.168130661","rc":[{"batb":[[1,10,32.11],[2,9.8,4.13]],"ltp":10.5,"tv":1461.17,"id":24707172}]}]}
{"op":"mcm","clk":"994500033","pt":1580552188689,"mc":[{"id":"1.168130661","rc":[{"batb":[[0,10.5,2.15]],"ltp":10.5,"tv":1461.17,"id":24707172}]}]}
{"op":"mcm","clk":"994500404","pt":1580552190671,"mc":[{"id":"1.168130661","rc":[{"batl":[[0,2.52,49.2],[1,2.54,102],[2,2.56,3.15]],"ltp":2.5,"tv":7417.2,"id":26314798}]}]}
{"op":"mcm","clk":"994501456","pt":1580552196704,"mc":[{"id":"1.168130661","rc":[{"batb":[[0,30,7.33]],"ltp":34.0,"tv":289.72,"id":25545675},{"batb":[[0,2.5,6.89],[1,2.48,105.49],[2,2.46,33.17]],"ltp":2.5,"tv":7417.2,"id":26314798}]}]}
{"op":"mcm","clk":"994501643","pt":1580552197721,"mc":[{"id":"1.168130661","rc":[{"batb":[[0,10.5,4.32]],"ltp":10.5,"tv":1461.17,"id":24707172},{"trd":[[2.5,532.42]],"batb":[[0,2.5,4.89]],"batl":[[0,2.52,45.2]],"ltp":2.5,"tv":7421.2,"id":26314798}],"tv":16369.73}]}
{"op":"mcm","clk":"994501802","pt":1580552198696,"mc":[{"id":"1.168130661","rc":[{"batb":[[2,2.46,19]],"ltp":2.5,"tv":7421.2,"id":26314798}]}]}
{"op":"mcm","clk":"994502800","pt":1580552204605,"mc":[{"id":"1.168130661","rc":[{"batl":[[0,3.05,5]],"ltp":3.0,"tv":5103.22,"id":25238892}]}]}
{"op":"mcm","clk":"994503152","pt":1580552206699,"mc":[{"id":"1.168130661","rc":[{"batb":[[0,10.5,2.15]],"ltp":10.5,"tv":1461.17,"id":24707172}]}]}
{"op":"mcm","clk":"994503752","pt":1580552209620,"mc":[{"id":"1.168130661","rc":[{"batl":[[2,20,20.03]],"ltp":13.5,"tv":1103.54,"id":24420205},{"batl":[[0,11.5,5.26]],"ltp":11.5,"tv":990.86,"id":420}]}]}
{"op":"mcm","clk":"994504368","pt":1580552211632,"mc":[{"id":"1.168130661","rc":[{"trd":[[2.52,387.87]],"batl":[[0,2.52,21.2]],"ltp":2.52,"tv":7469.2,"id":26314798}],"tv":16417.73}]}
{"op":"mcm","clk":"994504660","pt":1580552212623,"mc":[{"id":"1.168130661","rc":[{"batb":[[0,2.5,21.21]],"batl":[[0,2.52,17.39]],"ltp":2.52,"tv":7469.2,"id":26314798}]}]}
{"op":"mcm","clk":"994506070","pt":1580552220627,"mc":[{"id":"1.168130661","rc":[{"batb":[[0,13.5,4.89]],"ltp":13.5,"tv":1103.54,"id":24420205}]}]}
{"op":"mcm","clk":"994506291","pt":1580552221649,"mc":[{"id":"1.168130661","rc":[{"batl":[[0,14,2.3],[1,14.5,4],[2,15,5.13]],"ltp":13.5,"tv":1103.54,"id":24420205},{"trd":[[11.5,113.97]],"batl":[[0,12,330.33],[1,12.5,10],[2,13,10]],"ltp":11.5,"tv":991.86,"id":420}],"tv":16418.73}]}
{"op":"mcm","clk":"994506460","pt":1580552222513,"mc":[{"id":"1.168130661","rc":[{"batb":[[1,2.48,112.77]],"ltp":2.52,"tv":7469.2,"id":26314798},{"batb":[[0,11,6.12]],"batl":[[0,11.5,2.52],[1,12,330.33],[2,12.5,10]],"ltp":11.5,"tv":991.86,"id":420}]}]}
{"op":"mcm","clk":"994508055","pt":1580552231634,"mc":[{"id":"1.168130661","rc":[{"trd":[[2.52,399.77]],"batb":[[1,2.48,102.69]],"batl":[[0,2.52,11.44]],"ltp":2.52,"tv":7481.1,"id":26314798}],"tv":16430.63}]}
{"op":"mcm","clk":"994509295","pt":1580552238637,"mc":[{"id":"1.168130661","rc":[{"batl":[[1,3.1,2],[2,3.15,11.59]],"ltp":3.0,"tv":5103.22,"id":25238892},{"trd":[[2.5,574.84]],"batb":[[0,2.48,102.69],[1,2.46,19],[2,2.44,19]],"batl":[[0,2.5,5.79],[1,2.52,11.44],[2,2.54,102]],"ltp":2.5,"tv":7523.52,"id":26314798}],"tv":16473.05}]}
{"op":"mcm","clk":"994509454","pt":1580552239550,"mc":[{"id":"1.168130661","rc":[{"batb":[[1,2.46,27.68]],"ltp":2.5,"tv":7523.52,"id":26314798}]}]}
{"op":"mcm","clk":"994509569","pt":1580552240254,"mc":[{"id":"1.168130661","rc":[{"batb":[[0,2.48,95.41],[1,2.46,33.17]],"ltp":2.5,"tv":7523.52,"id":26314798}]}]}
{"op":"mcm","clk":"994511094","pt":1580552248672,"mc":[{"id":"1.168130661","rc":[{"trd":[[2.5,586.42]],"batb":[[0,2.5,11.49],[1,2.48,95.41],[2,2.46,33.17]],"batl":[[0,2.52,17.18],[1,2.54,102],[2,2.56,3.15]],"ltp":2.5,"tv":7535.1,"id":26314798}],"tv":16484.63}]}
{"op":"mcm","clk":"994511428","pt":1580552250678,"mc":[{"id":"1.168130661","rc":[{"batl":[[1,3.1,4]],"ltp":3.0,"tv":5103.22,"id":25238892},{"batb":[[2,2.46,27.68]],"ltp":2.5,"tv":7535.1,"id":26314798}]}]}
{"op":"mcm","clk":"994511716","pt":1580552252446,"mc":[{"id":"1.168130661","rc":[{"batl":[[0,14.5,4],[1,15,5.13],[2,17.5,14.03]],"ltp":13.5,"tv":1103.54,"id":24420205},{"batl":[[0,11.5,2.34]],"ltp":11.5,"tv":991.86,"id":420}]}]}
{"op":"mcm","clk":"994513118","pt":1580552259720,"mc":[{"id":"1.168130661","rc":[{"batl":[[0,12.5,2],[1,13,3.31],[2,13.5,38.27]],"ltp":10.5,"tv":1461.17,"id":24707172}]}]}
{"op":"mcm","clk":"994513364","pt":1580552260686,"mc":[{"id":"1.168130661","rc":[{"batl":[[0,12.5,4]],"ltp":10.5,"tv":1461.17,"id":24707172}]}]}
{"op":"mcm","clk":"994514152","pt":1580552264585,"mc":[{"id":"1.168130661","rc":[{"trd":[[34,58.74]],"batl":[[0,34,2.05]],"ltp":34.0,"tv":290.17,"id":25545675},{"trd":[[3.05,538.66]],"batl":[[0,3.1,4],[1,3.15,11.59],[2,3.2,16]],"ltp":3.05,"tv":5108.22,"id":25238892},{"trd":[[11,177.41]],"batb":[[0,10.5,8.81],[1,10,34.11]],"batl":[[0,11,6.11],[1,12.5,4],[2,13,3.31]],"ltp":11.0,"tv":1462.56,"id":24707172},{"trd":[[14.5,1.05]],"batl":[[0,14.5,2.95]],"ltp":14.5,"tv":1104.59,"id":24420205},{"trd":[[2.52,405.82]],"batb":[[0,2.5,20.49]],"batl":[[0,2.52,11.13]],"ltp":2.52,"tv":7541.15,"id":26314798},{"trd":[[11.5,117.32]],"batl":[[0,11.5,3.51]],"ltp":11.5,"tv":995.21,"id":420}],"tv":16501.92}]}
{"op":"mcm","clk":"994514588","pt":1580552266687,"mc":[{"id":"1.168130661","rc":[{"batb":[[1,2.48,100.75]],"ltp":2.52,"tv":7541.15,"id":26314798}]}]}
{"op":"mcm","clk":"994515331","pt":1580552269626,"mc":[{"id":"1.168130661","rc":[{"batl":[[2,20,20.03]],"ltp":14.5,"tv":1104.59,"id":24420205}]}]}
{"op":"mcm","clk":"994516927","pt":1580552277656,"mc":[{"id":"1.168130661","rc":[{"trd":[[34,62.66]],"batl":[[0,36,18.79],[1,44,10.17],[2,46,13.47]],"ltp":34.0,"tv":294.09,"id":25545675},{"trd":[[3.05,540.66]],"batb":[[0,3.05,3.31],[1,3,12.82],[2,2.98,9.49]],"ltp":3.05,"tv":5110.22,"id":25238892},{"trd":[[11,177.96]],"batl":[[0,11,5.56]],"ltp":11.0,"tv":1463.11,"id":24707172},{"trd":[[14.5,1.47]],"batl":[[0,14.5,2.53]],"ltp":14.5,"tv":1105.01,"id":24420205},{"trd":[[2.52,408.24]],"batl":[[0,2.52,8.71]],"ltp":2.52,"tv":7543.57,"id":26314798},{"trd":[[11.5,117.85]],"batl":[[0,11.5,2.98]],"ltp":11.5,"tv":995.74,"id":420}],"tv":16511.76}]}
{"op":"mcm","clk":"994518289","pt":1580552284689,"mc":[{"id":"1.168130661","rc":[{"batb":[[2,2.98,5]],"ltp":3.05,"tv":5110.22,"id":25238892},{"batb":[[0,14,4.53],[1,13.5,4.89],[2,13,15.75]],"ltp":14.5,"tv":1105.01,"id":24420205}]}]}
{"op":"mcm","clk":"994518473","pt":1580552285645,"mc":[{"id":"1.168130661","rc":[{"batb":[[0,3.05,3.83]],"ltp":3.05,"tv":5110.22,"id":25238892},{"trd":[[11,178.24]],"batl":[[0,11,5.42]],"ltp":11.0,"tv":1463.4,"id":24707172},{"batb":[[0,14,4.65]],"ltp":14.5,"tv":1105.01,"id":24420205},{"trd":[[2.52,409.49]],"batl":[[0,2.52,8.09]],"ltp":2.52,"tv":7544.82,"id":26314798},{"batb":[[0,11,6.27]],"batl":[[0,12,330.33],[1,12.5,10],[2,13,10]],"ltp":11.5,"tv":995.74,"id":420}],"tv":16513.29}]}
{"op":"mcm","clk":"994518665","pt":1580552286673,"mc":[{"id":"1.168130661","rc":[{"batl":[[0,11.5,2.75],[1,12,330.33],[2,12.5,10]],"ltp":11.5,"tv":995.74,"id":420}]}]}
{"op":"mcm","clk":"994519251","pt":1580552289673,"mc":[{"id":"1.168130661","rc":[{"batb":[[0,32,3.6],[1,30,7.33],[2,29,5.04]],"ltp":34.0,"tv":294.09,"id":25545675},{"trd":[[3.1,295.31]],"batb":[[0,3.05,38.3]],"batl":[[0,3.15,4],[1,3.2,16],[2,3.25,27.79]],"ltp":3.1,"tv":5118.22,"id":25238892},{"trd":[[11,189.09],[11.5,144.98]],"batb":[[0,11.5,1.05],[1,11,5.05],[2,10.5,2.15]],"batl":[[0,12.5,4],[1,13,3.31],[2,13.5,38.27]],"ltp":11.5,"tv":1476.24,"id":24707172},{"trd":[[14.5,6.53]],"batb":[[0,14.5,5.42],[1,14,2.65],[2,13.5,4.89]],"batl":[[0,15,5.13],[1,20,20.03],[2,21,2]],"ltp":14.5,"tv":1110.07,"id":24420205},{"trd":[[2.52,425.67]],"batb":[[0,2.52,37.63],[1,2.5,17.52],[2,2.48,100.75]],"batl":[[0,2.54,102],[1,2.56,3.15],[2,2.58,126.26]],"ltp":2.52,"tv":7561.0,"id":26314798},{"trd":[[11,220.55]],"batb":[[0,11,10.7]],"ltp":11.0,"tv":999.74,"id":420}],"tv":16559.38}]}
{"op":"mcm","clk":"994519462","pt":1580552290716,"mc":[{"id":"1.168130661","rc":[{"batl":[[1,3.2,24.9]],"ltp":3.1,"tv":5118.22,"id":25238892},{"trd":[[11.5,147.08]],"batb":[[0,11,7.05],[1,10.5,2.15],[2,10,32.11]],"ltp":11.5,"tv":1478.34,"id":24707172},{"trd":[[14.5,8.21]],"batb":[[0,14.5,4.58],[1,14,4.65]],"ltp":14.5,"tv":1111.75,"id":24420205}],"tv":16563.16}]}
{"op":"mcm","clk":"994519590","pt":1580552291319,"mc":[{"id":"1.168130661","rc":[{"batb":[[1,2.5,30.21]],"ltp":2.52,"tv":7561.0,"id":26314798}]}]}
{"op":"mcm","clk":"994519825","pt":1580552292650,"mc":[{"id":"1.168130661","rc":[{"batl":[[1,3.2,16],[2,3.25,36.54]],"ltp":3.1,"tv":5118.22,"id":25238892}]}]}
{"op":"mcm","clk":"994520192","pt":1580552294571,"mc":[{"id":"1.168130661","rc":[{"trd":[[2.52,448.51]],"batb":[[0,2.52,26.21]],"ltp":2.52,"tv":7583.84,"id":26314798}],"tv":16586.0}]}
{"op":"mcm","clk":"994520387","pt":1580552295590,"mc":[{"id":"1.168130661","rc":[{"batl":[[1,19.5,4.03],[2,20,20]],"ltp":14.5,"tv":1111.75,"id":24420205}]}]}
{"op":"mcm","clk":"994521178","pt":1580552299653,"mc":[{"id":"1.168130661","rc":[{"batl":[[2,20,8]],"ltp":14.5,"tv":1111.75,"id":24420205}]}]}
{"op":"mcm","clk":"994521707","pt":1580552302585,"mc":[{"id":"1.168130661","rc":[{"trd":[[2.52,458.51]],"batb":[[0,2.52,21.2]],"ltp":2.52,"tv":7593.84,"id":26314798}],"tv":16596.0}]}
{"op":"mcm","clk":"994522131","pt":1580552304668,"mc":[{"id":"1.168130661","rc":[{"trd":[[3.05,558.4]],"batb":[[0,3.05,29.43]],"ltp":3.05,"tv":5135.96,"id":25238892},{"batl":[[1,13,2.08]],"ltp":11.5,"tv":1478.34,"id":24707172}],"tv":16613.74}]}
{"op":"mcm","clk":"994522520","pt":1580552306690,"mc":[{"id":"1.168130661","rc":[{"batl":[[0,3.1,5],[1,3.15,4],[2,3.2,16]],"ltp":3.05,"tv":5135.96,"id":25238892},{"trd":[[11.5,151.36]],"batl":[[0,11.5,7.33],[1,12.5,4],[2,13,2.08]],"ltp":11.5,"tv":1482.62,"id":24707172}],"tv":16618.02}]}
{"op":"mcm","clk":"994523619","pt":1580552312700,"mc":[{"id":"1.168130661","rc":[{"batl":[[1,12.5,2]],"ltp":11.5,"tv":1482.62,"id":24707172}]}]}
{"op":"mcm","clk":"994523797","pt":1580552313702,"mc":[{"id":"1.168130661","rc":[{"trd":[[11.5,166.02]],"batb":[[0,11.5,2.18],[1,11,7.05],[2,10.5,2.15]],"batl":[[0,13,2.08],[1,13.5,38.27],[2,15,77.74]],"ltp":11.5,"tv":1497.28,"id":24707172}],"tv":16632.68}]}
{"op":"mcm","clk":"994524709","pt":1580552318701,"mc":[{"id":"1.168130661","rc":[{"trd":[[14.5,17.36]],"batb":[[0,14,2.65],[1,13.5,8.38],[2,13,15.75]],"batl":[[0,14.5,1.51],[1,15,5.13],[2,19.5,4.03]],"ltp":14.5,"tv":1120.89,"id":24420205},{"batl":[[0,11.5,3.83]],"ltp":11.0,"tv":999.74,"id":420}],"tv":16641.83}]}
{"op":"mcm","clk":"994525096","pt":1580552320699,"mc":[{"id":"1.168130661","rc":[{"batb":[[1,13.5,4.89]],"ltp":14.5,"tv":1120.89,"id":24420205}]}]}
{"op":"mcm","clk":"994525759","pt":1580552324619,"mc":[{"id":"1.168130661","rc":[{"batl":[[0,3.15,4],[1,3.2,16],[2,3.25,41.54]],"ltp":3.05,"tv":5135.96,"id":25238892}]}]}
{"op":"mcm","clk":"994525901","pt":1580552325526,"mc":[{"id":"1.168130661","rc":[{"trd":[[2.52,480.52]],"batb":[[0,2.52,10.2]],"ltp":2.52,"tv":7615.84,"id":26314798}],"tv":16663.83}]}
{"op":"mcm","clk":"994526567","pt":1580552329723,"mc":[{"id":"1.168130661","rc":[{"batl":[[2,18,14.03]],"ltp":14.5,"tv":1120.89,"id":24420205}]}]}
{"op":"mcm","clk":"994527310","pt":1580552333705,"mc":[{"id":"1.168130661","rc":[{"trd":[[3.05,578.4]],"batb":[[0,3.05,19.43]],"batl":[[0,3.15,14.19]],"ltp":3.05,"tv":5155.96,"id":25238892}],"tv":16683.84}]}
{"op":"mcm","clk":"994527492","pt":1580552334719,"mc":[{"id":"1.168130661","rc":[{"batb":[[1,2.5,17.52]],"ltp":2.52,"tv":7615.84,"id":26314798}]}]}
{"op":"mcm","clk":"994529522","pt":1580552346648,"mc":[{"id":"1.168130661","rc":[{"trd":[[2.54,270.91]],"batl":[[0,2.54,92]],"ltp":2.54,"tv":7635.84,"id":26314798}],"tv":16703.84}]}
{"op":"mcm","clk":"994529889","pt":1580552348678,"mc":[{"id":"1.168130661","rc":[{"batl":[[0,3.1,3.45],[1,3.15,14.19],[2,3.2,16]],"ltp":3.05,"tv":5155.96,"id":25238892},{"batl":[[0,15,5.13],[1,18,14.03],[2,19.5,4]],"ltp":14.5,"tv":1120.89,"id":24420205},{"batl":[[0,11.5,2.81]],"ltp":11.0,"tv":999.74,"id":420}]}]}
{"op":"mcm","clk":"994530267","pt":1580552350543,"mc":[{"id":"1.168130661","rc":[{"trd":[[11,225.83]],"batb":[[0,11,8.06]],"ltp":11.0,"tv":1005.02,"id":420}],"tv":16709.11}]}
{"op":"mcm","clk":"994530723","pt":1580552352682,"mc":[{"id":"1.168130661","rc":[{"batl":[[0,11.5,4.81]],"ltp":11.0,"tv":1005.02,"id":420}]}]}
{"op":"mcm","clk":"994530903","pt":1580552353608,"mc":[{"id":"1.168130661","rc":[{"batl":[[0,3.1,8.45]],"ltp":3.05,"tv":5155.96,"id":25238892}]}]}
{"op":"mcm","clk":"994532024","pt":1580552359695,"mc":[{"id":"1.168130661","rc":[{"batl":[[2,19.5,17]],"ltp":14.5,"tv":1120.89,"id":24420205}]}]}
{"op":"mcm","clk":"994532196","pt":1580552360573,"mc":[{"id":"1.168130661","rc":[{"batl":[[1,19.5,17.03],[2,20,8]],"ltp":14.5,"tv":1120.89,"id":24420205}]}]}
{"op":"mcm","clk":"994535459","pt":1580552378499,"mc":[{"id":"1.168130661","rc":[{"batl":[[1,12,331.32]],"ltp":11.0,"tv":1005.02,"id":420}]}]}
{"op":"mcm","clk":"994536009","pt":1580552381412,"mc":[{"id":"1.168130661","rc":[{"batl":[[0,3.1,5]],"ltp":3.05,"tv":5155.96,"id":25238892},{"batl":[[0,11.5,2]],"ltp":11.0,"tv":1005.02,"id":420}]}]}
{"op":"mcm","clk":"994536213","pt":1580552382436,"mc":[{"id":"1.168130661","rc":[{"batl":[[0,14.5,2.17],[1,15,5.13],[2,19.5,17.03]],"ltp":14.5,"tv":1120.89,"id":24420205}]}]}
{"op":"mcm","clk":"994536454","pt":1580552383717,"mc":[{"id":"1.168130661","rc":[{"batb":[[0,32,5.6]],"ltp":34.0,"tv":294.09,"id":25545675},{"batb":[[0,11,7.05],[1,10.5,2.15],[2,10,40.76]],"batl":[[0,12,9.44],[1,12.5,18.44],[2,13,2.08]],"ltp":11.5,"tv":1497.28,"id":24707172}]}]}
{"op":"mcm","clk":"994536824","pt":1580552385637,"mc":[{"id":"1.168130661","rc":[{"batb":[[1,30,10.18]],"ltp":34.0,"tv":294.09,"id":25545675}]}]}
{"op":"mcm","clk":"994537765","pt":1580552390549,"mc":[{"id":"1.168130661","rc":[{"batl":[[2,19,13.03]],"ltp":14.5,"tv":1120.89,"id":24420205}]}]}
{"op":"mcm","clk":"994537986","pt":1580552391636,"mc":[{"id":"1.168130661","rc":[{"batl":[[1,13,2.08],[2,13.5,36.27]],"ltp":11.5,"tv":1497.28,"id":24707172}]}]}
{"op":"mcm","clk":"994538176","pt":1580552392649,"mc":[{"id":"1.168130661","rc":[{"batb":[[0,11.5,2.28],[1,11,7.05],[2,10.5,2.15]],"batl":[[0,13,2.08],[1,13.5,36.27],[2,15,77.74]],"ltp":11.5,"tv":1497.28,"id":24707172}]}]}
{"op":"mcm","clk":"994538986","pt":1580552396663,"mc":[{"id":"1.168130661","rc":[{"trd":[[3.05,590.74]],"batb":[[0,3.05,13.25]],"ltp":3.05,"tv":5168.31,"id":25238892}],"tv":16721.45}]}
{"op":"mcm","clk":"994539970","pt":1580552401656,"mc":[{"id":"1.168130661","rc":[{"batl":[[0,12,3],[1,12.5,18.44],[2,13,2.08]],"ltp":11.5,"tv":1497.28,"id":24707172}]}]}
{"op":"mcm","clk":"994540182","pt":1580552402643,"mc":[{"id":"1.168130661","rc":[{"batb":[[0,11,7.05],[1,10.5,2.15],[2,10,40.76]],"ltp":11.5,"tv":1497.28,"id":24707172}]}]}
{"op":"mcm","clk":"994540374","pt":1580552403652,"mc":[{"id":"1.168130661","rc":[{"batl":[[0,14.5,6.17]],"ltp":14.5,"tv":1120.89,"id":24420205}]}]}
{"op":"mcm","clk":"994540944","pt":1580552406677,"mc":[{"id":"1.168130661","rc":[{"trd":[[11,195.09]],"batb":[[0,11,4.05]],"ltp":11.0,"tv":1503.28,"id":24707172},{"trd":[[11,231.83]],"batb":[[0,11,5.06]],"ltp":11.0,"tv":1011.02,"id":420}],"tv":16733.46}]}
{"op":"mcm","clk":"994541687","pt":1580552410686,"mc":[{"id":"1.168130661","rc":[{"batl":[[1,13,2.08],[2,13.5,36.27]],"ltp":11.0,"tv":1503.28,"id":24707172}]}]}
