{"op":"mcm","clk":"988712674","pt":1580479939158,"mc":[{"id":"1.168133553","rc":[{"batb":[[1,1.16,13],[2,1.03,1628.39]],"ltp":1.51,"tv":12.72,"id":16325787}]}]}
{"op":"mcm","clk":"988713135","pt":1580479944473,"mc":[{"id":"1.168133553","rc":[{"batb":[[0,1.18,36.35],[1,1.17,1.99],[2,1.16,13]],"ltp":1.51,"tv":12.72,"id":16325787}]}]}
{"op":"mcm","clk":"988713325","pt":1580479946664,"mc":[{"id":"1.168133553","rc":[{"batb":[[0,1.19,3],[1,1.18,36.35],[2,1.17,1.99]],"ltp":1.51,"tv":12.72,"id":16325787}]}]}
{"op":"mcm","clk":"988713955","pt":1580479954506,"mc":[{"id":"1.168133553","rc":[{"batb":[[2,1.16,10]],"ltp":1.51,"tv":12.72,"id":16325787}]}]}
{"op":"mcm","clk":"988713968","pt":1580479954712,"mc":[{"id":"1.168133553","rc":[{"batb":[[0,1.2,1.99],[1,1.19,3],[2,1.18,36.35]],"ltp":1.51,"tv":12.72,"id":16325787}]}]}
{"op":"mcm","clk":"988714430","pt":1580479960800,"mc":[{"id":"1.168133553","rc":[{"batb":[[0,1.2,4.99],[1,1.18,36.35],[2,1.16,10]],"ltp":1.51,"tv":12.72,"id":16325787}]}]}
{"op":"mcm","clk":"988715000","pt":1580479967499,"mc":[{"id":"1.168133553","rc":[{"batb":[[1,1.16,10],[2,1.03,1628.39]],"ltp":1.51,"tv":12.72,"id":16325787}]}]}
{"op":"mcm","clk":"988715622","pt":1580479975020,"mc":[{"id":"1.168133553","rc":[{"batb":[[0,1.21,3],[1,1.2,1.99],[2,1.16,10]],"ltp":1.51,"tv":12.72,"id":16325787}]}]}
{"op":"mcm","clk":"988716455","pt":1580479985496,"mc":[{"id":"1.168133553","rc":[{"batb":[[0,1.2,1.99],[1,1.17,3]],"ltp":1.51,"tv":12.72,"id":16325787}]}]}
{"op":"mcm","clk":"988717582","pt":1580480000036,"mc":[{"id":"1.168133553","rc":[{"batb":[[1,1.18,3]],"ltp":1.51,"tv":12.72,"id":16325787}]}]}
{"op":"mcm","clk":"988718364","pt":1580480009338,"mc":[{"id":"1.168133553","rc":[{"batb":[[1,1.19,3]],"ltp":1.51,"tv":12.72,"id":16325787}]}]}
{"op":"mcm","clk":"988718699","pt":1580480013944,"mc":[{"id":"1.168133553","rc":[{"batb":[[0,1.21,35.45],[1,1.2,1.99],[2,1.19,3]],"ltp":1.51,"tv":12.72,"id":16325787}]}]}
{"op":"mcm","clk":"988719220","pt":1580480020555,"mc":[{"id":"1.168133553","rc":[{"batb":[[0,1.23,3],[1,1.22,10],[2,1.21,35.45]],"ltp":1.51,"tv":12.72,"id":16325787}]}]}
{"op":"mcm","clk":"988719534","pt":1580480024351,"mc":[{"id":"1.168133553","rc":[{"batb":[[0,1.24,1.99],[1,1.23,3],[2,1.22,10]],"ltp":1.51,"tv":12.72,"id":16325787}]}]}
{"op":"mcm","clk":"988720098","pt":1580480031542,"mc":[{"id":"1.168133553","rc":[{"batb":[[0,1.24,4.99],[1,1.22,10],[2,1.21,35.45]],"ltp":1.51,"tv":12.72,"id":16325787}]}]}
{"op":"mcm","clk":"988720600","pt":1580480037107,"mc":[{"id":"1.168133553","rc":[{"batb":[[2,1.03,1628.39]],"ltp":1.51,"tv":12.72,"id":16325787}]}]}
{"op":"mcm","clk":"988721018","pt":1580480041688,"mc":[{"id":"1.168133553","rc":[{"batb":[[0,1.25,3],[1,1.24,1.99],[2,1.22,10]],"ltp":1.51,"tv":12.72,"id":16325787}]}]}
{"op":"mcm","clk":"988721925","pt":1580480052009,"mc":[{"id":"1.168133553","rc":[{"batb":[[0,1.24,1.99],[1,1.23,3]],"ltp":1.51,"tv":12.72,"id":16325787}]}]}
{"op":"mcm","clk":"988722649","pt":1580480060350,"mc":[{"id":"1.168133553","rc":[{"batb":[[0,1.25,34.31],[1,1.24,1.99],[2,1.23,3]],"ltp":1.51,"tv":12.72,"id":16325787}]}]}
{"op":"mcm","clk":"988722844","pt":1580480062553,"mc":[{"id":"1.168133553","rc":[{"batb":[[2,1.22,10]],"ltp":1.51,"tv":12.72,"id":16325787}]}]}
{"op":"mcm","clk":"988722857","pt":1580480062659,"mc":[{"id":"1.168133553","rc":[{"batb":[[0,1.26,3],[1,1.25,34.31],[2,1.24,1.99]],"ltp":1.51,"tv":12.72,"id":16325787}]}]}
{"op":"mcm","clk":"988724666","pt":1580480083975,"mc":[{"id":"1.168133553","rc":[{"batb":[[1,1.24,1.99],[2,1.22,10]],"ltp":1.51,"tv":12.72,"id":16325787}]}]}
{"op":"mcm","clk":"988725462","pt":1580480092686,"mc":[{"id":"1.168133553","rc":[{"batb":[[0,1.24,1.99],[1,1.23,3]],"ltp":1.51,"tv":12.72,"id":16325787}]}]}
{"op":"mcm","clk":"988726142","pt":1580480100565,"mc":[{"id":"1.168133553","rc":[{"batb":[[2,1.03,1628.39]],"ltp":1.51,"tv":12.72,"id":16325787}]}]}
{"op":"mcm","clk":"988726154","pt":1580480100668,"mc":[{"id":"1.168133553","rc":[{"batb":[[0,1.24,11.99]],"ltp":1.51,"tv":12.72,"id":16325787}]}]}
{"op":"mcm","clk":"988726579","pt":1580480105350,"mc":[{"id":"1.168133553","rc":[{"batb":[[0,1.25,3],[1,1.24,11.99]],"ltp":1.51,"tv":12.72,"id":16325787}]}]}
{"op":"mcm","clk":"988726759","pt":1580480107545,"mc":[{"id":"1.168133553","rc":[{"batb":[[0,1.26,34.05],[1,1.25,3],[2,1.24,11.99]],"ltp":1.51,"tv":12.72,"id":16325787}]}]}
{"op":"mcm","clk":"988727308","pt":1580480114345,"mc":[{"id":"1.168133553","rc":[{"batb":[[0,1.27,3],[1,1.26,34.05]],"ltp":1.51,"tv":12.72,"id":16325787}]}]}
{"op":"mcm","clk":"988728825","pt":1580480131795,"mc":[{"id":"1.168133553","rc":[{"batb":[[1,1.24,11.99],[2,1.03,1628.39]],"ltp":1.51,"tv":12.72,"id":16325787}]}]}
{"op":"mcm","clk":"988729713","pt":1580480141210,"mc":[{"id":"1.168133553","rc":[{"batb":[[0,1.25,3]],"ltp":1.51,"tv":12.72,"id":16325787}]}]}
{"op":"mcm","clk":"988731116","pt":1580480155616,"mc":[{"id":"1.168133553","rc":[{"batb":[[0,1.26,34.05],[1,1.25,3],[2,1.24,11.99]],"ltp":1.51,"tv":12.72,"id":16325787}]}]}
{"op":"mcm","clk":"988731800","pt":1580480162538,"mc":[{"id":"1.168133553","rc":[{"batb":[[0,1.27,3],[1,1.26,34.05]],"ltp":1.51,"tv":12.72,"id":16325787}]}]}
{"op":"mcm","clk":"988732242","pt":1580480167033,"mc":[{"id":"1.168133553","rc":[{"batb":[[0,1.28,1.99],[1,1.27,3],[2,1.26,34.05]],"ltp":1.51,"tv":12.72,"id":16325787}]}]}
{"op":"mcm","clk":"988733077","pt":1580480175028,"mc":[{"id":"1.168133553","rc":[{"batb":[[0,1.28,4.99],[1,1.26,34.05],[2,1.24,10]],"ltp":1.51,"tv":12.72,"id":16325787}]}]}
{"op":"mcm","clk":"988733562","pt":1580480180532,"mc":[{"id":"1.168133553","rc":[{"batb":[[1,1.04,10],[2,1.03,1628.39]],"ltp":1.51,"tv":12.72,"id":16325787}]}]}
{"op":"mcm","clk":"988734009","pt":1580480185768,"mc":[{"id":"1.168133553","rc":[{"batb":[[0,1.29,3],[1,1.28,1.99],[2,1.04,10]],"ltp":1.51,"tv":12.72,"id":16325787}]}]}
{"op":"mcm","clk":"988734920","pt":1580480196360,"mc":[{"id":"1.168133553","rc":[{"batb":[[0,1.28,1.99],[1,1.05,3]],"ltp":1.51,"tv":12.72,"id":16325787}]}]}
{"op":"mcm","clk":"988736101","pt":1580480208555,"mc":[{"id":"1.168133553","rc":[{"batb":[[1,1.04,10],[2,1.03,1628.39]],"ltp":1.51,"tv":12.72,"id":16325787}]}]}
{"op":"mcm","clk":"988736111","pt":1580480208660,"mc":[{"id":"1.168133553","rc":[{"batb":[[1,1.06,3],[2,1.04,10]],"ltp":1.51,"tv":12.72,"id":16325787}]}]}
{"op":"mcm","clk":"988737434","pt":1580480222774,"mc":[{"id":"1.168133553","rc":[{"batb":[[1,1.07,3]],"ltp":1.51,"tv":12.72,"id":16325787}]}]}
{"op":"mcm","clk":"988738159","pt":1580480229765,"mc":[{"id":"1.168133553","rc":[{"batb":[[0,1.08,1.99]],"ltp":1.51,"tv":12.72,"id":16325787}]}]}
{"op":"mcm","clk":"988738879","pt":1580480237904,"mc":[{"id":"1.168133553","rc":[{"batb":[[0,1.08,4.99],[1,1.04,10],[2,1.03,1628.39]],"ltp":1.51,"tv":12.72,"id":16325787}]}]}
{"op":"mcm","clk":"988740073","pt":1580480252189,"mc":[{"id":"1.168133553","rc":[{"batb":[[0,1.09,3],[1,1.08,1.99],[2,1.04,10]],"ltp":1.51,"tv":12.72,"id":16325787}]}]}
{"op":"mcm","clk":"988740802","pt":1580480260540,"mc":[{"id":"1.168133553","rc":[{"batb":[[2,1.03,1628.39]],"ltp":1.51,"tv":12.72,"id":16325787}]}]}
{"op":"mcm","clk":"988740819","pt":1580480260745,"mc":[{"id":"1.168133553","rc":[{"batb":[[0,1.09,13]],"ltp":1.51,"tv":12.72,"id":16325787}]}]}
{"op":"mcm","clk":"988741333","pt":1580480266274,"mc":[{"id":"1.168133553","rc":[{"batb":[[0,1.1,3],[1,1.09,10],[2,1.08,1.99]],"ltp":1.51,"tv":12.72,"id":16325787}]}]}
{"op":"mcm","clk":"988742040","pt":1580480273485,"mc":[{"id":"1.168133553","rc":[{"batb":[[0,1.11,38.65],[1,1.1,3],[2,1.09,10]],"ltp":1.51,"tv":12.72,"id":16325787}]}]}
{"op":"mcm","clk":"988742581","pt":1580480278746,"mc":[{"id":"1.168133553","rc":[{"batb":[[0,1.12,3],[1,1.11,38.65]],"ltp":1.51,"tv":12.72,"id":16325787}]}]}
{"op":"mcm","clk":"988744027","pt":1580480293387,"mc":[{"id":"1.168133553","rc":[{"batb":[[0,1.13,1.99],[1,1.12,3],[2,1.11,38.65]],"ltp":1.51,"tv":12.72,"id":16325787}]}]}
{"op":"mcm","clk":"988744429","pt":1580480297478,"mc":[{"id":"1.168133553","rc":[{"batb":[[1,1.09,10],[2,1.04,6]],"ltp":1.51,"tv":12.72,"id":16325787}]}]}
{"op":"mcm","clk":"988744440","pt":1580480297588,"mc":[{"id":"1.168133553","rc":[{"batb":[[0,1.14,37.63],[1,1.13,4.99],[2,1.09,10]],"ltp":1.51,"tv":12.72,"id":16325787}]}]}
{"op":"mcm","clk":"988746155","pt":1580480314707,"mc":[{"id":"1.168133553","rc":[{"batb":[[0,1.15,3],[1,1.14,37.63],[2,1.13,1.99]],"ltp":1.51,"tv":12.72,"id":16325787}]}]}
{"op":"mcm","clk":"988746767","pt":1580480321292,"mc":[{"id":"1.168133553","rc":[{"batb":[[1,1.13,1.99],[2,1.09,10]],"ltp":1.51,"tv":12.72,"id":16325787}]}]}
{"op":"mcm","clk":"988747167","pt":1580480326057,"mc":[{"id":"1.168133553","rc":[{"batb":[[0,1.13,1.99],[1,1.1,3]],"ltp":1.51,"tv":12.72,"id":16325787}]}]}
{"op":"mcm","clk":"988748467","pt":1580480340333,"mc":[{"id":"1.168133553","rc":[{"batb":[[1,1.11,10],[2,1.1,3]],"ltp":1.51,"tv":12.72,"id":16325787}]}]}
{"op":"mcm","clk":"988748565","pt":1580480341281,"mc":[{"id":"1.168133553","rc":[{"batb":[[1,1.12,3],[2,1.11,10]],"ltp":1.51,"tv":12.72,"id":16325787}]}]}
{"op":"mcm","clk":"988748923","pt":1580480344881,"mc":[{"id":"1.168133553","rc":[{"batb":[[0,1.14,37.63],[1,1.13,1.99],[2,1.12,3]],"ltp":1.51,"tv":12.72,"id":16325787}]}]}
{"op":"mcm","clk":"988750487","pt":1580480361141,"mc":[{"id":"1.168133553","rc":[{"batb":[[0,1.15,1.99],[1,1.14,37.63]],"ltp":1.51,"tv":12.72,"id":16325787}]}]}
{"op":"mcm","clk":"988750594","pt":1580480362134,"mc":[{"id":"1.168133553","rc":[{"batb":[[0,1.15,4.99],[2,1.11,10]],"ltp":1.51,"tv":12.72,"id":16325787}]}]}
{"op":"mcm","clk":"988751246","pt":1580480368823,"mc":[{"id":"1.168133553","rc":[{"batb":[[1,1.11,10],[2,1.04,6]],"ltp":1.51,"tv":12.72,"id":16325787}]}]}
{"op":"mcm","clk":"988751853","pt":1580480374951,"mc":[{"id":"1.168133553","rc":[{"batb":[[2,1.03,1628.39]],"ltp":1.51,"tv":12.72,"id":16325787}]}]}
{"op":"mcm","clk":"988751917","pt":1580480375683,"mc":[{"id":"1.168133553","rc":[{"batb":[[0,1.16,3],[1,1.15,1.99],[2,1.11,10]],"ltp":1.51,"tv":12.72,"id":16325787}]}]}
{"op":"mcm","clk":"988752955","pt":1580480386490,"mc":[{"id":"1.168133553","rc":[{"batb":[[0,1.15,1.99],[1,1.12,3]],"ltp":1.51,"tv":12.72,"id":16325787}]}]}
{"op":"mcm","clk":"988754466","pt":1580480402428,"mc":[{"id":"1.168133553","rc":[{"batb":[[1,1.13,3]],"ltp":1.51,"tv":12.72,"id":16325787}]}]}
{"op":"mcm","clk":"988756066","pt":1580480418216,"mc":[{"id":"1.168133553","rc":[{"batb":[[1,1.14,3]],"ltp":1.51,"tv":12.72,"id":16325787}]}]}
{"op":"mcm","clk":"988756247","pt":1580480419943,"mc":[{"id":"1.168133553","rc":[{"batb":[[1,1.14,13],[2,1.03,1628.39]],"ltp":1.51,"tv":12.72,"id":16325787}]}]}
{"op":"mcm","clk":"988757171","pt":1580480428856,"mc":[{"id":"1.168133553","rc":[{"batb":[[0,1.14,13],[1,1.03,1628.39],[2,1.02,2.19]],"ltp":1.51,"tv":12.72,"id":16325787}]}]}
{"op":"mcm","clk":"988757534","pt":1580480432436,"mc":[{"id":"1.168133553","rc":[{"batb":[[1,1.04,6],[2,1.03,1628.39]],"ltp":1.51,"tv":12.72,"id":16325787}]}]}
{"op":"mcm","clk":"988757734","pt":1580480434439,"mc":[{"id":"1.168133553","rc":[{"batb":[[0,1.15,3],[1,1.14,10],[2,1.04,6]],"ltp":1.51,"tv":12.72,"id":16325787}]}]}
{"op":"mcm","clk":"988758148","pt":1580480438849,"mc":[{"id":"1.168133553","rc":[{"batb":[[0,1.16,36.98],[1,1.15,3],[2,1.14,10]],"ltp":1.51,"tv":12.72,"id":16325787}]}]}
{"op":"mcm","clk":"988758861","pt":1580480446559,"mc":[{"id":"1.168133553","rc":[{"batb":[[1,1.14,10],[2,1.04,6]],"ltp":1.51,"tv":12.72,"id":16325787}]}]}
{"op":"mcm","clk":"988758868","pt":1580480446655,"mc":[{"id":"1.168133553","rc":[{"batb":[[0,1.17,3],[1,1.16,36.98],[2,1.14,10]],"ltp":1.51,"tv":12.72,"id":16325787}]}]}
{"op":"mcm","clk":"988759287","pt":1580480450461,"mc":[{"id":"1.168133553","rc":[{"batb":[[1,1.16,39.98]],"ltp":1.51,"tv":12.72,"id":16325787}]}]}
{"op":"mcm","clk":"988760525","pt":1580480462261,"mc":[{"id":"1.168133553","rc":[{"batb":[[1,1.16,3]],"ltp":1.51,"tv":12.72,"id":16325787}]}]}
{"op":"mcm","clk":"988760562","pt":1580480462576,"mc":[{"id":"1.168133553","rc":[{"batb":[[0,1.18,36.35],[1,1.17,3],[2,1.16,3]],"ltp":1.51,"tv":12.72,"id":16325787}]}]}
{"op":"mcm","clk":"988761579","pt":1580480472368,"mc":[{"id":"1.168133553","rc":[{"batb":[[0,1.19,3],[1,1.18,36.35]],"ltp":1.51,"tv":12.72,"id":16325787}]}]}
{"op":"mcm","clk":"988763019","pt":1580480486077,"mc":[{"id":"1.168133553","rc":[{"batb":[[1,1.16,3],[2,1.14,10]],"ltp":1.51,"tv":12.72,"id":16325787}]}]}
{"op":"mcm","clk":"988764067","pt":1580480496177,"mc":[{"id":"1.168133553","rc":[{"batb":[[0,1.17,3]],"ltp":1.51,"tv":12.72,"id":16325787}]}]}
{"op":"mcm","clk":"988764601","pt":1580480501569,"mc":[{"id":"1.168133553","rc":[{"batb":[[2,1.03,1628.39]],"ltp":1.51,"tv":12.72,"id":16325787}]}]}
{"op":"mcm","clk":"988765322","pt":1580480509286,"mc":[{"id":"1.168133553","rc":[{"batb":[[0,1.18,36.35],[1,1.17,3],[2,1.16,3]],"ltp":1.51,"tv":12.72,"id":16325787}]}]}
{"op":"mcm","clk":"988765847","pt":1580480514502,"mc":[{"id":"1.168133553","rc":[{"batb":[[0,1.19,3],[1,1.18,36.35]],"ltp":1.51,"tv":12.72,"id":16325787}]}]}
{"op":"mcm","clk":"988767571","pt":1580480532654,"mc":[{"id":"1.168133553","rc":[{"batb":[[1,1.16,3],[2,1.03,1628.39]],"ltp":1.51,"tv":12.72,"id":16325787}]}]}
{"op":"mcm","clk":"988768043","pt":1580480537721,"mc":[{"id":"1.168133553","rc":[{"batb":[[0,1.17,3]],"ltp":1.51,"tv":12.72,"id":16325787}]}]}
{"op":"mcm","clk":"988778270","pt":1580480555774,"mc":[{"id":"1.168133553","rc":[{"batb":[[0,1.18,36.35],[1,1.17,3],[2,1.16,3]],"ltp":1.51,"tv":12.72,"id":16325787}]}]}
{"op":"mcm","clk":"988778813","pt":1580480561758,"mc":[{"id":"1.168133553","rc":[{"batb":[[0,1.19,3],[1,1.18,36.35]],"ltp":1.51,"tv":12.72,"id":16325787}]}]}
{"op":"mcm","clk":"988780281","pt":1580480578203,"mc":[{"id":"1.168133553","rc":[{"batb":[[0,1.2,1.99],[1,1.19,3],[2,1.18,36.35]],"ltp":1.51,"tv":12.72,"id":16325787}]}]}
{"op":"mcm","clk":"988780455","pt":1580480580287,"mc":[{"id":"1.168133553","rc":[{"batb":[[2,1.16,3]],"ltp":1.51,"tv":12.72,"id":16325787}]}]}
{"op":"mcm","clk":"988780498","pt":1580480580704,"mc":[{"id":"1.168133553","rc":[{"batb":[[0,1.21,35.45],[1,1.2,1.99],[2,1.19,3]],"ltp":1.51,"tv":12.72,"id":16325787}]}]}
{"op":"mcm","clk":"988781034","pt":1580480586489,"mc":[{"id":"1.168133553","rc":[{"batb":[[0,1.22,3],[1,1.21,35.45],[2,1.2,1.99]],"ltp":1.51,"tv":12.72,"id":16325787}]}]}
{"op":"mcm","clk":"988782761","pt":1580480606246,"mc":[{"id":"1.168133553","rc":[{"batb":[[1,1.2,1.99],[2,1.16,3]],"ltp":1.51,"tv":12.72,"id":16325787}]}]}
{"op":"mcm","clk":"988783216","pt":1580480611554,"mc":[{"id":"1.168133553","rc":[{"batb":[[0,1.2,1.99],[1,1.17,3]],"ltp":1.51,"tv":12.72,"id":16325787}]}]}
{"op":"mcm","clk":"988784247","pt":1580480623170,"mc":[{"id":"1.168133553","rc":[{"batb":[[1,1.18,3]],"ltp":1.51,"tv":12.72,"id":16325787}]}]}
{"op":"mcm","clk":"988784829","pt":1580480630549,"mc":[{"id":"1.168133553","rc":[{"batb":[[0,1.18,3],[1,1.16,3],[2,1.03,1628.39]],"ltp":1.51,"tv":12.72,"id":16325787}]}]}
{"op":"mcm","clk":"988784837","pt":1580480630648,"mc":[{"id":"1.168133553","rc":[{"batb":[[0,1.19,1.99],[1,1.18,3],[2,1.16,3]],"ltp":1.51,"tv":12.72,"id":16325787}]}]}
{"op":"mcm","clk":"988785261","pt":1580480635686,"mc":[{"id":"1.168133553","rc":[{"batb":[[0,1.19,4.99],[1,1.16,3],[2,1.03,1628.39]],"ltp":1.51,"tv":12.72,"id":16325787}]}]}
{"op":"mcm","clk":"988786166","pt":1580480645990,"mc":[{"id":"1.168133553","rc":[{"batb":[[0,1.2,3],[1,1.19,1.99],[2,1.16,3]],"ltp":1.51,"tv":12.72,"id":16325787}]}]}
{"op":"mcm","clk":"988786695","pt":1580480652709,"mc":[{"id":"1.168133553","rc":[{"batb":[[0,1.21,35.45],[1,1.2,3],[2,1.19,1.99]],"ltp":1.51,"tv":12.72,"id":16325787}]}]}
{"op":"mcm","clk":"988787031","pt":1580480656391,"mc":[{"id":"1.168133553","rc":[{"batb":[[0,1.22,3],[1,1.21,35.45]],"ltp":1.51,"tv":12.72,"id":16325787}]}]}
{"op":"mcm","clk":"988787351","pt":1580480660283,"mc":[{"id":"1.168133553","rc":[{"batb":[[0,1.22,13]],"ltp":1.51,"tv":12.72,"id":16325787}]}]}
{"op":"mcm","clk":"988788176","pt":1580480670495,"mc":[{"id":"1.168133553","rc":[{"batb":[[0,1.23,3],[1,1.22,10],[2,1.21,35.45]],"ltp":1.51,"tv":12.72,"id":16325787}]}]}
{"op":"mcm","clk":"988788651","pt":1580480676096,"mc":[{"id":"1.168133553","rc":[{"batb":[[0,1.24,34.59],[1,1.23,3],[2,1.22,10]],"ltp":1.51,"tv":12.72,"id":16325787}]}]}
{"op":"mcm","clk":"988789112","pt":1580480681385,"mc":[{"id":"1.168133553","rc":[{"batb":[[0,1.25,3],[1,1.24,34.59]],"ltp":1.51,"tv":12.72,"id":16325787}]}]}
{"op":"mcm","clk":"988789613","pt":1580480687305,"mc":[{"id":"1.168133553","rc":[{"batb":[[0,1.26,1.99],[1,1.25,3],[2,1.24,34.59]],"ltp":1.51,"tv":12.72,"id":16325787}]}]}
{"op":"mcm","clk":"988790047","pt":1580480693318,"mc":[{"id":"1.168133553","rc":[{"batb":[[0,1.26,4.99],[1,1.24,34.59],[2,1.22,10]],"ltp":1.51,"tv":12.72,"id":16325787}]}]}
{"op":"mcm","clk":"988790211","pt":1580480694935,"mc":[{"id":"1.168133553","rc":[{"batb":[[1,1.25,3],[2,1.24,34.59]],"ltp":1.51,"tv":12.72,"id":16325787}]}]}
{"op":"mcm","clk":"988790631","pt":1580480700207,"mc":[{"id":"1.168133553","rc":[{"batb":[[0,1.27,33.78],[1,1.26,4.99],[2,1.25,3]],"ltp":1.51,"tv":12.72,"id":16325787}]}]}
{"op":"mcm","clk":"988790946","pt":1580480703542,"mc":[{"id":"1.168133553","rc":[{"batb":[[1,1.26,1.99]],"ltp":1.51,"tv":12.72,"id":16325787}]}]}
{"op":"mcm","clk":"988790955","pt":1580480703646,"mc":[{"id":"1.168133553","rc":[{"batb":[[0,1.28,3],[1,1.27,33.78],[2,1.26,1.99]],"ltp":1.51,"tv":12.72,"id":16325787}]}]}
{"op":"mcm","clk":"988792654","pt":1580480723552,"mc":[{"id":"1.168133553","rc":[{"batb":[[1,1.26,1.99],[2,1.25,3]],"ltp":1.51,"tv":12.72,"id":16325787}]}]}
{"op":"mcm","clk":"988792925","pt":1580480726737,"mc":[{"id":"1.168133553","rc":[{"batb":[[0,1.26,4.99],[1,1.25,3],[2,1.22,10]],"ltp":1.51,"tv":12.72,"id":16325787}]}]}
{"op":"mcm","clk":"988794168","pt":1580480741497,"mc":[{"id":"1.168133553","rc":[{"batb":[[0,1.26,11.99],[2,1.03,1628.39]],"ltp":1.51,"tv":12.72,"id":16325787}]}]}
{"op":"mcm","clk":"988794175","pt":1580480741600,"mc":[{"id":"1.168133553","rc":[{"batb":[[0,1.27,3],[1,1.26,11.99],[2,1.25,3]],"ltp":1.51,"tv":12.72,"id":16325787}]}]}
{"op":"mcm","clk":"988794351","pt":1580480743679,"mc":[{"id":"1.168133553","rc":[{"batb":[[0,1.28,1.99],[1,1.27,3],[2,1.26,10]],"ltp":1.51,"tv":12.72,"id":16325787}]}]}
{"op":"mcm","clk":"988794579","pt":1580480746906,"mc":[{"id":"1.168133553","rc":[{"batb":[[0,1.29,33.25],[1,1.28,1.99],[2,1.27,3]],"ltp":1.51,"tv":12.72,"id":16325787}]}]}
{"op":"mcm","clk":"988795244","pt":1580480755431,"mc":[{"id":"1.168133553","rc":[{"batb":[[0,1.3,3],[1,1.29,33.25],[2,1.28,1.99]],"ltp":1.51,"tv":12.72,"id":16325787}]}]}
{"op":"mcm","clk":"988796460","pt":1580480769626,"mc":[{"id":"1.168133553","rc":[{"batb":[[1,1.28,1.99],[2,1.26,10]],"ltp":1.51,"tv":12.72,"id":16325787}]}]}
{"op":"mcm","clk":"988796986","pt":1580480775749,"mc":[{"id":"1.168133553","rc":[{"batb":[[0,1.28,1.99],[1,1.27,3]],"ltp":1.51,"tv":12.72,"id":16325787}]}]}
{"op":"mcm","clk":"988797812","pt":1580480785242,"mc":[{"id":"1.168133553","rc":[{"batb":[[0,1.28,4.99],[1,1.26,10],[2,1.25,3]],"ltp":1.51,"tv":12.72,"id":16325787}]}]}
{"op":"mcm","clk":"988798663","pt":1580480795762,"mc":[{"id":"1.168133553","rc":[{"batb":[[0,1.29,3],[1,1.28,1.99],[2,1.26,10]],"ltp":1.51,"tv":12.72,"id":16325787}]}]}
{"op":"mcm","clk":"988799026","pt":1580480800570,"mc":[{"id":"1.168133553","rc":[{"batb":[[1,1.26,10],[2,1.25,3]],"ltp":1.51,"tv":12.72,"id":16325787}]}]}
{"op":"mcm","clk":"988799032","pt":1580480800676,"mc":[{"id":"1.168133553","rc":[{"batb":[[0,1.3,1.99],[1,1.29,3],[2,1.26,10]],"ltp":1.51,"tv":12.72,"id":16325787}]}]}
{"op":"mcm","clk":"988799440","pt":1580480806055,"mc":[{"id":"1.168133553","rc":[{"batb":[[0,1.3,4.99],[1,1.26,10],[2,1.25,3]],"ltp":1.51,"tv":12.72,"id":16325787}]}]}
{"op":"mcm","clk":"988800189","pt":1580480816484,"mc":[{"id":"1.168133553","rc":[{"batb":[[0,1.3,1.99]],"ltp":1.51,"tv":12.72,"id":16325787}]}]}
{"op":"mcm","clk":"988800198","pt":1580480816589,"mc":[{"id":"1.168133553","rc":[{"batb":[[0,1.31,3],[1,1.3,1.99],[2,1.26,10]],"ltp":1.51,"tv":12.72,"id":16325787}]}]}
{"op":"mcm","clk":"988800667","pt":1580480822691,"mc":[{"id":"1.168133553","rc":[{"batb":[[0,1.31,13],[2,1.25,3]],"ltp":1.51,"tv":12.72,"id":16325787}]}]}
{"op":"mcm","clk":"988801133","pt":1580480828444,"mc":[{"id":"1.168133553","rc":[{"batb":[[0,1.32,3],[1,1.31,10],[2,1.3,1.99]],"ltp":1.51,"tv":12.72,"id":16325787}]}]}
{"op":"mcm","clk":"988801945","pt":1580480839430,"mc":[{"id":"1.168133553","rc":[{"batb":[[0,1.33,32.25],[1,1.32,3],[2,1.31,10]],"ltp":1.51,"tv":12.72,"id":16325787}]}]}
{"op":"mcm","clk":"988802758","pt":1580480849452,"mc":[{"id":"1.168133553","rc":[{"batb":[[0,1.34,1.99],[1,1.33,32.25],[2,1.32,3]],"ltp":1.51,"tv":12.72,"id":16325787}]}]}
{"op":"mcm","clk":"988802794","pt":1580480849982,"mc":[{"id":"1.168133553","rc":[{"batb":[[0,1.34,4.99],[2,1.31,10]],"ltp":1.51,"tv":12.72,"id":16325787}]}]}
{"op":"mcm","clk":"988803843","pt":1580480862870,"mc":[{"id":"1.168133553","rc":[{"batb":[[1,1.31,10],[2,1.03,1628.39]],"ltp":1.51,"tv":12.72,"id":16325787}]}]}
{"op":"mcm","clk":"988804014","pt":1580480864788,"mc":[{"id":"1.168133553","rc":[{"batb":[[0,1.35,3],[1,1.34,1.99],[2,1.31,10]],"ltp":1.51,"tv":12.72,"id":16325787}]}]}
{"op":"mcm","clk":"988805091","pt":1580480877475,"mc":[{"id":"1.168133553","rc":[{"batb":[[0,1.34,1.99],[1,1.31,10],[2,1.03,1628.39]],"ltp":1.51,"tv":12.72,"id":16325787}]}]}
{"op":"mcm","clk":"988805100","pt":1580480877580,"mc":[{"id":"1.168133553","rc":[{"batb":[[1,1.32,3],[2,1.31,10]],"ltp":1.51,"tv":12.72,"id":16325787}]}]}
{"op":"mcm","clk":"988806124","pt":1580480889487,"mc":[{"id":"1.168133553","rc":[{"batb":[[1,1.33,3]],"ltp":1.51,"tv":12.72,"id":16325787}]}]}
{"op":"mcm","clk":"988807059","pt":1580480900325,"mc":[{"id":"1.168133553","rc":[{"batb":[[0,1.34,4.99],[1,1.31,10],[2,1.03,1628.39]],"ltp":1.51,"tv":12.72,"id":16325787}]}]}
{"op":"mcm","clk":"988807144","pt":1580480901528,"mc":[{"id":"1.168133553","rc":[{"batb":[[0,1.34,3]],"ltp":1.51,"tv":12.72,"id":16325787}]}]}
{"op":"mcm","clk":"988807238","pt":1580480902830,"mc":[{"id":"1.168133553","rc":[{"batb":[[1,1.04,10]],"ltp":1.51,"tv":12.72,"id":16325787}]}]}
{"op":"mcm","clk":"988807801","pt":1580480910426,"mc":[{"id":"1.168133553","rc":[{"batb":[[0,1.05,3]],"ltp":1.51,"tv":12.72,"id":16325787}]}]}
{"op":"mcm","clk":"988807865","pt":1580480911357,"mc":[{"id":"1.168133553","rc":[{"batb":[[0,1.06,40.46],[1,1.05,3],[2,1.04,10]],"ltp":1.51,"tv":12.72,"id":16325787}]}]}
{"op":"mcm","clk":"988808410","pt":1580480918537,"mc":[{"id":"1.168133553","rc":[{"batb":[[1,1.04,10],[2,1.03,1628.39]],"ltp":1.51,"tv":12.72,"id":16325787}]}]}
{"op":"mcm","clk":"988808424","pt":1580480918640,"mc":[{"id":"1.168133553","rc":[{"batb":[[0,1.07,3],[1,1.06,40.46],[2,1.04,10]],"ltp":1.51,"tv":12.72,"id":16325787}]}]}
{"op":"mcm","clk":"988809811","pt":1580480936167,"mc":[{"id":"1.168133553","rc":[{"batb":[[1,1.04,10],[2,1.03,1628.39]],"ltp":1.51,"tv":12.72,"id":16325787}]}]}
{"op":"mcm","clk":"988810193","pt":1580480941061,"mc":[{"id":"1.168133553","rc":[{"batb":[[0,1.05,3]],"ltp":1.51,"tv":12.72,"id":16325787}]}]}
{"op":"mcm","clk":"988811067","pt":1580480952607,"mc":[{"id":"1.168133553","rc":[{"batb":[[0,1.06,1.99],[1,1.05,3],[2,1.04,10]],"ltp":1.51,"tv":12.72,"id":16325787}]}]}
{"op":"mcm","clk":"988811631","pt":1580480959706,"mc":[{"id":"1.168133553","rc":[{"batb":[[0,1.07,40.08],[1,1.06,1.99],[2,1.05,3]],"ltp":1.51,"tv":12.72,"id":16325787}]}]}
{"op":"mcm","clk":"988811949","pt":1580480963905,"mc":[{"id":"1.168133553","rc":[{"batb":[[0,1.08,3],[1,1.07,40.08],[2,1.06,1.99]],"ltp":1.51,"tv":12.72,"id":16325787}]}]}
{"op":"mcm","clk":"988813421","pt":1580480983246,"mc":[{"id":"1.168133553","rc":[{"batb":[[1,1.06,1.99],[2,1.04,10]],"ltp":1.51,"tv":12.72,"id":16325787}]}]}
{"op":"mcm","clk":"988813574","pt":1580480984932,"mc":[{"id":"1.168133553","rc":[{"batb":[[1,1.07,10],[2,1.06,1.99]],"ltp":1.51,"tv":12.72,"id":16325787}]}]}
{"op":"mcm","clk":"988815525","pt":1580481007173,"mc":[{"id":"1.168133553","rc":[{"batb":[[0,1.09,41.34],[1,1.08,3],[2,1.07,10]],"ltp":1.51,"tv":12.72,"id":16325787}]}]}
{"op":"mcm","clk":"988815714","pt":1580481009279,"mc":[{"id":"1.168133553","rc":[{"batb":[[0,1.1,3],[1,1.09,41.34]],"ltp":1.51,"tv":12.72,"id":16325787}]}]}
{"op":"mcm","clk":"988817929","pt":1580481031289,"mc":[{"id":"1.168133553","rc":[{"batb":[[1,1.09,1.99]],"ltp":1.51,"tv":12.72,"id":16325787}]}]}
{"op":"mcm","clk":"988818015","pt":1580481031710,"mc":[{"id":"1.168133553","rc":[{"batb":[[0,1.11,38.65],[1,1.1,3],[2,1.09,1.99]],"ltp":1.51,"tv":12.72,"id":16325787}]}]}
{"op":"mcm","clk":"988818926","pt":1580481039101,"mc":[{"id":"1.168133553","rc":[{"batb":[[0,1.12,3],[1,1.11,38.65]],"ltp":1.51,"tv":12.72,"id":16325787}]}]}
{"op":"mcm","clk":"988820438","pt":1580481055149,"mc":[{"id":"1.168133553","rc":[{"batb":[[1,1.09,1.99],[2,1.07,10]],"ltp":1.51,"tv":12.72,"id":16325787}]}]}
{"op":"mcm","clk":"988820986","pt":1580481061467,"mc":[{"id":"1.168133553","rc":[{"batb":[[0,1.09,1.99],[1,1.08,3]],"ltp":1.51,"tv":12.72,"id":16325787}]}]}
{"op":"mcm","clk":"988821400","pt":1580481066403,"mc":[{"id":"1.168133553","rc":[{"batb":[[0,1.09,11.99],[2,1.04,6]],"ltp":1.51,"tv":12.72,"id":16325787}]}]}
{"op":"mcm","clk":"988821673","pt":1580481069488,"mc":[{"id":"1.168133553","rc":[{"batb":[[0,1.1,3],[1,1.09,11.99]],"ltp":1.51,"tv":12.72,"id":16325787}]}]}
{"op":"mcm","clk":"988822366","pt":1580481078304,"mc":[{"id":"1.168133553","rc":[{"batb":[[0,1.11,38.65],[1,1.1,3],[2,1.09,11.99]],"ltp":1.51,"tv":12.72,"id":16325787}]}]}
{"op":"mcm","clk":"988822685","pt":1580481082520,"mc":[{"id":"1.168133553","rc":[{"batb":[[0,1.12,3],[1,1.11,38.65]],"ltp":1.51,"tv":12.72,"id":16325787}]}]}
{"op":"mcm","clk":"988824226","pt":1580481101154,"mc":[{"id":"1.168133553","rc":[{"batb":[[1,1.09,11.99],[2,1.04,6]],"ltp":1.51,"tv":12.72,"id":16325787}]}]}
{"op":"mcm","clk":"988824630","pt":1580481106077,"mc":[{"id":"1.168133553","rc":[{"batb":[[0,1.1,3]],"ltp":1.51,"tv":12.72,"id":16325787}]}]}
{"op":"mcm","clk":"988826225","pt":1580481124290,"mc":[{"id":"1.168133553","rc":[{"batb":[[0,1.11,38.65],[1,1.1,3],[2,1.09,11.99]],"ltp":1.51,"tv":12.72,"id":16325787}]}]}
{"op":"mcm","clk":"988826284","pt":1580481124906,"mc":[{"id":"1.168133553","rc":[{"batb":[[0,1.12,1.99],[1,1.11,38.65],[2,1.1,3]],"ltp":1.51,"tv":12.72,"id":16325787}]}]}
{"op":"mcm","clk":"988826759","pt":1580481129290,"mc":[{"id":"1.168133553","rc":[{"batb":[[0,1.12,4.99],[2,1.09,10]],"ltp":1.51,"tv":12.72,"id":16325787}]}]}
{"op":"mcm","clk":"988827735","pt":1580481139742,"mc":[{"id":"1.168133553","rc":[{"batb":[[0,1.13,3],[1,1.12,1.99],[2,1.11,38.65]],"ltp":1.51,"tv":12.72,"id":16325787}]}]}
{"op":"mcm","clk":"988828036","pt":1580481143462,"mc":[{"id":"1.168133553","rc":[{"batb":[[1,1.12,4.99]],"ltp":1.51,"tv":12.72,"id":16325787}]}]}
{"op":"mcm","clk":"988828339","pt":1580481146870,"mc":[{"id":"1.168133553","rc":[{"batb":[[0,1.13,13]],"ltp":1.51,"tv":12.72,"id":16325787}]}]}
{"op":"mcm","clk":"988828453","pt":1580481148084,"mc":[{"id":"1.168133553","rc":[{"batb":[[0,1.14,37.63],[1,1.13,13],[2,1.12,4.99]],"ltp":1.51,"tv":12.72,"id":16325787}]}]}
{"op":"mcm","clk":"988828572","pt":1580481149518,"mc":[{"id":"1.168133553","rc":[{"batb":[[1,1.13,10]],"ltp":1.51,"tv":12.72,"id":16325787}]}]}
{"op":"mcm","clk":"988828581","pt":1580481149592,"mc":[{"id":"1.168133553","rc":[{"batb":[[0,1.15,3],[1,1.14,37.63],[2,1.13,10]],"ltp":1.51,"tv":12.72,"id":16325787}]}]}
{"op":"mcm","clk":"988830736","pt":1580481171815,"mc":[{"id":"1.168133553","rc":[{"batb":[[1,1.13,10],[2,1.12,4.99]],"ltp":1.51,"tv":12.72,"id":16325787}]}]}
{"op":"mcm","clk":"988831201","pt":1580481177432,"mc":[{"id":"1.168133553","rc":[{"batb":[[0,1.14,3]],"ltp":1.51,"tv":12.72,"id":16325787}]}]}
{"op":"mcm","clk":"988831798","pt":1580481183525,"mc":[{"id":"1.168133553","rc":[{"batb":[[0,1.15,1.99],[1,1.14,3],[2,1.13,10]],"ltp":1.51,"tv":12.72,"id":16325787}]}]}
{"op":"mcm","clk":"988832091","pt":1580481187443,"mc":[{"id":"1.168133553","rc":[{"batb":[[0,1.15,4.99],[1,1.13,10],[2,1.12,3]],"ltp":1.51,"tv":12.72,"id":16325787}]}]}
{"op":"mcm","clk":"988833186","pt":1580481199466,"mc":[{"id":"1.168133553","rc":[{"batb":[[0,1.15,1.99]],"ltp":1.51,"tv":12.72,"id":16325787}]}]}
{"op":"mcm","clk":"988833202","pt":1580481199621,"mc":[{"id":"1.168133553","rc":[{"batb":[[0,1.16,3],[1,1.15,1.99],[2,1.13,10]],"ltp":1.51,"tv":12.72,"id":16325787}]}]}
{"op":"mcm","clk":"988834177","pt":1580481211121,"mc":[{"id":"1.168133553","rc":[{"batb":[[0,1.15,1.99],[1,1.14,3]],"ltp":1.51,"tv":12.72,"id":16325787}]}]}
{"op":"mcm","clk":"988834783","pt":1580481218058,"mc":[{"id":"1.168133553","rc":[{"batb":[[0,1.16,36.98],[1,1.15,1.99],[2,1.14,3]],"ltp":1.51,"tv":12.72,"id":16325787}]}]}
{"op":"mcm","clk":"988835249","pt":1580481223436,"mc":[{"id":"1.168133553","rc":[{"batb":[[0,1.17,3],[1,1.16,36.98],[2,1.15,1.99]],"ltp":1.51,"tv":12.72,"id":16325787}]}]}
{"op":"mcm","clk":"988835508","pt":1580481226415,"mc":[{"id":"1.168133553","rc":[{"batb":[[1,1.16,46.98]],"ltp":1.51,"tv":12.72,"id":16325787}]}]}
{"op":"mcm","clk":"988836882","pt":1580481241433,"mc":[{"id":"1.168133553","rc":[{"batb":[[0,1.19,36.05],[1,1.18,1.99],[2,1.17,3]],"ltp":1.51,"tv":12.72,"id":16325787}]}]}
{"op":"mcm","clk":"988837133","pt":1580481244345,"mc":[{"id":"1.168133553","rc":[{"batb":[[0,1.2,3],[1,1.19,36.05],[2,1.18,1.99]],"ltp":1.51,"tv":12.72,"id":16325787}]}]}
{"op":"mcm","clk":"988838942","pt":1580481264471,"mc":[{"id":"1.168133553","rc":[{"batb":[[1,1.18,1.99],[2,1.16,10]],"ltp":1.51,"tv":12.72,"id":16325787}]}]}
{"op":"mcm","clk":"988839638","pt":1580481271780,"mc":[{"id":"1.168133553","rc":[{"batb":[[0,1.18,1.99],[1,1.17,3]],"ltp":1.51,"tv":12.72,"id":16325787}]}]}
{"op":"mcm","clk":"988840571","pt":1580481282110,"mc":[{"id":"1.168133553","rc":[{"batb":[[0,1.18,4.99],[1,1.16,10],[2,1.12,3]],"ltp":1.51,"tv":12.72,"id":16325787}]}]}
{"op":"mcm","clk":"988841530","pt":1580481292532,"mc":[{"id":"1.168133553","rc":[{"batb":[[0,1.19,3],[1,1.18,1.99],[2,1.16,10]],"ltp":1.51,"tv":12.72,"id":16325787}]}]}
{"op":"mcm","clk":"988842012","pt":1580481297729,"mc":[{"id":"1.168133553","rc":[{"batb":[[2,1.16,13]],"ltp":1.51,"tv":12.72,"id":16325787}]}]}
{"op":"mcm","clk":"988842120","pt":1580481298825,"mc":[{"id":"1.168133553","rc":[{"batb":[[0,1.2,1.99],[1,1.19,3]],"ltp":1.51,"tv":12.72,"id":16325787}]}]}
{"op":"mcm","clk":"988842704","pt":1580481305558,"mc":[{"id":"1.168133553","rc":[{"batb":[[2,1.16,3]],"ltp":1.51,"tv":12.72,"id":16325787}]}]}
{"op":"mcm","clk":"988842716","pt":1580481305662,"mc":[{"id":"1.168133553","rc":[{"batb":[[0,1.2,11.99]],"ltp":1.51,"tv":12.72,"id":16325787}]}]}
{"op":"mcm","clk":"988842972","pt":1580481308840,"mc":[{"id":"1.168133553","rc":[{"batb":[[0,1.21,3],[1,1.2,11.99]],"ltp":1.51,"tv":12.72,"id":16325787}]}]}
{"op":"mcm","clk":"988843096","pt":1580481310145,"mc":[{"id":"1.168133553","rc":[{"batb":[[0,1.22,35.16],[1,1.21,3],[2,1.2,11.99]],"ltp":1.51,"tv":12.72,"id":16325787}]}]}
{"op":"mcm","clk":"988844034","pt":1580481320540,"mc":[{"id":"1.168133553","rc":[{"batb":[[0,1.23,3],[1,1.22,35.16]],"ltp":1.51,"tv":12.72,"id":16325787}]}]}
{"op":"mcm","clk":"988845241","pt":1580481333797,"mc":[{"id":"1.168133553","rc":[{"batb":[[1,1.2,11.99],[2,1.16,3]],"ltp":1.51,"tv":12.72,"id":16325787}]}]}
{"op":"mcm","clk":"988845381","pt":1580481335200,"mc":[{"id":"1.168133553","rc":[{"batb":[[0,1.21,3]],"ltp":1.51,"tv":12.72,"id":16325787}]}]}
{"op":"mcm","clk":"988847056","pt":1580481355209,"mc":[{"id":"1.168133553","rc":[{"batb":[[0,1.22,1.99],[1,1.21,3],[2,1.2,10]],"ltp":1.51,"tv":12.72,"id":16325787}]}]}
{"op":"mcm","clk":"988847186","pt":1580481356819,"mc":[{"id":"1.168133553","rc":[{"batb":[[0,1.23,34.87],[1,1.22,1.99],[2,1.21,3]],"ltp":1.51,"tv":12.72,"id":16325787}]}]}
{"op":"mcm","clk":"988847259","pt":1580481357709,"mc":[{"id":"1.168133553","rc":[{"batb":[[0,1.24,3],[1,1.23,34.87],[2,1.22,1.99]],"ltp":1.51,"tv":12.72,"id":16325787}]}]}
{"op":"mcm","clk":"988848933","pt":1580481379945,"mc":[{"id":"1.168133553","rc":[{"batb":[[1,1.22,1.99],[2,1.2,10]],"ltp":1.51,"tv":12.72,"id":16325787}]}]}
{"op":"mcm","clk":"988849329","pt":1580481385056,"mc":[{"id":"1.168133553","rc":[{"batb":[[1,1.23,10],[2,1.22,1.99]],"ltp":1.51,"tv":12.72,"id":16325787}]}]}
{"op":"mcm","clk":"988850929","pt":1580481404427,"mc":[{"id":"1.168133553","rc":[{"batb":[[0,1.25,34.31],[1,1.24,3],[2,1.23,10]],"ltp":1.51,"tv":12.72,"id":16325787}]}]}
{"op":"mcm","clk":"988851157","pt":1580481407706,"mc":[{"id":"1.168133553","rc":[{"batb":[[0,1.26,3],[1,1.25,34.31]],"ltp":1.51,"tv":12.72,"id":16325787}]}]}
{"op":"mcm","clk":"988851948","pt":1580481417436,"mc":[{"id":"1.168133553","rc":[{"batb":[[0,1.27,1.99],[1,1.26,3],[2,1.25,34.31]],"ltp":1.51,"tv":12.72,"id":16325787}]}]}
{"op":"mcm","clk":"988852031","pt":1580481418328,"mc":[{"id":"1.168133553","rc":[{"batb":[[0,1.27,4.99],[1,1.25,34.31],[2,1.23,10]],"ltp":1.51,"tv":12.72,"id":16325787}]}]}
{"op":"mcm","clk":"988852138","pt":1580481419718,"mc":[{"id":"1.168133553","rc":[{"batb":[[1,1.26,3],[2,1.25,34.31]],"ltp":1.51,"tv":12.72,"id":16325787}]}]}
{"op":"mcm","clk":"988852747","pt":1580481427240,"mc":[{"id":"1.168133553","rc":[{"batb":[[2,1.23,10]],"ltp":1.51,"tv":12.72,"id":16325787}]}]}
{"op":"mcm","clk":"988852786","pt":1580481427643,"mc":[{"id":"1.168133553","rc":[{"batb":[[0,1.28,33.51],[1,1.27,4.99],[2,1.26,3]],"ltp":1.51,"tv":12.72,"id":16325787}]}]}
{"op":"mcm","clk":"988852922","pt":1580481429063,"mc":[{"id":"1.168133553","rc":[{"batb":[[0,1.29,3],[1,1.28,33.51],[2,1.27,1.99]],"ltp":1.51,"tv":12.72,"id":16325787}]}]}
{"op":"mcm","clk":"988863538","pt":1580481452339,"mc":[{"id":"1.168133553","rc":[{"batb":[[1,1.27,1.99],[2,1.26,3]],"ltp":1.51,"tv":12.72,"id":16325787}]}]}
{"op":"mcm","clk":"988864256","pt":1580481458196,"mc":[{"id":"1.168133553","rc":[{"batb":[[0,1.27,4.99],[1,1.26,3],[2,1.23,10]],"ltp":1.51,"tv":12.72,"id":16325787}]}]}
{"op":"mcm","clk":"988864872","pt":1580481464486,"mc":[{"id":"1.168133553","rc":[{"batb":[[2,1.03,1628.39]],"ltp":1.51,"tv":12.72,"id":16325787}]}]}
{"op":"mcm","clk":"988864899","pt":1580481464700,"mc":[{"id":"1.168133553","rc":[{"batb":[[0,1.27,14.99]],"ltp":1.51,"tv":12.72,"id":16325787}]}]}
{"op":"mcm","clk":"988865672","pt":1580481471423,"mc":[{"id":"1.168133553","rc":[{"batb":[[0,1.28,3],[1,1.27,10],[2,1.26,3]],"ltp":1.51,"tv":12.72,"id":16325787}]}]}
{"op":"mcm","clk":"988866156","pt":1580481475666,"mc":[{"id":"1.168133553","rc":[{"batb":[[0,1.29,33.25],[1,1.28,3],[2,1.27,10]],"ltp":1.51,"tv":12.72,"id":16325787}]}]}
{"op":"mcm","clk":"988867223","pt":1580481484873,"mc":[{"id":"1.168133553","rc":[{"batb":[[0,1.3,3],[1,1.29,33.25]],"ltp":1.51,"tv":12.72,"id":16325787}]}]}
{"op":"mcm","clk":"988868854","pt":1580481498691,"mc":[{"id":"1.168133553","rc":[{"batb":[[1,1.27,10],[2,1.03,1628.39]],"ltp":1.51,"tv":12.72,"id":16325787}]}]}
{"op":"mcm","clk":"988870056","pt":1580481509880,"mc":[{"id":"1.168133553","rc":[{"batb":[[0,1.28,3]],"ltp":1.51,"tv":12.72,"id":16325787}]}]}
{"op":"mcm","clk":"988871417","pt":1580481522799,"mc":[{"id":"1.168133553","rc":[{"batb":[[0,1.29,33.25],[1,1.28,3],[2,1.27,10]],"ltp":1.51,"tv":12.72,"id":16325787}]}]}
{"op":"mcm","clk":"988872081","pt":1580481529316,"mc":[{"id":"1.168133553","rc":[{"batb":[[0,1.3,3],[1,1.29,33.25]],"ltp":1.51,"tv":12.72,"id":16325787}]}]}
{"op":"mcm","clk":"988873407","pt":1580481544429,"mc":[{"id":"1.168133553","rc":[{"batb":[[0,1.3,13],[2,1.03,1628.39]],"ltp":1.51,"tv":12.72,"id":16325787}]}]}
{"op":"mcm","clk":"988873518","pt":1580481545732,"mc":[{"id":"1.168133553","rc":[{"batb":[[1,1.03,1628.39],[2,1.02,5002.19]],"ltp":1.51,"tv":12.72,"id":16325787}]}]}
{"op":"mcm","clk":"988873933","pt":1580481550540,"mc":[{"id":"1.168133553","rc":[{"batb":[[0,1.31,3],[1,1.3,10],[2,1.03,1628.39]],"ltp":1.51,"tv":12.72,"id":16325787}]}]}
{"op":"mcm","clk":"988875718","pt":1580481569262,"mc":[{"id":"1.168133553","rc":[{"batb":[[0,1.32,32.5],[1,1.31,3],[2,1.3,10]],"ltp":1.51,"tv":12.72,"id":16325787}]}]}
{"op":"mcm","clk":"988876050","pt":1580481572760,"mc":[{"id":"1.168133553","rc":[{"batb":[[0,1.33,3],[1,1.32,32.5]],"ltp":1.51,"tv":12.72,"id":16325787}]}]}
{"op":"mcm","clk":"988877974","pt":1580481592791,"mc":[{"id":"1.168133553","rc":[{"batb":[[1,1.3,10],[2,1.03,1628.39]],"ltp":1.51,"tv":12.72,"id":16325787}]}]}
{"op":"mcm","clk":"988878997","pt":1580481603096,"mc":[{"id":"1.168133553","rc":[{"batb":[[0,1.31,3]],"ltp":1.51,"tv":12.72,"id":16325787}]}]}
{"op":"mcm","clk":"988880217","pt":1580481616006,"mc":[{"id":"1.168133553","rc":[{"batb":[[0,1.32,32.5],[1,1.31,3],[2,1.3,10]],"ltp":1.51,"tv":12.72,"id":16325787}]}]}
{"op":"mcm","clk":"988881214","pt":1580481626549,"mc":[{"id":"1.168133553","rc":[{"batb":[[0,1.33,3],[1,1.32,32.5],[2,1.03,1628.39]],"ltp":1.51,"tv":12.72,"id":16325787}]}]}
{"op":"mcm","clk":"988882359","pt":1580481638840,"mc":[{"id":"1.168133553","rc":[{"batb":[[1,1.03,1628.39],[2,1.02,5002.19]],"ltp":1.51,"tv":12.72,"id":16325787}]}]}
{"op":"mcm","clk":"988883122","pt":1580481646750,"mc":[{"id":"1.168133553","rc":[{"batb":[[0,1.04,3]],"ltp":1.51,"tv":12.72,"id":16325787}]}]}
{"op":"mcm","clk":"988884576","pt":1580481662100,"mc":[{"id":"1.168133553","rc":[{"batb":[[0,1.05,40.85],[1,1.04,3],[2,1.03,1628.39]],"ltp":1.51,"tv":12.72,"id":16325787}]}]}
{"op":"mcm","clk":"988884957","pt":1580481665982,"mc":[{"id":"1.168133553","rc":[{"batb":[[0,1.06,3],[1,1.05,40.85]],"ltp":1.51,"tv":12.72,"id":16325787}]}]}
{"op":"mcm","clk":"988885317","pt":1580481669821,"mc":[{"id":"1.168133553","rc":[{"batb":[[0,1.07,1.99],[1,1.06,3],[2,1.05,40.85]],"ltp":1.51,"tv":12.72,"id":16325787}]}]}
{"op":"mcm","clk":"988886164","pt":1580481679303,"mc":[{"id":"1.168133553","rc":[{"batb":[[0,1.07,4.99],[1,1.05,40.85],[2,1.04,6]],"ltp":1.51,"tv":12.72,"id":16325787}]}]}
{"op":"mcm","clk":"988886654","pt":1580481684799,"mc":[{"id":"1.168133553","rc":[{"batb":[[1,1.04,6],[2,1.03,1628.39]],"ltp":1.51,"tv":12.72,"id":16325787}]}]}
{"op":"mcm","clk":"988887250","pt":1580481691554,"mc":[{"id":"1.168133553","rc":[{"batb":[[0,1.08,3],[1,1.07,1.99],[2,1.04,6]],"ltp":1.51,"tv":12.72,"id":16325787}]}]}
{"op":"mcm","clk":"988887762","pt":1580481697138,"mc":[{"id":"1.168133553","rc":[{"batb":[[2,1.05,3]],"ltp":1.51,"tv":12.72,"id":16325787}]}]}
{"op":"mcm","clk":"988888189","pt":1580481702762,"mc":[{"id":"1.168133553","rc":[{"batb":[[0,1.07,1.99],[1,1.06,3]],"ltp":1.51,"tv":12.72,"id":16325787}]}]}
{"op":"mcm","clk":"988888646","pt":1580481707952,"mc":[{"id":"1.168133553","rc":[{"batb":[[0,1.08,39.71],[1,1.07,1.99],[2,1.06,3]],"ltp":1.51,"tv":12.72,"id":16325787}]}]}
{"op":"mcm","clk":"988889138","pt":1580481713789,"mc":[{"id":"1.168133553","rc":[{"batb":[[0,1.09,3],[1,1.08,39.71],[2,1.07,1.99]],"ltp":1.51,"tv":12.72,"id":16325787}]}]}
{"op":"mcm","clk":"988890376","pt":1580481727808,"mc":[{"id":"1.168133553","rc":[{"batb":[[0,1.1,1.99],[1,1.09,3],[2,1.08,39.71]],"ltp":1.51,"tv":12.72,"id":16325787}]}]}
{"op":"mcm","clk":"988890694","pt":1580481731413,"mc":[{"id":"1.168133553","rc":[{"batb":[[0,1.11,38.65],[1,1.1,1.99],[2,1.09,3]],"ltp":1.51,"tv":12.72,"id":16325787}]}]}
{"op":"mcm","clk":"988891114","pt":1580481736135,"mc":[{"id":"1.168133553","rc":[{"batb":[[0,1.12,3],[1,1.11,38.65],[2,1.1,1.99]],"ltp":1.51,"tv":12.72,"id":16325787}]}]}
{"op":"mcm","clk":"988892811","pt":1580481754152,"mc":[{"id":"1.168133553","rc":[{"batb":[[1,1.1,1.99],[2,1.05,3]],"ltp":1.51,"tv":12.72,"id":16325787}]}]}
{"op":"mcm","clk":"988893253","pt":1580481759865,"mc":[{"id":"1.168133553","rc":[{"batb":[[0,1.1,1.99],[1,1.06,3]],"ltp":1.51,"tv":12.72,"id":16325787}]}]}
{"op":"mcm","clk":"988894043","pt":1580481769555,"mc":[{"id":"1.168133553","rc":[{"batb":[[1,1.07,3]],"ltp":1.51,"tv":12.72,"id":16325787}]}]}
{"op":"mcm","clk":"988894523","pt":1580481775186,"mc":[{"id":"1.168133553","rc":[{"batb":[[0,1.08,1.99]],"ltp":1.51,"tv":12.72,"id":16325787}]}]}
{"op":"mcm","clk":"988894658","pt":1580481776978,"mc":[{"id":"1.168133553","rc":[{"batb":[[0,1.09,39.35],[1,1.08,1.99],[2,1.07,3]],"ltp":1.51,"tv":12.72,"id":16325787}]}]}
{"op":"mcm","clk":"988895099","pt":1580481782277,"mc":[{"id":"1.168133553","rc":[{"batb":[[0,1.1,3],[1,1.09,39.35],[2,1.08,1.99]],"ltp":1.51,"tv":12.72,"id":16325787}]}]}
{"op":"mcm","clk":"988896662","pt":1580481799923,"mc":[{"id":"1.168133553","rc":[{"batb":[[1,1.08,1.99],[2,1.05,3]],"ltp":1.51,"tv":12.72,"id":16325787}]}]}
{"op":"mcm","clk":"988897621","pt":1580481811553,"mc":[{"id":"1.168133553","rc":[{"batb":[[0,1.08,1.99],[1,1.06,3]],"ltp":1.51,"tv":12.72,"id":16325787}]}]}
{"op":"mcm","clk":"988898282","pt":1580481820226,"mc":[{"id":"1.168133553","rc":[{"batb":[[1,1.07,3]],"ltp":1.51,"tv":12.72,"id":16325787}]}]}
{"op":"mcm","clk":"988898622","pt":1580481824643,"mc":[{"id":"1.168133553","rc":[{"batb":[[0,1.09,39.35],[1,1.08,1.99],[2,1.07,3]],"ltp":1.51,"tv":12.72,"id":16325787}]}]}
{"op":"mcm","clk":"988899141","pt":1580481831264,"mc":[{"id":"1.168133553","rc":[{"batb":[[0,1.1,3],[1,1.09,39.35],[2,1.08,1.99]],"ltp":1.51,"tv":12.72,"id":16325787}]}]}
{"op":"mcm","clk":"988900555","pt":1580481849157,"mc":[{"id":"1.168133553","rc":[{"batb":[[1,1.08,1.99],[2,1.04,6]],"ltp":1.51,"tv":12.72,"id":16325787}]}]}
{"op":"mcm","clk":"988901200","pt":1580481857303,"mc":[{"id":"1.168133553","rc":[{"batb":[[0,1.08,1.99],[1,1.05,3]],"ltp":1.51,"tv":12.72,"id":16325787}]}]}
{"op":"mcm","clk":"988902128","pt":1580481868681,"mc":[{"id":"1.168133553","rc":[{"batb":[[1,1.06,3]],"ltp":1.51,"tv":12.72,"id":16325787}]}]}
{"op":"mcm","clk":"988902606","pt":1580481874825,"mc":[{"id":"1.168133553","rc":[{"batb":[[0,1.07,1.99]],"ltp":1.51,"tv":12.72,"id":16325787}]}]}
{"op":"mcm","clk":"988903082","pt":1580481880099,"mc":[{"id":"1.168133553","rc":[{"batb":[[0,1.07,4.99],[1,1.04,6],[2,1.03,1628.39]],"ltp":1.51,"tv":12.72,"id":16325787}]}]}
{"op":"mcm","clk":"988903911","pt":1580481890535,"mc":[{"id":"1.168133553","rc":[{"batb":[[0,1.07,1.99]],"ltp":1.51,"tv":12.72,"id":16325787}]}]}
{"op":"mcm","clk":"988903918","pt":1580481890638,"mc":[{"id":"1.168133553","rc":[{"batb":[[0,1.08,3],[1,1.07,1.99],[2,1.04,6]],"ltp":1.51,"tv":12.72,"id":16325787}]}]}
{"op":"mcm","clk":"988904339","pt":1580481896432,"mc":[{"id":"1.168133553","rc":[{"batb":[[0,1.09,39.35],[1,1.08,3],[2,1.07,1.99]],"ltp":1.51,"tv":12.72,"id":16325787}]}]}
{"op":"mcm","clk":"988904814","pt":1580481902533,"mc":[{"id":"1.168133553","rc":[{"batb":[[0,1.1,3],[1,1.09,39.35]],"ltp":1.51,"tv":12.72,"id":16325787}]}]}
{"op":"mcm","clk":"988906124","pt":1580481919181,"mc":[{"id":"1.168133553","rc":[{"batb":[[1,1.07,1.99],[2,1.04,6]],"ltp":1.51,"tv":12.72,"id":16325787}]}]}
{"op":"mcm","clk":"988906490","pt":1580481923981,"mc":[{"id":"1.168133553","rc":[{"batb":[[0,1.07,1.99],[1,1.05,3]],"ltp":1.51,"tv":12.72,"id":16325787}]}]}
{"op":"mcm","clk":"988906640","pt":1580481926290,"mc":[{"id":"1.168133553","rc":[{"batb":[[0,1.05,3],[1,1.04,6],[2,1.03,1628.39]],"ltp":1.51,"tv":12.72,"id":16325787}]}]}
{"op":"mcm","clk":"988906665","pt":1580481926605,"mc":[{"id":"1.168133553","rc":[{"batb":[[0,1.06,1.99],[1,1.05,3],[2,1.04,6]],"ltp":1.51,"tv":12.72,"id":16325787}]}]}
{"op":"mcm","clk":"988907440","pt":1580481936117,"mc":[{"id":"1.168133553","rc":[{"batb":[[0,1.06,4.99],[1,1.04,6],[2,1.03,1628.39]],"ltp":1.51,"tv":12.72,"id":16325787}]}]}
{"op":"mcm","clk":"988908236","pt":1580481945939,"mc":[{"id":"1.168133553","rc":[{"batb":[[0,1.07,3],[1,1.06,1.99],[2,1.04,6]],"ltp":1.51,"tv":12.72,"id":16325787}]}]}
{"op":"mcm","clk":"988908445","pt":1580481948617,"mc":[{"id":"1.168133553","rc":[{"batb":[[0,1.07,13]],"ltp":1.51,"tv":12.72,"id":16325787}]}]}
{"op":"mcm","clk":"988909065","pt":1580481956446,"mc":[{"id":"1.168133553","rc":[{"batb":[[0,1.08,3],[1,1.07,10],[2,1.06,1.99]],"ltp":1.51,"tv":12.72,"id":16325787}]}]}
{"op":"mcm","clk":"988909809","pt":1580481965028,"mc":[{"id":"1.168133553","rc":[{"batb":[[0,1.09,39.35],[1,1.08,3],[2,1.07,10]],"ltp":1.51,"tv":12.72,"id":16325787}]}]}
{"op":"mcm","clk":"988909898","pt":1580481966031,"mc":[{"id":"1.168133553","rc":[{"batb":[[0,1.1,3],[1,1.09,39.35]],"ltp":1.51,"tv":12.72,"id":16325787}]}]}
{"op":"mcm","clk":"988911079","pt":1580481980073,"mc":[{"id":"1.168133553","rc":[{"batb":[[0,1.11,1.99],[1,1.1,3],[2,1.09,39.35]],"ltp":1.51,"tv":12.72,"id":16325787}]}]}
{"op":"mcm","clk":"988911366","pt":1580481983556,"mc":[{"id":"1.168133553","rc":[{"batb":[[1,1.09,39.35],[2,1.07,10]],"ltp":1.51,"tv":12.72,"id":16325787}]}]}
{"op":"mcm","clk":"988911375","pt":1580481983656,"mc":[{"id":"1.168133553","rc":[{"batb":[[0,1.11,4.99]],"ltp":1.51,"tv":12.72,"id":16325787}]}]}
{"op":"mcm","clk":"988911694","pt":1580481987785,"mc":[{"id":"1.168133553","rc":[{"batb":[[1,1.07,10],[2,1.04,6]],"ltp":1.51,"tv":12.72,"id":16325787}]}]}
{"op":"mcm","clk":"988912200","pt":1580481994383,"mc":[{"id":"1.168133553","rc":[{"batb":[[0,1.12,3],[1,1.11,1.99],[2,1.07,10]],"ltp":1.51,"tv":12.72,"id":16325787}]}]}
{"op":"mcm","clk":"988912891","pt":1580482003057,"mc":[{"id":"1.168133553","rc":[{"batb":[[0,1.11,1.99],[1,1.08,3]],"ltp":1.51,"tv":12.72,"id":16325787}]}]}
{"op":"mcm","clk":"988913471","pt":1580482011415,"mc":[{"id":"1.168133553","rc":[{"batb":[[1,1.09,3]],"ltp":1.51,"tv":12.72,"id":16325787}]}]}
{"op":"mcm","clk":"988914303","pt":1580482022015,"mc":[{"id":"1.168133553","rc":[{"batb":[[1,1.1,3]],"ltp":1.51,"tv":12.72,"id":16325787}]}]}
{"op":"mcm","clk":"988914446","pt":1580482023827,"mc":[{"id":"1.168133553","rc":[{"batb":[[2,1.08,3]],"ltp":1.51,"tv":12.72,"id":16325787}]}]}
{"op":"mcm","clk":"988914790","pt":1580482028493,"mc":[{"id":"1.168133553","rc":[{"batb":[[0,1.11,11.99]],"ltp":1.51,"tv":12.72,"id":16325787}]}]}
{"op":"mcm","clk":"988915130","pt":1580482033430,"mc":[{"id":"1.168133553","rc":[{"batb":[[0,1.12,38.3],[1,1.11,11.99],[2,1.1,3]],"ltp":1.51,"tv":12.72,"id":16325787}]}]}
{"op":"mcm","clk":"988915258","pt":1580482034944,"mc":[{"id":"1.168133553","rc":[{"batb":[[0,1.13,3],[1,1.12,38.3],[2,1.11,11.99]],"ltp":1.51,"tv":12.72,"id":16325787}]}]}
{"op":"mcm","clk":"988916061","pt":1580482046167,"mc":[{"id":"1.168133553","rc":[{"batb":[[0,1.14,1.99],[1,1.13,3],[2,1.12,38.3]],"ltp":1.51,"tv":12.72,"id":16325787}]}]}
{"op":"mcm","clk":"988916206","pt":1580482048090,"mc":[{"id":"1.168133553","rc":[{"batb":[[0,1.14,4.99],[1,1.12,38.3],[2,1.11,10]],"ltp":1.51,"tv":12.72,"id":16325787}]}]}
{"op":"mcm","clk":"988916940","pt":1580482057264,"mc":[{"id":"1.168133553","rc":[{"batb":[[1,1.11,10],[2,1.08,3]],"ltp":1.51,"tv":12.72,"id":16325787}]}]}
{"op":"mcm","clk":"988917044","pt":1580482059040,"mc":[{"id":"1.168133553","rc":[{"batb":[[0,1.15,3],[1,1.14,1.99],[2,1.11,10]],"ltp":1.51,"tv":12.72,"id":16325787}]}]}
{"op":"mcm","clk":"988917852","pt":1580482070347,"mc":[{"id":"1.168133553","rc":[{"batb":[[0,1.14,1.99],[1,1.12,3]],"ltp":1.51,"tv":12.72,"id":16325787}]}]}
{"op":"mcm","clk":"988918506","pt":1580482080532,"mc":[{"id":"1.168133553","rc":[{"batb":[[0,1.15,37.3],[1,1.14,1.99],[2,1.13,3]],"ltp":1.51,"tv":12.72,"id":16325787}]}]}
{"op":"mcm","clk":"988919162","pt":1580482091911,"mc":[{"id":"1.168133553","rc":[{"batb":[[0,1.16,3],[1,1.15,37.3],[2,1.14,1.99]],"ltp":1.51,"tv":12.72,"id":16325787}]}]}
{"op":"mcm","clk":"988920001","pt":1580482103543,"mc":[{"id":"1.168133553","rc":[{"batb":[[1,1.14,1.99],[2,1.11,10]],"ltp":1.51,"tv":12.72,"id":16325787}]}]}
{"op":"mcm","clk":"988920068","pt":1580482104571,"mc":[{"id":"1.168133553","rc":[{"batb":[[0,1.14,1.99],[1,1.11,10],[2,1.03,1628.39]],"ltp":1.51,"tv":12.72,"id":16325787}]}]}
{"op":"mcm","clk":"988920076","pt":1580482104628,"mc":[{"id":"1.168133553","rc":[{"batb":[[1,1.12,3],[2,1.11,10]],"ltp":1.51,"tv":12.72,"id":16325787}]}]}
{"op":"mcm","clk":"988920283","pt":1580482107870,"mc":[{"id":"1.168133553","rc":[{"batb":[[1,1.13,10],[2,1.12,3]],"ltp":1.51,"tv":12.72,"id":16325787}]}]}
{"op":"mcm","clk":"988920794","pt":1580482115755,"mc":[{"id":"1.168133553","rc":[{"batb":[[0,1.14,4.99],[2,1.04,6]],"ltp":1.51,"tv":12.72,"id":16325787}]}]}
{"op":"mcm","clk":"988921533","pt":1580482126569,"mc":[{"id":"1.168133553","rc":[{"batb":[[0,1.15,3],[1,1.14,1.99],[2,1.13,10]],"ltp":1.51,"tv":12.72,"id":16325787}]}]}
{"op":"mcm","clk":"988921578","pt":1580482127204,"mc":[{"id":"1.168133553","rc":[{"batb":[[0,1.16,36.98],[1,1.15,3],[2,1.14,1.99]],"ltp":1.51,"tv":12.72,"id":16325787}]}]}
{"op":"mcm","clk":"988922293","pt":1580482137790,"mc":[{"id":"1.168133553","rc":[{"batb":[[0,1.17,3],[1,1.16,36.98]],"ltp":1.51,"tv":12.72,"id":16325787}]}]}
{"op":"mcm","clk":"988923126","pt":1580482151030,"mc":[{"id":"1.168133553","rc":[{"batb":[[1,1.14,1.99],[2,1.13,10]],"ltp":1.51,"tv":12.72,"id":16325787}]}]}
{"op":"mcm","clk":"988923687","pt":1580482160029,"mc":[{"id":"1.168133553","rc":[{"batb":[[0,1.14,4.99],[1,1.13,10],[2,1.03,1628.39]],"ltp":1.51,"tv":12.72,"id":16325787}]}]}
{"op":"mcm","clk":"988923989","pt":1580482164339,"mc":[{"id":"1.168133553","rc":[{"batb":[[2,1.04,6]],"ltp":1.51,"tv":12.72,"id":16325787}]}]}
{"op":"mcm","clk":"988924528","pt":1580482171243,"mc":[{"id":"1.168133553","rc":[{"batb":[[0,1.15,3],[1,1.14,1.99],[2,1.13,10]],"ltp":1.51,"tv":12.72,"id":16325787}]}]}
{"op":"mcm","clk":"988924723","pt":1580482174667,"mc":[{"id":"1.168133553","rc":[{"batb":[[0,1.16,36.98],[1,1.15,3],[2,1.14,1.99]],"ltp":1.51,"tv":12.72,"id":16325787}]}]}
{"op":"mcm","clk":"988925047","pt":1580482179974,"mc":[{"id":"1.168133553","rc":[{"batb":[[0,1.17,3],[1,1.16,36.98]],"ltp":1.51,"tv":12.72,"id":16325787}]}]}
{"op":"mcm","clk":"988925473","pt":1580482187194,"mc":[{"id":"1.168133553","rc":[{"batb":[[1,1.16,46.98]],"ltp":1.51,"tv":12.72,"id":16325787}]}]}
{"op":"mcm","clk":"988926233","pt":1580482198105,"mc":[{"id":"1.168133553","rc":[{"batb":[[0,1.18,36.35],[1,1.17,3],[2,1.16,10]],"ltp":1.51,"tv":12.72,"id":16325787}]}]}
{"op":"mcm","clk":"988926290","pt":1580482198881,"mc":[{"id":"1.168133553","rc":[{"batb":[[0,1.19,3],[1,1.18,36.35]],"ltp":1.51,"tv":12.72,"id":16325787}]}]}
{"op":"mcm","clk":"988927937","pt":1580482222340,"mc":[{"id":"1.168133553","rc":[{"batb":[[0,1.21,35.45],[1,1.2,1.99],[2,1.19,3]],"ltp":1.51,"tv":12.72,"id":16325787}]}]}
{"op":"mcm","clk":"988928314","pt":1580482228418,"mc":[{"id":"1.168133553","rc":[{"batb":[[0,1.22,3],[1,1.21,35.45],[2,1.2,1.99]],"ltp":1.51,"tv":12.72,"id":16325787}]}]}
{"op":"mcm","clk":"988929284","pt":1580482245727,"mc":[{"id":"1.168133553","rc":[{"batb":[[1,1.2,1.99],[2,1.16,10]],"ltp":1.51,"tv":12.72,"id":16325787}]}]}
{"op":"mcm","clk":"988929498","pt":1580482249180,"mc":[{"id":"1.168133553","rc":[{"batb":[[0,1.2,1.99],[1,1.17,3]],"ltp":1.51,"tv":12.72,"id":16325787}]}]}
{"op":"mcm","clk":"988930096","pt":1580482259190,"mc":[{"id":"1.168133553","rc":[{"batb":[[1,1.18,3]],"ltp":1.51,"tv":12.72,"id":16325787}]}]}
{"op":"mcm","clk":"988930712","pt":1580482269103,"mc":[{"id":"1.168133553","rc":[{"batb":[[0,1.21,35.45],[1,1.2,1.99],[2,1.19,3]],"ltp":1.51,"tv":12.72,"id":16325787}]}]}
{"op":"mcm","clk":"988930902","pt":1580482272981,"mc":[{"id":"1.168133553","rc":[{"batb":[[0,1.22,1.99],[1,1.21,35.45]],"ltp":1.51,"tv":12.72,"id":16325787}]}]}
{"op":"mcm","clk":"988931172","pt":1580482278402,"mc":[{"id":"1.168133553","rc":[{"batb":[[0,1.22,4.99],[2,1.03,1628.39]],"ltp":1.51,"tv":12.72,"id":16325787}]}]}
{"op":"mcm","clk":"988931580","pt":1580482286225,"mc":[{"id":"1.168133553","rc":[{"batb":[[0,1.23,3],[1,1.22,1.99],[2,1.21,35.45]],"ltp":1.51,"tv":12.72,"id":16325787}]}]}
{"op":"mcm","clk":"988931818","pt":1580482290893,"mc":[{"id":"1.168133553","rc":[{"batb":[[1,1.22,4.99]],"ltp":1.51,"tv":12.72,"id":16325787}]}]}
{"op":"mcm","clk":"988931897","pt":1580482292422,"mc":[{"id":"1.168133553","rc":[{"batb":[[0,1.24,34.59],[1,1.23,3],[2,1.22,4.99]],"ltp":1.51,"tv":12.72,"id":16325787}]}]}
{"op":"mcm","clk":"988932068","pt":1580482295726,"mc":[{"id":"1.168133553","rc":[{"batb":[[0,1.25,3],[1,1.24,34.59]],"ltp":1.51,"tv":12.72,"id":16325787}]}]}
{"op":"mcm","clk":"988932266","pt":1580482299333,"mc":[{"id":"1.168133553","rc":[{"batl":[[0,2,2],[1,3.1,4.2]],"ltp":1.51,"tv":12.72,"id":16325787}]}]}
{"op":"mcm","clk":"988932786","pt":1580482308228,"mc":[{"id":"1.168133553","rc":[{"batl":[[0,2,2.2],[1,3.1,4]],"ltp":1.51,"tv":12.72,"id":16325787}]}]}
{"op":"mcm","clk":"988933271","pt":1580482315854,"mc":[{"id":"1.168133553","rc":[{"batb":[[1,1.22,4.99],[2,1.03,1628.39]],"ltp":1.51,"tv":12.72,"id":16325787}]}]}
{"op":"mcm","clk":"988933741","pt":1580482324476,"mc":[{"id":"1.168133553","rc":[{"trd":[[1.47,4]],"ltp":1.47,"tv":16.72,"id":16325787}],"tv":16.72}]}
{"op":"mcm","clk":"988933846","pt":1580482326454,"mc":[{"id":"1.168133553","rc":[{"batb":[[0,1.23,3]],"ltp":1.47,"tv":16.72,"id":16325787}]}]}
{"op":"mcm","clk":"988934753","pt":1580482341201,"mc":[{"id":"1.168133553","rc":[{"batb":[[1,1.22,3]],"batl":[[0,1.56,2],[1,2,2.2],[2,3.1,4]],"ltp":1.47,"tv":16.72,"id":16325787}]}]}
{"op":"mcm","clk":"988935393","pt":1580482350792,"mc":[{"id":"1.168133553","rc":[{"batl":[[0,1.59,2]],"ltp":1.47,"tv":16.72,"id":16325787}]}]}
{"op":"mcm","clk":"988944145","pt":1580482357505,"mc":[{"id":"1.168133553","rc":[{"batb":[[1,1.03,1628.39],[2,1.02,5002.19]],"ltp":1.47,"tv":16.72,"id":16325787}]}]}
{"op":"mcm","clk":"988944156","pt":1580482357712,"mc":[{"id":"1.168133553","rc":[{"batb":[[1,1.04,3],[2,1.03,1628.39]],"ltp":1.47,"tv":16.72,"id":16325787}]}]}
{"op":"mcm","clk":"988944716","pt":1580482366841,"mc":[{"id":"1.168133553","rc":[{"batb":[[0,1.05,3]],"ltp":1.47,"tv":16.72,"id":16325787}]}]}
{"op":"mcm","clk":"988944869","pt":1580482369436,"mc":[{"id":"1.168133553","rc":[{"batl":[[0,1.59,2.2],[1,2,2]],"ltp":1.47,"tv":16.72,"id":16325787}]}]}
{"op":"mcm","clk":"988946515","pt":1580482397347,"mc":[{"id":"1.168133553","rc":[{"batb":[[0,1.06,1.99],[1,1.05,3],[2,1.04,3]],"ltp":1.47,"tv":16.72,"id":16325787}]}]}
{"op":"mcm","clk":"988946553","pt":1580482397862,"mc":[{"id":"1.168133553","rc":[{"batb":[[0,1.06,4.99],[1,1.04,3],[2,1.03,1628.39]],"ltp":1.47,"tv":16.72,"id":16325787}]}]}
{"op":"mcm","clk":"988947087","pt":1580482408885,"mc":[{"id":"1.168133553","rc":[{"batb":[[0,1.07,3],[1,1.06,1.99],[2,1.04,3]],"ltp":1.47,"tv":16.72,"id":16325787}]}]}
{"op":"mcm","clk":"988947724","pt":1580482419712,"mc":[{"id":"1.168133553","rc":[{"batb":[[0,1.06,1.99],[1,1.05,3]],"ltp":1.47,"tv":16.72,"id":16325787}]}]}
{"op":"mcm","clk":"988948301","pt":1580482429310,"mc":[{"id":"1.168133553","rc":[{"batb":[[0,1.06,4.99],[1,1.04,3],[2,1.03,1628.39]],"ltp":1.47,"tv":16.72,"id":16325787}]}]}
{"op":"mcm","clk":"988948349","pt":1580482430216,"mc":[{"id":"1.168133553","rc":[{"batb":[[1,1.05,10],[2,1.04,3]],"ltp":1.47,"tv":16.72,"id":16325787}]}]}
{"op":"mcm","clk":"988948963","pt":1580482440832,"mc":[{"id":"1.168133553","rc":[{"batb":[[0,1.07,3],[1,1.06,1.99],[2,1.05,10]],"ltp":1.47,"tv":16.72,"id":16325787}]}]}
{"op":"mcm","clk":"988949566","pt":1580482451549,"mc":[{"id":"1.168133553","rc":[{"batb":[[0,1.06,1.99],[1,1.05,10],[2,1.04,3]],"ltp":1.47,"tv":16.72,"id":16325787}]}]}
{"op":"mcm","clk":"988949571","pt":1580482451653,"mc":[{"id":"1.168133553","rc":[{"batb":[[0,1.06,4.99]],"ltp":1.47,"tv":16.72,"id":16325787}]}]}
{"op":"mcm","clk":"988950129","pt":1580482461764,"mc":[{"id":"1.168133553","rc":[{"batb":[[0,1.07,3],[1,1.06,1.99],[2,1.05,10]],"ltp":1.47,"tv":16.72,"id":16325787}]}]}
{"op":"mcm","clk":"988950632","pt":1580482471875,"mc":[{"id":"1.168133553","rc":[{"batb":[[0,1.06,4.99],[1,1.05,10],[2,1.04,3]],"ltp":1.47,"tv":16.72,"id":16325787}]}]}
{"op":"mcm","clk":"988951058","pt":1580482478685,"mc":[{"id":"1.168133553","rc":[{"batb":[[0,1.07,3],[1,1.06,1.99],[2,1.05,10]],"ltp":1.47,"tv":16.72,"id":16325787}]}]}
{"op":"mcm","clk":"988951404","pt":1580482484502,"mc":[{"id":"1.168133553","rc":[{"batb":[[1,1.06,4.99]],"ltp":1.47,"tv":16.72,"id":16325787}]}]}
{"op":"mcm","clk":"988953108","pt":1580482510656,"mc":[{"id":"1.168133553","rc":[{"batb":[[0,1.07,13],[2,1.04,6]],"ltp":1.47,"tv":16.72,"id":16325787}]}]}
{"op":"mcm","clk":"988953358","pt":1580482514378,"mc":[{"id":"1.168133553","rc":[{"batb":[[0,1.08,1.99],[1,1.07,13],[2,1.06,3]],"ltp":1.47,"tv":16.72,"id":16325787}]}]}
{"op":"mcm","clk":"988953528","pt":1580482517354,"mc":[{"id":"1.168133553","rc":[{"batb":[[0,1.08,4.99],[1,1.07,10]],"ltp":1.47,"tv":16.72,"id":16325787}]}]}
{"op":"mcm","clk":"988954089","pt":1580482527005,"mc":[{"id":"1.168133553","rc":[{"batb":[[0,1.09,3],[1,1.08,1.99],[2,1.07,10]],"ltp":1.47,"tv":16.72,"id":16325787}]}]}
{"op":"mcm","clk":"988955037","pt":1580482542899,"mc":[{"id":"1.168133553","rc":[{"batb":[[0,1.08,4.99],[1,1.07,10],[2,1.06,3]],"ltp":1.47,"tv":16.72,"id":16325787}]}]}
{"op":"mcm","clk":"988955209","pt":1580482545997,"mc":[{"id":"1.168133553","rc":[{"batb":[[2,1.04,6]],"ltp":1.47,"tv":16.72,"id":16325787}]}]}
{"op":"mcm","clk":"988955704","pt":1580482555507,"mc":[{"id":"1.168133553","rc":[{"batb":[[0,1.08,1.99]],"ltp":1.47,"tv":16.72,"id":16325787}]}]}
{"op":"mcm","clk":"988955710","pt":1580482555609,"mc":[{"id":"1.168133553","rc":[{"batb":[[0,1.09,3],[1,1.08,1.99],[2,1.07,10]],"ltp":1.47,"tv":16.72,"id":16325787}]}]}
{"op":"mcm","clk":"988956255","pt":1580482564220,"mc":[{"id":"1.168133553","rc":[{"batb":[[0,1.08,4.99],[1,1.07,10],[2,1.04,6]],"ltp":1.47,"tv":16.72,"id":16325787}]}]}
{"op":"mcm","clk":"988956844","pt":1580482574821,"mc":[{"id":"1.168133553","rc":[{"batb":[[0,1.09,3],[1,1.08,1.99],[2,1.07,10]],"ltp":1.47,"tv":16.72,"id":16325787}]}]}
{"op":"mcm","clk":"988957444","pt":1580482584965,"mc":[{"id":"1.168133553","rc":[{"batb":[[0,1.08,4.99],[1,1.07,10],[2,1.04,6]],"ltp":1.47,"tv":16.72,"id":16325787}]}]}
{"op":"mcm","clk":"988958057","pt":1580482595172,"mc":[{"id":"1.168133553","rc":[{"batb":[[1,1.05,10]],"ltp":1.47,"tv":16.72,"id":16325787}]}]}
{"op":"mcm","clk":"988958268","pt":1580482598347,"mc":[{"id":"1.168133553","rc":[{"batb":[[0,1.09,3],[1,1.08,1.99],[2,1.05,10]],"ltp":1.47,"tv":16.72,"id":16325787}]}]}
{"op":"mcm","clk":"988958894","pt":1580482609169,"mc":[{"id":"1.168133553","rc":[{"batb":[[0,1.08,1.99],[1,1.06,3]],"ltp":1.47,"tv":16.72,"id":16325787}]}]}
{"op":"mcm","clk":"988959063","pt":1580482611984,"mc":[{"id":"1.168133553","rc":[{"batb":[[0,1.07,1.99]],"ltp":1.47,"tv":16.72,"id":16325787}]}]}
{"op":"mcm","clk":"988959845","pt":1580482625410,"mc":[{"id":"1.168133553","rc":[{"batb":[[0,1.07,4.99],[1,1.05,10],[2,1.04,6]],"ltp":1.47,"tv":16.72,"id":16325787}]}]}
{"op":"mcm","clk":"988960478","pt":1580482636139,"mc":[{"id":"1.168133553","rc":[{"batb":[[0,1.08,3],[1,1.07,1.99],[2,1.05,10]],"ltp":1.47,"tv":16.72,"id":16325787}]}]}
{"op":"mcm","clk":"988961166","pt":1580482647240,"mc":[{"id":"1.168133553","rc":[{"batb":[[0,1.07,1.99],[1,1.06,3]],"ltp":1.47,"tv":16.72,"id":16325787}]}]}
{"op":"mcm","clk":"988961780","pt":1580482658067,"mc":[{"id":"1.168133553","rc":[{"batb":[[0,1.07,4.99],[1,1.05,10],[2,1.04,6]],"ltp":1.47,"tv":16.72,"id":16325787}]}]}
{"op":"mcm","clk":"988962488","pt":1580482669097,"mc":[{"id":"1.168133553","rc":[{"batb":[[0,1.08,3],[1,1.07,1.99],[2,1.05,10]],"ltp":1.47,"tv":16.72,"id":16325787}]}]}
{"op":"mcm","clk":"988963184","pt":1580482678814,"mc":[{"id":"1.168133553","rc":[{"batb":[[2,1.06,3]],"ltp":1.47,"tv":16.72,"id":16325787}]}]}
{"op":"mcm","clk":"988963331","pt":1580482681301,"mc":[{"id":"1.168133553","rc":[{"batb":[[0,1.07,4.99],[1,1.06,3],[2,1.05,10]],"ltp":1.47,"tv":16.72,"id":16325787}]}]}
{"op":"mcm","clk":"988963560","pt":1580482685102,"mc":[{"id":"1.168133553","rc":[{"batb":[[0,1.07,14.99],[2,1.04,6]],"ltp":1.47,"tv":16.72,"id":16325787}]}]}
{"op":"mcm","clk":"988963883","pt":1580482690491,"mc":[{"id":"1.168133553","rc":[{"batb":[[0,1.07,11.99]],"ltp":1.47,"tv":16.72,"id":16325787}]}]}
{"op":"mcm","clk":"988963886","pt":1580482690611,"mc":[{"id":"1.168133553","rc":[{"batb":[[0,1.08,3],[1,1.07,11.99],[2,1.06,3]],"ltp":1.47,"tv":16.72,"id":16325787}]}]}
{"op":"mcm","clk":"988965198","pt":1580482712112,"mc":[{"id":"1.168133553","rc":[{"batb":[[0,1.09,1.99],[1,1.08,3],[2,1.07,10]],"ltp":1.47,"tv":16.72,"id":16325787}]}]}
{"op":"mcm","clk":"988965807","pt":1580482721232,"mc":[{"id":"1.168133553","rc":[{"batb":[[0,1.09,4.99],[1,1.07,10],[2,1.06,3]],"ltp":1.47,"tv":16.72,"id":16325787}]}]}
{"op":"mcm","clk":"988966572","pt":1580482731239,"mc":[{"id":"1.168133553","rc":[{"batb":[[0,1.1,3],[1,1.09,1.99],[2,1.07,10]],"ltp":1.47,"tv":16.72,"id":16325787}]}]}
{"op":"mcm","clk":"988967244","pt":1580482739830,"mc":[{"id":"1.168133553","rc":[{"batb":[[2,1.08,3]],"ltp":1.47,"tv":16.72,"id":16325787}]}]}
{"op":"mcm","clk":"988967636","pt":1580482745152,"mc":[{"id":"1.168133553","rc":[{"batb":[[0,1.09,4.99],[1,1.08,3],[2,1.07,10]],"ltp":1.47,"tv":16.72,"id":16325787}]}]}
{"op":"mcm","clk":"988968295","pt":1580482756505,"mc":[{"id":"1.168133553","rc":[{"batb":[[0,1.09,1.99]],"ltp":1.47,"tv":16.72,"id":16325787}]}]}
{"op":"mcm","clk":"988968299","pt":1580482756617,"mc":[{"id":"1.168133553","rc":[{"batb":[[0,1.1,3],[1,1.09,1.99],[2,1.08,3]],"ltp":1.47,"tv":16.72,"id":16325787}]}]}
{"op":"mcm","clk":"988968856","pt":1580482766016,"mc":[{"id":"1.168133553","rc":[{"batb":[[0,1.11,1.99],[1,1.1,3]],"ltp":1.47,"tv":16.72,"id":16325787}]}]}
{"op":"mcm","clk":"988969269","pt":1580482769784,"mc":[{"id":"1.168133553","rc":[{"batb":[[0,1.11,11.99]],"ltp":1.47,"tv":16.72,"id":16325787}]}]}
{"op":"mcm","clk":"988969338","pt":1580482770787,"mc":[{"id":"1.168133553","rc":[{"batb":[[0,1.12,3],[1,1.11,11.99]],"ltp":1.47,"tv":16.72,"id":16325787}]}]}
{"op":"mcm","clk":"988973462","pt":1580482817911,"mc":[{"id":"1.168133553","rc":[{"batb":[[2,1.04,6]],"ltp":1.47,"tv":16.72,"id":16325787}]}]}
{"op":"mcm","clk":"988973725","pt":1580482821309,"mc":[{"id":"1.168133553","rc":[{"batb":[[0,1.13,1.99],[1,1.12,3],[2,1.11,10]],"ltp":1.47,"tv":16.72,"id":16325787}]}]}
{"op":"mcm","clk":"988973900","pt":1580482823803,"mc":[{"id":"1.168133553","rc":[{"batb":[[0,1.13,4.99],[1,1.11,10],[2,1.04,6]],"ltp":1.47,"tv":16.72,"id":16325787}]}]}
{"op":"mcm","clk":"988974430","pt":1580482831737,"mc":[{"id":"1.168133553","rc":[{"batb":[[0,1.14,3],[1,1.13,1.99],[2,1.11,10]],"ltp":1.47,"tv":16.72,"id":16325787}]}]}
{"op":"mcm","clk":"988975172","pt":1580482840144,"mc":[{"id":"1.168133553","rc":[{"batb":[[0,1.13,1.99],[1,1.12,3]],"ltp":1.47,"tv":16.72,"id":16325787}]}]}
{"op":"mcm","clk":"988975942","pt":1580482850250,"mc":[{"id":"1.168133553","rc":[{"batb":[[2,1.04,6]],"ltp":1.47,"tv":16.72,"id":16325787}]}]}
{"op":"mcm","clk":"988975989","pt":1580482851148,"mc":[{"id":"1.168133553","rc":[{"batb":[[0,1.13,4.99],[1,1.04,6],[2,1.03,1628.39]],"ltp":1.47,"tv":16.72,"id":16325787}]}]}
{"op":"mcm","clk":"988977111","pt":1580482864172,"mc":[{"id":"1.168133553","rc":[{"batb":[[0,1.14,3],[1,1.13,1.99],[2,1.04,6]],"ltp":1.47,"tv":16.72,"id":16325787}]}]}
{"op":"mcm","clk":"988978081","pt":1580482873563,"mc":[{"id":"1.168133553","rc":[{"batb":[[0,1.13,1.99],[1,1.05,3]],"ltp":1.47,"tv":16.72,"id":16325787}]}]}
{"op":"mcm","clk":"988979039","pt":1580482884568,"mc":[{"id":"1.168133553","rc":[{"batb":[[1,1.06,3]],"ltp":1.47,"tv":16.72,"id":16325787}]}]}
{"op":"mcm","clk":"988979223","pt":1580482886963,"mc":[{"id":"1.168133553","rc":[{"batb":[[0,1.07,1.99]],"ltp":1.47,"tv":16.72,"id":16325787}]}]}
{"op":"mcm","clk":"988980097","pt":1580482895878,"mc":[{"id":"1.168133553","rc":[{"batb":[[0,1.07,4.99],[1,1.04,6],[2,1.03,1628.39]],"ltp":1.47,"tv":16.72,"id":16325787}]}]}
{"op":"mcm","clk":"988980854","pt":1580482906363,"mc":[{"id":"1.168133553","rc":[{"batb":[[0,1.08,3],[1,1.07,1.99],[2,1.04,6]],"ltp":1.47,"tv":16.72,"id":16325787}]}]}
{"op":"mcm","clk":"988981673","pt":1580482917799,"mc":[{"id":"1.168133553","rc":[{"batb":[[0,1.07,1.99],[1,1.05,3]],"ltp":1.47,"tv":16.72,"id":16325787}]}]}
{"op":"mcm","clk":"988982477","pt":1580482929079,"mc":[{"id":"1.168133553","rc":[{"batb":[[1,1.06,3]],"ltp":1.47,"tv":16.72,"id":16325787}]}]}
{"op":"mcm","clk":"988983262","pt":1580482939821,"mc":[{"id":"1.168133553","rc":[{"batb":[[0,1.07,4.99],[1,1.04,6],[2,1.03,1628.39]],"ltp":1.47,"tv":16.72,"id":16325787}]}]}
{"op":"mcm","clk":"988983845","pt":1580482950738,"mc":[{"id":"1.168133553","rc":[{"batb":[[0,1.08,3],[1,1.07,1.99],[2,1.04,6]],"ltp":1.47,"tv":16.72,"id":16325787}]}]}
{"op":"mcm","clk":"988984458","pt":1580482961845,"mc":[{"id":"1.168133553","rc":[{"batb":[[0,1.07,1.99],[1,1.05,3]],"ltp":1.47,"tv":16.72,"id":16325787}]}]}
{"op":"mcm","clk":"988986069","pt":1580482975362,"mc":[{"id":"1.168133553","rc":[{"batb":[[1,1.06,3]],"ltp":1.47,"tv":16.72,"id":16325787}]}]}
{"op":"mcm","clk":"988986644","pt":1580482986504,"mc":[{"id":"1.168133553","rc":[{"batb":[[0,1.07,4.99],[1,1.04,6],[2,1.03,1628.39]],"ltp":1.47,"tv":16.72,"id":16325787}]}]}
{"op":"mcm","clk":"988987448","pt":1580482999547,"mc":[{"id":"1.168133553","rc":[{"batb":[[0,1.07,1.99]],"ltp":1.47,"tv":16.72,"id":16325787}]}]}
{"op":"mcm","clk":"988987454","pt":1580482999650,"mc":[{"id":"1.168133553","rc":[{"batb":[[0,1.08,3],[1,1.07,1.99],[2,1.04,6]],"ltp":1.47,"tv":16.72,"id":16325787}]}]}
{"op":"mcm","clk":"988988130","pt":1580483010072,"mc":[{"id":"1.168133553","rc":[{"batb":[[0,1.07,1.99],[1,1.05,3]],"ltp":1.47,"tv":16.72,"id":16325787}]}]}
{"op":"mcm","clk":"988989099","pt":1580483021671,"mc":[{"id":"1.168133553","rc":[{"batb":[[1,1.06,3]],"ltp":1.47,"tv":16.72,"id":16325787}]}]}
{"op":"mcm","clk":"988989773","pt":1580483030390,"mc":[{"id":"1.168133553","rc":[{"batb":[[0,1.07,4.99],[1,1.04,6],[2,1.03,1628.39]],"ltp":1.47,"tv":16.72,"id":16325787}]}]}
{"op":"mcm","clk":"988990999","pt":1580483043998,"mc":[{"id":"1.168133553","rc":[{"batb":[[0,1.08,3],[1,1.07,1.99],[2,1.04,6]],"ltp":1.47,"tv":16.72,"id":16325787}]}]}
{"op":"mcm","clk":"988991808","pt":1580483053718,"mc":[{"id":"1.168133553","rc":[{"batb":[[0,1.07,1.99],[1,1.05,3]],"ltp":1.47,"tv":16.72,"id":16325787}]}]}
{"op":"mcm","clk":"988992956","pt":1580483065972,"mc":[{"id":"1.168133553","rc":[{"batb":[[1,1.06,3]],"ltp":1.47,"tv":16.72,"id":16325787}]}]}
{"op":"mcm","clk":"988993956","pt":1580483077508,"mc":[{"id":"1.168133553","rc":[{"batb":[[0,1.07,4.99],[1,1.04,6],[2,1.03,1628.39]],"ltp":1.47,"tv":16.72,"id":16325787}]}]}
{"op":"mcm","clk":"988994852","pt":1580483089031,"mc":[{"id":"1.168133553","rc":[{"batb":[[0,1.08,3],[1,1.07,1.99],[2,1.04,6]],"ltp":1.47,"tv":16.72,"id":16325787}]}]}
{"op":"mcm","clk":"988996575","pt":1580483106352,"mc":[{"id":"1.168133553","rc":[{"batb":[[0,1.07,1.99],[1,1.05,3]],"ltp":1.47,"tv":16.72,"id":16325787}]}]}
{"op":"mcm","clk":"988997584","pt":1580483119283,"mc":[{"id":"1.168133553","rc":[{"batb":[[1,1.06,3]],"ltp":1.47,"tv":16.72,"id":16325787}]}]}
{"op":"mcm","clk":"988998579","pt":1580483130524,"mc":[{"id":"1.168133553","rc":[{"batb":[[0,1.07,4.99],[1,1.04,6],[2,1.03,1628.39]],"ltp":1.47,"tv":16.72,"id":16325787}]}]}
{"op":"mcm","clk":"988999428","pt":1580483140013,"mc":[{"id":"1.168133553","rc":[{"batb":[[0,1.08,3],[1,1.07,1.99],[2,1.04,6]],"ltp":1.47,"tv":16.72,"id":16325787}]}]}
{"op":"mcm","clk":"989000170","pt":1580483150347,"mc":[{"id":"1.168133553","rc":[{"batb":[[0,1.07,1.99],[1,1.05,3]],"ltp":1.47,"tv":16.72,"id":16325787}]}]}
{"op":"mcm","clk":"989001632","pt":1580483164401,"mc":[{"id":"1.168133553","rc":[{"batb":[[1,1.06,3]],"ltp":1.47,"tv":16.72,"id":16325787}]}]}
{"op":"mcm","clk":"989001904","pt":1580483167531,"mc":[{"id":"1.168133553","rc":[{"batb":[[0,1.07,11.99]],"ltp":1.47,"tv":16.72,"id":16325787}]}]}
{"op":"mcm","clk":"989002714","pt":1580483176012,"mc":[{"id":"1.168133553","rc":[{"batb":[[0,1.08,3],[1,1.07,11.99]],"ltp":1.47,"tv":16.72,"id":16325787}]}]}
{"op":"mcm","clk":"989003299","pt":1580483182925,"mc":[{"id":"1.168133553","rc":[{"batb":[[0,1.09,1.99],[1,1.08,3],[2,1.07,10]],"ltp":1.47,"tv":16.72,"id":16325787}]}]}
{"op":"mcm","clk":"989003641","pt":1580483187485,"mc":[{"id":"1.168133553","rc":[{"batb":[[0,1.09,4.99],[1,1.07,10],[2,1.04,6]],"ltp":1.47,"tv":16.72,"id":16325787}]}]}
{"op":"mcm","clk":"989004509","pt":1580483198283,"mc":[{"id":"1.168133553","rc":[{"batb":[[0,1.1,3],[1,1.09,1.99],[2,1.07,10]],"ltp":1.47,"tv":16.72,"id":16325787}]}]}
{"op":"mcm","clk":"989005338","pt":1580483208853,"mc":[{"id":"1.168133553","rc":[{"batb":[[0,1.09,1.99],[1,1.08,3]],"ltp":1.47,"tv":16.72,"id":16325787}]}]}
{"op":"mcm","clk":"989006310","pt":1580483221568,"mc":[{"id":"1.168133553","rc":[{"batb":[[0,1.09,4.99],[1,1.07,10],[2,1.04,6]],"ltp":1.47,"tv":16.72,"id":16325787}]}]}
{"op":"mcm","clk":"989007074","pt":1580483230345,"mc":[{"id":"1.168133553","rc":[{"batb":[[0,1.1,3],[1,1.09,1.99],[2,1.07,10]],"ltp":1.47,"tv":16.72,"id":16325787}]}]}
{"op":"mcm","clk":"989007247","pt":1580483232748,"mc":[{"id":"1.168133553","rc":[{"batb":[[0,1.11,1.99],[1,1.1,3]],"ltp":1.47,"tv":16.72,"id":16325787}]}]}
{"op":"mcm","clk":"989007921","pt":1580483242396,"mc":[{"id":"1.168133553","rc":[{"batb":[[2,1.04,6]],"ltp":1.47,"tv":16.72,"id":16325787}]}]}
{"op":"mcm","clk":"989007951","pt":1580483242815,"mc":[{"id":"1.168133553","rc":[{"batb":[[0,1.11,14.99],[1,1.04,6],[2,1.03,1628.39]],"ltp":1.47,"tv":16.72,"id":16325787}]}]}
{"op":"mcm","clk":"989017653","pt":1580483256545,"mc":[{"id":"1.168133553","rc":[{"batb":[[0,1.11,11.99]],"ltp":1.47,"tv":16.72,"id":16325787}]}]}
{"op":"mcm","clk":"989017658","pt":1580483256665,"mc":[{"id":"1.168133553","rc":[{"batb":[[0,1.12,3],[1,1.11,11.99],[2,1.04,6]],"ltp":1.47,"tv":16.72,"id":16325787}]}]}
{"op":"mcm","clk":"989019298","pt":1580483281065,"mc":[{"id":"1.168133553","rc":[{"batb":[[0,1.13,1.99],[1,1.12,3],[2,1.11,10]],"ltp":1.47,"tv":16.72,"id":16325787}]}]}
{"op":"mcm","clk":"989019951","pt":1580483290284,"mc":[{"id":"1.168133553","rc":[{"batb":[[0,1.13,4.99],[1,1.11,10],[2,1.04,6]],"ltp":1.47,"tv":16.72,"id":16325787}]}]}
{"op":"mcm","clk":"989021224","pt":1580483308051,"mc":[{"id":"1.168133553","rc":[{"batb":[[0,1.14,3],[1,1.13,1.99],[2,1.11,10]],"ltp":1.47,"tv":16.72,"id":16325787}]}]}
{"op":"mcm","clk":"989022192","pt":1580483321742,"mc":[{"id":"1.168133553","rc":[{"batb":[[2,1.04,6]],"ltp":1.47,"tv":16.72,"id":16325787}]}]}
{"op":"mcm","clk":"989022303","pt":1580483323260,"mc":[{"id":"1.168133553","rc":[{"batb":[[0,1.13,1.99],[1,1.05,3]],"ltp":1.47,"tv":16.72,"id":16325787}]}]}
{"op":"mcm","clk":"989022916","pt":1580483331290,"mc":[{"id":"1.168133553","rc":[{"batb":[[0,1.06,1.99]],"ltp":1.47,"tv":16.72,"id":16325787}]}]}
{"op":"mcm","clk":"989023262","pt":1580483335998,"mc":[{"id":"1.168133553","rc":[{"batb":[[0,1.06,4.99],[1,1.04,6],[2,1.03,1628.39]],"ltp":1.47,"tv":16.72,"id":16325787}]}]}
{"op":"mcm","clk":"989024522","pt":1580483353283,"mc":[{"id":"1.168133553","rc":[{"batb":[[0,1.07,3],[1,1.06,1.99],[2,1.04,6]],"ltp":1.47,"tv":16.72,"id":16325787}]}]}
{"op":"mcm","clk":"989025528","pt":1580483367236,"mc":[{"id":"1.168133553","rc":[{"batb":[[0,1.06,1.99],[1,1.05,3]],"ltp":1.47,"tv":16.72,"id":16325787}]}]}
{"op":"mcm","clk":"989026151","pt":1580483376920,"mc":[{"id":"1.168133553","rc":[{"batb":[[0,1.06,4.99],[1,1.04,6],[2,1.03,1628.39]],"ltp":1.47,"tv":16.72,"id":16325787}]}]}
{"op":"mcm","clk":"989026851","pt":1580483387527,"mc":[{"id":"1.168133553","rc":[{"batb":[[0,1.06,1.99]],"ltp":1.47,"tv":16.72,"id":16325787}]}]}
{"op":"mcm","clk":"989026859","pt":1580483387631,"mc":[{"id":"1.168133553","rc":[{"batb":[[0,1.07,3],[1,1.06,1.99],[2,1.04,6]],"ltp":1.47,"tv":16.72,"id":16325787}]}]}
{"op":"mcm","clk":"989027052","pt":1580483390543,"mc":[{"id":"1.168133553","rc":[{"batb":[[1,1.04,6],[2,1.03,1628.39]],"ltp":1.47,"tv":16.72,"id":16325787}]}]}
{"op":"mcm","clk":"989027064","pt":1580483390646,"mc":[{"id":"1.168133553","rc":[{"batb":[[0,1.08,1.99],[1,1.07,3],[2,1.04,6]],"ltp":1.47,"tv":16.72,"id":16325787}]}]}
{"op":"mcm","clk":"989027724","pt":1580483400447,"mc":[{"id":"1.168133553","rc":[{"batb":[[0,1.08,4.99],[1,1.04,6],[2,1.03,1628.39]],"ltp":1.47,"tv":16.72,"id":16325787}]}]}
{"op":"mcm","clk":"989028860","pt":1580483414458,"mc":[{"id":"1.168133553","rc":[{"batb":[[0,1.09,3],[1,1.08,1.99],[2,1.04,6]],"ltp":1.47,"tv":16.72,"id":16325787}]}]}
{"op":"mcm","clk":"989029844","pt":1580483428224,"mc":[{"id":"1.168133553","rc":[{"batb":[[0,1.08,1.99],[1,1.05,3]],"ltp":1.47,"tv":16.72,"id":16325787}]}]}
{"op":"mcm","clk":"989030553","pt":1580483438129,"mc":[{"id":"1.168133553","rc":[{"batb":[[0,1.06,1.99]],"ltp":1.47,"tv":16.72,"id":16325787}]}]}
{"op":"mcm","clk":"989030802","pt":1580483441926,"mc":[{"id":"1.168133553","rc":[{"batb":[[0,1.06,4.99],[1,1.04,6],[2,1.03,1628.39]],"ltp":1.47,"tv":16.72,"id":16325787}]}]}
{"op":"mcm","clk":"989031693","pt":1580483452870,"mc":[{"id":"1.168133553","rc":[{"batb":[[0,1.07,3],[1,1.06,1.99],[2,1.04,6]],"ltp":1.47,"tv":16.72,"id":16325787}]}]}
{"op":"mcm","clk":"989033028","pt":1580483470018,"mc":[{"id":"1.168133553","rc":[{"batb":[[0,1.06,1.99],[1,1.05,3]],"ltp":1.47,"tv":16.72,"id":16325787}]}]}
{"op":"mcm","clk":"989033955","pt":1580483482299,"mc":[{"id":"1.168133553","rc":[{"batb":[[0,1.06,4.99],[1,1.04,6],[2,1.03,1628.39]],"ltp":1.47,"tv":16.72,"id":16325787}]}]}
{"op":"mcm","clk":"989034742","pt":1580483492526,"mc":[{"id":"1.168133553","rc":[{"batb":[[0,1.06,1.99]],"ltp":1.47,"tv":16.72,"id":16325787}]}]}
{"op":"mcm","clk":"989034749","pt":1580483492628,"mc":[{"id":"1.168133553","rc":[{"batb":[[0,1.07,3],[1,1.06,1.99],[2,1.04,6]],"ltp":1.47,"tv":16.72,"id":16325787}]}]}
{"op":"mcm","clk":"989035439","pt":1580483501951,"mc":[{"id":"1.168133553","rc":[{"batb":[[0,1.06,1.99],[1,1.05,3]],"ltp":1.47,"tv":16.72,"id":16325787}]}]}
{"op":"mcm","clk":"989036322","pt":1580483514364,"mc":[{"id":"1.168133553","rc":[{"batb":[[0,1.06,4.99],[1,1.04,6],[2,1.03,1628.39]],"ltp":1.47,"tv":16.72,"id":16325787}]}]}
{"op":"mcm","clk":"989037105","pt":1580483525795,"mc":[{"id":"1.168133553","rc":[{"batb":[[0,1.07,3],[1,1.06,1.99],[2,1.04,6]],"ltp":1.47,"tv":16.72,"id":16325787}]}]}
{"op":"mcm","clk":"989037807","pt":1580483535486,"mc":[{"id":"1.168133553","rc":[{"batb":[[0,1.06,1.99],[1,1.05,3]],"ltp":1.47,"tv":16.72,"id":16325787}]}]}
{"op":"mcm","clk":"989038554","pt":1580483546192,"mc":[{"id":"1.168133553","rc":[{"batb":[[0,1.06,4.99],[1,1.04,6],[2,1.03,1628.39]],"ltp":1.47,"tv":16.72,"id":16325787}]}]}
{"op":"mcm","clk":"989039235","pt":1580483555820,"mc":[{"id":"1.168133553","rc":[{"batb":[[0,1.07,3],[1,1.06,1.99],[2,1.04,6]],"ltp":1.47,"tv":16.72,"id":16325787}]}]}
{"op":"mcm","clk":"989039744","pt":1580483563417,"mc":[{"id":"1.168133553","rc":[{"batb":[[0,1.06,1.99],[1,1.05,3]],"ltp":1.47,"tv":16.72,"id":16325787}]}]}
{"op":"mcm","clk":"989040478","pt":1580483574501,"mc":[{"id":"1.168133553","rc":[{"batb":[[0,1.06,4.99],[1,1.04,6],[2,1.03,1628.39]],"ltp":1.47,"tv":16.72,"id":16325787}]}]}
{"op":"mcm","clk":"989041490","pt":1580483588426,"mc":[{"id":"1.168133553","rc":[{"batb":[[0,1.07,3],[1,1.06,1.99],[2,1.04,6]],"ltp":1.47,"tv":16.72,"id":16325787}]}]}
{"op":"mcm","clk":"989041685","pt":1580483590936,"mc":[{"id":"1.168133553","rc":[{"batb":[[0,1.08,1.99],[1,1.07,3]],"ltp":1.47,"tv":16.72,"id":16325787}]}]}
{"op":"mcm","clk":"989042266","pt":1580483599039,"mc":[{"id":"1.168133553","rc":[{"batb":[[0,1.08,4.99],[1,1.04,6],[2,1.03,1628.39]],"ltp":1.47,"tv":16.72,"id":16325787}]}]}
{"op":"mcm","clk":"989043058","pt":1580483609562,"mc":[{"id":"1.168133553","rc":[{"batb":[[0,1.08,1.99]],"ltp":1.47,"tv":16.72,"id":16325787}]}]}
{"op":"mcm","clk":"989043072","pt":1580483609666,"mc":[{"id":"1.168133553","rc":[{"batb":[[0,1.09,3],[1,1.08,1.99],[2,1.04,6]],"ltp":1.47,"tv":16.72,"id":16325787}]}]}
{"op":"mcm","clk":"989043832","pt":1580483620274,"mc":[{"id":"1.168133553","rc":[{"batb":[[0,1.08,1.99],[1,1.05,3]],"ltp":1.47,"tv":16.72,"id":16325787}]}]}
{"op":"mcm","clk":"989044758","pt":1580483633007,"mc":[{"id":"1.168133553","rc":[{"batb":[[1,1.06,3]],"ltp":1.47,"tv":16.72,"id":16325787}]}]}
{"op":"mcm","clk":"989045047","pt":1580483637333,"mc":[{"id":"1.168133553","rc":[{"batb":[[0,1.07,1.99]],"ltp":1.47,"tv":16.72,"id":16325787}]}]}
{"op":"mcm","clk":"989045830","pt":1580483647425,"mc":[{"id":"1.168133553","rc":[{"batb":[[0,1.07,4.99],[1,1.04,6],[2,1.03,1628.39]],"ltp":1.47,"tv":16.72,"id":16325787}]}]}
{"op":"mcm","clk":"989046598","pt":1580483657731,"mc":[{"id":"1.168133553","rc":[{"batb":[[0,1.08,3],[1,1.07,1.99],[2,1.04,6]],"ltp":1.47,"tv":16.72,"id":16325787}]}]}
{"op":"mcm","clk":"989047397","pt":1580483668446,"mc":[{"id":"1.168133553","rc":[{"batb":[[0,1.07,1.99],[1,1.05,3]],"ltp":1.47,"tv":16.72,"id":16325787}]}]}
{"op":"mcm","clk":"989047968","pt":1580483676572,"mc":[{"id":"1.168133553","rc":[{"batb":[[1,1.06,3]],"ltp":1.47,"tv":16.72,"id":16325787}]}]}
{"op":"mcm","clk":"989048551","pt":1580483685317,"mc":[{"id":"1.168133553","rc":[{"batb":[[0,1.07,4.99],[1,1.04,6],[2,1.03,1628.39]],"ltp":1.47,"tv":16.72,"id":16325787}]}]}
{"op":"mcm","clk":"989049244","pt":1580483695200,"mc":[{"id":"1.168133553","rc":[{"batb":[[0,1.08,3],[1,1.07,1.99],[2,1.04,6]],"ltp":1.47,"tv":16.72,"id":16325787}]}]}
{"op":"mcm","clk":"989049902","pt":1580483704144,"mc":[{"id":"1.168133553","rc":[{"batb":[[0,1.07,1.99],[1,1.05,3]],"ltp":1.47,"tv":16.72,"id":16325787}]}]}
{"op":"mcm","clk":"989050630","pt":1580483713928,"mc":[{"id":"1.168133553","rc":[{"batb":[[1,1.06,3]],"ltp":1.47,"tv":16.72,"id":16325787}]}]}
{"op":"mcm","clk":"989051586","pt":1580483727946,"mc":[{"id":"1.168133553","rc":[{"batb":[[0,1.07,4.99],[1,1.04,6],[2,1.03,1628.39]],"ltp":1.47,"tv":16.72,"id":16325787}]}]}
{"op":"mcm","clk":"989052341","pt":1580483738555,"mc":[{"id":"1.168133553","rc":[{"batb":[[0,1.07,1.99]],"ltp":1.47,"tv":16.72,"id":16325787}]}]}
{"op":"mcm","clk":"989052346","pt":1580483738656,"mc":[{"id":"1.168133553","rc":[{"batb":[[0,1.08,3],[1,1.07,1.99],[2,1.04,6]],"ltp":1.47,"tv":16.72,"id":16325787}]}]}
{"op":"mcm","clk":"989052963","pt":1580483747294,"mc":[{"id":"1.168133553","rc":[{"batb":[[0,1.07,1.99],[1,1.05,3]],"ltp":1.47,"tv":16.72,"id":16325787}]}]}
{"op":"mcm","clk":"989053954","pt":1580483759770,"mc":[{"id":"1.168133553","rc":[{"batb":[[1,1.06,3]],"ltp":1.47,"tv":16.72,"id":16325787}]}]}
{"op":"mcm","clk":"989054710","pt":1580483769684,"mc":[{"id":"1.168133553","rc":[{"batb":[[0,1.07,4.99],[1,1.04,6],[2,1.03,1628.39]],"ltp":1.47,"tv":16.72,"id":16325787}]}]}
{"op":"mcm","clk":"989055480","pt":1580483779500,"mc":[{"id":"1.168133553","rc":[{"batb":[[0,1.07,1.99]],"ltp":1.47,"tv":16.72,"id":16325787}]}]}
{"op":"mcm","clk":"989055486","pt":1580483779606,"mc":[{"id":"1.168133553","rc":[{"batb":[[0,1.08,3],[1,1.07,1.99],[2,1.04,6]],"ltp":1.47,"tv":16.72,"id":16325787}]}]}
{"op":"mcm","clk":"989055660","pt":1580483782076,"mc":[{"id":"1.168133553","rc":[{"batb":[[0,1.08,13]],"ltp":1.47,"tv":16.72,"id":16325787}]}]}
{"op":"mcm","clk":"989055738","pt":1580483783374,"mc":[{"id":"1.168133553","rc":[{"batb":[[0,1.09,1.99],[1,1.08,13]],"ltp":1.47,"tv":16.72,"id":16325787}]}]}
{"op":"mcm","clk":"989056145","pt":1580483788806,"mc":[{"id":"1.168133553","rc":[{"batb":[[0,1.09,4.99],[1,1.08,10]],"ltp":1.47,"tv":16.72,"id":16325787}]}]}
{"op":"mcm","clk":"989056873","pt":1580483799226,"mc":[{"id":"1.168133553","rc":[{"batb":[[0,1.1,3],[1,1.09,1.99],[2,1.08,10]],"ltp":1.47,"tv":16.72,"id":16325787}]}]}
{"op":"mcm","clk":"989057625","pt":1580483809310,"mc":[{"id":"1.168133553","rc":[{"batb":[[0,1.09,4.99],[1,1.08,10],[2,1.04,6]],"ltp":1.47,"tv":16.72,"id":16325787}]}]}
{"op":"mcm","clk":"989058451","pt":1580483820337,"mc":[{"id":"1.168133553","rc":[{"batb":[[0,1.1,3],[1,1.09,1.99],[2,1.08,10]],"ltp":1.47,"tv":16.72,"id":16325787}]}]}
{"op":"mcm","clk":"989059152","pt":1580483828943,"mc":[{"id":"1.168133553","rc":[{"batb":[[0,1.09,4.99],[1,1.08,10],[2,1.04,6]],"ltp":1.47,"tv":16.72,"id":16325787}]}]}
{"op":"mcm","clk":"989060131","pt":1580483841252,"mc":[{"id":"1.168133553","rc":[{"batb":[[0,1.1,3],[1,1.09,1.99],[2,1.08,10]],"ltp":1.47,"tv":16.72,"id":16325787}]}]}
{"op":"mcm","clk":"989060841","pt":1580483850461,"mc":[{"id":"1.168133553","rc":[{"batb":[[0,1.09,4.99],[1,1.08,10],[2,1.04,6]],"ltp":1.47,"tv":16.72,"id":16325787}]}]}
{"op":"mcm","clk":"989061485","pt":1580483857870,"mc":[{"id":"1.168133553","rc":[{"batb":[[1,1.05,10]],"ltp":1.47,"tv":16.72,"id":16325787}]}]}
{"op":"mcm","clk":"989061630","pt":1580483859792,"mc":[{"id":"1.168133553","rc":[{"batb":[[0,1.1,3],[1,1.09,1.99],[2,1.05,10]],"ltp":1.47,"tv":16.72,"id":16325787}]}]}
{"op":"mcm","clk":"989062444","pt":1580483869901,"mc":[{"id":"1.168133553","rc":[{"batb":[[0,1.09,1.99],[1,1.06,3]],"ltp":1.47,"tv":16.72,"id":16325787}]}]}
{"op":"mcm","clk":"989063370","pt":1580483880883,"mc":[{"id":"1.168133553","rc":[{"batb":[[1,1.07,3]],"ltp":1.47,"tv":16.72,"id":16325787}]}]}
{"op":"mcm","clk":"989064269","pt":1580483892507,"mc":[{"id":"1.168133553","rc":[{"batb":[[0,1.08,1.99],[1,1.05,10],[2,1.04,6]],"ltp":1.47,"tv":16.72,"id":16325787}]}]}
{"op":"mcm","clk":"989064281","pt":1580483892613,"mc":[{"id":"1.168133553","rc":[{"batb":[[0,1.08,4.99]],"ltp":1.47,"tv":16.72,"id":16325787}]}]}
{"op":"mcm","clk":"989064991","pt":1580483901120,"mc":[{"id":"1.168133553","rc":[{"batb":[[0,1.09,3],[1,1.08,1.99],[2,1.05,10]],"ltp":1.47,"tv":16.72,"id":16325787}]}]}
{"op":"mcm","clk":"989065743","pt":1580483909833,"mc":[{"id":"1.168133553","rc":[{"batb":[[0,1.08,1.99],[1,1.06,3]],"ltp":1.47,"tv":16.72,"id":16325787}]}]}
{"op":"mcm","clk":"989066709","pt":1580483920733,"mc":[{"id":"1.168133553","rc":[{"batb":[[1,1.07,3]],"ltp":1.47,"tv":16.72,"id":16325787}]}]}
{"op":"mcm","clk":"989067494","pt":1580483930243,"mc":[{"id":"1.168133553","rc":[{"batb":[[0,1.08,4.99],[1,1.05,10],[2,1.04,6]],"ltp":1.47,"tv":16.72,"id":16325787}]}]}
{"op":"mcm","clk":"989068528","pt":1580483942748,"mc":[{"id":"1.168133553","rc":[{"batb":[[0,1.09,3],[1,1.08,1.99],[2,1.05,10]],"ltp":1.47,"tv":16.72,"id":16325787}]}]}
{"op":"mcm","clk":"989069242","pt":1580483951393,"mc":[{"id":"1.168133553","rc":[{"batb":[[0,1.1,1.99],[1,1.09,3]],"ltp":1.47,"tv":16.72,"id":16325787}]}]}
{"op":"mcm","clk":"989069970","pt":1580483960475,"mc":[{"id":"1.168133553","rc":[{"batb":[[1,1.05,10],[2,1.04,6]],"ltp":1.47,"tv":16.72,"id":16325787}]}]}
{"op":"mcm","clk":"989069980","pt":1580483960582,"mc":[{"id":"1.168133553","rc":[{"batb":[[0,1.1,4.99]],"ltp":1.47,"tv":16.72,"id":16325787}]}]}
{"op":"mcm","clk":"989070780","pt":1580483972737,"mc":[{"id":"1.168133553","rc":[{"batb":[[0,1.11,3],[1,1.1,1.99],[2,1.05,10]],"ltp":1.47,"tv":16.72,"id":16325787}]}]}
{"op":"mcm","clk":"989071580","pt":1580483984039,"mc":[{"id":"1.168133553","rc":[{"batb":[[0,1.1,1.99],[1,1.06,3]],"ltp":1.47,"tv":16.72,"id":16325787}]}]}
{"op":"mcm","clk":"989072268","pt":1580483993527,"mc":[{"id":"1.168133553","rc":[{"batb":[[1,1.07,3]],"ltp":1.47,"tv":16.72,"id":16325787}]}]}
{"op":"mcm","clk":"989072938","pt":1580484003541,"mc":[{"id":"1.168133553","rc":[{"batb":[[1,1.08,3]],"ltp":1.47,"tv":16.72,"id":16325787}]}]}
{"op":"mcm","clk":"989072994","pt":1580484004479,"mc":[{"id":"1.168133553","rc":[{"batb":[[0,1.09,1.99]],"ltp":1.47,"tv":16.72,"id":16325787}]}]}
{"op":"mcm","clk":"989073269","pt":1580484008586,"mc":[{"id":"1.168133553","rc":[{"batb":[[2,1.04,6]],"ltp":1.47,"tv":16.72,"id":16325787}]}]}
{"op":"mcm","clk":"989073874","pt":1580484016297,"mc":[{"id":"1.168133553","rc":[{"batb":[[0,1.09,4.99],[1,1.04,6],[2,1.03,1628.39]],"ltp":1.47,"tv":16.72,"id":16325787}]}]}
{"op":"mcm","clk":"989074859","pt":1580484029390,"mc":[{"id":"1.168133553","rc":[{"batb":[[0,1.1,3],[1,1.09,1.99],[2,1.04,6]],"ltp":1.47,"tv":16.72,"id":16325787}]}]}
{"op":"mcm","clk":"989075476","pt":1580484037878,"mc":[{"id":"1.168133553","rc":[{"batb":[[0,1.09,1.99],[1,1.05,3]],"ltp":1.47,"tv":16.72,"id":16325787}]}]}
{"op":"mcm","clk":"989076262","pt":1580484048401,"mc":[{"id":"1.168133553","rc":[{"batb":[[1,1.06,3]],"ltp":1.47,"tv":16.72,"id":16325787}]}]}
{"op":"mcm","clk":"989077169","pt":1580484058905,"mc":[{"id":"1.168133553","rc":[{"batb":[[1,1.07,3]],"ltp":1.47,"tv":16.72,"id":16325787}]}]}
{"op":"mcm","clk":"989077378","pt":1580484061320,"mc":[{"id":"1.168133553","rc":[{"batb":[[0,1.08,1.99]],"ltp":1.47,"tv":16.72,"id":16325787}]}]}
{"op":"mcm","clk":"989078069","pt":1580484069730,"mc":[{"id":"1.168133553","rc":[{"batb":[[0,1.08,4.99],[1,1.04,6],[2,1.03,1628.39]],"ltp":1.47,"tv":16.72,"id":16325787}]}]}
{"op":"mcm","clk":"989078760","pt":1580484078864,"mc":[{"id":"1.168133553","rc":[{"batb":[[0,1.09,3],[1,1.08,1.99],[2,1.04,6]],"ltp":1.47,"tv":16.72,"id":16325787}]}]}
{"op":"mcm","clk":"989079529","pt":1580484088058,"mc":[{"id":"1.168133553","rc":[{"batb":[[0,1.08,1.99],[1,1.05,3]],"ltp":1.47,"tv":16.72,"id":16325787}]}]}
{"op":"mcm","clk":"989080477","pt":1580484099840,"mc":[{"id":"1.168133553","rc":[{"batb":[[1,1.06,3]],"ltp":1.47,"tv":16.72,"id":16325787}]}]}
{"op":"mcm","clk":"989081414","pt":1580484111192,"mc":[{"id":"1.168133553","rc":[{"batb":[[1,1.07,3]],"ltp":1.47,"tv":16.72,"id":16325787}]}]}
{"op":"mcm","clk":"989082328","pt":1580484122298,"mc":[{"id":"1.168133553","rc":[{"batb":[[0,1.08,4.99],[1,1.04,6],[2,1.03,1628.39]],"ltp":1.47,"tv":16.72,"id":16325787}]}]}
{"op":"mcm","clk":"989083195","pt":1580484133530,"mc":[{"id":"1.168133553","rc":[{"batb":[[0,1.09,3],[1,1.08,1.99],[2,1.04,6]],"ltp":1.47,"tv":16.72,"id":16325787}]}]}
{"op":"mcm","clk":"989083833","pt":1580484142247,"mc":[{"id":"1.168133553","rc":[{"batb":[[0,1.08,1.99],[1,1.05,3]],"ltp":1.47,"tv":16.72,"id":16325787}]}]}
{"op":"mcm","clk":"989093269","pt":1580484152274,"mc":[{"id":"1.168133553","rc":[{"batb":[[1,1.06,3]],"ltp":1.47,"tv":16.72,"id":16325787}]}]}
{"op":"mcm","clk":"989093753","pt":1580484158152,"mc":[{"id":"1.168133553","rc":[{"batb":[[1,1.07,10],[2,1.06,3]],"ltp":1.47,"tv":16.72,"id":16325787}]}]}
{"op":"mcm","clk":"989093933","pt":1580484160562,"mc":[{"id":"1.168133553","rc":[{"batb":[[2,1.04,6]],"ltp":1.47,"tv":16.72,"id":16325787}]}]}
{"op":"mcm","clk":"989093941","pt":1580484160659,"mc":[{"id":"1.168133553","rc":[{"batb":[[0,1.08,4.99]],"ltp":1.47,"tv":16.72,"id":16325787}]}]}
{"op":"mcm","clk":"989095013","pt":1580484173271,"mc":[{"id":"1.168133553","rc":[{"batb":[[0,1.09,3],[1,1.08,1.99],[2,1.07,10]],"ltp":1.47,"tv":16.72,"id":16325787}]}]}
{"op":"mcm","clk":"989095843","pt":1580484183469,"mc":[{"id":"1.168133553","rc":[{"batb":[[0,1.08,4.99],[1,1.07,10],[2,1.04,6]],"ltp":1.47,"tv":16.72,"id":16325787}]}]}
{"op":"mcm","clk":"989096566","pt":1580484193369,"mc":[{"id":"1.168133553","rc":[{"batb":[[0,1.09,3],[1,1.08,1.99],[2,1.07,10]],"ltp":1.47,"tv":16.72,"id":16325787}]}]}
{"op":"mcm","clk":"989097263","pt":1580484202569,"mc":[{"id":"1.168133553","rc":[{"batb":[[0,1.08,1.99],[1,1.07,10],[2,1.04,6]],"ltp":1.47,"tv":16.72,"id":16325787}]}]}
{"op":"mcm","clk":"989097270","pt":1580484202673,"mc":[{"id":"1.168133553","rc":[{"batb":[[0,1.08,4.99]],"ltp":1.47,"tv":16.72,"id":16325787}]}]}
{"op":"mcm","clk":"989097950","pt":1580484211477,"mc":[{"id":"1.168133553","rc":[{"batb":[[0,1.09,3],[1,1.08,1.99],[2,1.07,10]],"ltp":1.47,"tv":16.72,"id":16325787}]}]}
{"op":"mcm","clk":"989098444","pt":1580484218064,"mc":[{"id":"1.168133553","rc":[{"batb":[[0,1.1,1.99],[1,1.09,3]],"ltp":1.47,"tv":16.72,"id":16325787}]}]}
{"op":"mcm","clk":"989098768","pt":1580484222001,"mc":[{"id":"1.168133553","rc":[{"batb":[[0,1.1,4.99],[1,1.07,10],[2,1.04,6]],"ltp":1.47,"tv":16.72,"id":16325787}]}]}
{"op":"mcm","clk":"989099460","pt":1580484230568,"mc":[{"id":"1.168133553","rc":[{"batb":[[0,1.1,1.99]],"ltp":1.47,"tv":16.72,"id":16325787}]}]}
{"op":"mcm","clk":"989099474","pt":1580484230690,"mc":[{"id":"1.168133553","rc":[{"batb":[[0,1.11,3],[1,1.1,1.99],[2,1.07,10]],"ltp":1.47,"tv":16.72,"id":16325787}]}]}
{"op":"mcm","clk":"989099637","pt":1580484232696,"mc":[{"id":"1.168133553","rc":[{"batb":[[0,1.11,13],[2,1.04,6]],"ltp":1.47,"tv":16.72,"id":16325787}]}]}
{"op":"mcm","clk":"989100250","pt":1580484240994,"mc":[{"id":"1.168133553","rc":[{"batb":[[0,1.12,3],[1,1.11,10],[2,1.1,1.99]],"ltp":1.47,"tv":16.72,"id":16325787}]}]}
{"op":"mcm","clk":"989102207","pt":1580484266123,"mc":[{"id":"1.168133553","rc":[{"batb":[[0,1.13,1.99],[1,1.12,3],[2,1.11,10]],"ltp":1.47,"tv":16.72,"id":16325787}]}]}
{"op":"mcm","clk":"989103201","pt":1580484278448,"mc":[{"id":"1.168133553","rc":[{"batb":[[0,1.13,4.99],[1,1.11,10],[2,1.04,6]],"ltp":1.47,"tv":16.72,"id":16325787}]}]}
{"op":"mcm","clk":"989104312","pt":1580484293097,"mc":[{"id":"1.168133553","rc":[{"batb":[[0,1.14,3],[1,1.13,1.99],[2,1.11,10]],"ltp":1.47,"tv":16.72,"id":16325787}]}]}
{"op":"mcm","clk":"989105433","pt":1580484305912,"mc":[{"id":"1.168133553","rc":[{"batb":[[0,1.13,1.99],[1,1.12,3]],"ltp":1.47,"tv":16.72,"id":16325787}]}]}
{"op":"mcm","clk":"989105562","pt":1580484307713,"mc":[{"id":"1.168133553","rc":[{"batb":[[0,1.13,11.99],[2,1.04,6]],"ltp":1.47,"tv":16.72,"id":16325787}]}]}
{"op":"mcm","clk":"989106191","pt":1580484314912,"mc":[{"id":"1.168133553","rc":[{"batb":[[0,1.14,3],[1,1.13,11.99]],"ltp":1.47,"tv":16.72,"id":16325787}]}]}
{"op":"mcm","clk":"989107625","pt":1580484332371,"mc":[{"id":"1.168133553","rc":[{"batb":[[0,1.15,1.99],[1,1.14,3],[2,1.13,10]],"ltp":1.47,"tv":16.72,"id":16325787}]}]}
{"op":"mcm","clk":"989108324","pt":1580484341874,"mc":[{"id":"1.168133553","rc":[{"batb":[[0,1.15,4.99],[1,1.13,10],[2,1.03,1628.39]],"ltp":1.47,"tv":16.72,"id":16325787}]}]}
{"op":"mcm","clk":"989108990","pt":1580484350385,"mc":[{"id":"1.168133553","rc":[{"batb":[[0,1.16,3],[1,1.15,1.99],[2,1.13,10]],"ltp":1.47,"tv":16.72,"id":16325787}]}]}
{"op":"mcm","clk":"989109690","pt":1580484360415,"mc":[{"id":"1.168133553","rc":[{"batb":[[0,1.15,1.99],[1,1.14,3]],"ltp":1.47,"tv":16.72,"id":16325787}]}]}
{"op":"mcm","clk":"989110495","pt":1580484370522,"mc":[{"id":"1.168133553","rc":[{"batb":[[1,1.13,10],[2,1.03,1628.39]],"ltp":1.47,"tv":16.72,"id":16325787}]}]}
{"op":"mcm","clk":"989110505","pt":1580484370620,"mc":[{"id":"1.168133553","rc":[{"batb":[[0,1.15,4.99]],"ltp":1.47,"tv":16.72,"id":16325787}]}]}
{"op":"mcm","clk":"989111137","pt":1580484379110,"mc":[{"id":"1.168133553","rc":[{"batb":[[1,1.13,13]],"ltp":1.47,"tv":16.72,"id":16325787}]}]}
{"op":"mcm","clk":"989111320","pt":1580484381108,"mc":[{"id":"1.168133553","rc":[{"batb":[[0,1.16,3],[1,1.15,1.99],[2,1.13,13]],"ltp":1.47,"tv":16.72,"id":16325787}]}]}
{"op":"mcm","clk":"989111527","pt":1580484383799,"mc":[{"id":"1.168133553","rc":[{"batb":[[2,1.13,3]],"ltp":1.47,"tv":16.72,"id":16325787}]}]}
{"op":"mcm","clk":"989111804","pt":1580484388108,"mc":[{"id":"1.168133553","rc":[{"batb":[[0,1.17,1.99],[1,1.16,3]],"ltp":1.47,"tv":16.72,"id":16325787}]}]}
{"op":"mcm","clk":"989112124","pt":1580484392448,"mc":[{"id":"1.168133553","rc":[{"batb":[[0,1.17,4.99],[1,1.13,3],[2,1.03,1628.39]],"ltp":1.47,"tv":16.72,"id":16325787}]}]}
{"op":"mcm","clk":"989112940","pt":1580484403440,"mc":[{"id":"1.168133553","rc":[{"batb":[[0,1.18,3],[1,1.17,1.99],[2,1.13,3]],"ltp":1.47,"tv":16.72,"id":16325787}]}]}
{"op":"mcm","clk":"989113526","pt":1580484412231,"mc":[{"id":"1.168133553","rc":[{"batb":[[0,1.17,1.99],[1,1.14,3]],"ltp":1.47,"tv":16.72,"id":16325787}]}]}
{"op":"mcm","clk":"989114238","pt":1580484422066,"mc":[{"id":"1.168133553","rc":[{"batb":[[1,1.15,3]],"ltp":1.47,"tv":16.72,"id":16325787}]}]}
{"op":"mcm","clk":"989115143","pt":1580484434548,"mc":[{"id":"1.168133553","rc":[{"batb":[[1,1.16,3]],"ltp":1.47,"tv":16.72,"id":16325787}]}]}
{"op":"mcm","clk":"989115754","pt":1580484444772,"mc":[{"id":"1.168133553","rc":[{"batb":[[0,1.17,4.99],[1,1.13,3],[2,1.03,1628.39]],"ltp":1.47,"tv":16.72,"id":16325787}]}]}
{"op":"mcm","clk":"989116483","pt":1580484455489,"mc":[{"id":"1.168133553","rc":[{"batb":[[0,1.18,3],[1,1.17,1.99],[2,1.13,3]],"ltp":1.47,"tv":16.72,"id":16325787}]}]}
{"op":"mcm","clk":"989117431","pt":1580484469310,"mc":[{"id":"1.168133553","rc":[{"batb":[[0,1.17,1.99],[1,1.14,3]],"ltp":1.47,"tv":16.72,"id":16325787}]}]}
{"op":"mcm","clk":"989117778","pt":1580484474525,"mc":[{"id":"1.168133553","rc":[{"batb":[[2,1.03,1628.39]],"ltp":1.47,"tv":16.72,"id":16325787}]}]}
{"op":"mcm","clk":"989117784","pt":1580484474624,"mc":[{"id":"1.168133553","rc":[{"batb":[[2,1.04,3]],"ltp":1.47,"tv":16.72,"id":16325787}]}]}
{"op":"mcm","clk":"989118393","pt":1580484483531,"mc":[{"id":"1.168133553","rc":[{"batb":[[1,1.15,3]],"ltp":1.47,"tv":16.72,"id":16325787}]}]}
{"op":"mcm","clk":"989118909","pt":1580484491472,"mc":[{"id":"1.168133553","rc":[{"batb":[[0,1.16,1.99]],"ltp":1.47,"tv":16.72,"id":16325787}]}]}
{"op":"mcm","clk":"989119180","pt":1580484495757,"mc":[{"id":"1.168133553","rc":[{"batb":[[0,1.16,4.99],[1,1.04,3],[2,1.03,1628.39]],"ltp":1.47,"tv":16.72,"id":16325787}]}]}
{"op":"mcm","clk":"989119823","pt":1580484504557,"mc":[{"id":"1.168133553","rc":[{"batb":[[0,1.17,3],[1,1.16,1.99],[2,1.04,3]],"ltp":1.47,"tv":16.72,"id":16325787}]}]}
{"op":"mcm","clk":"989120536","pt":1580484514766,"mc":[{"id":"1.168133553","rc":[{"batb":[[0,1.16,1.99],[1,1.05,3]],"ltp":1.47,"tv":16.72,"id":16325787}]}]}
{"op":"mcm","clk":"989121207","pt":1580484525214,"mc":[{"id":"1.168133553","rc":[{"batb":[[1,1.06,3]],"ltp":1.47,"tv":16.72,"id":16325787}]}]}
{"op":"mcm","clk":"989121683","pt":1580484533490,"mc":[{"id":"1.168133553","rc":[{"batb":[[1,1.07,10],[2,1.06,3]],"ltp":1.47,"tv":16.72,"id":16325787}]}]}
{"op":"mcm","clk":"989121734","pt":1580484534325,"mc":[{"id":"1.168133553","rc":[{"batb":[[0,1.08,1.99]],"ltp":1.47,"tv":16.72,"id":16325787}]}]}
{"op":"mcm","clk":"989121848","pt":1580484536016,"mc":[{"id":"1.168133553","rc":[{"batb":[[0,1.08,4.99],[2,1.04,3]],"ltp":1.47,"tv":16.72,"id":16325787}]}]}
{"op":"mcm","clk":"989122682","pt":1580484547002,"mc":[{"id":"1.168133553","rc":[{"batb":[[0,1.09,3],[1,1.08,1.99],[2,1.07,10]],"ltp":1.47,"tv":16.72,"id":16325787}]}]}
{"op":"mcm","clk":"989123582","pt":1580484558837,"mc":[{"id":"1.168133553","rc":[{"batb":[[1,1.08,4.99]],"ltp":1.47,"tv":16.72,"id":16325787}]}]}
{"op":"mcm","clk":"989125197","pt":1580484583097,"mc":[{"id":"1.168133553","rc":[{"batb":[[0,1.1,1.99],[1,1.09,3],[2,1.08,3]],"ltp":1.47,"tv":16.72,"id":16325787}]}]}
{"op":"mcm","clk":"989125899","pt":1580484592798,"mc":[{"id":"1.168133553","rc":[{"batb":[[0,1.1,4.99],[1,1.08,3],[2,1.07,10]],"ltp":1.47,"tv":16.72,"id":16325787}]}]}
{"op":"mcm","clk":"989126748","pt":1580484604525,"mc":[{"id":"1.168133553","rc":[{"batb":[[0,1.11,3],[1,1.1,1.99],[2,1.08,3]],"ltp":1.47,"tv":16.72,"id":16325787}]}]}
{"op":"mcm","clk":"989127256","pt":1580484609900,"mc":[{"id":"1.168133553","rc":[{"batb":[[0,1.11,13]],"ltp":1.47,"tv":16.72,"id":16325787}]}]}
{"op":"mcm","clk":"989127707","pt":1580484616021,"mc":[{"id":"1.168133553","rc":[{"batb":[[0,1.12,3],[1,1.11,10],[2,1.1,1.99]],"ltp":1.47,"tv":16.72,"id":16325787}]}]}
{"op":"mcm","clk":"989128994","pt":1580484633534,"mc":[{"id":"1.168133553","rc":[{"batb":[[2,1.04,6]],"ltp":1.47,"tv":16.72,"id":16325787}]}]}
{"op":"mcm","clk":"989129068","pt":1580484634540,"mc":[{"id":"1.168133553","rc":[{"batb":[[0,1.13,1.99],[1,1.12,3],[2,1.11,10]],"ltp":1.47,"tv":16.72,"id":16325787}]}]}
{"op":"mcm","clk":"989129561","pt":1580484641754,"mc":[{"id":"1.168133553","rc":[{"batb":[[0,1.13,4.99],[1,1.11,10],[2,1.04,6]],"ltp":1.47,"tv":16.72,"id":16325787}]}]}
{"op":"mcm","clk":"989130357","pt":1580484652088,"mc":[{"id":"1.168133553","rc":[{"batb":[[0,1.14,3],[1,1.13,1.99],[2,1.11,10]],"ltp":1.47,"tv":16.72,"id":16325787}]}]}
{"op":"mcm","clk":"989131499","pt":1580484664712,"mc":[{"id":"1.168133553","rc":[{"batb":[[0,1.13,1.99],[1,1.12,3]],"ltp":1.47,"tv":16.72,"id":16325787}]}]}
{"op":"mcm","clk":"989132388","pt":1580484676008,"mc":[{"id":"1.168133553","rc":[{"batb":[[0,1.13,4.99],[1,1.11,10],[2,1.04,6]],"ltp":1.47,"tv":16.72,"id":16325787}]}]}
{"op":"mcm","clk":"989133449","pt":1580484687423,"mc":[{"id":"1.168133553","rc":[{"batb":[[1,1.05,10]],"ltp":1.47,"tv":16.72,"id":16325787}]}]}
{"op":"mcm","clk":"989133548","pt":1580484688404,"mc":[{"id":"1.168133553","rc":[{"batb":[[0,1.14,3],[1,1.13,1.99],[2,1.05,10]],"ltp":1.47,"tv":16.72,"id":16325787}]}]}
{"op":"mcm","clk":"989134423","pt":1580484699828,"mc":[{"id":"1.168133553","rc":[{"batb":[[0,1.13,1.99],[1,1.06,3]],"ltp":1.47,"tv":16.72,"id":16325787}]}]}
{"op":"mcm","clk":"989135198","pt":1580484709345,"mc":[{"id":"1.168133553","rc":[{"batb":[[1,1.07,3]],"ltp":1.47,"tv":16.72,"id":16325787}]}]}
{"op":"mcm","clk":"989135941","pt":1580484719729,"mc":[{"id":"1.168133553","rc":[{"batb":[[1,1.08,3]],"ltp":1.47,"tv":16.72,"id":16325787}]}]}
{"op":"mcm","clk":"989136735","pt":1580484730555,"mc":[{"id":"1.168133553","rc":[{"batb":[[1,1.05,10],[2,1.04,6]],"ltp":1.47,"tv":16.72,"id":16325787}]}]}
{"op":"mcm","clk":"989136740","pt":1580484730658,"mc":[{"id":"1.168133553","rc":[{"batb":[[1,1.09,3],[2,1.05,10]],"ltp":1.47,"tv":16.72,"id":16325787}]}]}
{"op":"mcm","clk":"989136958","pt":1580484733520,"mc":[{"id":"1.168133553","rc":[{"batb":[[0,1.1,1.99]],"ltp":1.47,"tv":16.72,"id":16325787}]}]}
{"op":"mcm","clk":"989137575","pt":1580484742058,"mc":[{"id":"1.168133553","rc":[{"batb":[[0,1.1,4.99],[1,1.05,10],[2,1.04,6]],"ltp":1.47,"tv":16.72,"id":16325787}]}]}
{"op":"mcm","clk":"989138390","pt":1580484752982,"mc":[{"id":"1.168133553","rc":[{"batb":[[0,1.11,3],[1,1.1,1.99],[2,1.05,10]],"ltp":1.47,"tv":16.72,"id":16325787}]}]}
{"op":"mcm","clk":"989139142","pt":1580484763358,"mc":[{"id":"1.168133553","rc":[{"batb":[[0,1.11,13],[2,1.04,6]],"ltp":1.47,"tv":16.72,"id":16325787}]}]}
{"op":"mcm","clk":"989139387","pt":1580484766376,"mc":[{"id":"1.168133553","rc":[{"batb":[[0,1.12,3],[1,1.11,10],[2,1.1,1.99]],"ltp":1.47,"tv":16.72,"id":16325787}]}]}
{"op":"mcm","clk":"989141231","pt":1580484785125,"mc":[{"id":"1.168133553","rc":[{"batb":[[0,1.13,1.99],[1,1.12,3],[2,1.11,10]],"ltp":1.47,"tv":16.72,"id":16325787}]}]}
{"op":"mcm","clk":"989141675","pt":1580484790903,"mc":[{"id":"1.168133553","rc":[{"batb":[[0,1.13,4.99],[1,1.11,10],[2,1.04,6]],"ltp":1.47,"tv":16.72,"id":16325787}]}]}
{"op":"mcm","clk":"989142517","pt":1580484802550,"mc":[{"id":"1.168133553","rc":[{"batb":[[0,1.14,3],[1,1.13,1.99],[2,1.11,10]],"ltp":1.47,"tv":16.72,"id":16325787}]}]}
{"op":"mcm","clk":"989143428","pt":1580484815151,"mc":[{"id":"1.168133553","rc":[{"batb":[[0,1.13,1.99],[1,1.12,3]],"ltp":1.47,"tv":16.72,"id":16325787}]}]}
{"op":"mcm","clk":"989144385","pt":1580484827960,"mc":[{"id":"1.168133553","rc":[{"batb":[[0,1.13,4.99],[1,1.11,10],[2,1.04,6]],"ltp":1.47,"tv":16.72,"id":16325787}]}]}
{"op":"mcm","clk":"989145206","pt":1580484839181,"mc":[{"id":"1.168133553","rc":[{"batb":[[1,1.05,10]],"ltp":1.47,"tv":16.72,"id":16325787}]}]}
{"op":"mcm","clk":"989145250","pt":1580484839861,"mc":[{"id":"1.168133553","rc":[{"batb":[[0,1.14,3],[1,1.13,1.99],[2,1.05,10]],"ltp":1.47,"tv":16.72,"id":16325787}]}]}
{"op":"mcm","clk":"989145903","pt":1580484849568,"mc":[{"id":"1.168133553","rc":[{"batb":[[0,1.13,1.99],[1,1.05,10],[2,1.04,6]],"ltp":1.47,"tv":16.72,"id":16325787}]}]}
{"op":"mcm","clk":"989145907","pt":1580484849677,"mc":[{"id":"1.168133553","rc":[{"batb":[[1,1.06,3],[2,1.05,10]],"ltp":1.47,"tv":16.72,"id":16325787}]}]}
{"op":"mcm","clk":"989146782","pt":1580484861490,"mc":[{"id":"1.168133553","rc":[{"batb":[[1,1.05,10],[2,1.04,6]],"ltp":1.47,"tv":16.72,"id":16325787}]}]}
{"op":"mcm","clk":"989146796","pt":1580484861599,"mc":[{"id":"1.168133553","rc":[{"batb":[[1,1.07,3],[2,1.05,10]],"ltp":1.47,"tv":16.72,"id":16325787}]}]}
{"op":"mcm","clk":"989147720","pt":1580484874113,"mc":[{"id":"1.168133553","rc":[{"batb":[[1,1.08,3]],"ltp":1.47,"tv":16.72,"id":16325787}]}]}
{"op":"mcm","clk":"989148373","pt":1580484883441,"mc":[{"id":"1.168133553","rc":[{"batb":[[0,1.09,1.99]],"ltp":1.47,"tv":16.72,"id":16325787}]}]}
{"op":"mcm","clk":"989148469","pt":1580484884546,"mc":[{"id":"1.168133553","rc":[{"batb":[[0,1.09,4.99],[1,1.05,10],[2,1.04,6]],"ltp":1.47,"tv":16.72,"id":16325787}]}]}
{"op":"mcm","clk":"989148590","pt":1580484885851,"mc":[{"id":"1.168133553","rc":[{"batb":[[1,1.06,3],[2,1.05,10]],"ltp":1.47,"tv":16.72,"id":16325787}]}]}
{"op":"mcm","clk":"989149468","pt":1580484897985,"mc":[{"id":"1.168133553","rc":[{"batb":[[0,1.1,3],[1,1.09,1.99],[2,1.06,3]],"ltp":1.47,"tv":16.72,"id":16325787}]}]}
{"op":"mcm","clk":"989150661","pt":1580484912166,"mc":[{"id":"1.168133553","rc":[{"batb":[[0,1.09,1.99],[1,1.07,3]],"ltp":1.47,"tv":16.72,"id":16325787}]}]}
{"op":"mcm","clk":"989151524","pt":1580484923519,"mc":[{"id":"1.168133553","rc":[{"batb":[[1,1.08,3]],"ltp":1.47,"tv":16.72,"id":16325787}]}]}
{"op":"mcm","clk":"989152527","pt":1580484937133,"mc":[{"id":"1.168133553","rc":[{"batb":[[0,1.09,4.99],[1,1.06,3],[2,1.04,6]],"ltp":1.47,"tv":16.72,"id":16325787}]}]}
{"op":"mcm","clk":"989153405","pt":1580484948126,"mc":[{"id":"1.168133553","rc":[{"batb":[[0,1.1,3],[1,1.09,1.99],[2,1.06,3]],"ltp":1.47,"tv":16.72,"id":16325787}]}]}
{"op":"mcm","clk":"989154372","pt":1580484960257,"mc":[{"id":"1.168133553","rc":[{"batb":[[0,1.09,1.99],[1,1.07,3]],"ltp":1.47,"tv":16.72,"id":16325787}]}]}
{"op":"mcm","clk":"989155342","pt":1580484970554,"mc":[{"id":"1.168133553","rc":[{"batb":[[1,1.08,3]],"ltp":1.47,"tv":16.72,"id":16325787}]}]}
{"op":"mcm","clk":"989156596","pt":1580484983757,"mc":[{"id":"1.168133553","rc":[{"batb":[[0,1.09,4.99],[1,1.06,3],[2,1.04,6]],"ltp":1.47,"tv":16.72,"id":16325787}]}]}
{"op":"mcm","clk":"989158067","pt":1580484999784,"mc":[{"id":"1.168133553","rc":[{"batb":[[0,1.1,3],[1,1.09,1.99],[2,1.06,3]],"ltp":1.47,"tv":16.72,"id":16325787}]}]}
{"op":"mcm","clk":"989159248","pt":1580485012491,"mc":[{"id":"1.168133553","rc":[{"batb":[[0,1.09,1.99],[1,1.06,3],[2,1.04,6]],"ltp":1.47,"tv":16.72,"id":16325787}]}]}
{"op":"mcm","clk":"989159253","pt":1580485012594,"mc":[{"id":"1.168133553","rc":[{"batb":[[1,1.07,3],[2,1.06,3]],"ltp":1.47,"tv":16.72,"id":16325787}]}]}
{"op":"mcm","clk":"989160464","pt":1580485025312,"mc":[{"id":"1.168133553","rc":[{"batb":[[0,1.08,1.99]],"ltp":1.47,"tv":16.72,"id":16325787}]}]}
{"op":"mcm","clk":"989160556","pt":1580485026280,"mc":[{"id":"1.168133553","rc":[{"batb":[[0,1.08,4.99],[1,1.06,3],[2,1.04,6]],"ltp":1.47,"tv":16.72,"id":16325787}]}]}
{"op":"mcm","clk":"989161683","pt":1580485037014,"mc":[{"id":"1.168133553","rc":[{"batb":[[0,1.09,3],[1,1.08,1.99],[2,1.06,3]],"ltp":1.47,"tv":16.72,"id":16325787}]}]}
{"op":"mcm","clk":"989162747","pt":1580485049528,"mc":[{"id":"1.168133553","rc":[{"batb":[[0,1.08,1.99],[1,1.07,3]],"ltp":1.47,"tv":16.72,"id":16325787}]}]}
{"op":"mcm","clk":"989172488","pt":1580485060476,"mc":[{"id":"1.168133553","rc":[{"batb":[[0,1.08,4.99],[1,1.06,3],[2,1.04,6]],"ltp":1.47,"tv":16.72,"id":16325787}]}]}
{"op":"mcm","clk":"989172952","pt":1580485066335,"mc":[{"id":"1.168133553","rc":[{"batb":[[1,1.07,10],[2,1.06,3]],"ltp":1.47,"tv":16.72,"id":16325787}]}]}
{"op":"mcm","clk":"989173610","pt":1580485074572,"mc":[{"id":"1.168133553","rc":[{"batb":[[0,1.08,1.99]],"ltp":1.47,"tv":16.72,"id":16325787}]}]}
{"op":"mcm","clk":"989173616","pt":1580485074674,"mc":[{"id":"1.168133553","rc":[{"batb":[[0,1.09,3],[1,1.08,1.99],[2,1.07,10]],"ltp":1.47,"tv":16.72,"id":16325787}]}]}
{"op":"mcm","clk":"989174608","pt":1580485086358,"mc":[{"id":"1.168133553","rc":[{"batb":[[0,1.08,4.99],[1,1.07,10],[2,1.04,6]],"ltp":1.47,"tv":16.72,"id":16325787}]}]}
{"op":"mcm","clk":"989175627","pt":1580485098347,"mc":[{"id":"1.168133553","rc":[{"batb":[[0,1.09,3],[1,1.08,1.99],[2,1.07,10]],"ltp":1.47,"tv":16.72,"id":16325787}]}]}
{"op":"mcm","clk":"989176445","pt":1580485107457,"mc":[{"id":"1.168133553","rc":[{"batb":[[0,1.08,4.99],[1,1.07,10],[2,1.04,6]],"ltp":1.47,"tv":16.72,"id":16325787}]}]}
{"op":"mcm","clk":"989177335","pt":1580485119075,"mc":[{"id":"1.168133553","rc":[{"batb":[[0,1.09,3],[1,1.08,1.99],[2,1.07,10]],"ltp":1.47,"tv":16.72,"id":16325787}]}]}
{"op":"mcm","clk":"989178516","pt":1580485132486,"mc":[{"id":"1.168133553","rc":[{"batb":[[0,1.08,4.99],[1,1.07,10],[2,1.04,6]],"ltp":1.47,"tv":16.72,"id":16325787}]}]}
{"op":"mcm","clk":"989179352","pt":1580485142806,"mc":[{"id":"1.168133553","rc":[{"batb":[[1,1.05,10]],"ltp":1.47,"tv":16.72,"id":16325787}]}]}
{"op":"mcm","clk":"989179688","pt":1580485147506,"mc":[{"id":"1.168133553","rc":[{"batb":[[0,1.08,1.99]],"ltp":1.47,"tv":16.72,"id":16325787}]}]}
{"op":"mcm","clk":"989179700","pt":1580485147608,"mc":[{"id":"1.168133553","rc":[{"batb":[[0,1.09,3],[1,1.08,1.99],[2,1.05,10]],"ltp":1.47,"tv":16.72,"id":16325787}]}]}
{"op":"mcm","clk":"989180671","pt":1580485159533,"mc":[{"id":"1.168133553","rc":[{"batb":[[0,1.08,1.99],[1,1.06,3]],"ltp":1.47,"tv":16.72,"id":16325787}]}]}
{"op":"mcm","clk":"989180735","pt":1580485160320,"mc":[{"id":"1.168133553","rc":[{"batb":[[0,1.06,4.99],[1,1.05,10],[2,1.04,6]],"ltp":1.47,"tv":16.72,"id":16325787}]}]}
{"op":"mcm","clk":"989181700","pt":1580485173160,"mc":[{"id":"1.168133553","rc":[{"batb":[[0,1.07,3],[1,1.06,1.99],[2,1.05,10]],"ltp":1.47,"tv":16.72,"id":16325787}]}]}
{"op":"mcm","clk":"989182725","pt":1580485186261,"mc":[{"id":"1.168133553","rc":[{"batb":[[0,1.06,4.99],[1,1.05,10],[2,1.04,6]],"ltp":1.47,"tv":16.72,"id":16325787}]}]}
{"op":"mcm","clk":"989183835","pt":1580485201569,"mc":[{"id":"1.168133553","rc":[{"batb":[[0,1.07,3],[1,1.06,1.99],[2,1.05,10]],"ltp":1.47,"tv":16.72,"id":16325787}]}]}
{"op":"mcm","clk":"989184317","pt":1580485207573,"mc":[{"id":"1.168133553","rc":[{"batb":[[0,1.08,1.99],[1,1.07,3]],"ltp":1.47,"tv":16.72,"id":16325787}]}]}
{"op":"mcm","clk":"989184932","pt":1580485215507,"mc":[{"id":"1.168133553","rc":[{"batb":[[1,1.05,10],[2,1.04,6]],"ltp":1.47,"tv":16.72,"id":16325787}]}]}
{"op":"mcm","clk":"989185011","pt":1580485216088,"mc":[{"id":"1.168133553","rc":[{"batb":[[0,1.08,4.99]],"ltp":1.47,"tv":16.72,"id":16325787}]}]}
{"op":"mcm","clk":"989185972","pt":1580485228729,"mc":[{"id":"1.168133553","rc":[{"batb":[[0,1.09,3],[1,1.08,1.99],[2,1.05,10]],"ltp":1.47,"tv":16.72,"id":16325787}]}]}
{"op":"mcm","clk":"989187269","pt":1580485246273,"mc":[{"id":"1.168133553","rc":[{"batb":[[0,1.08,1.99],[1,1.06,3]],"ltp":1.47,"tv":16.72,"id":16325787}]}]}
{"op":"mcm","clk":"989187683","pt":1580485251780,"mc":[{"id":"1.168133553","rc":[{"batb":[[0,1.07,1.99]],"ltp":1.47,"tv":16.72,"id":16325787}]}]}
{"op":"mcm","clk":"989188209","pt":1580485258967,"mc":[{"id":"1.168133553","rc":[{"batb":[[0,1.07,4.99],[1,1.05,10],[2,1.04,6]],"ltp":1.47,"tv":16.72,"id":16325787}]}]}
{"op":"mcm","clk":"989189404","pt":1580485274385,"mc":[{"id":"1.168133553","rc":[{"batb":[[0,1.08,3],[1,1.07,1.99],[2,1.05,10]],"ltp":1.47,"tv":16.72,"id":16325787}]}]}
{"op":"mcm","clk":"989190494","pt":1580485289931,"mc":[{"id":"1.168133553","rc":[{"batb":[[0,1.07,1.99],[1,1.06,3]],"ltp":1.47,"tv":16.72,"id":16325787}]}]}
{"op":"mcm","clk":"989191054","pt":1580485297103,"mc":[{"id":"1.168133553","rc":[{"batb":[[2,1.04,6]],"ltp":1.47,"tv":16.72,"id":16325787}]}]}
{"op":"mcm","clk":"989191479","pt":1580485303132,"mc":[{"id":"1.168133553","rc":[{"batb":[[0,1.07,4.99],[1,1.04,6],[2,1.03,1628.39]],"ltp":1.47,"tv":16.72,"id":16325787}]}]}
{"op":"mcm","clk":"989192380","pt":1580485315345,"mc":[{"id":"1.168133553","rc":[{"batb":[[0,1.08,3],[1,1.07,1.99],[2,1.04,6]],"ltp":1.47,"tv":16.72,"id":16325787}]}]}
{"op":"mcm","clk":"989193351","pt":1580485328856,"mc":[{"id":"1.168133553","rc":[{"batb":[[0,1.07,1.99],[1,1.05,3]],"ltp":1.47,"tv":16.72,"id":16325787}]}]}
{"op":"mcm","clk":"989194023","pt":1580485338839,"mc":[{"id":"1.168133553","rc":[{"batb":[[0,1.06,1.99]],"ltp":1.47,"tv":16.72,"id":16325787}]}]}
{"op":"mcm","clk":"989194311","pt":1580485343252,"mc":[{"id":"1.168133553","rc":[{"batb":[[0,1.06,4.99],[1,1.04,6],[2,1.03,1628.39]],"ltp":1.47,"tv":16.72,"id":16325787}]}]}
{"op":"mcm","clk":"989195186","pt":1580485356786,"mc":[{"id":"1.168133553","rc":[{"batb":[[0,1.07,3],[1,1.06,1.99],[2,1.04,6]],"ltp":1.47,"tv":16.72,"id":16325787}]}]}
{"op":"mcm","clk":"989196079","pt":1580485369570,"mc":[{"id":"1.168133553","rc":[{"batb":[[0,1.06,1.99],[1,1.05,3]],"ltp":1.47,"tv":16.72,"id":16325787}]}]}
{"op":"mcm","clk":"989197278","pt":1580485384782,"mc":[{"id":"1.168133553","rc":[{"batb":[[0,1.06,4.99],[1,1.04,6],[2,1.03,1628.39]],"ltp":1.47,"tv":16.72,"id":16325787}]}]}
{"op":"mcm","clk":"989198392","pt":1580485398299,"mc":[{"id":"1.168133553","rc":[{"batb":[[0,1.07,3],[1,1.06,1.99],[2,1.04,6]],"ltp":1.47,"tv":16.72,"id":16325787}]}]}
{"op":"mcm","clk":"989199329","pt":1580485411528,"mc":[{"id":"1.168133553","rc":[{"batb":[[0,1.06,1.99],[1,1.04,6],[2,1.03,1628.39]],"ltp":1.47,"tv":16.72,"id":16325787}]}]}
{"op":"mcm","clk":"989199333","pt":1580485411632,"mc":[{"id":"1.168133553","rc":[{"batb":[[1,1.05,3],[2,1.04,6]],"ltp":1.47,"tv":16.72,"id":16325787}]}]}
{"op":"mcm","clk":"989200332","pt":1580485425766,"mc":[{"id":"1.168133553","rc":[{"batb":[[0,1.06,4.99],[1,1.04,6],[2,1.03,1628.39]],"ltp":1.47,"tv":16.72,"id":16325787}]}]}
{"op":"mcm","clk":"989201163","pt":1580485436874,"mc":[{"id":"1.168133553","rc":[{"batb":[[0,1.07,3],[1,1.06,1.99],[2,1.04,6]],"ltp":1.47,"tv":16.72,"id":16325787}]}]}
{"op":"mcm","clk":"989202130","pt":1580485448469,"mc":[{"id":"1.168133553","rc":[{"batb":[[0,1.07,10],[2,1.05,3]],"ltp":1.47,"tv":16.72,"id":16325787}]}]}
{"op":"mcm","clk":"989203431","pt":1580485462874,"mc":[{"id":"1.168133553","rc":[{"batb":[[0,1.08,3],[1,1.07,10],[2,1.06,1.99]],"ltp":1.47,"tv":16.72,"id":16325787}]}]}
{"op":"mcm","clk":"989203876","pt":1580485468211,"mc":[{"id":"1.168133553","rc":[{"batb":[[0,1.09,1.99],[1,1.08,3],[2,1.07,10]],"ltp":1.47,"tv":16.72,"id":16325787}]}]}
{"op":"mcm","clk":"989204434","pt":1580485475203,"mc":[{"id":"1.168133553","rc":[{"batb":[[0,1.09,4.99],[1,1.07,10],[2,1.04,6]],"ltp":1.47,"tv":16.72,"id":16325787}]}]}
{"op":"mcm","clk":"989205452","pt":1580485487302,"mc":[{"id":"1.168133553","rc":[{"batb":[[0,1.1,3],[1,1.09,1.99],[2,1.07,10]],"ltp":1.47,"tv":16.72,"id":16325787}]}]}
{"op":"mcm","clk":"989206466","pt":1580485499168,"mc":[{"id":"1.168133553","rc":[{"batb":[[0,1.09,1.99],[1,1.08,3]],"ltp":1.47,"tv":16.72,"id":16325787}]}]}
{"op":"mcm","clk":"989207865","pt":1580485514444,"mc":[{"id":"1.168133553","rc":[{"batb":[[0,1.09,4.99],[1,1.07,10],[2,1.04,6]],"ltp":1.47,"tv":16.72,"id":16325787}]}]}
{"op":"mcm","clk":"989208535","pt":1580485522404,"mc":[{"id":"1.168133553","rc":[{"batb":[[1,1.04,6],[2,1.03,1628.39]],"ltp":1.47,"tv":16.72,"id":16325787}]}]}
{"op":"mcm","clk":"989208564","pt":1580485522709,"mc":[{"id":"1.168133553","rc":[{"batb":[[1,1.05,10],[2,1.04,6]],"ltp":1.47,"tv":16.72,"id":16325787}]}]}
{"op":"mcm","clk":"989208907","pt":1580485526824,"mc":[{"id":"1.168133553","rc":[{"batb":[[0,1.1,3],[1,1.09,1.99],[2,1.05,10]],"ltp":1.47,"tv":16.72,"id":16325787}]}]}
{"op":"mcm","clk":"989209990","pt":1580485539505,"mc":[{"id":"1.168133553","rc":[{"batb":[[0,1.09,1.99],[1,1.05,10],[2,1.04,6]],"ltp":1.47,"tv":16.72,"id":16325787}]}]}
{"op":"mcm","clk":"989210070","pt":1580485540512,"mc":[{"id":"1.168133553","rc":[{"batb":[[1,1.06,3],[2,1.05,10]],"ltp":1.47,"tv":16.72,"id":16325787}]}]}
{"op":"mcm","clk":"989211180","pt":1580485554538,"mc":[{"id":"1.168133553","rc":[{"batb":[[1,1.05,10],[2,1.04,6]],"ltp":1.47,"tv":16.72,"id":16325787}]}]}
{"op":"mcm","clk":"989211207","pt":1580485554811,"mc":[{"id":"1.168133553","rc":[{"batb":[[0,1.07,4.99]],"ltp":1.47,"tv":16.72,"id":16325787}]}]}
{"op":"mcm","clk":"989212340","pt":1580485568860,"mc":[{"id":"1.168133553","rc":[{"batb":[[0,1.08,3],[1,1.07,1.99],[2,1.05,10]],"ltp":1.47,"tv":16.72,"id":16325787}]}]}
{"op":"mcm","clk":"989213568","pt":1580485583958,"mc":[{"id":"1.168133553","rc":[{"batb":[[0,1.07,1.99],[1,1.06,3]],"ltp":1.47,"tv":16.72,"id":16325787}]}]}
{"op":"mcm","clk":"989214567","pt":1580485595003,"mc":[{"id":"1.168133553","rc":[{"batb":[[2,1.04,6]],"ltp":1.47,"tv":16.72,"id":16325787}]}]}
{"op":"mcm","clk":"989214810","pt":1580485598207,"mc":[{"id":"1.168133553","rc":[{"batb":[[0,1.07,4.99],[1,1.04,6],[2,1.03,1628.39]],"ltp":1.47,"tv":16.72,"id":16325787}]}]}
{"op":"mcm","clk":"989216021","pt":1580485611818,"mc":[{"id":"1.168133553","rc":[{"batb":[[0,1.08,3],[1,1.07,1.99],[2,1.04,6]],"ltp":1.47,"tv":16.72,"id":16325787}]}]}
{"op":"mcm","clk":"989217275","pt":1580485627740,"mc":[{"id":"1.168133553","rc":[{"batb":[[0,1.07,1.99],[1,1.05,3]],"ltp":1.47,"tv":16.72,"id":16325787}]}]}
{"op":"mcm","clk":"989218388","pt":1580485641553,"mc":[{"id":"1.168133553","rc":[{"batb":[[1,1.06,3]],"ltp":1.47,"tv":16.72,"id":16325787}]}]}
{"op":"mcm","clk":"989219329","pt":1580485655068,"mc":[{"id":"1.168133553","rc":[{"batb":[[0,1.07,4.99],[1,1.04,6],[2,1.03,1628.39]],"ltp":1.47,"tv":16.72,"id":16325787}]}]}
{"op":"mcm","clk":"989220430","pt":1580485669414,"mc":[{"id":"1.168133553","rc":[{"batb":[[0,1.08,3],[1,1.07,1.99],[2,1.04,6]],"ltp":1.47,"tv":16.72,"id":16325787}]}]}
{"op":"mcm","clk":"989221949","pt":1580485685386,"mc":[{"id":"1.168133553","rc":[{"batb":[[0,1.07,1.99],[1,1.05,3]],"ltp":1.47,"tv":16.72,"id":16325787}]}]}
{"op":"mcm","clk":"989222907","pt":1580485697219,"mc":[{"id":"1.168133553","rc":[{"batb":[[1,1.06,3]],"ltp":1.47,"tv":16.72,"id":16325787}]}]}
{"op":"mcm","clk":"989223146","pt":1580485700528,"mc":[{"id":"1.168133553","rc":[{"batb":[[2,1.05,3]],"ltp":1.47,"tv":16.72,"id":16325787}]}]}
{"op":"mcm","clk":"989223802","pt":1580485709535,"mc":[{"id":"1.168133553","rc":[{"batb":[[1,1.05,3],[2,1.04,6]],"ltp":1.47,"tv":16.72,"id":16325787}]}]}
{"op":"mcm","clk":"989223810","pt":1580485709639,"mc":[{"id":"1.168133553","rc":[{"batb":[[0,1.07,4.99]],"ltp":1.47,"tv":16.72,"id":16325787}]}]}
{"op":"mcm","clk":"989224752","pt":1580485722833,"mc":[{"id":"1.168133553","rc":[{"batb":[[0,1.08,3],[1,1.07,1.99],[2,1.05,3]],"ltp":1.47,"tv":16.72,"id":16325787}]}]}
{"op":"mcm","clk":"989225535","pt":1580485734562,"mc":[{"id":"1.168133553","rc":[{"batb":[[0,1.07,1.99],[1,1.05,3],[2,1.04,6]],"ltp":1.47,"tv":16.72,"id":16325787}]}]}
{"op":"mcm","clk":"989225544","pt":1580485734665,"mc":[{"id":"1.168133553","rc":[{"batb":[[1,1.06,3],[2,1.05,3]],"ltp":1.47,"tv":16.72,"id":16325787}]}]}
{"op":"mcm","clk":"989226247","pt":1580485744589,"mc":[{"id":"1.168133553","rc":[{"batb":[[0,1.07,11.99]],"ltp":1.47,"tv":16.72,"id":16325787}]}]}
{"op":"mcm","clk":"989226520","pt":1580485748265,"mc":[{"id":"1.168133553","rc":[{"batb":[[0,1.08,3],[1,1.07,11.99]],"ltp":1.47,"tv":16.72,"id":16325787}]}]}
{"op":"mcm","clk":"989229425","pt":1580485788524,"mc":[{"id":"1.168133553","rc":[{"batb":[[0,1.09,1.99],[1,1.08,3],[2,1.07,10]],"ltp":1.47,"tv":16.72,"id":16325787}]}]}
{"op":"mcm","clk":"989229465","pt":1580485789050,"mc":[{"id":"1.168133553","rc":[{"batb":[[0,1.09,4.99],[1,1.07,10],[2,1.05,3]],"ltp":1.47,"tv":16.72,"id":16325787}]}]}
{"op":"mcm","clk":"989230197","pt":1580485799937,"mc":[{"id":"1.168133553","rc":[{"batb":[[0,1.1,3],[1,1.09,1.99],[2,1.07,10]],"ltp":1.47,"tv":16.72,"id":16325787}]}]}
{"op":"mcm","clk":"989231144","pt":1580485811541,"mc":[{"id":"1.168133553","rc":[{"batb":[[2,1.08,3]],"ltp":1.47,"tv":16.72,"id":16325787}]}]}
{"op":"mcm","clk":"989231351","pt":1580485814349,"mc":[{"id":"1.168133553","rc":[{"batb":[[0,1.09,4.99],[1,1.08,3],[2,1.07,10]],"ltp":1.47,"tv":16.72,"id":16325787}]}]}
{"op":"mcm","clk":"989231667","pt":1580485818859,"mc":[{"id":"1.168133553","rc":[{"batb":[[2,1.04,6]],"ltp":1.47,"tv":16.72,"id":16325787}]}]}
{"op":"mcm","clk":"989232689","pt":1580485830545,"mc":[{"id":"1.168133553","rc":[{"batb":[[0,1.1,3],[1,1.09,1.99],[2,1.08,3]],"ltp":1.47,"tv":16.72,"id":16325787}]}]}
{"op":"mcm","clk":"989233547","pt":1580485843039,"mc":[{"id":"1.168133553","rc":[{"batb":[[0,1.09,4.99],[1,1.08,3],[2,1.04,6]],"ltp":1.47,"tv":16.72,"id":16325787}]}]}
{"op":"mcm","clk":"989234462","pt":1580485854444,"mc":[{"id":"1.168133553","rc":[{"batb":[[0,1.1,3],[1,1.09,1.99],[2,1.08,3]],"ltp":1.47,"tv":16.72,"id":16325787}]}]}
{"op":"mcm","clk":"989235815","pt":1580485872966,"mc":[{"id":"1.168133553","rc":[{"batb":[[0,1.11,1.99],[1,1.09,3]],"ltp":1.47,"tv":16.72,"id":16325787}]}]}
{"op":"mcm","clk":"989236825","pt":1580485886113,"mc":[{"id":"1.168133553","rc":[{"batb":[[1,1.1,3]],"ltp":1.47,"tv":16.72,"id":16325787}]}]}
{"op":"mcm","clk":"989238023","pt":1580485902829,"mc":[{"id":"1.168133553","rc":[{"batb":[[0,1.11,4.99],[1,1.08,3],[2,1.04,6]],"ltp":1.47,"tv":16.72,"id":16325787}]}]}
{"op":"mcm","clk":"989238665","pt":1580485911934,"mc":[{"id":"1.168133553","rc":[{"batb":[[1,1.05,3]],"ltp":1.47,"tv":16.72,"id":16325787}]}]}
{"op":"mcm","clk":"989239004","pt":1580485916231,"mc":[{"id":"1.168133553","rc":[{"batb":[[0,1.12,3],[1,1.11,1.99],[2,1.05,3]],"ltp":1.47,"tv":16.72,"id":16325787}]}]}
{"op":"mcm","clk":"989239221","pt":1580485919357,"mc":[{"id":"1.168133553","rc":[{"batb":[[0,1.13,1.99],[1,1.12,3]],"ltp":1.47,"tv":16.72,"id":16325787}]}]}
{"op":"mcm","clk":"989239817","pt":1580485927851,"mc":[{"id":"1.168133553","rc":[{"batb":[[0,1.13,4.99],[1,1.05,3],[2,1.04,6]],"ltp":1.47,"tv":16.72,"id":16325787}]}]}
{"op":"mcm","clk":"989240481","pt":1580485938688,"mc":[{"id":"1.168133553","rc":[{"batb":[[0,1.14,3],[1,1.13,1.99],[2,1.05,3]],"ltp":1.47,"tv":16.72,"id":16325787}]}]}
{"op":"mcm","clk":"989241334","pt":1580485951022,"mc":[{"id":"1.168133553","rc":[{"batb":[[0,1.13,1.99],[1,1.06,3]],"ltp":1.47,"tv":16.72,"id":16325787}]}]}
{"op":"mcm","clk":"989250925","pt":1580485957445,"mc":[{"id":"1.168133553","rc":[{"batb":[[0,1.07,1.99]],"ltp":1.47,"tv":16.72,"id":16325787}]}]}
{"op":"mcm","clk":"989251400","pt":1580485963839,"mc":[{"id":"1.168133553","rc":[{"batb":[[0,1.07,4.99],[1,1.05,3],[2,1.04,6]],"ltp":1.47,"tv":16.72,"id":16325787}]}]}
{"op":"mcm","clk":"989251860","pt":1580485969550,"mc":[{"id":"1.168133553","rc":[{"batb":[[1,1.06,10],[2,1.05,3]],"ltp":1.47,"tv":16.72,"id":16325787}]}]}
{"op":"mcm","clk":"989252556","pt":1580485979948,"mc":[{"id":"1.168133553","rc":[{"batb":[[0,1.08,3],[1,1.07,1.99],[2,1.06,10]],"ltp":1.47,"tv":16.72,"id":16325787}]}]}
{"op":"mcm","clk":"989253415","pt":1580485992552,"mc":[{"id":"1.168133553","rc":[{"batb":[[0,1.07,4.99],[1,1.06,10],[2,1.05,3]],"ltp":1.47,"tv":16.72,"id":16325787}]}]}
{"op":"mcm","clk":"989254310","pt":1580486006293,"mc":[{"id":"1.168133553","rc":[{"batb":[[0,1.08,3],[1,1.07,1.99],[2,1.06,10]],"ltp":1.47,"tv":16.72,"id":16325787}]}]}
{"op":"mcm","clk":"989255086","pt":1580486018987,"mc":[{"id":"1.168133553","rc":[{"batb":[[0,1.07,4.99],[1,1.06,10],[2,1.05,3]],"ltp":1.47,"tv":16.72,"id":16325787}]}]}
{"op":"mcm","clk":"989255806","pt":1580486030424,"mc":[{"id":"1.168133553","rc":[{"batb":[[0,1.08,3],[1,1.07,1.99],[2,1.06,10]],"ltp":1.47,"tv":16.72,"id":16325787}]}]}
{"op":"mcm","clk":"989256400","pt":1580486040354,"mc":[{"id":"1.168133553","rc":[{"batb":[[2,1.05,3]],"ltp":1.47,"tv":16.72,"id":16325787}]}]}
{"op":"mcm","clk":"989257748","pt":1580486047046,"mc":[{"id":"1.168133553","rc":[{"batb":[[0,1.07,1.99],[1,1.06,3]],"ltp":1.47,"tv":16.72,"id":16325787}]}]}
{"op":"mcm","clk":"989259452","pt":1580486060886,"mc":[{"id":"1.168133553","rc":[{"batb":[[0,1.07,4.99],[1,1.05,3],[2,1.04,6]],"ltp":1.47,"tv":16.72,"id":16325787}]}]}
{"op":"mcm","clk":"989260750","pt":1580486076515,"mc":[{"id":"1.168133553","rc":[{"batb":[[0,1.08,3],[1,1.07,1.99],[2,1.05,3]],"ltp":1.47,"tv":16.72,"id":16325787}]}]}
{"op":"mcm","clk":"989261531","pt":1580486085325,"mc":[{"id":"1.168133553","rc":[{"batb":[[0,1.07,1.99],[1,1.06,3]],"ltp":1.47,"tv":16.72,"id":16325787}]}]}
{"op":"mcm","clk":"989262895","pt":1580486100387,"mc":[{"id":"1.168133553","rc":[{"batb":[[0,1.07,4.99],[1,1.05,3],[2,1.04,6]],"ltp":1.47,"tv":16.72,"id":16325787}]}]}
{"op":"mcm","clk":"989264395","pt":1580486115053,"mc":[{"id":"1.168133553","rc":[{"batb":[[0,1.08,3],[1,1.07,1.99],[2,1.05,3]],"ltp":1.47,"tv":16.72,"id":16325787}]}]}
{"op":"mcm","clk":"989265214","pt":1580486126469,"mc":[{"id":"1.168133553","rc":[{"batb":[[0,1.07,1.99],[1,1.06,3]],"ltp":1.47,"tv":16.72,"id":16325787}]}]}
{"op":"mcm","clk":"989266015","pt":1580486138908,"mc":[{"id":"1.168133553","rc":[{"batb":[[0,1.07,4.99],[1,1.05,3],[2,1.04,6]],"ltp":1.47,"tv":16.72,"id":16325787}]}]}
{"op":"mcm","clk":"989266859","pt":1580486151524,"mc":[{"id":"1.168133553","rc":[{"batb":[[0,1.07,1.99]],"ltp":1.47,"tv":16.72,"id":16325787}]}]}
{"op":"mcm","clk":"989266866","pt":1580486151621,"mc":[{"id":"1.168133553","rc":[{"batb":[[0,1.08,3],[1,1.07,1.99],[2,1.05,3]],"ltp":1.47,"tv":16.72,"id":16325787}]}]}
{"op":"mcm","clk":"989267825","pt":1580486164250,"mc":[{"id":"1.168133553","rc":[{"batb":[[0,1.07,1.99],[1,1.06,3]],"ltp":1.47,"tv":16.72,"id":16325787}]}]}
{"op":"mcm","clk":"989268708","pt":1580486177475,"mc":[{"id":"1.168133553","rc":[{"batb":[[1,1.05,3],[2,1.04,6]],"ltp":1.47,"tv":16.72,"id":16325787}]}]}
{"op":"mcm","clk":"989268712","pt":1580486177577,"mc":[{"id":"1.168133553","rc":[{"batb":[[0,1.07,4.99]],"ltp":1.47,"tv":16.72,"id":16325787}]}]}
{"op":"mcm","clk":"989269717","pt":1580486190795,"mc":[{"id":"1.168133553","rc":[{"batb":[[0,1.08,3],[1,1.07,1.99],[2,1.05,3]],"ltp":1.47,"tv":16.72,"id":16325787}]}]}
{"op":"mcm","clk":"989269912","pt":1580486193571,"mc":[{"id":"1.168133553","rc":[{"batb":[[0,1.08,13]],"ltp":1.47,"tv":16.72,"id":16325787}]}]}
{"op":"mcm","clk":"989270553","pt":1580486202181,"mc":[{"id":"1.168133553","rc":[{"batb":[[0,1.09,3],[1,1.08,10],[2,1.07,1.99]],"ltp":1.47,"tv":16.72,"id":16325787}]}]}
{"op":"mcm","clk":"989271273","pt":1580486211817,"mc":[{"id":"1.168133553","rc":[{"batb":[[0,1.1,1.99],[1,1.09,3],[2,1.08,10]],"ltp":1.47,"tv":16.72,"id":16325787}]}]}
{"op":"mcm","clk":"989271701","pt":1580486216382,"mc":[{"id":"1.168133553","rc":[{"batb":[[0,1.1,4.99],[1,1.08,10],[2,1.05,3]],"ltp":1.47,"tv":16.72,"id":16325787}]}]}
{"op":"mcm","clk":"989272959","pt":1580486230708,"mc":[{"id":"1.168133553","rc":[{"batb":[[0,1.11,3],[1,1.1,1.99],[2,1.08,10]],"ltp":1.47,"tv":16.72,"id":16325787}]}]}
{"op":"mcm","clk":"989273909","pt":1580486242736,"mc":[{"id":"1.168133553","rc":[{"batb":[[0,1.1,1.99],[1,1.09,3]],"ltp":1.47,"tv":16.72,"id":16325787}]}]}
{"op":"mcm","clk":"989275021","pt":1580486256750,"mc":[{"id":"1.168133553","rc":[{"batb":[[0,1.1,4.99],[1,1.08,10],[2,1.05,3]],"ltp":1.47,"tv":16.72,"id":16325787}]}]}
{"op":"mcm","clk":"989275527","pt":1580486263480,"mc":[{"id":"1.168133553","rc":[{"batb":[[1,1.09,3],[2,1.08,10]],"ltp":1.47,"tv":16.72,"id":16325787}]}]}
{"op":"mcm","clk":"989276161","pt":1580486272413,"mc":[{"id":"1.168133553","rc":[{"batb":[[0,1.11,3],[1,1.1,1.99],[2,1.09,3]],"ltp":1.47,"tv":16.72,"id":16325787}]}]}
{"op":"mcm","clk":"989276865","pt":1580486281406,"mc":[{"id":"1.168133553","rc":[{"batb":[[0,1.11,13]],"ltp":1.47,"tv":16.72,"id":16325787}]}]}
{"op":"mcm","clk":"989277317","pt":1580486287383,"mc":[{"id":"1.168133553","rc":[{"batb":[[0,1.12,3],[1,1.11,10],[2,1.1,1.99]],"ltp":1.47,"tv":16.72,"id":16325787}]}]}
{"op":"mcm","clk":"989277961","pt":1580486295819,"mc":[{"id":"1.168133553","rc":[{"batb":[[0,1.13,1.99],[1,1.12,3],[2,1.11,10]],"ltp":1.47,"tv":16.72,"id":16325787}]}]}
{"op":"mcm","clk":"989278286","pt":1580486300492,"mc":[{"id":"1.168133553","rc":[{"batb":[[0,1.13,4.99],[1,1.11,10],[2,1.09,3]],"ltp":1.47,"tv":16.72,"id":16325787}]}]}
{"op":"mcm","clk":"989279767","pt":1580486317909,"mc":[{"id":"1.168133553","rc":[{"batb":[[0,1.14,3],[1,1.13,1.99],[2,1.11,10]],"ltp":1.47,"tv":16.72,"id":16325787}]}]}
{"op":"mcm","clk":"989280904","pt":1580486330541,"mc":[{"id":"1.168133553","rc":[{"batb":[[0,1.13,1.99],[1,1.12,3]],"ltp":1.47,"tv":16.72,"id":16325787}]}]}
{"op":"mcm","clk":"989282326","pt":1580486344569,"mc":[{"id":"1.168133553","rc":[{"batb":[[1,1.11,10],[2,1.04,6]],"ltp":1.47,"tv":16.72,"id":16325787}]}]}
{"op":"mcm","clk":"989282336","pt":1580486344641,"mc":[{"id":"1.168133553","rc":[{"batb":[[0,1.13,4.99]],"ltp":1.47,"tv":16.72,"id":16325787}]}]}
{"op":"mcm","clk":"989283853","pt":1580486360686,"mc":[{"id":"1.168133553","rc":[{"batb":[[0,1.14,3],[1,1.13,1.99],[2,1.11,10]],"ltp":1.47,"tv":16.72,"id":16325787}]}]}
{"op":"mcm","clk":"989284249","pt":1580486365514,"mc":[{"id":"1.168133553","rc":[{"batb":[[2,1.04,6]],"ltp":1.47,"tv":16.72,"id":16325787}]}]}
{"op":"mcm","clk":"989284254","pt":1580486365583,"mc":[{"id":"1.168133553","rc":[{"batb":[[1,1.13,11.99]],"ltp":1.47,"tv":16.72,"id":16325787}]}]}
{"op":"mcm","clk":"989285065","pt":1580486376422,"mc":[{"id":"1.168133553","rc":[{"batb":[[0,1.15,1.99],[1,1.14,3],[2,1.13,10]],"ltp":1.47,"tv":16.72,"id":16325787}]}]}
{"op":"mcm","clk":"989285916","pt":1580486386425,"mc":[{"id":"1.168133553","rc":[{"batb":[[0,1.15,4.99],[1,1.13,10],[2,1.03,1628.39]],"ltp":1.47,"tv":16.72,"id":16325787}]}]}
{"op":"mcm","clk":"989286823","pt":1580486397934,"mc":[{"id":"1.168133553","rc":[{"batb":[[0,1.16,3],[1,1.15,1.99],[2,1.13,10]],"ltp":1.47,"tv":16.72,"id":16325787}]}]}
{"op":"mcm","clk":"989288500","pt":1580486414305,"mc":[{"id":"1.168133553","rc":[{"batb":[[1,1.52,1.08]],"ltp":0.0,"tv":0.0,"id":27227336},{"batb":[[1,1.52,1.08]],"ltp":0.0,"tv":0.0,"id":21641292},{"batb":[[0,1.15,1.99],[1,1.14,3]],"ltp":1.47,"tv":16.72,"id":16325787}]}]}
{"op":"mcm","clk":"989289967","pt":1580486431494,"mc":[{"id":"1.168133553","rc":[{"batb":[[0,1.15,4.99],[1,1.13,10],[2,1.03,1628.12]],"ltp":1.47,"tv":16.72,"id":16325787}]}]}
{"op":"mcm","clk":"989290929","pt":1580486442324,"mc":[{"id":"1.168133553","rc":[{"batb":[[1,1.04,10]],"ltp":1.47,"tv":16.72,"id":16325787}]}]}
{"op":"mcm","clk":"989292007","pt":1580486453524,"mc":[{"id":"1.168133553","rc":[{"batb":[[0,1.15,1.99]],"ltp":1.47,"tv":16.72,"id":16325787}]}]}
{"op":"mcm","clk":"989292019","pt":1580486453802,"mc":[{"id":"1.168133553","rc":[{"batb":[[0,1.16,3],[1,1.15,1.99],[2,1.04,10]],"ltp":1.47,"tv":16.72,"id":16325787}]}]}
{"op":"mcm","clk":"989294422","pt":1580486473436,"mc":[{"id":"1.168133553","rc":[{"batb":[[0,1.15,1.99],[1,1.05,3]],"ltp":1.47,"tv":16.72,"id":16325787}]}]}
{"op":"mcm","clk":"989294858","pt":1580486478232,"mc":[{"id":"1.168133553","rc":[{"batb":[[0,1.06,1.99]],"ltp":1.47,"tv":16.72,"id":16325787}]}]}
{"op":"mcm","clk":"989295985","pt":1580486490062,"mc":[{"id":"1.168133553","rc":[{"batb":[[0,1.06,4.99],[1,1.04,10],[2,1.03,1628.12]],"ltp":1.47,"tv":16.72,"id":16325787}]}]}
{"op":"mcm","clk":"989298118","pt":1580486509647,"mc":[{"id":"1.168133553","rc":[{"batb":[[0,1.07,3],[1,1.06,1.99],[2,1.04,10]],"ltp":1.47,"tv":16.72,"id":16325787}]}]}
{"op":"mcm","clk":"989298879","pt":1580486517092,"mc":[{"id":"1.168133553","rc":[{"batb":[[2,1.03,1628.12]],"ltp":1.47,"tv":16.72,"id":16325787}]}]}
{"op":"mcm","clk":"989298977","pt":1580486517990,"mc":[{"id":"1.168133553","rc":[{"batb":[[2,1.04,6]],"ltp":1.47,"tv":16.72,"id":16325787}]}]}
{"op":"mcm","clk":"989299791","pt":1580486526078,"mc":[{"id":"1.168133553","rc":[{"batb":[[0,1.06,1.99],[1,1.05,3]],"ltp":1.47,"tv":16.72,"id":16325787}]}]}
{"op":"mcm","clk":"989301283","pt":1580486544008,"mc":[{"id":"1.168133553","rc":[{"batb":[[0,1.06,4.99],[1,1.04,6],[2,1.03,1628.12]],"ltp":1.47,"tv":16.72,"id":16325787}]}]}
{"op":"mcm","clk":"989302622","pt":1580486559732,"mc":[{"id":"1.168133553","rc":[{"batb":[[0,1.07,3],[1,1.06,1.99],[2,1.04,6]],"ltp":1.47,"tv":16.72,"id":16325787}]}]}
{"op":"mcm","clk":"989304174","pt":1580486578215,"mc":[{"id":"1.168133553","rc":[{"batb":[[0,1.06,1.99],[1,1.05,3]],"ltp":1.47,"tv":16.72,"id":16325787}]}]}
{"op":"mcm","clk":"989306076","pt":1580486595044,"mc":[{"id":"1.168133553","rc":[{"batb":[[0,1.06,4.99],[1,1.04,6],[2,1.03,1628.12]],"ltp":1.47,"tv":16.72,"id":16325787}]}]}
{"op":"mcm","clk":"989307940","pt":1580486611357,"mc":[{"id":"1.168133553","rc":[{"batb":[[0,1.07,3],[1,1.06,1.99],[2,1.04,6]],"ltp":1.47,"tv":16.72,"id":16325787}]}]}
{"op":"mcm","clk":"989309526","pt":1580486623966,"mc":[{"id":"1.168133553","rc":[{"batb":[[0,1.06,1.99],[1,1.05,3]],"ltp":1.47,"tv":16.72,"id":16325787}]}]}
{"op":"mcm","clk":"989310832","pt":1580486637263,"mc":[{"id":"1.168133553","rc":[{"batb":[[0,1.06,4.99],[1,1.04,6],[2,1.03,1628.12]],"ltp":1.47,"tv":16.72,"id":16325787}]}]}
{"op":"mcm","clk":"989312113","pt":1580486650111,"mc":[{"id":"1.168133553","rc":[{"batb":[[0,1.07,3],[1,1.06,1.99],[2,1.04,6]],"ltp":1.47,"tv":16.72,"id":16325787}]}]}
{"op":"mcm","clk":"989313658","pt":1580486660436,"mc":[{"id":"1.168133553","rc":[{"batb":[[0,1.06,1.99],[1,1.05,3]],"ltp":1.47,"tv":16.72,"id":16325787}]}]}
{"op":"mcm","clk":"989315293","pt":1580486673840,"mc":[{"id":"1.168133553","rc":[{"batb":[[0,1.06,4.99],[1,1.04,6],[2,1.03,1628.12]],"ltp":1.47,"tv":16.72,"id":16325787}]}]}
{"op":"mcm","clk":"989316662","pt":1580486686363,"mc":[{"id":"1.168133553","rc":[{"batb":[[0,1.07,3],[1,1.06,1.99],[2,1.04,6]],"ltp":1.47,"tv":16.72,"id":16325787}]}]}
{"op":"mcm","clk":"989318177","pt":1580486700709,"mc":[{"id":"1.168133553","rc":[{"batb":[[0,1.06,1.99],[1,1.05,3]],"ltp":1.47,"tv":16.72,"id":16325787}]}]}
{"op":"mcm","clk":"989319450","pt":1580486712718,"mc":[{"id":"1.168133553","rc":[{"batb":[[0,1.06,4.99],[1,1.04,6],[2,1.03,1628.12]],"ltp":1.47,"tv":16.72,"id":16325787}]}]}
{"op":"mcm","clk":"989320567","pt":1580486725072,"mc":[{"id":"1.168133553","rc":[{"batb":[[0,1.07,3],[1,1.06,1.99],[2,1.04,6]],"ltp":1.47,"tv":16.72,"id":16325787}]}]}
{"op":"mcm","clk":"989321747","pt":1580486737524,"mc":[{"id":"1.168133553","rc":[{"batb":[[0,1.06,1.99],[1,1.04,6],[2,1.03,1628.12]],"ltp":1.47,"tv":16.72,"id":16325787}]}]}
{"op":"mcm","clk":"989321759","pt":1580486737623,"mc":[{"id":"1.168133553","rc":[{"batb":[[1,1.05,3],[2,1.04,6]],"ltp":1.47,"tv":16.72,"id":16325787}]}]}
{"op":"mcm","clk":"989323369","pt":1580486754475,"mc":[{"id":"1.168133553","rc":[{"batb":[[1,1.04,6],[2,1.03,1628.12]],"ltp":1.47,"tv":16.72,"id":16325787}]}]}
{"op":"mcm","clk":"989323432","pt":1580486755051,"mc":[{"id":"1.168133553","rc":[{"batb":[[0,1.06,4.99]],"ltp":1.47,"tv":16.72,"id":16325787}]}]}
{"op":"mcm","clk":"989324879","pt":1580486768468,"mc":[{"id":"1.168133553","rc":[{"batb":[[0,1.07,3],[1,1.06,1.99],[2,1.04,6]],"ltp":1.47,"tv":16.72,"id":16325787}]}]}
{"op":"mcm","clk":"989326188","pt":1580486780413,"mc":[{"id":"1.168133553","rc":[{"batl":[[0,1.57,1.68],[1,1.59,2.2],[2,2,2]],"ltp":1.47,"tv":16.72,"id":16325787}]}]}
{"op":"mcm","clk":"989326255","pt":1580486781006,"mc":[{"id":"1.168133553","rc":[{"batl":[[0,1.59,2.2],[1,2,2],[2,3.1,4]],"ltp":1.47,"tv":16.72,"id":16325787}]}]}
{"op":"mcm","clk":"989326428","pt":1580486782488,"mc":[{"id":"1.168133553","rc":[{"batb":[[0,1.06,1.99],[1,1.05,3]],"ltp":1.47,"tv":16.72,"id":16325787}]}]}
{"op":"mcm","clk":"989327739","pt":1580486795206,"mc":[{"id":"1.168133553","rc":[{"batb":[[0,1.06,3],[1,1.05,1.99]],"ltp":1.47,"tv":16.72,"id":16325787}]}]}
{"op":"mcm","clk":"989328767","pt":1580486805239,"mc":[{"id":"1.168133553","rc":[{"batb":[[0,1.05,4.99],[1,1.04,6],[2,1.03,1628.12]],"ltp":1.47,"tv":16.72,"id":16325787}]}]}
{"op":"mcm","clk":"989330169","pt":1580486818071,"mc":[{"id":"1.168133553","rc":[{"batb":[[0,1.06,3],[1,1.05,1.99],[2,1.04,6]],"ltp":1.47,"tv":16.72,"id":16325787}]}]}
{"op":"mcm","clk":"989331412","pt":1580486829874,"mc":[{"id":"1.168133553","rc":[{"batb":[[0,1.05,4.99],[1,1.04,6],[2,1.03,1628.12]],"ltp":1.47,"tv":16.72,"id":16325787}]}]}
{"op":"mcm","clk":"989332819","pt":1580486845007,"mc":[{"id":"1.168133553","rc":[{"batb":[[0,1.06,3],[1,1.05,1.99],[2,1.04,6]],"ltp":1.47,"tv":16.72,"id":16325787}]}]}
{"op":"mcm","clk":"989343546","pt":1580486858027,"mc":[{"id":"1.168133553","rc":[{"batb":[[0,1.05,4.99],[1,1.04,6],[2,1.03,1628.12]],"ltp":1.47,"tv":16.72,"id":16325787}]}]}
{"op":"mcm","clk":"989344703","pt":1580486871092,"mc":[{"id":"1.168133553","rc":[{"batb":[[0,1.06,3],[1,1.05,1.99],[2,1.04,6]],"ltp":1.47,"tv":16.72,"id":16325787}]}]}
{"op":"mcm","clk":"989345939","pt":1580486883927,"mc":[{"id":"1.168133553","rc":[{"batb":[[0,1.05,4.99],[1,1.04,6],[2,1.03,1628.12]],"ltp":1.47,"tv":16.72,"id":16325787}]}]}
{"op":"mcm","clk":"989346949","pt":1580486895824,"mc":[{"id":"1.168133553","rc":[{"batb":[[0,1.06,3],[1,1.05,1.99],[2,1.04,6]],"ltp":1.47,"tv":16.72,"id":16325787}]}]}
{"op":"mcm","clk":"989347830","pt":1580486906247,"mc":[{"id":"1.168133553","rc":[{"batb":[[0,1.05,4.99],[1,1.04,6],[2,1.03,1628.12]],"ltp":1.47,"tv":16.72,"id":16325787}]}]}
{"op":"mcm","clk":"989348794","pt":1580486918483,"mc":[{"id":"1.168133553","rc":[{"batb":[[0,1.06,3],[1,1.05,1.99],[2,1.04,6]],"ltp":1.47,"tv":16.72,"id":16325787}]}]}
{"op":"mcm","clk":"989349478","pt":1580486926187,"mc":[{"id":"1.168133553","rc":[{"batb":[[0,1.07,1.99],[1,1.06,3]],"ltp":1.47,"tv":16.72,"id":16325787}]}]}
{"op":"mcm","clk":"989349770","pt":1580486929176,"mc":[{"id":"1.168133553","rc":[{"batb":[[0,1.07,4.99],[1,1.04,6],[2,1.03,1628.12]],"ltp":1.47,"tv":16.72,"id":16325787}]}]}
{"op":"mcm","clk":"989350530","pt":1580486938275,"mc":[{"id":"1.168133553","rc":[{"batb":[[0,1.08,3],[1,1.07,1.99],[2,1.04,6]],"ltp":1.47,"tv":16.72,"id":16325787}]}]}
{"op":"mcm","clk":"989352126","pt":1580486955289,"mc":[{"id":"1.168133553","rc":[{"batb":[[0,1.07,1.99],[1,1.05,3]],"ltp":1.47,"tv":16.72,"id":16325787}]}]}
{"op":"mcm","clk":"989353271","pt":1580486968113,"mc":[{"id":"1.168133553","rc":[{"batb":[[1,1.06,3]],"ltp":1.47,"tv":16.72,"id":16325787}]}]}
{"op":"mcm","clk":"989354566","pt":1580486983020,"mc":[{"id":"1.168133553","rc":[{"batb":[[0,1.07,4.99],[1,1.04,6],[2,1.03,1628.12]],"ltp":1.47,"tv":16.72,"id":16325787}]}]}
{"op":"mcm","clk":"989355601","pt":1580486995521,"mc":[{"id":"1.168133553","rc":[{"batb":[[0,1.08,3],[1,1.07,1.99],[2,1.04,6]],"ltp":1.47,"tv":16.72,"id":16325787}]}]}
{"op":"mcm","clk":"989357005","pt":1580487010265,"mc":[{"id":"1.168133553","rc":[{"batb":[[0,1.07,1.99],[1,1.05,3]],"ltp":1.47,"tv":16.72,"id":16325787}]}]}
{"op":"mcm","clk":"989358065","pt":1580487021685,"mc":[{"id":"1.168133553","rc":[{"batb":[[0,1.06,1.99]],"ltp":1.47,"tv":16.72,"id":16325787}]}]}
{"op":"mcm","clk":"989358364","pt":1580487024548,"mc":[{"id":"1.168133553","rc":[{"batb":[[0,1.06,4.99],[1,1.04,6],[2,1.03,1628.12]],"ltp":1.47,"tv":16.72,"id":16325787}]}]}
{"op":"mcm","clk":"989359828","pt":1580487040484,"mc":[{"id":"1.168133553","rc":[{"batb":[[0,1.06,1.99]],"ltp":1.47,"tv":16.72,"id":16325787}]}]}
{"op":"mcm","clk":"989359840","pt":1580487040587,"mc":[{"id":"1.168133553","rc":[{"batb":[[0,1.07,3],[1,1.06,1.99],[2,1.04,6]],"ltp":1.47,"tv":16.72,"id":16325787}]}]}
{"op":"mcm","clk":"989361297","pt":1580487055737,"mc":[{"id":"1.168133553","rc":[{"batb":[[0,1.06,1.99],[1,1.05,3]],"ltp":1.47,"tv":16.72,"id":16325787}]}]}
{"op":"mcm","clk":"989362797","pt":1580487070768,"mc":[{"id":"1.168133553","rc":[{"batb":[[0,1.06,4.99],[1,1.04,6],[2,1.03,1628.12]],"ltp":1.47,"tv":16.72,"id":16325787}]}]}
{"op":"mcm","clk":"989364218","pt":1580487086948,"mc":[{"id":"1.168133553","rc":[{"batb":[[0,1.07,3],[1,1.06,1.99],[2,1.04,6]],"ltp":1.47,"tv":16.72,"id":16325787}]}]}
{"op":"mcm","clk":"989364858","pt":1580487094386,"mc":[{"id":"1.168133553","rc":[{"batb":[[0,1.07,13]],"ltp":1.47,"tv":16.72,"id":16325787}]}]}
{"op":"mcm","clk":"989365425","pt":1580487100574,"mc":[{"id":"1.168133553","rc":[{"batb":[[0,1.08,3],[1,1.07,10],[2,1.06,1.99]],"ltp":1.47,"tv":16.72,"id":16325787}]}]}
{"op":"mcm","clk":"989366891","pt":1580487116759,"mc":[{"id":"1.168133553","rc":[{"batb":[[0,1.09,1.99],[1,1.08,3],[2,1.07,10]],"ltp":1.47,"tv":16.72,"id":16325787}]}]}
{"op":"mcm","clk":"989367467","pt":1580487123574,"mc":[{"id":"1.168133553","rc":[{"batb":[[0,1.09,4.99],[1,1.07,10],[2,1.04,6]],"ltp":1.47,"tv":16.72,"id":16325787}]}]}
{"op":"mcm","clk":"989368625","pt":1580487136453,"mc":[{"id":"1.168133553","rc":[{"batb":[[0,1.09,1.99]],"ltp":1.47,"tv":16.72,"id":16325787}]}]}
{"op":"mcm","clk":"989368643","pt":1580487136663,"mc":[{"id":"1.168133553","rc":[{"batb":[[0,1.1,3],[1,1.09,1.99],[2,1.07,10]],"ltp":1.47,"tv":16.72,"id":16325787}]}]}
{"op":"mcm","clk":"989369605","pt":1580487147553,"mc":[{"id":"1.168133553","rc":[{"batb":[[0,1.09,1.99],[1,1.07,10],[2,1.04,6]],"ltp":1.47,"tv":16.72,"id":16325787}]}]}
{"op":"mcm","clk":"989369612","pt":1580487147662,"mc":[{"id":"1.168133553","rc":[{"batb":[[1,1.08,3],[2,1.07,10]],"ltp":1.47,"tv":16.72,"id":16325787}]}]}
{"op":"mcm","clk":"989371098","pt":1580487163271,"mc":[{"id":"1.168133553","rc":[{"batb":[[0,1.09,4.99],[1,1.04,6],[2,1.03,1628.12]],"ltp":1.47,"tv":16.72,"id":16325787}]}]}
{"op":"mcm","clk":"989372326","pt":1580487175964,"mc":[{"id":"1.168133553","rc":[{"batb":[[0,1.1,3],[1,1.09,1.99],[2,1.04,6]],"ltp":1.47,"tv":16.72,"id":16325787}]}]}
{"op":"mcm","clk":"989374051","pt":1580487192477,"mc":[{"id":"1.168133553","rc":[{"batb":[[0,1.09,1.99],[1,1.05,3]],"ltp":1.47,"tv":16.72,"id":16325787}]}]}
{"op":"mcm","clk":"989375904","pt":1580487209299,"mc":[{"id":"1.168133553","rc":[{"batb":[[1,1.06,3]],"ltp":1.47,"tv":16.72,"id":16325787}]}]}
{"op":"mcm","clk":"989376111","pt":1580487211303,"mc":[{"id":"1.168133553","rc":[{"batb":[[0,1.07,1.99]],"ltp":1.47,"tv":16.72,"id":16325787}]}]}
{"op":"mcm","clk":"989377286","pt":1580487223222,"mc":[{"id":"1.168133553","rc":[{"batb":[[0,1.07,4.99],[1,1.04,6],[2,1.03,1628.12]],"ltp":1.47,"tv":16.72,"id":16325787}]}]}
{"op":"mcm","clk":"989378416","pt":1580487234931,"mc":[{"id":"1.168133553","rc":[{"batb":[[0,1.08,3],[1,1.07,1.99],[2,1.04,6]],"ltp":1.47,"tv":16.72,"id":16325787}]}]}
{"op":"mcm","clk":"989380302","pt":1580487253740,"mc":[{"id":"1.168133553","rc":[{"batb":[[0,1.07,1.99],[1,1.05,3]],"ltp":1.47,"tv":16.72,"id":16325787}]}]}
{"op":"mcm","clk":"989380671","pt":1580487257549,"mc":[{"id":"1.168133553","rc":[{"batb":[[0,1.06,1.99]],"ltp":1.47,"tv":16.72,"id":16325787}]}]}
{"op":"mcm","clk":"989381659","pt":1580487267072,"mc":[{"id":"1.168133553","rc":[{"batb":[[0,1.06,4.99],[1,1.04,6],[2,1.03,1628.12]],"ltp":1.47,"tv":16.72,"id":16325787}]}]}
{"op":"mcm","clk":"989383035","pt":1580487279692,"mc":[{"id":"1.168133553","rc":[{"batb":[[0,1.07,3],[1,1.06,1.99],[2,1.04,6]],"ltp":1.47,"tv":16.72,"id":16325787}]}]}
{"op":"mcm","clk":"989384161","pt":1580487291400,"mc":[{"id":"1.168133553","rc":[{"batb":[[0,1.06,1.99],[1,1.05,3]],"ltp":1.47,"tv":16.72,"id":16325787}]}]}
{"op":"mcm","clk":"989385203","pt":1580487302153,"mc":[{"id":"1.168133553","rc":[{"batb":[[0,1.06,11.99]],"ltp":1.47,"tv":16.72,"id":16325787}]}]}
{"op":"mcm","clk":"989385646","pt":1580487306131,"mc":[{"id":"1.168133553","rc":[{"batb":[[0,1.07,3],[1,1.06,11.99]],"ltp":1.47,"tv":16.72,"id":16325787}]}]}
{"op":"mcm","clk":"989389352","pt":1580487342546,"mc":[{"id":"1.168133553","rc":[{"batb":[[0,1.08,1.99],[1,1.07,3],[2,1.06,10]],"ltp":1.47,"tv":16.72,"id":16325787}]}]}
{"op":"mcm","clk":"989389873","pt":1580487348270,"mc":[{"id":"1.168133553","rc":[{"batb":[[0,1.08,4.99],[1,1.06,10],[2,1.04,6]],"ltp":1.47,"tv":16.72,"id":16325787}]}]}
{"op":"mcm","clk":"989391023","pt":1580487360569,"mc":[{"id":"1.168133553","rc":[{"batb":[[0,1.09,3],[1,1.08,1.99],[2,1.06,10]],"ltp":1.47,"tv":16.72,"id":16325787}]}]}
{"op":"mcm","clk":"989392223","pt":1580487372563,"mc":[{"id":"1.168133553","rc":[{"batb":[[0,1.08,1.99],[1,1.05,3],[2,1.04,6]],"ltp":1.47,"tv":16.72,"id":16325787}]}]}
{"op":"mcm","clk":"989392940","pt":1580487380364,"mc":[{"id":"1.168133553","rc":[{"batb":[[0,1.06,1.99]],"ltp":1.47,"tv":16.72,"id":16325787}]}]}
{"op":"mcm","clk":"989393380","pt":1580487385196,"mc":[{"id":"1.168133553","rc":[{"batb":[[0,1.06,4.99],[1,1.04,6],[2,1.03,1628.12]],"ltp":1.47,"tv":16.72,"id":16325787}]}]}
{"op":"mcm","clk":"989394350","pt":1580487395719,"mc":[{"id":"1.168133553","rc":[{"batb":[[0,1.07,3],[1,1.06,1.99],[2,1.04,6]],"ltp":1.47,"tv":16.72,"id":16325787}]}]}
{"op":"mcm","clk":"989395366","pt":1580487406208,"mc":[{"id":"1.168133553","rc":[{"batb":[[0,1.06,1.99],[1,1.05,3]],"ltp":1.47,"tv":16.72,"id":16325787}]}]}
{"op":"mcm","clk":"989396535","pt":1580487419547,"mc":[{"id":"1.168133553","rc":[{"batb":[[1,1.04,6],[2,1.03,1628.12]],"ltp":1.47,"tv":16.72,"id":16325787}]}]}
{"op":"mcm","clk":"989396629","pt":1580487420572,"mc":[{"id":"1.168133553","rc":[{"batb":[[0,1.06,4.99]],"ltp":1.47,"tv":16.72,"id":16325787}]}]}
{"op":"mcm","clk":"989397989","pt":1580487435223,"mc":[{"id":"1.168133553","rc":[{"batb":[[0,1.07,3],[1,1.06,1.99],[2,1.04,6]],"ltp":1.47,"tv":16.72,"id":16325787}]}]}
{"op":"mcm","clk":"989399377","pt":1580487450854,"mc":[{"id":"1.168133553","rc":[{"batb":[[0,1.06,1.99],[1,1.05,3]],"ltp":1.47,"tv":16.72,"id":16325787}]}]}
{"op":"mcm","clk":"989400461","pt":1580487463300,"mc":[{"id":"1.168133553","rc":[{"batb":[[0,1.06,4.99],[1,1.04,6],[2,1.03,1628.12]],"ltp":1.47,"tv":16.72,"id":16325787}]}]}
{"op":"mcm","clk":"989401842","pt":1580487478523,"mc":[{"id":"1.168133553","rc":[{"batb":[[0,1.07,3],[1,1.06,1.99],[2,1.04,6]],"ltp":1.47,"tv":16.72,"id":16325787}]}]}
{"op":"mcm","clk":"989403141","pt":1580487493312,"mc":[{"id":"1.168133553","rc":[{"batb":[[0,1.06,1.99],[1,1.05,3]],"ltp":1.47,"tv":16.72,"id":16325787}]}]}
{"op":"mcm","clk":"989404163","pt":1580487504165,"mc":[{"id":"1.168133553","rc":[{"batb":[[0,1.06,4.99],[1,1.04,6],[2,1.03,1628.12]],"ltp":1.47,"tv":16.72,"id":16325787}]}]}
{"op":"mcm","clk":"989405435","pt":1580487518230,"mc":[{"id":"1.168133553","rc":[{"batb":[[0,1.07,3],[1,1.06,1.99],[2,1.04,6]],"ltp":1.47,"tv":16.72,"id":16325787}]}]}
{"op":"mcm","clk":"989406443","pt":1580487530542,"mc":[{"id":"1.168133553","rc":[{"batb":[[0,1.06,1.99],[1,1.04,6],[2,1.03,1628.12]],"ltp":1.47,"tv":16.72,"id":16325787}]}]}
{"op":"mcm","clk":"989406451","pt":1580487530638,"mc":[{"id":"1.168133553","rc":[{"batb":[[1,1.05,3],[2,1.04,6]],"ltp":1.47,"tv":16.72,"id":16325787}]}]}
{"op":"mcm","clk":"989407953","pt":1580487549178,"mc":[{"id":"1.168133553","rc":[{"batb":[[0,1.06,4.99],[1,1.04,6],[2,1.03,1628.12]],"ltp":1.47,"tv":16.72,"id":16325787}]}]}
{"op":"mcm","clk":"989409297","pt":1580487566193,"mc":[{"id":"1.168133553","rc":[{"batb":[[0,1.07,3],[1,1.06,1.99],[2,1.04,6]],"ltp":1.47,"tv":16.72,"id":16325787}]}]}
{"op":"mcm","clk":"989410400","pt":1580487579925,"mc":[{"id":"1.168133553","rc":[{"batb":[[0,1.06,1.99],[1,1.05,3]],"ltp":1.47,"tv":16.72,"id":16325787}]}]}
{"op":"mcm","clk":"989411417","pt":1580487594220,"mc":[{"id":"1.168133553","rc":[{"batb":[[0,1.06,4.99],[1,1.04,6],[2,1.03,1628.12]],"ltp":1.47,"tv":16.72,"id":16325787}]}]}
{"op":"mcm","clk":"989412484","pt":1580487607067,"mc":[{"id":"1.168133553","rc":[{"batb":[[0,1.07,3],[1,1.06,1.99],[2,1.04,6]],"ltp":1.47,"tv":16.72,"id":16325787}]}]}
{"op":"mcm","clk":"989413845","pt":1580487623180,"mc":[{"id":"1.168133553","rc":[{"batb":[[0,1.06,1.99],[1,1.05,3]],"ltp":1.47,"tv":16.72,"id":16325787}]}]}
{"op":"mcm","clk":"989415234","pt":1580487640371,"mc":[{"id":"1.168133553","rc":[{"batb":[[0,1.06,4.99],[1,1.04,6],[2,1.03,1628.12]],"ltp":1.47,"tv":16.72,"id":16325787}]}]}
{"op":"mcm","clk":"989416104","pt":1580487651004,"mc":[{"id":"1.168133553","rc":[{"batb":[[1,1.05,10],[2,1.04,6]],"ltp":1.47,"tv":16.72,"id":16325787}]}]}
{"op":"mcm","clk":"989416228","pt":1580487652313,"mc":[{"id":"1.168133553","rc":[{"batb":[[0,1.07,3],[1,1.06,1.99],[2,1.05,10]],"ltp":1.47,"tv":16.72,"id":16325787}]}]}
{"op":"mcm","clk":"989417869","pt":1580487669331,"mc":[{"id":"1.168133553","rc":[{"batb":[[0,1.06,4.99],[1,1.05,10],[2,1.04,6]],"ltp":1.47,"tv":16.72,"id":16325787}]}]}
{"op":"mcm","clk":"989419495","pt":1580487688843,"mc":[{"id":"1.168133553","rc":[{"batb":[[0,1.07,3],[1,1.06,1.99],[2,1.05,10]],"ltp":1.47,"tv":16.72,"id":16325787}]}]}
{"op":"mcm","clk":"989420968","pt":1580487706552,"mc":[{"id":"1.168133553","rc":[{"batb":[[0,1.06,1.99],[1,1.05,10],[2,1.04,6]],"ltp":1.47,"tv":16.72,"id":16325787}]}]}
{"op":"mcm","clk":"989420987","pt":1580487706659,"mc":[{"id":"1.168133553","rc":[{"batb":[[0,1.06,4.99]],"ltp":1.47,"tv":16.72,"id":16325787}]}]}
{"op":"mcm","clk":"989422007","pt":1580487718807,"mc":[{"id":"1.168133553","rc":[{"batb":[[0,1.07,3],[1,1.06,1.99],[2,1.05,10]],"ltp":1.47,"tv":16.72,"id":16325787}]}]}
{"op":"mcm","clk":"989422144","pt":1580487720350,"mc":[{"id":"1.168133553","rc":[{"batb":[[0,1.07,13],[2,1.04,6]],"ltp":1.47,"tv":16.72,"id":16325787}]}]}
{"op":"mcm","clk":"989423259","pt":1580487733075,"mc":[{"id":"1.168133553","rc":[{"batb":[[0,1.08,1.99],[1,1.07,13]],"ltp":1.47,"tv":16.72,"id":16325787}]}]}
{"op":"mcm","clk":"989423384","pt":1580487734546,"mc":[{"id":"1.168133553","rc":[{"batb":[[1,1.07,10]],"ltp":1.47,"tv":16.72,"id":16325787}]}]}
{"op":"mcm","clk":"989423441","pt":1580487735178,"mc":[{"id":"1.168133553","rc":[{"batb":[[0,1.08,4.99]],"ltp":1.47,"tv":16.72,"id":16325787}]}]}
{"op":"mcm","clk":"989424638","pt":1580487749395,"mc":[{"id":"1.168133553","rc":[{"batb":[[0,1.09,3],[1,1.08,1.99],[2,1.07,10]],"ltp":1.47,"tv":16.72,"id":16325787}]}]}
{"op":"mcm","clk":"989435279","pt":1580487762315,"mc":[{"id":"1.168133553","rc":[{"batb":[[0,1.08,4.99],[1,1.07,10],[2,1.04,6]],"ltp":1.47,"tv":16.72,"id":16325787}]}]}
{"op":"mcm","clk":"989436761","pt":1580487779426,"mc":[{"id":"1.168133553","rc":[{"batb":[[0,1.09,3],[1,1.08,1.99],[2,1.07,10]],"ltp":1.47,"tv":16.72,"id":16325787}]}]}
{"op":"mcm","clk":"989437614","pt":1580487789135,"mc":[{"id":"1.168133553","rc":[{"batb":[[0,1.09,13],[2,1.04,6]],"ltp":1.47,"tv":16.72,"id":16325787}]}]}
{"op":"mcm","clk":"989438163","pt":1580487795197,"mc":[{"id":"1.168133553","rc":[{"batb":[[0,1.1,3],[1,1.09,10],[2,1.08,1.99]],"ltp":1.47,"tv":16.72,"id":16325787}]}]}
{"op":"mcm","clk":"989439943","pt":1580487815022,"mc":[{"id":"1.168133553","rc":[{"batb":[[0,1.11,1.99],[1,1.1,3],[2,1.09,10]],"ltp":1.47,"tv":16.72,"id":16325787}]}]}
{"op":"mcm","clk":"989440424","pt":1580487819795,"mc":[{"id":"1.168133553","rc":[{"batb":[[0,1.11,4.99],[1,1.09,10],[2,1.04,6]],"ltp":1.47,"tv":16.72,"id":16325787}]}]}
{"op":"mcm","clk":"989441549","pt":1580487831936,"mc":[{"id":"1.168133553","rc":[{"batb":[[0,1.12,3],[1,1.11,1.99],[2,1.09,10]],"ltp":1.47,"tv":16.72,"id":16325787}]}]}
{"op":"mcm","clk":"989442656","pt":1580487843507,"mc":[{"id":"1.168133553","rc":[{"batb":[[0,1.11,1.99],[1,1.1,3]],"ltp":1.47,"tv":16.72,"id":16325787}]}]}
{"op":"mcm","clk":"989443756","pt":1580487855568,"mc":[{"id":"1.168133553","rc":[{"batb":[[1,1.09,10],[2,1.04,6]],"ltp":1.47,"tv":16.72,"id":16325787}]}]}
{"op":"mcm","clk":"989443767","pt":1580487855659,"mc":[{"id":"1.168133553","rc":[{"batb":[[0,1.11,4.99]],"ltp":1.47,"tv":16.72,"id":16325787}]}]}
{"op":"mcm","clk":"989443966","pt":1580487858250,"mc":[{"id":"1.168133553","rc":[{"batb":[[1,1.05,10]],"ltp":1.47,"tv":16.72,"id":16325787}]}]}
{"op":"mcm","clk":"989445107","pt":1580487871470,"mc":[{"id":"1.168133553","rc":[{"batb":[[0,1.11,1.99]],"ltp":1.47,"tv":16.72,"id":16325787}]}]}
{"op":"mcm","clk":"989445115","pt":1580487871587,"mc":[{"id":"1.168133553","rc":[{"batb":[[0,1.12,3],[1,1.11,1.99],[2,1.05,10]],"ltp":1.47,"tv":16.72,"id":16325787}]}]}
{"op":"mcm","clk":"989446256","pt":1580487884471,"mc":[{"id":"1.168133553","rc":[{"batb":[[0,1.11,1.99],[1,1.06,3]],"ltp":1.47,"tv":16.72,"id":16325787}]}]}
{"op":"mcm","clk":"989447325","pt":1580487897401,"mc":[{"id":"1.168133553","rc":[{"batb":[[1,1.07,3]],"ltp":1.47,"tv":16.72,"id":16325787}]}]}
{"op":"mcm","clk":"989447648","pt":1580487901112,"mc":[{"id":"1.168133553","rc":[{"batb":[[0,1.08,1.99]],"ltp":1.47,"tv":16.72,"id":16325787}]}]}
{"op":"mcm","clk":"989448271","pt":1580487908209,"mc":[{"id":"1.168133553","rc":[{"batb":[[0,1.08,4.99],[1,1.05,10],[2,1.04,6]],"ltp":1.47,"tv":16.72,"id":16325787}]}]}
{"op":"mcm","clk":"989449331","pt":1580487919830,"mc":[{"id":"1.168133553","rc":[{"batb":[[0,1.09,3],[1,1.08,1.99],[2,1.05,10]],"ltp":1.47,"tv":16.72,"id":16325787}]}]}
{"op":"mcm","clk":"989449979","pt":1580487927356,"mc":[{"id":"1.168133553","rc":[{"batb":[[0,1.09,13],[2,1.04,6]],"ltp":1.47,"tv":16.72,"id":16325787}]}]}
{"op":"mcm","clk":"989450466","pt":1580487933243,"mc":[{"id":"1.168133553","rc":[{"batb":[[0,1.1,3],[1,1.09,10],[2,1.08,1.99]],"ltp":1.47,"tv":16.72,"id":16325787}]}]}
{"op":"mcm","clk":"989450955","pt":1580487938755,"mc":[{"id":"1.168133553","rc":[{"batb":[[0,1.11,1.99],[1,1.1,3],[2,1.09,10]],"ltp":1.47,"tv":16.72,"id":16325787}]}]}
{"op":"mcm","clk":"989451490","pt":1580487944935,"mc":[{"id":"1.168133553","rc":[{"batb":[[0,1.11,4.99],[1,1.09,10],[2,1.04,6]],"ltp":1.47,"tv":16.72,"id":16325787}]}]}
{"op":"mcm","clk":"989452546","pt":1580487957104,"mc":[{"id":"1.168133553","rc":[{"batb":[[0,1.12,3],[1,1.11,1.99],[2,1.09,10]],"ltp":1.47,"tv":16.72,"id":16325787}]}]}
{"op":"mcm","clk":"989453678","pt":1580487969863,"mc":[{"id":"1.168133553","rc":[{"batb":[[0,1.11,1.99],[1,1.1,3]],"ltp":1.47,"tv":16.72,"id":16325787}]}]}
{"op":"mcm","clk":"989454636","pt":1580487981120,"mc":[{"id":"1.168133553","rc":[{"batb":[[0,1.11,4.99],[1,1.09,10],[2,1.04,6]],"ltp":1.47,"tv":16.72,"id":16325787}]}]}
{"op":"mcm","clk":"989455893","pt":1580487996550,"mc":[{"id":"1.168133553","rc":[{"batb":[[0,1.12,3],[1,1.11,1.99]],"ltp":1.47,"tv":16.72,"id":16325787}]}]}
{"op":"mcm","clk":"989455957","pt":1580487997316,"mc":[{"id":"1.168133553","rc":[{"batb":[[0,1.12,13]],"ltp":1.47,"tv":16.72,"id":16325787}]}]}
{"op":"mcm","clk":"989456930","pt":1580488007549,"mc":[{"id":"1.168133553","rc":[{"batb":[[0,1.13,3],[1,1.12,10],[2,1.11,1.99]],"ltp":1.47,"tv":16.72,"id":16325787}]}]}
{"op":"mcm","clk":"989457938","pt":1580488018380,"mc":[{"id":"1.168133553","rc":[{"batb":[[0,1.14,1.99],[1,1.13,3],[2,1.12,10]],"ltp":1.47,"tv":16.72,"id":16325787}]}]}
{"op":"mcm","clk":"989458034","pt":1580488019379,"mc":[{"id":"1.168133553","rc":[{"batb":[[0,1.14,4.99],[1,1.12,10],[2,1.04,6]],"ltp":1.47,"tv":16.72,"id":16325787}]}]}
{"op":"mcm","clk":"989459147","pt":1580488031557,"mc":[{"id":"1.168133553","rc":[{"batb":[[0,1.15,3],[1,1.14,1.99],[2,1.12,10]],"ltp":1.47,"tv":16.72,"id":16325787}]}]}
{"op":"mcm","clk":"989460163","pt":1580488043375,"mc":[{"id":"1.168133553","rc":[{"batb":[[0,1.14,1.99],[1,1.13,3]],"ltp":1.47,"tv":16.72,"id":16325787}]}]}
{"op":"mcm","clk":"989461630","pt":1580488056889,"mc":[{"id":"1.168133553","rc":[{"batb":[[0,1.14,4.99],[1,1.12,10],[2,1.04,6]],"ltp":1.47,"tv":16.72,"id":16325787}]}]}
{"op":"mcm","clk":"989462414","pt":1580488065980,"mc":[{"id":"1.168133553","rc":[{"batb":[[1,1.05,10]],"ltp":1.47,"tv":16.72,"id":16325787}]}]}
{"op":"mcm","clk":"989462556","pt":1580488067820,"mc":[{"id":"1.168133553","rc":[{"batb":[[0,1.15,3],[1,1.14,1.99],[2,1.05,10]],"ltp":1.47,"tv":16.72,"id":16325787}]}]}
{"op":"mcm","clk":"989463683","pt":1580488078543,"mc":[{"id":"1.168133553","rc":[{"batb":[[0,1.14,1.99],[1,1.05,10],[2,1.03,1628.12]],"ltp":1.47,"tv":16.72,"id":16325787}]}]}
{"op":"mcm","clk":"989463692","pt":1580488078682,"mc":[{"id":"1.168133553","rc":[{"batb":[[1,1.06,3],[2,1.05,10]],"ltp":1.47,"tv":16.72,"id":16325787}]}]}
{"op":"mcm","clk":"989465007","pt":1580488091480,"mc":[{"id":"1.168133553","rc":[{"batb":[[1,1.05,10],[2,1.04,6]],"ltp":1.47,"tv":16.72,"id":16325787}]}]}
{"op":"mcm","clk":"989465019","pt":1580488091587,"mc":[{"id":"1.168133553","rc":[{"batb":[[1,1.07,3],[2,1.05,10]],"ltp":1.47,"tv":16.72,"id":16325787}]}]}
{"op":"mcm","clk":"989465926","pt":1580488101996,"mc":[{"id":"1.168133553","rc":[{"batb":[[1,1.08,3]],"ltp":1.47,"tv":16.72,"id":16325787}]}]}
{"op":"mcm","clk":"989466380","pt":1580488106402,"mc":[{"id":"1.168133553","rc":[{"batb":[[0,1.09,1.99]],"ltp":1.47,"tv":16.72,"id":16325787}]}]}
{"op":"mcm","clk":"989467147","pt":1580488113711,"mc":[{"id":"1.168133553","rc":[{"batb":[[0,1.09,4.99],[1,1.05,10],[2,1.04,6]],"ltp":1.47,"tv":16.72,"id":16325787}]}]}
{"op":"mcm","clk":"989468155","pt":1580488123393,"mc":[{"id":"1.168133553","rc":[{"batb":[[0,1.1,3],[1,1.09,1.99],[2,1.05,10]],"ltp":1.47,"tv":16.72,"id":16325787}]}]}
{"op":"mcm","clk":"989469353","pt":1580488133524,"mc":[{"id":"1.168133553","rc":[{"batb":[[0,1.09,1.99],[1,1.05,10],[2,1.04,6]],"ltp":1.47,"tv":16.72,"id":16325787}]}]}
{"op":"mcm","clk":"989469378","pt":1580488133691,"mc":[{"id":"1.168133553","rc":[{"batb":[[1,1.06,3],[2,1.05,10]],"ltp":1.47,"tv":16.72,"id":16325787}]}]}
{"op":"mcm","clk":"989469491","pt":1580488134716,"mc":[{"id":"1.168133553","rc":[{"batb":[[1,1.07,10],[2,1.06,3]],"ltp":1.47,"tv":16.72,"id":16325787}]}]}
{"op":"mcm","clk":"989470454","pt":1580488143704,"mc":[{"id":"1.168133553","rc":[{"batb":[[1,1.08,3],[2,1.07,10]],"ltp":1.47,"tv":16.72,"id":16325787}]}]}
{"op":"mcm","clk":"989471859","pt":1580488158551,"mc":[{"id":"1.168133553","rc":[{"batb":[[1,1.07,10],[2,1.04,6]],"ltp":1.47,"tv":16.72,"id":16325787}]}]}
{"op":"mcm","clk":"989471870","pt":1580488158659,"mc":[{"id":"1.168133553","rc":[{"batb":[[0,1.09,4.99]],"ltp":1.47,"tv":16.72,"id":16325787}]}]}
{"op":"mcm","clk":"989472998","pt":1580488170444,"mc":[{"id":"1.168133553","rc":[{"batb":[[0,1.1,3],[1,1.09,1.99],[2,1.07,10]],"ltp":1.47,"tv":16.72,"id":16325787}]}]}
{"op":"mcm","clk":"989473968","pt":1580488181490,"mc":[{"id":"1.168133553","rc":[{"batb":[[0,1.09,1.99],[1,1.08,3]],"ltp":1.47,"tv":16.72,"id":16325787}]}]}
{"op":"mcm","clk":"989475267","pt":1580488196480,"mc":[{"id":"1.168133553","rc":[{"batb":[[0,1.09,4.99],[1,1.07,10],[2,1.04,6]],"ltp":1.47,"tv":16.72,"id":16325787}]}]}
{"op":"mcm","clk":"989475896","pt":1580488204398,"mc":[{"id":"1.168133553","rc":[{"batb":[[1,1.05,10]],"ltp":1.47,"tv":16.72,"id":16325787}]}]}
{"op":"mcm","clk":"989476545","pt":1580488211516,"mc":[{"id":"1.168133553","rc":[{"batb":[[0,1.09,1.99]],"ltp":1.47,"tv":16.72,"id":16325787}]}]}
{"op":"mcm","clk":"989476548","pt":1580488211612,"mc":[{"id":"1.168133553","rc":[{"batb":[[0,1.1,3],[1,1.09,1.99],[2,1.05,10]],"ltp":1.47,"tv":16.72,"id":16325787}]}]}
{"op":"mcm","clk":"989477706","pt":1580488224911,"mc":[{"id":"1.168133553","rc":[{"batb":[[0,1.09,1.99],[1,1.06,3]],"ltp":1.47,"tv":16.72,"id":16325787}]}]}
{"op":"mcm","clk":"989479350","pt":1580488245692,"mc":[{"id":"1.168133553","rc":[{"batb":[[1,1.07,3]],"ltp":1.47,"tv":16.72,"id":16325787}]}]}
{"op":"mcm","clk":"989480789","pt":1580488264520,"mc":[{"id":"1.168133553","rc":[{"batb":[[1,1.05,10],[2,1.04,6]],"ltp":1.47,"tv":16.72,"id":16325787}]}]}
{"op":"mcm","clk":"989480795","pt":1580488264624,"mc":[{"id":"1.168133553","rc":[{"batb":[[1,1.08,3],[2,1.05,10]],"ltp":1.47,"tv":16.72,"id":16325787}]}]}
{"op":"mcm","clk":"989481586","pt":1580488274428,"mc":[{"id":"1.168133553","rc":[{"batb":[[2,1.04,6]],"ltp":1.47,"tv":16.72,"id":16325787}]}]}
{"op":"mcm","clk":"989482385","pt":1580488284052,"mc":[{"id":"1.168133553","rc":[{"batb":[[0,1.09,4.99],[1,1.04,6],[2,1.03,1628.12]],"ltp":1.47,"tv":16.72,"id":16325787}]}]}
{"op":"mcm","clk":"989483091","pt":1580488293150,"mc":[{"id":"1.168133553","rc":[{"batb":[[1,1.05,3],[2,1.04,6]],"ltp":1.47,"tv":16.72,"id":16325787}]}]}
{"op":"mcm","clk":"989483722","pt":1580488300554,"mc":[{"id":"1.168133553","rc":[{"batb":[[0,1.1,3],[1,1.09,1.99],[2,1.05,3]],"ltp":1.47,"tv":16.72,"id":16325787}]}]}
{"op":"mcm","clk":"989485374","pt":1580488318819,"mc":[{"id":"1.168133553","rc":[{"batb":[[0,1.09,1.99],[1,1.06,3]],"ltp":1.47,"tv":16.72,"id":16325787}]}]}
{"op":"mcm","clk":"989485656","pt":1580488321667,"mc":[{"id":"1.168133553","rc":[{"batb":[[0,1.07,1.99]],"ltp":1.47,"tv":16.72,"id":16325787}]}]}
{"op":"mcm","clk":"989487031","pt":1580488337483,"mc":[{"id":"1.168133553","rc":[{"batb":[[1,1.05,3],[2,1.04,6]],"ltp":1.47,"tv":16.72,"id":16325787}]}]}
{"op":"mcm","clk":"989487037","pt":1580488337587,"mc":[{"id":"1.168133553","rc":[{"batb":[[0,1.07,4.99]],"ltp":1.47,"tv":16.72,"id":16325787}]}]}
{"op":"mcm","clk":"989488507","pt":1580488353388,"mc":[{"id":"1.168133553","rc":[{"batb":[[0,1.08,3],[1,1.07,1.99],[2,1.05,3]],"ltp":1.47,"tv":16.72,"id":16325787}]}]}
{"op":"mcm","clk":"989489786","pt":1580488368404,"mc":[{"id":"1.168133553","rc":[{"batb":[[0,1.09,1.99],[1,1.06,3]],"ltp":1.47,"tv":16.72,"id":16325787}]}]}
{"op":"mcm","clk":"989490582","pt":1580488377434,"mc":[{"id":"1.168133553","rc":[{"batb":[[1,1.07,3]],"ltp":1.47,"tv":16.72,"id":16325787}]}]}
{"op":"mcm","clk":"989491650","pt":1580488389937,"mc":[{"id":"1.168133553","rc":[{"batb":[[1,1.08,3]],"ltp":1.47,"tv":16.72,"id":16325787}]}]}
{"op":"mcm","clk":"989492631","pt":1580488402185,"mc":[{"id":"1.168133553","rc":[{"batb":[[0,1.09,4.99],[1,1.05,3],[2,1.04,6]],"ltp":1.47,"tv":16.72,"id":16325787}]}]}
{"op":"mcm","clk":"989493767","pt":1580488415276,"mc":[{"id":"1.168133553","rc":[{"batb":[[0,1.1,3],[1,1.09,1.99],[2,1.05,3]],"ltp":1.47,"tv":16.72,"id":16325787}]}]}
{"op":"mcm","clk":"989494947","pt":1580488430917,"mc":[{"id":"1.168133553","rc":[{"batb":[[0,1.09,1.99],[1,1.06,3]],"ltp":1.47,"tv":16.72,"id":16325787}]}]}
{"op":"mcm","clk":"989496289","pt":1580488447715,"mc":[{"id":"1.168133553","rc":[{"batb":[[1,1.07,3]],"ltp":1.47,"tv":16.72,"id":16325787}]}]}
{"op":"mcm","clk":"989496855","pt":1580488454934,"mc":[{"id":"1.168133553","rc":[{"batb":[[0,1.08,1.99]],"ltp":1.47,"tv":16.72,"id":16325787}]}]}
{"op":"mcm","clk":"989497331","pt":1580488461542,"mc":[{"id":"1.168133553","rc":[{"batb":[[0,1.08,4.99],[1,1.05,3],[2,1.04,6]],"ltp":1.47,"tv":16.72,"id":16325787}]}]}
{"op":"mcm","clk":"989498417","pt":1580488474238,"mc":[{"id":"1.168133553","rc":[{"batb":[[0,1.09,3],[1,1.08,1.99],[2,1.05,3]],"ltp":1.47,"tv":16.72,"id":16325787}]}]}
{"op":"mcm","clk":"989499479","pt":1580488487563,"mc":[{"id":"1.168133553","rc":[{"batb":[[0,1.08,1.99],[1,1.05,3],[2,1.04,6]],"ltp":1.47,"tv":16.72,"id":16325787}]}]}
{"op":"mcm","clk":"989499489","pt":1580488487666,"mc":[{"id":"1.168133553","rc":[{"batb":[[1,1.06,3],[2,1.05,3]],"ltp":1.47,"tv":16.72,"id":16325787}]}]}
{"op":"mcm","clk":"989500572","pt":1580488500473,"mc":[{"id":"1.168133553","rc":[{"batb":[[0,1.07,1.99]],"ltp":1.47,"tv":16.72,"id":16325787}]}]}
{"op":"mcm","clk":"989500797","pt":1580488502499,"mc":[{"id":"1.168133553","rc":[{"batb":[[0,1.07,4.99],[1,1.05,3],[2,1.04,6]],"ltp":1.47,"tv":16.72,"id":16325787}]}]}
{"op":"mcm","clk":"989502136","pt":1580488516900,"mc":[{"id":"1.168133553","rc":[{"batb":[[0,1.08,3],[1,1.07,1.99],[2,1.05,3]],"ltp":1.47,"tv":16.72,"id":16325787}]}]}
{"op":"mcm","clk":"989503333","pt":1580488530304,"mc":[{"id":"1.168133553","rc":[{"batb":[[0,1.07,1.99],[1,1.06,3]],"ltp":1.47,"tv":16.72,"id":16325787}]}]}
{"op":"mcm","clk":"989504677","pt":1580488546137,"mc":[{"id":"1.168133553","rc":[{"batb":[[0,1.07,4.99],[1,1.05,3],[2,1.04,6]],"ltp":1.47,"tv":16.72,"id":16325787}]}]}
{"op":"mcm","clk":"989505832","pt":1580488559131,"mc":[{"id":"1.168133553","rc":[{"batb":[[0,1.08,3],[1,1.07,1.99],[2,1.05,3]],"ltp":1.47,"tv":16.72,"id":16325787}]}]}
{"op":"mcm","clk":"989507007","pt":1580488571505,"mc":[{"id":"1.168133553","rc":[{"batb":[[0,1.07,1.99],[1,1.06,3]],"ltp":1.47,"tv":16.72,"id":16325787}]}]}
{"op":"mcm","clk":"989508125","pt":1580488584308,"mc":[{"id":"1.168133553","rc":[{"batb":[[0,1.07,4.99],[1,1.05,3],[2,1.04,6]],"ltp":1.47,"tv":16.72,"id":16325787}]}]}
{"op":"mcm","clk":"989509033","pt":1580488594538,"mc":[{"id":"1.168133553","rc":[{"batb":[[0,1.08,3],[1,1.07,1.99],[2,1.05,3]],"ltp":1.47,"tv":16.72,"id":16325787}]}]}
{"op":"mcm","clk":"989510013","pt":1580488605472,"mc":[{"id":"1.168133553","rc":[{"batb":[[0,1.07,1.99],[1,1.06,3]],"ltp":1.47,"tv":16.72,"id":16325787}]}]}
{"op":"mcm","clk":"989511080","pt":1580488617492,"mc":[{"id":"1.168133553","rc":[{"batb":[[1,1.05,3],[2,1.04,6]],"ltp":1.47,"tv":16.72,"id":16325787}]}]}
{"op":"mcm","clk":"989511169","pt":1580488618384,"mc":[{"id":"1.168133553","rc":[{"batb":[[0,1.07,4.99]],"ltp":1.47,"tv":16.72,"id":16325787}]}]}
{"op":"mcm","clk":"989512070","pt":1580488629194,"mc":[{"id":"1.168133553","rc":[{"batb":[[0,1.08,3],[1,1.07,1.99],[2,1.05,3]],"ltp":1.47,"tv":16.72,"id":16325787}]}]}
{"op":"mcm","clk":"989513008","pt":1580488640204,"mc":[{"id":"1.168133553","rc":[{"batb":[[0,1.07,1.99],[1,1.06,3]],"ltp":1.47,"tv":16.72,"id":16325787}]}]}
{"op":"mcm","clk":"989523697","pt":1580488652900,"mc":[{"id":"1.168133553","rc":[{"batb":[[0,1.07,4.99],[1,1.05,3],[2,1.04,6]],"ltp":1.47,"tv":16.72,"id":16325787}]}]}
{"op":"mcm","clk":"989525078","pt":1580488669230,"mc":[{"id":"1.168133553","rc":[{"batb":[[0,1.08,3],[1,1.07,1.99],[2,1.05,3]],"ltp":1.47,"tv":16.72,"id":16325787}]}]}
{"op":"mcm","clk":"989526025","pt":1580488680831,"mc":[{"id":"1.168133553","rc":[{"batb":[[0,1.07,1.99],[1,1.06,3]],"ltp":1.47,"tv":16.72,"id":16325787}]}]}
{"op":"mcm","clk":"989527195","pt":1580488695975,"mc":[{"id":"1.168133553","rc":[{"batb":[[0,1.07,4.99],[1,1.05,3],[2,1.04,6]],"ltp":1.47,"tv":16.72,"id":16325787}]}]}
{"op":"mcm","clk":"989528708","pt":1580488712351,"mc":[{"id":"1.168133553","rc":[{"batb":[[0,1.08,3],[1,1.07,1.99],[2,1.05,3]],"ltp":1.47,"tv":16.72,"id":16325787}]}]}
{"op":"mcm","clk":"989530182","pt":1580488728405,"mc":[{"id":"1.168133553","rc":[{"batb":[[0,1.07,1.99],[1,1.06,3]],"ltp":1.47,"tv":16.72,"id":16325787}]}]}
{"op":"mcm","clk":"989531292","pt":1580488740104,"mc":[{"id":"1.168133553","rc":[{"batb":[[0,1.07,4.99],[1,1.05,3],[2,1.04,6]],"ltp":1.47,"tv":16.72,"id":16325787}]}]}
{"op":"mcm","clk":"989532743","pt":1580488757122,"mc":[{"id":"1.168133553","rc":[{"batb":[[0,1.08,3],[1,1.07,1.99],[2,1.05,3]],"ltp":1.47,"tv":16.72,"id":16325787}]}]}
{"op":"mcm","clk":"989532808","pt":1580488757905,"mc":[{"id":"1.168133553","rc":[{"batb":[[0,1.09,1.99],[1,1.08,3]],"ltp":1.47,"tv":16.72,"id":16325787}]}]}
{"op":"mcm","clk":"989533979","pt":1580488771911,"mc":[{"id":"1.168133553","rc":[{"batb":[[0,1.09,4.99],[1,1.05,3],[2,1.04,6]],"ltp":1.47,"tv":16.72,"id":16325787}]}]}
{"op":"mcm","clk":"989534859","pt":1580488783405,"mc":[{"id":"1.168133553","rc":[{"batb":[[0,1.1,3],[1,1.09,1.99],[2,1.05,3]],"ltp":1.47,"tv":16.72,"id":16325787}]}]}
{"op":"mcm","clk":"989535676","pt":1580488793120,"mc":[{"id":"1.168133553","rc":[{"batb":[[0,1.09,1.99],[1,1.06,3]],"ltp":1.47,"tv":16.72,"id":16325787}]}]}
{"op":"mcm","clk":"989536599","pt":1580488803800,"mc":[{"id":"1.168133553","rc":[{"batb":[[0,1.07,1.99]],"ltp":1.47,"tv":16.72,"id":16325787}]}]}
{"op":"mcm","clk":"989536765","pt":1580488805742,"mc":[{"id":"1.168133553","rc":[{"batb":[[0,1.07,4.99],[1,1.05,3],[2,1.04,6]],"ltp":1.47,"tv":16.72,"id":16325787}]}]}
{"op":"mcm","clk":"989538203","pt":1580488822452,"mc":[{"id":"1.168133553","rc":[{"batb":[[1,1.06,10],[2,1.05,3]],"ltp":1.47,"tv":16.72,"id":16325787}]}]}
{"op":"mcm","clk":"989538298","pt":1580488823748,"mc":[{"id":"1.168133553","rc":[{"batb":[[0,1.08,3],[1,1.07,1.99],[2,1.06,10]],"ltp":1.47,"tv":16.72,"id":16325787}]}]}
{"op":"mcm","clk":"989539494","pt":1580488839268,"mc":[{"id":"1.168133553","rc":[{"batb":[[0,1.07,4.99],[1,1.06,10],[2,1.05,3]],"ltp":1.47,"tv":16.72,"id":16325787}]}]}
{"op":"mcm","clk":"989540579","pt":1580488853415,"mc":[{"id":"1.168133553","rc":[{"batb":[[0,1.08,3],[1,1.07,1.99],[2,1.06,10]],"ltp":1.47,"tv":16.72,"id":16325787}]}]}
{"op":"mcm","clk":"989542207","pt":1580488871004,"mc":[{"id":"1.168133553","rc":[{"batb":[[0,1.07,4.99],[1,1.06,10],[2,1.04,6]],"ltp":1.47,"tv":16.72,"id":16325787}]}]}
{"op":"mcm","clk":"989543412","pt":1580488886038,"mc":[{"id":"1.168133553","rc":[{"batb":[[0,1.08,3],[1,1.07,1.99],[2,1.06,10]],"ltp":1.47,"tv":16.72,"id":16325787}]}]}
{"op":"mcm","clk":"989543945","pt":1580488891936,"mc":[{"id":"1.168133553","rc":[{"batb":[[0,1.08,13],[2,1.04,6]],"ltp":1.47,"tv":16.72,"id":16325787}]}]}
{"op":"mcm","clk":"989544566","pt":1580488899043,"mc":[{"id":"1.168133553","rc":[{"batb":[[0,1.09,3],[1,1.08,10],[2,1.07,1.99]],"ltp":1.47,"tv":16.72,"id":16325787}]}]}
{"op":"mcm","clk":"989545595","pt":1580488910161,"mc":[{"id":"1.168133553","rc":[{"batb":[[0,1.1,1.99],[1,1.09,3],[2,1.08,10]],"ltp":1.47,"tv":16.72,"id":16325787}]}]}
{"op":"mcm","clk":"989545729","pt":1580488911462,"mc":[{"id":"1.168133553","rc":[{"batb":[[0,1.1,4.99],[1,1.08,10],[2,1.04,6]],"ltp":1.47,"tv":16.72,"id":16325787}]}]}
{"op":"mcm","clk":"989547158","pt":1580488926782,"mc":[{"id":"1.168133553","rc":[{"batb":[[0,1.11,3],[1,1.1,1.99],[2,1.08,10]],"ltp":1.47,"tv":16.72,"id":16325787}]}]}
{"op":"mcm","clk":"989548124","pt":1580488936763,"mc":[{"id":"1.168133553","rc":[{"batb":[[0,1.1,1.99],[1,1.09,3]],"ltp":1.47,"tv":16.72,"id":16325787}]}]}
{"op":"mcm","clk":"989549416","pt":1580488950122,"mc":[{"id":"1.168133553","rc":[{"batb":[[0,1.1,4.99],[1,1.08,10],[2,1.04,6]],"ltp":1.47,"tv":16.72,"id":16325787}]}]}
{"op":"mcm","clk":"989550417","pt":1580488961509,"mc":[{"id":"1.168133553","rc":[{"batb":[[1,1.04,6],[2,1.03,1628.12]],"ltp":1.47,"tv":16.72,"id":16325787}]}]}
{"op":"mcm","clk":"989550700","pt":1580488965405,"mc":[{"id":"1.168133553","rc":[{"batb":[[0,1.11,3],[1,1.1,1.99],[2,1.04,6]],"ltp":1.47,"tv":16.72,"id":16325787}]}]}
{"op":"mcm","clk":"989551778","pt":1580488978944,"mc":[{"id":"1.168133553","rc":[{"batb":[[0,1.1,1.99],[1,1.05,3]],"ltp":1.47,"tv":16.72,"id":16325787}]}]}
{"op":"mcm","clk":"989552535","pt":1580488989286,"mc":[{"id":"1.168133553","rc":[{"batb":[[1,1.06,3]],"ltp":1.47,"tv":16.72,"id":16325787}]}]}
{"op":"mcm","clk":"989553409","pt":1580489000971,"mc":[{"id":"1.168133553","rc":[{"batb":[[1,1.07,3]],"ltp":1.47,"tv":16.72,"id":16325787}]}]}
{"op":"mcm","clk":"989554299","pt":1580489012516,"mc":[{"id":"1.168133553","rc":[{"batb":[[0,1.08,1.99]],"ltp":1.47,"tv":16.72,"id":16325787}]}]}
{"op":"mcm","clk":"989554454","pt":1580489014313,"mc":[{"id":"1.168133553","rc":[{"batb":[[0,1.08,4.99],[1,1.04,6],[2,1.03,1628.12]],"ltp":1.47,"tv":16.72,"id":16325787}]}]}
{"op":"mcm","clk":"989555307","pt":1580489026515,"mc":[{"id":"1.168133553","rc":[{"batb":[[0,1.09,3],[1,1.08,1.99],[2,1.04,6]],"ltp":1.47,"tv":16.72,"id":16325787}]}]}
{"op":"mcm","clk":"989556226","pt":1580489037713,"mc":[{"id":"1.168133553","rc":[{"batb":[[0,1.08,1.99],[1,1.05,3]],"ltp":1.47,"tv":16.72,"id":16325787}]}]}
{"op":"mcm","clk":"989556309","pt":1580489038708,"mc":[{"id":"1.168133553","rc":[{"batb":[[1,1.05,6]],"ltp":1.47,"tv":16.72,"id":16325787}]}]}
{"op":"mcm","clk":"989557625","pt":1580489055025,"mc":[{"id":"1.168133553","rc":[{"batb":[[1,1.06,3],[2,1.05,3]],"ltp":1.47,"tv":16.72,"id":16325787}]}]}
{"op":"mcm","clk":"989558558","pt":1580489066827,"mc":[{"id":"1.168133553","rc":[{"batb":[[1,1.07,3]],"ltp":1.47,"tv":16.72,"id":16325787}]}]}
{"op":"mcm","clk":"989559635","pt":1580489080527,"mc":[{"id":"1.168133553","rc":[{"batb":[[0,1.08,4.99],[1,1.05,3],[2,1.04,6]],"ltp":1.47,"tv":16.72,"id":16325787}]}]}
{"op":"mcm","clk":"989560548","pt":1580489091455,"mc":[{"id":"1.168133553","rc":[{"batb":[[0,1.09,3],[1,1.08,1.99],[2,1.05,3]],"ltp":1.47,"tv":16.72,"id":16325787}]}]}
{"op":"mcm","clk":"989561648","pt":1580489105970,"mc":[{"id":"1.168133553","rc":[{"batb":[[0,1.08,1.99],[1,1.06,3]],"ltp":1.47,"tv":16.72,"id":16325787}]}]}
{"op":"mcm","clk":"989562169","pt":1580489113212,"mc":[{"id":"1.168133553","rc":[{"batb":[[0,1.07,1.99]],"ltp":1.47,"tv":16.72,"id":16325787}]}]}
{"op":"mcm","clk":"989562779","pt":1580489119900,"mc":[{"id":"1.168133553","rc":[{"batb":[[0,1.07,4.99],[1,1.05,3],[2,1.04,6]],"ltp":1.47,"tv":16.72,"id":16325787}]}]}
{"op":"mcm","clk":"989563460","pt":1580489128197,"mc":[{"id":"1.168133553","rc":[{"batb":[[0,1.08,3],[1,1.07,1.99],[2,1.05,3]],"ltp":1.47,"tv":16.72,"id":16325787}]}]}
{"op":"mcm","clk":"989564521","pt":1580489140903,"mc":[{"id":"1.168133553","rc":[{"batb":[[0,1.07,1.99],[1,1.06,3]],"ltp":1.47,"tv":16.72,"id":16325787}]}]}
{"op":"mcm","clk":"989565358","pt":1580489151295,"mc":[{"id":"1.168133553","rc":[{"batb":[[0,1.07,4.99],[1,1.05,3],[2,1.04,6]],"ltp":1.47,"tv":16.72,"id":16325787}]}]}
{"op":"mcm","clk":"989566211","pt":1580489162179,"mc":[{"id":"1.168133553","rc":[{"batb":[[0,1.08,3],[1,1.07,1.99],[2,1.05,3]],"ltp":1.47,"tv":16.72,"id":16325787}]}]}
{"op":"mcm","clk":"989567205","pt":1580489175318,"mc":[{"id":"1.168133553","rc":[{"batb":[[0,1.07,1.99],[1,1.06,3]],"ltp":1.47,"tv":16.72,"id":16325787}]}]}
{"op":"mcm","clk":"989567987","pt":1580489185511,"mc":[{"id":"1.168133553","rc":[{"batb":[[0,1.07,4.99],[1,1.05,3],[2,1.04,6]],"ltp":1.47,"tv":16.72,"id":16325787}]}]}
{"op":"mcm","clk":"989568773","pt":1580489197509,"mc":[{"id":"1.168133553","rc":[{"batb":[[0,1.08,3],[1,1.07,1.99],[2,1.05,3]],"ltp":1.47,"tv":16.72,"id":16325787}]}]}
{"op":"mcm","clk":"989569227","pt":1580489204834,"mc":[{"id":"1.168133553","rc":[{"batb":[[0,1.07,1.99],[1,1.06,3]],"ltp":1.47,"tv":16.72,"id":16325787}]}]}
{"op":"mcm","clk":"989570206","pt":1580489218559,"mc":[{"id":"1.168133553","rc":[{"batb":[[0,1.07,4.99],[1,1.05,3],[2,1.04,6]],"ltp":1.47,"tv":16.72,"id":16325787}]}]}
{"op":"mcm","clk":"989570942","pt":1580489228477,"mc":[{"id":"1.168133553","rc":[{"batb":[[0,1.08,3],[1,1.07,1.99],[2,1.05,3]],"ltp":1.47,"tv":16.72,"id":16325787}]}]}
{"op":"mcm","clk":"989571640","pt":1580489238503,"mc":[{"id":"1.168133553","rc":[{"batb":[[0,1.08,13]],"ltp":1.47,"tv":16.72,"id":16325787}]}]}
{"op":"mcm","clk":"989571830","pt":1580489241313,"mc":[{"id":"1.168133553","rc":[{"batb":[[0,1.09,3],[1,1.08,10],[2,1.07,1.99]],"ltp":1.47,"tv":16.72,"id":16325787}]}]}
{"op":"mcm","clk":"989572467","pt":1580489249896,"mc":[{"id":"1.168133553","rc":[{"batb":[[0,1.1,1.99],[1,1.09,3],[2,1.08,10]],"ltp":1.47,"tv":16.72,"id":16325787}]}]}
{"op":"mcm","clk":"989572891","pt":1580489256386,"mc":[{"id":"1.168133553","rc":[{"batb":[[0,1.1,4.99],[1,1.08,10],[2,1.05,3]],"ltp":1.47,"tv":16.72,"id":16325787}]}]}
{"op":"mcm","clk":"989573827","pt":1580489271122,"mc":[{"id":"1.168133553","rc":[{"batb":[[1,1.09,3],[2,1.08,10]],"ltp":1.47,"tv":16.72,"id":16325787}]}]}
{"op":"mcm","clk":"989573902","pt":1580489272019,"mc":[{"id":"1.168133553","rc":[{"batb":[[0,1.11,3],[1,1.1,1.99],[2,1.09,3]],"ltp":1.47,"tv":16.72,"id":16325787}]}]}
{"op":"mcm","clk":"989574696","pt":1580489283720,"mc":[{"id":"1.168133553","rc":[{"batb":[[0,1.1,4.99],[1,1.09,3],[2,1.08,10]],"ltp":1.47,"tv":16.72,"id":16325787}]}]}
{"op":"mcm","clk":"989575471","pt":1580489294420,"mc":[{"id":"1.168133553","rc":[{"batb":[[0,1.11,3],[1,1.1,1.99],[2,1.09,3]],"ltp":1.47,"tv":16.72,"id":16325787}]}]}
{"op":"mcm","clk":"989576151","pt":1580489304931,"mc":[{"id":"1.168133553","rc":[{"batb":[[0,1.12,1.99],[1,1.11,3]],"ltp":1.47,"tv":16.72,"id":16325787}]}]}
{"op":"mcm","clk":"989576229","pt":1580489306234,"mc":[{"id":"1.168133553","rc":[{"batb":[[0,1.12,4.99],[1,1.09,3],[2,1.08,10]],"ltp":1.47,"tv":16.72,"id":16325787}]}]}
{"op":"mcm","clk":"989576322","pt":1580489307538,"mc":[{"id":"1.168133553","rc":[{"batb":[[2,1.04,6]],"ltp":1.47,"tv":16.72,"id":16325787}]}]}
{"op":"mcm","clk":"989576977","pt":1580489316149,"mc":[{"id":"1.168133553","rc":[{"batb":[[0,1.13,3],[1,1.12,1.99],[2,1.09,3]],"ltp":1.47,"tv":16.72,"id":16325787}]}]}
{"op":"mcm","clk":"989577498","pt":1580489325569,"mc":[{"id":"1.168133553","rc":[{"batb":[[0,1.12,1.99],[1,1.09,3],[2,1.04,6]],"ltp":1.47,"tv":16.72,"id":16325787}]}]}
{"op":"mcm","clk":"989577503","pt":1580489325672,"mc":[{"id":"1.168133553","rc":[{"batb":[[1,1.1,3],[2,1.09,3]],"ltp":1.47,"tv":16.72,"id":16325787}]}]}
{"op":"mcm","clk":"989578072","pt":1580489334943,"mc":[{"id":"1.168133553","rc":[{"batb":[[1,1.11,3]],"ltp":1.47,"tv":16.72,"id":16325787}]}]}
{"op":"mcm","clk":"989578621","pt":1580489343288,"mc":[{"id":"1.168133553","rc":[{"batb":[[0,1.12,4.99],[1,1.09,3],[2,1.04,6]],"ltp":1.47,"tv":16.72,"id":16325787}]}]}
{"op":"mcm","clk":"989579332","pt":1580489354504,"mc":[{"id":"1.168133553","rc":[{"batb":[[0,1.13,3],[1,1.12,1.99],[2,1.09,3]],"ltp":1.47,"tv":16.72,"id":16325787}]}]}
{"op":"mcm","clk":"989579435","pt":1580489356215,"mc":[{"id":"1.168133553","rc":[{"batb":[[2,1.05,3]],"ltp":1.47,"tv":16.72,"id":16325787}]}]}
{"op":"mcm","clk":"989579957","pt":1580489364518,"mc":[{"id":"1.168133553","rc":[{"batb":[[0,1.12,1.99],[1,1.05,3],[2,1.04,6]],"ltp":1.47,"tv":16.72,"id":16325787}]}]}
{"op":"mcm","clk":"989579959","pt":1580489364620,"mc":[{"id":"1.168133553","rc":[{"batb":[[1,1.06,3],[2,1.05,3]],"ltp":1.47,"tv":16.72,"id":16325787}]}]}
{"op":"mcm","clk":"989580480","pt":1580489372892,"mc":[{"id":"1.168133553","rc":[{"batb":[[1,1.07,3]],"ltp":1.47,"tv":16.72,"id":16325787}]}]}
{"op":"mcm","clk":"989580976","pt":1580489380112,"mc":[{"id":"1.168133553","rc":[{"batb":[[0,1.08,1.99]],"ltp":1.47,"tv":16.72,"id":16325787}]}]}
{"op":"mcm","clk":"989581093","pt":1580489382027,"mc":[{"id":"1.168133553","rc":[{"batb":[[0,1.08,4.99],[1,1.05,3],[2,1.04,6]],"ltp":1.47,"tv":16.72,"id":16325787}]}]}
{"op":"mcm","clk":"989581728","pt":1580489392027,"mc":[{"id":"1.168133553","rc":[{"batb":[[0,1.09,3],[1,1.08,1.99],[2,1.05,3]],"ltp":1.47,"tv":16.72,"id":16325787}]}]}
{"op":"mcm","clk":"989582346","pt":1580489402036,"mc":[{"id":"1.168133553","rc":[{"batb":[[0,1.08,1.99],[1,1.06,3]],"ltp":1.47,"tv":16.72,"id":16325787}]}]}
{"op":"mcm","clk":"989583222","pt":1580489414368,"mc":[{"id":"1.168133553","rc":[{"batb":[[1,1.07,3]],"ltp":1.47,"tv":16.72,"id":16325787}]}]}
{"op":"mcm","clk":"989584411","pt":1580489430867,"mc":[{"id":"1.168133553","rc":[{"batb":[[0,1.08,4.99],[1,1.05,3],[2,1.04,6]],"ltp":1.47,"tv":16.72,"id":16325787}]}]}
{"op":"mcm","clk":"989585322","pt":1580489442453,"mc":[{"id":"1.168133553","rc":[{"batb":[[0,1.09,3],[1,1.08,1.99],[2,1.05,3]],"ltp":1.47,"tv":16.72,"id":16325787}]}]}
{"op":"mcm","clk":"989585564","pt":1580489445871,"mc":[{"id":"1.168133553","rc":[{"batb":[[0,1.09,13]],"ltp":1.47,"tv":16.72,"id":16325787}]}]}
{"op":"mcm","clk":"989586025","pt":1580489452541,"mc":[{"id":"1.168133553","rc":[{"batb":[[0,1.09,10]],"ltp":1.47,"tv":16.72,"id":16325787}]}]}
{"op":"mcm","clk":"989586031","pt":1580489452645,"mc":[{"id":"1.168133553","rc":[{"batb":[[0,1.1,3],[1,1.09,10],[2,1.08,1.99]],"ltp":1.47,"tv":16.72,"id":16325787}]}]}
{"op":"mcm","clk":"989589929","pt":1580489505519,"mc":[{"id":"1.168133553","rc":[{"batb":[[0,1.11,1.99],[1,1.1,3],[2,1.09,10]],"ltp":1.47,"tv":16.72,"id":16325787}]}]}
{"op":"mcm","clk":"989590328","pt":1580489510960,"mc":[{"id":"1.168133553","rc":[{"batb":[[0,1.11,4.99],[1,1.09,10],[2,1.04,6]],"ltp":1.47,"tv":16.72,"id":16325787}]}]}
{"op":"mcm","clk":"989590605","pt":1580489515069,"mc":[{"id":"1.168133553","rc":[{"batb":[[1,1.05,10]],"ltp":1.47,"tv":16.72,"id":16325787}]}]}
{"op":"mcm","clk":"989590959","pt":1580489518962,"mc":[{"id":"1.168133553","rc":[{"batb":[[0,1.12,3],[1,1.11,1.99],[2,1.05,10]],"ltp":1.47,"tv":16.72,"id":16325787}]}]}
{"op":"mcm","clk":"989592189","pt":1580489530148,"mc":[{"id":"1.168133553","rc":[{"batb":[[0,1.11,1.99],[1,1.06,3]],"ltp":1.47,"tv":16.72,"id":16325787}]}]}
{"op":"mcm","clk":"989593255","pt":1580489541786,"mc":[{"id":"1.168133553","rc":[{"batb":[[1,1.07,3]],"ltp":1.47,"tv":16.72,"id":16325787}]}]}
{"op":"mcm","clk":"989594095","pt":1580489551474,"mc":[{"id":"1.168133553","rc":[{"batb":[[1,1.08,3]],"ltp":1.47,"tv":16.72,"id":16325787}]}]}
{"op":"mcm","clk":"989604532","pt":1580489561503,"mc":[{"id":"1.168133553","rc":[{"batb":[[1,1.05,10],[2,1.04,6]],"ltp":1.47,"tv":16.72,"id":16325787}]}]}
{"op":"mcm","clk":"989604543","pt":1580489561606,"mc":[{"id":"1.168133553","rc":[{"batb":[[1,1.09,3],[2,1.05,10]],"ltp":1.47,"tv":16.72,"id":16325787}]}]}
{"op":"mcm","clk":"989605504","pt":1580489572425,"mc":[{"id":"1.168133553","rc":[{"batb":[[1,1.1,3]],"ltp":1.47,"tv":16.72,"id":16325787}]}]}
{"op":"mcm","clk":"989606305","pt":1580489581932,"mc":[{"id":"1.168133553","rc":[{"batb":[[0,1.11,4.99],[1,1.05,10],[2,1.04,6]],"ltp":1.47,"tv":16.72,"id":16325787}]}]}
{"op":"mcm","clk":"989607483","pt":1580489593276,"mc":[{"id":"1.168133553","rc":[{"batb":[[0,1.12,3],[1,1.11,1.99],[2,1.05,10]],"ltp":1.47,"tv":16.72,"id":16325787}]}]}
{"op":"mcm","clk":"989608460","pt":1580489603216,"mc":[{"id":"1.168133553","rc":[{"batb":[[0,1.11,1.99],[1,1.06,3]],"ltp":1.47,"tv":16.72,"id":16325787}]}]}
{"op":"mcm","clk":"989609136","pt":1580489611204,"mc":[{"id":"1.168133553","rc":[{"batb":[[1,1.07,3]],"ltp":1.47,"tv":16.72,"id":16325787}]}]}
{"op":"mcm","clk":"989609923","pt":1580489621229,"mc":[{"id":"1.168133553","rc":[{"batb":[[1,1.08,3]],"ltp":1.47,"tv":16.72,"id":16325787}]}]}
{"op":"mcm","clk":"989610682","pt":1580489631005,"mc":[{"id":"1.168133553","rc":[{"batb":[[1,1.09,3]],"ltp":1.47,"tv":16.72,"id":16325787}]}]}
{"op":"mcm","clk":"989611543","pt":1580489641532,"mc":[{"id":"1.168133553","rc":[{"batb":[[1,1.1,3]],"ltp":1.47,"tv":16.72,"id":16325787}]}]}
{"op":"mcm","clk":"989611738","pt":1580489643863,"mc":[{"id":"1.168133553","rc":[{"batb":[[0,1.11,4.99]],"ltp":1.47,"tv":16.72,"id":16325787}]}]}
{"op":"mcm","clk":"989611920","pt":1580489646255,"mc":[{"id":"1.168133553","rc":[{"batb":[[0,1.16,3],[1,1.11,1.99],[2,1.1,3]],"ltp":1.47,"tv":16.72,"id":16325787}]}]}
{"op":"mcm","clk":"989612008","pt":1580489647347,"mc":[{"id":"1.168133553","rc":[{"trd":[[1.17,3.98]],"batb":[[0,1.16,1.99],[1,1.1,3],[2,1.05,10]],"ltp":1.17,"tv":20.7,"id":16325787}],"tv":20.7}]}
{"op":"mcm","clk":"989612265","pt":1580489651069,"mc":[{"id":"1.168133553","rc":[{"batb":[[1,1.11,3]],"ltp":1.17,"tv":20.7,"id":16325787}]}]}
{"op":"mcm","clk":"989612385","pt":1580489652878,"mc":[{"id":"1.168133553","rc":[{"batb":[[1,1.12,10],[2,1.11,3]],"ltp":1.17,"tv":20.7,"id":16325787}]}]}
{"op":"mcm","clk":"989612889","pt":1580489659563,"mc":[{"id":"1.168133553","rc":[{"batb":[[0,1.12,10],[1,1.11,3],[2,1.03,1628.12]],"ltp":1.17,"tv":20.7,"id":16325787}]}]}
{"op":"mcm","clk":"989612972","pt":1580489660557,"mc":[{"id":"1.168133553","rc":[{"batb":[[2,1.04,65.33]],"batl":[[1,1.99,34.14],[2,2,2]],"ltp":1.17,"tv":20.7,"id":16325787}]}]}
{"op":"mcm","clk":"989613226","pt":1580489663985,"mc":[{"id":"1.168133553","rc":[{"batb":[[0,1.13,3],[1,1.12,10]],"ltp":1.17,"tv":20.7,"id":16325787}]}]}
{"op":"mcm","clk":"989613541","pt":1580489668076,"mc":[{"id":"1.168133553","rc":[{"batb":[[2,1.05,6]],"ltp":1.17,"tv":20.7,"id":16325787}]}]}
{"op":"mcm","clk":"989613877","pt":1580489672489,"mc":[{"id":"1.168133553","rc":[{"trd":[[1.58,0.4],[1.59,2.52]],"batl":[[0,1.99,34.88],[1,2,2],[2,3.1,4]],"ltp":1.59,"tv":23.62,"id":16325787}],"tv":23.62}]}
{"op":"mcm","clk":"989615479","pt":1580489693424,"mc":[{"id":"1.168133553","rc":[{"batb":[[0,1.13,7.75]],"ltp":1.59,"tv":23.62,"id":16325787}]}]}
{"op":"mcm","clk":"989615529","pt":1580489694145,"mc":[{"id":"1.168133553","rc":[{"batb":[[2,1.04,6]],"batl":[[0,2,2.74],[1,3.05,10.22]],"ltp":1.59,"tv":23.62,"id":16325787}]}]}
{"op":"mcm","clk":"989616880","pt":1580489710354,"mc":[{"id":"1.168133553","rc":[{"batb":[[0,1.14,3],[1,1.13,4.75],[2,1.12,10]],"ltp":1.59,"tv":23.62,"id":16325787}]}]}
{"op":"mcm","clk":"989617516","pt":1580489718347,"mc":[{"id":"1.168133553","rc":[{"batb":[[2,1.04,6]],"ltp":1.59,"tv":23.62,"id":16325787}]}]}
{"op":"mcm","clk":"989618360","pt":1580489729184,"mc":[{"id":"1.168133553","rc":[{"batb":[[0,1.06,3],[1,1.05,4.75]],"ltp":1.59,"tv":23.62,"id":16325787}]}]}
{"op":"mcm","clk":"989619637","pt":1580489745883,"mc":[{"id":"1.168133553","rc":[{"batl":[[0,2,2.93]],"ltp":1.59,"tv":23.62,"id":16325787}]}]}
{"op":"mcm","clk":"989627439","pt":1580489850703,"mc":[{"id":"1.168133553","rc":[{"batb":[[0,1.06,13]],"ltp":1.59,"tv":23.62,"id":16325787}]}]}
{"op":"mcm","clk":"989628225","pt":1580489859392,"mc":[{"id":"1.168133553","rc":[{"batb":[[0,1.07,3],[1,1.06,10],[2,1.05,4.75]],"ltp":1.59,"tv":23.62,"id":16325787}]}]}
{"op":"mcm","clk":"989630723","pt":1580489891117,"mc":[{"id":"1.168133553","rc":[{"batb":[[0,1.07,7.44],[2,1.04,6]],"ltp":1.59,"tv":23.62,"id":16325787}]}]}
{"op":"mcm","clk":"989631701","pt":1580489902848,"mc":[{"id":"1.168133553","rc":[{"batb":[[0,1.08,3],[1,1.07,4.44],[2,1.06,10]],"ltp":1.59,"tv":23.62,"id":16325787}]}]}
{"op":"mcm","clk":"989635253","pt":1580489952001,"mc":[{"id":"1.168133553","rc":[{"batb":[[0,1.08,13],[2,1.04,6]],"ltp":1.59,"tv":23.62,"id":16325787}]}]}
{"op":"mcm","clk":"989635339","pt":1580489953100,"mc":[{"id":"1.168133553","rc":[{"batb":[[0,1.09,4.36],[1,1.08,13]],"ltp":1.59,"tv":23.62,"id":16325787}]}]}
{"op":"mcm","clk":"989636027","pt":1580489961720,"mc":[{"id":"1.168133553","rc":[{"batb":[[0,1.1,3],[1,1.09,4.36],[2,1.08,10]],"ltp":1.59,"tv":23.62,"id":16325787}]}]}
{"op":"mcm","clk":"989641945","pt":1580490027478,"mc":[{"id":"1.168133553","rc":[{"batb":[[2,1.04,6]],"ltp":1.59,"tv":23.62,"id":16325787}]}]}
{"op":"mcm","clk":"989641965","pt":1580490027791,"mc":[{"id":"1.168133553","rc":[{"batb":[[0,1.1,13]],"ltp":1.59,"tv":23.62,"id":16325787}]}]}
{"op":"mcm","clk":"989642481","pt":1580490033460,"mc":[{"id":"1.168133553","rc":[{"batb":[[0,1.11,3],[1,1.1,10],[2,1.09,4.36]],"ltp":1.59,"tv":23.62,"id":16325787}]}]}
{"op":"mcm","clk":"989644576","pt":1580490057322,"mc":[{"id":"1.168133553","rc":[{"batb":[[0,1.11,7.28],[2,1.04,6]],"ltp":1.59,"tv":23.62,"id":16325787}]}]}
{"op":"mcm","clk":"989645524","pt":1580490065846,"mc":[{"id":"1.168133553","rc":[{"batb":[[0,1.12,3],[1,1.11,4.28],[2,1.1,10]],"ltp":1.59,"tv":23.62,"id":16325787}]}]}
{"op":"mcm","clk":"989648352","pt":1580490095763,"mc":[{"id":"1.168133553","rc":[{"batb":[[2,1.04,6]],"ltp":1.59,"tv":23.62,"id":16325787}]}]}
{"op":"mcm","clk":"989651116","pt":1580490127410,"mc":[{"id":"1.168133553","rc":[{"batb":[[1,1.05,4.28]],"ltp":1.59,"tv":23.62,"id":16325787}]}]}
{"op":"mcm","clk":"989651670","pt":1580490133889,"mc":[{"id":"1.168133553","rc":[{"batb":[[0,1.06,3]],"ltp":1.59,"tv":23.62,"id":16325787}]}]}
{"op":"mcm","clk":"989655515","pt":1580490176481,"mc":[{"id":"1.168133553","rc":[{"batl":[[0,1.7,8.93],[1,2,2],[2,3.05,10.22]],"ltp":1.59,"tv":23.62,"id":16325787}]}]}
{"op":"mcm","clk":"989658580","pt":1580490208498,"mc":[{"id":"1.168133553","rc":[{"batl":[[0,1.68,8.93]],"ltp":1.59,"tv":23.62,"id":16325787}]}]}
{"op":"mcm","clk":"989659281","pt":1580490216147,"mc":[{"id":"1.168133553","rc":[{"batl":[[0,1.67,3.96],[1,1.68,8],[2,2,2]],"ltp":1.59,"tv":23.62,"id":16325787}]}]}
{"op":"mcm","clk":"989660135","pt":1580490224944,"mc":[{"id":"1.168133553","rc":[{"batl":[[0,1.63,8.93],[1,1.67,3.03]],"ltp":1.59,"tv":23.62,"id":16325787}]}]}
{"op":"mcm","clk":"989664174","pt":1580490268496,"mc":[{"id":"1.168133553","rc":[{"batl":[[1,2,2],[2,3.1,4]],"ltp":1.59,"tv":23.62,"id":16325787}]}]}
{"op":"mcm","clk":"989664184","pt":1580490268601,"mc":[{"id":"1.168133553","rc":[{"batl":[[0,1.62,3.96],[1,1.63,8],[2,2,2]],"ltp":1.59,"tv":23.62,"id":16325787}]}]}
{"op":"mcm","clk":"989692568","pt":1580490481713,"mc":[{"id":"1.168133553","rc":[{"batb":[[0,1.06,13]],"ltp":1.59,"tv":23.62,"id":16325787}]}]}
{"op":"mcm","clk":"989692905","pt":1580490485493,"mc":[{"id":"1.168133553","rc":[{"batb":[[1,1.04,6],[2,1.03,1628.12]],"ltp":1.59,"tv":23.62,"id":16325787}]}]}
{"op":"mcm","clk":"989692922","pt":1580490485706,"mc":[{"id":"1.168133553","rc":[{"batb":[[0,1.07,4.2],[1,1.06,13],[2,1.04,6]],"ltp":1.59,"tv":23.62,"id":16325787}]}]}
{"op":"mcm","clk":"989693083","pt":1580490487388,"mc":[{"id":"1.168133553","rc":[{"batb":[[0,1.08,3],[1,1.07,4.2],[2,1.06,10]],"ltp":1.59,"tv":23.62,"id":16325787}]}]}
{"op":"mcm","clk":"989698401","pt":1580490545174,"mc":[{"id":"1.168133553","rc":[{"batb":[[2,1.04,6]],"ltp":1.59,"tv":23.62,"id":16325787}]}]}
{"op":"mcm","clk":"989699151","pt":1580490552940,"mc":[{"id":"1.168133553","rc":[{"batb":[[1,1.05,4.2]],"ltp":1.59,"tv":23.62,"id":16325787}]}]}
{"op":"mcm","clk":"989699877","pt":1580490560539,"mc":[{"id":"1.168133553","rc":[{"batb":[[0,1.06,3]],"ltp":1.59,"tv":23.62,"id":16325787}]}]}
{"op":"mcm","clk":"989703913","pt":1580490604624,"mc":[{"id":"1.168133553","rc":[{"batl":[[0,1.55,100],[1,1.62,3.96],[2,1.63,8]],"ltp":1.59,"tv":23.62,"id":16325787}]}]}
{"op":"mcm","clk":"989705588","pt":1580490622068,"mc":[{"id":"1.168133553","rc":[{"batl":[[0,1.54,3.03],[1,1.55,100],[2,1.63,8.93]],"ltp":1.59,"tv":23.62,"id":16325787}]}]}
{"op":"mcm","clk":"989706369","pt":1580490630567,"mc":[{"id":"1.168133553","rc":[{"batl":[[2,1.63,8.74]],"ltp":1.59,"tv":23.62,"id":16325787}]}]}
{"op":"mcm","clk":"989706380","pt":1580490630673,"mc":[{"id":"1.168133553","rc":[{"batl":[[0,1.54,3.22]],"ltp":1.59,"tv":23.62,"id":16325787}]}]}
{"op":"mcm","clk":"989710539","pt":1580490672940,"mc":[{"id":"1.168133553","rc":[{"batb":[[0,1.06,13]],"ltp":1.59,"tv":23.62,"id":16325787}]}]}
{"op":"mcm","clk":"989710635","pt":1580490674047,"mc":[{"id":"1.168133553","rc":[{"batb":[[0,1.07,4.12],[1,1.06,13]],"ltp":1.59,"tv":23.62,"id":16325787}]}]}
{"op":"mcm","clk":"989711738","pt":1580490684573,"mc":[{"id":"1.168133553","rc":[{"batb":[[0,1.08,3],[1,1.07,4.12],[2,1.06,10]],"ltp":1.59,"tv":23.62,"id":16325787}]}]}
{"op":"mcm","clk":"989717006","pt":1580490736939,"mc":[{"id":"1.168133553","rc":[{"batb":[[2,1.04,6]],"ltp":1.59,"tv":23.62,"id":16325787}]}]}
{"op":"mcm","clk":"989717432","pt":1580490740433,"mc":[{"id":"1.168133553","rc":[{"batb":[[1,1.04,6],[2,1.03,1628.12]],"ltp":1.59,"tv":23.62,"id":16325787}]}]}
{"op":"mcm","clk":"989717580","pt":1580490741520,"mc":[{"id":"1.168133553","rc":[{"batb":[[0,1.05,4.12]],"ltp":1.59,"tv":23.62,"id":16325787}]}]}
{"op":"mcm","clk":"989717590","pt":1580490741625,"mc":[{"id":"1.168133553","rc":[{"batb":[[0,1.06,3],[1,1.05,4.12],[2,1.04,6]],"ltp":1.59,"tv":23.62,"id":16325787}]}]}
{"op":"mcm","clk":"989744916","pt":1580490992290,"mc":[{"id":"1.168133553","rc":[{"batb":[[0,1.06,13]],"ltp":1.59,"tv":23.62,"id":16325787}]}]}
{"op":"mcm","clk":"989746009","pt":1580491002086,"mc":[{"id":"1.168133553","rc":[{"batb":[[0,1.07,3],[1,1.06,10],[2,1.05,4.12]],"ltp":1.59,"tv":23.62,"id":16325787}]}]}
{"op":"mcm","clk":"989749885","pt":1580491037493,"mc":[{"id":"1.168133553","rc":[{"batb":[[2,1.04,6]],"ltp":1.59,"tv":23.62,"id":16325787}]}]}
{"op":"mcm","clk":"989749908","pt":1580491037698,"mc":[{"id":"1.168133553","rc":[{"batb":[[0,1.07,7.04]],"ltp":1.59,"tv":23.62,"id":16325787}]}]}
{"op":"mcm","clk":"989750827","pt":1580491045834,"mc":[{"id":"1.168133553","rc":[{"batb":[[0,1.08,3],[1,1.07,4.04],[2,1.06,10]],"ltp":1.59,"tv":23.62,"id":16325787}]}]}
{"op":"mcm","clk":"989752052","pt":1580491057368,"mc":[{"id":"1.168133553","rc":[{"batb":[[2,1.04,6]],"ltp":1.59,"tv":23.62,"id":16325787}]}]}
{"op":"mcm","clk":"989754376","pt":1580491078783,"mc":[{"id":"1.168133553","rc":[{"batb":[[1,1.05,4.04]],"ltp":1.59,"tv":23.62,"id":16325787}]}]}
{"op":"mcm","clk":"989755403","pt":1580491088201,"mc":[{"id":"1.168133553","rc":[{"batb":[[0,1.06,3]],"ltp":1.59,"tv":23.62,"id":16325787}]}]}
{"op":"mcm","clk":"989758678","pt":1580491122059,"mc":[{"id":"1.168133553","rc":[{"batl":[[2,2,2.74]],"ltp":1.59,"tv":23.62,"id":16325787}]}]}
{"op":"mcm","clk":"989760677","pt":1580491141552,"mc":[{"id":"1.168133553","rc":[{"batl":[[0,1.5,100],[1,1.54,3.22],[2,1.55,100]],"ltp":1.59,"tv":23.62,"id":16325787}]}]}
{"op":"mcm","clk":"989761314","pt":1580491147956,"mc":[{"id":"1.168133553","rc":[{"batl":[[0,1.49,3.03],[1,1.5,100],[2,1.55,100.19]],"ltp":1.59,"tv":23.62,"id":16325787}]}]}
{"op":"mcm","clk":"989761631","pt":1580491151103,"mc":[{"id":"1.168133553","rc":[{"batl":[[1,1.51,100]],"ltp":1.59,"tv":23.62,"id":16325787}]}]}
{"op":"mcm","clk":"989762863","pt":1580491161220,"mc":[{"id":"1.168133553","rc":[{"batb":[[1,1.05,7.04]],"ltp":1.59,"tv":23.62,"id":16325787}]}]}
{"op":"mcm","clk":"989765468","pt":1580491187449,"mc":[{"id":"1.168133553","rc":[{"batl":[[0,1.5,3.03]],"ltp":1.59,"tv":23.62,"id":16325787}]}]}
{"op":"mcm","clk":"989770026","pt":1580491231322,"mc":[{"id":"1.168133553","rc":[{"batb":[[0,1.55,90],[1,1.53,11.99],[2,1.52,1.08]],"ltp":0.0,"tv":0.0,"id":27227336},{"batb":[[0,1.55,90],[1,1.53,11.99],[2,1.52,1.08]],"ltp":0.0,"tv":0.0,"id":21641292},{"batb":[[0,1.08,90],[1,1.06,3],[2,1.05,7.04]],"ltp":1.59,"tv":23.62,"id":16325787}]}]}
{"op":"mcm","clk":"989770077","pt":1580491231740,"mc":[{"id":"1.168133553","rc":[{"batl":[[0,980,9],[1,1000,0.2]],"ltp":0.0,"tv":0.0,"id":27227336},{"batl":[[0,980,9],[1,1000,0.2]],"ltp":0.0,"tv":0.0,"id":21641292}]}]}
{"op":"mcm","clk":"989770370","pt":1580491234519,"mc":[{"id":"1.168133553","rc":[{"batb":[[1,1.05,7.04],[2,1.04,6]],"ltp":1.59,"tv":23.62,"id":16325787}]}]}
{"op":"mcm","clk":"989770497","pt":1580491235534,"mc":[{"id":"1.168133553","rc":[{"batb":[[0,1.09,3],[1,1.08,90],[2,1.05,7.04]],"ltp":1.59,"tv":23.62,"id":16325787}]}]}
{"op":"mcm","clk":"989770692","pt":1580491237311,"mc":[{"id":"1.168133553","rc":[{"batl":[[0,980,9.2],[1,1000,0]],"ltp":0.0,"tv":0.0,"id":27227336},{"batl":[[0,980,9.2],[1,1000,0]],"ltp":0.0,"tv":0.0,"id":21641292}]}]}
{"op":"mcm","clk":"989771250","pt":1580491242526,"mc":[{"id":"1.168133553","rc":[{"batl":[[2,1.54,6.19]],"ltp":1.59,"tv":23.62,"id":16325787}]}]}
{"op":"mcm","clk":"989771940","pt":1580491248503,"mc":[{"id":"1.168133553","rc":[{"batb":[[0,1.56,8.13],[1,1.55,90],[2,1.53,11.99]],"ltp":0.0,"tv":0.0,"id":27227336},{"batb":[[0,1.56,8.13],[1,1.55,90],[2,1.53,11.99]],"ltp":0.0,"tv":0.0,"id":21641292}]}]}
{"op":"mcm","clk":"989772247","pt":1580491251286,"mc":[{"id":"1.168133553","rc":[{"batb":[[2,1.53,1.99]],"ltp":0.0,"tv":0.0,"id":27227336},{"batb":[[2,1.53,1.99]],"ltp":0.0,"tv":0.0,"id":21641292}]}]}
{"op":"mcm","clk":"989772849","pt":1580491256398,"mc":[{"id":"1.168133553","rc":[{"batb":[[0,1.57,24.04],[1,1.56,8.13],[2,1.55,90]],"batl":[[0,970,3.23],[1,980,9]],"ltp":0.0,"tv":0.0,"id":27227336},{"batb":[[0,1.57,24.53],[1,1.56,8.13],[2,1.55,90]],"batl":[[0,970,3.23],[1,980,9]],"ltp":0.0,"tv":0.0,"id":21641292},{"batb":[[0,1.09,6.89],[2,1.05,3]],"ltp":1.59,"tv":23.62,"id":16325787}]}]}
{"op":"mcm","clk":"989773223","pt":1580491259323,"mc":[{"id":"1.168133553","rc":[{"batb":[[0,1.1,3],[1,1.09,3.89],[2,1.08,90]],"ltp":1.59,"tv":23.62,"id":16325787}]}]}
{"op":"mcm","clk":"989773521","pt":1580491262516,"mc":[{"id":"1.168133553","rc":[{"batb":[[0,1.58,1.99],[1,1.57,24.04],[2,1.56,8.13]],"ltp":0.0,"tv":0.0,"id":27227336}]}]}
{"op":"mcm","clk":"989773612","pt":1580491263310,"mc":[{"id":"1.168133553","rc":[{"batb":[[0,1.58,1.99],[1,1.57,24.53],[2,1.56,8.13]],"ltp":0.0,"tv":0.0,"id":21641292}]}]}
{"op":"mcm","clk":"989775368","pt":1580491279244,"mc":[{"id":"1.168133553","rc":[{"batb":[[0,1.58,9.84],[2,1.55,90]],"ltp":0.0,"tv":0.0,"id":27227336},{"batb":[[0,1.58,9.84],[2,1.55,90]],"ltp":0.0,"tv":0.0,"id":21641292}]}]}
{"op":"mcm","clk":"989775978","pt":1580491284418,"mc":[{"id":"1.168133553","rc":[{"batb":[[2,1.56,6]],"ltp":0.0,"tv":0.0,"id":27227336}]}]}
{"op":"mcm","clk":"989776108","pt":1580491285543,"mc":[{"id":"1.168133553","rc":[{"batb":[[2,1.56,6]],"ltp":0.0,"tv":0.0,"id":21641292}]}]}
{"op":"mcm","clk":"989777316","pt":1580491295550,"mc":[{"id":"1.168133553","rc":[{"batb":[[0,1.6,90],[1,1.59,1.04],[2,1.58,9.84]],"ltp":0.0,"tv":0.0,"id":27227336},{"batb":[[0,1.6,90],[1,1.59,1.04],[2,1.58,9.84]],"ltp":0.0,"tv":0.0,"id":21641292},{"batb":[[0,1.12,90],[1,1.11,1.48],[2,1.1,3]],"ltp":1.59,"tv":23.62,"id":16325787}]}]}
{"op":"mcm","clk":"989777361","pt":1580491295969,"mc":[{"id":"1.168133553","rc":[{"batl":[[0,950,9],[1,970,3.23]],"ltp":0.0,"tv":0.0,"id":27227336},{"batl":[[0,950,9],[1,970,3.23]],"ltp":0.0,"tv":0.0,"id":21641292}]}]}
{"op":"mcm","clk":"989777660","pt":1580491298442,"mc":[{"id":"1.168133553","rc":[{"batb":[[0,1.13,3],[1,1.12,90],[2,1.11,1.48]],"ltp":1.59,"tv":23.62,"id":16325787}]}]}
{"op":"mcm","clk":"989778860","pt":1580491309465,"mc":[{"id":"1.168133553","rc":[{"batb":[[0,1.61,7.47],[1,1.6,90],[2,1.59,1.04]],"batl":[[0,950,9.2],[1,970,3.03]],"ltp":0.0,"tv":0.0,"id":27227336},{"batb":[[0,1.61,7.47],[1,1.6,90],[2,1.59,1.04]],"batl":[[0,950,9.2],[1,970,3.03]],"ltp":0.0,"tv":0.0,"id":21641292}]}]}
{"op":"mcm","clk":"989779596","pt":1580491316289,"mc":[{"id":"1.168133553","rc":[{"batb":[[0,1.13,13]],"ltp":1.59,"tv":23.62,"id":16325787}]}]}
{"op":"mcm","clk":"989780279","pt":1580491322505,"mc":[{"id":"1.168133553","rc":[{"batb":[[0,1.14,3],[1,1.13,10],[2,1.12,90]],"ltp":1.59,"tv":23.62,"id":16325787}]}]}
{"op":"mcm","clk":"989781614","pt":1580491336471,"mc":[{"id":"1.168133553","rc":[{"batb":[[0,1.63,90],[1,1.61,7.47]],"ltp":0.0,"tv":0.0,"id":27227336},{"batb":[[0,1.63,90],[1,1.61,7.47]],"ltp":0.0,"tv":0.0,"id":21641292},{"batb":[[0,1.16,90],[1,1.14,3],[2,1.13,10]],"ltp":1.59,"tv":23.62,"id":16325787}]}]}
{"op":"mcm","clk":"989781824","pt":1580491338501,"mc":[{"id":"1.168133553","rc":[{"batb":[[0,1.64,7.12],[1,1.63,90]],"ltp":0.0,"tv":0.0,"id":27227336},{"batb":[[0,1.64,7.12],[1,1.63,90]],"ltp":0.0,"tv":0.0,"id":21641292}]}]}
{"op":"mcm","clk":"989781969","pt":1580491340111,"mc":[{"id":"1.168133553","rc":[{"batb":[[0,1.65,3],[1,1.64,7.12],[2,1.63,90]],"ltp":0.0,"tv":0.0,"id":27227336},{"batb":[[0,1.65,3],[1,1.64,7.12],[2,1.63,90]],"ltp":0.0,"tv":0.0,"id":21641292}]}]}
{"op":"mcm","clk":"989782589","pt":1580491347118,"mc":[{"id":"1.168133553","rc":[{"batb":[[0,1.17,3],[1,1.16,90]],"ltp":1.59,"tv":23.62,"id":16325787}]}]}
{"op":"mcm","clk":"989794119","pt":1580491367820,"mc":[{"id":"1.168133553","rc":[{"batb":[[0,1.65,3.99]],"ltp":0.0,"tv":0.0,"id":27227336},{"batb":[[0,1.65,3.99]],"ltp":0.0,"tv":0.0,"id":21641292},{"batb":[[0,1.18,1.4],[1,1.17,3],[2,1.16,90]],"ltp":1.59,"tv":23.62,"id":16325787}]}]}
{"op":"mcm","clk":"989794613","pt":1580491373490,"mc":[{"id":"1.168133553","rc":[{"batb":[[2,1.58,1.99]],"ltp":0.0,"tv":0.0,"id":27227336},{"batb":[[2,1.58,1.99]],"ltp":0.0,"tv":0.0,"id":21641292},{"batb":[[2,1.13,10]],"ltp":1.59,"tv":23.62,"id":16325787}]}]}
{"op":"mcm","clk":"989794672","pt":1580491374172,"mc":[{"id":"1.168133553","rc":[{"batb":[[0,1.67,90],[1,1.65,3.99],[2,1.64,7.12]],"ltp":0.0,"tv":0.0,"id":27227336},{"batb":[[0,1.67,90],[1,1.65,3.99],[2,1.64,7.12]],"ltp":0.0,"tv":0.0,"id":21641292},{"batb":[[0,1.19,90],[1,1.18,1.4],[2,1.17,3]],"ltp":1.59,"tv":23.62,"id":16325787}]}]}
{"op":"mcm","clk":"989795160","pt":1580491379410,"mc":[{"id":"1.168133553","rc":[{"batb":[[0,1.2,3],[1,1.19,90],[2,1.18,1.4]],"ltp":1.59,"tv":23.62,"id":16325787}]}]}
{"op":"mcm","clk":"989796995","pt":1580491399510,"mc":[{"id":"1.168133553","rc":[{"batb":[[2,1.58,1.99]],"ltp":0.0,"tv":0.0,"id":27227336},{"batb":[[2,1.58,1.99]],"ltp":0.0,"tv":0.0,"id":21641292}]}]}
{"op":"mcm","clk":"989797163","pt":1580491401332,"mc":[{"id":"1.168133553","rc":[{"batb":[[0,1.68,3],[1,1.67,90],[2,1.58,2.98]],"ltp":0.0,"tv":0.0,"id":27227336},{"batb":[[0,1.68,3],[1,1.67,90],[2,1.58,2.98]],"ltp":0.0,"tv":0.0,"id":21641292}]}]}
{"op":"mcm","clk":"989797587","pt":1580491405532,"mc":[{"id":"1.168133553","rc":[{"batb":[[0,1.69,1.99],[1,1.68,3],[2,1.67,90]],"ltp":0.0,"tv":0.0,"id":27227336},{"batb":[[0,1.69,1.99],[1,1.68,3],[2,1.67,90]],"ltp":0.0,"tv":0.0,"id":21641292}]}]}
{"op":"mcm","clk":"989798126","pt":1580491410543,"mc":[{"id":"1.168133553","rc":[{"batb":[[0,1.7,90],[1,1.69,1.99],[2,1.68,3]],"ltp":0.0,"tv":0.0,"id":27227336},{"batb":[[0,1.7,90],[1,1.69,1.99],[2,1.68,3]],"ltp":0.0,"tv":0.0,"id":21641292},{"batb":[[0,1.2,93],[1,1.18,1.4],[2,1.13,6]],"ltp":1.59,"tv":23.62,"id":16325787}]}]}
{"op":"mcm","clk":"989798442","pt":1580491413328,"mc":[{"id":"1.168133553","rc":[{"batb":[[0,1.21,3],[1,1.2,90],[2,1.18,1.4]],"ltp":1.59,"tv":23.62,"id":16325787}]}]}
{"op":"mcm","clk":"989803489","pt":1580491464400,"mc":[{"id":"1.168133553","rc":[{"batb":[[0,1.21,6.51]],"ltp":1.59,"tv":23.62,"id":16325787}]}]}
{"op":"mcm","clk":"989803599","pt":1580491465390,"mc":[{"id":"1.168133553","rc":[{"batb":[[0,1.71,22.07],[1,1.7,90],[2,1.69,1.99]],"batl":[[0,940,3.23],[1,950,9]],"ltp":0.0,"tv":0.0,"id":27227336}]}]}
{"op":"mcm","clk":"989803665","pt":1580491466220,"mc":[{"id":"1.168133553","rc":[{"batb":[[0,1.71,22.52],[1,1.7,90],[2,1.69,1.99]],"batl":[[0,940,3.23],[1,950,9]],"ltp":0.0,"tv":0.0,"id":21641292},{"batb":[[0,1.22,3],[1,1.21,3.51],[2,1.2,90]],"ltp":1.59,"tv":23.62,"id":16325787}]}]}
{"op":"mcm","clk":"989805355","pt":1580491482431,"mc":[{"id":"1.168133553","rc":[{"batb":[[0,1.73,90],[1,1.71,22.07]],"ltp":0.0,"tv":0.0,"id":27227336},{"batb":[[0,1.73,90],[1,1.71,22.52]],"ltp":0.0,"tv":0.0,"id":21641292}]}]}
{"op":"mcm","clk":"989805453","pt":1580491483430,"mc":[{"id":"1.168133553","rc":[{"batl":[[0,920,9],[1,940,3.23]],"ltp":0.0,"tv":0.0,"id":27227336},{"batl":[[0,920,9],[1,940,3.23]],"ltp":0.0,"tv":0.0,"id":21641292}]}]}
{"op":"mcm","clk":"989806585","pt":1580491495322,"mc":[{"id":"1.168133553","rc":[{"batl":[[0,920,9.2],[1,940,3.03]],"ltp":0.0,"tv":0.0,"id":27227336},{"batl":[[0,920,9.2],[1,940,3.03]],"ltp":0.0,"tv":0.0,"id":21641292}]}]}
{"op":"mcm","clk":"989808062","pt":1580491509060,"mc":[{"id":"1.168133553","rc":[{"batb":[[0,1.74,10],[1,1.73,90],[2,1.71,22.07]],"ltp":0.0,"tv":0.0,"id":27227336},{"batb":[[0,1.74,10],[1,1.73,90],[2,1.71,22.52]],"ltp":0.0,"tv":0.0,"id":21641292},{"batb":[[0,1.22,13]],"ltp":1.59,"tv":23.62,"id":16325787}]}]}
{"op":"mcm","clk":"989808737","pt":1580491515928,"mc":[{"id":"1.168133553","rc":[{"batb":[[0,1.23,3],[1,1.22,10],[2,1.21,3.51]],"ltp":1.59,"tv":23.62,"id":16325787}]}]}
{"op":"mcm","clk":"989808969","pt":1580491518642,"mc":[{"id":"1.168133553","rc":[{"batb":[[0,1.74,16.15]],"ltp":0.0,"tv":0.0,"id":27227336},{"batb":[[0,1.74,16.15]],"ltp":0.0,"tv":0.0,"id":21641292}]}]}
{"op":"mcm","clk":"989809072","pt":1580491519738,"mc":[{"id":"1.168133553","rc":[{"batb":[[0,1.76,90],[1,1.74,16.15]],"ltp":0.0,"tv":0.0,"id":27227336},{"batb":[[0,1.76,90],[1,1.74,16.15]],"ltp":0.0,"tv":0.0,"id":21641292}]}]}
{"op":"mcm","clk":"989810545","pt":1580491534349,"mc":[{"id":"1.168133553","rc":[{"batb":[[0,1.77,1.99],[1,1.76,90],[2,1.74,16.15]],"ltp":0.0,"tv":0.0,"id":27227336},{"batb":[[0,1.77,1.99],[1,1.76,90],[2,1.74,16.15]],"ltp":0.0,"tv":0.0,"id":21641292}]}]}
{"op":"mcm","clk":"989812064","pt":1580491549443,"mc":[{"id":"1.168133553","rc":[{"batb":[[0,1.77,7.9],[2,1.74,10]],"ltp":0.0,"tv":0.0,"id":27227336},{"batb":[[0,1.77,7.9],[2,1.74,10]],"ltp":0.0,"tv":0.0,"id":21641292}]}]}
{"op":"mcm","clk":"989812160","pt":1580491550483,"mc":[{"id":"1.168133553","rc":[{"batb":[[0,1.77,8.83]],"ltp":0.0,"tv":0.0,"id":27227336},{"batb":[[0,1.77,8.83]],"ltp":0.0,"tv":0.0,"id":21641292},{"batb":[[0,1.24,1.33],[1,1.23,3],[2,1.22,10]],"ltp":1.59,"tv":23.62,"id":16325787}]}]}
{"op":"mcm","clk":"989812191","pt":1580491550757,"mc":[{"id":"1.168133553","rc":[{"batl":[[0,1.48,45],[1,1.5,3.03],[2,1.51,100]],"ltp":1.59,"tv":23.62,"id":16325787}]}]}
{"op":"mcm","clk":"989812427","pt":1580491553380,"mc":[{"id":"1.168133553","rc":[{"batb":[[0,1.24,4.33],[1,1.22,10],[2,1.21,3.51]],"ltp":1.59,"tv":23.62,"id":16325787}]}]}
{"op":"mcm","clk":"989812607","pt":1580491554900,"mc":[{"id":"1.168133553","rc":[{"batb":[[0,1.78,1.98],[1,1.77,8.83],[2,1.76,90]],"ltp":0.0,"tv":0.0,"id":27227336},{"batb":[[0,1.78,1.98],[1,1.77,8.83],[2,1.76,90]],"ltp":0.0,"tv":0.0,"id":21641292},{"batb":[[0,1.24,39.33]],"ltp":1.59,"tv":23.62,"id":16325787}]}]}
{"op":"mcm","clk":"989812830","pt":1580491556785,"mc":[{"id":"1.168133553","rc":[{"batb":[[0,1.79,90],[1,1.78,1.98],[2,1.77,8.83]],"ltp":0.0,"tv":0.0,"id":27227336},{"batb":[[0,1.79,90],[1,1.78,1.98],[2,1.77,8.83]],"ltp":0.0,"tv":0.0,"id":21641292}]}]}
{"op":"mcm","clk":"989813849","pt":1580491566490,"mc":[{"id":"1.168133553","rc":[{"batb":[[0,1.24,36.33]],"ltp":1.59,"tv":23.62,"id":16325787}]}]}
{"op":"mcm","clk":"989813894","pt":1580491566883,"mc":[{"id":"1.168133553","rc":[{"batb":[[0,1.25,3],[1,1.24,36.33],[2,1.22,10]],"ltp":1.59,"tv":23.62,"id":16325787}]}]}
{"op":"mcm","clk":"989814544","pt":1580491572906,"mc":[{"id":"1.168133553","rc":[{"batb":[[0,1.8,10],[1,1.79,90],[2,1.78,1.98]],"ltp":0.0,"tv":0.0,"id":27227336},{"batb":[[0,1.8,10],[1,1.79,90],[2,1.78,1.98]],"ltp":0.0,"tv":0.0,"id":21641292},{"batb":[[0,1.25,13],[2,1.21,3.51]],"ltp":1.59,"tv":23.62,"id":16325787}]}]}
{"op":"mcm","clk":"989815190","pt":1580491579000,"mc":[{"id":"1.168133553","rc":[{"batb":[[0,1.81,5.62],[1,1.8,10],[2,1.79,90]],"ltp":0.0,"tv":0.0,"id":27227336},{"batb":[[0,1.81,5.62],[1,1.8,10],[2,1.79,90]],"ltp":0.0,"tv":0.0,"id":21641292}]}]}
{"op":"mcm","clk":"989815617","pt":1580491583434,"mc":[{"id":"1.168133553","rc":[{"batb":[[0,1.26,3],[1,1.25,10],[2,1.24,36.33]],"ltp":1.59,"tv":23.62,"id":16325787}]}]}
{"op":"mcm","clk":"989816472","pt":1580491591450,"mc":[{"id":"1.168133553","rc":[{"batb":[[0,1.83,90],[1,1.81,5.62],[2,1.8,10]],"ltp":0.0,"tv":0.0,"id":27227336},{"batb":[[0,1.83,90],[1,1.81,5.62],[2,1.8,10]],"ltp":0.0,"tv":0.0,"id":21641292}]}]}
{"op":"mcm","clk":"989818227","pt":1580491608526,"mc":[{"id":"1.168133553","rc":[{"batb":[[0,1.84,5.42],[1,1.83,90]],"ltp":0.0,"tv":0.0,"id":27227336},{"batb":[[0,1.84,5.42],[1,1.83,90]],"ltp":0.0,"tv":0.0,"id":21641292}]}]}
{"op":"mcm","clk":"989820123","pt":1580491626454,"mc":[{"id":"1.168133553","rc":[{"batb":[[0,1.86,90],[1,1.84,5.42]],"ltp":0.0,"tv":0.0,"id":27227336},{"batb":[[0,1.86,90],[1,1.84,5.42]],"ltp":0.0,"tv":0.0,"id":21641292}]}]}
{"op":"mcm","clk":"989821303","pt":1580491637279,"mc":[{"id":"1.168133553","rc":[{"batb":[[0,1.87,10],[1,1.86,90],[2,1.84,5.42]],"ltp":0.0,"tv":0.0,"id":27227336},{"batb":[[0,1.87,10],[1,1.86,90],[2,1.84,5.42]],"ltp":0.0,"tv":0.0,"id":21641292}]}]}
{"op":"mcm","clk":"989821440","pt":1580491638811,"mc":[{"id":"1.168133553","rc":[{"batb":[[2,1.78,1.98]],"ltp":0.0,"tv":0.0,"id":27227336},{"batb":[[2,1.78,1.98]],"ltp":0.0,"tv":0.0,"id":21641292}]}]}
{"op":"mcm","clk":"989822412","pt":1580491648423,"mc":[{"id":"1.168133553","rc":[{"batb":[[0,1.88,1.99],[1,1.87,10],[2,1.86,90]],"ltp":0.0,"tv":0.0,"id":27227336}]}]}
{"op":"mcm","clk":"989822485","pt":1580491649049,"mc":[{"id":"1.168133553","rc":[{"batb":[[0,1.88,1.99],[1,1.87,10],[2,1.86,90]],"ltp":0.0,"tv":0.0,"id":21641292}]}]}
{"op":"mcm","clk":"989822620","pt":1580491650266,"mc":[{"id":"1.168133553","rc":[{"batb":[[0,1.89,1.98],[1,1.88,1.99],[2,1.87,10]],"ltp":0.0,"tv":0.0,"id":27227336},{"batb":[[0,1.89,1.98],[1,1.88,1.99],[2,1.87,10]],"ltp":0.0,"tv":0.0,"id":21641292},{"batb":[[0,1.26,38],[2,1.24,1.33]],"ltp":1.59,"tv":23.62,"id":16325787}]}]}
