{"op":"mcm","clk":"993359184","pt":1580541228576,"mc":[{"id":"1.168130661","rc":[{"batb":[[0,2.68,4],[1,2.66,3],[2,2.64,2]],"batl":[[2,2.86,1.68]],"ltp":2.54,"tv":2086.26,"id":25238892}]}]}
{"op":"mcm","clk":"993361797","pt":1580541281323,"mc":[{"id":"1.168130661","rc":[{"batb":[[0,2.66,2],[1,2.64,2],[2,2.62,65.43]],"ltp":2.62,"tv":2233.99,"id":26314798}]}]}
{"op":"mcm","clk":"993362008","pt":1580541285644,"mc":[{"id":"1.168130661","rc":[{"batb":[[2,2.6,26.76]],"ltp":2.62,"tv":2233.99,"id":26314798}]}]}
{"op":"mcm","clk":"993365202","pt":1580541349533,"mc":[{"id":"1.168130661","rc":[{"batl":[[0,2.68,10]],"ltp":2.62,"tv":2233.99,"id":26314798}]}]}
{"op":"mcm","clk":"993365415","pt":1580541353635,"mc":[{"id":"1.168130661","rc":[{"batl":[[0,2.68,5]],"ltp":2.62,"tv":2233.99,"id":26314798}]}]}
{"op":"mcm","clk":"993365810","pt":1580541360448,"mc":[{"id":"1.168130661","rc":[{"batl":[[0,2.68,10]],"ltp":2.62,"tv":2233.99,"id":26314798}]}]}
{"op":"mcm","clk":"993367494","pt":1580541388582,"mc":[{"id":"1.168130661","rc":[{"trd":[[9.8,32.2]],"batb":[[0,9.6,7],[1,9.4,8.24],[2,9.2,7.63]],"batl":[[0,10,3.85]],"ltp":9.8,"tv":327.81,"id":24420205}],"tv":5159.53}]}
{"op":"mcm","clk":"993371044","pt":1580541453471,"mc":[{"id":"1.168130661","rc":[{"batb":[[0,14.5,1.18],[1,14,9.46],[2,13.5,5]],"ltp":14.0,"tv":237.61,"id":420}]}]}
{"op":"mcm","clk":"993373490","pt":1580541506651,"mc":[{"id":"1.168130661","rc":[{"trd":[[2.68,57.57]],"batb":[[0,2.66,3],[1,2.64,2],[2,2.62,12]],"batl":[[0,2.68,1.81],[1,2.7,11.21],[2,2.76,1.18]],"ltp":2.68,"tv":2094.26,"id":25238892}],"tv":5167.53}]}
{"op":"mcm","clk":"993375439","pt":1580541546141,"mc":[{"id":"1.168130661","rc":[{"batl":[[0,2.7,11.21],[1,2.76,1.18],[2,2.84,6]],"ltp":2.68,"tv":2094.26,"id":25238892}]}]}
{"op":"mcm","clk":"993376917","pt":1580541576701,"mc":[{"id":"1.168130661","rc":[{"batl":[[2,2.86,1.68]],"ltp":2.68,"tv":2094.26,"id":25238892}]}]}
{"op":"mcm","clk":"993377358","pt":1580541585599,"mc":[{"id":"1.168130661","rc":[{"trd":[[44,5.96]],"batl":[[0,50,1.82],[1,75,2],[2,150,2.95]],"ltp":44.0,"tv":72.85,"id":25545675},{"trd":[[2.6,78.32],[2.62,42.58],[2.64,74.82],[2.66,21]],"batb":[[0,2.54,47.37],[1,2.52,99],[2,2.5,6.75]],"batl":[[0,2.6,66.84]],"ltp":2.6,"tv":2160.58,"id":25238892},{"trd":[[15.5,45.28]],"batl":[[0,15.5,3.59]],"ltp":15.5,"tv":211.69,"id":24707172},{"trd":[[9.8,33.73],[10,102.44],[10.5,14.99]],"batb":[[1,9.4,5.39]],"batl":[[0,10,3.83],[1,10.5,5.79]],"ltp":10.5,"tv":335.94,"id":24420205},{"trd":[[2.68,127.77],[2.7,441.77]],"batl":[[0,2.7,5.23],[1,2.72,6],[2,2.74,84.92]],"ltp":2.7,"tv":2265.27,"id":26314798},{"trd":[[15.5,5.42]],"batl":[[0,16.5,3],[1,18.5,2.6],[2,22,11.08]],"ltp":15.5,"tv":243.03,"id":420}],"tv":5289.38}]}
{"op":"mcm","clk":"993377414","pt":1580541586696,"mc":[{"id":"1.168130661","rc":[{"trd":[[10,104.12]],"batl":[[0,10,2.99]],"ltp":10.0,"tv":337.62,"id":24420205}],"tv":5291.06}]}
{"op":"mcm","clk":"993377505","pt":1580541588410,"mc":[{"id":"1.168130661","rc":[{"batl":[[0,50,2.01]],"ltp":44.0,"tv":72.85,"id":25545675}]}]}
{"op":"mcm","clk":"993377864","pt":1580541595679,"mc":[{"id":"1.168130661","rc":[{"batb":[[0,30,5.31]],"ltp":44.0,"tv":72.85,"id":25545675},{"batl":[[0,2.7,10.23]],"ltp":2.7,"tv":2265.27,"id":26314798}]}]}
{"op":"mcm","clk":"993378332","pt":1580541604695,"mc":[{"id":"1.168130661","rc":[{"batb":[[0,32,1.66],[1,30,4.81],[2,29,4.3]],"ltp":44.0,"tv":72.85,"id":25545675},{"batl":[[0,2.76,1.18],[1,2.86,1.68],[2,2.88,3]],"ltp":2.6,"tv":2160.58,"id":25238892}]}]}
{"op":"mcm","clk":"993378451","pt":1580541606598,"mc":[{"id":"1.168130661","rc":[{"batl":[[2,170,1.28]],"ltp":44.0,"tv":72.85,"id":25545675},{"batb":[[1,2.5,6.75],[2,2.48,111]],"batl":[[1,2.84,2],[2,2.86,1.68]],"ltp":2.6,"tv":2160.58,"id":25238892},{"batl":[[0,16,2],[1,16.5,3],[2,18.5,2.6]],"ltp":15.5,"tv":243.03,"id":420}]}]}
{"op":"mcm","clk":"993378500","pt":1580541607631,"mc":[{"id":"1.168130661","rc":[{"batb":[[1,2.5,16.05]],"ltp":2.6,"tv":2160.58,"id":25238892}]}]}
{"op":"mcm","clk":"993378652","pt":1580541610720,"mc":[{"id":"1.168130661","rc":[{"batl":[[0,2.68,2],[1,2.7,10.23],[2,2.72,6]],"ltp":2.7,"tv":2265.27,"id":26314798},{"batb":[[1,13.5,5],[2,13,3.9]],"ltp":15.5,"tv":243.03,"id":420}]}]}
{"op":"mcm","clk":"993378877","pt":1580541615104,"mc":[{"id":"1.168130661","rc":[{"batb":[[2,29,4.9]],"ltp":44.0,"tv":72.85,"id":25545675}]}]}
{"op":"mcm","clk":"993379858","pt":1580541634397,"mc":[{"id":"1.168130661","rc":[{"trd":[[2.48,18.82],[2.5,36.1],[2.54,231.67]],"batb":[[0,2.48,101.59],[1,2.46,4.5],[2,2.44,6]],"ltp":2.48,"tv":2306.25,"id":25238892}],"tv":5436.73}]}
{"op":"mcm","clk":"993380378","pt":1580541645266,"mc":[{"id":"1.168130661","rc":[{"batl":[[1,2.8,9.72],[2,2.84,2]],"ltp":2.48,"tv":2306.25,"id":25238892}]}]}
{"op":"mcm","clk":"993380822","pt":1580541653713,"mc":[{"id":"1.168130661","rc":[{"batb":[[1,2.44,6],[2,2.42,83.61]],"ltp":2.48,"tv":2306.25,"id":25238892}]}]}
{"op":"mcm","clk":"993381080","pt":1580541660201,"mc":[{"id":"1.168130661","rc":[{"batl":[[1,2.78,2],[2,2.8,9.72]],"ltp":2.48,"tv":2306.25,"id":25238892}]}]}
{"op":"mcm","clk":"993381410","pt":1580541667985,"mc":[{"id":"1.168130661","rc":[{"batl":[[0,2.74,7.6],[1,2.76,1.18],[2,2.78,2]],"ltp":2.48,"tv":2306.25,"id":25238892}]}]}
{"op":"mcm","clk":"993381627","pt":1580541673323,"mc":[{"id":"1.168130661","rc":[{"trd":[[2.68,131.77]],"batl":[[0,2.7,10.23],[1,2.72,6],[2,2.74,84.92]],"ltp":2.68,"tv":2269.27,"id":26314798}],"tv":5440.73}]}
{"op":"mcm","clk":"993381684","pt":1580541674713,"mc":[{"id":"1.168130661","rc":[{"batb":[[0,2.66,8.48],[1,2.64,4]],"ltp":2.68,"tv":2269.27,"id":26314798}]}]}
{"op":"mcm","clk":"993382220","pt":1580541687532,"mc":[{"id":"1.168130661","rc":[{"batb":[[0,2.5,5],[1,2.48,101.59],[2,2.44,6]],"ltp":2.48,"tv":2306.25,"id":25238892}]}]}
{"op":"mcm","clk":"993382591","pt":1580541695128,"mc":[{"id":"1.168130661","rc":[{"batb":[[1,9.4,7.39]],"ltp":10.0,"tv":337.62,"id":24420205}]}]}
{"op":"mcm","clk":"993383543","pt":1580541714262,"mc":[{"id":"1.168130661","rc":[{"batl":[[0,2.72,2],[1,2.74,7.6],[2,2.76,1.18]],"ltp":2.48,"tv":2306.25,"id":25238892}]}]}
{"op":"mcm","clk":"993396386","pt":1580541771527,"mc":[{"id":"1.168130661","rc":[{"trd":[[2.5,40.2]],"batb":[[0,2.5,2.95]],"ltp":2.5,"tv":2310.35,"id":25238892}],"tv":5444.83}]}
{"op":"mcm","clk":"993396954","pt":1580541782546,"mc":[{"id":"1.168130661","rc":[{"batl":[[0,2.68,2],[1,2.7,10.23],[2,2.72,6]],"ltp":2.68,"tv":2269.27,"id":26314798}]}]}
{"op":"mcm","clk":"993399806","pt":1580541834309,"mc":[{"id":"1.168130661","rc":[{"batb":[[0,32,1.16]],"ltp":44.0,"tv":72.85,"id":25545675}]}]}
{"op":"mcm","clk":"993401278","pt":1580541859564,"mc":[{"id":"1.168130661","rc":[{"trd":[[2.5,44.2]],"batb":[[0,2.48,102.54],[1,2.44,6],[2,2.42,83.61]],"ltp":2.5,"tv":2314.35,"id":25238892}],"tv":5448.83}]}
{"op":"mcm","clk":"993402317","pt":1580541879304,"mc":[{"id":"1.168130661","rc":[{"batl":[[0,2.72,7.85]],"ltp":2.5,"tv":2314.35,"id":25238892}]}]}
{"op":"mcm","clk":"993402663","pt":1580541885265,"mc":[{"id":"1.168130661","rc":[{"batl":[[1,10.5,10.79]],"ltp":10.0,"tv":337.62,"id":24420205}]}]}
{"op":"mcm","clk":"993403167","pt":1580541893702,"mc":[{"id":"1.168130661","rc":[{"batl":[[1,2.76,1.18],[2,2.86,88.68]],"ltp":2.5,"tv":2314.35,"id":25238892}]}]}
{"op":"mcm","clk":"993403969","pt":1580541906428,"mc":[{"id":"1.168130661","rc":[{"batl":[[2,2.86,1.68]],"ltp":2.5,"tv":2314.35,"id":25238892}]}]}
{"op":"mcm","clk":"993404142","pt":1580541909315,"mc":[{"id":"1.168130661","rc":[{"batl":[[0,2.7,7.6],[1,2.72,7.85],[2,2.76,1.18]],"ltp":2.5,"tv":2314.35,"id":25238892}]}]}
{"op":"mcm","clk":"993404360","pt":1580541912304,"mc":[{"id":"1.168130661","rc":[{"batb":[[0,32,2.74]],"ltp":44.0,"tv":72.85,"id":25545675},{"batb":[[0,2.48,122.96]],"ltp":2.5,"tv":2314.35,"id":25238892},{"batb":[[0,14.5,11.26]],"ltp":15.5,"tv":211.69,"id":24707172},{"batb":[[0,9.6,12.27]],"ltp":10.0,"tv":337.62,"id":24420205},{"batb":[[0,2.66,27.52]],"ltp":2.68,"tv":2269.27,"id":26314798},{"batb":[[0,14.5,4.68]],"ltp":15.5,"tv":243.03,"id":420}]}]}
{"op":"mcm","clk":"993404623","pt":1580541916651,"mc":[{"id":"1.168130661","rc":[{"batb":[[0,32,7.21],[1,29,4.9],[2,27,8.23]],"ltp":44.0,"tv":72.85,"id":25545675}]}]}
{"op":"mcm","clk":"993405171","pt":1580541925936,"mc":[{"id":"1.168130661","rc":[{"batb":[[0,2.5,2.95],[1,2.48,122.01],[2,2.44,6]],"ltp":2.5,"tv":2314.35,"id":25238892}]}]}
{"op":"mcm","clk":"993405359","pt":1580541928635,"mc":[{"id":"1.168130661","rc":[{"batb":[[0,2.5,3.03]],"ltp":2.5,"tv":2314.35,"id":25238892},{"trd":[[2.68,135.78]],"batl":[[0,2.7,10.23],[1,2.72,6],[2,2.74,84.92]],"ltp":2.68,"tv":2273.27,"id":26314798}],"tv":5452.83}]}
{"op":"mcm","clk":"993405398","pt":1580541929152,"mc":[{"id":"1.168130661","rc":[{"batl":[[0,2.68,2],[1,2.7,7.6],[2,2.72,5.85]],"ltp":2.5,"tv":2314.35,"id":25238892},{"batl":[[0,16.5,3],[1,18.5,2.6],[2,22,11.08]],"ltp":15.5,"tv":243.03,"id":420}]}]}
{"op":"mcm","clk":"993405477","pt":1580541930238,"mc":[{"id":"1.168130661","rc":[{"batb":[[0,2.66,29.52]],"ltp":2.68,"tv":2273.27,"id":26314798}]}]}
{"op":"mcm","clk":"993405942","pt":1580541936449,"mc":[{"id":"1.168130661","rc":[{"batl":[[2,32,9.08]],"ltp":15.5,"tv":243.03,"id":420}]}]}
{"op":"mcm","clk":"993411258","pt":1580542013664,"mc":[{"id":"1.168130661","rc":[{"trd":[[14.5,42.9],[15,66.06]],"batb":[[0,13.5,12.02],[1,13,4.7],[2,12.5,2]],"batl":[[0,14.5,3.72],[1,15.5,3.59],[2,18,1.76]],"ltp":14.5,"tv":234.23,"id":24707172}],"tv":5475.37}]}
{"op":"mcm","clk":"993411283","pt":1580542013924,"mc":[{"id":"1.168130661","rc":[{"batb":[[1,13,7.03]],"ltp":14.5,"tv":234.23,"id":24707172}]}]}
{"op":"mcm","clk":"993411639","pt":1580542019928,"mc":[{"id":"1.168130661","rc":[{"batb":[[1,13,4.7]],"ltp":14.5,"tv":234.23,"id":24707172}]}]}
{"op":"mcm","clk":"993412441","pt":1580542031643,"mc":[{"id":"1.168130661","rc":[{"trd":[[2.66,91.65]],"batb":[[0,2.66,27.52]],"ltp":2.66,"tv":2277.27,"id":26314798}],"tv":5479.37}]}
{"op":"mcm","clk":"993415219","pt":1580542073491,"mc":[{"id":"1.168130661","rc":[{"batb":[[0,2.68,2],[1,2.66,27.52],[2,2.64,2]],"ltp":2.66,"tv":2277.27,"id":26314798}]}]}
{"op":"mcm","clk":"993415728","pt":1580542081647,"mc":[{"id":"1.168130661","rc":[{"batb":[[0,2.5,5.03]],"ltp":2.5,"tv":2314.35,"id":25238892}]}]}
{"op":"mcm","clk":"993415907","pt":1580542084447,"mc":[{"id":"1.168130661","rc":[{"batb":[[0,14,3],[1,13.5,12.02],[2,13,4.7]],"ltp":14.5,"tv":234.23,"id":24707172}]}]}
{"op":"mcm","clk":"993416301","pt":1580542090681,"mc":[{"id":"1.168130661","rc":[{"trd":[[14.5,50.34]],"batl":[[0,15.5,3.59],[1,18,1.76],[2,21,26.12]],"ltp":14.5,"tv":241.67,"id":24707172}],"tv":5486.81}]}
{"op":"mcm","clk":"993416691","pt":1580542096720,"mc":[{"id":"1.168130661","rc":[{"batl":[[2,2.76,1.18]],"ltp":2.5,"tv":2314.35,"id":25238892}]}]}
{"op":"mcm","clk":"993417405","pt":1580542108547,"mc":[{"id":"1.168130661","rc":[{"trd":[[14.5,11.73]],"batb":[[0,13.5,5],[1,13,3.9],[2,12,4.53]],"ltp":14.5,"tv":252.39,"id":420}],"tv":5496.17}]}
{"op":"mcm","clk":"993417903","pt":1580542116766,"mc":[{"id":"1.168130661","rc":[{"batl":[[2,21,14.12]],"ltp":14.5,"tv":241.67,"id":24707172}]}]}
{"op":"mcm","clk":"993418046","pt":1580542119549,"mc":[{"id":"1.168130661","rc":[{"batl":[[0,16.5,3.99]],"ltp":14.5,"tv":252.39,"id":420}]}]}
{"op":"mcm","clk":"993418557","pt":1580542128371,"mc":[{"id":"1.168130661","rc":[{"batb":[[0,14,9.46],[1,13.5,5],[2,13,3.9]],"ltp":14.5,"tv":252.39,"id":420}]}]}
{"op":"mcm","clk":"993419010","pt":1580542135550,"mc":[{"id":"1.168130661","rc":[{"batl":[[1,2.76,1.18],[2,2.86,88.68]],"ltp":2.5,"tv":2314.35,"id":25238892}]}]}
{"op":"mcm","clk":"993419065","pt":1580542136479,"mc":[{"id":"1.168130661","rc":[{"batl":[[2,2.84,8.18]],"ltp":2.5,"tv":2314.35,"id":25238892}]}]}
{"op":"mcm","clk":"993419633","pt":1580542145721,"mc":[{"id":"1.168130661","rc":[{"batl":[[0,2.76,1.18],[1,2.84,8.18],[2,2.86,88.68]],"ltp":2.5,"tv":2314.35,"id":25238892}]}]}
{"op":"mcm","clk":"993419694","pt":1580542146598,"mc":[{"id":"1.168130661","rc":[{"batl":[[1,2.82,2],[2,2.84,8.18]],"ltp":2.5,"tv":2314.35,"id":25238892},{"batl":[[0,16,2.99],[1,16.5,3],[2,18.5,2.6]],"ltp":14.5,"tv":252.39,"id":420}]}]}
{"op":"mcm","clk":"993419766","pt":1580542147685,"mc":[{"id":"1.168130661","rc":[{"batl":[[2,2.86,1.68]],"ltp":2.5,"tv":2314.35,"id":25238892},{"batb":[[0,13.5,5],[1,13,3.9],[2,12,4.53]],"ltp":14.5,"tv":252.39,"id":420}]}]}
{"op":"mcm","clk":"993422995","pt":1580542199697,"mc":[{"id":"1.168130661","rc":[{"batl":[[1,2.86,1.68],[2,2.9,1.18]],"ltp":2.5,"tv":2314.35,"id":25238892}]}]}
{"op":"mcm","clk":"993423066","pt":1580542200584,"mc":[{"id":"1.168130661","rc":[{"batl":[[1,2.84,2],[2,2.86,1.68]],"ltp":2.5,"tv":2314.35,"id":25238892},{"trd":[[10,110.1]],"batb":[[0,9.8,6.26],[1,9.6,12.27],[2,9.4,7.39]],"batl":[[0,10.5,10.79],[1,11.5,40],[2,12.5,9.41]],"ltp":10.0,"tv":343.6,"id":24420205}],"tv":5502.15}]}
{"op":"mcm","clk":"993423153","pt":1580542201680,"mc":[{"id":"1.168130661","rc":[{"batb":[[0,10,12.43],[1,9.8,6.26],[2,9.6,12.27]],"ltp":10.0,"tv":343.6,"id":24420205}]}]}
{"op":"mcm","clk":"993423743","pt":1580542210214,"mc":[{"id":"1.168130661","rc":[{"batl":[[0,2.74,7.6],[1,2.76,1.18],[2,2.84,2]],"ltp":2.5,"tv":2314.35,"id":25238892}]}]}
{"op":"mcm","clk":"993425113","pt":1580542229317,"mc":[{"id":"1.168130661","rc":[{"batl":[[0,10.5,5]],"ltp":10.0,"tv":343.6,"id":24420205}]}]}
{"op":"mcm","clk":"993425589","pt":1580542235640,"mc":[{"id":"1.168130661","rc":[{"batb":[[0,2.52,6.91],[1,2.5,4.95],[2,2.48,122.01]],"ltp":2.5,"tv":2314.35,"id":25238892},{"batb":[[0,14,4.23]],"ltp":14.5,"tv":241.67,"id":24707172}]}]}
{"op":"mcm","clk":"993425698","pt":1580542237034,"mc":[{"id":"1.168130661","rc":[{"batl":[[1,11,6],[2,11.5,40]],"ltp":10.0,"tv":343.6,"id":24420205}]}]}
{"op":"mcm","clk":"993426909","pt":1580542253645,"mc":[{"id":"1.168130661","rc":[{"batl":[[2,2.86,1.68]],"ltp":2.5,"tv":2314.35,"id":25238892}]}]}
{"op":"mcm","clk":"993426925","pt":1580542253853,"mc":[{"id":"1.168130661","rc":[{"batl":[[0,2.7,3.36],[1,2.72,2],[2,2.74,7.6]],"ltp":2.5,"tv":2314.35,"id":25238892}]}]}
{"op":"mcm","clk":"993427051","pt":1580542255654,"mc":[{"id":"1.168130661","rc":[{"batl":[[0,2.72,2],[1,2.74,7.6],[2,2.76,1.18]],"ltp":2.5,"tv":2314.35,"id":25238892}]}]}
{"op":"mcm","clk":"993427611","pt":1580542262482,"mc":[{"id":"1.168130661","rc":[{"batl":[[0,16,4.99]],"ltp":14.5,"tv":252.39,"id":420}]}]}
{"op":"mcm","clk":"993428045","pt":1580542268776,"mc":[{"id":"1.168130661","rc":[{"batl":[[0,16,5.99]],"ltp":14.5,"tv":252.39,"id":420}]}]}
{"op":"mcm","clk":"993428646","pt":1580542275673,"mc":[{"id":"1.168130661","rc":[{"batl":[[0,16,4.99]],"ltp":14.5,"tv":252.39,"id":420}]}]}
{"op":"mcm","clk":"993428779","pt":1580542277577,"mc":[{"id":"1.168130661","rc":[{"batl":[[0,15.5,3],[1,16,4.99],[2,16.5,3]],"ltp":14.5,"tv":252.39,"id":420}]}]}
{"op":"mcm","clk":"993429428","pt":1580542287203,"mc":[{"id":"1.168130661","rc":[{"batl":[[0,15,1],[1,15.5,3],[2,16,3.99]],"ltp":14.5,"tv":252.39,"id":420}]}]}
{"op":"mcm","clk":"993429876","pt":1580542291186,"mc":[{"id":"1.168130661","rc":[{"batl":[[0,14.5,1]],"ltp":14.5,"tv":252.39,"id":420}]}]}
{"op":"mcm","clk":"993430270","pt":1580542294692,"mc":[{"id":"1.168130661","rc":[{"batl":[[0,14,1]],"ltp":14.5,"tv":252.39,"id":420}]}]}
{"op":"mcm","clk":"993430397","pt":1580542296699,"mc":[{"id":"1.168130661","rc":[{"trd":[[13.5,2]],"batb":[[0,13.5,4]],"batl":[[0,15.5,3],[1,16,3.99],[2,16.5,3]],"ltp":13.5,"tv":254.39,"id":420}],"tv":5504.15}]}
{"op":"mcm","clk":"993431298","pt":1580542307611,"mc":[{"id":"1.168130661","rc":[{"batl":[[1,16,1.99]],"ltp":13.5,"tv":254.39,"id":420}]}]}
{"op":"mcm","clk":"993431522","pt":1580542311014,"mc":[{"id":"1.168130661","rc":[{"trd":[[13.5,4]],"batb":[[0,13.5,3]],"batl":[[1,16.5,3.99],[2,18.5,2.6]],"ltp":13.5,"tv":256.39,"id":420}],"tv":5506.15}]}
{"op":"mcm","clk":"993431692","pt":1580542313630,"mc":[{"id":"1.168130661","rc":[{"batl":[[0,16.5,3.99],[1,18.5,2.6],[2,19,13]],"ltp":13.5,"tv":256.39,"id":420}]}]}
{"op":"mcm","clk":"993431701","pt":1580542313734,"mc":[{"id":"1.168130661","rc":[{"batl":[[0,15,3],[1,16.5,3.99],[2,18.5,2.6]],"ltp":13.5,"tv":256.39,"id":420}]}]}
{"op":"mcm","clk":"993432778","pt":1580542326459,"mc":[{"id":"1.168130661","rc":[{"trd":[[50,2.6]],"batl":[[0,75,2.95],[1,170,1.28],[2,230,9]],"ltp":50.0,"tv":74.59,"id":25545675},{"trd":[[2.52,56.91]],"batb":[[0,2.5,4.95],[1,2.48,122.01],[2,2.44,6]],"batl":[[0,2.52,2.23],[1,2.72,2],[2,2.74,7.6]],"ltp":2.52,"tv":2369.89,"id":25238892},{"trd":[[15.5,52.46]],"batl":[[0,18,1.76],[1,21,14.12],[2,29,2.45]],"ltp":15.5,"tv":248.85,"id":24707172},{"trd":[[10.5,24.99]],"batl":[[0,11,6],[1,11.5,40],[2,12.5,9.41]],"ltp":10.5,"tv":353.6,"id":24420205},{"trd":[[2.7,462.23],[2.72,113.42],[2.74,52.4]],"batl":[[0,2.74,81.78],[1,2.76,199],[2,2.78,110.72]],"ltp":2.74,"tv":2316.01,"id":26314798},{"trd":[[15,6],[16,0.58]],"batl":[[0,16.5,3.7],[1,18.5,2.6],[2,19,13]],"ltp":16.0,"tv":262.97,"id":420}],"tv":5625.94}]}
{"op":"mcm","clk":"993432833","pt":1580542327138,"mc":[{"id":"1.168130661","rc":[{"trd":[[2.52,61.37]],"batl":[[0,2.72,2],[1,2.74,7.6],[2,2.76,1.18]],"ltp":2.52,"tv":2374.35,"id":25238892},{"batb":[[0,2.7,6],[1,2.68,2],[2,2.66,27.52]],"batl":[[0,2.74,97.55]],"ltp":2.74,"tv":2316.01,"id":26314798},{"batl":[[2,23,11.08]],"ltp":16.0,"tv":262.97,"id":420}],"tv":5630.4}]}
{"op":"mcm","clk":"993432987","pt":1580542329249,"mc":[{"id":"1.168130661","rc":[{"trd":[[2.74,56.86]],"batl":[[0,2.74,95.32],[2,2.78,112.83]],"ltp":2.74,"tv":2320.47,"id":26314798}],"tv":5634.86}]}
{"op":"mcm","clk":"993433078","pt":1580542330543,"mc":[{"id":"1.168130661","rc":[{"batb":[[0,32,7.48]],"ltp":50.0,"tv":74.59,"id":25545675}]}]}
{"op":"mcm","clk":"993433134","pt":1580542331566,"mc":[{"id":"1.168130661","rc":[{"batb":[[0,16,7.46],[1,14,4.23],[2,13.5,12.02]],"ltp":15.5,"tv":248.85,"id":24707172}]}]}
{"op":"mcm","clk":"993433477","pt":1580542336679,"mc":[{"id":"1.168130661","rc":[{"trd":[[11,16.76]],"batl":[[0,11.5,40.12],[1,12.5,9.41],[2,14,2.52]],"ltp":11.0,"tv":365.36,"id":24420205}],"tv":5646.62}]}
{"op":"mcm","clk":"993433549","pt":1580542337662,"mc":[{"id":"1.168130661","rc":[{"trd":[[11,17]],"batl":[[0,11.5,40],[1,12.5,13.96]],"ltp":11.0,"tv":365.6,"id":24420205}],"tv":5646.86}]}
{"op":"mcm","clk":"993433619","pt":1580542338688,"mc":[{"id":"1.168130661","rc":[{"batb":[[0,32,3.51]],"ltp":50.0,"tv":74.59,"id":25545675}]}]}
{"op":"mcm","clk":"993433691","pt":1580542339571,"mc":[{"id":"1.168130661","rc":[{"batl":[[0,16.5,3]],"ltp":16.0,"tv":262.97,"id":420}]}]}
{"op":"mcm","clk":"993433918","pt":1580542342655,"mc":[{"id":"1.168130661","rc":[{"batl":[[1,12,4],[2,12.5,13.96]],"ltp":11.0,"tv":365.6,"id":24420205}]}]}
{"op":"mcm","clk":"993434062","pt":1580542344864,"mc":[{"id":"1.168130661","rc":[{"batb":[[1,29,4.3]],"ltp":50.0,"tv":74.59,"id":25545675}]}]}
{"op":"mcm","clk":"993434310","pt":1580542348602,"mc":[{"id":"1.168130661","rc":[{"trd":[[16,20.64]],"batb":[[0,16,2.76]],"ltp":16.0,"tv":258.25,"id":24707172},{"trd":[[10,134.96]],"batb":[[0,9.8,6.26],[1,9.6,12.27],[2,9.4,7.39]],"ltp":10.0,"tv":390.46,"id":24420205}],"tv":5681.11}]}
{"op":"mcm","clk":"993434324","pt":1580542348782,"mc":[{"id":"1.168130661","rc":[{"batb":[[0,9.6,12.27],[1,9.4,7.39],[2,9.2,7.63]],"ltp":10.0,"tv":390.46,"id":24420205}]}]}
{"op":"mcm","clk":"993434504","pt":1580542351359,"mc":[{"id":"1.168130661","rc":[{"batb":[[0,14,4.23],[1,13.5,12.02],[2,13,4.7]],"ltp":16.0,"tv":258.25,"id":24707172}]}]}
{"op":"mcm","clk":"993434580","pt":1580542352694,"mc":[{"id":"1.168130661","rc":[{"batb":[[2,27,8.86]],"ltp":50.0,"tv":74.59,"id":25545675}]}]}
{"op":"mcm","clk":"993434850","pt":1580542357691,"mc":[{"id":"1.168130661","rc":[{"batl":[[1,21,14.37]],"ltp":16.0,"tv":258.25,"id":24707172},{"batl":[[2,32,9.08]],"ltp":16.0,"tv":262.97,"id":420}]}]}
{"op":"mcm","clk":"993435031","pt":1580542361297,"mc":[{"id":"1.168130661","rc":[{"batl":[[0,17.5,2],[1,18,1.76],[2,21,14.37]],"ltp":16.0,"tv":258.25,"id":24707172},{"batl":[[0,11,2],[1,11.5,40],[2,12,4]],"ltp":10.0,"tv":390.46,"id":24420205}]}]}
{"op":"mcm","clk":"993435110","pt":1580542362688,"mc":[{"id":"1.168130661","rc":[{"batb":[[0,14.5,1.1],[1,14,4.23],[2,13.5,12.02]],"ltp":16.0,"tv":258.25,"id":24707172},{"batl":[[0,11,3.45]],"ltp":10.0,"tv":390.46,"id":24420205}]}]}
{"op":"mcm","clk":"993437104","pt":1580542392356,"mc":[{"id":"1.168130661","rc":[{"batl":[[0,70,8.55],[1,75,2],[2,170,1.28]],"ltp":50.0,"tv":74.59,"id":25545675}]}]}
{"op":"mcm","clk":"993437316","pt":1580542395631,"mc":[{"id":"1.168130661","rc":[{"trd":[[2.72,70.79],[2.74,192.81]],"batl":[[0,2.74,4.47],[1,2.76,1.18],[2,2.84,8.18]],"ltp":2.74,"tv":2384.61,"id":25238892}],"tv":5691.37}]}
{"op":"mcm","clk":"993437843","pt":1580542403551,"mc":[{"id":"1.168130661","rc":[{"batl":[[0,11,7.45],[2,12.5,9.41]],"ltp":10.0,"tv":390.46,"id":24420205}]}]}
{"op":"mcm","clk":"993438039","pt":1580542406659,"mc":[{"id":"1.168130661","rc":[{"batb":[[0,9.6,14.27]],"ltp":10.0,"tv":390.46,"id":24420205}]}]}
{"op":"mcm","clk":"993438675","pt":1580542415672,"mc":[{"id":"1.168130661","rc":[{"batl":[[0,11,5.45]],"ltp":10.0,"tv":390.46,"id":24420205}]}]}
{"op":"mcm","clk":"993438736","pt":1580542416655,"mc":[{"id":"1.168130661","rc":[{"batl":[[0,65,1.03],[1,70,7.6],[2,75,2]],"ltp":50.0,"tv":74.59,"id":25545675},{"batb":[[0,2.52,2.16],[1,2.5,4.95],[2,2.48,122.01]],"ltp":2.74,"tv":2384.61,"id":25238892},{"batb":[[0,13.5,4.28]],"batl":[[0,16,2],[1,16.5,3],[2,18.5,2.6]],"ltp":16.0,"tv":262.97,"id":420}]}]}
{"op":"mcm","clk":"993438882","pt":1580542418878,"mc":[{"id":"1.168130661","rc":[{"batl":[[2,2.86,1.68]],"ltp":2.74,"tv":2384.61,"id":25238892}]}]}
{"op":"mcm","clk":"993439535","pt":1580542427656,"mc":[{"id":"1.168130661","rc":[{"batl":[[0,10.5,4],[1,11,5.45],[2,11.5,40]],"ltp":10.0,"tv":390.46,"id":24420205}]}]}
{"op":"mcm","clk":"993440051","pt":1580542435679,"mc":[{"id":"1.168130661","rc":[{"batl":[[0,2.76,1.18],[1,2.86,1.68],[2,2.9,1.18]],"ltp":2.74,"tv":2384.61,"id":25238892}]}]}
{"op":"mcm","clk":"993440105","pt":1580542436605,"mc":[{"id":"1.168130661","rc":[{"batb":[[0,2.54,3.13],[1,2.52,2.16],[2,2.5,4.95]],"ltp":2.74,"tv":2384.61,"id":25238892}]}]}
{"op":"mcm","clk":"993441176","pt":1580542451908,"mc":[{"id":"1.168130661","rc":[{"batl":[[1,2.84,5.6],[2,2.86,1.68]],"ltp":2.74,"tv":2384.61,"id":25238892}]}]}
{"op":"mcm","clk":"993441948","pt":1580542463540,"mc":[{"id":"1.168130661","rc":[{"batl":[[0,2.72,5],[1,2.74,95.32],[2,2.76,199]],"ltp":2.74,"tv":2320.47,"id":26314798}]}]}
{"op":"mcm","clk":"993442251","pt":1580542467933,"mc":[{"id":"1.168130661","rc":[{"batl":[[0,2.72,19]],"ltp":2.74,"tv":2320.47,"id":26314798}]}]}
{"op":"mcm","clk":"993442374","pt":1580542469536,"mc":[{"id":"1.168130661","rc":[{"batb":[[1,2.5,4.95],[2,2.48,122.01]],"ltp":2.74,"tv":2384.61,"id":25238892}]}]}
{"op":"mcm","clk":"993442387","pt":1580542469745,"mc":[{"id":"1.168130661","rc":[{"batb":[[0,2.56,2.13],[1,2.54,3.13],[2,2.5,4.95]],"ltp":2.74,"tv":2384.61,"id":25238892}]}]}
{"op":"mcm","clk":"993443425","pt":1580542485629,"mc":[{"id":"1.168130661","rc":[{"batb":[[0,14.5,4.1]],"ltp":16.0,"tv":258.25,"id":24707172},{"trd":[[2.7,474.23]],"batb":[[0,2.68,2],[1,2.66,27.52],[2,2.64,2]],"batl":[[0,2.72,14]],"ltp":2.7,"tv":2332.47,"id":26314798}],"tv":5703.37}]}
{"op":"mcm","clk":"993443799","pt":1580542491140,"mc":[{"id":"1.168130661","rc":[{"batb":[[0,15,4],[1,14.5,4.1],[2,14,4.23]],"ltp":16.0,"tv":258.25,"id":24707172}]}]}
{"op":"mcm","clk":"993444210","pt":1580542496712,"mc":[{"id":"1.168130661","rc":[{"trd":[[17.5,4.12]],"batl":[[0,18,1.76],[1,21,14.37],[2,29,2.45]],"ltp":17.5,"tv":262.25,"id":24707172}],"tv":5707.37}]}
{"op":"mcm","clk":"993444790","pt":1580542505546,"mc":[{"id":"1.168130661","rc":[{"batl":[[0,2.72,414]],"ltp":2.7,"tv":2332.47,"id":26314798}]}]}
{"op":"mcm","clk":"993444875","pt":1580542506682,"mc":[{"id":"1.168130661","rc":[{"batl":[[0,2.7,16.96],[1,2.72,414],[2,2.74,79.55]],"ltp":2.7,"tv":2332.47,"id":26314798}]}]}
{"op":"mcm","clk":"993445654","pt":1580542517717,"mc":[{"id":"1.168130661","rc":[{"batb":[[1,14.5,3]],"ltp":17.5,"tv":262.25,"id":24707172}]}]}
{"op":"mcm","clk":"993446077","pt":1580542523710,"mc":[{"id":"1.168130661","rc":[{"batb":[[0,15.5,2.26],[1,15,4],[2,14.5,3]],"ltp":17.5,"tv":262.25,"id":24707172}]}]}
{"op":"mcm","clk":"993447483","pt":1580542542203,"mc":[{"id":"1.168130661","rc":[{"trd":[[2.68,139.78]],"batb":[[0,2.66,27.52],[1,2.64,2],[2,2.6,26.76]],"batl":[[0,2.68,3],[1,2.7,16.96],[2,2.72,414]],"ltp":2.68,"tv":2336.47,"id":26314798}],"tv":5711.37}]}
{"op":"mcm","clk":"993447725","pt":1580542545714,"mc":[{"id":"1.168130661","rc":[{"batl":[[2,2.72,400]],"ltp":2.68,"tv":2336.47,"id":26314798}]}]}
{"op":"mcm","clk":"993447813","pt":1580542546912,"mc":[{"id":"1.168130661","rc":[{"batb":[[1,2.5,4.95],[2,2.48,122.01]],"ltp":2.74,"tv":2384.61,"id":25238892}]}]}
{"op":"mcm","clk":"993448667","pt":1580542558554,"mc":[{"id":"1.168130661","rc":[{"batb":[[0,2.58,3.13],[1,2.56,2.13],[2,2.5,4.95]],"ltp":2.74,"tv":2384.61,"id":25238892}]}]}
{"op":"mcm","clk":"993448958","pt":1580542562714,"mc":[{"id":"1.168130661","rc":[{"batl":[[1,2.86,1.68],[2,2.9,1.18]],"ltp":2.74,"tv":2384.61,"id":25238892},{"batl":[[1,20,1.05],[2,21,14.12]],"ltp":17.5,"tv":262.25,"id":24707172}]}]}
{"op":"mcm","clk":"993449973","pt":1580542577572,"mc":[{"id":"1.168130661","rc":[{"batb":[[0,2.6,2.09],[1,2.58,3.13]],"ltp":2.74,"tv":2384.61,"id":25238892}]}]}
{"op":"mcm","clk":"993450518","pt":1580542585349,"mc":[{"id":"1.168130661","rc":[{"batb":[[0,15.5,3.28]],"ltp":17.5,"tv":262.25,"id":24707172},{"batl":[[1,11,4]],"ltp":10.0,"tv":390.46,"id":24420205}]}]}
{"op":"mcm","clk":"993450568","pt":1580542586088,"mc":[{"id":"1.168130661","rc":[{"trd":[[2.66,95.65]],"batb":[[0,2.66,25.52]],"ltp":2.66,"tv":2340.47,"id":26314798}],"tv":5715.37}]}
{"op":"mcm","clk":"993450796","pt":1580542589440,"mc":[{"id":"1.168130661","rc":[{"batl":[[1,2.84,2.96],[2,2.86,1.68]],"ltp":2.74,"tv":2384.61,"id":25238892}]}]}
{"op":"mcm","clk":"993450942","pt":1580542591561,"mc":[{"id":"1.168130661","rc":[{"trd":[[2.68,143.74]],"batl":[[0,2.68,1.02]],"ltp":2.68,"tv":2344.43,"id":26314798}],"tv":5719.33}]}
{"op":"mcm","clk":"993451220","pt":1580542596455,"mc":[{"id":"1.168130661","rc":[{"trd":[[2.7,475.93]],"batl":[[0,2.7,16.11],[1,2.72,400],[2,2.74,79.55]],"ltp":2.7,"tv":2346.13,"id":26314798}],"tv":5721.02}]}
{"op":"mcm","clk":"993451630","pt":1580542602202,"mc":[{"id":"1.168130661","rc":[{"trd":[[2.7,478.17]],"batl":[[0,2.7,14.99]],"ltp":2.7,"tv":2348.37,"id":26314798}],"tv":5723.26}]}
{"op":"mcm","clk":"993452749","pt":1580542618612,"mc":[{"id":"1.168130661","rc":[{"batl":[[1,75,2],[2,150,2.95]],"ltp":50.0,"tv":74.59,"id":25545675}]}]}
{"op":"mcm","clk":"993453413","pt":1580542627632,"mc":[{"id":"1.168130661","rc":[{"batl":[[2,170,1.28]],"ltp":50.0,"tv":74.59,"id":25545675}]}]}
{"op":"mcm","clk":"993453551","pt":1580542629714,"mc":[{"id":"1.168130661","rc":[{"batl":[[0,2.7,19.99]],"ltp":2.7,"tv":2348.37,"id":26314798}]}]}
{"op":"mcm","clk":"993453900","pt":1580542634638,"mc":[{"id":"1.168130661","rc":[{"batl":[[0,60,8.55],[1,75,2.08]],"ltp":50.0,"tv":74.59,"id":25545675}]}]}
{"op":"mcm","clk":"993454964","pt":1580542648458,"mc":[{"id":"1.168130661","rc":[{"batb":[[2,2.6,28.76]],"ltp":2.7,"tv":2348.37,"id":26314798}]}]}
{"op":"mcm","clk":"993465289","pt":1580542655629,"mc":[{"id":"1.168130661","rc":[{"batl":[[1,75,2]],"ltp":50.0,"tv":74.59,"id":25545675}]}]}
{"op":"mcm","clk":"993465321","pt":1580542656151,"mc":[{"id":"1.168130661","rc":[{"batl":[[0,55,1.04],[1,60,7.6],[2,75,2]],"ltp":50.0,"tv":74.59,"id":25545675},{"batb":[[0,15.5,4.39]],"ltp":17.5,"tv":262.25,"id":24707172}]}]}
{"op":"mcm","clk":"993466207","pt":1580542668993,"mc":[{"id":"1.168130661","rc":[{"batb":[[1,2.5,4.95],[2,2.48,122.01]],"ltp":2.74,"tv":2384.61,"id":25238892}]}]}
{"op":"mcm","clk":"993466370","pt":1580542671673,"mc":[{"id":"1.168130661","rc":[{"batb":[[1,2.5,79.55]],"ltp":2.74,"tv":2384.61,"id":25238892}]}]}
{"op":"mcm","clk":"993466428","pt":1580542672605,"mc":[{"id":"1.168130661","rc":[{"batb":[[1,2.52,6],[2,2.5,79.55]],"ltp":2.74,"tv":2384.61,"id":25238892}]}]}
{"op":"mcm","clk":"993466602","pt":1580542675182,"mc":[{"id":"1.168130661","rc":[{"batl":[[1,2.86,1.68],[2,2.88,2.92]],"ltp":2.74,"tv":2384.61,"id":25238892}]}]}
{"op":"mcm","clk":"993466815","pt":1580542678696,"mc":[{"id":"1.168130661","rc":[{"batb":[[0,2.62,3.13],[1,2.6,2.09],[2,2.52,6]],"ltp":2.74,"tv":2384.61,"id":25238892}]}]}
{"op":"mcm","clk":"993467233","pt":1580542685704,"mc":[{"id":"1.168130661","rc":[{"batb":[[0,2.64,2.06],[1,2.62,3.13]],"ltp":2.74,"tv":2384.61,"id":25238892}]}]}
{"op":"mcm","clk":"993469524","pt":1580542727356,"mc":[{"id":"1.168130661","rc":[{"batl":[[1,2.84,2.96],[2,2.86,1.68]],"ltp":2.74,"tv":2384.61,"id":25238892}]}]}
{"op":"mcm","clk":"993470490","pt":1580542742493,"mc":[{"id":"1.168130661","rc":[{"batb":[[0,15.5,3.37]],"batl":[[1,21,14.37],[2,29,2.45]],"ltp":17.5,"tv":262.25,"id":24707172}]}]}
{"op":"mcm","clk":"993472093","pt":1580542770707,"mc":[{"id":"1.168130661","rc":[{"batb":[[2,9.2,5.9]],"ltp":10.0,"tv":390.46,"id":24420205}]}]}
{"op":"mcm","clk":"993473253","pt":1580542790243,"mc":[{"id":"1.168130661","rc":[{"batb":[[1,2.52,6],[2,2.5,79.55]],"ltp":2.74,"tv":2384.61,"id":25238892}]}]}
{"op":"mcm","clk":"993473412","pt":1580542793351,"mc":[{"id":"1.168130661","rc":[{"batb":[[1,30,2.13],[2,29,4.3]],"ltp":50.0,"tv":74.59,"id":25545675},{"batb":[[0,2.54,2.14]],"ltp":2.74,"tv":2384.61,"id":25238892},{"batb":[[1,9.4,12.78]],"ltp":10.0,"tv":390.46,"id":24420205},{"batb":[[2,2.62,10.12]],"ltp":2.7,"tv":2348.37,"id":26314798}]}]}
{"op":"mcm","clk":"993473585","pt":1580542796546,"mc":[{"id":"1.168130661","rc":[{"batb":[[1,30,4.71]],"ltp":50.0,"tv":74.59,"id":25545675}]}]}
{"op":"mcm","clk":"993473725","pt":1580542799341,"mc":[{"id":"1.168130661","rc":[{"batb":[[0,2.56,3.13],[1,2.54,2.14],[2,2.52,6]],"ltp":2.74,"tv":2384.61,"id":25238892},{"batb":[[0,16,5],[1,15.5,3.37],[2,15,4]],"ltp":17.5,"tv":262.25,"id":24707172}]}]}
{"op":"mcm","clk":"993474381","pt":1580542810077,"mc":[{"id":"1.168130661","rc":[{"batb":[[1,30,5.3]],"ltp":50.0,"tv":74.59,"id":25545675}]}]}
{"op":"mcm","clk":"993476680","pt":1580542847540,"mc":[{"id":"1.168130661","rc":[{"batb":[[0,2.58,2.11],[1,2.56,3.13]],"ltp":2.74,"tv":2384.61,"id":25238892},{"batb":[[0,16.5,2.12],[1,16,5],[2,15.5,1.11]],"ltp":17.5,"tv":262.25,"id":24707172}]}]}
{"op":"mcm","clk":"993477421","pt":1580542860588,"mc":[{"id":"1.168130661","rc":[{"batl":[[1,75,2],[2,150,2.95]],"ltp":50.0,"tv":74.59,"id":25545675}]}]}
{"op":"mcm","clk":"993477869","pt":1580542868676,"mc":[{"id":"1.168130661","rc":[{"batl":[[2,170,1.28]],"ltp":50.0,"tv":74.59,"id":25545675}]}]}
{"op":"mcm","clk":"993480054","pt":1580542910629,"mc":[{"id":"1.168130661","rc":[{"batb":[[1,2.52,6],[2,2.5,79.55]],"ltp":2.74,"tv":2384.61,"id":25238892},{"batl":[[0,18,2.54]],"ltp":17.5,"tv":262.25,"id":24707172}]}]}
{"op":"mcm","clk":"993480737","pt":1580542922617,"mc":[{"id":"1.168130661","rc":[{"batb":[[0,2.6,3.13],[1,2.58,2.11],[2,2.52,6]],"ltp":2.74,"tv":2384.61,"id":25238892}]}]}
{"op":"mcm","clk":"993482839","pt":1580542955599,"mc":[{"id":"1.168130661","rc":[{"batb":[[0,2.62,2.08],[1,2.6,3.13]],"ltp":2.74,"tv":2384.61,"id":25238892}]}]}
{"op":"mcm","clk":"993484795","pt":1580542984523,"mc":[{"id":"1.168130661","rc":[{"batb":[[0,16.5,3.16],[2,15,4]],"ltp":17.5,"tv":262.25,"id":24707172}]}]}
{"op":"mcm","clk":"993487505","pt":1580543032613,"mc":[{"id":"1.168130661","rc":[{"batb":[[1,2.52,6],[2,2.5,79.55]],"ltp":2.74,"tv":2384.61,"id":25238892}]}]}
{"op":"mcm","clk":"993487670","pt":1580543035402,"mc":[{"id":"1.168130661","rc":[{"batb":[[0,9.8,2],[1,9.6,12.27],[2,9.4,12.78]],"ltp":10.0,"tv":390.46,"id":24420205}]}]}
{"op":"mcm","clk":"993487996","pt":1580543040605,"mc":[{"id":"1.168130661","rc":[{"trd":[[10.5,32.99]],"batb":[[2,9.4,7.39]],"batl":[[0,11,4],[1,11.5,42.8],[2,12.5,9.41]],"ltp":10.5,"tv":398.46,"id":24420205}],"tv":5731.26}]}
{"op":"mcm","clk":"993488070","pt":1580543041645,"mc":[{"id":"1.168130661","rc":[{"batl":[[1,11.5,40]],"ltp":10.5,"tv":398.46,"id":24420205}]}]}
{"op":"mcm","clk":"993488287","pt":1580543045247,"mc":[{"id":"1.168130661","rc":[{"batb":[[0,2.64,3.13],[1,2.62,2.08],[2,2.52,6]],"ltp":2.74,"tv":2384.61,"id":25238892}]}]}
{"op":"mcm","clk":"993488494","pt":1580543049326,"mc":[{"id":"1.168130661","rc":[{"batb":[[0,9.8,6.29]],"ltp":10.5,"tv":398.46,"id":24420205}]}]}
{"op":"mcm","clk":"993489318","pt":1580543064348,"mc":[{"id":"1.168130661","rc":[{"batl":[[1,2.82,89.81],[2,2.84,2.96]],"ltp":2.74,"tv":2384.61,"id":25238892}]}]}
{"op":"mcm","clk":"993489381","pt":1580543065679,"mc":[{"id":"1.168130661","rc":[{"batl":[[1,2.8,8.3],[2,2.82,89.81]],"ltp":2.74,"tv":2384.61,"id":25238892}]}]}
{"op":"mcm","clk":"993489428","pt":1580543066453,"mc":[{"id":"1.168130661","rc":[{"batl":[[0,2.74,11.08],[1,2.76,1.18],[2,2.8,8.3]],"ltp":2.74,"tv":2384.61,"id":25238892}]}]}
{"op":"mcm","clk":"993489763","pt":1580543071647,"mc":[{"id":"1.168130661","rc":[{"batl":[[2,2.8,12.91]],"ltp":2.74,"tv":2384.61,"id":25238892},{"batb":[[1,9.6,14.81]],"ltp":10.5,"tv":398.46,"id":24420205}]}]}
{"op":"mcm","clk":"993490638","pt":1580543084439,"mc":[{"id":"1.168130661","rc":[{"batl":[[2,2.8,4.6]],"ltp":2.74,"tv":2384.61,"id":25238892}]}]}
{"op":"mcm","clk":"993491032","pt":1580543090998,"mc":[{"id":"1.168130661","rc":[{"batl":[[2,2.86,1.68]],"ltp":2.74,"tv":2384.61,"id":25238892}]}]}
{"op":"mcm","clk":"993494148","pt":1580543137659,"mc":[{"id":"1.168130661","rc":[{"batl":[[0,2.68,4],[1,2.7,19.99],[2,2.72,400]],"ltp":2.7,"tv":2348.37,"id":26314798}]}]}
{"op":"mcm","clk":"993494497","pt":1580543142597,"mc":[{"id":"1.168130661","rc":[{"batl":[[0,2.68,6]],"ltp":2.7,"tv":2348.37,"id":26314798}]}]}
{"op":"mcm","clk":"993494659","pt":1580543145264,"mc":[{"id":"1.168130661","rc":[{"batl":[[0,2.68,8]],"ltp":2.7,"tv":2348.37,"id":26314798}]}]}
{"op":"mcm","clk":"993495231","pt":1580543156133,"mc":[{"id":"1.168130661","rc":[{"batb":[[0,2.62,2.08],[1,2.54,2.5]],"ltp":2.74,"tv":2384.61,"id":25238892}]}]}
{"op":"mcm","clk":"993495840","pt":1580543165478,"mc":[{"id":"1.168130661","rc":[{"batb":[[0,2.64,3.13],[1,2.62,2.08],[2,2.54,2.5]],"ltp":2.74,"tv":2384.61,"id":25238892}]}]}
{"op":"mcm","clk":"993498090","pt":1580543196289,"mc":[{"id":"1.168130661","rc":[{"trd":[[2.68,159.74]],"batb":[[0,2.68,16.5],[1,2.66,25.52],[2,2.64,2]],"batl":[[0,2.7,19.99],[1,2.72,400],[2,2.74,79.55]],"ltp":2.68,"tv":2364.37,"id":26314798}],"tv":5747.26}]}
{"op":"mcm","clk":"993498262","pt":1580543198710,"mc":[{"id":"1.168130661","rc":[{"batb":[[1,2.66,30.66]],"ltp":2.68,"tv":2364.37,"id":26314798}]}]}
{"op":"mcm","clk":"993498389","pt":1580543200465,"mc":[{"id":"1.168130661","rc":[{"batb":[[1,2.66,32.66],[2,2.64,8]],"ltp":2.68,"tv":2364.37,"id":26314798}]}]}
{"op":"mcm","clk":"993500826","pt":1580543232356,"mc":[{"id":"1.168130661","rc":[{"batl":[[1,65,2],[2,75,2]],"ltp":50.0,"tv":74.59,"id":25545675}]}]}
{"op":"mcm","clk":"993501872","pt":1580543248651,"mc":[{"id":"1.168130661","rc":[{"trd":[[18,5.09]],"batl":[[0,21,14.37],[1,29,2.45],[2,48,5.08]],"ltp":18.0,"tv":267.34,"id":24707172}],"tv":5752.36}]}
{"op":"mcm","clk":"993502166","pt":1580543253486,"mc":[{"id":"1.168130661","rc":[{"batb":[[0,17,4],[1,16.5,3.16],[2,16,5]],"ltp":18.0,"tv":267.34,"id":24707172}]}]}
{"op":"mcm","clk":"993502712","pt":1580543258866,"mc":[{"id":"1.168130661","rc":[{"batl":[[2,60,9.08]],"ltp":18.0,"tv":267.34,"id":24707172}]}]}
{"op":"mcm","clk":"993503917","pt":1580543276091,"mc":[{"id":"1.168130661","rc":[{"batb":[[0,2.62,2.08],[1,2.54,7.06],[2,2.52,6]],"ltp":2.74,"tv":2384.61,"id":25238892}]}]}
{"op":"mcm","clk":"993504113","pt":1580543278721,"mc":[{"id":"1.168130661","rc":[{"batb":[[0,2.56,2.13],[1,2.52,6],[2,2.5,79.55]],"batl":[[0,2.76,1.18],[1,2.86,1.68],[2,2.88,29.21]],"ltp":2.74,"tv":2384.61,"id":25238892}]}]}
{"op":"mcm","clk":"993504192","pt":1580543279706,"mc":[{"id":"1.168130661","rc":[{"batl":[[2,2.9,4.08]],"ltp":2.74,"tv":2384.61,"id":25238892}]}]}
{"op":"mcm","clk":"993504604","pt":1580543285706,"mc":[{"id":"1.168130661","rc":[{"batb":[[0,2.58,3.13],[1,2.56,2.13],[2,2.52,6]],"ltp":2.74,"tv":2384.61,"id":25238892}]}]}
{"op":"mcm","clk":"993505083","pt":1580543291644,"mc":[{"id":"1.168130661","rc":[{"batl":[[1,2.84,2.96],[2,2.86,1.68]],"ltp":2.74,"tv":2384.61,"id":25238892}]}]}
{"op":"mcm","clk":"993506788","pt":1580543318571,"mc":[{"id":"1.168130661","rc":[{"batl":[[2,2.9,1.18]],"ltp":2.74,"tv":2384.61,"id":25238892}]}]}
{"op":"mcm","clk":"993506877","pt":1580543319649,"mc":[{"id":"1.168130661","rc":[{"batl":[[1,2.82,1.45],[2,2.84,2.96]],"ltp":2.74,"tv":2384.61,"id":25238892},{"batl":[[2,55,1.76]],"ltp":18.0,"tv":267.34,"id":24707172}]}]}
{"op":"mcm","clk":"993507379","pt":1580543327245,"mc":[{"id":"1.168130661","rc":[{"trd":[[2.56,4.26],[2.58,6.25]],"batb":[[0,2.52,6],[1,2.5,79.55],[2,2.48,122.01]],"batl":[[0,2.56,9.54],[1,2.58,27.27],[2,2.76,1.18]],"ltp":2.56,"tv":2395.12,"id":25238892}],"tv":5762.87}]}
{"op":"mcm","clk":"993507601","pt":1580543330690,"mc":[{"id":"1.168130661","rc":[{"trd":[[2.56,8.18]],"batl":[[0,2.56,7.58]],"ltp":2.56,"tv":2399.04,"id":25238892}],"tv":5766.79}]}
{"op":"mcm","clk":"993507663","pt":1580543331667,"mc":[{"id":"1.168130661","rc":[{"batb":[[0,32,7.48]],"ltp":50.0,"tv":74.59,"id":25545675},{"batb":[[0,17,15.17]],"ltp":18.0,"tv":267.34,"id":24707172}]}]}
{"op":"mcm","clk":"993507788","pt":1580543333625,"mc":[{"id":"1.168130661","rc":[{"trd":[[2.56,12.1]],"batl":[[0,2.56,5.62]],"ltp":2.56,"tv":2402.96,"id":25238892}],"tv":5770.71}]}
{"op":"mcm","clk":"993509160","pt":1580543353609,"mc":[{"id":"1.168130661","rc":[{"batb":[[1,30,8.92]],"ltp":50.0,"tv":74.59,"id":25545675}]}]}
{"op":"mcm","clk":"993510441","pt":1580543375216,"mc":[{"id":"1.168130661","rc":[{"batb":[[0,17,16.16],[1,16.5,2.12]],"ltp":18.0,"tv":267.34,"id":24707172}]}]}
{"op":"mcm","clk":"993510835","pt":1580543381686,"mc":[{"id":"1.168130661","rc":[{"trd":[[2.56,13.96]],"batl":[[0,2.56,4.69]],"ltp":2.56,"tv":2404.82,"id":25238892}],"tv":5772.57}]}
{"op":"mcm","clk":"993511202","pt":1580543387527,"mc":[{"id":"1.168130661","rc":[{"trd":[[2.56,15.82]],"batl":[[0,2.56,3.76]],"ltp":2.56,"tv":2406.68,"id":25238892}],"tv":5774.43}]}
{"op":"mcm","clk":"993511279","pt":1580543388723,"mc":[{"id":"1.168130661","rc":[{"batb":[[0,17.5,11.84],[1,17,4],[2,16.5,2.12]],"ltp":18.0,"tv":267.34,"id":24707172}]}]}
{"op":"mcm","clk":"993511561","pt":1580543392647,"mc":[{"id":"1.168130661","rc":[{"trd":[[2.56,16.68]],"batl":[[0,2.56,3.33]],"ltp":2.56,"tv":2407.54,"id":25238892}],"tv":5775.29}]}
{"op":"mcm","clk":"993511696","pt":1580543394660,"mc":[{"id":"1.168130661","rc":[{"trd":[[2.56,17.54]],"batl":[[0,2.56,2.9]],"ltp":2.56,"tv":2408.4,"id":25238892}],"tv":5776.15}]}
{"op":"mcm","clk":"993511806","pt":1580543396664,"mc":[{"id":"1.168130661","rc":[{"trd":[[2.56,17.96]],"batl":[[0,2.56,2.69]],"ltp":2.56,"tv":2408.82,"id":25238892}],"tv":5776.57}]}
{"op":"mcm","clk":"993511974","pt":1580543398976,"mc":[{"id":"1.168130661","rc":[{"trd":[[2.56,18.38]],"batl":[[0,2.56,2.48]],"ltp":2.56,"tv":2409.24,"id":25238892}],"tv":5776.99}]}
{"op":"mcm","clk":"993512599","pt":1580543407642,"mc":[{"id":"1.168130661","rc":[{"trd":[[2.56,18.58]],"batl":[[0,2.56,2.38]],"ltp":2.56,"tv":2409.44,"id":25238892},{"batb":[[0,17,4.98],[1,16.5,2.12],[2,16,5]],"ltp":18.0,"tv":267.34,"id":24707172}],"tv":5777.19}]}
{"op":"mcm","clk":"993512767","pt":1580543409705,"mc":[{"id":"1.168130661","rc":[{"trd":[[2.56,18.78]],"batl":[[0,2.56,2.28]],"ltp":2.56,"tv":2409.64,"id":25238892}],"tv":5777.39}]}
{"op":"mcm","clk":"993512877","pt":1580543411261,"mc":[{"id":"1.168130661","rc":[{"trd":[[2.56,18.98]],"batl":[[0,2.56,2.18]],"ltp":2.56,"tv":2409.84,"id":25238892}],"tv":5777.59}]}
{"op":"mcm","clk":"993512988","pt":1580543413074,"mc":[{"id":"1.168130661","rc":[{"trd":[[2.56,19.18]],"batl":[[0,2.56,2.08]],"ltp":2.56,"tv":2410.04,"id":25238892}],"tv":5777.79}]}
{"op":"mcm","clk":"993513097","pt":1580543414676,"mc":[{"id":"1.168130661","rc":[{"trd":[[2.56,19.38]],"batl":[[0,2.56,1.98]],"ltp":2.56,"tv":2410.24,"id":25238892}],"tv":5777.99}]}
{"op":"mcm","clk":"993513165","pt":1580543415564,"mc":[{"id":"1.168130661","rc":[{"trd":[[2.56,23.34],[2.58,6.29]],"batl":[[0,2.58,27.25],[1,2.76,1.18],[2,2.82,1.45]],"ltp":2.58,"tv":2414.24,"id":25238892}],"tv":5781.99}]}
{"op":"mcm","clk":"993514833","pt":1580543441496,"mc":[{"id":"1.168130661","rc":[{"trd":[[2.62,345.11],[2.64,211.63],[2.66,160.99],[2.68,192.74]],"batb":[[0,2.62,7.3],[1,2.6,28.42],[2,2.58,19.63]],"ltp":2.62,"tv":2484.34,"id":26314798}],"tv":5901.97}]}
{"op":"mcm","clk":"993514908","pt":1580543442628,"mc":[{"id":"1.168130661","rc":[{"batb":[[0,10,1.72],[1,9.8,6.29],[2,9.6,14.81]],"ltp":10.5,"tv":398.46,"id":24420205},{"batb":[[0,2.6,39.26],[1,2.58,19.63],[2,2.56,8.99]],"ltp":2.62,"tv":2484.34,"id":26314798}]}]}
{"op":"mcm","clk":"993515001","pt":1580543443714,"mc":[{"id":"1.168130661","rc":[{"batb":[[2,9.6,12.27]],"ltp":10.5,"tv":398.46,"id":24420205},{"batb":[[0,2.6,28.42],[1,2.58,32.78]],"ltp":2.62,"tv":2484.34,"id":26314798}]}]}
{"op":"mcm","clk":"993515198","pt":1580543446717,"mc":[{"id":"1.168130661","rc":[{"batb":[[0,17.5,11.84],[1,17,4],[2,16.5,2.12]],"ltp":18.0,"tv":267.34,"id":24707172}]}]}
{"op":"mcm","clk":"993515398","pt":1580543449720,"mc":[{"id":"1.168130661","rc":[{"batl":[[0,2.7,39.99]],"ltp":2.62,"tv":2484.34,"id":26314798}]}]}
{"op":"mcm","clk":"993516047","pt":1580543458716,"mc":[{"id":"1.168130661","rc":[{"trd":[[11,23.73]],"batl":[[0,11.5,40.64],[1,12.5,9.41],[2,14,2.52]],"ltp":11.0,"tv":405.18,"id":24420205}],"tv":5908.69}]}
{"op":"mcm","clk":"993516098","pt":1580543459540,"mc":[{"id":"1.168130661","rc":[{"trd":[[11,25.01]],"batl":[[0,11.5,40]],"ltp":11.0,"tv":406.46,"id":24420205}],"tv":5909.97}]}
{"op":"mcm","clk":"993516801","pt":1580543468330,"mc":[{"id":"1.168130661","rc":[{"batl":[[1,12,3],[2,12.5,9.41]],"ltp":11.0,"tv":406.46,"id":24420205}]}]}
{"op":"mcm","clk":"993516967","pt":1580543470549,"mc":[{"id":"1.168130661","rc":[{"batb":[[2,2.54,15]],"batl":[[0,2.68,4],[1,2.7,39.99],[2,2.72,400]],"ltp":2.62,"tv":2484.34,"id":26314798}]}]}
{"op":"mcm","clk":"993517075","pt":1580543472152,"mc":[{"id":"1.168130661","rc":[{"batb":[[0,10,3.31]],"ltp":11.0,"tv":406.46,"id":24420205}]}]}
{"op":"mcm","clk":"993518120","pt":1580543488172,"mc":[{"id":"1.168130661","rc":[{"trd":[[32,15.94],[34,4.67]],"batb":[[0,32,3.48]],"ltp":32.0,"tv":82.6,"id":25545675}],"tv":5917.97}]}
{"op":"mcm","clk":"993518322","pt":1580543491050,"mc":[{"id":"1.168130661","rc":[{"batl":[[0,2.68,9],[1,2.7,34.99]],"ltp":2.62,"tv":2484.34,"id":26314798}]}]}
{"op":"mcm","clk":"993518471","pt":1580543493466,"mc":[{"id":"1.168130661","rc":[{"batl":[[0,2.68,5]],"ltp":2.62,"tv":2484.34,"id":26314798}]}]}
{"op":"mcm","clk":"993519054","pt":1580543502685,"mc":[{"id":"1.168130661","rc":[{"batl":[[1,65,2.61]],"ltp":32.0,"tv":82.6,"id":25545675}]}]}
{"op":"mcm","clk":"993519461","pt":1580543508661,"mc":[{"id":"1.168130661","rc":[{"trd":[[2.58,9.65]],"batl":[[0,2.58,25.57]],"ltp":2.58,"tv":2417.6,"id":25238892}],"tv":5921.33}]}
{"op":"mcm","clk":"993519701","pt":1580543511874,"mc":[{"id":"1.168130661","rc":[{"batb":[[1,30,5.3]],"ltp":32.0,"tv":82.6,"id":25545675}]}]}
{"op":"mcm","clk":"993520778","pt":1580543527685,"mc":[{"id":"1.168130661","rc":[{"trd":[[2.5,62.62],[2.52,73.36]],"batb":[[0,2.5,70.33],[1,2.48,125.99],[2,2.42,4.8]],"ltp":2.5,"tv":2448.01,"id":25238892},{"trd":[[2.6,182.61]],"batb":[[0,2.6,13.21]],"ltp":2.6,"tv":2514.75,"id":26314798}],"tv":5982.15}]}
{"op":"mcm","clk":"993521198","pt":1580543532694,"mc":[{"id":"1.168130661","rc":[{"batl":[[0,2.56,6],[1,2.58,25.57],[2,2.76,1.18]],"ltp":2.5,"tv":2448.01,"id":25238892},{"batl":[[0,20,8.25],[1,21,14.12],[2,29,2.45]],"ltp":18.0,"tv":267.34,"id":24707172}]}]}
{"op":"mcm","clk":"993521268","pt":1580543533676,"mc":[{"id":"1.168130661","rc":[{"batb":[[0,2.5,74.6]],"ltp":2.5,"tv":2448.01,"id":25238892}]}]}
{"op":"mcm","clk":"993521529","pt":1580543537593,"mc":[{"id":"1.168130661","rc":[{"batb":[[0,2.5,82.6]],"ltp":2.5,"tv":2448.01,"id":25238892}]}]}
{"op":"mcm","clk":"993521812","pt":1580543541605,"mc":[{"id":"1.168130661","rc":[{"batb":[[1,2.48,136.16]],"ltp":2.5,"tv":2448.01,"id":25238892},{"batb":[[0,17,4.98],[1,16.5,9.58],[2,16,5]],"ltp":18.0,"tv":267.34,"id":24707172},{"batb":[[1,2.58,24.24]],"ltp":2.6,"tv":2514.75,"id":26314798}]}]}
{"op":"mcm","clk":"993522162","pt":1580543547405,"mc":[{"id":"1.168130661","rc":[{"batb":[[0,17,7.04],[1,16.5,7.46]],"ltp":18.0,"tv":267.34,"id":24707172}]}]}
{"op":"mcm","clk":"993522284","pt":1580543548699,"mc":[{"id":"1.168130661","rc":[{"batb":[[1,16,5],[2,15,6.06]],"ltp":18.0,"tv":267.34,"id":24707172}]}]}
{"op":"mcm","clk":"993532985","pt":1580543560326,"mc":[{"id":"1.168130661","rc":[{"batl":[[1,2.76,1.18],[2,2.82,1.45]],"ltp":2.5,"tv":2448.01,"id":25238892}]}]}
{"op":"mcm","clk":"993533513","pt":1580543567551,"mc":[{"id":"1.168130661","rc":[{"batl":[[0,2.74,6],[2,2.82,12.64]],"ltp":2.5,"tv":2448.01,"id":25238892},{"batb":[[1,16,9.3]],"ltp":18.0,"tv":267.34,"id":24707172}]}]}
{"op":"mcm","clk":"993533542","pt":1580543567962,"mc":[{"id":"1.168130661","rc":[{"trd":[[2.5,113.78]],"batb":[[0,2.5,57.01]],"ltp":2.5,"tv":2499.17,"id":25238892}],"tv":6033.31}]}
{"op":"mcm","clk":"993533683","pt":1580543569605,"mc":[{"id":"1.168130661","rc":[{"batl":[[2,2.82,1.45]],"ltp":2.5,"tv":2499.17,"id":25238892}]}]}
{"op":"mcm","clk":"993533762","pt":1580543570640,"mc":[{"id":"1.168130661","rc":[{"batl":[[0,2.74,8]],"ltp":2.5,"tv":2499.17,"id":25238892}]}]}
{"op":"mcm","clk":"993533917","pt":1580543572956,"mc":[{"id":"1.168130661","rc":[{"batb":[[0,2.5,82.6]],"ltp":2.5,"tv":2499.17,"id":25238892}]}]}
{"op":"mcm","clk":"993534367","pt":1580543579441,"mc":[{"id":"1.168130661","rc":[{"batb":[[0,30,5.3],[1,29,4.3],[2,27,8.23]],"ltp":32.0,"tv":82.6,"id":25545675}]}]}
{"op":"mcm","clk":"993534463","pt":1580543580680,"mc":[{"id":"1.168130661","rc":[{"batb":[[0,29,4.89],[1,27,8.23],[2,26,2.09]],"batl":[[0,50,1.14],[1,65,2.7]],"ltp":32.0,"tv":82.6,"id":25545675},{"batl":[[2,2.82,5.16]],"ltp":2.5,"tv":2499.17,"id":25238892}]}]}
{"op":"mcm","clk":"993534773","pt":1580543585176,"mc":[{"id":"1.168130661","rc":[{"batl":[[0,2.72,5.85],[1,2.74,8],[2,2.76,1.18]],"ltp":2.5,"tv":2499.17,"id":25238892}]}]}
{"op":"mcm","clk":"993534881","pt":1580543586878,"mc":[{"id":"1.168130661","rc":[{"batb":[[0,29,4.3]],"ltp":32.0,"tv":82.6,"id":25545675}]}]}
{"op":"mcm","clk":"993535461","pt":1580543595660,"mc":[{"id":"1.168130661","rc":[{"batb":[[1,27,8.86]],"ltp":32.0,"tv":82.6,"id":25545675},{"batl":[[0,2.7,6],[1,2.72,5.85],[2,2.74,2]],"ltp":2.5,"tv":2499.17,"id":25238892}]}]}
{"op":"mcm","clk":"993535865","pt":1580543601315,"mc":[{"id":"1.168130661","rc":[{"batl":[[0,2.68,2],[1,2.7,6],[2,2.72,5.85]],"ltp":2.5,"tv":2499.17,"id":25238892}]}]}
{"op":"mcm","clk":"993536391","pt":1580543608722,"mc":[{"id":"1.168130661","rc":[{"batl":[[0,2.66,6],[1,2.68,2]],"ltp":2.5,"tv":2499.17,"id":25238892}]}]}
{"op":"mcm","clk":"993536503","pt":1580543610215,"mc":[{"id":"1.168130661","rc":[{"batb":[[1,27,12.07]],"ltp":32.0,"tv":82.6,"id":25545675}]}]}
{"op":"mcm","clk":"993537061","pt":1580543618393,"mc":[{"id":"1.168130661","rc":[{"batb":[[0,29,8.14]],"ltp":32.0,"tv":82.6,"id":25545675}]}]}
{"op":"mcm","clk":"993537138","pt":1580543619676,"mc":[{"id":"1.168130661","rc":[{"batb":[[0,17.5,3.98],[1,17,6.06],[2,16,9.3]],"ltp":18.0,"tv":267.34,"id":24707172}]}]}
{"op":"mcm","clk":"993539088","pt":1580543643687,"mc":[{"id":"1.168130661","rc":[{"batl":[[0,48,7.79],[1,60,1.56],[2,65,2]],"ltp":32.0,"tv":82.6,"id":25545675}]}]}
{"op":"mcm","clk":"993539115","pt":1580543644043,"mc":[{"id":"1.168130661","rc":[{"batl":[[0,48,7.9]],"ltp":32.0,"tv":82.6,"id":25545675}]}]}
{"op":"mcm","clk":"993539310","pt":1580543646517,"mc":[{"id":"1.168130661","rc":[{"batb":[[1,27,14.6]],"ltp":32.0,"tv":82.6,"id":25545675}]}]}
{"op":"mcm","clk":"993539670","pt":1580543651415,"mc":[{"id":"1.168130661","rc":[{"batl":[[0,48,8.25]],"ltp":32.0,"tv":82.6,"id":25545675}]}]}
{"op":"mcm","clk":"993539992","pt":1580543655646,"mc":[{"id":"1.168130661","rc":[{"batl":[[0,46,1.26],[1,48,7.79],[2,65,2.95]],"ltp":32.0,"tv":82.6,"id":25545675},{"batl":[[0,2.7,2],[1,2.72,5.85],[2,2.74,2]],"ltp":2.5,"tv":2499.17,"id":25238892}]}]}
{"op":"mcm","clk":"993540072","pt":1580543656678,"mc":[{"id":"1.168130661","rc":[{"batl":[[2,65,8.86]],"ltp":32.0,"tv":82.6,"id":25545675},{"batl":[[0,2.68,6],[1,2.7,2],[2,2.72,5.85]],"ltp":2.5,"tv":2499.17,"id":25238892}]}]}
{"op":"mcm","clk":"993541191","pt":1580543672083,"mc":[{"id":"1.168130661","rc":[{"batb":[[0,2.52,26.89],[1,2.5,82.6],[2,2.48,136.16]],"ltp":2.5,"tv":2499.17,"id":25238892},{"batb":[[0,2.62,4.2],[1,2.6,13.21],[2,2.58,24.24]],"ltp":2.6,"tv":2514.75,"id":26314798}]}]}
{"op":"mcm","clk":"993541453","pt":1580543675446,"mc":[{"id":"1.168130661","rc":[{"batb":[[0,29,4.3]],"ltp":32.0,"tv":82.6,"id":25545675}]}]}
{"op":"mcm","clk":"993541715","pt":1580543678651,"mc":[{"id":"1.168130661","rc":[{"batl":[[0,2.66,2],[1,2.68,5],[2,2.7,34.99]],"ltp":2.6,"tv":2514.75,"id":26314798}]}]}
{"op":"mcm","clk":"993542012","pt":1580543682476,"mc":[{"id":"1.168130661","rc":[{"batl":[[2,65,11.81]],"ltp":32.0,"tv":82.6,"id":25545675},{"batb":[[1,2.5,91.74],[2,2.48,125.99]],"ltp":2.5,"tv":2499.17,"id":25238892},{"batb":[[0,2.64,11.22],[1,2.62,4.2],[2,2.6,13.21]],"batl":[[2,2.7,14.99]],"ltp":2.6,"tv":2514.75,"id":26314798}]}]}
{"op":"mcm","clk":"993542096","pt":1580543683661,"mc":[{"id":"1.168130661","rc":[{"batb":[[1,2.62,8.15]],"ltp":2.6,"tv":2514.75,"id":26314798}]}]}
{"op":"mcm","clk":"993543187","pt":1580543696261,"mc":[{"id":"1.168130661","rc":[{"batb":[[0,10,1.72]],"ltp":11.0,"tv":406.46,"id":24420205}]}]}
{"op":"mcm","clk":"993544971","pt":1580543718718,"mc":[{"id":"1.168130661","rc":[{"batl":[[0,48,8.7],[1,65,11.81],[2,75,2]],"ltp":32.0,"tv":82.6,"id":25545675}]}]}
{"op":"mcm","clk":"993546757","pt":1580543740600,"mc":[{"id":"1.168130661","rc":[{"batl":[[0,19.5,1.68],[1,20,8.25],[2,21,14.12]],"ltp":18.0,"tv":267.34,"id":24707172}]}]}
{"op":"mcm","clk":"993551179","pt":1580543796051,"mc":[{"id":"1.168130661","rc":[{"batb":[[0,29,4.87]],"ltp":32.0,"tv":82.6,"id":25545675}]}]}
{"op":"mcm","clk":"993551664","pt":1580543802314,"mc":[{"id":"1.168130661","rc":[{"trd":[[13.5,4.16]],"batb":[[0,13.5,4.2]],"ltp":13.5,"tv":263.12,"id":420}],"tv":6033.47}]}
{"op":"mcm","clk":"993552152","pt":1580543808614,"mc":[{"id":"1.168130661","rc":[{"batl":[[2,2.76,1.18]],"ltp":2.5,"tv":2499.17,"id":25238892}]}]}
{"op":"mcm","clk":"993552655","pt":1580543814221,"mc":[{"id":"1.168130661","rc":[{"batb":[[2,26,4.09]],"ltp":32.0,"tv":82.6,"id":25545675},{"batb":[[0,10,6.16]],"ltp":11.0,"tv":406.46,"id":24420205}]}]}
{"op":"mcm","clk":"993553063","pt":1580543819325,"mc":[{"id":"1.168130661","rc":[{"batb":[[0,10,9.52]],"ltp":11.0,"tv":406.46,"id":24420205}]}]}
{"op":"mcm","clk":"993553511","pt":1580543824365,"mc":[{"id":"1.168130661","rc":[{"batb":[[1,9.8,9.96]],"ltp":11.0,"tv":406.46,"id":24420205},{"trd":[[2.6,183.87],[2.62,361.41],[2.64,234.07]],"batb":[[0,2.62,3.95],[1,2.6,12.58],[2,2.58,28.14]],"ltp":2.6,"tv":2554.75,"id":26314798}],"tv":6073.47}]}
{"op":"mcm","clk":"993553921","pt":1580543829659,"mc":[{"id":"1.168130661","rc":[{"batb":[[0,2.6,12.58],[1,2.58,19.63],[2,2.54,15]],"ltp":2.6,"tv":2554.75,"id":26314798},{"trd":[[11,30.36],[11.5,8.86],[12,9.06],[13,7.8],[13.5,12.55]],"batb":[[0,10.5,3.28],[1,10,14.21],[2,9.8,69.01]],"batl":[[0,11,3.76],[1,16,2],[2,16.5,3]],"ltp":11.0,"tv":319.59,"id":420}],"tv":6129.94}]}
{"op":"mcm","clk":"993553993","pt":1580543830691,"mc":[{"id":"1.168130661","rc":[{"batb":[[2,9.8,43.01]],"ltp":11.0,"tv":319.59,"id":420}]}]}
{"op":"mcm","clk":"993554070","pt":1580543831669,"mc":[{"id":"1.168130661","rc":[{"batb":[[1,2.58,24.33]],"ltp":2.6,"tv":2554.75,"id":26314798},{"batb":[[0,10.5,4.79],[2,9.8,36]],"ltp":11.0,"tv":319.59,"id":420}]}]}
{"op":"mcm","clk":"993554226","pt":1580543833664,"mc":[{"id":"1.168130661","rc":[{"batb":[[2,2.52,15]],"ltp":2.6,"tv":2554.75,"id":26314798},{"batb":[[1,10,5.58]],"ltp":11.0,"tv":319.59,"id":420}]}]}
{"op":"mcm","clk":"993554311","pt":1580543834690,"mc":[{"id":"1.168130661","rc":[{"batb":[[1,9.8,5.67]],"ltp":11.0,"tv":406.46,"id":24420205},{"batb":[[0,10.5,8.79]],"ltp":11.0,"tv":319.59,"id":420}]}]}
{"op":"mcm","clk":"993554383","pt":1580543835582,"mc":[{"id":"1.168130661","rc":[{"batb":[[0,10,13.72]],"ltp":11.0,"tv":406.46,"id":24420205},{"batb":[[0,10.5,13]],"ltp":11.0,"tv":319.59,"id":420}]}]}
{"op":"mcm","clk":"993554459","pt":1580543836712,"mc":[{"id":"1.168130661","rc":[{"batb":[[2,2.52,20]],"ltp":2.6,"tv":2554.75,"id":26314798}]}]}
{"op":"mcm","clk":"993554758","pt":1580543840675,"mc":[{"id":"1.168130661","rc":[{"batl":[[1,2.76,1.18],[2,2.78,2]],"ltp":2.5,"tv":2499.17,"id":25238892}]}]}
{"op":"mcm","clk":"993554825","pt":1580543841509,"mc":[{"id":"1.168130661","rc":[{"batl":[[0,2.74,6]],"ltp":2.5,"tv":2499.17,"id":25238892}]}]}
{"op":"mcm","clk":"993554958","pt":1580543843300,"mc":[{"id":"1.168130661","rc":[{"batl":[[1,2.76,3.47]],"ltp":2.5,"tv":2499.17,"id":25238892}]}]}
{"op":"mcm","clk":"993555066","pt":1580543844686,"mc":[{"id":"1.168130661","rc":[{"batb":[[0,2.54,1.98],[1,2.52,26.89],[2,2.5,91.74]],"ltp":2.5,"tv":2499.17,"id":25238892},{"batb":[[0,18,1.98],[1,17.5,3.98],[2,17,6.06]],"ltp":18.0,"tv":267.34,"id":24707172},{"batb":[[0,10.5,1.98],[1,10,13.72],[2,9.8,5.67]],"ltp":11.0,"tv":406.46,"id":24420205},{"batb":[[0,2.6,28.29]],"ltp":2.6,"tv":2554.75,"id":26314798}]}]}
{"op":"mcm","clk":"993555111","pt":1580543845503,"mc":[{"id":"1.168130661","rc":[{"batb":[[2,9.8,9.64]],"ltp":11.0,"tv":406.46,"id":24420205}]}]}
{"op":"mcm","clk":"993555339","pt":1580543848629,"mc":[{"id":"1.168130661","rc":[{"batb":[[0,30,4.28],[1,29,4.3],[2,27,14.6]],"ltp":32.0,"tv":82.6,"id":25545675},{"batb":[[2,2.5,82.6]],"ltp":2.5,"tv":2499.17,"id":25238892},{"batb":[[0,18,12.54]],"ltp":18.0,"tv":267.34,"id":24707172},{"batb":[[2,9.8,2]],"ltp":11.0,"tv":406.46,"id":24420205},{"batb":[[0,2.62,65.09],[1,2.6,28.29],[2,2.58,24.33]],"ltp":2.6,"tv":2554.75,"id":26314798},{"trd":[[11,37.88]],"batb":[[0,11,8.29],[1,10.5,13],[2,10,5.58]],"batl":[[0,16,6.47],[1,16.5,3],[2,18,3.52]],"ltp":11.0,"tv":327.11,"id":420}],"tv":6137.45}]}
{"op":"mcm","clk":"993555726","pt":1580543853615,"mc":[{"id":"1.168130661","rc":[{"batb":[[1,10.5,11.48]],"batl":[[0,15.5,1.02],[1,16,6.47],[2,16.5,3]],"ltp":11.0,"tv":327.11,"id":420}]}]}
{"op":"mcm","clk":"993556260","pt":1580543860716,"mc":[{"id":"1.168130661","rc":[{"batl":[[0,15.5,1.34]],"ltp":11.0,"tv":327.11,"id":420}]}]}
{"op":"mcm","clk":"993556565","pt":1580543864632,"mc":[{"id":"1.168130661","rc":[{"batl":[[0,15.5,3.74]],"ltp":11.0,"tv":327.11,"id":420}]}]}
{"op":"mcm","clk":"993556888","pt":1580543868682,"mc":[{"id":"1.168130661","rc":[{"batb":[[0,18,1.98],[2,17,13.83]],"ltp":18.0,"tv":267.34,"id":24707172},{"batb":[[0,2.6,42.33],[1,2.58,26.5],[2,2.52,20]],"ltp":2.6,"tv":2554.75,"id":26314798},{"batl":[[1,16,2]],"ltp":11.0,"tv":327.11,"id":420}]}]}
{"op":"mcm","clk":"993556971","pt":1580543869554,"mc":[{"id":"1.168130661","rc":[{"batl":[[0,48,1.1]],"ltp":32.0,"tv":82.6,"id":25545675}]}]}
{"op":"mcm","clk":"993557028","pt":1580543870272,"mc":[{"id":"1.168130661","rc":[{"batb":[[2,17,6.06]],"ltp":18.0,"tv":267.34,"id":24707172},{"batb":[[0,2.6,28.29],[1,2.58,33.69]],"ltp":2.6,"tv":2554.75,"id":26314798}]}]}
{"op":"mcm","clk":"993557267","pt":1580543873360,"mc":[{"id":"1.168130661","rc":[{"batl":[[1,65,2.95]],"ltp":32.0,"tv":82.6,"id":25545675}]}]}
{"op":"mcm","clk":"993557389","pt":1580543874854,"mc":[{"id":"1.168130661","rc":[{"trd":[[2.6,187.87]],"batb":[[0,2.6,26.29]],"ltp":2.6,"tv":2558.76,"id":26314798}],"tv":6141.46}]}
{"op":"mcm","clk":"993557536","pt":1580543876658,"mc":[{"id":"1.168130661","rc":[{"batl":[[0,20,8.25],[1,21,14.12],[2,29,2.45]],"ltp":18.0,"tv":267.34,"id":24707172},{"batb":[[0,11.5,3.65],[1,11,8.29],[2,10.5,11.48]],"ltp":11.0,"tv":327.11,"id":420}]}]}
{"op":"mcm","clk":"993557939","pt":1580543881564,"mc":[{"id":"1.168130661","rc":[{"trd":[[11.5,86]],"batb":[[0,11,6.25],[1,10.5,1.98],[2,10,13.72]],"batl":[[0,12,3],[1,12.5,9.41],[2,14,2.52]],"ltp":11.5,"tv":486.46,"id":24420205},{"batb":[[0,11.5,7.65],[2,10.5,7.48]],"ltp":11.0,"tv":327.11,"id":420}],"tv":6221.46}]}
{"op":"mcm","clk":"993558007","pt":1580543882382,"mc":[{"id":"1.168130661","rc":[{"batl":[[1,12.5,14.44]],"ltp":11.5,"tv":486.46,"id":24420205}]}]}
{"op":"mcm","clk":"993558127","pt":1580543883468,"mc":[{"id":"1.168130661","rc":[{"batl":[[0,50,1.25],[1,65,2]],"ltp":32.0,"tv":82.6,"id":25545675},{"batb":[[2,10,19.03]],"batl":[[1,12.5,9.41]],"ltp":11.5,"tv":486.46,"id":24420205}]}]}
{"op":"mcm","clk":"993558160","pt":1580543883777,"mc":[{"id":"1.168130661","rc":[{"batl":[[1,65,2.61]],"ltp":32.0,"tv":82.6,"id":25545675}]}]}
{"op":"mcm","clk":"993558501","pt":1580543887384,"mc":[{"id":"1.168130661","rc":[{"batb":[[0,29,4.87],[1,27,14.6],[2,26,4.09]],"ltp":32.0,"tv":82.6,"id":25545675},{"batb":[[1,10.5,7.48],[2,10,14.21]],"ltp":11.0,"tv":327.11,"id":420}]}]}
{"op":"mcm","clk":"993558728","pt":1580543889602,"mc":[{"id":"1.168130661","rc":[{"batb":[[1,10.5,13.85]],"ltp":11.0,"tv":327.11,"id":420}]}]}
{"op":"mcm","clk":"993559811","pt":1580543902539,"mc":[{"id":"1.168130661","rc":[{"batl":[[2,2.82,3.71]],"ltp":2.5,"tv":2499.17,"id":25238892},{"batl":[[1,16.5,3],[2,18.5,2.31]],"ltp":11.0,"tv":327.11,"id":420}]}]}
{"op":"mcm","clk":"993561417","pt":1580543920152,"mc":[{"id":"1.168130661","rc":[{"batb":[[0,11.5,3.65]],"ltp":11.0,"tv":327.11,"id":420}]}]}
{"op":"mcm","clk":"993563138","pt":1580543938565,"mc":[{"id":"1.168130661","rc":[{"batb":[[1,11,3],[2,10.5,13.85]],"ltp":11.0,"tv":327.11,"id":420}]}]}
{"op":"mcm","clk":"993564451","pt":1580543951429,"mc":[{"id":"1.168130661","rc":[{"batl":[[0,48,7.9],[1,60,1.56],[2,65,2]],"ltp":32.0,"tv":82.6,"id":25545675}]}]}
{"op":"mcm","clk":"993564841","pt":1580543955699,"mc":[{"id":"1.168130661","rc":[{"batl":[[0,13,2],[1,15.5,3.74],[2,16.5,3]],"ltp":11.0,"tv":327.11,"id":420}]}]}
{"op":"mcm","clk":"993564903","pt":1580543956314,"mc":[{"id":"1.168130661","rc":[{"trd":[[13,11.8]],"batl":[[0,15.5,3.74],[1,16.5,3],[2,18.5,2.31]],"ltp":13.0,"tv":331.11,"id":420}],"tv":6225.46}]}
{"op":"mcm","clk":"993565305","pt":1580543960644,"mc":[{"id":"1.168130661","rc":[{"batl":[[0,48,8.7],[1,65,2.95],[2,75,2]],"ltp":32.0,"tv":82.6,"id":25545675}]}]}
{"op":"mcm","clk":"993569201","pt":1580544006633,"mc":[{"id":"1.168130661","rc":[{"batb":[[2,10,17.31]],"ltp":11.5,"tv":486.46,"id":24420205},{"batb":[[0,2.62,6.57],[1,2.6,26.29],[2,2.58,33.69]],"ltp":2.6,"tv":2558.76,"id":26314798}]}]}
{"op":"mcm","clk":"993569286","pt":1580544007712,"mc":[{"id":"1.168130661","rc":[{"batb":[[0,11.5,1.5],[1,11,6.25],[2,10.5,1.98]],"ltp":11.5,"tv":486.46,"id":24420205}]}]}
{"op":"mcm","clk":"993570040","pt":1580544017625,"mc":[{"id":"1.168130661","rc":[{"trd":[[12,9.04]],"batl":[[0,12.5,9.89],[1,14,2.52],[2,15,2]],"ltp":12.0,"tv":491.5,"id":24420205}],"tv":6230.5}]}
{"op":"mcm","clk":"993570128","pt":1580544018646,"mc":[{"id":"1.168130661","rc":[{"trd":[[12,10]],"batl":[[0,12.5,9.41]],"ltp":12.0,"tv":492.46,"id":24420205},{"batb":[[2,2.58,24.33]],"ltp":2.6,"tv":2558.76,"id":26314798}],"tv":6231.46}]}
{"op":"mcm","clk":"993571377","pt":1580544035546,"mc":[{"id":"1.168130661","rc":[{"batl":[[1,13.5,6],[2,14,2.52]],"ltp":12.0,"tv":492.46,"id":24420205}]}]}
{"op":"mcm","clk":"993573385","pt":1580544059606,"mc":[{"id":"1.168130661","rc":[{"batb":[[0,30,3.57],[1,29,4.3],[2,27,14.6]],"ltp":32.0,"tv":82.6,"id":25545675}]}]}
{"op":"mcm","clk":"993581548","pt":1580544148692,"mc":[{"id":"1.168130661","rc":[{"batb":[[0,12,1.44],[1,11.5,3.65],[2,11,3]],"ltp":13.0,"tv":331.11,"id":420}]}]}
{"op":"mcm","clk":"993583487","pt":1580544168627,"mc":[{"id":"1.168130661","rc":[{"batb":[[1,2.5,82.6],[2,2.48,122.01]],"ltp":2.5,"tv":2499.17,"id":25238892}]}]}
{"op":"mcm","clk":"993583571","pt":1580544169615,"mc":[{"id":"1.168130661","rc":[{"batb":[[1,2.52,6],[2,2.5,82.6]],"ltp":2.5,"tv":2499.17,"id":25238892}]}]}
{"op":"mcm","clk":"993584146","pt":1580544176678,"mc":[{"id":"1.168130661","rc":[{"batl":[[0,48,1.1]],"ltp":32.0,"tv":82.6,"id":25545675}]}]}
{"op":"mcm","clk":"993585084","pt":1580544189676,"mc":[{"id":"1.168130661","rc":[{"batl":[[0,15.5,2.71]],"ltp":13.0,"tv":331.11,"id":420}]}]}
{"op":"mcm","clk":"993585432","pt":1580544194687,"mc":[{"id":"1.168130661","rc":[{"batl":[[0,50,1.25],[1,65,2]],"ltp":32.0,"tv":82.6,"id":25545675}]}]}
{"op":"mcm","clk":"993585512","pt":1580544195674,"mc":[{"id":"1.168130661","rc":[{"batl":[[1,65,2.61]],"ltp":32.0,"tv":82.6,"id":25545675}]}]}
{"op":"mcm","clk":"993588402","pt":1580544238637,"mc":[{"id":"1.168130661","rc":[{"batl":[[0,2.68,5],[1,2.7,14.99],[2,2.72,400]],"ltp":2.6,"tv":2558.76,"id":26314798}]}]}
{"op":"mcm","clk":"993588485","pt":1580544239666,"mc":[{"id":"1.168130661","rc":[{"batl":[[1,2.7,25.96]],"ltp":2.6,"tv":2558.76,"id":26314798}]}]}
{"op":"mcm","clk":"993588657","pt":1580544242345,"mc":[{"id":"1.168130661","rc":[{"batb":[[2,11,5]],"ltp":13.0,"tv":331.11,"id":420}]}]}
{"op":"mcm","clk":"993588705","pt":1580544242961,"mc":[{"id":"1.168130661","rc":[{"batl":[[0,2.66,2],[1,2.68,5],[2,2.7,25.96]],"ltp":2.6,"tv":2558.76,"id":26314798}]}]}
{"op":"mcm","clk":"993589013","pt":1580544247337,"mc":[{"id":"1.168130661","rc":[{"batb":[[2,2.5,84.6]],"batl":[[0,2.72,2.01],[1,2.74,6],[2,2.76,3.47]],"ltp":2.5,"tv":2499.17,"id":25238892},{"batb":[[1,11,8.25]],"ltp":12.0,"tv":492.46,"id":24420205},{"batb":[[1,2.6,28.29]],"batl":[[1,2.68,7]],"ltp":2.6,"tv":2558.76,"id":26314798},{"batb":[[0,12,3.45]],"ltp":13.0,"tv":331.11,"id":420}]}]}
{"op":"mcm","clk":"993589318","pt":1580544252680,"mc":[{"id":"1.168130661","rc":[{"batl":[[0,2.7,6],[1,2.72,2.01],[2,2.74,2.06]],"ltp":2.5,"tv":2499.17,"id":25238892}]}]}
{"op":"mcm","clk":"993589388","pt":1580544253655,"mc":[{"id":"1.168130661","rc":[{"batl":[[1,2.74,2.06],[2,2.76,3.47]],"ltp":2.5,"tv":2499.17,"id":25238892}]}]}
{"op":"mcm","clk":"993590288","pt":1580544267193,"mc":[{"id":"1.168130661","rc":[{"batl":[[0,2.7,2.14],[1,2.72,6],[2,2.74,2.06]],"ltp":2.5,"tv":2499.17,"id":25238892}]}]}
{"op":"mcm","clk":"993590598","pt":1580544271463,"mc":[{"id":"1.168130661","rc":[{"batb":[[0,18,6.92],[1,17.5,3]],"ltp":18.0,"tv":267.34,"id":24707172}]}]}
{"op":"mcm","clk":"993591028","pt":1580544277190,"mc":[{"id":"1.168130661","rc":[{"batb":[[0,12,6.45],[2,11,2]],"ltp":13.0,"tv":331.11,"id":420}]}]}
{"op":"mcm","clk":"993591409","pt":1580544282611,"mc":[{"id":"1.168130661","rc":[{"batl":[[0,2.68,6],[1,2.74,2.06],[2,2.76,3.47]],"ltp":2.5,"tv":2499.17,"id":25238892},{"batb":[[0,2.62,8.57]],"ltp":2.6,"tv":2558.76,"id":26314798}]}]}
{"op":"mcm","clk":"993591430","pt":1580544282920,"mc":[{"id":"1.168130661","rc":[{"batl":[[0,2.66,4.46],[1,2.68,6]],"ltp":2.5,"tv":2499.17,"id":25238892},{"batb":[[0,2.62,6.57]],"ltp":2.6,"tv":2558.76,"id":26314798}]}]}
{"op":"mcm","clk":"993592165","pt":1580544294697,"mc":[{"id":"1.168130661","rc":[{"batl":[[0,2.64,6],[1,2.72,2.29]],"ltp":2.5,"tv":2499.17,"id":25238892},{"batb":[[0,18.5,3.93],[1,18,5.98],[2,17.5,3]],"ltp":18.0,"tv":267.34,"id":24707172},{"batb":[[0,2.62,8.57]],"ltp":2.6,"tv":2558.76,"id":26314798}]}]}
{"op":"mcm","clk":"993592669","pt":1580544302952,"mc":[{"id":"1.168130661","rc":[{"batl":[[1,2.66,2.01]],"ltp":2.5,"tv":2499.17,"id":25238892},{"batb":[[1,2.6,53.29]],"ltp":2.6,"tv":2558.76,"id":26314798}]}]}
{"op":"mcm","clk":"993594318","pt":1580544324684,"mc":[{"id":"1.168130661","rc":[{"batl":[[2,2.76,10.55]],"ltp":2.5,"tv":2499.17,"id":25238892}]}]}
{"op":"mcm","clk":"993594387","pt":1580544325460,"mc":[{"id":"1.168130661","rc":[{"batl":[[0,2.64,8]],"ltp":2.5,"tv":2499.17,"id":25238892}]}]}
{"op":"mcm","clk":"993594835","pt":1580544331574,"mc":[{"id":"1.168130661","rc":[{"batl":[[0,15,2],[1,15.5,2.71],[2,16.5,3]],"ltp":13.0,"tv":331.11,"id":420}]}]}
{"op":"mcm","clk":"993595689","pt":1580544342599,"mc":[{"id":"1.168130661","rc":[{"batl":[[2,2.76,15.95]],"ltp":2.5,"tv":2499.17,"id":25238892}]}]}
{"op":"mcm","clk":"993598508","pt":1580544383430,"mc":[{"id":"1.168130661","rc":[{"batl":[[0,2.62,2.12],[1,2.64,18],[2,2.66,2.01]],"ltp":2.5,"tv":2499.17,"id":25238892},{"batl":[[1,2.68,5],[2,2.7,27.96]],"ltp":2.6,"tv":2558.76,"id":26314798}]}]}
{"op":"mcm","clk":"993599303","pt":1580544394538,"mc":[{"id":"1.168130661","rc":[{"batl":[[0,2.6,6],[1,2.62,2.12],[2,2.64,12]],"ltp":2.5,"tv":2499.17,"id":25238892},{"batb":[[2,17.5,5]],"ltp":18.0,"tv":267.34,"id":24707172},{"batl":[[0,12.5,11.41]],"ltp":12.0,"tv":492.46,"id":24420205}]}]}
{"op":"mcm","clk":"993599719","pt":1580544401148,"mc":[{"id":"1.168130661","rc":[{"batl":[[0,2.6,8]],"ltp":2.5,"tv":2499.17,"id":25238892}]}]}
{"op":"mcm","clk":"993599788","pt":1580544402335,"mc":[{"id":"1.168130661","rc":[{"batb":[[0,30,7.28]],"ltp":32.0,"tv":82.6,"id":25545675}]}]}
{"op":"mcm","clk":"993599851","pt":1580544403160,"mc":[{"id":"1.168130661","rc":[{"batb":[[2,27,13.97]],"ltp":32.0,"tv":82.6,"id":25545675}]}]}
{"op":"mcm","clk":"993600344","pt":1580544410136,"mc":[{"id":"1.168130661","rc":[{"batb":[[0,30,7.87]],"ltp":32.0,"tv":82.6,"id":25545675}]}]}
{"op":"mcm","clk":"993601840","pt":1580544435298,"mc":[{"id":"1.168130661","rc":[{"batl":[[2,22,1.76]],"ltp":18.0,"tv":267.34,"id":24707172}]}]}
{"op":"mcm","clk":"993612968","pt":1580544452686,"mc":[{"id":"1.168130661","rc":[{"trd":[[2.52,89.4],[2.54,235.64]],"batb":[[0,2.5,84.6],[1,2.48,164.01],[2,2.42,4.8]],"batl":[[0,2.58,2.17],[1,2.6,8],[2,2.62,2.12]],"ltp":2.52,"tv":2519.17,"id":25238892},{"batb":[[1,18,7.98]],"ltp":18.0,"tv":267.34,"id":24707172},{"batb":[[0,2.64,2.17],[1,2.62,8.57],[2,2.6,53.29]],"ltp":2.6,"tv":2558.76,"id":26314798},{"batl":[[0,14.5,2.17],[1,15,2],[2,15.5,2.71]],"ltp":13.0,"tv":331.11,"id":420}],"tv":6251.46}]}
{"op":"mcm","clk":"993613035","pt":1580544453616,"mc":[{"id":"1.168130661","rc":[{"batb":[[0,2.52,10.1],[1,2.5,84.6],[2,2.48,164.01]],"batl":[[0,2.6,6],[1,2.62,2.12],[2,2.64,12]],"ltp":2.52,"tv":2519.17,"id":25238892}]}]}
{"op":"mcm","clk":"993613126","pt":1580544454706,"mc":[{"id":"1.168130661","rc":[{"batb":[[2,2.48,179.4]],"ltp":2.52,"tv":2519.17,"id":25238892},{"batl":[[2,15.5,4.71]],"ltp":13.0,"tv":331.11,"id":420}]}]}
{"op":"mcm","clk":"993613172","pt":1580544455429,"mc":[{"id":"1.168130661","rc":[{"batb":[[2,2.48,164.01]],"ltp":2.52,"tv":2519.17,"id":25238892}]}]}
{"op":"mcm","clk":"993613376","pt":1580544458632,"mc":[{"id":"1.168130661","rc":[{"batl":[[2,15.5,2.32]],"ltp":13.0,"tv":331.11,"id":420}]}]}
{"op":"mcm","clk":"993614150","pt":1580544469654,"mc":[{"id":"1.168130661","rc":[{"trd":[[18.5,4]],"batb":[[0,18.5,1.93]],"ltp":18.5,"tv":271.34,"id":24707172}],"tv":6255.46}]}
{"op":"mcm","clk":"993615477","pt":1580544489546,"mc":[{"id":"1.168130661","rc":[{"trd":[[2.6,87.92]],"batl":[[0,2.6,1.2]],"ltp":2.6,"tv":2528.77,"id":25238892},{"trd":[[12,19.05]],"batb":[[0,12,3.49],[2,11,6.92]],"ltp":12.0,"tv":341.11,"id":420}],"tv":6275.06}]}
{"op":"mcm","clk":"993615792","pt":1580544494187,"mc":[{"id":"1.168130661","rc":[{"batl":[[0,14,2],[1,15,2.07]],"ltp":12.0,"tv":341.11,"id":420}]}]}
{"op":"mcm","clk":"993616281","pt":1580544500672,"mc":[{"id":"1.168130661","rc":[{"trd":[[2.6,90.32],[2.62,46.82],[2.64,98.82],[2.7,93.4]],"batb":[[0,2.54,4.11],[1,2.52,7.92],[2,2.5,82.6]],"batl":[[0,2.72,2.11],[1,2.74,91],[2,2.76,10.93]],"ltp":2.7,"tv":2572.77,"id":25238892},{"batb":[[1,18,5.98]],"batl":[[0,19.5,2.11],[1,20,10.25],[2,21,14.12]],"ltp":18.5,"tv":271.34,"id":24707172},{"batl":[[0,12,2.1],[1,12.5,11.41],[2,13.5,6]],"ltp":12.0,"tv":492.46,"id":24420205},{"batb":[[0,2.62,8.57],[1,2.6,53.29],[2,2.58,19.63]],"batl":[[1,2.68,7]],"ltp":2.6,"tv":2558.76,"id":26314798}],"tv":6319.06}]}
{"op":"mcm","clk":"993616356","pt":1580544501702,"mc":[{"id":"1.168130661","rc":[{"batb":[[0,2.56,6.63],[1,2.54,4.11],[2,2.52,16.5]],"ltp":2.7,"tv":2572.77,"id":25238892}]}]}
{"op":"mcm","clk":"993616442","pt":1580544502682,"mc":[{"id":"1.168130661","rc":[{"batb":[[0,2.56,10.63]],"batl":[[0,2.72,10.65]],"ltp":2.7,"tv":2572.77,"id":25238892}]}]}
{"op":"mcm","clk":"993616514","pt":1580544503664,"mc":[{"id":"1.168130661","rc":[{"batb":[[0,2.54,4.11],[1,2.52,7.92],[2,2.5,82.6]],"batl":[[2,2.76,3.47]],"ltp":2.7,"tv":2572.77,"id":25238892}]}]}
{"op":"mcm","clk":"993616814","pt":1580544507691,"mc":[{"id":"1.168130661","rc":[{"batl":[[1,2.68,5]],"ltp":2.6,"tv":2558.76,"id":26314798},{"trd":[[12,26.04]],"batb":[[0,11.5,3.65],[1,11,8.92],[2,10.5,3.28]],"batl":[[0,12,5.75],[1,12.5,2.15],[2,14,2]],"ltp":12.0,"tv":348.09,"id":420}],"tv":6326.04}]}
{"op":"mcm","clk":"993616885","pt":1580544508565,"mc":[{"id":"1.168130661","rc":[{"trd":[[2.72,100.33]],"batl":[[0,2.72,9.88]],"ltp":2.72,"tv":2602.32,"id":25238892}],"tv":6355.59}]}
{"op":"mcm","clk":"993616983","pt":1580544509697,"mc":[{"id":"1.168130661","rc":[{"trd":[[2.7,101.7]],"batl":[[0,2.7,6],[1,2.72,9.88],[2,2.74,91]],"ltp":2.7,"tv":2610.62,"id":25238892},{"trd":[[11,27.17],[11.5,88.99]],"batb":[[0,11,7.17],[1,10.5,1.98],[2,10,25.49]],"ltp":11.0,"tv":497.61,"id":24420205},{"batb":[[1,11,4]],"ltp":12.0,"tv":348.09,"id":420}],"tv":6369.04}]}
{"op":"mcm","clk":"993617032","pt":1580544510264,"mc":[{"id":"1.168130661","rc":[{"batl":[[0,2.7,8]],"ltp":2.7,"tv":2610.62,"id":25238892}]}]}
{"op":"mcm","clk":"993617200","pt":1580544512479,"mc":[{"id":"1.168130661","rc":[{"batb":[[0,2.54,15.51]],"batl":[[0,2.68,3.55],[1,2.7,6],[2,2.72,11.88]],"ltp":2.7,"tv":2610.62,"id":25238892}]}]}
{"op":"mcm","clk":"993617371","pt":1580544514691,"mc":[{"id":"1.168130661","rc":[{"batb":[[1,2.52,13.31]],"ltp":2.7,"tv":2610.62,"id":25238892}]}]}
{"op":"mcm","clk":"993617568","pt":1580544517214,"mc":[{"id":"1.168130661","rc":[{"trd":[[11.5,13.66]],"batb":[[0,11.5,1.25]],"ltp":11.5,"tv":352.9,"id":420}],"tv":6373.85}]}
{"op":"mcm","clk":"993617736","pt":1580544519680,"mc":[{"id":"1.168130661","rc":[{"batl":[[0,12,8.1],[2,14,2.52]],"ltp":11.0,"tv":497.61,"id":24420205},{"batb":[[0,11.5,3.25]],"ltp":11.5,"tv":352.9,"id":420}]}]}
{"op":"mcm","clk":"993618032","pt":1580544523699,"mc":[{"id":"1.168130661","rc":[{"batl":[[0,2.66,6],[1,2.68,3.55],[2,2.7,2.23]],"ltp":2.7,"tv":2610.62,"id":25238892},{"batb":[[1,18,7.98]],"batl":[[0,20,10.25],[1,21,14.12],[2,22,1.76]],"ltp":18.5,"tv":271.34,"id":24707172},{"trd":[[11,44.34],[11.5,20.16]],"batb":[[0,10.5,8.66],[1,10,15.97],[2,9.8,39.02]],"batl":[[0,11.5,13.73],[1,12,7.75],[2,12.5,2.15]],"ltp":11.0,"tv":365.86,"id":420}],"tv":6386.81}]}
{"op":"mcm","clk":"993618154","pt":1580544525708,"mc":[{"id":"1.168130661","rc":[{"batb":[[1,10,13.24]],"ltp":11.0,"tv":365.86,"id":420}]}]}
{"op":"mcm","clk":"993618834","pt":1580544536529,"mc":[{"id":"1.168130661","rc":[{"trd":[[2.66,33]],"batl":[[0,2.68,3.55],[1,2.72,11.88],[2,2.76,1.18]],"ltp":2.66,"tv":2622.62,"id":25238892},{"batb":[[0,18.5,12.2]],"ltp":18.5,"tv":271.34,"id":24707172},{"trd":[[10.5,65.35]],"batb":[[0,10.5,4.26]],"batl":[[0,11.5,15.73]],"ltp":10.5,"tv":378.66,"id":420}],"tv":6411.61}]}
{"op":"mcm","clk":"993618965","pt":1580544538437,"mc":[{"id":"1.168130661","rc":[{"batb":[[0,10.5,8.26]],"ltp":10.5,"tv":378.66,"id":420}]}]}
{"op":"mcm","clk":"993619349","pt":1580544543721,"mc":[{"id":"1.168130661","rc":[{"trd":[[2.68,77.8]],"batb":[[0,2.54,16.41]],"batl":[[0,2.72,9.88],[1,2.76,3.19],[2,2.8,4.11]],"ltp":2.68,"tv":2642.85,"id":25238892}],"tv":6431.83}]}
{"op":"mcm","clk":"993619417","pt":1580544544549,"mc":[{"id":"1.168130661","rc":[{"batb":[[0,2.54,23.84]],"batl":[[1,2.74,6.88],[2,2.76,3.19]],"ltp":2.68,"tv":2642.85,"id":25238892}]}]}
{"op":"mcm","clk":"993619714","pt":1580544548529,"mc":[{"id":"1.168130661","rc":[{"batl":[[0,2.7,2],[1,2.72,9.88],[2,2.74,8.88]],"ltp":2.68,"tv":2642.85,"id":25238892}]}]}
{"op":"mcm","clk":"993619848","pt":1580544550445,"mc":[{"id":"1.168130661","rc":[{"batb":[[1,2.52,16.04]],"ltp":2.68,"tv":2642.85,"id":25238892}]}]}
{"op":"mcm","clk":"993620251","pt":1580544555654,"mc":[{"id":"1.168130661","rc":[{"batb":[[0,18.5,1.93],[2,17.5,12.45]],"ltp":18.5,"tv":271.34,"id":24707172}]}]}
{"op":"mcm","clk":"993620608","pt":1580544560654,"mc":[{"id":"1.168130661","rc":[{"batb":[[2,17.5,7.51]],"ltp":18.5,"tv":271.34,"id":24707172},{"trd":[[10.5,84.51]],"batb":[[0,10,13.24],[1,9.8,44.08],[2,9,3]],"batl":[[0,10.5,10.39],[1,11,3.11],[2,11.5,15.73]],"ltp":10.5,"tv":397.81,"id":420}],"tv":6450.99}]}
{"op":"mcm","clk":"993620643","pt":1580544561168,"mc":[{"id":"1.168130661","rc":[{"batb":[[0,10,14.36]],"ltp":10.5,"tv":397.81,"id":420}]}]}
{"op":"mcm","clk":"993621022","pt":1580544567447,"mc":[{"id":"1.168130661","rc":[{"batl":[[2,2.74,6.88]],"ltp":2.68,"tv":2642.85,"id":25238892},{"batb":[[2,10,16.86]],"ltp":11.0,"tv":497.61,"id":24420205},{"batb":[[0,2.64,2.14],[1,2.62,8.57],[2,2.6,53.29]],"ltp":2.6,"tv":2558.76,"id":26314798},{"batb":[[0,10,5.73]],"ltp":10.5,"tv":397.81,"id":420}]}]}
{"op":"mcm","clk":"993621094","pt":1580544568689,"mc":[{"id":"1.168130661","rc":[{"batb":[[0,10,8.73]],"ltp":10.5,"tv":397.81,"id":420}]}]}
{"op":"mcm","clk":"993621172","pt":1580544569673,"mc":[{"id":"1.168130661","rc":[{"batl":[[0,20,8.25]],"ltp":18.5,"tv":271.34,"id":24707172},{"batl":[[2,2.7,25.96]],"ltp":2.6,"tv":2558.76,"id":26314798},{"trd":[[10,106.29]],"batb":[[0,9.8,38],[1,9.6,4.91],[2,9.4,2.15]],"ltp":10.0,"tv":430.75,"id":420}],"tv":6483.93}]}
{"op":"mcm","clk":"993621310","pt":1580544571541,"mc":[{"id":"1.168130661","rc":[{"batb":[[1,9.6,15.96]],"ltp":10.0,"tv":430.75,"id":420}]}]}
{"op":"mcm","clk":"993621516","pt":1580544574379,"mc":[{"id":"1.168130661","rc":[{"batb":[[0,18.5,12.2]],"ltp":18.5,"tv":271.34,"id":24707172}]}]}
{"op":"mcm","clk":"993621870","pt":1580544579648,"mc":[{"id":"1.168130661","rc":[{"trd":[[12,26.2]],"batl":[[0,12.5,11.41],[1,14,2.52],[2,15,2]],"ltp":12.0,"tv":513.81,"id":24420205}],"tv":6500.13}]}
{"op":"mcm","clk":"993621884","pt":1580544579854,"mc":[{"id":"1.168130661","rc":[{"batl":[[1,21,16.12]],"ltp":18.5,"tv":271.34,"id":24707172}]}]}
{"op":"mcm","clk":"993622428","pt":1580544587693,"mc":[{"id":"1.168130661","rc":[{"batb":[[0,9.8,41]],"ltp":10.0,"tv":430.75,"id":420}]}]}
{"op":"mcm","clk":"993622497","pt":1580544588674,"mc":[{"id":"1.168130661","rc":[{"batl":[[0,19.5,1.76],[1,20,8.25],[2,21,16.12]],"ltp":18.5,"tv":271.34,"id":24707172},{"batl":[[1,13.5,4],[2,14,2.52]],"ltp":12.0,"tv":513.81,"id":24420205}]}]}
{"op":"mcm","clk":"993622913","pt":1580544594403,"mc":[{"id":"1.168130661","rc":[{"batb":[[0,18.5,1.93]],"ltp":18.5,"tv":271.34,"id":24707172}]}]}
{"op":"mcm","clk":"993623627","pt":1580544604306,"mc":[{"id":"1.168130661","rc":[{"batl":[[1,20,10.25]],"ltp":18.5,"tv":271.34,"id":24707172}]}]}
{"op":"mcm","clk":"993624335","pt":1580544613661,"mc":[{"id":"1.168130661","rc":[{"batb":[[0,18.5,12.2]],"ltp":18.5,"tv":271.34,"id":24707172},{"batl":[[1,2.68,9]],"ltp":2.6,"tv":2558.76,"id":26314798}]}]}
{"op":"mcm","clk":"993625658","pt":1580544632653,"mc":[{"id":"1.168130661","rc":[{"batb":[[0,18.5,1.93],[2,17.5,12.45]],"ltp":18.5,"tv":271.34,"id":24707172}]}]}
{"op":"mcm","clk":"993625822","pt":1580544634679,"mc":[{"id":"1.168130661","rc":[{"trd":[[2.54,247.64]],"batb":[[0,2.56,4.17],[1,2.54,17.84],[2,2.52,16.04]],"ltp":2.54,"tv":2654.85,"id":25238892},{"batl":[[1,20,8.25],[2,21,14.12]],"ltp":18.5,"tv":271.34,"id":24707172}],"tv":6512.13}]}
{"op":"mcm","clk":"993626046","pt":1580544637679,"mc":[{"id":"1.168130661","rc":[{"batb":[[2,2.52,10.66]],"ltp":2.54,"tv":2654.85,"id":25238892},{"batb":[[2,17.5,7.51]],"ltp":18.5,"tv":271.34,"id":24707172}]}]}
{"op":"mcm","clk":"993626057","pt":1580544637882,"mc":[{"id":"1.168130661","rc":[{"batl":[[2,2.7,27.96]],"ltp":2.6,"tv":2558.76,"id":26314798}]}]}
{"op":"mcm","clk":"993626521","pt":1580544643666,"mc":[{"id":"1.168130661","rc":[{"batb":[[0,2.6,4.23],[1,2.58,5.5],[2,2.56,4.17]],"batl":[[2,2.74,8.88]],"ltp":2.54,"tv":2654.85,"id":25238892},{"batb":[[0,10,2.23],[1,9.8,41],[2,9.6,15.96]],"ltp":10.0,"tv":430.75,"id":420}]}]}
{"op":"mcm","clk":"993626665","pt":1580544645675,"mc":[{"id":"1.168130661","rc":[{"batb":[[2,9.6,2.15]],"ltp":10.0,"tv":430.75,"id":420}]}]}
{"op":"mcm","clk":"993626708","pt":1580544646394,"mc":[{"id":"1.168130661","rc":[{"batb":[[0,10,4.23]],"ltp":10.0,"tv":430.75,"id":420}]}]}
{"op":"mcm","clk":"993627371","pt":1580544655378,"mc":[{"id":"1.168130661","rc":[{"batb":[[2,28,5.18]],"ltp":32.0,"tv":82.6,"id":25545675},{"batl":[[0,2.72,9.88],[1,2.74,8.88],[2,2.76,3.19]],"ltp":2.54,"tv":2654.85,"id":25238892},{"batb":[[0,2.64,70.38]],"ltp":2.6,"tv":2558.76,"id":26314798}]}]}
{"op":"mcm","clk":"993627530","pt":1580544657705,"mc":[{"id":"1.168130661","rc":[{"batb":[[1,2.62,22.59]],"batl":[[2,2.7,16.99]],"ltp":2.6,"tv":2558.76,"id":26314798}]}]}
{"op":"mcm","clk":"993627607","pt":1580544658693,"mc":[{"id":"1.168130661","rc":[{"batl":[[0,12,5],[1,12.5,11.41],[2,13.5,4]],"ltp":12.0,"tv":513.81,"id":24420205}]}]}
{"op":"mcm","clk":"993628031","pt":1580544664690,"mc":[{"id":"1.168130661","rc":[{"batl":[[0,12,9],[2,14,2.52]],"ltp":12.0,"tv":513.81,"id":24420205}]}]}
{"op":"mcm","clk":"993628103","pt":1580544665721,"mc":[{"id":"1.168130661","rc":[{"batb":[[2,27,8.23]],"ltp":32.0,"tv":82.6,"id":25545675},{"batb":[[0,2.6,74.17]],"batl":[[1,2.74,6.88]],"ltp":2.54,"tv":2654.85,"id":25238892},{"batb":[[0,2.64,2.14],[2,2.6,123.23]],"ltp":2.6,"tv":2558.76,"id":26314798},{"batb":[[0,10,2],[2,9.6,4.28]],"ltp":10.0,"tv":430.75,"id":420}]}]}
{"op":"mcm","clk":"993628160","pt":1580544666493,"mc":[{"id":"1.168130661","rc":[{"batb":[[1,2.62,32.42]],"ltp":2.6,"tv":2558.76,"id":26314798}]}]}
{"op":"mcm","clk":"993628369","pt":1580544669536,"mc":[{"id":"1.168130661","rc":[{"batb":[[1,2.58,19.56]],"ltp":2.54,"tv":2654.85,"id":25238892},{"batb":[[1,2.62,18.39]],"ltp":2.6,"tv":2558.76,"id":26314798},{"trd":[[10,110.29]],"batb":[[0,9.8,39],[1,9.6,2.15],[2,9.2,3.43]],"batl":[[0,10,1.6],[1,10.5,13.39],[2,11,3.11]],"ltp":10.0,"tv":434.75,"id":420}],"tv":6516.13}]}
{"op":"mcm","clk":"993628469","pt":1580544670626,"mc":[{"id":"1.168130661","rc":[{"batb":[[0,18.5,12.2]],"ltp":18.5,"tv":271.34,"id":24707172}]}]}
{"op":"mcm","clk":"993628524","pt":1580544671451,"mc":[{"id":"1.168130661","rc":[{"batb":[[1,9.6,16.19]],"ltp":10.0,"tv":434.75,"id":420}]}]}
{"op":"mcm","clk":"993628803","pt":1580544675615,"mc":[{"id":"1.168130661","rc":[{"batb":[[0,2.64,4.08],[1,2.62,5.42],[2,2.6,74.17]],"ltp":2.54,"tv":2654.85,"id":25238892}]}]}
{"op":"mcm","clk":"993629505","pt":1580544685718,"mc":[{"id":"1.168130661","rc":[{"trd":[[10,113.49]],"batb":[[0,9.8,39.4]],"batl":[[0,10.5,13.39],[1,11,3.11],[2,11.5,15.73]],"ltp":10.0,"tv":437.95,"id":420}],"tv":6519.33}]}
{"op":"mcm","clk":"993629559","pt":1580544686448,"mc":[{"id":"1.168130661","rc":[{"trd":[[30,16.55]],"batb":[[0,30,5.87]],"ltp":30.0,"tv":86.6,"id":25545675},{"batb":[[0,9.8,41.4],[1,9.6,2.15],[2,9.2,17.62]],"batl":[[0,10.5,10.39]],"ltp":10.0,"tv":437.95,"id":420}],"tv":6523.34}]}
{"op":"mcm","clk":"993629804","pt":1580544689723,"mc":[{"id":"1.168130661","rc":[{"batb":[[0,30,5.28]],"ltp":30.0,"tv":86.6,"id":25545675},{"batb":[[0,18.5,1.93],[2,17.5,12.45]],"ltp":18.5,"tv":271.34,"id":24707172},{"batb":[[1,9.6,16.19]],"ltp":10.0,"tv":437.95,"id":420}]}]}
{"op":"mcm","clk":"993629970","pt":1580544691639,"mc":[{"id":"1.168130661","rc":[{"trd":[[2.64,238.35]],"batb":[[0,2.62,18.39],[1,2.6,123.23],[2,2.58,19.63]],"batl":[[0,2.64,2.86],[1,2.66,2],[2,2.68,9]],"ltp":2.64,"tv":2563.04,"id":26314798}],"tv":6527.62}]}
{"op":"mcm","clk":"993630045","pt":1580544692553,"mc":[{"id":"1.168130661","rc":[{"batb":[[2,17.5,7.51]],"ltp":18.5,"tv":271.34,"id":24707172},{"batb":[[1,9.6,2.15],[2,9.2,24.71]],"ltp":10.0,"tv":437.95,"id":420}]}]}
{"op":"mcm","clk":"993630108","pt":1580544693355,"mc":[{"id":"1.168130661","rc":[{"batb":[[1,2.6,129.53]],"ltp":2.64,"tv":2563.04,"id":26314798},{"batb":[[1,9.6,16.19]],"ltp":10.0,"tv":437.95,"id":420}]}]}
{"op":"mcm","clk":"993630303","pt":1580544695635,"mc":[{"id":"1.168130661","rc":[{"batb":[[0,32,2.19],[1,30,5.28],[2,29,4.3]],"ltp":30.0,"tv":86.6,"id":25545675},{"batb":[[0,2.64,30.58]],"ltp":2.54,"tv":2654.85,"id":25238892},{"batb":[[0,18.5,5.71]],"ltp":18.5,"tv":271.34,"id":24707172},{"batb":[[0,11,13.53]],"ltp":12.0,"tv":513.81,"id":24420205},{"trd":[[2.64,244.07]],"batb":[[0,2.64,25.64],[1,2.62,18.39],[2,2.6,129.53]],"batl":[[0,2.66,2],[1,2.68,9],[2,2.7,16.99]],"ltp":2.64,"tv":2568.76,"id":26314798},{"batb":[[0,9.8,48.54],[1,9.6,2.15]],"ltp":10.0,"tv":437.95,"id":420}],"tv":6533.34}]}
{"op":"mcm","clk":"993630380","pt":1580544696669,"mc":[{"id":"1.168130661","rc":[{"batb":[[1,30,5.87]],"ltp":30.0,"tv":86.6,"id":25545675}]}]}
{"op":"mcm","clk":"993630462","pt":1580544697658,"mc":[{"id":"1.168130661","rc":[{"batb":[[1,2.62,15.7]],"ltp":2.54,"tv":2654.85,"id":25238892},{"batb":[[1,2.62,26.4]],"ltp":2.64,"tv":2568.76,"id":26314798},{"batb":[[1,9.6,16.19]],"ltp":10.0,"tv":437.95,"id":420}]}]}
{"op":"mcm","clk":"993630586","pt":1580544699673,"mc":[{"id":"1.168130661","rc":[{"batl":[[0,50,1.06]],"ltp":30.0,"tv":86.6,"id":25545675}]}]}
{"op":"mcm","clk":"993630897","pt":1580544704273,"mc":[{"id":"1.168130661","rc":[{"batl":[[0,2.72,23.2]],"ltp":2.54,"tv":2654.85,"id":25238892},{"batb":[[0,10,2.64],[1,9.8,48.14],[2,9.6,16.19]],"ltp":10.0,"tv":437.95,"id":420}]}]}
{"op":"mcm","clk":"993630977","pt":1580544705471,"mc":[{"id":"1.168130661","rc":[{"batb":[[2,10,19.11]],"ltp":12.0,"tv":513.81,"id":24420205}]}]}
{"op":"mcm","clk":"993631129","pt":1580544707683,"mc":[{"id":"1.168130661","rc":[{"batb":[[2,9.6,2.15]],"ltp":10.0,"tv":437.95,"id":420}]}]}
{"op":"mcm","clk":"993631261","pt":1580544709395,"mc":[{"id":"1.168130661","rc":[{"trd":[[9.8,54.72],[10,118.77]],"batb":[[0,9.8,42.78],[1,9.2,7.09],[2,9,3]],"ltp":9.8,"tv":449.95,"id":420}],"tv":6545.34}]}
{"op":"mcm","clk":"993631335","pt":1580544710486,"mc":[{"id":"1.168130661","rc":[{"batb":[[1,9.2,14.18]],"ltp":9.8,"tv":449.95,"id":420}]}]}
{"op":"mcm","clk":"993631546","pt":1580544713655,"mc":[{"id":"1.168130661","rc":[{"batb":[[0,9.8,39.78],[1,9.4,3],[2,9.2,14.18]],"ltp":9.8,"tv":449.95,"id":420}]}]}
{"op":"mcm","clk":"993631857","pt":1580544718472,"mc":[{"id":"1.168130661","rc":[{"trd":[[12,44.2]],"batl":[[0,12.5,11.41],[1,14,2.52],[2,15,2]],"ltp":12.0,"tv":531.82,"id":24420205},{"batb":[[1,9.6,9.65],[2,9.4,10.09]],"ltp":9.8,"tv":449.95,"id":420}],"tv":6563.34}]}
{"op":"mcm","clk":"993632017","pt":1580544720703,"mc":[{"id":"1.168130661","rc":[{"batb":[[1,9.6,16.74]],"ltp":9.8,"tv":449.95,"id":420}]}]}
{"op":"mcm","clk":"993632486","pt":1580544726372,"mc":[{"id":"1.168130661","rc":[{"trd":[[9.8,60.02]],"batb":[[0,9.8,37.13]],"ltp":9.8,"tv":455.25,"id":420}],"tv":6568.64}]}
{"op":"mcm","clk":"993632999","pt":1580544733411,"mc":[{"id":"1.168130661","rc":[{"batl":[[1,13.5,4],[2,14,2.52]],"ltp":12.0,"tv":531.82,"id":24420205},{"batb":[[0,9.8,40.13],[2,9.4,7.09]],"ltp":9.8,"tv":455.25,"id":420}]}]}
{"op":"mcm","clk":"993633097","pt":1580544734704,"mc":[{"id":"1.168130661","rc":[{"trd":[[18.5,10]],"batb":[[0,18.5,2.71]],"ltp":18.5,"tv":277.34,"id":24707172}],"tv":6574.64}]}
{"op":"mcm","clk":"993633170","pt":1580544735688,"mc":[{"id":"1.168130661","rc":[{"batl":[[1,2.68,5]],"ltp":2.64,"tv":2568.76,"id":26314798}]}]}
{"op":"mcm","clk":"993634361","pt":1580544750623,"mc":[{"id":"1.168130661","rc":[{"batb":[[1,9.6,23.83]],"ltp":9.8,"tv":455.25,"id":420}]}]}
{"op":"mcm","clk":"993637400","pt":1580544786661,"mc":[{"id":"1.168130661","rc":[{"batl":[[1,2.74,8.88]],"ltp":2.54,"tv":2654.85,"id":25238892},{"batb":[[0,18.5,3.64]],"ltp":18.5,"tv":277.34,"id":24707172}]}]}
{"op":"mcm","clk":"993637699","pt":1580544790674,"mc":[{"id":"1.168130661","rc":[{"trd":[[9.8,68.14]],"batb":[[0,9.8,36.07]],"ltp":9.8,"tv":463.37,"id":420}],"tv":6582.75}]}
{"op":"mcm","clk":"993638247","pt":1580544797490,"mc":[{"id":"1.168130661","rc":[{"batb":[[0,19,8],[1,18.5,5.64],[2,18,7.98]],"ltp":18.5,"tv":277.34,"id":24707172}]}]}
{"op":"mcm","clk":"993638714","pt":1580544802653,"mc":[{"id":"1.168130661","rc":[{"batl":[[0,10.5,13.39]],"ltp":9.8,"tv":463.37,"id":420}]}]}
{"op":"mcm","clk":"993638803","pt":1580544803688,"mc":[{"id":"1.168130661","rc":[{"batl":[[0,10.5,10.39]],"ltp":9.8,"tv":463.37,"id":420}]}]}
{"op":"mcm","clk":"993638964","pt":1580544805459,"mc":[{"id":"1.168130661","rc":[{"batb":[[0,11.5,2.13],[1,11,13.53],[2,10.5,1.98]],"ltp":12.0,"tv":531.82,"id":24420205},{"batb":[[0,2.64,23.64]],"batl":[[0,2.68,7],[1,2.7,27.96],[2,2.72,415.25]],"ltp":2.64,"tv":2568.76,"id":26314798}]}]}
{"op":"mcm","clk":"993640005","pt":1580544817633,"mc":[{"id":"1.168130661","rc":[{"batb":[[0,2.66,11.48],[1,2.64,30.58],[2,2.62,15.7]],"ltp":2.54,"tv":2654.85,"id":25238892},{"batl":[[2,21,16.12]],"ltp":18.5,"tv":277.34,"id":24707172},{"batl":[[0,12.5,9.41],[1,13,2.2],[2,13.5,4]],"ltp":12.0,"tv":531.82,"id":24420205},{"batb":[[0,2.66,6.48],[1,2.64,23.64],[2,2.62,19.83]],"ltp":2.64,"tv":2568.76,"id":26314798}]}]}
{"op":"mcm","clk":"993640093","pt":1580544818637,"mc":[{"id":"1.168130661","rc":[{"batb":[[1,30,7.87]],"ltp":30.0,"tv":86.6,"id":25545675}]}]}
{"op":"mcm","clk":"993640207","pt":1580544819630,"mc":[{"id":"1.168130661","rc":[{"batb":[[2,2.62,11.82]],"ltp":2.64,"tv":2568.76,"id":26314798}]}]}
{"op":"mcm","clk":"993640545","pt":1580544823719,"mc":[{"id":"1.168130661","rc":[{"batb":[[0,34,2.23],[1,32,5.66],[2,30,4.16]],"ltp":30.0,"tv":86.6,"id":25545675}]}]}
{"op":"mcm","clk":"993640645","pt":1580544824642,"mc":[{"id":"1.168130661","rc":[{"batb":[[0,32,5.66],[1,30,4.16],[2,29,4.3]],"ltp":30.0,"tv":86.6,"id":25545675}]}]}
{"op":"mcm","clk":"993641127","pt":1580544830541,"mc":[{"id":"1.168130661","rc":[{"batl":[[0,12.5,13.41],[2,14,2.52]],"ltp":12.0,"tv":531.82,"id":24420205}]}]}
{"op":"mcm","clk":"993641300","pt":1580544832628,"mc":[{"id":"1.168130661","rc":[{"trd":[[2.72,110.33]],"batb":[[0,2.7,5.04],[1,2.66,11.48],[2,2.64,30.58]],"batl":[[0,2.72,18.2]],"ltp":2.72,"tv":2664.85,"id":25238892}],"tv":6592.75}]}
{"op":"mcm","clk":"993641389","pt":1580544833661,"mc":[{"id":"1.168130661","rc":[{"batb":[[1,30,7.34]],"ltp":30.0,"tv":86.6,"id":25545675},{"trd":[[2.72,143.45]],"batb":[[0,2.7,9.96]],"batl":[[0,2.72,3.64],[1,2.74,2]],"ltp":2.72,"tv":2697.97,"id":25238892}],"tv":6625.87}]}
{"op":"mcm","clk":"993641467","pt":1580544834642,"mc":[{"id":"1.168130661","rc":[{"batb":[[0,34,2.29],[1,32,5.66],[2,30,7.34]],"ltp":30.0,"tv":86.6,"id":25545675},{"batb":[[1,2.68,5.29],[2,2.66,13.59]],"ltp":2.72,"tv":2697.97,"id":25238892}]}]}
{"op":"mcm","clk":"993641543","pt":1580544835632,"mc":[{"id":"1.168130661","rc":[{"batb":[[0,32,5.66],[1,30,7.34],[2,29,4.3]],"ltp":30.0,"tv":86.6,"id":25545675},{"batl":[[0,2.72,1.64]],"ltp":2.72,"tv":2697.97,"id":25238892},{"batl":[[0,12.5,15.41]],"ltp":12.0,"tv":531.82,"id":24420205},{"trd":[[2.66,173.95]],"batb":[[0,2.64,23.64],[1,2.62,11.82],[2,2.6,123.23]],"ltp":2.66,"tv":2581.71,"id":26314798}],"tv":6638.82}]}
{"op":"mcm","clk":"993641616","pt":1580544836668,"mc":[{"id":"1.168130661","rc":[{"trd":[[2.72,146.73]],"batb":[[1,2.68,8.81]],"batl":[[0,2.76,3.19],[1,2.84,8.51],[2,2.86,87]],"ltp":2.72,"tv":2701.25,"id":25238892},{"batb":[[1,2.62,14.7]],"ltp":2.66,"tv":2581.71,"id":26314798}],"tv":6642.1}]}
{"op":"mcm","clk":"993641715","pt":1580544837660,"mc":[{"id":"1.168130661","rc":[{"batb":[[0,34,2.31],[1,32,5.66],[2,30,7.34]],"ltp":30.0,"tv":86.6,"id":25545675},{"batl":[[0,2.76,5.19]],"ltp":2.72,"tv":2701.25,"id":25238892},{"batb":[[1,2.62,19.83]],"ltp":2.66,"tv":2581.71,"id":26314798}]}]}
{"op":"mcm","clk":"993641822","pt":1580544838647,"mc":[{"id":"1.168130661","rc":[{"batb":[[0,32,5.66],[1,30,7.34],[2,29,4.3]],"ltp":30.0,"tv":86.6,"id":25545675},{"trd":[[2.76,284.95]],"batl":[[0,2.78,2],[1,2.8,2],[2,2.84,8.51]],"ltp":2.76,"tv":2705.25,"id":25238892}],"tv":6646.1}]}
{"op":"mcm","clk":"993641886","pt":1580544839467,"mc":[{"id":"1.168130661","rc":[{"batl":[[2,2.84,2.96]],"ltp":2.76,"tv":2705.25,"id":25238892}]}]}
{"op":"mcm","clk":"993642155","pt":1580544842681,"mc":[{"id":"1.168130661","rc":[{"batb":[[0,34,2.01],[1,32,2.19],[2,30,7.34]],"ltp":30.0,"tv":86.6,"id":25545675}]}]}
{"op":"mcm","clk":"993642222","pt":1580544843355,"mc":[{"id":"1.168130661","rc":[{"batb":[[0,32,2.19],[1,30,7.34],[2,29,4.3]],"ltp":30.0,"tv":86.6,"id":25545675}]}]}
{"op":"mcm","clk":"993643105","pt":1580544852564,"mc":[{"id":"1.168130661","rc":[{"batb":[[0,34,2.06],[1,32,2.19],[2,30,7.34]],"ltp":30.0,"tv":86.6,"id":25545675},{"batb":[[0,2.7,14.96]],"ltp":2.76,"tv":2705.25,"id":25238892}]}]}
{"op":"mcm","clk":"993643620","pt":1580544858661,"mc":[{"id":"1.168130661","rc":[{"batl":[[1,20,10.25]],"ltp":18.5,"tv":277.34,"id":24707172},{"trd":[[12.5,32]],"batl":[[0,13.5,2.09],[1,14,2.52],[2,15,2]],"ltp":12.5,"tv":562.64,"id":24420205},{"batb":[[1,2.62,17.83]],"ltp":2.66,"tv":2581.71,"id":26314798},{"batl":[[0,10.5,13.39]],"ltp":9.8,"tv":463.37,"id":420}],"tv":6676.93}]}
{"op":"mcm","clk":"993644371","pt":1580544868286,"mc":[{"id":"1.168130661","rc":[{"batl":[[0,13.5,5.09]],"ltp":12.5,"tv":562.64,"id":24420205}]}]}
{"op":"mcm","clk":"993645682","pt":1580544882695,"mc":[{"id":"1.168130661","rc":[{"batb":[[0,32,2.19],[1,30,7.34],[2,29,4.3]],"ltp":30.0,"tv":86.6,"id":25545675},{"trd":[[2.78,343.11]],"batb":[[0,2.7,9.96],[2,2.66,11.48]],"batl":[[0,2.74,2.23],[1,2.78,20.7]],"ltp":2.78,"tv":2716.93,"id":25238892}],"tv":6688.61}]}
{"op":"mcm","clk":"993645888","pt":1580544884713,"mc":[{"id":"1.168130661","rc":[{"batb":[[1,30,4.16]],"ltp":30.0,"tv":86.6,"id":25545675}]}]}
{"op":"mcm","clk":"993646339","pt":1580544889633,"mc":[{"id":"1.168130661","rc":[{"batb":[[1,30,3.57]],"ltp":30.0,"tv":86.6,"id":25545675}]}]}
{"op":"mcm","clk":"993646719","pt":1580544893625,"mc":[{"id":"1.168130661","rc":[{"trd":[[2.68,197.78]],"batl":[[0,2.68,4.48]],"ltp":2.68,"tv":2586.75,"id":26314798}],"tv":6693.64}]}
{"op":"mcm","clk":"993646959","pt":1580544896537,"mc":[{"id":"1.168130661","rc":[{"batb":[[0,34,2.3],[1,32,2.19],[2,30,3.57]],"ltp":30.0,"tv":86.6,"id":25545675}]}]}
{"op":"mcm","clk":"993647066","pt":1580544897627,"mc":[{"id":"1.168130661","rc":[{"batb":[[0,32,2.19],[1,30,3.57],[2,29,4.3]],"ltp":30.0,"tv":86.6,"id":25545675}]}]}
{"op":"mcm","clk":"993651429","pt":1580544943708,"mc":[{"id":"1.168130661","rc":[{"batb":[[0,34,2.13],[1,32,2.19],[2,30,3.57]],"ltp":30.0,"tv":86.6,"id":25545675}]}]}
{"op":"mcm","clk":"993651473","pt":1580544944177,"mc":[{"id":"1.168130661","rc":[{"batb":[[0,32,2.19],[1,30,3.57],[2,29,4.3]],"ltp":30.0,"tv":86.6,"id":25545675}]}]}
{"op":"mcm","clk":"993652563","pt":1580544955612,"mc":[{"id":"1.168130661","rc":[{"batl":[[2,2.9,1.18]],"ltp":2.78,"tv":2716.93,"id":25238892}]}]}
{"op":"mcm","clk":"993652875","pt":1580544958721,"mc":[{"id":"1.168130661","rc":[{"batl":[[0,2.76,2.32]],"ltp":2.78,"tv":2716.93,"id":25238892},{"trd":[[2.64,273.66]],"batb":[[0,2.64,8.84],[1,2.62,20.83]],"batl":[[0,2.66,2],[1,2.68,4.48],[2,2.7,27.96]],"ltp":2.64,"tv":2616.34,"id":26314798}],"tv":6723.24}]}
{"op":"mcm","clk":"993653100","pt":1580544960705,"mc":[{"id":"1.168130661","rc":[{"batb":[[1,2.62,12.82]],"ltp":2.64,"tv":2616.34,"id":26314798}]}]}
{"op":"mcm","clk":"993654466","pt":1580544974668,"mc":[{"id":"1.168130661","rc":[{"trd":[[11,32.91],[11.5,93.25]],"batb":[[0,11.5,2],[1,11,10.66]],"ltp":11.0,"tv":572.64,"id":24420205}],"tv":6733.24}]}
{"op":"mcm","clk":"993656055","pt":1580544990647,"mc":[{"id":"1.168130661","rc":[{"trd":[[19,10.18]],"batb":[[0,19,2.91]],"ltp":19.0,"tv":287.52,"id":24707172}],"tv":6743.42}]}
{"op":"mcm","clk":"993659445","pt":1580545020603,"mc":[{"id":"1.168130661","rc":[{"trd":[[2.66,177.95]],"batl":[[0,2.68,4.48],[1,2.7,27.96],[2,2.72,402]],"ltp":2.66,"tv":2620.34,"id":26314798}],"tv":6747.42}]}
{"op":"mcm","clk":"993659536","pt":1580545021639,"mc":[{"id":"1.168130661","rc":[{"batb":[[1,2.62,14.82]],"ltp":2.66,"tv":2620.34,"id":26314798}]}]}
{"op":"mcm","clk":"993660142","pt":1580545026628,"mc":[{"id":"1.168130661","rc":[{"batb":[[2,2.66,5]],"ltp":2.78,"tv":2716.93,"id":25238892}]}]}
{"op":"mcm","clk":"993660251","pt":1580545027722,"mc":[{"id":"1.168130661","rc":[{"batb":[[0,2.72,6.34],[1,2.7,9.96],[2,2.68,8.81]],"ltp":2.78,"tv":2716.93,"id":25238892},{"batb":[[0,12,3.64],[1,11.5,2],[2,11,10.66]],"ltp":11.0,"tv":572.64,"id":24420205}]}]}
{"op":"mcm","clk":"993660323","pt":1580545028501,"mc":[{"id":"1.168130661","rc":[{"batb":[[0,12,5.64]],"ltp":11.0,"tv":572.64,"id":24420205}]}]}
{"op":"mcm","clk":"993660360","pt":1580545028916,"mc":[{"id":"1.168130661","rc":[{"trd":[[2.68,203.78]],"batl":[[0,2.68,1.48]],"ltp":2.68,"tv":2626.34,"id":26314798}],"tv":6753.42}]}
{"op":"mcm","clk":"993660593","pt":1580545031610,"mc":[{"id":"1.168130661","rc":[{"batb":[[1,2.7,14.96]],"ltp":2.78,"tv":2716.93,"id":25238892},{"batb":[[2,11,14.51]],"ltp":11.0,"tv":572.64,"id":24420205},{"trd":[[2.68,206.74],[2.7,480.43]],"batb":[[1,2.62,11.82]],"batl":[[0,2.68,2.04],[1,2.7,26.83]],"ltp":2.7,"tv":2631.56,"id":26314798}],"tv":6758.64}]}
{"op":"mcm","clk":"993660667","pt":1580545032644,"mc":[{"id":"1.168130661","rc":[{"batl":[[0,2.68,4.04]],"ltp":2.7,"tv":2631.56,"id":26314798}]}]}
{"op":"mcm","clk":"993661525","pt":1580545042667,"mc":[{"id":"1.168130661","rc":[{"batb":[[0,34,2.12],[1,32,2.19],[2,30,3.57]],"ltp":30.0,"tv":86.6,"id":25545675},{"batb":[[1,2.62,14.82]],"batl":[[0,2.66,13.25],[1,2.68,4.04],[2,2.7,26.83]],"ltp":2.7,"tv":2631.56,"id":26314798}]}]}
{"op":"mcm","clk":"993661624","pt":1580545043654,"mc":[{"id":"1.168130661","rc":[{"batb":[[0,32,2.19],[1,30,3.57],[2,29,4.3]],"ltp":30.0,"tv":86.6,"id":25545675},{"trd":[[2.66,188.35]],"batl":[[0,2.66,8.05]],"ltp":2.66,"tv":2641.96,"id":26314798}],"tv":6769.04}]}
{"op":"mcm","clk":"993662051","pt":1580545048561,"mc":[{"id":"1.168130661","rc":[{"batb":[[0,2.64,17.24]],"ltp":2.66,"tv":2641.96,"id":26314798}]}]}
{"op":"mcm","clk":"993662265","pt":1580545050632,"mc":[{"id":"1.168130661","rc":[{"batl":[[0,2.66,16.45]],"ltp":2.66,"tv":2641.96,"id":26314798}]}]}
{"op":"mcm","clk":"993663638","pt":1580545063712,"mc":[{"id":"1.168130661","rc":[{"batl":[[0,2.66,8.05]],"ltp":2.66,"tv":2641.96,"id":26314798}]}]}
{"op":"mcm","clk":"993663916","pt":1580545066720,"mc":[{"id":"1.168130661","rc":[{"batb":[[0,2.64,8.84]],"ltp":2.66,"tv":2641.96,"id":26314798}]}]}
{"op":"mcm","clk":"993665954","pt":1580545086681,"mc":[{"id":"1.168130661","rc":[{"batb":[[0,34,2.25],[1,32,2.19],[2,30,3.57]],"ltp":30.0,"tv":86.6,"id":25545675}]}]}
{"op":"mcm","clk":"993666028","pt":1580545087462,"mc":[{"id":"1.168130661","rc":[{"batb":[[0,32,2.19],[1,30,3.57],[2,29,4.3]],"ltp":30.0,"tv":86.6,"id":25545675}]}]}
{"op":"mcm","clk":"993667927","pt":1580545108705,"mc":[{"id":"1.168130661","rc":[{"batl":[[0,13,3.38],[1,13.5,5.09],[2,14,2.52]],"ltp":11.0,"tv":572.64,"id":24420205}]}]}
{"op":"mcm","clk":"993669046","pt":1580545122669,"mc":[{"id":"1.168130661","rc":[{"batb":[[0,34,2.23],[1,32,2.19],[2,30,3.57]],"ltp":30.0,"tv":86.6,"id":25545675}]}]}
{"op":"mcm","clk":"993669097","pt":1580545123492,"mc":[{"id":"1.168130661","rc":[{"batb":[[0,32,2.19],[1,30,3.57],[2,29,4.3]],"ltp":30.0,"tv":86.6,"id":25545675}]}]}
{"op":"mcm","clk":"993670433","pt":1580545140620,"mc":[{"id":"1.168130661","rc":[{"trd":[[19,14.18]],"batb":[[0,18.5,6.55],[1,18,7.98],[2,17.5,5]],"ltp":19.0,"tv":291.52,"id":24707172},{"trd":[[13,6.76]],"batl":[[0,13,2]],"ltp":13.0,"tv":579.4,"id":24420205}],"tv":6779.8}]}
{"op":"mcm","clk":"993670488","pt":1580545141389,"mc":[{"id":"1.168130661","rc":[{"batb":[[0,18.5,4.55]],"batl":[[0,19.5,3.76]],"ltp":19.0,"tv":291.52,"id":24707172}]}]}
{"op":"mcm","clk":"993671495","pt":1580545154454,"mc":[{"id":"1.168130661","rc":[{"batl":[[0,13,3.23]],"ltp":13.0,"tv":579.4,"id":24420205}]}]}
{"op":"mcm","clk":"993673118","pt":1580545175270,"mc":[{"id":"1.168130661","rc":[{"batb":[[1,30,1.57]],"ltp":30.0,"tv":86.6,"id":25545675}]}]}
{"op":"mcm","clk":"993674726","pt":1580545196180,"mc":[{"id":"1.168130661","rc":[{"batl":[[1,13.5,3]],"ltp":13.0,"tv":579.4,"id":24420205}]}]}
{"op":"mcm","clk":"993675154","pt":1580545201699,"mc":[{"id":"1.168130661","rc":[{"trd":[[19.5,3.52]],"batb":[[0,19,4.91],[1,18.5,3.64],[2,18,7.98]],"batl":[[0,20,10.25],[1,21,16.12],[2,22,1.76]],"ltp":19.5,"tv":295.04,"id":24707172},{"trd":[[13,9.21]],"batl":[[0,13.5,3],[1,14,2.52],[2,15,2]],"ltp":13.0,"tv":581.85,"id":24420205}],"tv":6785.77}]}
{"op":"mcm","clk":"993677723","pt":1580545234452,"mc":[{"id":"1.168130661","rc":[{"trd":[[2.72,159.41]],"batb":[[0,2.7,9.96],[1,2.68,8.81],[2,2.66,5]],"batl":[[0,2.72,1.16],[1,2.74,2.18],[2,2.76,2.32]],"ltp":2.72,"tv":2729.6,"id":25238892},{"trd":[[19,23.76]],"batb":[[0,18.5,3.76],[1,18,7.98],[2,17.5,5]],"ltp":19.0,"tv":304.62,"id":24707172},{"trd":[[12,48.2]],"batb":[[0,12,3.64]],"ltp":12.0,"tv":585.85,"id":24420205},{"trd":[[2.64,291.34]],"batb":[[0,2.62,14.82],[1,2.6,123.23],[2,2.58,19.63]],"ltp":2.64,"tv":2659.64,"id":26314798},{"trd":[[9.8,73.14]],"batb":[[0,9.8,33.57]],"ltp":9.8,"tv":468.37,"id":420}],"tv":6834.7}]}
{"op":"mcm","clk":"993677808","pt":1580545235618,"mc":[{"id":"1.168130661","rc":[{"batb":[[1,18,11.09]],"ltp":19.0,"tv":304.62,"id":24707172},{"batb":[[0,12.5,1.38],[1,12,3.64],[2,11.5,2]],"ltp":12.0,"tv":585.85,"id":24420205},{"batb":[[1,2.6,128.86]],"ltp":2.64,"tv":2659.64,"id":26314798},{"batb":[[0,10,1.72],[1,9.8,33.57],[2,9.6,23.83]],"ltp":9.8,"tv":468.37,"id":420}]}]}
{"op":"mcm","clk":"993677908","pt":1580545236686,"mc":[{"id":"1.168130661","rc":[{"batb":[[1,18,7.98]],"ltp":19.0,"tv":304.62,"id":24707172},{"batb":[[1,12,1.64],[2,11,10.21]],"batl":[[0,13,3.87],[1,13.5,3],[2,14,2.52]],"ltp":12.0,"tv":585.85,"id":24420205},{"batb":[[2,9.2,14.18]],"ltp":9.8,"tv":468.37,"id":420}]}]}
{"op":"mcm","clk":"993678087","pt":1580545238655,"mc":[{"id":"1.168130661","rc":[{"trd":[[18.5,19.09],[19,24]],"batb":[[0,18.5,1.9],[1,18,5.98]],"batl":[[0,19.5,2.2],[1,20,10.25],[2,21,16.12]],"ltp":18.5,"tv":313.95,"id":24707172},{"batb":[[2,11,6.36]],"ltp":12.0,"tv":585.85,"id":24420205},{"batb":[[0,2.64,2.21],[1,2.62,14.82],[2,2.6,128.86]],"batl":[[1,2.68,2]],"ltp":2.64,"tv":2659.64,"id":26314798}],"tv":6844.03}]}
{"op":"mcm","clk":"993678184","pt":1580545239648,"mc":[{"id":"1.168130661","rc":[{"batb":[[2,17.5,7.87]],"ltp":18.5,"tv":313.95,"id":24707172}]}]}
{"op":"mcm","clk":"993678346","pt":1580545241661,"mc":[{"id":"1.168130661","rc":[{"batb":[[1,18,7.98],[2,17.5,5]],"ltp":18.5,"tv":313.95,"id":24707172},{"batb":[[2,2.6,123.23]],"ltp":2.64,"tv":2659.64,"id":26314798}]}]}
{"op":"mcm","clk":"993678671","pt":1580545245558,"mc":[{"id":"1.168130661","rc":[{"batb":[[1,9.8,30.57],[2,9.4,3]],"ltp":9.8,"tv":468.37,"id":420}]}]}
{"op":"mcm","clk":"993680014","pt":1580545264639,"mc":[{"id":"1.168130661","rc":[{"batb":[[1,30,2.14]],"ltp":30.0,"tv":86.6,"id":25545675}]}]}
{"op":"mcm","clk":"993681205","pt":1580545280637,"mc":[{"id":"1.168130661","rc":[{"trd":[[13,15.93]],"batl":[[0,13.5,3.51],[1,14,2.52],[2,15,2]],"ltp":13.0,"tv":592.57,"id":24420205}],"tv":6850.75}]}
{"op":"mcm","clk":"993681224","pt":1580545280942,"mc":[{"id":"1.168130661","rc":[{"trd":[[13,16.95]],"batl":[[0,13.5,3]],"ltp":13.0,"tv":593.59,"id":24420205}],"tv":6851.77}]}
{"op":"mcm","clk":"993684810","pt":1580545326696,"mc":[{"id":"1.168130661","rc":[{"batb":[[2,2.6,121.23]],"ltp":2.64,"tv":2659.64,"id":26314798}]}]}
{"op":"mcm","clk":"993684891","pt":1580545327630,"mc":[{"id":"1.168130661","rc":[{"batb":[[0,2.64,4.21]],"ltp":2.64,"tv":2659.64,"id":26314798}]}]}
{"op":"mcm","clk":"993685815","pt":1580545337537,"mc":[{"id":"1.168130661","rc":[{"batb":[[0,2.64,4]],"batl":[[1,2.68,4]],"ltp":2.64,"tv":2659.64,"id":26314798}]}]}
{"op":"mcm","clk":"993697433","pt":1580545357657,"mc":[{"id":"1.168130661","rc":[{"trd":[[2.7,104.02]],"batb":[[0,2.7,8.8]],"batl":[[0,2.76,2.32],[1,2.78,20.7],[2,2.86,87]],"ltp":2.7,"tv":2731.92,"id":25238892}],"tv":6854.09}]}
{"op":"mcm","clk":"993697885","pt":1580545362674,"mc":[{"id":"1.168130661","rc":[{"batl":[[2,2.9,1.18]],"ltp":2.7,"tv":2731.92,"id":25238892}]}]}
{"op":"mcm","clk":"993697998","pt":1580545363666,"mc":[{"id":"1.168130661","rc":[{"batb":[[0,2.7,12.8],[1,2.68,5.29]],"ltp":2.7,"tv":2731.92,"id":25238892}]}]}
{"op":"mcm","clk":"993700480","pt":1580545392713,"mc":[{"id":"1.168130661","rc":[{"batb":[[1,2.68,9.73]],"ltp":2.7,"tv":2731.92,"id":25238892}]}]}
{"op":"mcm","clk":"993702521","pt":1580545418448,"mc":[{"id":"1.168130661","rc":[{"batl":[[2,21,14.12]],"ltp":18.5,"tv":313.95,"id":24707172}]}]}
{"op":"mcm","clk":"993703392","pt":1580545428631,"mc":[{"id":"1.168130661","rc":[{"trd":[[2.66,192.35]],"batl":[[0,2.66,6.05]],"ltp":2.66,"tv":2663.64,"id":26314798}],"tv":6858.09}]}
{"op":"mcm","clk":"993703916","pt":1580545435663,"mc":[{"id":"1.168130661","rc":[{"trd":[[2.66,204.44]],"batb":[[0,2.66,5.58],[1,2.64,2],[2,2.62,14.82]],"batl":[[0,2.68,4],[1,2.7,26.83],[2,2.72,402]],"ltp":2.66,"tv":2675.74,"id":26314798}],"tv":6870.19}]}
{"op":"mcm","clk":"993704088","pt":1580545437666,"mc":[{"id":"1.168130661","rc":[{"batb":[[0,2.66,7.58]],"ltp":2.66,"tv":2675.74,"id":26314798}]}]}
{"op":"mcm","clk":"993704179","pt":1580545438652,"mc":[{"id":"1.168130661","rc":[{"batb":[[2,2.62,17.13]],"ltp":2.66,"tv":2675.74,"id":26314798}]}]}
{"op":"mcm","clk":"993704913","pt":1580545446557,"mc":[{"id":"1.168130661","rc":[{"trd":[[2.68,210.74]],"batb":[[1,2.62,17.13],[2,2.6,121.23]],"batl":[[0,2.68,2]],"ltp":2.68,"tv":2679.74,"id":26314798}],"tv":6874.19}]}
{"op":"mcm","clk":"993705124","pt":1580545448633,"mc":[{"id":"1.168130661","rc":[{"trd":[[2.7,116.44]],"batb":[[0,2.7,6.59]],"ltp":2.7,"tv":2744.34,"id":25238892},{"batl":[[0,2.7,26.83],[1,2.72,402],[2,2.74,79.55]],"ltp":2.68,"tv":2679.74,"id":26314798}],"tv":6886.61}]}
{"op":"mcm","clk":"993705516","pt":1580545452698,"mc":[{"id":"1.168130661","rc":[{"batl":[[0,2.7,46.83]],"ltp":2.68,"tv":2679.74,"id":26314798}]}]}
{"op":"mcm","clk":"993705604","pt":1580545453524,"mc":[{"id":"1.168130661","rc":[{"batb":[[0,2.7,2.59],[1,2.68,5.29]],"ltp":2.7,"tv":2744.34,"id":25238892},{"batb":[[1,2.64,2],[2,2.62,17.13]],"ltp":2.68,"tv":2679.74,"id":26314798}]}]}
{"op":"mcm","clk":"993707130","pt":1580545470686,"mc":[{"id":"1.168130661","rc":[{"batb":[[0,2.7,6.75]],"ltp":2.7,"tv":2744.34,"id":25238892},{"trd":[[12,51.48],[12.5,34.76]],"batb":[[0,11.5,8.84],[1,11,6.36],[2,10.5,15]],"batl":[[0,13,2.12],[1,13.5,3],[2,14,2.52]],"ltp":12.0,"tv":599.63,"id":24420205}],"tv":6892.64}]}
{"op":"mcm","clk":"993707219","pt":1580545471682,"mc":[{"id":"1.168130661","rc":[{"batb":[[0,2.66,5.58]],"ltp":2.68,"tv":2679.74,"id":26314798}]}]}
{"op":"mcm","clk":"993707314","pt":1580545472675,"mc":[{"id":"1.168130661","rc":[{"batb":[[0,2.68,2],[1,2.66,5.58],[2,2.64,4]],"ltp":2.68,"tv":2679.74,"id":26314798}]}]}
{"op":"mcm","clk":"993707634","pt":1580545475690,"mc":[{"id":"1.168130661","rc":[{"batb":[[0,2.72,18.83],[1,2.7,6.75],[2,2.68,5.29]],"ltp":2.7,"tv":2744.34,"id":25238892}]}]}
{"op":"mcm","clk":"993707837","pt":1580545477711,"mc":[{"id":"1.168130661","rc":[{"batb":[[1,2.7,13.16]],"ltp":2.7,"tv":2744.34,"id":25238892}]}]}
{"op":"mcm","clk":"993708498","pt":1580545484641,"mc":[{"id":"1.168130661","rc":[{"batl":[[0,12.5,2.66],[1,13,2.24],[2,13.5,3]],"ltp":12.0,"tv":599.63,"id":24420205}]}]}
{"op":"mcm","clk":"993709379","pt":1580545495655,"mc":[{"id":"1.168130661","rc":[{"trd":[[2.68,214.74]],"batb":[[0,2.66,5.58],[1,2.64,4],[2,2.62,14.82]],"batl":[[0,2.68,3],[1,2.7,46.83],[2,2.72,402]],"ltp":2.68,"tv":2683.74,"id":26314798}],"tv":6896.64}]}
{"op":"mcm","clk":"993709442","pt":1580545496650,"mc":[{"id":"1.168130661","rc":[{"batb":[[1,2.64,2]],"ltp":2.68,"tv":2683.74,"id":26314798}]}]}
{"op":"mcm","clk":"993709521","pt":1580545497637,"mc":[{"id":"1.168130661","rc":[{"batb":[[2,2.62,17.13]],"ltp":2.68,"tv":2683.74,"id":26314798}]}]}
{"op":"mcm","clk":"993710423","pt":1580545508563,"mc":[{"id":"1.168130661","rc":[{"batl":[[0,12.5,5.66],[2,14,2.52]],"ltp":12.0,"tv":599.63,"id":24420205}]}]}
{"op":"mcm","clk":"993710991","pt":1580545514691,"mc":[{"id":"1.168130661","rc":[{"batl":[[0,12.5,3]],"ltp":12.0,"tv":599.63,"id":24420205}]}]}
{"op":"mcm","clk":"993711075","pt":1580545515685,"mc":[{"id":"1.168130661","rc":[{"batb":[[0,2.72,23.83]],"batl":[[0,2.78,22.7],[1,2.9,1.18],[2,2.96,7.02]],"ltp":2.7,"tv":2744.34,"id":25238892},{"batl":[[0,12,2.53],[1,12.5,3],[2,13,2.24]],"ltp":12.0,"tv":599.63,"id":24420205}]}]}
{"op":"mcm","clk":"993712700","pt":1580545534708,"mc":[{"id":"1.168130661","rc":[{"batl":[[2,2.96,36]],"ltp":2.7,"tv":2744.34,"id":25238892},{"batl":[[1,12.5,5]],"ltp":12.0,"tv":599.63,"id":24420205},{"trd":[[2.66,215.6]],"batb":[[0,2.64,2],[1,2.62,17.13],[2,2.6,121.23]],"batl":[[0,2.66,2.42],[1,2.68,5],[2,2.7,46.83]],"ltp":2.66,"tv":2694.9,"id":26314798}],"tv":6907.8}]}
{"op":"mcm","clk":"993712897","pt":1580545536610,"mc":[{"id":"1.168130661","rc":[{"batl":[[2,2.96,50.49]],"ltp":2.7,"tv":2744.34,"id":25238892},{"batb":[[1,2.62,14.82]],"ltp":2.66,"tv":2694.9,"id":26314798}]}]}
{"op":"mcm","clk":"993713157","pt":1580545539521,"mc":[{"id":"1.168130661","rc":[{"batb":[[0,18.5,2.83]],"ltp":18.5,"tv":313.95,"id":24707172}]}]}
{"op":"mcm","clk":"993713239","pt":1580545540613,"mc":[{"id":"1.168130661","rc":[{"trd":[[2.72,175.41]],"batb":[[0,2.72,10.83]],"ltp":2.72,"tv":2760.34,"id":25238892}],"tv":6923.8}]}
{"op":"mcm","clk":"993713341","pt":1580545541704,"mc":[{"id":"1.168130661","rc":[{"batl":[[0,2.76,2.22],[1,2.78,22.7],[2,2.9,1.18]],"ltp":2.72,"tv":2760.34,"id":25238892},{"batb":[[0,2.64,5.22]],"batl":[[2,2.7,26.83]],"ltp":2.66,"tv":2694.9,"id":26314798},{"batb":[[1,9.8,34.35]],"ltp":9.8,"tv":468.37,"id":420}]}]}
{"op":"mcm","clk":"993715147","pt":1580545562222,"mc":[{"id":"1.168130661","rc":[{"batb":[[0,19,3],[1,18.5,2.83],[2,18,7.98]],"ltp":18.5,"tv":313.95,"id":24707172}]}]}
{"op":"mcm","clk":"993715910","pt":1580545571718,"mc":[{"id":"1.168130661","rc":[{"trd":[[12,56.54]],"batb":[[0,12,5.87],[1,11.5,8.84],[2,11,6.36]],"batl":[[0,12.5,5],[1,13,2.24],[2,14,2.52]],"ltp":12.0,"tv":604.69,"id":24420205}],"tv":6928.86}]}
{"op":"mcm","clk":"993715979","pt":1580545572545,"mc":[{"id":"1.168130661","rc":[{"trd":[[12,64.14]],"batb":[[0,12,4.08]],"batl":[[0,12.5,3]],"ltp":12.0,"tv":612.29,"id":24420205},{"batb":[[0,2.64,2]],"ltp":2.66,"tv":2694.9,"id":26314798}],"tv":6936.46}]}
{"op":"mcm","clk":"993716404","pt":1580545577675,"mc":[{"id":"1.168130661","rc":[{"batb":[[0,12,2]],"ltp":12.0,"tv":612.29,"id":24420205}]}]}
{"op":"mcm","clk":"993717878","pt":1580545593697,"mc":[{"id":"1.168130661","rc":[{"batl":[[1,14,2.52],[2,15,2]],"ltp":12.0,"tv":612.29,"id":24420205}]}]}
{"op":"mcm","clk":"993718515","pt":1580545601618,"mc":[{"id":"1.168130661","rc":[{"batb":[[2,11,8.86]],"ltp":12.0,"tv":612.29,"id":24420205}]}]}
{"op":"mcm","clk":"993720509","pt":1580545624716,"mc":[{"id":"1.168130661","rc":[{"batl":[[0,14,2.52],[1,15,2],[2,17.5,14]],"ltp":12.0,"tv":612.29,"id":24420205}]}]}
{"op":"mcm","clk":"993720613","pt":1580545625707,"mc":[{"id":"1.168130661","rc":[{"batb":[[0,2.74,6.28],[1,2.72,10.83],[2,2.7,13.16]],"ltp":2.72,"tv":2760.34,"id":25238892},{"batl":[[0,13.5,3],[1,14,2.52],[2,15,2]],"ltp":12.0,"tv":612.29,"id":24420205}]}]}
{"op":"mcm","clk":"993720691","pt":1580545626636,"mc":[{"id":"1.168130661","rc":[{"batb":[[2,2.7,6.75]],"ltp":2.72,"tv":2760.34,"id":25238892}]}]}
{"op":"mcm","clk":"993721310","pt":1580545633624,"mc":[{"id":"1.168130661","rc":[{"batb":[[1,2.72,14.83]],"ltp":2.72,"tv":2760.34,"id":25238892},{"trd":[[18.5,23.09],[19,30]],"batb":[[0,18,6.81],[1,17.5,8.18],[2,17,7.36]],"ltp":18.5,"tv":323.95,"id":24707172}],"tv":6946.46}]}
{"op":"mcm","clk":"993721389","pt":1580545634708,"mc":[{"id":"1.168130661","rc":[{"trd":[[2.76,289.39]],"batb":[[0,2.74,7.06]],"batl":[[0,2.78,22.7],[1,2.9,1.18],[2,2.96,7.02]],"ltp":2.76,"tv":2764.78,"id":25238892}],"tv":6950.9}]}
{"op":"mcm","clk":"993721482","pt":1580545635649,"mc":[{"id":"1.168130661","rc":[{"batb":[[1,17.5,5]],"ltp":18.5,"tv":323.95,"id":24707172}]}]}
{"op":"mcm","clk":"993723837","pt":1580545665539,"mc":[{"id":"1.168130661","rc":[{"batl":[[2,2.96,36]],"ltp":2.76,"tv":2764.78,"id":25238892}]}]}
{"op":"mcm","clk":"993724278","pt":1580545671666,"mc":[{"id":"1.168130661","rc":[{"batl":[[2,2.96,50.49]],"ltp":2.76,"tv":2764.78,"id":25238892},{"trd":[[12,64.24],[13.5,7.74]],"batb":[[0,12,1.95],[1,11.5,2.16]],"batl":[[0,14,2.52],[1,15,2],[2,17,5.79]],"ltp":12.0,"tv":620.12,"id":24420205}],"tv":6958.74}]}
{"op":"mcm","clk":"993724339","pt":1580545672585,"mc":[{"id":"1.168130661","rc":[{"batb":[[0,12,6.49]],"ltp":12.0,"tv":620.12,"id":24420205}]}]}
{"op":"mcm","clk":"993724414","pt":1580545673667,"mc":[{"id":"1.168130661","rc":[{"batb":[[0,2.74,6.28]],"ltp":2.76,"tv":2764.78,"id":25238892},{"trd":[[12.5,38.44]],"batb":[[0,12,6.94]],"batl":[[2,17.5,14]],"ltp":12.5,"tv":623.8,"id":24420205}],"tv":6962.42}]}
{"op":"mcm","clk":"993724494","pt":1580545674650,"mc":[{"id":"1.168130661","rc":[{"trd":[[12,66.58]],"batb":[[0,12,7.32]],"ltp":12.0,"tv":626.14,"id":24420205}],"tv":6964.76}]}
{"op":"mcm","clk":"993724776","pt":1580545678656,"mc":[{"id":"1.168130661","rc":[{"trd":[[12,75.28]],"batb":[[0,12,2.97]],"ltp":12.0,"tv":634.84,"id":24420205}],"tv":6973.46}]}
{"op":"mcm","clk":"993725932","pt":1580545693703,"mc":[{"id":"1.168130661","rc":[{"batl":[[2,20,20.29]],"ltp":12.0,"tv":634.84,"id":24420205}]}]}
{"op":"mcm","clk":"993727435","pt":1580545712622,"mc":[{"id":"1.168130661","rc":[{"batl":[[1,14.5,5],[2,15,2]],"ltp":12.0,"tv":634.84,"id":24420205}]}]}
{"op":"mcm","clk":"993741377","pt":1580545880378,"mc":[{"id":"1.168130661","rc":[{"trd":[[18,17.06],[18.5,24.75]],"batb":[[0,17.5,5],[1,17,12],[2,16,5]],"batl":[[0,18,2.19],[1,19.5,2.2],[2,20,10.25]],"ltp":18.0,"tv":337.57,"id":24707172}],"tv":6987.08}]}
{"op":"mcm","clk":"993741611","pt":1580545883480,"mc":[{"id":"1.168130661","rc":[{"batb":[[1,17,7.36]],"ltp":18.0,"tv":337.57,"id":24707172}]}]}
{"op":"mcm","clk":"993744399","pt":1580545918639,"mc":[{"id":"1.168130661","rc":[{"batb":[[0,12.5,3.48],[1,12,2.97],[2,11.5,2.16]],"ltp":12.0,"tv":634.84,"id":24420205}]}]}
{"op":"mcm","clk":"993749727","pt":1580545977723,"mc":[{"id":"1.168130661","rc":[{"trd":[[2.64,295.34]],"batb":[[0,2.62,14.82],[1,2.6,121.23],[2,2.58,19.63]],"batl":[[2,2.7,15.86]],"ltp":2.64,"tv":2698.9,"id":26314798}],"tv":6991.08}]}
{"op":"mcm","clk":"993752202","pt":1580546007168,"mc":[{"id":"1.168130661","rc":[{"batb":[[1,2.6,126.36]],"ltp":2.64,"tv":2698.9,"id":26314798}]}]}
{"op":"mcm","clk":"993753365","pt":1580546021565,"mc":[{"id":"1.168130661","rc":[{"trd":[[2.62,367.27]],"batb":[[0,2.62,11.89]],"ltp":2.62,"tv":2704.76,"id":26314798}],"tv":6996.94}]}
{"op":"mcm","clk":"993754763","pt":1580546038623,"mc":[{"id":"1.168130661","rc":[{"batl":[[0,2.64,2],[1,2.66,2.42],[2,2.68,5]],"ltp":2.62,"tv":2704.76,"id":26314798}]}]}
{"op":"mcm","clk":"993760576","pt":1580546107717,"mc":[{"id":"1.168130661","rc":[{"batb":[[2,16,13.52]],"ltp":18.0,"tv":337.57,"id":24707172},{"batb":[[0,2.62,90.84],[1,2.6,56.42]],"ltp":2.62,"tv":2704.76,"id":26314798}]}]}
{"op":"mcm","clk":"993760920","pt":1580546111690,"mc":[{"id":"1.168130661","rc":[{"batb":[[1,2.6,31.42]],"ltp":2.62,"tv":2704.76,"id":26314798}]}]}
{"op":"mcm","clk":"993761424","pt":1580546117714,"mc":[{"id":"1.168130661","rc":[{"trd":[[2.64,299.34]],"batb":[[0,2.64,6.53],[1,2.62,90.84],[2,2.6,40.33]],"batl":[[0,2.66,2.42],[1,2.68,6.97],[2,2.7,15.86]],"ltp":2.64,"tv":2708.76,"id":26314798}],"tv":7000.94}]}
{"op":"mcm","clk":"993761525","pt":1580546118702,"mc":[{"id":"1.168130661","rc":[{"batb":[[2,2.6,31.42]],"ltp":2.64,"tv":2708.76,"id":26314798}]}]}
{"op":"mcm","clk":"993763509","pt":1580546142624,"mc":[{"id":"1.168130661","rc":[{"trd":[[17.5,14.12]],"batb":[[0,17,7.36],[1,16,13.52],[2,14.5,3]],"ltp":17.5,"tv":347.57,"id":24707172}],"tv":7010.94}]}
{"op":"mcm","clk":"993763584","pt":1580546143657,"mc":[{"id":"1.168130661","rc":[{"batb":[[0,17,9.36],[1,16.5,4.08],[2,16,13.52]],"ltp":17.5,"tv":347.57,"id":24707172}]}]}
{"op":"mcm","clk":"993764430","pt":1580546154450,"mc":[{"id":"1.168130661","rc":[{"trd":[[2.74,204.81]],"batb":[[0,2.72,11.12],[1,2.7,10.23],[2,2.68,5.29]],"batl":[[0,2.76,2.29],[1,2.78,22.7],[2,2.9,1.18]],"ltp":2.74,"tv":2776.78,"id":25238892},{"batb":[[1,16,13.52],[2,14.5,3]],"ltp":17.5,"tv":347.57,"id":24707172},{"batb":[[0,2.64,8.53]],"ltp":2.64,"tv":2708.76,"id":26314798}],"tv":7022.94}]}
{"op":"mcm","clk":"993764541","pt":1580546155641,"mc":[{"id":"1.168130661","marketDefinition":{"bspMarket":true,"turnInPlayEnabled":true,"persistenceEnabled":true,"marketBaseRate":5.0,"eventId":"29678694","eventTypeId":"7","numberOfWinners":1,"bettingType":"ODDS","marketType":"WIN","marketTime":"2020-02-01T12:35:00.000Z","suspendTime":"2020-02-01T12:35:00.000Z","bspReconciled":false,"complete":true,"inPlay":false,"crossMatching":true,"runnersVoidable":false,"numberOfActiveRunners":6,"betDelay":0,"status":"OPEN","runners":[{"adjustmentFactor":33.12,"status":"ACTIVE","sortPriority":1,"id":26314798,"name":"Ayr Harbour"},{"adjustmentFactor":30.53,"status":"ACTIVE","sortPriority":2,"id":25238892,"name":"Phuket Power"},{"adjustmentFactor":14.91,"status":"ACTIVE","sortPriority":3,"id":420,"name":"Barking Mad"},{"adjustmentFactor":8.45,"status":"ACTIVE","sortPriority":4,"id":24420205,"name":"Rodney Le Roc"},{"adjustmentFactor":7.01,"status":"ACTIVE","sortPriority":5,"id":24707172,"name":"Thomas Lanfiere"},{"adjustmentFactor":5.95,"status":"ACTIVE","sortPriority":6,"id":25545675,"name":"Gift Of Youth"}],"regulators":["MR_INT"],"venue":"Lingfield","countryCode":"GB","discountAllowed":true,"timezone":"Europe/London","openDate":"2020-02-01T12:35:00.000Z","version":3142902892,"name":"7f Hcap","eventName":"Ling  1st Feb"},"rc":[{"batb":[[0,13,1.33],[1,12.5,3.48],[2,12,2.97]],"ltp":12.0,"tv":634.84,"id":24420205}]}]}
{"op":"mcm","clk":"993765002","pt":1580546160666,"mc":[{"id":"1.168130661","rc":[{"batb":[[1,16,18.7]],"ltp":17.5,"tv":347.57,"id":24707172}]}]}
{"op":"mcm","clk":"993766246","pt":1580546174602,"mc":[{"id":"1.168130661","rc":[{"batb":[[0,2.64,6.53]],"ltp":2.64,"tv":2708.76,"id":26314798}]}]}
{"op":"mcm","clk":"993766376","pt":1580546176200,"mc":[{"id":"1.168130661","rc":[{"trd":[[2.72,196.83],[2.74,205.38]],"batb":[[0,2.7,6.19],[1,2.68,5.29],[2,2.64,26.5]],"ltp":2.72,"tv":2798.78,"id":25238892}],"tv":7044.94}]}
{"op":"mcm","clk":"993766469","pt":1580546177389,"mc":[{"id":"1.168130661","rc":[{"batb":[[0,2.7,7.71]],"ltp":2.72,"tv":2798.78,"id":25238892}]}]}
{"op":"mcm","clk":"993766894","pt":1580546182711,"mc":[{"id":"1.168130661","rc":[{"trd":[[32,19.94]],"batb":[[0,30,2.33],[1,29,4.3],[2,28,5.81]],"ltp":32.0,"tv":90.6,"id":25545675}],"tv":7048.94}]}
{"op":"mcm","clk":"993767998","pt":1580546196705,"mc":[{"id":"1.168130661","rc":[{"trd":[[30,20.18],[32,20.32]],"batb":[[0,29,4.63],[1,28,5.81],[2,27,3.05]],"ltp":30.0,"tv":94.6,"id":25545675}],"tv":7052.94}]}
{"op":"mcm","clk":"993768062","pt":1580546197642,"mc":[{"id":"1.168130661","rc":[{"batb":[[0,2.64,8.53]],"ltp":2.64,"tv":2708.76,"id":26314798}]}]}
{"op":"mcm","clk":"993768679","pt":1580546204435,"mc":[{"id":"1.168130661","rc":[{"batb":[[0,30,2.57],[1,29,4.3],[2,28,5.81]],"ltp":30.0,"tv":94.6,"id":25545675},{"trd":[[2.68,84.38],[2.7,131.62],[2.72,197.07]],"batb":[[0,2.66,14.3],[1,2.64,26.5],[2,2.62,78.95]],"ltp":2.68,"tv":2820.77,"id":25238892}],"tv":7074.94}]}
{"op":"mcm","clk":"993768858","pt":1580546206516,"mc":[{"id":"1.168130661","rc":[{"batb":[[1,2.64,31.45]],"ltp":2.68,"tv":2820.77,"id":25238892}]}]}
{"op":"mcm","clk":"993770226","pt":1580546221541,"mc":[{"id":"1.168130661","rc":[{"trd":[[2.66,55]],"batb":[[0,2.68,3],[1,2.66,3.3],[2,2.64,31.45]],"ltp":2.66,"tv":2842.77,"id":25238892},{"batb":[[0,2.64,10.53],[2,2.6,33.42]],"batl":[[1,2.68,4.97]],"ltp":2.64,"tv":2708.76,"id":26314798}],"tv":7096.94}]}
{"op":"mcm","clk":"993771081","pt":1580546231570,"mc":[{"id":"1.168130661","rc":[{"trd":[[30,24.17]],"batb":[[0,29,4.3],[1,28,5.81],[2,27,3.05]],"ltp":30.0,"tv":98.59,"id":25545675}],"tv":7100.93}]}
{"op":"mcm","clk":"993771399","pt":1580546235361,"mc":[{"id":"1.168130661","rc":[{"batb":[[2,2.64,26.5]],"ltp":2.66,"tv":2842.77,"id":25238892}]}]}
{"op":"mcm","clk":"993771843","pt":1580546240652,"mc":[{"id":"1.168130661","rc":[{"trd":[[17,4.2]],"batb":[[0,17,9.26]],"ltp":17.0,"tv":347.77,"id":24707172}],"tv":7101.13}]}
{"op":"mcm","clk":"993772540","pt":1580546249637,"mc":[{"id":"1.168130661","rc":[{"trd":[[29,23.23]],"batb":[[0,29,2.3]],"ltp":29.0,"tv":102.6,"id":25545675}],"tv":7105.14}]}
{"op":"mcm","clk":"993783862","pt":1580546262684,"mc":[{"id":"1.168130661","rc":[{"batl":[[0,46,2.34],[1,48,7.6],[2,60,1.56]],"ltp":29.0,"tv":102.6,"id":25545675},{"trd":[[2.68,88.38]],"ltp":2.68,"tv":2846.77,"id":25238892}],"tv":7109.14}]}
{"op":"mcm","clk":"993785135","pt":1580546275611,"mc":[{"id":"1.168130661","rc":[{"batl":[[0,46,3.18],[2,65,2.95]],"ltp":29.0,"tv":102.6,"id":25545675}]}]}
{"op":"mcm","clk":"993786377","pt":1580546286719,"mc":[{"id":"1.168130661","rc":[{"batb":[[0,17,10.24]],"ltp":17.0,"tv":347.77,"id":24707172}]}]}
{"op":"mcm","clk":"993790585","pt":1580546335699,"mc":[{"id":"1.168130661","rc":[{"batl":[[0,2.78,22.7],[1,2.9,1.18],[2,2.92,6]],"ltp":2.68,"tv":2846.77,"id":25238892},{"trd":[[12.5,40.85],[13,19.61]],"batb":[[0,12.5,4.27],[1,12,2],[2,11.5,2.16]],"batl":[[0,13.5,4.99],[1,14,2.52],[2,14.5,5]],"ltp":12.5,"tv":639.91,"id":24420205}],"tv":7114.21}]}
{"op":"mcm","clk":"993790655","pt":1580546336682,"mc":[{"id":"1.168130661","rc":[{"batb":[[2,11.5,5.99]],"ltp":12.5,"tv":639.91,"id":24420205}]}]}
{"op":"mcm","clk":"993791749","pt":1580546351695,"mc":[{"id":"1.168130661","rc":[{"batl":[[0,13.5,9.99],[2,15,2]],"ltp":12.5,"tv":639.91,"id":24420205}]}]}
{"op":"mcm","clk":"993792375","pt":1580546359519,"mc":[{"id":"1.168130661","rc":[{"batl":[[1,2.9,3.04]],"ltp":2.68,"tv":2846.77,"id":25238892}]}]}
{"op":"mcm","clk":"993792814","pt":1580546364639,"mc":[{"id":"1.168130661","rc":[{"batl":[[2,2.96,7.02]],"ltp":2.68,"tv":2846.77,"id":25238892}]}]}
{"op":"mcm","clk":"993792951","pt":1580546366405,"mc":[{"id":"1.168130661","rc":[{"batl":[[1,2.86,14.48],[2,2.88,14.48]],"ltp":2.68,"tv":2846.77,"id":25238892}]}]}
{"op":"mcm","clk":"993793411","pt":1580546371640,"mc":[{"id":"1.168130661","rc":[{"batl":[[0,2.76,4],[1,2.78,22.7],[2,2.86,14.48]],"ltp":2.68,"tv":2846.77,"id":25238892}]}]}
{"op":"mcm","clk":"993795490","pt":1580546393680,"mc":[{"id":"1.168130661","rc":[{"batb":[[1,2.66,7.83]],"ltp":2.68,"tv":2846.77,"id":25238892}]}]}
{"op":"mcm","clk":"993795841","pt":1580546396387,"mc":[{"id":"1.168130661","rc":[{"batl":[[2,2.9,3.04]],"ltp":2.68,"tv":2846.77,"id":25238892}]}]}
{"op":"mcm","clk":"993796690","pt":1580546405601,"mc":[{"id":"1.168130661","rc":[{"batl":[[0,2.78,22.7],[1,2.86,3.83],[2,2.88,2.18]],"ltp":2.68,"tv":2846.77,"id":25238892}]}]}
{"op":"mcm","clk":"993797488","pt":1580546414689,"mc":[{"id":"1.168130661","rc":[{"batl":[[1,2.86,23.07]],"ltp":2.68,"tv":2846.77,"id":25238892},{"trd":[[13.5,27.72]],"batl":[[0,14,2.52],[1,15,2],[2,20,20.29]],"ltp":13.5,"tv":659.89,"id":24420205}],"tv":7134.19}]}
{"op":"mcm","clk":"993797645","pt":1580546416515,"mc":[{"id":"1.168130661","rc":[{"trd":[[2.64,309.34]],"batb":[[0,2.64,5.53]],"ltp":2.64,"tv":2718.76,"id":26314798}],"tv":7144.19}]}
{"op":"mcm","clk":"993797866","pt":1580546419723,"mc":[{"id":"1.168130661","rc":[{"batl":[[1,14.5,5],[2,15,2]],"ltp":13.5,"tv":659.89,"id":24420205}]}]}
{"op":"mcm","clk":"993798590","pt":1580546428700,"mc":[{"id":"1.168130661","rc":[{"batl":[[1,2.84,1.9],[2,2.86,23.07]],"ltp":2.68,"tv":2846.77,"id":25238892}]}]}
{"op":"mcm","clk":"993798768","pt":1580546430630,"mc":[{"id":"1.168130661","rc":[{"trd":[[12.5,45.73]],"batb":[[0,12.5,1.83]],"ltp":12.5,"tv":664.77,"id":24420205}],"tv":7149.07}]}
{"op":"mcm","clk":"993798861","pt":1580546431629,"mc":[{"id":"1.168130661","rc":[{"batb":[[0,12,2],[1,11.5,5.99],[2,11,6.36]],"ltp":12.5,"tv":664.77,"id":24420205}]}]}
{"op":"mcm","clk":"993799162","pt":1580546434610,"mc":[{"id":"1.168130661","rc":[{"batl":[[0,44,1.2],[1,46,2.34],[2,48,7.6]],"ltp":29.0,"tv":102.6,"id":25545675}]}]}
{"op":"mcm","clk":"993799226","pt":1580546435441,"mc":[{"id":"1.168130661","rc":[{"batl":[[0,42,2.19],[1,44,1.2],[2,46,2.34]],"ltp":29.0,"tv":102.6,"id":25545675},{"batl":[[2,2.86,37.56]],"ltp":2.68,"tv":2846.77,"id":25238892},{"batb":[[0,11.5,2.16],[1,11,9.77],[2,10.5,10.56]],"ltp":12.5,"tv":664.77,"id":24420205},{"batb":[[2,2.6,28.29]],"ltp":2.64,"tv":2718.76,"id":26314798}]}]}
{"op":"mcm","clk":"993799352","pt":1580546436710,"mc":[{"id":"1.168130661","rc":[{"batb":[[1,11,6.36]],"ltp":12.5,"tv":664.77,"id":24420205}]}]}
{"op":"mcm","clk":"993799861","pt":1580546442666,"mc":[{"id":"1.168130661","rc":[{"batl":[[0,44,1.2],[1,48,7.71],[2,60,3.97]],"ltp":29.0,"tv":102.6,"id":25545675},{"batb":[[0,2.66,7.83],[1,2.64,26.5],[2,2.62,81.01]],"batl":[[0,2.78,20.7]],"ltp":2.68,"tv":2846.77,"id":25238892},{"batb":[[0,17,8.24]],"batl":[[1,20,8.25],[2,21,14.12]],"ltp":17.0,"tv":347.77,"id":24707172},{"batb":[[0,11.5,6.77],[2,10.5,13.21]],"batl":[[0,14,2.88]],"ltp":12.5,"tv":664.77,"id":24420205},{"trd":[[2.64,312.4]],"batb":[[0,2.62,87.84],[1,2.6,26.58],[2,2.58,19.63]],"batl":[[2,2.7,13.86]],"ltp":2.64,"tv":2721.82,"id":26314798},{"batl":[[0,10.5,10.39],[1,11.5,13.73],[2,12,5.75]],"ltp":9.8,"tv":468.37,"id":420}],"tv":7152.12}]}
{"op":"mcm","clk":"993800053","pt":1580546444563,"mc":[{"id":"1.168130661","rc":[{"batl":[[2,65,5.97]],"ltp":29.0,"tv":102.6,"id":25545675},{"batb":[[2,10.5,10.56]],"ltp":12.5,"tv":664.77,"id":24420205},{"batb":[[1,2.6,38.33]],"ltp":2.64,"tv":2721.82,"id":26314798}]}]}
{"op":"mcm","clk":"993800591","pt":1580546450532,"mc":[{"id":"1.168130661","rc":[{"batb":[[0,29,6.14]],"batl":[[0,42,2.27],[1,44,1.2],[2,48,7.71]],"ltp":29.0,"tv":102.6,"id":25545675},{"batb":[[0,2.68,3.27],[1,2.66,7.83],[2,2.64,26.5]],"batl":[[0,2.78,22.7]],"ltp":2.68,"tv":2846.77,"id":25238892},{"batb":[[0,17,10.24]],"ltp":17.0,"tv":347.77,"id":24707172},{"batb":[[0,12,2.27],[1,11.5,6.77],[2,11,6.36]],"ltp":12.5,"tv":664.77,"id":24420205},{"batb":[[0,2.64,4.27],[1,2.62,91.84],[2,2.6,38.33]],"ltp":2.64,"tv":2721.82,"id":26314798},{"batl":[[1,11,3.27],[2,11.5,13.73]],"ltp":9.8,"tv":468.37,"id":420}]}]}
{"op":"mcm","clk":"993801481","pt":1580546460560,"mc":[{"id":"1.168130661","rc":[{"batb":[[0,30,2.6],[1,29,6.14],[2,28,5.81]],"ltp":29.0,"tv":102.6,"id":25545675},{"batb":[[2,2.6,26.58]],"ltp":2.64,"tv":2721.82,"id":26314798}]}]}
{"op":"mcm","clk":"993801845","pt":1580546464694,"mc":[{"id":"1.168130661","rc":[{"batl":[[0,2.76,4],[1,2.78,22.7],[2,2.84,1.9]],"ltp":2.68,"tv":2846.77,"id":25238892}]}]}
{"op":"mcm","clk":"993802282","pt":1580546469696,"mc":[{"id":"1.168130661","rc":[{"batb":[[1,29,2.3]],"ltp":29.0,"tv":102.6,"id":25545675}]}]}
{"op":"mcm","clk":"993804030","pt":1580546487678,"mc":[{"id":"1.168130661","rc":[{"batl":[[2,50,1.06]],"ltp":29.0,"tv":102.6,"id":25545675},{"batl":[[2,2.7,15.86]],"ltp":2.64,"tv":2721.82,"id":26314798},{"batl":[[0,10.5,13.39]],"ltp":9.8,"tv":468.37,"id":420}]}]}
{"op":"mcm","clk":"993804133","pt":1580546488614,"mc":[{"id":"1.168130661","rc":[{"batl":[[0,44,1.2],[1,50,1.06],[2,65,5.02]],"ltp":29.0,"tv":102.6,"id":25545675}]}]}
{"op":"mcm","clk":"993804317","pt":1580546490288,"mc":[{"id":"1.168130661","rc":[{"batl":[[2,65,2]],"ltp":29.0,"tv":102.6,"id":25545675}]}]}
{"op":"mcm","clk":"993804655","pt":1580546493423,"mc":[{"id":"1.168130661","rc":[{"batl":[[0,2.78,22.7],[1,2.84,1.9],[2,2.86,3.83]],"ltp":2.68,"tv":2846.77,"id":25238892}]}]}
{"op":"mcm","clk":"993805536","pt":1580546502614,"mc":[{"id":"1.168130661","rc":[{"batl":[[0,50,1.42],[1,65,2],[2,75,2]],"ltp":29.0,"tv":102.6,"id":25545675}]}]}
{"op":"mcm","clk":"993805613","pt":1580546503237,"mc":[{"id":"1.168130661","rc":[{"batl":[[1,65,2.61]],"ltp":29.0,"tv":102.6,"id":25545675},{"batl":[[0,2.76,2.23],[1,2.78,22.7],[2,2.84,1.9]],"ltp":2.68,"tv":2846.77,"id":25238892}]}]}
{"op":"mcm","clk":"993805830","pt":1580546505521,"mc":[{"id":"1.168130661","rc":[{"batl":[[0,50,1.06]],"ltp":29.0,"tv":102.6,"id":25545675}]}]}
{"op":"mcm","clk":"993808301","pt":1580546531669,"mc":[{"id":"1.168130661","rc":[{"batl":[[0,2.74,4.85],[1,2.76,2.23],[2,2.78,22.7]],"ltp":2.68,"tv":2846.77,"id":25238892}]}]}
{"op":"mcm","clk":"993808398","pt":1580546532660,"mc":[{"id":"1.168130661","rc":[{"batl":[[0,2.76,2.23],[1,2.78,22.7],[2,2.84,1.9]],"ltp":2.68,"tv":2846.77,"id":25238892}]}]}
{"op":"mcm","clk":"993810618","pt":1580546556473,"mc":[{"id":"1.168130661","rc":[{"trd":[[2.66,220.44]],"batb":[[0,2.66,2.73],[1,2.64,4.27],[2,2.62,91.84]],"batl":[[0,2.68,4.97],[1,2.7,15.86],[2,2.72,402]],"ltp":2.66,"tv":2726.66,"id":26314798}],"tv":7156.96}]}
{"op":"mcm","clk":"993811117","pt":1580546561691,"mc":[{"id":"1.168130661","rc":[{"trd":[[9.8,141.69],[10,122.21]],"batb":[[0,9.4,3.07],[1,9.2,14.18],[2,9,18.98]],"batl":[[0,10,6.77],[1,10.5,13.39],[2,11,3.27]],"ltp":9.8,"tv":540.37,"id":420}],"tv":7228.97}]}
{"op":"mcm","clk":"993811261","pt":1580546563146,"mc":[{"id":"1.168130661","rc":[{"batb":[[1,9.2,7.09]],"batl":[[0,10,9.77]],"ltp":9.8,"tv":540.37,"id":420}]}]}
{"op":"mcm","clk":"993812165","pt":1580546572691,"mc":[{"id":"1.168130661","rc":[{"batb":[[0,2.68,9.7]],"ltp":2.68,"tv":2846.77,"id":25238892}]}]}
{"op":"mcm","clk":"993813222","pt":1580546583690,"mc":[{"id":"1.168130661","rc":[{"batb":[[0,9.4,5.07]],"ltp":9.8,"tv":540.37,"id":420}]}]}
{"op":"mcm","clk":"993813388","pt":1580546585631,"mc":[{"id":"1.168130661","rc":[{"batb":[[1,29,2.89]],"ltp":29.0,"tv":102.6,"id":25545675},{"trd":[[9.8,141.83]],"batb":[[0,9.4,5]],"batl":[[0,9.8,1.97],[1,10,9.77],[2,10.5,13.39]],"ltp":9.8,"tv":540.51,"id":420}],"tv":7229.11}]}
{"op":"mcm","clk":"993813582","pt":1580546587715,"mc":[{"id":"1.168130661","rc":[{"batb":[[1,9.2,2.12]],"ltp":9.8,"tv":540.51,"id":420}]}]}
{"op":"mcm","clk":"993814948","pt":1580546603632,"mc":[{"id":"1.168130661","rc":[{"batl":[[1,14.5,7]],"ltp":12.5,"tv":664.77,"id":24420205}]}]}
{"op":"mcm","clk":"993817641","pt":1580546633667,"mc":[{"id":"1.168130661","rc":[{"batl":[[1,14.5,5]],"ltp":12.5,"tv":664.77,"id":24420205},{"trd":[[9.4,10]],"batb":[[0,9.2,2.12],[1,9,18.98],[2,8.8,2.95]],"ltp":9.4,"tv":550.51,"id":420}],"tv":7239.11}]}
{"op":"mcm","clk":"993818092","pt":1580546638678,"mc":[{"id":"1.168130661","rc":[{"batb":[[0,9,18.98],[1,8.8,2.95],[2,8,44]],"ltp":9.4,"tv":550.51,"id":420}]}]}
{"op":"mcm","clk":"993818182","pt":1580546639574,"mc":[{"id":"1.168130661","rc":[{"batb":[[1,8.8,10.13]],"batl":[[0,9.8,3.97]],"ltp":9.4,"tv":550.51,"id":420}]}]}
{"op":"mcm","clk":"993818380","pt":1580546641706,"mc":[{"id":"1.168130661","rc":[{"batb":[[0,30,6.85],[1,29,2.3]],"ltp":29.0,"tv":102.6,"id":25545675},{"batl":[[1,14.5,7]],"ltp":12.5,"tv":664.77,"id":24420205}]}]}
{"op":"mcm","clk":"993818775","pt":1580546645670,"mc":[{"id":"1.168130661","rc":[{"batb":[[0,9,20.98]],"ltp":9.4,"tv":550.51,"id":420}]}]}
{"op":"mcm","clk":"993819741","pt":1580546655588,"mc":[{"id":"1.168130661","rc":[{"batb":[[2,8,13]],"ltp":9.4,"tv":550.51,"id":420}]}]}
{"op":"mcm","clk":"993820864","pt":1580546668619,"mc":[{"id":"1.168130661","rc":[{"batl":[[1,14.5,5]],"ltp":12.5,"tv":664.77,"id":24420205}]}]}
{"op":"mcm","clk":"993821419","pt":1580546674513,"mc":[{"id":"1.168130661","rc":[{"trd":[[18,21.06]],"batb":[[0,17.5,3.16],[1,17,9.26],[2,16,18.7]],"batl":[[0,20,10.44],[1,21,14.12],[2,22,1.76]],"ltp":18.0,"tv":351.77,"id":24707172},{"batl":[[1,14.5,7]],"ltp":12.5,"tv":664.77,"id":24420205}],"tv":7243.11}]}
{"op":"mcm","clk":"993821745","pt":1580546678300,"mc":[{"id":"1.168130661","rc":[{"batb":[[0,17.5,7.16]],"ltp":18.0,"tv":351.77,"id":24707172}]}]}
{"op":"mcm","clk":"993821838","pt":1580546679438,"mc":[{"id":"1.168130661","rc":[{"batb":[[0,30,3.14]],"ltp":29.0,"tv":102.6,"id":25545675}]}]}
{"op":"mcm","clk":"993823024","pt":1580546693235,"mc":[{"id":"1.168130661","rc":[{"batb":[[1,17,12.84]],"ltp":18.0,"tv":351.77,"id":24707172}]}]}
{"op":"mcm","clk":"993824618","pt":1580546712671,"mc":[{"id":"1.168130661","rc":[{"batl":[[0,19.5,2.69],[1,20,10.25],[2,21,14.12]],"ltp":18.0,"tv":351.77,"id":24707172}]}]}
{"op":"mcm","clk":"993825047","pt":1580546717611,"mc":[{"id":"1.168130661","rc":[{"batb":[[0,30,6.85]],"ltp":29.0,"tv":102.6,"id":25545675}]}]}
{"op":"mcm","clk":"993826124","pt":1580546730527,"mc":[{"id":"1.168130661","rc":[{"batl":[[0,19.5,4.69]],"ltp":18.0,"tv":351.77,"id":24707172},{"batl":[[0,14,4.88]],"ltp":12.5,"tv":664.77,"id":24420205},{"trd":[[2.68,224.68]],"batb":[[0,2.68,9.03],[1,2.66,2.73],[2,2.64,4.27]],"batl":[[0,2.7,24.83],[1,2.72,402],[2,2.74,79.55]],"ltp":2.68,"tv":2736.6,"id":26314798},{"batl":[[0,9.8,6.97]],"ltp":9.4,"tv":550.51,"id":420}],"tv":7253.05}]}
{"op":"mcm","clk":"993826512","pt":1580546735345,"mc":[{"id":"1.168130661","rc":[{"batl":[[0,2.7,44.83]],"ltp":2.68,"tv":2736.6,"id":26314798}]}]}
{"op":"mcm","clk":"993826620","pt":1580546736530,"mc":[{"id":"1.168130661","rc":[{"batb":[[0,30,3.14]],"ltp":29.0,"tv":102.6,"id":25545675}]}]}
{"op":"mcm","clk":"993827456","pt":1580546746648,"mc":[{"id":"1.168130661","rc":[{"batl":[[0,19,2.33],[1,19.5,2],[2,20,10.25]],"ltp":18.0,"tv":351.77,"id":24707172},{"batl":[[0,9.8,4.97]],"ltp":9.4,"tv":550.51,"id":420}]}]}
{"op":"mcm","clk":"993828123","pt":1580546754764,"mc":[{"id":"1.168130661","rc":[{"trd":[[2.68,234.68]],"batb":[[0,2.68,4.03]],"ltp":2.68,"tv":2746.6,"id":26314798}],"tv":7263.05}]}
{"op":"mcm","clk":"993828370","pt":1580546757681,"mc":[{"id":"1.168130661","rc":[{"batb":[[1,17,9.26]],"ltp":18.0,"tv":351.77,"id":24707172}]}]}
{"op":"mcm","clk":"993829050","pt":1580546765064,"mc":[{"id":"1.168130661","rc":[{"batb":[[2,2.64,24.27]],"ltp":2.68,"tv":2746.6,"id":26314798}]}]}
{"op":"mcm","clk":"993831453","pt":1580546791594,"mc":[{"id":"1.168130661","rc":[{"trd":[[2.76,293.85]],"batl":[[0,2.76,2]],"ltp":2.76,"tv":2851.23,"id":25238892}],"tv":7267.51}]}
{"op":"mcm","clk":"993832518","pt":1580546804542,"mc":[{"id":"1.168130661","rc":[{"trd":[[32,21.39]],"batb":[[0,30,2.6]],"batl":[[0,32,1.46],[1,50,1.06],[2,65,2.61]],"ltp":32.0,"tv":103.68,"id":25545675}],"tv":7268.58}]}
{"op":"mcm","clk":"993832610","pt":1580546805632,"mc":[{"id":"1.168130661","rc":[{"batb":[[1,29,4.3]],"ltp":32.0,"tv":103.68,"id":25545675},{"batl":[[0,2.78,22.7],[1,2.84,1.9],[2,2.9,51.18]],"ltp":2.76,"tv":2851.23,"id":25238892},{"batl":[[0,14,2.88]],"ltp":12.5,"tv":664.77,"id":24420205},{"trd":[[9.8,145.77]],"batl":[[0,10,9.77],[1,10.5,13.39],[2,11.5,13.73]],"ltp":9.8,"tv":554.45,"id":420}],"tv":7272.52}]}
{"op":"mcm","clk":"993833003","pt":1580546809408,"mc":[{"id":"1.168130661","rc":[{"batl":[[2,2.88,18.95]],"ltp":2.76,"tv":2851.23,"id":25238892}]}]}
{"op":"mcm","clk":"993833207","pt":1580546811525,"mc":[{"id":"1.168130661","rc":[{"batb":[[2,8.4,3]],"ltp":9.8,"tv":554.45,"id":420}]}]}
{"op":"mcm","clk":"993833362","pt":1580546813250,"mc":[{"id":"1.168130661","rc":[{"batb":[[0,30,4.6]],"ltp":32.0,"tv":103.68,"id":25545675},{"trd":[[2.68,242.74]],"batb":[[0,2.66,2.73],[1,2.64,24.27],[2,2.62,91.84]],"batl":[[0,2.68,2.47],[1,2.7,46.83],[2,2.72,402]],"ltp":2.68,"tv":2754.66,"id":26314798},{"batl":[[0,10,6.77]],"ltp":9.8,"tv":554.45,"id":420}],"tv":7280.58}]}
{"op":"mcm","clk":"993834087","pt":1580546821709,"mc":[{"id":"1.168130661","rc":[{"batl":[[2,65,2]],"ltp":32.0,"tv":103.68,"id":25545675}]}]}
{"op":"mcm","clk":"993834171","pt":1580546822649,"mc":[{"id":"1.168130661","rc":[{"batl":[[1,50,1.83]],"ltp":32.0,"tv":103.68,"id":25545675},{"batl":[[2,2.88,33.43]],"ltp":2.76,"tv":2851.23,"id":25238892}]}]}
{"op":"mcm","clk":"993835847","pt":1580546842704,"mc":[{"id":"1.168130661","rc":[{"batb":[[0,12.5,3.48],[1,12,2.27],[2,11.5,6.77]],"ltp":12.5,"tv":664.77,"id":24420205}]}]}
{"op":"mcm","clk":"993835920","pt":1580546843685,"mc":[{"id":"1.168130661","rc":[{"batl":[[2,2.88,47.92]],"ltp":2.76,"tv":2851.23,"id":25238892},{"batb":[[0,13,2.12],[1,12.5,3.48],[2,12,2.27]],"ltp":12.5,"tv":664.77,"id":24420205}]}]}
{"op":"mcm","clk":"993836059","pt":1580546845489,"mc":[{"id":"1.168130661","rc":[{"batl":[[0,2.76,4],[1,2.78,22.7],[2,2.84,1.9]],"ltp":2.76,"tv":2851.23,"id":25238892},{"batl":[[0,14,4.88]],"ltp":12.5,"tv":664.77,"id":24420205}]}]}
{"op":"mcm","clk":"993836125","pt":1580546846470,"mc":[{"id":"1.168130661","rc":[{"trd":[[14,5.76]],"batl":[[0,14.5,7],[1,15,2],[2,17.5,17.4]],"ltp":14.0,"tv":670.53,"id":24420205}],"tv":7286.35}]}
{"op":"mcm","clk":"993836564","pt":1580546853693,"mc":[{"id":"1.168130661","rc":[{"batl":[[0,9.8,2],[1,10,6.77],[2,10.5,13.39]],"ltp":9.8,"tv":554.45,"id":420}]}]}
{"op":"mcm","clk":"993836630","pt":1580546854676,"mc":[{"id":"1.168130661","rc":[{"batl":[[1,10,9.77]],"ltp":9.8,"tv":554.45,"id":420}]}]}
{"op":"mcm","clk":"993837401","pt":1580546865417,"mc":[{"id":"1.168130661","rc":[{"batl":[[2,20,20]],"ltp":14.0,"tv":670.53,"id":24420205},{"batb":[[0,9.2,1.87],[1,9,20.98],[2,8.8,10.13]],"ltp":9.8,"tv":554.45,"id":420}]}]}
{"op":"mcm","clk":"993837714","pt":1580546869646,"mc":[{"id":"1.168130661","rc":[{"batl":[[0,2.78,22.7],[1,2.84,1.9],[2,2.88,4.46]],"ltp":2.76,"tv":2851.23,"id":25238892},{"batb":[[2,8.8,2.95]],"ltp":9.8,"tv":554.45,"id":420}]}]}
{"op":"mcm","clk":"993839727","pt":1580546895675,"mc":[{"id":"1.168130661","rc":[{"batl":[[2,20,8]],"ltp":14.0,"tv":670.53,"id":24420205}]}]}
{"op":"mcm","clk":"993840028","pt":1580546899285,"mc":[{"id":"1.168130661","rc":[{"batl":[[2,2.88,33.44]],"ltp":2.76,"tv":2851.23,"id":25238892}]}]}
{"op":"mcm","clk":"993840443","pt":1580546904576,"mc":[{"id":"1.168130661","rc":[{"batl":[[0,2.76,4],[1,2.78,22.7],[2,2.84,1.9]],"ltp":2.76,"tv":2851.23,"id":25238892}]}]}
{"op":"mcm","clk":"993840688","pt":1580546907674,"mc":[{"id":"1.168130661","rc":[{"batl":[[0,10,9.77],[1,10.5,13.39],[2,11.5,13.73]],"ltp":9.8,"tv":554.45,"id":420}]}]}
{"op":"mcm","clk":"993842313","pt":1580546928714,"mc":[{"id":"1.168130661","rc":[{"batl":[[0,2.78,22.7],[1,2.84,1.9],[2,2.88,4.46]],"ltp":2.76,"tv":2851.23,"id":25238892}]}]}
{"op":"mcm","clk":"993843335","pt":1580546941705,"mc":[{"id":"1.168130661","rc":[{"batl":[[0,2.7,46.83],[1,2.72,402],[2,2.74,79.55]],"ltp":2.68,"tv":2754.66,"id":26314798}]}]}
{"op":"mcm","clk":"993843406","pt":1580546942484,"mc":[{"id":"1.168130661","rc":[{"batl":[[2,2.88,33.44]],"ltp":2.76,"tv":2851.23,"id":25238892}]}]}
{"op":"mcm","clk":"993843514","pt":1580546943722,"mc":[{"id":"1.168130661","rc":[{"batb":[[0,2.68,2],[1,2.66,2.73],[2,2.64,24.27]],"ltp":2.68,"tv":2754.66,"id":26314798}]}]}
{"op":"mcm","clk":"993843559","pt":1580546944343,"mc":[{"id":"1.168130661","rc":[{"batl":[[2,2.88,47.92]],"ltp":2.76,"tv":2851.23,"id":25238892}]}]}
{"op":"mcm","clk":"993843755","pt":1580546946680,"mc":[{"id":"1.168130661","rc":[{"batb":[[0,2.66,2.73],[1,2.64,24.27],[2,2.62,91.84]],"ltp":2.68,"tv":2754.66,"id":26314798}]}]}
{"op":"mcm","clk":"993844457","pt":1580546956629,"mc":[{"id":"1.168130661","rc":[{"trd":[[2.66,225.9]],"batb":[[0,2.64,24.27],[1,2.62,91.84],[2,2.6,28.29]],"ltp":2.66,"tv":2760.12,"id":26314798}],"tv":7291.81}]}
{"op":"mcm","clk":"993844536","pt":1580546957671,"mc":[{"id":"1.168130661","rc":[{"batl":[[0,2.76,2.09],[1,2.78,22.7],[2,2.84,1.9]],"ltp":2.76,"tv":2851.23,"id":25238892},{"trd":[[2.7,488.43]],"batb":[[0,2.64,20]],"batl":[[0,2.7,42.83]],"ltp":2.7,"tv":2768.12,"id":26314798},{"batl":[[0,10,6.77]],"ltp":9.8,"tv":554.45,"id":420}],"tv":7299.8}]}
{"op":"mcm","clk":"993844700","pt":1580546959845,"mc":[{"id":"1.168130661","rc":[{"trd":[[10,130.41]],"batl":[[0,10,2.67]],"ltp":10.0,"tv":562.65,"id":420}],"tv":7308.0}]}
{"op":"mcm","clk":"993844794","pt":1580546961243,"mc":[{"id":"1.168130661","rc":[{"batb":[[1,2.62,98.66]],"batl":[[0,2.68,2],[1,2.7,42.83],[2,2.72,402]],"ltp":2.7,"tv":2768.12,"id":26314798}]}]}
{"op":"mcm","clk":"993845716","pt":1580546972644,"mc":[{"id":"1.168130661","rc":[{"batb":[[0,9.4,4.09],[1,9.2,3.6],[2,9,20.98]],"batl":[[0,10.5,13.39],[1,11.5,13.73],[2,12,5.75]],"ltp":10.0,"tv":562.65,"id":420}]}]}
{"op":"mcm","clk":"993847275","pt":1580546991500,"mc":[{"id":"1.168130661","rc":[{"batl":[[1,11.5,17.77]],"ltp":10.0,"tv":562.65,"id":420}]}]}
{"op":"mcm","clk":"993847784","pt":1580546996680,"mc":[{"id":"1.168130661","rc":[{"batb":[[2,9,18.98]],"ltp":10.0,"tv":562.65,"id":420}]}]}
{"op":"mcm","clk":"993847871","pt":1580546997709,"mc":[{"id":"1.168130661","rc":[{"batb":[[0,9.4,6.09]],"ltp":10.0,"tv":562.65,"id":420}]}]}
{"op":"mcm","clk":"993848477","pt":1580547004628,"mc":[{"id":"1.168130661","rc":[{"batb":[[1,9.2,6.09]],"batl":[[1,11.5,13.73]],"ltp":10.0,"tv":562.65,"id":420}]}]}
{"op":"mcm","clk":"993850185","pt":1580547027455,"mc":[{"id":"1.168130661","rc":[{"trd":[[2.76,298.03],[2.78,382.93]],"batl":[[0,2.78,2.79],[1,2.84,1.9],[2,2.9,51.18]],"ltp":2.78,"tv":2895.23,"id":25238892}],"tv":7352.0}]}
{"op":"mcm","clk":"993850653","pt":1580547033554,"mc":[{"id":"1.168130661","rc":[{"batl":[[0,2.8,2.18],[2,2.86,4]],"ltp":2.78,"tv":2895.23,"id":25238892},{"batl":[[0,14,2.18],[1,14.5,7],[2,15,2]],"ltp":14.0,"tv":670.53,"id":24420205},{"batl":[[0,2.68,4]],"ltp":2.7,"tv":2768.12,"id":26314798}]}]}
{"op":"mcm","clk":"993850760","pt":1580547034530,"mc":[{"id":"1.168130661","rc":[{"batl":[[0,2.82,2.18]],"ltp":2.78,"tv":2895.23,"id":25238892}]}]}
{"op":"mcm","clk":"993851387","pt":1580547039561,"mc":[{"id":"1.168130661","rc":[{"trd":[[10.5,98.51]],"batl":[[0,10.5,6.39]],"ltp":10.5,"tv":576.65,"id":420}],"tv":7366.0}]}
{"op":"mcm","clk":"993851558","pt":1580547041671,"mc":[{"id":"1.168130661","rc":[{"trd":[[2.82,125.78],[2.84,120.89]],"batl":[[0,2.84,3.61],[1,2.86,4],[2,2.9,51.18]],"ltp":2.84,"tv":2900.62,"id":25238892}],"tv":7371.39}]}
{"op":"mcm","clk":"993851619","pt":1580547042544,"mc":[{"id":"1.168130661","rc":[{"batb":[[0,9.6,1.66],[1,9.4,2],[2,9.2,4.36]],"batl":[[0,10,2.67],[1,10.5,6.39],[2,11.5,13.73]],"ltp":10.5,"tv":576.65,"id":420}]}]}
{"op":"mcm","clk":"993852115","pt":1580547049677,"mc":[{"id":"1.168130661","rc":[{"trd":[[30,28.17]],"batb":[[0,30,2.6]],"ltp":30.0,"tv":107.67,"id":25545675}],"tv":7375.39}]}
{"op":"mcm","clk":"993853239","pt":1580547062607,"mc":[{"id":"1.168130661","rc":[{"batl":[[0,2.8,2.01],[1,2.82,6.98],[2,2.84,3.61]],"ltp":2.84,"tv":2900.62,"id":25238892}]}]}
{"op":"mcm","clk":"993853542","pt":1580547066419,"mc":[{"id":"1.168130661","rc":[{"batl":[[1,48,1.23],[2,65,2.95]],"ltp":30.0,"tv":107.67,"id":25545675}]}]}
{"op":"mcm","clk":"993853889","pt":1580547070700,"mc":[{"id":"1.168130661","rc":[{"trd":[[17.5,19.12]],"batb":[[0,17.5,6.66]],"ltp":17.5,"tv":356.78,"id":24707172},{"trd":[[12.5,47.49],[13,23.85]],"batb":[[0,13,2],[1,12.5,2.6]],"ltp":12.5,"tv":676.53,"id":24420205}],"tv":7386.39}]}
{"op":"mcm","clk":"993854047","pt":1580547072722,"mc":[{"id":"1.168130661","rc":[{"batl":[[0,19,4.33]],"ltp":17.5,"tv":356.78,"id":24707172},{"trd":[[2.68,250.74]],"batb":[[0,2.68,38.01],[1,2.64,25],[2,2.62,98.66]],"batl":[[0,2.7,40.83],[1,2.72,402],[2,2.74,79.55]],"ltp":2.68,"tv":2776.12,"id":26314798}],"tv":7394.39}]}
{"op":"mcm","clk":"993854125","pt":1580547073601,"mc":[{"id":"1.168130661","rc":[{"batb":[[1,2.66,11.84],[2,2.64,25]],"ltp":2.68,"tv":2776.12,"id":26314798}]}]}
{"op":"mcm","clk":"993854310","pt":1580547075720,"mc":[{"id":"1.168130661","rc":[{"batb":[[1,2.66,24.53]],"ltp":2.68,"tv":2776.12,"id":26314798}]}]}
{"op":"mcm","clk":"993854952","pt":1580547083526,"mc":[{"id":"1.168130661","rc":[{"batl":[[0,2.78,1.68],[1,2.8,2.01],[2,2.82,6.98]],"ltp":2.84,"tv":2900.62,"id":25238892},{"batl":[[0,14.5,7],[1,15,2],[2,17.5,14]],"ltp":12.5,"tv":676.53,"id":24420205}]}]}
{"op":"mcm","clk":"993855123","pt":1580547085541,"mc":[{"id":"1.168130661","rc":[{"batl":[[1,2.82,2.98],[2,2.84,2.22]],"ltp":2.84,"tv":2900.62,"id":25238892},{"batl":[[2,17.5,17.13]],"ltp":12.5,"tv":676.53,"id":24420205}]}]}
{"op":"mcm","clk":"993855589","pt":1580547091549,"mc":[{"id":"1.168130661","rc":[{"trd":[[2.68,268.73]],"batb":[[0,2.68,29.01]],"ltp":2.68,"tv":2794.11,"id":26314798}],"tv":7412.39}]}
{"op":"mcm","clk":"993855941","pt":1580547096640,"mc":[{"id":"1.168130661","rc":[{"batb":[[0,2.7,5.2],[1,2.68,9.7],[2,2.66,7.83]],"ltp":2.84,"tv":2900.62,"id":25238892},{"batb":[[1,2.66,4.43]],"ltp":2.68,"tv":2794.11,"id":26314798}]}]}
{"op":"mcm","clk":"993856430","pt":1580547103450,"mc":[{"id":"1.168130661","rc":[{"batb":[[1,2.66,14.17]],"ltp":2.68,"tv":2794.11,"id":26314798}]}]}
{"op":"mcm","clk":"993856682","pt":1580547106672,"mc":[{"id":"1.168130661","rc":[{"batl":[[2,17.5,3.13]],"ltp":12.5,"tv":676.53,"id":24420205}]}]}
{"op":"mcm","clk":"993856897","pt":1580547109549,"mc":[{"id":"1.168130661","rc":[{"trd":[[10,135.75]],"batl":[[0,10.5,6.39],[1,11.5,13.73],[2,12,5.75]],"ltp":10.0,"tv":581.99,"id":420}],"tv":7417.73}]}
{"op":"mcm","clk":"993857376","pt":1580547115679,"mc":[{"id":"1.168130661","rc":[{"batl":[[0,2.82,2.98],[1,2.84,2.22],[2,2.88,6]],"ltp":2.84,"tv":2900.62,"id":25238892},{"batl":[[2,20,20]],"ltp":12.5,"tv":676.53,"id":24420205}]}]}
{"op":"mcm","clk":"993857452","pt":1580547116664,"mc":[{"id":"1.168130661","rc":[{"trd":[[2.68,278.73]],"batb":[[0,2.68,24.01]],"ltp":2.68,"tv":2804.11,"id":26314798}],"tv":7427.73}]}
{"op":"mcm","clk":"993858521","pt":1580547129510,"mc":[{"id":"1.168130661","rc":[{"batb":[[0,29,4.9],[1,28,5.81],[2,27,3.05]],"ltp":30.0,"tv":107.67,"id":25545675}]}]}
{"op":"mcm","clk":"993858694","pt":1580547131690,"mc":[{"id":"1.168130661","rc":[{"trd":[[2.7,150.1]],"batb":[[0,2.68,6.43],[1,2.66,13.99],[2,2.64,30.5]],"batl":[[0,2.7,30.76],[1,2.74,2.05],[2,2.76,2.05]],"ltp":2.7,"tv":2919.1,"id":25238892},{"batl":[[0,19,2.33]],"ltp":17.5,"tv":356.78,"id":24707172},{"batb":[[1,2.66,20.17]],"ltp":2.68,"tv":2804.11,"id":26314798},{"batb":[[0,9.6,3.66]],"ltp":10.0,"tv":581.99,"id":420}],"tv":7446.21}]}
{"op":"mcm","clk":"993858830","pt":1580547133399,"mc":[{"id":"1.168130661","rc":[{"batb":[[1,2.66,11.83]],"ltp":2.7,"tv":2919.1,"id":25238892}]}]}
{"op":"mcm","clk":"993859090","pt":1580547136612,"mc":[{"id":"1.168130661","rc":[{"batl":[[1,2.72,3.08],[2,2.74,2.05]],"ltp":2.7,"tv":2919.1,"id":25238892},{"batl":[[2,19.5,13]],"ltp":12.5,"tv":676.53,"id":24420205},{"trd":[[2.7,498.42]],"batl":[[0,2.7,35.83]],"ltp":2.7,"tv":2814.11,"id":26314798}],"tv":7456.2}]}
{"op":"mcm","clk":"993859182","pt":1580547137699,"mc":[{"id":"1.168130661","rc":[{"trd":[[2.68,109.41]],"batb":[[0,2.66,11.83],[1,2.64,26.5],[2,2.62,81.01]],"batl":[[0,2.68,20.24],[1,2.78,3.09],[2,2.82,2.98]],"ltp":2.68,"tv":2940.13,"id":25238892},{"batl":[[0,14.5,5],[2,19,11.37]],"ltp":12.5,"tv":676.53,"id":24420205}],"tv":7477.24}]}
{"op":"mcm","clk":"993859244","pt":1580547138525,"mc":[{"id":"1.168130661","rc":[{"batb":[[1,2.64,29.5],[2,2.62,84.01]],"batl":[[1,2.72,3.09],[2,2.74,3.09]],"ltp":2.68,"tv":2940.13,"id":25238892},{"batl":[[1,15,4]],"ltp":12.5,"tv":676.53,"id":24420205}]}]}
{"op":"mcm","clk":"993859350","pt":1580547139710,"mc":[{"id":"1.168130661","rc":[{"batb":[[1,2.64,34.05]],"ltp":2.68,"tv":2940.13,"id":25238892},{"batl":[[1,2.72,400],[2,2.74,81.55]],"ltp":2.7,"tv":2814.11,"id":26314798}]}]}
{"op":"mcm","clk":"993859635","pt":1580547143647,"mc":[{"id":"1.168130661","rc":[{"trd":[[2.68,288.73]],"batb":[[0,2.68,19.01]],"ltp":2.68,"tv":2824.11,"id":26314798}],"tv":7487.24}]}
{"op":"mcm","clk":"993859772","pt":1580547145623,"mc":[{"id":"1.168130661","rc":[{"trd":[[2.66,78.66]],"batb":[[0,2.64,34.05],[1,2.62,84.01],[2,2.58,6]],"batl":[[0,2.66,8.41],[1,2.74,8.21],[2,2.8,3.13]],"ltp":2.66,"tv":2963.79,"id":25238892},{"batb":[[1,2.66,9.75]],"ltp":2.68,"tv":2824.11,"id":26314798}],"tv":7510.9}]}
{"op":"mcm","clk":"993859863","pt":1580547146659,"mc":[{"id":"1.168130661","rc":[{"batb":[[2,2.54,98]],"ltp":2.66,"tv":2963.79,"id":25238892}]}]}
{"op":"mcm","clk":"993859920","pt":1580547147433,"mc":[{"id":"1.168130661","rc":[{"batb":[[0,2.64,29.5],[1,2.62,95.05],[2,2.6,3.14]],"batl":[[1,2.8,13.63],[2,2.82,2.98]],"ltp":2.66,"tv":2963.79,"id":25238892},{"batb":[[1,2.66,16.75]],"ltp":2.68,"tv":2824.11,"id":26314798}]}]}
{"op":"mcm","clk":"993859996","pt":1580547148420,"mc":[{"id":"1.168130661","rc":[{"batl":[[1,2.8,18.31]],"ltp":2.66,"tv":2963.79,"id":25238892}]}]}
{"op":"mcm","clk":"993860210","pt":1580547150960,"mc":[{"id":"1.168130661","rc":[{"trd":[[2.64,115.65]],"batb":[[0,2.66,3.16],[1,2.64,21.09],[2,2.62,95.05]],"batl":[[0,2.8,18.31],[1,2.82,8.84],[2,2.86,87]],"ltp":2.64,"tv":2980.62,"id":25238892},{"batb":[[2,12,4.45]],"ltp":12.5,"tv":676.53,"id":24420205},{"batb":[[1,2.66,9.75]],"ltp":2.68,"tv":2824.11,"id":26314798}],"tv":7527.72}]}
{"op":"mcm","clk":"993870232","pt":1580547152629,"mc":[{"id":"1.168130661","rc":[{"batb":[[2,2.62,82.51]],"batl":[[0,2.8,3.13],[1,2.82,2.98]],"ltp":2.64,"tv":2980.62,"id":25238892}]}]}
{"op":"mcm","clk":"993871287","pt":1580547165869,"mc":[{"id":"1.168130661","rc":[{"batl":[[2,2.88,6]],"ltp":2.64,"tv":2980.62,"id":25238892}]}]}
{"op":"mcm","clk":"993871438","pt":1580547167644,"mc":[{"id":"1.168130661","rc":[{"batl":[[0,18.5,2.21],[1,19,2.26],[2,19.5,2]],"ltp":17.5,"tv":356.78,"id":24707172}]}]}
{"op":"mcm","clk":"993872273","pt":1580547176642,"mc":[{"id":"1.168130661","rc":[{"batl":[[0,2.78,2],[1,2.8,3.13],[2,2.82,2.98]],"ltp":2.64,"tv":2980.62,"id":25238892}]}]}
{"op":"mcm","clk":"993872316","pt":1580547177157,"mc":[{"id":"1.168130661","rc":[{"batl":[[0,14.5,7]],"ltp":12.5,"tv":676.53,"id":24420205}]}]}
{"op":"mcm","clk":"993872506","pt":1580547179492,"mc":[{"id":"1.168130661","rc":[{"batb":[[0,2.68,1.68],[2,2.62,81.95]],"ltp":2.64,"tv":2980.62,"id":25238892}]}]}
{"op":"mcm","clk":"993872648","pt":1580547181259,"mc":[{"id":"1.168130661","rc":[{"trd":[[2.68,112.77]],"batb":[[0,2.64,21.09],[1,2.62,81.95],[2,2.54,6]],"batl":[[0,2.78,2.32]],"ltp":2.68,"tv":2983.98,"id":25238892}],"tv":7531.08}]}
{"op":"mcm","clk":"993873575","pt":1580547192457,"mc":[{"id":"1.168130661","rc":[{"trd":[[2.64,132.81]],"batb":[[0,2.64,12.51],[1,2.62,89.13],[2,2.6,3.06]],"batl":[[0,2.66,11.8],[1,2.78,2],[2,2.8,3.13]],"ltp":2.64,"tv":3001.14,"id":25238892},{"batl":[[0,14.5,5]],"ltp":12.5,"tv":676.53,"id":24420205},{"batb":[[1,2.66,16.75]],"ltp":2.68,"tv":2824.11,"id":26314798}],"tv":7548.24}]}
{"op":"mcm","clk":"993873673","pt":1580547193698,"mc":[{"id":"1.168130661","rc":[{"batl":[[2,2.8,22.72]],"ltp":2.64,"tv":3001.14,"id":25238892}]}]}
{"op":"mcm","clk":"993874042","pt":1580547198680,"mc":[{"id":"1.168130661","rc":[{"trd":[[2.64,155.77],[2.66,79.3]],"batb":[[0,2.64,1.02]],"batl":[[0,2.78,2],[1,2.8,22.72],[2,2.82,2.98]],"ltp":2.66,"tv":3024.74,"id":25238892}],"tv":7571.85}]}
{"op":"mcm","clk":"993874106","pt":1580547199403,"mc":[{"id":"1.168130661","rc":[{"batl":[[0,2.78,16.48]],"ltp":2.66,"tv":3024.74,"id":25238892}]}]}
{"op":"mcm","clk":"993874210","pt":1580547200696,"mc":[{"id":"1.168130661","rc":[{"batb":[[1,2.62,81.95]],"batl":[[1,2.8,17.98]],"ltp":2.66,"tv":3024.74,"id":25238892}]}]}
{"op":"mcm","clk":"993875082","pt":1580547211276,"mc":[{"id":"1.168130661","rc":[{"batl":[[0,2.76,1.1],[1,2.78,16.48],[2,2.8,17.98]],"ltp":2.66,"tv":3024.74,"id":25238892}]}]}
{"op":"mcm","clk":"993876431","pt":1580547227636,"mc":[{"id":"1.168130661","rc":[{"trd":[[2.7,538.43]],"batl":[[0,2.7,15.83]],"ltp":2.7,"tv":2864.12,"id":26314798}],"tv":7611.86}]}
{"op":"mcm","clk":"993876469","pt":1580547228051,"mc":[{"id":"1.168130661","rc":[{"batb":[[0,2.64,3.02]],"ltp":2.66,"tv":3024.74,"id":25238892},{"batl":[[0,14.5,7]],"ltp":12.5,"tv":676.53,"id":24420205},{"batb":[[0,2.68,23.21]],"ltp":2.7,"tv":2864.12,"id":26314798}]}]}
{"op":"mcm","clk":"993876598","pt":1580547229662,"mc":[{"id":"1.168130661","rc":[{"batb":[[2,2.64,39.43]],"ltp":2.7,"tv":2864.12,"id":26314798}]}]}
{"op":"mcm","clk":"993876690","pt":1580547230651,"mc":[{"id":"1.168130661","rc":[{"batl":[[1,2.78,2],[2,2.8,3.13]],"ltp":2.66,"tv":3024.74,"id":25238892},{"trd":[[11.5,105.15],[12,84.18],[12.5,52.69],[13,27.85]],"batb":[[1,11,7.18],[2,10.5,10.56]],"ltp":11.5,"tv":706.53,"id":24420205},{"batb":[[2,2.64,42.43]],"ltp":2.7,"tv":2864.12,"id":26314798},{"batb":[[0,9.6,1.66],[1,9.4,4]],"ltp":10.0,"tv":581.99,"id":420}],"tv":7641.85}]}
{"op":"mcm","clk":"993876750","pt":1580547231326,"mc":[{"id":"1.168130661","rc":[{"batb":[[0,11.5,2.27],[1,11,6.36]],"batl":[[0,14,5.32],[1,14.5,7],[2,15,4]],"ltp":11.5,"tv":706.53,"id":24420205}]}]}
{"op":"mcm","clk":"993877126","pt":1580547235651,"mc":[{"id":"1.168130661","rc":[{"batb":[[0,30,6.31],[1,29,4.3],[2,28,5.81]],"ltp":30.0,"tv":107.67,"id":25545675}]}]}
{"op":"mcm","clk":"993877186","pt":1580547236326,"mc":[{"id":"1.168130661","rc":[{"batl":[[0,14,7.32]],"ltp":11.5,"tv":706.53,"id":24420205}]}]}
{"op":"mcm","clk":"993877500","pt":1580547239646,"mc":[{"id":"1.168130661","rc":[{"batl":[[0,2.76,25.1]],"ltp":2.66,"tv":3024.74,"id":25238892}]}]}
{"op":"mcm","clk":"993877772","pt":1580547242673,"mc":[{"id":"1.168130661","rc":[{"trd":[[2.74,209.38]],"batl":[[0,2.74,22],[1,2.76,1.1],[2,2.78,2]],"ltp":2.74,"tv":3028.74,"id":25238892}],"tv":7645.85}]}
{"op":"mcm","clk":"993877863","pt":1580547243567,"mc":[{"id":"1.168130661","rc":[{"batl":[[0,13.5,1.68],[1,14,7.32],[2,14.5,7]],"ltp":11.5,"tv":706.53,"id":24420205}]}]}
{"op":"mcm","clk":"993878214","pt":1580547246569,"mc":[{"id":"1.168130661","rc":[{"trd":[[32,22.38]],"batl":[[0,48,1.7],[1,65,2.95],[2,75,2]],"ltp":32.0,"tv":108.66,"id":25545675},{"trd":[[2.74,220.91]],"batl":[[0,2.72,10.47]],"ltp":2.74,"tv":3040.27,"id":25238892},{"trd":[[18,21.25],[18.5,26.27]],"batl":[[0,19.5,2.5],[1,20,10.25],[2,21,14.12]],"ltp":18.5,"tv":358.49,"id":24707172},{"trd":[[11.5,112.14],[12,84.46]],"batb":[[0,11.5,2.03]],"batl":[[0,13.5,3.68],[1,14,2.36]],"ltp":11.5,"tv":713.8,"id":24420205},{"trd":[[2.7,550.14]],"batb":[[0,2.68,35.01]],"batl":[[0,2.7,4.12]],"ltp":2.7,"tv":2875.83,"id":26314798},{"trd":[[10.5,101.52]],"batl":[[0,10.5,3.39]],"ltp":10.5,"tv":584.99,"id":420}],"tv":7682.07}]}
{"op":"mcm","clk":"993878367","pt":1580547248486,"mc":[{"id":"1.168130661","rc":[{"batb":[[1,2.66,28.45]],"ltp":2.7,"tv":2875.83,"id":26314798}]}]}
{"op":"mcm","clk":"993878896","pt":1580547254671,"mc":[{"id":"1.168130661","rc":[{"batl":[[0,2.7,10.47]],"ltp":2.74,"tv":3040.27,"id":25238892}]}]}
{"op":"mcm","clk":"993879048","pt":1580547256661,"mc":[{"id":"1.168130661","rc":[{"batl":[[0,48,1.69]],"ltp":32.0,"tv":108.66,"id":25545675}]}]}
{"op":"mcm","clk":"993879225","pt":1580547258686,"mc":[{"id":"1.168130661","rc":[{"batl":[[0,2.68,10.47]],"ltp":2.74,"tv":3040.27,"id":25238892}]}]}
{"op":"mcm","clk":"993879330","pt":1580547259672,"mc":[{"id":"1.168130661","rc":[{"batl":[[2,2.78,6]],"ltp":2.74,"tv":3040.27,"id":25238892},{"batb":[[0,18,3],[1,17.5,6.66],[2,17,9.26]],"ltp":18.5,"tv":358.49,"id":24707172}]}]}
{"op":"mcm","clk":"993879373","pt":1580547260195,"mc":[{"id":"1.168130661","rc":[{"batl":[[1,2.76,10.33],[2,2.78,11.6]],"ltp":2.74,"tv":3040.27,"id":25238892},{"batb":[[2,10.5,12.84]],"ltp":11.5,"tv":713.8,"id":24420205}]}]}
{"op":"mcm","clk":"993880265","pt":1580547270704,"mc":[{"id":"1.168130661","rc":[{"batb":[[0,18,5]],"ltp":18.5,"tv":358.49,"id":24707172},{"batl":[[0,13.5,8.68],[2,14.5,2]],"ltp":11.5,"tv":713.8,"id":24420205}]}]}
{"op":"mcm","clk":"993880725","pt":1580547275719,"mc":[{"id":"1.168130661","rc":[{"batl":[[1,2.76,9.23]],"ltp":2.74,"tv":3040.27,"id":25238892}]}]}
{"op":"mcm","clk":"993881242","pt":1580547281526,"mc":[{"id":"1.168130661","rc":[{"batb":[[0,9.4,4],[1,9.2,4.36],[2,9,18.98]],"ltp":10.5,"tv":584.99,"id":420}]}]}
{"op":"mcm","clk":"993881355","pt":1580547282621,"mc":[{"id":"1.168130661","rc":[{"batl":[[2,2.78,5.6]],"ltp":2.74,"tv":3040.27,"id":25238892}]}]}
{"op":"mcm","clk":"993882551","pt":1580547296481,"mc":[{"id":"1.168130661","rc":[{"trd":[[32,22.85]],"batl":[[0,48,1.22]],"ltp":32.0,"tv":109.13,"id":25545675},{"trd":[[2.68,118.35]],"batl":[[0,2.68,4.89],[1,2.78,5.6],[2,2.8,11.94]],"ltp":2.68,"tv":3045.85,"id":25238892},{"trd":[[18.5,26.77],[19.5,3.82]],"batl":[[0,19,3.03],[1,19.5,7.12],[2,20,10.25]],"ltp":19.5,"tv":359.29,"id":24707172},{"trd":[[11.5,113.78],[12,84.78],[12.5,52.84],[13,28.56]],"batb":[[0,11.5,1.21]],"ltp":11.5,"tv":716.62,"id":24420205},{"trd":[[2.7,554.26],[2.72,114.83]],"batb":[[0,2.68,39.16]],"batl":[[0,2.72,398.59],[1,2.74,81.55],[2,2.76,224]],"ltp":2.72,"tv":2881.36,"id":26314798},{"trd":[[10.5,106.87]],"batb":[[0,9.6,6.84],[1,9.4,4],[2,9.2,4.36]],"batl":[[0,11,3.3]],"ltp":10.5,"tv":590.34,"id":420}],"tv":7702.62}]}
{"op":"mcm","clk":"993882664","pt":1580547297629,"mc":[{"id":"1.168130661","rc":[{"batl":[[1,2.7,4.31],[2,2.82,10.13]],"ltp":2.68,"tv":3045.85,"id":25238892},{"batb":[[2,10.5,10.56]],"ltp":11.5,"tv":716.62,"id":24420205},{"batb":[[0,9.8,2.31],[1,9.6,6.84],[2,9.4,6.74]],"ltp":10.5,"tv":590.34,"id":420}]}]}
{"op":"mcm","clk":"993882864","pt":1580547299698,"mc":[{"id":"1.168130661","rc":[{"batb":[[2,9.4,4]],"ltp":10.5,"tv":590.34,"id":420}]}]}
{"op":"mcm","clk":"993883290","pt":1580547304660,"mc":[{"id":"1.168130661","rc":[{"batl":[[0,50,1.83],[1,65,2]],"ltp":32.0,"tv":109.13,"id":25545675}]}]}
{"op":"mcm","clk":"993883698","pt":1580547309256,"mc":[{"id":"1.168130661","rc":[{"batb":[[0,9.8,4.31],[2,9.4,2]],"ltp":10.5,"tv":590.34,"id":420}]}]}
{"op":"mcm","clk":"993884001","pt":1580547312631,"mc":[{"id":"1.168130661","rc":[{"batl":[[0,50,1.06]],"ltp":32.0,"tv":109.13,"id":25545675}]}]}
{"op":"mcm","clk":"993884108","pt":1580547313667,"mc":[{"id":"1.168130661","rc":[{"batl":[[1,65,2.61]],"ltp":32.0,"tv":109.13,"id":25545675}]}]}
{"op":"mcm","clk":"993886395","pt":1580547337495,"mc":[{"id":"1.168130661","rc":[{"batl":[[0,13,2],[1,13.5,8.68],[2,14,2.36]],"ltp":11.5,"tv":716.62,"id":24420205}]}]}
{"op":"mcm","clk":"993889087","pt":1580547365719,"mc":[{"id":"1.168130661","rc":[{"trd":[[2.68,128.13],[2.7,156.32]],"batl":[[0,2.74,4.02],[1,2.82,10.13],[2,2.88,6]],"ltp":2.7,"tv":3061.85,"id":25238892}],"tv":7718.62}]}
{"op":"mcm","clk":"993889772","pt":1580547372649,"mc":[{"id":"1.168130661","rc":[{"batb":[[0,30,2.6]],"ltp":32.0,"tv":109.13,"id":25545675}]}]}
{"op":"mcm","clk":"993889851","pt":1580547373524,"mc":[{"id":"1.168130661","rc":[{"batl":[[1,2.8,1.08],[2,2.82,10.13]],"ltp":2.7,"tv":3061.85,"id":25238892}]}]}
{"op":"mcm","clk":"993891936","pt":1580547395436,"mc":[{"id":"1.168130661","rc":[{"batl":[[2,2.82,2.98]],"ltp":2.7,"tv":3061.85,"id":25238892}]}]}
{"op":"mcm","clk":"993907491","pt":1580547582684,"mc":[{"id":"1.168130661","rc":[{"batb":[[2,2.64,50.63]],"ltp":2.72,"tv":2881.36,"id":26314798}]}]}
{"op":"mcm","clk":"993907513","pt":1580547582997,"mc":[{"id":"1.168130661","rc":[{"batb":[[1,2.62,83.95]],"ltp":2.7,"tv":3061.85,"id":25238892},{"batb":[[1,2.66,21.45]],"ltp":2.72,"tv":2881.36,"id":26314798}]}]}
{"op":"mcm","clk":"993909471","pt":1580547604632,"mc":[{"id":"1.168130661","rc":[{"trd":[[2.64,156.77]],"batb":[[0,2.64,2.52]],"ltp":2.64,"tv":3062.85,"id":25238892}],"tv":7719.62}]}
{"op":"mcm","clk":"993909598","pt":1580547605637,"mc":[{"id":"1.168130661","rc":[{"trd":[[2.68,290.73]],"batb":[[0,2.68,38.16]],"ltp":2.68,"tv":2883.36,"id":26314798}],"tv":7721.62}]}
{"op":"mcm","clk":"993909700","pt":1580547606541,"mc":[{"id":"1.168130661","rc":[{"trd":[[2.64,157.77]],"batb":[[0,2.64,4.02]],"ltp":2.64,"tv":3063.85,"id":25238892},{"batb":[[0,11.5,2.71]],"ltp":11.5,"tv":716.62,"id":24420205},{"batb":[[0,2.7,6.38],[1,2.68,38.16],[2,2.66,9]],"batl":[[2,2.76,227]],"ltp":2.68,"tv":2883.36,"id":26314798},{"batb":[[0,10,1.72],[1,9.8,4.31],[2,9.6,6.84]],"ltp":10.5,"tv":590.34,"id":420}],"tv":7722.62}]}
{"op":"mcm","clk":"993909822","pt":1580547607549,"mc":[{"id":"1.168130661","rc":[{"batb":[[0,30,3.18]],"ltp":32.0,"tv":109.13,"id":25545675},{"batb":[[0,18,5.93]],"ltp":19.5,"tv":359.29,"id":24707172}]}]}
{"op":"mcm","clk":"993910047","pt":1580547609640,"mc":[{"id":"1.168130661","rc":[{"batl":[[1,2.76,4],[2,2.8,1.08]],"ltp":2.64,"tv":3063.85,"id":25238892}]}]}
{"op":"mcm","clk":"993911866","pt":1580547629264,"mc":[{"id":"1.168130661","rc":[{"batl":[[1,13.5,7]],"ltp":11.5,"tv":716.62,"id":24420205}]}]}
{"op":"mcm","clk":"993913579","pt":1580547648715,"mc":[{"id":"1.168130661","rc":[{"batl":[[0,13.5,7],[1,14,2.36],[2,14.5,2]],"ltp":11.5,"tv":716.62,"id":24420205}]}]}
{"op":"mcm","clk":"993915702","pt":1580547669404,"mc":[{"id":"1.168130661","rc":[{"trd":[[2.74,228.91]],"batl":[[0,2.76,4.02],[1,2.8,1.08],[2,2.82,2.98]],"ltp":2.74,"tv":3071.85,"id":25238892}],"tv":7730.62}]}
{"op":"mcm","clk":"993920605","pt":1580547712565,"mc":[{"id":"1.168130661","rc":[{"trd":[[2.72,135.13]],"batl":[[0,2.72,388.44]],"ltp":2.72,"tv":2903.66,"id":26314798}],"tv":7750.92}]}
{"op":"mcm","clk":"993922056","pt":1580547725082,"mc":[{"id":"1.168130661","rc":[{"trd":[[2.72,139.13]],"batl":[[0,2.72,386.44]],"ltp":2.72,"tv":2907.66,"id":26314798}],"tv":7754.92}]}
{"op":"mcm","clk":"993922773","pt":1580547730697,"mc":[{"id":"1.168130661","rc":[{"batb":[[0,12,3.64],[1,11.5,2.71],[2,11,6.36]],"ltp":11.5,"tv":716.62,"id":24420205}]}]}
{"op":"mcm","clk":"993922871","pt":1580547731691,"mc":[{"id":"1.168130661","rc":[{"batl":[[0,2.74,4],[1,2.76,4],[2,2.8,1.08]],"ltp":2.74,"tv":3071.85,"id":25238892},{"batb":[[0,12,5.64]],"ltp":11.5,"tv":716.62,"id":24420205}]}]}
{"op":"mcm","clk":"993923064","pt":1580547733322,"mc":[{"id":"1.168130661","rc":[{"batl":[[1,2.8,1.08],[2,2.82,2.98]],"ltp":2.74,"tv":3071.85,"id":25238892}]}]}
{"op":"mcm","clk":"993927541","pt":1580547775662,"mc":[{"id":"1.168130661","rc":[{"trd":[[2.72,159.55]],"batl":[[0,2.72,376.23]],"ltp":2.72,"tv":2928.08,"id":26314798}],"tv":7775.34}]}
{"op":"mcm","clk":"993930387","pt":1580547802516,"mc":[{"id":"1.168130661","rc":[{"trd":[[2.64,158.77]],"batb":[[0,2.64,3.52]],"ltp":2.64,"tv":3072.85,"id":25238892},{"batl":[[0,19,5.03]],"ltp":19.5,"tv":359.29,"id":24707172}],"tv":7776.34}]}
{"op":"mcm","clk":"993937433","pt":1580547871626,"mc":[{"id":"1.168130661","rc":[{"trd":[[18,31.25],[18.5,28.64]],"batb":[[0,17.5,4],[1,17,13.03],[2,16,13.52]],"batl":[[0,18,2.07],[1,19,2],[2,19.5,7.12]],"ltp":18.0,"tv":371.15,"id":24707172}],"tv":7788.2}]}
{"op":"mcm","clk":"993937640","pt":1580547873612,"mc":[{"id":"1.168130661","rc":[{"batb":[[1,17,9.26]],"ltp":18.0,"tv":371.15,"id":24707172}]}]}
{"op":"mcm","clk":"993937824","pt":1580547875639,"mc":[{"id":"1.168130661","rc":[{"batb":[[0,12.5,1.38],[1,12,3.64],[2,11.5,1.21]],"ltp":11.5,"tv":716.62,"id":24420205}]}]}
{"op":"mcm","clk":"993941465","pt":1580547911552,"mc":[{"id":"1.168130661","rc":[{"trd":[[18,35.39]],"batb":[[0,18,2.93],[1,17.5,6],[2,17,9.26]],"batl":[[0,18.5,3.03]],"ltp":18.0,"tv":375.29,"id":24707172}],"tv":7792.34}]}
{"op":"mcm","clk":"993946292","pt":1580547959657,"mc":[{"id":"1.168130661","rc":[{"trd":[[12.5,55.6]],"batb":[[0,12,3.64],[1,11.5,1.21],[2,11,11.98]],"batl":[[0,12.5,3.91],[1,13,16.8],[2,13.5,7]],"ltp":12.5,"tv":719.38,"id":24420205}],"tv":7795.1}]}
{"op":"mcm","clk":"993946356","pt":1580547960344,"mc":[{"id":"1.168130661","rc":[{"batl":[[1,13,18.8]],"ltp":12.5,"tv":719.38,"id":24420205}]}]}
{"op":"mcm","clk":"993946476","pt":1580547961649,"mc":[{"id":"1.168130661","rc":[{"trd":[[12.5,63.82]],"batl":[[0,12.5,1.8]],"ltp":12.5,"tv":727.59,"id":24420205}],"tv":7803.32}]}
{"op":"mcm","clk":"993948104","pt":1580547977677,"mc":[{"id":"1.168130661","rc":[{"trd":[[2.72,276.93]],"batl":[[0,2.72,317.54]],"ltp":2.72,"tv":3045.46,"id":26314798}],"tv":7920.7}]}
{"op":"mcm","clk":"993948590","pt":1580547982675,"mc":[{"id":"1.168130661","rc":[{"trd":[[2.7,567.02]],"batb":[[0,2.68,38.16],[1,2.66,9],[2,2.64,50.63]],"batl":[[0,2.72,318.16]],"ltp":2.7,"tv":3058.21,"id":26314798}],"tv":7933.45}]}
{"op":"mcm","clk":"993948662","pt":1580547983457,"mc":[{"id":"1.168130661","rc":[{"batl":[[0,2.72,317.54]],"ltp":2.7,"tv":3058.21,"id":26314798}]}]}
{"op":"mcm","clk":"993948768","pt":1580547984705,"mc":[{"id":"1.168130661","rc":[{"batb":[[0,2.66,6.48],[1,2.64,3.52],[2,2.62,83.95]],"ltp":2.64,"tv":3072.85,"id":25238892},{"batb":[[1,2.66,21.74]],"ltp":2.7,"tv":3058.21,"id":26314798}]}]}
{"op":"mcm","clk":"993948787","pt":1580547984862,"mc":[{"id":"1.168130661","rc":[{"batb":[[0,2.68,5.13],[1,2.66,6.48],[2,2.64,3.52]],"ltp":2.64,"tv":3072.85,"id":25238892},{"batb":[[1,2.66,12.74]],"ltp":2.7,"tv":3058.21,"id":26314798},{"batb":[[0,10,3.72]],"ltp":10.5,"tv":590.34,"id":420}]}]}
{"op":"mcm","clk":"993950054","pt":1580547998575,"mc":[{"id":"1.168130661","rc":[{"trd":[[18,39.39]],"batb":[[0,17.5,6.93],[1,17,9.26],[2,16,13.52]],"ltp":18.0,"tv":379.29,"id":24707172}],"tv":7937.45}]}
{"op":"mcm","clk":"993950774","pt":1580548006696,"mc":[{"id":"1.168130661","rc":[{"batl":[[0,12.5,6.8]],"ltp":12.5,"tv":727.59,"id":24420205}]}]}
{"op":"mcm","clk":"993950863","pt":1580548007685,"mc":[{"id":"1.168130661","rc":[{"batb":[[2,11,13.98]],"ltp":12.5,"tv":727.59,"id":24420205},{"batb":[[0,2.68,44.58]],"ltp":2.7,"tv":3058.21,"id":26314798}]}]}
{"op":"mcm","clk":"993951371","pt":1580548013708,"mc":[{"id":"1.168130661","rc":[{"batl":[[0,12.5,11.8],[2,13.5,2]],"ltp":12.5,"tv":727.59,"id":24420205}]}]}
{"op":"mcm","clk":"993952485","pt":1580548026651,"mc":[{"id":"1.168130661","rc":[{"trd":[[2.68,379.9]],"batb":[[0,2.66,12.74],[1,2.64,50.63],[2,2.62,89.95]],"batl":[[0,2.68,39.44],[1,2.72,317.54],[2,2.74,81.55]],"ltp":2.68,"tv":3147.38,"id":26314798}],"tv":8026.62}]}
{"op":"mcm","clk":"993952549","pt":1580548027326,"mc":[{"id":"1.168130661","rc":[{"batl":[[0,2.76,4.03]],"ltp":2.64,"tv":3072.85,"id":25238892},{"batb":[[1,2.64,65.48]],"batl":[[1,2.72,320.54]],"ltp":2.68,"tv":3147.38,"id":26314798}]}]}
{"op":"mcm","clk":"993952739","pt":1580548029646,"mc":[{"id":"1.168130661","rc":[{"batl":[[0,2.78,4.04]],"ltp":2.64,"tv":3072.85,"id":25238892},{"batb":[[0,2.64,46.89],[1,2.62,89.95],[2,2.6,24.29]],"batl":[[1,2.7,3.04],[2,2.72,320.54]],"ltp":2.68,"tv":3147.38,"id":26314798}]}]}
{"op":"mcm","clk":"993952825","pt":1580548030334,"mc":[{"id":"1.168130661","rc":[{"batb":[[0,2.64,42.63],[1,2.62,103.97]],"ltp":2.68,"tv":3147.38,"id":26314798}]}]}
{"op":"mcm","clk":"993964768","pt":1580548054658,"mc":[{"id":"1.168130661","rc":[{"trd":[[2.68,146.49]],"batb":[[0,2.66,10.48],[1,2.64,6.32],[2,2.62,82.95]],"batl":[[0,2.68,15.82],[1,2.78,4.04],[2,2.8,5.26]],"ltp":2.68,"tv":3091.21,"id":25238892},{"batb":[[0,12,5.64]],"ltp":12.5,"tv":727.59,"id":24420205},{"trd":[[2.68,396.72]],"batb":[[0,2.64,51.63]],"batl":[[0,2.68,31.03]],"ltp":2.68,"tv":3164.2,"id":26314798}],"tv":8061.8}]}
{"op":"mcm","clk":"993965046","pt":1580548057676,"mc":[{"id":"1.168130661","rc":[{"batl":[[1,2.76,13.77],[2,2.78,12.48]],"ltp":2.68,"tv":3091.21,"id":25238892}]}]}
{"op":"mcm","clk":"993965214","pt":1580548059653,"mc":[{"id":"1.168130661","rc":[{"trd":[[2.66,100.25]],"batb":[[0,2.64,6.32],[1,2.62,82.95],[2,2.56,6]],"batl":[[0,2.66,5.34]],"ltp":2.66,"tv":3112.17,"id":25238892}],"tv":8082.76}]}
{"op":"mcm","clk":"993965291","pt":1580548060487,"mc":[{"id":"1.168130661","rc":[{"trd":[[2.66,110.93]],"batb":[[0,2.64,4.18],[2,2.6,4.22]],"batl":[[0,2.76,13.77],[1,2.78,26.25],[2,2.8,5.26]],"ltp":2.66,"tv":3122.85,"id":25238892},{"batb":[[0,12,3.64]],"ltp":12.5,"tv":727.59,"id":24420205},{"batb":[[0,2.64,42.63]],"batl":[[1,2.7,3.22]],"ltp":2.68,"tv":3164.2,"id":26314798}],"tv":8093.44}]}
{"op":"mcm","clk":"993965373","pt":1580548061580,"mc":[{"id":"1.168130661","rc":[{"batb":[[0,30,6.88]],"ltp":32.0,"tv":109.13,"id":25545675},{"batl":[[0,2.74,2],[1,2.76,13.77],[2,2.78,12.48]],"ltp":2.66,"tv":3122.85,"id":25238892}]}]}
{"op":"mcm","clk":"993965896","pt":1580548067695,"mc":[{"id":"1.168130661","rc":[{"batb":[[2,28,5.18]],"ltp":32.0,"tv":109.13,"id":25545675}]}]}
{"op":"mcm","clk":"993966204","pt":1580548071693,"mc":[{"id":"1.168130661","rc":[{"trd":[[2.64,168.77]],"batb":[[0,2.64,4.28],[2,2.56,6]],"batl":[[1,2.78,7],[2,2.8,8.08]],"ltp":2.64,"tv":3132.85,"id":25238892},{"batb":[[1,2.62,107.97]],"ltp":2.68,"tv":3164.2,"id":26314798}],"tv":8103.44}]}
{"op":"mcm","clk":"993966442","pt":1580548074704,"mc":[{"id":"1.168130661","rc":[{"batb":[[2,2.52,7.92]],"ltp":2.64,"tv":3132.85,"id":25238892}]}]}
{"op":"mcm","clk":"993966506","pt":1580548075385,"mc":[{"id":"1.168130661","rc":[{"batb":[[0,30,7.47]],"ltp":32.0,"tv":109.13,"id":25545675}]}]}
{"op":"mcm","clk":"993967204","pt":1580548083414,"mc":[{"id":"1.168130661","rc":[{"batb":[[0,30,3.76]],"ltp":32.0,"tv":109.13,"id":25545675}]}]}
{"op":"mcm","clk":"993967315","pt":1580548084717,"mc":[{"id":"1.168130661","rc":[{"trd":[[12.5,83.82]],"batb":[[0,12,5.64]],"batl":[[0,12.5,1.8]],"ltp":12.5,"tv":747.59,"id":24420205}],"tv":8123.44}]}
{"op":"mcm","clk":"993967881","pt":1580548090703,"mc":[{"id":"1.168130661","rc":[{"batb":[[0,30,3.18]],"ltp":32.0,"tv":109.13,"id":25545675}]}]}
{"op":"mcm","clk":"993968423","pt":1580548097457,"mc":[{"id":"1.168130661","rc":[{"batb":[[1,29,4.9]],"ltp":32.0,"tv":109.13,"id":25545675}]}]}
{"op":"mcm","clk":"993968703","pt":1580548100722,"mc":[{"id":"1.168130661","rc":[{"batl":[[2,2.8,7]],"ltp":2.64,"tv":3132.85,"id":25238892}]}]}
{"op":"mcm","clk":"993968762","pt":1580548101657,"mc":[{"id":"1.168130661","rc":[{"batl":[[1,2.76,1.1],[2,2.78,7]],"ltp":2.64,"tv":3132.85,"id":25238892}]}]}
{"op":"mcm","clk":"993969226","pt":1580548107652,"mc":[{"id":"1.168130661","rc":[{"trd":[[2.66,248.22]],"batl":[[0,2.66,2.84],[1,2.68,31.03],[2,2.7,3.22]],"ltp":2.66,"tv":3186.52,"id":26314798}],"tv":8145.76}]}
{"op":"mcm","clk":"993969305","pt":1580548108639,"mc":[{"id":"1.168130661","rc":[{"batl":[[0,12.5,3.8]],"ltp":12.5,"tv":747.59,"id":24420205},{"batb":[[2,2.6,35.29]],"ltp":2.66,"tv":3186.52,"id":26314798}]}]}
{"op":"mcm","clk":"993969539","pt":1580548111654,"mc":[{"id":"1.168130661","rc":[{"trd":[[12,96.05]],"batb":[[0,11.5,1.21],[1,11,13.98],[2,10.5,10.56]],"ltp":12.0,"tv":758.87,"id":24420205}],"tv":8157.03}]}
{"op":"mcm","clk":"993969690","pt":1580548113682,"mc":[{"id":"1.168130661","rc":[{"batb":[[1,11,8.36],[2,10.5,13.04]],"ltp":12.0,"tv":758.87,"id":24420205},{"batl":[[0,2.66,2]],"ltp":2.66,"tv":3186.52,"id":26314798}]}]}
{"op":"mcm","clk":"993969839","pt":1580548115577,"mc":[{"id":"1.168130661","rc":[{"batb":[[0,30,6.88]],"ltp":32.0,"tv":109.13,"id":25545675},{"batb":[[2,10.5,10.56]],"ltp":12.0,"tv":758.87,"id":24420205}]}]}
{"op":"mcm","clk":"993970014","pt":1580548117659,"mc":[{"id":"1.168130661","rc":[{"batb":[[0,2.64,53.63]],"batl":[[0,2.68,31.03],[1,2.7,5.22],[2,2.72,320.54]],"ltp":2.66,"tv":3186.52,"id":26314798}]}]}
{"op":"mcm","clk":"993971551","pt":1580548135312,"mc":[{"id":"1.168130661","rc":[{"batb":[[0,10,13.72]],"ltp":10.5,"tv":590.34,"id":420}]}]}
{"op":"mcm","clk":"993971851","pt":1580548138584,"mc":[{"id":"1.168130661","rc":[{"trd":[[17,28.94],[17.5,31.12],[18,41.25]],"batb":[[0,16,13.52],[1,15,5.37],[2,14.5,9.12]],"batl":[[0,17,5.7],[1,18,2.63],[2,18.5,2.41]],"ltp":17.0,"tv":417.89,"id":24707172},{"batb":[[1,9.8,9.47]],"ltp":10.5,"tv":590.34,"id":420}],"tv":8195.63}]}
{"op":"mcm","clk":"993971957","pt":1580548139624,"mc":[{"id":"1.168130661","rc":[{"batl":[[1,19,2],[2,19.5,1.7]],"ltp":17.0,"tv":417.89,"id":24707172}]}]}
{"op":"mcm","clk":"993972063","pt":1580548140614,"mc":[{"id":"1.168130661","rc":[{"batb":[[0,16,15.52],[1,15,8.54]],"batl":[[1,17.5,2],[2,20,8.25]],"ltp":17.0,"tv":417.89,"id":24707172}]}]}
{"op":"mcm","clk":"993972156","pt":1580548141709,"mc":[{"id":"1.168130661","rc":[{"batb":[[1,15,13.91]],"ltp":17.0,"tv":417.89,"id":24707172}]}]}
{"op":"mcm","clk":"993973607","pt":1580548158627,"mc":[{"id":"1.168130661","rc":[{"batb":[[2,2.52,106.92]],"ltp":2.64,"tv":3132.85,"id":25238892}]}]}
{"op":"mcm","clk":"993973710","pt":1580548159718,"mc":[{"id":"1.168130661","rc":[{"batb":[[2,14.5,8.37]],"ltp":17.0,"tv":417.89,"id":24707172}]}]}
{"op":"mcm","clk":"993974100","pt":1580548163642,"mc":[{"id":"1.168130661","rc":[{"batb":[[1,15.5,2.12],[2,15,13.91]],"batl":[[0,16.5,6],[1,17,7.7],[2,17.5,2]],"ltp":17.0,"tv":417.89,"id":24707172},{"batl":[[1,2.7,2]],"ltp":2.66,"tv":3186.52,"id":26314798}]}]}
{"op":"mcm","clk":"993974349","pt":1580548165631,"mc":[{"id":"1.168130661","rc":[{"batl":[[0,2.72,2],[1,2.74,2],[2,2.76,1.1]],"ltp":2.64,"tv":3132.85,"id":25238892}]}]}
{"op":"mcm","clk":"993974687","pt":1580548168614,"mc":[{"id":"1.168130661","rc":[{"batb":[[2,2.54,6]],"ltp":2.64,"tv":3132.85,"id":25238892}]}]}
{"op":"mcm","clk":"993975462","pt":1580548176664,"mc":[{"id":"1.168130661","rc":[{"batb":[[0,2.64,62.52]],"ltp":2.66,"tv":3186.52,"id":26314798}]}]}
{"op":"mcm","clk":"993978048","pt":1580548203703,"mc":[{"id":"1.168130661","rc":[{"batb":[[0,2.66,11.26],[1,2.64,62.52],[2,2.62,107.97]],"ltp":2.66,"tv":3186.52,"id":26314798}]}]}
{"op":"mcm","clk":"993978162","pt":1580548204695,"mc":[{"id":"1.168130661","rc":[{"trd":[[2.68,428.04]],"batl":[[0,2.68,15.37]],"ltp":2.68,"tv":3217.84,"id":26314798}],"tv":8226.95}]}
{"op":"mcm","clk":"993978281","pt":1580548205681,"mc":[{"id":"1.168130661","rc":[{"batb":[[1,2.64,66.48],[2,2.62,93.95]],"ltp":2.68,"tv":3217.84,"id":26314798}]}]}
{"op":"mcm","clk":"993982973","pt":1580548249683,"mc":[{"id":"1.168130661","rc":[{"trd":[[46,0.11]],"batl":[[0,60,1.56],[1,65,2]],"ltp":46.0,"tv":109.24,"id":25545675},{"trd":[[2.72,199.21]],"batl":[[0,2.74,2],[1,2.76,1.1],[2,2.78,7]],"ltp":2.72,"tv":3134.99,"id":25238892},{"trd":[[16.5,9.09]],"batl":[[0,16.5,5.69]],"ltp":16.5,"tv":418.2,"id":24707172},{"trd":[[11,49.61],[11.5,116.64]],"batb":[[0,11.5,2.03],[1,11,8.78]],"ltp":11.0,"tv":778.43,"id":24420205},{"trd":[[2.68,429.93]],"batl":[[0,2.68,13.48]],"ltp":2.68,"tv":3219.73,"id":26314798},{"trd":[[11,44.8]],"batl":[[0,11,2.84]],"ltp":11.0,"tv":590.8,"id":420}],"tv":8251.42}]}
{"op":"mcm","clk":"993983505","pt":1580548254673,"mc":[{"id":"1.168130661","rc":[{"batl":[[0,50,1.15],[1,65,2.61]],"ltp":46.0,"tv":109.24,"id":25545675},{"batb":[[0,2.64,66.48],[1,2.62,93.95],[2,2.6,35.29]],"ltp":2.68,"tv":3219.73,"id":26314798}]}]}
{"op":"mcm","clk":"993983591","pt":1580548255602,"mc":[{"id":"1.168130661","rc":[{"batb":[[0,2.64,62.52],[1,2.62,108.82]],"ltp":2.68,"tv":3219.73,"id":26314798}]}]}
{"op":"mcm","clk":"993984053","pt":1580548259679,"mc":[{"id":"1.168130661","rc":[{"batb":[[0,2.66,2],[1,2.64,4.28],[2,2.62,82.95]],"ltp":2.72,"tv":3134.99,"id":25238892}]}]}
{"op":"mcm","clk":"993984159","pt":1580548260682,"mc":[{"id":"1.168130661","rc":[{"batb":[[0,2.68,4.32],[1,2.66,2],[2,2.64,4.28]],"ltp":2.72,"tv":3134.99,"id":25238892}]}]}
{"op":"mcm","clk":"993984882","pt":1580548267694,"mc":[{"id":"1.168130661","rc":[{"batl":[[0,2.66,1.68],[1,2.68,13.48],[2,2.7,2]],"ltp":2.68,"tv":3219.73,"id":26314798}]}]}
{"op":"mcm","clk":"993984962","pt":1580548268575,"mc":[{"id":"1.168130661","rc":[{"batb":[[0,16,13.52],[2,15,15.91]],"ltp":16.5,"tv":418.2,"id":24707172},{"batb":[[0,11,8.78],[1,10.5,10.56],[2,10,19.27]],"ltp":11.0,"tv":778.43,"id":24420205},{"trd":[[2.66,251.58]],"batl":[[0,2.68,13.48],[1,2.7,2],[2,2.72,320.54]],"ltp":2.66,"tv":3223.09,"id":26314798}],"tv":8254.79}]}
{"op":"mcm","clk":"993985056","pt":1580548269709,"mc":[{"id":"1.168130661","rc":[{"batb":[[1,2.62,96.96]],"ltp":2.66,"tv":3223.09,"id":26314798}]}]}
{"op":"mcm","clk":"993985240","pt":1580548271691,"mc":[{"id":"1.168130661","rc":[{"trd":[[2.74,232.91]],"batl":[[0,2.74,10.87],[1,2.76,7.16]],"ltp":2.74,"tv":3138.99,"id":25238892},{"batb":[[1,2.62,107.97]],"ltp":2.66,"tv":3223.09,"id":26314798},{"batb":[[0,10.5,2.06],[1,10,13.72],[2,9.8,9.47]],"ltp":11.0,"tv":590.8,"id":420}],"tv":8258.79}]}
{"op":"mcm","clk":"993985433","pt":1580548273690,"mc":[{"id":"1.168130661","rc":[{"batl":[[1,2.76,1.1]],"ltp":2.74,"tv":3138.99,"id":25238892},{"batb":[[2,9.8,4.31]],"ltp":11.0,"tv":590.8,"id":420}]}]}
{"op":"mcm","clk":"993985896","pt":1580548278682,"mc":[{"id":"1.168130661","rc":[{"batb":[[0,10,13.72],[1,9.8,4.31],[2,9.6,6.84]],"ltp":11.0,"tv":590.8,"id":420}]}]}
{"op":"mcm","clk":"993986157","pt":1580548281623,"mc":[{"id":"1.168130661","rc":[{"batb":[[0,2.7,6.11],[1,2.68,4.32],[2,2.66,2]],"ltp":2.74,"tv":3138.99,"id":25238892}]}]}
{"op":"mcm","clk":"993986238","pt":1580548282512,"mc":[{"id":"1.168130661","rc":[{"batb":[[1,9.8,9.47]],"ltp":11.0,"tv":590.8,"id":420}]}]}
{"op":"mcm","clk":"993987842","pt":1580548297714,"mc":[{"id":"1.168130661","rc":[{"batl":[[0,2.74,21.87]],"ltp":2.74,"tv":3138.99,"id":25238892},{"batb":[[0,10.5,2.2],[1,10,13.72],[2,9.8,9.47]],"ltp":11.0,"tv":590.8,"id":420}]}]}
{"op":"mcm","clk":"993987928","pt":1580548298707,"mc":[{"id":"1.168130661","rc":[{"batl":[[2,2.78,13.26]],"ltp":2.74,"tv":3138.99,"id":25238892}]}]}
{"op":"mcm","clk":"993988021","pt":1580548299642,"mc":[{"id":"1.168130661","rc":[{"trd":[[2.68,474.02]],"batb":[[0,2.68,57.95],[1,2.66,10.21],[2,2.64,62.52]],"batl":[[0,2.7,12.99],[1,2.72,320.54],[2,2.74,81.55]],"ltp":2.68,"tv":3267.19,"id":26314798},{"batb":[[2,9.8,4.31]],"ltp":11.0,"tv":590.8,"id":420}],"tv":8302.88}]}
{"op":"mcm","clk":"993988209","pt":1580548301621,"mc":[{"id":"1.168130661","rc":[{"batb":[[1,2.66,24.2]],"ltp":2.68,"tv":3267.19,"id":26314798}]}]}
{"op":"mcm","clk":"993988518","pt":1580548304704,"mc":[{"id":"1.168130661","rc":[{"batb":[[0,2.7,2],[2,2.66,6.24]],"batl":[[1,2.76,35.1]],"ltp":2.74,"tv":3138.99,"id":25238892}]}]}
{"op":"mcm","clk":"993991185","pt":1580548328654,"mc":[{"id":"1.168130661","rc":[{"batb":[[2,9.8,2.31]],"ltp":11.0,"tv":590.8,"id":420}]}]}
{"op":"mcm","clk":"993991283","pt":1580548329483,"mc":[{"id":"1.168130661","rc":[{"batb":[[0,10.5,4.2]],"ltp":11.0,"tv":590.8,"id":420}]}]}
{"op":"mcm","clk":"993991967","pt":1580548336657,"mc":[{"id":"1.168130661","rc":[{"batl":[[1,2.76,29.1]],"ltp":2.74,"tv":3138.99,"id":25238892},{"batl":[[0,2.7,62.99]],"ltp":2.68,"tv":3267.19,"id":26314798},{"batl":[[0,11.5,15.73],[1,12,5.75],[2,14.5,17]],"ltp":11.0,"tv":590.8,"id":420}]}]}
{"op":"mcm","clk":"993992158","pt":1580548338696,"mc":[{"id":"1.168130661","rc":[{"batl":[[2,15.5,2.32]],"ltp":11.0,"tv":590.8,"id":420}]}]}
{"op":"mcm","clk":"993992391","pt":1580548340681,"mc":[{"id":"1.168130661","rc":[{"batl":[[0,2.7,64.99]],"ltp":2.68,"tv":3267.19,"id":26314798}]}]}
{"op":"mcm","clk":"993999237","pt":1580548402557,"mc":[{"id":"1.168130661","rc":[{"batl":[[0,2.74,27.87]],"ltp":2.74,"tv":3138.99,"id":25238892}]}]}
{"op":"mcm","clk":"994003959","pt":1580548446622,"mc":[{"id":"1.168130661","rc":[{"batb":[[1,10,3.72]],"batl":[[0,11,2.03],[1,11.5,15.73],[2,12,5.75]],"ltp":11.0,"tv":590.8,"id":420}]}]}
{"op":"mcm","clk":"994004084","pt":1580548447716,"mc":[{"id":"1.168130661","rc":[{"batb":[[0,2.7,6.03]],"batl":[[0,2.74,21.87]],"ltp":2.74,"tv":3138.99,"id":25238892},{"trd":[[11,48.86]],"batb":[[0,10.5,2],[1,10,2],[2,9.8,5.62]],"batl":[[0,11,2]],"ltp":11.0,"tv":594.86,"id":420}],"tv":8306.94}]}
{"op":"mcm","clk":"994004280","pt":1580548449692,"mc":[{"id":"1.168130661","rc":[{"batb":[[1,10,4],[2,9.8,2.31]],"ltp":11.0,"tv":594.86,"id":420}]}]}
{"op":"mcm","clk":"994004398","pt":1580548450631,"mc":[{"id":"1.168130661","rc":[{"batb":[[0,11.5,1.5],[1,11,8.78],[2,10.5,10.56]],"ltp":11.0,"tv":778.43,"id":24420205},{"batb":[[1,10,8]],"ltp":11.0,"tv":594.86,"id":420}]}]}
{"op":"mcm","clk":"994004519","pt":1580548451721,"mc":[{"id":"1.168130661","rc":[{"batb":[[0,10.5,4],[1,10,10]],"batl":[[0,11.5,15.73],[1,12,5.75],[2,15.5,2.32]],"ltp":11.0,"tv":594.86,"id":420}]}]}
{"op":"mcm","clk":"994004842","pt":1580548454630,"mc":[{"id":"1.168130661","rc":[{"batb":[[0,30,3.18]],"ltp":46.0,"tv":109.24,"id":25545675},{"batl":[[1,2.72,343.74]],"ltp":2.68,"tv":3267.19,"id":26314798},{"batl":[[0,11,2.08],[1,11.5,15.73],[2,12,5.75]],"ltp":11.0,"tv":594.86,"id":420}]}]}
{"op":"mcm","clk":"994004961","pt":1580548455628,"mc":[{"id":"1.168130661","rc":[{"trd":[[10.5,110.86]],"batb":[[0,9.4,9.01],[1,9.2,2.49],[2,9,18.98]],"batl":[[0,11,2.73]],"ltp":10.5,"tv":598.86,"id":420}],"tv":8310.94}]}
{"op":"mcm","clk":"994005414","pt":1580548459719,"mc":[{"id":"1.168130661","rc":[{"trd":[[10.5,112.16]],"batb":[[0,10.5,1.45],[1,10,10],[2,9.4,6.93]],"batl":[[0,11.5,15.73],[1,12,5.75],[2,14.5,17]],"ltp":10.5,"tv":600.16,"id":420}],"tv":8312.24}]}
{"op":"mcm","clk":"994005733","pt":1580548462538,"mc":[{"id":"1.168130661","rc":[{"batb":[[0,30,6.88]],"ltp":46.0,"tv":109.24,"id":25545675}]}]}
{"op":"mcm","clk":"994005934","pt":1580548464342,"mc":[{"id":"1.168130661","rc":[{"batl":[[0,2.7,62.99]],"ltp":2.68,"tv":3267.19,"id":26314798}]}]}
{"op":"mcm","clk":"994007118","pt":1580548475721,"mc":[{"id":"1.168130661","rc":[{"batb":[[2,9.6,2]],"ltp":10.5,"tv":600.16,"id":420}]}]}
{"op":"mcm","clk":"994007851","pt":1580548482457,"mc":[{"id":"1.168130661","rc":[{"batb":[[0,9.8,6.58],[1,9.6,2],[2,9.2,2.49]],"batl":[[0,11,2.23],[1,11.5,15.73],[2,12,5.75]],"ltp":10.5,"tv":600.16,"id":420}]}]}
{"op":"mcm","clk":"994007882","pt":1580548482764,"mc":[{"id":"1.168130661","rc":[{"batb":[[0,9.8,2.23]],"ltp":10.5,"tv":600.16,"id":420}]}]}
{"op":"mcm","clk":"994008059","pt":1580548484676,"mc":[{"id":"1.168130661","rc":[{"batb":[[0,10,10],[1,9.8,2.23],[2,9.6,2]],"ltp":10.5,"tv":600.16,"id":420}]}]}
{"op":"mcm","clk":"994008152","pt":1580548485554,"mc":[{"id":"1.168130661","rc":[{"trd":[[16,42.64]],"batb":[[0,16,2.52]],"ltp":16.0,"tv":440.2,"id":24707172},{"batb":[[0,10.5,2.24],[1,10,10],[2,9.8,2.23]],"ltp":10.5,"tv":600.16,"id":420}],"tv":8334.24}]}
{"op":"mcm","clk":"994008391","pt":1580548487684,"mc":[{"id":"1.168130661","rc":[{"trd":[[16,47.68]],"batb":[[0,15,3.17],[1,14.5,3],[2,14,3]],"batl":[[0,15.5,3.91],[1,16,3.63],[2,16.5,5.69]],"ltp":16.0,"tv":445.24,"id":24707172},{"batl":[[0,11.5,15.73],[1,12,5.75],[2,14.5,17]],"ltp":10.5,"tv":600.16,"id":420}],"tv":8339.28}]}
{"op":"mcm","clk":"994008493","pt":1580548488462,"mc":[{"id":"1.168130661","rc":[{"trd":[[15,72.39]],"batb":[[0,14.5,5],[1,14,3],[2,13.5,12.02]],"batl":[[0,15.5,4.52],[1,16,5.63]],"ltp":15.0,"tv":451.57,"id":24707172},{"batl":[[2,15.5,2.32]],"ltp":10.5,"tv":600.16,"id":420}],"tv":8345.62}]}
{"op":"mcm","clk":"994008678","pt":1580548490178,"mc":[{"id":"1.168130661","rc":[{"trd":[[11,50.61],[11.5,119.64]],"batb":[[0,11,8.28],[1,10.5,10.56],[2,10,19.27]],"ltp":11.0,"tv":782.43,"id":24420205}],"tv":8349.61}]}
{"op":"mcm","clk":"994009146","pt":1580548494700,"mc":[{"id":"1.168130661","rc":[{"batb":[[0,34,2.3],[1,32,3.47],[2,30,3.18]],"ltp":46.0,"tv":109.24,"id":25545675},{"trd":[[14.5,61.84]],"batb":[[0,14,3],[1,13.5,12.02],[2,13,7.54]],"batl":[[0,14.5,7.67],[1,15.5,4.52],[2,16,5.63]],"ltp":14.5,"tv":463.07,"id":24707172}],"tv":8361.11}]}
{"op":"mcm","clk":"994009265","pt":1580548495651,"mc":[{"id":"1.168130661","rc":[{"batb":[[0,14,3.77]],"batl":[[1,15,3.91],[2,15.5,3.91]],"ltp":14.5,"tv":463.07,"id":24707172},{"batl":[[0,12.5,1.8]],"ltp":11.0,"tv":782.43,"id":24420205},{"batb":[[0,10.5,4.24],[1,9.8,2.23],[2,9.2,2.49]],"ltp":10.5,"tv":600.16,"id":420}]}]}
{"op":"mcm","clk":"994009729","pt":1580548499695,"mc":[{"id":"1.168130661","rc":[{"batl":[[0,60,1.56],[1,65,2]],"ltp":46.0,"tv":109.24,"id":25545675},{"batb":[[0,10.5,2],[1,10,2.32],[2,9.8,2.23]],"batl":[[0,11,2.32],[1,11.5,15.73],[2,12,5.75]],"ltp":10.5,"tv":600.16,"id":420}]}]}
{"op":"mcm","clk":"994009830","pt":1580548500676,"mc":[{"id":"1.168130661","rc":[{"batb":[[2,9.8,5.71]],"ltp":10.5,"tv":600.16,"id":420}]}]}
{"op":"mcm","clk":"994009949","pt":1580548501723,"mc":[{"id":"1.168130661","rc":[{"batb":[[0,14,4.91]],"ltp":14.5,"tv":463.07,"id":24707172},{"batb":[[0,2.68,72.17],[2,2.64,39.2]],"ltp":2.68,"tv":3267.19,"id":26314798},{"batb":[[2,9.8,2.23]],"batl":[[0,11,2]],"ltp":10.5,"tv":600.16,"id":420}]}]}
{"op":"mcm","clk":"994010052","pt":1580548502611,"mc":[{"id":"1.168130661","rc":[{"batb":[[0,34,3.27],[1,32,2.01]],"ltp":46.0,"tv":109.24,"id":25545675}]}]}
{"op":"mcm","clk":"994010197","pt":1580548503705,"mc":[{"id":"1.168130661","rc":[{"batb":[[2,30,5.62]],"ltp":46.0,"tv":109.24,"id":25545675},{"batb":[[2,9.8,4.36]],"ltp":10.5,"tv":600.16,"id":420}]}]}
{"op":"mcm","clk":"994010300","pt":1580548504596,"mc":[{"id":"1.168130661","rc":[{"batb":[[1,32,2.66],[2,30,3.62]],"ltp":46.0,"tv":109.24,"id":25545675},{"batl":[[0,13,18.8],[1,13.5,2],[2,14,2.36]],"ltp":11.0,"tv":782.43,"id":24420205},{"batl":[[1,2.72,340.74]],"ltp":2.68,"tv":3267.19,"id":26314798},{"batb":[[0,10,2.32],[1,9.8,4.36],[2,9.2,2.49]],"batl":[[0,11.5,15.73],[1,12,5.75],[2,15.5,2.32]],"ltp":10.5,"tv":600.16,"id":420}]}]}
{"op":"mcm","clk":"994010534","pt":1580548506382,"mc":[{"id":"1.168130661","rc":[{"batb":[[0,36,2.03],[1,34,3.27],[2,32,2.66]],"ltp":46.0,"tv":109.24,"id":25545675}]}]}
{"op":"mcm","clk":"994010950","pt":1580548509656,"mc":[{"id":"1.168130661","rc":[{"trd":[[2.7,576.82]],"batl":[[0,2.7,58.09]],"ltp":2.7,"tv":3276.99,"id":26314798}],"tv":8370.91}]}
{"op":"mcm","clk":"994011094","pt":1580548510998,"mc":[{"id":"1.168130661","rc":[{"trd":[[2.68,487.6]],"batb":[[0,2.68,65.38]],"ltp":2.68,"tv":3290.57,"id":26314798}],"tv":8384.49}]}
{"op":"mcm","clk":"994011625","pt":1580548515414,"mc":[{"id":"1.168130661","rc":[{"batb":[[2,32,3.22]],"ltp":46.0,"tv":109.24,"id":25545675},{"batb":[[0,10,4.32]],"ltp":10.5,"tv":600.16,"id":420}]}]}
{"op":"mcm","clk":"994011878","pt":1580548517702,"mc":[{"id":"1.168130661","rc":[{"batb":[[0,14,4.14],[1,13.5,12.82]],"ltp":14.5,"tv":463.07,"id":24707172}]}]}
{"op":"mcm","clk":"994013549","pt":1580548531706,"mc":[{"id":"1.168130661","rc":[{"batb":[[1,2.66,38.52]],"ltp":2.68,"tv":3290.57,"id":26314798}]}]}
{"op":"mcm","clk":"994014561","pt":1580548540258,"mc":[{"id":"1.168130661","rc":[{"batl":[[0,11,2.21],[1,11.5,15.73],[2,12,5.75]],"ltp":10.5,"tv":600.16,"id":420}]}]}
{"op":"mcm","clk":"994016653","pt":1580548557573,"mc":[{"id":"1.168130661","rc":[{"batl":[[0,2.72,100],[1,2.74,21.87],[2,2.76,29.1]],"ltp":2.74,"tv":3138.99,"id":25238892}]}]}
{"op":"mcm","clk":"994016780","pt":1580548558668,"mc":[{"id":"1.168130661","rc":[{"trd":[[2.72,236.52]],"batb":[[0,2.7,2]],"batl":[[0,2.72,81.34]],"ltp":2.72,"tv":3176.31,"id":25238892},{"batl":[[0,13,16.8]],"ltp":11.0,"tv":782.43,"id":24420205}],"tv":8421.81}]}
{"op":"mcm","clk":"994016904","pt":1580548559719,"mc":[{"id":"1.168130661","rc":[{"batb":[[0,36,3.09],[1,34,2.32]],"ltp":46.0,"tv":109.24,"id":25545675},{"trd":[[14,31.97]],"batb":[[0,13.5,13.43],[1,13,7.54],[2,12.5,2]],"ltp":14.0,"tv":470.13,"id":24707172}],"tv":8428.87}]}
{"op":"mcm","clk":"994016985","pt":1580548560612,"mc":[{"id":"1.168130661","rc":[{"batb":[[0,13.5,12.63]],"ltp":14.0,"tv":470.13,"id":24707172}]}]}
{"op":"mcm","clk":"994017330","pt":1580548564175,"mc":[{"id":"1.168130661","rc":[{"batb":[[1,32,3.22],[2,30,1.18]],"ltp":46.0,"tv":109.24,"id":25545675},{"batl":[[0,13,18.8]],"ltp":11.0,"tv":782.43,"id":24420205},{"batb":[[0,2.68,75.38]],"ltp":2.68,"tv":3290.57,"id":26314798}]}]}
{"op":"mcm","clk":"994017694","pt":1580548567657,"mc":[{"id":"1.168130661","rc":[{"batb":[[0,34,5.31]],"ltp":46.0,"tv":109.24,"id":25545675}]}]}
{"op":"mcm","clk":"994017784","pt":1580548568484,"mc":[{"id":"1.168130661","rc":[{"batb":[[0,14,2.61],[1,13.5,12.82],[2,13,7.54]],"ltp":14.0,"tv":470.13,"id":24707172}]}]}
{"op":"mcm","clk":"994018611","pt":1580548575593,"mc":[{"id":"1.168130661","rc":[{"batb":[[0,36,3.09],[1,34,2.04],[2,32,3.22]],"ltp":46.0,"tv":109.24,"id":25545675}]}]}
{"op":"mcm","clk":"994018707","pt":1580548576481,"mc":[{"id":"1.168130661","rc":[{"batb":[[0,36,5.09]],"ltp":46.0,"tv":109.24,"id":25545675}]}]}
{"op":"mcm","clk":"994018971","pt":1580548578684,"mc":[{"id":"1.168130661","rc":[{"batb":[[0,14,4.61]],"ltp":14.0,"tv":470.13,"id":24707172},{"batb":[[2,10,21.27]],"ltp":11.0,"tv":782.43,"id":24420205},{"batb":[[2,9.6,2]],"ltp":10.5,"tv":600.16,"id":420}]}]}
{"op":"mcm","clk":"994019109","pt":1580548579982,"mc":[{"id":"1.168130661","rc":[{"batl":[[0,60,3.33]],"ltp":46.0,"tv":109.24,"id":25545675}]}]}
{"op":"mcm","clk":"994020309","pt":1580548589675,"mc":[{"id":"1.168130661","rc":[{"trd":[[14.5,77.17],[15,73.61]],"batb":[[0,14.5,2.2],[1,14,4.61],[2,13.5,12.02]],"batl":[[0,15.5,3.91],[1,16,3.63],[2,16.5,5.69]],"ltp":15.0,"tv":486.69,"id":24707172}],"tv":8445.42}]}
{"op":"mcm","clk":"994020413","pt":1580548590705,"mc":[{"id":"1.168130661","rc":[{"batl":[[1,2.74,27.87]],"ltp":2.72,"tv":3176.31,"id":25238892},{"batl":[[1,16,3]],"ltp":15.0,"tv":486.69,"id":24707172},{"batb":[[0,2.68,65.38]],"ltp":2.68,"tv":3290.57,"id":26314798}]}]}
{"op":"mcm","clk":"994020512","pt":1580548591577,"mc":[{"id":"1.168130661","rc":[{"batb":[[1,34,4.58]],"ltp":46.0,"tv":109.24,"id":25545675}]}]}
{"op":"mcm","clk":"994021263","pt":1580548598409,"mc":[{"id":"1.168130661","rc":[{"trd":[[2.7,160.32]],"batb":[[0,2.68,4.32],[1,2.66,8.27],[2,2.64,4.28]],"ltp":2.7,"tv":3180.31,"id":25238892},{"batl":[[0,13,20.8]],"ltp":11.0,"tv":782.43,"id":24420205}],"tv":8449.42}]}
{"op":"mcm","clk":"994022580","pt":1580548609011,"mc":[{"id":"1.168130661","rc":[{"batb":[[1,34,2.04]],"ltp":46.0,"tv":109.24,"id":25545675}]}]}
{"op":"mcm","clk":"994023884","pt":1580548618711,"mc":[{"id":"1.168130661","rc":[{"batl":[[1,2.74,21.87]],"ltp":2.7,"tv":3180.31,"id":25238892},{"batb":[[0,12,2.32],[1,11.5,3.81],[2,11,8.28]],"ltp":11.0,"tv":782.43,"id":24420205},{"batb":[[0,2.68,75.38]],"ltp":2.68,"tv":3290.57,"id":26314798}]}]}
{"op":"mcm","clk":"994023929","pt":1580548619137,"mc":[{"id":"1.168130661","rc":[{"batb":[[1,34,4.58]],"ltp":46.0,"tv":109.24,"id":25545675},{"batl":[[0,2.7,2],[1,2.72,81.34],[2,2.74,21.87]],"ltp":2.7,"tv":3180.31,"id":25238892}]}]}
{"op":"mcm","clk":"994024104","pt":1580548620648,"mc":[{"id":"1.168130661","rc":[{"batb":[[1,34,2.04]],"ltp":46.0,"tv":109.24,"id":25545675}]}]}
{"op":"mcm","clk":"994024168","pt":1580548621224,"mc":[{"id":"1.168130661","rc":[{"batl":[[2,2.74,27.87]],"ltp":2.7,"tv":3180.31,"id":25238892}]}]}
{"op":"mcm","clk":"994024319","pt":1580548622639,"mc":[{"id":"1.168130661","rc":[{"batb":[[1,34,4.58]],"ltp":46.0,"tv":109.24,"id":25545675}]}]}
{"op":"mcm","clk":"994025822","pt":1580548634710,"mc":[{"id":"1.168130661","rc":[{"batb":[[1,34,2.04]],"ltp":46.0,"tv":109.24,"id":25545675},{"batl":[[0,2.72,81.34],[1,2.74,21.87],[2,2.76,29.1]],"ltp":2.7,"tv":3180.31,"id":25238892}]}]}
{"op":"mcm","clk":"994025932","pt":1580548635659,"mc":[{"id":"1.168130661","rc":[{"batb":[[1,34,4.58]],"ltp":46.0,"tv":109.24,"id":25545675}]}]}
{"op":"mcm","clk":"994028608","pt":1580548658682,"mc":[{"id":"1.168130661","rc":[{"trd":[[50,4.07]],"batl":[[0,60,2.59]],"ltp":50.0,"tv":110.72,"id":25545675}],"tv":8450.9}]}
{"op":"mcm","clk":"994028932","pt":1580548661672,"mc":[{"id":"1.168130661","rc":[{"trd":[[50,4.33]],"batl":[[0,60,2.46]],"ltp":50.0,"tv":110.98,"id":25545675}],"tv":8451.16}]}
{"op":"mcm","clk":"994029389","pt":1580548665698,"mc":[{"id":"1.168130661","rc":[{"trd":[[50,4.37]],"batb":[[1,34,2.04]],"batl":[[0,60,2.44]],"ltp":50.0,"tv":111.01,"id":25545675}],"tv":8451.19}]}
{"op":"mcm","clk":"994029716","pt":1580548668700,"mc":[{"id":"1.168130661","rc":[{"trd":[[50,4.39]],"batl":[[0,60,2.43]],"ltp":50.0,"tv":111.03,"id":25545675}],"tv":8451.21}]}
{"op":"mcm","clk":"994030137","pt":1580548672718,"mc":[{"id":"1.168130661","rc":[{"batl":[[1,2.74,27.87]],"ltp":2.7,"tv":3180.31,"id":25238892},{"batb":[[0,11.5,5.81],[1,11,8.28],[2,10.5,10.56]],"batl":[[0,12.5,2.28],[1,13,20.8],[2,13.5,2]],"ltp":11.0,"tv":782.43,"id":24420205},{"batb":[[0,2.68,65.38]],"batl":[[1,2.72,342.74]],"ltp":2.68,"tv":3290.57,"id":26314798},{"trd":[[11,57.62]],"batl":[[0,11,2.12]],"ltp":11.0,"tv":608.92,"id":420}],"tv":8459.97}]}
{"op":"mcm","clk":"994030274","pt":1580548673660,"mc":[{"id":"1.168130661","rc":[{"batb":[[1,34,4.58]],"ltp":50.0,"tv":111.03,"id":25545675}]}]}
{"op":"mcm","clk":"994030392","pt":1580548674607,"mc":[{"id":"1.168130661","rc":[{"batb":[[1,34,2.04]],"ltp":50.0,"tv":111.03,"id":25545675},{"batb":[[0,2.68,75.38]],"batl":[[1,2.72,340.74]],"ltp":2.68,"tv":3290.57,"id":26314798}]}]}
{"op":"mcm","clk":"994031181","pt":1580548681620,"mc":[{"id":"1.168130661","rc":[{"trd":[[15.5,60.27]],"batb":[[0,15.5,5.09],[1,14.5,2.2],[2,14,4.61]],"batl":[[0,16,3],[1,16.5,5.69],[2,17,5.7]],"ltp":15.5,"tv":494.5,"id":24707172}],"tv":8467.79}]}
{"op":"mcm","clk":"994031288","pt":1580548682651,"mc":[{"id":"1.168130661","rc":[{"batb":[[1,34,4.58]],"ltp":50.0,"tv":111.03,"id":25545675},{"batl":[[0,16.5,5.69],[1,17,8.7],[2,19,13]],"ltp":15.5,"tv":494.5,"id":24707172},{"batb":[[0,2.68,65.38]],"ltp":2.68,"tv":3290.57,"id":26314798}]}]}
{"op":"mcm","clk":"994031400","pt":1580548683639,"mc":[{"id":"1.168130661","rc":[{"batb":[[1,34,2.04]],"ltp":50.0,"tv":111.03,"id":25545675}]}]}
{"op":"mcm","clk":"994031638","pt":1580548685677,"mc":[{"id":"1.168130661","rc":[{"trd":[[16.5,20.47]],"batb":[[0,16.5,2.31],[1,15.5,5.09],[2,14.5,2.2]],"batl":[[0,17,8.7],[1,19,13],[2,20,8.25]],"ltp":16.5,"tv":505.88,"id":24707172}],"tv":8479.17}]}
{"op":"mcm","clk":"994031734","pt":1580548686461,"mc":[{"id":"1.168130661","rc":[{"batb":[[1,34,4.58]],"ltp":50.0,"tv":111.03,"id":25545675},{"batl":[[0,17,5.7],[1,17.5,3.03],[2,19,15.11]],"ltp":16.5,"tv":505.88,"id":24707172}]}]}
{"op":"mcm","clk":"994031854","pt":1580548687662,"mc":[{"id":"1.168130661","rc":[{"batb":[[1,34,2.04]],"ltp":50.0,"tv":111.03,"id":25545675},{"batl":[[2,19,13]],"ltp":16.5,"tv":505.88,"id":24707172}]}]}
{"op":"mcm","clk":"994031946","pt":1580548688598,"mc":[{"id":"1.168130661","rc":[{"batb":[[0,36,2]],"ltp":50.0,"tv":111.03,"id":25545675}]}]}
{"op":"mcm","clk":"994032056","pt":1580548689640,"mc":[{"id":"1.168130661","rc":[{"batb":[[0,34,5.41],[1,30,4.68],[2,29,5.74]],"ltp":50.0,"tv":111.03,"id":25545675},{"batl":[[1,2.72,342.74]],"ltp":2.68,"tv":3290.57,"id":26314798}]}]}
{"op":"mcm","clk":"994032344","pt":1580548692657,"mc":[{"id":"1.168130661","rc":[{"batb":[[0,32,2.06]],"ltp":50.0,"tv":111.03,"id":25545675}]}]}
{"op":"mcm","clk":"994032765","pt":1580548696665,"mc":[{"id":"1.168130661","rc":[{"batb":[[0,32,5.53]],"ltp":50.0,"tv":111.03,"id":25545675}]}]}
{"op":"mcm","clk":"994032856","pt":1580548697658,"mc":[{"id":"1.168130661","rc":[{"batb":[[0,32,6.09]],"ltp":50.0,"tv":111.03,"id":25545675}]}]}
{"op":"mcm","clk":"994033027","pt":1580548699682,"mc":[{"id":"1.168130661","rc":[{"batl":[[2,20,8.25]],"ltp":16.5,"tv":505.88,"id":24707172}]}]}
{"op":"mcm","clk":"994033857","pt":1580548707574,"mc":[{"id":"1.168130661","rc":[{"batl":[[0,2.7,1.93],[1,2.72,81.34],[2,2.74,27.87]],"ltp":2.7,"tv":3180.31,"id":25238892},{"trd":[[2.7,596.42]],"batl":[[0,2.7,48.29]],"ltp":2.7,"tv":3310.17,"id":26314798}],"tv":8498.77}]}
{"op":"mcm","clk":"994033957","pt":1580548708325,"mc":[{"id":"1.168130661","rc":[{"batl":[[0,2.72,81.34],[1,2.74,27.87],[2,2.76,29.1]],"ltp":2.7,"tv":3180.31,"id":25238892}]}]}
{"op":"mcm","clk":"994035154","pt":1580548718612,"mc":[{"id":"1.168130661","rc":[{"trd":[[11.5,131.26]],"batb":[[0,11,8.28],[1,10.5,10.56],[2,10,21.27]],"ltp":11.5,"tv":794.05,"id":24420205}],"tv":8510.39}]}
{"op":"mcm","clk":"994036560","pt":1580548731721,"mc":[{"id":"1.168130661","rc":[{"trd":[[17,40.34]],"batb":[[0,17,1.3],[1,16.5,2.31],[2,15.5,5.09]],"batl":[[0,18.5,3.03],[1,19.5,2.28],[2,20,10.82]],"ltp":17.0,"tv":517.28,"id":24707172}],"tv":8521.79}]}
{"op":"mcm","clk":"994036778","pt":1580548733704,"mc":[{"id":"1.168130661","rc":[{"batl":[[0,18.5,5.03],[2,20,8.25]],"ltp":17.0,"tv":517.28,"id":24707172}]}]}
{"op":"mcm","clk":"994036979","pt":1580548735623,"mc":[{"id":"1.168130661","rc":[{"batb":[[0,32,5.53]],"ltp":50.0,"tv":111.03,"id":25545675}]}]}
{"op":"mcm","clk":"994037080","pt":1580548736633,"mc":[{"id":"1.168130661","rc":[{"batb":[[0,32,2.06]],"ltp":50.0,"tv":111.03,"id":25545675}]}]}
{"op":"mcm","clk":"994037692","pt":1580548742702,"mc":[{"id":"1.168130661","rc":[{"batb":[[1,30,5.27]],"ltp":50.0,"tv":111.03,"id":25545675}]}]}
{"op":"mcm","clk":"994037775","pt":1580548743639,"mc":[{"id":"1.168130661","rc":[{"batb":[[2,16,6.1]],"ltp":17.0,"tv":517.28,"id":24707172}]}]}
{"op":"mcm","clk":"994038841","pt":1580548753640,"mc":[{"id":"1.168130661","rc":[{"batb":[[2,29,2.3]],"ltp":50.0,"tv":111.03,"id":25545675}]}]}
{"op":"mcm","clk":"994039037","pt":1580548755661,"mc":[{"id":"1.168130661","rc":[{"batl":[[0,55,7.65],[1,60,2.38],[2,65,2]],"ltp":50.0,"tv":111.03,"id":25545675}]}]}
{"op":"mcm","clk":"994039231","pt":1580548757640,"mc":[{"id":"1.168130661","rc":[{"batb":[[2,15.5,5.09]],"ltp":17.0,"tv":517.28,"id":24707172}]}]}
{"op":"mcm","clk":"994039415","pt":1580548759664,"mc":[{"id":"1.168130661","rc":[{"batb":[[1,30,4.68]],"ltp":50.0,"tv":111.03,"id":25545675}]}]}
{"op":"mcm","clk":"994039512","pt":1580548760656,"mc":[{"id":"1.168130661","rc":[{"batl":[[0,55,8.39],[1,60,1.77]],"ltp":50.0,"tv":111.03,"id":25545675}]}]}
{"op":"mcm","clk":"994040267","pt":1580548767651,"mc":[{"id":"1.168130661","rc":[{"batb":[[2,29,2.9]],"ltp":50.0,"tv":111.03,"id":25545675},{"batb":[[0,17,3.3]],"ltp":17.0,"tv":517.28,"id":24707172}]}]}
{"op":"mcm","clk":"994040993","pt":1580548774668,"mc":[{"id":"1.168130661","rc":[{"trd":[[2.7,616.02]],"batl":[[0,2.7,38.49]],"ltp":2.7,"tv":3329.77,"id":26314798}],"tv":8541.39}]}
{"op":"mcm","clk":"994041863","pt":1580548783374,"mc":[{"id":"1.168130661","rc":[{"batl":[[0,55,8.49]],"ltp":50.0,"tv":111.03,"id":25545675}]}]}
{"op":"mcm","clk":"994043145","pt":1580548795593,"mc":[{"id":"1.168130661","rc":[{"batb":[[0,10.5,1.64],[1,10,4.32],[2,9.8,4.36]],"ltp":11.0,"tv":608.92,"id":420}]}]}
{"op":"mcm","clk":"994044053","pt":1580548804527,"mc":[{"id":"1.168130661","rc":[{"trd":[[2.68,150.49]],"batb":[[0,2.66,8.27],[1,2.64,4.28],[2,2.62,78.95]],"batl":[[0,2.72,88.34]],"ltp":2.68,"tv":3184.31,"id":25238892}],"tv":8545.39}]}
{"op":"mcm","clk":"994044368","pt":1580548807600,"mc":[{"id":"1.168130661","rc":[{"batl":[[0,2.7,2],[1,2.72,88.34],[2,2.74,27.87]],"ltp":2.68,"tv":3184.31,"id":25238892}]}]}
{"op":"mcm","clk":"994044542","pt":1580548809426,"mc":[{"id":"1.168130661","rc":[{"batb":[[0,32,5.53]],"ltp":50.0,"tv":111.03,"id":25545675}]}]}
{"op":"mcm","clk":"994045297","pt":1580548817633,"mc":[{"id":"1.168130661","rc":[{"batb":[[0,32,2.06]],"ltp":50.0,"tv":111.03,"id":25545675}]}]}
{"op":"mcm","clk":"994046029","pt":1580548825443,"mc":[{"id":"1.168130661","rc":[{"batb":[[0,32,5.53]],"ltp":50.0,"tv":111.03,"id":25545675},{"trd":[[11,54.61]],"batb":[[0,11.5,2.13],[1,11,6.28],[2,10.5,10.56]],"ltp":11.0,"tv":798.05,"id":24420205}],"tv":8549.39}]}
{"op":"mcm","clk":"994046155","pt":1580548826643,"mc":[{"id":"1.168130661","rc":[{"trd":[[11.5,135.52]],"batb":[[0,11.5,2.14]],"ltp":11.5,"tv":802.31,"id":24420205}],"tv":8553.65}]}
{"op":"mcm","clk":"994046249","pt":1580548827528,"mc":[{"id":"1.168130661","rc":[{"trd":[[11.5,139.8]],"batb":[[0,11.5,2.15]],"ltp":11.5,"tv":806.59,"id":24420205}],"tv":8557.93}]}
{"op":"mcm","clk":"994046347","pt":1580548828665,"mc":[{"id":"1.168130661","rc":[{"trd":[[11.5,144.1]],"batb":[[0,11,6.28],[1,10.5,10.56],[2,10,21.27]],"ltp":11.5,"tv":810.89,"id":24420205}],"tv":8562.23}]}
{"op":"mcm","clk":"994046443","pt":1580548829657,"mc":[{"id":"1.168130661","rc":[{"batl":[[0,12.5,2.43]],"ltp":11.5,"tv":810.89,"id":24420205}]}]}
{"op":"mcm","clk":"994046833","pt":1580548833586,"mc":[{"id":"1.168130661","rc":[{"batb":[[0,32,2.06]],"ltp":50.0,"tv":111.03,"id":25545675}]}]}
{"op":"mcm","clk":"994047711","pt":1580548841675,"mc":[{"id":"1.168130661","rc":[{"batb":[[0,32,5.53]],"ltp":50.0,"tv":111.03,"id":25545675}]}]}
{"op":"mcm","clk":"994048653","pt":1580548850490,"mc":[{"id":"1.168130661","rc":[{"batb":[[0,32,2.06]],"ltp":50.0,"tv":111.03,"id":25545675}]}]}
{"op":"mcm","clk":"994048879","pt":1580548852721,"mc":[{"id":"1.168130661","rc":[{"batl":[[0,13,20.95],[1,13.5,2],[2,14,2.36]],"ltp":11.5,"tv":810.89,"id":24420205},{"trd":[[10.5,115.44]],"batb":[[0,10,4.32],[1,9.8,4.36],[2,9.6,2]],"batl":[[0,10.5,10.36],[1,11,2.12],[2,11.5,15.73]],"ltp":10.5,"tv":612.2,"id":420}],"tv":8565.5}]}
{"op":"mcm","clk":"994049101","pt":1580548854693,"mc":[{"id":"1.168130661","rc":[{"batb":[[2,16,1.08]],"ltp":17.0,"tv":517.28,"id":24707172}]}]}
{"op":"mcm","clk":"994049515","pt":1580548858597,"mc":[{"id":"1.168130661","rc":[{"batb":[[0,32,5.53]],"ltp":50.0,"tv":111.03,"id":25545675}]}]}
{"op":"mcm","clk":"994050150","pt":1580548864681,"mc":[{"id":"1.168130661","rc":[{"batb":[[0,10,5.91]],"ltp":10.5,"tv":612.2,"id":420}]}]}
{"op":"mcm","clk":"994051573","pt":1580548878432,"mc":[{"id":"1.168130661","rc":[{"batl":[[0,2.7,7]],"ltp":2.68,"tv":3184.31,"id":25238892}]}]}
{"op":"mcm","clk":"994052416","pt":1580548886686,"mc":[{"id":"1.168130661","rc":[{"trd":[[50,4.42]],"batl":[[0,55,8.46]],"ltp":50.0,"tv":111.06,"id":25545675},{"trd":[[2.64,193.33],[2.66,128.12]],"batb":[[0,2.62,81.95],[1,2.6,6.74],[2,2.58,8.85]],"batl":[[0,2.64,28.8],[1,2.68,7.14],[2,2.7,14]],"ltp":2.64,"tv":3226.06,"id":25238892},{"trd":[[18.5,28.73]],"batb":[[0,17,5.3]],"batl":[[0,18.5,2.94],[1,19,2.14],[2,19.5,2.28]],"ltp":18.5,"tv":517.37,"id":24707172},{"trd":[[11.5,144.25]],"batb":[[0,11.5,2.1],[1,11,6.28],[2,10.5,10.56]],"batl":[[0,13,20.8]],"ltp":11.5,"tv":811.04,"id":24420205},{"trd":[[2.7,616.66]],"batb":[[0,2.68,75.38]],"batl":[[0,2.7,37.85],[1,2.72,340.74],[2,2.74,79.55]],"ltp":2.7,"tv":3330.41,"id":26314798},{"trd":[[10.5,115.6]],"batl":[[0,10.5,8.2]],"ltp":10.5,"tv":612.36,"id":420}],"tv":8608.32}]}
{"op":"mcm","clk":"994052517","pt":1580548887623,"mc":[{"id":"1.168130661","rc":[{"trd":[[50,4.9]],"batb":[[2,29,2.3]],"batl":[[0,55,7.98]],"ltp":50.0,"tv":111.54,"id":25545675},{"trd":[[2.64,241.84]],"batb":[[0,2.64,11.19],[1,2.62,81.95],[2,2.6,6.74]],"batl":[[0,2.68,7.14],[1,2.7,14],[2,2.72,88.34]],"ltp":2.64,"tv":3274.57,"id":25238892},{"trd":[[18.5,33.31]],"batl":[[0,19.5,2.28],[1,20,8.25],[2,21,14.12]],"ltp":18.5,"tv":521.95,"id":24707172},{"trd":[[12,98.05]],"ltp":12.0,"tv":813.04,"id":24420205},{"trd":[[2.7,625.55]],"batb":[[0,2.68,105.82]],"batl":[[0,2.7,28.96]],"ltp":2.7,"tv":3339.3,"id":26314798},{"trd":[[10.5,129.71]],"batb":[[0,10.5,1.71],[1,10,5.91],[2,9.8,4.36]],"batl":[[0,11,2.12],[1,11.5,15.73],[2,12,5.75]],"ltp":10.5,"tv":626.47,"id":420}],"tv":8686.9}]}
{"op":"mcm","clk":"994052618","pt":1580548888620,"mc":[{"id":"1.168130661","rc":[{"batb":[[0,36,4.15],[1,34,2.35],[2,32,5.53]],"ltp":50.0,"tv":111.54,"id":25545675},{"batb":[[0,2.64,14.19]],"batl":[[0,2.68,11.05],[1,2.7,16.67],[2,2.72,99.54]],"ltp":2.64,"tv":3274.57,"id":25238892},{"batb":[[0,18,2.18],[1,17.5,6.57],[2,17,5.3]],"ltp":18.5,"tv":521.95,"id":24707172},{"trd":[[12,102.45]],"batb":[[0,12,4.47],[1,11.5,2.1]],"batl":[[0,12.5,3.15],[1,13,20.8],[2,13.5,2]],"ltp":12.0,"tv":817.44,"id":24420205},{"batb":[[0,2.68,95.82],[1,2.66,24.2]],"batl":[[2,2.74,81.55]],"ltp":2.7,"tv":3339.3,"id":26314798},{"trd":[[10.5,133.13]],"batb":[[0,10,5.91],[1,9.8,4.36],[2,9.6,2]],"ltp":10.5,"tv":629.89,"id":420}],"tv":8694.72}]}
{"op":"mcm","clk":"994052718","pt":1580548889723,"mc":[{"id":"1.168130661","rc":[{"batb":[[1,34,4.66]],"ltp":50.0,"tv":111.54,"id":25545675},{"batb":[[1,2.62,85.08]],"batl":[[1,2.7,7],[2,2.72,88.34]],"ltp":2.64,"tv":3274.57,"id":25238892}]}]}
{"op":"mcm","clk":"994052813","pt":1580548890557,"mc":[{"id":"1.168130661","rc":[{"batb":[[2,32,2.06]],"ltp":50.0,"tv":111.54,"id":25545675}]}]}
{"op":"mcm","clk":"994052927","pt":1580548891645,"mc":[{"id":"1.168130661","rc":[{"batl":[[1,2.7,21]],"ltp":2.64,"tv":3274.57,"id":25238892}]}]}
{"op":"mcm","clk":"994053014","pt":1580548892554,"mc":[{"id":"1.168130661","rc":[{"batb":[[0,36,2]],"ltp":50.0,"tv":111.54,"id":25545675},{"batl":[[0,2.66,5],[1,2.68,11.05],[2,2.7,21]],"ltp":2.64,"tv":3274.57,"id":25238892},{"batb":[[0,2.68,105.82]],"ltp":2.7,"tv":3339.3,"id":26314798}]}]}
{"op":"mcm","clk":"994053205","pt":1580548893642,"mc":[{"id":"1.168130661","rc":[{"batl":[[0,50,10.38],[1,55,7.6],[2,60,1.77]],"ltp":50.0,"tv":111.54,"id":25545675},{"batl":[[1,2.7,16],[2,2.72,88.34]],"ltp":2.64,"tv":3274.57,"id":25238892}]}]}
{"op":"mcm","clk":"994053311","pt":1580548894646,"mc":[{"id":"1.168130661","rc":[{"batb":[[2,32,2.61]],"ltp":50.0,"tv":111.54,"id":25545675},{"batl":[[1,2.7,24]],"ltp":2.64,"tv":3274.57,"id":25238892}]}]}
{"op":"mcm","clk":"994053757","pt":1580548898645,"mc":[{"id":"1.168130661","rc":[{"trd":[[2.66,132.12]],"ltp":2.66,"tv":3278.57,"id":25238892}],"tv":8698.72}]}
{"op":"mcm","clk":"994054533","pt":1580548906653,"mc":[{"id":"1.168130661","rc":[{"batl":[[0,2.66,3]],"ltp":2.66,"tv":3278.57,"id":25238892}]}]}
{"op":"mcm","clk":"994054936","pt":1580548910651,"mc":[{"id":"1.168130661","rc":[{"batb":[[0,2.64,16.19]],"ltp":2.66,"tv":3278.57,"id":25238892}]}]}
{"op":"mcm","clk":"994055206","pt":1580548913663,"mc":[{"id":"1.168130661","rc":[{"batb":[[0,36,2.64]],"ltp":50.0,"tv":111.54,"id":25545675},{"batb":[[0,18,4.18]],"ltp":18.5,"tv":521.95,"id":24707172},{"batb":[[0,10,4.32]],"ltp":10.5,"tv":629.89,"id":420}]}]}
{"op":"mcm","clk":"994055272","pt":1580548914291,"mc":[{"id":"1.168130661","rc":[{"batb":[[0,18,2.18],[1,17.5,4.57],[2,17,3.3]],"ltp":18.5,"tv":521.95,"id":24707172}]}]}
{"op":"mcm","clk":"994055688","pt":1580548918678,"mc":[{"id":"1.168130661","rc":[{"batl":[[1,2.7,27]],"ltp":2.66,"tv":3278.57,"id":25238892}]}]}
{"op":"mcm","clk":"994055896","pt":1580548920650,"mc":[{"id":"1.168130661","rc":[{"batb":[[0,18,4.18]],"ltp":18.5,"tv":521.95,"id":24707172},{"batl":[[1,2.72,342.74]],"ltp":2.7,"tv":3339.3,"id":26314798}]}]}
{"op":"mcm","clk":"994055981","pt":1580548921495,"mc":[{"id":"1.168130661","rc":[{"batb":[[2,17,1.3]],"ltp":18.5,"tv":521.95,"id":24707172}]}]}
{"op":"mcm","clk":"994056395","pt":1580548925608,"mc":[{"id":"1.168130661","rc":[{"trd":[[18,45.25]],"batb":[[0,17.5,4.57],[1,17,1.3],[2,16.5,2.31]],"batl":[[0,19.5,7.48]],"ltp":18.0,"tv":525.95,"id":24707172}],"tv":8702.72}]}
